#######################################################################
# +-----------------------------------------------------------------+ #
# |                            BO3 object                           | #
# +-----------------------------------------------------------------+ #
#######################################################################

Author: Bo3 BulkEdit

Description: Converted Schematic - Modified by Bo3BulkEdit

Version: 3

SettingsMode: WriteDisable

#######################################################################
# +-----------------------------------------------------------------+ #
# |                          Main settings                          | #
# +-----------------------------------------------------------------+ #
#######################################################################



Frequency: 0


SpawnHeight: randomY





##############################
# Height Limits for the BO3. #
##############################

MinHeight: 0
MaxHeight: 256

#######################################################################
# +-----------------------------------------------------------------+ #
# |                      Source block settings                      | #
# +-----------------------------------------------------------------+ #
#######################################################################

CanOverride: true
MaxPercentageOutsideSourceBlock: 100
OutsideSourceBlock: placeAnyway

#######################################################################
# +-----------------------------------------------------------------+ #
# |                               OTG+                              | #
# +-----------------------------------------------------------------+ #
#######################################################################

#######################################################################
# +-----------------------------------------------------------------+ #
# |                              Blocks                             | #
# +-----------------------------------------------------------------+ #
#######################################################################

B(0,750,0,AIR)
B(15,750,15,AIR)
B(6,-2,14,betternether:quartz_stained_glass:15)
B(5,-2,15,betternether:quartz_stained_glass:15)
B(6,-2,15,betternether:quartz_stained_glass:15)
B(3,-1,10,betternether:quartz_stained_glass:15)
B(4,-1,10,betternether:quartz_stained_glass:15)
B(5,-1,10,betternether:quartz_stained_glass:15)
B(3,-1,11,betternether:quartz_stained_glass:15)
B(4,-1,11,betternether:quartz_stained_glass:15)
B(5,-1,11,betternether:quartz_stained_glass:15)
B(6,-1,11,betternether:quartz_stained_glass:15)
B(4,-1,12,betternether:quartz_stained_glass:15)
B(5,-1,12,betternether:quartz_stained_glass:15)
B(6,-1,12,betternether:quartz_stained_glass:15)
B(6,-1,13,betternether:quartz_stained_glass:15)
B(7,-1,13,betternether:quartz_stained_glass:15)
B(4,-1,14,betternether:quartz_stained_glass:15)
B(5,-1,14,betternether:quartz_stained_glass:15)
B(6,-1,14,betternether:quartz_stained_glass:15)
B(5,-1,15,betternether:quartz_stained_glass:15)
B(6,-1,15,betternether:quartz_stained_glass:15)
B(4,0,7,betternether:quartz_stained_glass:15)
B(5,0,7,betternether:quartz_stained_glass:15)
B(2,0,8,betternether:quartz_stained_glass:15)
B(3,0,8,betternether:quartz_stained_glass:15)
B(4,0,8,betternether:quartz_stained_glass:15)
B(5,0,8,betternether:quartz_stained_glass:15)
B(6,0,8,betternether:quartz_stained_glass:15)
B(2,0,9,betternether:quartz_stained_glass:15)
B(3,0,9,betternether:quartz_stained_glass:15)
B(4,0,9,betternether:quartz_stained_glass:15)
B(5,0,9,betternether:quartz_stained_glass:15)
B(6,0,9,betternether:quartz_stained_glass:15)
B(7,0,9,betternether:quartz_stained_glass:15)
B(1,0,10,betternether:quartz_stained_glass:15)
B(2,0,10,betternether:quartz_stained_glass:15)
B(3,0,10,betternether:quartz_stained_glass:15)
B(4,0,10,betternether:quartz_stained_glass:15)
B(5,0,10,betternether:quartz_stained_glass:15)
B(6,0,10,betternether:quartz_stained_glass:15)
B(7,0,10,betternether:quartz_stained_glass:15)
B(2,0,11,betternether:quartz_stained_glass:15)
B(3,0,11,betternether:quartz_stained_glass:15)
B(4,0,11,betternether:quartz_stained_glass:15)
B(5,0,11,betternether:quartz_stained_glass:15)
B(6,0,11,betternether:quartz_stained_glass:15)
B(7,0,11,betternether:quartz_stained_glass:15)
B(3,0,12,betternether:quartz_stained_glass:15)
B(4,0,12,betternether:quartz_stained_glass:15)
B(6,0,12,betternether:quartz_stained_glass:15)
B(7,0,12,betternether:quartz_stained_glass:15)
B(3,0,13,betternether:quartz_stained_glass:15)
B(4,0,13,betternether:quartz_stained_glass:15)
B(5,0,13,betternether:quartz_stained_glass:15)
B(6,0,13,betternether:quartz_stained_glass:15)
B(7,0,13,betternether:quartz_stained_glass:15)
B(4,0,14,betternether:quartz_stained_glass:15)
B(5,0,14,betternether:quartz_stained_glass:15)
B(6,0,14,betternether:quartz_stained_glass:15)
B(3,1,5,betternether:quartz_stained_glass:15)
B(4,1,5,betternether:quartz_stained_glass:15)
B(5,1,5,betternether:quartz_stained_glass:15)
B(2,1,6,betternether:quartz_stained_glass:15)
B(3,1,6,betternether:quartz_stained_glass:15)
B(4,1,6,betternether:quartz_stained_glass:15)
B(5,1,6,betternether:quartz_stained_glass:15)
B(0,1,7,betternether:quartz_stained_glass:15)
B(1,1,7,betternether:quartz_stained_glass:15)
B(2,1,7,betternether:quartz_stained_glass:15)
B(3,1,7,betternether:quartz_stained_glass:15)
B(4,1,7,betternether:quartz_stained_glass:15)
B(5,1,7,betternether:quartz_stained_glass:15)
B(6,1,7,betternether:quartz_stained_glass:15)
B(0,1,8,betternether:quartz_stained_glass:15)
B(1,1,8,betternether:quartz_stained_glass:15)
B(2,1,8,betternether:quartz_stained_glass:15)
B(3,1,8,betternether:quartz_stained_glass:15)
B(4,1,8,betternether:quartz_stained_glass:15)
B(5,1,8,betternether:quartz_stained_glass:15)
B(6,1,8,betternether:quartz_stained_glass:15)
B(0,1,9,betternether:quartz_stained_glass:15)
B(1,1,9,betternether:quartz_stained_glass:15)
B(2,1,9,betternether:quartz_stained_glass:15)
B(3,1,9,betternether:quartz_stained_glass:15)
B(4,1,9,betternether:quartz_stained_glass:15)
B(5,1,9,betternether:quartz_stained_glass:15)
B(6,1,9,betternether:quartz_stained_glass:15)
B(7,1,9,betternether:quartz_stained_glass:15)
B(1,1,10,betternether:quartz_stained_glass:15)
B(2,1,10,betternether:quartz_stained_glass:15)
B(3,1,10,betternether:quartz_stained_glass:15)
RB(4,1,10,srparasites:parasitestain:1,80,quark:crystal:1,30,srparasites:parasiterubbledense:1,100)
B(5,1,10,betternether:quartz_stained_glass:15)
B(6,1,10,betternether:quartz_stained_glass:15)
B(7,1,10,betternether:quartz_stained_glass:15)
B(2,1,11,betternether:quartz_stained_glass:15)
B(3,1,11,betternether:quartz_stained_glass:15)
B(4,1,11,betternether:quartz_stained_glass:15)
B(5,1,11,betternether:quartz_stained_glass:15)
B(6,1,11,betternether:quartz_stained_glass:15)
B(7,1,11,betternether:quartz_stained_glass:15)
B(2,1,12,betternether:quartz_stained_glass:15)
B(3,1,12,betternether:quartz_stained_glass:15)
B(4,1,12,betternether:quartz_stained_glass:15)
B(5,1,12,betternether:quartz_stained_glass:15)
B(6,1,12,betternether:quartz_stained_glass:15)
B(7,1,12,betternether:quartz_stained_glass:15)
B(3,1,13,betternether:quartz_stained_glass:15)
B(4,1,13,betternether:quartz_stained_glass:15)
B(5,1,13,betternether:quartz_stained_glass:15)
B(6,1,13,betternether:quartz_stained_glass:15)
B(3,2,3,betternether:quartz_stained_glass:15)
B(0,2,4,betternether:quartz_stained_glass:15)
B(1,2,4,betternether:quartz_stained_glass:15)
B(2,2,4,betternether:quartz_stained_glass:15)
B(3,2,4,betternether:quartz_stained_glass:15)
B(4,2,4,betternether:quartz_stained_glass:15)
B(0,2,5,betternether:quartz_stained_glass:15)
B(1,2,5,betternether:quartz_stained_glass:15)
B(2,2,5,betternether:quartz_stained_glass:15)
B(3,2,5,betternether:quartz_stained_glass:15)
B(4,2,5,betternether:quartz_stained_glass:15)
B(5,2,5,betternether:quartz_stained_glass:15)
B(0,2,6,betternether:quartz_stained_glass:15)
B(1,2,6,betternether:quartz_stained_glass:15)
B(2,2,6,betternether:quartz_stained_glass:15)
B(3,2,6,betternether:quartz_stained_glass:15)
B(4,2,6,betternether:quartz_stained_glass:15)
B(5,2,6,betternether:quartz_stained_glass:15)
B(0,2,7,betternether:quartz_stained_glass:15)
B(1,2,7,betternether:quartz_stained_glass:15)
B(2,2,7,betternether:quartz_stained_glass:15)
B(3,2,7,betternether:quartz_stained_glass:15)
B(4,2,7,betternether:quartz_stained_glass:15)
B(5,2,7,betternether:quartz_stained_glass:15)
B(6,2,7,betternether:quartz_stained_glass:15)
B(0,2,8,betternether:quartz_stained_glass:15)
B(1,2,8,betternether:quartz_stained_glass:15)
B(2,2,8,betternether:quartz_stained_glass:15)
B(3,2,8,betternether:quartz_stained_glass:15)
B(4,2,8,betternether:quartz_stained_glass:15)
B(5,2,8,betternether:quartz_stained_glass:15)
B(6,2,8,betternether:quartz_stained_glass:15)
B(0,2,9,betternether:quartz_stained_glass:15)
B(1,2,9,betternether:quartz_stained_glass:15)
B(2,2,9,betternether:quartz_stained_glass:15)
B(3,2,9,betternether:quartz_stained_glass:15)
RB(4,2,9,srparasites:parasitestain:1,80,quark:crystal:1,30,srparasites:parasiterubbledense:1,100)
B(5,2,9,betternether:quartz_stained_glass:15)
B(6,2,9,betternether:quartz_stained_glass:15)
B(7,2,9,betternether:quartz_stained_glass:15)
B(1,2,10,betternether:quartz_stained_glass:15)
B(2,2,10,betternether:quartz_stained_glass:15)
B(3,2,10,betternether:quartz_stained_glass:15)
RB(4,2,10,srparasites:parasitestain:1,80,quark:crystal:1,30,srparasites:parasiterubbledense:1,100)
RB(5,2,10,srparasites:parasitestain:1,80,quark:crystal:1,30,srparasites:parasiterubbledense:1,100)
B(6,2,10,betternether:quartz_stained_glass:15)
B(7,2,10,betternether:quartz_stained_glass:15)
B(2,2,11,betternether:quartz_stained_glass:15)
B(3,2,11,betternether:quartz_stained_glass:15)
B(4,2,11,betternether:quartz_stained_glass:15)
B(5,2,11,betternether:quartz_stained_glass:15)
B(6,2,11,betternether:quartz_stained_glass:15)
B(7,2,11,betternether:quartz_stained_glass:15)
B(2,2,12,betternether:quartz_stained_glass:15)
B(3,2,12,betternether:quartz_stained_glass:15)
B(4,2,12,betternether:quartz_stained_glass:15)
B(5,2,12,betternether:quartz_stained_glass:15)
B(6,2,12,betternether:quartz_stained_glass:15)
B(4,2,13,betternether:quartz_stained_glass:15)
B(5,2,13,betternether:quartz_stained_glass:15)
B(2,3,1,betternether:quartz_stained_glass:15)
B(3,3,1,betternether:quartz_stained_glass:15)
B(0,3,2,betternether:quartz_stained_glass:15)
B(1,3,2,betternether:quartz_stained_glass:15)
B(2,3,2,betternether:quartz_stained_glass:15)
B(3,3,2,betternether:quartz_stained_glass:15)
B(0,3,3,betternether:quartz_stained_glass:15)
B(1,3,3,betternether:quartz_stained_glass:15)
B(2,3,3,betternether:quartz_stained_glass:15)
B(3,3,3,betternether:quartz_stained_glass:15)
B(4,3,3,betternether:quartz_stained_glass:15)
B(0,3,4,betternether:quartz_stained_glass:15)
B(1,3,4,betternether:quartz_stained_glass:15)
B(2,3,4,betternether:quartz_stained_glass:15)
B(3,3,4,betternether:quartz_stained_glass:15)
B(4,3,4,betternether:quartz_stained_glass:15)
B(0,3,5,betternether:quartz_stained_glass:15)
B(1,3,5,betternether:quartz_stained_glass:15)
B(2,3,5,betternether:quartz_stained_glass:15)
B(3,3,5,betternether:quartz_stained_glass:15)
B(4,3,5,betternether:quartz_stained_glass:15)
B(5,3,5,betternether:quartz_stained_glass:15)
B(0,3,6,betternether:quartz_stained_glass:15)
B(1,3,6,betternether:quartz_stained_glass:15)
B(2,3,6,betternether:quartz_stained_glass:15)
B(3,3,6,betternether:quartz_stained_glass:15)
B(4,3,6,betternether:quartz_stained_glass:15)
B(5,3,6,betternether:quartz_stained_glass:15)
B(0,3,7,betternether:quartz_stained_glass:15)
B(1,3,7,betternether:quartz_stained_glass:15)
B(2,3,7,betternether:quartz_stained_glass:15)
B(3,3,7,betternether:quartz_stained_glass:15)
B(4,3,7,betternether:quartz_stained_glass:15)
B(5,3,7,betternether:quartz_stained_glass:15)
B(6,3,7,betternether:quartz_stained_glass:15)
B(0,3,8,betternether:quartz_stained_glass:15)
B(1,3,8,betternether:quartz_stained_glass:15)
B(2,3,8,betternether:quartz_stained_glass:15)
RB(3,3,8,srparasites:parasitestain:1,80,quark:crystal:1,30,srparasites:parasiterubbledense:1,100)
RB(4,3,8,srparasites:parasitestain:1,80,quark:crystal:1,30,srparasites:parasiterubbledense:1,100)
B(5,3,8,betternether:quartz_stained_glass:15)
B(6,3,8,betternether:quartz_stained_glass:15)
B(0,3,9,betternether:quartz_stained_glass:15)
B(1,3,9,betternether:quartz_stained_glass:15)
B(2,3,9,betternether:quartz_stained_glass:15)
RB(3,3,9,srparasites:parasitestain:1,80,quark:crystal:1,30,srparasites:parasiterubbledense:1,100)
RB(4,3,9,srparasites:parasitestain:1,80,quark:crystal:1,30,srparasites:parasiterubbledense:1,100)
RB(5,3,9,srparasites:parasitestain:1,80,quark:crystal:1,30,srparasites:parasiterubbledense:1,100)
B(6,3,9,betternether:quartz_stained_glass:15)
B(1,3,10,betternether:quartz_stained_glass:15)
B(2,3,10,betternether:quartz_stained_glass:15)
B(3,3,10,betternether:quartz_stained_glass:15)
B(4,3,10,betternether:quartz_stained_glass:15)
B(5,3,10,betternether:quartz_stained_glass:15)
B(6,3,10,betternether:quartz_stained_glass:15)
B(2,3,11,betternether:quartz_stained_glass:15)
B(3,3,11,betternether:quartz_stained_glass:15)
B(4,3,11,betternether:quartz_stained_glass:15)
B(5,3,11,betternether:quartz_stained_glass:15)
B(6,3,11,betternether:quartz_stained_glass:15)
B(3,3,12,betternether:quartz_stained_glass:15)
B(4,3,12,betternether:quartz_stained_glass:15)
B(5,3,12,betternether:quartz_stained_glass:15)
B(0,4,0,betternether:quartz_stained_glass:15)
B(1,4,0,betternether:quartz_stained_glass:15)
B(2,4,0,betternether:quartz_stained_glass:15)
B(3,4,0,betternether:quartz_stained_glass:15)
B(0,4,1,betternether:quartz_stained_glass:15)
B(1,4,1,betternether:quartz_stained_glass:15)
B(2,4,1,betternether:quartz_stained_glass:15)
B(3,4,1,betternether:quartz_stained_glass:15)
B(0,4,2,betternether:quartz_stained_glass:15)
B(1,4,2,betternether:quartz_stained_glass:15)
B(2,4,2,betternether:quartz_stained_glass:15)
B(3,4,2,betternether:quartz_stained_glass:15)
B(0,4,3,betternether:quartz_stained_glass:15)
B(1,4,3,betternether:quartz_stained_glass:15)
B(2,4,3,betternether:quartz_stained_glass:15)
B(3,4,3,betternether:quartz_stained_glass:15)
B(4,4,3,betternether:quartz_stained_glass:15)
B(0,4,4,betternether:quartz_stained_glass:15)
B(1,4,4,betternether:quartz_stained_glass:15)
B(2,4,4,betternether:quartz_stained_glass:15)
B(3,4,4,betternether:quartz_stained_glass:15)
B(4,4,4,betternether:quartz_stained_glass:15)
B(0,4,5,betternether:quartz_stained_glass:15)
B(1,4,5,betternether:quartz_stained_glass:15)
RB(2,4,5,srparasites:parasitestain:1,80,quark:crystal:1,30,srparasites:parasiterubbledense:1,100)
B(3,4,5,betternether:quartz_stained_glass:15)
B(4,4,5,betternether:quartz_stained_glass:15)
B(5,4,5,betternether:quartz_stained_glass:15)
B(0,4,6,betternether:quartz_stained_glass:15)
B(1,4,6,betternether:quartz_stained_glass:15)
B(2,4,6,betternether:quartz_stained_glass:15)
B(3,4,6,betternether:quartz_stained_glass:15)
B(4,4,6,betternether:quartz_stained_glass:15)
B(5,4,6,betternether:quartz_stained_glass:15)
B(0,4,7,betternether:quartz_stained_glass:15)
B(1,4,7,betternether:quartz_stained_glass:15)
RB(2,4,7,srparasites:parasitestain:1,80,quark:crystal:1,30,srparasites:parasiterubbledense:1,100)
RB(3,4,7,srparasites:parasitestain:1,80,quark:crystal:1,30,srparasites:parasiterubbledense:1,100)
B(4,4,7,betternether:quartz_stained_glass:15)
B(5,4,7,betternether:quartz_stained_glass:15)
B(6,4,7,betternether:quartz_stained_glass:15)
B(0,4,8,betternether:quartz_stained_glass:15)
B(1,4,8,betternether:quartz_stained_glass:15)
B(2,4,8,betternether:quartz_stained_glass:15)
RB(3,4,8,srparasites:parasitestain:1,80,quark:crystal:1,30,srparasites:parasiterubbledense:1,100)
B(4,4,8,betternether:quartz_stained_glass:15)
B(5,4,8,betternether:quartz_stained_glass:15)
B(6,4,8,betternether:quartz_stained_glass:15)
B(0,4,9,betternether:quartz_stained_glass:15)
B(1,4,9,betternether:quartz_stained_glass:15)
B(2,4,9,betternether:quartz_stained_glass:15)
B(3,4,9,betternether:quartz_stained_glass:15)
RB(4,4,9,srparasites:parasitestain:1,80,quark:crystal:1,30,srparasites:parasiterubbledense:1,100)
B(5,4,9,betternether:quartz_stained_glass:15)
B(6,4,9,betternether:quartz_stained_glass:15)
B(1,4,10,betternether:quartz_stained_glass:15)
B(2,4,10,betternether:quartz_stained_glass:15)
B(3,4,10,betternether:quartz_stained_glass:15)
B(4,4,10,betternether:quartz_stained_glass:15)
B(5,4,10,betternether:quartz_stained_glass:15)
B(6,4,10,betternether:quartz_stained_glass:15)
B(2,4,11,betternether:quartz_stained_glass:15)
B(3,4,11,betternether:quartz_stained_glass:15)
B(4,4,11,betternether:quartz_stained_glass:15)
B(5,4,11,betternether:quartz_stained_glass:15)
B(4,4,12,betternether:quartz_stained_glass:15)
B(0,5,0,betternether:quartz_stained_glass:15)
B(1,5,0,betternether:quartz_stained_glass:15)
B(2,5,0,betternether:quartz_stained_glass:15)
B(3,5,0,betternether:quartz_stained_glass:15)
B(0,5,1,betternether:quartz_stained_glass:15)
B(1,5,1,betternether:quartz_stained_glass:15)
B(2,5,1,betternether:quartz_stained_glass:15)
B(3,5,1,betternether:quartz_stained_glass:15)
B(0,5,2,betternether:quartz_stained_glass:15)
B(1,5,2,betternether:quartz_stained_glass:15)
B(2,5,2,betternether:quartz_stained_glass:15)
B(3,5,2,betternether:quartz_stained_glass:15)
B(0,5,3,betternether:quartz_stained_glass:15)
RB(1,5,3,srparasites:parasitestain:1,80,quark:crystal:1,30,srparasites:parasiterubbledense:1,100)
B(2,5,3,betternether:quartz_stained_glass:15)
B(3,5,3,betternether:quartz_stained_glass:15)
B(4,5,3,betternether:quartz_stained_glass:15)
B(0,5,4,betternether:quartz_stained_glass:15)
RB(1,5,4,srparasites:parasitestain:1,80,quark:crystal:1,30,srparasites:parasiterubbledense:1,100)
B(2,5,4,betternether:quartz_stained_glass:15)
B(3,5,4,betternether:quartz_stained_glass:15)
B(4,5,4,betternether:quartz_stained_glass:15)
B(0,5,5,betternether:quartz_stained_glass:15)
RB(1,5,5,srparasites:parasitestain:1,80,quark:crystal:1,30,srparasites:parasiterubbledense:1,100)
RB(2,5,5,srparasites:parasitestain:1,80,quark:crystal:1,30,srparasites:parasiterubbledense:1,100)
RB(3,5,5,srparasites:parasitestain:1,80,quark:crystal:1,30,srparasites:parasiterubbledense:1,100)
B(4,5,5,betternether:quartz_stained_glass:15)
B(5,5,5,betternether:quartz_stained_glass:15)
B(0,5,6,betternether:quartz_stained_glass:15)
B(1,5,6,betternether:quartz_stained_glass:15)
RB(2,5,6,srparasites:parasitestain:1,80,quark:crystal:1,30,srparasites:parasiterubbledense:1,100)
RB(3,5,6,srparasites:parasitestain:1,80,quark:crystal:1,30,srparasites:parasiterubbledense:1,100)
B(4,5,6,betternether:quartz_stained_glass:15)
B(5,5,6,betternether:quartz_stained_glass:15)
B(0,5,7,betternether:quartz_stained_glass:15)
B(1,5,7,betternether:quartz_stained_glass:15)
B(2,5,7,betternether:quartz_stained_glass:15)
B(3,5,7,betternether:quartz_stained_glass:15)
B(4,5,7,betternether:quartz_stained_glass:15)
B(5,5,7,betternether:quartz_stained_glass:15)
B(6,5,7,betternether:quartz_stained_glass:15)
B(0,5,8,betternether:quartz_stained_glass:15)
B(1,5,8,betternether:quartz_stained_glass:15)
B(2,5,8,betternether:quartz_stained_glass:15)
B(3,5,8,betternether:quartz_stained_glass:15)
B(4,5,8,betternether:quartz_stained_glass:15)
B(5,5,8,betternether:quartz_stained_glass:15)
B(6,5,8,betternether:quartz_stained_glass:15)
B(0,5,9,betternether:quartz_stained_glass:15)
B(1,5,9,betternether:quartz_stained_glass:15)
B(2,5,9,betternether:quartz_stained_glass:15)
B(3,5,9,betternether:quartz_stained_glass:15)
B(4,5,9,betternether:quartz_stained_glass:15)
B(5,5,9,betternether:quartz_stained_glass:15)
B(6,5,9,betternether:quartz_stained_glass:15)
B(1,5,10,betternether:quartz_stained_glass:15)
B(2,5,10,betternether:quartz_stained_glass:15)
B(3,5,10,betternether:quartz_stained_glass:15)
B(4,5,10,betternether:quartz_stained_glass:15)
B(5,5,10,betternether:quartz_stained_glass:15)
B(3,5,11,betternether:quartz_stained_glass:15)
B(4,5,11,betternether:quartz_stained_glass:15)
B(0,6,0,betternether:quartz_stained_glass:15)
B(1,6,0,betternether:quartz_stained_glass:15)
B(2,6,0,betternether:quartz_stained_glass:15)
B(3,6,0,betternether:quartz_stained_glass:15)
RB(0,6,1,srparasites:parasitestain:1,80,quark:crystal:1,30,srparasites:parasiterubbledense:1,100)
B(1,6,1,betternether:quartz_stained_glass:15)
B(2,6,1,betternether:quartz_stained_glass:15)
B(3,6,1,betternether:quartz_stained_glass:15)
B(0,6,2,betternether:quartz_stained_glass:15)
B(1,6,2,betternether:quartz_stained_glass:15)
B(2,6,2,betternether:quartz_stained_glass:15)
B(3,6,2,betternether:quartz_stained_glass:15)
B(0,6,3,betternether:quartz_stained_glass:15)
RB(1,6,3,srparasites:parasitestain:1,80,quark:crystal:1,30,srparasites:parasiterubbledense:1,100)
B(2,6,3,betternether:quartz_stained_glass:15)
B(3,6,3,betternether:quartz_stained_glass:15)
B(4,6,3,betternether:quartz_stained_glass:15)
B(0,6,4,betternether:quartz_stained_glass:15)
RB(1,6,4,srparasites:parasitestain:1,80,quark:crystal:1,30,srparasites:parasiterubbledense:1,100)
B(2,6,4,betternether:quartz_stained_glass:15)
B(3,6,4,betternether:quartz_stained_glass:15)
B(4,6,4,betternether:quartz_stained_glass:15)
B(0,6,5,betternether:quartz_stained_glass:15)
B(1,6,5,betternether:quartz_stained_glass:15)
RB(2,6,5,srparasites:parasitestain:1,80,quark:crystal:1,30,srparasites:parasiterubbledense:1,100)
B(3,6,5,betternether:quartz_stained_glass:15)
B(4,6,5,betternether:quartz_stained_glass:15)
B(5,6,5,betternether:quartz_stained_glass:15)
B(0,6,6,betternether:quartz_stained_glass:15)
B(1,6,6,betternether:quartz_stained_glass:15)
B(2,6,6,betternether:quartz_stained_glass:15)
B(3,6,6,betternether:quartz_stained_glass:15)
B(4,6,6,betternether:quartz_stained_glass:15)
B(5,6,6,betternether:quartz_stained_glass:15)
B(0,6,7,betternether:quartz_stained_glass:15)
B(1,6,7,betternether:quartz_stained_glass:15)
B(2,6,7,betternether:quartz_stained_glass:15)
B(3,6,7,betternether:quartz_stained_glass:15)
B(4,6,7,betternether:quartz_stained_glass:15)
B(5,6,7,betternether:quartz_stained_glass:15)
B(6,6,7,betternether:quartz_stained_glass:15)
B(0,6,8,betternether:quartz_stained_glass:15)
B(1,6,8,betternether:quartz_stained_glass:15)
B(2,6,8,betternether:quartz_stained_glass:15)
B(3,6,8,betternether:quartz_stained_glass:15)
B(4,6,8,betternether:quartz_stained_glass:15)
B(5,6,8,betternether:quartz_stained_glass:15)
B(6,6,8,betternether:quartz_stained_glass:15)
B(0,6,9,betternether:quartz_stained_glass:15)
B(1,6,9,betternether:quartz_stained_glass:15)
B(2,6,9,betternether:quartz_stained_glass:15)
B(3,6,9,betternether:quartz_stained_glass:15)
B(4,6,9,betternether:quartz_stained_glass:15)
B(5,6,9,betternether:quartz_stained_glass:15)
B(1,6,10,betternether:quartz_stained_glass:15)
B(2,6,10,betternether:quartz_stained_glass:15)
B(3,6,10,betternether:quartz_stained_glass:15)
B(4,6,10,betternether:quartz_stained_glass:15)
RB(0,7,0,srparasites:parasitestain:1,80,quark:crystal:1,30,srparasites:parasiterubbledense:1,100)
RB(1,7,0,srparasites:parasitestain:1,80,quark:crystal:1,30,srparasites:parasiterubbledense:1,100)
B(2,7,0,betternether:quartz_stained_glass:15)
B(3,7,0,betternether:quartz_stained_glass:15)
RB(0,7,1,srparasites:parasitestain:1,80,quark:crystal:1,30,srparasites:parasiterubbledense:1,100)
B(1,7,1,betternether:quartz_stained_glass:15)
B(2,7,1,betternether:quartz_stained_glass:15)
B(3,7,1,betternether:quartz_stained_glass:15)
RB(0,7,2,srparasites:parasitestain:1,80,quark:crystal:1,30,srparasites:parasiterubbledense:1,100)
RB(1,7,2,srparasites:parasitestain:1,80,quark:crystal:1,30,srparasites:parasiterubbledense:1,100)
B(2,7,2,betternether:quartz_stained_glass:15)
B(3,7,2,betternether:quartz_stained_glass:15)
B(0,7,3,betternether:quartz_stained_glass:15)
RB(1,7,3,srparasites:parasitestain:1,80,quark:crystal:1,30,srparasites:parasiterubbledense:1,100)
B(2,7,3,betternether:quartz_stained_glass:15)
B(3,7,3,betternether:quartz_stained_glass:15)
B(4,7,3,betternether:quartz_stained_glass:15)
B(0,7,4,betternether:quartz_stained_glass:15)
B(1,7,4,betternether:quartz_stained_glass:15)
B(2,7,4,betternether:quartz_stained_glass:15)
B(3,7,4,betternether:quartz_stained_glass:15)
B(4,7,4,betternether:quartz_stained_glass:15)
B(0,7,5,betternether:quartz_stained_glass:15)
B(1,7,5,betternether:quartz_stained_glass:15)
B(2,7,5,betternether:quartz_stained_glass:15)
B(3,7,5,betternether:quartz_stained_glass:15)
B(4,7,5,betternether:quartz_stained_glass:15)
B(5,7,5,betternether:quartz_stained_glass:15)
B(0,7,6,betternether:quartz_stained_glass:15)
B(1,7,6,betternether:quartz_stained_glass:15)
B(2,7,6,betternether:quartz_stained_glass:15)
B(3,7,6,betternether:quartz_stained_glass:15)
B(4,7,6,betternether:quartz_stained_glass:15)
B(5,7,6,betternether:quartz_stained_glass:15)
B(0,7,7,betternether:quartz_stained_glass:15)
B(1,7,7,betternether:quartz_stained_glass:15)
B(2,7,7,betternether:quartz_stained_glass:15)
B(3,7,7,betternether:quartz_stained_glass:15)
B(4,7,7,betternether:quartz_stained_glass:15)
B(5,7,7,betternether:quartz_stained_glass:15)
B(6,7,7,betternether:quartz_stained_glass:15)
B(0,7,8,betternether:quartz_stained_glass:15)
B(1,7,8,betternether:quartz_stained_glass:15)
B(2,7,8,betternether:quartz_stained_glass:15)
B(3,7,8,betternether:quartz_stained_glass:15)
B(4,7,8,betternether:quartz_stained_glass:15)
B(0,7,9,betternether:quartz_stained_glass:15)
B(1,7,9,betternether:quartz_stained_glass:15)
B(2,7,9,betternether:quartz_stained_glass:15)
B(3,7,9,betternether:quartz_stained_glass:15)
RB(0,8,0,srparasites:parasitestain:1,80,quark:crystal:1,30,srparasites:parasiterubbledense:1,100)
B(1,8,0,betternether:quartz_stained_glass:15)
B(2,8,0,betternether:quartz_stained_glass:15)
B(3,8,0,betternether:quartz_stained_glass:15)
B(0,8,1,betternether:quartz_stained_glass:15)
B(1,8,1,betternether:quartz_stained_glass:15)
B(2,8,1,betternether:quartz_stained_glass:15)
B(3,8,1,betternether:quartz_stained_glass:15)
B(0,8,2,betternether:quartz_stained_glass:15)
B(1,8,2,betternether:quartz_stained_glass:15)
B(2,8,2,betternether:quartz_stained_glass:15)
B(3,8,2,betternether:quartz_stained_glass:15)
B(0,8,3,betternether:quartz_stained_glass:15)
B(1,8,3,betternether:quartz_stained_glass:15)
B(2,8,3,betternether:quartz_stained_glass:15)
B(3,8,3,betternether:quartz_stained_glass:15)
B(4,8,3,betternether:quartz_stained_glass:15)
B(0,8,4,betternether:quartz_stained_glass:15)
B(1,8,4,betternether:quartz_stained_glass:15)
B(2,8,4,betternether:quartz_stained_glass:15)
B(3,8,4,betternether:quartz_stained_glass:15)
B(4,8,4,betternether:quartz_stained_glass:15)
B(0,8,5,betternether:quartz_stained_glass:15)
B(1,8,5,betternether:quartz_stained_glass:15)
B(2,8,5,betternether:quartz_stained_glass:15)
B(3,8,5,betternether:quartz_stained_glass:15)
B(4,8,5,betternether:quartz_stained_glass:15)
B(0,8,6,betternether:quartz_stained_glass:15)
B(1,8,6,betternether:quartz_stained_glass:15)
B(2,8,6,betternether:quartz_stained_glass:15)
B(3,8,6,betternether:quartz_stained_glass:15)
B(4,8,6,betternether:quartz_stained_glass:15)
B(0,8,7,betternether:quartz_stained_glass:15)
B(1,8,7,betternether:quartz_stained_glass:15)
B(0,9,0,betternether:quartz_stained_glass:15)
B(1,9,0,betternether:quartz_stained_glass:15)
B(2,9,0,betternether:quartz_stained_glass:15)
B(3,9,0,betternether:quartz_stained_glass:15)
B(0,9,1,betternether:quartz_stained_glass:15)
B(1,9,1,betternether:quartz_stained_glass:15)
B(2,9,1,betternether:quartz_stained_glass:15)
B(3,9,1,betternether:quartz_stained_glass:15)
B(0,9,2,betternether:quartz_stained_glass:15)
B(1,9,2,betternether:quartz_stained_glass:15)
B(2,9,2,betternether:quartz_stained_glass:15)
B(3,9,2,betternether:quartz_stained_glass:15)
B(0,9,3,betternether:quartz_stained_glass:15)
B(1,9,3,betternether:quartz_stained_glass:15)
B(2,9,3,betternether:quartz_stained_glass:15)
B(3,9,3,betternether:quartz_stained_glass:15)
B(4,9,3,betternether:quartz_stained_glass:15)
B(0,9,4,betternether:quartz_stained_glass:15)
B(1,9,4,betternether:quartz_stained_glass:15)
B(2,9,4,betternether:quartz_stained_glass:15)
B(0,9,5,betternether:quartz_stained_glass:15)
B(1,9,5,betternether:quartz_stained_glass:15)
B(0,10,0,betternether:quartz_stained_glass:15)
B(1,10,0,betternether:quartz_stained_glass:15)
B(2,10,0,betternether:quartz_stained_glass:15)
B(3,10,0,betternether:quartz_stained_glass:15)
B(0,10,1,betternether:quartz_stained_glass:15)
B(1,10,1,betternether:quartz_stained_glass:15)
B(2,10,1,betternether:quartz_stained_glass:15)
B(0,10,2,betternether:quartz_stained_glass:15)
B(1,10,2,betternether:quartz_stained_glass:15)
B(2,10,2,betternether:quartz_stained_glass:15)
B(0,10,3,betternether:quartz_stained_glass:15)
B(1,10,3,betternether:quartz_stained_glass:15)
B(0,11,0,betternether:quartz_stained_glass:15)
B(1,11,0,betternether:quartz_stained_glass:15)
B(2,11,0,betternether:quartz_stained_glass:15)

#######################################################################
# +-----------------------------------------------------------------+ #
# |                             Branches                            | #
# +-----------------------------------------------------------------+ #
#######################################################################

BR(-16,0,0,true,CRYST-SET-DIAG-THIN-04_0x2,NORTH,100,0)
BR(0,0,-16,true,CRYST-SET-DIAG-THIN-04_1x1,NORTH,100,0)
