
#######################################################################
# +-----------------------------------------------------------------+ #
# |                            BO4 object                           | #
# +-----------------------------------------------------------------+ #
#######################################################################

Author: NLBlackEagle

Description: No description given

SettingsMode: WriteDisable


#######################################################################
# +-----------------------------------------------------------------+ #
# |                          Main settings                          | #
# +-----------------------------------------------------------------+ #
#######################################################################

FixedRotation: 

Frequency: 0

SpawnHeight: highestBlock

UseCenterForHighestBlock: true

##############################
# Height Limits for the BO4. #
##############################

MinHeight: 0

MaxHeight: 255

InheritBO3: 

InheritBO3Rotation: NORTH

OverrideChildSettings: true

OverrideParentHeight: false

CanOverride: true

BranchFrequency: 0

BranchFrequencyGroup: 

MustBeBelowOther: false

MustBeInside: 

CannotBeInside: 

ReplacesBO3: 

MustBeInsideWorldBorders: false

CanSpawnOnWater: true

SpawnOnWaterOnly: false

SpawnUnderWater: false

SpawnAtWaterLevel: false

HeightOffset: 0

RemoveAir: false

ReplaceAbove: 

ReplaceBelow: 

ReplaceWithBiomeBlocks: false

ReplaceWithSurfaceBlock: GRASS

ReplaceWithGroundBlock: DIRT

ReplaceWithStoneBlock: STONE

SmoothRadius: 0

SmoothHeightOffset: 0

SmoothStartTop: false

SmoothStartWood: false

SmoothingSurfaceBlock: 

SmoothingGroundBlock: 

BO3Group: 

IsSpawnPoint: false

DoReplaceBlocks: false


#######################################################################
# +-----------------------------------------------------------------+ #
# |                              Blocks                             | #
# +-----------------------------------------------------------------+ #
#######################################################################

Block(-8,0,-7,contenttweaker:reinforced_concrete)
Block(-8,0,-6,contenttweaker:reinforced_concrete)
Block(-8,0,-5,contenttweaker:reinforced_concrete)
Block(-8,0,-4,contenttweaker:reinforced_concrete)
Block(-8,0,-3,contenttweaker:reinforced_concrete)
Block(-8,0,-2,contenttweaker:reinforced_concrete)
Block(-8,0,-1,contenttweaker:reinforced_concrete)
Block(-8,0,0,contenttweaker:reinforced_concrete)
Block(-8,0,1,contenttweaker:reinforced_concrete)
Block(-8,0,2,contenttweaker:reinforced_concrete)
Block(-8,0,3,contenttweaker:reinforced_concrete)
Block(-8,0,4,contenttweaker:reinforced_concrete)
Block(-8,0,5,contenttweaker:reinforced_concrete)
Block(-8,0,6,contenttweaker:reinforced_concrete)
Block(-8,0,7,contenttweaker:reinforced_concrete)
Block(-8,0,8,contenttweaker:reinforced_concrete)
Block(-8,1,-7,contenttweaker:reinforced_concrete)
Block(-8,2,-7,contenttweaker:reinforced_concrete)
Block(-8,2,-1,contenttweaker:reinforced_concrete)
Block(-8,2,0,contenttweaker:reinforced_concrete)
Block(-8,2,1,contenttweaker:reinforced_concrete)
Block(-8,2,2,contenttweaker:reinforced_concrete)
Block(-8,2,3,contenttweaker:reinforced_concrete)
Block(-8,2,4,contenttweaker:reinforced_concrete)
Block(-8,2,5,contenttweaker:reinforced_concrete)
Block(-8,2,6,contenttweaker:reinforced_concrete)
Block(-8,2,7,contenttweaker:reinforced_concrete)
Block(-8,2,8,contenttweaker:reinforced_concrete)
Block(-8,3,-7,contenttweaker:reinforced_concrete)
Block(-8,3,-1,contenttweaker:reinforced_concrete)
Block(-8,3,0,contenttweaker:reinforced_concrete)
Block(-8,3,1,contenttweaker:reinforced_concrete)
Block(-8,3,2,AIR:0)
Block(-8,3,3,AIR:0)
Block(-8,3,4,AIR:0)
Block(-8,3,5,AIR:0)
Block(-8,3,6,AIR:0)
Block(-8,3,7,AIR:0)
Block(-8,3,8,contenttweaker:reinforced_concrete)
Block(-8,4,-7,contenttweaker:reinforced_concrete)
Block(-8,4,-1,contenttweaker:reinforced_concrete)
Block(-8,4,0,contenttweaker:reinforced_concrete)
Block(-8,4,1,contenttweaker:reinforced_concrete)
Block(-8,4,2,AIR:0)
Block(-8,4,3,AIR:0)
Block(-8,4,4,AIR:0)
Block(-8,4,5,AIR:0)
Block(-8,4,6,AIR:0)
Block(-8,4,7,AIR:0)
Block(-8,4,8,contenttweaker:reinforced_concrete)
Block(-8,5,-7,contenttweaker:reinforced_concrete)
Block(-8,5,-1,contenttweaker:reinforced_concrete)
Block(-8,5,0,contenttweaker:reinforced_concrete)
Block(-8,5,1,contenttweaker:reinforced_concrete)
Block(-8,5,2,contenttweaker:reinforced_concrete)
Block(-8,5,3,contenttweaker:reinforced_concrete)
Block(-8,5,4,contenttweaker:reinforced_concrete)
Block(-8,5,5,contenttweaker:reinforced_concrete)
Block(-8,5,6,contenttweaker:reinforced_concrete)
Block(-8,5,7,contenttweaker:reinforced_concrete)
Block(-8,5,8,contenttweaker:reinforced_concrete)
Block(-8,6,-7,contenttweaker:reinforced_concrete)
Block(-8,6,-1,contenttweaker:reinforced_concrete)
Block(-8,6,0,contenttweaker:reinforced_concrete)
Block(-8,6,1,contenttweaker:reinforced_concrete)
Block(-8,7,-7,contenttweaker:reinforced_concrete)
Block(-8,8,-7,contenttweaker:reinforced_concrete)
Block(-8,8,-6,contenttweaker:reinforced_concrete)
Block(-8,8,-5,contenttweaker:reinforced_concrete)
Block(-8,8,-4,contenttweaker:reinforced_concrete)
Block(-8,8,-3,contenttweaker:reinforced_concrete)
Block(-8,8,-2,contenttweaker:reinforced_concrete)
Block(-8,8,-1,contenttweaker:reinforced_concrete)
Block(-8,8,0,contenttweaker:reinforced_concrete)
Block(-8,8,1,contenttweaker:reinforced_concrete)
Block(-8,8,2,contenttweaker:reinforced_concrete)
Block(-8,8,3,contenttweaker:reinforced_concrete)
Block(-8,8,4,contenttweaker:reinforced_concrete)
Block(-8,8,5,contenttweaker:reinforced_concrete)
Block(-8,8,6,contenttweaker:reinforced_concrete)
Block(-8,8,7,contenttweaker:reinforced_concrete)
Block(-8,8,8,contenttweaker:reinforced_concrete)
Block(-7,0,-7,contenttweaker:reinforced_concrete)
Block(-7,0,-6,contenttweaker:reinforced_concrete)
Block(-7,0,-5,contenttweaker:reinforced_concrete)
Block(-7,0,-4,contenttweaker:reinforced_concrete)
Block(-7,0,-3,contenttweaker:reinforced_concrete)
Block(-7,0,-2,contenttweaker:reinforced_concrete)
Block(-7,0,-1,contenttweaker:reinforced_concrete)
Block(-7,0,0,contenttweaker:reinforced_concrete)
Block(-7,0,1,contenttweaker:reinforced_concrete)
Block(-7,0,2,contenttweaker:reinforced_concrete)
Block(-7,0,3,contenttweaker:reinforced_concrete)
Block(-7,0,4,contenttweaker:reinforced_concrete)
Block(-7,0,5,contenttweaker:reinforced_concrete)
Block(-7,0,6,contenttweaker:reinforced_concrete)
Block(-7,0,7,contenttweaker:reinforced_concrete)
Block(-7,0,8,contenttweaker:reinforced_concrete)
Block(-7,1,-7,contenttweaker:reinforced_concrete)
Block(-7,1,-6,contenttweaker:reinforced_concrete)
Block(-7,1,-5,contenttweaker:reinforced_concrete)
Block(-7,1,-4,contenttweaker:reinforced_concrete)
Block(-7,1,-3,contenttweaker:reinforced_concrete)
Block(-7,2,-7,contenttweaker:reinforced_concrete)
Block(-7,2,-6,contenttweaker:reinforced_concrete)
Block(-7,2,-5,contenttweaker:reinforced_concrete)
Block(-7,2,-4,contenttweaker:reinforced_concrete)
Block(-7,2,-3,contenttweaker:reinforced_concrete)
Block(-7,2,-1,contenttweaker:reinforced_concrete)
Block(-7,2,0,contenttweaker:reinforced_concrete)
Block(-7,2,1,contenttweaker:reinforced_concrete)
Block(-7,2,2,contenttweaker:reinforced_concrete)
Block(-7,2,3,contenttweaker:reinforced_concrete)
Block(-7,2,4,contenttweaker:reinforced_concrete)
Block(-7,2,5,contenttweaker:reinforced_concrete)
Block(-7,2,6,contenttweaker:reinforced_concrete)
Block(-7,2,7,contenttweaker:reinforced_concrete)
Block(-7,2,8,contenttweaker:reinforced_concrete)
Block(-7,3,-7,contenttweaker:reinforced_concrete)
Block(-7,3,-6,contenttweaker:reinforced_concrete)
Block(-7,3,-5,contenttweaker:reinforced_concrete)
Block(-7,3,-4,contenttweaker:reinforced_concrete)
Block(-7,3,-3,contenttweaker:reinforced_concrete)
Block(-7,3,-1,contenttweaker:reinforced_concrete)
Block(-7,3,0,contenttweaker:reinforced_concrete)
Block(-7,3,1,contenttweaker:reinforced_concrete)
Block(-7,3,2,AIR:0)
Block(-7,3,3,AIR:0)
Block(-7,3,4,AIR:0)
Block(-7,3,5,AIR:0)
Block(-7,3,6,AIR:0)
Block(-7,3,7,AIR:0)
Block(-7,3,8,contenttweaker:reinforced_concrete)
Block(-7,4,-7,contenttweaker:reinforced_concrete)
Block(-7,4,-6,contenttweaker:reinforced_concrete)
Block(-7,4,-5,contenttweaker:reinforced_concrete)
Block(-7,4,-4,contenttweaker:reinforced_concrete)
Block(-7,4,-3,contenttweaker:reinforced_concrete)
Block(-7,4,-1,contenttweaker:reinforced_concrete)
Block(-7,4,0,contenttweaker:reinforced_concrete)
Block(-7,4,1,contenttweaker:reinforced_concrete)
Block(-7,4,2,AIR:0)
Block(-7,4,3,AIR:0)
Block(-7,4,4,AIR:0)
Block(-7,4,5,AIR:0)
Block(-7,4,6,AIR:0)
Block(-7,4,7,AIR:0)
Block(-7,4,8,contenttweaker:reinforced_concrete)
Block(-7,5,-7,contenttweaker:reinforced_concrete)
Block(-7,5,-6,contenttweaker:reinforced_concrete)
Block(-7,5,-5,contenttweaker:reinforced_concrete)
Block(-7,5,-4,contenttweaker:reinforced_concrete)
Block(-7,5,-3,contenttweaker:reinforced_concrete)
Block(-7,5,-1,contenttweaker:reinforced_concrete)
Block(-7,5,0,contenttweaker:reinforced_concrete)
Block(-7,5,1,contenttweaker:reinforced_concrete)
Block(-7,5,2,contenttweaker:reinforced_concrete)
Block(-7,5,3,contenttweaker:reinforced_concrete)
Block(-7,5,4,contenttweaker:reinforced_concrete)
Block(-7,5,5,contenttweaker:reinforced_concrete)
Block(-7,5,6,contenttweaker:reinforced_concrete)
Block(-7,5,7,contenttweaker:reinforced_concrete)
Block(-7,5,8,contenttweaker:reinforced_concrete)
Block(-7,6,-7,contenttweaker:reinforced_concrete)
Block(-7,6,-6,contenttweaker:reinforced_concrete)
Block(-7,6,-5,contenttweaker:reinforced_concrete)
Block(-7,6,-4,contenttweaker:reinforced_concrete)
Block(-7,6,-3,contenttweaker:reinforced_concrete)
Block(-7,6,-1,contenttweaker:reinforced_concrete)
Block(-7,6,0,contenttweaker:reinforced_concrete)
Block(-7,6,1,contenttweaker:reinforced_concrete)
Block(-7,7,-7,contenttweaker:reinforced_concrete)
Block(-7,7,-6,contenttweaker:reinforced_concrete)
Block(-7,7,-5,contenttweaker:reinforced_concrete)
Block(-7,7,-4,contenttweaker:reinforced_concrete)
Block(-7,7,-3,contenttweaker:reinforced_concrete)
Block(-7,8,-7,contenttweaker:reinforced_concrete)
Block(-7,8,-6,contenttweaker:reinforced_concrete)
Block(-7,8,-5,contenttweaker:reinforced_concrete)
Block(-7,8,-4,contenttweaker:reinforced_concrete)
Block(-7,8,-3,contenttweaker:reinforced_concrete)
Block(-7,8,-2,contenttweaker:reinforced_concrete)
Block(-7,8,-1,contenttweaker:reinforced_concrete)
Block(-7,8,0,contenttweaker:reinforced_concrete)
Block(-7,8,1,contenttweaker:reinforced_concrete)
Block(-7,8,2,contenttweaker:reinforced_concrete)
Block(-7,8,3,contenttweaker:reinforced_concrete)
Block(-7,8,4,contenttweaker:reinforced_concrete)
Block(-7,8,5,contenttweaker:reinforced_concrete)
Block(-7,8,6,contenttweaker:reinforced_concrete)
Block(-7,8,7,contenttweaker:reinforced_concrete)
Block(-7,8,8,contenttweaker:reinforced_concrete)
Block(-6,0,-3,contenttweaker:reinforced_concrete)
Block(-6,0,-2,contenttweaker:reinforced_concrete)
Block(-6,0,-1,contenttweaker:reinforced_concrete)
Block(-6,0,0,contenttweaker:reinforced_concrete)
Block(-6,0,1,contenttweaker:reinforced_concrete)
Block(-6,0,2,contenttweaker:reinforced_concrete)
Block(-6,0,3,contenttweaker:reinforced_concrete)
Block(-6,0,4,contenttweaker:reinforced_concrete)
Block(-6,0,5,contenttweaker:reinforced_concrete)
Block(-6,0,6,contenttweaker:reinforced_concrete)
Block(-6,0,7,contenttweaker:reinforced_concrete)
Block(-6,0,8,contenttweaker:reinforced_concrete)
Block(-6,1,-3,contenttweaker:reinforced_concrete)
Block(-6,2,-3,contenttweaker:reinforced_concrete)
Block(-6,2,-1,contenttweaker:reinforced_concrete)
Block(-6,2,0,contenttweaker:reinforced_concrete)
Block(-6,2,1,contenttweaker:reinforced_concrete)
Block(-6,2,2,contenttweaker:reinforced_concrete)
Block(-6,2,3,contenttweaker:reinforced_concrete)
Block(-6,2,4,contenttweaker:reinforced_concrete)
Block(-6,2,5,contenttweaker:reinforced_concrete)
Block(-6,2,6,contenttweaker:reinforced_concrete)
Block(-6,2,7,contenttweaker:reinforced_concrete)
Block(-6,2,8,contenttweaker:reinforced_concrete)
Block(-6,3,-3,contenttweaker:reinforced_concrete)
Block(-6,3,-1,contenttweaker:reinforced_concrete)
Block(-6,3,0,contenttweaker:reinforced_concrete)
Block(-6,3,1,contenttweaker:reinforced_concrete)
Block(-6,3,2,contenttweaker:reinforced_concrete)
Block(-6,3,3,contenttweaker:reinforced_concrete)
Block(-6,3,4,contenttweaker:reinforced_concrete)
Block(-6,3,5,contenttweaker:reinforced_concrete)
Block(-6,3,6,contenttweaker:reinforced_concrete)
Block(-6,3,7,contenttweaker:reinforced_concrete)
Block(-6,3,8,contenttweaker:reinforced_concrete)
Block(-6,4,-3,contenttweaker:reinforced_concrete)
Block(-6,4,-1,contenttweaker:reinforced_concrete)
Block(-6,4,0,contenttweaker:reinforced_concrete)
Block(-6,4,1,contenttweaker:reinforced_concrete)
Block(-6,4,2,contenttweaker:reinforced_concrete)
Block(-6,4,3,contenttweaker:reinforced_concrete)
Block(-6,4,4,contenttweaker:reinforced_concrete)
Block(-6,4,5,contenttweaker:reinforced_concrete)
Block(-6,4,6,contenttweaker:reinforced_concrete)
Block(-6,4,7,contenttweaker:reinforced_concrete)
Block(-6,4,8,contenttweaker:reinforced_concrete)
Block(-6,5,-3,contenttweaker:reinforced_concrete)
Block(-6,5,-1,contenttweaker:reinforced_concrete)
Block(-6,5,0,contenttweaker:reinforced_concrete)
Block(-6,5,1,contenttweaker:reinforced_concrete)
Block(-6,5,2,contenttweaker:reinforced_concrete)
Block(-6,5,3,contenttweaker:reinforced_concrete)
Block(-6,5,4,contenttweaker:reinforced_concrete)
Block(-6,5,5,contenttweaker:reinforced_concrete)
Block(-6,5,6,contenttweaker:reinforced_concrete)
Block(-6,5,7,contenttweaker:reinforced_concrete)
Block(-6,5,8,contenttweaker:reinforced_concrete)
Block(-6,6,-3,contenttweaker:reinforced_concrete)
Block(-6,6,-1,contenttweaker:reinforced_concrete)
Block(-6,6,0,contenttweaker:reinforced_concrete)
Block(-6,6,1,contenttweaker:reinforced_concrete)
Block(-6,7,-3,contenttweaker:reinforced_concrete)
Block(-6,8,-3,contenttweaker:reinforced_concrete)
Block(-6,8,-2,contenttweaker:reinforced_concrete)
Block(-6,8,-1,contenttweaker:reinforced_concrete)
Block(-6,8,0,contenttweaker:reinforced_concrete)
Block(-6,8,1,contenttweaker:reinforced_concrete)
Block(-6,8,2,contenttweaker:reinforced_concrete)
Block(-6,8,3,contenttweaker:reinforced_concrete)
Block(-6,8,4,contenttweaker:reinforced_concrete)
Block(-6,8,5,contenttweaker:reinforced_concrete)
Block(-6,8,6,contenttweaker:reinforced_concrete)
Block(-6,8,7,contenttweaker:reinforced_concrete)
Block(-6,8,8,contenttweaker:reinforced_concrete)
Block(-5,0,-3,contenttweaker:reinforced_concrete)
Block(-5,0,-2,contenttweaker:reinforced_concrete)
Block(-5,0,-1,contenttweaker:reinforced_concrete)
Block(-5,0,0,contenttweaker:reinforced_concrete)
Block(-5,0,1,contenttweaker:reinforced_concrete)
Block(-5,0,2,contenttweaker:reinforced_concrete)
Block(-5,0,3,contenttweaker:reinforced_concrete)
Block(-5,0,4,contenttweaker:reinforced_concrete)
Block(-5,0,5,contenttweaker:reinforced_concrete)
Block(-5,0,6,contenttweaker:reinforced_concrete)
Block(-5,0,7,contenttweaker:reinforced_concrete)
Block(-5,0,8,contenttweaker:reinforced_concrete)
Block(-5,1,-3,contenttweaker:reinforced_concrete)
Block(-5,2,-3,contenttweaker:reinforced_concrete)
Block(-5,3,-3,contenttweaker:reinforced_concrete)
Block(-5,4,-3,contenttweaker:reinforced_concrete)
Block(-5,5,-3,contenttweaker:reinforced_concrete)
Block(-5,6,-3,contenttweaker:reinforced_concrete)
Block(-5,7,-3,contenttweaker:reinforced_concrete)
Block(-5,8,-3,contenttweaker:reinforced_concrete)
Block(-5,8,-2,contenttweaker:reinforced_concrete)
Block(-5,8,-1,contenttweaker:reinforced_concrete)
Block(-5,8,0,contenttweaker:reinforced_concrete)
Block(-5,8,1,contenttweaker:reinforced_concrete)
Block(-5,8,2,contenttweaker:reinforced_concrete)
Block(-5,8,3,contenttweaker:reinforced_concrete)
Block(-5,8,4,contenttweaker:reinforced_concrete)
Block(-5,8,5,contenttweaker:reinforced_concrete)
Block(-5,8,6,contenttweaker:reinforced_concrete)
Block(-5,8,7,contenttweaker:reinforced_concrete)
Block(-5,8,8,contenttweaker:reinforced_concrete)
Block(-4,0,-3,contenttweaker:reinforced_concrete)
Block(-4,0,-2,contenttweaker:reinforced_concrete)
Block(-4,0,-1,contenttweaker:reinforced_concrete)
Block(-4,0,0,contenttweaker:reinforced_concrete)
Block(-4,0,1,contenttweaker:reinforced_concrete)
Block(-4,0,2,contenttweaker:reinforced_concrete)
Block(-4,0,3,contenttweaker:reinforced_concrete)
Block(-4,0,4,contenttweaker:reinforced_concrete)
Block(-4,0,5,contenttweaker:reinforced_concrete)
Block(-4,0,6,contenttweaker:reinforced_concrete)
Block(-4,0,7,contenttweaker:reinforced_concrete)
Block(-4,0,8,contenttweaker:reinforced_concrete)
Block(-4,1,-3,contenttweaker:reinforced_concrete)
Block(-4,1,-2,contenttweaker:reinforced_concrete)
Block(-4,1,-1,contenttweaker:reinforced_concrete)
Block(-4,1,0,contenttweaker:reinforced_concrete)
Block(-4,1,1,contenttweaker:reinforced_concrete)
Block(-4,1,2,contenttweaker:reinforced_concrete)
Block(-4,1,3,contenttweaker:reinforced_concrete)
Block(-4,1,4,contenttweaker:reinforced_concrete)
Block(-4,1,5,contenttweaker:reinforced_concrete)
Block(-4,1,6,contenttweaker:reinforced_concrete)
Block(-4,1,7,contenttweaker:reinforced_concrete)
Block(-4,1,8,contenttweaker:reinforced_concrete)
Block(-4,2,-3,contenttweaker:reinforced_concrete)
Block(-4,2,-2,contenttweaker:reinforced_concrete)
Block(-4,2,-1,contenttweaker:reinforced_concrete)
Block(-4,2,0,contenttweaker:reinforced_concrete)
Block(-4,2,1,contenttweaker:reinforced_concrete)
Block(-4,2,2,contenttweaker:reinforced_concrete)
Block(-4,2,3,contenttweaker:reinforced_concrete)
Block(-4,2,4,contenttweaker:reinforced_concrete)
Block(-4,2,5,contenttweaker:reinforced_concrete)
Block(-4,2,6,contenttweaker:reinforced_concrete)
Block(-4,2,7,contenttweaker:reinforced_concrete)
Block(-4,2,8,contenttweaker:reinforced_concrete)
Block(-4,3,-3,contenttweaker:reinforced_concrete)
Block(-4,3,-2,contenttweaker:reinforced_concrete)
Block(-4,3,-1,contenttweaker:reinforced_concrete)
Block(-4,3,0,contenttweaker:reinforced_concrete)
Block(-4,3,1,contenttweaker:reinforced_concrete)
Block(-4,3,2,contenttweaker:reinforced_concrete)
Block(-4,3,3,contenttweaker:reinforced_concrete)
Block(-4,3,4,contenttweaker:reinforced_concrete)
Block(-4,3,5,contenttweaker:reinforced_concrete)
Block(-4,3,6,contenttweaker:reinforced_concrete)
Block(-4,3,7,contenttweaker:reinforced_concrete)
Block(-4,3,8,contenttweaker:reinforced_concrete)
Block(-4,4,-3,contenttweaker:reinforced_concrete)
Block(-4,4,-2,contenttweaker:reinforced_concrete)
Block(-4,4,-1,contenttweaker:reinforced_concrete)
Block(-4,4,0,contenttweaker:reinforced_concrete)
Block(-4,4,1,contenttweaker:reinforced_concrete)
Block(-4,4,2,contenttweaker:reinforced_concrete)
Block(-4,4,3,contenttweaker:reinforced_concrete)
Block(-4,4,4,contenttweaker:reinforced_concrete)
Block(-4,4,5,contenttweaker:reinforced_concrete)
Block(-4,4,6,contenttweaker:reinforced_concrete)
Block(-4,4,7,contenttweaker:reinforced_concrete)
Block(-4,4,8,contenttweaker:reinforced_concrete)
Block(-4,5,-3,contenttweaker:reinforced_concrete)
Block(-4,5,-2,contenttweaker:reinforced_concrete)
Block(-4,5,-1,contenttweaker:reinforced_concrete)
Block(-4,5,0,contenttweaker:reinforced_concrete)
Block(-4,5,1,contenttweaker:reinforced_concrete)
Block(-4,5,2,contenttweaker:reinforced_concrete)
Block(-4,5,3,contenttweaker:reinforced_concrete)
Block(-4,5,4,contenttweaker:reinforced_concrete)
Block(-4,5,5,contenttweaker:reinforced_concrete)
Block(-4,5,6,contenttweaker:reinforced_concrete)
Block(-4,5,7,contenttweaker:reinforced_concrete)
Block(-4,5,8,contenttweaker:reinforced_concrete)
Block(-4,6,-3,contenttweaker:reinforced_concrete)
Block(-4,6,-2,contenttweaker:reinforced_concrete)
Block(-4,6,-1,contenttweaker:reinforced_concrete)
Block(-4,6,0,contenttweaker:reinforced_concrete)
Block(-4,6,1,contenttweaker:reinforced_concrete)
Block(-4,6,2,contenttweaker:reinforced_concrete)
Block(-4,6,3,contenttweaker:reinforced_concrete)
Block(-4,6,4,contenttweaker:reinforced_concrete)
Block(-4,6,5,contenttweaker:reinforced_concrete)
Block(-4,6,6,contenttweaker:reinforced_concrete)
Block(-4,6,7,contenttweaker:reinforced_concrete)
Block(-4,6,8,contenttweaker:reinforced_concrete)
Block(-4,7,-3,contenttweaker:reinforced_concrete)
Block(-4,7,-2,contenttweaker:reinforced_concrete)
Block(-4,7,-1,contenttweaker:reinforced_concrete)
Block(-4,7,0,contenttweaker:reinforced_concrete)
Block(-4,7,1,contenttweaker:reinforced_concrete)
Block(-4,7,2,contenttweaker:reinforced_concrete)
Block(-4,7,3,contenttweaker:reinforced_concrete)
Block(-4,7,4,contenttweaker:reinforced_concrete)
Block(-4,7,5,contenttweaker:reinforced_concrete)
Block(-4,7,6,contenttweaker:reinforced_concrete)
Block(-4,7,7,contenttweaker:reinforced_concrete)
Block(-4,7,8,contenttweaker:reinforced_concrete)
Block(-4,8,-3,contenttweaker:reinforced_concrete)
Block(-4,8,-2,contenttweaker:reinforced_concrete)
Block(-4,8,-1,contenttweaker:reinforced_concrete)
Block(-4,8,0,contenttweaker:reinforced_concrete)
Block(-4,8,1,contenttweaker:reinforced_concrete)
Block(-4,8,2,contenttweaker:reinforced_concrete)
Block(-4,8,3,contenttweaker:reinforced_concrete)
Block(-4,8,4,contenttweaker:reinforced_concrete)
Block(-4,8,5,contenttweaker:reinforced_concrete)
Block(-4,8,6,contenttweaker:reinforced_concrete)
Block(-4,8,7,contenttweaker:reinforced_concrete)
Block(-4,8,8,contenttweaker:reinforced_concrete)
Block(-8,1,-6,dimstack:bedrock)
Block(-8,1,-5,dimstack:bedrock)
Block(-8,1,-4,dimstack:bedrock)
Block(-8,1,-3,dimstack:bedrock)
Block(-8,1,-2,dimstack:bedrock)
Block(-8,1,-1,dimstack:bedrock)
Block(-8,1,0,dimstack:bedrock)
Block(-8,1,1,dimstack:bedrock)
Block(-8,1,2,dimstack:bedrock)
Block(-8,1,3,dimstack:bedrock)
Block(-8,1,4,dimstack:bedrock)
Block(-8,1,5,dimstack:bedrock)
Block(-8,1,6,dimstack:bedrock)
Block(-8,1,7,dimstack:bedrock)
Block(-8,1,8,dimstack:bedrock)
Block(-8,2,-6,dimstack:bedrock)
Block(-8,2,-5,dimstack:bedrock)
Block(-8,2,-4,dimstack:bedrock)
Block(-8,2,-3,dimstack:bedrock)
Block(-8,2,-2,dimstack:bedrock)
Block(-8,3,-6,dimstack:bedrock)
Block(-8,3,-5,dimstack:bedrock)
Block(-8,3,-4,dimstack:bedrock)
Block(-8,3,-3,dimstack:bedrock)
Block(-8,3,-2,dimstack:bedrock)
Block(-8,4,-6,dimstack:bedrock)
Block(-8,4,-5,dimstack:bedrock)
Block(-8,4,-4,dimstack:bedrock)
Block(-8,4,-3,dimstack:bedrock)
Block(-8,4,-2,dimstack:bedrock)
Block(-8,5,-6,dimstack:bedrock)
Block(-8,5,-5,dimstack:bedrock)
Block(-8,5,-4,dimstack:bedrock)
Block(-8,5,-3,dimstack:bedrock)
Block(-8,5,-2,dimstack:bedrock)
Block(-8,6,-6,dimstack:bedrock)
Block(-8,6,-5,dimstack:bedrock)
Block(-8,6,-4,dimstack:bedrock)
Block(-8,6,-3,dimstack:bedrock)
Block(-8,6,-2,dimstack:bedrock)
Block(-8,6,2,dimstack:bedrock)
Block(-8,6,3,dimstack:bedrock)
Block(-8,6,4,dimstack:bedrock)
Block(-8,6,5,dimstack:bedrock)
Block(-8,6,6,dimstack:bedrock)
Block(-8,6,7,dimstack:bedrock)
Block(-8,6,8,dimstack:bedrock)
Block(-8,7,-6,dimstack:bedrock)
Block(-8,7,-5,dimstack:bedrock)
Block(-8,7,-4,dimstack:bedrock)
Block(-8,7,-3,dimstack:bedrock)
Block(-8,7,-2,dimstack:bedrock)
Block(-8,7,-1,dimstack:bedrock)
Block(-8,7,0,dimstack:bedrock)
Block(-8,7,1,dimstack:bedrock)
Block(-8,7,2,dimstack:bedrock)
Block(-8,7,3,dimstack:bedrock)
Block(-8,7,4,dimstack:bedrock)
Block(-8,7,5,dimstack:bedrock)
Block(-8,7,6,dimstack:bedrock)
Block(-8,7,7,dimstack:bedrock)
Block(-8,7,8,dimstack:bedrock)
Block(-7,1,-2,dimstack:bedrock)
Block(-7,1,-1,dimstack:bedrock)
Block(-7,1,0,dimstack:bedrock)
Block(-7,1,1,dimstack:bedrock)
Block(-7,1,2,dimstack:bedrock)
Block(-7,1,3,dimstack:bedrock)
Block(-7,1,4,dimstack:bedrock)
Block(-7,1,5,dimstack:bedrock)
Block(-7,1,6,dimstack:bedrock)
Block(-7,1,7,dimstack:bedrock)
Block(-7,1,8,dimstack:bedrock)
Block(-7,2,-2,dimstack:bedrock)
Block(-7,3,-2,dimstack:bedrock)
Block(-7,4,-2,dimstack:bedrock)
Block(-7,5,-2,dimstack:bedrock)
Block(-7,6,-2,dimstack:bedrock)
Block(-7,6,2,dimstack:bedrock)
Block(-7,6,3,dimstack:bedrock)
Block(-7,6,4,dimstack:bedrock)
Block(-7,6,5,dimstack:bedrock)
Block(-7,6,6,dimstack:bedrock)
Block(-7,6,7,dimstack:bedrock)
Block(-7,6,8,dimstack:bedrock)
Block(-7,7,-2,dimstack:bedrock)
Block(-7,7,-1,dimstack:bedrock)
Block(-7,7,0,dimstack:bedrock)
Block(-7,7,1,dimstack:bedrock)
Block(-7,7,2,dimstack:bedrock)
Block(-7,7,3,dimstack:bedrock)
Block(-7,7,4,dimstack:bedrock)
Block(-7,7,5,dimstack:bedrock)
Block(-7,7,6,dimstack:bedrock)
Block(-7,7,7,dimstack:bedrock)
Block(-7,7,8,dimstack:bedrock)
Block(-6,1,-2,dimstack:bedrock)
Block(-6,1,-1,dimstack:bedrock)
Block(-6,1,0,dimstack:bedrock)
Block(-6,1,1,dimstack:bedrock)
Block(-6,1,2,dimstack:bedrock)
Block(-6,1,3,dimstack:bedrock)
Block(-6,1,4,dimstack:bedrock)
Block(-6,1,5,dimstack:bedrock)
Block(-6,1,6,dimstack:bedrock)
Block(-6,1,7,dimstack:bedrock)
Block(-6,1,8,dimstack:bedrock)
Block(-6,2,-2,dimstack:bedrock)
Block(-6,3,-2,dimstack:bedrock)
Block(-6,4,-2,dimstack:bedrock)
Block(-6,5,-2,dimstack:bedrock)
Block(-6,6,-2,dimstack:bedrock)
Block(-6,6,2,dimstack:bedrock)
Block(-6,6,3,dimstack:bedrock)
Block(-6,6,4,dimstack:bedrock)
Block(-6,6,5,dimstack:bedrock)
Block(-6,6,6,dimstack:bedrock)
Block(-6,6,7,dimstack:bedrock)
Block(-6,6,8,dimstack:bedrock)
Block(-6,7,-2,dimstack:bedrock)
Block(-6,7,-1,dimstack:bedrock)
Block(-6,7,0,dimstack:bedrock)
Block(-6,7,1,dimstack:bedrock)
Block(-6,7,2,dimstack:bedrock)
Block(-6,7,3,dimstack:bedrock)
Block(-6,7,4,dimstack:bedrock)
Block(-6,7,5,dimstack:bedrock)
Block(-6,7,6,dimstack:bedrock)
Block(-6,7,7,dimstack:bedrock)
Block(-6,7,8,dimstack:bedrock)
Block(-5,1,-2,dimstack:bedrock)
Block(-5,1,-1,dimstack:bedrock)
Block(-5,1,0,dimstack:bedrock)
Block(-5,1,1,dimstack:bedrock)
Block(-5,1,2,dimstack:bedrock)
Block(-5,1,3,dimstack:bedrock)
Block(-5,1,4,dimstack:bedrock)
Block(-5,1,5,dimstack:bedrock)
Block(-5,1,6,dimstack:bedrock)
Block(-5,1,7,dimstack:bedrock)
Block(-5,1,8,dimstack:bedrock)
Block(-5,2,-2,dimstack:bedrock)
Block(-5,2,-1,dimstack:bedrock)
Block(-5,2,0,dimstack:bedrock)
Block(-5,2,1,dimstack:bedrock)
Block(-5,2,2,dimstack:bedrock)
Block(-5,2,3,dimstack:bedrock)
Block(-5,2,4,dimstack:bedrock)
Block(-5,2,5,dimstack:bedrock)
Block(-5,2,6,dimstack:bedrock)
Block(-5,2,7,dimstack:bedrock)
Block(-5,2,8,dimstack:bedrock)
Block(-5,3,-2,dimstack:bedrock)
Block(-5,3,-1,dimstack:bedrock)
Block(-5,3,0,dimstack:bedrock)
Block(-5,3,1,dimstack:bedrock)
Block(-5,3,2,dimstack:bedrock)
Block(-5,3,3,dimstack:bedrock)
Block(-5,3,4,dimstack:bedrock)
Block(-5,3,5,dimstack:bedrock)
Block(-5,3,6,dimstack:bedrock)
Block(-5,3,7,dimstack:bedrock)
Block(-5,3,8,dimstack:bedrock)
Block(-5,4,-2,dimstack:bedrock)
Block(-5,4,-1,dimstack:bedrock)
Block(-5,4,0,dimstack:bedrock)
Block(-5,4,1,dimstack:bedrock)
Block(-5,4,2,dimstack:bedrock)
Block(-5,4,3,dimstack:bedrock)
Block(-5,4,4,dimstack:bedrock)
Block(-5,4,5,dimstack:bedrock)
Block(-5,4,6,dimstack:bedrock)
Block(-5,4,7,dimstack:bedrock)
Block(-5,4,8,dimstack:bedrock)
Block(-5,5,-2,dimstack:bedrock)
Block(-5,5,-1,dimstack:bedrock)
Block(-5,5,0,dimstack:bedrock)
Block(-5,5,1,dimstack:bedrock)
Block(-5,5,2,dimstack:bedrock)
Block(-5,5,3,dimstack:bedrock)
Block(-5,5,4,dimstack:bedrock)
Block(-5,5,5,dimstack:bedrock)
Block(-5,5,6,dimstack:bedrock)
Block(-5,5,7,dimstack:bedrock)
Block(-5,5,8,dimstack:bedrock)
Block(-5,6,-2,dimstack:bedrock)
Block(-5,6,-1,dimstack:bedrock)
Block(-5,6,0,dimstack:bedrock)
Block(-5,6,1,dimstack:bedrock)
Block(-5,6,2,dimstack:bedrock)
Block(-5,6,3,dimstack:bedrock)
Block(-5,6,4,dimstack:bedrock)
Block(-5,6,5,dimstack:bedrock)
Block(-5,6,6,dimstack:bedrock)
Block(-5,6,7,dimstack:bedrock)
Block(-5,6,8,dimstack:bedrock)
Block(-5,7,-2,dimstack:bedrock)
Block(-5,7,-1,dimstack:bedrock)
Block(-5,7,0,dimstack:bedrock)
Block(-5,7,1,dimstack:bedrock)
Block(-5,7,2,dimstack:bedrock)
Block(-5,7,3,dimstack:bedrock)
Block(-5,7,4,dimstack:bedrock)
Block(-5,7,5,dimstack:bedrock)
Block(-5,7,6,dimstack:bedrock)
Block(-5,7,7,dimstack:bedrock)
Block(-5,7,8,dimstack:bedrock)

#######################################################################
# +-----------------------------------------------------------------+ #
# |                             Branches                            | #
# +-----------------------------------------------------------------+ #
#######################################################################

Branch(0,0,16,true,TeleportReceiverFG_C1R1,NORTH,100.0,0)

#######################################################################
# +-----------------------------------------------------------------+ #
# |                             Entities                            | #
# +-----------------------------------------------------------------+ #
#######################################################################


#######################################################################
# +-----------------------------------------------------------------+ #
# |                            Particles                            | #
# +-----------------------------------------------------------------+ #
#######################################################################


#######################################################################
# +-----------------------------------------------------------------+ #
# |                             Spawners                            | #
# +-----------------------------------------------------------------+ #
#######################################################################


#######################################################################
# +-----------------------------------------------------------------+ #
# |                             ModData                             | #
# +-----------------------------------------------------------------+ #
#######################################################################

