
#######################################################################
# +-----------------------------------------------------------------+ #
# |                            BO3 object                           | #
# +-----------------------------------------------------------------+ #
#######################################################################

Author: NLBlackHeavenNL

Description: No description given

Version: 3

SettingsMode: WriteWithoutComments


#######################################################################
# +-----------------------------------------------------------------+ #
# |                          Main settings                          | #
# +-----------------------------------------------------------------+ #
#######################################################################

Tree: true

Frequency: 1

Rarity: 100.0

RotateRandomly: false

SpawnHeight: highestSolidBlock

SpawnHeightOffset: 0

SpawnHeightVariance: 0

##############################
# Height Limits for the BO3. #
##############################

MinHeight: 0

MaxHeight: 255

######################
# Extrusion settings #
######################

ExtrudeMode: None

ExtrudeThroughBlocks: AIR

MaxBranchDepth: 10

ExcludedBiomes: All


#######################################################################
# +-----------------------------------------------------------------+ #
# |                      Source block settings                      | #
# +-----------------------------------------------------------------+ #
#######################################################################

SourceBlocks: AIR,GRASS,DIRT,biomesoplenty:dirt,dynamictrees:leaves1

MaxPercentageOutsideSourceBlock: 0

OutsideSourceBlock: placeAnyway

DoReplaceBlocks: true

IsOTGPlus: false


#######################################################################
# +-----------------------------------------------------------------+ #
# |                              Blocks                             | #
# +-----------------------------------------------------------------+ #
#######################################################################

Block(-8,7,-4,dynamictrees:leaves1:4)
Block(-8,7,-3,dynamictrees:leaves1:4)
Block(-8,7,-2,dynamictrees:leaves1:4)
Block(-7,6,-4,dynamictrees:leaves1:4)
Block(-7,6,-3,dynamictrees:leaves1:4)
Block(-7,6,-2,dynamictrees:leaves1:4)
Block(-7,7,-6,dynamictrees:leaves1:4)
Block(-7,7,-5,dynamictrees:leaves1:4)
Block(-7,7,-4,dynamictrees:leaves1:5)
Block(-7,7,-3,dynamictrees:leaves1:5)
Block(-7,7,-2,dynamictrees:leaves1:5)
Block(-7,7,-1,dynamictrees:leaves1:4)
Block(-7,8,-4,dynamictrees:leaves1:4)
Block(-7,8,-3,dynamictrees:leaves1:4)
Block(-7,8,-2,dynamictrees:leaves1:4)
Block(-7,8,-1,dynamictrees:leaves1:4)
Block(-7,8,0,dynamictrees:leaves1:4)
Block(-7,8,1,dynamictrees:leaves1:4)
Block(-7,8,4,dynamictrees:leaves1:4)
Block(-7,8,5,dynamictrees:leaves1:4)
Block(-6,6,-6,dynamictrees:leaves1:4)
Block(-6,6,-5,dynamictrees:leaves1:4)
Block(-6,7,-7,dynamictrees:leaves1:4)
Block(-6,7,-6,dynamictrees:leaves1:5)
Block(-6,7,-5,dynamictrees:leaves1:5)
Block(-6,7,-4,dynamictrees:leaves1:6)
Block(-6,7,-3,dynamictrees:leaves1:7)
Block(-6,7,-2,dynamictrees:leaves1:6)
Block(-6,7,-1,dynamictrees:leaves1:5)
Block(-6,7,0,dynamictrees:leaves1:4)
Block(-6,7,1,dynamictrees:leaves1:4)
Block(-6,7,4,dynamictrees:leaves1:4)
Block(-6,7,5,dynamictrees:leaves1:4)
Block(-6,8,-6,dynamictrees:leaves1:4)
Block(-6,8,-5,dynamictrees:leaves1:4)
Block(-6,8,-4,dynamictrees:leaves1:5)
Block(-6,8,-3,dynamictrees:leaves1:5)
Block(-6,8,-2,dynamictrees:leaves1:5)
Block(-6,8,-1,dynamictrees:leaves1:5)
Block(-6,8,0,dynamictrees:leaves1:5)
Block(-6,8,1,dynamictrees:leaves1:5)
Block(-6,8,2,dynamictrees:leaves1:4)
Block(-6,8,3,dynamictrees:leaves1:4)
Block(-6,8,4,dynamictrees:leaves1:5)
Block(-6,8,5,dynamictrees:leaves1:5)
Block(-6,8,6,dynamictrees:leaves1:4)
Block(-6,9,-4,dynamictrees:leaves1:4)
Block(-6,9,-3,dynamictrees:leaves1:4)
Block(-6,9,-2,dynamictrees:leaves1:4)
Block(-6,9,-1,dynamictrees:leaves1:4)
Block(-6,9,0,dynamictrees:leaves1:4)
Block(-6,9,1,dynamictrees:leaves1:4)
Block(-6,9,4,dynamictrees:leaves1:4)
Block(-6,9,5,dynamictrees:leaves1:4)
Block(-5,6,-7,dynamictrees:leaves1:4)
Block(-5,7,-8,dynamictrees:leaves1:4)
Block(-5,7,-7,dynamictrees:leaves1:5)
Block(-5,7,-6,dynamictrees:leaves1:6)
Block(-5,7,-5,dynamictrees:leaves1:7)
Block(-5,7,-4,dynamictrees:leaves1:7)
Block(-5,7,-3,dynamictrees:darkoakbranch)
Block(-5,7,2,dynamictrees:leaves1:4)
Block(-5,7,6,dynamictrees:leaves1:4)
Block(-5,8,-7,dynamictrees:leaves1:4)
Block(-5,8,-6,dynamictrees:leaves1:5)
Block(-5,8,-5,dynamictrees:leaves1:5)
Block(-5,8,-4,dynamictrees:leaves1:5)
Block(-5,8,-3,dynamictrees:leaves1:7)
Block(-5,8,-2,dynamictrees:leaves1:6)
Block(-5,8,-1,dynamictrees:leaves1:6)
Block(-5,8,0,dynamictrees:leaves1:7)
Block(-5,8,1,dynamictrees:leaves1:6)
Block(-5,8,2,dynamictrees:leaves1:5)
Block(-5,8,3,dynamictrees:leaves1:5)
Block(-5,8,4,dynamictrees:leaves1:7)
Block(-5,8,5,dynamictrees:leaves1:6)
Block(-5,8,6,dynamictrees:leaves1:5)
Block(-5,8,7,dynamictrees:leaves1:4)
Block(-5,9,-6,dynamictrees:leaves1:4)
Block(-5,9,-5,dynamictrees:leaves1:4)
Block(-5,9,-4,dynamictrees:leaves1:4)
Block(-5,9,-3,dynamictrees:leaves1:5)
Block(-5,9,-2,dynamictrees:leaves1:5)
Block(-5,9,-1,dynamictrees:leaves1:5)
Block(-5,9,0,dynamictrees:leaves1:5)
Block(-5,9,1,dynamictrees:leaves1:5)
Block(-5,9,2,dynamictrees:leaves1:4)
Block(-5,9,3,dynamictrees:leaves1:4)
Block(-5,9,4,dynamictrees:leaves1:5)
Block(-5,9,5,dynamictrees:leaves1:5)
Block(-5,9,6,dynamictrees:leaves1:4)
Block(-5,10,-3,dynamictrees:leaves1:4)
Block(-5,10,-2,dynamictrees:leaves1:4)
Block(-5,10,-1,dynamictrees:leaves1:4)
Block(-5,10,0,dynamictrees:leaves1:4)
Block(-5,10,1,dynamictrees:leaves1:4)
Block(-5,10,4,dynamictrees:leaves1:4)
Block(-5,10,5,dynamictrees:leaves1:4)
Block(-4,6,-7,dynamictrees:leaves1:4)
Block(-4,7,-8,dynamictrees:leaves1:4)
Block(-4,7,-7,dynamictrees:leaves1:5)
Block(-4,7,-6,dynamictrees:leaves1:7)
Block(-4,7,-5,dynamictrees:darkoakbranch)
Block(-4,7,-4,dynamictrees:darkoakbranch:1)
Block(-4,7,-3,dynamictrees:darkoakbranch:1)
Block(-4,7,6,dynamictrees:leaves1:4)
Block(-4,8,-7,dynamictrees:leaves1:4)
Block(-4,8,-6,dynamictrees:leaves1:5)
Block(-4,8,-5,dynamictrees:leaves1:7)
Block(-4,8,-4,dynamictrees:leaves1:5)
Block(-4,8,-3,dynamictrees:leaves1:6)
Block(-4,8,-2,dynamictrees:leaves1:7)
Block(-4,8,-1,dynamictrees:leaves1:7)
Block(-4,8,0,dynamictrees:darkoakbranch)
Block(-4,8,2,dynamictrees:leaves1:6)
Block(-4,8,3,dynamictrees:darkoakbranch:1)
Block(-4,8,4,dynamictrees:darkoakbranch)
Block(-4,8,5,dynamictrees:leaves1:7)
Block(-4,8,6,dynamictrees:leaves1:5)
Block(-4,8,7,dynamictrees:leaves1:4)
Block(-4,9,-6,dynamictrees:leaves1:4)
Block(-4,9,-5,dynamictrees:leaves1:5)
Block(-4,9,-4,dynamictrees:leaves1:4)
Block(-4,9,-3,dynamictrees:leaves1:5)
Block(-4,9,-2,dynamictrees:leaves1:5)
Block(-4,9,-1,dynamictrees:leaves1:5)
Block(-4,9,0,dynamictrees:leaves1:7)
Block(-4,9,1,dynamictrees:leaves1:6)
Block(-4,9,2,dynamictrees:leaves1:5)
Block(-4,9,3,dynamictrees:leaves1:5)
Block(-4,9,4,dynamictrees:leaves1:7)
Block(-4,9,5,dynamictrees:leaves1:5)
Block(-4,9,6,dynamictrees:leaves1:4)
Block(-4,10,-5,dynamictrees:leaves1:4)
Block(-4,10,-3,dynamictrees:leaves1:4)
Block(-4,10,-2,dynamictrees:leaves1:4)
Block(-4,10,-1,dynamictrees:leaves1:4)
Block(-4,10,0,dynamictrees:leaves1:5)
Block(-4,10,1,dynamictrees:leaves1:5)
Block(-4,10,2,dynamictrees:leaves1:4)
Block(-4,10,3,dynamictrees:leaves1:4)
Block(-4,10,4,dynamictrees:leaves1:5)
Block(-4,10,5,dynamictrees:leaves1:4)
Block(-4,11,0,dynamictrees:leaves1:4)
Block(-4,11,1,dynamictrees:leaves1:4)
Block(-4,11,4,dynamictrees:leaves1:4)
Block(-3,6,-7,dynamictrees:leaves1:4)
Block(-3,7,-8,dynamictrees:leaves1:4)
Block(-3,7,-7,dynamictrees:leaves1:5)
Block(-3,7,-6,dynamictrees:leaves1:6)
Block(-3,7,-5,dynamictrees:leaves1:7)
Block(-3,7,-3,dynamictrees:darkoakbranch:2)
Block(-3,7,6,dynamictrees:leaves1:4)
Block(-3,7,7,dynamictrees:leaves1:4)
Block(-3,8,-7,dynamictrees:leaves1:4)
Block(-3,8,-6,dynamictrees:leaves1:5)
Block(-3,8,-5,dynamictrees:leaves1:5)
Block(-3,8,-4,dynamictrees:leaves1:6)
Block(-3,8,-3,dynamictrees:leaves1:7)
Block(-3,8,-2,dynamictrees:darkoakbranch)
Block(-3,8,-1,dynamictrees:darkoakbranch:1)
Block(-3,8,0,dynamictrees:darkoakbranch:1)
Block(-3,8,1,dynamictrees:darkoakbranch)
Block(-3,8,2,dynamictrees:leaves1:7)
Block(-3,8,3,dynamictrees:darkoakbranch:1)
Block(-3,8,5,dynamictrees:leaves1:6)
Block(-3,8,6,dynamictrees:leaves1:5)
Block(-3,8,7,dynamictrees:leaves1:5)
Block(-3,8,8,dynamictrees:leaves1:4)
Block(-3,9,-6,dynamictrees:leaves1:4)
Block(-3,9,-5,dynamictrees:leaves1:4)
Block(-3,9,-4,dynamictrees:leaves1:5)
Block(-3,9,-3,dynamictrees:leaves1:5)
Block(-3,9,-2,dynamictrees:leaves1:7)
Block(-3,9,-1,dynamictrees:leaves1:5)
Block(-3,9,1,dynamictrees:leaves1:7)
Block(-3,9,2,dynamictrees:leaves1:5)
Block(-3,9,3,dynamictrees:leaves1:5)
Block(-3,9,4,dynamictrees:leaves1:6)
Block(-3,9,5,dynamictrees:leaves1:5)
Block(-3,9,6,dynamictrees:leaves1:4)
Block(-3,9,7,dynamictrees:leaves1:4)
Block(-3,10,-4,dynamictrees:leaves1:4)
Block(-3,10,-3,dynamictrees:leaves1:4)
Block(-3,10,-2,dynamictrees:leaves1:5)
Block(-3,10,-1,dynamictrees:leaves1:4)
Block(-3,10,0,dynamictrees:leaves1:4)
Block(-3,10,1,dynamictrees:leaves1:5)
Block(-3,10,2,dynamictrees:leaves1:4)
Block(-3,10,3,dynamictrees:leaves1:4)
Block(-3,10,4,dynamictrees:leaves1:5)
Block(-3,10,5,dynamictrees:leaves1:4)
Block(-3,11,-2,dynamictrees:leaves1:4)
Block(-3,11,0,dynamictrees:leaves1:4)
Block(-3,11,1,dynamictrees:leaves1:4)
Block(-3,11,4,dynamictrees:leaves1:4)
Block(-3,12,0,dynamictrees:leaves1:4)
Block(-3,12,1,dynamictrees:leaves1:4)
Block(-3,12,2,dynamictrees:leaves1:4)
Block(-2,6,-6,dynamictrees:leaves1:4)
Block(-2,7,-7,dynamictrees:leaves1:4)
Block(-2,7,-6,dynamictrees:leaves1:5)
Block(-2,7,-5,dynamictrees:leaves1:7)
Block(-2,7,-4,dynamictrees:darkoakbranch)
Block(-2,7,-3,dynamictrees:darkoakbranch:2)
Block(-2,7,-2,dynamictrees:darkoakbranch:3)
Block(-2,7,8,dynamictrees:leaves1:4)
Block(-2,8,-6,dynamictrees:leaves1:4)
Block(-2,8,-5,dynamictrees:leaves1:5)
Block(-2,8,-4,dynamictrees:leaves1:7)
Block(-2,8,-3,dynamictrees:leaves1:6)
Block(-2,8,-2,dynamictrees:leaves1:7)
Block(-2,8,-1,dynamictrees:leaves1:7)
Block(-2,8,0,dynamictrees:darkoakbranch:2)
Block(-2,8,2,dynamictrees:darkoakbranch:2)
Block(-2,8,3,dynamictrees:darkoakbranch:2)
Block(-2,8,4,dynamictrees:darkoakbranch)
Block(-2,8,5,dynamictrees:leaves1:7)
Block(-2,8,6,dynamictrees:leaves1:7)
Block(-2,8,7,dynamictrees:leaves1:6)
Block(-2,8,8,dynamictrees:leaves1:5)
Block(-2,8,9,dynamictrees:leaves1:4)
Block(-2,9,-5,dynamictrees:leaves1:4)
Block(-2,9,-4,dynamictrees:leaves1:5)
Block(-2,9,-3,dynamictrees:leaves1:5)
Block(-2,9,-2,dynamictrees:leaves1:5)
Block(-2,9,-1,dynamictrees:leaves1:5)
Block(-2,9,3,dynamictrees:leaves1:5)
Block(-2,9,4,dynamictrees:leaves1:7)
Block(-2,9,5,dynamictrees:leaves1:5)
Block(-2,9,6,dynamictrees:leaves1:5)
Block(-2,9,7,dynamictrees:leaves1:5)
Block(-2,9,8,dynamictrees:leaves1:4)
Block(-2,10,-4,dynamictrees:leaves1:4)
Block(-2,10,-3,dynamictrees:leaves1:4)
Block(-2,10,-2,dynamictrees:leaves1:4)
Block(-2,10,-1,dynamictrees:leaves1:4)
Block(-2,10,3,dynamictrees:leaves1:4)
Block(-2,10,4,dynamictrees:leaves1:5)
Block(-2,10,5,dynamictrees:leaves1:4)
Block(-2,10,6,dynamictrees:leaves1:4)
Block(-2,10,7,dynamictrees:leaves1:4)
Block(-2,11,0,dynamictrees:leaves1:4)
Block(-2,11,1,dynamictrees:leaves1:4)
Block(-2,11,2,dynamictrees:leaves1:4)
Block(-2,11,4,dynamictrees:leaves1:4)
Block(-2,12,-1,dynamictrees:leaves1:4)
Block(-2,12,0,dynamictrees:leaves1:5)
Block(-2,12,1,dynamictrees:leaves1:5)
Block(-2,12,2,dynamictrees:leaves1:5)
Block(-2,12,3,dynamictrees:leaves1:4)
Block(-2,13,0,dynamictrees:leaves1:4)
Block(-2,13,1,dynamictrees:leaves1:4)
Block(-2,13,2,dynamictrees:leaves1:4)
Block(-1,0,-2,dynamictrees:darkoakroot)
Block(-1,0,4,dynamictrees:darkoakroot)
Block(-1,1,-1,dynamictrees:darkoakroot:1)
Block(-1,6,-6,dynamictrees:leaves1:4)
Block(-1,7,-7,dynamictrees:leaves1:4)
Block(-1,7,-6,dynamictrees:leaves1:5)
Block(-1,7,-5,dynamictrees:leaves1:6)
Block(-1,7,-4,dynamictrees:leaves1:7)
Block(-1,7,-2,dynamictrees:darkoakbranch:3)
Block(-1,7,8,dynamictrees:leaves1:4)
Block(-1,8,-6,dynamictrees:leaves1:4)
Block(-1,8,-5,dynamictrees:leaves1:5)
Block(-1,8,-4,dynamictrees:leaves1:5)
Block(-1,8,-3,dynamictrees:leaves1:5)
Block(-1,8,-1,dynamictrees:darkoakbranch)
Block(-1,8,0,dynamictrees:darkoakbranch:2)
Block(-1,8,1,dynamictrees:darkoakbranch:4)
Block(-1,8,2,dynamictrees:darkoakbranch:2)
Block(-1,8,4,dynamictrees:leaves1:7)
Block(-1,8,5,dynamictrees:leaves1:7)
Block(-1,8,6,dynamictrees:darkoakbranch)
Block(-1,8,7,dynamictrees:leaves1:7)
Block(-1,8,8,dynamictrees:leaves1:5)
Block(-1,8,9,dynamictrees:leaves1:4)
Block(-1,9,-5,dynamictrees:leaves1:4)
Block(-1,9,-4,dynamictrees:leaves1:4)
Block(-1,9,-3,dynamictrees:leaves1:4)
Block(-1,9,-1,dynamictrees:leaves1:7)
Block(-1,9,4,dynamictrees:leaves1:5)
Block(-1,9,5,dynamictrees:leaves1:5)
Block(-1,9,6,dynamictrees:leaves1:7)
Block(-1,9,7,dynamictrees:leaves1:5)
Block(-1,9,8,dynamictrees:leaves1:4)
Block(-1,10,-3,dynamictrees:leaves1:4)
Block(-1,10,4,dynamictrees:leaves1:4)
Block(-1,10,5,dynamictrees:leaves1:4)
Block(-1,10,6,dynamictrees:leaves1:5)
Block(-1,10,7,dynamictrees:leaves1:4)
Block(-1,11,-1,dynamictrees:leaves1:4)
Block(-1,11,3,dynamictrees:leaves1:4)
Block(-1,11,6,dynamictrees:leaves1:4)
Block(-1,12,-2,dynamictrees:leaves1:4)
Block(-1,12,-1,dynamictrees:leaves1:5)
Block(-1,12,0,dynamictrees:leaves1:6)
Block(-1,12,1,dynamictrees:leaves1:7)
Block(-1,12,2,dynamictrees:leaves1:5)
Block(-1,12,3,dynamictrees:leaves1:5)
Block(-1,12,4,dynamictrees:leaves1:4)
Block(-1,13,-1,dynamictrees:leaves1:4)
Block(-1,13,0,dynamictrees:leaves1:5)
Block(-1,13,1,dynamictrees:leaves1:5)
Block(-1,13,2,dynamictrees:leaves1:5)
Block(-1,13,3,dynamictrees:leaves1:4)
Block(-1,14,0,dynamictrees:leaves1:4)
Block(-1,14,1,dynamictrees:leaves1:4)
Block(-1,14,2,dynamictrees:leaves1:4)
Block(0,0,4,dynamictrees:darkoakroot:1)
Block(0,1,-1,dynamictrees:darkoakroot:2)
Block(0,1,3,dynamictrees:darkoakroot:2)
Block(0,2,0,dynamictrees:darkoakroot:3)
Block(0,2,1,dynamictrees:darkoakroot:4)
Block(0,2,2,dynamictrees:trunkshell:7)
Block(0,3,0,dynamictrees:trunkshell:5)
Block(0,3,1,dynamictrees:trunkshell:6)
Block(0,3,2,dynamictrees:trunkshell:7)
Block(0,4,0,dynamictrees:trunkshell:5)
Block(0,4,1,dynamictrees:trunkshell:6)
Block(0,4,2,dynamictrees:trunkshell:7)
Block(0,5,0,dynamictrees:trunkshell:5)
Block(0,5,1,dynamictrees:trunkshell:6)
Block(0,5,2,dynamictrees:trunkshell:7)
Block(0,6,0,dynamictrees:trunkshell:5)
Block(0,6,1,dynamictrees:trunkshell:6)
Block(0,6,2,dynamictrees:trunkshell:7)
Block(0,7,-6,dynamictrees:leaves1:4)
Block(0,7,-3,dynamictrees:darkoakbranch:1)
Block(0,7,-2,dynamictrees:darkoakbranch:4)
Block(0,7,-1,dynamictrees:darkoakbranch:4)
Block(0,7,0,dynamictrees:trunkshell:5)
Block(0,7,1,dynamictrees:trunkshell:6)
Block(0,7,2,dynamictrees:trunkshell:7)
Block(0,7,8,dynamictrees:leaves1:4)
Block(0,7,9,dynamictrees:leaves1:4)
Block(0,8,-5,dynamictrees:leaves1:4)
Block(0,8,-4,dynamictrees:leaves1:5)
Block(0,8,-3,dynamictrees:leaves1:4)
Block(0,8,0,dynamictrees:trunkshell:5)
Block(0,8,1,dynamictrees:darkoakbranch:4)
Block(0,8,2,dynamictrees:trunkshell:7)
Block(0,8,3,dynamictrees:darkoakbranch:2)
Block(0,8,4,dynamictrees:darkoakbranch:1)
Block(0,8,5,dynamictrees:darkoakbranch:1)
Block(0,8,6,dynamictrees:darkoakbranch:1)
Block(0,8,7,dynamictrees:leaves1:5)
Block(0,8,8,dynamictrees:leaves1:5)
Block(0,8,9,dynamictrees:leaves1:5)
Block(0,8,10,dynamictrees:leaves1:4)
Block(0,9,-6,dynamictrees:leaves1:4)
Block(0,9,-5,dynamictrees:leaves1:5)
Block(0,9,-4,dynamictrees:leaves1:5)
Block(0,9,-3,dynamictrees:leaves1:4)
Block(0,9,-1,dynamictrees:darkoakbranch)
Block(0,9,5,dynamictrees:leaves1:4)
Block(0,9,6,dynamictrees:leaves1:5)
Block(0,9,7,dynamictrees:leaves1:4)
Block(0,9,8,dynamictrees:leaves1:4)
Block(0,9,9,dynamictrees:leaves1:4)
Block(0,10,-5,dynamictrees:leaves1:4)
Block(0,10,-4,dynamictrees:leaves1:4)
Block(0,10,1,dynamictrees:darkoakbranch)
Block(0,10,6,dynamictrees:leaves1:4)
Block(0,11,-2,dynamictrees:leaves1:4)
Block(0,11,4,dynamictrees:leaves1:4)
Block(0,12,-3,dynamictrees:leaves1:4)
Block(0,12,-2,dynamictrees:leaves1:5)
Block(0,12,-1,dynamictrees:leaves1:6)
Block(0,12,1,dynamictrees:darkoakbranch)
Block(0,12,3,dynamictrees:leaves1:6)
Block(0,12,4,dynamictrees:leaves1:5)
Block(0,12,5,dynamictrees:leaves1:4)
Block(0,13,-2,dynamictrees:leaves1:4)
Block(0,13,-1,dynamictrees:leaves1:5)
Block(0,13,0,dynamictrees:leaves1:6)
Block(0,13,1,dynamictrees:leaves1:7)
Block(0,13,2,dynamictrees:leaves1:6)
Block(0,13,3,dynamictrees:leaves1:5)
Block(0,13,4,dynamictrees:leaves1:4)
Block(0,14,-1,dynamictrees:leaves1:4)
Block(0,14,0,dynamictrees:leaves1:5)
Block(0,14,1,dynamictrees:leaves1:5)
Block(0,14,2,dynamictrees:leaves1:5)
Block(0,14,3,dynamictrees:leaves1:4)
Block(0,15,0,dynamictrees:leaves1:4)
Block(0,15,1,dynamictrees:leaves1:4)
Block(0,15,2,dynamictrees:leaves1:4)
Block(1,1,1,dynamictrees:rootydirt:0)
Block(1,1,3,dynamictrees:darkoakroot:3)
Block(1,2,0,dynamictrees:trunkshell)
Block(1,2,1,dynamictrees:darkoakbranch:14)
Block(1,2,2,dynamictrees:darkoakroot:4)
Block(1,3,0,dynamictrees:trunkshell)
Block(1,3,1,dynamictrees:darkoakbranch:13)
Block(1,3,2,dynamictrees:trunkshell:0)
Block(1,4,0,dynamictrees:trunkshell)
Block(1,4,1,dynamictrees:darkoakbranch:12)
Block(1,4,2,dynamictrees:trunkshell:0)
Block(1,5,0,dynamictrees:trunkshell)
Block(1,5,1,dynamictrees:darkoakbranch:12)
Block(1,5,2,dynamictrees:trunkshell:0)
Block(1,6,0,dynamictrees:trunkshell)
Block(1,6,1,dynamictrees:darkoakbranch:12)
Block(1,6,2,dynamictrees:trunkshell:0)
Block(1,7,-4,dynamictrees:darkoakbranch)
Block(1,7,-3,dynamictrees:darkoakbranch:1)
Block(1,7,-1,dynamictrees:darkoakbranch:5)
Block(1,7,0,dynamictrees:darkoakbranch:5)
Block(1,7,1,dynamictrees:darkoakbranch:11)
Block(1,7,2,dynamictrees:trunkshell:0)
Block(1,8,-6,dynamictrees:leaves1:4)
Block(1,8,-4,dynamictrees:leaves1:7)
Block(1,8,0,dynamictrees:trunkshell)
Block(1,8,1,dynamictrees:darkoakbranch:9)
Block(1,8,2,dynamictrees:darkoakbranch:4)
Block(1,8,3,dynamictrees:darkoakbranch:4)
Block(1,8,6,dynamictrees:leaves1:4)
Block(1,8,7,dynamictrees:leaves1:5)
Block(1,8,8,dynamictrees:leaves1:7)
Block(1,8,9,dynamictrees:leaves1:6)
Block(1,8,10,dynamictrees:leaves1:5)
Block(1,9,-7,dynamictrees:leaves1:4)
Block(1,9,-6,dynamictrees:leaves1:5)
Block(1,9,-5,dynamictrees:leaves1:6)
Block(1,9,-4,dynamictrees:leaves1:7)
Block(1,9,-1,dynamictrees:darkoakbranch:3)
Block(1,9,0,dynamictrees:darkoakbranch:4)
Block(1,9,1,dynamictrees:darkoakbranch:6)
Block(1,9,6,dynamictrees:leaves1:4)
Block(1,9,7,dynamictrees:leaves1:4)
Block(1,9,8,dynamictrees:leaves1:5)
Block(1,9,9,dynamictrees:leaves1:5)
Block(1,9,10,dynamictrees:leaves1:4)
Block(1,10,-6,dynamictrees:leaves1:4)
Block(1,10,-5,dynamictrees:leaves1:5)
Block(1,10,-4,dynamictrees:leaves1:5)
Block(1,10,-3,dynamictrees:leaves1:4)
Block(1,10,1,dynamictrees:darkoakbranch:1)
Block(1,10,8,dynamictrees:leaves1:4)
Block(1,10,9,dynamictrees:leaves1:4)
Block(1,11,-5,dynamictrees:leaves1:4)
Block(1,11,-4,dynamictrees:leaves1:4)
Block(1,11,-2,dynamictrees:leaves1:4)
Block(1,11,1,dynamictrees:darkoakbranch:1)
Block(1,11,4,dynamictrees:leaves1:4)
Block(1,12,-3,dynamictrees:leaves1:4)
Block(1,12,-2,dynamictrees:leaves1:5)
Block(1,12,-1,dynamictrees:leaves1:7)
Block(1,12,0,dynamictrees:darkoakbranch)
Block(1,12,1,dynamictrees:darkoakbranch:1)
Block(1,12,2,dynamictrees:darkoakbranch)
Block(1,12,3,dynamictrees:leaves1:7)
Block(1,12,4,dynamictrees:leaves1:5)
Block(1,12,5,dynamictrees:leaves1:4)
Block(1,13,-2,dynamictrees:leaves1:4)
Block(1,13,-1,dynamictrees:leaves1:5)
Block(1,13,0,dynamictrees:leaves1:7)
Block(1,13,1,dynamictrees:leaves1:6)
Block(1,13,2,dynamictrees:leaves1:7)
Block(1,13,3,dynamictrees:leaves1:5)
Block(1,13,4,dynamictrees:leaves1:4)
Block(1,14,-1,dynamictrees:leaves1:4)
Block(1,14,0,dynamictrees:leaves1:5)
Block(1,14,1,dynamictrees:leaves1:5)
Block(1,14,2,dynamictrees:leaves1:5)
Block(1,14,3,dynamictrees:leaves1:4)
Block(1,15,0,dynamictrees:leaves1:4)
Block(1,15,1,dynamictrees:leaves1:4)
Block(1,15,2,dynamictrees:leaves1:4)
Block(2,1,3,dynamictrees:darkoakroot)
Block(2,2,0,dynamictrees:trunkshell:3)
Block(2,2,1,dynamictrees:darkoakroot:4)
Block(2,2,2,dynamictrees:trunkshell:1)
Block(2,3,0,dynamictrees:trunkshell:3)
Block(2,3,1,dynamictrees:trunkshell:2)
Block(2,3,2,dynamictrees:trunkshell:1)
Block(2,4,0,dynamictrees:trunkshell:3)
Block(2,4,1,dynamictrees:trunkshell:2)
Block(2,4,2,dynamictrees:trunkshell:1)
Block(2,5,0,dynamictrees:trunkshell:3)
Block(2,5,1,dynamictrees:trunkshell:2)
Block(2,5,2,dynamictrees:trunkshell:1)
Block(2,6,0,dynamictrees:trunkshell:3)
Block(2,6,1,dynamictrees:trunkshell:2)
Block(2,6,2,dynamictrees:trunkshell:1)
Block(2,7,-1,dynamictrees:darkoakbranch:1)
Block(2,7,0,dynamictrees:trunkshell:3)
Block(2,7,1,dynamictrees:darkoakbranch:2)
Block(2,7,2,dynamictrees:trunkshell:1)
Block(2,8,-6,dynamictrees:leaves1:4)
Block(2,8,0,dynamictrees:trunkshell:3)
Block(2,8,1,dynamictrees:trunkshell:2)
Block(2,8,2,dynamictrees:trunkshell:1)
Block(2,8,3,dynamictrees:darkoakbranch:3)
Block(2,8,4,dynamictrees:darkoakbranch:2)
Block(2,8,5,dynamictrees:darkoakbranch:1)
Block(2,8,6,dynamictrees:darkoakbranch:1)
Block(2,8,7,dynamictrees:darkoakbranch:1)
Block(2,8,8,dynamictrees:darkoakbranch)
Block(2,8,9,dynamictrees:leaves1:7)
Block(2,8,10,dynamictrees:leaves1:5)
Block(2,9,-7,dynamictrees:leaves1:4)
Block(2,9,-6,dynamictrees:leaves1:5)
Block(2,9,-5,dynamictrees:leaves1:7)
Block(2,9,-4,dynamictrees:darkoakbranch)
Block(2,9,-3,dynamictrees:darkoakbranch:1)
Block(2,9,-2,dynamictrees:darkoakbranch:2)
Block(2,9,-1,dynamictrees:darkoakbranch:3)
Block(2,9,1,dynamictrees:darkoakbranch:4)
Block(2,9,5,dynamictrees:leaves1:4)
Block(2,9,6,dynamictrees:leaves1:4)
Block(2,9,7,dynamictrees:leaves1:5)
Block(2,9,8,dynamictrees:leaves1:7)
Block(2,9,9,dynamictrees:leaves1:5)
Block(2,9,10,dynamictrees:leaves1:4)
Block(2,10,-6,dynamictrees:leaves1:4)
Block(2,10,-5,dynamictrees:leaves1:5)
Block(2,10,-4,dynamictrees:leaves1:7)
Block(2,10,-3,dynamictrees:leaves1:5)
Block(2,10,7,dynamictrees:leaves1:4)
Block(2,10,8,dynamictrees:leaves1:5)
Block(2,10,9,dynamictrees:leaves1:4)
Block(2,11,-5,dynamictrees:leaves1:4)
Block(2,11,-4,dynamictrees:leaves1:5)
Block(2,11,-3,dynamictrees:leaves1:4)
Block(2,11,-2,dynamictrees:leaves1:4)
Block(2,11,4,dynamictrees:leaves1:4)
Block(2,11,8,dynamictrees:leaves1:4)
Block(2,12,-4,dynamictrees:leaves1:4)
Block(2,12,-3,dynamictrees:leaves1:4)
Block(2,12,-2,dynamictrees:leaves1:5)
Block(2,12,-1,dynamictrees:leaves1:6)
Block(2,12,1,dynamictrees:darkoakbranch)
Block(2,12,3,dynamictrees:leaves1:6)
Block(2,12,4,dynamictrees:leaves1:5)
Block(2,12,5,dynamictrees:leaves1:4)
Block(2,13,-2,dynamictrees:leaves1:4)
Block(2,13,-1,dynamictrees:leaves1:5)
Block(2,13,0,dynamictrees:leaves1:6)
Block(2,13,1,dynamictrees:leaves1:7)
Block(2,13,2,dynamictrees:leaves1:6)
Block(2,13,3,dynamictrees:leaves1:5)
Block(2,13,4,dynamictrees:leaves1:4)
Block(2,14,-1,dynamictrees:leaves1:4)
Block(2,14,0,dynamictrees:leaves1:5)
Block(2,14,1,dynamictrees:leaves1:5)
Block(2,14,2,dynamictrees:leaves1:5)
Block(2,14,3,dynamictrees:leaves1:4)
Block(2,15,0,dynamictrees:leaves1:4)
Block(2,15,1,dynamictrees:leaves1:4)
Block(2,15,2,dynamictrees:leaves1:4)
Block(3,1,0,dynamictrees:darkoakroot)
Block(3,1,1,dynamictrees:darkoakroot:3)
Block(3,1,2,dynamictrees:darkoakroot:2)
Block(3,7,-1,dynamictrees:darkoakbranch:1)
Block(3,7,1,dynamictrees:darkoakbranch:1)
Block(3,7,2,dynamictrees:darkoakbranch:1)
Block(3,7,10,dynamictrees:leaves1:4)
Block(3,8,-6,dynamictrees:leaves1:4)
Block(3,8,4,dynamictrees:darkoakbranch:1)
Block(3,8,5,dynamictrees:leaves1:7)
Block(3,8,6,dynamictrees:leaves1:6)
Block(3,8,7,dynamictrees:leaves1:5)
Block(3,8,8,dynamictrees:leaves1:7)
Block(3,8,9,dynamictrees:leaves1:6)
Block(3,8,10,dynamictrees:leaves1:5)
Block(3,8,11,dynamictrees:leaves1:4)
Block(3,9,-7,dynamictrees:leaves1:4)
Block(3,9,-6,dynamictrees:leaves1:5)
Block(3,9,-5,dynamictrees:leaves1:6)
Block(3,9,-4,dynamictrees:leaves1:7)
Block(3,9,-3,dynamictrees:darkoakbranch:1)
Block(3,9,-1,dynamictrees:darkoakbranch:1)
Block(3,9,1,dynamictrees:darkoakbranch:3)
Block(3,9,2,dynamictrees:darkoakbranch:3)
Block(3,9,4,dynamictrees:leaves1:5)
Block(3,9,5,dynamictrees:leaves1:5)
Block(3,9,6,dynamictrees:leaves1:5)
Block(3,9,7,dynamictrees:leaves1:4)
Block(3,9,8,dynamictrees:leaves1:5)
Block(3,9,9,dynamictrees:leaves1:5)
Block(3,9,10,dynamictrees:leaves1:4)
Block(3,10,-6,dynamictrees:leaves1:4)
Block(3,10,-5,dynamictrees:leaves1:5)
Block(3,10,-4,dynamictrees:leaves1:5)
Block(3,10,-3,dynamictrees:leaves1:5)
Block(3,10,-2,dynamictrees:leaves1:5)
Block(3,10,4,dynamictrees:leaves1:4)
Block(3,10,5,dynamictrees:leaves1:4)
Block(3,10,6,dynamictrees:leaves1:4)
Block(3,10,8,dynamictrees:leaves1:4)
Block(3,10,9,dynamictrees:leaves1:4)
Block(3,11,-5,dynamictrees:leaves1:4)
Block(3,11,-4,dynamictrees:leaves1:4)
Block(3,11,-3,dynamictrees:leaves1:4)
Block(3,11,-2,dynamictrees:leaves1:4)
Block(3,11,-1,dynamictrees:leaves1:4)
Block(3,11,3,dynamictrees:leaves1:4)
Block(3,12,-2,dynamictrees:leaves1:4)
Block(3,12,-1,dynamictrees:leaves1:5)
Block(3,12,0,dynamictrees:leaves1:6)
Block(3,12,1,dynamictrees:leaves1:7)
Block(3,12,2,dynamictrees:leaves1:6)
Block(3,12,3,dynamictrees:leaves1:5)
Block(3,12,4,dynamictrees:leaves1:4)
Block(3,13,-1,dynamictrees:leaves1:4)
Block(3,13,0,dynamictrees:leaves1:5)
Block(3,13,1,dynamictrees:leaves1:5)
Block(3,13,2,dynamictrees:leaves1:5)
Block(3,13,3,dynamictrees:leaves1:4)
Block(3,14,0,dynamictrees:leaves1:4)
Block(3,14,1,dynamictrees:leaves1:4)
Block(3,14,2,dynamictrees:leaves1:4)
Block(4,0,2,dynamictrees:darkoakroot:1)
Block(4,0,3,dynamictrees:darkoakroot)
Block(4,7,-1,dynamictrees:darkoakbranch:1)
Block(4,7,2,dynamictrees:darkoakbranch:1)
Block(4,7,7,dynamictrees:leaves1:4)
Block(4,7,8,dynamictrees:leaves1:4)
Block(4,7,9,dynamictrees:leaves1:4)
Block(4,8,-5,dynamictrees:leaves1:4)
Block(4,8,3,dynamictrees:darkoakbranch)
Block(4,8,4,dynamictrees:darkoakbranch:1)
Block(4,8,5,dynamictrees:darkoakbranch)
Block(4,8,6,dynamictrees:leaves1:7)
Block(4,8,7,dynamictrees:leaves1:5)
Block(4,8,8,dynamictrees:leaves1:5)
Block(4,8,9,dynamictrees:leaves1:5)
Block(4,8,10,dynamictrees:leaves1:4)
Block(4,9,-6,dynamictrees:leaves1:4)
Block(4,9,-5,dynamictrees:leaves1:5)
Block(4,9,-4,dynamictrees:leaves1:7)
Block(4,9,-3,dynamictrees:darkoakbranch)
Block(4,9,-1,dynamictrees:darkoakbranch)
Block(4,9,2,dynamictrees:darkoakbranch:2)
Block(4,9,3,dynamictrees:leaves1:7)
Block(4,9,4,dynamictrees:leaves1:6)
Block(4,9,5,dynamictrees:leaves1:7)
Block(4,9,6,dynamictrees:leaves1:5)
Block(4,9,7,dynamictrees:leaves1:4)
Block(4,9,8,dynamictrees:leaves1:4)
Block(4,9,9,dynamictrees:leaves1:4)
Block(4,10,-5,dynamictrees:leaves1:4)
Block(4,10,-4,dynamictrees:leaves1:5)
Block(4,10,-3,dynamictrees:leaves1:7)
Block(4,10,-2,dynamictrees:leaves1:6)
Block(4,10,-1,dynamictrees:leaves1:7)
Block(4,10,3,dynamictrees:leaves1:5)
Block(4,10,4,dynamictrees:leaves1:5)
Block(4,10,5,dynamictrees:leaves1:5)
Block(4,10,6,dynamictrees:leaves1:4)
Block(4,11,-4,dynamictrees:leaves1:4)
Block(4,11,-3,dynamictrees:leaves1:5)
Block(4,11,-2,dynamictrees:leaves1:5)
Block(4,11,-1,dynamictrees:leaves1:5)
Block(4,11,0,dynamictrees:leaves1:4)
Block(4,11,1,dynamictrees:leaves1:4)
Block(4,11,2,dynamictrees:leaves1:4)
Block(4,11,3,dynamictrees:leaves1:4)
Block(4,11,4,dynamictrees:leaves1:4)
Block(4,11,5,dynamictrees:leaves1:4)
Block(4,12,-3,dynamictrees:leaves1:4)
Block(4,12,-2,dynamictrees:leaves1:4)
Block(4,12,-1,dynamictrees:leaves1:4)
Block(4,12,0,dynamictrees:leaves1:5)
Block(4,12,1,dynamictrees:leaves1:5)
Block(4,12,2,dynamictrees:leaves1:5)
Block(4,12,3,dynamictrees:leaves1:4)
Block(4,13,0,dynamictrees:leaves1:4)
Block(4,13,1,dynamictrees:leaves1:4)
Block(4,13,2,dynamictrees:leaves1:4)
Block(5,7,-1,dynamictrees:darkoakbranch)
Block(5,7,2,dynamictrees:darkoakbranch)
Block(5,8,-5,dynamictrees:leaves1:4)
Block(5,8,-1,dynamictrees:leaves1:7)
Block(5,8,6,dynamictrees:leaves1:5)
Block(5,8,7,dynamictrees:leaves1:4)
Block(5,8,8,dynamictrees:leaves1:4)
Block(5,8,9,dynamictrees:leaves1:4)
Block(5,9,-6,dynamictrees:leaves1:4)
Block(5,9,-5,dynamictrees:leaves1:5)
Block(5,9,-4,dynamictrees:leaves1:6)
Block(5,9,-3,dynamictrees:leaves1:7)
Block(5,9,-2,dynamictrees:leaves1:6)
Block(5,9,-1,dynamictrees:leaves1:7)
Block(5,9,2,dynamictrees:darkoakbranch:2)
Block(5,9,3,dynamictrees:darkoakbranch:1)
Block(5,9,4,dynamictrees:darkoakbranch:1)
Block(5,9,5,dynamictrees:leaves1:6)
Block(5,9,6,dynamictrees:leaves1:5)
Block(5,9,7,dynamictrees:leaves1:4)
Block(5,10,-5,dynamictrees:leaves1:4)
Block(5,10,-4,dynamictrees:leaves1:5)
Block(5,10,-3,dynamictrees:leaves1:5)
Block(5,10,-2,dynamictrees:leaves1:5)
Block(5,10,-1,dynamictrees:leaves1:5)
Block(5,10,0,dynamictrees:leaves1:4)
Block(5,10,1,dynamictrees:leaves1:5)
Block(5,10,2,dynamictrees:leaves1:5)
Block(5,10,3,dynamictrees:leaves1:4)
Block(5,10,4,dynamictrees:leaves1:5)
Block(5,10,5,dynamictrees:leaves1:5)
Block(5,10,6,dynamictrees:leaves1:4)
Block(5,11,-4,dynamictrees:leaves1:4)
Block(5,11,-3,dynamictrees:leaves1:4)
Block(5,11,-2,dynamictrees:leaves1:4)
Block(5,11,-1,dynamictrees:leaves1:4)
Block(5,11,1,dynamictrees:leaves1:4)
Block(5,11,2,dynamictrees:leaves1:4)
Block(5,11,4,dynamictrees:leaves1:4)
Block(5,11,5,dynamictrees:leaves1:4)
Block(5,12,0,dynamictrees:leaves1:4)
Block(5,12,1,dynamictrees:leaves1:4)
Block(5,12,2,dynamictrees:leaves1:4)
Block(6,8,-4,dynamictrees:leaves1:4)
Block(6,8,-3,dynamictrees:leaves1:4)
Block(6,8,-2,dynamictrees:leaves1:4)
Block(6,8,6,dynamictrees:leaves1:4)
Block(6,9,-5,dynamictrees:leaves1:4)
Block(6,9,-4,dynamictrees:leaves1:5)
Block(6,9,-3,dynamictrees:leaves1:5)
Block(6,9,-2,dynamictrees:leaves1:5)
Block(6,9,-1,dynamictrees:leaves1:6)
Block(6,9,0,dynamictrees:leaves1:7)
Block(6,9,1,dynamictrees:darkoakbranch)
Block(6,9,2,dynamictrees:darkoakbranch:1)
Block(6,9,3,dynamictrees:leaves1:7)
Block(6,9,4,dynamictrees:darkoakbranch)
Block(6,9,5,dynamictrees:leaves1:7)
Block(6,9,6,dynamictrees:leaves1:5)
Block(6,9,7,dynamictrees:leaves1:4)
Block(6,10,-4,dynamictrees:leaves1:4)
Block(6,10,-3,dynamictrees:leaves1:4)
Block(6,10,-2,dynamictrees:leaves1:4)
Block(6,10,-1,dynamictrees:leaves1:5)
Block(6,10,0,dynamictrees:leaves1:5)
Block(6,10,1,dynamictrees:leaves1:7)
Block(6,10,2,dynamictrees:leaves1:6)
Block(6,10,3,dynamictrees:leaves1:5)
Block(6,10,4,dynamictrees:leaves1:7)
Block(6,10,5,dynamictrees:leaves1:5)
Block(6,10,6,dynamictrees:leaves1:4)
Block(6,11,-1,dynamictrees:leaves1:4)
Block(6,11,0,dynamictrees:leaves1:4)
Block(6,11,1,dynamictrees:leaves1:5)
Block(6,11,2,dynamictrees:leaves1:5)
Block(6,11,3,dynamictrees:leaves1:4)
Block(6,11,4,dynamictrees:leaves1:5)
Block(6,11,5,dynamictrees:leaves1:4)
Block(6,12,1,dynamictrees:leaves1:4)
Block(6,12,2,dynamictrees:leaves1:4)
Block(6,12,4,dynamictrees:leaves1:4)
Block(7,7,-3,dynamictrees:leaves1:4)
Block(7,8,-1,dynamictrees:leaves1:4)
Block(7,8,6,dynamictrees:leaves1:4)
Block(7,9,-4,dynamictrees:leaves1:4)
Block(7,9,-3,dynamictrees:leaves1:4)
Block(7,9,-2,dynamictrees:leaves1:4)
Block(7,9,-1,dynamictrees:leaves1:5)
Block(7,9,0,dynamictrees:leaves1:6)
Block(7,9,2,dynamictrees:darkoakbranch)
Block(7,9,3,dynamictrees:leaves1:7)
Block(7,9,4,dynamictrees:leaves1:7)
Block(7,9,5,dynamictrees:leaves1:6)
Block(7,9,6,dynamictrees:leaves1:5)
Block(7,9,7,dynamictrees:leaves1:4)
Block(7,10,-1,dynamictrees:leaves1:4)
Block(7,10,0,dynamictrees:leaves1:5)
Block(7,10,1,dynamictrees:leaves1:6)
Block(7,10,2,dynamictrees:leaves1:7)
Block(7,10,3,dynamictrees:leaves1:5)
Block(7,10,4,dynamictrees:leaves1:5)
Block(7,10,5,dynamictrees:leaves1:5)
Block(7,10,6,dynamictrees:leaves1:4)
Block(7,11,0,dynamictrees:leaves1:4)
Block(7,11,1,dynamictrees:leaves1:5)
Block(7,11,2,dynamictrees:leaves1:5)
Block(7,11,3,dynamictrees:leaves1:4)
Block(7,11,4,dynamictrees:leaves1:4)
Block(7,11,5,dynamictrees:leaves1:4)
Block(7,12,1,dynamictrees:leaves1:4)
Block(7,12,2,dynamictrees:leaves1:4)
Block(8,8,0,dynamictrees:leaves1:4)
Block(8,8,4,dynamictrees:leaves1:4)
Block(8,8,5,dynamictrees:leaves1:4)
Block(8,9,-1,dynamictrees:leaves1:4)
Block(8,9,0,dynamictrees:leaves1:5)
Block(8,9,1,dynamictrees:leaves1:6)
Block(8,9,2,dynamictrees:leaves1:7)
Block(8,9,3,dynamictrees:leaves1:6)
Block(8,9,4,dynamictrees:leaves1:5)
Block(8,9,5,dynamictrees:leaves1:5)
Block(8,9,6,dynamictrees:leaves1:4)
Block(8,10,0,dynamictrees:leaves1:4)
Block(8,10,1,dynamictrees:leaves1:5)
Block(8,10,2,dynamictrees:leaves1:5)
Block(8,10,3,dynamictrees:leaves1:5)
Block(8,10,4,dynamictrees:leaves1:4)
Block(8,10,5,dynamictrees:leaves1:4)
Block(8,11,1,dynamictrees:leaves1:4)
Block(8,11,2,dynamictrees:leaves1:4)
Block(8,11,3,dynamictrees:leaves1:4)
Block(9,8,1,dynamictrees:leaves1:4)
Block(9,8,2,dynamictrees:leaves1:4)
Block(9,8,3,dynamictrees:leaves1:4)
Block(9,9,0,dynamictrees:leaves1:4)
Block(9,9,1,dynamictrees:leaves1:5)
Block(9,9,2,dynamictrees:leaves1:5)
Block(9,9,3,dynamictrees:leaves1:5)
Block(9,9,4,dynamictrees:leaves1:4)
Block(9,9,5,dynamictrees:leaves1:4)
Block(9,10,1,dynamictrees:leaves1:4)
Block(9,10,2,dynamictrees:leaves1:4)
Block(9,10,3,dynamictrees:leaves1:4)
Block(10,9,1,dynamictrees:leaves1:4)
Block(10,9,2,dynamictrees:leaves1:4)
Block(10,9,3,dynamictrees:leaves1:4)
Block(-1,0,-1,GRASS:0)
Block(0,0,-1,GRASS:0)
Block(0,0,0,GRASS:0)
Block(0,0,1,GRASS:0)
Block(0,0,2,GRASS:0)
Block(0,0,3,GRASS:0)
Block(0,1,0,GRASS:0)
Block(0,1,1,GRASS:0)
Block(0,1,2,GRASS:0)
Block(1,0,0,GRASS:0)
Block(1,0,1,GRASS:0)
Block(1,0,2,GRASS:0)
Block(1,0,3,GRASS:0)
Block(1,1,0,GRASS:0)
Block(1,1,2,GRASS:0)
Block(2,0,0,GRASS:0)
Block(2,0,1,GRASS:0)
Block(2,0,2,GRASS:0)
Block(2,0,3,GRASS:0)
Block(2,1,0,GRASS:0)
Block(2,1,1,GRASS:0)
Block(2,1,2,GRASS:0)
Block(3,0,0,GRASS:0)
Block(3,0,1,GRASS:0)
Block(3,0,2,GRASS:0)

#######################################################################
# +-----------------------------------------------------------------+ #
# |                            BO3 checks                           | #
# +-----------------------------------------------------------------+ #
#######################################################################

BlockCheck(1,-1,1,GRASS,DIRT,biomesoplenty:grass,biomesoplenty:dirt)
BlockCheck(-1,0,-1,Solid)
BlockCheck(0,0,-1,Solid)
BlockCheck(0,0,0,Solid)
BlockCheck(0,0,1,Solid)
BlockCheck(0,0,2,Solid)
BlockCheck(0,0,3,Solid)
BlockCheck(1,0,0,Solid)
BlockCheck(1,0,1,Solid)
BlockCheck(1,0,2,Solid)
BlockCheck(1,0,3,Solid)
BlockCheck(2,0,0,Solid)
BlockCheck(2,0,1,Solid)
BlockCheck(2,0,2,Solid)
BlockCheck(2,0,3,Solid)
BlockCheck(3,0,0,Solid)
BlockCheck(3,0,1,Solid)
BlockCheck(3,0,2,Solid)

#######################################################################
# +-----------------------------------------------------------------+ #
# |                             Branches                            | #
# +-----------------------------------------------------------------+ #
#######################################################################


#######################################################################
# +-----------------------------------------------------------------+ #
# |                             Entities                            | #
# +-----------------------------------------------------------------+ #
#######################################################################


#######################################################################
# +-----------------------------------------------------------------+ #
# |                            Particles                            | #
# +-----------------------------------------------------------------+ #
#######################################################################


#######################################################################
# +-----------------------------------------------------------------+ #
# |                             Spawners                            | #
# +-----------------------------------------------------------------+ #
#######################################################################


#######################################################################
# +-----------------------------------------------------------------+ #
# |                             ModData                             | #
# +-----------------------------------------------------------------+ #
#######################################################################

