
#######################################################################
# +-----------------------------------------------------------------+ #
# |                            BO4 object                           | #
# +-----------------------------------------------------------------+ #
#######################################################################

Author: NLBlackEagle

Description: No description given

SettingsMode: WriteDisable


#######################################################################
# +-----------------------------------------------------------------+ #
# |                          Main settings                          | #
# +-----------------------------------------------------------------+ #
#######################################################################

Frequency: 0

SpawnHeight: highestBlock

UseCenterForHighestBlock: true

##############################
# Height Limits for the BO4. #
##############################

MinHeight: 0

MaxHeight: 255

InheritBO3: 

InheritBO3Rotation: NORTH

OverrideChildSettings: true

OverrideParentHeight: false

CanOverride: false

BranchFrequency: 0

BranchFrequencyGroup: 

MustBeBelowOther: false

MustBeInside: 

CannotBeInside: 

ReplacesBO3: 

MustBeInsideWorldBorders: false

CanSpawnOnWater: true

SpawnOnWaterOnly: false

SpawnUnderWater: false

SpawnAtWaterLevel: false

HeightOffset: 0

RemoveAir: true

ReplaceAbove: 

ReplaceBelow: 

ReplaceWithBiomeBlocks: true

ReplaceWithSurfaceBlock: GRASS

ReplaceWithGroundBlock: DIRT

ReplaceWithStoneBlock: STONE

SmoothRadius: 0

SmoothHeightOffset: 0

SmoothStartTop: false

SmoothStartWood: false

SmoothingSurfaceBlock: 

SmoothingGroundBlock: 

BO3Group: 

IsSpawnPoint: false

DoReplaceBlocks: true


#######################################################################
# +-----------------------------------------------------------------+ #
# |                              Blocks                             | #
# +-----------------------------------------------------------------+ #
#######################################################################

Block(1,0,-7,STONE:6)
Block(1,0,-2,STONE:6)
Block(1,0,3,STONE:6)
Block(1,0,8,STONE:6)
Block(1,1,-7,STONE:6)
Block(1,1,-2,STONE:6)
Block(1,1,3,STONE:6)
Block(1,1,8,STONE:6)
Block(1,2,-7,STONE:6)
Block(1,2,-2,STONE:6)
Block(1,2,3,STONE:6)
Block(1,2,8,STONE:6)
Block(1,3,-7,STONE:6)
Block(1,3,-2,STONE:6)
Block(1,3,3,STONE:6)
Block(1,3,8,STONE:6)
Block(1,4,-7,STONE:6)
Block(1,4,-2,STONE:6)
Block(1,4,3,STONE:6)
Block(1,4,8,STONE:6)
RandomBlock(1,5,-7,SPRUCE_WOOD_STAIRS:0,70,DARK_OAK_STAIRS:0,100)
RandomBlock(1,5,-2,SPRUCE_WOOD_STAIRS:0,70,DARK_OAK_STAIRS:0,100)
RandomBlock(1,5,3,SPRUCE_WOOD_STAIRS:0,70,DARK_OAK_STAIRS:0,100)
RandomBlock(1,5,8,SPRUCE_WOOD_STAIRS:0,70,DARK_OAK_STAIRS:0,100)
Block(2,5,-7,SPRUCE_WOOD_STAIRS:5)
Block(2,5,-2,SPRUCE_WOOD_STAIRS:5)
Block(2,5,3,SPRUCE_WOOD_STAIRS:5)
Block(2,5,8,SPRUCE_WOOD_STAIRS:5)
RandomBlock(2,6,-7,SPRUCE_WOOD_STAIRS:0,70,DARK_OAK_STAIRS:0,100)
RandomBlock(2,6,-2,SPRUCE_WOOD_STAIRS:0,70,DARK_OAK_STAIRS:0,100)
RandomBlock(2,6,3,SPRUCE_WOOD_STAIRS:0,70,DARK_OAK_STAIRS:0,100)
RandomBlock(2,6,8,SPRUCE_WOOD_STAIRS:0,70,DARK_OAK_STAIRS:0,100)
Block(3,6,-7,SPRUCE_WOOD_STAIRS:5)
Block(3,6,-2,SPRUCE_WOOD_STAIRS:5)
Block(3,6,3,SPRUCE_WOOD_STAIRS:5)
Block(3,6,8,SPRUCE_WOOD_STAIRS:5)
RandomBlock(3,7,-7,SPRUCE_WOOD_STAIRS:0,70,DARK_OAK_STAIRS:0,100)
RandomBlock(3,7,-2,SPRUCE_WOOD_STAIRS:0,70,DARK_OAK_STAIRS:0,100)
RandomBlock(3,7,3,SPRUCE_WOOD_STAIRS:0,70,DARK_OAK_STAIRS:0,100)
RandomBlock(3,7,8,SPRUCE_WOOD_STAIRS:0,70,DARK_OAK_STAIRS:0,100)
Block(4,7,-7,SPRUCE_WOOD_STAIRS:5)
Block(4,7,-2,SPRUCE_WOOD_STAIRS:5)
Block(4,7,3,SPRUCE_WOOD_STAIRS:5)
Block(4,7,8,SPRUCE_WOOD_STAIRS:5)
RandomBlock(4,8,-7,SPRUCE_WOOD_STAIRS:0,70,DARK_OAK_STAIRS:0,100)
RandomBlock(4,8,-2,SPRUCE_WOOD_STAIRS:0,70,DARK_OAK_STAIRS:0,100)
RandomBlock(4,8,3,SPRUCE_WOOD_STAIRS:0,70,DARK_OAK_STAIRS:0,100)
RandomBlock(4,8,8,SPRUCE_WOOD_STAIRS:0,70,DARK_OAK_STAIRS:0,100)
Block(5,8,-7,SPRUCE_WOOD_STAIRS:5)
Block(5,8,-2,SPRUCE_WOOD_STAIRS:5)
Block(5,8,3,SPRUCE_WOOD_STAIRS:5)
Block(5,8,8,SPRUCE_WOOD_STAIRS:5)
RandomBlock(5,9,-7,SPRUCE_WOOD_STAIRS:0,70,DARK_OAK_STAIRS:0,100)
RandomBlock(5,9,-2,SPRUCE_WOOD_STAIRS:0,70,DARK_OAK_STAIRS:0,100)
RandomBlock(5,9,3,SPRUCE_WOOD_STAIRS:0,70,DARK_OAK_STAIRS:0,100)
RandomBlock(5,9,8,SPRUCE_WOOD_STAIRS:0,70,DARK_OAK_STAIRS:0,100)
Block(6,9,-7,SPRUCE_WOOD_STAIRS:5)
Block(6,9,-2,SPRUCE_WOOD_STAIRS:5)
Block(6,9,3,SPRUCE_WOOD_STAIRS:5)
Block(6,9,8,SPRUCE_WOOD_STAIRS:5)
RandomBlock(6,10,-7,SPRUCE_WOOD_STAIRS:0,70,DARK_OAK_STAIRS:0,100)
RandomBlock(6,10,-2,SPRUCE_WOOD_STAIRS:0,70,DARK_OAK_STAIRS:0,100)
RandomBlock(6,10,3,SPRUCE_WOOD_STAIRS:0,70,DARK_OAK_STAIRS:0,100)
RandomBlock(6,10,8,SPRUCE_WOOD_STAIRS:0,70,DARK_OAK_STAIRS:0,100)
Block(6,11,-7,SPRUCE_WOOD_STAIRS:4)
Block(6,11,-2,SPRUCE_WOOD_STAIRS:4)
Block(6,11,3,SPRUCE_WOOD_STAIRS:4)
Block(6,11,8,SPRUCE_WOOD_STAIRS:4)
RandomBlock(6,12,-7,SPRUCE_WOOD_STAIRS:1,70,DARK_OAK_STAIRS:1,100)
RandomBlock(6,12,-2,SPRUCE_WOOD_STAIRS:1,70,DARK_OAK_STAIRS:1,100)
RandomBlock(6,12,3,SPRUCE_WOOD_STAIRS:1,70,DARK_OAK_STAIRS:1,100)
RandomBlock(6,12,8,SPRUCE_WOOD_STAIRS:1,70,DARK_OAK_STAIRS:1,100)
Block(7,0,-7,LOG:1)
Block(7,0,-6,STONE:6)
Block(7,0,-5,STONE:6)
Block(7,0,-4,STONE:6)
Block(7,0,-3,STONE:6)
Block(7,0,-2,LOG:1)
Block(7,0,-1,STONE:6)
Block(7,0,0,STONE:6)
Block(7,0,1,STONE:6)
Block(7,0,2,STONE:6)
Block(7,0,3,LOG:1)
Block(7,0,4,STONE:6)
Block(7,0,5,STONE:6)
Block(7,0,6,STONE:6)
Block(7,0,7,STONE:6)
Block(7,0,8,LOG:1)
Block(7,1,-7,LOG:1)
Block(7,1,-6,STONE:6)
Block(7,1,-5,STONE:6)
Block(7,1,-4,STONE:6)
Block(7,1,-3,STONE:6)
Block(7,1,-2,LOG:1)
Block(7,1,-1,STONE:6)
Block(7,1,0,STONE:6)
Block(7,1,1,STONE:6)
Block(7,1,2,STONE:6)
Block(7,1,3,LOG:1)
Block(7,1,4,STONE:6)
Block(7,1,5,STONE:6)
Block(7,1,6,STONE:6)
Block(7,1,7,STONE:6)
Block(7,1,8,LOG:1)
Block(7,2,-7,LOG:1)
Block(7,2,-6,STONE:6)
Block(7,2,-5,STONE:6)
Block(7,2,-4,STONE:6)
Block(7,2,-3,STONE:6)
Block(7,2,-2,LOG:1)
Block(7,2,-1,STONE:6)
Block(7,2,0,STONE:6)
Block(7,2,1,STONE:6)
Block(7,2,2,STONE:6)
Block(7,2,3,LOG:1)
Block(7,2,4,STONE:6)
Block(7,2,5,STONE:6)
Block(7,2,6,STONE:6)
Block(7,2,7,STONE:6)
Block(7,2,8,LOG:1)
Block(7,3,-7,LOG:1)
Block(7,3,-6,STONE:6)
Block(7,3,-5,STONE:6)
Block(7,3,-4,STONE:6)
Block(7,3,-3,STONE:6)
Block(7,3,-2,LOG:1)
Block(7,3,-1,STONE:6)
Block(7,3,0,STONE:6)
Block(7,3,1,STONE:6)
Block(7,3,2,STONE:6)
Block(7,3,3,LOG:1)
Block(7,3,4,STONE:6)
Block(7,3,5,STONE:6)
Block(7,3,6,STONE:6)
Block(7,3,7,STONE:6)
Block(7,3,8,LOG:1)
Block(7,4,-7,LOG:1)
Block(7,4,-6,STONE:6)
Block(7,4,-5,STONE:6)
Block(7,4,-4,STONE:6)
Block(7,4,-3,STONE:6)
Block(7,4,-2,LOG:1)
Block(7,4,-1,STONE:6)
Block(7,4,0,STONE:6)
Block(7,4,1,STONE:6)
Block(7,4,2,STONE:6)
Block(7,4,3,LOG:1)
Block(7,4,4,STONE:6)
Block(7,4,5,STONE:6)
Block(7,4,6,STONE:6)
Block(7,4,7,STONE:6)
Block(7,4,8,LOG:1)
Block(7,5,-7,LOG:1)
Block(7,5,-6,STONE:6)
Block(7,5,-5,STONE:6)
Block(7,5,-4,STONE:6)
Block(7,5,-3,STONE:6)
Block(7,5,-2,LOG:1)
Block(7,5,-1,STONE:6)
Block(7,5,0,STONE:6)
Block(7,5,1,STONE:6)
Block(7,5,2,STONE:6)
Block(7,5,3,LOG:1)
Block(7,5,4,STONE:6)
Block(7,5,5,STONE:6)
Block(7,5,6,STONE:6)
Block(7,5,7,STONE:6)
Block(7,5,8,LOG:1)
Block(7,6,-7,LOG:1)
Block(7,6,-6,STONE:6)
RandomBlock(7,6,-5,COBBLESTONE:0,60,MOSSY_COBBLESTONE:0,5,SMOOTH_BRICK:0,10,SMOOTH_BRICK:1,10,SMOOTH_BRICK:2,10,COBBLESTONE:0,100)
RandomBlock(7,6,-4,COBBLESTONE:0,60,MOSSY_COBBLESTONE:0,5,SMOOTH_BRICK:0,10,SMOOTH_BRICK:1,10,SMOOTH_BRICK:2,10,COBBLESTONE:0,100)
Block(7,6,-3,STONE:6)
Block(7,6,-2,LOG:1)
Block(7,6,-1,STONE:6)
RandomBlock(7,6,0,COBBLESTONE:0,60,MOSSY_COBBLESTONE:0,5,SMOOTH_BRICK:0,10,SMOOTH_BRICK:1,10,SMOOTH_BRICK:2,10,COBBLESTONE:0,100)
RandomBlock(7,6,1,COBBLESTONE:0,60,MOSSY_COBBLESTONE:0,5,SMOOTH_BRICK:0,10,SMOOTH_BRICK:1,10,SMOOTH_BRICK:2,10,COBBLESTONE:0,100)
Block(7,6,2,STONE:6)
Block(7,6,3,LOG:1)
Block(7,6,4,STONE:6)
RandomBlock(7,6,5,COBBLESTONE:0,60,MOSSY_COBBLESTONE:0,5,SMOOTH_BRICK:0,10,SMOOTH_BRICK:1,10,SMOOTH_BRICK:2,10,COBBLESTONE:0,100)
RandomBlock(7,6,6,COBBLESTONE:0,60,MOSSY_COBBLESTONE:0,5,SMOOTH_BRICK:0,10,SMOOTH_BRICK:1,10,SMOOTH_BRICK:2,10,COBBLESTONE:0,100)
Block(7,6,7,STONE:6)
Block(7,6,8,LOG:1)
Block(7,7,-7,LOG:1)
Block(7,7,-6,STONE:6)
RandomBlock(7,7,-5,COBBLESTONE:0,60,MOSSY_COBBLESTONE:0,5,SMOOTH_BRICK:0,10,SMOOTH_BRICK:1,10,SMOOTH_BRICK:2,10,COBBLESTONE:0,100)
RandomBlock(7,7,-4,COBBLESTONE:0,60,MOSSY_COBBLESTONE:0,5,SMOOTH_BRICK:0,10,SMOOTH_BRICK:1,10,SMOOTH_BRICK:2,10,COBBLESTONE:0,100)
Block(7,7,-3,STONE:6)
Block(7,7,-2,LOG:1)
Block(7,7,-1,STONE:6)
RandomBlock(7,7,0,COBBLESTONE:0,60,MOSSY_COBBLESTONE:0,5,SMOOTH_BRICK:0,10,SMOOTH_BRICK:1,10,SMOOTH_BRICK:2,10,COBBLESTONE:0,100)
RandomBlock(7,7,1,COBBLESTONE:0,60,MOSSY_COBBLESTONE:0,5,SMOOTH_BRICK:0,10,SMOOTH_BRICK:1,10,SMOOTH_BRICK:2,10,COBBLESTONE:0,100)
Block(7,7,2,STONE:6)
Block(7,7,3,LOG:1)
Block(7,7,4,STONE:6)
RandomBlock(7,7,5,COBBLESTONE:0,60,MOSSY_COBBLESTONE:0,5,SMOOTH_BRICK:0,10,SMOOTH_BRICK:1,10,SMOOTH_BRICK:2,10,COBBLESTONE:0,100)
RandomBlock(7,7,6,COBBLESTONE:0,60,MOSSY_COBBLESTONE:0,5,SMOOTH_BRICK:0,10,SMOOTH_BRICK:1,10,SMOOTH_BRICK:2,10,COBBLESTONE:0,100)
Block(7,7,7,STONE:6)
Block(7,7,8,LOG:1)
Block(7,8,-7,LOG:1)
Block(7,8,-6,LOG:9)
Block(7,8,-5,LOG:9)
Block(7,8,-4,LOG:9)
Block(7,8,-3,LOG:9)
Block(7,8,-2,LOG:1)
Block(7,8,-1,LOG:9)
Block(7,8,0,LOG:9)
Block(7,8,1,LOG:9)
Block(7,8,2,LOG:9)
Block(7,8,3,LOG:1)
Block(7,8,4,LOG:9)
Block(7,8,5,LOG:9)
Block(7,8,6,LOG:9)
Block(7,8,7,LOG:9)
Block(7,8,8,LOG:1)
Block(7,9,-7,LOG:1)
Block(7,9,-6,DARK_OAK_FENCE:0)
Block(7,9,-5,DARK_OAK_FENCE:0)
Block(7,9,-4,DARK_OAK_FENCE:0)
Block(7,9,-3,DARK_OAK_FENCE:0)
Block(7,9,-2,LOG:1)
Block(7,9,-1,DARK_OAK_FENCE:0)
Block(7,9,0,DARK_OAK_FENCE:0)
Block(7,9,1,DARK_OAK_FENCE:0)
Block(7,9,2,DARK_OAK_FENCE:0)
Block(7,9,3,LOG:1)
Block(7,9,4,DARK_OAK_FENCE:0)
Block(7,9,5,DARK_OAK_FENCE:0)
Block(7,9,6,DARK_OAK_FENCE:0)
Block(7,9,7,DARK_OAK_FENCE:0)
Block(7,9,8,LOG:1)
Block(7,10,-7,LOG:1)
Block(7,10,-6,LOG:9)
Block(7,10,-5,LOG:9)
Block(7,10,-4,LOG:9)
Block(7,10,-3,LOG:9)
Block(7,10,-2,LOG:1)
Block(7,10,-1,LOG:9)
Block(7,10,0,LOG:9)
Block(7,10,1,LOG:9)
Block(7,10,2,LOG:9)
Block(7,10,3,LOG:1)
Block(7,10,4,LOG:9)
Block(7,10,5,LOG:9)
Block(7,10,6,LOG:9)
Block(7,10,7,LOG:9)
Block(7,10,8,LOG:9)
Block(7,11,-7,LOG:1)
Block(7,11,-6,TRAP_DOOR:2)
Block(7,11,-5,TRAP_DOOR:2)
Block(7,11,-4,TRAP_DOOR:2)
Block(7,11,-3,TRAP_DOOR:2)
Block(7,11,-2,LOG:1)
Block(7,11,-1,TRAP_DOOR:2)
Block(7,11,0,TRAP_DOOR:2)
Block(7,11,1,TRAP_DOOR:2)
Block(7,11,2,TRAP_DOOR:2)
Block(7,11,3,LOG:1)
Block(7,11,4,TRAP_DOOR:2)
Block(7,11,5,TRAP_DOOR:2)
Block(7,11,6,TRAP_DOOR:2)
Block(7,11,7,TRAP_DOOR:2)
Block(7,11,8,LOG:1)
Block(7,12,-7,TRAP_DOOR:1)
Block(7,12,-2,TRAP_DOOR:1)
Block(7,12,3,TRAP_DOOR:1)
Block(7,12,8,TRAP_DOOR:1)

#######################################################################
# +-----------------------------------------------------------------+ #
# |                             Branches                            | #
# +-----------------------------------------------------------------+ #
#######################################################################

Branch(0,0,16,true,viking_greathallC0R3,NORTH,100.0,0)

#######################################################################
# +-----------------------------------------------------------------+ #
# |                             Entities                            | #
# +-----------------------------------------------------------------+ #
#######################################################################


#######################################################################
# +-----------------------------------------------------------------+ #
# |                            Particles                            | #
# +-----------------------------------------------------------------+ #
#######################################################################


#######################################################################
# +-----------------------------------------------------------------+ #
# |                             Spawners                            | #
# +-----------------------------------------------------------------+ #
#######################################################################


#######################################################################
# +-----------------------------------------------------------------+ #
# |                             ModData                             | #
# +-----------------------------------------------------------------+ #
#######################################################################

