Author: NLBlackEagle
Description: No description given
SettingsMode: WriteDisable
Frequency: 0
SpawnHeight: highestBlock
UseCenterForHighestBlock: true
MinHeight: 0
MaxHeight: 255
InheritBO3: 
InheritBO3Rotation: NORTH
OverrideChildSettings: true
OverrideParentHeight: false
CanOverride: false
BranchFrequency: 0
BranchFrequencyGroup: 
MustBeBelowOther: false
MustBeInside: 
CannotBeInside: 
ReplacesBO3: 
MustBeInsideWorldBorders: false
CanSpawnOnWater: true
SpawnOnWaterOnly: false
SpawnUnderWater: false
SpawnAtWaterLevel: false
HeightOffset: 0
RemoveAir: true
ReplaceAbove: 
ReplaceBelow: 
ReplaceWithBiomeBlocks: true
ReplaceWithSurfaceBlock: GRASS
ReplaceWithGroundBlock: DIRT
ReplaceWithStoneBlock: STONE
SmoothRadius: 0
SmoothHeightOffset: 0
SmoothStartTop: false
SmoothStartWood: false
SmoothingSurfaceBlock: 
SmoothingGroundBlock: 
BO3Group: 
IsSpawnPoint: false
DoReplaceBlocks: true
RandomBlock(-4,5,-7,AIR,70,WALL_BANNER:4,../../NBT/Banners/viking_honor_1.nbt,20,WALL_BANNER:4,../../NBT/Banners/viking_honor_2.nbt,20,WALL_BANNER:4,../../NBT/Banners/viking_honor_3.nbt,20,WALL_BANNER:4,../../NBT/Banners/viking_honor_4.nbt,20,WALL_BANNER:4,../../NBT/Banners/viking_honor_5.nbt,20,WALL_BANNER:4,../../NBT/Banners/viking_honor_6.nbt,100)
RandomBlock(-4,5,-5,AIR,70,WALL_BANNER:4,../../NBT/Banners/viking_regular_1.nbt,20,WALL_BANNER:4,../../NBT/Banners/viking_regular_2.nbt,20,WALL_BANNER:4,../../NBT/Banners/viking_regular_3.nbt,20,WALL_BANNER:4,../../NBT/Banners/viking_regular_4.nbt,20,WALL_BANNER:4,../../NBT/Banners/viking_regular_5.nbt,20,WALL_BANNER:4,../../NBT/Banners/viking_regular_6.nbt,20,WALL_BANNER:4,../../NBT/Banners/viking_regular_7.nbt,20,WALL_BANNER:4,../../NBT/Banners/viking_regular_8.nbt,100)
RandomBlock(-4,5,-3,AIR,70,WALL_BANNER:4,../../NBT/Banners/viking_wealthy_1.nbt,20,WALL_BANNER:4,../../NBT/Banners/viking_wealthy_2.nbt,20,WALL_BANNER:4,../../NBT/Banners/viking_wealthy_3.nbt,20,WALL_BANNER:4,../../NBT/Banners/viking_wealthy_4.nbt,20,WALL_BANNER:4,../../NBT/Banners/viking_wealthy_5.nbt,20,WALL_BANNER:4,../../NBT/Banners/viking_wealthy_6.nbt,20,WALL_BANNER:4,../../NBT/Banners/viking_wealthy_7.nbt,20,WALL_BANNER:4,../../NBT/Banners/viking_wealthy_8.nbt,20,WALL_BANNER:4,../../NBT/Banners/viking_wealthy_9.nbt,100)
RandomBlock(-4,5,-1,AIR,70,WALL_BANNER:4,../../NBT/Banners/viking_emblem_1.nbt,20,WALL_BANNER:4,../../NBT/Banners/viking_emblem_2.nbt,20,WALL_BANNER:4,../../NBT/Banners/viking_emblem_3.nbt,20,WALL_BANNER:4,../../NBT/Banners/viking_emblem_4.nbt,100)
RandomBlock(-4,5,1,AIR,70,WALL_BANNER:4,../../NBT/Banners/viking_wealthy_1.nbt,20,WALL_BANNER:4,../../NBT/Banners/viking_wealthy_2.nbt,20,WALL_BANNER:4,../../NBT/Banners/viking_wealthy_3.nbt,20,WALL_BANNER:4,../../NBT/Banners/viking_wealthy_4.nbt,20,WALL_BANNER:4,../../NBT/Banners/viking_wealthy_5.nbt,20,WALL_BANNER:4,../../NBT/Banners/viking_wealthy_6.nbt,20,WALL_BANNER:4,../../NBT/Banners/viking_wealthy_7.nbt,20,WALL_BANNER:4,../../NBT/Banners/viking_wealthy_8.nbt,20,WALL_BANNER:4,../../NBT/Banners/viking_wealthy_9.nbt,100)
RandomBlock(-4,5,3,AIR,70,WALL_BANNER:4,../../NBT/Banners/viking_wealthy_1.nbt,20,WALL_BANNER:4,../../NBT/Banners/viking_wealthy_2.nbt,20,WALL_BANNER:4,../../NBT/Banners/viking_wealthy_3.nbt,20,WALL_BANNER:4,../../NBT/Banners/viking_wealthy_4.nbt,20,WALL_BANNER:4,../../NBT/Banners/viking_wealthy_5.nbt,20,WALL_BANNER:4,../../NBT/Banners/viking_wealthy_6.nbt,20,WALL_BANNER:4,../../NBT/Banners/viking_wealthy_7.nbt,20,WALL_BANNER:4,../../NBT/Banners/viking_wealthy_8.nbt,20,WALL_BANNER:4,../../NBT/Banners/viking_wealthy_9.nbt,100)
RandomBlock(-4,5,5,AIR,70,WALL_BANNER:4,../../NBT/Banners/viking_emblem_1.nbt,20,WALL_BANNER:4,../../NBT/Banners/viking_emblem_2.nbt,20,WALL_BANNER:4,../../NBT/Banners/viking_emblem_3.nbt,20,WALL_BANNER:4,../../NBT/Banners/viking_emblem_4.nbt,100)
RandomBlock(-4,5,7,AIR,70,WALL_BANNER:4,../../NBT/Banners/viking_wealthy_1.nbt,20,WALL_BANNER:4,../../NBT/Banners/viking_wealthy_2.nbt,20,WALL_BANNER:4,../../NBT/Banners/viking_wealthy_3.nbt,20,WALL_BANNER:4,../../NBT/Banners/viking_wealthy_4.nbt,20,WALL_BANNER:4,../../NBT/Banners/viking_wealthy_5.nbt,20,WALL_BANNER:4,../../NBT/Banners/viking_wealthy_6.nbt,20,WALL_BANNER:4,../../NBT/Banners/viking_wealthy_7.nbt,20,WALL_BANNER:4,../../NBT/Banners/viking_wealthy_8.nbt,20,WALL_BANNER:4,../../NBT/Banners/viking_wealthy_9.nbt,100)
Block(-3,4,-7,WOOD:1)
Block(-3,4,-6,WOOD:1)
Block(-3,4,-5,WOOD:1)
Block(-3,4,-4,WOOD:1)
Block(-3,4,-3,WOOD:1)
Block(-3,4,-2,WOOD:1)
Block(-3,4,-1,WOOD:1)
Block(-3,4,0,WOOD:1)
Block(-3,4,1,WOOD:1)
Block(-3,4,2,WOOD:1)
Block(-3,4,3,WOOD:1)
Block(-3,4,4,WOOD:1)
Block(-3,4,5,WOOD:1)
Block(-3,4,6,WOOD:1)
Block(-3,4,7,WOOD:1)
Block(-3,4,8,WOOD:1)
Block(-3,5,-7,WOOD:1)
Block(-3,5,-6,DARK_OAK_STAIRS:0)
Block(-3,5,-5,WOOD:1)
Block(-3,5,-4,DARK_OAK_STAIRS:0)
Block(-3,5,-3,WOOD:1)
Block(-3,5,-2,DARK_OAK_STAIRS:0)
Block(-3,5,-1,WOOD:1)
Block(-3,5,0,DARK_OAK_STAIRS:0)
Block(-3,5,1,WOOD:1)
Block(-3,5,2,DARK_OAK_STAIRS:0)
Block(-3,5,3,WOOD:1)
Block(-3,5,4,DARK_OAK_STAIRS:0)
Block(-3,5,5,WOOD:1)
Block(-3,5,6,DARK_OAK_STAIRS:0)
Block(-3,5,7,WOOD:1)
Block(-3,5,8,DARK_OAK_STAIRS:0)
Block(-3,6,-6,WOOD_STEP:5)
Block(-3,6,-4,WOOD_STEP:5)
Block(-3,6,-2,WOOD_STEP:5)
Block(-3,6,0,WOOD_STEP:5)
Block(-3,6,2,WOOD_STEP:5)
Block(-3,6,4,WOOD_STEP:5)
Block(-3,6,6,WOOD_STEP:5)
Block(-3,6,8,WOOD_STEP:5)
Block(-3,9,-6,WOOL:0)
Block(-3,9,-5,WOOL:14)
Block(-3,10,-7,WOOL:14)
Block(-3,10,-6,WOOL:0)
Block(-3,10,-5,WOOL:14)
Block(-3,11,-7,SPRUCE_FENCE_GATE:1)
Block(-3,11,-6,SPRUCE_FENCE_GATE:1)
Block(-3,11,-5,SPRUCE_FENCE_GATE:1)
Block(-3,12,-7,WOOD_STEP:5)
Block(-3,12,-6,WOOD_STEP:5)
Block(-3,12,-5,WOOD_STEP:5)
Block(-2,0,-4,DARK_OAK_FENCE:0)
Block(-2,0,-2,LOG:5)
Block(-2,0,0,DARK_OAK_FENCE:0)
Block(-2,0,4,DARK_OAK_FENCE:0)
Block(-2,0,8,DARK_OAK_FENCE:0)
Block(-2,1,-4,DARK_OAK_FENCE:0)
Block(-2,1,0,DARK_OAK_FENCE:0)
Block(-2,1,4,DARK_OAK_FENCE:0)
Block(-2,1,8,DARK_OAK_FENCE:0)
Block(-2,2,-4,DARK_OAK_FENCE:0)
Block(-2,2,0,DARK_OAK_FENCE:0)
Block(-2,2,4,DARK_OAK_FENCE:0)
Block(-2,2,8,DARK_OAK_FENCE:0)
Block(-2,3,-7,WOOD:1)
Block(-2,3,-6,WOOD:1)
Block(-2,3,-5,WOOD:1)
Block(-2,3,-4,WOOD:1)
Block(-2,3,-3,WOOD:1)
Block(-2,3,-2,WOOD:1)
Block(-2,3,-1,WOOD:1)
Block(-2,3,0,WOOD:1)
Block(-2,3,1,WOOD:1)
Block(-2,3,2,WOOD:1)
Block(-2,3,3,WOOD:1)
Block(-2,3,4,WOOD:1)
Block(-2,3,5,WOOD:1)
Block(-2,3,6,WOOD:1)
Block(-2,3,7,WOOD:1)
Block(-2,3,8,WOOD:1)
Block(-2,4,-7,WEB:0)
Block(-2,4,-6,WEB:0)
Block(-2,4,-5,WEB:0)
Block(-2,4,-4,WEB:0)
Block(-2,4,-3,WEB:0)
Block(-2,4,-2,WEB:0)
Block(-2,4,-1,WEB:0)
Block(-2,4,0,WEB:0)
Block(-2,4,1,WEB:0)
Block(-2,4,2,WEB:0)
Block(-2,4,3,WEB:0)
Block(-2,4,4,WEB:0)
Block(-2,4,5,WEB:0)
Block(-2,4,6,WEB:0)
Block(-2,4,7,WEB:0)
Block(-2,4,8,WEB:0)
Block(-2,5,-7,WOOD_STEP:5)
Block(-2,5,-6,WOOD_STEP:5)
Block(-2,5,-5,WOOD_STEP:5)
Block(-2,5,-4,WOOD_STEP:5)
Block(-2,5,-3,WOOD_STEP:5)
Block(-2,5,-2,WOOD_STEP:5)
Block(-2,5,-1,WOOD_STEP:5)
Block(-2,5,0,WOOD_STEP:5)
Block(-2,5,1,WOOD_STEP:5)
Block(-2,5,2,WOOD_STEP:5)
Block(-2,5,3,WOOD_STEP:5)
Block(-2,5,4,WOOD_STEP:5)
Block(-2,5,5,WOOD_STEP:5)
Block(-2,5,6,WOOD_STEP:5)
Block(-2,5,7,WOOD_STEP:5)
Block(-2,5,8,WOOD_STEP:5)
Block(-2,10,-4,WOOL:0)
Block(-2,10,-3,WOOL:14)
Block(-2,10,-2,WOOL:0)
Block(-2,11,-4,SPRUCE_FENCE_GATE:1)
Block(-2,11,-3,SPRUCE_FENCE_GATE:1)
Block(-2,11,-2,SPRUCE_FENCE_GATE:1)
Block(-2,12,-4,WOOD_STEP:5)
Block(-2,12,-3,WOOD_STEP:5)
Block(-2,12,-2,WOOD_STEP:5)
Block(-1,0,-7,LOG:5)
Block(-1,0,-2,LOG:5)
Block(-1,0,1,LOG:5)
Block(-1,0,6,LOG:5)
Block(-1,2,-7,WOOD:1)
Block(-1,2,-6,WOOD:1)
Block(-1,2,-5,WOOD:1)
Block(-1,2,-4,WOOD:1)
Block(-1,2,-3,WOOD:1)
Block(-1,2,-2,WOOD:1)
Block(-1,2,-1,WOOD:1)
Block(-1,2,0,WOOD:1)
Block(-1,2,1,WOOD:1)
Block(-1,2,2,WOOD:1)
Block(-1,2,3,WOOD:1)
Block(-1,2,4,WOOD:1)
Block(-1,2,5,WOOD:1)
Block(-1,2,6,WOOD:1)
Block(-1,2,7,WOOD:1)
Block(-1,2,8,WOOD:1)
Block(-1,4,-7,WEB:0)
Block(-1,4,-6,WEB:0)
Block(-1,4,-5,WEB:0)
Block(-1,4,-4,WEB:0)
Block(-1,4,-3,WEB:0)
Block(-1,4,-2,WEB:0)
Block(-1,4,-1,WEB:0)
Block(-1,4,0,WEB:0)
Block(-1,4,1,WEB:0)
Block(-1,4,2,WEB:0)
Block(-1,4,3,WEB:0)
Block(-1,4,4,WEB:0)
Block(-1,4,5,WEB:0)
Block(-1,4,6,WEB:0)
Block(-1,4,7,WEB:0)
Block(-1,4,8,WEB:0)
Block(-1,5,-7,WOOD_STEP:5)
Block(-1,5,-6,WOOD_STEP:5)
Block(-1,5,-5,WOOD_STEP:5)
Block(-1,5,-4,WOOD_STEP:5)
Block(-1,5,-3,WOOD_STEP:5)
Block(-1,5,-2,WOOD_STEP:5)
Block(-1,5,-1,WOOD_STEP:5)
Block(-1,5,0,WOOD_STEP:5)
Block(-1,5,1,WOOD_STEP:5)
Block(-1,5,2,WOOD_STEP:5)
Block(-1,5,3,WOOD_STEP:5)
Block(-1,5,4,WOOD_STEP:5)
Block(-1,5,5,WOOD_STEP:5)
Block(-1,5,6,WOOD_STEP:5)
Block(-1,5,7,WOOD_STEP:5)
Block(-1,5,8,WOOD_STEP:5)
Block(-1,6,7,AIR:0)
Block(-1,8,-7,SPRUCE_FENCE:0)
Block(-1,8,0,WOOL:0)
Block(-1,9,-1,WOOL:14)
Block(-1,9,0,WOOL:0)
Block(-1,9,1,WOOL:14)
Block(-1,10,-1,WOOL:14)
Block(-1,10,0,WOOL:0)
Block(-1,10,1,WOOL:14)
Block(-1,10,2,WOOL:0)
Block(-1,10,3,WOOL:14)
Block(-1,11,-1,SPRUCE_FENCE_GATE:3)
Block(-1,11,0,SPRUCE_FENCE_GATE:3)
Block(-1,11,1,SPRUCE_FENCE_GATE:7)
Block(-1,11,2,SPRUCE_FENCE_GATE:3)
Block(-1,11,3,SPRUCE_FENCE_GATE:3)
Block(-1,12,-1,WOOD_STEP:5)
Block(-1,12,0,WOOD_STEP:5)
Block(-1,12,1,WOOD_DOUBLE_STEP:5)
Block(-1,12,2,WOOD_STEP:5)
Block(-1,12,3,WOOD_STEP:5)
Block(-1,13,1,SPRUCE_FENCE:0)
Block(-1,14,1,SPRUCE_FENCE:0)
Block(-1,15,1,SPRUCE_FENCE:0)
Block(-1,16,1,SPRUCE_FENCE:0)
Block(-1,17,1,SPRUCE_FENCE:0)
Block(-1,18,1,SPRUCE_FENCE:0)
Block(-1,19,1,SPRUCE_FENCE:0)
Block(-1,20,1,SPRUCE_FENCE:0)
Block(-1,21,1,SPRUCE_FENCE:0)
Block(-1,22,1,SPRUCE_FENCE:0)
Block(-1,23,1,SPRUCE_FENCE:0)
Block(-1,24,1,SPRUCE_FENCE:0)
Block(-1,25,1,SPRUCE_FENCE:0)
Block(-1,26,1,SPRUCE_FENCE:0)
Block(-1,27,1,SPRUCE_FENCE:0)
Block(0,0,-7,LOG:5)
Block(0,0,-2,LOG:5)
Block(0,0,1,LOG:5)
Block(0,0,6,LOG:5)
Block(0,1,-7,LOG:9)
Block(0,1,-6,LOG:9)
Block(0,1,-5,LOG:9)
Block(0,1,-4,LOG:9)
Block(0,1,-3,LOG:9)
Block(0,1,-2,LOG:9)
Block(0,1,-1,LOG:9)
Block(0,1,0,LOG:9)
Block(0,1,1,LOG:9)
Block(0,1,2,LOG:9)
Block(0,1,3,LOG:9)
Block(0,1,4,LOG:9)
Block(0,1,5,LOG:9)
Block(0,1,6,LOG:9)
Block(0,1,7,LOG:9)
Block(0,1,8,LOG:9)
Block(0,2,1,LOG:1)
Block(0,3,1,LOG:1)
Block(0,4,-7,WEB:0)
Block(0,4,-6,WEB:0)
Block(0,4,-5,WEB:0)
Block(0,4,-4,WEB:0)
Block(0,4,-3,WEB:0)
Block(0,4,-2,WEB:0)
Block(0,4,-1,WEB:0)
Block(0,4,0,WEB:0)
Block(0,4,1,LOG:1)
Block(0,4,2,WEB:0)
Block(0,4,3,WEB:0)
Block(0,4,4,WEB:0)
Block(0,4,5,WEB:0)
Block(0,4,6,WEB:0)
Block(0,4,7,WEB:0)
Block(0,4,8,WEB:0)
Block(0,5,-7,WOOD_DOUBLE_STEP:5)
Block(0,5,-6,WOOD_STEP:5)
Block(0,5,-5,WOOD_STEP:5)
Block(0,5,-4,WOOD_STEP:5)
Block(0,5,-3,WOOD_STEP:5)
Block(0,5,-2,WOOD_STEP:5)
Block(0,5,-1,WOOD_STEP:5)
Block(0,5,0,WOOD_STEP:5)
Block(0,5,1,LOG:1)
Block(0,5,2,WOOD_STEP:5)
Block(0,5,3,WOOD_STEP:5)
Block(0,5,4,WOOD_STEP:5)
Block(0,5,5,WOOD_STEP:5)
Block(0,5,6,WOOD_STEP:5)
Block(0,5,7,WOOD_STEP:5)
Block(0,5,8,WOOD_STEP:5)
Block(0,6,-7,SPRUCE_FENCE:0)
Block(0,6,1,LOG:1)
Block(0,7,-7,SPRUCE_FENCE:0)
Block(0,7,1,LOG:1)
Block(0,8,-7,SPRUCE_FENCE:0)
Block(0,8,1,LOG:1)
Block(0,9,1,LOG:1)
Block(0,9,5,WOOL:14)
Block(0,9,6,WOOL:0)
Block(0,10,1,LOG:1)
Block(0,10,4,WOOL:0)
Block(0,10,5,WOOL:14)
Block(0,10,6,WOOL:0)
Block(0,11,1,LOG:1)
Block(0,11,4,SPRUCE_FENCE_GATE:1)
Block(0,11,5,SPRUCE_FENCE_GATE:1)
Block(0,11,6,SPRUCE_FENCE_GATE:1)
Block(0,12,1,LOG:1)
Block(0,12,4,WOOD_STEP:5)
Block(0,12,5,WOOD_STEP:5)
Block(0,12,6,WOOD_STEP:5)
Block(0,13,1,LOG:1)
Block(0,14,1,LOG:1)
Block(0,15,1,LOG:1)
Block(0,16,1,LOG:1)
Block(0,17,1,LOG:1)
Block(0,18,1,LOG:1)
Block(0,19,1,LOG:1)
Block(0,20,1,LOG:1)
Block(0,21,1,LOG:1)
Block(0,22,1,LOG:1)
Block(0,23,1,LOG:1)
Block(0,24,1,LOG:1)
Block(0,25,1,LOG:1)
Block(0,26,0,TRAP_DOOR:12)
Block(0,26,1,LOG:1)
Block(0,26,2,TRAP_DOOR:13)
Block(0,27,0,TRAP_DOOR:12)
Block(0,27,1,SPRUCE_FENCE:0)
Block(0,27,2,TRAP_DOOR:13)
Block(0,28,1,TRAP_DOOR:1)
Block(1,0,-7,LOG:5)
Block(1,0,-2,LOG:5)
Block(1,0,1,LOG:5)
Block(1,0,6,LOG:5)
Block(1,2,-7,WOOD:1)
Block(1,2,-6,WOOD:1)
Block(1,2,-5,WOOD:1)
Block(1,2,-4,WOOD:1)
Block(1,2,-3,WOOD:1)
Block(1,2,-2,WOOD:1)
Block(1,2,-1,WOOD:1)
Block(1,2,0,WOOD:1)
Block(1,2,1,WOOD:1)
Block(1,2,2,WOOD:1)
Block(1,2,3,WOOD:1)
Block(1,2,4,WOOD:1)
Block(1,2,5,WOOD:1)
Block(1,2,6,WOOD:1)
Block(1,2,7,WOOD:1)
Block(1,2,8,WOOD:1)
Block(1,4,-7,WEB:0)
Block(1,4,-6,WEB:0)
Block(1,4,-5,WEB:0)
Block(1,4,-4,WEB:0)
Block(1,4,-3,WEB:0)
Block(1,4,-2,WEB:0)
Block(1,4,-1,WEB:0)
Block(1,4,0,WEB:0)
Block(1,4,1,WEB:0)
Block(1,4,2,WEB:0)
Block(1,4,3,WEB:0)
Block(1,4,4,WEB:0)
Block(1,4,5,WEB:0)
Block(1,4,6,WEB:0)
Block(1,4,7,WEB:0)
Block(1,4,8,WEB:0)
Block(1,5,-7,WOOD_STEP:5)
Block(1,5,-6,WOOD_STEP:5)
Block(1,5,-5,WOOD_STEP:5)
Block(1,5,-4,WOOD_STEP:5)
Block(1,5,-3,WOOD_STEP:5)
Block(1,5,-2,WOOD_STEP:5)
Block(1,5,-1,WOOD_STEP:5)
Block(1,5,0,WOOD_STEP:5)
Block(1,5,1,WOOD_STEP:5)
Block(1,5,2,WOOD_STEP:5)
Block(1,5,3,WOOD_STEP:5)
Block(1,5,4,WOOD_STEP:5)
Block(1,5,5,WOOD_STEP:5)
Block(1,5,6,WOOD_STEP:5)
Block(1,5,7,WOOD_STEP:5)
Block(1,5,8,WOOD_STEP:5)
Block(1,6,-3,AIR:0)
Block(1,6,1,SPRUCE_FENCE:0)
Block(1,7,1,SPRUCE_FENCE:0)
Block(1,8,-7,SPRUCE_FENCE:0)
Block(1,8,1,SPRUCE_FENCE:0)
Block(1,9,1,SPRUCE_FENCE:0)
Block(1,9,7,WOOL:14)
Block(1,9,8,WOOL:0)
Block(1,10,1,SPRUCE_FENCE:0)
Block(1,10,7,WOOL:14)
Block(1,10,8,WOOL:0)
Block(1,11,1,SPRUCE_FENCE:0)
Block(1,11,7,SPRUCE_FENCE_GATE:1)
Block(1,11,8,SPRUCE_FENCE_GATE:1)
Block(1,12,1,SPRUCE_FENCE:0)
Block(1,12,7,WOOD_STEP:5)
Block(1,12,8,WOOD_STEP:5)
Block(1,13,1,SPRUCE_FENCE:0)
Block(1,14,1,SPRUCE_FENCE:0)
Block(1,15,1,SPRUCE_FENCE:0)
Block(1,16,1,SPRUCE_FENCE:0)
Block(1,17,1,SPRUCE_FENCE:0)
Block(1,18,1,SPRUCE_FENCE:0)
Block(1,19,1,SPRUCE_FENCE:0)
Block(1,20,1,SPRUCE_FENCE:0)
Block(1,21,1,SPRUCE_FENCE:0)
Block(1,22,1,SPRUCE_FENCE:0)
Block(1,23,1,SPRUCE_FENCE:0)
Block(1,24,1,SPRUCE_FENCE:0)
Block(1,25,1,SPRUCE_FENCE:0)
Block(1,26,1,SPRUCE_FENCE:0)
Block(1,27,1,SPRUCE_FENCE:0)
Block(2,0,-4,DARK_OAK_FENCE:0)
Block(2,0,0,DARK_OAK_FENCE:0)
Block(2,0,4,DARK_OAK_FENCE:0)
Block(2,0,6,LOG:5)
Block(2,0,8,DARK_OAK_FENCE:0)
Block(2,1,-4,DARK_OAK_FENCE:0)
Block(2,1,0,DARK_OAK_FENCE:0)
Block(2,1,4,DARK_OAK_FENCE:0)
Block(2,1,8,DARK_OAK_FENCE:0)
Block(2,2,-4,DARK_OAK_FENCE:0)
Block(2,2,0,DARK_OAK_FENCE:0)
Block(2,2,4,DARK_OAK_FENCE:0)
Block(2,2,8,DARK_OAK_FENCE:0)
Block(2,3,-7,WOOD:1)
Block(2,3,-6,WOOD:1)
Block(2,3,-5,WOOD:1)
Block(2,3,-4,WOOD:1)
Block(2,3,-3,WOOD:1)
Block(2,3,-2,WOOD:1)
Block(2,3,-1,WOOD:1)
Block(2,3,0,WOOD:1)
Block(2,3,1,WOOD:1)
Block(2,3,2,WOOD:1)
Block(2,3,3,WOOD:1)
Block(2,3,4,WOOD:1)
Block(2,3,5,WOOD:1)
Block(2,3,6,WOOD:1)
Block(2,3,7,WOOD:1)
Block(2,3,8,WOOD:1)
Block(2,4,-7,WEB:0)
Block(2,4,-6,WEB:0)
Block(2,4,-5,WEB:0)
Block(2,4,-4,WEB:0)
Block(2,4,-3,WEB:0)
Block(2,4,-2,WEB:0)
Block(2,4,-1,WEB:0)
Block(2,4,0,WEB:0)
Block(2,4,1,WEB:0)
Block(2,4,2,WEB:0)
Block(2,4,3,WEB:0)
Block(2,4,4,WEB:0)
Block(2,4,5,WEB:0)
Block(2,4,6,WEB:0)
Block(2,4,7,WEB:0)
Block(2,4,8,WEB:0)
Block(2,5,-7,WOOD_STEP:5)
Block(2,5,-6,WOOD_STEP:5)
Block(2,5,-5,WOOD_STEP:5)
Block(2,5,-4,WOOD_STEP:5)
Block(2,5,-3,WOOD_STEP:5)
Block(2,5,-2,WOOD_STEP:5)
Block(2,5,-1,WOOD_STEP:5)
Block(2,5,0,WOOD_STEP:5)
Block(2,5,1,WOOD_STEP:5)
Block(2,5,2,WOOD_STEP:5)
Block(2,5,3,WOOD_STEP:5)
Block(2,5,4,WOOD_STEP:5)
Block(2,5,5,WOOD_STEP:5)
Block(2,5,6,WOOD_STEP:5)
Block(2,5,7,WOOD_STEP:5)
Block(2,5,8,WOOD_STEP:5)
Block(3,4,-7,WOOD:1)
Block(3,4,-6,WOOD:1)
Block(3,4,-5,WOOD:1)
Block(3,4,-4,WOOD:1)
Block(3,4,-3,WOOD:1)
Block(3,4,-2,WOOD:1)
Block(3,4,-1,WOOD:1)
Block(3,4,0,WOOD:1)
Block(3,4,1,WOOD:1)
Block(3,4,2,WOOD:1)
Block(3,4,3,WOOD:1)
Block(3,4,4,WOOD:1)
Block(3,4,5,WOOD:1)
Block(3,4,6,WOOD:1)
Block(3,4,7,WOOD:1)
Block(3,4,8,WOOD:1)
Block(3,5,-7,WOOD:1)
Block(3,5,-6,DARK_OAK_STAIRS:1)
Block(3,5,-5,WOOD:1)
Block(3,5,-4,DARK_OAK_STAIRS:1)
Block(3,5,-3,WOOD:1)
Block(3,5,-2,DARK_OAK_STAIRS:1)
Block(3,5,-1,WOOD:1)
Block(3,5,0,DARK_OAK_STAIRS:1)
Block(3,5,1,WOOD:1)
Block(3,5,2,DARK_OAK_STAIRS:1)
Block(3,5,3,WOOD:1)
Block(3,5,4,DARK_OAK_STAIRS:1)
Block(3,5,5,WOOD:1)
Block(3,5,6,DARK_OAK_STAIRS:1)
Block(3,5,7,WOOD:1)
Block(3,5,8,DARK_OAK_STAIRS:1)
Block(3,6,-6,WOOD_STEP:5)
Block(3,6,-4,WOOD_STEP:5)
Block(3,6,-2,WOOD_STEP:5)
Block(3,6,0,WOOD_STEP:5)
Block(3,6,2,WOOD_STEP:5)
Block(3,6,4,WOOD_STEP:5)
Block(3,6,6,WOOD_STEP:5)
Block(3,6,8,WOOD_STEP:5)
Block(4,0,0,LOG:1)
Block(4,0,2,LOG:1)
Block(4,1,0,LOG:1)
Block(4,1,2,LOG:1)
Block(4,2,0,LOG:1)
Block(4,2,2,LOG:1)
Block(4,3,0,LOG:1)
Block(4,3,1,WOOD:1)
Block(4,3,2,LOG:1)
Block(4,4,0,LOG:1)
RandomBlock(4,4,1,SPRUCE_WOOD_STAIRS:1,70,DARK_OAK_STAIRS:1,100)
Block(4,4,2,LOG:1)
RandomBlock(4,5,-7,AIR,70,WALL_BANNER:5,../../NBT/Banners/viking_honor_1.nbt,20,WALL_BANNER:5,../../NBT/Banners/viking_honor_2.nbt,20,WALL_BANNER:5,../../NBT/Banners/viking_honor_3.nbt,20,WALL_BANNER:5,../../NBT/Banners/viking_honor_4.nbt,20,WALL_BANNER:5,../../NBT/Banners/viking_honor_5.nbt,20,WALL_BANNER:5,../../NBT/Banners/viking_honor_6.nbt,100)
RandomBlock(4,5,-5,AIR,70,WALL_BANNER:5,../../NBT/Banners/viking_emblem_1.nbt,20,WALL_BANNER:5,../../NBT/Banners/viking_emblem_2.nbt,20,WALL_BANNER:5,../../NBT/Banners/viking_emblem_3.nbt,20,WALL_BANNER:5,../../NBT/Banners/viking_emblem_4.nbt,100)
RandomBlock(4,5,-3,AIR,70,WALL_BANNER:5,../../NBT/Banners/viking_honor_1.nbt,20,WALL_BANNER:5,../../NBT/Banners/viking_honor_2.nbt,20,WALL_BANNER:5,../../NBT/Banners/viking_honor_3.nbt,20,WALL_BANNER:5,../../NBT/Banners/viking_honor_4.nbt,20,WALL_BANNER:5,../../NBT/Banners/viking_honor_5.nbt,20,WALL_BANNER:5,../../NBT/Banners/viking_honor_6.nbt,100)
RandomBlock(4,5,-1,AIR,70,WALL_BANNER:5,../../NBT/Banners/viking_wealthy_1.nbt,20,WALL_BANNER:5,../../NBT/Banners/viking_wealthy_2.nbt,20,WALL_BANNER:5,../../NBT/Banners/viking_wealthy_3.nbt,20,WALL_BANNER:5,../../NBT/Banners/viking_wealthy_4.nbt,20,WALL_BANNER:5,../../NBT/Banners/viking_wealthy_5.nbt,20,WALL_BANNER:5,../../NBT/Banners/viking_wealthy_6.nbt,20,WALL_BANNER:5,../../NBT/Banners/viking_wealthy_7.nbt,20,WALL_BANNER:5,../../NBT/Banners/viking_wealthy_8.nbt,20,WALL_BANNER:5,../../NBT/Banners/viking_wealthy_9.nbt,100)
Block(4,5,0,LOG:1)
Block(4,5,2,LOG:1)
RandomBlock(4,5,3,AIR,70,WALL_BANNER:5,../../NBT/Banners/viking_wealthy_1.nbt,20,WALL_BANNER:5,../../NBT/Banners/viking_wealthy_2.nbt,20,WALL_BANNER:5,../../NBT/Banners/viking_wealthy_3.nbt,20,WALL_BANNER:5,../../NBT/Banners/viking_wealthy_4.nbt,20,WALL_BANNER:5,../../NBT/Banners/viking_wealthy_5.nbt,20,WALL_BANNER:5,../../NBT/Banners/viking_wealthy_6.nbt,20,WALL_BANNER:5,../../NBT/Banners/viking_wealthy_7.nbt,20,WALL_BANNER:5,../../NBT/Banners/viking_wealthy_8.nbt,20,WALL_BANNER:5,../../NBT/Banners/viking_wealthy_9.nbt,100)
RandomBlock(4,5,5,AIR,70,WALL_BANNER:5,../../NBT/Banners/viking_regular_1.nbt,20,WALL_BANNER:5,../../NBT/Banners/viking_regular_2.nbt,20,WALL_BANNER:5,../../NBT/Banners/viking_regular_3.nbt,20,WALL_BANNER:5,../../NBT/Banners/viking_regular_4.nbt,20,WALL_BANNER:5,../../NBT/Banners/viking_regular_5.nbt,20,WALL_BANNER:5,../../NBT/Banners/viking_regular_6.nbt,20,WALL_BANNER:5,../../NBT/Banners/viking_regular_7.nbt,20,WALL_BANNER:5,../../NBT/Banners/viking_regular_8.nbt,100)
RandomBlock(4,5,7,AIR,70,WALL_BANNER:5,../../NBT/Banners/viking_wealthy_1.nbt,20,WALL_BANNER:5,../../NBT/Banners/viking_wealthy_2.nbt,20,WALL_BANNER:5,../../NBT/Banners/viking_wealthy_3.nbt,20,WALL_BANNER:5,../../NBT/Banners/viking_wealthy_4.nbt,20,WALL_BANNER:5,../../NBT/Banners/viking_wealthy_5.nbt,20,WALL_BANNER:5,../../NBT/Banners/viking_wealthy_6.nbt,20,WALL_BANNER:5,../../NBT/Banners/viking_wealthy_7.nbt,20,WALL_BANNER:5,../../NBT/Banners/viking_wealthy_8.nbt,20,WALL_BANNER:5,../../NBT/Banners/viking_wealthy_9.nbt,100)
Block(4,6,0,LOG:1)
Block(4,6,2,LOG:1)
RandomBlock(4,7,-1,SPRUCE_WOOD_STAIRS:2,70,DARK_OAK_STAIRS:2,100)
Block(4,7,0,LOG:1)
Block(4,7,2,LOG:1)
RandomBlock(4,7,3,SPRUCE_WOOD_STAIRS:3,70,DARK_OAK_STAIRS:3,100)
RandomBlock(4,8,0,SPRUCE_WOOD_STAIRS:2,70,DARK_OAK_STAIRS:2,100)
Block(4,8,1,SPRUCE_WOOD_STAIRS:4)
RandomBlock(4,8,2,SPRUCE_WOOD_STAIRS:3,70,DARK_OAK_STAIRS:3,100)
RandomBlock(4,9,1,WOOD_STEP:1,70,WOOD_STEP:5,100)
Block(5,0,5,SPRUCE_WOOD_STAIRS:6)
RandomBlock(5,0,6,SPRUCE_WOOD_STAIRS:3,70,DARK_OAK_STAIRS:3,100)
Block(5,1,4,SPRUCE_WOOD_STAIRS:6)
RandomBlock(5,1,5,SPRUCE_WOOD_STAIRS:3,70,DARK_OAK_STAIRS:3,100)
Block(5,2,3,SPRUCE_WOOD_STAIRS:6)
RandomBlock(5,2,4,SPRUCE_WOOD_STAIRS:3,70,DARK_OAK_STAIRS:3,100)
Block(5,3,0,WOOD:1)
Block(5,3,1,WOOD:1)
Block(5,3,2,WOOD:1)
RandomBlock(5,3,3,SPRUCE_WOOD_STAIRS:3,70,DARK_OAK_STAIRS:3,100)
Block(5,4,0,SPRUCE_FENCE:0)
RandomBlock(5,7,-1,SPRUCE_WOOD_STAIRS:2,70,DARK_OAK_STAIRS:2,100)
RandomBlock(5,7,3,SPRUCE_WOOD_STAIRS:3,70,DARK_OAK_STAIRS:3,100)
RandomBlock(5,8,0,SPRUCE_WOOD_STAIRS:2,70,DARK_OAK_STAIRS:2,100)
RandomBlock(5,8,2,SPRUCE_WOOD_STAIRS:3,70,DARK_OAK_STAIRS:3,100)
Block(5,9,1,TRAP_DOOR:2)
Block(6,0,0,LOG:1)
Block(6,0,2,LOG:1)
Block(6,1,0,LOG:1)
Block(6,1,2,LOG:1)
Block(6,2,0,LOG:1)
Block(6,2,2,LOG:1)
Block(6,3,0,LOG:1)
Block(6,3,1,WOOD:1)
Block(6,3,2,LOG:1)
Block(6,4,0,LOG:1)
Block(6,4,1,SPRUCE_FENCE:0)
Block(6,4,2,LOG:1)
Block(6,5,0,LOG:1)
Block(6,5,2,LOG:1)
Block(6,6,0,LOG:1)
Block(6,6,2,LOG:1)
RandomBlock(6,7,-1,SPRUCE_WOOD_STAIRS:2,70,DARK_OAK_STAIRS:2,100)
Block(6,7,0,LOG:1)
Block(6,7,2,LOG:1)
RandomBlock(6,7,3,SPRUCE_WOOD_STAIRS:3,70,DARK_OAK_STAIRS:3,100)
RandomBlock(6,8,0,SPRUCE_WOOD_STAIRS:2,70,DARK_OAK_STAIRS:2,100)
Block(6,8,1,SPRUCE_WOOD_STAIRS:5)
RandomBlock(6,8,2,SPRUCE_WOOD_STAIRS:3,70,DARK_OAK_STAIRS:3,100)
RandomBlock(6,9,1,WOOD_STEP:1,70,WOOD_STEP:5,100)
Branch(0,0,16,true,viking_ship_construct_01C0R2,NORTH,100.0,0)
Entity(-1,6,7,minecraft:stray,1,../../NBT/Entities/VikingVillage/frossen_kriger.txt)
Entity(1,6,-3,minecraft:stray,1,../../NBT/Entities/VikingVillage/frossen_kriger.txt)
