Author: NLBlackEagle
Description: No description given
SettingsMode: WriteDisable
Frequency: 0
SpawnHeight: highestBlock
UseCenterForHighestBlock: true
MinHeight: 0
MaxHeight: 255
InheritBO3: 
InheritBO3Rotation: NORTH
OverrideChildSettings: true
OverrideParentHeight: false
CanOverride: false
BranchFrequency: 0
BranchFrequencyGroup: 
MustBeBelowOther: false
MustBeInside: 
CannotBeInside: 
ReplacesBO3: 
MustBeInsideWorldBorders: false
CanSpawnOnWater: true
SpawnOnWaterOnly: false
SpawnUnderWater: false
SpawnAtWaterLevel: false
HeightOffset: 0
RemoveAir: true
ReplaceAbove: 
ReplaceBelow: 
ReplaceWithBiomeBlocks: true
ReplaceWithSurfaceBlock: GRASS
ReplaceWithGroundBlock: DIRT
ReplaceWithStoneBlock: STONE
SmoothRadius: 0
SmoothHeightOffset: 0
SmoothStartTop: false
SmoothStartWood: false
SmoothingSurfaceBlock: 
SmoothingGroundBlock: 
BO3Group: 
IsSpawnPoint: false
DoReplaceBlocks: true
Block(-7,0,-4,LOG:1)
Block(-7,1,-4,LOG:1)
Block(-7,2,-4,LOG:1)
Block(-7,3,-4,LOG:1)
Block(-7,4,-4,LOG:1)
Block(-7,5,-4,LOG:1)
Block(-7,6,-4,LOG:1)
Block(-7,7,-4,LOG:1)
RandomBlock(-7,8,-4,SPRUCE_WOOD_STAIRS:0,70,DARK_OAK_STAIRS:0,100)
Block(-6,8,-4,SPRUCE_WOOD_STAIRS:5)
RandomBlock(-6,9,-4,SPRUCE_WOOD_STAIRS:0,70,DARK_OAK_STAIRS:0,100)
Block(-5,9,-4,SPRUCE_WOOD_STAIRS:5)
RandomBlock(-5,10,-4,SPRUCE_WOOD_STAIRS:0,70,DARK_OAK_STAIRS:0,100)
Block(-5,11,-4,SPRUCE_WOOD_STAIRS:4)
RandomBlock(-5,12,-4,WOOD_STEP:1,70,WOOD_STEP:5,100)
Block(-4,0,-4,LOG:1)
Block(-4,1,-4,LOG:1)
Block(-4,2,-4,LOG:1)
Block(-4,3,-4,LOG:1)
Block(-4,4,-4,LOG:1)
Block(-4,5,-4,LOG:1)
Block(-4,6,-4,LOG:1)
Block(-4,7,-4,LOG:1)
Block(-4,8,-7,LOG:9)
Block(-4,8,-6,WOOD_BUTTON:3)
Block(-4,8,-4,LOG:1)
Block(-4,9,-4,LOG:1)
RandomBlock(-4,9,-3,AIR,70,WALL_BANNER:3,../../NBT/Banners/viking_emblem_1.nbt,20,WALL_BANNER:3,../../NBT/Banners/viking_emblem_2.nbt,20,WALL_BANNER:3,../../NBT/Banners/viking_emblem_3.nbt,20,WALL_BANNER:3,../../NBT/Banners/viking_emblem_4.nbt,100)
Block(-4,10,-7,LOG:9)
Block(-4,10,-6,LOG:9)
Block(-4,10,-5,LOG:9)
Block(-4,10,-4,LOG:9)
Block(-4,10,-3,LOG:9)
Block(-4,10,-2,WOOD_BUTTON:3)
Block(-4,11,-4,LOG:1)
Block(-4,12,-4,TRAP_DOOR:2)
Block(-4,14,-7,WOOD_BUTTON:3)
Block(-3,10,-7,SPRUCE_WOOD_STAIRS:5)
Block(-3,10,-6,SPRUCE_WOOD_STAIRS:5)
Block(-3,10,-5,SPRUCE_WOOD_STAIRS:5)
RandomBlock(-3,11,-7,SPRUCE_WOOD_STAIRS:0,70,DARK_OAK_STAIRS:0,100)
RandomBlock(-3,11,-6,SPRUCE_WOOD_STAIRS:0,70,DARK_OAK_STAIRS:0,100)
RandomBlock(-3,11,-5,SPRUCE_WOOD_STAIRS:0,70,DARK_OAK_STAIRS:0,100)
Block(-3,11,-4,SPRUCE_WOOD_STAIRS:5)
RandomBlock(-3,12,-4,SPRUCE_WOOD_STAIRS:0,70,DARK_OAK_STAIRS:0,100)
Block(-2,0,-7,STONE:6)
Block(-2,1,-7,STONE:6)
Block(-2,2,-7,STONE:6)
Block(-2,3,-7,STONE:6)
Block(-2,4,-7,STONE:6)
Block(-2,5,-7,COBBLESTONE_STAIRS:3)
Block(-2,11,-7,SPRUCE_WOOD_STAIRS:5)
Block(-2,11,-6,SPRUCE_WOOD_STAIRS:5)
Block(-2,11,-5,SPRUCE_WOOD_STAIRS:5)
RandomBlock(-2,12,-7,SPRUCE_WOOD_STAIRS:0,70,DARK_OAK_STAIRS:0,100)
RandomBlock(-2,12,-6,SPRUCE_WOOD_STAIRS:0,70,DARK_OAK_STAIRS:0,100)
RandomBlock(-2,12,-5,SPRUCE_WOOD_STAIRS:0,70,DARK_OAK_STAIRS:0,100)
Block(-2,12,-4,SPRUCE_WOOD_STAIRS:5)
RandomBlock(-2,13,-4,SPRUCE_WOOD_STAIRS:0,70,DARK_OAK_STAIRS:0,100)
Block(-1,0,-7,STONE:6)
Block(-1,1,-7,STONE:6)
Block(-1,2,-7,STONE:6)
Block(-1,3,-7,STONE:6)
Block(-1,4,-7,STONE:6)
Block(-1,5,-7,COBBLESTONE_STAIRS:3)
Block(-1,12,-7,SPRUCE_WOOD_STAIRS:5)
Block(-1,12,-6,SPRUCE_WOOD_STAIRS:5)
Block(-1,12,-5,SPRUCE_WOOD_STAIRS:5)
RandomBlock(-1,13,-7,SPRUCE_WOOD_STAIRS:0,70,DARK_OAK_STAIRS:0,100)
RandomBlock(-1,13,-6,SPRUCE_WOOD_STAIRS:0,70,DARK_OAK_STAIRS:0,100)
RandomBlock(-1,13,-5,SPRUCE_WOOD_STAIRS:0,70,DARK_OAK_STAIRS:0,100)
Block(-1,13,-4,SPRUCE_WOOD_STAIRS:5)
RandomBlock(-1,14,-4,SPRUCE_WOOD_STAIRS:0,70,DARK_OAK_STAIRS:0,100)
Block(-1,16,-7,WOOD_BUTTON:3)
Block(-1,17,-7,WOOD_BUTTON:3)
Block(0,0,-7,STONE:6)
Block(0,1,-7,STONE:6)
Block(0,2,-7,STONE:6)
Block(0,3,-7,STONE:6)
Block(0,4,-7,STONE:6)
Block(0,5,-7,COBBLESTONE_STAIRS:3)
Block(0,12,-7,SPRUCE_WOOD_STAIRS:4)
Block(0,12,-6,SPRUCE_WOOD_STAIRS:4)
Block(0,12,-5,SPRUCE_WOOD_STAIRS:4)
RandomBlock(0,13,-7,SPRUCE_WOOD_STAIRS:1,70,DARK_OAK_STAIRS:1,100)
RandomBlock(0,13,-6,SPRUCE_WOOD_STAIRS:1,70,DARK_OAK_STAIRS:1,100)
RandomBlock(0,13,-5,SPRUCE_WOOD_STAIRS:1,70,DARK_OAK_STAIRS:1,100)
Block(0,13,-4,SPRUCE_WOOD_STAIRS:4)
RandomBlock(0,14,-4,SPRUCE_WOOD_STAIRS:1,70,DARK_OAK_STAIRS:1,100)
Block(0,16,-7,WOOD_BUTTON:3)
Block(0,17,-7,WOOD_BUTTON:3)
Block(1,0,-7,STONE:6)
Block(1,1,-7,STONE:6)
Block(1,2,-7,STONE:6)
Block(1,3,-7,STONE:6)
Block(1,4,-7,STONE:6)
Block(1,5,-7,COBBLESTONE_STAIRS:3)
Block(1,11,-7,SPRUCE_WOOD_STAIRS:4)
Block(1,11,-6,SPRUCE_WOOD_STAIRS:4)
Block(1,11,-5,SPRUCE_WOOD_STAIRS:4)
RandomBlock(1,12,-7,SPRUCE_WOOD_STAIRS:1,70,DARK_OAK_STAIRS:1,100)
RandomBlock(1,12,-6,SPRUCE_WOOD_STAIRS:1,70,DARK_OAK_STAIRS:1,100)
RandomBlock(1,12,-5,SPRUCE_WOOD_STAIRS:1,70,DARK_OAK_STAIRS:1,100)
Block(1,12,-4,SPRUCE_WOOD_STAIRS:4)
RandomBlock(1,13,-4,SPRUCE_WOOD_STAIRS:1,70,DARK_OAK_STAIRS:1,100)
Block(2,10,-7,SPRUCE_WOOD_STAIRS:4)
Block(2,10,-6,SPRUCE_WOOD_STAIRS:4)
Block(2,10,-5,SPRUCE_WOOD_STAIRS:4)
RandomBlock(2,11,-7,SPRUCE_WOOD_STAIRS:1,70,DARK_OAK_STAIRS:1,100)
RandomBlock(2,11,-6,SPRUCE_WOOD_STAIRS:1,70,DARK_OAK_STAIRS:1,100)
RandomBlock(2,11,-5,SPRUCE_WOOD_STAIRS:1,70,DARK_OAK_STAIRS:1,100)
Block(2,11,-4,SPRUCE_WOOD_STAIRS:4)
RandomBlock(2,12,-4,SPRUCE_WOOD_STAIRS:1,70,DARK_OAK_STAIRS:1,100)
Block(3,0,-4,LOG:1)
Block(3,1,-4,LOG:1)
Block(3,2,-4,LOG:1)
Block(3,3,-4,LOG:1)
Block(3,4,-4,LOG:1)
Block(3,5,-4,LOG:1)
Block(3,6,-4,LOG:1)
Block(3,7,-4,LOG:1)
Block(3,8,-7,LOG:9)
Block(3,8,-6,WOOD_BUTTON:3)
Block(3,8,-4,LOG:1)
Block(3,9,-4,LOG:1)
RandomBlock(3,9,-3,AIR,70,WALL_BANNER:3,../../NBT/Banners/viking_emblem_1.nbt,20,WALL_BANNER:3,../../NBT/Banners/viking_emblem_2.nbt,20,WALL_BANNER:3,../../NBT/Banners/viking_emblem_3.nbt,20,WALL_BANNER:3,../../NBT/Banners/viking_emblem_4.nbt,100)
Block(3,10,-7,LOG:9)
Block(3,10,-6,LOG:9)
Block(3,10,-5,LOG:9)
Block(3,10,-4,LOG:9)
Block(3,10,-3,LOG:9)
Block(3,10,-2,WOOD_BUTTON:3)
Block(3,11,-4,LOG:1)
Block(3,12,-4,TRAP_DOOR:1)
Block(4,9,-4,SPRUCE_WOOD_STAIRS:4)
RandomBlock(4,10,-4,SPRUCE_WOOD_STAIRS:1,70,DARK_OAK_STAIRS:1,100)
Block(4,11,-4,SPRUCE_WOOD_STAIRS:5)
RandomBlock(4,12,-4,WOOD_STEP:1,70,WOOD_STEP:5,100)
Block(5,8,-4,SPRUCE_WOOD_STAIRS:4)
RandomBlock(5,9,-4,SPRUCE_WOOD_STAIRS:1,70,DARK_OAK_STAIRS:1,100)
Block(6,0,-4,LOG:1)
Block(6,1,-4,LOG:1)
Block(6,2,-4,LOG:1)
Block(6,3,-4,LOG:1)
Block(6,4,-4,LOG:1)
Block(6,5,-4,LOG:1)
Block(6,6,-4,LOG:1)
Block(6,7,-4,LOG:1)
RandomBlock(6,8,-4,SPRUCE_WOOD_STAIRS:1,70,DARK_OAK_STAIRS:1,100)
Branch(0,0,-16,true,viking_greathallC1R2,NORTH,100.0,0)
