
#######################################################################
# +-----------------------------------------------------------------+ #
# |                            BO3 object                           | #
# +-----------------------------------------------------------------+ #
#######################################################################

Author: NLBlackEagle

Description: Converted version of the BO2 47

Version: 3

SettingsMode: WriteDisable


#######################################################################
# +-----------------------------------------------------------------+ #
# |                          Main settings                          | #
# +-----------------------------------------------------------------+ #
#######################################################################

Tree: true

Frequency: 1

Rarity: 100.0

RotateRandomly: true

SpawnHeight: highestSolidBlock

SpawnHeightOffset: 0

SpawnHeightVariance: 0

##############################
# Height Limits for the BO3. #
##############################

MinHeight: 0

MaxHeight: 255

######################
# Extrusion settings #
######################

ExtrudeMode: None

ExtrudeThroughBlocks: AIR

MaxBranchDepth: 10

ExcludedBiomes: 


#######################################################################
# +-----------------------------------------------------------------+ #
# |                      Source block settings                      | #
# +-----------------------------------------------------------------+ #
#######################################################################

SourceBlocks: AIR,GRAVEL,STONE

MaxPercentageOutsideSourceBlock: 0

OutsideSourceBlock: placeAnyway

DoReplaceBlocks: true

IsOTGPlus: false


#######################################################################
# +-----------------------------------------------------------------+ #
# |                              Blocks                             | #
# +-----------------------------------------------------------------+ #
#######################################################################

Block(0,29,2,LEAVES:4)
Block(0,20,-2,LEAVES:4)
Block(0,21,-2,LEAVES:4)
Block(0,22,-2,LEAVES:4)
Block(0,25,2,LEAVES:4)
Block(0,24,2,LEAVES:4)
Block(0,21,2,LEAVES:4)
Block(0,20,2,LEAVES:4)
Block(2,9,2,LEAVES:4)
Block(-1,-1,-1,LOG:13)
Block(-1,-2,-1,LOG:13)
Block(2,9,7,LEAVES:4)
Block(0,28,-2,LEAVES:4)
Block(-3,25,1,LEAVES:4)
Block(0,29,-2,LEAVES:4)
Block(-1,-5,-1,LOG:13)
Block(-3,24,1,LEAVES:4)
Block(-1,-7,-1,LOG:13)
Block(-3,20,1,LEAVES:4)
Block(0,11,-2,LEAVES:4)
Block(0,18,2,LEAVES:4)
Block(0,17,2,LEAVES:4)
Block(-1,1,0,LOG:13)
Block(-1,0,0,LOG:13)
Block(-1,3,0,LOG:13)
Block(0,0,2,LOG:13)
Block(-2,-1,0,LOG:13)
Block(-1,2,0,LOG:13)
Block(-2,-2,0,LOG:13)
Block(0,12,2,LEAVES:4)
Block(0,11,2,LEAVES:4)
Block(-3,8,4,LEAVES:4)
Block(-2,-4,0,LOG:13)
Block(-5,10,-5,LEAVES:4)
Block(-2,-5,0,LOG:13)
Block(-2,-6,0,LOG:13)
Block(-2,-8,0,LOG:13)
Block(3,8,1,LEAVES:4)
Block(3,9,1,LEAVES:4)
Block(-1,4,0,LOG:13)
Block(-1,5,0,LOG:13)
Block(-3,16,1,LEAVES:4)
Block(-1,6,0,LOG:13)
Block(-3,15,1,LEAVES:4)
Block(-1,7,0,LOG:13)
Block(-3,14,1,LEAVES:4)
Block(-1,8,0,LOG:13)
Block(-1,9,0,LOG:13)
Block(-3,12,1,LEAVES:4)
Block(-3,11,1,LEAVES:4)
Block(1,9,-5,LEAVES:4)
Block(-7,8,0,LEAVES:4)
Block(-7,9,0,LEAVES:4)
Block(0,34,-2,LEAVES:4)
Block(0,33,-2,LEAVES:4)
Block(0,30,-2,LEAVES:4)
Block(3,10,-2,LEAVES:4)
Block(0,9,6,LEAVES:4)
Block(3,19,-2,LEAVES:4)
Block(3,15,-2,LEAVES:4)
Block(3,16,-2,LEAVES:4)
Block(5,8,1,LEAVES:4)
Block(-2,29,0,LOG:13)
Block(4,9,-2,LEAVES:4)
Block(-2,28,0,LOG:13)
Block(-2,27,0,LEAVES:4)
Block(4,7,-2,LEAVES:4)
Block(-3,39,-1,LEAVES:4)
Block(-2,22,0,LOG:13)
Block(-2,21,0,LOG:13)
Block(-3,38,-1,LEAVES:4)
Block(-2,20,0,LOG:13)
Block(-2,26,0,LEAVES:4)
Block(-3,31,-1,LEAVES:4)
Block(-2,25,0,LEAVES:4)
Block(-3,34,-1,LEAVES:4)
Block(-2,24,0,LEAVES:4)
Block(-3,33,-1,LEAVES:4)
Block(-2,23,0,LEAVES:4)
Block(-3,40,-1,LEAVES:4)
Block(-3,33,-2,LEAVES:4)
Block(1,9,-4,LEAVES:4)
Block(-3,32,-2,LEAVES:4)
Block(-3,35,-2,LEAVES:4)
Block(-3,36,-2,LEAVES:4)
Block(-2,17,0,LEAVES:4)
Block(-2,16,0,LEAVES:4)
Block(3,17,0,LEAVES:4)
Block(3,14,0,LEAVES:4)
Block(-2,19,0,LOG:13)
Block(3,15,0,LEAVES:4)
Block(-2,18,0,LEAVES:4)
Block(-3,29,-1,LEAVES:4)
Block(-3,28,-1,LEAVES:4)
Block(-3,27,-1,LEAVES:4)
Block(0,-5,2,LOG:13)
Block(0,-3,2,LOG:13)
Block(-2,11,0,LEAVES:4)
Block(-2,10,0,LEAVES:4)
Block(0,-4,2,LOG:13)
Block(0,-1,2,LOG:13)
Block(3,12,0,LEAVES:4)
Block(-2,13,0,LEAVES:4)
Block(-3,22,-1,LEAVES:4)
Block(-2,12,0,LEAVES:4)
Block(3,13,0,LEAVES:4)
Block(-3,21,-1,LEAVES:4)
Block(3,10,0,LEAVES:4)
Block(-2,15,0,LEAVES:4)
Block(3,11,0,LEAVES:4)
Block(-2,14,0,LEAVES:4)
Block(-3,30,-1,LEAVES:4)
Block(-3,-6,1,LOG:13)
Block(-3,-7,1,LOG:13)
Block(-3,-5,1,LOG:13)
Block(-3,18,-1,LEAVES:4)
Block(-3,17,-1,LEAVES:4)
Block(-5,9,1,LEAVES:4)
Block(-4,7,-4,LEAVES:4)
Block(-3,10,-1,LEAVES:4)
Block(-4,8,-4,LEAVES:4)
Block(-3,12,-1,LEAVES:4)
Block(-3,11,-1,LEAVES:4)
Block(-3,13,-1,LEAVES:4)
Block(-3,15,-1,LEAVES:4)
Block(1,10,5,LEAVES:4)
Block(6,8,1,LEAVES:4)
Block(-3,15,-2,LEAVES:4)
Block(-3,14,-2,LEAVES:4)
Block(-3,17,-2,LEAVES:4)
Block(0,12,-5,LEAVES:4)
Block(-3,13,-5,LEAVES:4)
Block(-3,12,-2,LEAVES:4)
Block(-6,8,5,LEAVES:4)
Block(-5,7,3,LEAVES:4)
Block(-2,37,-2,LEAVES:4)
Block(-2,35,-2,LEAVES:4)
Block(-2,36,-2,LEAVES:4)
Block(-2,42,-2,LEAVES:4)
Block(-5,6,5,LEAVES:4)
Block(-5,7,5,LEAVES:4)
Block(-5,8,5,LEAVES:4)
Block(-3,27,-2,LEAVES:4)
Block(-3,26,-2,LEAVES:4)
Block(-3,25,-2,LEAVES:4)
Block(-4,8,3,LEAVES:4)
Block(-3,22,-2,LEAVES:4)
Block(2,9,0,LEAVES:4)
Block(-1,9,2,LEAVES:4)
Block(-3,9,-5,LEAVES:4)
Block(2,26,-1,LEAVES:4)
Block(2,27,-1,LEAVES:4)
Block(-3,7,-5,LEAVES:4)
Block(-2,32,-2,LEAVES:4)
Block(-2,25,-2,LEAVES:4)
Block(-2,24,-2,LEAVES:4)
Block(-2,23,-2,LEAVES:4)
Block(-3,9,-3,LEAVES:4)
Block(-6,9,-3,LEAVES:4)
Block(0,9,-5,LEAVES:4)
Block(-3,6,6,LEAVES:4)
Block(-2,47,-1,LEAVES:4)
Block(-3,8,-3,LEAVES:4)
Block(-3,7,6,LEAVES:4)
Block(0,8,-5,LEAVES:4)
Block(2,20,-1,LEAVES:4)
Block(-2,44,-1,LEAVES:4)
Block(-2,-1,2,LOG:13)
Block(-2,43,-1,LEAVES:4)
Block(-2,26,-2,LEAVES:4)
Block(-6,6,-3,LEAVES:4)
Block(-5,10,6,LEAVES:4)
Block(-1,1,2,LOG:13)
Block(-1,0,2,LOG:13)
Block(-2,-8,2,LOG:13)
Block(-5,11,6,LEAVES:4)
Block(-1,44,-1,LEAVES:4)
Block(-1,45,-1,LEAVES:4)
Block(1,9,7,LEAVES:4)
Block(-1,46,-1,LEAVES:4)
Block(-4,25,3,LEAVES:4)
Block(-5,22,0,LEAVES:4)
Block(-5,25,0,LEAVES:4)
Block(2,10,7,LEAVES:4)
Block(-4,26,3,LEAVES:4)
Block(4,7,2,LEAVES:4)
Block(-5,29,0,LEAVES:4)
Block(-5,28,0,LEAVES:4)
Block(4,8,2,LEAVES:4)
Block(-2,54,0,LOG:13)
Block(-2,12,-2,LEAVES:4)
Block(-2,55,0,LOG:13)
Block(-2,52,0,LOG:13)
Block(-2,53,0,LOG:13)
Block(-2,15,-2,LEAVES:4)
Block(2,32,-1,LEAVES:4)
Block(-2,19,-2,LEAVES:4)
Block(-3,10,7,LEAVES:4)
Block(-2,10,-2,LEAVES:4)
Block(-2,51,0,LOG:13)
Block(2,12,3,LEAVES:4)
Block(-4,18,3,LEAVES:4)
Block(-2,50,0,LOG:13)
Block(-4,15,3,LEAVES:4)
Block(-4,14,3,LEAVES:4)
Block(-2,45,0,LOG:13)
Block(-2,24,-1,LEAVES:4)
Block(-5,20,0,LEAVES:4)
Block(-2,46,0,LOG:13)
Block(-2,23,-1,LEAVES:4)
Block(-2,47,0,LEAVES:4)
Block(-2,22,-1,LEAVES:4)
Block(-2,48,0,LOG:13)
Block(-2,21,-1,LEAVES:4)
Block(-2,41,0,LEAVES:4)
Block(-2,28,-1,LEAVES:4)
Block(-2,42,0,LEAVES:4)
Block(-2,27,-1,LEAVES:4)
Block(-2,43,0,LOG:13)
Block(-2,26,-1,LEAVES:4)
Block(-2,44,0,LOG:13)
Block(-2,25,-1,LEAVES:4)
Block(5,12,2,LEAVES:4)
Block(-2,29,-1,LEAVES:4)
Block(5,13,2,LEAVES:4)
Block(-2,49,0,LOG:13)
Block(5,14,2,LEAVES:4)
Block(3,26,0,LEAVES:4)
Block(-2,40,0,LOG:13)
Block(2,19,-1,LEAVES:4)
Block(2,17,-1,LEAVES:4)
Block(-2,40,-1,LEAVES:4)
Block(2,16,-1,LEAVES:4)
Block(-2,41,-1,LEAVES:4)
Block(2,13,-1,LEAVES:4)
Block(-2,42,-1,LEAVES:4)
Block(-2,36,0,LOG:13)
Block(-2,33,-1,LEAVES:4)
Block(2,12,-1,LEAVES:4)
Block(-2,37,0,LOG:13)
Block(2,11,-1,LEAVES:4)
Block(-6,14,4,LEAVES:4)
Block(-2,34,0,LOG:13)
Block(-6,13,4,LEAVES:4)
Block(-2,35,0,LOG:13)
Block(-2,34,-1,LEAVES:4)
Block(-5,10,0,LEAVES:4)
Block(-4,12,3,LEAVES:4)
Block(-2,37,-1,LEAVES:4)
Block(-2,32,0,LOG:13)
Block(-2,36,-1,LEAVES:4)
Block(-2,33,0,LOG:13)
Block(-2,39,-1,LEAVES:4)
Block(-2,30,0,LOG:13)
Block(-2,38,-1,LEAVES:4)
Block(-2,31,0,LOG:13)
Block(-2,38,0,LOG:13)
Block(5,9,-2,LEAVES:4)
Block(-2,39,0,LOG:13)
Block(-2,20,2,LEAVES:4)
Block(-1,16,-1,LEAVES:4)
Block(-6,17,2,LEAVES:4)
Block(-1,15,-1,LEAVES:4)
Block(-1,14,-1,LEAVES:4)
Block(-1,13,-1,LEAVES:4)
Block(-6,18,2,LEAVES:4)
Block(-5,23,2,LEAVES:4)
Block(-1,12,-1,LEAVES:4)
Block(-5,22,2,LEAVES:4)
Block(-1,11,-1,LEAVES:4)
Block(-1,20,-1,LEAVES:4)
Block(-1,21,-1,LEAVES:4)
Block(-5,14,2,LEAVES:4)
Block(-2,18,2,LEAVES:4)
Block(-6,22,2,LEAVES:4)
Block(-5,18,2,LEAVES:4)
Block(-9,8,-1,LEAVES:4)
Block(-5,19,2,LEAVES:4)
Block(-9,9,-1,LEAVES:4)
Block(-2,13,2,LEAVES:4)
Block(-2,10,2,LEAVES:4)
Block(-2,16,2,LEAVES:4)
Block(-2,17,2,LEAVES:4)
Block(-2,14,2,LEAVES:4)
Block(2,22,3,LEAVES:4)
Block(-2,20,-1,LEAVES:4)
Block(-2,31,2,LEAVES:4)
Block(-2,30,2,LEAVES:4)
Block(-1,10,-1,LEAVES:4)
Block(-2,19,-1,LEAVES:4)
Block(-2,21,2,LEAVES:4)
Block(-2,14,-1,LEAVES:4)
Block(2,27,1,LEAVES:4)
Block(-2,15,-1,LEAVES:4)
Block(2,26,1,LEAVES:4)
Block(-2,16,-1,LEAVES:4)
Block(1,-3,2,LOG:13)
Block(-2,10,-1,LEAVES:4)
Block(1,-5,2,LOG:13)
Block(-2,28,2,LEAVES:4)
Block(-2,13,-1,LEAVES:4)
Block(-1,36,-1,LEAVES:4)
Block(2,10,-2,LEAVES:4)
Block(-1,35,-1,LEAVES:4)
Block(2,11,-2,LEAVES:4)
Block(-1,34,-1,LEAVES:4)
Block(-1,33,-1,LEAVES:4)
Block(-1,39,-1,LEAVES:4)
Block(2,9,-5,LEAVES:4)
Block(-1,38,-1,LEAVES:4)
Block(2,11,1,LEAVES:4)
Block(2,10,1,LEAVES:4)
Block(-2,6,6,LEAVES:4)
Block(2,15,-2,LEAVES:4)
Block(-1,43,-1,LEAVES:4)
Block(-1,40,-1,LEAVES:4)
Block(2,9,-3,LEAVES:4)
Block(2,16,-2,LEAVES:4)
Block(-2,38,2,LEAVES:4)
Block(-2,13,-5,LEAVES:4)
Block(2,19,1,LEAVES:4)
Block(-2,12,-5,LEAVES:4)
Block(2,18,1,LEAVES:4)
Block(2,15,1,LEAVES:4)
Block(2,14,1,LEAVES:4)
Block(-2,33,2,LEAVES:4)
Block(-2,17,-5,LEAVES:4)
Block(-1,23,-1,LEAVES:4)
Block(-7,8,-2,LEAVES:4)
Block(-1,22,-1,LEAVES:4)
Block(-1,25,-1,LEAVES:4)
Block(-1,24,-1,LEAVES:4)
Block(-1,26,-1,LEAVES:4)
Block(2,20,-2,LEAVES:4)
Block(-1,30,-1,LEAVES:4)
Block(-1,31,-1,LEAVES:4)
Block(-1,32,-1,LEAVES:4)
Block(2,9,-1,LEAVES:4)
Block(-4,12,-6,LEAVES:4)
Block(-1,-1,2,LOG:13)
Block(-4,21,0,LEAVES:4)
Block(-1,-2,2,LOG:13)
Block(-4,24,0,LEAVES:4)
Block(1,19,2,LEAVES:4)
Block(-4,23,0,LEAVES:4)
Block(1,18,2,LEAVES:4)
Block(-4,26,0,LEAVES:4)
Block(1,17,2,LEAVES:4)
Block(1,14,2,LEAVES:4)
Block(1,13,2,LEAVES:4)
Block(-4,29,0,LEAVES:4)
Block(1,12,2,LEAVES:4)
Block(-1,-7,2,LOG:13)
Block(1,11,2,LEAVES:4)
Block(-1,-6,2,LOG:13)
Block(-1,-3,2,LOG:13)
Block(-6,17,3,LEAVES:4)
Block(-4,23,2,LEAVES:4)
Block(-1,-4,2,LOG:13)
Block(-6,18,3,LEAVES:4)
Block(3,8,-3,LEAVES:4)
Block(1,10,6,LEAVES:4)
Block(3,9,-3,LEAVES:4)
Block(1,27,-3,LEAVES:4)
Block(-4,30,0,LEAVES:4)
Block(-4,31,0,LEAVES:4)
Block(-4,11,0,LEAVES:4)
Block(-4,10,0,LEAVES:4)
Block(-3,11,5,LEAVES:4)
Block(-4,19,2,LEAVES:4)
Block(-4,15,2,LEAVES:4)
Block(0,46,1,LEAVES:4)
Block(-6,14,3,LEAVES:4)
Block(-6,13,3,LEAVES:4)
Block(-4,22,2,LEAVES:4)
Block(-4,45,0,LEAVES:4)
Block(-3,26,4,LEAVES:4)
Block(0,39,1,LEAVES:4)
Block(0,38,1,LEAVES:4)
Block(0,36,1,LEAVES:4)
Block(0,35,1,LEAVES:4)
Block(0,20,5,LEAVES:4)
Block(0,31,1,LEAVES:4)
Block(0,30,1,LEAVES:4)
Block(-4,39,0,LEAVES:4)
Block(-2,-3,1,LOG:13)
Block(-4,38,0,LEAVES:4)
Block(1,10,-3,LEAVES:4)
Block(-2,-4,1,LOG:13)
Block(-2,-5,1,LOG:13)
Block(-2,-6,1,LOG:13)
Block(-2,-7,1,LOG:13)
Block(1,15,-3,LEAVES:4)
Block(-4,34,0,LEAVES:4)
Block(-4,33,0,LEAVES:4)
Block(-6,9,-5,LEAVES:4)
Block(-6,7,-5,LEAVES:4)
Block(-2,9,-5,LEAVES:4)
Block(-6,6,-5,LEAVES:4)
Block(-2,6,-5,LEAVES:4)
Block(-2,-1,1,LOG:13)
Block(-2,-2,1,LOG:13)
Block(-2,7,-5,LEAVES:4)
Block(0,24,1,LEAVES:4)
Block(0,23,1,LEAVES:4)
Block(0,25,1,LEAVES:4)
Block(0,20,1,LEAVES:4)
Block(1,19,-3,LEAVES:4)
Block(-3,26,5,LEAVES:4)
Block(-1,11,-2,LEAVES:4)
Block(-3,25,5,LEAVES:4)
Block(0,21,1,LEAVES:4)
Block(-8,8,-1,LEAVES:4)
Block(-1,12,-5,LEAVES:4)
Block(-6,19,-3,LEAVES:4)
Block(-8,9,-1,LEAVES:4)
Block(-1,18,2,LEAVES:4)
Block(-1,17,2,LEAVES:4)
Block(-1,15,-2,LEAVES:4)
Block(-1,13,2,LEAVES:4)
Block(-1,12,2,LEAVES:4)
Block(-1,19,-2,LEAVES:4)
Block(-5,7,-3,LEAVES:4)
Block(-1,11,2,LEAVES:4)
Block(-1,18,-2,LEAVES:4)
Block(-1,10,2,LEAVES:4)
Block(-5,8,-3,LEAVES:4)
Block(-6,15,-3,LEAVES:4)
Block(-4,7,5,LEAVES:4)
Block(0,10,1,LEAVES:4)
Block(-5,10,-2,LEAVES:4)
Block(-4,8,5,LEAVES:4)
Block(0,11,1,LEAVES:4)
Block(0,14,1,LEAVES:4)
Block(0,15,1,LEAVES:4)
Block(0,12,1,LEAVES:4)
Block(-4,34,-1,LEAVES:4)
Block(0,13,1,LEAVES:4)
Block(-4,33,-1,LEAVES:4)
Block(-4,32,-1,LEAVES:4)
Block(0,19,1,LEAVES:4)
Block(0,16,1,LEAVES:4)
Block(-4,30,-1,LEAVES:4)
Block(-5,16,-2,LEAVES:4)
Block(-1,22,-5,LEAVES:4)
Block(-1,24,-2,LEAVES:4)
Block(-1,13,-4,LEAVES:4)
Block(-1,23,-2,LEAVES:4)
Block(-6,17,1,LEAVES:4)
Block(-1,25,-2,LEAVES:4)
Block(-1,29,-2,LEAVES:4)
Block(-5,26,-2,LEAVES:4)
Block(-6,22,1,LEAVES:4)
Block(-5,25,-2,LEAVES:4)
Block(-1,30,-2,LEAVES:4)
Block(-4,28,-1,LEAVES:4)
Block(-5,20,-2,LEAVES:4)
Block(-1,31,-2,LEAVES:4)
Block(-4,27,-1,LEAVES:4)
Block(-4,29,-1,LEAVES:4)
Block(-5,21,-2,LEAVES:4)
Block(-4,26,-1,LEAVES:4)
Block(-2,9,3,LEAVES:4)
Block(-1,17,-5,LEAVES:4)
Block(-4,21,-1,LEAVES:4)
Block(2,18,2,LEAVES:4)
Block(2,17,2,LEAVES:4)
Block(1,34,2,LEAVES:4)
Block(2,19,2,LEAVES:4)
Block(-1,39,-2,LEAVES:4)
Block(-1,38,-2,LEAVES:4)
Block(-1,22,-4,LEAVES:4)
Block(2,14,2,LEAVES:4)
Block(-1,36,-2,LEAVES:4)
Block(2,13,2,LEAVES:4)
Block(-1,35,-2,LEAVES:4)
Block(2,12,2,LEAVES:4)
Block(-1,34,-2,LEAVES:4)
Block(-1,23,-4,LEAVES:4)
Block(-5,32,-2,LEAVES:4)
Block(-1,17,-4,LEAVES:4)
Block(4,9,1,LEAVES:4)
Block(5,11,-1,LEAVES:4)
Block(-1,18,-4,LEAVES:4)
Block(5,10,-1,LEAVES:4)
Block(4,8,1,LEAVES:4)
Block(3,26,1,LEAVES:4)
Block(1,9,8,LEAVES:4)
Block(-5,10,-3,LEAVES:4)
Block(3,9,6,LEAVES:4)
Block(0,-6,1,LOG:13)
Block(1,23,2,LEAVES:4)
Block(-5,16,-3,LEAVES:4)
Block(1,24,2,LEAVES:4)
Block(-5,15,-3,LEAVES:4)
Block(-6,9,-2,LEAVES:4)
Block(1,28,2,LEAVES:4)
Block(-6,8,-2,LEAVES:4)
Block(-4,15,-4,LEAVES:4)
Block(-5,19,-3,LEAVES:4)
Block(1,29,2,LEAVES:4)
Block(-1,45,-2,LEAVES:4)
Block(-4,13,-4,LEAVES:4)
Block(-4,12,-4,LEAVES:4)
Block(-6,20,-3,LEAVES:4)
Block(-4,11,-4,LEAVES:4)
Block(-6,8,1,LEAVES:4)
Block(3,10,1,LEAVES:4)
Block(-6,9,1,LEAVES:4)
Block(3,14,1,LEAVES:4)
Block(3,15,1,LEAVES:4)
Block(3,17,1,LEAVES:4)
Block(3,18,1,LEAVES:4)
Block(3,9,4,LEAVES:4)
Block(0,-1,1,LOG:13)
Block(0,-2,1,LOG:13)
Block(0,-5,1,LOG:13)
Block(5,7,3,LEAVES:4)
Block(0,-4,1,LOG:13)
Block(-1,43,0,LEAVES:4)
Block(0,2,0,LOG:13)
Block(-1,42,0,LOG:13)
Block(0,3,0,LOG:13)
Block(-1,41,0,LEAVES:4)
Block(0,0,0,LOG:13)
Block(-1,40,0,LEAVES:4)
Block(0,1,0,LOG:13)
Block(-1,47,0,LEAVES:4)
Block(0,6,0,LOG:13)
Block(0,7,0,LOG:13)
Block(0,4,0,LOG:13)
Block(-1,44,0,LEAVES:4)
Block(0,5,0,LOG:13)
Block(-3,9,-1,LEAVES:4)
Block(-5,25,-3,LEAVES:4)
Block(-5,26,-3,LEAVES:4)
Block(-5,20,-3,LEAVES:4)
Block(3,9,-5,LEAVES:4)
Block(1,10,7,LEAVES:4)
Block(-4,10,-1,LEAVES:4)
Block(-3,9,1,LEAVES:4)
Block(7,8,1,LEAVES:4)
Block(-4,12,-1,LEAVES:4)
Block(-4,17,-1,LEAVES:4)
Block(0,22,-3,LEAVES:4)
Block(-1,31,2,LEAVES:4)
Block(0,29,-3,LEAVES:4)
Block(-1,32,2,LEAVES:4)
Block(0,28,-3,LEAVES:4)
Block(-1,34,2,LEAVES:4)
Block(-1,35,2,LEAVES:4)
Block(-1,37,2,LEAVES:4)
Block(-1,38,2,LEAVES:4)
Block(-2,42,1,LEAVES:4)
Block(-2,43,1,LEAVES:4)
Block(-2,45,1,LEAVES:4)
Block(-2,46,1,LEAVES:4)
Block(-1,30,2,LEAVES:4)
Block(-3,44,-1,LEAVES:4)
Block(-1,22,2,LEAVES:4)
Block(-3,45,-1,LEAVES:4)
Block(4,8,-1,LEAVES:4)
Block(-3,42,-1,LEAVES:4)
Block(-1,20,2,LEAVES:4)
Block(-3,43,-1,LEAVES:4)
Block(-1,21,2,LEAVES:4)
Block(0,9,0,LEAVES:4)
Block(2,9,4,LEAVES:4)
Block(0,8,0,LEAVES:4)
Block(-3,46,-1,LEAVES:4)
Block(-1,25,2,LEAVES:4)
Block(-1,28,2,LEAVES:4)
Block(-1,9,6,LEAVES:4)
Block(-1,29,2,LEAVES:4)
Block(-1,8,6,LEAVES:4)
Block(4,7,-1,LEAVES:4)
Block(-1,10,4,LEAVES:4)
Block(-2,15,4,LEAVES:4)
Block(-2,14,4,LEAVES:4)
Block(-2,12,4,LEAVES:4)
Block(-5,7,-5,LEAVES:4)
Block(-2,19,4,LEAVES:4)
Block(-2,16,4,LEAVES:4)
Block(-2,5,1,LOG:13)
Block(-4,11,-3,LEAVES:4)
Block(-3,12,4,LEAVES:4)
Block(-2,4,1,LOG:13)
Block(-5,9,-5,LEAVES:4)
Block(-2,3,1,LOG:13)
Block(-4,13,-3,LEAVES:4)
Block(-2,30,1,LOG:13)
Block(-2,2,1,LOG:13)
Block(-4,12,-3,LEAVES:4)
Block(-2,9,1,LEAVES:4)
Block(-4,15,-3,LEAVES:4)
Block(-2,8,1,LOG:13)
Block(-2,7,1,LOG:13)
Block(-5,8,6,LEAVES:4)
Block(-2,6,1,LOG:13)
Block(-4,16,-3,LEAVES:4)
Block(-2,25,1,LEAVES:4)
Block(-2,24,1,LEAVES:4)
Block(1,19,4,LEAVES:4)
Block(-2,27,1,LEAVES:4)
Block(-2,26,1,LEAVES:4)
Block(-2,21,1,LEAVES:4)
Block(-2,0,1,LOG:13)
Block(-2,20,1,LEAVES:4)
Block(-2,1,1,LOG:13)
Block(-2,23,1,LEAVES:4)
Block(-2,22,1,LEAVES:4)
Block(1,10,4,LEAVES:4)
Block(6,13,2,LEAVES:4)
Block(-2,29,1,LEAVES:4)
Block(1,14,4,LEAVES:4)
Block(-2,28,1,LOG:13)
Block(-2,26,4,LEAVES:4)
Block(-1,21,4,LEAVES:4)
Block(-2,25,4,LEAVES:4)
Block(-1,20,4,LEAVES:4)
Block(-1,10,0,LOG:13)
Block(0,15,5,LEAVES:4)
Block(-1,11,0,LEAVES:4)
Block(-1,12,0,LEAVES:4)
Block(0,10,5,LEAVES:4)
Block(0,10,-3,LEAVES:4)
Block(-1,13,0,LEAVES:4)
Block(-1,14,0,LEAVES:4)
Block(-2,40,1,LEAVES:4)
Block(-1,15,0,LEAVES:4)
Block(-2,41,1,LEAVES:4)
Block(-1,16,0,LEAVES:4)
Block(-1,17,0,LEAVES:4)
Block(-1,18,0,LEAVES:4)
Block(-1,19,0,LOG:13)
Block(2,10,8,LEAVES:4)
Block(0,19,5,LEAVES:4)
Block(-2,38,1,LEAVES:4)
Block(-2,36,1,LEAVES:4)
Block(-2,34,1,LEAVES:4)
Block(-2,33,1,LEAVES:4)
Block(-2,32,1,LEAVES:4)
Block(-2,31,1,LOG:13)
Block(-1,16,4,LEAVES:4)
Block(-1,17,4,LEAVES:4)
Block(5,12,1,LEAVES:4)
Block(5,13,1,LEAVES:4)
Block(0,17,-3,LEAVES:4)
Block(-2,39,1,LEAVES:4)
Block(-3,36,1,LEAVES:4)
Block(-1,24,0,LEAVES:4)
Block(-3,37,1,LEAVES:4)
Block(-1,25,0,LEAVES:4)
Block(-1,22,0,LOG:13)
Block(-1,23,0,LEAVES:4)
Block(-1,20,0,LOG:13)
Block(-3,33,1,LEAVES:4)
Block(-1,21,0,LOG:13)
Block(-3,35,1,LEAVES:4)
Block(6,10,-1,LEAVES:4)
Block(6,11,-1,LEAVES:4)
Block(-1,28,0,LOG:13)
Block(-4,32,-3,LEAVES:4)
Block(-1,29,0,LOG:13)
Block(-1,26,0,LEAVES:4)
Block(-1,27,0,LOG:13)
Block(2,10,6,LEAVES:4)
Block(0,34,2,LEAVES:4)
Block(0,30,2,LEAVES:4)
Block(-3,40,1,LEAVES:4)
Block(-3,41,1,LEAVES:4)
Block(0,35,2,LEAVES:4)
Block(0,38,2,LEAVES:4)
Block(-1,33,0,LOG:13)
Block(-1,34,0,LOG:13)
Block(-1,19,6,LEAVES:4)
Block(-1,35,0,LOG:13)
Block(-1,36,0,LOG:13)
Block(-1,16,6,LEAVES:4)
Block(-1,30,0,LOG:13)
Block(-1,15,6,LEAVES:4)
Block(-1,31,0,LOG:13)
Block(-1,32,0,LOG:13)
Block(-2,9,-1,LEAVES:4)
Block(-4,7,-6,LEAVES:4)
Block(-4,26,-3,LEAVES:4)
Block(-4,25,-3,LEAVES:4)
Block(-1,37,0,LEAVES:4)
Block(-1,38,0,LEAVES:4)
Block(-1,39,0,LEAVES:4)
Block(-2,12,1,LEAVES:4)
Block(-2,11,1,LEAVES:4)
Block(-2,10,1,LEAVES:4)
Block(-4,35,2,LEAVES:4)
Block(-2,16,1,LEAVES:4)
Block(-2,15,1,LEAVES:4)
Block(-2,14,1,LEAVES:4)
Block(-2,13,1,LEAVES:4)
Block(1,23,4,LEAVES:4)
Block(-2,19,1,LOG:13)
Block(-1,20,6,LEAVES:4)
Block(-2,18,1,LOG:13)
Block(-2,17,1,LEAVES:4)
Block(-2,9,-3,LEAVES:4)
Block(1,22,4,LEAVES:4)
Block(-2,8,-3,LEAVES:4)
Block(-5,28,1,LEAVES:4)
Block(-2,27,3,LEAVES:4)
Block(-3,30,0,LEAVES:4)
Block(-5,23,1,LEAVES:4)
Block(0,36,0,LEAVES:4)
Block(0,34,0,LEAVES:4)
Block(0,33,0,LEAVES:4)
Block(0,37,0,LEAVES:4)
Block(-3,28,0,LEAVES:4)
Block(-3,29,0,LEAVES:4)
Block(-4,25,4,LEAVES:4)
Block(-2,32,3,LEAVES:4)
Block(-3,22,0,LEAVES:4)
Block(-3,23,0,LEAVES:4)
Block(1,10,-4,LEAVES:4)
Block(-3,21,0,LEAVES:4)
Block(0,20,6,LEAVES:4)
Block(-3,24,0,LEAVES:4)
Block(-3,25,0,LEAVES:4)
Block(-5,18,1,LEAVES:4)
Block(-3,16,2,LEAVES:4)
Block(-3,15,2,LEAVES:4)
Block(0,41,0,LEAVES:4)
Block(-3,13,2,LEAVES:4)
Block(-3,41,0,LEAVES:4)
Block(0,42,0,LEAVES:4)
Block(-3,40,0,LEAVES:4)
Block(-3,19,2,LEAVES:4)
Block(-3,39,0,LEAVES:4)
Block(-4,14,4,LEAVES:4)
Block(3,17,2,LEAVES:4)
Block(3,18,2,LEAVES:4)
Block(-4,17,4,LEAVES:4)
Block(-3,31,0,LEAVES:4)
Block(-5,22,1,LEAVES:4)
Block(3,12,2,LEAVES:4)
Block(0,15,6,LEAVES:4)
Block(-3,32,0,LEAVES:4)
Block(3,13,2,LEAVES:4)
Block(-3,33,0,LEAVES:4)
Block(3,14,2,LEAVES:4)
Block(-3,34,0,LEAVES:4)
Block(3,8,0,LEAVES:4)
Block(-3,35,0,LEAVES:4)
Block(3,9,0,LEAVES:4)
Block(-3,36,0,LEAVES:4)
Block(-3,37,0,LEAVES:4)
Block(-3,38,0,LEAVES:4)
Block(0,10,0,LEAVES:4)
Block(6,7,-1,LEAVES:4)
Block(-3,27,2,LEAVES:4)
Block(-1,16,5,LEAVES:4)
Block(-5,9,0,LEAVES:4)
Block(-3,28,2,LEAVES:4)
Block(-1,19,5,LEAVES:4)
Block(-3,13,-3,LEAVES:4)
Block(0,18,0,LEAVES:4)
Block(-3,14,-3,LEAVES:4)
Block(0,17,0,LEAVES:4)
Block(-3,11,-3,LEAVES:4)
Block(0,16,0,LEAVES:4)
Block(0,15,0,LEAVES:4)
Block(0,14,0,LEAVES:4)
Block(-3,17,-3,LEAVES:4)
Block(0,13,0,LEAVES:4)
Block(-3,18,-3,LEAVES:4)
Block(1,8,-6,LEAVES:4)
Block(0,12,0,LEAVES:4)
Block(0,11,0,LEAVES:4)
Block(-6,15,-4,LEAVES:4)
Block(-3,46,0,LEAVES:4)
Block(-3,47,0,LEAVES:4)
Block(-1,20,5,LEAVES:4)
Block(-3,45,0,LEAVES:4)
Block(-3,32,2,LEAVES:4)
Block(-3,36,2,LEAVES:4)
Block(0,21,0,LEAVES:4)
Block(-3,33,2,LEAVES:4)
Block(0,20,0,LEAVES:4)
Block(0,29,0,LEAVES:4)
Block(0,28,0,LEAVES:4)
Block(-2,10,6,LEAVES:4)
Block(0,23,0,LEAVES:4)
Block(0,22,0,LEAVES:4)
Block(0,9,7,LEAVES:4)
Block(0,24,0,LEAVES:4)
Block(-5,7,4,LEAVES:4)
Block(0,19,0,LEAVES:4)
Block(-5,6,4,LEAVES:4)
Block(-5,9,-1,LEAVES:4)
Block(-6,8,6,LEAVES:4)
Block(-4,8,2,LEAVES:4)
Block(-3,9,7,LEAVES:4)
Block(-3,10,-4,LEAVES:4)
Block(2,9,6,LEAVES:4)
Block(-2,11,-3,LEAVES:4)
Block(6,10,-2,LEAVES:4)
Block(-2,19,-3,LEAVES:4)
Block(-2,18,-3,LEAVES:4)
Block(-2,15,-3,LEAVES:4)
Block(-3,7,5,LEAVES:4)
Block(-2,14,-3,LEAVES:4)
Block(4,11,0,LEAVES:4)
Block(4,12,0,LEAVES:4)
Block(4,13,0,LEAVES:4)
Block(-2,22,-3,LEAVES:4)
Block(-3,9,3,LEAVES:4)
Block(4,10,0,LEAVES:4)
Block(0,0,1,LOG:13)
Block(0,2,1,LOG:13)
Block(0,1,1,LOG:13)
Block(0,4,1,LOG:13)
Block(0,3,1,LOG:13)
Block(0,6,1,LOG:13)
Block(0,5,1,LOG:13)
Block(-4,8,-5,LEAVES:4)
Block(-4,12,4,LEAVES:4)
Block(-4,7,-5,LEAVES:4)
Block(-4,13,4,LEAVES:4)
Block(-4,9,-5,LEAVES:4)
Block(-4,11,4,LEAVES:4)
Block(-1,-8,0,LOG:13)
Block(-1,-7,0,LOG:13)
Block(-1,-6,0,LOG:13)
Block(-2,23,-3,LEAVES:4)
Block(-1,-5,0,LOG:13)
Block(-1,-4,0,LOG:13)
Block(-4,13,5,LEAVES:4)
Block(-4,12,5,LEAVES:4)
Block(-4,11,5,LEAVES:4)
Block(-7,8,1,LEAVES:4)
Block(5,9,0,LEAVES:4)
Block(5,8,0,LEAVES:4)
Block(-2,12,-6,LEAVES:4)
Block(-3,13,-4,LEAVES:4)
Block(-3,13,0,LEAVES:4)
Block(6,13,1,LEAVES:4)
Block(6,12,1,LEAVES:4)
Block(-3,14,-4,LEAVES:4)
Block(-3,17,-4,LEAVES:4)
Block(-4,10,7,LEAVES:4)
Block(-3,12,0,LEAVES:4)
Block(-3,11,0,LEAVES:4)
Block(5,7,2,LEAVES:4)
Block(-4,12,-5,LEAVES:4)
Block(-3,18,0,LEAVES:4)
Block(-1,29,1,LOG:13)
Block(3,17,3,LEAVES:4)
Block(-1,27,1,LOG:13)
Block(0,20,4,LEAVES:4)
Block(5,10,-2,LEAVES:4)
Block(-1,28,1,LOG:13)
Block(0,22,4,LEAVES:4)
Block(0,23,4,LEAVES:4)
Block(3,8,2,LEAVES:4)
Block(-1,21,1,LEAVES:4)
Block(-1,7,1,LOG:13)
Block(3,19,-1,LEAVES:4)
Block(-1,22,1,LEAVES:4)
Block(-1,8,1,LOG:13)
Block(1,-4,0,LOG:13)
Block(-1,9,1,LOG:13)
Block(-1,20,1,LOG:13)
Block(2,9,1,LEAVES:4)
Block(3,16,-1,LEAVES:4)
Block(-1,25,1,LEAVES:4)
Block(-1,3,1,LOG:13)
Block(3,15,-1,LEAVES:4)
Block(-1,26,1,LEAVES:4)
Block(-1,4,1,LOG:13)
Block(-1,23,1,LEAVES:4)
Block(-1,5,1,LOG:13)
Block(-1,24,1,LEAVES:4)
Block(-1,6,1,LOG:13)
Block(3,12,-1,LEAVES:4)
Block(3,11,-1,LEAVES:4)
Block(-1,2,1,LOG:13)
Block(-1,16,1,LEAVES:4)
Block(0,10,4,LEAVES:4)
Block(-1,17,1,LEAVES:4)
Block(-1,18,1,LEAVES:4)
Block(-1,19,1,LOG:13)
Block(1,17,-1,LEAVES:4)
Block(1,9,6,LEAVES:4)
Block(-1,18,-3,LEAVES:4)
Block(-1,10,1,LOG:13)
Block(0,15,4,LEAVES:4)
Block(-1,11,1,LEAVES:4)
Block(0,16,4,LEAVES:4)
Block(-1,12,1,LEAVES:4)
Block(-1,13,1,LEAVES:4)
Block(-1,14,-3,LEAVES:4)
Block(-1,14,1,LEAVES:4)
Block(0,19,4,LEAVES:4)
Block(-1,15,1,LEAVES:4)
Block(-1,23,-3,LEAVES:4)
Block(5,10,0,LEAVES:4)
Block(5,12,0,LEAVES:4)
Block(1,11,-1,LEAVES:4)
Block(1,12,-1,LEAVES:4)
Block(6,7,2,LEAVES:4)
Block(2,15,-3,LEAVES:4)
Block(2,19,-3,LEAVES:4)
Block(-1,45,1,LEAVES:4)
Block(-1,46,1,LEAVES:4)
Block(-2,7,5,LEAVES:4)
Block(-2,9,7,LEAVES:4)
Block(-6,19,-1,LEAVES:4)
Block(-6,15,-1,LEAVES:4)
Block(-3,-7,0,LOG:13)
Block(-1,39,1,LEAVES:4)
Block(0,9,5,LEAVES:4)
Block(-1,35,1,LEAVES:4)
Block(6,8,0,LEAVES:4)
Block(-1,36,1,LEAVES:4)
Block(6,7,0,LEAVES:4)
Block(-1,30,1,LEAVES:4)
Block(-1,31,1,LEAVES:4)
Block(-1,32,1,LEAVES:4)
Block(-1,15,7,LEAVES:4)
Block(-1,33,1,LEAVES:4)
Block(1,-7,0,LOG:13)
Block(-1,40,1,LEAVES:4)
Block(3,8,-1,LEAVES:4)
Block(-5,7,2,LEAVES:4)
Block(-5,8,2,LEAVES:4)
Block(1,18,0,LEAVES:4)
Block(1,19,0,LEAVES:4)
Block(1,16,0,LEAVES:4)
Block(1,17,0,LEAVES:4)
Block(1,14,0,LEAVES:4)
Block(1,15,0,LEAVES:4)
Block(1,12,0,LEAVES:4)
Block(1,13,0,LEAVES:4)
Block(1,10,0,LEAVES:4)
Block(-2,15,6,LEAVES:4)
Block(-3,8,-4,LEAVES:4)
Block(0,9,-4,LEAVES:4)
Block(-3,7,-4,LEAVES:4)
Block(0,-5,3,LOG:13)
Block(0,-4,3,LOG:13)
Block(0,-6,3,LOG:13)
Block(2,22,4,LEAVES:4)
Block(-1,-3,1,LOG:13)
Block(-1,-2,1,LOG:13)
Block(-1,-5,1,LOG:13)
Block(-1,-4,1,LOG:13)
Block(-1,-6,1,LOG:13)
Block(-6,20,-1,LEAVES:4)
Block(4,7,3,LEAVES:4)
Block(1,-4,1,LOG:13)
Block(1,-3,1,LOG:13)
Block(1,36,0,LEAVES:4)
Block(1,35,0,LEAVES:4)
Block(1,32,0,LEAVES:4)
Block(1,33,0,LEAVES:4)
Block(0,-1,0,LOG:13)
Block(0,-2,0,LOG:13)
Block(-5,13,5,LEAVES:4)
Block(-5,12,5,LEAVES:4)
Block(-5,11,5,LEAVES:4)
Block(-5,10,5,LEAVES:4)
Block(2,9,-4,LEAVES:4)
Block(2,9,-6,LEAVES:4)
Block(3,26,-1,LEAVES:4)
Block(1,27,0,LEAVES:4)
Block(-7,9,-1,LEAVES:4)
Block(1,28,0,LEAVES:4)
Block(4,15,-1,LEAVES:4)
Block(4,12,-1,LEAVES:4)
Block(5,7,-1,LEAVES:4)
Block(4,11,-1,LEAVES:4)
Block(0,-6,0,LOG:13)
Block(0,-5,0,LOG:13)
Block(-4,10,-4,LEAVES:4)
Block(2,9,-2,LEAVES:4)
Block(-4,8,-3,LEAVES:4)
Block(0,43,-1,LEAVES:4)
Block(1,11,3,LEAVES:4)
Block(1,15,1,LEAVES:4)
Block(0,42,-1,LEAVES:4)
Block(1,16,1,LEAVES:4)
Block(1,10,3,LEAVES:4)
Block(-8,8,-2,LEAVES:4)
Block(-6,13,2,LEAVES:4)
Block(1,19,1,LEAVES:4)
Block(-4,7,6,LEAVES:4)
Block(1,19,3,LEAVES:4)
Block(1,10,1,LEAVES:4)
Block(8,8,1,LEAVES:4)
Block(-4,6,6,LEAVES:4)
Block(1,11,1,LEAVES:4)
Block(1,12,1,LEAVES:4)
Block(1,27,1,LEAVES:4)
Block(1,23,3,LEAVES:4)
Block(1,24,3,LEAVES:4)
Block(1,32,-2,LEAVES:4)
Block(0,11,3,LEAVES:4)
Block(1,28,1,LEAVES:4)
Block(1,29,1,LEAVES:4)
Block(0,16,3,LEAVES:4)
Block(1,28,3,LEAVES:4)
Block(1,20,1,LEAVES:4)
Block(1,29,3,LEAVES:4)
Block(0,15,3,LEAVES:4)
Block(-2,-6,-1,LOG:13)
Block(0,20,3,LEAVES:4)
Block(0,21,3,LEAVES:4)
Block(0,23,3,LEAVES:4)
Block(0,24,3,LEAVES:4)
Block(0,28,3,LEAVES:4)
Block(0,29,3,LEAVES:4)
Block(-5,10,4,LEAVES:4)
Block(-5,13,4,LEAVES:4)
Block(-5,14,4,LEAVES:4)
Block(7,10,-1,LEAVES:4)
Block(-5,11,4,LEAVES:4)
Block(-6,28,0,LEAVES:4)
Block(3,9,5,LEAVES:4)
Block(3,8,5,LEAVES:4)
Block(0,34,3,LEAVES:4)
Block(-5,17,4,LEAVES:4)
Block(-6,8,2,LEAVES:4)
Block(-6,19,0,LEAVES:4)
Block(-5,8,-2,LEAVES:4)
Block(-5,9,-2,LEAVES:4)
Block(-5,10,-4,LEAVES:4)
Block(-2,7,0,LOG:13)
Block(-2,8,0,LOG:13)
Block(-2,9,0,LEAVES:4)
Block(-2,3,0,LOG:13)
Block(3,9,-2,LEAVES:4)
Block(-2,4,0,LOG:13)
Block(-5,15,-4,LEAVES:4)
Block(-2,5,0,LOG:13)
Block(-2,6,0,LOG:13)
Block(-2,0,0,LOG:13)
Block(3,9,-4,LEAVES:4)
Block(-2,2,0,LOG:13)
Block(-2,1,0,LOG:13)
Block(3,8,-4,LEAVES:4)
Block(-7,13,3,LEAVES:4)
Block(-7,12,3,LEAVES:4)
Block(-3,9,-2,LEAVES:4)
Block(-5,28,-1,LEAVES:4)
Block(-5,27,-1,LEAVES:4)
Block(-5,26,-1,LEAVES:4)
Block(-5,21,-1,LEAVES:4)
Block(-5,20,-1,LEAVES:4)
Block(-5,25,-1,LEAVES:4)
Block(-2,8,4,LEAVES:4)
Block(3,9,-6,LEAVES:4)
Block(-5,7,-6,LEAVES:4)
Block(1,32,-1,LEAVES:4)
Block(1,33,-1,LEAVES:4)
Block(-1,-4,3,LOG:13)
Block(-5,16,-1,LEAVES:4)
Block(-1,-6,3,LOG:13)
Block(4,15,-2,LEAVES:4)
Block(1,21,-2,LEAVES:4)
Block(1,20,-2,LEAVES:4)
Block(-5,10,-1,LEAVES:4)
Block(1,28,-2,LEAVES:4)
Block(4,10,-2,LEAVES:4)
Block(1,27,-2,LEAVES:4)
Block(4,8,0,LEAVES:4)
Block(4,9,0,LEAVES:4)
Block(1,21,-1,LEAVES:4)
Block(1,9,1,LEAVES:4)
Block(1,20,-1,LEAVES:4)
Block(-6,9,-1,LEAVES:4)
Block(1,11,-2,LEAVES:4)
Block(-1,33,-3,LEAVES:4)
Block(-1,34,-3,LEAVES:4)
Block(-6,9,-4,LEAVES:4)
Block(1,10,-2,LEAVES:4)
Block(-6,6,-4,LEAVES:4)
Block(-1,29,-3,LEAVES:4)
Block(-1,28,-3,LEAVES:4)
Block(-3,6,-6,LEAVES:4)
Block(-1,24,-3,LEAVES:4)
Block(1,16,-2,LEAVES:4)
Block(-1,27,-3,LEAVES:4)
Block(-3,12,-6,LEAVES:4)
Block(1,28,-1,LEAVES:4)
Block(1,27,-1,LEAVES:4)
Block(-3,26,3,LEAVES:4)
Block(-4,7,4,LEAVES:4)
Block(-3,27,3,LEAVES:4)
Block(-4,8,4,LEAVES:4)
Block(-2,16,5,LEAVES:4)
Block(-2,15,5,LEAVES:4)
Block(2,32,0,LEAVES:4)
Block(-3,31,3,LEAVES:4)
Block(-3,32,3,LEAVES:4)
Block(-3,15,3,LEAVES:4)
Block(-3,14,3,LEAVES:4)
Block(-3,13,3,LEAVES:4)
Block(-3,12,3,LEAVES:4)
Block(0,-6,-1,LOG:13)
Block(-2,11,5,LEAVES:4)
Block(0,28,-4,LEAVES:4)
Block(0,27,-4,LEAVES:4)
Block(-5,15,3,LEAVES:4)
Block(-5,14,3,LEAVES:4)
Block(0,22,-4,LEAVES:4)
Block(-3,9,2,LEAVES:4)
Block(-5,18,3,LEAVES:4)
Block(-2,-3,3,LOG:13)
Block(-6,7,4,LEAVES:4)
Block(-1,17,3,LEAVES:4)
Block(-6,8,4,LEAVES:4)
Block(-2,-4,3,LOG:13)
Block(-2,10,-4,LEAVES:4)
Block(-6,9,4,LEAVES:4)
Block(-1,11,3,LEAVES:4)
Block(-1,10,3,LEAVES:4)
Block(-3,11,6,LEAVES:4)
Block(-3,10,6,LEAVES:4)
Block(-2,-5,3,LOG:13)
Block(-2,-6,3,LOG:13)
Block(-1,18,3,LEAVES:4)
Block(-6,9,0,LEAVES:4)
Block(0,17,-4,LEAVES:4)
Block(-8,9,0,LEAVES:4)
Block(-1,28,3,LEAVES:4)
Block(-1,27,3,LEAVES:4)
Block(-1,22,3,LEAVES:4)
Block(-1,21,3,LEAVES:4)
Block(2,9,5,LEAVES:4)
Block(-1,9,5,LEAVES:4)
Block(-8,8,0,LEAVES:4)
Block(0,8,1,LOG:13)
Block(0,7,1,LOG:13)
Block(-2,9,-2,LEAVES:4)
Block(0,9,1,LEAVES:4)
Block(-5,7,-4,LEAVES:4)
Block(-2,9,2,LEAVES:4)
Block(-3,-5,2,LOG:13)
Block(-3,-6,2,LOG:13)
Block(-1,34,3,LEAVES:4)
Block(-1,32,3,LEAVES:4)
Block(-2,14,-4,LEAVES:4)
Block(-2,13,-4,LEAVES:4)
Block(0,18,-1,LEAVES:4)
Block(0,17,-1,LEAVES:4)
Block(-2,18,-4,LEAVES:4)
Block(-2,17,-4,LEAVES:4)
Block(0,11,-1,LEAVES:4)
Block(-4,11,6,LEAVES:4)
Block(-2,21,-4,LEAVES:4)
Block(-4,10,6,LEAVES:4)
Block(0,12,-1,LEAVES:4)
Block(-2,22,-4,LEAVES:4)
Block(0,13,-1,LEAVES:4)
Block(-2,20,3,LEAVES:4)
Block(-6,20,-2,LEAVES:4)
Block(0,29,-1,LEAVES:4)
Block(0,28,-1,LEAVES:4)
Block(7,7,2,LEAVES:4)
Block(7,8,0,LEAVES:4)
Block(2,15,0,LEAVES:4)
Block(7,7,0,LEAVES:4)
Block(2,16,0,LEAVES:4)
Block(2,13,0,LEAVES:4)
Block(2,14,0,LEAVES:4)
Block(2,17,0,LEAVES:4)
Block(2,18,0,LEAVES:4)
Block(-2,19,3,LEAVES:4)
Block(-2,17,3,LEAVES:4)
Block(0,22,-1,LEAVES:4)
Block(-2,16,3,LEAVES:4)
Block(-2,15,3,LEAVES:4)
Block(2,11,0,LEAVES:4)
Block(0,21,-1,LEAVES:4)
Block(2,12,0,LEAVES:4)
Block(-2,13,3,LEAVES:4)
Block(-2,12,3,LEAVES:4)
Block(2,10,0,LEAVES:4)
Block(0,38,-1,LEAVES:4)
Block(4,17,1,LEAVES:4)
Block(4,13,1,LEAVES:4)
Block(4,14,1,LEAVES:4)
Block(-6,15,-2,LEAVES:4)
Block(-6,19,-2,LEAVES:4)
Block(4,18,2,LEAVES:4)
Block(4,17,2,LEAVES:4)
Block(-1,0,-1,LOG:13)
Block(2,27,0,LEAVES:4)
Block(0,33,-1,LEAVES:4)
Block(-2,8,-4,LEAVES:4)
Block(3,15,-3,LEAVES:4)
Block(0,34,-1,LEAVES:4)
Block(4,12,2,LEAVES:4)
Block(-1,9,-1,LEAVES:4)
Block(-2,7,-4,LEAVES:4)
Block(2,20,0,LEAVES:4)
Block(4,14,2,LEAVES:4)
Block(3,19,-3,LEAVES:4)
Block(0,30,-1,LEAVES:4)
Block(4,13,2,LEAVES:4)
Block(0,31,-1,LEAVES:4)

#######################################################################
# +-----------------------------------------------------------------+ #
# |                            BO3 checks                           | #
# +-----------------------------------------------------------------+ #
#######################################################################

BlockCheck(0,-1,0,GRAVEL)
BlockCheck(0,-2,0,Solid)

#######################################################################
# +-----------------------------------------------------------------+ #
# |                             Branches                            | #
# +-----------------------------------------------------------------+ #
#######################################################################


#######################################################################
# +-----------------------------------------------------------------+ #
# |                             Entities                            | #
# +-----------------------------------------------------------------+ #
#######################################################################


#######################################################################
# +-----------------------------------------------------------------+ #
# |                            Particles                            | #
# +-----------------------------------------------------------------+ #
#######################################################################


#######################################################################
# +-----------------------------------------------------------------+ #
# |                             Spawners                            | #
# +-----------------------------------------------------------------+ #
#######################################################################


#######################################################################
# +-----------------------------------------------------------------+ #
# |                             ModData                             | #
# +-----------------------------------------------------------------+ #
#######################################################################

