
#######################################################################
# +-----------------------------------------------------------------+ #
# |                            BO3 object                           | #
# +-----------------------------------------------------------------+ #
#######################################################################

Author: NLBlackEagle

Description: No description given

Version: 3

SettingsMode: WriteDisable


#######################################################################
# +-----------------------------------------------------------------+ #
# |                          Main settings                          | #
# +-----------------------------------------------------------------+ #
#######################################################################

Tree: true

Frequency: 0

Rarity: 100.0

RotateRandomly: true

SpawnHeight: highestSolidBlock

SpawnHeightOffset: 0

SpawnHeightVariance: 1

##############################
# Height Limits for the BO3. #
##############################

MinHeight: 0

MaxHeight: 255

######################
# Extrusion settings #
######################

ExtrudeMode: None

ExtrudeThroughBlocks: AIR

MaxBranchDepth: 10

ExcludedBiomes: All


#######################################################################
# +-----------------------------------------------------------------+ #
# |                      Source block settings                      | #
# +-----------------------------------------------------------------+ #
#######################################################################

SourceBlocks: AIR

MaxPercentageOutsideSourceBlock: 50

OutsideSourceBlock: placeAnyway

DoReplaceBlocks: true

IsOTGPlus: false


#######################################################################
# +-----------------------------------------------------------------+ #
# |                              Blocks                             | #
# +-----------------------------------------------------------------+ #
#######################################################################

Block(-11,56,-2,LEAVES:13)
Block(-11,56,-1,LEAVES:13)
Block(-11,57,-2,LEAVES:13)
Block(-11,57,1,LEAVES:14)
Block(-11,58,1,LEAVES:13)
Block(-10,45,-5,LEAVES:14)
Block(-10,46,-5,LEAVES:13)
Block(-10,55,-1,LEAVES:13)
Block(-10,56,-1,LEAVES:13)
Block(-10,56,0,LOG:13)
Block(-10,59,0,LEAVES:13)
Block(-10,59,1,LEAVES:13)
Block(-9,45,-5,LEAVES:14)
Block(-9,46,-3,LEAVES:13)
Block(-9,47,-3,LEAVES:13)
Block(-9,48,-5,LEAVES:14)
Block(-9,54,0,LEAVES:13)
Block(-9,55,-3,LEAVES:13)
Block(-9,55,-2,LEAVES:13)
Block(-9,55,0,LEAVES:13)
Block(-9,56,-3,LEAVES:13)
Block(-9,56,0,LOG:13)
Block(-9,56,1,LOG:13)
Block(-9,57,-1,LEAVES:14)
Block(-9,57,1,LOG:13)
Block(-9,58,-2,LEAVES:14)
Block(-9,58,-1,LEAVES:14)
Block(-9,59,-4,LEAVES:14)
Block(-9,59,-3,LEAVES:14)
Block(-9,59,0,LEAVES:14)
Block(-8,-9,1,LOG_2:13)
Block(-8,45,-4,LEAVES:13)
Block(-8,46,-6,LOG:13)
Block(-8,46,-5,LOG:13)
Block(-8,46,-4,LEAVES:13)
Block(-8,46,-3,LEAVES:13)
Block(-8,47,-7,LEAVES:13)
Block(-8,47,-5,LEAVES:13)
Block(-8,48,-5,LEAVES:13)
Block(-8,53,0,LEAVES:13)
Block(-8,54,0,LEAVES:13)
Block(-8,56,0,LEAVES:14)
Block(-8,57,0,LEAVES:14)
Block(-8,57,1,LOG:13)
Block(-8,57,2,LEAVES:14)
Block(-8,57,3,LEAVES:14)
Block(-8,58,-2,LEAVES:14)
Block(-8,58,-1,LEAVES:14)
Block(-8,58,0,LEAVES:14)
Block(-8,58,3,LEAVES:14)
Block(-8,59,-4,LEAVES:14)
Block(-8,59,1,LEAVES:14)
Block(-8,59,5,LEAVES:13)
Block(-8,60,1,LEAVES:14)
Block(-8,60,2,LEAVES:14)
Block(-8,60,5,LEAVES:13)
Block(-8,61,3,LEAVES:13)
Block(-8,62,0,LEAVES:13)
Block(-8,62,1,LEAVES:13)
Block(-8,63,2,LEAVES:13)
Block(-8,63,3,LEAVES:14)
Block(-8,64,2,LEAVES:13)
Block(-8,64,3,LEAVES:14)
Block(-8,65,-1,LEAVES:13)
Block(-8,65,0,LEAVES:13)
Block(-7,-9,1,LOG:13)
Block(-7,-9,2,LOG:13)
Block(-7,-8,2,LOG_2:13)
Block(-7,43,-6,LEAVES:14)
Block(-7,44,-6,LEAVES:14)
Block(-7,44,-5,LEAVES:14)
Block(-7,45,-4,LOG:13)
Block(-7,46,-5,LOG:13)
Block(-7,46,-4,LOG:13)
Block(-7,47,-7,LEAVES:13)
Block(-7,47,-6,LEAVES:13)
Block(-7,53,-3,LEAVES:13)
Block(-7,53,-2,LEAVES:13)
Block(-7,56,-2,LEAVES:14)
Block(-7,56,-1,LEAVES:14)
Block(-7,57,-4,LEAVES:14)
Block(-7,57,-1,LEAVES:14)
Block(-7,57,0,LEAVES:14)
Block(-7,57,1,LOG:13)
Block(-7,58,-3,LEAVES:14)
Block(-7,58,-1,LEAVES:14)
Block(-7,58,0,LEAVES:14)
Block(-7,58,1,LOG:13)
Block(-7,59,-2,LEAVES:14)
Block(-7,60,-1,LEAVES:14)
Block(-7,60,4,LEAVES:14)
Block(-7,60,5,LEAVES:13)
Block(-7,61,2,LEAVES:14)
Block(-7,61,3,LEAVES:14)
Block(-7,62,0,LEAVES:13)
Block(-7,62,4,LEAVES:14)
Block(-7,62,5,LOG:13)
Block(-7,63,1,LEAVES:13)
Block(-7,63,3,LEAVES:14)
Block(-7,63,5,LEAVES:13)
Block(-7,64,0,LOG:13)
Block(-7,64,3,LEAVES:14)
Block(-7,65,-1,LEAVES:13)
Block(-6,-8,2,LOG_2:13)
Block(-6,-8,3,LOG_2:13)
Block(-6,-7,2,LOG_2:13)
Block(-6,-7,3,LOG_2:13)
Block(-6,45,-4,LOG:13)
Block(-6,46,-6,LEAVES:13)
Block(-6,46,-5,LEAVES:13)
Block(-6,47,-6,LEAVES:13)
Block(-6,47,-3,LEAVES:13)
Block(-6,48,-9,LOG:13)
Block(-6,48,-8,LOG:13)
Block(-6,48,-3,LEAVES:13)
Block(-6,50,-9,LEAVES:13)
Block(-6,50,-8,LEAVES:13)
Block(-6,50,6,LEAVES:13)
Block(-6,50,7,LEAVES:13)
Block(-6,52,7,LOG:13)
Block(-6,53,-2,LEAVES:13)
Block(-6,53,5,LEAVES:14)
Block(-6,53,6,LEAVES:13)
Block(-6,54,-4,LEAVES:13)
Block(-6,54,-3,LEAVES:13)
Block(-6,54,8,LEAVES:13)
Block(-6,54,9,LEAVES:13)
Block(-6,55,-4,LOG:13)
Block(-6,55,-2,LEAVES:13)
Block(-6,56,-4,LOG:13)
Block(-6,56,-1,LEAVES:14)
Block(-6,57,-4,LEAVES:14)
Block(-6,57,-3,LEAVES:14)
Block(-6,57,-1,LOG:13)
Block(-6,57,0,LOG:13)
Block(-6,58,0,LOG:13)
Block(-6,58,1,LOG:13)
Block(-6,58,2,LEAVES:14)
Block(-6,59,-3,LEAVES:14)
Block(-6,59,-2,LOG:13)
Block(-6,59,-1,LOG:13)
Block(-6,59,0,LOG:13)
Block(-6,59,2,LEAVES:14)
Block(-6,60,-4,LEAVES:14)
Block(-6,60,-2,LEAVES:14)
Block(-6,60,-1,LEAVES:14)
Block(-6,61,-5,LEAVES:14)
Block(-6,61,4,LEAVES:14)
Block(-6,62,-5,LEAVES:14)
Block(-6,62,2,LEAVES:14)
Block(-6,62,3,LEAVES:14)
Block(-6,62,4,LOG:13)
Block(-6,62,5,LOG:13)
Block(-6,63,-7,LEAVES:14)
Block(-6,63,2,LEAVES:14)
Block(-6,64,0,LOG:13)
Block(-6,64,1,LOG:13)
Block(-6,64,2,LEAVES:14)
Block(-6,65,-8,LEAVES:14)
Block(-6,65,-7,LEAVES:14)
Block(-6,65,0,LEAVES:13)
Block(-6,69,4,LEAVES:13)
Block(-6,70,4,LEAVES:14)
Block(-5,-7,3,LOG_2:13)
Block(-5,-7,4,LOG_2:13)
Block(-5,-6,-5,LOG_2:13)
Block(-5,-6,3,LOG_2:13)
Block(-5,-6,4,LOG:13)
Block(-5,-5,4,LOG:13)
Block(-5,44,-7,LEAVES:14)
Block(-5,44,-6,LEAVES:13)
Block(-5,45,-5,LOG:13)
Block(-5,45,-4,LOG:13)
Block(-5,46,-6,LEAVES:13)
Block(-5,46,-5,LOG:13)
Block(-5,47,-8,LEAVES:13)
Block(-5,47,-7,LEAVES:13)
Block(-5,47,-6,LEAVES:13)
Block(-5,48,-9,LEAVES:13)
Block(-5,48,-8,LOG:13)
Block(-5,48,-7,LOG:13)
Block(-5,48,-5,LEAVES:14)
Block(-5,49,-7,LEAVES:13)
Block(-5,49,-6,LEAVES:14)
Block(-5,49,-5,LEAVES:14)
Block(-5,50,-8,LEAVES:13)
Block(-5,50,-6,LEAVES:14)
Block(-5,50,6,LEAVES:14)
Block(-5,51,7,LEAVES:14)
Block(-5,51,8,LEAVES:13)
Block(-5,51,9,LEAVES:13)
Block(-5,52,6,LEAVES:14)
Block(-5,52,7,LOG:13)
Block(-5,52,8,LEAVES:13)
Block(-5,53,5,LEAVES:14)
Block(-5,53,8,LEAVES:13)
Block(-5,54,-4,LEAVES:13)
Block(-5,54,-3,LEAVES:13)
Block(-5,54,-2,LEAVES:13)
Block(-5,54,5,LEAVES:14)
Block(-5,54,6,LEAVES:13)
Block(-5,54,9,LEAVES:13)
Block(-5,55,-3,LEAVES:13)
Block(-5,55,0,LEAVES:14)
Block(-5,55,1,LEAVES:14)
Block(-5,55,8,LEAVES:13)
Block(-5,55,9,LEAVES:13)
Block(-5,56,-4,LEAVES:14)
Block(-5,56,-3,LOG:13)
Block(-5,56,-2,LOG:13)
Block(-5,56,-1,LOG:13)
Block(-5,57,-1,LOG:13)
Block(-5,57,0,LEAVES:14)
Block(-5,58,-2,LEAVES:13)
Block(-5,58,-1,LEAVES:14)
Block(-5,58,1,LEAVES:14)
Block(-5,60,-4,LEAVES:14)
Block(-5,60,-3,LEAVES:13)
Block(-5,60,2,LEAVES:14)
Block(-5,60,5,LEAVES:14)
Block(-5,60,6,LEAVES:13)
Block(-5,61,4,LEAVES:14)
Block(-5,61,5,LEAVES:14)
Block(-5,62,-6,LEAVES:14)
Block(-5,62,-5,LEAVES:14)
Block(-5,62,1,LEAVES:14)
Block(-5,62,2,LEAVES:14)
Block(-5,62,3,LEAVES:14)
Block(-5,62,4,LOG:13)
Block(-5,62,5,LEAVES:14)
Block(-5,62,6,LEAVES:13)
Block(-5,63,-8,LEAVES:13)
Block(-5,63,-7,LOG:13)
Block(-5,63,-6,LOG:13)
Block(-5,63,-1,LEAVES:13)
Block(-5,63,0,LEAVES:13)
Block(-5,63,1,LEAVES:14)
Block(-5,63,2,LEAVES:14)
Block(-5,63,3,LOG:13)
Block(-5,63,4,LOG:13)
Block(-5,63,5,LEAVES:13)
Block(-5,64,-6,LEAVES:14)
Block(-5,64,-5,LEAVES:14)
Block(-5,64,1,LOG:13)
Block(-5,64,2,LOG:13)
Block(-5,64,3,LOG:13)
Block(-5,65,-7,LEAVES:14)
Block(-5,65,-5,LEAVES:14)
Block(-5,65,0,LEAVES:13)
Block(-5,65,1,LEAVES:13)
Block(-5,69,4,LEAVES:13)
Block(-5,70,2,LEAVES:13)
Block(-5,71,2,LEAVES:13)
Block(-5,72,-5,LEAVES:14)
Block(-5,72,-4,LEAVES:14)
Block(-5,72,-2,LEAVES:14)
Block(-5,72,-1,LEAVES:14)
Block(-5,72,4,LEAVES:14)
Block(-5,73,-5,LEAVES:14)
Block(-5,73,-4,LEAVES:14)
Block(-5,73,-3,LEAVES:14)
Block(-5,73,-2,LEAVES:14)
Block(-5,74,-4,LEAVES:14)
Block(-5,74,-3,LEAVES:14)
Block(-5,74,-2,LEAVES:14)
Block(-4,-9,3,LOG_2:13)
Block(-4,-9,4,LOG:13)
Block(-4,-8,2,LOG_2:13)
Block(-4,-8,3,LOG_2:13)
Block(-4,-8,4,LOG_2:13)
Block(-4,-7,-6,LOG_2:13)
Block(-4,-7,2,LOG_2:13)
Block(-4,-7,3,LOG_2:13)
Block(-4,-6,-7,LOG_2:13)
Block(-4,-6,-6,LOG_2:13)
Block(-4,-6,-5,LOG_2:13)
Block(-4,-6,-4,LOG_2:13)
Block(-4,-6,4,LOG_2:13)
Block(-4,-5,-6,LOG_2:13)
Block(-4,-5,-5,LOG_2:13)
Block(-4,-5,-4,LOG:13)
Block(-4,-5,-3,LOG:13)
Block(-4,-5,3,LOG:13)
Block(-4,-5,4,LOG:13)
Block(-4,-4,-5,LOG:13)
Block(-4,-4,-4,LOG:13)
Block(-4,-4,-3,LOG:13)
Block(-4,-4,-2,LOG:13)
Block(-4,-3,-4,LOG:13)
Block(-4,-3,-3,LOG:13)
Block(-4,-3,-2,LOG:13)
Block(-4,-2,-4,LOG:13)
Block(-4,-2,-3,LOG_2:13)
Block(-4,-2,-2,LOG:13)
Block(-4,-1,-4,LOG_2:13)
Block(-4,-1,-3,LOG_2:13)
Block(-4,-1,-2,LOG_2:13)
Block(-4,-1,-1,LOG:13)
Block(-4,0,-3,LOG_2:13)
Block(-4,0,-2,LOG_2:13)
Block(-4,1,-2,LOG_2:13)
Block(-4,43,-8,LEAVES:14)
Block(-4,44,-7,LEAVES:14)
Block(-4,44,-5,LEAVES:13)
Block(-4,45,-6,LEAVES:13)
Block(-4,46,-7,LEAVES:13)
Block(-4,46,-6,LOG:13)
Block(-4,46,-5,LOG:13)
Block(-4,46,-4,LOG:13)
Block(-4,46,-3,LOG:13)
Block(-4,47,-11,LEAVES:13)
Block(-4,47,-8,LEAVES:13)
Block(-4,47,-7,LOG:13)
Block(-4,47,-6,LOG:13)
Block(-4,47,-5,LOG:13)
Block(-4,48,-8,LEAVES:13)
Block(-4,48,-7,LOG:13)
Block(-4,48,-5,LEAVES:14)
Block(-4,49,-11,LEAVES:13)
Block(-4,49,-8,LEAVES:13)
Block(-4,49,-7,LOG:13)
Block(-4,49,-5,LEAVES:14)
Block(-4,49,8,LEAVES:13)
Block(-4,50,-8,LEAVES:14)
Block(-4,50,6,LEAVES:14)
Block(-4,51,2,LEAVES:13)
Block(-4,51,3,LEAVES:14)
Block(-4,51,6,LEAVES:14)
Block(-4,51,8,LEAVES:13)
Block(-4,51,9,LEAVES:13)
Block(-4,52,6,LOG:13)
Block(-4,52,7,LOG:13)
Block(-4,52,8,LEAVES:14)
Block(-4,53,7,LOG:13)
Block(-4,53,8,LEAVES:14)
Block(-4,54,-3,LEAVES:13)
Block(-4,54,-2,LEAVES:13)
Block(-4,54,-1,LEAVES:13)
Block(-4,54,5,LEAVES:14)
Block(-4,54,6,LEAVES:13)
Block(-4,54,7,LOG:13)
Block(-4,54,8,LEAVES:13)
Block(-4,55,-2,LOG:13)
Block(-4,55,1,LEAVES:14)
Block(-4,55,9,LEAVES:13)
Block(-4,56,-4,LEAVES:14)
Block(-4,56,-3,LEAVES:14)
Block(-4,56,-2,LOG:13)
Block(-4,56,-1,LEAVES:14)
Block(-4,56,0,LEAVES:14)
Block(-4,57,-1,LEAVES:14)
Block(-4,58,-2,LEAVES:13)
Block(-4,60,2,LEAVES:14)
Block(-4,60,3,LEAVES:14)
Block(-4,60,6,LEAVES:14)
Block(-4,61,3,LEAVES:14)
Block(-4,61,5,LEAVES:14)
Block(-4,62,1,LEAVES:14)
Block(-4,62,2,LEAVES:14)
Block(-4,62,3,LEAVES:14)
Block(-4,62,4,LEAVES:14)
Block(-4,62,5,LEAVES:14)
Block(-4,62,6,LEAVES:13)
Block(-4,63,-6,LOG:13)
Block(-4,63,-1,LEAVES:13)
Block(-4,63,1,LOG:13)
Block(-4,63,3,LEAVES:14)
Block(-4,63,5,LEAVES:13)
Block(-4,64,-6,LOG:13)
Block(-4,64,0,LEAVES:13)
Block(-4,64,1,LOG:13)
Block(-4,64,4,LEAVES:13)
Block(-4,65,1,LEAVES:13)
Block(-4,69,-1,LEAVES:13)
Block(-4,69,0,LEAVES:13)
Block(-4,69,3,LEAVES:13)
Block(-4,70,-2,LEAVES:13)
Block(-4,70,-1,LEAVES:13)
Block(-4,70,0,LEAVES:13)
Block(-4,70,2,LEAVES:13)
Block(-4,70,3,LEAVES:13)
Block(-4,71,-4,LEAVES:14)
Block(-4,71,4,LEAVES:13)
Block(-4,71,6,LEAVES:13)
Block(-4,72,-4,LEAVES:14)
Block(-4,72,-3,LOG:13)
Block(-4,72,-2,LEAVES:14)
Block(-4,72,-1,LEAVES:14)
Block(-4,72,4,LEAVES:14)
Block(-4,73,-4,LOG:13)
Block(-4,73,-3,LOG:13)
Block(-4,73,-1,LEAVES:14)
Block(-4,73,0,LEAVES:13)
Block(-4,73,1,LEAVES:13)
Block(-4,75,2,LEAVES:13)
Block(-4,76,0,LEAVES:13)
Block(-4,77,0,LEAVES:13)
Block(-3,-10,4,LOG:13)
Block(-3,-10,5,LOG:13)
Block(-3,-9,4,LOG:13)
Block(-3,-7,-8,LOG_2:13)
Block(-3,-7,-7,LOG_2:13)
Block(-3,-7,-6,LOG_2:13)
Block(-3,-7,-5,LOG_2:13)
Block(-3,-7,-3,LOG:13)
Block(-3,-7,3,LOG_2:13)
Block(-3,-6,-6,LOG_2:13)
Block(-3,-6,-5,LOG_2:13)
Block(-3,-6,-4,LOG_2:13)
Block(-3,-6,-3,LOG:13)
Block(-3,-6,-2,LOG:13)
Block(-3,-6,3,LOG_2:13)
Block(-3,-6,4,LOG_2:13)
Block(-3,-5,-7,LOG_2:13)
Block(-3,-5,-6,LOG_2:13)
Block(-3,-5,-5,LOG_2:13)
Block(-3,-5,-4,LOG:13)
Block(-3,-5,-3,LOG:13)
Block(-3,-5,-2,LOG:13)
Block(-3,-5,3,LOG:13)
Block(-3,-5,4,LOG:13)
Block(-3,-4,-4,LOG:13)
Block(-3,-4,-3,LOG:13)
Block(-3,-4,-2,LOG:13)
Block(-3,-4,4,LOG_2:13)
Block(-3,-3,-4,LOG:13)
Block(-3,-3,-3,LOG_2:13)
Block(-3,-3,-2,LOG:13)
Block(-3,-2,-4,LOG_2:13)
Block(-3,-2,-3,LOG_2:13)
Block(-3,-2,-2,LOG_2:13)
Block(-3,-2,-1,LOG:13)
Block(-3,-1,-3,LOG_2:13)
Block(-3,-1,-2,LOG_2:13)
Block(-3,-1,-1,LOG_2:13)
Block(-3,-1,0,LOG_2:13)
Block(-3,0,-3,LOG_2:13)
Block(-3,0,-2,LOG_2:13)
Block(-3,0,-1,LOG_2:13)
Block(-3,0,0,LOG_2:13)
Block(-3,1,-3,LOG_2:13)
Block(-3,1,-2,LOG_2:13)
Block(-3,1,-1,LOG_2:13)
Block(-3,2,-3,LOG:13)
Block(-3,2,-2,LOG:13)
Block(-3,2,-1,LOG_2:13)
Block(-3,3,-3,LOG:13)
Block(-3,3,-2,LOG:13)
Block(-3,4,-3,LOG:13)
Block(-3,4,-2,LOG_2:13)
Block(-3,43,-8,LEAVES:14)
Block(-3,43,-7,LEAVES:14)
Block(-3,44,-6,LEAVES:14)
Block(-3,44,-5,LEAVES:14)
Block(-3,45,-7,LEAVES:14)
Block(-3,45,-6,LEAVES:14)
Block(-3,46,-9,LEAVES:13)
Block(-3,46,-8,LEAVES:13)
Block(-3,46,-7,LEAVES:14)
Block(-3,46,-4,LOG:13)
Block(-3,46,-3,LOG:13)
Block(-3,46,-2,LOG:13)
Block(-3,46,9,LEAVES:14)
Block(-3,47,-11,LEAVES:13)
Block(-3,47,-10,LEAVES:13)
Block(-3,47,-9,LEAVES:13)
Block(-3,47,-7,LEAVES:14)
Block(-3,47,-6,LEAVES:14)
Block(-3,47,-5,LEAVES:14)
Block(-3,47,8,LEAVES:13)
Block(-3,47,9,LEAVES:13)
Block(-3,48,-8,LOG:13)
Block(-3,48,-7,LOG:13)
Block(-3,48,2,LEAVES:13)
Block(-3,48,3,LEAVES:13)
Block(-3,49,-11,LEAVES:14)
Block(-3,49,-10,LEAVES:14)
Block(-3,49,-8,LOG:13)
Block(-3,49,-7,LEAVES:14)
Block(-3,49,-6,LEAVES:14)
Block(-3,49,-5,LEAVES:14)
Block(-3,49,4,LEAVES:14)
Block(-3,49,5,LEAVES:14)
Block(-3,49,7,LOG:13)
Block(-3,49,8,LEAVES:13)
Block(-3,50,3,LEAVES:13)
Block(-3,50,9,LEAVES:13)
Block(-3,50,10,LEAVES:13)
Block(-3,51,2,LEAVES:13)
Block(-3,51,5,LOG:13)
Block(-3,51,6,LEAVES:14)
Block(-3,51,7,LEAVES:14)
Block(-3,52,5,LOG:13)
Block(-3,52,7,LEAVES:14)
Block(-3,52,8,LEAVES:14)
Block(-3,53,-3,LEAVES:13)
Block(-3,53,6,LEAVES:14)
Block(-3,53,7,LEAVES:14)
Block(-3,53,8,LEAVES:14)
Block(-3,54,-2,LEAVES:14)
Block(-3,54,-1,LEAVES:14)
Block(-3,54,6,LEAVES:14)
Block(-3,54,7,LOG:13)
Block(-3,54,8,LOG:13)
Block(-3,55,-3,LEAVES:14)
Block(-3,55,-2,LOG:13)
Block(-3,55,8,LEAVES:13)
Block(-3,56,-4,LEAVES:14)
Block(-3,56,-2,LEAVES:14)
Block(-3,56,-1,LEAVES:14)
Block(-3,57,1,LEAVES:14)
Block(-3,60,2,LEAVES:14)
Block(-3,60,3,LEAVES:14)
Block(-3,61,-6,LEAVES:13)
Block(-3,61,-5,LEAVES:13)
Block(-3,61,2,LEAVES:14)
Block(-3,61,3,LOG:13)
Block(-3,61,4,LOG:13)
Block(-3,62,-6,LEAVES:13)
Block(-3,62,-5,LEAVES:14)
Block(-3,62,-4,LEAVES:14)
Block(-3,62,0,LEAVES:13)
Block(-3,62,1,LEAVES:14)
Block(-3,62,3,LEAVES:14)
Block(-3,62,4,LOG:13)
Block(-3,62,5,LOG:13)
Block(-3,62,6,LOG:13)
Block(-3,63,-6,LEAVES:14)
Block(-3,63,-5,LEAVES:14)
Block(-3,63,0,LEAVES:13)
Block(-3,63,1,LOG:13)
Block(-3,63,2,LOG:13)
Block(-3,63,4,LEAVES:14)
Block(-3,63,5,LEAVES:13)
Block(-3,64,-7,LEAVES:14)
Block(-3,64,-6,LOG:13)
Block(-3,64,-5,LEAVES:14)
Block(-3,64,-4,LEAVES:14)
Block(-3,64,-2,LEAVES:13)
Block(-3,64,1,LEAVES:13)
Block(-3,64,2,LEAVES:14)
Block(-3,64,3,LEAVES:14)
Block(-3,64,4,LEAVES:13)
Block(-3,65,-6,LEAVES:14)
Block(-3,65,2,LEAVES:13)
Block(-3,66,-6,LEAVES:14)
Block(-3,67,5,LEAVES:13)
Block(-3,68,4,LEAVES:13)
Block(-3,68,5,LEAVES:13)
Block(-3,70,-3,LEAVES:14)
Block(-3,70,2,LOG:13)
Block(-3,70,3,LOG:13)
Block(-3,70,4,LEAVES:13)
Block(-3,71,-6,LEAVES:14)
Block(-3,71,-5,LEAVES:14)
Block(-3,71,-3,LEAVES:14)
Block(-3,71,-2,LOG:13)
Block(-3,71,5,LEAVES:14)
Block(-3,71,6,LEAVES:14)
Block(-3,72,-6,LEAVES:14)
Block(-3,72,-4,LEAVES:14)
Block(-3,72,-3,LOG:13)
Block(-3,72,-2,LOG:13)
Block(-3,72,3,LEAVES:13)
Block(-3,73,-4,LEAVES:14)
Block(-3,73,-2,LEAVES:14)
Block(-3,73,-1,LEAVES:13)
Block(-3,73,0,LEAVES:13)
Block(-3,73,1,LEAVES:13)
Block(-3,73,2,LEAVES:13)
Block(-3,73,3,LEAVES:14)
Block(-3,74,-5,LEAVES:14)
Block(-3,74,-4,LEAVES:14)
Block(-3,74,-2,LEAVES:14)
Block(-3,74,-1,LEAVES:13)
Block(-3,75,1,LEAVES:13)
Block(-3,75,2,LEAVES:14)
Block(-3,76,-2,LEAVES:13)
Block(-3,76,3,LEAVES:14)
Block(-3,76,4,LEAVES:13)
Block(-3,77,-2,LEAVES:14)
Block(-3,78,-4,LEAVES:14)
Block(-3,80,-5,LEAVES:14)
Block(-3,80,-4,LEAVES:14)
Block(-2,-11,5,LOG:13)
Block(-2,-10,-8,LOG:13)
Block(-2,-10,5,LOG_2:13)
Block(-2,-8,-9,LOG_2:13)
Block(-2,-7,-9,LOG_2:13)
Block(-2,-7,-8,LOG_2:13)
Block(-2,-7,2,LOG:13)
Block(-2,-7,3,LOG_2:13)
Block(-2,-6,-2,LOG_2:13)
Block(-2,-6,-1,LOG_2:13)
Block(-2,-6,0,LOG_2:13)
Block(-2,-6,1,LOG_2:13)
Block(-2,-6,2,LOG:13)
Block(-2,-6,3,LOG_2:13)
Block(-2,-5,-3,LOG:13)
Block(-2,-5,-2,LOG_2:13)
Block(-2,-5,-1,LOG_2:13)
Block(-2,-5,0,LOG_2:13)
Block(-2,-5,2,LOG:13)
Block(-2,-5,3,LOG:13)
Block(-2,-5,4,LOG_2:13)
Block(-2,-4,-3,LOG:13)
Block(-2,-4,-2,LOG:13)
Block(-2,-4,-1,LOG:13)
Block(-2,-4,0,LOG:13)
Block(-2,-4,2,LOG:13)
Block(-2,-4,3,LOG_2:13)
Block(-2,-4,4,LOG_2:13)
Block(-2,-3,-3,LOG_2:13)
Block(-2,-3,-2,LOG:13)
Block(-2,-3,-1,LOG:13)
Block(-2,-3,0,LOG:13)
Block(-2,-3,2,LOG:13)
Block(-2,-3,3,LOG_2:13)
Block(-2,-3,4,LOG_2:13)
Block(-2,-2,-3,LOG_2:13)
Block(-2,-2,-2,LOG_2:13)
Block(-2,-2,-1,LOG_2:13)
Block(-2,-2,0,LOG:13)
Block(-2,-2,2,LOG_2:13)
Block(-2,-2,3,LOG_2:13)
Block(-2,-2,4,LOG_2:13)
Block(-2,-1,-3,LOG_2:13)
Block(-2,-1,-2,LOG_2:13)
Block(-2,-1,-1,LOG_2:13)
Block(-2,-1,0,LOG:13)
Block(-2,-1,2,LOG:13)
Block(-2,-1,3,LOG:13)
Block(-2,0,-3,LOG_2:13)
Block(-2,0,-2,LOG_2:13)
Block(-2,0,-1,LOG_2:13)
Block(-2,0,0,LOG_2:13)
Block(-2,0,3,LOG:13)
Block(-2,1,-2,LOG_2:13)
Block(-2,1,-1,LOG_2:13)
Block(-2,1,0,LOG_2:13)
Block(-2,1,3,LOG:13)
Block(-2,2,-2,LOG:13)
Block(-2,2,-1,LOG_2:13)
Block(-2,2,0,LOG_2:13)
Block(-2,2,3,LOG:13)
Block(-2,3,-2,LOG:13)
Block(-2,3,-1,LOG:13)
Block(-2,3,0,LOG:13)
Block(-2,4,-3,LOG:13)
Block(-2,4,-2,LOG:13)
Block(-2,4,-1,LOG:13)
Block(-2,4,0,LOG:13)
Block(-2,5,-3,LOG:13)
Block(-2,5,-2,LOG:13)
Block(-2,5,-1,LOG:13)
Block(-2,5,0,LOG:13)
Block(-2,6,-3,LOG:13)
Block(-2,6,-2,LOG_2:13)
Block(-2,6,-1,LOG_2:13)
Block(-2,6,0,LOG:13)
Block(-2,7,-3,LOG:13)
Block(-2,7,-2,LOG_2:13)
Block(-2,7,-1,LOG_2:13)
Block(-2,7,0,LOG_2:13)
Block(-2,8,-2,LOG_2:13)
Block(-2,8,-1,LOG_2:13)
Block(-2,9,-2,LOG_2:13)
Block(-2,10,-2,LOG_2:13)
Block(-2,11,-2,LOG_2:13)
Block(-2,12,-2,LOG_2:13)
Block(-2,13,-2,LOG:13)
Block(-2,13,-1,LOG:13)
Block(-2,14,-2,LOG:13)
Block(-2,14,-1,LOG:13)
Block(-2,15,-2,LOG:13)
Block(-2,15,-1,LOG:13)
Block(-2,16,-2,LOG:13)
Block(-2,16,-1,LOG:13)
Block(-2,17,-2,LOG_2:13)
Block(-2,17,-1,LOG:13)
Block(-2,18,-2,LOG_2:13)
Block(-2,18,-1,LOG_2:13)
Block(-2,19,-2,LOG_2:13)
Block(-2,19,-1,LOG_2:13)
Block(-2,20,-2,LOG:13)
Block(-2,20,-1,LOG_2:13)
Block(-2,21,-2,LOG:13)
Block(-2,21,-1,LOG_2:13)
Block(-2,22,-2,LOG:13)
Block(-2,22,-1,LOG_2:13)
Block(-2,23,-2,LOG:13)
Block(-2,23,-1,LOG_2:13)
Block(-2,44,-6,LEAVES:14)
Block(-2,45,-6,LEAVES:14)
Block(-2,45,-2,LOG:13)
Block(-2,46,-9,LEAVES:14)
Block(-2,46,-8,LEAVES:14)
Block(-2,46,-7,LEAVES:14)
Block(-2,46,-3,LOG:13)
Block(-2,46,-2,LOG:13)
Block(-2,47,-9,LEAVES:13)
Block(-2,47,-6,LEAVES:14)
Block(-2,47,-5,LEAVES:14)
Block(-2,48,-9,LEAVES:14)
Block(-2,48,-7,LEAVES:14)
Block(-2,48,-6,LEAVES:14)
Block(-2,48,2,LEAVES:13)
Block(-2,48,7,LEAVES:13)
Block(-2,49,-9,LOG:13)
Block(-2,49,-8,LOG:13)
Block(-2,49,-7,LEAVES:14)
Block(-2,49,-5,LEAVES:14)
Block(-2,49,3,LEAVES:13)
Block(-2,49,5,LEAVES:14)
Block(-2,49,6,LEAVES:13)
Block(-2,49,7,LOG:13)
Block(-2,50,-8,LEAVES:14)
Block(-2,50,3,LOG:13)
Block(-2,50,4,LOG:13)
Block(-2,50,8,LEAVES:13)
Block(-2,50,10,LEAVES:13)
Block(-2,51,4,LOG:13)
Block(-2,51,5,LOG:13)
Block(-2,51,8,LEAVES:14)
Block(-2,53,-3,LEAVES:14)
Block(-2,53,-2,LEAVES:14)
Block(-2,53,6,LEAVES:14)
Block(-2,53,7,LEAVES:14)
Block(-2,55,-2,LOG:13)
Block(-2,55,7,LEAVES:14)
Block(-2,55,8,LEAVES:13)
Block(-2,56,-4,LEAVES:13)
Block(-2,56,-3,LEAVES:14)
Block(-2,57,0,LEAVES:14)
Block(-2,57,1,LEAVES:14)
Block(-2,60,-2,LEAVES:13)
Block(-2,60,3,LEAVES:14)
Block(-2,60,4,LEAVES:14)
Block(-2,61,-5,LEAVES:13)
Block(-2,61,-3,LEAVES:13)
Block(-2,61,-2,LEAVES:13)
Block(-2,61,2,LOG:13)
Block(-2,61,3,LOG:13)
Block(-2,61,5,LEAVES:14)
Block(-2,61,6,LEAVES:13)
Block(-2,62,-7,LEAVES:13)
Block(-2,62,-5,LEAVES:14)
Block(-2,62,-4,LEAVES:14)
Block(-2,62,0,LEAVES:13)
Block(-2,62,1,LEAVES:13)
Block(-2,62,2,LOG:13)
Block(-2,62,3,LEAVES:14)
Block(-2,62,4,LEAVES:14)
Block(-2,63,-6,LEAVES:14)
Block(-2,63,-5,LEAVES:14)
Block(-2,63,-3,LEAVES:14)
Block(-2,63,1,LEAVES:13)
Block(-2,63,2,LOG:13)
Block(-2,63,3,LEAVES:14)
Block(-2,63,5,LEAVES:13)
Block(-2,64,-7,LEAVES:14)
Block(-2,64,-6,LOG:13)
Block(-2,64,-4,LEAVES:14)
Block(-2,64,-3,LEAVES:14)
Block(-2,64,-2,LEAVES:14)
Block(-2,64,-1,LEAVES:14)
Block(-2,64,2,LEAVES:14)
Block(-2,65,-7,LEAVES:14)
Block(-2,65,-6,LEAVES:14)
Block(-2,65,1,LEAVES:13)
Block(-2,65,2,LEAVES:14)
Block(-2,66,-4,LEAVES:14)
Block(-2,67,-4,LEAVES:14)
Block(-2,67,5,LEAVES:14)
Block(-2,67,6,LEAVES:14)
Block(-2,68,-6,LEAVES:14)
Block(-2,69,-3,LEAVES:14)
Block(-2,69,3,LOG:13)
Block(-2,70,-5,LEAVES:14)
Block(-2,70,-4,LEAVES:14)
Block(-2,70,-3,LEAVES:14)
Block(-2,70,-1,LOG:13)
Block(-2,70,0,LOG:13)
Block(-2,70,3,LOG:13)
Block(-2,70,4,LEAVES:13)
Block(-2,70,5,LEAVES:14)
Block(-2,70,7,LEAVES:14)
Block(-2,70,8,LEAVES:14)
Block(-2,71,-2,LOG:13)
Block(-2,71,-1,LOG:13)
Block(-2,71,2,LEAVES:13)
Block(-2,72,-4,LEAVES:14)
Block(-2,72,-3,LEAVES:14)
Block(-2,72,-2,LEAVES:14)
Block(-2,72,2,LEAVES:13)
Block(-2,73,-6,LEAVES:14)
Block(-2,73,-5,LEAVES:14)
Block(-2,73,-4,LEAVES:14)
Block(-2,73,-3,LEAVES:14)
Block(-2,74,-2,LEAVES:13)
Block(-2,74,-1,LEAVES:13)
Block(-2,74,1,LEAVES:13)
Block(-2,75,0,LOG:13)
Block(-2,75,1,LOG:13)
Block(-2,76,2,LEAVES:14)
Block(-2,76,4,LEAVES:14)
Block(-2,77,-3,LEAVES:13)
Block(-2,77,-2,LEAVES:13)
Block(-2,77,2,LEAVES:14)
Block(-2,78,-5,LEAVES:13)
Block(-2,78,-4,LEAVES:13)
Block(-2,79,-3,LEAVES:14)
Block(-2,79,-2,LEAVES:14)
Block(-2,80,-4,LEAVES:14)
Block(-2,80,-2,LEAVES:14)
Block(-2,81,-1,LEAVES:14)
Block(-2,81,0,LEAVES:13)
Block(-1,-11,5,LOG:13)
Block(-1,-10,-8,LOG:13)
Block(-1,-10,-7,LOG:13)
Block(-1,-8,-9,LOG_2:13)
Block(-1,-7,2,LOG:13)
Block(-1,-7,3,LOG_2:13)
Block(-1,-6,-1,LOG_2:13)
Block(-1,-6,0,LOG_2:13)
Block(-1,-6,1,LOG_2:13)
Block(-1,-6,2,LOG:13)
Block(-1,-6,3,LOG_2:13)
Block(-1,-5,-3,LOG:13)
Block(-1,-5,-2,LOG_2:13)
Block(-1,-5,-1,LOG_2:13)
Block(-1,-5,0,LOG_2:13)
Block(-1,-5,1,LOG:13)
Block(-1,-5,3,LOG:13)
Block(-1,-5,4,LOG_2:13)
Block(-1,-4,-3,LOG:13)
Block(-1,-4,-2,LOG:13)
Block(-1,-4,-1,LOG:13)
Block(-1,-4,0,LOG:13)
Block(-1,-4,1,LOG:13)
Block(-1,-4,2,LOG:13)
Block(-1,-4,3,LOG:13)
Block(-1,-4,4,LOG_2:13)
Block(-1,-3,-2,LOG_2:13)
Block(-1,-3,-1,LOG:13)
Block(-1,-3,0,LOG:13)
Block(-1,-3,1,LOG:13)
Block(-1,-3,2,LOG:13)
Block(-1,-3,3,LOG_2:13)
Block(-1,-3,4,LOG_2:13)
Block(-1,-2,-3,LOG_2:13)
Block(-1,-2,-2,LOG_2:13)
Block(-1,-2,-1,LOG_2:13)
Block(-1,-2,0,LOG:13)
Block(-1,-2,1,LOG:13)
Block(-1,-2,2,LOG_2:13)
Block(-1,-2,3,LOG_2:13)
Block(-1,-2,4,LOG_2:13)
Block(-1,-1,-2,LOG_2:13)
Block(-1,-1,-1,LOG_2:13)
Block(-1,-1,0,LOG:13)
Block(-1,-1,1,LOG:13)
Block(-1,-1,2,LOG:13)
Block(-1,-1,3,LOG_2:13)
Block(-1,-1,4,LOG_2:13)
Block(-1,0,-2,LOG_2:13)
Block(-1,0,-1,LOG_2:13)
Block(-1,0,0,LOG:13)
Block(-1,0,1,LOG:13)
Block(-1,0,3,LOG:13)
Block(-1,0,4,LOG:13)
Block(-1,1,-2,LOG_2:13)
Block(-1,1,-1,LOG_2:13)
Block(-1,1,0,LOG:13)
Block(-1,1,1,LOG:13)
Block(-1,1,3,LOG:13)
Block(-1,2,-2,LOG:13)
Block(-1,2,-1,LOG:13)
Block(-1,2,0,LOG:13)
Block(-1,2,1,LOG:13)
Block(-1,2,2,LOG:13)
Block(-1,2,3,LOG:13)
Block(-1,3,-2,LOG:13)
Block(-1,3,-1,LOG:13)
Block(-1,3,0,LOG:13)
Block(-1,3,1,LOG:13)
Block(-1,3,3,LOG_2:13)
Block(-1,4,-2,LOG:13)
Block(-1,4,-1,LOG:13)
Block(-1,4,0,LOG:13)
Block(-1,4,1,LOG_2:13)
Block(-1,4,3,LOG_2:13)
Block(-1,5,-2,LOG:13)
Block(-1,5,-1,LOG:13)
Block(-1,5,0,LOG:13)
Block(-1,5,1,LOG_2:13)
Block(-1,5,3,LOG_2:13)
Block(-1,6,-2,LOG_2:13)
Block(-1,6,-1,LOG_2:13)
Block(-1,6,0,LOG_2:13)
Block(-1,6,1,LOG:13)
Block(-1,6,3,LOG_2:13)
Block(-1,7,-2,LOG_2:13)
Block(-1,7,-1,LOG_2:13)
Block(-1,7,0,LOG_2:13)
Block(-1,7,1,LOG:13)
Block(-1,7,2,LOG:13)
Block(-1,7,3,LOG:13)
Block(-1,8,-2,LOG_2:13)
Block(-1,8,-1,LOG_2:13)
Block(-1,8,0,LOG:13)
Block(-1,8,1,LOG:13)
Block(-1,8,2,LOG:13)
Block(-1,9,-2,LOG_2:13)
Block(-1,9,-1,LOG:13)
Block(-1,9,0,LOG:13)
Block(-1,9,1,LOG:13)
Block(-1,9,2,LOG:13)
Block(-1,10,-2,LOG_2:13)
Block(-1,10,-1,LOG:13)
Block(-1,10,0,LOG:13)
Block(-1,10,1,LOG:13)
Block(-1,10,2,LOG:13)
Block(-1,11,-2,LOG_2:13)
Block(-1,11,-1,LOG_2:13)
Block(-1,11,0,LOG_2:13)
Block(-1,11,1,LOG:13)
Block(-1,11,2,LOG:13)
Block(-1,12,-2,LOG_2:13)
Block(-1,12,-1,LOG_2:13)
Block(-1,12,0,LOG_2:13)
Block(-1,12,1,LOG:13)
Block(-1,12,2,LOG:13)
Block(-1,13,-2,LOG:13)
Block(-1,13,-1,LOG_2:13)
Block(-1,13,0,LOG_2:13)
Block(-1,13,1,LOG:13)
Block(-1,13,2,LOG:13)
Block(-1,14,-1,LOG:13)
Block(-1,14,0,LOG_2:13)
Block(-1,15,-1,LOG:13)
Block(-1,15,0,LOG_2:13)
Block(-1,16,-1,LOG:13)
Block(-1,16,0,LOG:13)
Block(-1,17,-1,LOG:13)
Block(-1,17,0,LOG:13)
Block(-1,18,-1,LOG_2:13)
Block(-1,18,0,LOG:13)
Block(-1,19,-1,LOG_2:13)
Block(-1,19,0,LOG_2:13)
Block(-1,20,-1,LOG_2:13)
Block(-1,20,0,LOG_2:13)
Block(-1,21,-1,LOG_2:13)
Block(-1,21,0,LOG_2:13)
Block(-1,22,-1,LOG_2:13)
Block(-1,22,0,LOG_2:13)
Block(-1,23,-2,LOG:13)
Block(-1,23,-1,LOG:13)
Block(-1,23,0,LOG_2:13)
Block(-1,24,-2,LOG:13)
Block(-1,24,-1,LOG:13)
Block(-1,24,0,LOG:13)
Block(-1,25,-2,LOG:13)
Block(-1,25,-1,LOG:13)
Block(-1,25,0,LOG:13)
Block(-1,26,-2,LOG_2:13)
Block(-1,26,-1,LOG_2:13)
Block(-1,26,0,LOG_2:13)
Block(-1,27,-2,LOG_2:13)
Block(-1,27,-1,LOG_2:13)
Block(-1,27,0,LOG_2:13)
Block(-1,28,-2,LOG:13)
Block(-1,28,-1,LOG:13)
Block(-1,28,0,LOG:13)
Block(-1,29,-2,LOG:13)
Block(-1,29,-1,LOG:13)
Block(-1,29,0,LOG:13)
Block(-1,30,-2,LOG:13)
Block(-1,30,-1,LOG:13)
Block(-1,30,0,LOG:13)
Block(-1,31,-2,LOG_2:13)
Block(-1,31,-1,LOG_2:13)
Block(-1,31,0,LOG:13)
Block(-1,32,-2,LOG_2:13)
Block(-1,32,-1,LOG_2:13)
Block(-1,32,0,LOG_2:13)
Block(-1,33,-1,LOG_2:13)
Block(-1,33,0,LOG_2:13)
Block(-1,34,-1,LOG:13)
Block(-1,35,-1,LOG:13)
Block(-1,36,-1,LOG:13)
Block(-1,37,-1,LOG:13)
Block(-1,38,-1,LOG:13)
Block(-1,39,-1,LOG:13)
Block(-1,40,-1,LOG:13)
Block(-1,41,-1,LOG:13)
Block(-1,43,6,LEAVES:13)
Block(-1,43,7,LEAVES:13)
Block(-1,44,-6,LEAVES:14)
Block(-1,45,-6,LEAVES:14)
Block(-1,45,-2,LOG:13)
Block(-1,45,6,LEAVES:13)
Block(-1,45,7,LEAVES:14)
Block(-1,46,-2,LOG:13)
Block(-1,46,-1,LOG:13)
Block(-1,47,-10,LEAVES:14)
Block(-1,47,-9,LEAVES:14)
Block(-1,48,-8,LEAVES:14)
Block(-1,48,-7,LEAVES:14)
Block(-1,48,-6,LEAVES:14)
Block(-1,48,8,LEAVES:13)
Block(-1,49,-10,LEAVES:14)
Block(-1,49,-9,LOG:13)
Block(-1,49,3,LEAVES:13)
Block(-1,49,4,LEAVES:14)
Block(-1,49,6,LEAVES:13)
Block(-1,49,7,LOG:13)
Block(-1,50,-10,LEAVES:14)
Block(-1,50,-8,LEAVES:13)
Block(-1,50,2,LOG:13)
Block(-1,50,3,LOG:13)
Block(-1,50,6,LOG:13)
Block(-1,50,7,LOG:13)
Block(-1,51,4,LEAVES:14)
Block(-1,51,5,LOG:13)
Block(-1,51,6,LOG:13)
Block(-1,51,8,LEAVES:14)
Block(-1,55,-2,LOG:13)
Block(-1,55,-1,LOG:13)
Block(-1,56,-2,LOG:13)
Block(-1,56,-1,LOG:13)
Block(-1,59,3,LEAVES:14)
Block(-1,60,3,LEAVES:13)
Block(-1,61,-5,LEAVES:13)
Block(-1,61,-3,LEAVES:13)
Block(-1,61,1,LOG:13)
Block(-1,61,2,LOG:13)
Block(-1,61,5,LEAVES:13)
Block(-1,62,-7,LEAVES:13)
Block(-1,62,-6,LEAVES:13)
Block(-1,62,-4,LOG:13)
Block(-1,62,-3,LOG:13)
Block(-1,62,1,LEAVES:13)
Block(-1,63,-5,LOG:13)
Block(-1,63,-4,LOG:13)
Block(-1,63,-3,LEAVES:14)
Block(-1,63,-1,LEAVES:14)
Block(-1,63,2,LEAVES:13)
Block(-1,63,5,LEAVES:13)
Block(-1,63,6,LEAVES:13)
Block(-1,64,-8,LOG:13)
Block(-1,64,-7,LOG:13)
Block(-1,64,-6,LOG:13)
Block(-1,64,-5,LOG:13)
Block(-1,64,-4,LEAVES:14)
Block(-1,64,3,LEAVES:13)
Block(-1,65,-5,LOG:13)
Block(-1,66,-6,LEAVES:14)
Block(-1,66,-5,LEAVES:14)
Block(-1,66,-4,LEAVES:14)
Block(-1,67,-8,LEAVES:14)
Block(-1,67,-6,LEAVES:14)
Block(-1,67,5,LEAVES:14)
Block(-1,68,-6,LEAVES:14)
Block(-1,68,0,LOG:13)
Block(-1,68,6,LEAVES:14)
Block(-1,68,7,LEAVES:14)
Block(-1,69,0,LOG:13)
Block(-1,69,3,LOG:13)
Block(-1,69,5,LEAVES:14)
Block(-1,69,6,LEAVES:14)
Block(-1,70,-5,LEAVES:14)
Block(-1,70,-4,LOG:13)
Block(-1,70,-3,LOG:13)
Block(-1,70,-2,LOG:13)
Block(-1,70,-1,LOG:13)
Block(-1,70,0,LOG:13)
Block(-1,70,4,LEAVES:14)
Block(-1,70,8,LEAVES:14)
Block(-1,71,-4,LOG:13)
Block(-1,71,-2,LOG:13)
Block(-1,71,-1,LEAVES:13)
Block(-1,72,-5,LEAVES:14)
Block(-1,72,-2,LOG:13)
Block(-1,72,-1,LEAVES:13)
Block(-1,73,-6,LEAVES:14)
Block(-1,73,-4,LEAVES:14)
Block(-1,73,-3,LEAVES:14)
Block(-1,73,-2,LOG:13)
Block(-1,73,-1,LOG:13)
Block(-1,74,-1,LOG:13)
Block(-1,74,0,LOG:13)
Block(-1,74,2,LEAVES:14)
Block(-1,75,0,LOG:13)
Block(-1,76,-2,LEAVES:13)
Block(-1,76,-1,LEAVES:13)
Block(-1,76,0,LEAVES:14)
Block(-1,77,2,LEAVES:14)
Block(-1,78,-4,LOG:13)
Block(-1,78,-3,LOG:13)
Block(-1,78,-1,LEAVES:14)
Block(-1,78,0,LEAVES:14)
Block(-1,79,-4,LOG:13)
Block(-1,79,-3,LOG:13)
Block(-1,79,-1,LEAVES:14)
Block(-1,79,0,LEAVES:14)
Block(-1,80,0,LEAVES:14)
Block(-1,80,1,LOG:13)
Block(-1,81,-1,LEAVES:14)
Block(-1,81,1,LEAVES:13)
Block(-1,81,2,LEAVES:13)
Block(0,-10,-7,LOG:13)
Block(0,-10,-6,LOG:13)
Block(0,-10,6,LOG:13)
Block(0,-9,-6,LOG:13)
Block(0,-9,-5,LOG:13)
Block(0,-9,6,LOG:13)
Block(0,-9,7,LOG:13)
Block(0,-8,-5,LOG_2:13)
Block(0,-8,4,LOG_2:13)
Block(0,-8,5,LOG:13)
Block(0,-7,1,LOG:13)
Block(0,-7,3,LOG_2:13)
Block(0,-7,4,LOG_2:13)
Block(0,-7,5,LOG_2:13)
Block(0,-6,0,LOG:13)
Block(0,-6,1,LOG:13)
Block(0,-6,2,LOG:13)
Block(0,-5,-1,LOG_2:13)
Block(0,-5,0,LOG:13)
Block(0,-5,1,LOG:13)
Block(0,-5,2,LOG:13)
Block(0,-5,3,LOG_2:13)
Block(0,-4,-1,LOG:13)
Block(0,-4,0,LOG:13)
Block(0,-4,1,LOG:13)
Block(0,-4,2,LOG:13)
Block(0,-4,3,LOG:13)
Block(0,-3,-1,LOG:13)
Block(0,-3,0,LOG:13)
Block(0,-3,1,LOG:13)
Block(0,-3,2,LOG:13)
Block(0,-3,3,LOG_2:13)
Block(0,-3,4,LOG_2:13)
Block(0,-2,-1,LOG_2:13)
Block(0,-2,0,LOG:13)
Block(0,-2,1,LOG:13)
Block(0,-2,2,LOG:13)
Block(0,-2,3,LOG_2:13)
Block(0,-2,4,LOG_2:13)
Block(0,-1,-1,LOG_2:13)
Block(0,-1,0,LOG_2:13)
Block(0,-1,1,LOG:13)
Block(0,-1,2,LOG:13)
Block(0,-1,3,LOG_2:13)
Block(0,-1,4,LOG_2:13)
Block(0,0,-1,LOG_2:13)
Block(0,0,0,LOG_2:13)
Block(0,0,1,LOG:13)
Block(0,0,2,LOG:13)
Block(0,0,3,LOG:13)
Block(0,0,4,LOG_2:13)
Block(0,1,-1,LOG_2:13)
Block(0,1,0,LOG_2:13)
Block(0,1,1,LOG:13)
Block(0,1,2,LOG:13)
Block(0,1,3,LOG:13)
Block(0,1,4,LOG:13)
Block(0,2,-1,LOG:13)
Block(0,2,0,LOG_2:13)
Block(0,2,1,LOG_2:13)
Block(0,2,2,LOG:13)
Block(0,2,3,LOG:13)
Block(0,3,-1,LOG:13)
Block(0,3,0,LOG_2:13)
Block(0,3,1,LOG_2:13)
Block(0,3,2,LOG_2:13)
Block(0,3,3,LOG:13)
Block(0,4,-1,LOG:13)
Block(0,4,0,LOG_2:13)
Block(0,4,1,LOG_2:13)
Block(0,4,2,LOG_2:13)
Block(0,4,3,LOG_2:13)
Block(0,5,-1,LOG:13)
Block(0,5,0,LOG_2:13)
Block(0,5,1,LOG_2:13)
Block(0,5,2,LOG_2:13)
Block(0,5,3,LOG_2:13)
Block(0,6,-1,LOG_2:13)
Block(0,6,0,LOG_2:13)
Block(0,6,1,LOG_2:13)
Block(0,6,2,LOG:13)
Block(0,6,3,LOG_2:13)
Block(0,7,-1,LOG_2:13)
Block(0,7,0,LOG_2:13)
Block(0,7,1,LOG:13)
Block(0,7,2,LOG:13)
Block(0,7,3,LOG:13)
Block(0,8,-1,LOG_2:13)
Block(0,8,0,LOG:13)
Block(0,8,1,LOG:13)
Block(0,8,2,LOG:13)
Block(0,9,-1,LOG:13)
Block(0,9,0,LOG:13)
Block(0,9,1,LOG:13)
Block(0,9,2,LOG:13)
Block(0,10,-1,LOG:13)
Block(0,10,0,LOG:13)
Block(0,10,1,LOG:13)
Block(0,10,2,LOG:13)
Block(0,11,-1,LOG_2:13)
Block(0,11,0,LOG_2:13)
Block(0,11,1,LOG:13)
Block(0,11,2,LOG:13)
Block(0,12,-1,LOG_2:13)
Block(0,12,0,LOG_2:13)
Block(0,12,1,LOG:13)
Block(0,12,2,LOG:13)
Block(0,13,-1,LOG_2:13)
Block(0,13,0,LOG_2:13)
Block(0,13,1,LOG_2:13)
Block(0,13,2,LOG_2:13)
Block(0,14,-1,LOG:13)
Block(0,14,0,LOG:13)
Block(0,14,1,LOG_2:13)
Block(0,14,2,LOG_2:13)
Block(0,15,-1,LOG:13)
Block(0,15,0,LOG:13)
Block(0,15,1,LOG_2:13)
Block(0,15,2,LOG_2:13)
Block(0,16,-1,LOG:13)
Block(0,16,0,LOG:13)
Block(0,16,1,LOG_2:13)
Block(0,16,2,LOG_2:13)
Block(0,17,-1,LOG:13)
Block(0,17,0,LOG:13)
Block(0,17,1,LOG:13)
Block(0,17,2,LOG:13)
Block(0,18,-1,LOG:13)
Block(0,18,0,LOG:13)
Block(0,18,1,LOG:13)
Block(0,18,2,LOG:13)
Block(0,19,-1,LOG_2:13)
Block(0,19,0,LOG_2:13)
Block(0,19,1,LOG:13)
Block(0,19,2,LOG:13)
Block(0,20,-1,LOG_2:13)
Block(0,20,0,LOG_2:13)
Block(0,20,1,LOG_2:13)
Block(0,20,2,LOG_2:13)
Block(0,21,-1,LOG_2:13)
Block(0,21,0,LOG_2:13)
Block(0,21,1,LOG_2:13)
Block(0,21,2,LOG:13)
Block(0,22,-1,LOG_2:13)
Block(0,22,0,LOG_2:13)
Block(0,22,1,LOG_2:13)
Block(0,22,2,LOG:13)
Block(0,23,-1,LOG:13)
Block(0,23,0,LOG_2:13)
Block(0,23,1,LOG_2:13)
Block(0,23,2,LOG:13)
Block(0,24,-1,LOG:13)
Block(0,24,0,LOG:13)
Block(0,24,1,LOG:13)
Block(0,24,2,LOG:13)
Block(0,25,-1,LOG:13)
Block(0,25,0,LOG:13)
Block(0,25,1,LOG:13)
Block(0,25,2,LOG:13)
Block(0,26,-1,LOG_2:13)
Block(0,26,0,LOG:13)
Block(0,26,1,LOG:13)
Block(0,26,2,LOG:13)
Block(0,27,-11,LEAVES:14)
Block(0,27,-10,LEAVES:13)
Block(0,27,-1,LOG_2:13)
Block(0,27,0,LOG_2:13)
Block(0,27,1,LOG:13)
Block(0,27,2,LOG:13)
Block(0,28,-1,LOG_2:13)
Block(0,28,0,LOG:13)
Block(0,28,1,LOG:13)
Block(0,28,2,LOG:13)
Block(0,29,-1,LOG:13)
Block(0,29,0,LOG:13)
Block(0,29,1,LOG:13)
Block(0,29,2,LOG_2:13)
Block(0,30,-1,LOG:13)
Block(0,30,0,LOG:13)
Block(0,30,1,LOG:13)
Block(0,30,2,LOG_2:13)
Block(0,31,-1,LOG:13)
Block(0,31,0,LOG:13)
Block(0,31,1,LOG:13)
Block(0,31,2,LOG_2:13)
Block(0,32,-1,LOG_2:13)
Block(0,32,0,LOG_2:13)
Block(0,32,1,LOG_2:13)
Block(0,32,2,LOG:13)
Block(0,33,-1,LOG_2:13)
Block(0,33,0,LOG_2:13)
Block(0,33,1,LOG_2:13)
Block(0,34,-1,LOG:13)
Block(0,34,0,LOG_2:13)
Block(0,34,1,LOG:13)
Block(0,35,-1,LOG:13)
Block(0,35,0,LOG:13)
Block(0,35,1,LOG:13)
Block(0,36,-1,LOG:13)
Block(0,36,0,LOG:13)
Block(0,36,1,LOG:13)
Block(0,37,-1,LOG:13)
Block(0,37,0,LOG:13)
Block(0,37,1,LOG_2:13)
Block(0,38,-1,LOG:13)
Block(0,38,0,LOG:13)
Block(0,38,1,LOG:13)
Block(0,39,-1,LOG:13)
Block(0,39,0,LOG:13)
Block(0,39,1,LOG:13)
Block(0,40,-1,LOG:13)
Block(0,40,0,LOG:13)
Block(0,40,1,LOG:13)
Block(0,41,-1,LOG:13)
Block(0,41,0,LOG:13)
Block(0,41,1,LOG:13)
Block(0,42,-1,LOG:13)
Block(0,42,0,LOG:13)
Block(0,42,1,LOG:13)
Block(0,42,10,LEAVES:14)
Block(0,43,-1,LOG:13)
Block(0,43,0,LOG:13)
Block(0,43,1,LOG:13)
Block(0,43,7,LEAVES:13)
Block(0,43,9,LEAVES:14)
Block(0,43,10,LEAVES:14)
Block(0,44,-1,LOG:13)
Block(0,44,0,LOG:13)
Block(0,44,1,LOG:13)
Block(0,45,-2,LOG:13)
Block(0,45,-1,LOG:13)
Block(0,45,0,LOG:13)
Block(0,45,1,LOG:13)
Block(0,45,7,LEAVES:14)
Block(0,45,9,LEAVES:14)
Block(0,46,-10,LEAVES:14)
Block(0,46,-2,LOG:13)
Block(0,46,-1,LOG:13)
Block(0,46,0,LOG:13)
Block(0,46,1,LOG:13)
Block(0,46,9,LEAVES:14)
Block(0,47,-10,LEAVES:14)
Block(0,47,-2,LOG:13)
Block(0,47,-1,LOG:13)
Block(0,47,0,LOG:13)
Block(0,47,1,LOG:13)
Block(0,47,9,LEAVES:14)
Block(0,48,-8,LEAVES:14)
Block(0,48,-7,LEAVES:13)
Block(0,48,-6,LEAVES:13)
Block(0,48,-1,LOG:13)
Block(0,48,0,LOG:13)
Block(0,48,1,LOG:13)
Block(0,48,8,LEAVES:13)
Block(0,49,-1,LOG:13)
Block(0,49,0,LOG:13)
Block(0,49,1,LOG:13)
Block(0,49,8,LEAVES:13)
Block(0,50,-8,LEAVES:13)
Block(0,50,-7,LEAVES:13)
Block(0,50,-1,LOG:13)
Block(0,50,0,LOG:13)
Block(0,50,1,LOG:13)
Block(0,50,2,LOG:13)
Block(0,51,-1,LOG:13)
Block(0,51,0,LOG:13)
Block(0,52,-1,LOG:13)
Block(0,52,0,LOG:13)
Block(0,53,-1,LOG:13)
Block(0,53,0,LOG:13)
Block(0,54,-2,LOG:13)
Block(0,54,-1,LOG:13)
Block(0,54,0,LOG:13)
Block(0,55,-2,LOG:13)
Block(0,55,-1,LOG:13)
Block(0,55,0,LOG:13)
Block(0,56,-1,LOG:13)
Block(0,56,0,LOG:13)
Block(0,57,-9,LEAVES:14)
Block(0,57,-8,LEAVES:14)
Block(0,57,-7,LOG:13)
Block(0,57,-1,LOG:13)
Block(0,57,0,LOG:13)
Block(0,58,-9,LEAVES:14)
Block(0,58,-6,LEAVES:14)
Block(0,58,0,LOG:13)
Block(0,59,-6,LEAVES:14)
Block(0,59,0,LOG:13)
Block(0,60,0,LOG:13)
Block(0,61,-6,LEAVES:13)
Block(0,61,-5,LEAVES:14)
Block(0,61,-3,LOG:13)
Block(0,61,-2,LOG:13)
Block(0,61,0,LOG:13)
Block(0,61,1,LOG:13)
Block(0,61,2,LEAVES:13)
Block(0,62,-3,LOG:13)
Block(0,62,-2,LEAVES:14)
Block(0,62,0,LOG:13)
Block(0,63,-7,LEAVES:13)
Block(0,63,-6,LEAVES:14)
Block(0,63,-5,LEAVES:14)
Block(0,63,-1,LEAVES:14)
Block(0,63,0,LOG:13)
Block(0,64,-8,LOG:13)
Block(0,64,-7,LEAVES:13)
Block(0,64,-6,LEAVES:14)
Block(0,64,-5,LEAVES:14)
Block(0,64,-4,LEAVES:14)
Block(0,64,-3,LEAVES:14)
Block(0,64,-2,LEAVES:14)
Block(0,64,0,LOG:13)
Block(0,64,2,LEAVES:13)
Block(0,64,3,LEAVES:13)
Block(0,65,-6,LEAVES:14)
Block(0,65,-5,LOG:13)
Block(0,65,0,LOG:13)
Block(0,66,-6,LEAVES:14)
Block(0,66,-5,LOG:13)
Block(0,66,0,LOG:13)
Block(0,67,-8,LEAVES:14)
Block(0,67,-7,LEAVES:14)
Block(0,67,0,LOG:13)
Block(0,68,0,LOG:13)
Block(0,68,3,LOG:13)
Block(0,68,5,LEAVES:14)
Block(0,68,7,LEAVES:14)
Block(0,68,8,LEAVES:14)
Block(0,69,0,LOG:13)
Block(0,69,3,LOG:13)
Block(0,69,5,LEAVES:14)
Block(0,69,6,LEAVES:14)
Block(0,69,7,LEAVES:14)
Block(0,70,0,LOG:13)
Block(0,70,4,LEAVES:14)
Block(0,70,6,LOG:13)
Block(0,70,7,LEAVES:14)
Block(0,71,-5,LOG:13)
Block(0,71,-4,LOG:13)
Block(0,71,-3,LEAVES:14)
Block(0,71,0,LOG:13)
Block(0,71,4,LEAVES:14)
Block(0,71,5,LEAVES:14)
Block(0,71,6,LOG:13)
Block(0,71,7,LOG:13)
Block(0,72,-5,LOG:13)
Block(0,72,-4,LEAVES:14)
Block(0,73,-5,LEAVES:14)
Block(0,74,2,LEAVES:14)
Block(0,75,2,LEAVES:14)
Block(0,76,-1,LEAVES:13)
Block(0,77,-3,LEAVES:13)
Block(0,77,-2,LEAVES:13)
Block(0,77,-1,LEAVES:14)
Block(0,78,-3,LOG:13)
Block(0,78,-1,LEAVES:14)
Block(0,79,-4,LEAVES:13)
Block(0,79,-2,LEAVES:14)
Block(0,79,-1,LEAVES:14)
Block(0,79,0,LEAVES:14)
Block(0,79,2,LEAVES:14)
Block(0,80,0,LOG:13)
Block(0,80,1,LEAVES:14)
Block(0,81,2,LEAVES:13)
Block(1,-9,-5,LOG:13)
Block(1,-9,5,LOG:13)
Block(1,-9,6,LOG:13)
Block(1,-9,7,LOG:13)
Block(1,-9,8,LOG:13)
Block(1,-8,-5,LOG:13)
Block(1,-8,-4,LOG:13)
Block(1,-8,1,LOG_2:13)
Block(1,-8,4,LOG:13)
Block(1,-8,5,LOG:13)
Block(1,-7,-5,LOG_2:13)
Block(1,-7,-4,LOG:13)
Block(1,-7,-1,LOG:13)
Block(1,-7,1,LOG_2:13)
Block(1,-6,-5,LOG_2:13)
Block(1,-6,-1,LOG:13)
Block(1,-6,0,LOG:13)
Block(1,-5,-2,LOG_2:13)
Block(1,-5,-1,LOG_2:13)
Block(1,-5,0,LOG:13)
Block(1,-5,1,LOG:13)
Block(1,-5,2,LOG:13)
Block(1,-4,-2,LOG_2:13)
Block(1,-4,0,LOG:13)
Block(1,-4,1,LOG:13)
Block(1,-4,2,LOG:13)
Block(1,-3,-2,LOG_2:13)
Block(1,-3,0,LOG:13)
Block(1,-3,1,LOG:13)
Block(1,-3,2,LOG:13)
Block(1,-2,-2,LOG_2:13)
Block(1,-2,0,LOG_2:13)
Block(1,-2,1,LOG:13)
Block(1,-1,-2,LOG_2:13)
Block(1,-1,0,LOG_2:13)
Block(1,-1,1,LOG:13)
Block(1,-1,2,LOG:13)
Block(1,0,-2,LOG_2:13)
Block(1,0,0,LOG_2:13)
Block(1,0,1,LOG_2:13)
Block(1,0,2,LOG:13)
Block(1,1,-2,LOG_2:13)
Block(1,1,0,LOG_2:13)
Block(1,1,1,LOG_2:13)
Block(1,1,2,LOG:13)
Block(1,1,3,LOG:13)
Block(1,2,-2,LOG_2:13)
Block(1,2,0,LOG_2:13)
Block(1,2,1,LOG_2:13)
Block(1,2,2,LOG:13)
Block(1,2,3,LOG:13)
Block(1,3,-2,LOG:13)
Block(1,3,0,LOG_2:13)
Block(1,3,1,LOG_2:13)
Block(1,3,2,LOG_2:13)
Block(1,3,3,LOG:13)
Block(1,4,-2,LOG:13)
Block(1,4,0,LOG_2:13)
Block(1,4,1,LOG_2:13)
Block(1,4,2,LOG_2:13)
Block(1,4,3,LOG:13)
Block(1,5,-2,LOG:13)
Block(1,5,0,LOG_2:13)
Block(1,5,1,LOG_2:13)
Block(1,5,2,LOG:13)
Block(1,5,3,LOG:13)
Block(1,6,-2,LOG_2:13)
Block(1,6,0,LOG_2:13)
Block(1,6,1,LOG:13)
Block(1,6,2,LOG:13)
Block(1,6,3,LOG:13)
Block(1,7,-2,LOG_2:13)
Block(1,7,0,LOG:13)
Block(1,7,1,LOG:13)
Block(1,7,2,LOG:13)
Block(1,7,3,LOG:13)
Block(1,8,-2,LOG_2:13)
Block(1,8,0,LOG:13)
Block(1,8,1,LOG:13)
Block(1,8,2,LOG:13)
Block(1,9,-2,LOG_2:13)
Block(1,9,0,LOG:13)
Block(1,9,1,LOG:13)
Block(1,9,2,LOG:13)
Block(1,10,-2,LOG:13)
Block(1,10,0,LOG_2:13)
Block(1,10,1,LOG:13)
Block(1,10,2,LOG:13)
Block(1,11,-2,LOG:13)
Block(1,11,0,LOG_2:13)
Block(1,11,1,LOG:13)
Block(1,11,2,LOG:13)
Block(1,12,-2,LOG:13)
Block(1,12,0,LOG_2:13)
Block(1,12,1,LOG_2:13)
Block(1,12,2,LOG:13)
Block(1,13,-2,LOG_2:13)
Block(1,13,-1,LOG:13)
Block(1,13,0,LOG:13)
Block(1,13,1,LOG_2:13)
Block(1,13,2,LOG_2:13)
Block(1,14,-2,LOG:13)
Block(1,14,-1,LOG:13)
Block(1,14,0,LOG:13)
Block(1,14,1,LOG:13)
Block(1,14,2,LOG_2:13)
Block(1,15,-2,LOG:13)
Block(1,15,-1,LOG:13)
Block(1,15,0,LOG:13)
Block(1,15,1,LOG:13)
Block(1,15,2,LOG_2:13)
Block(1,16,-2,LOG:13)
Block(1,16,-1,LOG:13)
Block(1,16,0,LOG:13)
Block(1,16,1,LOG:13)
Block(1,16,2,LOG_2:13)
Block(1,17,-2,LOG:13)
Block(1,17,-1,LOG:13)
Block(1,17,0,LOG:13)
Block(1,17,1,LOG:13)
Block(1,17,2,LOG_2:13)
Block(1,18,-2,LOG:13)
Block(1,18,-1,LOG:13)
Block(1,18,0,LOG:13)
Block(1,18,1,LOG:13)
Block(1,18,2,LOG:13)
Block(1,19,-2,LOG:13)
Block(1,19,-1,LOG:13)
Block(1,19,0,LOG:13)
Block(1,19,1,LOG:13)
Block(1,19,2,LOG:13)
Block(1,20,-2,LOG_2:13)
Block(1,20,-1,LOG_2:13)
Block(1,20,0,LOG_2:13)
Block(1,20,1,LOG:13)
Block(1,20,2,LOG:13)
Block(1,21,-2,LOG_2:13)
Block(1,21,-1,LOG_2:13)
Block(1,21,0,LOG_2:13)
Block(1,21,1,LOG_2:13)
Block(1,21,2,LOG:13)
Block(1,22,-2,LOG_2:13)
Block(1,22,-1,LOG_2:13)
Block(1,22,0,LOG_2:13)
Block(1,22,1,LOG_2:13)
Block(1,22,2,LOG:13)
Block(1,23,-2,LOG:13)
Block(1,23,-1,LOG:13)
Block(1,23,0,LOG_2:13)
Block(1,23,1,LOG_2:13)
Block(1,23,2,LOG:13)
Block(1,24,-2,LOG:13)
Block(1,24,-1,LOG:13)
Block(1,24,0,LOG:13)
Block(1,24,1,LOG:13)
Block(1,24,2,LOG:13)
Block(1,25,-2,LOG_2:13)
Block(1,25,-1,LOG:13)
Block(1,25,0,LOG:13)
Block(1,25,1,LOG:13)
Block(1,25,2,LOG:13)
Block(1,26,-9,LEAVES:13)
Block(1,26,-8,LEAVES:13)
Block(1,26,-2,LOG_2:13)
Block(1,26,-1,LOG_2:13)
Block(1,26,0,LOG:13)
Block(1,26,1,LOG:13)
Block(1,26,2,LOG:13)
Block(1,27,-11,LEAVES:14)
Block(1,27,-1,LOG_2:13)
Block(1,27,0,LOG:13)
Block(1,27,1,LOG:13)
Block(1,27,2,LOG:13)
Block(1,28,-1,LOG:13)
Block(1,28,0,LOG:13)
Block(1,28,1,LOG:13)
Block(1,28,2,LOG_2:13)
Block(1,29,-1,LOG:13)
Block(1,29,0,LOG:13)
Block(1,29,1,LOG_2:13)
Block(1,29,2,LOG_2:13)
Block(1,30,-1,LOG:13)
Block(1,30,0,LOG:13)
Block(1,30,1,LOG_2:13)
Block(1,30,2,LOG_2:13)
Block(1,31,-1,LOG:13)
Block(1,31,0,LOG:13)
Block(1,31,1,LOG_2:13)
Block(1,31,2,LOG_2:13)
Block(1,32,-2,LOG:13)
Block(1,32,-1,LOG_2:13)
Block(1,32,0,LOG_2:13)
Block(1,32,1,LOG_2:13)
Block(1,32,2,LOG_2:13)
Block(1,33,-2,LOG_2:13)
Block(1,33,-1,LOG_2:13)
Block(1,33,0,LOG_2:13)
Block(1,33,1,LOG_2:13)
Block(1,33,2,LOG_2:13)
Block(1,34,-2,LOG_2:13)
Block(1,34,-1,LOG_2:13)
Block(1,34,0,LOG_2:13)
Block(1,34,1,LOG_2:13)
Block(1,34,2,LOG_2:13)
Block(1,35,-2,LOG_2:13)
Block(1,35,-1,LOG:13)
Block(1,35,0,LOG:13)
Block(1,35,1,LOG_2:13)
Block(1,35,2,LOG:13)
Block(1,36,-2,LOG_2:13)
Block(1,36,-1,LOG:13)
Block(1,36,0,LOG:13)
Block(1,36,1,LOG:13)
Block(1,36,2,LOG:13)
Block(1,37,-2,LOG:13)
Block(1,37,-1,LOG:13)
Block(1,37,0,LOG:13)
Block(1,37,1,LOG:13)
Block(1,37,2,LOG:13)
Block(1,38,-2,LOG:13)
Block(1,38,-1,LOG:13)
Block(1,38,0,LOG:13)
Block(1,38,1,LOG:13)
Block(1,38,2,LOG:13)
Block(1,39,-2,LOG:13)
Block(1,39,-1,LOG:13)
Block(1,39,0,LOG:13)
Block(1,39,1,LOG:13)
Block(1,39,2,LOG:13)
Block(1,40,-2,LOG:13)
Block(1,40,-1,LOG:13)
Block(1,40,0,LOG:13)
Block(1,40,1,LOG:13)
Block(1,40,2,LOG:13)
Block(1,41,-2,LOG:13)
Block(1,41,-1,LOG:13)
Block(1,41,0,LOG:13)
Block(1,41,1,LOG:13)
Block(1,41,2,LOG:13)
Block(1,42,-1,LOG:13)
Block(1,42,0,LOG:13)
Block(1,42,1,LOG:13)
Block(1,43,-1,LOG:13)
Block(1,43,0,LOG:13)
Block(1,43,1,LOG:13)
Block(1,43,7,LEAVES:13)
Block(1,43,9,LEAVES:14)
Block(1,44,-1,LOG:13)
Block(1,44,0,LOG:13)
Block(1,44,1,LOG:13)
Block(1,44,8,LEAVES:14)
Block(1,45,-1,LOG:13)
Block(1,45,0,LOG:13)
Block(1,45,1,LOG:13)
Block(1,45,6,LEAVES:13)
Block(1,45,8,LOG:13)
Block(1,45,9,LEAVES:14)
Block(1,46,-2,LOG:13)
Block(1,46,-1,LOG:13)
Block(1,46,0,LOG:13)
Block(1,46,1,LOG:13)
Block(1,46,9,LEAVES:14)
Block(1,47,-1,LOG:13)
Block(1,47,0,LOG:13)
Block(1,47,1,LOG:13)
Block(1,47,11,LEAVES:13)
Block(1,48,-1,LOG:13)
Block(1,48,0,LOG:13)
Block(1,48,1,LOG:13)
Block(1,48,11,LEAVES:13)
Block(1,49,-1,LOG:13)
Block(1,49,0,LOG:13)
Block(1,49,1,LOG:13)
Block(1,49,9,LEAVES:13)
Block(1,50,-1,LOG:13)
Block(1,50,0,LOG:13)
Block(1,50,1,LOG:13)
Block(1,51,-1,LOG:13)
Block(1,51,0,LOG:13)
Block(1,51,1,LOG:13)
Block(1,52,-1,LOG:13)
Block(1,52,0,LOG:13)
Block(1,52,1,LOG:13)
Block(1,53,-1,LOG:13)
Block(1,53,0,LOG:13)
Block(1,53,1,LOG:13)
Block(1,54,-2,LOG:13)
Block(1,54,-1,LOG:13)
Block(1,54,0,LOG:13)
Block(1,54,1,LOG:13)
Block(1,55,-8,LEAVES:14)
Block(1,55,-7,LEAVES:14)
Block(1,55,-2,LOG:13)
Block(1,55,-1,LOG:13)
Block(1,55,0,LOG:13)
Block(1,55,1,LOG:13)
Block(1,56,-8,LEAVES:14)
Block(1,56,-1,LOG:13)
Block(1,56,0,LOG:13)
Block(1,56,1,LOG:13)
Block(1,57,-8,LEAVES:14)
Block(1,57,-7,LOG:13)
Block(1,57,-1,LOG:13)
Block(1,57,0,LOG:13)
Block(1,57,1,LOG:13)
Block(1,58,-1,LOG:13)
Block(1,58,0,LOG:13)
Block(1,58,1,LOG:13)
Block(1,59,-2,LOG:13)
Block(1,59,-1,LOG:13)
Block(1,59,0,LOG:13)
Block(1,59,1,LOG:13)
Block(1,59,4,LEAVES:13)
Block(1,59,5,LEAVES:13)
Block(1,60,-2,LOG:13)
Block(1,60,-1,LOG:13)
Block(1,60,0,LOG:13)
Block(1,60,1,LOG:13)
Block(1,61,-2,LOG:13)
Block(1,61,-1,LOG:13)
Block(1,61,0,LOG:13)
Block(1,61,1,LOG:13)
Block(1,62,-3,LEAVES:14)
Block(1,62,-1,LOG:13)
Block(1,62,0,LOG:13)
Block(1,62,1,LOG:13)
Block(1,63,-5,LEAVES:14)
Block(1,63,0,LOG:13)
Block(1,63,1,LOG:13)
Block(1,64,-6,LEAVES:14)
Block(1,64,-2,LEAVES:14)
Block(1,64,0,LOG:13)
Block(1,64,1,LOG:13)
Block(1,65,-8,LEAVES:14)
Block(1,65,-5,LEAVES:14)
Block(1,65,0,LOG:13)
Block(1,65,1,LOG:13)
Block(1,66,-6,LOG:13)
Block(1,66,-5,LOG:13)
Block(1,66,-4,LEAVES:14)
Block(1,66,0,LOG:13)
Block(1,66,1,LOG:13)
Block(1,67,-4,LEAVES:14)
Block(1,67,1,LOG:13)
Block(1,67,2,LOG:13)
Block(1,68,-4,LEAVES:14)
Block(1,68,0,LOG:13)
Block(1,68,1,LOG:13)
Block(1,68,2,LOG:13)
Block(1,68,3,LOG:13)
Block(1,68,5,LEAVES:14)
Block(1,68,6,LEAVES:14)
Block(1,68,7,LEAVES:14)
Block(1,68,8,LEAVES:14)
Block(1,69,0,LOG:13)
Block(1,69,1,LOG:13)
Block(1,70,0,LOG:13)
Block(1,70,4,LEAVES:14)
Block(1,70,6,LOG:13)
Block(1,70,7,LEAVES:14)
Block(1,71,-4,LEAVES:14)
Block(1,71,-3,LEAVES:14)
Block(1,71,0,LOG:13)
Block(1,71,1,LOG:13)
Block(1,71,5,LEAVES:14)
Block(1,71,6,LEAVES:14)
Block(1,71,8,LEAVES:14)
Block(1,72,-5,LOG:13)
Block(1,72,0,LOG:13)
Block(1,72,1,LOG:13)
Block(1,73,-7,LEAVES:14)
Block(1,73,-6,LEAVES:14)
Block(1,73,-5,LOG:13)
Block(1,73,-4,LEAVES:14)
Block(1,73,1,LOG:13)
Block(1,74,-7,LEAVES:14)
Block(1,74,-4,LEAVES:14)
Block(1,74,1,LOG:13)
Block(1,75,-4,LEAVES:13)
Block(1,75,0,LOG:13)
Block(1,75,1,LOG:13)
Block(1,75,2,LOG:13)
Block(1,76,-1,LOG:13)
Block(1,76,0,LOG:13)
Block(1,76,1,LEAVES:14)
Block(1,76,2,LOG:13)
Block(1,77,-3,LEAVES:13)
Block(1,77,-2,LOG:13)
Block(1,77,-1,LOG:13)
Block(1,78,-3,LOG:13)
Block(1,78,-2,LOG:13)
Block(1,78,2,LEAVES:14)
Block(1,78,3,LEAVES:14)
Block(1,79,-4,LEAVES:13)
Block(1,79,-3,LEAVES:14)
Block(1,79,-2,LOG:13)
Block(1,79,-1,LOG:13)
Block(1,79,0,LOG:13)
Block(1,79,1,LEAVES:14)
Block(1,79,2,LEAVES:13)
Block(1,80,-4,LEAVES:14)
Block(1,80,-1,LEAVES:14)
Block(1,81,-3,LEAVES:14)
Block(1,82,-3,LEAVES:14)
Block(2,-14,4,LOG:13)
Block(2,-13,5,LOG_2:13)
Block(2,-9,1,LOG_2:13)
Block(2,-8,-2,LOG:13)
Block(2,-8,1,LOG_2:13)
Block(2,-7,-5,LOG_2:13)
Block(2,-7,-4,LOG_2:13)
Block(2,-7,-3,LOG:13)
Block(2,-7,-2,LOG:13)
Block(2,-7,-1,LOG:13)
Block(2,-6,-5,LOG_2:13)
Block(2,-6,-4,LOG:13)
Block(2,-6,-3,LOG:13)
Block(2,-6,-2,LOG_2:13)
Block(2,-5,-4,LOG:13)
Block(2,-5,-3,LOG:13)
Block(2,-5,-2,LOG_2:13)
Block(2,-5,-1,LOG_2:13)
Block(2,-5,0,LOG:13)
Block(2,-5,1,LOG:13)
Block(2,-4,-4,LOG:13)
Block(2,-4,-3,LOG:13)
Block(2,-4,-2,LOG_2:13)
Block(2,-4,-1,LOG_2:13)
Block(2,-4,0,LOG:13)
Block(2,-4,1,LOG:13)
Block(2,-3,-3,LOG_2:13)
Block(2,-3,-2,LOG_2:13)
Block(2,-3,-1,LOG_2:13)
Block(2,-3,0,LOG:13)
Block(2,-3,1,LOG:13)
Block(2,-2,-3,LOG_2:13)
Block(2,-2,-2,LOG_2:13)
Block(2,-2,-1,LOG_2:13)
Block(2,-2,0,LOG_2:13)
Block(2,-2,1,LOG_2:13)
Block(2,-1,-3,LOG_2:13)
Block(2,-1,-2,LOG_2:13)
Block(2,-1,-1,LOG_2:13)
Block(2,-1,0,LOG_2:13)
Block(2,-1,1,LOG_2:13)
Block(2,0,-3,LOG_2:13)
Block(2,0,-2,LOG_2:13)
Block(2,0,-1,LOG_2:13)
Block(2,0,0,LOG_2:13)
Block(2,1,-3,LOG_2:13)
Block(2,1,-2,LOG_2:13)
Block(2,1,-1,LOG_2:13)
Block(2,1,0,LOG_2:13)
Block(2,1,1,LOG_2:13)
Block(2,2,-3,LOG_2:13)
Block(2,2,-2,LOG_2:13)
Block(2,2,-1,LOG_2:13)
Block(2,2,0,LOG_2:13)
Block(2,2,1,LOG_2:13)
Block(2,3,-3,LOG_2:13)
Block(2,3,-2,LOG_2:13)
Block(2,3,-1,LOG:13)
Block(2,3,0,LOG:13)
Block(2,3,1,LOG_2:13)
Block(2,3,2,LOG_2:13)
Block(2,4,-3,LOG_2:13)
Block(2,4,-2,LOG_2:13)
Block(2,4,-1,LOG:13)
Block(2,4,0,LOG_2:13)
Block(2,4,1,LOG_2:13)
Block(2,4,2,LOG_2:13)
Block(2,5,-3,LOG_2:13)
Block(2,5,-2,LOG_2:13)
Block(2,5,-1,LOG_2:13)
Block(2,5,0,LOG_2:13)
Block(2,5,1,LOG:13)
Block(2,5,2,LOG:13)
Block(2,6,-3,LOG_2:13)
Block(2,6,-2,LOG_2:13)
Block(2,6,-1,LOG_2:13)
Block(2,6,0,LOG:13)
Block(2,6,1,LOG:13)
Block(2,6,2,LOG:13)
Block(2,7,-3,LOG_2:13)
Block(2,7,-2,LOG_2:13)
Block(2,7,-1,LOG_2:13)
Block(2,7,0,LOG:13)
Block(2,7,1,LOG:13)
Block(2,7,2,LOG:13)
Block(2,8,-3,LOG_2:13)
Block(2,8,-2,LOG_2:13)
Block(2,8,-1,LOG_2:13)
Block(2,8,0,LOG:13)
Block(2,8,1,LOG:13)
Block(2,8,2,LOG:13)
Block(2,9,-3,LOG:13)
Block(2,9,-2,LOG_2:13)
Block(2,9,-1,LOG_2:13)
Block(2,9,0,LOG_2:13)
Block(2,9,1,LOG_2:13)
Block(2,9,2,LOG:13)
Block(2,10,-3,LOG:13)
Block(2,10,-2,LOG:13)
Block(2,10,-1,LOG:13)
Block(2,10,0,LOG_2:13)
Block(2,10,1,LOG_2:13)
Block(2,10,2,LOG:13)
Block(2,11,-3,LOG:13)
Block(2,11,-2,LOG:13)
Block(2,11,-1,LOG:13)
Block(2,11,0,LOG_2:13)
Block(2,11,1,LOG_2:13)
Block(2,11,2,LOG:13)
Block(2,12,-3,LOG:13)
Block(2,12,-2,LOG_2:13)
Block(2,12,-1,LOG_2:13)
Block(2,12,0,LOG_2:13)
Block(2,12,1,LOG_2:13)
Block(2,12,2,LOG:13)
Block(2,13,-3,LOG_2:13)
Block(2,13,-2,LOG_2:13)
Block(2,13,-1,LOG_2:13)
Block(2,13,0,LOG:13)
Block(2,13,1,LOG:13)
Block(2,13,2,LOG:13)
Block(2,14,-3,LOG:13)
Block(2,14,-2,LOG:13)
Block(2,14,-1,LOG:13)
Block(2,14,0,LOG:13)
Block(2,14,1,LOG:13)
Block(2,14,2,LOG:13)
Block(2,15,-3,LOG:13)
Block(2,15,-2,LOG:13)
Block(2,15,-1,LOG:13)
Block(2,15,0,LOG:13)
Block(2,15,1,LOG:13)
Block(2,15,2,LOG_2:13)
Block(2,16,-3,LOG:13)
Block(2,16,-2,LOG:13)
Block(2,16,-1,LOG:13)
Block(2,16,0,LOG:13)
Block(2,16,1,LOG:13)
Block(2,16,2,LOG_2:13)
Block(2,17,-3,LOG_2:13)
Block(2,17,-2,LOG:13)
Block(2,17,-1,LOG:13)
Block(2,17,0,LOG:13)
Block(2,17,1,LOG:13)
Block(2,17,2,LOG_2:13)
Block(2,18,-2,LOG:13)
Block(2,18,-1,LOG:13)
Block(2,18,0,LOG:13)
Block(2,18,1,LOG:13)
Block(2,18,2,LOG_2:13)
Block(2,19,-2,LOG_2:13)
Block(2,19,-1,LOG:13)
Block(2,19,0,LOG:13)
Block(2,19,1,LOG:13)
Block(2,19,2,LOG:13)
Block(2,20,-2,LOG_2:13)
Block(2,20,-1,LOG_2:13)
Block(2,20,0,LOG:13)
Block(2,20,1,LOG_2:13)
Block(2,20,2,LOG:13)
Block(2,21,-2,LOG_2:13)
Block(2,21,-1,LOG_2:13)
Block(2,21,0,LOG_2:13)
Block(2,21,1,LOG_2:13)
Block(2,21,2,LOG:13)
Block(2,22,-1,LOG:13)
Block(2,22,0,LOG:13)
Block(2,22,1,LOG_2:13)
Block(2,22,2,LOG_2:13)
Block(2,23,-1,LOG:13)
Block(2,23,0,LOG:13)
Block(2,23,1,LOG_2:13)
Block(2,23,2,LOG_2:13)
Block(2,24,-1,LOG:13)
Block(2,24,0,LOG:13)
Block(2,24,1,LOG:13)
Block(2,24,2,LOG_2:13)
Block(2,25,-11,LEAVES:14)
Block(2,25,-1,LOG_2:13)
Block(2,25,0,LOG:13)
Block(2,25,1,LOG:13)
Block(2,25,2,LOG_2:13)
Block(2,26,-10,LEAVES:14)
Block(2,26,-8,LEAVES:13)
Block(2,26,-1,LOG_2:13)
Block(2,26,0,LOG:13)
Block(2,26,1,LOG:13)
Block(2,26,2,LOG_2:13)
Block(2,27,-9,LEAVES:13)
Block(2,27,-2,LOG_2:13)
Block(2,27,-1,LOG_2:13)
Block(2,27,0,LOG:13)
Block(2,27,1,LOG:13)
Block(2,27,2,LOG_2:13)
Block(2,28,-8,LEAVES:14)
Block(2,28,-2,LOG:13)
Block(2,28,-1,LOG:13)
Block(2,28,0,LOG:13)
Block(2,28,1,LOG_2:13)
Block(2,28,2,LOG_2:13)
Block(2,29,-2,LOG_2:13)
Block(2,29,-1,LOG:13)
Block(2,29,0,LOG_2:13)
Block(2,29,1,LOG_2:13)
Block(2,29,2,LOG_2:13)
Block(2,30,-2,LOG_2:13)
Block(2,30,-1,LOG:13)
Block(2,30,0,LOG_2:13)
Block(2,30,1,LOG_2:13)
Block(2,30,2,LOG_2:13)
Block(2,31,-2,LOG:13)
Block(2,31,-1,LOG:13)
Block(2,31,0,LOG_2:13)
Block(2,31,1,LOG_2:13)
Block(2,31,2,LOG_2:13)
Block(2,32,-2,LOG:13)
Block(2,32,-1,LOG:13)
Block(2,32,0,LOG_2:13)
Block(2,32,1,LOG_2:13)
Block(2,32,2,LOG:13)
Block(2,33,-2,LOG:13)
Block(2,33,-1,LOG_2:13)
Block(2,33,0,LOG_2:13)
Block(2,33,1,LOG_2:13)
Block(2,33,2,LOG:13)
Block(2,34,-2,LOG_2:13)
Block(2,34,-1,LOG_2:13)
Block(2,34,0,LOG_2:13)
Block(2,34,1,LOG_2:13)
Block(2,34,2,LOG_2:13)
Block(2,35,-2,LOG_2:13)
Block(2,35,-1,LOG_2:13)
Block(2,35,0,LOG_2:13)
Block(2,35,1,LOG_2:13)
Block(2,35,2,LOG_2:13)
Block(2,36,-2,LOG:13)
Block(2,36,-1,LOG:13)
Block(2,36,0,LOG:13)
Block(2,36,1,LOG:13)
Block(2,36,2,LOG:13)
Block(2,37,-2,LOG:13)
Block(2,37,-1,LOG:13)
Block(2,37,0,LOG:13)
Block(2,37,1,LOG:13)
Block(2,37,2,LOG:13)
Block(2,38,-2,LOG:13)
Block(2,38,-1,LOG:13)
Block(2,38,0,LOG:13)
Block(2,38,1,LOG:13)
Block(2,39,-2,LOG:13)
Block(2,39,-1,LOG:13)
Block(2,39,0,LOG:13)
Block(2,39,1,LOG:13)
Block(2,40,-2,LOG:13)
Block(2,40,-1,LOG:13)
Block(2,40,0,LOG:13)
Block(2,40,1,LOG:13)
Block(2,41,-2,LOG:13)
Block(2,41,-1,LOG:13)
Block(2,41,0,LOG:13)
Block(2,41,1,LOG:13)
Block(2,42,-2,LOG:13)
Block(2,42,-1,LOG:13)
Block(2,42,0,LOG:13)
Block(2,42,1,LOG:13)
Block(2,42,2,LOG:13)
Block(2,43,-2,LOG:13)
Block(2,43,-1,LOG:13)
Block(2,43,0,LOG:13)
Block(2,43,1,LOG:13)
Block(2,43,2,LOG:13)
Block(2,43,6,LEAVES:13)
Block(2,43,7,LEAVES:13)
Block(2,44,-2,LOG:13)
Block(2,44,-1,LOG:13)
Block(2,44,0,LOG:13)
Block(2,44,1,LOG:13)
Block(2,44,2,LOG:13)
Block(2,44,3,LOG:13)
Block(2,44,9,LEAVES:14)
Block(2,44,10,LEAVES:14)
Block(2,45,-2,LOG:13)
Block(2,45,-1,LOG:13)
Block(2,45,0,LOG:13)
Block(2,45,1,LOG:13)
Block(2,45,6,LEAVES:14)
Block(2,45,7,LEAVES:14)
Block(2,45,8,LOG:13)
Block(2,45,10,LEAVES:14)
Block(2,46,-2,LOG:13)
Block(2,46,-1,LOG:13)
Block(2,46,0,LOG:13)
Block(2,46,1,LOG:13)
Block(2,46,6,LEAVES:14)
Block(2,46,9,LEAVES:14)
Block(2,46,10,LEAVES:14)
Block(2,47,-2,LOG:13)
Block(2,47,-1,LOG:13)
Block(2,47,0,LOG:13)
Block(2,47,1,LOG:13)
Block(2,47,10,LEAVES:14)
Block(2,47,11,LEAVES:14)
Block(2,48,-2,LOG:13)
Block(2,48,-1,LOG:13)
Block(2,48,0,LOG:13)
Block(2,48,1,LOG:13)
Block(2,48,7,LEAVES:13)
Block(2,48,9,LEAVES:14)
Block(2,48,10,LOG:13)
Block(2,49,-1,LOG:13)
Block(2,49,0,LOG:13)
Block(2,49,1,LOG:13)
Block(2,49,9,LEAVES:13)
Block(2,50,-1,LOG:13)
Block(2,50,0,LOG:13)
Block(2,50,1,LOG:13)
Block(2,51,-2,LOG:13)
Block(2,51,-1,LOG:13)
Block(2,51,0,LOG:13)
Block(2,51,1,LOG:13)
Block(2,52,-2,LOG:13)
Block(2,52,-1,LOG:13)
Block(2,52,0,LOG:13)
Block(2,52,1,LOG:13)
Block(2,53,-9,LEAVES:13)
Block(2,53,-1,LOG:13)
Block(2,53,0,LOG:13)
Block(2,53,1,LOG:13)
Block(2,54,-10,LEAVES:13)
Block(2,54,-9,LEAVES:13)
Block(2,54,-1,LOG:13)
Block(2,54,0,LOG:13)
Block(2,54,1,LOG:13)
Block(2,54,6,LEAVES:14)
Block(2,55,-9,LEAVES:13)
Block(2,55,-7,LEAVES:14)
Block(2,55,-6,LEAVES:14)
Block(2,55,-1,LOG:13)
Block(2,55,0,LOG:13)
Block(2,55,1,LOG:13)
Block(2,55,5,LEAVES:14)
Block(2,55,8,LEAVES:13)
Block(2,56,-10,LEAVES:13)
Block(2,56,-9,LEAVES:14)
Block(2,56,-7,LOG:13)
Block(2,56,-6,LEAVES:14)
Block(2,56,-1,LOG:13)
Block(2,56,0,LOG:13)
Block(2,56,1,LOG:13)
Block(2,56,5,LEAVES:14)
Block(2,56,8,LEAVES:13)
Block(2,57,-10,LEAVES:13)
Block(2,57,-7,LOG:13)
Block(2,57,-6,LEAVES:14)
Block(2,57,-1,LOG:13)
Block(2,57,0,LOG:13)
Block(2,58,-8,LEAVES:14)
Block(2,58,-1,LOG:13)
Block(2,58,0,LOG:13)
Block(2,59,-9,LEAVES:14)
Block(2,59,-8,LEAVES:14)
Block(2,59,-1,LOG:13)
Block(2,59,0,LOG:13)
Block(2,59,5,LEAVES:13)
Block(2,60,-1,LOG:13)
Block(2,60,0,LOG:13)
Block(2,61,-2,LOG:13)
Block(2,61,-1,LOG:13)
Block(2,61,0,LOG:13)
Block(2,62,-1,LOG:13)
Block(2,62,0,LOG:13)
Block(2,63,-6,LEAVES:14)
Block(2,63,-5,LEAVES:14)
Block(2,65,-8,LEAVES:14)
Block(2,65,-7,LEAVES:14)
Block(2,66,-6,LOG:13)
Block(2,66,-5,LEAVES:13)
Block(2,66,-4,LEAVES:13)
Block(2,67,2,LOG:13)
Block(2,68,-1,LOG:13)
Block(2,68,3,LOG:13)
Block(2,68,4,LOG:13)
Block(2,68,5,LOG:13)
Block(2,69,-1,LOG:13)
Block(2,69,5,LOG:13)
Block(2,70,-1,LOG:13)
Block(2,70,5,LOG:13)
Block(2,70,6,LOG:13)
Block(2,71,-1,LOG:13)
Block(2,71,7,LEAVES:14)
Block(2,71,8,LEAVES:14)
Block(2,72,-6,LEAVES:13)
Block(2,73,-6,LEAVES:14)
Block(2,73,-5,LOG:13)
Block(2,75,2,LOG:13)
Block(2,76,1,LEAVES:14)
Block(2,76,2,LOG:13)
Block(2,76,3,LOG:13)
Block(2,77,-2,LEAVES:13)
Block(2,77,-1,LEAVES:14)
Block(2,77,0,LEAVES:14)
Block(2,77,2,LEAVES:14)
Block(2,77,3,LOG:13)
Block(2,78,-1,LEAVES:14)
Block(2,78,0,LEAVES:14)
Block(2,78,1,LEAVES:14)
Block(2,78,3,LEAVES:14)
Block(2,79,-3,LEAVES:14)
Block(2,79,-2,LOG:13)
Block(2,80,-2,LEAVES:14)
Block(2,80,-1,LEAVES:14)
Block(2,80,0,LEAVES:14)
Block(2,81,0,LEAVES:14)
Block(2,81,1,LEAVES:13)
Block(3,-13,5,LOG_2:13)
Block(3,-12,5,LOG_2:13)
Block(3,-11,5,LOG_2:13)
Block(3,-10,1,LOG:13)
Block(3,-9,1,LOG_2:13)
Block(3,-9,6,LOG_2:13)
Block(3,-6,-5,LOG_2:13)
Block(3,-6,-4,LOG_2:13)
Block(3,-6,-3,LOG_2:13)
Block(3,-6,-2,LOG_2:13)
Block(3,-6,1,LOG_2:13)
Block(3,-6,2,LOG_2:13)
Block(3,-6,3,LOG_2:13)
Block(3,-5,-5,LOG_2:13)
Block(3,-5,-4,LOG:13)
Block(3,-5,-3,LOG:13)
Block(3,-5,-2,LOG_2:13)
Block(3,-5,0,LOG_2:13)
Block(3,-5,1,LOG_2:13)
Block(3,-5,2,LOG_2:13)
Block(3,-5,3,LOG_2:13)
Block(3,-4,-5,LOG_2:13)
Block(3,-4,-4,LOG:13)
Block(3,-4,-3,LOG:13)
Block(3,-4,-2,LOG_2:13)
Block(3,-4,0,LOG_2:13)
Block(3,-4,1,LOG_2:13)
Block(3,-4,2,LOG_2:13)
Block(3,-4,3,LOG_2:13)
Block(3,-3,-5,LOG:13)
Block(3,-3,-4,LOG:13)
Block(3,-3,-3,LOG:13)
Block(3,-3,-2,LOG_2:13)
Block(3,-3,0,LOG_2:13)
Block(3,-3,1,LOG_2:13)
Block(3,-3,2,LOG_2:13)
Block(3,-3,3,LOG_2:13)
Block(3,-2,-5,LOG:13)
Block(3,-2,-4,LOG:13)
Block(3,-2,-3,LOG:13)
Block(3,-2,-2,LOG_2:13)
Block(3,-2,0,LOG_2:13)
Block(3,-2,1,LOG_2:13)
Block(3,-2,2,LOG_2:13)
Block(3,-2,3,LOG_2:13)
Block(3,-1,-5,LOG:13)
Block(3,-1,-4,LOG_2:13)
Block(3,-1,-3,LOG_2:13)
Block(3,-1,-2,LOG_2:13)
Block(3,-1,0,LOG_2:13)
Block(3,-1,1,LOG_2:13)
Block(3,-1,2,LOG_2:13)
Block(3,-1,3,LOG_2:13)
Block(3,0,-4,LOG_2:13)
Block(3,0,-3,LOG_2:13)
Block(3,0,-2,LOG_2:13)
Block(3,0,1,LOG_2:13)
Block(3,0,2,LOG_2:13)
Block(3,1,-4,LOG_2:13)
Block(3,1,-3,LOG_2:13)
Block(3,1,-2,LOG_2:13)
Block(3,1,2,LOG_2:13)
Block(3,2,-4,LOG_2:13)
Block(3,2,-3,LOG_2:13)
Block(3,2,-2,LOG_2:13)
Block(3,2,0,LOG:13)
Block(3,2,1,LOG:13)
Block(3,2,2,LOG_2:13)
Block(3,3,-4,LOG:13)
Block(3,3,-3,LOG_2:13)
Block(3,3,-2,LOG_2:13)
Block(3,3,0,LOG:13)
Block(3,3,1,LOG:13)
Block(3,3,2,LOG_2:13)
Block(3,4,-3,LOG_2:13)
Block(3,4,-2,LOG_2:13)
Block(3,4,0,LOG:13)
Block(3,4,1,LOG:13)
Block(3,4,2,LOG_2:13)
Block(3,5,-3,LOG_2:13)
Block(3,5,-2,LOG_2:13)
Block(3,5,0,LOG:13)
Block(3,5,1,LOG:13)
Block(3,5,2,LOG_2:13)
Block(3,6,-4,LOG_2:13)
Block(3,6,-3,LOG_2:13)
Block(3,6,-2,LOG_2:13)
Block(3,6,0,LOG:13)
Block(3,6,1,LOG:13)
Block(3,6,2,LOG:13)
Block(3,7,-3,LOG_2:13)
Block(3,7,-2,LOG_2:13)
Block(3,7,0,LOG:13)
Block(3,7,1,LOG:13)
Block(3,7,2,LOG:13)
Block(3,8,-3,LOG_2:13)
Block(3,8,-2,LOG_2:13)
Block(3,8,0,LOG:13)
Block(3,8,1,LOG:13)
Block(3,8,2,LOG_2:13)
Block(3,9,-4,LOG_2:13)
Block(3,9,-3,LOG_2:13)
Block(3,9,-2,LOG_2:13)
Block(3,9,0,LOG_2:13)
Block(3,9,1,LOG_2:13)
Block(3,9,2,LOG_2:13)
Block(3,10,-3,LOG:13)
Block(3,10,-2,LOG:13)
Block(3,10,0,LOG_2:13)
Block(3,10,1,LOG_2:13)
Block(3,10,2,LOG_2:13)
Block(3,11,-3,LOG_2:13)
Block(3,11,-2,LOG_2:13)
Block(3,11,0,LOG_2:13)
Block(3,11,1,LOG_2:13)
Block(3,11,2,LOG_2:13)
Block(3,12,-3,LOG_2:13)
Block(3,12,-2,LOG_2:13)
Block(3,12,0,LOG_2:13)
Block(3,12,1,LOG_2:13)
Block(3,12,2,LOG_2:13)
Block(3,13,-3,LOG_2:13)
Block(3,13,-2,LOG_2:13)
Block(3,13,0,LOG:13)
Block(3,13,1,LOG:13)
Block(3,13,2,LOG:13)
Block(3,14,-3,LOG:13)
Block(3,14,-2,LOG_2:13)
Block(3,14,0,LOG:13)
Block(3,14,1,LOG:13)
Block(3,14,2,LOG:13)
Block(3,15,-3,LOG:13)
Block(3,15,-2,LOG:13)
Block(3,15,0,LOG:13)
Block(3,15,1,LOG:13)
Block(3,15,2,LOG_2:13)
Block(3,16,-3,LOG:13)
Block(3,16,-2,LOG:13)
Block(3,16,1,LOG_2:13)
Block(3,16,2,LOG_2:13)
Block(3,17,-3,LOG_2:13)
Block(3,17,-2,LOG:13)
Block(3,17,1,LOG_2:13)
Block(3,17,2,LOG_2:13)
Block(3,18,-4,LOG_2:13)
Block(3,18,-3,LOG:13)
Block(3,18,1,LOG_2:13)
Block(3,18,2,LOG_2:13)
Block(3,19,-4,LOG_2:13)
Block(3,19,-3,LOG_2:13)
Block(3,19,0,LOG_2:13)
Block(3,19,1,LOG_2:13)
Block(3,19,2,LOG_2:13)
Block(3,20,-1,LOG_2:13)
Block(3,20,0,LOG_2:13)
Block(3,20,1,LOG_2:13)
Block(3,20,2,LOG_2:13)
Block(3,21,0,LOG_2:13)
Block(3,21,1,LOG_2:13)
Block(3,21,2,LOG_2:13)
Block(3,22,0,LOG:13)
Block(3,22,1,LOG_2:13)
Block(3,22,2,LOG_2:13)
Block(3,23,-8,LEAVES:13)
Block(3,23,-7,LEAVES:13)
Block(3,23,-1,LOG:13)
Block(3,23,0,LOG:13)
Block(3,23,1,LOG_2:13)
Block(3,23,2,LOG_2:13)
Block(3,24,0,LOG:13)
Block(3,24,1,LOG_2:13)
Block(3,24,2,LOG_2:13)
Block(3,25,-11,LEAVES:14)
Block(3,25,-10,LEAVES:13)
Block(3,25,-8,LEAVES:13)
Block(3,25,-7,LEAVES:13)
Block(3,25,-1,LOG_2:13)
Block(3,25,0,LOG:13)
Block(3,25,1,LOG_2:13)
Block(3,25,2,LOG_2:13)
Block(3,26,-1,LOG_2:13)
Block(3,26,0,LOG_2:13)
Block(3,26,1,LOG_2:13)
Block(3,26,2,LOG_2:13)
Block(3,27,-10,LEAVES:14)
Block(3,27,-9,LOG:13)
Block(3,27,-8,LOG:13)
Block(3,27,-1,LOG_2:13)
Block(3,27,0,LOG_2:13)
Block(3,27,1,LOG_2:13)
Block(3,27,2,LOG_2:13)
Block(3,28,-11,LEAVES:14)
Block(3,28,-9,LEAVES:14)
Block(3,28,-8,LEAVES:14)
Block(3,28,0,LOG:13)
Block(3,28,1,LOG:13)
Block(3,28,2,LOG:13)
Block(3,29,0,LOG:13)
Block(3,29,1,LOG_2:13)
Block(3,29,2,LOG:13)
Block(3,30,0,LOG:13)
Block(3,30,1,LOG_2:13)
Block(3,30,2,LOG_2:13)
Block(3,31,0,LOG:13)
Block(3,31,1,LOG_2:13)
Block(3,31,2,LOG:13)
Block(3,32,-1,LOG:13)
Block(3,32,0,LOG:13)
Block(3,32,1,LOG:13)
Block(3,32,2,LOG:13)
Block(3,33,-1,LOG:13)
Block(3,33,0,LOG_2:13)
Block(3,33,1,LOG_2:13)
Block(3,34,-1,LOG_2:13)
Block(3,34,0,LOG_2:13)
Block(3,34,1,LOG_2:13)
Block(3,35,-1,LOG:13)
Block(3,35,0,LOG_2:13)
Block(3,35,1,LOG_2:13)
Block(3,36,-1,LOG:13)
Block(3,36,0,LOG:13)
Block(3,36,1,LOG_2:13)
Block(3,37,-1,LOG:13)
Block(3,37,0,LOG:13)
Block(3,37,1,LOG:13)
Block(3,38,-1,LOG:13)
Block(3,38,0,LOG:13)
Block(3,38,1,LOG:13)
Block(3,39,-1,LOG:13)
Block(3,39,0,LOG:13)
Block(3,39,1,LOG:13)
Block(3,40,-3,LOG:13)
Block(3,40,-2,LOG:13)
Block(3,40,-1,LOG:13)
Block(3,40,0,LOG:13)
Block(3,40,1,LOG:13)
Block(3,41,-2,LOG:13)
Block(3,41,-1,LOG:13)
Block(3,41,0,LOG:13)
Block(3,41,1,LOG:13)
Block(3,42,-2,LOG:13)
Block(3,42,-1,LOG:13)
Block(3,42,0,LOG:13)
Block(3,42,3,LOG:13)
Block(3,42,7,LEAVES:14)
Block(3,43,-1,LOG:13)
Block(3,43,0,LOG:13)
Block(3,43,3,LOG:13)
Block(3,43,4,LOG:13)
Block(3,43,5,LOG:13)
Block(3,43,8,LEAVES:14)
Block(3,44,-1,LOG:13)
Block(3,44,0,LOG:13)
Block(3,44,1,LOG:13)
Block(3,44,3,LOG:13)
Block(3,44,4,LOG:13)
Block(3,44,7,LOG:13)
Block(3,44,8,LOG:13)
Block(3,44,9,LEAVES:14)
Block(3,45,0,LOG:13)
Block(3,45,8,LOG:13)
Block(3,45,9,LEAVES:14)
Block(3,45,10,LEAVES:14)
Block(3,46,10,LEAVES:14)
Block(3,47,9,LEAVES:14)
Block(3,47,10,LOG:13)
Block(3,47,11,LOG:13)
Block(3,48,7,LEAVES:13)
Block(3,48,8,LEAVES:13)
Block(3,48,10,LOG:13)
Block(3,49,1,LOG:13)
Block(3,49,2,LOG:13)
Block(3,51,-3,LOG:13)
Block(3,51,-2,LOG:13)
Block(3,51,-1,LOG:13)
Block(3,51,5,LEAVES:13)
Block(3,52,-2,LOG:13)
Block(3,52,-1,LOG:13)
Block(3,52,5,LEAVES:14)
Block(3,52,6,LEAVES:13)
Block(3,53,-9,LEAVES:13)
Block(3,53,-8,LEAVES:13)
Block(3,53,-7,LEAVES:13)
Block(3,53,-1,LOG:13)
Block(3,54,-10,LEAVES:13)
Block(3,54,-8,LEAVES:13)
Block(3,54,-7,LEAVES:14)
Block(3,54,6,LEAVES:14)
Block(3,54,7,LEAVES:14)
Block(3,55,-9,LOG:13)
Block(3,55,-8,LOG:13)
Block(3,55,-7,LOG:13)
Block(3,55,-6,LEAVES:14)
Block(3,55,4,LEAVES:14)
Block(3,55,5,LEAVES:14)
Block(3,56,-10,LEAVES:13)
Block(3,56,-7,LOG:13)
Block(3,56,2,LOG:13)
Block(3,56,5,LEAVES:13)
Block(3,57,2,LOG:13)
Block(3,57,3,LEAVES:13)
Block(3,58,-7,LEAVES:13)
Block(3,58,2,LEAVES:13)
Block(3,58,5,LEAVES:13)
Block(3,58,6,LEAVES:13)
Block(3,59,4,LEAVES:13)
Block(3,60,3,LEAVES:14)
Block(3,60,4,LEAVES:13)
Block(3,61,2,LEAVES:14)
Block(3,61,3,LEAVES:14)
Block(3,62,-1,LOG:13)
Block(3,62,0,LOG:13)
Block(3,63,-1,LOG:13)
Block(3,68,4,LOG:13)
Block(3,68,5,LEAVES:14)
Block(3,68,6,LEAVES:14)
Block(3,69,3,LEAVES:14)
Block(3,69,4,LEAVES:14)
Block(3,70,5,LEAVES:14)
Block(3,70,6,LEAVES:14)
Block(3,71,-5,LEAVES:13)
Block(3,71,-2,LEAVES:14)
Block(3,71,-1,LOG:13)
Block(3,71,4,LEAVES:14)
Block(3,71,6,LEAVES:14)
Block(3,72,-8,LEAVES:13)
Block(3,72,-7,LEAVES:13)
Block(3,72,-1,LOG:13)
Block(3,73,-8,LEAVES:13)
Block(3,73,-5,LOG:13)
Block(3,73,-4,LEAVES:13)
Block(3,73,-1,LEAVES:13)
Block(3,73,0,LEAVES:13)
Block(3,74,-6,LEAVES:14)
Block(3,74,-5,LOG:13)
Block(3,75,-7,LEAVES:14)
Block(3,75,-6,LEAVES:14)
Block(3,75,3,LEAVES:14)
Block(3,76,2,LEAVES:14)
Block(3,76,3,LOG:13)
Block(3,77,0,LEAVES:14)
Block(3,77,3,LOG:13)
Block(3,78,0,LEAVES:14)
Block(3,78,1,LEAVES:13)
Block(3,78,3,LOG:13)
Block(3,78,4,LOG:13)
Block(3,79,-2,LEAVES:14)
Block(3,79,-1,LEAVES:14)
Block(3,79,3,LOG:13)
Block(3,79,4,LEAVES:14)
Block(3,80,-3,LEAVES:14)
Block(3,80,-2,LOG:13)
Block(3,80,-1,LEAVES:14)
Block(3,80,0,LEAVES:14)
Block(3,80,1,LEAVES:13)
Block(3,80,4,LEAVES:13)
Block(3,81,-1,LEAVES:14)
Block(3,81,1,LEAVES:13)
Block(3,82,-1,LEAVES:14)
Block(4,-12,-6,LOG_2:13)
Block(4,-11,-6,LOG_2:13)
Block(4,-11,-5,LOG_2:13)
Block(4,-11,5,LOG_2:13)
Block(4,-11,8,LOG:13)
Block(4,-11,9,LOG:13)
Block(4,-10,-11,LOG:13)
Block(4,-10,1,LOG_2:13)
Block(4,-10,2,LOG:13)
Block(4,-10,5,LOG_2:13)
Block(4,-10,6,LOG_2:13)
Block(4,-10,7,LOG_2:13)
Block(4,-10,8,LOG_2:13)
Block(4,-9,6,LOG_2:13)
Block(4,-8,6,LOG_2:13)
Block(4,-6,-5,LOG_2:13)
Block(4,-6,-4,LOG_2:13)
Block(4,-6,-3,LOG_2:13)
Block(4,-6,2,LOG:13)
Block(4,-6,3,LOG:13)
Block(4,-6,4,LOG_2:13)
Block(4,-5,-5,LOG_2:13)
Block(4,-5,-4,LOG:13)
Block(4,-5,-3,LOG:13)
Block(4,-5,-2,LOG_2:13)
Block(4,-5,2,LOG_2:13)
Block(4,-5,3,LOG_2:13)
Block(4,-5,4,LOG_2:13)
Block(4,-5,5,LOG_2:13)
Block(4,-4,-5,LOG_2:13)
Block(4,-4,-4,LOG:13)
Block(4,-4,-3,LOG:13)
Block(4,-4,-2,LOG:13)
Block(4,-4,2,LOG_2:13)
Block(4,-4,3,LOG_2:13)
Block(4,-4,4,LOG_2:13)
Block(4,-3,-6,LOG:13)
Block(4,-3,-5,LOG:13)
Block(4,-3,-4,LOG:13)
Block(4,-3,-3,LOG:13)
Block(4,-3,-2,LOG:13)
Block(4,-3,2,LOG_2:13)
Block(4,-3,3,LOG_2:13)
Block(4,-3,4,LOG_2:13)
Block(4,-2,-6,LOG:13)
Block(4,-2,-5,LOG:13)
Block(4,-2,-4,LOG:13)
Block(4,-2,-3,LOG:13)
Block(4,-2,-2,LOG_2:13)
Block(4,-2,2,LOG_2:13)
Block(4,-2,3,LOG_2:13)
Block(4,-1,-5,LOG:13)
Block(4,-1,-4,LOG_2:13)
Block(4,-1,-3,LOG_2:13)
Block(4,-1,-2,LOG_2:13)
Block(4,-1,2,LOG_2:13)
Block(4,-1,3,LOG:13)
Block(4,0,-5,LOG:13)
Block(4,0,-4,LOG_2:13)
Block(4,0,-3,LOG_2:13)
Block(4,0,-2,LOG_2:13)
Block(4,0,2,LOG:13)
Block(4,0,3,LOG:13)
Block(4,1,-5,LOG:13)
Block(4,1,-4,LOG:13)
Block(4,1,-3,LOG_2:13)
Block(4,1,-2,LOG_2:13)
Block(4,1,2,LOG:13)
Block(4,1,3,LOG:13)
Block(4,2,-5,LOG:13)
Block(4,2,-4,LOG:13)
Block(4,2,-3,LOG_2:13)
Block(4,2,-2,LOG_2:13)
Block(4,2,2,LOG_2:13)
Block(4,2,3,LOG_2:13)
Block(4,3,-5,LOG:13)
Block(4,3,-4,LOG:13)
Block(4,3,-3,LOG_2:13)
Block(4,3,2,LOG_2:13)
Block(4,3,3,LOG_2:13)
Block(4,4,-5,LOG_2:13)
Block(4,4,-4,LOG:13)
Block(4,4,-3,LOG:13)
Block(4,4,3,LOG_2:13)
Block(4,5,-4,LOG_2:13)
Block(4,5,-3,LOG_2:13)
Block(4,5,3,LOG_2:13)
Block(4,6,-4,LOG_2:13)
Block(4,6,-3,LOG_2:13)
Block(4,6,3,LOG_2:13)
Block(4,7,-4,LOG_2:13)
Block(4,7,-3,LOG_2:13)
Block(4,7,-2,LOG:13)
Block(4,7,3,LOG_2:13)
Block(4,8,-3,LOG_2:13)
Block(4,8,2,LOG_2:13)
Block(4,9,2,LOG_2:13)
Block(4,10,2,LOG_2:13)
Block(4,11,2,LOG_2:13)
Block(4,12,2,LOG:13)
Block(4,13,1,LOG:13)
Block(4,13,2,LOG:13)
Block(4,14,1,LOG:13)
Block(4,15,1,LOG:13)
Block(4,16,-3,LOG:13)
Block(4,16,1,LOG_2:13)
Block(4,17,-3,LOG:13)
Block(4,17,1,LOG_2:13)
Block(4,18,-4,LOG_2:13)
Block(4,18,-3,LOG:13)
Block(4,18,1,LOG_2:13)
Block(4,19,-7,LEAVES:13)
Block(4,19,-4,LOG_2:13)
Block(4,19,1,LOG_2:13)
Block(4,20,-7,LEAVES:13)
Block(4,20,-4,LOG_2:13)
Block(4,20,1,LOG_2:13)
Block(4,21,-4,LOG_2:13)
Block(4,21,1,LOG_2:13)
Block(4,22,1,LOG_2:13)
Block(4,23,-7,LEAVES:13)
Block(4,23,1,LOG:13)
Block(4,25,-8,LEAVES:13)
Block(4,26,-8,LEAVES:13)
Block(4,26,-7,LEAVES:13)
Block(4,26,-6,LEAVES:13)
Block(4,27,-8,LEAVES:13)
Block(4,27,-7,LOG:13)
Block(4,28,-11,LEAVES:14)
Block(4,28,-10,LEAVES:13)
Block(4,28,-9,LEAVES:13)
Block(4,28,-7,LOG_2:13)
Block(4,28,-6,LEAVES:14)
Block(4,31,-7,LEAVES:14)
Block(4,31,-6,LEAVES:14)
Block(4,33,-5,LEAVES:13)
Block(4,33,-4,LEAVES:13)
Block(4,34,-8,LEAVES:13)
Block(4,34,-7,LEAVES:13)
Block(4,38,0,LOG:13)
Block(4,39,-1,LOG:13)
Block(4,39,0,LOG:13)
Block(4,40,-3,LOG:13)
Block(4,40,-2,LOG:13)
Block(4,40,-1,LOG:13)
Block(4,40,0,LOG:13)
Block(4,41,-3,LOG:13)
Block(4,41,-2,LOG:13)
Block(4,41,-1,LOG:13)
Block(4,41,6,LEAVES:14)
Block(4,42,6,LEAVES:14)
Block(4,42,7,LOG:13)
Block(4,42,8,LOG:13)
Block(4,42,9,LEAVES:14)
Block(4,43,5,LOG:13)
Block(4,43,6,LOG:13)
Block(4,43,7,LOG:13)
Block(4,43,8,LEAVES:14)
Block(4,43,11,LEAVES:13)
Block(4,44,6,LOG:13)
Block(4,44,7,LOG:13)
Block(4,44,9,LEAVES:14)
Block(4,44,11,LEAVES:14)
Block(4,45,7,LEAVES:14)
Block(4,45,10,LEAVES:14)
Block(4,46,8,LEAVES:14)
Block(4,47,8,LEAVES:14)
Block(4,47,9,LEAVES:14)
Block(4,47,10,LOG:13)
Block(4,48,10,LEAVES:14)
Block(4,48,11,LEAVES:14)
Block(4,49,2,LOG:13)
Block(4,49,11,LEAVES:14)
Block(4,51,-12,LEAVES:14)
Block(4,51,-3,LOG:13)
Block(4,51,-2,LOG:13)
Block(4,52,-12,LEAVES:14)
Block(4,52,-4,LOG:13)
Block(4,52,-3,LOG:13)
Block(4,53,-10,LEAVES:13)
Block(4,53,-8,LEAVES:13)
Block(4,53,-7,LEAVES:14)
Block(4,53,7,LEAVES:13)
Block(4,54,-7,LOG:13)
Block(4,54,-6,LOG:13)
Block(4,54,6,LOG:13)
Block(4,54,7,LOG:13)
Block(4,54,8,LEAVES:13)
Block(4,55,-10,LOG:13)
Block(4,55,-9,LOG:13)
Block(4,55,-8,LEAVES:13)
Block(4,55,-7,LOG:13)
Block(4,55,4,LEAVES:13)
Block(4,55,6,LEAVES:13)
Block(4,56,-10,LEAVES:13)
Block(4,56,-9,LEAVES:13)
Block(4,56,-7,LEAVES:13)
Block(4,56,-6,LEAVES:14)
Block(4,56,6,LEAVES:13)
Block(4,57,-6,LEAVES:13)
Block(4,57,2,LOG:13)
Block(4,57,3,LOG:13)
Block(4,57,4,LEAVES:13)
Block(4,57,5,LEAVES:13)
Block(4,58,-8,LEAVES:13)
Block(4,58,-7,LEAVES:13)
Block(4,58,2,LEAVES:13)
Block(4,58,3,LOG:13)
Block(4,58,4,LOG:13)
Block(4,58,5,LOG:13)
Block(4,58,6,LOG:13)
Block(4,58,7,LEAVES:13)
Block(4,59,3,LOG:13)
Block(4,59,7,LEAVES:13)
Block(4,61,2,LEAVES:14)
Block(4,63,-1,LOG:13)
Block(4,67,6,LEAVES:14)
Block(4,68,3,LEAVES:13)
Block(4,68,4,LEAVES:14)
Block(4,68,6,LEAVES:14)
Block(4,69,4,LEAVES:14)
Block(4,70,-5,LEAVES:13)
Block(4,70,3,LEAVES:14)
Block(4,70,4,LEAVES:14)
Block(4,71,-5,LEAVES:13)
Block(4,71,-2,LEAVES:13)
Block(4,71,0,LEAVES:13)
Block(4,71,3,LEAVES:14)
Block(4,71,4,LEAVES:14)
Block(4,72,-1,LOG:13)
Block(4,72,0,LOG:13)
Block(4,73,-2,LOG:13)
Block(4,73,-1,LOG:13)
Block(4,73,0,LEAVES:13)
Block(4,74,-5,LEAVES:13)
Block(4,74,-2,LOG:13)
Block(4,74,-1,LOG:13)
Block(4,75,2,LEAVES:14)
Block(4,75,3,LEAVES:14)
Block(4,77,-1,LEAVES:14)
Block(4,77,0,LEAVES:14)
Block(4,77,1,LEAVES:14)
Block(4,78,1,LEAVES:13)
Block(4,78,2,LEAVES:13)
Block(4,78,3,LEAVES:14)
Block(4,78,4,LOG:13)
Block(4,79,-2,LEAVES:14)
Block(4,79,-1,LEAVES:14)
Block(4,79,0,LEAVES:14)
Block(4,79,1,LEAVES:13)
Block(4,79,2,LOG:13)
Block(4,80,-3,LEAVES:14)
Block(4,80,-1,LEAVES:14)
Block(4,81,-3,LEAVES:14)
Block(4,81,-2,LOG:13)
Block(4,81,-1,LOG:13)
Block(4,82,-1,LEAVES:13)
Block(5,-11,-5,LOG_2:13)
Block(5,-10,-11,LOG:13)
Block(5,-10,-10,LOG:13)
Block(5,-10,7,LOG:13)
Block(5,-9,6,LOG_2:13)
Block(5,-8,4,LOG:13)
Block(5,-8,5,LOG_2:13)
Block(5,-8,6,LOG_2:13)
Block(5,-7,-5,LOG:13)
Block(5,-7,3,LOG:13)
Block(5,-7,4,LOG:13)
Block(5,-7,5,LOG_2:13)
Block(5,-6,-6,LOG:13)
Block(5,-6,-5,LOG_2:13)
Block(5,-6,-4,LOG_2:13)
Block(5,-6,-3,LOG_2:13)
Block(5,-6,3,LOG:13)
Block(5,-6,4,LOG:13)
Block(5,-6,5,LOG_2:13)
Block(5,-5,-6,LOG_2:13)
Block(5,-5,-5,LOG_2:13)
Block(5,-5,-4,LOG_2:13)
Block(5,-5,-3,LOG_2:13)
Block(5,-5,-2,LOG_2:13)
Block(5,-5,2,LOG:13)
Block(5,-5,3,LOG:13)
Block(5,-5,4,LOG:13)
Block(5,-5,5,LOG_2:13)
Block(5,-4,-6,LOG:13)
Block(5,-4,-5,LOG:13)
Block(5,-4,-4,LOG:13)
Block(5,-4,-3,LOG:13)
Block(5,-4,-2,LOG_2:13)
Block(5,-4,2,LOG_2:13)
Block(5,-4,3,LOG:13)
Block(5,-4,4,LOG_2:13)
Block(5,-3,-6,LOG:13)
Block(5,-3,-5,LOG:13)
Block(5,-3,-4,LOG:13)
Block(5,-3,-3,LOG:13)
Block(5,-3,-2,LOG:13)
Block(5,-3,2,LOG_2:13)
Block(5,-3,3,LOG_2:13)
Block(5,-3,4,LOG_2:13)
Block(5,-2,-5,LOG:13)
Block(5,-2,-4,LOG_2:13)
Block(5,-2,-3,LOG_2:13)
Block(5,-2,-2,LOG_2:13)
Block(5,-2,2,LOG_2:13)
Block(5,-2,3,LOG:13)
Block(5,-2,4,LOG:13)
Block(5,-1,-5,LOG:13)
Block(5,-1,-4,LOG_2:13)
Block(5,-1,-3,LOG_2:13)
Block(5,-1,2,LOG:13)
Block(5,-1,3,LOG:13)
Block(5,0,-4,LOG_2:13)
Block(5,0,-3,LOG_2:13)
Block(5,1,-5,LOG:13)
Block(5,1,-4,LOG:13)
Block(5,1,-3,LOG_2:13)
Block(5,2,-5,LOG:13)
Block(5,2,-4,LOG:13)
Block(5,2,-3,LOG:13)
Block(5,3,-5,LOG:13)
Block(5,3,-4,LOG:13)
Block(5,3,-3,LOG:13)
Block(5,4,-4,LOG:13)
Block(5,4,-3,LOG:13)
Block(5,5,-3,LOG:13)
Block(5,19,-4,LOG_2:13)
Block(5,20,-7,LEAVES:14)
Block(5,21,-10,LEAVES:13)
Block(5,21,-9,LEAVES:13)
Block(5,21,-5,LOG:13)
Block(5,21,-4,LOG:13)
Block(5,22,-10,LEAVES:13)
Block(5,22,-9,LEAVES:13)
Block(5,22,-7,LEAVES:13)
Block(5,22,-6,LOG_2:13)
Block(5,22,-5,LOG_2:13)
Block(5,22,-4,LOG_2:13)
Block(5,23,-8,LEAVES:13)
Block(5,23,-5,LOG_2:13)
Block(5,24,-9,LEAVES:13)
Block(5,24,-8,LEAVES:13)
Block(5,25,-9,LEAVES:13)
Block(5,26,-8,LEAVES:13)
Block(5,26,-6,LEAVES:13)
Block(5,27,-7,LEAVES:13)
Block(5,28,-7,LOG:13)
Block(5,28,-6,LOG:13)
Block(5,28,-3,LEAVES:14)
Block(5,30,-2,LEAVES:14)
Block(5,31,-7,LEAVES:13)
Block(5,32,-8,LEAVES:13)
Block(5,32,-7,LEAVES:13)
Block(5,32,-6,LEAVES:13)
Block(5,33,-8,LEAVES:13)
Block(5,33,-7,LEAVES:13)
Block(5,33,-5,LEAVES:13)
Block(5,33,-4,LEAVES:13)
Block(5,34,-8,LEAVES:13)
Block(5,34,-5,LEAVES:13)
Block(5,41,-4,LOG:13)
Block(5,41,-3,LOG:13)
Block(5,41,9,LEAVES:14)
Block(5,42,8,LOG:13)
Block(5,42,9,LOG:13)
Block(5,42,10,LOG:13)
Block(5,44,7,LOG:13)
Block(5,44,9,LEAVES:13)
Block(5,44,10,LEAVES:14)
Block(5,45,9,LEAVES:13)
Block(5,46,8,LEAVES:13)
Block(5,46,9,LOG:13)
Block(5,46,10,LOG:13)
Block(5,47,10,LOG:13)
Block(5,47,12,LEAVES:14)
Block(5,48,10,LEAVES:14)
Block(5,49,3,LOG:13)
Block(5,50,3,LOG:13)
Block(5,51,4,LEAVES:13)
Block(5,52,-12,LEAVES:13)
Block(5,52,-11,LEAVES:13)
Block(5,52,-5,LOG:13)
Block(5,52,-4,LOG:13)
Block(5,52,-3,LOG:13)
Block(5,52,4,LEAVES:13)
Block(5,53,-10,LEAVES:13)
Block(5,53,-9,LEAVES:14)
Block(5,53,-8,LEAVES:14)
Block(5,53,-7,LEAVES:14)
Block(5,53,-6,LOG:13)
Block(5,53,-5,LOG:13)
Block(5,53,-2,LEAVES:14)
Block(5,53,-1,LEAVES:13)
Block(5,53,6,LEAVES:13)
Block(5,54,-12,LEAVES:13)
Block(5,54,-11,LOG:13)
Block(5,54,-10,LOG:13)
Block(5,54,-6,LOG:13)
Block(5,54,-5,LEAVES:14)
Block(5,54,5,LOG:13)
Block(5,54,6,LOG:13)
Block(5,54,8,LEAVES:13)
Block(5,55,-12,LEAVES:13)
Block(5,55,-10,LOG:13)
Block(5,55,-8,LEAVES:13)
Block(5,55,-7,LEAVES:13)
Block(5,55,8,LEAVES:13)
Block(5,56,-8,LEAVES:13)
Block(5,56,-7,LEAVES:13)
Block(5,56,-6,LEAVES:14)
Block(5,56,5,LEAVES:13)
Block(5,56,6,LEAVES:13)
Block(5,57,-4,LEAVES:14)
Block(5,57,5,LEAVES:13)
Block(5,57,6,LOG:13)
Block(5,58,-4,LEAVES:14)
Block(5,58,2,LEAVES:13)
Block(5,58,3,LEAVES:13)
Block(5,58,4,LEAVES:13)
Block(5,59,-6,LEAVES:13)
Block(5,59,3,LOG:13)
Block(5,59,4,LEAVES:13)
Block(5,59,5,LEAVES:13)
Block(5,59,6,LEAVES:13)
Block(5,60,1,LEAVES:14)
Block(5,60,2,LEAVES:14)
Block(5,60,3,LOG:13)
Block(5,60,5,LEAVES:13)
Block(5,60,6,LEAVES:13)
Block(5,61,-3,LEAVES:14)
Block(5,61,3,LEAVES:14)
Block(5,62,-3,LEAVES:13)
Block(5,62,1,LEAVES:14)
Block(5,62,3,LEAVES:14)
Block(5,62,4,LEAVES:14)
Block(5,63,-1,LOG:13)
Block(5,64,1,LEAVES:14)
Block(5,64,4,LEAVES:14)
Block(5,65,-1,LEAVES:13)
Block(5,65,0,LEAVES:13)
Block(5,65,4,LEAVES:14)
Block(5,67,0,LEAVES:13)
Block(5,67,1,LEAVES:13)
Block(5,68,0,LEAVES:13)
Block(5,68,1,LEAVES:13)
Block(5,68,3,LEAVES:13)
Block(5,70,-2,LEAVES:13)
Block(5,70,-1,LEAVES:13)
Block(5,70,0,LEAVES:13)
Block(5,70,1,LEAVES:13)
Block(5,70,3,LEAVES:14)
Block(5,71,-1,LEAVES:13)
Block(5,71,0,LOG:13)
Block(5,71,1,LOG:13)
Block(5,72,-2,LEAVES:13)
Block(5,72,0,LOG:13)
Block(5,72,1,LEAVES:14)
Block(5,73,-3,LEAVES:13)
Block(5,74,-6,LEAVES:13)
Block(5,74,-5,LEAVES:13)
Block(5,76,0,LEAVES:14)
Block(5,77,-1,LEAVES:14)
Block(5,77,0,LEAVES:14)
Block(5,77,1,LEAVES:14)
Block(5,77,3,LEAVES:14)
Block(5,78,0,LEAVES:14)
Block(5,78,2,LEAVES:13)
Block(5,79,-1,LEAVES:14)
Block(5,79,0,LEAVES:14)
Block(5,79,1,LEAVES:13)
Block(5,79,3,LEAVES:13)
Block(5,80,-1,LEAVES:14)
Block(5,80,1,LOG:13)
Block(5,80,2,LEAVES:13)
Block(5,81,-2,LEAVES:13)
Block(5,81,-1,LEAVES:13)
Block(6,-13,-1,LOG:13)
Block(6,-12,-4,LOG_2:13)
Block(6,-12,-1,LOG:13)
Block(6,-11,-5,LOG:13)
Block(6,-11,-4,LOG:13)
Block(6,-11,-3,LOG:13)
Block(6,-10,-10,LOG:13)
Block(6,-10,-9,LOG_2:13)
Block(6,-10,-3,LOG:13)
Block(6,-10,-2,LOG:13)
Block(6,-10,7,LOG:13)
Block(6,-9,-10,LOG_2:13)
Block(6,-9,-9,LOG_2:13)
Block(6,-9,5,LOG_2:13)
Block(6,-9,6,LOG_2:13)
Block(6,-9,7,LOG:13)
Block(6,-8,-9,LOG_2:13)
Block(6,-8,-8,LOG_2:13)
Block(6,-8,-3,LOG_2:13)
Block(6,-8,-2,LOG_2:13)
Block(6,-8,5,LOG_2:13)
Block(6,-8,6,LOG_2:13)
Block(6,-7,-6,LOG:13)
Block(6,-7,-4,LOG:13)
Block(6,-7,-3,LOG_2:13)
Block(6,-7,3,LOG:13)
Block(6,-7,4,LOG:13)
Block(6,-7,5,LOG:13)
Block(6,-6,-6,LOG:13)
Block(6,-6,-5,LOG:13)
Block(6,-6,-4,LOG_2:13)
Block(6,-6,3,LOG:13)
Block(6,-6,4,LOG:13)
Block(6,-6,5,LOG:13)
Block(6,-5,-6,LOG:13)
Block(6,-5,-5,LOG:13)
Block(6,-5,-4,LOG:13)
Block(6,-5,-3,LOG_2:13)
Block(6,-5,2,LOG:13)
Block(6,-5,3,LOG:13)
Block(6,-5,4,LOG:13)
Block(6,-5,5,LOG:13)
Block(6,-4,-6,LOG:13)
Block(6,-4,-5,LOG:13)
Block(6,-4,-4,LOG:13)
Block(6,-4,3,LOG:13)
Block(6,-4,4,LOG:13)
Block(6,-3,-5,LOG:13)
Block(6,-3,-4,LOG:13)
Block(6,-3,3,LOG:13)
Block(6,-3,4,LOG:13)
Block(6,-2,-5,LOG_2:13)
Block(6,-2,4,LOG:13)
Block(6,-1,3,LOG:13)
Block(6,21,-9,LEAVES:13)
Block(6,21,-8,LEAVES:14)
Block(6,22,-8,LEAVES:14)
Block(6,22,-7,LOG_2:13)
Block(6,22,-6,LOG_2:13)
Block(6,23,-7,LEAVES:13)
Block(6,23,-5,LOG_2:13)
Block(6,24,-9,LEAVES:13)
Block(6,24,-5,LOG_2:13)
Block(6,25,-9,LEAVES:13)
Block(6,25,-8,LEAVES:13)
Block(6,26,-8,LEAVES:13)
Block(6,26,-7,LEAVES:13)
Block(6,26,-6,LEAVES:13)
Block(6,27,-8,LEAVES:13)
Block(6,27,-5,LOG_2:13)
Block(6,28,-9,LEAVES:13)
Block(6,28,-7,LEAVES:13)
Block(6,28,-6,LOG:13)
Block(6,28,-5,LOG_2:13)
Block(6,28,-3,LEAVES:14)
Block(6,28,-2,LEAVES:14)
Block(6,29,-7,LOG_2:13)
Block(6,29,-6,LOG:13)
Block(6,29,-5,LEAVES:14)
Block(6,30,-7,LOG:13)
Block(6,30,-6,LEAVES:14)
Block(6,30,-4,LOG:13)
Block(6,30,-3,LEAVES:13)
Block(6,30,-2,LEAVES:14)
Block(6,31,-7,LEAVES:13)
Block(6,31,-5,LOG:13)
Block(6,32,-7,LEAVES:13)
Block(6,32,-6,LOG:13)
Block(6,32,-5,LOG:13)
Block(6,33,-7,LOG_2:13)
Block(6,33,-6,LOG:13)
Block(6,34,-7,LOG_2:13)
Block(6,40,-9,LEAVES:14)
Block(6,40,-8,LEAVES:14)
Block(6,40,-5,LEAVES:14)
Block(6,40,-4,LEAVES:14)
Block(6,40,10,LEAVES:14)
Block(6,41,-4,LOG:13)
Block(6,41,7,LEAVES:14)
Block(6,41,8,LEAVES:14)
Block(6,42,7,LEAVES:14)
Block(6,42,10,LOG:13)
Block(6,42,11,LEAVES:13)
Block(6,43,9,LEAVES:13)
Block(6,43,11,LEAVES:13)
Block(6,44,7,LOG:13)
Block(6,44,8,LEAVES:13)
Block(6,44,9,LEAVES:13)
Block(6,44,10,LEAVES:13)
Block(6,44,11,LEAVES:14)
Block(6,45,7,LOG:13)
Block(6,45,8,LOG:13)
Block(6,45,9,LOG:13)
Block(6,46,9,LOG:13)
Block(6,46,10,LEAVES:14)
Block(6,47,11,LEAVES:14)
Block(6,47,12,LEAVES:14)
Block(6,50,-2,LEAVES:14)
Block(6,50,-1,LEAVES:14)
Block(6,50,3,LOG:13)
Block(6,50,4,LOG:13)
Block(6,51,-4,LEAVES:14)
Block(6,51,-3,LEAVES:14)
Block(6,51,4,LEAVES:13)
Block(6,52,-8,LEAVES:14)
Block(6,52,-3,LOG:13)
Block(6,52,-2,LEAVES:13)
Block(6,52,6,LEAVES:13)
Block(6,53,-11,LEAVES:13)
Block(6,53,-8,LEAVES:14)
Block(6,53,-3,LOG:13)
Block(6,53,-1,LEAVES:13)
Block(6,53,5,LOG:13)
Block(6,53,6,LEAVES:13)
Block(6,54,-11,LOG:13)
Block(6,54,-7,LOG:13)
Block(6,54,-6,LOG:13)
Block(6,54,4,LEAVES:13)
Block(6,54,5,LOG:13)
Block(6,54,6,LEAVES:13)
Block(6,55,-6,LOG:13)
Block(6,55,-5,LOG:13)
Block(6,55,6,LEAVES:13)
Block(6,56,-6,LEAVES:14)
Block(6,56,-5,LOG:13)
Block(6,56,3,LEAVES:13)
Block(6,56,4,LEAVES:13)
Block(6,57,-7,LEAVES:13)
Block(6,57,-6,LEAVES:13)
Block(6,57,-5,LOG:13)
Block(6,57,-4,LEAVES:14)
Block(6,57,3,LEAVES:13)
Block(6,57,6,LEAVES:13)
Block(6,57,7,LEAVES:13)
Block(6,58,-8,LEAVES:13)
Block(6,58,-7,LEAVES:13)
Block(6,58,-6,LEAVES:13)
Block(6,58,-4,LEAVES:14)
Block(6,58,5,LEAVES:13)
Block(6,59,-6,LEAVES:13)
Block(6,59,-4,LEAVES:13)
Block(6,59,3,LEAVES:14)
Block(6,59,4,LEAVES:14)
Block(6,59,5,LEAVES:13)
Block(6,60,2,LEAVES:14)
Block(6,60,3,LOG:13)
Block(6,60,4,LOG:13)
Block(6,62,-3,LEAVES:13)
Block(6,62,-2,LEAVES:13)
Block(6,62,1,LEAVES:14)
Block(6,62,2,LEAVES:14)
Block(6,63,-1,LOG:13)
Block(6,63,0,LEAVES:14)
Block(6,64,-3,LEAVES:13)
Block(6,64,-2,LEAVES:13)
Block(6,64,-1,LOG:13)
Block(6,64,0,LOG:13)
Block(6,64,1,LEAVES:13)
Block(6,64,2,LEAVES:14)
Block(6,64,4,LEAVES:14)
Block(6,65,-3,LEAVES:13)
Block(6,65,-1,LEAVES:13)
Block(6,65,0,LOG:13)
Block(6,65,1,LOG:13)
Block(6,67,0,LEAVES:13)
Block(6,68,1,LEAVES:13)
Block(6,69,2,LEAVES:13)
Block(6,70,-2,LEAVES:14)
Block(6,70,-1,LEAVES:13)
Block(6,70,1,LOG:13)
Block(6,70,2,LOG:13)
Block(6,71,0,LEAVES:14)
Block(6,71,1,LOG:13)
Block(6,72,1,LEAVES:14)
Block(6,73,-3,LEAVES:13)
Block(6,73,-2,LEAVES:13)
Block(6,77,3,LEAVES:14)
Block(6,77,4,LEAVES:14)
Block(6,78,0,LEAVES:14)
Block(6,78,1,LEAVES:14)
Block(6,79,3,LEAVES:13)
Block(6,79,4,LEAVES:14)
Block(6,80,1,LEAVES:13)
Block(6,80,2,LEAVES:13)
Block(7,-12,-1,LOG:13)
Block(7,-11,-1,LOG_2:13)
Block(7,-10,-2,LOG:13)
Block(7,-10,6,LOG:13)
Block(7,-9,-2,LOG_2:13)
Block(7,-9,2,LOG:13)
Block(7,-9,6,LOG_2:13)
Block(7,-8,-8,LOG:13)
Block(7,-8,-7,LOG:13)
Block(7,-8,-4,LOG:13)
Block(7,-8,-3,LOG_2:13)
Block(7,-8,-2,LOG_2:13)
Block(7,-8,2,LOG:13)
Block(7,-8,3,LOG:13)
Block(7,-7,-7,LOG:13)
Block(7,-7,-6,LOG:13)
Block(7,-7,-5,LOG:13)
Block(7,-7,-4,LOG_2:13)
Block(7,-7,3,LOG:13)
Block(7,-7,5,LOG:13)
Block(7,-6,-7,LOG:13)
Block(7,-6,-6,LOG:13)
Block(7,-6,-5,LOG:13)
Block(7,-6,3,LOG:13)
Block(7,-6,4,LOG:13)
Block(7,-6,5,LOG:13)
Block(7,-5,-6,LOG:13)
Block(7,-5,-5,LOG:13)
Block(7,-4,-5,LOG:13)
Block(7,21,-8,LEAVES:13)
Block(7,22,-9,LEAVES:13)
Block(7,22,-8,LOG_2:13)
Block(7,22,-7,LOG_2:13)
Block(7,23,-11,LEAVES:13)
Block(7,23,-9,LEAVES:13)
Block(7,23,-6,LEAVES:14)
Block(7,24,-9,LEAVES:13)
Block(7,24,-6,LEAVES:13)
Block(7,24,-5,LOG_2:13)
Block(7,25,-5,LOG_2:13)
Block(7,26,-5,LOG_2:13)
Block(7,27,-5,LOG:13)
Block(7,27,-3,LEAVES:14)
Block(7,28,-9,LEAVES:14)
Block(7,28,-8,LEAVES:14)
Block(7,28,-5,LOG_2:13)
Block(7,28,-4,LOG_2:13)
Block(7,29,-4,LOG_2:13)
Block(7,29,-3,LOG_2:13)
Block(7,30,-6,LEAVES:14)
Block(7,30,-4,LOG_2:13)
Block(7,31,-9,LEAVES:13)
Block(7,31,-8,LEAVES:14)
Block(7,32,-9,LEAVES:13)
Block(7,32,-6,LEAVES:13)
Block(7,32,-5,LEAVES:13)
Block(7,33,-7,LEAVES:13)
Block(7,34,-8,LEAVES:14)
Block(7,34,-7,LEAVES:14)
Block(7,34,-6,LEAVES:14)
Block(7,36,-8,LEAVES:14)
Block(7,37,-8,LEAVES:14)
Block(7,39,-7,LEAVES:14)
Block(7,39,-6,LEAVES:14)
Block(7,39,10,LEAVES:14)
Block(7,40,-8,LEAVES:14)
Block(7,40,-4,LEAVES:14)
Block(7,40,10,LEAVES:14)
Block(7,41,-4,LOG:13)
Block(7,41,10,LOG:13)
Block(7,42,-1,LEAVES:14)
Block(7,42,0,LEAVES:14)
Block(7,43,10,LEAVES:13)
Block(7,44,7,LEAVES:13)
Block(7,45,5,LEAVES:13)
Block(7,45,7,LOG:13)
Block(7,46,5,LEAVES:14)
Block(7,46,10,LEAVES:14)
Block(7,47,7,LEAVES:13)
Block(7,47,8,LEAVES:13)
Block(7,48,8,LEAVES:13)
Block(7,50,-1,LEAVES:13)
Block(7,50,4,LOG:13)
Block(7,51,-4,LEAVES:14)
Block(7,51,-2,LEAVES:14)
Block(7,51,4,LOG:13)
Block(7,51,5,LEAVES:13)
Block(7,52,-13,LEAVES:13)
Block(7,52,-12,LEAVES:13)
Block(7,52,-3,LEAVES:14)
Block(7,52,4,LOG:13)
Block(7,52,5,LOG:13)
Block(7,52,6,LEAVES:13)
Block(7,53,-4,LEAVES:14)
Block(7,53,-3,LOG:13)
Block(7,53,2,LEAVES:13)
Block(7,53,4,LEAVES:13)
Block(7,53,5,LOG:13)
Block(7,54,-13,LEAVES:13)
Block(7,54,-12,LEAVES:13)
Block(7,54,-10,LEAVES:14)
Block(7,54,-9,LEAVES:14)
Block(7,54,-8,LEAVES:14)
Block(7,54,-7,LOG:13)
Block(7,54,-6,LEAVES:14)
Block(7,54,4,LEAVES:13)
Block(7,54,6,LEAVES:13)
Block(7,55,-9,LEAVES:14)
Block(7,55,-7,LEAVES:14)
Block(7,55,-6,LEAVES:14)
Block(7,55,6,LEAVES:13)
Block(7,56,-6,LEAVES:13)
Block(7,57,-6,LEAVES:13)
Block(7,57,-5,LOG:13)
Block(7,58,-8,LEAVES:14)
Block(7,58,-7,LEAVES:13)
Block(7,58,6,LEAVES:13)
Block(7,60,3,LEAVES:14)
Block(7,60,4,LEAVES:14)
Block(7,61,1,LEAVES:14)
Block(7,61,4,LEAVES:14)
Block(7,62,-1,LEAVES:13)
Block(7,62,1,LEAVES:14)
Block(7,63,-2,LEAVES:13)
Block(7,63,3,LOG:13)
Block(7,64,-4,LEAVES:13)
Block(7,64,-2,LOG:13)
Block(7,64,-1,LOG:13)
Block(7,64,0,LEAVES:13)
Block(7,64,2,LOG:13)
Block(7,64,3,LOG:13)
Block(7,65,-4,LEAVES:13)
Block(7,65,1,LOG:13)
Block(7,65,2,LOG:13)
Block(7,65,3,LEAVES:13)
Block(7,66,-1,LEAVES:14)
Block(7,66,0,LEAVES:13)
Block(7,66,1,LOG:13)
Block(7,66,3,LEAVES:13)
Block(7,67,1,LEAVES:13)
Block(7,68,1,LEAVES:13)
Block(7,68,2,LEAVES:13)
Block(7,69,0,LEAVES:14)
Block(7,69,1,LEAVES:13)
Block(7,70,0,LEAVES:14)
Block(7,70,3,LEAVES:13)
Block(7,70,4,LEAVES:14)
Block(7,71,-2,LEAVES:14)
Block(7,71,0,LEAVES:14)
Block(7,71,1,LEAVES:14)
Block(7,71,4,LEAVES:14)
Block(7,72,2,LEAVES:14)
Block(8,-12,8,LOG_2:13)
Block(8,-11,7,LOG_2:13)
Block(8,-11,8,LOG_2:13)
Block(8,-10,-1,LOG_2:13)
Block(8,-10,1,LOG:13)
Block(8,-10,2,LOG:13)
Block(8,-10,6,LOG:13)
Block(8,-10,7,LOG:13)
Block(8,-9,-2,LOG_2:13)
Block(8,-9,2,LOG:13)
Block(8,-7,-6,LOG_2:13)
Block(8,-6,-7,LOG_2:13)
Block(8,-6,-6,LOG_2:13)
Block(8,-5,-7,LOG:13)
Block(8,-5,-6,LOG:13)
Block(8,19,-10,LEAVES:13)
Block(8,20,-10,LEAVES:13)
Block(8,20,-9,LEAVES:13)
Block(8,22,-9,LEAVES:13)
Block(8,22,-8,LOG_2:13)
Block(8,23,-11,LEAVES:13)
Block(8,23,-10,LEAVES:13)
Block(8,24,-6,LOG:13)
Block(8,24,-5,LOG:13)
Block(8,25,-5,LOG_2:13)
Block(8,25,-4,LOG_2:13)
Block(8,26,-4,LEAVES:14)
Block(8,26,-3,LEAVES:14)
Block(8,26,-2,LEAVES:14)
Block(8,27,-5,LEAVES:14)
Block(8,27,-3,LEAVES:14)
Block(8,27,-2,LEAVES:14)
Block(8,28,-3,LEAVES:14)
Block(8,28,-2,LEAVES:14)
Block(8,29,-6,LEAVES:14)
Block(8,29,-5,LEAVES:14)
Block(8,29,-3,LEAVES:14)
Block(8,30,-6,LEAVES:14)
Block(8,30,-3,LEAVES:14)
Block(8,33,-6,LEAVES:14)
Block(8,37,-8,LEAVES:14)
Block(8,38,-11,LEAVES:14)
Block(8,38,-10,LEAVES:14)
Block(8,38,-4,LEAVES:14)
Block(8,38,-1,LEAVES:13)
Block(8,39,-11,LEAVES:14)
Block(8,39,-8,LEAVES:13)
Block(8,39,-7,LEAVES:14)
Block(8,39,-5,LEAVES:14)
Block(8,39,-1,LEAVES:13)
Block(8,40,-9,LEAVES:13)
Block(8,40,-6,LOG:13)
Block(8,41,-10,LEAVES:13)
Block(8,41,-9,LEAVES:13)
Block(8,41,-7,LEAVES:14)
Block(8,41,-5,LOG:13)
Block(8,41,-4,LOG:13)
Block(8,41,0,LEAVES:14)
Block(8,41,1,LEAVES:14)
Block(8,41,10,LOG:13)
Block(8,42,-1,LEAVES:14)
Block(8,43,-3,LEAVES:13)
Block(8,43,9,LEAVES:13)
Block(8,43,10,LEAVES:13)
Block(8,44,6,LEAVES:13)
Block(8,45,5,LEAVES:13)
Block(8,45,6,LOG:13)
Block(8,45,7,LOG:13)
Block(8,46,7,LEAVES:13)
Block(8,46,9,LEAVES:13)
Block(8,47,7,LEAVES:13)
Block(8,49,3,LEAVES:14)
Block(8,50,-3,LEAVES:14)
Block(8,50,-2,LEAVES:14)
Block(8,50,3,LEAVES:13)
Block(8,50,4,LEAVES:14)
Block(8,51,-4,LEAVES:14)
Block(8,51,-3,LEAVES:14)
Block(8,51,-2,LEAVES:13)
Block(8,51,5,LOG:13)
Block(8,52,-13,LEAVES:13)
Block(8,52,-5,LEAVES:14)
Block(8,52,-4,LEAVES:14)
Block(8,52,4,LEAVES:13)
Block(8,52,5,LOG:13)
Block(8,53,-8,LEAVES:14)
Block(8,53,-7,LOG:13)
Block(8,53,-5,LEAVES:14)
Block(8,53,-4,LEAVES:14)
Block(8,53,-3,LOG:13)
Block(8,53,-2,LEAVES:13)
Block(8,53,-1,LEAVES:13)
Block(8,53,2,LEAVES:13)
Block(8,53,3,LEAVES:13)
Block(8,53,7,LEAVES:14)
Block(8,54,-13,LEAVES:13)
Block(8,54,-10,LEAVES:13)
Block(8,54,-8,LEAVES:14)
Block(8,54,-7,LOG:13)
Block(8,54,-3,LEAVES:13)
Block(8,54,-2,LEAVES:13)
Block(8,54,7,LEAVES:14)
Block(8,55,-10,LEAVES:14)
Block(8,55,-5,LEAVES:13)
Block(8,56,-8,LEAVES:14)
Block(8,56,-7,LEAVES:14)
Block(8,57,-8,LEAVES:14)
Block(8,57,-6,LEAVES:13)
Block(8,57,-5,LEAVES:13)
Block(8,57,-4,LEAVES:13)
Block(8,58,-6,LEAVES:13)
Block(8,58,-4,LEAVES:13)
Block(8,58,5,LEAVES:13)
Block(8,58,6,LEAVES:13)
Block(8,59,-7,LEAVES:14)
Block(8,59,-6,LEAVES:14)
Block(8,59,-4,LEAVES:14)
Block(8,62,-4,LEAVES:13)
Block(8,62,-3,LEAVES:13)
Block(8,62,-2,LEAVES:13)
Block(8,62,-1,LEAVES:13)
Block(8,62,2,LEAVES:14)
Block(8,62,3,LEAVES:14)
Block(8,63,4,LEAVES:14)
Block(8,63,5,LEAVES:14)
Block(8,64,-4,LEAVES:13)
Block(8,64,-3,LOG:13)
Block(8,64,-2,LOG:13)
Block(8,64,-1,LEAVES:14)
Block(8,64,2,LEAVES:14)
Block(8,64,3,LEAVES:14)
Block(8,65,1,LEAVES:14)
Block(8,65,2,LEAVES:13)
Block(8,65,4,LEAVES:13)
Block(8,66,0,LEAVES:14)
Block(8,66,1,LOG:13)
Block(8,69,0,LEAVES:14)
Block(8,69,1,LEAVES:14)
Block(8,71,-2,LEAVES:14)
Block(8,71,-1,LEAVES:14)
Block(8,71,0,LEAVES:14)
Block(8,72,1,LEAVES:14)
Block(8,72,2,LEAVES:14)
Block(9,-10,2,LOG:13)
Block(9,-8,-6,LOG_2:13)
Block(9,-8,-5,LOG_2:13)
Block(9,-7,-8,LOG_2:13)
Block(9,-7,-7,LOG_2:13)
Block(9,-7,-6,LOG_2:13)
Block(9,-6,-7,LOG_2:13)
Block(9,-6,-6,LOG_2:13)
Block(9,-5,-6,LOG:13)
Block(9,22,-9,LEAVES:13)
Block(9,23,-7,LEAVES:13)
Block(9,24,-7,LEAVES:13)
Block(9,24,-6,LEAVES:13)
Block(9,25,-6,LOG:13)
Block(9,25,-5,LOG:13)
Block(9,25,-4,LOG:13)
Block(9,26,-5,LEAVES:14)
Block(9,26,-4,LOG:13)
Block(9,26,-2,LEAVES:14)
Block(9,27,-8,LEAVES:14)
Block(9,27,-7,LEAVES:14)
Block(9,27,-6,LEAVES:14)
Block(9,27,-5,LEAVES:14)
Block(9,27,-4,LOG:13)
Block(9,27,-3,LOG_2:13)
Block(9,28,-3,LOG_2:13)
Block(9,28,-2,LEAVES:14)
Block(9,29,-6,LEAVES:14)
Block(9,29,-5,LEAVES:14)
Block(9,33,-7,LEAVES:14)
Block(9,33,-6,LEAVES:14)
Block(9,38,-9,LEAVES:13)
Block(9,38,-5,LEAVES:14)
Block(9,38,-4,LEAVES:14)
Block(9,38,0,LEAVES:13)
Block(9,38,1,LEAVES:13)
Block(9,39,-9,LEAVES:13)
Block(9,39,-8,LOG:13)
Block(9,39,-7,LOG:13)
Block(9,39,-6,LOG:13)
Block(9,39,-1,LEAVES:14)
Block(9,40,-6,LOG:13)
Block(9,40,-5,LEAVES:14)
Block(9,40,-3,LOG:13)
Block(9,40,-2,LOG:13)
Block(9,40,-1,LOG:13)
Block(9,40,0,LOG:13)
Block(9,40,1,LEAVES:14)
Block(9,40,2,LEAVES:13)
Block(9,41,-7,LEAVES:14)
Block(9,41,-6,LEAVES:14)
Block(9,41,-5,LOG:13)
Block(9,41,-4,LOG:13)
Block(9,41,-3,LOG:13)
Block(9,41,-2,LEAVES:14)
Block(9,41,-1,LEAVES:14)
Block(9,41,1,LEAVES:14)
Block(9,41,2,LEAVES:14)
Block(9,42,-7,LEAVES:14)
Block(9,42,-6,LEAVES:14)
Block(9,42,-5,LOG:13)
Block(9,42,0,LEAVES:14)
Block(9,42,8,LEAVES:13)
Block(9,43,-7,LEAVES:14)
Block(9,43,-4,LEAVES:13)
Block(9,43,-3,LEAVES:14)
Block(9,43,0,LEAVES:14)
Block(9,43,1,LEAVES:14)
Block(9,43,7,LEAVES:13)
Block(9,43,8,LEAVES:13)
Block(9,45,5,LOG:13)
Block(9,45,6,LOG:13)
Block(9,45,7,LEAVES:13)
Block(9,46,5,LOG:13)
Block(9,46,8,LEAVES:13)
Block(9,46,9,LEAVES:13)
Block(9,49,4,LEAVES:14)
Block(9,50,-2,LEAVES:13)
Block(9,50,4,LEAVES:14)
Block(9,50,5,LEAVES:14)
Block(9,51,-3,LEAVES:14)
Block(9,51,5,LOG:13)
Block(9,51,6,LOG:13)
Block(9,52,-8,LOG:13)
Block(9,52,-7,LOG:13)
Block(9,52,-5,LEAVES:14)
Block(9,52,-3,LOG:13)
Block(9,52,-2,LEAVES:13)
Block(9,52,4,LEAVES:14)
Block(9,52,5,LEAVES:14)
Block(9,52,6,LEAVES:14)
Block(9,53,-10,LEAVES:13)
Block(9,53,-9,LEAVES:14)
Block(9,53,-7,LOG:13)
Block(9,53,-6,LEAVES:14)
Block(9,53,-5,LOG:13)
Block(9,53,-4,LOG:13)
Block(9,53,-3,LOG:13)
Block(9,53,-1,LEAVES:13)
Block(9,53,3,LEAVES:13)
Block(9,53,4,LEAVES:14)
Block(9,53,6,LEAVES:14)
Block(9,54,-10,LEAVES:13)
Block(9,54,-7,LEAVES:14)
Block(9,54,-6,LEAVES:14)
Block(9,54,-5,LEAVES:14)
Block(9,54,-4,LEAVES:13)
Block(9,54,-2,LEAVES:13)
Block(9,54,4,LEAVES:14)
Block(9,54,5,LEAVES:14)
Block(9,54,6,LEAVES:14)
Block(9,55,-8,LEAVES:14)
Block(9,55,-5,LEAVES:13)
Block(9,55,-4,LEAVES:13)
Block(9,56,-9,LEAVES:14)
Block(9,56,-8,LEAVES:14)
Block(9,58,-5,LEAVES:13)
Block(9,61,2,LEAVES:13)
Block(9,62,-4,LEAVES:13)
Block(9,62,2,LEAVES:14)
Block(9,63,-4,LOG:13)
Block(9,63,-3,LOG:13)
Block(9,63,4,LEAVES:14)
Block(9,64,-4,LEAVES:13)
Block(9,64,-3,LOG:13)
Block(9,64,-1,LEAVES:13)
Block(9,65,-1,LEAVES:14)
Block(9,65,4,LEAVES:13)
Block(9,65,5,LEAVES:13)
Block(9,66,1,LOG:13)
Block(9,66,2,LEAVES:14)
Block(9,67,-1,LEAVES:14)
Block(9,67,2,LEAVES:14)
Block(9,68,-1,LEAVES:14)
Block(10,-9,-4,LOG_2:13)
Block(10,-8,-8,LOG_2:13)
Block(10,-8,-5,LOG_2:13)
Block(10,-8,-4,LOG_2:13)
Block(10,-7,-8,LOG_2:13)
Block(10,-7,-7,LOG_2:13)
Block(10,24,-7,LEAVES:13)
Block(10,24,-6,LEAVES:13)
Block(10,25,-6,LOG:13)
Block(10,25,-4,LEAVES:13)
Block(10,26,-8,LEAVES:14)
Block(10,26,-7,LEAVES:14)
Block(10,26,-6,LOG:13)
Block(10,26,-4,LEAVES:14)
Block(10,26,-3,LEAVES:14)
Block(10,26,-2,LEAVES:14)
Block(10,27,-8,LEAVES:14)
Block(10,27,-4,LEAVES:14)
Block(10,28,-5,LEAVES:14)
Block(10,28,-3,LOG_2:13)
Block(10,29,-5,LEAVES:14)
Block(10,29,-4,LEAVES:13)
Block(10,29,-3,LOG_2:13)
Block(10,30,-5,LEAVES:14)
Block(10,30,-2,LEAVES:13)
Block(10,31,-2,LEAVES:14)
Block(10,38,1,LEAVES:14)
Block(10,39,-10,LEAVES:13)
Block(10,39,-9,LEAVES:13)
Block(10,39,-2,LEAVES:14)
Block(10,39,0,LEAVES:13)
Block(10,40,-10,LEAVES:13)
Block(10,40,-7,LEAVES:13)
Block(10,40,-4,LEAVES:14)
Block(10,40,-1,LEAVES:14)
Block(10,40,0,LOG:13)
Block(10,41,-7,LEAVES:14)
Block(10,41,-5,LEAVES:14)
Block(10,41,-4,LEAVES:14)
Block(10,41,-2,LEAVES:14)
Block(10,41,-1,LEAVES:14)
Block(10,41,0,LOG:13)
Block(10,42,-5,LOG:13)
Block(10,42,-4,LOG:13)
Block(10,42,-2,LEAVES:14)
Block(10,42,-1,LEAVES:14)
Block(10,44,-3,LEAVES:13)
Block(10,44,-2,LEAVES:14)
Block(10,45,7,LEAVES:13)
Block(10,46,5,LEAVES:13)
Block(10,47,5,LEAVES:13)
Block(10,50,5,LEAVES:14)
Block(10,51,-7,LEAVES:14)
Block(10,51,-4,LEAVES:14)
Block(10,51,5,LEAVES:14)
Block(10,51,6,LOG:13)
Block(10,52,-7,LEAVES:14)
Block(10,52,-4,LEAVES:14)
Block(10,52,-3,LOG:13)
Block(10,52,-2,LOG:13)
Block(10,52,-1,LOG:13)
Block(10,52,6,LOG:13)
Block(10,52,7,LEAVES:14)
Block(10,53,-6,LEAVES:14)
Block(10,53,-2,LEAVES:14)
Block(10,53,3,LEAVES:14)
Block(10,53,5,LEAVES:14)
Block(10,54,-6,LEAVES:14)
Block(10,54,5,LEAVES:14)
Block(10,55,-7,LEAVES:14)
Block(10,55,-4,LEAVES:13)
Block(10,58,-6,LEAVES:13)
Block(10,58,-5,LEAVES:13)
Block(10,62,-3,LEAVES:13)
Block(10,62,-2,LEAVES:13)
Block(10,63,-5,LEAVES:13)
Block(10,63,-4,LEAVES:13)
Block(10,64,-3,LEAVES:13)
Block(10,64,-2,LEAVES:13)
Block(10,65,-4,LEAVES:13)
Block(10,65,-2,LEAVES:13)
Block(11,-9,-4,LOG_2:13)
Block(11,-9,-3,LOG_2:13)
Block(11,-8,-9,LOG_2:13)
Block(11,-8,-8,LOG_2:13)
Block(11,24,-8,LEAVES:14)
Block(11,24,-6,LEAVES:13)
Block(11,25,-7,LEAVES:14)
Block(11,25,-5,LEAVES:13)
Block(11,25,-4,LEAVES:13)
Block(11,25,-3,LEAVES:13)
Block(11,26,-8,LEAVES:14)
Block(11,26,-7,LOG:13)
Block(11,26,-6,LOG:13)
Block(11,27,-7,LEAVES:14)
Block(11,28,-5,LEAVES:13)
Block(11,28,-4,LEAVES:13)
Block(11,29,-4,LEAVES:13)
Block(11,29,-3,LOG_2:13)
Block(11,39,-3,LEAVES:14)
Block(11,39,-2,LEAVES:14)
Block(11,39,-1,LEAVES:14)
Block(11,40,-6,LEAVES:13)
Block(11,40,-4,LEAVES:13)
Block(11,40,-3,LEAVES:14)
Block(11,40,1,LEAVES:14)
Block(11,41,0,LEAVES:14)
Block(11,41,1,LEAVES:14)
Block(11,42,-6,LEAVES:14)
Block(11,42,-4,LOG:13)
Block(11,42,-2,LEAVES:13)
Block(11,42,-1,LEAVES:14)
Block(11,42,1,LEAVES:14)
Block(11,43,-4,LOG:13)
Block(11,43,-3,LOG:13)
Block(11,43,-2,LEAVES:13)
Block(11,44,-3,LEAVES:13)
Block(11,51,-4,LEAVES:14)
Block(11,51,-3,LEAVES:13)
Block(11,51,5,LEAVES:14)
Block(11,52,-4,LEAVES:14)
Block(11,52,2,LEAVES:14)
Block(11,52,3,LEAVES:14)
Block(11,52,5,LOG:13)
Block(11,52,6,LOG:13)
Block(11,52,7,LEAVES:14)
Block(11,53,-4,LEAVES:14)
Block(11,53,-3,LEAVES:14)
Block(11,53,-2,LEAVES:14)
Block(11,53,2,LEAVES:13)
Block(11,53,5,LOG:13)
Block(11,53,6,LEAVES:14)
Block(11,53,7,LEAVES:14)
Block(11,54,4,LEAVES:14)
Block(11,54,5,LEAVES:14)
Block(11,55,-8,LEAVES:14)
Block(11,55,-7,LEAVES:14)
Block(11,55,3,LEAVES:14)
Block(11,55,4,LEAVES:14)
Block(11,61,-2,LEAVES:13)
Block(11,62,-2,LEAVES:13)
Block(11,63,-4,LEAVES:13)
Block(11,65,-5,LEAVES:13)
Block(11,65,-4,LEAVES:13)
Block(12,-9,-9,LOG_2:13)
Block(12,-8,-9,LOG_2:13)
Block(12,23,-6,LEAVES:13)
Block(12,24,-8,LEAVES:14)
Block(12,24,-7,LEAVES:14)
Block(12,25,-6,LEAVES:13)
Block(12,25,-5,LEAVES:13)
Block(12,26,-7,LOG_2:13)
Block(12,26,-5,LEAVES:13)
Block(12,27,-7,LEAVES:14)
Block(12,27,-6,LEAVES:14)
Block(12,27,-3,LEAVES:14)
Block(12,28,-6,LEAVES:13)
Block(12,28,-5,LEAVES:13)
Block(12,29,-6,LEAVES:13)
Block(12,29,-3,LEAVES:13)
Block(12,29,-2,LEAVES:13)
Block(12,30,-4,LEAVES:13)
Block(12,31,-5,LEAVES:13)
Block(12,31,-4,LEAVES:13)
Block(12,40,-7,LEAVES:13)
Block(12,40,-6,LEAVES:13)
Block(12,40,0,LEAVES:14)
Block(12,40,1,LEAVES:14)
Block(12,41,-3,LEAVES:13)
Block(12,42,-7,LEAVES:13)
Block(12,42,-6,LEAVES:13)
Block(12,42,-2,LEAVES:13)
Block(12,43,-3,LOG:13)
Block(12,43,-2,LOG:13)
Block(12,43,0,LEAVES:14)
Block(12,44,-4,LEAVES:13)
Block(12,51,5,LEAVES:14)
Block(12,52,4,LEAVES:14)
Block(12,52,5,LEAVES:14)
Block(12,53,4,LOG:13)
Block(12,53,5,LOG:13)
Block(12,54,4,LOG:13)
Block(13,-9,-9,LOG_2:13)
Block(13,23,-7,LEAVES:14)
Block(13,23,-6,LEAVES:13)
Block(13,26,-6,LEAVES:13)
Block(13,26,-5,LEAVES:13)
Block(13,26,-3,LEAVES:14)
Block(13,27,-3,LEAVES:14)
Block(13,30,-3,LEAVES:13)
Block(13,41,-3,LEAVES:13)
Block(13,41,-2,LEAVES:14)
Block(13,43,-1,LEAVES:13)
Block(13,43,0,LEAVES:14)
Block(13,44,-4,LEAVES:13)
Block(13,44,-3,LEAVES:13)
Block(13,53,3,LEAVES:14)
Block(13,53,4,LEAVES:14)
Block(13,54,3,LEAVES:14)
Block(13,54,6,LEAVES:14)
Block(13,55,6,LEAVES:14)
Block(14,-9,-9,LOG_2:13)
Block(14,30,-4,LEAVES:13)
Block(14,30,-3,LEAVES:13)

#######################################################################
# +-----------------------------------------------------------------+ #
# |                            BO3 checks                           | #
# +-----------------------------------------------------------------+ #
#######################################################################

BlockCheck(-8,-10,1,Solid)
BlockCheck(-3,-8,-3,Solid)
BlockCheck(-2,-11,-8,Solid)
BlockCheck(-1,-12,5,Solid)
BlockCheck(-1,-9,-9,Solid)
BlockCheck(1,-10,8,Solid)
BlockCheck(2,-15,4,Solid)
BlockCheck(4,-13,-6,Solid)
BlockCheck(4,-11,-11,Solid)
BlockCheck(4,-11,2,Solid)
BlockCheck(6,-14,-1,Solid)
BlockCheck(6,-13,-4,Solid)
BlockCheck(8,-13,8,Solid)
BlockCheck(9,-11,2,Solid)
BlockCheck(11,-10,-3,Solid)
BlockCheck(14,-10,-9,Solid)

#######################################################################
# +-----------------------------------------------------------------+ #
