
#######################################################################
# +-----------------------------------------------------------------+ #
# |                            BO3 object                           | #
# +-----------------------------------------------------------------+ #
#######################################################################

Author: NLBlackEagle

Description: No description given

Version: 3

SettingsMode: WriteDisable


#######################################################################
# +-----------------------------------------------------------------+ #
# |                          Main settings                          | #
# +-----------------------------------------------------------------+ #
#######################################################################

Tree: true

Frequency: 0

Rarity: 30.0

RotateRandomly: true

SpawnHeight: highestSolidBlock

SpawnHeightOffset: 0

SpawnHeightVariance: 1

##############################
# Height Limits for the BO3. #
##############################

MinHeight: 0

MaxHeight: 255

######################
# Extrusion settings #
######################

ExtrudeMode: None

ExtrudeThroughBlocks: AIR

MaxBranchDepth: 10

ExcludedBiomes: All


#######################################################################
# +-----------------------------------------------------------------+ #
# |                      Source block settings                      | #
# +-----------------------------------------------------------------+ #
#######################################################################

SourceBlocks: AIR

MaxPercentageOutsideSourceBlock: 50

OutsideSourceBlock: placeAnyway

DoReplaceBlocks: true

IsOTGPlus: false


#######################################################################
# +-----------------------------------------------------------------+ #
# |                              Blocks                             | #
# +-----------------------------------------------------------------+ #
#######################################################################

Block(-10,-11,-4,LOG:13)
Block(-10,54,3,LOG:13)
Block(-9,-11,-5,LOG:13)
Block(-9,-11,-4,LOG:13)
Block(-9,-7,-6,LOG_2:13)
Block(-9,-7,-5,LOG_2:13)
Block(-9,53,1,LOG:13)
Block(-9,53,2,LOG:13)
Block(-8,-11,-5,LOG:13)
Block(-8,-10,-6,LOG:13)
Block(-8,-10,-5,LOG:13)
Block(-8,-8,-5,LOG_2:13)
Block(-8,-7,-5,LOG_2:13)
Block(-8,52,1,LOG:13)
Block(-8,53,1,LOG:13)
Block(-8,54,1,LOG:13)
Block(-7,-10,-7,LOG:13)
Block(-7,-10,-6,LOG:13)
Block(-7,-9,-8,LOG:13)
Block(-7,-9,-7,LOG:13)
Block(-7,-8,-7,LOG:13)
Block(-7,-8,-6,LOG:13)
Block(-7,-8,-5,LOG:13)
Block(-7,52,3,LOG:13)
Block(-7,52,4,LOG:13)
Block(-7,53,0,LOG:13)
Block(-7,53,1,LOG:13)
Block(-7,53,2,LOG:13)
Block(-7,53,3,LOG:13)
Block(-7,54,2,LOG:13)
Block(-6,-10,-1,LOG_2:13)
Block(-6,-9,-12,LOG:13)
Block(-6,-9,-11,LOG_2:13)
Block(-6,-9,-10,LOG_2:13)
Block(-6,-9,-9,LOG:13)
Block(-6,-9,-8,LOG:13)
Block(-6,-9,-1,LOG_2:13)
Block(-6,-8,-6,LOG:13)
Block(-6,-8,-5,LOG_2:13)
Block(-6,-7,-5,LOG:13)
Block(-6,-6,3,LOG_2:13)
Block(-6,-5,3,LOG_2:13)
Block(-6,-5,4,LOG_2:13)
Block(-6,-4,4,LOG:13)
Block(-6,53,2,LOG:13)
Block(-6,53,3,LOG:13)
Block(-6,62,3,LOG:13)
Block(-6,64,0,LOG:13)
Block(-6,68,-2,LOG:13)
Block(-6,69,4,LOG:13)
Block(-6,87,2,LOG:13)
Block(-5,-9,-10,LOG:13)
Block(-5,-9,-8,LOG:13)
Block(-5,-9,-1,LOG_2:13)
Block(-5,-9,0,LOG:13)
Block(-5,-8,0,LOG:13)
Block(-5,-8,1,LOG:13)
Block(-5,-8,8,LOG_2:13)
Block(-5,-8,9,LOG_2:13)
Block(-5,-7,-6,LOG_2:13)
Block(-5,-7,-5,LOG_2:13)
Block(-5,-7,7,LOG:13)
Block(-5,-7,8,LOG:13)
Block(-5,-6,-5,LOG_2:13)
Block(-5,-6,-4,LOG:13)
Block(-5,-6,7,LOG:13)
Block(-5,-5,-5,LOG_2:13)
Block(-5,-5,-4,LOG_2:13)
Block(-5,-5,7,LOG:13)
Block(-5,-4,4,LOG_2:13)
Block(-5,-4,5,LOG_2:13)
Block(-5,-4,6,LOG_2:13)
Block(-5,50,-2,LOG:13)
Block(-5,51,-2,LOG:13)
Block(-5,53,3,LOG:13)
Block(-5,53,4,LOG:13)
Block(-5,53,5,LOG:13)
Block(-5,55,-1,LOG:13)
Block(-5,55,0,LOG:13)
Block(-5,55,1,LOG:13)
Block(-5,56,6,LOG:13)
Block(-5,62,3,LOG:13)
Block(-5,64,0,LOG:13)
Block(-5,67,-3,LOG:13)
Block(-5,67,-2,LOG:13)
Block(-5,69,4,LOG:13)
Block(-5,69,5,LOG:13)
Block(-5,80,0,LOG:13)
Block(-5,86,2,LOG:13)
Block(-5,87,2,LOG:13)
Block(-5,87,3,LOG:13)
Block(-4,-8,1,LOG:13)
Block(-4,-8,2,LOG_2:13)
Block(-4,-8,9,LOG:13)
Block(-4,-5,-5,LOG_2:13)
Block(-4,-5,-4,LOG_2:13)
Block(-4,-4,-4,LOG_2:13)
Block(-4,-4,-3,LOG_2:13)
Block(-4,-4,5,LOG_2:13)
Block(-4,-4,6,LOG_2:13)
Block(-4,-4,7,LOG_2:13)
Block(-4,-3,-3,LOG_2:13)
Block(-4,-3,-2,LOG_2:13)
Block(-4,49,-5,LOG:13)
Block(-4,49,-4,LOG:13)
Block(-4,49,-3,LOG:13)
Block(-4,50,-5,LOG:13)
Block(-4,50,-2,LOG:13)
Block(-4,51,3,LOG:13)
Block(-4,51,4,LOG:13)
Block(-4,53,3,LOG:13)
Block(-4,54,-1,LOG:13)
Block(-4,55,-1,LOG:13)
Block(-4,55,1,LOG:13)
Block(-4,55,2,LOG:13)
Block(-4,56,1,LOG:13)
Block(-4,56,6,LOG:13)
Block(-4,62,-4,LOG:13)
Block(-4,62,3,LOG:13)
Block(-4,63,-4,LOG:13)
Block(-4,64,0,LOG:13)
Block(-4,64,1,LOG:13)
Block(-4,65,9,LOG:13)
Block(-4,65,10,LOG:13)
Block(-4,67,-2,LOG:13)
Block(-4,67,-1,LOG:13)
Block(-4,68,4,LOG:13)
Block(-4,69,0,LOG:13)
Block(-4,69,4,LOG:13)
Block(-4,70,4,LOG:13)
Block(-4,74,1,LOG:13)
Block(-4,79,0,LOG:13)
Block(-4,80,-1,LOG:13)
Block(-4,80,0,LOG:13)
Block(-4,86,2,LOG:13)
Block(-4,90,-2,LOG:13)
Block(-3,-8,2,LOG:13)
Block(-3,-8,9,LOG:13)
Block(-3,-7,2,LOG:13)
Block(-3,-5,-4,LOG_2:13)
Block(-3,-4,-4,LOG_2:13)
Block(-3,-4,-3,LOG_2:13)
Block(-3,-4,-2,LOG_2:13)
Block(-3,-4,5,LOG_2:13)
Block(-3,-3,-4,LOG:13)
Block(-3,-3,-3,LOG:13)
Block(-3,-3,-2,LOG:13)
Block(-3,-3,4,LOG:13)
Block(-3,-3,5,LOG:13)
Block(-3,-3,6,LOG_2:13)
Block(-3,-2,-3,LOG:13)
Block(-3,-2,-2,LOG:13)
Block(-3,-2,3,LOG:13)
Block(-3,-2,4,LOG:13)
Block(-3,-2,5,LOG:13)
Block(-3,-1,-3,LOG:13)
Block(-3,-1,-2,LOG:13)
Block(-3,-1,3,LOG:13)
Block(-3,-1,4,LOG:13)
Block(-3,-1,5,LOG:13)
Block(-3,0,-3,LOG:13)
Block(-3,0,-2,LOG:13)
Block(-3,0,-1,LOG:13)
Block(-3,0,3,LOG_2:13)
Block(-3,0,4,LOG_2:13)
Block(-3,0,5,LOG_2:13)
Block(-3,1,-3,LOG:13)
Block(-3,1,-2,LOG:13)
Block(-3,1,-1,LOG:13)
Block(-3,1,3,LOG_2:13)
Block(-3,1,4,LOG_2:13)
Block(-3,1,5,LOG_2:13)
Block(-3,2,-3,LOG:13)
Block(-3,2,-2,LOG:13)
Block(-3,2,-1,LOG:13)
Block(-3,2,4,LOG_2:13)
Block(-3,3,-3,LOG:13)
Block(-3,3,-2,LOG:13)
Block(-3,3,-1,LOG:13)
Block(-3,3,3,LOG:13)
Block(-3,3,4,LOG_2:13)
Block(-3,4,-3,LOG_2:13)
Block(-3,4,-2,LOG_2:13)
Block(-3,4,-1,LOG:13)
Block(-3,4,4,LOG_2:13)
Block(-3,5,-2,LOG_2:13)
Block(-3,47,-3,LOG:13)
Block(-3,47,-2,LOG:13)
Block(-3,48,-5,LOG:13)
Block(-3,48,-1,LOG:13)
Block(-3,49,-3,LOG:13)
Block(-3,49,-2,LOG:13)
Block(-3,51,3,LOG:13)
Block(-3,52,3,LOG:13)
Block(-3,53,1,LOG:13)
Block(-3,53,3,LOG:13)
Block(-3,54,-1,LOG:13)
Block(-3,54,2,LOG:13)
Block(-3,54,3,LOG:13)
Block(-3,55,2,LOG:13)
Block(-3,56,5,LOG:13)
Block(-3,56,6,LOG:13)
Block(-3,57,5,LOG:13)
Block(-3,60,-6,LOG:13)
Block(-3,60,-5,LOG:13)
Block(-3,60,-4,LOG:13)
Block(-3,61,-4,LOG:13)
Block(-3,62,-4,LOG:13)
Block(-3,62,2,LOG:13)
Block(-3,62,3,LOG:13)
Block(-3,63,2,LOG:13)
Block(-3,64,1,LOG:13)
Block(-3,64,7,LOG:13)
Block(-3,64,8,LOG:13)
Block(-3,65,8,LOG:13)
Block(-3,65,9,LOG:13)
Block(-3,67,-1,LOG:13)
Block(-3,68,-1,LOG:13)
Block(-3,68,0,LOG:13)
Block(-3,68,3,LOG:13)
Block(-3,68,4,LOG:13)
Block(-3,68,5,LOG:13)
Block(-3,69,-4,LOG:13)
Block(-3,69,-3,LOG:13)
Block(-3,69,0,LOG:13)
Block(-3,71,-3,LOG:13)
Block(-3,74,1,LOG:13)
Block(-3,74,2,LOG:13)
Block(-3,74,5,LOG:13)
Block(-3,74,6,LOG:13)
Block(-3,75,2,LOG:13)
Block(-3,75,5,LOG:13)
Block(-3,80,0,LOG:13)
Block(-3,81,0,LOG:13)
Block(-3,86,1,LOG:13)
Block(-3,86,2,LOG:13)
Block(-3,89,-1,LOG:13)
Block(-3,89,0,LOG:13)
Block(-3,90,-2,LOG:13)
Block(-3,90,-1,LOG:13)
Block(-3,91,-1,LOG:13)
Block(-2,-9,3,LOG:13)
Block(-2,-8,9,LOG_2:13)
Block(-2,-7,2,LOG:13)
Block(-2,-3,-2,LOG:13)
Block(-2,-3,4,LOG:13)
Block(-2,-3,6,LOG:13)
Block(-2,-2,-3,LOG:13)
Block(-2,-2,-2,LOG:13)
Block(-2,-2,-1,LOG:13)
Block(-2,-2,1,LOG_2:13)
Block(-2,-2,2,LOG_2:13)
Block(-2,-2,3,LOG:13)
Block(-2,-2,4,LOG:13)
Block(-2,-2,5,LOG:13)
Block(-2,-1,-3,LOG:13)
Block(-2,-1,-2,LOG:13)
Block(-2,-1,-1,LOG:13)
Block(-2,-1,1,LOG_2:13)
Block(-2,-1,2,LOG_2:13)
Block(-2,-1,3,LOG:13)
Block(-2,-1,4,LOG:13)
Block(-2,-1,5,LOG_2:13)
Block(-2,0,-3,LOG_2:13)
Block(-2,0,-2,LOG:13)
Block(-2,0,-1,LOG:13)
Block(-2,0,2,LOG_2:13)
Block(-2,0,3,LOG_2:13)
Block(-2,0,4,LOG_2:13)
Block(-2,0,5,LOG_2:13)
Block(-2,1,-3,LOG_2:13)
Block(-2,1,-2,LOG_2:13)
Block(-2,1,-1,LOG:13)
Block(-2,1,2,LOG_2:13)
Block(-2,1,3,LOG_2:13)
Block(-2,1,4,LOG_2:13)
Block(-2,1,5,LOG_2:13)
Block(-2,1,6,LOG_2:13)
Block(-2,2,-3,LOG_2:13)
Block(-2,2,-2,LOG_2:13)
Block(-2,2,-1,LOG_2:13)
Block(-2,2,0,LOG:13)
Block(-2,2,2,LOG:13)
Block(-2,2,3,LOG:13)
Block(-2,2,4,LOG:13)
Block(-2,2,5,LOG_2:13)
Block(-2,2,6,LOG_2:13)
Block(-2,3,-3,LOG_2:13)
Block(-2,3,-2,LOG_2:13)
Block(-2,3,-1,LOG_2:13)
Block(-2,3,0,LOG:13)
Block(-2,3,1,LOG:13)
Block(-2,3,2,LOG:13)
Block(-2,3,3,LOG:13)
Block(-2,3,4,LOG:13)
Block(-2,3,5,LOG_2:13)
Block(-2,4,-2,LOG_2:13)
Block(-2,4,-1,LOG_2:13)
Block(-2,4,0,LOG_2:13)
Block(-2,4,1,LOG:13)
Block(-2,4,2,LOG:13)
Block(-2,4,3,LOG:13)
Block(-2,4,4,LOG:13)
Block(-2,4,5,LOG_2:13)
Block(-2,5,-2,LOG_2:13)
Block(-2,5,-1,LOG_2:13)
Block(-2,5,0,LOG_2:13)
Block(-2,5,1,LOG:13)
Block(-2,5,2,LOG:13)
Block(-2,5,3,LOG:13)
Block(-2,5,4,LOG:13)
Block(-2,5,5,LOG_2:13)
Block(-2,6,-2,LOG_2:13)
Block(-2,6,-1,LOG_2:13)
Block(-2,6,0,LOG_2:13)
Block(-2,6,2,LOG:13)
Block(-2,6,3,LOG_2:13)
Block(-2,6,4,LOG_2:13)
Block(-2,7,-2,LOG_2:13)
Block(-2,7,-1,LOG_2:13)
Block(-2,7,0,LOG_2:13)
Block(-2,7,3,LOG_2:13)
Block(-2,8,-2,LOG:13)
Block(-2,8,-1,LOG:13)
Block(-2,8,0,LOG:13)
Block(-2,8,2,LOG_2:13)
Block(-2,8,3,LOG_2:13)
Block(-2,9,-2,LOG:13)
Block(-2,9,-1,LOG:13)
Block(-2,9,0,LOG:13)
Block(-2,9,2,LOG_2:13)
Block(-2,9,3,LOG_2:13)
Block(-2,10,-2,LOG:13)
Block(-2,10,-1,LOG:13)
Block(-2,10,0,LOG:13)
Block(-2,10,2,LOG_2:13)
Block(-2,10,3,LOG:13)
Block(-2,11,-2,LOG:13)
Block(-2,11,-1,LOG:13)
Block(-2,11,0,LOG_2:13)
Block(-2,11,2,LOG_2:13)
Block(-2,11,3,LOG:13)
Block(-2,12,-2,LOG:13)
Block(-2,12,0,LOG:13)
Block(-2,12,2,LOG_2:13)
Block(-2,12,3,LOG:13)
Block(-2,13,-2,LOG:13)
Block(-2,13,0,LOG_2:13)
Block(-2,13,2,LOG_2:13)
Block(-2,13,3,LOG_2:13)
Block(-2,14,2,LOG_2:13)
Block(-2,14,3,LOG_2:13)
Block(-2,15,2,LOG:13)
Block(-2,15,3,LOG_2:13)
Block(-2,16,2,LOG:13)
Block(-2,16,3,LOG:13)
Block(-2,17,2,LOG:13)
Block(-2,18,2,LOG:13)
Block(-2,19,2,LOG:13)
Block(-2,48,-1,LOG:13)
Block(-2,49,-2,LOG:13)
Block(-2,49,-1,LOG:13)
Block(-2,52,3,LOG:13)
Block(-2,57,5,LOG:13)
Block(-2,58,8,LOG:13)
Block(-2,58,9,LOG:13)
Block(-2,61,-4,LOG:13)
Block(-2,61,-3,LOG:13)
Block(-2,63,2,LOG:13)
Block(-2,63,5,LOG:13)
Block(-2,63,6,LOG:13)
Block(-2,64,1,LOG:13)
Block(-2,64,2,LOG:13)
Block(-2,64,6,LOG:13)
Block(-2,64,7,LOG:13)
Block(-2,67,-4,LOG:13)
Block(-2,67,-3,LOG:13)
Block(-2,68,-3,LOG:13)
Block(-2,68,-2,LOG:13)
Block(-2,68,-1,LOG:13)
Block(-2,68,3,LOG:13)
Block(-2,69,-3,LOG:13)
Block(-2,70,-3,LOG:13)
Block(-2,71,-3,LOG:13)
Block(-2,73,2,LOG:13)
Block(-2,73,5,LOG:13)
Block(-2,74,2,LOG:13)
Block(-2,74,4,LOG:13)
Block(-2,74,5,LOG:13)
Block(-2,79,5,LOG:13)
Block(-2,80,-1,LOG:13)
Block(-2,80,0,LOG:13)
Block(-2,80,1,LOG:13)
Block(-2,85,1,LOG:13)
Block(-2,86,0,LOG:13)
Block(-2,86,1,LOG:13)
Block(-2,87,0,LOG:13)
Block(-2,87,1,LOG:13)
Block(-2,87,4,LOG:13)
Block(-2,87,5,LOG:13)
Block(-2,88,0,LOG:13)
Block(-2,88,1,LOG:13)
Block(-2,89,0,LOG:13)
Block(-1,-10,4,LOG:13)
Block(-1,-9,3,LOG:13)
Block(-1,-9,4,LOG:13)
Block(-1,-9,5,LOG:13)
Block(-1,-9,9,LOG:13)
Block(-1,-8,5,LOG_2:13)
Block(-1,-8,9,LOG_2:13)
Block(-1,-7,2,LOG_2:13)
Block(-1,-6,2,LOG_2:13)
Block(-1,-3,-2,LOG:13)
Block(-1,-2,-2,LOG:13)
Block(-1,-2,-1,LOG:13)
Block(-1,-2,0,LOG:13)
Block(-1,-2,1,LOG:13)
Block(-1,-2,2,LOG:13)
Block(-1,-2,5,LOG:13)
Block(-1,-1,-2,LOG:13)
Block(-1,-1,-1,LOG:13)
Block(-1,-1,0,LOG:13)
Block(-1,-1,1,LOG:13)
Block(-1,-1,2,LOG_2:13)
Block(-1,-1,3,LOG:13)
Block(-1,-1,4,LOG:13)
Block(-1,-1,5,LOG:13)
Block(-1,0,-3,LOG:13)
Block(-1,0,-2,LOG:13)
Block(-1,0,-1,LOG:13)
Block(-1,0,0,LOG:13)
Block(-1,0,1,LOG:13)
Block(-1,0,2,LOG_2:13)
Block(-1,0,4,LOG_2:13)
Block(-1,0,5,LOG_2:13)
Block(-1,1,-3,LOG_2:13)
Block(-1,1,-2,LOG_2:13)
Block(-1,1,-1,LOG:13)
Block(-1,1,0,LOG:13)
Block(-1,1,1,LOG_2:13)
Block(-1,1,2,LOG_2:13)
Block(-1,1,4,LOG_2:13)
Block(-1,1,5,LOG_2:13)
Block(-1,2,-2,LOG_2:13)
Block(-1,2,-1,LOG_2:13)
Block(-1,2,0,LOG_2:13)
Block(-1,2,1,LOG_2:13)
Block(-1,2,2,LOG_2:13)
Block(-1,2,4,LOG:13)
Block(-1,2,5,LOG:13)
Block(-1,3,-2,LOG_2:13)
Block(-1,3,-1,LOG_2:13)
Block(-1,3,0,LOG_2:13)
Block(-1,3,1,LOG_2:13)
Block(-1,3,2,LOG:13)
Block(-1,3,4,LOG:13)
Block(-1,3,5,LOG:13)
Block(-1,4,-2,LOG_2:13)
Block(-1,4,-1,LOG_2:13)
Block(-1,4,0,LOG_2:13)
Block(-1,4,1,LOG_2:13)
Block(-1,4,2,LOG:13)
Block(-1,4,3,LOG:13)
Block(-1,4,4,LOG:13)
Block(-1,4,5,LOG_2:13)
Block(-1,5,-2,LOG:13)
Block(-1,5,-1,LOG_2:13)
Block(-1,5,0,LOG_2:13)
Block(-1,5,1,LOG_2:13)
Block(-1,5,2,LOG_2:13)
Block(-1,5,3,LOG_2:13)
Block(-1,5,4,LOG_2:13)
Block(-1,5,5,LOG_2:13)
Block(-1,6,-1,LOG_2:13)
Block(-1,6,0,LOG_2:13)
Block(-1,6,1,LOG:13)
Block(-1,6,2,LOG:13)
Block(-1,6,3,LOG_2:13)
Block(-1,6,4,LOG_2:13)
Block(-1,6,5,LOG_2:13)
Block(-1,7,-1,LOG:13)
Block(-1,7,0,LOG:13)
Block(-1,7,1,LOG:13)
Block(-1,7,2,LOG:13)
Block(-1,7,3,LOG_2:13)
Block(-1,7,4,LOG_2:13)
Block(-1,8,-1,LOG:13)
Block(-1,8,0,LOG:13)
Block(-1,8,1,LOG:13)
Block(-1,8,2,LOG:13)
Block(-1,8,3,LOG:13)
Block(-1,8,4,LOG_2:13)
Block(-1,9,-1,LOG:13)
Block(-1,9,0,LOG:13)
Block(-1,9,1,LOG_2:13)
Block(-1,9,2,LOG_2:13)
Block(-1,9,3,LOG:13)
Block(-1,9,4,LOG:13)
Block(-1,10,-1,LOG:13)
Block(-1,10,0,LOG_2:13)
Block(-1,10,1,LOG_2:13)
Block(-1,10,2,LOG_2:13)
Block(-1,10,3,LOG:13)
Block(-1,10,4,LOG:13)
Block(-1,11,-2,LOG:13)
Block(-1,11,-1,LOG_2:13)
Block(-1,11,0,LOG_2:13)
Block(-1,11,1,LOG_2:13)
Block(-1,11,2,LOG_2:13)
Block(-1,11,3,LOG:13)
Block(-1,11,4,LOG:13)
Block(-1,12,-2,LOG:13)
Block(-1,12,-1,LOG:13)
Block(-1,12,0,LOG_2:13)
Block(-1,12,1,LOG_2:13)
Block(-1,12,2,LOG_2:13)
Block(-1,12,3,LOG:13)
Block(-1,12,4,LOG:13)
Block(-1,13,-2,LOG:13)
Block(-1,13,-1,LOG_2:13)
Block(-1,13,0,LOG_2:13)
Block(-1,13,1,LOG_2:13)
Block(-1,13,2,LOG_2:13)
Block(-1,13,3,LOG_2:13)
Block(-1,13,4,LOG_2:13)
Block(-1,14,-2,LOG:13)
Block(-1,14,-1,LOG_2:13)
Block(-1,14,0,LOG_2:13)
Block(-1,14,1,LOG_2:13)
Block(-1,14,2,LOG_2:13)
Block(-1,14,3,LOG_2:13)
Block(-1,14,4,LOG_2:13)
Block(-1,15,-2,LOG:13)
Block(-1,15,-1,LOG:13)
Block(-1,15,0,LOG:13)
Block(-1,15,1,LOG_2:13)
Block(-1,15,2,LOG_2:13)
Block(-1,15,3,LOG_2:13)
Block(-1,15,4,LOG_2:13)
Block(-1,16,-2,LOG:13)
Block(-1,16,-1,LOG:13)
Block(-1,16,0,LOG:13)
Block(-1,16,1,LOG:13)
Block(-1,16,2,LOG:13)
Block(-1,16,3,LOG_2:13)
Block(-1,17,-2,LOG:13)
Block(-1,17,-1,LOG:13)
Block(-1,17,0,LOG:13)
Block(-1,17,1,LOG:13)
Block(-1,17,2,LOG:13)
Block(-1,17,3,LOG_2:13)
Block(-1,18,-1,LOG:13)
Block(-1,18,0,LOG:13)
Block(-1,18,1,LOG:13)
Block(-1,18,2,LOG:13)
Block(-1,18,3,LOG_2:13)
Block(-1,19,-1,LOG:13)
Block(-1,19,0,LOG:13)
Block(-1,19,1,LOG:13)
Block(-1,19,2,LOG:13)
Block(-1,19,3,LOG_2:13)
Block(-1,20,-1,LOG:13)
Block(-1,20,1,LOG:13)
Block(-1,20,2,LOG_2:13)
Block(-1,20,3,LOG_2:13)
Block(-1,21,1,LOG_2:13)
Block(-1,21,2,LOG_2:13)
Block(-1,21,3,LOG_2:13)
Block(-1,22,1,LOG_2:13)
Block(-1,22,2,LOG_2:13)
Block(-1,22,3,LOG:13)
Block(-1,23,1,LOG_2:13)
Block(-1,23,2,LOG:13)
Block(-1,23,3,LOG:13)
Block(-1,24,1,LOG:13)
Block(-1,24,2,LOG:13)
Block(-1,24,3,LOG:13)
Block(-1,25,1,LOG_2:13)
Block(-1,25,2,LOG:13)
Block(-1,26,1,LOG_2:13)
Block(-1,26,2,LOG_2:13)
Block(-1,27,1,LOG_2:13)
Block(-1,27,2,LOG_2:13)
Block(-1,28,1,LOG_2:13)
Block(-1,28,2,LOG_2:13)
Block(-1,29,1,LOG_2:13)
Block(-1,29,2,LOG_2:13)
Block(-1,30,1,LOG:13)
Block(-1,30,2,LOG_2:13)
Block(-1,31,1,LOG:13)
Block(-1,31,2,LOG:13)
Block(-1,32,1,LOG:13)
Block(-1,32,2,LOG:13)
Block(-1,33,1,LOG_2:13)
Block(-1,33,2,LOG:13)
Block(-1,34,1,LOG_2:13)
Block(-1,34,2,LOG_2:13)
Block(-1,35,1,LOG:13)
Block(-1,35,2,LOG:13)
Block(-1,36,1,LOG:13)
Block(-1,36,2,LOG:13)
Block(-1,37,1,LOG:13)
Block(-1,37,2,LOG:13)
Block(-1,38,1,LOG:13)
Block(-1,38,2,LOG:13)
Block(-1,39,1,LOG:13)
Block(-1,39,2,LOG:13)
Block(-1,40,1,LOG:13)
Block(-1,40,2,LOG:13)
Block(-1,41,1,LOG:13)
Block(-1,41,2,LOG:13)
Block(-1,42,1,LOG:13)
Block(-1,42,2,LOG:13)
Block(-1,43,1,LOG:13)
Block(-1,43,2,LOG:13)
Block(-1,44,1,LOG:13)
Block(-1,44,2,LOG:13)
Block(-1,45,1,LOG:13)
Block(-1,46,1,LOG:13)
Block(-1,48,-1,LOG:13)
Block(-1,48,0,LOG:13)
Block(-1,49,-1,LOG:13)
Block(-1,49,0,LOG:13)
Block(-1,51,2,LOG:13)
Block(-1,51,3,LOG:13)
Block(-1,52,3,LOG:13)
Block(-1,53,4,LOG:13)
Block(-1,53,5,LOG:13)
Block(-1,57,5,LOG:13)
Block(-1,58,6,LOG:13)
Block(-1,58,7,LOG:13)
Block(-1,58,8,LOG:13)
Block(-1,61,-3,LOG:13)
Block(-1,61,-2,LOG:13)
Block(-1,62,3,LOG:13)
Block(-1,62,4,LOG:13)
Block(-1,63,2,LOG:13)
Block(-1,63,4,LOG:13)
Block(-1,63,5,LOG:13)
Block(-1,64,6,LOG:13)
Block(-1,65,6,LOG:13)
Block(-1,65,7,LOG:13)
Block(-1,67,-4,LOG:13)
Block(-1,67,-1,LOG:13)
Block(-1,67,0,LOG:13)
Block(-1,68,-1,LOG:13)
Block(-1,68,2,LOG:13)
Block(-1,68,3,LOG:13)
Block(-1,68,4,LOG:13)
Block(-1,69,4,LOG:13)
Block(-1,73,3,LOG:13)
Block(-1,74,3,LOG:13)
Block(-1,74,4,LOG:13)
Block(-1,75,4,LOG:13)
Block(-1,78,5,LOG:13)
Block(-1,78,6,LOG:13)
Block(-1,78,7,LOG:13)
Block(-1,79,8,LOG:13)
Block(-1,80,1,LOG:13)
Block(-1,81,1,LOG:13)
Block(-1,82,1,LOG:13)
Block(-1,82,3,LOG:13)
Block(-1,83,0,LOG:13)
Block(-1,83,1,LOG:13)
Block(-1,84,0,LOG:13)
Block(-1,84,1,LOG:13)
Block(-1,85,0,LOG:13)
Block(-1,85,1,LOG:13)
Block(-1,85,4,LOG:13)
Block(-1,86,0,LOG:13)
Block(-1,86,1,LOG:13)
Block(-1,86,2,LOG:13)
Block(-1,86,3,LOG:13)
Block(-1,86,4,LOG:13)
Block(-1,87,-2,LOG:13)
Block(-1,87,-1,LOG:13)
Block(-1,87,0,LOG:13)
Block(-1,87,1,LOG:13)
Block(-1,87,4,LOG:13)
Block(-1,88,-3,LOG:13)
Block(-1,88,-2,LOG:13)
Block(-1,88,0,LOG:13)
Block(-1,88,1,LOG:13)
Block(-1,89,0,LOG:13)
Block(-1,89,1,LOG:13)
Block(-1,89,2,LOG:13)
Block(-1,89,3,LOG:13)
Block(-1,90,2,LOG:13)
Block(-1,91,0,LOG:13)
Block(0,-8,-3,LOG:13)
Block(0,-8,-2,LOG:13)
Block(0,-8,5,LOG_2:13)
Block(0,-8,6,LOG_2:13)
Block(0,-7,-3,LOG:13)
Block(0,-7,-2,LOG:13)
Block(0,-7,-1,LOG:13)
Block(0,-7,0,LOG_2:13)
Block(0,-7,5,LOG_2:13)
Block(0,-7,6,LOG_2:13)
Block(0,-6,0,LOG_2:13)
Block(0,-6,1,LOG_2:13)
Block(0,-6,2,LOG_2:13)
Block(0,-5,1,LOG_2:13)
Block(0,-5,2,LOG_2:13)
Block(0,-3,0,LOG:13)
Block(0,-2,-1,LOG:13)
Block(0,-2,0,LOG:13)
Block(0,-2,1,LOG:13)
Block(0,-2,2,LOG:13)
Block(0,-2,3,LOG:13)
Block(0,-1,-1,LOG:13)
Block(0,-1,0,LOG:13)
Block(0,-1,1,LOG:13)
Block(0,-1,2,LOG:13)
Block(0,-1,3,LOG:13)
Block(0,-1,4,LOG:13)
Block(0,0,-1,LOG:13)
Block(0,0,0,LOG_2:13)
Block(0,0,1,LOG:13)
Block(0,0,2,LOG_2:13)
Block(0,0,3,LOG_2:13)
Block(0,0,4,LOG:13)
Block(0,1,-1,LOG:13)
Block(0,1,0,LOG:13)
Block(0,1,1,LOG:13)
Block(0,1,2,LOG_2:13)
Block(0,1,3,LOG_2:13)
Block(0,1,4,LOG_2:13)
Block(0,2,-1,LOG:13)
Block(0,2,0,LOG:13)
Block(0,2,1,LOG_2:13)
Block(0,2,2,LOG_2:13)
Block(0,2,3,LOG_2:13)
Block(0,2,4,LOG:13)
Block(0,3,-1,LOG:13)
Block(0,3,0,LOG_2:13)
Block(0,3,1,LOG_2:13)
Block(0,3,2,LOG_2:13)
Block(0,3,3,LOG:13)
Block(0,3,4,LOG:13)
Block(0,4,-1,LOG_2:13)
Block(0,4,0,LOG_2:13)
Block(0,4,1,LOG_2:13)
Block(0,4,2,LOG_2:13)
Block(0,4,3,LOG:13)
Block(0,4,4,LOG:13)
Block(0,5,-1,LOG_2:13)
Block(0,5,0,LOG_2:13)
Block(0,5,1,LOG_2:13)
Block(0,5,2,LOG_2:13)
Block(0,5,3,LOG_2:13)
Block(0,5,4,LOG_2:13)
Block(0,6,-1,LOG_2:13)
Block(0,6,0,LOG:13)
Block(0,6,1,LOG:13)
Block(0,6,2,LOG:13)
Block(0,6,3,LOG_2:13)
Block(0,6,4,LOG_2:13)
Block(0,7,-2,LOG_2:13)
Block(0,7,-1,LOG:13)
Block(0,7,0,LOG:13)
Block(0,7,1,LOG:13)
Block(0,7,2,LOG:13)
Block(0,7,3,LOG_2:13)
Block(0,7,4,LOG_2:13)
Block(0,8,-2,LOG:13)
Block(0,8,-1,LOG:13)
Block(0,8,0,LOG:13)
Block(0,8,1,LOG:13)
Block(0,8,2,LOG:13)
Block(0,8,3,LOG:13)
Block(0,8,4,LOG:13)
Block(0,9,-2,LOG:13)
Block(0,9,-1,LOG:13)
Block(0,9,0,LOG:13)
Block(0,9,1,LOG:13)
Block(0,9,2,LOG:13)
Block(0,9,3,LOG:13)
Block(0,9,4,LOG:13)
Block(0,10,-2,LOG:13)
Block(0,10,-1,LOG_2:13)
Block(0,10,0,LOG_2:13)
Block(0,10,1,LOG_2:13)
Block(0,10,2,LOG:13)
Block(0,10,3,LOG:13)
Block(0,11,-2,LOG_2:13)
Block(0,11,-1,LOG_2:13)
Block(0,11,0,LOG_2:13)
Block(0,11,1,LOG_2:13)
Block(0,11,2,LOG:13)
Block(0,11,3,LOG:13)
Block(0,12,-2,LOG:13)
Block(0,12,-1,LOG_2:13)
Block(0,12,0,LOG_2:13)
Block(0,12,1,LOG_2:13)
Block(0,12,2,LOG:13)
Block(0,12,3,LOG:13)
Block(0,13,-2,LOG:13)
Block(0,13,-1,LOG_2:13)
Block(0,13,0,LOG_2:13)
Block(0,13,1,LOG_2:13)
Block(0,13,2,LOG_2:13)
Block(0,13,3,LOG:13)
Block(0,13,4,LOG_2:13)
Block(0,14,-2,LOG:13)
Block(0,14,-1,LOG_2:13)
Block(0,14,0,LOG_2:13)
Block(0,14,1,LOG_2:13)
Block(0,14,2,LOG_2:13)
Block(0,14,3,LOG_2:13)
Block(0,14,4,LOG_2:13)
Block(0,15,-1,LOG:13)
Block(0,15,0,LOG_2:13)
Block(0,15,1,LOG_2:13)
Block(0,15,2,LOG_2:13)
Block(0,15,3,LOG_2:13)
Block(0,15,4,LOG_2:13)
Block(0,16,-1,LOG:13)
Block(0,16,0,LOG:13)
Block(0,16,1,LOG_2:13)
Block(0,16,2,LOG_2:13)
Block(0,16,3,LOG_2:13)
Block(0,17,-1,LOG:13)
Block(0,17,0,LOG:13)
Block(0,17,1,LOG:13)
Block(0,17,2,LOG_2:13)
Block(0,17,3,LOG_2:13)
Block(0,18,-1,LOG:13)
Block(0,18,0,LOG:13)
Block(0,18,1,LOG:13)
Block(0,18,2,LOG_2:13)
Block(0,18,3,LOG_2:13)
Block(0,19,-1,LOG:13)
Block(0,19,0,LOG:13)
Block(0,19,1,LOG:13)
Block(0,19,2,LOG_2:13)
Block(0,19,3,LOG_2:13)
Block(0,20,-1,LOG:13)
Block(0,20,0,LOG:13)
Block(0,20,1,LOG_2:13)
Block(0,20,2,LOG_2:13)
Block(0,20,3,LOG_2:13)
Block(0,21,-1,LOG_2:13)
Block(0,21,0,LOG_2:13)
Block(0,21,1,LOG_2:13)
Block(0,21,2,LOG_2:13)
Block(0,21,3,LOG_2:13)
Block(0,22,-1,LOG_2:13)
Block(0,22,0,LOG_2:13)
Block(0,22,1,LOG_2:13)
Block(0,22,2,LOG:13)
Block(0,22,3,LOG:13)
Block(0,23,-1,LOG_2:13)
Block(0,23,0,LOG_2:13)
Block(0,23,1,LOG:13)
Block(0,23,2,LOG:13)
Block(0,23,3,LOG:13)
Block(0,24,-1,LOG:13)
Block(0,24,0,LOG_2:13)
Block(0,24,1,LOG:13)
Block(0,24,2,LOG:13)
Block(0,24,3,LOG:13)
Block(0,25,-1,LOG_2:13)
Block(0,25,0,LOG_2:13)
Block(0,25,1,LOG_2:13)
Block(0,25,2,LOG:13)
Block(0,25,3,LOG:13)
Block(0,26,-1,LOG:13)
Block(0,26,0,LOG_2:13)
Block(0,26,1,LOG_2:13)
Block(0,26,2,LOG_2:13)
Block(0,26,3,LOG:13)
Block(0,27,-1,LOG:13)
Block(0,27,0,LOG_2:13)
Block(0,27,1,LOG_2:13)
Block(0,27,2,LOG_2:13)
Block(0,27,3,LOG_2:13)
Block(0,28,0,LOG_2:13)
Block(0,28,1,LOG_2:13)
Block(0,28,2,LOG_2:13)
Block(0,28,3,LOG_2:13)
Block(0,29,0,LOG:13)
Block(0,29,1,LOG_2:13)
Block(0,29,2,LOG_2:13)
Block(0,29,3,LOG_2:13)
Block(0,30,0,LOG:13)
Block(0,30,1,LOG:13)
Block(0,30,2,LOG_2:13)
Block(0,30,3,LOG_2:13)
Block(0,31,0,LOG:13)
Block(0,31,1,LOG:13)
Block(0,31,2,LOG:13)
Block(0,31,3,LOG:13)
Block(0,32,0,LOG_2:13)
Block(0,32,1,LOG:13)
Block(0,32,2,LOG:13)
Block(0,32,3,LOG:13)
Block(0,33,0,LOG_2:13)
Block(0,33,1,LOG_2:13)
Block(0,33,2,LOG:13)
Block(0,33,3,LOG:13)
Block(0,34,0,LOG_2:13)
Block(0,34,1,LOG_2:13)
Block(0,34,2,LOG:13)
Block(0,34,3,LOG:13)
Block(0,35,0,LOG:13)
Block(0,35,1,LOG:13)
Block(0,35,2,LOG:13)
Block(0,35,3,LOG:13)
Block(0,36,0,LOG_2:13)
Block(0,36,1,LOG:13)
Block(0,36,2,LOG:13)
Block(0,36,3,LOG:13)
Block(0,37,0,LOG_2:13)
Block(0,37,1,LOG_2:13)
Block(0,37,2,LOG_2:13)
Block(0,37,3,LOG:13)
Block(0,38,0,LOG:13)
Block(0,38,1,LOG:13)
Block(0,38,2,LOG:13)
Block(0,38,3,LOG:13)
Block(0,39,0,LOG:13)
Block(0,39,1,LOG:13)
Block(0,39,2,LOG:13)
Block(0,39,3,LOG:13)
Block(0,40,0,LOG:13)
Block(0,40,1,LOG:13)
Block(0,40,2,LOG:13)
Block(0,40,3,LOG:13)
Block(0,41,0,LOG:13)
Block(0,41,1,LOG:13)
Block(0,41,2,LOG:13)
Block(0,42,0,LOG:13)
Block(0,42,1,LOG:13)
Block(0,42,2,LOG:13)
Block(0,43,0,LOG:13)
Block(0,43,1,LOG:13)
Block(0,43,2,LOG:13)
Block(0,43,3,LOG:13)
Block(0,44,0,LOG:13)
Block(0,44,1,LOG:13)
Block(0,44,2,LOG:13)
Block(0,44,3,LOG:13)
Block(0,45,0,LOG:13)
Block(0,45,1,LOG:13)
Block(0,45,2,LOG:13)
Block(0,45,3,LOG:13)
Block(0,46,0,LOG:13)
Block(0,46,1,LOG:13)
Block(0,46,2,LOG:13)
Block(0,46,3,LOG:13)
Block(0,47,-3,LOG:13)
Block(0,47,-1,LOG:13)
Block(0,47,0,LOG:13)
Block(0,47,1,LOG:13)
Block(0,47,2,LOG:13)
Block(0,47,5,LOG:13)
Block(0,48,-1,LOG:13)
Block(0,48,0,LOG:13)
Block(0,48,1,LOG:13)
Block(0,48,2,LOG:13)
Block(0,49,0,LOG:13)
Block(0,49,1,LOG:13)
Block(0,49,2,LOG:13)
Block(0,50,1,LOG:13)
Block(0,50,2,LOG:13)
Block(0,51,1,LOG:13)
Block(0,51,2,LOG:13)
Block(0,52,1,LOG:13)
Block(0,53,1,LOG:13)
Block(0,54,1,LOG:13)
Block(0,55,1,LOG:13)
Block(0,56,1,LOG:13)
Block(0,57,1,LOG:13)
Block(0,57,2,LOG:13)
Block(0,57,4,LOG:13)
Block(0,57,5,LOG:13)
Block(0,57,6,LOG:13)
Block(0,58,-3,LOG:13)
Block(0,58,1,LOG:13)
Block(0,58,2,LOG:13)
Block(0,58,6,LOG:13)
Block(0,59,-3,LOG:13)
Block(0,59,0,LOG:13)
Block(0,59,1,LOG:13)
Block(0,59,2,LOG:13)
Block(0,60,-2,LOG:13)
Block(0,60,-1,LOG:13)
Block(0,60,0,LOG:13)
Block(0,60,1,LOG:13)
Block(0,60,2,LOG:13)
Block(0,61,-4,LOG:13)
Block(0,61,-3,LOG:13)
Block(0,61,-2,LOG:13)
Block(0,61,-1,LOG:13)
Block(0,61,2,LOG:13)
Block(0,61,3,LOG:13)
Block(0,62,-4,LOG:13)
Block(0,62,2,LOG:13)
Block(0,62,3,LOG:13)
Block(0,63,-4,LOG:13)
Block(0,63,2,LOG:13)
Block(0,64,-4,LOG:13)
Block(0,65,7,LOG:13)
Block(0,65,8,LOG:13)
Block(0,66,2,LOG:13)
Block(0,66,8,LOG:13)
Block(0,66,9,LOG:13)
Block(0,67,0,LOG:13)
Block(0,67,1,LOG:13)
Block(0,67,2,LOG:13)
Block(0,68,-1,LOG:13)
Block(0,68,1,LOG:13)
Block(0,68,2,LOG:13)
Block(0,69,-2,LOG:13)
Block(0,69,-1,LOG:13)
Block(0,69,1,LOG:13)
Block(0,69,2,LOG:13)
Block(0,70,1,LOG:13)
Block(0,70,2,LOG:13)
Block(0,71,1,LOG:13)
Block(0,71,2,LOG:13)
Block(0,72,2,LOG:13)
Block(0,73,2,LOG:13)
Block(0,73,3,LOG:13)
Block(0,74,2,LOG:13)
Block(0,74,3,LOG:13)
Block(0,75,2,LOG:13)
Block(0,76,1,LOG:13)
Block(0,76,2,LOG:13)
Block(0,77,1,LOG:13)
Block(0,77,2,LOG:13)
Block(0,77,3,LOG:13)
Block(0,77,4,LOG:13)
Block(0,77,5,LOG:13)
Block(0,78,1,LOG:13)
Block(0,78,5,LOG:13)
Block(0,79,0,LOG:13)
Block(0,79,1,LOG:13)
Block(0,80,0,LOG:13)
Block(0,80,1,LOG:13)
Block(0,80,2,LOG:13)
Block(0,81,0,LOG:13)
Block(0,81,1,LOG:13)
Block(0,81,2,LOG:13)
Block(0,81,3,LOG:13)
Block(0,82,0,LOG:13)
Block(0,82,1,LOG:13)
Block(0,82,3,LOG:13)
Block(0,82,4,LOG:13)
Block(0,83,0,LOG:13)
Block(0,83,1,LOG:13)
Block(0,84,0,LOG:13)
Block(0,85,0,LOG:13)
Block(0,86,1,LOG:13)
Block(0,87,4,LOG:13)
Block(0,88,-2,LOG:13)
Block(0,89,0,LOG:13)
Block(0,90,-1,LOG:13)
Block(0,90,0,LOG:13)
Block(0,91,0,LOG:13)
Block(1,-8,-4,LOG_2:13)
Block(1,-8,-3,LOG:13)
Block(1,-7,-3,LOG_2:13)
Block(1,-7,6,LOG_2:13)
Block(1,-7,7,LOG:13)
Block(1,-6,1,LOG_2:13)
Block(1,-6,2,LOG_2:13)
Block(1,-5,1,LOG_2:13)
Block(1,-5,2,LOG_2:13)
Block(1,-4,0,LOG_2:13)
Block(1,-4,1,LOG_2:13)
Block(1,-4,2,LOG:13)
Block(1,-3,-2,LOG:13)
Block(1,-3,-1,LOG:13)
Block(1,-3,0,LOG:13)
Block(1,-3,1,LOG:13)
Block(1,-2,-3,LOG:13)
Block(1,-2,-2,LOG:13)
Block(1,-2,-1,LOG:13)
Block(1,-2,0,LOG_2:13)
Block(1,-2,2,LOG:13)
Block(1,-2,3,LOG:13)
Block(1,-1,-3,LOG:13)
Block(1,-1,-2,LOG:13)
Block(1,-1,-1,LOG_2:13)
Block(1,-1,0,LOG_2:13)
Block(1,-1,1,LOG:13)
Block(1,-1,2,LOG:13)
Block(1,-1,3,LOG:13)
Block(1,0,-3,LOG:13)
Block(1,0,-2,LOG:13)
Block(1,0,-1,LOG_2:13)
Block(1,0,0,LOG:13)
Block(1,0,1,LOG:13)
Block(1,0,2,LOG_2:13)
Block(1,0,3,LOG_2:13)
Block(1,1,-3,LOG:13)
Block(1,1,-2,LOG:13)
Block(1,1,-1,LOG:13)
Block(1,1,0,LOG:13)
Block(1,1,1,LOG:13)
Block(1,1,2,LOG_2:13)
Block(1,1,3,LOG_2:13)
Block(1,1,4,LOG_2:13)
Block(1,2,-3,LOG:13)
Block(1,2,-2,LOG:13)
Block(1,2,-1,LOG:13)
Block(1,2,0,LOG:13)
Block(1,2,1,LOG_2:13)
Block(1,2,2,LOG_2:13)
Block(1,2,3,LOG_2:13)
Block(1,2,4,LOG:13)
Block(1,3,-3,LOG:13)
Block(1,3,-2,LOG:13)
Block(1,3,-1,LOG:13)
Block(1,3,0,LOG:13)
Block(1,3,1,LOG:13)
Block(1,3,2,LOG_2:13)
Block(1,3,3,LOG:13)
Block(1,3,4,LOG:13)
Block(1,4,-3,LOG:13)
Block(1,4,-2,LOG:13)
Block(1,4,-1,LOG:13)
Block(1,4,0,LOG:13)
Block(1,4,1,LOG_2:13)
Block(1,4,2,LOG_2:13)
Block(1,4,3,LOG:13)
Block(1,4,4,LOG:13)
Block(1,5,-3,LOG:13)
Block(1,5,-2,LOG_2:13)
Block(1,5,-1,LOG_2:13)
Block(1,5,0,LOG_2:13)
Block(1,5,1,LOG_2:13)
Block(1,5,2,LOG_2:13)
Block(1,5,3,LOG_2:13)
Block(1,6,-2,LOG_2:13)
Block(1,6,-1,LOG_2:13)
Block(1,6,0,LOG:13)
Block(1,6,1,LOG:13)
Block(1,6,2,LOG_2:13)
Block(1,6,3,LOG_2:13)
Block(1,7,-2,LOG_2:13)
Block(1,7,-1,LOG:13)
Block(1,7,0,LOG:13)
Block(1,7,1,LOG:13)
Block(1,7,2,LOG:13)
Block(1,7,3,LOG:13)
Block(1,8,-2,LOG:13)
Block(1,8,-1,LOG:13)
Block(1,8,0,LOG:13)
Block(1,8,1,LOG:13)
Block(1,8,2,LOG:13)
Block(1,8,3,LOG:13)
Block(1,9,-2,LOG:13)
Block(1,9,-1,LOG:13)
Block(1,9,0,LOG:13)
Block(1,9,1,LOG:13)
Block(1,9,2,LOG:13)
Block(1,9,3,LOG:13)
Block(1,10,-2,LOG_2:13)
Block(1,10,-1,LOG_2:13)
Block(1,10,0,LOG_2:13)
Block(1,10,1,LOG:13)
Block(1,10,2,LOG:13)
Block(1,10,3,LOG:13)
Block(1,11,-2,LOG_2:13)
Block(1,11,-1,LOG_2:13)
Block(1,11,0,LOG_2:13)
Block(1,11,1,LOG:13)
Block(1,11,2,LOG:13)
Block(1,11,3,LOG:13)
Block(1,12,-2,LOG_2:13)
Block(1,12,-1,LOG_2:13)
Block(1,12,0,LOG_2:13)
Block(1,12,1,LOG:13)
Block(1,12,2,LOG:13)
Block(1,12,3,LOG:13)
Block(1,13,-2,LOG_2:13)
Block(1,13,-1,LOG_2:13)
Block(1,13,0,LOG:13)
Block(1,13,1,LOG:13)
Block(1,13,2,LOG:13)
Block(1,13,3,LOG:13)
Block(1,14,-2,LOG_2:13)
Block(1,14,-1,LOG:13)
Block(1,14,0,LOG:13)
Block(1,14,1,LOG:13)
Block(1,14,2,LOG:13)
Block(1,14,3,LOG:13)
Block(1,15,-1,LOG:13)
Block(1,15,0,LOG:13)
Block(1,15,1,LOG_2:13)
Block(1,15,2,LOG_2:13)
Block(1,15,3,LOG_2:13)
Block(1,16,-1,LOG:13)
Block(1,16,0,LOG:13)
Block(1,16,1,LOG_2:13)
Block(1,16,2,LOG_2:13)
Block(1,16,3,LOG_2:13)
Block(1,17,-1,LOG:13)
Block(1,17,0,LOG:13)
Block(1,17,1,LOG_2:13)
Block(1,17,2,LOG_2:13)
Block(1,18,-1,LOG:13)
Block(1,18,0,LOG:13)
Block(1,18,1,LOG_2:13)
Block(1,18,2,LOG:13)
Block(1,19,-1,LOG:13)
Block(1,19,0,LOG:13)
Block(1,19,1,LOG_2:13)
Block(1,19,2,LOG:13)
Block(1,20,-1,LOG_2:13)
Block(1,20,0,LOG_2:13)
Block(1,20,1,LOG_2:13)
Block(1,20,2,LOG_2:13)
Block(1,21,-1,LOG_2:13)
Block(1,21,0,LOG_2:13)
Block(1,21,1,LOG_2:13)
Block(1,21,2,LOG_2:13)
Block(1,22,-1,LOG_2:13)
Block(1,22,0,LOG_2:13)
Block(1,22,1,LOG_2:13)
Block(1,22,2,LOG_2:13)
Block(1,23,-1,LOG_2:13)
Block(1,23,0,LOG_2:13)
Block(1,23,1,LOG_2:13)
Block(1,23,2,LOG:13)
Block(1,24,-1,LOG:13)
Block(1,24,0,LOG_2:13)
Block(1,24,1,LOG:13)
Block(1,24,2,LOG:13)
Block(1,25,-1,LOG:13)
Block(1,25,0,LOG_2:13)
Block(1,25,1,LOG_2:13)
Block(1,25,2,LOG:13)
Block(1,25,3,LOG:13)
Block(1,26,-1,LOG:13)
Block(1,26,0,LOG_2:13)
Block(1,26,1,LOG_2:13)
Block(1,26,2,LOG_2:13)
Block(1,26,3,LOG:13)
Block(1,27,-1,LOG:13)
Block(1,27,0,LOG:13)
Block(1,27,1,LOG_2:13)
Block(1,27,2,LOG_2:13)
Block(1,27,3,LOG_2:13)
Block(1,28,-1,LOG:13)
Block(1,28,0,LOG:13)
Block(1,28,1,LOG:13)
Block(1,28,2,LOG_2:13)
Block(1,28,3,LOG_2:13)
Block(1,29,-1,LOG:13)
Block(1,29,0,LOG:13)
Block(1,29,1,LOG:13)
Block(1,29,2,LOG_2:13)
Block(1,29,3,LOG_2:13)
Block(1,30,-1,LOG:13)
Block(1,30,0,LOG:13)
Block(1,30,1,LOG:13)
Block(1,30,2,LOG:13)
Block(1,30,3,LOG:13)
Block(1,31,-1,LOG_2:13)
Block(1,31,0,LOG_2:13)
Block(1,31,1,LOG:13)
Block(1,31,2,LOG:13)
Block(1,31,3,LOG:13)
Block(1,32,0,LOG_2:13)
Block(1,32,1,LOG:13)
Block(1,32,2,LOG:13)
Block(1,32,3,LOG:13)
Block(1,33,0,LOG_2:13)
Block(1,33,1,LOG:13)
Block(1,33,2,LOG:13)
Block(1,33,3,LOG:13)
Block(1,34,0,LOG_2:13)
Block(1,34,1,LOG:13)
Block(1,34,2,LOG:13)
Block(1,34,3,LOG:13)
Block(1,35,0,LOG:13)
Block(1,35,1,LOG:13)
Block(1,35,2,LOG:13)
Block(1,35,3,LOG:13)
Block(1,36,0,LOG_2:13)
Block(1,36,1,LOG_2:13)
Block(1,36,2,LOG:13)
Block(1,36,3,LOG:13)
Block(1,37,0,LOG_2:13)
Block(1,37,1,LOG_2:13)
Block(1,37,2,LOG_2:13)
Block(1,37,3,LOG_2:13)
Block(1,38,0,LOG:13)
Block(1,38,1,LOG:13)
Block(1,38,2,LOG:13)
Block(1,38,3,LOG:13)
Block(1,39,0,LOG:13)
Block(1,39,1,LOG:13)
Block(1,39,2,LOG:13)
Block(1,39,3,LOG:13)
Block(1,40,0,LOG:13)
Block(1,40,1,LOG:13)
Block(1,40,2,LOG:13)
Block(1,41,0,LOG:13)
Block(1,41,1,LOG:13)
Block(1,41,2,LOG:13)
Block(1,42,0,LOG:13)
Block(1,42,1,LOG:13)
Block(1,42,2,LOG:13)
Block(1,43,0,LOG:13)
Block(1,43,1,LOG:13)
Block(1,43,2,LOG:13)
Block(1,43,3,LOG:13)
Block(1,44,0,LOG:13)
Block(1,44,1,LOG:13)
Block(1,44,2,LOG:13)
Block(1,44,3,LOG:13)
Block(1,45,0,LOG:13)
Block(1,45,1,LOG:13)
Block(1,45,2,LOG:13)
Block(1,45,3,LOG:13)
Block(1,46,-1,LOG:13)
Block(1,46,0,LOG:13)
Block(1,46,1,LOG:13)
Block(1,46,2,LOG:13)
Block(1,47,-3,LOG:13)
Block(1,47,-2,LOG:13)
Block(1,47,-1,LOG:13)
Block(1,47,0,LOG:13)
Block(1,47,1,LOG:13)
Block(1,47,2,LOG:13)
Block(1,47,3,LOG:13)
Block(1,48,-2,LOG:13)
Block(1,48,-1,LOG:13)
Block(1,48,0,LOG:13)
Block(1,48,1,LOG:13)
Block(1,48,2,LOG:13)
Block(1,48,3,LOG:13)
Block(1,48,4,LOG:13)
Block(1,49,0,LOG:13)
Block(1,49,1,LOG:13)
Block(1,49,2,LOG:13)
Block(1,50,0,LOG:13)
Block(1,50,1,LOG:13)
Block(1,50,2,LOG:13)
Block(1,50,6,LOG:13)
Block(1,51,0,LOG:13)
Block(1,51,1,LOG:13)
Block(1,51,2,LOG:13)
Block(1,52,0,LOG:13)
Block(1,52,1,LOG:13)
Block(1,52,2,LOG:13)
Block(1,53,1,LOG:13)
Block(1,53,2,LOG:13)
Block(1,54,1,LOG:13)
Block(1,54,2,LOG:13)
Block(1,55,1,LOG:13)
Block(1,55,2,LOG:13)
Block(1,56,1,LOG:13)
Block(1,56,2,LOG:13)
Block(1,56,3,LOG:13)
Block(1,56,4,LOG:13)
Block(1,57,1,LOG:13)
Block(1,57,2,LOG:13)
Block(1,57,3,LOG:13)
Block(1,57,4,LOG:13)
Block(1,57,5,LOG:13)
Block(1,58,1,LOG:13)
Block(1,58,2,LOG:13)
Block(1,59,0,LOG:13)
Block(1,59,1,LOG:13)
Block(1,59,2,LOG:13)
Block(1,60,0,LOG:13)
Block(1,60,1,LOG:13)
Block(1,60,2,LOG:13)
Block(1,61,-2,LOG:13)
Block(1,61,0,LOG:13)
Block(1,61,1,LOG:13)
Block(1,61,2,LOG:13)
Block(1,62,-7,LOG:13)
Block(1,62,-6,LOG:13)
Block(1,62,-5,LOG:13)
Block(1,62,-4,LOG:13)
Block(1,62,1,LOG:13)
Block(1,62,2,LOG:13)
Block(1,63,-6,LOG:13)
Block(1,63,1,LOG:13)
Block(1,63,2,LOG:13)
Block(1,64,1,LOG:13)
Block(1,64,2,LOG:13)
Block(1,65,1,LOG:13)
Block(1,65,2,LOG:13)
Block(1,66,1,LOG:13)
Block(1,66,2,LOG:13)
Block(1,66,9,LOG:13)
Block(1,66,10,LOG:13)
Block(1,67,1,LOG:13)
Block(1,67,2,LOG:13)
Block(1,68,1,LOG:13)
Block(1,68,2,LOG:13)
Block(1,69,-2,LOG:13)
Block(1,69,1,LOG:13)
Block(1,69,2,LOG:13)
Block(1,69,3,LOG:13)
Block(1,70,1,LOG:13)
Block(1,70,2,LOG:13)
Block(1,70,3,LOG:13)
Block(1,71,-5,LOG:13)
Block(1,71,1,LOG:13)
Block(1,71,2,LOG:13)
Block(1,72,-1,LOG:13)
Block(1,72,0,LOG:13)
Block(1,72,1,LOG:13)
Block(1,72,2,LOG:13)
Block(1,73,1,LOG:13)
Block(1,73,2,LOG:13)
Block(1,74,-4,LOG:13)
Block(1,74,1,LOG:13)
Block(1,74,2,LOG:13)
Block(1,75,-4,LOG:13)
Block(1,75,1,LOG:13)
Block(1,75,2,LOG:13)
Block(1,76,1,LOG:13)
Block(1,76,2,LOG:13)
Block(1,76,6,LOG:13)
Block(1,77,1,LOG:13)
Block(1,77,2,LOG:13)
Block(1,78,1,LOG:13)
Block(1,78,2,LOG:13)
Block(1,79,2,LOG:13)
Block(1,80,2,LOG:13)
Block(1,81,2,LOG:13)
Block(1,82,4,LOG:13)
Block(1,83,1,LOG:13)
Block(1,84,1,LOG:13)
Block(1,90,-2,LOG:13)
Block(1,90,-1,LOG:13)
Block(1,91,-2,LOG:13)
Block(2,-9,-8,LOG_2:13)
Block(2,-9,-7,LOG_2:13)
Block(2,-9,-6,LOG_2:13)
Block(2,-9,-5,LOG_2:13)
Block(2,-8,-5,LOG_2:13)
Block(2,-8,-4,LOG_2:13)
Block(2,-7,6,LOG:13)
Block(2,-6,6,LOG_2:13)
Block(2,-5,1,LOG_2:13)
Block(2,-4,0,LOG:13)
Block(2,-4,1,LOG:13)
Block(2,-3,-3,LOG_2:13)
Block(2,-3,-2,LOG:13)
Block(2,-3,-1,LOG:13)
Block(2,-3,0,LOG_2:13)
Block(2,-3,1,LOG:13)
Block(2,-2,-4,LOG_2:13)
Block(2,-2,-3,LOG:13)
Block(2,-2,-2,LOG:13)
Block(2,-2,-1,LOG_2:13)
Block(2,-2,0,LOG_2:13)
Block(2,-2,1,LOG:13)
Block(2,-2,2,LOG:13)
Block(2,-1,-4,LOG_2:13)
Block(2,-1,-3,LOG:13)
Block(2,-1,-2,LOG_2:13)
Block(2,-1,-1,LOG_2:13)
Block(2,-1,0,LOG_2:13)
Block(2,-1,1,LOG:13)
Block(2,-1,2,LOG:13)
Block(2,0,-4,LOG_2:13)
Block(2,0,-3,LOG:13)
Block(2,0,-2,LOG_2:13)
Block(2,0,-1,LOG_2:13)
Block(2,0,0,LOG_2:13)
Block(2,0,1,LOG:13)
Block(2,0,2,LOG:13)
Block(2,1,-4,LOG_2:13)
Block(2,1,-3,LOG:13)
Block(2,1,-1,LOG:13)
Block(2,1,0,LOG:13)
Block(2,1,1,LOG_2:13)
Block(2,1,2,LOG_2:13)
Block(2,1,3,LOG_2:13)
Block(2,2,-4,LOG_2:13)
Block(2,2,-3,LOG:13)
Block(2,2,-2,LOG:13)
Block(2,2,-1,LOG:13)
Block(2,2,0,LOG:13)
Block(2,2,1,LOG_2:13)
Block(2,2,2,LOG_2:13)
Block(2,2,3,LOG_2:13)
Block(2,3,-3,LOG_2:13)
Block(2,3,-2,LOG:13)
Block(2,3,-1,LOG:13)
Block(2,3,0,LOG:13)
Block(2,3,1,LOG_2:13)
Block(2,3,2,LOG_2:13)
Block(2,3,3,LOG:13)
Block(2,3,4,LOG:13)
Block(2,4,-3,LOG_2:13)
Block(2,4,-2,LOG_2:13)
Block(2,4,-1,LOG_2:13)
Block(2,4,0,LOG_2:13)
Block(2,4,1,LOG_2:13)
Block(2,4,2,LOG:13)
Block(2,4,3,LOG:13)
Block(2,5,-2,LOG_2:13)
Block(2,5,-1,LOG_2:13)
Block(2,5,0,LOG_2:13)
Block(2,5,1,LOG_2:13)
Block(2,5,2,LOG_2:13)
Block(2,5,3,LOG_2:13)
Block(2,6,-2,LOG_2:13)
Block(2,6,-1,LOG_2:13)
Block(2,6,0,LOG:13)
Block(2,6,1,LOG:13)
Block(2,6,2,LOG_2:13)
Block(2,6,3,LOG_2:13)
Block(2,7,-2,LOG_2:13)
Block(2,7,-1,LOG:13)
Block(2,7,0,LOG:13)
Block(2,7,1,LOG:13)
Block(2,7,2,LOG:13)
Block(2,7,3,LOG_2:13)
Block(2,8,-2,LOG:13)
Block(2,8,-1,LOG:13)
Block(2,8,0,LOG:13)
Block(2,8,1,LOG:13)
Block(2,8,2,LOG:13)
Block(2,8,3,LOG:13)
Block(2,9,-2,LOG:13)
Block(2,9,-1,LOG:13)
Block(2,9,0,LOG:13)
Block(2,9,1,LOG:13)
Block(2,9,2,LOG:13)
Block(2,9,3,LOG:13)
Block(2,10,-2,LOG_2:13)
Block(2,10,-1,LOG_2:13)
Block(2,10,0,LOG:13)
Block(2,10,1,LOG:13)
Block(2,10,2,LOG:13)
Block(2,10,3,LOG:13)
Block(2,11,-2,LOG_2:13)
Block(2,11,-1,LOG_2:13)
Block(2,11,0,LOG:13)
Block(2,11,1,LOG:13)
Block(2,11,2,LOG:13)
Block(2,12,-2,LOG_2:13)
Block(2,12,-1,LOG_2:13)
Block(2,12,0,LOG:13)
Block(2,12,1,LOG:13)
Block(2,12,2,LOG:13)
Block(2,13,-1,LOG_2:13)
Block(2,13,0,LOG:13)
Block(2,13,1,LOG:13)
Block(2,13,2,LOG:13)
Block(2,14,-1,LOG_2:13)
Block(2,14,0,LOG:13)
Block(2,14,1,LOG:13)
Block(2,14,2,LOG:13)
Block(2,15,-1,LOG:13)
Block(2,15,0,LOG:13)
Block(2,15,1,LOG:13)
Block(2,15,2,LOG:13)
Block(2,16,-1,LOG:13)
Block(2,16,0,LOG:13)
Block(2,16,1,LOG:13)
Block(2,16,2,LOG_2:13)
Block(2,17,-1,LOG:13)
Block(2,17,0,LOG_2:13)
Block(2,17,1,LOG_2:13)
Block(2,17,2,LOG:13)
Block(2,18,-1,LOG:13)
Block(2,18,0,LOG_2:13)
Block(2,18,1,LOG_2:13)
Block(2,18,2,LOG:13)
Block(2,19,-1,LOG:13)
Block(2,19,0,LOG_2:13)
Block(2,19,1,LOG_2:13)
Block(2,20,-1,LOG_2:13)
Block(2,20,0,LOG_2:13)
Block(2,20,1,LOG_2:13)
Block(2,21,-1,LOG_2:13)
Block(2,21,0,LOG_2:13)
Block(2,21,1,LOG_2:13)
Block(2,22,-1,LOG_2:13)
Block(2,22,0,LOG_2:13)
Block(2,22,1,LOG_2:13)
Block(2,23,-1,LOG_2:13)
Block(2,23,0,LOG_2:13)
Block(2,23,1,LOG_2:13)
Block(2,24,-1,LOG:13)
Block(2,24,0,LOG_2:13)
Block(2,24,1,LOG_2:13)
Block(2,24,2,LOG:13)
Block(2,25,-1,LOG_2:13)
Block(2,25,0,LOG_2:13)
Block(2,25,1,LOG_2:13)
Block(2,25,2,LOG_2:13)
Block(2,26,-1,LOG:13)
Block(2,26,0,LOG_2:13)
Block(2,26,1,LOG_2:13)
Block(2,26,2,LOG_2:13)
Block(2,27,-1,LOG:13)
Block(2,27,0,LOG:13)
Block(2,27,1,LOG:13)
Block(2,27,2,LOG_2:13)
Block(2,28,-1,LOG:13)
Block(2,28,0,LOG:13)
Block(2,28,1,LOG:13)
Block(2,28,2,LOG:13)
Block(2,29,-1,LOG:13)
Block(2,29,0,LOG:13)
Block(2,29,1,LOG:13)
Block(2,29,2,LOG:13)
Block(2,30,-1,LOG_2:13)
Block(2,30,0,LOG:13)
Block(2,30,1,LOG:13)
Block(2,30,2,LOG:13)
Block(2,31,0,LOG_2:13)
Block(2,31,1,LOG:13)
Block(2,31,2,LOG:13)
Block(2,32,0,LOG_2:13)
Block(2,32,1,LOG_2:13)
Block(2,32,2,LOG:13)
Block(2,33,0,LOG_2:13)
Block(2,33,1,LOG:13)
Block(2,33,2,LOG:13)
Block(2,34,0,LOG:13)
Block(2,34,1,LOG:13)
Block(2,34,2,LOG:13)
Block(2,35,0,LOG:13)
Block(2,35,1,LOG:13)
Block(2,35,2,LOG:13)
Block(2,36,0,LOG_2:13)
Block(2,36,1,LOG_2:13)
Block(2,36,2,LOG_2:13)
Block(2,37,1,LOG_2:13)
Block(2,37,2,LOG_2:13)
Block(2,38,1,LOG:13)
Block(2,38,2,LOG:13)
Block(2,39,1,LOG:13)
Block(2,39,2,LOG:13)
Block(2,40,0,LOG:13)
Block(2,40,1,LOG:13)
Block(2,40,2,LOG:13)
Block(2,41,0,LOG:13)
Block(2,41,1,LOG:13)
Block(2,41,2,LOG:13)
Block(2,42,0,LOG:13)
Block(2,42,1,LOG:13)
Block(2,42,2,LOG:13)
Block(2,43,1,LOG:13)
Block(2,43,2,LOG:13)
Block(2,44,1,LOG:13)
Block(2,44,2,LOG:13)
Block(2,45,1,LOG:13)
Block(2,45,2,LOG:13)
Block(2,46,1,LOG:13)
Block(2,47,-5,LOG:13)
Block(2,47,-3,LOG:13)
Block(2,47,1,LOG:13)
Block(2,48,-7,LOG:13)
Block(2,48,-6,LOG:13)
Block(2,48,-5,LOG:13)
Block(2,48,-4,LOG:13)
Block(2,48,-3,LOG:13)
Block(2,48,1,LOG:13)
Block(2,48,4,LOG:13)
Block(2,49,-3,LOG:13)
Block(2,49,1,LOG:13)
Block(2,49,4,LOG:13)
Block(2,49,5,LOG:13)
Block(2,50,-4,LOG:13)
Block(2,50,1,LOG:13)
Block(2,51,1,LOG:13)
Block(2,51,2,LOG:13)
Block(2,52,1,LOG:13)
Block(2,52,2,LOG:13)
Block(2,52,3,LOG:13)
Block(2,53,1,LOG:13)
Block(2,53,2,LOG:13)
Block(2,54,0,LOG:13)
Block(2,54,1,LOG:13)
Block(2,54,2,LOG:13)
Block(2,55,1,LOG:13)
Block(2,55,2,LOG:13)
Block(2,56,1,LOG:13)
Block(2,56,2,LOG:13)
Block(2,57,1,LOG:13)
Block(2,57,2,LOG:13)
Block(2,58,-4,LOG:13)
Block(2,58,1,LOG:13)
Block(2,58,2,LOG:13)
Block(2,59,1,LOG:13)
Block(2,59,2,LOG:13)
Block(2,60,1,LOG:13)
Block(2,60,2,LOG:13)
Block(2,61,-2,LOG:13)
Block(2,61,1,LOG:13)
Block(2,62,-6,LOG:13)
Block(2,62,1,LOG:13)
Block(2,63,1,LOG:13)
Block(2,64,1,LOG:13)
Block(2,65,1,LOG:13)
Block(2,65,2,LOG:13)
Block(2,66,1,LOG:13)
Block(2,66,2,LOG:13)
Block(2,69,2,LOG:13)
Block(2,69,3,LOG:13)
Block(2,69,4,LOG:13)
Block(2,70,4,LOG:13)
Block(2,70,5,LOG:13)
Block(2,70,6,LOG:13)
Block(2,71,-5,LOG:13)
Block(2,71,6,LOG:13)
Block(2,71,7,LOG:13)
Block(2,72,-5,LOG:13)
Block(2,72,-4,LOG:13)
Block(2,72,-1,LOG:13)
Block(2,72,0,LOG:13)
Block(2,72,1,LOG:13)
Block(2,72,7,LOG:13)
Block(2,73,-4,LOG:13)
Block(2,73,-2,LOG:13)
Block(2,73,-1,LOG:13)
Block(2,73,0,LOG:13)
Block(2,74,-4,LOG:13)
Block(2,76,-4,LOG:13)
Block(2,76,2,LOG:13)
Block(2,76,3,LOG:13)
Block(2,79,2,LOG:13)
Block(2,80,2,LOG:13)
Block(2,84,0,LOG:13)
Block(2,84,1,LOG:13)
Block(2,84,2,LOG:13)
Block(2,85,1,LOG:13)
Block(3,-11,7,LOG_2:13)
Block(3,-9,-5,LOG_2:13)
Block(3,-6,6,LOG:13)
Block(3,-5,5,LOG_2:13)
Block(3,-5,6,LOG_2:13)
Block(3,-4,-3,LOG_2:13)
Block(3,-4,-2,LOG_2:13)
Block(3,-4,-1,LOG_2:13)
Block(3,-4,1,LOG:13)
Block(3,-4,2,LOG:13)
Block(3,-4,3,LOG:13)
Block(3,-3,-4,LOG_2:13)
Block(3,-3,-3,LOG_2:13)
Block(3,-3,-2,LOG_2:13)
Block(3,-3,-1,LOG_2:13)
Block(3,-3,1,LOG:13)
Block(3,-3,2,LOG:13)
Block(3,-2,-4,LOG_2:13)
Block(3,-2,-3,LOG_2:13)
Block(3,-2,-2,LOG_2:13)
Block(3,-2,0,LOG:13)
Block(3,-2,1,LOG:13)
Block(3,-2,2,LOG:13)
Block(3,-1,-4,LOG_2:13)
Block(3,-1,-3,LOG:13)
Block(3,-1,-2,LOG_2:13)
Block(3,-1,-1,LOG_2:13)
Block(3,-1,0,LOG_2:13)
Block(3,-1,1,LOG:13)
Block(3,-1,2,LOG:13)
Block(3,-1,3,LOG:13)
Block(3,0,-3,LOG:13)
Block(3,0,-2,LOG_2:13)
Block(3,0,-1,LOG_2:13)
Block(3,0,0,LOG:13)
Block(3,0,1,LOG:13)
Block(3,0,2,LOG:13)
Block(3,0,3,LOG_2:13)
Block(3,1,-3,LOG:13)
Block(3,1,-2,LOG:13)
Block(3,1,-1,LOG:13)
Block(3,1,0,LOG:13)
Block(3,1,1,LOG:13)
Block(3,1,2,LOG_2:13)
Block(3,2,-3,LOG_2:13)
Block(3,2,-2,LOG:13)
Block(3,2,-1,LOG:13)
Block(3,2,0,LOG:13)
Block(3,2,1,LOG_2:13)
Block(3,2,2,LOG_2:13)
Block(3,3,-2,LOG_2:13)
Block(3,3,-1,LOG_2:13)
Block(3,3,0,LOG_2:13)
Block(3,3,1,LOG_2:13)
Block(3,3,3,LOG:13)
Block(3,4,-2,LOG_2:13)
Block(3,4,-1,LOG_2:13)
Block(3,4,0,LOG_2:13)
Block(3,4,1,LOG_2:13)
Block(3,4,2,LOG:13)
Block(3,4,3,LOG:13)
Block(3,5,-2,LOG_2:13)
Block(3,5,-1,LOG_2:13)
Block(3,5,0,LOG_2:13)
Block(3,5,1,LOG:13)
Block(3,5,2,LOG:13)
Block(3,5,3,LOG_2:13)
Block(3,6,-2,LOG_2:13)
Block(3,6,-1,LOG_2:13)
Block(3,6,0,LOG:13)
Block(3,6,1,LOG:13)
Block(3,6,2,LOG_2:13)
Block(3,6,3,LOG_2:13)
Block(3,7,-2,LOG_2:13)
Block(3,7,-1,LOG:13)
Block(3,7,0,LOG:13)
Block(3,7,1,LOG_2:13)
Block(3,7,2,LOG_2:13)
Block(3,7,3,LOG_2:13)
Block(3,8,-2,LOG:13)
Block(3,8,-1,LOG:13)
Block(3,8,0,LOG:13)
Block(3,8,1,LOG:13)
Block(3,8,2,LOG:13)
Block(3,9,-2,LOG:13)
Block(3,9,-1,LOG:13)
Block(3,9,0,LOG:13)
Block(3,9,1,LOG:13)
Block(3,9,2,LOG:13)
Block(3,10,-2,LOG:13)
Block(3,10,-1,LOG_2:13)
Block(3,10,0,LOG:13)
Block(3,10,1,LOG:13)
Block(3,11,-2,LOG:13)
Block(3,11,-1,LOG_2:13)
Block(3,11,0,LOG_2:13)
Block(3,11,1,LOG:13)
Block(3,12,-2,LOG_2:13)
Block(3,12,-1,LOG_2:13)
Block(3,12,0,LOG_2:13)
Block(3,12,1,LOG:13)
Block(3,13,-1,LOG_2:13)
Block(3,13,0,LOG_2:13)
Block(3,13,1,LOG:13)
Block(3,14,-1,LOG_2:13)
Block(3,14,0,LOG_2:13)
Block(3,14,1,LOG:13)
Block(3,15,-1,LOG_2:13)
Block(3,15,0,LOG_2:13)
Block(3,15,1,LOG:13)
Block(3,16,-1,LOG_2:13)
Block(3,16,0,LOG_2:13)
Block(3,16,1,LOG:13)
Block(3,17,-1,LOG_2:13)
Block(3,17,0,LOG_2:13)
Block(3,17,1,LOG_2:13)
Block(3,18,0,LOG_2:13)
Block(3,18,1,LOG_2:13)
Block(3,19,0,LOG_2:13)
Block(3,19,1,LOG_2:13)
Block(3,20,0,LOG_2:13)
Block(3,20,1,LOG_2:13)
Block(3,21,0,LOG_2:13)
Block(3,22,0,LOG_2:13)
Block(3,23,0,LOG_2:13)
Block(3,24,0,LOG_2:13)
Block(3,25,0,LOG_2:13)
Block(3,26,0,LOG_2:13)
Block(3,27,0,LOG_2:13)
Block(3,28,0,LOG_2:13)
Block(3,28,1,LOG:13)
Block(3,29,0,LOG_2:13)
Block(3,29,1,LOG:13)
Block(3,30,0,LOG_2:13)
Block(3,30,1,LOG:13)
Block(3,31,0,LOG_2:13)
Block(3,31,1,LOG:13)
Block(3,32,0,LOG_2:13)
Block(3,32,1,LOG_2:13)
Block(3,33,1,LOG:13)
Block(3,34,1,LOG:13)
Block(3,35,1,LOG:13)
Block(3,48,-4,LOG:13)
Block(3,48,0,LOG:13)
Block(3,48,1,LOG:13)
Block(3,49,0,LOG:13)
Block(3,49,5,LOG:13)
Block(3,49,6,LOG:13)
Block(3,50,-1,LOG:13)
Block(3,51,2,LOG:13)
Block(3,51,3,LOG:13)
Block(3,51,7,LOG:13)
Block(3,52,3,LOG:13)
Block(3,53,-5,LOG:13)
Block(3,53,-4,LOG:13)
Block(3,53,0,LOG:13)
Block(3,53,1,LOG:13)
Block(3,54,-3,LOG:13)
Block(3,54,-1,LOG:13)
Block(3,54,0,LOG:13)
Block(3,55,-1,LOG:13)
Block(3,55,0,LOG:13)
Block(3,55,7,LOG:13)
Block(3,57,-3,LOG:13)
Block(3,58,-4,LOG:13)
Block(3,58,-3,LOG:13)
Block(3,59,2,LOG:13)
Block(3,60,2,LOG:13)
Block(3,63,-6,LOG:13)
Block(3,66,1,LOG:13)
Block(3,69,4,LOG:13)
Block(3,70,4,LOG:13)
Block(3,71,4,LOG:13)
Block(3,71,7,LOG:13)
Block(3,71,8,LOG:13)
Block(3,73,-4,LOG:13)
Block(3,73,-3,LOG:13)
Block(3,73,-2,LOG:13)
Block(3,74,-4,LOG:13)
Block(3,74,-2,LOG:13)
Block(3,75,-2,LOG:13)
Block(3,75,-1,LOG:13)
Block(3,75,5,LOG:13)
Block(3,76,-4,LOG:13)
Block(3,76,3,LOG:13)
Block(3,76,4,LOG:13)
Block(3,79,2,LOG:13)
Block(3,80,2,LOG:13)
Block(3,83,2,LOG:13)
Block(3,84,2,LOG:13)
Block(3,84,3,LOG:13)
Block(4,-11,7,LOG_2:13)
Block(4,-10,7,LOG_2:13)
Block(4,-5,-5,LOG:13)
Block(4,-5,-4,LOG:13)
Block(4,-5,-3,LOG_2:13)
Block(4,-5,3,LOG:13)
Block(4,-5,5,LOG_2:13)
Block(4,-4,-5,LOG_2:13)
Block(4,-4,-4,LOG_2:13)
Block(4,-4,-3,LOG_2:13)
Block(4,-4,2,LOG:13)
Block(4,-4,3,LOG:13)
Block(4,-4,4,LOG_2:13)
Block(4,-4,5,LOG_2:13)
Block(4,-3,-4,LOG_2:13)
Block(4,-3,-3,LOG_2:13)
Block(4,-3,-1,LOG_2:13)
Block(4,-3,0,LOG:13)
Block(4,-3,1,LOG:13)
Block(4,-3,2,LOG:13)
Block(4,-2,-4,LOG_2:13)
Block(4,-2,-1,LOG_2:13)
Block(4,-2,0,LOG:13)
Block(4,-2,1,LOG:13)
Block(4,-2,2,LOG:13)
Block(4,-2,3,LOG_2:13)
Block(4,-1,-1,LOG:13)
Block(4,-1,0,LOG:13)
Block(4,-1,2,LOG:13)
Block(4,-1,3,LOG_2:13)
Block(4,0,-1,LOG:13)
Block(4,0,0,LOG:13)
Block(4,0,3,LOG_2:13)
Block(4,1,-1,LOG:13)
Block(4,1,0,LOG:13)
Block(4,1,1,LOG_2:13)
Block(4,1,2,LOG_2:13)
Block(4,1,3,LOG_2:13)
Block(4,2,1,LOG_2:13)
Block(4,2,2,LOG_2:13)
Block(4,2,3,LOG:13)
Block(4,3,1,LOG:13)
Block(4,3,2,LOG:13)
Block(4,3,3,LOG:13)
Block(4,4,1,LOG:13)
Block(4,4,2,LOG:13)
Block(4,4,3,LOG:13)
Block(4,5,1,LOG:13)
Block(4,5,2,LOG:13)
Block(4,6,2,LOG_2:13)
Block(4,48,-4,LOG:13)
Block(4,48,0,LOG:13)
Block(4,49,-4,LOG:13)
Block(4,52,3,LOG:13)
Block(4,52,4,LOG:13)
Block(4,52,7,LOG:13)
Block(4,53,4,LOG:13)
Block(4,54,-3,LOG:13)
Block(4,54,-2,LOG:13)
Block(4,54,6,LOG:13)
Block(4,55,-2,LOG:13)
Block(4,55,-1,LOG:13)
Block(4,55,6,LOG:13)
Block(4,57,-3,LOG:13)
Block(4,60,2,LOG:13)
Block(4,60,3,LOG:13)
Block(4,61,3,LOG:13)
Block(4,66,0,LOG:13)
Block(4,66,1,LOG:13)
Block(4,67,0,LOG:13)
Block(4,70,4,LOG:13)
Block(4,70,5,LOG:13)
Block(4,71,7,LOG:13)
Block(4,72,-2,LOG:13)
Block(4,73,-6,LOG:13)
Block(4,73,-5,LOG:13)
Block(4,73,-4,LOG:13)
Block(4,73,-2,LOG:13)
Block(4,76,4,LOG:13)
Block(4,80,1,LOG:13)
Block(4,80,2,LOG:13)
Block(4,80,3,LOG:13)
Block(5,-11,7,LOG_2:13)
Block(5,-6,-6,LOG_2:13)
Block(5,-6,-5,LOG:13)
Block(5,-5,-6,LOG:13)
Block(5,-5,-5,LOG:13)
Block(5,-5,3,LOG:13)
Block(5,-5,4,LOG:13)
Block(5,-4,-5,LOG:13)
Block(5,-4,-4,LOG:13)
Block(5,-4,3,LOG:13)
Block(5,-4,4,LOG:13)
Block(5,-3,0,LOG:13)
Block(5,-3,1,LOG:13)
Block(5,-3,2,LOG_2:13)
Block(5,-3,3,LOG:13)
Block(5,-2,-1,LOG:13)
Block(5,-2,0,LOG:13)
Block(5,-2,1,LOG:13)
Block(5,-2,2,LOG_2:13)
Block(5,-2,3,LOG_2:13)
Block(5,-1,-1,LOG:13)
Block(5,-1,0,LOG:13)
Block(5,-1,1,LOG:13)
Block(5,-1,2,LOG_2:13)
Block(5,-1,3,LOG_2:13)
Block(5,0,0,LOG:13)
Block(5,0,1,LOG_2:13)
Block(5,0,2,LOG_2:13)
Block(5,0,3,LOG_2:13)
Block(5,1,0,LOG:13)
Block(5,1,1,LOG_2:13)
Block(5,1,2,LOG_2:13)
Block(5,2,1,LOG_2:13)
Block(5,2,2,LOG:13)
Block(5,3,1,LOG:13)
Block(5,48,0,LOG:13)
Block(5,49,-4,LOG:13)
Block(5,49,-1,LOG:13)
Block(5,49,0,LOG:13)
Block(5,52,3,LOG:13)
Block(5,52,9,LOG:13)
Block(5,53,4,LOG:13)
Block(5,53,5,LOG:13)
Block(5,53,6,LOG:13)
Block(5,53,7,LOG:13)
Block(5,53,8,LOG:13)
Block(5,54,-7,LOG:13)
Block(5,54,-6,LOG:13)
Block(5,54,4,LOG:13)
Block(5,54,6,LOG:13)
Block(5,54,8,LOG:13)
Block(5,55,-6,LOG:13)
Block(5,55,-2,LOG:13)
Block(5,56,-5,LOG:13)
Block(5,56,-4,LOG:13)
Block(5,56,-3,LOG:13)
Block(5,56,-2,LOG:13)
Block(5,56,-1,LOG:13)
Block(5,56,0,LOG:13)
Block(5,57,-4,LOG:13)
Block(5,57,-3,LOG:13)
Block(5,57,1,LOG:13)
Block(5,58,-3,LOG:13)
Block(5,59,-4,LOG:13)
Block(5,59,-3,LOG:13)
Block(5,60,3,LOG:13)
Block(5,61,2,LOG:13)
Block(5,61,3,LOG:13)
Block(5,62,1,LOG:13)
Block(5,62,2,LOG:13)
Block(5,66,2,LOG:13)
Block(5,67,-2,LOG:13)
Block(5,67,-1,LOG:13)
Block(5,67,0,LOG:13)
Block(5,68,0,LOG:13)
Block(5,68,1,LOG:13)
Block(5,70,5,LOG:13)
Block(5,70,6,LOG:13)
Block(5,71,4,LOG:13)
Block(5,72,-2,LOG:13)
Block(5,76,4,LOG:13)
Block(5,77,3,LOG:13)
Block(5,80,2,LOG:13)
Block(5,81,2,LOG:13)
Block(6,-11,-2,LOG_2:13)
Block(6,-10,-3,LOG_2:13)
Block(6,-10,-2,LOG_2:13)
Block(6,-10,7,LOG_2:13)
Block(6,-9,-3,LOG:13)
Block(6,-7,-6,LOG_2:13)
Block(6,-7,-5,LOG_2:13)
Block(6,-7,3,LOG_2:13)
Block(6,-6,-6,LOG_2:13)
Block(6,-6,2,LOG_2:13)
Block(6,-6,3,LOG_2:13)
Block(6,-5,2,LOG:13)
Block(6,-5,3,LOG:13)
Block(6,-5,4,LOG:13)
Block(6,-4,3,LOG:13)
Block(6,-4,4,LOG:13)
Block(6,-3,0,LOG:13)
Block(6,-3,2,LOG_2:13)
Block(6,-3,3,LOG:13)
Block(6,-3,4,LOG:13)
Block(6,-2,0,LOG:13)
Block(6,-2,2,LOG_2:13)
Block(6,-2,3,LOG_2:13)
Block(6,-1,0,LOG:13)
Block(6,-1,1,LOG_2:13)
Block(6,-1,2,LOG_2:13)
Block(6,0,0,LOG_2:13)
Block(6,0,1,LOG_2:13)
Block(6,0,2,LOG_2:13)
Block(6,1,0,LOG:13)
Block(6,49,0,LOG:13)
Block(6,51,3,LOG:13)
Block(6,54,4,LOG:13)
Block(6,56,-5,LOG:13)
Block(6,56,-1,LOG:13)
Block(6,57,-5,LOG:13)
Block(6,57,-4,LOG:13)
Block(6,57,-1,LOG:13)
Block(6,61,3,LOG:13)
Block(6,62,1,LOG:13)
Block(6,63,1,LOG:13)
Block(6,67,-1,LOG:13)
Block(6,68,1,LOG:13)
Block(6,69,1,LOG:13)
Block(6,69,2,LOG:13)
Block(6,70,6,LOG:13)
Block(6,71,6,LOG:13)
Block(6,72,-2,LOG:13)
Block(6,72,-1,LOG:13)
Block(6,75,5,LOG:13)
Block(6,79,2,LOG:13)
Block(6,80,2,LOG:13)
Block(7,-13,-5,LOG:13)
Block(7,-12,-5,LOG_2:13)
Block(7,-10,7,LOG_2:13)
Block(7,-9,-5,LOG_2:13)
Block(7,-9,-4,LOG:13)
Block(7,-9,-3,LOG:13)
Block(7,-9,7,LOG_2:13)
Block(7,-8,-8,LOG:13)
Block(7,-8,-7,LOG:13)
Block(7,-8,-6,LOG:13)
Block(7,-8,-5,LOG_2:13)
Block(7,-7,-6,LOG:13)
Block(7,-7,-5,LOG_2:13)
Block(7,-6,2,LOG_2:13)
Block(7,-6,3,LOG_2:13)
Block(7,-5,2,LOG_2:13)
Block(7,-5,3,LOG_2:13)
Block(7,51,3,LOG:13)
Block(7,54,-5,LOG:13)
Block(7,54,4,LOG:13)
Block(7,54,5,LOG:13)
Block(7,55,-5,LOG:13)
Block(7,55,4,LOG:13)
Block(7,55,6,LOG:13)
Block(7,55,7,LOG:13)
Block(7,57,-5,LOG:13)
Block(7,57,-1,LOG:13)
Block(7,57,0,LOG:13)
Block(7,57,6,LOG:13)
Block(7,57,7,LOG:13)
Block(7,58,-1,LOG:13)
Block(7,61,3,LOG:13)
Block(7,62,3,LOG:13)
Block(7,62,4,LOG:13)
Block(7,63,4,LOG:13)
Block(7,67,-2,LOG:13)
Block(7,67,-1,LOG:13)
Block(7,68,-1,LOG:13)
Block(7,69,1,LOG:13)
Block(8,-12,-5,LOG:13)
Block(8,-12,-4,LOG:13)
Block(8,-11,-4,LOG_2:13)
Block(8,-9,-4,LOG:13)
Block(8,-9,6,LOG:13)
Block(8,-9,7,LOG_2:13)
Block(8,-8,-9,LOG_2:13)
Block(8,-8,-8,LOG:13)
Block(8,-8,-5,LOG:13)
Block(8,-8,-4,LOG:13)
Block(8,-7,2,LOG_2:13)
Block(8,-7,3,LOG_2:13)
Block(8,-6,2,LOG_2:13)
Block(8,-5,2,LOG_2:13)
Block(8,55,5,LOG:13)
Block(8,55,7,LOG:13)
Block(8,56,5,LOG:13)
Block(8,57,-5,LOG:13)
Block(8,57,1,LOG:13)
Block(8,57,5,LOG:13)
Block(8,58,-4,LOG:13)
Block(8,58,-1,LOG:13)
Block(8,59,-1,LOG:13)
Block(8,60,-1,LOG:13)
Block(8,62,3,LOG:13)
Block(8,67,-1,LOG:13)
Block(9,-11,-5,LOG:13)
Block(9,-11,-4,LOG_2:13)
Block(9,-10,-4,LOG:13)
Block(9,-9,-4,LOG:13)
Block(9,-9,5,LOG:13)
Block(9,-9,6,LOG:13)
Block(9,-9,7,LOG:13)
Block(9,-8,3,LOG:13)
Block(9,-8,4,LOG:13)
Block(9,-8,5,LOG:13)
Block(9,-7,2,LOG:13)
Block(9,-7,3,LOG:13)
Block(9,57,-3,LOG:13)
Block(9,57,-2,LOG:13)
Block(9,58,-1,LOG:13)
Block(9,58,0,LOG:13)
Block(9,59,0,LOG:13)
Block(9,62,3,LOG:13)
Block(9,62,4,LOG:13)
Block(9,63,1,LOG:13)
Block(9,63,2,LOG:13)
Block(9,63,3,LOG:13)
Block(10,-11,-9,LOG_2:13)
Block(10,-10,-5,LOG:13)
Block(10,-10,-4,LOG:13)
Block(10,-10,8,LOG:13)
Block(10,-9,7,LOG:13)
Block(10,-9,8,LOG_2:13)
Block(10,-8,4,LOG:13)
Block(10,59,0,LOG:13)
Block(10,59,1,LOG:13)
Block(10,62,4,LOG:13)
Block(11,-11,-9,LOG_2:13)
Block(11,-11,-8,LOG:13)
Block(11,-11,-7,LOG:13)
Block(11,-10,-6,LOG:13)
Block(11,-10,-5,LOG:13)
Block(12,-11,-7,LOG:13)
Block(12,-10,-7,LOG_2:13)
Block(12,-10,-6,LOG:13)

#######################################################################
# +-----------------------------------------------------------------+ #
# |                            BO3 checks                           | #
# +-----------------------------------------------------------------+ #
#######################################################################

BlockCheck(-10,-12,-4,Solid)
BlockCheck(-9,-8,-6,Solid)
BlockCheck(-6,-11,-1,Solid)
BlockCheck(-6,-10,-12,Solid)
BlockCheck(-1,-11,4,Solid)
BlockCheck(-1,-10,9,Solid)
BlockCheck(2,-10,-8,Solid)
BlockCheck(3,-12,7,Solid)
BlockCheck(4,-6,-3,Solid)
BlockCheck(6,-12,-2,Solid)
BlockCheck(7,-14,-5,Solid)
BlockCheck(8,-9,-9,Solid)
BlockCheck(10,-12,-9,Solid)
BlockCheck(10,-11,8,Solid)
BlockCheck(10,-9,4,Solid)

#######################################################################
# +-----------------------------------------------------------------+ #
# |                             Branches                            | #
# +-----------------------------------------------------------------+ #
#######################################################################


#######################################################################
# +-----------------------------------------------------------------+ #
# |                             Entities                            | #
# +-----------------------------------------------------------------+ #
#######################################################################


#######################################################################
# +-----------------------------------------------------------------+ #
# |                            Particles                            | #
# +-----------------------------------------------------------------+ #
#######################################################################


#######################################################################
# +-----------------------------------------------------------------+ #
# |                             Spawners                            | #
# +-----------------------------------------------------------------+ #
#######################################################################


#######################################################################
# +-----------------------------------------------------------------+ #
# |                             ModData                             | #
# +-----------------------------------------------------------------+ #
#######################################################################

