
#######################################################################
# +-----------------------------------------------------------------+ #
# |                            BO3 object                           | #
# +-----------------------------------------------------------------+ #
#######################################################################

Author: NLBlackEagle

Description: No description given

Version: 3

SettingsMode: WriteDisable


#######################################################################
# +-----------------------------------------------------------------+ #
# |                          Main settings                          | #
# +-----------------------------------------------------------------+ #
#######################################################################

Tree: true

Frequency: 0

Rarity: 100.0

RotateRandomly: true

SpawnHeight: highestSolidBlock

SpawnHeightOffset: 0

SpawnHeightVariance: 1

##############################
# Height Limits for the BO3. #
##############################

MinHeight: 0

MaxHeight: 255

######################
# Extrusion settings #
######################

ExtrudeMode: None

ExtrudeThroughBlocks: AIR

MaxBranchDepth: 10

ExcludedBiomes: All


#######################################################################
# +-----------------------------------------------------------------+ #
# |                      Source block settings                      | #
# +-----------------------------------------------------------------+ #
#######################################################################

SourceBlocks: AIR

MaxPercentageOutsideSourceBlock: 50

OutsideSourceBlock: placeAnyway

DoReplaceBlocks: true

IsOTGPlus: false


#######################################################################
# +-----------------------------------------------------------------+ #
# |                              Blocks                             | #
# +-----------------------------------------------------------------+ #
#######################################################################

Block(-11,47,9,LEAVES:13)
Block(-11,47,10,LEAVES:13)
Block(-11,48,7,LEAVES:13)
Block(-11,48,8,LEAVES:13)
Block(-11,48,9,LEAVES:13)
Block(-11,48,10,LEAVES:13)
Block(-11,49,9,LEAVES:13)
Block(-10,34,1,LEAVES:13)
Block(-10,43,6,LEAVES:13)
Block(-10,43,7,LEAVES:13)
Block(-10,43,8,LEAVES:13)
Block(-10,45,6,LEAVES:13)
Block(-10,45,7,LEAVES:13)
Block(-10,47,10,LEAVES:13)
Block(-10,48,7,LEAVES:13)
Block(-10,48,8,LOG:13)
Block(-10,48,9,LOG:13)
Block(-10,48,10,LEAVES:13)
Block(-10,49,6,LEAVES:13)
Block(-10,49,9,LEAVES:13)
Block(-10,49,10,LEAVES:13)
Block(-10,50,9,LEAVES:13)
Block(-10,51,8,LEAVES:14)
Block(-10,56,1,LEAVES:13)
Block(-10,57,1,LEAVES:13)
Block(-10,57,2,LEAVES:13)
Block(-10,58,2,LEAVES:13)
Block(-10,58,3,LEAVES:13)
Block(-10,60,7,LEAVES:13)
Block(-10,61,6,LEAVES:13)
Block(-10,62,2,LEAVES:13)
Block(-10,63,2,LEAVES:13)
Block(-9,33,3,LEAVES:13)
Block(-9,34,0,LEAVES:13)
Block(-9,35,0,LEAVES:13)
Block(-9,35,1,LEAVES:13)
Block(-9,36,-2,LEAVES:13)
Block(-9,36,2,LEAVES:13)
Block(-9,37,-3,LEAVES:13)
Block(-9,42,6,LEAVES:13)
Block(-9,42,7,LEAVES:13)
Block(-9,43,5,LEAVES:13)
Block(-9,43,6,LOG:13)
Block(-9,43,7,LEAVES:13)
Block(-9,44,5,LEAVES:13)
Block(-9,44,6,LEAVES:13)
Block(-9,44,7,LEAVES:13)
Block(-9,45,6,LEAVES:13)
Block(-9,47,8,LEAVES:13)
Block(-9,47,9,LOG:13)
Block(-9,47,11,LEAVES:13)
Block(-9,48,7,LEAVES:13)
Block(-9,48,8,LEAVES:13)
Block(-9,48,9,LOG:13)
Block(-9,48,10,LEAVES:13)
Block(-9,48,11,LEAVES:13)
Block(-9,48,12,LEAVES:14)
Block(-9,49,7,LEAVES:13)
Block(-9,49,8,LEAVES:13)
Block(-9,49,9,LOG:13)
Block(-9,49,10,LEAVES:13)
Block(-9,49,12,LEAVES:13)
Block(-9,50,8,LEAVES:14)
Block(-9,50,9,LEAVES:13)
Block(-9,50,10,LEAVES:13)
Block(-9,51,9,LEAVES:13)
Block(-9,51,10,LEAVES:14)
Block(-9,54,8,LEAVES:13)
Block(-9,56,1,LEAVES:13)
Block(-9,57,0,LEAVES:13)
Block(-9,57,1,LOG:13)
Block(-9,57,2,LEAVES:13)
Block(-9,57,3,LEAVES:13)
Block(-9,58,2,LEAVES:13)
Block(-9,59,5,LEAVES:13)
Block(-9,59,6,LEAVES:13)
Block(-9,60,0,LEAVES:13)
Block(-9,60,5,LEAVES:13)
Block(-9,60,6,LEAVES:13)
Block(-9,61,1,LEAVES:14)
Block(-9,61,2,LEAVES:14)
Block(-9,61,6,LEAVES:13)
Block(-9,62,-1,LEAVES:13)
Block(-9,62,1,LEAVES:13)
Block(-9,62,2,LOG:13)
Block(-9,62,3,LEAVES:14)
Block(-9,63,0,LEAVES:13)
Block(-9,63,1,LEAVES:13)
Block(-9,63,3,LEAVES:14)
Block(-9,63,4,LEAVES:14)
Block(-8,32,2,LEAVES:13)
Block(-8,33,2,LOG_2:13)
Block(-8,33,3,LEAVES:13)
Block(-8,34,1,LEAVES:13)
Block(-8,34,2,LEAVES:13)
Block(-8,34,3,LEAVES:13)
Block(-8,35,-1,LEAVES:13)
Block(-8,35,0,LOG_2:13)
Block(-8,35,1,LEAVES:13)
Block(-8,35,2,LEAVES:13)
Block(-8,36,-2,LEAVES:13)
Block(-8,36,-1,LEAVES:13)
Block(-8,36,1,LEAVES:13)
Block(-8,37,-4,LEAVES:13)
Block(-8,37,-3,LOG:13)
Block(-8,37,-2,LEAVES:13)
Block(-8,37,-1,LEAVES:13)
Block(-8,38,-4,LEAVES:13)
Block(-8,38,-2,LEAVES:13)
Block(-8,42,6,LEAVES:13)
Block(-8,43,4,LEAVES:13)
Block(-8,43,5,LEAVES:13)
Block(-8,43,6,LOG:13)
Block(-8,43,7,LEAVES:13)
Block(-8,44,5,LEAVES:13)
Block(-8,44,6,LEAVES:13)
Block(-8,44,7,LEAVES:13)
Block(-8,45,5,LEAVES:13)
Block(-8,45,6,LEAVES:13)
Block(-8,45,12,LEAVES:13)
Block(-8,45,13,LEAVES:13)
Block(-8,46,8,LEAVES:14)
Block(-8,46,10,LEAVES:14)
Block(-8,46,12,LEAVES:13)
Block(-8,46,13,LEAVES:13)
Block(-8,47,9,LOG:13)
Block(-8,47,10,LOG:13)
Block(-8,47,11,LOG:13)
Block(-8,47,12,LEAVES:13)
Block(-8,47,13,LEAVES:13)
Block(-8,48,8,LEAVES:13)
Block(-8,48,9,LEAVES:14)
Block(-8,48,10,LEAVES:13)
Block(-8,48,11,LOG:13)
Block(-8,49,8,LEAVES:13)
Block(-8,49,9,LOG:13)
Block(-8,49,10,LEAVES:13)
Block(-8,49,11,LEAVES:13)
Block(-8,49,12,LEAVES:13)
Block(-8,50,8,LEAVES:13)
Block(-8,50,9,LOG:13)
Block(-8,50,10,LEAVES:13)
Block(-8,50,12,LEAVES:13)
Block(-8,51,10,LEAVES:13)
Block(-8,51,11,LEAVES:13)
Block(-8,52,6,LEAVES:13)
Block(-8,52,8,LEAVES:13)
Block(-8,53,6,LEAVES:13)
Block(-8,53,7,LEAVES:13)
Block(-8,53,9,LEAVES:13)
Block(-8,54,7,LEAVES:13)
Block(-8,54,8,LOG:13)
Block(-8,54,9,LEAVES:13)
Block(-8,56,1,LEAVES:13)
Block(-8,56,2,LEAVES:13)
Block(-8,56,8,LEAVES:13)
Block(-8,57,1,LOG:13)
Block(-8,57,2,LOG:13)
Block(-8,58,0,LEAVES:13)
Block(-8,58,3,LEAVES:13)
Block(-8,58,4,LOG:13)
Block(-8,59,4,LOG:13)
Block(-8,59,5,LOG:13)
Block(-8,59,6,LOG:13)
Block(-8,60,0,LEAVES:13)
Block(-8,60,1,LEAVES:13)
Block(-8,60,5,LEAVES:13)
Block(-8,60,6,LOG:13)
Block(-8,60,7,LEAVES:13)
Block(-8,61,-5,LEAVES:13)
Block(-8,61,0,LEAVES:13)
Block(-8,61,1,LEAVES:13)
Block(-8,61,2,LEAVES:14)
Block(-8,62,0,LEAVES:13)
Block(-8,62,1,LEAVES:13)
Block(-8,62,2,LOG:13)
Block(-8,62,3,LEAVES:13)
Block(-8,63,-1,LEAVES:13)
Block(-8,63,0,LEAVES:13)
Block(-8,63,2,LEAVES:13)
Block(-8,63,3,LEAVES:13)
Block(-7,-5,-2,LOG_2:13)
Block(-7,-5,-1,LOG:13)
Block(-7,32,2,LEAVES:13)
Block(-7,32,3,LEAVES:13)
Block(-7,32,4,LEAVES:13)
Block(-7,33,1,LOG:13)
Block(-7,33,2,LOG_2:13)
Block(-7,33,3,LEAVES:13)
Block(-7,34,-1,LEAVES:13)
Block(-7,34,1,LEAVES:13)
Block(-7,34,2,LEAVES:13)
Block(-7,34,3,LEAVES:13)
Block(-7,35,-1,LEAVES:13)
Block(-7,35,0,LOG:13)
Block(-7,35,2,LEAVES:14)
Block(-7,36,-3,LEAVES:13)
Block(-7,36,-1,LEAVES:14)
Block(-7,36,0,LEAVES:13)
Block(-7,37,-3,LOG_2:13)
Block(-7,37,-2,LEAVES:13)
Block(-7,37,-1,LEAVES:14)
Block(-7,37,0,LEAVES:14)
Block(-7,38,-3,LEAVES:13)
Block(-7,38,-1,LEAVES:14)
Block(-7,39,-2,LEAVES:13)
Block(-7,42,5,LEAVES:13)
Block(-7,42,6,LEAVES:13)
Block(-7,43,5,LEAVES:13)
Block(-7,43,6,LOG:13)
Block(-7,43,7,LEAVES:13)
Block(-7,44,5,LEAVES:13)
Block(-7,44,6,LEAVES:13)
Block(-7,44,7,LEAVES:13)
Block(-7,45,11,LEAVES:13)
Block(-7,45,12,LEAVES:13)
Block(-7,45,14,LEAVES:13)
Block(-7,46,8,LEAVES:14)
Block(-7,46,9,LEAVES:14)
Block(-7,46,10,LEAVES:13)
Block(-7,46,11,LEAVES:13)
Block(-7,46,12,LOG:13)
Block(-7,46,13,LOG:13)
Block(-7,46,14,LEAVES:13)
Block(-7,47,8,LEAVES:14)
Block(-7,47,9,LOG:13)
Block(-7,47,11,LEAVES:14)
Block(-7,48,9,LEAVES:14)
Block(-7,48,11,LEAVES:13)
Block(-7,48,12,LEAVES:13)
Block(-7,48,13,LEAVES:14)
Block(-7,49,9,LEAVES:13)
Block(-7,49,11,LEAVES:13)
Block(-7,49,12,LEAVES:14)
Block(-7,49,13,LEAVES:13)
Block(-7,50,9,LEAVES:13)
Block(-7,50,10,LEAVES:13)
Block(-7,50,11,LEAVES:13)
Block(-7,50,12,LEAVES:13)
Block(-7,51,12,LEAVES:13)
Block(-7,53,3,LEAVES:13)
Block(-7,53,4,LEAVES:13)
Block(-7,53,7,LEAVES:13)
Block(-7,53,8,LOG:13)
Block(-7,53,9,LEAVES:13)
Block(-7,54,7,LEAVES:13)
Block(-7,54,8,LOG:13)
Block(-7,54,9,LEAVES:13)
Block(-7,55,4,LEAVES:13)
Block(-7,55,7,LEAVES:13)
Block(-7,55,8,LEAVES:13)
Block(-7,56,1,LEAVES:13)
Block(-7,56,7,LEAVES:13)
Block(-7,56,9,LEAVES:13)
Block(-7,57,0,LEAVES:13)
Block(-7,57,1,LEAVES:13)
Block(-7,57,2,LOG:13)
Block(-7,57,3,LOG:13)
Block(-7,58,0,LEAVES:13)
Block(-7,58,3,LOG:13)
Block(-7,58,4,LOG:13)
Block(-7,59,6,LOG:13)
Block(-7,59,7,LEAVES:13)
Block(-7,60,6,LEAVES:13)
Block(-7,61,1,LOG:13)
Block(-7,61,2,LOG:13)
Block(-7,61,5,LEAVES:13)
Block(-7,61,7,LEAVES:13)
Block(-7,62,-5,LEAVES:13)
Block(-7,62,0,LEAVES:13)
Block(-7,62,1,LEAVES:13)
Block(-7,62,2,LOG:13)
Block(-7,62,3,LEAVES:13)
Block(-7,63,2,LEAVES:13)
Block(-7,63,4,LEAVES:13)
Block(-7,64,2,LEAVES:13)
Block(-6,-6,5,LOG_2:13)
Block(-6,-5,-1,LOG:13)
Block(-6,-4,-1,LOG:13)
Block(-6,-4,0,LOG:13)
Block(-6,-4,1,LOG:13)
Block(-6,-3,1,LOG_2:13)
Block(-6,33,1,LOG:13)
Block(-6,33,3,LEAVES:13)
Block(-6,34,1,LOG:13)
Block(-6,34,2,LEAVES:14)
Block(-6,35,-2,LEAVES:14)
Block(-6,35,-1,LEAVES:14)
Block(-6,35,0,LOG:13)
Block(-6,35,1,LOG:13)
Block(-6,35,2,LEAVES:14)
Block(-6,36,-2,LOG:13)
Block(-6,36,-1,LEAVES:13)
Block(-6,36,0,LEAVES:14)
Block(-6,37,-3,LOG_2:13)
Block(-6,37,-2,LEAVES:14)
Block(-6,37,-1,LEAVES:14)
Block(-6,37,0,LEAVES:14)
Block(-6,38,-2,LEAVES:13)
Block(-6,39,-3,LEAVES:13)
Block(-6,42,6,LEAVES:13)
Block(-6,43,5,LEAVES:13)
Block(-6,43,6,LOG:13)
Block(-6,45,13,LEAVES:13)
Block(-6,46,8,LOG:13)
Block(-6,46,9,LOG:13)
Block(-6,46,11,LEAVES:13)
Block(-6,46,12,LOG:13)
Block(-6,46,13,LEAVES:13)
Block(-6,46,14,LEAVES:13)
Block(-6,47,8,LEAVES:14)
Block(-6,47,9,LOG:13)
Block(-6,47,10,LOG:13)
Block(-6,47,11,LOG:13)
Block(-6,47,12,LEAVES:13)
Block(-6,48,10,LEAVES:13)
Block(-6,48,11,LEAVES:13)
Block(-6,49,11,LEAVES:13)
Block(-6,50,12,LEAVES:13)
Block(-6,51,11,LEAVES:13)
Block(-6,52,3,LEAVES:13)
Block(-6,52,4,LEAVES:13)
Block(-6,53,3,LOG:13)
Block(-6,53,4,LOG:13)
Block(-6,53,5,LEAVES:13)
Block(-6,53,7,LEAVES:13)
Block(-6,53,8,LEAVES:13)
Block(-6,54,3,LEAVES:13)
Block(-6,54,4,LOG:13)
Block(-6,54,6,LEAVES:13)
Block(-6,54,7,LEAVES:13)
Block(-6,54,8,LOG:13)
Block(-6,55,9,LEAVES:13)
Block(-6,56,-5,LEAVES:13)
Block(-6,56,1,LEAVES:13)
Block(-6,56,10,LEAVES:13)
Block(-6,57,-4,LEAVES:13)
Block(-6,57,0,LEAVES:13)
Block(-6,57,1,LEAVES:13)
Block(-6,58,3,LOG:13)
Block(-6,59,3,LOG:13)
Block(-6,59,6,LEAVES:13)
Block(-6,60,-6,LEAVES:13)
Block(-6,60,-4,LEAVES:13)
Block(-6,60,3,LOG:13)
Block(-6,60,6,LEAVES:13)
Block(-6,61,-5,LOG:13)
Block(-6,61,-4,LOG:13)
Block(-6,61,2,LOG:13)
Block(-6,61,3,LOG:13)
Block(-6,61,6,LEAVES:13)
Block(-6,62,-6,LEAVES:13)
Block(-6,62,-4,LEAVES:13)
Block(-6,64,6,LEAVES:14)
Block(-6,64,7,LEAVES:14)
Block(-6,65,6,LEAVES:14)
Block(-5,-9,3,LOG:13)
Block(-5,-8,3,LOG:13)
Block(-5,-7,-3,LOG_2:13)
Block(-5,-6,5,LOG:13)
Block(-5,-5,2,LOG:13)
Block(-5,-5,5,LOG:13)
Block(-5,-4,2,LOG:13)
Block(-5,-3,1,LOG:13)
Block(-5,-2,1,LOG_2:13)
Block(-5,34,1,LEAVES:14)
Block(-5,35,-1,LOG:13)
Block(-5,35,0,LOG:13)
Block(-5,35,1,LEAVES:14)
Block(-5,36,-3,LEAVES:13)
Block(-5,36,-2,LOG_2:13)
Block(-5,36,-1,LOG_2:13)
Block(-5,36,0,LEAVES:14)
Block(-5,37,-2,LOG_2:13)
Block(-5,37,-1,LEAVES:14)
Block(-5,38,-3,LEAVES:13)
Block(-5,43,6,LOG:13)
Block(-5,44,6,LOG:13)
Block(-5,44,7,LOG:13)
Block(-5,44,8,LOG:13)
Block(-5,44,10,LEAVES:14)
Block(-5,45,7,LOG:13)
Block(-5,45,8,LOG:13)
Block(-5,45,10,LEAVES:14)
Block(-5,46,8,LOG:13)
Block(-5,46,10,LEAVES:13)
Block(-5,46,11,LEAVES:14)
Block(-5,47,10,LEAVES:13)
Block(-5,47,11,LEAVES:13)
Block(-5,47,12,LEAVES:13)
Block(-5,51,5,LEAVES:13)
Block(-5,52,3,LEAVES:13)
Block(-5,52,4,LOG:13)
Block(-5,52,5,LOG:13)
Block(-5,52,6,LOG:13)
Block(-5,52,7,LOG:13)
Block(-5,53,3,LEAVES:13)
Block(-5,53,4,LOG:13)
Block(-5,53,5,LEAVES:13)
Block(-5,53,7,LOG:13)
Block(-5,53,8,LOG:13)
Block(-5,53,9,LEAVES:14)
Block(-5,53,10,LEAVES:13)
Block(-5,54,4,LEAVES:13)
Block(-5,54,8,LOG:13)
Block(-5,54,9,LOG:13)
Block(-5,55,-5,LEAVES:13)
Block(-5,55,-4,LEAVES:13)
Block(-5,55,8,LEAVES:13)
Block(-5,55,9,LEAVES:13)
Block(-5,56,-4,LOG:13)
Block(-5,56,-3,LEAVES:13)
Block(-5,58,3,LOG:13)
Block(-5,59,3,LOG:13)
Block(-5,60,-5,LEAVES:13)
Block(-5,60,-4,LEAVES:13)
Block(-5,60,-3,LEAVES:13)
Block(-5,61,-5,LEAVES:13)
Block(-5,61,-4,LOG:13)
Block(-5,61,-3,LEAVES:13)
Block(-5,62,-5,LEAVES:13)
Block(-5,62,-4,LEAVES:13)
Block(-5,63,-3,LEAVES:14)
Block(-5,63,5,LEAVES:14)
Block(-5,63,6,LEAVES:14)
Block(-5,63,7,LEAVES:14)
Block(-5,64,5,LEAVES:14)
Block(-5,64,6,LOG:13)
Block(-5,65,6,LEAVES:13)
Block(-5,65,7,LEAVES:14)
Block(-5,72,-1,LEAVES:14)
Block(-4,-8,3,LOG:13)
Block(-4,-7,-3,LOG:13)
Block(-4,-5,5,LOG:13)
Block(-4,-4,2,LOG:13)
Block(-4,-4,4,LOG:13)
Block(-4,-4,5,LOG:13)
Block(-4,-3,2,LOG:13)
Block(-4,-2,1,LOG:13)
Block(-4,-2,2,LOG:13)
Block(-4,-1,1,LOG:13)
Block(-4,-1,2,LOG:13)
Block(-4,0,1,LOG:13)
Block(-4,0,2,LOG:13)
Block(-4,1,1,LOG:13)
Block(-4,35,0,LOG:13)
Block(-4,35,1,LOG_2:13)
Block(-4,36,10,LEAVES:13)
Block(-4,37,-2,LEAVES:13)
Block(-4,42,11,LEAVES:13)
Block(-4,43,10,LEAVES:13)
Block(-4,43,12,LEAVES:13)
Block(-4,44,-9,LEAVES:13)
Block(-4,44,-8,LEAVES:13)
Block(-4,44,5,LOG:13)
Block(-4,44,6,LOG:13)
Block(-4,44,10,LEAVES:14)
Block(-4,44,11,LEAVES:13)
Block(-4,44,12,LEAVES:13)
Block(-4,45,8,LOG:13)
Block(-4,45,9,LOG:13)
Block(-4,45,11,LEAVES:13)
Block(-4,45,12,LEAVES:14)
Block(-4,46,10,LEAVES:14)
Block(-4,46,11,LEAVES:14)
Block(-4,46,12,LEAVES:14)
Block(-4,51,5,LOG:13)
Block(-4,52,5,LOG:13)
Block(-4,52,8,LEAVES:14)
Block(-4,53,4,LEAVES:13)
Block(-4,53,8,LEAVES:14)
Block(-4,53,9,LEAVES:13)
Block(-4,54,-4,LEAVES:13)
Block(-4,54,-3,LEAVES:13)
Block(-4,54,9,LEAVES:14)
Block(-4,55,-4,LOG:13)
Block(-4,55,-3,LEAVES:13)
Block(-4,56,-5,LEAVES:13)
Block(-4,56,-4,LOG:13)
Block(-4,56,-3,LEAVES:13)
Block(-4,57,-5,LEAVES:13)
Block(-4,57,-4,LEAVES:13)
Block(-4,59,-5,LEAVES:13)
Block(-4,59,2,LOG:13)
Block(-4,59,3,LOG:13)
Block(-4,60,-5,LEAVES:14)
Block(-4,60,-4,LEAVES:13)
Block(-4,60,-1,LOG:13)
Block(-4,61,-5,LEAVES:13)
Block(-4,61,-4,LOG:13)
Block(-4,61,-3,LEAVES:14)
Block(-4,62,-5,LEAVES:13)
Block(-4,62,-4,LEAVES:14)
Block(-4,62,-3,LEAVES:14)
Block(-4,62,6,LEAVES:14)
Block(-4,63,-5,LEAVES:13)
Block(-4,63,-4,LEAVES:14)
Block(-4,63,-2,LEAVES:14)
Block(-4,63,5,LEAVES:14)
Block(-4,63,6,LOG:13)
Block(-4,64,5,LEAVES:13)
Block(-4,64,6,LOG:13)
Block(-4,64,7,LEAVES:13)
Block(-4,65,7,LEAVES:13)
Block(-4,69,5,LEAVES:13)
Block(-4,71,0,LEAVES:14)
Block(-4,71,1,LEAVES:14)
Block(-4,71,2,LEAVES:13)
Block(-4,72,0,LEAVES:14)
Block(-4,72,1,LEAVES:14)
Block(-4,73,-1,LEAVES:14)
Block(-4,73,0,LEAVES:14)
Block(-4,73,1,LEAVES:14)
Block(-3,-8,3,LOG:13)
Block(-3,-7,-3,LOG:13)
Block(-3,-7,3,LOG:13)
Block(-3,-6,-3,LOG:13)
Block(-3,-5,-3,LOG:13)
Block(-3,-4,1,LOG:13)
Block(-3,-4,3,LOG:13)
Block(-3,-4,4,LOG:13)
Block(-3,-3,1,LOG:13)
Block(-3,-3,2,LOG:13)
Block(-3,-3,3,LOG_2:13)
Block(-3,-2,0,LOG:13)
Block(-3,-2,1,LOG:13)
Block(-3,-2,2,LOG_2:13)
Block(-3,-1,0,LOG:13)
Block(-3,-1,1,LOG:13)
Block(-3,-1,2,LOG:13)
Block(-3,0,0,LOG:13)
Block(-3,0,1,LOG:13)
Block(-3,0,2,LOG:13)
Block(-3,1,0,LOG:13)
Block(-3,1,1,LOG:13)
Block(-3,1,2,LOG:13)
Block(-3,2,0,LOG_2:13)
Block(-3,2,1,LOG:13)
Block(-3,2,2,LOG:13)
Block(-3,3,0,LOG:13)
Block(-3,3,1,LOG:13)
Block(-3,3,2,LOG:13)
Block(-3,4,1,LOG:13)
Block(-3,4,2,LOG:13)
Block(-3,5,1,LOG:13)
Block(-3,35,1,LOG_2:13)
Block(-3,35,10,LEAVES:13)
Block(-3,36,9,LEAVES:14)
Block(-3,36,10,LEAVES:13)
Block(-3,36,11,LEAVES:13)
Block(-3,36,12,LEAVES:13)
Block(-3,37,8,LEAVES:14)
Block(-3,37,10,LEAVES:14)
Block(-3,37,11,LEAVES:13)
Block(-3,37,12,LEAVES:13)
Block(-3,42,10,LEAVES:13)
Block(-3,42,11,LEAVES:13)
Block(-3,43,-8,LEAVES:13)
Block(-3,43,10,LOG:13)
Block(-3,43,11,LOG:13)
Block(-3,43,12,LEAVES:13)
Block(-3,44,-8,LOG:13)
Block(-3,44,-7,LEAVES:13)
Block(-3,44,5,LOG:13)
Block(-3,44,10,LOG:13)
Block(-3,44,11,LOG:13)
Block(-3,44,12,LEAVES:13)
Block(-3,45,-7,LEAVES:13)
Block(-3,45,-6,LEAVES:13)
Block(-3,45,9,LOG:13)
Block(-3,45,10,LOG:13)
Block(-3,46,-8,LEAVES:13)
Block(-3,47,-6,LEAVES:13)
Block(-3,48,-8,LEAVES:13)
Block(-3,48,-7,LEAVES:13)
Block(-3,48,-5,LEAVES:13)
Block(-3,49,-9,LEAVES:13)
Block(-3,49,-6,LEAVES:13)
Block(-3,50,-9,LEAVES:13)
Block(-3,50,-8,LEAVES:13)
Block(-3,50,-7,LEAVES:13)
Block(-3,51,5,LOG:13)
Block(-3,52,5,LOG:13)
Block(-3,53,-4,LOG:13)
Block(-3,53,-3,LOG:13)
Block(-3,54,-7,LEAVES:13)
Block(-3,54,-6,LOG:13)
Block(-3,54,-5,LOG:13)
Block(-3,54,-4,LOG:13)
Block(-3,54,7,LEAVES:14)
Block(-3,54,8,LEAVES:14)
Block(-3,54,9,LEAVES:14)
Block(-3,55,-6,LEAVES:13)
Block(-3,55,-5,LEAVES:13)
Block(-3,55,-4,LOG:13)
Block(-3,55,-3,LEAVES:13)
Block(-3,55,7,LEAVES:14)
Block(-3,55,8,LEAVES:14)
Block(-3,56,-4,LEAVES:13)
Block(-3,56,-3,LEAVES:13)
Block(-3,57,-4,LEAVES:13)
Block(-3,58,-5,LEAVES:13)
Block(-3,58,-4,LEAVES:14)
Block(-3,58,-2,LEAVES:14)
Block(-3,59,-7,LEAVES:13)
Block(-3,59,-6,LEAVES:13)
Block(-3,59,-5,LOG:13)
Block(-3,59,-4,LOG:13)
Block(-3,59,-3,LEAVES:13)
Block(-3,59,2,LOG:13)
Block(-3,60,-5,LEAVES:13)
Block(-3,60,-4,LOG:13)
Block(-3,60,-3,LOG:13)
Block(-3,60,-2,LOG:13)
Block(-3,60,-1,LOG:13)
Block(-3,61,-5,LEAVES:13)
Block(-3,61,-4,LOG:13)
Block(-3,61,-3,LEAVES:13)
Block(-3,62,-5,LEAVES:13)
Block(-3,62,-4,LOG:13)
Block(-3,62,-3,LEAVES:14)
Block(-3,62,-2,LEAVES:14)
Block(-3,62,5,LEAVES:13)
Block(-3,63,-5,LEAVES:13)
Block(-3,63,-4,LEAVES:13)
Block(-3,63,5,LEAVES:13)
Block(-3,63,6,LOG:13)
Block(-3,63,7,LEAVES:13)
Block(-3,64,-5,LEAVES:14)
Block(-3,64,5,LEAVES:14)
Block(-3,64,6,LEAVES:13)
Block(-3,64,7,LEAVES:14)
Block(-3,65,6,LEAVES:13)
Block(-3,67,6,LEAVES:13)
Block(-3,68,6,LEAVES:13)
Block(-3,69,1,LEAVES:13)
Block(-3,69,5,LEAVES:13)
Block(-3,69,6,LEAVES:13)
Block(-3,70,0,LOG:13)
Block(-3,70,4,LEAVES:14)
Block(-3,70,5,LEAVES:13)
Block(-3,71,0,LOG:13)
Block(-3,71,1,LEAVES:13)
Block(-3,72,1,LEAVES:13)
Block(-3,73,0,LEAVES:14)
Block(-3,77,-1,LOG:13)
Block(-3,77,0,LEAVES:13)
Block(-3,77,1,LEAVES:13)
Block(-3,77,3,LEAVES:13)
Block(-3,78,-1,LEAVES:13)
Block(-3,79,0,LEAVES:13)
Block(-2,-7,3,LOG_2:13)
Block(-2,-7,4,LOG_2:13)
Block(-2,-6,2,LOG:13)
Block(-2,-6,3,LOG_2:13)
Block(-2,-5,-3,LOG:13)
Block(-2,-5,1,LOG:13)
Block(-2,-5,2,LOG:13)
Block(-2,-5,6,LOG_2:13)
Block(-2,-4,1,LOG:13)
Block(-2,-4,2,LOG:13)
Block(-2,-4,6,LOG:13)
Block(-2,-3,1,LOG_2:13)
Block(-2,-2,0,LOG_2:13)
Block(-2,-2,1,LOG_2:13)
Block(-2,-2,2,LOG_2:13)
Block(-2,-1,-1,LOG_2:13)
Block(-2,-1,0,LOG_2:13)
Block(-2,-1,1,LOG:13)
Block(-2,-1,2,LOG:13)
Block(-2,-1,3,LOG_2:13)
Block(-2,0,0,LOG_2:13)
Block(-2,0,1,LOG:13)
Block(-2,0,2,LOG:13)
Block(-2,0,3,LOG:13)
Block(-2,1,0,LOG_2:13)
Block(-2,1,1,LOG:13)
Block(-2,1,2,LOG:13)
Block(-2,1,3,LOG:13)
Block(-2,2,0,LOG_2:13)
Block(-2,2,1,LOG:13)
Block(-2,2,2,LOG:13)
Block(-2,2,3,LOG:13)
Block(-2,3,0,LOG_2:13)
Block(-2,3,1,LOG:13)
Block(-2,3,2,LOG:13)
Block(-2,3,3,LOG_2:13)
Block(-2,4,0,LOG:13)
Block(-2,4,1,LOG:13)
Block(-2,4,2,LOG_2:13)
Block(-2,4,3,LOG_2:13)
Block(-2,5,0,LOG:13)
Block(-2,5,1,LOG_2:13)
Block(-2,5,2,LOG_2:13)
Block(-2,5,3,LOG_2:13)
Block(-2,6,0,LOG_2:13)
Block(-2,6,1,LOG_2:13)
Block(-2,6,2,LOG_2:13)
Block(-2,7,0,LOG_2:13)
Block(-2,7,1,LOG_2:13)
Block(-2,7,2,LOG_2:13)
Block(-2,8,1,LOG_2:13)
Block(-2,8,2,LOG_2:13)
Block(-2,9,1,LOG:13)
Block(-2,9,2,LOG_2:13)
Block(-2,10,1,LOG:13)
Block(-2,10,2,LOG_2:13)
Block(-2,11,1,LOG:13)
Block(-2,11,2,LOG_2:13)
Block(-2,12,1,LOG:13)
Block(-2,12,2,LOG_2:13)
Block(-2,13,1,LOG:13)
Block(-2,13,2,LOG:13)
Block(-2,14,0,LOG:13)
Block(-2,14,1,LOG:13)
Block(-2,14,2,LOG:13)
Block(-2,15,0,LOG_2:13)
Block(-2,15,1,LOG_2:13)
Block(-2,15,2,LOG:13)
Block(-2,16,0,LOG_2:13)
Block(-2,16,1,LOG_2:13)
Block(-2,16,2,LOG_2:13)
Block(-2,17,0,LOG_2:13)
Block(-2,17,1,LOG_2:13)
Block(-2,17,2,LOG_2:13)
Block(-2,18,0,LOG_2:13)
Block(-2,18,1,LOG_2:13)
Block(-2,19,0,LOG_2:13)
Block(-2,19,1,LOG_2:13)
Block(-2,20,0,LOG_2:13)
Block(-2,20,1,LOG_2:13)
Block(-2,21,1,LOG:13)
Block(-2,22,1,LOG:13)
Block(-2,23,1,LOG:13)
Block(-2,24,1,LOG:13)
Block(-2,33,2,LOG:13)
Block(-2,34,1,LOG_2:13)
Block(-2,34,2,LOG:13)
Block(-2,35,1,LOG_2:13)
Block(-2,35,2,LOG:13)
Block(-2,35,9,LEAVES:13)
Block(-2,35,10,LEAVES:13)
Block(-2,35,11,LEAVES:13)
Block(-2,36,8,LEAVES:14)
Block(-2,36,10,LOG:13)
Block(-2,36,11,LEAVES:13)
Block(-2,37,8,LEAVES:14)
Block(-2,37,9,LEAVES:13)
Block(-2,37,11,LEAVES:13)
Block(-2,38,8,LEAVES:14)
Block(-2,38,9,LEAVES:14)
Block(-2,42,-8,LEAVES:13)
Block(-2,42,2,LEAVES:13)
Block(-2,42,3,LOG:13)
Block(-2,43,-9,LEAVES:13)
Block(-2,43,3,LOG:13)
Block(-2,43,4,LOG:13)
Block(-2,43,11,LEAVES:13)
Block(-2,44,-9,LEAVES:13)
Block(-2,44,-8,LOG:13)
Block(-2,44,-7,LEAVES:13)
Block(-2,44,4,LOG:13)
Block(-2,44,5,LOG:13)
Block(-2,44,10,LEAVES:13)
Block(-2,44,11,LEAVES:13)
Block(-2,44,12,LEAVES:13)
Block(-2,45,-9,LEAVES:13)
Block(-2,45,-8,LOG:13)
Block(-2,45,-7,LOG:13)
Block(-2,45,-6,LEAVES:13)
Block(-2,45,-5,LEAVES:13)
Block(-2,45,11,LEAVES:13)
Block(-2,46,-9,LEAVES:13)
Block(-2,46,-8,LEAVES:13)
Block(-2,46,-7,LEAVES:13)
Block(-2,46,-6,LEAVES:13)
Block(-2,46,-5,LEAVES:13)
Block(-2,47,-7,LEAVES:13)
Block(-2,47,-6,LEAVES:13)
Block(-2,47,-4,LEAVES:14)
Block(-2,48,-6,LOG:13)
Block(-2,48,-5,LOG:13)
Block(-2,49,-9,LOG:13)
Block(-2,49,-8,LOG:13)
Block(-2,49,-7,LOG:13)
Block(-2,49,-6,LOG:13)
Block(-2,50,-8,LEAVES:13)
Block(-2,50,-6,LEAVES:13)
Block(-2,51,5,LOG:13)
Block(-2,53,-3,LOG:13)
Block(-2,53,-2,LOG:13)
Block(-2,53,-1,LOG:13)
Block(-2,53,8,LEAVES:14)
Block(-2,54,-8,LEAVES:13)
Block(-2,54,-7,LEAVES:13)
Block(-2,54,-6,LOG:13)
Block(-2,54,-5,LEAVES:14)
Block(-2,54,-4,LEAVES:13)
Block(-2,54,-3,LEAVES:14)
Block(-2,55,-7,LEAVES:13)
Block(-2,55,-6,LEAVES:13)
Block(-2,55,-4,LEAVES:14)
Block(-2,56,-8,LEAVES:13)
Block(-2,56,-6,LEAVES:13)
Block(-2,56,-5,LEAVES:13)
Block(-2,56,-4,LEAVES:14)
Block(-2,57,-4,LEAVES:14)
Block(-2,58,-5,LEAVES:13)
Block(-2,59,-5,LOG:13)
Block(-2,59,-3,LEAVES:13)
Block(-2,59,0,LOG:13)
Block(-2,59,1,LOG:13)
Block(-2,59,2,LOG:13)
Block(-2,60,-6,LEAVES:13)
Block(-2,60,-4,LEAVES:13)
Block(-2,60,-1,LOG:13)
Block(-2,60,0,LOG:13)
Block(-2,61,-4,LOG:13)
Block(-2,61,-3,LEAVES:13)
Block(-2,62,-5,LEAVES:14)
Block(-2,62,6,LOG:13)
Block(-2,63,5,LOG:13)
Block(-2,63,6,LOG:13)
Block(-2,63,7,LOG:13)
Block(-2,64,5,LEAVES:14)
Block(-2,64,6,LEAVES:14)
Block(-2,65,4,LEAVES:14)
Block(-2,65,5,LEAVES:14)
Block(-2,65,6,LEAVES:13)
Block(-2,67,6,LEAVES:13)
Block(-2,67,7,LEAVES:13)
Block(-2,68,4,LEAVES:14)
Block(-2,68,5,LOG:13)
Block(-2,68,6,LOG:13)
Block(-2,68,7,LEAVES:13)
Block(-2,69,1,LEAVES:13)
Block(-2,69,4,LEAVES:14)
Block(-2,69,5,LEAVES:13)
Block(-2,69,7,LEAVES:13)
Block(-2,70,-1,LEAVES:13)
Block(-2,70,0,LOG:13)
Block(-2,70,1,LOG:13)
Block(-2,70,3,LEAVES:14)
Block(-2,71,0,LEAVES:13)
Block(-2,71,1,LEAVES:13)
Block(-2,72,5,LEAVES:13)
Block(-2,73,6,LEAVES:13)
Block(-2,76,-1,LEAVES:13)
Block(-2,77,-1,LOG:13)
Block(-2,77,0,LOG:13)
Block(-2,77,1,LEAVES:13)
Block(-2,77,2,LEAVES:13)
Block(-2,77,3,LEAVES:13)
Block(-2,78,-1,LEAVES:13)
Block(-2,78,0,LEAVES:13)
Block(-2,78,1,LEAVES:13)
Block(-2,79,0,LEAVES:13)
Block(-2,79,1,LEAVES:13)
Block(-1,-5,-3,LOG:13)
Block(-1,-5,2,LOG:13)
Block(-1,-4,-3,LOG:13)
Block(-1,-4,-2,LOG:13)
Block(-1,-4,5,LOG:13)
Block(-1,-4,6,LOG:13)
Block(-1,-3,-2,LOG_2:13)
Block(-1,-3,2,LOG_2:13)
Block(-1,-3,3,LOG_2:13)
Block(-1,-3,4,LOG_2:13)
Block(-1,-3,5,LOG:13)
Block(-1,-2,-2,LOG_2:13)
Block(-1,-2,-1,LOG_2:13)
Block(-1,-2,1,LOG_2:13)
Block(-1,-2,2,LOG_2:13)
Block(-1,-2,3,LOG_2:13)
Block(-1,-2,4,LOG_2:13)
Block(-1,-1,-2,LOG_2:13)
Block(-1,-1,-1,LOG_2:13)
Block(-1,-1,0,LOG_2:13)
Block(-1,-1,1,LOG_2:13)
Block(-1,-1,2,LOG_2:13)
Block(-1,-1,3,LOG_2:13)
Block(-1,-1,4,LOG_2:13)
Block(-1,0,-2,LOG_2:13)
Block(-1,0,-1,LOG_2:13)
Block(-1,0,0,LOG_2:13)
Block(-1,0,1,LOG_2:13)
Block(-1,0,3,LOG_2:13)
Block(-1,1,-2,LOG:13)
Block(-1,1,-1,LOG_2:13)
Block(-1,1,0,LOG_2:13)
Block(-1,1,1,LOG_2:13)
Block(-1,1,2,LOG:13)
Block(-1,1,3,LOG:13)
Block(-1,2,-1,LOG_2:13)
Block(-1,2,0,LOG_2:13)
Block(-1,2,1,LOG_2:13)
Block(-1,2,2,LOG:13)
Block(-1,2,3,LOG:13)
Block(-1,3,-1,LOG_2:13)
Block(-1,3,0,LOG_2:13)
Block(-1,3,1,LOG:13)
Block(-1,3,2,LOG:13)
Block(-1,3,3,LOG:13)
Block(-1,4,-1,LOG_2:13)
Block(-1,4,0,LOG:13)
Block(-1,4,1,LOG:13)
Block(-1,4,2,LOG:13)
Block(-1,4,3,LOG:13)
Block(-1,5,0,LOG_2:13)
Block(-1,5,1,LOG_2:13)
Block(-1,5,3,LOG:13)
Block(-1,6,0,LOG_2:13)
Block(-1,6,1,LOG_2:13)
Block(-1,6,3,LOG:13)
Block(-1,7,0,LOG_2:13)
Block(-1,7,3,LOG:13)
Block(-1,8,0,LOG_2:13)
Block(-1,8,3,LOG:13)
Block(-1,9,0,LOG:13)
Block(-1,9,3,LOG_2:13)
Block(-1,10,0,LOG:13)
Block(-1,10,3,LOG_2:13)
Block(-1,11,2,LOG_2:13)
Block(-1,11,3,LOG_2:13)
Block(-1,12,1,LOG_2:13)
Block(-1,12,2,LOG_2:13)
Block(-1,12,3,LOG_2:13)
Block(-1,13,0,LOG:13)
Block(-1,13,1,LOG:13)
Block(-1,13,2,LOG:13)
Block(-1,13,3,LOG_2:13)
Block(-1,14,0,LOG_2:13)
Block(-1,14,1,LOG_2:13)
Block(-1,14,2,LOG:13)
Block(-1,14,3,LOG:13)
Block(-1,15,0,LOG_2:13)
Block(-1,15,1,LOG_2:13)
Block(-1,15,2,LOG_2:13)
Block(-1,15,3,LOG:13)
Block(-1,16,1,LOG_2:13)
Block(-1,16,2,LOG_2:13)
Block(-1,16,3,LOG_2:13)
Block(-1,17,1,LOG_2:13)
Block(-1,17,2,LOG_2:13)
Block(-1,17,3,LOG_2:13)
Block(-1,18,0,LOG_2:13)
Block(-1,18,1,LOG_2:13)
Block(-1,18,2,LOG_2:13)
Block(-1,18,3,LOG_2:13)
Block(-1,19,0,LOG_2:13)
Block(-1,19,1,LOG_2:13)
Block(-1,19,2,LOG_2:13)
Block(-1,19,3,LOG_2:13)
Block(-1,20,0,LOG_2:13)
Block(-1,20,1,LOG_2:13)
Block(-1,20,2,LOG:13)
Block(-1,20,3,LOG:13)
Block(-1,21,0,LOG_2:13)
Block(-1,21,1,LOG_2:13)
Block(-1,21,2,LOG:13)
Block(-1,21,3,LOG:13)
Block(-1,22,0,LOG_2:13)
Block(-1,22,1,LOG:13)
Block(-1,22,2,LOG:13)
Block(-1,22,3,LOG:13)
Block(-1,23,0,LOG_2:13)
Block(-1,23,1,LOG:13)
Block(-1,23,2,LOG:13)
Block(-1,23,3,LOG:13)
Block(-1,24,0,LOG:13)
Block(-1,24,1,LOG:13)
Block(-1,24,2,LOG:13)
Block(-1,25,0,LOG:13)
Block(-1,25,1,LOG:13)
Block(-1,25,2,LOG:13)
Block(-1,26,0,LOG_2:13)
Block(-1,26,1,LOG_2:13)
Block(-1,26,2,LOG_2:13)
Block(-1,27,1,LOG_2:13)
Block(-1,27,2,LOG_2:13)
Block(-1,28,1,LOG_2:13)
Block(-1,28,2,LOG_2:13)
Block(-1,29,2,LOG_2:13)
Block(-1,29,9,LEAVES:13)
Block(-1,30,2,LOG_2:13)
Block(-1,31,2,LOG_2:13)
Block(-1,32,2,LOG:13)
Block(-1,33,2,LOG:13)
Block(-1,34,2,LOG:13)
Block(-1,35,2,LOG_2:13)
Block(-1,35,9,LEAVES:13)
Block(-1,35,10,LEAVES:13)
Block(-1,36,1,LOG:13)
Block(-1,36,2,LOG_2:13)
Block(-1,36,8,LEAVES:13)
Block(-1,36,9,LOG:13)
Block(-1,36,10,LOG:13)
Block(-1,37,1,LOG:13)
Block(-1,37,2,LOG:13)
Block(-1,37,8,LEAVES:13)
Block(-1,37,9,LEAVES:13)
Block(-1,37,10,LEAVES:13)
Block(-1,38,1,LOG:13)
Block(-1,38,2,LOG:13)
Block(-1,38,9,LEAVES:13)
Block(-1,38,10,LEAVES:14)
Block(-1,39,1,LOG:13)
Block(-1,39,2,LOG:13)
Block(-1,39,3,LOG:13)
Block(-1,40,1,LOG:13)
Block(-1,40,2,LOG:13)
Block(-1,40,3,LOG:13)
Block(-1,41,1,LOG:13)
Block(-1,41,2,LOG:13)
Block(-1,41,3,LOG:13)
Block(-1,42,-9,LEAVES:13)
Block(-1,42,1,LOG:13)
Block(-1,42,2,LOG:13)
Block(-1,42,3,LOG:13)
Block(-1,43,-8,LEAVES:13)
Block(-1,43,1,LOG:13)
Block(-1,43,2,LOG:13)
Block(-1,43,3,LOG:13)
Block(-1,43,4,LOG:13)
Block(-1,44,-8,LEAVES:13)
Block(-1,44,-7,LEAVES:13)
Block(-1,44,-4,LEAVES:13)
Block(-1,44,1,LOG:13)
Block(-1,44,2,LOG:13)
Block(-1,44,4,LOG:13)
Block(-1,45,-8,LEAVES:13)
Block(-1,45,-7,LOG:13)
Block(-1,45,-6,LOG:13)
Block(-1,45,-5,LOG:13)
Block(-1,45,-4,LEAVES:13)
Block(-1,45,-1,LOG:13)
Block(-1,45,0,LOG:13)
Block(-1,45,1,LOG:13)
Block(-1,45,10,LEAVES:13)
Block(-1,45,12,LEAVES:13)
Block(-1,46,-8,LEAVES:13)
Block(-1,46,-6,LEAVES:13)
Block(-1,46,-5,LOG:13)
Block(-1,46,-4,LEAVES:13)
Block(-1,46,-3,LOG:13)
Block(-1,46,-2,LOG:13)
Block(-1,46,-1,LOG:13)
Block(-1,46,1,LOG:13)
Block(-1,46,11,LEAVES:13)
Block(-1,47,-8,LEAVES:14)
Block(-1,47,-7,LEAVES:14)
Block(-1,47,-6,LEAVES:14)
Block(-1,47,-5,LOG:13)
Block(-1,47,1,LOG:13)
Block(-1,48,-8,LEAVES:13)
Block(-1,48,-7,LEAVES:14)
Block(-1,48,-6,LEAVES:13)
Block(-1,48,-5,LOG:13)
Block(-1,48,-4,LEAVES:14)
Block(-1,49,-9,LEAVES:13)
Block(-1,49,-8,LEAVES:13)
Block(-1,49,-7,LEAVES:13)
Block(-1,49,-6,LEAVES:14)
Block(-1,49,-5,LEAVES:14)
Block(-1,50,-8,LEAVES:13)
Block(-1,50,-7,LEAVES:13)
Block(-1,50,2,LOG:13)
Block(-1,50,3,LOG:13)
Block(-1,50,4,LOG:13)
Block(-1,50,5,LOG:13)
Block(-1,50,11,LEAVES:13)
Block(-1,51,3,LOG:13)
Block(-1,51,5,LOG:13)
Block(-1,51,6,LOG:13)
Block(-1,51,9,LOG:13)
Block(-1,51,10,LOG:13)
Block(-1,51,12,LEAVES:13)
Block(-1,52,-1,LOG:13)
Block(-1,52,0,LOG:13)
Block(-1,52,6,LOG:13)
Block(-1,52,7,LOG:13)
Block(-1,52,8,LOG:13)
Block(-1,52,9,LOG:13)
Block(-1,52,10,LEAVES:13)
Block(-1,53,-5,LEAVES:13)
Block(-1,53,-4,LEAVES:14)
Block(-1,53,-1,LOG:13)
Block(-1,53,0,LOG:13)
Block(-1,53,8,LOG:13)
Block(-1,53,9,LEAVES:14)
Block(-1,53,10,LEAVES:14)
Block(-1,53,11,LEAVES:13)
Block(-1,54,-6,LOG:13)
Block(-1,54,9,LEAVES:14)
Block(-1,55,-7,LEAVES:13)
Block(-1,55,-6,LOG:13)
Block(-1,55,-4,LEAVES:14)
Block(-1,56,-7,LEAVES:13)
Block(-1,56,-5,LEAVES:13)
Block(-1,56,-4,LEAVES:14)
Block(-1,57,-4,LEAVES:14)
Block(-1,57,-3,LEAVES:14)
Block(-1,58,-5,LEAVES:13)
Block(-1,59,1,LOG:13)
Block(-1,60,-5,LEAVES:13)
Block(-1,61,-5,LEAVES:13)
Block(-1,62,3,LOG:13)
Block(-1,62,4,LOG:13)
Block(-1,62,5,LOG:13)
Block(-1,67,6,LEAVES:13)
Block(-1,68,4,LOG:13)
Block(-1,68,5,LOG:13)
Block(-1,68,6,LEAVES:13)
Block(-1,68,7,LEAVES:13)
Block(-1,69,2,LOG:13)
Block(-1,69,5,LEAVES:14)
Block(-1,69,6,LEAVES:14)
Block(-1,69,7,LEAVES:13)
Block(-1,70,-1,LEAVES:13)
Block(-1,70,1,LOG:13)
Block(-1,70,2,LOG:13)
Block(-1,70,4,LEAVES:14)
Block(-1,71,0,LEAVES:13)
Block(-1,71,5,LEAVES:14)
Block(-1,71,6,LEAVES:14)
Block(-1,72,4,LEAVES:13)
Block(-1,72,5,LOG:13)
Block(-1,72,6,LOG:13)
Block(-1,73,4,LEAVES:13)
Block(-1,73,5,LEAVES:13)
Block(-1,73,6,LEAVES:14)
Block(-1,74,5,LEAVES:13)
Block(-1,74,6,LEAVES:13)
Block(-1,76,0,LOG:13)
Block(-1,76,1,LOG:13)
Block(-1,76,2,LEAVES:13)
Block(-1,76,3,LEAVES:13)
Block(-1,77,0,LOG:13)
Block(-1,77,1,LOG:13)
Block(-1,77,2,LEAVES:14)
Block(-1,78,1,LEAVES:13)
Block(-1,78,2,LEAVES:13)
Block(0,-7,6,LOG_2:13)
Block(0,-7,7,LOG_2:13)
Block(0,-7,8,LOG_2:13)
Block(0,-6,5,LOG_2:13)
Block(0,-6,6,LOG_2:13)
Block(0,-5,-4,LOG:13)
Block(0,-5,-3,LOG:13)
Block(0,-5,-2,LOG:13)
Block(0,-4,-3,LOG_2:13)
Block(0,-4,-2,LOG_2:13)
Block(0,-2,-2,LOG_2:13)
Block(0,-2,-1,LOG_2:13)
Block(0,-2,0,LOG_2:13)
Block(0,-2,1,LOG_2:13)
Block(0,-2,2,LOG_2:13)
Block(0,-2,3,LOG_2:13)
Block(0,-1,-2,LOG_2:13)
Block(0,-1,-1,LOG_2:13)
Block(0,-1,0,LOG_2:13)
Block(0,-1,1,LOG_2:13)
Block(0,-1,2,LOG_2:13)
Block(0,-1,3,LOG_2:13)
Block(0,0,-2,LOG_2:13)
Block(0,0,-1,LOG_2:13)
Block(0,0,0,LOG_2:13)
Block(0,0,1,LOG_2:13)
Block(0,0,2,LOG_2:13)
Block(0,0,3,LOG_2:13)
Block(0,1,-1,LOG_2:13)
Block(0,1,0,LOG_2:13)
Block(0,1,1,LOG_2:13)
Block(0,1,2,LOG_2:13)
Block(0,1,3,LOG:13)
Block(0,2,-1,LOG_2:13)
Block(0,2,0,LOG_2:13)
Block(0,2,1,LOG_2:13)
Block(0,2,2,LOG_2:13)
Block(0,2,3,LOG:13)
Block(0,3,-1,LOG_2:13)
Block(0,3,0,LOG_2:13)
Block(0,3,1,LOG_2:13)
Block(0,3,2,LOG:13)
Block(0,3,3,LOG:13)
Block(0,4,-1,LOG_2:13)
Block(0,4,0,LOG_2:13)
Block(0,4,1,LOG_2:13)
Block(0,4,2,LOG:13)
Block(0,4,3,LOG:13)
Block(0,5,-1,LOG_2:13)
Block(0,5,0,LOG_2:13)
Block(0,5,1,LOG_2:13)
Block(0,5,2,LOG:13)
Block(0,5,3,LOG:13)
Block(0,6,-1,LOG_2:13)
Block(0,6,0,LOG_2:13)
Block(0,6,1,LOG_2:13)
Block(0,6,2,LOG:13)
Block(0,6,3,LOG:13)
Block(0,7,0,LOG_2:13)
Block(0,7,1,LOG_2:13)
Block(0,7,2,LOG:13)
Block(0,8,0,LOG_2:13)
Block(0,8,1,LOG_2:13)
Block(0,8,2,LOG:13)
Block(0,9,0,LOG_2:13)
Block(0,9,1,LOG_2:13)
Block(0,9,2,LOG_2:13)
Block(0,9,3,LOG_2:13)
Block(0,10,0,LOG_2:13)
Block(0,10,1,LOG_2:13)
Block(0,10,2,LOG_2:13)
Block(0,10,3,LOG_2:13)
Block(0,11,0,LOG_2:13)
Block(0,11,1,LOG_2:13)
Block(0,11,2,LOG_2:13)
Block(0,11,3,LOG_2:13)
Block(0,12,0,LOG_2:13)
Block(0,12,1,LOG_2:13)
Block(0,12,2,LOG_2:13)
Block(0,12,3,LOG_2:13)
Block(0,13,0,LOG_2:13)
Block(0,13,1,LOG:13)
Block(0,13,2,LOG:13)
Block(0,13,3,LOG_2:13)
Block(0,14,0,LOG_2:13)
Block(0,14,1,LOG:13)
Block(0,14,2,LOG:13)
Block(0,14,3,LOG:13)
Block(0,15,1,LOG_2:13)
Block(0,15,2,LOG:13)
Block(0,15,3,LOG:13)
Block(0,16,1,LOG_2:13)
Block(0,16,2,LOG_2:13)
Block(0,16,3,LOG:13)
Block(0,17,1,LOG_2:13)
Block(0,17,2,LOG_2:13)
Block(0,17,3,LOG:13)
Block(0,18,1,LOG_2:13)
Block(0,18,2,LOG_2:13)
Block(0,18,3,LOG:13)
Block(0,19,1,LOG_2:13)
Block(0,19,2,LOG_2:13)
Block(0,19,3,LOG:13)
Block(0,20,1,LOG_2:13)
Block(0,20,2,LOG_2:13)
Block(0,20,3,LOG:13)
Block(0,21,1,LOG_2:13)
Block(0,21,2,LOG_2:13)
Block(0,21,3,LOG:13)
Block(0,22,1,LOG_2:13)
Block(0,22,2,LOG_2:13)
Block(0,22,3,LOG:13)
Block(0,23,1,LOG_2:13)
Block(0,23,2,LOG_2:13)
Block(0,23,3,LOG_2:13)
Block(0,24,1,LOG:13)
Block(0,24,2,LOG_2:13)
Block(0,24,3,LOG_2:13)
Block(0,25,1,LOG_2:13)
Block(0,25,2,LOG_2:13)
Block(0,25,3,LOG_2:13)
Block(0,26,1,LOG_2:13)
Block(0,26,2,LOG_2:13)
Block(0,26,3,LOG_2:13)
Block(0,27,1,LOG_2:13)
Block(0,27,2,LOG_2:13)
Block(0,27,3,LOG_2:13)
Block(0,28,1,LOG_2:13)
Block(0,28,2,LOG_2:13)
Block(0,28,3,LOG_2:13)
Block(0,29,1,LOG_2:13)
Block(0,29,2,LOG_2:13)
Block(0,29,3,LOG_2:13)
Block(0,29,7,LEAVES:13)
Block(0,29,10,LEAVES:13)
Block(0,30,1,LOG_2:13)
Block(0,30,2,LOG_2:13)
Block(0,30,3,LOG_2:13)
Block(0,30,8,LOG_2:13)
Block(0,30,9,LOG:13)
Block(0,30,10,LEAVES:13)
Block(0,31,1,LOG_2:13)
Block(0,31,2,LOG_2:13)
Block(0,31,3,LOG_2:13)
Block(0,31,8,LEAVES:13)
Block(0,31,9,LEAVES:13)
Block(0,32,1,LOG:13)
Block(0,32,2,LOG_2:13)
Block(0,32,3,LOG:13)
Block(0,33,1,LOG:13)
Block(0,33,2,LOG:13)
Block(0,33,3,LOG:13)
Block(0,34,1,LOG:13)
Block(0,34,2,LOG:13)
Block(0,34,3,LOG:13)
Block(0,35,1,LOG_2:13)
Block(0,35,2,LOG_2:13)
Block(0,35,3,LOG_2:13)
Block(0,36,1,LOG_2:13)
Block(0,36,2,LOG_2:13)
Block(0,36,3,LOG_2:13)
Block(0,36,4,LOG_2:13)
Block(0,36,8,LEAVES:13)
Block(0,36,9,LEAVES:13)
Block(0,37,1,LOG_2:13)
Block(0,37,2,LOG:13)
Block(0,37,3,LOG_2:13)
Block(0,37,7,LEAVES:13)
Block(0,37,8,LOG_2:13)
Block(0,37,9,LOG_2:13)
Block(0,37,10,LEAVES:13)
Block(0,38,1,LOG:13)
Block(0,38,2,LOG:13)
Block(0,38,3,LOG:13)
Block(0,38,6,LEAVES:13)
Block(0,38,7,LEAVES:13)
Block(0,38,8,LEAVES:13)
Block(0,38,9,LEAVES:13)
Block(0,39,1,LOG:13)
Block(0,39,2,LOG:13)
Block(0,39,3,LOG:13)
Block(0,40,1,LOG:13)
Block(0,40,2,LOG:13)
Block(0,40,3,LOG:13)
Block(0,41,1,LOG:13)
Block(0,41,2,LOG:13)
Block(0,41,3,LOG:13)
Block(0,42,1,LOG:13)
Block(0,42,2,LOG:13)
Block(0,42,3,LOG:13)
Block(0,43,1,LOG:13)
Block(0,43,2,LOG:13)
Block(0,43,3,LOG:13)
Block(0,44,-7,LEAVES:13)
Block(0,44,0,LOG:13)
Block(0,44,1,LOG:13)
Block(0,44,2,LOG:13)
Block(0,45,-7,LEAVES:13)
Block(0,45,-6,LEAVES:13)
Block(0,45,-5,LEAVES:13)
Block(0,45,0,LOG:13)
Block(0,45,1,LOG:13)
Block(0,45,2,LOG:13)
Block(0,46,-6,LEAVES:13)
Block(0,46,-5,LOG:13)
Block(0,46,-4,LOG:13)
Block(0,46,-3,LOG:13)
Block(0,46,1,LOG:13)
Block(0,46,2,LOG:13)
Block(0,47,-5,LEAVES:14)
Block(0,47,-4,LEAVES:13)
Block(0,47,1,LOG:13)
Block(0,47,2,LOG:13)
Block(0,48,-7,LEAVES:14)
Block(0,48,1,LOG:13)
Block(0,48,2,LOG:13)
Block(0,49,1,LOG:13)
Block(0,49,2,LOG:13)
Block(0,50,1,LOG:13)
Block(0,50,2,LOG:13)
Block(0,50,3,LOG:13)
Block(0,50,12,LEAVES:13)
Block(0,51,0,LOG:13)
Block(0,51,1,LOG:13)
Block(0,51,2,LOG:13)
Block(0,51,10,LOG:13)
Block(0,51,11,LOG:13)
Block(0,51,12,LEAVES:13)
Block(0,52,0,LOG:13)
Block(0,52,1,LOG:13)
Block(0,52,2,LOG:13)
Block(0,52,8,LEAVES:14)
Block(0,52,9,LEAVES:14)
Block(0,52,10,LEAVES:14)
Block(0,52,11,LEAVES:13)
Block(0,53,1,LOG:13)
Block(0,53,8,LOG:13)
Block(0,53,9,LOG:13)
Block(0,53,10,LEAVES:13)
Block(0,53,11,LEAVES:13)
Block(0,53,12,LEAVES:13)
Block(0,54,-7,LEAVES:13)
Block(0,54,1,LOG:13)
Block(0,54,2,LOG:13)
Block(0,54,10,LEAVES:14)
Block(0,54,11,LEAVES:14)
Block(0,55,-5,LEAVES:13)
Block(0,55,-4,LEAVES:14)
Block(0,55,1,LOG:13)
Block(0,56,-6,LEAVES:13)
Block(0,56,-5,LEAVES:14)
Block(0,56,-3,LEAVES:14)
Block(0,56,1,LOG:13)
Block(0,57,1,LOG:13)
Block(0,58,1,LOG:13)
Block(0,59,1,LOG:13)
Block(0,60,1,LOG:13)
Block(0,60,2,LOG:13)
Block(0,61,2,LOG:13)
Block(0,61,3,LOG:13)
Block(0,62,2,LOG:13)
Block(0,62,3,LOG:13)
Block(0,62,6,LEAVES:14)
Block(0,63,2,LOG:13)
Block(0,63,7,LEAVES:14)
Block(0,64,2,LOG:13)
Block(0,65,2,LOG:13)
Block(0,67,2,LOG:13)
Block(0,67,4,LOG:13)
Block(0,68,2,LOG:13)
Block(0,68,4,LOG:13)
Block(0,68,5,LEAVES:13)
Block(0,68,6,LEAVES:13)
Block(0,69,2,LOG:13)
Block(0,70,2,LOG:13)
Block(0,71,6,LEAVES:13)
Block(0,72,4,LOG:13)
Block(0,72,5,LOG:13)
Block(0,72,6,LEAVES:14)
Block(0,72,7,LEAVES:14)
Block(0,73,2,LEAVES:14)
Block(0,73,4,LEAVES:14)
Block(0,73,5,LEAVES:13)
Block(0,73,6,LEAVES:13)
Block(0,75,1,LOG:13)
Block(0,75,2,LOG:13)
Block(0,76,1,LOG:13)
Block(0,76,2,LOG:13)
Block(0,76,3,LEAVES:13)
Block(0,77,0,LEAVES:13)
Block(0,77,1,LEAVES:13)
Block(0,77,2,LEAVES:13)
Block(0,77,3,LEAVES:13)
Block(0,78,0,LEAVES:13)
Block(0,78,2,LEAVES:14)
Block(0,79,2,LEAVES:14)
Block(1,-7,-5,LOG:13)
Block(1,-7,8,LOG_2:13)
Block(1,-6,-5,LOG:13)
Block(1,-6,-4,LOG_2:13)
Block(1,-6,3,LOG:13)
Block(1,-6,4,LOG:13)
Block(1,-6,5,LOG:13)
Block(1,-5,-4,LOG_2:13)
Block(1,-3,0,LOG_2:13)
Block(1,-3,1,LOG_2:13)
Block(1,-2,-1,LOG_2:13)
Block(1,-2,0,LOG_2:13)
Block(1,-2,1,LOG:13)
Block(1,-1,-1,LOG_2:13)
Block(1,-1,0,LOG_2:13)
Block(1,-1,1,LOG_2:13)
Block(1,-1,2,LOG:13)
Block(1,0,-1,LOG_2:13)
Block(1,0,0,LOG_2:13)
Block(1,0,1,LOG_2:13)
Block(1,0,2,LOG:13)
Block(1,1,-1,LOG:13)
Block(1,1,0,LOG_2:13)
Block(1,1,1,LOG_2:13)
Block(1,1,2,LOG_2:13)
Block(1,2,-1,LOG:13)
Block(1,2,0,LOG_2:13)
Block(1,2,1,LOG_2:13)
Block(1,2,2,LOG_2:13)
Block(1,3,0,LOG_2:13)
Block(1,3,1,LOG_2:13)
Block(1,3,2,LOG_2:13)
Block(1,4,0,LOG_2:13)
Block(1,4,1,LOG_2:13)
Block(1,4,2,LOG_2:13)
Block(1,5,0,LOG_2:13)
Block(1,5,1,LOG_2:13)
Block(1,5,2,LOG:13)
Block(1,6,0,LOG_2:13)
Block(1,6,1,LOG:13)
Block(1,6,2,LOG:13)
Block(1,7,0,LOG_2:13)
Block(1,7,1,LOG:13)
Block(1,7,2,LOG:13)
Block(1,8,0,LOG:13)
Block(1,8,1,LOG:13)
Block(1,8,2,LOG:13)
Block(1,9,1,LOG:13)
Block(1,9,2,LOG:13)
Block(1,10,1,LOG:13)
Block(1,10,2,LOG:13)
Block(1,11,2,LOG_2:13)
Block(1,12,2,LOG_2:13)
Block(1,13,2,LOG:13)
Block(1,14,2,LOG:13)
Block(1,15,2,LOG:13)
Block(1,16,2,LOG:13)
Block(1,17,2,LOG:13)
Block(1,18,2,LOG:13)
Block(1,19,2,LOG:13)
Block(1,20,2,LOG_2:13)
Block(1,21,2,LOG_2:13)
Block(1,22,2,LOG_2:13)
Block(1,23,2,LOG_2:13)
Block(1,24,1,LOG:13)
Block(1,24,2,LOG_2:13)
Block(1,25,1,LOG:13)
Block(1,25,2,LOG_2:13)
Block(1,26,1,LOG_2:13)
Block(1,26,2,LOG_2:13)
Block(1,27,1,LOG_2:13)
Block(1,27,2,LOG_2:13)
Block(1,27,3,LOG_2:13)
Block(1,28,1,LOG_2:13)
Block(1,28,2,LOG_2:13)
Block(1,28,3,LOG_2:13)
Block(1,28,4,LOG:13)
Block(1,28,7,LEAVES:13)
Block(1,28,8,LEAVES:13)
Block(1,28,9,LEAVES:13)
Block(1,29,1,LOG_2:13)
Block(1,29,2,LOG_2:13)
Block(1,29,4,LOG:13)
Block(1,29,7,LOG:13)
Block(1,29,8,LOG:13)
Block(1,29,9,LEAVES:13)
Block(1,30,1,LOG_2:13)
Block(1,30,2,LOG_2:13)
Block(1,30,7,LEAVES:13)
Block(1,30,8,LOG:13)
Block(1,30,9,LEAVES:13)
Block(1,31,1,LOG_2:13)
Block(1,31,2,LOG_2:13)
Block(1,31,8,LEAVES:13)
Block(1,32,2,LOG_2:13)
Block(1,33,2,LOG_2:13)
Block(1,34,2,LOG:13)
Block(1,35,1,LOG_2:13)
Block(1,35,2,LOG_2:13)
Block(1,36,1,LOG_2:13)
Block(1,36,2,LOG_2:13)
Block(1,36,3,LOG_2:13)
Block(1,36,4,LOG:13)
Block(1,36,6,LEAVES:13)
Block(1,37,0,LOG_2:13)
Block(1,37,1,LOG_2:13)
Block(1,37,2,LOG_2:13)
Block(1,37,4,LOG_2:13)
Block(1,37,5,LOG:13)
Block(1,37,6,LEAVES:13)
Block(1,37,7,LOG:13)
Block(1,37,8,LOG_2:13)
Block(1,38,2,LOG:13)
Block(1,38,5,LEAVES:13)
Block(1,38,6,LEAVES:13)
Block(1,38,7,LOG:13)
Block(1,39,2,LOG:13)
Block(1,40,2,LOG:13)
Block(1,41,2,LOG:13)
Block(1,42,2,LOG:13)
Block(1,43,2,LOG:13)
Block(1,44,2,LOG:13)
Block(1,45,2,LOG:13)
Block(1,45,3,LOG:13)
Block(1,46,-5,LEAVES:13)
Block(1,46,-4,LOG:13)
Block(1,46,2,LOG:13)
Block(1,47,-4,LOG:13)
Block(1,47,2,LOG:13)
Block(1,48,2,LOG:13)
Block(1,49,2,LOG:13)
Block(1,50,1,LOG:13)
Block(1,50,2,LOG:13)
Block(1,51,2,LOG:13)
Block(1,51,9,LEAVES:14)
Block(1,51,11,LEAVES:13)
Block(1,52,2,LOG:13)
Block(1,52,10,LEAVES:13)
Block(1,52,11,LEAVES:13)
Block(1,53,1,LOG:13)
Block(1,53,2,LOG:13)
Block(1,53,8,LEAVES:14)
Block(1,53,11,LEAVES:13)
Block(1,54,1,LOG:13)
Block(1,54,2,LOG:13)
Block(1,55,1,LOG:13)
Block(1,55,2,LOG:13)
Block(1,55,3,LOG:13)
Block(1,56,1,LOG:13)
Block(1,56,2,LOG:13)
Block(1,57,1,LOG:13)
Block(1,57,2,LOG:13)
Block(1,58,1,LOG:13)
Block(1,58,2,LOG:13)
Block(1,59,2,LOG:13)
Block(1,60,2,LOG:13)
Block(1,61,1,LOG:13)
Block(1,61,2,LOG:13)
Block(1,61,6,LEAVES:13)
Block(1,61,7,LEAVES:14)
Block(1,61,8,LEAVES:14)
Block(1,62,1,LOG:13)
Block(1,62,2,LOG:13)
Block(1,62,6,LEAVES:14)
Block(1,62,7,LEAVES:13)
Block(1,62,8,LOG:13)
Block(1,62,9,LEAVES:13)
Block(1,63,1,LOG:13)
Block(1,63,2,LOG:13)
Block(1,63,6,LEAVES:14)
Block(1,64,0,LOG:13)
Block(1,64,1,LOG:13)
Block(1,64,2,LOG:13)
Block(1,65,-3,LEAVES:14)
Block(1,65,2,LOG:13)
Block(1,65,3,LOG:13)
Block(1,66,-3,LEAVES:14)
Block(1,66,2,LOG:13)
Block(1,66,3,LOG:13)
Block(1,66,4,LOG:13)
Block(1,67,2,LOG:13)
Block(1,67,4,LOG:13)
Block(1,67,5,LOG:13)
Block(1,69,1,LOG:13)
Block(1,69,2,LOG:13)
Block(1,70,2,LOG:13)
Block(1,71,2,LOG:13)
Block(1,71,3,LOG:13)
Block(1,71,7,LEAVES:14)
Block(1,72,1,LEAVES:14)
Block(1,72,2,LOG:13)
Block(1,72,3,LOG:13)
Block(1,72,4,LOG:13)
Block(1,72,5,LEAVES:14)
Block(1,72,6,LEAVES:14)
Block(1,73,-1,LEAVES:14)
Block(1,73,1,LEAVES:14)
Block(1,73,2,LOG:13)
Block(1,73,3,LOG:13)
Block(1,73,4,LOG:13)
Block(1,74,-2,LEAVES:14)
Block(1,74,-1,LEAVES:14)
Block(1,74,1,LEAVES:14)
Block(1,74,2,LOG:13)
Block(1,74,3,LEAVES:14)
Block(1,74,4,LOG:13)
Block(1,74,5,LOG:13)
Block(1,75,1,LEAVES:13)
Block(1,75,2,LOG:13)
Block(1,75,4,LEAVES:13)
Block(1,75,5,LOG:13)
Block(1,76,1,LOG:13)
Block(1,76,5,LEAVES:13)
Block(1,76,7,LEAVES:13)
Block(1,76,8,LEAVES:13)
Block(1,77,0,LOG:13)
Block(1,77,1,LEAVES:13)
Block(1,77,2,LEAVES:13)
Block(1,77,9,LEAVES:14)
Block(1,78,0,LOG:13)
Block(1,78,1,LOG:13)
Block(1,78,7,LEAVES:14)
Block(1,78,8,LEAVES:14)
Block(1,79,0,LEAVES:14)
Block(1,79,1,LOG:13)
Block(1,79,2,LEAVES:13)
Block(2,-7,-5,LOG:13)
Block(2,-7,4,LOG:13)
Block(2,-6,3,LOG:13)
Block(2,-6,4,LOG_2:13)
Block(2,-5,2,LOG:13)
Block(2,-5,3,LOG_2:13)
Block(2,-5,4,LOG_2:13)
Block(2,-4,1,LOG:13)
Block(2,-4,2,LOG:13)
Block(2,-3,0,LOG_2:13)
Block(2,-3,1,LOG:13)
Block(2,-2,0,LOG_2:13)
Block(2,-2,1,LOG:13)
Block(2,-1,0,LOG_2:13)
Block(2,-1,1,LOG_2:13)
Block(2,0,0,LOG_2:13)
Block(2,0,1,LOG_2:13)
Block(2,1,0,LOG_2:13)
Block(2,1,1,LOG_2:13)
Block(2,2,0,LOG:13)
Block(2,2,1,LOG_2:13)
Block(2,3,1,LOG_2:13)
Block(2,4,1,LOG_2:13)
Block(2,5,1,LOG_2:13)
Block(2,6,1,LOG_2:13)
Block(2,28,4,LOG:13)
Block(2,28,5,LOG:13)
Block(2,28,6,LOG_2:13)
Block(2,28,7,LOG:13)
Block(2,29,4,LOG:13)
Block(2,29,5,LOG:13)
Block(2,29,7,LOG:13)
Block(2,29,8,LEAVES:13)
Block(2,30,7,LEAVES:13)
Block(2,37,-1,LOG_2:13)
Block(2,37,0,LOG:13)
Block(2,37,5,LOG:13)
Block(2,37,6,LOG:13)
Block(2,37,7,LEAVES:13)
Block(2,37,9,LEAVES:13)
Block(2,38,-1,LOG:13)
Block(2,38,5,LEAVES:13)
Block(2,38,6,LOG:13)
Block(2,38,7,LOG:13)
Block(2,38,8,LEAVES:13)
Block(2,38,9,LEAVES:13)
Block(2,39,5,LEAVES:13)
Block(2,39,6,LEAVES:13)
Block(2,39,9,LEAVES:13)
Block(2,46,-6,LEAVES:13)
Block(2,47,-6,LEAVES:13)
Block(2,47,-5,LOG:13)
Block(2,47,-4,LOG:13)
Block(2,47,2,LOG:13)
Block(2,48,-7,LEAVES:13)
Block(2,48,2,LOG:13)
Block(2,49,-9,LEAVES:13)
Block(2,49,-8,LEAVES:13)
Block(2,49,2,LOG:13)
Block(2,50,1,LOG:13)
Block(2,51,1,LOG:13)
Block(2,52,9,LEAVES:14)
Block(2,52,11,LEAVES:14)
Block(2,55,2,LOG:13)
Block(2,55,3,LOG:13)
Block(2,56,3,LOG:13)
Block(2,56,4,LOG:13)
Block(2,58,2,LOG:13)
Block(2,58,3,LOG:13)
Block(2,59,2,LOG:13)
Block(2,59,3,LOG:13)
Block(2,60,2,LOG:13)
Block(2,61,6,LOG:13)
Block(2,61,7,LEAVES:13)
Block(2,61,8,LEAVES:13)
Block(2,62,6,LOG:13)
Block(2,62,7,LOG:13)
Block(2,62,8,LOG:13)
Block(2,62,9,LEAVES:13)
Block(2,63,5,LEAVES:13)
Block(2,63,6,LEAVES:13)
Block(2,63,7,LEAVES:14)
Block(2,64,0,LOG:13)
Block(2,65,-4,LEAVES:14)
Block(2,65,-2,LOG:13)
Block(2,65,-1,LOG:13)
Block(2,65,0,LOG:13)
Block(2,66,-3,LOG:13)
Block(2,66,-2,LOG:13)
Block(2,67,-4,LEAVES:14)
Block(2,67,-3,LEAVES:14)
Block(2,69,0,LOG:13)
Block(2,69,1,LOG:13)
Block(2,70,0,LOG:13)
Block(2,71,-3,LEAVES:14)
Block(2,71,-1,LEAVES:14)
Block(2,72,5,LEAVES:14)
Block(2,73,-2,LEAVES:14)
Block(2,73,-1,LEAVES:13)
Block(2,73,0,LOG:13)
Block(2,73,1,LOG:13)
Block(2,73,2,LOG:13)
Block(2,73,3,LEAVES:14)
Block(2,74,-2,LEAVES:14)
Block(2,74,-1,LEAVES:14)
Block(2,74,0,LEAVES:13)
Block(2,74,1,LEAVES:14)
Block(2,74,2,LEAVES:14)
Block(2,74,5,LEAVES:13)
Block(2,74,6,LEAVES:13)
Block(2,74,7,LEAVES:13)
Block(2,74,8,LEAVES:13)
Block(2,75,2,LEAVES:14)
Block(2,75,5,LOG:13)
Block(2,75,6,LOG:13)
Block(2,75,7,LEAVES:13)
Block(2,75,8,LEAVES:13)
Block(2,76,2,LEAVES:13)
Block(2,76,5,LEAVES:13)
Block(2,76,6,LOG:13)
Block(2,76,7,LEAVES:13)
Block(2,76,8,LEAVES:13)
Block(2,77,0,LOG:13)
Block(2,77,1,LEAVES:13)
Block(2,77,6,LEAVES:13)
Block(2,77,7,LEAVES:14)
Block(2,77,8,LEAVES:14)
Block(2,78,0,LEAVES:13)
Block(2,78,1,LEAVES:13)
Block(2,79,-1,LEAVES:13)
Block(2,79,1,LEAVES:13)
Block(2,79,2,LEAVES:13)
Block(3,-9,-1,LOG:13)
Block(3,-8,-1,LOG:13)
Block(3,-8,0,LOG:13)
Block(3,-8,4,LOG_2:13)
Block(3,-7,0,LOG:13)
Block(3,-7,1,LOG:13)
Block(3,-7,4,LOG:13)
Block(3,-6,1,LOG:13)
Block(3,-6,2,LOG:13)
Block(3,-5,2,LOG:13)
Block(3,-4,1,LOG:13)
Block(3,-4,2,LOG:13)
Block(3,-3,0,LOG_2:13)
Block(3,-3,1,LOG:13)
Block(3,-2,0,LOG_2:13)
Block(3,-1,0,LOG_2:13)
Block(3,27,8,LOG:13)
Block(3,27,9,LOG:13)
Block(3,27,10,LEAVES:13)
Block(3,27,11,LEAVES:13)
Block(3,27,12,LEAVES:13)
Block(3,28,8,LOG:13)
Block(3,28,9,LEAVES:13)
Block(3,28,10,LEAVES:13)
Block(3,28,12,LEAVES:13)
Block(3,30,6,LEAVES:13)
Block(3,30,7,LOG:13)
Block(3,30,8,LEAVES:13)
Block(3,31,7,LEAVES:13)
Block(3,37,-1,LOG:13)
Block(3,37,7,LEAVES:13)
Block(3,37,8,LEAVES:13)
Block(3,37,9,LEAVES:13)
Block(3,38,-3,LEAVES:13)
Block(3,38,-1,LOG:13)
Block(3,38,0,LEAVES:13)
Block(3,38,6,LEAVES:13)
Block(3,38,7,LOG:13)
Block(3,38,8,LOG:13)
Block(3,38,9,LEAVES:13)
Block(3,39,-1,LEAVES:13)
Block(3,39,0,LEAVES:13)
Block(3,39,1,LEAVES:13)
Block(3,39,5,LEAVES:13)
Block(3,39,6,LEAVES:13)
Block(3,39,7,LEAVES:13)
Block(3,39,8,LEAVES:13)
Block(3,39,9,LEAVES:13)
Block(3,40,-3,LEAVES:13)
Block(3,40,-2,LEAVES:13)
Block(3,40,-1,LEAVES:13)
Block(3,41,0,LEAVES:13)
Block(3,46,-5,LEAVES:13)
Block(3,46,-4,LEAVES:13)
Block(3,47,-9,LEAVES:13)
Block(3,47,-8,LEAVES:13)
Block(3,47,-7,LEAVES:13)
Block(3,47,-6,LOG:13)
Block(3,47,-5,LOG:13)
Block(3,48,-8,LOG:13)
Block(3,48,-7,LOG:13)
Block(3,48,-6,LOG:13)
Block(3,48,-4,LEAVES:14)
Block(3,48,2,LOG:13)
Block(3,49,-9,LEAVES:13)
Block(3,49,-8,LEAVES:13)
Block(3,49,-7,LEAVES:13)
Block(3,49,-5,LEAVES:13)
Block(3,49,2,LOG:13)
Block(3,49,3,LOG:13)
Block(3,50,-6,LEAVES:13)
Block(3,50,8,LEAVES:13)
Block(3,51,0,LOG:13)
Block(3,51,1,LOG:13)
Block(3,52,0,LOG:13)
Block(3,52,7,LEAVES:14)
Block(3,52,8,LEAVES:13)
Block(3,53,7,LEAVES:14)
Block(3,56,4,LOG:13)
Block(3,57,4,LOG:13)
Block(3,57,7,LEAVES:13)
Block(3,58,6,LEAVES:13)
Block(3,59,3,LOG:13)
Block(3,60,3,LOG:13)
Block(3,60,4,LOG:13)
Block(3,60,5,LOG:13)
Block(3,61,4,LOG:13)
Block(3,61,5,LOG:13)
Block(3,61,6,LOG:13)
Block(3,61,7,LEAVES:14)
Block(3,62,3,LEAVES:14)
Block(3,62,6,LEAVES:13)
Block(3,62,7,LEAVES:13)
Block(3,62,8,LEAVES:13)
Block(3,63,6,LEAVES:14)
Block(3,63,7,LEAVES:13)
Block(3,63,8,LEAVES:13)
Block(3,64,-1,LEAVES:13)
Block(3,64,0,LOG:13)
Block(3,65,-4,LEAVES:13)
Block(3,65,-3,LOG:13)
Block(3,66,-4,LEAVES:13)
Block(3,66,-3,LOG:13)
Block(3,66,-2,LEAVES:13)
Block(3,67,-4,LEAVES:13)
Block(3,67,-3,LEAVES:13)
Block(3,68,-3,LEAVES:13)
Block(3,69,-2,LEAVES:13)
Block(3,69,-1,LEAVES:13)
Block(3,70,-2,LOG:13)
Block(3,70,-1,LOG:13)
Block(3,70,0,LOG:13)
Block(3,70,1,LOG:13)
Block(3,71,-2,LEAVES:14)
Block(3,71,-1,LEAVES:13)
Block(3,71,0,LEAVES:13)
Block(3,72,-2,LEAVES:13)
Block(3,72,-1,LEAVES:14)
Block(3,73,-1,LEAVES:13)
Block(3,73,0,LOG:13)
Block(3,73,8,LEAVES:13)
Block(3,74,-2,LEAVES:14)
Block(3,74,-1,LOG:13)
Block(3,74,0,LOG:13)
Block(3,74,1,LEAVES:13)
Block(3,74,7,LEAVES:13)
Block(3,75,-1,LEAVES:14)
Block(3,75,1,LEAVES:14)
Block(3,75,5,LEAVES:13)
Block(3,75,6,LEAVES:13)
Block(3,75,7,LEAVES:14)
Block(3,76,0,LEAVES:14)
Block(3,76,5,LEAVES:13)
Block(3,76,6,LOG:13)
Block(3,76,7,LOG:13)
Block(3,77,0,LEAVES:13)
Block(3,77,5,LEAVES:13)
Block(3,77,6,LEAVES:13)
Block(3,77,7,LEAVES:14)
Block(3,77,8,LEAVES:14)
Block(3,77,9,LEAVES:14)
Block(3,78,1,LEAVES:13)
Block(3,78,6,LEAVES:13)
Block(3,78,8,LEAVES:14)
Block(3,79,1,LEAVES:13)
Block(4,-8,4,LOG_2:13)
Block(4,25,12,LEAVES:13)
Block(4,26,10,LEAVES:13)
Block(4,26,12,LEAVES:13)
Block(4,27,10,LOG:13)
Block(4,27,11,LOG:13)
Block(4,27,12,LEAVES:13)
Block(4,28,9,LEAVES:13)
Block(4,28,10,LEAVES:13)
Block(4,28,12,LEAVES:13)
Block(4,29,8,LEAVES:13)
Block(4,29,9,LEAVES:13)
Block(4,30,6,LEAVES:13)
Block(4,30,7,LOG:13)
Block(4,30,8,LEAVES:13)
Block(4,31,7,LEAVES:13)
Block(4,37,-2,LEAVES:13)
Block(4,37,-1,LEAVES:13)
Block(4,38,-2,LEAVES:13)
Block(4,38,-1,LOG:13)
Block(4,38,0,LEAVES:13)
Block(4,38,5,LEAVES:13)
Block(4,38,7,LEAVES:13)
Block(4,39,-3,LEAVES:13)
Block(4,39,-2,LOG:13)
Block(4,39,-1,LOG:13)
Block(4,39,0,LOG:13)
Block(4,39,1,LEAVES:13)
Block(4,39,6,LEAVES:13)
Block(4,40,-3,LOG:13)
Block(4,40,-2,LOG:13)
Block(4,40,-1,LEAVES:13)
Block(4,40,0,LOG:13)
Block(4,40,1,LOG:13)
Block(4,40,2,LEAVES:13)
Block(4,41,-4,LEAVES:13)
Block(4,41,-3,LEAVES:13)
Block(4,41,-1,LEAVES:13)
Block(4,46,-6,LEAVES:13)
Block(4,47,-7,LEAVES:13)
Block(4,47,-6,LEAVES:14)
Block(4,47,-5,LEAVES:14)
Block(4,48,-9,LEAVES:13)
Block(4,48,-8,LEAVES:13)
Block(4,48,-7,LEAVES:13)
Block(4,48,-6,LOG:13)
Block(4,48,-5,LEAVES:13)
Block(4,49,-9,LEAVES:13)
Block(4,49,-8,LEAVES:13)
Block(4,49,-6,LOG:13)
Block(4,49,-5,LEAVES:13)
Block(4,49,-4,LEAVES:14)
Block(4,49,3,LOG:13)
Block(4,49,6,LEAVES:14)
Block(4,50,-5,LEAVES:13)
Block(4,50,6,LEAVES:14)
Block(4,50,7,LEAVES:13)
Block(4,50,8,LEAVES:13)
Block(4,51,5,LEAVES:13)
Block(4,51,6,LEAVES:13)
Block(4,51,7,LOG:13)
Block(4,51,8,LOG:13)
Block(4,52,-1,LOG:13)
Block(4,52,0,LOG:13)
Block(4,52,7,LOG:13)
Block(4,52,8,LEAVES:13)
Block(4,53,7,LEAVES:14)
Block(4,53,8,LEAVES:14)
Block(4,56,5,LEAVES:13)
Block(4,56,6,LOG:13)
Block(4,56,7,LOG:13)
Block(4,57,4,LOG:13)
Block(4,57,5,LOG:13)
Block(4,57,6,LOG:13)
Block(4,57,8,LEAVES:13)
Block(4,58,4,LEAVES:14)
Block(4,58,6,LEAVES:13)
Block(4,58,7,LEAVES:13)
Block(4,59,6,LEAVES:13)
Block(4,61,3,LEAVES:14)
Block(4,61,6,LOG:13)
Block(4,62,4,LEAVES:14)
Block(4,62,7,LEAVES:14)
Block(4,64,-2,LEAVES:13)
Block(4,64,-1,LOG:13)
Block(4,64,0,LOG:13)
Block(4,65,-1,LEAVES:13)
Block(4,65,0,LEAVES:14)
Block(4,66,-4,LEAVES:13)
Block(4,66,-3,LEAVES:13)
Block(4,66,-2,LEAVES:13)
Block(4,66,0,LEAVES:14)
Block(4,66,1,LEAVES:13)
Block(4,67,-3,LEAVES:13)
Block(4,67,-2,LEAVES:13)
Block(4,69,-3,LEAVES:14)
Block(4,70,-2,LOG:13)
Block(4,70,1,LOG:13)
Block(4,71,-3,LEAVES:13)
Block(4,71,-2,LOG:13)
Block(4,71,0,LEAVES:13)
Block(4,71,1,LOG:13)
Block(4,71,2,LOG:13)
Block(4,72,-1,LEAVES:13)
Block(4,72,1,LEAVES:13)
Block(4,72,2,LOG:13)
Block(4,72,4,LEAVES:13)
Block(4,73,2,LEAVES:14)
Block(4,73,4,LEAVES:13)
Block(4,74,-1,LEAVES:13)
Block(4,74,0,LEAVES:14)
Block(4,74,1,LEAVES:13)
Block(4,75,-1,LEAVES:14)
Block(4,75,0,LEAVES:14)
Block(4,75,6,LEAVES:13)
Block(4,75,7,LEAVES:14)
Block(4,76,-1,LEAVES:14)
Block(4,76,5,LEAVES:14)
Block(4,76,6,LEAVES:14)
Block(4,76,7,LEAVES:14)
Block(4,76,8,LEAVES:14)
Block(5,-9,4,LOG_2:13)
Block(5,-9,5,LOG_2:13)
Block(5,-8,5,LOG:13)
Block(5,26,11,LEAVES:13)
Block(5,26,12,LEAVES:13)
Block(5,26,13,LEAVES:13)
Block(5,27,12,LEAVES:13)
Block(5,28,7,LEAVES:13)
Block(5,28,9,LEAVES:13)
Block(5,28,10,LEAVES:13)
Block(5,28,11,LEAVES:13)
Block(5,29,7,LEAVES:13)
Block(5,29,8,LOG_2:13)
Block(5,29,9,LEAVES:13)
Block(5,29,10,LEAVES:13)
Block(5,30,6,LEAVES:13)
Block(5,30,8,LEAVES:13)
Block(5,31,7,LEAVES:13)
Block(5,31,9,LEAVES:13)
Block(5,38,-1,LEAVES:13)
Block(5,39,-3,LEAVES:13)
Block(5,39,-2,LEAVES:13)
Block(5,39,-1,LOG:13)
Block(5,39,0,LEAVES:13)
Block(5,39,1,LEAVES:13)
Block(5,40,-5,LEAVES:13)
Block(5,40,-4,LEAVES:13)
Block(5,40,-3,LOG:13)
Block(5,40,-1,LEAVES:13)
Block(5,40,0,LEAVES:13)
Block(5,40,1,LEAVES:13)
Block(5,40,2,LEAVES:13)
Block(5,41,-4,LEAVES:13)
Block(5,46,-6,LEAVES:13)
Block(5,46,-5,LEAVES:14)
Block(5,47,-7,LEAVES:13)
Block(5,47,-5,LEAVES:14)
Block(5,48,-8,LEAVES:13)
Block(5,48,-6,LOG:13)
Block(5,48,-5,LEAVES:14)
Block(5,48,-4,LEAVES:14)
Block(5,48,3,LOG:13)
Block(5,48,4,LOG:13)
Block(5,49,-6,LEAVES:13)
Block(5,49,3,LOG:13)
Block(5,49,4,LOG:13)
Block(5,49,5,LEAVES:14)
Block(5,49,6,LEAVES:14)
Block(5,49,7,LEAVES:14)
Block(5,50,-6,LEAVES:13)
Block(5,50,4,LOG:13)
Block(5,50,5,LOG:13)
Block(5,50,6,LOG:13)
Block(5,50,7,LEAVES:13)
Block(5,50,8,LEAVES:13)
Block(5,51,5,LEAVES:14)
Block(5,51,6,LOG:13)
Block(5,51,7,LOG:13)
Block(5,52,-2,LOG:13)
Block(5,52,-1,LOG:13)
Block(5,52,6,LEAVES:13)
Block(5,52,7,LEAVES:14)
Block(5,52,8,LEAVES:14)
Block(5,53,8,LEAVES:14)
Block(5,54,-2,LEAVES:13)
Block(5,55,-5,LEAVES:14)
Block(5,55,-3,LEAVES:13)
Block(5,55,-1,LEAVES:13)
Block(5,56,-6,LEAVES:14)
Block(5,56,-4,LEAVES:13)
Block(5,56,-3,LEAVES:13)
Block(5,56,-2,LEAVES:13)
Block(5,56,6,LEAVES:13)
Block(5,56,7,LOG:13)
Block(5,56,8,LEAVES:13)
Block(5,57,-3,LEAVES:13)
Block(5,57,5,LEAVES:14)
Block(5,57,6,LEAVES:13)
Block(5,57,7,LEAVES:13)
Block(5,58,4,LEAVES:14)
Block(5,58,5,LEAVES:13)
Block(5,58,6,LEAVES:13)
Block(5,58,7,LEAVES:13)
Block(5,58,8,LEAVES:13)
Block(5,59,5,LEAVES:14)
Block(5,61,6,LOG:13)
Block(5,62,5,LEAVES:13)
Block(5,62,6,LOG:13)
Block(5,62,7,LEAVES:13)
Block(5,63,-2,LEAVES:13)
Block(5,63,-1,LOG:13)
Block(5,63,0,LEAVES:13)
Block(5,63,6,LEAVES:13)
Block(5,63,7,LEAVES:13)
Block(5,63,8,LEAVES:13)
Block(5,64,-2,LEAVES:13)
Block(5,64,-1,LOG:13)
Block(5,64,0,LOG:13)
Block(5,64,1,LOG:13)
Block(5,64,2,LEAVES:13)
Block(5,64,6,LEAVES:14)
Block(5,65,-2,LEAVES:13)
Block(5,65,0,LOG:13)
Block(5,65,1,LOG:13)
Block(5,65,2,LOG:13)
Block(5,65,3,LEAVES:13)
Block(5,65,6,LEAVES:14)
Block(5,66,1,LEAVES:13)
Block(5,66,2,LOG:13)
Block(5,67,-4,LEAVES:13)
Block(5,67,1,LEAVES:14)
Block(5,67,2,LEAVES:13)
Block(5,67,3,LEAVES:14)
Block(5,67,5,LEAVES:13)
Block(5,70,-2,LEAVES:13)
Block(5,71,-3,LEAVES:13)
Block(5,71,1,LEAVES:14)
Block(5,71,3,LEAVES:14)
Block(5,71,5,LEAVES:13)
Block(5,72,-2,LEAVES:13)
Block(5,72,1,LEAVES:14)
Block(5,72,2,LOG:13)
Block(5,72,3,LOG:13)
Block(5,72,4,LOG:13)
Block(5,73,1,LEAVES:14)
Block(5,73,3,LEAVES:13)
Block(5,73,5,LEAVES:13)
Block(5,75,0,LEAVES:14)
Block(5,76,0,LEAVES:14)
Block(5,76,7,LEAVES:14)
Block(6,-9,5,LOG_2:13)
Block(6,-9,6,LOG:13)
Block(6,29,10,LEAVES:13)
Block(6,30,9,LEAVES:13)
Block(6,39,-2,LEAVES:13)
Block(6,39,-1,LOG:13)
Block(6,39,0,LEAVES:13)
Block(6,39,1,LEAVES:13)
Block(6,40,-4,LEAVES:13)
Block(6,40,-3,LEAVES:13)
Block(6,40,0,LEAVES:13)
Block(6,46,-7,LEAVES:14)
Block(6,47,-8,LEAVES:13)
Block(6,47,-7,LEAVES:14)
Block(6,47,-6,LEAVES:14)
Block(6,48,-5,LEAVES:14)
Block(6,48,4,LOG:13)
Block(6,48,5,LOG:13)
Block(6,49,-6,LEAVES:14)
Block(6,49,6,LEAVES:14)
Block(6,50,5,LEAVES:14)
Block(6,50,6,LEAVES:14)
Block(6,50,7,LEAVES:13)
Block(6,51,6,LEAVES:14)
Block(6,51,7,LEAVES:14)
Block(6,51,8,LEAVES:13)
Block(6,52,-3,LEAVES:14)
Block(6,52,-2,LOG:13)
Block(6,52,6,LEAVES:14)
Block(6,52,7,LEAVES:13)
Block(6,53,-2,LOG:13)
Block(6,54,-5,LEAVES:13)
Block(6,54,-4,LOG:13)
Block(6,54,-3,LOG:13)
Block(6,54,-2,LOG:13)
Block(6,54,-1,LEAVES:13)
Block(6,55,-6,LEAVES:14)
Block(6,55,-5,LOG:13)
Block(6,55,-4,LOG:13)
Block(6,55,-3,LEAVES:13)
Block(6,55,-2,LOG:13)
Block(6,56,-5,LOG:13)
Block(6,56,-4,LEAVES:13)
Block(6,56,-3,LEAVES:13)
Block(6,56,-2,LOG:13)
Block(6,56,-1,LEAVES:13)
Block(6,56,6,LEAVES:13)
Block(6,56,7,LOG:13)
Block(6,57,-5,LEAVES:14)
Block(6,57,-4,LEAVES:13)
Block(6,57,-2,LEAVES:13)
Block(6,57,5,LEAVES:14)
Block(6,57,6,LEAVES:13)
Block(6,57,7,LEAVES:13)
Block(6,57,8,LEAVES:13)
Block(6,58,4,LEAVES:14)
Block(6,58,5,LEAVES:14)
Block(6,58,6,LEAVES:13)
Block(6,58,7,LEAVES:13)
Block(6,61,5,LEAVES:14)
Block(6,61,6,LEAVES:13)
Block(6,62,-1,LEAVES:13)
Block(6,62,4,LEAVES:13)
Block(6,62,5,LOG:13)
Block(6,62,6,LOG:13)
Block(6,63,-2,LEAVES:13)
Block(6,63,-1,LOG:13)
Block(6,63,5,LEAVES:13)
Block(6,63,6,LEAVES:13)
Block(6,63,7,LEAVES:13)
Block(6,64,-2,LEAVES:13)
Block(6,64,-1,LEAVES:13)
Block(6,64,0,LEAVES:13)
Block(6,64,5,LEAVES:14)
Block(6,64,6,LEAVES:13)
Block(6,64,7,LEAVES:13)
Block(6,64,8,LEAVES:13)
Block(6,65,0,LEAVES:14)
Block(6,65,1,LEAVES:14)
Block(6,65,2,LEAVES:14)
Block(6,65,3,LEAVES:13)
Block(6,65,5,LEAVES:14)
Block(6,65,6,LEAVES:14)
Block(6,66,-1,LEAVES:14)
Block(6,66,1,LEAVES:14)
Block(6,66,2,LOG:13)
Block(6,66,3,LOG:13)
Block(6,67,2,LEAVES:13)
Block(6,67,3,LEAVES:13)
Block(6,67,4,LEAVES:13)
Block(6,71,3,LEAVES:13)
Block(6,72,1,LEAVES:14)
Block(6,72,3,LEAVES:13)
Block(6,72,4,LEAVES:13)
Block(6,73,2,LEAVES:14)
Block(7,38,0,LEAVES:13)
Block(7,39,-2,LEAVES:13)
Block(7,39,-1,LEAVES:13)
Block(7,40,-1,LEAVES:13)
Block(7,40,0,LEAVES:13)
Block(7,47,7,LEAVES:13)
Block(7,48,5,LOG:13)
Block(7,48,6,LOG:13)
Block(7,48,7,LEAVES:13)
Block(7,48,8,LEAVES:13)
Block(7,48,10,LEAVES:13)
Block(7,49,6,LEAVES:14)
Block(7,52,-3,LEAVES:14)
Block(7,52,-2,LOG:13)
Block(7,53,-2,LOG:13)
Block(7,55,-5,LEAVES:13)
Block(7,55,-4,LEAVES:13)
Block(7,55,-1,LEAVES:13)
Block(7,56,-6,LOG:13)
Block(7,56,-5,LOG:13)
Block(7,56,-3,LEAVES:14)
Block(7,56,-2,LEAVES:13)
Block(7,56,-1,LEAVES:13)
Block(7,56,7,LOG:13)
Block(7,56,8,LEAVES:13)
Block(7,57,-8,LEAVES:13)
Block(7,57,-7,LEAVES:13)
Block(7,57,-6,LEAVES:13)
Block(7,57,-5,LEAVES:14)
Block(7,57,-3,LEAVES:13)
Block(7,57,5,LEAVES:14)
Block(7,57,7,LEAVES:13)
Block(7,58,5,LEAVES:14)
Block(7,58,6,LEAVES:14)
Block(7,58,8,LEAVES:13)
Block(7,61,4,LEAVES:13)
Block(7,61,6,LEAVES:13)
Block(7,62,-1,LOG:13)
Block(7,62,4,LOG:13)
Block(7,62,5,LOG:13)
Block(7,62,7,LEAVES:13)
Block(7,63,-2,LEAVES:13)
Block(7,63,-1,LOG:13)
Block(7,63,4,LEAVES:13)
Block(7,63,6,LEAVES:13)
Block(7,64,-1,LEAVES:13)
Block(7,64,5,LEAVES:14)
Block(7,65,-1,LEAVES:14)
Block(7,65,0,LEAVES:14)
Block(7,65,1,LEAVES:13)
Block(7,65,2,LEAVES:13)
Block(7,66,0,LEAVES:14)
Block(7,66,1,LEAVES:14)
Block(7,66,2,LEAVES:13)
Block(7,66,3,LOG:13)
Block(7,66,4,LEAVES:13)
Block(7,67,-1,LEAVES:14)
Block(7,67,1,LEAVES:13)
Block(7,67,2,LEAVES:13)
Block(7,67,3,LOG:13)
Block(7,68,2,LEAVES:13)
Block(8,40,0,LEAVES:13)
Block(8,47,7,LEAVES:13)
Block(8,47,9,LEAVES:13)
Block(8,48,6,LOG:13)
Block(8,48,7,LOG:13)
Block(8,48,8,LOG:13)
Block(8,48,9,LEAVES:13)
Block(8,48,10,LEAVES:13)
Block(8,49,6,LEAVES:13)
Block(8,49,7,LEAVES:14)
Block(8,49,8,LEAVES:13)
Block(8,49,9,LEAVES:13)
Block(8,49,10,LEAVES:13)
Block(8,50,6,LEAVES:14)
Block(8,50,7,LEAVES:13)
Block(8,51,-2,LEAVES:14)
Block(8,51,-1,LEAVES:14)
Block(8,52,-2,LEAVES:14)
Block(8,52,-1,LEAVES:14)
Block(8,53,-2,LOG:13)
Block(8,54,-7,LEAVES:13)
Block(8,54,-6,LEAVES:13)
Block(8,54,-2,LOG:13)
Block(8,54,-1,LEAVES:13)
Block(8,55,-6,LEAVES:13)
Block(8,55,-3,LEAVES:14)
Block(8,55,-2,LEAVES:13)
Block(8,56,-7,LEAVES:13)
Block(8,56,-6,LOG:13)
Block(8,56,-5,LEAVES:13)
Block(8,56,-4,LEAVES:13)
Block(8,56,-2,LEAVES:13)
Block(8,56,0,LEAVES:13)
Block(8,56,7,LEAVES:13)
Block(8,57,-7,LEAVES:13)
Block(8,57,-5,LEAVES:14)
Block(8,57,-2,LEAVES:13)
Block(8,57,-1,LEAVES:14)
Block(8,57,4,LEAVES:14)
Block(8,57,5,LEAVES:14)
Block(8,57,7,LEAVES:13)
Block(8,58,5,LEAVES:14)
Block(8,58,6,LEAVES:14)
Block(8,59,5,LEAVES:14)
Block(8,59,6,LEAVES:14)
Block(8,61,5,LEAVES:13)
Block(8,62,5,LEAVES:13)
Block(8,62,6,LEAVES:13)
Block(8,63,-1,LEAVES:13)
Block(8,64,-1,LEAVES:13)
Block(8,65,0,LEAVES:14)
Block(8,66,-1,LEAVES:14)
Block(8,66,3,LEAVES:13)
Block(8,67,2,LEAVES:13)
Block(8,67,3,LEAVES:13)
Block(8,68,2,LEAVES:13)
Block(9,48,5,LEAVES:14)
Block(9,48,6,LEAVES:14)
Block(9,48,7,LEAVES:14)
Block(9,48,8,LEAVES:13)
Block(9,49,5,LEAVES:14)
Block(9,49,6,LEAVES:13)
Block(9,49,7,LEAVES:13)
Block(9,49,8,LEAVES:13)
Block(9,50,7,LEAVES:13)
Block(9,52,-3,LEAVES:14)
Block(9,52,-2,LEAVES:14)
Block(9,53,-3,LEAVES:13)
Block(9,53,-2,LEAVES:13)
Block(9,53,-1,LEAVES:14)
Block(9,54,-6,LEAVES:13)
Block(9,54,-3,LEAVES:13)
Block(9,54,-2,LOG:13)
Block(9,54,-1,LOG:13)
Block(9,55,-5,LEAVES:13)
Block(9,55,-3,LEAVES:13)
Block(9,55,-2,LEAVES:13)
Block(9,55,-1,LOG:13)
Block(9,55,0,LOG:13)
Block(9,56,-6,LEAVES:13)
Block(9,56,-5,LEAVES:13)
Block(9,56,-2,LEAVES:14)
Block(9,56,-1,LEAVES:13)
Block(9,56,1,LEAVES:13)
Block(9,57,-7,LEAVES:13)
Block(9,57,-3,LEAVES:14)
Block(9,58,6,LEAVES:14)
Block(9,59,5,LEAVES:14)
Block(9,66,2,LEAVES:13)
Block(9,67,1,LEAVES:13)
Block(9,67,2,LEAVES:13)
Block(9,68,2,LEAVES:13)
Block(10,48,6,LEAVES:14)
Block(10,49,7,LEAVES:13)
Block(10,49,8,LEAVES:13)
Block(10,50,6,LEAVES:14)
Block(10,52,-2,LEAVES:14)
Block(10,54,-2,LEAVES:13)
Block(10,54,-1,LEAVES:13)
Block(10,55,-1,LEAVES:13)
Block(10,55,0,LEAVES:13)
Block(10,56,-1,LEAVES:13)
Block(10,56,0,LEAVES:13)
Block(10,57,-2,LEAVES:14)
Block(10,57,-1,LEAVES:13)
Block(10,57,1,LEAVES:13)
Block(11,49,6,LEAVES:14)
Block(11,56,0,LEAVES:13)
Block(11,56,1,LEAVES:13)

#######################################################################
# +-----------------------------------------------------------------+ #
# |                            BO3 checks                           | #
# +-----------------------------------------------------------------+ #
#######################################################################

BlockCheck(-7,-6,-2,Solid)
BlockCheck(-6,-7,5,Solid)
BlockCheck(-5,-10,3,Solid)
BlockCheck(-5,-8,-3,Solid)
BlockCheck(-2,-6,6,Solid)
BlockCheck(1,-8,8,Solid)
BlockCheck(2,-8,-5,Solid)
BlockCheck(3,-10,-1,Solid)
BlockCheck(6,-10,6,Solid)

#######################################################################
# +-----------------------------------------------------------------+ #
# |                             Branches                            | #
# +-----------------------------------------------------------------+ #
#######################################################################


#######################################################################
# +-----------------------------------------------------------------+ #
# |                             Entities                            | #
# +-----------------------------------------------------------------+ #
#######################################################################


#######################################################################
# +-----------------------------------------------------------------+ #
# |                            Particles                            | #
# +-----------------------------------------------------------------+ #
#######################################################################


#######################################################################
# +-----------------------------------------------------------------+ #
# |                             Spawners                            | #
# +-----------------------------------------------------------------+ #
#######################################################################


#######################################################################
# +-----------------------------------------------------------------+ #
# |                             ModData                             | #
# +-----------------------------------------------------------------+ #
#######################################################################

