
#######################################################################
# +-----------------------------------------------------------------+ #
# |                            BO4 object                           | #
# +-----------------------------------------------------------------+ #
#######################################################################

Author: NLBlackEagle

Description: No description given

SettingsMode: WriteDisable


#######################################################################
# +-----------------------------------------------------------------+ #
# |                          Main settings                          | #
# +-----------------------------------------------------------------+ #
#######################################################################

Frequency: 0

SpawnHeight: highestBlock

UseCenterForHighestBlock: true

##############################
# Height Limits for the BO4. #
##############################

MinHeight: 0

MaxHeight: 255

InheritBO3: 

InheritBO3Rotation: NORTH

OverrideChildSettings: true

OverrideParentHeight: false

CanOverride: true

BranchFrequency: 0

BranchFrequencyGroup: 

MustBeBelowOther: false

MustBeInside: 

CannotBeInside: 

ReplacesBO3: 

MustBeInsideWorldBorders: false

CanSpawnOnWater: true

SpawnOnWaterOnly: false

SpawnUnderWater: false

SpawnAtWaterLevel: false

HeightOffset: 0

RemoveAir: true

ReplaceAbove: 

ReplaceBelow: 

ReplaceWithBiomeBlocks: true

ReplaceWithSurfaceBlock: GRASS

ReplaceWithGroundBlock: DIRT

ReplaceWithStoneBlock: STONE

SmoothRadius: 0

SmoothHeightOffset: 0

SmoothStartTop: false

SmoothStartWood: false

SmoothingSurfaceBlock: 

SmoothingGroundBlock: 

BO3Group: 

IsSpawnPoint: false

DoReplaceBlocks: true


#######################################################################
# +-----------------------------------------------------------------+ #
# |                              Blocks                             | #
# +-----------------------------------------------------------------+ #
#######################################################################

Block(2,19,8,STAINED_CLAY:3)
Block(2,20,7,STAINED_CLAY:3)
Block(2,20,8,STAINED_CLAY:3)
Block(2,21,5,STAINED_CLAY:3)
Block(3,17,8,STAINED_CLAY:3)
Block(3,18,7,STAINED_CLAY:3)
Block(3,18,8,STAINED_CLAY:3)
Block(3,19,5,STAINED_CLAY:3)
Block(3,19,6,STAINED_CLAY:3)
Block(3,19,7,STAINED_CLAY:3)
Block(3,19,8,STAINED_CLAY:3)
Block(3,20,4,STAINED_CLAY:3)
Block(3,20,5,STAINED_CLAY:3)
Block(3,20,6,STAINED_CLAY:3)
Block(3,20,7,STAINED_CLAY:3)
Block(3,20,8,STAINED_CLAY:3)
Block(3,21,2,STAINED_CLAY:3)
Block(3,21,3,STAINED_CLAY:3)
Block(3,21,4,STAINED_CLAY:3)
Block(3,21,5,STAINED_CLAY:3)
Block(3,22,1,STAINED_CLAY:3)
Block(3,22,2,STAINED_CLAY:3)
Block(4,17,6,STAINED_CLAY:3)
Block(4,17,7,STAINED_CLAY:3)
Block(4,17,8,STAINED_CLAY:3)
Block(4,18,4,STAINED_CLAY:3)
Block(4,18,5,STAINED_CLAY:3)
Block(4,18,6,STAINED_CLAY:3)
Block(4,18,7,STAINED_CLAY:3)
Block(4,18,8,STAINED_CLAY:3)
Block(4,19,2,STAINED_CLAY:3)
Block(4,19,3,STAINED_CLAY:3)
Block(4,19,4,STAINED_CLAY:3)
Block(4,19,5,STAINED_CLAY:3)
Block(4,19,6,STAINED_CLAY:3)
Block(4,19,7,STAINED_CLAY:3)
Block(4,19,8,STAINED_CLAY:3)
Block(4,20,1,STAINED_CLAY:3)
Block(4,20,2,STAINED_CLAY:3)
Block(4,20,3,STAINED_CLAY:3)
Block(4,20,4,STAINED_CLAY:3)
Block(4,20,5,STAINED_CLAY:3)
Block(4,20,6,STAINED_CLAY:3)
Block(4,20,7,STAINED_CLAY:3)
Block(4,20,8,STAINED_CLAY:3)
Block(4,21,0,STAINED_CLAY:3)
Block(4,21,1,STAINED_CLAY:3)
Block(4,21,2,STAINED_CLAY:3)
Block(4,21,3,STAINED_CLAY:3)
Block(4,21,4,STAINED_CLAY:3)
Block(4,21,5,STAINED_CLAY:3)
Block(4,21,6,STAINED_CLAY:3)
Block(4,22,-2,STAINED_CLAY:3)
Block(4,22,-1,STAINED_CLAY:3)
Block(4,22,0,STAINED_CLAY:3)
Block(4,22,1,STAINED_CLAY:3)
Block(4,22,2,STAINED_CLAY:3)
Block(4,22,3,STAINED_CLAY:3)
Block(4,23,-3,STAINED_CLAY:3)
Block(4,23,-2,STAINED_CLAY:3)
Block(4,23,-1,STAINED_CLAY:3)
Block(4,23,0,STAINED_CLAY:3)
Block(4,24,-4,STAINED_CLAY:3)
Block(4,24,-3,STAINED_CLAY:3)
Block(4,25,-6,STAINED_CLAY:3)
Block(5,16,8,STAINED_CLAY:3)
Block(5,17,6,STAINED_CLAY:3)
Block(5,17,7,STAINED_CLAY:3)
Block(5,17,8,STAINED_CLAY:3)
Block(5,18,4,STAINED_CLAY:3)
Block(5,18,5,STAINED_CLAY:3)
Block(5,18,6,STAINED_CLAY:3)
Block(5,18,7,STAINED_CLAY:3)
Block(5,18,8,STAINED_CLAY:3)
Block(5,19,2,STAINED_CLAY:3)
Block(5,19,3,STAINED_CLAY:3)
Block(5,19,4,STAINED_CLAY:3)
Block(5,19,5,STAINED_CLAY:3)
Block(5,19,6,STAINED_CLAY:3)
Block(5,19,7,STAINED_CLAY:3)
Block(5,19,8,STAINED_CLAY:3)
Block(5,20,0,STAINED_CLAY:3)
Block(5,20,1,STAINED_CLAY:3)
Block(5,20,2,STAINED_CLAY:3)
Block(5,20,3,STAINED_CLAY:3)
Block(5,20,4,STAINED_CLAY:3)
Block(5,20,5,STAINED_CLAY:3)
Block(5,20,6,STAINED_CLAY:3)
Block(5,20,7,STAINED_CLAY:3)
Block(5,20,8,STAINED_CLAY:3)
Block(5,21,-2,STAINED_CLAY:3)
Block(5,21,-1,STAINED_CLAY:3)
Block(5,21,0,STAINED_CLAY:3)
Block(5,21,1,STAINED_CLAY:3)
Block(5,21,2,STAINED_CLAY:3)
Block(5,21,3,STAINED_CLAY:3)
Block(5,21,4,STAINED_CLAY:3)
Block(5,21,5,STAINED_CLAY:3)
Block(5,21,6,STAINED_CLAY:3)
Block(5,22,-4,STAINED_CLAY:3)
Block(5,22,-3,STAINED_CLAY:3)
Block(5,22,-2,STAINED_CLAY:3)
Block(5,22,-1,STAINED_CLAY:3)
Block(5,22,0,STAINED_CLAY:3)
Block(5,22,1,STAINED_CLAY:3)
Block(5,22,2,STAINED_CLAY:3)
Block(5,22,3,STAINED_CLAY:3)
Block(5,23,-6,STAINED_CLAY:3)
Block(5,23,-5,STAINED_CLAY:3)
Block(5,23,-4,STAINED_CLAY:3)
Block(5,23,-3,STAINED_CLAY:3)
Block(5,23,-2,STAINED_CLAY:3)
Block(5,23,-1,STAINED_CLAY:3)
Block(5,23,0,STAINED_CLAY:3)
Block(5,24,-7,STAINED_CLAY:3)
Block(5,24,-6,STAINED_CLAY:3)
Block(5,24,-5,STAINED_CLAY:3)
Block(5,24,-4,STAINED_CLAY:3)
Block(5,24,-3,STAINED_CLAY:3)
Block(5,25,-7,STAINED_CLAY:3)
Block(5,25,-6,STAINED_CLAY:3)
Block(5,25,-5,STAINED_CLAY:3)
Block(6,16,8,STAINED_CLAY:3)
Block(6,17,6,STAINED_CLAY:3)
Block(6,17,7,STAINED_CLAY:3)
Block(6,17,8,STAINED_CLAY:3)
Block(6,18,4,STAINED_CLAY:3)
Block(6,18,5,STAINED_CLAY:3)
Block(6,18,6,STAINED_CLAY:3)
Block(6,18,7,STAINED_CLAY:3)
Block(6,18,8,STAINED_CLAY:3)
Block(6,19,2,STAINED_CLAY:3)
Block(6,19,3,STAINED_CLAY:3)
Block(6,19,4,STAINED_CLAY:3)
Block(6,19,5,STAINED_CLAY:3)
Block(6,19,6,STAINED_CLAY:3)
Block(6,19,7,STAINED_CLAY:3)
Block(6,19,8,STAINED_CLAY:3)
Block(6,20,0,STAINED_CLAY:3)
Block(6,20,1,STAINED_CLAY:3)
Block(6,20,2,STAINED_CLAY:3)
Block(6,20,3,STAINED_CLAY:3)
Block(6,20,4,STAINED_CLAY:3)
Block(6,20,5,STAINED_CLAY:3)
Block(6,20,6,STAINED_CLAY:3)
Block(6,20,7,STAINED_CLAY:3)
Block(6,20,8,STAINED_CLAY:3)
Block(6,21,-2,OBSIDIAN:0)
Block(6,21,-1,STAINED_CLAY:3)
Block(6,21,0,STAINED_CLAY:3)
Block(6,21,1,STAINED_CLAY:3)
Block(6,21,2,STAINED_CLAY:3)
Block(6,21,3,STAINED_CLAY:3)
Block(6,21,4,STAINED_CLAY:3)
Block(6,21,5,STAINED_CLAY:3)
Block(6,21,6,STAINED_CLAY:3)
Block(6,21,7,STAINED_CLAY:3)
Block(6,22,-4,OBSIDIAN:0)
Block(6,22,-3,OBSIDIAN:0)
Block(6,22,-2,OBSIDIAN:0)
Block(6,22,-1,OBSIDIAN:0)
Block(6,22,0,STAINED_CLAY:3)
Block(6,22,1,STAINED_CLAY:3)
Block(6,22,2,STAINED_CLAY:3)
Block(6,22,3,STAINED_CLAY:3)
Block(6,22,4,STAINED_CLAY:3)
Block(6,23,-6,STAINED_CLAY:3)
Block(6,23,-5,OBSIDIAN:0)
Block(6,23,-4,OBSIDIAN:0)
Block(6,23,-3,OBSIDIAN:0)
Block(6,23,-2,OBSIDIAN:0)
Block(6,23,-1,OBSIDIAN:0)
Block(6,23,0,STAINED_CLAY:3)
Block(6,23,1,STAINED_CLAY:3)
Block(6,24,-7,STAINED_CLAY:3)
Block(6,24,-6,STAINED_CLAY:3)
Block(6,24,-5,OBSIDIAN:0)
Block(6,24,-4,OBSIDIAN:0)
Block(6,24,-3,OBSIDIAN:0)
Block(6,24,-2,OBSIDIAN:0)
Block(6,25,-7,STAINED_CLAY:3)
Block(6,25,-6,STAINED_CLAY:3)
Block(6,25,-5,STAINED_CLAY:3)
Block(7,16,8,OBSIDIAN:0)
Block(7,17,6,OBSIDIAN:0)
Block(7,17,7,STAINED_CLAY:3)
Block(7,17,8,OBSIDIAN:0)
Block(7,18,4,OBSIDIAN:0)
Block(7,18,5,OBSIDIAN:0)
Block(7,18,6,OBSIDIAN:0)
Block(7,18,7,OBSIDIAN:0)
Block(7,18,8,OBSIDIAN:0)
Block(7,19,2,OBSIDIAN:0)
Block(7,19,3,OBSIDIAN:0)
Block(7,19,4,OBSIDIAN:0)
Block(7,19,5,OBSIDIAN:0)
Block(7,19,6,OBSIDIAN:0)
Block(7,19,7,OBSIDIAN:0)
Block(7,19,8,STAINED_CLAY:3)
Block(7,20,0,OBSIDIAN:0)
Block(7,20,1,OBSIDIAN:0)
Block(7,20,2,OBSIDIAN:0)
Block(7,20,3,OBSIDIAN:0)
Block(7,20,4,OBSIDIAN:0)
Block(7,20,5,OBSIDIAN:0)
Block(7,20,6,OBSIDIAN:0)
Block(7,20,7,OBSIDIAN:0)
Block(7,20,8,STAINED_CLAY:3)
Block(7,21,-2,OBSIDIAN:0)
Block(7,21,-1,OBSIDIAN:0)
Block(7,21,0,OBSIDIAN:0)
Block(7,21,1,OBSIDIAN:0)
Block(7,21,2,OBSIDIAN:0)
Block(7,21,3,OBSIDIAN:0)
Block(7,21,4,OBSIDIAN:0)
Block(7,21,5,OBSIDIAN:0)
Block(7,21,6,OBSIDIAN:0)
Block(7,21,7,STAINED_CLAY:3)
Block(7,22,-4,OBSIDIAN:0)
Block(7,22,-3,OBSIDIAN:0)
Block(7,22,-2,OBSIDIAN:0)
Block(7,22,-1,OBSIDIAN:0)
Block(7,22,0,OBSIDIAN:0)
Block(7,22,1,OBSIDIAN:0)
Block(7,22,2,OBSIDIAN:0)
Block(7,22,3,OBSIDIAN:0)
Block(7,22,4,STAINED_CLAY:3)
Block(7,23,-6,OBSIDIAN:0)
Block(7,23,-5,OBSIDIAN:0)
Block(7,23,-4,OBSIDIAN:0)
Block(7,23,-3,OBSIDIAN:0)
Block(7,23,-2,OBSIDIAN:0)
Block(7,23,-1,OBSIDIAN:0)
Block(7,23,0,OBSIDIAN:0)
Block(7,23,1,OBSIDIAN:0)
Block(7,24,-7,STAINED_CLAY:3)
Block(7,24,-6,OBSIDIAN:0)
Block(7,24,-5,OBSIDIAN:0)
Block(7,24,-4,OBSIDIAN:0)
Block(7,24,-3,OBSIDIAN:0)
Block(7,24,-2,OBSIDIAN:0)
Block(7,24,-1,OBSIDIAN:0)
Block(7,25,-7,STAINED_CLAY:3)
Block(7,25,-6,OBSIDIAN:0)
Block(7,25,-5,OBSIDIAN:0)
Block(7,25,-4,OBSIDIAN:0)
Block(7,26,-7,STAINED_CLAY:3)

#######################################################################
# +-----------------------------------------------------------------+ #
# |                             Branches                            | #
# +-----------------------------------------------------------------+ #
#######################################################################


#######################################################################
# +-----------------------------------------------------------------+ #
# |                             Entities                            | #
# +-----------------------------------------------------------------+ #
#######################################################################


#######################################################################
# +-----------------------------------------------------------------+ #
# |                            Particles                            | #
# +-----------------------------------------------------------------+ #
#######################################################################


#######################################################################
# +-----------------------------------------------------------------+ #
# |                             Spawners                            | #
# +-----------------------------------------------------------------+ #
#######################################################################


#######################################################################
# +-----------------------------------------------------------------+ #
# |                             ModData                             | #
# +-----------------------------------------------------------------+ #
#######################################################################

