
#######################################################################
# +-----------------------------------------------------------------+ #
# |                            BO4 object                           | #
# +-----------------------------------------------------------------+ #
#######################################################################

Author: NLBlackEagle

Description: No description given

SettingsMode: WriteDisable


#######################################################################
# +-----------------------------------------------------------------+ #
# |                          Main settings                          | #
# +-----------------------------------------------------------------+ #
#######################################################################

Frequency: 0

SpawnHeight: highestBlock

UseCenterForHighestBlock: true

##############################
# Height Limits for the BO4. #
##############################

MinHeight: 0

MaxHeight: 255

InheritBO3: 

InheritBO3Rotation: NORTH

OverrideChildSettings: true

OverrideParentHeight: false

CanOverride: true

BranchFrequency: 0

BranchFrequencyGroup: 

MustBeBelowOther: false

MustBeInside: 

CannotBeInside: 

ReplacesBO3: 

MustBeInsideWorldBorders: false

CanSpawnOnWater: true

SpawnOnWaterOnly: false

SpawnUnderWater: false

SpawnAtWaterLevel: false

HeightOffset: 0

RemoveAir: true

ReplaceAbove: 

ReplaceBelow: 

ReplaceWithBiomeBlocks: true

ReplaceWithSurfaceBlock: GRASS

ReplaceWithGroundBlock: DIRT

ReplaceWithStoneBlock: STONE

SmoothRadius: 0

SmoothHeightOffset: 0

SmoothStartTop: false

SmoothStartWood: false

SmoothingSurfaceBlock: 

SmoothingGroundBlock: 

BO3Group: 

IsSpawnPoint: false

DoReplaceBlocks: true


#######################################################################
# +-----------------------------------------------------------------+ #
# |                              Blocks                             | #
# +-----------------------------------------------------------------+ #
#######################################################################

Block(-8,0,-4,STAINED_CLAY:3)
Block(-8,0,-3,STAINED_CLAY:3)
Block(-8,0,-2,STAINED_CLAY:3)
Block(-8,0,-1,STAINED_CLAY:3)
Block(-8,0,0,STAINED_CLAY:3)
Block(-8,0,1,STAINED_CLAY:3)
Block(-8,0,2,STAINED_CLAY:3)
Block(-8,0,3,STAINED_CLAY:3)
Block(-8,0,4,STAINED_CLAY:3)
Block(-8,0,5,STAINED_CLAY:3)
Block(-8,0,6,STAINED_CLAY:3)
Block(-8,0,7,STAINED_CLAY:3)
Block(-8,0,8,STAINED_CLAY:3)
Block(-8,1,-4,STAINED_CLAY:3)
Block(-8,1,-3,STAINED_CLAY:3)
Block(-8,1,-2,STAINED_CLAY:3)
Block(-8,1,-1,STAINED_CLAY:3)
Block(-8,1,0,STAINED_CLAY:3)
Block(-8,1,1,STAINED_CLAY:3)
Block(-8,1,2,STAINED_CLAY:3)
Block(-8,1,3,STAINED_CLAY:3)
Block(-8,1,4,STAINED_CLAY:3)
Block(-8,1,5,STAINED_CLAY:3)
Block(-8,1,6,STAINED_CLAY:3)
Block(-8,1,7,STAINED_CLAY:3)
Block(-8,1,8,STAINED_CLAY:3)
Block(-8,2,-5,STAINED_CLAY:3)
Block(-8,2,-4,STAINED_CLAY:3)
Block(-8,2,-3,STAINED_CLAY:3)
Block(-8,2,-2,STAINED_CLAY:3)
Block(-8,2,-1,STAINED_CLAY:3)
Block(-8,2,0,STAINED_CLAY:3)
Block(-8,2,1,STAINED_CLAY:3)
Block(-8,2,2,STAINED_CLAY:3)
Block(-8,2,3,STAINED_CLAY:3)
Block(-8,2,4,STAINED_CLAY:3)
Block(-8,2,5,STAINED_CLAY:3)
Block(-8,2,6,STAINED_CLAY:3)
Block(-8,2,7,STAINED_CLAY:3)
Block(-8,2,8,STAINED_CLAY:3)
Block(-8,3,-5,STAINED_CLAY:3)
Block(-8,3,-4,STAINED_CLAY:3)
Block(-8,3,-3,STAINED_CLAY:3)
Block(-8,3,-2,STAINED_CLAY:3)
Block(-8,3,-1,STAINED_CLAY:3)
Block(-8,3,0,STAINED_CLAY:3)
Block(-8,3,1,STAINED_CLAY:3)
Block(-8,3,2,STAINED_CLAY:3)
Block(-8,3,3,STAINED_CLAY:3)
Block(-8,3,4,STAINED_CLAY:3)
Block(-8,3,5,STAINED_CLAY:3)
Block(-8,3,6,STAINED_CLAY:3)
Block(-8,3,7,STAINED_CLAY:3)
Block(-8,3,8,STAINED_CLAY:3)
Block(-8,4,-5,STAINED_CLAY:3)
Block(-8,4,-4,STAINED_CLAY:3)
Block(-8,4,-3,STAINED_CLAY:3)
Block(-8,4,-2,STAINED_CLAY:3)
Block(-8,4,-1,STAINED_CLAY:3)
Block(-8,4,0,STAINED_CLAY:3)
Block(-8,4,1,STAINED_CLAY:3)
Block(-8,4,2,STAINED_CLAY:3)
Block(-8,4,3,STAINED_CLAY:3)
Block(-8,4,4,STAINED_CLAY:3)
Block(-8,4,5,STAINED_CLAY:3)
Block(-8,4,6,STAINED_CLAY:3)
Block(-8,4,7,STAINED_CLAY:3)
Block(-8,4,8,STAINED_CLAY:3)
Block(-8,5,-5,STAINED_CLAY:3)
Block(-8,5,-4,STAINED_CLAY:3)
Block(-8,5,-3,STAINED_CLAY:3)
Block(-8,5,-2,STAINED_CLAY:3)
Block(-8,5,-1,STAINED_CLAY:3)
Block(-8,5,0,STAINED_CLAY:3)
Block(-8,5,1,STAINED_CLAY:3)
Block(-8,5,2,STAINED_CLAY:3)
Block(-8,5,3,STAINED_CLAY:3)
Block(-8,5,4,STAINED_CLAY:3)
Block(-8,5,5,STAINED_CLAY:3)
Block(-8,5,6,STAINED_CLAY:3)
Block(-8,5,7,STAINED_CLAY:3)
Block(-8,5,8,STAINED_CLAY:3)
Block(-8,6,-5,STAINED_CLAY:3)
Block(-8,6,-4,STAINED_CLAY:3)
Block(-8,6,-3,STAINED_CLAY:3)
Block(-8,6,-2,STAINED_CLAY:3)
Block(-8,6,-1,STAINED_CLAY:3)
Block(-8,6,0,STAINED_CLAY:3)
Block(-8,6,1,STAINED_CLAY:3)
Block(-8,6,2,STAINED_CLAY:3)
Block(-8,6,3,STAINED_CLAY:3)
Block(-8,6,4,STAINED_CLAY:3)
Block(-8,6,5,STAINED_CLAY:3)
Block(-8,6,6,STAINED_CLAY:3)
Block(-8,6,7,STAINED_CLAY:3)
Block(-8,6,8,STAINED_CLAY:3)
Block(-8,7,-6,STAINED_CLAY:3)
Block(-8,7,-5,STAINED_CLAY:3)
Block(-8,7,-4,STAINED_CLAY:3)
Block(-8,7,-3,STAINED_CLAY:3)
Block(-8,7,-2,STAINED_CLAY:3)
Block(-8,7,-1,STAINED_CLAY:3)
Block(-8,7,0,STAINED_CLAY:3)
Block(-8,7,1,STAINED_CLAY:3)
Block(-8,7,2,STAINED_CLAY:3)
Block(-8,7,3,STAINED_CLAY:3)
Block(-8,7,4,STAINED_CLAY:3)
Block(-8,7,5,STAINED_CLAY:3)
Block(-8,7,6,STAINED_CLAY:3)
Block(-8,7,7,STAINED_CLAY:3)
Block(-8,7,8,STAINED_CLAY:3)
Block(-8,8,-6,STAINED_CLAY:3)
Block(-8,8,-5,STAINED_CLAY:3)
Block(-8,8,-4,STAINED_CLAY:3)
Block(-8,8,-3,STAINED_CLAY:3)
Block(-8,8,-2,STAINED_CLAY:3)
Block(-8,8,-1,STAINED_CLAY:3)
Block(-8,8,0,STAINED_CLAY:3)
Block(-8,8,1,STAINED_CLAY:3)
Block(-8,8,2,STAINED_CLAY:3)
Block(-8,8,3,STAINED_CLAY:3)
Block(-8,8,4,STAINED_CLAY:3)
Block(-8,8,5,STAINED_CLAY:3)
Block(-8,8,6,STAINED_CLAY:3)
Block(-8,8,7,STAINED_CLAY:3)
Block(-8,8,8,STAINED_CLAY:3)
Block(-8,9,-6,STAINED_CLAY:3)
Block(-8,9,-5,STAINED_CLAY:3)
Block(-8,9,-4,STAINED_CLAY:3)
Block(-8,9,-3,STAINED_CLAY:3)
Block(-8,9,-2,STAINED_CLAY:3)
Block(-8,9,-1,STAINED_CLAY:3)
Block(-8,9,0,STAINED_CLAY:3)
Block(-8,9,1,STAINED_CLAY:3)
Block(-8,9,2,STAINED_CLAY:3)
Block(-8,9,3,STAINED_CLAY:3)
Block(-8,9,4,STAINED_CLAY:3)
Block(-8,9,5,STAINED_CLAY:3)
Block(-8,9,6,STAINED_CLAY:3)
Block(-8,9,7,STAINED_CLAY:3)
Block(-8,9,8,STAINED_CLAY:3)
Block(-8,10,-6,STAINED_CLAY:3)
Block(-8,10,-5,STAINED_CLAY:3)
Block(-8,10,-4,STAINED_CLAY:3)
Block(-8,10,-3,STAINED_CLAY:3)
Block(-8,10,-2,STAINED_CLAY:3)
Block(-8,10,-1,STAINED_CLAY:3)
Block(-8,10,0,STAINED_CLAY:3)
Block(-8,10,1,STAINED_CLAY:3)
Block(-8,10,2,STAINED_CLAY:3)
Block(-8,10,3,STAINED_CLAY:3)
Block(-8,10,4,STAINED_CLAY:3)
Block(-8,10,5,STAINED_CLAY:3)
Block(-8,10,6,STAINED_CLAY:3)
Block(-8,10,7,STAINED_CLAY:3)
Block(-8,10,8,STAINED_CLAY:3)
Block(-8,11,-7,OBSIDIAN:0)
Block(-8,11,-6,STAINED_CLAY:3)
Block(-8,11,-5,STAINED_CLAY:3)
Block(-8,11,-4,STAINED_CLAY:3)
Block(-8,11,-3,STAINED_CLAY:3)
Block(-8,11,-2,STAINED_CLAY:3)
Block(-8,11,-1,STAINED_CLAY:3)
Block(-8,11,0,STAINED_CLAY:3)
Block(-8,11,1,STAINED_CLAY:3)
Block(-8,11,2,STAINED_CLAY:3)
Block(-8,11,3,STAINED_CLAY:3)
Block(-8,11,4,STAINED_CLAY:3)
Block(-8,11,5,STAINED_CLAY:3)
Block(-8,11,6,STAINED_CLAY:3)
Block(-8,11,7,STAINED_CLAY:3)
Block(-8,11,8,STAINED_CLAY:3)
Block(-8,12,-7,OBSIDIAN:0)
Block(-8,12,-6,STAINED_CLAY:3)
Block(-8,12,-5,STAINED_CLAY:3)
Block(-8,12,-4,STAINED_CLAY:3)
Block(-8,12,-3,STAINED_CLAY:3)
Block(-8,12,-2,STAINED_CLAY:3)
Block(-8,12,-1,STAINED_CLAY:3)
Block(-8,12,0,STAINED_CLAY:3)
Block(-8,12,1,STAINED_CLAY:3)
Block(-8,12,2,STAINED_CLAY:3)
Block(-8,12,3,STAINED_CLAY:3)
Block(-8,12,4,STAINED_CLAY:3)
Block(-8,12,5,STAINED_CLAY:3)
Block(-8,12,6,STAINED_CLAY:3)
Block(-8,12,7,STAINED_CLAY:3)
Block(-8,12,8,STAINED_CLAY:3)
Block(-8,13,-7,OBSIDIAN:0)
Block(-8,13,-6,STAINED_CLAY:3)
Block(-8,13,-5,STAINED_CLAY:3)
Block(-8,13,-4,STAINED_CLAY:3)
Block(-8,13,-3,STAINED_CLAY:3)
Block(-8,13,-2,STAINED_CLAY:3)
Block(-8,13,-1,STAINED_CLAY:3)
Block(-8,13,0,STAINED_CLAY:3)
Block(-8,13,1,STAINED_CLAY:3)
Block(-8,13,2,STAINED_CLAY:3)
Block(-8,13,3,STAINED_CLAY:3)
Block(-8,13,4,STAINED_CLAY:3)
Block(-8,13,5,STAINED_CLAY:3)
Block(-8,13,6,STAINED_CLAY:3)
Block(-8,13,7,STAINED_CLAY:3)
Block(-8,13,8,STAINED_CLAY:3)
Block(-8,14,-7,OBSIDIAN:0)
Block(-8,14,-6,STAINED_CLAY:3)
Block(-8,14,-5,STAINED_CLAY:3)
Block(-8,14,-4,STAINED_CLAY:3)
Block(-8,14,-3,STAINED_CLAY:3)
Block(-8,14,-2,STAINED_CLAY:3)
Block(-8,14,-1,STAINED_CLAY:3)
Block(-8,14,0,STAINED_CLAY:3)
Block(-8,14,1,STAINED_CLAY:3)
Block(-8,14,2,STAINED_CLAY:3)
Block(-8,14,3,STAINED_CLAY:3)
Block(-8,14,4,STAINED_CLAY:3)
Block(-8,14,5,STAINED_CLAY:3)
Block(-8,14,6,STAINED_CLAY:3)
Block(-8,14,7,STAINED_CLAY:3)
Block(-8,14,8,STAINED_CLAY:3)
Block(-8,15,-7,OBSIDIAN:0)
Block(-8,15,-6,STAINED_CLAY:3)
Block(-8,15,-5,STAINED_CLAY:3)
Block(-8,15,-4,STAINED_CLAY:3)
Block(-8,15,-3,STAINED_CLAY:3)
Block(-8,15,-2,STAINED_CLAY:3)
Block(-8,15,-1,STAINED_CLAY:3)
Block(-8,15,0,STAINED_CLAY:3)
Block(-8,15,1,STAINED_CLAY:3)
Block(-8,15,2,STAINED_CLAY:3)
Block(-8,15,3,STAINED_CLAY:3)
Block(-8,15,4,STAINED_CLAY:3)
Block(-8,15,5,STAINED_CLAY:3)
Block(-8,15,6,STAINED_CLAY:3)
Block(-8,15,7,STAINED_CLAY:3)
Block(-8,15,8,STAINED_CLAY:3)
Block(-8,16,-7,OBSIDIAN:0)
Block(-8,16,-6,OBSIDIAN:0)
Block(-8,16,-5,STAINED_CLAY:3)
Block(-8,16,-4,STAINED_CLAY:3)
Block(-8,16,-3,STAINED_CLAY:3)
Block(-8,16,-2,STAINED_CLAY:3)
Block(-8,16,-1,STAINED_CLAY:3)
Block(-8,16,0,STAINED_CLAY:3)
Block(-8,16,1,STAINED_CLAY:3)
Block(-8,16,2,STAINED_CLAY:3)
Block(-8,16,3,STAINED_CLAY:3)
Block(-8,16,4,STAINED_CLAY:3)
Block(-8,16,5,STAINED_CLAY:3)
Block(-8,16,6,STAINED_CLAY:3)
Block(-8,16,7,STAINED_CLAY:3)
Block(-8,16,8,STAINED_CLAY:3)
Block(-8,17,-7,OBSIDIAN:0)
Block(-8,17,-6,OBSIDIAN:0)
Block(-8,17,-5,STAINED_CLAY:3)
Block(-8,17,-4,STAINED_CLAY:3)
Block(-8,17,-3,STAINED_CLAY:3)
Block(-8,17,-2,STAINED_CLAY:3)
Block(-8,17,-1,STAINED_CLAY:3)
Block(-8,17,0,STAINED_CLAY:3)
Block(-8,17,1,STAINED_CLAY:3)
Block(-8,17,2,STAINED_CLAY:3)
Block(-8,17,3,STAINED_CLAY:3)
Block(-8,17,4,STAINED_CLAY:3)
Block(-8,17,5,STAINED_CLAY:3)
Block(-8,17,6,STAINED_CLAY:3)
Block(-8,17,7,STAINED_CLAY:3)
Block(-8,17,8,STAINED_CLAY:3)
Block(-8,18,-7,OBSIDIAN:0)
Block(-8,18,-6,OBSIDIAN:0)
Block(-8,18,-5,STAINED_CLAY:3)
Block(-8,18,-4,STAINED_CLAY:3)
Block(-8,18,-3,STAINED_CLAY:3)
Block(-8,18,-2,STAINED_CLAY:3)
Block(-8,18,-1,STAINED_CLAY:3)
Block(-8,18,0,STAINED_CLAY:3)
Block(-8,18,1,STAINED_CLAY:3)
Block(-8,18,2,STAINED_CLAY:3)
Block(-8,18,3,STAINED_CLAY:3)
Block(-8,18,4,STAINED_CLAY:3)
Block(-8,18,5,STAINED_CLAY:3)
Block(-8,18,6,STAINED_CLAY:3)
Block(-8,18,7,STAINED_CLAY:3)
Block(-8,18,8,STAINED_CLAY:3)
Block(-8,19,-7,OBSIDIAN:0)
Block(-8,19,-6,OBSIDIAN:0)
Block(-8,19,-5,OBSIDIAN:0)
Block(-8,19,-4,STAINED_CLAY:3)
Block(-8,19,-3,STAINED_CLAY:3)
Block(-8,19,-2,STAINED_CLAY:3)
Block(-8,19,-1,STAINED_CLAY:3)
Block(-8,19,0,STAINED_CLAY:3)
Block(-8,19,1,STAINED_CLAY:3)
Block(-8,19,2,STAINED_CLAY:3)
Block(-8,19,3,STAINED_CLAY:3)
Block(-8,19,4,STAINED_CLAY:3)
Block(-8,19,5,STAINED_CLAY:3)
Block(-8,19,6,STAINED_CLAY:3)
Block(-8,19,7,STAINED_CLAY:3)
Block(-8,19,8,STAINED_CLAY:3)
Block(-8,20,-7,OBSIDIAN:0)
Block(-8,20,-6,OBSIDIAN:0)
Block(-8,20,-5,OBSIDIAN:0)
Block(-8,20,-4,STAINED_CLAY:3)
Block(-8,20,-3,STAINED_CLAY:3)
Block(-8,20,-2,STAINED_CLAY:3)
Block(-8,20,-1,STAINED_CLAY:3)
Block(-8,20,0,STAINED_CLAY:3)
Block(-8,20,1,STAINED_CLAY:3)
Block(-8,20,2,STAINED_CLAY:3)
Block(-8,20,3,STAINED_CLAY:3)
Block(-8,20,4,STAINED_CLAY:3)
Block(-8,20,5,STAINED_CLAY:3)
Block(-8,20,6,STAINED_CLAY:3)
Block(-8,20,7,STAINED_CLAY:3)
Block(-8,20,8,STAINED_CLAY:3)
Block(-8,21,-7,OBSIDIAN:0)
Block(-8,21,-6,OBSIDIAN:0)
Block(-8,21,-5,OBSIDIAN:0)
Block(-8,21,-4,STAINED_CLAY:3)
Block(-8,21,-3,STAINED_CLAY:3)
Block(-8,21,-2,STAINED_CLAY:3)
Block(-8,21,-1,STAINED_CLAY:3)
Block(-8,21,0,STAINED_CLAY:3)
Block(-8,21,1,STAINED_CLAY:3)
Block(-8,21,2,STAINED_CLAY:3)
Block(-8,21,3,STAINED_CLAY:3)
Block(-8,21,4,STAINED_CLAY:3)
Block(-8,21,5,STAINED_CLAY:3)
Block(-8,21,6,STAINED_CLAY:3)
Block(-8,21,7,STAINED_CLAY:3)
Block(-8,21,8,STAINED_CLAY:3)
Block(-8,22,-7,OBSIDIAN:0)
Block(-8,22,-6,OBSIDIAN:0)
Block(-8,22,-5,OBSIDIAN:0)
Block(-8,22,-4,STAINED_CLAY:3)
Block(-8,22,-3,STAINED_CLAY:3)
Block(-8,22,-2,STAINED_CLAY:3)
Block(-8,22,-1,STAINED_CLAY:3)
Block(-8,22,0,STAINED_CLAY:3)
Block(-8,22,1,STAINED_CLAY:3)
Block(-8,22,2,STAINED_CLAY:3)
Block(-8,22,3,STAINED_CLAY:3)
Block(-8,22,4,STAINED_CLAY:3)
Block(-8,22,5,STAINED_CLAY:3)
Block(-8,22,6,OBSIDIAN:0)
Block(-8,22,7,OBSIDIAN:0)
Block(-8,23,-7,OBSIDIAN:0)
Block(-8,23,-6,OBSIDIAN:0)
Block(-8,23,-5,OBSIDIAN:0)
Block(-8,23,-4,STAINED_CLAY:3)
Block(-8,23,-3,STAINED_CLAY:3)
Block(-8,23,-2,STAINED_CLAY:3)
Block(-8,23,-1,STAINED_CLAY:3)
Block(-8,23,0,STAINED_CLAY:3)
Block(-8,23,1,STAINED_CLAY:3)
Block(-8,23,2,STAINED_CLAY:3)
Block(-8,23,3,STAINED_CLAY:3)
Block(-8,23,4,STAINED_CLAY:3)
Block(-8,23,5,STAINED_CLAY:3)
Block(-8,23,6,OBSIDIAN:0)
Block(-8,23,7,OBSIDIAN:0)
Block(-8,24,-7,OBSIDIAN:0)
Block(-8,24,-6,OBSIDIAN:0)
Block(-8,24,-5,OBSIDIAN:0)
Block(-8,24,-4,STAINED_CLAY:3)
Block(-8,24,-3,STAINED_CLAY:3)
Block(-8,24,-2,STAINED_CLAY:3)
Block(-8,24,-1,STAINED_CLAY:3)
Block(-8,24,0,STAINED_CLAY:3)
Block(-8,24,1,STAINED_CLAY:3)
Block(-8,24,2,STAINED_CLAY:3)
Block(-8,24,3,STAINED_CLAY:3)
Block(-8,24,4,STAINED_CLAY:3)
Block(-8,24,5,STAINED_CLAY:3)
Block(-8,24,6,OBSIDIAN:0)
Block(-8,24,7,OBSIDIAN:0)
Block(-8,25,-7,OBSIDIAN:0)
Block(-8,25,-6,OBSIDIAN:0)
Block(-8,25,-5,OBSIDIAN:0)
Block(-8,25,-4,STAINED_CLAY:3)
Block(-8,25,-3,STAINED_CLAY:3)
Block(-8,25,-2,STAINED_CLAY:3)
Block(-8,25,-1,STAINED_CLAY:3)
Block(-8,25,0,STAINED_CLAY:3)
Block(-8,25,1,STAINED_CLAY:3)
Block(-8,25,2,STAINED_CLAY:3)
Block(-8,25,3,STAINED_CLAY:3)
Block(-8,25,4,STAINED_CLAY:3)
Block(-8,25,5,STAINED_CLAY:3)
Block(-8,25,6,STAINED_CLAY:3)
Block(-8,26,-7,STAINED_CLAY:3)
Block(-8,26,-6,STAINED_CLAY:3)
Block(-8,26,-5,STAINED_CLAY:3)
Block(-8,26,-4,STAINED_CLAY:3)
Block(-8,26,-3,STAINED_CLAY:3)
Block(-8,26,-2,STAINED_CLAY:3)
Block(-8,26,-1,STAINED_CLAY:3)
Block(-8,26,0,STAINED_CLAY:3)
Block(-8,26,1,STAINED_CLAY:3)
Block(-8,26,2,STAINED_CLAY:3)
Block(-8,26,3,STAINED_CLAY:3)
Block(-8,26,4,STAINED_CLAY:3)
Block(-8,26,5,STAINED_CLAY:3)
Block(-8,26,6,STAINED_CLAY:3)
Block(-8,27,-7,STAINED_CLAY:3)
Block(-8,27,-6,STAINED_CLAY:3)
Block(-8,27,-5,STAINED_CLAY:3)
Block(-8,27,-4,STAINED_CLAY:3)
Block(-8,27,-3,STAINED_CLAY:3)
Block(-8,27,-2,STAINED_CLAY:3)
Block(-8,27,-1,STAINED_CLAY:3)
Block(-8,27,0,STAINED_CLAY:3)
Block(-8,27,1,STAINED_CLAY:3)
Block(-8,27,2,STAINED_CLAY:3)
Block(-8,27,3,STAINED_CLAY:3)
Block(-8,27,4,STAINED_CLAY:3)
Block(-8,27,5,STAINED_CLAY:3)
Block(-8,27,6,STAINED_CLAY:3)
Block(-8,28,-7,STAINED_CLAY:3)
Block(-8,28,-6,STAINED_CLAY:3)
Block(-8,28,-5,STAINED_CLAY:3)
Block(-8,28,-4,STAINED_CLAY:3)
Block(-8,28,-3,STAINED_CLAY:3)
Block(-8,28,-2,STAINED_CLAY:3)
Block(-8,28,-1,STAINED_CLAY:3)
Block(-8,28,0,STAINED_CLAY:3)
Block(-8,28,1,STAINED_CLAY:3)
Block(-8,28,2,STAINED_CLAY:3)
Block(-8,28,3,STAINED_CLAY:3)
Block(-8,28,4,STAINED_CLAY:3)
Block(-8,28,5,STAINED_CLAY:3)
Block(-8,29,-7,STAINED_CLAY:3)
Block(-8,29,-6,STAINED_CLAY:3)
Block(-8,29,-5,STAINED_CLAY:3)
Block(-8,29,-4,STAINED_CLAY:3)
Block(-8,29,-3,STAINED_CLAY:3)
Block(-8,29,-2,STAINED_CLAY:3)
Block(-8,29,-1,STAINED_CLAY:3)
Block(-8,29,0,STAINED_CLAY:3)
Block(-8,29,1,STAINED_CLAY:3)
Block(-8,29,2,STAINED_CLAY:3)
Block(-8,29,3,STAINED_CLAY:3)
Block(-8,29,4,STAINED_CLAY:3)
Block(-8,29,5,STAINED_CLAY:3)
Block(-8,30,-7,STAINED_CLAY:3)
Block(-8,30,-6,STAINED_CLAY:3)
Block(-8,30,-5,STAINED_CLAY:3)
Block(-8,30,-4,STAINED_CLAY:3)
Block(-8,30,-3,STAINED_CLAY:3)
Block(-8,30,-2,STAINED_CLAY:3)
Block(-8,30,-1,STAINED_CLAY:3)
Block(-8,30,0,STAINED_CLAY:3)
Block(-8,30,1,STAINED_CLAY:3)
Block(-8,30,2,STAINED_CLAY:3)
Block(-8,30,3,STAINED_CLAY:3)
Block(-8,30,4,STAINED_CLAY:3)
Block(-8,30,5,STAINED_CLAY:3)
Block(-8,31,-7,STAINED_CLAY:3)
Block(-8,31,-6,STAINED_CLAY:3)
Block(-8,31,-5,STAINED_CLAY:3)
Block(-8,31,-4,STAINED_CLAY:3)
Block(-8,31,-3,STAINED_CLAY:3)
Block(-8,31,-2,STAINED_CLAY:3)
Block(-8,31,-1,STAINED_CLAY:3)
Block(-8,31,0,STAINED_CLAY:3)
Block(-8,31,1,STAINED_CLAY:3)
Block(-8,31,2,STAINED_CLAY:3)
Block(-8,31,3,STAINED_CLAY:3)
Block(-8,31,4,STAINED_CLAY:3)
Block(-8,32,-7,STAINED_CLAY:3)
Block(-8,32,-6,STAINED_CLAY:3)
Block(-8,32,-5,STAINED_CLAY:3)
Block(-8,32,-4,STAINED_CLAY:3)
Block(-8,32,-3,STAINED_CLAY:3)
Block(-8,32,-2,STAINED_CLAY:3)
Block(-8,32,-1,STAINED_CLAY:3)
Block(-8,32,0,STAINED_CLAY:3)
Block(-8,32,1,STAINED_CLAY:3)
Block(-8,32,2,STAINED_CLAY:3)
Block(-8,32,3,STAINED_CLAY:3)
Block(-8,32,4,STAINED_CLAY:3)
Block(-8,33,-7,STAINED_CLAY:3)
Block(-8,33,-6,STAINED_CLAY:3)
Block(-8,33,-5,STAINED_CLAY:3)
Block(-8,33,-4,STAINED_CLAY:3)
Block(-8,33,-3,STAINED_CLAY:3)
Block(-8,33,-2,STAINED_CLAY:3)
Block(-8,33,-1,STAINED_CLAY:3)
Block(-8,33,0,STAINED_CLAY:3)
Block(-8,33,1,STAINED_CLAY:3)
Block(-8,33,2,STAINED_CLAY:3)
Block(-8,33,3,STAINED_CLAY:3)
Block(-8,34,-7,STAINED_CLAY:3)
Block(-8,34,-6,STAINED_CLAY:3)
Block(-8,34,-5,STAINED_CLAY:3)
Block(-8,34,-4,STAINED_CLAY:3)
Block(-8,34,-3,STAINED_CLAY:3)
Block(-8,34,-2,STAINED_CLAY:3)
Block(-8,34,-1,STAINED_CLAY:3)
Block(-8,34,0,STAINED_CLAY:3)
Block(-8,34,1,STAINED_CLAY:3)
Block(-8,34,2,STAINED_CLAY:3)
Block(-8,34,3,STAINED_CLAY:3)
Block(-8,35,-7,STAINED_CLAY:3)
Block(-8,35,-6,STAINED_CLAY:3)
Block(-8,35,-5,STAINED_CLAY:3)
Block(-8,35,-4,STAINED_CLAY:3)
Block(-8,35,-3,STAINED_CLAY:3)
Block(-8,35,-2,STAINED_CLAY:3)
Block(-8,35,-1,STAINED_CLAY:3)
Block(-8,35,0,STAINED_CLAY:3)
Block(-8,35,1,STAINED_CLAY:3)
Block(-8,35,2,STAINED_CLAY:3)
Block(-8,35,3,STAINED_CLAY:3)
Block(-8,36,-7,STAINED_CLAY:3)
Block(-8,36,-6,STAINED_CLAY:3)
Block(-8,36,-5,STAINED_CLAY:3)
Block(-8,36,-4,STAINED_CLAY:3)
Block(-8,36,-3,STAINED_CLAY:3)
Block(-8,36,-2,STAINED_CLAY:3)
Block(-8,36,-1,STAINED_CLAY:3)
Block(-8,36,0,STAINED_CLAY:3)
Block(-8,36,1,STAINED_CLAY:3)
Block(-8,36,2,STAINED_CLAY:3)
Block(-8,37,-7,STAINED_CLAY:3)
Block(-8,37,-6,STAINED_CLAY:3)
Block(-8,37,-5,STAINED_CLAY:3)
Block(-8,37,-4,STAINED_CLAY:3)
Block(-8,37,-3,STAINED_CLAY:3)
Block(-8,37,-2,STAINED_CLAY:3)
Block(-8,37,-1,STAINED_CLAY:3)
Block(-8,37,0,STAINED_CLAY:3)
Block(-8,37,1,STAINED_CLAY:3)
Block(-8,37,2,STAINED_CLAY:3)
Block(-8,38,-7,STAINED_CLAY:3)
Block(-8,38,-6,STAINED_CLAY:3)
Block(-8,38,-5,STAINED_CLAY:3)
Block(-8,38,-4,STAINED_CLAY:3)
Block(-8,38,-3,STAINED_CLAY:3)
Block(-8,38,-2,STAINED_CLAY:3)
Block(-8,38,-1,STAINED_CLAY:3)
Block(-8,38,0,STAINED_CLAY:3)
Block(-8,38,1,STAINED_CLAY:3)
Block(-8,38,2,STAINED_CLAY:3)
Block(-8,39,-7,STAINED_CLAY:3)
Block(-8,39,-6,STAINED_CLAY:3)
Block(-8,39,-5,STAINED_CLAY:3)
Block(-8,39,-4,STAINED_CLAY:3)
Block(-8,39,-3,STAINED_CLAY:3)
Block(-8,39,-2,STAINED_CLAY:3)
Block(-8,39,-1,STAINED_CLAY:3)
Block(-8,39,0,STAINED_CLAY:3)
Block(-8,39,1,STAINED_CLAY:3)
Block(-8,40,-7,STAINED_CLAY:3)
Block(-8,40,-6,STAINED_CLAY:3)
Block(-8,40,-5,STAINED_CLAY:3)
Block(-8,40,-4,STAINED_CLAY:3)
Block(-8,40,-3,STAINED_CLAY:3)
Block(-8,40,-2,STAINED_CLAY:3)
Block(-8,40,-1,STAINED_CLAY:3)
Block(-8,40,0,STAINED_CLAY:3)
Block(-8,40,1,STAINED_CLAY:3)
Block(-8,41,-7,STAINED_CLAY:3)
Block(-8,41,-6,STAINED_CLAY:3)
Block(-8,41,-5,STAINED_CLAY:3)
Block(-8,41,-4,STAINED_CLAY:3)
Block(-8,41,-3,STAINED_CLAY:3)
Block(-8,41,-2,STAINED_CLAY:3)
Block(-8,41,-1,STAINED_CLAY:3)
Block(-8,41,0,STAINED_CLAY:3)
Block(-8,41,1,STAINED_CLAY:3)
Block(-8,42,-7,STAINED_CLAY:3)
Block(-8,42,-6,STAINED_CLAY:3)
Block(-8,42,-5,STAINED_CLAY:3)
Block(-8,42,-4,STAINED_CLAY:3)
Block(-8,42,-3,STAINED_CLAY:3)
Block(-8,42,-2,STAINED_CLAY:3)
Block(-8,42,-1,STAINED_CLAY:3)
Block(-8,42,0,STAINED_CLAY:3)
Block(-8,43,-7,STAINED_CLAY:3)
Block(-8,43,-6,STAINED_CLAY:3)
Block(-8,43,-5,STAINED_CLAY:3)
Block(-8,43,-4,STAINED_CLAY:3)
Block(-8,43,-3,STAINED_CLAY:3)
Block(-8,43,-2,STAINED_CLAY:3)
Block(-8,43,-1,STAINED_CLAY:3)
Block(-8,43,0,STAINED_CLAY:3)
Block(-8,44,-7,STAINED_CLAY:3)
Block(-8,44,-6,STAINED_CLAY:3)
Block(-8,44,-5,STAINED_CLAY:3)
Block(-8,44,-4,STAINED_CLAY:3)
Block(-8,44,-3,STAINED_CLAY:3)
Block(-8,44,-2,STAINED_CLAY:3)
Block(-8,44,-1,STAINED_CLAY:3)
Block(-8,44,0,STAINED_CLAY:3)
Block(-8,45,-7,STAINED_CLAY:3)
Block(-8,45,-6,STAINED_CLAY:3)
Block(-8,45,-5,STAINED_CLAY:3)
Block(-8,45,-4,STAINED_CLAY:3)
Block(-8,45,-3,STAINED_CLAY:3)
Block(-8,45,-2,STAINED_CLAY:3)
Block(-8,45,-1,STAINED_CLAY:3)
Block(-8,46,-7,STAINED_CLAY:3)
Block(-8,46,-6,STAINED_CLAY:3)
Block(-8,46,-5,STAINED_CLAY:3)
Block(-8,46,-4,STAINED_CLAY:3)
Block(-8,46,-3,STAINED_CLAY:3)
Block(-8,46,-2,STAINED_CLAY:3)
Block(-8,46,-1,STAINED_CLAY:3)
Block(-8,47,-7,STAINED_CLAY:3)
Block(-8,47,-6,STAINED_CLAY:3)
Block(-8,47,-5,STAINED_CLAY:3)
Block(-8,47,-4,STAINED_CLAY:3)
Block(-8,47,-3,STAINED_CLAY:3)
Block(-8,47,-2,STAINED_CLAY:3)
Block(-8,48,-7,STAINED_CLAY:3)
Block(-8,48,-6,STAINED_CLAY:3)
Block(-8,48,-5,STAINED_CLAY:3)
Block(-8,48,-4,STAINED_CLAY:3)
Block(-8,48,-3,STAINED_CLAY:3)
Block(-8,48,-2,STAINED_CLAY:3)
Block(-8,49,-7,STAINED_CLAY:3)
Block(-8,49,-6,STAINED_CLAY:3)
Block(-8,49,-5,STAINED_CLAY:3)
Block(-8,49,-4,STAINED_CLAY:3)
Block(-8,49,-3,STAINED_CLAY:3)
Block(-8,49,-2,STAINED_CLAY:3)
Block(-8,50,-7,STAINED_CLAY:3)
Block(-8,50,-6,STAINED_CLAY:3)
Block(-8,50,-5,STAINED_CLAY:3)
Block(-8,50,-4,STAINED_CLAY:3)
Block(-8,50,-3,STAINED_CLAY:3)
Block(-8,51,-7,STAINED_CLAY:3)
Block(-8,51,-6,STAINED_CLAY:3)
Block(-8,51,-5,STAINED_CLAY:3)
Block(-8,51,-4,STAINED_CLAY:3)
Block(-8,51,-3,STAINED_CLAY:3)
Block(-8,52,-7,STAINED_CLAY:3)
Block(-8,52,-6,STAINED_CLAY:3)
Block(-8,52,-5,STAINED_CLAY:3)
Block(-8,52,-4,STAINED_CLAY:3)
Block(-8,52,-3,STAINED_CLAY:3)
Block(-8,53,-7,STAINED_CLAY:3)
Block(-8,53,-6,STAINED_CLAY:3)
Block(-8,53,-5,STAINED_CLAY:3)
Block(-8,53,-4,STAINED_CLAY:3)
Block(-8,54,-7,STAINED_CLAY:3)
Block(-8,54,-6,STAINED_CLAY:3)
Block(-8,54,-5,STAINED_CLAY:3)
Block(-8,54,-4,STAINED_CLAY:3)
Block(-8,55,-7,STAINED_CLAY:3)
Block(-8,55,-6,STAINED_CLAY:3)
Block(-8,55,-5,STAINED_CLAY:3)
Block(-8,55,-4,STAINED_CLAY:3)
Block(-8,56,-7,STAINED_CLAY:3)
Block(-8,56,-6,STAINED_CLAY:3)
Block(-8,56,-5,STAINED_CLAY:3)
Block(-8,57,-7,STAINED_CLAY:3)
Block(-8,57,-6,STAINED_CLAY:3)
Block(-8,57,-5,STAINED_CLAY:3)
Block(-8,58,-7,STAINED_CLAY:3)
Block(-8,58,-6,STAINED_CLAY:3)
Block(-8,58,-5,STAINED_CLAY:3)
Block(-8,59,-7,STAINED_CLAY:3)
Block(-8,59,-6,STAINED_CLAY:3)
Block(-8,60,-7,STAINED_CLAY:3)
Block(-8,60,-6,STAINED_CLAY:3)
Block(-8,61,-7,STAINED_CLAY:3)
Block(-8,62,-7,STAINED_CLAY:3)
Block(-8,63,-7,STAINED_CLAY:3)
Block(-7,0,-3,STAINED_CLAY:3)
Block(-7,0,-2,STAINED_CLAY:3)
Block(-7,0,-1,STAINED_CLAY:3)
Block(-7,0,0,STAINED_CLAY:3)
Block(-7,0,1,STAINED_CLAY:3)
Block(-7,0,2,STAINED_CLAY:3)
Block(-7,0,3,STAINED_CLAY:3)
Block(-7,0,4,STAINED_CLAY:3)
Block(-7,0,5,STAINED_CLAY:3)
Block(-7,0,6,STAINED_CLAY:3)
Block(-7,0,7,STAINED_CLAY:3)
Block(-7,0,8,STAINED_CLAY:3)
Block(-7,1,-4,STAINED_CLAY:3)
Block(-7,1,-3,STAINED_CLAY:3)
Block(-7,1,-2,STAINED_CLAY:3)
Block(-7,1,-1,STAINED_CLAY:3)
Block(-7,1,0,STAINED_CLAY:3)
Block(-7,1,1,STAINED_CLAY:3)
Block(-7,1,2,STAINED_CLAY:3)
Block(-7,1,3,STAINED_CLAY:3)
Block(-7,1,4,STAINED_CLAY:3)
Block(-7,1,5,STAINED_CLAY:3)
Block(-7,1,6,STAINED_CLAY:3)
Block(-7,1,7,STAINED_CLAY:3)
Block(-7,1,8,STAINED_CLAY:3)
Block(-7,2,-4,STAINED_CLAY:3)
Block(-7,2,-3,STAINED_CLAY:3)
Block(-7,2,-2,STAINED_CLAY:3)
Block(-7,2,-1,STAINED_CLAY:3)
Block(-7,2,0,STAINED_CLAY:3)
Block(-7,2,1,STAINED_CLAY:3)
Block(-7,2,2,STAINED_CLAY:3)
Block(-7,2,3,STAINED_CLAY:3)
Block(-7,2,4,STAINED_CLAY:3)
Block(-7,2,5,STAINED_CLAY:3)
Block(-7,2,6,STAINED_CLAY:3)
Block(-7,2,7,STAINED_CLAY:3)
Block(-7,2,8,STAINED_CLAY:3)
Block(-7,3,-4,STAINED_CLAY:3)
Block(-7,3,-3,STAINED_CLAY:3)
Block(-7,3,-2,STAINED_CLAY:3)
Block(-7,3,-1,STAINED_CLAY:3)
Block(-7,3,0,STAINED_CLAY:3)
Block(-7,3,1,STAINED_CLAY:3)
Block(-7,3,2,STAINED_CLAY:3)
Block(-7,3,3,STAINED_CLAY:3)
Block(-7,3,4,STAINED_CLAY:3)
Block(-7,3,5,STAINED_CLAY:3)
Block(-7,3,6,STAINED_CLAY:3)
Block(-7,3,7,STAINED_CLAY:3)
Block(-7,3,8,STAINED_CLAY:3)
Block(-7,4,-4,STAINED_CLAY:3)
Block(-7,4,-3,STAINED_CLAY:3)
Block(-7,4,-2,STAINED_CLAY:3)
Block(-7,4,-1,STAINED_CLAY:3)
Block(-7,4,0,STAINED_CLAY:3)
Block(-7,4,1,STAINED_CLAY:3)
Block(-7,4,2,STAINED_CLAY:3)
Block(-7,4,3,STAINED_CLAY:3)
Block(-7,4,4,STAINED_CLAY:3)
Block(-7,4,5,STAINED_CLAY:3)
Block(-7,4,6,STAINED_CLAY:3)
Block(-7,4,7,STAINED_CLAY:3)
Block(-7,4,8,STAINED_CLAY:3)
Block(-7,5,-4,STAINED_CLAY:3)
Block(-7,5,-3,STAINED_CLAY:3)
Block(-7,5,-2,STAINED_CLAY:3)
Block(-7,5,-1,STAINED_CLAY:3)
Block(-7,5,0,STAINED_CLAY:3)
Block(-7,5,1,STAINED_CLAY:3)
Block(-7,5,2,STAINED_CLAY:3)
Block(-7,5,3,STAINED_CLAY:3)
Block(-7,5,4,STAINED_CLAY:3)
Block(-7,5,5,STAINED_CLAY:3)
Block(-7,5,6,STAINED_CLAY:3)
Block(-7,5,7,STAINED_CLAY:3)
Block(-7,5,8,STAINED_CLAY:3)
Block(-7,6,-5,STAINED_CLAY:3)
Block(-7,6,-4,STAINED_CLAY:3)
Block(-7,6,-3,STAINED_CLAY:3)
Block(-7,6,-2,STAINED_CLAY:3)
Block(-7,6,-1,STAINED_CLAY:3)
Block(-7,6,0,STAINED_CLAY:3)
Block(-7,6,1,STAINED_CLAY:3)
Block(-7,6,2,STAINED_CLAY:3)
Block(-7,6,3,STAINED_CLAY:3)
Block(-7,6,4,STAINED_CLAY:3)
Block(-7,6,5,STAINED_CLAY:3)
Block(-7,6,6,STAINED_CLAY:3)
Block(-7,6,7,STAINED_CLAY:3)
Block(-7,6,8,STAINED_CLAY:3)
Block(-7,7,-5,STAINED_CLAY:3)
Block(-7,7,-4,STAINED_CLAY:3)
Block(-7,7,-3,STAINED_CLAY:3)
Block(-7,7,-2,STAINED_CLAY:3)
Block(-7,7,-1,STAINED_CLAY:3)
Block(-7,7,0,STAINED_CLAY:3)
Block(-7,7,1,STAINED_CLAY:3)
Block(-7,7,2,STAINED_CLAY:3)
Block(-7,7,3,STAINED_CLAY:3)
Block(-7,7,4,STAINED_CLAY:3)
Block(-7,7,5,STAINED_CLAY:3)
Block(-7,7,6,STAINED_CLAY:3)
Block(-7,7,7,STAINED_CLAY:3)
Block(-7,7,8,STAINED_CLAY:3)
Block(-7,8,-5,STAINED_CLAY:3)
Block(-7,8,-4,STAINED_CLAY:3)
Block(-7,8,-3,STAINED_CLAY:3)
Block(-7,8,-2,STAINED_CLAY:3)
Block(-7,8,-1,STAINED_CLAY:3)
Block(-7,8,0,STAINED_CLAY:3)
Block(-7,8,1,STAINED_CLAY:3)
Block(-7,8,2,STAINED_CLAY:3)
Block(-7,8,3,STAINED_CLAY:3)
Block(-7,8,4,STAINED_CLAY:3)
Block(-7,8,5,STAINED_CLAY:3)
Block(-7,8,6,STAINED_CLAY:3)
Block(-7,8,7,STAINED_CLAY:3)
Block(-7,8,8,STAINED_CLAY:3)
Block(-7,9,-5,STAINED_CLAY:3)
Block(-7,9,-4,STAINED_CLAY:3)
Block(-7,9,-3,STAINED_CLAY:3)
Block(-7,9,-2,STAINED_CLAY:3)
Block(-7,9,-1,STAINED_CLAY:3)
Block(-7,9,0,STAINED_CLAY:3)
Block(-7,9,1,STAINED_CLAY:3)
Block(-7,9,2,STAINED_CLAY:3)
Block(-7,9,3,STAINED_CLAY:3)
Block(-7,9,4,STAINED_CLAY:3)
Block(-7,9,5,STAINED_CLAY:3)
Block(-7,9,6,STAINED_CLAY:3)
Block(-7,9,7,STAINED_CLAY:3)
Block(-7,9,8,STAINED_CLAY:3)
Block(-7,10,-5,STAINED_CLAY:3)
Block(-7,10,-4,STAINED_CLAY:3)
Block(-7,10,-3,STAINED_CLAY:3)
Block(-7,10,-2,STAINED_CLAY:3)
Block(-7,10,-1,STAINED_CLAY:3)
Block(-7,10,0,STAINED_CLAY:3)
Block(-7,10,1,STAINED_CLAY:3)
Block(-7,10,2,STAINED_CLAY:3)
Block(-7,10,3,STAINED_CLAY:3)
Block(-7,10,4,STAINED_CLAY:3)
Block(-7,10,5,STAINED_CLAY:3)
Block(-7,10,6,STAINED_CLAY:3)
Block(-7,10,7,STAINED_CLAY:3)
Block(-7,10,8,STAINED_CLAY:3)
Block(-7,11,-6,STAINED_CLAY:3)
Block(-7,11,-5,STAINED_CLAY:3)
Block(-7,11,-4,STAINED_CLAY:3)
Block(-7,11,-3,STAINED_CLAY:3)
Block(-7,11,-2,STAINED_CLAY:3)
Block(-7,11,-1,STAINED_CLAY:3)
Block(-7,11,0,STAINED_CLAY:3)
Block(-7,11,1,STAINED_CLAY:3)
Block(-7,11,2,STAINED_CLAY:3)
Block(-7,11,3,STAINED_CLAY:3)
Block(-7,11,4,STAINED_CLAY:3)
Block(-7,11,5,STAINED_CLAY:3)
Block(-7,11,6,STAINED_CLAY:3)
Block(-7,11,7,STAINED_CLAY:3)
Block(-7,11,8,STAINED_CLAY:3)
Block(-7,12,-6,STAINED_CLAY:3)
Block(-7,12,-5,STAINED_CLAY:3)
Block(-7,12,-4,STAINED_CLAY:3)
Block(-7,12,-3,STAINED_CLAY:3)
Block(-7,12,-2,STAINED_CLAY:3)
Block(-7,12,-1,STAINED_CLAY:3)
Block(-7,12,0,STAINED_CLAY:3)
Block(-7,12,1,STAINED_CLAY:3)
Block(-7,12,2,STAINED_CLAY:3)
Block(-7,12,3,STAINED_CLAY:3)
Block(-7,12,4,STAINED_CLAY:3)
Block(-7,12,5,STAINED_CLAY:3)
Block(-7,12,6,STAINED_CLAY:3)
Block(-7,12,7,STAINED_CLAY:3)
Block(-7,12,8,STAINED_CLAY:3)
Block(-7,13,-6,STAINED_CLAY:3)
Block(-7,13,-5,STAINED_CLAY:3)
Block(-7,13,-4,STAINED_CLAY:3)
Block(-7,13,-3,STAINED_CLAY:3)
Block(-7,13,-2,STAINED_CLAY:3)
Block(-7,13,-1,STAINED_CLAY:3)
Block(-7,13,0,STAINED_CLAY:3)
Block(-7,13,1,STAINED_CLAY:3)
Block(-7,13,2,STAINED_CLAY:3)
Block(-7,13,3,STAINED_CLAY:3)
Block(-7,13,4,STAINED_CLAY:3)
Block(-7,13,5,STAINED_CLAY:3)
Block(-7,13,6,STAINED_CLAY:3)
Block(-7,13,7,STAINED_CLAY:3)
Block(-7,13,8,STAINED_CLAY:3)
Block(-7,14,-6,STAINED_CLAY:3)
Block(-7,14,-5,STAINED_CLAY:3)
Block(-7,14,-4,STAINED_CLAY:3)
Block(-7,14,-3,STAINED_CLAY:3)
Block(-7,14,-2,STAINED_CLAY:3)
Block(-7,14,-1,STAINED_CLAY:3)
Block(-7,14,0,STAINED_CLAY:3)
Block(-7,14,1,STAINED_CLAY:3)
Block(-7,14,2,STAINED_CLAY:3)
Block(-7,14,3,STAINED_CLAY:3)
Block(-7,14,4,STAINED_CLAY:3)
Block(-7,14,5,STAINED_CLAY:3)
Block(-7,14,6,STAINED_CLAY:3)
Block(-7,14,7,STAINED_CLAY:3)
Block(-7,14,8,STAINED_CLAY:3)
Block(-7,15,-7,OBSIDIAN:0)
Block(-7,15,-6,STAINED_CLAY:3)
Block(-7,15,-5,STAINED_CLAY:3)
Block(-7,15,-4,STAINED_CLAY:3)
Block(-7,15,-3,STAINED_CLAY:3)
Block(-7,15,-2,STAINED_CLAY:3)
Block(-7,15,-1,STAINED_CLAY:3)
Block(-7,15,0,STAINED_CLAY:3)
Block(-7,15,1,STAINED_CLAY:3)
Block(-7,15,2,STAINED_CLAY:3)
Block(-7,15,3,STAINED_CLAY:3)
Block(-7,15,4,STAINED_CLAY:3)
Block(-7,15,5,STAINED_CLAY:3)
Block(-7,15,6,STAINED_CLAY:3)
Block(-7,15,7,STAINED_CLAY:3)
Block(-7,15,8,STAINED_CLAY:3)
Block(-7,16,-7,OBSIDIAN:0)
Block(-7,16,-6,STAINED_CLAY:3)
Block(-7,16,-5,STAINED_CLAY:3)
Block(-7,16,-4,STAINED_CLAY:3)
Block(-7,16,-3,STAINED_CLAY:3)
Block(-7,16,-2,STAINED_CLAY:3)
Block(-7,16,-1,STAINED_CLAY:3)
Block(-7,16,0,STAINED_CLAY:3)
Block(-7,16,1,STAINED_CLAY:3)
Block(-7,16,2,STAINED_CLAY:3)
Block(-7,16,3,STAINED_CLAY:3)
Block(-7,16,4,STAINED_CLAY:3)
Block(-7,16,5,STAINED_CLAY:3)
Block(-7,16,6,STAINED_CLAY:3)
Block(-7,16,7,STAINED_CLAY:3)
Block(-7,16,8,STAINED_CLAY:3)
Block(-7,17,-7,OBSIDIAN:0)
Block(-7,17,-6,STAINED_CLAY:3)
Block(-7,17,-5,STAINED_CLAY:3)
Block(-7,17,-4,STAINED_CLAY:3)
Block(-7,17,-3,STAINED_CLAY:3)
Block(-7,17,-2,STAINED_CLAY:3)
Block(-7,17,-1,STAINED_CLAY:3)
Block(-7,17,0,STAINED_CLAY:3)
Block(-7,17,1,STAINED_CLAY:3)
Block(-7,17,2,STAINED_CLAY:3)
Block(-7,17,3,STAINED_CLAY:3)
Block(-7,17,4,STAINED_CLAY:3)
Block(-7,17,5,STAINED_CLAY:3)
Block(-7,17,6,STAINED_CLAY:3)
Block(-7,17,7,STAINED_CLAY:3)
Block(-7,17,8,STAINED_CLAY:3)
Block(-7,18,-7,OBSIDIAN:0)
Block(-7,18,-6,OBSIDIAN:0)
Block(-7,18,-5,STAINED_CLAY:3)
Block(-7,18,-4,STAINED_CLAY:3)
Block(-7,18,-3,STAINED_CLAY:3)
Block(-7,18,-2,STAINED_CLAY:3)
Block(-7,18,-1,STAINED_CLAY:3)
Block(-7,18,0,STAINED_CLAY:3)
Block(-7,18,1,STAINED_CLAY:3)
Block(-7,18,2,STAINED_CLAY:3)
Block(-7,18,3,STAINED_CLAY:3)
Block(-7,18,4,STAINED_CLAY:3)
Block(-7,18,5,STAINED_CLAY:3)
Block(-7,18,6,STAINED_CLAY:3)
Block(-7,18,7,STAINED_CLAY:3)
Block(-7,18,8,STAINED_CLAY:3)
Block(-7,19,-7,OBSIDIAN:0)
Block(-7,19,-6,OBSIDIAN:0)
Block(-7,19,-5,OBSIDIAN:0)
Block(-7,19,-4,STAINED_CLAY:3)
Block(-7,19,-3,STAINED_CLAY:3)
Block(-7,19,-2,STAINED_CLAY:3)
Block(-7,19,-1,STAINED_CLAY:3)
Block(-7,19,0,STAINED_CLAY:3)
Block(-7,19,1,STAINED_CLAY:3)
Block(-7,19,2,STAINED_CLAY:3)
Block(-7,19,3,STAINED_CLAY:3)
Block(-7,19,4,STAINED_CLAY:3)
Block(-7,19,5,STAINED_CLAY:3)
Block(-7,19,6,STAINED_CLAY:3)
Block(-7,19,7,STAINED_CLAY:3)
Block(-7,19,8,STAINED_CLAY:3)
Block(-7,20,-7,OBSIDIAN:0)
Block(-7,20,-6,OBSIDIAN:0)
Block(-7,20,-5,OBSIDIAN:0)
Block(-7,20,-4,STAINED_CLAY:3)
Block(-7,20,-3,STAINED_CLAY:3)
Block(-7,20,-2,STAINED_CLAY:3)
Block(-7,20,-1,STAINED_CLAY:3)
Block(-7,20,0,STAINED_CLAY:3)
Block(-7,20,1,STAINED_CLAY:3)
Block(-7,20,2,STAINED_CLAY:3)
Block(-7,20,3,STAINED_CLAY:3)
Block(-7,20,4,STAINED_CLAY:3)
Block(-7,20,5,STAINED_CLAY:3)
Block(-7,20,6,STAINED_CLAY:3)
Block(-7,20,7,STAINED_CLAY:3)
Block(-7,20,8,STAINED_CLAY:3)
Block(-7,21,-7,OBSIDIAN:0)
Block(-7,21,-6,OBSIDIAN:0)
Block(-7,21,-5,OBSIDIAN:0)
Block(-7,21,-4,STAINED_CLAY:3)
Block(-7,21,-3,STAINED_CLAY:3)
Block(-7,21,-2,STAINED_CLAY:3)
Block(-7,21,-1,STAINED_CLAY:3)
Block(-7,21,0,STAINED_CLAY:3)
Block(-7,21,1,STAINED_CLAY:3)
Block(-7,21,2,STAINED_CLAY:3)
Block(-7,21,3,STAINED_CLAY:3)
Block(-7,21,4,STAINED_CLAY:3)
Block(-7,21,5,OBSIDIAN:0)
Block(-7,21,6,OBSIDIAN:0)
Block(-7,21,7,OBSIDIAN:0)
Block(-7,21,8,OBSIDIAN:0)
Block(-7,22,-7,OBSIDIAN:0)
Block(-7,22,-6,OBSIDIAN:0)
Block(-7,22,-5,OBSIDIAN:0)
Block(-7,22,-4,OBSIDIAN:0)
Block(-7,22,-3,STAINED_CLAY:3)
Block(-7,22,-2,STAINED_CLAY:3)
Block(-7,22,-1,STAINED_CLAY:3)
Block(-7,22,0,STAINED_CLAY:3)
Block(-7,22,1,STAINED_CLAY:3)
Block(-7,22,2,STAINED_CLAY:3)
Block(-7,22,3,STAINED_CLAY:3)
Block(-7,22,4,STAINED_CLAY:3)
Block(-7,22,5,OBSIDIAN:0)
Block(-7,22,6,OBSIDIAN:0)
Block(-7,22,7,OBSIDIAN:0)
Block(-7,23,-7,OBSIDIAN:0)
Block(-7,23,-6,OBSIDIAN:0)
Block(-7,23,-5,OBSIDIAN:0)
Block(-7,23,-4,OBSIDIAN:0)
Block(-7,23,-3,STAINED_CLAY:3)
Block(-7,23,-2,STAINED_CLAY:3)
Block(-7,23,-1,STAINED_CLAY:3)
Block(-7,23,0,STAINED_CLAY:3)
Block(-7,23,1,STAINED_CLAY:3)
Block(-7,23,2,STAINED_CLAY:3)
Block(-7,23,3,STAINED_CLAY:3)
Block(-7,23,4,STAINED_CLAY:3)
Block(-7,23,5,OBSIDIAN:0)
Block(-7,23,6,OBSIDIAN:0)
Block(-7,23,7,OBSIDIAN:0)
Block(-7,24,-7,OBSIDIAN:0)
Block(-7,24,-6,OBSIDIAN:0)
Block(-7,24,-5,OBSIDIAN:0)
Block(-7,24,-4,OBSIDIAN:0)
Block(-7,24,-3,STAINED_CLAY:3)
Block(-7,24,-2,STAINED_CLAY:3)
Block(-7,24,-1,STAINED_CLAY:3)
Block(-7,24,0,STAINED_CLAY:3)
Block(-7,24,1,STAINED_CLAY:3)
Block(-7,24,2,STAINED_CLAY:3)
Block(-7,24,3,STAINED_CLAY:3)
Block(-7,24,4,STAINED_CLAY:3)
Block(-7,24,5,OBSIDIAN:0)
Block(-7,24,6,OBSIDIAN:0)
Block(-7,24,7,OBSIDIAN:0)
Block(-7,25,-7,OBSIDIAN:0)
Block(-7,25,-6,OBSIDIAN:0)
Block(-7,25,-5,OBSIDIAN:0)
Block(-7,25,-4,STAINED_CLAY:3)
Block(-7,25,-3,STAINED_CLAY:3)
Block(-7,25,-2,STAINED_CLAY:3)
Block(-7,25,-1,STAINED_CLAY:3)
Block(-7,25,0,STAINED_CLAY:3)
Block(-7,25,1,STAINED_CLAY:3)
Block(-7,25,2,STAINED_CLAY:3)
Block(-7,25,3,STAINED_CLAY:3)
Block(-7,25,4,STAINED_CLAY:3)
Block(-7,25,5,OBSIDIAN:0)
Block(-7,25,6,OBSIDIAN:0)
Block(-7,26,-7,OBSIDIAN:0)
Block(-7,26,-6,OBSIDIAN:0)
Block(-7,26,-5,STAINED_CLAY:3)
Block(-7,26,-4,STAINED_CLAY:3)
Block(-7,26,-3,STAINED_CLAY:3)
Block(-7,26,-2,STAINED_CLAY:3)
Block(-7,26,-1,STAINED_CLAY:3)
Block(-7,26,0,STAINED_CLAY:3)
Block(-7,26,1,STAINED_CLAY:3)
Block(-7,26,2,STAINED_CLAY:3)
Block(-7,26,3,STAINED_CLAY:3)
Block(-7,26,4,STAINED_CLAY:3)
Block(-7,26,5,OBSIDIAN:0)
Block(-7,26,6,OBSIDIAN:0)
Block(-7,27,-7,STAINED_CLAY:3)
Block(-7,27,-6,STAINED_CLAY:3)
Block(-7,27,-5,STAINED_CLAY:3)
Block(-7,27,-4,STAINED_CLAY:3)
Block(-7,27,-3,STAINED_CLAY:3)
Block(-7,27,-2,STAINED_CLAY:3)
Block(-7,27,-1,STAINED_CLAY:3)
Block(-7,27,0,STAINED_CLAY:3)
Block(-7,27,1,STAINED_CLAY:3)
Block(-7,27,2,STAINED_CLAY:3)
Block(-7,27,3,STAINED_CLAY:3)
Block(-7,27,4,STAINED_CLAY:3)
Block(-7,27,5,OBSIDIAN:0)
Block(-7,27,6,OBSIDIAN:0)
Block(-7,28,-7,STAINED_CLAY:3)
Block(-7,28,-6,STAINED_CLAY:3)
Block(-7,28,-5,STAINED_CLAY:3)
Block(-7,28,-4,STAINED_CLAY:3)
Block(-7,28,-3,STAINED_CLAY:3)
Block(-7,28,-2,STAINED_CLAY:3)
Block(-7,28,-1,STAINED_CLAY:3)
Block(-7,28,0,STAINED_CLAY:3)
Block(-7,28,1,STAINED_CLAY:3)
Block(-7,28,2,STAINED_CLAY:3)
Block(-7,28,3,STAINED_CLAY:3)
Block(-7,28,4,STAINED_CLAY:3)
Block(-7,28,5,OBSIDIAN:0)
Block(-7,29,-7,STAINED_CLAY:3)
Block(-7,29,-6,STAINED_CLAY:3)
Block(-7,29,-5,STAINED_CLAY:3)
Block(-7,29,-4,STAINED_CLAY:3)
Block(-7,29,-3,STAINED_CLAY:3)
Block(-7,29,-2,STAINED_CLAY:3)
Block(-7,29,-1,STAINED_CLAY:3)
Block(-7,29,0,STAINED_CLAY:3)
Block(-7,29,1,STAINED_CLAY:3)
Block(-7,29,2,STAINED_CLAY:3)
Block(-7,29,3,STAINED_CLAY:3)
Block(-7,29,4,STAINED_CLAY:3)
Block(-7,29,5,OBSIDIAN:0)
Block(-7,30,-7,STAINED_CLAY:3)
Block(-7,30,-6,STAINED_CLAY:3)
Block(-7,30,-5,STAINED_CLAY:3)
Block(-7,30,-4,STAINED_CLAY:3)
Block(-7,30,-3,STAINED_CLAY:3)
Block(-7,30,-2,STAINED_CLAY:3)
Block(-7,30,-1,STAINED_CLAY:3)
Block(-7,30,0,STAINED_CLAY:3)
Block(-7,30,1,STAINED_CLAY:3)
Block(-7,30,2,STAINED_CLAY:3)
Block(-7,30,3,STAINED_CLAY:3)
Block(-7,30,4,STAINED_CLAY:3)
Block(-7,30,5,STAINED_CLAY:3)
Block(-7,31,-7,STAINED_CLAY:3)
Block(-7,31,-6,STAINED_CLAY:3)
Block(-7,31,-5,STAINED_CLAY:3)
Block(-7,31,-4,STAINED_CLAY:3)
Block(-7,31,-3,STAINED_CLAY:3)
Block(-7,31,-2,STAINED_CLAY:3)
Block(-7,31,-1,STAINED_CLAY:3)
Block(-7,31,0,STAINED_CLAY:3)
Block(-7,31,1,STAINED_CLAY:3)
Block(-7,31,2,STAINED_CLAY:3)
Block(-7,31,3,STAINED_CLAY:3)
Block(-7,31,4,STAINED_CLAY:3)
Block(-7,32,-7,STAINED_CLAY:3)
Block(-7,32,-6,STAINED_CLAY:3)
Block(-7,32,-5,STAINED_CLAY:3)
Block(-7,32,-4,STAINED_CLAY:3)
Block(-7,32,-3,STAINED_CLAY:3)
Block(-7,32,-2,STAINED_CLAY:3)
Block(-7,32,-1,STAINED_CLAY:3)
Block(-7,32,0,STAINED_CLAY:3)
Block(-7,32,1,STAINED_CLAY:3)
Block(-7,32,2,STAINED_CLAY:3)
Block(-7,32,3,STAINED_CLAY:3)
Block(-7,32,4,STAINED_CLAY:3)
Block(-7,33,-7,STAINED_CLAY:3)
Block(-7,33,-6,STAINED_CLAY:3)
Block(-7,33,-5,STAINED_CLAY:3)
Block(-7,33,-4,STAINED_CLAY:3)
Block(-7,33,-3,STAINED_CLAY:3)
Block(-7,33,-2,STAINED_CLAY:3)
Block(-7,33,-1,STAINED_CLAY:3)
Block(-7,33,0,STAINED_CLAY:3)
Block(-7,33,1,STAINED_CLAY:3)
Block(-7,33,2,STAINED_CLAY:3)
Block(-7,33,3,STAINED_CLAY:3)
Block(-7,33,4,STAINED_CLAY:3)
Block(-7,34,-7,STAINED_CLAY:3)
Block(-7,34,-6,STAINED_CLAY:3)
Block(-7,34,-5,STAINED_CLAY:3)
Block(-7,34,-4,STAINED_CLAY:3)
Block(-7,34,-3,STAINED_CLAY:3)
Block(-7,34,-2,STAINED_CLAY:3)
Block(-7,34,-1,STAINED_CLAY:3)
Block(-7,34,0,STAINED_CLAY:3)
Block(-7,34,1,STAINED_CLAY:3)
Block(-7,34,2,STAINED_CLAY:3)
Block(-7,34,3,STAINED_CLAY:3)
Block(-7,35,-7,STAINED_CLAY:3)
Block(-7,35,-6,STAINED_CLAY:3)
Block(-7,35,-5,STAINED_CLAY:3)
Block(-7,35,-4,STAINED_CLAY:3)
Block(-7,35,-3,STAINED_CLAY:3)
Block(-7,35,-2,STAINED_CLAY:3)
Block(-7,35,-1,STAINED_CLAY:3)
Block(-7,35,0,STAINED_CLAY:3)
Block(-7,35,1,STAINED_CLAY:3)
Block(-7,35,2,STAINED_CLAY:3)
Block(-7,35,3,STAINED_CLAY:3)
Block(-7,36,-7,STAINED_CLAY:3)
Block(-7,36,-6,STAINED_CLAY:3)
Block(-7,36,-5,STAINED_CLAY:3)
Block(-7,36,-4,STAINED_CLAY:3)
Block(-7,36,-3,STAINED_CLAY:3)
Block(-7,36,-2,STAINED_CLAY:3)
Block(-7,36,-1,STAINED_CLAY:3)
Block(-7,36,0,STAINED_CLAY:3)
Block(-7,36,1,STAINED_CLAY:3)
Block(-7,36,2,STAINED_CLAY:3)
Block(-7,37,-7,STAINED_CLAY:3)
Block(-7,37,-6,STAINED_CLAY:3)
Block(-7,37,-5,STAINED_CLAY:3)
Block(-7,37,-4,STAINED_CLAY:3)
Block(-7,37,-3,STAINED_CLAY:3)
Block(-7,37,-2,STAINED_CLAY:3)
Block(-7,37,-1,STAINED_CLAY:3)
Block(-7,37,0,STAINED_CLAY:3)
Block(-7,37,1,STAINED_CLAY:3)
Block(-7,37,2,STAINED_CLAY:3)
Block(-7,38,-7,STAINED_CLAY:3)
Block(-7,38,-6,STAINED_CLAY:3)
Block(-7,38,-5,STAINED_CLAY:3)
Block(-7,38,-4,STAINED_CLAY:3)
Block(-7,38,-3,STAINED_CLAY:3)
Block(-7,38,-2,STAINED_CLAY:3)
Block(-7,38,-1,STAINED_CLAY:3)
Block(-7,38,0,STAINED_CLAY:3)
Block(-7,38,1,STAINED_CLAY:3)
Block(-7,38,2,STAINED_CLAY:3)
Block(-7,39,-7,STAINED_CLAY:3)
Block(-7,39,-6,STAINED_CLAY:3)
Block(-7,39,-5,STAINED_CLAY:3)
Block(-7,39,-4,STAINED_CLAY:3)
Block(-7,39,-3,STAINED_CLAY:3)
Block(-7,39,-2,STAINED_CLAY:3)
Block(-7,39,-1,STAINED_CLAY:3)
Block(-7,39,0,STAINED_CLAY:3)
Block(-7,39,1,STAINED_CLAY:3)
Block(-7,40,-7,STAINED_CLAY:3)
Block(-7,40,-6,STAINED_CLAY:3)
Block(-7,40,-5,STAINED_CLAY:3)
Block(-7,40,-4,STAINED_CLAY:3)
Block(-7,40,-3,STAINED_CLAY:3)
Block(-7,40,-2,STAINED_CLAY:3)
Block(-7,40,-1,STAINED_CLAY:3)
Block(-7,40,0,STAINED_CLAY:3)
Block(-7,40,1,STAINED_CLAY:3)
Block(-7,41,-7,STAINED_CLAY:3)
Block(-7,41,-6,STAINED_CLAY:3)
Block(-7,41,-5,STAINED_CLAY:3)
Block(-7,41,-4,STAINED_CLAY:3)
Block(-7,41,-3,STAINED_CLAY:3)
Block(-7,41,-2,STAINED_CLAY:3)
Block(-7,41,-1,STAINED_CLAY:3)
Block(-7,41,0,STAINED_CLAY:3)
Block(-7,41,1,STAINED_CLAY:3)
Block(-7,42,-7,STAINED_CLAY:3)
Block(-7,42,-6,STAINED_CLAY:3)
Block(-7,42,-5,STAINED_CLAY:3)
Block(-7,42,-4,STAINED_CLAY:3)
Block(-7,42,-3,STAINED_CLAY:3)
Block(-7,42,-2,STAINED_CLAY:3)
Block(-7,42,-1,STAINED_CLAY:3)
Block(-7,42,0,STAINED_CLAY:3)
Block(-7,43,-7,STAINED_CLAY:3)
Block(-7,43,-6,STAINED_CLAY:3)
Block(-7,43,-5,STAINED_CLAY:3)
Block(-7,43,-4,STAINED_CLAY:3)
Block(-7,43,-3,STAINED_CLAY:3)
Block(-7,43,-2,STAINED_CLAY:3)
Block(-7,43,-1,STAINED_CLAY:3)
Block(-7,43,0,STAINED_CLAY:3)
Block(-7,44,-7,STAINED_CLAY:3)
Block(-7,44,-6,STAINED_CLAY:3)
Block(-7,44,-5,STAINED_CLAY:3)
Block(-7,44,-4,STAINED_CLAY:3)
Block(-7,44,-3,STAINED_CLAY:3)
Block(-7,44,-2,STAINED_CLAY:3)
Block(-7,44,-1,STAINED_CLAY:3)
Block(-7,44,0,STAINED_CLAY:3)
Block(-7,45,-7,STAINED_CLAY:3)
Block(-7,45,-6,STAINED_CLAY:3)
Block(-7,45,-5,STAINED_CLAY:3)
Block(-7,45,-4,STAINED_CLAY:3)
Block(-7,45,-3,STAINED_CLAY:3)
Block(-7,45,-2,STAINED_CLAY:3)
Block(-7,45,-1,STAINED_CLAY:3)
Block(-7,46,-7,STAINED_CLAY:3)
Block(-7,46,-6,STAINED_CLAY:3)
Block(-7,46,-5,STAINED_CLAY:3)
Block(-7,46,-4,STAINED_CLAY:3)
Block(-7,46,-3,STAINED_CLAY:3)
Block(-7,46,-2,STAINED_CLAY:3)
Block(-7,46,-1,STAINED_CLAY:3)
Block(-7,47,-7,STAINED_CLAY:3)
Block(-7,47,-6,STAINED_CLAY:3)
Block(-7,47,-5,STAINED_CLAY:3)
Block(-7,47,-4,STAINED_CLAY:3)
Block(-7,47,-3,STAINED_CLAY:3)
Block(-7,47,-2,STAINED_CLAY:3)
Block(-7,47,-1,STAINED_CLAY:3)
Block(-7,48,-7,STAINED_CLAY:3)
Block(-7,48,-6,STAINED_CLAY:3)
Block(-7,48,-5,STAINED_CLAY:3)
Block(-7,48,-4,STAINED_CLAY:3)
Block(-7,48,-3,STAINED_CLAY:3)
Block(-7,48,-2,STAINED_CLAY:3)
Block(-7,49,-7,STAINED_CLAY:3)
Block(-7,49,-6,STAINED_CLAY:3)
Block(-7,49,-5,STAINED_CLAY:3)
Block(-7,49,-4,STAINED_CLAY:3)
Block(-7,49,-3,STAINED_CLAY:3)
Block(-7,49,-2,STAINED_CLAY:3)
Block(-7,50,-7,STAINED_CLAY:3)
Block(-7,50,-6,STAINED_CLAY:3)
Block(-7,50,-5,STAINED_CLAY:3)
Block(-7,50,-4,STAINED_CLAY:3)
Block(-7,50,-3,STAINED_CLAY:3)
Block(-7,51,-7,STAINED_CLAY:3)
Block(-7,51,-6,STAINED_CLAY:3)
Block(-7,51,-5,STAINED_CLAY:3)
Block(-7,51,-4,STAINED_CLAY:3)
Block(-7,51,-3,STAINED_CLAY:3)
Block(-7,52,-7,STAINED_CLAY:3)
Block(-7,52,-6,STAINED_CLAY:3)
Block(-7,52,-5,STAINED_CLAY:3)
Block(-7,52,-4,STAINED_CLAY:3)
Block(-7,52,-3,STAINED_CLAY:3)
Block(-7,53,-7,STAINED_CLAY:3)
Block(-7,53,-6,STAINED_CLAY:3)
Block(-7,53,-5,STAINED_CLAY:3)
Block(-7,53,-4,STAINED_CLAY:3)
Block(-7,54,-7,STAINED_CLAY:3)
Block(-7,54,-6,STAINED_CLAY:3)
Block(-7,54,-5,STAINED_CLAY:3)
Block(-7,54,-4,STAINED_CLAY:3)
Block(-7,55,-7,STAINED_CLAY:3)
Block(-7,55,-6,STAINED_CLAY:3)
Block(-7,55,-5,STAINED_CLAY:3)
Block(-7,55,-4,STAINED_CLAY:3)
Block(-7,56,-7,STAINED_CLAY:3)
Block(-7,56,-6,STAINED_CLAY:3)
Block(-7,56,-5,STAINED_CLAY:3)
Block(-7,57,-7,STAINED_CLAY:3)
Block(-7,57,-6,STAINED_CLAY:3)
Block(-7,57,-5,STAINED_CLAY:3)
Block(-7,58,-7,STAINED_CLAY:3)
Block(-7,58,-6,STAINED_CLAY:3)
Block(-7,58,-5,STAINED_CLAY:3)
Block(-7,59,-7,STAINED_CLAY:3)
Block(-7,59,-6,STAINED_CLAY:3)
Block(-7,60,-7,STAINED_CLAY:3)
Block(-7,60,-6,STAINED_CLAY:3)
Block(-7,61,-7,STAINED_CLAY:3)
Block(-7,61,-6,STAINED_CLAY:3)
Block(-7,62,-7,STAINED_CLAY:3)
Block(-7,63,-7,STAINED_CLAY:3)
Block(-6,0,-3,STAINED_CLAY:3)
Block(-6,0,-2,STAINED_CLAY:3)
Block(-6,0,-1,STAINED_CLAY:3)
Block(-6,0,0,STAINED_CLAY:3)
Block(-6,0,1,STAINED_CLAY:3)
Block(-6,0,2,STAINED_CLAY:3)
Block(-6,0,3,STAINED_CLAY:3)
Block(-6,0,4,STAINED_CLAY:3)
Block(-6,0,5,STAINED_CLAY:3)
Block(-6,0,6,STAINED_CLAY:3)
Block(-6,0,7,STAINED_CLAY:3)
Block(-6,0,8,STAINED_CLAY:3)
Block(-6,1,-3,STAINED_CLAY:3)
Block(-6,1,-2,STAINED_CLAY:3)
Block(-6,1,-1,STAINED_CLAY:3)
Block(-6,1,0,STAINED_CLAY:3)
Block(-6,1,1,STAINED_CLAY:3)
Block(-6,1,2,STAINED_CLAY:3)
Block(-6,1,3,STAINED_CLAY:3)
Block(-6,1,4,STAINED_CLAY:3)
Block(-6,1,5,STAINED_CLAY:3)
Block(-6,1,6,STAINED_CLAY:3)
Block(-6,1,7,STAINED_CLAY:3)
Block(-6,1,8,STAINED_CLAY:3)
Block(-6,2,-3,STAINED_CLAY:3)
Block(-6,2,-2,STAINED_CLAY:3)
Block(-6,2,-1,STAINED_CLAY:3)
Block(-6,2,0,STAINED_CLAY:3)
Block(-6,2,1,STAINED_CLAY:3)
Block(-6,2,2,STAINED_CLAY:3)
Block(-6,2,3,STAINED_CLAY:3)
Block(-6,2,4,STAINED_CLAY:3)
Block(-6,2,5,STAINED_CLAY:3)
Block(-6,2,6,STAINED_CLAY:3)
Block(-6,2,7,STAINED_CLAY:3)
Block(-6,2,8,STAINED_CLAY:3)
Block(-6,3,-3,STAINED_CLAY:3)
Block(-6,3,-2,STAINED_CLAY:3)
Block(-6,3,-1,STAINED_CLAY:3)
Block(-6,3,0,STAINED_CLAY:3)
Block(-6,3,1,STAINED_CLAY:3)
Block(-6,3,2,STAINED_CLAY:3)
Block(-6,3,3,STAINED_CLAY:3)
Block(-6,3,4,STAINED_CLAY:3)
Block(-6,3,5,STAINED_CLAY:3)
Block(-6,3,6,STAINED_CLAY:3)
Block(-6,3,7,STAINED_CLAY:3)
Block(-6,3,8,STAINED_CLAY:3)
Block(-6,4,-3,STAINED_CLAY:3)
Block(-6,4,-2,STAINED_CLAY:3)
Block(-6,4,-1,STAINED_CLAY:3)
Block(-6,4,0,STAINED_CLAY:3)
Block(-6,4,1,STAINED_CLAY:3)
Block(-6,4,2,STAINED_CLAY:3)
Block(-6,4,3,STAINED_CLAY:3)
Block(-6,4,4,STAINED_CLAY:3)
Block(-6,4,5,STAINED_CLAY:3)
Block(-6,4,6,STAINED_CLAY:3)
Block(-6,4,7,STAINED_CLAY:3)
Block(-6,4,8,STAINED_CLAY:3)
Block(-6,5,-4,STAINED_CLAY:3)
Block(-6,5,-3,STAINED_CLAY:3)
Block(-6,5,-2,STAINED_CLAY:3)
Block(-6,5,-1,STAINED_CLAY:3)
Block(-6,5,0,STAINED_CLAY:3)
Block(-6,5,1,STAINED_CLAY:3)
Block(-6,5,2,STAINED_CLAY:3)
Block(-6,5,3,STAINED_CLAY:3)
Block(-6,5,4,STAINED_CLAY:3)
Block(-6,5,5,STAINED_CLAY:3)
Block(-6,5,6,STAINED_CLAY:3)
Block(-6,5,7,STAINED_CLAY:3)
Block(-6,5,8,STAINED_CLAY:3)
Block(-6,6,-4,STAINED_CLAY:3)
Block(-6,6,-3,STAINED_CLAY:3)
Block(-6,6,-2,STAINED_CLAY:3)
Block(-6,6,-1,STAINED_CLAY:3)
Block(-6,6,0,STAINED_CLAY:3)
Block(-6,6,1,STAINED_CLAY:3)
Block(-6,6,2,STAINED_CLAY:3)
Block(-6,6,3,STAINED_CLAY:3)
Block(-6,6,4,STAINED_CLAY:3)
Block(-6,6,5,STAINED_CLAY:3)
Block(-6,6,6,STAINED_CLAY:3)
Block(-6,6,7,STAINED_CLAY:3)
Block(-6,6,8,STAINED_CLAY:3)
Block(-6,7,-4,STAINED_CLAY:3)
Block(-6,7,-3,STAINED_CLAY:3)
Block(-6,7,-2,STAINED_CLAY:3)
Block(-6,7,-1,STAINED_CLAY:3)
Block(-6,7,0,STAINED_CLAY:3)
Block(-6,7,1,STAINED_CLAY:3)
Block(-6,7,2,STAINED_CLAY:3)
Block(-6,7,3,STAINED_CLAY:3)
Block(-6,7,4,STAINED_CLAY:3)
Block(-6,7,5,STAINED_CLAY:3)
Block(-6,7,6,STAINED_CLAY:3)
Block(-6,7,7,STAINED_CLAY:3)
Block(-6,7,8,STAINED_CLAY:3)
Block(-6,8,-4,STAINED_CLAY:3)
Block(-6,8,-3,STAINED_CLAY:3)
Block(-6,8,-2,STAINED_CLAY:3)
Block(-6,8,-1,STAINED_CLAY:3)
Block(-6,8,0,STAINED_CLAY:3)
Block(-6,8,1,STAINED_CLAY:3)
Block(-6,8,2,STAINED_CLAY:3)
Block(-6,8,3,STAINED_CLAY:3)
Block(-6,8,4,STAINED_CLAY:3)
Block(-6,8,5,STAINED_CLAY:3)
Block(-6,8,6,STAINED_CLAY:3)
Block(-6,8,7,STAINED_CLAY:3)
Block(-6,8,8,STAINED_CLAY:3)
Block(-6,9,-4,STAINED_CLAY:3)
Block(-6,9,-3,STAINED_CLAY:3)
Block(-6,9,-2,STAINED_CLAY:3)
Block(-6,9,-1,STAINED_CLAY:3)
Block(-6,9,0,STAINED_CLAY:3)
Block(-6,9,1,STAINED_CLAY:3)
Block(-6,9,2,STAINED_CLAY:3)
Block(-6,9,3,STAINED_CLAY:3)
Block(-6,9,4,STAINED_CLAY:3)
Block(-6,9,5,STAINED_CLAY:3)
Block(-6,9,6,STAINED_CLAY:3)
Block(-6,9,7,STAINED_CLAY:3)
Block(-6,9,8,STAINED_CLAY:3)
Block(-6,10,-5,STAINED_CLAY:3)
Block(-6,10,-4,STAINED_CLAY:3)
Block(-6,10,-3,STAINED_CLAY:3)
Block(-6,10,-2,STAINED_CLAY:3)
Block(-6,10,-1,STAINED_CLAY:3)
Block(-6,10,0,STAINED_CLAY:3)
Block(-6,10,1,STAINED_CLAY:3)
Block(-6,10,2,STAINED_CLAY:3)
Block(-6,10,3,STAINED_CLAY:3)
Block(-6,10,4,STAINED_CLAY:3)
Block(-6,10,5,STAINED_CLAY:3)
Block(-6,10,6,STAINED_CLAY:3)
Block(-6,10,7,STAINED_CLAY:3)
Block(-6,10,8,STAINED_CLAY:3)
Block(-6,11,-5,STAINED_CLAY:3)
Block(-6,11,-4,STAINED_CLAY:3)
Block(-6,11,-3,STAINED_CLAY:3)
Block(-6,11,-2,STAINED_CLAY:3)
Block(-6,11,-1,STAINED_CLAY:3)
Block(-6,11,0,STAINED_CLAY:3)
Block(-6,11,1,STAINED_CLAY:3)
Block(-6,11,2,STAINED_CLAY:3)
Block(-6,11,3,STAINED_CLAY:3)
Block(-6,11,4,STAINED_CLAY:3)
Block(-6,11,5,STAINED_CLAY:3)
Block(-6,11,6,STAINED_CLAY:3)
Block(-6,11,7,STAINED_CLAY:3)
Block(-6,11,8,STAINED_CLAY:3)
Block(-6,12,-5,STAINED_CLAY:3)
Block(-6,12,-4,STAINED_CLAY:3)
Block(-6,12,-3,STAINED_CLAY:3)
Block(-6,12,-2,STAINED_CLAY:3)
Block(-6,12,-1,STAINED_CLAY:3)
Block(-6,12,0,STAINED_CLAY:3)
Block(-6,12,1,STAINED_CLAY:3)
Block(-6,12,2,STAINED_CLAY:3)
Block(-6,12,3,STAINED_CLAY:3)
Block(-6,12,4,STAINED_CLAY:3)
Block(-6,12,5,STAINED_CLAY:3)
Block(-6,12,6,STAINED_CLAY:3)
Block(-6,12,7,STAINED_CLAY:3)
Block(-6,12,8,STAINED_CLAY:3)
Block(-6,13,-5,STAINED_CLAY:3)
Block(-6,13,-4,STAINED_CLAY:3)
Block(-6,13,-3,STAINED_CLAY:3)
Block(-6,13,-2,STAINED_CLAY:3)
Block(-6,13,-1,STAINED_CLAY:3)
Block(-6,13,0,STAINED_CLAY:3)
Block(-6,13,1,STAINED_CLAY:3)
Block(-6,13,2,STAINED_CLAY:3)
Block(-6,13,3,STAINED_CLAY:3)
Block(-6,13,4,STAINED_CLAY:3)
Block(-6,13,5,STAINED_CLAY:3)
Block(-6,13,6,STAINED_CLAY:3)
Block(-6,13,7,STAINED_CLAY:3)
Block(-6,13,8,STAINED_CLAY:3)
Block(-6,14,-5,STAINED_CLAY:3)
Block(-6,14,-4,STAINED_CLAY:3)
Block(-6,14,-3,STAINED_CLAY:3)
Block(-6,14,-2,STAINED_CLAY:3)
Block(-6,14,-1,STAINED_CLAY:3)
Block(-6,14,0,STAINED_CLAY:3)
Block(-6,14,1,STAINED_CLAY:3)
Block(-6,14,2,STAINED_CLAY:3)
Block(-6,14,3,STAINED_CLAY:3)
Block(-6,14,4,STAINED_CLAY:3)
Block(-6,14,5,STAINED_CLAY:3)
Block(-6,14,6,STAINED_CLAY:3)
Block(-6,14,7,STAINED_CLAY:3)
Block(-6,14,8,STAINED_CLAY:3)
Block(-6,15,-6,STAINED_CLAY:3)
Block(-6,15,-5,STAINED_CLAY:3)
Block(-6,15,-4,STAINED_CLAY:3)
Block(-6,15,-3,STAINED_CLAY:3)
Block(-6,15,-2,STAINED_CLAY:3)
Block(-6,15,-1,STAINED_CLAY:3)
Block(-6,15,0,STAINED_CLAY:3)
Block(-6,15,1,STAINED_CLAY:3)
Block(-6,15,2,STAINED_CLAY:3)
Block(-6,15,3,STAINED_CLAY:3)
Block(-6,15,4,STAINED_CLAY:3)
Block(-6,15,5,STAINED_CLAY:3)
Block(-6,15,6,STAINED_CLAY:3)
Block(-6,15,7,STAINED_CLAY:3)
Block(-6,15,8,STAINED_CLAY:3)
Block(-6,16,-6,STAINED_CLAY:3)
Block(-6,16,-5,STAINED_CLAY:3)
Block(-6,16,-4,STAINED_CLAY:3)
Block(-6,16,-3,STAINED_CLAY:3)
Block(-6,16,-2,STAINED_CLAY:3)
Block(-6,16,-1,STAINED_CLAY:3)
Block(-6,16,0,STAINED_CLAY:3)
Block(-6,16,1,STAINED_CLAY:3)
Block(-6,16,2,STAINED_CLAY:3)
Block(-6,16,3,STAINED_CLAY:3)
Block(-6,16,4,STAINED_CLAY:3)
Block(-6,16,5,STAINED_CLAY:3)
Block(-6,16,6,STAINED_CLAY:3)
Block(-6,16,7,STAINED_CLAY:3)
Block(-6,16,8,STAINED_CLAY:3)
Block(-6,17,-6,STAINED_CLAY:3)
Block(-6,17,-5,STAINED_CLAY:3)
Block(-6,17,-4,STAINED_CLAY:3)
Block(-6,17,-3,STAINED_CLAY:3)
Block(-6,17,-2,STAINED_CLAY:3)
Block(-6,17,-1,STAINED_CLAY:3)
Block(-6,17,0,STAINED_CLAY:3)
Block(-6,17,1,STAINED_CLAY:3)
Block(-6,17,2,STAINED_CLAY:3)
Block(-6,17,3,STAINED_CLAY:3)
Block(-6,17,4,STAINED_CLAY:3)
Block(-6,17,5,STAINED_CLAY:3)
Block(-6,17,6,STAINED_CLAY:3)
Block(-6,17,7,STAINED_CLAY:3)
Block(-6,17,8,OBSIDIAN:0)
Block(-6,18,-6,OBSIDIAN:0)
Block(-6,18,-5,STAINED_CLAY:3)
Block(-6,18,-4,STAINED_CLAY:3)
Block(-6,18,-3,STAINED_CLAY:3)
Block(-6,18,-2,STAINED_CLAY:3)
Block(-6,18,-1,STAINED_CLAY:3)
Block(-6,18,0,STAINED_CLAY:3)
Block(-6,18,1,STAINED_CLAY:3)
Block(-6,18,2,STAINED_CLAY:3)
Block(-6,18,3,STAINED_CLAY:3)
Block(-6,18,4,STAINED_CLAY:3)
Block(-6,18,5,STAINED_CLAY:3)
Block(-6,18,6,STAINED_CLAY:3)
Block(-6,18,7,STAINED_CLAY:3)
Block(-6,18,8,OBSIDIAN:0)
Block(-6,19,-7,OBSIDIAN:0)
Block(-6,19,-6,OBSIDIAN:0)
Block(-6,19,-5,OBSIDIAN:0)
Block(-6,19,-4,STAINED_CLAY:3)
Block(-6,19,-3,STAINED_CLAY:3)
Block(-6,19,-2,STAINED_CLAY:3)
Block(-6,19,-1,STAINED_CLAY:3)
Block(-6,19,0,STAINED_CLAY:3)
Block(-6,19,1,STAINED_CLAY:3)
Block(-6,19,2,STAINED_CLAY:3)
Block(-6,19,3,STAINED_CLAY:3)
Block(-6,19,4,STAINED_CLAY:3)
Block(-6,19,5,STAINED_CLAY:3)
Block(-6,19,6,STAINED_CLAY:3)
Block(-6,19,7,STAINED_CLAY:3)
Block(-6,19,8,OBSIDIAN:0)
Block(-6,20,-7,OBSIDIAN:0)
Block(-6,20,-6,OBSIDIAN:0)
Block(-6,20,-5,OBSIDIAN:0)
Block(-6,20,-4,STAINED_CLAY:3)
Block(-6,20,-3,STAINED_CLAY:3)
Block(-6,20,-2,STAINED_CLAY:3)
Block(-6,20,-1,STAINED_CLAY:3)
Block(-6,20,0,STAINED_CLAY:3)
Block(-6,20,1,STAINED_CLAY:3)
Block(-6,20,2,STAINED_CLAY:3)
Block(-6,20,3,STAINED_CLAY:3)
Block(-6,20,4,STAINED_CLAY:3)
Block(-6,20,5,STAINED_CLAY:3)
Block(-6,20,6,OBSIDIAN:0)
Block(-6,20,7,OBSIDIAN:0)
Block(-6,20,8,OBSIDIAN:0)
Block(-6,21,-7,OBSIDIAN:0)
Block(-6,21,-6,OBSIDIAN:0)
Block(-6,21,-5,OBSIDIAN:0)
Block(-6,21,-4,OBSIDIAN:0)
Block(-6,21,-3,OBSIDIAN:0)
Block(-6,21,-2,STAINED_CLAY:3)
Block(-6,21,-1,STAINED_CLAY:3)
Block(-6,21,0,STAINED_CLAY:3)
Block(-6,21,1,STAINED_CLAY:3)
Block(-6,21,2,STAINED_CLAY:3)
Block(-6,21,3,STAINED_CLAY:3)
Block(-6,21,4,STAINED_CLAY:3)
Block(-6,21,5,OBSIDIAN:0)
Block(-6,21,6,OBSIDIAN:0)
Block(-6,21,7,OBSIDIAN:0)
Block(-6,21,8,OBSIDIAN:0)
Block(-6,22,-7,OBSIDIAN:0)
Block(-6,22,-6,OBSIDIAN:0)
Block(-6,22,-5,OBSIDIAN:0)
Block(-6,22,-4,OBSIDIAN:0)
Block(-6,22,-3,OBSIDIAN:0)
Block(-6,22,-2,STAINED_CLAY:3)
Block(-6,22,-1,STAINED_CLAY:3)
Block(-6,22,0,STAINED_CLAY:3)
Block(-6,22,1,STAINED_CLAY:3)
Block(-6,22,2,STAINED_CLAY:3)
Block(-6,22,3,STAINED_CLAY:3)
Block(-6,22,4,OBSIDIAN:0)
Block(-6,22,5,OBSIDIAN:0)
Block(-6,22,6,OBSIDIAN:0)
Block(-6,22,7,OBSIDIAN:0)
Block(-6,22,8,OBSIDIAN:0)
Block(-6,23,-7,OBSIDIAN:0)
Block(-6,23,-6,OBSIDIAN:0)
Block(-6,23,-5,OBSIDIAN:0)
Block(-6,23,-4,OBSIDIAN:0)
Block(-6,23,-3,OBSIDIAN:0)
Block(-6,23,-2,STAINED_CLAY:3)
Block(-6,23,-1,STAINED_CLAY:3)
Block(-6,23,0,STAINED_CLAY:3)
Block(-6,23,1,STAINED_CLAY:3)
Block(-6,23,2,STAINED_CLAY:3)
Block(-6,23,3,STAINED_CLAY:3)
Block(-6,23,4,OBSIDIAN:0)
Block(-6,23,5,OBSIDIAN:0)
Block(-6,23,6,OBSIDIAN:0)
Block(-6,23,7,OBSIDIAN:0)
Block(-6,24,-7,OBSIDIAN:0)
Block(-6,24,-6,OBSIDIAN:0)
Block(-6,24,-5,OBSIDIAN:0)
Block(-6,24,-4,OBSIDIAN:0)
Block(-6,24,-3,OBSIDIAN:0)
Block(-6,24,-2,STAINED_CLAY:3)
Block(-6,24,-1,STAINED_CLAY:3)
Block(-6,24,0,STAINED_CLAY:3)
Block(-6,24,1,STAINED_CLAY:3)
Block(-6,24,2,STAINED_CLAY:3)
Block(-6,24,3,STAINED_CLAY:3)
Block(-6,24,4,OBSIDIAN:0)
Block(-6,24,5,OBSIDIAN:0)
Block(-6,24,6,OBSIDIAN:0)
Block(-6,24,7,OBSIDIAN:0)
Block(-6,25,-7,OBSIDIAN:0)
Block(-6,25,-6,OBSIDIAN:0)
Block(-6,25,-5,OBSIDIAN:0)
Block(-6,25,-4,OBSIDIAN:0)
Block(-6,25,-3,OBSIDIAN:0)
Block(-6,25,-2,STAINED_CLAY:3)
Block(-6,25,-1,STAINED_CLAY:3)
Block(-6,25,0,STAINED_CLAY:3)
Block(-6,25,1,STAINED_CLAY:3)
Block(-6,25,2,STAINED_CLAY:3)
Block(-6,25,3,STAINED_CLAY:3)
Block(-6,25,4,OBSIDIAN:0)
Block(-6,25,5,OBSIDIAN:0)
Block(-6,25,6,OBSIDIAN:0)
Block(-6,26,-7,OBSIDIAN:0)
Block(-6,26,-6,OBSIDIAN:0)
Block(-6,26,-5,STAINED_CLAY:3)
Block(-6,26,-4,STAINED_CLAY:3)
Block(-6,26,-3,STAINED_CLAY:3)
Block(-6,26,-2,STAINED_CLAY:3)
Block(-6,26,-1,STAINED_CLAY:3)
Block(-6,26,0,STAINED_CLAY:3)
Block(-6,26,1,STAINED_CLAY:3)
Block(-6,26,2,STAINED_CLAY:3)
Block(-6,26,3,STAINED_CLAY:3)
Block(-6,26,4,OBSIDIAN:0)
Block(-6,26,5,OBSIDIAN:0)
Block(-6,26,6,OBSIDIAN:0)
Block(-6,27,-7,STAINED_CLAY:3)
Block(-6,27,-6,STAINED_CLAY:3)
Block(-6,27,-5,STAINED_CLAY:3)
Block(-6,27,-4,STAINED_CLAY:3)
Block(-6,27,-3,STAINED_CLAY:3)
Block(-6,27,-2,STAINED_CLAY:3)
Block(-6,27,-1,STAINED_CLAY:3)
Block(-6,27,0,STAINED_CLAY:3)
Block(-6,27,1,STAINED_CLAY:3)
Block(-6,27,2,STAINED_CLAY:3)
Block(-6,27,3,STAINED_CLAY:3)
Block(-6,27,4,OBSIDIAN:0)
Block(-6,27,5,OBSIDIAN:0)
Block(-6,27,6,OBSIDIAN:0)
Block(-6,28,-7,STAINED_CLAY:3)
Block(-6,28,-6,STAINED_CLAY:3)
Block(-6,28,-5,STAINED_CLAY:3)
Block(-6,28,-4,STAINED_CLAY:3)
Block(-6,28,-3,STAINED_CLAY:3)
Block(-6,28,-2,STAINED_CLAY:3)
Block(-6,28,-1,STAINED_CLAY:3)
Block(-6,28,0,STAINED_CLAY:3)
Block(-6,28,1,STAINED_CLAY:3)
Block(-6,28,2,STAINED_CLAY:3)
Block(-6,28,3,STAINED_CLAY:3)
Block(-6,28,4,OBSIDIAN:0)
Block(-6,28,5,OBSIDIAN:0)
Block(-6,29,-7,STAINED_CLAY:3)
Block(-6,29,-6,STAINED_CLAY:3)
Block(-6,29,-5,STAINED_CLAY:3)
Block(-6,29,-4,STAINED_CLAY:3)
Block(-6,29,-3,STAINED_CLAY:3)
Block(-6,29,-2,STAINED_CLAY:3)
Block(-6,29,-1,STAINED_CLAY:3)
Block(-6,29,0,STAINED_CLAY:3)
Block(-6,29,1,STAINED_CLAY:3)
Block(-6,29,2,STAINED_CLAY:3)
Block(-6,29,3,OBSIDIAN:0)
Block(-6,29,4,OBSIDIAN:0)
Block(-6,29,5,OBSIDIAN:0)
Block(-6,30,-7,STAINED_CLAY:3)
Block(-6,30,-6,STAINED_CLAY:3)
Block(-6,30,-5,STAINED_CLAY:3)
Block(-6,30,-4,STAINED_CLAY:3)
Block(-6,30,-3,STAINED_CLAY:3)
Block(-6,30,-2,STAINED_CLAY:3)
Block(-6,30,-1,STAINED_CLAY:3)
Block(-6,30,0,STAINED_CLAY:3)
Block(-6,30,1,STAINED_CLAY:3)
Block(-6,30,2,STAINED_CLAY:3)
Block(-6,30,3,OBSIDIAN:0)
Block(-6,30,4,OBSIDIAN:0)
Block(-6,30,5,OBSIDIAN:0)
Block(-6,31,-7,STAINED_CLAY:3)
Block(-6,31,-6,STAINED_CLAY:3)
Block(-6,31,-5,STAINED_CLAY:3)
Block(-6,31,-4,STAINED_CLAY:3)
Block(-6,31,-3,STAINED_CLAY:3)
Block(-6,31,-2,STAINED_CLAY:3)
Block(-6,31,-1,STAINED_CLAY:3)
Block(-6,31,0,STAINED_CLAY:3)
Block(-6,31,1,STAINED_CLAY:3)
Block(-6,31,2,STAINED_CLAY:3)
Block(-6,31,3,OBSIDIAN:0)
Block(-6,31,4,OBSIDIAN:0)
Block(-6,32,-7,STAINED_CLAY:3)
Block(-6,32,-6,STAINED_CLAY:3)
Block(-6,32,-5,STAINED_CLAY:3)
Block(-6,32,-4,STAINED_CLAY:3)
Block(-6,32,-3,STAINED_CLAY:3)
Block(-6,32,-2,STAINED_CLAY:3)
Block(-6,32,-1,STAINED_CLAY:3)
Block(-6,32,0,STAINED_CLAY:3)
Block(-6,32,1,STAINED_CLAY:3)
Block(-6,32,2,STAINED_CLAY:3)
Block(-6,32,3,STAINED_CLAY:3)
Block(-6,32,4,STAINED_CLAY:3)
Block(-6,33,-7,STAINED_CLAY:3)
Block(-6,33,-6,STAINED_CLAY:3)
Block(-6,33,-5,STAINED_CLAY:3)
Block(-6,33,-4,STAINED_CLAY:3)
Block(-6,33,-3,STAINED_CLAY:3)
Block(-6,33,-2,STAINED_CLAY:3)
Block(-6,33,-1,STAINED_CLAY:3)
Block(-6,33,0,STAINED_CLAY:3)
Block(-6,33,1,STAINED_CLAY:3)
Block(-6,33,2,STAINED_CLAY:3)
Block(-6,33,3,STAINED_CLAY:3)
Block(-6,33,4,STAINED_CLAY:3)
Block(-6,34,-7,STAINED_CLAY:3)
Block(-6,34,-6,STAINED_CLAY:3)
Block(-6,34,-5,STAINED_CLAY:3)
Block(-6,34,-4,STAINED_CLAY:3)
Block(-6,34,-3,STAINED_CLAY:3)
Block(-6,34,-2,STAINED_CLAY:3)
Block(-6,34,-1,STAINED_CLAY:3)
Block(-6,34,0,STAINED_CLAY:3)
Block(-6,34,1,STAINED_CLAY:3)
Block(-6,34,2,STAINED_CLAY:3)
Block(-6,34,3,STAINED_CLAY:3)
Block(-6,35,-7,STAINED_CLAY:3)
Block(-6,35,-6,STAINED_CLAY:3)
Block(-6,35,-5,STAINED_CLAY:3)
Block(-6,35,-4,STAINED_CLAY:3)
Block(-6,35,-3,STAINED_CLAY:3)
Block(-6,35,-2,STAINED_CLAY:3)
Block(-6,35,-1,STAINED_CLAY:3)
Block(-6,35,0,STAINED_CLAY:3)
Block(-6,35,1,STAINED_CLAY:3)
Block(-6,35,2,STAINED_CLAY:3)
Block(-6,35,3,STAINED_CLAY:3)
Block(-6,36,-7,STAINED_CLAY:3)
Block(-6,36,-6,STAINED_CLAY:3)
Block(-6,36,-5,STAINED_CLAY:3)
Block(-6,36,-4,STAINED_CLAY:3)
Block(-6,36,-3,STAINED_CLAY:3)
Block(-6,36,-2,STAINED_CLAY:3)
Block(-6,36,-1,STAINED_CLAY:3)
Block(-6,36,0,STAINED_CLAY:3)
Block(-6,36,1,STAINED_CLAY:3)
Block(-6,36,2,STAINED_CLAY:3)
Block(-6,36,3,STAINED_CLAY:3)
Block(-6,37,-7,STAINED_CLAY:3)
Block(-6,37,-6,STAINED_CLAY:3)
Block(-6,37,-5,STAINED_CLAY:3)
Block(-6,37,-4,STAINED_CLAY:3)
Block(-6,37,-3,STAINED_CLAY:3)
Block(-6,37,-2,STAINED_CLAY:3)
Block(-6,37,-1,STAINED_CLAY:3)
Block(-6,37,0,STAINED_CLAY:3)
Block(-6,37,1,STAINED_CLAY:3)
Block(-6,37,2,STAINED_CLAY:3)
Block(-6,38,-7,OBSIDIAN:0)
Block(-6,38,-6,STAINED_CLAY:3)
Block(-6,38,-5,STAINED_CLAY:3)
Block(-6,38,-4,STAINED_CLAY:3)
Block(-6,38,-3,STAINED_CLAY:3)
Block(-6,38,-2,STAINED_CLAY:3)
Block(-6,38,-1,STAINED_CLAY:3)
Block(-6,38,0,STAINED_CLAY:3)
Block(-6,38,1,STAINED_CLAY:3)
Block(-6,38,2,STAINED_CLAY:3)
Block(-6,39,-7,OBSIDIAN:0)
Block(-6,39,-6,STAINED_CLAY:3)
Block(-6,39,-5,STAINED_CLAY:3)
Block(-6,39,-4,STAINED_CLAY:3)
Block(-6,39,-3,STAINED_CLAY:3)
Block(-6,39,-2,STAINED_CLAY:3)
Block(-6,39,-1,STAINED_CLAY:3)
Block(-6,39,0,STAINED_CLAY:3)
Block(-6,39,1,STAINED_CLAY:3)
Block(-6,40,-7,OBSIDIAN:0)
Block(-6,40,-6,STAINED_CLAY:3)
Block(-6,40,-5,STAINED_CLAY:3)
Block(-6,40,-4,STAINED_CLAY:3)
Block(-6,40,-3,STAINED_CLAY:3)
Block(-6,40,-2,STAINED_CLAY:3)
Block(-6,40,-1,STAINED_CLAY:3)
Block(-6,40,0,STAINED_CLAY:3)
Block(-6,40,1,STAINED_CLAY:3)
Block(-6,41,-7,STAINED_CLAY:3)
Block(-6,41,-6,STAINED_CLAY:3)
Block(-6,41,-5,STAINED_CLAY:3)
Block(-6,41,-4,STAINED_CLAY:3)
Block(-6,41,-3,STAINED_CLAY:3)
Block(-6,41,-2,STAINED_CLAY:3)
Block(-6,41,-1,STAINED_CLAY:3)
Block(-6,41,0,STAINED_CLAY:3)
Block(-6,41,1,STAINED_CLAY:3)
Block(-6,42,-7,STAINED_CLAY:3)
Block(-6,42,-6,STAINED_CLAY:3)
Block(-6,42,-5,STAINED_CLAY:3)
Block(-6,42,-4,STAINED_CLAY:3)
Block(-6,42,-3,STAINED_CLAY:3)
Block(-6,42,-2,STAINED_CLAY:3)
Block(-6,42,-1,STAINED_CLAY:3)
Block(-6,42,0,STAINED_CLAY:3)
Block(-6,43,-7,STAINED_CLAY:3)
Block(-6,43,-6,STAINED_CLAY:3)
Block(-6,43,-5,STAINED_CLAY:3)
Block(-6,43,-4,STAINED_CLAY:3)
Block(-6,43,-3,STAINED_CLAY:3)
Block(-6,43,-2,STAINED_CLAY:3)
Block(-6,43,-1,STAINED_CLAY:3)
Block(-6,43,0,STAINED_CLAY:3)
Block(-6,44,-7,STAINED_CLAY:3)
Block(-6,44,-6,STAINED_CLAY:3)
Block(-6,44,-5,STAINED_CLAY:3)
Block(-6,44,-4,STAINED_CLAY:3)
Block(-6,44,-3,STAINED_CLAY:3)
Block(-6,44,-2,STAINED_CLAY:3)
Block(-6,44,-1,STAINED_CLAY:3)
Block(-6,44,0,STAINED_CLAY:3)
Block(-6,45,-7,STAINED_CLAY:3)
Block(-6,45,-6,STAINED_CLAY:3)
Block(-6,45,-5,STAINED_CLAY:3)
Block(-6,45,-4,STAINED_CLAY:3)
Block(-6,45,-3,STAINED_CLAY:3)
Block(-6,45,-2,STAINED_CLAY:3)
Block(-6,45,-1,STAINED_CLAY:3)
Block(-6,46,-7,STAINED_CLAY:3)
Block(-6,46,-6,STAINED_CLAY:3)
Block(-6,46,-5,STAINED_CLAY:3)
Block(-6,46,-4,STAINED_CLAY:3)
Block(-6,46,-3,STAINED_CLAY:3)
Block(-6,46,-2,STAINED_CLAY:3)
Block(-6,46,-1,STAINED_CLAY:3)
Block(-6,47,-7,STAINED_CLAY:3)
Block(-6,47,-6,STAINED_CLAY:3)
Block(-6,47,-5,STAINED_CLAY:3)
Block(-6,47,-4,STAINED_CLAY:3)
Block(-6,47,-3,STAINED_CLAY:3)
Block(-6,47,-2,STAINED_CLAY:3)
Block(-6,47,-1,STAINED_CLAY:3)
Block(-6,48,-7,STAINED_CLAY:3)
Block(-6,48,-6,STAINED_CLAY:3)
Block(-6,48,-5,STAINED_CLAY:3)
Block(-6,48,-4,STAINED_CLAY:3)
Block(-6,48,-3,STAINED_CLAY:3)
Block(-6,48,-2,STAINED_CLAY:3)
Block(-6,49,-7,STAINED_CLAY:3)
Block(-6,49,-6,STAINED_CLAY:3)
Block(-6,49,-5,STAINED_CLAY:3)
Block(-6,49,-4,STAINED_CLAY:3)
Block(-6,49,-3,STAINED_CLAY:3)
Block(-6,49,-2,STAINED_CLAY:3)
Block(-6,50,-7,STAINED_CLAY:3)
Block(-6,50,-6,STAINED_CLAY:3)
Block(-6,50,-5,STAINED_CLAY:3)
Block(-6,50,-4,STAINED_CLAY:3)
Block(-6,50,-3,STAINED_CLAY:3)
Block(-6,50,-2,STAINED_CLAY:3)
Block(-6,51,-7,STAINED_CLAY:3)
Block(-6,51,-6,STAINED_CLAY:3)
Block(-6,51,-5,STAINED_CLAY:3)
Block(-6,51,-4,STAINED_CLAY:3)
Block(-6,51,-3,STAINED_CLAY:3)
Block(-6,52,-7,STAINED_CLAY:3)
Block(-6,52,-6,STAINED_CLAY:3)
Block(-6,52,-5,STAINED_CLAY:3)
Block(-6,52,-4,STAINED_CLAY:3)
Block(-6,52,-3,STAINED_CLAY:3)
Block(-6,53,-7,STAINED_CLAY:3)
Block(-6,53,-6,STAINED_CLAY:3)
Block(-6,53,-5,STAINED_CLAY:3)
Block(-6,53,-4,STAINED_CLAY:3)
Block(-6,54,-7,STAINED_CLAY:3)
Block(-6,54,-6,STAINED_CLAY:3)
Block(-6,54,-5,STAINED_CLAY:3)
Block(-6,54,-4,STAINED_CLAY:3)
Block(-6,55,-7,STAINED_CLAY:3)
Block(-6,55,-6,STAINED_CLAY:3)
Block(-6,55,-5,STAINED_CLAY:3)
Block(-6,55,-4,STAINED_CLAY:3)
Block(-6,56,-7,STAINED_CLAY:3)
Block(-6,56,-6,STAINED_CLAY:3)
Block(-6,56,-5,STAINED_CLAY:3)
Block(-6,57,-7,STAINED_CLAY:3)
Block(-6,57,-6,STAINED_CLAY:3)
Block(-6,57,-5,STAINED_CLAY:3)
Block(-6,58,-7,STAINED_CLAY:3)
Block(-6,58,-6,STAINED_CLAY:3)
Block(-6,58,-5,STAINED_CLAY:3)
Block(-6,59,-7,STAINED_CLAY:3)
Block(-6,59,-6,STAINED_CLAY:3)
Block(-6,60,-7,STAINED_CLAY:3)
Block(-6,60,-6,STAINED_CLAY:3)
Block(-6,61,-7,STAINED_CLAY:3)
Block(-6,61,-6,STAINED_CLAY:3)
Block(-6,62,-7,STAINED_CLAY:3)
Block(-6,63,-7,STAINED_CLAY:3)
Block(-5,0,-2,STAINED_CLAY:3)
Block(-5,0,-1,STAINED_CLAY:3)
Block(-5,0,0,STAINED_CLAY:3)
Block(-5,0,1,STAINED_CLAY:3)
Block(-5,0,2,STAINED_CLAY:3)
Block(-5,0,3,STAINED_CLAY:3)
Block(-5,0,4,STAINED_CLAY:3)
Block(-5,0,5,STAINED_CLAY:3)
Block(-5,0,6,STAINED_CLAY:3)
Block(-5,0,7,STAINED_CLAY:3)
Block(-5,0,8,STAINED_CLAY:3)
Block(-5,1,-2,STAINED_CLAY:3)
Block(-5,1,-1,STAINED_CLAY:3)
Block(-5,1,0,STAINED_CLAY:3)
Block(-5,1,1,STAINED_CLAY:3)
Block(-5,1,2,STAINED_CLAY:3)
Block(-5,1,3,STAINED_CLAY:3)
Block(-5,1,4,STAINED_CLAY:3)
Block(-5,1,5,STAINED_CLAY:3)
Block(-5,1,6,STAINED_CLAY:3)
Block(-5,1,7,STAINED_CLAY:3)
Block(-5,1,8,STAINED_CLAY:3)
Block(-5,2,-2,STAINED_CLAY:3)
Block(-5,2,-1,STAINED_CLAY:3)
Block(-5,2,0,STAINED_CLAY:3)
Block(-5,2,1,STAINED_CLAY:3)
Block(-5,2,2,STAINED_CLAY:3)
Block(-5,2,3,STAINED_CLAY:3)
Block(-5,2,4,STAINED_CLAY:3)
Block(-5,2,5,STAINED_CLAY:3)
Block(-5,2,6,STAINED_CLAY:3)
Block(-5,2,7,STAINED_CLAY:3)
Block(-5,2,8,STAINED_CLAY:3)
Block(-5,3,-2,STAINED_CLAY:3)
Block(-5,3,-1,STAINED_CLAY:3)
Block(-5,3,0,STAINED_CLAY:3)
Block(-5,3,1,STAINED_CLAY:3)
Block(-5,3,2,STAINED_CLAY:3)
Block(-5,3,3,STAINED_CLAY:3)
Block(-5,3,4,STAINED_CLAY:3)
Block(-5,3,5,STAINED_CLAY:3)
Block(-5,3,6,STAINED_CLAY:3)
Block(-5,3,7,STAINED_CLAY:3)
Block(-5,3,8,STAINED_CLAY:3)
Block(-5,4,-2,STAINED_CLAY:3)
Block(-5,4,-1,STAINED_CLAY:3)
Block(-5,4,0,STAINED_CLAY:3)
Block(-5,4,1,STAINED_CLAY:3)
Block(-5,4,2,STAINED_CLAY:3)
Block(-5,4,3,STAINED_CLAY:3)
Block(-5,4,4,STAINED_CLAY:3)
Block(-5,4,5,STAINED_CLAY:3)
Block(-5,4,6,STAINED_CLAY:3)
Block(-5,4,7,STAINED_CLAY:3)
Block(-5,4,8,STAINED_CLAY:3)
Block(-5,5,-3,STAINED_CLAY:3)
Block(-5,5,-2,STAINED_CLAY:3)
Block(-5,5,-1,STAINED_CLAY:3)
Block(-5,5,0,STAINED_CLAY:3)
Block(-5,5,1,STAINED_CLAY:3)
Block(-5,5,2,STAINED_CLAY:3)
Block(-5,5,3,STAINED_CLAY:3)
Block(-5,5,4,STAINED_CLAY:3)
Block(-5,5,5,STAINED_CLAY:3)
Block(-5,5,6,STAINED_CLAY:3)
Block(-5,5,7,STAINED_CLAY:3)
Block(-5,5,8,STAINED_CLAY:3)
Block(-5,6,-3,STAINED_CLAY:3)
Block(-5,6,-2,STAINED_CLAY:3)
Block(-5,6,-1,STAINED_CLAY:3)
Block(-5,6,0,STAINED_CLAY:3)
Block(-5,6,1,STAINED_CLAY:3)
Block(-5,6,2,STAINED_CLAY:3)
Block(-5,6,3,STAINED_CLAY:3)
Block(-5,6,4,STAINED_CLAY:3)
Block(-5,6,5,STAINED_CLAY:3)
Block(-5,6,6,STAINED_CLAY:3)
Block(-5,6,7,STAINED_CLAY:3)
Block(-5,6,8,STAINED_CLAY:3)
Block(-5,7,-3,STAINED_CLAY:3)
Block(-5,7,-2,STAINED_CLAY:3)
Block(-5,7,-1,STAINED_CLAY:3)
Block(-5,7,0,STAINED_CLAY:3)
Block(-5,7,1,STAINED_CLAY:3)
Block(-5,7,2,STAINED_CLAY:3)
Block(-5,7,3,STAINED_CLAY:3)
Block(-5,7,4,STAINED_CLAY:3)
Block(-5,7,5,STAINED_CLAY:3)
Block(-5,7,6,STAINED_CLAY:3)
Block(-5,7,7,STAINED_CLAY:3)
Block(-5,7,8,STAINED_CLAY:3)
Block(-5,8,-3,STAINED_CLAY:3)
Block(-5,8,-2,STAINED_CLAY:3)
Block(-5,8,-1,STAINED_CLAY:3)
Block(-5,8,0,STAINED_CLAY:3)
Block(-5,8,1,STAINED_CLAY:3)
Block(-5,8,2,STAINED_CLAY:3)
Block(-5,8,3,STAINED_CLAY:3)
Block(-5,8,4,STAINED_CLAY:3)
Block(-5,8,5,STAINED_CLAY:3)
Block(-5,8,6,STAINED_CLAY:3)
Block(-5,8,7,STAINED_CLAY:3)
Block(-5,8,8,STAINED_CLAY:3)
Block(-5,9,-4,STAINED_CLAY:3)
Block(-5,9,-3,STAINED_CLAY:3)
Block(-5,9,-2,STAINED_CLAY:3)
Block(-5,9,-1,STAINED_CLAY:3)
Block(-5,9,0,STAINED_CLAY:3)
Block(-5,9,1,STAINED_CLAY:3)
Block(-5,9,2,STAINED_CLAY:3)
Block(-5,9,3,STAINED_CLAY:3)
Block(-5,9,4,STAINED_CLAY:3)
Block(-5,9,5,STAINED_CLAY:3)
Block(-5,9,6,STAINED_CLAY:3)
Block(-5,9,7,STAINED_CLAY:3)
Block(-5,9,8,STAINED_CLAY:3)
Block(-5,10,-4,STAINED_CLAY:3)
Block(-5,10,-3,STAINED_CLAY:3)
Block(-5,10,-2,STAINED_CLAY:3)
Block(-5,10,-1,STAINED_CLAY:3)
Block(-5,10,0,STAINED_CLAY:3)
Block(-5,10,1,STAINED_CLAY:3)
Block(-5,10,2,STAINED_CLAY:3)
Block(-5,10,3,STAINED_CLAY:3)
Block(-5,10,4,STAINED_CLAY:3)
Block(-5,10,5,STAINED_CLAY:3)
Block(-5,10,6,STAINED_CLAY:3)
Block(-5,10,7,STAINED_CLAY:3)
Block(-5,10,8,STAINED_CLAY:3)
Block(-5,11,-4,STAINED_CLAY:3)
Block(-5,11,-3,STAINED_CLAY:3)
Block(-5,11,-2,STAINED_CLAY:3)
Block(-5,11,-1,STAINED_CLAY:3)
Block(-5,11,0,STAINED_CLAY:3)
Block(-5,11,1,STAINED_CLAY:3)
Block(-5,11,2,STAINED_CLAY:3)
Block(-5,11,3,STAINED_CLAY:3)
Block(-5,11,4,STAINED_CLAY:3)
Block(-5,11,5,STAINED_CLAY:3)
Block(-5,11,6,STAINED_CLAY:3)
Block(-5,11,7,STAINED_CLAY:3)
Block(-5,11,8,STAINED_CLAY:3)
Block(-5,12,-4,STAINED_CLAY:3)
Block(-5,12,-3,STAINED_CLAY:3)
Block(-5,12,-2,STAINED_CLAY:3)
Block(-5,12,-1,STAINED_CLAY:3)
Block(-5,12,0,STAINED_CLAY:3)
Block(-5,12,1,STAINED_CLAY:3)
Block(-5,12,2,STAINED_CLAY:3)
Block(-5,12,3,STAINED_CLAY:3)
Block(-5,12,4,STAINED_CLAY:3)
Block(-5,12,5,STAINED_CLAY:3)
Block(-5,12,6,STAINED_CLAY:3)
Block(-5,12,7,STAINED_CLAY:3)
Block(-5,12,8,STAINED_CLAY:3)
Block(-5,13,-4,STAINED_CLAY:3)
Block(-5,13,-3,STAINED_CLAY:3)
Block(-5,13,-2,STAINED_CLAY:3)
Block(-5,13,-1,STAINED_CLAY:3)
Block(-5,13,0,STAINED_CLAY:3)
Block(-5,13,1,STAINED_CLAY:3)
Block(-5,13,2,STAINED_CLAY:3)
Block(-5,13,3,STAINED_CLAY:3)
Block(-5,13,4,STAINED_CLAY:3)
Block(-5,13,5,STAINED_CLAY:3)
Block(-5,13,6,STAINED_CLAY:3)
Block(-5,13,7,STAINED_CLAY:3)
Block(-5,13,8,STAINED_CLAY:3)
Block(-5,14,-5,STAINED_CLAY:3)
Block(-5,14,-4,STAINED_CLAY:3)
Block(-5,14,-3,STAINED_CLAY:3)
Block(-5,14,-2,STAINED_CLAY:3)
Block(-5,14,-1,STAINED_CLAY:3)
Block(-5,14,0,STAINED_CLAY:3)
Block(-5,14,1,STAINED_CLAY:3)
Block(-5,14,2,STAINED_CLAY:3)
Block(-5,14,3,STAINED_CLAY:3)
Block(-5,14,4,STAINED_CLAY:3)
Block(-5,14,5,STAINED_CLAY:3)
Block(-5,14,6,STAINED_CLAY:3)
Block(-5,14,7,STAINED_CLAY:3)
Block(-5,14,8,STAINED_CLAY:3)
Block(-5,15,-5,STAINED_CLAY:3)
Block(-5,15,-4,STAINED_CLAY:3)
Block(-5,15,-3,STAINED_CLAY:3)
Block(-5,15,-2,STAINED_CLAY:3)
Block(-5,15,-1,STAINED_CLAY:3)
Block(-5,15,0,STAINED_CLAY:3)
Block(-5,15,1,STAINED_CLAY:3)
Block(-5,15,2,STAINED_CLAY:3)
Block(-5,15,3,STAINED_CLAY:3)
Block(-5,15,4,STAINED_CLAY:3)
Block(-5,15,5,STAINED_CLAY:3)
Block(-5,15,6,STAINED_CLAY:3)
Block(-5,15,7,STAINED_CLAY:3)
Block(-5,15,8,STAINED_CLAY:3)
Block(-5,16,-5,STAINED_CLAY:3)
Block(-5,16,-4,STAINED_CLAY:3)
Block(-5,16,-3,STAINED_CLAY:3)
Block(-5,16,-2,STAINED_CLAY:3)
Block(-5,16,-1,STAINED_CLAY:3)
Block(-5,16,0,STAINED_CLAY:3)
Block(-5,16,1,STAINED_CLAY:3)
Block(-5,16,2,STAINED_CLAY:3)
Block(-5,16,3,STAINED_CLAY:3)
Block(-5,16,4,STAINED_CLAY:3)
Block(-5,16,5,STAINED_CLAY:3)
Block(-5,16,6,STAINED_CLAY:3)
Block(-5,16,7,OBSIDIAN:0)
Block(-5,16,8,OBSIDIAN:0)
Block(-5,17,-5,STAINED_CLAY:3)
Block(-5,17,-4,STAINED_CLAY:3)
Block(-5,17,-3,STAINED_CLAY:3)
Block(-5,17,-2,STAINED_CLAY:3)
Block(-5,17,-1,STAINED_CLAY:3)
Block(-5,17,0,STAINED_CLAY:3)
Block(-5,17,1,STAINED_CLAY:3)
Block(-5,17,2,STAINED_CLAY:3)
Block(-5,17,3,STAINED_CLAY:3)
Block(-5,17,4,STAINED_CLAY:3)
Block(-5,17,5,STAINED_CLAY:3)
Block(-5,17,6,STAINED_CLAY:3)
Block(-5,17,7,OBSIDIAN:0)
Block(-5,17,8,OBSIDIAN:0)
Block(-5,18,-5,STAINED_CLAY:3)
Block(-5,18,-4,STAINED_CLAY:3)
Block(-5,18,-3,STAINED_CLAY:3)
Block(-5,18,-2,STAINED_CLAY:3)
Block(-5,18,-1,STAINED_CLAY:3)
Block(-5,18,0,STAINED_CLAY:3)
Block(-5,18,1,STAINED_CLAY:3)
Block(-5,18,2,STAINED_CLAY:3)
Block(-5,18,3,STAINED_CLAY:3)
Block(-5,18,4,STAINED_CLAY:3)
Block(-5,18,5,STAINED_CLAY:3)
Block(-5,18,6,STAINED_CLAY:3)
Block(-5,18,7,OBSIDIAN:0)
Block(-5,18,8,OBSIDIAN:0)
Block(-5,19,-6,OBSIDIAN:0)
Block(-5,19,-5,STAINED_CLAY:3)
Block(-5,19,-4,OBSIDIAN:0)
Block(-5,19,-3,OBSIDIAN:0)
Block(-5,19,-2,OBSIDIAN:0)
Block(-5,19,-1,STAINED_CLAY:3)
Block(-5,19,0,STAINED_CLAY:3)
Block(-5,19,1,STAINED_CLAY:3)
Block(-5,19,2,STAINED_CLAY:3)
Block(-5,19,3,STAINED_CLAY:3)
Block(-5,19,4,STAINED_CLAY:3)
Block(-5,19,5,STAINED_CLAY:3)
Block(-5,19,6,STAINED_CLAY:3)
Block(-5,19,7,OBSIDIAN:0)
Block(-5,19,8,OBSIDIAN:0)
Block(-5,20,-6,OBSIDIAN:0)
Block(-5,20,-5,OBSIDIAN:0)
Block(-5,20,-4,OBSIDIAN:0)
Block(-5,20,-3,OBSIDIAN:0)
Block(-5,20,-2,OBSIDIAN:0)
Block(-5,20,-1,STAINED_CLAY:3)
Block(-5,20,0,STAINED_CLAY:3)
Block(-5,20,1,STAINED_CLAY:3)
Block(-5,20,2,STAINED_CLAY:3)
Block(-5,20,3,STAINED_CLAY:3)
Block(-5,20,4,STAINED_CLAY:3)
Block(-5,20,5,STAINED_CLAY:3)
Block(-5,20,6,OBSIDIAN:0)
Block(-5,20,7,OBSIDIAN:0)
Block(-5,20,8,OBSIDIAN:0)
Block(-5,21,-6,OBSIDIAN:0)
Block(-5,21,-5,OBSIDIAN:0)
Block(-5,21,-4,OBSIDIAN:0)
Block(-5,21,-3,OBSIDIAN:0)
Block(-5,21,-2,OBSIDIAN:0)
Block(-5,21,-1,STAINED_CLAY:3)
Block(-5,21,0,STAINED_CLAY:3)
Block(-5,21,1,STAINED_CLAY:3)
Block(-5,21,2,STAINED_CLAY:3)
Block(-5,21,3,STAINED_CLAY:3)
Block(-5,21,4,STAINED_CLAY:3)
Block(-5,21,5,OBSIDIAN:0)
Block(-5,21,6,OBSIDIAN:0)
Block(-5,21,7,OBSIDIAN:0)
Block(-5,21,8,OBSIDIAN:0)
Block(-5,22,-6,OBSIDIAN:0)
Block(-5,22,-5,OBSIDIAN:0)
Block(-5,22,-4,OBSIDIAN:0)
Block(-5,22,-3,OBSIDIAN:0)
Block(-5,22,-2,OBSIDIAN:0)
Block(-5,22,-1,STAINED_CLAY:3)
Block(-5,22,0,STAINED_CLAY:3)
Block(-5,22,1,STAINED_CLAY:3)
Block(-5,22,2,STAINED_CLAY:3)
Block(-5,22,3,STAINED_CLAY:3)
Block(-5,22,4,OBSIDIAN:0)
Block(-5,22,5,OBSIDIAN:0)
Block(-5,22,6,OBSIDIAN:0)
Block(-5,22,7,OBSIDIAN:0)
Block(-5,22,8,OBSIDIAN:0)
Block(-5,23,-6,OBSIDIAN:0)
Block(-5,23,-5,OBSIDIAN:0)
Block(-5,23,-4,OBSIDIAN:0)
Block(-5,23,-3,OBSIDIAN:0)
Block(-5,23,-2,OBSIDIAN:0)
Block(-5,23,-1,STAINED_CLAY:3)
Block(-5,23,0,STAINED_CLAY:3)
Block(-5,23,1,STAINED_CLAY:3)
Block(-5,23,2,STAINED_CLAY:3)
Block(-5,23,3,STAINED_CLAY:3)
Block(-5,23,4,OBSIDIAN:0)
Block(-5,23,5,OBSIDIAN:0)
Block(-5,23,6,OBSIDIAN:0)
Block(-5,23,7,OBSIDIAN:0)
Block(-5,24,-7,OBSIDIAN:0)
Block(-5,24,-6,OBSIDIAN:0)
Block(-5,24,-5,OBSIDIAN:0)
Block(-5,24,-4,OBSIDIAN:0)
Block(-5,24,-3,OBSIDIAN:0)
Block(-5,24,-2,OBSIDIAN:0)
Block(-5,24,-1,STAINED_CLAY:3)
Block(-5,24,0,STAINED_CLAY:3)
Block(-5,24,1,STAINED_CLAY:3)
Block(-5,24,2,STAINED_CLAY:3)
Block(-5,24,3,STAINED_CLAY:3)
Block(-5,24,4,OBSIDIAN:0)
Block(-5,24,5,OBSIDIAN:0)
Block(-5,24,6,OBSIDIAN:0)
Block(-5,24,7,OBSIDIAN:0)
Block(-5,25,-7,OBSIDIAN:0)
Block(-5,25,-6,OBSIDIAN:0)
Block(-5,25,-5,OBSIDIAN:0)
Block(-5,25,-4,OBSIDIAN:0)
Block(-5,25,-3,OBSIDIAN:0)
Block(-5,25,-2,STAINED_CLAY:3)
Block(-5,25,-1,STAINED_CLAY:3)
Block(-5,25,0,STAINED_CLAY:3)
Block(-5,25,1,STAINED_CLAY:3)
Block(-5,25,2,STAINED_CLAY:3)
Block(-5,25,3,OBSIDIAN:0)
Block(-5,25,4,OBSIDIAN:0)
Block(-5,25,5,OBSIDIAN:0)
Block(-5,25,6,OBSIDIAN:0)
Block(-5,25,7,OBSIDIAN:0)
Block(-5,26,-7,OBSIDIAN:0)
Block(-5,26,-6,OBSIDIAN:0)
Block(-5,26,-5,OBSIDIAN:0)
Block(-5,26,-4,OBSIDIAN:0)
Block(-5,26,-3,STAINED_CLAY:3)
Block(-5,26,-2,STAINED_CLAY:3)
Block(-5,26,-1,STAINED_CLAY:3)
Block(-5,26,0,STAINED_CLAY:3)
Block(-5,26,1,STAINED_CLAY:3)
Block(-5,26,2,STAINED_CLAY:3)
Block(-5,26,3,OBSIDIAN:0)
Block(-5,26,4,OBSIDIAN:0)
Block(-5,26,5,OBSIDIAN:0)
Block(-5,26,6,OBSIDIAN:0)
Block(-5,27,-7,STAINED_CLAY:3)
Block(-5,27,-6,STAINED_CLAY:3)
Block(-5,27,-5,STAINED_CLAY:3)
Block(-5,27,-4,STAINED_CLAY:3)
Block(-5,27,-3,STAINED_CLAY:3)
Block(-5,27,-2,STAINED_CLAY:3)
Block(-5,27,-1,STAINED_CLAY:3)
Block(-5,27,0,STAINED_CLAY:3)
Block(-5,27,1,STAINED_CLAY:3)
Block(-5,27,2,STAINED_CLAY:3)
Block(-5,27,3,OBSIDIAN:0)
Block(-5,27,4,OBSIDIAN:0)
Block(-5,27,5,OBSIDIAN:0)
Block(-5,27,6,OBSIDIAN:0)
Block(-5,28,-7,STAINED_CLAY:3)
Block(-5,28,-6,STAINED_CLAY:3)
Block(-5,28,-5,STAINED_CLAY:3)
Block(-5,28,-4,STAINED_CLAY:3)
Block(-5,28,-3,STAINED_CLAY:3)
Block(-5,28,-2,STAINED_CLAY:3)
Block(-5,28,-1,STAINED_CLAY:3)
Block(-5,28,0,STAINED_CLAY:3)
Block(-5,28,1,STAINED_CLAY:3)
Block(-5,28,2,OBSIDIAN:0)
Block(-5,28,3,OBSIDIAN:0)
Block(-5,28,4,OBSIDIAN:0)
Block(-5,28,5,OBSIDIAN:0)
Block(-5,29,-7,STAINED_CLAY:3)
Block(-5,29,-6,STAINED_CLAY:3)
Block(-5,29,-5,STAINED_CLAY:3)
Block(-5,29,-4,STAINED_CLAY:3)
Block(-5,29,-3,STAINED_CLAY:3)
Block(-5,29,-2,STAINED_CLAY:3)
Block(-5,29,-1,STAINED_CLAY:3)
Block(-5,29,0,STAINED_CLAY:3)
Block(-5,29,1,STAINED_CLAY:3)
Block(-5,29,2,OBSIDIAN:0)
Block(-5,29,3,OBSIDIAN:0)
Block(-5,29,4,OBSIDIAN:0)
Block(-5,29,5,OBSIDIAN:0)
Block(-5,30,-7,STAINED_CLAY:3)
Block(-5,30,-6,STAINED_CLAY:3)
Block(-5,30,-5,STAINED_CLAY:3)
Block(-5,30,-4,STAINED_CLAY:3)
Block(-5,30,-3,STAINED_CLAY:3)
Block(-5,30,-2,STAINED_CLAY:3)
Block(-5,30,-1,STAINED_CLAY:3)
Block(-5,30,0,STAINED_CLAY:3)
Block(-5,30,1,STAINED_CLAY:3)
Block(-5,30,2,OBSIDIAN:0)
Block(-5,30,3,OBSIDIAN:0)
Block(-5,30,4,OBSIDIAN:0)
Block(-5,30,5,OBSIDIAN:0)
Block(-5,31,-7,STAINED_CLAY:3)
Block(-5,31,-6,STAINED_CLAY:3)
Block(-5,31,-5,STAINED_CLAY:3)
Block(-5,31,-4,STAINED_CLAY:3)
Block(-5,31,-3,STAINED_CLAY:3)
Block(-5,31,-2,STAINED_CLAY:3)
Block(-5,31,-1,STAINED_CLAY:3)
Block(-5,31,0,STAINED_CLAY:3)
Block(-5,31,1,STAINED_CLAY:3)
Block(-5,31,2,OBSIDIAN:0)
Block(-5,31,3,OBSIDIAN:0)
Block(-5,31,4,OBSIDIAN:0)
Block(-5,32,-7,STAINED_CLAY:3)
Block(-5,32,-6,STAINED_CLAY:3)
Block(-5,32,-5,STAINED_CLAY:3)
Block(-5,32,-4,STAINED_CLAY:3)
Block(-5,32,-3,STAINED_CLAY:3)
Block(-5,32,-2,STAINED_CLAY:3)
Block(-5,32,-1,STAINED_CLAY:3)
Block(-5,32,0,STAINED_CLAY:3)
Block(-5,32,1,STAINED_CLAY:3)
Block(-5,32,2,OBSIDIAN:0)
Block(-5,32,3,OBSIDIAN:0)
Block(-5,32,4,OBSIDIAN:0)
Block(-5,33,-7,STAINED_CLAY:3)
Block(-5,33,-6,STAINED_CLAY:3)
Block(-5,33,-5,STAINED_CLAY:3)
Block(-5,33,-4,STAINED_CLAY:3)
Block(-5,33,-3,STAINED_CLAY:3)
Block(-5,33,-2,STAINED_CLAY:3)
Block(-5,33,-1,STAINED_CLAY:3)
Block(-5,33,0,STAINED_CLAY:3)
Block(-5,33,1,STAINED_CLAY:3)
Block(-5,33,2,STAINED_CLAY:3)
Block(-5,33,3,STAINED_CLAY:3)
Block(-5,33,4,STAINED_CLAY:3)
Block(-5,34,-7,STAINED_CLAY:3)
Block(-5,34,-6,STAINED_CLAY:3)
Block(-5,34,-5,STAINED_CLAY:3)
Block(-5,34,-4,STAINED_CLAY:3)
Block(-5,34,-3,STAINED_CLAY:3)
Block(-5,34,-2,STAINED_CLAY:3)
Block(-5,34,-1,STAINED_CLAY:3)
Block(-5,34,0,STAINED_CLAY:3)
Block(-5,34,1,STAINED_CLAY:3)
Block(-5,34,2,STAINED_CLAY:3)
Block(-5,34,3,STAINED_CLAY:3)
Block(-5,35,-7,STAINED_CLAY:3)
Block(-5,35,-6,STAINED_CLAY:3)
Block(-5,35,-5,STAINED_CLAY:3)
Block(-5,35,-4,STAINED_CLAY:3)
Block(-5,35,-3,STAINED_CLAY:3)
Block(-5,35,-2,STAINED_CLAY:3)
Block(-5,35,-1,STAINED_CLAY:3)
Block(-5,35,0,STAINED_CLAY:3)
Block(-5,35,1,STAINED_CLAY:3)
Block(-5,35,2,STAINED_CLAY:3)
Block(-5,35,3,STAINED_CLAY:3)
Block(-5,36,-7,STAINED_CLAY:3)
Block(-5,36,-6,STAINED_CLAY:3)
Block(-5,36,-5,STAINED_CLAY:3)
Block(-5,36,-4,STAINED_CLAY:3)
Block(-5,36,-3,STAINED_CLAY:3)
Block(-5,36,-2,STAINED_CLAY:3)
Block(-5,36,-1,STAINED_CLAY:3)
Block(-5,36,0,STAINED_CLAY:3)
Block(-5,36,1,STAINED_CLAY:3)
Block(-5,36,2,STAINED_CLAY:3)
Block(-5,36,3,STAINED_CLAY:3)
Block(-5,37,-7,STAINED_CLAY:3)
Block(-5,37,-6,STAINED_CLAY:3)
Block(-5,37,-5,STAINED_CLAY:3)
Block(-5,37,-4,STAINED_CLAY:3)
Block(-5,37,-3,STAINED_CLAY:3)
Block(-5,37,-2,STAINED_CLAY:3)
Block(-5,37,-1,STAINED_CLAY:3)
Block(-5,37,0,STAINED_CLAY:3)
Block(-5,37,1,STAINED_CLAY:3)
Block(-5,37,2,STAINED_CLAY:3)
Block(-5,38,-7,OBSIDIAN:0)
Block(-5,38,-6,STAINED_CLAY:3)
Block(-5,38,-5,STAINED_CLAY:3)
Block(-5,38,-4,STAINED_CLAY:3)
Block(-5,38,-3,STAINED_CLAY:3)
Block(-5,38,-2,STAINED_CLAY:3)
Block(-5,38,-1,STAINED_CLAY:3)
Block(-5,38,0,STAINED_CLAY:3)
Block(-5,38,1,STAINED_CLAY:3)
Block(-5,38,2,STAINED_CLAY:3)
Block(-5,39,-7,OBSIDIAN:0)
Block(-5,39,-6,STAINED_CLAY:3)
Block(-5,39,-5,STAINED_CLAY:3)
Block(-5,39,-4,STAINED_CLAY:3)
Block(-5,39,-3,STAINED_CLAY:3)
Block(-5,39,-2,STAINED_CLAY:3)
Block(-5,39,-1,STAINED_CLAY:3)
Block(-5,39,0,STAINED_CLAY:3)
Block(-5,39,1,STAINED_CLAY:3)
Block(-5,39,2,STAINED_CLAY:3)
Block(-5,40,-7,OBSIDIAN:0)
Block(-5,40,-6,STAINED_CLAY:3)
Block(-5,40,-5,STAINED_CLAY:3)
Block(-5,40,-4,STAINED_CLAY:3)
Block(-5,40,-3,STAINED_CLAY:3)
Block(-5,40,-2,STAINED_CLAY:3)
Block(-5,40,-1,STAINED_CLAY:3)
Block(-5,40,0,STAINED_CLAY:3)
Block(-5,40,1,STAINED_CLAY:3)
Block(-5,41,-7,OBSIDIAN:0)
Block(-5,41,-6,STAINED_CLAY:3)
Block(-5,41,-5,STAINED_CLAY:3)
Block(-5,41,-4,STAINED_CLAY:3)
Block(-5,41,-3,STAINED_CLAY:3)
Block(-5,41,-2,STAINED_CLAY:3)
Block(-5,41,-1,STAINED_CLAY:3)
Block(-5,41,0,STAINED_CLAY:3)
Block(-5,41,1,STAINED_CLAY:3)
Block(-5,42,-7,OBSIDIAN:0)
Block(-5,42,-6,STAINED_CLAY:3)
Block(-5,42,-5,STAINED_CLAY:3)
Block(-5,42,-4,STAINED_CLAY:3)
Block(-5,42,-3,STAINED_CLAY:3)
Block(-5,42,-2,STAINED_CLAY:3)
Block(-5,42,-1,STAINED_CLAY:3)
Block(-5,42,0,STAINED_CLAY:3)
Block(-5,43,-7,OBSIDIAN:0)
Block(-5,43,-6,STAINED_CLAY:3)
Block(-5,43,-5,STAINED_CLAY:3)
Block(-5,43,-4,STAINED_CLAY:3)
Block(-5,43,-3,STAINED_CLAY:3)
Block(-5,43,-2,STAINED_CLAY:3)
Block(-5,43,-1,STAINED_CLAY:3)
Block(-5,43,0,STAINED_CLAY:3)
Block(-5,44,-7,OBSIDIAN:0)
Block(-5,44,-6,STAINED_CLAY:3)
Block(-5,44,-5,STAINED_CLAY:3)
Block(-5,44,-4,STAINED_CLAY:3)
Block(-5,44,-3,STAINED_CLAY:3)
Block(-5,44,-2,STAINED_CLAY:3)
Block(-5,44,-1,STAINED_CLAY:3)
Block(-5,44,0,STAINED_CLAY:3)
Block(-5,45,-7,OBSIDIAN:0)
Block(-5,45,-6,STAINED_CLAY:3)
Block(-5,45,-5,STAINED_CLAY:3)
Block(-5,45,-4,STAINED_CLAY:3)
Block(-5,45,-3,STAINED_CLAY:3)
Block(-5,45,-2,STAINED_CLAY:3)
Block(-5,45,-1,STAINED_CLAY:3)
Block(-5,46,-7,STAINED_CLAY:3)
Block(-5,46,-6,STAINED_CLAY:3)
Block(-5,46,-5,STAINED_CLAY:3)
Block(-5,46,-4,STAINED_CLAY:3)
Block(-5,46,-3,STAINED_CLAY:3)
Block(-5,46,-2,STAINED_CLAY:3)
Block(-5,46,-1,STAINED_CLAY:3)
Block(-5,47,-7,STAINED_CLAY:3)
Block(-5,47,-6,STAINED_CLAY:3)
Block(-5,47,-5,STAINED_CLAY:3)
Block(-5,47,-4,STAINED_CLAY:3)
Block(-5,47,-3,STAINED_CLAY:3)
Block(-5,47,-2,STAINED_CLAY:3)
Block(-5,47,-1,STAINED_CLAY:3)
Block(-5,48,-7,STAINED_CLAY:3)
Block(-5,48,-6,STAINED_CLAY:3)
Block(-5,48,-5,STAINED_CLAY:3)
Block(-5,48,-4,STAINED_CLAY:3)
Block(-5,48,-3,STAINED_CLAY:3)
Block(-5,48,-2,STAINED_CLAY:3)
Block(-5,49,-7,STAINED_CLAY:3)
Block(-5,49,-6,STAINED_CLAY:3)
Block(-5,49,-5,STAINED_CLAY:3)
Block(-5,49,-4,STAINED_CLAY:3)
Block(-5,49,-3,STAINED_CLAY:3)
Block(-5,49,-2,STAINED_CLAY:3)
Block(-5,50,-7,STAINED_CLAY:3)
Block(-5,50,-6,STAINED_CLAY:3)
Block(-5,50,-5,STAINED_CLAY:3)
Block(-5,50,-4,STAINED_CLAY:3)
Block(-5,50,-3,STAINED_CLAY:3)
Block(-5,50,-2,STAINED_CLAY:3)
Block(-5,51,-7,STAINED_CLAY:3)
Block(-5,51,-6,STAINED_CLAY:3)
Block(-5,51,-5,STAINED_CLAY:3)
Block(-5,51,-4,STAINED_CLAY:3)
Block(-5,51,-3,STAINED_CLAY:3)
Block(-5,52,-7,STAINED_CLAY:3)
Block(-5,52,-6,STAINED_CLAY:3)
Block(-5,52,-5,STAINED_CLAY:3)
Block(-5,52,-4,STAINED_CLAY:3)
Block(-5,52,-3,STAINED_CLAY:3)
Block(-5,53,-7,STAINED_CLAY:3)
Block(-5,53,-6,STAINED_CLAY:3)
Block(-5,53,-5,STAINED_CLAY:3)
Block(-5,53,-4,STAINED_CLAY:3)
Block(-5,54,-7,STAINED_CLAY:3)
Block(-5,54,-6,STAINED_CLAY:3)
Block(-5,54,-5,STAINED_CLAY:3)
Block(-5,54,-4,STAINED_CLAY:3)
Block(-5,55,-7,STAINED_CLAY:3)
Block(-5,55,-6,STAINED_CLAY:3)
Block(-5,55,-5,STAINED_CLAY:3)
Block(-5,55,-4,STAINED_CLAY:3)
Block(-5,56,-7,STAINED_CLAY:3)
Block(-5,56,-6,STAINED_CLAY:3)
Block(-5,56,-5,STAINED_CLAY:3)
Block(-5,57,-7,STAINED_CLAY:3)
Block(-5,57,-6,STAINED_CLAY:3)
Block(-5,57,-5,STAINED_CLAY:3)
Block(-5,58,-7,STAINED_CLAY:3)
Block(-5,58,-6,STAINED_CLAY:3)
Block(-5,58,-5,STAINED_CLAY:3)
Block(-5,59,-7,STAINED_CLAY:3)
Block(-5,59,-6,STAINED_CLAY:3)
Block(-5,60,-7,STAINED_CLAY:3)
Block(-5,60,-6,STAINED_CLAY:3)
Block(-5,61,-7,STAINED_CLAY:3)
Block(-5,61,-6,STAINED_CLAY:3)
Block(-5,62,-7,STAINED_CLAY:3)
Block(-5,63,-7,STAINED_CLAY:3)
Block(-5,64,-7,STAINED_CLAY:3)
Block(-4,0,-1,STAINED_CLAY:3)
Block(-4,0,0,STAINED_CLAY:3)
Block(-4,0,1,STAINED_CLAY:3)
Block(-4,0,2,STAINED_CLAY:3)
Block(-4,0,3,STAINED_CLAY:3)
Block(-4,0,4,STAINED_CLAY:3)
Block(-4,0,5,STAINED_CLAY:3)
Block(-4,0,6,STAINED_CLAY:3)
Block(-4,0,7,STAINED_CLAY:3)
Block(-4,0,8,STAINED_CLAY:3)
Block(-4,1,-1,STAINED_CLAY:3)
Block(-4,1,0,STAINED_CLAY:3)
Block(-4,1,1,STAINED_CLAY:3)
Block(-4,1,2,STAINED_CLAY:3)
Block(-4,1,3,STAINED_CLAY:3)
Block(-4,1,4,STAINED_CLAY:3)
Block(-4,1,5,STAINED_CLAY:3)
Block(-4,1,6,STAINED_CLAY:3)
Block(-4,1,7,STAINED_CLAY:3)
Block(-4,1,8,STAINED_CLAY:3)
Block(-4,2,-1,STAINED_CLAY:3)
Block(-4,2,0,STAINED_CLAY:3)
Block(-4,2,1,STAINED_CLAY:3)
Block(-4,2,2,STAINED_CLAY:3)
Block(-4,2,3,STAINED_CLAY:3)
Block(-4,2,4,STAINED_CLAY:3)
Block(-4,2,5,STAINED_CLAY:3)
Block(-4,2,6,STAINED_CLAY:3)
Block(-4,2,7,STAINED_CLAY:3)
Block(-4,2,8,STAINED_CLAY:3)
Block(-4,3,-1,STAINED_CLAY:3)
Block(-4,3,0,STAINED_CLAY:3)
Block(-4,3,1,STAINED_CLAY:3)
Block(-4,3,2,STAINED_CLAY:3)
Block(-4,3,3,STAINED_CLAY:3)
Block(-4,3,4,STAINED_CLAY:3)
Block(-4,3,5,STAINED_CLAY:3)
Block(-4,3,6,STAINED_CLAY:3)
Block(-4,3,7,STAINED_CLAY:3)
Block(-4,3,8,STAINED_CLAY:3)
Block(-4,4,-2,STAINED_CLAY:3)
Block(-4,4,-1,STAINED_CLAY:3)
Block(-4,4,0,STAINED_CLAY:3)
Block(-4,4,1,STAINED_CLAY:3)
Block(-4,4,2,STAINED_CLAY:3)
Block(-4,4,3,STAINED_CLAY:3)
Block(-4,4,4,STAINED_CLAY:3)
Block(-4,4,5,STAINED_CLAY:3)
Block(-4,4,6,STAINED_CLAY:3)
Block(-4,4,7,STAINED_CLAY:3)
Block(-4,4,8,STAINED_CLAY:3)
Block(-4,5,-2,STAINED_CLAY:3)
Block(-4,5,-1,STAINED_CLAY:3)
Block(-4,5,0,STAINED_CLAY:3)
Block(-4,5,1,STAINED_CLAY:3)
Block(-4,5,2,STAINED_CLAY:3)
Block(-4,5,3,STAINED_CLAY:3)
Block(-4,5,4,STAINED_CLAY:3)
Block(-4,5,5,STAINED_CLAY:3)
Block(-4,5,6,STAINED_CLAY:3)
Block(-4,5,7,STAINED_CLAY:3)
Block(-4,5,8,STAINED_CLAY:3)
Block(-4,6,-2,STAINED_CLAY:3)
Block(-4,6,-1,STAINED_CLAY:3)
Block(-4,6,0,STAINED_CLAY:3)
Block(-4,6,1,STAINED_CLAY:3)
Block(-4,6,2,STAINED_CLAY:3)
Block(-4,6,3,STAINED_CLAY:3)
Block(-4,6,4,STAINED_CLAY:3)
Block(-4,6,5,STAINED_CLAY:3)
Block(-4,6,6,STAINED_CLAY:3)
Block(-4,6,7,STAINED_CLAY:3)
Block(-4,6,8,STAINED_CLAY:3)
Block(-4,7,-2,STAINED_CLAY:3)
Block(-4,7,-1,STAINED_CLAY:3)
Block(-4,7,0,STAINED_CLAY:3)
Block(-4,7,1,STAINED_CLAY:3)
Block(-4,7,2,STAINED_CLAY:3)
Block(-4,7,3,STAINED_CLAY:3)
Block(-4,7,4,STAINED_CLAY:3)
Block(-4,7,5,STAINED_CLAY:3)
Block(-4,7,6,STAINED_CLAY:3)
Block(-4,7,7,STAINED_CLAY:3)
Block(-4,7,8,STAINED_CLAY:3)
Block(-4,8,-2,STAINED_CLAY:3)
Block(-4,8,-1,STAINED_CLAY:3)
Block(-4,8,0,STAINED_CLAY:3)
Block(-4,8,1,STAINED_CLAY:3)
Block(-4,8,2,STAINED_CLAY:3)
Block(-4,8,3,STAINED_CLAY:3)
Block(-4,8,4,STAINED_CLAY:3)
Block(-4,8,5,STAINED_CLAY:3)
Block(-4,8,6,STAINED_CLAY:3)
Block(-4,8,7,STAINED_CLAY:3)
Block(-4,8,8,STAINED_CLAY:3)
Block(-4,9,-3,STAINED_CLAY:3)
Block(-4,9,-2,STAINED_CLAY:3)
Block(-4,9,-1,STAINED_CLAY:3)
Block(-4,9,0,STAINED_CLAY:3)
Block(-4,9,1,STAINED_CLAY:3)
Block(-4,9,2,STAINED_CLAY:3)
Block(-4,9,3,STAINED_CLAY:3)
Block(-4,9,4,STAINED_CLAY:3)
Block(-4,9,5,STAINED_CLAY:3)
Block(-4,9,6,STAINED_CLAY:3)
Block(-4,9,7,STAINED_CLAY:3)
Block(-4,9,8,STAINED_CLAY:3)
Block(-4,10,-3,STAINED_CLAY:3)
Block(-4,10,-2,STAINED_CLAY:3)
Block(-4,10,-1,STAINED_CLAY:3)
Block(-4,10,0,STAINED_CLAY:3)
Block(-4,10,1,STAINED_CLAY:3)
Block(-4,10,2,STAINED_CLAY:3)
Block(-4,10,3,STAINED_CLAY:3)
Block(-4,10,4,STAINED_CLAY:3)
Block(-4,10,5,STAINED_CLAY:3)
Block(-4,10,6,STAINED_CLAY:3)
Block(-4,10,7,STAINED_CLAY:3)
Block(-4,10,8,STAINED_CLAY:3)
Block(-4,11,-3,STAINED_CLAY:3)
Block(-4,11,-2,STAINED_CLAY:3)
Block(-4,11,-1,STAINED_CLAY:3)
Block(-4,11,0,STAINED_CLAY:3)
Block(-4,11,1,STAINED_CLAY:3)
Block(-4,11,2,STAINED_CLAY:3)
Block(-4,11,3,STAINED_CLAY:3)
Block(-4,11,4,STAINED_CLAY:3)
Block(-4,11,5,STAINED_CLAY:3)
Block(-4,11,6,STAINED_CLAY:3)
Block(-4,11,7,STAINED_CLAY:3)
Block(-4,11,8,OBSIDIAN:0)
Block(-4,12,-3,STAINED_CLAY:3)
Block(-4,12,-2,STAINED_CLAY:3)
Block(-4,12,-1,STAINED_CLAY:3)
Block(-4,12,0,STAINED_CLAY:3)
Block(-4,12,1,STAINED_CLAY:3)
Block(-4,12,2,STAINED_CLAY:3)
Block(-4,12,3,STAINED_CLAY:3)
Block(-4,12,4,STAINED_CLAY:3)
Block(-4,12,5,STAINED_CLAY:3)
Block(-4,12,6,STAINED_CLAY:3)
Block(-4,12,7,STAINED_CLAY:3)
Block(-4,12,8,OBSIDIAN:0)
Block(-4,13,-4,STAINED_CLAY:3)
Block(-4,13,-3,STAINED_CLAY:3)
Block(-4,13,-2,STAINED_CLAY:3)
Block(-4,13,-1,STAINED_CLAY:3)
Block(-4,13,0,STAINED_CLAY:3)
Block(-4,13,1,STAINED_CLAY:3)
Block(-4,13,2,STAINED_CLAY:3)
Block(-4,13,3,STAINED_CLAY:3)
Block(-4,13,4,STAINED_CLAY:3)
Block(-4,13,5,STAINED_CLAY:3)
Block(-4,13,6,STAINED_CLAY:3)
Block(-4,13,7,STAINED_CLAY:3)
Block(-4,13,8,OBSIDIAN:0)
Block(-4,14,-4,STAINED_CLAY:3)
Block(-4,14,-3,STAINED_CLAY:3)
Block(-4,14,-2,STAINED_CLAY:3)
Block(-4,14,-1,STAINED_CLAY:3)
Block(-4,14,0,STAINED_CLAY:3)
Block(-4,14,1,STAINED_CLAY:3)
Block(-4,14,2,STAINED_CLAY:3)
Block(-4,14,3,STAINED_CLAY:3)
Block(-4,14,4,STAINED_CLAY:3)
Block(-4,14,5,STAINED_CLAY:3)
Block(-4,14,6,STAINED_CLAY:3)
Block(-4,14,7,STAINED_CLAY:3)
Block(-4,14,8,OBSIDIAN:0)
Block(-4,15,-4,STAINED_CLAY:3)
Block(-4,15,-3,STAINED_CLAY:3)
Block(-4,15,-2,STAINED_CLAY:3)
Block(-4,15,-1,STAINED_CLAY:3)
Block(-4,15,0,STAINED_CLAY:3)
Block(-4,15,1,STAINED_CLAY:3)
Block(-4,15,2,STAINED_CLAY:3)
Block(-4,15,3,STAINED_CLAY:3)
Block(-4,15,4,STAINED_CLAY:3)
Block(-4,15,5,STAINED_CLAY:3)
Block(-4,15,6,STAINED_CLAY:3)
Block(-4,15,7,STAINED_CLAY:3)
Block(-4,15,8,OBSIDIAN:0)
Block(-4,16,-4,STAINED_CLAY:3)
Block(-4,16,-3,STAINED_CLAY:3)
Block(-4,16,-2,STAINED_CLAY:3)
Block(-4,16,-1,STAINED_CLAY:3)
Block(-4,16,0,STAINED_CLAY:3)
Block(-4,16,1,STAINED_CLAY:3)
Block(-4,16,2,STAINED_CLAY:3)
Block(-4,16,3,STAINED_CLAY:3)
Block(-4,16,4,STAINED_CLAY:3)
Block(-4,16,5,STAINED_CLAY:3)
Block(-4,16,6,STAINED_CLAY:3)
Block(-4,16,7,OBSIDIAN:0)
Block(-4,16,8,OBSIDIAN:0)
Block(-4,17,-4,STAINED_CLAY:3)
Block(-4,17,-3,STAINED_CLAY:3)
Block(-4,17,-2,STAINED_CLAY:3)
Block(-4,17,-1,STAINED_CLAY:3)
Block(-4,17,0,STAINED_CLAY:3)
Block(-4,17,1,STAINED_CLAY:3)
Block(-4,17,2,STAINED_CLAY:3)
Block(-4,17,3,STAINED_CLAY:3)
Block(-4,17,4,STAINED_CLAY:3)
Block(-4,17,5,STAINED_CLAY:3)
Block(-4,17,6,OBSIDIAN:0)
Block(-4,17,7,OBSIDIAN:0)
Block(-4,17,8,OBSIDIAN:0)
Block(-4,18,-5,OBSIDIAN:0)
Block(-4,18,-4,OBSIDIAN:0)
Block(-4,18,-3,OBSIDIAN:0)
Block(-4,18,-2,OBSIDIAN:0)
Block(-4,18,-1,OBSIDIAN:0)
Block(-4,18,0,STAINED_CLAY:3)
Block(-4,18,1,STAINED_CLAY:3)
Block(-4,18,2,STAINED_CLAY:3)
Block(-4,18,3,STAINED_CLAY:3)
Block(-4,18,4,STAINED_CLAY:3)
Block(-4,18,5,STAINED_CLAY:3)
Block(-4,18,6,OBSIDIAN:0)
Block(-4,18,7,OBSIDIAN:0)
Block(-4,18,8,OBSIDIAN:0)
Block(-4,19,-5,OBSIDIAN:0)
Block(-4,19,-4,OBSIDIAN:0)
Block(-4,19,-3,OBSIDIAN:0)
Block(-4,19,-2,OBSIDIAN:0)
Block(-4,19,-1,OBSIDIAN:0)
Block(-4,19,0,STAINED_CLAY:3)
Block(-4,19,1,STAINED_CLAY:3)
Block(-4,19,2,STAINED_CLAY:3)
Block(-4,19,3,STAINED_CLAY:3)
Block(-4,19,4,STAINED_CLAY:3)
Block(-4,19,5,STAINED_CLAY:3)
Block(-4,19,6,OBSIDIAN:0)
Block(-4,19,7,OBSIDIAN:0)
Block(-4,19,8,OBSIDIAN:0)
Block(-4,20,-5,OBSIDIAN:0)
Block(-4,20,-4,OBSIDIAN:0)
Block(-4,20,-3,OBSIDIAN:0)
Block(-4,20,-2,OBSIDIAN:0)
Block(-4,20,-1,OBSIDIAN:0)
Block(-4,20,0,STAINED_CLAY:3)
Block(-4,20,1,STAINED_CLAY:3)
Block(-4,20,2,STAINED_CLAY:3)
Block(-4,20,3,STAINED_CLAY:3)
Block(-4,20,4,STAINED_CLAY:3)
Block(-4,20,5,STAINED_CLAY:3)
Block(-4,20,6,OBSIDIAN:0)
Block(-4,20,7,OBSIDIAN:0)
Block(-4,20,8,OBSIDIAN:0)
Block(-4,21,-5,OBSIDIAN:0)
Block(-4,21,-4,OBSIDIAN:0)
Block(-4,21,-3,OBSIDIAN:0)
Block(-4,21,-2,OBSIDIAN:0)
Block(-4,21,-1,OBSIDIAN:0)
Block(-4,21,0,STAINED_CLAY:3)
Block(-4,21,1,STAINED_CLAY:3)
Block(-4,21,2,STAINED_CLAY:3)
Block(-4,21,3,STAINED_CLAY:3)
Block(-4,21,4,STAINED_CLAY:3)
Block(-4,21,5,OBSIDIAN:0)
Block(-4,21,6,OBSIDIAN:0)
Block(-4,21,7,OBSIDIAN:0)
Block(-4,21,8,OBSIDIAN:0)
Block(-4,22,-5,OBSIDIAN:0)
Block(-4,22,-4,OBSIDIAN:0)
Block(-4,22,-3,OBSIDIAN:0)
Block(-4,22,-2,OBSIDIAN:0)
Block(-4,22,-1,OBSIDIAN:0)
Block(-4,22,0,STAINED_CLAY:3)
Block(-4,22,1,STAINED_CLAY:3)
Block(-4,22,2,STAINED_CLAY:3)
Block(-4,22,3,STAINED_CLAY:3)
Block(-4,22,4,OBSIDIAN:0)
Block(-4,22,5,OBSIDIAN:0)
Block(-4,22,6,OBSIDIAN:0)
Block(-4,22,7,OBSIDIAN:0)
Block(-4,22,8,OBSIDIAN:0)
Block(-4,23,-6,OBSIDIAN:0)
Block(-4,23,-5,OBSIDIAN:0)
Block(-4,23,-4,OBSIDIAN:0)
Block(-4,23,-3,OBSIDIAN:0)
Block(-4,23,-2,OBSIDIAN:0)
Block(-4,23,-1,STAINED_CLAY:3)
Block(-4,23,0,STAINED_CLAY:3)
Block(-4,23,1,STAINED_CLAY:3)
Block(-4,23,2,STAINED_CLAY:3)
Block(-4,23,3,STAINED_CLAY:3)
Block(-4,23,4,OBSIDIAN:0)
Block(-4,23,5,OBSIDIAN:0)
Block(-4,23,6,OBSIDIAN:0)
Block(-4,23,7,OBSIDIAN:0)
Block(-4,24,-6,OBSIDIAN:0)
Block(-4,24,-5,OBSIDIAN:0)
Block(-4,24,-4,OBSIDIAN:0)
Block(-4,24,-3,OBSIDIAN:0)
Block(-4,24,-2,OBSIDIAN:0)
Block(-4,24,-1,STAINED_CLAY:3)
Block(-4,24,0,STAINED_CLAY:3)
Block(-4,24,1,STAINED_CLAY:3)
Block(-4,24,2,STAINED_CLAY:3)
Block(-4,24,3,STAINED_CLAY:3)
Block(-4,24,4,OBSIDIAN:0)
Block(-4,24,5,OBSIDIAN:0)
Block(-4,24,6,OBSIDIAN:0)
Block(-4,24,7,OBSIDIAN:0)
Block(-4,25,-6,OBSIDIAN:0)
Block(-4,25,-5,OBSIDIAN:0)
Block(-4,25,-4,OBSIDIAN:0)
Block(-4,25,-3,OBSIDIAN:0)
Block(-4,25,-2,STAINED_CLAY:3)
Block(-4,25,-1,STAINED_CLAY:3)
Block(-4,25,0,STAINED_CLAY:3)
Block(-4,25,1,STAINED_CLAY:3)
Block(-4,25,2,STAINED_CLAY:3)
Block(-4,25,3,OBSIDIAN:0)
Block(-4,25,4,OBSIDIAN:0)
Block(-4,25,5,OBSIDIAN:0)
Block(-4,25,6,OBSIDIAN:0)
Block(-4,25,7,OBSIDIAN:0)
Block(-4,26,-6,OBSIDIAN:0)
Block(-4,26,-5,OBSIDIAN:0)
Block(-4,26,-4,OBSIDIAN:0)
Block(-4,26,-3,STAINED_CLAY:3)
Block(-4,26,-2,STAINED_CLAY:3)
Block(-4,26,-1,STAINED_CLAY:3)
Block(-4,26,0,STAINED_CLAY:3)
Block(-4,26,1,STAINED_CLAY:3)
Block(-4,26,2,STAINED_CLAY:3)
Block(-4,26,3,OBSIDIAN:0)
Block(-4,26,4,OBSIDIAN:0)
Block(-4,26,5,OBSIDIAN:0)
Block(-4,26,6,OBSIDIAN:0)
Block(-4,27,-6,STAINED_CLAY:3)
Block(-4,27,-5,STAINED_CLAY:3)
Block(-4,27,-4,STAINED_CLAY:3)
Block(-4,27,-3,STAINED_CLAY:3)
Block(-4,27,-2,STAINED_CLAY:3)
Block(-4,27,-1,STAINED_CLAY:3)
Block(-4,27,0,STAINED_CLAY:3)
Block(-4,27,1,STAINED_CLAY:3)
Block(-4,27,2,STAINED_CLAY:3)
Block(-4,27,3,OBSIDIAN:0)
Block(-4,27,4,OBSIDIAN:0)
Block(-4,27,5,OBSIDIAN:0)
Block(-4,27,6,OBSIDIAN:0)
Block(-4,28,-7,STAINED_CLAY:3)
Block(-4,28,-6,STAINED_CLAY:3)
Block(-4,28,-5,STAINED_CLAY:3)
Block(-4,28,-4,STAINED_CLAY:3)
Block(-4,28,-3,STAINED_CLAY:3)
Block(-4,28,-2,STAINED_CLAY:3)
Block(-4,28,-1,STAINED_CLAY:3)
Block(-4,28,0,STAINED_CLAY:3)
Block(-4,28,1,STAINED_CLAY:3)
Block(-4,28,2,OBSIDIAN:0)
Block(-4,28,3,OBSIDIAN:0)
Block(-4,28,4,OBSIDIAN:0)
Block(-4,28,5,OBSIDIAN:0)
Block(-4,28,6,OBSIDIAN:0)
Block(-4,29,-7,STAINED_CLAY:3)
Block(-4,29,-6,STAINED_CLAY:3)
Block(-4,29,-5,STAINED_CLAY:3)
Block(-4,29,-4,STAINED_CLAY:3)
Block(-4,29,-3,STAINED_CLAY:3)
Block(-4,29,-2,STAINED_CLAY:3)
Block(-4,29,-1,STAINED_CLAY:3)
Block(-4,29,0,STAINED_CLAY:3)
Block(-4,29,1,OBSIDIAN:0)
Block(-4,29,2,OBSIDIAN:0)
Block(-4,29,3,OBSIDIAN:0)
Block(-4,29,4,OBSIDIAN:0)
Block(-4,29,5,OBSIDIAN:0)
Block(-4,30,-7,STAINED_CLAY:3)
Block(-4,30,-6,STAINED_CLAY:3)
Block(-4,30,-5,STAINED_CLAY:3)
Block(-4,30,-4,STAINED_CLAY:3)
Block(-4,30,-3,STAINED_CLAY:3)
Block(-4,30,-2,STAINED_CLAY:3)
Block(-4,30,-1,STAINED_CLAY:3)
Block(-4,30,0,STAINED_CLAY:3)
Block(-4,30,1,OBSIDIAN:0)
Block(-4,30,2,OBSIDIAN:0)
Block(-4,30,3,OBSIDIAN:0)
Block(-4,30,4,OBSIDIAN:0)
Block(-4,30,5,OBSIDIAN:0)
Block(-4,31,-7,STAINED_CLAY:3)
Block(-4,31,-6,STAINED_CLAY:3)
Block(-4,31,-5,STAINED_CLAY:3)
Block(-4,31,-4,STAINED_CLAY:3)
Block(-4,31,-3,STAINED_CLAY:3)
Block(-4,31,-2,STAINED_CLAY:3)
Block(-4,31,-1,STAINED_CLAY:3)
Block(-4,31,0,STAINED_CLAY:3)
Block(-4,31,1,OBSIDIAN:0)
Block(-4,31,2,OBSIDIAN:0)
Block(-4,31,3,OBSIDIAN:0)
Block(-4,31,4,OBSIDIAN:0)
Block(-4,32,-7,STAINED_CLAY:3)
Block(-4,32,-6,STAINED_CLAY:3)
Block(-4,32,-5,STAINED_CLAY:3)
Block(-4,32,-4,STAINED_CLAY:3)
Block(-4,32,-3,STAINED_CLAY:3)
Block(-4,32,-2,STAINED_CLAY:3)
Block(-4,32,-1,STAINED_CLAY:3)
Block(-4,32,0,STAINED_CLAY:3)
Block(-4,32,1,STAINED_CLAY:3)
Block(-4,32,2,OBSIDIAN:0)
Block(-4,32,3,OBSIDIAN:0)
Block(-4,32,4,OBSIDIAN:0)
Block(-4,33,-7,STAINED_CLAY:3)
Block(-4,33,-6,STAINED_CLAY:3)
Block(-4,33,-5,STAINED_CLAY:3)
Block(-4,33,-4,STAINED_CLAY:3)
Block(-4,33,-3,STAINED_CLAY:3)
Block(-4,33,-2,STAINED_CLAY:3)
Block(-4,33,-1,STAINED_CLAY:3)
Block(-4,33,0,STAINED_CLAY:3)
Block(-4,33,1,STAINED_CLAY:3)
Block(-4,33,2,OBSIDIAN:0)
Block(-4,33,3,OBSIDIAN:0)
Block(-4,33,4,OBSIDIAN:0)
Block(-4,34,-7,STAINED_CLAY:3)
Block(-4,34,-6,STAINED_CLAY:3)
Block(-4,34,-5,STAINED_CLAY:3)
Block(-4,34,-4,STAINED_CLAY:3)
Block(-4,34,-3,STAINED_CLAY:3)
Block(-4,34,-2,STAINED_CLAY:3)
Block(-4,34,-1,STAINED_CLAY:3)
Block(-4,34,0,STAINED_CLAY:3)
Block(-4,34,1,STAINED_CLAY:3)
Block(-4,34,2,OBSIDIAN:0)
Block(-4,34,3,OBSIDIAN:0)
Block(-4,35,-7,STAINED_CLAY:3)
Block(-4,35,-6,STAINED_CLAY:3)
Block(-4,35,-5,STAINED_CLAY:3)
Block(-4,35,-4,STAINED_CLAY:3)
Block(-4,35,-3,STAINED_CLAY:3)
Block(-4,35,-2,STAINED_CLAY:3)
Block(-4,35,-1,STAINED_CLAY:3)
Block(-4,35,0,STAINED_CLAY:3)
Block(-4,35,1,STAINED_CLAY:3)
Block(-4,35,2,STAINED_CLAY:3)
Block(-4,35,3,STAINED_CLAY:3)
Block(-4,36,-7,STAINED_CLAY:3)
Block(-4,36,-6,STAINED_CLAY:3)
Block(-4,36,-5,STAINED_CLAY:3)
Block(-4,36,-4,STAINED_CLAY:3)
Block(-4,36,-3,STAINED_CLAY:3)
Block(-4,36,-2,STAINED_CLAY:3)
Block(-4,36,-1,STAINED_CLAY:3)
Block(-4,36,0,STAINED_CLAY:3)
Block(-4,36,1,STAINED_CLAY:3)
Block(-4,36,2,STAINED_CLAY:3)
Block(-4,36,3,STAINED_CLAY:3)
Block(-4,37,-7,STAINED_CLAY:3)
Block(-4,37,-6,STAINED_CLAY:3)
Block(-4,37,-5,STAINED_CLAY:3)
Block(-4,37,-4,STAINED_CLAY:3)
Block(-4,37,-3,STAINED_CLAY:3)
Block(-4,37,-2,STAINED_CLAY:3)
Block(-4,37,-1,STAINED_CLAY:3)
Block(-4,37,0,STAINED_CLAY:3)
Block(-4,37,1,STAINED_CLAY:3)
Block(-4,37,2,STAINED_CLAY:3)
Block(-4,38,-7,OBSIDIAN:0)
Block(-4,38,-6,STAINED_CLAY:3)
Block(-4,38,-5,STAINED_CLAY:3)
Block(-4,38,-4,STAINED_CLAY:3)
Block(-4,38,-3,STAINED_CLAY:3)
Block(-4,38,-2,STAINED_CLAY:3)
Block(-4,38,-1,STAINED_CLAY:3)
Block(-4,38,0,STAINED_CLAY:3)
Block(-4,38,1,STAINED_CLAY:3)
Block(-4,38,2,STAINED_CLAY:3)
Block(-4,39,-7,OBSIDIAN:0)
Block(-4,39,-6,STAINED_CLAY:3)
Block(-4,39,-5,STAINED_CLAY:3)
Block(-4,39,-4,STAINED_CLAY:3)
Block(-4,39,-3,STAINED_CLAY:3)
Block(-4,39,-2,STAINED_CLAY:3)
Block(-4,39,-1,STAINED_CLAY:3)
Block(-4,39,0,STAINED_CLAY:3)
Block(-4,39,1,STAINED_CLAY:3)
Block(-4,39,2,STAINED_CLAY:3)
Block(-4,40,-7,OBSIDIAN:0)
Block(-4,40,-6,STAINED_CLAY:3)
Block(-4,40,-5,STAINED_CLAY:3)
Block(-4,40,-4,STAINED_CLAY:3)
Block(-4,40,-3,STAINED_CLAY:3)
Block(-4,40,-2,STAINED_CLAY:3)
Block(-4,40,-1,STAINED_CLAY:3)
Block(-4,40,0,STAINED_CLAY:3)
Block(-4,40,1,STAINED_CLAY:3)
Block(-4,41,-7,OBSIDIAN:0)
Block(-4,41,-6,OBSIDIAN:0)
Block(-4,41,-5,STAINED_CLAY:3)
Block(-4,41,-4,STAINED_CLAY:3)
Block(-4,41,-3,STAINED_CLAY:3)
Block(-4,41,-2,STAINED_CLAY:3)
Block(-4,41,-1,STAINED_CLAY:3)
Block(-4,41,0,STAINED_CLAY:3)
Block(-4,41,1,STAINED_CLAY:3)
Block(-4,42,-7,OBSIDIAN:0)
Block(-4,42,-6,OBSIDIAN:0)
Block(-4,42,-5,STAINED_CLAY:3)
Block(-4,42,-4,STAINED_CLAY:3)
Block(-4,42,-3,STAINED_CLAY:3)
Block(-4,42,-2,STAINED_CLAY:3)
Block(-4,42,-1,STAINED_CLAY:3)
Block(-4,42,0,STAINED_CLAY:3)
Block(-4,43,-7,OBSIDIAN:0)
Block(-4,43,-6,OBSIDIAN:0)
Block(-4,43,-5,STAINED_CLAY:3)
Block(-4,43,-4,STAINED_CLAY:3)
Block(-4,43,-3,STAINED_CLAY:3)
Block(-4,43,-2,STAINED_CLAY:3)
Block(-4,43,-1,STAINED_CLAY:3)
Block(-4,43,0,STAINED_CLAY:3)
Block(-4,44,-7,OBSIDIAN:0)
Block(-4,44,-6,OBSIDIAN:0)
Block(-4,44,-5,STAINED_CLAY:3)
Block(-4,44,-4,STAINED_CLAY:3)
Block(-4,44,-3,STAINED_CLAY:3)
Block(-4,44,-2,STAINED_CLAY:3)
Block(-4,44,-1,STAINED_CLAY:3)
Block(-4,44,0,STAINED_CLAY:3)
Block(-4,45,-7,OBSIDIAN:0)
Block(-4,45,-6,OBSIDIAN:0)
Block(-4,45,-5,STAINED_CLAY:3)
Block(-4,45,-4,STAINED_CLAY:3)
Block(-4,45,-3,STAINED_CLAY:3)
Block(-4,45,-2,STAINED_CLAY:3)
Block(-4,45,-1,STAINED_CLAY:3)
Block(-4,46,-7,OBSIDIAN:0)
Block(-4,46,-6,OBSIDIAN:0)
Block(-4,46,-5,STAINED_CLAY:3)
Block(-4,46,-4,STAINED_CLAY:3)
Block(-4,46,-3,STAINED_CLAY:3)
Block(-4,46,-2,STAINED_CLAY:3)
Block(-4,46,-1,STAINED_CLAY:3)
Block(-4,47,-7,STAINED_CLAY:3)
Block(-4,47,-6,STAINED_CLAY:3)
Block(-4,47,-5,STAINED_CLAY:3)
Block(-4,47,-4,STAINED_CLAY:3)
Block(-4,47,-3,STAINED_CLAY:3)
Block(-4,47,-2,STAINED_CLAY:3)
Block(-4,47,-1,STAINED_CLAY:3)
Block(-4,48,-7,STAINED_CLAY:3)
Block(-4,48,-6,STAINED_CLAY:3)
Block(-4,48,-5,STAINED_CLAY:3)
Block(-4,48,-4,STAINED_CLAY:3)
Block(-4,48,-3,STAINED_CLAY:3)
Block(-4,48,-2,STAINED_CLAY:3)
Block(-4,49,-7,STAINED_CLAY:3)
Block(-4,49,-6,STAINED_CLAY:3)
Block(-4,49,-5,STAINED_CLAY:3)
Block(-4,49,-4,STAINED_CLAY:3)
Block(-4,49,-3,STAINED_CLAY:3)
Block(-4,49,-2,STAINED_CLAY:3)
Block(-4,50,-7,STAINED_CLAY:3)
Block(-4,50,-6,STAINED_CLAY:3)
Block(-4,50,-5,STAINED_CLAY:3)
Block(-4,50,-4,STAINED_CLAY:3)
