
#######################################################################
# +-----------------------------------------------------------------+ #
# |                            BO4 object                           | #
# +-----------------------------------------------------------------+ #
#######################################################################

Author: NLBlackEagle

Description: No description given

SettingsMode: WriteDisable


#######################################################################
# +-----------------------------------------------------------------+ #
# |                          Main settings                          | #
# +-----------------------------------------------------------------+ #
#######################################################################

Frequency: 0

SpawnHeight: highestBlock

UseCenterForHighestBlock: true

##############################
# Height Limits for the BO4. #
##############################

MinHeight: 0

MaxHeight: 255

InheritBO3: 

InheritBO3Rotation: NORTH

OverrideChildSettings: true

OverrideParentHeight: false

CanOverride: true

BranchFrequency: 0

BranchFrequencyGroup: 

MustBeBelowOther: false

MustBeInside: 

CannotBeInside: 

ReplacesBO3: 

MustBeInsideWorldBorders: false

CanSpawnOnWater: true

SpawnOnWaterOnly: false

SpawnUnderWater: false

SpawnAtWaterLevel: false

HeightOffset: 0

RemoveAir: true

ReplaceAbove: 

ReplaceBelow: 

ReplaceWithBiomeBlocks: true

ReplaceWithSurfaceBlock: GRASS

ReplaceWithGroundBlock: DIRT

ReplaceWithStoneBlock: STONE

SmoothRadius: 0

SmoothHeightOffset: 0

SmoothStartTop: false

SmoothStartWood: false

SmoothingSurfaceBlock: 

SmoothingGroundBlock: 

BO3Group: 

IsSpawnPoint: false

DoReplaceBlocks: true


#######################################################################
# +-----------------------------------------------------------------+ #
# |                              Blocks                             | #
# +-----------------------------------------------------------------+ #
#######################################################################

Block(-7,0,3,STAINED_CLAY:3)
Block(-7,0,4,STAINED_CLAY:3)
Block(-7,0,5,STAINED_CLAY:3)
Block(-7,0,6,STAINED_CLAY:3)
Block(-7,0,7,STAINED_CLAY:3)
Block(-7,0,8,STAINED_CLAY:3)
Block(-6,0,2,STAINED_CLAY:3)
Block(-6,0,3,STAINED_CLAY:3)
Block(-6,0,4,STAINED_CLAY:3)
Block(-6,0,5,STAINED_CLAY:3)
Block(-6,0,6,STAINED_CLAY:3)
Block(-6,0,7,STAINED_CLAY:3)
Block(-6,0,8,STAINED_CLAY:3)
Block(-6,1,2,STAINED_CLAY:3)
Block(-6,1,3,STAINED_CLAY:3)
Block(-6,1,4,STAINED_CLAY:3)
Block(-6,1,5,STAINED_CLAY:3)
Block(-6,1,6,STAINED_CLAY:3)
Block(-6,1,7,STAINED_CLAY:3)
Block(-6,1,8,STAINED_CLAY:3)
Block(-6,2,2,STAINED_CLAY:3)
Block(-6,2,3,STAINED_CLAY:3)
Block(-6,2,4,STAINED_CLAY:3)
Block(-6,2,5,STAINED_CLAY:3)
Block(-6,2,6,STAINED_CLAY:3)
Block(-6,2,7,STAINED_CLAY:3)
Block(-6,2,8,STAINED_CLAY:3)
Block(-6,3,2,STAINED_CLAY:3)
Block(-6,3,3,STAINED_CLAY:3)
Block(-6,3,4,STAINED_CLAY:3)
Block(-6,3,5,STAINED_CLAY:3)
Block(-6,3,6,STAINED_CLAY:3)
Block(-6,3,7,STAINED_CLAY:3)
Block(-6,3,8,STAINED_CLAY:3)
Block(-6,4,2,STAINED_CLAY:3)
Block(-6,4,3,STAINED_CLAY:3)
Block(-6,4,4,STAINED_CLAY:3)
Block(-6,4,5,STAINED_CLAY:3)
Block(-6,4,6,STAINED_CLAY:3)
Block(-6,4,7,STAINED_CLAY:3)
Block(-6,4,8,STAINED_CLAY:3)
Block(-5,0,1,STAINED_CLAY:3)
Block(-5,0,2,STAINED_CLAY:3)
Block(-5,0,3,STAINED_CLAY:3)
Block(-5,0,4,STAINED_CLAY:3)
Block(-5,0,5,STAINED_CLAY:3)
Block(-5,0,6,STAINED_CLAY:3)
Block(-5,0,7,STAINED_CLAY:3)
Block(-5,0,8,STAINED_CLAY:3)
Block(-5,1,1,STAINED_CLAY:3)
Block(-5,1,2,STAINED_CLAY:3)
Block(-5,1,3,STAINED_CLAY:3)
Block(-5,1,4,STAINED_CLAY:3)
Block(-5,1,5,STAINED_CLAY:3)
Block(-5,1,6,STAINED_CLAY:3)
Block(-5,1,7,STAINED_CLAY:3)
Block(-5,1,8,STAINED_CLAY:3)
Block(-5,2,1,STAINED_CLAY:3)
Block(-5,2,2,STAINED_CLAY:3)
Block(-5,2,3,STAINED_CLAY:3)
Block(-5,2,4,STAINED_CLAY:3)
Block(-5,2,5,STAINED_CLAY:3)
Block(-5,2,6,STAINED_CLAY:3)
Block(-5,2,7,STAINED_CLAY:3)
Block(-5,2,8,STAINED_CLAY:3)
Block(-5,3,1,STAINED_CLAY:3)
Block(-5,3,2,STAINED_CLAY:3)
Block(-5,3,3,STAINED_CLAY:3)
Block(-5,3,4,STAINED_CLAY:3)
Block(-5,3,5,STAINED_CLAY:3)
Block(-5,3,6,STAINED_CLAY:3)
Block(-5,3,7,STAINED_CLAY:3)
Block(-5,3,8,STAINED_CLAY:3)
Block(-5,4,1,STAINED_CLAY:3)
Block(-5,4,2,STAINED_CLAY:3)
Block(-5,4,3,STAINED_CLAY:3)
Block(-5,4,4,STAINED_CLAY:3)
Block(-5,4,5,STAINED_CLAY:3)
Block(-5,4,6,STAINED_CLAY:3)
Block(-5,4,7,STAINED_CLAY:3)
Block(-5,4,8,STAINED_CLAY:3)
Block(-5,5,1,STAINED_CLAY:3)
Block(-5,5,2,STAINED_CLAY:3)
Block(-5,5,3,STAINED_CLAY:3)
Block(-5,5,4,STAINED_CLAY:3)
Block(-5,5,5,STAINED_CLAY:3)
Block(-5,5,6,STAINED_CLAY:3)
Block(-5,5,7,STAINED_CLAY:3)
Block(-5,5,8,STAINED_CLAY:3)
Block(-5,6,1,STAINED_CLAY:3)
Block(-5,6,2,STAINED_CLAY:3)
Block(-5,6,3,STAINED_CLAY:3)
Block(-5,6,4,STAINED_CLAY:3)
Block(-5,6,5,STAINED_CLAY:3)
Block(-5,6,6,STAINED_CLAY:3)
Block(-5,6,7,STAINED_CLAY:3)
Block(-5,6,8,STAINED_CLAY:3)
Block(-5,7,1,STAINED_CLAY:3)
Block(-5,7,2,STAINED_CLAY:3)
Block(-5,7,3,STAINED_CLAY:3)
Block(-5,7,4,STAINED_CLAY:3)
Block(-5,7,5,STAINED_CLAY:3)
Block(-5,7,6,STAINED_CLAY:3)
Block(-5,7,7,STAINED_CLAY:3)
Block(-5,7,8,STAINED_CLAY:3)
Block(-5,8,1,STAINED_CLAY:3)
Block(-5,8,2,STAINED_CLAY:3)
Block(-5,8,3,STAINED_CLAY:3)
Block(-5,8,4,STAINED_CLAY:3)
Block(-5,8,5,STAINED_CLAY:3)
Block(-5,8,6,STAINED_CLAY:3)
Block(-5,8,7,STAINED_CLAY:3)
Block(-5,8,8,STAINED_CLAY:3)
Block(-5,9,1,STAINED_CLAY:3)
Block(-5,9,2,STAINED_CLAY:3)
Block(-5,9,3,STAINED_CLAY:3)
Block(-5,9,4,STAINED_CLAY:3)
Block(-5,9,5,STAINED_CLAY:3)
Block(-5,9,6,STAINED_CLAY:3)
Block(-5,9,7,STAINED_CLAY:3)
Block(-5,9,8,STAINED_CLAY:3)
Block(-4,0,0,OBSIDIAN:0)
Block(-4,0,1,STAINED_CLAY:3)
Block(-4,0,2,STAINED_CLAY:3)
Block(-4,0,3,STAINED_CLAY:3)
Block(-4,0,4,STAINED_CLAY:3)
Block(-4,0,5,STAINED_CLAY:3)
Block(-4,0,6,STAINED_CLAY:3)
Block(-4,0,7,STAINED_CLAY:3)
Block(-4,0,8,STAINED_CLAY:3)
Block(-4,1,0,OBSIDIAN:0)
Block(-4,1,1,STAINED_CLAY:3)
Block(-4,1,2,STAINED_CLAY:3)
Block(-4,1,3,STAINED_CLAY:3)
Block(-4,1,4,STAINED_CLAY:3)
Block(-4,1,5,STAINED_CLAY:3)
Block(-4,1,6,STAINED_CLAY:3)
Block(-4,1,7,STAINED_CLAY:3)
Block(-4,1,8,STAINED_CLAY:3)
Block(-4,2,0,OBSIDIAN:0)
Block(-4,2,1,STAINED_CLAY:3)
Block(-4,2,2,STAINED_CLAY:3)
Block(-4,2,3,STAINED_CLAY:3)
Block(-4,2,4,STAINED_CLAY:3)
Block(-4,2,5,STAINED_CLAY:3)
Block(-4,2,6,STAINED_CLAY:3)
Block(-4,2,7,STAINED_CLAY:3)
Block(-4,2,8,STAINED_CLAY:3)
Block(-4,3,0,OBSIDIAN:0)
Block(-4,3,1,STAINED_CLAY:3)
Block(-4,3,2,STAINED_CLAY:3)
Block(-4,3,3,STAINED_CLAY:3)
Block(-4,3,4,STAINED_CLAY:3)
Block(-4,3,5,STAINED_CLAY:3)
Block(-4,3,6,STAINED_CLAY:3)
Block(-4,3,7,STAINED_CLAY:3)
Block(-4,3,8,STAINED_CLAY:3)
Block(-4,4,0,STAINED_CLAY:3)
Block(-4,4,1,STAINED_CLAY:3)
Block(-4,4,2,STAINED_CLAY:3)
Block(-4,4,3,STAINED_CLAY:3)
Block(-4,4,4,STAINED_CLAY:3)
Block(-4,4,5,STAINED_CLAY:3)
Block(-4,4,6,STAINED_CLAY:3)
Block(-4,4,7,STAINED_CLAY:3)
Block(-4,4,8,STAINED_CLAY:3)
Block(-4,5,0,STAINED_CLAY:3)
Block(-4,5,1,STAINED_CLAY:3)
Block(-4,5,2,STAINED_CLAY:3)
Block(-4,5,3,STAINED_CLAY:3)
Block(-4,5,4,STAINED_CLAY:3)
Block(-4,5,5,STAINED_CLAY:3)
Block(-4,5,6,STAINED_CLAY:3)
Block(-4,5,7,STAINED_CLAY:3)
Block(-4,5,8,STAINED_CLAY:3)
Block(-4,6,0,STAINED_CLAY:3)
Block(-4,6,1,STAINED_CLAY:3)
Block(-4,6,2,STAINED_CLAY:3)
Block(-4,6,3,STAINED_CLAY:3)
Block(-4,6,4,STAINED_CLAY:3)
Block(-4,6,5,STAINED_CLAY:3)
Block(-4,6,6,STAINED_CLAY:3)
Block(-4,6,7,STAINED_CLAY:3)
Block(-4,6,8,STAINED_CLAY:3)
Block(-4,7,0,STAINED_CLAY:3)
Block(-4,7,1,STAINED_CLAY:3)
Block(-4,7,2,STAINED_CLAY:3)
Block(-4,7,3,STAINED_CLAY:3)
Block(-4,7,4,STAINED_CLAY:3)
Block(-4,7,5,STAINED_CLAY:3)
Block(-4,7,6,STAINED_CLAY:3)
Block(-4,7,7,STAINED_CLAY:3)
Block(-4,7,8,STAINED_CLAY:3)
Block(-4,8,0,STAINED_CLAY:3)
Block(-4,8,1,STAINED_CLAY:3)
Block(-4,8,2,STAINED_CLAY:3)
Block(-4,8,3,STAINED_CLAY:3)
Block(-4,8,4,STAINED_CLAY:3)
Block(-4,8,5,STAINED_CLAY:3)
Block(-4,8,6,STAINED_CLAY:3)
Block(-4,8,7,STAINED_CLAY:3)
Block(-4,8,8,STAINED_CLAY:3)
Block(-4,9,0,STAINED_CLAY:3)
Block(-4,9,1,STAINED_CLAY:3)
Block(-4,9,2,STAINED_CLAY:3)
Block(-4,9,3,STAINED_CLAY:3)
Block(-4,9,4,STAINED_CLAY:3)
Block(-4,9,5,STAINED_CLAY:3)
Block(-4,9,6,STAINED_CLAY:3)
Block(-4,9,7,STAINED_CLAY:3)
Block(-4,9,8,STAINED_CLAY:3)
Block(-4,10,0,STAINED_CLAY:3)
Block(-4,10,1,STAINED_CLAY:3)
Block(-4,10,2,STAINED_CLAY:3)
Block(-4,10,3,STAINED_CLAY:3)
Block(-4,10,4,STAINED_CLAY:3)
Block(-4,10,5,STAINED_CLAY:3)
Block(-4,10,6,STAINED_CLAY:3)
Block(-4,10,7,STAINED_CLAY:3)
Block(-4,10,8,STAINED_CLAY:3)
Block(-4,11,0,STAINED_CLAY:3)
Block(-4,11,1,STAINED_CLAY:3)
Block(-4,11,2,STAINED_CLAY:3)
Block(-4,11,3,STAINED_CLAY:3)
Block(-4,11,4,STAINED_CLAY:3)
Block(-4,11,5,STAINED_CLAY:3)
Block(-4,11,6,STAINED_CLAY:3)
Block(-4,11,7,STAINED_CLAY:3)
Block(-4,11,8,STAINED_CLAY:3)
Block(-4,12,0,STAINED_CLAY:3)
Block(-4,12,1,STAINED_CLAY:3)
Block(-4,12,2,STAINED_CLAY:3)
Block(-4,12,3,STAINED_CLAY:3)
Block(-4,12,4,STAINED_CLAY:3)
Block(-4,12,5,STAINED_CLAY:3)
Block(-4,12,6,STAINED_CLAY:3)
Block(-4,12,7,STAINED_CLAY:3)
Block(-4,12,8,OBSIDIAN:0)
Block(-4,13,0,STAINED_CLAY:3)
Block(-4,13,1,STAINED_CLAY:3)
Block(-4,13,2,STAINED_CLAY:3)
Block(-4,13,3,STAINED_CLAY:3)
Block(-4,13,4,STAINED_CLAY:3)
Block(-4,13,5,STAINED_CLAY:3)
Block(-4,13,6,STAINED_CLAY:3)
Block(-4,13,7,OBSIDIAN:0)
Block(-4,13,8,OBSIDIAN:0)
Block(-3,0,-1,OBSIDIAN:0)
Block(-3,0,0,OBSIDIAN:0)
Block(-3,0,1,OBSIDIAN:0)
Block(-3,0,2,STAINED_CLAY:3)
Block(-3,0,3,STAINED_CLAY:3)
Block(-3,0,4,STAINED_CLAY:3)
Block(-3,0,5,STAINED_CLAY:3)
Block(-3,0,6,STAINED_CLAY:3)
Block(-3,0,7,STAINED_CLAY:3)
Block(-3,0,8,STAINED_CLAY:3)
Block(-3,1,-1,OBSIDIAN:0)
Block(-3,1,0,OBSIDIAN:0)
Block(-3,1,1,OBSIDIAN:0)
Block(-3,1,2,STAINED_CLAY:3)
Block(-3,1,3,STAINED_CLAY:3)
Block(-3,1,4,STAINED_CLAY:3)
Block(-3,1,5,STAINED_CLAY:3)
Block(-3,1,6,STAINED_CLAY:3)
Block(-3,1,7,STAINED_CLAY:3)
Block(-3,1,8,STAINED_CLAY:3)
Block(-3,2,-1,OBSIDIAN:0)
Block(-3,2,0,OBSIDIAN:0)
Block(-3,2,1,OBSIDIAN:0)
Block(-3,2,2,STAINED_CLAY:3)
Block(-3,2,3,STAINED_CLAY:3)
Block(-3,2,4,STAINED_CLAY:3)
Block(-3,2,5,STAINED_CLAY:3)
Block(-3,2,6,STAINED_CLAY:3)
Block(-3,2,7,STAINED_CLAY:3)
Block(-3,2,8,STAINED_CLAY:3)
Block(-3,3,-1,OBSIDIAN:0)
Block(-3,3,0,OBSIDIAN:0)
Block(-3,3,1,STAINED_CLAY:3)
Block(-3,3,2,STAINED_CLAY:3)
Block(-3,3,3,STAINED_CLAY:3)
Block(-3,3,4,STAINED_CLAY:3)
Block(-3,3,5,STAINED_CLAY:3)
Block(-3,3,6,STAINED_CLAY:3)
Block(-3,3,7,STAINED_CLAY:3)
Block(-3,3,8,STAINED_CLAY:3)
Block(-3,4,-1,OBSIDIAN:0)
Block(-3,4,0,STAINED_CLAY:3)
Block(-3,4,1,STAINED_CLAY:3)
Block(-3,4,2,STAINED_CLAY:3)
Block(-3,4,3,STAINED_CLAY:3)
Block(-3,4,4,STAINED_CLAY:3)
Block(-3,4,5,STAINED_CLAY:3)
Block(-3,4,6,STAINED_CLAY:3)
Block(-3,4,7,STAINED_CLAY:3)
Block(-3,4,8,STAINED_CLAY:3)
Block(-3,5,-1,STAINED_CLAY:3)
Block(-3,5,0,STAINED_CLAY:3)
Block(-3,5,1,STAINED_CLAY:3)
Block(-3,5,2,STAINED_CLAY:3)
Block(-3,5,3,STAINED_CLAY:3)
Block(-3,5,4,STAINED_CLAY:3)
Block(-3,5,5,STAINED_CLAY:3)
Block(-3,5,6,STAINED_CLAY:3)
Block(-3,5,7,STAINED_CLAY:3)
Block(-3,5,8,STAINED_CLAY:3)
Block(-3,6,-1,STAINED_CLAY:3)
Block(-3,6,0,STAINED_CLAY:3)
Block(-3,6,1,STAINED_CLAY:3)
Block(-3,6,2,STAINED_CLAY:3)
Block(-3,6,3,STAINED_CLAY:3)
Block(-3,6,4,STAINED_CLAY:3)
Block(-3,6,5,STAINED_CLAY:3)
Block(-3,6,6,STAINED_CLAY:3)
Block(-3,6,7,STAINED_CLAY:3)
Block(-3,6,8,STAINED_CLAY:3)
Block(-3,7,-1,STAINED_CLAY:3)
Block(-3,7,0,STAINED_CLAY:3)
Block(-3,7,1,STAINED_CLAY:3)
Block(-3,7,2,STAINED_CLAY:3)
Block(-3,7,3,STAINED_CLAY:3)
Block(-3,7,4,STAINED_CLAY:3)
Block(-3,7,5,STAINED_CLAY:3)
Block(-3,7,6,STAINED_CLAY:3)
Block(-3,7,7,STAINED_CLAY:3)
Block(-3,7,8,STAINED_CLAY:3)
Block(-3,8,-1,STAINED_CLAY:3)
Block(-3,8,0,STAINED_CLAY:3)
Block(-3,8,1,STAINED_CLAY:3)
Block(-3,8,2,STAINED_CLAY:3)
Block(-3,8,3,STAINED_CLAY:3)
Block(-3,8,4,STAINED_CLAY:3)
Block(-3,8,5,STAINED_CLAY:3)
Block(-3,8,6,STAINED_CLAY:3)
Block(-3,8,7,STAINED_CLAY:3)
Block(-3,8,8,STAINED_CLAY:3)
Block(-3,9,-1,STAINED_CLAY:3)
Block(-3,9,0,STAINED_CLAY:3)
Block(-3,9,1,STAINED_CLAY:3)
Block(-3,9,2,STAINED_CLAY:3)
Block(-3,9,3,STAINED_CLAY:3)
Block(-3,9,4,STAINED_CLAY:3)
Block(-3,9,5,STAINED_CLAY:3)
Block(-3,9,6,STAINED_CLAY:3)
Block(-3,9,7,STAINED_CLAY:3)
Block(-3,9,8,STAINED_CLAY:3)
Block(-3,10,-1,STAINED_CLAY:3)
Block(-3,10,0,STAINED_CLAY:3)
Block(-3,10,1,STAINED_CLAY:3)
Block(-3,10,2,STAINED_CLAY:3)
Block(-3,10,3,STAINED_CLAY:3)
Block(-3,10,4,STAINED_CLAY:3)
Block(-3,10,5,STAINED_CLAY:3)
Block(-3,10,6,STAINED_CLAY:3)
Block(-3,10,7,STAINED_CLAY:3)
Block(-3,10,8,STAINED_CLAY:3)
Block(-3,11,-1,STAINED_CLAY:3)
Block(-3,11,0,STAINED_CLAY:3)
Block(-3,11,1,STAINED_CLAY:3)
Block(-3,11,2,STAINED_CLAY:3)
Block(-3,11,3,STAINED_CLAY:3)
Block(-3,11,4,STAINED_CLAY:3)
Block(-3,11,5,STAINED_CLAY:3)
Block(-3,11,6,STAINED_CLAY:3)
Block(-3,11,7,STAINED_CLAY:3)
Block(-3,11,8,STAINED_CLAY:3)
Block(-3,12,-1,STAINED_CLAY:3)
Block(-3,12,0,STAINED_CLAY:3)
Block(-3,12,1,STAINED_CLAY:3)
Block(-3,12,2,STAINED_CLAY:3)
Block(-3,12,3,STAINED_CLAY:3)
Block(-3,12,4,STAINED_CLAY:3)
Block(-3,12,5,STAINED_CLAY:3)
Block(-3,12,6,STAINED_CLAY:3)
Block(-3,12,7,STAINED_CLAY:3)
Block(-3,12,8,OBSIDIAN:0)
Block(-3,13,-1,STAINED_CLAY:3)
Block(-3,13,0,STAINED_CLAY:3)
Block(-3,13,1,STAINED_CLAY:3)
Block(-3,13,2,STAINED_CLAY:3)
Block(-3,13,3,STAINED_CLAY:3)
Block(-3,13,4,STAINED_CLAY:3)
Block(-3,13,5,STAINED_CLAY:3)
Block(-3,13,6,STAINED_CLAY:3)
Block(-3,13,7,OBSIDIAN:0)
Block(-3,13,8,OBSIDIAN:0)
Block(-3,14,-1,STAINED_CLAY:3)
Block(-3,14,0,STAINED_CLAY:3)
Block(-3,14,1,STAINED_CLAY:3)
Block(-3,14,2,STAINED_CLAY:3)
Block(-3,14,3,STAINED_CLAY:3)
Block(-3,14,4,STAINED_CLAY:3)
Block(-3,14,5,STAINED_CLAY:3)
Block(-3,14,6,OBSIDIAN:0)
Block(-3,14,7,OBSIDIAN:0)
Block(-3,14,8,OBSIDIAN:0)
Block(-3,15,-1,STAINED_CLAY:3)
Block(-3,15,0,STAINED_CLAY:3)
Block(-3,15,1,STAINED_CLAY:3)
Block(-3,15,2,STAINED_CLAY:3)
Block(-3,15,3,STAINED_CLAY:3)
Block(-3,15,4,STAINED_CLAY:3)
Block(-3,15,5,STAINED_CLAY:3)
Block(-3,15,6,OBSIDIAN:0)
Block(-3,15,7,OBSIDIAN:0)
Block(-3,15,8,OBSIDIAN:0)
Block(-3,16,-1,STAINED_CLAY:3)
Block(-3,16,0,STAINED_CLAY:3)
Block(-3,16,1,STAINED_CLAY:3)
Block(-3,16,2,STAINED_CLAY:3)
Block(-3,16,3,STAINED_CLAY:3)
Block(-3,16,4,STAINED_CLAY:3)
Block(-3,16,5,OBSIDIAN:0)
Block(-3,16,6,OBSIDIAN:0)
Block(-3,16,7,OBSIDIAN:0)
Block(-3,16,8,OBSIDIAN:0)
Block(-3,17,-1,STAINED_CLAY:3)
Block(-3,17,0,STAINED_CLAY:3)
Block(-3,17,1,STAINED_CLAY:3)
Block(-3,17,2,STAINED_CLAY:3)
Block(-3,17,3,STAINED_CLAY:3)
Block(-3,17,4,OBSIDIAN:0)
Block(-3,17,5,OBSIDIAN:0)
Block(-3,17,6,OBSIDIAN:0)
Block(-3,17,7,OBSIDIAN:0)
Block(-3,17,8,OBSIDIAN:0)
Block(-3,18,-1,STAINED_CLAY:3)
Block(-3,18,0,STAINED_CLAY:3)
Block(-3,18,1,STAINED_CLAY:3)
Block(-3,18,2,STAINED_CLAY:3)
Block(-3,18,3,STAINED_CLAY:3)
Block(-3,18,4,OBSIDIAN:0)
Block(-3,18,5,OBSIDIAN:0)
Block(-3,18,6,OBSIDIAN:0)
Block(-3,18,7,OBSIDIAN:0)
Block(-3,18,8,OBSIDIAN:0)
Block(-2,0,-3,OBSIDIAN:0)
Block(-2,0,-2,OBSIDIAN:0)
Block(-2,0,-1,OBSIDIAN:0)
Block(-2,0,0,OBSIDIAN:0)
Block(-2,0,1,OBSIDIAN:0)
Block(-2,0,2,STAINED_CLAY:3)
Block(-2,0,3,STAINED_CLAY:3)
Block(-2,0,4,STAINED_CLAY:3)
Block(-2,0,5,STAINED_CLAY:3)
Block(-2,0,6,STAINED_CLAY:3)
Block(-2,0,7,STAINED_CLAY:3)
Block(-2,0,8,STAINED_CLAY:3)
Block(-2,1,-2,OBSIDIAN:0)
Block(-2,1,-1,OBSIDIAN:0)
Block(-2,1,0,OBSIDIAN:0)
Block(-2,1,1,OBSIDIAN:0)
Block(-2,1,2,STAINED_CLAY:3)
Block(-2,1,3,STAINED_CLAY:3)
Block(-2,1,4,STAINED_CLAY:3)
Block(-2,1,5,STAINED_CLAY:3)
Block(-2,1,6,STAINED_CLAY:3)
Block(-2,1,7,STAINED_CLAY:3)
Block(-2,1,8,STAINED_CLAY:3)
Block(-2,2,-2,OBSIDIAN:0)
Block(-2,2,-1,OBSIDIAN:0)
Block(-2,2,0,OBSIDIAN:0)
Block(-2,2,1,OBSIDIAN:0)
Block(-2,2,2,STAINED_CLAY:3)
Block(-2,2,3,STAINED_CLAY:3)
Block(-2,2,4,STAINED_CLAY:3)
Block(-2,2,5,STAINED_CLAY:3)
Block(-2,2,6,STAINED_CLAY:3)
Block(-2,2,7,STAINED_CLAY:3)
Block(-2,2,8,STAINED_CLAY:3)
Block(-2,3,-2,OBSIDIAN:0)
Block(-2,3,-1,OBSIDIAN:0)
Block(-2,3,0,OBSIDIAN:0)
Block(-2,3,1,STAINED_CLAY:3)
Block(-2,3,2,STAINED_CLAY:3)
Block(-2,3,3,STAINED_CLAY:3)
Block(-2,3,4,STAINED_CLAY:3)
Block(-2,3,5,STAINED_CLAY:3)
Block(-2,3,6,STAINED_CLAY:3)
Block(-2,3,7,STAINED_CLAY:3)
Block(-2,3,8,STAINED_CLAY:3)
Block(-2,4,-2,OBSIDIAN:0)
Block(-2,4,-1,OBSIDIAN:0)
Block(-2,4,0,STAINED_CLAY:3)
Block(-2,4,1,STAINED_CLAY:3)
Block(-2,4,2,STAINED_CLAY:3)
Block(-2,4,3,STAINED_CLAY:3)
Block(-2,4,4,STAINED_CLAY:3)
Block(-2,4,5,STAINED_CLAY:3)
Block(-2,4,6,STAINED_CLAY:3)
Block(-2,4,7,STAINED_CLAY:3)
Block(-2,4,8,STAINED_CLAY:3)
Block(-2,5,-2,STAINED_CLAY:3)
Block(-2,5,-1,STAINED_CLAY:3)
Block(-2,5,0,STAINED_CLAY:3)
Block(-2,5,1,STAINED_CLAY:3)
Block(-2,5,2,STAINED_CLAY:3)
Block(-2,5,3,STAINED_CLAY:3)
Block(-2,5,4,STAINED_CLAY:3)
Block(-2,5,5,STAINED_CLAY:3)
Block(-2,5,6,STAINED_CLAY:3)
Block(-2,5,7,STAINED_CLAY:3)
Block(-2,5,8,STAINED_CLAY:3)
Block(-2,6,-2,STAINED_CLAY:3)
Block(-2,6,-1,STAINED_CLAY:3)
Block(-2,6,0,STAINED_CLAY:3)
Block(-2,6,1,STAINED_CLAY:3)
Block(-2,6,2,STAINED_CLAY:3)
Block(-2,6,3,STAINED_CLAY:3)
Block(-2,6,4,STAINED_CLAY:3)
Block(-2,6,5,STAINED_CLAY:3)
Block(-2,6,6,STAINED_CLAY:3)
Block(-2,6,7,STAINED_CLAY:3)
Block(-2,6,8,STAINED_CLAY:3)
Block(-2,7,-2,STAINED_CLAY:3)
Block(-2,7,-1,STAINED_CLAY:3)
Block(-2,7,0,STAINED_CLAY:3)
Block(-2,7,1,STAINED_CLAY:3)
Block(-2,7,2,STAINED_CLAY:3)
Block(-2,7,3,STAINED_CLAY:3)
Block(-2,7,4,STAINED_CLAY:3)
Block(-2,7,5,STAINED_CLAY:3)
Block(-2,7,6,STAINED_CLAY:3)
Block(-2,7,7,STAINED_CLAY:3)
Block(-2,7,8,STAINED_CLAY:3)
Block(-2,8,-2,STAINED_CLAY:3)
Block(-2,8,-1,STAINED_CLAY:3)
Block(-2,8,0,STAINED_CLAY:3)
Block(-2,8,1,STAINED_CLAY:3)
Block(-2,8,2,STAINED_CLAY:3)
Block(-2,8,3,STAINED_CLAY:3)
Block(-2,8,4,STAINED_CLAY:3)
Block(-2,8,5,STAINED_CLAY:3)
Block(-2,8,6,STAINED_CLAY:3)
Block(-2,8,7,STAINED_CLAY:3)
Block(-2,8,8,STAINED_CLAY:3)
Block(-2,9,-2,STAINED_CLAY:3)
Block(-2,9,-1,STAINED_CLAY:3)
Block(-2,9,0,STAINED_CLAY:3)
Block(-2,9,1,STAINED_CLAY:3)
Block(-2,9,2,STAINED_CLAY:3)
Block(-2,9,3,STAINED_CLAY:3)
Block(-2,9,4,STAINED_CLAY:3)
Block(-2,9,5,STAINED_CLAY:3)
Block(-2,9,6,STAINED_CLAY:3)
Block(-2,9,7,STAINED_CLAY:3)
Block(-2,9,8,STAINED_CLAY:3)
Block(-2,10,-2,STAINED_CLAY:3)
Block(-2,10,-1,STAINED_CLAY:3)
Block(-2,10,0,STAINED_CLAY:3)
Block(-2,10,1,STAINED_CLAY:3)
Block(-2,10,2,STAINED_CLAY:3)
Block(-2,10,3,STAINED_CLAY:3)
Block(-2,10,4,STAINED_CLAY:3)
Block(-2,10,5,STAINED_CLAY:3)
Block(-2,10,6,STAINED_CLAY:3)
Block(-2,10,7,STAINED_CLAY:3)
Block(-2,10,8,OBSIDIAN:0)
Block(-2,11,-2,STAINED_CLAY:3)
Block(-2,11,-1,STAINED_CLAY:3)
Block(-2,11,0,STAINED_CLAY:3)
Block(-2,11,1,STAINED_CLAY:3)
Block(-2,11,2,STAINED_CLAY:3)
Block(-2,11,3,STAINED_CLAY:3)
Block(-2,11,4,STAINED_CLAY:3)
Block(-2,11,5,STAINED_CLAY:3)
Block(-2,11,6,STAINED_CLAY:3)
Block(-2,11,7,STAINED_CLAY:3)
Block(-2,11,8,OBSIDIAN:0)
Block(-2,12,-2,STAINED_CLAY:3)
Block(-2,12,-1,STAINED_CLAY:3)
Block(-2,12,0,STAINED_CLAY:3)
Block(-2,12,1,STAINED_CLAY:3)
Block(-2,12,2,STAINED_CLAY:3)
Block(-2,12,3,STAINED_CLAY:3)
Block(-2,12,4,STAINED_CLAY:3)
Block(-2,12,5,STAINED_CLAY:3)
Block(-2,12,6,STAINED_CLAY:3)
Block(-2,12,7,STAINED_CLAY:3)
Block(-2,12,8,OBSIDIAN:0)
Block(-2,13,-2,STAINED_CLAY:3)
Block(-2,13,-1,STAINED_CLAY:3)
Block(-2,13,0,STAINED_CLAY:3)
Block(-2,13,1,STAINED_CLAY:3)
Block(-2,13,2,STAINED_CLAY:3)
Block(-2,13,3,STAINED_CLAY:3)
Block(-2,13,4,STAINED_CLAY:3)
Block(-2,13,5,STAINED_CLAY:3)
Block(-2,13,6,STAINED_CLAY:3)
Block(-2,13,7,OBSIDIAN:0)
Block(-2,13,8,OBSIDIAN:0)
Block(-2,14,-2,STAINED_CLAY:3)
Block(-2,14,-1,STAINED_CLAY:3)
Block(-2,14,0,STAINED_CLAY:3)
Block(-2,14,1,STAINED_CLAY:3)
Block(-2,14,2,STAINED_CLAY:3)
Block(-2,14,3,STAINED_CLAY:3)
Block(-2,14,4,STAINED_CLAY:3)
Block(-2,14,5,STAINED_CLAY:3)
Block(-2,14,6,OBSIDIAN:0)
Block(-2,14,7,OBSIDIAN:0)
Block(-2,14,8,OBSIDIAN:0)
Block(-2,15,-2,STAINED_CLAY:3)
Block(-2,15,-1,STAINED_CLAY:3)
Block(-2,15,0,STAINED_CLAY:3)
Block(-2,15,1,STAINED_CLAY:3)
Block(-2,15,2,STAINED_CLAY:3)
Block(-2,15,3,STAINED_CLAY:3)
Block(-2,15,4,STAINED_CLAY:3)
Block(-2,15,5,STAINED_CLAY:3)
Block(-2,15,6,OBSIDIAN:0)
Block(-2,15,7,OBSIDIAN:0)
Block(-2,15,8,OBSIDIAN:0)
Block(-2,16,-2,STAINED_CLAY:3)
Block(-2,16,-1,STAINED_CLAY:3)
Block(-2,16,0,STAINED_CLAY:3)
Block(-2,16,1,STAINED_CLAY:3)
Block(-2,16,2,STAINED_CLAY:3)
Block(-2,16,3,STAINED_CLAY:3)
Block(-2,16,4,STAINED_CLAY:3)
Block(-2,16,5,OBSIDIAN:0)
Block(-2,16,6,OBSIDIAN:0)
Block(-2,16,7,OBSIDIAN:0)
Block(-2,16,8,OBSIDIAN:0)
Block(-2,17,-2,STAINED_CLAY:3)
Block(-2,17,-1,STAINED_CLAY:3)
Block(-2,17,0,STAINED_CLAY:3)
Block(-2,17,1,STAINED_CLAY:3)
Block(-2,17,2,STAINED_CLAY:3)
Block(-2,17,3,STAINED_CLAY:3)
Block(-2,17,4,OBSIDIAN:0)
Block(-2,17,5,OBSIDIAN:0)
Block(-2,17,6,OBSIDIAN:0)
Block(-2,17,7,OBSIDIAN:0)
Block(-2,17,8,OBSIDIAN:0)
Block(-2,18,-2,STAINED_CLAY:3)
Block(-2,18,-1,STAINED_CLAY:3)
Block(-2,18,0,STAINED_CLAY:3)
Block(-2,18,1,STAINED_CLAY:3)
Block(-2,18,2,STAINED_CLAY:3)
Block(-2,18,3,STAINED_CLAY:3)
Block(-2,18,4,OBSIDIAN:0)
Block(-2,18,5,OBSIDIAN:0)
Block(-2,18,6,OBSIDIAN:0)
Block(-2,18,7,OBSIDIAN:0)
Block(-2,18,8,OBSIDIAN:0)
Block(-2,19,-2,STAINED_CLAY:3)
Block(-2,19,-1,STAINED_CLAY:3)
Block(-2,19,0,STAINED_CLAY:3)
Block(-2,19,1,STAINED_CLAY:3)
Block(-2,19,2,STAINED_CLAY:3)
Block(-2,19,3,OBSIDIAN:0)
Block(-2,19,4,OBSIDIAN:0)
Block(-2,19,5,OBSIDIAN:0)
Block(-2,19,6,OBSIDIAN:0)
Block(-2,19,7,OBSIDIAN:0)
Block(-2,19,8,OBSIDIAN:0)
Block(-2,20,-2,STAINED_CLAY:3)
Block(-2,20,-1,STAINED_CLAY:3)
Block(-2,20,0,STAINED_CLAY:3)
Block(-2,20,1,STAINED_CLAY:3)
Block(-2,20,2,OBSIDIAN:0)
Block(-2,20,3,OBSIDIAN:0)
Block(-2,20,4,OBSIDIAN:0)
Block(-2,20,5,OBSIDIAN:0)
Block(-2,20,6,OBSIDIAN:0)
Block(-2,20,7,OBSIDIAN:0)
Block(-2,20,8,OBSIDIAN:0)
Block(-2,21,-2,STAINED_CLAY:3)
Block(-2,21,-1,STAINED_CLAY:3)
Block(-2,21,0,STAINED_CLAY:3)
Block(-2,21,1,OBSIDIAN:0)
Block(-2,21,2,OBSIDIAN:0)
Block(-2,21,3,OBSIDIAN:0)
Block(-2,21,4,OBSIDIAN:0)
Block(-2,21,5,OBSIDIAN:0)
Block(-2,21,6,OBSIDIAN:0)
Block(-2,21,7,OBSIDIAN:0)
Block(-2,22,-2,STAINED_CLAY:3)
Block(-2,22,-1,STAINED_CLAY:3)
Block(-2,22,0,STAINED_CLAY:3)
Block(-2,22,1,OBSIDIAN:0)
Block(-2,22,2,OBSIDIAN:0)
Block(-2,22,3,OBSIDIAN:0)
Block(-2,22,4,OBSIDIAN:0)
Block(-2,22,5,OBSIDIAN:0)
Block(-2,22,6,OBSIDIAN:0)
Block(-2,22,7,OBSIDIAN:0)
Block(-1,0,-4,OBSIDIAN:0)
Block(-1,0,-3,OBSIDIAN:0)
Block(-1,0,-2,OBSIDIAN:0)
Block(-1,0,-1,OBSIDIAN:0)
Block(-1,0,0,OBSIDIAN:0)
Block(-1,0,1,OBSIDIAN:0)
Block(-1,0,2,STAINED_CLAY:3)
Block(-1,0,3,STAINED_CLAY:3)
Block(-1,0,4,STAINED_CLAY:3)
Block(-1,0,5,STAINED_CLAY:3)
Block(-1,0,6,STAINED_CLAY:3)
Block(-1,0,7,STAINED_CLAY:3)
Block(-1,0,8,STAINED_CLAY:3)
Block(-1,1,-4,OBSIDIAN:0)
Block(-1,1,-3,OBSIDIAN:0)
Block(-1,1,-2,OBSIDIAN:0)
Block(-1,1,-1,OBSIDIAN:0)
Block(-1,1,0,OBSIDIAN:0)
Block(-1,1,1,OBSIDIAN:0)
Block(-1,1,2,STAINED_CLAY:3)
Block(-1,1,3,STAINED_CLAY:3)
Block(-1,1,4,STAINED_CLAY:3)
Block(-1,1,5,STAINED_CLAY:3)
Block(-1,1,6,STAINED_CLAY:3)
Block(-1,1,7,STAINED_CLAY:3)
Block(-1,1,8,STAINED_CLAY:3)
Block(-1,2,-4,OBSIDIAN:0)
Block(-1,2,-3,OBSIDIAN:0)
Block(-1,2,-2,OBSIDIAN:0)
Block(-1,2,-1,OBSIDIAN:0)
Block(-1,2,0,OBSIDIAN:0)
Block(-1,2,1,OBSIDIAN:0)
Block(-1,2,2,STAINED_CLAY:3)
Block(-1,2,3,STAINED_CLAY:3)
Block(-1,2,4,STAINED_CLAY:3)
Block(-1,2,5,STAINED_CLAY:3)
Block(-1,2,6,STAINED_CLAY:3)
Block(-1,2,7,STAINED_CLAY:3)
Block(-1,2,8,STAINED_CLAY:3)
Block(-1,3,-4,OBSIDIAN:0)
Block(-1,3,-3,OBSIDIAN:0)
Block(-1,3,-2,OBSIDIAN:0)
Block(-1,3,-1,OBSIDIAN:0)
Block(-1,3,0,OBSIDIAN:0)
Block(-1,3,1,STAINED_CLAY:3)
Block(-1,3,2,STAINED_CLAY:3)
Block(-1,3,3,STAINED_CLAY:3)
Block(-1,3,4,STAINED_CLAY:3)
Block(-1,3,5,STAINED_CLAY:3)
Block(-1,3,6,STAINED_CLAY:3)
Block(-1,3,7,STAINED_CLAY:3)
Block(-1,3,8,STAINED_CLAY:3)
Block(-1,4,-4,OBSIDIAN:0)
Block(-1,4,-3,OBSIDIAN:0)
Block(-1,4,-2,OBSIDIAN:0)
Block(-1,4,-1,OBSIDIAN:0)
Block(-1,4,0,STAINED_CLAY:3)
Block(-1,4,1,STAINED_CLAY:3)
Block(-1,4,2,STAINED_CLAY:3)
Block(-1,4,3,STAINED_CLAY:3)
Block(-1,4,4,STAINED_CLAY:3)
Block(-1,4,5,STAINED_CLAY:3)
Block(-1,4,6,STAINED_CLAY:3)
Block(-1,4,7,STAINED_CLAY:3)
Block(-1,4,8,STAINED_CLAY:3)
Block(-1,5,-4,OBSIDIAN:0)
Block(-1,5,-3,OBSIDIAN:0)
Block(-1,5,-2,OBSIDIAN:0)
Block(-1,5,-1,STAINED_CLAY:3)
Block(-1,5,0,STAINED_CLAY:3)
Block(-1,5,1,STAINED_CLAY:3)
Block(-1,5,2,STAINED_CLAY:3)
Block(-1,5,3,STAINED_CLAY:3)
Block(-1,5,4,STAINED_CLAY:3)
Block(-1,5,5,STAINED_CLAY:3)
Block(-1,5,6,STAINED_CLAY:3)
Block(-1,5,7,STAINED_CLAY:3)
Block(-1,5,8,STAINED_CLAY:3)
Block(-1,6,-3,OBSIDIAN:0)
Block(-1,6,-2,STAINED_CLAY:3)
Block(-1,6,-1,STAINED_CLAY:3)
Block(-1,6,0,STAINED_CLAY:3)
Block(-1,6,1,STAINED_CLAY:3)
Block(-1,6,2,STAINED_CLAY:3)
Block(-1,6,3,STAINED_CLAY:3)
Block(-1,6,4,STAINED_CLAY:3)
Block(-1,6,5,STAINED_CLAY:3)
Block(-1,6,6,STAINED_CLAY:3)
Block(-1,6,7,STAINED_CLAY:3)
Block(-1,6,8,STAINED_CLAY:3)
Block(-1,7,-3,STAINED_CLAY:3)
Block(-1,7,-2,STAINED_CLAY:3)
Block(-1,7,-1,STAINED_CLAY:3)
Block(-1,7,0,STAINED_CLAY:3)
Block(-1,7,1,STAINED_CLAY:3)
Block(-1,7,2,STAINED_CLAY:3)
Block(-1,7,3,STAINED_CLAY:3)
Block(-1,7,4,STAINED_CLAY:3)
Block(-1,7,5,STAINED_CLAY:3)
Block(-1,7,6,STAINED_CLAY:3)
Block(-1,7,7,STAINED_CLAY:3)
Block(-1,7,8,STAINED_CLAY:3)
Block(-1,8,-3,STAINED_CLAY:3)
Block(-1,8,-2,STAINED_CLAY:3)
Block(-1,8,-1,STAINED_CLAY:3)
Block(-1,8,0,STAINED_CLAY:3)
Block(-1,8,1,STAINED_CLAY:3)
Block(-1,8,2,STAINED_CLAY:3)
Block(-1,8,3,STAINED_CLAY:3)
Block(-1,8,4,STAINED_CLAY:3)
Block(-1,8,5,STAINED_CLAY:3)
Block(-1,8,6,STAINED_CLAY:3)
Block(-1,8,7,STAINED_CLAY:3)
Block(-1,8,8,STAINED_CLAY:3)
Block(-1,9,-3,STAINED_CLAY:3)
Block(-1,9,-2,STAINED_CLAY:3)
Block(-1,9,-1,STAINED_CLAY:3)
Block(-1,9,0,STAINED_CLAY:3)
Block(-1,9,1,STAINED_CLAY:3)
Block(-1,9,2,STAINED_CLAY:3)
Block(-1,9,3,STAINED_CLAY:3)
Block(-1,9,4,STAINED_CLAY:3)
Block(-1,9,5,STAINED_CLAY:3)
Block(-1,9,6,STAINED_CLAY:3)
Block(-1,9,7,STAINED_CLAY:3)
Block(-1,9,8,STAINED_CLAY:3)
Block(-1,10,-3,STAINED_CLAY:3)
Block(-1,10,-2,STAINED_CLAY:3)
Block(-1,10,-1,STAINED_CLAY:3)
Block(-1,10,0,STAINED_CLAY:3)
Block(-1,10,1,STAINED_CLAY:3)
Block(-1,10,2,STAINED_CLAY:3)
Block(-1,10,3,STAINED_CLAY:3)
Block(-1,10,4,STAINED_CLAY:3)
Block(-1,10,5,STAINED_CLAY:3)
Block(-1,10,6,STAINED_CLAY:3)
Block(-1,10,7,STAINED_CLAY:3)
Block(-1,10,8,OBSIDIAN:0)
Block(-1,11,-3,STAINED_CLAY:3)
Block(-1,11,-2,STAINED_CLAY:3)
Block(-1,11,-1,STAINED_CLAY:3)
Block(-1,11,0,STAINED_CLAY:3)
Block(-1,11,1,STAINED_CLAY:3)
Block(-1,11,2,STAINED_CLAY:3)
Block(-1,11,3,STAINED_CLAY:3)
Block(-1,11,4,STAINED_CLAY:3)
Block(-1,11,5,STAINED_CLAY:3)
Block(-1,11,6,STAINED_CLAY:3)
Block(-1,11,7,OBSIDIAN:0)
Block(-1,11,8,OBSIDIAN:0)
Block(-1,12,-3,STAINED_CLAY:3)
Block(-1,12,-2,STAINED_CLAY:3)
Block(-1,12,-1,STAINED_CLAY:3)
Block(-1,12,0,STAINED_CLAY:3)
Block(-1,12,1,STAINED_CLAY:3)
Block(-1,12,2,STAINED_CLAY:3)
Block(-1,12,3,STAINED_CLAY:3)
Block(-1,12,4,STAINED_CLAY:3)
Block(-1,12,5,STAINED_CLAY:3)
Block(-1,12,6,STAINED_CLAY:3)
Block(-1,12,7,OBSIDIAN:0)
Block(-1,12,8,OBSIDIAN:0)
Block(-1,13,-3,STAINED_CLAY:3)
Block(-1,13,-2,STAINED_CLAY:3)
Block(-1,13,-1,STAINED_CLAY:3)
Block(-1,13,0,STAINED_CLAY:3)
Block(-1,13,1,STAINED_CLAY:3)
Block(-1,13,2,STAINED_CLAY:3)
Block(-1,13,3,STAINED_CLAY:3)
Block(-1,13,4,STAINED_CLAY:3)
Block(-1,13,5,STAINED_CLAY:3)
Block(-1,13,6,STAINED_CLAY:3)
Block(-1,13,7,OBSIDIAN:0)
Block(-1,13,8,OBSIDIAN:0)
Block(-1,14,-3,STAINED_CLAY:3)
Block(-1,14,-2,STAINED_CLAY:3)
Block(-1,14,-1,STAINED_CLAY:3)
Block(-1,14,0,STAINED_CLAY:3)
Block(-1,14,1,STAINED_CLAY:3)
Block(-1,14,2,STAINED_CLAY:3)
Block(-1,14,3,STAINED_CLAY:3)
Block(-1,14,4,STAINED_CLAY:3)
Block(-1,14,5,STAINED_CLAY:3)
Block(-1,14,6,STAINED_CLAY:3)
Block(-1,14,7,OBSIDIAN:0)
Block(-1,14,8,OBSIDIAN:0)
Block(-1,15,-3,STAINED_CLAY:3)
Block(-1,15,-2,STAINED_CLAY:3)
Block(-1,15,-1,STAINED_CLAY:3)
Block(-1,15,0,STAINED_CLAY:3)
Block(-1,15,1,STAINED_CLAY:3)
Block(-1,15,2,STAINED_CLAY:3)
Block(-1,15,3,STAINED_CLAY:3)
Block(-1,15,4,STAINED_CLAY:3)
Block(-1,15,5,STAINED_CLAY:3)
Block(-1,15,6,STAINED_CLAY:3)
Block(-1,15,7,OBSIDIAN:0)
Block(-1,15,8,OBSIDIAN:0)
Block(-1,16,-3,STAINED_CLAY:3)
Block(-1,16,-2,STAINED_CLAY:3)
Block(-1,16,-1,STAINED_CLAY:3)
Block(-1,16,0,STAINED_CLAY:3)
Block(-1,16,1,STAINED_CLAY:3)
Block(-1,16,2,STAINED_CLAY:3)
Block(-1,16,3,STAINED_CLAY:3)
Block(-1,16,4,STAINED_CLAY:3)
Block(-1,16,5,OBSIDIAN:0)
Block(-1,16,6,OBSIDIAN:0)
Block(-1,16,7,OBSIDIAN:0)
Block(-1,16,8,OBSIDIAN:0)
Block(-1,17,-3,STAINED_CLAY:3)
Block(-1,17,-2,STAINED_CLAY:3)
Block(-1,17,-1,STAINED_CLAY:3)
Block(-1,17,0,STAINED_CLAY:3)
Block(-1,17,1,STAINED_CLAY:3)
Block(-1,17,2,STAINED_CLAY:3)
Block(-1,17,3,STAINED_CLAY:3)
Block(-1,17,4,STAINED_CLAY:3)
Block(-1,17,5,OBSIDIAN:0)
Block(-1,17,6,OBSIDIAN:0)
Block(-1,17,7,OBSIDIAN:0)
Block(-1,17,8,OBSIDIAN:0)
Block(-1,18,-3,STAINED_CLAY:3)
Block(-1,18,-2,STAINED_CLAY:3)
Block(-1,18,-1,STAINED_CLAY:3)
Block(-1,18,0,STAINED_CLAY:3)
Block(-1,18,1,STAINED_CLAY:3)
Block(-1,18,2,STAINED_CLAY:3)
Block(-1,18,3,STAINED_CLAY:3)
Block(-1,18,4,OBSIDIAN:0)
Block(-1,18,5,OBSIDIAN:0)
Block(-1,18,6,OBSIDIAN:0)
Block(-1,18,7,OBSIDIAN:0)
Block(-1,18,8,OBSIDIAN:0)
Block(-1,19,-3,STAINED_CLAY:3)
Block(-1,19,-2,STAINED_CLAY:3)
Block(-1,19,-1,STAINED_CLAY:3)
Block(-1,19,0,STAINED_CLAY:3)
Block(-1,19,1,STAINED_CLAY:3)
Block(-1,19,2,STAINED_CLAY:3)
Block(-1,19,3,OBSIDIAN:0)
Block(-1,19,4,OBSIDIAN:0)
Block(-1,19,5,OBSIDIAN:0)
Block(-1,19,6,OBSIDIAN:0)
Block(-1,19,7,OBSIDIAN:0)
Block(-1,19,8,OBSIDIAN:0)
Block(-1,20,-3,STAINED_CLAY:3)
Block(-1,20,-2,STAINED_CLAY:3)
Block(-1,20,-1,STAINED_CLAY:3)
Block(-1,20,0,STAINED_CLAY:3)
Block(-1,20,1,STAINED_CLAY:3)
Block(-1,20,2,OBSIDIAN:0)
Block(-1,20,3,OBSIDIAN:0)
Block(-1,20,4,OBSIDIAN:0)
Block(-1,20,5,OBSIDIAN:0)
Block(-1,20,6,OBSIDIAN:0)
Block(-1,20,7,OBSIDIAN:0)
Block(-1,20,8,OBSIDIAN:0)
Block(-1,21,-3,STAINED_CLAY:3)
Block(-1,21,-2,STAINED_CLAY:3)
Block(-1,21,-1,STAINED_CLAY:3)
Block(-1,21,0,STAINED_CLAY:3)
Block(-1,21,1,OBSIDIAN:0)
Block(-1,21,2,OBSIDIAN:0)
Block(-1,21,3,OBSIDIAN:0)
Block(-1,21,4,OBSIDIAN:0)
Block(-1,21,5,OBSIDIAN:0)
Block(-1,21,6,OBSIDIAN:0)
Block(-1,21,7,OBSIDIAN:0)
Block(-1,22,-3,STAINED_CLAY:3)
Block(-1,22,-2,STAINED_CLAY:3)
Block(-1,22,-1,STAINED_CLAY:3)
Block(-1,22,0,STAINED_CLAY:3)
Block(-1,22,1,OBSIDIAN:0)
Block(-1,22,2,OBSIDIAN:0)
Block(-1,22,3,OBSIDIAN:0)
Block(-1,22,4,OBSIDIAN:0)
Block(-1,22,5,OBSIDIAN:0)
Block(-1,22,6,OBSIDIAN:0)
Block(-1,22,7,OBSIDIAN:0)
Block(-1,23,-3,STAINED_CLAY:3)
Block(-1,23,-2,STAINED_CLAY:3)
Block(-1,23,-1,STAINED_CLAY:3)
Block(-1,23,0,OBSIDIAN:0)
Block(-1,23,1,OBSIDIAN:0)
Block(-1,23,2,OBSIDIAN:0)
Block(-1,23,3,OBSIDIAN:0)
Block(-1,23,4,OBSIDIAN:0)
Block(-1,23,5,OBSIDIAN:0)
Block(-1,23,6,OBSIDIAN:0)
Block(-1,23,7,OBSIDIAN:0)
Block(-1,24,-3,STAINED_CLAY:3)
Block(-1,24,-2,STAINED_CLAY:3)
Block(-1,24,-1,OBSIDIAN:0)
Block(-1,24,0,OBSIDIAN:0)
Block(-1,24,1,OBSIDIAN:0)
Block(-1,24,2,OBSIDIAN:0)
Block(-1,24,3,OBSIDIAN:0)
Block(-1,24,4,OBSIDIAN:0)
Block(-1,24,5,OBSIDIAN:0)
Block(-1,24,6,OBSIDIAN:0)
Block(-1,25,-3,STAINED_CLAY:3)
Block(-1,25,-2,STAINED_CLAY:3)
Block(-1,25,-1,OBSIDIAN:0)
Block(-1,25,0,OBSIDIAN:0)
Block(-1,25,1,OBSIDIAN:0)
Block(-1,25,2,OBSIDIAN:0)
Block(-1,25,3,OBSIDIAN:0)
Block(-1,25,4,OBSIDIAN:0)
Block(-1,25,5,OBSIDIAN:0)
Block(-1,25,6,STAINED_CLAY:3)
Block(-1,26,-3,OBSIDIAN:0)
Block(-1,26,-2,OBSIDIAN:0)
Block(-1,26,-1,OBSIDIAN:0)
Block(-1,26,0,OBSIDIAN:0)
Block(-1,26,1,OBSIDIAN:0)
Block(-1,26,2,OBSIDIAN:0)
Block(-1,26,3,OBSIDIAN:0)
Block(-1,26,4,OBSIDIAN:0)
Block(-1,26,5,OBSIDIAN:0)
Block(-1,26,6,STAINED_CLAY:3)
Block(-1,27,-3,OBSIDIAN:0)
Block(-1,27,-2,OBSIDIAN:0)
Block(-1,27,-1,OBSIDIAN:0)
Block(-1,27,0,OBSIDIAN:0)
Block(-1,27,1,OBSIDIAN:0)
Block(-1,27,2,OBSIDIAN:0)
Block(-1,27,3,OBSIDIAN:0)
Block(-1,27,4,OBSIDIAN:0)
Block(-1,27,5,STAINED_CLAY:3)
Block(0,0,-5,STAINED_CLAY:3)
Block(0,0,-4,OBSIDIAN:0)
Block(0,0,-3,OBSIDIAN:0)
Block(0,0,-2,OBSIDIAN:0)
Block(0,0,-1,OBSIDIAN:0)
Block(0,0,0,OBSIDIAN:0)
Block(0,0,1,STAINED_CLAY:3)
Block(0,0,2,STAINED_CLAY:3)
Block(0,0,3,STAINED_CLAY:3)
Block(0,0,4,STAINED_CLAY:3)
Block(0,0,5,STAINED_CLAY:3)
Block(0,0,6,STAINED_CLAY:3)
Block(0,0,7,STAINED_CLAY:3)
Block(0,0,8,STAINED_CLAY:3)
Block(0,1,-5,OBSIDIAN:0)
Block(0,1,-4,OBSIDIAN:0)
Block(0,1,-3,OBSIDIAN:0)
Block(0,1,-2,OBSIDIAN:0)
Block(0,1,-1,OBSIDIAN:0)
Block(0,1,0,OBSIDIAN:0)
Block(0,1,1,STAINED_CLAY:3)
Block(0,1,2,STAINED_CLAY:3)
Block(0,1,3,STAINED_CLAY:3)
Block(0,1,4,STAINED_CLAY:3)
Block(0,1,5,STAINED_CLAY:3)
Block(0,1,6,STAINED_CLAY:3)
Block(0,1,7,STAINED_CLAY:3)
Block(0,1,8,STAINED_CLAY:3)
Block(0,2,-5,OBSIDIAN:0)
Block(0,2,-4,OBSIDIAN:0)
Block(0,2,-3,OBSIDIAN:0)
Block(0,2,-2,OBSIDIAN:0)
Block(0,2,-1,OBSIDIAN:0)
Block(0,2,0,OBSIDIAN:0)
Block(0,2,1,STAINED_CLAY:3)
Block(0,2,2,STAINED_CLAY:3)
Block(0,2,3,STAINED_CLAY:3)
Block(0,2,4,STAINED_CLAY:3)
Block(0,2,5,STAINED_CLAY:3)
Block(0,2,6,STAINED_CLAY:3)
Block(0,2,7,STAINED_CLAY:3)
Block(0,2,8,STAINED_CLAY:3)
Block(0,3,-5,OBSIDIAN:0)
Block(0,3,-4,OBSIDIAN:0)
Block(0,3,-3,OBSIDIAN:0)
Block(0,3,-2,OBSIDIAN:0)
Block(0,3,-1,OBSIDIAN:0)
Block(0,3,0,OBSIDIAN:0)
Block(0,3,1,STAINED_CLAY:3)
Block(0,3,2,STAINED_CLAY:3)
Block(0,3,3,STAINED_CLAY:3)
Block(0,3,4,STAINED_CLAY:3)
Block(0,3,5,STAINED_CLAY:3)
Block(0,3,6,STAINED_CLAY:3)
Block(0,3,7,STAINED_CLAY:3)
Block(0,3,8,STAINED_CLAY:3)
Block(0,4,-5,OBSIDIAN:0)
Block(0,4,-4,OBSIDIAN:0)
Block(0,4,-3,OBSIDIAN:0)
Block(0,4,-2,OBSIDIAN:0)
Block(0,4,-1,STAINED_CLAY:3)
Block(0,4,0,STAINED_CLAY:3)
Block(0,4,1,STAINED_CLAY:3)
Block(0,4,2,STAINED_CLAY:3)
Block(0,4,3,STAINED_CLAY:3)
Block(0,4,4,STAINED_CLAY:3)
Block(0,4,5,STAINED_CLAY:3)
Block(0,4,6,STAINED_CLAY:3)
Block(0,4,7,STAINED_CLAY:3)
Block(0,4,8,STAINED_CLAY:3)
Block(0,5,-5,OBSIDIAN:0)
Block(0,5,-4,OBSIDIAN:0)
Block(0,5,-3,OBSIDIAN:0)
Block(0,5,-2,OBSIDIAN:0)
Block(0,5,-1,STAINED_CLAY:3)
Block(0,5,0,STAINED_CLAY:3)
Block(0,5,1,STAINED_CLAY:3)
Block(0,5,2,STAINED_CLAY:3)
Block(0,5,3,STAINED_CLAY:3)
Block(0,5,4,STAINED_CLAY:3)
Block(0,5,5,STAINED_CLAY:3)
Block(0,5,6,STAINED_CLAY:3)
Block(0,5,7,STAINED_CLAY:3)
Block(0,5,8,STAINED_CLAY:3)
Block(0,6,-5,OBSIDIAN:0)
Block(0,6,-4,OBSIDIAN:0)
Block(0,6,-3,OBSIDIAN:0)
Block(0,6,-2,STAINED_CLAY:3)
Block(0,6,-1,STAINED_CLAY:3)
Block(0,6,0,STAINED_CLAY:3)
Block(0,6,1,STAINED_CLAY:3)
Block(0,6,2,STAINED_CLAY:3)
Block(0,6,3,STAINED_CLAY:3)
Block(0,6,4,STAINED_CLAY:3)
Block(0,6,5,STAINED_CLAY:3)
Block(0,6,6,STAINED_CLAY:3)
Block(0,6,7,STAINED_CLAY:3)
Block(0,6,8,STAINED_CLAY:3)
Block(0,7,-5,OBSIDIAN:0)
Block(0,7,-4,OBSIDIAN:0)
Block(0,7,-3,OBSIDIAN:0)
Block(0,7,-2,STAINED_CLAY:3)
Block(0,7,-1,STAINED_CLAY:3)
Block(0,7,0,STAINED_CLAY:3)
Block(0,7,1,STAINED_CLAY:3)
Block(0,7,2,STAINED_CLAY:3)
Block(0,7,3,STAINED_CLAY:3)
Block(0,7,4,STAINED_CLAY:3)
Block(0,7,5,STAINED_CLAY:3)
Block(0,7,6,STAINED_CLAY:3)
Block(0,7,7,STAINED_CLAY:3)
Block(0,7,8,STAINED_CLAY:3)
Block(0,8,-5,OBSIDIAN:0)
Block(0,8,-4,OBSIDIAN:0)
Block(0,8,-3,STAINED_CLAY:3)
Block(0,8,-2,STAINED_CLAY:3)
Block(0,8,-1,STAINED_CLAY:3)
Block(0,8,0,STAINED_CLAY:3)
Block(0,8,1,STAINED_CLAY:3)
Block(0,8,2,STAINED_CLAY:3)
Block(0,8,3,STAINED_CLAY:3)
Block(0,8,4,STAINED_CLAY:3)
Block(0,8,5,STAINED_CLAY:3)
Block(0,8,6,STAINED_CLAY:3)
Block(0,8,7,STAINED_CLAY:3)
Block(0,8,8,STAINED_CLAY:3)
Block(0,9,-5,OBSIDIAN:0)
Block(0,9,-4,STAINED_CLAY:3)
Block(0,9,-3,STAINED_CLAY:3)
Block(0,9,-2,STAINED_CLAY:3)
Block(0,9,-1,STAINED_CLAY:3)
Block(0,9,0,STAINED_CLAY:3)
Block(0,9,1,STAINED_CLAY:3)
Block(0,9,2,STAINED_CLAY:3)
Block(0,9,3,STAINED_CLAY:3)
Block(0,9,4,STAINED_CLAY:3)
Block(0,9,5,STAINED_CLAY:3)
Block(0,9,6,STAINED_CLAY:3)
Block(0,9,7,STAINED_CLAY:3)
Block(0,9,8,STAINED_CLAY:3)
Block(0,10,-5,OBSIDIAN:0)
Block(0,10,-4,STAINED_CLAY:3)
Block(0,10,-3,STAINED_CLAY:3)
Block(0,10,-2,STAINED_CLAY:3)
Block(0,10,-1,STAINED_CLAY:3)
Block(0,10,0,STAINED_CLAY:3)
Block(0,10,1,STAINED_CLAY:3)
Block(0,10,2,STAINED_CLAY:3)
Block(0,10,3,STAINED_CLAY:3)
Block(0,10,4,STAINED_CLAY:3)
Block(0,10,5,STAINED_CLAY:3)
Block(0,10,6,STAINED_CLAY:3)
Block(0,10,7,STAINED_CLAY:3)
Block(0,10,8,OBSIDIAN:0)
Block(0,11,-5,STAINED_CLAY:3)
Block(0,11,-4,STAINED_CLAY:3)
Block(0,11,-3,STAINED_CLAY:3)
Block(0,11,-2,STAINED_CLAY:3)
Block(0,11,-1,STAINED_CLAY:3)
Block(0,11,0,STAINED_CLAY:3)
Block(0,11,1,STAINED_CLAY:3)
Block(0,11,2,STAINED_CLAY:3)
Block(0,11,3,STAINED_CLAY:3)
Block(0,11,4,STAINED_CLAY:3)
Block(0,11,5,STAINED_CLAY:3)
Block(0,11,6,STAINED_CLAY:3)
Block(0,11,7,OBSIDIAN:0)
Block(0,11,8,OBSIDIAN:0)
Block(0,12,-4,STAINED_CLAY:3)
Block(0,12,-3,STAINED_CLAY:3)
Block(0,12,-2,STAINED_CLAY:3)
Block(0,12,-1,STAINED_CLAY:3)
Block(0,12,0,STAINED_CLAY:3)
Block(0,12,1,STAINED_CLAY:3)
Block(0,12,2,STAINED_CLAY:3)
Block(0,12,3,STAINED_CLAY:3)
Block(0,12,4,STAINED_CLAY:3)
Block(0,12,5,STAINED_CLAY:3)
Block(0,12,6,STAINED_CLAY:3)
Block(0,12,7,OBSIDIAN:0)
Block(0,12,8,OBSIDIAN:0)
Block(0,13,-4,STAINED_CLAY:3)
Block(0,13,-3,STAINED_CLAY:3)
Block(0,13,-2,STAINED_CLAY:3)
Block(0,13,-1,STAINED_CLAY:3)
Block(0,13,0,STAINED_CLAY:3)
Block(0,13,1,STAINED_CLAY:3)
Block(0,13,2,STAINED_CLAY:3)
Block(0,13,3,STAINED_CLAY:3)
Block(0,13,4,STAINED_CLAY:3)
Block(0,13,5,STAINED_CLAY:3)
Block(0,13,6,STAINED_CLAY:3)
Block(0,13,7,OBSIDIAN:0)
Block(0,13,8,OBSIDIAN:0)
Block(0,14,-4,STAINED_CLAY:3)
Block(0,14,-3,STAINED_CLAY:3)
Block(0,14,-2,STAINED_CLAY:3)
Block(0,14,-1,STAINED_CLAY:3)
Block(0,14,0,STAINED_CLAY:3)
Block(0,14,1,STAINED_CLAY:3)
Block(0,14,2,STAINED_CLAY:3)
Block(0,14,3,STAINED_CLAY:3)
Block(0,14,4,STAINED_CLAY:3)
Block(0,14,5,STAINED_CLAY:3)
Block(0,14,6,STAINED_CLAY:3)
Block(0,14,7,OBSIDIAN:0)
Block(0,14,8,OBSIDIAN:0)
Block(0,15,-4,STAINED_CLAY:3)
Block(0,15,-3,STAINED_CLAY:3)
Block(0,15,-2,STAINED_CLAY:3)
Block(0,15,-1,STAINED_CLAY:3)
Block(0,15,0,STAINED_CLAY:3)
Block(0,15,1,STAINED_CLAY:3)
Block(0,15,2,STAINED_CLAY:3)
Block(0,15,3,STAINED_CLAY:3)
Block(0,15,4,STAINED_CLAY:3)
Block(0,15,5,STAINED_CLAY:3)
Block(0,15,6,STAINED_CLAY:3)
Block(0,15,7,OBSIDIAN:0)
Block(0,15,8,OBSIDIAN:0)
Block(0,16,-4,STAINED_CLAY:3)
Block(0,16,-3,STAINED_CLAY:3)
Block(0,16,-2,STAINED_CLAY:3)
Block(0,16,-1,STAINED_CLAY:3)
Block(0,16,0,STAINED_CLAY:3)
Block(0,16,1,STAINED_CLAY:3)
Block(0,16,2,STAINED_CLAY:3)
Block(0,16,3,STAINED_CLAY:3)
Block(0,16,4,STAINED_CLAY:3)
Block(0,16,5,STAINED_CLAY:3)
Block(0,16,6,STAINED_CLAY:3)
Block(0,16,7,STAINED_CLAY:3)
Block(0,16,8,OBSIDIAN:0)
Block(0,17,-4,STAINED_CLAY:3)
Block(0,17,-3,STAINED_CLAY:3)
Block(0,17,-2,STAINED_CLAY:3)
Block(0,17,-1,STAINED_CLAY:3)
Block(0,17,0,STAINED_CLAY:3)
Block(0,17,1,STAINED_CLAY:3)
Block(0,17,2,STAINED_CLAY:3)
Block(0,17,3,STAINED_CLAY:3)
Block(0,17,4,STAINED_CLAY:3)
Block(0,17,5,STAINED_CLAY:3)
Block(0,17,6,OBSIDIAN:0)
Block(0,17,7,OBSIDIAN:0)
Block(0,17,8,OBSIDIAN:0)
Block(0,18,-4,STAINED_CLAY:3)
Block(0,18,-3,STAINED_CLAY:3)
Block(0,18,-2,STAINED_CLAY:3)
Block(0,18,-1,STAINED_CLAY:3)
Block(0,18,0,STAINED_CLAY:3)
Block(0,18,1,STAINED_CLAY:3)
Block(0,18,2,STAINED_CLAY:3)
Block(0,18,3,STAINED_CLAY:3)
Block(0,18,4,STAINED_CLAY:3)
Block(0,18,5,STAINED_CLAY:3)
Block(0,18,6,OBSIDIAN:0)
Block(0,18,7,OBSIDIAN:0)
Block(0,18,8,OBSIDIAN:0)
Block(0,19,-4,STAINED_CLAY:3)
Block(0,19,-3,STAINED_CLAY:3)
Block(0,19,-2,STAINED_CLAY:3)
Block(0,19,-1,STAINED_CLAY:3)
Block(0,19,0,STAINED_CLAY:3)
Block(0,19,1,STAINED_CLAY:3)
Block(0,19,2,STAINED_CLAY:3)
Block(0,19,3,OBSIDIAN:0)
Block(0,19,4,OBSIDIAN:0)
Block(0,19,5,OBSIDIAN:0)
Block(0,19,6,OBSIDIAN:0)
Block(0,19,7,OBSIDIAN:0)
Block(0,19,8,OBSIDIAN:0)
Block(0,20,-4,STAINED_CLAY:3)
Block(0,20,-3,STAINED_CLAY:3)
Block(0,20,-2,STAINED_CLAY:3)
Block(0,20,-1,STAINED_CLAY:3)
Block(0,20,0,STAINED_CLAY:3)
Block(0,20,1,STAINED_CLAY:3)
Block(0,20,2,OBSIDIAN:0)
Block(0,20,3,OBSIDIAN:0)
Block(0,20,4,OBSIDIAN:0)
Block(0,20,5,OBSIDIAN:0)
Block(0,20,6,OBSIDIAN:0)
Block(0,20,7,OBSIDIAN:0)
Block(0,20,8,STAINED_CLAY:3)
Block(0,21,-4,STAINED_CLAY:3)
Block(0,21,-3,STAINED_CLAY:3)
Block(0,21,-2,STAINED_CLAY:3)
Block(0,21,-1,STAINED_CLAY:3)
Block(0,21,0,STAINED_CLAY:3)
Block(0,21,1,OBSIDIAN:0)
Block(0,21,2,OBSIDIAN:0)
Block(0,21,3,OBSIDIAN:0)
Block(0,21,4,OBSIDIAN:0)
Block(0,21,5,OBSIDIAN:0)
Block(0,21,6,OBSIDIAN:0)
Block(0,21,7,OBSIDIAN:0)
Block(0,22,-4,STAINED_CLAY:3)
Block(0,22,-3,STAINED_CLAY:3)
Block(0,22,-2,STAINED_CLAY:3)
Block(0,22,-1,STAINED_CLAY:3)
Block(0,22,0,STAINED_CLAY:3)
Block(0,22,1,OBSIDIAN:0)
Block(0,22,2,OBSIDIAN:0)
Block(0,22,3,OBSIDIAN:0)
Block(0,22,4,OBSIDIAN:0)
Block(0,22,5,OBSIDIAN:0)
Block(0,22,6,OBSIDIAN:0)
Block(0,22,7,OBSIDIAN:0)
Block(0,23,-4,STAINED_CLAY:3)
Block(0,23,-3,STAINED_CLAY:3)
Block(0,23,-2,STAINED_CLAY:3)
Block(0,23,-1,STAINED_CLAY:3)
Block(0,23,0,OBSIDIAN:0)
Block(0,23,1,OBSIDIAN:0)
Block(0,23,2,OBSIDIAN:0)
Block(0,23,3,OBSIDIAN:0)
Block(0,23,4,OBSIDIAN:0)
Block(0,23,5,OBSIDIAN:0)
Block(0,23,6,OBSIDIAN:0)
Block(0,23,7,OBSIDIAN:0)
Block(0,24,-4,STAINED_CLAY:3)
Block(0,24,-3,STAINED_CLAY:3)
Block(0,24,-2,STAINED_CLAY:3)
Block(0,24,-1,OBSIDIAN:0)
Block(0,24,0,OBSIDIAN:0)
Block(0,24,1,OBSIDIAN:0)
Block(0,24,2,OBSIDIAN:0)
Block(0,24,3,OBSIDIAN:0)
Block(0,24,4,OBSIDIAN:0)
Block(0,24,5,OBSIDIAN:0)
Block(0,24,6,OBSIDIAN:0)
Block(0,25,-4,STAINED_CLAY:3)
Block(0,25,-3,STAINED_CLAY:3)
Block(0,25,-2,STAINED_CLAY:3)
Block(0,25,-1,OBSIDIAN:0)
Block(0,25,0,OBSIDIAN:0)
Block(0,25,1,OBSIDIAN:0)
Block(0,25,2,OBSIDIAN:0)
Block(0,25,3,OBSIDIAN:0)
Block(0,25,4,OBSIDIAN:0)
Block(0,25,5,OBSIDIAN:0)
Block(0,25,6,STAINED_CLAY:3)
Block(0,26,-4,STAINED_CLAY:3)
Block(0,26,-3,OBSIDIAN:0)
Block(0,26,-2,OBSIDIAN:0)
Block(0,26,-1,OBSIDIAN:0)
Block(0,26,0,OBSIDIAN:0)
Block(0,26,1,OBSIDIAN:0)
Block(0,26,2,OBSIDIAN:0)
Block(0,26,3,OBSIDIAN:0)
Block(0,26,4,OBSIDIAN:0)
Block(0,26,5,OBSIDIAN:0)
Block(0,26,6,STAINED_CLAY:3)
Block(0,27,-4,OBSIDIAN:0)
Block(0,27,-3,OBSIDIAN:0)
Block(0,27,-2,OBSIDIAN:0)
Block(0,27,-1,OBSIDIAN:0)
Block(0,27,0,OBSIDIAN:0)
Block(0,27,1,OBSIDIAN:0)
Block(0,27,2,OBSIDIAN:0)
Block(0,27,3,OBSIDIAN:0)
Block(0,27,4,OBSIDIAN:0)
Block(0,27,5,STAINED_CLAY:3)
Block(0,28,-4,OBSIDIAN:0)
Block(0,28,-3,OBSIDIAN:0)
Block(0,28,-2,OBSIDIAN:0)
Block(0,28,-1,OBSIDIAN:0)
Block(0,28,0,OBSIDIAN:0)
Block(0,28,1,OBSIDIAN:0)
Block(0,28,2,OBSIDIAN:0)
Block(0,28,3,OBSIDIAN:0)
Block(0,28,4,STAINED_CLAY:3)
Block(0,28,5,STAINED_CLAY:3)
Block(0,29,-4,OBSIDIAN:0)
Block(0,29,-3,OBSIDIAN:0)
Block(0,29,-2,OBSIDIAN:0)
Block(0,29,-1,OBSIDIAN:0)
Block(0,29,0,OBSIDIAN:0)
Block(0,29,1,OBSIDIAN:0)
Block(0,29,2,OBSIDIAN:0)
Block(0,29,3,OBSIDIAN:0)
Block(0,29,4,STAINED_CLAY:3)
Block(0,30,-4,OBSIDIAN:0)
Block(0,30,-3,OBSIDIAN:0)
Block(0,30,-2,OBSIDIAN:0)
Block(0,30,-1,OBSIDIAN:0)
Block(0,30,0,OBSIDIAN:0)
Block(0,30,1,OBSIDIAN:0)
Block(0,30,2,OBSIDIAN:0)
Block(0,30,3,STAINED_CLAY:3)
Block(0,30,4,STAINED_CLAY:3)
Block(0,31,-4,OBSIDIAN:0)
Block(0,31,-3,OBSIDIAN:0)
Block(0,31,-2,OBSIDIAN:0)
Block(0,31,-1,OBSIDIAN:0)
Block(0,31,0,OBSIDIAN:0)
Block(0,31,1,OBSIDIAN:0)
Block(0,31,2,STAINED_CLAY:3)
Block(0,31,3,STAINED_CLAY:3)
Block(0,31,4,STAINED_CLAY:3)
Block(0,32,-4,OBSIDIAN:0)
Block(0,32,-3,OBSIDIAN:0)
Block(0,32,-2,OBSIDIAN:0)
Block(0,32,-1,OBSIDIAN:0)
Block(0,32,0,STAINED_CLAY:3)
Block(0,32,1,STAINED_CLAY:3)
Block(0,32,2,STAINED_CLAY:3)
Block(0,32,3,STAINED_CLAY:3)
Block(1,0,-6,STAINED_CLAY:3)
Block(1,0,-5,STAINED_CLAY:3)
Block(1,0,-4,STAINED_CLAY:3)
Block(1,0,-3,OBSIDIAN:0)
Block(1,0,-2,OBSIDIAN:0)
Block(1,0,-1,OBSIDIAN:0)
Block(1,0,0,STAINED_CLAY:3)
Block(1,0,1,STAINED_CLAY:3)
Block(1,0,2,STAINED_CLAY:3)
Block(1,0,3,STAINED_CLAY:3)
Block(1,0,4,STAINED_CLAY:3)
Block(1,0,5,STAINED_CLAY:3)
Block(1,0,6,STAINED_CLAY:3)
Block(1,0,7,STAINED_CLAY:3)
Block(1,0,8,STAINED_CLAY:3)
Block(1,1,-6,OBSIDIAN:0)
Block(1,1,-5,OBSIDIAN:0)
Block(1,1,-4,OBSIDIAN:0)
Block(1,1,-3,OBSIDIAN:0)
Block(1,1,-2,OBSIDIAN:0)
Block(1,1,-1,OBSIDIAN:0)
Block(1,1,0,STAINED_CLAY:3)
Block(1,1,1,STAINED_CLAY:3)
Block(1,1,2,STAINED_CLAY:3)
Block(1,1,3,STAINED_CLAY:3)
Block(1,1,4,STAINED_CLAY:3)
Block(1,1,5,STAINED_CLAY:3)
Block(1,1,6,STAINED_CLAY:3)
Block(1,1,7,STAINED_CLAY:3)
Block(1,1,8,STAINED_CLAY:3)
Block(1,2,-6,OBSIDIAN:0)
Block(1,2,-5,OBSIDIAN:0)
Block(1,2,-4,OBSIDIAN:0)
Block(1,2,-3,OBSIDIAN:0)
Block(1,2,-2,OBSIDIAN:0)
Block(1,2,-1,OBSIDIAN:0)
Block(1,2,0,STAINED_CLAY:3)
Block(1,2,1,STAINED_CLAY:3)
Block(1,2,2,STAINED_CLAY:3)
Block(1,2,3,STAINED_CLAY:3)
Block(1,2,4,STAINED_CLAY:3)
Block(1,2,5,STAINED_CLAY:3)
Block(1,2,6,STAINED_CLAY:3)
Block(1,2,7,STAINED_CLAY:3)
Block(1,2,8,STAINED_CLAY:3)
Block(1,3,-6,OBSIDIAN:0)
Block(1,3,-5,OBSIDIAN:0)
Block(1,3,-4,OBSIDIAN:0)
Block(1,3,-3,OBSIDIAN:0)
Block(1,3,-2,OBSIDIAN:0)
Block(1,3,-1,STAINED_CLAY:3)
Block(1,3,0,STAINED_CLAY:3)
Block(1,3,1,STAINED_CLAY:3)
Block(1,3,2,STAINED_CLAY:3)
Block(1,3,3,STAINED_CLAY:3)
Block(1,3,4,STAINED_CLAY:3)
Block(1,3,5,STAINED_CLAY:3)
Block(1,3,6,STAINED_CLAY:3)
Block(1,3,7,STAINED_CLAY:3)
Block(1,3,8,STAINED_CLAY:3)
Block(1,4,-6,OBSIDIAN:0)
Block(1,4,-5,OBSIDIAN:0)
Block(1,4,-4,OBSIDIAN:0)
Block(1,4,-3,OBSIDIAN:0)
Block(1,4,-2,OBSIDIAN:0)
Block(1,4,-1,STAINED_CLAY:3)
Block(1,4,0,STAINED_CLAY:3)
Block(1,4,1,STAINED_CLAY:3)
Block(1,4,2,STAINED_CLAY:3)
Block(1,4,3,STAINED_CLAY:3)
Block(1,4,4,STAINED_CLAY:3)
Block(1,4,5,STAINED_CLAY:3)
Block(1,4,6,STAINED_CLAY:3)
Block(1,4,7,STAINED_CLAY:3)
Block(1,4,8,STAINED_CLAY:3)
Block(1,5,-6,OBSIDIAN:0)
Block(1,5,-5,OBSIDIAN:0)
Block(1,5,-4,OBSIDIAN:0)
Block(1,5,-3,OBSIDIAN:0)
Block(1,5,-2,OBSIDIAN:0)
Block(1,5,-1,STAINED_CLAY:3)
Block(1,5,0,STAINED_CLAY:3)
Block(1,5,1,STAINED_CLAY:3)
Block(1,5,2,STAINED_CLAY:3)
Block(1,5,3,STAINED_CLAY:3)
Block(1,5,4,STAINED_CLAY:3)
Block(1,5,5,STAINED_CLAY:3)
Block(1,5,6,STAINED_CLAY:3)
Block(1,5,7,STAINED_CLAY:3)
Block(1,5,8,STAINED_CLAY:3)
Block(1,6,-6,OBSIDIAN:0)
Block(1,6,-5,OBSIDIAN:0)
Block(1,6,-4,OBSIDIAN:0)
Block(1,6,-3,OBSIDIAN:0)
Block(1,6,-2,STAINED_CLAY:3)
Block(1,6,-1,STAINED_CLAY:3)
Block(1,6,0,STAINED_CLAY:3)
Block(1,6,1,STAINED_CLAY:3)
Block(1,6,2,STAINED_CLAY:3)
Block(1,6,3,STAINED_CLAY:3)
Block(1,6,4,STAINED_CLAY:3)
Block(1,6,5,STAINED_CLAY:3)
Block(1,6,6,STAINED_CLAY:3)
Block(1,6,7,STAINED_CLAY:3)
Block(1,6,8,STAINED_CLAY:3)
Block(1,7,-6,OBSIDIAN:0)
Block(1,7,-5,OBSIDIAN:0)
Block(1,7,-4,OBSIDIAN:0)
Block(1,7,-3,OBSIDIAN:0)
Block(1,7,-2,STAINED_CLAY:3)
Block(1,7,-1,STAINED_CLAY:3)
Block(1,7,0,STAINED_CLAY:3)
Block(1,7,1,STAINED_CLAY:3)
Block(1,7,2,STAINED_CLAY:3)
Block(1,7,3,STAINED_CLAY:3)
Block(1,7,4,STAINED_CLAY:3)
Block(1,7,5,STAINED_CLAY:3)
Block(1,7,6,STAINED_CLAY:3)
Block(1,7,7,STAINED_CLAY:3)
Block(1,7,8,STAINED_CLAY:3)
Block(1,8,-6,OBSIDIAN:0)
Block(1,8,-5,OBSIDIAN:0)
Block(1,8,-4,OBSIDIAN:0)
Block(1,8,-3,STAINED_CLAY:3)
Block(1,8,-2,STAINED_CLAY:3)
Block(1,8,-1,STAINED_CLAY:3)
Block(1,8,0,STAINED_CLAY:3)
Block(1,8,1,STAINED_CLAY:3)
Block(1,8,2,STAINED_CLAY:3)
Block(1,8,3,STAINED_CLAY:3)
Block(1,8,4,STAINED_CLAY:3)
Block(1,8,5,STAINED_CLAY:3)
Block(1,8,6,STAINED_CLAY:3)
Block(1,8,7,STAINED_CLAY:3)
Block(1,8,8,STAINED_CLAY:3)
Block(1,9,-6,OBSIDIAN:0)
Block(1,9,-5,OBSIDIAN:0)
Block(1,9,-4,OBSIDIAN:0)
Block(1,9,-3,STAINED_CLAY:3)
Block(1,9,-2,STAINED_CLAY:3)
Block(1,9,-1,STAINED_CLAY:3)
Block(1,9,0,STAINED_CLAY:3)
Block(1,9,1,STAINED_CLAY:3)
Block(1,9,2,STAINED_CLAY:3)
Block(1,9,3,STAINED_CLAY:3)
Block(1,9,4,STAINED_CLAY:3)
Block(1,9,5,STAINED_CLAY:3)
Block(1,9,6,STAINED_CLAY:3)
Block(1,9,7,STAINED_CLAY:3)
Block(1,9,8,STAINED_CLAY:3)
Block(1,10,-6,OBSIDIAN:0)
Block(1,10,-5,OBSIDIAN:0)
Block(1,10,-4,STAINED_CLAY:3)
Block(1,10,-3,STAINED_CLAY:3)
Block(1,10,-2,STAINED_CLAY:3)
Block(1,10,-1,STAINED_CLAY:3)
Block(1,10,0,STAINED_CLAY:3)
Block(1,10,1,STAINED_CLAY:3)
Block(1,10,2,STAINED_CLAY:3)
Block(1,10,3,STAINED_CLAY:3)
Block(1,10,4,STAINED_CLAY:3)
Block(1,10,5,STAINED_CLAY:3)
Block(1,10,6,STAINED_CLAY:3)
Block(1,10,7,STAINED_CLAY:3)
Block(1,10,8,OBSIDIAN:0)
Block(1,11,-6,OBSIDIAN:0)
Block(1,11,-5,STAINED_CLAY:3)
Block(1,11,-4,STAINED_CLAY:3)
Block(1,11,-3,STAINED_CLAY:3)
Block(1,11,-2,STAINED_CLAY:3)
Block(1,11,-1,STAINED_CLAY:3)
Block(1,11,0,STAINED_CLAY:3)
Block(1,11,1,STAINED_CLAY:3)
Block(1,11,2,STAINED_CLAY:3)
Block(1,11,3,STAINED_CLAY:3)
Block(1,11,4,STAINED_CLAY:3)
Block(1,11,5,STAINED_CLAY:3)
Block(1,11,6,STAINED_CLAY:3)
Block(1,11,7,OBSIDIAN:0)
Block(1,11,8,OBSIDIAN:0)
Block(1,12,-6,STAINED_CLAY:3)
Block(1,12,-5,STAINED_CLAY:3)
Block(1,12,-4,STAINED_CLAY:3)
Block(1,12,-3,STAINED_CLAY:3)
Block(1,12,-2,STAINED_CLAY:3)
Block(1,12,-1,STAINED_CLAY:3)
Block(1,12,0,STAINED_CLAY:3)
Block(1,12,1,STAINED_CLAY:3)
Block(1,12,2,STAINED_CLAY:3)
Block(1,12,3,STAINED_CLAY:3)
Block(1,12,4,STAINED_CLAY:3)
Block(1,12,5,STAINED_CLAY:3)
Block(1,12,6,STAINED_CLAY:3)
Block(1,12,7,OBSIDIAN:0)
Block(1,12,8,OBSIDIAN:0)
Block(1,13,-6,STAINED_CLAY:3)
Block(1,13,-5,STAINED_CLAY:3)
Block(1,13,-4,STAINED_CLAY:3)
Block(1,13,-3,STAINED_CLAY:3)
Block(1,13,-2,STAINED_CLAY:3)
Block(1,13,-1,STAINED_CLAY:3)
Block(1,13,0,STAINED_CLAY:3)
Block(1,13,1,STAINED_CLAY:3)
Block(1,13,2,STAINED_CLAY:3)
Block(1,13,3,STAINED_CLAY:3)
Block(1,13,4,STAINED_CLAY:3)
Block(1,13,5,STAINED_CLAY:3)
Block(1,13,6,STAINED_CLAY:3)
Block(1,13,7,OBSIDIAN:0)
Block(1,13,8,OBSIDIAN:0)
Block(1,14,-6,STAINED_CLAY:3)
Block(1,14,-5,STAINED_CLAY:3)
Block(1,14,-4,STAINED_CLAY:3)
Block(1,14,-3,STAINED_CLAY:3)
Block(1,14,-2,STAINED_CLAY:3)
Block(1,14,-1,STAINED_CLAY:3)
Block(1,14,0,STAINED_CLAY:3)
Block(1,14,1,STAINED_CLAY:3)
Block(1,14,2,STAINED_CLAY:3)
Block(1,14,3,STAINED_CLAY:3)
Block(1,14,4,STAINED_CLAY:3)
Block(1,14,5,STAINED_CLAY:3)
Block(1,14,6,STAINED_CLAY:3)
Block(1,14,7,STAINED_CLAY:3)
Block(1,14,8,OBSIDIAN:0)
Block(1,15,-6,STAINED_CLAY:3)
Block(1,15,-5,STAINED_CLAY:3)
Block(1,15,-4,STAINED_CLAY:3)
Block(1,15,-3,STAINED_CLAY:3)
Block(1,15,-2,STAINED_CLAY:3)
Block(1,15,-1,STAINED_CLAY:3)
Block(1,15,0,STAINED_CLAY:3)
Block(1,15,1,STAINED_CLAY:3)
Block(1,15,2,STAINED_CLAY:3)
Block(1,15,3,STAINED_CLAY:3)
Block(1,15,4,STAINED_CLAY:3)
Block(1,15,5,STAINED_CLAY:3)
Block(1,15,6,STAINED_CLAY:3)
Block(1,15,7,STAINED_CLAY:3)
Block(1,15,8,OBSIDIAN:0)
Block(1,16,-6,STAINED_CLAY:3)
Block(1,16,-5,STAINED_CLAY:3)
Block(1,16,-4,STAINED_CLAY:3)
Block(1,16,-3,STAINED_CLAY:3)
Block(1,16,-2,STAINED_CLAY:3)
Block(1,16,-1,STAINED_CLAY:3)
Block(1,16,0,STAINED_CLAY:3)
Block(1,16,1,STAINED_CLAY:3)
Block(1,16,2,STAINED_CLAY:3)
Block(1,16,3,STAINED_CLAY:3)
Block(1,16,4,STAINED_CLAY:3)
Block(1,16,5,STAINED_CLAY:3)
Block(1,16,6,STAINED_CLAY:3)
Block(1,16,7,STAINED_CLAY:3)
Block(1,16,8,OBSIDIAN:0)
Block(1,17,-6,STAINED_CLAY:3)
Block(1,17,-5,STAINED_CLAY:3)
Block(1,17,-4,STAINED_CLAY:3)
Block(1,17,-3,STAINED_CLAY:3)
Block(1,17,-2,STAINED_CLAY:3)
Block(1,17,-1,STAINED_CLAY:3)
Block(1,17,0,STAINED_CLAY:3)
Block(1,17,1,STAINED_CLAY:3)
Block(1,17,2,STAINED_CLAY:3)
Block(1,17,3,STAINED_CLAY:3)
Block(1,17,4,STAINED_CLAY:3)
Block(1,17,5,STAINED_CLAY:3)
Block(1,17,6,STAINED_CLAY:3)
Block(1,17,7,STAINED_CLAY:3)
Block(1,17,8,STAINED_CLAY:3)
Block(1,18,-5,STAINED_CLAY:3)
Block(1,18,-4,STAINED_CLAY:3)
Block(1,18,-3,STAINED_CLAY:3)
Block(1,18,-2,STAINED_CLAY:3)
Block(1,18,-1,STAINED_CLAY:3)
Block(1,18,0,STAINED_CLAY:3)
Block(1,18,1,STAINED_CLAY:3)
Block(1,18,2,STAINED_CLAY:3)
Block(1,18,3,STAINED_CLAY:3)
Block(1,18,4,STAINED_CLAY:3)
Block(1,18,5,STAINED_CLAY:3)
Block(1,18,6,STAINED_CLAY:3)
Block(1,18,7,STAINED_CLAY:3)
Block(1,18,8,STAINED_CLAY:3)
Block(1,19,-5,STAINED_CLAY:3)
Block(1,19,-4,STAINED_CLAY:3)
Block(1,19,-3,STAINED_CLAY:3)
Block(1,19,-2,STAINED_CLAY:3)
Block(1,19,-1,STAINED_CLAY:3)
Block(1,19,0,STAINED_CLAY:3)
Block(1,19,1,STAINED_CLAY:3)
Block(1,19,2,STAINED_CLAY:3)
Block(1,19,3,STAINED_CLAY:3)
Block(1,19,4,STAINED_CLAY:3)
Block(1,19,5,STAINED_CLAY:3)
Block(1,19,6,STAINED_CLAY:3)
Block(1,19,7,STAINED_CLAY:3)
Block(1,19,8,STAINED_CLAY:3)
Block(1,20,-5,STAINED_CLAY:3)
Block(1,20,-4,STAINED_CLAY:3)
Block(1,20,-3,STAINED_CLAY:3)
Block(1,20,-2,STAINED_CLAY:3)
Block(1,20,-1,STAINED_CLAY:3)
Block(1,20,0,STAINED_CLAY:3)
Block(1,20,1,STAINED_CLAY:3)
Block(1,20,2,OBSIDIAN:0)
Block(1,20,3,OBSIDIAN:0)
Block(1,20,4,OBSIDIAN:0)
Block(1,20,5,OBSIDIAN:0)
Block(1,20,6,OBSIDIAN:0)
Block(1,20,7,STAINED_CLAY:3)
Block(1,20,8,STAINED_CLAY:3)
Block(1,21,-5,STAINED_CLAY:3)
Block(1,21,-4,STAINED_CLAY:3)
Block(1,21,-3,STAINED_CLAY:3)
Block(1,21,-2,STAINED_CLAY:3)
Block(1,21,-1,STAINED_CLAY:3)
Block(1,21,0,STAINED_CLAY:3)
Block(1,21,1,STAINED_CLAY:3)
Block(1,21,2,OBSIDIAN:0)
Block(1,21,3,OBSIDIAN:0)
Block(1,21,4,OBSIDIAN:0)
Block(1,21,5,OBSIDIAN:0)
Block(1,21,6,OBSIDIAN:0)
Block(1,21,7,STAINED_CLAY:3)
Block(1,22,-5,STAINED_CLAY:3)
Block(1,22,-4,STAINED_CLAY:3)
Block(1,22,-3,STAINED_CLAY:3)
Block(1,22,-2,STAINED_CLAY:3)
Block(1,22,-1,STAINED_CLAY:3)
Block(1,22,0,STAINED_CLAY:3)
Block(1,22,1,STAINED_CLAY:3)
Block(1,22,2,OBSIDIAN:0)
Block(1,22,3,OBSIDIAN:0)
Block(1,22,4,OBSIDIAN:0)
Block(1,22,5,OBSIDIAN:0)
Block(1,22,6,OBSIDIAN:0)
Block(1,22,7,STAINED_CLAY:3)
Block(1,23,-5,STAINED_CLAY:3)
Block(1,23,-4,STAINED_CLAY:3)
Block(1,23,-3,STAINED_CLAY:3)
Block(1,23,-2,STAINED_CLAY:3)
Block(1,23,-1,STAINED_CLAY:3)
Block(1,23,0,OBSIDIAN:0)
Block(1,23,1,OBSIDIAN:0)
Block(1,23,2,OBSIDIAN:0)
Block(1,23,3,OBSIDIAN:0)
Block(1,23,4,OBSIDIAN:0)
Block(1,23,5,OBSIDIAN:0)
Block(1,23,6,OBSIDIAN:0)
Block(1,23,7,STAINED_CLAY:3)
Block(1,24,-5,STAINED_CLAY:3)
Block(1,24,-4,STAINED_CLAY:3)
Block(1,24,-3,STAINED_CLAY:3)
Block(1,24,-2,STAINED_CLAY:3)
Block(1,24,-1,STAINED_CLAY:3)
Block(1,24,0,OBSIDIAN:0)
Block(1,24,1,OBSIDIAN:0)
Block(1,24,2,OBSIDIAN:0)
Block(1,24,3,OBSIDIAN:0)
Block(1,24,4,OBSIDIAN:0)
Block(1,24,5,OBSIDIAN:0)
Block(1,24,6,OBSIDIAN:0)
Block(1,25,-5,STAINED_CLAY:3)
Block(1,25,-4,STAINED_CLAY:3)
Block(1,25,-3,STAINED_CLAY:3)
Block(1,25,-2,STAINED_CLAY:3)
Block(1,25,-1,OBSIDIAN:0)
Block(1,25,0,OBSIDIAN:0)
Block(1,25,1,OBSIDIAN:0)
Block(1,25,2,OBSIDIAN:0)
Block(1,25,3,OBSIDIAN:0)
Block(1,25,4,OBSIDIAN:0)
Block(1,25,5,STAINED_CLAY:3)
Block(1,25,6,STAINED_CLAY:3)
Block(1,26,-5,STAINED_CLAY:3)
Block(1,26,-4,STAINED_CLAY:3)
Block(1,26,-3,OBSIDIAN:0)
Block(1,26,-2,OBSIDIAN:0)
Block(1,26,-1,OBSIDIAN:0)
Block(1,26,0,OBSIDIAN:0)
Block(1,26,1,OBSIDIAN:0)
Block(1,26,2,OBSIDIAN:0)
Block(1,26,3,OBSIDIAN:0)
Block(1,26,4,OBSIDIAN:0)
Block(1,26,5,STAINED_CLAY:3)
Block(1,26,6,STAINED_CLAY:3)
Block(1,27,-5,STAINED_CLAY:3)
Block(1,27,-4,OBSIDIAN:0)
Block(1,27,-3,OBSIDIAN:0)
Block(1,27,-2,OBSIDIAN:0)
Block(1,27,-1,OBSIDIAN:0)
Block(1,27,0,OBSIDIAN:0)
Block(1,27,1,OBSIDIAN:0)
Block(1,27,2,OBSIDIAN:0)
Block(1,27,3,OBSIDIAN:0)
Block(1,27,4,OBSIDIAN:0)
Block(1,27,5,STAINED_CLAY:3)
Block(1,28,-5,OBSIDIAN:0)
Block(1,28,-4,OBSIDIAN:0)
Block(1,28,-3,OBSIDIAN:0)
Block(1,28,-2,OBSIDIAN:0)
Block(1,28,-1,OBSIDIAN:0)
Block(1,28,0,OBSIDIAN:0)
Block(1,28,1,OBSIDIAN:0)
Block(1,28,2,OBSIDIAN:0)
Block(1,28,3,OBSIDIAN:0)
Block(1,28,4,STAINED_CLAY:3)
Block(1,28,5,STAINED_CLAY:3)
Block(1,29,-5,OBSIDIAN:0)
Block(1,29,-4,OBSIDIAN:0)
Block(1,29,-3,OBSIDIAN:0)
Block(1,29,-2,OBSIDIAN:0)
Block(1,29,-1,OBSIDIAN:0)
Block(1,29,0,OBSIDIAN:0)
Block(1,29,1,OBSIDIAN:0)
Block(1,29,2,OBSIDIAN:0)
Block(1,29,3,OBSIDIAN:0)
Block(1,29,4,STAINED_CLAY:3)
Block(1,29,5,STAINED_CLAY:3)
Block(1,30,-5,OBSIDIAN:0)
Block(1,30,-4,OBSIDIAN:0)
Block(1,30,-3,OBSIDIAN:0)
Block(1,30,-2,OBSIDIAN:0)
Block(1,30,-1,OBSIDIAN:0)
Block(1,30,0,OBSIDIAN:0)
Block(1,30,1,OBSIDIAN:0)
Block(1,30,2,OBSIDIAN:0)
Block(1,30,3,STAINED_CLAY:3)
Block(1,30,4,STAINED_CLAY:3)
Block(1,31,-5,OBSIDIAN:0)
Block(1,31,-4,OBSIDIAN:0)
Block(1,31,-3,OBSIDIAN:0)
Block(1,31,-2,OBSIDIAN:0)
Block(1,31,-1,OBSIDIAN:0)
Block(1,31,0,OBSIDIAN:0)
Block(1,31,1,OBSIDIAN:0)
Block(1,31,2,STAINED_CLAY:3)
Block(1,31,3,STAINED_CLAY:3)
Block(1,31,4,STAINED_CLAY:3)
Block(1,32,-5,OBSIDIAN:0)
Block(1,32,-4,OBSIDIAN:0)
Block(1,32,-3,OBSIDIAN:0)
Block(1,32,-2,OBSIDIAN:0)
Block(1,32,-1,OBSIDIAN:0)
Block(1,32,0,STAINED_CLAY:3)
Block(1,32,1,STAINED_CLAY:3)
Block(1,32,2,STAINED_CLAY:3)
Block(1,32,3,STAINED_CLAY:3)
Block(1,33,-5,OBSIDIAN:0)
Block(1,33,-4,OBSIDIAN:0)
Block(1,33,-3,OBSIDIAN:0)
Block(1,33,-2,OBSIDIAN:0)
Block(1,33,-1,OBSIDIAN:0)
Block(1,33,0,STAINED_CLAY:3)
Block(1,33,1,STAINED_CLAY:3)
Block(1,33,2,STAINED_CLAY:3)
Block(1,33,3,STAINED_CLAY:3)
Block(1,34,-5,OBSIDIAN:0)
Block(1,34,-4,OBSIDIAN:0)
Block(1,34,-3,OBSIDIAN:0)
Block(1,34,-2,OBSIDIAN:0)
Block(1,34,-1,STAINED_CLAY:3)
Block(1,34,0,STAINED_CLAY:3)
Block(1,34,1,STAINED_CLAY:3)
Block(1,34,2,STAINED_CLAY:3)
Block(1,34,3,STAINED_CLAY:3)
Block(1,35,-5,OBSIDIAN:0)
Block(1,35,-4,OBSIDIAN:0)
Block(1,35,-3,OBSIDIAN:0)
Block(1,35,-2,STAINED_CLAY:3)
Block(1,35,-1,STAINED_CLAY:3)
Block(1,35,0,STAINED_CLAY:3)
Block(1,35,1,STAINED_CLAY:3)
Block(1,35,2,STAINED_CLAY:3)
Block(1,36,-5,STAINED_CLAY:3)
Block(1,36,-4,STAINED_CLAY:3)
Block(1,36,-3,STAINED_CLAY:3)
Block(1,36,-2,STAINED_CLAY:3)
Block(1,36,-1,STAINED_CLAY:3)
Block(1,36,0,STAINED_CLAY:3)
Block(1,36,1,STAINED_CLAY:3)
Block(1,36,2,STAINED_CLAY:3)
Block(2,0,-7,STAINED_CLAY:3)
Block(2,0,-6,STAINED_CLAY:3)
Block(2,0,-5,STAINED_CLAY:3)
Block(2,0,-4,STAINED_CLAY:3)
Block(2,0,-3,STAINED_CLAY:3)
Block(2,0,-2,STAINED_CLAY:3)
Block(2,0,-1,STAINED_CLAY:3)
Block(2,0,0,STAINED_CLAY:3)
Block(2,0,1,STAINED_CLAY:3)
Block(2,0,2,STAINED_CLAY:3)
Block(2,0,3,STAINED_CLAY:3)
Block(2,0,4,STAINED_CLAY:3)
Block(2,0,5,STAINED_CLAY:3)
Block(2,0,6,STAINED_CLAY:3)
Block(2,0,7,STAINED_CLAY:3)
Block(2,0,8,STAINED_CLAY:3)
Block(2,1,-7,STAINED_CLAY:3)
Block(2,1,-6,STAINED_CLAY:3)
Block(2,1,-5,STAINED_CLAY:3)
Block(2,1,-4,STAINED_CLAY:3)
Block(2,1,-3,STAINED_CLAY:3)
Block(2,1,-2,STAINED_CLAY:3)
Block(2,1,-1,STAINED_CLAY:3)
Block(2,1,0,STAINED_CLAY:3)
Block(2,1,1,STAINED_CLAY:3)
Block(2,1,2,STAINED_CLAY:3)
Block(2,1,3,STAINED_CLAY:3)
Block(2,1,4,STAINED_CLAY:3)
Block(2,1,5,STAINED_CLAY:3)
Block(2,1,6,STAINED_CLAY:3)
Block(2,1,7,STAINED_CLAY:3)
Block(2,1,8,STAINED_CLAY:3)
Block(2,2,-7,OBSIDIAN:0)
Block(2,2,-6,OBSIDIAN:0)
Block(2,2,-5,OBSIDIAN:0)
Block(2,2,-4,OBSIDIAN:0)
Block(2,2,-3,OBSIDIAN:0)
Block(2,2,-2,STAINED_CLAY:3)
Block(2,2,-1,STAINED_CLAY:3)
Block(2,2,0,STAINED_CLAY:3)
Block(2,2,1,STAINED_CLAY:3)
Block(2,2,2,STAINED_CLAY:3)
Block(2,2,3,STAINED_CLAY:3)
Block(2,2,4,STAINED_CLAY:3)
Block(2,2,5,STAINED_CLAY:3)
Block(2,2,6,STAINED_CLAY:3)
Block(2,2,7,STAINED_CLAY:3)
Block(2,2,8,STAINED_CLAY:3)
Block(2,3,-7,OBSIDIAN:0)
Block(2,3,-6,OBSIDIAN:0)
Block(2,3,-5,OBSIDIAN:0)
Block(2,3,-4,OBSIDIAN:0)
Block(2,3,-3,OBSIDIAN:0)
Block(2,3,-2,STAINED_CLAY:3)
Block(2,3,-1,STAINED_CLAY:3)
Block(2,3,0,STAINED_CLAY:3)
Block(2,3,1,STAINED_CLAY:3)
Block(2,3,2,STAINED_CLAY:3)
Block(2,3,3,STAINED_CLAY:3)
Block(2,3,4,STAINED_CLAY:3)
Block(2,3,5,STAINED_CLAY:3)
Block(2,3,6,STAINED_CLAY:3)
Block(2,3,7,STAINED_CLAY:3)
Block(2,3,8,STAINED_CLAY:3)
Block(2,4,-7,OBSIDIAN:0)
Block(2,4,-6,OBSIDIAN:0)
Block(2,4,-5,OBSIDIAN:0)
Block(2,4,-4,OBSIDIAN:0)
Block(2,4,-3,OBSIDIAN:0)
Block(2,4,-2,STAINED_CLAY:3)
Block(2,4,-1,STAINED_CLAY:3)
Block(2,4,0,STAINED_CLAY:3)
Block(2,4,1,STAINED_CLAY:3)
Block(2,4,2,STAINED_CLAY:3)
Block(2,4,3,STAINED_CLAY:3)
Block(2,4,4,STAINED_CLAY:3)
Block(2,4,5,STAINED_CLAY:3)
Block(2,4,6,STAINED_CLAY:3)
Block(2,4,7,STAINED_CLAY:3)
Block(2,4,8,STAINED_CLAY:3)
Block(2,5,-7,OBSIDIAN:0)
Block(2,5,-6,OBSIDIAN:0)
Block(2,5,-5,OBSIDIAN:0)
Block(2,5,-4,OBSIDIAN:0)
Block(2,5,-3,OBSIDIAN:0)
Block(2,5,-2,STAINED_CLAY:3)
Block(2,5,-1,STAINED_CLAY:3)
Block(2,5,0,STAINED_CLAY:3)
Block(2,5,1,STAINED_CLAY:3)
Block(2,5,2,STAINED_CLAY:3)
Block(2,5,3,STAINED_CLAY:3)
Block(2,5,4,STAINED_CLAY:3)
Block(2,5,5,STAINED_CLAY:3)
Block(2,5,6,STAINED_CLAY:3)
Block(2,5,7,STAINED_CLAY:3)
Block(2,5,8,STAINED_CLAY:3)
Block(2,6,-7,OBSIDIAN:0)
Block(2,6,-6,OBSIDIAN:0)
Block(2,6,-5,OBSIDIAN:0)
Block(2,6,-4,OBSIDIAN:0)
Block(2,6,-3,OBSIDIAN:0)
Block(2,6,-2,STAINED_CLAY:3)
Block(2,6,-1,STAINED_CLAY:3)
Block(2,6,0,STAINED_CLAY:3)
Block(2,6,1,STAINED_CLAY:3)
Block(2,6,2,STAINED_CLAY:3)
Block(2,6,3,STAINED_CLAY:3)
Block(2,6,4,STAINED_CLAY:3)
Block(2,6,5,STAINED_CLAY:3)
Block(2,6,6,STAINED_CLAY:3)
Block(2,6,7,STAINED_CLAY:3)
Block(2,6,8,STAINED_CLAY:3)
Block(2,7,-7,OBSIDIAN:0)
Block(2,7,-6,OBSIDIAN:0)
Block(2,7,-5,OBSIDIAN:0)
Block(2,7,-4,OBSIDIAN:0)
Block(2,7,-3,OBSIDIAN:0)
Block(2,7,-2,STAINED_CLAY:3)
Block(2,7,-1,STAINED_CLAY:3)
Block(2,7,0,STAINED_CLAY:3)
Block(2,7,1,STAINED_CLAY:3)
Block(2,7,2,STAINED_CLAY:3)
Block(2,7,3,STAINED_CLAY:3)
Block(2,7,4,STAINED_CLAY:3)
Block(2,7,5,STAINED_CLAY:3)
Block(2,7,6,STAINED_CLAY:3)
Block(2,7,7,STAINED_CLAY:3)
Block(2,7,8,STAINED_CLAY:3)
Block(2,8,-7,OBSIDIAN:0)
Block(2,8,-6,OBSIDIAN:0)
Block(2,8,-5,OBSIDIAN:0)
Block(2,8,-4,OBSIDIAN:0)
Block(2,8,-3,STAINED_CLAY:3)
Block(2,8,-2,STAINED_CLAY:3)
Block(2,8,-1,STAINED_CLAY:3)
Block(2,8,0,STAINED_CLAY:3)
Block(2,8,1,STAINED_CLAY:3)
Block(2,8,2,STAINED_CLAY:3)
Block(2,8,3,STAINED_CLAY:3)
Block(2,8,4,STAINED_CLAY:3)
Block(2,8,5,STAINED_CLAY:3)
Block(2,8,6,STAINED_CLAY:3)
Block(2,8,7,STAINED_CLAY:3)
Block(2,8,8,STAINED_CLAY:3)
Block(2,9,-7,OBSIDIAN:0)
Block(2,9,-6,OBSIDIAN:0)
Block(2,9,-5,OBSIDIAN:0)
Block(2,9,-4,OBSIDIAN:0)
Block(2,9,-3,STAINED_CLAY:3)
Block(2,9,-2,STAINED_CLAY:3)
Block(2,9,-1,STAINED_CLAY:3)
Block(2,9,0,STAINED_CLAY:3)
Block(2,9,1,STAINED_CLAY:3)
Block(2,9,2,STAINED_CLAY:3)
Block(2,9,3,STAINED_CLAY:3)
Block(2,9,4,STAINED_CLAY:3)
Block(2,9,5,STAINED_CLAY:3)
Block(2,9,6,STAINED_CLAY:3)
Block(2,9,7,STAINED_CLAY:3)
Block(2,9,8,STAINED_CLAY:3)
Block(2,10,-7,OBSIDIAN:0)
Block(2,10,-6,OBSIDIAN:0)
Block(2,10,-5,OBSIDIAN:0)
Block(2,10,-4,STAINED_CLAY:3)
Block(2,10,-3,STAINED_CLAY:3)
Block(2,10,-2,STAINED_CLAY:3)
Block(2,10,-1,STAINED_CLAY:3)
Block(2,10,0,STAINED_CLAY:3)
Block(2,10,1,STAINED_CLAY:3)
Block(2,10,2,STAINED_CLAY:3)
Block(2,10,3,STAINED_CLAY:3)
Block(2,10,4,STAINED_CLAY:3)
Block(2,10,5,STAINED_CLAY:3)
Block(2,10,6,STAINED_CLAY:3)
Block(2,10,7,STAINED_CLAY:3)
Block(2,10,8,OBSIDIAN:0)
Block(2,11,-7,OBSIDIAN:0)
Block(2,11,-6,OBSIDIAN:0)
Block(2,11,-5,STAINED_CLAY:3)
Block(2,11,-4,STAINED_CLAY:3)
Block(2,11,-3,STAINED_CLAY:3)
Block(2,11,-2,STAINED_CLAY:3)
Block(2,11,-1,STAINED_CLAY:3)
Block(2,11,0,STAINED_CLAY:3)
Block(2,11,1,STAINED_CLAY:3)
Block(2,11,2,STAINED_CLAY:3)
Block(2,11,3,STAINED_CLAY:3)
Block(2,11,4,STAINED_CLAY:3)
Block(2,11,5,STAINED_CLAY:3)
Block(2,11,6,STAINED_CLAY:3)
Block(2,11,7,STAINED_CLAY:3)
Block(2,11,8,OBSIDIAN:0)
Block(2,12,-7,STAINED_CLAY:3)
Block(2,12,-6,STAINED_CLAY:3)
Block(2,12,-5,STAINED_CLAY:3)
Block(2,12,-4,STAINED_CLAY:3)
Block(2,12,-3,STAINED_CLAY:3)
Block(2,12,-2,STAINED_CLAY:3)
Block(2,12,-1,STAINED_CLAY:3)
Block(2,12,0,STAINED_CLAY:3)
Block(2,12,1,STAINED_CLAY:3)
Block(2,12,2,STAINED_CLAY:3)
Block(2,12,3,STAINED_CLAY:3)
Block(2,12,4,STAINED_CLAY:3)
Block(2,12,5,STAINED_CLAY:3)
Block(2,12,6,STAINED_CLAY:3)
Block(2,12,7,STAINED_CLAY:3)
Block(2,12,8,OBSIDIAN:0)
Block(2,13,-7,STAINED_CLAY:3)
Block(2,13,-6,STAINED_CLAY:3)
Block(2,13,-5,STAINED_CLAY:3)
Block(2,13,-4,STAINED_CLAY:3)
Block(2,13,-3,STAINED_CLAY:3)
Block(2,13,-2,STAINED_CLAY:3)
Block(2,13,-1,STAINED_CLAY:3)
Block(2,13,0,STAINED_CLAY:3)
Block(2,13,1,STAINED_CLAY:3)
Block(2,13,2,STAINED_CLAY:3)
Block(2,13,3,STAINED_CLAY:3)
Block(2,13,4,STAINED_CLAY:3)
Block(2,13,5,STAINED_CLAY:3)
Block(2,13,6,STAINED_CLAY:3)
Block(2,13,7,STAINED_CLAY:3)
Block(2,13,8,OBSIDIAN:0)
Block(2,14,-7,STAINED_CLAY:3)
Block(2,14,-6,STAINED_CLAY:3)
Block(2,14,-5,STAINED_CLAY:3)
Block(2,14,-4,STAINED_CLAY:3)
Block(2,14,-3,STAINED_CLAY:3)
Block(2,14,-2,STAINED_CLAY:3)
Block(2,14,-1,STAINED_CLAY:3)
Block(2,14,0,STAINED_CLAY:3)
Block(2,14,1,STAINED_CLAY:3)
Block(2,14,2,STAINED_CLAY:3)
Block(2,14,3,STAINED_CLAY:3)
Block(2,14,4,STAINED_CLAY:3)
Block(2,14,5,STAINED_CLAY:3)
Block(2,14,6,STAINED_CLAY:3)
Block(2,14,7,STAINED_CLAY:3)
Block(2,14,8,OBSIDIAN:0)
Block(2,15,-7,STAINED_CLAY:3)
Block(2,15,-6,STAINED_CLAY:3)
Block(2,15,-5,STAINED_CLAY:3)
Block(2,15,-4,STAINED_CLAY:3)
Block(2,15,-3,STAINED_CLAY:3)
Block(2,15,-2,STAINED_CLAY:3)
Block(2,15,-1,STAINED_CLAY:3)
Block(2,15,0,STAINED_CLAY:3)
Block(2,15,1,STAINED_CLAY:3)
Block(2,15,2,STAINED_CLAY:3)
Block(2,15,3,STAINED_CLAY:3)
Block(2,15,4,STAINED_CLAY:3)
Block(2,15,5,STAINED_CLAY:3)
Block(2,15,6,STAINED_CLAY:3)
Block(2,15,7,STAINED_CLAY:3)
Block(2,15,8,STAINED_CLAY:3)
Block(2,16,-7,STAINED_CLAY:3)
Block(2,16,-6,STAINED_CLAY:3)
Block(2,16,-5,STAINED_CLAY:3)
Block(2,16,-4,STAINED_CLAY:3)
Block(2,16,-3,STAINED_CLAY:3)
Block(2,16,-2,STAINED_CLAY:3)
Block(2,16,-1,STAINED_CLAY:3)
Block(2,16,0,STAINED_CLAY:3)
Block(2,16,1,STAINED_CLAY:3)
Block(2,16,2,STAINED_CLAY:3)
Block(2,16,3,STAINED_CLAY:3)
Block(2,16,4,STAINED_CLAY:3)
Block(2,16,5,STAINED_CLAY:3)
Block(2,16,6,STAINED_CLAY:3)
Block(2,16,7,STAINED_CLAY:3)
Block(2,16,8,STAINED_CLAY:3)
Block(2,17,-7,STAINED_CLAY:3)
Block(2,17,-6,STAINED_CLAY:3)
Block(2,17,-5,STAINED_CLAY:3)
Block(2,17,-4,STAINED_CLAY:3)
Block(2,17,-3,STAINED_CLAY:3)
Block(2,17,-2,STAINED_CLAY:3)
Block(2,17,-1,STAINED_CLAY:3)
Block(2,17,0,STAINED_CLAY:3)
Block(2,17,1,STAINED_CLAY:3)
Block(2,17,2,STAINED_CLAY:3)
Block(2,17,3,STAINED_CLAY:3)
Block(2,17,4,STAINED_CLAY:3)
Block(2,17,5,STAINED_CLAY:3)
Block(2,17,6,STAINED_CLAY:3)
Block(2,17,7,STAINED_CLAY:3)
Block(2,17,8,STAINED_CLAY:3)
Block(2,18,-7,STAINED_CLAY:3)
Block(2,18,-6,STAINED_CLAY:3)
Block(2,18,-5,STAINED_CLAY:3)
Block(2,18,-4,STAINED_CLAY:3)
Block(2,18,-3,STAINED_CLAY:3)
Block(2,18,-2,STAINED_CLAY:3)
Block(2,18,-1,STAINED_CLAY:3)
Block(2,18,0,STAINED_CLAY:3)
Block(2,18,1,STAINED_CLAY:3)
Block(2,18,2,STAINED_CLAY:3)
Block(2,18,3,STAINED_CLAY:3)
Block(2,18,4,STAINED_CLAY:3)
Block(2,18,5,STAINED_CLAY:3)
Block(2,18,6,STAINED_CLAY:3)
Block(2,18,7,STAINED_CLAY:3)
Block(2,18,8,STAINED_CLAY:3)
Block(2,19,-7,STAINED_CLAY:3)
Block(2,19,-6,STAINED_CLAY:3)
Block(2,19,-5,STAINED_CLAY:3)
Block(2,19,-4,STAINED_CLAY:3)
Block(2,19,-3,STAINED_CLAY:3)
Block(2,19,-2,STAINED_CLAY:3)
Block(2,19,-1,STAINED_CLAY:3)
Block(2,19,0,STAINED_CLAY:3)
Block(2,19,1,STAINED_CLAY:3)
Block(2,19,2,STAINED_CLAY:3)
Block(2,19,3,STAINED_CLAY:3)
Block(2,19,4,STAINED_CLAY:3)
Block(2,19,5,STAINED_CLAY:3)
Block(2,19,6,STAINED_CLAY:3)
Block(2,19,7,STAINED_CLAY:3)
Block(2,19,8,STAINED_CLAY:3)
Block(2,20,-7,STAINED_CLAY:3)
Block(2,20,-6,STAINED_CLAY:3)
Block(2,20,-5,STAINED_CLAY:3)
Block(2,20,-4,STAINED_CLAY:3)
Block(2,20,-3,STAINED_CLAY:3)
Block(2,20,-2,STAINED_CLAY:3)
Block(2,20,-1,STAINED_CLAY:3)
Block(2,20,0,STAINED_CLAY:3)
Block(2,20,1,STAINED_CLAY:3)
Block(2,20,2,STAINED_CLAY:3)
Block(2,20,3,STAINED_CLAY:3)
Block(2,20,4,STAINED_CLAY:3)
Block(2,20,5,STAINED_CLAY:3)
Block(2,20,6,STAINED_CLAY:3)
Block(2,20,7,STAINED_CLAY:3)
Block(2,20,8,STAINED_CLAY:3)
Block(2,21,-7,STAINED_CLAY:3)
Block(2,21,-6,STAINED_CLAY:3)
Block(2,21,-5,STAINED_CLAY:3)
Block(2,21,-4,STAINED_CLAY:3)
Block(2,21,-3,STAINED_CLAY:3)
Block(2,21,-2,STAINED_CLAY:3)
Block(2,21,-1,STAINED_CLAY:3)
Block(2,21,0,STAINED_CLAY:3)
Block(2,21,1,STAINED_CLAY:3)
Block(2,21,2,STAINED_CLAY:3)
Block(2,21,3,OBSIDIAN:0)
Block(2,21,4,OBSIDIAN:0)
Block(2,21,5,OBSIDIAN:0)
Block(2,21,6,STAINED_CLAY:3)
Block(2,21,7,STAINED_CLAY:3)
Block(2,22,-7,STAINED_CLAY:3)
Block(2,22,-6,STAINED_CLAY:3)
Block(2,22,-5,STAINED_CLAY:3)
Block(2,22,-4,STAINED_CLAY:3)
Block(2,22,-3,STAINED_CLAY:3)
Block(2,22,-2,STAINED_CLAY:3)
Block(2,22,-1,STAINED_CLAY:3)
Block(2,22,0,STAINED_CLAY:3)
Block(2,22,1,STAINED_CLAY:3)
Block(2,22,2,STAINED_CLAY:3)
Block(2,22,3,OBSIDIAN:0)
Block(2,22,4,OBSIDIAN:0)
Block(2,22,5,OBSIDIAN:0)
Block(2,22,6,STAINED_CLAY:3)
Block(2,22,7,STAINED_CLAY:3)
Block(2,23,-7,STAINED_CLAY:3)
Block(2,23,-6,STAINED_CLAY:3)
Block(2,23,-5,STAINED_CLAY:3)
Block(2,23,-4,STAINED_CLAY:3)
Block(2,23,-3,STAINED_CLAY:3)
Block(2,23,-2,STAINED_CLAY:3)
Block(2,23,-1,STAINED_CLAY:3)
Block(2,23,0,STAINED_CLAY:3)
Block(2,23,1,STAINED_CLAY:3)
Block(2,23,2,STAINED_CLAY:3)
Block(2,23,3,OBSIDIAN:0)
Block(2,23,4,OBSIDIAN:0)
Block(2,23,5,OBSIDIAN:0)
Block(2,23,6,STAINED_CLAY:3)
Block(2,23,7,STAINED_CLAY:3)
Block(2,24,-6,STAINED_CLAY:3)
Block(2,24,-5,STAINED_CLAY:3)
Block(2,24,-4,STAINED_CLAY:3)
Block(2,24,-3,STAINED_CLAY:3)
Block(2,24,-2,STAINED_CLAY:3)
Block(2,24,-1,STAINED_CLAY:3)
Block(2,24,0,STAINED_CLAY:3)
Block(2,24,1,OBSIDIAN:0)
Block(2,24,2,OBSIDIAN:0)
Block(2,24,3,OBSIDIAN:0)
Block(2,24,4,STAINED_CLAY:3)
Block(2,24,5,STAINED_CLAY:3)
Block(2,24,6,STAINED_CLAY:3)
Block(2,25,-6,STAINED_CLAY:3)
Block(2,25,-5,STAINED_CLAY:3)
Block(2,25,-4,STAINED_CLAY:3)
Block(2,25,-3,STAINED_CLAY:3)
Block(2,25,-2,STAINED_CLAY:3)
Block(2,25,-1,STAINED_CLAY:3)
Block(2,25,0,STAINED_CLAY:3)
Block(2,25,1,OBSIDIAN:0)
Block(2,25,2,OBSIDIAN:0)
Block(2,25,3,OBSIDIAN:0)
Block(2,25,4,STAINED_CLAY:3)
Block(2,25,5,STAINED_CLAY:3)
Block(2,25,6,STAINED_CLAY:3)
Block(2,26,-6,STAINED_CLAY:3)
Block(2,26,-5,STAINED_CLAY:3)
Block(2,26,-4,STAINED_CLAY:3)
Block(2,26,-3,STAINED_CLAY:3)
Block(2,26,-2,OBSIDIAN:0)
Block(2,26,-1,OBSIDIAN:0)
Block(2,26,0,OBSIDIAN:0)
Block(2,26,1,OBSIDIAN:0)
Block(2,26,2,OBSIDIAN:0)
Block(2,26,3,OBSIDIAN:0)
Block(2,26,4,STAINED_CLAY:3)
Block(2,26,5,STAINED_CLAY:3)
Block(2,26,6,STAINED_CLAY:3)
Block(2,27,-6,STAINED_CLAY:3)
Block(2,27,-5,STAINED_CLAY:3)
Block(2,27,-4,OBSIDIAN:0)
Block(2,27,-3,OBSIDIAN:0)
Block(2,27,-2,OBSIDIAN:0)
Block(2,27,-1,OBSIDIAN:0)
Block(2,27,0,OBSIDIAN:0)
Block(2,27,1,OBSIDIAN:0)
Block(2,27,2,OBSIDIAN:0)
Block(2,27,3,STAINED_CLAY:3)
Block(2,27,4,STAINED_CLAY:3)
Block(2,27,5,STAINED_CLAY:3)
Block(2,28,-6,STAINED_CLAY:3)
Block(2,28,-5,STAINED_CLAY:3)
Block(2,28,-4,OBSIDIAN:0)
Block(2,28,-3,OBSIDIAN:0)
Block(2,28,-2,OBSIDIAN:0)
Block(2,28,-1,OBSIDIAN:0)
Block(2,28,0,OBSIDIAN:0)
Block(2,28,1,OBSIDIAN:0)
Block(2,28,2,OBSIDIAN:0)
Block(2,28,3,STAINED_CLAY:3)
Block(2,28,4,STAINED_CLAY:3)
Block(2,28,5,STAINED_CLAY:3)
Block(2,29,-6,STAINED_CLAY:3)
Block(2,29,-5,STAINED_CLAY:3)
Block(2,29,-4,OBSIDIAN:0)
Block(2,29,-3,OBSIDIAN:0)
Block(2,29,-2,OBSIDIAN:0)
Block(2,29,-1,OBSIDIAN:0)
Block(2,29,0,OBSIDIAN:0)
Block(2,29,1,OBSIDIAN:0)
Block(2,29,2,OBSIDIAN:0)
Block(2,29,3,STAINED_CLAY:3)
Block(2,29,4,STAINED_CLAY:3)
Block(2,29,5,STAINED_CLAY:3)
Block(2,30,-6,OBSIDIAN:0)
Block(2,30,-5,OBSIDIAN:0)
Block(2,30,-4,OBSIDIAN:0)
Block(2,30,-3,OBSIDIAN:0)
Block(2,30,-2,OBSIDIAN:0)
Block(2,30,-1,OBSIDIAN:0)
Block(2,30,0,OBSIDIAN:0)
Block(2,30,1,OBSIDIAN:0)
Block(2,30,2,OBSIDIAN:0)
Block(2,30,3,STAINED_CLAY:3)
Block(2,30,4,STAINED_CLAY:3)
Block(2,31,-6,OBSIDIAN:0)
Block(2,31,-5,OBSIDIAN:0)
Block(2,31,-4,OBSIDIAN:0)
Block(2,31,-3,OBSIDIAN:0)
Block(2,31,-2,OBSIDIAN:0)
Block(2,31,-1,OBSIDIAN:0)
Block(2,31,0,OBSIDIAN:0)
Block(2,31,1,STAINED_CLAY:3)
Block(2,31,2,STAINED_CLAY:3)
Block(2,31,3,STAINED_CLAY:3)
Block(2,31,4,STAINED_CLAY:3)
Block(2,32,-6,OBSIDIAN:0)
Block(2,32,-5,OBSIDIAN:0)
Block(2,32,-4,OBSIDIAN:0)
Block(2,32,-3,OBSIDIAN:0)
Block(2,32,-2,OBSIDIAN:0)
Block(2,32,-1,STAINED_CLAY:3)
Block(2,32,0,STAINED_CLAY:3)
Block(2,32,1,STAINED_CLAY:3)
Block(2,32,2,STAINED_CLAY:3)
Block(2,32,3,STAINED_CLAY:3)
Block(2,32,4,STAINED_CLAY:3)
Block(2,33,-6,OBSIDIAN:0)
Block(2,33,-5,OBSIDIAN:0)
Block(2,33,-4,OBSIDIAN:0)
Block(2,33,-3,OBSIDIAN:0)
Block(2,33,-2,OBSIDIAN:0)
Block(2,33,-1,STAINED_CLAY:3)
Block(2,33,0,STAINED_CLAY:3)
Block(2,33,1,STAINED_CLAY:3)
Block(2,33,2,STAINED_CLAY:3)
Block(2,33,3,STAINED_CLAY:3)
Block(2,34,-6,OBSIDIAN:0)
Block(2,34,-5,OBSIDIAN:0)
Block(2,34,-4,OBSIDIAN:0)
Block(2,34,-3,OBSIDIAN:0)
Block(2,34,-2,OBSIDIAN:0)
Block(2,34,-1,STAINED_CLAY:3)
Block(2,34,0,STAINED_CLAY:3)
Block(2,34,1,STAINED_CLAY:3)
Block(2,34,2,STAINED_CLAY:3)
Block(2,34,3,STAINED_CLAY:3)
Block(2,35,-6,OBSIDIAN:0)
Block(2,35,-5,OBSIDIAN:0)
Block(2,35,-4,STAINED_CLAY:3)
Block(2,35,-3,STAINED_CLAY:3)
Block(2,35,-2,STAINED_CLAY:3)
Block(2,35,-1,STAINED_CLAY:3)
Block(2,35,0,STAINED_CLAY:3)
Block(2,35,1,STAINED_CLAY:3)
Block(2,35,2,STAINED_CLAY:3)
Block(2,36,-6,OBSIDIAN:0)
Block(2,36,-5,STAINED_CLAY:3)
Block(2,36,-4,STAINED_CLAY:3)
Block(2,36,-3,STAINED_CLAY:3)
Block(2,36,-2,STAINED_CLAY:3)
Block(2,36,-1,STAINED_CLAY:3)
Block(2,36,0,STAINED_CLAY:3)
Block(2,36,1,STAINED_CLAY:3)
Block(2,36,2,STAINED_CLAY:3)
Block(2,37,-6,STAINED_CLAY:3)
Block(2,37,-5,STAINED_CLAY:3)
Block(2,37,-4,STAINED_CLAY:3)
Block(2,37,-3,STAINED_CLAY:3)
Block(2,37,-2,STAINED_CLAY:3)
Block(2,37,-1,STAINED_CLAY:3)
Block(2,37,0,STAINED_CLAY:3)
Block(2,37,1,STAINED_CLAY:3)
Block(2,37,2,STAINED_CLAY:3)
Block(2,38,-6,STAINED_CLAY:3)
Block(2,38,-5,STAINED_CLAY:3)
Block(2,38,-4,STAINED_CLAY:3)
Block(2,38,-3,STAINED_CLAY:3)
Block(2,38,-2,STAINED_CLAY:3)
Block(2,38,-1,STAINED_CLAY:3)
Block(2,38,0,STAINED_CLAY:3)
Block(2,38,1,STAINED_CLAY:3)
Block(2,39,-6,STAINED_CLAY:3)
Block(2,39,-5,STAINED_CLAY:3)
Block(2,39,-4,STAINED_CLAY:3)
Block(2,39,-3,STAINED_CLAY:3)
Block(2,39,-2,STAINED_CLAY:3)
Block(2,39,-1,STAINED_CLAY:3)
Block(2,39,0,STAINED_CLAY:3)
Block(2,39,1,STAINED_CLAY:3)
Block(2,40,-6,STAINED_CLAY:3)
Block(2,40,-5,STAINED_CLAY:3)
Block(2,40,-4,STAINED_CLAY:3)
Block(2,40,-3,STAINED_CLAY:3)
Block(2,40,-2,STAINED_CLAY:3)
Block(2,40,-1,STAINED_CLAY:3)
Block(2,40,0,STAINED_CLAY:3)
Block(2,40,1,STAINED_CLAY:3)
Block(2,41,-6,STAINED_CLAY:3)
Block(2,41,-5,STAINED_CLAY:3)
Block(2,41,-4,STAINED_CLAY:3)
Block(2,41,-3,STAINED_CLAY:3)
Block(2,41,-2,STAINED_CLAY:3)
Block(2,41,-1,STAINED_CLAY:3)
Block(2,41,0,STAINED_CLAY:3)
Block(3,0,-7,STAINED_CLAY:3)
Block(3,0,-6,STAINED_CLAY:3)
Block(3,0,-5,STAINED_CLAY:3)
Block(3,0,-4,STAINED_CLAY:3)
Block(3,0,-3,STAINED_CLAY:3)
Block(3,0,-2,STAINED_CLAY:3)
Block(3,0,-1,STAINED_CLAY:3)
Block(3,0,0,STAINED_CLAY:3)
Block(3,0,1,STAINED_CLAY:3)
Block(3,0,2,STAINED_CLAY:3)
Block(3,0,3,STAINED_CLAY:3)
Block(3,0,4,STAINED_CLAY:3)
Block(3,0,5,STAINED_CLAY:3)
Block(3,0,6,STAINED_CLAY:3)
Block(3,0,7,STAINED_CLAY:3)
Block(3,0,8,STAINED_CLAY:3)
Block(3,1,-7,STAINED_CLAY:3)
Block(3,1,-6,STAINED_CLAY:3)
Block(3,1,-5,STAINED_CLAY:3)
Block(3,1,-4,STAINED_CLAY:3)
Block(3,1,-3,STAINED_CLAY:3)
Block(3,1,-2,STAINED_CLAY:3)
Block(3,1,-1,STAINED_CLAY:3)
Block(3,1,0,STAINED_CLAY:3)
Block(3,1,1,STAINED_CLAY:3)
Block(3,1,2,STAINED_CLAY:3)
Block(3,1,3,STAINED_CLAY:3)
Block(3,1,4,STAINED_CLAY:3)
Block(3,1,5,STAINED_CLAY:3)
Block(3,1,6,STAINED_CLAY:3)
Block(3,1,7,STAINED_CLAY:3)
Block(3,1,8,STAINED_CLAY:3)
Block(3,2,-7,STAINED_CLAY:3)
Block(3,2,-6,STAINED_CLAY:3)
Block(3,2,-5,STAINED_CLAY:3)
Block(3,2,-4,STAINED_CLAY:3)
Block(3,2,-3,STAINED_CLAY:3)
Block(3,2,-2,STAINED_CLAY:3)
Block(3,2,-1,STAINED_CLAY:3)
Block(3,2,0,STAINED_CLAY:3)
Block(3,2,1,STAINED_CLAY:3)
Block(3,2,2,STAINED_CLAY:3)
Block(3,2,3,STAINED_CLAY:3)
Block(3,2,4,STAINED_CLAY:3)
Block(3,2,5,STAINED_CLAY:3)
Block(3,2,6,STAINED_CLAY:3)
Block(3,2,7,STAINED_CLAY:3)
Block(3,2,8,STAINED_CLAY:3)
Block(3,3,-7,STAINED_CLAY:3)
Block(3,3,-6,OBSIDIAN:0)
Block(3,3,-5,OBSIDIAN:0)
Block(3,3,-4,OBSIDIAN:0)
Block(3,3,-3,STAINED_CLAY:3)
Block(3,3,-2,STAINED_CLAY:3)
Block(3,3,-1,STAINED_CLAY:3)
Block(3,3,0,STAINED_CLAY:3)
Block(3,3,1,STAINED_CLAY:3)
Block(3,3,2,STAINED_CLAY:3)
Block(3,3,3,STAINED_CLAY:3)
Block(3,3,4,STAINED_CLAY:3)
Block(3,3,5,STAINED_CLAY:3)
Block(3,3,6,STAINED_CLAY:3)
Block(3,3,7,STAINED_CLAY:3)
Block(3,3,8,STAINED_CLAY:3)
Block(3,4,-7,OBSIDIAN:0)
Block(3,4,-6,OBSIDIAN:0)
Block(3,4,-5,OBSIDIAN:0)
Block(3,4,-4,OBSIDIAN:0)
Block(3,4,-3,STAINED_CLAY:3)
Block(3,4,-2,STAINED_CLAY:3)
Block(3,4,-1,STAINED_CLAY:3)
Block(3,4,0,STAINED_CLAY:3)
Block(3,4,1,STAINED_CLAY:3)
Block(3,4,2,STAINED_CLAY:3)
Block(3,4,3,STAINED_CLAY:3)
Block(3,4,4,STAINED_CLAY:3)
Block(3,4,5,STAINED_CLAY:3)
Block(3,4,6,STAINED_CLAY:3)
Block(3,4,7,STAINED_CLAY:3)
Block(3,4,8,STAINED_CLAY:3)
Block(3,5,-7,OBSIDIAN:0)
Block(3,5,-6,OBSIDIAN:0)
Block(3,5,-5,OBSIDIAN:0)
Block(3,5,-4,OBSIDIAN:0)
Block(3,5,-3,STAINED_CLAY:3)
Block(3,5,-2,STAINED_CLAY:3)
Block(3,5,-1,STAINED_CLAY:3)
Block(3,5,0,STAINED_CLAY:3)
Block(3,5,1,STAINED_CLAY:3)
Block(3,5,2,STAINED_CLAY:3)
Block(3,5,3,STAINED_CLAY:3)
Block(3,5,4,STAINED_CLAY:3)
Block(3,5,5,STAINED_CLAY:3)
Block(3,5,6,STAINED_CLAY:3)
Block(3,5,7,STAINED_CLAY:3)
Block(3,5,8,STAINED_CLAY:3)
Block(3,6,-7,OBSIDIAN:0)
Block(3,6,-6,OBSIDIAN:0)
Block(3,6,-5,OBSIDIAN:0)
Block(3,6,-4,OBSIDIAN:0)
Block(3,6,-3,STAINED_CLAY:3)
Block(3,6,-2,STAINED_CLAY:3)
Block(3,6,-1,STAINED_CLAY:3)
Block(3,6,0,STAINED_CLAY:3)
Block(3,6,1,STAINED_CLAY:3)
Block(3,6,2,STAINED_CLAY:3)
Block(3,6,3,STAINED_CLAY:3)
Block(3,6,4,STAINED_CLAY:3)
Block(3,6,5,STAINED_CLAY:3)
Block(3,6,6,STAINED_CLAY:3)
Block(3,6,7,STAINED_CLAY:3)
Block(3,6,8,STAINED_CLAY:3)
Block(3,7,-7,OBSIDIAN:0)
Block(3,7,-6,OBSIDIAN:0)
Block(3,7,-5,OBSIDIAN:0)
Block(3,7,-4,OBSIDIAN:0)
Block(3,7,-3,STAINED_CLAY:3)
Block(3,7,-2,STAINED_CLAY:3)
Block(3,7,-1,STAINED_CLAY:3)
Block(3,7,0,STAINED_CLAY:3)
Block(3,7,1,STAINED_CLAY:3)
Block(3,7,2,STAINED_CLAY:3)
Block(3,7,3,STAINED_CLAY:3)
Block(3,7,4,STAINED_CLAY:3)
Block(3,7,5,STAINED_CLAY:3)
Block(3,7,6,STAINED_CLAY:3)
Block(3,7,7,STAINED_CLAY:3)
Block(3,7,8,STAINED_CLAY:3)
Block(3,8,-7,OBSIDIAN:0)
Block(3,8,-6,OBSIDIAN:0)
Block(3,8,-5,OBSIDIAN:0)
Block(3,8,-4,OBSIDIAN:0)
Block(3,8,-3,STAINED_CLAY:3)
Block(3,8,-2,STAINED_CLAY:3)
Block(3,8,-1,STAINED_CLAY:3)
Block(3,8,0,STAINED_CLAY:3)
Block(3,8,1,STAINED_CLAY:3)
Block(3,8,2,STAINED_CLAY:3)
Block(3,8,3,STAINED_CLAY:3)
Block(3,8,4,STAINED_CLAY:3)
Block(3,8,5,STAINED_CLAY:3)
Block(3,8,6,STAINED_CLAY:3)
Block(3,8,7,STAINED_CLAY:3)
Block(3,8,8,STAINED_CLAY:3)
Block(3,9,-7,OBSIDIAN:0)
Block(3,9,-6,OBSIDIAN:0)
Block(3,9,-5,OBSIDIAN:0)
Block(3,9,-4,OBSIDIAN:0)
Block(3,9,-3,STAINED_CLAY:3)
Block(3,9,-2,STAINED_CLAY:3)
Block(3,9,-1,STAINED_CLAY:3)
Block(3,9,0,STAINED_CLAY:3)
Block(3,9,1,STAINED_CLAY:3)
Block(3,9,2,STAINED_CLAY:3)
Block(3,9,3,STAINED_CLAY:3)
Block(3,9,4,STAINED_CLAY:3)
Block(3,9,5,STAINED_CLAY:3)
Block(3,9,6,STAINED_CLAY:3)
Block(3,9,7,STAINED_CLAY:3)
Block(3,9,8,STAINED_CLAY:3)
Block(3,10,-7,OBSIDIAN:0)
Block(3,10,-6,OBSIDIAN:0)
Block(3,10,-5,OBSIDIAN:0)
Block(3,10,-4,STAINED_CLAY:3)
Block(3,10,-3,STAINED_CLAY:3)
Block(3,10,-2,STAINED_CLAY:3)
Block(3,10,-1,STAINED_CLAY:3)
Block(3,10,0,STAINED_CLAY:3)
Block(3,10,1,STAINED_CLAY:3)
Block(3,10,2,STAINED_CLAY:3)
Block(3,10,3,STAINED_CLAY:3)
Block(3,10,4,STAINED_CLAY:3)
Block(3,10,5,STAINED_CLAY:3)
Block(3,10,6,STAINED_CLAY:3)
Block(3,10,7,STAINED_CLAY:3)
Block(3,10,8,STAINED_CLAY:3)
Block(3,11,-7,OBSIDIAN:0)
Block(3,11,-6,OBSIDIAN:0)
Block(3,11,-5,STAINED_CLAY:3)
Block(3,11,-4,STAINED_CLAY:3)
Block(3,11,-3,STAINED_CLAY:3)
Block(3,11,-2,STAINED_CLAY:3)
Block(3,11,-1,STAINED_CLAY:3)
Block(3,11,0,STAINED_CLAY:3)
Block(3,11,1,STAINED_CLAY:3)
Block(3,11,2,STAINED_CLAY:3)
Block(3,11,3,STAINED_CLAY:3)
Block(3,11,4,STAINED_CLAY:3)
Block(3,11,5,STAINED_CLAY:3)
Block(3,11,6,STAINED_CLAY:3)
Block(3,11,7,STAINED_CLAY:3)
Block(3,11,8,STAINED_CLAY:3)
Block(3,12,-7,STAINED_CLAY:3)
Block(3,12,-6,STAINED_CLAY:3)
Block(3,12,-5,STAINED_CLAY:3)
Block(3,12,-4,STAINED_CLAY:3)
Block(3,12,-3,STAINED_CLAY:3)
Block(3,12,-2,STAINED_CLAY:3)
Block(3,12,-1,STAINED_CLAY:3)
Block(3,12,0,STAINED_CLAY:3)
Block(3,12,1,STAINED_CLAY:3)
Block(3,12,2,STAINED_CLAY:3)
Block(3,12,3,STAINED_CLAY:3)
Block(3,12,4,STAINED_CLAY:3)
Block(3,12,5,STAINED_CLAY:3)
Block(3,12,6,STAINED_CLAY:3)
Block(3,12,7,STAINED_CLAY:3)
Block(3,12,8,STAINED_CLAY:3)
Block(3,13,-7,STAINED_CLAY:3)
Block(3,13,-6,STAINED_CLAY:3)
Block(3,13,-5,STAINED_CLAY:3)
Block(3,13,-4,STAINED_CLAY:3)
Block(3,13,-3,STAINED_CLAY:3)
Block(3,13,-2,STAINED_CLAY:3)
Block(3,13,-1,STAINED_CLAY:3)
Block(3,13,0,STAINED_CLAY:3)
Block(3,13,1,STAINED_CLAY:3)
Block(3,13,2,STAINED_CLAY:3)
Block(3,13,3,STAINED_CLAY:3)
Block(3,13,4,STAINED_CLAY:3)
Block(3,13,5,STAINED_CLAY:3)
Block(3,13,6,STAINED_CLAY:3)
Block(3,13,7,STAINED_CLAY:3)
Block(3,13,8,STAINED_CLAY:3)
Block(3,14,-7,STAINED_CLAY:3)
Block(3,14,-6,STAINED_CLAY:3)
Block(3,14,-5,STAINED_CLAY:3)
Block(3,14,-4,STAINED_CLAY:3)
Block(3,14,-3,STAINED_CLAY:3)
Block(3,14,-2,STAINED_CLAY:3)
Block(3,14,-1,STAINED_CLAY:3)
Block(3,14,0,STAINED_CLAY:3)
Block(3,14,1,STAINED_CLAY:3)
Block(3,14,2,STAINED_CLAY:3)
Block(3,14,3,STAINED_CLAY:3)
Block(3,14,4,STAINED_CLAY:3)
Block(3,14,5,STAINED_CLAY:3)
Block(3,14,6,STAINED_CLAY:3)
Block(3,14,7,STAINED_CLAY:3)
Block(3,14,8,STAINED_CLAY:3)
Block(3,15,-7,STAINED_CLAY:3)
Block(3,15,-6,STAINED_CLAY:3)
Block(3,15,-5,STAINED_CLAY:3)
Block(3,15,-4,STAINED_CLAY:3)
Block(3,15,-3,STAINED_CLAY:3)
Block(3,15,-2,STAINED_CLAY:3)
Block(3,15,-1,STAINED_CLAY:3)
Block(3,15,0,STAINED_CLAY:3)
Block(3,15,1,STAINED_CLAY:3)
Block(3,15,2,STAINED_CLAY:3)
Block(3,15,3,STAINED_CLAY:3)
Block(3,15,4,STAINED_CLAY:3)
Block(3,15,5,STAINED_CLAY:3)
Block(3,15,6,STAINED_CLAY:3)
Block(3,15,7,STAINED_CLAY:3)
Block(3,15,8,STAINED_CLAY:3)
Block(3,16,-7,STAINED_CLAY:3)
Block(3,16,-6,STAINED_CLAY:3)
Block(3,16,-5,STAINED_CLAY:3)
Block(3,16,-4,STAINED_CLAY:3)
Block(3,16,-3,STAINED_CLAY:3)
Block(3,16,-2,STAINED_CLAY:3)
Block(3,16,-1,STAINED_CLAY:3)
Block(3,16,0,STAINED_CLAY:3)
Block(3,16,1,STAINED_CLAY:3)
Block(3,16,2,STAINED_CLAY:3)
Block(3,16,3,STAINED_CLAY:3)
Block(3,16,4,STAINED_CLAY:3)
Block(3,16,5,STAINED_CLAY:3)
Block(3,16,6,STAINED_CLAY:3)
Block(3,16,7,STAINED_CLAY:3)
Block(3,16,8,STAINED_CLAY:3)
Block(3,17,-7,STAINED_CLAY:3)
Block(3,17,-6,STAINED_CLAY:3)
Block(3,17,-5,STAINED_CLAY:3)
Block(3,17,-4,STAINED_CLAY:3)
Block(3,17,-3,STAINED_CLAY:3)
Block(3,17,-2,STAINED_CLAY:3)
Block(3,17,-1,STAINED_CLAY:3)
Block(3,17,0,STAINED_CLAY:3)
Block(3,17,1,STAINED_CLAY:3)
Block(3,17,2,STAINED_CLAY:3)
Block(3,17,3,STAINED_CLAY:3)
Block(3,17,4,STAINED_CLAY:3)
Block(3,17,5,STAINED_CLAY:3)
Block(3,17,6,STAINED_CLAY:3)
Block(3,17,7,STAINED_CLAY:3)
Block(3,17,8,STAINED_CLAY:3)
Block(3,18,-7,STAINED_CLAY:3)
Block(3,18,-6,STAINED_CLAY:3)
Block(3,18,-5,STAINED_CLAY:3)
Block(3,18,-4,STAINED_CLAY:3)
Block(3,18,-3,STAINED_CLAY:3)
Block(3,18,-2,STAINED_CLAY:3)
Block(3,18,-1,STAINED_CLAY:3)
Block(3,18,0,STAINED_CLAY:3)
Block(3,18,1,STAINED_CLAY:3)
Block(3,18,2,STAINED_CLAY:3)
Block(3,18,3,STAINED_CLAY:3)
Block(3,18,4,STAINED_CLAY:3)
Block(3,18,5,STAINED_CLAY:3)
Block(3,18,6,STAINED_CLAY:3)
Block(3,18,7,STAINED_CLAY:3)
Block(3,18,8,STAINED_CLAY:3)
Block(3,19,-7,STAINED_CLAY:3)
Block(3,19,-6,STAINED_CLAY:3)
Block(3,19,-5,STAINED_CLAY:3)
Block(3,19,-4,STAINED_CLAY:3)
Block(3,19,-3,STAINED_CLAY:3)
Block(3,19,-2,STAINED_CLAY:3)
Block(3,19,-1,STAINED_CLAY:3)
Block(3,19,0,STAINED_CLAY:3)
Block(3,19,1,STAINED_CLAY:3)
Block(3,19,2,STAINED_CLAY:3)
Block(3,19,3,STAINED_CLAY:3)
Block(3,19,4,STAINED_CLAY:3)
Block(3,19,5,STAINED_CLAY:3)
Block(3,19,6,STAINED_CLAY:3)
Block(3,19,7,STAINED_CLAY:3)
Block(3,19,8,STAINED_CLAY:3)
Block(3,20,-7,STAINED_CLAY:3)
Block(3,20,-6,STAINED_CLAY:3)
Block(3,20,-5,STAINED_CLAY:3)
Block(3,20,-4,STAINED_CLAY:3)
Block(3,20,-3,STAINED_CLAY:3)
Block(3,20,-2,STAINED_CLAY:3)
Block(3,20,-1,STAINED_CLAY:3)
Block(3,20,0,STAINED_CLAY:3)
Block(3,20,1,STAINED_CLAY:3)
Block(3,20,2,STAINED_CLAY:3)
Block(3,20,3,STAINED_CLAY:3)
Block(3,20,4,STAINED_CLAY:3)
Block(3,20,5,STAINED_CLAY:3)
Block(3,20,6,STAINED_CLAY:3)
Block(3,20,7,STAINED_CLAY:3)
Block(3,20,8,STAINED_CLAY:3)
Block(3,21,-7,STAINED_CLAY:3)
Block(3,21,-6,STAINED_CLAY:3)
Block(3,21,-5,STAINED_CLAY:3)
Block(3,21,-4,STAINED_CLAY:3)
Block(3,21,-3,STAINED_CLAY:3)
Block(3,21,-2,STAINED_CLAY:3)
Block(3,21,-1,STAINED_CLAY:3)
Block(3,21,0,STAINED_CLAY:3)
Block(3,21,1,STAINED_CLAY:3)
Block(3,21,2,STAINED_CLAY:3)
Block(3,21,3,STAINED_CLAY:3)
Block(3,21,4,STAINED_CLAY:3)
Block(3,21,5,STAINED_CLAY:3)
Block(3,21,6,STAINED_CLAY:3)
Block(3,21,7,STAINED_CLAY:3)
Block(3,21,8,STAINED_CLAY:3)
Block(3,22,-7,STAINED_CLAY:3)
Block(3,22,-6,STAINED_CLAY:3)
Block(3,22,-5,STAINED_CLAY:3)
Block(3,22,-4,STAINED_CLAY:3)
Block(3,22,-3,STAINED_CLAY:3)
Block(3,22,-2,STAINED_CLAY:3)
Block(3,22,-1,STAINED_CLAY:3)
Block(3,22,0,STAINED_CLAY:3)
Block(3,22,1,STAINED_CLAY:3)
Block(3,22,2,STAINED_CLAY:3)
Block(3,22,3,STAINED_CLAY:3)
Block(3,22,4,STAINED_CLAY:3)
Block(3,22,5,STAINED_CLAY:3)
Block(3,22,6,STAINED_CLAY:3)
Block(3,22,7,STAINED_CLAY:3)
Block(3,23,-7,STAINED_CLAY:3)
Block(3,23,-6,STAINED_CLAY:3)
Block(3,23,-5,STAINED_CLAY:3)
Block(3,23,-4,STAINED_CLAY:3)
Block(3,23,-3,STAINED_CLAY:3)
Block(3,23,-2,STAINED_CLAY:3)
Block(3,23,-1,STAINED_CLAY:3)
Block(3,23,0,STAINED_CLAY:3)
Block(3,23,1,STAINED_CLAY:3)
Block(3,23,2,STAINED_CLAY:3)
Block(3,23,3,STAINED_CLAY:3)
Block(3,23,4,STAINED_CLAY:3)
Block(3,23,5,STAINED_CLAY:3)
Block(3,23,6,STAINED_CLAY:3)
Block(3,23,7,STAINED_CLAY:3)
Block(3,24,-7,STAINED_CLAY:3)
Block(3,24,-6,STAINED_CLAY:3)
Block(3,24,-5,STAINED_CLAY:3)
Block(3,24,-4,STAINED_CLAY:3)
Block(3,24,-3,STAINED_CLAY:3)
Block(3,24,-2,STAINED_CLAY:3)
Block(3,24,-1,STAINED_CLAY:3)
Block(3,24,0,STAINED_CLAY:3)
Block(3,24,1,STAINED_CLAY:3)
Block(3,24,2,STAINED_CLAY:3)
Block(3,24,3,STAINED_CLAY:3)
Block(3,24,4,STAINED_CLAY:3)
Block(3,24,5,STAINED_CLAY:3)
Block(3,24,6,STAINED_CLAY:3)
Block(3,25,-7,STAINED_CLAY:3)
Block(3,25,-6,STAINED_CLAY:3)
Block(3,25,-5,STAINED_CLAY:3)
Block(3,25,-4,STAINED_CLAY:3)
Block(3,25,-3,STAINED_CLAY:3)
Block(3,25,-2,STAINED_CLAY:3)
Block(3,25,-1,STAINED_CLAY:3)
Block(3,25,0,STAINED_CLAY:3)
Block(3,25,1,STAINED_CLAY:3)
Block(3,25,2,STAINED_CLAY:3)
Block(3,25,3,STAINED_CLAY:3)
Block(3,25,4,STAINED_CLAY:3)
Block(3,25,5,STAINED_CLAY:3)
Block(3,25,6,STAINED_CLAY:3)
Block(3,26,-7,STAINED_CLAY:3)
Block(3,26,-6,STAINED_CLAY:3)
Block(3,26,-5,STAINED_CLAY:3)
Block(3,26,-4,STAINED_CLAY:3)
Block(3,26,-3,STAINED_CLAY:3)
Block(3,26,-2,STAINED_CLAY:3)
Block(3,26,-1,STAINED_CLAY:3)
Block(3,26,0,STAINED_CLAY:3)
Block(3,26,1,STAINED_CLAY:3)
Block(3,26,2,STAINED_CLAY:3)
Block(3,26,3,STAINED_CLAY:3)
Block(3,26,4,STAINED_CLAY:3)
Block(3,26,5,STAINED_CLAY:3)
Block(3,26,6,STAINED_CLAY:3)
Block(3,27,-7,STAINED_CLAY:3)
Block(3,27,-6,STAINED_CLAY:3)
Block(3,27,-5,STAINED_CLAY:3)
Block(3,27,-4,STAINED_CLAY:3)
Block(3,27,-3,STAINED_CLAY:3)
Block(3,27,-2,STAINED_CLAY:3)
Block(3,27,-1,OBSIDIAN:0)
Block(3,27,0,OBSIDIAN:0)
Block(3,27,1,OBSIDIAN:0)
Block(3,27,2,STAINED_CLAY:3)
Block(3,27,3,STAINED_CLAY:3)
Block(3,27,4,STAINED_CLAY:3)
Block(3,27,5,STAINED_CLAY:3)
Block(3,28,-7,STAINED_CLAY:3)
Block(3,28,-6,STAINED_CLAY:3)
Block(3,28,-5,STAINED_CLAY:3)
Block(3,28,-4,STAINED_CLAY:3)
Block(3,28,-3,OBSIDIAN:0)
Block(3,28,-2,OBSIDIAN:0)
Block(3,28,-1,OBSIDIAN:0)
Block(3,28,0,OBSIDIAN:0)
Block(3,28,1,OBSIDIAN:0)
Block(3,28,2,STAINED_CLAY:3)
Block(3,28,3,STAINED_CLAY:3)
Block(3,28,4,STAINED_CLAY:3)
Block(3,28,5,STAINED_CLAY:3)
Block(3,29,-7,STAINED_CLAY:3)
Block(3,29,-6,STAINED_CLAY:3)
Block(3,29,-5,STAINED_CLAY:3)
Block(3,29,-4,STAINED_CLAY:3)
Block(3,29,-3,OBSIDIAN:0)
Block(3,29,-2,OBSIDIAN:0)
Block(3,29,-1,OBSIDIAN:0)
Block(3,29,0,OBSIDIAN:0)
Block(3,29,1,OBSIDIAN:0)
Block(3,29,2,STAINED_CLAY:3)
Block(3,29,3,STAINED_CLAY:3)
Block(3,29,4,STAINED_CLAY:3)
Block(3,29,5,STAINED_CLAY:3)
Block(3,30,-7,OBSIDIAN:0)
Block(3,30,-6,OBSIDIAN:0)
Block(3,30,-5,STAINED_CLAY:3)
Block(3,30,-4,STAINED_CLAY:3)
Block(3,30,-3,OBSIDIAN:0)
Block(3,30,-2,OBSIDIAN:0)
Block(3,30,-1,OBSIDIAN:0)
Block(3,30,0,STAINED_CLAY:3)
Block(3,30,1,STAINED_CLAY:3)
Block(3,30,2,STAINED_CLAY:3)
Block(3,30,3,STAINED_CLAY:3)
Block(3,30,4,STAINED_CLAY:3)
Block(3,31,-7,OBSIDIAN:0)
Block(3,31,-6,OBSIDIAN:0)
Block(3,31,-5,OBSIDIAN:0)
Block(3,31,-4,OBSIDIAN:0)
Block(3,31,-3,OBSIDIAN:0)
Block(3,31,-2,STAINED_CLAY:3)
Block(3,31,-1,STAINED_CLAY:3)
Block(3,31,0,STAINED_CLAY:3)
Block(3,31,1,STAINED_CLAY:3)
Block(3,31,2,STAINED_CLAY:3)
Block(3,31,3,STAINED_CLAY:3)
Block(3,31,4,STAINED_CLAY:3)
Block(3,32,-7,OBSIDIAN:0)
Block(3,32,-6,OBSIDIAN:0)
Block(3,32,-5,OBSIDIAN:0)
Block(3,32,-4,OBSIDIAN:0)
Block(3,32,-3,OBSIDIAN:0)
Block(3,32,-2,STAINED_CLAY:3)
Block(3,32,-1,STAINED_CLAY:3)
Block(3,32,0,STAINED_CLAY:3)
Block(3,32,1,STAINED_CLAY:3)
Block(3,32,2,STAINED_CLAY:3)
Block(3,32,3,STAINED_CLAY:3)
Block(3,32,4,STAINED_CLAY:3)
Block(3,33,-7,OBSIDIAN:0)
Block(3,33,-6,OBSIDIAN:0)
Block(3,33,-5,OBSIDIAN:0)
Block(3,33,-4,OBSIDIAN:0)
Block(3,33,-3,OBSIDIAN:0)
Block(3,33,-2,STAINED_CLAY:3)
Block(3,33,-1,STAINED_CLAY:3)
Block(3,33,0,STAINED_CLAY:3)
Block(3,33,1,STAINED_CLAY:3)
Block(3,33,2,STAINED_CLAY:3)
Block(3,33,3,STAINED_CLAY:3)
Block(3,34,-7,OBSIDIAN:0)
Block(3,34,-6,OBSIDIAN:0)
Block(3,34,-5,OBSIDIAN:0)
Block(3,34,-4,OBSIDIAN:0)
Block(3,34,-3,STAINED_CLAY:3)
Block(3,34,-2,STAINED_CLAY:3)
Block(3,34,-1,STAINED_CLAY:3)
Block(3,34,0,STAINED_CLAY:3)
Block(3,34,1,STAINED_CLAY:3)
Block(3,34,2,STAINED_CLAY:3)
Block(3,34,3,STAINED_CLAY:3)
Block(3,35,-7,OBSIDIAN:0)
Block(3,35,-6,OBSIDIAN:0)
Block(3,35,-5,OBSIDIAN:0)
Block(3,35,-4,STAINED_CLAY:3)
Block(3,35,-3,STAINED_CLAY:3)
Block(3,35,-2,STAINED_CLAY:3)
Block(3,35,-1,STAINED_CLAY:3)
Block(3,35,0,STAINED_CLAY:3)
Block(3,35,1,STAINED_CLAY:3)
Block(3,35,2,STAINED_CLAY:3)
Block(3,35,3,STAINED_CLAY:3)
Block(3,36,-7,OBSIDIAN:0)
Block(3,36,-6,OBSIDIAN:0)
Block(3,36,-5,STAINED_CLAY:3)
Block(3,36,-4,STAINED_CLAY:3)
Block(3,36,-3,STAINED_CLAY:3)
Block(3,36,-2,STAINED_CLAY:3)
Block(3,36,-1,STAINED_CLAY:3)
Block(3,36,0,STAINED_CLAY:3)
Block(3,36,1,STAINED_CLAY:3)
Block(3,36,2,STAINED_CLAY:3)
Block(3,37,-7,STAINED_CLAY:3)
Block(3,37,-6,STAINED_CLAY:3)
Block(3,37,-5,STAINED_CLAY:3)
Block(3,37,-4,STAINED_CLAY:3)
Block(3,37,-3,STAINED_CLAY:3)
Block(3,37,-2,STAINED_CLAY:3)
Block(3,37,-1,STAINED_CLAY:3)
Block(3,37,0,STAINED_CLAY:3)
Block(3,37,1,STAINED_CLAY:3)
Block(3,37,2,STAINED_CLAY:3)
Block(3,38,-7,STAINED_CLAY:3)
Block(3,38,-6,STAINED_CLAY:3)
Block(3,38,-5,STAINED_CLAY:3)
Block(3,38,-4,STAINED_CLAY:3)
Block(3,38,-3,STAINED_CLAY:3)
Block(3,38,-2,STAINED_CLAY:3)
Block(3,38,-1,STAINED_CLAY:3)
Block(3,38,0,STAINED_CLAY:3)
Block(3,38,1,STAINED_CLAY:3)
Block(3,39,-7,STAINED_CLAY:3)
Block(3,39,-6,STAINED_CLAY:3)
Block(3,39,-5,STAINED_CLAY:3)
Block(3,39,-4,STAINED_CLAY:3)
Block(3,39,-3,STAINED_CLAY:3)
Block(3,39,-2,STAINED_CLAY:3)
Block(3,39,-1,STAINED_CLAY:3)
Block(3,39,0,STAINED_CLAY:3)
Block(3,39,1,STAINED_CLAY:3)
Block(3,40,-7,STAINED_CLAY:3)
Block(3,40,-6,STAINED_CLAY:3)
Block(3,40,-5,STAINED_CLAY:3)
Block(3,40,-4,STAINED_CLAY:3)
Block(3,40,-3,STAINED_CLAY:3)
Block(3,40,-2,STAINED_CLAY:3)
Block(3,40,-1,STAINED_CLAY:3)
Block(3,40,0,STAINED_CLAY:3)
Block(3,40,1,STAINED_CLAY:3)
Block(3,41,-7,STAINED_CLAY:3)
Block(3,41,-6,STAINED_CLAY:3)
Block(3,41,-5,STAINED_CLAY:3)
Block(3,41,-4,STAINED_CLAY:3)
Block(3,41,-3,STAINED_CLAY:3)
Block(3,41,-2,STAINED_CLAY:3)
Block(3,41,-1,STAINED_CLAY:3)
Block(3,41,0,STAINED_CLAY:3)
Block(3,42,-7,STAINED_CLAY:3)
Block(3,42,-6,STAINED_CLAY:3)
Block(3,42,-5,STAINED_CLAY:3)
Block(3,42,-4,STAINED_CLAY:3)
Block(3,42,-3,STAINED_CLAY:3)
Block(3,42,-2,STAINED_CLAY:3)
Block(3,42,-1,STAINED_CLAY:3)
Block(3,42,0,STAINED_CLAY:3)
Block(3,43,-7,STAINED_CLAY:3)
Block(3,43,-6,STAINED_CLAY:3)
Block(3,43,-5,STAINED_CLAY:3)
Block(3,43,-4,STAINED_CLAY:3)
Block(3,43,-3,STAINED_CLAY:3)
Block(3,43,-2,STAINED_CLAY:3)
Block(3,43,-1,STAINED_CLAY:3)
Block(3,43,0,STAINED_CLAY:3)
Block(3,44,-7,STAINED_CLAY:3)
Block(3,44,-6,STAINED_CLAY:3)
Block(3,44,-5,STAINED_CLAY:3)
Block(3,44,-4,STAINED_CLAY:3)
Block(3,44,-3,STAINED_CLAY:3)
Block(3,44,-2,STAINED_CLAY:3)
Block(3,44,-1,STAINED_CLAY:3)
Block(3,45,-7,STAINED_CLAY:3)
Block(3,45,-6,STAINED_CLAY:3)
Block(3,45,-5,STAINED_CLAY:3)
Block(3,45,-4,STAINED_CLAY:3)
Block(3,45,-3,STAINED_CLAY:3)
Block(3,45,-2,STAINED_CLAY:3)
Block(3,45,-1,STAINED_CLAY:3)
Block(4,0,-7,STAINED_CLAY:3)
Block(4,0,-6,STAINED_CLAY:3)
Block(4,0,-5,STAINED_CLAY:3)
Block(4,0,-4,STAINED_CLAY:3)
Block(4,0,-3,STAINED_CLAY:3)
Block(4,0,-2,STAINED_CLAY:3)
Block(4,0,-1,STAINED_CLAY:3)
Block(4,0,0,STAINED_CLAY:3)
Block(4,0,1,STAINED_CLAY:3)
Block(4,0,2,STAINED_CLAY:3)
Block(4,0,3,STAINED_CLAY:3)
Block(4,0,4,STAINED_CLAY:3)
Block(4,0,5,STAINED_CLAY:3)
Block(4,0,6,STAINED_CLAY:3)
Block(4,0,7,STAINED_CLAY:3)
Block(4,0,8,STAINED_CLAY:3)
Block(4,1,-7,STAINED_CLAY:3)
Block(4,1,-6,STAINED_CLAY:3)
Block(4,1,-5,STAINED_CLAY:3)
Block(4,1,-4,STAINED_CLAY:3)
Block(4,1,-3,STAINED_CLAY:3)
Block(4,1,-2,STAINED_CLAY:3)
Block(4,1,-1,STAINED_CLAY:3)
Block(4,1,0,STAINED_CLAY:3)
Block(4,1,1,STAINED_CLAY:3)
Block(4,1,2,STAINED_CLAY:3)
Block(4,1,3,STAINED_CLAY:3)
Block(4,1,4,STAINED_CLAY:3)
Block(4,1,5,STAINED_CLAY:3)
Block(4,1,6,STAINED_CLAY:3)
Block(4,1,7,STAINED_CLAY:3)
Block(4,1,8,STAINED_CLAY:3)
Block(4,2,-7,STAINED_CLAY:3)
Block(4,2,-6,STAINED_CLAY:3)
Block(4,2,-5,STAINED_CLAY:3)
Block(4,2,-4,STAINED_CLAY:3)
Block(4,2,-3,STAINED_CLAY:3)
Block(4,2,-2,STAINED_CLAY:3)
Block(4,2,-1,STAINED_CLAY:3)
Block(4,2,0,STAINED_CLAY:3)
Block(4,2,1,STAINED_CLAY:3)
Block(4,2,2,STAINED_CLAY:3)
Block(4,2,3,STAINED_CLAY:3)
Block(4,2,4,STAINED_CLAY:3)
Block(4,2,5,STAINED_CLAY:3)
Block(4,2,6,STAINED_CLAY:3)
Block(4,2,7,STAINED_CLAY:3)
Block(4,2,8,STAINED_CLAY:3)
Block(4,3,-7,STAINED_CLAY:3)
Block(4,3,-6,STAINED_CLAY:3)
Block(4,3,-5,STAINED_CLAY:3)
Block(4,3,-4,STAINED_CLAY:3)
Block(4,3,-3,STAINED_CLAY:3)
Block(4,3,-2,STAINED_CLAY:3)
Block(4,3,-1,STAINED_CLAY:3)
Block(4,3,0,STAINED_CLAY:3)
Block(4,3,1,STAINED_CLAY:3)
Block(4,3,2,STAINED_CLAY:3)
Block(4,3,3,STAINED_CLAY:3)
Block(4,3,4,STAINED_CLAY:3)
Block(4,3,5,STAINED_CLAY:3)
Block(4,3,6,STAINED_CLAY:3)
Block(4,3,7,STAINED_CLAY:3)
Block(4,3,8,STAINED_CLAY:3)
Block(4,4,-7,STAINED_CLAY:3)
Block(4,4,-6,STAINED_CLAY:3)
Block(4,4,-5,STAINED_CLAY:3)
Block(4,4,-4,STAINED_CLAY:3)
Block(4,4,-3,STAINED_CLAY:3)
Block(4,4,-2,STAINED_CLAY:3)
Block(4,4,-1,STAINED_CLAY:3)
Block(4,4,0,STAINED_CLAY:3)
Block(4,4,1,STAINED_CLAY:3)
Block(4,4,2,STAINED_CLAY:3)
Block(4,4,3,STAINED_CLAY:3)
Block(4,4,4,STAINED_CLAY:3)
Block(4,4,5,STAINED_CLAY:3)
Block(4,4,6,STAINED_CLAY:3)
Block(4,4,7,STAINED_CLAY:3)
Block(4,4,8,STAINED_CLAY:3)
Block(4,5,-7,OBSIDIAN:0)
Block(4,5,-6,OBSIDIAN:0)
Block(4,5,-5,OBSIDIAN:0)
Block(4,5,-4,STAINED_CLAY:3)
Block(4,5,-3,STAINED_CLAY:3)
Block(4,5,-2,STAINED_CLAY:3)
Block(4,5,-1,STAINED_CLAY:3)
Block(4,5,0,STAINED_CLAY:3)
Block(4,5,1,STAINED_CLAY:3)
Block(4,5,2,STAINED_CLAY:3)
Block(4,5,3,STAINED_CLAY:3)
Block(4,5,4,STAINED_CLAY:3)
Block(4,5,5,STAINED_CLAY:3)
Block(4,5,6,STAINED_CLAY:3)
Block(4,5,7,STAINED_CLAY:3)
Block(4,5,8,STAINED_CLAY:3)
Block(4,6,-7,OBSIDIAN:0)
Block(4,6,-6,OBSIDIAN:0)
Block(4,6,-5,OBSIDIAN:0)
Block(4,6,-4,STAINED_CLAY:3)
Block(4,6,-3,STAINED_CLAY:3)
Block(4,6,-2,STAINED_CLAY:3)
Block(4,6,-1,STAINED_CLAY:3)
Block(4,6,0,STAINED_CLAY:3)
Block(4,6,1,STAINED_CLAY:3)
Block(4,6,2,STAINED_CLAY:3)
Block(4,6,3,STAINED_CLAY:3)
Block(4,6,4,STAINED_CLAY:3)
Block(4,6,5,STAINED_CLAY:3)
Block(4,6,6,STAINED_CLAY:3)
Block(4,6,7,STAINED_CLAY:3)
Block(4,6,8,STAINED_CLAY:3)
Block(4,7,-7,OBSIDIAN:0)
Block(4,7,-6,OBSIDIAN:0)
Block(4,7,-5,OBSIDIAN:0)
Block(4,7,-4,STAINED_CLAY:3)
Block(4,7,-3,STAINED_CLAY:3)
Block(4,7,-2,STAINED_CLAY:3)
Block(4,7,-1,STAINED_CLAY:3)
Block(4,7,0,STAINED_CLAY:3)
Block(4,7,1,STAINED_CLAY:3)
Block(4,7,2,STAINED_CLAY:3)
Block(4,7,3,STAINED_CLAY:3)
Block(4,7,4,STAINED_CLAY:3)
Block(4,7,5,STAINED_CLAY:3)
Block(4,7,6,STAINED_CLAY:3)
Block(4,7,7,STAINED_CLAY:3)
Block(4,7,8,STAINED_CLAY:3)
Block(4,8,-7,OBSIDIAN:0)
Block(4,8,-6,OBSIDIAN:0)
Block(4,8,-5,OBSIDIAN:0)
Block(4,8,-4,STAINED_CLAY:3)
Block(4,8,-3,STAINED_CLAY:3)
Block(4,8,-2,STAINED_CLAY:3)
Block(4,8,-1,STAINED_CLAY:3)
Block(4,8,0,STAINED_CLAY:3)
Block(4,8,1,STAINED_CLAY:3)
Block(4,8,2,STAINED_CLAY:3)
Block(4,8,3,STAINED_CLAY:3)
Block(4,8,4,STAINED_CLAY:3)
Block(4,8,5,STAINED_CLAY:3)
Block(4,8,6,STAINED_CLAY:3)
Block(4,8,7,STAINED_CLAY:3)
Block(4,8,8,STAINED_CLAY:3)
Block(4,9,-7,OBSIDIAN:0)
Block(4,9,-6,OBSIDIAN:0)
Block(4,9,-5,OBSIDIAN:0)
Block(4,9,-4,STAINED_CLAY:3)
Block(4,9,-3,STAINED_CLAY:3)
Block(4,9,-2,STAINED_CLAY:3)
Block(4,9,-1,STAINED_CLAY:3)
Block(4,9,0,STAINED_CLAY:3)
Block(4,9,1,STAINED_CLAY:3)
Block(4,9,2,STAINED_CLAY:3)
Block(4,9,3,STAINED_CLAY:3)
Block(4,9,4,STAINED_CLAY:3)
Block(4,9,5,STAINED_CLAY:3)
Block(4,9,6,STAINED_CLAY:3)
Block(4,9,7,STAINED_CLAY:3)
Block(4,9,8,STAINED_CLAY:3)
Block(4,10,-7,OBSIDIAN:0)
Block(4,10,-6,OBSIDIAN:0)
Block(4,10,-5,OBSIDIAN:0)
Block(4,10,-4,STAINED_CLAY:3)
Block(4,10,-3,STAINED_CLAY:3)
Block(4,10,-2,STAINED_CLAY:3)
Block(4,10,-1,STAINED_CLAY:3)
Block(4,10,0,STAINED_CLAY:3)
Block(4,10,1,STAINED_CLAY:3)
Block(4,10,2,STAINED_CLAY:3)
Block(4,10,3,STAINED_CLAY:3)
Block(4,10,4,STAINED_CLAY:3)
Block(4,10,5,STAINED_CLAY:3)
Block(4,10,6,STAINED_CLAY:3)
Block(4,10,7,STAINED_CLAY:3)
Block(4,10,8,STAINED_CLAY:3)
Block(4,11,-7,OBSIDIAN:0)
Block(4,11,-6,STAINED_CLAY:3)
Block(4,11,-5,STAINED_CLAY:3)
Block(4,11,-4,STAINED_CLAY:3)
Block(4,11,-3,STAINED_CLAY:3)
Block(4,11,-2,STAINED_CLAY:3)
Block(4,11,-1,STAINED_CLAY:3)
Block(4,11,0,STAINED_CLAY:3)
Block(4,11,1,STAINED_CLAY:3)
Block(4,11,2,STAINED_CLAY:3)
Block(4,11,3,STAINED_CLAY:3)
Block(4,11,4,STAINED_CLAY:3)
Block(4,11,5,STAINED_CLAY:3)
Block(4,11,6,STAINED_CLAY:3)
Block(4,11,7,STAINED_CLAY:3)
Block(4,11,8,STAINED_CLAY:3)
Block(4,12,-7,OBSIDIAN:0)
Block(4,12,-6,STAINED_CLAY:3)
Block(4,12,-5,STAINED_CLAY:3)
Block(4,12,-4,STAINED_CLAY:3)
Block(4,12,-3,STAINED_CLAY:3)
Block(4,12,-2,STAINED_CLAY:3)
Block(4,12,-1,STAINED_CLAY:3)
Block(4,12,0,STAINED_CLAY:3)
Block(4,12,1,STAINED_CLAY:3)
Block(4,12,2,STAINED_CLAY:3)
Block(4,12,3,STAINED_CLAY:3)
Block(4,12,4,STAINED_CLAY:3)
Block(4,12,5,STAINED_CLAY:3)
Block(4,12,6,STAINED_CLAY:3)
Block(4,12,7,STAINED_CLAY:3)
Block(4,12,8,STAINED_CLAY:3)
Block(4,13,-7,OBSIDIAN:0)
Block(4,13,-6,STAINED_CLAY:3)
Block(4,13,-5,STAINED_CLAY:3)
Block(4,13,-4,STAINED_CLAY:3)
Block(4,13,-3,STAINED_CLAY:3)
Block(4,13,-2,STAINED_CLAY:3)
Block(4,13,-1,STAINED_CLAY:3)
Block(4,13,0,STAINED_CLAY:3)
Block(4,13,1,STAINED_CLAY:3)
Block(4,13,2,STAINED_CLAY:3)
Block(4,13,3,STAINED_CLAY:3)
Block(4,13,4,STAINED_CLAY:3)
Block(4,13,5,STAINED_CLAY:3)
Block(4,13,6,STAINED_CLAY:3)
Block(4,13,7,STAINED_CLAY:3)
Block(4,13,8,STAINED_CLAY:3)
Block(4,14,-7,OBSIDIAN:0)
Block(4,14,-6,STAINED_CLAY:3)
Block(4,14,-5,STAINED_CLAY:3)
Block(4,14,-4,STAINED_CLAY:3)
Block(4,14,-3,STAINED_CLAY:3)
Block(4,14,-2,STAINED_CLAY:3)
Block(4,14,-1,STAINED_CLAY:3)
Block(4,14,0,STAINED_CLAY:3)
Block(4,14,1,STAINED_CLAY:3)
Block(4,14,2,STAINED_CLAY:3)
Block(4,14,3,STAINED_CLAY:3)
Block(4,14,4,STAINED_CLAY:3)
