
#######################################################################
# +-----------------------------------------------------------------+ #
# |                            BO3 object                           | #
# +-----------------------------------------------------------------+ #
#######################################################################

Author: NLBlackHeavenNL

Description: No description given

Version: 3

SettingsMode: WriteWithoutComments


#######################################################################
# +-----------------------------------------------------------------+ #
# |                          Main settings                          | #
# +-----------------------------------------------------------------+ #
#######################################################################

Tree: true

Frequency: 1

Rarity: 100.0

RotateRandomly: false

SpawnHeight: highestSolidBlock

SpawnHeightOffset: -1

SpawnHeightVariance: 0

##############################
# Height Limits for the BO3. #
##############################

MinHeight: 0

MaxHeight: 255

######################
# Extrusion settings #
######################

ExtrudeMode: None

ExtrudeThroughBlocks: AIR

MaxBranchDepth: 10

ExcludedBiomes: All


#######################################################################
# +-----------------------------------------------------------------+ #
# |                      Source block settings                      | #
# +-----------------------------------------------------------------+ #
#######################################################################

SourceBlocks: AIR,GRASS,DIRT,biomesoplenty:dirt

MaxPercentageOutsideSourceBlock: 0

OutsideSourceBlock: placeAnyway

DoReplaceBlocks: true

IsOTGPlus: false


#######################################################################
# +-----------------------------------------------------------------+ #
# |                              Blocks                             | #
# +-----------------------------------------------------------------+ #
#######################################################################

Block(-2,10,4,dynamictrees:leaves0:8)
Block(-2,11,-1,dynamictrees:leaves0:8)
Block(-2,11,0,dynamictrees:leaves0:8)
Block(-2,11,1,dynamictrees:leaves0:8)
Block(-2,11,2,dynamictrees:leaves0:8)
Block(-2,12,0,dynamictrees:leaves0:8)
Block(-2,12,1,dynamictrees:leaves0:8)
Block(-2,12,2,dynamictrees:leaves0:8)
Block(-1,10,-2,dynamictrees:leaves0:8)
Block(-1,10,-1,dynamictrees:leaves0:8)
Block(-1,10,0,dynamictrees:leaves0:8)
Block(-1,10,2,dynamictrees:leaves0:11)
Block(-1,10,4,dynamictrees:leaves0:9)
Block(-1,10,5,dynamictrees:leaves0:10)
Block(-1,10,6,dynamictrees:leaves0:9)
Block(-1,10,7,dynamictrees:leaves0:8)
Block(-1,11,-2,dynamictrees:leaves0:8)
Block(-1,11,-1,dynamictrees:leaves0:9)
Block(-1,11,0,dynamictrees:leaves0:10)
Block(-1,11,1,dynamictrees:leaves0:11)
Block(-1,11,2,dynamictrees:leaves0:10)
Block(-1,11,3,dynamictrees:leaves0:11)
Block(-1,11,4,dynamictrees:leaves0:10)
Block(-1,11,5,dynamictrees:leaves0:9)
Block(-1,11,6,dynamictrees:leaves0:8)
Block(-1,12,-1,dynamictrees:leaves0:8)
Block(-1,12,0,dynamictrees:leaves0:9)
Block(-1,12,1,dynamictrees:leaves0:10)
Block(-1,12,2,dynamictrees:leaves0:9)
Block(-1,12,3,dynamictrees:leaves0:10)
Block(-1,12,4,dynamictrees:leaves0:9)
Block(-1,13,0,dynamictrees:leaves0:8)
Block(-1,13,1,dynamictrees:leaves0:9)
Block(-1,13,2,dynamictrees:leaves0:8)
Block(-1,13,3,dynamictrees:leaves0:9)
Block(-1,13,4,dynamictrees:leaves0:8)
Block(-1,14,1,dynamictrees:leaves0:8)
Block(-1,14,3,dynamictrees:leaves0:8)
Block(0,9,-2,dynamictrees:leaves0:8)
Block(0,9,6,dynamictrees:leaves0:8)
Block(0,10,-3,dynamictrees:leaves0:8)
Block(0,10,-2,dynamictrees:leaves0:10)
Block(0,10,-1,dynamictrees:leaves0:11)
Block(0,10,5,dynamictrees:leaves0:11)
Block(0,10,6,dynamictrees:leaves0:10)
Block(0,10,7,dynamictrees:leaves0:8)
Block(0,11,-3,dynamictrees:leaves0:8)
Block(0,11,-2,dynamictrees:leaves0:9)
Block(0,11,-1,dynamictrees:leaves0:10)
Block(0,11,0,dynamictrees:leaves0:11)
Block(0,11,1,dynamictrees:birchbranch)
Block(0,11,2,dynamictrees:leaves0:11)
Block(0,11,3,dynamictrees:leaves0:10)
Block(0,11,4,dynamictrees:leaves0:9)
Block(0,11,5,dynamictrees:leaves0:10)
Block(0,11,6,dynamictrees:leaves0:9)
Block(0,11,7,dynamictrees:leaves0:8)
Block(0,12,-2,dynamictrees:leaves0:8)
Block(0,12,-1,dynamictrees:leaves0:9)
Block(0,12,0,dynamictrees:leaves0:10)
Block(0,12,1,dynamictrees:leaves0:11)
Block(0,12,2,dynamictrees:leaves0:10)
Block(0,12,3,dynamictrees:leaves0:11)
Block(0,12,4,dynamictrees:leaves0:10)
Block(0,12,5,dynamictrees:leaves0:9)
Block(0,12,6,dynamictrees:leaves0:8)
Block(0,13,-1,dynamictrees:leaves0:8)
Block(0,13,0,dynamictrees:leaves0:9)
Block(0,13,1,dynamictrees:leaves0:10)
Block(0,13,2,dynamictrees:leaves0:9)
Block(0,13,3,dynamictrees:leaves0:10)
Block(0,13,4,dynamictrees:leaves0:9)
Block(0,13,5,dynamictrees:leaves0:8)
Block(0,14,0,dynamictrees:leaves0:8)
Block(0,14,1,dynamictrees:leaves0:8)
Block(0,14,2,dynamictrees:leaves0:8)
Block(0,14,3,dynamictrees:leaves0:8)
Block(0,14,4,dynamictrees:leaves0:8)
Block(1,0,2,dynamictrees:rootydirt:0)
Block(1,1,2,dynamictrees:birchbranch:6)
Block(1,2,2,dynamictrees:birchbranch:5)
Block(1,3,2,dynamictrees:birchbranch:5)
Block(1,4,1,dynamictrees:birchbranch:3)
Block(1,4,2,dynamictrees:birchbranch:5)
Block(1,4,3,dynamictrees:birchbranch:4)
Block(1,5,1,dynamictrees:birchbranch:3)
Block(1,5,3,dynamictrees:birchbranch:4)
Block(1,6,1,dynamictrees:birchbranch:3)
Block(1,6,3,dynamictrees:birchbranch:3)
Block(1,7,1,dynamictrees:birchbranch:2)
Block(1,7,3,dynamictrees:birchbranch:3)
Block(1,8,1,dynamictrees:birchbranch:2)
Block(1,8,3,dynamictrees:birchbranch:3)
Block(1,9,-2,dynamictrees:leaves0:8)
Block(1,9,1,dynamictrees:birchbranch:2)
Block(1,9,3,dynamictrees:birchbranch:2)
Block(1,9,6,dynamictrees:leaves0:8)
Block(1,10,-3,dynamictrees:leaves0:8)
Block(1,10,-2,dynamictrees:leaves0:11)
Block(1,10,-1,dynamictrees:birchbranch)
Block(1,10,0,dynamictrees:birchbranch:1)
Block(1,10,1,dynamictrees:birchbranch:1)
Block(1,10,3,dynamictrees:birchbranch:1)
Block(1,10,4,dynamictrees:birchbranch:1)
Block(1,10,5,dynamictrees:birchbranch)
Block(1,10,6,dynamictrees:leaves0:11)
Block(1,10,7,dynamictrees:leaves0:8)
Block(1,11,-3,dynamictrees:leaves0:8)
Block(1,11,-2,dynamictrees:leaves0:10)
Block(1,11,-1,dynamictrees:leaves0:11)
Block(1,11,0,dynamictrees:leaves0:10)
Block(1,11,1,dynamictrees:birchbranch:1)
Block(1,11,2,dynamictrees:leaves0:10)
Block(1,11,3,dynamictrees:birchbranch:1)
Block(1,11,4,dynamictrees:leaves0:10)
Block(1,11,5,dynamictrees:leaves0:11)
Block(1,11,6,dynamictrees:leaves0:10)
Block(1,11,7,dynamictrees:leaves0:8)
Block(1,12,-3,dynamictrees:leaves0:8)
Block(1,12,-2,dynamictrees:leaves0:9)
Block(1,12,-1,dynamictrees:leaves0:10)
Block(1,12,0,dynamictrees:leaves0:11)
Block(1,12,1,dynamictrees:birchbranch)
Block(1,12,2,dynamictrees:leaves0:11)
Block(1,12,3,dynamictrees:birchbranch)
Block(1,12,4,dynamictrees:leaves0:11)
Block(1,12,5,dynamictrees:leaves0:10)
Block(1,12,6,dynamictrees:leaves0:9)
Block(1,12,7,dynamictrees:leaves0:8)
Block(1,13,-2,dynamictrees:leaves0:8)
Block(1,13,-1,dynamictrees:leaves0:9)
Block(1,13,0,dynamictrees:leaves0:10)
Block(1,13,1,dynamictrees:leaves0:11)
Block(1,13,2,dynamictrees:leaves0:10)
Block(1,13,3,dynamictrees:leaves0:11)
Block(1,13,4,dynamictrees:leaves0:10)
Block(1,13,5,dynamictrees:leaves0:9)
Block(1,14,-1,dynamictrees:leaves0:8)
Block(1,14,0,dynamictrees:leaves0:8)
Block(1,14,1,dynamictrees:leaves0:8)
Block(1,14,2,dynamictrees:leaves0:8)
Block(1,14,3,dynamictrees:leaves0:8)
Block(1,14,4,dynamictrees:leaves0:8)
Block(1,14,5,dynamictrees:leaves0:8)
Block(2,9,-2,dynamictrees:leaves0:8)
Block(2,9,6,dynamictrees:leaves0:8)
Block(2,10,-3,dynamictrees:leaves0:8)
Block(2,10,-2,dynamictrees:leaves0:10)
Block(2,10,-1,dynamictrees:leaves0:11)
Block(2,10,5,dynamictrees:leaves0:11)
Block(2,10,6,dynamictrees:leaves0:10)
Block(2,10,7,dynamictrees:leaves0:8)
Block(2,11,-3,dynamictrees:leaves0:8)
Block(2,11,-2,dynamictrees:leaves0:9)
Block(2,11,-1,dynamictrees:leaves0:10)
Block(2,11,0,dynamictrees:leaves0:9)
Block(2,11,1,dynamictrees:leaves0:8)
Block(2,11,2,dynamictrees:leaves0:9)
Block(2,11,3,dynamictrees:leaves0:10)
Block(2,11,4,dynamictrees:leaves0:9)
Block(2,11,5,dynamictrees:leaves0:10)
Block(2,11,6,dynamictrees:leaves0:9)
Block(2,11,7,dynamictrees:leaves0:8)
Block(2,12,-2,dynamictrees:leaves0:8)
Block(2,12,-1,dynamictrees:leaves0:9)
Block(2,12,0,dynamictrees:leaves0:10)
Block(2,12,1,dynamictrees:leaves0:11)
Block(2,12,2,dynamictrees:leaves0:10)
Block(2,12,3,dynamictrees:leaves0:11)
Block(2,12,4,dynamictrees:leaves0:10)
Block(2,12,5,dynamictrees:leaves0:9)
Block(2,12,6,dynamictrees:leaves0:8)
Block(2,13,-1,dynamictrees:leaves0:8)
Block(2,13,0,dynamictrees:leaves0:9)
Block(2,13,1,dynamictrees:leaves0:10)
Block(2,13,2,dynamictrees:leaves0:9)
Block(2,13,3,dynamictrees:leaves0:10)
Block(2,13,4,dynamictrees:leaves0:9)
Block(2,13,5,dynamictrees:leaves0:8)
Block(2,14,0,dynamictrees:leaves0:8)
Block(2,14,1,dynamictrees:leaves0:8)
Block(2,14,2,dynamictrees:leaves0:8)
Block(2,14,3,dynamictrees:leaves0:8)
Block(2,14,4,dynamictrees:leaves0:8)
Block(3,10,-2,dynamictrees:leaves0:8)
Block(3,10,-1,dynamictrees:leaves0:8)
Block(3,10,4,dynamictrees:leaves0:11)
Block(3,10,5,dynamictrees:leaves0:10)
Block(3,10,6,dynamictrees:leaves0:9)
Block(3,10,7,dynamictrees:leaves0:8)
Block(3,11,-2,dynamictrees:leaves0:8)
Block(3,11,-1,dynamictrees:leaves0:8)
Block(3,11,0,dynamictrees:leaves0:8)
Block(3,11,4,dynamictrees:leaves0:8)
Block(3,11,5,dynamictrees:leaves0:9)
Block(3,11,6,dynamictrees:leaves0:8)
Block(3,12,-1,dynamictrees:leaves0:8)
Block(3,12,0,dynamictrees:leaves0:8)
Block(3,12,1,dynamictrees:leaves0:8)
Block(3,12,2,dynamictrees:leaves0:9)
Block(3,12,3,dynamictrees:leaves0:10)
Block(3,12,4,dynamictrees:leaves0:9)
Block(3,13,0,dynamictrees:leaves0:8)
Block(3,13,1,dynamictrees:leaves0:8)
Block(3,13,2,dynamictrees:leaves0:8)
Block(3,13,3,dynamictrees:leaves0:9)
Block(3,13,4,dynamictrees:leaves0:8)
Block(3,14,3,dynamictrees:leaves0:8)
Block(4,13,3,dynamictrees:leaves0:8)

#######################################################################
# +-----------------------------------------------------------------+ #
# |                            BO3 checks                           | #
# +-----------------------------------------------------------------+ #
#######################################################################

BlockCheck(1,-1,2,GRASS,DIRT,biomesoplenty:grass,UNKNOWN_BLOCK)

#######################################################################
# +-----------------------------------------------------------------+ #
# |                             Branches                            | #
# +-----------------------------------------------------------------+ #
#######################################################################


#######################################################################
# +-----------------------------------------------------------------+ #
# |                             Entities                            | #
# +-----------------------------------------------------------------+ #
#######################################################################


#######################################################################
# +-----------------------------------------------------------------+ #
# |                            Particles                            | #
# +-----------------------------------------------------------------+ #
#######################################################################


#######################################################################
# +-----------------------------------------------------------------+ #
# |                             Spawners                            | #
# +-----------------------------------------------------------------+ #
#######################################################################


#######################################################################
# +-----------------------------------------------------------------+ #
# |                             ModData                             | #
# +-----------------------------------------------------------------+ #
#######################################################################

