
#######################################################################
# +-----------------------------------------------------------------+ #
# |                            BO3 object                           | #
# +-----------------------------------------------------------------+ #
#######################################################################

Author: NLBlackHeavenNL

Description: No description given

Version: 3

SettingsMode: WriteWithoutComments


#######################################################################
# +-----------------------------------------------------------------+ #
# |                          Main settings                          | #
# +-----------------------------------------------------------------+ #
#######################################################################

Tree: true

Frequency: 1

Rarity: 100.0

RotateRandomly: false

SpawnHeight: highestSolidBlock

SpawnHeightOffset: -2

SpawnHeightVariance: 0

##############################
# Height Limits for the BO3. #
##############################

MinHeight: 0

MaxHeight: 255

######################
# Extrusion settings #
######################

ExtrudeMode: None

ExtrudeThroughBlocks: AIR

MaxBranchDepth: 10

ExcludedBiomes: All


#######################################################################
# +-----------------------------------------------------------------+ #
# |                      Source block settings                      | #
# +-----------------------------------------------------------------+ #
#######################################################################

SourceBlocks: AIR,GRASS,DIRT,biomesoplenty:dirt,biomesoplenty:grass,STATIONARY_WATER,biomesoplenty:mud

MaxPercentageOutsideSourceBlock: 0

OutsideSourceBlock: placeAnyway

DoReplaceBlocks: true

IsOTGPlus: false


#######################################################################
# +-----------------------------------------------------------------+ #
# |                              Blocks                             | #
# +-----------------------------------------------------------------+ #
#######################################################################

Block(-5,7,-1,dynamictreesbop:leaves3:4)
Block(-5,7,0,dynamictreesbop:leaves3:4)
Block(-5,8,-1,dynamictreesbop:leaves3:4)
Block(-5,8,0,dynamictreesbop:leaves3:4)
Block(-5,8,1,dynamictreesbop:leaves3:4)
Block(-5,9,0,dynamictreesbop:leaves3:4)
Block(-4,6,-1,dynamictreesbop:leaves3:4)
Block(-4,6,2,dynamictreesbop:leaves3:4)
Block(-4,7,-2,dynamictreesbop:leaves3:4)
Block(-4,7,-1,dynamictreesbop:leaves3:6)
Block(-4,7,0,dynamictreesbop:leaves3:7)
Block(-4,7,1,dynamictreesbop:leaves3:4)
Block(-4,7,2,dynamictreesbop:leaves3:4)
Block(-4,7,3,dynamictreesbop:leaves3:4)
Block(-4,8,-2,dynamictreesbop:leaves3:4)
Block(-4,8,-1,dynamictreesbop:leaves3:5)
Block(-4,8,0,dynamictreesbop:leaves3:6)
Block(-4,8,1,dynamictreesbop:leaves3:5)
Block(-4,8,2,dynamictreesbop:leaves3:4)
Block(-4,8,3,dynamictreesbop:leaves3:4)
Block(-4,9,-1,dynamictreesbop:leaves3:4)
Block(-4,9,0,dynamictreesbop:leaves3:5)
Block(-4,9,1,dynamictreesbop:leaves3:4)
Block(-4,9,2,dynamictreesbop:leaves3:4)
Block(-4,9,3,dynamictreesbop:leaves3:4)
Block(-4,10,0,dynamictreesbop:leaves3:4)
Block(-3,5,2,dynamictreesbop:mangrovebranch)
Block(-3,6,2,dynamictreesbop:leaves3:7)
Block(-3,7,-2,dynamictreesbop:leaves3:4)
Block(-3,7,-1,dynamictreesbop:leaves3:7)
Block(-3,7,0,dynamictreesbop:mangrovebranch)
Block(-3,7,1,dynamictreesbop:mangrovebranch:1)
Block(-3,7,2,dynamictreesbop:leaves3:6)
Block(-3,7,3,dynamictreesbop:leaves3:5)
Block(-3,7,4,dynamictreesbop:leaves3:4)
Block(-3,8,-2,dynamictreesbop:leaves3:4)
Block(-3,8,-1,dynamictreesbop:leaves3:6)
Block(-3,8,0,dynamictreesbop:leaves3:7)
Block(-3,8,1,dynamictreesbop:leaves3:6)
Block(-3,8,2,dynamictreesbop:leaves3:7)
Block(-3,8,3,dynamictreesbop:leaves3:6)
Block(-3,8,4,dynamictreesbop:leaves3:4)
Block(-3,9,-2,dynamictreesbop:leaves3:4)
Block(-3,9,-1,dynamictreesbop:leaves3:5)
Block(-3,9,0,dynamictreesbop:leaves3:6)
Block(-3,9,1,dynamictreesbop:leaves3:5)
Block(-3,9,2,dynamictreesbop:leaves3:6)
Block(-3,9,3,dynamictreesbop:leaves3:5)
Block(-3,9,4,dynamictreesbop:leaves3:4)
Block(-3,10,-1,dynamictreesbop:leaves3:4)
Block(-3,10,0,dynamictreesbop:leaves3:5)
Block(-3,10,1,dynamictreesbop:leaves3:4)
Block(-3,10,2,dynamictreesbop:leaves3:4)
Block(-3,10,3,dynamictreesbop:leaves3:4)
Block(-3,11,0,dynamictreesbop:leaves3:4)
Block(-2,5,2,dynamictreesbop:mangrovebranch:1)
Block(-2,6,2,dynamictreesbop:mangrovebranch)
Block(-2,7,1,dynamictreesbop:mangrovebranch:2)
Block(-2,7,2,dynamictreesbop:leaves3:7)
Block(-2,7,3,dynamictreesbop:leaves3:6)
Block(-2,7,4,dynamictreesbop:leaves3:4)
Block(-2,8,-2,dynamictreesbop:leaves3:4)
Block(-2,8,-1,dynamictreesbop:leaves3:7)
Block(-2,8,0,dynamictreesbop:mangrovebranch)
Block(-2,8,1,dynamictreesbop:mangrovebranch:1)
Block(-2,8,2,dynamictreesbop:mangrovebranch)
Block(-2,8,3,dynamictreesbop:leaves3:7)
Block(-2,8,4,dynamictreesbop:leaves3:4)
Block(-2,9,-2,dynamictreesbop:leaves3:4)
Block(-2,9,-1,dynamictreesbop:leaves3:6)
Block(-2,9,0,dynamictreesbop:leaves3:7)
Block(-2,9,1,dynamictreesbop:leaves3:7)
Block(-2,9,2,dynamictreesbop:leaves3:7)
Block(-2,9,3,dynamictreesbop:leaves3:6)
Block(-2,9,4,dynamictreesbop:leaves3:4)
Block(-2,10,-2,dynamictreesbop:leaves3:4)
Block(-2,10,-1,dynamictreesbop:leaves3:5)
Block(-2,10,0,dynamictreesbop:leaves3:6)
Block(-2,10,1,dynamictreesbop:leaves3:6)
Block(-2,10,2,dynamictreesbop:leaves3:5)
Block(-2,10,3,dynamictreesbop:leaves3:4)
Block(-2,11,-1,dynamictreesbop:leaves3:4)
Block(-2,11,0,dynamictreesbop:leaves3:5)
Block(-2,11,1,dynamictreesbop:leaves3:4)
Block(-2,11,2,dynamictreesbop:leaves3:4)
Block(-2,12,0,dynamictreesbop:leaves3:4)
Block(-1,5,0,dynamictreesbop:mangrovebranch)
Block(-1,5,1,dynamictreesbop:mangrovebranch:1)
Block(-1,5,2,dynamictreesbop:mangrovebranch:1)
Block(-1,7,0,dynamictreesbop:mangrovebranch)
Block(-1,7,1,dynamictreesbop:mangrovebranch:2)
Block(-1,7,4,dynamictreesbop:leaves3:4)
Block(-1,8,-2,dynamictreesbop:leaves3:4)
Block(-1,8,0,dynamictreesbop:leaves3:7)
Block(-1,8,3,dynamictreesbop:leaves3:6)
Block(-1,8,4,dynamictreesbop:leaves3:5)
Block(-1,8,5,dynamictreesbop:leaves3:4)
Block(-1,9,-3,dynamictreesbop:leaves3:4)
Block(-1,9,-2,dynamictreesbop:leaves3:5)
Block(-1,9,-1,dynamictreesbop:leaves3:6)
Block(-1,9,0,dynamictreesbop:leaves3:7)
Block(-1,9,1,dynamictreesbop:mangrovebranch)
Block(-1,9,2,dynamictreesbop:leaves3:7)
Block(-1,9,3,dynamictreesbop:leaves3:6)
Block(-1,9,4,dynamictreesbop:leaves3:4)
Block(-1,10,-2,dynamictreesbop:leaves3:4)
Block(-1,10,-1,dynamictreesbop:leaves3:6)
Block(-1,10,0,dynamictreesbop:leaves3:7)
Block(-1,10,1,dynamictreesbop:leaves3:7)
Block(-1,10,2,dynamictreesbop:leaves3:6)
Block(-1,10,3,dynamictreesbop:leaves3:5)
Block(-1,10,4,dynamictreesbop:leaves3:4)
Block(-1,11,-2,dynamictreesbop:leaves3:4)
Block(-1,11,-1,dynamictreesbop:leaves3:5)
Block(-1,11,0,dynamictreesbop:leaves3:6)
Block(-1,11,1,dynamictreesbop:leaves3:4)
Block(-1,11,2,dynamictreesbop:leaves3:4)
Block(-1,11,3,dynamictreesbop:leaves3:4)
Block(-1,12,-1,dynamictreesbop:leaves3:4)
Block(-1,12,0,dynamictreesbop:leaves3:4)
Block(0,1,1,dynamictreesbop:rootywater)
Block(0,2,1,dynamictreesbop:mangrovebranch:3)
Block(0,3,1,dynamictreesbop:mangrovebranch:3)
Block(0,4,1,dynamictreesbop:mangrovebranch:3)
Block(0,5,1,dynamictreesbop:mangrovebranch:3)
Block(0,6,0,dynamictreesbop:mangrovebranch)
Block(0,6,1,dynamictreesbop:mangrovebranch:3)
Block(0,7,1,dynamictreesbop:mangrovebranch:3)
Block(0,7,2,dynamictreesbop:mangrovebranch:1)
Block(0,7,3,dynamictreesbop:mangrovebranch)
Block(0,7,4,dynamictreesbop:leaves3:7)
Block(0,7,5,dynamictreesbop:leaves3:4)
Block(0,8,-3,dynamictreesbop:leaves3:4)
Block(0,8,-2,dynamictreesbop:leaves3:7)
Block(0,8,-1,dynamictreesbop:mangrovebranch)
Block(0,8,0,dynamictreesbop:mangrovebranch:1)
Block(0,8,1,dynamictreesbop:mangrovebranch:3)
Block(0,8,3,dynamictreesbop:leaves3:7)
Block(0,8,4,dynamictreesbop:leaves3:6)
Block(0,8,5,dynamictreesbop:leaves3:4)
Block(0,9,-3,dynamictreesbop:leaves3:4)
Block(0,9,-2,dynamictreesbop:leaves3:6)
Block(0,9,-1,dynamictreesbop:leaves3:7)
Block(0,9,0,dynamictreesbop:leaves3:7)
Block(0,9,1,dynamictreesbop:mangrovebranch:1)
Block(0,9,2,dynamictreesbop:mangrovebranch)
Block(0,9,3,dynamictreesbop:leaves3:7)
Block(0,9,4,dynamictreesbop:leaves3:4)
Block(0,10,-2,dynamictreesbop:leaves3:4)
Block(0,10,-1,dynamictreesbop:leaves3:7)
Block(0,10,0,dynamictreesbop:mangrovebranch)
Block(0,10,1,dynamictreesbop:mangrovebranch:1)
Block(0,10,2,dynamictreesbop:leaves3:7)
Block(0,10,3,dynamictreesbop:leaves3:6)
Block(0,10,4,dynamictreesbop:leaves3:4)
Block(0,11,-2,dynamictreesbop:leaves3:4)
Block(0,11,-1,dynamictreesbop:leaves3:6)
Block(0,11,0,dynamictreesbop:leaves3:7)
Block(0,11,1,dynamictreesbop:leaves3:4)
Block(0,11,2,dynamictreesbop:leaves3:4)
Block(0,11,3,dynamictreesbop:leaves3:4)
Block(0,12,-1,dynamictreesbop:leaves3:4)
Block(0,12,0,dynamictreesbop:leaves3:4)
Block(1,4,1,dynamictreesbop:mangrovebranch)
Block(1,6,1,dynamictreesbop:mangrovebranch:1)
Block(1,6,2,dynamictreesbop:mangrovebranch:1)
Block(1,7,4,dynamictreesbop:leaves3:4)
Block(1,8,-2,dynamictreesbop:leaves3:4)
Block(1,8,1,dynamictreesbop:mangrovebranch:1)
Block(1,8,3,dynamictreesbop:leaves3:5)
Block(1,8,4,dynamictreesbop:leaves3:4)
Block(1,9,-3,dynamictreesbop:leaves3:4)
Block(1,9,-2,dynamictreesbop:leaves3:5)
Block(1,9,-1,dynamictreesbop:leaves3:6)
Block(1,9,0,dynamictreesbop:leaves3:7)
Block(1,9,1,dynamictreesbop:leaves3:6)
Block(1,9,2,dynamictreesbop:leaves3:7)
Block(1,9,3,dynamictreesbop:leaves3:6)
Block(1,9,4,dynamictreesbop:leaves3:4)
Block(1,10,-2,dynamictreesbop:leaves3:4)
Block(1,10,-1,dynamictreesbop:leaves3:6)
Block(1,10,0,dynamictreesbop:leaves3:7)
Block(1,10,1,dynamictreesbop:leaves3:5)
Block(1,10,2,dynamictreesbop:leaves3:6)
Block(1,10,3,dynamictreesbop:leaves3:5)
Block(1,10,4,dynamictreesbop:leaves3:4)
Block(1,11,-2,dynamictreesbop:leaves3:4)
Block(1,11,-1,dynamictreesbop:leaves3:5)
Block(1,11,0,dynamictreesbop:leaves3:6)
Block(1,11,1,dynamictreesbop:leaves3:4)
Block(1,11,2,dynamictreesbop:leaves3:4)
Block(1,11,3,dynamictreesbop:leaves3:4)
Block(1,12,-1,dynamictreesbop:leaves3:4)
Block(1,12,0,dynamictreesbop:leaves3:4)
Block(2,6,2,dynamictreesbop:mangrovebranch:1)
Block(2,6,3,dynamictreesbop:mangrovebranch)
Block(2,6,4,dynamictreesbop:leaves3:7)
Block(2,6,5,dynamictreesbop:leaves3:4)
Block(2,7,3,dynamictreesbop:leaves3:7)
Block(2,7,4,dynamictreesbop:leaves3:6)
Block(2,7,5,dynamictreesbop:leaves3:4)
Block(2,8,-2,dynamictreesbop:leaves3:4)
Block(2,8,-1,dynamictreesbop:leaves3:6)
Block(2,8,0,dynamictreesbop:leaves3:7)
Block(2,8,1,dynamictreesbop:mangrovebranch:1)
Block(2,8,2,dynamictreesbop:leaves3:7)
Block(2,8,3,dynamictreesbop:leaves3:6)
Block(2,8,4,dynamictreesbop:leaves3:5)
Block(2,8,5,dynamictreesbop:leaves3:4)
Block(2,9,-2,dynamictreesbop:leaves3:4)
Block(2,9,-1,dynamictreesbop:leaves3:7)
Block(2,9,0,dynamictreesbop:mangrovebranch)
Block(2,9,1,dynamictreesbop:mangrovebranch:1)
Block(2,9,2,dynamictreesbop:leaves3:6)
Block(2,9,3,dynamictreesbop:leaves3:5)
Block(2,9,4,dynamictreesbop:leaves3:4)
Block(2,10,-2,dynamictreesbop:leaves3:4)
Block(2,10,-1,dynamictreesbop:leaves3:6)
Block(2,10,0,dynamictreesbop:leaves3:7)
Block(2,10,1,dynamictreesbop:leaves3:6)
Block(2,10,2,dynamictreesbop:leaves3:5)
Block(2,10,3,dynamictreesbop:leaves3:4)
Block(2,11,-1,dynamictreesbop:leaves3:4)
Block(2,11,0,dynamictreesbop:leaves3:4)
Block(2,11,1,dynamictreesbop:leaves3:4)
Block(2,11,2,dynamictreesbop:leaves3:4)
Block(3,6,2,dynamictreesbop:mangrovebranch:1)
Block(3,7,2,dynamictreesbop:mangrovebranch:1)
Block(3,7,4,dynamictreesbop:leaves3:4)
Block(3,8,-2,dynamictreesbop:leaves3:4)
Block(3,8,-1,dynamictreesbop:leaves3:5)
Block(3,8,0,dynamictreesbop:leaves3:6)
Block(3,8,1,dynamictreesbop:leaves3:7)
Block(3,8,2,dynamictreesbop:mangrovebranch)
Block(3,8,3,dynamictreesbop:leaves3:7)
Block(3,8,4,dynamictreesbop:leaves3:4)
Block(3,9,-2,dynamictreesbop:leaves3:4)
Block(3,9,-1,dynamictreesbop:leaves3:6)
Block(3,9,0,dynamictreesbop:leaves3:7)
Block(3,9,1,dynamictreesbop:mangrovebranch)
Block(3,9,2,dynamictreesbop:leaves3:7)
Block(3,9,3,dynamictreesbop:leaves3:6)
Block(3,9,4,dynamictreesbop:leaves3:4)
Block(3,10,-2,dynamictreesbop:leaves3:4)
Block(3,10,-1,dynamictreesbop:leaves3:5)
Block(3,10,0,dynamictreesbop:leaves3:6)
Block(3,10,1,dynamictreesbop:leaves3:7)
Block(3,10,2,dynamictreesbop:leaves3:6)
Block(3,10,3,dynamictreesbop:leaves3:5)
Block(3,10,4,dynamictreesbop:leaves3:4)
Block(3,11,-1,dynamictreesbop:leaves3:4)
Block(3,11,0,dynamictreesbop:leaves3:4)
Block(3,11,1,dynamictreesbop:leaves3:4)
Block(3,11,2,dynamictreesbop:leaves3:4)
Block(3,11,3,dynamictreesbop:leaves3:4)
Block(4,7,3,dynamictreesbop:leaves3:4)
Block(4,8,-1,dynamictreesbop:leaves3:4)
Block(4,8,0,dynamictreesbop:leaves3:5)
Block(4,8,1,dynamictreesbop:leaves3:6)
Block(4,8,2,dynamictreesbop:leaves3:7)
Block(4,8,3,dynamictreesbop:leaves3:6)
Block(4,8,4,dynamictreesbop:leaves3:4)
Block(4,9,-2,dynamictreesbop:leaves3:4)
Block(4,9,-1,dynamictreesbop:leaves3:5)
Block(4,9,0,dynamictreesbop:leaves3:6)
Block(4,9,1,dynamictreesbop:leaves3:7)
Block(4,9,2,dynamictreesbop:leaves3:6)
Block(4,9,3,dynamictreesbop:leaves3:5)
Block(4,9,4,dynamictreesbop:leaves3:4)
Block(4,10,-1,dynamictreesbop:leaves3:4)
Block(4,10,0,dynamictreesbop:leaves3:5)
Block(4,10,1,dynamictreesbop:leaves3:6)
Block(4,10,2,dynamictreesbop:leaves3:5)
Block(4,10,3,dynamictreesbop:leaves3:4)
Block(4,11,0,dynamictreesbop:leaves3:4)
Block(4,11,1,dynamictreesbop:leaves3:4)
Block(4,11,2,dynamictreesbop:leaves3:4)
Block(5,8,0,dynamictreesbop:leaves3:4)
Block(5,8,1,dynamictreesbop:leaves3:4)
Block(5,8,2,dynamictreesbop:leaves3:4)
Block(5,8,3,dynamictreesbop:leaves3:4)
Block(5,9,-1,dynamictreesbop:leaves3:4)
Block(5,9,0,dynamictreesbop:leaves3:4)
Block(5,9,1,dynamictreesbop:leaves3:4)
Block(5,9,2,dynamictreesbop:leaves3:4)
Block(5,9,3,dynamictreesbop:leaves3:4)
Block(5,10,0,dynamictreesbop:leaves3:4)
Block(5,10,1,dynamictreesbop:leaves3:4)
Block(5,10,2,dynamictreesbop:leaves3:4)

#######################################################################
# +-----------------------------------------------------------------+ #
# |                            BO3 checks                           | #
# +-----------------------------------------------------------------+ #
#######################################################################

BlockCheck(0,-1,1,STATIONARY_WATER)
BlockCheck(0,1,1,AIR)
BlockCheck(0,-1,1,Solid,biomesoplenty:mud)

#######################################################################
# +-----------------------------------------------------------------+ #
# |                             Branches                            | #
# +-----------------------------------------------------------------+ #
#######################################################################


#######################################################################
# +-----------------------------------------------------------------+ #
# |                             Entities                            | #
# +-----------------------------------------------------------------+ #
#######################################################################


#######################################################################
# +-----------------------------------------------------------------+ #
# |                            Particles                            | #
# +-----------------------------------------------------------------+ #
#######################################################################


#######################################################################
# +-----------------------------------------------------------------+ #
# |                             Spawners                            | #
# +-----------------------------------------------------------------+ #
#######################################################################


#######################################################################
# +-----------------------------------------------------------------+ #
# |                             ModData                             | #
# +-----------------------------------------------------------------+ #
#######################################################################

