
#######################################################################
# +-----------------------------------------------------------------+ #
# |                            BO3 object                           | #
# +-----------------------------------------------------------------+ #
#######################################################################

Author: NLBlackEagle

Description: No description given

Version: 3

SettingsMode: WriteWithoutComments


#######################################################################
# +-----------------------------------------------------------------+ #
# |                          Main settings                          | #
# +-----------------------------------------------------------------+ #
#######################################################################

Tree: false

Frequency: 50

Rarity: 100.0

RotateRandomly: false

SpawnHeight: randomY

SpawnHeightOffset: 0

SpawnHeightVariance: 0

##############################
# Height Limits for the BO3. #
##############################

MinHeight: 0

MaxHeight: 255

######################
# Extrusion settings #
######################

ExtrudeMode: None

ExtrudeThroughBlocks: AIR

MaxBranchDepth: 10

ExcludedBiomes: All


#######################################################################
# +-----------------------------------------------------------------+ #
# |                      Source block settings                      | #
# +-----------------------------------------------------------------+ #
#######################################################################

SourceBlocks: AIR,GRASS

MaxPercentageOutsideSourceBlock: 0

OutsideSourceBlock: placeAnyway

DoReplaceBlocks: true

IsOTGPlus: false


#######################################################################
# +-----------------------------------------------------------------+ #
# |                              Blocks                             | #
# +-----------------------------------------------------------------+ #
#######################################################################

Block(-1,8,0,dynamictrees:leaves0:12)
Block(-1,8,1,dynamictrees:leaves0:12)
Block(-1,8,2,dynamictrees:leaves0:12)
Block(-1,9,0,dynamictrees:leaves0:12)
Block(-1,9,1,dynamictrees:leaves0:12)
Block(-1,9,2,dynamictrees:leaves0:12)
Block(0,7,0,dynamictrees:leaves0:12)
Block(0,7,1,dynamictrees:leaves0:12)
Block(0,7,2,dynamictrees:leaves0:12)
Block(0,8,-1,dynamictrees:leaves0:12)
Block(0,8,0,dynamictrees:leaves0:14)
Block(0,8,1,dynamictrees:leaves0:15)
Block(0,8,2,dynamictrees:leaves0:14)
Block(0,8,3,dynamictrees:leaves0:12)
Block(0,9,-1,dynamictrees:leaves0:12)
Block(0,9,0,dynamictrees:leaves0:13)
Block(0,9,1,dynamictrees:leaves0:14)
Block(0,9,2,dynamictrees:leaves0:13)
Block(0,9,3,dynamictrees:leaves0:12)
Block(0,10,0,dynamictrees:leaves0:12)
Block(0,10,1,dynamictrees:leaves0:12)
Block(0,10,2,dynamictrees:leaves0:12)
Block(1,0,1,dynamictrees:rootydirt:14)
Block(1,1,1,dynamictrees:junglebranch:4)
Block(1,2,1,dynamictrees:junglebranch:4)
Block(1,3,1,dynamictrees:junglebranch:3)
Block(1,4,1,dynamictrees:junglebranch:3)
Block(1,5,1,dynamictrees:junglebranch:2)
Block(1,6,1,dynamictrees:junglebranch:1)
Block(1,7,0,dynamictrees:leaves0:12)
Block(1,7,1,dynamictrees:junglebranch:1)
Block(1,7,2,dynamictrees:leaves0:12)
Block(1,8,-1,dynamictrees:leaves0:12)
Block(1,8,0,dynamictrees:leaves0:15)
Block(1,8,1,dynamictrees:junglebranch)
Block(1,8,2,dynamictrees:leaves0:15)
Block(1,8,3,dynamictrees:leaves0:12)
Block(1,9,-1,dynamictrees:leaves0:12)
Block(1,9,0,dynamictrees:leaves0:14)
Block(1,9,1,dynamictrees:leaves0:15)
Block(1,9,2,dynamictrees:leaves0:14)
Block(1,9,3,dynamictrees:leaves0:12)
Block(1,10,0,dynamictrees:leaves0:12)
Block(1,10,1,dynamictrees:leaves0:12)
Block(1,10,2,dynamictrees:leaves0:12)
Block(2,4,1,dynamictrees:junglebranch:1)
Block(2,7,0,dynamictrees:leaves0:12)
Block(2,7,1,dynamictrees:leaves0:12)
Block(2,7,2,dynamictrees:leaves0:12)
Block(2,8,-1,dynamictrees:leaves0:12)
Block(2,8,0,dynamictrees:leaves0:14)
Block(2,8,1,dynamictrees:leaves0:15)
Block(2,8,2,dynamictrees:leaves0:14)
Block(2,8,3,dynamictrees:leaves0:12)
Block(2,9,-1,dynamictrees:leaves0:12)
Block(2,9,0,dynamictrees:leaves0:13)
Block(2,9,1,dynamictrees:leaves0:14)
Block(2,9,2,dynamictrees:leaves0:13)
Block(2,9,3,dynamictrees:leaves0:12)
Block(2,10,0,dynamictrees:leaves0:12)
Block(2,10,1,dynamictrees:leaves0:12)
Block(2,10,2,dynamictrees:leaves0:12)
Block(3,3,0,dynamictrees:leaves0:12)
Block(3,3,1,dynamictrees:leaves0:12)
Block(3,3,2,dynamictrees:leaves0:12)
Block(3,4,0,dynamictrees:leaves0:12)
Block(3,4,1,dynamictrees:junglebranch:1)
Block(3,4,2,dynamictrees:leaves0:12)
Block(3,5,0,dynamictrees:leaves0:12)
Block(3,5,1,dynamictrees:leaves0:12)
Block(3,5,2,dynamictrees:leaves0:12)
Block(3,8,0,dynamictrees:leaves0:12)
Block(3,8,1,dynamictrees:leaves0:12)
Block(3,8,2,dynamictrees:leaves0:12)
Block(3,9,0,dynamictrees:leaves0:12)
Block(3,9,1,dynamictrees:leaves0:12)
Block(3,9,2,dynamictrees:leaves0:12)
Block(4,3,-1,dynamictrees:leaves0:12)
Block(4,3,0,dynamictrees:leaves0:14)
Block(4,3,1,dynamictrees:leaves0:15)
Block(4,3,2,dynamictrees:leaves0:14)
Block(4,3,3,dynamictrees:leaves0:12)
Block(4,4,-1,dynamictrees:leaves0:12)
Block(4,4,0,dynamictrees:leaves0:15)
Block(4,4,1,dynamictrees:junglebranch)
Block(4,4,2,dynamictrees:leaves0:15)
Block(4,4,3,dynamictrees:leaves0:12)
Block(4,5,-1,dynamictrees:leaves0:12)
Block(4,5,0,dynamictrees:leaves0:14)
Block(4,5,1,dynamictrees:leaves0:15)
Block(4,5,2,dynamictrees:leaves0:14)
Block(4,5,3,dynamictrees:leaves0:12)
Block(4,6,0,dynamictrees:leaves0:12)
Block(4,6,1,dynamictrees:leaves0:12)
Block(4,6,2,dynamictrees:leaves0:12)
Block(5,3,-1,dynamictrees:leaves0:12)
Block(5,3,0,dynamictrees:leaves0:13)
Block(5,3,1,dynamictrees:leaves0:14)
Block(5,3,2,dynamictrees:leaves0:13)
Block(5,3,3,dynamictrees:leaves0:12)
Block(5,4,-1,dynamictrees:leaves0:12)
Block(5,4,0,dynamictrees:leaves0:14)
Block(5,4,1,dynamictrees:leaves0:15)
Block(5,4,2,dynamictrees:leaves0:14)
Block(5,4,3,dynamictrees:leaves0:12)
Block(5,5,-1,dynamictrees:leaves0:12)
Block(5,5,0,dynamictrees:leaves0:13)
Block(5,5,1,dynamictrees:leaves0:14)
Block(5,5,2,dynamictrees:leaves0:13)
Block(5,5,3,dynamictrees:leaves0:12)
Block(5,6,0,dynamictrees:leaves0:12)
Block(5,6,1,dynamictrees:leaves0:12)
Block(5,6,2,dynamictrees:leaves0:12)
Block(6,3,0,dynamictrees:leaves0:12)
Block(6,3,1,dynamictrees:leaves0:12)
Block(6,3,2,dynamictrees:leaves0:12)
Block(6,4,0,dynamictrees:leaves0:12)
Block(6,4,1,dynamictrees:leaves0:12)
Block(6,4,2,dynamictrees:leaves0:12)
Block(6,5,0,dynamictrees:leaves0:12)
Block(6,5,1,dynamictrees:leaves0:12)
Block(6,5,2,dynamictrees:leaves0:12)

#######################################################################
# +-----------------------------------------------------------------+ #
# |                            BO3 checks                           | #
# +-----------------------------------------------------------------+ #
#######################################################################

BlockCheck(1,-1,1,GRASS,biomesoplenty:grass,biomesoplenty:dirt)
BlockCheck(1,1,1,AIR)

#######################################################################
# +-----------------------------------------------------------------+ #
# |                             Branches                            | #
# +-----------------------------------------------------------------+ #
#######################################################################


#######################################################################
# +-----------------------------------------------------------------+ #
# |                             Entities                            | #
# +-----------------------------------------------------------------+ #
#######################################################################


#######################################################################
# +-----------------------------------------------------------------+ #
# |                            Particles                            | #
# +-----------------------------------------------------------------+ #
#######################################################################


#######################################################################
# +-----------------------------------------------------------------+ #
# |                             Spawners                            | #
# +-----------------------------------------------------------------+ #
#######################################################################


#######################################################################
# +-----------------------------------------------------------------+ #
# |                             ModData                             | #
# +-----------------------------------------------------------------+ #
#######################################################################

