#######################################################################
# +-----------------------------------------------------------------+ #
# |                            BO3 object                           | #
# +-----------------------------------------------------------------+ #
#######################################################################

Author: Bo3 BulkEdit

Description: Converted Schematic - Modified by Bo3BulkEdit

Version: 3

SettingsMode: WriteDisable

#######################################################################
# +-----------------------------------------------------------------+ #
# |                          Main settings                          | #
# +-----------------------------------------------------------------+ #
#######################################################################

IsOTGPlus: true
Tree: false
Frequency: 1
Rarity: 100.0
RotateRandomly: false
SpawnHeight: randomY
MaxBranchDepth: 10
ExcludedBiomes: All

##############################
# Height Limits for the BO3. #
##############################

MinHeight: 0
MaxHeight: 255

#######################################################################
# +-----------------------------------------------------------------+ #
# |                      Source block settings                      | #
# +-----------------------------------------------------------------+ #
#######################################################################

CanOverride: true
MaxPercentageOutsideSourceBlock: 100
OutsideSourceBlock: placeAnyway

#######################################################################
# +-----------------------------------------------------------------+ #
# |                               OTG+                              | #
# +-----------------------------------------------------------------+ #
#######################################################################

BO3Group: CeilingCrystals:0

#######################################################################
# +-----------------------------------------------------------------+ #
# |                              Blocks                             | #
# +-----------------------------------------------------------------+ #
#######################################################################

B(0,750,0,AIR)
B(15,750,15,AIR)
B(3,-23,3,betternether:quartz_stained_glass:15)
B(4,-23,3,betternether:quartz_stained_glass:15)
B(3,-23,4,betternether:quartz_stained_glass:15)
B(4,-23,4,betternether:quartz_stained_glass:15)
B(5,-23,4,betternether:quartz_stained_glass:15)
B(4,-23,5,betternether:quartz_stained_glass:15)
B(5,-23,5,betternether:quartz_stained_glass:15)
B(0,-22,0,betternether:quartz_stained_glass:15)
B(1,-22,0,betternether:quartz_stained_glass:15)
B(2,-22,0,betternether:quartz_stained_glass:15)
B(0,-22,1,betternether:quartz_stained_glass:15)
B(1,-22,1,betternether:quartz_stained_glass:15)
B(2,-22,1,betternether:quartz_stained_glass:15)
B(3,-22,1,betternether:quartz_stained_glass:15)
B(0,-22,2,betternether:quartz_stained_glass:15)
B(1,-22,2,betternether:quartz_stained_glass:15)
B(2,-22,2,betternether:quartz_stained_glass:15)
B(3,-22,2,betternether:quartz_stained_glass:15)
B(4,-22,2,betternether:quartz_stained_glass:15)
B(1,-22,3,betternether:quartz_stained_glass:15)
B(2,-22,3,betternether:quartz_stained_glass:15)
B(3,-22,3,betternether:quartz_stained_glass:15)
B(4,-22,3,betternether:quartz_stained_glass:15)
B(5,-22,3,betternether:quartz_stained_glass:15)
B(1,-22,4,betternether:quartz_stained_glass:15)
B(2,-22,4,betternether:quartz_stained_glass:15)
B(3,-22,4,betternether:quartz_stained_glass:15)
B(4,-22,4,betternether:quartz_stained_glass:15)
B(5,-22,4,betternether:quartz_stained_glass:15)
B(3,-22,5,betternether:quartz_stained_glass:15)
B(4,-22,5,betternether:quartz_stained_glass:15)
B(5,-22,5,betternether:quartz_stained_glass:15)
B(0,-21,0,betternether:quartz_stained_glass:15)
B(2,-21,0,betternether:quartz_stained_glass:15)
B(3,-21,0,betternether:quartz_stained_glass:15)
B(0,-21,1,betternether:quartz_stained_glass:15)
RB(1,-21,1,srparasites:parasitestain:1,80,quark:crystal:1,30,srparasites:parasiterubbledense:1,100)
B(2,-21,1,betternether:quartz_stained_glass:15)
B(3,-21,1,betternether:quartz_stained_glass:15)
B(0,-21,2,betternether:quartz_stained_glass:15)
B(1,-21,2,betternether:quartz_stained_glass:15)
RB(2,-21,2,srparasites:parasitestain:1,80,quark:crystal:1,30,srparasites:parasiterubbledense:1,100)
B(3,-21,2,betternether:quartz_stained_glass:15)
B(4,-21,2,betternether:quartz_stained_glass:15)
B(5,-21,2,betternether:quartz_stained_glass:15)
B(0,-21,3,betternether:quartz_stained_glass:15)
B(1,-21,3,betternether:quartz_stained_glass:15)
B(2,-21,3,betternether:quartz_stained_glass:15)
B(4,-21,3,betternether:quartz_stained_glass:15)
B(5,-21,3,betternether:quartz_stained_glass:15)
B(1,-21,4,betternether:quartz_stained_glass:15)
B(2,-21,4,betternether:quartz_stained_glass:15)
B(3,-21,4,betternether:quartz_stained_glass:15)
B(4,-21,4,betternether:quartz_stained_glass:15)
B(5,-21,4,betternether:quartz_stained_glass:15)
B(2,-21,5,betternether:quartz_stained_glass:15)
B(3,-21,5,betternether:quartz_stained_glass:15)
RB(0,-20,0,srparasites:parasitestain:1,80,quark:crystal:1,30,srparasites:parasiterubbledense:1,100)
RB(1,-20,0,srparasites:parasitestain:1,80,quark:crystal:1,30,srparasites:parasiterubbledense:1,100)
B(2,-20,0,betternether:quartz_stained_glass:15)
B(3,-20,0,betternether:quartz_stained_glass:15)
B(4,-20,0,betternether:quartz_stained_glass:15)
RB(0,-20,1,srparasites:parasitestain:1,80,quark:crystal:1,30,srparasites:parasiterubbledense:1,100)
RB(1,-20,1,srparasites:parasitestain:1,80,quark:crystal:1,30,srparasites:parasiterubbledense:1,100)
B(2,-20,1,betternether:quartz_stained_glass:15)
B(3,-20,1,betternether:quartz_stained_glass:15)
B(4,-20,1,betternether:quartz_stained_glass:15)
B(0,-20,2,betternether:quartz_stained_glass:15)
B(1,-20,2,betternether:quartz_stained_glass:15)
RB(2,-20,2,srparasites:parasitestain:1,80,quark:crystal:1,30,srparasites:parasiterubbledense:1,100)
B(3,-20,2,betternether:quartz_stained_glass:15)
B(4,-20,2,betternether:quartz_stained_glass:15)
B(0,-20,3,betternether:quartz_stained_glass:15)
B(1,-20,3,betternether:quartz_stained_glass:15)
B(4,-20,3,betternether:quartz_stained_glass:15)
B(5,-20,3,betternether:quartz_stained_glass:15)
B(0,-20,4,betternether:quartz_stained_glass:15)
B(1,-20,4,betternether:quartz_stained_glass:15)
B(2,-20,4,betternether:quartz_stained_glass:15)
B(3,-20,4,betternether:quartz_stained_glass:15)
B(2,-20,5,betternether:quartz_stained_glass:15)
RB(0,-19,0,srparasites:parasitestain:1,80,quark:crystal:1,30,srparasites:parasiterubbledense:1,100)
B(1,-19,0,betternether:quartz_stained_glass:15)
B(2,-19,0,betternether:quartz_stained_glass:15)
B(3,-19,0,betternether:quartz_stained_glass:15)
B(4,-19,0,betternether:quartz_stained_glass:15)
B(0,-19,1,betternether:quartz_stained_glass:15)
B(1,-19,1,betternether:quartz_stained_glass:15)
B(2,-19,1,betternether:quartz_stained_glass:15)
B(3,-19,1,betternether:quartz_stained_glass:15)
B(4,-19,1,betternether:quartz_stained_glass:15)
B(0,-19,2,betternether:quartz_stained_glass:15)
B(1,-19,2,betternether:quartz_stained_glass:15)
B(2,-19,2,betternether:quartz_stained_glass:15)
B(3,-19,2,betternether:quartz_stained_glass:15)
B(4,-19,2,betternether:quartz_stained_glass:15)
B(0,-19,3,betternether:quartz_stained_glass:15)
B(1,-19,3,betternether:quartz_stained_glass:15)
B(2,-19,3,betternether:quartz_stained_glass:15)
B(3,-19,3,betternether:quartz_stained_glass:15)
B(4,-19,3,betternether:quartz_stained_glass:15)
B(0,-19,4,betternether:quartz_stained_glass:15)
B(1,-19,4,betternether:quartz_stained_glass:15)
B(2,-19,4,betternether:quartz_stained_glass:15)
B(3,-19,4,betternether:quartz_stained_glass:15)
B(0,-18,0,betternether:quartz_stained_glass:15)
B(1,-18,0,betternether:quartz_stained_glass:15)
B(2,-18,0,betternether:quartz_stained_glass:15)
B(3,-18,0,betternether:quartz_stained_glass:15)
B(4,-18,0,betternether:quartz_stained_glass:15)
B(0,-18,1,betternether:quartz_stained_glass:15)
B(1,-18,1,betternether:quartz_stained_glass:15)
B(2,-18,1,betternether:quartz_stained_glass:15)
B(3,-18,1,betternether:quartz_stained_glass:15)
B(4,-18,1,betternether:quartz_stained_glass:15)
B(0,-18,2,betternether:quartz_stained_glass:15)
B(1,-18,2,betternether:quartz_stained_glass:15)
B(2,-18,2,betternether:quartz_stained_glass:15)
B(3,-18,2,betternether:quartz_stained_glass:15)
B(0,-18,3,betternether:quartz_stained_glass:15)
B(1,-18,3,betternether:quartz_stained_glass:15)
B(2,-18,3,betternether:quartz_stained_glass:15)
B(0,-18,4,betternether:quartz_stained_glass:15)
B(0,-17,0,betternether:quartz_stained_glass:15)
B(1,-17,0,betternether:quartz_stained_glass:15)
B(2,-17,0,betternether:quartz_stained_glass:15)
B(0,-17,1,betternether:quartz_stained_glass:15)
B(1,-17,1,betternether:quartz_stained_glass:15)
B(0,-17,2,betternether:quartz_stained_glass:15)

