
#######################################################################
# +-----------------------------------------------------------------+ #
# |                            BO3 object                           | #
# +-----------------------------------------------------------------+ #
#######################################################################

Author: NLBlackHeavenNL

Description: No description given

Version: 3

SettingsMode: WriteWithoutComments


#######################################################################
# +-----------------------------------------------------------------+ #
# |                          Main settings                          | #
# +-----------------------------------------------------------------+ #
#######################################################################

Tree: true

Frequency: 1

Rarity: 100.0

RotateRandomly: false

SpawnHeight: highestSolidBlock

SpawnHeightOffset: -1

SpawnHeightVariance: 0

##############################
# Height Limits for the BO3. #
##############################

MinHeight: 0

MaxHeight: 255

######################
# Extrusion settings #
######################

ExtrudeMode: None

ExtrudeThroughBlocks: AIR

MaxBranchDepth: 10

ExcludedBiomes: All


#######################################################################
# +-----------------------------------------------------------------+ #
# |                      Source block settings                      | #
# +-----------------------------------------------------------------+ #
#######################################################################

SourceBlocks: AIR,GRASS,DIRT,biomesoplenty:dirt

MaxPercentageOutsideSourceBlock: 0

OutsideSourceBlock: placeAnyway

DoReplaceBlocks: true

IsOTGPlus: false


#######################################################################
# +-----------------------------------------------------------------+ #
# |                              Blocks                             | #
# +-----------------------------------------------------------------+ #
#######################################################################

Block(-3,11,1,dynamictrees:leaves1:0)
Block(-3,11,2,dynamictrees:leaves1:0)
Block(-3,11,3,dynamictrees:leaves1:0)
Block(-2,11,0,dynamictrees:leaves1:0)
Block(-2,11,1,dynamictrees:leaves1:1)
Block(-2,11,2,dynamictrees:leaves1:1)
Block(-2,11,3,dynamictrees:leaves1:1)
Block(-2,11,4,dynamictrees:leaves1:0)
Block(-2,12,1,dynamictrees:leaves1:0)
Block(-2,12,2,dynamictrees:leaves1:0)
Block(-2,12,3,dynamictrees:leaves1:0)
Block(-1,11,-1,dynamictrees:leaves1:0)
Block(-1,11,0,dynamictrees:leaves1:1)
Block(-1,11,1,dynamictrees:leaves1:2)
Block(-1,11,2,dynamictrees:leaves1)
Block(-1,11,3,dynamictrees:leaves1:2)
Block(-1,11,4,dynamictrees:leaves1:1)
Block(-1,11,5,dynamictrees:leaves1:0)
Block(-1,12,0,dynamictrees:leaves1:0)
Block(-1,12,1,dynamictrees:leaves1:1)
Block(-1,12,2,dynamictrees:leaves1:1)
Block(-1,12,3,dynamictrees:leaves1:1)
Block(-1,12,4,dynamictrees:leaves1:0)
Block(0,0,2,dynamictrees:rootydirt:0)
Block(0,1,2,dynamictrees:acaciabranch:4)
Block(0,2,2,dynamictrees:acaciabranch:4)
Block(0,3,2,dynamictrees:acaciabranch:3)
Block(0,4,2,dynamictrees:acaciabranch:3)
Block(0,5,2,dynamictrees:acaciabranch:3)
Block(0,6,2,dynamictrees:acaciabranch:3)
Block(0,7,2,dynamictrees:acaciabranch:3)
Block(0,8,2,dynamictrees:acaciabranch:2)
Block(0,8,3,dynamictrees:acaciabranch:1)
Block(0,8,4,dynamictrees:acaciabranch:1)
Block(0,9,2,dynamictrees:acaciabranch:1)
Block(0,9,4,dynamictrees:acaciabranch)
Block(0,10,1,dynamictrees:acaciabranch)
Block(0,10,2,dynamictrees:acaciabranch:1)
Block(0,10,4,dynamictrees:leaves1:1)
Block(0,10,5,dynamictrees:leaves1:0)
Block(0,11,-1,dynamictrees:leaves1:0)
Block(0,11,0,dynamictrees:leaves1:1)
Block(0,11,1,dynamictrees:leaves1)
Block(0,11,2,dynamictrees:acaciabranch)
Block(0,11,3,dynamictrees:leaves1)
Block(0,11,4,dynamictrees:leaves1:1)
Block(0,11,5,dynamictrees:leaves1:0)
Block(0,12,0,dynamictrees:leaves1:0)
Block(0,12,1,dynamictrees:leaves1:1)
Block(0,12,2,dynamictrees:leaves1:1)
Block(0,12,3,dynamictrees:leaves1:1)
Block(0,12,4,dynamictrees:leaves1:0)
Block(1,7,2,dynamictrees:acaciabranch:1)
Block(1,11,-1,dynamictrees:leaves1:0)
Block(1,11,0,dynamictrees:leaves1:1)
Block(1,11,1,dynamictrees:leaves1:2)
Block(1,11,2,dynamictrees:leaves1)
Block(1,11,3,dynamictrees:leaves1:2)
Block(1,11,4,dynamictrees:leaves1:1)
Block(1,11,5,dynamictrees:leaves1:0)
Block(1,12,0,dynamictrees:leaves1:0)
Block(1,12,1,dynamictrees:leaves1:1)
Block(1,12,2,dynamictrees:leaves1:1)
Block(1,12,3,dynamictrees:leaves1:1)
Block(1,12,4,dynamictrees:leaves1:0)
Block(2,7,2,dynamictrees:acaciabranch:1)
Block(2,8,2,dynamictrees:acaciabranch:1)
Block(2,9,2,dynamictrees:acaciabranch)
Block(2,10,2,dynamictrees:leaves1:1)
Block(2,11,0,dynamictrees:leaves1:0)
Block(2,11,1,dynamictrees:leaves1:1)
Block(2,11,2,dynamictrees:leaves1:1)
Block(2,11,3,dynamictrees:leaves1:1)
Block(2,11,4,dynamictrees:leaves1:0)
Block(2,12,1,dynamictrees:leaves1:0)
Block(2,12,2,dynamictrees:leaves1:0)
Block(2,12,3,dynamictrees:leaves1:0)
Block(3,10,2,dynamictrees:leaves1:0)
Block(3,11,1,dynamictrees:leaves1:0)
Block(3,11,2,dynamictrees:leaves1:0)
Block(3,11,3,dynamictrees:leaves1:0)

#######################################################################
# +-----------------------------------------------------------------+ #
# |                            BO3 checks                           | #
# +-----------------------------------------------------------------+ #
#######################################################################

BlockCheck(0,-1,2,GRASS,DIRT,biomesoplenty:grass,biomesoplenty:dirt)

#######################################################################
# +-----------------------------------------------------------------+ #
# |                             Branches                            | #
# +-----------------------------------------------------------------+ #
#######################################################################


#######################################################################
# +-----------------------------------------------------------------+ #
# |                             Entities                            | #
# +-----------------------------------------------------------------+ #
#######################################################################


#######################################################################
# +-----------------------------------------------------------------+ #
# |                            Particles                            | #
# +-----------------------------------------------------------------+ #
#######################################################################


#######################################################################
# +-----------------------------------------------------------------+ #
# |                             Spawners                            | #
# +-----------------------------------------------------------------+ #
#######################################################################


#######################################################################
# +-----------------------------------------------------------------+ #
# |                             ModData                             | #
# +-----------------------------------------------------------------+ #
#######################################################################

