
#######################################################################
# +-----------------------------------------------------------------+ #
# |                            BO3 object                           | #
# +-----------------------------------------------------------------+ #
#######################################################################

Author: NLBlackHeavenNL

Description: No description given

Version: 3

SettingsMode: WriteWithoutComments


#######################################################################
# +-----------------------------------------------------------------+ #
# |                          Main settings                          | #
# +-----------------------------------------------------------------+ #
#######################################################################

Tree: true

Frequency: 1

Rarity: 100.0

RotateRandomly: false

SpawnHeight: highestSolidBlock

SpawnHeightOffset: -1

SpawnHeightVariance: 0

##############################
# Height Limits for the BO3. #
##############################

MinHeight: 0

MaxHeight: 255

######################
# Extrusion settings #
######################

ExtrudeMode: None

ExtrudeThroughBlocks: AIR

MaxBranchDepth: 10

ExcludedBiomes: All


#######################################################################
# +-----------------------------------------------------------------+ #
# |                      Source block settings                      | #
# +-----------------------------------------------------------------+ #
#######################################################################

SourceBlocks: AIR,GRASS,DIRT,biomesoplenty:dirt

MaxPercentageOutsideSourceBlock: 0

OutsideSourceBlock: placeAnyway

DoReplaceBlocks: true

IsOTGPlus: false


#######################################################################
# +-----------------------------------------------------------------+ #
# |                              Blocks                             | #
# +-----------------------------------------------------------------+ #
#######################################################################

Block(-6,8,2,dynamictrees:leaves1:0)
Block(-6,8,3,dynamictrees:leaves1:0)
Block(-6,8,4,dynamictrees:leaves1:0)
Block(-5,7,0,dynamictrees:leaves1:0)
Block(-5,8,1,dynamictrees:leaves1:0)
Block(-5,8,2,dynamictrees:leaves1:1)
Block(-5,8,3,dynamictrees:leaves1:1)
Block(-5,8,4,dynamictrees:leaves1:1)
Block(-5,8,5,dynamictrees:leaves1:0)
Block(-5,9,2,dynamictrees:leaves1:0)
Block(-5,9,3,dynamictrees:leaves1:0)
Block(-5,9,4,dynamictrees:leaves1:0)
Block(-4,7,-1,dynamictrees:leaves1:0)
Block(-4,8,0,dynamictrees:leaves1:0)
Block(-4,8,1,dynamictrees:leaves1:1)
Block(-4,8,2,dynamictrees:leaves1:2)
Block(-4,8,3,dynamictrees:leaves1)
Block(-4,8,4,dynamictrees:leaves1:2)
Block(-4,8,5,dynamictrees:leaves1:1)
Block(-4,8,6,dynamictrees:leaves1:0)
Block(-4,9,1,dynamictrees:leaves1:0)
Block(-4,9,2,dynamictrees:leaves1:1)
Block(-4,9,3,dynamictrees:leaves1:1)
Block(-4,9,4,dynamictrees:leaves1:1)
Block(-4,9,5,dynamictrees:leaves1:0)
Block(-3,8,-1,dynamictrees:leaves1:0)
Block(-3,8,0,dynamictrees:leaves1:1)
Block(-3,8,1,dynamictrees:leaves1:2)
Block(-3,8,2,dynamictrees:leaves1)
Block(-3,8,3,dynamictrees:acaciabranch)
Block(-3,8,4,dynamictrees:leaves1)
Block(-3,8,5,dynamictrees:leaves1:1)
Block(-3,8,6,dynamictrees:leaves1:0)
Block(-3,9,0,dynamictrees:leaves1:0)
Block(-3,9,1,dynamictrees:leaves1:1)
Block(-3,9,2,dynamictrees:leaves1:1)
Block(-3,9,3,dynamictrees:leaves1:1)
Block(-3,9,4,dynamictrees:leaves1:1)
Block(-3,9,5,dynamictrees:leaves1:0)
Block(-2,7,1,dynamictrees:acaciabranch)
Block(-2,8,-2,dynamictrees:leaves1:0)
Block(-2,8,-1,dynamictrees:leaves1:1)
Block(-2,8,0,dynamictrees:leaves1:2)
Block(-2,8,1,dynamictrees:leaves1)
Block(-2,8,3,dynamictrees:acaciabranch:1)
Block(-2,8,5,dynamictrees:leaves1:0)
Block(-2,8,6,dynamictrees:leaves1:0)
Block(-2,9,-1,dynamictrees:leaves1:0)
Block(-2,9,0,dynamictrees:leaves1:1)
Block(-2,9,1,dynamictrees:leaves1:1)
Block(-2,9,2,dynamictrees:leaves1:0)
Block(-2,9,3,dynamictrees:leaves1:0)
Block(-2,9,4,dynamictrees:leaves1:0)
Block(-2,9,5,dynamictrees:leaves1:0)
Block(-1,3,3,dynamictrees:acaciabranch:4)
Block(-1,4,0,dynamictrees:acaciabranch:1)
Block(-1,4,1,dynamictrees:acaciabranch:1)
Block(-1,4,2,dynamictrees:acaciabranch:1)
Block(-1,4,3,dynamictrees:acaciabranch:3)
Block(-1,5,0,dynamictrees:acaciabranch)
Block(-1,5,3,dynamictrees:acaciabranch:3)
Block(-1,6,0,dynamictrees:leaves1:1)
Block(-1,6,3,dynamictrees:acaciabranch:3)
Block(-1,7,0,dynamictrees:acaciabranch)
Block(-1,7,1,dynamictrees:acaciabranch:1)
Block(-1,7,2,dynamictrees:acaciabranch:1)
Block(-1,7,3,dynamictrees:acaciabranch:2)
Block(-1,8,-2,dynamictrees:leaves1:0)
Block(-1,8,-1,dynamictrees:leaves1:1)
Block(-1,8,0,dynamictrees:leaves1)
Block(-1,8,1,dynamictrees:acaciabranch)
Block(-1,8,3,dynamictrees:acaciabranch:2)
Block(-1,8,4,dynamictrees:acaciabranch)
Block(-1,8,5,dynamictrees:leaves1)
Block(-1,8,6,dynamictrees:leaves1:1)
Block(-1,8,7,dynamictrees:leaves1:0)
Block(-1,9,-1,dynamictrees:leaves1:0)
Block(-1,9,0,dynamictrees:leaves1:1)
Block(-1,9,1,dynamictrees:leaves1:1)
Block(-1,9,2,dynamictrees:leaves1:1)
Block(-1,9,3,dynamictrees:acaciabranch:1)
Block(-1,9,4,dynamictrees:leaves1:1)
Block(-1,9,5,dynamictrees:leaves1:1)
Block(-1,9,6,dynamictrees:leaves1:0)
Block(-1,10,2,dynamictrees:leaves1:0)
Block(-1,10,3,dynamictrees:leaves1:0)
Block(-1,10,4,dynamictrees:leaves1:0)
Block(0,0,3,dynamictrees:rootydirt:0)
Block(0,1,3,dynamictrees:acaciabranch:6)
Block(0,2,3,dynamictrees:acaciabranch:6)
Block(0,3,3,dynamictrees:acaciabranch:6)
Block(0,8,-2,dynamictrees:leaves1:0)
Block(0,8,-1,dynamictrees:leaves1:1)
Block(0,8,0,dynamictrees:leaves1:2)
Block(0,8,6,dynamictrees:leaves1:1)
Block(0,8,7,dynamictrees:leaves1:0)
Block(0,9,-1,dynamictrees:leaves1:0)
Block(0,9,0,dynamictrees:leaves1:1)
Block(0,9,1,dynamictrees:leaves1:1)
Block(0,9,2,dynamictrees:leaves1)
Block(0,9,3,dynamictrees:acaciabranch)
Block(0,9,4,dynamictrees:leaves1)
Block(0,9,5,dynamictrees:leaves1:1)
Block(0,9,6,dynamictrees:leaves1:0)
Block(0,10,1,dynamictrees:leaves1:0)
Block(0,10,2,dynamictrees:leaves1:1)
Block(0,10,3,dynamictrees:leaves1:1)
Block(0,10,4,dynamictrees:leaves1:1)
Block(0,10,5,dynamictrees:leaves1:0)
Block(1,8,-1,dynamictrees:leaves1:1)
Block(1,8,0,dynamictrees:leaves1)
Block(1,8,5,dynamictrees:leaves1:1)
Block(1,8,6,dynamictrees:leaves1:0)
Block(1,9,0,dynamictrees:leaves1:1)
Block(1,9,1,dynamictrees:leaves1:1)
Block(1,9,2,dynamictrees:leaves1:2)
Block(1,9,3,dynamictrees:leaves1)
Block(1,9,4,dynamictrees:leaves1:2)
Block(1,9,5,dynamictrees:leaves1:1)
Block(1,9,6,dynamictrees:leaves1:0)
Block(1,10,1,dynamictrees:leaves1:0)
Block(1,10,2,dynamictrees:leaves1:1)
Block(1,10,3,dynamictrees:leaves1:1)
Block(1,10,4,dynamictrees:leaves1:1)
Block(1,10,5,dynamictrees:leaves1:0)
Block(2,8,0,dynamictrees:leaves1:2)
Block(2,8,1,dynamictrees:leaves1)
Block(2,8,2,dynamictrees:leaves1:1)
Block(2,8,5,dynamictrees:leaves1:0)
Block(2,9,1,dynamictrees:leaves1:1)
Block(2,9,2,dynamictrees:leaves1:1)
Block(2,9,3,dynamictrees:leaves1:1)
Block(2,9,4,dynamictrees:leaves1:1)
Block(2,9,5,dynamictrees:leaves1:0)
Block(2,10,2,dynamictrees:leaves1:0)
Block(2,10,3,dynamictrees:leaves1:0)
Block(2,10,4,dynamictrees:leaves1:0)
Block(3,9,2,dynamictrees:leaves1:0)
Block(3,9,3,dynamictrees:leaves1:0)
Block(3,9,4,dynamictrees:leaves1:0)

#######################################################################
# +-----------------------------------------------------------------+ #
# |                            BO3 checks                           | #
# +-----------------------------------------------------------------+ #
#######################################################################

BlockCheck(0,-1,3,GRASS,DIRT,biomesoplenty:grass,biomesoplenty:dirt)

#######################################################################
# +-----------------------------------------------------------------+ #
# |                             Branches                            | #
# +-----------------------------------------------------------------+ #
#######################################################################


#######################################################################
# +-----------------------------------------------------------------+ #
# |                             Entities                            | #
# +-----------------------------------------------------------------+ #
#######################################################################


#######################################################################
# +-----------------------------------------------------------------+ #
# |                            Particles                            | #
# +-----------------------------------------------------------------+ #
#######################################################################


#######################################################################
# +-----------------------------------------------------------------+ #
# |                             Spawners                            | #
# +-----------------------------------------------------------------+ #
#######################################################################


#######################################################################
# +-----------------------------------------------------------------+ #
# |                             ModData                             | #
# +-----------------------------------------------------------------+ #
#######################################################################

