#######################################################################
# +-----------------------------------------------------------------+ #
# |                            BO3 object                           | #
# +-----------------------------------------------------------------+ #
#######################################################################

Author: Bo3 BulkEdit

Description: Converted Schematic - Modified by Bo3BulkEdit

Version: 3

SettingsMode: WriteDisable

#######################################################################
# +-----------------------------------------------------------------+ #
# |                          Main settings                          | #
# +-----------------------------------------------------------------+ #
#######################################################################

IsOTGPlus: true
Tree: false
Frequency: 1
Rarity: 100.0
RotateRandomly: false
SpawnHeight: randomY
MaxBranchDepth: 10
ExcludedBiomes: All

##############################
# Height Limits for the BO3. #
##############################

MinHeight: 0
MaxHeight: 255

#######################################################################
# +-----------------------------------------------------------------+ #
# |                      Source block settings                      | #
# +-----------------------------------------------------------------+ #
#######################################################################

CanOverride: true
MaxPercentageOutsideSourceBlock: 100
OutsideSourceBlock: placeAnyway

#######################################################################
# +-----------------------------------------------------------------+ #
# |                               OTG+                              | #
# +-----------------------------------------------------------------+ #
#######################################################################

BO3Group: CeilingCrystals:0

#######################################################################
# +-----------------------------------------------------------------+ #
# |                              Blocks                             | #
# +-----------------------------------------------------------------+ #
#######################################################################

B(0,750,0,AIR)
B(15,750,15,AIR)
B(15,-29,7,betternether:quartz_stained_glass:15)
B(15,-29,8,betternether:quartz_stained_glass:15)
B(15,-29,9,betternether:quartz_stained_glass:15)
B(15,-28,6,betternether:quartz_stained_glass:15)
B(14,-28,7,betternether:quartz_stained_glass:15)
B(15,-28,7,betternether:quartz_stained_glass:15)
B(14,-28,8,betternether:quartz_stained_glass:15)
B(15,-28,8,betternether:quartz_stained_glass:15)
B(15,-28,9,betternether:quartz_stained_glass:15)
B(15,-27,5,betternether:quartz_stained_glass:15)
B(14,-27,6,betternether:quartz_stained_glass:15)
B(15,-27,6,betternether:quartz_stained_glass:15)
B(14,-27,7,betternether:quartz_stained_glass:15)
B(15,-27,7,betternether:quartz_stained_glass:15)
B(14,-27,8,betternether:quartz_stained_glass:15)
B(15,-27,8,betternether:quartz_stained_glass:15)
B(15,-27,9,betternether:quartz_stained_glass:15)
B(15,-26,4,betternether:quartz_stained_glass:15)
B(13,-26,5,betternether:quartz_stained_glass:15)
B(14,-26,5,betternether:quartz_stained_glass:15)
B(15,-26,5,betternether:quartz_stained_glass:15)
B(13,-26,6,betternether:quartz_stained_glass:15)
B(14,-26,6,betternether:quartz_stained_glass:15)
B(15,-26,6,betternether:quartz_stained_glass:15)
B(14,-26,7,betternether:quartz_stained_glass:15)
B(15,-26,7,betternether:quartz_stained_glass:15)
B(14,-26,8,betternether:quartz_stained_glass:15)
B(15,-26,8,betternether:quartz_stained_glass:15)
B(15,-26,9,betternether:quartz_stained_glass:15)
B(15,-25,3,betternether:quartz_stained_glass:15)
B(13,-25,4,betternether:quartz_stained_glass:15)
B(14,-25,4,betternether:quartz_stained_glass:15)
B(15,-25,4,betternether:quartz_stained_glass:15)
B(12,-25,5,betternether:quartz_stained_glass:15)
B(13,-25,5,betternether:quartz_stained_glass:15)
B(14,-25,5,betternether:quartz_stained_glass:15)
B(15,-25,5,betternether:quartz_stained_glass:15)
B(13,-25,6,betternether:quartz_stained_glass:15)
B(14,-25,6,betternether:quartz_stained_glass:15)
B(15,-25,6,betternether:quartz_stained_glass:15)
B(14,-25,7,betternether:quartz_stained_glass:15)
B(15,-25,7,betternether:quartz_stained_glass:15)
B(14,-25,8,betternether:quartz_stained_glass:15)
B(15,-25,8,betternether:quartz_stained_glass:15)
B(15,-25,9,betternether:quartz_stained_glass:15)
B(15,-24,1,betternether:quartz_stained_glass:15)
B(13,-24,2,betternether:quartz_stained_glass:15)
B(14,-24,2,betternether:quartz_stained_glass:15)
B(15,-24,2,betternether:quartz_stained_glass:15)
B(12,-24,3,betternether:quartz_stained_glass:15)
B(13,-24,3,betternether:quartz_stained_glass:15)
B(14,-24,3,betternether:quartz_stained_glass:15)
B(15,-24,3,betternether:quartz_stained_glass:15)
B(12,-24,4,betternether:quartz_stained_glass:15)
B(13,-24,4,betternether:quartz_stained_glass:15)
B(14,-24,4,betternether:quartz_stained_glass:15)
B(15,-24,4,betternether:quartz_stained_glass:15)
B(12,-24,5,betternether:quartz_stained_glass:15)
B(13,-24,5,betternether:quartz_stained_glass:15)
B(14,-24,5,betternether:quartz_stained_glass:15)
RB(15,-24,5,srparasites:parasitestain:1,80,quark:crystal:1,30,srparasites:parasiterubbledense:1,100)
B(13,-24,6,betternether:quartz_stained_glass:15)
B(14,-24,6,betternether:quartz_stained_glass:15)
RB(15,-24,6,srparasites:parasitestain:1,80,quark:crystal:1,30,srparasites:parasiterubbledense:1,100)
B(14,-24,7,betternether:quartz_stained_glass:15)
RB(15,-24,7,srparasites:parasitestain:1,80,quark:crystal:1,30,srparasites:parasiterubbledense:1,100)
B(14,-24,8,betternether:quartz_stained_glass:15)
B(15,-24,8,betternether:quartz_stained_glass:15)
B(15,-24,9,betternether:quartz_stained_glass:15)
B(13,-23,1,betternether:quartz_stained_glass:15)
B(14,-23,1,betternether:quartz_stained_glass:15)
B(15,-23,1,betternether:quartz_stained_glass:15)
B(12,-23,2,betternether:quartz_stained_glass:15)
B(13,-23,2,betternether:quartz_stained_glass:15)
B(14,-23,2,betternether:quartz_stained_glass:15)
B(15,-23,2,betternether:quartz_stained_glass:15)
B(12,-23,3,betternether:quartz_stained_glass:15)
B(13,-23,3,betternether:quartz_stained_glass:15)
B(14,-23,3,betternether:quartz_stained_glass:15)
B(15,-23,3,betternether:quartz_stained_glass:15)
B(12,-23,4,betternether:quartz_stained_glass:15)
B(13,-23,4,betternether:quartz_stained_glass:15)
B(14,-23,4,betternether:quartz_stained_glass:15)
RB(15,-23,4,srparasites:parasitestain:1,80,quark:crystal:1,30,srparasites:parasiterubbledense:1,100)
B(12,-23,5,betternether:quartz_stained_glass:15)
B(13,-23,5,betternether:quartz_stained_glass:15)
B(14,-23,5,betternether:quartz_stained_glass:15)
RB(15,-23,5,srparasites:parasitestain:1,80,quark:crystal:1,30,srparasites:parasiterubbledense:1,100)
B(13,-23,6,betternether:quartz_stained_glass:15)
RB(14,-23,6,srparasites:parasitestain:1,80,quark:crystal:1,30,srparasites:parasiterubbledense:1,100)
RB(15,-23,6,srparasites:parasitestain:1,80,quark:crystal:1,30,srparasites:parasiterubbledense:1,100)
B(14,-23,7,betternether:quartz_stained_glass:15)
B(15,-23,7,betternether:quartz_stained_glass:15)
B(14,-23,8,betternether:quartz_stained_glass:15)
B(15,-23,8,betternether:quartz_stained_glass:15)
B(15,-23,9,betternether:quartz_stained_glass:15)
B(13,-22,0,betternether:quartz_stained_glass:15)
B(14,-22,0,betternether:quartz_stained_glass:15)
B(15,-22,0,betternether:quartz_stained_glass:15)
B(12,-22,1,betternether:quartz_stained_glass:15)
B(13,-22,1,betternether:quartz_stained_glass:15)
B(14,-22,1,betternether:quartz_stained_glass:15)
B(15,-22,1,betternether:quartz_stained_glass:15)
B(11,-22,2,betternether:quartz_stained_glass:15)
B(12,-22,2,betternether:quartz_stained_glass:15)
B(13,-22,2,betternether:quartz_stained_glass:15)
B(14,-22,2,betternether:quartz_stained_glass:15)
B(15,-22,2,betternether:quartz_stained_glass:15)
B(11,-22,3,betternether:quartz_stained_glass:15)
B(12,-22,3,betternether:quartz_stained_glass:15)
B(13,-22,3,betternether:quartz_stained_glass:15)
B(14,-22,3,betternether:quartz_stained_glass:15)
B(15,-22,3,betternether:quartz_stained_glass:15)
B(12,-22,4,betternether:quartz_stained_glass:15)
B(13,-22,4,betternether:quartz_stained_glass:15)
B(14,-22,4,betternether:quartz_stained_glass:15)
RB(15,-22,4,srparasites:parasitestain:1,80,quark:crystal:1,30,srparasites:parasiterubbledense:1,100)
B(12,-22,5,betternether:quartz_stained_glass:15)
B(13,-22,5,betternether:quartz_stained_glass:15)
RB(14,-22,5,srparasites:parasitestain:1,80,quark:crystal:1,30,srparasites:parasiterubbledense:1,100)
RB(15,-22,5,srparasites:parasitestain:1,80,quark:crystal:1,30,srparasites:parasiterubbledense:1,100)
B(13,-22,6,betternether:quartz_stained_glass:15)
RB(14,-22,6,srparasites:parasitestain:1,80,quark:crystal:1,30,srparasites:parasiterubbledense:1,100)
B(15,-22,6,betternether:quartz_stained_glass:15)
B(14,-22,7,betternether:quartz_stained_glass:15)
B(15,-22,7,betternether:quartz_stained_glass:15)
B(14,-22,8,betternether:quartz_stained_glass:15)
B(15,-22,8,betternether:quartz_stained_glass:15)
B(15,-22,9,betternether:quartz_stained_glass:15)
B(11,-21,0,betternether:quartz_stained_glass:15)
B(12,-21,0,betternether:quartz_stained_glass:15)
B(13,-21,0,betternether:quartz_stained_glass:15)
B(14,-21,0,betternether:quartz_stained_glass:15)
B(15,-21,0,betternether:quartz_stained_glass:15)
B(10,-21,1,betternether:quartz_stained_glass:15)
B(11,-21,1,betternether:quartz_stained_glass:15)
B(12,-21,1,betternether:quartz_stained_glass:15)
B(13,-21,1,betternether:quartz_stained_glass:15)
B(14,-21,1,betternether:quartz_stained_glass:15)
B(15,-21,1,betternether:quartz_stained_glass:15)
B(10,-21,2,betternether:quartz_stained_glass:15)
B(11,-21,2,betternether:quartz_stained_glass:15)
B(12,-21,2,betternether:quartz_stained_glass:15)
B(13,-21,2,betternether:quartz_stained_glass:15)
B(14,-21,2,betternether:quartz_stained_glass:15)
B(15,-21,2,betternether:quartz_stained_glass:15)
B(11,-21,3,betternether:quartz_stained_glass:15)
B(12,-21,3,betternether:quartz_stained_glass:15)
B(13,-21,3,betternether:quartz_stained_glass:15)
RB(14,-21,3,srparasites:parasitestain:1,80,quark:crystal:1,30,srparasites:parasiterubbledense:1,100)
RB(15,-21,3,srparasites:parasitestain:1,80,quark:crystal:1,30,srparasites:parasiterubbledense:1,100)
B(12,-21,4,betternether:quartz_stained_glass:15)
B(13,-21,4,betternether:quartz_stained_glass:15)
RB(14,-21,4,srparasites:parasitestain:1,80,quark:crystal:1,30,srparasites:parasiterubbledense:1,100)
RB(15,-21,4,srparasites:parasitestain:1,80,quark:crystal:1,30,srparasites:parasiterubbledense:1,100)
B(12,-21,5,betternether:quartz_stained_glass:15)
B(13,-21,5,betternether:quartz_stained_glass:15)
B(14,-21,5,betternether:quartz_stained_glass:15)
RB(15,-21,5,srparasites:parasitestain:1,80,quark:crystal:1,30,srparasites:parasiterubbledense:1,100)
B(13,-21,6,betternether:quartz_stained_glass:15)
B(14,-21,6,betternether:quartz_stained_glass:15)
B(15,-21,6,betternether:quartz_stained_glass:15)
B(14,-21,7,betternether:quartz_stained_glass:15)
B(15,-21,7,betternether:quartz_stained_glass:15)
B(14,-21,8,betternether:quartz_stained_glass:15)
B(15,-21,8,betternether:quartz_stained_glass:15)
B(10,-20,0,betternether:quartz_stained_glass:15)
B(11,-20,0,betternether:quartz_stained_glass:15)
B(12,-20,0,betternether:quartz_stained_glass:15)
B(13,-20,0,betternether:quartz_stained_glass:15)
B(14,-20,0,betternether:quartz_stained_glass:15)
B(15,-20,0,betternether:quartz_stained_glass:15)
B(10,-20,1,betternether:quartz_stained_glass:15)
B(11,-20,1,betternether:quartz_stained_glass:15)
B(12,-20,1,betternether:quartz_stained_glass:15)
RB(13,-20,1,srparasites:parasitestain:1,80,quark:crystal:1,30,srparasites:parasiterubbledense:1,100)
B(14,-20,1,betternether:quartz_stained_glass:15)
B(15,-20,1,betternether:quartz_stained_glass:15)
B(10,-20,2,betternether:quartz_stained_glass:15)
B(11,-20,2,betternether:quartz_stained_glass:15)
B(12,-20,2,betternether:quartz_stained_glass:15)
B(13,-20,2,betternether:quartz_stained_glass:15)
B(14,-20,2,betternether:quartz_stained_glass:15)
RB(15,-20,2,srparasites:parasitestain:1,80,quark:crystal:1,30,srparasites:parasiterubbledense:1,100)
B(11,-20,3,betternether:quartz_stained_glass:15)
B(12,-20,3,betternether:quartz_stained_glass:15)
RB(13,-20,3,srparasites:parasitestain:1,80,quark:crystal:1,30,srparasites:parasiterubbledense:1,100)
RB(14,-20,3,srparasites:parasitestain:1,80,quark:crystal:1,30,srparasites:parasiterubbledense:1,100)
RB(15,-20,3,srparasites:parasitestain:1,80,quark:crystal:1,30,srparasites:parasiterubbledense:1,100)
B(12,-20,4,betternether:quartz_stained_glass:15)
B(13,-20,4,betternether:quartz_stained_glass:15)
RB(14,-20,4,srparasites:parasitestain:1,80,quark:crystal:1,30,srparasites:parasiterubbledense:1,100)
RB(15,-20,4,srparasites:parasitestain:1,80,quark:crystal:1,30,srparasites:parasiterubbledense:1,100)
B(12,-20,5,betternether:quartz_stained_glass:15)
B(13,-20,5,betternether:quartz_stained_glass:15)
B(14,-20,5,betternether:quartz_stained_glass:15)
B(15,-20,5,betternether:quartz_stained_glass:15)
B(13,-20,6,betternether:quartz_stained_glass:15)
B(14,-20,6,betternether:quartz_stained_glass:15)
B(15,-20,6,betternether:quartz_stained_glass:15)
B(14,-20,7,betternether:quartz_stained_glass:15)
B(15,-20,7,betternether:quartz_stained_glass:15)
B(14,-20,8,betternether:quartz_stained_glass:15)
B(15,-20,8,betternether:quartz_stained_glass:15)
B(9,-19,0,betternether:quartz_stained_glass:15)
B(10,-19,0,betternether:quartz_stained_glass:15)
B(11,-19,0,betternether:quartz_stained_glass:15)
RB(12,-19,0,srparasites:parasitestain:1,80,quark:crystal:1,30,srparasites:parasiterubbledense:1,100)
B(13,-19,0,betternether:quartz_stained_glass:15)
B(14,-19,0,betternether:quartz_stained_glass:15)
B(15,-19,0,betternether:quartz_stained_glass:15)
B(9,-19,1,betternether:quartz_stained_glass:15)
B(10,-19,1,betternether:quartz_stained_glass:15)
B(11,-19,1,betternether:quartz_stained_glass:15)
B(12,-19,1,betternether:quartz_stained_glass:15)
RB(13,-19,1,srparasites:parasitestain:1,80,quark:crystal:1,30,srparasites:parasiterubbledense:1,100)
RB(14,-19,1,srparasites:parasitestain:1,80,quark:crystal:1,30,srparasites:parasiterubbledense:1,100)
B(15,-19,1,betternether:quartz_stained_glass:15)
B(10,-19,2,betternether:quartz_stained_glass:15)
B(11,-19,2,betternether:quartz_stained_glass:15)
RB(12,-19,2,srparasites:parasitestain:1,80,quark:crystal:1,30,srparasites:parasiterubbledense:1,100)
RB(13,-19,2,srparasites:parasitestain:1,80,quark:crystal:1,30,srparasites:parasiterubbledense:1,100)
RB(14,-19,2,srparasites:parasitestain:1,80,quark:crystal:1,30,srparasites:parasiterubbledense:1,100)
B(15,-19,2,betternether:quartz_stained_glass:15)
B(11,-19,3,betternether:quartz_stained_glass:15)
B(12,-19,3,betternether:quartz_stained_glass:15)
B(13,-19,3,betternether:quartz_stained_glass:15)
RB(14,-19,3,srparasites:parasitestain:1,80,quark:crystal:1,30,srparasites:parasiterubbledense:1,100)
B(15,-19,3,betternether:quartz_stained_glass:15)
B(12,-19,4,betternether:quartz_stained_glass:15)
B(13,-19,4,betternether:quartz_stained_glass:15)
B(14,-19,4,betternether:quartz_stained_glass:15)
B(15,-19,4,betternether:quartz_stained_glass:15)
B(12,-19,5,betternether:quartz_stained_glass:15)
B(13,-19,5,betternether:quartz_stained_glass:15)
B(14,-19,5,betternether:quartz_stained_glass:15)
B(15,-19,5,betternether:quartz_stained_glass:15)
B(13,-19,6,betternether:quartz_stained_glass:15)
B(14,-19,6,betternether:quartz_stained_glass:15)
B(15,-19,6,betternether:quartz_stained_glass:15)
B(14,-19,7,betternether:quartz_stained_glass:15)
B(9,-18,0,betternether:quartz_stained_glass:15)
B(10,-18,0,betternether:quartz_stained_glass:15)
B(11,-18,0,betternether:quartz_stained_glass:15)
RB(12,-18,0,srparasites:parasitestain:1,80,quark:crystal:1,30,srparasites:parasiterubbledense:1,100)
RB(13,-18,0,srparasites:parasitestain:1,80,quark:crystal:1,30,srparasites:parasiterubbledense:1,100)
B(14,-18,0,betternether:quartz_stained_glass:15)
B(15,-18,0,betternether:quartz_stained_glass:15)
B(9,-18,1,betternether:quartz_stained_glass:15)
B(10,-18,1,betternether:quartz_stained_glass:15)
B(11,-18,1,betternether:quartz_stained_glass:15)
RB(12,-18,1,srparasites:parasitestain:1,80,quark:crystal:1,30,srparasites:parasiterubbledense:1,100)
RB(13,-18,1,srparasites:parasitestain:1,80,quark:crystal:1,30,srparasites:parasiterubbledense:1,100)
RB(14,-18,1,srparasites:parasitestain:1,80,quark:crystal:1,30,srparasites:parasiterubbledense:1,100)
B(15,-18,1,betternether:quartz_stained_glass:15)
B(10,-18,2,betternether:quartz_stained_glass:15)
B(11,-18,2,betternether:quartz_stained_glass:15)
RB(12,-18,2,srparasites:parasitestain:1,80,quark:crystal:1,30,srparasites:parasiterubbledense:1,100)
B(13,-18,2,betternether:quartz_stained_glass:15)
B(14,-18,2,betternether:quartz_stained_glass:15)
B(15,-18,2,betternether:quartz_stained_glass:15)
B(11,-18,3,betternether:quartz_stained_glass:15)
B(12,-18,3,betternether:quartz_stained_glass:15)
B(13,-18,3,betternether:quartz_stained_glass:15)
RB(14,-18,3,srparasites:parasitestain:1,80,quark:crystal:1,30,srparasites:parasiterubbledense:1,100)
B(15,-18,3,betternether:quartz_stained_glass:15)
B(12,-18,4,betternether:quartz_stained_glass:15)
B(13,-18,4,betternether:quartz_stained_glass:15)
B(14,-18,4,betternether:quartz_stained_glass:15)
B(15,-18,4,betternether:quartz_stained_glass:15)
B(12,-18,5,betternether:quartz_stained_glass:15)
B(13,-18,5,betternether:quartz_stained_glass:15)
B(14,-18,5,betternether:quartz_stained_glass:15)
B(15,-18,5,betternether:quartz_stained_glass:15)
B(14,-18,6,betternether:quartz_stained_glass:15)
B(9,-17,0,betternether:quartz_stained_glass:15)
B(10,-17,0,betternether:quartz_stained_glass:15)
RB(11,-17,0,srparasites:parasitestain:1,80,quark:crystal:1,30,srparasites:parasiterubbledense:1,100)
RB(12,-17,0,srparasites:parasitestain:1,80,quark:crystal:1,30,srparasites:parasiterubbledense:1,100)
B(13,-17,0,betternether:quartz_stained_glass:15)
B(14,-17,0,betternether:quartz_stained_glass:15)
B(15,-17,0,betternether:quartz_stained_glass:15)
B(9,-17,1,betternether:quartz_stained_glass:15)
B(10,-17,1,betternether:quartz_stained_glass:15)
RB(11,-17,1,srparasites:parasitestain:1,80,quark:crystal:1,30,srparasites:parasiterubbledense:1,100)
B(12,-17,1,betternether:quartz_stained_glass:15)
RB(13,-17,1,srparasites:parasitestain:1,80,quark:crystal:1,30,srparasites:parasiterubbledense:1,100)
B(14,-17,1,betternether:quartz_stained_glass:15)
B(15,-17,1,betternether:quartz_stained_glass:15)
B(10,-17,2,betternether:quartz_stained_glass:15)
B(11,-17,2,betternether:quartz_stained_glass:15)
B(12,-17,2,betternether:quartz_stained_glass:15)
B(13,-17,2,betternether:quartz_stained_glass:15)
B(14,-17,2,betternether:quartz_stained_glass:15)
B(15,-17,2,betternether:quartz_stained_glass:15)
B(11,-17,3,betternether:quartz_stained_glass:15)
B(12,-17,3,betternether:quartz_stained_glass:15)
B(13,-17,3,betternether:quartz_stained_glass:15)
B(14,-17,3,betternether:quartz_stained_glass:15)
B(15,-17,3,betternether:quartz_stained_glass:15)
B(12,-17,4,betternether:quartz_stained_glass:15)
B(13,-17,4,betternether:quartz_stained_glass:15)
B(14,-17,4,betternether:quartz_stained_glass:15)
B(15,-17,4,betternether:quartz_stained_glass:15)
B(9,-16,0,betternether:quartz_stained_glass:15)
RB(10,-16,0,srparasites:parasitestain:1,80,quark:crystal:1,30,srparasites:parasiterubbledense:1,100)
RB(11,-16,0,srparasites:parasitestain:1,80,quark:crystal:1,30,srparasites:parasiterubbledense:1,100)
RB(12,-16,0,srparasites:parasitestain:1,80,quark:crystal:1,30,srparasites:parasiterubbledense:1,100)
B(13,-16,0,betternether:quartz_stained_glass:15)
B(14,-16,0,betternether:quartz_stained_glass:15)
B(15,-16,0,betternether:quartz_stained_glass:15)
B(9,-16,1,betternether:quartz_stained_glass:15)
B(10,-16,1,betternether:quartz_stained_glass:15)
B(11,-16,1,betternether:quartz_stained_glass:15)
B(12,-16,1,betternether:quartz_stained_glass:15)
B(13,-16,1,betternether:quartz_stained_glass:15)
B(14,-16,1,betternether:quartz_stained_glass:15)
B(15,-16,1,betternether:quartz_stained_glass:15)
B(10,-16,2,betternether:quartz_stained_glass:15)
B(11,-16,2,betternether:quartz_stained_glass:15)
B(12,-16,2,betternether:quartz_stained_glass:15)
B(13,-16,2,betternether:quartz_stained_glass:15)
B(14,-16,2,betternether:quartz_stained_glass:15)
B(15,-16,2,betternether:quartz_stained_glass:15)
B(11,-16,3,betternether:quartz_stained_glass:15)
B(12,-16,3,betternether:quartz_stained_glass:15)
B(13,-16,3,betternether:quartz_stained_glass:15)
B(14,-16,3,betternether:quartz_stained_glass:15)
B(15,-16,3,betternether:quartz_stained_glass:15)
B(12,-16,4,betternether:quartz_stained_glass:15)
B(13,-16,4,betternether:quartz_stained_glass:15)
B(14,-16,4,betternether:quartz_stained_glass:15)
B(9,-15,0,betternether:quartz_stained_glass:15)
RB(10,-15,0,srparasites:parasitestain:1,80,quark:crystal:1,30,srparasites:parasiterubbledense:1,100)
B(11,-15,0,betternether:quartz_stained_glass:15)
RB(12,-15,0,srparasites:parasitestain:1,80,quark:crystal:1,30,srparasites:parasiterubbledense:1,100)
B(13,-15,0,betternether:quartz_stained_glass:15)
B(14,-15,0,betternether:quartz_stained_glass:15)
B(15,-15,0,betternether:quartz_stained_glass:15)
B(9,-15,1,betternether:quartz_stained_glass:15)
B(10,-15,1,betternether:quartz_stained_glass:15)
B(11,-15,1,betternether:quartz_stained_glass:15)
B(12,-15,1,betternether:quartz_stained_glass:15)
B(13,-15,1,betternether:quartz_stained_glass:15)
B(14,-15,1,betternether:quartz_stained_glass:15)
B(15,-15,1,betternether:quartz_stained_glass:15)
B(10,-15,2,betternether:quartz_stained_glass:15)
B(11,-15,2,betternether:quartz_stained_glass:15)
B(12,-15,2,betternether:quartz_stained_glass:15)
B(13,-15,2,betternether:quartz_stained_glass:15)
B(14,-15,2,betternether:quartz_stained_glass:15)
B(15,-15,2,betternether:quartz_stained_glass:15)
B(11,-15,3,betternether:quartz_stained_glass:15)
B(12,-15,3,betternether:quartz_stained_glass:15)
B(13,-15,3,betternether:quartz_stained_glass:15)
B(14,-15,3,betternether:quartz_stained_glass:15)
B(9,-14,0,betternether:quartz_stained_glass:15)
B(10,-14,0,betternether:quartz_stained_glass:15)
B(11,-14,0,betternether:quartz_stained_glass:15)
B(12,-14,0,betternether:quartz_stained_glass:15)
B(13,-14,0,betternether:quartz_stained_glass:15)
B(14,-14,0,betternether:quartz_stained_glass:15)
B(9,-14,1,betternether:quartz_stained_glass:15)
B(10,-14,1,betternether:quartz_stained_glass:15)
B(11,-14,1,betternether:quartz_stained_glass:15)
B(12,-14,1,betternether:quartz_stained_glass:15)
B(13,-14,1,betternether:quartz_stained_glass:15)
B(14,-14,1,betternether:quartz_stained_glass:15)
B(10,-14,2,betternether:quartz_stained_glass:15)
B(11,-14,2,betternether:quartz_stained_glass:15)
B(12,-14,2,betternether:quartz_stained_glass:15)
B(9,-13,0,betternether:quartz_stained_glass:15)
B(10,-13,0,betternether:quartz_stained_glass:15)
B(11,-13,0,betternether:quartz_stained_glass:15)
B(12,-13,0,betternether:quartz_stained_glass:15)
B(13,-13,0,betternether:quartz_stained_glass:15)
B(14,-13,0,betternether:quartz_stained_glass:15)
B(9,-13,1,betternether:quartz_stained_glass:15)
B(10,-13,1,betternether:quartz_stained_glass:15)
B(11,-13,1,betternether:quartz_stained_glass:15)
B(12,-13,1,betternether:quartz_stained_glass:15)
B(10,-13,2,betternether:quartz_stained_glass:15)
B(11,-13,2,betternether:quartz_stained_glass:15)
B(9,-12,0,betternether:quartz_stained_glass:15)
B(10,-12,0,betternether:quartz_stained_glass:15)
B(11,-12,0,betternether:quartz_stained_glass:15)
B(9,-12,1,betternether:quartz_stained_glass:15)
B(10,-12,1,betternether:quartz_stained_glass:15)
B(9,-11,0,betternether:quartz_stained_glass:15)
B(10,-11,0,betternether:quartz_stained_glass:15)
B(9,-10,0,betternether:quartz_stained_glass:15)

#######################################################################
# +-----------------------------------------------------------------+ #
# |                             Branches                            | #
# +-----------------------------------------------------------------+ #
#######################################################################

BR(16,0,0,true,CEILING_SPIKE-SET-FAT-BIG-06_1x1,NORTH,100,0)
BR(0,0,16,true,CEILING_SPIKE-SET-FAT-BIG-06_0x2,NORTH,100,0)
