
#######################################################################
# +-----------------------------------------------------------------+ #
# |                            BO4 object                           | #
# +-----------------------------------------------------------------+ #
#######################################################################

Author: NLBlackEagle

Description: No description given

SettingsMode: WriteWithoutComments


#######################################################################
# +-----------------------------------------------------------------+ #
# |                          Main settings                          | #
# +-----------------------------------------------------------------+ #
#######################################################################

FixedRotation: 

Frequency: 0

SpawnHeight: highestBlock

UseCenterForHighestBlock: true

##############################
# Height Limits for the BO4. #
##############################

MinHeight: 0

MaxHeight: 255

InheritBO3: 

InheritBO3Rotation: NORTH

OverrideChildSettings: true

OverrideParentHeight: false

CanOverride: false

BranchFrequency: 0

BranchFrequencyGroup: 

MustBeBelowOther: false

MustBeInside: 

CannotBeInside: 

ReplacesBO3: 

MustBeInsideWorldBorders: false

CanSpawnOnWater: true

SpawnOnWaterOnly: false

SpawnUnderWater: false

SpawnAtWaterLevel: false

HeightOffset: 0

RemoveAir: false

ReplaceAbove: 

ReplaceBelow: STONE

ReplaceWithBiomeBlocks: true

ReplaceWithSurfaceBlock: GRASS

ReplaceWithGroundBlock: DIRT

ReplaceWithStoneBlock: STONE

SmoothRadius: 0

SmoothHeightOffset: 0

SmoothStartTop: false

SmoothStartWood: false

SmoothingSurfaceBlock: 

SmoothingGroundBlock: 

BO3Group: 

IsSpawnPoint: false

DoReplaceBlocks: true


#######################################################################
# +-----------------------------------------------------------------+ #
# |                              Blocks                             | #
# +-----------------------------------------------------------------+ #
#######################################################################

Block(-5,0,4,STONE:0)
Block(-5,0,5,STONE:0)
Block(-5,0,6,STONE:0)
Block(-5,0,7,STONE:0)
Block(-5,0,8,STONE:0)
Block(-5,1,5,STONE:0)
Block(-5,1,6,STONE:0)
Block(-4,0,-7,STONE:0)
Block(-4,0,0,STONE:0)
Block(-4,0,1,STONE:0)
Block(-4,0,2,STONE:0)
Block(-4,0,3,STONE:0)
Block(-4,0,4,STONE:0)
Block(-4,0,5,STONE:0)
Block(-4,0,6,STONE:0)
Block(-4,0,7,STONE:0)
Block(-4,0,8,STONE:0)
Block(-4,1,2,STONE:0)
Block(-4,1,3,STONE:0)
Block(-4,1,4,STONE:0)
Block(-4,1,5,STONE:0)
Block(-4,1,6,STONE:0)
Block(-4,1,7,STONE:0)
Block(-4,1,8,STONE:0)
Block(-4,2,4,STONE:0)
Block(-4,2,5,STONE:0)
Block(-4,2,6,STONE:0)
Block(-4,2,7,STONE:0)
Block(-3,0,-7,STONE:0)
Block(-3,0,-6,STONE:0)
Block(-3,0,-5,STONE:0)
Block(-3,0,-3,STONE:0)
Block(-3,0,-2,STONE:0)
Block(-3,0,-1,STONE:0)
Block(-3,0,0,STONE:0)
Block(-3,0,1,STONE:0)
Block(-3,0,2,STONE:0)
Block(-3,0,3,STONE:0)
Block(-3,0,4,STONE:0)
Block(-3,0,5,STONE:0)
Block(-3,0,6,STONE:0)
Block(-3,0,7,STONE:0)
Block(-3,0,8,STONE:0)
Block(-3,1,-7,STONE:0)
Block(-3,1,-6,STONE:0)
Block(-3,1,-5,STONE:0)
Block(-3,1,-1,STONE:0)
Block(-3,1,0,STONE:0)
Block(-3,1,1,STONE:0)
Block(-3,1,2,STONE:0)
Block(-3,1,3,STONE:0)
Block(-3,1,4,STONE:0)
Block(-3,1,5,STONE:0)
Block(-3,1,6,STONE:0)
Block(-3,1,7,STONE:0)
Block(-3,1,8,STONE:0)
Block(-3,2,-7,STONE:0)
Block(-3,2,-6,STONE:0)
Block(-3,2,0,STONE:0)
Block(-3,2,1,STONE:0)
Block(-3,2,2,STONE:0)
Block(-3,2,3,STONE:0)
Block(-3,2,4,STONE:0)
Block(-3,2,5,STONE:0)
Block(-3,2,6,STONE:0)
Block(-3,2,7,STONE:0)
Block(-3,2,8,STONE:0)
Block(-3,3,3,STONE:0)
Block(-3,3,4,STONE:0)
Block(-3,3,5,STONE:0)
Block(-3,3,6,STONE:0)
Block(-3,3,7,STONE:0)
Block(-3,3,8,STONE:0)
Block(-3,4,5,STONE:0)
Block(-3,4,6,STONE:0)
Block(-2,0,-7,STONE:0)
Block(-2,0,-6,STONE:0)
Block(-2,0,-5,STONE:0)
Block(-2,0,-4,STONE:0)
Block(-2,0,-3,STONE:0)
Block(-2,0,-2,STONE:0)
Block(-2,0,-1,STONE:0)
Block(-2,0,0,STONE:0)
Block(-2,0,1,STONE:0)
Block(-2,0,2,STONE:0)
Block(-2,0,3,STONE:0)
Block(-2,0,4,STONE:0)
Block(-2,0,5,STONE:0)
Block(-2,0,6,STONE:0)
Block(-2,0,7,STONE:0)
Block(-2,0,8,STONE:0)
Block(-2,1,-7,STONE:0)
Block(-2,1,-6,STONE:0)
Block(-2,1,-5,STONE:0)
Block(-2,1,-4,STONE:0)
Block(-2,1,-3,STONE:0)
Block(-2,1,-2,STONE:0)
Block(-2,1,-1,STONE:0)
Block(-2,1,0,STONE:0)
Block(-2,1,1,STONE:0)
Block(-2,1,2,STONE:0)
Block(-2,1,3,STONE:0)
Block(-2,1,4,STONE:0)
Block(-2,1,5,STONE:0)
Block(-2,1,6,STONE:0)
Block(-2,1,7,STONE:0)
Block(-2,1,8,STONE:0)
Block(-2,2,-7,STONE:0)
Block(-2,2,-6,STONE:0)
Block(-2,2,-5,STONE:0)
Block(-2,2,-4,STONE:0)
Block(-2,2,-1,STONE:0)
Block(-2,2,0,STONE:0)
Block(-2,2,1,STONE:0)
Block(-2,2,2,STONE:0)
Block(-2,2,3,STONE:0)
Block(-2,2,4,STONE:0)
Block(-2,2,5,STONE:0)
Block(-2,2,6,STONE:0)
Block(-2,2,7,STONE:0)
Block(-2,2,8,STONE:0)
Block(-2,3,-7,STONE:0)
Block(-2,3,-6,STONE:0)
Block(-2,3,-5,STONE:0)
Block(-2,3,0,STONE:0)
Block(-2,3,1,STONE:0)
Block(-2,3,2,STONE:0)
Block(-2,3,3,STONE:0)
Block(-2,3,4,STONE:0)
Block(-2,3,5,STONE:0)
Block(-2,3,6,STONE:0)
Block(-2,3,7,STONE:0)
Block(-2,3,8,STONE:0)
Block(-2,4,-6,STONE:0)
Block(-2,4,3,STONE:0)
Block(-2,4,4,STONE:0)
Block(-2,4,5,STONE:0)
Block(-2,4,6,STONE:0)
Block(-2,4,7,STONE:0)
Block(-2,4,8,STONE:0)
Block(-2,5,5,STONE:0)
Block(-2,5,6,STONE:0)
Block(-2,5,7,STONE:0)
Block(-1,0,-7,STONE:0)
Block(-1,0,-6,STONE:0)
Block(-1,0,-5,STONE:0)
Block(-1,0,-4,STONE:0)
Block(-1,0,-3,STONE:0)
Block(-1,0,-2,STONE:0)
Block(-1,0,-1,STONE:0)
Block(-1,0,0,STONE:0)
Block(-1,0,1,STONE:0)
Block(-1,0,2,STONE:0)
Block(-1,0,3,STONE:0)
Block(-1,0,4,STONE:0)
Block(-1,0,5,STONE:0)
Block(-1,0,6,STONE:0)
Block(-1,0,7,STONE:0)
Block(-1,0,8,STONE:0)
Block(-1,1,-7,STONE:0)
Block(-1,1,-6,STONE:0)
Block(-1,1,-5,STONE:0)
Block(-1,1,-4,STONE:0)
Block(-1,1,-3,STONE:0)
Block(-1,1,-2,STONE:0)
Block(-1,1,-1,STONE:0)
Block(-1,1,0,STONE:0)
Block(-1,1,1,STONE:0)
Block(-1,1,2,STONE:0)
Block(-1,1,3,STONE:0)
Block(-1,1,4,STONE:0)
Block(-1,1,5,STONE:0)
Block(-1,1,6,STONE:0)
Block(-1,1,7,STONE:0)
Block(-1,1,8,STONE:0)
Block(-1,2,-7,STONE:0)
Block(-1,2,-6,STONE:0)
Block(-1,2,-5,STONE:0)
Block(-1,2,-4,STONE:0)
Block(-1,2,-3,STONE:0)
Block(-1,2,-2,STONE:0)
Block(-1,2,-1,STONE:0)
Block(-1,2,0,STONE:0)
Block(-1,2,1,STONE:0)
Block(-1,2,2,STONE:0)
Block(-1,2,3,STONE:0)
Block(-1,2,4,STONE:0)
Block(-1,2,5,STONE:0)
Block(-1,2,6,STONE:0)
Block(-1,2,7,STONE:0)
Block(-1,2,8,STONE:0)
Block(-1,3,-7,STONE:0)
Block(-1,3,-6,STONE:0)
Block(-1,3,-5,STONE:0)
Block(-1,3,-4,STONE:0)
Block(-1,3,-3,STONE:0)
Block(-1,3,-1,STONE:0)
Block(-1,3,0,STONE:0)
Block(-1,3,1,STONE:0)
Block(-1,3,2,STONE:0)
Block(-1,3,3,STONE:0)
Block(-1,3,4,STONE:0)
Block(-1,3,5,STONE:0)
Block(-1,3,6,STONE:0)
Block(-1,3,7,STONE:0)
Block(-1,3,8,STONE:0)
Block(-1,4,-7,STONE:0)
Block(-1,4,-6,STONE:0)
Block(-1,4,-5,STONE:0)
Block(-1,4,-4,STONE:0)
Block(-1,4,-3,STONE:0)
Block(-1,4,0,STONE:0)
Block(-1,4,1,STONE:0)
Block(-1,4,3,STONE:0)
Block(-1,4,4,STONE:0)
Block(-1,4,5,STONE:0)
Block(-1,4,6,STONE:0)
Block(-1,4,7,STONE:0)
Block(-1,4,8,STONE:0)
Block(-1,5,-7,STONE:0)
Block(-1,5,-6,STONE:0)
Block(-1,5,-5,STONE:0)
Block(-1,5,-4,STONE:0)
Block(-1,5,1,STONE:0)
Block(-1,5,3,STONE:0)
Block(-1,5,4,STONE:0)
Block(-1,5,5,STONE:0)
Block(-1,5,6,STONE:0)
Block(-1,5,7,STONE:0)
Block(-1,5,8,STONE:0)
Block(-1,6,-7,STONE:0)
Block(-1,6,-6,STONE:0)
Block(-1,6,-5,STONE:0)
Block(-1,6,4,STONE:0)
Block(-1,6,6,STONE:0)
Block(-1,6,7,STONE:0)
Block(0,0,-7,STONE:0)
Block(0,0,-6,STONE:0)
Block(0,0,-5,STONE:0)
Block(0,0,-4,STONE:0)
Block(0,0,-3,STONE:0)
Block(0,0,-2,STONE:0)
Block(0,0,-1,STONE:0)
Block(0,0,0,STONE:0)
Block(0,0,1,STONE:0)
Block(0,0,2,STONE:0)
Block(0,0,3,STONE:0)
Block(0,0,4,STONE:0)
Block(0,0,5,STONE:0)
Block(0,0,6,STONE:0)
Block(0,0,7,STONE:0)
Block(0,0,8,STONE:0)
Block(0,1,-7,STONE:0)
Block(0,1,-6,STONE:0)
Block(0,1,-5,STONE:0)
Block(0,1,-4,STONE:0)
Block(0,1,-3,STONE:0)
Block(0,1,-2,STONE:0)
Block(0,1,-1,STONE:0)
Block(0,1,0,STONE:0)
Block(0,1,1,STONE:0)
Block(0,1,2,STONE:0)
Block(0,1,3,STONE:0)
Block(0,1,4,STONE:0)
Block(0,1,5,STONE:0)
Block(0,1,6,STONE:0)
Block(0,1,7,STONE:0)
Block(0,1,8,STONE:0)
Block(0,2,-7,STONE:0)
Block(0,2,-6,STONE:0)
Block(0,2,-5,STONE:0)
Block(0,2,-4,STONE:0)
Block(0,2,-3,STONE:0)
Block(0,2,-2,STONE:0)
Block(0,2,-1,STONE:0)
Block(0,2,0,STONE:0)
Block(0,2,1,STONE:0)
Block(0,2,2,STONE:0)
Block(0,2,3,STONE:0)
Block(0,2,4,STONE:0)
Block(0,2,5,STONE:0)
Block(0,2,6,STONE:0)
Block(0,2,7,STONE:0)
Block(0,2,8,STONE:0)
Block(0,3,-7,STONE:0)
Block(0,3,-6,STONE:0)
Block(0,3,-5,STONE:0)
Block(0,3,-4,STONE:0)
Block(0,3,-3,STONE:0)
Block(0,3,-2,STONE:0)
Block(0,3,-1,STONE:0)
Block(0,3,0,STONE:0)
Block(0,3,1,STONE:0)
Block(0,3,2,STONE:0)
Block(0,3,3,STONE:0)
Block(0,3,4,STONE:0)
Block(0,3,5,STONE:0)
Block(0,3,6,STONE:0)
Block(0,3,7,STONE:0)
Block(0,3,8,STONE:0)
Block(0,4,-7,STONE:0)
Block(0,4,-6,STONE:0)
Block(0,4,-5,STONE:0)
Block(0,4,-4,STONE:0)
Block(0,4,-3,STONE:0)
Block(0,4,-2,STONE:0)
Block(0,4,-1,STONE:0)
Block(0,4,0,STONE:0)
Block(0,4,1,STONE:0)
Block(0,4,2,STONE:0)
Block(0,4,3,STONE:0)
Block(0,4,4,STONE:0)
Block(0,4,5,STONE:0)
Block(0,4,6,STONE:0)
Block(0,4,7,STONE:0)
Block(0,4,8,STONE:0)
Block(0,5,-7,STONE:0)
Block(0,5,-6,STONE:0)
Block(0,5,-5,STONE:0)
Block(0,5,-4,STONE:0)
Block(0,5,-3,STONE:0)
Block(0,5,-2,STONE:0)
Block(0,5,-1,STONE:0)
Block(0,5,1,STONE:0)
Block(0,5,2,STONE:0)
Block(0,5,3,STONE:0)
Block(0,5,4,STONE:0)
Block(0,5,5,STONE:0)
Block(0,5,6,STONE:0)
Block(0,5,7,STONE:0)
Block(0,5,8,STONE:0)
Block(0,6,-7,STONE:0)
Block(0,6,-6,STONE:0)
Block(0,6,-5,STONE:0)
Block(0,6,-4,STONE:0)
Block(0,6,-1,STONE:0)
Block(0,6,2,STONE:0)
Block(0,6,3,STONE:0)
Block(0,6,4,STONE:0)
Block(0,6,5,STONE:0)
Block(0,6,6,STONE:0)
Block(0,6,7,STONE:0)
Block(0,6,8,STONE:0)
Block(0,7,-7,STONE:0)
Block(0,7,-6,STONE:0)
Block(0,7,3,STONE:0)
Block(0,7,4,STONE:0)
Block(0,7,6,STONE:0)
Block(0,7,7,STONE:0)
Block(1,0,-7,STONE:0)
Block(1,0,-6,STONE:0)
Block(1,0,-5,STONE:0)
Block(1,0,-4,STONE:0)
Block(1,0,-3,STONE:0)
Block(1,0,-2,STONE:0)
Block(1,0,-1,STONE:0)
Block(1,0,0,STONE:0)
Block(1,0,1,STONE:0)
Block(1,0,2,STONE:0)
Block(1,0,3,STONE:0)
Block(1,0,4,STONE:0)
Block(1,0,5,STONE:0)
Block(1,0,6,STONE:0)
Block(1,0,7,STONE:0)
Block(1,0,8,STONE:0)
Block(1,1,-7,STONE:0)
Block(1,1,-6,STONE:0)
Block(1,1,-5,STONE:0)
Block(1,1,-4,STONE:0)
Block(1,1,-3,STONE:0)
Block(1,1,-2,STONE:0)
Block(1,1,-1,STONE:0)
Block(1,1,0,STONE:0)
Block(1,1,1,STONE:0)
Block(1,1,2,STONE:0)
Block(1,1,3,STONE:0)
Block(1,1,4,STONE:0)
Block(1,1,5,STONE:0)
Block(1,1,6,STONE:0)
Block(1,1,7,STONE:0)
Block(1,1,8,STONE:0)
Block(1,2,-7,STONE:0)
Block(1,2,-6,STONE:0)
Block(1,2,-5,STONE:0)
Block(1,2,-4,STONE:0)
Block(1,2,-3,STONE:0)
Block(1,2,-2,STONE:0)
Block(1,2,-1,STONE:0)
Block(1,2,0,STONE:0)
Block(1,2,1,STONE:0)
Block(1,2,2,STONE:0)
Block(1,2,3,STONE:0)
Block(1,2,4,STONE:0)
Block(1,2,5,STONE:0)
Block(1,2,6,STONE:0)
Block(1,2,7,STONE:0)
Block(1,2,8,STONE:0)
Block(1,3,-7,STONE:0)
Block(1,3,-6,STONE:0)
Block(1,3,-5,STONE:0)
Block(1,3,-4,STONE:0)
Block(1,3,-3,STONE:0)
Block(1,3,-2,STONE:0)
Block(1,3,-1,STONE:0)
Block(1,3,0,STONE:0)
Block(1,3,1,STONE:0)
Block(1,3,2,STONE:0)
Block(1,3,3,STONE:0)
Block(1,3,4,STONE:0)
Block(1,3,5,STONE:0)
Block(1,3,6,STONE:0)
Block(1,3,7,STONE:0)
Block(1,3,8,STONE:0)
Block(1,4,-7,STONE:0)
Block(1,4,-6,STONE:0)
Block(1,4,-5,STONE:0)
Block(1,4,-4,STONE:0)
Block(1,4,-3,STONE:0)
Block(1,4,-2,STONE:0)
Block(1,4,-1,STONE:0)
Block(1,4,0,STONE:0)
Block(1,4,1,STONE:0)
Block(1,4,2,STONE:0)
Block(1,4,3,STONE:0)
Block(1,4,4,STONE:0)
Block(1,4,5,STONE:0)
Block(1,4,6,STONE:0)
Block(1,4,7,STONE:0)
Block(1,4,8,STONE:0)
Block(1,5,-7,STONE:0)
Block(1,5,-6,STONE:0)
Block(1,5,-5,STONE:0)
Block(1,5,-4,STONE:0)
Block(1,5,-3,STONE:0)
Block(1,5,-2,STONE:0)
Block(1,5,-1,STONE:0)
Block(1,5,0,STONE:0)
Block(1,5,1,STONE:0)
Block(1,5,2,STONE:0)
Block(1,5,3,STONE:0)
Block(1,5,4,STONE:0)
Block(1,5,5,STONE:0)
Block(1,5,6,STONE:0)
Block(1,5,7,STONE:0)
Block(1,5,8,STONE:0)
Block(1,6,-7,STONE:0)
Block(1,6,-6,STONE:0)
Block(1,6,-5,STONE:0)
Block(1,6,-4,STONE:0)
Block(1,6,-3,STONE:0)
Block(1,6,-2,STONE:0)
Block(1,6,-1,STONE:0)
Block(1,6,0,STONE:0)
Block(1,6,2,STONE:0)
Block(1,6,3,STONE:0)
Block(1,6,4,STONE:0)
Block(1,6,5,STONE:0)
Block(1,6,6,STONE:0)
Block(1,6,7,STONE:0)
Block(1,6,8,STONE:0)
Block(1,7,-7,STONE:0)
Block(1,7,-6,STONE:0)
Block(1,7,-5,STONE:0)
Block(1,7,-4,STONE:0)
Block(1,7,-3,STONE:0)
Block(1,7,0,STONE:0)
Block(1,7,2,STONE:0)
Block(1,7,3,STONE:0)
Block(1,7,4,STONE:0)
Block(1,7,5,STONE:0)
Block(1,7,6,STONE:0)
Block(1,7,7,STONE:0)
Block(1,7,8,STONE:0)
Block(1,8,-5,STONE:0)
Block(2,0,-7,STONE:0)
Block(2,0,-6,STONE:0)
Block(2,0,-5,STONE:0)
Block(2,0,-4,STONE:0)
Block(2,0,-3,STONE:0)
Block(2,0,-2,STONE:0)
Block(2,0,-1,STONE:0)
Block(2,0,0,STONE:0)
Block(2,0,1,STONE:0)
Block(2,0,2,STONE:0)
Block(2,0,3,STONE:0)
Block(2,0,4,STONE:0)
Block(2,0,5,STONE:0)
Block(2,0,6,STONE:0)
Block(2,0,7,STONE:0)
Block(2,0,8,STONE:0)
Block(2,1,-7,STONE:0)
Block(2,1,-6,STONE:0)
Block(2,1,-5,STONE:0)
Block(2,1,-4,STONE:0)
Block(2,1,-3,STONE:0)
Block(2,1,-2,STONE:0)
Block(2,1,-1,STONE:0)
Block(2,1,0,STONE:0)
Block(2,1,1,STONE:0)
Block(2,1,2,STONE:0)
Block(2,1,3,STONE:0)
Block(2,1,4,STONE:0)
Block(2,1,5,STONE:0)
Block(2,1,6,STONE:0)
Block(2,1,7,STONE:0)
Block(2,1,8,STONE:0)
Block(2,2,-7,STONE:0)
Block(2,2,-6,STONE:0)
Block(2,2,-5,STONE:0)
Block(2,2,-4,STONE:0)
Block(2,2,-3,STONE:0)
Block(2,2,-2,STONE:0)
Block(2,2,-1,STONE:0)
Block(2,2,0,STONE:0)
Block(2,2,1,STONE:0)
Block(2,2,2,STONE:0)
Block(2,2,3,STONE:0)
Block(2,2,4,STONE:0)
Block(2,2,5,STONE:0)
Block(2,2,6,STONE:0)
Block(2,2,7,STONE:0)
Block(2,2,8,STONE:0)
Block(2,3,-7,STONE:0)
Block(2,3,-6,STONE:0)
Block(2,3,-5,STONE:0)
Block(2,3,-4,STONE:0)
Block(2,3,-3,STONE:0)
Block(2,3,-2,STONE:0)
Block(2,3,-1,STONE:0)
Block(2,3,0,STONE:0)
Block(2,3,1,STONE:0)
Block(2,3,2,STONE:0)
Block(2,3,3,STONE:0)
Block(2,3,4,STONE:0)
Block(2,3,5,STONE:0)
Block(2,3,6,STONE:0)
Block(2,3,7,STONE:0)
Block(2,3,8,STONE:0)
Block(2,4,-7,STONE:0)
Block(2,4,-6,STONE:0)
Block(2,4,-5,STONE:0)
Block(2,4,-4,STONE:0)
Block(2,4,-3,STONE:0)
Block(2,4,-2,STONE:0)
Block(2,4,-1,STONE:0)
Block(2,4,0,STONE:0)
Block(2,4,1,STONE:0)
Block(2,4,2,STONE:0)
Block(2,4,3,STONE:0)
Block(2,4,4,STONE:0)
Block(2,4,5,STONE:0)
Block(2,4,6,STONE:0)
Block(2,4,7,STONE:0)
Block(2,4,8,STONE:0)
Block(2,5,-7,STONE:0)
Block(2,5,-6,STONE:0)
Block(2,5,-5,STONE:0)
Block(2,5,-4,STONE:0)
Block(2,5,-3,STONE:0)
Block(2,5,-2,STONE:0)
Block(2,5,-1,STONE:0)
Block(2,5,0,STONE:0)
Block(2,5,1,STONE:0)
Block(2,5,2,STONE:0)
Block(2,5,3,STONE:0)
Block(2,5,4,STONE:0)
Block(2,5,5,STONE:0)
Block(2,5,6,STONE:0)
Block(2,5,7,STONE:0)
Block(2,5,8,STONE:0)
Block(2,6,-7,STONE:0)
Block(2,6,-6,STONE:0)
Block(2,6,-5,STONE:0)
Block(2,6,-4,STONE:0)
Block(2,6,-3,STONE:0)
Block(2,6,-2,STONE:0)
Block(2,6,-1,STONE:0)
Block(2,6,0,STONE:0)
Block(2,6,1,STONE:0)
Block(2,6,2,STONE:0)
Block(2,6,3,STONE:0)
Block(2,6,4,STONE:0)
Block(2,6,5,STONE:0)
Block(2,6,6,STONE:0)
Block(2,6,7,STONE:0)
Block(2,6,8,STONE:0)
Block(2,7,-7,STONE:0)
Block(2,7,-6,STONE:0)
Block(2,7,-5,STONE:0)
Block(2,7,-4,STONE:0)
Block(2,7,-3,STONE:0)
Block(2,7,-2,STONE:0)
Block(2,7,-1,STONE:0)
Block(2,7,0,STONE:0)
Block(2,7,1,STONE:0)
Block(2,7,2,STONE:0)
Block(2,7,3,STONE:0)
Block(2,7,4,STONE:0)
Block(2,7,5,STONE:0)
Block(2,7,6,STONE:0)
Block(2,7,7,STONE:0)
Block(2,7,8,STONE:0)
Block(2,8,-6,STONE:0)
Block(2,8,-5,STONE:0)
Block(2,8,-4,STONE:0)
Block(2,8,-3,STONE:0)
Block(2,8,-2,STONE:0)
Block(2,8,1,STONE:0)
Block(2,8,2,STONE:0)
Block(2,8,3,STONE:0)
Block(2,8,4,STONE:0)
Block(2,8,5,STONE:0)
Block(2,8,6,STONE:0)
Block(3,0,-7,STONE:0)
Block(3,0,-6,STONE:0)
Block(3,0,-5,STONE:0)
Block(3,0,-4,STONE:0)
Block(3,0,-3,STONE:0)
Block(3,0,-2,STONE:0)
Block(3,0,-1,STONE:0)
Block(3,0,0,STONE:0)
Block(3,0,1,STONE:0)
Block(3,0,2,STONE:0)
Block(3,0,3,STONE:0)
Block(3,0,4,STONE:0)
Block(3,0,5,STONE:0)
Block(3,0,6,STONE:0)
Block(3,0,7,STONE:0)
Block(3,0,8,STONE:0)
Block(3,1,-7,STONE:0)
Block(3,1,-6,STONE:0)
Block(3,1,-5,STONE:0)
Block(3,1,-4,STONE:0)
Block(3,1,-3,STONE:0)
Block(3,1,-2,STONE:0)
Block(3,1,-1,STONE:0)
Block(3,1,0,STONE:0)
Block(3,1,1,STONE:0)
Block(3,1,2,STONE:0)
Block(3,1,3,STONE:0)
Block(3,1,4,STONE:0)
Block(3,1,5,STONE:0)
Block(3,1,6,STONE:0)
Block(3,1,7,STONE:0)
Block(3,1,8,STONE:0)
Block(3,2,-7,STONE:0)
Block(3,2,-6,STONE:0)
Block(3,2,-5,STONE:0)
Block(3,2,-4,STONE:0)
Block(3,2,-3,STONE:0)
Block(3,2,-2,STONE:0)
Block(3,2,-1,STONE:0)
Block(3,2,0,STONE:0)
Block(3,2,1,STONE:0)
Block(3,2,2,STONE:0)
Block(3,2,3,STONE:0)
Block(3,2,4,STONE:0)
Block(3,2,5,STONE:0)
Block(3,2,6,STONE:0)
Block(3,2,7,STONE:0)
Block(3,2,8,STONE:0)
Block(3,3,-7,STONE:0)
Block(3,3,-6,STONE:0)
Block(3,3,-5,STONE:0)
Block(3,3,-4,STONE:0)
Block(3,3,-3,STONE:0)
Block(3,3,-2,STONE:0)
Block(3,3,-1,STONE:0)
Block(3,3,0,STONE:0)
Block(3,3,1,STONE:0)
Block(3,3,2,STONE:0)
Block(3,3,3,STONE:0)
Block(3,3,4,STONE:0)
Block(3,3,5,STONE:0)
Block(3,3,6,STONE:0)
Block(3,3,7,STONE:0)
Block(3,3,8,STONE:0)
Block(3,4,-7,STONE:0)
Block(3,4,-6,STONE:0)
Block(3,4,-5,STONE:0)
Block(3,4,-4,STONE:0)
Block(3,4,-3,STONE:0)
Block(3,4,-2,STONE:0)
Block(3,4,-1,STONE:0)
Block(3,4,0,STONE:0)
Block(3,4,1,STONE:0)
Block(3,4,2,STONE:0)
Block(3,4,3,STONE:0)
Block(3,4,4,STONE:0)
Block(3,4,5,STONE:0)
Block(3,4,6,STONE:0)
Block(3,4,7,STONE:0)
Block(3,4,8,STONE:0)
Block(3,5,-7,STONE:0)
Block(3,5,-6,STONE:0)
Block(3,5,-5,STONE:0)
Block(3,5,-4,STONE:0)
Block(3,5,-3,STONE:0)
Block(3,5,-2,STONE:0)
Block(3,5,-1,STONE:0)
Block(3,5,0,STONE:0)
Block(3,5,1,STONE:0)
Block(3,5,2,STONE:0)
Block(3,5,3,STONE:0)
Block(3,5,4,STONE:0)
Block(3,5,5,STONE:0)
Block(3,5,6,STONE:0)
Block(3,5,7,STONE:0)
Block(3,5,8,STONE:0)
Block(3,6,-7,STONE:0)
Block(3,6,-6,STONE:0)
Block(3,6,-5,STONE:0)
Block(3,6,-4,STONE:0)
Block(3,6,-3,STONE:0)
Block(3,6,-2,STONE:0)
Block(3,6,-1,STONE:0)
Block(3,6,0,STONE:0)
Block(3,6,1,STONE:0)
Block(3,6,2,STONE:0)
Block(3,6,3,STONE:0)
Block(3,6,4,STONE:0)
Block(3,6,5,STONE:0)
Block(3,6,6,STONE:0)
Block(3,6,7,STONE:0)
Block(3,6,8,STONE:0)
Block(3,7,-7,STONE:0)
Block(3,7,-6,STONE:0)
Block(3,7,-5,STONE:0)
Block(3,7,-4,STONE:0)
Block(3,7,-3,STONE:0)
Block(3,7,-2,STONE:0)
Block(3,7,-1,STONE:0)
Block(3,7,0,STONE:0)
Block(3,7,1,STONE:0)
Block(3,7,2,STONE:0)
Block(3,7,3,STONE:0)
Block(3,7,4,STONE:0)
Block(3,7,5,STONE:0)
Block(3,7,6,STONE:0)
Block(3,7,7,STONE:0)
Block(3,7,8,STONE:0)
Block(3,8,-6,STONE:0)
Block(3,8,-5,STONE:0)
Block(3,8,-4,STONE:0)
Block(3,8,-3,STONE:0)
Block(3,8,-2,STONE:0)
Block(3,8,-1,STONE:0)
Block(3,8,0,STONE:0)
Block(3,8,1,STONE:0)
Block(3,8,2,STONE:0)
Block(3,8,3,STONE:0)
Block(3,8,4,STONE:0)
Block(3,8,5,STONE:0)
Block(3,8,6,STONE:0)
Block(3,8,7,STONE:0)
Block(3,9,-3,STONE:0)
Block(3,9,-2,STONE:0)
Block(3,9,2,STONE:0)
Block(3,9,3,STONE:0)
Block(3,9,4,STONE:0)
Block(4,0,-7,STONE:0)
Block(4,0,-6,STONE:0)
Block(4,0,-5,STONE:0)
Block(4,0,-4,STONE:0)
Block(4,0,-3,STONE:0)
Block(4,0,-2,STONE:0)
Block(4,0,-1,STONE:0)
Block(4,0,0,STONE:0)
Block(4,0,1,STONE:0)
Block(4,0,2,STONE:0)
Block(4,0,3,STONE:0)
Block(4,0,4,STONE:0)
Block(4,0,5,STONE:0)
Block(4,0,6,STONE:0)
Block(4,0,7,STONE:0)
Block(4,0,8,STONE:0)
Block(4,1,-7,STONE:0)
Block(4,1,-6,STONE:0)
Block(4,1,-5,STONE:0)
Block(4,1,-4,STONE:0)
Block(4,1,-3,STONE:0)
Block(4,1,-2,STONE:0)
Block(4,1,-1,STONE:0)
Block(4,1,0,STONE:0)
Block(4,1,1,STONE:0)
Block(4,1,2,STONE:0)
Block(4,1,3,STONE:0)
Block(4,1,4,STONE:0)
Block(4,1,5,STONE:0)
Block(4,1,6,STONE:0)
Block(4,1,7,STONE:0)
Block(4,1,8,STONE:0)
Block(4,2,-7,STONE:0)
Block(4,2,-6,STONE:0)
Block(4,2,-5,STONE:0)
Block(4,2,-4,STONE:0)
Block(4,2,-3,STONE:0)
Block(4,2,-2,STONE:0)
Block(4,2,-1,STONE:0)
Block(4,2,0,STONE:0)
Block(4,2,1,STONE:0)
Block(4,2,2,STONE:0)
Block(4,2,3,STONE:0)
Block(4,2,4,STONE:0)
Block(4,2,5,STONE:0)
Block(4,2,6,STONE:0)
Block(4,2,7,STONE:0)
Block(4,2,8,STONE:0)
Block(4,3,-7,STONE:0)
Block(4,3,-6,STONE:0)
Block(4,3,-5,STONE:0)
Block(4,3,-4,STONE:0)
Block(4,3,-3,STONE:0)
Block(4,3,-2,STONE:0)
Block(4,3,-1,STONE:0)
Block(4,3,0,STONE:0)
Block(4,3,1,STONE:0)
Block(4,3,2,STONE:0)
Block(4,3,3,STONE:0)
Block(4,3,4,STONE:0)
Block(4,3,5,STONE:0)
Block(4,3,6,STONE:0)
Block(4,3,7,STONE:0)
Block(4,3,8,STONE:0)
Block(4,4,-7,STONE:0)
Block(4,4,-6,STONE:0)
Block(4,4,-5,STONE:0)
Block(4,4,-4,STONE:0)
Block(4,4,-3,STONE:0)
Block(4,4,-2,STONE:0)
Block(4,4,-1,STONE:0)
Block(4,4,0,STONE:0)
Block(4,4,1,STONE:0)
Block(4,4,2,STONE:0)
Block(4,4,3,STONE:0)
Block(4,4,4,STONE:0)
Block(4,4,5,STONE:0)
Block(4,4,6,STONE:0)
Block(4,4,7,STONE:0)
Block(4,4,8,STONE:0)
Block(4,5,-7,STONE:0)
Block(4,5,-6,STONE:0)
Block(4,5,-5,STONE:0)
Block(4,5,-4,STONE:0)
Block(4,5,-3,STONE:0)
Block(4,5,-2,STONE:0)
Block(4,5,-1,STONE:0)
Block(4,5,0,STONE:0)
Block(4,5,1,STONE:0)
Block(4,5,2,STONE:0)
Block(4,5,3,STONE:0)
Block(4,5,4,STONE:0)
Block(4,5,5,STONE:0)
Block(4,5,6,STONE:0)
Block(4,5,7,STONE:0)
Block(4,5,8,STONE:0)
Block(4,6,-7,STONE:0)
Block(4,6,-6,STONE:0)
Block(4,6,-5,STONE:0)
Block(4,6,-4,STONE:0)
Block(4,6,-3,STONE:0)
Block(4,6,-2,STONE:0)
Block(4,6,-1,STONE:0)
Block(4,6,0,STONE:0)
Block(4,6,1,STONE:0)
Block(4,6,2,STONE:0)
Block(4,6,3,STONE:0)
Block(4,6,4,STONE:0)
Block(4,6,5,STONE:0)
Block(4,6,6,STONE:0)
Block(4,6,7,STONE:0)
Block(4,6,8,STONE:0)
Block(4,7,-7,notreepunching:loose_rock/stone)
Block(4,7,-6,STONE:0)
Block(4,7,-5,STONE:0)
Block(4,7,-4,STONE:0)
Block(4,7,-3,STONE:0)
Block(4,7,-2,STONE:0)
Block(4,7,-1,STONE:0)
Block(4,7,0,STONE:0)
Block(4,7,1,STONE:0)
Block(4,7,2,STONE:0)
Block(4,7,3,STONE:0)
Block(4,7,4,STONE:0)
Block(4,7,5,STONE:0)
Block(4,7,6,STONE:0)
Block(4,7,7,STONE:0)
Block(4,7,8,STONE:0)
Block(4,8,-5,STONE:0)
Block(4,8,-4,STONE:0)
Block(4,8,-3,STONE:0)
Block(4,8,-2,STONE:0)
Block(4,8,-1,STONE:0)
Block(4,8,0,STONE:0)
Block(4,8,1,STONE:0)
Block(4,8,2,STONE:0)
Block(4,8,3,STONE:0)
Block(4,8,4,STONE:0)
Block(4,8,5,STONE:0)
Block(4,8,6,STONE:0)
Block(4,8,7,STONE:0)
Block(4,9,-4,STONE:0)
Block(4,9,-3,STONE:0)
Block(4,9,-2,STONE:0)
Block(4,9,-1,STONE:0)
Block(4,9,0,STONE:0)
Block(4,9,1,STONE:0)
Block(4,9,2,STONE:0)
Block(4,9,3,STONE:0)
Block(4,9,4,STONE:0)
Block(4,9,5,STONE:0)
Block(4,10,-2,STONE:0)
Block(4,10,-1,biomesoplenty:grass:1)
Block(4,10,1,biomesoplenty:grass:1)
Block(4,10,2,STONE:0)
Block(4,10,3,biomesoplenty:grass:1)
Block(4,11,-2,AIR:0)
Block(4,11,-1,AIR:0)
Block(4,11,1,AIR:0)
Block(4,11,2,AIR:0)
Block(4,11,3,AIR:0)
Block(4,12,-2,AIR:0)
Block(4,12,-1,AIR:0)
Block(4,12,1,AIR:0)
Block(4,12,2,AIR:0)
Block(4,12,3,AIR:0)
Block(4,13,-2,AIR:0)
Block(4,13,-1,AIR:0)
Block(4,13,1,AIR:0)
Block(4,13,2,AIR:0)
Block(4,13,3,AIR:0)
Block(4,14,-2,AIR:0)
Block(4,14,-1,AIR:0)
Block(4,14,1,AIR:0)
Block(4,14,2,AIR:0)
Block(4,14,3,AIR:0)
Block(4,15,-2,AIR:0)
Block(4,15,-1,AIR:0)
Block(4,15,1,AIR:0)
Block(4,15,2,AIR:0)
Block(4,15,3,AIR:0)
Block(4,16,-2,AIR:0)
Block(4,16,-1,AIR:0)
Block(4,16,1,AIR:0)
Block(4,16,2,AIR:0)
Block(4,16,3,AIR:0)
Block(4,17,-2,AIR:0)
Block(4,17,-1,AIR:0)
Block(4,17,1,AIR:0)
Block(4,17,2,AIR:0)
Block(4,17,3,AIR:0)
Block(4,18,-2,AIR:0)
Block(4,18,-1,AIR:0)
Block(4,18,1,AIR:0)
Block(4,18,2,AIR:0)
Block(4,18,3,AIR:0)
Block(4,19,-2,AIR:0)
Block(4,19,-1,AIR:0)
Block(4,19,1,AIR:0)
Block(4,19,2,AIR:0)
Block(4,19,3,AIR:0)
Block(4,20,-2,AIR:0)
Block(4,20,-1,AIR:0)
Block(4,20,1,AIR:0)
Block(4,20,2,AIR:0)
Block(4,20,3,AIR:0)
Block(4,21,-2,AIR:0)
Block(4,21,-1,AIR:0)
Block(4,21,1,AIR:0)
Block(4,21,2,AIR:0)
Block(4,21,3,AIR:0)
Block(4,22,-2,AIR:0)
Block(4,22,-1,AIR:0)
Block(4,22,1,AIR:0)
Block(4,22,2,AIR:0)
Block(4,22,3,AIR:0)
Block(4,23,-2,AIR:0)
Block(4,23,-1,AIR:0)
Block(4,23,1,AIR:0)
Block(4,23,2,AIR:0)
Block(4,23,3,AIR:0)
Block(4,24,-2,AIR:0)
Block(4,24,-1,AIR:0)
Block(4,24,1,AIR:0)
Block(4,24,2,AIR:0)
Block(4,24,3,AIR:0)
Block(4,25,-2,AIR:0)
Block(4,25,-1,AIR:0)
Block(4,25,1,AIR:0)
Block(4,25,2,AIR:0)
Block(4,25,3,AIR:0)
Block(4,26,-2,AIR:0)
Block(4,26,-1,AIR:0)
Block(4,26,1,AIR:0)
Block(4,26,2,AIR:0)
Block(4,26,3,AIR:0)
Block(4,27,-2,AIR:0)
Block(4,27,-1,AIR:0)
Block(4,27,1,AIR:0)
Block(4,27,2,AIR:0)
Block(4,27,3,AIR:0)
Block(4,28,-2,AIR:0)
Block(4,28,-1,AIR:0)
Block(4,28,1,AIR:0)
Block(4,28,2,AIR:0)
Block(4,28,3,AIR:0)
Block(4,29,-2,AIR:0)
Block(4,29,-1,AIR:0)
Block(4,29,1,AIR:0)
Block(4,29,2,AIR:0)
Block(4,29,3,AIR:0)
Block(4,30,-2,AIR:0)
Block(4,30,-1,AIR:0)
Block(4,30,1,AIR:0)
Block(4,30,2,AIR:0)
Block(4,30,3,AIR:0)
Block(4,31,-2,AIR:0)
Block(4,31,-1,AIR:0)
Block(4,31,1,AIR:0)
Block(4,31,2,AIR:0)
Block(4,31,3,AIR:0)
Block(4,32,-2,AIR:0)
Block(4,32,-1,AIR:0)
Block(4,32,1,AIR:0)
Block(4,32,2,AIR:0)
Block(4,32,3,AIR:0)
Block(5,0,-7,STONE:0)
Block(5,0,-6,STONE:0)
Block(5,0,-5,STONE:0)
Block(5,0,-4,STONE:0)
Block(5,0,-3,STONE:0)
Block(5,0,-2,STONE:0)
Block(5,0,-1,STONE:0)
Block(5,0,0,STONE:0)
Block(5,0,1,STONE:0)
Block(5,0,2,STONE:0)
Block(5,0,3,STONE:0)
Block(5,0,4,STONE:0)
Block(5,0,5,STONE:0)
Block(5,0,6,STONE:0)
Block(5,0,7,STONE:0)
Block(5,0,8,STONE:0)
Block(5,1,-7,STONE:0)
Block(5,1,-6,STONE:0)
Block(5,1,-5,STONE:0)
Block(5,1,-4,STONE:0)
Block(5,1,-3,STONE:0)
Block(5,1,-2,STONE:0)
Block(5,1,-1,STONE:0)
Block(5,1,0,STONE:0)
Block(5,1,1,STONE:0)
Block(5,1,2,STONE:0)
Block(5,1,3,STONE:0)
Block(5,1,4,STONE:0)
Block(5,1,5,STONE:0)
Block(5,1,6,STONE:0)
Block(5,1,7,STONE:0)
Block(5,1,8,STONE:0)
Block(5,2,-7,STONE:0)
Block(5,2,-6,STONE:0)
Block(5,2,-5,STONE:0)
Block(5,2,-4,STONE:0)
Block(5,2,-3,STONE:0)
Block(5,2,-2,STONE:0)
Block(5,2,-1,STONE:0)
Block(5,2,0,STONE:0)
Block(5,2,1,STONE:0)
Block(5,2,2,STONE:0)
Block(5,2,3,STONE:0)
Block(5,2,4,STONE:0)
Block(5,2,5,STONE:0)
Block(5,2,6,STONE:0)
Block(5,2,7,STONE:0)
Block(5,2,8,STONE:0)
Block(5,3,-7,STONE:0)
Block(5,3,-6,STONE:0)
Block(5,3,-5,STONE:0)
Block(5,3,-4,STONE:0)
Block(5,3,-3,STONE:0)
Block(5,3,-2,STONE:0)
Block(5,3,-1,STONE:0)
Block(5,3,0,STONE:0)
Block(5,3,1,STONE:0)
Block(5,3,2,STONE:0)
Block(5,3,3,STONE:0)
Block(5,3,4,STONE:0)
Block(5,3,5,STONE:0)
Block(5,3,6,STONE:0)
Block(5,3,7,STONE:0)
Block(5,3,8,STONE:0)
Block(5,4,-7,STONE:0)
Block(5,4,-6,STONE:0)
Block(5,4,-5,STONE:0)
Block(5,4,-4,STONE:0)
Block(5,4,-3,STONE:0)
Block(5,4,-2,STONE:0)
Block(5,4,-1,STONE:0)
Block(5,4,0,STONE:0)
Block(5,4,1,STONE:0)
Block(5,4,2,STONE:0)
Block(5,4,3,STONE:0)
Block(5,4,4,STONE:0)
Block(5,4,5,STONE:0)
Block(5,4,6,STONE:0)
Block(5,4,7,STONE:0)
Block(5,4,8,STONE:0)
Block(5,5,-7,STONE:0)
Block(5,5,-6,STONE:0)
Block(5,5,-5,STONE:0)
Block(5,5,-4,STONE:0)
Block(5,5,-3,STONE:0)
Block(5,5,-2,STONE:0)
Block(5,5,-1,STONE:0)
Block(5,5,0,STONE:0)
Block(5,5,1,STONE:0)
Block(5,5,2,STONE:0)
Block(5,5,3,STONE:0)
Block(5,5,4,STONE:0)
Block(5,5,5,STONE:0)
Block(5,5,6,STONE:0)
Block(5,5,7,STONE:0)
Block(5,5,8,STONE:0)
Block(5,6,-7,STONE:0)
Block(5,6,-6,STONE:0)
Block(5,6,-5,STONE:0)
Block(5,6,-4,STONE:0)
Block(5,6,-3,STONE:0)
Block(5,6,-2,STONE:0)
Block(5,6,-1,STONE:0)
Block(5,6,0,STONE:0)
Block(5,6,1,STONE:0)
Block(5,6,2,STONE:0)
Block(5,6,3,STONE:0)
Block(5,6,4,STONE:0)
Block(5,6,5,STONE:0)
Block(5,6,6,STONE:0)
Block(5,6,7,STONE:0)
Block(5,6,8,STONE:0)
Block(5,7,-7,STONE:0)
Block(5,7,-6,STONE:0)
Block(5,7,-5,STONE:0)
Block(5,7,-4,STONE:0)
Block(5,7,-3,STONE:0)
Block(5,7,-2,STONE:0)
Block(5,7,-1,STONE:0)
Block(5,7,0,STONE:0)
Block(5,7,1,STONE:0)
Block(5,7,2,STONE:0)
Block(5,7,3,STONE:0)
Block(5,7,4,STONE:0)
Block(5,7,5,STONE:0)
Block(5,7,6,STONE:0)
Block(5,7,7,STONE:0)
Block(5,7,8,STONE:0)
Block(5,8,-7,notreepunching:loose_rock/stone)
Block(5,8,-6,STONE:0)
Block(5,8,-5,AIR:0)
Block(5,8,-4,STONE:0)
Block(5,8,-3,STONE:0)
Block(5,8,-2,STONE:0)
Block(5,8,-1,STONE:0)
Block(5,8,0,STONE:0)
Block(5,8,1,STONE:0)
Block(5,8,2,STONE:0)
Block(5,8,3,STONE:0)
Block(5,8,4,STONE:0)
Block(5,8,5,STONE:0)
Block(5,8,6,STONE:0)
Block(5,8,7,STONE:0)
Block(5,9,-6,STONE:0)
Block(5,9,-3,STONE:0)
Block(5,9,-2,STONE:0)
Block(5,9,-1,STONE:0)
Block(5,9,0,STONE:0)
Block(5,9,1,STONE:0)
Block(5,9,2,STONE:0)
Block(5,9,3,STONE:0)
Block(5,9,4,STONE:0)
Block(5,9,5,STONE:0)
Block(5,9,6,STONE:0)
Block(5,10,-3,biomesoplenty:grass:1)
Block(5,10,-2,STONE:0)
Block(5,10,-1,STONE:0)
Block(5,10,0,STONE:0)
Block(5,10,1,STONE:0)
Block(5,10,2,STONE:0)
Block(5,10,3,STONE:0)
Block(5,10,4,STONE:0)
Block(5,10,5,biomesoplenty:grass:1)
Block(5,11,-3,AIR:0)
Block(5,11,-2,AIR:0)
Block(5,11,-1,STONE:0)
Block(5,11,0,STONE:0)
Block(5,11,1,AIR:0)
Block(5,11,2,biomesoplenty:grass:1)
Block(5,11,3,STONE:0)
Block(5,11,4,STONE:0)
Block(5,11,5,AIR:0)
Block(5,12,-3,AIR:0)
Block(5,12,-2,AIR:0)
Block(5,12,-1,AIR:0)
Block(5,12,0,biomesoplenty:grass:1)
Block(5,12,1,AIR:0)
Block(5,12,2,AIR:0)
Block(5,12,3,AIR:0)
Block(5,12,4,AIR:0)
Block(5,12,5,AIR:0)
Block(5,13,-3,AIR:0)
Block(5,13,-2,AIR:0)
Block(5,13,-1,AIR:0)
Block(5,13,0,AIR:0)
Block(5,13,1,AIR:0)
Block(5,13,2,AIR:0)
Block(5,13,3,AIR:0)
Block(5,13,4,AIR:0)
Block(5,13,5,AIR:0)
Block(5,14,-3,AIR:0)
Block(5,14,-2,AIR:0)
Block(5,14,-1,AIR:0)
Block(5,14,0,AIR:0)
Block(5,14,1,AIR:0)
Block(5,14,2,AIR:0)
Block(5,14,3,AIR:0)
Block(5,14,4,AIR:0)
Block(5,14,5,AIR:0)
Block(5,15,-3,AIR:0)
Block(5,15,-2,AIR:0)
Block(5,15,-1,AIR:0)
Block(5,15,0,AIR:0)
Block(5,15,1,AIR:0)
Block(5,15,2,AIR:0)
Block(5,15,3,AIR:0)
Block(5,15,4,AIR:0)
Block(5,15,5,AIR:0)
Block(5,16,-3,AIR:0)
Block(5,16,-2,AIR:0)
Block(5,16,-1,AIR:0)
Block(5,16,0,AIR:0)
Block(5,16,1,AIR:0)
Block(5,16,2,AIR:0)
Block(5,16,3,AIR:0)
Block(5,16,4,AIR:0)
Block(5,16,5,AIR:0)
Block(5,17,-3,AIR:0)
Block(5,17,-2,AIR:0)
Block(5,17,-1,AIR:0)
Block(5,17,0,AIR:0)
Block(5,17,1,AIR:0)
Block(5,17,2,AIR:0)
Block(5,17,3,AIR:0)
Block(5,17,4,AIR:0)
Block(5,17,5,AIR:0)
Block(5,18,-3,AIR:0)
Block(5,18,-2,AIR:0)
Block(5,18,-1,AIR:0)
Block(5,18,0,AIR:0)
Block(5,18,1,AIR:0)
Block(5,18,2,AIR:0)
Block(5,18,3,AIR:0)
Block(5,18,4,AIR:0)
Block(5,18,5,AIR:0)
Block(5,19,-3,AIR:0)
Block(5,19,-2,AIR:0)
Block(5,19,-1,AIR:0)
Block(5,19,0,AIR:0)
Block(5,19,1,AIR:0)
Block(5,19,2,AIR:0)
Block(5,19,3,AIR:0)
Block(5,19,4,AIR:0)
Block(5,19,5,AIR:0)
Block(5,20,-3,AIR:0)
Block(5,20,-2,AIR:0)
Block(5,20,-1,AIR:0)
Block(5,20,0,AIR:0)
Block(5,20,1,AIR:0)
Block(5,20,2,AIR:0)
Block(5,20,3,AIR:0)
Block(5,20,4,AIR:0)
Block(5,20,5,AIR:0)
Block(5,21,-3,AIR:0)
Block(5,21,-2,AIR:0)
Block(5,21,-1,AIR:0)
Block(5,21,0,AIR:0)
Block(5,21,1,AIR:0)
Block(5,21,2,AIR:0)
Block(5,21,3,AIR:0)
Block(5,21,4,AIR:0)
Block(5,21,5,AIR:0)
Block(5,22,-3,AIR:0)
Block(5,22,-2,AIR:0)
Block(5,22,-1,AIR:0)
Block(5,22,0,AIR:0)
Block(5,22,1,AIR:0)
Block(5,22,2,AIR:0)
Block(5,22,3,AIR:0)
Block(5,22,4,AIR:0)
Block(5,22,5,AIR:0)
Block(5,23,-3,AIR:0)
Block(5,23,-2,AIR:0)
Block(5,23,-1,AIR:0)
Block(5,23,0,AIR:0)
Block(5,23,1,AIR:0)
Block(5,23,2,AIR:0)
Block(5,23,3,AIR:0)
Block(5,23,4,AIR:0)
Block(5,23,5,AIR:0)
Block(5,24,-3,AIR:0)
Block(5,24,-2,AIR:0)
Block(5,24,-1,AIR:0)
Block(5,24,0,AIR:0)
Block(5,24,1,AIR:0)
Block(5,24,2,AIR:0)
Block(5,24,3,AIR:0)
Block(5,24,4,AIR:0)
Block(5,24,5,AIR:0)
Block(5,25,-3,AIR:0)
Block(5,25,-2,AIR:0)
Block(5,25,-1,AIR:0)
Block(5,25,0,AIR:0)
Block(5,25,1,AIR:0)
Block(5,25,2,AIR:0)
Block(5,25,3,AIR:0)
Block(5,25,4,AIR:0)
Block(5,25,5,AIR:0)
Block(5,26,-3,AIR:0)
Block(5,26,-2,AIR:0)
Block(5,26,-1,AIR:0)
Block(5,26,0,AIR:0)
Block(5,26,1,AIR:0)
Block(5,26,2,AIR:0)
Block(5,26,3,AIR:0)
Block(5,26,4,AIR:0)
Block(5,26,5,AIR:0)
Block(5,27,-3,AIR:0)
Block(5,27,-2,AIR:0)
Block(5,27,-1,AIR:0)
Block(5,27,0,AIR:0)
Block(5,27,1,AIR:0)
Block(5,27,2,AIR:0)
Block(5,27,3,AIR:0)
Block(5,27,4,AIR:0)
Block(5,27,5,AIR:0)
Block(5,28,-3,AIR:0)
Block(5,28,-2,AIR:0)
Block(5,28,-1,AIR:0)
Block(5,28,0,AIR:0)
Block(5,28,1,AIR:0)
Block(5,28,2,AIR:0)
Block(5,28,3,AIR:0)
Block(5,28,4,AIR:0)
Block(5,28,5,AIR:0)
Block(5,29,-3,AIR:0)
Block(5,29,-2,AIR:0)
Block(5,29,-1,AIR:0)
Block(5,29,0,AIR:0)
Block(5,29,1,AIR:0)
Block(5,29,2,AIR:0)
Block(5,29,3,AIR:0)
Block(5,29,4,AIR:0)
Block(5,29,5,AIR:0)
Block(5,30,-3,AIR:0)
Block(5,30,-2,AIR:0)
Block(5,30,-1,AIR:0)
Block(5,30,0,AIR:0)
Block(5,30,1,AIR:0)
Block(5,30,2,AIR:0)
Block(5,30,3,AIR:0)
Block(5,30,4,AIR:0)
Block(5,30,5,AIR:0)
Block(5,31,-3,AIR:0)
Block(5,31,-2,AIR:0)
Block(5,31,-1,AIR:0)
Block(5,31,0,AIR:0)
Block(5,31,1,AIR:0)
Block(5,31,2,AIR:0)
Block(5,31,3,AIR:0)
Block(5,31,4,AIR:0)
Block(5,31,5,AIR:0)
Block(5,32,-3,AIR:0)
Block(5,32,-2,AIR:0)
Block(5,32,-1,AIR:0)
Block(5,32,0,AIR:0)
Block(5,32,1,AIR:0)
Block(5,32,2,AIR:0)
Block(5,32,3,AIR:0)
Block(5,32,4,AIR:0)
Block(5,32,5,AIR:0)
Block(6,0,-7,STONE:0)
Block(6,0,-6,STONE:0)
Block(6,0,-5,STONE:0)
Block(6,0,-4,STONE:0)
Block(6,0,-3,STONE:0)
Block(6,0,-2,STONE:0)
Block(6,0,-1,STONE:0)
Block(6,0,0,STONE:0)
Block(6,0,1,STONE:0)
Block(6,0,2,STONE:0)
Block(6,0,3,STONE:0)
Block(6,0,4,STONE:0)
Block(6,0,5,STONE:0)
Block(6,0,6,STONE:0)
Block(6,0,7,STONE:0)
Block(6,0,8,STONE:0)
Block(6,1,-7,STONE:0)
Block(6,1,-6,STONE:0)
Block(6,1,-5,STONE:0)
Block(6,1,-4,STONE:0)
Block(6,1,-3,STONE:0)
Block(6,1,-2,STONE:0)
Block(6,1,-1,STONE:0)
Block(6,1,0,STONE:0)
Block(6,1,1,STONE:0)
Block(6,1,2,STONE:0)
Block(6,1,3,STONE:0)
Block(6,1,4,STONE:0)
Block(6,1,5,STONE:0)
Block(6,1,6,STONE:0)
Block(6,1,7,STONE:0)
Block(6,1,8,STONE:0)
Block(6,2,-7,STONE:0)
Block(6,2,-6,STONE:0)
Block(6,2,-5,STONE:0)
Block(6,2,-4,STONE:0)
Block(6,2,-3,STONE:0)
Block(6,2,-2,STONE:0)
Block(6,2,-1,STONE:0)
Block(6,2,0,STONE:0)
Block(6,2,1,STONE:0)
Block(6,2,2,STONE:0)
Block(6,2,3,STONE:0)
Block(6,2,4,STONE:0)
Block(6,2,5,STONE:0)
Block(6,2,6,STONE:0)
Block(6,2,7,STONE:0)
Block(6,2,8,STONE:0)
Block(6,3,-7,STONE:0)
Block(6,3,-6,STONE:0)
Block(6,3,-5,STONE:0)
Block(6,3,-4,STONE:0)
Block(6,3,-3,STONE:0)
Block(6,3,-2,STONE:0)
Block(6,3,-1,STONE:0)
Block(6,3,0,STONE:0)
Block(6,3,1,STONE:0)
Block(6,3,2,STONE:0)
Block(6,3,3,STONE:0)
Block(6,3,4,STONE:0)
Block(6,3,5,STONE:0)
Block(6,3,6,STONE:0)
Block(6,3,7,STONE:0)
Block(6,3,8,STONE:0)
Block(6,4,-7,STONE:0)
Block(6,4,-6,STONE:0)
Block(6,4,-5,STONE:0)
Block(6,4,-4,STONE:0)
Block(6,4,-3,STONE:0)
Block(6,4,-2,STONE:0)
Block(6,4,-1,STONE:0)
Block(6,4,0,STONE:0)
Block(6,4,1,STONE:0)
Block(6,4,2,STONE:0)
Block(6,4,3,STONE:0)
Block(6,4,4,STONE:0)
Block(6,4,5,STONE:0)
Block(6,4,6,STONE:0)
Block(6,4,7,STONE:0)
Block(6,4,8,STONE:0)
Block(6,5,-7,STONE:0)
Block(6,5,-6,STONE:0)
Block(6,5,-5,STONE:0)
Block(6,5,-4,STONE:0)
Block(6,5,-3,STONE:0)
Block(6,5,-2,STONE:0)
Block(6,5,-1,STONE:0)
Block(6,5,0,STONE:0)
Block(6,5,1,STONE:0)
Block(6,5,2,STONE:0)
Block(6,5,3,STONE:0)
Block(6,5,4,STONE:0)
Block(6,5,5,STONE:0)
Block(6,5,6,STONE:0)
Block(6,5,7,STONE:0)
Block(6,5,8,STONE:0)
Block(6,6,-7,iceandfire:chared_stone)
Block(6,6,-6,STONE:0)
Block(6,6,-5,STONE:0)
Block(6,6,-4,STONE:0)
Block(6,6,-3,STONE:0)
Block(6,6,-2,STONE:0)
Block(6,6,-1,STONE:0)
Block(6,6,0,STONE:0)
Block(6,6,1,STONE:0)
Block(6,6,2,STONE:0)
Block(6,6,3,STONE:0)
Block(6,6,4,STONE:0)
Block(6,6,5,STONE:0)
Block(6,6,6,STONE:0)
Block(6,6,7,STONE:0)
Block(6,6,8,STONE:0)
Block(6,7,-7,STONE:0)
Block(6,7,-6,iceandfire:chared_stone)
Block(6,7,-5,iceandfire:chared_stone)
Block(6,7,-4,STONE:0)
Block(6,7,-3,STONE:0)
Block(6,7,-2,STONE:0)
Block(6,7,-1,STONE:0)
Block(6,7,0,STONE:0)
Block(6,7,1,STONE:0)
Block(6,7,2,STONE:0)
Block(6,7,3,STONE:0)
Block(6,7,4,STONE:0)
Block(6,7,5,STONE:0)
Block(6,7,6,STONE:0)
Block(6,7,7,STONE:0)
Block(6,7,8,STONE:0)
Block(6,8,-7,STONE:0)
Block(6,8,-6,iceandfire:chared_cobblestone)
Block(6,8,-5,STONE:0)
Block(6,8,-4,iceandfire:chared_stone)
Block(6,8,-3,STONE:0)
Block(6,8,-2,STONE:0)
Block(6,8,-1,STONE:0)
Block(6,8,0,STONE:0)
Block(6,8,1,STONE:0)
Block(6,8,2,STONE:0)
Block(6,8,3,STONE:0)
Block(6,8,4,STONE:0)
Block(6,8,5,STONE:0)
Block(6,8,6,STONE:0)
Block(6,8,7,STONE:0)
Block(6,8,8,STONE:0)
Block(6,9,-7,quark:stone_stairs:6)
Block(6,9,-6,STONE:0)
Block(6,9,-5,STONE:0)
Block(6,9,-4,STONE:0)
Block(6,9,-3,STONE:0)
Block(6,9,-2,STONE:0)
Block(6,9,-1,STONE:0)
Block(6,9,0,STONE:0)
Block(6,9,1,STONE:0)
Block(6,9,2,STONE:0)
Block(6,9,3,STONE:0)
Block(6,9,4,STONE:0)
Block(6,9,5,STONE:0)
Block(6,9,6,STONE:0)
Block(6,9,7,STONE:0)
Block(6,9,8,STONE:0)
Block(6,10,-7,biomesoplenty:grass:1)
Block(6,10,-3,STONE:0)
Block(6,10,-2,STONE:0)
Block(6,10,-1,STONE:0)
Block(6,10,0,STONE:0)
Block(6,10,1,STONE:0)
Block(6,10,2,STONE:0)
Block(6,10,3,STONE:0)
Block(6,10,4,STONE:0)
Block(6,10,5,STONE:0)
Block(6,10,6,STONE:0)
Block(6,10,7,biomesoplenty:grass:1)
Block(6,11,-7,AIR:0)
Block(6,11,-3,AIR:0)
Block(6,11,-2,biomesoplenty:grass:1)
Block(6,11,-1,STONE:0)
Block(6,11,0,STONE:0)
Block(6,11,1,STONE:0)
Block(6,11,2,STONE:0)
Block(6,11,3,STONE:0)
Block(6,11,4,STONE:0)
Block(6,11,5,STONE:0)
Block(6,11,6,STONE:0)
Block(6,11,7,AIR:0)
Block(6,12,-7,AIR:0)
Block(6,12,-3,AIR:0)
Block(6,12,-2,AIR:0)
Block(6,12,-1,STONE:0)
Block(6,12,0,STONE:0)
Block(6,12,1,AIR:0)
Block(6,12,2,STONE:0)
Block(6,12,3,biomesoplenty:grass:1)
Block(6,12,4,biomesoplenty:grass:1)
Block(6,12,5,AIR:0)
Block(6,12,6,AIR:0)
Block(6,12,7,AIR:0)
Block(6,13,-7,AIR:0)
Block(6,13,-3,AIR:0)
Block(6,13,-2,AIR:0)
Block(6,13,-1,AIR:0)
Block(6,13,0,AIR:0)
Block(6,13,1,AIR:0)
Block(6,13,2,AIR:0)
Block(6,13,3,AIR:0)
Block(6,13,4,biomesoplenty:plant_0:10)
Block(6,13,5,AIR:0)
Block(6,13,6,AIR:0)
Block(6,13,7,AIR:0)
Block(6,14,-7,AIR:0)
Block(6,14,-3,AIR:0)
Block(6,14,-2,AIR:0)
Block(6,14,-1,AIR:0)
Block(6,14,0,AIR:0)
Block(6,14,1,AIR:0)
Block(6,14,2,AIR:0)
Block(6,14,3,AIR:0)
Block(6,14,4,AIR:0)
Block(6,14,5,AIR:0)
Block(6,14,6,AIR:0)
Block(6,14,7,AIR:0)
Block(6,15,-7,AIR:0)
Block(6,15,-3,AIR:0)
Block(6,15,-2,AIR:0)
Block(6,15,-1,AIR:0)
Block(6,15,0,AIR:0)
Block(6,15,1,AIR:0)
Block(6,15,2,AIR:0)
Block(6,15,3,AIR:0)
Block(6,15,4,AIR:0)
Block(6,15,5,AIR:0)
Block(6,15,6,AIR:0)
Block(6,15,7,AIR:0)
Block(6,16,-7,AIR:0)
Block(6,16,-3,AIR:0)
Block(6,16,-2,AIR:0)
Block(6,16,-1,AIR:0)
Block(6,16,0,AIR:0)
Block(6,16,1,AIR:0)
Block(6,16,2,AIR:0)
Block(6,16,3,AIR:0)
Block(6,16,4,AIR:0)
Block(6,16,5,AIR:0)
Block(6,16,6,AIR:0)
Block(6,16,7,AIR:0)
Block(6,17,-7,AIR:0)
Block(6,17,-3,AIR:0)
Block(6,17,-2,AIR:0)
Block(6,17,-1,AIR:0)
Block(6,17,0,AIR:0)
Block(6,17,1,AIR:0)
Block(6,17,2,AIR:0)
Block(6,17,3,AIR:0)
Block(6,17,4,AIR:0)
Block(6,17,5,AIR:0)
Block(6,17,6,AIR:0)
Block(6,17,7,AIR:0)
Block(6,18,-7,AIR:0)
Block(6,18,-3,AIR:0)
Block(6,18,-2,AIR:0)
Block(6,18,-1,AIR:0)
Block(6,18,0,AIR:0)
Block(6,18,1,AIR:0)
Block(6,18,2,AIR:0)
Block(6,18,3,AIR:0)
Block(6,18,4,AIR:0)
Block(6,18,5,AIR:0)
Block(6,18,6,AIR:0)
Block(6,18,7,AIR:0)
Block(6,19,-7,AIR:0)
Block(6,19,-3,AIR:0)
Block(6,19,-2,AIR:0)
Block(6,19,-1,AIR:0)
Block(6,19,0,AIR:0)
Block(6,19,1,AIR:0)
Block(6,19,2,AIR:0)
Block(6,19,3,AIR:0)
Block(6,19,4,AIR:0)
Block(6,19,5,AIR:0)
Block(6,19,6,AIR:0)
Block(6,19,7,AIR:0)
Block(6,20,-7,AIR:0)
Block(6,20,-3,AIR:0)
Block(6,20,-2,AIR:0)
Block(6,20,-1,AIR:0)
Block(6,20,0,AIR:0)
Block(6,20,1,AIR:0)
Block(6,20,2,AIR:0)
Block(6,20,3,AIR:0)
Block(6,20,4,AIR:0)
Block(6,20,5,AIR:0)
Block(6,20,6,AIR:0)
Block(6,20,7,AIR:0)
Block(6,21,-7,AIR:0)
Block(6,21,-3,AIR:0)
Block(6,21,-2,AIR:0)
Block(6,21,-1,AIR:0)
Block(6,21,0,AIR:0)
Block(6,21,1,AIR:0)
Block(6,21,2,AIR:0)
Block(6,21,3,AIR:0)
Block(6,21,4,AIR:0)
Block(6,21,5,AIR:0)
Block(6,21,6,AIR:0)
Block(6,21,7,AIR:0)
Block(6,22,-7,AIR:0)
Block(6,22,-3,AIR:0)
Block(6,22,-2,AIR:0)
Block(6,22,-1,AIR:0)
Block(6,22,0,AIR:0)
Block(6,22,1,AIR:0)
Block(6,22,2,AIR:0)
Block(6,22,3,AIR:0)
Block(6,22,4,AIR:0)
Block(6,22,5,AIR:0)
Block(6,22,6,AIR:0)
Block(6,22,7,AIR:0)
Block(6,23,-7,AIR:0)
Block(6,23,-3,AIR:0)
Block(6,23,-2,AIR:0)
Block(6,23,-1,AIR:0)
Block(6,23,0,AIR:0)
Block(6,23,1,AIR:0)
Block(6,23,2,AIR:0)
Block(6,23,3,AIR:0)
Block(6,23,4,AIR:0)
Block(6,23,5,AIR:0)
Block(6,23,6,AIR:0)
Block(6,23,7,AIR:0)
Block(6,24,-7,AIR:0)
Block(6,24,-3,AIR:0)
Block(6,24,-2,AIR:0)
Block(6,24,-1,AIR:0)
Block(6,24,0,AIR:0)
Block(6,24,1,AIR:0)
Block(6,24,2,AIR:0)
Block(6,24,3,AIR:0)
Block(6,24,4,AIR:0)
Block(6,24,5,AIR:0)
Block(6,24,6,AIR:0)
Block(6,24,7,AIR:0)
Block(6,25,-7,AIR:0)
Block(6,25,-3,AIR:0)
Block(6,25,-2,AIR:0)
Block(6,25,-1,AIR:0)
Block(6,25,0,AIR:0)
Block(6,25,1,AIR:0)
Block(6,25,2,AIR:0)
Block(6,25,3,AIR:0)
Block(6,25,4,AIR:0)
Block(6,25,5,AIR:0)
Block(6,25,6,AIR:0)
Block(6,25,7,AIR:0)
Block(6,26,-7,AIR:0)
Block(6,26,-3,AIR:0)
Block(6,26,-2,AIR:0)
Block(6,26,-1,AIR:0)
Block(6,26,0,AIR:0)
Block(6,26,1,AIR:0)
Block(6,26,2,AIR:0)
Block(6,26,3,AIR:0)
Block(6,26,4,AIR:0)
Block(6,26,5,AIR:0)
Block(6,26,6,AIR:0)
Block(6,26,7,AIR:0)
Block(6,27,-7,AIR:0)
Block(6,27,-3,AIR:0)
Block(6,27,-2,AIR:0)
Block(6,27,-1,AIR:0)
Block(6,27,0,AIR:0)
Block(6,27,1,AIR:0)
Block(6,27,2,AIR:0)
Block(6,27,3,AIR:0)
Block(6,27,4,AIR:0)
Block(6,27,5,AIR:0)
Block(6,27,6,AIR:0)
Block(6,27,7,AIR:0)
Block(6,28,-7,AIR:0)
Block(6,28,-3,AIR:0)
Block(6,28,-2,AIR:0)
Block(6,28,-1,AIR:0)
Block(6,28,0,AIR:0)
Block(6,28,1,AIR:0)
Block(6,28,2,AIR:0)
Block(6,28,3,AIR:0)
Block(6,28,4,AIR:0)
Block(6,28,5,AIR:0)
Block(6,28,6,AIR:0)
Block(6,28,7,AIR:0)
Block(6,29,-7,AIR:0)
Block(6,29,-3,AIR:0)
Block(6,29,-2,AIR:0)
Block(6,29,-1,AIR:0)
Block(6,29,0,AIR:0)
Block(6,29,1,AIR:0)
Block(6,29,2,AIR:0)
Block(6,29,3,AIR:0)
Block(6,29,4,AIR:0)
Block(6,29,5,AIR:0)
Block(6,29,6,AIR:0)
Block(6,29,7,AIR:0)
Block(6,30,-7,AIR:0)
Block(6,30,-3,AIR:0)
Block(6,30,-2,AIR:0)
Block(6,30,-1,AIR:0)
Block(6,30,0,AIR:0)
Block(6,30,1,AIR:0)
Block(6,30,2,AIR:0)
Block(6,30,3,AIR:0)
Block(6,30,4,AIR:0)
Block(6,30,5,AIR:0)
Block(6,30,6,AIR:0)
Block(6,30,7,AIR:0)
Block(6,31,-7,AIR:0)
Block(6,31,-3,AIR:0)
Block(6,31,-2,AIR:0)
Block(6,31,-1,AIR:0)
Block(6,31,0,AIR:0)
Block(6,31,1,AIR:0)
Block(6,31,2,AIR:0)
Block(6,31,3,AIR:0)
Block(6,31,4,AIR:0)
Block(6,31,5,AIR:0)
Block(6,31,6,AIR:0)
Block(6,31,7,AIR:0)
Block(6,32,-7,AIR:0)
Block(6,32,-3,AIR:0)
Block(6,32,-2,AIR:0)
Block(6,32,-1,AIR:0)
Block(6,32,0,AIR:0)
Block(6,32,1,AIR:0)
Block(6,32,2,AIR:0)
Block(6,32,3,AIR:0)
Block(6,32,4,AIR:0)
Block(6,32,5,AIR:0)
Block(6,32,6,AIR:0)
Block(6,32,7,AIR:0)
Block(7,0,-7,STONE:0)
Block(7,0,-6,STONE:0)
Block(7,0,-5,STONE:0)
Block(7,0,-4,STONE:0)
Block(7,0,-3,STONE:0)
Block(7,0,-2,STONE:0)
Block(7,0,-1,STONE:0)
Block(7,0,0,STONE:0)
Block(7,0,1,STONE:0)
Block(7,0,2,STONE:0)
Block(7,0,3,STONE:0)
Block(7,0,4,STONE:0)
Block(7,0,5,STONE:0)
Block(7,0,6,STONE:0)
Block(7,0,7,STONE:0)
Block(7,0,8,STONE:0)
Block(7,1,-7,STONE:0)
Block(7,1,-6,STONE:0)
Block(7,1,-5,STONE:0)
Block(7,1,-4,STONE:0)
Block(7,1,-3,STONE:0)
Block(7,1,-2,STONE:0)
Block(7,1,-1,STONE:0)
Block(7,1,0,STONE:0)
Block(7,1,1,STONE:0)
Block(7,1,2,STONE:0)
Block(7,1,3,STONE:0)
Block(7,1,4,STONE:0)
Block(7,1,5,STONE:0)
Block(7,1,6,STONE:0)
Block(7,1,7,STONE:0)
Block(7,1,8,STONE:0)
Block(7,2,-7,STONE:0)
Block(7,2,-6,STONE:0)
Block(7,2,-5,STONE:0)
Block(7,2,-4,STONE:0)
Block(7,2,-3,STONE:0)
Block(7,2,-2,STONE:0)
Block(7,2,-1,STONE:0)
Block(7,2,0,STONE:0)
Block(7,2,1,STONE:0)
Block(7,2,2,STONE:0)
Block(7,2,3,STONE:0)
Block(7,2,4,STONE:0)
Block(7,2,5,STONE:0)
Block(7,2,6,STONE:0)
Block(7,2,7,STONE:0)
Block(7,2,8,STONE:0)
Block(7,3,-7,STONE:0)
Block(7,3,-6,STONE:0)
Block(7,3,-5,STONE:0)
Block(7,3,-4,STONE:0)
Block(7,3,-3,STONE:0)
Block(7,3,-2,STONE:0)
Block(7,3,-1,STONE:0)
Block(7,3,0,STONE:0)
Block(7,3,1,STONE:0)
Block(7,3,2,STONE:0)
Block(7,3,3,STONE:0)
Block(7,3,4,STONE:0)
Block(7,3,5,STONE:0)
Block(7,3,6,STONE:0)
Block(7,3,7,STONE:0)
Block(7,3,8,STONE:0)
Block(7,4,-7,STONE:0)
Block(7,4,-6,STONE:0)
Block(7,4,-5,STONE:0)
Block(7,4,-4,STONE:0)
Block(7,4,-3,STONE:0)
Block(7,4,-2,STONE:0)
Block(7,4,-1,STONE:0)
Block(7,4,0,STONE:0)
Block(7,4,1,STONE:0)
Block(7,4,2,STONE:0)
Block(7,4,3,STONE:0)
Block(7,4,4,STONE:0)
Block(7,4,5,STONE:0)
Block(7,4,6,STONE:0)
Block(7,4,7,STONE:0)
Block(7,4,8,STONE:0)
Block(7,5,-7,STONE:0)
Block(7,5,-6,STONE:0)
Block(7,5,-5,STONE:0)
Block(7,5,-4,STONE:0)
Block(7,5,-3,STONE:0)
Block(7,5,-2,STONE:0)
Block(7,5,-1,STONE:0)
Block(7,5,0,STONE:0)
Block(7,5,1,STONE:0)
Block(7,5,2,STONE:0)
Block(7,5,3,STONE:0)
Block(7,5,4,STONE:0)
Block(7,5,5,STONE:0)
Block(7,5,6,STONE:0)
Block(7,5,7,STONE:0)
Block(7,5,8,STONE:0)
Block(7,6,-7,quark:stone_stairs:1)
Block(7,6,-6,iceandfire:chared_stone)
Block(7,6,-5,STONE:0)
Block(7,6,-4,STONE:0)
Block(7,6,-3,STONE:0)
Block(7,6,-2,STONE:0)
Block(7,6,-1,STONE:0)
Block(7,6,0,STONE:0)
Block(7,6,1,STONE:0)
Block(7,6,2,STONE:0)
Block(7,6,3,STONE:0)
Block(7,6,4,STONE:0)
Block(7,6,5,STONE:0)
Block(7,6,6,STONE:0)
Block(7,6,7,STONE:0)
Block(7,6,8,STONE:0)
Block(7,7,-7,quark:stone_stairs:5)
Block(7,7,-6,iceandfire:chared_cobblestone)
Block(7,7,-5,iceandfire:chared_cobblestone)
Block(7,7,-4,iceandfire:chared_cobblestone)
Block(7,7,-3,STONE:0)
Block(7,7,-2,STONE:0)
Block(7,7,-1,STONE:0)
Block(7,7,0,STONE:0)
Block(7,7,1,STONE:0)
Block(7,7,2,STONE:0)
Block(7,7,3,STONE:0)
Block(7,7,4,STONE:0)
Block(7,7,5,STONE:0)
Block(7,7,6,STONE:0)
Block(7,7,7,STONE:0)
Block(7,7,8,STONE:0)
Block(7,8,-7,STONE:0)
Block(7,8,-6,iceandfire:chared_cobblestone)
Block(7,8,-5,iceandfire:chared_cobblestone)
Block(7,8,-4,iceandfire:chared_stone)
Block(7,8,-3,STONE:0)
Block(7,8,-2,STONE:0)
Block(7,8,-1,STONE:0)
Block(7,8,0,STONE:0)
Block(7,8,1,STONE:0)
Block(7,8,2,STONE:0)
Block(7,8,3,STONE:0)
Block(7,8,4,STONE:0)
Block(7,8,5,STONE:0)
Block(7,8,6,STONE:0)
Block(7,8,7,STONE:0)
Block(7,8,8,STONE:0)
Block(7,9,-7,STONE:0)
Block(7,9,-6,iceandfire:chared_cobblestone)
Block(7,9,-5,iceandfire:chared_cobblestone)
Block(7,9,-4,iceandfire:chared_stone)
Block(7,9,-3,STONE:0)
Block(7,9,-2,STONE:0)
Block(7,9,-1,STONE:0)
Block(7,9,0,STONE:0)
Block(7,9,1,STONE:0)
Block(7,9,2,STONE:0)
Block(7,9,3,STONE:0)
Block(7,9,4,STONE:0)
Block(7,9,5,STONE:0)
Block(7,9,6,STONE:0)
Block(7,9,7,STONE:0)
Block(7,9,8,STONE:0)
Block(7,10,-7,STONE:0)
Block(7,10,-6,STONE:0)
Block(7,10,-5,STONE:0)
Block(7,10,-4,STONE:0)
Block(7,10,-3,STONE:0)
Block(7,10,-2,STONE:0)
Block(7,10,-1,STONE:0)
Block(7,10,0,STONE:0)
Block(7,10,1,STONE:0)
Block(7,10,2,STONE:0)
Block(7,10,3,STONE:0)
Block(7,10,4,STONE:0)
Block(7,10,5,STONE:0)
Block(7,10,6,STONE:0)
Block(7,10,7,STONE:0)
Block(7,10,8,STONE:0)
Block(7,11,-7,STONE:0)
Block(7,11,-6,STONE:0)
Block(7,11,-5,STONE:0)
Block(7,11,-4,biomesoplenty:grass:1)
Block(7,11,-3,biomesoplenty:grass:1)
Block(7,11,-2,STONE:0)
Block(7,11,-1,STONE:0)
Block(7,11,0,STONE:0)
Block(7,11,1,STONE:0)
Block(7,11,2,STONE:0)
Block(7,11,3,STONE:0)
Block(7,11,4,STONE:0)
Block(7,11,5,STONE:0)
Block(7,11,6,STONE:0)
Block(7,11,7,STONE:0)
Block(7,11,8,biomesoplenty:grass:1)
Block(7,12,-7,AIR:0)
Block(7,12,-6,biomesoplenty:grass:1)
Block(7,12,-5,STONE:0)
Block(7,12,-4,biomesoplenty:plant_0:10)
Block(7,12,-3,AIR:0)
Block(7,12,-2,STONE:0)
Block(7,12,-1,STONE:0)
Block(7,12,0,STONE:0)
Block(7,12,1,STONE:0)
Block(7,12,2,STONE:0)
Block(7,12,3,STONE:0)
Block(7,12,4,STONE:0)
Block(7,12,5,STONE:0)
Block(7,12,6,biomesoplenty:grass:1)
Block(7,12,7,AIR:0)
Block(7,12,8,AIR:0)
Block(7,13,-7,AIR:0)
Block(7,13,-6,AIR:0)
Block(7,13,-5,AIR:0)
Block(7,13,-4,AIR:0)
Block(7,13,-3,AIR:0)
Block(7,13,-2,AIR:0)
Block(7,13,-1,biomesoplenty:grass:1)
Block(7,13,0,STONE:0)
Block(7,13,1,STONE:0)
Block(7,13,2,biomesoplenty:grass:1)
Block(7,13,3,STONE:0)
Block(7,13,4,AIR:0)
Block(7,13,5,AIR:0)
Block(7,13,6,AIR:0)
Block(7,13,7,AIR:0)
Block(7,13,8,AIR:0)
Block(7,14,-7,AIR:0)
Block(7,14,-6,AIR:0)
Block(7,14,-5,AIR:0)
Block(7,14,-4,AIR:0)
Block(7,14,-3,AIR:0)
Block(7,14,-2,AIR:0)
Block(7,14,-1,AIR:0)
Block(7,14,0,AIR:0)
Block(7,14,1,AIR:0)
Block(7,14,2,biomesoplenty:plant_0:10)
Block(7,14,3,AIR:0)
Block(7,14,4,AIR:0)
Block(7,14,5,AIR:0)
Block(7,14,6,AIR:0)
Block(7,14,7,AIR:0)
Block(7,14,8,AIR:0)
Block(7,15,-7,AIR:0)
Block(7,15,-6,AIR:0)
Block(7,15,-5,AIR:0)
Block(7,15,-4,AIR:0)
Block(7,15,-3,AIR:0)
Block(7,15,-2,AIR:0)
Block(7,15,-1,AIR:0)
Block(7,15,0,AIR:0)
Block(7,15,1,AIR:0)
Block(7,15,2,AIR:0)
Block(7,15,3,AIR:0)
Block(7,15,4,AIR:0)
Block(7,15,5,AIR:0)
Block(7,15,6,AIR:0)
Block(7,15,7,AIR:0)
Block(7,15,8,AIR:0)
Block(7,16,-7,AIR:0)
Block(7,16,-6,AIR:0)
Block(7,16,-5,AIR:0)
Block(7,16,-4,AIR:0)
Block(7,16,-3,AIR:0)
Block(7,16,-2,AIR:0)
Block(7,16,-1,AIR:0)
Block(7,16,0,AIR:0)
Block(7,16,1,AIR:0)
Block(7,16,2,AIR:0)
Block(7,16,3,AIR:0)
Block(7,16,4,AIR:0)
Block(7,16,5,AIR:0)
Block(7,16,6,AIR:0)
Block(7,16,7,AIR:0)
Block(7,16,8,AIR:0)
Block(7,17,-7,AIR:0)
Block(7,17,-6,AIR:0)
Block(7,17,-5,AIR:0)
Block(7,17,-4,AIR:0)
Block(7,17,-3,AIR:0)
Block(7,17,-2,AIR:0)
Block(7,17,-1,AIR:0)
Block(7,17,0,AIR:0)
Block(7,17,1,AIR:0)
Block(7,17,2,AIR:0)
Block(7,17,3,AIR:0)
Block(7,17,4,AIR:0)
Block(7,17,5,AIR:0)
Block(7,17,6,AIR:0)
Block(7,17,7,AIR:0)
Block(7,17,8,AIR:0)
Block(7,18,-7,AIR:0)
Block(7,18,-6,AIR:0)
Block(7,18,-5,AIR:0)
Block(7,18,-4,AIR:0)
Block(7,18,-3,AIR:0)
Block(7,18,-2,AIR:0)
Block(7,18,-1,AIR:0)
Block(7,18,0,AIR:0)
Block(7,18,1,AIR:0)
Block(7,18,2,AIR:0)
Block(7,18,3,AIR:0)
Block(7,18,4,AIR:0)
Block(7,18,5,AIR:0)
Block(7,18,6,AIR:0)
Block(7,18,7,AIR:0)
Block(7,18,8,AIR:0)
Block(7,19,-7,AIR:0)
Block(7,19,-6,AIR:0)
Block(7,19,-5,AIR:0)
Block(7,19,-4,AIR:0)
Block(7,19,-3,AIR:0)
Block(7,19,-2,AIR:0)
Block(7,19,-1,AIR:0)
Block(7,19,0,AIR:0)
Block(7,19,1,AIR:0)
Block(7,19,2,AIR:0)
Block(7,19,3,AIR:0)
Block(7,19,4,AIR:0)
Block(7,19,5,AIR:0)
Block(7,19,6,AIR:0)
Block(7,19,7,AIR:0)
Block(7,19,8,AIR:0)
Block(7,20,-7,AIR:0)
Block(7,20,-6,AIR:0)
Block(7,20,-5,AIR:0)
Block(7,20,-4,AIR:0)
Block(7,20,-3,AIR:0)
Block(7,20,-2,AIR:0)
Block(7,20,-1,AIR:0)
Block(7,20,0,AIR:0)
Block(7,20,1,AIR:0)
Block(7,20,2,AIR:0)
Block(7,20,3,AIR:0)
Block(7,20,4,AIR:0)
Block(7,20,5,AIR:0)
Block(7,20,6,AIR:0)
Block(7,20,7,AIR:0)
Block(7,20,8,AIR:0)
Block(7,21,-7,AIR:0)
Block(7,21,-6,AIR:0)
Block(7,21,-5,AIR:0)
Block(7,21,-4,AIR:0)
Block(7,21,-3,AIR:0)
Block(7,21,-2,AIR:0)
Block(7,21,-1,AIR:0)
Block(7,21,0,AIR:0)
Block(7,21,1,AIR:0)
Block(7,21,2,AIR:0)
Block(7,21,3,AIR:0)
Block(7,21,4,AIR:0)
Block(7,21,5,AIR:0)
Block(7,21,6,AIR:0)
Block(7,21,7,AIR:0)
Block(7,21,8,AIR:0)
Block(7,22,-7,AIR:0)
Block(7,22,-6,AIR:0)
Block(7,22,-5,AIR:0)
Block(7,22,-4,AIR:0)
Block(7,22,-3,AIR:0)
Block(7,22,-2,AIR:0)
Block(7,22,-1,AIR:0)
Block(7,22,0,AIR:0)
Block(7,22,1,AIR:0)
Block(7,22,2,AIR:0)
Block(7,22,3,AIR:0)
Block(7,22,4,AIR:0)
Block(7,22,5,AIR:0)
Block(7,22,6,AIR:0)
Block(7,22,7,AIR:0)
Block(7,22,8,AIR:0)
Block(7,23,-7,AIR:0)
Block(7,23,-6,AIR:0)
Block(7,23,-5,AIR:0)
Block(7,23,-4,AIR:0)
Block(7,23,-3,AIR:0)
Block(7,23,-2,AIR:0)
Block(7,23,-1,AIR:0)
Block(7,23,0,AIR:0)
Block(7,23,1,AIR:0)
Block(7,23,2,AIR:0)
Block(7,23,3,AIR:0)
Block(7,23,4,AIR:0)
Block(7,23,5,AIR:0)
Block(7,23,6,AIR:0)
Block(7,23,7,AIR:0)
Block(7,23,8,AIR:0)
Block(7,24,-7,AIR:0)
Block(7,24,-6,AIR:0)
Block(7,24,-5,AIR:0)
Block(7,24,-4,AIR:0)
Block(7,24,-3,AIR:0)
Block(7,24,-2,AIR:0)
Block(7,24,-1,AIR:0)
Block(7,24,0,AIR:0)
Block(7,24,1,AIR:0)
Block(7,24,2,AIR:0)
Block(7,24,3,AIR:0)
Block(7,24,4,AIR:0)
Block(7,24,5,AIR:0)
Block(7,24,6,AIR:0)
Block(7,24,7,AIR:0)
Block(7,24,8,AIR:0)
Block(7,25,-7,AIR:0)
Block(7,25,-6,AIR:0)
Block(7,25,-5,AIR:0)
Block(7,25,-4,AIR:0)
Block(7,25,-3,AIR:0)
Block(7,25,-2,AIR:0)
Block(7,25,-1,AIR:0)
Block(7,25,0,AIR:0)
Block(7,25,1,AIR:0)
Block(7,25,2,AIR:0)
Block(7,25,3,AIR:0)
Block(7,25,4,AIR:0)
Block(7,25,5,AIR:0)
Block(7,25,6,AIR:0)
Block(7,25,7,AIR:0)
Block(7,25,8,AIR:0)
Block(7,26,-7,AIR:0)
Block(7,26,-6,AIR:0)
Block(7,26,-5,AIR:0)
Block(7,26,-4,AIR:0)
Block(7,26,-3,AIR:0)
Block(7,26,-2,AIR:0)
Block(7,26,-1,AIR:0)
Block(7,26,0,AIR:0)
Block(7,26,1,AIR:0)
Block(7,26,2,AIR:0)
Block(7,26,3,AIR:0)
Block(7,26,4,AIR:0)
Block(7,26,5,AIR:0)
Block(7,26,6,AIR:0)
Block(7,26,7,AIR:0)
Block(7,26,8,AIR:0)
Block(7,27,-7,AIR:0)
Block(7,27,-6,AIR:0)
Block(7,27,-5,AIR:0)
Block(7,27,-4,AIR:0)
Block(7,27,-3,AIR:0)
Block(7,27,-2,AIR:0)
Block(7,27,-1,AIR:0)
Block(7,27,0,AIR:0)
Block(7,27,1,AIR:0)
Block(7,27,2,AIR:0)
Block(7,27,3,AIR:0)
Block(7,27,4,AIR:0)
Block(7,27,5,AIR:0)
Block(7,27,6,AIR:0)
Block(7,27,7,AIR:0)
Block(7,27,8,AIR:0)
Block(7,28,-7,AIR:0)
Block(7,28,-6,AIR:0)
Block(7,28,-5,AIR:0)
Block(7,28,-4,AIR:0)
Block(7,28,-3,AIR:0)
Block(7,28,-2,AIR:0)
Block(7,28,-1,AIR:0)
Block(7,28,0,AIR:0)
Block(7,28,1,AIR:0)
Block(7,28,2,AIR:0)
Block(7,28,3,AIR:0)
Block(7,28,4,AIR:0)
Block(7,28,5,AIR:0)
Block(7,28,6,AIR:0)
Block(7,28,7,AIR:0)
Block(7,28,8,AIR:0)
Block(7,29,-7,AIR:0)
Block(7,29,-6,AIR:0)
Block(7,29,-5,AIR:0)
Block(7,29,-4,AIR:0)
Block(7,29,-3,AIR:0)
Block(7,29,-2,AIR:0)
Block(7,29,-1,AIR:0)
Block(7,29,0,AIR:0)
Block(7,29,1,AIR:0)
Block(7,29,2,AIR:0)
Block(7,29,3,AIR:0)
Block(7,29,4,AIR:0)
Block(7,29,5,AIR:0)
Block(7,29,6,AIR:0)
Block(7,29,7,AIR:0)
Block(7,29,8,AIR:0)
Block(7,30,-7,AIR:0)
Block(7,30,-6,AIR:0)
Block(7,30,-5,AIR:0)
Block(7,30,-4,AIR:0)
Block(7,30,-3,AIR:0)
Block(7,30,-2,AIR:0)
Block(7,30,-1,AIR:0)
Block(7,30,0,AIR:0)
Block(7,30,1,AIR:0)
Block(7,30,2,AIR:0)
Block(7,30,3,AIR:0)
Block(7,30,4,AIR:0)
Block(7,30,5,AIR:0)
Block(7,30,6,AIR:0)
Block(7,30,7,AIR:0)
Block(7,30,8,AIR:0)
Block(7,31,-7,AIR:0)
Block(7,31,-6,AIR:0)
Block(7,31,-5,AIR:0)
Block(7,31,-4,AIR:0)
Block(7,31,-3,AIR:0)
Block(7,31,-2,AIR:0)
Block(7,31,-1,AIR:0)
Block(7,31,0,AIR:0)
Block(7,31,1,AIR:0)
Block(7,31,2,AIR:0)
Block(7,31,3,AIR:0)
Block(7,31,4,AIR:0)
Block(7,31,5,AIR:0)
Block(7,31,6,AIR:0)
Block(7,31,7,AIR:0)
Block(7,31,8,AIR:0)
Block(7,32,-7,AIR:0)
Block(7,32,-6,AIR:0)
Block(7,32,-5,AIR:0)
Block(7,32,-4,AIR:0)
Block(7,32,-3,AIR:0)
Block(7,32,-2,AIR:0)
Block(7,32,-1,AIR:0)
Block(7,32,0,AIR:0)
Block(7,32,1,AIR:0)
Block(7,32,2,AIR:0)
Block(7,32,3,AIR:0)
Block(7,32,4,AIR:0)
Block(7,32,5,AIR:0)
Block(7,32,6,AIR:0)
Block(7,32,7,AIR:0)
Block(7,32,8,AIR:0)

#######################################################################
# +-----------------------------------------------------------------+ #
# |                             Branches                            | #
# +-----------------------------------------------------------------+ #
#######################################################################

Branch(0,0,16,true,HerbalistC0R5,NORTH,100.0,0)

#######################################################################
# +-----------------------------------------------------------------+ #
# |                             Entities                            | #
# +-----------------------------------------------------------------+ #
#######################################################################


#######################################################################
# +-----------------------------------------------------------------+ #
# |                            Particles                            | #
# +-----------------------------------------------------------------+ #
#######################################################################


#######################################################################
# +-----------------------------------------------------------------+ #
# |                             Spawners                            | #
# +-----------------------------------------------------------------+ #
#######################################################################


#######################################################################
# +-----------------------------------------------------------------+ #
# |                             ModData                             | #
# +-----------------------------------------------------------------+ #
#######################################################################

