#######################################################################
# +-----------------------------------------------------------------+ #
# |                            BO3 object                           | #
# +-----------------------------------------------------------------+ #
#######################################################################

Author: Bo3 BulkEdit

Description: Converted Schematic - Modified by Bo3BulkEdit

Version: 3

SettingsMode: WriteDisable

#######################################################################
# +-----------------------------------------------------------------+ #
# |                          Main settings                          | #
# +-----------------------------------------------------------------+ #
#######################################################################



Frequency: 0


SpawnHeight: randomY





##############################
# Height Limits for the BO3. #
##############################

MinHeight: 0
MaxHeight: 256

#######################################################################
# +-----------------------------------------------------------------+ #
# |                      Source block settings                      | #
# +-----------------------------------------------------------------+ #
#######################################################################

CanOverride: true
MaxPercentageOutsideSourceBlock: 100
OutsideSourceBlock: placeAnyway

#######################################################################
# +-----------------------------------------------------------------+ #
# |                               OTG+                              | #
# +-----------------------------------------------------------------+ #
#######################################################################

#######################################################################
# +-----------------------------------------------------------------+ #
# |                              Blocks                             | #
# +-----------------------------------------------------------------+ #
#######################################################################

B(0,750,0,AIR)
B(15,750,15,AIR)
B(10,5,15,betternether:quartz_stained_glass:15)
B(11,5,15,betternether:quartz_stained_glass:15)
B(10,6,15,betternether:quartz_stained_glass:15)
B(11,6,15,betternether:quartz_stained_glass:15)
B(10,7,14,betternether:quartz_stained_glass:15)
B(9,7,15,betternether:quartz_stained_glass:15)
RB(10,7,15,srparasites:parasitestain:1,80,quark:crystal:1,30,srparasites:parasiterubbledense:1,100)
B(11,7,15,betternether:quartz_stained_glass:15)
B(10,8,13,betternether:quartz_stained_glass:15)
B(9,8,14,betternether:quartz_stained_glass:15)
B(10,8,14,betternether:quartz_stained_glass:15)
B(7,8,15,betternether:quartz_stained_glass:15)
B(8,8,15,betternether:quartz_stained_glass:15)
B(9,8,15,betternether:quartz_stained_glass:15)
RB(10,8,15,srparasites:parasitestain:1,80,quark:crystal:1,30,srparasites:parasiterubbledense:1,100)
B(11,8,15,betternether:quartz_stained_glass:15)
B(10,9,13,betternether:quartz_stained_glass:15)
B(9,9,14,betternether:quartz_stained_glass:15)
B(10,9,14,betternether:quartz_stained_glass:15)
B(7,9,15,betternether:quartz_stained_glass:15)
B(8,9,15,betternether:quartz_stained_glass:15)
RB(9,9,15,srparasites:parasitestain:1,80,quark:crystal:1,30,srparasites:parasiterubbledense:1,100)
RB(10,9,15,srparasites:parasitestain:1,80,quark:crystal:1,30,srparasites:parasiterubbledense:1,100)
B(11,9,15,betternether:quartz_stained_glass:15)
B(9,10,13,betternether:quartz_stained_glass:15)
B(10,10,13,betternether:quartz_stained_glass:15)
B(7,10,14,betternether:quartz_stained_glass:15)
B(8,10,14,betternether:quartz_stained_glass:15)
RB(9,10,14,srparasites:parasitestain:1,80,quark:crystal:1,30,srparasites:parasiterubbledense:1,100)
B(10,10,14,betternether:quartz_stained_glass:15)
B(7,10,15,betternether:quartz_stained_glass:15)
B(8,10,15,betternether:quartz_stained_glass:15)
RB(9,10,15,srparasites:parasitestain:1,80,quark:crystal:1,30,srparasites:parasiterubbledense:1,100)
RB(10,10,15,srparasites:parasitestain:1,80,quark:crystal:1,30,srparasites:parasiterubbledense:1,100)
B(11,10,15,betternether:quartz_stained_glass:15)
B(10,11,12,betternether:quartz_stained_glass:15)
B(7,11,13,betternether:quartz_stained_glass:15)
B(8,11,13,betternether:quartz_stained_glass:15)
B(9,11,13,betternether:quartz_stained_glass:15)
B(10,11,13,betternether:quartz_stained_glass:15)
B(6,11,14,betternether:quartz_stained_glass:15)
B(7,11,14,betternether:quartz_stained_glass:15)
B(8,11,14,betternether:quartz_stained_glass:15)
RB(9,11,14,srparasites:parasitestain:1,80,quark:crystal:1,30,srparasites:parasiterubbledense:1,100)
RB(10,11,14,srparasites:parasitestain:1,80,quark:crystal:1,30,srparasites:parasiterubbledense:1,100)
B(7,11,15,betternether:quartz_stained_glass:15)
B(8,11,15,betternether:quartz_stained_glass:15)
RB(9,11,15,srparasites:parasitestain:1,80,quark:crystal:1,30,srparasites:parasiterubbledense:1,100)
RB(10,11,15,srparasites:parasitestain:1,80,quark:crystal:1,30,srparasites:parasiterubbledense:1,100)
B(11,11,15,betternether:quartz_stained_glass:15)
B(10,12,12,betternether:quartz_stained_glass:15)
B(7,12,13,betternether:quartz_stained_glass:15)
B(8,12,13,betternether:quartz_stained_glass:15)
B(9,12,13,betternether:quartz_stained_glass:15)
B(10,12,13,betternether:quartz_stained_glass:15)
B(6,12,14,betternether:quartz_stained_glass:15)
B(7,12,14,betternether:quartz_stained_glass:15)
RB(8,12,14,srparasites:parasitestain:1,80,quark:crystal:1,30,srparasites:parasiterubbledense:1,100)
RB(9,12,14,srparasites:parasitestain:1,80,quark:crystal:1,30,srparasites:parasiterubbledense:1,100)
RB(10,12,14,srparasites:parasitestain:1,80,quark:crystal:1,30,srparasites:parasiterubbledense:1,100)
B(7,12,15,betternether:quartz_stained_glass:15)
B(8,12,15,betternether:quartz_stained_glass:15)
RB(9,12,15,srparasites:parasitestain:1,80,quark:crystal:1,30,srparasites:parasiterubbledense:1,100)
RB(10,12,15,srparasites:parasitestain:1,80,quark:crystal:1,30,srparasites:parasiterubbledense:1,100)
B(11,12,15,betternether:quartz_stained_glass:15)
B(9,13,12,betternether:quartz_stained_glass:15)
B(10,13,12,betternether:quartz_stained_glass:15)
B(6,13,13,betternether:quartz_stained_glass:15)
B(7,13,13,betternether:quartz_stained_glass:15)
RB(8,13,13,srparasites:parasitestain:1,80,quark:crystal:1,30,srparasites:parasiterubbledense:1,100)
B(9,13,13,betternether:quartz_stained_glass:15)
B(10,13,13,betternether:quartz_stained_glass:15)
B(6,13,14,betternether:quartz_stained_glass:15)
B(7,13,14,betternether:quartz_stained_glass:15)
RB(8,13,14,srparasites:parasitestain:1,80,quark:crystal:1,30,srparasites:parasiterubbledense:1,100)
RB(9,13,14,srparasites:parasitestain:1,80,quark:crystal:1,30,srparasites:parasiterubbledense:1,100)
RB(10,13,14,srparasites:parasitestain:1,80,quark:crystal:1,30,srparasites:parasiterubbledense:1,100)
B(7,13,15,betternether:quartz_stained_glass:15)
RB(8,13,15,srparasites:parasitestain:1,80,quark:crystal:1,30,srparasites:parasiterubbledense:1,100)
RB(9,13,15,srparasites:parasitestain:1,80,quark:crystal:1,30,srparasites:parasiterubbledense:1,100)
RB(10,13,15,srparasites:parasitestain:1,80,quark:crystal:1,30,srparasites:parasiterubbledense:1,100)
B(11,13,15,betternether:quartz_stained_glass:15)
B(8,14,11,betternether:quartz_stained_glass:15)
B(9,14,11,betternether:quartz_stained_glass:15)
B(7,14,12,betternether:quartz_stained_glass:15)
B(8,14,12,betternether:quartz_stained_glass:15)
B(9,14,12,betternether:quartz_stained_glass:15)
B(10,14,12,betternether:quartz_stained_glass:15)
B(5,14,13,betternether:quartz_stained_glass:15)
B(6,14,13,betternether:quartz_stained_glass:15)
B(7,14,13,betternether:quartz_stained_glass:15)
RB(8,14,13,srparasites:parasitestain:1,80,quark:crystal:1,30,srparasites:parasiterubbledense:1,100)
RB(9,14,13,srparasites:parasitestain:1,80,quark:crystal:1,30,srparasites:parasiterubbledense:1,100)
B(10,14,13,betternether:quartz_stained_glass:15)
B(6,14,14,betternether:quartz_stained_glass:15)
B(7,14,14,betternether:quartz_stained_glass:15)
RB(8,14,14,srparasites:parasitestain:1,80,quark:crystal:1,30,srparasites:parasiterubbledense:1,100)
RB(9,14,14,srparasites:parasitestain:1,80,quark:crystal:1,30,srparasites:parasiterubbledense:1,100)
B(10,14,14,betternether:quartz_stained_glass:15)
B(7,14,15,betternether:quartz_stained_glass:15)
RB(8,14,15,srparasites:parasitestain:1,80,quark:crystal:1,30,srparasites:parasiterubbledense:1,100)
RB(9,14,15,srparasites:parasitestain:1,80,quark:crystal:1,30,srparasites:parasiterubbledense:1,100)
B(10,14,15,betternether:quartz_stained_glass:15)
B(11,14,15,betternether:quartz_stained_glass:15)
B(8,15,11,betternether:quartz_stained_glass:15)
B(9,15,11,betternether:quartz_stained_glass:15)
B(7,15,12,betternether:quartz_stained_glass:15)
B(8,15,12,betternether:quartz_stained_glass:15)
B(9,15,12,betternether:quartz_stained_glass:15)
B(10,15,12,betternether:quartz_stained_glass:15)
B(5,15,13,betternether:quartz_stained_glass:15)
B(6,15,13,betternether:quartz_stained_glass:15)
B(7,15,13,betternether:quartz_stained_glass:15)
RB(8,15,13,srparasites:parasitestain:1,80,quark:crystal:1,30,srparasites:parasiterubbledense:1,100)
RB(9,15,13,srparasites:parasitestain:1,80,quark:crystal:1,30,srparasites:parasiterubbledense:1,100)
B(10,15,13,betternether:quartz_stained_glass:15)
B(6,15,14,betternether:quartz_stained_glass:15)
B(7,15,14,betternether:quartz_stained_glass:15)
RB(8,15,14,srparasites:parasitestain:1,80,quark:crystal:1,30,srparasites:parasiterubbledense:1,100)
RB(9,15,14,srparasites:parasitestain:1,80,quark:crystal:1,30,srparasites:parasiterubbledense:1,100)
B(10,15,14,betternether:quartz_stained_glass:15)
B(7,15,15,betternether:quartz_stained_glass:15)
B(8,15,15,betternether:quartz_stained_glass:15)
RB(9,15,15,srparasites:parasitestain:1,80,quark:crystal:1,30,srparasites:parasiterubbledense:1,100)
B(10,15,15,betternether:quartz_stained_glass:15)
B(11,15,15,betternether:quartz_stained_glass:15)
B(8,16,10,betternether:quartz_stained_glass:15)
B(7,16,11,betternether:quartz_stained_glass:15)
RB(8,16,11,srparasites:parasitestain:1,80,quark:crystal:1,30,srparasites:parasiterubbledense:1,100)
B(9,16,11,betternether:quartz_stained_glass:15)
B(5,16,12,betternether:quartz_stained_glass:15)
B(6,16,12,betternether:quartz_stained_glass:15)
B(7,16,12,betternether:quartz_stained_glass:15)
RB(8,16,12,srparasites:parasitestain:1,80,quark:crystal:1,30,srparasites:parasiterubbledense:1,100)
B(9,16,12,betternether:quartz_stained_glass:15)
B(10,16,12,betternether:quartz_stained_glass:15)
B(5,16,13,betternether:quartz_stained_glass:15)
B(6,16,13,betternether:quartz_stained_glass:15)
RB(7,16,13,srparasites:parasitestain:1,80,quark:crystal:1,30,srparasites:parasiterubbledense:1,100)
RB(8,16,13,srparasites:parasitestain:1,80,quark:crystal:1,30,srparasites:parasiterubbledense:1,100)
RB(9,16,13,srparasites:parasitestain:1,80,quark:crystal:1,30,srparasites:parasiterubbledense:1,100)
B(10,16,13,betternether:quartz_stained_glass:15)
B(6,16,14,betternether:quartz_stained_glass:15)
B(7,16,14,betternether:quartz_stained_glass:15)
RB(8,16,14,srparasites:parasitestain:1,80,quark:crystal:1,30,srparasites:parasiterubbledense:1,100)
RB(9,16,14,srparasites:parasitestain:1,80,quark:crystal:1,30,srparasites:parasiterubbledense:1,100)
B(10,16,14,betternether:quartz_stained_glass:15)
B(7,16,15,betternether:quartz_stained_glass:15)
B(8,16,15,betternether:quartz_stained_glass:15)
B(9,16,15,betternether:quartz_stained_glass:15)
B(10,16,15,betternether:quartz_stained_glass:15)
B(7,17,10,betternether:quartz_stained_glass:15)
B(8,17,10,betternether:quartz_stained_glass:15)
B(5,17,11,betternether:quartz_stained_glass:15)
B(6,17,11,betternether:quartz_stained_glass:15)
B(7,17,11,betternether:quartz_stained_glass:15)
RB(8,17,11,srparasites:parasitestain:1,80,quark:crystal:1,30,srparasites:parasiterubbledense:1,100)
B(9,17,11,betternether:quartz_stained_glass:15)
B(5,17,12,betternether:quartz_stained_glass:15)
B(6,17,12,betternether:quartz_stained_glass:15)
B(7,17,12,betternether:quartz_stained_glass:15)
RB(8,17,12,srparasites:parasitestain:1,80,quark:crystal:1,30,srparasites:parasiterubbledense:1,100)
RB(9,17,12,srparasites:parasitestain:1,80,quark:crystal:1,30,srparasites:parasiterubbledense:1,100)
B(10,17,12,betternether:quartz_stained_glass:15)
B(5,17,13,betternether:quartz_stained_glass:15)
B(6,17,13,betternether:quartz_stained_glass:15)
RB(7,17,13,srparasites:parasitestain:1,80,quark:crystal:1,30,srparasites:parasiterubbledense:1,100)
RB(8,17,13,srparasites:parasitestain:1,80,quark:crystal:1,30,srparasites:parasiterubbledense:1,100)
B(9,17,13,betternether:quartz_stained_glass:15)
B(10,17,13,betternether:quartz_stained_glass:15)
B(6,17,14,betternether:quartz_stained_glass:15)
B(7,17,14,betternether:quartz_stained_glass:15)
RB(8,17,14,srparasites:parasitestain:1,80,quark:crystal:1,30,srparasites:parasiterubbledense:1,100)
RB(9,17,14,srparasites:parasitestain:1,80,quark:crystal:1,30,srparasites:parasiterubbledense:1,100)
B(10,17,14,betternether:quartz_stained_glass:15)
B(7,17,15,betternether:quartz_stained_glass:15)
B(8,17,15,betternether:quartz_stained_glass:15)
B(9,17,15,betternether:quartz_stained_glass:15)
B(7,18,10,betternether:quartz_stained_glass:15)
B(8,18,10,betternether:quartz_stained_glass:15)
B(5,18,11,betternether:quartz_stained_glass:15)
B(6,18,11,betternether:quartz_stained_glass:15)
RB(7,18,11,srparasites:parasitestain:1,80,quark:crystal:1,30,srparasites:parasiterubbledense:1,100)
RB(8,18,11,srparasites:parasitestain:1,80,quark:crystal:1,30,srparasites:parasiterubbledense:1,100)
B(9,18,11,betternether:quartz_stained_glass:15)
B(5,18,12,betternether:quartz_stained_glass:15)
B(6,18,12,betternether:quartz_stained_glass:15)
B(7,18,12,betternether:quartz_stained_glass:15)
RB(8,18,12,srparasites:parasitestain:1,80,quark:crystal:1,30,srparasites:parasiterubbledense:1,100)
RB(9,18,12,srparasites:parasitestain:1,80,quark:crystal:1,30,srparasites:parasiterubbledense:1,100)
B(10,18,12,betternether:quartz_stained_glass:15)
B(5,18,13,betternether:quartz_stained_glass:15)
B(6,18,13,betternether:quartz_stained_glass:15)
B(7,18,13,betternether:quartz_stained_glass:15)
RB(8,18,13,srparasites:parasitestain:1,80,quark:crystal:1,30,srparasites:parasiterubbledense:1,100)
B(9,18,13,betternether:quartz_stained_glass:15)
B(10,18,13,betternether:quartz_stained_glass:15)
B(6,18,14,betternether:quartz_stained_glass:15)
B(7,18,14,betternether:quartz_stained_glass:15)
RB(8,18,14,srparasites:parasitestain:1,80,quark:crystal:1,30,srparasites:parasiterubbledense:1,100)
B(9,18,14,betternether:quartz_stained_glass:15)
B(7,18,15,betternether:quartz_stained_glass:15)
B(8,18,15,betternether:quartz_stained_glass:15)
B(8,19,9,betternether:quartz_stained_glass:15)
B(5,19,10,betternether:quartz_stained_glass:15)
B(6,19,10,betternether:quartz_stained_glass:15)
B(7,19,10,betternether:quartz_stained_glass:15)
B(8,19,10,betternether:quartz_stained_glass:15)
B(5,19,11,betternether:quartz_stained_glass:15)
B(6,19,11,betternether:quartz_stained_glass:15)
RB(7,19,11,srparasites:parasitestain:1,80,quark:crystal:1,30,srparasites:parasiterubbledense:1,100)
RB(8,19,11,srparasites:parasitestain:1,80,quark:crystal:1,30,srparasites:parasiterubbledense:1,100)
B(9,19,11,betternether:quartz_stained_glass:15)
B(5,19,12,betternether:quartz_stained_glass:15)
B(6,19,12,betternether:quartz_stained_glass:15)
RB(7,19,12,srparasites:parasitestain:1,80,quark:crystal:1,30,srparasites:parasiterubbledense:1,100)
RB(8,19,12,srparasites:parasitestain:1,80,quark:crystal:1,30,srparasites:parasiterubbledense:1,100)
RB(9,19,12,srparasites:parasitestain:1,80,quark:crystal:1,30,srparasites:parasiterubbledense:1,100)
B(10,19,12,betternether:quartz_stained_glass:15)
B(5,19,13,betternether:quartz_stained_glass:15)
B(6,19,13,betternether:quartz_stained_glass:15)
B(7,19,13,betternether:quartz_stained_glass:15)
RB(8,19,13,srparasites:parasitestain:1,80,quark:crystal:1,30,srparasites:parasiterubbledense:1,100)
B(9,19,13,betternether:quartz_stained_glass:15)
B(6,19,14,betternether:quartz_stained_glass:15)
B(7,19,14,betternether:quartz_stained_glass:15)
B(8,19,14,betternether:quartz_stained_glass:15)
B(9,19,14,betternether:quartz_stained_glass:15)
B(8,19,15,betternether:quartz_stained_glass:15)
B(8,20,8,betternether:quartz_stained_glass:15)
B(7,20,9,betternether:quartz_stained_glass:15)
B(8,20,9,betternether:quartz_stained_glass:15)
B(4,20,10,betternether:quartz_stained_glass:15)
B(5,20,10,betternether:quartz_stained_glass:15)
B(6,20,10,betternether:quartz_stained_glass:15)
RB(7,20,10,srparasites:parasitestain:1,80,quark:crystal:1,30,srparasites:parasiterubbledense:1,100)
RB(8,20,10,srparasites:parasitestain:1,80,quark:crystal:1,30,srparasites:parasiterubbledense:1,100)
B(5,20,11,betternether:quartz_stained_glass:15)
B(6,20,11,betternether:quartz_stained_glass:15)
RB(7,20,11,srparasites:parasitestain:1,80,quark:crystal:1,30,srparasites:parasiterubbledense:1,100)
RB(8,20,11,srparasites:parasitestain:1,80,quark:crystal:1,30,srparasites:parasiterubbledense:1,100)
B(9,20,11,betternether:quartz_stained_glass:15)
B(5,20,12,betternether:quartz_stained_glass:15)
B(6,20,12,betternether:quartz_stained_glass:15)
RB(7,20,12,srparasites:parasitestain:1,80,quark:crystal:1,30,srparasites:parasiterubbledense:1,100)
RB(8,20,12,srparasites:parasitestain:1,80,quark:crystal:1,30,srparasites:parasiterubbledense:1,100)
B(9,20,12,betternether:quartz_stained_glass:15)
B(10,20,12,betternether:quartz_stained_glass:15)
B(5,20,13,betternether:quartz_stained_glass:15)
B(6,20,13,betternether:quartz_stained_glass:15)
B(7,20,13,betternether:quartz_stained_glass:15)
RB(8,20,13,srparasites:parasitestain:1,80,quark:crystal:1,30,srparasites:parasiterubbledense:1,100)
B(9,20,13,betternether:quartz_stained_glass:15)
B(6,20,14,betternether:quartz_stained_glass:15)
B(7,20,14,betternether:quartz_stained_glass:15)
B(8,20,14,betternether:quartz_stained_glass:15)
B(8,21,8,betternether:quartz_stained_glass:15)
B(7,21,9,betternether:quartz_stained_glass:15)
B(8,21,9,betternether:quartz_stained_glass:15)
B(4,21,10,betternether:quartz_stained_glass:15)
B(5,21,10,betternether:quartz_stained_glass:15)
RB(6,21,10,srparasites:parasitestain:1,80,quark:crystal:1,30,srparasites:parasiterubbledense:1,100)
RB(7,21,10,srparasites:parasitestain:1,80,quark:crystal:1,30,srparasites:parasiterubbledense:1,100)
RB(8,21,10,srparasites:parasitestain:1,80,quark:crystal:1,30,srparasites:parasiterubbledense:1,100)
B(5,21,11,betternether:quartz_stained_glass:15)
B(6,21,11,betternether:quartz_stained_glass:15)
RB(7,21,11,srparasites:parasitestain:1,80,quark:crystal:1,30,srparasites:parasiterubbledense:1,100)
RB(8,21,11,srparasites:parasitestain:1,80,quark:crystal:1,30,srparasites:parasiterubbledense:1,100)
B(9,21,11,betternether:quartz_stained_glass:15)
B(5,21,12,betternether:quartz_stained_glass:15)
B(6,21,12,betternether:quartz_stained_glass:15)
B(7,21,12,betternether:quartz_stained_glass:15)
RB(8,21,12,srparasites:parasitestain:1,80,quark:crystal:1,30,srparasites:parasiterubbledense:1,100)
B(9,21,12,betternether:quartz_stained_glass:15)
B(10,21,12,betternether:quartz_stained_glass:15)
B(5,21,13,betternether:quartz_stained_glass:15)
B(6,21,13,betternether:quartz_stained_glass:15)
B(7,21,13,betternether:quartz_stained_glass:15)
B(8,21,13,betternether:quartz_stained_glass:15)
B(6,21,14,betternether:quartz_stained_glass:15)
B(7,22,8,betternether:quartz_stained_glass:15)
B(8,22,8,betternether:quartz_stained_glass:15)
B(4,22,9,betternether:quartz_stained_glass:15)
B(5,22,9,betternether:quartz_stained_glass:15)
B(6,22,9,betternether:quartz_stained_glass:15)
B(7,22,9,betternether:quartz_stained_glass:15)
B(8,22,9,betternether:quartz_stained_glass:15)
B(4,22,10,betternether:quartz_stained_glass:15)
B(5,22,10,betternether:quartz_stained_glass:15)
RB(6,22,10,srparasites:parasitestain:1,80,quark:crystal:1,30,srparasites:parasiterubbledense:1,100)
RB(7,22,10,srparasites:parasitestain:1,80,quark:crystal:1,30,srparasites:parasiterubbledense:1,100)
RB(8,22,10,srparasites:parasitestain:1,80,quark:crystal:1,30,srparasites:parasiterubbledense:1,100)
B(5,22,11,betternether:quartz_stained_glass:15)
RB(6,22,11,srparasites:parasitestain:1,80,quark:crystal:1,30,srparasites:parasiterubbledense:1,100)
RB(7,22,11,srparasites:parasitestain:1,80,quark:crystal:1,30,srparasites:parasiterubbledense:1,100)
RB(8,22,11,srparasites:parasitestain:1,80,quark:crystal:1,30,srparasites:parasiterubbledense:1,100)
B(9,22,11,betternether:quartz_stained_glass:15)
B(5,22,12,betternether:quartz_stained_glass:15)
B(6,22,12,betternether:quartz_stained_glass:15)
B(7,22,12,betternether:quartz_stained_glass:15)
RB(8,22,12,srparasites:parasitestain:1,80,quark:crystal:1,30,srparasites:parasiterubbledense:1,100)
B(9,22,12,betternether:quartz_stained_glass:15)
B(5,22,13,betternether:quartz_stained_glass:15)
B(6,22,13,betternether:quartz_stained_glass:15)
B(7,22,13,betternether:quartz_stained_glass:15)
B(8,22,13,betternether:quartz_stained_glass:15)
B(7,23,7,betternether:quartz_stained_glass:15)
B(5,23,8,betternether:quartz_stained_glass:15)
B(6,23,8,betternether:quartz_stained_glass:15)
B(7,23,8,betternether:quartz_stained_glass:15)
B(8,23,8,betternether:quartz_stained_glass:15)
B(3,23,9,betternether:quartz_stained_glass:15)
B(4,23,9,betternether:quartz_stained_glass:15)
B(5,23,9,betternether:quartz_stained_glass:15)
B(6,23,9,betternether:quartz_stained_glass:15)
RB(7,23,9,srparasites:parasitestain:1,80,quark:crystal:1,30,srparasites:parasiterubbledense:1,100)
RB(8,23,9,srparasites:parasitestain:1,80,quark:crystal:1,30,srparasites:parasiterubbledense:1,100)
B(4,23,10,betternether:quartz_stained_glass:15)
B(5,23,10,betternether:quartz_stained_glass:15)
RB(6,23,10,srparasites:parasitestain:1,80,quark:crystal:1,30,srparasites:parasiterubbledense:1,100)
RB(7,23,10,srparasites:parasitestain:1,80,quark:crystal:1,30,srparasites:parasiterubbledense:1,100)
B(8,23,10,betternether:quartz_stained_glass:15)
B(5,23,11,betternether:quartz_stained_glass:15)
RB(6,23,11,srparasites:parasitestain:1,80,quark:crystal:1,30,srparasites:parasiterubbledense:1,100)
RB(7,23,11,srparasites:parasitestain:1,80,quark:crystal:1,30,srparasites:parasiterubbledense:1,100)
RB(8,23,11,srparasites:parasitestain:1,80,quark:crystal:1,30,srparasites:parasiterubbledense:1,100)
B(9,23,11,betternether:quartz_stained_glass:15)
B(5,23,12,betternether:quartz_stained_glass:15)
B(6,23,12,betternether:quartz_stained_glass:15)
B(7,23,12,betternether:quartz_stained_glass:15)
RB(8,23,12,srparasites:parasitestain:1,80,quark:crystal:1,30,srparasites:parasiterubbledense:1,100)
B(9,23,12,betternether:quartz_stained_glass:15)
B(5,23,13,betternether:quartz_stained_glass:15)
B(6,23,13,betternether:quartz_stained_glass:15)
B(7,24,7,betternether:quartz_stained_glass:15)
B(5,24,8,betternether:quartz_stained_glass:15)
B(6,24,8,betternether:quartz_stained_glass:15)
B(7,24,8,betternether:quartz_stained_glass:15)
B(8,24,8,betternether:quartz_stained_glass:15)
B(3,24,9,betternether:quartz_stained_glass:15)
B(4,24,9,betternether:quartz_stained_glass:15)
B(5,24,9,betternether:quartz_stained_glass:15)
RB(6,24,9,srparasites:parasitestain:1,80,quark:crystal:1,30,srparasites:parasiterubbledense:1,100)
RB(7,24,9,srparasites:parasitestain:1,80,quark:crystal:1,30,srparasites:parasiterubbledense:1,100)
RB(8,24,9,srparasites:parasitestain:1,80,quark:crystal:1,30,srparasites:parasiterubbledense:1,100)
B(4,24,10,betternether:quartz_stained_glass:15)
B(5,24,10,betternether:quartz_stained_glass:15)
RB(6,24,10,srparasites:parasitestain:1,80,quark:crystal:1,30,srparasites:parasiterubbledense:1,100)
RB(7,24,10,srparasites:parasitestain:1,80,quark:crystal:1,30,srparasites:parasiterubbledense:1,100)
B(8,24,10,betternether:quartz_stained_glass:15)
B(5,24,11,betternether:quartz_stained_glass:15)
B(6,24,11,betternether:quartz_stained_glass:15)
RB(7,24,11,srparasites:parasitestain:1,80,quark:crystal:1,30,srparasites:parasiterubbledense:1,100)
B(8,24,11,betternether:quartz_stained_glass:15)
B(9,24,11,betternether:quartz_stained_glass:15)
B(5,24,12,betternether:quartz_stained_glass:15)
B(6,24,12,betternether:quartz_stained_glass:15)
B(7,24,12,betternether:quartz_stained_glass:15)
B(8,24,12,betternether:quartz_stained_glass:15)
B(5,24,13,betternether:quartz_stained_glass:15)
B(5,25,7,betternether:quartz_stained_glass:15)
B(6,25,7,betternether:quartz_stained_glass:15)
B(7,25,7,betternether:quartz_stained_glass:15)
B(4,25,8,betternether:quartz_stained_glass:15)
B(5,25,8,betternether:quartz_stained_glass:15)
B(6,25,8,betternether:quartz_stained_glass:15)
B(7,25,8,betternether:quartz_stained_glass:15)
B(8,25,8,betternether:quartz_stained_glass:15)
B(3,25,9,betternether:quartz_stained_glass:15)
B(4,25,9,betternether:quartz_stained_glass:15)
B(5,25,9,betternether:quartz_stained_glass:15)
RB(6,25,9,srparasites:parasitestain:1,80,quark:crystal:1,30,srparasites:parasiterubbledense:1,100)
RB(7,25,9,srparasites:parasitestain:1,80,quark:crystal:1,30,srparasites:parasiterubbledense:1,100)
RB(8,25,9,srparasites:parasitestain:1,80,quark:crystal:1,30,srparasites:parasiterubbledense:1,100)
B(4,25,10,betternether:quartz_stained_glass:15)
B(5,25,10,betternether:quartz_stained_glass:15)
RB(6,25,10,srparasites:parasitestain:1,80,quark:crystal:1,30,srparasites:parasiterubbledense:1,100)
RB(7,25,10,srparasites:parasitestain:1,80,quark:crystal:1,30,srparasites:parasiterubbledense:1,100)
B(8,25,10,betternether:quartz_stained_glass:15)
B(5,25,11,betternether:quartz_stained_glass:15)
B(6,25,11,betternether:quartz_stained_glass:15)
B(7,25,11,betternether:quartz_stained_glass:15)
B(8,25,11,betternether:quartz_stained_glass:15)
B(5,25,12,betternether:quartz_stained_glass:15)
B(6,25,12,betternether:quartz_stained_glass:15)
B(7,25,12,betternether:quartz_stained_glass:15)
B(8,25,12,betternether:quartz_stained_glass:15)
B(6,26,6,betternether:quartz_stained_glass:15)
B(7,26,6,betternether:quartz_stained_glass:15)
B(4,26,7,betternether:quartz_stained_glass:15)
B(5,26,7,betternether:quartz_stained_glass:15)
B(6,26,7,betternether:quartz_stained_glass:15)
B(7,26,7,betternether:quartz_stained_glass:15)
B(3,26,8,betternether:quartz_stained_glass:15)
B(4,26,8,betternether:quartz_stained_glass:15)
B(5,26,8,betternether:quartz_stained_glass:15)
RB(6,26,8,srparasites:parasitestain:1,80,quark:crystal:1,30,srparasites:parasiterubbledense:1,100)
RB(7,26,8,srparasites:parasitestain:1,80,quark:crystal:1,30,srparasites:parasiterubbledense:1,100)
B(8,26,8,betternether:quartz_stained_glass:15)
B(3,26,9,betternether:quartz_stained_glass:15)
B(4,26,9,betternether:quartz_stained_glass:15)
B(5,26,9,betternether:quartz_stained_glass:15)
RB(6,26,9,srparasites:parasitestain:1,80,quark:crystal:1,30,srparasites:parasiterubbledense:1,100)
RB(7,26,9,srparasites:parasitestain:1,80,quark:crystal:1,30,srparasites:parasiterubbledense:1,100)
B(8,26,9,betternether:quartz_stained_glass:15)
B(4,26,10,betternether:quartz_stained_glass:15)
B(5,26,10,betternether:quartz_stained_glass:15)
RB(6,26,10,srparasites:parasitestain:1,80,quark:crystal:1,30,srparasites:parasiterubbledense:1,100)
RB(7,26,10,srparasites:parasitestain:1,80,quark:crystal:1,30,srparasites:parasiterubbledense:1,100)
B(8,26,10,betternether:quartz_stained_glass:15)
B(5,26,11,betternether:quartz_stained_glass:15)
B(6,26,11,betternether:quartz_stained_glass:15)
B(7,26,11,betternether:quartz_stained_glass:15)
B(5,26,12,betternether:quartz_stained_glass:15)
B(6,26,12,betternether:quartz_stained_glass:15)
B(6,27,6,betternether:quartz_stained_glass:15)
B(7,27,6,betternether:quartz_stained_glass:15)
B(4,27,7,betternether:quartz_stained_glass:15)
RB(5,27,7,srparasites:parasitestain:1,80,quark:crystal:1,30,srparasites:parasiterubbledense:1,100)
B(6,27,7,betternether:quartz_stained_glass:15)
B(7,27,7,betternether:quartz_stained_glass:15)
B(3,27,8,betternether:quartz_stained_glass:15)
B(4,27,8,betternether:quartz_stained_glass:15)
B(5,27,8,betternether:quartz_stained_glass:15)
RB(6,27,8,srparasites:parasitestain:1,80,quark:crystal:1,30,srparasites:parasiterubbledense:1,100)
RB(7,27,8,srparasites:parasitestain:1,80,quark:crystal:1,30,srparasites:parasiterubbledense:1,100)
B(8,27,8,betternether:quartz_stained_glass:15)
B(3,27,9,betternether:quartz_stained_glass:15)
B(4,27,9,betternether:quartz_stained_glass:15)
B(5,27,9,betternether:quartz_stained_glass:15)
RB(6,27,9,srparasites:parasitestain:1,80,quark:crystal:1,30,srparasites:parasiterubbledense:1,100)
RB(7,27,9,srparasites:parasitestain:1,80,quark:crystal:1,30,srparasites:parasiterubbledense:1,100)
B(8,27,9,betternether:quartz_stained_glass:15)
B(4,27,10,betternether:quartz_stained_glass:15)
B(5,27,10,betternether:quartz_stained_glass:15)
RB(6,27,10,srparasites:parasitestain:1,80,quark:crystal:1,30,srparasites:parasiterubbledense:1,100)
B(7,27,10,betternether:quartz_stained_glass:15)
B(5,27,11,betternether:quartz_stained_glass:15)
B(6,27,11,betternether:quartz_stained_glass:15)
B(6,28,5,betternether:quartz_stained_glass:15)
B(3,28,6,betternether:quartz_stained_glass:15)
B(4,28,6,betternether:quartz_stained_glass:15)
B(5,28,6,betternether:quartz_stained_glass:15)
B(6,28,6,betternether:quartz_stained_glass:15)
B(7,28,6,betternether:quartz_stained_glass:15)
B(3,28,7,betternether:quartz_stained_glass:15)
B(4,28,7,betternether:quartz_stained_glass:15)
RB(5,28,7,srparasites:parasitestain:1,80,quark:crystal:1,30,srparasites:parasiterubbledense:1,100)
B(6,28,7,betternether:quartz_stained_glass:15)
B(7,28,7,betternether:quartz_stained_glass:15)
B(3,28,8,betternether:quartz_stained_glass:15)
B(4,28,8,betternether:quartz_stained_glass:15)
RB(5,28,8,srparasites:parasitestain:1,80,quark:crystal:1,30,srparasites:parasiterubbledense:1,100)
RB(6,28,8,srparasites:parasitestain:1,80,quark:crystal:1,30,srparasites:parasiterubbledense:1,100)
RB(7,28,8,srparasites:parasitestain:1,80,quark:crystal:1,30,srparasites:parasiterubbledense:1,100)
B(8,28,8,betternether:quartz_stained_glass:15)
B(3,28,9,betternether:quartz_stained_glass:15)
B(4,28,9,betternether:quartz_stained_glass:15)
B(5,28,9,betternether:quartz_stained_glass:15)
RB(6,28,9,srparasites:parasitestain:1,80,quark:crystal:1,30,srparasites:parasiterubbledense:1,100)
RB(7,28,9,srparasites:parasitestain:1,80,quark:crystal:1,30,srparasites:parasiterubbledense:1,100)
B(8,28,9,betternether:quartz_stained_glass:15)
B(4,28,10,betternether:quartz_stained_glass:15)
B(5,28,10,betternether:quartz_stained_glass:15)
B(6,28,10,betternether:quartz_stained_glass:15)
B(7,28,10,betternether:quartz_stained_glass:15)
B(6,28,11,betternether:quartz_stained_glass:15)
B(6,29,4,betternether:quartz_stained_glass:15)
B(5,29,5,betternether:quartz_stained_glass:15)
B(6,29,5,betternether:quartz_stained_glass:15)
B(2,29,6,betternether:quartz_stained_glass:15)
B(3,29,6,betternether:quartz_stained_glass:15)
B(4,29,6,betternether:quartz_stained_glass:15)
B(5,29,6,betternether:quartz_stained_glass:15)
RB(6,29,6,srparasites:parasitestain:1,80,quark:crystal:1,30,srparasites:parasiterubbledense:1,100)
B(7,29,6,betternether:quartz_stained_glass:15)
B(3,29,7,betternether:quartz_stained_glass:15)
B(4,29,7,betternether:quartz_stained_glass:15)
RB(5,29,7,srparasites:parasitestain:1,80,quark:crystal:1,30,srparasites:parasiterubbledense:1,100)
RB(6,29,7,srparasites:parasitestain:1,80,quark:crystal:1,30,srparasites:parasiterubbledense:1,100)
B(7,29,7,betternether:quartz_stained_glass:15)
B(3,29,8,betternether:quartz_stained_glass:15)
B(4,29,8,betternether:quartz_stained_glass:15)
RB(5,29,8,srparasites:parasitestain:1,80,quark:crystal:1,30,srparasites:parasiterubbledense:1,100)
RB(6,29,8,srparasites:parasitestain:1,80,quark:crystal:1,30,srparasites:parasiterubbledense:1,100)
B(7,29,8,betternether:quartz_stained_glass:15)
B(8,29,8,betternether:quartz_stained_glass:15)
B(3,29,9,betternether:quartz_stained_glass:15)
B(4,29,9,betternether:quartz_stained_glass:15)
B(5,29,9,betternether:quartz_stained_glass:15)
RB(6,29,9,srparasites:parasitestain:1,80,quark:crystal:1,30,srparasites:parasiterubbledense:1,100)
RB(7,29,9,srparasites:parasitestain:1,80,quark:crystal:1,30,srparasites:parasiterubbledense:1,100)
B(8,29,9,betternether:quartz_stained_glass:15)
B(4,29,10,betternether:quartz_stained_glass:15)
B(5,29,10,betternether:quartz_stained_glass:15)
B(6,29,10,betternether:quartz_stained_glass:15)
B(6,30,4,betternether:quartz_stained_glass:15)
B(5,30,5,betternether:quartz_stained_glass:15)
B(6,30,5,betternether:quartz_stained_glass:15)
B(2,30,6,betternether:quartz_stained_glass:15)
B(3,30,6,betternether:quartz_stained_glass:15)
RB(4,30,6,srparasites:parasitestain:1,80,quark:crystal:1,30,srparasites:parasiterubbledense:1,100)
RB(5,30,6,srparasites:parasitestain:1,80,quark:crystal:1,30,srparasites:parasiterubbledense:1,100)
RB(6,30,6,srparasites:parasitestain:1,80,quark:crystal:1,30,srparasites:parasiterubbledense:1,100)
B(7,30,6,betternether:quartz_stained_glass:15)
B(3,30,7,betternether:quartz_stained_glass:15)
B(4,30,7,betternether:quartz_stained_glass:15)
RB(5,30,7,srparasites:parasitestain:1,80,quark:crystal:1,30,srparasites:parasiterubbledense:1,100)
RB(6,30,7,srparasites:parasitestain:1,80,quark:crystal:1,30,srparasites:parasiterubbledense:1,100)
B(7,30,7,betternether:quartz_stained_glass:15)
B(3,30,8,betternether:quartz_stained_glass:15)
B(4,30,8,betternether:quartz_stained_glass:15)
B(5,30,8,betternether:quartz_stained_glass:15)
RB(6,30,8,srparasites:parasitestain:1,80,quark:crystal:1,30,srparasites:parasiterubbledense:1,100)
B(7,30,8,betternether:quartz_stained_glass:15)
B(8,30,8,betternether:quartz_stained_glass:15)
B(3,30,9,betternether:quartz_stained_glass:15)
B(4,30,9,betternether:quartz_stained_glass:15)
B(5,30,9,betternether:quartz_stained_glass:15)
RB(6,30,9,srparasites:parasitestain:1,80,quark:crystal:1,30,srparasites:parasiterubbledense:1,100)
B(7,30,9,betternether:quartz_stained_glass:15)
B(4,30,10,betternether:quartz_stained_glass:15)
B(5,31,4,betternether:quartz_stained_glass:15)
B(6,31,4,betternether:quartz_stained_glass:15)
B(3,31,5,betternether:quartz_stained_glass:15)
B(4,31,5,betternether:quartz_stained_glass:15)
B(5,31,5,betternether:quartz_stained_glass:15)
B(6,31,5,betternether:quartz_stained_glass:15)
B(2,31,6,betternether:quartz_stained_glass:15)
B(3,31,6,betternether:quartz_stained_glass:15)
RB(4,31,6,srparasites:parasitestain:1,80,quark:crystal:1,30,srparasites:parasiterubbledense:1,100)
RB(5,31,6,srparasites:parasitestain:1,80,quark:crystal:1,30,srparasites:parasiterubbledense:1,100)
RB(6,31,6,srparasites:parasitestain:1,80,quark:crystal:1,30,srparasites:parasiterubbledense:1,100)
B(7,31,6,betternether:quartz_stained_glass:15)
B(3,31,7,betternether:quartz_stained_glass:15)
RB(4,31,7,srparasites:parasitestain:1,80,quark:crystal:1,30,srparasites:parasiterubbledense:1,100)
RB(5,31,7,srparasites:parasitestain:1,80,quark:crystal:1,30,srparasites:parasiterubbledense:1,100)
RB(6,31,7,srparasites:parasitestain:1,80,quark:crystal:1,30,srparasites:parasiterubbledense:1,100)
B(7,31,7,betternether:quartz_stained_glass:15)
B(3,31,8,betternether:quartz_stained_glass:15)
B(4,31,8,betternether:quartz_stained_glass:15)
B(5,31,8,betternether:quartz_stained_glass:15)
RB(6,31,8,srparasites:parasitestain:1,80,quark:crystal:1,30,srparasites:parasiterubbledense:1,100)
B(7,31,8,betternether:quartz_stained_glass:15)
B(3,31,9,betternether:quartz_stained_glass:15)
B(4,31,9,betternether:quartz_stained_glass:15)
B(5,31,9,betternether:quartz_stained_glass:15)
B(6,31,9,betternether:quartz_stained_glass:15)
B(7,31,9,betternether:quartz_stained_glass:15)
B(6,32,3,betternether:quartz_stained_glass:15)
B(3,32,4,betternether:quartz_stained_glass:15)
B(4,32,4,betternether:quartz_stained_glass:15)
B(5,32,4,betternether:quartz_stained_glass:15)
B(6,32,4,betternether:quartz_stained_glass:15)
B(2,32,5,betternether:quartz_stained_glass:15)
B(3,32,5,betternether:quartz_stained_glass:15)
B(4,32,5,betternether:quartz_stained_glass:15)
RB(5,32,5,srparasites:parasitestain:1,80,quark:crystal:1,30,srparasites:parasiterubbledense:1,100)
RB(6,32,5,srparasites:parasitestain:1,80,quark:crystal:1,30,srparasites:parasiterubbledense:1,100)
B(2,32,6,betternether:quartz_stained_glass:15)
B(3,32,6,betternether:quartz_stained_glass:15)
RB(4,32,6,srparasites:parasitestain:1,80,quark:crystal:1,30,srparasites:parasiterubbledense:1,100)
RB(5,32,6,srparasites:parasitestain:1,80,quark:crystal:1,30,srparasites:parasiterubbledense:1,100)
RB(6,32,6,srparasites:parasitestain:1,80,quark:crystal:1,30,srparasites:parasiterubbledense:1,100)
B(7,32,6,betternether:quartz_stained_glass:15)
B(3,32,7,betternether:quartz_stained_glass:15)
RB(4,32,7,srparasites:parasitestain:1,80,quark:crystal:1,30,srparasites:parasiterubbledense:1,100)
RB(5,32,7,srparasites:parasitestain:1,80,quark:crystal:1,30,srparasites:parasiterubbledense:1,100)
B(6,32,7,betternether:quartz_stained_glass:15)
B(7,32,7,betternether:quartz_stained_glass:15)
B(3,32,8,betternether:quartz_stained_glass:15)
B(4,32,8,betternether:quartz_stained_glass:15)
B(5,32,8,betternether:quartz_stained_glass:15)
RB(6,32,8,srparasites:parasitestain:1,80,quark:crystal:1,30,srparasites:parasiterubbledense:1,100)
B(7,32,8,betternether:quartz_stained_glass:15)
B(3,32,9,betternether:quartz_stained_glass:15)
B(4,32,9,betternether:quartz_stained_glass:15)
B(5,32,9,betternether:quartz_stained_glass:15)
B(6,32,9,betternether:quartz_stained_glass:15)
B(6,33,3,betternether:quartz_stained_glass:15)
B(3,33,4,betternether:quartz_stained_glass:15)
B(4,33,4,betternether:quartz_stained_glass:15)
B(5,33,4,betternether:quartz_stained_glass:15)
B(6,33,4,betternether:quartz_stained_glass:15)
B(2,33,5,betternether:quartz_stained_glass:15)
B(3,33,5,betternether:quartz_stained_glass:15)
RB(4,33,5,srparasites:parasitestain:1,80,quark:crystal:1,30,srparasites:parasiterubbledense:1,100)
RB(5,33,5,srparasites:parasitestain:1,80,quark:crystal:1,30,srparasites:parasiterubbledense:1,100)
RB(6,33,5,srparasites:parasitestain:1,80,quark:crystal:1,30,srparasites:parasiterubbledense:1,100)
B(2,33,6,betternether:quartz_stained_glass:15)
B(3,33,6,betternether:quartz_stained_glass:15)
RB(4,33,6,srparasites:parasitestain:1,80,quark:crystal:1,30,srparasites:parasiterubbledense:1,100)
RB(5,33,6,srparasites:parasitestain:1,80,quark:crystal:1,30,srparasites:parasiterubbledense:1,100)
RB(6,33,6,srparasites:parasitestain:1,80,quark:crystal:1,30,srparasites:parasiterubbledense:1,100)
B(7,33,6,betternether:quartz_stained_glass:15)
B(3,33,7,betternether:quartz_stained_glass:15)
B(4,33,7,betternether:quartz_stained_glass:15)
RB(5,33,7,srparasites:parasitestain:1,80,quark:crystal:1,30,srparasites:parasiterubbledense:1,100)
B(6,33,7,betternether:quartz_stained_glass:15)
B(7,33,7,betternether:quartz_stained_glass:15)
B(3,33,8,betternether:quartz_stained_glass:15)
B(4,33,8,betternether:quartz_stained_glass:15)
B(5,33,8,betternether:quartz_stained_glass:15)
B(6,33,8,betternether:quartz_stained_glass:15)
B(3,33,9,betternether:quartz_stained_glass:15)
B(6,33,9,betternether:quartz_stained_glass:15)
B(3,34,3,betternether:quartz_stained_glass:15)
B(5,34,3,betternether:quartz_stained_glass:15)
B(6,34,3,betternether:quartz_stained_glass:15)
B(2,34,4,betternether:quartz_stained_glass:15)
B(3,34,4,betternether:quartz_stained_glass:15)
B(4,34,4,betternether:quartz_stained_glass:15)
B(5,34,4,betternether:quartz_stained_glass:15)
B(6,34,4,betternether:quartz_stained_glass:15)
B(2,34,5,betternether:quartz_stained_glass:15)
B(3,34,5,betternether:quartz_stained_glass:15)
RB(4,34,5,srparasites:parasitestain:1,80,quark:crystal:1,30,srparasites:parasiterubbledense:1,100)
RB(5,34,5,srparasites:parasitestain:1,80,quark:crystal:1,30,srparasites:parasiterubbledense:1,100)
RB(6,34,5,srparasites:parasitestain:1,80,quark:crystal:1,30,srparasites:parasiterubbledense:1,100)
B(2,34,6,betternether:quartz_stained_glass:15)
B(3,34,6,betternether:quartz_stained_glass:15)
RB(4,34,6,srparasites:parasitestain:1,80,quark:crystal:1,30,srparasites:parasiterubbledense:1,100)
RB(5,34,6,srparasites:parasitestain:1,80,quark:crystal:1,30,srparasites:parasiterubbledense:1,100)
RB(6,34,6,srparasites:parasitestain:1,80,quark:crystal:1,30,srparasites:parasiterubbledense:1,100)
B(7,34,6,betternether:quartz_stained_glass:15)
B(3,34,7,betternether:quartz_stained_glass:15)
B(4,34,7,betternether:quartz_stained_glass:15)
B(5,34,7,betternether:quartz_stained_glass:15)
B(6,34,7,betternether:quartz_stained_glass:15)
B(3,34,8,betternether:quartz_stained_glass:15)
B(4,34,8,betternether:quartz_stained_glass:15)
B(5,34,8,betternether:quartz_stained_glass:15)
B(6,34,8,betternether:quartz_stained_glass:15)
B(5,35,2,betternether:quartz_stained_glass:15)
B(2,35,3,betternether:quartz_stained_glass:15)
B(3,35,3,betternether:quartz_stained_glass:15)
B(4,35,3,betternether:quartz_stained_glass:15)
B(5,35,3,betternether:quartz_stained_glass:15)
B(6,35,3,betternether:quartz_stained_glass:15)
B(1,35,4,betternether:quartz_stained_glass:15)
B(2,35,4,betternether:quartz_stained_glass:15)
B(3,35,4,betternether:quartz_stained_glass:15)
RB(4,35,4,srparasites:parasitestain:1,80,quark:crystal:1,30,srparasites:parasiterubbledense:1,100)
B(5,35,4,betternether:quartz_stained_glass:15)
B(6,35,4,betternether:quartz_stained_glass:15)
B(2,35,5,betternether:quartz_stained_glass:15)
B(3,35,5,betternether:quartz_stained_glass:15)
RB(4,35,5,srparasites:parasitestain:1,80,quark:crystal:1,30,srparasites:parasiterubbledense:1,100)
RB(5,35,5,srparasites:parasitestain:1,80,quark:crystal:1,30,srparasites:parasiterubbledense:1,100)
B(6,35,5,betternether:quartz_stained_glass:15)
B(2,35,6,betternether:quartz_stained_glass:15)
B(3,35,6,betternether:quartz_stained_glass:15)
RB(4,35,6,srparasites:parasitestain:1,80,quark:crystal:1,30,srparasites:parasiterubbledense:1,100)
RB(5,35,6,srparasites:parasitestain:1,80,quark:crystal:1,30,srparasites:parasiterubbledense:1,100)
RB(6,35,6,srparasites:parasitestain:1,80,quark:crystal:1,30,srparasites:parasiterubbledense:1,100)
B(7,35,6,betternether:quartz_stained_glass:15)
B(3,35,7,betternether:quartz_stained_glass:15)
B(4,35,7,betternether:quartz_stained_glass:15)
B(5,35,7,betternether:quartz_stained_glass:15)
B(6,35,7,betternether:quartz_stained_glass:15)
B(3,35,8,betternether:quartz_stained_glass:15)
B(4,35,8,betternether:quartz_stained_glass:15)
B(5,36,2,betternether:quartz_stained_glass:15)
B(2,36,3,betternether:quartz_stained_glass:15)
RB(3,36,3,srparasites:parasitestain:1,80,quark:crystal:1,30,srparasites:parasiterubbledense:1,100)
B(4,36,3,betternether:quartz_stained_glass:15)
B(5,36,3,betternether:quartz_stained_glass:15)
B(6,36,3,betternether:quartz_stained_glass:15)
B(1,36,4,betternether:quartz_stained_glass:15)
B(2,36,4,betternether:quartz_stained_glass:15)
B(3,36,4,betternether:quartz_stained_glass:15)
RB(4,36,4,srparasites:parasitestain:1,80,quark:crystal:1,30,srparasites:parasiterubbledense:1,100)
RB(5,36,4,srparasites:parasitestain:1,80,quark:crystal:1,30,srparasites:parasiterubbledense:1,100)
B(6,36,4,betternether:quartz_stained_glass:15)
B(2,36,5,betternether:quartz_stained_glass:15)
B(3,36,5,betternether:quartz_stained_glass:15)
RB(4,36,5,srparasites:parasitestain:1,80,quark:crystal:1,30,srparasites:parasiterubbledense:1,100)
RB(5,36,5,srparasites:parasitestain:1,80,quark:crystal:1,30,srparasites:parasiterubbledense:1,100)
B(6,36,5,betternether:quartz_stained_glass:15)
B(2,36,6,betternether:quartz_stained_glass:15)
B(3,36,6,betternether:quartz_stained_glass:15)
RB(4,36,6,srparasites:parasitestain:1,80,quark:crystal:1,30,srparasites:parasiterubbledense:1,100)
RB(5,36,6,srparasites:parasitestain:1,80,quark:crystal:1,30,srparasites:parasiterubbledense:1,100)
B(6,36,6,betternether:quartz_stained_glass:15)
B(7,36,6,betternether:quartz_stained_glass:15)
B(3,36,7,betternether:quartz_stained_glass:15)
B(4,36,7,betternether:quartz_stained_glass:15)
B(5,36,7,betternether:quartz_stained_glass:15)
B(3,36,8,betternether:quartz_stained_glass:15)
B(4,37,1,betternether:quartz_stained_glass:15)
B(3,37,2,betternether:quartz_stained_glass:15)
B(4,37,2,betternether:quartz_stained_glass:15)
B(5,37,2,betternether:quartz_stained_glass:15)
B(1,37,3,betternether:quartz_stained_glass:15)
B(2,37,3,betternether:quartz_stained_glass:15)
RB(3,37,3,srparasites:parasitestain:1,80,quark:crystal:1,30,srparasites:parasiterubbledense:1,100)
B(4,37,3,betternether:quartz_stained_glass:15)
B(5,37,3,betternether:quartz_stained_glass:15)
B(6,37,3,betternether:quartz_stained_glass:15)
B(1,37,4,betternether:quartz_stained_glass:15)
B(2,37,4,betternether:quartz_stained_glass:15)
RB(3,37,4,srparasites:parasitestain:1,80,quark:crystal:1,30,srparasites:parasiterubbledense:1,100)
RB(4,37,4,srparasites:parasitestain:1,80,quark:crystal:1,30,srparasites:parasiterubbledense:1,100)
RB(5,37,4,srparasites:parasitestain:1,80,quark:crystal:1,30,srparasites:parasiterubbledense:1,100)
B(6,37,4,betternether:quartz_stained_glass:15)
B(2,37,5,betternether:quartz_stained_glass:15)
B(3,37,5,betternether:quartz_stained_glass:15)
RB(4,37,5,srparasites:parasitestain:1,80,quark:crystal:1,30,srparasites:parasiterubbledense:1,100)
RB(5,37,5,srparasites:parasitestain:1,80,quark:crystal:1,30,srparasites:parasiterubbledense:1,100)
B(6,37,5,betternether:quartz_stained_glass:15)
B(2,37,6,betternether:quartz_stained_glass:15)
B(3,37,6,betternether:quartz_stained_glass:15)
B(4,37,6,betternether:quartz_stained_glass:15)
B(5,37,6,betternether:quartz_stained_glass:15)
B(6,37,6,betternether:quartz_stained_glass:15)
B(3,37,7,betternether:quartz_stained_glass:15)
B(4,37,7,betternether:quartz_stained_glass:15)
B(3,38,1,betternether:quartz_stained_glass:15)
B(4,38,1,betternether:quartz_stained_glass:15)
B(2,38,2,betternether:quartz_stained_glass:15)
B(3,38,2,betternether:quartz_stained_glass:15)
B(4,38,2,betternether:quartz_stained_glass:15)
B(5,38,2,betternether:quartz_stained_glass:15)
B(1,38,3,betternether:quartz_stained_glass:15)
B(2,38,3,betternether:quartz_stained_glass:15)
RB(3,38,3,srparasites:parasitestain:1,80,quark:crystal:1,30,srparasites:parasiterubbledense:1,100)
RB(4,38,3,srparasites:parasitestain:1,80,quark:crystal:1,30,srparasites:parasiterubbledense:1,100)
B(5,38,3,betternether:quartz_stained_glass:15)
B(6,38,3,betternether:quartz_stained_glass:15)
B(1,38,4,betternether:quartz_stained_glass:15)
B(2,38,4,betternether:quartz_stained_glass:15)
RB(3,38,4,srparasites:parasitestain:1,80,quark:crystal:1,30,srparasites:parasiterubbledense:1,100)
RB(4,38,4,srparasites:parasitestain:1,80,quark:crystal:1,30,srparasites:parasiterubbledense:1,100)
B(5,38,4,betternether:quartz_stained_glass:15)
B(6,38,4,betternether:quartz_stained_glass:15)
B(2,38,5,betternether:quartz_stained_glass:15)
B(3,38,5,betternether:quartz_stained_glass:15)
RB(4,38,5,srparasites:parasitestain:1,80,quark:crystal:1,30,srparasites:parasiterubbledense:1,100)
RB(5,38,5,srparasites:parasitestain:1,80,quark:crystal:1,30,srparasites:parasiterubbledense:1,100)
B(6,38,5,betternether:quartz_stained_glass:15)
B(2,38,6,betternether:quartz_stained_glass:15)
B(3,38,6,betternether:quartz_stained_glass:15)
B(4,38,6,betternether:quartz_stained_glass:15)
B(5,38,6,betternether:quartz_stained_glass:15)
B(3,38,7,betternether:quartz_stained_glass:15)
B(3,39,1,betternether:quartz_stained_glass:15)
B(4,39,1,betternether:quartz_stained_glass:15)
B(2,39,2,betternether:quartz_stained_glass:15)
RB(3,39,2,srparasites:parasitestain:1,80,quark:crystal:1,30,srparasites:parasiterubbledense:1,100)
B(4,39,2,betternether:quartz_stained_glass:15)
B(5,39,2,betternether:quartz_stained_glass:15)
B(1,39,3,betternether:quartz_stained_glass:15)
B(2,39,3,betternether:quartz_stained_glass:15)
RB(3,39,3,srparasites:parasitestain:1,80,quark:crystal:1,30,srparasites:parasiterubbledense:1,100)
RB(4,39,3,srparasites:parasitestain:1,80,quark:crystal:1,30,srparasites:parasiterubbledense:1,100)
RB(5,39,3,srparasites:parasitestain:1,80,quark:crystal:1,30,srparasites:parasiterubbledense:1,100)
B(6,39,3,betternether:quartz_stained_glass:15)
B(1,39,4,betternether:quartz_stained_glass:15)
B(2,39,4,betternether:quartz_stained_glass:15)
B(3,39,4,betternether:quartz_stained_glass:15)
RB(4,39,4,srparasites:parasitestain:1,80,quark:crystal:1,30,srparasites:parasiterubbledense:1,100)
B(5,39,4,betternether:quartz_stained_glass:15)
B(6,39,4,betternether:quartz_stained_glass:15)
B(2,39,5,betternether:quartz_stained_glass:15)
B(3,39,5,betternether:quartz_stained_glass:15)
RB(4,39,5,srparasites:parasitestain:1,80,quark:crystal:1,30,srparasites:parasiterubbledense:1,100)
B(5,39,5,betternether:quartz_stained_glass:15)
B(2,39,6,betternether:quartz_stained_glass:15)
B(4,39,6,betternether:quartz_stained_glass:15)
B(5,39,6,betternether:quartz_stained_glass:15)
B(3,40,0,betternether:quartz_stained_glass:15)
B(4,40,0,betternether:quartz_stained_glass:15)
B(1,40,1,betternether:quartz_stained_glass:15)
B(2,40,1,betternether:quartz_stained_glass:15)
B(3,40,1,betternether:quartz_stained_glass:15)
B(4,40,1,betternether:quartz_stained_glass:15)
B(1,40,2,betternether:quartz_stained_glass:15)
B(2,40,2,betternether:quartz_stained_glass:15)
RB(3,40,2,srparasites:parasitestain:1,80,quark:crystal:1,30,srparasites:parasiterubbledense:1,100)
B(4,40,2,betternether:quartz_stained_glass:15)
B(5,40,2,betternether:quartz_stained_glass:15)
B(1,40,3,betternether:quartz_stained_glass:15)
RB(2,40,3,srparasites:parasitestain:1,80,quark:crystal:1,30,srparasites:parasiterubbledense:1,100)
RB(3,40,3,srparasites:parasitestain:1,80,quark:crystal:1,30,srparasites:parasiterubbledense:1,100)
RB(4,40,3,srparasites:parasitestain:1,80,quark:crystal:1,30,srparasites:parasiterubbledense:1,100)
RB(5,40,3,srparasites:parasitestain:1,80,quark:crystal:1,30,srparasites:parasiterubbledense:1,100)
B(6,40,3,betternether:quartz_stained_glass:15)
B(1,40,4,betternether:quartz_stained_glass:15)
B(2,40,4,betternether:quartz_stained_glass:15)
B(3,40,4,betternether:quartz_stained_glass:15)
RB(4,40,4,srparasites:parasitestain:1,80,quark:crystal:1,30,srparasites:parasiterubbledense:1,100)
B(5,40,4,betternether:quartz_stained_glass:15)
B(2,40,5,betternether:quartz_stained_glass:15)
B(3,40,5,betternether:quartz_stained_glass:15)
B(4,40,5,betternether:quartz_stained_glass:15)
B(5,40,5,betternether:quartz_stained_glass:15)
B(1,41,0,betternether:quartz_stained_glass:15)
B(2,41,0,betternether:quartz_stained_glass:15)
B(3,41,0,betternether:quartz_stained_glass:15)
B(4,41,0,betternether:quartz_stained_glass:15)
B(1,41,1,betternether:quartz_stained_glass:15)
B(2,41,1,betternether:quartz_stained_glass:15)
RB(3,41,1,srparasites:parasitestain:1,80,quark:crystal:1,30,srparasites:parasiterubbledense:1,100)
B(4,41,1,betternether:quartz_stained_glass:15)
B(1,41,2,betternether:quartz_stained_glass:15)
B(2,41,2,betternether:quartz_stained_glass:15)
RB(3,41,2,srparasites:parasitestain:1,80,quark:crystal:1,30,srparasites:parasiterubbledense:1,100)
B(4,41,2,betternether:quartz_stained_glass:15)
B(5,41,2,betternether:quartz_stained_glass:15)
B(1,41,3,betternether:quartz_stained_glass:15)
RB(2,41,3,srparasites:parasitestain:1,80,quark:crystal:1,30,srparasites:parasiterubbledense:1,100)
RB(3,41,3,srparasites:parasitestain:1,80,quark:crystal:1,30,srparasites:parasiterubbledense:1,100)
RB(4,41,3,srparasites:parasitestain:1,80,quark:crystal:1,30,srparasites:parasiterubbledense:1,100)
B(5,41,3,betternether:quartz_stained_glass:15)
B(6,41,3,betternether:quartz_stained_glass:15)
B(1,41,4,betternether:quartz_stained_glass:15)
B(2,41,4,betternether:quartz_stained_glass:15)
B(3,41,4,betternether:quartz_stained_glass:15)
RB(4,41,4,srparasites:parasitestain:1,80,quark:crystal:1,30,srparasites:parasiterubbledense:1,100)
B(5,41,4,betternether:quartz_stained_glass:15)
B(2,41,5,betternether:quartz_stained_glass:15)
B(3,41,5,betternether:quartz_stained_glass:15)
B(4,41,5,betternether:quartz_stained_glass:15)
B(1,42,0,betternether:quartz_stained_glass:15)
B(2,42,0,betternether:quartz_stained_glass:15)
B(3,42,0,betternether:quartz_stained_glass:15)
B(4,42,0,betternether:quartz_stained_glass:15)
B(1,42,1,betternether:quartz_stained_glass:15)
B(2,42,1,betternether:quartz_stained_glass:15)
RB(3,42,1,srparasites:parasitestain:1,80,quark:crystal:1,30,srparasites:parasiterubbledense:1,100)
RB(4,42,1,srparasites:parasitestain:1,80,quark:crystal:1,30,srparasites:parasiterubbledense:1,100)
B(1,42,2,betternether:quartz_stained_glass:15)
B(2,42,2,betternether:quartz_stained_glass:15)
RB(3,42,2,srparasites:parasitestain:1,80,quark:crystal:1,30,srparasites:parasiterubbledense:1,100)
RB(4,42,2,srparasites:parasitestain:1,80,quark:crystal:1,30,srparasites:parasiterubbledense:1,100)
B(5,42,2,betternether:quartz_stained_glass:15)
B(1,42,3,betternether:quartz_stained_glass:15)
B(2,42,3,betternether:quartz_stained_glass:15)
RB(3,42,3,srparasites:parasitestain:1,80,quark:crystal:1,30,srparasites:parasiterubbledense:1,100)
RB(4,42,3,srparasites:parasitestain:1,80,quark:crystal:1,30,srparasites:parasiterubbledense:1,100)
B(5,42,3,betternether:quartz_stained_glass:15)
B(6,42,3,betternether:quartz_stained_glass:15)
B(1,42,4,betternether:quartz_stained_glass:15)
B(2,42,4,betternether:quartz_stained_glass:15)
B(3,42,4,betternether:quartz_stained_glass:15)
B(4,42,4,betternether:quartz_stained_glass:15)
B(2,42,5,betternether:quartz_stained_glass:15)
B(4,42,5,betternether:quartz_stained_glass:15)
B(1,43,0,betternether:quartz_stained_glass:15)
B(2,43,0,betternether:quartz_stained_glass:15)
B(3,43,0,betternether:quartz_stained_glass:15)
B(4,43,0,betternether:quartz_stained_glass:15)
B(1,43,1,betternether:quartz_stained_glass:15)
B(2,43,1,betternether:quartz_stained_glass:15)
RB(3,43,1,srparasites:parasitestain:1,80,quark:crystal:1,30,srparasites:parasiterubbledense:1,100)
B(4,43,1,betternether:quartz_stained_glass:15)
B(1,43,2,betternether:quartz_stained_glass:15)
B(2,43,2,betternether:quartz_stained_glass:15)
RB(3,43,2,srparasites:parasitestain:1,80,quark:crystal:1,30,srparasites:parasiterubbledense:1,100)
B(4,43,2,betternether:quartz_stained_glass:15)
B(1,43,3,betternether:quartz_stained_glass:15)
B(2,43,3,betternether:quartz_stained_glass:15)
B(3,43,3,betternether:quartz_stained_glass:15)
B(4,43,3,betternether:quartz_stained_glass:15)
B(5,43,3,betternether:quartz_stained_glass:15)
B(2,43,4,betternether:quartz_stained_glass:15)
B(3,43,4,betternether:quartz_stained_glass:15)
B(4,43,4,betternether:quartz_stained_glass:15)
B(1,44,0,betternether:quartz_stained_glass:15)
B(2,44,0,betternether:quartz_stained_glass:15)
B(3,44,0,betternether:quartz_stained_glass:15)
B(4,44,0,betternether:quartz_stained_glass:15)
B(1,44,1,betternether:quartz_stained_glass:15)
B(2,44,1,betternether:quartz_stained_glass:15)
RB(3,44,1,srparasites:parasitestain:1,80,quark:crystal:1,30,srparasites:parasiterubbledense:1,100)
B(4,44,1,betternether:quartz_stained_glass:15)
B(1,44,2,betternether:quartz_stained_glass:15)
B(2,44,2,betternether:quartz_stained_glass:15)
B(3,44,2,betternether:quartz_stained_glass:15)
B(4,44,2,betternether:quartz_stained_glass:15)
B(1,44,3,betternether:quartz_stained_glass:15)
B(2,44,3,betternether:quartz_stained_glass:15)
B(4,44,3,betternether:quartz_stained_glass:15)
B(1,45,0,betternether:quartz_stained_glass:15)
B(2,45,0,betternether:quartz_stained_glass:15)
B(3,45,0,betternether:quartz_stained_glass:15)
B(4,45,0,betternether:quartz_stained_glass:15)
B(1,45,1,betternether:quartz_stained_glass:15)
B(2,45,1,betternether:quartz_stained_glass:15)
B(3,45,1,betternether:quartz_stained_glass:15)
B(4,45,1,betternether:quartz_stained_glass:15)
B(1,45,2,betternether:quartz_stained_glass:15)
B(2,45,2,betternether:quartz_stained_glass:15)
B(3,45,2,betternether:quartz_stained_glass:15)
B(4,45,2,betternether:quartz_stained_glass:15)
B(1,45,3,betternether:quartz_stained_glass:15)
B(1,46,0,betternether:quartz_stained_glass:15)
B(2,46,0,betternether:quartz_stained_glass:15)
B(2,46,1,betternether:quartz_stained_glass:15)
B(3,46,1,betternether:quartz_stained_glass:15)
B(2,46,2,betternether:quartz_stained_glass:15)
B(2,47,1,betternether:quartz_stained_glass:15)

