
#######################################################################
# +-----------------------------------------------------------------+ #
# |                            BO4 object                           | #
# +-----------------------------------------------------------------+ #
#######################################################################

Author: NLBlackEagle

Description: No description given

SettingsMode: WriteDisable


#######################################################################
# +-----------------------------------------------------------------+ #
# |                          Main settings                          | #
# +-----------------------------------------------------------------+ #
#######################################################################

Frequency: 0

SpawnHeight: highestBlock

UseCenterForHighestBlock: true

##############################
# Height Limits for the BO4. #
##############################

MinHeight: 0

MaxHeight: 255

InheritBO3: 

InheritBO3Rotation: NORTH

OverrideChildSettings: true

OverrideParentHeight: false

CanOverride: true

BranchFrequency: 0

BranchFrequencyGroup: 

MustBeBelowOther: false

MustBeInside: 

CannotBeInside: 

ReplacesBO3: L4-M-CrossC0R0, L4-M-CrossC0R1, L4-M-CrossC0R2, L4-M-CrossC0R3, L4-M-CrossC1R0, L4-M-CrossC1R1, L4-M-CrossC1R2, L4-M-CrossC1R3, L4-M-CrossC2R0, L4-M-CrossC2R1, L4-M-CrossC2R2, L4-M-CrossC2R3, L4-M-CrossC3R0, L4-M-CrossC3R1, L4-M-CrossC3R2, L4-M-CrossC3R3, L4-M-Straigth-START_01-C0R0, L4-M-Straigth-START_01-C0R1, L4-M-Straigth-START_01-C1R0, L4-M-Straigth-START_01-C1R1, L4-M-Straigth-START_01-C2R0, L4-M-Straigth-START_01-C2R1, L4-M-Straigth-START_01-C3R0, L4-M-Straigth-START_01-C3R1, L4-M-Straigth-3CC0R0, L4-M-Straigth-3CC0R1, L4-M-Straigth-3CC0R2, L4-M-Straigth-3CC1R0, L4-M-Straigth-3CC1R1, L4-M-Straigth-3CC1R2, L4-M-Straigth-3CC2R0, L4-M-Straigth-3CC2R1, L4-M-Straigth-3CC2R2, L4-M-Straigth-3CC3R0, L4-M-Straigth-3CC3R1, L4-M-Straigth-3CC3R2, L4-M-Cross, skyscraper_2x2_01, skyscraper_2x2_02, skyscraper_2x2_03, skyscraper_2x2_04, skyscraper_2x2_05, skyscraper_3x3_01, skyscraper_3x3_02, skyscraper_3x3_03, L3-M-Straigth-2CC0R0, L3-M-Straigth-2CC0R1, L3-M-Straigth-2CC1R0, L3-M-Straigth-2CC1R1, L3-M-Straigth-2CC2R0, L3-M-Straigth-2CC2R1, L3-M-Straigth-2CC3R0, L3-M-Straigth-2CC3R1, L3-M-Straigth-3CC0R0, L3-M-Straigth-3CC0R1, L3-M-Straigth-3CC0R2, L3-M-Straigth-3CC1R0, L3-M-Straigth-3CC1R1, L3-M-Straigth-3CC1R2, L3-M-Straigth-3CC2R0, L3-M-Straigth-3CC2R1, L3-M-Straigth-3CC2R2, L3-M-Straigth-3CC3R0, L3-M-Straigth-3CC3R1, L3-M-Straigth-3CC3R2L4-M-CrossC0R0, L4-M-CrossC0R1, L4-M-CrossC0R2, L4-M-CrossC0R3, L4-M-CrossC1R0, L4-M-CrossC1R1, L4-M-CrossC1R2, L4-M-CrossC1R3, L4-M-CrossC2R0, L4-M-CrossC2R1, L4-M-CrossC2R2, L4-M-CrossC2R3, L4-M-CrossC3R0, L4-M-CrossC3R1, L4-M-CrossC3R2, L4-M-CrossC3R3, L4-M-Straigth-START_01-C0R0, L4-M-Straigth-START_01-C0R1, L4-M-Straigth-START_01-C1R0, L4-M-Straigth-START_01-C1R1, L4-M-Straigth-START_01-C2R0, L4-M-Straigth-START_01-C2R1, L4-M-Straigth-START_01-C3R0, L4-M-Straigth-START_01-C3R1, L4-M-Straigth-3CC0R0, L4-M-Straigth-3CC0R1, L4-M-Straigth-3CC0R2, L4-M-Straigth-3CC1R0, L4-M-Straigth-3CC1R1, L4-M-Straigth-3CC1R2, L4-M-Straigth-3CC2R0, L4-M-Straigth-3CC2R1, L4-M-Straigth-3CC2R2, L4-M-Straigth-3CC3R0, L4-M-Straigth-3CC3R1, L4-M-Straigth-3CC3R2, L4-M-Cross, skyscraper_2x2_01, skyscraper_2x2_02, skyscraper_2x2_03, skyscraper_2x2_04, skyscraper_2x2_05, skyscraper_3x3_01, skyscraper_3x3_02, skyscraper_3x3_03

MustBeInsideWorldBorders: false

CanSpawnOnWater: true

SpawnOnWaterOnly: false

SpawnUnderWater: false

SpawnAtWaterLevel: false

HeightOffset: 0

RemoveAir: false

ReplaceAbove: 

ReplaceBelow: 

ReplaceWithBiomeBlocks: false

ReplaceWithSurfaceBlock: GRASS

ReplaceWithGroundBlock: DIRT

ReplaceWithStoneBlock: eaglemixins:deepslate

SmoothRadius: 0

SmoothHeightOffset: 0

SmoothStartTop: false

SmoothStartWood: false

SmoothingSurfaceBlock: 

SmoothingGroundBlock: 

BO3Group: 

IsSpawnPoint: false

DoReplaceBlocks: false


#######################################################################
# +-----------------------------------------------------------------+ #
# |                              Blocks                             | #
# +-----------------------------------------------------------------+ #
#######################################################################

RandomBlock(-8,0,-7,CONCRETE:7,60,quark:iron_plate:1,20,STAINED_CLAY:12,15,STAINED_CLAY:15,5,AIR,7,IRON_BARS,12,CONCRETE:7,100)
RandomBlock(-8,0,-6,CONCRETE:7,60,quark:iron_plate:1,20,STAINED_CLAY:12,15,STAINED_CLAY:15,5,AIR,7,IRON_BARS,12,CONCRETE:7,100)
RandomBlock(-8,0,-5,CONCRETE:7,60,quark:iron_plate:1,20,STAINED_CLAY:12,15,STAINED_CLAY:15,5,AIR,7,IRON_BARS,12,CONCRETE:7,100)
RandomBlock(-8,0,-4,CONCRETE:7,60,quark:iron_plate:1,20,STAINED_CLAY:12,15,STAINED_CLAY:15,5,AIR,7,IRON_BARS,12,CONCRETE:7,100)
RandomBlock(-8,0,-3,CONCRETE:7,60,quark:iron_plate:1,20,STAINED_CLAY:12,15,STAINED_CLAY:15,5,AIR,7,IRON_BARS,12,CONCRETE:7,100)
RandomBlock(-8,0,-2,CONCRETE:7,60,quark:iron_plate:1,20,STAINED_CLAY:12,15,STAINED_CLAY:15,5,AIR,7,IRON_BARS,12,CONCRETE:7,100)
RandomBlock(-8,0,-1,CONCRETE:7,60,quark:iron_plate:1,20,STAINED_CLAY:12,15,STAINED_CLAY:15,5,AIR,7,IRON_BARS,12,CONCRETE:7,100)
RandomBlock(-8,0,0,CONCRETE:7,60,quark:iron_plate:1,20,STAINED_CLAY:12,15,STAINED_CLAY:15,5,AIR,7,IRON_BARS,12,CONCRETE:7,100)
RandomBlock(-8,0,1,CONCRETE:7,60,quark:iron_plate:1,20,STAINED_CLAY:12,15,STAINED_CLAY:15,5,AIR,7,IRON_BARS,12,CONCRETE:7,100)
RandomBlock(-8,0,2,CONCRETE:7,60,quark:iron_plate:1,20,STAINED_CLAY:12,15,STAINED_CLAY:15,5,AIR,7,IRON_BARS,12,CONCRETE:7,100)
RandomBlock(-8,0,3,CONCRETE:7,60,quark:iron_plate:1,20,STAINED_CLAY:12,15,STAINED_CLAY:15,5,AIR,7,IRON_BARS,12,CONCRETE:7,100)
RandomBlock(-8,0,4,CONCRETE:7,60,quark:iron_plate:1,20,STAINED_CLAY:12,15,STAINED_CLAY:15,5,AIR,7,IRON_BARS,12,CONCRETE:7,100)
RandomBlock(-8,0,5,CONCRETE:7,60,quark:iron_plate:1,20,STAINED_CLAY:12,15,STAINED_CLAY:15,5,AIR,7,IRON_BARS,12,CONCRETE:7,100)
RandomBlock(-8,0,6,CONCRETE:7,60,quark:iron_plate:1,20,STAINED_CLAY:12,15,STAINED_CLAY:15,5,AIR,7,IRON_BARS,12,CONCRETE:7,100)
RandomBlock(-8,0,7,CONCRETE:7,60,quark:iron_plate:1,20,STAINED_CLAY:12,15,STAINED_CLAY:15,5,AIR,7,IRON_BARS,12,CONCRETE:7,100)
RandomBlock(-8,0,8,CONCRETE:7,60,quark:iron_plate:1,20,STAINED_CLAY:12,15,STAINED_CLAY:15,5,AIR,7,IRON_BARS,12,CONCRETE:7,100)
Block(-8,1,-7,OBSIDIAN:0)
Block(-8,1,-6,OBSIDIAN:0)
Block(-8,1,-5,OBSIDIAN:0)
Block(-8,1,-4,OBSIDIAN:0)
Block(-8,1,-3,OBSIDIAN:0)
Block(-8,1,-2,OBSIDIAN:0)
Block(-8,1,-1,OBSIDIAN:0)
Block(-8,1,0,OBSIDIAN:0)
Block(-8,1,1,OBSIDIAN:0)
Block(-8,1,2,OBSIDIAN:0)
Block(-8,1,3,OBSIDIAN:0)
Block(-8,1,4,OBSIDIAN:0)
Block(-8,1,5,OBSIDIAN:0)
Block(-8,1,6,OBSIDIAN:0)
Block(-8,1,7,OBSIDIAN:0)
Block(-8,1,8,OBSIDIAN:0)
Block(-8,2,-7,OBSIDIAN:0)
Block(-8,2,-6,OBSIDIAN:0)
Block(-8,2,-5,OBSIDIAN:0)
Block(-8,2,-4,OBSIDIAN:0)
Block(-8,2,-3,OBSIDIAN:0)
Block(-8,2,-2,OBSIDIAN:0)
Block(-8,2,-1,OBSIDIAN:0)
Block(-8,2,0,OBSIDIAN:0)
Block(-8,2,1,OBSIDIAN:0)
Block(-8,2,2,OBSIDIAN:0)
Block(-8,2,3,OBSIDIAN:0)
Block(-8,2,4,OBSIDIAN:0)
Block(-8,2,5,OBSIDIAN:0)
Block(-8,2,6,OBSIDIAN:0)
Block(-8,2,7,OBSIDIAN:0)
Block(-8,2,8,OBSIDIAN:0)
Block(-8,3,-7,STATIONARY_LAVA:0)
Block(-8,3,-6,STATIONARY_LAVA:0)
Block(-8,3,-5,STATIONARY_LAVA:0)
Block(-8,3,-4,STATIONARY_LAVA:0)
Block(-8,3,-3,STATIONARY_LAVA:0)
Block(-8,3,-2,STATIONARY_LAVA:0)
Block(-8,3,-1,STATIONARY_LAVA:0)
Block(-8,3,0,STATIONARY_LAVA:0)
Block(-8,3,1,STATIONARY_LAVA:0)
Block(-8,3,2,STATIONARY_LAVA:0)
Block(-8,3,3,STATIONARY_LAVA:0)
Block(-8,3,4,STATIONARY_LAVA:0)
Block(-8,3,5,STATIONARY_LAVA:0)
Block(-8,3,6,STATIONARY_LAVA:0)
Block(-8,3,7,STATIONARY_LAVA:0)
Block(-8,3,8,STATIONARY_LAVA:0)
Block(-8,4,-7,OBSIDIAN:0)
Block(-8,4,-6,OBSIDIAN:0)
Block(-8,4,-5,OBSIDIAN:0)
Block(-8,4,-4,OBSIDIAN:0)
Block(-8,4,-3,OBSIDIAN:0)
Block(-8,4,-2,OBSIDIAN:0)
Block(-8,4,-1,OBSIDIAN:0)
Block(-8,4,0,OBSIDIAN:0)
Block(-8,4,1,OBSIDIAN:0)
Block(-8,4,2,OBSIDIAN:0)
Block(-8,4,3,OBSIDIAN:0)
Block(-8,4,4,OBSIDIAN:0)
Block(-8,4,5,OBSIDIAN:0)
Block(-8,4,6,OBSIDIAN:0)
Block(-8,4,7,OBSIDIAN:0)
Block(-8,4,8,OBSIDIAN:0)
Block(-8,5,-7,STATIONARY_LAVA:0)
Block(-8,5,-6,OBSIDIAN:0)
Block(-8,5,-5,OBSIDIAN:0)
Block(-8,5,-4,OBSIDIAN:0)
Block(-8,5,-3,OBSIDIAN:0)
Block(-8,5,-2,OBSIDIAN:0)
Block(-8,5,-1,OBSIDIAN:0)
Block(-8,5,0,OBSIDIAN:0)
Block(-8,5,1,IRON_PLATE:0)
RandomBlock(-8,5,2,emerald_ore,50,gold_ore,35,iron_ore,100)
RandomBlock(-8,5,3,GOLD_BLOCK,40,MOB_SPAWNER:0,../../DestructionLayers/Parasites/parasite_multi.nbt,20,CHEST:2,../../../../../Chests/Loot/simple_dungeon.nbt,10,CHEST:2,../../../../../Chests/Loot/gem_loot.nbt,10,CHEST:2,../../../../../Chests/Loot/desert_pyramid.nbt,5,CHEST:2,../../../../../Chests/Loot/jungle_temple.nbt,5,CHEST:2,../../../../../Chests/Loot/stronghold_library.nbt,10,CHEST:2,../../../../../Chests/Loot/woodland_mansion.nbt,10,CHEST:2,../../../../../Chests/Loot/end_city_treasure.nbt,10,CHEST:2,../../../../../Chests/RLCraft/IceAndFire/fire_dragon_roost_chest.nbt,5,CHEST:2,../../../../../Chests/lore/moderncity.nbt,5,chest:2,../../../../../Chests/RLCraft/IceAndFire/ice_dragon_roost_chest.nbt,5,chest:2,../../../../../Chests/lore/moderncity.nbt,2,chest:2,../../../../../Chests/RLCraft/IceAndFire/lightning_dragon_roost_chest.nbt,5,chest:2,../../../../../Chests/loot/moderncity_epic_loot.nbt,100)
RandomBlock(-8,5,4,GOLD_BLOCK,40,MOB_SPAWNER:0,../../DestructionLayers/Parasites/parasite_multi.nbt,20,CHEST:2,../../../../../Chests/Loot/simple_dungeon.nbt,10,CHEST:2,../../../../../Chests/Loot/gem_loot.nbt,10,CHEST:2,../../../../../Chests/Loot/desert_pyramid.nbt,5,CHEST:2,../../../../../Chests/Loot/jungle_temple.nbt,5,CHEST:2,../../../../../Chests/Loot/stronghold_library.nbt,10,CHEST:2,../../../../../Chests/Loot/woodland_mansion.nbt,10,CHEST:2,../../../../../Chests/Loot/end_city_treasure.nbt,10,CHEST:2,../../../../../Chests/RLCraft/IceAndFire/fire_dragon_roost_chest.nbt,5,CHEST:2,../../../../../Chests/lore/moderncity.nbt,5,chest:2,../../../../../Chests/RLCraft/IceAndFire/ice_dragon_roost_chest.nbt,5,chest:2,../../../../../Chests/lore/moderncity.nbt,2,chest:2,../../../../../Chests/RLCraft/IceAndFire/lightning_dragon_roost_chest.nbt,5,chest:2,../../../../../Chests/loot/moderncity_epic_loot.nbt,100)
Block(-8,5,5,IRON_PLATE:0)
Block(-8,5,6,IRON_PLATE:0)
Block(-8,5,7,IRON_PLATE:0)
Block(-8,5,8,IRON_PLATE:0)
Block(-8,6,-7,STATIONARY_LAVA:0)
Block(-8,6,-6,OBSIDIAN:0)
Block(-8,6,-5,OBSIDIAN:0)
Block(-8,6,-4,OBSIDIAN:0)
Block(-8,6,-3,OBSIDIAN:0)
Block(-8,6,-2,OBSIDIAN:0)
Block(-8,6,-1,OBSIDIAN:0)
Block(-8,6,0,OBSIDIAN:0)
Block(-8,6,2,STEP:8)
Block(-8,6,3,STEP:8)
Block(-8,6,4,STEP:8)
Block(-8,7,-7,STATIONARY_LAVA:0)
Block(-8,7,-6,OBSIDIAN:0)
Block(-8,7,-5,OBSIDIAN:0)
Block(-8,7,-4,OBSIDIAN:0)
Block(-8,7,-3,OBSIDIAN:0)
Block(-8,7,-2,OBSIDIAN:0)
Block(-8,7,-1,OBSIDIAN:0)
Block(-8,7,0,OBSIDIAN:0)
RandomBlock(-8,7,2,GOLD_BLOCK,40,MOB_SPAWNER:0,../../DestructionLayers/Parasites/parasite_multi.nbt,20,CHEST:2,../../../../../Chests/Loot/simple_dungeon.nbt,10,CHEST:2,../../../../../Chests/Loot/gem_loot.nbt,10,CHEST:2,../../../../../Chests/Loot/desert_pyramid.nbt,5,CHEST:2,../../../../../Chests/Loot/jungle_temple.nbt,5,CHEST:2,../../../../../Chests/Loot/stronghold_library.nbt,10,CHEST:2,../../../../../Chests/Loot/woodland_mansion.nbt,10,CHEST:2,../../../../../Chests/Loot/end_city_treasure.nbt,10,CHEST:2,../../../../../Chests/RLCraft/IceAndFire/fire_dragon_roost_chest.nbt,5,CHEST:2,../../../../../Chests/lore/moderncity.nbt,5,chest:2,../../../../../Chests/RLCraft/IceAndFire/ice_dragon_roost_chest.nbt,5,chest:2,../../../../../Chests/lore/moderncity.nbt,2,chest:2,../../../../../Chests/RLCraft/IceAndFire/lightning_dragon_roost_chest.nbt,5,chest:2,../../../../../Chests/loot/moderncity_epic_loot.nbt,100)
Block(-8,7,3,LAPIS_BLOCK:0)
RandomBlock(-8,7,4,GOLD_BLOCK,40,MOB_SPAWNER:0,../../DestructionLayers/Parasites/parasite_multi.nbt,20,CHEST:2,../../../../../Chests/Loot/simple_dungeon.nbt,10,CHEST:2,../../../../../Chests/Loot/gem_loot.nbt,10,CHEST:2,../../../../../Chests/Loot/desert_pyramid.nbt,5,CHEST:2,../../../../../Chests/Loot/jungle_temple.nbt,5,CHEST:2,../../../../../Chests/Loot/stronghold_library.nbt,10,CHEST:2,../../../../../Chests/Loot/woodland_mansion.nbt,10,CHEST:2,../../../../../Chests/Loot/end_city_treasure.nbt,10,CHEST:2,../../../../../Chests/RLCraft/IceAndFire/fire_dragon_roost_chest.nbt,5,CHEST:2,../../../../../Chests/lore/moderncity.nbt,5,chest:2,../../../../../Chests/RLCraft/IceAndFire/ice_dragon_roost_chest.nbt,5,chest:2,../../../../../Chests/lore/moderncity.nbt,2,chest:2,../../../../../Chests/RLCraft/IceAndFire/lightning_dragon_roost_chest.nbt,5,chest:2,../../../../../Chests/loot/moderncity_epic_loot.nbt,100)
Block(-8,8,-7,STATIONARY_LAVA:0)
Block(-8,8,-6,OBSIDIAN:0)
Block(-8,8,-5,OBSIDIAN:0)
Block(-8,8,-4,OBSIDIAN:0)
Block(-8,8,-3,OBSIDIAN:0)
Block(-8,8,-2,OBSIDIAN:0)
Block(-8,8,-1,OBSIDIAN:0)
Block(-8,8,0,OBSIDIAN:0)
Block(-8,8,2,STEP:8)
Block(-8,8,3,STEP:8)
Block(-8,8,4,STEP:8)
Block(-8,8,6,STEP:8)
Block(-8,8,7,STEP:8)
Block(-8,9,-7,STATIONARY_LAVA:0)
Block(-8,9,-6,OBSIDIAN:0)
Block(-8,9,-5,OBSIDIAN:0)
Block(-8,9,-4,OBSIDIAN:0)
Block(-8,9,-3,OBSIDIAN:0)
Block(-8,9,-2,OBSIDIAN:0)
Block(-8,9,-1,OBSIDIAN:0)
Block(-8,9,0,OBSIDIAN:0)
RandomBlock(-8,9,2,CHEST:2,../../../../../Chests/Loot/simple_dungeon.nbt,10,CHEST:2,../../../../../Chests/Loot/gem_loot.nbt,10,CHEST:2,../../../../../Chests/Loot/desert_pyramid.nbt,5,CHEST:2,../../../../../Chests/Loot/jungle_temple.nbt,5,CHEST:2,../../../../../Chests/Loot/stronghold_library.nbt,10,CHEST:2,../../../../../Chests/Loot/woodland_mansion.nbt,10,CHEST:2,../../../../../Chests/Loot/end_city_treasure.nbt,10,CHEST:2,../../../../../Chests/RLCraft/IceAndFire/fire_dragon_roost_chest.nbt,5,CHEST:2,../../../../../Chests/lore/moderncity.nbt,5,chest:2,../../../../../Chests/RLCraft/IceAndFire/ice_dragon_roost_chest.nbt,5,chest:2,../../../../../Chests/lore/moderncity.nbt,2,chest:2,../../../../../Chests/RLCraft/IceAndFire/lightning_dragon_roost_chest.nbt,5,chest:2,../../../../../Chests/loot/moderncity_epic_loot.nbt,100)
RandomBlock(-8,9,3,AIR:0,20,TNT:0,100)
RandomBlock(-8,9,4,GOLD_BLOCK,40,MOB_SPAWNER:0,../../DestructionLayers/Parasites/parasite_multi.nbt,20,CHEST:2,../../../../../Chests/Loot/simple_dungeon.nbt,10,CHEST:2,../../../../../Chests/Loot/gem_loot.nbt,10,CHEST:2,../../../../../Chests/Loot/desert_pyramid.nbt,5,CHEST:2,../../../../../Chests/Loot/jungle_temple.nbt,5,CHEST:2,../../../../../Chests/Loot/stronghold_library.nbt,10,CHEST:2,../../../../../Chests/Loot/woodland_mansion.nbt,10,CHEST:2,../../../../../Chests/Loot/end_city_treasure.nbt,10,CHEST:2,../../../../../Chests/RLCraft/IceAndFire/fire_dragon_roost_chest.nbt,5,CHEST:2,../../../../../Chests/lore/moderncity.nbt,5,chest:2,../../../../../Chests/RLCraft/IceAndFire/ice_dragon_roost_chest.nbt,5,chest:2,../../../../../Chests/lore/moderncity.nbt,2,chest:2,../../../../../Chests/RLCraft/IceAndFire/lightning_dragon_roost_chest.nbt,5,chest:2,../../../../../Chests/loot/moderncity_epic_loot.nbt,100)
RandomBlock(-8,9,6,AIR:0,20,TNT:0,100)
RandomBlock(-8,9,7,AIR:0,20,TNT:0,100)
Block(-8,10,-7,STATIONARY_LAVA:0)
Block(-8,10,-6,OBSIDIAN:0)
Block(-8,10,-5,OBSIDIAN:0)
Block(-8,10,-4,OBSIDIAN:0)
Block(-8,10,-3,OBSIDIAN:0)
Block(-8,10,-2,OBSIDIAN:0)
Block(-8,10,-1,OBSIDIAN:0)
Block(-8,10,0,OBSIDIAN:0)
Block(-8,10,1,STEP:8)
Block(-8,10,2,STEP:8)
Block(-8,10,3,STEP:8)
Block(-8,10,4,STEP:8)
Block(-8,10,5,STEP:8)
Block(-8,10,8,STEP:8)
Block(-8,11,-7,OBSIDIAN:0)
Block(-8,11,-6,OBSIDIAN:0)
Block(-8,11,-5,OBSIDIAN:0)
Block(-8,11,-4,OBSIDIAN:0)
Block(-8,11,-3,OBSIDIAN:0)
Block(-8,11,-2,OBSIDIAN:0)
Block(-8,11,-1,OBSIDIAN:0)
Block(-8,11,0,OBSIDIAN:0)
Block(-8,11,1,OBSIDIAN:0)
Block(-8,11,2,OBSIDIAN:0)
Block(-8,11,3,OBSIDIAN:0)
Block(-8,11,4,OBSIDIAN:0)
Block(-8,11,5,OBSIDIAN:0)
Block(-8,11,6,STAINED_GLASS:15)
Block(-8,11,7,STAINED_GLASS:15)
Block(-8,11,8,OBSIDIAN:0)
Block(-8,12,-7,STATIONARY_LAVA:0)
Block(-8,12,-6,STATIONARY_LAVA:0)
Block(-8,12,-5,STATIONARY_LAVA:0)
Block(-8,12,-4,STATIONARY_LAVA:0)
Block(-8,12,-3,STATIONARY_LAVA:0)
Block(-8,12,-2,STATIONARY_LAVA:0)
Block(-8,12,-1,STATIONARY_LAVA:0)
Block(-8,12,0,STATIONARY_LAVA:0)
Block(-8,12,1,STATIONARY_LAVA:0)
Block(-8,12,2,STATIONARY_LAVA:0)
Block(-8,12,3,STATIONARY_LAVA:0)
Block(-8,12,4,STATIONARY_LAVA:0)
Block(-8,12,5,STATIONARY_LAVA:0)
Block(-8,12,6,STATIONARY_LAVA:0)
Block(-8,12,7,STATIONARY_LAVA:0)
Block(-8,12,8,STATIONARY_LAVA:0)
Block(-8,13,-7,OBSIDIAN:0)
Block(-8,13,-6,OBSIDIAN:0)
Block(-8,13,-5,OBSIDIAN:0)
Block(-8,13,-4,OBSIDIAN:0)
Block(-8,13,-3,OBSIDIAN:0)
Block(-8,13,-2,OBSIDIAN:0)
Block(-8,13,-1,OBSIDIAN:0)
Block(-8,13,0,OBSIDIAN:0)
Block(-8,13,1,OBSIDIAN:0)
Block(-8,13,2,OBSIDIAN:0)
Block(-8,13,3,OBSIDIAN:0)
Block(-8,13,4,OBSIDIAN:0)
Block(-8,13,5,OBSIDIAN:0)
Block(-8,13,6,OBSIDIAN:0)
Block(-8,13,7,OBSIDIAN:0)
Block(-8,13,8,OBSIDIAN:0)
Block(-8,14,-7,OBSIDIAN:0)
Block(-8,14,-6,OBSIDIAN:0)
Block(-8,14,-5,OBSIDIAN:0)
Block(-8,14,-4,OBSIDIAN:0)
Block(-8,14,-3,OBSIDIAN:0)
Block(-8,14,-2,OBSIDIAN:0)
Block(-8,14,-1,OBSIDIAN:0)
Block(-8,14,0,OBSIDIAN:0)
Block(-8,14,1,OBSIDIAN:0)
Block(-8,14,2,OBSIDIAN:0)
Block(-8,14,3,OBSIDIAN:0)
Block(-8,14,4,OBSIDIAN:0)
Block(-8,14,5,OBSIDIAN:0)
Block(-8,14,6,OBSIDIAN:0)
Block(-8,14,7,OBSIDIAN:0)
Block(-8,14,8,OBSIDIAN:0)
Block(-8,15,-7,OBSIDIAN:0)
Block(-8,15,-6,OBSIDIAN:0)
Block(-8,15,-5,OBSIDIAN:0)
Block(-8,15,-4,OBSIDIAN:0)
Block(-8,15,-3,OBSIDIAN:0)
Block(-8,15,-2,OBSIDIAN:0)
Block(-8,15,-1,OBSIDIAN:0)
Block(-8,15,0,OBSIDIAN:0)
Block(-8,15,1,OBSIDIAN:0)
Block(-8,15,2,OBSIDIAN:0)
Block(-8,15,3,OBSIDIAN:0)
Block(-8,15,4,OBSIDIAN:0)
Block(-8,15,5,OBSIDIAN:0)
Block(-8,15,6,OBSIDIAN:0)
Block(-8,15,7,OBSIDIAN:0)
Block(-8,15,8,OBSIDIAN:0)
Block(-8,16,-7,OBSIDIAN:0)
Block(-8,16,-6,OBSIDIAN:0)
Block(-8,16,-5,OBSIDIAN:0)
Block(-8,16,-4,OBSIDIAN:0)
Block(-8,16,-3,OBSIDIAN:0)
Block(-8,16,-2,OBSIDIAN:0)
Block(-8,16,-1,OBSIDIAN:0)
Block(-8,16,0,OBSIDIAN:0)
Block(-8,16,1,OBSIDIAN:0)
Block(-8,16,2,OBSIDIAN:0)
Block(-8,16,3,OBSIDIAN:0)
Block(-8,16,4,OBSIDIAN:0)
Block(-8,16,5,OBSIDIAN:0)
Block(-8,16,6,OBSIDIAN:0)
Block(-8,16,7,OBSIDIAN:0)
Block(-8,16,8,OBSIDIAN:0)
RandomBlock(-8,17,-7,CONCRETE:7,60,quark:iron_plate:1,20,STAINED_CLAY:12,15,STAINED_CLAY:15,5,AIR,7,IRON_BARS,12,CONCRETE:7,100)
RandomBlock(-8,17,-6,CONCRETE:7,60,quark:iron_plate:1,20,STAINED_CLAY:12,15,STAINED_CLAY:15,5,AIR,7,IRON_BARS,12,CONCRETE:7,100)
RandomBlock(-8,17,-5,CONCRETE:7,60,quark:iron_plate:1,20,STAINED_CLAY:12,15,STAINED_CLAY:15,5,AIR,7,IRON_BARS,12,CONCRETE:7,100)
RandomBlock(-8,17,-4,CONCRETE:7,60,quark:iron_plate:1,20,STAINED_CLAY:12,15,STAINED_CLAY:15,5,AIR,7,IRON_BARS,12,CONCRETE:7,100)
RandomBlock(-8,17,-3,CONCRETE:7,60,quark:iron_plate:1,20,STAINED_CLAY:12,15,STAINED_CLAY:15,5,AIR,7,IRON_BARS,12,CONCRETE:7,100)
RandomBlock(-8,17,-2,CONCRETE:7,60,quark:iron_plate:1,20,STAINED_CLAY:12,15,STAINED_CLAY:15,5,AIR,7,IRON_BARS,12,CONCRETE:7,100)
RandomBlock(-8,17,-1,CONCRETE:7,60,quark:iron_plate:1,20,STAINED_CLAY:12,15,STAINED_CLAY:15,5,AIR,7,IRON_BARS,12,CONCRETE:7,100)
RandomBlock(-8,17,0,CONCRETE:7,60,quark:iron_plate:1,20,STAINED_CLAY:12,15,STAINED_CLAY:15,5,AIR,7,IRON_BARS,12,CONCRETE:7,100)
RandomBlock(-8,17,1,CONCRETE:7,60,quark:iron_plate:1,20,STAINED_CLAY:12,15,STAINED_CLAY:15,5,AIR,7,IRON_BARS,12,CONCRETE:7,100)
RandomBlock(-8,17,2,CONCRETE:7,60,quark:iron_plate:1,20,STAINED_CLAY:12,15,STAINED_CLAY:15,5,AIR,7,IRON_BARS,12,CONCRETE:7,100)
RandomBlock(-8,17,3,CONCRETE:7,60,quark:iron_plate:1,20,STAINED_CLAY:12,15,STAINED_CLAY:15,5,AIR,7,IRON_BARS,12,CONCRETE:7,100)
RandomBlock(-8,17,4,CONCRETE:7,60,quark:iron_plate:1,20,STAINED_CLAY:12,15,STAINED_CLAY:15,5,AIR,7,IRON_BARS,12,CONCRETE:7,100)
RandomBlock(-8,17,5,CONCRETE:7,60,quark:iron_plate:1,20,STAINED_CLAY:12,15,STAINED_CLAY:15,5,AIR,7,IRON_BARS,12,CONCRETE:7,100)
RandomBlock(-8,17,6,CONCRETE:7,60,quark:iron_plate:1,20,STAINED_CLAY:12,15,STAINED_CLAY:15,5,AIR,7,IRON_BARS,12,CONCRETE:7,100)
RandomBlock(-8,17,7,CONCRETE:7,60,quark:iron_plate:1,20,STAINED_CLAY:12,15,STAINED_CLAY:15,5,AIR,7,IRON_BARS,12,CONCRETE:7,100)
RandomBlock(-8,17,8,CONCRETE:7,60,quark:iron_plate:1,20,STAINED_CLAY:12,15,STAINED_CLAY:15,5,AIR,7,IRON_BARS,12,CONCRETE:7,100)
Block(-8,18,-7,CONCRETE:0)
Block(-8,18,-6,OBSIDIAN:0)
Block(-8,18,-4,DARK_OAK_FENCE_GATE:5)
RandomBlock(-8,18,-3,CONCRETE:7,60,quark:iron_plate:1,20,STAINED_CLAY:12,15,STAINED_CLAY:15,5,AIR,7,IRON_BARS,12,CONCRETE:7,100)
Block(-8,18,-2,OBSIDIAN:0)
Block(-8,18,-1,CONCRETE:0)
Block(-8,18,7,CONCRETE:0)
Block(-8,19,-7,CONCRETE:0)
Block(-8,19,-6,OBSIDIAN:0)
RandomBlock(-8,19,-3,CONCRETE:7,60,quark:iron_plate:1,20,STAINED_CLAY:12,15,STAINED_CLAY:15,5,AIR,7,IRON_BARS,12,CONCRETE:7,100)
Block(-8,19,-2,OBSIDIAN:0)
Block(-8,19,-1,CONCRETE:0)
Block(-8,19,0,CONCRETE:0)
Block(-8,19,1,CONCRETE:0)
Block(-8,19,2,CONCRETE:0)
Block(-8,19,3,CONCRETE:0)
Block(-8,19,4,CONCRETE:0)
Block(-8,19,5,CONCRETE:0)
Block(-8,19,6,CONCRETE:0)
Block(-8,19,7,CONCRETE:0)
Block(-8,20,-7,CONCRETE:0)
Block(-8,20,-6,OBSIDIAN:0)
Block(-8,20,-5,STEP:8)
Block(-8,20,-4,STEP:8)
RandomBlock(-8,20,-3,CONCRETE:7,60,quark:iron_plate:1,20,STAINED_CLAY:12,15,STAINED_CLAY:15,5,AIR,7,IRON_BARS,12,CONCRETE:7,100)
Block(-8,20,-2,OBSIDIAN:0)
Block(-8,20,-1,CONCRETE:0)
Block(-8,20,7,CONCRETE:0)
Block(-8,21,-7,CONCRETE:0)
Block(-8,21,-6,OBSIDIAN:0)
RandomBlock(-8,21,-5,CONCRETE:7,60,quark:iron_plate:1,20,STAINED_CLAY:12,15,STAINED_CLAY:15,5,AIR,7,IRON_BARS,12,CONCRETE:7,100)
RandomBlock(-8,21,-4,CONCRETE:7,60,quark:iron_plate:1,20,STAINED_CLAY:12,15,STAINED_CLAY:15,5,AIR,7,IRON_BARS,12,CONCRETE:7,100)
RandomBlock(-8,21,-3,CONCRETE:7,60,quark:iron_plate:1,20,STAINED_CLAY:12,15,STAINED_CLAY:15,5,AIR,7,IRON_BARS,12,CONCRETE:7,100)
Block(-8,21,-2,OBSIDIAN:0)
Block(-8,21,-1,CONCRETE:0)
Block(-8,21,7,CONCRETE:0)
Block(-8,21,8,SMOOTH_STAIRS:7)
Block(-8,22,-7,CONCRETE:0)
Block(-8,22,-6,OBSIDIAN:0)
Block(-8,22,-5,OBSIDIAN:0)
Block(-8,22,-4,OBSIDIAN:0)
Block(-8,22,-3,OBSIDIAN:0)
Block(-8,22,-2,OBSIDIAN:0)
Block(-8,22,-1,CONCRETE:0)
Block(-8,22,7,CONCRETE:0)
RandomBlock(-8,22,8,CONCRETE:7,60,quark:iron_plate:1,20,STAINED_CLAY:12,15,STAINED_CLAY:15,5,AIR,7,IRON_BARS,12,CONCRETE:7,100)
Block(-8,23,-7,CONCRETE:0)
Block(-8,23,-6,CONCRETE:0)
Block(-8,23,-5,CONCRETE:0)
Block(-8,23,-4,CONCRETE:0)
Block(-8,23,-3,CONCRETE:0)
Block(-8,23,-2,OBSIDIAN:0)
Block(-8,23,-1,CONCRETE:0)
Block(-8,23,0,CONCRETE:0)
Block(-8,23,6,CONCRETE:0)
Block(-8,23,7,CONCRETE:0)
Block(-8,23,8,OBSIDIAN:0)
Block(-8,24,-2,QUARTZ_STAIRS:2)
Block(-8,24,-1,CONCRETE:0)
Block(-8,24,0,CONCRETE:0)
Block(-8,24,1,CONCRETE:0)
Block(-8,24,2,CONCRETE:0)
Block(-8,24,3,CONCRETE:0)
Block(-8,24,4,CONCRETE:0)
Block(-8,24,5,CONCRETE:0)
Block(-8,24,6,CONCRETE:0)
Block(-8,24,7,CONCRETE:0)
Block(-8,24,8,CONCRETE:0)
Block(-8,25,-1,CONCRETE:0)
Block(-8,25,0,STAINED_GLASS_PANE:15)
Block(-8,25,1,STAINED_GLASS_PANE:15)
Block(-8,25,2,STAINED_GLASS_PANE:15)
Block(-8,25,3,STAINED_GLASS_PANE:15)
Block(-8,25,4,STAINED_GLASS_PANE:15)
Block(-8,25,5,STAINED_GLASS_PANE:15)
Block(-8,25,6,STAINED_GLASS_PANE:15)
Block(-8,25,7,CONCRETE:0)
Block(-8,26,-1,CONCRETE:0)
Block(-8,26,7,CONCRETE:0)
Block(-8,27,-1,CONCRETE:0)
Block(-8,27,7,CONCRETE:0)
Block(-8,28,-2,QUARTZ_STAIRS:6)
Block(-8,28,-1,CONCRETE:0)
Block(-8,28,7,CONCRETE:0)
Block(-8,29,-3,QUARTZ_STAIRS:6)
Block(-8,29,-2,CONCRETE:0)
Block(-8,29,-1,CONCRETE:0)
Block(-8,29,0,CONCRETE:0)
Block(-8,29,1,CONCRETE:0)
Block(-8,29,2,CONCRETE:0)
Block(-8,29,3,CONCRETE:0)
Block(-8,29,4,CONCRETE:0)
Block(-8,29,5,CONCRETE:0)
Block(-8,29,6,CONCRETE:0)
Block(-8,29,7,CONCRETE:0)
Block(-8,29,8,CONCRETE:0)
Block(-8,30,-3,COBBLE_WALL:0)
Block(-8,30,-2,CONCRETE:0)
Block(-8,30,-1,CONCRETE:0)
Block(-8,30,5,CONCRETE:0)
Block(-8,30,6,CARPET:15)
Block(-8,30,7,CARPET:15)
Block(-8,30,8,CARPET:15)
Block(-8,31,-6,STEP:15)
Block(-8,31,-5,STEP:15)
Block(-8,31,-4,STEP:15)
Block(-8,31,-3,STEP:15)
Block(-8,31,-2,CONCRETE:0)
Block(-8,31,-1,CONCRETE:0)
Block(-8,31,5,CONCRETE:0)
Block(-8,32,-2,CONCRETE:0)
Block(-8,32,-1,CONCRETE:0)
Block(-8,32,0,CONCRETE:0)
Block(-8,32,1,CONCRETE:0)
Block(-8,32,2,CONCRETE:0)
Block(-8,32,3,CONCRETE:0)
Block(-8,32,5,CONCRETE:0)
Block(-8,33,-3,QUARTZ_STAIRS:6)
Block(-8,33,-2,CONCRETE:0)
Block(-8,33,-1,CONCRETE:0)
Block(-8,33,0,CONCRETE:0)
Block(-8,33,1,CONCRETE:0)
Block(-8,33,2,CONCRETE:0)
Block(-8,33,3,CONCRETE:0)
Block(-8,33,4,CONCRETE:0)
Block(-8,33,5,CONCRETE:0)
Block(-8,33,6,CONCRETE:0)
Block(-8,33,7,CONCRETE:0)
Block(-8,33,8,CONCRETE:0)
Block(-8,34,-3,COBBLE_WALL:0)
Block(-8,34,-2,CONCRETE:0)
Block(-8,34,0,CONCRETE:0)
Block(-8,34,1,CONCRETE:0)
Block(-8,35,-2,CONCRETE:0)
Block(-8,35,0,CONCRETE:0)
Block(-8,35,1,CONCRETE:0)
Block(-8,36,-2,CONCRETE:0)
Block(-8,36,0,CONCRETE:0)
Block(-8,37,-2,CONCRETE:0)
Block(-8,37,0,CONCRETE:0)
Block(-8,38,-2,CONCRETE:0)
Block(-8,38,0,CONCRETE:0)
Block(-8,38,4,STEP:15)
Block(-8,38,7,CONCRETE:0)
Block(-8,39,-2,QUARTZ_STAIRS:2)
Block(-8,39,-1,CONCRETE:0)
Block(-8,39,0,CONCRETE:0)
Block(-8,39,2,CONCRETE:0)
Block(-8,39,4,CONCRETE:0)
Block(-8,39,7,QUARTZ_STAIRS:1)
Block(-8,40,-1,STEP:7)
Block(-8,40,0,CONCRETE:0)
Block(-8,40,2,STEP:7)
Block(-8,40,4,COBBLE_WALL:0)
Block(-8,41,0,COBBLE_WALL:0)
RandomBlock(-7,0,-7,CONCRETE:7,60,quark:iron_plate:1,20,STAINED_CLAY:12,15,STAINED_CLAY:15,5,AIR,7,IRON_BARS,12,CONCRETE:7,100)
RandomBlock(-7,0,-6,CONCRETE:7,60,quark:iron_plate:1,20,STAINED_CLAY:12,15,STAINED_CLAY:15,5,AIR,7,IRON_BARS,12,CONCRETE:7,100)
RandomBlock(-7,0,-5,CONCRETE:7,60,quark:iron_plate:1,20,STAINED_CLAY:12,15,STAINED_CLAY:15,5,AIR,7,IRON_BARS,12,CONCRETE:7,100)
RandomBlock(-7,0,-4,CONCRETE:7,60,quark:iron_plate:1,20,STAINED_CLAY:12,15,STAINED_CLAY:15,5,AIR,7,IRON_BARS,12,CONCRETE:7,100)
RandomBlock(-7,0,-3,CONCRETE:7,60,quark:iron_plate:1,20,STAINED_CLAY:12,15,STAINED_CLAY:15,5,AIR,7,IRON_BARS,12,CONCRETE:7,100)
RandomBlock(-7,0,-2,CONCRETE:7,60,quark:iron_plate:1,20,STAINED_CLAY:12,15,STAINED_CLAY:15,5,AIR,7,IRON_BARS,12,CONCRETE:7,100)
RandomBlock(-7,0,-1,CONCRETE:7,60,quark:iron_plate:1,20,STAINED_CLAY:12,15,STAINED_CLAY:15,5,AIR,7,IRON_BARS,12,CONCRETE:7,100)
RandomBlock(-7,0,0,CONCRETE:7,60,quark:iron_plate:1,20,STAINED_CLAY:12,15,STAINED_CLAY:15,5,AIR,7,IRON_BARS,12,CONCRETE:7,100)
RandomBlock(-7,0,1,CONCRETE:7,60,quark:iron_plate:1,20,STAINED_CLAY:12,15,STAINED_CLAY:15,5,AIR,7,IRON_BARS,12,CONCRETE:7,100)
RandomBlock(-7,0,2,CONCRETE:7,60,quark:iron_plate:1,20,STAINED_CLAY:12,15,STAINED_CLAY:15,5,AIR,7,IRON_BARS,12,CONCRETE:7,100)
RandomBlock(-7,0,3,CONCRETE:7,60,quark:iron_plate:1,20,STAINED_CLAY:12,15,STAINED_CLAY:15,5,AIR,7,IRON_BARS,12,CONCRETE:7,100)
RandomBlock(-7,0,4,CONCRETE:7,60,quark:iron_plate:1,20,STAINED_CLAY:12,15,STAINED_CLAY:15,5,AIR,7,IRON_BARS,12,CONCRETE:7,100)
RandomBlock(-7,0,5,CONCRETE:7,60,quark:iron_plate:1,20,STAINED_CLAY:12,15,STAINED_CLAY:15,5,AIR,7,IRON_BARS,12,CONCRETE:7,100)
RandomBlock(-7,0,6,CONCRETE:7,60,quark:iron_plate:1,20,STAINED_CLAY:12,15,STAINED_CLAY:15,5,AIR,7,IRON_BARS,12,CONCRETE:7,100)
RandomBlock(-7,0,7,CONCRETE:7,60,quark:iron_plate:1,20,STAINED_CLAY:12,15,STAINED_CLAY:15,5,AIR,7,IRON_BARS,12,CONCRETE:7,100)
RandomBlock(-7,0,8,CONCRETE:7,60,quark:iron_plate:1,20,STAINED_CLAY:12,15,STAINED_CLAY:15,5,AIR,7,IRON_BARS,12,CONCRETE:7,100)
Block(-7,1,-7,OBSIDIAN:0)
Block(-7,1,-6,OBSIDIAN:0)
Block(-7,1,-5,OBSIDIAN:0)
Block(-7,1,-4,OBSIDIAN:0)
Block(-7,1,-3,OBSIDIAN:0)
Block(-7,1,-2,OBSIDIAN:0)
Block(-7,1,-1,OBSIDIAN:0)
Block(-7,1,0,OBSIDIAN:0)
Block(-7,1,1,OBSIDIAN:0)
Block(-7,1,2,OBSIDIAN:0)
Block(-7,1,3,OBSIDIAN:0)
Block(-7,1,4,OBSIDIAN:0)
Block(-7,1,5,OBSIDIAN:0)
Block(-7,1,6,OBSIDIAN:0)
Block(-7,1,7,OBSIDIAN:0)
Block(-7,1,8,OBSIDIAN:0)
Block(-7,2,-7,OBSIDIAN:0)
Block(-7,2,-6,OBSIDIAN:0)
Block(-7,2,-5,OBSIDIAN:0)
Block(-7,2,-4,OBSIDIAN:0)
Block(-7,2,-3,OBSIDIAN:0)
Block(-7,2,-2,OBSIDIAN:0)
Block(-7,2,-1,OBSIDIAN:0)
Block(-7,2,0,OBSIDIAN:0)
Block(-7,2,1,OBSIDIAN:0)
Block(-7,2,2,OBSIDIAN:0)
Block(-7,2,3,OBSIDIAN:0)
Block(-7,2,4,OBSIDIAN:0)
Block(-7,2,5,OBSIDIAN:0)
Block(-7,2,6,OBSIDIAN:0)
Block(-7,2,7,OBSIDIAN:0)
Block(-7,2,8,OBSIDIAN:0)
Block(-7,3,-7,STATIONARY_LAVA:0)
Block(-7,3,-6,STATIONARY_LAVA:0)
Block(-7,3,-5,STATIONARY_LAVA:0)
Block(-7,3,-4,STATIONARY_LAVA:0)
Block(-7,3,-3,STATIONARY_LAVA:0)
Block(-7,3,-2,STATIONARY_LAVA:0)
Block(-7,3,-1,STATIONARY_LAVA:0)
Block(-7,3,0,STATIONARY_LAVA:0)
Block(-7,3,1,STATIONARY_LAVA:0)
Block(-7,3,2,STATIONARY_LAVA:0)
Block(-7,3,3,STATIONARY_LAVA:0)
Block(-7,3,4,STATIONARY_LAVA:0)
Block(-7,3,5,STATIONARY_LAVA:0)
Block(-7,3,6,STATIONARY_LAVA:0)
Block(-7,3,7,STATIONARY_LAVA:0)
Block(-7,3,8,STATIONARY_LAVA:0)
Block(-7,4,-7,OBSIDIAN:0)
Block(-7,4,-6,OBSIDIAN:0)
Block(-7,4,-5,OBSIDIAN:0)
Block(-7,4,-4,OBSIDIAN:0)
Block(-7,4,-3,OBSIDIAN:0)
Block(-7,4,-2,OBSIDIAN:0)
Block(-7,4,-1,OBSIDIAN:0)
Block(-7,4,0,OBSIDIAN:0)
Block(-7,4,1,OBSIDIAN:0)
Block(-7,4,2,OBSIDIAN:0)
Block(-7,4,3,OBSIDIAN:0)
Block(-7,4,4,OBSIDIAN:0)
Block(-7,4,5,OBSIDIAN:0)
Block(-7,4,6,OBSIDIAN:0)
Block(-7,4,7,OBSIDIAN:0)
Block(-7,4,8,OBSIDIAN:0)
Block(-7,5,-7,STATIONARY_LAVA:0)
Block(-7,5,-6,OBSIDIAN:0)
Block(-7,5,-5,OBSIDIAN:0)
Block(-7,5,-4,OBSIDIAN:0)
Block(-7,5,-3,OBSIDIAN:0)
Block(-7,5,-2,OBSIDIAN:0)
Block(-7,5,-1,OBSIDIAN:0)
Block(-7,5,0,OBSIDIAN:0)
Block(-7,5,1,IRON_PLATE:0)
RandomBlock(-7,5,2,CHEST:2,../../../../../Chests/Loot/simple_dungeon.nbt,10,CHEST:2,../../../../../Chests/Loot/gem_loot.nbt,10,CHEST:2,../../../../../Chests/Loot/desert_pyramid.nbt,5,CHEST:2,../../../../../Chests/Loot/jungle_temple.nbt,5,CHEST:2,../../../../../Chests/Loot/stronghold_library.nbt,10,CHEST:2,../../../../../Chests/Loot/woodland_mansion.nbt,10,CHEST:2,../../../../../Chests/Loot/end_city_treasure.nbt,10,CHEST:2,../../../../../Chests/RLCraft/IceAndFire/fire_dragon_roost_chest.nbt,5,CHEST:2,../../../../../Chests/lore/moderncity.nbt,5,chest:2,../../../../../Chests/RLCraft/IceAndFire/ice_dragon_roost_chest.nbt,5,chest:2,../../../../../Chests/lore/moderncity.nbt,2,chest:2,../../../../../Chests/RLCraft/IceAndFire/lightning_dragon_roost_chest.nbt,5,chest:2,../../../../../Chests/loot/moderncity_epic_loot.nbt,100)
RandomBlock(-7,5,3,AIR:0,20,TNT:0,100)
RandomBlock(-7,5,4,CHEST:3,../../../../../Chests/Loot/simple_dungeon.nbt,10,CHEST:3,../../../../../Chests/Loot/gem_loot.nbt,10,CHEST:3,../../../../../Chests/Loot/desert_pyramid.nbt,5,CHEST:3,../../../../../Chests/Loot/jungle_temple.nbt,5,CHEST:3,../../../../../Chests/Loot/stronghold_library.nbt,10,CHEST:3,../../../../../Chests/Loot/woodland_mansion.nbt,10,CHEST:3,../../../../../Chests/Loot/end_city_treasure.nbt,10,CHEST:3,../../../../../Chests/RLCraft/IceAndFire/fire_dragon_roost_chest.nbt,5,CHEST:3,../../../../../Chests/lore/moderncity.nbt,5,chest:3,../../../../../Chests/RLCraft/IceAndFire/ice_dragon_roost_chest.nbt,5,chest:3,../../../../../Chests/lore/moderncity.nbt,2,chest:3,../../../../../Chests/RLCraft/IceAndFire/lightning_dragon_roost_chest.nbt,5,chest:3,../../../../../Chests/loot/moderncity_epic_loot.nbt,100)
Block(-7,5,5,IRON_PLATE:0)
Block(-7,5,6,IRON_PLATE:0)
Block(-7,5,7,IRON_PLATE:0)
Block(-7,5,8,IRON_PLATE:0)
Block(-7,6,-7,STATIONARY_LAVA:0)
Block(-7,6,-6,OBSIDIAN:0)
Block(-7,6,-5,OBSIDIAN:0)
Block(-7,6,-4,OBSIDIAN:0)
Block(-7,6,-3,OBSIDIAN:0)
Block(-7,6,-2,OBSIDIAN:0)
Block(-7,6,-1,OBSIDIAN:0)
Block(-7,6,0,OBSIDIAN:0)
Block(-7,6,2,STEP:8)
Block(-7,6,3,STEP:8)
Block(-7,6,4,STEP:8)
Block(-7,7,-7,STATIONARY_LAVA:0)
Block(-7,7,-6,OBSIDIAN:0)
Block(-7,7,-5,OBSIDIAN:0)
Block(-7,7,-4,OBSIDIAN:0)
Block(-7,7,-3,OBSIDIAN:0)
Block(-7,7,-2,OBSIDIAN:0)
Block(-7,7,-1,OBSIDIAN:0)
Block(-7,7,0,OBSIDIAN:0)
Block(-7,7,2,GOLD_PLATE:0)
RandomBlock(-7,7,3,AIR:0,20,TNT:0,100)
Block(-7,7,4,GOLD_BLOCK:0)
Block(-7,8,-7,STATIONARY_LAVA:0)
Block(-7,8,-6,OBSIDIAN:0)
Block(-7,8,-5,OBSIDIAN:0)
Block(-7,8,-4,OBSIDIAN:0)
Block(-7,8,-3,OBSIDIAN:0)
Block(-7,8,-2,OBSIDIAN:0)
Block(-7,8,-1,OBSIDIAN:0)
Block(-7,8,0,OBSIDIAN:0)
Block(-7,8,2,STEP:8)
Block(-7,8,3,STEP:8)
Block(-7,8,4,STEP:8)
Block(-7,8,6,STEP:8)
Block(-7,8,7,STEP:8)
Block(-7,9,-7,STATIONARY_LAVA:0)
Block(-7,9,-6,OBSIDIAN:0)
Block(-7,9,-5,OBSIDIAN:0)
Block(-7,9,-4,OBSIDIAN:0)
Block(-7,9,-3,OBSIDIAN:0)
Block(-7,9,-2,OBSIDIAN:0)
Block(-7,9,-1,OBSIDIAN:0)
Block(-7,9,0,OBSIDIAN:0)
RandomBlock(-7,9,2,GOLD_BLOCK,40,MOB_SPAWNER:0,../../DestructionLayers/Parasites/parasite_multi.nbt,20,CHEST:2,../../../../../Chests/Loot/simple_dungeon.nbt,10,CHEST:2,../../../../../Chests/Loot/gem_loot.nbt,10,CHEST:2,../../../../../Chests/Loot/desert_pyramid.nbt,5,CHEST:2,../../../../../Chests/Loot/jungle_temple.nbt,5,CHEST:2,../../../../../Chests/Loot/stronghold_library.nbt,10,CHEST:2,../../../../../Chests/Loot/woodland_mansion.nbt,10,CHEST:2,../../../../../Chests/Loot/end_city_treasure.nbt,10,CHEST:2,../../../../../Chests/RLCraft/IceAndFire/fire_dragon_roost_chest.nbt,5,CHEST:2,../../../../../Chests/lore/moderncity.nbt,5,chest:2,../../../../../Chests/RLCraft/IceAndFire/ice_dragon_roost_chest.nbt,5,chest:2,../../../../../Chests/lore/moderncity.nbt,2,chest:2,../../../../../Chests/RLCraft/IceAndFire/lightning_dragon_roost_chest.nbt,5,chest:2,../../../../../Chests/loot/moderncity_epic_loot.nbt,100)
RandomBlock(-7,9,3,AIR:0,20,TNT:0,100)
RandomBlock(-7,9,4,CHEST:3,../../../../../Chests/Loot/simple_dungeon.nbt,10,CHEST:3,../../../../../Chests/Loot/gem_loot.nbt,10,CHEST:3,../../../../../Chests/Loot/desert_pyramid.nbt,5,CHEST:3,../../../../../Chests/Loot/jungle_temple.nbt,5,CHEST:3,../../../../../Chests/Loot/stronghold_library.nbt,10,CHEST:3,../../../../../Chests/Loot/woodland_mansion.nbt,10,CHEST:3,../../../../../Chests/Loot/end_city_treasure.nbt,10,CHEST:3,../../../../../Chests/RLCraft/IceAndFire/fire_dragon_roost_chest.nbt,5,CHEST:3,../../../../../Chests/lore/moderncity.nbt,5,chest:3,../../../../../Chests/RLCraft/IceAndFire/ice_dragon_roost_chest.nbt,5,chest:3,../../../../../Chests/lore/moderncity.nbt,2,chest:3,../../../../../Chests/RLCraft/IceAndFire/lightning_dragon_roost_chest.nbt,5,chest:3,../../../../../Chests/loot/moderncity_epic_loot.nbt,100)
Block(-7,10,-7,STATIONARY_LAVA:0)
Block(-7,10,-6,OBSIDIAN:0)
Block(-7,10,-5,OBSIDIAN:0)
Block(-7,10,-4,OBSIDIAN:0)
Block(-7,10,-3,OBSIDIAN:0)
Block(-7,10,-2,OBSIDIAN:0)
Block(-7,10,-1,OBSIDIAN:0)
Block(-7,10,0,OBSIDIAN:0)
Block(-7,10,1,STEP:8)
Block(-7,10,2,STEP:8)
Block(-7,10,3,STEP:8)
Block(-7,10,4,STEP:8)
Block(-7,10,5,STEP:8)
Block(-7,10,8,STEP:8)
Block(-7,11,-7,OBSIDIAN:0)
Block(-7,11,-6,OBSIDIAN:0)
Block(-7,11,-5,OBSIDIAN:0)
Block(-7,11,-4,OBSIDIAN:0)
Block(-7,11,-3,OBSIDIAN:0)
Block(-7,11,-2,OBSIDIAN:0)
Block(-7,11,-1,OBSIDIAN:0)
Block(-7,11,0,OBSIDIAN:0)
Block(-7,11,1,OBSIDIAN:0)
Block(-7,11,2,OBSIDIAN:0)
Block(-7,11,3,OBSIDIAN:0)
Block(-7,11,4,OBSIDIAN:0)
Block(-7,11,5,OBSIDIAN:0)
Block(-7,11,6,STAINED_GLASS:15)
Block(-7,11,7,STAINED_GLASS:15)
Block(-7,11,8,OBSIDIAN:0)
Block(-7,12,-7,STATIONARY_LAVA:0)
Block(-7,12,-6,STATIONARY_LAVA:0)
Block(-7,12,-5,STATIONARY_LAVA:0)
Block(-7,12,-4,STATIONARY_LAVA:0)
Block(-7,12,-3,STATIONARY_LAVA:0)
Block(-7,12,-2,STATIONARY_LAVA:0)
Block(-7,12,-1,STATIONARY_LAVA:0)
Block(-7,12,0,STATIONARY_LAVA:0)
Block(-7,12,1,STATIONARY_LAVA:0)
Block(-7,12,2,STATIONARY_LAVA:0)
Block(-7,12,3,STATIONARY_LAVA:0)
Block(-7,12,4,STATIONARY_LAVA:0)
Block(-7,12,5,STATIONARY_LAVA:0)
Block(-7,12,6,STATIONARY_LAVA:0)
Block(-7,12,7,STATIONARY_LAVA:0)
Block(-7,12,8,STATIONARY_LAVA:0)
Block(-7,13,-7,OBSIDIAN:0)
Block(-7,13,-6,OBSIDIAN:0)
Block(-7,13,-5,OBSIDIAN:0)
Block(-7,13,-4,OBSIDIAN:0)
Block(-7,13,-3,OBSIDIAN:0)
Block(-7,13,-2,OBSIDIAN:0)
Block(-7,13,-1,OBSIDIAN:0)
Block(-7,13,0,OBSIDIAN:0)
Block(-7,13,1,OBSIDIAN:0)
Block(-7,13,2,OBSIDIAN:0)
Block(-7,13,3,OBSIDIAN:0)
Block(-7,13,4,OBSIDIAN:0)
Block(-7,13,5,OBSIDIAN:0)
Block(-7,13,6,OBSIDIAN:0)
Block(-7,13,7,OBSIDIAN:0)
Block(-7,13,8,OBSIDIAN:0)
Block(-7,14,-7,OBSIDIAN:0)
Block(-7,14,-6,OBSIDIAN:0)
Block(-7,14,-5,OBSIDIAN:0)
Block(-7,14,-4,OBSIDIAN:0)
Block(-7,14,-3,OBSIDIAN:0)
Block(-7,14,-2,OBSIDIAN:0)
Block(-7,14,-1,OBSIDIAN:0)
Block(-7,14,0,OBSIDIAN:0)
Block(-7,14,1,OBSIDIAN:0)
Block(-7,14,2,OBSIDIAN:0)
Block(-7,14,3,OBSIDIAN:0)
Block(-7,14,4,OBSIDIAN:0)
Block(-7,14,5,OBSIDIAN:0)
Block(-7,14,6,OBSIDIAN:0)
Block(-7,14,7,OBSIDIAN:0)
Block(-7,14,8,OBSIDIAN:0)
Block(-7,15,-7,OBSIDIAN:0)
Block(-7,15,-6,OBSIDIAN:0)
Block(-7,15,-5,OBSIDIAN:0)
Block(-7,15,-4,OBSIDIAN:0)
Block(-7,15,-3,OBSIDIAN:0)
Block(-7,15,-2,OBSIDIAN:0)
Block(-7,15,-1,OBSIDIAN:0)
Block(-7,15,0,OBSIDIAN:0)
Block(-7,15,1,OBSIDIAN:0)
Block(-7,15,2,OBSIDIAN:0)
Block(-7,15,3,OBSIDIAN:0)
Block(-7,15,4,OBSIDIAN:0)
Block(-7,15,5,OBSIDIAN:0)
Block(-7,15,6,OBSIDIAN:0)
Block(-7,15,7,OBSIDIAN:0)
Block(-7,15,8,OBSIDIAN:0)
Block(-7,16,-7,OBSIDIAN:0)
Block(-7,16,-6,OBSIDIAN:0)
Block(-7,16,-5,OBSIDIAN:0)
Block(-7,16,-4,OBSIDIAN:0)
Block(-7,16,-3,OBSIDIAN:0)
Block(-7,16,-2,OBSIDIAN:0)
Block(-7,16,-1,OBSIDIAN:0)
Block(-7,16,0,OBSIDIAN:0)
Block(-7,16,1,OBSIDIAN:0)
Block(-7,16,2,OBSIDIAN:0)
Block(-7,16,3,OBSIDIAN:0)
Block(-7,16,4,OBSIDIAN:0)
Block(-7,16,5,OBSIDIAN:0)
Block(-7,16,6,OBSIDIAN:0)
Block(-7,16,7,OBSIDIAN:0)
Block(-7,16,8,OBSIDIAN:0)
RandomBlock(-7,17,-7,CONCRETE:7,60,quark:iron_plate:1,20,STAINED_CLAY:12,15,STAINED_CLAY:15,5,AIR,7,IRON_BARS,12,CONCRETE:7,100)
RandomBlock(-7,17,-6,CONCRETE:7,60,quark:iron_plate:1,20,STAINED_CLAY:12,15,STAINED_CLAY:15,5,AIR,7,IRON_BARS,12,CONCRETE:7,100)
RandomBlock(-7,17,-5,CONCRETE:7,60,quark:iron_plate:1,20,STAINED_CLAY:12,15,STAINED_CLAY:15,5,AIR,7,IRON_BARS,12,CONCRETE:7,100)
RandomBlock(-7,17,-4,CONCRETE:7,60,quark:iron_plate:1,20,STAINED_CLAY:12,15,STAINED_CLAY:15,5,AIR,7,IRON_BARS,12,CONCRETE:7,100)
RandomBlock(-7,17,-3,CONCRETE:7,60,quark:iron_plate:1,20,STAINED_CLAY:12,15,STAINED_CLAY:15,5,AIR,7,IRON_BARS,12,CONCRETE:7,100)
RandomBlock(-7,17,-2,CONCRETE:7,60,quark:iron_plate:1,20,STAINED_CLAY:12,15,STAINED_CLAY:15,5,AIR,7,IRON_BARS,12,CONCRETE:7,100)
RandomBlock(-7,17,-1,CONCRETE:7,60,quark:iron_plate:1,20,STAINED_CLAY:12,15,STAINED_CLAY:15,5,AIR,7,IRON_BARS,12,CONCRETE:7,100)
RandomBlock(-7,17,0,CONCRETE:7,60,quark:iron_plate:1,20,STAINED_CLAY:12,15,STAINED_CLAY:15,5,AIR,7,IRON_BARS,12,CONCRETE:7,100)
RandomBlock(-7,17,1,CONCRETE:7,60,quark:iron_plate:1,20,STAINED_CLAY:12,15,STAINED_CLAY:15,5,AIR,7,IRON_BARS,12,CONCRETE:7,100)
RandomBlock(-7,17,2,CONCRETE:7,60,quark:iron_plate:1,20,STAINED_CLAY:12,15,STAINED_CLAY:15,5,AIR,7,IRON_BARS,12,CONCRETE:7,100)
RandomBlock(-7,17,3,CONCRETE:7,60,quark:iron_plate:1,20,STAINED_CLAY:12,15,STAINED_CLAY:15,5,AIR,7,IRON_BARS,12,CONCRETE:7,100)
RandomBlock(-7,17,4,CONCRETE:7,60,quark:iron_plate:1,20,STAINED_CLAY:12,15,STAINED_CLAY:15,5,AIR,7,IRON_BARS,12,CONCRETE:7,100)
RandomBlock(-7,17,5,CONCRETE:7,60,quark:iron_plate:1,20,STAINED_CLAY:12,15,STAINED_CLAY:15,5,AIR,7,IRON_BARS,12,CONCRETE:7,100)
RandomBlock(-7,17,6,CONCRETE:7,60,quark:iron_plate:1,20,STAINED_CLAY:12,15,STAINED_CLAY:15,5,AIR,7,IRON_BARS,12,CONCRETE:7,100)
RandomBlock(-7,17,7,CONCRETE:7,60,quark:iron_plate:1,20,STAINED_CLAY:12,15,STAINED_CLAY:15,5,AIR,7,IRON_BARS,12,CONCRETE:7,100)
RandomBlock(-7,17,8,CONCRETE:7,60,quark:iron_plate:1,20,STAINED_CLAY:12,15,STAINED_CLAY:15,5,AIR,7,IRON_BARS,12,CONCRETE:7,100)
Block(-7,18,-7,CONCRETE:0)
Block(-7,18,-6,OBSIDIAN:0)
RandomBlock(-7,18,-3,CONCRETE:7,60,quark:iron_plate:1,20,STAINED_CLAY:12,15,STAINED_CLAY:15,5,AIR,7,IRON_BARS,12,CONCRETE:7,100)
Block(-7,18,-2,OBSIDIAN:0)
Block(-7,18,-1,STAINED_GLASS_PANE:15)
Block(-7,18,1,QUARTZ_STAIRS:4)
Block(-7,18,2,QUARTZ_STAIRS:4)
Block(-7,18,7,STAINED_GLASS_PANE:15)
Block(-7,19,-7,CONCRETE:0)
Block(-7,19,-6,OBSIDIAN:0)
RandomBlock(-7,19,-3,CONCRETE:7,60,quark:iron_plate:1,20,STAINED_CLAY:12,15,STAINED_CLAY:15,5,AIR,7,IRON_BARS,12,CONCRETE:7,100)
Block(-7,19,-2,OBSIDIAN:0)
Block(-7,19,-1,CONCRETE:0)
Block(-7,19,0,CONCRETE:0)
Block(-7,19,1,QUARTZ_STAIRS:1)
Block(-7,19,2,QUARTZ_STAIRS:1)
Block(-7,19,3,CONCRETE:0)
Block(-7,19,4,QUARTZ_STAIRS:5)
Block(-7,19,5,QUARTZ_STAIRS:5)
Block(-7,19,6,CONCRETE:0)
Block(-7,19,7,CONCRETE:0)
Block(-7,20,-7,CONCRETE:0)
Block(-7,20,-6,OBSIDIAN:0)
Block(-7,20,-5,STEP:8)
Block(-7,20,-4,STEP:8)
RandomBlock(-7,20,-3,CONCRETE:7,60,quark:iron_plate:1,20,STAINED_CLAY:12,15,STAINED_CLAY:15,5,AIR,7,IRON_BARS,12,CONCRETE:7,100)
Block(-7,20,-2,OBSIDIAN:0)
Block(-7,20,-1,STAINED_GLASS_PANE:15)
Block(-7,20,0,STAINED_GLASS_PANE:15)
Block(-7,20,3,STAINED_GLASS_PANE:15)
Block(-7,20,4,QUARTZ_STAIRS:0)
Block(-7,20,5,QUARTZ_STAIRS:0)
Block(-7,20,6,STAINED_GLASS_PANE:15)
Block(-7,20,7,STAINED_GLASS_PANE:15)
Block(-7,21,-7,CONCRETE:0)
Block(-7,21,-6,OBSIDIAN:0)
RandomBlock(-7,21,-5,CONCRETE:7,60,quark:iron_plate:1,20,STAINED_CLAY:12,15,STAINED_CLAY:15,5,AIR,7,IRON_BARS,12,CONCRETE:7,100)
RandomBlock(-7,21,-4,CONCRETE:7,60,quark:iron_plate:1,20,STAINED_CLAY:12,15,STAINED_CLAY:15,5,AIR,7,IRON_BARS,12,CONCRETE:7,100)
RandomBlock(-7,21,-3,CONCRETE:7,60,quark:iron_plate:1,20,STAINED_CLAY:12,15,STAINED_CLAY:15,5,AIR,7,IRON_BARS,12,CONCRETE:7,100)
Block(-7,21,-2,OBSIDIAN:0)
Block(-7,21,-1,STAINED_GLASS_PANE:15)
Block(-7,21,0,STAINED_GLASS_PANE:15)
Block(-7,21,3,STAINED_GLASS_PANE:15)
Block(-7,21,6,STAINED_GLASS_PANE:15)
Block(-7,21,7,STAINED_GLASS_PANE:15)
Block(-7,22,-7,CONCRETE:0)
Block(-7,22,-6,OBSIDIAN:0)
Block(-7,22,-5,OBSIDIAN:0)
Block(-7,22,-4,OBSIDIAN:0)
Block(-7,22,-3,OBSIDIAN:0)
Block(-7,22,-2,OBSIDIAN:0)
Block(-7,22,-1,STAINED_GLASS_PANE:15)
Block(-7,22,0,STAINED_GLASS_PANE:15)
Block(-7,22,3,STAINED_GLASS_PANE:15)
Block(-7,22,6,STAINED_GLASS_PANE:15)
Block(-7,22,7,STAINED_GLASS_PANE:15)
Block(-7,22,8,SMOOTH_STAIRS:6)
Block(-7,23,-7,CONCRETE:0)
Block(-7,23,-6,CONCRETE:0)
Block(-7,23,-5,CONCRETE:0)
Block(-7,23,-4,CONCRETE:0)
Block(-7,23,-3,CONCRETE:0)
Block(-7,23,-2,OBSIDIAN:0)
Block(-7,23,-1,CONCRETE:0)
Block(-7,23,0,CONCRETE:0)
Block(-7,23,3,STAINED_GLASS_PANE:15)
Block(-7,23,6,CONCRETE:0)
Block(-7,23,7,CONCRETE:0)
Block(-7,23,8,OBSIDIAN:0)
Block(-7,24,-2,STEP:0)
RandomBlock(-7,24,-1,CONCRETE:7,60,quark:iron_plate:1,20,STAINED_CLAY:12,15,STAINED_CLAY:15,5,AIR,7,IRON_BARS,12,CONCRETE:7,100)
Block(-7,24,0,CONCRETE:0)
Block(-7,24,3,CONCRETE:0)
Block(-7,24,6,CONCRETE:0)
Block(-7,24,7,CONCRETE:0)
Block(-7,24,8,CONCRETE:0)
Block(-7,25,-1,STAINED_GLASS_PANE:15)
Block(-7,25,3,STAINED_GLASS_PANE:15)
Block(-7,25,7,STAINED_GLASS_PANE:15)
Block(-7,26,-1,STAINED_GLASS_PANE:15)
Block(-7,26,3,STAINED_GLASS_PANE:15)
Block(-7,26,7,STAINED_GLASS_PANE:15)
Block(-7,27,-1,STAINED_GLASS_PANE:15)
Block(-7,27,3,STAINED_GLASS_PANE:15)
Block(-7,27,7,STAINED_GLASS_PANE:15)
Block(-7,28,-1,STEP:8)
Block(-7,28,1,QUARTZ_STAIRS:4)
Block(-7,28,2,QUARTZ_STAIRS:4)
Block(-7,28,3,STAINED_GLASS_PANE:15)
Block(-7,28,7,STAINED_GLASS_PANE:15)
Block(-7,29,-3,STEP:8)
Block(-7,29,-2,CONCRETE:0)
Block(-7,29,-1,CONCRETE:0)
Block(-7,29,0,CONCRETE:0)
Block(-7,29,1,QUARTZ_STAIRS:1)
Block(-7,29,2,QUARTZ_STAIRS:1)
Block(-7,29,3,CONCRETE:0)
Block(-7,29,4,STEP:8)
Block(-7,29,5,CONCRETE:0)
Block(-7,29,6,STEP:8)
Block(-7,29,7,CONCRETE:0)
Block(-7,29,8,STEP:8)
Block(-7,30,-3,IRON_FENCE:0)
Block(-7,30,-2,STEP:7)
RandomBlock(-7,30,-1,CONCRETE:7,60,quark:iron_plate:1,20,STAINED_CLAY:12,15,STAINED_CLAY:15,5,AIR,7,IRON_BARS,12,CONCRETE:7,100)
Block(-7,30,0,STAINED_GLASS_PANE:15)
Block(-7,30,3,STAINED_GLASS_PANE:15)
Block(-7,30,5,STAINED_GLASS_PANE:15)
Block(-7,30,6,CARPET:15)
Block(-7,30,7,DARK_OAK_STAIRS:1)
Block(-7,30,8,CARPET:15)
Block(-7,31,-1,STAINED_GLASS_PANE:15)
Block(-7,31,3,STAINED_GLASS_PANE:15)
Block(-7,31,5,STAINED_GLASS_PANE:15)
Block(-7,32,-2,STEP:8)
Block(-7,32,-1,STAINED_GLASS_PANE:15)
Block(-7,32,3,CONCRETE:0)
Block(-7,32,5,STAINED_GLASS_PANE:15)
Block(-7,33,-3,STEP:8)
Block(-7,33,-2,CONCRETE:0)
Block(-7,33,-1,STEP:8)
Block(-7,33,0,STEP:8)
Block(-7,33,1,STEP:8)
Block(-7,33,2,STEP:8)
Block(-7,33,3,DOUBLE_STEP:0)
Block(-7,33,4,STEP:8)
Block(-7,33,5,STEP:8)
Block(-7,33,6,STEP:8)
Block(-7,33,7,STEP:8)
Block(-7,33,8,STEP:8)
Block(-7,34,-3,IRON_FENCE:0)
Block(-7,38,2,STEP:15)
Block(-7,38,4,CONCRETE:0)
Block(-7,38,7,CONCRETE:0)
Block(-7,39,0,CONCRETE:0)
Block(-7,39,2,CONCRETE:0)
Block(-7,39,4,QUARTZ_STAIRS:1)
Block(-7,39,7,COBBLE_WALL:0)
Block(-7,40,0,STEP:7)
Block(-7,40,2,COBBLE_WALL:0)
RandomBlock(-6,0,-7,CONCRETE:7,60,quark:iron_plate:1,20,STAINED_CLAY:12,15,STAINED_CLAY:15,5,AIR,7,IRON_BARS,12,CONCRETE:7,100)
RandomBlock(-6,0,-6,CONCRETE:7,60,quark:iron_plate:1,20,STAINED_CLAY:12,15,STAINED_CLAY:15,5,AIR,7,IRON_BARS,12,CONCRETE:7,100)
RandomBlock(-6,0,-5,CONCRETE:7,60,quark:iron_plate:1,20,STAINED_CLAY:12,15,STAINED_CLAY:15,5,AIR,7,IRON_BARS,12,CONCRETE:7,100)
RandomBlock(-6,0,-4,CONCRETE:7,60,quark:iron_plate:1,20,STAINED_CLAY:12,15,STAINED_CLAY:15,5,AIR,7,IRON_BARS,12,CONCRETE:7,100)
RandomBlock(-6,0,-3,CONCRETE:7,60,quark:iron_plate:1,20,STAINED_CLAY:12,15,STAINED_CLAY:15,5,AIR,7,IRON_BARS,12,CONCRETE:7,100)
RandomBlock(-6,0,-2,CONCRETE:7,60,quark:iron_plate:1,20,STAINED_CLAY:12,15,STAINED_CLAY:15,5,AIR,7,IRON_BARS,12,CONCRETE:7,100)
RandomBlock(-6,0,-1,CONCRETE:7,60,quark:iron_plate:1,20,STAINED_CLAY:12,15,STAINED_CLAY:15,5,AIR,7,IRON_BARS,12,CONCRETE:7,100)
RandomBlock(-6,0,0,CONCRETE:7,60,quark:iron_plate:1,20,STAINED_CLAY:12,15,STAINED_CLAY:15,5,AIR,7,IRON_BARS,12,CONCRETE:7,100)
RandomBlock(-6,0,1,CONCRETE:7,60,quark:iron_plate:1,20,STAINED_CLAY:12,15,STAINED_CLAY:15,5,AIR,7,IRON_BARS,12,CONCRETE:7,100)
RandomBlock(-6,0,2,CONCRETE:7,60,quark:iron_plate:1,20,STAINED_CLAY:12,15,STAINED_CLAY:15,5,AIR,7,IRON_BARS,12,CONCRETE:7,100)
RandomBlock(-6,0,3,CONCRETE:7,60,quark:iron_plate:1,20,STAINED_CLAY:12,15,STAINED_CLAY:15,5,AIR,7,IRON_BARS,12,CONCRETE:7,100)
RandomBlock(-6,0,4,CONCRETE:7,60,quark:iron_plate:1,20,STAINED_CLAY:12,15,STAINED_CLAY:15,5,AIR,7,IRON_BARS,12,CONCRETE:7,100)
RandomBlock(-6,0,5,CONCRETE:7,60,quark:iron_plate:1,20,STAINED_CLAY:12,15,STAINED_CLAY:15,5,AIR,7,IRON_BARS,12,CONCRETE:7,100)
RandomBlock(-6,0,6,CONCRETE:7,60,quark:iron_plate:1,20,STAINED_CLAY:12,15,STAINED_CLAY:15,5,AIR,7,IRON_BARS,12,CONCRETE:7,100)
RandomBlock(-6,0,7,CONCRETE:7,60,quark:iron_plate:1,20,STAINED_CLAY:12,15,STAINED_CLAY:15,5,AIR,7,IRON_BARS,12,CONCRETE:7,100)
RandomBlock(-6,0,8,CONCRETE:7,60,quark:iron_plate:1,20,STAINED_CLAY:12,15,STAINED_CLAY:15,5,AIR,7,IRON_BARS,12,CONCRETE:7,100)
Block(-6,1,-7,OBSIDIAN:0)
Block(-6,1,-6,OBSIDIAN:0)
Block(-6,1,-5,OBSIDIAN:0)
Block(-6,1,-4,OBSIDIAN:0)
Block(-6,1,-3,OBSIDIAN:0)
Block(-6,1,-2,OBSIDIAN:0)
Block(-6,1,-1,OBSIDIAN:0)
Block(-6,1,0,OBSIDIAN:0)
Block(-6,1,1,OBSIDIAN:0)
Block(-6,1,2,OBSIDIAN:0)
Block(-6,1,3,OBSIDIAN:0)
Block(-6,1,4,OBSIDIAN:0)
Block(-6,1,5,OBSIDIAN:0)
Block(-6,1,6,OBSIDIAN:0)
Block(-6,1,7,OBSIDIAN:0)
Block(-6,1,8,OBSIDIAN:0)
Block(-6,2,-7,OBSIDIAN:0)
Block(-6,2,-6,OBSIDIAN:0)
Block(-6,2,-5,OBSIDIAN:0)
Block(-6,2,-4,OBSIDIAN:0)
Block(-6,2,-3,OBSIDIAN:0)
Block(-6,2,-2,OBSIDIAN:0)
Block(-6,2,-1,OBSIDIAN:0)
Block(-6,2,0,OBSIDIAN:0)
Block(-6,2,1,OBSIDIAN:0)
Block(-6,2,2,OBSIDIAN:0)
Block(-6,2,3,OBSIDIAN:0)
Block(-6,2,4,OBSIDIAN:0)
Block(-6,2,5,OBSIDIAN:0)
Block(-6,2,6,OBSIDIAN:0)
Block(-6,2,7,OBSIDIAN:0)
Block(-6,2,8,OBSIDIAN:0)
Block(-6,3,-7,STATIONARY_LAVA:0)
Block(-6,3,-6,STATIONARY_LAVA:0)
Block(-6,3,-5,STATIONARY_LAVA:0)
Block(-6,3,-4,STATIONARY_LAVA:0)
Block(-6,3,-3,STATIONARY_LAVA:0)
Block(-6,3,-2,STATIONARY_LAVA:0)
Block(-6,3,-1,STATIONARY_LAVA:0)
Block(-6,3,0,STATIONARY_LAVA:0)
Block(-6,3,1,STATIONARY_LAVA:0)
Block(-6,3,2,STATIONARY_LAVA:0)
Block(-6,3,3,STATIONARY_LAVA:0)
Block(-6,3,4,STATIONARY_LAVA:0)
Block(-6,3,5,STATIONARY_LAVA:0)
Block(-6,3,6,STATIONARY_LAVA:0)
Block(-6,3,7,STATIONARY_LAVA:0)
Block(-6,3,8,STATIONARY_LAVA:0)
Block(-6,4,-7,OBSIDIAN:0)
Block(-6,4,-6,OBSIDIAN:0)
Block(-6,4,-5,OBSIDIAN:0)
Block(-6,4,-4,OBSIDIAN:0)
Block(-6,4,-3,OBSIDIAN:0)
Block(-6,4,-2,OBSIDIAN:0)
Block(-6,4,-1,OBSIDIAN:0)
Block(-6,4,0,OBSIDIAN:0)
Block(-6,4,1,OBSIDIAN:0)
Block(-6,4,2,OBSIDIAN:0)
Block(-6,4,3,OBSIDIAN:0)
Block(-6,4,4,OBSIDIAN:0)
Block(-6,4,5,OBSIDIAN:0)
Block(-6,4,6,OBSIDIAN:0)
Block(-6,4,7,OBSIDIAN:0)
Block(-6,4,8,OBSIDIAN:0)
Block(-6,5,-7,STATIONARY_LAVA:0)
Block(-6,5,-6,OBSIDIAN:0)
Block(-6,5,-5,STATIONARY_LAVA:0)
Block(-6,5,-4,STATIONARY_LAVA:0)
Block(-6,5,-3,STATIONARY_LAVA:0)
Block(-6,5,-2,STATIONARY_LAVA:0)
Block(-6,5,-1,STATIONARY_LAVA:0)
Block(-6,5,0,OBSIDIAN:0)
Block(-6,5,1,IRON_PLATE:0)
RandomBlock(-6,5,2,GOLD_BLOCK,40,MOB_SPAWNER:0,../../DestructionLayers/Parasites/parasite_multi.nbt,20,CHEST:2,../../../../../Chests/Loot/simple_dungeon.nbt,10,CHEST:2,../../../../../Chests/Loot/gem_loot.nbt,10,CHEST:2,../../../../../Chests/Loot/desert_pyramid.nbt,5,CHEST:2,../../../../../Chests/Loot/jungle_temple.nbt,5,CHEST:2,../../../../../Chests/Loot/stronghold_library.nbt,10,CHEST:2,../../../../../Chests/Loot/woodland_mansion.nbt,10,CHEST:2,../../../../../Chests/Loot/end_city_treasure.nbt,10,CHEST:2,../../../../../Chests/RLCraft/IceAndFire/fire_dragon_roost_chest.nbt,5,CHEST:2,../../../../../Chests/lore/moderncity.nbt,5,chest:2,../../../../../Chests/RLCraft/IceAndFire/ice_dragon_roost_chest.nbt,5,chest:2,../../../../../Chests/lore/moderncity.nbt,2,chest:2,../../../../../Chests/RLCraft/IceAndFire/lightning_dragon_roost_chest.nbt,5,chest:2,../../../../../Chests/loot/moderncity_epic_loot.nbt,100)
RandomBlock(-6,5,3,AIR:0,20,TNT:0,100)
RandomBlock(-6,5,4,GOLD_BLOCK,40,MOB_SPAWNER:0,../../DestructionLayers/Parasites/parasite_multi.nbt,20,CHEST:2,../../../../../Chests/Loot/simple_dungeon.nbt,10,CHEST:2,../../../../../Chests/Loot/gem_loot.nbt,10,CHEST:2,../../../../../Chests/Loot/desert_pyramid.nbt,5,CHEST:2,../../../../../Chests/Loot/jungle_temple.nbt,5,CHEST:2,../../../../../Chests/Loot/stronghold_library.nbt,10,CHEST:2,../../../../../Chests/Loot/woodland_mansion.nbt,10,CHEST:2,../../../../../Chests/Loot/end_city_treasure.nbt,10,CHEST:2,../../../../../Chests/RLCraft/IceAndFire/fire_dragon_roost_chest.nbt,5,CHEST:2,../../../../../Chests/lore/moderncity.nbt,5,chest:2,../../../../../Chests/RLCraft/IceAndFire/ice_dragon_roost_chest.nbt,5,chest:2,../../../../../Chests/lore/moderncity.nbt,2,chest:2,../../../../../Chests/RLCraft/IceAndFire/lightning_dragon_roost_chest.nbt,5,chest:2,../../../../../Chests/loot/moderncity_epic_loot.nbt,100)
Block(-6,5,5,IRON_PLATE:0)
Block(-6,5,6,IRON_PLATE:0)
Block(-6,5,7,IRON_PLATE:0)
Block(-6,5,8,IRON_PLATE:0)
Block(-6,6,-7,STATIONARY_LAVA:0)
Block(-6,6,-6,OBSIDIAN:0)
Block(-6,6,-5,STATIONARY_LAVA:0)
Block(-6,6,-4,STATIONARY_LAVA:0)
Block(-6,6,-3,STATIONARY_LAVA:0)
Block(-6,6,-2,STATIONARY_LAVA:0)
Block(-6,6,-1,STATIONARY_LAVA:0)
Block(-6,6,0,OBSIDIAN:0)
Block(-6,6,2,STEP:8)
Block(-6,6,3,STEP:8)
Block(-6,6,4,STEP:8)
Block(-6,7,-7,STATIONARY_LAVA:0)
Block(-6,7,-6,OBSIDIAN:0)
Block(-6,7,-5,STATIONARY_LAVA:0)
Block(-6,7,-4,STATIONARY_LAVA:0)
Block(-6,7,-3,STATIONARY_LAVA:0)
Block(-6,7,-2,STATIONARY_LAVA:0)
Block(-6,7,-1,STATIONARY_LAVA:0)
Block(-6,7,0,OBSIDIAN:0)
RandomBlock(-6,7,2,CHEST:2,../../../../../Chests/Loot/simple_dungeon.nbt,10,CHEST:2,../../../../../Chests/Loot/gem_loot.nbt,10,CHEST:2,../../../../../Chests/Loot/desert_pyramid.nbt,5,CHEST:2,../../../../../Chests/Loot/jungle_temple.nbt,5,CHEST:2,../../../../../Chests/Loot/stronghold_library.nbt,10,CHEST:2,../../../../../Chests/Loot/woodland_mansion.nbt,10,CHEST:2,../../../../../Chests/Loot/end_city_treasure.nbt,10,CHEST:2,../../../../../Chests/RLCraft/IceAndFire/fire_dragon_roost_chest.nbt,5,CHEST:2,../../../../../Chests/lore/moderncity.nbt,5,chest:2,../../../../../Chests/RLCraft/IceAndFire/ice_dragon_roost_chest.nbt,5,chest:2,../../../../../Chests/lore/moderncity.nbt,2,chest:2,../../../../../Chests/RLCraft/IceAndFire/lightning_dragon_roost_chest.nbt,5,chest:2,../../../../../Chests/loot/moderncity_epic_loot.nbt,100)
RandomBlock(-6,7,3,AIR:0,20,TNT:0,100)
RandomBlock(-6,7,4,GOLD_BLOCK,40,MOB_SPAWNER:0,../../DestructionLayers/Parasites/parasite_multi.nbt,20,CHEST:2,../../../../../Chests/Loot/simple_dungeon.nbt,10,CHEST:2,../../../../../Chests/Loot/gem_loot.nbt,10,CHEST:2,../../../../../Chests/Loot/desert_pyramid.nbt,5,CHEST:2,../../../../../Chests/Loot/jungle_temple.nbt,5,CHEST:2,../../../../../Chests/Loot/stronghold_library.nbt,10,CHEST:2,../../../../../Chests/Loot/woodland_mansion.nbt,10,CHEST:2,../../../../../Chests/Loot/end_city_treasure.nbt,10,CHEST:2,../../../../../Chests/RLCraft/IceAndFire/fire_dragon_roost_chest.nbt,5,CHEST:2,../../../../../Chests/lore/moderncity.nbt,5,chest:2,../../../../../Chests/RLCraft/IceAndFire/ice_dragon_roost_chest.nbt,5,chest:2,../../../../../Chests/lore/moderncity.nbt,2,chest:2,../../../../../Chests/RLCraft/IceAndFire/lightning_dragon_roost_chest.nbt,5,chest:2,../../../../../Chests/loot/moderncity_epic_loot.nbt,100)
Block(-6,8,-7,STATIONARY_LAVA:0)
Block(-6,8,-6,OBSIDIAN:0)
Block(-6,8,-5,STATIONARY_LAVA:0)
Block(-6,8,-4,STATIONARY_LAVA:0)
Block(-6,8,-3,STATIONARY_LAVA:0)
Block(-6,8,-2,STATIONARY_LAVA:0)
Block(-6,8,-1,STATIONARY_LAVA:0)
Block(-6,8,0,OBSIDIAN:0)
Block(-6,8,2,STEP:8)
Block(-6,8,3,STEP:8)
Block(-6,8,4,STEP:8)
Block(-6,8,6,STEP:8)
Block(-6,8,7,STEP:8)
Block(-6,9,-7,STATIONARY_LAVA:0)
Block(-6,9,-6,OBSIDIAN:0)
Block(-6,9,-5,STATIONARY_LAVA:0)
Block(-6,9,-4,STATIONARY_LAVA:0)
Block(-6,9,-3,STATIONARY_LAVA:0)
Block(-6,9,-2,STATIONARY_LAVA:0)
Block(-6,9,-1,STATIONARY_LAVA:0)
Block(-6,9,0,OBSIDIAN:0)
Block(-6,9,2,minecraft:yellow_glazed_terracotta:0)
RandomBlock(-6,9,3,AIR:0,20,TNT:0,100)
RandomBlock(-6,9,4,GOLD_BLOCK,40,MOB_SPAWNER:0,../../DestructionLayers/Parasites/parasite_multi.nbt,20,CHEST:2,../../../../../Chests/Loot/simple_dungeon.nbt,10,CHEST:2,../../../../../Chests/Loot/gem_loot.nbt,10,CHEST:2,../../../../../Chests/Loot/desert_pyramid.nbt,5,CHEST:2,../../../../../Chests/Loot/jungle_temple.nbt,5,CHEST:2,../../../../../Chests/Loot/stronghold_library.nbt,10,CHEST:2,../../../../../Chests/Loot/woodland_mansion.nbt,10,CHEST:2,../../../../../Chests/Loot/end_city_treasure.nbt,10,CHEST:2,../../../../../Chests/RLCraft/IceAndFire/fire_dragon_roost_chest.nbt,5,CHEST:2,../../../../../Chests/lore/moderncity.nbt,5,chest:2,../../../../../Chests/RLCraft/IceAndFire/ice_dragon_roost_chest.nbt,5,chest:2,../../../../../Chests/lore/moderncity.nbt,2,chest:2,../../../../../Chests/RLCraft/IceAndFire/lightning_dragon_roost_chest.nbt,5,chest:2,../../../../../Chests/loot/moderncity_epic_loot.nbt,100)
Block(-6,10,-7,STATIONARY_LAVA:0)
Block(-6,10,-6,OBSIDIAN:0)
Block(-6,10,-5,STATIONARY_LAVA:0)
Block(-6,10,-4,STATIONARY_LAVA:0)
Block(-6,10,-3,STATIONARY_LAVA:0)
Block(-6,10,-2,STATIONARY_LAVA:0)
Block(-6,10,-1,STATIONARY_LAVA:0)
Block(-6,10,0,OBSIDIAN:0)
Block(-6,10,1,STEP:8)
Block(-6,10,2,STEP:8)
Block(-6,10,3,STEP:8)
Block(-6,10,4,STEP:8)
Block(-6,10,5,STEP:8)
Block(-6,10,8,STEP:8)
Block(-6,11,-7,OBSIDIAN:0)
Block(-6,11,-6,OBSIDIAN:0)
Block(-6,11,-5,OBSIDIAN:0)
Block(-6,11,-4,OBSIDIAN:0)
Block(-6,11,-3,OBSIDIAN:0)
Block(-6,11,-2,OBSIDIAN:0)
Block(-6,11,-1,OBSIDIAN:0)
Block(-6,11,0,OBSIDIAN:0)
Block(-6,11,1,OBSIDIAN:0)
Block(-6,11,2,OBSIDIAN:0)
Block(-6,11,3,OBSIDIAN:0)
Block(-6,11,4,OBSIDIAN:0)
Block(-6,11,5,OBSIDIAN:0)
Block(-6,11,6,STAINED_GLASS:15)
Block(-6,11,7,STAINED_GLASS:15)
Block(-6,11,8,OBSIDIAN:0)
Block(-6,12,-7,STATIONARY_LAVA:0)
Block(-6,12,-6,STATIONARY_LAVA:0)
Block(-6,12,-5,STATIONARY_LAVA:0)
Block(-6,12,-4,STATIONARY_LAVA:0)
Block(-6,12,-3,STATIONARY_LAVA:0)
Block(-6,12,-2,STATIONARY_LAVA:0)
Block(-6,12,-1,STATIONARY_LAVA:0)
Block(-6,12,0,STATIONARY_LAVA:0)
Block(-6,12,1,STATIONARY_LAVA:0)
Block(-6,12,2,STATIONARY_LAVA:0)
Block(-6,12,3,STATIONARY_LAVA:0)
Block(-6,12,4,STATIONARY_LAVA:0)
Block(-6,12,5,STATIONARY_LAVA:0)
Block(-6,12,6,STATIONARY_LAVA:0)
Block(-6,12,7,STATIONARY_LAVA:0)
Block(-6,12,8,STATIONARY_LAVA:0)
Block(-6,13,-7,OBSIDIAN:0)
Block(-6,13,-6,OBSIDIAN:0)
Block(-6,13,-5,OBSIDIAN:0)
Block(-6,13,-4,OBSIDIAN:0)
Block(-6,13,-3,OBSIDIAN:0)
Block(-6,13,-2,OBSIDIAN:0)
Block(-6,13,-1,OBSIDIAN:0)
Block(-6,13,0,OBSIDIAN:0)
Block(-6,13,1,OBSIDIAN:0)
Block(-6,13,2,OBSIDIAN:0)
Block(-6,13,3,OBSIDIAN:0)
Block(-6,13,4,OBSIDIAN:0)
Block(-6,13,5,OBSIDIAN:0)
Block(-6,13,6,OBSIDIAN:0)
Block(-6,13,7,OBSIDIAN:0)
Block(-6,13,8,OBSIDIAN:0)
Block(-6,14,-7,OBSIDIAN:0)
Block(-6,14,-6,OBSIDIAN:0)
Block(-6,14,-5,OBSIDIAN:0)
Block(-6,14,-4,OBSIDIAN:0)
Block(-6,14,-3,OBSIDIAN:0)
Block(-6,14,-2,OBSIDIAN:0)
Block(-6,14,-1,OBSIDIAN:0)
Block(-6,14,0,OBSIDIAN:0)
Block(-6,14,1,OBSIDIAN:0)
Block(-6,14,2,OBSIDIAN:0)
Block(-6,14,3,OBSIDIAN:0)
Block(-6,14,4,OBSIDIAN:0)
Block(-6,14,5,OBSIDIAN:0)
Block(-6,14,6,OBSIDIAN:0)
Block(-6,14,7,OBSIDIAN:0)
Block(-6,14,8,OBSIDIAN:0)
Block(-6,15,-7,OBSIDIAN:0)
Block(-6,15,-6,OBSIDIAN:0)
Block(-6,15,-5,OBSIDIAN:0)
Block(-6,15,-4,OBSIDIAN:0)
Block(-6,15,-3,OBSIDIAN:0)
Block(-6,15,-2,OBSIDIAN:0)
Block(-6,15,-1,OBSIDIAN:0)
Block(-6,15,0,OBSIDIAN:0)
Block(-6,15,1,OBSIDIAN:0)
Block(-6,15,2,OBSIDIAN:0)
Block(-6,15,3,OBSIDIAN:0)
Block(-6,15,4,OBSIDIAN:0)
Block(-6,15,5,OBSIDIAN:0)
Block(-6,15,6,OBSIDIAN:0)
Block(-6,15,7,OBSIDIAN:0)
Block(-6,15,8,OBSIDIAN:0)
Block(-6,16,-7,OBSIDIAN:0)
Block(-6,16,-6,OBSIDIAN:0)
Block(-6,16,-5,OBSIDIAN:0)
Block(-6,16,-4,OBSIDIAN:0)
Block(-6,16,-3,OBSIDIAN:0)
Block(-6,16,-2,OBSIDIAN:0)
Block(-6,16,-1,OBSIDIAN:0)
Block(-6,16,0,OBSIDIAN:0)
Block(-6,16,1,OBSIDIAN:0)
Block(-6,16,2,OBSIDIAN:0)
Block(-6,16,3,OBSIDIAN:0)
Block(-6,16,4,OBSIDIAN:0)
Block(-6,16,5,OBSIDIAN:0)
Block(-6,16,6,OBSIDIAN:0)
Block(-6,16,7,OBSIDIAN:0)
Block(-6,16,8,OBSIDIAN:0)
RandomBlock(-6,17,-7,CONCRETE:7,60,quark:iron_plate:1,20,STAINED_CLAY:12,15,STAINED_CLAY:15,5,AIR,7,IRON_BARS,12,CONCRETE:7,100)
RandomBlock(-6,17,-6,CONCRETE:7,60,quark:iron_plate:1,20,STAINED_CLAY:12,15,STAINED_CLAY:15,5,AIR,7,IRON_BARS,12,CONCRETE:7,100)
RandomBlock(-6,17,-5,CONCRETE:7,60,quark:iron_plate:1,20,STAINED_CLAY:12,15,STAINED_CLAY:15,5,AIR,7,IRON_BARS,12,CONCRETE:7,100)
RandomBlock(-6,17,-4,CONCRETE:7,60,quark:iron_plate:1,20,STAINED_CLAY:12,15,STAINED_CLAY:15,5,AIR,7,IRON_BARS,12,CONCRETE:7,100)
RandomBlock(-6,17,-3,CONCRETE:7,60,quark:iron_plate:1,20,STAINED_CLAY:12,15,STAINED_CLAY:15,5,AIR,7,IRON_BARS,12,CONCRETE:7,100)
RandomBlock(-6,17,-2,CONCRETE:7,60,quark:iron_plate:1,20,STAINED_CLAY:12,15,STAINED_CLAY:15,5,AIR,7,IRON_BARS,12,CONCRETE:7,100)
RandomBlock(-6,17,-1,CONCRETE:7,60,quark:iron_plate:1,20,STAINED_CLAY:12,15,STAINED_CLAY:15,5,AIR,7,IRON_BARS,12,CONCRETE:7,100)
RandomBlock(-6,17,0,CONCRETE:7,60,quark:iron_plate:1,20,STAINED_CLAY:12,15,STAINED_CLAY:15,5,AIR,7,IRON_BARS,12,CONCRETE:7,100)
RandomBlock(-6,17,1,CONCRETE:7,60,quark:iron_plate:1,20,STAINED_CLAY:12,15,STAINED_CLAY:15,5,AIR,7,IRON_BARS,12,CONCRETE:7,100)
RandomBlock(-6,17,2,CONCRETE:7,60,quark:iron_plate:1,20,STAINED_CLAY:12,15,STAINED_CLAY:15,5,AIR,7,IRON_BARS,12,CONCRETE:7,100)
RandomBlock(-6,17,3,CONCRETE:7,60,quark:iron_plate:1,20,STAINED_CLAY:12,15,STAINED_CLAY:15,5,AIR,7,IRON_BARS,12,CONCRETE:7,100)
RandomBlock(-6,17,4,CONCRETE:7,60,quark:iron_plate:1,20,STAINED_CLAY:12,15,STAINED_CLAY:15,5,AIR,7,IRON_BARS,12,CONCRETE:7,100)
RandomBlock(-6,17,5,CONCRETE:7,60,quark:iron_plate:1,20,STAINED_CLAY:12,15,STAINED_CLAY:15,5,AIR,7,IRON_BARS,12,CONCRETE:7,100)
RandomBlock(-6,17,6,CONCRETE:7,60,quark:iron_plate:1,20,STAINED_CLAY:12,15,STAINED_CLAY:15,5,AIR,7,IRON_BARS,12,CONCRETE:7,100)
RandomBlock(-6,17,7,CONCRETE:7,60,quark:iron_plate:1,20,STAINED_CLAY:12,15,STAINED_CLAY:15,5,AIR,7,IRON_BARS,12,CONCRETE:7,100)
RandomBlock(-6,17,8,CONCRETE:7,60,quark:iron_plate:1,20,STAINED_CLAY:12,15,STAINED_CLAY:15,5,AIR,7,IRON_BARS,12,CONCRETE:7,100)
Block(-6,18,-7,CONCRETE:0)
Block(-6,18,-6,OBSIDIAN:0)
RandomBlock(-6,18,-3,CONCRETE:7,60,quark:iron_plate:1,20,STAINED_CLAY:12,15,STAINED_CLAY:15,5,AIR,7,IRON_BARS,12,CONCRETE:7,100)
Block(-6,18,-2,OBSIDIAN:0)
Block(-6,18,-1,CONCRETE:0)
Block(-6,18,0,CONCRETE:0)
Block(-6,18,1,QUARTZ_STAIRS:1)
Block(-6,18,2,QUARTZ_STAIRS:1)
Block(-6,18,3,CONCRETE:0)
Block(-6,18,6,CONCRETE:0)
Block(-6,18,7,CONCRETE:0)
Block(-6,19,-7,CONCRETE:0)
Block(-6,19,-6,OBSIDIAN:0)
RandomBlock(-6,19,-3,CONCRETE:7,60,quark:iron_plate:1,20,STAINED_CLAY:12,15,STAINED_CLAY:15,5,AIR,7,IRON_BARS,12,CONCRETE:7,100)
Block(-6,19,-2,OBSIDIAN:0)
Block(-6,19,-1,CONCRETE:0)
Block(-6,19,0,CONCRETE:0)
Block(-6,19,3,CONCRETE:0)
Block(-6,19,6,CONCRETE:0)
Block(-6,19,7,CONCRETE:0)
Block(-6,19,8,STONE_BUTTON:3)
Block(-6,20,-7,CONCRETE:0)
Block(-6,20,-6,OBSIDIAN:0)
Block(-6,20,-5,STEP:8)
Block(-6,20,-4,STEP:8)
RandomBlock(-6,20,-3,CONCRETE:7,60,quark:iron_plate:1,20,STAINED_CLAY:12,15,STAINED_CLAY:15,5,AIR,7,IRON_BARS,12,CONCRETE:7,100)
Block(-6,20,-2,OBSIDIAN:0)
Block(-6,20,-1,CONCRETE:0)
Block(-6,20,3,CONCRETE:0)
Block(-6,20,4,QUARTZ_STAIRS:5)
Block(-6,20,5,QUARTZ_STAIRS:5)
Block(-6,20,7,CONCRETE:0)
Block(-6,21,-7,CONCRETE:0)
Block(-6,21,-6,OBSIDIAN:0)
RandomBlock(-6,21,-5,CONCRETE:7,60,quark:iron_plate:1,20,STAINED_CLAY:12,15,STAINED_CLAY:15,5,AIR,7,IRON_BARS,12,CONCRETE:7,100)
RandomBlock(-6,21,-4,CONCRETE:7,60,quark:iron_plate:1,20,STAINED_CLAY:12,15,STAINED_CLAY:15,5,AIR,7,IRON_BARS,12,CONCRETE:7,100)
RandomBlock(-6,21,-3,CONCRETE:7,60,quark:iron_plate:1,20,STAINED_CLAY:12,15,STAINED_CLAY:15,5,AIR,7,IRON_BARS,12,CONCRETE:7,100)
Block(-6,21,-2,OBSIDIAN:0)
Block(-6,21,-1,CONCRETE:0)
Block(-6,21,3,CONCRETE:0)
Block(-6,21,4,QUARTZ_STAIRS:0)
Block(-6,21,5,QUARTZ_STAIRS:0)
Block(-6,21,7,CONCRETE:0)
Block(-6,21,8,SMOOTH_STAIRS:7)
Block(-6,22,-7,CONCRETE:0)
Block(-6,22,-6,OBSIDIAN:0)
Block(-6,22,-5,OBSIDIAN:0)
Block(-6,22,-4,OBSIDIAN:0)
Block(-6,22,-3,OBSIDIAN:0)
Block(-6,22,-2,OBSIDIAN:0)
Block(-6,22,-1,CONCRETE:0)
Block(-6,22,3,CONCRETE:0)
Block(-6,22,7,CONCRETE:0)
RandomBlock(-6,22,8,CONCRETE:7,60,quark:iron_plate:1,20,STAINED_CLAY:12,15,STAINED_CLAY:15,5,AIR,7,IRON_BARS,12,CONCRETE:7,100)
Block(-6,23,-7,CONCRETE:0)
Block(-6,23,-6,CONCRETE:0)
Block(-6,23,-5,CONCRETE:0)
Block(-6,23,-4,CONCRETE:0)
Block(-6,23,-3,CONCRETE:0)
Block(-6,23,-2,OBSIDIAN:0)
Block(-6,23,-1,CONCRETE:0)
Block(-6,23,0,CONCRETE:0)
Block(-6,23,3,CONCRETE:0)
Block(-6,23,6,CONCRETE:0)
Block(-6,23,7,CONCRETE:0)
Block(-6,23,8,OBSIDIAN:0)
Block(-6,24,-2,QUARTZ_STAIRS:2)
Block(-6,24,-1,CONCRETE:0)
Block(-6,24,0,CONCRETE:0)
Block(-6,24,3,CONCRETE:0)
Block(-6,24,6,CONCRETE:0)
Block(-6,24,7,CONCRETE:0)
Block(-6,24,8,CONCRETE:0)
Block(-6,25,-1,CONCRETE:0)
Block(-6,25,3,CONCRETE:0)
Block(-6,25,7,CONCRETE:0)
Block(-6,26,-1,CONCRETE:0)
Block(-6,26,3,CONCRETE:0)
Block(-6,26,7,CONCRETE:0)
Block(-6,27,-1,CONCRETE:0)
Block(-6,27,1,QUARTZ_STAIRS:4)
Block(-6,27,2,QUARTZ_STAIRS:4)
Block(-6,27,3,CONCRETE:0)
Block(-6,27,7,CONCRETE:0)
Block(-6,28,-2,QUARTZ_STAIRS:6)
Block(-6,28,-1,CONCRETE:0)
Block(-6,28,1,QUARTZ_STAIRS:1)
Block(-6,28,2,QUARTZ_STAIRS:1)
Block(-6,28,3,CONCRETE:0)
Block(-6,28,7,CONCRETE:0)
Block(-6,29,-3,QUARTZ_STAIRS:6)
Block(-6,29,-2,CONCRETE:0)
Block(-6,29,-1,CONCRETE:0)
Block(-6,29,0,CONCRETE:0)
Block(-6,29,3,CONCRETE:0)
Block(-6,29,4,CONCRETE:0)
Block(-6,29,5,CONCRETE:0)
Block(-6,29,6,CONCRETE:0)
Block(-6,29,7,CONCRETE:0)
Block(-6,29,8,CONCRETE:0)
Block(-6,30,-3,COBBLE_WALL:0)
Block(-6,30,-2,CONCRETE:0)
Block(-6,30,-1,CONCRETE:0)
Block(-6,30,3,CONCRETE:0)
Block(-6,30,5,CONCRETE:0)
Block(-6,30,6,DARK_OAK_STAIRS:3)
Block(-6,30,7,DARK_OAK_STAIRS:5)
Block(-6,30,8,DARK_OAK_STAIRS:2)
Block(-6,31,-2,CONCRETE:0)
Block(-6,31,-1,CONCRETE:0)
Block(-6,31,3,CONCRETE:0)
Block(-6,31,5,CONCRETE:0)
Block(-6,31,7,CARPET:14)
Block(-6,32,-2,CONCRETE:0)
Block(-6,32,-1,CONCRETE:0)
Block(-6,32,3,CONCRETE:0)
Block(-6,32,5,CONCRETE:0)
Block(-6,33,-3,QUARTZ_STAIRS:6)
Block(-6,33,-2,CONCRETE:0)
Block(-6,33,-1,CONCRETE:0)
Block(-6,33,0,CONCRETE:0)
Block(-6,33,1,CONCRETE:0)
Block(-6,33,2,CONCRETE:0)
Block(-6,33,3,CONCRETE:0)
Block(-6,33,4,CONCRETE:0)
Block(-6,33,5,CONCRETE:0)
Block(-6,33,6,CONCRETE:0)
Block(-6,33,7,CONCRETE:0)
Block(-6,33,8,CONCRETE:0)
Block(-6,34,-3,COBBLE_WALL:0)
Block(-6,34,-2,CONCRETE:0)
Block(-6,35,-2,CONCRETE:0)
Block(-6,36,-2,CONCRETE:0)
Block(-6,37,-2,CONCRETE:0)
Block(-6,37,7,STEP:15)
Block(-6,38,-2,CONCRETE:0)
Block(-6,38,0,STEP:15)
Block(-6,38,2,CONCRETE:0)
Block(-6,38,4,CONCRETE:0)
Block(-6,38,7,CONCRETE:0)
Block(-6,39,-2,QUARTZ_STAIRS:2)
Block(-6,39,-1,CONCRETE:0)
Block(-6,39,0,CONCRETE:0)
Block(-6,39,2,QUARTZ_STAIRS:1)
Block(-6,39,4,COBBLE_WALL:0)
Block(-6,40,0,COBBLE_WALL:0)
RandomBlock(-5,0,-7,CONCRETE:7,60,quark:iron_plate:1,20,STAINED_CLAY:12,15,STAINED_CLAY:15,5,AIR,7,IRON_BARS,12,CONCRETE:7,100)
RandomBlock(-5,0,-6,CONCRETE:7,60,quark:iron_plate:1,20,STAINED_CLAY:12,15,STAINED_CLAY:15,5,AIR,7,IRON_BARS,12,CONCRETE:7,100)
RandomBlock(-5,0,-5,CONCRETE:7,60,quark:iron_plate:1,20,STAINED_CLAY:12,15,STAINED_CLAY:15,5,AIR,7,IRON_BARS,12,CONCRETE:7,100)
RandomBlock(-5,0,-4,CONCRETE:7,60,quark:iron_plate:1,20,STAINED_CLAY:12,15,STAINED_CLAY:15,5,AIR,7,IRON_BARS,12,CONCRETE:7,100)
RandomBlock(-5,0,-3,CONCRETE:7,60,quark:iron_plate:1,20,STAINED_CLAY:12,15,STAINED_CLAY:15,5,AIR,7,IRON_BARS,12,CONCRETE:7,100)
RandomBlock(-5,0,-2,CONCRETE:7,60,quark:iron_plate:1,20,STAINED_CLAY:12,15,STAINED_CLAY:15,5,AIR,7,IRON_BARS,12,CONCRETE:7,100)
RandomBlock(-5,0,-1,CONCRETE:7,60,quark:iron_plate:1,20,STAINED_CLAY:12,15,STAINED_CLAY:15,5,AIR,7,IRON_BARS,12,CONCRETE:7,100)
RandomBlock(-5,0,0,CONCRETE:7,60,quark:iron_plate:1,20,STAINED_CLAY:12,15,STAINED_CLAY:15,5,AIR,7,IRON_BARS,12,CONCRETE:7,100)
RandomBlock(-5,0,1,CONCRETE:7,60,quark:iron_plate:1,20,STAINED_CLAY:12,15,STAINED_CLAY:15,5,AIR,7,IRON_BARS,12,CONCRETE:7,100)
RandomBlock(-5,0,2,CONCRETE:7,60,quark:iron_plate:1,20,STAINED_CLAY:12,15,STAINED_CLAY:15,5,AIR,7,IRON_BARS,12,CONCRETE:7,100)
RandomBlock(-5,0,3,CONCRETE:7,60,quark:iron_plate:1,20,STAINED_CLAY:12,15,STAINED_CLAY:15,5,AIR,7,IRON_BARS,12,CONCRETE:7,100)
RandomBlock(-5,0,4,CONCRETE:7,60,quark:iron_plate:1,20,STAINED_CLAY:12,15,STAINED_CLAY:15,5,AIR,7,IRON_BARS,12,CONCRETE:7,100)
RandomBlock(-5,0,5,CONCRETE:7,60,quark:iron_plate:1,20,STAINED_CLAY:12,15,STAINED_CLAY:15,5,AIR,7,IRON_BARS,12,CONCRETE:7,100)
RandomBlock(-5,0,6,CONCRETE:7,60,quark:iron_plate:1,20,STAINED_CLAY:12,15,STAINED_CLAY:15,5,AIR,7,IRON_BARS,12,CONCRETE:7,100)
RandomBlock(-5,0,7,CONCRETE:7,60,quark:iron_plate:1,20,STAINED_CLAY:12,15,STAINED_CLAY:15,5,AIR,7,IRON_BARS,12,CONCRETE:7,100)
RandomBlock(-5,0,8,CONCRETE:7,60,quark:iron_plate:1,20,STAINED_CLAY:12,15,STAINED_CLAY:15,5,AIR,7,IRON_BARS,12,CONCRETE:7,100)
Block(-5,1,-7,OBSIDIAN:0)
Block(-5,1,-6,OBSIDIAN:0)
Block(-5,1,-5,OBSIDIAN:0)
Block(-5,1,-4,OBSIDIAN:0)
Block(-5,1,-3,OBSIDIAN:0)
Block(-5,1,-2,OBSIDIAN:0)
Block(-5,1,-1,OBSIDIAN:0)
Block(-5,1,0,OBSIDIAN:0)
Block(-5,1,1,OBSIDIAN:0)
Block(-5,1,2,OBSIDIAN:0)
Block(-5,1,3,OBSIDIAN:0)
Block(-5,1,4,OBSIDIAN:0)
Block(-5,1,5,OBSIDIAN:0)
Block(-5,1,6,OBSIDIAN:0)
Block(-5,1,7,OBSIDIAN:0)
Block(-5,1,8,OBSIDIAN:0)
Block(-5,2,-7,OBSIDIAN:0)
Block(-5,2,-6,OBSIDIAN:0)
Block(-5,2,-5,OBSIDIAN:0)
Block(-5,2,-4,OBSIDIAN:0)
Block(-5,2,-3,OBSIDIAN:0)
Block(-5,2,-2,OBSIDIAN:0)
Block(-5,2,-1,OBSIDIAN:0)
Block(-5,2,0,OBSIDIAN:0)
Block(-5,2,1,OBSIDIAN:0)
Block(-5,2,2,OBSIDIAN:0)
Block(-5,2,3,OBSIDIAN:0)
Block(-5,2,4,OBSIDIAN:0)
Block(-5,2,5,OBSIDIAN:0)
Block(-5,2,6,OBSIDIAN:0)
Block(-5,2,7,OBSIDIAN:0)
Block(-5,2,8,OBSIDIAN:0)
Block(-5,3,-7,STATIONARY_LAVA:0)
Block(-5,3,-6,STATIONARY_LAVA:0)
Block(-5,3,-5,STATIONARY_LAVA:0)
Block(-5,3,-4,STATIONARY_LAVA:0)
Block(-5,3,-3,STATIONARY_LAVA:0)
Block(-5,3,-2,STATIONARY_LAVA:0)
Block(-5,3,-1,STATIONARY_LAVA:0)
Block(-5,3,0,STATIONARY_LAVA:0)
Block(-5,3,1,STATIONARY_LAVA:0)
Block(-5,3,2,STATIONARY_LAVA:0)
Block(-5,3,3,STATIONARY_LAVA:0)
Block(-5,3,4,STATIONARY_LAVA:0)
Block(-5,3,5,STATIONARY_LAVA:0)
Block(-5,3,6,STATIONARY_LAVA:0)
Block(-5,3,7,STATIONARY_LAVA:0)
Block(-5,3,8,STATIONARY_LAVA:0)
Block(-5,4,-7,OBSIDIAN:0)
Block(-5,4,-6,OBSIDIAN:0)
Block(-5,4,-5,OBSIDIAN:0)
Block(-5,4,-4,OBSIDIAN:0)
Block(-5,4,-3,OBSIDIAN:0)
Block(-5,4,-2,OBSIDIAN:0)
Block(-5,4,-1,OBSIDIAN:0)
Block(-5,4,0,OBSIDIAN:0)
Block(-5,4,1,OBSIDIAN:0)
Block(-5,4,2,OBSIDIAN:0)
Block(-5,4,3,OBSIDIAN:0)
Block(-5,4,4,OBSIDIAN:0)
Block(-5,4,5,OBSIDIAN:0)
Block(-5,4,6,OBSIDIAN:0)
Block(-5,4,7,OBSIDIAN:0)
Block(-5,4,8,OBSIDIAN:0)
Block(-5,5,-7,STATIONARY_LAVA:0)
Block(-5,5,-6,OBSIDIAN:0)
Block(-5,5,-5,STATIONARY_LAVA:0)
Block(-5,5,-4,STATIONARY_LAVA:0)
Block(-5,5,-3,STATIONARY_LAVA:0)
Block(-5,5,-2,STATIONARY_LAVA:0)
Block(-5,5,-1,STATIONARY_LAVA:0)
Block(-5,5,0,OBSIDIAN:0)
Block(-5,5,1,IRON_PLATE:0)
#RandomBlock(-5,5,2,AIR:0,30,CHEST:5,../../../../../Chests/Loot/junk_loot.nbt,10,CHEST:5,../../../../../Chests/Loot/simple_dungeon.nbt,5,CHEST:5,../../../../../Chests/loot/moderncity_junk_loot.nbt,65,CHEST:2,../../../../../Chests/loot/moderncity_junk_loot.nbt,20,CHEST:2,../../../../../Chests/loot/moderncity_common_loot.nbt,5,CHEST:2,../../../../../Chests/loot/moderncity_rare_loot.nbt,3,CHEST:2,../../../../../Chests/loot/moderncity_epic_loot.nbt,1,CHEST:2,../../../../../Chests/loot/moderncity_junk_loot.nbt,100)
RandomBlock(-5,5,3,AIR:0,20,TNT:0,100)
RandomBlock(-5,5,4,CHEST:3,../../../../../Chests/Loot/simple_dungeon.nbt,10,CHEST:3,../../../../../Chests/Loot/gem_loot.nbt,10,CHEST:3,../../../../../Chests/Loot/desert_pyramid.nbt,5,CHEST:3,../../../../../Chests/Loot/jungle_temple.nbt,5,CHEST:3,../../../../../Chests/Loot/stronghold_library.nbt,10,CHEST:3,../../../../../Chests/Loot/woodland_mansion.nbt,10,CHEST:3,../../../../../Chests/Loot/end_city_treasure.nbt,10,CHEST:3,../../../../../Chests/RLCraft/IceAndFire/fire_dragon_roost_chest.nbt,5,CHEST:3,../../../../../Chests/lore/moderncity.nbt,5,chest:3,../../../../../Chests/RLCraft/IceAndFire/ice_dragon_roost_chest.nbt,5,chest:3,../../../../../Chests/lore/moderncity.nbt,2,chest:3,../../../../../Chests/RLCraft/IceAndFire/lightning_dragon_roost_chest.nbt,5,chest:3,../../../../../Chests/loot/moderncity_epic_loot.nbt,100)
Block(-5,5,5,IRON_PLATE:0)
Block(-5,5,6,IRON_PLATE:0)
Block(-5,5,7,IRON_PLATE:0)
Block(-5,5,8,IRON_PLATE:0)
Block(-5,6,-7,STATIONARY_LAVA:0)
Block(-5,6,-6,OBSIDIAN:0)
Block(-5,6,-5,STATIONARY_LAVA:0)
Block(-5,6,-4,STATIONARY_LAVA:0)
Block(-5,6,-3,STATIONARY_LAVA:0)
Block(-5,6,-2,STATIONARY_LAVA:0)
Block(-5,6,-1,STATIONARY_LAVA:0)
Block(-5,6,0,OBSIDIAN:0)
Block(-5,6,2,STEP:8)
Block(-5,6,3,STEP:8)
Block(-5,6,4,STEP:8)
Block(-5,7,-7,STATIONARY_LAVA:0)
Block(-5,7,-6,OBSIDIAN:0)
Block(-5,7,-5,STATIONARY_LAVA:0)
Block(-5,7,-4,STATIONARY_LAVA:0)
Block(-5,7,-3,STATIONARY_LAVA:0)
Block(-5,7,-2,STATIONARY_LAVA:0)
Block(-5,7,-1,STATIONARY_LAVA:0)
Block(-5,7,0,OBSIDIAN:0)
Block(-5,7,2,GOLD_PLATE:0)
RandomBlock(-5,7,3,AIR:0,20,TNT:0,100)
#RandomBlock(-5,7,4,AIR:0,30,CHEST:5,../../../../../Chests/Loot/junk_loot.nbt,10,CHEST:5,../../../../../Chests/Loot/simple_dungeon.nbt,5,CHEST:5,../../../../../Chests/loot/moderncity_junk_loot.nbt,65,CHEST:3,../../../../../Chests/loot/moderncity_junk_loot.nbt,20,CHEST:3,../../../../../Chests/loot/moderncity_common_loot.nbt,5,CHEST:3,../../../../../Chests/loot/moderncity_rare_loot.nbt,3,CHEST:3,../../../../../Chests/loot/moderncity_epic_loot.nbt,1,CHEST:3,../../../../../Chests/loot/moderncity_junk_loot.nbt,100)
Block(-5,8,-7,STATIONARY_LAVA:0)
Block(-5,8,-6,OBSIDIAN:0)
Block(-5,8,-5,STATIONARY_LAVA:0)
Block(-5,8,-4,STATIONARY_LAVA:0)
Block(-5,8,-3,STATIONARY_LAVA:0)
Block(-5,8,-2,STATIONARY_LAVA:0)
Block(-5,8,-1,STATIONARY_LAVA:0)
Block(-5,8,0,OBSIDIAN:0)
Block(-5,8,2,STEP:8)
Block(-5,8,3,STEP:8)
Block(-5,8,4,STEP:8)
Block(-5,8,6,STEP:8)
Block(-5,8,7,STEP:8)
Block(-5,9,-7,STATIONARY_LAVA:0)
Block(-5,9,-6,OBSIDIAN:0)
Block(-5,9,-5,STATIONARY_LAVA:0)
Block(-5,9,-4,STATIONARY_LAVA:0)
Block(-5,9,-3,STATIONARY_LAVA:0)
Block(-5,9,-2,STATIONARY_LAVA:0)
Block(-5,9,-1,STATIONARY_LAVA:0)
Block(-5,9,0,OBSIDIAN:0)
#RandomBlock(-5,9,2,AIR:0,30,CHEST:5,../../../../../Chests/Loot/junk_loot.nbt,10,CHEST:5,../../../../../Chests/Loot/simple_dungeon.nbt,5,CHEST:5,../../../../../Chests/loot/moderncity_junk_loot.nbt,65,CHEST:2,../../../../../Chests/loot/moderncity_junk_loot.nbt,20,CHEST:2,../../../../../Chests/loot/moderncity_common_loot.nbt,5,CHEST:2,../../../../../Chests/loot/moderncity_rare_loot.nbt,3,CHEST:2,../../../../../Chests/loot/moderncity_epic_loot.nbt,1,CHEST:2,../../../../../Chests/loot/moderncity_junk_loot.nbt,100)
RandomBlock(-5,9,3,AIR:0,20,TNT:0,100)
RandomBlock(-5,9,4,CHEST:3,../../../../../Chests/Loot/simple_dungeon.nbt,10,CHEST:3,../../../../../Chests/Loot/gem_loot.nbt,10,CHEST:3,../../../../../Chests/Loot/desert_pyramid.nbt,5,CHEST:3,../../../../../Chests/Loot/jungle_temple.nbt,5,CHEST:3,../../../../../Chests/Loot/stronghold_library.nbt,10,CHEST:3,../../../../../Chests/Loot/woodland_mansion.nbt,10,CHEST:3,../../../../../Chests/Loot/end_city_treasure.nbt,10,CHEST:3,../../../../../Chests/RLCraft/IceAndFire/fire_dragon_roost_chest.nbt,5,CHEST:3,../../../../../Chests/lore/moderncity.nbt,5,chest:3,../../../../../Chests/RLCraft/IceAndFire/ice_dragon_roost_chest.nbt,5,chest:3,../../../../../Chests/lore/moderncity.nbt,2,chest:3,../../../../../Chests/RLCraft/IceAndFire/lightning_dragon_roost_chest.nbt,5,chest:3,../../../../../Chests/loot/moderncity_epic_loot.nbt,100)
Block(-5,10,-7,STATIONARY_LAVA:0)
Block(-5,10,-6,OBSIDIAN:0)
Block(-5,10,-5,STATIONARY_LAVA:0)
Block(-5,10,-4,STATIONARY_LAVA:0)
Block(-5,10,-3,STATIONARY_LAVA:0)
Block(-5,10,-2,STATIONARY_LAVA:0)
Block(-5,10,-1,STATIONARY_LAVA:0)
Block(-5,10,0,OBSIDIAN:0)
Block(-5,10,1,STEP:8)
Block(-5,10,2,STEP:8)
Block(-5,10,3,STEP:8)
Block(-5,10,4,STEP:8)
Block(-5,10,5,STEP:8)
Block(-5,10,8,STEP:8)
Block(-5,11,-7,OBSIDIAN:0)
Block(-5,11,-6,OBSIDIAN:0)
Block(-5,11,-5,OBSIDIAN:0)
Block(-5,11,-4,OBSIDIAN:0)
Block(-5,11,-3,OBSIDIAN:0)
Block(-5,11,-2,OBSIDIAN:0)
Block(-5,11,-1,OBSIDIAN:0)
Block(-5,11,0,OBSIDIAN:0)
Block(-5,11,1,OBSIDIAN:0)
Block(-5,11,2,OBSIDIAN:0)
Block(-5,11,3,OBSIDIAN:0)
Block(-5,11,4,OBSIDIAN:0)
Block(-5,11,5,OBSIDIAN:0)
Block(-5,11,6,STAINED_GLASS:15)
Block(-5,11,7,STAINED_GLASS:15)
Block(-5,11,8,OBSIDIAN:0)
Block(-5,12,-7,STATIONARY_LAVA:0)
Block(-5,12,-6,STATIONARY_LAVA:0)
Block(-5,12,-5,STATIONARY_LAVA:0)
Block(-5,12,-4,STATIONARY_LAVA:0)
Block(-5,12,-3,STATIONARY_LAVA:0)
Block(-5,12,-2,STATIONARY_LAVA:0)
Block(-5,12,-1,STATIONARY_LAVA:0)
Block(-5,12,0,STATIONARY_LAVA:0)
Block(-5,12,1,STATIONARY_LAVA:0)
Block(-5,12,2,STATIONARY_LAVA:0)
Block(-5,12,3,STATIONARY_LAVA:0)
Block(-5,12,4,STATIONARY_LAVA:0)
Block(-5,12,5,STATIONARY_LAVA:0)
Block(-5,12,6,STATIONARY_LAVA:0)
Block(-5,12,7,STATIONARY_LAVA:0)
Block(-5,12,8,STATIONARY_LAVA:0)
Block(-5,13,-7,OBSIDIAN:0)
Block(-5,13,-6,OBSIDIAN:0)
Block(-5,13,-5,OBSIDIAN:0)
Block(-5,13,-4,OBSIDIAN:0)
Block(-5,13,-3,OBSIDIAN:0)
Block(-5,13,-2,OBSIDIAN:0)
Block(-5,13,-1,OBSIDIAN:0)
Block(-5,13,0,OBSIDIAN:0)
Block(-5,13,1,OBSIDIAN:0)
Block(-5,13,2,OBSIDIAN:0)
Block(-5,13,3,OBSIDIAN:0)
Block(-5,13,4,OBSIDIAN:0)
Block(-5,13,5,OBSIDIAN:0)
Block(-5,13,6,OBSIDIAN:0)
Block(-5,13,7,OBSIDIAN:0)
Block(-5,13,8,OBSIDIAN:0)
Block(-5,14,-7,OBSIDIAN:0)
Block(-5,14,-6,OBSIDIAN:0)
Block(-5,14,-5,OBSIDIAN:0)
Block(-5,14,-4,OBSIDIAN:0)
Block(-5,14,-3,OBSIDIAN:0)
Block(-5,14,-2,OBSIDIAN:0)
Block(-5,14,-1,OBSIDIAN:0)
Block(-5,14,0,OBSIDIAN:0)
Block(-5,14,1,OBSIDIAN:0)
Block(-5,14,2,OBSIDIAN:0)
Block(-5,14,3,OBSIDIAN:0)
Block(-5,14,4,OBSIDIAN:0)
Block(-5,14,5,OBSIDIAN:0)
Block(-5,14,6,OBSIDIAN:0)
Block(-5,14,7,OBSIDIAN:0)
Block(-5,14,8,OBSIDIAN:0)
Block(-5,15,-7,OBSIDIAN:0)
Block(-5,15,-6,OBSIDIAN:0)
Block(-5,15,-5,OBSIDIAN:0)
Block(-5,15,-4,OBSIDIAN:0)
Block(-5,15,-3,OBSIDIAN:0)
Block(-5,15,-2,OBSIDIAN:0)
Block(-5,15,-1,OBSIDIAN:0)
Block(-5,15,0,OBSIDIAN:0)
Block(-5,15,1,OBSIDIAN:0)
Block(-5,15,2,OBSIDIAN:0)
Block(-5,15,3,OBSIDIAN:0)
Block(-5,15,4,OBSIDIAN:0)
Block(-5,15,5,OBSIDIAN:0)
Block(-5,15,6,OBSIDIAN:0)
Block(-5,15,7,OBSIDIAN:0)
Block(-5,15,8,OBSIDIAN:0)
Block(-5,16,-7,OBSIDIAN:0)
Block(-5,16,-6,OBSIDIAN:0)
Block(-5,16,-5,OBSIDIAN:0)
Block(-5,16,-4,OBSIDIAN:0)
Block(-5,16,-3,OBSIDIAN:0)
Block(-5,16,-2,OBSIDIAN:0)
Block(-5,16,-1,OBSIDIAN:0)
Block(-5,16,0,OBSIDIAN:0)
Block(-5,16,1,OBSIDIAN:0)
Block(-5,16,2,OBSIDIAN:0)
Block(-5,16,3,OBSIDIAN:0)
Block(-5,16,4,OBSIDIAN:0)
Block(-5,16,5,OBSIDIAN:0)
Block(-5,16,6,OBSIDIAN:0)
Block(-5,16,7,OBSIDIAN:0)
Block(-5,16,8,OBSIDIAN:0)
RandomBlock(-5,17,-7,CONCRETE:7,60,quark:iron_plate:1,20,STAINED_CLAY:12,15,STAINED_CLAY:15,5,AIR,7,IRON_BARS,12,CONCRETE:7,100)
RandomBlock(-5,17,-6,CONCRETE:7,60,quark:iron_plate:1,20,STAINED_CLAY:12,15,STAINED_CLAY:15,5,AIR,7,IRON_BARS,12,CONCRETE:7,100)
RandomBlock(-5,17,-5,CONCRETE:7,60,quark:iron_plate:1,20,STAINED_CLAY:12,15,STAINED_CLAY:15,5,AIR,7,IRON_BARS,12,CONCRETE:7,100)
RandomBlock(-5,17,-4,CONCRETE:7,60,quark:iron_plate:1,20,STAINED_CLAY:12,15,STAINED_CLAY:15,5,AIR,7,IRON_BARS,12,CONCRETE:7,100)
RandomBlock(-5,17,-3,CONCRETE:7,60,quark:iron_plate:1,20,STAINED_CLAY:12,15,STAINED_CLAY:15,5,AIR,7,IRON_BARS,12,CONCRETE:7,100)
RandomBlock(-5,17,-2,CONCRETE:7,60,quark:iron_plate:1,20,STAINED_CLAY:12,15,STAINED_CLAY:15,5,AIR,7,IRON_BARS,12,CONCRETE:7,100)
RandomBlock(-5,17,-1,CONCRETE:7,60,quark:iron_plate:1,20,STAINED_CLAY:12,15,STAINED_CLAY:15,5,AIR,7,IRON_BARS,12,CONCRETE:7,100)
RandomBlock(-5,17,0,CONCRETE:7,60,quark:iron_plate:1,20,STAINED_CLAY:12,15,STAINED_CLAY:15,5,AIR,7,IRON_BARS,12,CONCRETE:7,100)
RandomBlock(-5,17,1,CONCRETE:7,60,quark:iron_plate:1,20,STAINED_CLAY:12,15,STAINED_CLAY:15,5,AIR,7,IRON_BARS,12,CONCRETE:7,100)
RandomBlock(-5,17,2,CONCRETE:7,60,quark:iron_plate:1,20,STAINED_CLAY:12,15,STAINED_CLAY:15,5,AIR,7,IRON_BARS,12,CONCRETE:7,100)
RandomBlock(-5,17,3,CONCRETE:7,60,quark:iron_plate:1,20,STAINED_CLAY:12,15,STAINED_CLAY:15,5,AIR,7,IRON_BARS,12,CONCRETE:7,100)
RandomBlock(-5,17,4,CONCRETE:7,60,quark:iron_plate:1,20,STAINED_CLAY:12,15,STAINED_CLAY:15,5,AIR,7,IRON_BARS,12,CONCRETE:7,100)
RandomBlock(-5,17,5,CONCRETE:7,60,quark:iron_plate:1,20,STAINED_CLAY:12,15,STAINED_CLAY:15,5,AIR,7,IRON_BARS,12,CONCRETE:7,100)
RandomBlock(-5,17,6,CONCRETE:7,60,quark:iron_plate:1,20,STAINED_CLAY:12,15,STAINED_CLAY:15,5,AIR,7,IRON_BARS,12,CONCRETE:7,100)
RandomBlock(-5,17,7,CONCRETE:7,60,quark:iron_plate:1,20,STAINED_CLAY:12,15,STAINED_CLAY:15,5,AIR,7,IRON_BARS,12,CONCRETE:7,100)
RandomBlock(-5,17,8,CONCRETE:7,60,quark:iron_plate:1,20,STAINED_CLAY:12,15,STAINED_CLAY:15,5,AIR,7,IRON_BARS,12,CONCRETE:7,100)
Block(-5,18,-7,CONCRETE:0)
Block(-5,18,-6,OBSIDIAN:0)
RandomBlock(-5,18,-3,CONCRETE:7,60,quark:iron_plate:1,20,STAINED_CLAY:12,15,STAINED_CLAY:15,5,AIR,7,IRON_BARS,12,CONCRETE:7,100)
Block(-5,18,-2,OBSIDIAN:0)
Block(-5,18,-1,STAINED_GLASS_PANE:15)
Block(-5,18,3,STAINED_GLASS_PANE:15)
Block(-5,18,7,IRON_DOOR_BLOCK:1)
Block(-5,19,-7,CONCRETE:0)
Block(-5,19,-6,OBSIDIAN:0)
RandomBlock(-5,19,-3,CONCRETE:7,60,quark:iron_plate:1,20,STAINED_CLAY:12,15,STAINED_CLAY:15,5,AIR,7,IRON_BARS,12,CONCRETE:7,100)
Block(-5,19,-2,OBSIDIAN:0)
Block(-5,19,-1,CONCRETE:0)
Block(-5,19,3,CONCRETE:0)
Block(-5,19,6,STONE_BUTTON:1)
Block(-5,19,7,IRON_DOOR_BLOCK:8)
Block(-5,20,-7,CONCRETE:0)
Block(-5,20,-6,OBSIDIAN:0)
Block(-5,20,-5,STEP:8)
Block(-5,20,-4,STEP:8)
RandomBlock(-5,20,-3,CONCRETE:7,60,quark:iron_plate:1,20,STAINED_CLAY:12,15,STAINED_CLAY:15,5,AIR,7,IRON_BARS,12,CONCRETE:7,100)
Block(-5,20,-2,OBSIDIAN:0)
Block(-5,20,-1,STAINED_GLASS_PANE:15)
Block(-5,20,3,STAINED_GLASS_PANE:15)
Block(-5,20,7,STAINED_GLASS_PANE:15)
Block(-5,21,-7,CONCRETE:0)
Block(-5,21,-6,OBSIDIAN:0)
RandomBlock(-5,21,-5,CONCRETE:7,60,quark:iron_plate:1,20,STAINED_CLAY:12,15,STAINED_CLAY:15,5,AIR,7,IRON_BARS,12,CONCRETE:7,100)
RandomBlock(-5,21,-4,CONCRETE:7,60,quark:iron_plate:1,20,STAINED_CLAY:12,15,STAINED_CLAY:15,5,AIR,7,IRON_BARS,12,CONCRETE:7,100)
RandomBlock(-5,21,-3,CONCRETE:7,60,quark:iron_plate:1,20,STAINED_CLAY:12,15,STAINED_CLAY:15,5,AIR,7,IRON_BARS,12,CONCRETE:7,100)
Block(-5,21,-2,OBSIDIAN:0)
Block(-5,21,-1,STAINED_GLASS_PANE:15)
Block(-5,21,3,STAINED_GLASS_PANE:15)
Block(-5,21,4,QUARTZ_STAIRS:5)
Block(-5,21,5,QUARTZ_STAIRS:5)
Block(-5,21,7,CONCRETE:0)
Block(-5,21,8,STEP:8)
Block(-5,22,-7,CONCRETE:0)
Block(-5,22,-6,OBSIDIAN:0)
Block(-5,22,-5,OBSIDIAN:0)
Block(-5,22,-4,OBSIDIAN:0)
Block(-5,22,-3,OBSIDIAN:0)
Block(-5,22,-2,OBSIDIAN:0)
Block(-5,22,-1,STAINED_GLASS_PANE:15)
Block(-5,22,3,STAINED_GLASS_PANE:15)
Block(-5,22,4,QUARTZ_STAIRS:0)
Block(-5,22,5,QUARTZ_STAIRS:0)
Block(-5,22,7,STAINED_GLASS_PANE:15)
RandomBlock(-5,22,8,CONCRETE:7,60,quark:iron_plate:1,20,STAINED_CLAY:12,15,STAINED_CLAY:15,5,AIR,7,IRON_BARS,12,CONCRETE:7,100)
Block(-5,23,-7,CONCRETE:0)
Block(-5,23,-6,CONCRETE:0)
Block(-5,23,-5,CONCRETE:0)
Block(-5,23,-4,CONCRETE:0)
Block(-5,23,-3,CONCRETE:0)
Block(-5,23,-2,OBSIDIAN:0)
Block(-5,23,-1,CONCRETE:0)
Block(-5,23,0,CONCRETE:0)
Block(-5,23,3,STAINED_GLASS_PANE:15)
Block(-5,23,6,CONCRETE:0)
Block(-5,23,7,CONCRETE:0)
Block(-5,23,8,OBSIDIAN:0)
Block(-5,24,-2,STEP:0)
RandomBlock(-5,24,-1,CONCRETE:7,60,quark:iron_plate:1,20,STAINED_CLAY:12,15,STAINED_CLAY:15,5,AIR,7,IRON_BARS,12,CONCRETE:7,100)
Block(-5,24,0,CONCRETE:0)
Block(-5,24,3,CONCRETE:0)
Block(-5,24,6,CONCRETE:0)
Block(-5,24,7,CONCRETE:0)
Block(-5,24,8,CONCRETE:0)
Block(-5,25,-1,STAINED_GLASS_PANE:15)
Block(-5,25,3,STAINED_GLASS_PANE:15)
Block(-5,25,7,STAINED_GLASS_PANE:15)
Block(-5,26,-1,STAINED_GLASS_PANE:15)
Block(-5,26,1,QUARTZ_STAIRS:4)
Block(-5,26,2,QUARTZ_STAIRS:4)
Block(-5,26,3,STAINED_GLASS_PANE:15)
Block(-5,26,7,STAINED_GLASS_PANE:15)
Block(-5,27,-1,STAINED_GLASS_PANE:15)
Block(-5,27,1,QUARTZ_STAIRS:1)
Block(-5,27,2,QUARTZ_STAIRS:1)
Block(-5,27,3,STAINED_GLASS_PANE:15)
Block(-5,27,7,STAINED_GLASS_PANE:15)
Block(-5,28,-1,STEP:8)
Block(-5,28,3,STAINED_GLASS_PANE:15)
Block(-5,28,7,STAINED_GLASS_PANE:15)
Block(-5,29,-3,STEP:8)
Block(-5,29,-2,CONCRETE:0)
Block(-5,29,-1,CONCRETE:0)
Block(-5,29,0,CONCRETE:0)
Block(-5,29,3,CONCRETE:0)
Block(-5,29,4,STEP:8)
Block(-5,29,5,CONCRETE:0)
Block(-5,29,6,STEP:8)
Block(-5,29,7,CONCRETE:0)
Block(-5,29,8,STEP:8)
Block(-5,30,-3,IRON_FENCE:0)
Block(-5,30,-2,STEP:7)
RandomBlock(-5,30,-1,CONCRETE:7,60,quark:iron_plate:1,20,STAINED_CLAY:12,15,STAINED_CLAY:15,5,AIR,7,IRON_BARS,12,CONCRETE:7,100)
Block(-5,30,3,STAINED_GLASS_PANE:15)
Block(-5,30,5,STAINED_GLASS_PANE:15)
Block(-5,30,6,CARPET:15)
Block(-5,30,7,WOOD_STEP:13)
Block(-5,30,8,CARPET:15)
Block(-5,31,-1,STAINED_GLASS_PANE:15)
Block(-5,31,3,STAINED_GLASS_PANE:15)
Block(-5,31,5,STAINED_GLASS_PANE:15)
Block(-5,31,7,CARPET:14)
Block(-5,32,-2,STEP:8)
Block(-5,32,-1,STAINED_GLASS_PANE:15)
Block(-5,32,3,CONCRETE:0)
Block(-5,32,5,STAINED_GLASS_PANE:15)
Block(-5,33,-3,STEP:8)
Block(-5,33,-2,CONCRETE:0)
Block(-5,33,-1,STEP:8)
Block(-5,33,0,STEP:8)
Block(-5,33,1,STEP:8)
Block(-5,33,2,STEP:8)
Block(-5,33,3,DOUBLE_STEP:0)
Block(-5,33,4,STEP:8)
Block(-5,33,5,STEP:8)
Block(-5,33,6,STEP:8)
Block(-5,33,7,STEP:8)
Block(-5,33,8,STEP:8)
Block(-5,34,-3,IRON_FENCE:0)
Block(-5,37,4,STEP:15)
Block(-5,37,7,CONCRETE:0)
Block(-5,38,0,CONCRETE:0)
Block(-5,38,2,CONCRETE:0)
Block(-5,38,4,CONCRETE:0)
Block(-5,38,7,QUARTZ_STAIRS:1)
Block(-5,39,0,QUARTZ_STAIRS:1)
Block(-5,39,2,COBBLE_WALL:0)
RandomBlock(-4,0,-7,CONCRETE:7,60,quark:iron_plate:1,20,STAINED_CLAY:12,15,STAINED_CLAY:15,5,AIR,7,IRON_BARS,12,CONCRETE:7,100)
RandomBlock(-4,0,-6,CONCRETE:7,60,quark:iron_plate:1,20,STAINED_CLAY:12,15,STAINED_CLAY:15,5,AIR,7,IRON_BARS,12,CONCRETE:7,100)
RandomBlock(-4,0,-5,CONCRETE:7,60,quark:iron_plate:1,20,STAINED_CLAY:12,15,STAINED_CLAY:15,5,AIR,7,IRON_BARS,12,CONCRETE:7,100)
RandomBlock(-4,0,-4,CONCRETE:7,60,quark:iron_plate:1,20,STAINED_CLAY:12,15,STAINED_CLAY:15,5,AIR,7,IRON_BARS,12,CONCRETE:7,100)
RandomBlock(-4,0,-3,CONCRETE:7,60,quark:iron_plate:1,20,STAINED_CLAY:12,15,STAINED_CLAY:15,5,AIR,7,IRON_BARS,12,CONCRETE:7,100)
RandomBlock(-4,0,-2,CONCRETE:7,60,quark:iron_plate:1,20,STAINED_CLAY:12,15,STAINED_CLAY:15,5,AIR,7,IRON_BARS,12,CONCRETE:7,100)
RandomBlock(-4,0,-1,CONCRETE:7,60,quark:iron_plate:1,20,STAINED_CLAY:12,15,STAINED_CLAY:15,5,AIR,7,IRON_BARS,12,CONCRETE:7,100)
RandomBlock(-4,0,0,CONCRETE:7,60,quark:iron_plate:1,20,STAINED_CLAY:12,15,STAINED_CLAY:15,5,AIR,7,IRON_BARS,12,CONCRETE:7,100)
RandomBlock(-4,0,1,CONCRETE:7,60,quark:iron_plate:1,20,STAINED_CLAY:12,15,STAINED_CLAY:15,5,AIR,7,IRON_BARS,12,CONCRETE:7,100)
RandomBlock(-4,0,2,CONCRETE:7,60,quark:iron_plate:1,20,STAINED_CLAY:12,15,STAINED_CLAY:15,5,AIR,7,IRON_BARS,12,CONCRETE:7,100)
RandomBlock(-4,0,3,CONCRETE:7,60,quark:iron_plate:1,20,STAINED_CLAY:12,15,STAINED_CLAY:15,5,AIR,7,IRON_BARS,12,CONCRETE:7,100)
RandomBlock(-4,0,4,CONCRETE:7,60,quark:iron_plate:1,20,STAINED_CLAY:12,15,STAINED_CLAY:15,5,AIR,7,IRON_BARS,12,CONCRETE:7,100)
RandomBlock(-4,0,5,CONCRETE:7,60,quark:iron_plate:1,20,STAINED_CLAY:12,15,STAINED_CLAY:15,5,AIR,7,IRON_BARS,12,CONCRETE:7,100)
RandomBlock(-4,0,6,CONCRETE:7,60,quark:iron_plate:1,20,STAINED_CLAY:12,15,STAINED_CLAY:15,5,AIR,7,IRON_BARS,12,CONCRETE:7,100)
RandomBlock(-4,0,7,CONCRETE:7,60,quark:iron_plate:1,20,STAINED_CLAY:12,15,STAINED_CLAY:15,5,AIR,7,IRON_BARS,12,CONCRETE:7,100)
RandomBlock(-4,0,8,CONCRETE:7,60,quark:iron_plate:1,20,STAINED_CLAY:12,15,STAINED_CLAY:15,5,AIR,7,IRON_BARS,12,CONCRETE:7,100)
Block(-4,1,-7,OBSIDIAN:0)
Block(-4,1,-6,OBSIDIAN:0)
Block(-4,1,-5,OBSIDIAN:0)
Block(-4,1,-4,OBSIDIAN:0)
Block(-4,1,-3,OBSIDIAN:0)
Block(-4,1,-2,OBSIDIAN:0)
Block(-4,1,-1,OBSIDIAN:0)
Block(-4,1,0,OBSIDIAN:0)
Block(-4,1,1,OBSIDIAN:0)
Block(-4,1,2,OBSIDIAN:0)
Block(-4,1,3,OBSIDIAN:0)
Block(-4,1,4,OBSIDIAN:0)
Block(-4,1,5,OBSIDIAN:0)
Block(-4,1,6,OBSIDIAN:0)
Block(-4,1,7,OBSIDIAN:0)
Block(-4,1,8,OBSIDIAN:0)
Block(-4,2,-7,OBSIDIAN:0)
Block(-4,2,-6,OBSIDIAN:0)
Block(-4,2,-5,OBSIDIAN:0)
Block(-4,2,-4,OBSIDIAN:0)
Block(-4,2,-3,OBSIDIAN:0)
Block(-4,2,-2,OBSIDIAN:0)
Block(-4,2,-1,OBSIDIAN:0)
Block(-4,2,0,OBSIDIAN:0)
Block(-4,2,1,OBSIDIAN:0)
Block(-4,2,2,OBSIDIAN:0)
Block(-4,2,3,OBSIDIAN:0)
Block(-4,2,4,OBSIDIAN:0)
Block(-4,2,5,OBSIDIAN:0)
Block(-4,2,6,OBSIDIAN:0)
Block(-4,2,7,OBSIDIAN:0)
Block(-4,2,8,OBSIDIAN:0)
Block(-4,3,-7,STATIONARY_LAVA:0)
Block(-4,3,-6,STATIONARY_LAVA:0)
Block(-4,3,-5,STATIONARY_LAVA:0)
Block(-4,3,-4,STATIONARY_LAVA:0)
Block(-4,3,-3,STATIONARY_LAVA:0)
Block(-4,3,-2,STATIONARY_LAVA:0)
Block(-4,3,-1,STATIONARY_LAVA:0)
Block(-4,3,0,STATIONARY_LAVA:0)
Block(-4,3,1,STATIONARY_LAVA:0)
Block(-4,3,2,STATIONARY_LAVA:0)
Block(-4,3,3,STATIONARY_LAVA:0)
Block(-4,3,4,STATIONARY_LAVA:0)
Block(-4,3,5,STATIONARY_LAVA:0)
Block(-4,3,6,STATIONARY_LAVA:0)
Block(-4,3,7,STATIONARY_LAVA:0)
Block(-4,3,8,STATIONARY_LAVA:0)
Block(-4,4,-7,OBSIDIAN:0)
Block(-4,4,-6,OBSIDIAN:0)
Block(-4,4,-5,OBSIDIAN:0)
Block(-4,4,-4,OBSIDIAN:0)
Block(-4,4,-3,OBSIDIAN:0)
Block(-4,4,-2,OBSIDIAN:0)
Block(-4,4,-1,OBSIDIAN:0)
Block(-4,4,0,OBSIDIAN:0)
Block(-4,4,1,OBSIDIAN:0)
Block(-4,4,2,OBSIDIAN:0)
Block(-4,4,3,OBSIDIAN:0)
Block(-4,4,4,OBSIDIAN:0)
Block(-4,4,5,OBSIDIAN:0)
Block(-4,4,6,OBSIDIAN:0)
Block(-4,4,7,OBSIDIAN:0)
Block(-4,4,8,OBSIDIAN:0)
Block(-4,5,-7,STATIONARY_LAVA:0)
Block(-4,5,-6,OBSIDIAN:0)
Block(-4,5,-5,STATIONARY_LAVA:0)
Block(-4,5,-4,STATIONARY_LAVA:0)
Block(-4,5,-3,STATIONARY_LAVA:0)
Block(-4,5,-2,STATIONARY_LAVA:0)
Block(-4,5,-1,STATIONARY_LAVA:0)
Block(-4,5,0,OBSIDIAN:0)
Block(-4,5,1,IRON_PLATE:0)
Block(-4,5,2,GOLD_BLOCK:0)
RandomBlock(-4,5,3,GOLD_BLOCK,40,MOB_SPAWNER:0,../../DestructionLayers/Parasites/parasite_multi.nbt,20,CHEST:2,../../../../../Chests/Loot/simple_dungeon.nbt,10,CHEST:2,../../../../../Chests/Loot/gem_loot.nbt,10,CHEST:2,../../../../../Chests/Loot/desert_pyramid.nbt,5,CHEST:2,../../../../../Chests/Loot/jungle_temple.nbt,5,CHEST:2,../../../../../Chests/Loot/stronghold_library.nbt,10,CHEST:2,../../../../../Chests/Loot/woodland_mansion.nbt,10,CHEST:2,../../../../../Chests/Loot/end_city_treasure.nbt,10,CHEST:2,../../../../../Chests/RLCraft/IceAndFire/fire_dragon_roost_chest.nbt,5,CHEST:2,../../../../../Chests/lore/moderncity.nbt,5,chest:2,../../../../../Chests/RLCraft/IceAndFire/ice_dragon_roost_chest.nbt,5,chest:2,../../../../../Chests/lore/moderncity.nbt,2,chest:2,../../../../../Chests/RLCraft/IceAndFire/lightning_dragon_roost_chest.nbt,5,chest:2,../../../../../Chests/loot/moderncity_epic_loot.nbt,100)
RandomBlock(-4,5,4,emerald_ore,50,gold_ore,35,iron_ore,100)
Block(-4,5,5,IRON_PLATE:0)
Block(-4,5,6,IRON_PLATE:0)
Block(-4,5,7,IRON_PLATE:0)
Block(-4,5,8,IRON_PLATE:0)
Block(-4,6,-7,STATIONARY_LAVA:0)
Block(-4,6,-6,OBSIDIAN:0)
Block(-4,6,-5,STATIONARY_LAVA:0)
Block(-4,6,-4,STATIONARY_LAVA:0)
Block(-4,6,-3,STATIONARY_LAVA:0)
Block(-4,6,-2,STATIONARY_LAVA:0)
Block(-4,6,-1,STATIONARY_LAVA:0)
Block(-4,6,0,OBSIDIAN:0)
Block(-4,6,2,STEP:8)
Block(-4,6,3,STEP:8)
Block(-4,6,4,STEP:8)
Block(-4,7,-7,STATIONARY_LAVA:0)
Block(-4,7,-6,OBSIDIAN:0)
Block(-4,7,-5,STATIONARY_LAVA:0)
Block(-4,7,-4,STATIONARY_LAVA:0)
Block(-4,7,-3,STATIONARY_LAVA:0)
Block(-4,7,-2,STATIONARY_LAVA:0)
Block(-4,7,-1,STATIONARY_LAVA:0)
Block(-4,7,0,OBSIDIAN:0)
RandomBlock(-4,7,2,CHEST:2,../../../../../Chests/Loot/simple_dungeon.nbt,10,CHEST:2,../../../../../Chests/Loot/gem_loot.nbt,10,CHEST:2,../../../../../Chests/Loot/desert_pyramid.nbt,5,CHEST:2,../../../../../Chests/Loot/jungle_temple.nbt,5,CHEST:2,../../../../../Chests/Loot/stronghold_library.nbt,10,CHEST:2,../../../../../Chests/Loot/woodland_mansion.nbt,10,CHEST:2,../../../../../Chests/Loot/end_city_treasure.nbt,10,CHEST:2,../../../../../Chests/RLCraft/IceAndFire/fire_dragon_roost_chest.nbt,5,CHEST:2,../../../../../Chests/lore/moderncity.nbt,5,chest:2,../../../../../Chests/RLCraft/IceAndFire/ice_dragon_roost_chest.nbt,5,chest:2,../../../../../Chests/lore/moderncity.nbt,2,chest:2,../../../../../Chests/RLCraft/IceAndFire/lightning_dragon_roost_chest.nbt,5,chest:2,../../../../../Chests/loot/moderncity_epic_loot.nbt,100)
Block(-4,7,3,GOLD_BLOCK:0)
RandomBlock(-4,7,4,GOLD_BLOCK,40,MOB_SPAWNER:0,../../DestructionLayers/Parasites/parasite_multi.nbt,20,CHEST:2,../../../../../Chests/Loot/simple_dungeon.nbt,10,CHEST:2,../../../../../Chests/Loot/gem_loot.nbt,10,CHEST:2,../../../../../Chests/Loot/desert_pyramid.nbt,5,CHEST:2,../../../../../Chests/Loot/jungle_temple.nbt,5,CHEST:2,../../../../../Chests/Loot/stronghold_library.nbt,10,CHEST:2,../../../../../Chests/Loot/woodland_mansion.nbt,10,CHEST:2,../../../../../Chests/Loot/end_city_treasure.nbt,10,CHEST:2,../../../../../Chests/RLCraft/IceAndFire/fire_dragon_roost_chest.nbt,5,CHEST:2,../../../../../Chests/lore/moderncity.nbt,5,chest:2,../../../../../Chests/RLCraft/IceAndFire/ice_dragon_roost_chest.nbt,5,chest:2,../../../../../Chests/lore/moderncity.nbt,2,chest:2,../../../../../Chests/RLCraft/IceAndFire/lightning_dragon_roost_chest.nbt,5,chest:2,../../../../../Chests/loot/moderncity_epic_loot.nbt,100)
Block(-4,8,-7,STATIONARY_LAVA:0)
Block(-4,8,-6,OBSIDIAN:0)
Block(-4,8,-5,STATIONARY_LAVA:0)
Block(-4,8,-4,STATIONARY_LAVA:0)
Block(-4,8,-3,STATIONARY_LAVA:0)
Block(-4,8,-2,STATIONARY_LAVA:0)
Block(-4,8,-1,STATIONARY_LAVA:0)
Block(-4,8,0,OBSIDIAN:0)
Block(-4,8,2,STEP:8)
Block(-4,8,3,STEP:8)
Block(-4,8,4,STEP:8)
Block(-4,8,6,STEP:8)
Block(-4,8,7,STEP:8)
Block(-4,9,-7,STATIONARY_LAVA:0)
Block(-4,9,-6,OBSIDIAN:0)
Block(-4,9,-5,STATIONARY_LAVA:0)
Block(-4,9,-4,STATIONARY_LAVA:0)
Block(-4,9,-3,STATIONARY_LAVA:0)
Block(-4,9,-2,STATIONARY_LAVA:0)
Block(-4,9,-1,STATIONARY_LAVA:0)
Block(-4,9,0,OBSIDIAN:0)
RandomBlock(-4,9,2,emerald_ore,50,gold_ore,35,iron_ore,100)
RandomBlock(-4,9,3,AIR:0,20,TNT:0,100)
RandomBlock(-4,9,4,emerald_ore,50,gold_ore,35,iron_ore,100)
RandomBlock(-4,9,6,AIR:0,20,TNT:0,100)
RandomBlock(-4,9,7,AIR:0,20,TNT:0,100)
Block(-4,10,-7,STATIONARY_LAVA:0)
Block(-4,10,-6,OBSIDIAN:0)
Block(-4,10,-5,STATIONARY_LAVA:0)
Block(-4,10,-4,STATIONARY_LAVA:0)
Block(-4,10,-3,STATIONARY_LAVA:0)
Block(-4,10,-2,STATIONARY_LAVA:0)
Block(-4,10,-1,STATIONARY_LAVA:0)
Block(-4,10,0,OBSIDIAN:0)
Block(-4,10,1,STEP:8)
Block(-4,10,2,STEP:8)
Block(-4,10,3,STEP:8)
Block(-4,10,4,STEP:8)
Block(-4,10,5,STEP:8)
Block(-4,10,8,STEP:8)
Block(-4,11,-7,OBSIDIAN:0)
Block(-4,11,-6,OBSIDIAN:0)
Block(-4,11,-5,OBSIDIAN:0)
Block(-4,11,-4,OBSIDIAN:0)
Block(-4,11,-3,OBSIDIAN:0)
Block(-4,11,-2,OBSIDIAN:0)
Block(-4,11,-1,OBSIDIAN:0)
Block(-4,11,0,OBSIDIAN:0)
Block(-4,11,1,OBSIDIAN:0)
Block(-4,11,2,OBSIDIAN:0)
Block(-4,11,3,OBSIDIAN:0)
Block(-4,11,4,OBSIDIAN:0)
Block(-4,11,5,OBSIDIAN:0)
Block(-4,11,6,STAINED_GLASS:15)
Block(-4,11,7,STAINED_GLASS:15)
Block(-4,11,8,OBSIDIAN:0)
Block(-4,12,-7,STATIONARY_LAVA:0)
Block(-4,12,-6,STATIONARY_LAVA:0)
Block(-4,12,-5,STATIONARY_LAVA:0)
Block(-4,12,-4,STATIONARY_LAVA:0)
Block(-4,12,-3,STATIONARY_LAVA:0)
Block(-4,12,-2,STATIONARY_LAVA:0)
Block(-4,12,-1,STATIONARY_LAVA:0)
Block(-4,12,0,STATIONARY_LAVA:0)
Block(-4,12,1,STATIONARY_LAVA:0)
Block(-4,12,2,STATIONARY_LAVA:0)
Block(-4,12,3,STATIONARY_LAVA:0)
Block(-4,12,4,STATIONARY_LAVA:0)
Block(-4,12,5,STATIONARY_LAVA:0)
Block(-4,12,6,STATIONARY_LAVA:0)
Block(-4,12,7,STATIONARY_LAVA:0)
Block(-4,12,8,STATIONARY_LAVA:0)
Block(-4,13,-7,OBSIDIAN:0)
Block(-4,13,-6,OBSIDIAN:0)
Block(-4,13,-5,OBSIDIAN:0)
Block(-4,13,-4,OBSIDIAN:0)
Block(-4,13,-3,OBSIDIAN:0)
Block(-4,13,-2,OBSIDIAN:0)
Block(-4,13,-1,OBSIDIAN:0)
Block(-4,13,0,OBSIDIAN:0)
Block(-4,13,1,OBSIDIAN:0)
Block(-4,13,2,OBSIDIAN:0)
Block(-4,13,3,OBSIDIAN:0)
Block(-4,13,4,OBSIDIAN:0)
Block(-4,13,5,OBSIDIAN:0)
Block(-4,13,6,OBSIDIAN:0)
Block(-4,13,7,OBSIDIAN:0)
Block(-4,13,8,OBSIDIAN:0)
Block(-4,14,-7,OBSIDIAN:0)
Block(-4,14,-6,OBSIDIAN:0)
Block(-4,14,-5,OBSIDIAN:0)
Block(-4,14,-4,OBSIDIAN:0)
Block(-4,14,-3,OBSIDIAN:0)
Block(-4,14,-2,OBSIDIAN:0)
Block(-4,14,-1,OBSIDIAN:0)
Block(-4,14,0,OBSIDIAN:0)
Block(-4,14,1,OBSIDIAN:0)
Block(-4,14,2,OBSIDIAN:0)
Block(-4,14,3,OBSIDIAN:0)
Block(-4,14,4,OBSIDIAN:0)
Block(-4,14,5,OBSIDIAN:0)
Block(-4,14,6,OBSIDIAN:0)
Block(-4,14,7,OBSIDIAN:0)
Block(-4,14,8,OBSIDIAN:0)
Block(-4,15,-7,OBSIDIAN:0)
Block(-4,15,-6,OBSIDIAN:0)
Block(-4,15,-5,OBSIDIAN:0)
Block(-4,15,-4,OBSIDIAN:0)
Block(-4,15,-3,OBSIDIAN:0)
Block(-4,15,-2,OBSIDIAN:0)
Block(-4,15,-1,OBSIDIAN:0)
Block(-4,15,0,OBSIDIAN:0)
Block(-4,15,1,OBSIDIAN:0)
Block(-4,15,2,OBSIDIAN:0)
Block(-4,15,3,OBSIDIAN:0)
Block(-4,15,4,OBSIDIAN:0)
Block(-4,15,5,OBSIDIAN:0)
Block(-4,15,6,OBSIDIAN:0)
Block(-4,15,7,OBSIDIAN:0)
Block(-4,15,8,OBSIDIAN:0)
Block(-4,16,-7,OBSIDIAN:0)
Block(-4,16,-6,OBSIDIAN:0)
Block(-4,16,-5,OBSIDIAN:0)
Block(-4,16,-4,OBSIDIAN:0)
Block(-4,16,-3,OBSIDIAN:0)
Block(-4,16,-2,OBSIDIAN:0)
Block(-4,16,-1,OBSIDIAN:0)
Block(-4,16,0,OBSIDIAN:0)
Block(-4,16,1,OBSIDIAN:0)
Block(-4,16,2,OBSIDIAN:0)
Block(-4,16,3,OBSIDIAN:0)
Block(-4,16,4,OBSIDIAN:0)
Block(-4,16,5,OBSIDIAN:0)
Block(-4,16,6,OBSIDIAN:0)
Block(-4,16,7,OBSIDIAN:0)
Block(-4,16,8,OBSIDIAN:0)
RandomBlock(-4,17,-7,CONCRETE:7,60,quark:iron_plate:1,20,STAINED_CLAY:12,15,STAINED_CLAY:15,5,AIR,7,IRON_BARS,12,CONCRETE:7,100)
RandomBlock(-4,17,-6,CONCRETE:7,60,quark:iron_plate:1,20,STAINED_CLAY:12,15,STAINED_CLAY:15,5,AIR,7,IRON_BARS,12,CONCRETE:7,100)
RandomBlock(-4,17,-5,CONCRETE:7,60,quark:iron_plate:1,20,STAINED_CLAY:12,15,STAINED_CLAY:15,5,AIR,7,IRON_BARS,12,CONCRETE:7,100)
RandomBlock(-4,17,-4,CONCRETE:7,60,quark:iron_plate:1,20,STAINED_CLAY:12,15,STAINED_CLAY:15,5,AIR,7,IRON_BARS,12,CONCRETE:7,100)
RandomBlock(-4,17,-3,CONCRETE:7,60,quark:iron_plate:1,20,STAINED_CLAY:12,15,STAINED_CLAY:15,5,AIR,7,IRON_BARS,12,CONCRETE:7,100)
RandomBlock(-4,17,-2,CONCRETE:7,60,quark:iron_plate:1,20,STAINED_CLAY:12,15,STAINED_CLAY:15,5,AIR,7,IRON_BARS,12,CONCRETE:7,100)
RandomBlock(-4,17,-1,CONCRETE:7,60,quark:iron_plate:1,20,STAINED_CLAY:12,15,STAINED_CLAY:15,5,AIR,7,IRON_BARS,12,CONCRETE:7,100)
RandomBlock(-4,17,0,CONCRETE:7,60,quark:iron_plate:1,20,STAINED_CLAY:12,15,STAINED_CLAY:15,5,AIR,7,IRON_BARS,12,CONCRETE:7,100)
RandomBlock(-4,17,1,CONCRETE:7,60,quark:iron_plate:1,20,STAINED_CLAY:12,15,STAINED_CLAY:15,5,AIR,7,IRON_BARS,12,CONCRETE:7,100)
RandomBlock(-4,17,2,CONCRETE:7,60,quark:iron_plate:1,20,STAINED_CLAY:12,15,STAINED_CLAY:15,5,AIR,7,IRON_BARS,12,CONCRETE:7,100)
RandomBlock(-4,17,3,CONCRETE:7,60,quark:iron_plate:1,20,STAINED_CLAY:12,15,STAINED_CLAY:15,5,AIR,7,IRON_BARS,12,CONCRETE:7,100)
RandomBlock(-4,17,4,CONCRETE:7,60,quark:iron_plate:1,20,STAINED_CLAY:12,15,STAINED_CLAY:15,5,AIR,7,IRON_BARS,12,CONCRETE:7,100)
RandomBlock(-4,17,5,CONCRETE:7,60,quark:iron_plate:1,20,STAINED_CLAY:12,15,STAINED_CLAY:15,5,AIR,7,IRON_BARS,12,CONCRETE:7,100)
RandomBlock(-4,17,6,CONCRETE:7,60,quark:iron_plate:1,20,STAINED_CLAY:12,15,STAINED_CLAY:15,5,AIR,7,IRON_BARS,12,CONCRETE:7,100)
RandomBlock(-4,17,7,CONCRETE:7,60,quark:iron_plate:1,20,STAINED_CLAY:12,15,STAINED_CLAY:15,5,AIR,7,IRON_BARS,12,CONCRETE:7,100)
RandomBlock(-4,17,8,CONCRETE:7,60,quark:iron_plate:1,20,STAINED_CLAY:12,15,STAINED_CLAY:15,5,AIR,7,IRON_BARS,12,CONCRETE:7,100)
Block(-4,18,-7,CONCRETE:0)
Block(-4,18,-6,OBSIDIAN:0)
RandomBlock(-4,18,-3,CONCRETE:7,60,quark:iron_plate:1,20,STAINED_CLAY:12,15,STAINED_CLAY:15,5,AIR,7,IRON_BARS,12,CONCRETE:7,100)
Block(-4,18,-2,OBSIDIAN:0)
Block(-4,18,-1,CONCRETE:0)
Block(-4,18,3,CONCRETE:0)
Block(-4,18,7,CONCRETE:0)
Block(-4,19,-7,CONCRETE:0)
Block(-4,19,-6,OBSIDIAN:0)
RandomBlock(-4,19,-3,CONCRETE:7,60,quark:iron_plate:1,20,STAINED_CLAY:12,15,STAINED_CLAY:15,5,AIR,7,IRON_BARS,12,CONCRETE:7,100)
Block(-4,19,-2,OBSIDIAN:0)
Block(-4,19,-1,CONCRETE:0)
Block(-4,19,3,CONCRETE:0)
Block(-4,19,7,CONCRETE:0)
Block(-4,20,-7,CONCRETE:0)
Block(-4,20,-6,OBSIDIAN:0)
Block(-4,20,-5,STEP:8)
Block(-4,20,-4,STEP:8)
RandomBlock(-4,20,-3,CONCRETE:7,60,quark:iron_plate:1,20,STAINED_CLAY:12,15,STAINED_CLAY:15,5,AIR,7,IRON_BARS,12,CONCRETE:7,100)
Block(-4,20,-2,OBSIDIAN:0)
Block(-4,20,-1,CONCRETE:0)
Block(-4,20,3,CONCRETE:0)
Block(-4,20,7,CONCRETE:0)
Block(-4,21,-7,CONCRETE:0)
Block(-4,21,-6,OBSIDIAN:0)
RandomBlock(-4,21,-5,CONCRETE:7,60,quark:iron_plate:1,20,STAINED_CLAY:12,15,STAINED_CLAY:15,5,AIR,7,IRON_BARS,12,CONCRETE:7,100)
RandomBlock(-4,21,-4,CONCRETE:7,60,quark:iron_plate:1,20,STAINED_CLAY:12,15,STAINED_CLAY:15,5,AIR,7,IRON_BARS,12,CONCRETE:7,100)
RandomBlock(-4,21,-3,CONCRETE:7,60,quark:iron_plate:1,20,STAINED_CLAY:12,15,STAINED_CLAY:15,5,AIR,7,IRON_BARS,12,CONCRETE:7,100)
Block(-4,21,-2,OBSIDIAN:0)
Block(-4,21,-1,CONCRETE:0)
Block(-4,21,3,CONCRETE:0)
Block(-4,21,7,CONCRETE:0)
Block(-4,21,8,SMOOTH_STAIRS:7)
Block(-4,22,-7,CONCRETE:0)
Block(-4,22,-6,OBSIDIAN:0)
Block(-4,22,-5,OBSIDIAN:0)
Block(-4,22,-4,OBSIDIAN:0)
Block(-4,22,-3,OBSIDIAN:0)
Block(-4,22,-2,OBSIDIAN:0)
Block(-4,22,-1,CONCRETE:0)
Block(-4,22,3,CONCRETE:0)
Block(-4,22,4,QUARTZ_STAIRS:5)
Block(-4,22,5,QUARTZ_STAIRS:5)
Block(-4,22,7,CONCRETE:0)
RandomBlock(-4,22,8,CONCRETE:7,60,quark:iron_plate:1,20,STAINED_CLAY:12,15,STAINED_CLAY:15,5,AIR,7,IRON_BARS,12,CONCRETE:7,100)
Block(-4,23,-7,CONCRETE:0)
Block(-4,23,-6,CONCRETE:0)
Block(-4,23,-5,CONCRETE:0)
Block(-4,23,-4,CONCRETE:0)
Block(-4,23,-3,CONCRETE:0)
Block(-4,23,-2,OBSIDIAN:0)
Block(-4,23,-1,CONCRETE:0)
Block(-4,23,0,CONCRETE:0)
Block(-4,23,3,CONCRETE:0)
Block(-4,23,4,QUARTZ_STAIRS:0)
Block(-4,23,5,QUARTZ_STAIRS:0)
Block(-4,23,6,CONCRETE:0)
Block(-4,23,7,CONCRETE:0)
Block(-4,23,8,OBSIDIAN:0)
Block(-4,24,-2,QUARTZ_STAIRS:2)
Block(-4,24,-1,CONCRETE:0)
Block(-4,24,0,CONCRETE:0)
Block(-4,24,3,CONCRETE:0)
