
#######################################################################
# +-----------------------------------------------------------------+ #
# |                            BO3 object                           | #
# +-----------------------------------------------------------------+ #
#######################################################################

Author: NLBlackHeavenNL

Description: No description given

Version: 3

SettingsMode: WriteWithoutComments


#######################################################################
# +-----------------------------------------------------------------+ #
# |                          Main settings                          | #
# +-----------------------------------------------------------------+ #
#######################################################################

Tree: true

Frequency: 1

Rarity: 100.0

RotateRandomly: false

SpawnHeight: highestSolidBlock

SpawnHeightOffset: -1

SpawnHeightVariance: 0

##############################
# Height Limits for the BO3. #
##############################

MinHeight: 0

MaxHeight: 255

######################
# Extrusion settings #
######################

ExtrudeMode: None

ExtrudeThroughBlocks: AIR

MaxBranchDepth: 10

ExcludedBiomes: All


#######################################################################
# +-----------------------------------------------------------------+ #
# |                      Source block settings                      | #
# +-----------------------------------------------------------------+ #
#######################################################################

SourceBlocks: AIR,GRASS,DIRT,biomesoplenty:dirt,biomesoplenty:grass,UNKNOWN_BLOCK

MaxPercentageOutsideSourceBlock: 0

OutsideSourceBlock: placeAnyway

DoReplaceBlocks: true

IsOTGPlus: false


#######################################################################
# +-----------------------------------------------------------------+ #
# |                              Blocks                             | #
# +-----------------------------------------------------------------+ #
#######################################################################

Block(-2,5,0,dynamictreesbop:leaves3:12)
Block(-2,6,0,dynamictreesbop:leaves3:12)
Block(-2,6,1,dynamictreesbop:leaves3:12)
Block(-2,7,0,dynamictreesbop:leaves3:12)
Block(-2,7,1,dynamictreesbop:leaves3:12)
Block(-2,7,2,dynamictreesbop:leaves3:12)
Block(-2,8,1,dynamictreesbop:leaves3:12)
Block(-1,3,0,dynamictreesbop:willowbranch)
Block(-1,3,1,dynamictreesbop:willowbranch:2)
Block(-1,4,0,dynamictreesbop:leaves3:15)
Block(-1,4,1,dynamictreesbop:willowbranch:1)
Block(-1,5,-1,dynamictreesbop:leaves3:12)
Block(-1,5,0,dynamictreesbop:leaves3:15)
Block(-1,5,1,dynamictreesbop:willowbranch)
Block(-1,6,-1,dynamictreesbop:leaves3:12)
Block(-1,6,0,dynamictreesbop:leaves3:14)
Block(-1,6,1,dynamictreesbop:leaves3:15)
Block(-1,6,2,dynamictreesbop:leaves3:12)
Block(-1,6,3,dynamictreesbop:leaves3:12)
Block(-1,6,4,dynamictreesbop:leaves3:12)
Block(-1,7,-1,dynamictreesbop:leaves3:12)
Block(-1,7,0,dynamictreesbop:leaves3:13)
Block(-1,7,1,dynamictreesbop:leaves3:14)
Block(-1,7,2,dynamictreesbop:leaves3:13)
Block(-1,7,3,dynamictreesbop:leaves3:12)
Block(-1,7,4,dynamictreesbop:leaves3:12)
Block(-1,8,0,dynamictreesbop:leaves3:12)
Block(-1,8,1,dynamictreesbop:leaves3:13)
Block(-1,8,2,dynamictreesbop:leaves3:12)
Block(-1,9,1,dynamictreesbop:leaves3:12)
Block(0,3,0,dynamictreesbop:leaves3:15)
Block(0,3,1,dynamictreesbop:willowbranch:2)
Block(0,4,-1,dynamictreesbop:leaves3:12)
Block(0,4,0,dynamictreesbop:leaves3:14)
Block(0,5,-1,dynamictreesbop:leaves3:14)
Block(0,5,0,dynamictreesbop:leaves3:15)
Block(0,6,-1,dynamictreesbop:leaves3:12)
Block(0,6,0,dynamictreesbop:leaves3:14)
Block(0,6,3,dynamictreesbop:leaves3:15)
Block(0,6,4,dynamictreesbop:leaves3:14)
Block(0,6,5,dynamictreesbop:leaves3:12)
Block(0,7,-1,dynamictreesbop:leaves3:12)
Block(0,7,0,dynamictreesbop:leaves3:14)
Block(0,7,1,dynamictreesbop:leaves3:15)
Block(0,7,2,dynamictreesbop:leaves3:14)
Block(0,7,3,dynamictreesbop:leaves3:14)
Block(0,7,4,dynamictreesbop:leaves3:13)
Block(0,7,5,dynamictreesbop:leaves3:12)
Block(0,8,-1,dynamictreesbop:leaves3:12)
Block(0,8,0,dynamictreesbop:leaves3:13)
Block(0,8,1,dynamictreesbop:leaves3:14)
Block(0,8,2,dynamictreesbop:leaves3:13)
Block(0,8,3,dynamictreesbop:leaves3:12)
Block(0,8,4,dynamictreesbop:leaves3:12)
Block(0,9,0,dynamictreesbop:leaves3:12)
Block(0,9,1,dynamictreesbop:leaves3:12)
Block(0,9,2,dynamictreesbop:leaves3:12)
Block(1,0,1,dynamictrees:rootydirt)
Block(1,1,1,dynamictreesbop:willowbranch:5)
Block(1,2,1,dynamictreesbop:willowbranch:5)
Block(1,3,0,dynamictreesbop:willowbranch)
Block(1,3,1,dynamictreesbop:willowbranch:4)
Block(1,3,2,dynamictreesbop:willowbranch:1)
Block(1,3,3,dynamictreesbop:willowbranch)
Block(1,4,-1,dynamictreesbop:leaves3:12)
Block(1,4,0,dynamictreesbop:leaves3:15)
Block(1,4,1,dynamictreesbop:willowbranch:2)
Block(1,4,3,dynamictreesbop:leaves3:15)
Block(1,5,-2,dynamictreesbop:leaves3:12)
Block(1,5,-1,dynamictreesbop:leaves3:15)
Block(1,5,0,dynamictreesbop:willowbranch)
Block(1,5,1,dynamictreesbop:willowbranch:2)
Block(1,5,3,dynamictreesbop:leaves3:15)
Block(1,6,-2,dynamictreesbop:leaves3:12)
Block(1,6,-1,dynamictreesbop:leaves3:14)
Block(1,6,0,dynamictreesbop:leaves3:15)
Block(1,6,1,dynamictreesbop:willowbranch:1)
Block(1,6,2,dynamictreesbop:willowbranch:1)
Block(1,6,3,dynamictreesbop:willowbranch)
Block(1,6,4,dynamictreesbop:leaves3:15)
Block(1,6,5,dynamictreesbop:leaves3:12)
Block(1,7,-1,dynamictreesbop:leaves3:12)
Block(1,7,0,dynamictreesbop:leaves3:15)
Block(1,7,1,dynamictreesbop:willowbranch)
Block(1,7,2,dynamictreesbop:leaves3:15)
Block(1,7,3,dynamictreesbop:leaves3:15)
Block(1,7,4,dynamictreesbop:leaves3:14)
Block(1,7,5,dynamictreesbop:leaves3:12)
Block(1,8,-1,dynamictreesbop:leaves3:12)
Block(1,8,0,dynamictreesbop:leaves3:14)
Block(1,8,1,dynamictreesbop:leaves3:15)
Block(1,8,2,dynamictreesbop:leaves3:14)
Block(1,8,3,dynamictreesbop:leaves3:12)
Block(1,8,4,dynamictreesbop:leaves3:12)
Block(1,9,0,dynamictreesbop:leaves3:12)
Block(1,9,1,dynamictreesbop:leaves3:12)
Block(1,9,2,dynamictreesbop:leaves3:12)
Block(2,3,0,dynamictreesbop:leaves3:15)
Block(2,3,1,dynamictreesbop:willowbranch:1)
Block(2,4,0,dynamictreesbop:leaves3:12)
Block(2,5,-1,dynamictreesbop:leaves3:12)
Block(2,5,0,dynamictreesbop:leaves3:15)
Block(2,5,1,dynamictreesbop:willowbranch)
Block(2,6,-1,dynamictreesbop:leaves3:12)
Block(2,6,0,dynamictreesbop:leaves3:14)
Block(2,6,1,dynamictreesbop:leaves3:15)
Block(2,6,3,dynamictreesbop:leaves3:15)
Block(2,6,4,dynamictreesbop:leaves3:14)
Block(2,6,5,dynamictreesbop:leaves3:12)
Block(2,7,-1,dynamictreesbop:leaves3:12)
Block(2,7,0,dynamictreesbop:leaves3:14)
Block(2,7,1,dynamictreesbop:leaves3:15)
Block(2,7,2,dynamictreesbop:leaves3:14)
Block(2,7,3,dynamictreesbop:leaves3:14)
Block(2,7,4,dynamictreesbop:leaves3:13)
Block(2,7,5,dynamictreesbop:leaves3:12)
Block(2,8,-1,dynamictreesbop:leaves3:12)
Block(2,8,0,dynamictreesbop:leaves3:13)
Block(2,8,1,dynamictreesbop:leaves3:14)
Block(2,8,2,dynamictreesbop:leaves3:13)
Block(2,8,3,dynamictreesbop:leaves3:12)
Block(2,8,4,dynamictreesbop:leaves3:12)
Block(2,9,0,dynamictreesbop:leaves3:12)
Block(2,9,1,dynamictreesbop:leaves3:12)
Block(2,9,2,dynamictreesbop:leaves3:12)
Block(3,3,0,dynamictreesbop:leaves3:14)
Block(3,3,1,dynamictreesbop:willowbranch:1)
Block(3,4,-1,dynamictreesbop:leaves3:12)
Block(3,4,0,dynamictreesbop:leaves3:15)
Block(3,4,1,dynamictreesbop:willowbranch)
Block(3,5,-1,dynamictreesbop:leaves3:12)
Block(3,5,0,dynamictreesbop:leaves3:14)
Block(3,5,1,dynamictreesbop:leaves3:15)
Block(3,6,-1,dynamictreesbop:leaves3:12)
Block(3,6,0,dynamictreesbop:leaves3:13)
Block(3,6,1,dynamictreesbop:leaves3:14)
Block(3,6,2,dynamictreesbop:leaves3:12)
Block(3,6,3,dynamictreesbop:leaves3:12)
Block(3,6,4,dynamictreesbop:leaves3:12)
Block(3,7,0,dynamictreesbop:leaves3:12)
Block(3,7,1,dynamictreesbop:leaves3:12)
Block(3,7,2,dynamictreesbop:leaves3:12)
Block(3,7,3,dynamictreesbop:leaves3:12)
Block(3,7,4,dynamictreesbop:leaves3:12)
Block(3,8,0,dynamictreesbop:leaves3:12)
Block(3,8,1,dynamictreesbop:leaves3:12)
Block(3,8,2,dynamictreesbop:leaves3:12)
Block(4,3,0,dynamictreesbop:leaves3:13)
Block(4,4,-1,dynamictreesbop:leaves3:12)
Block(4,4,0,dynamictreesbop:leaves3:14)
Block(4,4,1,dynamictreesbop:leaves3:15)
Block(4,4,2,dynamictreesbop:leaves3:12)
Block(4,5,-1,dynamictreesbop:leaves3:12)
Block(4,5,0,dynamictreesbop:leaves3:13)
Block(4,5,1,dynamictreesbop:leaves3:14)
Block(4,5,2,dynamictreesbop:leaves3:12)
Block(4,6,0,dynamictreesbop:leaves3:12)
Block(4,6,1,dynamictreesbop:leaves3:13)
Block(4,6,2,dynamictreesbop:leaves3:12)
Block(4,7,1,dynamictreesbop:leaves3:12)
Block(5,4,0,dynamictreesbop:leaves3:12)
Block(5,4,1,dynamictreesbop:leaves3:12)
Block(5,5,0,dynamictreesbop:leaves3:12)
Block(5,5,1,dynamictreesbop:leaves3:12)
Block(5,6,1,dynamictreesbop:leaves3:12)

#######################################################################
# +-----------------------------------------------------------------+ #
# |                            BO3 checks                           | #
# +-----------------------------------------------------------------+ #
#######################################################################

BlockCheck(1,-1,1,GRASS,DIRT,UNKNOWN_BLOCK,biomesoplenty:grass,biomesoplenty:dirt)

#######################################################################
# +-----------------------------------------------------------------+ #
# |                             Branches                            | #
# +-----------------------------------------------------------------+ #
#######################################################################


#######################################################################
# +-----------------------------------------------------------------+ #
# |                             Entities                            | #
# +-----------------------------------------------------------------+ #
#######################################################################


#######################################################################
# +-----------------------------------------------------------------+ #
# |                            Particles                            | #
# +-----------------------------------------------------------------+ #
#######################################################################


#######################################################################
# +-----------------------------------------------------------------+ #
# |                             Spawners                            | #
# +-----------------------------------------------------------------+ #
#######################################################################


#######################################################################
# +-----------------------------------------------------------------+ #
# |                             ModData                             | #
# +-----------------------------------------------------------------+ #
#######################################################################

