
#######################################################################
# +-----------------------------------------------------------------+ #
# |                            BO4 object                           | #
# +-----------------------------------------------------------------+ #
#######################################################################

Author: NLBlackEagle

Description: No description given

SettingsMode: WriteDisable


#######################################################################
# +-----------------------------------------------------------------+ #
# |                          Main settings                          | #
# +-----------------------------------------------------------------+ #
#######################################################################

Frequency: 0

SpawnHeight: highestBlock

UseCenterForHighestBlock: true

##############################
# Height Limits for the BO4. #
##############################

MinHeight: 0

MaxHeight: 255

InheritBO3: 

InheritBO3Rotation: NORTH

OverrideChildSettings: true

OverrideParentHeight: false

CanOverride: true

BranchFrequency: 0

BranchFrequencyGroup: 

MustBeBelowOther: false

MustBeInside: 

CannotBeInside: 

ReplacesBO3: 

MustBeInsideWorldBorders: false

CanSpawnOnWater: true

SpawnOnWaterOnly: false

SpawnUnderWater: false

SpawnAtWaterLevel: false

HeightOffset: 0

RemoveAir: true

ReplaceAbove: 

ReplaceBelow: 

ReplaceWithBiomeBlocks: true

ReplaceWithSurfaceBlock: GRASS

ReplaceWithGroundBlock: DIRT

ReplaceWithStoneBlock: STONE

SmoothRadius: 0

SmoothHeightOffset: 0

SmoothStartTop: false

SmoothStartWood: false

SmoothingSurfaceBlock: 

SmoothingGroundBlock: 

BO3Group: 

IsSpawnPoint: false

DoReplaceBlocks: true


#######################################################################
# +-----------------------------------------------------------------+ #
# |                              Blocks                             | #
# +-----------------------------------------------------------------+ #
#######################################################################

Block(-8,0,-7,STAINED_CLAY:3)
Block(-8,0,-6,STAINED_CLAY:3)
Block(-8,0,-5,STAINED_CLAY:3)
Block(-8,0,-4,STAINED_CLAY:3)
Block(-8,0,-3,STAINED_CLAY:3)
Block(-8,0,-2,STAINED_CLAY:3)
Block(-8,0,-1,STAINED_CLAY:3)
Block(-8,0,0,STAINED_CLAY:3)
Block(-8,0,1,STAINED_CLAY:3)
Block(-8,0,2,STAINED_CLAY:3)
Block(-8,1,-7,STAINED_CLAY:3)
Block(-8,1,-6,STAINED_CLAY:3)
Block(-8,1,-5,STAINED_CLAY:3)
Block(-8,1,-4,STAINED_CLAY:3)
Block(-8,1,-3,STAINED_CLAY:3)
Block(-8,1,-2,STAINED_CLAY:3)
Block(-8,1,-1,STAINED_CLAY:3)
Block(-8,1,0,STAINED_CLAY:3)
Block(-8,2,-7,STAINED_CLAY:3)
Block(-8,2,-6,STAINED_CLAY:3)
Block(-8,2,-5,STAINED_CLAY:3)
Block(-8,2,-4,STAINED_CLAY:3)
Block(-8,2,-3,STAINED_CLAY:3)
Block(-8,2,-2,STAINED_CLAY:3)
Block(-8,2,-1,STAINED_CLAY:3)
Block(-8,3,-7,STAINED_CLAY:3)
Block(-8,3,-6,STAINED_CLAY:3)
Block(-8,3,-5,STAINED_CLAY:3)
Block(-8,3,-4,STAINED_CLAY:3)
Block(-8,3,-3,STAINED_CLAY:3)
Block(-8,3,-2,STAINED_CLAY:3)
Block(-8,4,-7,STAINED_CLAY:3)
Block(-8,4,-6,STAINED_CLAY:3)
Block(-8,4,-5,STAINED_CLAY:3)
Block(-8,4,-4,STAINED_CLAY:3)
Block(-8,4,-3,STAINED_CLAY:3)
Block(-8,5,-7,STAINED_CLAY:3)
Block(-8,5,-6,STAINED_CLAY:3)
Block(-8,5,-5,STAINED_CLAY:3)
Block(-8,5,-4,STAINED_CLAY:3)
Block(-8,6,-7,STAINED_CLAY:3)
Block(-8,6,-6,STAINED_CLAY:3)
Block(-8,6,-5,STAINED_CLAY:3)
Block(-8,7,-7,STAINED_CLAY:3)
Block(-8,7,-6,STAINED_CLAY:3)
Block(-8,8,-7,STAINED_CLAY:3)
Block(-7,0,-7,STAINED_CLAY:3)
Block(-7,0,-6,STAINED_CLAY:3)
Block(-7,0,-5,STAINED_CLAY:3)
Block(-7,0,-4,STAINED_CLAY:3)
Block(-7,0,-3,STAINED_CLAY:3)
Block(-7,0,-2,STAINED_CLAY:3)
Block(-7,0,-1,STAINED_CLAY:3)
Block(-7,0,0,STAINED_CLAY:3)
Block(-7,0,1,STAINED_CLAY:3)
Block(-7,0,2,STAINED_CLAY:3)
Block(-7,1,-7,STAINED_CLAY:3)
Block(-7,1,-6,STAINED_CLAY:3)
Block(-7,1,-5,STAINED_CLAY:3)
Block(-7,1,-4,STAINED_CLAY:3)
Block(-7,1,-3,STAINED_CLAY:3)
Block(-7,1,-2,STAINED_CLAY:3)
Block(-7,1,-1,STAINED_CLAY:3)
Block(-7,1,0,STAINED_CLAY:3)
Block(-7,1,1,STAINED_CLAY:3)
Block(-7,2,-7,STAINED_CLAY:3)
Block(-7,2,-6,STAINED_CLAY:3)
Block(-7,2,-5,STAINED_CLAY:3)
Block(-7,2,-4,STAINED_CLAY:3)
Block(-7,2,-3,STAINED_CLAY:3)
Block(-7,2,-2,STAINED_CLAY:3)
Block(-7,2,-1,STAINED_CLAY:3)
Block(-7,2,0,STAINED_CLAY:3)
Block(-7,3,-7,STAINED_CLAY:3)
Block(-7,3,-6,STAINED_CLAY:3)
Block(-7,3,-5,STAINED_CLAY:3)
Block(-7,3,-4,STAINED_CLAY:3)
Block(-7,3,-3,STAINED_CLAY:3)
Block(-7,3,-2,STAINED_CLAY:3)
Block(-7,4,-7,STAINED_CLAY:3)
Block(-7,4,-6,STAINED_CLAY:3)
Block(-7,4,-5,STAINED_CLAY:3)
Block(-7,4,-4,STAINED_CLAY:3)
Block(-7,4,-3,STAINED_CLAY:3)
Block(-7,5,-7,STAINED_CLAY:3)
Block(-7,5,-6,STAINED_CLAY:3)
Block(-7,5,-5,STAINED_CLAY:3)
Block(-7,5,-4,STAINED_CLAY:3)
Block(-7,6,-7,STAINED_CLAY:3)
Block(-7,6,-6,STAINED_CLAY:3)
Block(-7,6,-5,STAINED_CLAY:3)
Block(-7,7,-7,STAINED_CLAY:3)
Block(-7,7,-6,STAINED_CLAY:3)
Block(-7,8,-7,STAINED_CLAY:3)
Block(-6,0,-7,STAINED_CLAY:3)
Block(-6,0,-6,STAINED_CLAY:3)
Block(-6,0,-5,STAINED_CLAY:3)
Block(-6,0,-4,STAINED_CLAY:3)
Block(-6,0,-3,STAINED_CLAY:3)
Block(-6,0,-2,STAINED_CLAY:3)
Block(-6,0,-1,STAINED_CLAY:3)
Block(-6,0,0,STAINED_CLAY:3)
Block(-6,0,1,STAINED_CLAY:3)
Block(-6,0,2,STAINED_CLAY:3)
Block(-6,1,-7,STAINED_CLAY:3)
Block(-6,1,-6,STAINED_CLAY:3)
Block(-6,1,-5,STAINED_CLAY:3)
Block(-6,1,-4,STAINED_CLAY:3)
Block(-6,1,-3,STAINED_CLAY:3)
Block(-6,1,-2,STAINED_CLAY:3)
Block(-6,1,-1,STAINED_CLAY:3)
Block(-6,1,0,STAINED_CLAY:3)
Block(-6,1,1,STAINED_CLAY:3)
Block(-6,2,-7,STAINED_CLAY:3)
Block(-6,2,-6,STAINED_CLAY:3)
Block(-6,2,-5,STAINED_CLAY:3)
Block(-6,2,-4,STAINED_CLAY:3)
Block(-6,2,-3,STAINED_CLAY:3)
Block(-6,2,-2,STAINED_CLAY:3)
Block(-6,2,-1,STAINED_CLAY:3)
Block(-6,2,0,STAINED_CLAY:3)
Block(-6,3,-7,STAINED_CLAY:3)
Block(-6,3,-6,STAINED_CLAY:3)
Block(-6,3,-5,STAINED_CLAY:3)
Block(-6,3,-4,STAINED_CLAY:3)
Block(-6,3,-3,STAINED_CLAY:3)
Block(-6,3,-2,STAINED_CLAY:3)
Block(-6,3,-1,STAINED_CLAY:3)
Block(-6,4,-7,STAINED_CLAY:3)
Block(-6,4,-6,STAINED_CLAY:3)
Block(-6,4,-5,STAINED_CLAY:3)
Block(-6,4,-4,STAINED_CLAY:3)
Block(-6,4,-3,STAINED_CLAY:3)
Block(-6,4,-2,STAINED_CLAY:3)
Block(-6,5,-7,STAINED_CLAY:3)
Block(-6,5,-6,STAINED_CLAY:3)
Block(-6,5,-5,STAINED_CLAY:3)
Block(-6,5,-4,STAINED_CLAY:3)
Block(-6,5,-3,STAINED_CLAY:3)
Block(-6,6,-7,STAINED_CLAY:3)
Block(-6,6,-6,STAINED_CLAY:3)
Block(-6,6,-5,STAINED_CLAY:3)
Block(-6,7,-7,STAINED_CLAY:3)
Block(-6,7,-6,STAINED_CLAY:3)
Block(-6,8,-7,STAINED_CLAY:3)
Block(-5,0,-7,STAINED_CLAY:3)
Block(-5,0,-6,STAINED_CLAY:3)
Block(-5,0,-5,STAINED_CLAY:3)
Block(-5,0,-4,STAINED_CLAY:3)
Block(-5,0,-3,STAINED_CLAY:3)
Block(-5,0,-2,STAINED_CLAY:3)
Block(-5,0,-1,STAINED_CLAY:3)
Block(-5,0,0,STAINED_CLAY:3)
Block(-5,0,1,STAINED_CLAY:3)
Block(-5,0,2,STAINED_CLAY:3)
Block(-5,1,-7,STAINED_CLAY:3)
Block(-5,1,-6,STAINED_CLAY:3)
Block(-5,1,-5,STAINED_CLAY:3)
Block(-5,1,-4,STAINED_CLAY:3)
Block(-5,1,-3,STAINED_CLAY:3)
Block(-5,1,-2,STAINED_CLAY:3)
Block(-5,1,-1,STAINED_CLAY:3)
Block(-5,1,0,STAINED_CLAY:3)
Block(-5,1,1,STAINED_CLAY:3)
Block(-5,2,-7,STAINED_CLAY:3)
Block(-5,2,-6,STAINED_CLAY:3)
Block(-5,2,-5,STAINED_CLAY:3)
Block(-5,2,-4,STAINED_CLAY:3)
Block(-5,2,-3,STAINED_CLAY:3)
Block(-5,2,-2,STAINED_CLAY:3)
Block(-5,2,-1,STAINED_CLAY:3)
Block(-5,2,0,STAINED_CLAY:3)
Block(-5,3,-7,STAINED_CLAY:3)
Block(-5,3,-6,STAINED_CLAY:3)
Block(-5,3,-5,STAINED_CLAY:3)
Block(-5,3,-4,STAINED_CLAY:3)
Block(-5,3,-3,STAINED_CLAY:3)
Block(-5,3,-2,STAINED_CLAY:3)
Block(-5,3,-1,STAINED_CLAY:3)
Block(-5,4,-7,STAINED_CLAY:3)
Block(-5,4,-6,STAINED_CLAY:3)
Block(-5,4,-5,STAINED_CLAY:3)
Block(-5,4,-4,STAINED_CLAY:3)
Block(-5,4,-3,STAINED_CLAY:3)
Block(-5,4,-2,STAINED_CLAY:3)
Block(-5,5,-7,STAINED_CLAY:3)
Block(-5,5,-6,STAINED_CLAY:3)
Block(-5,5,-5,STAINED_CLAY:3)
Block(-5,5,-4,STAINED_CLAY:3)
Block(-5,5,-3,STAINED_CLAY:3)
Block(-5,6,-7,STAINED_CLAY:3)
Block(-5,6,-6,STAINED_CLAY:3)
Block(-5,6,-5,STAINED_CLAY:3)
Block(-5,6,-4,STAINED_CLAY:3)
Block(-5,7,-7,STAINED_CLAY:3)
Block(-5,7,-6,STAINED_CLAY:3)
Block(-5,7,-5,STAINED_CLAY:3)
Block(-5,8,-7,STAINED_CLAY:3)
Block(-4,0,-7,STAINED_CLAY:3)
Block(-4,0,-6,STAINED_CLAY:3)
Block(-4,0,-5,STAINED_CLAY:3)
Block(-4,0,-4,STAINED_CLAY:3)
Block(-4,0,-3,STAINED_CLAY:3)
Block(-4,0,-2,STAINED_CLAY:3)
Block(-4,0,-1,STAINED_CLAY:3)
Block(-4,0,0,STAINED_CLAY:3)
Block(-4,0,1,STAINED_CLAY:3)
Block(-4,0,2,STAINED_CLAY:3)
Block(-4,1,-7,STAINED_CLAY:3)
Block(-4,1,-6,STAINED_CLAY:3)
Block(-4,1,-5,STAINED_CLAY:3)
Block(-4,1,-4,STAINED_CLAY:3)
Block(-4,1,-3,STAINED_CLAY:3)
Block(-4,1,-2,STAINED_CLAY:3)
Block(-4,1,-1,STAINED_CLAY:3)
Block(-4,1,0,STAINED_CLAY:3)
Block(-4,1,1,STAINED_CLAY:3)
Block(-4,2,-7,STAINED_CLAY:3)
Block(-4,2,-6,STAINED_CLAY:3)
Block(-4,2,-5,STAINED_CLAY:3)
Block(-4,2,-4,STAINED_CLAY:3)
Block(-4,2,-3,STAINED_CLAY:3)
Block(-4,2,-2,STAINED_CLAY:3)
Block(-4,2,-1,STAINED_CLAY:3)
Block(-4,2,0,STAINED_CLAY:3)
Block(-4,3,-7,STAINED_CLAY:3)
Block(-4,3,-6,STAINED_CLAY:3)
Block(-4,3,-5,STAINED_CLAY:3)
Block(-4,3,-4,STAINED_CLAY:3)
Block(-4,3,-3,STAINED_CLAY:3)
Block(-4,3,-2,STAINED_CLAY:3)
Block(-4,3,-1,STAINED_CLAY:3)
Block(-4,4,-7,STAINED_CLAY:3)
Block(-4,4,-6,STAINED_CLAY:3)
Block(-4,4,-5,STAINED_CLAY:3)
Block(-4,4,-4,STAINED_CLAY:3)
Block(-4,4,-3,STAINED_CLAY:3)
Block(-4,4,-2,STAINED_CLAY:3)
Block(-4,5,-7,STAINED_CLAY:3)
Block(-4,5,-6,STAINED_CLAY:3)
Block(-4,5,-5,STAINED_CLAY:3)
Block(-4,5,-4,STAINED_CLAY:3)
Block(-4,5,-3,STAINED_CLAY:3)
Block(-4,6,-7,STAINED_CLAY:3)
Block(-4,6,-6,STAINED_CLAY:3)
Block(-4,6,-5,STAINED_CLAY:3)
Block(-4,6,-4,STAINED_CLAY:3)
Block(-4,7,-7,STAINED_CLAY:3)
Block(-4,7,-6,STAINED_CLAY:3)
Block(-4,7,-5,STAINED_CLAY:3)
Block(-4,8,-7,STAINED_CLAY:3)
Block(-4,8,-6,STAINED_CLAY:3)
Block(-4,9,-7,STAINED_CLAY:3)
Block(-3,0,-7,STAINED_CLAY:3)
Block(-3,0,-6,STAINED_CLAY:3)
Block(-3,0,-5,STAINED_CLAY:3)
Block(-3,0,-4,STAINED_CLAY:3)
Block(-3,0,-3,STAINED_CLAY:3)
Block(-3,0,-2,STAINED_CLAY:3)
Block(-3,0,-1,STAINED_CLAY:3)
Block(-3,0,0,STAINED_CLAY:3)
Block(-3,0,1,STAINED_CLAY:3)
Block(-3,0,2,STAINED_CLAY:3)
Block(-3,1,-7,STAINED_CLAY:3)
Block(-3,1,-6,STAINED_CLAY:3)
Block(-3,1,-5,STAINED_CLAY:3)
Block(-3,1,-4,STAINED_CLAY:3)
Block(-3,1,-3,STAINED_CLAY:3)
Block(-3,1,-2,STAINED_CLAY:3)
Block(-3,1,-1,STAINED_CLAY:3)
Block(-3,1,0,STAINED_CLAY:3)
Block(-3,1,1,STAINED_CLAY:3)
Block(-3,2,-7,STAINED_CLAY:3)
Block(-3,2,-6,STAINED_CLAY:3)
Block(-3,2,-5,STAINED_CLAY:3)
Block(-3,2,-4,STAINED_CLAY:3)
Block(-3,2,-3,STAINED_CLAY:3)
Block(-3,2,-2,STAINED_CLAY:3)
Block(-3,2,-1,STAINED_CLAY:3)
Block(-3,2,0,STAINED_CLAY:3)
Block(-3,3,-7,STAINED_CLAY:3)
Block(-3,3,-6,STAINED_CLAY:3)
Block(-3,3,-5,STAINED_CLAY:3)
Block(-3,3,-4,STAINED_CLAY:3)
Block(-3,3,-3,STAINED_CLAY:3)
Block(-3,3,-2,STAINED_CLAY:3)
Block(-3,3,-1,STAINED_CLAY:3)
Block(-3,4,-7,STAINED_CLAY:3)
Block(-3,4,-6,STAINED_CLAY:3)
Block(-3,4,-5,STAINED_CLAY:3)
Block(-3,4,-4,STAINED_CLAY:3)
Block(-3,4,-3,STAINED_CLAY:3)
Block(-3,4,-2,STAINED_CLAY:3)
Block(-3,5,-7,STAINED_CLAY:3)
Block(-3,5,-6,STAINED_CLAY:3)
Block(-3,5,-5,STAINED_CLAY:3)
Block(-3,5,-4,STAINED_CLAY:3)
Block(-3,5,-3,STAINED_CLAY:3)
Block(-3,6,-7,STAINED_CLAY:3)
Block(-3,6,-6,STAINED_CLAY:3)
Block(-3,6,-5,STAINED_CLAY:3)
Block(-3,6,-4,STAINED_CLAY:3)
Block(-3,7,-7,STAINED_CLAY:3)
Block(-3,7,-6,STAINED_CLAY:3)
Block(-3,7,-5,STAINED_CLAY:3)
Block(-3,8,-7,STAINED_CLAY:3)
Block(-3,8,-6,STAINED_CLAY:3)
Block(-3,9,-7,STAINED_CLAY:3)
Block(-2,0,3,STAINED_CLAY:3)
Block(-2,1,1,STAINED_CLAY:3)
Block(-2,2,-1,STAINED_CLAY:3)
Block(-2,2,0,STAINED_CLAY:3)
Block(-2,3,-3,STAINED_CLAY:3)
Block(-2,3,-2,STAINED_CLAY:3)
Block(-2,3,-1,STAINED_CLAY:3)
Block(-2,4,-6,STAINED_CLAY:3)
Block(-2,4,-5,STAINED_CLAY:3)
Block(-2,4,-4,STAINED_CLAY:3)
Block(-2,4,-3,STAINED_CLAY:3)
Block(-2,4,-2,STAINED_CLAY:3)
Block(-2,5,-7,STAINED_CLAY:3)
Block(-2,5,-6,STAINED_CLAY:3)
Block(-2,5,-5,STAINED_CLAY:3)
Block(-2,5,-4,STAINED_CLAY:3)
Block(-2,5,-3,STAINED_CLAY:3)
Block(-2,6,-7,STAINED_CLAY:3)
Block(-2,6,-6,STAINED_CLAY:3)
Block(-2,6,-5,STAINED_CLAY:3)
Block(-2,6,-4,STAINED_CLAY:3)
Block(-2,7,-7,STAINED_CLAY:3)
Block(-2,7,-6,STAINED_CLAY:3)
Block(-2,7,-5,STAINED_CLAY:3)
Block(-2,8,-7,STAINED_CLAY:3)
Block(-2,8,-6,STAINED_CLAY:3)
Block(-2,9,-7,STAINED_CLAY:3)
Block(-1,9,-7,STAINED_CLAY:3)

#######################################################################
# +-----------------------------------------------------------------+ #
# |                             Branches                            | #
# +-----------------------------------------------------------------+ #
#######################################################################

Branch(-16,0,0,true,OBSIDIANSpike_Huge_12C0R4,NORTH,100.0,0)

#######################################################################
# +-----------------------------------------------------------------+ #
# |                             Entities                            | #
# +-----------------------------------------------------------------+ #
#######################################################################


#######################################################################
# +-----------------------------------------------------------------+ #
# |                            Particles                            | #
# +-----------------------------------------------------------------+ #
#######################################################################


#######################################################################
# +-----------------------------------------------------------------+ #
# |                             Spawners                            | #
# +-----------------------------------------------------------------+ #
#######################################################################


#######################################################################
# +-----------------------------------------------------------------+ #
# |                             ModData                             | #
# +-----------------------------------------------------------------+ #
#######################################################################

