#######################################################################
# +-----------------------------------------------------------------+ #
# |                            BO3 object                           | #
# +-----------------------------------------------------------------+ #
#######################################################################

Author: Bo3 BulkEdit

Description: Converted Schematic - Modified by Bo3BulkEdit

Version: 3

SettingsMode: WriteDisable

#######################################################################
# +-----------------------------------------------------------------+ #
# |                          Main settings                          | #
# +-----------------------------------------------------------------+ #
#######################################################################



Frequency: 0


SpawnHeight: randomY





##############################
# Height Limits for the BO3. #
##############################

MinHeight: 0
MaxHeight: 256

#######################################################################
# +-----------------------------------------------------------------+ #
# |                      Source block settings                      | #
# +-----------------------------------------------------------------+ #
#######################################################################

CanOverride: true
MaxPercentageOutsideSourceBlock: 100
OutsideSourceBlock: placeAnyway

#######################################################################
# +-----------------------------------------------------------------+ #
# |                               OTG+                              | #
# +-----------------------------------------------------------------+ #
#######################################################################

#######################################################################
# +-----------------------------------------------------------------+ #
# |                              Blocks                             | #
# +-----------------------------------------------------------------+ #
#######################################################################

B(0,750,0,AIR)
B(15,750,15,AIR)
B(2,6,15,betternether:quartz_stained_glass:15)
B(3,6,15,betternether:quartz_stained_glass:15)
B(1,7,15,betternether:quartz_stained_glass:15)
B(2,7,15,betternether:quartz_stained_glass:15)
B(3,7,15,betternether:quartz_stained_glass:15)
B(0,8,14,betternether:quartz_stained_glass:15)
B(1,8,14,betternether:quartz_stained_glass:15)
B(2,8,14,betternether:quartz_stained_glass:15)
B(0,8,15,betternether:quartz_stained_glass:15)
B(1,8,15,betternether:quartz_stained_glass:15)
B(2,8,15,betternether:quartz_stained_glass:15)
B(3,8,15,betternether:quartz_stained_glass:15)
B(0,9,13,betternether:quartz_stained_glass:15)
B(1,9,13,betternether:quartz_stained_glass:15)
B(0,9,14,betternether:quartz_stained_glass:15)
B(1,9,14,betternether:quartz_stained_glass:15)
B(2,9,14,betternether:quartz_stained_glass:15)
B(0,9,15,betternether:quartz_stained_glass:15)
B(1,9,15,betternether:quartz_stained_glass:15)
B(2,9,15,betternether:quartz_stained_glass:15)
B(3,9,15,betternether:quartz_stained_glass:15)
B(0,10,12,betternether:quartz_stained_glass:15)
B(0,10,13,betternether:quartz_stained_glass:15)
B(1,10,13,betternether:quartz_stained_glass:15)
B(0,10,14,betternether:quartz_stained_glass:15)
B(1,10,14,betternether:quartz_stained_glass:15)
B(2,10,14,betternether:quartz_stained_glass:15)
B(0,10,15,betternether:quartz_stained_glass:15)
B(1,10,15,betternether:quartz_stained_glass:15)
B(2,10,15,betternether:quartz_stained_glass:15)
B(3,10,15,betternether:quartz_stained_glass:15)
B(0,11,12,betternether:quartz_stained_glass:15)
B(0,11,13,betternether:quartz_stained_glass:15)
B(1,11,13,betternether:quartz_stained_glass:15)
B(0,11,14,betternether:quartz_stained_glass:15)
B(1,11,14,betternether:quartz_stained_glass:15)
B(2,11,14,betternether:quartz_stained_glass:15)
RB(0,11,15,srparasites:parasitestain:1,80,quark:crystal:1,30,srparasites:parasiterubbledense:1,100)
RB(1,11,15,srparasites:parasitestain:1,80,quark:crystal:1,30,srparasites:parasiterubbledense:1,100)
B(2,11,15,betternether:quartz_stained_glass:15)
B(3,11,15,betternether:quartz_stained_glass:15)
B(0,12,12,betternether:quartz_stained_glass:15)
B(0,12,13,betternether:quartz_stained_glass:15)
B(1,12,13,betternether:quartz_stained_glass:15)
RB(0,12,14,srparasites:parasitestain:1,80,quark:crystal:1,30,srparasites:parasiterubbledense:1,100)
B(1,12,14,betternether:quartz_stained_glass:15)
B(2,12,14,betternether:quartz_stained_glass:15)
RB(0,12,15,srparasites:parasitestain:1,80,quark:crystal:1,30,srparasites:parasiterubbledense:1,100)
B(1,12,15,betternether:quartz_stained_glass:15)
B(2,12,15,betternether:quartz_stained_glass:15)
B(3,12,15,betternether:quartz_stained_glass:15)
B(0,13,12,betternether:quartz_stained_glass:15)
B(0,13,13,betternether:quartz_stained_glass:15)
B(1,13,13,betternether:quartz_stained_glass:15)
B(0,13,14,betternether:quartz_stained_glass:15)
B(1,13,14,betternether:quartz_stained_glass:15)
B(2,13,14,betternether:quartz_stained_glass:15)
B(0,13,15,betternether:quartz_stained_glass:15)
B(1,13,15,betternether:quartz_stained_glass:15)
B(2,13,15,betternether:quartz_stained_glass:15)
B(3,13,15,betternether:quartz_stained_glass:15)
B(0,14,12,betternether:quartz_stained_glass:15)
B(0,14,13,betternether:quartz_stained_glass:15)
B(1,14,13,betternether:quartz_stained_glass:15)
B(0,14,14,betternether:quartz_stained_glass:15)
B(1,14,14,betternether:quartz_stained_glass:15)
B(2,14,14,betternether:quartz_stained_glass:15)
B(0,14,15,betternether:quartz_stained_glass:15)
B(1,14,15,betternether:quartz_stained_glass:15)
B(2,14,15,betternether:quartz_stained_glass:15)
B(0,15,12,betternether:quartz_stained_glass:15)
B(0,15,13,betternether:quartz_stained_glass:15)
B(1,15,13,betternether:quartz_stained_glass:15)
B(0,15,14,betternether:quartz_stained_glass:15)
B(1,15,14,betternether:quartz_stained_glass:15)
B(0,15,15,betternether:quartz_stained_glass:15)
B(1,15,15,betternether:quartz_stained_glass:15)
B(0,16,12,betternether:quartz_stained_glass:15)
B(0,16,13,betternether:quartz_stained_glass:15)
B(1,16,13,betternether:quartz_stained_glass:15)
B(0,16,14,betternether:quartz_stained_glass:15)
B(1,16,14,betternether:quartz_stained_glass:15)
B(0,16,15,betternether:quartz_stained_glass:15)
B(0,17,12,betternether:quartz_stained_glass:15)
B(0,17,13,betternether:quartz_stained_glass:15)

#######################################################################
# +-----------------------------------------------------------------+ #
# |                             Branches                            | #
# +-----------------------------------------------------------------+ #
#######################################################################

BR(-16,0,0,true,SPIKE-THIN-DIAG-MED-02_0x0,NORTH,100,0)
