
#######################################################################
# +-----------------------------------------------------------------+ #
# |                            BO4 object                           | #
# +-----------------------------------------------------------------+ #
#######################################################################

Author: NLBlackEagle

Description: No description given

SettingsMode: WriteWithoutComments


#######################################################################
# +-----------------------------------------------------------------+ #
# |                          Main settings                          | #
# +-----------------------------------------------------------------+ #
#######################################################################

FixedRotation: 

Frequency: 0

SpawnHeight: highestBlock

UseCenterForHighestBlock: true

##############################
# Height Limits for the BO4. #
##############################

MinHeight: 0

MaxHeight: 255

InheritBO3: 

InheritBO3Rotation: NORTH

OverrideChildSettings: true

OverrideParentHeight: false

CanOverride: true

BranchFrequency: 0

BranchFrequencyGroup: 

MustBeBelowOther: false

MustBeInside: 

CannotBeInside: 

ReplacesBO3: 

MustBeInsideWorldBorders: false

CanSpawnOnWater: true

SpawnOnWaterOnly: false

SpawnUnderWater: false

SpawnAtWaterLevel: false

HeightOffset: 0

RemoveAir: false

ReplaceAbove: 

ReplaceBelow: 

ReplaceWithBiomeBlocks: false

ReplaceWithSurfaceBlock: GRASS

ReplaceWithGroundBlock: DIRT

ReplaceWithStoneBlock: STONE

SmoothRadius: 0

SmoothHeightOffset: 0

SmoothStartTop: false

SmoothStartWood: false

SmoothingSurfaceBlock: 

SmoothingGroundBlock: 

BO3Group: 

IsSpawnPoint: false

DoReplaceBlocks: true


#######################################################################
# +-----------------------------------------------------------------+ #
# |                              Blocks                             | #
# +-----------------------------------------------------------------+ #
#######################################################################

RandomBlock(-4,0,6,BRICK:0,50,MONSTER_EGGS:2,15,MONSTER_EGGS:3,15,MONSTER_EGGS:4,15,BRICK_STAIRS:0,10,BRICK_STAIRS:1,10,BRICK_STAIRS:2,10,BRICK_STAIRS:3,10,STEP:12,15,STEP:4,50,BRICK:0,100)
RandomBlock(-4,0,7,BRICK:0,50,MONSTER_EGGS:2,15,MONSTER_EGGS:3,15,MONSTER_EGGS:4,15,BRICK_STAIRS:0,10,BRICK_STAIRS:1,10,BRICK_STAIRS:2,10,BRICK_STAIRS:3,10,STEP:12,15,STEP:4,50,BRICK:0,100)
RandomBlock(-4,0,8,BRICK:0,50,MONSTER_EGGS:2,15,MONSTER_EGGS:3,15,MONSTER_EGGS:4,15,BRICK_STAIRS:0,10,BRICK_STAIRS:1,10,BRICK_STAIRS:2,10,BRICK_STAIRS:3,10,STEP:12,15,STEP:4,50,BRICK:0,100)
RandomBlock(-4,1,6,BRICK:0,50,MONSTER_EGGS:2,15,MONSTER_EGGS:3,15,MONSTER_EGGS:4,15,BRICK_STAIRS:0,10,BRICK_STAIRS:1,10,BRICK_STAIRS:2,10,BRICK_STAIRS:3,10,STEP:12,15,STEP:4,50,BRICK:0,100)
RandomBlock(-4,1,7,BRICK:0,50,MONSTER_EGGS:2,15,MONSTER_EGGS:3,15,MONSTER_EGGS:4,15,BRICK_STAIRS:0,10,BRICK_STAIRS:1,10,BRICK_STAIRS:2,10,BRICK_STAIRS:3,10,STEP:12,15,STEP:4,50,BRICK:0,100)
RandomBlock(-4,1,8,BRICK:0,50,MONSTER_EGGS:2,15,MONSTER_EGGS:3,15,MONSTER_EGGS:4,15,BRICK_STAIRS:0,10,BRICK_STAIRS:1,10,BRICK_STAIRS:2,10,BRICK_STAIRS:3,10,STEP:12,15,STEP:4,50,BRICK:0,100)
RandomBlock(-4,2,6,BRICK:0,50,MONSTER_EGGS:2,15,MONSTER_EGGS:3,15,MONSTER_EGGS:4,15,BRICK_STAIRS:0,10,BRICK_STAIRS:1,10,BRICK_STAIRS:2,10,BRICK_STAIRS:3,10,STEP:12,15,STEP:4,50,BRICK:0,100)
RandomBlock(-4,2,7,BRICK:0,50,MONSTER_EGGS:2,15,MONSTER_EGGS:3,15,MONSTER_EGGS:4,15,BRICK_STAIRS:0,10,BRICK_STAIRS:1,10,BRICK_STAIRS:2,10,BRICK_STAIRS:3,10,STEP:12,15,STEP:4,50,BRICK:0,100)
RandomBlock(-4,2,8,BRICK:0,50,MONSTER_EGGS:2,15,MONSTER_EGGS:3,15,MONSTER_EGGS:4,15,BRICK_STAIRS:0,10,BRICK_STAIRS:1,10,BRICK_STAIRS:2,10,BRICK_STAIRS:3,10,STEP:12,15,STEP:4,50,BRICK:0,100)
RandomBlock(-4,3,6,BRICK:0,50,MONSTER_EGGS:2,15,MONSTER_EGGS:3,15,MONSTER_EGGS:4,15,BRICK_STAIRS:0,10,BRICK_STAIRS:1,10,BRICK_STAIRS:2,10,BRICK_STAIRS:3,10,STEP:12,15,STEP:4,50,BRICK:0,100)
RandomBlock(-4,3,7,BRICK:0,50,MONSTER_EGGS:2,15,MONSTER_EGGS:3,15,MONSTER_EGGS:4,15,BRICK_STAIRS:0,10,BRICK_STAIRS:1,10,BRICK_STAIRS:2,10,BRICK_STAIRS:3,10,STEP:12,15,STEP:4,50,BRICK:0,100)
RandomBlock(-4,3,8,BRICK:0,50,MONSTER_EGGS:2,15,MONSTER_EGGS:3,15,MONSTER_EGGS:4,15,BRICK_STAIRS:0,10,BRICK_STAIRS:1,10,BRICK_STAIRS:2,10,BRICK_STAIRS:3,10,STEP:12,15,STEP:4,50,BRICK:0,100)
RandomBlock(-4,4,6,BRICK:0,50,MONSTER_EGGS:2,15,MONSTER_EGGS:3,15,MONSTER_EGGS:4,15,BRICK_STAIRS:0,10,BRICK_STAIRS:1,10,BRICK_STAIRS:2,10,BRICK_STAIRS:3,10,STEP:12,15,STEP:4,50,BRICK:0,100)
RandomBlock(-4,4,7,BRICK:0,50,MONSTER_EGGS:2,15,MONSTER_EGGS:3,15,MONSTER_EGGS:4,15,BRICK_STAIRS:0,10,BRICK_STAIRS:1,10,BRICK_STAIRS:2,10,BRICK_STAIRS:3,10,STEP:12,15,STEP:4,50,BRICK:0,100)
RandomBlock(-4,4,8,BRICK:0,50,MONSTER_EGGS:2,15,MONSTER_EGGS:3,15,MONSTER_EGGS:4,15,BRICK_STAIRS:0,10,BRICK_STAIRS:1,10,BRICK_STAIRS:2,10,BRICK_STAIRS:3,10,STEP:12,15,STEP:4,50,BRICK:0,100)
RandomBlock(-4,5,6,BRICK:0,50,MONSTER_EGGS:2,15,MONSTER_EGGS:3,15,MONSTER_EGGS:4,15,BRICK_STAIRS:0,10,BRICK_STAIRS:1,10,BRICK_STAIRS:2,10,BRICK_STAIRS:3,10,STEP:12,15,STEP:4,50,BRICK:0,100)
RandomBlock(-4,5,7,BRICK:0,50,MONSTER_EGGS:2,15,MONSTER_EGGS:3,15,MONSTER_EGGS:4,15,BRICK_STAIRS:0,10,BRICK_STAIRS:1,10,BRICK_STAIRS:2,10,BRICK_STAIRS:3,10,STEP:12,15,STEP:4,50,BRICK:0,100)
RandomBlock(-4,5,8,BRICK:0,50,MONSTER_EGGS:2,15,MONSTER_EGGS:3,15,MONSTER_EGGS:4,15,BRICK_STAIRS:0,10,BRICK_STAIRS:1,10,BRICK_STAIRS:2,10,BRICK_STAIRS:3,10,STEP:12,15,STEP:4,50,BRICK:0,100)
RandomBlock(-4,6,7,BRICK:0,50,MONSTER_EGGS:2,15,MONSTER_EGGS:3,15,MONSTER_EGGS:4,15,BRICK_STAIRS:0,10,BRICK_STAIRS:1,10,BRICK_STAIRS:2,10,BRICK_STAIRS:3,10,STEP:12,15,STEP:4,50,BRICK:0,100)
RandomBlock(-3,0,3,BRICK:0,50,MONSTER_EGGS:2,15,MONSTER_EGGS:3,15,MONSTER_EGGS:4,15,BRICK_STAIRS:0,10,BRICK_STAIRS:1,10,BRICK_STAIRS:2,10,BRICK_STAIRS:3,10,STEP:12,15,STEP:4,50,BRICK:0,100)
RandomBlock(-3,0,4,BRICK:0,50,MONSTER_EGGS:2,15,MONSTER_EGGS:3,15,MONSTER_EGGS:4,15,BRICK_STAIRS:0,10,BRICK_STAIRS:1,10,BRICK_STAIRS:2,10,BRICK_STAIRS:3,10,STEP:12,15,STEP:4,50,BRICK:0,100)
RandomBlock(-3,0,5,BRICK:0,50,MONSTER_EGGS:2,15,MONSTER_EGGS:3,15,MONSTER_EGGS:4,15,BRICK_STAIRS:0,10,BRICK_STAIRS:1,10,BRICK_STAIRS:2,10,BRICK_STAIRS:3,10,STEP:12,15,STEP:4,50,BRICK:0,100)
RandomBlock(-3,0,6,BRICK:0,50,MONSTER_EGGS:2,15,MONSTER_EGGS:3,15,MONSTER_EGGS:4,15,BRICK_STAIRS:0,10,BRICK_STAIRS:1,10,BRICK_STAIRS:2,10,BRICK_STAIRS:3,10,STEP:12,15,STEP:4,50,BRICK:0,100)
RandomBlock(-3,0,7,BRICK:0,50,MONSTER_EGGS:2,15,MONSTER_EGGS:3,15,MONSTER_EGGS:4,15,BRICK_STAIRS:0,10,BRICK_STAIRS:1,10,BRICK_STAIRS:2,10,BRICK_STAIRS:3,10,STEP:12,15,STEP:4,50,BRICK:0,100)
RandomBlock(-3,0,8,BRICK:0,50,MONSTER_EGGS:2,15,MONSTER_EGGS:3,15,MONSTER_EGGS:4,15,BRICK_STAIRS:0,10,BRICK_STAIRS:1,10,BRICK_STAIRS:2,10,BRICK_STAIRS:3,10,STEP:12,15,STEP:4,50,BRICK:0,100)
RandomBlock(-3,1,3,BRICK:0,50,MONSTER_EGGS:2,15,MONSTER_EGGS:3,15,MONSTER_EGGS:4,15,BRICK_STAIRS:0,10,BRICK_STAIRS:1,10,BRICK_STAIRS:2,10,BRICK_STAIRS:3,10,STEP:12,15,STEP:4,50,BRICK:0,100)
RandomBlock(-3,1,4,BRICK:0,50,MONSTER_EGGS:2,15,MONSTER_EGGS:3,15,MONSTER_EGGS:4,15,BRICK_STAIRS:0,10,BRICK_STAIRS:1,10,BRICK_STAIRS:2,10,BRICK_STAIRS:3,10,STEP:12,15,STEP:4,50,BRICK:0,100)
RandomBlock(-3,1,5,BRICK:0,50,MONSTER_EGGS:2,15,MONSTER_EGGS:3,15,MONSTER_EGGS:4,15,BRICK_STAIRS:0,10,BRICK_STAIRS:1,10,BRICK_STAIRS:2,10,BRICK_STAIRS:3,10,STEP:12,15,STEP:4,50,BRICK:0,100)
Block(-3,1,6,DOUBLE_STEP:0)
Block(-3,1,7,DOUBLE_STEP:0)
Block(-3,1,8,DOUBLE_STEP:0)
RandomBlock(-3,2,3,BRICK:0,50,MONSTER_EGGS:2,15,MONSTER_EGGS:3,15,MONSTER_EGGS:4,15,BRICK_STAIRS:0,10,BRICK_STAIRS:1,10,BRICK_STAIRS:2,10,BRICK_STAIRS:3,10,STEP:12,15,STEP:4,50,BRICK:0,100)
RandomBlock(-3,2,4,BRICK:0,50,MONSTER_EGGS:2,15,MONSTER_EGGS:3,15,MONSTER_EGGS:4,15,BRICK_STAIRS:0,10,BRICK_STAIRS:1,10,BRICK_STAIRS:2,10,BRICK_STAIRS:3,10,STEP:12,15,STEP:4,50,BRICK:0,100)
RandomBlock(-3,2,5,BRICK:0,50,MONSTER_EGGS:2,15,MONSTER_EGGS:3,15,MONSTER_EGGS:4,15,BRICK_STAIRS:0,10,BRICK_STAIRS:1,10,BRICK_STAIRS:2,10,BRICK_STAIRS:3,10,STEP:12,15,STEP:4,50,BRICK:0,100)
Block(-3,2,6,FURNACE:5)
Block(-3,2,7,FURNACE:5)
Block(-3,2,8,FURNACE:5)
RandomBlock(-3,3,3,BRICK:0,50,MONSTER_EGGS:2,15,MONSTER_EGGS:3,15,MONSTER_EGGS:4,15,BRICK_STAIRS:0,10,BRICK_STAIRS:1,10,BRICK_STAIRS:2,10,BRICK_STAIRS:3,10,STEP:12,15,STEP:4,50,BRICK:0,100)
RandomBlock(-3,3,4,BRICK:0,50,MONSTER_EGGS:2,15,MONSTER_EGGS:3,15,MONSTER_EGGS:4,15,BRICK_STAIRS:0,10,BRICK_STAIRS:1,10,BRICK_STAIRS:2,10,BRICK_STAIRS:3,10,STEP:12,15,STEP:4,50,BRICK:0,100)
RandomBlock(-3,3,5,BRICK:0,50,MONSTER_EGGS:2,15,MONSTER_EGGS:3,15,MONSTER_EGGS:4,15,BRICK_STAIRS:0,10,BRICK_STAIRS:1,10,BRICK_STAIRS:2,10,BRICK_STAIRS:3,10,STEP:12,15,STEP:4,50,BRICK:0,100)
Block(-3,3,6,FURNACE:5)
Block(-3,3,7,FURNACE:5)
Block(-3,3,8,FURNACE:5)
RandomBlock(-3,4,3,BRICK:0,50,MONSTER_EGGS:2,15,MONSTER_EGGS:3,15,MONSTER_EGGS:4,15,BRICK_STAIRS:0,10,BRICK_STAIRS:1,10,BRICK_STAIRS:2,10,BRICK_STAIRS:3,10,STEP:12,15,STEP:4,50,BRICK:0,100)
RandomBlock(-3,4,4,BRICK:0,50,MONSTER_EGGS:2,15,MONSTER_EGGS:3,15,MONSTER_EGGS:4,15,BRICK_STAIRS:0,10,BRICK_STAIRS:1,10,BRICK_STAIRS:2,10,BRICK_STAIRS:3,10,STEP:12,15,STEP:4,50,BRICK:0,100)
RandomBlock(-3,4,5,BRICK:0,50,MONSTER_EGGS:2,15,MONSTER_EGGS:3,15,MONSTER_EGGS:4,15,BRICK_STAIRS:0,10,BRICK_STAIRS:1,10,BRICK_STAIRS:2,10,BRICK_STAIRS:3,10,STEP:12,15,STEP:4,50,BRICK:0,100)
Block(-3,4,6,IRON_FENCE:0)
Block(-3,4,7,IRON_FENCE:0)
Block(-3,4,8,IRON_FENCE:0)
RandomBlock(-3,5,3,BRICK:0,50,MONSTER_EGGS:2,15,MONSTER_EGGS:3,15,MONSTER_EGGS:4,15,BRICK_STAIRS:0,10,BRICK_STAIRS:1,10,BRICK_STAIRS:2,10,BRICK_STAIRS:3,10,STEP:12,15,STEP:4,50,BRICK:0,100)
RandomBlock(-3,5,4,BRICK:0,50,MONSTER_EGGS:2,15,MONSTER_EGGS:3,15,MONSTER_EGGS:4,15,BRICK_STAIRS:0,10,BRICK_STAIRS:1,10,BRICK_STAIRS:2,10,BRICK_STAIRS:3,10,STEP:12,15,STEP:4,50,BRICK:0,100)
RandomBlock(-3,5,5,BRICK:0,50,MONSTER_EGGS:2,15,MONSTER_EGGS:3,15,MONSTER_EGGS:4,15,BRICK_STAIRS:0,10,BRICK_STAIRS:1,10,BRICK_STAIRS:2,10,BRICK_STAIRS:3,10,STEP:12,15,STEP:4,50,BRICK:0,100)
Block(-3,5,6,BRICK_STAIRS:7)
Block(-3,5,7,IRON_FENCE:0)
Block(-3,5,8,BRICK_STAIRS:6)
RandomBlock(-3,6,5,BRICK:0,50,MONSTER_EGGS:2,15,MONSTER_EGGS:3,15,MONSTER_EGGS:4,15,BRICK_STAIRS:0,10,BRICK_STAIRS:1,10,BRICK_STAIRS:2,10,BRICK_STAIRS:3,10,STEP:12,15,STEP:4,50,BRICK:0,100)
RandomBlock(-3,6,6,BRICK:0,50,MONSTER_EGGS:2,15,MONSTER_EGGS:3,15,MONSTER_EGGS:4,15,BRICK_STAIRS:0,10,BRICK_STAIRS:1,10,BRICK_STAIRS:2,10,BRICK_STAIRS:3,10,STEP:12,15,STEP:4,50,BRICK:0,100)
Block(-3,6,7,STEP:12)
RandomBlock(-3,6,8,BRICK:0,50,MONSTER_EGGS:2,15,MONSTER_EGGS:3,15,MONSTER_EGGS:4,15,BRICK_STAIRS:0,10,BRICK_STAIRS:1,10,BRICK_STAIRS:2,10,BRICK_STAIRS:3,10,STEP:12,15,STEP:4,50,BRICK:0,100)
RandomBlock(-3,7,7,BRICK:0,50,MONSTER_EGGS:2,15,MONSTER_EGGS:3,15,MONSTER_EGGS:4,15,BRICK_STAIRS:0,10,BRICK_STAIRS:1,10,BRICK_STAIRS:2,10,BRICK_STAIRS:3,10,STEP:12,15,STEP:4,50,BRICK:0,100)
RandomBlock(-2,0,1,BRICK:0,50,MONSTER_EGGS:2,15,MONSTER_EGGS:3,15,MONSTER_EGGS:4,15,BRICK_STAIRS:0,10,BRICK_STAIRS:1,10,BRICK_STAIRS:2,10,BRICK_STAIRS:3,10,STEP:12,15,STEP:4,50,BRICK:0,100)
RandomBlock(-2,0,2,BRICK:0,50,MONSTER_EGGS:2,15,MONSTER_EGGS:3,15,MONSTER_EGGS:4,15,BRICK_STAIRS:0,10,BRICK_STAIRS:1,10,BRICK_STAIRS:2,10,BRICK_STAIRS:3,10,STEP:12,15,STEP:4,50,BRICK:0,100)
RandomBlock(-2,0,3,BRICK:0,50,MONSTER_EGGS:2,15,MONSTER_EGGS:3,15,MONSTER_EGGS:4,15,BRICK_STAIRS:0,10,BRICK_STAIRS:1,10,BRICK_STAIRS:2,10,BRICK_STAIRS:3,10,STEP:12,15,STEP:4,50,BRICK:0,100)
RandomBlock(-2,0,4,BRICK:0,50,MONSTER_EGGS:2,15,MONSTER_EGGS:3,15,MONSTER_EGGS:4,15,BRICK_STAIRS:0,10,BRICK_STAIRS:1,10,BRICK_STAIRS:2,10,BRICK_STAIRS:3,10,STEP:12,15,STEP:4,50,BRICK:0,100)
RandomBlock(-2,0,5,BRICK:0,50,MONSTER_EGGS:2,15,MONSTER_EGGS:3,15,MONSTER_EGGS:4,15,BRICK_STAIRS:0,10,BRICK_STAIRS:1,10,BRICK_STAIRS:2,10,BRICK_STAIRS:3,10,STEP:12,15,STEP:4,50,BRICK:0,100)
RandomBlock(-2,0,6,BRICK:0,50,MONSTER_EGGS:2,15,MONSTER_EGGS:3,15,MONSTER_EGGS:4,15,BRICK_STAIRS:0,10,BRICK_STAIRS:1,10,BRICK_STAIRS:2,10,BRICK_STAIRS:3,10,STEP:12,15,STEP:4,50,BRICK:0,100)
RandomBlock(-2,0,7,BRICK:0,50,MONSTER_EGGS:2,15,MONSTER_EGGS:3,15,MONSTER_EGGS:4,15,BRICK_STAIRS:0,10,BRICK_STAIRS:1,10,BRICK_STAIRS:2,10,BRICK_STAIRS:3,10,STEP:12,15,STEP:4,50,BRICK:0,100)
RandomBlock(-2,0,8,BRICK:0,50,MONSTER_EGGS:2,15,MONSTER_EGGS:3,15,MONSTER_EGGS:4,15,BRICK_STAIRS:0,10,BRICK_STAIRS:1,10,BRICK_STAIRS:2,10,BRICK_STAIRS:3,10,STEP:12,15,STEP:4,50,BRICK:0,100)
RandomBlock(-2,1,1,BRICK:0,50,MONSTER_EGGS:2,15,MONSTER_EGGS:3,15,MONSTER_EGGS:4,15,BRICK_STAIRS:0,10,BRICK_STAIRS:1,10,BRICK_STAIRS:2,10,BRICK_STAIRS:3,10,STEP:12,15,STEP:4,50,BRICK:0,100)
RandomBlock(-2,1,2,BRICK:0,50,MONSTER_EGGS:2,15,MONSTER_EGGS:3,15,MONSTER_EGGS:4,15,BRICK_STAIRS:0,10,BRICK_STAIRS:1,10,BRICK_STAIRS:2,10,BRICK_STAIRS:3,10,STEP:12,15,STEP:4,50,BRICK:0,100)
Block(-2,1,3,DOUBLE_STEP:0)
Block(-2,1,4,DOUBLE_STEP:0)
RandomBlock(-2,1,5,CAULDRON:0,25,AIR:0,100)
RandomBlock(-2,1,6,WEB:0,14,AIR:0,100)
RandomBlock(-2,1,7,WEB:0,14,AIR:0,100)
RandomBlock(-2,1,8,WEB:0,14,AIR:0,100)
RandomBlock(-2,2,-6,DIRT:0,20,STONE:0,20,GRAVEL:0,20,BRICK:0,100)
RandomBlock(-2,2,-5,DIRT:0,20,STONE:0,20,GRAVEL:0,20,BRICK:0,100)
RandomBlock(-2,2,1,BRICK:0,50,MONSTER_EGGS:2,15,MONSTER_EGGS:3,15,MONSTER_EGGS:4,15,BRICK_STAIRS:0,10,BRICK_STAIRS:1,10,BRICK_STAIRS:2,10,BRICK_STAIRS:3,10,STEP:12,15,STEP:4,50,BRICK:0,100)
RandomBlock(-2,2,2,BRICK:0,50,MONSTER_EGGS:2,15,MONSTER_EGGS:3,15,MONSTER_EGGS:4,15,BRICK_STAIRS:0,10,BRICK_STAIRS:1,10,BRICK_STAIRS:2,10,BRICK_STAIRS:3,10,STEP:12,15,STEP:4,50,BRICK:0,100)
RandomBlock(-2,2,3,BREWING_STAND:0,6,AIR:0,100)
RandomBlock(-2,2,4,BREWING_STAND:0,6,AIR:0,100)
RandomBlock(-2,2,5,WEB:0,14,AIR:0,100)
RandomBlock(-2,2,6,WEB:0,14,AIR:0,100)
RandomBlock(-2,2,7,WEB:0,14,AIR:0,100)
RandomBlock(-2,2,8,WEB:0,14,AIR:0,100)
RandomBlock(-2,3,-6,DIRT:0,20,STONE:0,20,GRAVEL:0,20,BRICK:0,100)
RandomBlock(-2,3,-5,DIRT:0,20,STONE:0,20,GRAVEL:0,20,BRICK:0,100)
RandomBlock(-2,3,-4,DIRT:0,20,STONE:0,20,GRAVEL:0,20,BRICK:0,100)
RandomBlock(-2,3,-3,DIRT:0,20,STONE:0,20,GRAVEL:0,20,BRICK:0,100)
RandomBlock(-2,3,1,BRICK:0,50,MONSTER_EGGS:2,15,MONSTER_EGGS:3,15,MONSTER_EGGS:4,15,BRICK_STAIRS:0,10,BRICK_STAIRS:1,10,BRICK_STAIRS:2,10,BRICK_STAIRS:3,10,STEP:12,15,STEP:4,50,BRICK:0,100)
RandomBlock(-2,3,2,BRICK:0,50,MONSTER_EGGS:2,15,MONSTER_EGGS:3,15,MONSTER_EGGS:4,15,BRICK_STAIRS:0,10,BRICK_STAIRS:1,10,BRICK_STAIRS:2,10,BRICK_STAIRS:3,10,STEP:12,15,STEP:4,50,BRICK:0,100)
Block(-2,3,3,AIR:0)
Block(-2,3,4,AIR:0)
Block(-2,3,5,AIR:0)
Block(-2,3,6,AIR:0)
Block(-2,3,7,AIR:0)
Block(-2,3,8,AIR:0)
RandomBlock(-2,4,1,BRICK:0,50,MONSTER_EGGS:2,15,MONSTER_EGGS:3,15,MONSTER_EGGS:4,15,BRICK_STAIRS:0,10,BRICK_STAIRS:1,10,BRICK_STAIRS:2,10,BRICK_STAIRS:3,10,STEP:12,15,STEP:4,50,BRICK:0,100)
RandomBlock(-2,4,2,BRICK:0,50,MONSTER_EGGS:2,15,MONSTER_EGGS:3,15,MONSTER_EGGS:4,15,BRICK_STAIRS:0,10,BRICK_STAIRS:1,10,BRICK_STAIRS:2,10,BRICK_STAIRS:3,10,STEP:12,15,STEP:4,50,BRICK:0,100)
Block(-2,4,3,AIR:0)
Block(-2,4,4,AIR:0)
Block(-2,4,5,AIR:0)
Block(-2,4,6,AIR:0)
Block(-2,4,7,AIR:0)
Block(-2,4,8,AIR:0)
RandomBlock(-2,5,1,BRICK:0,50,MONSTER_EGGS:2,15,MONSTER_EGGS:3,15,MONSTER_EGGS:4,15,BRICK_STAIRS:0,10,BRICK_STAIRS:1,10,BRICK_STAIRS:2,10,BRICK_STAIRS:3,10,STEP:12,15,STEP:4,50,BRICK:0,100)
RandomBlock(-2,5,2,BRICK:0,50,MONSTER_EGGS:2,15,MONSTER_EGGS:3,15,MONSTER_EGGS:4,15,BRICK_STAIRS:0,10,BRICK_STAIRS:1,10,BRICK_STAIRS:2,10,BRICK_STAIRS:3,10,STEP:12,15,STEP:4,50,BRICK:0,100)
Block(-2,5,3,BRICK_STAIRS:7)
Block(-2,5,4,AIR:0)
Block(-2,5,5,AIR:0)
Block(-2,5,6,AIR:0)
Block(-2,5,7,AIR:0)
Block(-2,5,8,AIR:0)
RandomBlock(-2,6,2,BRICK:0,50,MONSTER_EGGS:2,15,MONSTER_EGGS:3,15,MONSTER_EGGS:4,15,BRICK_STAIRS:0,10,BRICK_STAIRS:1,10,BRICK_STAIRS:2,10,BRICK_STAIRS:3,10,STEP:12,15,STEP:4,50,BRICK:0,100)
RandomBlock(-2,6,3,BRICK:0,50,MONSTER_EGGS:2,15,MONSTER_EGGS:3,15,MONSTER_EGGS:4,15,BRICK_STAIRS:0,10,BRICK_STAIRS:1,10,BRICK_STAIRS:2,10,BRICK_STAIRS:3,10,STEP:12,15,STEP:4,50,BRICK:0,100)
RandomBlock(-2,6,4,BRICK:0,50,MONSTER_EGGS:2,15,MONSTER_EGGS:3,15,MONSTER_EGGS:4,15,BRICK_STAIRS:0,10,BRICK_STAIRS:1,10,BRICK_STAIRS:2,10,BRICK_STAIRS:3,10,STEP:12,15,STEP:4,50,BRICK:0,100)
Block(-2,6,5,BRICK_STAIRS:7)
Block(-2,6,6,AIR:0)
Block(-2,6,7,AIR:0)
Block(-2,6,8,AIR:0)
RandomBlock(-2,7,5,BRICK:0,50,MONSTER_EGGS:2,15,MONSTER_EGGS:3,15,MONSTER_EGGS:4,15,BRICK_STAIRS:0,10,BRICK_STAIRS:1,10,BRICK_STAIRS:2,10,BRICK_STAIRS:3,10,STEP:12,15,STEP:4,50,BRICK:0,100)
RandomBlock(-2,7,6,BRICK:0,50,MONSTER_EGGS:2,15,MONSTER_EGGS:3,15,MONSTER_EGGS:4,15,BRICK_STAIRS:0,10,BRICK_STAIRS:1,10,BRICK_STAIRS:2,10,BRICK_STAIRS:3,10,STEP:12,15,STEP:4,50,BRICK:0,100)
Block(-2,7,7,STEP:12)
RandomBlock(-2,7,8,BRICK:0,50,MONSTER_EGGS:2,15,MONSTER_EGGS:3,15,MONSTER_EGGS:4,15,BRICK_STAIRS:0,10,BRICK_STAIRS:1,10,BRICK_STAIRS:2,10,BRICK_STAIRS:3,10,STEP:12,15,STEP:4,50,BRICK:0,100)
RandomBlock(-2,8,7,BRICK:0,50,MONSTER_EGGS:2,15,MONSTER_EGGS:3,15,MONSTER_EGGS:4,15,BRICK_STAIRS:0,10,BRICK_STAIRS:1,10,BRICK_STAIRS:2,10,BRICK_STAIRS:3,10,STEP:12,15,STEP:4,50,BRICK:0,100)
RandomBlock(-1,0,-7,BRICK:0,50,MONSTER_EGGS:2,15,MONSTER_EGGS:3,15,MONSTER_EGGS:4,15,BRICK_STAIRS:0,10,BRICK_STAIRS:1,10,BRICK_STAIRS:2,10,BRICK_STAIRS:3,10,STEP:12,15,STEP:4,50,BRICK:0,100)
RandomBlock(-1,0,-6,BRICK:0,50,MONSTER_EGGS:2,15,MONSTER_EGGS:3,15,MONSTER_EGGS:4,15,BRICK_STAIRS:0,10,BRICK_STAIRS:1,10,BRICK_STAIRS:2,10,BRICK_STAIRS:3,10,STEP:12,15,STEP:4,50,BRICK:0,100)
RandomBlock(-1,0,-5,BRICK:0,50,MONSTER_EGGS:2,15,MONSTER_EGGS:3,15,MONSTER_EGGS:4,15,BRICK_STAIRS:0,10,BRICK_STAIRS:1,10,BRICK_STAIRS:2,10,BRICK_STAIRS:3,10,STEP:12,15,STEP:4,50,BRICK:0,100)
RandomBlock(-1,0,-4,BRICK:0,50,MONSTER_EGGS:2,15,MONSTER_EGGS:3,15,MONSTER_EGGS:4,15,BRICK_STAIRS:0,10,BRICK_STAIRS:1,10,BRICK_STAIRS:2,10,BRICK_STAIRS:3,10,STEP:12,15,STEP:4,50,BRICK:0,100)
RandomBlock(-1,0,-3,BRICK:0,50,MONSTER_EGGS:2,15,MONSTER_EGGS:3,15,MONSTER_EGGS:4,15,BRICK_STAIRS:0,10,BRICK_STAIRS:1,10,BRICK_STAIRS:2,10,BRICK_STAIRS:3,10,STEP:12,15,STEP:4,50,BRICK:0,100)
RandomBlock(-1,0,-2,BRICK:0,50,MONSTER_EGGS:2,15,MONSTER_EGGS:3,15,MONSTER_EGGS:4,15,BRICK_STAIRS:0,10,BRICK_STAIRS:1,10,BRICK_STAIRS:2,10,BRICK_STAIRS:3,10,STEP:12,15,STEP:4,50,BRICK:0,100)
RandomBlock(-1,0,-1,BRICK:0,50,MONSTER_EGGS:2,15,MONSTER_EGGS:3,15,MONSTER_EGGS:4,15,BRICK_STAIRS:0,10,BRICK_STAIRS:1,10,BRICK_STAIRS:2,10,BRICK_STAIRS:3,10,STEP:12,15,STEP:4,50,BRICK:0,100)
RandomBlock(-1,0,0,BRICK:0,50,MONSTER_EGGS:2,15,MONSTER_EGGS:3,15,MONSTER_EGGS:4,15,BRICK_STAIRS:0,10,BRICK_STAIRS:1,10,BRICK_STAIRS:2,10,BRICK_STAIRS:3,10,STEP:12,15,STEP:4,50,BRICK:0,100)
RandomBlock(-1,0,1,BRICK:0,50,MONSTER_EGGS:2,15,MONSTER_EGGS:3,15,MONSTER_EGGS:4,15,BRICK_STAIRS:0,10,BRICK_STAIRS:1,10,BRICK_STAIRS:2,10,BRICK_STAIRS:3,10,STEP:12,15,STEP:4,50,BRICK:0,100)
RandomBlock(-1,0,2,BRICK:0,50,MONSTER_EGGS:2,15,MONSTER_EGGS:3,15,MONSTER_EGGS:4,15,BRICK_STAIRS:0,10,BRICK_STAIRS:1,10,BRICK_STAIRS:2,10,BRICK_STAIRS:3,10,STEP:12,15,STEP:4,50,BRICK:0,100)
RandomBlock(-1,0,3,BRICK:0,50,MONSTER_EGGS:2,15,MONSTER_EGGS:3,15,MONSTER_EGGS:4,15,BRICK_STAIRS:0,10,BRICK_STAIRS:1,10,BRICK_STAIRS:2,10,BRICK_STAIRS:3,10,STEP:12,15,STEP:4,50,BRICK:0,100)
RandomBlock(-1,0,4,BRICK:0,50,MONSTER_EGGS:2,15,MONSTER_EGGS:3,15,MONSTER_EGGS:4,15,BRICK_STAIRS:0,10,BRICK_STAIRS:1,10,BRICK_STAIRS:2,10,BRICK_STAIRS:3,10,STEP:12,15,STEP:4,50,BRICK:0,100)
RandomBlock(-1,0,5,BRICK:0,50,MONSTER_EGGS:2,15,MONSTER_EGGS:3,15,MONSTER_EGGS:4,15,BRICK_STAIRS:0,10,BRICK_STAIRS:1,10,BRICK_STAIRS:2,10,BRICK_STAIRS:3,10,STEP:12,15,STEP:4,50,BRICK:0,100)
RandomBlock(-1,0,6,BRICK:0,50,MONSTER_EGGS:2,15,MONSTER_EGGS:3,15,MONSTER_EGGS:4,15,BRICK_STAIRS:0,10,BRICK_STAIRS:1,10,BRICK_STAIRS:2,10,BRICK_STAIRS:3,10,STEP:12,15,STEP:4,50,BRICK:0,100)
RandomBlock(-1,0,7,BRICK:0,50,MONSTER_EGGS:2,15,MONSTER_EGGS:3,15,MONSTER_EGGS:4,15,BRICK_STAIRS:0,10,BRICK_STAIRS:1,10,BRICK_STAIRS:2,10,BRICK_STAIRS:3,10,STEP:12,15,STEP:4,50,BRICK:0,100)
RandomBlock(-1,0,8,BRICK:0,50,MONSTER_EGGS:2,15,MONSTER_EGGS:3,15,MONSTER_EGGS:4,15,BRICK_STAIRS:0,10,BRICK_STAIRS:1,10,BRICK_STAIRS:2,10,BRICK_STAIRS:3,10,STEP:12,15,STEP:4,50,BRICK:0,100)
RandomBlock(-1,1,-7,BRICK:0,50,MONSTER_EGGS:2,15,MONSTER_EGGS:3,15,MONSTER_EGGS:4,15,BRICK_STAIRS:0,10,BRICK_STAIRS:1,10,BRICK_STAIRS:2,10,BRICK_STAIRS:3,10,STEP:12,15,STEP:4,50,BRICK:0,100)
RandomBlock(-1,1,-6,BRICK:0,50,MONSTER_EGGS:2,15,MONSTER_EGGS:3,15,MONSTER_EGGS:4,15,BRICK_STAIRS:0,10,BRICK_STAIRS:1,10,BRICK_STAIRS:2,10,BRICK_STAIRS:3,10,STEP:12,15,STEP:4,50,BRICK:0,100)
RandomBlock(-1,1,-5,BRICK:0,50,MONSTER_EGGS:2,15,MONSTER_EGGS:3,15,MONSTER_EGGS:4,15,BRICK_STAIRS:0,10,BRICK_STAIRS:1,10,BRICK_STAIRS:2,10,BRICK_STAIRS:3,10,STEP:12,15,STEP:4,50,BRICK:0,100)
RandomBlock(-1,1,-4,BRICK:0,50,MONSTER_EGGS:2,15,MONSTER_EGGS:3,15,MONSTER_EGGS:4,15,BRICK_STAIRS:0,10,BRICK_STAIRS:1,10,BRICK_STAIRS:2,10,BRICK_STAIRS:3,10,STEP:12,15,STEP:4,50,BRICK:0,100)
RandomBlock(-1,1,-3,BRICK:0,50,MONSTER_EGGS:2,15,MONSTER_EGGS:3,15,MONSTER_EGGS:4,15,BRICK_STAIRS:0,10,BRICK_STAIRS:1,10,BRICK_STAIRS:2,10,BRICK_STAIRS:3,10,STEP:12,15,STEP:4,50,BRICK:0,100)
RandomBlock(-1,1,-2,BRICK:0,50,MONSTER_EGGS:2,15,MONSTER_EGGS:3,15,MONSTER_EGGS:4,15,BRICK_STAIRS:0,10,BRICK_STAIRS:1,10,BRICK_STAIRS:2,10,BRICK_STAIRS:3,10,STEP:12,15,STEP:4,50,BRICK:0,100)
RandomBlock(-1,1,-1,BRICK:0,50,MONSTER_EGGS:2,15,MONSTER_EGGS:3,15,MONSTER_EGGS:4,15,BRICK_STAIRS:0,10,BRICK_STAIRS:1,10,BRICK_STAIRS:2,10,BRICK_STAIRS:3,10,STEP:12,15,STEP:4,50,BRICK:0,100)
RandomBlock(-1,1,0,BRICK:0,50,MONSTER_EGGS:2,15,MONSTER_EGGS:3,15,MONSTER_EGGS:4,15,BRICK_STAIRS:0,10,BRICK_STAIRS:1,10,BRICK_STAIRS:2,10,BRICK_STAIRS:3,10,STEP:12,15,STEP:4,50,BRICK:0,100)
RandomBlock(-1,1,1,WEB:0,14,AIR:0,100)
Block(-1,1,2,AIR:0)
Block(-1,1,3,AIR:0)
Block(-1,1,4,AIR:0)
Block(-1,1,5,AIR:0)
Block(-1,1,6,AIR:0)
RandomBlock(-1,1,7,WEB:0,14,AIR:0,100)
Block(-1,1,8,AIR:0)
RandomBlock(-1,2,-7,BRICK:0,50,MONSTER_EGGS:2,15,MONSTER_EGGS:3,15,MONSTER_EGGS:4,15,BRICK_STAIRS:0,10,BRICK_STAIRS:1,10,BRICK_STAIRS:2,10,BRICK_STAIRS:3,10,STEP:12,15,STEP:4,50,BRICK:0,100)
RandomBlock(-1,2,-6,BRICK:0,25,AIR:0,100)
RandomBlock(-1,2,-5,BRICK:0,25,AIR:0,100)
RandomBlock(-1,2,-4,BRICK:0,25,AIR:0,100)
RandomBlock(-1,2,-3,BRICK:0,25,AIR:0,100)
RandomBlock(-1,2,-2,BRICK:0,50,MONSTER_EGGS:2,15,MONSTER_EGGS:3,15,MONSTER_EGGS:4,15,BRICK_STAIRS:0,10,BRICK_STAIRS:1,10,BRICK_STAIRS:2,10,BRICK_STAIRS:3,10,STEP:12,15,STEP:4,50,BRICK:0,100)
RandomBlock(-1,2,-1,BRICK:0,50,MONSTER_EGGS:2,15,MONSTER_EGGS:3,15,MONSTER_EGGS:4,15,BRICK_STAIRS:0,10,BRICK_STAIRS:1,10,BRICK_STAIRS:2,10,BRICK_STAIRS:3,10,STEP:12,15,STEP:4,50,BRICK:0,100)
RandomBlock(-1,2,0,BRICK:0,50,MONSTER_EGGS:2,15,MONSTER_EGGS:3,15,MONSTER_EGGS:4,15,BRICK_STAIRS:0,10,BRICK_STAIRS:1,10,BRICK_STAIRS:2,10,BRICK_STAIRS:3,10,STEP:12,15,STEP:4,50,BRICK:0,100)
RandomBlock(-1,2,1,WEB:0,14,AIR:0,100)
Block(-1,2,2,AIR:0)
Block(-1,2,3,AIR:0)
Block(-1,2,4,AIR:0)
Block(-1,2,5,AIR:0)
Block(-1,2,6,AIR:0)
RandomBlock(-1,2,7,WEB:0,14,AIR:0,100)
Block(-1,2,8,AIR:0)
RandomBlock(-1,3,-7,BRICK:0,50,MONSTER_EGGS:2,15,MONSTER_EGGS:3,15,MONSTER_EGGS:4,15,BRICK_STAIRS:0,10,BRICK_STAIRS:1,10,BRICK_STAIRS:2,10,BRICK_STAIRS:3,10,STEP:12,15,STEP:4,50,BRICK:0,100)
RandomBlock(-1,3,-6,BRICK:0,25,AIR:0,100)
RandomBlock(-1,3,-5,BRICK:0,25,AIR:0,100)
RandomBlock(-1,3,-4,BRICK:0,25,AIR:0,100)
RandomBlock(-1,3,-3,BRICK:0,25,AIR:0,100)
RandomBlock(-1,3,-2,BRICK:0,50,MONSTER_EGGS:2,15,MONSTER_EGGS:3,15,MONSTER_EGGS:4,15,BRICK_STAIRS:0,10,BRICK_STAIRS:1,10,BRICK_STAIRS:2,10,BRICK_STAIRS:3,10,STEP:12,15,STEP:4,50,BRICK:0,100)
RandomBlock(-1,3,-1,BRICK:0,50,MONSTER_EGGS:2,15,MONSTER_EGGS:3,15,MONSTER_EGGS:4,15,BRICK_STAIRS:0,10,BRICK_STAIRS:1,10,BRICK_STAIRS:2,10,BRICK_STAIRS:3,10,STEP:12,15,STEP:4,50,BRICK:0,100)
RandomBlock(-1,3,0,BRICK:0,50,MONSTER_EGGS:2,15,MONSTER_EGGS:3,15,MONSTER_EGGS:4,15,BRICK_STAIRS:0,10,BRICK_STAIRS:1,10,BRICK_STAIRS:2,10,BRICK_STAIRS:3,10,STEP:12,15,STEP:4,50,BRICK:0,100)
RandomBlock(-1,3,1,WEB:0,14,AIR:0,100)
Block(-1,3,2,AIR:0)
Block(-1,3,3,AIR:0)
Block(-1,3,4,AIR:0)
Block(-1,3,5,AIR:0)
Block(-1,3,6,AIR:0)
Block(-1,3,7,AIR:0)
Block(-1,3,8,AIR:0)
RandomBlock(-1,4,-7,BRICK:0,50,MONSTER_EGGS:2,15,MONSTER_EGGS:3,15,MONSTER_EGGS:4,15,BRICK_STAIRS:0,10,BRICK_STAIRS:1,10,BRICK_STAIRS:2,10,BRICK_STAIRS:3,10,STEP:12,15,STEP:4,50,BRICK:0,100)
RandomBlock(-1,4,-6,BRICK:0,50,MONSTER_EGGS:2,15,MONSTER_EGGS:3,15,MONSTER_EGGS:4,15,BRICK_STAIRS:0,10,BRICK_STAIRS:1,10,BRICK_STAIRS:2,10,BRICK_STAIRS:3,10,STEP:12,15,STEP:4,50,BRICK:0,100)
RandomBlock(-1,4,-5,BRICK:0,50,MONSTER_EGGS:2,15,MONSTER_EGGS:3,15,MONSTER_EGGS:4,15,BRICK_STAIRS:0,10,BRICK_STAIRS:1,10,BRICK_STAIRS:2,10,BRICK_STAIRS:3,10,STEP:12,15,STEP:4,50,BRICK:0,100)
RandomBlock(-1,4,-4,BRICK:0,50,MONSTER_EGGS:2,15,MONSTER_EGGS:3,15,MONSTER_EGGS:4,15,BRICK_STAIRS:0,10,BRICK_STAIRS:1,10,BRICK_STAIRS:2,10,BRICK_STAIRS:3,10,STEP:12,15,STEP:4,50,BRICK:0,100)
RandomBlock(-1,4,-3,BRICK:0,50,MONSTER_EGGS:2,15,MONSTER_EGGS:3,15,MONSTER_EGGS:4,15,BRICK_STAIRS:0,10,BRICK_STAIRS:1,10,BRICK_STAIRS:2,10,BRICK_STAIRS:3,10,STEP:12,15,STEP:4,50,BRICK:0,100)
RandomBlock(-1,4,-2,BRICK:0,50,MONSTER_EGGS:2,15,MONSTER_EGGS:3,15,MONSTER_EGGS:4,15,BRICK_STAIRS:0,10,BRICK_STAIRS:1,10,BRICK_STAIRS:2,10,BRICK_STAIRS:3,10,STEP:12,15,STEP:4,50,BRICK:0,100)
RandomBlock(-1,4,-1,BRICK:0,50,MONSTER_EGGS:2,15,MONSTER_EGGS:3,15,MONSTER_EGGS:4,15,BRICK_STAIRS:0,10,BRICK_STAIRS:1,10,BRICK_STAIRS:2,10,BRICK_STAIRS:3,10,STEP:12,15,STEP:4,50,BRICK:0,100)
RandomBlock(-1,4,0,BRICK:0,50,MONSTER_EGGS:2,15,MONSTER_EGGS:3,15,MONSTER_EGGS:4,15,BRICK_STAIRS:0,10,BRICK_STAIRS:1,10,BRICK_STAIRS:2,10,BRICK_STAIRS:3,10,STEP:12,15,STEP:4,50,BRICK:0,100)
RandomBlock(-1,4,1,WEB:0,14,AIR:0,100)
Block(-1,4,2,AIR:0)
Block(-1,4,3,AIR:0)
Block(-1,4,4,AIR:0)
Block(-1,4,5,AIR:0)
Block(-1,4,6,AIR:0)
Block(-1,4,7,AIR:0)
Block(-1,4,8,AIR:0)
RandomBlock(-1,5,0,BRICK:0,50,MONSTER_EGGS:2,15,MONSTER_EGGS:3,15,MONSTER_EGGS:4,15,BRICK_STAIRS:0,10,BRICK_STAIRS:1,10,BRICK_STAIRS:2,10,BRICK_STAIRS:3,10,STEP:12,15,STEP:4,50,BRICK:0,100)
Block(-1,5,1,BRICK_STAIRS:7)
RandomBlock(-1,5,2,WEB:0,14,AIR:0,100)
Block(-1,5,3,AIR:0)
Block(-1,5,4,AIR:0)
Block(-1,5,5,AIR:0)
Block(-1,5,6,AIR:0)
Block(-1,5,7,AIR:0)
Block(-1,5,8,AIR:0)
RandomBlock(-1,6,0,BRICK:0,50,MONSTER_EGGS:2,15,MONSTER_EGGS:3,15,MONSTER_EGGS:4,15,BRICK_STAIRS:0,10,BRICK_STAIRS:1,10,BRICK_STAIRS:2,10,BRICK_STAIRS:3,10,STEP:12,15,STEP:4,50,BRICK:0,100)
RandomBlock(-1,6,1,BRICK:0,50,MONSTER_EGGS:2,15,MONSTER_EGGS:3,15,MONSTER_EGGS:4,15,BRICK_STAIRS:0,10,BRICK_STAIRS:1,10,BRICK_STAIRS:2,10,BRICK_STAIRS:3,10,STEP:12,15,STEP:4,50,BRICK:0,100)
RandomBlock(-1,6,2,BRICK:0,50,MONSTER_EGGS:2,15,MONSTER_EGGS:3,15,MONSTER_EGGS:4,15,BRICK_STAIRS:0,10,BRICK_STAIRS:1,10,BRICK_STAIRS:2,10,BRICK_STAIRS:3,10,STEP:12,15,STEP:4,50,BRICK:0,100)
Block(-1,6,3,BRICK_STAIRS:7)
Block(-1,6,4,AIR:0)
Block(-1,6,5,AIR:0)
Block(-1,6,6,AIR:0)
Block(-1,6,7,AIR:0)
Block(-1,6,8,AIR:0)
RandomBlock(-1,7,2,BRICK:0,50,MONSTER_EGGS:2,15,MONSTER_EGGS:3,15,MONSTER_EGGS:4,15,BRICK_STAIRS:0,10,BRICK_STAIRS:1,10,BRICK_STAIRS:2,10,BRICK_STAIRS:3,10,STEP:12,15,STEP:4,50,BRICK:0,100)
RandomBlock(-1,7,3,BRICK:0,50,MONSTER_EGGS:2,15,MONSTER_EGGS:3,15,MONSTER_EGGS:4,15,BRICK_STAIRS:0,10,BRICK_STAIRS:1,10,BRICK_STAIRS:2,10,BRICK_STAIRS:3,10,STEP:12,15,STEP:4,50,BRICK:0,100)
RandomBlock(-1,7,4,BRICK:0,50,MONSTER_EGGS:2,15,MONSTER_EGGS:3,15,MONSTER_EGGS:4,15,BRICK_STAIRS:0,10,BRICK_STAIRS:1,10,BRICK_STAIRS:2,10,BRICK_STAIRS:3,10,STEP:12,15,STEP:4,50,BRICK:0,100)
Block(-1,7,5,AIR:0)
Block(-1,7,6,AIR:0)
Block(-1,7,7,AIR:0)
Block(-1,7,8,AIR:0)
RandomBlock(-1,8,5,BRICK:0,50,MONSTER_EGGS:2,15,MONSTER_EGGS:3,15,MONSTER_EGGS:4,15,BRICK_STAIRS:0,10,BRICK_STAIRS:1,10,BRICK_STAIRS:2,10,BRICK_STAIRS:3,10,STEP:12,15,STEP:4,50,BRICK:0,100)
RandomBlock(-1,8,6,BRICK:0,50,MONSTER_EGGS:2,15,MONSTER_EGGS:3,15,MONSTER_EGGS:4,15,BRICK_STAIRS:0,10,BRICK_STAIRS:1,10,BRICK_STAIRS:2,10,BRICK_STAIRS:3,10,STEP:12,15,STEP:4,50,BRICK:0,100)
RandomBlock(-1,8,7,BRICK:0,50,MONSTER_EGGS:2,15,MONSTER_EGGS:3,15,MONSTER_EGGS:4,15,BRICK_STAIRS:0,10,BRICK_STAIRS:1,10,BRICK_STAIRS:2,10,BRICK_STAIRS:3,10,STEP:12,15,STEP:4,50,BRICK:0,100)
RandomBlock(-1,8,8,BRICK:0,50,MONSTER_EGGS:2,15,MONSTER_EGGS:3,15,MONSTER_EGGS:4,15,BRICK_STAIRS:0,10,BRICK_STAIRS:1,10,BRICK_STAIRS:2,10,BRICK_STAIRS:3,10,STEP:12,15,STEP:4,50,BRICK:0,100)
RandomBlock(0,0,-7,BRICK:0,50,MONSTER_EGGS:2,15,MONSTER_EGGS:3,15,MONSTER_EGGS:4,15,BRICK_STAIRS:0,10,BRICK_STAIRS:1,10,BRICK_STAIRS:2,10,BRICK_STAIRS:3,10,STEP:12,15,STEP:4,50,BRICK:0,100)
RandomBlock(0,0,-6,BRICK:0,50,MONSTER_EGGS:2,15,MONSTER_EGGS:3,15,MONSTER_EGGS:4,15,BRICK_STAIRS:0,10,BRICK_STAIRS:1,10,BRICK_STAIRS:2,10,BRICK_STAIRS:3,10,STEP:12,15,STEP:4,50,BRICK:0,100)
RandomBlock(0,0,-5,BRICK:0,50,MONSTER_EGGS:2,15,MONSTER_EGGS:3,15,MONSTER_EGGS:4,15,BRICK_STAIRS:0,10,BRICK_STAIRS:1,10,BRICK_STAIRS:2,10,BRICK_STAIRS:3,10,STEP:12,15,STEP:4,50,BRICK:0,100)
RandomBlock(0,0,-4,BRICK:0,50,MONSTER_EGGS:2,15,MONSTER_EGGS:3,15,MONSTER_EGGS:4,15,BRICK_STAIRS:0,10,BRICK_STAIRS:1,10,BRICK_STAIRS:2,10,BRICK_STAIRS:3,10,STEP:12,15,STEP:4,50,BRICK:0,100)
RandomBlock(0,0,-3,BRICK:0,50,MONSTER_EGGS:2,15,MONSTER_EGGS:3,15,MONSTER_EGGS:4,15,BRICK_STAIRS:0,10,BRICK_STAIRS:1,10,BRICK_STAIRS:2,10,BRICK_STAIRS:3,10,STEP:12,15,STEP:4,50,BRICK:0,100)
RandomBlock(0,0,-2,BRICK:0,50,MONSTER_EGGS:2,15,MONSTER_EGGS:3,15,MONSTER_EGGS:4,15,BRICK_STAIRS:0,10,BRICK_STAIRS:1,10,BRICK_STAIRS:2,10,BRICK_STAIRS:3,10,STEP:12,15,STEP:4,50,BRICK:0,100)
RandomBlock(0,0,-1,BRICK:0,50,MONSTER_EGGS:2,15,MONSTER_EGGS:3,15,MONSTER_EGGS:4,15,BRICK_STAIRS:0,10,BRICK_STAIRS:1,10,BRICK_STAIRS:2,10,BRICK_STAIRS:3,10,STEP:12,15,STEP:4,50,BRICK:0,100)
RandomBlock(0,0,0,BRICK:0,50,MONSTER_EGGS:2,15,MONSTER_EGGS:3,15,MONSTER_EGGS:4,15,BRICK_STAIRS:0,10,BRICK_STAIRS:1,10,BRICK_STAIRS:2,10,BRICK_STAIRS:3,10,STEP:12,15,STEP:4,50,BRICK:0,100)
RandomBlock(0,0,1,BRICK:0,50,MONSTER_EGGS:2,15,MONSTER_EGGS:3,15,MONSTER_EGGS:4,15,BRICK_STAIRS:0,10,BRICK_STAIRS:1,10,BRICK_STAIRS:2,10,BRICK_STAIRS:3,10,STEP:12,15,STEP:4,50,BRICK:0,100)
RandomBlock(0,0,2,BRICK:0,50,MONSTER_EGGS:2,15,MONSTER_EGGS:3,15,MONSTER_EGGS:4,15,BRICK_STAIRS:0,10,BRICK_STAIRS:1,10,BRICK_STAIRS:2,10,BRICK_STAIRS:3,10,STEP:12,15,STEP:4,50,BRICK:0,100)
RandomBlock(0,0,3,BRICK:0,50,MONSTER_EGGS:2,15,MONSTER_EGGS:3,15,MONSTER_EGGS:4,15,BRICK_STAIRS:0,10,BRICK_STAIRS:1,10,BRICK_STAIRS:2,10,BRICK_STAIRS:3,10,STEP:12,15,STEP:4,50,BRICK:0,100)
RandomBlock(0,0,4,BRICK:0,50,MONSTER_EGGS:2,15,MONSTER_EGGS:3,15,MONSTER_EGGS:4,15,BRICK_STAIRS:0,10,BRICK_STAIRS:1,10,BRICK_STAIRS:2,10,BRICK_STAIRS:3,10,STEP:12,15,STEP:4,50,BRICK:0,100)
RandomBlock(0,0,5,BRICK:0,50,MONSTER_EGGS:2,15,MONSTER_EGGS:3,15,MONSTER_EGGS:4,15,BRICK_STAIRS:0,10,BRICK_STAIRS:1,10,BRICK_STAIRS:2,10,BRICK_STAIRS:3,10,STEP:12,15,STEP:4,50,BRICK:0,100)
RandomBlock(0,0,6,BRICK:0,50,MONSTER_EGGS:2,15,MONSTER_EGGS:3,15,MONSTER_EGGS:4,15,BRICK_STAIRS:0,10,BRICK_STAIRS:1,10,BRICK_STAIRS:2,10,BRICK_STAIRS:3,10,STEP:12,15,STEP:4,50,BRICK:0,100)
RandomBlock(0,0,7,BRICK:0,50,MONSTER_EGGS:2,15,MONSTER_EGGS:3,15,MONSTER_EGGS:4,15,BRICK_STAIRS:0,10,BRICK_STAIRS:1,10,BRICK_STAIRS:2,10,BRICK_STAIRS:3,10,STEP:12,15,STEP:4,50,BRICK:0,100)
RandomBlock(0,0,8,BRICK:0,50,MONSTER_EGGS:2,15,MONSTER_EGGS:3,15,MONSTER_EGGS:4,15,BRICK_STAIRS:0,10,BRICK_STAIRS:1,10,BRICK_STAIRS:2,10,BRICK_STAIRS:3,10,STEP:12,15,STEP:4,50,BRICK:0,100)
RandomBlock(0,1,-7,CHEST:5,../../../../Chests/Loot/junk_loot.nbt,20,CHEST:5../../../../Chests/Loot/bottle_loot.nbt,2,CHEST:5,../../../../Chests/Loot/common_loot.nbt,2,CHEST:5,../../../../Chests/Loot/village_blacksmith.nbt,2,CHEST:5,../../../../Chests/Loot/stronghold_library.nbt,2,CHEST:5,../../../../Chests/Loot/stronghold_corridor.nbt,2,CHEST:5,../../../../Chests/Loot/simple_dungeon.nbt,5,MOB_SPAWNER:0,../../ruins_spawners/alchemist_multi.nbt,10,WEB:0,10,AIR:0,100)
RandomBlock(0,1,-6,CHEST:5,../../../../Chests/Loot/junk_loot.nbt,20,CHEST:5../../../../Chests/Loot/bottle_loot.nbt,2,CHEST:5,../../../../Chests/Loot/common_loot.nbt,2,CHEST:5,../../../../Chests/Loot/village_blacksmith.nbt,2,CHEST:5,../../../../Chests/Loot/stronghold_library.nbt,2,CHEST:5,../../../../Chests/Loot/stronghold_corridor.nbt,2,CHEST:5,../../../../Chests/Loot/simple_dungeon.nbt,5,MOB_SPAWNER:0,../../ruins_spawners/alchemist_multi.nbt,10,WEB:0,10,AIR:0,100)
RandomBlock(0,1,-5,CHEST:5,../../../../Chests/Loot/junk_loot.nbt,20,CHEST:5../../../../Chests/Loot/bottle_loot.nbt,2,CHEST:5,../../../../Chests/Loot/common_loot.nbt,2,CHEST:5,../../../../Chests/Loot/village_blacksmith.nbt,2,CHEST:5,../../../../Chests/Loot/stronghold_library.nbt,2,CHEST:5,../../../../Chests/Loot/stronghold_corridor.nbt,2,CHEST:5,../../../../Chests/Loot/simple_dungeon.nbt,5,MOB_SPAWNER:0,../../ruins_spawners/alchemist_multi.nbt,10,WEB:0,10,AIR:0,100)
RandomBlock(0,1,-4,CHEST:5,../../../../Chests/Loot/junk_loot.nbt,20,CHEST:5../../../../Chests/Loot/bottle_loot.nbt,2,CHEST:5,../../../../Chests/Loot/common_loot.nbt,2,CHEST:5,../../../../Chests/Loot/village_blacksmith.nbt,2,CHEST:5,../../../../Chests/Loot/stronghold_library.nbt,2,CHEST:5,../../../../Chests/Loot/stronghold_corridor.nbt,2,CHEST:5,../../../../Chests/Loot/simple_dungeon.nbt,5,MOB_SPAWNER:0,../../ruins_spawners/alchemist_multi.nbt,10,WEB:0,10,AIR:0,100)
RandomBlock(0,1,-3,CHEST:5,../../../../Chests/Loot/junk_loot.nbt,20,CHEST:5../../../../Chests/Loot/bottle_loot.nbt,2,CHEST:5,../../../../Chests/Loot/common_loot.nbt,2,CHEST:5,../../../../Chests/Loot/village_blacksmith.nbt,2,CHEST:5,../../../../Chests/Loot/stronghold_library.nbt,2,CHEST:5,../../../../Chests/Loot/stronghold_corridor.nbt,2,CHEST:5,../../../../Chests/Loot/simple_dungeon.nbt,5,MOB_SPAWNER:0,../../ruins_spawners/alchemist_multi.nbt,10,WEB:0,10,AIR:0,100)
RandomBlock(0,1,-2,CHEST:5,../../../../Chests/Loot/junk_loot.nbt,20,CHEST:5../../../../Chests/Loot/bottle_loot.nbt,2,CHEST:5,../../../../Chests/Loot/common_loot.nbt,2,CHEST:5,../../../../Chests/Loot/village_blacksmith.nbt,2,CHEST:5,../../../../Chests/Loot/stronghold_library.nbt,2,CHEST:5,../../../../Chests/Loot/stronghold_corridor.nbt,2,CHEST:5,../../../../Chests/Loot/simple_dungeon.nbt,5,MOB_SPAWNER:0,../../ruins_spawners/alchemist_multi.nbt,10,WEB:0,10,AIR:0,100)
RandomBlock(0,1,-1,BRICK:0,50,MONSTER_EGGS:2,15,MONSTER_EGGS:3,15,MONSTER_EGGS:4,15,BRICK_STAIRS:0,10,BRICK_STAIRS:1,10,BRICK_STAIRS:2,10,BRICK_STAIRS:3,10,STEP:12,15,STEP:4,50,BRICK:0,100)
RandomBlock(0,1,0,WEB:0,14,AIR:0,100)
Block(0,1,1,AIR:0)
Block(0,1,2,AIR:0)
Block(0,1,3,AIR:0)
Block(0,1,4,STEP:0)
Block(0,1,5,AIR:0)
RandomBlock(0,1,6,WEB:0,14,AIR:0,100)
RandomBlock(0,1,7,WEB:0,14,AIR:0,100)
RandomBlock(0,1,8,WEB:0,14,AIR:0,100)
RandomBlock(0,2,-7,WEB:0,14,AIR:0,100)
RandomBlock(0,2,-6,WEB:0,14,AIR:0,100)
RandomBlock(0,2,-5,WEB:0,14,AIR:0,100)
RandomBlock(0,2,-4,WEB:0,14,AIR:0,100)
RandomBlock(0,2,-3,WEB:0,14,AIR:0,100)
RandomBlock(0,2,-2,WEB:0,14,AIR:0,100)
RandomBlock(0,2,-1,BRICK:0,50,MONSTER_EGGS:2,15,MONSTER_EGGS:3,15,MONSTER_EGGS:4,15,BRICK_STAIRS:0,10,BRICK_STAIRS:1,10,BRICK_STAIRS:2,10,BRICK_STAIRS:3,10,STEP:12,15,STEP:4,50,BRICK:0,100)
RandomBlock(0,2,0,WEB:0,14,AIR:0,100)
Block(0,2,1,AIR:0)
Block(0,2,2,AIR:0)
Block(0,2,3,AIR:0)
Block(0,2,4,AIR:0)
Block(0,2,5,AIR:0)
RandomBlock(0,2,6,WEB:0,14,AIR:0,100)
RandomBlock(0,2,7,WEB:0,14,AIR:0,100)
RandomBlock(0,2,8,WEB:0,14,AIR:0,100)
RandomBlock(0,3,-7,WEB:0,14,AIR:0,100)
RandomBlock(0,3,-6,WEB:0,14,AIR:0,100)
RandomBlock(0,3,-5,WEB:0,14,AIR:0,100)
RandomBlock(0,3,-4,WEB:0,14,AIR:0,100)
RandomBlock(0,3,-3,WEB:0,14,AIR:0,100)
RandomBlock(0,3,-2,WEB:0,14,AIR:0,100)
RandomBlock(0,3,-1,BRICK:0,50,MONSTER_EGGS:2,15,MONSTER_EGGS:3,15,MONSTER_EGGS:4,15,BRICK_STAIRS:0,10,BRICK_STAIRS:1,10,BRICK_STAIRS:2,10,BRICK_STAIRS:3,10,STEP:12,15,STEP:4,50,BRICK:0,100)
RandomBlock(0,3,0,WEB:0,14,AIR:0,100)
Block(0,3,1,AIR:0)
Block(0,3,2,AIR:0)
Block(0,3,3,AIR:0)
Block(0,3,4,AIR:0)
Block(0,3,5,AIR:0)
Block(0,3,6,AIR:0)
Block(0,3,7,AIR:0)
Block(0,3,8,AIR:0)
Block(0,4,-7,STEP:12)
Block(0,4,-6,STEP:12)
Block(0,4,-5,STEP:12)
Block(0,4,-4,STEP:12)
Block(0,4,-3,STEP:12)
Block(0,4,-2,STEP:12)
RandomBlock(0,4,-1,BRICK:0,50,MONSTER_EGGS:2,15,MONSTER_EGGS:3,15,MONSTER_EGGS:4,15,BRICK_STAIRS:0,10,BRICK_STAIRS:1,10,BRICK_STAIRS:2,10,BRICK_STAIRS:3,10,STEP:12,15,STEP:4,50,BRICK:0,100)
RandomBlock(0,4,0,WEB:0,14,AIR:0,100)
Block(0,4,1,AIR:0)
Block(0,4,2,AIR:0)
Block(0,4,3,AIR:0)
Block(0,4,4,AIR:0)
Block(0,4,5,AIR:0)
Block(0,4,6,AIR:0)
Block(0,4,7,AIR:0)
Block(0,4,8,AIR:0)
RandomBlock(0,5,-7,BRICK:0,50,MONSTER_EGGS:2,15,MONSTER_EGGS:3,15,MONSTER_EGGS:4,15,BRICK_STAIRS:0,10,BRICK_STAIRS:1,10,BRICK_STAIRS:2,10,BRICK_STAIRS:3,10,STEP:12,15,STEP:4,50,BRICK:0,100)
RandomBlock(0,5,-6,BRICK:0,50,MONSTER_EGGS:2,15,MONSTER_EGGS:3,15,MONSTER_EGGS:4,15,BRICK_STAIRS:0,10,BRICK_STAIRS:1,10,BRICK_STAIRS:2,10,BRICK_STAIRS:3,10,STEP:12,15,STEP:4,50,BRICK:0,100)
RandomBlock(0,5,-5,BRICK:0,50,MONSTER_EGGS:2,15,MONSTER_EGGS:3,15,MONSTER_EGGS:4,15,BRICK_STAIRS:0,10,BRICK_STAIRS:1,10,BRICK_STAIRS:2,10,BRICK_STAIRS:3,10,STEP:12,15,STEP:4,50,BRICK:0,100)
RandomBlock(0,5,-4,BRICK:0,50,MONSTER_EGGS:2,15,MONSTER_EGGS:3,15,MONSTER_EGGS:4,15,BRICK_STAIRS:0,10,BRICK_STAIRS:1,10,BRICK_STAIRS:2,10,BRICK_STAIRS:3,10,STEP:12,15,STEP:4,50,BRICK:0,100)
RandomBlock(0,5,-3,BRICK:0,50,MONSTER_EGGS:2,15,MONSTER_EGGS:3,15,MONSTER_EGGS:4,15,BRICK_STAIRS:0,10,BRICK_STAIRS:1,10,BRICK_STAIRS:2,10,BRICK_STAIRS:3,10,STEP:12,15,STEP:4,50,BRICK:0,100)
RandomBlock(0,5,-2,BRICK:0,50,MONSTER_EGGS:2,15,MONSTER_EGGS:3,15,MONSTER_EGGS:4,15,BRICK_STAIRS:0,10,BRICK_STAIRS:1,10,BRICK_STAIRS:2,10,BRICK_STAIRS:3,10,STEP:12,15,STEP:4,50,BRICK:0,100)
RandomBlock(0,5,-1,BRICK:0,50,MONSTER_EGGS:2,15,MONSTER_EGGS:3,15,MONSTER_EGGS:4,15,BRICK_STAIRS:0,10,BRICK_STAIRS:1,10,BRICK_STAIRS:2,10,BRICK_STAIRS:3,10,STEP:12,15,STEP:4,50,BRICK:0,100)
Block(0,5,0,BRICK_STAIRS:5)
RandomBlock(0,5,1,WEB:0,14,AIR:0,100)
Block(0,5,2,AIR:0)
Block(0,5,3,AIR:0)
Block(0,5,4,AIR:0)
Block(0,5,5,AIR:0)
Block(0,5,6,AIR:0)
RandomBlock(0,5,7,GLOWSTONE:0,6,AIR:0,100)
Block(0,5,8,AIR:0)
RandomBlock(0,6,-1,BRICK:0,50,MONSTER_EGGS:2,15,MONSTER_EGGS:3,15,MONSTER_EGGS:4,15,BRICK_STAIRS:0,10,BRICK_STAIRS:1,10,BRICK_STAIRS:2,10,BRICK_STAIRS:3,10,STEP:12,15,STEP:4,50,BRICK:0,100)
RandomBlock(0,6,0,BRICK:0,50,MONSTER_EGGS:2,15,MONSTER_EGGS:3,15,MONSTER_EGGS:4,15,BRICK_STAIRS:0,10,BRICK_STAIRS:1,10,BRICK_STAIRS:2,10,BRICK_STAIRS:3,10,STEP:12,15,STEP:4,50,BRICK:0,100)
RandomBlock(0,6,1,BRICK:0,50,MONSTER_EGGS:2,15,MONSTER_EGGS:3,15,MONSTER_EGGS:4,15,BRICK_STAIRS:0,10,BRICK_STAIRS:1,10,BRICK_STAIRS:2,10,BRICK_STAIRS:3,10,STEP:12,15,STEP:4,50,BRICK:0,100)
RandomBlock(0,6,2,WEB:0,14,AIR:0,100)
Block(0,6,3,AIR:0)
Block(0,6,4,AIR:0)
Block(0,6,5,AIR:0)
Block(0,6,6,AIR:0)
Block(0,6,7,IRON_FENCE:0)
Block(0,6,8,AIR:0)
RandomBlock(0,7,0,BRICK:0,50,MONSTER_EGGS:2,15,MONSTER_EGGS:3,15,MONSTER_EGGS:4,15,BRICK_STAIRS:0,10,BRICK_STAIRS:1,10,BRICK_STAIRS:2,10,BRICK_STAIRS:3,10,STEP:12,15,STEP:4,50,BRICK:0,100)
RandomBlock(0,7,1,BRICK:0,50,MONSTER_EGGS:2,15,MONSTER_EGGS:3,15,MONSTER_EGGS:4,15,BRICK_STAIRS:0,10,BRICK_STAIRS:1,10,BRICK_STAIRS:2,10,BRICK_STAIRS:3,10,STEP:12,15,STEP:4,50,BRICK:0,100)
RandomBlock(0,7,2,BRICK:0,50,MONSTER_EGGS:2,15,MONSTER_EGGS:3,15,MONSTER_EGGS:4,15,BRICK_STAIRS:0,10,BRICK_STAIRS:1,10,BRICK_STAIRS:2,10,BRICK_STAIRS:3,10,STEP:12,15,STEP:4,50,BRICK:0,100)
RandomBlock(0,7,3,WEB:0,14,AIR:0,100)
Block(0,7,4,AIR:0)
Block(0,7,5,AIR:0)
Block(0,7,6,AIR:0)
Block(0,7,7,IRON_FENCE:0)
Block(0,7,8,AIR:0)
RandomBlock(0,8,3,BRICK:0,50,MONSTER_EGGS:2,15,MONSTER_EGGS:3,15,MONSTER_EGGS:4,15,BRICK_STAIRS:0,10,BRICK_STAIRS:1,10,BRICK_STAIRS:2,10,BRICK_STAIRS:3,10,STEP:12,15,STEP:4,50,BRICK:0,100)
RandomBlock(0,8,4,BRICK:0,50,MONSTER_EGGS:2,15,MONSTER_EGGS:3,15,MONSTER_EGGS:4,15,BRICK_STAIRS:0,10,BRICK_STAIRS:1,10,BRICK_STAIRS:2,10,BRICK_STAIRS:3,10,STEP:12,15,STEP:4,50,BRICK:0,100)
RandomBlock(0,8,5,BRICK:0,50,MONSTER_EGGS:2,15,MONSTER_EGGS:3,15,MONSTER_EGGS:4,15,BRICK_STAIRS:0,10,BRICK_STAIRS:1,10,BRICK_STAIRS:2,10,BRICK_STAIRS:3,10,STEP:12,15,STEP:4,50,BRICK:0,100)
RandomBlock(0,8,6,BRICK:0,50,MONSTER_EGGS:2,15,MONSTER_EGGS:3,15,MONSTER_EGGS:4,15,BRICK_STAIRS:0,10,BRICK_STAIRS:1,10,BRICK_STAIRS:2,10,BRICK_STAIRS:3,10,STEP:12,15,STEP:4,50,BRICK:0,100)
RandomBlock(0,8,7,BRICK:0,50,MONSTER_EGGS:2,15,MONSTER_EGGS:3,15,MONSTER_EGGS:4,15,BRICK_STAIRS:0,10,BRICK_STAIRS:1,10,BRICK_STAIRS:2,10,BRICK_STAIRS:3,10,STEP:12,15,STEP:4,50,BRICK:0,100)
RandomBlock(0,8,8,BRICK:0,50,MONSTER_EGGS:2,15,MONSTER_EGGS:3,15,MONSTER_EGGS:4,15,BRICK_STAIRS:0,10,BRICK_STAIRS:1,10,BRICK_STAIRS:2,10,BRICK_STAIRS:3,10,STEP:12,15,STEP:4,50,BRICK:0,100)
RandomBlock(1,0,-7,BRICK:0,50,MONSTER_EGGS:2,15,MONSTER_EGGS:3,15,MONSTER_EGGS:4,15,BRICK_STAIRS:0,10,BRICK_STAIRS:1,10,BRICK_STAIRS:2,10,BRICK_STAIRS:3,10,STEP:12,15,STEP:4,50,BRICK:0,100)
RandomBlock(1,0,-6,BRICK:0,50,MONSTER_EGGS:2,15,MONSTER_EGGS:3,15,MONSTER_EGGS:4,15,BRICK_STAIRS:0,10,BRICK_STAIRS:1,10,BRICK_STAIRS:2,10,BRICK_STAIRS:3,10,STEP:12,15,STEP:4,50,BRICK:0,100)
RandomBlock(1,0,-5,BRICK:0,50,MONSTER_EGGS:2,15,MONSTER_EGGS:3,15,MONSTER_EGGS:4,15,BRICK_STAIRS:0,10,BRICK_STAIRS:1,10,BRICK_STAIRS:2,10,BRICK_STAIRS:3,10,STEP:12,15,STEP:4,50,BRICK:0,100)
RandomBlock(1,0,-4,BRICK:0,50,MONSTER_EGGS:2,15,MONSTER_EGGS:3,15,MONSTER_EGGS:4,15,BRICK_STAIRS:0,10,BRICK_STAIRS:1,10,BRICK_STAIRS:2,10,BRICK_STAIRS:3,10,STEP:12,15,STEP:4,50,BRICK:0,100)
RandomBlock(1,0,-3,BRICK:0,50,MONSTER_EGGS:2,15,MONSTER_EGGS:3,15,MONSTER_EGGS:4,15,BRICK_STAIRS:0,10,BRICK_STAIRS:1,10,BRICK_STAIRS:2,10,BRICK_STAIRS:3,10,STEP:12,15,STEP:4,50,BRICK:0,100)
RandomBlock(1,0,-2,BRICK:0,50,MONSTER_EGGS:2,15,MONSTER_EGGS:3,15,MONSTER_EGGS:4,15,BRICK_STAIRS:0,10,BRICK_STAIRS:1,10,BRICK_STAIRS:2,10,BRICK_STAIRS:3,10,STEP:12,15,STEP:4,50,BRICK:0,100)
RandomBlock(1,0,-1,BRICK:0,50,MONSTER_EGGS:2,15,MONSTER_EGGS:3,15,MONSTER_EGGS:4,15,BRICK_STAIRS:0,10,BRICK_STAIRS:1,10,BRICK_STAIRS:2,10,BRICK_STAIRS:3,10,STEP:12,15,STEP:4,50,BRICK:0,100)
RandomBlock(1,0,0,BRICK:0,50,MONSTER_EGGS:2,15,MONSTER_EGGS:3,15,MONSTER_EGGS:4,15,BRICK_STAIRS:0,10,BRICK_STAIRS:1,10,BRICK_STAIRS:2,10,BRICK_STAIRS:3,10,STEP:12,15,STEP:4,50,BRICK:0,100)
RandomBlock(1,0,1,BRICK:0,50,MONSTER_EGGS:2,15,MONSTER_EGGS:3,15,MONSTER_EGGS:4,15,BRICK_STAIRS:0,10,BRICK_STAIRS:1,10,BRICK_STAIRS:2,10,BRICK_STAIRS:3,10,STEP:12,15,STEP:4,50,BRICK:0,100)
RandomBlock(1,0,2,BRICK:0,50,MONSTER_EGGS:2,15,MONSTER_EGGS:3,15,MONSTER_EGGS:4,15,BRICK_STAIRS:0,10,BRICK_STAIRS:1,10,BRICK_STAIRS:2,10,BRICK_STAIRS:3,10,STEP:12,15,STEP:4,50,BRICK:0,100)
RandomBlock(1,0,3,BRICK:0,50,MONSTER_EGGS:2,15,MONSTER_EGGS:3,15,MONSTER_EGGS:4,15,BRICK_STAIRS:0,10,BRICK_STAIRS:1,10,BRICK_STAIRS:2,10,BRICK_STAIRS:3,10,STEP:12,15,STEP:4,50,BRICK:0,100)
RandomBlock(1,0,4,BRICK:0,50,MONSTER_EGGS:2,15,MONSTER_EGGS:3,15,MONSTER_EGGS:4,15,BRICK_STAIRS:0,10,BRICK_STAIRS:1,10,BRICK_STAIRS:2,10,BRICK_STAIRS:3,10,STEP:12,15,STEP:4,50,BRICK:0,100)
RandomBlock(1,0,5,BRICK:0,50,MONSTER_EGGS:2,15,MONSTER_EGGS:3,15,MONSTER_EGGS:4,15,BRICK_STAIRS:0,10,BRICK_STAIRS:1,10,BRICK_STAIRS:2,10,BRICK_STAIRS:3,10,STEP:12,15,STEP:4,50,BRICK:0,100)
RandomBlock(1,0,6,BRICK:0,50,MONSTER_EGGS:2,15,MONSTER_EGGS:3,15,MONSTER_EGGS:4,15,BRICK_STAIRS:0,10,BRICK_STAIRS:1,10,BRICK_STAIRS:2,10,BRICK_STAIRS:3,10,STEP:12,15,STEP:4,50,BRICK:0,100)
RandomBlock(1,0,7,BRICK:0,50,MONSTER_EGGS:2,15,MONSTER_EGGS:3,15,MONSTER_EGGS:4,15,BRICK_STAIRS:0,10,BRICK_STAIRS:1,10,BRICK_STAIRS:2,10,BRICK_STAIRS:3,10,STEP:12,15,STEP:4,50,BRICK:0,100)
RandomBlock(1,0,8,BRICK:0,50,MONSTER_EGGS:2,15,MONSTER_EGGS:3,15,MONSTER_EGGS:4,15,BRICK_STAIRS:0,10,BRICK_STAIRS:1,10,BRICK_STAIRS:2,10,BRICK_STAIRS:3,10,STEP:12,15,STEP:4,50,BRICK:0,100)
RandomBlock(1,1,-7,WEB:0,14,AIR:0,100)
RandomBlock(1,1,-6,WEB:0,14,AIR:0,100)
RandomBlock(1,1,-5,WEB:0,14,AIR:0,100)
RandomBlock(1,1,-4,WEB:0,14,AIR:0,100)
RandomBlock(1,1,-3,WEB:0,14,AIR:0,100)
RandomBlock(1,1,-2,WEB:0,14,AIR:0,100)
RandomBlock(1,1,-1,WEB:0,14,AIR:0,100)
Block(1,1,0,AIR:0)
Block(1,1,1,AIR:0)
Block(1,1,2,AIR:0)
Block(1,1,3,STEP:0)
RandomBlock(1,1,4,DOUBLE_STEP:0,16,IRON_FENCE:0,16,MOB_SPAWNER:0,../../ruins_spawners/alchemist_multi.nbt,100)
Block(1,1,5,STEP:0)
Block(1,1,6,AIR:0)
RandomBlock(1,1,7,WEB:0,14,AIR:0,100)
Block(1,1,8,AIR:0)
Block(1,2,-7,AIR:0)
Block(1,2,-6,AIR:0)
Block(1,2,-5,AIR:0)
Block(1,2,-4,AIR:0)
Block(1,2,-3,AIR:0)
Block(1,2,-2,AIR:0)
RandomBlock(1,2,-1,WEB:0,14,AIR:0,100)
Block(1,2,0,AIR:0)
Block(1,2,1,AIR:0)
Block(1,2,2,AIR:0)
Block(1,2,3,AIR:0)
Block(1,2,4,IRON_FENCE:0)
Block(1,2,5,AIR:0)
Block(1,2,6,AIR:0)
RandomBlock(1,2,7,WEB:0,14,AIR:0,100)
Block(1,2,8,AIR:0)
Block(1,3,-7,AIR:0)
Block(1,3,-6,AIR:0)
Block(1,3,-5,AIR:0)
Block(1,3,-4,AIR:0)
Block(1,3,-3,AIR:0)
Block(1,3,-2,AIR:0)
RandomBlock(1,3,-1,WEB:0,14,AIR:0,100)
Block(1,3,0,AIR:0)
Block(1,3,1,AIR:0)
Block(1,3,2,AIR:0)
Block(1,3,3,AIR:0)
Block(1,3,4,GLASS:0)
Block(1,3,5,AIR:0)
Block(1,3,6,AIR:0)
Block(1,3,7,AIR:0)
Block(1,3,8,AIR:0)
Block(1,4,-7,AIR:0)
Block(1,4,-6,AIR:0)
Block(1,4,-5,AIR:0)
Block(1,4,-4,AIR:0)
Block(1,4,-3,AIR:0)
Block(1,4,-2,AIR:0)
Block(1,4,-1,STEP:12)
Block(1,4,0,AIR:0)
Block(1,4,1,AIR:0)
Block(1,4,2,AIR:0)
Block(1,4,3,AIR:0)
Block(1,4,4,AIR:0)
Block(1,4,5,AIR:0)
Block(1,4,6,AIR:0)
Block(1,4,7,AIR:0)
Block(1,4,8,AIR:0)
Block(1,5,-7,BRICK_STAIRS:5)
Block(1,5,-6,BRICK_STAIRS:5)
Block(1,5,-5,BRICK_STAIRS:5)
Block(1,5,-4,STEP:12)
Block(1,5,-3,BRICK_STAIRS:5)
Block(1,5,-2,BRICK_STAIRS:5)
RandomBlock(1,5,-1,BRICK:0,50,MONSTER_EGGS:2,15,MONSTER_EGGS:3,15,MONSTER_EGGS:4,15,BRICK_STAIRS:0,10,BRICK_STAIRS:1,10,BRICK_STAIRS:2,10,BRICK_STAIRS:3,10,STEP:12,15,STEP:4,50,BRICK:0,100)
RandomBlock(1,5,0,WEB:0,14,AIR:0,100)
Block(1,5,1,AIR:0)
Block(1,5,2,AIR:0)
Block(1,5,3,AIR:0)
Block(1,5,4,AIR:0)
Block(1,5,5,AIR:0)
Block(1,5,6,AIR:0)
Block(1,5,7,AIR:0)
Block(1,5,8,AIR:0)
RandomBlock(1,6,-7,BRICK:0,50,MONSTER_EGGS:2,15,MONSTER_EGGS:3,15,MONSTER_EGGS:4,15,BRICK_STAIRS:0,10,BRICK_STAIRS:1,10,BRICK_STAIRS:2,10,BRICK_STAIRS:3,10,STEP:12,15,STEP:4,50,BRICK:0,100)
RandomBlock(1,6,-6,BRICK:0,50,MONSTER_EGGS:2,15,MONSTER_EGGS:3,15,MONSTER_EGGS:4,15,BRICK_STAIRS:0,10,BRICK_STAIRS:1,10,BRICK_STAIRS:2,10,BRICK_STAIRS:3,10,STEP:12,15,STEP:4,50,BRICK:0,100)
RandomBlock(1,6,-5,BRICK:0,50,MONSTER_EGGS:2,15,MONSTER_EGGS:3,15,MONSTER_EGGS:4,15,BRICK_STAIRS:0,10,BRICK_STAIRS:1,10,BRICK_STAIRS:2,10,BRICK_STAIRS:3,10,STEP:12,15,STEP:4,50,BRICK:0,100)
RandomBlock(1,6,-4,BRICK:0,50,MONSTER_EGGS:2,15,MONSTER_EGGS:3,15,MONSTER_EGGS:4,15,BRICK_STAIRS:0,10,BRICK_STAIRS:1,10,BRICK_STAIRS:2,10,BRICK_STAIRS:3,10,STEP:12,15,STEP:4,50,BRICK:0,100)
RandomBlock(1,6,-3,BRICK:0,50,MONSTER_EGGS:2,15,MONSTER_EGGS:3,15,MONSTER_EGGS:4,15,BRICK_STAIRS:0,10,BRICK_STAIRS:1,10,BRICK_STAIRS:2,10,BRICK_STAIRS:3,10,STEP:12,15,STEP:4,50,BRICK:0,100)
RandomBlock(1,6,-2,BRICK:0,50,MONSTER_EGGS:2,15,MONSTER_EGGS:3,15,MONSTER_EGGS:4,15,BRICK_STAIRS:0,10,BRICK_STAIRS:1,10,BRICK_STAIRS:2,10,BRICK_STAIRS:3,10,STEP:12,15,STEP:4,50,BRICK:0,100)
RandomBlock(1,6,-1,BRICK:0,50,MONSTER_EGGS:2,15,MONSTER_EGGS:3,15,MONSTER_EGGS:4,15,BRICK_STAIRS:0,10,BRICK_STAIRS:1,10,BRICK_STAIRS:2,10,BRICK_STAIRS:3,10,STEP:12,15,STEP:4,50,BRICK:0,100)
Block(1,6,0,STEP:12)
RandomBlock(1,6,1,WEB:0,14,AIR:0,100)
Block(1,6,2,AIR:0)
Block(1,6,3,AIR:0)
Block(1,6,4,AIR:0)
Block(1,6,5,AIR:0)
Block(1,6,6,AIR:0)
Block(1,6,7,AIR:0)
Block(1,6,8,AIR:0)
RandomBlock(1,7,-1,BRICK:0,50,MONSTER_EGGS:2,15,MONSTER_EGGS:3,15,MONSTER_EGGS:4,15,BRICK_STAIRS:0,10,BRICK_STAIRS:1,10,BRICK_STAIRS:2,10,BRICK_STAIRS:3,10,STEP:12,15,STEP:4,50,BRICK:0,100)
RandomBlock(1,7,0,BRICK:0,50,MONSTER_EGGS:2,15,MONSTER_EGGS:3,15,MONSTER_EGGS:4,15,BRICK_STAIRS:0,10,BRICK_STAIRS:1,10,BRICK_STAIRS:2,10,BRICK_STAIRS:3,10,STEP:12,15,STEP:4,50,BRICK:0,100)
RandomBlock(1,7,1,WEB:0,14,AIR:0,100)
Block(1,7,2,AIR:0)
Block(1,7,3,AIR:0)
Block(1,7,4,AIR:0)
Block(1,7,5,AIR:0)
Block(1,7,6,AIR:0)
Block(1,7,7,AIR:0)
Block(1,7,8,AIR:0)
RandomBlock(1,8,0,BRICK:0,50,MONSTER_EGGS:2,15,MONSTER_EGGS:3,15,MONSTER_EGGS:4,15,BRICK_STAIRS:0,10,BRICK_STAIRS:1,10,BRICK_STAIRS:2,10,BRICK_STAIRS:3,10,STEP:12,15,STEP:4,50,BRICK:0,100)
RandomBlock(1,8,1,BRICK:0,50,MONSTER_EGGS:2,15,MONSTER_EGGS:3,15,MONSTER_EGGS:4,15,BRICK_STAIRS:0,10,BRICK_STAIRS:1,10,BRICK_STAIRS:2,10,BRICK_STAIRS:3,10,STEP:12,15,STEP:4,50,BRICK:0,100)
RandomBlock(1,8,2,BRICK:0,50,MONSTER_EGGS:2,15,MONSTER_EGGS:3,15,MONSTER_EGGS:4,15,BRICK_STAIRS:0,10,BRICK_STAIRS:1,10,BRICK_STAIRS:2,10,BRICK_STAIRS:3,10,STEP:12,15,STEP:4,50,BRICK:0,100)
Block(1,8,3,AIR:0)
Block(1,8,4,AIR:0)
Block(1,8,5,AIR:0)
Block(1,8,6,AIR:0)
Block(1,8,7,AIR:0)
Block(1,8,8,AIR:0)
RandomBlock(1,9,2,BRICK:0,50,MONSTER_EGGS:2,15,MONSTER_EGGS:3,15,MONSTER_EGGS:4,15,BRICK_STAIRS:0,10,BRICK_STAIRS:1,10,BRICK_STAIRS:2,10,BRICK_STAIRS:3,10,STEP:12,15,STEP:4,50,BRICK:0,100)
RandomBlock(1,9,3,BRICK:0,50,MONSTER_EGGS:2,15,MONSTER_EGGS:3,15,MONSTER_EGGS:4,15,BRICK_STAIRS:0,10,BRICK_STAIRS:1,10,BRICK_STAIRS:2,10,BRICK_STAIRS:3,10,STEP:12,15,STEP:4,50,BRICK:0,100)
RandomBlock(1,9,4,BRICK:0,50,MONSTER_EGGS:2,15,MONSTER_EGGS:3,15,MONSTER_EGGS:4,15,BRICK_STAIRS:0,10,BRICK_STAIRS:1,10,BRICK_STAIRS:2,10,BRICK_STAIRS:3,10,STEP:12,15,STEP:4,50,BRICK:0,100)
RandomBlock(1,9,5,BRICK:0,50,MONSTER_EGGS:2,15,MONSTER_EGGS:3,15,MONSTER_EGGS:4,15,BRICK_STAIRS:0,10,BRICK_STAIRS:1,10,BRICK_STAIRS:2,10,BRICK_STAIRS:3,10,STEP:12,15,STEP:4,50,BRICK:0,100)
RandomBlock(1,9,6,BRICK:0,50,MONSTER_EGGS:2,15,MONSTER_EGGS:3,15,MONSTER_EGGS:4,15,BRICK_STAIRS:0,10,BRICK_STAIRS:1,10,BRICK_STAIRS:2,10,BRICK_STAIRS:3,10,STEP:12,15,STEP:4,50,BRICK:0,100)
RandomBlock(1,9,7,BRICK:0,50,MONSTER_EGGS:2,15,MONSTER_EGGS:3,15,MONSTER_EGGS:4,15,BRICK_STAIRS:0,10,BRICK_STAIRS:1,10,BRICK_STAIRS:2,10,BRICK_STAIRS:3,10,STEP:12,15,STEP:4,50,BRICK:0,100)
RandomBlock(1,9,8,BRICK:0,50,MONSTER_EGGS:2,15,MONSTER_EGGS:3,15,MONSTER_EGGS:4,15,BRICK_STAIRS:0,10,BRICK_STAIRS:1,10,BRICK_STAIRS:2,10,BRICK_STAIRS:3,10,STEP:12,15,STEP:4,50,BRICK:0,100)
RandomBlock(2,0,-7,BRICK:0,50,MONSTER_EGGS:2,15,MONSTER_EGGS:3,15,MONSTER_EGGS:4,15,BRICK_STAIRS:0,10,BRICK_STAIRS:1,10,BRICK_STAIRS:2,10,BRICK_STAIRS:3,10,STEP:12,15,STEP:4,50,BRICK:0,100)
RandomBlock(2,0,-6,BRICK:0,50,MONSTER_EGGS:2,15,MONSTER_EGGS:3,15,MONSTER_EGGS:4,15,BRICK_STAIRS:0,10,BRICK_STAIRS:1,10,BRICK_STAIRS:2,10,BRICK_STAIRS:3,10,STEP:12,15,STEP:4,50,BRICK:0,100)
RandomBlock(2,0,-5,BRICK:0,50,MONSTER_EGGS:2,15,MONSTER_EGGS:3,15,MONSTER_EGGS:4,15,BRICK_STAIRS:0,10,BRICK_STAIRS:1,10,BRICK_STAIRS:2,10,BRICK_STAIRS:3,10,STEP:12,15,STEP:4,50,BRICK:0,100)
RandomBlock(2,0,-4,BRICK:0,50,MONSTER_EGGS:2,15,MONSTER_EGGS:3,15,MONSTER_EGGS:4,15,BRICK_STAIRS:0,10,BRICK_STAIRS:1,10,BRICK_STAIRS:2,10,BRICK_STAIRS:3,10,STEP:12,15,STEP:4,50,BRICK:0,100)
RandomBlock(2,0,-3,BRICK:0,50,MONSTER_EGGS:2,15,MONSTER_EGGS:3,15,MONSTER_EGGS:4,15,BRICK_STAIRS:0,10,BRICK_STAIRS:1,10,BRICK_STAIRS:2,10,BRICK_STAIRS:3,10,STEP:12,15,STEP:4,50,BRICK:0,100)
RandomBlock(2,0,-2,BRICK:0,50,MONSTER_EGGS:2,15,MONSTER_EGGS:3,15,MONSTER_EGGS:4,15,BRICK_STAIRS:0,10,BRICK_STAIRS:1,10,BRICK_STAIRS:2,10,BRICK_STAIRS:3,10,STEP:12,15,STEP:4,50,BRICK:0,100)
RandomBlock(2,0,-1,BRICK:0,50,MONSTER_EGGS:2,15,MONSTER_EGGS:3,15,MONSTER_EGGS:4,15,BRICK_STAIRS:0,10,BRICK_STAIRS:1,10,BRICK_STAIRS:2,10,BRICK_STAIRS:3,10,STEP:12,15,STEP:4,50,BRICK:0,100)
RandomBlock(2,0,0,BRICK:0,50,MONSTER_EGGS:2,15,MONSTER_EGGS:3,15,MONSTER_EGGS:4,15,BRICK_STAIRS:0,10,BRICK_STAIRS:1,10,BRICK_STAIRS:2,10,BRICK_STAIRS:3,10,STEP:12,15,STEP:4,50,BRICK:0,100)
RandomBlock(2,0,1,BRICK:0,50,MONSTER_EGGS:2,15,MONSTER_EGGS:3,15,MONSTER_EGGS:4,15,BRICK_STAIRS:0,10,BRICK_STAIRS:1,10,BRICK_STAIRS:2,10,BRICK_STAIRS:3,10,STEP:12,15,STEP:4,50,BRICK:0,100)
RandomBlock(2,0,2,BRICK:0,50,MONSTER_EGGS:2,15,MONSTER_EGGS:3,15,MONSTER_EGGS:4,15,BRICK_STAIRS:0,10,BRICK_STAIRS:1,10,BRICK_STAIRS:2,10,BRICK_STAIRS:3,10,STEP:12,15,STEP:4,50,BRICK:0,100)
RandomBlock(2,0,3,BRICK:0,50,MONSTER_EGGS:2,15,MONSTER_EGGS:3,15,MONSTER_EGGS:4,15,BRICK_STAIRS:0,10,BRICK_STAIRS:1,10,BRICK_STAIRS:2,10,BRICK_STAIRS:3,10,STEP:12,15,STEP:4,50,BRICK:0,100)
RandomBlock(2,0,4,BRICK:0,50,MONSTER_EGGS:2,15,MONSTER_EGGS:3,15,MONSTER_EGGS:4,15,BRICK_STAIRS:0,10,BRICK_STAIRS:1,10,BRICK_STAIRS:2,10,BRICK_STAIRS:3,10,STEP:12,15,STEP:4,50,BRICK:0,100)
RandomBlock(2,0,5,BRICK:0,50,MONSTER_EGGS:2,15,MONSTER_EGGS:3,15,MONSTER_EGGS:4,15,BRICK_STAIRS:0,10,BRICK_STAIRS:1,10,BRICK_STAIRS:2,10,BRICK_STAIRS:3,10,STEP:12,15,STEP:4,50,BRICK:0,100)
RandomBlock(2,0,6,BRICK:0,50,MONSTER_EGGS:2,15,MONSTER_EGGS:3,15,MONSTER_EGGS:4,15,BRICK_STAIRS:0,10,BRICK_STAIRS:1,10,BRICK_STAIRS:2,10,BRICK_STAIRS:3,10,STEP:12,15,STEP:4,50,BRICK:0,100)
RandomBlock(2,0,7,BRICK:0,50,MONSTER_EGGS:2,15,MONSTER_EGGS:3,15,MONSTER_EGGS:4,15,BRICK_STAIRS:0,10,BRICK_STAIRS:1,10,BRICK_STAIRS:2,10,BRICK_STAIRS:3,10,STEP:12,15,STEP:4,50,BRICK:0,100)
RandomBlock(2,0,8,BRICK:0,50,MONSTER_EGGS:2,15,MONSTER_EGGS:3,15,MONSTER_EGGS:4,15,BRICK_STAIRS:0,10,BRICK_STAIRS:1,10,BRICK_STAIRS:2,10,BRICK_STAIRS:3,10,STEP:12,15,STEP:4,50,BRICK:0,100)
RandomBlock(2,1,-7,WEB:0,14,AIR:0,100)
RandomBlock(2,1,-6,WEB:0,14,AIR:0,100)
RandomBlock(2,1,-5,WEB:0,14,AIR:0,100)
RandomBlock(2,1,-4,WEB:0,14,AIR:0,100)
RandomBlock(2,1,-3,WEB:0,14,AIR:0,100)
RandomBlock(2,1,-2,WEB:0,14,AIR:0,100)
RandomBlock(2,1,-1,WEB:0,14,AIR:0,100)
Block(2,1,0,AIR:0)
Block(2,1,1,AIR:0)
Block(2,1,2,AIR:0)
Block(2,1,3,AIR:0)
Block(2,1,4,STEP:0)
Block(2,1,5,AIR:0)
Block(2,1,6,AIR:0)
Block(2,1,7,AIR:0)
Block(2,1,8,AIR:0)
Block(2,2,-7,AIR:0)
Block(2,2,-6,AIR:0)
Block(2,2,-5,AIR:0)
Block(2,2,-4,AIR:0)
Block(2,2,-3,AIR:0)
Block(2,2,-2,AIR:0)
RandomBlock(2,2,-1,WEB:0,14,AIR:0,100)
Block(2,2,0,AIR:0)
Block(2,2,1,AIR:0)
Block(2,2,2,AIR:0)
Block(2,2,3,AIR:0)
Block(2,2,4,AIR:0)
Block(2,2,5,AIR:0)
Block(2,2,6,AIR:0)
Block(2,2,7,AIR:0)
Block(2,2,8,AIR:0)
Block(2,3,-7,AIR:0)
Block(2,3,-6,AIR:0)
Block(2,3,-5,AIR:0)
Block(2,3,-4,AIR:0)
Block(2,3,-3,AIR:0)
Block(2,3,-2,AIR:0)
RandomBlock(2,3,-1,WEB:0,14,AIR:0,100)
Block(2,3,0,AIR:0)
Block(2,3,1,AIR:0)
Block(2,3,2,AIR:0)
Block(2,3,3,AIR:0)
Block(2,3,4,AIR:0)
Block(2,3,5,AIR:0)
Block(2,3,6,AIR:0)
Block(2,3,7,AIR:0)
Block(2,3,8,AIR:0)
Block(2,4,-7,AIR:0)
Block(2,4,-6,AIR:0)
Block(2,4,-5,AIR:0)
Block(2,4,-4,AIR:0)
Block(2,4,-3,AIR:0)
Block(2,4,-2,AIR:0)
RandomBlock(2,4,-1,WEB:0,14,AIR:0,100)
Block(2,4,0,AIR:0)
Block(2,4,1,AIR:0)
Block(2,4,2,AIR:0)
Block(2,4,3,AIR:0)
Block(2,4,4,AIR:0)
Block(2,4,5,AIR:0)
Block(2,4,6,AIR:0)
Block(2,4,7,AIR:0)
Block(2,4,8,AIR:0)
Block(2,5,-7,AIR:0)
Block(2,5,-6,AIR:0)
Block(2,5,-5,AIR:0)
Block(2,5,-4,AIR:0)
Block(2,5,-3,AIR:0)
Block(2,5,-2,AIR:0)
Block(2,5,-1,BRICK_STAIRS:5)
Block(2,5,0,AIR:0)
Block(2,5,1,AIR:0)
Block(2,5,2,AIR:0)
Block(2,5,3,AIR:0)
Block(2,5,4,AIR:0)
Block(2,5,5,AIR:0)
Block(2,5,6,AIR:0)
Block(2,5,7,AIR:0)
Block(2,5,8,AIR:0)
Block(2,6,-7,STEP:12)
Block(2,6,-6,STEP:12)
Block(2,6,-5,STEP:12)
Block(2,6,-4,STEP:12)
Block(2,6,-3,STEP:12)
Block(2,6,-2,STEP:12)
RandomBlock(2,6,-1,BRICK:0,50,MONSTER_EGGS:2,15,MONSTER_EGGS:3,15,MONSTER_EGGS:4,15,BRICK_STAIRS:0,10,BRICK_STAIRS:1,10,BRICK_STAIRS:2,10,BRICK_STAIRS:3,10,STEP:12,15,STEP:4,50,BRICK:0,100)
Block(2,6,0,AIR:0)
Block(2,6,1,AIR:0)
Block(2,6,2,AIR:0)
Block(2,6,3,AIR:0)
Block(2,6,4,AIR:0)
Block(2,6,5,AIR:0)
Block(2,6,6,AIR:0)
Block(2,6,7,AIR:0)
Block(2,6,8,AIR:0)
RandomBlock(2,7,-7,BRICK:0,50,MONSTER_EGGS:2,15,MONSTER_EGGS:3,15,MONSTER_EGGS:4,15,BRICK_STAIRS:0,10,BRICK_STAIRS:1,10,BRICK_STAIRS:2,10,BRICK_STAIRS:3,10,STEP:12,15,STEP:4,50,BRICK:0,100)
RandomBlock(2,7,-6,BRICK:0,50,MONSTER_EGGS:2,15,MONSTER_EGGS:3,15,MONSTER_EGGS:4,15,BRICK_STAIRS:0,10,BRICK_STAIRS:1,10,BRICK_STAIRS:2,10,BRICK_STAIRS:3,10,STEP:12,15,STEP:4,50,BRICK:0,100)
RandomBlock(2,7,-5,BRICK:0,50,MONSTER_EGGS:2,15,MONSTER_EGGS:3,15,MONSTER_EGGS:4,15,BRICK_STAIRS:0,10,BRICK_STAIRS:1,10,BRICK_STAIRS:2,10,BRICK_STAIRS:3,10,STEP:12,15,STEP:4,50,BRICK:0,100)
RandomBlock(2,7,-4,BRICK:0,50,MONSTER_EGGS:2,15,MONSTER_EGGS:3,15,MONSTER_EGGS:4,15,BRICK_STAIRS:0,10,BRICK_STAIRS:1,10,BRICK_STAIRS:2,10,BRICK_STAIRS:3,10,STEP:12,15,STEP:4,50,BRICK:0,100)
RandomBlock(2,7,-3,BRICK:0,50,MONSTER_EGGS:2,15,MONSTER_EGGS:3,15,MONSTER_EGGS:4,15,BRICK_STAIRS:0,10,BRICK_STAIRS:1,10,BRICK_STAIRS:2,10,BRICK_STAIRS:3,10,STEP:12,15,STEP:4,50,BRICK:0,100)
RandomBlock(2,7,-2,BRICK:0,50,MONSTER_EGGS:2,15,MONSTER_EGGS:3,15,MONSTER_EGGS:4,15,BRICK_STAIRS:0,10,BRICK_STAIRS:1,10,BRICK_STAIRS:2,10,BRICK_STAIRS:3,10,STEP:12,15,STEP:4,50,BRICK:0,100)
RandomBlock(2,7,-1,BRICK:0,50,MONSTER_EGGS:2,15,MONSTER_EGGS:3,15,MONSTER_EGGS:4,15,BRICK_STAIRS:0,10,BRICK_STAIRS:1,10,BRICK_STAIRS:2,10,BRICK_STAIRS:3,10,STEP:12,15,STEP:4,50,BRICK:0,100)
Block(2,7,0,BRICK_STAIRS:5)
Block(2,7,1,AIR:0)
Block(2,7,2,AIR:0)
Block(2,7,3,AIR:0)
Block(2,7,4,AIR:0)
Block(2,7,5,AIR:0)
Block(2,7,6,AIR:0)
Block(2,7,7,AIR:0)
Block(2,7,8,AIR:0)
RandomBlock(2,8,-1,BRICK:0,50,MONSTER_EGGS:2,15,MONSTER_EGGS:3,15,MONSTER_EGGS:4,15,BRICK_STAIRS:0,10,BRICK_STAIRS:1,10,BRICK_STAIRS:2,10,BRICK_STAIRS:3,10,STEP:12,15,STEP:4,50,BRICK:0,100)
RandomBlock(2,8,0,BRICK:0,50,MONSTER_EGGS:2,15,MONSTER_EGGS:3,15,MONSTER_EGGS:4,15,BRICK_STAIRS:0,10,BRICK_STAIRS:1,10,BRICK_STAIRS:2,10,BRICK_STAIRS:3,10,STEP:12,15,STEP:4,50,BRICK:0,100)
Block(2,8,1,AIR:0)
Block(2,8,2,AIR:0)
Block(2,8,3,AIR:0)
Block(2,8,4,AIR:0)
Block(2,8,5,AIR:0)
Block(2,8,6,AIR:0)
Block(2,8,7,AIR:0)
Block(2,8,8,AIR:0)
RandomBlock(2,9,0,BRICK:0,50,MONSTER_EGGS:2,15,MONSTER_EGGS:3,15,MONSTER_EGGS:4,15,BRICK_STAIRS:0,10,BRICK_STAIRS:1,10,BRICK_STAIRS:2,10,BRICK_STAIRS:3,10,STEP:12,15,STEP:4,50,BRICK:0,100)
RandomBlock(2,9,1,BRICK:0,50,MONSTER_EGGS:2,15,MONSTER_EGGS:3,15,MONSTER_EGGS:4,15,BRICK_STAIRS:0,10,BRICK_STAIRS:1,10,BRICK_STAIRS:2,10,BRICK_STAIRS:3,10,STEP:12,15,STEP:4,50,BRICK:0,100)
RandomBlock(2,9,2,BRICK:0,50,MONSTER_EGGS:2,15,MONSTER_EGGS:3,15,MONSTER_EGGS:4,15,BRICK_STAIRS:0,10,BRICK_STAIRS:1,10,BRICK_STAIRS:2,10,BRICK_STAIRS:3,10,STEP:12,15,STEP:4,50,BRICK:0,100)
RandomBlock(2,9,3,BRICK:0,50,MONSTER_EGGS:2,15,MONSTER_EGGS:3,15,MONSTER_EGGS:4,15,BRICK_STAIRS:0,10,BRICK_STAIRS:1,10,BRICK_STAIRS:2,10,BRICK_STAIRS:3,10,STEP:12,15,STEP:4,50,BRICK:0,100)
RandomBlock(2,9,4,BRICK:0,50,MONSTER_EGGS:2,15,MONSTER_EGGS:3,15,MONSTER_EGGS:4,15,BRICK_STAIRS:0,10,BRICK_STAIRS:1,10,BRICK_STAIRS:2,10,BRICK_STAIRS:3,10,STEP:12,15,STEP:4,50,BRICK:0,100)
RandomBlock(2,9,5,BRICK:0,50,MONSTER_EGGS:2,15,MONSTER_EGGS:3,15,MONSTER_EGGS:4,15,BRICK_STAIRS:0,10,BRICK_STAIRS:1,10,BRICK_STAIRS:2,10,BRICK_STAIRS:3,10,STEP:12,15,STEP:4,50,BRICK:0,100)
RandomBlock(2,9,6,BRICK:0,50,MONSTER_EGGS:2,15,MONSTER_EGGS:3,15,MONSTER_EGGS:4,15,BRICK_STAIRS:0,10,BRICK_STAIRS:1,10,BRICK_STAIRS:2,10,BRICK_STAIRS:3,10,STEP:12,15,STEP:4,50,BRICK:0,100)
RandomBlock(2,9,7,BRICK:0,50,MONSTER_EGGS:2,15,MONSTER_EGGS:3,15,MONSTER_EGGS:4,15,BRICK_STAIRS:0,10,BRICK_STAIRS:1,10,BRICK_STAIRS:2,10,BRICK_STAIRS:3,10,STEP:12,15,STEP:4,50,BRICK:0,100)
RandomBlock(2,9,8,BRICK:0,50,MONSTER_EGGS:2,15,MONSTER_EGGS:3,15,MONSTER_EGGS:4,15,BRICK_STAIRS:0,10,BRICK_STAIRS:1,10,BRICK_STAIRS:2,10,BRICK_STAIRS:3,10,STEP:12,15,STEP:4,50,BRICK:0,100)
RandomBlock(3,0,-7,BRICK:0,50,MONSTER_EGGS:2,15,MONSTER_EGGS:3,15,MONSTER_EGGS:4,15,BRICK_STAIRS:0,10,BRICK_STAIRS:1,10,BRICK_STAIRS:2,10,BRICK_STAIRS:3,10,STEP:12,15,STEP:4,50,BRICK:0,100)
RandomBlock(3,0,-6,BRICK:0,50,MONSTER_EGGS:2,15,MONSTER_EGGS:3,15,MONSTER_EGGS:4,15,BRICK_STAIRS:0,10,BRICK_STAIRS:1,10,BRICK_STAIRS:2,10,BRICK_STAIRS:3,10,STEP:12,15,STEP:4,50,BRICK:0,100)
RandomBlock(3,0,-5,BRICK:0,50,MONSTER_EGGS:2,15,MONSTER_EGGS:3,15,MONSTER_EGGS:4,15,BRICK_STAIRS:0,10,BRICK_STAIRS:1,10,BRICK_STAIRS:2,10,BRICK_STAIRS:3,10,STEP:12,15,STEP:4,50,BRICK:0,100)
RandomBlock(3,0,-4,BRICK:0,50,MONSTER_EGGS:2,15,MONSTER_EGGS:3,15,MONSTER_EGGS:4,15,BRICK_STAIRS:0,10,BRICK_STAIRS:1,10,BRICK_STAIRS:2,10,BRICK_STAIRS:3,10,STEP:12,15,STEP:4,50,BRICK:0,100)
RandomBlock(3,0,-3,BRICK:0,50,MONSTER_EGGS:2,15,MONSTER_EGGS:3,15,MONSTER_EGGS:4,15,BRICK_STAIRS:0,10,BRICK_STAIRS:1,10,BRICK_STAIRS:2,10,BRICK_STAIRS:3,10,STEP:12,15,STEP:4,50,BRICK:0,100)
RandomBlock(3,0,-2,BRICK:0,50,MONSTER_EGGS:2,15,MONSTER_EGGS:3,15,MONSTER_EGGS:4,15,BRICK_STAIRS:0,10,BRICK_STAIRS:1,10,BRICK_STAIRS:2,10,BRICK_STAIRS:3,10,STEP:12,15,STEP:4,50,BRICK:0,100)
RandomBlock(3,0,-1,BRICK:0,50,MONSTER_EGGS:2,15,MONSTER_EGGS:3,15,MONSTER_EGGS:4,15,BRICK_STAIRS:0,10,BRICK_STAIRS:1,10,BRICK_STAIRS:2,10,BRICK_STAIRS:3,10,STEP:12,15,STEP:4,50,BRICK:0,100)
RandomBlock(3,0,0,BRICK:0,50,MONSTER_EGGS:2,15,MONSTER_EGGS:3,15,MONSTER_EGGS:4,15,BRICK_STAIRS:0,10,BRICK_STAIRS:1,10,BRICK_STAIRS:2,10,BRICK_STAIRS:3,10,STEP:12,15,STEP:4,50,BRICK:0,100)
RandomBlock(3,0,1,BRICK:0,50,MONSTER_EGGS:2,15,MONSTER_EGGS:3,15,MONSTER_EGGS:4,15,BRICK_STAIRS:0,10,BRICK_STAIRS:1,10,BRICK_STAIRS:2,10,BRICK_STAIRS:3,10,STEP:12,15,STEP:4,50,BRICK:0,100)
RandomBlock(3,0,2,BRICK:0,50,MONSTER_EGGS:2,15,MONSTER_EGGS:3,15,MONSTER_EGGS:4,15,BRICK_STAIRS:0,10,BRICK_STAIRS:1,10,BRICK_STAIRS:2,10,BRICK_STAIRS:3,10,STEP:12,15,STEP:4,50,BRICK:0,100)
RandomBlock(3,0,3,BRICK:0,50,MONSTER_EGGS:2,15,MONSTER_EGGS:3,15,MONSTER_EGGS:4,15,BRICK_STAIRS:0,10,BRICK_STAIRS:1,10,BRICK_STAIRS:2,10,BRICK_STAIRS:3,10,STEP:12,15,STEP:4,50,BRICK:0,100)
RandomBlock(3,0,4,BRICK:0,50,MONSTER_EGGS:2,15,MONSTER_EGGS:3,15,MONSTER_EGGS:4,15,BRICK_STAIRS:0,10,BRICK_STAIRS:1,10,BRICK_STAIRS:2,10,BRICK_STAIRS:3,10,STEP:12,15,STEP:4,50,BRICK:0,100)
RandomBlock(3,0,5,BRICK:0,50,MONSTER_EGGS:2,15,MONSTER_EGGS:3,15,MONSTER_EGGS:4,15,BRICK_STAIRS:0,10,BRICK_STAIRS:1,10,BRICK_STAIRS:2,10,BRICK_STAIRS:3,10,STEP:12,15,STEP:4,50,BRICK:0,100)
RandomBlock(3,0,6,BRICK:0,50,MONSTER_EGGS:2,15,MONSTER_EGGS:3,15,MONSTER_EGGS:4,15,BRICK_STAIRS:0,10,BRICK_STAIRS:1,10,BRICK_STAIRS:2,10,BRICK_STAIRS:3,10,STEP:12,15,STEP:4,50,BRICK:0,100)
RandomBlock(3,0,7,BRICK:0,50,MONSTER_EGGS:2,15,MONSTER_EGGS:3,15,MONSTER_EGGS:4,15,BRICK_STAIRS:0,10,BRICK_STAIRS:1,10,BRICK_STAIRS:2,10,BRICK_STAIRS:3,10,STEP:12,15,STEP:4,50,BRICK:0,100)
RandomBlock(3,0,8,BRICK:0,50,MONSTER_EGGS:2,15,MONSTER_EGGS:3,15,MONSTER_EGGS:4,15,BRICK_STAIRS:0,10,BRICK_STAIRS:1,10,BRICK_STAIRS:2,10,BRICK_STAIRS:3,10,STEP:12,15,STEP:4,50,BRICK:0,100)
RandomBlock(3,1,-7,WEB:0,14,AIR:0,100)
RandomBlock(3,1,-6,WEB:0,14,AIR:0,100)
RandomBlock(3,1,-5,WEB:0,14,AIR:0,100)
RandomBlock(3,1,-4,WEB:0,14,AIR:0,100)
RandomBlock(3,1,-3,WEB:0,14,AIR:0,100)
RandomBlock(3,1,-2,WEB:0,14,AIR:0,100)
RandomBlock(3,1,-1,WEB:0,14,AIR:0,100)
Block(3,1,0,AIR:0)
Block(3,1,1,AIR:0)
Block(3,1,2,AIR:0)
Block(3,1,3,AIR:0)
Block(3,1,4,AIR:0)
Block(3,1,5,AIR:0)
Block(3,1,6,AIR:0)
Block(3,1,7,AIR:0)
Block(3,1,8,AIR:0)
Block(3,2,-7,AIR:0)
Block(3,2,-6,AIR:0)
Block(3,2,-5,AIR:0)
Block(3,2,-4,AIR:0)
Block(3,2,-3,AIR:0)
Block(3,2,-2,AIR:0)
RandomBlock(3,2,-1,WEB:0,14,AIR:0,100)
Block(3,2,0,AIR:0)
Block(3,2,1,AIR:0)
Block(3,2,2,AIR:0)
Block(3,2,3,AIR:0)
Block(3,2,4,AIR:0)
Block(3,2,5,AIR:0)
Block(3,2,6,AIR:0)
Block(3,2,7,AIR:0)
Block(3,2,8,AIR:0)
Block(3,3,-7,AIR:0)
Block(3,3,-6,AIR:0)
Block(3,3,-5,AIR:0)
Block(3,3,-4,AIR:0)
Block(3,3,-3,AIR:0)
Block(3,3,-2,AIR:0)
RandomBlock(3,3,-1,WEB:0,14,AIR:0,100)
Block(3,3,0,AIR:0)
Block(3,3,1,AIR:0)
Block(3,3,2,AIR:0)
Block(3,3,3,AIR:0)
Block(3,3,4,AIR:0)
Block(3,3,5,AIR:0)
Block(3,3,6,AIR:0)
Block(3,3,7,AIR:0)
Block(3,3,8,AIR:0)
Block(3,4,-7,AIR:0)
Block(3,4,-6,AIR:0)
Block(3,4,-5,AIR:0)
RandomBlock(3,4,-4,GLOWSTONE:0,6,AIR:0,100)
Block(3,4,-3,AIR:0)
Block(3,4,-2,AIR:0)
RandomBlock(3,4,-1,WEB:0,14,AIR:0,100)
Block(3,4,0,AIR:0)
Block(3,4,1,AIR:0)
Block(3,4,2,AIR:0)
Block(3,4,3,AIR:0)
Block(3,4,4,AIR:0)
Block(3,4,5,AIR:0)
Block(3,4,6,AIR:0)
Block(3,4,7,AIR:0)
Block(3,4,8,AIR:0)
Block(3,5,-7,AIR:0)
Block(3,5,-6,AIR:0)
Block(3,5,-5,AIR:0)
Block(3,5,-4,IRON_FENCE:0)
Block(3,5,-3,AIR:0)
Block(3,5,-2,AIR:0)
Block(3,5,-1,STEP:12)
Block(3,5,0,AIR:0)
Block(3,5,1,AIR:0)
Block(3,5,2,AIR:0)
Block(3,5,3,AIR:0)
Block(3,5,4,AIR:0)
Block(3,5,5,AIR:0)
Block(3,5,6,AIR:0)
Block(3,5,7,AIR:0)
Block(3,5,8,AIR:0)
Block(3,6,-7,AIR:0)
Block(3,6,-6,AIR:0)
Block(3,6,-5,AIR:0)
Block(3,6,-4,IRON_FENCE:0)
Block(3,6,-3,AIR:0)
Block(3,6,-2,AIR:0)
RandomBlock(3,6,-1,BRICK:0,50,MONSTER_EGGS:2,15,MONSTER_EGGS:3,15,MONSTER_EGGS:4,15,BRICK_STAIRS:0,10,BRICK_STAIRS:1,10,BRICK_STAIRS:2,10,BRICK_STAIRS:3,10,STEP:12,15,STEP:4,50,BRICK:0,100)
Block(3,6,0,AIR:0)
Block(3,6,1,AIR:0)
Block(3,6,2,AIR:0)
RandomBlock(3,6,3,GLOWSTONE:0,6,AIR:0,100)
Block(3,6,4,AIR:0)
Block(3,6,5,AIR:0)
Block(3,6,6,AIR:0)
RandomBlock(3,6,7,GLOWSTONE:0,6,AIR:0,100)
Block(3,6,8,AIR:0)
RandomBlock(3,7,-7,BRICK:0,50,MONSTER_EGGS:2,15,MONSTER_EGGS:3,15,MONSTER_EGGS:4,15,BRICK_STAIRS:0,10,BRICK_STAIRS:1,10,BRICK_STAIRS:2,10,BRICK_STAIRS:3,10,STEP:12,15,STEP:4,50,BRICK:0,100)
RandomBlock(3,7,-6,BRICK:0,50,MONSTER_EGGS:2,15,MONSTER_EGGS:3,15,MONSTER_EGGS:4,15,BRICK_STAIRS:0,10,BRICK_STAIRS:1,10,BRICK_STAIRS:2,10,BRICK_STAIRS:3,10,STEP:12,15,STEP:4,50,BRICK:0,100)
RandomBlock(3,7,-5,BRICK:0,50,MONSTER_EGGS:2,15,MONSTER_EGGS:3,15,MONSTER_EGGS:4,15,BRICK_STAIRS:0,10,BRICK_STAIRS:1,10,BRICK_STAIRS:2,10,BRICK_STAIRS:3,10,STEP:12,15,STEP:4,50,BRICK:0,100)
RandomBlock(3,7,-4,BRICK:0,50,MONSTER_EGGS:2,15,MONSTER_EGGS:3,15,MONSTER_EGGS:4,15,BRICK_STAIRS:0,10,BRICK_STAIRS:1,10,BRICK_STAIRS:2,10,BRICK_STAIRS:3,10,STEP:12,15,STEP:4,50,BRICK:0,100)
RandomBlock(3,7,-3,BRICK:0,50,MONSTER_EGGS:2,15,MONSTER_EGGS:3,15,MONSTER_EGGS:4,15,BRICK_STAIRS:0,10,BRICK_STAIRS:1,10,BRICK_STAIRS:2,10,BRICK_STAIRS:3,10,STEP:12,15,STEP:4,50,BRICK:0,100)
RandomBlock(3,7,-2,BRICK:0,50,MONSTER_EGGS:2,15,MONSTER_EGGS:3,15,MONSTER_EGGS:4,15,BRICK_STAIRS:0,10,BRICK_STAIRS:1,10,BRICK_STAIRS:2,10,BRICK_STAIRS:3,10,STEP:12,15,STEP:4,50,BRICK:0,100)
RandomBlock(3,7,-1,BRICK:0,50,MONSTER_EGGS:2,15,MONSTER_EGGS:3,15,MONSTER_EGGS:4,15,BRICK_STAIRS:0,10,BRICK_STAIRS:1,10,BRICK_STAIRS:2,10,BRICK_STAIRS:3,10,STEP:12,15,STEP:4,50,BRICK:0,100)
Block(3,7,0,AIR:0)
Block(3,7,1,AIR:0)
Block(3,7,2,AIR:0)
Block(3,7,3,IRON_FENCE:0)
Block(3,7,4,AIR:0)
Block(3,7,5,AIR:0)
Block(3,7,6,AIR:0)
Block(3,7,7,IRON_FENCE:0)
Block(3,7,8,AIR:0)
RandomBlock(3,8,-1,BRICK:0,50,MONSTER_EGGS:2,15,MONSTER_EGGS:3,15,MONSTER_EGGS:4,15,BRICK_STAIRS:0,10,BRICK_STAIRS:1,10,BRICK_STAIRS:2,10,BRICK_STAIRS:3,10,STEP:12,15,STEP:4,50,BRICK:0,100)
RandomBlock(3,8,0,BRICK:0,50,MONSTER_EGGS:2,15,MONSTER_EGGS:3,15,MONSTER_EGGS:4,15,BRICK_STAIRS:0,10,BRICK_STAIRS:1,10,BRICK_STAIRS:2,10,BRICK_STAIRS:3,10,STEP:12,15,STEP:4,50,BRICK:0,100)
Block(3,8,1,AIR:0)
Block(3,8,2,AIR:0)
Block(3,8,3,IRON_FENCE:0)
Block(3,8,4,AIR:0)
Block(3,8,5,AIR:0)
Block(3,8,6,AIR:0)
Block(3,8,7,IRON_FENCE:0)
Block(3,8,8,AIR:0)
RandomBlock(3,9,0,BRICK:0,50,MONSTER_EGGS:2,15,MONSTER_EGGS:3,15,MONSTER_EGGS:4,15,BRICK_STAIRS:0,10,BRICK_STAIRS:1,10,BRICK_STAIRS:2,10,BRICK_STAIRS:3,10,STEP:12,15,STEP:4,50,BRICK:0,100)
RandomBlock(3,9,1,BRICK:0,50,MONSTER_EGGS:2,15,MONSTER_EGGS:3,15,MONSTER_EGGS:4,15,BRICK_STAIRS:0,10,BRICK_STAIRS:1,10,BRICK_STAIRS:2,10,BRICK_STAIRS:3,10,STEP:12,15,STEP:4,50,BRICK:0,100)
RandomBlock(3,9,2,BRICK:0,50,MONSTER_EGGS:2,15,MONSTER_EGGS:3,15,MONSTER_EGGS:4,15,BRICK_STAIRS:0,10,BRICK_STAIRS:1,10,BRICK_STAIRS:2,10,BRICK_STAIRS:3,10,STEP:12,15,STEP:4,50,BRICK:0,100)
RandomBlock(3,9,3,BRICK:0,50,MONSTER_EGGS:2,15,MONSTER_EGGS:3,15,MONSTER_EGGS:4,15,BRICK_STAIRS:0,10,BRICK_STAIRS:1,10,BRICK_STAIRS:2,10,BRICK_STAIRS:3,10,STEP:12,15,STEP:4,50,BRICK:0,100)
RandomBlock(3,9,4,BRICK:0,50,MONSTER_EGGS:2,15,MONSTER_EGGS:3,15,MONSTER_EGGS:4,15,BRICK_STAIRS:0,10,BRICK_STAIRS:1,10,BRICK_STAIRS:2,10,BRICK_STAIRS:3,10,STEP:12,15,STEP:4,50,BRICK:0,100)
RandomBlock(3,9,5,BRICK:0,50,MONSTER_EGGS:2,15,MONSTER_EGGS:3,15,MONSTER_EGGS:4,15,BRICK_STAIRS:0,10,BRICK_STAIRS:1,10,BRICK_STAIRS:2,10,BRICK_STAIRS:3,10,STEP:12,15,STEP:4,50,BRICK:0,100)
RandomBlock(3,9,6,BRICK:0,50,MONSTER_EGGS:2,15,MONSTER_EGGS:3,15,MONSTER_EGGS:4,15,BRICK_STAIRS:0,10,BRICK_STAIRS:1,10,BRICK_STAIRS:2,10,BRICK_STAIRS:3,10,STEP:12,15,STEP:4,50,BRICK:0,100)
RandomBlock(3,9,7,BRICK:0,50,MONSTER_EGGS:2,15,MONSTER_EGGS:3,15,MONSTER_EGGS:4,15,BRICK_STAIRS:0,10,BRICK_STAIRS:1,10,BRICK_STAIRS:2,10,BRICK_STAIRS:3,10,STEP:12,15,STEP:4,50,BRICK:0,100)
RandomBlock(3,9,8,BRICK:0,50,MONSTER_EGGS:2,15,MONSTER_EGGS:3,15,MONSTER_EGGS:4,15,BRICK_STAIRS:0,10,BRICK_STAIRS:1,10,BRICK_STAIRS:2,10,BRICK_STAIRS:3,10,STEP:12,15,STEP:4,50,BRICK:0,100)
RandomBlock(4,0,-7,BRICK:0,50,MONSTER_EGGS:2,15,MONSTER_EGGS:3,15,MONSTER_EGGS:4,15,BRICK_STAIRS:0,10,BRICK_STAIRS:1,10,BRICK_STAIRS:2,10,BRICK_STAIRS:3,10,STEP:12,15,STEP:4,50,BRICK:0,100)
RandomBlock(4,0,-6,BRICK:0,50,MONSTER_EGGS:2,15,MONSTER_EGGS:3,15,MONSTER_EGGS:4,15,BRICK_STAIRS:0,10,BRICK_STAIRS:1,10,BRICK_STAIRS:2,10,BRICK_STAIRS:3,10,STEP:12,15,STEP:4,50,BRICK:0,100)
RandomBlock(4,0,-5,BRICK:0,50,MONSTER_EGGS:2,15,MONSTER_EGGS:3,15,MONSTER_EGGS:4,15,BRICK_STAIRS:0,10,BRICK_STAIRS:1,10,BRICK_STAIRS:2,10,BRICK_STAIRS:3,10,STEP:12,15,STEP:4,50,BRICK:0,100)
RandomBlock(4,0,-4,BRICK:0,50,MONSTER_EGGS:2,15,MONSTER_EGGS:3,15,MONSTER_EGGS:4,15,BRICK_STAIRS:0,10,BRICK_STAIRS:1,10,BRICK_STAIRS:2,10,BRICK_STAIRS:3,10,STEP:12,15,STEP:4,50,BRICK:0,100)
RandomBlock(4,0,-3,BRICK:0,50,MONSTER_EGGS:2,15,MONSTER_EGGS:3,15,MONSTER_EGGS:4,15,BRICK_STAIRS:0,10,BRICK_STAIRS:1,10,BRICK_STAIRS:2,10,BRICK_STAIRS:3,10,STEP:12,15,STEP:4,50,BRICK:0,100)
RandomBlock(4,0,-2,BRICK:0,50,MONSTER_EGGS:2,15,MONSTER_EGGS:3,15,MONSTER_EGGS:4,15,BRICK_STAIRS:0,10,BRICK_STAIRS:1,10,BRICK_STAIRS:2,10,BRICK_STAIRS:3,10,STEP:12,15,STEP:4,50,BRICK:0,100)
RandomBlock(4,0,-1,BRICK:0,50,MONSTER_EGGS:2,15,MONSTER_EGGS:3,15,MONSTER_EGGS:4,15,BRICK_STAIRS:0,10,BRICK_STAIRS:1,10,BRICK_STAIRS:2,10,BRICK_STAIRS:3,10,STEP:12,15,STEP:4,50,BRICK:0,100)
RandomBlock(4,0,0,BRICK:0,50,MONSTER_EGGS:2,15,MONSTER_EGGS:3,15,MONSTER_EGGS:4,15,BRICK_STAIRS:0,10,BRICK_STAIRS:1,10,BRICK_STAIRS:2,10,BRICK_STAIRS:3,10,STEP:12,15,STEP:4,50,BRICK:0,100)
RandomBlock(4,0,1,BRICK:0,50,MONSTER_EGGS:2,15,MONSTER_EGGS:3,15,MONSTER_EGGS:4,15,BRICK_STAIRS:0,10,BRICK_STAIRS:1,10,BRICK_STAIRS:2,10,BRICK_STAIRS:3,10,STEP:12,15,STEP:4,50,BRICK:0,100)
RandomBlock(4,0,2,BRICK:0,50,MONSTER_EGGS:2,15,MONSTER_EGGS:3,15,MONSTER_EGGS:4,15,BRICK_STAIRS:0,10,BRICK_STAIRS:1,10,BRICK_STAIRS:2,10,BRICK_STAIRS:3,10,STEP:12,15,STEP:4,50,BRICK:0,100)
RandomBlock(4,0,3,BRICK:0,50,MONSTER_EGGS:2,15,MONSTER_EGGS:3,15,MONSTER_EGGS:4,15,BRICK_STAIRS:0,10,BRICK_STAIRS:1,10,BRICK_STAIRS:2,10,BRICK_STAIRS:3,10,STEP:12,15,STEP:4,50,BRICK:0,100)
RandomBlock(4,0,4,BRICK:0,50,MONSTER_EGGS:2,15,MONSTER_EGGS:3,15,MONSTER_EGGS:4,15,BRICK_STAIRS:0,10,BRICK_STAIRS:1,10,BRICK_STAIRS:2,10,BRICK_STAIRS:3,10,STEP:12,15,STEP:4,50,BRICK:0,100)
RandomBlock(4,0,5,BRICK:0,50,MONSTER_EGGS:2,15,MONSTER_EGGS:3,15,MONSTER_EGGS:4,15,BRICK_STAIRS:0,10,BRICK_STAIRS:1,10,BRICK_STAIRS:2,10,BRICK_STAIRS:3,10,STEP:12,15,STEP:4,50,BRICK:0,100)
RandomBlock(4,0,6,BRICK:0,50,MONSTER_EGGS:2,15,MONSTER_EGGS:3,15,MONSTER_EGGS:4,15,BRICK_STAIRS:0,10,BRICK_STAIRS:1,10,BRICK_STAIRS:2,10,BRICK_STAIRS:3,10,STEP:12,15,STEP:4,50,BRICK:0,100)
RandomBlock(4,0,7,BRICK:0,50,MONSTER_EGGS:2,15,MONSTER_EGGS:3,15,MONSTER_EGGS:4,15,BRICK_STAIRS:0,10,BRICK_STAIRS:1,10,BRICK_STAIRS:2,10,BRICK_STAIRS:3,10,STEP:12,15,STEP:4,50,BRICK:0,100)
RandomBlock(4,0,8,BRICK:0,50,MONSTER_EGGS:2,15,MONSTER_EGGS:3,15,MONSTER_EGGS:4,15,BRICK_STAIRS:0,10,BRICK_STAIRS:1,10,BRICK_STAIRS:2,10,BRICK_STAIRS:3,10,STEP:12,15,STEP:4,50,BRICK:0,100)
RandomBlock(4,1,-7,WEB:0,14,AIR:0,100)
RandomBlock(4,1,-6,CHEST:2,../../../../Chests/Loot/junk_loot.nbt,20,CHEST:2../../../../Chests/Loot/bottle_loot.nbt,2,CHEST:2,../../../../Chests/Loot/common_loot.nbt,2,CHEST:2,../../../../Chests/Loot/village_blacksmith.nbt,2,CHEST:2,../../../../Chests/Loot/stronghold_library.nbt,2,CHEST:2,../../../../Chests/Loot/stronghold_corridor.nbt,2,CHEST:2,../../../../Chests/Loot/simple_dungeon.nbt,5,MOB_SPAWNER:0,../../ruins_spawners/alchemist_multi.nbt,10,WEB:0,10,AIR:0,100)
RandomBlock(4,1,-5,WEB:0,14,AIR:0,100)
RandomBlock(4,1,-4,WEB:0,14,AIR:0,100)
RandomBlock(4,1,-3,CHEST:2,../../../../Chests/Loot/junk_loot.nbt,20,CHEST:2../../../../Chests/Loot/bottle_loot.nbt,2,CHEST:2,../../../../Chests/Loot/common_loot.nbt,2,CHEST:2,../../../../Chests/Loot/village_blacksmith.nbt,2,CHEST:2,../../../../Chests/Loot/stronghold_library.nbt,2,CHEST:2,../../../../Chests/Loot/stronghold_corridor.nbt,2,CHEST:2,../../../../Chests/Loot/simple_dungeon.nbt,5,MOB_SPAWNER:0,../../ruins_spawners/alchemist_multi.nbt,10,WEB:0,10,AIR:0,100)
RandomBlock(4,1,-2,WEB:0,14,AIR:0,100)
RandomBlock(4,1,-1,WEB:0,14,AIR:0,100)
Block(4,1,0,AIR:0)
Block(4,1,1,AIR:0)
Block(4,1,2,AIR:0)
Block(4,1,3,AIR:0)
Block(4,1,4,STEP:0)
Block(4,1,5,AIR:0)
Block(4,1,6,AIR:0)
Block(4,1,7,AIR:0)
Block(4,1,8,AIR:0)
Block(4,2,-7,AIR:0)
Block(4,2,-6,AIR:0)
Block(4,2,-5,AIR:0)
Block(4,2,-4,AIR:0)
Block(4,2,-3,AIR:0)
Block(4,2,-2,AIR:0)
RandomBlock(4,2,-1,WEB:0,14,AIR:0,100)
Block(4,2,0,AIR:0)
Block(4,2,1,AIR:0)
Block(4,2,2,AIR:0)
Block(4,2,3,AIR:0)
Block(4,2,4,AIR:0)
Block(4,2,5,AIR:0)
Block(4,2,6,AIR:0)
Block(4,2,7,AIR:0)
Block(4,2,8,AIR:0)
Block(4,3,-7,AIR:0)
Block(4,3,-6,AIR:0)
Block(4,3,-5,AIR:0)
Block(4,3,-4,AIR:0)
Block(4,3,-3,AIR:0)
Block(4,3,-2,AIR:0)
RandomBlock(4,3,-1,WEB:0,14,AIR:0,100)
Block(4,3,0,AIR:0)
Block(4,3,1,AIR:0)
Block(4,3,2,AIR:0)
Block(4,3,3,AIR:0)
Block(4,3,4,AIR:0)
Block(4,3,5,AIR:0)
Block(4,3,6,AIR:0)
Block(4,3,7,AIR:0)
Block(4,3,8,AIR:0)
Block(4,4,-7,AIR:0)
Block(4,4,-6,AIR:0)
Block(4,4,-5,AIR:0)
Block(4,4,-4,AIR:0)
Block(4,4,-3,AIR:0)
Block(4,4,-2,AIR:0)
RandomBlock(4,4,-1,WEB:0,14,AIR:0,100)
Block(4,4,0,AIR:0)
Block(4,4,1,AIR:0)
Block(4,4,2,AIR:0)
Block(4,4,3,AIR:0)
Block(4,4,4,AIR:0)
Block(4,4,5,AIR:0)
Block(4,4,6,AIR:0)
Block(4,4,7,AIR:0)
Block(4,4,8,AIR:0)
Block(4,5,-7,AIR:0)
Block(4,5,-6,AIR:0)
Block(4,5,-5,AIR:0)
Block(4,5,-4,AIR:0)
Block(4,5,-3,AIR:0)
Block(4,5,-2,AIR:0)
Block(4,5,-1,BRICK_STAIRS:4)
Block(4,5,0,AIR:0)
Block(4,5,1,AIR:0)
Block(4,5,2,AIR:0)
Block(4,5,3,AIR:0)
Block(4,5,4,AIR:0)
Block(4,5,5,AIR:0)
Block(4,5,6,AIR:0)
Block(4,5,7,AIR:0)
Block(4,5,8,AIR:0)
Block(4,6,-7,STEP:12)
Block(4,6,-6,STEP:12)
Block(4,6,-5,STEP:12)
Block(4,6,-4,STEP:12)
Block(4,6,-3,STEP:12)
Block(4,6,-2,STEP:12)
RandomBlock(4,6,-1,BRICK:0,50,MONSTER_EGGS:2,15,MONSTER_EGGS:3,15,MONSTER_EGGS:4,15,BRICK_STAIRS:0,10,BRICK_STAIRS:1,10,BRICK_STAIRS:2,10,BRICK_STAIRS:3,10,STEP:12,15,STEP:4,50,BRICK:0,100)
Block(4,6,0,AIR:0)
Block(4,6,1,AIR:0)
Block(4,6,2,AIR:0)
Block(4,6,3,AIR:0)
Block(4,6,4,AIR:0)
Block(4,6,5,AIR:0)
Block(4,6,6,AIR:0)
Block(4,6,7,AIR:0)
Block(4,6,8,AIR:0)
RandomBlock(4,7,-7,BRICK:0,50,MONSTER_EGGS:2,15,MONSTER_EGGS:3,15,MONSTER_EGGS:4,15,BRICK_STAIRS:0,10,BRICK_STAIRS:1,10,BRICK_STAIRS:2,10,BRICK_STAIRS:3,10,STEP:12,15,STEP:4,50,BRICK:0,100)
RandomBlock(4,7,-6,BRICK:0,50,MONSTER_EGGS:2,15,MONSTER_EGGS:3,15,MONSTER_EGGS:4,15,BRICK_STAIRS:0,10,BRICK_STAIRS:1,10,BRICK_STAIRS:2,10,BRICK_STAIRS:3,10,STEP:12,15,STEP:4,50,BRICK:0,100)
RandomBlock(4,7,-5,BRICK:0,50,MONSTER_EGGS:2,15,MONSTER_EGGS:3,15,MONSTER_EGGS:4,15,BRICK_STAIRS:0,10,BRICK_STAIRS:1,10,BRICK_STAIRS:2,10,BRICK_STAIRS:3,10,STEP:12,15,STEP:4,50,BRICK:0,100)
RandomBlock(4,7,-4,BRICK:0,50,MONSTER_EGGS:2,15,MONSTER_EGGS:3,15,MONSTER_EGGS:4,15,BRICK_STAIRS:0,10,BRICK_STAIRS:1,10,BRICK_STAIRS:2,10,BRICK_STAIRS:3,10,STEP:12,15,STEP:4,50,BRICK:0,100)
RandomBlock(4,7,-3,BRICK:0,50,MONSTER_EGGS:2,15,MONSTER_EGGS:3,15,MONSTER_EGGS:4,15,BRICK_STAIRS:0,10,BRICK_STAIRS:1,10,BRICK_STAIRS:2,10,BRICK_STAIRS:3,10,STEP:12,15,STEP:4,50,BRICK:0,100)
RandomBlock(4,7,-2,BRICK:0,50,MONSTER_EGGS:2,15,MONSTER_EGGS:3,15,MONSTER_EGGS:4,15,BRICK_STAIRS:0,10,BRICK_STAIRS:1,10,BRICK_STAIRS:2,10,BRICK_STAIRS:3,10,STEP:12,15,STEP:4,50,BRICK:0,100)
RandomBlock(4,7,-1,BRICK:0,50,MONSTER_EGGS:2,15,MONSTER_EGGS:3,15,MONSTER_EGGS:4,15,BRICK_STAIRS:0,10,BRICK_STAIRS:1,10,BRICK_STAIRS:2,10,BRICK_STAIRS:3,10,STEP:12,15,STEP:4,50,BRICK:0,100)
Block(4,7,0,BRICK_STAIRS:4)
Block(4,7,1,AIR:0)
Block(4,7,2,AIR:0)
Block(4,7,3,AIR:0)
Block(4,7,4,AIR:0)
Block(4,7,5,AIR:0)
Block(4,7,6,AIR:0)
Block(4,7,7,AIR:0)
Block(4,7,8,AIR:0)
RandomBlock(4,8,-1,BRICK:0,50,MONSTER_EGGS:2,15,MONSTER_EGGS:3,15,MONSTER_EGGS:4,15,BRICK_STAIRS:0,10,BRICK_STAIRS:1,10,BRICK_STAIRS:2,10,BRICK_STAIRS:3,10,STEP:12,15,STEP:4,50,BRICK:0,100)
RandomBlock(4,8,0,BRICK:0,50,MONSTER_EGGS:2,15,MONSTER_EGGS:3,15,MONSTER_EGGS:4,15,BRICK_STAIRS:0,10,BRICK_STAIRS:1,10,BRICK_STAIRS:2,10,BRICK_STAIRS:3,10,STEP:12,15,STEP:4,50,BRICK:0,100)
Block(4,8,1,AIR:0)
Block(4,8,2,AIR:0)
Block(4,8,3,AIR:0)
Block(4,8,4,AIR:0)
Block(4,8,5,AIR:0)
Block(4,8,6,AIR:0)
Block(4,8,7,AIR:0)
Block(4,8,8,AIR:0)
RandomBlock(4,9,0,BRICK:0,50,MONSTER_EGGS:2,15,MONSTER_EGGS:3,15,MONSTER_EGGS:4,15,BRICK_STAIRS:0,10,BRICK_STAIRS:1,10,BRICK_STAIRS:2,10,BRICK_STAIRS:3,10,STEP:12,15,STEP:4,50,BRICK:0,100)
RandomBlock(4,9,1,BRICK:0,50,MONSTER_EGGS:2,15,MONSTER_EGGS:3,15,MONSTER_EGGS:4,15,BRICK_STAIRS:0,10,BRICK_STAIRS:1,10,BRICK_STAIRS:2,10,BRICK_STAIRS:3,10,STEP:12,15,STEP:4,50,BRICK:0,100)
RandomBlock(4,9,2,BRICK:0,50,MONSTER_EGGS:2,15,MONSTER_EGGS:3,15,MONSTER_EGGS:4,15,BRICK_STAIRS:0,10,BRICK_STAIRS:1,10,BRICK_STAIRS:2,10,BRICK_STAIRS:3,10,STEP:12,15,STEP:4,50,BRICK:0,100)
RandomBlock(4,9,3,BRICK:0,50,MONSTER_EGGS:2,15,MONSTER_EGGS:3,15,MONSTER_EGGS:4,15,BRICK_STAIRS:0,10,BRICK_STAIRS:1,10,BRICK_STAIRS:2,10,BRICK_STAIRS:3,10,STEP:12,15,STEP:4,50,BRICK:0,100)
RandomBlock(4,9,4,BRICK:0,50,MONSTER_EGGS:2,15,MONSTER_EGGS:3,15,MONSTER_EGGS:4,15,BRICK_STAIRS:0,10,BRICK_STAIRS:1,10,BRICK_STAIRS:2,10,BRICK_STAIRS:3,10,STEP:12,15,STEP:4,50,BRICK:0,100)
RandomBlock(4,9,5,BRICK:0,50,MONSTER_EGGS:2,15,MONSTER_EGGS:3,15,MONSTER_EGGS:4,15,BRICK_STAIRS:0,10,BRICK_STAIRS:1,10,BRICK_STAIRS:2,10,BRICK_STAIRS:3,10,STEP:12,15,STEP:4,50,BRICK:0,100)
RandomBlock(4,9,6,BRICK:0,50,MONSTER_EGGS:2,15,MONSTER_EGGS:3,15,MONSTER_EGGS:4,15,BRICK_STAIRS:0,10,BRICK_STAIRS:1,10,BRICK_STAIRS:2,10,BRICK_STAIRS:3,10,STEP:12,15,STEP:4,50,BRICK:0,100)
RandomBlock(4,9,7,BRICK:0,50,MONSTER_EGGS:2,15,MONSTER_EGGS:3,15,MONSTER_EGGS:4,15,BRICK_STAIRS:0,10,BRICK_STAIRS:1,10,BRICK_STAIRS:2,10,BRICK_STAIRS:3,10,STEP:12,15,STEP:4,50,BRICK:0,100)
RandomBlock(4,9,8,BRICK:0,50,MONSTER_EGGS:2,15,MONSTER_EGGS:3,15,MONSTER_EGGS:4,15,BRICK_STAIRS:0,10,BRICK_STAIRS:1,10,BRICK_STAIRS:2,10,BRICK_STAIRS:3,10,STEP:12,15,STEP:4,50,BRICK:0,100)
RandomBlock(5,0,-7,BRICK:0,50,MONSTER_EGGS:2,15,MONSTER_EGGS:3,15,MONSTER_EGGS:4,15,BRICK_STAIRS:0,10,BRICK_STAIRS:1,10,BRICK_STAIRS:2,10,BRICK_STAIRS:3,10,STEP:12,15,STEP:4,50,BRICK:0,100)
RandomBlock(5,0,-6,BRICK:0,50,MONSTER_EGGS:2,15,MONSTER_EGGS:3,15,MONSTER_EGGS:4,15,BRICK_STAIRS:0,10,BRICK_STAIRS:1,10,BRICK_STAIRS:2,10,BRICK_STAIRS:3,10,STEP:12,15,STEP:4,50,BRICK:0,100)
RandomBlock(5,0,-5,BRICK:0,50,MONSTER_EGGS:2,15,MONSTER_EGGS:3,15,MONSTER_EGGS:4,15,BRICK_STAIRS:0,10,BRICK_STAIRS:1,10,BRICK_STAIRS:2,10,BRICK_STAIRS:3,10,STEP:12,15,STEP:4,50,BRICK:0,100)
RandomBlock(5,0,-4,BRICK:0,50,MONSTER_EGGS:2,15,MONSTER_EGGS:3,15,MONSTER_EGGS:4,15,BRICK_STAIRS:0,10,BRICK_STAIRS:1,10,BRICK_STAIRS:2,10,BRICK_STAIRS:3,10,STEP:12,15,STEP:4,50,BRICK:0,100)
RandomBlock(5,0,-3,BRICK:0,50,MONSTER_EGGS:2,15,MONSTER_EGGS:3,15,MONSTER_EGGS:4,15,BRICK_STAIRS:0,10,BRICK_STAIRS:1,10,BRICK_STAIRS:2,10,BRICK_STAIRS:3,10,STEP:12,15,STEP:4,50,BRICK:0,100)
RandomBlock(5,0,-2,BRICK:0,50,MONSTER_EGGS:2,15,MONSTER_EGGS:3,15,MONSTER_EGGS:4,15,BRICK_STAIRS:0,10,BRICK_STAIRS:1,10,BRICK_STAIRS:2,10,BRICK_STAIRS:3,10,STEP:12,15,STEP:4,50,BRICK:0,100)
RandomBlock(5,0,-1,BRICK:0,50,MONSTER_EGGS:2,15,MONSTER_EGGS:3,15,MONSTER_EGGS:4,15,BRICK_STAIRS:0,10,BRICK_STAIRS:1,10,BRICK_STAIRS:2,10,BRICK_STAIRS:3,10,STEP:12,15,STEP:4,50,BRICK:0,100)
RandomBlock(5,0,0,BRICK:0,50,MONSTER_EGGS:2,15,MONSTER_EGGS:3,15,MONSTER_EGGS:4,15,BRICK_STAIRS:0,10,BRICK_STAIRS:1,10,BRICK_STAIRS:2,10,BRICK_STAIRS:3,10,STEP:12,15,STEP:4,50,BRICK:0,100)
RandomBlock(5,0,1,BRICK:0,50,MONSTER_EGGS:2,15,MONSTER_EGGS:3,15,MONSTER_EGGS:4,15,BRICK_STAIRS:0,10,BRICK_STAIRS:1,10,BRICK_STAIRS:2,10,BRICK_STAIRS:3,10,STEP:12,15,STEP:4,50,BRICK:0,100)
RandomBlock(5,0,2,BRICK:0,50,MONSTER_EGGS:2,15,MONSTER_EGGS:3,15,MONSTER_EGGS:4,15,BRICK_STAIRS:0,10,BRICK_STAIRS:1,10,BRICK_STAIRS:2,10,BRICK_STAIRS:3,10,STEP:12,15,STEP:4,50,BRICK:0,100)
RandomBlock(5,0,3,BRICK:0,50,MONSTER_EGGS:2,15,MONSTER_EGGS:3,15,MONSTER_EGGS:4,15,BRICK_STAIRS:0,10,BRICK_STAIRS:1,10,BRICK_STAIRS:2,10,BRICK_STAIRS:3,10,STEP:12,15,STEP:4,50,BRICK:0,100)
RandomBlock(5,0,4,BRICK:0,50,MONSTER_EGGS:2,15,MONSTER_EGGS:3,15,MONSTER_EGGS:4,15,BRICK_STAIRS:0,10,BRICK_STAIRS:1,10,BRICK_STAIRS:2,10,BRICK_STAIRS:3,10,STEP:12,15,STEP:4,50,BRICK:0,100)
RandomBlock(5,0,5,BRICK:0,50,MONSTER_EGGS:2,15,MONSTER_EGGS:3,15,MONSTER_EGGS:4,15,BRICK_STAIRS:0,10,BRICK_STAIRS:1,10,BRICK_STAIRS:2,10,BRICK_STAIRS:3,10,STEP:12,15,STEP:4,50,BRICK:0,100)
RandomBlock(5,0,6,BRICK:0,50,MONSTER_EGGS:2,15,MONSTER_EGGS:3,15,MONSTER_EGGS:4,15,BRICK_STAIRS:0,10,BRICK_STAIRS:1,10,BRICK_STAIRS:2,10,BRICK_STAIRS:3,10,STEP:12,15,STEP:4,50,BRICK:0,100)
RandomBlock(5,0,7,BRICK:0,50,MONSTER_EGGS:2,15,MONSTER_EGGS:3,15,MONSTER_EGGS:4,15,BRICK_STAIRS:0,10,BRICK_STAIRS:1,10,BRICK_STAIRS:2,10,BRICK_STAIRS:3,10,STEP:12,15,STEP:4,50,BRICK:0,100)
RandomBlock(5,0,8,BRICK:0,50,MONSTER_EGGS:2,15,MONSTER_EGGS:3,15,MONSTER_EGGS:4,15,BRICK_STAIRS:0,10,BRICK_STAIRS:1,10,BRICK_STAIRS:2,10,BRICK_STAIRS:3,10,STEP:12,15,STEP:4,50,BRICK:0,100)
RandomBlock(5,1,-7,WEB:0,14,AIR:0,100)
RandomBlock(5,1,-6,WEB:0,14,AIR:0,100)
RandomBlock(5,1,-5,WEB:0,14,AIR:0,100)
RandomBlock(5,1,-4,WEB:0,14,AIR:0,100)
RandomBlock(5,1,-3,WEB:0,14,AIR:0,100)
RandomBlock(5,1,-2,WEB:0,14,AIR:0,100)
RandomBlock(5,1,-1,WEB:0,14,AIR:0,100)
Block(5,1,0,AIR:0)
Block(5,1,1,AIR:0)
Block(5,1,2,AIR:0)
Block(5,1,3,STEP:0)
RandomBlock(5,1,4,DOUBLE_STEP:0,16,IRON_FENCE:0,16,MOB_SPAWNER:0,../../ruins_spawners/alchemist_multi.nbt,100)
Block(5,1,5,STEP:0)
Block(5,1,6,AIR:0)
RandomBlock(5,1,7,WEB:0,14,AIR:0,100)
Block(5,1,8,AIR:0)
Block(5,2,-7,AIR:0)
Block(5,2,-6,AIR:0)
Block(5,2,-5,AIR:0)
Block(5,2,-4,AIR:0)
Block(5,2,-3,AIR:0)
Block(5,2,-2,AIR:0)
RandomBlock(5,2,-1,WEB:0,14,AIR:0,100)
Block(5,2,0,AIR:0)
Block(5,2,1,AIR:0)
Block(5,2,2,AIR:0)
Block(5,2,3,AIR:0)
Block(5,2,4,IRON_FENCE:0)
Block(5,2,5,AIR:0)
Block(5,2,6,AIR:0)
RandomBlock(5,2,7,WEB:0,14,AIR:0,100)
Block(5,2,8,AIR:0)
Block(5,3,-7,AIR:0)
Block(5,3,-6,AIR:0)
Block(5,3,-5,AIR:0)
Block(5,3,-4,AIR:0)
Block(5,3,-3,AIR:0)
Block(5,3,-2,AIR:0)
RandomBlock(5,3,-1,WEB:0,14,AIR:0,100)
Block(5,3,0,AIR:0)
Block(5,3,1,AIR:0)
Block(5,3,2,AIR:0)
Block(5,3,3,AIR:0)
Block(5,3,4,GLASS:0)
Block(5,3,5,AIR:0)
Block(5,3,6,AIR:0)
Block(5,3,7,AIR:0)
Block(5,3,8,AIR:0)
Block(5,4,-7,AIR:0)
Block(5,4,-6,AIR:0)
Block(5,4,-5,AIR:0)
Block(5,4,-4,AIR:0)
Block(5,4,-3,AIR:0)
Block(5,4,-2,AIR:0)
Block(5,4,-1,STEP:12)
Block(5,4,0,AIR:0)
Block(5,4,1,AIR:0)
Block(5,4,2,AIR:0)
Block(5,4,3,AIR:0)
Block(5,4,4,AIR:0)
Block(5,4,5,AIR:0)
Block(5,4,6,AIR:0)
Block(5,4,7,AIR:0)
Block(5,4,8,AIR:0)
Block(5,5,-7,BRICK_STAIRS:4)
Block(5,5,-6,BRICK_STAIRS:4)
Block(5,5,-5,BRICK_STAIRS:4)
Block(5,5,-4,BRICK_STAIRS:4)
Block(5,5,-3,BRICK_STAIRS:4)
Block(5,5,-2,BRICK_STAIRS:4)
RandomBlock(5,5,-1,BRICK:0,50,MONSTER_EGGS:2,15,MONSTER_EGGS:3,15,MONSTER_EGGS:4,15,BRICK_STAIRS:0,10,BRICK_STAIRS:1,10,BRICK_STAIRS:2,10,BRICK_STAIRS:3,10,STEP:12,15,STEP:4,50,BRICK:0,100)
RandomBlock(5,5,0,WEB:0,14,AIR:0,100)
Block(5,5,1,AIR:0)
Block(5,5,2,AIR:0)
Block(5,5,3,AIR:0)
Block(5,5,4,AIR:0)
Block(5,5,5,AIR:0)
Block(5,5,6,AIR:0)
Block(5,5,7,AIR:0)
Block(5,5,8,AIR:0)
RandomBlock(5,6,-7,BRICK:0,50,MONSTER_EGGS:2,15,MONSTER_EGGS:3,15,MONSTER_EGGS:4,15,BRICK_STAIRS:0,10,BRICK_STAIRS:1,10,BRICK_STAIRS:2,10,BRICK_STAIRS:3,10,STEP:12,15,STEP:4,50,BRICK:0,100)
RandomBlock(5,6,-6,BRICK:0,50,MONSTER_EGGS:2,15,MONSTER_EGGS:3,15,MONSTER_EGGS:4,15,BRICK_STAIRS:0,10,BRICK_STAIRS:1,10,BRICK_STAIRS:2,10,BRICK_STAIRS:3,10,STEP:12,15,STEP:4,50,BRICK:0,100)
RandomBlock(5,6,-5,BRICK:0,50,MONSTER_EGGS:2,15,MONSTER_EGGS:3,15,MONSTER_EGGS:4,15,BRICK_STAIRS:0,10,BRICK_STAIRS:1,10,BRICK_STAIRS:2,10,BRICK_STAIRS:3,10,STEP:12,15,STEP:4,50,BRICK:0,100)
RandomBlock(5,6,-4,BRICK:0,50,MONSTER_EGGS:2,15,MONSTER_EGGS:3,15,MONSTER_EGGS:4,15,BRICK_STAIRS:0,10,BRICK_STAIRS:1,10,BRICK_STAIRS:2,10,BRICK_STAIRS:3,10,STEP:12,15,STEP:4,50,BRICK:0,100)
RandomBlock(5,6,-3,BRICK:0,50,MONSTER_EGGS:2,15,MONSTER_EGGS:3,15,MONSTER_EGGS:4,15,BRICK_STAIRS:0,10,BRICK_STAIRS:1,10,BRICK_STAIRS:2,10,BRICK_STAIRS:3,10,STEP:12,15,STEP:4,50,BRICK:0,100)
RandomBlock(5,6,-2,BRICK:0,50,MONSTER_EGGS:2,15,MONSTER_EGGS:3,15,MONSTER_EGGS:4,15,BRICK_STAIRS:0,10,BRICK_STAIRS:1,10,BRICK_STAIRS:2,10,BRICK_STAIRS:3,10,STEP:12,15,STEP:4,50,BRICK:0,100)
RandomBlock(5,6,-1,BRICK:0,50,MONSTER_EGGS:2,15,MONSTER_EGGS:3,15,MONSTER_EGGS:4,15,BRICK_STAIRS:0,10,BRICK_STAIRS:1,10,BRICK_STAIRS:2,10,BRICK_STAIRS:3,10,STEP:12,15,STEP:4,50,BRICK:0,100)
Block(5,6,0,STEP:12)
RandomBlock(5,6,1,WEB:0,14,AIR:0,100)
Block(5,6,2,AIR:0)
Block(5,6,3,AIR:0)
Block(5,6,4,AIR:0)
Block(5,6,5,AIR:0)
Block(5,6,6,AIR:0)
Block(5,6,7,AIR:0)
Block(5,6,8,AIR:0)
RandomBlock(5,7,-1,BRICK:0,50,MONSTER_EGGS:2,15,MONSTER_EGGS:3,15,MONSTER_EGGS:4,15,BRICK_STAIRS:0,10,BRICK_STAIRS:1,10,BRICK_STAIRS:2,10,BRICK_STAIRS:3,10,STEP:12,15,STEP:4,50,BRICK:0,100)
RandomBlock(5,7,0,BRICK:0,50,MONSTER_EGGS:2,15,MONSTER_EGGS:3,15,MONSTER_EGGS:4,15,BRICK_STAIRS:0,10,BRICK_STAIRS:1,10,BRICK_STAIRS:2,10,BRICK_STAIRS:3,10,STEP:12,15,STEP:4,50,BRICK:0,100)
RandomBlock(5,7,1,WEB:0,14,AIR:0,100)
Block(5,7,2,AIR:0)
Block(5,7,3,AIR:0)
Block(5,7,4,AIR:0)
Block(5,7,5,AIR:0)
Block(5,7,6,AIR:0)
Block(5,7,7,AIR:0)
Block(5,7,8,AIR:0)
RandomBlock(5,8,0,BRICK:0,50,MONSTER_EGGS:2,15,MONSTER_EGGS:3,15,MONSTER_EGGS:4,15,BRICK_STAIRS:0,10,BRICK_STAIRS:1,10,BRICK_STAIRS:2,10,BRICK_STAIRS:3,10,STEP:12,15,STEP:4,50,BRICK:0,100)
RandomBlock(5,8,1,BRICK:0,50,MONSTER_EGGS:2,15,MONSTER_EGGS:3,15,MONSTER_EGGS:4,15,BRICK_STAIRS:0,10,BRICK_STAIRS:1,10,BRICK_STAIRS:2,10,BRICK_STAIRS:3,10,STEP:12,15,STEP:4,50,BRICK:0,100)
RandomBlock(5,8,2,BRICK:0,50,MONSTER_EGGS:2,15,MONSTER_EGGS:3,15,MONSTER_EGGS:4,15,BRICK_STAIRS:0,10,BRICK_STAIRS:1,10,BRICK_STAIRS:2,10,BRICK_STAIRS:3,10,STEP:12,15,STEP:4,50,BRICK:0,100)
Block(5,8,3,AIR:0)
Block(5,8,4,AIR:0)
Block(5,8,5,AIR:0)
Block(5,8,6,AIR:0)
Block(5,8,7,AIR:0)
Block(5,8,8,AIR:0)
RandomBlock(5,9,2,BRICK:0,50,MONSTER_EGGS:2,15,MONSTER_EGGS:3,15,MONSTER_EGGS:4,15,BRICK_STAIRS:0,10,BRICK_STAIRS:1,10,BRICK_STAIRS:2,10,BRICK_STAIRS:3,10,STEP:12,15,STEP:4,50,BRICK:0,100)
RandomBlock(5,9,3,BRICK:0,50,MONSTER_EGGS:2,15,MONSTER_EGGS:3,15,MONSTER_EGGS:4,15,BRICK_STAIRS:0,10,BRICK_STAIRS:1,10,BRICK_STAIRS:2,10,BRICK_STAIRS:3,10,STEP:12,15,STEP:4,50,BRICK:0,100)
RandomBlock(5,9,4,BRICK:0,50,MONSTER_EGGS:2,15,MONSTER_EGGS:3,15,MONSTER_EGGS:4,15,BRICK_STAIRS:0,10,BRICK_STAIRS:1,10,BRICK_STAIRS:2,10,BRICK_STAIRS:3,10,STEP:12,15,STEP:4,50,BRICK:0,100)
RandomBlock(5,9,5,BRICK:0,50,MONSTER_EGGS:2,15,MONSTER_EGGS:3,15,MONSTER_EGGS:4,15,BRICK_STAIRS:0,10,BRICK_STAIRS:1,10,BRICK_STAIRS:2,10,BRICK_STAIRS:3,10,STEP:12,15,STEP:4,50,BRICK:0,100)
RandomBlock(5,9,6,BRICK:0,50,MONSTER_EGGS:2,15,MONSTER_EGGS:3,15,MONSTER_EGGS:4,15,BRICK_STAIRS:0,10,BRICK_STAIRS:1,10,BRICK_STAIRS:2,10,BRICK_STAIRS:3,10,STEP:12,15,STEP:4,50,BRICK:0,100)
RandomBlock(5,9,7,BRICK:0,50,MONSTER_EGGS:2,15,MONSTER_EGGS:3,15,MONSTER_EGGS:4,15,BRICK_STAIRS:0,10,BRICK_STAIRS:1,10,BRICK_STAIRS:2,10,BRICK_STAIRS:3,10,STEP:12,15,STEP:4,50,BRICK:0,100)
RandomBlock(5,9,8,BRICK:0,50,MONSTER_EGGS:2,15,MONSTER_EGGS:3,15,MONSTER_EGGS:4,15,BRICK_STAIRS:0,10,BRICK_STAIRS:1,10,BRICK_STAIRS:2,10,BRICK_STAIRS:3,10,STEP:12,15,STEP:4,50,BRICK:0,100)
RandomBlock(6,0,-7,BRICK:0,50,MONSTER_EGGS:2,15,MONSTER_EGGS:3,15,MONSTER_EGGS:4,15,BRICK_STAIRS:0,10,BRICK_STAIRS:1,10,BRICK_STAIRS:2,10,BRICK_STAIRS:3,10,STEP:12,15,STEP:4,50,BRICK:0,100)
RandomBlock(6,0,-6,BRICK:0,50,MONSTER_EGGS:2,15,MONSTER_EGGS:3,15,MONSTER_EGGS:4,15,BRICK_STAIRS:0,10,BRICK_STAIRS:1,10,BRICK_STAIRS:2,10,BRICK_STAIRS:3,10,STEP:12,15,STEP:4,50,BRICK:0,100)
RandomBlock(6,0,-5,BRICK:0,50,MONSTER_EGGS:2,15,MONSTER_EGGS:3,15,MONSTER_EGGS:4,15,BRICK_STAIRS:0,10,BRICK_STAIRS:1,10,BRICK_STAIRS:2,10,BRICK_STAIRS:3,10,STEP:12,15,STEP:4,50,BRICK:0,100)
RandomBlock(6,0,-4,BRICK:0,50,MONSTER_EGGS:2,15,MONSTER_EGGS:3,15,MONSTER_EGGS:4,15,BRICK_STAIRS:0,10,BRICK_STAIRS:1,10,BRICK_STAIRS:2,10,BRICK_STAIRS:3,10,STEP:12,15,STEP:4,50,BRICK:0,100)
RandomBlock(6,0,-3,BRICK:0,50,MONSTER_EGGS:2,15,MONSTER_EGGS:3,15,MONSTER_EGGS:4,15,BRICK_STAIRS:0,10,BRICK_STAIRS:1,10,BRICK_STAIRS:2,10,BRICK_STAIRS:3,10,STEP:12,15,STEP:4,50,BRICK:0,100)
RandomBlock(6,0,-2,BRICK:0,50,MONSTER_EGGS:2,15,MONSTER_EGGS:3,15,MONSTER_EGGS:4,15,BRICK_STAIRS:0,10,BRICK_STAIRS:1,10,BRICK_STAIRS:2,10,BRICK_STAIRS:3,10,STEP:12,15,STEP:4,50,BRICK:0,100)
RandomBlock(6,0,-1,BRICK:0,50,MONSTER_EGGS:2,15,MONSTER_EGGS:3,15,MONSTER_EGGS:4,15,BRICK_STAIRS:0,10,BRICK_STAIRS:1,10,BRICK_STAIRS:2,10,BRICK_STAIRS:3,10,STEP:12,15,STEP:4,50,BRICK:0,100)
RandomBlock(6,0,0,BRICK:0,50,MONSTER_EGGS:2,15,MONSTER_EGGS:3,15,MONSTER_EGGS:4,15,BRICK_STAIRS:0,10,BRICK_STAIRS:1,10,BRICK_STAIRS:2,10,BRICK_STAIRS:3,10,STEP:12,15,STEP:4,50,BRICK:0,100)
RandomBlock(6,0,1,BRICK:0,50,MONSTER_EGGS:2,15,MONSTER_EGGS:3,15,MONSTER_EGGS:4,15,BRICK_STAIRS:0,10,BRICK_STAIRS:1,10,BRICK_STAIRS:2,10,BRICK_STAIRS:3,10,STEP:12,15,STEP:4,50,BRICK:0,100)
RandomBlock(6,0,2,BRICK:0,50,MONSTER_EGGS:2,15,MONSTER_EGGS:3,15,MONSTER_EGGS:4,15,BRICK_STAIRS:0,10,BRICK_STAIRS:1,10,BRICK_STAIRS:2,10,BRICK_STAIRS:3,10,STEP:12,15,STEP:4,50,BRICK:0,100)
RandomBlock(6,0,3,BRICK:0,50,MONSTER_EGGS:2,15,MONSTER_EGGS:3,15,MONSTER_EGGS:4,15,BRICK_STAIRS:0,10,BRICK_STAIRS:1,10,BRICK_STAIRS:2,10,BRICK_STAIRS:3,10,STEP:12,15,STEP:4,50,BRICK:0,100)
RandomBlock(6,0,4,BRICK:0,50,MONSTER_EGGS:2,15,MONSTER_EGGS:3,15,MONSTER_EGGS:4,15,BRICK_STAIRS:0,10,BRICK_STAIRS:1,10,BRICK_STAIRS:2,10,BRICK_STAIRS:3,10,STEP:12,15,STEP:4,50,BRICK:0,100)
RandomBlock(6,0,5,BRICK:0,50,MONSTER_EGGS:2,15,MONSTER_EGGS:3,15,MONSTER_EGGS:4,15,BRICK_STAIRS:0,10,BRICK_STAIRS:1,10,BRICK_STAIRS:2,10,BRICK_STAIRS:3,10,STEP:12,15,STEP:4,50,BRICK:0,100)
RandomBlock(6,0,6,BRICK:0,50,MONSTER_EGGS:2,15,MONSTER_EGGS:3,15,MONSTER_EGGS:4,15,BRICK_STAIRS:0,10,BRICK_STAIRS:1,10,BRICK_STAIRS:2,10,BRICK_STAIRS:3,10,STEP:12,15,STEP:4,50,BRICK:0,100)
RandomBlock(6,0,7,BRICK:0,50,MONSTER_EGGS:2,15,MONSTER_EGGS:3,15,MONSTER_EGGS:4,15,BRICK_STAIRS:0,10,BRICK_STAIRS:1,10,BRICK_STAIRS:2,10,BRICK_STAIRS:3,10,STEP:12,15,STEP:4,50,BRICK:0,100)
RandomBlock(6,0,8,BRICK:0,50,MONSTER_EGGS:2,15,MONSTER_EGGS:3,15,MONSTER_EGGS:4,15,BRICK_STAIRS:0,10,BRICK_STAIRS:1,10,BRICK_STAIRS:2,10,BRICK_STAIRS:3,10,STEP:12,15,STEP:4,50,BRICK:0,100)
RandomBlock(6,1,-7,CHEST:2,../../../../Chests/Loot/junk_loot.nbt,20,CHEST:2../../../../Chests/Loot/bottle_loot.nbt,2,CHEST:2,../../../../Chests/Loot/common_loot.nbt,2,CHEST:2,../../../../Chests/Loot/village_blacksmith.nbt,2,CHEST:2,../../../../Chests/Loot/stronghold_library.nbt,2,CHEST:2,../../../../Chests/Loot/stronghold_corridor.nbt,2,CHEST:2,../../../../Chests/Loot/simple_dungeon.nbt,5,MOB_SPAWNER:0,../../ruins_spawners/alchemist_multi.nbt,10,WEB:0,10,AIR:0,100)
RandomBlock(6,1,-6,WEB:0,14,AIR:0,100)
RandomBlock(6,1,-5,WEB:0,14,AIR:0,100)
RandomBlock(6,1,-4,WEB:0,14,AIR:0,100)
RandomBlock(6,1,-3,WEB:0,14,AIR:0,100)
RandomBlock(6,1,-2,CHEST:2,../../../../Chests/Loot/junk_loot.nbt,20,CHEST:2../../../../Chests/Loot/bottle_loot.nbt,2,CHEST:2,../../../../Chests/Loot/common_loot.nbt,2,CHEST:2,../../../../Chests/Loot/village_blacksmith.nbt,2,CHEST:2,../../../../Chests/Loot/stronghold_library.nbt,2,CHEST:2,../../../../Chests/Loot/stronghold_corridor.nbt,2,CHEST:2,../../../../Chests/Loot/simple_dungeon.nbt,5,MOB_SPAWNER:0,../../ruins_spawners/alchemist_multi.nbt,10,WEB:0,10,AIR:0,100)
RandomBlock(6,1,-1,BRICK:0,50,MONSTER_EGGS:2,15,MONSTER_EGGS:3,15,MONSTER_EGGS:4,15,BRICK_STAIRS:0,10,BRICK_STAIRS:1,10,BRICK_STAIRS:2,10,BRICK_STAIRS:3,10,STEP:12,15,STEP:4,50,BRICK:0,100)
RandomBlock(6,1,0,WEB:0,14,AIR:0,100)
Block(6,1,1,AIR:0)
Block(6,1,2,AIR:0)
Block(6,1,3,AIR:0)
Block(6,1,4,STEP:0)
Block(6,1,5,AIR:0)
RandomBlock(6,1,6,WEB:0,14,AIR:0,100)
RandomBlock(6,1,7,WEB:0,14,AIR:0,100)
RandomBlock(6,1,8,WEB:0,14,AIR:0,100)
RandomBlock(6,2,-7,WEB:0,14,AIR:0,100)
Block(6,2,-6,AIR:0)
Block(6,2,-5,AIR:0)
Block(6,2,-4,AIR:0)
Block(6,2,-3,AIR:0)
RandomBlock(6,2,-2,WEB:0,14,AIR:0,100)
RandomBlock(6,2,-1,BRICK:0,50,MONSTER_EGGS:2,15,MONSTER_EGGS:3,15,MONSTER_EGGS:4,15,BRICK_STAIRS:0,10,BRICK_STAIRS:1,10,BRICK_STAIRS:2,10,BRICK_STAIRS:3,10,STEP:12,15,STEP:4,50,BRICK:0,100)
RandomBlock(6,2,0,WEB:0,14,AIR:0,100)
Block(6,2,1,AIR:0)
Block(6,2,2,AIR:0)
Block(6,2,3,AIR:0)
Block(6,2,4,AIR:0)
Block(6,2,5,AIR:0)
RandomBlock(6,2,6,WEB:0,14,AIR:0,100)
RandomBlock(6,2,7,WEB:0,14,AIR:0,100)
RandomBlock(6,2,8,WEB:0,14,AIR:0,100)
RandomBlock(6,3,-7,WEB:0,14,AIR:0,100)
Block(6,3,-6,AIR:0)
Block(6,3,-5,AIR:0)
Block(6,3,-4,AIR:0)
Block(6,3,-3,AIR:0)
RandomBlock(6,3,-2,WEB:0,14,AIR:0,100)
RandomBlock(6,3,-1,BRICK:0,50,MONSTER_EGGS:2,15,MONSTER_EGGS:3,15,MONSTER_EGGS:4,15,BRICK_STAIRS:0,10,BRICK_STAIRS:1,10,BRICK_STAIRS:2,10,BRICK_STAIRS:3,10,STEP:12,15,STEP:4,50,BRICK:0,100)
RandomBlock(6,3,0,WEB:0,14,AIR:0,100)
Block(6,3,1,AIR:0)
Block(6,3,2,AIR:0)
Block(6,3,3,AIR:0)
Block(6,3,4,AIR:0)
Block(6,3,5,AIR:0)
Block(6,3,6,AIR:0)
Block(6,3,7,AIR:0)
Block(6,3,8,AIR:0)
Block(6,4,-7,STEP:12)
Block(6,4,-6,STEP:12)
Block(6,4,-5,STEP:12)
Block(6,4,-4,STEP:12)
Block(6,4,-3,STEP:12)
Block(6,4,-2,STEP:12)
RandomBlock(6,4,-1,BRICK:0,50,MONSTER_EGGS:2,15,MONSTER_EGGS:3,15,MONSTER_EGGS:4,15,BRICK_STAIRS:0,10,BRICK_STAIRS:1,10,BRICK_STAIRS:2,10,BRICK_STAIRS:3,10,STEP:12,15,STEP:4,50,BRICK:0,100)
RandomBlock(6,4,0,WEB:0,14,AIR:0,100)
Block(6,4,1,AIR:0)
Block(6,4,2,AIR:0)
Block(6,4,3,AIR:0)
Block(6,4,4,AIR:0)
Block(6,4,5,AIR:0)
Block(6,4,6,AIR:0)
Block(6,4,7,AIR:0)
Block(6,4,8,AIR:0)
RandomBlock(6,5,-7,BRICK:0,50,MONSTER_EGGS:2,15,MONSTER_EGGS:3,15,MONSTER_EGGS:4,15,BRICK_STAIRS:0,10,BRICK_STAIRS:1,10,BRICK_STAIRS:2,10,BRICK_STAIRS:3,10,STEP:12,15,STEP:4,50,BRICK:0,100)
RandomBlock(6,5,-6,BRICK:0,50,MONSTER_EGGS:2,15,MONSTER_EGGS:3,15,MONSTER_EGGS:4,15,BRICK_STAIRS:0,10,BRICK_STAIRS:1,10,BRICK_STAIRS:2,10,BRICK_STAIRS:3,10,STEP:12,15,STEP:4,50,BRICK:0,100)
RandomBlock(6,5,-5,BRICK:0,50,MONSTER_EGGS:2,15,MONSTER_EGGS:3,15,MONSTER_EGGS:4,15,BRICK_STAIRS:0,10,BRICK_STAIRS:1,10,BRICK_STAIRS:2,10,BRICK_STAIRS:3,10,STEP:12,15,STEP:4,50,BRICK:0,100)
RandomBlock(6,5,-4,BRICK:0,50,MONSTER_EGGS:2,15,MONSTER_EGGS:3,15,MONSTER_EGGS:4,15,BRICK_STAIRS:0,10,BRICK_STAIRS:1,10,BRICK_STAIRS:2,10,BRICK_STAIRS:3,10,STEP:12,15,STEP:4,50,BRICK:0,100)
RandomBlock(6,5,-3,BRICK:0,50,MONSTER_EGGS:2,15,MONSTER_EGGS:3,15,MONSTER_EGGS:4,15,BRICK_STAIRS:0,10,BRICK_STAIRS:1,10,BRICK_STAIRS:2,10,BRICK_STAIRS:3,10,STEP:12,15,STEP:4,50,BRICK:0,100)
RandomBlock(6,5,-2,BRICK:0,50,MONSTER_EGGS:2,15,MONSTER_EGGS:3,15,MONSTER_EGGS:4,15,BRICK_STAIRS:0,10,BRICK_STAIRS:1,10,BRICK_STAIRS:2,10,BRICK_STAIRS:3,10,STEP:12,15,STEP:4,50,BRICK:0,100)
RandomBlock(6,5,-1,BRICK:0,50,MONSTER_EGGS:2,15,MONSTER_EGGS:3,15,MONSTER_EGGS:4,15,BRICK_STAIRS:0,10,BRICK_STAIRS:1,10,BRICK_STAIRS:2,10,BRICK_STAIRS:3,10,STEP:12,15,STEP:4,50,BRICK:0,100)
Block(6,5,0,BRICK_STAIRS:4)
RandomBlock(6,5,1,WEB:0,14,AIR:0,100)
Block(6,5,2,AIR:0)
Block(6,5,3,AIR:0)
Block(6,5,4,AIR:0)
Block(6,5,5,AIR:0)
Block(6,5,6,AIR:0)
RandomBlock(6,5,7,GLOWSTONE:0,6,AIR:0,100)
Block(6,5,8,AIR:0)
RandomBlock(6,6,-1,BRICK:0,50,MONSTER_EGGS:2,15,MONSTER_EGGS:3,15,MONSTER_EGGS:4,15,BRICK_STAIRS:0,10,BRICK_STAIRS:1,10,BRICK_STAIRS:2,10,BRICK_STAIRS:3,10,STEP:12,15,STEP:4,50,BRICK:0,100)
RandomBlock(6,6,0,BRICK:0,50,MONSTER_EGGS:2,15,MONSTER_EGGS:3,15,MONSTER_EGGS:4,15,BRICK_STAIRS:0,10,BRICK_STAIRS:1,10,BRICK_STAIRS:2,10,BRICK_STAIRS:3,10,STEP:12,15,STEP:4,50,BRICK:0,100)
RandomBlock(6,6,1,BRICK:0,50,MONSTER_EGGS:2,15,MONSTER_EGGS:3,15,MONSTER_EGGS:4,15,BRICK_STAIRS:0,10,BRICK_STAIRS:1,10,BRICK_STAIRS:2,10,BRICK_STAIRS:3,10,STEP:12,15,STEP:4,50,BRICK:0,100)
RandomBlock(6,6,2,WEB:0,14,AIR:0,100)
Block(6,6,3,AIR:0)
Block(6,6,4,AIR:0)
Block(6,6,5,AIR:0)
Block(6,6,6,AIR:0)
Block(6,6,7,IRON_FENCE:0)
Block(6,6,8,AIR:0)
RandomBlock(6,7,0,BRICK:0,50,MONSTER_EGGS:2,15,MONSTER_EGGS:3,15,MONSTER_EGGS:4,15,BRICK_STAIRS:0,10,BRICK_STAIRS:1,10,BRICK_STAIRS:2,10,BRICK_STAIRS:3,10,STEP:12,15,STEP:4,50,BRICK:0,100)
RandomBlock(6,7,1,BRICK:0,50,MONSTER_EGGS:2,15,MONSTER_EGGS:3,15,MONSTER_EGGS:4,15,BRICK_STAIRS:0,10,BRICK_STAIRS:1,10,BRICK_STAIRS:2,10,BRICK_STAIRS:3,10,STEP:12,15,STEP:4,50,BRICK:0,100)
RandomBlock(6,7,2,BRICK:0,50,MONSTER_EGGS:2,15,MONSTER_EGGS:3,15,MONSTER_EGGS:4,15,BRICK_STAIRS:0,10,BRICK_STAIRS:1,10,BRICK_STAIRS:2,10,BRICK_STAIRS:3,10,STEP:12,15,STEP:4,50,BRICK:0,100)
RandomBlock(6,7,3,WEB:0,14,AIR:0,100)
Block(6,7,4,AIR:0)
Block(6,7,5,AIR:0)
Block(6,7,6,AIR:0)
Block(6,7,7,IRON_FENCE:0)
Block(6,7,8,AIR:0)
RandomBlock(6,8,2,BRICK:0,50,MONSTER_EGGS:2,15,MONSTER_EGGS:3,15,MONSTER_EGGS:4,15,BRICK_STAIRS:0,10,BRICK_STAIRS:1,10,BRICK_STAIRS:2,10,BRICK_STAIRS:3,10,STEP:12,15,STEP:4,50,BRICK:0,100)
RandomBlock(6,8,3,BRICK:0,50,MONSTER_EGGS:2,15,MONSTER_EGGS:3,15,MONSTER_EGGS:4,15,BRICK_STAIRS:0,10,BRICK_STAIRS:1,10,BRICK_STAIRS:2,10,BRICK_STAIRS:3,10,STEP:12,15,STEP:4,50,BRICK:0,100)
RandomBlock(6,8,4,BRICK:0,50,MONSTER_EGGS:2,15,MONSTER_EGGS:3,15,MONSTER_EGGS:4,15,BRICK_STAIRS:0,10,BRICK_STAIRS:1,10,BRICK_STAIRS:2,10,BRICK_STAIRS:3,10,STEP:12,15,STEP:4,50,BRICK:0,100)
RandomBlock(6,8,5,BRICK:0,50,MONSTER_EGGS:2,15,MONSTER_EGGS:3,15,MONSTER_EGGS:4,15,BRICK_STAIRS:0,10,BRICK_STAIRS:1,10,BRICK_STAIRS:2,10,BRICK_STAIRS:3,10,STEP:12,15,STEP:4,50,BRICK:0,100)
RandomBlock(6,8,6,BRICK:0,50,MONSTER_EGGS:2,15,MONSTER_EGGS:3,15,MONSTER_EGGS:4,15,BRICK_STAIRS:0,10,BRICK_STAIRS:1,10,BRICK_STAIRS:2,10,BRICK_STAIRS:3,10,STEP:12,15,STEP:4,50,BRICK:0,100)
RandomBlock(6,8,7,BRICK:0,50,MONSTER_EGGS:2,15,MONSTER_EGGS:3,15,MONSTER_EGGS:4,15,BRICK_STAIRS:0,10,BRICK_STAIRS:1,10,BRICK_STAIRS:2,10,BRICK_STAIRS:3,10,STEP:12,15,STEP:4,50,BRICK:0,100)
RandomBlock(6,8,8,BRICK:0,50,MONSTER_EGGS:2,15,MONSTER_EGGS:3,15,MONSTER_EGGS:4,15,BRICK_STAIRS:0,10,BRICK_STAIRS:1,10,BRICK_STAIRS:2,10,BRICK_STAIRS:3,10,STEP:12,15,STEP:4,50,BRICK:0,100)
RandomBlock(7,0,-7,BRICK:0,50,MONSTER_EGGS:2,15,MONSTER_EGGS:3,15,MONSTER_EGGS:4,15,BRICK_STAIRS:0,10,BRICK_STAIRS:1,10,BRICK_STAIRS:2,10,BRICK_STAIRS:3,10,STEP:12,15,STEP:4,50,BRICK:0,100)
RandomBlock(7,0,-6,BRICK:0,50,MONSTER_EGGS:2,15,MONSTER_EGGS:3,15,MONSTER_EGGS:4,15,BRICK_STAIRS:0,10,BRICK_STAIRS:1,10,BRICK_STAIRS:2,10,BRICK_STAIRS:3,10,STEP:12,15,STEP:4,50,BRICK:0,100)
RandomBlock(7,0,-5,BRICK:0,50,MONSTER_EGGS:2,15,MONSTER_EGGS:3,15,MONSTER_EGGS:4,15,BRICK_STAIRS:0,10,BRICK_STAIRS:1,10,BRICK_STAIRS:2,10,BRICK_STAIRS:3,10,STEP:12,15,STEP:4,50,BRICK:0,100)
RandomBlock(7,0,-4,BRICK:0,50,MONSTER_EGGS:2,15,MONSTER_EGGS:3,15,MONSTER_EGGS:4,15,BRICK_STAIRS:0,10,BRICK_STAIRS:1,10,BRICK_STAIRS:2,10,BRICK_STAIRS:3,10,STEP:12,15,STEP:4,50,BRICK:0,100)
RandomBlock(7,0,-3,BRICK:0,50,MONSTER_EGGS:2,15,MONSTER_EGGS:3,15,MONSTER_EGGS:4,15,BRICK_STAIRS:0,10,BRICK_STAIRS:1,10,BRICK_STAIRS:2,10,BRICK_STAIRS:3,10,STEP:12,15,STEP:4,50,BRICK:0,100)
RandomBlock(7,0,-2,BRICK:0,50,MONSTER_EGGS:2,15,MONSTER_EGGS:3,15,MONSTER_EGGS:4,15,BRICK_STAIRS:0,10,BRICK_STAIRS:1,10,BRICK_STAIRS:2,10,BRICK_STAIRS:3,10,STEP:12,15,STEP:4,50,BRICK:0,100)
RandomBlock(7,0,-1,BRICK:0,50,MONSTER_EGGS:2,15,MONSTER_EGGS:3,15,MONSTER_EGGS:4,15,BRICK_STAIRS:0,10,BRICK_STAIRS:1,10,BRICK_STAIRS:2,10,BRICK_STAIRS:3,10,STEP:12,15,STEP:4,50,BRICK:0,100)
RandomBlock(7,0,0,BRICK:0,50,MONSTER_EGGS:2,15,MONSTER_EGGS:3,15,MONSTER_EGGS:4,15,BRICK_STAIRS:0,10,BRICK_STAIRS:1,10,BRICK_STAIRS:2,10,BRICK_STAIRS:3,10,STEP:12,15,STEP:4,50,BRICK:0,100)
RandomBlock(7,0,1,BRICK:0,50,MONSTER_EGGS:2,15,MONSTER_EGGS:3,15,MONSTER_EGGS:4,15,BRICK_STAIRS:0,10,BRICK_STAIRS:1,10,BRICK_STAIRS:2,10,BRICK_STAIRS:3,10,STEP:12,15,STEP:4,50,BRICK:0,100)
RandomBlock(7,0,2,BRICK:0,50,MONSTER_EGGS:2,15,MONSTER_EGGS:3,15,MONSTER_EGGS:4,15,BRICK_STAIRS:0,10,BRICK_STAIRS:1,10,BRICK_STAIRS:2,10,BRICK_STAIRS:3,10,STEP:12,15,STEP:4,50,BRICK:0,100)
RandomBlock(7,0,3,BRICK:0,50,MONSTER_EGGS:2,15,MONSTER_EGGS:3,15,MONSTER_EGGS:4,15,BRICK_STAIRS:0,10,BRICK_STAIRS:1,10,BRICK_STAIRS:2,10,BRICK_STAIRS:3,10,STEP:12,15,STEP:4,50,BRICK:0,100)
RandomBlock(7,0,4,BRICK:0,50,MONSTER_EGGS:2,15,MONSTER_EGGS:3,15,MONSTER_EGGS:4,15,BRICK_STAIRS:0,10,BRICK_STAIRS:1,10,BRICK_STAIRS:2,10,BRICK_STAIRS:3,10,STEP:12,15,STEP:4,50,BRICK:0,100)
RandomBlock(7,0,5,BRICK:0,50,MONSTER_EGGS:2,15,MONSTER_EGGS:3,15,MONSTER_EGGS:4,15,BRICK_STAIRS:0,10,BRICK_STAIRS:1,10,BRICK_STAIRS:2,10,BRICK_STAIRS:3,10,STEP:12,15,STEP:4,50,BRICK:0,100)
