
#######################################################################
# +-----------------------------------------------------------------+ #
# |                            BO4 object                           | #
# +-----------------------------------------------------------------+ #
#######################################################################

Author: NLBlackEagle

Description: No description given

SettingsMode: WriteWithoutComments


#######################################################################
# +-----------------------------------------------------------------+ #
# |                          Main settings                          | #
# +-----------------------------------------------------------------+ #
#######################################################################

FixedRotation: 

Frequency: 0

SpawnHeight: highestBlock

UseCenterForHighestBlock: true

##############################
# Height Limits for the BO4. #
##############################

MinHeight: 0

MaxHeight: 255

InheritBO3: 

InheritBO3Rotation: NORTH

OverrideChildSettings: true

OverrideParentHeight: false

CanOverride: true

BranchFrequency: 0

BranchFrequencyGroup: 

MustBeBelowOther: false

MustBeInside: 

CannotBeInside: 

ReplacesBO3: 

MustBeInsideWorldBorders: false

CanSpawnOnWater: true

SpawnOnWaterOnly: false

SpawnUnderWater: false

SpawnAtWaterLevel: false

HeightOffset: 0

RemoveAir: false

ReplaceAbove: 

ReplaceBelow: 

ReplaceWithBiomeBlocks: false

ReplaceWithSurfaceBlock: GRASS

ReplaceWithGroundBlock: DIRT

ReplaceWithStoneBlock: STONE

SmoothRadius: 0

SmoothHeightOffset: 0

SmoothStartTop: false

SmoothStartWood: false

SmoothingSurfaceBlock: 

SmoothingGroundBlock: 

BO3Group: 

IsSpawnPoint: false

DoReplaceBlocks: true


#######################################################################
# +-----------------------------------------------------------------+ #
# |                              Blocks                             | #
# +-----------------------------------------------------------------+ #
#######################################################################

RandomBlock(-8,0,-4,quark:iron_plate:1,40,lycanitesmobs:ashenstone,100)
RandomBlock(-8,1,-6,quark:iron_plate:1,40,lycanitesmobs:ashenstone,100)
RandomBlock(-8,1,-5,quark:iron_plate:1,40,lycanitesmobs:ashenstone,100)
RandomBlock(-8,1,-4,quark:iron_plate:1,40,lycanitesmobs:ashenstone,100)
RandomBlock(-8,1,-3,quark:iron_plate:1,40,lycanitesmobs:ashenstone,100)
RandomBlock(-8,1,-2,quark:iron_plate:1,40,lycanitesmobs:ashenstone,100)
RandomBlock(-8,2,-7,quark:iron_plate:1,40,lycanitesmobs:ashenstone,100)
RandomBlock(-8,2,-6,quark:iron_plate:1,40,lycanitesmobs:ashenstone,100)
Block(-8,2,-5,OBSIDIAN:0)
Block(-8,2,-4,OBSERVER:5)
Block(-8,2,-3,OBSIDIAN:0)
RandomBlock(-8,2,-2,quark:iron_plate:1,40,lycanitesmobs:ashenstone,100)
RandomBlock(-8,2,-1,quark:iron_plate:1,40,lycanitesmobs:ashenstone,100)
RandomBlock(-8,3,-7,quark:iron_plate:1,40,lycanitesmobs:ashenstone,100)
RandomBlock(-8,3,-6,quark:iron_plate:1,40,lycanitesmobs:ashenstone,100)
Block(-8,3,-5,REDSTONE_BLOCK:0)
Block(-8,3,-4,OBSERVER:5)
Block(-8,3,-3,REDSTONE_BLOCK:0)
RandomBlock(-8,3,-2,quark:iron_plate:1,40,lycanitesmobs:ashenstone,100)
RandomBlock(-8,3,-1,quark:iron_plate:1,40,lycanitesmobs:ashenstone,100)
RandomBlock(-8,4,-6,quark:iron_plate:1,40,lycanitesmobs:ashenstone,100)
Block(-8,4,-5,OBSIDIAN:0)
Block(-8,4,-4,OBSERVER:1)
Block(-8,4,-3,OBSIDIAN:0)
RandomBlock(-8,4,-2,quark:iron_plate:1,40,lycanitesmobs:ashenstone,100)
RandomBlock(-8,5,-6,quark:iron_plate:1,40,lycanitesmobs:ashenstone,100)
RandomBlock(-8,5,-5,quark:iron_plate:1,40,lycanitesmobs:ashenstone,100)
RandomBlock(-8,5,-4,quark:iron_plate:1,40,lycanitesmobs:ashenstone,100)
RandomBlock(-8,5,-3,quark:iron_plate:1,40,lycanitesmobs:ashenstone,100)
RandomBlock(-8,5,-2,quark:iron_plate:1,40,lycanitesmobs:ashenstone,100)
RandomBlock(-8,6,-4,quark:iron_plate:1,40,lycanitesmobs:ashenstone,100)
RandomBlock(-7,0,-4,quark:iron_plate:1,40,lycanitesmobs:ashenstone,100)
RandomBlock(-7,1,-5,quark:iron_plate:1,40,lycanitesmobs:ashenstone,100)
RandomBlock(-7,1,-4,quark:iron_plate:1,40,lycanitesmobs:ashenstone,100)
RandomBlock(-7,1,-3,quark:iron_plate:1,40,lycanitesmobs:ashenstone,100)
RandomBlock(-7,2,-6,quark:iron_plate:1,40,lycanitesmobs:ashenstone,100)
RandomBlock(-7,2,-5,quark:iron_plate:1,40,lycanitesmobs:ashenstone,100)
Block(-7,2,-4,OBSIDIAN:0)
RandomBlock(-7,2,-3,quark:iron_plate:1,40,lycanitesmobs:ashenstone,100)
RandomBlock(-7,2,-2,quark:iron_plate:1,40,lycanitesmobs:ashenstone,100)
RandomBlock(-7,3,-7,quark:iron_plate:1,40,lycanitesmobs:ashenstone,100)
RandomBlock(-7,3,-6,quark:iron_plate:1,40,lycanitesmobs:ashenstone,100)
Block(-7,3,-4,OBSIDIAN:0)
RandomBlock(-7,3,-2,quark:iron_plate:1,40,lycanitesmobs:ashenstone,100)
RandomBlock(-7,3,-1,quark:iron_plate:1,40,lycanitesmobs:ashenstone,100)
RandomBlock(-7,4,-6,quark:iron_plate:1,40,lycanitesmobs:ashenstone,100)
RandomBlock(-7,4,-5,quark:iron_plate:1,40,lycanitesmobs:ashenstone,100)
RandomBlock(-7,4,-4,quark:iron_plate:1,40,lycanitesmobs:ashenstone,100)
RandomBlock(-7,4,-3,quark:iron_plate:1,40,lycanitesmobs:ashenstone,100)
RandomBlock(-7,4,-2,quark:iron_plate:1,40,lycanitesmobs:ashenstone,100)
RandomBlock(-7,5,-5,quark:iron_plate:1,40,lycanitesmobs:ashenstone,100)
RandomBlock(-7,5,-4,quark:iron_plate:1,40,lycanitesmobs:ashenstone,100)
RandomBlock(-7,5,-3,quark:iron_plate:1,40,lycanitesmobs:ashenstone,100)
RandomBlock(-7,6,-4,quark:iron_plate:1,40,lycanitesmobs:ashenstone,100)
RandomBlock(-6,0,-4,quark:iron_plate:1,40,lycanitesmobs:ashenstone,100)
RandomBlock(-6,1,-5,quark:iron_plate:1,40,lycanitesmobs:ashenstone,100)
RandomBlock(-6,1,-4,quark:iron_plate:1,40,lycanitesmobs:ashenstone,100)
RandomBlock(-6,1,-3,quark:iron_plate:1,40,lycanitesmobs:ashenstone,100)
RandomBlock(-6,2,-6,quark:iron_plate:1,40,lycanitesmobs:ashenstone,100)
RandomBlock(-6,2,-5,quark:iron_plate:1,40,lycanitesmobs:ashenstone,100)
RandomBlock(-6,2,-4,quark:iron_plate:1,40,lycanitesmobs:ashenstone,100)
RandomBlock(-6,2,-3,quark:iron_plate:1,40,lycanitesmobs:ashenstone,100)
RandomBlock(-6,2,-2,quark:iron_plate:1,40,lycanitesmobs:ashenstone,100)
RandomBlock(-6,3,-7,quark:iron_plate:1,40,lycanitesmobs:ashenstone,100)
RandomBlock(-6,3,-6,quark:iron_plate:1,40,lycanitesmobs:ashenstone,100)
RandomBlock(-6,3,-4,quark:iron_plate:1,40,lycanitesmobs:ashenstone,100)
RandomBlock(-6,3,-2,quark:iron_plate:1,40,lycanitesmobs:ashenstone,100)
RandomBlock(-6,3,-1,quark:iron_plate:1,40,lycanitesmobs:ashenstone,100)
RandomBlock(-6,4,-6,quark:iron_plate:1,40,lycanitesmobs:ashenstone,100)
RandomBlock(-6,4,-5,quark:iron_plate:1,40,lycanitesmobs:ashenstone,100)
RandomBlock(-6,4,-4,quark:iron_plate:1,40,lycanitesmobs:ashenstone,100)
RandomBlock(-6,4,-3,quark:iron_plate:1,40,lycanitesmobs:ashenstone,100)
RandomBlock(-6,4,-2,quark:iron_plate:1,40,lycanitesmobs:ashenstone,100)
RandomBlock(-6,5,-5,quark:iron_plate:1,40,lycanitesmobs:ashenstone,100)
RandomBlock(-6,5,-4,quark:iron_plate:1,40,lycanitesmobs:ashenstone,100)
RandomBlock(-6,5,-3,quark:iron_plate:1,40,lycanitesmobs:ashenstone,100)
RandomBlock(-6,6,-4,quark:iron_plate:1,40,lycanitesmobs:ashenstone,100)
RandomBlock(-5,1,-5,quark:iron_plate:1,40,lycanitesmobs:ashenstone,100)
RandomBlock(-5,1,-4,quark:iron_plate:1,40,lycanitesmobs:ashenstone,100)
RandomBlock(-5,1,-3,quark:iron_plate:1,40,lycanitesmobs:ashenstone,100)
RandomBlock(-5,2,-6,quark:iron_plate:1,40,lycanitesmobs:ashenstone,100)
RandomBlock(-5,2,-5,quark:iron_plate:1,40,lycanitesmobs:ashenstone,100)
RandomBlock(-5,2,-4,quark:iron_plate:1,40,lycanitesmobs:ashenstone,100)
RandomBlock(-5,2,-3,quark:iron_plate:1,40,lycanitesmobs:ashenstone,100)
RandomBlock(-5,2,-2,quark:iron_plate:1,40,lycanitesmobs:ashenstone,100)
RandomBlock(-5,3,-6,quark:iron_plate:1,40,lycanitesmobs:ashenstone,100)
RandomBlock(-5,3,-4,quark:iron_plate:1,40,lycanitesmobs:ashenstone,100)
RandomBlock(-5,3,-2,quark:iron_plate:1,40,lycanitesmobs:ashenstone,100)
RandomBlock(-5,4,-5,quark:iron_plate:1,40,lycanitesmobs:ashenstone,100)
RandomBlock(-5,4,-4,quark:iron_plate:1,40,lycanitesmobs:ashenstone,100)
RandomBlock(-5,4,-3,quark:iron_plate:1,40,lycanitesmobs:ashenstone,100)
RandomBlock(-5,5,-5,quark:iron_plate:1,40,lycanitesmobs:ashenstone,100)
RandomBlock(-5,5,-4,quark:iron_plate:1,40,lycanitesmobs:ashenstone,100)
RandomBlock(-5,5,-3,quark:iron_plate:1,40,lycanitesmobs:ashenstone,100)
RandomBlock(-4,1,-4,quark:iron_plate:1,40,lycanitesmobs:ashenstone,100)
RandomBlock(-4,2,-5,quark:iron_plate:1,40,lycanitesmobs:ashenstone,100)
RandomBlock(-4,2,-4,quark:iron_plate:1,40,lycanitesmobs:ashenstone,100)
RandomBlock(-4,2,-3,quark:iron_plate:1,40,lycanitesmobs:ashenstone,100)
RandomBlock(-4,3,-6,quark:iron_plate:1,40,lycanitesmobs:ashenstone,100)
Block(-4,3,-5,IRON_TRAPDOOR:6)
RandomBlock(-4,3,-4,quark:iron_plate:1,40,lycanitesmobs:ashenstone,100)
Block(-4,3,-3,IRON_TRAPDOOR:6)
RandomBlock(-4,3,-2,quark:iron_plate:1,40,lycanitesmobs:ashenstone,100)
RandomBlock(-4,4,-5,quark:iron_plate:1,40,lycanitesmobs:ashenstone,100)
RandomBlock(-4,4,-4,quark:iron_plate:1,40,lycanitesmobs:ashenstone,100)
RandomBlock(-4,4,-3,quark:iron_plate:1,40,lycanitesmobs:ashenstone,100)
RandomBlock(-4,5,-4,quark:iron_plate:1,40,lycanitesmobs:ashenstone,100)
RandomBlock(-3,2,-4,quark:iron_plate:1,40,lycanitesmobs:ashenstone,100)
RandomBlock(-3,3,-4,quark:iron_plate:1,40,lycanitesmobs:ashenstone,100)
RandomBlock(-3,4,-4,quark:iron_plate:1,40,lycanitesmobs:ashenstone,100)

#######################################################################
# +-----------------------------------------------------------------+ #
# |                             Branches                            | #
# +-----------------------------------------------------------------+ #
#######################################################################

Branch(0,0,16,true,LostSubmarineC3R3,NORTH,100.0,0)

#######################################################################
# +-----------------------------------------------------------------+ #
# |                             Entities                            | #
# +-----------------------------------------------------------------+ #
#######################################################################


#######################################################################
# +-----------------------------------------------------------------+ #
# |                            Particles                            | #
# +-----------------------------------------------------------------+ #
#######################################################################


#######################################################################
# +-----------------------------------------------------------------+ #
# |                             Spawners                            | #
# +-----------------------------------------------------------------+ #
#######################################################################


#######################################################################
# +-----------------------------------------------------------------+ #
# |                             ModData                             | #
# +-----------------------------------------------------------------+ #
#######################################################################

