
#######################################################################
# +-----------------------------------------------------------------+ #
# |                            BO4 object                           | #
# +-----------------------------------------------------------------+ #
#######################################################################

Author: NLBlackEagle

Description: No description given

SettingsMode: WriteWithoutComments


#######################################################################
# +-----------------------------------------------------------------+ #
# |                          Main settings                          | #
# +-----------------------------------------------------------------+ #
#######################################################################

FixedRotation: 

Frequency: 0

SpawnHeight: highestBlock

UseCenterForHighestBlock: true

##############################
# Height Limits for the BO4. #
##############################

MinHeight: 0

MaxHeight: 255

InheritBO3: 

InheritBO3Rotation: NORTH

OverrideChildSettings: true

OverrideParentHeight: false

CanOverride: true

BranchFrequency: 0

BranchFrequencyGroup: 

MustBeBelowOther: false

MustBeInside: 

CannotBeInside: 

ReplacesBO3: 

MustBeInsideWorldBorders: false

CanSpawnOnWater: true

SpawnOnWaterOnly: false

SpawnUnderWater: false

SpawnAtWaterLevel: false

HeightOffset: 0

RemoveAir: false

ReplaceAbove: 

ReplaceBelow: 

ReplaceWithBiomeBlocks: false

ReplaceWithSurfaceBlock: GRASS

ReplaceWithGroundBlock: DIRT

ReplaceWithStoneBlock: STONE

SmoothRadius: 0

SmoothHeightOffset: 0

SmoothStartTop: false

SmoothStartWood: false

SmoothingSurfaceBlock: 

SmoothingGroundBlock: 

BO3Group: 

IsSpawnPoint: false

DoReplaceBlocks: true


#######################################################################
# +-----------------------------------------------------------------+ #
# |                              Blocks                             | #
# +-----------------------------------------------------------------+ #
#######################################################################

Block(-8,0,-7,dimstack:bedrock:7)
Block(-8,0,-6,dimstack:bedrock:7)
Block(-8,0,-5,dimstack:bedrock:7)
Block(-8,0,-4,dimstack:bedrock:7)
Block(-8,0,-3,dimstack:bedrock:7)
Block(-8,0,-2,dimstack:bedrock:7)
Block(-8,0,-1,dimstack:bedrock:7)
Block(-8,0,0,dimstack:bedrock:7)
Block(-8,0,1,dimstack:bedrock:7)
Block(-8,0,2,dimstack:bedrock:7)
Block(-8,0,3,dimstack:bedrock:7)
Block(-8,0,4,dimstack:bedrock:7)
Block(-8,0,5,dimstack:bedrock:7)
Block(-8,0,6,dimstack:bedrock:7)
Block(-8,0,7,dimstack:bedrock:7)
Block(-8,0,8,dimstack:bedrock:7)
Block(-8,1,-7,dimstack:bedrock:7)
Block(-8,1,-6,MOSSY_COBBLESTONE:0)
Block(-8,1,-5,COBBLESTONE:0)
Block(-8,1,-4,MOSSY_COBBLESTONE:0)
Block(-8,1,-3,MOSSY_COBBLESTONE:0)
Block(-8,1,-2,MOSSY_COBBLESTONE:0)
Block(-8,1,-1,MOSSY_COBBLESTONE:0)
Block(-8,1,0,MOSSY_COBBLESTONE:0)
Block(-8,1,1,AIR:0)
Block(-8,1,2,AIR:0)
Block(-8,1,3,COBBLESTONE:0)
Block(-8,1,4,MOSSY_COBBLESTONE:0)
Block(-8,1,5,COBBLESTONE:0)
Block(-8,1,6,MOSSY_COBBLESTONE:0)
Block(-8,1,7,MOSSY_COBBLESTONE:0)
Block(-8,1,8,MOSSY_COBBLESTONE:0)
Block(-8,2,-7,dimstack:bedrock:7)
Block(-8,2,-6,COBBLESTONE:0)
Block(-8,2,-5,AIR:0)
Block(-8,2,-4,AIR:0)
Block(-8,2,-3,AIR:0)
Block(-8,2,-2,MOB_SPAWNER:0,../../ruins_spawners/crypt_multi.nbt)
Block(-8,2,-1,AIR:0)
Block(-8,2,0,AIR:0)
Block(-8,2,1,MOSSY_COBBLESTONE:0)
Block(-8,2,2,MOSSY_COBBLESTONE:0)
Block(-8,2,3,AIR:0)
Block(-8,2,4,AIR:0)
Block(-8,2,5,AIR:0)
Block(-8,2,6,AIR:0)
Block(-8,2,7,AIR:0)
Block(-8,2,8,AIR:0)
Block(-8,3,-7,dimstack:bedrock:7)
Block(-8,3,-6,MOSSY_COBBLESTONE:0)
Block(-8,3,-5,AIR:0)
Block(-8,3,-4,AIR:0)
Block(-8,3,-3,AIR:0)
Block(-8,3,-2,AIR:0)
Block(-8,3,-1,AIR:0)
Block(-8,3,0,AIR:0)
Block(-8,3,1,MOSSY_COBBLESTONE:0)
Block(-8,3,2,MOSSY_COBBLESTONE:0)
Block(-8,3,3,AIR:0)
Block(-8,3,4,AIR:0)
Block(-8,3,5,AIR:0)
Block(-8,3,6,AIR:0)
Block(-8,3,7,AIR:0)
Block(-8,3,8,AIR:0)
Block(-8,4,-7,dimstack:bedrock:7)
Block(-8,4,-6,COBBLESTONE:0)
Block(-8,4,-5,MOSSY_COBBLESTONE:0)
Block(-8,4,-4,MOSSY_COBBLESTONE:0)
Block(-8,4,-3,MOSSY_COBBLESTONE:0)
Block(-8,4,-2,MOSSY_COBBLESTONE:0)
Block(-8,4,-1,COBBLESTONE:0)
Block(-8,4,0,MOSSY_COBBLESTONE:0)
Block(-8,4,1,MOSSY_COBBLESTONE:0)
Block(-8,4,2,MOSSY_COBBLESTONE:0)
Block(-8,4,3,MOSSY_COBBLESTONE:0)
Block(-8,4,4,COBBLESTONE:0)
Block(-8,4,5,MOSSY_COBBLESTONE:0)
Block(-8,4,6,MOSSY_COBBLESTONE:0)
Block(-8,4,7,MOSSY_COBBLESTONE:0)
Block(-8,4,8,MOSSY_COBBLESTONE:0)
Block(-8,5,-7,dimstack:bedrock:7)
Block(-8,5,-6,dimstack:bedrock:7)
Block(-8,5,-5,dimstack:bedrock:7)
Block(-8,5,-4,dimstack:bedrock:7)
Block(-8,5,-3,dimstack:bedrock:7)
Block(-8,5,-2,dimstack:bedrock:7)
Block(-8,5,-1,dimstack:bedrock:7)
Block(-8,5,0,dimstack:bedrock:7)
Block(-8,5,1,dimstack:bedrock:7)
Block(-8,5,2,dimstack:bedrock:7)
Block(-8,5,3,dimstack:bedrock:7)
Block(-8,5,4,dimstack:bedrock:7)
Block(-8,5,5,dimstack:bedrock:7)
Block(-8,5,6,dimstack:bedrock:7)
Block(-8,5,7,dimstack:bedrock:7)
Block(-8,5,8,dimstack:bedrock:7)
Block(-8,14,2,MOSSY_COBBLESTONE:0)
Block(-8,14,3,NETHERRACK:0)
Block(-8,14,4,NETHERRACK:0)
Block(-8,14,5,NETHERRACK:0)
Block(-8,14,6,MOSSY_COBBLESTONE:0)
Block(-8,15,1,MOSSY_COBBLESTONE:0)
Block(-8,15,2,NETHERRACK:0)
Block(-8,15,3,AIR:0)
Block(-8,15,4,AIR:0)
Block(-8,15,5,AIR:0)
Block(-8,15,6,NETHERRACK:0)
Block(-8,15,7,MOSSY_COBBLESTONE:0)
Block(-8,16,1,MOSSY_COBBLESTONE:0)
Block(-8,16,2,NETHERRACK:0)
Block(-8,16,3,AIR:0)
Block(-8,16,4,AIR:0)
Block(-8,16,5,AIR:0)
Block(-8,16,6,NETHERRACK:0)
Block(-8,16,7,MOSSY_COBBLESTONE:0)
Block(-8,17,1,MOSSY_COBBLESTONE:0)
Block(-8,17,2,NETHERRACK:0)
Block(-8,17,3,AIR:0)
Block(-8,17,4,AIR:0)
Block(-8,17,5,AIR:0)
Block(-8,17,6,NETHERRACK:0)
Block(-8,17,7,MOSSY_COBBLESTONE:0)
Block(-8,18,-5,MOSSY_COBBLESTONE:0)
Block(-8,18,1,MOSSY_COBBLESTONE:0)
Block(-8,18,2,NETHERRACK:0)
Block(-8,18,3,AIR:0)
Block(-8,18,4,AIR:0)
Block(-8,18,5,AIR:0)
Block(-8,18,6,NETHERRACK:0)
Block(-8,18,7,COBBLESTONE:0)
Block(-8,19,-4,MOSSY_COBBLESTONE:0)
Block(-8,19,-3,MOSSY_COBBLESTONE:0)
Block(-8,19,-2,COBBLESTONE:0)
Block(-8,19,1,MOSSY_COBBLESTONE:0)
Block(-8,19,2,NETHERRACK:0)
Block(-8,19,3,AIR:0)
Block(-8,19,4,AIR:0)
Block(-8,19,5,AIR:0)
Block(-8,19,6,NETHERRACK:0)
Block(-8,19,7,MOSSY_COBBLESTONE:0)
Block(-8,20,1,MOSSY_COBBLESTONE:0)
Block(-8,20,2,NETHERRACK:0)
Block(-8,20,3,AIR:0)
Block(-8,20,4,AIR:0)
Block(-8,20,5,AIR:0)
Block(-8,20,6,NETHERRACK:0)
Block(-8,20,7,MOSSY_COBBLESTONE:0)
Block(-8,21,2,MOSSY_COBBLESTONE:0)
Block(-8,21,3,NETHERRACK:0)
Block(-8,21,4,NETHERRACK:0)
Block(-8,21,5,NETHERRACK:0)
Block(-8,21,6,COBBLESTONE:0)
Block(-8,22,2,MOSSY_COBBLESTONE:0)
Block(-8,22,3,MOSSY_COBBLESTONE:0)
Block(-8,22,4,MOSSY_COBBLESTONE:0)
Block(-8,22,5,MOSSY_COBBLESTONE:0)
Block(-8,22,6,MOSSY_COBBLESTONE:0)
Block(-8,23,1,MOSSY_COBBLESTONE:0)
Block(-8,23,2,MOSSY_COBBLESTONE:0)
Block(-8,23,3,COBBLESTONE:0)
Block(-8,23,4,MOSSY_COBBLESTONE:0)
Block(-8,23,5,COBBLESTONE:0)
Block(-8,23,6,MOSSY_COBBLESTONE:0)
Block(-8,23,7,MOSSY_COBBLESTONE:0)
Block(-8,24,1,MOSSY_COBBLESTONE:0)
Block(-8,24,2,COBBLESTONE:0)
Block(-8,24,3,MOSSY_COBBLESTONE:0)
Block(-8,24,4,MOSSY_COBBLESTONE:0)
Block(-8,24,5,MOSSY_COBBLESTONE:0)
Block(-8,24,6,MOSSY_COBBLESTONE:0)
Block(-8,24,7,MOSSY_COBBLESTONE:0)
Block(-8,25,-1,MOSSY_COBBLESTONE:0)
Block(-8,25,0,MOSSY_COBBLESTONE:0)
Block(-8,25,1,COBBLESTONE:0)
Block(-8,25,2,MOSSY_COBBLESTONE:0)
Block(-8,25,3,MOSSY_COBBLESTONE:0)
Block(-8,25,4,MOSSY_COBBLESTONE:0)
Block(-8,25,5,COBBLESTONE:0)
Block(-8,25,6,MOSSY_COBBLESTONE:0)
Block(-8,25,7,MOSSY_COBBLESTONE:0)
Block(-8,25,8,MOSSY_COBBLESTONE:0)
Block(-8,26,-1,MOSSY_COBBLESTONE:0)
Block(-8,26,0,MOSSY_COBBLESTONE:0)
Block(-8,26,1,COBBLESTONE:0)
Block(-8,26,2,MOSSY_COBBLESTONE:0)
Block(-8,26,3,MOSSY_COBBLESTONE:0)
Block(-8,26,4,MOSSY_COBBLESTONE:0)
Block(-8,26,5,MOSSY_COBBLESTONE:0)
Block(-8,26,6,MOSSY_COBBLESTONE:0)
Block(-8,26,7,MOSSY_COBBLESTONE:0)
Block(-8,26,8,MOSSY_COBBLESTONE:0)
Block(-8,27,-1,MOSSY_COBBLESTONE:0)
Block(-8,27,0,COBBLESTONE:0)
Block(-8,27,1,MOSSY_COBBLESTONE:0)
Block(-8,27,2,MOSSY_COBBLESTONE:0)
Block(-8,27,3,MOSSY_COBBLESTONE:0)
Block(-8,27,4,COBBLESTONE:0)
Block(-8,27,5,MOSSY_COBBLESTONE:0)
Block(-8,27,6,MOSSY_COBBLESTONE:0)
Block(-8,27,7,MOSSY_COBBLESTONE:0)
Block(-8,27,8,COBBLESTONE:0)
Block(-8,28,-1,MOSSY_COBBLESTONE:0)
Block(-8,28,0,MOSSY_COBBLESTONE:0)
Block(-8,28,1,MOSSY_COBBLESTONE:0)
Block(-8,28,2,COBBLESTONE:0)
Block(-8,28,3,MOSSY_COBBLESTONE:0)
Block(-8,28,4,MOSSY_COBBLESTONE:0)
Block(-8,28,5,MOSSY_COBBLESTONE:0)
Block(-8,28,6,MOSSY_COBBLESTONE:0)
Block(-8,28,7,MOSSY_COBBLESTONE:0)
Block(-8,28,8,MOSSY_COBBLESTONE:0)
Block(-8,29,0,MOSSY_COBBLESTONE:0)
Block(-8,29,1,MOSSY_COBBLESTONE:0)
Block(-8,29,2,MOSSY_COBBLESTONE:0)
Block(-8,29,3,MOSSY_COBBLESTONE:0)
Block(-8,29,4,MOSSY_COBBLESTONE:0)
Block(-8,29,5,COBBLESTONE:0)
Block(-8,29,6,MOSSY_COBBLESTONE:0)
Block(-8,29,7,MOSSY_COBBLESTONE:0)
Block(-8,29,8,MOSSY_COBBLESTONE:0)
Block(-8,30,1,MOSSY_COBBLESTONE:0)
Block(-8,30,2,MOSSY_COBBLESTONE:0)
Block(-8,30,3,MOSSY_COBBLESTONE:0)
Block(-8,30,4,COBBLESTONE:0)
Block(-8,30,5,MOSSY_COBBLESTONE:0)
Block(-8,30,6,MOSSY_COBBLESTONE:0)
Block(-8,30,7,MOSSY_COBBLESTONE:0)
Block(-7,0,-7,dimstack:bedrock:7)
Block(-7,0,-6,dimstack:bedrock:7)
Block(-7,0,-5,dimstack:bedrock:7)
Block(-7,0,-4,dimstack:bedrock:7)
Block(-7,0,-3,dimstack:bedrock:7)
Block(-7,0,-2,dimstack:bedrock:7)
Block(-7,0,-1,dimstack:bedrock:7)
Block(-7,0,0,dimstack:bedrock:7)
Block(-7,0,1,dimstack:bedrock:7)
Block(-7,0,2,dimstack:bedrock:7)
Block(-7,0,3,dimstack:bedrock:7)
Block(-7,0,4,dimstack:bedrock:7)
Block(-7,0,5,dimstack:bedrock:7)
Block(-7,0,6,dimstack:bedrock:7)
Block(-7,0,7,dimstack:bedrock:7)
Block(-7,0,8,dimstack:bedrock:7)
Block(-7,1,-7,dimstack:bedrock:7)
Block(-7,1,-6,COBBLESTONE:0)
Block(-7,1,-5,MOSSY_COBBLESTONE:0)
Block(-7,1,-4,MOSSY_COBBLESTONE:0)
Block(-7,1,-3,MOSSY_COBBLESTONE:0)
Block(-7,1,-2,MOSSY_COBBLESTONE:0)
Block(-7,1,-1,MOSSY_COBBLESTONE:0)
Block(-7,1,0,MOSSY_COBBLESTONE:0)
Block(-7,1,1,AIR:0)
Block(-7,1,2,AIR:0)
Block(-7,1,3,COBBLESTONE:0)
Block(-7,1,4,MOSSY_COBBLESTONE:0)
Block(-7,1,5,MOSSY_COBBLESTONE:0)
Block(-7,1,6,MOSSY_COBBLESTONE:0)
Block(-7,1,7,MOSSY_COBBLESTONE:0)
Block(-7,1,8,MOSSY_COBBLESTONE:0)
Block(-7,2,-7,dimstack:bedrock:7)
Block(-7,2,-6,MOSSY_COBBLESTONE:0)
Block(-7,2,-5,AIR:0)
Block(-7,2,-4,AIR:0)
Block(-7,2,-3,AIR:0)
Block(-7,2,-2,AIR:0)
Block(-7,2,-1,AIR:0)
Block(-7,2,0,AIR:0)
Block(-7,2,1,COBBLESTONE:0)
Block(-7,2,2,COBBLESTONE:0)
Block(-7,2,3,AIR:0)
Block(-7,2,4,AIR:0)
Block(-7,2,5,AIR:0)
Block(-7,2,6,AIR:0)
Block(-7,2,7,AIR:0)
Block(-7,2,8,AIR:0)
Block(-7,3,-7,dimstack:bedrock:7)
Block(-7,3,-6,MOSSY_COBBLESTONE:0)
Block(-7,3,-5,AIR:0)
Block(-7,3,-4,AIR:0)
Block(-7,3,-3,AIR:0)
Block(-7,3,-2,AIR:0)
Block(-7,3,-1,AIR:0)
Block(-7,3,0,AIR:0)
Block(-7,3,1,MOSSY_COBBLESTONE:0)
Block(-7,3,2,COBBLESTONE:0)
Block(-7,3,3,AIR:0)
Block(-7,3,4,AIR:0)
Block(-7,3,5,AIR:0)
Block(-7,3,6,AIR:0)
Block(-7,3,7,AIR:0)
Block(-7,3,8,AIR:0)
Block(-7,4,-7,dimstack:bedrock:7)
Block(-7,4,-6,MOSSY_COBBLESTONE:0)
Block(-7,4,-5,MOSSY_COBBLESTONE:0)
Block(-7,4,-4,MOSSY_COBBLESTONE:0)
Block(-7,4,-3,MOSSY_COBBLESTONE:0)
Block(-7,4,-2,MOSSY_COBBLESTONE:0)
Block(-7,4,-1,MOSSY_COBBLESTONE:0)
Block(-7,4,0,MOSSY_COBBLESTONE:0)
Block(-7,4,1,MOSSY_COBBLESTONE:0)
Block(-7,4,2,MOSSY_COBBLESTONE:0)
Block(-7,4,3,MOSSY_COBBLESTONE:0)
Block(-7,4,4,MOSSY_COBBLESTONE:0)
Block(-7,4,5,MOSSY_COBBLESTONE:0)
Block(-7,4,6,COBBLESTONE:0)
Block(-7,4,7,MOSSY_COBBLESTONE:0)
Block(-7,4,8,MOSSY_COBBLESTONE:0)
Block(-7,5,-7,dimstack:bedrock:7)
Block(-7,5,-6,dimstack:bedrock:7)
Block(-7,5,-5,dimstack:bedrock:7)
Block(-7,5,-4,dimstack:bedrock:7)
Block(-7,5,-3,dimstack:bedrock:7)
Block(-7,5,-2,dimstack:bedrock:7)
Block(-7,5,-1,dimstack:bedrock:7)
Block(-7,5,0,dimstack:bedrock:7)
Block(-7,5,1,dimstack:bedrock:7)
Block(-7,5,2,dimstack:bedrock:7)
Block(-7,5,3,dimstack:bedrock:7)
Block(-7,5,4,dimstack:bedrock:7)
Block(-7,5,5,dimstack:bedrock:7)
Block(-7,5,6,dimstack:bedrock:7)
Block(-7,5,7,dimstack:bedrock:7)
Block(-7,5,8,dimstack:bedrock:7)
Block(-7,14,3,MOSSY_COBBLESTONE:0)
Block(-7,14,4,MOSSY_COBBLESTONE:0)
Block(-7,14,5,MOSSY_COBBLESTONE:0)
Block(-7,15,-5,GRASS:0)
Block(-7,15,2,MOSSY_COBBLESTONE:0)
Block(-7,15,3,NETHERRACK:0)
Block(-7,15,4,NETHERRACK:0)
Block(-7,15,5,NETHERRACK:0)
Block(-7,15,6,COBBLESTONE:0)
Block(-7,16,2,MOSSY_COBBLESTONE:0)
Block(-7,16,3,FIRE:15)
Block(-7,16,4,FIRE:15)
Block(-7,16,5,FIRE:15)
Block(-7,16,6,MOSSY_COBBLESTONE:0)
Block(-7,17,-5,MOSSY_COBBLESTONE:0)
Block(-7,17,2,MOSSY_COBBLESTONE:0)
Block(-7,17,3,AIR:0)
Block(-7,17,4,AIR:0)
Block(-7,17,5,AIR:0)
Block(-7,17,6,MOSSY_COBBLESTONE:0)
Block(-7,18,-4,MOSSY_COBBLESTONE:0)
Block(-7,18,-2,COBBLESTONE:0)
Block(-7,18,2,MOSSY_COBBLESTONE:0)
Block(-7,18,3,AIR:0)
Block(-7,18,4,AIR:0)
Block(-7,18,5,AIR:0)
Block(-7,18,6,COBBLESTONE:0)
Block(-7,19,2,MOSSY_COBBLESTONE:0)
Block(-7,19,3,AIR:0)
Block(-7,19,4,AIR:0)
Block(-7,19,5,AIR:0)
Block(-7,19,6,MOSSY_COBBLESTONE:0)
Block(-7,20,2,COBBLESTONE:0)
Block(-7,20,3,AIR:0)
Block(-7,20,4,AIR:0)
Block(-7,20,5,AIR:0)
Block(-7,20,6,MOSSY_COBBLESTONE:0)
Block(-7,21,2,MOSSY_COBBLESTONE:0)
Block(-7,21,3,MOSSY_COBBLESTONE:0)
Block(-7,21,4,COBBLESTONE:0)
Block(-7,21,5,MOSSY_COBBLESTONE:0)
Block(-7,21,6,MOSSY_COBBLESTONE:0)
Block(-7,22,1,MOSSY_COBBLESTONE:0)
Block(-7,22,2,COBBLESTONE:0)
Block(-7,22,3,MOSSY_COBBLESTONE:0)
Block(-7,22,4,MOSSY_COBBLESTONE:0)
Block(-7,22,5,MOSSY_COBBLESTONE:0)
Block(-7,22,6,MOSSY_COBBLESTONE:0)
Block(-7,22,7,COBBLESTONE:0)
Block(-7,23,0,MOSSY_COBBLESTONE:0)
Block(-7,23,1,MOSSY_COBBLESTONE:0)
Block(-7,23,2,COBBLESTONE:0)
Block(-7,23,3,COBBLESTONE:0)
Block(-7,23,4,MOSSY_COBBLESTONE:0)
Block(-7,23,5,MOSSY_COBBLESTONE:0)
Block(-7,23,6,MOSSY_COBBLESTONE:0)
Block(-7,23,7,MOSSY_COBBLESTONE:0)
Block(-7,23,8,MOSSY_COBBLESTONE:0)
Block(-7,24,0,MOSSY_COBBLESTONE:0)
Block(-7,24,1,MOSSY_COBBLESTONE:0)
Block(-7,24,2,MOSSY_COBBLESTONE:0)
Block(-7,24,3,MOSSY_COBBLESTONE:0)
Block(-7,24,4,MOSSY_COBBLESTONE:0)
Block(-7,24,5,MOSSY_COBBLESTONE:0)
Block(-7,24,6,COBBLESTONE:0)
Block(-7,24,7,MOSSY_COBBLESTONE:0)
Block(-7,24,8,MOSSY_COBBLESTONE:0)
Block(-7,25,-1,MOSSY_COBBLESTONE:0)
Block(-7,25,0,MOSSY_COBBLESTONE:0)
Block(-7,25,1,MOSSY_COBBLESTONE:0)
Block(-7,25,2,MOSSY_COBBLESTONE:0)
Block(-7,25,3,COBBLESTONE:0)
Block(-7,25,4,MOSSY_COBBLESTONE:0)
Block(-7,25,5,MOSSY_COBBLESTONE:0)
Block(-7,25,6,MOSSY_COBBLESTONE:0)
Block(-7,25,7,MOSSY_COBBLESTONE:0)
Block(-7,25,8,MOSSY_COBBLESTONE:0)
Block(-7,26,-1,MOSSY_COBBLESTONE:0)
Block(-7,26,0,MOSSY_COBBLESTONE:0)
Block(-7,26,1,COBBLESTONE:0)
Block(-7,26,2,MOSSY_COBBLESTONE:0)
Block(-7,26,3,MOSSY_COBBLESTONE:0)
Block(-7,26,4,MOSSY_COBBLESTONE:0)
Block(-7,26,5,MOSSY_COBBLESTONE:0)
Block(-7,26,6,MOSSY_COBBLESTONE:0)
Block(-7,26,7,MOSSY_COBBLESTONE:0)
Block(-7,26,8,MOSSY_COBBLESTONE:0)
Block(-7,27,-1,MOSSY_COBBLESTONE:0)
Block(-7,27,0,MOSSY_COBBLESTONE:0)
Block(-7,27,1,MOSSY_COBBLESTONE:0)
Block(-7,27,2,COBBLESTONE:0)
Block(-7,27,3,MOSSY_COBBLESTONE:0)
Block(-7,27,4,MOSSY_COBBLESTONE:0)
Block(-7,27,5,COBBLESTONE:0)
Block(-7,27,6,COBBLESTONE:0)
Block(-7,27,7,COBBLESTONE:0)
Block(-7,27,8,MOSSY_COBBLESTONE:0)
Block(-7,28,-1,MOSSY_COBBLESTONE:0)
Block(-7,28,0,COBBLESTONE:0)
Block(-7,28,1,MOSSY_COBBLESTONE:0)
Block(-7,28,2,MOSSY_COBBLESTONE:0)
Block(-7,28,3,MOSSY_COBBLESTONE:0)
Block(-7,28,4,MOSSY_COBBLESTONE:0)
Block(-7,28,5,MOSSY_COBBLESTONE:0)
Block(-7,28,6,MOSSY_COBBLESTONE:0)
Block(-7,28,7,MOSSY_COBBLESTONE:0)
Block(-7,28,8,MOSSY_COBBLESTONE:0)
Block(-7,29,0,MOSSY_COBBLESTONE:0)
Block(-7,29,1,MOSSY_COBBLESTONE:0)
Block(-7,29,2,MOSSY_COBBLESTONE:0)
Block(-7,29,3,MOSSY_COBBLESTONE:0)
Block(-7,29,4,MOSSY_COBBLESTONE:0)
Block(-7,29,5,MOSSY_COBBLESTONE:0)
Block(-7,29,6,COBBLESTONE:0)
Block(-7,29,7,MOSSY_COBBLESTONE:0)
Block(-7,29,8,MOSSY_COBBLESTONE:0)
Block(-7,30,1,MOSSY_COBBLESTONE:0)
Block(-7,30,2,MOSSY_COBBLESTONE:0)
Block(-7,30,3,MOSSY_COBBLESTONE:0)
Block(-7,30,4,COBBLESTONE:0)
Block(-7,30,5,MOSSY_COBBLESTONE:0)
Block(-7,30,6,MOSSY_COBBLESTONE:0)
Block(-7,30,7,MOSSY_COBBLESTONE:0)
Block(-7,31,3,COBBLESTONE:0)
Block(-7,31,4,COBBLESTONE:0)
Block(-7,31,5,COBBLESTONE:0)
Block(-6,0,-7,dimstack:bedrock:7)
Block(-6,0,-6,dimstack:bedrock:7)
Block(-6,0,-5,dimstack:bedrock:7)
Block(-6,0,-4,dimstack:bedrock:7)
Block(-6,0,-3,dimstack:bedrock:7)
Block(-6,0,-2,dimstack:bedrock:7)
Block(-6,0,-1,dimstack:bedrock:7)
Block(-6,0,0,dimstack:bedrock:7)
Block(-6,0,1,dimstack:bedrock:7)
Block(-6,0,2,dimstack:bedrock:7)
Block(-6,0,3,dimstack:bedrock:7)
Block(-6,0,4,dimstack:bedrock:7)
Block(-6,0,5,dimstack:bedrock:7)
Block(-6,0,6,dimstack:bedrock:7)
Block(-6,0,7,dimstack:bedrock:7)
Block(-6,0,8,dimstack:bedrock:7)
Block(-6,1,-7,dimstack:bedrock:7)
Block(-6,1,-6,MOSSY_COBBLESTONE:0)
Block(-6,1,-5,MOSSY_COBBLESTONE:0)
Block(-6,1,-4,COBBLESTONE:0)
Block(-6,1,-3,MOSSY_COBBLESTONE:0)
Block(-6,1,-2,MOSSY_COBBLESTONE:0)
Block(-6,1,-1,COBBLESTONE:0)
Block(-6,1,0,COBBLESTONE:0)
Block(-6,1,1,MOSSY_COBBLESTONE:0)
Block(-6,1,2,MOSSY_COBBLESTONE:0)
Block(-6,1,3,MOSSY_COBBLESTONE:0)
Block(-6,1,4,MOSSY_COBBLESTONE:0)
Block(-6,1,5,MOSSY_COBBLESTONE:0)
Block(-6,1,6,COBBLESTONE:0)
Block(-6,1,7,MOSSY_COBBLESTONE:0)
Block(-6,1,8,MOSSY_COBBLESTONE:0)
Block(-6,2,-7,dimstack:bedrock:7)
Block(-6,2,-6,MOSSY_COBBLESTONE:0)
Block(-6,2,-5,MOSSY_COBBLESTONE:0)
Block(-6,2,-4,COBBLESTONE:0)
Block(-6,2,-3,COBBLESTONE:0)
Block(-6,2,-2,MOSSY_COBBLESTONE:0)
Block(-6,2,-1,MOSSY_COBBLESTONE:0)
Block(-6,2,0,AIR:0)
Block(-6,2,1,AIR:0)
Block(-6,2,2,AIR:0)
Block(-6,2,3,AIR:0)
Block(-6,2,4,AIR:0)
Block(-6,2,5,AIR:0)
Block(-6,2,6,AIR:0)
Block(-6,2,7,AIR:0)
Block(-6,2,8,AIR:0)
Block(-6,3,-7,dimstack:bedrock:7)
Block(-6,3,-6,MOSSY_COBBLESTONE:0)
Block(-6,3,-5,COBBLESTONE:0)
Block(-6,3,-4,MOSSY_COBBLESTONE:0)
Block(-6,3,-3,MOSSY_COBBLESTONE:0)
Block(-6,3,-2,MOSSY_COBBLESTONE:0)
Block(-6,3,-1,MOSSY_COBBLESTONE:0)
Block(-6,3,0,AIR:0)
Block(-6,3,1,AIR:0)
Block(-6,3,2,AIR:0)
Block(-6,3,3,AIR:0)
Block(-6,3,4,AIR:0)
Block(-6,3,5,AIR:0)
Block(-6,3,6,AIR:0)
Block(-6,3,7,AIR:0)
Block(-6,3,8,AIR:0)
Block(-6,4,-7,dimstack:bedrock:7)
Block(-6,4,-6,MOSSY_COBBLESTONE:0)
Block(-6,4,-5,MOSSY_COBBLESTONE:0)
Block(-6,4,-4,COBBLESTONE:0)
Block(-6,4,-3,MOSSY_COBBLESTONE:0)
Block(-6,4,-2,COBBLESTONE:0)
Block(-6,4,-1,MOSSY_COBBLESTONE:0)
Block(-6,4,0,MOSSY_COBBLESTONE:0)
Block(-6,4,1,MOSSY_COBBLESTONE:0)
Block(-6,4,2,MOSSY_COBBLESTONE:0)
Block(-6,4,3,MOSSY_COBBLESTONE:0)
Block(-6,4,4,MOSSY_COBBLESTONE:0)
Block(-6,4,5,MOSSY_COBBLESTONE:0)
Block(-6,4,6,MOSSY_COBBLESTONE:0)
Block(-6,4,7,MOSSY_COBBLESTONE:0)
Block(-6,4,8,MOSSY_COBBLESTONE:0)
Block(-6,5,-7,dimstack:bedrock:7)
Block(-6,5,-6,dimstack:bedrock:7)
Block(-6,5,-5,dimstack:bedrock:7)
Block(-6,5,-4,dimstack:bedrock:7)
Block(-6,5,-3,dimstack:bedrock:7)
Block(-6,5,-2,dimstack:bedrock:7)
Block(-6,5,-1,dimstack:bedrock:7)
Block(-6,5,0,dimstack:bedrock:7)
Block(-6,5,1,dimstack:bedrock:7)
Block(-6,5,2,dimstack:bedrock:7)
Block(-6,5,3,dimstack:bedrock:7)
Block(-6,5,4,dimstack:bedrock:7)
Block(-6,5,5,dimstack:bedrock:7)
Block(-6,5,6,dimstack:bedrock:7)
Block(-6,5,7,dimstack:bedrock:7)
Block(-6,5,8,dimstack:bedrock:7)
Block(-6,13,-6,DIRT:0)
Block(-6,14,-6,COBBLESTONE:0)
Block(-6,15,-6,MOSSY_COBBLESTONE:0)
Block(-6,15,2,MOSSY_COBBLESTONE:0)
Block(-6,15,3,NETHERRACK:0)
Block(-6,15,4,NETHERRACK:0)
Block(-6,15,5,NETHERRACK:0)
Block(-6,15,6,MOSSY_COBBLESTONE:0)
Block(-6,16,-6,COBBLESTONE:0)
Block(-6,16,2,COBBLESTONE:0)
Block(-6,16,3,FIRE:15)
Block(-6,16,4,FIRE:15)
Block(-6,16,5,FIRE:15)
Block(-6,16,6,COBBLESTONE:0)
Block(-6,17,2,COBBLESTONE:0)
Block(-6,17,3,AIR:0)
Block(-6,17,4,AIR:0)
Block(-6,17,5,AIR:0)
Block(-6,17,6,MOSSY_COBBLESTONE:0)
Block(-6,18,-4,MOSSY_COBBLESTONE:0)
Block(-6,18,-2,MOSSY_COBBLESTONE:0)
Block(-6,18,2,MOSSY_COBBLESTONE:0)
Block(-6,18,3,AIR:0)
Block(-6,18,4,AIR:0)
Block(-6,18,5,AIR:0)
Block(-6,18,6,MOSSY_COBBLESTONE:0)
Block(-6,19,2,MOSSY_COBBLESTONE:0)
Block(-6,19,3,AIR:0)
Block(-6,19,4,AIR:0)
Block(-6,19,5,AIR:0)
Block(-6,19,6,MOSSY_COBBLESTONE:0)
Block(-6,20,2,MOSSY_COBBLESTONE:0)
Block(-6,20,3,AIR:0)
Block(-6,20,4,AIR:0)
Block(-6,20,5,AIR:0)
Block(-6,20,6,MOSSY_COBBLESTONE:0)
Block(-6,21,1,MOSSY_COBBLESTONE:0)
Block(-6,21,2,MOSSY_COBBLESTONE:0)
Block(-6,21,3,MOSSY_COBBLESTONE:0)
Block(-6,21,4,MOSSY_COBBLESTONE:0)
Block(-6,21,5,MOSSY_COBBLESTONE:0)
Block(-6,21,6,COBBLESTONE:0)
Block(-6,21,7,MOSSY_COBBLESTONE:0)
Block(-6,22,1,MOSSY_COBBLESTONE:0)
Block(-6,22,2,MOSSY_COBBLESTONE:0)
Block(-6,22,3,MOSSY_COBBLESTONE:0)
Block(-6,22,4,MOSSY_COBBLESTONE:0)
Block(-6,22,5,MOSSY_COBBLESTONE:0)
Block(-6,22,6,MOSSY_COBBLESTONE:0)
Block(-6,22,7,MOSSY_COBBLESTONE:0)
Block(-6,23,0,MOSSY_COBBLESTONE:0)
Block(-6,23,1,COBBLESTONE:0)
Block(-6,23,2,COBBLESTONE:0)
Block(-6,23,3,MOSSY_COBBLESTONE:0)
Block(-6,23,4,COBBLESTONE:0)
Block(-6,23,5,MOSSY_COBBLESTONE:0)
Block(-6,23,6,MOSSY_COBBLESTONE:0)
Block(-6,23,7,MOSSY_COBBLESTONE:0)
Block(-6,23,8,MOSSY_COBBLESTONE:0)
Block(-6,24,0,MOSSY_COBBLESTONE:0)
Block(-6,24,1,MOSSY_COBBLESTONE:0)
Block(-6,24,2,MOSSY_COBBLESTONE:0)
Block(-6,24,3,MOSSY_COBBLESTONE:0)
Block(-6,24,4,MOSSY_COBBLESTONE:0)
Block(-6,24,5,COBBLESTONE:0)
Block(-6,24,6,COBBLESTONE:0)
Block(-6,24,7,MOSSY_COBBLESTONE:0)
Block(-6,24,8,COBBLESTONE:0)
Block(-6,25,-1,MOSSY_COBBLESTONE:0)
Block(-6,25,0,MOSSY_COBBLESTONE:0)
Block(-6,25,1,COBBLESTONE:0)
Block(-6,25,2,MOSSY_COBBLESTONE:0)
Block(-6,25,3,MOSSY_COBBLESTONE:0)
Block(-6,25,4,MOSSY_COBBLESTONE:0)
Block(-6,25,5,COBBLESTONE:0)
Block(-6,25,6,MOSSY_COBBLESTONE:0)
Block(-6,25,7,MOSSY_COBBLESTONE:0)
Block(-6,25,8,MOSSY_COBBLESTONE:0)
Block(-6,26,-1,MOSSY_COBBLESTONE:0)
Block(-6,26,0,MOSSY_COBBLESTONE:0)
Block(-6,26,1,MOSSY_COBBLESTONE:0)
Block(-6,26,2,COBBLESTONE:0)
Block(-6,26,3,MOSSY_COBBLESTONE:0)
Block(-6,26,4,MOSSY_COBBLESTONE:0)
Block(-6,26,5,COBBLESTONE:0)
Block(-6,26,6,MOSSY_COBBLESTONE:0)
Block(-6,26,7,MOSSY_COBBLESTONE:0)
Block(-6,26,8,MOSSY_COBBLESTONE:0)
Block(-6,27,-1,MOSSY_COBBLESTONE:0)
Block(-6,27,0,MOSSY_COBBLESTONE:0)
Block(-6,27,1,MOSSY_COBBLESTONE:0)
Block(-6,27,2,MOSSY_COBBLESTONE:0)
Block(-6,27,3,MOSSY_COBBLESTONE:0)
Block(-6,27,4,MOSSY_COBBLESTONE:0)
Block(-6,27,5,MOSSY_COBBLESTONE:0)
Block(-6,27,6,MOSSY_COBBLESTONE:0)
Block(-6,27,7,MOSSY_COBBLESTONE:0)
Block(-6,27,8,MOSSY_COBBLESTONE:0)
Block(-6,28,-1,MOSSY_COBBLESTONE:0)
Block(-6,28,0,MOSSY_COBBLESTONE:0)
Block(-6,28,1,COBBLESTONE:0)
Block(-6,28,2,COBBLESTONE:0)
Block(-6,28,3,MOSSY_COBBLESTONE:0)
Block(-6,28,4,MOSSY_COBBLESTONE:0)
Block(-6,28,5,MOSSY_COBBLESTONE:0)
Block(-6,28,6,MOSSY_COBBLESTONE:0)
Block(-6,28,7,COBBLESTONE:0)
Block(-6,28,8,MOSSY_COBBLESTONE:0)
Block(-6,29,0,MOSSY_COBBLESTONE:0)
Block(-6,29,1,MOSSY_COBBLESTONE:0)
Block(-6,29,2,COBBLESTONE:0)
Block(-6,29,3,MOSSY_COBBLESTONE:0)
Block(-6,29,4,MOSSY_COBBLESTONE:0)
Block(-6,29,5,MOSSY_COBBLESTONE:0)
Block(-6,29,6,MOSSY_COBBLESTONE:0)
Block(-6,29,7,MOSSY_COBBLESTONE:0)
Block(-6,29,8,MOSSY_COBBLESTONE:0)
Block(-6,30,1,MOSSY_COBBLESTONE:0)
Block(-6,30,2,MOSSY_COBBLESTONE:0)
Block(-6,30,3,MOSSY_COBBLESTONE:0)
Block(-6,30,4,MOSSY_COBBLESTONE:0)
Block(-6,30,5,MOSSY_COBBLESTONE:0)
Block(-6,30,6,MOSSY_COBBLESTONE:0)
Block(-6,30,7,MOSSY_COBBLESTONE:0)
Block(-6,31,3,MOSSY_COBBLESTONE:0)
Block(-6,31,4,MOSSY_COBBLESTONE:0)
Block(-6,31,5,COBBLESTONE:0)
Block(-5,0,-7,dimstack:bedrock:7)
Block(-5,0,-6,dimstack:bedrock:7)
Block(-5,0,-5,dimstack:bedrock:7)
Block(-5,0,-4,dimstack:bedrock:7)
Block(-5,0,-3,dimstack:bedrock:7)
Block(-5,0,-2,dimstack:bedrock:7)
Block(-5,0,-1,dimstack:bedrock:7)
Block(-5,0,0,dimstack:bedrock:7)
Block(-5,0,1,dimstack:bedrock:7)
Block(-5,0,2,dimstack:bedrock:7)
Block(-5,0,3,dimstack:bedrock:7)
Block(-5,0,4,dimstack:bedrock:7)
Block(-5,0,5,dimstack:bedrock:7)
Block(-5,0,6,dimstack:bedrock:7)
Block(-5,0,7,dimstack:bedrock:7)
Block(-5,0,8,dimstack:bedrock:7)
Block(-5,1,-7,dimstack:bedrock:7)
Block(-5,1,-6,AIR:0)
Block(-5,1,-5,AIR:0)
Block(-5,1,-4,AIR:0)
Block(-5,1,-3,AIR:0)
Block(-5,1,-2,AIR:0)
Block(-5,1,-1,AIR:0)
Block(-5,1,0,AIR:0)
Block(-5,1,1,AIR:0)
Block(-5,1,2,AIR:0)
Block(-5,1,3,MOSSY_COBBLESTONE:0)
Block(-5,1,4,MOSSY_COBBLESTONE:0)
Block(-5,1,5,MOSSY_COBBLESTONE:0)
Block(-5,1,6,COBBLESTONE:0)
Block(-5,1,7,MOSSY_COBBLESTONE:0)
Block(-5,1,8,MOSSY_COBBLESTONE:0)
Block(-5,2,-7,dimstack:bedrock:7)
Block(-5,2,-6,AIR:0)
Block(-5,2,-5,AIR:0)
Block(-5,2,-4,AIR:0)
Block(-5,2,-3,AIR:0)
Block(-5,2,-2,AIR:0)
Block(-5,2,-1,MOSSY_COBBLESTONE:0)
Block(-5,2,0,COBBLESTONE:0)
Block(-5,2,1,COBBLESTONE:0)
Block(-5,2,2,MOSSY_COBBLESTONE:0)
Block(-5,2,3,MOSSY_COBBLESTONE:0)
Block(-5,2,4,AIR:0)
Block(-5,2,5,MOB_SPAWNER:0,../../ruins_spawners/crypt_multi.nbt)
Block(-5,2,6,AIR:0)
Block(-5,2,7,MOB_SPAWNER:0,../../ruins_spawners/crypt_multi.nbt)
Block(-5,2,8,AIR:0)
Block(-5,3,-7,dimstack:bedrock:7)
Block(-5,3,-6,AIR:0)
Block(-5,3,-5,AIR:0)
Block(-5,3,-4,AIR:0)
Block(-5,3,-3,AIR:0)
Block(-5,3,-2,AIR:0)
Block(-5,3,-1,MOSSY_COBBLESTONE:0)
Block(-5,3,0,MOSSY_COBBLESTONE:0)
Block(-5,3,1,MOSSY_COBBLESTONE:0)
Block(-5,3,2,MOSSY_COBBLESTONE:0)
Block(-5,3,3,MOSSY_COBBLESTONE:0)
Block(-5,3,4,AIR:0)
Block(-5,3,5,AIR:0)
Block(-5,3,6,AIR:0)
Block(-5,3,7,AIR:0)
Block(-5,3,8,AIR:0)
Block(-5,4,-7,dimstack:bedrock:7)
Block(-5,4,-6,MOSSY_COBBLESTONE:0)
Block(-5,4,-5,MOSSY_COBBLESTONE:0)
Block(-5,4,-4,MOSSY_COBBLESTONE:0)
Block(-5,4,-3,MOSSY_COBBLESTONE:0)
Block(-5,4,-2,MOSSY_COBBLESTONE:0)
Block(-5,4,-1,COBBLESTONE:0)
Block(-5,4,0,MOSSY_COBBLESTONE:0)
Block(-5,4,1,COBBLESTONE:0)
Block(-5,4,2,MOSSY_COBBLESTONE:0)
Block(-5,4,3,MOSSY_COBBLESTONE:0)
Block(-5,4,4,MOSSY_COBBLESTONE:0)
Block(-5,4,5,MOSSY_COBBLESTONE:0)
Block(-5,4,6,MOSSY_COBBLESTONE:0)
Block(-5,4,7,MOSSY_COBBLESTONE:0)
Block(-5,4,8,MOSSY_COBBLESTONE:0)
Block(-5,5,-7,dimstack:bedrock:7)
Block(-5,5,-6,dimstack:bedrock:7)
Block(-5,5,-5,dimstack:bedrock:7)
Block(-5,5,-4,dimstack:bedrock:7)
Block(-5,5,-3,dimstack:bedrock:7)
Block(-5,5,-2,dimstack:bedrock:7)
Block(-5,5,-1,dimstack:bedrock:7)
Block(-5,5,0,dimstack:bedrock:7)
Block(-5,5,1,dimstack:bedrock:7)
Block(-5,5,2,dimstack:bedrock:7)
Block(-5,5,3,dimstack:bedrock:7)
Block(-5,5,4,dimstack:bedrock:7)
Block(-5,5,5,dimstack:bedrock:7)
Block(-5,5,6,dimstack:bedrock:7)
Block(-5,5,7,dimstack:bedrock:7)
Block(-5,5,8,dimstack:bedrock:7)
Block(-5,13,-7,DIRT:0)
Block(-5,14,-7,AIR:0)
Block(-5,14,-4,DIRT:0)
Block(-5,14,-2,DIRT:0)
Block(-5,14,7,DIRT:0)
Block(-5,15,-7,AIR:0)
Block(-5,15,-4,GRASS:0)
Block(-5,15,-2,GRASS:0)
Block(-5,15,2,MOSSY_COBBLESTONE:0)
Block(-5,15,3,NETHERRACK:0)
Block(-5,15,4,NETHERRACK:0)
Block(-5,15,5,NETHERRACK:0)
Block(-5,15,6,MOSSY_COBBLESTONE:0)
Block(-5,16,-7,AIR:0)
Block(-5,16,2,MOSSY_COBBLESTONE:0)
Block(-5,16,3,FIRE:15)
Block(-5,16,4,FIRE:15)
Block(-5,16,5,FIRE:15)
Block(-5,16,6,MOSSY_COBBLESTONE:0)
Block(-5,17,-4,MOSSY_COBBLESTONE:0)
Block(-5,17,-2,MOSSY_COBBLESTONE:0)
Block(-5,17,2,AIR:0)
Block(-5,17,3,AIR:0)
Block(-5,17,4,AIR:0)
Block(-5,17,5,AIR:0)
Block(-5,17,6,AIR:0)
Block(-5,18,2,AIR:0)
Block(-5,18,3,AIR:0)
Block(-5,18,4,AIR:0)
Block(-5,18,5,AIR:0)
Block(-5,18,6,AIR:0)
Block(-5,19,2,AIR:0)
Block(-5,19,3,AIR:0)
Block(-5,19,4,AIR:0)
Block(-5,19,5,AIR:0)
Block(-5,19,6,AIR:0)
Block(-5,20,2,AIR:0)
Block(-5,20,3,AIR:0)
Block(-5,20,4,AIR:0)
Block(-5,20,5,AIR:0)
Block(-5,20,6,AIR:0)
Block(-5,21,1,COBBLESTONE:0)
Block(-5,21,2,COBBLESTONE:0)
Block(-5,21,3,MOSSY_COBBLESTONE:0)
Block(-5,21,4,MOSSY_COBBLESTONE:0)
Block(-5,21,5,MOSSY_COBBLESTONE:0)
Block(-5,21,6,MOSSY_COBBLESTONE:0)
Block(-5,21,7,MOSSY_COBBLESTONE:0)
Block(-5,22,1,MOSSY_COBBLESTONE:0)
Block(-5,22,2,MOSSY_COBBLESTONE:0)
Block(-5,22,3,COBBLESTONE:0)
Block(-5,22,4,COBBLESTONE:0)
Block(-5,22,5,COBBLESTONE:0)
Block(-5,22,6,MOSSY_COBBLESTONE:0)
Block(-5,22,7,MOSSY_COBBLESTONE:0)
Block(-5,23,0,MOSSY_COBBLESTONE:0)
Block(-5,23,1,MOSSY_COBBLESTONE:0)
Block(-5,23,2,MOSSY_COBBLESTONE:0)
Block(-5,23,3,MOSSY_COBBLESTONE:0)
Block(-5,23,4,MOSSY_COBBLESTONE:0)
Block(-5,23,5,COBBLESTONE:0)
Block(-5,23,6,MOSSY_COBBLESTONE:0)
Block(-5,23,7,MOSSY_COBBLESTONE:0)
Block(-5,23,8,MOSSY_COBBLESTONE:0)
Block(-5,24,0,COBBLESTONE:0)
Block(-5,24,1,COBBLESTONE:0)
Block(-5,24,2,MOSSY_COBBLESTONE:0)
Block(-5,24,3,MOSSY_COBBLESTONE:0)
Block(-5,24,4,MOSSY_COBBLESTONE:0)
Block(-5,24,5,MOSSY_COBBLESTONE:0)
Block(-5,24,6,COBBLESTONE:0)
Block(-5,24,7,MOSSY_COBBLESTONE:0)
Block(-5,24,8,MOSSY_COBBLESTONE:0)
Block(-5,25,-1,MOSSY_COBBLESTONE:0)
Block(-5,25,0,MOSSY_COBBLESTONE:0)
Block(-5,25,1,COBBLESTONE:0)
Block(-5,25,2,MOSSY_COBBLESTONE:0)
Block(-5,25,3,MOSSY_COBBLESTONE:0)
Block(-5,25,4,MOSSY_COBBLESTONE:0)
Block(-5,25,5,MOSSY_COBBLESTONE:0)
Block(-5,25,6,MOSSY_COBBLESTONE:0)
Block(-5,25,7,MOSSY_COBBLESTONE:0)
Block(-5,25,8,MOSSY_COBBLESTONE:0)
Block(-5,26,-1,MOSSY_COBBLESTONE:0)
Block(-5,26,0,MOSSY_COBBLESTONE:0)
Block(-5,26,1,MOSSY_COBBLESTONE:0)
Block(-5,26,2,MOSSY_COBBLESTONE:0)
Block(-5,26,3,MOSSY_COBBLESTONE:0)
Block(-5,26,4,MOSSY_COBBLESTONE:0)
Block(-5,26,5,MOSSY_COBBLESTONE:0)
Block(-5,26,6,MOSSY_COBBLESTONE:0)
Block(-5,26,7,MOSSY_COBBLESTONE:0)
Block(-5,26,8,MOSSY_COBBLESTONE:0)
Block(-5,27,-1,MOSSY_COBBLESTONE:0)
Block(-5,27,0,MOSSY_COBBLESTONE:0)
Block(-5,27,1,COBBLESTONE:0)
Block(-5,27,2,MOSSY_COBBLESTONE:0)
Block(-5,27,3,MOSSY_COBBLESTONE:0)
Block(-5,27,4,MOSSY_COBBLESTONE:0)
Block(-5,27,5,MOSSY_COBBLESTONE:0)
Block(-5,27,6,MOSSY_COBBLESTONE:0)
Block(-5,27,7,MOSSY_COBBLESTONE:0)
Block(-5,27,8,MOSSY_COBBLESTONE:0)
Block(-5,28,-1,MOSSY_COBBLESTONE:0)
Block(-5,28,0,MOSSY_COBBLESTONE:0)
Block(-5,28,1,MOSSY_COBBLESTONE:0)
Block(-5,28,2,MOSSY_COBBLESTONE:0)
Block(-5,28,3,MOSSY_COBBLESTONE:0)
Block(-5,28,4,MOSSY_COBBLESTONE:0)
Block(-5,28,5,MOSSY_COBBLESTONE:0)
Block(-5,28,6,MOSSY_COBBLESTONE:0)
Block(-5,28,7,MOSSY_COBBLESTONE:0)
Block(-5,28,8,MOSSY_COBBLESTONE:0)
Block(-5,29,0,COBBLESTONE:0)
Block(-5,29,1,MOSSY_COBBLESTONE:0)
Block(-5,29,2,MOSSY_COBBLESTONE:0)
Block(-5,29,3,MOSSY_COBBLESTONE:0)
Block(-5,29,4,MOSSY_COBBLESTONE:0)
Block(-5,29,5,MOSSY_COBBLESTONE:0)
Block(-5,29,6,MOSSY_COBBLESTONE:0)
Block(-5,29,7,MOSSY_COBBLESTONE:0)
Block(-5,29,8,COBBLESTONE:0)
Block(-5,30,1,MOSSY_COBBLESTONE:0)
Block(-5,30,2,MOSSY_COBBLESTONE:0)
Block(-5,30,3,COBBLESTONE:0)
Block(-5,30,4,MOSSY_COBBLESTONE:0)
Block(-5,30,5,MOSSY_COBBLESTONE:0)
Block(-5,30,6,MOSSY_COBBLESTONE:0)
Block(-5,30,7,MOSSY_COBBLESTONE:0)
Block(-4,0,-7,dimstack:bedrock:7)
Block(-4,0,-6,dimstack:bedrock:7)
Block(-4,0,-5,dimstack:bedrock:7)
Block(-4,0,-4,dimstack:bedrock:7)
Block(-4,0,-3,dimstack:bedrock:7)
Block(-4,0,-2,dimstack:bedrock:7)
Block(-4,0,-1,dimstack:bedrock:7)
Block(-4,0,0,dimstack:bedrock:7)
Block(-4,0,1,dimstack:bedrock:7)
Block(-4,0,2,dimstack:bedrock:7)
Block(-4,0,3,dimstack:bedrock:7)
Block(-4,0,4,dimstack:bedrock:7)
Block(-4,0,5,dimstack:bedrock:7)
Block(-4,0,6,dimstack:bedrock:7)
Block(-4,0,7,dimstack:bedrock:7)
Block(-4,0,8,dimstack:bedrock:7)
Block(-4,1,-7,dimstack:bedrock:7)
Block(-4,1,-6,AIR:0)
Block(-4,1,-5,AIR:0)
Block(-4,1,-4,AIR:0)
Block(-4,1,-3,AIR:0)
Block(-4,1,-2,AIR:0)
Block(-4,1,-1,AIR:0)
Block(-4,1,0,AIR:0)
Block(-4,1,1,AIR:0)
Block(-4,1,2,AIR:0)
Block(-4,1,3,MOSSY_COBBLESTONE:0)
Block(-4,1,4,MOSSY_COBBLESTONE:0)
Block(-4,1,5,COBBLESTONE:0)
Block(-4,1,6,COBBLESTONE:0)
Block(-4,1,7,MOSSY_COBBLESTONE:0)
Block(-4,1,8,MOSSY_COBBLESTONE:0)
Block(-4,2,-7,dimstack:bedrock:7)
Block(-4,2,-6,AIR:0)
Block(-4,2,-5,AIR:0)
Block(-4,2,-4,AIR:0)
Block(-4,2,-3,AIR:0)
Block(-4,2,-2,AIR:0)
Block(-4,2,-1,AIR:0)
Block(-4,2,0,AIR:0)
Block(-4,2,1,AIR:0)
Block(-4,2,2,AIR:0)
Block(-4,2,3,MOSSY_COBBLESTONE:0)
Block(-4,2,4,AIR:0)
Block(-4,2,5,AIR:0)
Block(-4,2,6,AIR:0)
Block(-4,2,7,AIR:0)
Block(-4,2,8,AIR:0)
Block(-4,3,-7,dimstack:bedrock:7)
Block(-4,3,-6,AIR:0)
Block(-4,3,-5,AIR:0)
Block(-4,3,-4,AIR:0)
Block(-4,3,-3,AIR:0)
Block(-4,3,-2,AIR:0)
Block(-4,3,-1,AIR:0)
Block(-4,3,0,AIR:0)
Block(-4,3,1,AIR:0)
Block(-4,3,2,AIR:0)
Block(-4,3,3,COBBLESTONE:0)
Block(-4,3,4,AIR:0)
Block(-4,3,5,AIR:0)
Block(-4,3,6,AIR:0)
Block(-4,3,7,AIR:0)
Block(-4,3,8,AIR:0)
Block(-4,4,-7,dimstack:bedrock:7)
Block(-4,4,-6,MOSSY_COBBLESTONE:0)
Block(-4,4,-5,MOSSY_COBBLESTONE:0)
Block(-4,4,-4,MOSSY_COBBLESTONE:0)
Block(-4,4,-3,MOSSY_COBBLESTONE:0)
Block(-4,4,-2,MOSSY_COBBLESTONE:0)
Block(-4,4,-1,MOSSY_COBBLESTONE:0)
Block(-4,4,0,MOSSY_COBBLESTONE:0)
Block(-4,4,1,MOSSY_COBBLESTONE:0)
Block(-4,4,2,MOSSY_COBBLESTONE:0)
Block(-4,4,3,MOSSY_COBBLESTONE:0)
Block(-4,4,4,MOSSY_COBBLESTONE:0)
Block(-4,4,5,MOSSY_COBBLESTONE:0)
Block(-4,4,6,MOSSY_COBBLESTONE:0)
Block(-4,4,7,MOSSY_COBBLESTONE:0)
Block(-4,4,8,MOSSY_COBBLESTONE:0)
Block(-4,5,-7,dimstack:bedrock:7)
Block(-4,5,-6,dimstack:bedrock:7)
Block(-4,5,-5,dimstack:bedrock:7)
Block(-4,5,-4,dimstack:bedrock:7)
Block(-4,5,-3,dimstack:bedrock:7)
Block(-4,5,-2,dimstack:bedrock:7)
Block(-4,5,-1,dimstack:bedrock:7)
Block(-4,5,0,dimstack:bedrock:7)
Block(-4,5,1,dimstack:bedrock:7)
Block(-4,5,2,dimstack:bedrock:7)
Block(-4,5,3,dimstack:bedrock:7)
Block(-4,5,4,dimstack:bedrock:7)
Block(-4,5,5,dimstack:bedrock:7)
Block(-4,5,6,dimstack:bedrock:7)
Block(-4,5,7,dimstack:bedrock:7)
Block(-4,5,8,dimstack:bedrock:7)
Block(-4,13,-4,DIRT:0)
Block(-4,13,-2,DIRT:0)
Block(-4,14,-4,COBBLESTONE:0)
Block(-4,14,-2,COBBLESTONE:0)
Block(-4,14,1,DIRT:0)
Block(-4,14,4,DIRT:0)
Block(-4,15,-4,MOSSY_COBBLESTONE:0)
Block(-4,15,-2,COBBLESTONE:0)
Block(-4,15,2,MOSSY_COBBLESTONE:0)
Block(-4,15,3,NETHERRACK:0)
Block(-4,15,4,NETHERRACK:0)
Block(-4,15,5,NETHERRACK:0)
Block(-4,15,6,MOSSY_COBBLESTONE:0)
Block(-4,16,-4,MOSSY_COBBLESTONE:0)
Block(-4,16,-2,MOSSY_COBBLESTONE:0)
Block(-4,16,2,MOSSY_COBBLESTONE:0)
Block(-4,16,3,FIRE:15)
Block(-4,16,4,FIRE:15)
Block(-4,16,5,FIRE:15)
Block(-4,16,6,MOSSY_COBBLESTONE:0)
Block(-4,17,2,AIR:0)
Block(-4,17,3,AIR:0)
Block(-4,17,4,AIR:0)
Block(-4,17,5,AIR:0)
Block(-4,17,6,AIR:0)
Block(-4,18,2,AIR:0)
Block(-4,18,3,AIR:0)
Block(-4,18,4,AIR:0)
Block(-4,18,5,AIR:0)
Block(-4,18,6,AIR:0)
Block(-4,19,2,AIR:0)
Block(-4,19,3,AIR:0)
Block(-4,19,4,AIR:0)
Block(-4,19,5,AIR:0)
Block(-4,19,6,AIR:0)
Block(-4,20,2,AIR:0)
Block(-4,20,3,AIR:0)
Block(-4,20,4,AIR:0)
Block(-4,20,5,AIR:0)
Block(-4,20,6,AIR:0)
Block(-4,21,1,MOSSY_COBBLESTONE:0)
Block(-4,21,2,MOSSY_COBBLESTONE:0)
Block(-4,21,3,MOSSY_COBBLESTONE:0)
Block(-4,21,4,COBBLESTONE:0)
Block(-4,21,5,MOSSY_COBBLESTONE:0)
Block(-4,21,6,MOSSY_COBBLESTONE:0)
Block(-4,21,7,MOSSY_COBBLESTONE:0)
Block(-4,22,1,COBBLESTONE:0)
Block(-4,22,2,COBBLESTONE:0)
Block(-4,22,3,MOSSY_COBBLESTONE:0)
Block(-4,22,4,MOSSY_COBBLESTONE:0)
Block(-4,22,5,MOSSY_COBBLESTONE:0)
Block(-4,22,6,MOSSY_COBBLESTONE:0)
Block(-4,22,7,MOSSY_COBBLESTONE:0)
Block(-4,23,0,MOSSY_COBBLESTONE:0)
Block(-4,23,1,MOSSY_COBBLESTONE:0)
Block(-4,23,2,COBBLESTONE:0)
Block(-4,23,3,MOSSY_COBBLESTONE:0)
Block(-4,23,4,MOSSY_COBBLESTONE:0)
Block(-4,23,5,MOSSY_COBBLESTONE:0)
Block(-4,23,6,COBBLESTONE:0)
Block(-4,23,7,MOSSY_COBBLESTONE:0)
Block(-4,23,8,MOSSY_COBBLESTONE:0)
Block(-4,24,0,MOSSY_COBBLESTONE:0)
Block(-4,24,1,MOSSY_COBBLESTONE:0)
Block(-4,24,2,MOSSY_COBBLESTONE:0)
Block(-4,24,3,COBBLESTONE:0)
Block(-4,24,4,MOSSY_COBBLESTONE:0)
Block(-4,24,5,MOSSY_COBBLESTONE:0)
Block(-4,24,6,MOSSY_COBBLESTONE:0)
Block(-4,24,7,MOSSY_COBBLESTONE:0)
Block(-4,24,8,MOSSY_COBBLESTONE:0)
Block(-4,25,-1,MOSSY_COBBLESTONE:0)
Block(-4,25,0,MOSSY_COBBLESTONE:0)
Block(-4,25,1,MOSSY_COBBLESTONE:0)
Block(-4,25,2,MOSSY_COBBLESTONE:0)
Block(-4,25,3,MOSSY_COBBLESTONE:0)
Block(-4,25,4,MOSSY_COBBLESTONE:0)
Block(-4,25,5,COBBLESTONE:0)
Block(-4,25,6,MOSSY_COBBLESTONE:0)
Block(-4,25,7,COBBLESTONE:0)
Block(-4,25,8,MOSSY_COBBLESTONE:0)
Block(-4,26,-1,MOSSY_COBBLESTONE:0)
Block(-4,26,0,MOSSY_COBBLESTONE:0)
Block(-4,26,1,MOSSY_COBBLESTONE:0)
Block(-4,26,2,MOSSY_COBBLESTONE:0)
Block(-4,26,3,MOSSY_COBBLESTONE:0)
Block(-4,26,4,MOSSY_COBBLESTONE:0)
Block(-4,26,5,MOSSY_COBBLESTONE:0)
Block(-4,26,6,MOSSY_COBBLESTONE:0)
Block(-4,26,7,MOSSY_COBBLESTONE:0)
Block(-4,26,8,MOSSY_COBBLESTONE:0)
Block(-4,27,-1,MOSSY_COBBLESTONE:0)
Block(-4,27,0,COBBLESTONE:0)
Block(-4,27,1,MOSSY_COBBLESTONE:0)
Block(-4,27,2,MOSSY_COBBLESTONE:0)
Block(-4,27,3,MOSSY_COBBLESTONE:0)
Block(-4,27,4,MOSSY_COBBLESTONE:0)
Block(-4,27,5,MOSSY_COBBLESTONE:0)
Block(-4,27,6,MOSSY_COBBLESTONE:0)
Block(-4,27,7,COBBLESTONE:0)
Block(-4,27,8,MOSSY_COBBLESTONE:0)
Block(-4,28,-1,MOSSY_COBBLESTONE:0)
Block(-4,28,0,MOSSY_COBBLESTONE:0)
Block(-4,28,1,MOSSY_COBBLESTONE:0)
Block(-4,28,2,MOSSY_COBBLESTONE:0)
Block(-4,28,3,MOSSY_COBBLESTONE:0)
Block(-4,28,4,MOSSY_COBBLESTONE:0)
Block(-4,28,5,MOSSY_COBBLESTONE:0)
Block(-4,28,6,MOSSY_COBBLESTONE:0)
Block(-4,28,7,MOSSY_COBBLESTONE:0)
Block(-4,28,8,MOSSY_COBBLESTONE:0)
Block(-4,29,1,MOSSY_COBBLESTONE:0)
Block(-4,29,2,MOSSY_COBBLESTONE:0)
Block(-4,29,3,MOSSY_COBBLESTONE:0)
Block(-4,29,4,MOSSY_COBBLESTONE:0)
Block(-4,29,5,MOSSY_COBBLESTONE:0)
Block(-4,29,6,MOSSY_COBBLESTONE:0)
Block(-4,29,7,MOSSY_COBBLESTONE:0)
Block(-3,0,-7,dimstack:bedrock:7)
Block(-3,0,-6,dimstack:bedrock:7)
Block(-3,0,-5,dimstack:bedrock:7)
Block(-3,0,-4,dimstack:bedrock:7)
Block(-3,0,-3,dimstack:bedrock:7)
Block(-3,0,-2,dimstack:bedrock:7)
Block(-3,0,-1,dimstack:bedrock:7)
Block(-3,0,0,dimstack:bedrock:7)
Block(-3,0,1,dimstack:bedrock:7)
Block(-3,0,2,dimstack:bedrock:7)
Block(-3,0,3,dimstack:bedrock:7)
Block(-3,0,4,dimstack:bedrock:7)
Block(-3,0,5,dimstack:bedrock:7)
Block(-3,0,6,dimstack:bedrock:7)
Block(-3,0,7,dimstack:bedrock:7)
Block(-3,0,8,dimstack:bedrock:7)
Block(-3,1,-7,dimstack:bedrock:7)
Block(-3,1,-6,AIR:0)
Block(-3,1,-5,AIR:0)
Block(-3,1,-4,AIR:0)
Block(-3,1,-3,AIR:0)
Block(-3,1,-2,AIR:0)
Block(-3,1,-1,AIR:0)
Block(-3,1,0,AIR:0)
Block(-3,1,1,AIR:0)
Block(-3,1,2,AIR:0)
Block(-3,1,3,MOSSY_COBBLESTONE:0)
Block(-3,1,4,MOSSY_COBBLESTONE:0)
Block(-3,1,5,MOSSY_COBBLESTONE:0)
Block(-3,1,6,MOSSY_COBBLESTONE:0)
Block(-3,1,7,MOSSY_COBBLESTONE:0)
Block(-3,1,8,MOSSY_COBBLESTONE:0)
Block(-3,2,-7,dimstack:bedrock:7)
Block(-3,2,-6,AIR:0)
Block(-3,2,-5,AIR:0)
Block(-3,2,-4,AIR:0)
Block(-3,2,-3,AIR:0)
Block(-3,2,-2,AIR:0)
Block(-3,2,-1,AIR:0)
Block(-3,2,0,AIR:0)
Block(-3,2,1,AIR:0)
Block(-3,2,2,AIR:0)
Block(-3,2,3,MOSSY_COBBLESTONE:0)
Block(-3,2,4,MOSSY_COBBLESTONE:0)
Block(-3,2,5,MOSSY_COBBLESTONE:0)
Block(-3,2,6,COBBLESTONE:0)
Block(-3,2,7,MOSSY_COBBLESTONE:0)
Block(-3,2,8,MOSSY_COBBLESTONE:0)
Block(-3,3,-7,dimstack:bedrock:7)
Block(-3,3,-6,AIR:0)
Block(-3,3,-5,AIR:0)
Block(-3,3,-4,AIR:0)
Block(-3,3,-3,AIR:0)
Block(-3,3,-2,AIR:0)
Block(-3,3,-1,AIR:0)
Block(-3,3,0,AIR:0)
Block(-3,3,1,AIR:0)
Block(-3,3,2,AIR:0)
Block(-3,3,3,MOSSY_COBBLESTONE:0)
Block(-3,3,4,MOSSY_COBBLESTONE:0)
Block(-3,3,5,MOSSY_COBBLESTONE:0)
Block(-3,3,6,MOSSY_COBBLESTONE:0)
Block(-3,3,7,MOSSY_COBBLESTONE:0)
Block(-3,3,8,MOSSY_COBBLESTONE:0)
Block(-3,4,-7,dimstack:bedrock:7)
Block(-3,4,-6,MOSSY_COBBLESTONE:0)
Block(-3,4,-5,MOSSY_COBBLESTONE:0)
Block(-3,4,-4,MOSSY_COBBLESTONE:0)
Block(-3,4,-3,MOSSY_COBBLESTONE:0)
Block(-3,4,-2,COBBLESTONE:0)
Block(-3,4,-1,MOSSY_COBBLESTONE:0)
Block(-3,4,0,MOSSY_COBBLESTONE:0)
Block(-3,4,1,MOSSY_COBBLESTONE:0)
Block(-3,4,2,MOSSY_COBBLESTONE:0)
Block(-3,4,3,MOSSY_COBBLESTONE:0)
Block(-3,4,4,MOSSY_COBBLESTONE:0)
Block(-3,4,5,MOSSY_COBBLESTONE:0)
Block(-3,4,6,MOSSY_COBBLESTONE:0)
Block(-3,4,7,MOSSY_COBBLESTONE:0)
Block(-3,4,8,MOSSY_COBBLESTONE:0)
Block(-3,5,-7,dimstack:bedrock:7)
Block(-3,5,-6,dimstack:bedrock:7)
Block(-3,5,-5,dimstack:bedrock:7)
Block(-3,5,-4,dimstack:bedrock:7)
Block(-3,5,-3,dimstack:bedrock:7)
Block(-3,5,-2,dimstack:bedrock:7)
Block(-3,5,-1,dimstack:bedrock:7)
Block(-3,5,0,dimstack:bedrock:7)
Block(-3,5,1,dimstack:bedrock:7)
Block(-3,5,2,dimstack:bedrock:7)
Block(-3,5,3,dimstack:bedrock:7)
Block(-3,5,4,dimstack:bedrock:7)
Block(-3,5,5,dimstack:bedrock:7)
Block(-3,5,6,dimstack:bedrock:7)
Block(-3,5,7,dimstack:bedrock:7)
Block(-3,5,8,dimstack:bedrock:7)
Block(-3,13,-4,DIRT:0)
Block(-3,13,-2,DIRT:0)
Block(-3,14,-4,AIR:0)
Block(-3,14,-2,AIR:0)
Block(-3,14,7,DIRT:0)
Block(-3,15,-4,AIR:0)
Block(-3,15,-2,AIR:0)
Block(-3,15,2,MOSSY_COBBLESTONE:0)
Block(-3,15,3,COBBLESTONE:0)
Block(-3,15,4,MOSSY_COBBLESTONE:0)
Block(-3,15,5,MOSSY_COBBLESTONE:0)
Block(-3,15,6,MOSSY_COBBLESTONE:0)
Block(-3,16,-4,AIR:0)
Block(-3,16,-2,AIR:0)
Block(-3,16,2,COBBLESTONE:0)
Block(-3,16,3,AIR:0)
Block(-3,16,4,AIR:0)
Block(-3,16,5,AIR:0)
Block(-3,16,6,MOSSY_COBBLESTONE:0)
Block(-3,17,2,MOSSY_COBBLESTONE:0)
Block(-3,17,3,AIR:0)
Block(-3,17,4,AIR:0)
Block(-3,17,5,AIR:0)
Block(-3,17,6,MOSSY_COBBLESTONE:0)
Block(-3,18,2,MOSSY_COBBLESTONE:0)
Block(-3,18,3,AIR:0)
Block(-3,18,4,AIR:0)
Block(-3,18,5,AIR:0)
Block(-3,18,6,MOSSY_COBBLESTONE:0)
Block(-3,19,3,AIR:0)
Block(-3,19,4,AIR:0)
Block(-3,19,5,AIR:0)
Block(-3,20,3,AIR:0)
Block(-3,20,4,AIR:0)
Block(-3,20,5,AIR:0)
Block(-3,21,2,MOSSY_COBBLESTONE:0)
Block(-3,21,3,MOSSY_COBBLESTONE:0)
Block(-3,21,4,MOSSY_COBBLESTONE:0)
Block(-3,21,5,MOSSY_COBBLESTONE:0)
Block(-3,21,6,MOSSY_COBBLESTONE:0)
Block(-3,22,2,MOSSY_COBBLESTONE:0)
Block(-3,22,3,MOSSY_COBBLESTONE:0)
Block(-3,22,4,MOSSY_COBBLESTONE:0)
Block(-3,22,5,MOSSY_COBBLESTONE:0)
Block(-3,22,6,MOSSY_COBBLESTONE:0)
Block(-3,23,1,MOSSY_COBBLESTONE:0)
Block(-3,23,2,MOSSY_COBBLESTONE:0)
Block(-3,23,3,MOSSY_COBBLESTONE:0)
Block(-3,23,5,MOSSY_COBBLESTONE:0)
Block(-3,23,6,MOSSY_COBBLESTONE:0)
Block(-3,23,7,MOSSY_COBBLESTONE:0)
Block(-3,24,1,MOSSY_COBBLESTONE:0)
Block(-3,24,2,MOSSY_COBBLESTONE:0)
Block(-3,24,3,MOSSY_COBBLESTONE:0)
Block(-3,24,5,MOSSY_COBBLESTONE:0)
Block(-3,24,6,MOSSY_COBBLESTONE:0)
Block(-3,24,7,MOSSY_COBBLESTONE:0)
Block(-3,25,0,MOSSY_COBBLESTONE:0)
Block(-3,25,1,COBBLESTONE:0)
Block(-3,25,2,MOSSY_COBBLESTONE:0)
Block(-3,25,3,MOSSY_COBBLESTONE:0)
Block(-3,25,4,MOSSY_COBBLESTONE:0)
Block(-3,25,5,MOSSY_COBBLESTONE:0)
Block(-3,25,6,MOSSY_COBBLESTONE:0)
Block(-3,25,7,COBBLESTONE:0)
Block(-3,25,8,MOSSY_COBBLESTONE:0)
Block(-3,26,0,MOSSY_COBBLESTONE:0)
Block(-3,26,1,STATIONARY_LAVA:0)
Block(-3,26,2,STATIONARY_LAVA:0)
Block(-3,26,3,STATIONARY_LAVA:0)
Block(-3,26,4,MOSSY_COBBLESTONE:0)
Block(-3,26,5,STATIONARY_LAVA:0)
Block(-3,26,6,STATIONARY_LAVA:0)
Block(-3,26,7,STATIONARY_LAVA:0)
Block(-3,26,8,MOSSY_COBBLESTONE:0)
Block(-3,27,0,MOSSY_COBBLESTONE:0)
Block(-3,27,1,STATIONARY_LAVA:0)
Block(-3,27,2,MOSSY_COBBLESTONE:0)
Block(-3,27,3,MOSSY_COBBLESTONE:0)
Block(-3,27,4,MOSSY_COBBLESTONE:0)
Block(-3,27,5,MOSSY_COBBLESTONE:0)
Block(-3,27,6,COBBLESTONE:0)
Block(-3,27,7,STATIONARY_LAVA:0)
Block(-3,27,8,MOSSY_COBBLESTONE:0)
Block(-3,28,0,MOSSY_COBBLESTONE:0)
Block(-3,28,1,MOSSY_COBBLESTONE:0)
Block(-3,28,2,MOSSY_COBBLESTONE:0)
Block(-3,28,3,COBBLESTONE:0)
Block(-3,28,4,MOSSY_COBBLESTONE:0)
Block(-3,28,5,MOSSY_COBBLESTONE:0)
Block(-3,28,6,COBBLESTONE:0)
Block(-3,28,7,MOSSY_COBBLESTONE:0)
Block(-3,28,8,MOSSY_COBBLESTONE:0)
Block(-2,0,-7,dimstack:bedrock:7)
Block(-2,0,-6,dimstack:bedrock:7)
Block(-2,0,-5,dimstack:bedrock:7)
Block(-2,0,-4,dimstack:bedrock:7)
Block(-2,0,-3,dimstack:bedrock:7)
Block(-2,0,-2,dimstack:bedrock:7)
Block(-2,0,-1,dimstack:bedrock:7)
Block(-2,0,0,dimstack:bedrock:7)
Block(-2,0,1,dimstack:bedrock:7)
Block(-2,0,2,dimstack:bedrock:7)
Block(-2,0,3,dimstack:bedrock:7)
Block(-2,0,4,dimstack:bedrock:7)
Block(-2,0,5,dimstack:bedrock:7)
Block(-2,0,6,dimstack:bedrock:7)
Block(-2,0,7,dimstack:bedrock:7)
Block(-2,0,8,dimstack:bedrock:7)
Block(-2,1,-7,dimstack:bedrock:7)
Block(-2,1,-6,dimstack:bedrock:7)
Block(-2,1,-5,dimstack:bedrock:7)
Block(-2,1,-4,dimstack:bedrock:7)
Block(-2,1,-3,dimstack:bedrock:7)
Block(-2,1,-2,dimstack:bedrock:7)
Block(-2,1,-1,dimstack:bedrock:7)
Block(-2,1,0,dimstack:bedrock:7)
Block(-2,1,1,dimstack:bedrock:7)
Block(-2,1,2,dimstack:bedrock:7)
Block(-2,1,3,dimstack:bedrock:7)
Block(-2,1,4,dimstack:bedrock:7)
Block(-2,1,5,dimstack:bedrock:7)
Block(-2,1,6,dimstack:bedrock:7)
Block(-2,1,7,dimstack:bedrock:7)
Block(-2,1,8,dimstack:bedrock:7)
Block(-2,2,-7,dimstack:bedrock:7)
Block(-2,2,-6,dimstack:bedrock:7)
Block(-2,2,-5,dimstack:bedrock:7)
Block(-2,2,-4,dimstack:bedrock:7)
Block(-2,2,-3,dimstack:bedrock:7)
Block(-2,2,-2,dimstack:bedrock:7)
Block(-2,2,-1,dimstack:bedrock:7)
Block(-2,2,0,dimstack:bedrock:7)
Block(-2,2,1,dimstack:bedrock:7)
Block(-2,2,2,dimstack:bedrock:7)
Block(-2,2,3,dimstack:bedrock:7)
Block(-2,2,4,dimstack:bedrock:7)
Block(-2,2,5,dimstack:bedrock:7)
Block(-2,2,6,dimstack:bedrock:7)
Block(-2,2,7,dimstack:bedrock:7)
Block(-2,2,8,dimstack:bedrock:7)
Block(-2,3,-7,dimstack:bedrock:7)
Block(-2,3,-6,dimstack:bedrock:7)
Block(-2,3,-5,dimstack:bedrock:7)
Block(-2,3,-4,dimstack:bedrock:7)
Block(-2,3,-3,dimstack:bedrock:7)
Block(-2,3,-2,dimstack:bedrock:7)
Block(-2,3,-1,dimstack:bedrock:7)
Block(-2,3,0,dimstack:bedrock:7)
Block(-2,3,1,dimstack:bedrock:7)
Block(-2,3,2,dimstack:bedrock:7)
Block(-2,3,3,dimstack:bedrock:7)
Block(-2,3,4,dimstack:bedrock:7)
Block(-2,3,5,dimstack:bedrock:7)
Block(-2,3,6,dimstack:bedrock:7)
Block(-2,3,7,dimstack:bedrock:7)
Block(-2,3,8,dimstack:bedrock:7)
Block(-2,4,-7,dimstack:bedrock:7)
Block(-2,4,-6,dimstack:bedrock:7)
Block(-2,4,-5,dimstack:bedrock:7)
Block(-2,4,-4,dimstack:bedrock:7)
Block(-2,4,-3,dimstack:bedrock:7)
Block(-2,4,-2,dimstack:bedrock:7)
Block(-2,4,-1,dimstack:bedrock:7)
Block(-2,4,0,dimstack:bedrock:7)
Block(-2,4,1,dimstack:bedrock:7)
Block(-2,4,2,dimstack:bedrock:7)
Block(-2,4,3,dimstack:bedrock:7)
Block(-2,4,4,dimstack:bedrock:7)
Block(-2,4,5,dimstack:bedrock:7)
Block(-2,4,6,dimstack:bedrock:7)
Block(-2,4,7,dimstack:bedrock:7)
Block(-2,4,8,dimstack:bedrock:7)
Block(-2,5,-7,dimstack:bedrock:7)
Block(-2,5,-6,dimstack:bedrock:7)
Block(-2,5,-5,dimstack:bedrock:7)
Block(-2,5,-4,dimstack:bedrock:7)
Block(-2,5,-3,dimstack:bedrock:7)
Block(-2,5,-2,dimstack:bedrock:7)
Block(-2,5,-1,dimstack:bedrock:7)
Block(-2,5,0,dimstack:bedrock:7)
Block(-2,5,1,dimstack:bedrock:7)
Block(-2,5,2,dimstack:bedrock:7)
Block(-2,5,3,dimstack:bedrock:7)
Block(-2,5,4,dimstack:bedrock:7)
Block(-2,5,5,dimstack:bedrock:7)
Block(-2,5,6,dimstack:bedrock:7)
Block(-2,5,7,dimstack:bedrock:7)
Block(-2,5,8,dimstack:bedrock:7)
Block(-2,13,-4,DIRT:0)
Block(-2,13,-2,DIRT:0)
Block(-2,14,-4,AIR:0)
Block(-2,14,-2,AIR:0)
Block(-2,15,-4,AIR:0)
Block(-2,15,-2,AIR:0)
Block(-2,15,3,MOSSY_COBBLESTONE:0)
Block(-2,15,4,COBBLESTONE:0)
Block(-2,15,5,COBBLESTONE:0)
Block(-2,16,-4,AIR:0)
Block(-2,16,-2,AIR:0)
Block(-2,16,3,MOSSY_COBBLESTONE:0)
Block(-2,16,4,MOSSY_COBBLESTONE:0)
Block(-2,16,5,MOSSY_COBBLESTONE:0)
Block(-2,17,3,AIR:0)
Block(-2,17,4,AIR:0)
Block(-2,17,5,AIR:0)
Block(-2,18,3,AIR:0)
Block(-2,18,4,AIR:0)
Block(-2,18,5,AIR:0)
Block(-2,19,3,AIR:0)
Block(-2,19,4,AIR:0)
Block(-2,19,5,AIR:0)
Block(-2,20,3,MOSSY_COBBLESTONE:0)
Block(-2,20,4,AIR:0)
Block(-2,20,5,MOSSY_COBBLESTONE:0)
Block(-2,21,3,MOSSY_COBBLESTONE:0)
Block(-2,21,4,MOSSY_COBBLESTONE:0)
Block(-2,21,5,MOSSY_COBBLESTONE:0)
Block(-2,22,3,MOSSY_COBBLESTONE:0)
Block(-2,22,4,COBBLESTONE:0)
Block(-2,22,5,MOSSY_COBBLESTONE:0)
Block(-2,23,2,COBBLESTONE:0)
Block(-2,23,3,MOSSY_COBBLESTONE:0)
Block(-2,23,5,MOSSY_COBBLESTONE:0)
Block(-2,23,6,MOSSY_COBBLESTONE:0)
Block(-2,24,2,MOSSY_COBBLESTONE:0)
Block(-2,24,3,MOSSY_COBBLESTONE:0)
Block(-2,24,5,MOSSY_COBBLESTONE:0)
Block(-2,24,6,MOSSY_COBBLESTONE:0)
Block(-2,25,1,MOSSY_COBBLESTONE:0)
Block(-2,25,2,MOSSY_COBBLESTONE:0)
Block(-2,25,3,MOSSY_COBBLESTONE:0)
Block(-2,25,4,MOSSY_COBBLESTONE:0)
Block(-2,25,5,MOSSY_COBBLESTONE:0)
Block(-2,25,6,MOSSY_COBBLESTONE:0)
Block(-2,25,7,MOSSY_COBBLESTONE:0)
Block(-2,26,4,MOSSY_COBBLESTONE:0)
Block(-2,27,2,COBBLESTONE:0)
Block(-2,27,3,MOSSY_COBBLESTONE:0)
Block(-2,27,4,MOSSY_COBBLESTONE:0)
Block(-2,27,5,MOSSY_COBBLESTONE:0)
Block(-2,27,6,MOSSY_COBBLESTONE:0)
Block(-2,28,0,MOSSY_COBBLESTONE:0)
Block(-2,28,1,MOSSY_COBBLESTONE:0)
Block(-2,28,2,MOSSY_COBBLESTONE:0)
Block(-2,28,3,MOSSY_COBBLESTONE:0)
Block(-2,28,4,MOSSY_COBBLESTONE:0)
Block(-2,28,5,MOSSY_COBBLESTONE:0)
Block(-2,28,6,MOSSY_COBBLESTONE:0)
Block(-2,28,7,MOSSY_COBBLESTONE:0)

#######################################################################
# +-----------------------------------------------------------------+ #
# |                             Branches                            | #
# +-----------------------------------------------------------------+ #
#######################################################################

Branch(0,0,16,true,FlamingSkullHouseC1R1,NORTH,100.0,0)

#######################################################################
# +-----------------------------------------------------------------+ #
# |                             Entities                            | #
# +-----------------------------------------------------------------+ #
#######################################################################


#######################################################################
# +-----------------------------------------------------------------+ #
# |                            Particles                            | #
# +-----------------------------------------------------------------+ #
#######################################################################


#######################################################################
# +-----------------------------------------------------------------+ #
# |                             Spawners                            | #
# +-----------------------------------------------------------------+ #
#######################################################################


#######################################################################
# +-----------------------------------------------------------------+ #
# |                             ModData                             | #
# +-----------------------------------------------------------------+ #
#######################################################################

