
#######################################################################
# +-----------------------------------------------------------------+ #
# |                            BO4 object                           | #
# +-----------------------------------------------------------------+ #
#######################################################################

Author: NLBlackEagle

Description: No description given

SettingsMode: WriteWithoutComments


#######################################################################
# +-----------------------------------------------------------------+ #
# |                          Main settings                          | #
# +-----------------------------------------------------------------+ #
#######################################################################

FixedRotation: 

Frequency: 0

SpawnHeight: highestBlock

UseCenterForHighestBlock: true

##############################
# Height Limits for the BO4. #
##############################

MinHeight: 0

MaxHeight: 255

InheritBO3: 

InheritBO3Rotation: NORTH

OverrideChildSettings: true

OverrideParentHeight: false

CanOverride: true

BranchFrequency: 0

BranchFrequencyGroup: 

MustBeBelowOther: false

MustBeInside: 

CannotBeInside: 

ReplacesBO3: 

MustBeInsideWorldBorders: false

CanSpawnOnWater: true

SpawnOnWaterOnly: false

SpawnUnderWater: false

SpawnAtWaterLevel: false

HeightOffset: 0

RemoveAir: false

ReplaceAbove: 

ReplaceBelow: 

ReplaceWithBiomeBlocks: false

ReplaceWithSurfaceBlock: GRASS

ReplaceWithGroundBlock: DIRT

ReplaceWithStoneBlock: STONE

SmoothRadius: 0

SmoothHeightOffset: 0

SmoothStartTop: false

SmoothStartWood: false

SmoothingSurfaceBlock: 

SmoothingGroundBlock: 

BO3Group: 

IsSpawnPoint: false

DoReplaceBlocks: true


#######################################################################
# +-----------------------------------------------------------------+ #
# |                              Blocks                             | #
# +-----------------------------------------------------------------+ #
#######################################################################

Block(-8,0,-7,dimstack:bedrock:7)
Block(-8,0,-6,dimstack:bedrock:7)
Block(-8,0,-5,dimstack:bedrock:7)
Block(-8,0,-4,dimstack:bedrock:7)
Block(-8,0,-3,dimstack:bedrock:7)
Block(-8,0,-2,dimstack:bedrock:7)
Block(-8,0,-1,dimstack:bedrock:7)
Block(-8,1,-7,dimstack:bedrock:7)
Block(-8,1,-6,dimstack:bedrock:7)
Block(-8,1,-5,dimstack:bedrock:7)
Block(-8,1,-4,dimstack:bedrock:7)
Block(-8,1,-3,dimstack:bedrock:7)
Block(-8,1,-2,dimstack:bedrock:7)
Block(-8,1,-1,dimstack:bedrock:7)
Block(-8,2,-7,dimstack:bedrock:7)
Block(-8,2,-6,dimstack:bedrock:7)
Block(-8,2,-5,dimstack:bedrock:7)
Block(-8,2,-4,dimstack:bedrock:7)
Block(-8,2,-3,dimstack:bedrock:7)
Block(-8,2,-2,dimstack:bedrock:7)
Block(-8,2,-1,dimstack:bedrock:7)
Block(-8,3,-7,dimstack:bedrock:7)
Block(-8,3,-6,dimstack:bedrock:7)
Block(-8,3,-5,dimstack:bedrock:7)
Block(-8,3,-4,dimstack:bedrock:7)
Block(-8,3,-3,dimstack:bedrock:7)
Block(-8,3,-2,dimstack:bedrock:7)
Block(-8,3,-1,dimstack:bedrock:7)
Block(-8,4,-7,dimstack:bedrock:7)
Block(-8,4,-6,dimstack:bedrock:7)
Block(-8,4,-5,dimstack:bedrock:7)
Block(-8,4,-4,dimstack:bedrock:7)
Block(-8,4,-3,dimstack:bedrock:7)
Block(-8,4,-2,dimstack:bedrock:7)
Block(-8,4,-1,dimstack:bedrock:7)
Block(-8,5,-7,dimstack:bedrock:7)
Block(-8,5,-6,dimstack:bedrock:7)
Block(-8,5,-5,dimstack:bedrock:7)
Block(-8,5,-4,dimstack:bedrock:7)
Block(-8,5,-3,dimstack:bedrock:7)
Block(-8,5,-2,dimstack:bedrock:7)
Block(-8,5,-1,dimstack:bedrock:7)
Block(-7,0,-7,dimstack:bedrock:7)
Block(-7,0,-6,dimstack:bedrock:7)
Block(-7,0,-5,dimstack:bedrock:7)
Block(-7,0,-4,dimstack:bedrock:7)
Block(-7,0,-3,dimstack:bedrock:7)
Block(-7,0,-2,dimstack:bedrock:7)
Block(-7,0,-1,dimstack:bedrock:7)
Block(-7,1,-7,AIR:0)
Block(-7,1,-6,AIR:0)
Block(-7,1,-5,AIR:0)
Block(-7,1,-4,AIR:0)
Block(-7,1,-3,AIR:0)
Block(-7,1,-2,AIR:0)
Block(-7,1,-1,dimstack:bedrock:7)
Block(-7,2,-7,AIR:0)
Block(-7,2,-6,AIR:0)
Block(-7,2,-5,AIR:0)
Block(-7,2,-4,AIR:0)
Block(-7,2,-3,AIR:0)
Block(-7,2,-2,AIR:0)
Block(-7,2,-1,dimstack:bedrock:7)
Block(-7,3,-7,AIR:0)
Block(-7,3,-6,AIR:0)
Block(-7,3,-5,AIR:0)
Block(-7,3,-4,AIR:0)
Block(-7,3,-3,AIR:0)
Block(-7,3,-2,AIR:0)
Block(-7,3,-1,dimstack:bedrock:7)
Block(-7,4,-7,MOSSY_COBBLESTONE:0)
Block(-7,4,-6,COBBLESTONE:0)
Block(-7,4,-5,MOSSY_COBBLESTONE:0)
Block(-7,4,-4,MOSSY_COBBLESTONE:0)
Block(-7,4,-3,MOSSY_COBBLESTONE:0)
Block(-7,4,-2,MOSSY_COBBLESTONE:0)
Block(-7,4,-1,dimstack:bedrock:7)
Block(-7,5,-7,dimstack:bedrock:7)
Block(-7,5,-6,dimstack:bedrock:7)
Block(-7,5,-5,dimstack:bedrock:7)
Block(-7,5,-4,dimstack:bedrock:7)
Block(-7,5,-3,dimstack:bedrock:7)
Block(-7,5,-2,dimstack:bedrock:7)
Block(-7,5,-1,dimstack:bedrock:7)
Block(-7,14,-5,GRASS:0)
Block(-6,0,-7,dimstack:bedrock:7)
Block(-6,0,-6,dimstack:bedrock:7)
Block(-6,0,-5,dimstack:bedrock:7)
Block(-6,0,-4,dimstack:bedrock:7)
Block(-6,0,-3,dimstack:bedrock:7)
Block(-6,0,-2,dimstack:bedrock:7)
Block(-6,0,-1,dimstack:bedrock:7)
Block(-6,1,-7,dimstack:bedrock:7)
Block(-6,1,-6,MOSSY_COBBLESTONE:0)
Block(-6,1,-5,MOSSY_COBBLESTONE:0)
Block(-6,1,-4,MOSSY_COBBLESTONE:0)
Block(-6,1,-3,MOSSY_COBBLESTONE:0)
Block(-6,1,-2,MOSSY_COBBLESTONE:0)
Block(-6,1,-1,dimstack:bedrock:7)
Block(-6,2,-7,dimstack:bedrock:7)
Block(-6,2,-6,COBBLESTONE:0)
Block(-6,2,-5,MOSSY_COBBLESTONE:0)
Block(-6,2,-4,MOSSY_COBBLESTONE:0)
Block(-6,2,-3,MOSSY_COBBLESTONE:0)
Block(-6,2,-2,MOSSY_COBBLESTONE:0)
Block(-6,2,-1,dimstack:bedrock:7)
Block(-6,3,-7,dimstack:bedrock:7)
Block(-6,3,-6,MOSSY_COBBLESTONE:0)
Block(-6,3,-5,MOSSY_COBBLESTONE:0)
Block(-6,3,-4,MOSSY_COBBLESTONE:0)
Block(-6,3,-3,COBBLESTONE:0)
Block(-6,3,-2,MOSSY_COBBLESTONE:0)
Block(-6,3,-1,dimstack:bedrock:7)
Block(-6,4,-7,MOSSY_COBBLESTONE:0)
Block(-6,4,-6,MOSSY_COBBLESTONE:0)
Block(-6,4,-5,COBBLESTONE:0)
Block(-6,4,-4,MOSSY_COBBLESTONE:0)
Block(-6,4,-3,MOSSY_COBBLESTONE:0)
Block(-6,4,-2,MOSSY_COBBLESTONE:0)
Block(-6,4,-1,dimstack:bedrock:7)
Block(-6,5,-7,dimstack:bedrock:7)
Block(-6,5,-6,dimstack:bedrock:7)
Block(-6,5,-5,dimstack:bedrock:7)
Block(-6,5,-4,dimstack:bedrock:7)
Block(-6,5,-3,dimstack:bedrock:7)
Block(-6,5,-2,dimstack:bedrock:7)
Block(-6,5,-1,dimstack:bedrock:7)
Block(-6,6,-7,MOSSY_COBBLESTONE:0)
Block(-6,6,-6,MOSSY_COBBLESTONE:0)
Block(-6,6,-5,MOSSY_COBBLESTONE:0)
Block(-6,6,-4,MOSSY_COBBLESTONE:0)
Block(-6,6,-3,MOSSY_COBBLESTONE:0)
Block(-6,6,-2,MOSSY_COBBLESTONE:0)
Block(-6,7,-7,MOSSY_COBBLESTONE:0)
Block(-6,7,-6,MOSSY_COBBLESTONE:0)
Block(-6,7,-5,MOSSY_COBBLESTONE:0)
Block(-6,7,-4,MOSSY_COBBLESTONE:0)
Block(-6,7,-3,MOSSY_COBBLESTONE:0)
Block(-6,7,-2,MOSSY_COBBLESTONE:0)
Block(-6,8,-7,COBBLESTONE:0)
Block(-6,8,-6,MOSSY_COBBLESTONE:0)
Block(-6,8,-5,COBBLESTONE:0)
Block(-6,8,-4,MOSSY_COBBLESTONE:0)
Block(-6,8,-3,MOSSY_COBBLESTONE:0)
Block(-6,8,-2,MOSSY_COBBLESTONE:0)
Block(-6,9,-7,MOSSY_COBBLESTONE:0)
Block(-6,9,-6,MOSSY_COBBLESTONE:0)
Block(-6,9,-5,COBBLESTONE:0)
Block(-6,9,-4,MOSSY_COBBLESTONE:0)
Block(-6,9,-3,MOSSY_COBBLESTONE:0)
Block(-6,9,-2,MOSSY_COBBLESTONE:0)
Block(-6,12,-7,MOSSY_COBBLESTONE:0)
Block(-6,12,-6,MOSSY_COBBLESTONE:0)
Block(-6,12,-5,MOSSY_COBBLESTONE:0)
Block(-6,12,-4,MOSSY_COBBLESTONE:0)
Block(-6,12,-3,MOSSY_COBBLESTONE:0)
Block(-6,12,-2,MOSSY_COBBLESTONE:0)
Block(-6,14,-7,GRASS:0)
Block(-6,14,-6,GRASS:0)
Block(-6,14,-3,DIRT:0)
Block(-5,0,-7,dimstack:bedrock:7)
Block(-5,0,-6,dimstack:bedrock:7)
Block(-5,0,-5,dimstack:bedrock:7)
Block(-5,0,-4,dimstack:bedrock:7)
Block(-5,0,-3,dimstack:bedrock:7)
Block(-5,0,-2,dimstack:bedrock:7)
Block(-5,0,-1,dimstack:bedrock:7)
Block(-5,1,-7,dimstack:bedrock:7)
Block(-5,1,-6,MOSSY_COBBLESTONE:0)
Block(-5,1,-5,MOSSY_COBBLESTONE:0)
Block(-5,1,-4,MOSSY_COBBLESTONE:0)
Block(-5,1,-3,MOSSY_COBBLESTONE:0)
Block(-5,1,-2,MOSSY_COBBLESTONE:0)
Block(-5,1,-1,dimstack:bedrock:7)
Block(-5,2,-7,dimstack:bedrock:7)
Block(-5,2,-6,MOSSY_COBBLESTONE:0)
Block(-5,2,-5,AIR:0)
Block(-5,2,-4,MOSSY_COBBLESTONE:0)
Block(-5,2,-3,AIR:0)
Block(-5,2,-2,MOSSY_COBBLESTONE:0)
Block(-5,2,-1,dimstack:bedrock:7)
Block(-5,3,-7,dimstack:bedrock:7)
Block(-5,3,-6,COBBLESTONE:0)
Block(-5,3,-5,MOSSY_COBBLESTONE:0)
Block(-5,3,-4,AIR:0)
Block(-5,3,-3,AIR:0)
Block(-5,3,-2,COBBLESTONE:0)
Block(-5,3,-1,dimstack:bedrock:7)
Block(-5,4,-7,MOSSY_COBBLESTONE:0)
Block(-5,4,-6,MOSSY_COBBLESTONE:0)
Block(-5,4,-5,AIR:0)
Block(-5,4,-4,AIR:0)
Block(-5,4,-3,AIR:0)
Block(-5,4,-2,MOSSY_COBBLESTONE:0)
Block(-5,4,-1,dimstack:bedrock:7)
Block(-5,5,-7,MOSSY_COBBLESTONE:0)
Block(-5,5,-6,AIR:0)
Block(-5,5,-5,AIR:0)
Block(-5,5,-4,AIR:0)
Block(-5,5,-3,AIR:0)
Block(-5,5,-2,MOSSY_COBBLESTONE:0)
Block(-5,5,-1,dimstack:bedrock:7)
Block(-5,6,-7,AIR:0)
Block(-5,6,-6,AIR:0)
Block(-5,6,-5,AIR:0)
Block(-5,6,-4,AIR:0)
Block(-5,6,-3,AIR:0)
Block(-5,6,-2,MOSSY_COBBLESTONE:0)
Block(-5,7,-7,AIR:0)
Block(-5,7,-6,AIR:0)
Block(-5,7,-5,AIR:0)
Block(-5,7,-4,AIR:0)
Block(-5,7,-3,AIR:0)
Block(-5,7,-2,MOSSY_COBBLESTONE:0)
Block(-5,8,-7,AIR:0)
Block(-5,8,-6,AIR:0)
Block(-5,8,-5,AIR:0)
Block(-5,8,-4,AIR:0)
Block(-5,8,-3,AIR:0)
Block(-5,8,-2,MOSSY_COBBLESTONE:0)
Block(-5,9,-7,MOSSY_COBBLESTONE:0)
Block(-5,9,-6,MOSSY_COBBLESTONE:0)
Block(-5,9,-5,MOSSY_COBBLESTONE:0)
Block(-5,9,-4,MOSSY_COBBLESTONE:0)
Block(-5,9,-3,MOSSY_COBBLESTONE:0)
Block(-5,9,-2,COBBLESTONE:0)
Block(-5,14,-7,GRASS:0)
Block(-5,14,-6,GRASS:0)
Block(-5,14,-5,GRASS:0)
Block(-4,0,-7,dimstack:bedrock:7)
Block(-4,0,-6,dimstack:bedrock:7)
Block(-4,0,-5,dimstack:bedrock:7)
Block(-4,0,-4,dimstack:bedrock:7)
Block(-4,0,-3,dimstack:bedrock:7)
Block(-4,0,-2,dimstack:bedrock:7)
Block(-4,0,-1,dimstack:bedrock:7)
Block(-4,1,-7,dimstack:bedrock:7)
Block(-4,1,-6,MOSSY_COBBLESTONE:0)
Block(-4,1,-5,MOSSY_COBBLESTONE:0)
Block(-4,1,-4,MOSSY_COBBLESTONE:0)
Block(-4,1,-3,MOSSY_COBBLESTONE:0)
Block(-4,1,-2,MOSSY_COBBLESTONE:0)
Block(-4,1,-1,dimstack:bedrock:7)
Block(-4,2,-7,dimstack:bedrock:7)
Block(-4,2,-6,MOSSY_COBBLESTONE:0)
Block(-4,2,-5,AIR:0)
Block(-4,2,-4,AIR:0)
Block(-4,2,-3,AIR:0)
Block(-4,2,-2,MOSSY_COBBLESTONE:0)
Block(-4,2,-1,dimstack:bedrock:7)
Block(-4,3,-7,dimstack:bedrock:7)
Block(-4,3,-6,MOSSY_COBBLESTONE:0)
Block(-4,3,-5,AIR:0)
Block(-4,3,-4,AIR:0)
Block(-4,3,-3,AIR:0)
Block(-4,3,-2,MOSSY_COBBLESTONE:0)
Block(-4,3,-1,dimstack:bedrock:7)
Block(-4,4,-7,COBBLESTONE:0)
Block(-4,4,-6,MOSSY_COBBLESTONE:0)
Block(-4,4,-5,MOSSY_COBBLESTONE:0)
Block(-4,4,-4,MOSSY_COBBLESTONE:0)
Block(-4,4,-3,AIR:0)
Block(-4,4,-2,MOSSY_COBBLESTONE:0)
Block(-4,4,-1,dimstack:bedrock:7)
Block(-4,5,-7,dimstack:bedrock:7)
Block(-4,5,-6,dimstack:bedrock:7)
Block(-4,5,-5,dimstack:bedrock:7)
Block(-4,5,-4,dimstack:bedrock:7)
Block(-4,5,-3,dimstack:bedrock:7)
Block(-4,5,-2,dimstack:bedrock:7)
Block(-4,5,-1,dimstack:bedrock:7)
Block(-4,6,-7,MOSSY_COBBLESTONE:0)
Block(-4,6,-6,MOSSY_COBBLESTONE:0)
Block(-4,6,-5,MOSSY_COBBLESTONE:0)
Block(-4,6,-4,COBBLESTONE:0)
Block(-4,6,-3,MOSSY_COBBLESTONE:0)
Block(-4,6,-2,MOSSY_COBBLESTONE:0)
Block(-4,7,-7,MOSSY_COBBLESTONE:0)
Block(-4,7,-6,COBBLESTONE:0)
Block(-4,7,-5,MOSSY_COBBLESTONE:0)
Block(-4,7,-4,MOSSY_COBBLESTONE:0)
Block(-4,7,-3,MOSSY_COBBLESTONE:0)
Block(-4,7,-2,MOSSY_COBBLESTONE:0)
Block(-4,8,-7,MOSSY_COBBLESTONE:0)
Block(-4,8,-6,COBBLESTONE:0)
Block(-4,8,-5,MOSSY_COBBLESTONE:0)
Block(-4,8,-4,MOSSY_COBBLESTONE:0)
Block(-4,8,-3,MOSSY_COBBLESTONE:0)
Block(-4,8,-2,MOSSY_COBBLESTONE:0)
Block(-4,9,-7,MOSSY_COBBLESTONE:0)
Block(-4,9,-6,COBBLESTONE:0)
Block(-4,9,-5,MOSSY_COBBLESTONE:0)
Block(-4,9,-4,MOSSY_COBBLESTONE:0)
Block(-4,9,-3,MOSSY_COBBLESTONE:0)
Block(-4,9,-2,COBBLESTONE:0)
Block(-4,14,-7,DIRT:0)
Block(-4,14,-6,DIRT:0)
Block(-4,14,-5,DIRT:0)
Block(-4,14,-4,GRASS:0)
Block(-4,15,-7,GRASS:0)
Block(-4,15,-6,GRASS:0)
Block(-4,15,-5,GRASS:0)
Block(-3,0,-7,dimstack:bedrock:7)
Block(-3,0,-6,dimstack:bedrock:7)
Block(-3,0,-5,dimstack:bedrock:7)
Block(-3,0,-4,dimstack:bedrock:7)
Block(-3,0,-3,dimstack:bedrock:7)
Block(-3,0,-2,dimstack:bedrock:7)
Block(-3,0,-1,dimstack:bedrock:7)
Block(-3,1,-7,dimstack:bedrock:7)
Block(-3,1,-6,MOSSY_COBBLESTONE:0)
Block(-3,1,-5,COBBLESTONE:0)
Block(-3,1,-4,MOSSY_COBBLESTONE:0)
Block(-3,1,-3,MOSSY_COBBLESTONE:0)
Block(-3,1,-2,MOSSY_COBBLESTONE:0)
Block(-3,1,-1,dimstack:bedrock:7)
Block(-3,2,-7,dimstack:bedrock:7)
Block(-3,2,-6,COBBLESTONE:0)
Block(-3,2,-5,MOB_SPAWNER:0,../../ruins_spawners/crypt_multi.nbt)
Block(-3,2,-4,AIR:0)
Block(-3,2,-3,AIR:0)
Block(-3,2,-2,MOSSY_COBBLESTONE:0)
Block(-3,2,-1,dimstack:bedrock:7)
Block(-3,3,-7,dimstack:bedrock:7)
Block(-3,3,-6,MOSSY_COBBLESTONE:0)
Block(-3,3,-5,AIR:0)
Block(-3,3,-4,AIR:0)
Block(-3,3,-3,AIR:0)
Block(-3,3,-2,MOSSY_COBBLESTONE:0)
Block(-3,3,-1,dimstack:bedrock:7)
Block(-3,4,-7,MOSSY_COBBLESTONE:0)
Block(-3,4,-6,MOSSY_COBBLESTONE:0)
Block(-3,4,-5,MOSSY_COBBLESTONE:0)
Block(-3,4,-4,MOSSY_COBBLESTONE:0)
Block(-3,4,-3,MOSSY_COBBLESTONE:0)
Block(-3,4,-2,MOSSY_COBBLESTONE:0)
Block(-3,4,-1,dimstack:bedrock:7)
Block(-3,5,-7,dimstack:bedrock:7)
Block(-3,5,-6,dimstack:bedrock:7)
Block(-3,5,-5,dimstack:bedrock:7)
Block(-3,5,-4,dimstack:bedrock:7)
Block(-3,5,-3,dimstack:bedrock:7)
Block(-3,5,-2,dimstack:bedrock:7)
Block(-3,5,-1,dimstack:bedrock:7)
Block(-3,12,-7,COBBLESTONE:0)
Block(-3,12,-6,MOSSY_COBBLESTONE:0)
Block(-3,12,-5,MOSSY_COBBLESTONE:0)
Block(-3,12,-4,MOSSY_COBBLESTONE:0)
Block(-3,12,-3,MOSSY_COBBLESTONE:0)
Block(-3,12,-2,COBBLESTONE:0)
Block(-3,14,-7,DIRT:0)
Block(-3,14,-6,DIRT:0)
Block(-3,14,-5,DIRT:0)
Block(-3,14,-4,DIRT:0)
Block(-3,15,-7,GRASS:0)
Block(-3,15,-6,GRASS:0)
Block(-3,15,-5,GRASS:0)
Block(-3,15,-4,GRASS:0)
Block(-2,0,-7,dimstack:bedrock:7)
Block(-2,0,-6,dimstack:bedrock:7)
Block(-2,0,-5,dimstack:bedrock:7)
Block(-2,0,-4,dimstack:bedrock:7)
Block(-2,0,-3,dimstack:bedrock:7)
Block(-2,0,-2,dimstack:bedrock:7)
Block(-2,0,-1,dimstack:bedrock:7)
Block(-2,1,-7,dimstack:bedrock:7)
Block(-2,1,-6,MOSSY_COBBLESTONE:0)
Block(-2,1,-5,MOSSY_COBBLESTONE:0)
Block(-2,1,-4,MOSSY_COBBLESTONE:0)
Block(-2,1,-3,MOSSY_COBBLESTONE:0)
Block(-2,1,-2,MOSSY_COBBLESTONE:0)
Block(-2,1,-1,dimstack:bedrock:7)
Block(-2,2,-7,dimstack:bedrock:7)
Block(-2,2,-6,MOSSY_COBBLESTONE:0)
Block(-2,2,-5,MOSSY_COBBLESTONE:0)
Block(-2,2,-4,MOSSY_COBBLESTONE:0)
Block(-2,2,-3,AIR:0)
Block(-2,2,-2,MOSSY_COBBLESTONE:0)
Block(-2,2,-1,dimstack:bedrock:7)
Block(-2,3,-7,dimstack:bedrock:7)
Block(-2,3,-6,COBBLESTONE:0)
Block(-2,3,-5,MOSSY_COBBLESTONE:0)
Block(-2,3,-4,MOSSY_COBBLESTONE:0)
Block(-2,3,-3,AIR:0)
Block(-2,3,-2,MOSSY_COBBLESTONE:0)
Block(-2,3,-1,dimstack:bedrock:7)
Block(-2,4,-7,MOSSY_COBBLESTONE:0)
Block(-2,4,-6,MOSSY_COBBLESTONE:0)
Block(-2,4,-5,MOSSY_COBBLESTONE:0)
Block(-2,4,-4,MOSSY_COBBLESTONE:0)
Block(-2,4,-3,MOSSY_COBBLESTONE:0)
Block(-2,4,-2,MOSSY_COBBLESTONE:0)
Block(-2,4,-1,dimstack:bedrock:7)
Block(-2,5,-7,dimstack:bedrock:7)
Block(-2,5,-6,dimstack:bedrock:7)
Block(-2,5,-5,dimstack:bedrock:7)
Block(-2,5,-4,dimstack:bedrock:7)
Block(-2,5,-3,dimstack:bedrock:7)
Block(-2,5,-2,dimstack:bedrock:7)
Block(-2,5,-1,dimstack:bedrock:7)
Block(-2,12,-7,COBBLESTONE:0)
Block(-2,12,-6,MOSSY_COBBLESTONE:0)
Block(-2,12,-5,COBBLESTONE:0)
Block(-2,12,-4,MOSSY_COBBLESTONE:0)
Block(-2,12,-3,MOSSY_COBBLESTONE:0)
Block(-2,12,-2,COBBLESTONE:0)
Block(-2,14,-7,DIRT:0)
Block(-2,14,-6,DIRT:0)
Block(-2,14,-5,DIRT:0)
Block(-2,14,-4,DIRT:0)
Block(-2,15,-7,GRASS:0)
Block(-2,15,-6,GRASS:0)
Block(-2,15,-5,GRASS:0)
Block(-2,15,-4,GRASS:0)
Block(-1,0,-7,dimstack:bedrock:7)
Block(-1,0,-6,dimstack:bedrock:7)
Block(-1,0,-5,dimstack:bedrock:7)
Block(-1,0,-4,dimstack:bedrock:7)
Block(-1,0,-3,dimstack:bedrock:7)
Block(-1,0,-2,dimstack:bedrock:7)
Block(-1,0,-1,dimstack:bedrock:7)
Block(-1,1,-7,dimstack:bedrock:7)
Block(-1,1,-6,AIR:0)
Block(-1,1,-5,AIR:0)
Block(-1,1,-4,AIR:0)
Block(-1,1,-3,MOSSY_COBBLESTONE:0)
Block(-1,1,-2,AIR:0)
Block(-1,1,-1,dimstack:bedrock:7)
Block(-1,2,-7,dimstack:bedrock:7)
Block(-1,2,-6,AIR:0)
Block(-1,2,-5,AIR:0)
Block(-1,2,-4,MOSSY_COBBLESTONE:0)
Block(-1,2,-3,AIR:0)
Block(-1,2,-2,MOSSY_COBBLESTONE:0)
Block(-1,2,-1,dimstack:bedrock:7)
Block(-1,3,-7,dimstack:bedrock:7)
Block(-1,3,-6,AIR:0)
Block(-1,3,-5,AIR:0)
Block(-1,3,-4,MOSSY_COBBLESTONE:0)
Block(-1,3,-3,AIR:0)
Block(-1,3,-2,COBBLESTONE:0)
Block(-1,3,-1,dimstack:bedrock:7)
Block(-1,4,-7,MOSSY_COBBLESTONE:0)
Block(-1,4,-6,MOSSY_COBBLESTONE:0)
Block(-1,4,-5,COBBLESTONE:0)
Block(-1,4,-4,MOSSY_COBBLESTONE:0)
Block(-1,4,-3,MOSSY_COBBLESTONE:0)
Block(-1,4,-2,MOSSY_COBBLESTONE:0)
Block(-1,4,-1,dimstack:bedrock:7)
Block(-1,5,-7,dimstack:bedrock:7)
Block(-1,5,-6,dimstack:bedrock:7)
Block(-1,5,-5,dimstack:bedrock:7)
Block(-1,5,-4,dimstack:bedrock:7)
Block(-1,5,-3,dimstack:bedrock:7)
Block(-1,5,-2,dimstack:bedrock:7)
Block(-1,5,-1,dimstack:bedrock:7)
Block(-1,14,-7,DIRT:0)
Block(-1,14,-6,MOSSY_COBBLESTONE:0)
Block(-1,14,-5,COBBLESTONE:0)
Block(-1,14,-4,DIRT:0)
Block(-1,15,-7,DIRT:0)
Block(-1,15,-6,DIRT:0)
Block(-1,15,-5,DIRT:0)
Block(-1,15,-4,GRASS:0)
Block(-1,16,-7,GRASS:0)
Block(-1,16,-6,GRASS:0)
Block(-1,16,-5,GRASS:0)
Block(0,0,-7,dimstack:bedrock:7)
Block(0,0,-6,dimstack:bedrock:7)
Block(0,0,-5,dimstack:bedrock:7)
Block(0,0,-4,dimstack:bedrock:7)
Block(0,0,-3,dimstack:bedrock:7)
Block(0,0,-2,dimstack:bedrock:7)
Block(0,0,-1,dimstack:bedrock:7)
Block(0,1,-7,AIR:0)
Block(0,1,-6,AIR:0)
Block(0,1,-5,AIR:0)
Block(0,1,-4,AIR:0)
Block(0,1,-3,MOSSY_COBBLESTONE:0)
Block(0,1,-2,AIR:0)
Block(0,1,-1,dimstack:bedrock:7)
Block(0,2,-7,AIR:0)
Block(0,2,-6,AIR:0)
Block(0,2,-5,AIR:0)
Block(0,2,-4,MOSSY_COBBLESTONE:0)
Block(0,2,-3,AIR:0)
Block(0,2,-2,MOSSY_COBBLESTONE:0)
Block(0,2,-1,dimstack:bedrock:7)
Block(0,3,-7,AIR:0)
Block(0,3,-6,AIR:0)
Block(0,3,-5,AIR:0)
Block(0,3,-4,MOSSY_COBBLESTONE:0)
Block(0,3,-3,AIR:0)
Block(0,3,-2,MOSSY_COBBLESTONE:0)
Block(0,3,-1,dimstack:bedrock:7)
Block(0,4,-7,MOSSY_COBBLESTONE:0)
Block(0,4,-6,MOSSY_COBBLESTONE:0)
Block(0,4,-5,MOSSY_COBBLESTONE:0)
Block(0,4,-4,MOSSY_COBBLESTONE:0)
Block(0,4,-3,MOSSY_COBBLESTONE:0)
Block(0,4,-2,MOSSY_COBBLESTONE:0)
Block(0,4,-1,dimstack:bedrock:7)
Block(0,5,-7,dimstack:bedrock:7)
Block(0,5,-6,dimstack:bedrock:7)
Block(0,5,-5,dimstack:bedrock:7)
Block(0,5,-4,dimstack:bedrock:7)
Block(0,5,-3,dimstack:bedrock:7)
Block(0,5,-2,dimstack:bedrock:7)
Block(0,5,-1,dimstack:bedrock:7)
Block(0,14,-7,DIRT:0)
Block(0,14,-6,MOSSY_COBBLESTONE:0)
Block(0,14,-5,MOSSY_COBBLESTONE:0)
Block(0,14,-4,DIRT:0)
Block(0,14,-2,DIRT:0)
Block(0,15,-7,DIRT:0)
Block(0,15,-6,MOSSY_COBBLESTONE:0)
Block(0,15,-5,MOSSY_COBBLESTONE:0)
Block(0,15,-4,GRASS:0)
Block(0,16,-7,GRASS:0)
Block(0,16,-6,GRASS:0)
Block(0,16,-5,GRASS:0)
Block(1,0,-7,dimstack:bedrock:7)
Block(1,0,-6,dimstack:bedrock:7)
Block(1,0,-5,dimstack:bedrock:7)
Block(1,0,-4,dimstack:bedrock:7)
Block(1,0,-3,dimstack:bedrock:7)
Block(1,0,-2,dimstack:bedrock:7)
Block(1,0,-1,dimstack:bedrock:7)
Block(1,1,-7,MOSSY_COBBLESTONE:0)
Block(1,1,-6,COBBLESTONE:0)
Block(1,1,-5,MOSSY_COBBLESTONE:0)
Block(1,1,-4,MOSSY_COBBLESTONE:0)
Block(1,1,-3,MOSSY_COBBLESTONE:0)
Block(1,1,-2,AIR:0)
Block(1,1,-1,dimstack:bedrock:7)
Block(1,2,-7,MOSSY_COBBLESTONE:0)
Block(1,2,-6,MOSSY_COBBLESTONE:0)
Block(1,2,-5,MOSSY_COBBLESTONE:0)
Block(1,2,-4,MOSSY_COBBLESTONE:0)
Block(1,2,-3,AIR:0)
Block(1,2,-2,MOSSY_COBBLESTONE:0)
Block(1,2,-1,dimstack:bedrock:7)
Block(1,3,-7,MOSSY_COBBLESTONE:0)
Block(1,3,-6,MOSSY_COBBLESTONE:0)
Block(1,3,-5,MOSSY_COBBLESTONE:0)
Block(1,3,-4,MOSSY_COBBLESTONE:0)
Block(1,3,-3,AIR:0)
Block(1,3,-2,MOSSY_COBBLESTONE:0)
Block(1,3,-1,dimstack:bedrock:7)
Block(1,4,-7,MOSSY_COBBLESTONE:0)
Block(1,4,-6,MOSSY_COBBLESTONE:0)
Block(1,4,-5,MOSSY_COBBLESTONE:0)
Block(1,4,-4,MOSSY_COBBLESTONE:0)
Block(1,4,-3,MOSSY_COBBLESTONE:0)
Block(1,4,-2,MOSSY_COBBLESTONE:0)
Block(1,4,-1,dimstack:bedrock:7)
Block(1,5,-7,dimstack:bedrock:7)
Block(1,5,-6,dimstack:bedrock:7)
Block(1,5,-5,dimstack:bedrock:7)
Block(1,5,-4,dimstack:bedrock:7)
Block(1,5,-3,dimstack:bedrock:7)
Block(1,5,-2,dimstack:bedrock:7)
Block(1,5,-1,dimstack:bedrock:7)
Block(1,14,-7,DIRT:0)
Block(1,14,-6,MOSSY_COBBLESTONE:0)
Block(1,14,-5,COBBLESTONE:0)
Block(1,14,-4,DIRT:0)
Block(1,15,-7,DIRT:0)
Block(1,15,-6,MOSSY_COBBLESTONE:0)
Block(1,15,-5,MOSSY_COBBLESTONE:0)
Block(1,15,-4,GRASS:0)
Block(1,16,-7,GRASS:0)
Block(1,16,-6,GRASS:0)
Block(2,0,-7,dimstack:bedrock:7)
Block(2,0,-6,dimstack:bedrock:7)
Block(2,0,-5,dimstack:bedrock:7)
Block(2,0,-4,dimstack:bedrock:7)
Block(2,0,-3,dimstack:bedrock:7)
Block(2,0,-2,dimstack:bedrock:7)
Block(2,0,-1,dimstack:bedrock:7)
Block(2,1,-7,COBBLESTONE:0)
Block(2,1,-6,MOSSY_COBBLESTONE:0)
Block(2,1,-5,MOSSY_COBBLESTONE:0)
Block(2,1,-4,MOSSY_COBBLESTONE:0)
Block(2,1,-3,MOSSY_COBBLESTONE:0)
Block(2,1,-2,AIR:0)
Block(2,1,-1,dimstack:bedrock:7)
Block(2,2,-7,AIR:0)
Block(2,2,-6,AIR:0)
Block(2,2,-5,AIR:0)
Block(2,2,-4,MOSSY_COBBLESTONE:0)
Block(2,2,-3,AIR:0)
Block(2,2,-2,MOSSY_COBBLESTONE:0)
Block(2,2,-1,dimstack:bedrock:7)
Block(2,3,-7,AIR:0)
Block(2,3,-6,AIR:0)
Block(2,3,-5,AIR:0)
Block(2,3,-4,MOSSY_COBBLESTONE:0)
Block(2,3,-3,AIR:0)
Block(2,3,-2,MOSSY_COBBLESTONE:0)
Block(2,3,-1,dimstack:bedrock:7)
Block(2,4,-7,MOSSY_COBBLESTONE:0)
Block(2,4,-6,COBBLESTONE:0)
Block(2,4,-5,MOSSY_COBBLESTONE:0)
Block(2,4,-4,MOSSY_COBBLESTONE:0)
Block(2,4,-3,MOSSY_COBBLESTONE:0)
Block(2,4,-2,MOSSY_COBBLESTONE:0)
Block(2,4,-1,dimstack:bedrock:7)
Block(2,5,-7,dimstack:bedrock:7)
Block(2,5,-6,dimstack:bedrock:7)
Block(2,5,-5,dimstack:bedrock:7)
Block(2,5,-4,dimstack:bedrock:7)
Block(2,5,-3,dimstack:bedrock:7)
Block(2,5,-2,dimstack:bedrock:7)
Block(2,5,-1,dimstack:bedrock:7)
Block(2,14,-7,DIRT:0)
Block(2,14,-4,DIRT:0)
Block(2,15,-7,DIRT:0)
Block(2,15,-6,MOSSY_COBBLESTONE:0)
Block(2,15,-5,MOSSY_COBBLESTONE:0)
Block(2,15,-4,GRASS:0)
Block(2,16,-7,GRASS:0)
Block(2,16,-6,COBBLESTONE:0)
Block(2,16,-5,COBBLESTONE:0)
Block(3,0,-7,dimstack:bedrock:7)
Block(3,0,-6,dimstack:bedrock:7)
Block(3,0,-5,dimstack:bedrock:7)
Block(3,0,-4,dimstack:bedrock:7)
Block(3,0,-3,dimstack:bedrock:7)
Block(3,0,-2,dimstack:bedrock:7)
Block(3,0,-1,dimstack:bedrock:7)
Block(3,1,-7,COBBLESTONE:0)
Block(3,1,-6,COBBLESTONE:0)
Block(3,1,-5,MOSSY_COBBLESTONE:0)
Block(3,1,-4,MOSSY_COBBLESTONE:0)
Block(3,1,-3,COBBLESTONE:0)
Block(3,1,-2,AIR:0)
Block(3,1,-1,dimstack:bedrock:7)
Block(3,2,-7,MOB_SPAWNER:0,../../ruins_spawners/crypt_multi.nbt)
Block(3,2,-6,AIR:0)
Block(3,2,-5,AIR:0)
Block(3,2,-4,MOSSY_COBBLESTONE:0)
Block(3,2,-3,AIR:0)
Block(3,2,-2,MOSSY_COBBLESTONE:0)
Block(3,2,-1,dimstack:bedrock:7)
Block(3,3,-7,AIR:0)
Block(3,3,-6,AIR:0)
Block(3,3,-5,AIR:0)
Block(3,3,-4,MOSSY_COBBLESTONE:0)
Block(3,3,-3,AIR:0)
Block(3,3,-2,COBBLESTONE:0)
Block(3,3,-1,dimstack:bedrock:7)
Block(3,4,-7,MOSSY_COBBLESTONE:0)
Block(3,4,-6,MOSSY_COBBLESTONE:0)
Block(3,4,-5,COBBLESTONE:0)
Block(3,4,-4,COBBLESTONE:0)
Block(3,4,-3,COBBLESTONE:0)
Block(3,4,-2,COBBLESTONE:0)
Block(3,4,-1,dimstack:bedrock:7)
Block(3,5,-7,dimstack:bedrock:7)
Block(3,5,-6,dimstack:bedrock:7)
Block(3,5,-5,dimstack:bedrock:7)
Block(3,5,-4,dimstack:bedrock:7)
Block(3,5,-3,dimstack:bedrock:7)
Block(3,5,-2,dimstack:bedrock:7)
Block(3,5,-1,dimstack:bedrock:7)
Block(3,14,-7,DIRT:0)
Block(3,14,-2,DIRT:0)
Block(3,15,-7,DIRT:0)
Block(3,16,-7,GRASS:0)
Block(3,16,-6,MOSSY_COBBLESTONE:0)
Block(3,16,-5,MOSSY_COBBLESTONE:0)
Block(3,17,-6,COBBLESTONE:0)
Block(3,17,-5,MOSSY_COBBLESTONE:0)
Block(4,0,-7,dimstack:bedrock:7)
Block(4,0,-6,dimstack:bedrock:7)
Block(4,0,-5,dimstack:bedrock:7)
Block(4,0,-4,dimstack:bedrock:7)
Block(4,0,-3,dimstack:bedrock:7)
Block(4,0,-2,dimstack:bedrock:7)
Block(4,0,-1,dimstack:bedrock:7)
Block(4,1,-7,MOSSY_COBBLESTONE:0)
Block(4,1,-6,MOSSY_COBBLESTONE:0)
Block(4,1,-5,COBBLESTONE:0)
Block(4,1,-4,COBBLESTONE:0)
Block(4,1,-3,MOSSY_COBBLESTONE:0)
Block(4,1,-2,AIR:0)
Block(4,1,-1,dimstack:bedrock:7)
Block(4,2,-7,AIR:0)
Block(4,2,-6,AIR:0)
Block(4,2,-5,AIR:0)
Block(4,2,-4,MOSSY_COBBLESTONE:0)
Block(4,2,-3,AIR:0)
Block(4,2,-2,COBBLESTONE:0)
Block(4,2,-1,dimstack:bedrock:7)
Block(4,3,-7,AIR:0)
Block(4,3,-6,AIR:0)
Block(4,3,-5,AIR:0)
Block(4,3,-4,COBBLESTONE:0)
Block(4,3,-3,AIR:0)
Block(4,3,-2,MOSSY_COBBLESTONE:0)
Block(4,3,-1,dimstack:bedrock:7)
Block(4,4,-7,MOSSY_COBBLESTONE:0)
Block(4,4,-6,MOSSY_COBBLESTONE:0)
Block(4,4,-5,COBBLESTONE:0)
Block(4,4,-4,COBBLESTONE:0)
Block(4,4,-3,MOSSY_COBBLESTONE:0)
Block(4,4,-2,MOSSY_COBBLESTONE:0)
Block(4,4,-1,dimstack:bedrock:7)
Block(4,5,-7,dimstack:bedrock:7)
Block(4,5,-6,dimstack:bedrock:7)
Block(4,5,-5,dimstack:bedrock:7)
Block(4,5,-4,dimstack:bedrock:7)
Block(4,5,-3,dimstack:bedrock:7)
Block(4,5,-2,dimstack:bedrock:7)
Block(4,5,-1,dimstack:bedrock:7)
Block(4,14,-7,DIRT:0)
Block(4,15,-7,GRASS:0)
Block(4,17,-6,MOSSY_COBBLESTONE:0)
Block(4,17,-5,MOSSY_COBBLESTONE:0)
Block(4,18,-6,MOSSY_COBBLESTONE:0)
Block(4,18,-5,MOSSY_COBBLESTONE:0)
Block(5,0,-7,dimstack:bedrock:7)
Block(5,0,-6,dimstack:bedrock:7)
Block(5,0,-5,dimstack:bedrock:7)
Block(5,0,-4,dimstack:bedrock:7)
Block(5,0,-3,dimstack:bedrock:7)
Block(5,0,-2,dimstack:bedrock:7)
Block(5,0,-1,dimstack:bedrock:7)
Block(5,1,-7,AIR:0)
Block(5,1,-6,AIR:0)
Block(5,1,-5,MOSSY_COBBLESTONE:0)
Block(5,1,-4,AIR:0)
Block(5,1,-3,MOSSY_COBBLESTONE:0)
Block(5,1,-2,AIR:0)
Block(5,1,-1,dimstack:bedrock:7)
Block(5,2,-7,MOSSY_COBBLESTONE:0)
Block(5,2,-6,MOSSY_COBBLESTONE:0)
Block(5,2,-5,AIR:0)
Block(5,2,-4,MOSSY_COBBLESTONE:0)
Block(5,2,-3,AIR:0)
Block(5,2,-2,MOSSY_COBBLESTONE:0)
Block(5,2,-1,dimstack:bedrock:7)
Block(5,3,-7,MOSSY_COBBLESTONE:0)
Block(5,3,-6,MOSSY_COBBLESTONE:0)
Block(5,3,-5,AIR:0)
Block(5,3,-4,MOSSY_COBBLESTONE:0)
Block(5,3,-3,AIR:0)
Block(5,3,-2,COBBLESTONE:0)
Block(5,3,-1,dimstack:bedrock:7)
Block(5,4,-7,MOSSY_COBBLESTONE:0)
Block(5,4,-6,MOSSY_COBBLESTONE:0)
Block(5,4,-5,MOSSY_COBBLESTONE:0)
Block(5,4,-4,MOSSY_COBBLESTONE:0)
Block(5,4,-3,COBBLESTONE:0)
Block(5,4,-2,MOSSY_COBBLESTONE:0)
Block(5,4,-1,dimstack:bedrock:7)
Block(5,5,-7,dimstack:bedrock:7)
Block(5,5,-6,dimstack:bedrock:7)
Block(5,5,-5,dimstack:bedrock:7)
Block(5,5,-4,dimstack:bedrock:7)
Block(5,5,-3,dimstack:bedrock:7)
Block(5,5,-2,dimstack:bedrock:7)
Block(5,5,-1,dimstack:bedrock:7)
Block(5,18,-6,MOSSY_COBBLESTONE:0)
Block(5,18,-5,MOSSY_COBBLESTONE:0)
Block(5,19,-6,MOSSY_COBBLESTONE:0)
Block(5,19,-5,COBBLESTONE:0)
Block(5,20,-5,COBBLESTONE:0)
Block(6,0,-7,dimstack:bedrock:7)
Block(6,0,-6,dimstack:bedrock:7)
Block(6,0,-5,dimstack:bedrock:7)
Block(6,0,-4,dimstack:bedrock:7)
Block(6,0,-3,dimstack:bedrock:7)
Block(6,0,-2,dimstack:bedrock:7)
Block(6,0,-1,dimstack:bedrock:7)
Block(6,1,-7,MOSSY_COBBLESTONE:0)
Block(6,1,-6,AIR:0)
Block(6,1,-5,MOSSY_COBBLESTONE:0)
Block(6,1,-4,AIR:0)
Block(6,1,-3,COBBLESTONE:0)
Block(6,1,-2,AIR:0)
Block(6,1,-1,dimstack:bedrock:7)
Block(6,2,-7,MOSSY_COBBLESTONE:0)
Block(6,2,-6,MOSSY_COBBLESTONE:0)
Block(6,2,-5,AIR:0)
Block(6,2,-4,MOSSY_COBBLESTONE:0)
Block(6,2,-3,AIR:0)
Block(6,2,-2,MOSSY_COBBLESTONE:0)
Block(6,2,-1,dimstack:bedrock:7)
Block(6,3,-7,COBBLESTONE:0)
Block(6,3,-6,MOSSY_COBBLESTONE:0)
Block(6,3,-5,AIR:0)
Block(6,3,-4,MOSSY_COBBLESTONE:0)
Block(6,3,-3,AIR:0)
Block(6,3,-2,COBBLESTONE:0)
Block(6,3,-1,dimstack:bedrock:7)
Block(6,4,-7,MOSSY_COBBLESTONE:0)
Block(6,4,-6,MOSSY_COBBLESTONE:0)
Block(6,4,-5,MOSSY_COBBLESTONE:0)
Block(6,4,-4,MOSSY_COBBLESTONE:0)
Block(6,4,-3,MOSSY_COBBLESTONE:0)
Block(6,4,-2,MOSSY_COBBLESTONE:0)
Block(6,4,-1,dimstack:bedrock:7)
Block(6,5,-7,dimstack:bedrock:7)
Block(6,5,-6,dimstack:bedrock:7)
Block(6,5,-5,dimstack:bedrock:7)
Block(6,5,-4,dimstack:bedrock:7)
Block(6,5,-3,dimstack:bedrock:7)
Block(6,5,-2,dimstack:bedrock:7)
Block(6,5,-1,dimstack:bedrock:7)
Block(6,19,-7,MOSSY_COBBLESTONE:0)
Block(6,19,-6,MOSSY_COBBLESTONE:0)
Block(6,19,-5,MOSSY_COBBLESTONE:0)
Block(6,19,-4,MOSSY_COBBLESTONE:0)
Block(6,20,-6,MOSSY_COBBLESTONE:0)
Block(6,20,-5,COBBLESTONE:0)
Block(6,20,-4,MOSSY_COBBLESTONE:0)
Block(7,0,-7,dimstack:bedrock:7)
Block(7,0,-6,dimstack:bedrock:7)
Block(7,0,-5,dimstack:bedrock:7)
Block(7,0,-4,dimstack:bedrock:7)
Block(7,0,-3,dimstack:bedrock:7)
Block(7,0,-2,dimstack:bedrock:7)
Block(7,0,-1,dimstack:bedrock:7)
Block(7,1,-7,MOSSY_COBBLESTONE:0)
Block(7,1,-6,AIR:0)
Block(7,1,-5,MOSSY_COBBLESTONE:0)
Block(7,1,-4,AIR:0)
Block(7,1,-3,MOSSY_COBBLESTONE:0)
Block(7,1,-2,AIR:0)
Block(7,1,-1,dimstack:bedrock:7)
Block(7,2,-7,MOSSY_COBBLESTONE:0)
Block(7,2,-6,MOSSY_COBBLESTONE:0)
Block(7,2,-5,AIR:0)
Block(7,2,-4,COBBLESTONE:0)
Block(7,2,-3,AIR:0)
Block(7,2,-2,MOSSY_COBBLESTONE:0)
Block(7,2,-1,dimstack:bedrock:7)
Block(7,3,-7,COBBLESTONE:0)
Block(7,3,-6,MOSSY_COBBLESTONE:0)
Block(7,3,-5,AIR:0)
Block(7,3,-4,MOSSY_COBBLESTONE:0)
Block(7,3,-3,AIR:0)
Block(7,3,-2,MOSSY_COBBLESTONE:0)
Block(7,3,-1,dimstack:bedrock:7)
Block(7,4,-7,MOSSY_COBBLESTONE:0)
Block(7,4,-6,MOSSY_COBBLESTONE:0)
Block(7,4,-5,MOSSY_COBBLESTONE:0)
Block(7,4,-4,MOSSY_COBBLESTONE:0)
Block(7,4,-3,MOSSY_COBBLESTONE:0)
Block(7,4,-2,MOSSY_COBBLESTONE:0)
Block(7,4,-1,dimstack:bedrock:7)
Block(7,5,-7,dimstack:bedrock:7)
Block(7,5,-6,dimstack:bedrock:7)
Block(7,5,-5,dimstack:bedrock:7)
Block(7,5,-4,dimstack:bedrock:7)
Block(7,5,-3,dimstack:bedrock:7)
Block(7,5,-2,dimstack:bedrock:7)
Block(7,5,-1,dimstack:bedrock:7)
Block(7,14,-5,DIRT:0)
Block(7,15,-7,MOSSY_COBBLESTONE:0)
Block(7,16,-7,MOSSY_COBBLESTONE:0)
Block(7,17,-7,MOSSY_COBBLESTONE:0)
Block(7,18,-7,MOSSY_COBBLESTONE:0)
Block(7,19,-7,COBBLESTONE:0)
Block(7,19,-6,COBBLESTONE:0)
Block(7,19,-5,MOSSY_COBBLESTONE:0)
Block(7,19,-4,MOSSY_COBBLESTONE:0)
Block(7,20,-6,MOSSY_COBBLESTONE:0)
Block(7,20,-5,MOSSY_COBBLESTONE:0)
Block(7,20,-4,MOSSY_COBBLESTONE:0)

#######################################################################
# +-----------------------------------------------------------------+ #
# |                             Branches                            | #
# +-----------------------------------------------------------------+ #
#######################################################################


#######################################################################
# +-----------------------------------------------------------------+ #
# |                             Entities                            | #
# +-----------------------------------------------------------------+ #
#######################################################################


#######################################################################
# +-----------------------------------------------------------------+ #
# |                            Particles                            | #
# +-----------------------------------------------------------------+ #
#######################################################################


#######################################################################
# +-----------------------------------------------------------------+ #
# |                             Spawners                            | #
# +-----------------------------------------------------------------+ #
#######################################################################


#######################################################################
# +-----------------------------------------------------------------+ #
# |                             ModData                             | #
# +-----------------------------------------------------------------+ #
#######################################################################

