#######################################################################
# +-----------------------------------------------------------------+ #
# |                            BO3 object                           | #
# +-----------------------------------------------------------------+ #
#######################################################################

Author: Bo3 BulkEdit

Description: Converted Schematic - Modified by Bo3BulkEdit

Version: 3

SettingsMode: WriteDisable

#######################################################################
# +-----------------------------------------------------------------+ #
# |                          Main settings                          | #
# +-----------------------------------------------------------------+ #
#######################################################################

IsOTGPlus: true
Tree: false
Frequency: 1
Rarity: 100.0
RotateRandomly: false
SpawnHeight: randomY
MaxBranchDepth: 10
ExcludedBiomes: All

##############################
# Height Limits for the BO3. #
##############################

MinHeight: 0
MaxHeight: 255

#######################################################################
# +-----------------------------------------------------------------+ #
# |                      Source block settings                      | #
# +-----------------------------------------------------------------+ #
#######################################################################

CanOverride: true
MaxPercentageOutsideSourceBlock: 100
OutsideSourceBlock: placeAnyway

#######################################################################
# +-----------------------------------------------------------------+ #
# |                               OTG+                              | #
# +-----------------------------------------------------------------+ #
#######################################################################

BO3Group: CeilingCrystals:0

#######################################################################
# +-----------------------------------------------------------------+ #
# |                              Blocks                             | #
# +-----------------------------------------------------------------+ #
#######################################################################

B(0,750,0,AIR)
B(15,750,15,AIR)
B(14,-18,14,betternether:quartz_stained_glass:15)
B(15,-18,14,betternether:quartz_stained_glass:15)
B(13,-18,15,betternether:quartz_stained_glass:15)
B(14,-18,15,betternether:quartz_stained_glass:15)
B(15,-18,15,betternether:quartz_stained_glass:15)
B(15,-17,11,betternether:quartz_stained_glass:15)
B(14,-17,12,betternether:quartz_stained_glass:15)
B(15,-17,12,betternether:quartz_stained_glass:15)
B(12,-17,13,betternether:quartz_stained_glass:15)
B(13,-17,13,betternether:quartz_stained_glass:15)
B(14,-17,13,betternether:quartz_stained_glass:15)
B(15,-17,13,betternether:quartz_stained_glass:15)
B(12,-17,14,betternether:quartz_stained_glass:15)
B(13,-17,14,betternether:quartz_stained_glass:15)
B(14,-17,14,betternether:quartz_stained_glass:15)
B(15,-17,14,betternether:quartz_stained_glass:15)
B(12,-17,15,betternether:quartz_stained_glass:15)
B(13,-17,15,betternether:quartz_stained_glass:15)
B(14,-17,15,betternether:quartz_stained_glass:15)
B(15,-17,15,betternether:quartz_stained_glass:15)
B(15,-16,9,betternether:quartz_stained_glass:15)
B(12,-16,10,betternether:quartz_stained_glass:15)
B(13,-16,10,betternether:quartz_stained_glass:15)
B(14,-16,10,betternether:quartz_stained_glass:15)
B(15,-16,10,betternether:quartz_stained_glass:15)
B(11,-16,11,betternether:quartz_stained_glass:15)
B(12,-16,11,betternether:quartz_stained_glass:15)
B(13,-16,11,betternether:quartz_stained_glass:15)
B(14,-16,11,betternether:quartz_stained_glass:15)
B(15,-16,11,betternether:quartz_stained_glass:15)
B(11,-16,12,betternether:quartz_stained_glass:15)
B(12,-16,12,betternether:quartz_stained_glass:15)
B(13,-16,12,betternether:quartz_stained_glass:15)
B(14,-16,12,betternether:quartz_stained_glass:15)
B(15,-16,12,betternether:quartz_stained_glass:15)
B(11,-16,13,betternether:quartz_stained_glass:15)
B(12,-16,13,betternether:quartz_stained_glass:15)
B(13,-16,13,betternether:quartz_stained_glass:15)
B(14,-16,13,betternether:quartz_stained_glass:15)
B(15,-16,13,betternether:quartz_stained_glass:15)
B(12,-16,14,betternether:quartz_stained_glass:15)
B(13,-16,14,betternether:quartz_stained_glass:15)
B(14,-16,14,betternether:quartz_stained_glass:15)
B(15,-16,14,betternether:quartz_stained_glass:15)
B(12,-16,15,betternether:quartz_stained_glass:15)
B(13,-16,15,betternether:quartz_stained_glass:15)
B(14,-16,15,betternether:quartz_stained_glass:15)
RB(15,-16,15,srparasites:parasitestain:1,80,quark:crystal:1,30,srparasites:parasiterubbledense:1,100)
B(12,-15,8,betternether:quartz_stained_glass:15)
B(13,-15,8,betternether:quartz_stained_glass:15)
B(14,-15,8,betternether:quartz_stained_glass:15)
B(15,-15,8,betternether:quartz_stained_glass:15)
B(11,-15,9,betternether:quartz_stained_glass:15)
B(12,-15,9,betternether:quartz_stained_glass:15)
B(13,-15,9,betternether:quartz_stained_glass:15)
B(14,-15,9,betternether:quartz_stained_glass:15)
B(15,-15,9,betternether:quartz_stained_glass:15)
B(10,-15,10,betternether:quartz_stained_glass:15)
B(11,-15,10,betternether:quartz_stained_glass:15)
B(12,-15,10,betternether:quartz_stained_glass:15)
B(13,-15,10,betternether:quartz_stained_glass:15)
B(14,-15,10,betternether:quartz_stained_glass:15)
B(15,-15,10,betternether:quartz_stained_glass:15)
B(10,-15,11,betternether:quartz_stained_glass:15)
B(11,-15,11,betternether:quartz_stained_glass:15)
B(12,-15,11,betternether:quartz_stained_glass:15)
B(13,-15,11,betternether:quartz_stained_glass:15)
B(14,-15,11,betternether:quartz_stained_glass:15)
B(15,-15,11,betternether:quartz_stained_glass:15)
B(11,-15,12,betternether:quartz_stained_glass:15)
B(12,-15,12,betternether:quartz_stained_glass:15)
B(13,-15,12,betternether:quartz_stained_glass:15)
B(14,-15,12,betternether:quartz_stained_glass:15)
B(15,-15,12,betternether:quartz_stained_glass:15)
B(11,-15,13,betternether:quartz_stained_glass:15)
B(12,-15,13,betternether:quartz_stained_glass:15)
B(13,-15,13,betternether:quartz_stained_glass:15)
RB(14,-15,13,srparasites:parasitestain:1,80,quark:crystal:1,30,srparasites:parasiterubbledense:1,100)
B(15,-15,13,betternether:quartz_stained_glass:15)
B(12,-15,14,betternether:quartz_stained_glass:15)
B(13,-15,14,betternether:quartz_stained_glass:15)
B(14,-15,14,betternether:quartz_stained_glass:15)
B(15,-15,14,betternether:quartz_stained_glass:15)
B(12,-15,15,betternether:quartz_stained_glass:15)
B(13,-15,15,betternether:quartz_stained_glass:15)
B(14,-15,15,betternether:quartz_stained_glass:15)
RB(15,-15,15,srparasites:parasitestain:1,80,quark:crystal:1,30,srparasites:parasiterubbledense:1,100)
B(13,-14,5,betternether:quartz_stained_glass:15)
B(12,-14,6,betternether:quartz_stained_glass:15)
B(13,-14,6,betternether:quartz_stained_glass:15)
B(14,-14,6,betternether:quartz_stained_glass:15)
B(9,-14,7,betternether:quartz_stained_glass:15)
B(10,-14,7,betternether:quartz_stained_glass:15)
B(11,-14,7,betternether:quartz_stained_glass:15)
B(12,-14,7,betternether:quartz_stained_glass:15)
B(13,-14,7,betternether:quartz_stained_glass:15)
B(14,-14,7,betternether:quartz_stained_glass:15)
B(15,-14,7,betternether:quartz_stained_glass:15)
B(9,-14,8,betternether:quartz_stained_glass:15)
B(10,-14,8,betternether:quartz_stained_glass:15)
B(11,-14,8,betternether:quartz_stained_glass:15)
B(12,-14,8,betternether:quartz_stained_glass:15)
B(13,-14,8,betternether:quartz_stained_glass:15)
B(14,-14,8,betternether:quartz_stained_glass:15)
B(15,-14,8,betternether:quartz_stained_glass:15)
B(10,-14,9,betternether:quartz_stained_glass:15)
B(11,-14,9,betternether:quartz_stained_glass:15)
B(12,-14,9,betternether:quartz_stained_glass:15)
B(13,-14,9,betternether:quartz_stained_glass:15)
B(14,-14,9,betternether:quartz_stained_glass:15)
B(15,-14,9,betternether:quartz_stained_glass:15)
B(10,-14,10,betternether:quartz_stained_glass:15)
B(11,-14,10,betternether:quartz_stained_glass:15)
B(12,-14,10,betternether:quartz_stained_glass:15)
B(13,-14,10,betternether:quartz_stained_glass:15)
B(14,-14,10,betternether:quartz_stained_glass:15)
B(15,-14,10,betternether:quartz_stained_glass:15)
B(10,-14,11,betternether:quartz_stained_glass:15)
B(11,-14,11,betternether:quartz_stained_glass:15)
B(12,-14,11,betternether:quartz_stained_glass:15)
B(13,-14,11,betternether:quartz_stained_glass:15)
B(14,-14,11,betternether:quartz_stained_glass:15)
B(15,-14,11,betternether:quartz_stained_glass:15)
B(11,-14,12,betternether:quartz_stained_glass:15)
B(12,-14,12,betternether:quartz_stained_glass:15)
B(13,-14,12,betternether:quartz_stained_glass:15)
RB(14,-14,12,srparasites:parasitestain:1,80,quark:crystal:1,30,srparasites:parasiterubbledense:1,100)
B(15,-14,12,betternether:quartz_stained_glass:15)
B(11,-14,13,betternether:quartz_stained_glass:15)
B(12,-14,13,betternether:quartz_stained_glass:15)
RB(13,-14,13,srparasites:parasitestain:1,80,quark:crystal:1,30,srparasites:parasiterubbledense:1,100)
RB(14,-14,13,srparasites:parasitestain:1,80,quark:crystal:1,30,srparasites:parasiterubbledense:1,100)
B(15,-14,13,betternether:quartz_stained_glass:15)
B(12,-14,14,betternether:quartz_stained_glass:15)
B(13,-14,14,betternether:quartz_stained_glass:15)
RB(14,-14,14,srparasites:parasitestain:1,80,quark:crystal:1,30,srparasites:parasiterubbledense:1,100)
B(15,-14,14,betternether:quartz_stained_glass:15)
B(12,-14,15,betternether:quartz_stained_glass:15)
B(13,-14,15,betternether:quartz_stained_glass:15)
B(14,-14,15,betternether:quartz_stained_glass:15)
RB(15,-14,15,srparasites:parasitestain:1,80,quark:crystal:1,30,srparasites:parasiterubbledense:1,100)
B(10,-13,4,betternether:quartz_stained_glass:15)
B(11,-13,4,betternether:quartz_stained_glass:15)
B(12,-13,4,betternether:quartz_stained_glass:15)
B(13,-13,4,betternether:quartz_stained_glass:15)
B(9,-13,5,betternether:quartz_stained_glass:15)
B(10,-13,5,betternether:quartz_stained_glass:15)
B(11,-13,5,betternether:quartz_stained_glass:15)
B(12,-13,5,betternether:quartz_stained_glass:15)
B(13,-13,5,betternether:quartz_stained_glass:15)
B(8,-13,6,betternether:quartz_stained_glass:15)
B(9,-13,6,betternether:quartz_stained_glass:15)
B(10,-13,6,betternether:quartz_stained_glass:15)
B(11,-13,6,betternether:quartz_stained_glass:15)
B(12,-13,6,betternether:quartz_stained_glass:15)
B(13,-13,6,betternether:quartz_stained_glass:15)
B(14,-13,6,betternether:quartz_stained_glass:15)
B(8,-13,7,betternether:quartz_stained_glass:15)
B(9,-13,7,betternether:quartz_stained_glass:15)
B(10,-13,7,betternether:quartz_stained_glass:15)
B(11,-13,7,betternether:quartz_stained_glass:15)
B(12,-13,7,betternether:quartz_stained_glass:15)
B(13,-13,7,betternether:quartz_stained_glass:15)
B(14,-13,7,betternether:quartz_stained_glass:15)
B(15,-13,7,betternether:quartz_stained_glass:15)
B(9,-13,8,betternether:quartz_stained_glass:15)
B(10,-13,8,betternether:quartz_stained_glass:15)
B(11,-13,8,betternether:quartz_stained_glass:15)
B(12,-13,8,betternether:quartz_stained_glass:15)
B(13,-13,8,betternether:quartz_stained_glass:15)
B(14,-13,8,betternether:quartz_stained_glass:15)
B(15,-13,8,betternether:quartz_stained_glass:15)
B(10,-13,9,betternether:quartz_stained_glass:15)
B(11,-13,9,betternether:quartz_stained_glass:15)
B(12,-13,9,betternether:quartz_stained_glass:15)
B(13,-13,9,betternether:quartz_stained_glass:15)
B(14,-13,9,betternether:quartz_stained_glass:15)
B(15,-13,9,betternether:quartz_stained_glass:15)
B(10,-13,10,betternether:quartz_stained_glass:15)
B(11,-13,10,betternether:quartz_stained_glass:15)
B(12,-13,10,betternether:quartz_stained_glass:15)
B(13,-13,10,betternether:quartz_stained_glass:15)
B(14,-13,10,betternether:quartz_stained_glass:15)
B(15,-13,10,betternether:quartz_stained_glass:15)
B(10,-13,11,betternether:quartz_stained_glass:15)
B(11,-13,11,betternether:quartz_stained_glass:15)
B(12,-13,11,betternether:quartz_stained_glass:15)
RB(13,-13,11,srparasites:parasitestain:1,80,quark:crystal:1,30,srparasites:parasiterubbledense:1,100)
RB(14,-13,11,srparasites:parasitestain:1,80,quark:crystal:1,30,srparasites:parasiterubbledense:1,100)
B(15,-13,11,betternether:quartz_stained_glass:15)
B(11,-13,12,betternether:quartz_stained_glass:15)
B(12,-13,12,betternether:quartz_stained_glass:15)
RB(13,-13,12,srparasites:parasitestain:1,80,quark:crystal:1,30,srparasites:parasiterubbledense:1,100)
RB(14,-13,12,srparasites:parasitestain:1,80,quark:crystal:1,30,srparasites:parasiterubbledense:1,100)
B(15,-13,12,betternether:quartz_stained_glass:15)
B(11,-13,13,betternether:quartz_stained_glass:15)
B(12,-13,13,betternether:quartz_stained_glass:15)
B(13,-13,13,betternether:quartz_stained_glass:15)
B(14,-13,13,betternether:quartz_stained_glass:15)
B(15,-13,13,betternether:quartz_stained_glass:15)
B(12,-13,14,betternether:quartz_stained_glass:15)
B(13,-13,14,betternether:quartz_stained_glass:15)
B(14,-13,14,betternether:quartz_stained_glass:15)
B(15,-13,14,betternether:quartz_stained_glass:15)
B(12,-13,15,betternether:quartz_stained_glass:15)
B(13,-13,15,betternether:quartz_stained_glass:15)
B(14,-13,15,betternether:quartz_stained_glass:15)
B(15,-13,15,betternether:quartz_stained_glass:15)
B(10,-12,2,betternether:quartz_stained_glass:15)
B(11,-12,2,betternether:quartz_stained_glass:15)
B(12,-12,2,betternether:quartz_stained_glass:15)
B(7,-12,3,betternether:quartz_stained_glass:15)
B(9,-12,3,betternether:quartz_stained_glass:15)
B(10,-12,3,betternether:quartz_stained_glass:15)
B(11,-12,3,betternether:quartz_stained_glass:15)
B(12,-12,3,betternether:quartz_stained_glass:15)
B(13,-12,3,betternether:quartz_stained_glass:15)
B(7,-12,4,betternether:quartz_stained_glass:15)
B(8,-12,4,betternether:quartz_stained_glass:15)
B(9,-12,4,betternether:quartz_stained_glass:15)
B(10,-12,4,betternether:quartz_stained_glass:15)
B(11,-12,4,betternether:quartz_stained_glass:15)
B(12,-12,4,betternether:quartz_stained_glass:15)
B(13,-12,4,betternether:quartz_stained_glass:15)
B(8,-12,5,betternether:quartz_stained_glass:15)
B(9,-12,5,betternether:quartz_stained_glass:15)
B(10,-12,5,betternether:quartz_stained_glass:15)
B(11,-12,5,betternether:quartz_stained_glass:15)
B(12,-12,5,betternether:quartz_stained_glass:15)
B(13,-12,5,betternether:quartz_stained_glass:15)
B(8,-12,6,betternether:quartz_stained_glass:15)
B(9,-12,6,betternether:quartz_stained_glass:15)
B(10,-12,6,betternether:quartz_stained_glass:15)
B(11,-12,6,betternether:quartz_stained_glass:15)
B(12,-12,6,betternether:quartz_stained_glass:15)
B(13,-12,6,betternether:quartz_stained_glass:15)
B(14,-12,6,betternether:quartz_stained_glass:15)
B(8,-12,7,betternether:quartz_stained_glass:15)
B(9,-12,7,betternether:quartz_stained_glass:15)
B(10,-12,7,betternether:quartz_stained_glass:15)
RB(11,-12,7,srparasites:parasitestain:1,80,quark:crystal:1,30,srparasites:parasiterubbledense:1,100)
B(12,-12,7,betternether:quartz_stained_glass:15)
B(13,-12,7,betternether:quartz_stained_glass:15)
B(14,-12,7,betternether:quartz_stained_glass:15)
B(15,-12,7,betternether:quartz_stained_glass:15)
B(9,-12,8,betternether:quartz_stained_glass:15)
B(10,-12,8,betternether:quartz_stained_glass:15)
B(11,-12,8,betternether:quartz_stained_glass:15)
RB(12,-12,8,srparasites:parasitestain:1,80,quark:crystal:1,30,srparasites:parasiterubbledense:1,100)
B(13,-12,8,betternether:quartz_stained_glass:15)
B(14,-12,8,betternether:quartz_stained_glass:15)
B(15,-12,8,betternether:quartz_stained_glass:15)
B(10,-12,9,betternether:quartz_stained_glass:15)
B(11,-12,9,betternether:quartz_stained_glass:15)
RB(12,-12,9,srparasites:parasitestain:1,80,quark:crystal:1,30,srparasites:parasiterubbledense:1,100)
RB(13,-12,9,srparasites:parasitestain:1,80,quark:crystal:1,30,srparasites:parasiterubbledense:1,100)
B(14,-12,9,betternether:quartz_stained_glass:15)
B(15,-12,9,betternether:quartz_stained_glass:15)
B(10,-12,10,betternether:quartz_stained_glass:15)
B(11,-12,10,betternether:quartz_stained_glass:15)
RB(12,-12,10,srparasites:parasitestain:1,80,quark:crystal:1,30,srparasites:parasiterubbledense:1,100)
RB(13,-12,10,srparasites:parasitestain:1,80,quark:crystal:1,30,srparasites:parasiterubbledense:1,100)
B(14,-12,10,betternether:quartz_stained_glass:15)
B(15,-12,10,betternether:quartz_stained_glass:15)
B(10,-12,11,betternether:quartz_stained_glass:15)
B(11,-12,11,betternether:quartz_stained_glass:15)
B(12,-12,11,betternether:quartz_stained_glass:15)
RB(13,-12,11,srparasites:parasitestain:1,80,quark:crystal:1,30,srparasites:parasiterubbledense:1,100)
B(14,-12,11,betternether:quartz_stained_glass:15)
B(15,-12,11,betternether:quartz_stained_glass:15)
B(11,-12,12,betternether:quartz_stained_glass:15)
B(12,-12,12,betternether:quartz_stained_glass:15)
B(13,-12,12,betternether:quartz_stained_glass:15)
B(14,-12,12,betternether:quartz_stained_glass:15)
B(15,-12,12,betternether:quartz_stained_glass:15)
B(11,-12,13,betternether:quartz_stained_glass:15)
B(12,-12,13,betternether:quartz_stained_glass:15)
B(13,-12,13,betternether:quartz_stained_glass:15)
B(14,-12,13,betternether:quartz_stained_glass:15)
B(15,-12,13,betternether:quartz_stained_glass:15)
B(12,-12,14,betternether:quartz_stained_glass:15)
B(13,-12,14,betternether:quartz_stained_glass:15)
B(14,-12,14,betternether:quartz_stained_glass:15)
B(15,-12,14,betternether:quartz_stained_glass:15)
B(12,-12,15,betternether:quartz_stained_glass:15)
B(13,-12,15,betternether:quartz_stained_glass:15)
B(14,-12,15,betternether:quartz_stained_glass:15)
B(15,-12,15,betternether:quartz_stained_glass:15)
B(10,-11,0,betternether:quartz_stained_glass:15)
B(11,-11,0,betternether:quartz_stained_glass:15)
B(7,-11,1,betternether:quartz_stained_glass:15)
B(8,-11,1,betternether:quartz_stained_glass:15)
B(9,-11,1,betternether:quartz_stained_glass:15)
B(10,-11,1,betternether:quartz_stained_glass:15)
B(11,-11,1,betternether:quartz_stained_glass:15)
B(7,-11,2,betternether:quartz_stained_glass:15)
B(8,-11,2,betternether:quartz_stained_glass:15)
B(9,-11,2,betternether:quartz_stained_glass:15)
B(10,-11,2,betternether:quartz_stained_glass:15)
B(11,-11,2,betternether:quartz_stained_glass:15)
B(12,-11,2,betternether:quartz_stained_glass:15)
B(6,-11,3,betternether:quartz_stained_glass:15)
B(7,-11,3,betternether:quartz_stained_glass:15)
B(8,-11,3,betternether:quartz_stained_glass:15)
B(9,-11,3,betternether:quartz_stained_glass:15)
B(10,-11,3,betternether:quartz_stained_glass:15)
B(11,-11,3,betternether:quartz_stained_glass:15)
B(12,-11,3,betternether:quartz_stained_glass:15)
B(13,-11,3,betternether:quartz_stained_glass:15)
B(7,-11,4,betternether:quartz_stained_glass:15)
B(8,-11,4,betternether:quartz_stained_glass:15)
B(9,-11,4,betternether:quartz_stained_glass:15)
B(10,-11,4,betternether:quartz_stained_glass:15)
B(11,-11,4,betternether:quartz_stained_glass:15)
B(12,-11,4,betternether:quartz_stained_glass:15)
B(13,-11,4,betternether:quartz_stained_glass:15)
B(8,-11,5,betternether:quartz_stained_glass:15)
B(9,-11,5,betternether:quartz_stained_glass:15)
B(10,-11,5,betternether:quartz_stained_glass:15)
B(11,-11,5,betternether:quartz_stained_glass:15)
B(12,-11,5,betternether:quartz_stained_glass:15)
B(13,-11,5,betternether:quartz_stained_glass:15)
B(8,-11,6,betternether:quartz_stained_glass:15)
B(9,-11,6,betternether:quartz_stained_glass:15)
B(10,-11,6,betternether:quartz_stained_glass:15)
B(11,-11,6,betternether:quartz_stained_glass:15)
B(12,-11,6,betternether:quartz_stained_glass:15)
B(13,-11,6,betternether:quartz_stained_glass:15)
B(14,-11,6,betternether:quartz_stained_glass:15)
B(8,-11,7,betternether:quartz_stained_glass:15)
B(9,-11,7,betternether:quartz_stained_glass:15)
B(10,-11,7,betternether:quartz_stained_glass:15)
RB(11,-11,7,srparasites:parasitestain:1,80,quark:crystal:1,30,srparasites:parasiterubbledense:1,100)
RB(12,-11,7,srparasites:parasitestain:1,80,quark:crystal:1,30,srparasites:parasiterubbledense:1,100)
B(13,-11,7,betternether:quartz_stained_glass:15)
B(14,-11,7,betternether:quartz_stained_glass:15)
B(15,-11,7,betternether:quartz_stained_glass:15)
B(9,-11,8,betternether:quartz_stained_glass:15)
B(10,-11,8,betternether:quartz_stained_glass:15)
B(11,-11,8,betternether:quartz_stained_glass:15)
RB(12,-11,8,srparasites:parasitestain:1,80,quark:crystal:1,30,srparasites:parasiterubbledense:1,100)
B(13,-11,8,betternether:quartz_stained_glass:15)
B(14,-11,8,betternether:quartz_stained_glass:15)
B(15,-11,8,betternether:quartz_stained_glass:15)
B(10,-11,9,betternether:quartz_stained_glass:15)
B(11,-11,9,betternether:quartz_stained_glass:15)
B(12,-11,9,betternether:quartz_stained_glass:15)
B(13,-11,9,betternether:quartz_stained_glass:15)
B(14,-11,9,betternether:quartz_stained_glass:15)
B(15,-11,9,betternether:quartz_stained_glass:15)
B(10,-11,10,betternether:quartz_stained_glass:15)
B(11,-11,10,betternether:quartz_stained_glass:15)
B(12,-11,10,betternether:quartz_stained_glass:15)
B(13,-11,10,betternether:quartz_stained_glass:15)
B(14,-11,10,betternether:quartz_stained_glass:15)
B(15,-11,10,betternether:quartz_stained_glass:15)
B(10,-11,11,betternether:quartz_stained_glass:15)
B(11,-11,11,betternether:quartz_stained_glass:15)
B(12,-11,11,betternether:quartz_stained_glass:15)
B(14,-11,11,betternether:quartz_stained_glass:15)
B(15,-11,11,betternether:quartz_stained_glass:15)
B(11,-11,12,betternether:quartz_stained_glass:15)
B(12,-11,12,betternether:quartz_stained_glass:15)
B(13,-11,12,betternether:quartz_stained_glass:15)
B(14,-11,12,betternether:quartz_stained_glass:15)
B(15,-11,12,betternether:quartz_stained_glass:15)
B(11,-11,13,betternether:quartz_stained_glass:15)
B(12,-11,13,betternether:quartz_stained_glass:15)
B(13,-11,13,betternether:quartz_stained_glass:15)
B(14,-11,13,betternether:quartz_stained_glass:15)
B(15,-11,13,betternether:quartz_stained_glass:15)
B(12,-11,14,betternether:quartz_stained_glass:15)
B(13,-11,14,betternether:quartz_stained_glass:15)
B(14,-11,14,betternether:quartz_stained_glass:15)
B(15,-11,14,betternether:quartz_stained_glass:15)
B(12,-11,15,betternether:quartz_stained_glass:15)
B(13,-11,15,betternether:quartz_stained_glass:15)
B(14,-11,15,betternether:quartz_stained_glass:15)
B(15,-11,15,betternether:quartz_stained_glass:15)
B(5,-10,0,betternether:quartz_stained_glass:15)
B(6,-10,0,betternether:quartz_stained_glass:15)
B(7,-10,0,betternether:quartz_stained_glass:15)
B(8,-10,0,betternether:quartz_stained_glass:15)
B(9,-10,0,betternether:quartz_stained_glass:15)
B(10,-10,0,betternether:quartz_stained_glass:15)
B(11,-10,0,betternether:quartz_stained_glass:15)
B(6,-10,1,betternether:quartz_stained_glass:15)
B(7,-10,1,betternether:quartz_stained_glass:15)
B(8,-10,1,betternether:quartz_stained_glass:15)
B(9,-10,1,betternether:quartz_stained_glass:15)
B(10,-10,1,betternether:quartz_stained_glass:15)
B(11,-10,1,betternether:quartz_stained_glass:15)
B(6,-10,2,betternether:quartz_stained_glass:15)
B(7,-10,2,betternether:quartz_stained_glass:15)
B(8,-10,2,betternether:quartz_stained_glass:15)
B(9,-10,2,betternether:quartz_stained_glass:15)
B(10,-10,2,betternether:quartz_stained_glass:15)
B(11,-10,2,betternether:quartz_stained_glass:15)
B(12,-10,2,betternether:quartz_stained_glass:15)
B(6,-10,3,betternether:quartz_stained_glass:15)
B(7,-10,3,betternether:quartz_stained_glass:15)
B(8,-10,3,betternether:quartz_stained_glass:15)
B(9,-10,3,betternether:quartz_stained_glass:15)
B(10,-10,3,betternether:quartz_stained_glass:15)
B(11,-10,3,betternether:quartz_stained_glass:15)
B(12,-10,3,betternether:quartz_stained_glass:15)
B(13,-10,3,betternether:quartz_stained_glass:15)
B(7,-10,4,betternether:quartz_stained_glass:15)
B(8,-10,4,betternether:quartz_stained_glass:15)
B(9,-10,4,betternether:quartz_stained_glass:15)
B(10,-10,4,betternether:quartz_stained_glass:15)
B(11,-10,4,betternether:quartz_stained_glass:15)
B(12,-10,4,betternether:quartz_stained_glass:15)
B(13,-10,4,betternether:quartz_stained_glass:15)
B(8,-10,5,betternether:quartz_stained_glass:15)
B(9,-10,5,betternether:quartz_stained_glass:15)
RB(10,-10,5,srparasites:parasitestain:1,80,quark:crystal:1,30,srparasites:parasiterubbledense:1,100)
RB(11,-10,5,srparasites:parasitestain:1,80,quark:crystal:1,30,srparasites:parasiterubbledense:1,100)
B(12,-10,5,betternether:quartz_stained_glass:15)
B(13,-10,5,betternether:quartz_stained_glass:15)
B(8,-10,6,betternether:quartz_stained_glass:15)
B(9,-10,6,betternether:quartz_stained_glass:15)
B(10,-10,6,betternether:quartz_stained_glass:15)
RB(11,-10,6,srparasites:parasitestain:1,80,quark:crystal:1,30,srparasites:parasiterubbledense:1,100)
RB(12,-10,6,srparasites:parasitestain:1,80,quark:crystal:1,30,srparasites:parasiterubbledense:1,100)
B(13,-10,6,betternether:quartz_stained_glass:15)
B(14,-10,6,betternether:quartz_stained_glass:15)
B(8,-10,7,betternether:quartz_stained_glass:15)
B(9,-10,7,betternether:quartz_stained_glass:15)
RB(10,-10,7,srparasites:parasitestain:1,80,quark:crystal:1,30,srparasites:parasiterubbledense:1,100)
RB(11,-10,7,srparasites:parasitestain:1,80,quark:crystal:1,30,srparasites:parasiterubbledense:1,100)
B(12,-10,7,betternether:quartz_stained_glass:15)
B(13,-10,7,betternether:quartz_stained_glass:15)
B(14,-10,7,betternether:quartz_stained_glass:15)
B(15,-10,7,betternether:quartz_stained_glass:15)
B(9,-10,8,betternether:quartz_stained_glass:15)
B(10,-10,8,betternether:quartz_stained_glass:15)
B(11,-10,8,betternether:quartz_stained_glass:15)
B(12,-10,8,betternether:quartz_stained_glass:15)
B(13,-10,8,betternether:quartz_stained_glass:15)
B(14,-10,8,betternether:quartz_stained_glass:15)
B(15,-10,8,betternether:quartz_stained_glass:15)
B(10,-10,9,betternether:quartz_stained_glass:15)
B(11,-10,9,betternether:quartz_stained_glass:15)
B(12,-10,9,betternether:quartz_stained_glass:15)
B(13,-10,9,betternether:quartz_stained_glass:15)
B(14,-10,9,betternether:quartz_stained_glass:15)
B(15,-10,9,betternether:quartz_stained_glass:15)
B(10,-10,10,betternether:quartz_stained_glass:15)
B(11,-10,10,betternether:quartz_stained_glass:15)
B(12,-10,10,betternether:quartz_stained_glass:15)
B(14,-10,10,betternether:quartz_stained_glass:15)
B(15,-10,10,betternether:quartz_stained_glass:15)
B(10,-10,11,betternether:quartz_stained_glass:15)
B(11,-10,11,betternether:quartz_stained_glass:15)
B(12,-10,11,betternether:quartz_stained_glass:15)
B(14,-10,11,betternether:quartz_stained_glass:15)
B(15,-10,11,betternether:quartz_stained_glass:15)
B(11,-10,12,betternether:quartz_stained_glass:15)
B(12,-10,12,betternether:quartz_stained_glass:15)
B(13,-10,12,betternether:quartz_stained_glass:15)
B(14,-10,12,betternether:quartz_stained_glass:15)
B(15,-10,12,betternether:quartz_stained_glass:15)
B(11,-10,13,betternether:quartz_stained_glass:15)
B(12,-10,13,betternether:quartz_stained_glass:15)
B(13,-10,13,betternether:quartz_stained_glass:15)
B(15,-10,13,betternether:quartz_stained_glass:15)
B(12,-10,14,betternether:quartz_stained_glass:15)
B(5,-9,0,betternether:quartz_stained_glass:15)
B(6,-9,0,betternether:quartz_stained_glass:15)
B(7,-9,0,betternether:quartz_stained_glass:15)
B(8,-9,0,betternether:quartz_stained_glass:15)
B(9,-9,0,betternether:quartz_stained_glass:15)
B(10,-9,0,betternether:quartz_stained_glass:15)
B(11,-9,0,betternether:quartz_stained_glass:15)
B(6,-9,1,betternether:quartz_stained_glass:15)
B(7,-9,1,betternether:quartz_stained_glass:15)
B(8,-9,1,betternether:quartz_stained_glass:15)
B(9,-9,1,betternether:quartz_stained_glass:15)
B(10,-9,1,betternether:quartz_stained_glass:15)
B(11,-9,1,betternether:quartz_stained_glass:15)
B(6,-9,2,betternether:quartz_stained_glass:15)
B(7,-9,2,betternether:quartz_stained_glass:15)
B(8,-9,2,betternether:quartz_stained_glass:15)
B(9,-9,2,betternether:quartz_stained_glass:15)
B(10,-9,2,betternether:quartz_stained_glass:15)
B(11,-9,2,betternether:quartz_stained_glass:15)
B(12,-9,2,betternether:quartz_stained_glass:15)
B(6,-9,3,betternether:quartz_stained_glass:15)
B(7,-9,3,betternether:quartz_stained_glass:15)
B(8,-9,3,betternether:quartz_stained_glass:15)
B(9,-9,3,betternether:quartz_stained_glass:15)
RB(10,-9,3,srparasites:parasitestain:1,80,quark:crystal:1,30,srparasites:parasiterubbledense:1,100)
B(11,-9,3,betternether:quartz_stained_glass:15)
B(12,-9,3,betternether:quartz_stained_glass:15)
B(13,-9,3,betternether:quartz_stained_glass:15)
B(7,-9,4,betternether:quartz_stained_glass:15)
B(8,-9,4,betternether:quartz_stained_glass:15)
RB(9,-9,4,srparasites:parasitestain:1,80,quark:crystal:1,30,srparasites:parasiterubbledense:1,100)
RB(10,-9,4,srparasites:parasitestain:1,80,quark:crystal:1,30,srparasites:parasiterubbledense:1,100)
B(11,-9,4,betternether:quartz_stained_glass:15)
B(12,-9,4,betternether:quartz_stained_glass:15)
B(13,-9,4,betternether:quartz_stained_glass:15)
B(8,-9,5,betternether:quartz_stained_glass:15)
B(9,-9,5,betternether:quartz_stained_glass:15)
B(10,-9,5,betternether:quartz_stained_glass:15)
B(11,-9,5,betternether:quartz_stained_glass:15)
B(12,-9,5,betternether:quartz_stained_glass:15)
B(13,-9,5,betternether:quartz_stained_glass:15)
B(8,-9,6,betternether:quartz_stained_glass:15)
B(9,-9,6,betternether:quartz_stained_glass:15)
B(10,-9,6,betternether:quartz_stained_glass:15)
RB(11,-9,6,srparasites:parasitestain:1,80,quark:crystal:1,30,srparasites:parasiterubbledense:1,100)
B(12,-9,6,betternether:quartz_stained_glass:15)
B(13,-9,6,betternether:quartz_stained_glass:15)
B(14,-9,6,betternether:quartz_stained_glass:15)
B(8,-9,7,betternether:quartz_stained_glass:15)
B(9,-9,7,betternether:quartz_stained_glass:15)
B(10,-9,7,betternether:quartz_stained_glass:15)
B(11,-9,7,betternether:quartz_stained_glass:15)
B(12,-9,7,betternether:quartz_stained_glass:15)
B(13,-9,7,betternether:quartz_stained_glass:15)
B(14,-9,7,betternether:quartz_stained_glass:15)
B(15,-9,7,betternether:quartz_stained_glass:15)
B(9,-9,8,betternether:quartz_stained_glass:15)
B(10,-9,8,betternether:quartz_stained_glass:15)
B(11,-9,8,betternether:quartz_stained_glass:15)
B(12,-9,8,betternether:quartz_stained_glass:15)
B(13,-9,8,betternether:quartz_stained_glass:15)
B(14,-9,8,betternether:quartz_stained_glass:15)
B(15,-9,8,betternether:quartz_stained_glass:15)
B(10,-9,9,betternether:quartz_stained_glass:15)
B(11,-9,9,betternether:quartz_stained_glass:15)
B(12,-9,9,betternether:quartz_stained_glass:15)
B(13,-9,9,betternether:quartz_stained_glass:15)
B(14,-9,9,betternether:quartz_stained_glass:15)
B(15,-9,9,betternether:quartz_stained_glass:15)
B(10,-9,10,betternether:quartz_stained_glass:15)
B(11,-9,10,betternether:quartz_stained_glass:15)
B(12,-9,10,betternether:quartz_stained_glass:15)
B(13,-9,10,betternether:quartz_stained_glass:15)
B(14,-9,10,betternether:quartz_stained_glass:15)
B(15,-9,10,betternether:quartz_stained_glass:15)
B(10,-9,11,betternether:quartz_stained_glass:15)
B(11,-9,11,betternether:quartz_stained_glass:15)
B(12,-9,11,betternether:quartz_stained_glass:15)
B(12,-9,12,betternether:quartz_stained_glass:15)
B(5,-8,0,betternether:quartz_stained_glass:15)
B(6,-8,0,betternether:quartz_stained_glass:15)
B(7,-8,0,betternether:quartz_stained_glass:15)
B(8,-8,0,betternether:quartz_stained_glass:15)
B(9,-8,0,betternether:quartz_stained_glass:15)
B(10,-8,0,betternether:quartz_stained_glass:15)
B(11,-8,0,betternether:quartz_stained_glass:15)
B(6,-8,1,betternether:quartz_stained_glass:15)
B(7,-8,1,betternether:quartz_stained_glass:15)
RB(8,-8,1,srparasites:parasitestain:1,80,quark:crystal:1,30,srparasites:parasiterubbledense:1,100)
RB(9,-8,1,srparasites:parasitestain:1,80,quark:crystal:1,30,srparasites:parasiterubbledense:1,100)
B(10,-8,1,betternether:quartz_stained_glass:15)
B(11,-8,1,betternether:quartz_stained_glass:15)
B(6,-8,2,betternether:quartz_stained_glass:15)
B(7,-8,2,betternether:quartz_stained_glass:15)
RB(8,-8,2,srparasites:parasitestain:1,80,quark:crystal:1,30,srparasites:parasiterubbledense:1,100)
RB(9,-8,2,srparasites:parasitestain:1,80,quark:crystal:1,30,srparasites:parasiterubbledense:1,100)
RB(10,-8,2,srparasites:parasitestain:1,80,quark:crystal:1,30,srparasites:parasiterubbledense:1,100)
B(11,-8,2,betternether:quartz_stained_glass:15)
B(12,-8,2,betternether:quartz_stained_glass:15)
B(6,-8,3,betternether:quartz_stained_glass:15)
B(7,-8,3,betternether:quartz_stained_glass:15)
B(8,-8,3,betternether:quartz_stained_glass:15)
RB(9,-8,3,srparasites:parasitestain:1,80,quark:crystal:1,30,srparasites:parasiterubbledense:1,100)
RB(10,-8,3,srparasites:parasitestain:1,80,quark:crystal:1,30,srparasites:parasiterubbledense:1,100)
B(11,-8,3,betternether:quartz_stained_glass:15)
B(12,-8,3,betternether:quartz_stained_glass:15)
B(13,-8,3,betternether:quartz_stained_glass:15)
B(7,-8,4,betternether:quartz_stained_glass:15)
B(8,-8,4,betternether:quartz_stained_glass:15)
B(9,-8,4,betternether:quartz_stained_glass:15)
B(10,-8,4,betternether:quartz_stained_glass:15)
B(11,-8,4,betternether:quartz_stained_glass:15)
B(12,-8,4,betternether:quartz_stained_glass:15)
B(13,-8,4,betternether:quartz_stained_glass:15)
B(8,-8,5,betternether:quartz_stained_glass:15)
B(9,-8,5,betternether:quartz_stained_glass:15)
B(10,-8,5,betternether:quartz_stained_glass:15)
B(11,-8,5,betternether:quartz_stained_glass:15)
B(12,-8,5,betternether:quartz_stained_glass:15)
B(13,-8,5,betternether:quartz_stained_glass:15)
B(8,-8,6,betternether:quartz_stained_glass:15)
B(9,-8,6,betternether:quartz_stained_glass:15)
B(10,-8,6,betternether:quartz_stained_glass:15)
B(11,-8,6,betternether:quartz_stained_glass:15)
B(12,-8,6,betternether:quartz_stained_glass:15)
B(13,-8,6,betternether:quartz_stained_glass:15)
B(14,-8,6,betternether:quartz_stained_glass:15)
B(8,-8,7,betternether:quartz_stained_glass:15)
B(9,-8,7,betternether:quartz_stained_glass:15)
B(10,-8,7,betternether:quartz_stained_glass:15)
B(11,-8,7,betternether:quartz_stained_glass:15)
B(12,-8,7,betternether:quartz_stained_glass:15)
B(13,-8,7,betternether:quartz_stained_glass:15)
B(14,-8,7,betternether:quartz_stained_glass:15)
B(15,-8,7,betternether:quartz_stained_glass:15)
B(9,-8,8,betternether:quartz_stained_glass:15)
B(10,-8,8,betternether:quartz_stained_glass:15)
B(11,-8,8,betternether:quartz_stained_glass:15)
B(12,-8,8,betternether:quartz_stained_glass:15)
B(13,-8,8,betternether:quartz_stained_glass:15)
B(14,-8,8,betternether:quartz_stained_glass:15)
B(10,-8,9,betternether:quartz_stained_glass:15)
B(11,-8,9,betternether:quartz_stained_glass:15)
B(12,-8,9,betternether:quartz_stained_glass:15)
B(13,-8,9,betternether:quartz_stained_glass:15)
B(10,-8,10,betternether:quartz_stained_glass:15)
B(5,-7,0,betternether:quartz_stained_glass:15)
B(6,-7,0,betternether:quartz_stained_glass:15)
RB(7,-7,0,srparasites:parasitestain:1,80,quark:crystal:1,30,srparasites:parasiterubbledense:1,100)
RB(8,-7,0,srparasites:parasitestain:1,80,quark:crystal:1,30,srparasites:parasiterubbledense:1,100)
RB(9,-7,0,srparasites:parasitestain:1,80,quark:crystal:1,30,srparasites:parasiterubbledense:1,100)
B(10,-7,0,betternether:quartz_stained_glass:15)
B(11,-7,0,betternether:quartz_stained_glass:15)
B(6,-7,1,betternether:quartz_stained_glass:15)
B(7,-7,1,betternether:quartz_stained_glass:15)
RB(8,-7,1,srparasites:parasitestain:1,80,quark:crystal:1,30,srparasites:parasiterubbledense:1,100)
B(9,-7,1,betternether:quartz_stained_glass:15)
B(10,-7,1,betternether:quartz_stained_glass:15)
B(11,-7,1,betternether:quartz_stained_glass:15)
B(6,-7,2,betternether:quartz_stained_glass:15)
B(7,-7,2,betternether:quartz_stained_glass:15)
B(8,-7,2,betternether:quartz_stained_glass:15)
B(9,-7,2,betternether:quartz_stained_glass:15)
B(10,-7,2,betternether:quartz_stained_glass:15)
B(11,-7,2,betternether:quartz_stained_glass:15)
B(12,-7,2,betternether:quartz_stained_glass:15)
B(6,-7,3,betternether:quartz_stained_glass:15)
B(7,-7,3,betternether:quartz_stained_glass:15)
B(8,-7,3,betternether:quartz_stained_glass:15)
B(9,-7,3,betternether:quartz_stained_glass:15)
B(10,-7,3,betternether:quartz_stained_glass:15)
B(11,-7,3,betternether:quartz_stained_glass:15)
B(12,-7,3,betternether:quartz_stained_glass:15)
B(13,-7,3,betternether:quartz_stained_glass:15)
B(7,-7,4,betternether:quartz_stained_glass:15)
B(8,-7,4,betternether:quartz_stained_glass:15)
B(9,-7,4,betternether:quartz_stained_glass:15)
B(10,-7,4,betternether:quartz_stained_glass:15)
B(11,-7,4,betternether:quartz_stained_glass:15)
B(12,-7,4,betternether:quartz_stained_glass:15)
B(13,-7,4,betternether:quartz_stained_glass:15)
B(8,-7,5,betternether:quartz_stained_glass:15)
B(9,-7,5,betternether:quartz_stained_glass:15)
B(10,-7,5,betternether:quartz_stained_glass:15)
B(11,-7,5,betternether:quartz_stained_glass:15)
B(12,-7,5,betternether:quartz_stained_glass:15)
B(13,-7,5,betternether:quartz_stained_glass:15)
B(8,-7,6,betternether:quartz_stained_glass:15)
B(9,-7,6,betternether:quartz_stained_glass:15)
B(10,-7,6,betternether:quartz_stained_glass:15)
B(11,-7,6,betternether:quartz_stained_glass:15)
B(12,-7,6,betternether:quartz_stained_glass:15)
B(13,-7,6,betternether:quartz_stained_glass:15)
B(8,-7,7,betternether:quartz_stained_glass:15)
B(9,-7,7,betternether:quartz_stained_glass:15)
B(10,-7,7,betternether:quartz_stained_glass:15)
B(11,-7,7,betternether:quartz_stained_glass:15)
B(10,-7,8,betternether:quartz_stained_glass:15)
B(5,-6,0,betternether:quartz_stained_glass:15)
B(6,-6,0,betternether:quartz_stained_glass:15)
B(7,-6,0,betternether:quartz_stained_glass:15)
B(8,-6,0,betternether:quartz_stained_glass:15)
B(9,-6,0,betternether:quartz_stained_glass:15)
B(10,-6,0,betternether:quartz_stained_glass:15)
B(11,-6,0,betternether:quartz_stained_glass:15)
B(6,-6,1,betternether:quartz_stained_glass:15)
B(7,-6,1,betternether:quartz_stained_glass:15)
B(8,-6,1,betternether:quartz_stained_glass:15)
B(9,-6,1,betternether:quartz_stained_glass:15)
B(10,-6,1,betternether:quartz_stained_glass:15)
B(11,-6,1,betternether:quartz_stained_glass:15)
B(6,-6,2,betternether:quartz_stained_glass:15)
B(7,-6,2,betternether:quartz_stained_glass:15)
B(8,-6,2,betternether:quartz_stained_glass:15)
B(9,-6,2,betternether:quartz_stained_glass:15)
B(10,-6,2,betternether:quartz_stained_glass:15)
B(11,-6,2,betternether:quartz_stained_glass:15)
B(12,-6,2,betternether:quartz_stained_glass:15)
B(6,-6,3,betternether:quartz_stained_glass:15)
B(7,-6,3,betternether:quartz_stained_glass:15)
B(8,-6,3,betternether:quartz_stained_glass:15)
B(9,-6,3,betternether:quartz_stained_glass:15)
B(10,-6,3,betternether:quartz_stained_glass:15)
B(11,-6,3,betternether:quartz_stained_glass:15)
B(12,-6,3,betternether:quartz_stained_glass:15)
B(13,-6,3,betternether:quartz_stained_glass:15)
B(7,-6,4,betternether:quartz_stained_glass:15)
B(8,-6,4,betternether:quartz_stained_glass:15)
B(9,-6,4,betternether:quartz_stained_glass:15)
B(10,-6,4,betternether:quartz_stained_glass:15)
B(11,-6,4,betternether:quartz_stained_glass:15)
B(12,-6,4,betternether:quartz_stained_glass:15)
B(8,-6,5,betternether:quartz_stained_glass:15)
B(9,-6,5,betternether:quartz_stained_glass:15)
B(10,-6,5,betternether:quartz_stained_glass:15)
B(11,-6,5,betternether:quartz_stained_glass:15)
B(8,-6,6,betternether:quartz_stained_glass:15)
B(9,-6,6,betternether:quartz_stained_glass:15)
B(5,-5,0,betternether:quartz_stained_glass:15)
B(6,-5,0,betternether:quartz_stained_glass:15)
B(7,-5,0,betternether:quartz_stained_glass:15)
B(8,-5,0,betternether:quartz_stained_glass:15)
B(9,-5,0,betternether:quartz_stained_glass:15)
B(10,-5,0,betternether:quartz_stained_glass:15)
B(11,-5,0,betternether:quartz_stained_glass:15)
B(6,-5,1,betternether:quartz_stained_glass:15)
B(7,-5,1,betternether:quartz_stained_glass:15)
B(8,-5,1,betternether:quartz_stained_glass:15)
B(9,-5,1,betternether:quartz_stained_glass:15)
B(10,-5,1,betternether:quartz_stained_glass:15)
B(11,-5,1,betternether:quartz_stained_glass:15)
B(6,-5,2,betternether:quartz_stained_glass:15)
B(7,-5,2,betternether:quartz_stained_glass:15)
B(8,-5,2,betternether:quartz_stained_glass:15)
B(9,-5,2,betternether:quartz_stained_glass:15)
B(10,-5,2,betternether:quartz_stained_glass:15)
B(11,-5,2,betternether:quartz_stained_glass:15)
B(6,-5,3,betternether:quartz_stained_glass:15)
B(7,-5,3,betternether:quartz_stained_glass:15)
B(8,-5,3,betternether:quartz_stained_glass:15)
B(9,-5,3,betternether:quartz_stained_glass:15)
B(10,-5,3,betternether:quartz_stained_glass:15)
B(11,-5,3,betternether:quartz_stained_glass:15)
B(8,-5,4,betternether:quartz_stained_glass:15)
B(5,-4,0,betternether:quartz_stained_glass:15)
B(6,-4,0,betternether:quartz_stained_glass:15)
B(7,-4,0,betternether:quartz_stained_glass:15)
B(8,-4,0,betternether:quartz_stained_glass:15)
B(9,-4,0,betternether:quartz_stained_glass:15)
B(10,-4,0,betternether:quartz_stained_glass:15)
B(11,-4,0,betternether:quartz_stained_glass:15)
B(6,-4,1,betternether:quartz_stained_glass:15)
B(7,-4,1,betternether:quartz_stained_glass:15)
B(8,-4,1,betternether:quartz_stained_glass:15)
B(9,-4,1,betternether:quartz_stained_glass:15)
B(6,-4,2,betternether:quartz_stained_glass:15)
B(7,-4,2,betternether:quartz_stained_glass:15)
B(8,-4,2,betternether:quartz_stained_glass:15)
B(6,-3,0,betternether:quartz_stained_glass:15)

#######################################################################
# +-----------------------------------------------------------------+ #
# |                             Branches                            | #
# +-----------------------------------------------------------------+ #
#######################################################################

BR(0,0,16,true,CEILING_SPIKE-SET-DIAG-THIN-04_0x2,NORTH,100,0)
BR(16,0,0,true,CEILING_SPIKE-SET-DIAG-THIN-04_1x1,NORTH,100,0)
