
#######################################################################
# +-----------------------------------------------------------------+ #
# |                            BO4 object                           | #
# +-----------------------------------------------------------------+ #
#######################################################################

Author: NLBlackEagle

Description: No description given

SettingsMode: WriteDisable


#######################################################################
# +-----------------------------------------------------------------+ #
# |                          Main settings                          | #
# +-----------------------------------------------------------------+ #
#######################################################################

Frequency: 0

SpawnHeight: highestBlock

UseCenterForHighestBlock: true

##############################
# Height Limits for the BO4. #
##############################

MinHeight: 0

MaxHeight: 255

InheritBO3: 

InheritBO3Rotation: NORTH

OverrideChildSettings: true

OverrideParentHeight: false

CanOverride: false

BranchFrequency: 0

BranchFrequencyGroup: 

MustBeBelowOther: false

MustBeInside: 

CannotBeInside: 

ReplacesBO3: 

MustBeInsideWorldBorders: false

CanSpawnOnWater: true

SpawnOnWaterOnly: false

SpawnUnderWater: false

SpawnAtWaterLevel: false

HeightOffset: 0

RemoveAir: true

ReplaceAbove: 

ReplaceBelow: 

ReplaceWithBiomeBlocks: true

ReplaceWithSurfaceBlock: GRASS

ReplaceWithGroundBlock: DIRT

ReplaceWithStoneBlock: STONE

SmoothRadius: 0

SmoothHeightOffset: 0

SmoothStartTop: false

SmoothStartWood: false

SmoothingSurfaceBlock: 

SmoothingGroundBlock: 

BO3Group: 

IsSpawnPoint: false

DoReplaceBlocks: true


#######################################################################
# +-----------------------------------------------------------------+ #
# |                              Blocks                             | #
# +-----------------------------------------------------------------+ #
#######################################################################

Block(-8,-5,4,LOG:13)
Block(-8,-4,4,LOG:13)
Block(-8,-3,4,LOG:13)
Block(-8,-2,4,LOG:13)
Block(-8,-2,5,LOG:13)
Block(-8,-1,8,LOG_2:13)
Block(-8,0,8,LOG:13)
Block(-8,1,7,LOG:13)
Block(-8,1,8,LOG_2:13)
Block(-8,2,8,LOG:13)
Block(-8,3,8,LOG:13)
Block(-7,-6,2,LOG:13)
Block(-7,-5,2,LOG:13)
Block(-7,-4,2,LOG:13)
Block(-7,-3,2,LOG:13)
Block(-7,-2,2,LOG:13)
Block(-7,-2,3,LOG_2:13)
Block(-7,-2,4,LOG:13)
Block(-7,0,8,LOG_2:13)
Block(-7,1,6,LOG_2:13)
Block(-7,1,7,minecraft:black_glazed_terracotta:3)
Block(-7,1,8,LOG_2:13)
Block(-7,2,7,minecraft:black_glazed_terracotta:3)
Block(-7,2,8,LOG:13)
Block(-6,-4,5,LOG:13)
Block(-6,-3,5,LOG:13)
Block(-6,-2,5,LOG:13)
Block(-6,-1,5,LOG:13)
Block(-6,0,5,LOG:13)
Block(-6,1,5,minecraft:black_glazed_terracotta:3)
Block(-6,1,8,LOG_2:13)
Block(-5,0,3,minecraft:black_glazed_terracotta:3)
Block(-5,0,4,LOG:13)
Block(-5,1,4,minecraft:black_glazed_terracotta:3)
Block(-5,13,3,LEAVES:12)
Block(-5,14,2,LEAVES:12)
Block(-5,14,3,LEAVES:12)
Block(-5,14,4,LEAVES:12)
Block(-5,15,3,LEAVES:12)
Block(-4,-4,2,LOG:13)
Block(-4,-3,2,LOG:13)
Block(-4,-2,2,LOG:13)
Block(-4,-1,2,LOG_2:13)
Block(-4,0,2,minecraft:black_glazed_terracotta:3)
Block(-4,0,3,LOG_2:13)
Block(-4,1,8,LOG:13)
Block(-4,11,4,LEAVES:12)
Block(-4,12,4,LEAVES:12)
Block(-4,13,2,LEAVES:12)
Block(-4,13,3,LEAVES:12)
Block(-4,13,4,LEAVES:12)
Block(-4,14,0,LEAVES:12)
Block(-4,14,1,LEAVES:12)
Block(-4,14,2,LEAVES:12)
Block(-4,14,3,LEAVES:12)
Block(-4,14,4,LEAVES:12)
Block(-4,14,5,LEAVES:12)
Block(-4,15,2,LEAVES:12)
Block(-4,15,3,LEAVES:12)
Block(-4,15,4,LEAVES:12)
Block(-3,-6,5,LOG:13)
Block(-3,-5,5,LOG:13)
Block(-3,-4,5,LOG:13)
Block(-3,-3,5,LOG:13)
Block(-3,-2,1,LOG:13)
Block(-3,-1,1,minecraft:black_glazed_terracotta:3)
Block(-3,-1,2,LOG_2:13)
Block(-3,1,8,LOG:13)
Block(-3,2,8,LOG:13)
Block(-3,3,8,LOG_2:13)
Block(-3,13,1,LEAVES:12)
Block(-3,13,2,LOG:13)
Block(-3,13,3,LEAVES:12)
Block(-3,13,4,LEAVES:12)
Block(-3,13,5,LEAVES:12)
Block(-3,14,1,LEAVES:12)
Block(-3,14,2,LEAVES:12)
Block(-3,14,3,LEAVES:12)
Block(-3,14,4,LEAVES:12)
Block(-3,14,5,LEAVES:12)
Block(-3,14,6,LEAVES:12)
Block(-3,15,1,LEAVES:12)
Block(-3,15,2,LEAVES:12)
Block(-3,15,3,LEAVES:12)
Block(-3,15,4,LEAVES:12)
Block(-3,15,5,LEAVES:12)
Block(-2,-6,0,LOG:13)
Block(-2,-5,0,LOG:13)
Block(-2,-4,0,LOG:13)
Block(-2,-3,0,minecraft:black_glazed_terracotta:3)
Block(-2,-3,5,LOG:13)
Block(-2,-3,6,LOG:13)
Block(-2,-2,0,minecraft:black_glazed_terracotta:3)
Block(-2,-2,1,minecraft:black_glazed_terracotta:3)
Block(-2,-2,6,LOG:13)
Block(-2,0,8,LOG:13)
Block(-2,1,7,LOG:13)
Block(-2,1,8,LOG:13)
Block(-2,2,8,LOG:13)
Block(-2,3,8,LOG_2:13)
Block(-2,4,8,minecraft:black_glazed_terracotta:3)
Block(-2,5,8,minecraft:black_glazed_terracotta:3)
Block(-2,6,8,LOG_2:13)
Block(-2,7,8,LEAVES:12)
Block(-2,9,4,LEAVES:12)
Block(-2,10,4,LEAVES:12)
Block(-2,10,8,LEAVES:12)
Block(-2,11,4,LEAVES:12)
Block(-2,12,3,LEAVES:12)
Block(-2,12,4,LEAVES:12)
Block(-2,13,2,LEAVES:12)
Block(-2,13,3,LOG:13)
Block(-2,13,4,LEAVES:12)
Block(-2,13,5,LEAVES:12)
Block(-2,14,0,LEAVES:12)
Block(-2,14,1,LEAVES:12)
Block(-2,14,2,LEAVES:12)
Block(-2,14,3,LEAVES:12)
Block(-2,14,4,LEAVES:12)
Block(-2,14,5,LEAVES:12)
Block(-2,14,6,LEAVES:12)
Block(-2,14,7,LEAVES:12)
Block(-2,15,1,LEAVES:12)
Block(-2,15,2,LEAVES:12)
Block(-2,15,3,LEAVES:12)
Block(-2,15,4,LEAVES:12)
Block(-2,15,5,LEAVES:12)
Block(-1,-3,6,LOG:13)
Block(-1,-3,7,LOG:13)
Block(-1,-2,7,LOG:13)
Block(-1,1,7,LOG_2:13)
Block(-1,1,8,LOG:13)
Block(-1,2,7,LOG:13)
Block(-1,2,8,LOG:13)
Block(-1,3,8,minecraft:black_glazed_terracotta:3)
Block(-1,4,8,minecraft:black_glazed_terracotta:3)
Block(-1,9,8,LEAVES:12)
Block(-1,10,6,LEAVES:12)
Block(-1,10,8,LOG:13)
Block(-1,11,6,LEAVES:12)
Block(-1,11,7,LEAVES:12)
Block(-1,11,8,LOG:13)
Block(-1,12,5,LEAVES:12)
Block(-1,12,6,LEAVES:12)
Block(-1,12,7,LEAVES:12)
Block(-1,13,0,LEAVES:12)
Block(-1,13,1,LEAVES:12)
Block(-1,13,2,LEAVES:12)
Block(-1,13,3,LEAVES:12)
Block(-1,13,4,LOG:13)
Block(-1,13,5,LEAVES:12)
Block(-1,13,6,LEAVES:12)
Block(-1,13,7,LEAVES:12)
Block(-1,13,8,LEAVES:12)
Block(-1,14,-1,LEAVES:12)
Block(-1,14,0,LEAVES:12)
Block(-1,14,1,LEAVES:12)
Block(-1,14,2,LEAVES:12)
Block(-1,14,3,LEAVES:12)
Block(-1,14,4,LEAVES:12)
Block(-1,14,5,LEAVES:12)
Block(-1,14,6,LEAVES:12)
Block(-1,14,7,LEAVES:12)
Block(-1,15,0,LEAVES:12)
Block(-1,15,1,LEAVES:12)
Block(-1,15,2,LEAVES:12)
Block(-1,15,3,LEAVES:12)
Block(-1,15,4,LEAVES:12)
Block(-1,15,5,LEAVES:12)
Block(-1,15,6,LEAVES:12)
Block(0,-6,7,LOG:13)
Block(0,-5,7,LOG:13)
Block(0,-4,7,LOG:13)
Block(0,-3,7,LOG:13)
Block(0,-2,7,LOG:13)
Block(0,-2,8,LOG:13)
Block(0,-1,7,LOG:13)
Block(0,-1,8,LOG:13)
Block(0,0,6,LOG:13)
Block(0,0,7,LOG_2:13)
Block(0,0,8,LOG_2:13)
Block(0,1,6,LOG:13)
Block(0,1,7,LOG:13)
Block(0,1,8,LOG:13)
Block(0,2,7,minecraft:black_glazed_terracotta:3)
Block(0,2,8,LOG:13)
Block(0,3,7,minecraft:black_glazed_terracotta:3)
Block(0,3,8,LOG:13)
Block(0,4,8,LOG:13)
Block(0,9,8,LOG:13)
Block(0,10,8,LOG:13)
Block(0,11,7,LOG:13)
Block(0,11,8,LOG:13)
Block(0,12,2,LEAVES:12)
Block(0,12,4,LEAVES:12)
Block(0,12,6,LEAVES:12)
Block(0,12,7,LOG_2:13)
Block(0,12,8,LEAVES:12)
Block(0,13,-1,LEAVES:12)
Block(0,13,0,LEAVES:12)
Block(0,13,1,LEAVES:12)
Block(0,13,2,LEAVES:12)
Block(0,13,3,LEAVES:12)
Block(0,13,4,LOG:13)
Block(0,13,5,LOG:13)
Block(0,13,6,LEAVES:12)
Block(0,13,7,LEAVES:12)
Block(0,13,8,LEAVES:12)
Block(0,14,-2,LEAVES:12)
Block(0,14,-1,LEAVES:12)
Block(0,14,0,LEAVES:12)
Block(0,14,1,LEAVES:12)
Block(0,14,2,LEAVES:12)
Block(0,14,3,LEAVES:12)
Block(0,14,4,LEAVES:12)
Block(0,14,5,LEAVES:12)
Block(0,14,6,LEAVES:12)
Block(0,14,7,LEAVES:12)
Block(0,14,8,LEAVES:12)
Block(0,15,-1,LEAVES:12)
Block(0,15,0,LEAVES:12)
Block(0,15,1,LEAVES:12)
Block(0,15,2,LEAVES:12)
Block(0,15,3,LEAVES:12)
Block(0,15,4,LEAVES:12)
Block(0,15,5,LEAVES:12)
Block(0,15,6,LEAVES:12)
Block(1,0,7,LOG:13)
Block(1,1,6,LOG_2:13)
Block(1,1,7,LOG:13)
Block(1,1,8,LOG:13)
Block(1,2,6,minecraft:black_glazed_terracotta:3)
Block(1,2,7,LOG:13)
Block(1,2,8,LOG:13)
Block(1,3,7,LOG:13)
Block(1,8,3,LEAVES:12)
Block(1,9,3,LEAVES:12)
Block(1,9,6,LEAVES:12)
Block(1,10,3,LEAVES:12)
Block(1,10,6,LEAVES:12)
Block(1,11,3,LEAVES:12)
Block(1,11,6,LEAVES:12)
Block(1,11,7,LOG:13)
Block(1,11,8,LOG:13)
Block(1,12,3,LEAVES:12)
Block(1,12,5,LEAVES:12)
Block(1,12,6,LOG:13)
Block(1,12,7,LOG:13)
Block(1,12,8,LEAVES:12)
Block(1,13,-2,LEAVES:12)
Block(1,13,-1,LEAVES:12)
Block(1,13,0,LEAVES:12)
Block(1,13,1,LEAVES:12)
Block(1,13,2,LEAVES:12)
Block(1,13,3,LEAVES:12)
Block(1,13,4,LOG:13)
Block(1,13,5,LOG:13)
Block(1,13,6,LOG:13)
Block(1,13,7,LEAVES:12)
Block(1,13,8,LEAVES:12)
Block(1,14,-2,LEAVES:12)
Block(1,14,-1,LEAVES:12)
Block(1,14,0,LEAVES:12)
Block(1,14,1,LEAVES:12)
Block(1,14,2,LEAVES:12)
Block(1,14,3,LEAVES:12)
Block(1,14,4,LEAVES:12)
Block(1,14,5,LEAVES:12)
Block(1,14,6,LEAVES:12)
Block(1,14,7,LEAVES:12)
Block(1,14,8,LEAVES:12)
Block(1,15,-2,LEAVES:12)
Block(1,15,-1,LEAVES:12)
Block(1,15,0,LEAVES:12)
Block(1,15,1,LEAVES:12)
Block(1,15,2,LEAVES:12)
Block(1,15,3,LEAVES:12)
Block(1,15,4,LEAVES:12)
Block(1,15,5,LEAVES:12)
Block(1,15,6,LEAVES:12)
Block(1,15,7,LEAVES:12)
Block(1,15,8,LEAVES:12)
Block(1,16,7,LEAVES:12)
Block(1,16,8,LEAVES:12)
Block(1,17,8,LEAVES:12)
Block(2,0,6,LOG:13)
Block(2,1,5,minecraft:black_glazed_terracotta:3)
Block(2,1,6,LOG_2:13)
Block(2,1,7,LOG:13)
Block(2,1,8,LOG:13)
Block(2,2,6,LOG:13)
Block(2,2,7,LOG:13)
Block(2,10,8,LEAVES:12)
Block(2,11,8,LEAVES:12)
Block(2,12,2,LEAVES:12)
Block(2,12,5,LOG:13)
Block(2,12,7,LEAVES:12)
Block(2,12,8,LEAVES:12)
Block(2,13,-1,LEAVES:12)
Block(2,13,0,LEAVES:12)
Block(2,13,1,LEAVES:12)
Block(2,13,2,LEAVES:12)
Block(2,13,3,LEAVES:12)
Block(2,13,4,LOG:13)
Block(2,13,5,LOG:13)
Block(2,13,6,LEAVES:12)
Block(2,13,7,LEAVES:12)
Block(2,13,8,LEAVES:12)
Block(2,14,-2,LEAVES:12)
Block(2,14,-1,LEAVES:12)
Block(2,14,0,LEAVES:12)
Block(2,14,1,LEAVES:12)
Block(2,14,2,LEAVES:12)
Block(2,14,3,LEAVES:12)
Block(2,14,4,LOG:13)
Block(2,14,5,LEAVES:12)
Block(2,14,6,LEAVES:12)
Block(2,14,7,LEAVES:12)
Block(2,14,8,LEAVES:12)
Block(2,15,-2,LEAVES:12)
Block(2,15,-1,LEAVES:12)
Block(2,15,0,LEAVES:12)
Block(2,15,1,LEAVES:12)
Block(2,15,2,LEAVES:12)
Block(2,15,3,LEAVES:12)
Block(2,15,4,LEAVES:12)
Block(2,15,5,LEAVES:12)
Block(2,15,6,LEAVES:12)
Block(2,15,7,LEAVES:12)
Block(2,15,8,LEAVES:12)
Block(2,16,5,LEAVES:12)
Block(2,16,6,LEAVES:12)
Block(2,16,7,LEAVES:12)
Block(2,16,8,LEAVES:12)
Block(2,17,6,LEAVES:12)
Block(2,17,7,LEAVES:12)
Block(2,17,8,LEAVES:12)
Block(3,-2,6,LOG:13)
Block(3,-1,6,LOG:13)
Block(3,0,5,LOG:13)
Block(3,0,6,LOG_2:13)
Block(3,1,5,minecraft:black_glazed_terracotta:3)
Block(3,1,6,LOG:13)
Block(3,2,5,LOG_2:13)
Block(3,12,4,LEAVES:12)
Block(3,12,6,LEAVES:12)
Block(3,13,-2,LEAVES:12)
Block(3,13,-1,LEAVES:12)
Block(3,13,0,LEAVES:12)
Block(3,13,2,LEAVES:12)
Block(3,13,3,LOG_2:13)
Block(3,13,4,LOG_2:13)
Block(3,13,5,LEAVES:12)
Block(3,13,6,LEAVES:12)
Block(3,13,8,LEAVES:12)
Block(3,14,-2,LEAVES:12)
Block(3,14,-1,LEAVES:12)
Block(3,14,0,LEAVES:12)
Block(3,14,1,LEAVES:12)
Block(3,14,2,LEAVES:12)
Block(3,14,3,LOG_2:13)
Block(3,14,4,LEAVES:12)
Block(3,14,5,LEAVES:12)
Block(3,14,6,LEAVES:12)
Block(3,14,7,LEAVES:12)
Block(3,14,8,LEAVES:12)
Block(3,15,-2,LEAVES:12)
Block(3,15,-1,LEAVES:12)
Block(3,15,0,LEAVES:12)
Block(3,15,1,LEAVES:12)
Block(3,15,2,LEAVES:12)
Block(3,15,3,LEAVES:12)
Block(3,15,4,LEAVES:12)
Block(3,15,5,LEAVES:12)
Block(3,15,6,LEAVES:12)
Block(3,15,7,LEAVES:12)
Block(3,15,8,LOG:13)
Block(3,16,1,LEAVES:12)
Block(3,16,4,LEAVES:12)
Block(3,16,5,LEAVES:12)
Block(3,16,6,LEAVES:12)
Block(3,16,7,LEAVES:12)
Block(3,16,8,LOG_2:13)
Block(3,17,5,LEAVES:12)
Block(3,17,6,LEAVES:12)
Block(3,17,7,LEAVES:12)
Block(3,17,8,LEAVES:12)
Block(4,-3,4,LOG:13)
Block(4,-2,4,LOG:13)
Block(4,-1,4,LOG:13)
Block(4,0,4,minecraft:black_glazed_terracotta:3)
Block(4,0,5,LOG:13)
Block(4,1,4,LOG_2:13)
Block(4,1,5,LOG:13)
Block(4,8,5,LEAVES:12)
Block(4,9,5,LEAVES:12)
Block(4,10,2,LEAVES:12)
Block(4,10,5,LEAVES:12)
Block(4,11,2,LEAVES:12)
Block(4,11,5,LEAVES:12)
Block(4,12,2,LEAVES:12)
Block(4,12,5,LEAVES:12)
Block(4,13,-1,LEAVES:12)
Block(4,13,1,LEAVES:12)
Block(4,13,2,LEAVES:12)
Block(4,13,3,LEAVES:12)
Block(4,13,4,LEAVES:12)
Block(4,13,5,LEAVES:12)
Block(4,13,7,LEAVES:12)
Block(4,14,-2,LEAVES:12)
Block(4,14,-1,LEAVES:12)
Block(4,14,0,LEAVES:12)
Block(4,14,1,LOG:13)
Block(4,14,2,LOG:13)
Block(4,14,3,LEAVES:12)
Block(4,14,4,LEAVES:12)
Block(4,14,5,LEAVES:12)
Block(4,14,6,LEAVES:12)
Block(4,15,-2,LEAVES:12)
Block(4,15,-1,LEAVES:12)
Block(4,15,0,LEAVES:12)
Block(4,15,1,LEAVES:12)
Block(4,15,2,LEAVES:12)
Block(4,15,3,LEAVES:12)
Block(4,15,4,LEAVES:12)
Block(4,15,5,LEAVES:12)
Block(4,15,6,LEAVES:12)
Block(4,16,-1,LEAVES:12)
Block(4,16,0,LEAVES:12)
Block(4,16,1,LEAVES:12)
Block(4,16,2,LEAVES:12)
Block(4,16,3,LEAVES:12)
Block(4,16,4,LEAVES:12)
Block(4,16,5,LEAVES:12)
Block(4,16,6,LEAVES:12)
Block(4,16,7,LOG:13)
Block(4,16,8,LOG:13)
Block(4,17,4,LEAVES:12)
Block(4,17,5,LEAVES:12)
Block(4,17,6,LEAVES:12)
Block(4,17,7,LEAVES:12)
Block(4,17,8,LOG:13)
Block(4,18,8,LEAVES:12)
Block(5,-1,2,LOG_2:13)
Block(5,0,2,minecraft:black_glazed_terracotta:3)
Block(5,0,3,LOG:13)
Block(5,1,3,minecraft:black_glazed_terracotta:3)
Block(5,11,4,LEAVES:12)
Block(5,12,4,LEAVES:12)
Block(5,13,3,LEAVES:12)
Block(5,13,4,LEAVES:12)
Block(5,13,6,LEAVES:12)
Block(5,13,7,LEAVES:12)
Block(5,14,-1,LEAVES:12)
Block(5,14,0,LEAVES:12)
Block(5,14,1,LEAVES:12)
Block(5,14,2,LEAVES:12)
Block(5,14,3,LEAVES:12)
Block(5,14,4,LEAVES:12)
Block(5,14,5,LEAVES:12)
Block(5,14,7,LEAVES:12)
Block(5,15,-3,LEAVES:12)
Block(5,15,-1,LEAVES:12)
Block(5,15,0,LEAVES:12)
Block(5,15,1,LEAVES:12)
Block(5,15,2,LEAVES:12)
Block(5,15,3,LEAVES:12)
Block(5,15,4,LEAVES:12)
Block(5,15,5,LEAVES:12)
Block(5,15,6,LEAVES:12)
Block(5,15,7,LEAVES:12)
Block(5,15,8,LEAVES:12)
Block(5,16,-1,LEAVES:12)
Block(5,16,0,LEAVES:12)
Block(5,16,1,LEAVES:12)
Block(5,16,2,LEAVES:12)
Block(5,16,3,LEAVES:12)
Block(5,16,4,LEAVES:12)
Block(5,16,5,LEAVES:12)
Block(5,16,6,LEAVES:12)
Block(5,16,7,LOG:13)
Block(5,16,8,LEAVES:12)
Block(5,17,5,LEAVES:12)
Block(5,17,6,LEAVES:12)
Block(5,17,7,LEAVES:12)
Block(5,17,8,LEAVES:12)
Block(5,18,6,LEAVES:12)
Block(5,18,7,LEAVES:12)
Block(5,18,8,LEAVES:12)
Block(6,-5,2,LOG:13)
Block(6,-4,2,LOG:13)
Block(6,-3,2,LOG:13)
Block(6,-2,2,LOG:13)
Block(6,-1,1,LOG:13)
Block(6,-1,2,LOG:13)
Block(6,0,1,minecraft:black_glazed_terracotta:3)
Block(6,0,2,LOG:13)
Block(6,13,-1,LEAVES:12)
Block(6,13,0,LEAVES:12)
Block(6,13,1,LEAVES:12)
Block(6,13,2,LEAVES:12)
Block(6,13,7,LEAVES:12)
Block(6,14,-2,LEAVES:12)
Block(6,14,-1,LEAVES:12)
Block(6,14,0,LEAVES:12)
Block(6,14,1,LEAVES:12)
Block(6,14,2,LEAVES:12)
Block(6,14,3,LEAVES:12)
Block(6,14,4,LEAVES:12)
Block(6,14,5,LEAVES:12)
Block(6,14,6,LEAVES:12)
Block(6,15,-1,LEAVES:12)
Block(6,15,0,LEAVES:12)
Block(6,15,1,LEAVES:12)
Block(6,15,2,LEAVES:12)
Block(6,15,3,LEAVES:12)
Block(6,15,4,LEAVES:12)
Block(6,15,5,LEAVES:12)
Block(6,15,6,LEAVES:12)
Block(6,15,8,LEAVES:12)
Block(6,16,0,LEAVES:12)
Block(6,16,1,LEAVES:12)
Block(6,16,2,LEAVES:12)
Block(6,16,3,LEAVES:12)
Block(6,16,4,LEAVES:12)
Block(6,16,5,LEAVES:12)
Block(6,16,6,LOG:13)
Block(6,16,7,LEAVES:12)
Block(6,16,8,LEAVES:12)
Block(6,17,4,LEAVES:12)
Block(6,17,5,LEAVES:12)
Block(6,17,6,LEAVES:12)
Block(6,17,7,LEAVES:12)
Block(6,17,8,LEAVES:12)
Block(6,18,6,LEAVES:12)
Block(6,18,7,LEAVES:12)
Block(6,18,8,LEAVES:12)
Block(7,-1,0,LOG:13)
Block(7,-1,1,LOG_2:13)
Block(7,0,0,minecraft:black_glazed_terracotta:3)
Block(7,0,1,LOG:13)
Block(7,9,1,LEAVES:12)
Block(7,10,1,LEAVES:12)
Block(7,11,1,LEAVES:12)
Block(7,11,7,LEAVES:12)
Block(7,12,1,LEAVES:12)
Block(7,12,7,LEAVES:12)
Block(7,13,-2,LEAVES:12)
Block(7,13,-1,LEAVES:12)
Block(7,13,0,LEAVES:12)
Block(7,13,1,LEAVES:12)
Block(7,13,2,LEAVES:12)
Block(7,13,7,LEAVES:12)
Block(7,14,-2,LEAVES:12)
Block(7,14,-1,LEAVES:12)
Block(7,14,0,LEAVES:12)
Block(7,14,1,LEAVES:12)
Block(7,14,2,LEAVES:12)
Block(7,14,3,LEAVES:12)
Block(7,14,4,LEAVES:12)
Block(7,14,5,LEAVES:12)
Block(7,14,6,LEAVES:12)
Block(7,14,7,LEAVES:12)
Block(7,15,-2,LEAVES:12)
Block(7,15,-1,LEAVES:12)
Block(7,15,0,LEAVES:12)
Block(7,15,1,LEAVES:12)
Block(7,15,2,LEAVES:12)
Block(7,15,3,LEAVES:12)
Block(7,15,4,LEAVES:12)
Block(7,15,5,LEAVES:12)
Block(7,15,6,LEAVES:12)
Block(7,15,7,LEAVES:12)
Block(7,15,8,LEAVES:12)
Block(7,16,1,LEAVES:12)
Block(7,16,2,LEAVES:12)
Block(7,16,3,LEAVES:12)
Block(7,16,4,LEAVES:12)
Block(7,16,5,LOG:13)
Block(7,16,6,LEAVES:12)
Block(7,16,7,LEAVES:12)
Block(7,16,8,LEAVES:12)
Block(7,17,4,LEAVES:12)
Block(7,17,5,LEAVES:12)
Block(7,17,6,LEAVES:12)
Block(7,17,7,LEAVES:12)
Block(7,17,8,LEAVES:12)
Block(7,18,7,LEAVES:12)
Block(7,18,8,LEAVES:12)

#######################################################################
# +-----------------------------------------------------------------+ #
# |                             Branches                            | #
# +-----------------------------------------------------------------+ #
#######################################################################

Branch(16,0,0,true,CherryTreeCorrupted04C2R0,NORTH,100.0,0)

#######################################################################
# +-----------------------------------------------------------------+ #
# |                             Entities                            | #
# +-----------------------------------------------------------------+ #
#######################################################################


#######################################################################
# +-----------------------------------------------------------------+ #
# |                            Particles                            | #
# +-----------------------------------------------------------------+ #
#######################################################################


#######################################################################
# +-----------------------------------------------------------------+ #
# |                             Spawners                            | #
# +-----------------------------------------------------------------+ #
#######################################################################


#######################################################################
# +-----------------------------------------------------------------+ #
# |                             ModData                             | #
# +-----------------------------------------------------------------+ #
#######################################################################

