
#######################################################################
# +-----------------------------------------------------------------+ #
# |                            BO4 object                           | #
# +-----------------------------------------------------------------+ #
#######################################################################

Author: NLBlackEagle

Description: No description given

SettingsMode: WriteDisable


#######################################################################
# +-----------------------------------------------------------------+ #
# |                          Main settings                          | #
# +-----------------------------------------------------------------+ #
#######################################################################

Frequency: 0

SpawnHeight: highestBlock

UseCenterForHighestBlock: true

##############################
# Height Limits for the BO4. #
##############################

MinHeight: 0

MaxHeight: 255

InheritBO3: 

InheritBO3Rotation: NORTH

OverrideChildSettings: true

OverrideParentHeight: false

CanOverride: true

BranchFrequency: 0

BranchFrequencyGroup: 

MustBeBelowOther: false

MustBeInside: 

CannotBeInside: 

ReplacesBO3: 

MustBeInsideWorldBorders: false

CanSpawnOnWater: true

SpawnOnWaterOnly: false

SpawnUnderWater: false

SpawnAtWaterLevel: false

HeightOffset: 0

RemoveAir: true

ReplaceAbove: 

ReplaceBelow: 

ReplaceWithBiomeBlocks: true

ReplaceWithSurfaceBlock: GRASS

ReplaceWithGroundBlock: DIRT

ReplaceWithStoneBlock: STONE

SmoothRadius: 0

SmoothHeightOffset: 0

SmoothStartTop: false

SmoothStartWood: false

SmoothingSurfaceBlock: 

SmoothingGroundBlock: 

BO3Group: 

IsSpawnPoint: false

DoReplaceBlocks: true


#######################################################################
# +-----------------------------------------------------------------+ #
# |                              Blocks                             | #
# +-----------------------------------------------------------------+ #
#######################################################################

Block(-8,0,-7,DIRT:1)
Block(-8,1,-7,DIRT:1)
Block(-7,0,-7,DIRT:1)
Block(-7,0,-6,DIRT:1)
Block(-7,1,-7,DIRT:1)
Block(-7,1,-6,DIRT:1)
Block(-7,2,-7,DIRT:1)
Block(-7,3,-7,DIRT:1)
Block(-7,4,-7,DIRT:1)
Block(-6,0,-7,DIRT:1)
Block(-6,0,-6,DIRT:1)
Block(-6,0,-5,DIRT:1)
Block(-6,0,-4,DIRT:1)
Block(-6,1,-7,DIRT:1)
Block(-6,1,-6,DIRT:1)
Block(-6,1,-5,DIRT:1)
Block(-6,2,-7,DIRT:1)
Block(-6,2,-6,DIRT:1)
Block(-6,2,-5,DIRT:1)
Block(-6,3,-7,DIRT:1)
Block(-6,3,-6,DIRT:1)
Block(-6,4,-7,DIRT:1)
Block(-6,4,-6,DIRT:1)
Block(-6,5,-7,DIRT:1)
Block(-6,6,-7,DIRT:1)
Block(-5,0,-7,DIRT:1)
Block(-5,0,-6,DIRT:1)
Block(-5,0,-5,DIRT:1)
Block(-5,0,-4,DIRT:1)
Block(-5,0,-3,DIRT:1)
Block(-5,1,-7,DIRT:1)
Block(-5,1,-6,DIRT:1)
Block(-5,1,-5,DIRT:1)
Block(-5,1,-4,DIRT:1)
Block(-5,2,-7,DIRT:1)
Block(-5,2,-6,DIRT:1)
Block(-5,2,-5,DIRT:1)
Block(-5,2,-4,DIRT:1)
Block(-5,3,-7,DIRT:1)
Block(-5,3,-6,DIRT:1)
Block(-5,3,-5,DIRT:1)
Block(-5,3,-4,DIRT:1)
Block(-5,4,-7,DIRT:1)
Block(-5,4,-6,DIRT:1)
Block(-5,4,-5,DIRT:1)
Block(-5,5,-7,DIRT:1)
Block(-5,5,-6,DIRT:1)
Block(-5,5,-5,DIRT:1)
Block(-5,6,-7,DIRT:1)
Block(-5,6,-6,DIRT:1)
Block(-5,7,-7,DIRT:1)
Block(-5,7,-6,DIRT:1)
Block(-5,8,-7,DIRT:1)
Block(-5,9,-7,DIRT:1)
Block(-4,0,-7,DIRT:1)
Block(-4,0,-6,DIRT:1)
Block(-4,0,-5,DIRT:1)
Block(-4,0,-4,DIRT:1)
Block(-4,0,-3,DIRT:1)
Block(-4,0,-2,DIRT:1)
Block(-4,1,-7,DIRT:1)
Block(-4,1,-6,DIRT:1)
Block(-4,1,-5,DIRT:1)
Block(-4,1,-4,DIRT:1)
Block(-4,1,-3,DIRT:1)
Block(-4,1,-2,DIRT:1)
Block(-4,2,-7,DIRT:1)
Block(-4,2,-6,DIRT:1)
Block(-4,2,-5,DIRT:1)
Block(-4,2,-4,DIRT:1)
Block(-4,2,-3,DIRT:1)
Block(-4,3,-7,DIRT:1)
Block(-4,3,-6,DIRT:1)
Block(-4,3,-5,DIRT:1)
Block(-4,3,-4,DIRT:1)
Block(-4,3,-3,DIRT:1)
Block(-4,4,-7,DIRT:1)
Block(-4,4,-6,DIRT:1)
Block(-4,4,-5,DIRT:1)
Block(-4,4,-4,DIRT:1)
Block(-4,5,-7,DIRT:1)
Block(-4,5,-6,DIRT:1)
Block(-4,5,-5,DIRT:1)
Block(-4,5,-4,DIRT:1)
Block(-4,6,-7,DIRT:1)
Block(-4,6,-6,DIRT:1)
Block(-4,6,-5,DIRT:1)
Block(-4,7,-7,DIRT:1)
Block(-4,7,-6,DIRT:1)
Block(-4,8,-7,DIRT:1)
Block(-3,0,-7,DIRT:1)
Block(-3,0,-6,DIRT:1)
Block(-3,0,-5,DIRT:1)
Block(-3,0,-4,DIRT:1)
Block(-3,0,-3,DIRT:1)
Block(-3,0,-2,DIRT:1)
Block(-3,0,-1,DIRT:1)
Block(-3,0,0,DIRT:1)
Block(-3,1,-7,DIRT:1)
Block(-3,1,-6,DIRT:1)
Block(-3,1,-5,DIRT:1)
Block(-3,1,-4,DIRT:1)
Block(-3,1,-3,DIRT:1)
Block(-3,1,-2,DIRT:1)
Block(-3,1,-1,DIRT:1)
Block(-3,2,-7,DIRT:1)
Block(-3,2,-6,DIRT:1)
Block(-3,2,-5,DIRT:1)
Block(-3,2,-4,DIRT:1)
Block(-3,2,-3,DIRT:1)
Block(-3,2,-2,DIRT:1)
Block(-3,3,-7,DIRT:1)
Block(-3,3,-6,DIRT:1)
Block(-3,3,-5,DIRT:1)
Block(-3,3,-4,DIRT:1)
Block(-3,3,-3,DIRT:1)
Block(-3,4,-7,DIRT:1)
Block(-3,4,-6,DIRT:1)
Block(-3,4,-5,DIRT:1)
Block(-3,4,-4,DIRT:1)
Block(-3,5,-7,DIRT:1)
Block(-3,5,-6,DIRT:1)
Block(-3,5,-5,DIRT:1)
Block(-3,6,-7,DIRT:1)
Block(-3,6,-6,DIRT:1)
Block(-3,7,-7,DIRT:1)
Block(-2,0,-7,STAINED_CLAY:0)
Block(-2,0,-6,DIRT:1)
Block(-2,0,-5,DIRT:1)
Block(-2,0,-4,DIRT:1)
Block(-2,0,-3,DIRT:1)
Block(-2,0,-2,DIRT:1)
Block(-2,1,-7,STAINED_CLAY:0)
Block(-2,1,-6,DIRT:1)
Block(-2,1,-5,DIRT:1)
Block(-2,1,-4,DIRT:1)
Block(-2,1,-3,DIRT:1)
Block(-2,2,-7,DIRT:1)
Block(-2,2,-6,DIRT:1)
Block(-2,2,-5,DIRT:1)
Block(-2,2,-4,DIRT:1)
Block(-2,3,-7,DIRT:1)
Block(-2,3,-6,DIRT:1)
Block(-2,3,-5,DIRT:1)
Block(-2,4,-7,DIRT:1)
Block(-2,4,-6,DIRT:1)
Block(-2,5,-7,DIRT:1)
Block(-1,0,-7,STAINED_CLAY:0)
Block(-1,0,-6,STAINED_CLAY:0)
Block(-1,0,-5,DIRT:1)
Block(-1,0,-4,DIRT:1)
Block(-1,1,-7,STAINED_CLAY:0)
Block(-1,1,-6,STAINED_CLAY:0)
Block(-1,1,-5,DIRT:1)
Block(-1,2,-7,STAINED_CLAY:0)
Block(-1,2,-6,STAINED_CLAY:0)
Block(-1,3,-7,STAINED_CLAY:0)
Block(0,0,-7,STAINED_CLAY:0)
Block(0,0,-6,STAINED_CLAY:0)
Block(0,1,-7,STAINED_CLAY:0)

#######################################################################
# +-----------------------------------------------------------------+ #
# |                             Branches                            | #
# +-----------------------------------------------------------------+ #
#######################################################################


#######################################################################
# +-----------------------------------------------------------------+ #
# |                             Entities                            | #
# +-----------------------------------------------------------------+ #
#######################################################################


#######################################################################
# +-----------------------------------------------------------------+ #
# |                            Particles                            | #
# +-----------------------------------------------------------------+ #
#######################################################################


#######################################################################
# +-----------------------------------------------------------------+ #
# |                             Spawners                            | #
# +-----------------------------------------------------------------+ #
#######################################################################


#######################################################################
# +-----------------------------------------------------------------+ #
# |                             ModData                             | #
# +-----------------------------------------------------------------+ #
#######################################################################

