#######################################################################
# +-----------------------------------------------------------------+ #
# |                            BO3 object                           | #
# +-----------------------------------------------------------------+ #
#######################################################################

Author: Bo3 BulkEdit

Description: Converted Schematic - Modified by Bo3BulkEdit

Version: 3

SettingsMode: WriteDisable

#######################################################################
# +-----------------------------------------------------------------+ #
# |                          Main settings                          | #
# +-----------------------------------------------------------------+ #
#######################################################################



Frequency: 0


SpawnHeight: randomY





##############################
# Height Limits for the BO3. #
##############################

MinHeight: 0
MaxHeight: 256

#######################################################################
# +-----------------------------------------------------------------+ #
# |                      Source block settings                      | #
# +-----------------------------------------------------------------+ #
#######################################################################

CanOverride: true
MaxPercentageOutsideSourceBlock: 100
OutsideSourceBlock: placeAnyway

#######################################################################
# +-----------------------------------------------------------------+ #
# |                               OTG+                              | #
# +-----------------------------------------------------------------+ #
#######################################################################

#######################################################################
# +-----------------------------------------------------------------+ #
# |                              Blocks                             | #
# +-----------------------------------------------------------------+ #
#######################################################################

B(0,750,0,AIR)
B(15,750,15,AIR)
B(9,15,15,betternether:quartz_stained_glass:15)
B(10,15,15,betternether:quartz_stained_glass:15)
B(10,16,14,betternether:quartz_stained_glass:15)
B(7,16,15,betternether:quartz_stained_glass:15)
B(8,16,15,betternether:quartz_stained_glass:15)
B(9,16,15,betternether:quartz_stained_glass:15)
B(10,16,15,betternether:quartz_stained_glass:15)
B(11,16,15,betternether:quartz_stained_glass:15)
B(9,17,13,betternether:quartz_stained_glass:15)
B(10,17,13,betternether:quartz_stained_glass:15)
B(7,17,14,betternether:quartz_stained_glass:15)
B(8,17,14,betternether:quartz_stained_glass:15)
B(9,17,14,betternether:quartz_stained_glass:15)
B(10,17,14,betternether:quartz_stained_glass:15)
B(5,17,15,betternether:quartz_stained_glass:15)
B(6,17,15,betternether:quartz_stained_glass:15)
B(7,17,15,betternether:quartz_stained_glass:15)
B(8,17,15,betternether:quartz_stained_glass:15)
B(9,17,15,betternether:quartz_stained_glass:15)
B(10,17,15,betternether:quartz_stained_glass:15)
B(11,17,15,betternether:quartz_stained_glass:15)
B(7,18,13,betternether:quartz_stained_glass:15)
B(8,18,13,betternether:quartz_stained_glass:15)
B(9,18,13,betternether:quartz_stained_glass:15)
B(10,18,13,betternether:quartz_stained_glass:15)
B(6,18,14,betternether:quartz_stained_glass:15)
B(7,18,14,betternether:quartz_stained_glass:15)
B(8,18,14,betternether:quartz_stained_glass:15)
B(9,18,14,betternether:quartz_stained_glass:15)
B(10,18,14,betternether:quartz_stained_glass:15)
B(5,18,15,betternether:quartz_stained_glass:15)
B(6,18,15,betternether:quartz_stained_glass:15)
B(7,18,15,betternether:quartz_stained_glass:15)
B(8,18,15,betternether:quartz_stained_glass:15)
B(9,18,15,betternether:quartz_stained_glass:15)
B(10,18,15,betternether:quartz_stained_glass:15)
B(11,18,15,betternether:quartz_stained_glass:15)
B(7,19,12,betternether:quartz_stained_glass:15)
B(8,19,12,betternether:quartz_stained_glass:15)
B(9,19,12,betternether:quartz_stained_glass:15)
B(10,19,12,betternether:quartz_stained_glass:15)
B(6,19,13,betternether:quartz_stained_glass:15)
B(7,19,13,betternether:quartz_stained_glass:15)
B(8,19,13,betternether:quartz_stained_glass:15)
B(9,19,13,betternether:quartz_stained_glass:15)
B(10,19,13,betternether:quartz_stained_glass:15)
B(5,19,14,betternether:quartz_stained_glass:15)
B(6,19,14,betternether:quartz_stained_glass:15)
B(7,19,14,betternether:quartz_stained_glass:15)
B(8,19,14,betternether:quartz_stained_glass:15)
B(9,19,14,betternether:quartz_stained_glass:15)
B(10,19,14,betternether:quartz_stained_glass:15)
B(5,19,15,betternether:quartz_stained_glass:15)
B(6,19,15,betternether:quartz_stained_glass:15)
B(7,19,15,betternether:quartz_stained_glass:15)
B(8,19,15,betternether:quartz_stained_glass:15)
B(9,19,15,betternether:quartz_stained_glass:15)
B(10,19,15,betternether:quartz_stained_glass:15)
B(11,19,15,betternether:quartz_stained_glass:15)
B(8,20,10,betternether:quartz_stained_glass:15)
B(7,20,11,betternether:quartz_stained_glass:15)
B(8,20,11,betternether:quartz_stained_glass:15)
B(9,20,11,betternether:quartz_stained_glass:15)
B(4,20,12,betternether:quartz_stained_glass:15)
B(5,20,12,betternether:quartz_stained_glass:15)
B(6,20,12,betternether:quartz_stained_glass:15)
B(7,20,12,betternether:quartz_stained_glass:15)
B(8,20,12,betternether:quartz_stained_glass:15)
B(9,20,12,betternether:quartz_stained_glass:15)
B(10,20,12,betternether:quartz_stained_glass:15)
B(4,20,13,betternether:quartz_stained_glass:15)
B(5,20,13,betternether:quartz_stained_glass:15)
B(6,20,13,betternether:quartz_stained_glass:15)
B(7,20,13,betternether:quartz_stained_glass:15)
B(8,20,13,betternether:quartz_stained_glass:15)
B(9,20,13,betternether:quartz_stained_glass:15)
B(10,20,13,betternether:quartz_stained_glass:15)
B(5,20,14,betternether:quartz_stained_glass:15)
B(6,20,14,betternether:quartz_stained_glass:15)
B(7,20,14,betternether:quartz_stained_glass:15)
B(8,20,14,betternether:quartz_stained_glass:15)
B(9,20,14,betternether:quartz_stained_glass:15)
B(10,20,14,betternether:quartz_stained_glass:15)
B(5,20,15,betternether:quartz_stained_glass:15)
B(6,20,15,betternether:quartz_stained_glass:15)
RB(7,20,15,srparasites:parasitestain:1,80,quark:crystal:1,30,srparasites:parasiterubbledense:1,100)
RB(8,20,15,srparasites:parasitestain:1,80,quark:crystal:1,30,srparasites:parasiterubbledense:1,100)
RB(9,20,15,srparasites:parasitestain:1,80,quark:crystal:1,30,srparasites:parasiterubbledense:1,100)
RB(10,20,15,srparasites:parasitestain:1,80,quark:crystal:1,30,srparasites:parasiterubbledense:1,100)
B(11,20,15,betternether:quartz_stained_glass:15)
B(7,21,10,betternether:quartz_stained_glass:15)
B(8,21,10,betternether:quartz_stained_glass:15)
B(5,21,11,betternether:quartz_stained_glass:15)
B(6,21,11,betternether:quartz_stained_glass:15)
B(7,21,11,betternether:quartz_stained_glass:15)
B(8,21,11,betternether:quartz_stained_glass:15)
B(9,21,11,betternether:quartz_stained_glass:15)
B(4,21,12,betternether:quartz_stained_glass:15)
B(5,21,12,betternether:quartz_stained_glass:15)
B(6,21,12,betternether:quartz_stained_glass:15)
B(7,21,12,betternether:quartz_stained_glass:15)
B(8,21,12,betternether:quartz_stained_glass:15)
B(9,21,12,betternether:quartz_stained_glass:15)
B(10,21,12,betternether:quartz_stained_glass:15)
B(4,21,13,betternether:quartz_stained_glass:15)
B(5,21,13,betternether:quartz_stained_glass:15)
B(6,21,13,betternether:quartz_stained_glass:15)
RB(7,21,13,srparasites:parasitestain:1,80,quark:crystal:1,30,srparasites:parasiterubbledense:1,100)
B(8,21,13,betternether:quartz_stained_glass:15)
B(9,21,13,betternether:quartz_stained_glass:15)
B(10,21,13,betternether:quartz_stained_glass:15)
B(5,21,14,betternether:quartz_stained_glass:15)
B(6,21,14,betternether:quartz_stained_glass:15)
B(7,21,14,betternether:quartz_stained_glass:15)
B(8,21,14,betternether:quartz_stained_glass:15)
RB(9,21,14,srparasites:parasitestain:1,80,quark:crystal:1,30,srparasites:parasiterubbledense:1,100)
B(10,21,14,betternether:quartz_stained_glass:15)
B(5,21,15,betternether:quartz_stained_glass:15)
RB(6,21,15,srparasites:parasitestain:1,80,quark:crystal:1,30,srparasites:parasiterubbledense:1,100)
RB(7,21,15,srparasites:parasitestain:1,80,quark:crystal:1,30,srparasites:parasiterubbledense:1,100)
RB(8,21,15,srparasites:parasitestain:1,80,quark:crystal:1,30,srparasites:parasiterubbledense:1,100)
B(9,21,15,betternether:quartz_stained_glass:15)
B(10,21,15,betternether:quartz_stained_glass:15)
B(11,21,15,betternether:quartz_stained_glass:15)
B(5,22,9,betternether:quartz_stained_glass:15)
B(6,22,9,betternether:quartz_stained_glass:15)
B(7,22,9,betternether:quartz_stained_glass:15)
B(8,22,9,betternether:quartz_stained_glass:15)
B(4,22,10,betternether:quartz_stained_glass:15)
B(5,22,10,betternether:quartz_stained_glass:15)
B(6,22,10,betternether:quartz_stained_glass:15)
B(7,22,10,betternether:quartz_stained_glass:15)
B(8,22,10,betternether:quartz_stained_glass:15)
B(3,22,11,betternether:quartz_stained_glass:15)
B(4,22,11,betternether:quartz_stained_glass:15)
B(5,22,11,betternether:quartz_stained_glass:15)
B(6,22,11,betternether:quartz_stained_glass:15)
B(7,22,11,betternether:quartz_stained_glass:15)
B(8,22,11,betternether:quartz_stained_glass:15)
B(9,22,11,betternether:quartz_stained_glass:15)
B(3,22,12,betternether:quartz_stained_glass:15)
B(4,22,12,betternether:quartz_stained_glass:15)
B(5,22,12,betternether:quartz_stained_glass:15)
RB(6,22,12,srparasites:parasitestain:1,80,quark:crystal:1,30,srparasites:parasiterubbledense:1,100)
B(7,22,12,betternether:quartz_stained_glass:15)
B(8,22,12,betternether:quartz_stained_glass:15)
B(9,22,12,betternether:quartz_stained_glass:15)
B(10,22,12,betternether:quartz_stained_glass:15)
B(4,22,13,betternether:quartz_stained_glass:15)
B(5,22,13,betternether:quartz_stained_glass:15)
B(6,22,13,betternether:quartz_stained_glass:15)
RB(7,22,13,srparasites:parasitestain:1,80,quark:crystal:1,30,srparasites:parasiterubbledense:1,100)
RB(8,22,13,srparasites:parasitestain:1,80,quark:crystal:1,30,srparasites:parasiterubbledense:1,100)
B(9,22,13,betternether:quartz_stained_glass:15)
B(10,22,13,betternether:quartz_stained_glass:15)
B(5,22,14,betternether:quartz_stained_glass:15)
RB(6,22,14,srparasites:parasitestain:1,80,quark:crystal:1,30,srparasites:parasiterubbledense:1,100)
RB(7,22,14,srparasites:parasitestain:1,80,quark:crystal:1,30,srparasites:parasiterubbledense:1,100)
RB(8,22,14,srparasites:parasitestain:1,80,quark:crystal:1,30,srparasites:parasiterubbledense:1,100)
B(9,22,14,betternether:quartz_stained_glass:15)
B(10,22,14,betternether:quartz_stained_glass:15)
B(5,22,15,betternether:quartz_stained_glass:15)
B(6,22,15,betternether:quartz_stained_glass:15)
B(7,22,15,betternether:quartz_stained_glass:15)
B(8,22,15,betternether:quartz_stained_glass:15)
B(9,22,15,betternether:quartz_stained_glass:15)
B(10,22,15,betternether:quartz_stained_glass:15)
B(11,22,15,betternether:quartz_stained_glass:15)
B(7,23,8,betternether:quartz_stained_glass:15)
B(8,23,8,betternether:quartz_stained_glass:15)
B(4,23,9,betternether:quartz_stained_glass:15)
B(5,23,9,betternether:quartz_stained_glass:15)
B(6,23,9,betternether:quartz_stained_glass:15)
B(7,23,9,betternether:quartz_stained_glass:15)
B(8,23,9,betternether:quartz_stained_glass:15)
B(3,23,10,betternether:quartz_stained_glass:15)
B(4,23,10,betternether:quartz_stained_glass:15)
B(5,23,10,betternether:quartz_stained_glass:15)
B(6,23,10,betternether:quartz_stained_glass:15)
B(7,23,10,betternether:quartz_stained_glass:15)
B(8,23,10,betternether:quartz_stained_glass:15)
B(3,23,11,betternether:quartz_stained_glass:15)
B(4,23,11,betternether:quartz_stained_glass:15)
B(5,23,11,betternether:quartz_stained_glass:15)
B(6,23,11,betternether:quartz_stained_glass:15)
B(7,23,11,betternether:quartz_stained_glass:15)
B(8,23,11,betternether:quartz_stained_glass:15)
B(9,23,11,betternether:quartz_stained_glass:15)
B(3,23,12,betternether:quartz_stained_glass:15)
B(4,23,12,betternether:quartz_stained_glass:15)
B(5,23,12,betternether:quartz_stained_glass:15)
RB(6,23,12,srparasites:parasitestain:1,80,quark:crystal:1,30,srparasites:parasiterubbledense:1,100)
RB(7,23,12,srparasites:parasitestain:1,80,quark:crystal:1,30,srparasites:parasiterubbledense:1,100)
B(8,23,12,betternether:quartz_stained_glass:15)
B(9,23,12,betternether:quartz_stained_glass:15)
B(10,23,12,betternether:quartz_stained_glass:15)
B(4,23,13,betternether:quartz_stained_glass:15)
B(5,23,13,betternether:quartz_stained_glass:15)
RB(6,23,13,srparasites:parasitestain:1,80,quark:crystal:1,30,srparasites:parasiterubbledense:1,100)
RB(7,23,13,srparasites:parasitestain:1,80,quark:crystal:1,30,srparasites:parasiterubbledense:1,100)
RB(8,23,13,srparasites:parasitestain:1,80,quark:crystal:1,30,srparasites:parasiterubbledense:1,100)
B(9,23,13,betternether:quartz_stained_glass:15)
B(10,23,13,betternether:quartz_stained_glass:15)
B(5,23,14,betternether:quartz_stained_glass:15)
RB(6,23,14,srparasites:parasitestain:1,80,quark:crystal:1,30,srparasites:parasiterubbledense:1,100)
B(7,23,14,betternether:quartz_stained_glass:15)
B(8,23,14,betternether:quartz_stained_glass:15)
B(9,23,14,betternether:quartz_stained_glass:15)
B(10,23,14,betternether:quartz_stained_glass:15)
B(5,23,15,betternether:quartz_stained_glass:15)
B(6,23,15,betternether:quartz_stained_glass:15)
B(7,23,15,betternether:quartz_stained_glass:15)
B(8,23,15,betternether:quartz_stained_glass:15)
B(9,23,15,betternether:quartz_stained_glass:15)
B(10,23,15,betternether:quartz_stained_glass:15)
B(11,23,15,betternether:quartz_stained_glass:15)
B(5,24,8,betternether:quartz_stained_glass:15)
B(6,24,8,betternether:quartz_stained_glass:15)
B(7,24,8,betternether:quartz_stained_glass:15)
B(8,24,8,betternether:quartz_stained_glass:15)
B(3,24,9,betternether:quartz_stained_glass:15)
B(4,24,9,betternether:quartz_stained_glass:15)
B(5,24,9,betternether:quartz_stained_glass:15)
B(6,24,9,betternether:quartz_stained_glass:15)
B(7,24,9,betternether:quartz_stained_glass:15)
B(8,24,9,betternether:quartz_stained_glass:15)
B(3,24,10,betternether:quartz_stained_glass:15)
B(4,24,10,betternether:quartz_stained_glass:15)
B(5,24,10,betternether:quartz_stained_glass:15)
B(6,24,10,betternether:quartz_stained_glass:15)
B(7,24,10,betternether:quartz_stained_glass:15)
B(8,24,10,betternether:quartz_stained_glass:15)
B(3,24,11,betternether:quartz_stained_glass:15)
B(4,24,11,betternether:quartz_stained_glass:15)
B(5,24,11,betternether:quartz_stained_glass:15)
RB(6,24,11,srparasites:parasitestain:1,80,quark:crystal:1,30,srparasites:parasiterubbledense:1,100)
B(7,24,11,betternether:quartz_stained_glass:15)
B(8,24,11,betternether:quartz_stained_glass:15)
B(9,24,11,betternether:quartz_stained_glass:15)
B(3,24,12,betternether:quartz_stained_glass:15)
B(4,24,12,betternether:quartz_stained_glass:15)
B(5,24,12,betternether:quartz_stained_glass:15)
RB(6,24,12,srparasites:parasitestain:1,80,quark:crystal:1,30,srparasites:parasiterubbledense:1,100)
RB(7,24,12,srparasites:parasitestain:1,80,quark:crystal:1,30,srparasites:parasiterubbledense:1,100)
B(8,24,12,betternether:quartz_stained_glass:15)
B(9,24,12,betternether:quartz_stained_glass:15)
B(10,24,12,betternether:quartz_stained_glass:15)
B(4,24,13,betternether:quartz_stained_glass:15)
RB(5,24,13,srparasites:parasitestain:1,80,quark:crystal:1,30,srparasites:parasiterubbledense:1,100)
RB(6,24,13,srparasites:parasitestain:1,80,quark:crystal:1,30,srparasites:parasiterubbledense:1,100)
RB(7,24,13,srparasites:parasitestain:1,80,quark:crystal:1,30,srparasites:parasiterubbledense:1,100)
B(8,24,13,betternether:quartz_stained_glass:15)
B(9,24,13,betternether:quartz_stained_glass:15)
B(10,24,13,betternether:quartz_stained_glass:15)
B(5,24,14,betternether:quartz_stained_glass:15)
B(6,24,14,betternether:quartz_stained_glass:15)
B(7,24,14,betternether:quartz_stained_glass:15)
B(8,24,14,betternether:quartz_stained_glass:15)
B(9,24,14,betternether:quartz_stained_glass:15)
B(10,24,14,betternether:quartz_stained_glass:15)
B(5,24,15,betternether:quartz_stained_glass:15)
B(6,24,15,betternether:quartz_stained_glass:15)
B(7,24,15,betternether:quartz_stained_glass:15)
B(8,24,15,betternether:quartz_stained_glass:15)
B(9,24,15,betternether:quartz_stained_glass:15)
B(10,24,15,betternether:quartz_stained_glass:15)
B(11,24,15,betternether:quartz_stained_glass:15)
B(5,25,6,betternether:quartz_stained_glass:15)
B(4,25,7,betternether:quartz_stained_glass:15)
B(5,25,7,betternether:quartz_stained_glass:15)
B(6,25,7,betternether:quartz_stained_glass:15)
B(7,25,7,betternether:quartz_stained_glass:15)
B(2,25,8,betternether:quartz_stained_glass:15)
B(3,25,8,betternether:quartz_stained_glass:15)
B(4,25,8,betternether:quartz_stained_glass:15)
B(5,25,8,betternether:quartz_stained_glass:15)
B(6,25,8,betternether:quartz_stained_glass:15)
B(7,25,8,betternether:quartz_stained_glass:15)
B(8,25,8,betternether:quartz_stained_glass:15)
B(2,25,9,betternether:quartz_stained_glass:15)
B(3,25,9,betternether:quartz_stained_glass:15)
B(4,25,9,betternether:quartz_stained_glass:15)
RB(5,25,9,srparasites:parasitestain:1,80,quark:crystal:1,30,srparasites:parasiterubbledense:1,100)
B(6,25,9,betternether:quartz_stained_glass:15)
B(7,25,9,betternether:quartz_stained_glass:15)
B(8,25,9,betternether:quartz_stained_glass:15)
B(3,25,10,betternether:quartz_stained_glass:15)
B(4,25,10,betternether:quartz_stained_glass:15)
B(5,25,10,betternether:quartz_stained_glass:15)
B(6,25,10,betternether:quartz_stained_glass:15)
RB(7,25,10,srparasites:parasitestain:1,80,quark:crystal:1,30,srparasites:parasiterubbledense:1,100)
B(8,25,10,betternether:quartz_stained_glass:15)
B(3,25,11,betternether:quartz_stained_glass:15)
B(4,25,11,betternether:quartz_stained_glass:15)
RB(5,25,11,srparasites:parasitestain:1,80,quark:crystal:1,30,srparasites:parasiterubbledense:1,100)
RB(6,25,11,srparasites:parasitestain:1,80,quark:crystal:1,30,srparasites:parasiterubbledense:1,100)
RB(7,25,11,srparasites:parasitestain:1,80,quark:crystal:1,30,srparasites:parasiterubbledense:1,100)
B(8,25,11,betternether:quartz_stained_glass:15)
B(9,25,11,betternether:quartz_stained_glass:15)
B(3,25,12,betternether:quartz_stained_glass:15)
B(4,25,12,betternether:quartz_stained_glass:15)
RB(5,25,12,srparasites:parasitestain:1,80,quark:crystal:1,30,srparasites:parasiterubbledense:1,100)
RB(6,25,12,srparasites:parasitestain:1,80,quark:crystal:1,30,srparasites:parasiterubbledense:1,100)
B(7,25,12,betternether:quartz_stained_glass:15)
B(8,25,12,betternether:quartz_stained_glass:15)
B(9,25,12,betternether:quartz_stained_glass:15)
B(10,25,12,betternether:quartz_stained_glass:15)
B(4,25,13,betternether:quartz_stained_glass:15)
B(5,25,13,betternether:quartz_stained_glass:15)
B(6,25,13,betternether:quartz_stained_glass:15)
B(7,25,13,betternether:quartz_stained_glass:15)
B(8,25,13,betternether:quartz_stained_glass:15)
B(9,25,13,betternether:quartz_stained_glass:15)
B(10,25,13,betternether:quartz_stained_glass:15)
B(5,25,14,betternether:quartz_stained_glass:15)
B(6,25,14,betternether:quartz_stained_glass:15)
B(7,25,14,betternether:quartz_stained_glass:15)
B(8,25,14,betternether:quartz_stained_glass:15)
B(9,25,14,betternether:quartz_stained_glass:15)
B(10,25,14,betternether:quartz_stained_glass:15)
B(5,25,15,betternether:quartz_stained_glass:15)
B(6,25,15,betternether:quartz_stained_glass:15)
B(7,25,15,betternether:quartz_stained_glass:15)
B(8,25,15,betternether:quartz_stained_glass:15)
B(6,26,5,betternether:quartz_stained_glass:15)
B(4,26,6,betternether:quartz_stained_glass:15)
B(5,26,6,betternether:quartz_stained_glass:15)
B(6,26,6,betternether:quartz_stained_glass:15)
B(2,26,7,betternether:quartz_stained_glass:15)
B(3,26,7,betternether:quartz_stained_glass:15)
B(4,26,7,betternether:quartz_stained_glass:15)
B(5,26,7,betternether:quartz_stained_glass:15)
B(6,26,7,betternether:quartz_stained_glass:15)
B(7,26,7,betternether:quartz_stained_glass:15)
B(1,26,8,betternether:quartz_stained_glass:15)
B(2,26,8,betternether:quartz_stained_glass:15)
B(3,26,8,betternether:quartz_stained_glass:15)
B(4,26,8,betternether:quartz_stained_glass:15)
B(5,26,8,betternether:quartz_stained_glass:15)
B(6,26,8,betternether:quartz_stained_glass:15)
B(7,26,8,betternether:quartz_stained_glass:15)
B(8,26,8,betternether:quartz_stained_glass:15)
B(2,26,9,betternether:quartz_stained_glass:15)
B(3,26,9,betternether:quartz_stained_glass:15)
B(4,26,9,betternether:quartz_stained_glass:15)
RB(5,26,9,srparasites:parasitestain:1,80,quark:crystal:1,30,srparasites:parasiterubbledense:1,100)
B(6,26,9,betternether:quartz_stained_glass:15)
B(7,26,9,betternether:quartz_stained_glass:15)
B(8,26,9,betternether:quartz_stained_glass:15)
B(3,26,10,betternether:quartz_stained_glass:15)
B(4,26,10,betternether:quartz_stained_glass:15)
RB(5,26,10,srparasites:parasitestain:1,80,quark:crystal:1,30,srparasites:parasiterubbledense:1,100)
RB(6,26,10,srparasites:parasitestain:1,80,quark:crystal:1,30,srparasites:parasiterubbledense:1,100)
RB(7,26,10,srparasites:parasitestain:1,80,quark:crystal:1,30,srparasites:parasiterubbledense:1,100)
B(8,26,10,betternether:quartz_stained_glass:15)
B(3,26,11,betternether:quartz_stained_glass:15)
B(4,26,11,betternether:quartz_stained_glass:15)
RB(5,26,11,srparasites:parasitestain:1,80,quark:crystal:1,30,srparasites:parasiterubbledense:1,100)
RB(6,26,11,srparasites:parasitestain:1,80,quark:crystal:1,30,srparasites:parasiterubbledense:1,100)
B(7,26,11,betternether:quartz_stained_glass:15)
B(8,26,11,betternether:quartz_stained_glass:15)
B(9,26,11,betternether:quartz_stained_glass:15)
B(3,26,12,betternether:quartz_stained_glass:15)
B(4,26,12,betternether:quartz_stained_glass:15)
B(5,26,12,betternether:quartz_stained_glass:15)
RB(6,26,12,srparasites:parasitestain:1,80,quark:crystal:1,30,srparasites:parasiterubbledense:1,100)
B(7,26,12,betternether:quartz_stained_glass:15)
B(8,26,12,betternether:quartz_stained_glass:15)
B(9,26,12,betternether:quartz_stained_glass:15)
B(10,26,12,betternether:quartz_stained_glass:15)
B(4,26,13,betternether:quartz_stained_glass:15)
B(5,26,13,betternether:quartz_stained_glass:15)
B(6,26,13,betternether:quartz_stained_glass:15)
B(7,26,13,betternether:quartz_stained_glass:15)
B(8,26,13,betternether:quartz_stained_glass:15)
B(9,26,13,betternether:quartz_stained_glass:15)
B(5,26,14,betternether:quartz_stained_glass:15)
B(6,26,14,betternether:quartz_stained_glass:15)
B(7,26,14,betternether:quartz_stained_glass:15)
B(8,26,14,betternether:quartz_stained_glass:15)
B(9,26,14,betternether:quartz_stained_glass:15)
B(5,26,15,betternether:quartz_stained_glass:15)
B(6,26,15,betternether:quartz_stained_glass:15)
B(5,27,4,betternether:quartz_stained_glass:15)
B(6,27,4,betternether:quartz_stained_glass:15)
B(2,27,5,betternether:quartz_stained_glass:15)
B(3,27,5,betternether:quartz_stained_glass:15)
B(4,27,5,betternether:quartz_stained_glass:15)
B(5,27,5,betternether:quartz_stained_glass:15)
B(6,27,5,betternether:quartz_stained_glass:15)
B(1,27,6,betternether:quartz_stained_glass:15)
B(2,27,6,betternether:quartz_stained_glass:15)
B(3,27,6,betternether:quartz_stained_glass:15)
B(4,27,6,betternether:quartz_stained_glass:15)
B(5,27,6,betternether:quartz_stained_glass:15)
B(6,27,6,betternether:quartz_stained_glass:15)
B(1,27,7,betternether:quartz_stained_glass:15)
B(2,27,7,betternether:quartz_stained_glass:15)
B(3,27,7,betternether:quartz_stained_glass:15)
B(4,27,7,betternether:quartz_stained_glass:15)
B(5,27,7,betternether:quartz_stained_glass:15)
B(6,27,7,betternether:quartz_stained_glass:15)
B(7,27,7,betternether:quartz_stained_glass:15)
B(1,27,8,betternether:quartz_stained_glass:15)
B(2,27,8,betternether:quartz_stained_glass:15)
B(3,27,8,betternether:quartz_stained_glass:15)
B(4,27,8,betternether:quartz_stained_glass:15)
RB(5,27,8,srparasites:parasitestain:1,80,quark:crystal:1,30,srparasites:parasiterubbledense:1,100)
B(6,27,8,betternether:quartz_stained_glass:15)
B(7,27,8,betternether:quartz_stained_glass:15)
B(8,27,8,betternether:quartz_stained_glass:15)
B(2,27,9,betternether:quartz_stained_glass:15)
B(3,27,9,betternether:quartz_stained_glass:15)
RB(4,27,9,srparasites:parasitestain:1,80,quark:crystal:1,30,srparasites:parasiterubbledense:1,100)
RB(5,27,9,srparasites:parasitestain:1,80,quark:crystal:1,30,srparasites:parasiterubbledense:1,100)
RB(6,27,9,srparasites:parasitestain:1,80,quark:crystal:1,30,srparasites:parasiterubbledense:1,100)
B(7,27,9,betternether:quartz_stained_glass:15)
B(8,27,9,betternether:quartz_stained_glass:15)
B(3,27,10,betternether:quartz_stained_glass:15)
RB(4,27,10,srparasites:parasitestain:1,80,quark:crystal:1,30,srparasites:parasiterubbledense:1,100)
B(5,27,10,betternether:quartz_stained_glass:15)
B(6,27,10,betternether:quartz_stained_glass:15)
B(7,27,10,betternether:quartz_stained_glass:15)
B(8,27,10,betternether:quartz_stained_glass:15)
B(3,27,11,betternether:quartz_stained_glass:15)
B(4,27,11,betternether:quartz_stained_glass:15)
B(5,27,11,betternether:quartz_stained_glass:15)
RB(6,27,11,srparasites:parasitestain:1,80,quark:crystal:1,30,srparasites:parasiterubbledense:1,100)
B(7,27,11,betternether:quartz_stained_glass:15)
B(8,27,11,betternether:quartz_stained_glass:15)
B(9,27,11,betternether:quartz_stained_glass:15)
B(3,27,12,betternether:quartz_stained_glass:15)
B(4,27,12,betternether:quartz_stained_glass:15)
B(5,27,12,betternether:quartz_stained_glass:15)
B(6,27,12,betternether:quartz_stained_glass:15)
B(7,27,12,betternether:quartz_stained_glass:15)
B(8,27,12,betternether:quartz_stained_glass:15)
B(9,27,12,betternether:quartz_stained_glass:15)
B(4,27,13,betternether:quartz_stained_glass:15)
B(5,27,13,betternether:quartz_stained_glass:15)
B(6,27,13,betternether:quartz_stained_glass:15)
B(7,27,13,betternether:quartz_stained_glass:15)
B(8,27,13,betternether:quartz_stained_glass:15)
B(5,27,14,betternether:quartz_stained_glass:15)
B(6,27,14,betternether:quartz_stained_glass:15)
B(3,28,4,betternether:quartz_stained_glass:15)
B(4,28,4,betternether:quartz_stained_glass:15)
B(5,28,4,betternether:quartz_stained_glass:15)
B(6,28,4,betternether:quartz_stained_glass:15)
B(1,28,5,betternether:quartz_stained_glass:15)
B(2,28,5,betternether:quartz_stained_glass:15)
B(3,28,5,betternether:quartz_stained_glass:15)
B(4,28,5,betternether:quartz_stained_glass:15)
B(5,28,5,betternether:quartz_stained_glass:15)
B(6,28,5,betternether:quartz_stained_glass:15)
B(1,28,6,betternether:quartz_stained_glass:15)
B(2,28,6,betternether:quartz_stained_glass:15)
B(3,28,6,betternether:quartz_stained_glass:15)
B(4,28,6,betternether:quartz_stained_glass:15)
B(5,28,6,betternether:quartz_stained_glass:15)
B(6,28,6,betternether:quartz_stained_glass:15)
B(1,28,7,betternether:quartz_stained_glass:15)
B(2,28,7,betternether:quartz_stained_glass:15)
B(3,28,7,betternether:quartz_stained_glass:15)
RB(4,28,7,srparasites:parasitestain:1,80,quark:crystal:1,30,srparasites:parasiterubbledense:1,100)
B(5,28,7,betternether:quartz_stained_glass:15)
B(6,28,7,betternether:quartz_stained_glass:15)
B(7,28,7,betternether:quartz_stained_glass:15)
B(1,28,8,betternether:quartz_stained_glass:15)
B(2,28,8,betternether:quartz_stained_glass:15)
B(3,28,8,betternether:quartz_stained_glass:15)
B(4,28,8,betternether:quartz_stained_glass:15)
RB(5,28,8,srparasites:parasitestain:1,80,quark:crystal:1,30,srparasites:parasiterubbledense:1,100)
RB(6,28,8,srparasites:parasitestain:1,80,quark:crystal:1,30,srparasites:parasiterubbledense:1,100)
B(7,28,8,betternether:quartz_stained_glass:15)
B(8,28,8,betternether:quartz_stained_glass:15)
B(2,28,9,betternether:quartz_stained_glass:15)
RB(3,28,9,srparasites:parasitestain:1,80,quark:crystal:1,30,srparasites:parasiterubbledense:1,100)
RB(4,28,9,srparasites:parasitestain:1,80,quark:crystal:1,30,srparasites:parasiterubbledense:1,100)
RB(5,28,9,srparasites:parasitestain:1,80,quark:crystal:1,30,srparasites:parasiterubbledense:1,100)
B(6,28,9,betternether:quartz_stained_glass:15)
B(7,28,9,betternether:quartz_stained_glass:15)
B(8,28,9,betternether:quartz_stained_glass:15)
B(3,28,10,betternether:quartz_stained_glass:15)
B(4,28,10,betternether:quartz_stained_glass:15)
B(5,28,10,betternether:quartz_stained_glass:15)
B(6,28,10,betternether:quartz_stained_glass:15)
B(7,28,10,betternether:quartz_stained_glass:15)
B(8,28,10,betternether:quartz_stained_glass:15)
B(3,28,11,betternether:quartz_stained_glass:15)
B(4,28,11,betternether:quartz_stained_glass:15)
B(5,28,11,betternether:quartz_stained_glass:15)
B(6,28,11,betternether:quartz_stained_glass:15)
B(7,28,11,betternether:quartz_stained_glass:15)
B(8,28,11,betternether:quartz_stained_glass:15)
B(9,28,11,betternether:quartz_stained_glass:15)
B(3,28,12,betternether:quartz_stained_glass:15)
B(4,28,12,betternether:quartz_stained_glass:15)
B(5,28,12,betternether:quartz_stained_glass:15)
B(6,28,12,betternether:quartz_stained_glass:15)
B(7,28,12,betternether:quartz_stained_glass:15)
B(8,28,12,betternether:quartz_stained_glass:15)
B(9,28,12,betternether:quartz_stained_glass:15)
B(4,28,13,betternether:quartz_stained_glass:15)
B(5,28,13,betternether:quartz_stained_glass:15)
B(6,28,13,betternether:quartz_stained_glass:15)
B(5,28,14,betternether:quartz_stained_glass:15)
B(3,29,3,betternether:quartz_stained_glass:15)
B(5,29,3,betternether:quartz_stained_glass:15)
B(2,29,4,betternether:quartz_stained_glass:15)
B(3,29,4,betternether:quartz_stained_glass:15)
B(4,29,4,betternether:quartz_stained_glass:15)
B(5,29,4,betternether:quartz_stained_glass:15)
B(6,29,4,betternether:quartz_stained_glass:15)
B(0,29,5,betternether:quartz_stained_glass:15)
B(1,29,5,betternether:quartz_stained_glass:15)
B(2,29,5,betternether:quartz_stained_glass:15)
B(3,29,5,betternether:quartz_stained_glass:15)
B(4,29,5,betternether:quartz_stained_glass:15)
B(5,29,5,betternether:quartz_stained_glass:15)
B(6,29,5,betternether:quartz_stained_glass:15)
B(1,29,6,betternether:quartz_stained_glass:15)
B(2,29,6,betternether:quartz_stained_glass:15)
RB(3,29,6,srparasites:parasitestain:1,80,quark:crystal:1,30,srparasites:parasiterubbledense:1,100)
B(4,29,6,betternether:quartz_stained_glass:15)
RB(5,29,6,srparasites:parasitestain:1,80,quark:crystal:1,30,srparasites:parasiterubbledense:1,100)
B(6,29,6,betternether:quartz_stained_glass:15)
B(1,29,7,betternether:quartz_stained_glass:15)
B(2,29,7,betternether:quartz_stained_glass:15)
B(3,29,7,betternether:quartz_stained_glass:15)
RB(4,29,7,srparasites:parasitestain:1,80,quark:crystal:1,30,srparasites:parasiterubbledense:1,100)
RB(5,29,7,srparasites:parasitestain:1,80,quark:crystal:1,30,srparasites:parasiterubbledense:1,100)
B(6,29,7,betternether:quartz_stained_glass:15)
B(7,29,7,betternether:quartz_stained_glass:15)
B(1,29,8,betternether:quartz_stained_glass:15)
B(2,29,8,betternether:quartz_stained_glass:15)
RB(3,29,8,srparasites:parasitestain:1,80,quark:crystal:1,30,srparasites:parasiterubbledense:1,100)
RB(4,29,8,srparasites:parasitestain:1,80,quark:crystal:1,30,srparasites:parasiterubbledense:1,100)
RB(5,29,8,srparasites:parasitestain:1,80,quark:crystal:1,30,srparasites:parasiterubbledense:1,100)
B(6,29,8,betternether:quartz_stained_glass:15)
B(7,29,8,betternether:quartz_stained_glass:15)
B(8,29,8,betternether:quartz_stained_glass:15)
B(2,29,9,betternether:quartz_stained_glass:15)
B(3,29,9,betternether:quartz_stained_glass:15)
B(4,29,9,betternether:quartz_stained_glass:15)
B(5,29,9,betternether:quartz_stained_glass:15)
B(6,29,9,betternether:quartz_stained_glass:15)
B(7,29,9,betternether:quartz_stained_glass:15)
B(8,29,9,betternether:quartz_stained_glass:15)
B(3,29,10,betternether:quartz_stained_glass:15)
B(4,29,10,betternether:quartz_stained_glass:15)
B(5,29,10,betternether:quartz_stained_glass:15)
B(6,29,10,betternether:quartz_stained_glass:15)
B(7,29,10,betternether:quartz_stained_glass:15)
B(8,29,10,betternether:quartz_stained_glass:15)
B(3,29,11,betternether:quartz_stained_glass:15)
B(4,29,11,betternether:quartz_stained_glass:15)
B(5,29,11,betternether:quartz_stained_glass:15)
B(6,29,11,betternether:quartz_stained_glass:15)
B(7,29,11,betternether:quartz_stained_glass:15)
B(8,29,11,betternether:quartz_stained_glass:15)
B(3,29,12,betternether:quartz_stained_glass:15)
B(4,29,12,betternether:quartz_stained_glass:15)
B(5,29,12,betternether:quartz_stained_glass:15)
B(3,30,3,betternether:quartz_stained_glass:15)
B(4,30,3,betternether:quartz_stained_glass:15)
B(5,30,3,betternether:quartz_stained_glass:15)
B(1,30,4,betternether:quartz_stained_glass:15)
B(2,30,4,betternether:quartz_stained_glass:15)
B(3,30,4,betternether:quartz_stained_glass:15)
B(4,30,4,betternether:quartz_stained_glass:15)
B(5,30,4,betternether:quartz_stained_glass:15)
B(6,30,4,betternether:quartz_stained_glass:15)
B(0,30,5,betternether:quartz_stained_glass:15)
B(1,30,5,betternether:quartz_stained_glass:15)
B(2,30,5,betternether:quartz_stained_glass:15)
B(3,30,5,betternether:quartz_stained_glass:15)
B(4,30,5,betternether:quartz_stained_glass:15)
B(5,30,5,betternether:quartz_stained_glass:15)
B(6,30,5,betternether:quartz_stained_glass:15)
B(1,30,6,betternether:quartz_stained_glass:15)
B(2,30,6,betternether:quartz_stained_glass:15)
RB(3,30,6,srparasites:parasitestain:1,80,quark:crystal:1,30,srparasites:parasiterubbledense:1,100)
RB(4,30,6,srparasites:parasitestain:1,80,quark:crystal:1,30,srparasites:parasiterubbledense:1,100)
RB(5,30,6,srparasites:parasitestain:1,80,quark:crystal:1,30,srparasites:parasiterubbledense:1,100)
B(6,30,6,betternether:quartz_stained_glass:15)
B(1,30,7,betternether:quartz_stained_glass:15)
B(2,30,7,betternether:quartz_stained_glass:15)
RB(3,30,7,srparasites:parasitestain:1,80,quark:crystal:1,30,srparasites:parasiterubbledense:1,100)
RB(4,30,7,srparasites:parasitestain:1,80,quark:crystal:1,30,srparasites:parasiterubbledense:1,100)
B(5,30,7,betternether:quartz_stained_glass:15)
B(6,30,7,betternether:quartz_stained_glass:15)
B(7,30,7,betternether:quartz_stained_glass:15)
B(1,30,8,betternether:quartz_stained_glass:15)
B(2,30,8,betternether:quartz_stained_glass:15)
RB(3,30,8,srparasites:parasitestain:1,80,quark:crystal:1,30,srparasites:parasiterubbledense:1,100)
B(4,30,8,betternether:quartz_stained_glass:15)
RB(5,30,8,srparasites:parasitestain:1,80,quark:crystal:1,30,srparasites:parasiterubbledense:1,100)
B(6,30,8,betternether:quartz_stained_glass:15)
B(7,30,8,betternether:quartz_stained_glass:15)
B(8,30,8,betternether:quartz_stained_glass:15)
B(2,30,9,betternether:quartz_stained_glass:15)
B(3,30,9,betternether:quartz_stained_glass:15)
B(4,30,9,betternether:quartz_stained_glass:15)
B(5,30,9,betternether:quartz_stained_glass:15)
B(6,30,9,betternether:quartz_stained_glass:15)
B(7,30,9,betternether:quartz_stained_glass:15)
B(3,30,10,betternether:quartz_stained_glass:15)
B(4,30,10,betternether:quartz_stained_glass:15)
B(5,30,10,betternether:quartz_stained_glass:15)
B(6,30,10,betternether:quartz_stained_glass:15)
B(7,30,10,betternether:quartz_stained_glass:15)
B(3,30,11,betternether:quartz_stained_glass:15)
B(4,30,11,betternether:quartz_stained_glass:15)
B(5,30,11,betternether:quartz_stained_glass:15)
B(6,30,11,betternether:quartz_stained_glass:15)
B(3,31,2,betternether:quartz_stained_glass:15)
B(5,31,2,betternether:quartz_stained_glass:15)
B(1,31,3,betternether:quartz_stained_glass:15)
B(2,31,3,betternether:quartz_stained_glass:15)
B(3,31,3,betternether:quartz_stained_glass:15)
B(4,31,3,betternether:quartz_stained_glass:15)
B(5,31,3,betternether:quartz_stained_glass:15)
B(0,31,4,betternether:quartz_stained_glass:15)
B(1,31,4,betternether:quartz_stained_glass:15)
B(2,31,4,betternether:quartz_stained_glass:15)
RB(3,31,4,srparasites:parasitestain:1,80,quark:crystal:1,30,srparasites:parasiterubbledense:1,100)
B(4,31,4,betternether:quartz_stained_glass:15)
B(5,31,4,betternether:quartz_stained_glass:15)
B(6,31,4,betternether:quartz_stained_glass:15)
B(0,31,5,betternether:quartz_stained_glass:15)
B(1,31,5,betternether:quartz_stained_glass:15)
B(2,31,5,betternether:quartz_stained_glass:15)
B(3,31,5,betternether:quartz_stained_glass:15)
B(4,31,5,betternether:quartz_stained_glass:15)
RB(5,31,5,srparasites:parasitestain:1,80,quark:crystal:1,30,srparasites:parasiterubbledense:1,100)
B(6,31,5,betternether:quartz_stained_glass:15)
B(1,31,6,betternether:quartz_stained_glass:15)
RB(2,31,6,srparasites:parasitestain:1,80,quark:crystal:1,30,srparasites:parasiterubbledense:1,100)
RB(3,31,6,srparasites:parasitestain:1,80,quark:crystal:1,30,srparasites:parasiterubbledense:1,100)
RB(4,31,6,srparasites:parasitestain:1,80,quark:crystal:1,30,srparasites:parasiterubbledense:1,100)
B(5,31,6,betternether:quartz_stained_glass:15)
B(6,31,6,betternether:quartz_stained_glass:15)
B(1,31,7,betternether:quartz_stained_glass:15)
B(2,31,7,betternether:quartz_stained_glass:15)
RB(3,31,7,srparasites:parasitestain:1,80,quark:crystal:1,30,srparasites:parasiterubbledense:1,100)
RB(4,31,7,srparasites:parasitestain:1,80,quark:crystal:1,30,srparasites:parasiterubbledense:1,100)
B(5,31,7,betternether:quartz_stained_glass:15)
B(6,31,7,betternether:quartz_stained_glass:15)
B(7,31,7,betternether:quartz_stained_glass:15)
B(1,31,8,betternether:quartz_stained_glass:15)
B(2,31,8,betternether:quartz_stained_glass:15)
B(3,31,8,betternether:quartz_stained_glass:15)
B(4,31,8,betternether:quartz_stained_glass:15)
B(5,31,8,betternether:quartz_stained_glass:15)
B(6,31,8,betternether:quartz_stained_glass:15)
B(7,31,8,betternether:quartz_stained_glass:15)
B(8,31,8,betternether:quartz_stained_glass:15)
B(2,31,9,betternether:quartz_stained_glass:15)
B(3,31,9,betternether:quartz_stained_glass:15)
B(4,31,9,betternether:quartz_stained_glass:15)
B(5,31,9,betternether:quartz_stained_glass:15)
B(6,31,9,betternether:quartz_stained_glass:15)
B(7,31,9,betternether:quartz_stained_glass:15)
B(3,31,10,betternether:quartz_stained_glass:15)
B(4,31,10,betternether:quartz_stained_glass:15)
B(5,31,10,betternether:quartz_stained_glass:15)
B(6,31,10,betternether:quartz_stained_glass:15)
B(3,31,11,betternether:quartz_stained_glass:15)
B(4,31,11,betternether:quartz_stained_glass:15)
B(3,32,2,betternether:quartz_stained_glass:15)
B(4,32,2,betternether:quartz_stained_glass:15)
B(5,32,2,betternether:quartz_stained_glass:15)
B(1,32,3,betternether:quartz_stained_glass:15)
B(2,32,3,betternether:quartz_stained_glass:15)
B(3,32,3,betternether:quartz_stained_glass:15)
B(4,32,3,betternether:quartz_stained_glass:15)
B(5,32,3,betternether:quartz_stained_glass:15)
B(0,32,4,betternether:quartz_stained_glass:15)
B(1,32,4,betternether:quartz_stained_glass:15)
B(2,32,4,betternether:quartz_stained_glass:15)
RB(3,32,4,srparasites:parasitestain:1,80,quark:crystal:1,30,srparasites:parasiterubbledense:1,100)
B(4,32,4,betternether:quartz_stained_glass:15)
B(5,32,4,betternether:quartz_stained_glass:15)
B(6,32,4,betternether:quartz_stained_glass:15)
B(0,32,5,betternether:quartz_stained_glass:15)
B(1,32,5,betternether:quartz_stained_glass:15)
RB(2,32,5,srparasites:parasitestain:1,80,quark:crystal:1,30,srparasites:parasiterubbledense:1,100)
RB(3,32,5,srparasites:parasitestain:1,80,quark:crystal:1,30,srparasites:parasiterubbledense:1,100)
RB(4,32,5,srparasites:parasitestain:1,80,quark:crystal:1,30,srparasites:parasiterubbledense:1,100)
B(5,32,5,betternether:quartz_stained_glass:15)
B(6,32,5,betternether:quartz_stained_glass:15)
B(1,32,6,betternether:quartz_stained_glass:15)
B(2,32,6,betternether:quartz_stained_glass:15)
RB(3,32,6,srparasites:parasitestain:1,80,quark:crystal:1,30,srparasites:parasiterubbledense:1,100)
B(4,32,6,betternether:quartz_stained_glass:15)
B(5,32,6,betternether:quartz_stained_glass:15)
B(6,32,6,betternether:quartz_stained_glass:15)
B(1,32,7,betternether:quartz_stained_glass:15)
B(2,32,7,betternether:quartz_stained_glass:15)
B(3,32,7,betternether:quartz_stained_glass:15)
B(4,32,7,betternether:quartz_stained_glass:15)
B(5,32,7,betternether:quartz_stained_glass:15)
B(6,32,7,betternether:quartz_stained_glass:15)
B(7,32,7,betternether:quartz_stained_glass:15)
B(1,32,8,betternether:quartz_stained_glass:15)
B(2,32,8,betternether:quartz_stained_glass:15)
B(3,32,8,betternether:quartz_stained_glass:15)
B(4,32,8,betternether:quartz_stained_glass:15)
B(5,32,8,betternether:quartz_stained_glass:15)
B(6,32,8,betternether:quartz_stained_glass:15)
B(7,32,8,betternether:quartz_stained_glass:15)
B(2,32,9,betternether:quartz_stained_glass:15)
B(3,32,9,betternether:quartz_stained_glass:15)
B(4,32,9,betternether:quartz_stained_glass:15)
B(3,32,10,betternether:quartz_stained_glass:15)
B(3,33,2,betternether:quartz_stained_glass:15)
B(4,33,2,betternether:quartz_stained_glass:15)
B(1,33,3,betternether:quartz_stained_glass:15)
B(2,33,3,betternether:quartz_stained_glass:15)
B(3,33,3,betternether:quartz_stained_glass:15)
B(4,33,3,betternether:quartz_stained_glass:15)
B(1,33,4,betternether:quartz_stained_glass:15)
B(2,33,4,betternether:quartz_stained_glass:15)
RB(3,33,4,srparasites:parasitestain:1,80,quark:crystal:1,30,srparasites:parasiterubbledense:1,100)
B(4,33,4,betternether:quartz_stained_glass:15)
B(5,33,4,betternether:quartz_stained_glass:15)
B(6,33,4,betternether:quartz_stained_glass:15)
B(1,33,5,betternether:quartz_stained_glass:15)
B(2,33,5,betternether:quartz_stained_glass:15)
B(3,33,5,betternether:quartz_stained_glass:15)
B(4,33,5,betternether:quartz_stained_glass:15)
B(5,33,5,betternether:quartz_stained_glass:15)
B(6,33,5,betternether:quartz_stained_glass:15)
B(1,33,6,betternether:quartz_stained_glass:15)
B(2,33,6,betternether:quartz_stained_glass:15)
RB(3,33,6,srparasites:parasitestain:1,80,quark:crystal:1,30,srparasites:parasiterubbledense:1,100)
B(4,33,6,betternether:quartz_stained_glass:15)
B(5,33,6,betternether:quartz_stained_glass:15)
B(6,33,6,betternether:quartz_stained_glass:15)
B(1,33,7,betternether:quartz_stained_glass:15)
B(2,33,7,betternether:quartz_stained_glass:15)
B(3,33,7,betternether:quartz_stained_glass:15)
B(4,33,7,betternether:quartz_stained_glass:15)
B(5,33,7,betternether:quartz_stained_glass:15)
B(6,33,7,betternether:quartz_stained_glass:15)
B(1,33,8,betternether:quartz_stained_glass:15)
B(2,33,8,betternether:quartz_stained_glass:15)
B(3,33,8,betternether:quartz_stained_glass:15)
B(4,33,8,betternether:quartz_stained_glass:15)
B(5,33,8,betternether:quartz_stained_glass:15)
B(6,33,8,betternether:quartz_stained_glass:15)
B(3,33,9,betternether:quartz_stained_glass:15)
B(3,34,1,betternether:quartz_stained_glass:15)
B(1,34,2,betternether:quartz_stained_glass:15)
B(2,34,2,betternether:quartz_stained_glass:15)
B(3,34,2,betternether:quartz_stained_glass:15)
B(4,34,2,betternether:quartz_stained_glass:15)
B(1,34,3,betternether:quartz_stained_glass:15)
B(2,34,3,betternether:quartz_stained_glass:15)
B(3,34,3,betternether:quartz_stained_glass:15)
B(4,34,3,betternether:quartz_stained_glass:15)
B(1,34,4,betternether:quartz_stained_glass:15)
B(2,34,4,betternether:quartz_stained_glass:15)
B(3,34,4,betternether:quartz_stained_glass:15)
B(4,34,4,betternether:quartz_stained_glass:15)
B(5,34,4,betternether:quartz_stained_glass:15)
B(6,34,4,betternether:quartz_stained_glass:15)
B(1,34,5,betternether:quartz_stained_glass:15)
B(2,34,5,betternether:quartz_stained_glass:15)
B(3,34,5,betternether:quartz_stained_glass:15)
B(4,34,5,betternether:quartz_stained_glass:15)
B(5,34,5,betternether:quartz_stained_glass:15)
B(6,34,5,betternether:quartz_stained_glass:15)
B(1,34,6,betternether:quartz_stained_glass:15)
B(2,34,6,betternether:quartz_stained_glass:15)
B(3,34,6,betternether:quartz_stained_glass:15)
B(4,34,6,betternether:quartz_stained_glass:15)
B(5,34,6,betternether:quartz_stained_glass:15)
B(1,34,7,betternether:quartz_stained_glass:15)
B(2,34,7,betternether:quartz_stained_glass:15)
B(3,34,7,betternether:quartz_stained_glass:15)
B(4,34,7,betternether:quartz_stained_glass:15)
B(3,34,8,betternether:quartz_stained_glass:15)
B(3,35,1,betternether:quartz_stained_glass:15)
B(1,35,2,betternether:quartz_stained_glass:15)
B(2,35,2,betternether:quartz_stained_glass:15)
B(3,35,2,betternether:quartz_stained_glass:15)
B(4,35,2,betternether:quartz_stained_glass:15)
B(1,35,3,betternether:quartz_stained_glass:15)
B(2,35,3,betternether:quartz_stained_glass:15)
B(3,35,3,betternether:quartz_stained_glass:15)
B(1,35,4,betternether:quartz_stained_glass:15)
B(2,35,4,betternether:quartz_stained_glass:15)
RB(3,35,4,srparasites:parasitestain:1,80,quark:crystal:1,30,srparasites:parasiterubbledense:1,100)
B(4,35,4,betternether:quartz_stained_glass:15)
B(5,35,4,betternether:quartz_stained_glass:15)
B(1,35,5,betternether:quartz_stained_glass:15)
B(2,35,5,betternether:quartz_stained_glass:15)
B(3,35,5,betternether:quartz_stained_glass:15)
B(4,35,5,betternether:quartz_stained_glass:15)
B(5,35,5,betternether:quartz_stained_glass:15)
B(1,35,6,betternether:quartz_stained_glass:15)
B(2,35,6,betternether:quartz_stained_glass:15)
B(3,35,6,betternether:quartz_stained_glass:15)
B(4,35,6,betternether:quartz_stained_glass:15)
B(3,35,7,betternether:quartz_stained_glass:15)
B(3,36,1,betternether:quartz_stained_glass:15)
B(1,36,2,betternether:quartz_stained_glass:15)
B(2,36,2,betternether:quartz_stained_glass:15)
B(3,36,2,betternether:quartz_stained_glass:15)
B(1,36,3,betternether:quartz_stained_glass:15)
B(2,36,3,betternether:quartz_stained_glass:15)
B(3,36,3,betternether:quartz_stained_glass:15)
B(1,36,4,betternether:quartz_stained_glass:15)
B(2,36,4,betternether:quartz_stained_glass:15)
B(3,36,4,betternether:quartz_stained_glass:15)
B(4,36,4,betternether:quartz_stained_glass:15)
B(1,36,5,betternether:quartz_stained_glass:15)
B(2,36,5,betternether:quartz_stained_glass:15)
B(3,36,5,betternether:quartz_stained_glass:15)
B(4,36,5,betternether:quartz_stained_glass:15)
B(3,37,1,betternether:quartz_stained_glass:15)
B(1,37,2,betternether:quartz_stained_glass:15)
B(2,37,2,betternether:quartz_stained_glass:15)
B(3,37,2,betternether:quartz_stained_glass:15)
B(1,37,3,betternether:quartz_stained_glass:15)
B(2,37,3,betternether:quartz_stained_glass:15)
B(3,37,3,betternether:quartz_stained_glass:15)
B(1,37,4,betternether:quartz_stained_glass:15)
B(2,37,4,betternether:quartz_stained_glass:15)
B(3,37,4,betternether:quartz_stained_glass:15)
B(2,38,1,betternether:quartz_stained_glass:15)
B(3,38,1,betternether:quartz_stained_glass:15)
B(0,38,2,betternether:quartz_stained_glass:15)
B(1,38,2,betternether:quartz_stained_glass:15)
B(2,38,2,betternether:quartz_stained_glass:15)
B(3,38,2,betternether:quartz_stained_glass:15)
B(1,38,3,betternether:quartz_stained_glass:15)
B(1,39,0,betternether:quartz_stained_glass:15)
B(1,39,1,betternether:quartz_stained_glass:15)
B(2,39,1,betternether:quartz_stained_glass:15)
B(1,39,2,betternether:quartz_stained_glass:15)
B(2,39,2,betternether:quartz_stained_glass:15)
B(1,40,0,betternether:quartz_stained_glass:15)
B(1,40,1,betternether:quartz_stained_glass:15)

