
#######################################################################
# +-----------------------------------------------------------------+ #
# |                            BO4 object                           | #
# +-----------------------------------------------------------------+ #
#######################################################################

Author: NLBlackEagle

Description: No description given

SettingsMode: WriteDisable


#######################################################################
# +-----------------------------------------------------------------+ #
# |                          Main settings                          | #
# +-----------------------------------------------------------------+ #
#######################################################################

Frequency: 0

SpawnHeight: highestBlock

UseCenterForHighestBlock: true

##############################
# Height Limits for the BO4. #
##############################

MinHeight: 0

MaxHeight: 255

InheritBO3: 

InheritBO3Rotation: NORTH

OverrideChildSettings: true

OverrideParentHeight: false

CanOverride: true

BranchFrequency: 0

BranchFrequencyGroup: 

MustBeBelowOther: false

MustBeInside: 

CannotBeInside: 

ReplacesBO3: 

MustBeInsideWorldBorders: false

CanSpawnOnWater: true

SpawnOnWaterOnly: false

SpawnUnderWater: false

SpawnAtWaterLevel: false

HeightOffset: 0

RemoveAir: true

ReplaceAbove: 

ReplaceBelow: 

ReplaceWithBiomeBlocks: true

ReplaceWithSurfaceBlock: GRASS

ReplaceWithGroundBlock: DIRT

ReplaceWithStoneBlock: STONE

SmoothRadius: 0

SmoothHeightOffset: 0

SmoothStartTop: false

SmoothStartWood: false

SmoothingSurfaceBlock: 

SmoothingGroundBlock: 

BO3Group: 

IsSpawnPoint: false

DoReplaceBlocks: true


#######################################################################
# +-----------------------------------------------------------------+ #
# |                              Blocks                             | #
# +-----------------------------------------------------------------+ #
#######################################################################

Block(-8,3,-7,DIRT:1)
Block(-8,3,-6,DIRT:1)
Block(-8,3,-5,DIRT:1)
Block(-8,3,-4,DIRT:1)
Block(-8,3,-3,DIRT:1)
Block(-8,3,-2,DIRT:1)
Block(-8,3,-1,DIRT:1)
Block(-8,3,0,DIRT:1)
Block(-8,3,1,DIRT:1)
Block(-8,3,2,DIRT:1)
Block(-8,3,3,STAINED_CLAY:0)
Block(-8,3,4,STAINED_CLAY:0)
Block(-8,3,5,STAINED_CLAY:0)
Block(-8,3,6,STAINED_CLAY:0)
Block(-8,3,7,STAINED_CLAY:0)
Block(-8,3,8,STAINED_CLAY:0)
Block(-8,4,-7,DIRT:1)
Block(-8,4,-6,DIRT:1)
Block(-8,4,-5,DIRT:1)
Block(-8,4,-4,DIRT:1)
Block(-8,4,-3,DIRT:1)
Block(-8,4,-2,DIRT:1)
Block(-8,4,-1,DIRT:1)
Block(-8,4,0,DIRT:1)
Block(-8,4,1,DIRT:1)
Block(-8,4,2,DIRT:1)
Block(-8,4,3,STAINED_CLAY:0)
Block(-8,4,4,STAINED_CLAY:0)
Block(-8,4,5,STAINED_CLAY:0)
Block(-8,4,6,STAINED_CLAY:0)
Block(-8,4,7,STAINED_CLAY:0)
Block(-8,4,8,STAINED_CLAY:0)
Block(-8,5,-7,DIRT:1)
Block(-8,5,-6,DIRT:1)
Block(-8,5,-5,DIRT:1)
Block(-8,5,-4,DIRT:1)
Block(-8,5,-3,DIRT:1)
Block(-8,5,-2,DIRT:1)
Block(-8,5,-1,DIRT:1)
Block(-8,5,0,DIRT:1)
Block(-8,5,1,DIRT:1)
Block(-8,5,2,DIRT:1)
Block(-8,5,3,STAINED_CLAY:0)
Block(-8,5,4,STAINED_CLAY:0)
Block(-8,5,5,STAINED_CLAY:0)
Block(-8,5,6,STAINED_CLAY:0)
Block(-8,5,7,STAINED_CLAY:0)
Block(-8,6,-7,DIRT:1)
Block(-8,6,-6,DIRT:1)
Block(-8,6,-5,DIRT:1)
Block(-8,6,-4,DIRT:1)
Block(-8,6,-3,DIRT:1)
Block(-8,6,-2,DIRT:1)
Block(-8,6,-1,DIRT:1)
Block(-8,6,0,DIRT:1)
Block(-8,6,1,DIRT:1)
Block(-8,6,2,DIRT:1)
Block(-8,6,3,STAINED_CLAY:0)
Block(-8,6,4,STAINED_CLAY:0)
Block(-8,6,5,STAINED_CLAY:0)
Block(-8,6,6,STAINED_CLAY:0)
Block(-8,7,-7,DIRT:1)
Block(-8,7,-6,DIRT:1)
Block(-8,7,-5,DIRT:1)
Block(-8,7,-4,DIRT:1)
Block(-8,7,-3,DIRT:1)
Block(-8,7,-2,DIRT:1)
Block(-8,7,-1,DIRT:1)
Block(-8,7,0,DIRT:1)
Block(-8,7,1,DIRT:1)
Block(-8,7,2,DIRT:1)
Block(-8,7,3,DIRT:1)
Block(-8,7,4,STAINED_CLAY:0)
Block(-8,7,5,STAINED_CLAY:0)
Block(-8,8,-7,DIRT:1)
Block(-8,8,-6,DIRT:1)
Block(-8,8,-5,DIRT:1)
Block(-8,8,-4,DIRT:1)
Block(-8,8,-3,DIRT:1)
Block(-8,8,-2,DIRT:1)
Block(-8,8,-1,DIRT:1)
Block(-8,8,0,DIRT:1)
Block(-8,8,1,DIRT:1)
Block(-8,8,2,DIRT:1)
Block(-8,8,3,DIRT:1)
Block(-8,8,4,DIRT:1)
Block(-8,9,-7,DIRT:1)
Block(-8,9,-6,DIRT:1)
Block(-8,9,-5,DIRT:1)
Block(-8,9,-4,DIRT:1)
Block(-8,9,-3,DIRT:1)
Block(-8,9,-2,DIRT:1)
Block(-8,9,-1,DIRT:1)
Block(-8,9,0,DIRT:1)
Block(-8,9,1,DIRT:1)
Block(-8,9,2,DIRT:1)
Block(-8,9,3,DIRT:1)
Block(-8,9,4,DIRT:1)
Block(-8,10,-7,DIRT:1)
Block(-8,10,-6,DIRT:1)
Block(-8,10,-5,DIRT:1)
Block(-8,10,-4,DIRT:1)
Block(-8,10,-3,DIRT:1)
Block(-8,10,-2,DIRT:1)
Block(-8,10,-1,DIRT:1)
Block(-8,10,0,DIRT:1)
Block(-8,10,1,DIRT:1)
Block(-8,10,2,DIRT:1)
Block(-8,10,3,DIRT:1)
Block(-8,11,-7,DIRT:1)
Block(-8,11,-6,DIRT:1)
Block(-8,11,-5,DIRT:1)
Block(-8,11,-4,DIRT:1)
Block(-8,11,-3,DIRT:1)
Block(-8,11,-2,DIRT:1)
Block(-8,11,-1,DIRT:1)
Block(-8,11,0,DIRT:1)
Block(-8,11,1,DIRT:1)
Block(-8,11,2,DIRT:1)
Block(-8,12,-7,DIRT:1)
Block(-8,12,-6,DIRT:1)
Block(-8,12,-5,DIRT:1)
Block(-8,12,-4,DIRT:1)
Block(-8,12,-3,DIRT:1)
Block(-8,12,-2,DIRT:1)
Block(-8,12,-1,DIRT:1)
Block(-8,12,0,DIRT:1)
Block(-8,13,-7,DIRT:1)
Block(-8,13,-6,DIRT:1)
Block(-8,13,-5,DIRT:1)
Block(-8,13,-4,DIRT:1)
Block(-8,13,-3,DIRT:1)
Block(-8,13,-2,DIRT:1)
Block(-8,14,-7,DIRT:1)
Block(-8,14,-6,DIRT:1)
Block(-8,14,-5,DIRT:1)
Block(-8,14,-4,DIRT:1)
Block(-8,15,-7,DIRT:1)
Block(-8,15,-6,DIRT:1)
Block(-7,3,-7,DIRT:1)
Block(-7,3,-6,DIRT:1)
Block(-7,3,-5,DIRT:1)
Block(-7,3,-4,DIRT:1)
Block(-7,3,-3,DIRT:1)
Block(-7,3,-2,DIRT:1)
Block(-7,3,-1,DIRT:1)
Block(-7,3,0,DIRT:1)
Block(-7,3,1,DIRT:1)
Block(-7,3,2,DIRT:1)
Block(-7,3,3,DIRT:1)
Block(-7,3,4,STAINED_CLAY:0)
Block(-7,3,5,STAINED_CLAY:0)
Block(-7,3,6,STAINED_CLAY:0)
Block(-7,3,7,STAINED_CLAY:0)
Block(-7,4,-7,DIRT:1)
Block(-7,4,-6,DIRT:1)
Block(-7,4,-5,DIRT:1)
Block(-7,4,-4,DIRT:1)
Block(-7,4,-3,DIRT:1)
Block(-7,4,-2,DIRT:1)
Block(-7,4,-1,DIRT:1)
Block(-7,4,0,DIRT:1)
Block(-7,4,1,DIRT:1)
Block(-7,4,2,DIRT:1)
Block(-7,4,3,DIRT:1)
Block(-7,4,4,STAINED_CLAY:0)
Block(-7,4,5,STAINED_CLAY:0)
Block(-7,4,6,STAINED_CLAY:0)
Block(-7,4,7,STAINED_CLAY:0)
Block(-7,4,8,STAINED_CLAY:0)
Block(-7,5,-7,DIRT:1)
Block(-7,5,-6,DIRT:1)
Block(-7,5,-5,DIRT:1)
Block(-7,5,-4,DIRT:1)
Block(-7,5,-3,DIRT:1)
Block(-7,5,-2,DIRT:1)
Block(-7,5,-1,DIRT:1)
Block(-7,5,0,DIRT:1)
Block(-7,5,1,DIRT:1)
Block(-7,5,2,DIRT:1)
Block(-7,5,3,DIRT:1)
Block(-7,5,4,STAINED_CLAY:0)
Block(-7,5,5,STAINED_CLAY:0)
Block(-7,5,6,STAINED_CLAY:0)
Block(-7,5,7,STAINED_CLAY:0)
Block(-7,5,8,STAINED_CLAY:0)
Block(-7,6,-7,DIRT:1)
Block(-7,6,-6,DIRT:1)
Block(-7,6,-5,DIRT:1)
Block(-7,6,-4,DIRT:1)
Block(-7,6,-3,DIRT:1)
Block(-7,6,-2,DIRT:1)
Block(-7,6,-1,DIRT:1)
Block(-7,6,0,DIRT:1)
Block(-7,6,1,DIRT:1)
Block(-7,6,2,DIRT:1)
Block(-7,6,3,DIRT:1)
Block(-7,6,4,DIRT:1)
Block(-7,6,5,STAINED_CLAY:0)
Block(-7,6,6,STAINED_CLAY:0)
Block(-7,6,7,STAINED_CLAY:0)
Block(-7,7,-7,DIRT:1)
Block(-7,7,-6,DIRT:1)
Block(-7,7,-5,DIRT:1)
Block(-7,7,-4,DIRT:1)
Block(-7,7,-3,DIRT:1)
Block(-7,7,-2,DIRT:1)
Block(-7,7,-1,DIRT:1)
Block(-7,7,0,DIRT:1)
Block(-7,7,1,DIRT:1)
Block(-7,7,2,DIRT:1)
Block(-7,7,3,DIRT:1)
Block(-7,7,4,DIRT:1)
Block(-7,7,5,DIRT:1)
Block(-7,7,6,DIRT:1)
Block(-7,8,-7,DIRT:1)
Block(-7,8,-6,DIRT:1)
Block(-7,8,-5,DIRT:1)
Block(-7,8,-4,DIRT:1)
Block(-7,8,-3,DIRT:1)
Block(-7,8,-2,DIRT:1)
Block(-7,8,-1,DIRT:1)
Block(-7,8,0,DIRT:1)
Block(-7,8,1,DIRT:1)
Block(-7,8,2,DIRT:1)
Block(-7,8,3,DIRT:1)
Block(-7,8,4,DIRT:1)
Block(-7,8,5,DIRT:1)
Block(-7,9,-7,DIRT:1)
Block(-7,9,-6,DIRT:1)
Block(-7,9,-5,DIRT:1)
Block(-7,9,-4,DIRT:1)
Block(-7,9,-3,DIRT:1)
Block(-7,9,-2,DIRT:1)
Block(-7,9,-1,DIRT:1)
Block(-7,9,0,DIRT:1)
Block(-7,9,1,DIRT:1)
Block(-7,9,2,DIRT:1)
Block(-7,9,3,DIRT:1)
Block(-7,9,4,DIRT:1)
Block(-7,10,-7,DIRT:1)
Block(-7,10,-6,DIRT:1)
Block(-7,10,-5,DIRT:1)
Block(-7,10,-4,DIRT:1)
Block(-7,10,-3,DIRT:1)
Block(-7,10,-2,DIRT:1)
Block(-7,10,-1,DIRT:1)
Block(-7,10,0,DIRT:1)
Block(-7,10,1,DIRT:1)
Block(-7,10,2,DIRT:1)
Block(-7,10,3,DIRT:1)
Block(-7,11,-7,DIRT:1)
Block(-7,11,-6,DIRT:1)
Block(-7,11,-5,DIRT:1)
Block(-7,11,-4,DIRT:1)
Block(-7,11,-3,DIRT:1)
Block(-7,11,-2,DIRT:1)
Block(-7,11,-1,DIRT:1)
Block(-7,11,0,DIRT:1)
Block(-7,11,1,DIRT:1)
Block(-7,12,-7,DIRT:1)
Block(-7,12,-6,DIRT:1)
Block(-7,12,-5,DIRT:1)
Block(-7,12,-4,DIRT:1)
Block(-7,12,-3,DIRT:1)
Block(-7,12,-2,DIRT:1)
Block(-7,12,-1,DIRT:1)
Block(-7,13,-7,DIRT:1)
Block(-7,13,-6,DIRT:1)
Block(-7,13,-5,DIRT:1)
Block(-7,13,-4,DIRT:1)
Block(-7,13,-3,DIRT:1)
Block(-7,14,-7,DIRT:1)
Block(-7,14,-6,DIRT:1)
Block(-7,14,-5,DIRT:1)
Block(-7,15,-7,DIRT:1)
Block(-6,3,-7,DIRT:1)
Block(-6,3,-6,DIRT:1)
Block(-6,3,-5,DIRT:1)
Block(-6,3,-4,DIRT:1)
Block(-6,3,-3,DIRT:1)
Block(-6,3,-2,DIRT:1)
Block(-6,3,-1,DIRT:1)
Block(-6,3,0,DIRT:1)
Block(-6,3,1,DIRT:1)
Block(-6,3,2,DIRT:1)
Block(-6,3,3,DIRT:1)
Block(-6,3,4,DIRT:1)
Block(-6,3,5,DIRT:1)
Block(-6,3,6,DIRT:1)
Block(-6,4,-7,DIRT:1)
Block(-6,4,-6,DIRT:1)
Block(-6,4,-5,DIRT:1)
Block(-6,4,-4,DIRT:1)
Block(-6,4,-3,DIRT:1)
Block(-6,4,-2,DIRT:1)
Block(-6,4,-1,DIRT:1)
Block(-6,4,0,DIRT:1)
Block(-6,4,1,DIRT:1)
Block(-6,4,2,DIRT:1)
Block(-6,4,3,DIRT:1)
Block(-6,4,4,DIRT:1)
Block(-6,4,5,DIRT:1)
Block(-6,4,6,DIRT:1)
Block(-6,4,7,DIRT:1)
Block(-6,4,8,DIRT:1)
Block(-6,5,-7,DIRT:1)
Block(-6,5,-6,DIRT:1)
Block(-6,5,-5,DIRT:1)
Block(-6,5,-4,DIRT:1)
Block(-6,5,-3,DIRT:1)
Block(-6,5,-2,DIRT:1)
Block(-6,5,-1,DIRT:1)
Block(-6,5,0,DIRT:1)
Block(-6,5,1,DIRT:1)
Block(-6,5,2,DIRT:1)
Block(-6,5,3,DIRT:1)
Block(-6,5,4,DIRT:1)
Block(-6,5,5,DIRT:1)
Block(-6,5,6,DIRT:1)
Block(-6,5,7,DIRT:1)
Block(-6,5,8,DIRT:1)
Block(-6,6,-7,DIRT:1)
Block(-6,6,-6,DIRT:1)
Block(-6,6,-5,DIRT:1)
Block(-6,6,-4,DIRT:1)
Block(-6,6,-3,DIRT:1)
Block(-6,6,-2,DIRT:1)
Block(-6,6,-1,DIRT:1)
Block(-6,6,0,DIRT:1)
Block(-6,6,1,DIRT:1)
Block(-6,6,2,DIRT:1)
Block(-6,6,3,DIRT:1)
Block(-6,6,4,DIRT:1)
Block(-6,6,5,DIRT:1)
Block(-6,6,6,DIRT:1)
Block(-6,6,7,DIRT:1)
Block(-6,7,-7,DIRT:1)
Block(-6,7,-6,DIRT:1)
Block(-6,7,-5,DIRT:1)
Block(-6,7,-4,DIRT:1)
Block(-6,7,-3,DIRT:1)
Block(-6,7,-2,DIRT:1)
Block(-6,7,-1,DIRT:1)
Block(-6,7,0,DIRT:1)
Block(-6,7,1,DIRT:1)
Block(-6,7,2,DIRT:1)
Block(-6,7,3,DIRT:1)
Block(-6,7,4,DIRT:1)
Block(-6,7,5,DIRT:1)
Block(-6,7,6,DIRT:1)
Block(-6,8,-7,DIRT:1)
Block(-6,8,-6,DIRT:1)
Block(-6,8,-5,DIRT:1)
Block(-6,8,-4,DIRT:1)
Block(-6,8,-3,DIRT:1)
Block(-6,8,-2,DIRT:1)
Block(-6,8,-1,DIRT:1)
Block(-6,8,0,DIRT:1)
Block(-6,8,1,DIRT:1)
Block(-6,8,2,DIRT:1)
Block(-6,8,3,DIRT:1)
Block(-6,8,4,DIRT:1)
Block(-6,8,5,DIRT:1)
Block(-6,9,-7,DIRT:1)
Block(-6,9,-6,DIRT:1)
Block(-6,9,-5,DIRT:1)
Block(-6,9,-4,DIRT:1)
Block(-6,9,-3,DIRT:1)
Block(-6,9,-2,DIRT:1)
Block(-6,9,-1,DIRT:1)
Block(-6,9,0,DIRT:1)
Block(-6,9,1,DIRT:1)
Block(-6,9,2,DIRT:1)
Block(-6,9,3,DIRT:1)
Block(-6,9,4,DIRT:1)
Block(-6,10,-7,DIRT:1)
Block(-6,10,-6,DIRT:1)
Block(-6,10,-5,DIRT:1)
Block(-6,10,-4,DIRT:1)
Block(-6,10,-3,DIRT:1)
Block(-6,10,-2,DIRT:1)
Block(-6,10,-1,DIRT:1)
Block(-6,10,0,DIRT:1)
Block(-6,10,1,DIRT:1)
Block(-6,10,2,DIRT:1)
Block(-6,11,-7,DIRT:1)
Block(-6,11,-6,DIRT:1)
Block(-6,11,-5,DIRT:1)
Block(-6,11,-4,DIRT:1)
Block(-6,11,-3,DIRT:1)
Block(-6,11,-2,DIRT:1)
Block(-6,11,-1,DIRT:1)
Block(-6,11,0,DIRT:1)
Block(-6,12,-7,DIRT:1)
Block(-6,12,-6,DIRT:1)
Block(-6,12,-5,DIRT:1)
Block(-6,12,-4,DIRT:1)
Block(-6,12,-3,DIRT:1)
Block(-6,12,-2,DIRT:1)
Block(-6,13,-7,DIRT:1)
Block(-6,13,-6,DIRT:1)
Block(-6,13,-5,DIRT:1)
Block(-6,13,-4,DIRT:1)
Block(-6,14,-7,DIRT:1)
Block(-6,14,-6,DIRT:1)
Block(-5,3,-7,DIRT:1)
Block(-5,3,-6,DIRT:1)
Block(-5,3,-5,DIRT:1)
Block(-5,3,-4,DIRT:1)
Block(-5,3,-3,DIRT:1)
Block(-5,3,-2,DIRT:1)
Block(-5,3,-1,DIRT:1)
Block(-5,3,0,DIRT:1)
Block(-5,3,1,DIRT:1)
Block(-5,3,2,DIRT:1)
Block(-5,3,3,DIRT:1)
Block(-5,3,4,DIRT:1)
Block(-5,3,5,DIRT:1)
Block(-5,4,-7,DIRT:1)
Block(-5,4,-6,DIRT:1)
Block(-5,4,-5,DIRT:1)
Block(-5,4,-4,DIRT:1)
Block(-5,4,-3,DIRT:1)
Block(-5,4,-2,DIRT:1)
Block(-5,4,-1,DIRT:1)
Block(-5,4,0,DIRT:1)
Block(-5,4,1,DIRT:1)
Block(-5,4,2,DIRT:1)
Block(-5,4,3,DIRT:1)
Block(-5,4,4,DIRT:1)
Block(-5,4,5,DIRT:1)
Block(-5,4,6,DIRT:1)
Block(-5,4,7,DIRT:1)
Block(-5,4,8,DIRT:1)
Block(-5,5,-7,DIRT:1)
Block(-5,5,-6,DIRT:1)
Block(-5,5,-5,DIRT:1)
Block(-5,5,-4,DIRT:1)
Block(-5,5,-3,DIRT:1)
Block(-5,5,-2,DIRT:1)
Block(-5,5,-1,DIRT:1)
Block(-5,5,0,DIRT:1)
Block(-5,5,1,DIRT:1)
Block(-5,5,2,DIRT:1)
Block(-5,5,3,DIRT:1)
Block(-5,5,4,DIRT:1)
Block(-5,5,5,DIRT:1)
Block(-5,5,6,DIRT:1)
Block(-5,5,7,DIRT:1)
Block(-5,5,8,DIRT:1)
Block(-5,6,-7,DIRT:1)
Block(-5,6,-6,DIRT:1)
Block(-5,6,-5,DIRT:1)
Block(-5,6,-4,DIRT:1)
Block(-5,6,-3,DIRT:1)
Block(-5,6,-2,DIRT:1)
Block(-5,6,-1,DIRT:1)
Block(-5,6,0,DIRT:1)
Block(-5,6,1,DIRT:1)
Block(-5,6,2,DIRT:1)
Block(-5,6,3,DIRT:1)
Block(-5,6,4,DIRT:1)
Block(-5,6,5,DIRT:1)
Block(-5,6,6,DIRT:1)
Block(-5,6,7,DIRT:1)
Block(-5,6,8,DIRT:1)
Block(-5,7,-7,DIRT:1)
Block(-5,7,-6,DIRT:1)
Block(-5,7,-5,DIRT:1)
Block(-5,7,-4,DIRT:1)
Block(-5,7,-3,DIRT:1)
Block(-5,7,-2,DIRT:1)
Block(-5,7,-1,DIRT:1)
Block(-5,7,0,DIRT:1)
Block(-5,7,1,DIRT:1)
Block(-5,7,2,DIRT:1)
Block(-5,7,3,DIRT:1)
Block(-5,7,4,DIRT:1)
Block(-5,7,5,DIRT:1)
Block(-5,7,6,DIRT:1)
Block(-5,7,7,DIRT:1)
Block(-5,8,-7,DIRT:1)
Block(-5,8,-6,DIRT:1)
Block(-5,8,-5,DIRT:1)
Block(-5,8,-4,DIRT:1)
Block(-5,8,-3,DIRT:1)
Block(-5,8,-2,DIRT:1)
Block(-5,8,-1,DIRT:1)
Block(-5,8,0,DIRT:1)
Block(-5,8,1,DIRT:1)
Block(-5,8,2,DIRT:1)
Block(-5,8,3,DIRT:1)
Block(-5,8,4,DIRT:1)
Block(-5,8,5,DIRT:1)
Block(-5,9,-7,DIRT:1)
Block(-5,9,-6,DIRT:1)
Block(-5,9,-5,DIRT:1)
Block(-5,9,-4,DIRT:1)
Block(-5,9,-3,DIRT:1)
Block(-5,9,-2,DIRT:1)
Block(-5,9,-1,DIRT:1)
Block(-5,9,0,DIRT:1)
Block(-5,9,1,DIRT:1)
Block(-5,9,2,DIRT:1)
Block(-5,9,3,DIRT:1)
Block(-5,10,-7,DIRT:1)
Block(-5,10,-6,DIRT:1)
Block(-5,10,-5,DIRT:1)
Block(-5,10,-4,DIRT:1)
Block(-5,10,-3,DIRT:1)
Block(-5,10,-2,DIRT:1)
Block(-5,10,-1,DIRT:1)
Block(-5,10,0,DIRT:1)
Block(-5,10,1,DIRT:1)
Block(-5,11,-7,DIRT:1)
Block(-5,11,-6,DIRT:1)
Block(-5,11,-5,DIRT:1)
Block(-5,11,-4,DIRT:1)
Block(-5,11,-3,DIRT:1)
Block(-5,11,-2,DIRT:1)
Block(-5,11,-1,DIRT:1)
Block(-5,12,-7,DIRT:1)
Block(-5,12,-6,DIRT:1)
Block(-5,12,-5,DIRT:1)
Block(-5,12,-4,DIRT:1)
Block(-5,12,-3,DIRT:1)
Block(-5,13,-7,DIRT:1)
Block(-5,13,-6,DIRT:1)
Block(-5,13,-5,DIRT:1)
Block(-5,14,-7,DIRT:1)
Block(-4,3,-7,DIRT:1)
Block(-4,3,-6,DIRT:1)
Block(-4,3,-5,DIRT:1)
Block(-4,3,-4,DIRT:1)
Block(-4,3,-3,DIRT:1)
Block(-4,3,-2,DIRT:1)
Block(-4,3,-1,DIRT:1)
Block(-4,3,0,DIRT:1)
Block(-4,3,1,DIRT:1)
Block(-4,3,2,DIRT:1)
Block(-4,3,3,DIRT:1)
Block(-4,3,4,DIRT:1)
Block(-4,4,-7,DIRT:1)
Block(-4,4,-6,DIRT:1)
Block(-4,4,-5,DIRT:1)
Block(-4,4,-4,DIRT:1)
Block(-4,4,-3,DIRT:1)
Block(-4,4,-2,DIRT:1)
Block(-4,4,-1,DIRT:1)
Block(-4,4,0,DIRT:1)
Block(-4,4,1,DIRT:1)
Block(-4,4,2,DIRT:1)
Block(-4,4,3,DIRT:1)
Block(-4,4,4,DIRT:1)
Block(-4,4,5,DIRT:1)
Block(-4,4,6,DIRT:1)
Block(-4,4,7,DIRT:1)
Block(-4,4,8,DIRT:1)
Block(-4,5,-7,DIRT:1)
Block(-4,5,-6,DIRT:1)
Block(-4,5,-5,DIRT:1)
Block(-4,5,-4,DIRT:1)
Block(-4,5,-3,DIRT:1)
Block(-4,5,-2,DIRT:1)
Block(-4,5,-1,DIRT:1)
Block(-4,5,0,DIRT:1)
Block(-4,5,1,DIRT:1)
Block(-4,5,2,DIRT:1)
Block(-4,5,3,DIRT:1)
Block(-4,5,4,DIRT:1)
Block(-4,5,5,DIRT:1)
Block(-4,5,6,DIRT:1)
Block(-4,5,7,DIRT:1)
Block(-4,5,8,DIRT:1)
Block(-4,6,-7,DIRT:1)
Block(-4,6,-6,DIRT:1)
Block(-4,6,-5,DIRT:1)
Block(-4,6,-4,DIRT:1)
Block(-4,6,-3,DIRT:1)
Block(-4,6,-2,DIRT:1)
Block(-4,6,-1,DIRT:1)
Block(-4,6,0,DIRT:1)
Block(-4,6,1,DIRT:1)
Block(-4,6,2,DIRT:1)
Block(-4,6,3,DIRT:1)
Block(-4,6,4,DIRT:1)
Block(-4,6,5,DIRT:1)
Block(-4,6,6,DIRT:1)
Block(-4,6,7,DIRT:1)
Block(-4,6,8,DIRT:1)
Block(-4,7,-7,DIRT:1)
Block(-4,7,-6,DIRT:1)
Block(-4,7,-5,DIRT:1)
Block(-4,7,-4,DIRT:1)
Block(-4,7,-3,DIRT:1)
Block(-4,7,-2,DIRT:1)
Block(-4,7,-1,DIRT:1)
Block(-4,7,0,DIRT:1)
Block(-4,7,1,DIRT:1)
Block(-4,7,2,DIRT:1)
Block(-4,7,3,DIRT:1)
Block(-4,7,4,DIRT:1)
Block(-4,7,5,DIRT:1)
Block(-4,7,6,DIRT:1)
Block(-4,8,-7,DIRT:1)
Block(-4,8,-6,DIRT:1)
Block(-4,8,-5,DIRT:1)
Block(-4,8,-4,DIRT:1)
Block(-4,8,-3,DIRT:1)
Block(-4,8,-2,DIRT:1)
Block(-4,8,-1,DIRT:1)
Block(-4,8,0,DIRT:1)
Block(-4,8,1,DIRT:1)
Block(-4,8,2,DIRT:1)
Block(-4,8,3,DIRT:1)
Block(-4,8,4,DIRT:1)
Block(-4,9,-7,DIRT:1)
Block(-4,9,-6,DIRT:1)
Block(-4,9,-5,DIRT:1)
Block(-4,9,-4,DIRT:1)
Block(-4,9,-3,DIRT:1)
Block(-4,9,-2,DIRT:1)
Block(-4,9,-1,DIRT:1)
Block(-4,9,0,DIRT:1)
Block(-4,9,1,DIRT:1)
Block(-4,9,2,DIRT:1)
Block(-4,10,-7,DIRT:1)
Block(-4,10,-6,DIRT:1)
Block(-4,10,-5,DIRT:1)
Block(-4,10,-4,DIRT:1)
Block(-4,10,-3,DIRT:1)
Block(-4,10,-2,DIRT:1)
Block(-4,10,-1,DIRT:1)
Block(-4,10,0,DIRT:1)
Block(-4,11,-7,DIRT:1)
Block(-4,11,-6,DIRT:1)
Block(-4,11,-5,DIRT:1)
Block(-4,11,-4,DIRT:1)
Block(-4,11,-3,DIRT:1)
Block(-4,11,-2,DIRT:1)
Block(-4,12,-7,DIRT:1)
Block(-4,12,-6,DIRT:1)
Block(-4,12,-5,DIRT:1)
Block(-4,12,-4,DIRT:1)
Block(-4,13,-7,DIRT:1)
Block(-4,13,-6,DIRT:1)
Block(-3,3,-5,DIRT:1)
Block(-3,3,-4,DIRT:1)
Block(-3,3,-3,DIRT:1)
Block(-3,3,-2,DIRT:1)
Block(-3,3,-1,DIRT:1)
Block(-3,3,0,DIRT:1)
Block(-3,3,1,DIRT:1)
Block(-3,3,2,DIRT:1)
Block(-3,4,-7,DIRT:1)
Block(-3,4,-6,DIRT:1)
Block(-3,4,-5,DIRT:1)
Block(-3,4,-4,DIRT:1)
Block(-3,4,-3,DIRT:1)
Block(-3,4,-2,DIRT:1)
Block(-3,4,-1,DIRT:1)
Block(-3,4,0,DIRT:1)
Block(-3,4,1,DIRT:1)
Block(-3,4,2,DIRT:1)
Block(-3,4,3,DIRT:1)
Block(-3,4,4,DIRT:1)
Block(-3,4,5,DIRT:1)
Block(-3,4,6,DIRT:1)
Block(-3,4,7,DIRT:1)
Block(-3,4,8,DIRT:1)
Block(-3,5,-7,DIRT:1)
Block(-3,5,-6,DIRT:1)
Block(-3,5,-5,DIRT:1)
Block(-3,5,-4,DIRT:1)
Block(-3,5,-3,DIRT:1)
Block(-3,5,-2,DIRT:1)
Block(-3,5,-1,DIRT:1)
Block(-3,5,0,DIRT:1)
Block(-3,5,1,DIRT:1)
Block(-3,5,2,DIRT:1)
Block(-3,5,3,DIRT:1)
Block(-3,5,4,DIRT:1)
Block(-3,5,5,DIRT:1)
Block(-3,5,6,DIRT:1)
Block(-3,5,7,DIRT:1)
Block(-3,5,8,DIRT:1)
Block(-3,6,-7,DIRT:1)
Block(-3,6,-6,DIRT:1)
Block(-3,6,-5,DIRT:1)
Block(-3,6,-4,DIRT:1)
Block(-3,6,-3,DIRT:1)
Block(-3,6,-2,DIRT:1)
Block(-3,6,-1,DIRT:1)
Block(-3,6,0,DIRT:1)
Block(-3,6,1,DIRT:1)
Block(-3,6,2,DIRT:1)
Block(-3,6,3,DIRT:1)
Block(-3,6,4,DIRT:1)
Block(-3,6,5,DIRT:1)
Block(-3,6,6,DIRT:1)
Block(-3,7,-7,DIRT:1)
Block(-3,7,-6,DIRT:1)
Block(-3,7,-5,DIRT:1)
Block(-3,7,-4,DIRT:1)
Block(-3,7,-3,DIRT:1)
Block(-3,7,-2,DIRT:1)
Block(-3,7,-1,DIRT:1)
Block(-3,7,0,DIRT:1)
Block(-3,7,1,DIRT:1)
Block(-3,7,2,DIRT:1)
Block(-3,7,3,DIRT:1)
Block(-3,7,4,DIRT:1)
Block(-3,8,-7,DIRT:1)
Block(-3,8,-6,DIRT:1)
Block(-3,8,-5,DIRT:1)
Block(-3,8,-4,DIRT:1)
Block(-3,8,-3,DIRT:1)
Block(-3,8,-2,DIRT:1)
Block(-3,8,-1,DIRT:1)
Block(-3,8,0,DIRT:1)
Block(-3,8,1,DIRT:1)
Block(-3,8,2,DIRT:1)
Block(-3,9,-7,DIRT:1)
Block(-3,9,-6,DIRT:1)
Block(-3,9,-5,DIRT:1)
Block(-3,9,-4,DIRT:1)
Block(-3,9,-3,DIRT:1)
Block(-3,9,-2,DIRT:1)
Block(-3,9,-1,DIRT:1)
Block(-3,9,0,DIRT:1)
Block(-3,10,-7,DIRT:1)
Block(-3,10,-6,DIRT:1)
Block(-3,10,-5,DIRT:1)
Block(-3,10,-4,DIRT:1)
Block(-3,10,-3,DIRT:1)
Block(-3,10,-2,DIRT:1)
Block(-3,11,-7,DIRT:1)
Block(-3,11,-6,DIRT:1)
Block(-3,11,-5,DIRT:1)
Block(-3,11,-4,DIRT:1)
Block(-3,12,-7,DIRT:1)
Block(-3,12,-6,DIRT:1)
Block(-2,3,-2,DIRT:1)
Block(-2,3,-1,DIRT:1)
Block(-2,3,0,DIRT:1)
Block(-2,3,1,DIRT:1)
Block(-2,4,-7,DIRT:1)
Block(-2,4,-6,DIRT:1)
Block(-2,4,-5,DIRT:1)
Block(-2,4,-4,DIRT:1)
Block(-2,4,-3,DIRT:1)
Block(-2,4,-2,DIRT:1)
Block(-2,4,-1,DIRT:1)
Block(-2,4,0,DIRT:1)
Block(-2,4,1,DIRT:1)
Block(-2,4,2,DIRT:1)
Block(-2,4,3,DIRT:1)
Block(-2,4,4,DIRT:1)
Block(-2,4,5,DIRT:1)
Block(-2,4,6,DIRT:1)
Block(-2,4,7,DIRT:1)
Block(-2,4,8,DIRT:1)
Block(-2,5,-7,DIRT:1)
Block(-2,5,-6,DIRT:1)
Block(-2,5,-5,DIRT:1)
Block(-2,5,-4,DIRT:1)
Block(-2,5,-3,DIRT:1)
Block(-2,5,-2,DIRT:1)
Block(-2,5,-1,DIRT:1)
Block(-2,5,0,DIRT:1)
Block(-2,5,1,DIRT:1)
Block(-2,5,2,DIRT:1)
Block(-2,5,3,DIRT:1)
Block(-2,5,4,DIRT:1)
Block(-2,5,5,DIRT:1)
Block(-2,5,6,DIRT:1)
Block(-2,5,7,DIRT:1)
Block(-2,6,-7,DIRT:1)
Block(-2,6,-6,DIRT:1)
Block(-2,6,-5,DIRT:1)
Block(-2,6,-4,DIRT:1)
Block(-2,6,-3,DIRT:1)
Block(-2,6,-2,DIRT:1)
Block(-2,6,-1,DIRT:1)
Block(-2,6,0,DIRT:1)
Block(-2,6,1,DIRT:1)
Block(-2,6,2,DIRT:1)
Block(-2,6,3,DIRT:1)
Block(-2,6,4,DIRT:1)
Block(-2,6,5,DIRT:1)
Block(-2,7,-7,DIRT:1)
Block(-2,7,-6,DIRT:1)
Block(-2,7,-5,DIRT:1)
Block(-2,7,-4,DIRT:1)
Block(-2,7,-3,DIRT:1)
Block(-2,7,-2,DIRT:1)
Block(-2,7,-1,DIRT:1)
Block(-2,7,0,DIRT:1)
Block(-2,7,1,DIRT:1)
Block(-2,7,2,DIRT:1)
Block(-2,7,3,DIRT:1)
Block(-2,8,-7,DIRT:1)
Block(-2,8,-6,DIRT:1)
Block(-2,8,-5,DIRT:1)
Block(-2,8,-4,DIRT:1)
Block(-2,8,-3,DIRT:1)
Block(-2,8,-2,DIRT:1)
Block(-2,8,-1,DIRT:1)
Block(-2,8,0,DIRT:1)
Block(-2,8,1,DIRT:1)
Block(-2,9,-7,DIRT:1)
Block(-2,9,-6,DIRT:1)
Block(-2,9,-5,DIRT:1)
Block(-2,9,-4,DIRT:1)
Block(-2,9,-3,DIRT:1)
Block(-2,9,-2,DIRT:1)
Block(-2,9,-1,DIRT:1)
Block(-2,10,-7,DIRT:1)
Block(-2,10,-6,DIRT:1)
Block(-2,10,-5,DIRT:1)
Block(-2,10,-4,DIRT:1)
Block(-2,10,-3,DIRT:1)
Block(-2,11,-7,DIRT:1)
Block(-2,11,-6,DIRT:1)
Block(-2,11,-5,DIRT:1)
Block(-2,12,-7,DIRT:1)
Block(-1,3,0,DIRT:1)
Block(-1,4,-7,DIRT:1)
Block(-1,4,-6,DIRT:1)
Block(-1,4,-5,DIRT:1)
Block(-1,4,-4,DIRT:1)
Block(-1,4,-3,DIRT:1)
Block(-1,4,-2,DIRT:1)
Block(-1,4,-1,DIRT:1)
Block(-1,4,0,DIRT:1)
Block(-1,4,1,DIRT:1)
Block(-1,4,2,DIRT:1)
Block(-1,4,3,DIRT:1)
Block(-1,4,4,DIRT:1)
Block(-1,4,5,DIRT:1)
Block(-1,4,6,DIRT:1)
Block(-1,4,7,DIRT:1)
Block(-1,4,8,DIRT:1)
Block(-1,5,-7,DIRT:1)
Block(-1,5,-6,DIRT:1)
Block(-1,5,-5,DIRT:1)
Block(-1,5,-4,DIRT:1)
Block(-1,5,-3,DIRT:1)
Block(-1,5,-2,DIRT:1)
Block(-1,5,-1,DIRT:1)
Block(-1,5,0,DIRT:1)
Block(-1,5,1,DIRT:1)
Block(-1,5,2,DIRT:1)
Block(-1,5,3,DIRT:1)
Block(-1,5,4,DIRT:1)
Block(-1,5,5,DIRT:1)
Block(-1,5,6,DIRT:1)
Block(-1,6,-7,DIRT:1)
Block(-1,6,-6,DIRT:1)
Block(-1,6,-5,DIRT:1)
Block(-1,6,-4,DIRT:1)
Block(-1,6,-3,DIRT:1)
Block(-1,6,-2,DIRT:1)
Block(-1,6,-1,DIRT:1)
Block(-1,6,0,DIRT:1)
Block(-1,6,1,DIRT:1)
Block(-1,6,2,DIRT:1)
Block(-1,6,3,DIRT:1)
Block(-1,6,4,DIRT:1)
Block(-1,7,-7,DIRT:1)
Block(-1,7,-6,DIRT:1)
Block(-1,7,-5,DIRT:1)
Block(-1,7,-4,DIRT:1)
Block(-1,7,-3,DIRT:1)
Block(-1,7,-2,DIRT:1)
Block(-1,7,-1,DIRT:1)
Block(-1,7,0,DIRT:1)
Block(-1,7,1,DIRT:1)
Block(-1,7,2,DIRT:1)
Block(-1,8,-7,DIRT:1)
Block(-1,8,-6,DIRT:1)
Block(-1,8,-5,DIRT:1)
Block(-1,8,-4,DIRT:1)
Block(-1,8,-3,DIRT:1)
Block(-1,8,-2,DIRT:1)
Block(-1,8,-1,DIRT:1)
Block(-1,8,0,DIRT:1)
Block(-1,9,-7,DIRT:1)
Block(-1,9,-6,DIRT:1)
Block(-1,9,-5,DIRT:1)
Block(-1,9,-4,DIRT:1)
Block(-1,9,-3,DIRT:1)
Block(-1,9,-2,DIRT:1)
Block(-1,10,-7,DIRT:1)
Block(-1,10,-6,DIRT:1)
Block(-1,10,-5,DIRT:1)
Block(-1,10,-4,DIRT:1)
Block(-1,11,-7,DIRT:1)
Block(-1,11,-6,DIRT:1)
Block(0,4,-7,DIRT:1)
Block(0,4,-6,DIRT:1)
Block(0,4,-5,DIRT:1)
Block(0,4,-4,DIRT:1)
Block(0,4,-3,DIRT:1)
Block(0,4,-2,DIRT:1)
Block(0,4,-1,DIRT:1)
Block(0,4,0,DIRT:1)
Block(0,4,1,DIRT:1)
Block(0,4,2,DIRT:1)
Block(0,4,3,DIRT:1)
Block(0,4,4,DIRT:1)
Block(0,4,5,DIRT:1)
Block(0,4,6,DIRT:1)
Block(0,4,7,DIRT:1)
Block(0,5,-7,DIRT:1)
Block(0,5,-6,DIRT:1)
Block(0,5,-5,DIRT:1)
Block(0,5,-4,DIRT:1)
Block(0,5,-3,DIRT:1)
Block(0,5,-2,DIRT:1)
Block(0,5,-1,DIRT:1)
Block(0,5,0,DIRT:1)
Block(0,5,1,DIRT:1)
Block(0,5,2,DIRT:1)
Block(0,5,3,DIRT:1)
Block(0,5,4,DIRT:1)
Block(0,5,5,DIRT:1)
Block(0,6,-7,DIRT:1)
Block(0,6,-6,DIRT:1)
Block(0,6,-5,DIRT:1)
Block(0,6,-4,DIRT:1)
Block(0,6,-3,DIRT:1)
Block(0,6,-2,DIRT:1)
Block(0,6,-1,DIRT:1)
Block(0,6,0,DIRT:1)
Block(0,6,1,DIRT:1)
Block(0,6,2,DIRT:1)
Block(0,6,3,DIRT:1)
Block(0,7,-7,DIRT:1)
Block(0,7,-6,DIRT:1)
Block(0,7,-5,DIRT:1)
Block(0,7,-4,DIRT:1)
Block(0,7,-3,DIRT:1)
Block(0,7,-2,DIRT:1)
Block(0,7,-1,DIRT:1)
Block(0,7,0,DIRT:1)
Block(0,7,1,DIRT:1)
Block(0,8,-7,DIRT:1)
Block(0,8,-6,DIRT:1)
Block(0,8,-5,DIRT:1)
Block(0,8,-4,DIRT:1)
Block(0,8,-3,DIRT:1)
Block(0,8,-2,DIRT:1)
Block(0,8,-1,DIRT:1)
Block(0,9,-7,DIRT:1)
Block(0,9,-6,DIRT:1)
Block(0,9,-5,DIRT:1)
Block(0,9,-4,DIRT:1)
Block(0,9,-3,DIRT:1)
Block(0,10,-7,DIRT:1)
Block(0,10,-6,DIRT:1)
Block(0,10,-5,DIRT:1)
Block(0,11,-7,DIRT:1)
Block(1,4,-7,DIRT:1)
Block(1,4,-6,DIRT:1)
Block(1,4,-5,DIRT:1)
Block(1,4,-4,DIRT:1)
Block(1,4,-3,DIRT:1)
Block(1,4,-2,DIRT:1)
Block(1,4,-1,DIRT:1)
Block(1,4,0,DIRT:1)
Block(1,4,1,DIRT:1)
Block(1,4,2,DIRT:1)
Block(1,4,3,DIRT:1)
Block(1,4,4,DIRT:1)
Block(1,4,5,DIRT:1)
Block(1,4,6,DIRT:1)
Block(1,5,-7,DIRT:1)
Block(1,5,-6,DIRT:1)
Block(1,5,-5,DIRT:1)
Block(1,5,-4,DIRT:1)
Block(1,5,-3,DIRT:1)
Block(1,5,-2,DIRT:1)
Block(1,5,-1,DIRT:1)
Block(1,5,0,DIRT:1)
Block(1,5,1,DIRT:1)
Block(1,5,2,DIRT:1)
Block(1,5,3,DIRT:1)
Block(1,5,4,DIRT:1)
Block(1,6,-7,DIRT:1)
Block(1,6,-6,DIRT:1)
Block(1,6,-5,DIRT:1)
Block(1,6,-4,DIRT:1)
Block(1,6,-3,DIRT:1)
Block(1,6,-2,DIRT:1)
Block(1,6,-1,DIRT:1)
Block(1,6,0,DIRT:1)
Block(1,6,1,DIRT:1)
Block(1,6,2,DIRT:1)
Block(1,7,-7,DIRT:1)
Block(1,7,-6,DIRT:1)
Block(1,7,-5,DIRT:1)
Block(1,7,-4,DIRT:1)
Block(1,7,-3,DIRT:1)
Block(1,7,-2,DIRT:1)
Block(1,7,-1,DIRT:1)
Block(1,7,0,DIRT:1)
Block(1,8,-7,DIRT:1)
Block(1,8,-6,DIRT:1)
Block(1,8,-5,DIRT:1)
Block(1,8,-4,DIRT:1)
Block(1,8,-3,DIRT:1)
Block(1,8,-2,DIRT:1)
Block(1,9,-7,DIRT:1)
Block(1,9,-6,DIRT:1)
Block(1,9,-5,DIRT:1)
Block(1,9,-4,DIRT:1)
Block(1,10,-7,DIRT:1)
Block(1,10,-6,DIRT:1)
Block(2,4,-7,DIRT:1)
Block(2,4,-6,DIRT:1)
Block(2,4,-5,DIRT:1)
Block(2,4,-4,DIRT:1)
Block(2,4,-3,DIRT:1)
Block(2,4,-2,DIRT:1)
Block(2,4,-1,DIRT:1)
Block(2,4,0,DIRT:1)
Block(2,4,1,DIRT:1)
Block(2,4,2,DIRT:1)
Block(2,4,3,DIRT:1)
Block(2,4,4,DIRT:1)
Block(2,5,-7,DIRT:1)
Block(2,5,-6,DIRT:1)
Block(2,5,-5,DIRT:1)
Block(2,5,-4,DIRT:1)
Block(2,5,-3,DIRT:1)
Block(2,5,-2,DIRT:1)
Block(2,5,-1,DIRT:1)
Block(2,5,0,DIRT:1)
Block(2,5,1,DIRT:1)
Block(2,5,2,DIRT:1)
Block(2,6,-7,DIRT:1)
Block(2,6,-6,DIRT:1)
Block(2,6,-5,DIRT:1)
Block(2,6,-4,DIRT:1)
Block(2,6,-3,DIRT:1)
Block(2,6,-2,DIRT:1)
Block(2,6,-1,DIRT:1)
Block(2,6,0,DIRT:1)
Block(2,7,-7,DIRT:1)
Block(2,7,-6,DIRT:1)
Block(2,7,-5,DIRT:1)
Block(2,7,-4,DIRT:1)
Block(2,7,-3,DIRT:1)
Block(2,7,-2,DIRT:1)
Block(2,8,-7,DIRT:1)
Block(2,8,-6,DIRT:1)
Block(2,8,-5,DIRT:1)
Block(2,8,-4,DIRT:1)
Block(2,9,-7,DIRT:1)
Block(2,9,-6,DIRT:1)
Block(3,4,-7,DIRT:1)
Block(3,4,-6,DIRT:1)
Block(3,4,-5,DIRT:1)
Block(3,4,-4,DIRT:1)
Block(3,4,-3,DIRT:1)
Block(3,4,-2,DIRT:1)
Block(3,4,-1,DIRT:1)
Block(3,4,0,DIRT:1)
Block(3,4,1,DIRT:1)
Block(3,4,2,DIRT:1)
Block(3,4,3,DIRT:1)
Block(3,5,-7,DIRT:1)
Block(3,5,-6,DIRT:1)
Block(3,5,-5,DIRT:1)
Block(3,5,-4,DIRT:1)
Block(3,5,-3,DIRT:1)
Block(3,5,-2,DIRT:1)
Block(3,5,-1,DIRT:1)
Block(3,5,0,DIRT:1)
Block(3,5,1,DIRT:1)
Block(3,6,-7,DIRT:1)
Block(3,6,-6,DIRT:1)
Block(3,6,-5,DIRT:1)
Block(3,6,-4,DIRT:1)
Block(3,6,-3,DIRT:1)
Block(3,6,-2,DIRT:1)
Block(3,6,-1,DIRT:1)
Block(3,7,-7,DIRT:1)
Block(3,7,-6,DIRT:1)
Block(3,7,-5,DIRT:1)
Block(3,7,-4,DIRT:1)
Block(3,7,-3,DIRT:1)
Block(3,8,-7,DIRT:1)
Block(3,8,-6,DIRT:1)
Block(3,8,-5,DIRT:1)
Block(4,4,-7,DIRT:1)
Block(4,4,-6,DIRT:1)
Block(4,4,-5,DIRT:1)
Block(4,4,-4,DIRT:1)
Block(4,4,-3,DIRT:1)
Block(4,4,-2,DIRT:1)
Block(4,4,-1,DIRT:1)
Block(4,4,0,DIRT:1)
Block(4,4,1,DIRT:1)
Block(4,4,2,DIRT:1)
Block(4,5,-7,DIRT:1)
Block(4,5,-6,DIRT:1)
Block(4,5,-5,DIRT:1)
Block(4,5,-4,DIRT:1)
Block(4,5,-3,DIRT:1)
Block(4,5,-2,DIRT:1)
Block(4,5,-1,DIRT:1)
Block(4,5,0,DIRT:1)
Block(4,6,-6,DIRT:1)
Block(4,6,-5,DIRT:1)
Block(4,6,-4,DIRT:1)
Block(4,6,-3,DIRT:1)
Block(4,6,-2,DIRT:1)
Block(4,7,-5,DIRT:1)
Block(4,7,-4,DIRT:1)
Block(5,4,-5,DIRT:1)
Block(5,4,-4,DIRT:1)
Block(5,4,-3,DIRT:1)
Block(5,4,-2,DIRT:1)
Block(5,4,-1,DIRT:1)
Block(5,4,0,DIRT:1)
Block(5,4,1,DIRT:1)
Block(5,5,-5,DIRT:1)
Block(5,5,-4,DIRT:1)
Block(5,5,-3,DIRT:1)
Block(5,5,-2,DIRT:1)
Block(5,5,-1,DIRT:1)
Block(5,6,-4,DIRT:1)
Block(5,6,-3,DIRT:1)
Block(6,4,-3,DIRT:1)
Block(6,4,-2,DIRT:1)
Block(6,4,-1,DIRT:1)
Block(6,4,0,DIRT:1)
Block(6,5,-2,DIRT:1)
Block(7,4,-1,DIRT:1)

#######################################################################
# +-----------------------------------------------------------------+ #
# |                             Branches                            | #
# +-----------------------------------------------------------------+ #
#######################################################################

Branch(0,0,16,true,MudSpike_Huge_14C3R6,NORTH,100.0,0)
Branch(-16,0,0,true,MudSpike_Huge_14C2R5,NORTH,100.0,0)

#######################################################################
# +-----------------------------------------------------------------+ #
# |                             Entities                            | #
# +-----------------------------------------------------------------+ #
#######################################################################


#######################################################################
# +-----------------------------------------------------------------+ #
# |                            Particles                            | #
# +-----------------------------------------------------------------+ #
#######################################################################


#######################################################################
# +-----------------------------------------------------------------+ #
# |                             Spawners                            | #
# +-----------------------------------------------------------------+ #
#######################################################################


#######################################################################
# +-----------------------------------------------------------------+ #
# |                             ModData                             | #
# +-----------------------------------------------------------------+ #
#######################################################################

