Author: NLBlackEagle
Description: No description given
SettingsMode: WriteDisable
Frequency: 0
SpawnHeight: highestBlock
UseCenterForHighestBlock: true
MinHeight: 0
MaxHeight: 255
InheritBO3: 
InheritBO3Rotation: NORTH
OverrideChildSettings: true
OverrideParentHeight: false
CanOverride: false
BranchFrequency: 0
BranchFrequencyGroup: 
MustBeBelowOther: false
MustBeInside: 
CannotBeInside: 
ReplacesBO3: 
MustBeInsideWorldBorders: false
CanSpawnOnWater: true
SpawnOnWaterOnly: false
SpawnUnderWater: false
SpawnAtWaterLevel: false
HeightOffset: 0
RemoveAir: false
ReplaceAbove: 
ReplaceBelow: 
ReplaceWithBiomeBlocks: false
ReplaceWithSurfaceBlock: GRASS
ReplaceWithGroundBlock: DIRT
ReplaceWithStoneBlock: STONE
SmoothRadius: 0
SmoothHeightOffset: 0
SmoothStartTop: false
SmoothStartWood: false
SmoothingSurfaceBlock: 
SmoothingGroundBlock: 
BO3Group: 
IsSpawnPoint: false
DoReplaceBlocks: false
Block(-8,10,8,LOG:13)
Block(-8,11,8,WOOD:0)
Block(-8,12,8,WOOD:0)
Block(-8,13,6,WOOD_STEP:8)
Block(-8,13,7,LOG:13)
Block(-8,13,8,WOOD:0)
RandomBlock(-8,14,4,WALL_BANNER:2,../../Banners/royal_01.nbt,20,WALL_BANNER:2,../../Banners/royal_02.nbt,20,WALL_BANNER:2,../../Banners/royal_03.nbt,20,WALL_BANNER:2,../../Banners/royal_04.nbt,20,WALL_BANNER:2,../../Banners/royal_05.nbt,100)
Block(-8,14,5,WOOD:0)
Block(-8,14,6,WOOD:0)
Block(-8,14,7,WOOD:0)
Block(-8,14,8,WOOD:0)
Block(-8,15,-3,WOOL:15)
Block(-8,15,4,WOOD_STEP:9)
Block(-8,15,5,WOOD_DOUBLE_STEP:1)
Block(-8,15,6,WOOD_DOUBLE_STEP:1)
Block(-8,15,7,WOOD_STEP:1)
Block(-8,15,8,WOOD:5)
Block(-8,16,-3,WOOL:11)
Block(-8,16,2,WOOD_STEP:9)
Block(-8,16,3,WOOD_DOUBLE_STEP:1)
Block(-8,16,4,WOOD_DOUBLE_STEP:1)
Block(-8,16,5,WOOD_STEP:1)
Block(-8,16,8,WOOD:5)
Block(-8,17,-3,WOOL:11)
Block(-8,17,0,WOOD_STEP:9)
Block(-8,17,1,WOOD_DOUBLE_STEP:1)
Block(-8,17,2,WOOD_DOUBLE_STEP:1)
Block(-8,17,3,WOOD_STEP:1)
Block(-8,17,8,WOOD:5)
Block(-8,18,-2,WOOD_STEP:9)
Block(-8,18,-1,WOOD_DOUBLE_STEP:1)
Block(-8,18,0,WOOD_DOUBLE_STEP:1)
Block(-8,18,1,WOOD_STEP:1)
Block(-8,18,8,WOOD_STEP:5)
Block(-8,19,-4,WOOD_STEP:9)
Block(-8,19,-3,WOOD_DOUBLE_STEP:1)
Block(-8,19,-2,WOOD_DOUBLE_STEP:1)
Block(-8,19,-1,WOOD_STEP:1)
Block(-8,19,0,FENCE:0)
Block(-8,19,1,FENCE:0)
Block(-8,20,-7,WOOD_STEP:9)
Block(-8,20,-6,WOOD_STEP:9)
Block(-8,20,-5,WOOD_DOUBLE_STEP:1)
Block(-8,20,-4,WOOD_DOUBLE_STEP:1)
Block(-8,20,-3,WOOD_STEP:1)
Block(-8,20,1,FENCE:0)
Block(-8,20,2,FENCE:0)
Block(-8,21,2,FENCE:0)
Block(-8,21,3,FENCE:0)
Block(-8,21,8,WOOL:11)
Block(-8,22,3,FENCE:0)
Block(-8,22,4,FENCE:0)
Block(-8,22,7,WOOL:15)
Block(-8,23,4,FENCE:0)
Block(-8,23,5,FENCE:0)
Block(-8,23,7,WOOL:15)
Block(-8,24,5,FENCE:0)
Block(-8,24,6,FENCE:0)
Block(-8,24,7,WOOL:15)
Block(-8,25,6,FENCE:0)
Block(-8,25,7,FENCE:0)
Block(-8,25,8,WOOL:15)
Block(-8,26,7,FENCE:0)
Block(-8,26,8,FENCE:0)
Block(-8,27,8,FENCE:0)
Block(-8,30,8,WOOL:15)
Block(-8,31,8,WOOL:11)
Block(-8,32,7,WOOL:15)
Block(-8,33,7,WOOL:15)
Block(-8,34,7,WOOL:15)
Block(-8,35,8,WOOL:11)
Block(-8,36,8,WOOL:11)
Block(-7,12,8,WOOD:0)
Block(-7,13,7,WOOD_STEP:8)
Block(-7,13,8,WOOD:0)
Block(-7,14,5,WOOD:0)
Block(-7,14,6,WOOD:0)
Block(-7,14,7,WOOD:0)
Block(-7,14,8,WOOD:0)
Block(-7,15,-3,WOOL:15)
Block(-7,15,4,FENCE:0)
Block(-7,15,5,WOOD_DOUBLE_STEP:5)
Block(-7,15,6,WOOD_STEP:5)
Block(-7,15,8,WOOD:5)
Block(-7,16,-3,WOOL:11)
Block(-7,16,7,DISPENSER:2)
Block(-7,16,8,CONCRETE:15)
Block(-7,17,-3,WOOL:11)
Block(-7,17,7,WOOD_STEP:13)
Block(-7,17,8,WOOD_STEP:13)
Block(-7,18,8,WOOD_STEP:5)
Block(-7,19,-1,WOOD_STEP:1)
Block(-7,21,8,WOOL:15)
Block(-7,22,8,WOOL:15)
Block(-7,23,7,WOOL:15)
Block(-7,24,8,WOOL:15)
Block(-7,25,8,WOOL:11)
Block(-7,26,8,WOOL:11)
Block(-7,30,8,WOOL:15)
Block(-7,31,8,WOOL:11)
Block(-7,32,8,WOOL:15)
Block(-7,33,7,WOOL:15)
Block(-7,34,8,WOOL:15)
Block(-7,35,8,WOOL:11)
Block(-7,36,8,WOOL:11)
Block(-6,12,6,FENCE:0)
Block(-6,12,7,FENCE:0)
Block(-6,12,8,FENCE:0)
Block(-6,13,8,WOOD:0)
Block(-6,14,-2,WOOL:15)
Block(-6,14,7,WOOD:0)
Block(-6,14,8,WOOD:0)
Block(-6,15,-2,WOOL:11)
Block(-6,15,4,FENCE:0)
Block(-6,15,5,TRAP_DOOR:7)
Block(-6,15,7,WOOD_STEP:5)
Block(-6,15,8,WOOD:5)
Block(-6,16,-3,WOOL:11)
Block(-6,16,3,FENCE:0)
Block(-6,16,4,FENCE:0)
Block(-6,16,8,WOOD:5)
Block(-6,17,-2,WOOL:11)
Block(-6,17,8,WOOD:5)
Block(-6,18,-2,WOOL:15)
Block(-6,18,0,FENCE:0)
Block(-6,18,8,WOOD_STEP:5)
Block(-6,19,0,WOOD_STEP:1)
Block(-6,21,8,WOOL:11)
Block(-6,22,8,WOOL:11)
Block(-6,23,8,WOOL:15)
Block(-6,24,8,WOOL:11)
Block(-6,25,8,WOOL:11)
Block(-6,31,8,WOOL:11)
Block(-6,32,8,WOOL:11)
Block(-6,33,8,WOOL:15)
Block(-6,34,8,WOOL:11)
Block(-6,35,8,WOOL:11)
Block(-5,12,5,FENCE:0)
Block(-5,12,6,FENCE:0)
Block(-5,13,5,FENCE:0)
Block(-5,14,-1,WOOL:15)
Block(-5,14,8,WOOD:0)
Block(-5,15,-2,WOOL:11)
Block(-5,15,8,WOOD:5)
Block(-5,16,-2,WOOL:11)
Block(-5,16,3,FENCE:0)
Block(-5,16,8,TRAP_DOOR:7)
Block(-5,17,-2,WOOL:11)
Block(-5,17,2,FENCE:0)
Block(-5,17,3,FENCE:0)
Block(-5,17,8,TRAP_DOOR:15)
Block(-5,18,-1,WOOL:15)
Block(-5,18,0,FENCE:0)
Block(-5,19,0,WOOD_STEP:1)
Block(-5,22,8,WOOL:11)
Block(-5,23,8,WOOL:11)
Block(-5,24,8,WOOL:11)
Block(-5,32,8,WOOL:11)
Block(-5,33,8,WOOL:11)
Block(-5,34,8,WOOL:11)
Block(-4,13,-1,WOOL:11)
Block(-4,13,3,FENCE:0)
Block(-4,13,4,FENCE:0)
Block(-4,13,5,FENCE:0)
Block(-4,14,-1,WOOL:15)
Block(-4,14,0,WOOL:11)
Block(-4,15,-1,WOOL:11)
Block(-4,16,-2,WOOL:11)
Block(-4,17,-2,WOOL:11)
Block(-4,17,2,FENCE:0)
Block(-4,18,-1,WOOL:11)
Block(-4,18,0,FENCE:0)
Block(-4,18,2,FENCE:0)
Block(-4,19,0,WOOD_STEP:1)
Block(-4,23,8,WOOL:11)
Block(-4,33,8,WOOL:11)
Block(-3,13,1,WOOL:15)
Block(-3,13,2,WOOL:15)
Block(-3,13,3,FENCE:0)
Block(-3,14,0,WOOL:11)
Block(-3,14,1,WOOL:15)
Block(-3,18,-1,WOOL:15)
Block(-3,18,0,WOOL:15)
Block(-3,18,2,FENCE:0)
Block(-3,19,0,WOOL:11)
Block(-3,19,1,WOOL:11)
Block(-3,19,2,FENCE:0)
Branch(0,0,16,true,Royal_FloatC1R1,NORTH,100.0,0)
