
#######################################################################
# +-----------------------------------------------------------------+ #
# |                            BO3 object                           | #
# +-----------------------------------------------------------------+ #
#######################################################################

Author: NLBlackHeavenNL

Description: No description given

Version: 3

SettingsMode: WriteWithoutComments


#######################################################################
# +-----------------------------------------------------------------+ #
# |                          Main settings                          | #
# +-----------------------------------------------------------------+ #
#######################################################################

Tree: true

Frequency: 1

Rarity: 100.0

RotateRandomly: false

SpawnHeight: highestSolidBlock

SpawnHeightOffset: -1

SpawnHeightVariance: 0

##############################
# Height Limits for the BO3. #
##############################

MinHeight: 0

MaxHeight: 255

######################
# Extrusion settings #
######################

ExtrudeMode: None

ExtrudeThroughBlocks: AIR

MaxBranchDepth: 10

ExcludedBiomes: All


#######################################################################
# +-----------------------------------------------------------------+ #
# |                      Source block settings                      | #
# +-----------------------------------------------------------------+ #
#######################################################################

SourceBlocks: AIR,GRASS,DIRT,biomesoplenty:dirt,MYCEL

MaxPercentageOutsideSourceBlock: 0

OutsideSourceBlock: placeAnyway

DoReplaceBlocks: true

IsOTGPlus: false


#######################################################################
# +-----------------------------------------------------------------+ #
# |                              Blocks                             | #
# +-----------------------------------------------------------------+ #
#######################################################################

Block(-6,5,3,rustic:leaves0:4)
Block(-6,6,2,rustic:leaves0:4)
Block(-6,6,3,rustic:leaves0:4)
Block(-5,5,2,rustic:leaves0:4)
Block(-5,5,3,rustic:leaves0:7)
Block(-5,5,4,rustic:leaves0:4)
Block(-5,6,1,rustic:leaves0:4)
Block(-5,6,2,rustic:leaves0:5)
Block(-5,6,3,rustic:leaves0:6)
Block(-5,6,4,rustic:leaves0:4)
Block(-5,7,2,rustic:leaves0:4)
Block(-5,7,3,rustic:leaves0:4)
Block(-5,7,4,rustic:leaves0:4)
Block(-5,7,5,rustic:leaves0:4)
Block(-5,8,2,rustic:leaves0:4)
Block(-5,8,3,rustic:leaves0:4)
Block(-5,8,4,rustic:leaves0:4)
Block(-4,5,1,rustic:leaves0:4)
Block(-4,5,3,rustic:ironwoodbranch)
Block(-4,6,-2,rustic:leaves0:4)
Block(-4,6,-1,rustic:leaves0:4)
Block(-4,6,0,rustic:leaves0:4)
Block(-4,6,1,rustic:leaves0:5)
Block(-4,6,2,rustic:leaves0:6)
Block(-4,6,3,rustic:leaves0:7)
Block(-4,6,4,rustic:leaves0:4)
Block(-4,6,5,rustic:leaves0:4)
Block(-4,7,-2,rustic:leaves0:4)
Block(-4,7,-1,rustic:leaves0:4)
Block(-4,7,0,rustic:leaves0:4)
Block(-4,7,1,rustic:leaves0:4)
Block(-4,7,2,rustic:leaves0:6)
Block(-4,7,3,rustic:leaves0:7)
Block(-4,7,4,rustic:leaves0:6)
Block(-4,7,5,rustic:leaves0:5)
Block(-4,7,6,rustic:leaves0:4)
Block(-4,8,1,rustic:leaves0:4)
Block(-4,8,2,rustic:leaves0:5)
Block(-4,8,3,rustic:leaves0:6)
Block(-4,8,4,rustic:leaves0:5)
Block(-4,8,5,rustic:leaves0:4)
Block(-4,9,2,rustic:leaves0:4)
Block(-4,9,3,rustic:leaves0:4)
Block(-4,9,4,rustic:leaves0:4)
Block(-3,5,-2,rustic:leaves0:4)
Block(-3,5,-1,rustic:leaves0:4)
Block(-3,5,0,rustic:leaves0:4)
Block(-3,5,1,rustic:leaves0:7)
Block(-3,5,2,rustic:ironwoodbranch)
Block(-3,5,3,rustic:ironwoodbranch:2)
Block(-3,5,6,rustic:leaves0:4)
Block(-3,6,-3,rustic:leaves0:4)
Block(-3,6,-2,rustic:leaves0:6)
Block(-3,6,-1,rustic:leaves0:7)
Block(-3,6,0,rustic:leaves0:6)
Block(-3,6,1,rustic:leaves0:6)
Block(-3,6,2,rustic:leaves0:7)
Block(-3,6,3,rustic:ironwoodbranch:1)
Block(-3,6,4,rustic:leaves0:4)
Block(-3,6,5,rustic:leaves0:4)
Block(-3,6,6,rustic:leaves0:4)
Block(-3,6,7,rustic:leaves0:4)
Block(-3,7,-3,rustic:leaves0:4)
Block(-3,7,-2,rustic:leaves0:5)
Block(-3,7,-1,rustic:leaves0:6)
Block(-3,7,0,rustic:leaves0:5)
Block(-3,7,1,rustic:leaves0:4)
Block(-3,7,2,rustic:leaves0:7)
Block(-3,7,3,rustic:ironwoodbranch)
Block(-3,7,4,rustic:leaves0:7)
Block(-3,7,5,rustic:leaves0:6)
Block(-3,7,6,rustic:leaves0:4)
Block(-3,8,-2,rustic:leaves0:4)
Block(-3,8,-1,rustic:leaves0:4)
Block(-3,8,0,rustic:leaves0:4)
Block(-3,8,1,rustic:leaves0:4)
Block(-3,8,2,rustic:leaves0:6)
Block(-3,8,3,rustic:leaves0:7)
Block(-3,8,4,rustic:leaves0:6)
Block(-3,8,5,rustic:leaves0:5)
Block(-3,8,6,rustic:leaves0:4)
Block(-3,9,2,rustic:leaves0:4)
Block(-3,9,3,rustic:leaves0:4)
Block(-3,9,4,rustic:leaves0:4)
Block(-3,9,5,rustic:leaves0:4)
Block(-3,12,1,rustic:leaves0:4)
Block(-3,12,2,rustic:leaves0:4)
Block(-3,12,3,rustic:leaves0:4)
Block(-3,12,4,rustic:leaves0:4)
Block(-3,13,1,rustic:leaves0:4)
Block(-3,13,2,rustic:leaves0:4)
Block(-3,13,3,rustic:leaves0:4)
Block(-3,14,2,rustic:leaves0:4)
Block(-2,5,-2,rustic:leaves0:4)
Block(-2,5,-1,rustic:ironwoodbranch:1)
Block(-2,5,0,rustic:ironwoodbranch:1)
Block(-2,5,3,rustic:ironwoodbranch:2)
Block(-2,5,6,rustic:leaves0:5)
Block(-2,5,7,rustic:leaves0:4)
Block(-2,6,-3,rustic:leaves0:4)
Block(-2,6,-2,rustic:leaves0:7)
Block(-2,6,-1,rustic:ironwoodbranch)
Block(-2,6,0,rustic:leaves0:7)
Block(-2,6,1,rustic:leaves0:4)
Block(-2,6,5,rustic:leaves0:7)
Block(-2,6,6,rustic:leaves0:6)
Block(-2,6,7,rustic:leaves0:5)
Block(-2,6,8,rustic:leaves0:4)
Block(-2,7,-3,rustic:leaves0:4)
Block(-2,7,-2,rustic:leaves0:6)
Block(-2,7,-1,rustic:leaves0:7)
Block(-2,7,0,rustic:leaves0:6)
Block(-2,7,1,rustic:leaves0:4)
Block(-2,7,2,rustic:leaves0:4)
Block(-2,7,4,rustic:ironwoodbranch)
Block(-2,7,5,rustic:leaves0:7)
Block(-2,7,6,rustic:leaves0:5)
Block(-2,7,7,rustic:leaves0:4)
Block(-2,8,-2,rustic:leaves0:4)
Block(-2,8,-1,rustic:leaves0:4)
Block(-2,8,0,rustic:leaves0:4)
Block(-2,8,3,rustic:leaves0:6)
Block(-2,8,4,rustic:leaves0:7)
Block(-2,8,5,rustic:leaves0:6)
Block(-2,8,6,rustic:leaves0:4)
Block(-2,9,3,rustic:leaves0:4)
Block(-2,9,4,rustic:leaves0:4)
Block(-2,9,5,rustic:leaves0:4)
Block(-2,11,1,rustic:leaves0:4)
Block(-2,11,3,rustic:leaves0:4)
Block(-2,11,4,rustic:leaves0:4)
Block(-2,12,0,rustic:leaves0:4)
Block(-2,12,1,rustic:leaves0:6)
Block(-2,12,2,rustic:leaves0:7)
Block(-2,12,3,rustic:leaves0:6)
Block(-2,12,4,rustic:leaves0:5)
Block(-2,12,5,rustic:leaves0:4)
Block(-2,13,0,rustic:leaves0:4)
Block(-2,13,1,rustic:leaves0:5)
Block(-2,13,2,rustic:leaves0:6)
Block(-2,13,3,rustic:leaves0:5)
Block(-2,13,4,rustic:leaves0:4)
Block(-2,14,1,rustic:leaves0:4)
Block(-2,14,2,rustic:leaves0:5)
Block(-2,14,3,rustic:leaves0:4)
Block(-2,15,2,rustic:leaves0:4)
Block(-1,0,-1,GRASS:0)
Block(-1,1,-1,rustic:ironwoodroot:2)
Block(-1,5,-4,rustic:leaves0:4)
Block(-1,5,-3,rustic:leaves0:4)
Block(-1,5,-2,rustic:leaves0:4)
Block(-1,5,0,rustic:ironwoodbranch:2)
Block(-1,5,3,rustic:ironwoodbranch:4)
Block(-1,5,5,rustic:leaves0:7)
Block(-1,5,6,rustic:leaves0:6)
Block(-1,5,7,rustic:leaves0:5)
Block(-1,5,8,rustic:leaves0:4)
Block(-1,6,-4,rustic:leaves0:4)
Block(-1,6,-3,rustic:leaves0:5)
Block(-1,6,-2,rustic:leaves0:6)
Block(-1,6,-1,rustic:leaves0:7)
Block(-1,6,0,rustic:ironwoodbranch)
Block(-1,6,3,rustic:ironwoodbranch:2)
Block(-1,6,4,rustic:ironwoodbranch:2)
Block(-1,6,5,rustic:ironwoodbranch)
Block(-1,6,6,rustic:leaves0:7)
Block(-1,6,7,rustic:leaves0:6)
Block(-1,6,8,rustic:leaves0:4)
Block(-1,7,-3,rustic:leaves0:4)
Block(-1,7,-2,rustic:leaves0:5)
Block(-1,7,-1,rustic:leaves0:6)
Block(-1,7,0,rustic:leaves0:7)
Block(-1,7,4,rustic:ironwoodbranch:1)
Block(-1,7,5,rustic:leaves0:7)
Block(-1,7,6,rustic:leaves0:6)
Block(-1,7,7,rustic:leaves0:5)
Block(-1,7,8,rustic:leaves0:4)
Block(-1,8,-2,rustic:leaves0:4)
Block(-1,8,-1,rustic:leaves0:4)
Block(-1,8,0,rustic:leaves0:4)
Block(-1,8,5,rustic:leaves0:4)
Block(-1,8,6,rustic:leaves0:4)
Block(-1,8,7,rustic:leaves0:4)
Block(-1,11,0,rustic:leaves0:4)
Block(-1,11,4,rustic:leaves0:4)
Block(-1,11,5,rustic:leaves0:4)
Block(-1,12,0,rustic:leaves0:4)
Block(-1,12,1,rustic:leaves0:7)
Block(-1,12,2,rustic:ironwoodbranch)
Block(-1,12,3,rustic:leaves0:7)
Block(-1,12,4,rustic:leaves0:6)
Block(-1,12,5,rustic:leaves0:5)
Block(-1,12,6,rustic:leaves0:4)
Block(-1,13,-1,rustic:leaves0:4)
Block(-1,13,0,rustic:leaves0:5)
Block(-1,13,1,rustic:leaves0:6)
Block(-1,13,2,rustic:leaves0:7)
Block(-1,13,3,rustic:leaves0:6)
Block(-1,13,4,rustic:leaves0:5)
Block(-1,13,5,rustic:leaves0:4)
Block(-1,14,0,rustic:leaves0:4)
Block(-1,14,1,rustic:leaves0:5)
Block(-1,14,2,rustic:leaves0:6)
Block(-1,14,3,rustic:leaves0:5)
Block(-1,14,4,rustic:leaves0:4)
Block(-1,15,1,rustic:leaves0:4)
Block(-1,15,2,rustic:leaves0:5)
Block(-1,15,3,rustic:leaves0:4)
Block(-1,16,2,rustic:leaves0:4)
Block(0,0,-1,GRASS:0)
Block(0,0,0,GRASS:0)
Block(0,0,1,GRASS:0)
Block(0,0,2,GRASS:0)
Block(0,0,3,GRASS:0)
Block(0,0,5,rustic:ironwoodroot)
Block(0,1,-1,rustic:ironwoodroot:3)
Block(0,1,0,rustic:ironwoodroot:4)
Block(0,1,1,DIRT:2)
Block(0,1,2,DIRT:2)
Block(0,1,3,DIRT:2)
Block(0,2,1,rustic:ironwoodroot:5)
Block(0,2,2,dynamictrees:trunkshell:6)
Block(0,2,3,dynamictrees:trunkshell:7)
Block(0,3,1,dynamictrees:trunkshell:5)
Block(0,3,2,dynamictrees:trunkshell:6)
Block(0,3,3,dynamictrees:trunkshell:7)
Block(0,4,-4,rustic:leaves0:4)
Block(0,4,1,dynamictrees:trunkshell:5)
Block(0,4,2,dynamictrees:trunkshell:6)
Block(0,4,3,dynamictrees:trunkshell:7)
Block(0,5,-5,rustic:leaves0:4)
Block(0,5,-4,rustic:leaves0:6)
Block(0,5,-3,rustic:leaves0:7)
Block(0,5,0,rustic:ironwoodbranch:2)
Block(0,5,1,dynamictrees:trunkshell:5)
Block(0,5,2,dynamictrees:trunkshell:6)
Block(0,5,3,rustic:ironwoodbranch:4)
Block(0,5,7,rustic:leaves0:4)
Block(0,6,-5,rustic:leaves0:4)
Block(0,6,-4,rustic:leaves0:5)
Block(0,6,-3,rustic:leaves0:6)
Block(0,6,-2,rustic:leaves0:7)
Block(0,6,1,dynamictrees:trunkshell:5)
Block(0,6,2,dynamictrees:trunkshell:6)
Block(0,6,3,dynamictrees:trunkshell:7)
Block(0,6,6,rustic:ironwoodbranch)
Block(0,6,7,rustic:leaves0:7)
Block(0,6,8,rustic:leaves0:4)
Block(0,7,-4,rustic:leaves0:4)
Block(0,7,-3,rustic:leaves0:5)
Block(0,7,-2,rustic:leaves0:6)
Block(0,7,-1,rustic:leaves0:5)
Block(0,7,0,rustic:ironwoodbranch:2)
Block(0,7,6,rustic:leaves0:7)
Block(0,7,7,rustic:leaves0:6)
Block(0,7,8,rustic:leaves0:4)
Block(0,8,-3,rustic:leaves0:4)
Block(0,8,-2,rustic:leaves0:4)
Block(0,8,-1,rustic:leaves0:4)
Block(0,8,0,rustic:ironwoodbranch:1)
Block(0,8,6,rustic:leaves0:4)
Block(0,8,7,rustic:leaves0:4)
Block(0,9,0,rustic:ironwoodbranch:1)
Block(0,9,6,rustic:leaves0:4)
Block(0,10,0,rustic:ironwoodbranch)
Block(0,10,2,rustic:ironwoodbranch)
Block(0,11,-2,rustic:leaves0:4)
Block(0,11,-1,rustic:leaves0:4)
Block(0,11,0,rustic:leaves0:7)
Block(0,11,1,rustic:ironwoodbranch)
Block(0,11,2,rustic:leaves0:7)
Block(0,11,5,rustic:leaves0:4)
Block(0,12,-1,rustic:leaves0:4)
Block(0,12,0,rustic:leaves0:6)
Block(0,12,1,rustic:leaves0:7)
Block(0,12,2,rustic:ironwoodbranch:1)
Block(0,12,4,rustic:leaves0:7)
Block(0,12,5,rustic:leaves0:6)
Block(0,12,6,rustic:leaves0:4)
Block(0,13,-1,rustic:leaves0:4)
Block(0,13,0,rustic:leaves0:6)
Block(0,13,1,rustic:leaves0:7)
Block(0,13,2,rustic:leaves0:6)
Block(0,13,3,rustic:leaves0:7)
Block(0,13,4,rustic:leaves0:6)
Block(0,13,5,rustic:leaves0:5)
Block(0,13,6,rustic:leaves0:4)
Block(0,14,-1,rustic:leaves0:4)
Block(0,14,0,rustic:leaves0:5)
Block(0,14,1,rustic:leaves0:6)
Block(0,14,2,rustic:leaves0:7)
Block(0,14,3,rustic:leaves0:6)
Block(0,14,4,rustic:leaves0:5)
Block(0,14,5,rustic:leaves0:4)
Block(0,15,0,rustic:leaves0:4)
Block(0,15,1,rustic:leaves0:5)
Block(0,15,2,rustic:leaves0:6)
Block(0,15,3,rustic:leaves0:5)
Block(0,15,4,rustic:leaves0:4)
Block(0,16,1,rustic:leaves0:4)
Block(0,16,2,rustic:leaves0:4)
Block(0,16,3,rustic:leaves0:4)
Block(1,0,1,GRASS:0)
Block(1,0,2,GRASS:0)
Block(1,0,3,GRASS:0)
Block(1,0,5,rustic:ironwoodroot:1)
Block(1,1,1,DIRT:2)
Block(1,1,2,dynamictrees:rootydirt:0)
Block(1,1,3,DIRT:2)
Block(1,2,1,rustic:ironwoodroot:6)
Block(1,2,2,rustic:ironwoodbranchx:1)
Block(1,2,3,rustic:ironwoodroot:6)
Block(1,3,1,dynamictrees:trunkshell)
Block(1,3,2,rustic:ironwoodbranchx)
Block(1,3,3,dynamictrees:trunkshell:0)
Block(1,4,1,dynamictrees:trunkshell)
Block(1,4,2,rustic:ironwoodbranch:15)
Block(1,4,3,dynamictrees:trunkshell:0)
Block(1,4,6,rustic:ironwoodbranch)
Block(1,4,7,rustic:leaves0:7)
Block(1,4,8,rustic:leaves0:4)
Block(1,5,-5,rustic:leaves0:4)
Block(1,5,-4,rustic:leaves0:7)
Block(1,5,-3,rustic:ironwoodbranch)
Block(1,5,-2,rustic:ironwoodbranch:1)
Block(1,5,-1,rustic:ironwoodbranch:2)
Block(1,5,0,rustic:ironwoodbranch:6)
Block(1,5,1,rustic:ironwoodbranch:7)
Block(1,5,2,rustic:ironwoodbranch:15)
Block(1,5,3,rustic:ironwoodbranch:6)
Block(1,5,4,rustic:ironwoodbranch:4)
Block(1,5,5,rustic:ironwoodbranch:4)
Block(1,5,6,rustic:ironwoodbranch:2)
Block(1,5,7,rustic:leaves0:4)
Block(1,6,-5,rustic:leaves0:4)
Block(1,6,-4,rustic:leaves0:6)
Block(1,6,-3,rustic:leaves0:7)
Block(1,6,-2,rustic:ironwoodbranch)
Block(1,6,0,rustic:ironwoodbranch:4)
Block(1,6,1,dynamictrees:trunkshell)
Block(1,6,2,rustic:ironwoodbranch:8)
Block(1,6,3,dynamictrees:trunkshell:0)
Block(1,6,6,rustic:ironwoodbranch:1)
Block(1,6,7,rustic:leaves0:4)
Block(1,7,-5,rustic:leaves0:4)
Block(1,7,-4,rustic:leaves0:5)
Block(1,7,-3,rustic:leaves0:6)
Block(1,7,-2,rustic:leaves0:7)
Block(1,7,-1,rustic:ironwoodbranch:3)
Block(1,7,0,rustic:ironwoodbranch:4)
Block(1,7,2,rustic:ironwoodbranch:7)
Block(1,7,3,rustic:ironwoodbranch:2)
Block(1,7,4,rustic:ironwoodbranch:1)
Block(1,7,5,rustic:ironwoodbranch)
Block(1,7,6,rustic:leaves0:7)
Block(1,7,7,rustic:leaves0:4)
Block(1,8,-4,rustic:leaves0:4)
Block(1,8,-3,rustic:leaves0:4)
Block(1,8,-2,rustic:leaves0:4)
Block(1,8,-1,rustic:ironwoodbranch:2)
Block(1,8,2,rustic:ironwoodbranch:6)
Block(1,8,4,rustic:ironwoodbranch)
Block(1,8,5,rustic:leaves0:7)
Block(1,8,6,rustic:leaves0:6)
Block(1,8,7,rustic:leaves0:4)
Block(1,9,-1,rustic:ironwoodbranch:1)
Block(1,9,2,rustic:ironwoodbranch:6)
Block(1,9,4,rustic:leaves0:7)
Block(1,9,5,rustic:leaves0:6)
Block(1,9,6,rustic:leaves0:5)
Block(1,9,7,rustic:leaves0:4)
Block(1,10,-2,rustic:leaves0:4)
Block(1,10,2,rustic:ironwoodbranch:5)
Block(1,10,3,rustic:ironwoodbranch:2)
Block(1,10,4,rustic:ironwoodbranch:1)
Block(1,10,5,rustic:leaves0:5)
Block(1,10,6,rustic:leaves0:4)
Block(1,11,-2,rustic:leaves0:4)
Block(1,11,-1,rustic:leaves0:4)
Block(1,11,1,rustic:ironwoodbranch:1)
Block(1,11,2,rustic:ironwoodbranch:4)
Block(1,11,4,rustic:ironwoodbranch:1)
Block(1,11,5,rustic:leaves0:4)
Block(1,12,2,rustic:ironwoodbranch:3)
Block(1,12,4,rustic:ironwoodbranch)
Block(1,12,5,rustic:leaves0:7)
Block(1,12,6,rustic:leaves0:4)
Block(1,13,-1,rustic:leaves0:4)
Block(1,13,0,rustic:leaves0:7)
Block(1,13,1,rustic:ironwoodbranch)
Block(1,13,2,rustic:ironwoodbranch:2)
Block(1,13,3,rustic:ironwoodbranch)
Block(1,13,4,rustic:leaves0:7)
Block(1,13,5,rustic:leaves0:6)
Block(1,13,6,rustic:leaves0:4)
Block(1,14,-1,rustic:leaves0:4)
Block(1,14,0,rustic:leaves0:6)
Block(1,14,1,rustic:leaves0:7)
Block(1,14,2,rustic:ironwoodbranch)
Block(1,14,3,rustic:leaves0:7)
Block(1,14,4,rustic:leaves0:6)
Block(1,14,5,rustic:leaves0:5)
Block(1,14,6,rustic:leaves0:4)
Block(1,15,-1,rustic:leaves0:4)
Block(1,15,0,rustic:leaves0:5)
Block(1,15,1,rustic:leaves0:6)
Block(1,15,2,rustic:leaves0:7)
Block(1,15,3,rustic:leaves0:6)
Block(1,15,4,rustic:leaves0:5)
Block(1,15,5,rustic:leaves0:4)
Block(1,16,0,rustic:leaves0:4)
Block(1,16,1,rustic:leaves0:4)
Block(1,16,2,rustic:leaves0:4)
Block(1,16,3,rustic:leaves0:4)
Block(1,16,4,rustic:leaves0:4)
Block(2,0,1,GRASS:0)
Block(2,0,2,GRASS:0)
Block(2,0,3,GRASS:0)
Block(2,0,4,GRASS:0)
Block(2,0,5,rustic:ironwoodroot:3)
Block(2,1,1,DIRT:2)
Block(2,1,2,DIRT:2)
Block(2,1,3,DIRT:2)
Block(2,1,4,rustic:ironwoodroot:4)
Block(2,2,1,dynamictrees:trunkshell:3)
Block(2,2,2,dynamictrees:trunkshell:2)
Block(2,2,3,rustic:ironwoodroot:5)
Block(2,3,1,dynamictrees:trunkshell:3)
Block(2,3,2,dynamictrees:trunkshell:2)
Block(2,3,3,dynamictrees:trunkshell:1)
Block(2,4,-4,rustic:leaves0:4)
Block(2,4,1,dynamictrees:trunkshell:3)
Block(2,4,2,dynamictrees:trunkshell:2)
Block(2,4,3,dynamictrees:trunkshell:1)
Block(2,4,7,rustic:leaves0:4)
Block(2,5,-5,rustic:leaves0:4)
Block(2,5,-4,rustic:leaves0:6)
Block(2,5,-3,rustic:leaves0:7)
Block(2,5,-2,rustic:ironwoodbranch)
Block(2,5,1,dynamictrees:trunkshell:3)
Block(2,5,2,rustic:ironwoodbranch:6)
Block(2,5,3,dynamictrees:trunkshell:1)
Block(2,5,5,rustic:ironwoodbranch:2)
Block(2,5,7,rustic:leaves0:4)
Block(2,6,-5,rustic:leaves0:4)
Block(2,6,-4,rustic:leaves0:5)
Block(2,6,-3,rustic:leaves0:6)
Block(2,6,-2,rustic:leaves0:7)
Block(2,6,1,dynamictrees:trunkshell:3)
Block(2,6,2,dynamictrees:trunkshell:2)
Block(2,6,3,dynamictrees:trunkshell:1)
Block(2,6,5,rustic:ironwoodbranch)
Block(2,6,6,rustic:leaves0:7)
Block(2,6,7,rustic:leaves0:4)
Block(2,7,-4,rustic:leaves0:4)
Block(2,7,-3,rustic:leaves0:5)
Block(2,7,-2,rustic:leaves0:6)
Block(2,7,-1,rustic:ironwoodbranch:1)
Block(2,7,5,rustic:leaves0:7)
Block(2,7,6,rustic:leaves0:6)
Block(2,7,7,rustic:leaves0:4)
Block(2,8,-3,rustic:leaves0:4)
Block(2,8,-2,rustic:leaves0:4)
Block(2,8,5,rustic:leaves0:6)
Block(2,8,6,rustic:leaves0:5)
Block(2,8,7,rustic:leaves0:4)
Block(2,9,-2,rustic:leaves0:4)
Block(2,9,-1,rustic:ironwoodbranch:1)
Block(2,9,1,rustic:ironwoodbranch)
Block(2,9,2,rustic:ironwoodbranch:2)
Block(2,9,3,rustic:ironwoodbranch:1)
Block(2,9,4,rustic:ironwoodbranch)
Block(2,9,5,rustic:leaves0:7)
Block(2,9,6,rustic:leaves0:4)
Block(2,10,-3,rustic:leaves0:4)
Block(2,10,-2,rustic:leaves0:7)
Block(2,10,-1,rustic:ironwoodbranch)
Block(2,10,1,rustic:leaves0:7)
Block(2,10,4,rustic:leaves0:7)
Block(2,10,5,rustic:leaves0:6)
Block(2,10,6,rustic:leaves0:4)
Block(2,11,-3,rustic:leaves0:4)
Block(2,11,-2,rustic:leaves0:6)
Block(2,11,-1,rustic:leaves0:7)
Block(2,11,1,rustic:ironwoodbranch)
Block(2,11,4,rustic:leaves0:6)
Block(2,11,5,rustic:leaves0:5)
Block(2,11,6,rustic:leaves0:4)
Block(2,12,-2,rustic:leaves0:4)
Block(2,12,-1,rustic:leaves0:4)
Block(2,12,0,rustic:leaves0:4)
Block(2,12,1,rustic:leaves0:7)
Block(2,12,4,rustic:leaves0:7)
Block(2,12,5,rustic:leaves0:6)
Block(2,12,6,rustic:leaves0:4)
Block(2,13,-1,rustic:leaves0:4)
Block(2,13,0,rustic:leaves0:6)
Block(2,13,1,rustic:leaves0:7)
Block(2,13,2,rustic:ironwoodbranch)
Block(2,13,3,rustic:leaves0:7)
Block(2,13,4,rustic:leaves0:6)
Block(2,13,5,rustic:leaves0:5)
Block(2,13,6,rustic:leaves0:4)
Block(2,14,-1,rustic:leaves0:4)
Block(2,14,0,rustic:leaves0:5)
Block(2,14,1,rustic:leaves0:6)
Block(2,14,2,rustic:leaves0:7)
Block(2,14,3,rustic:leaves0:6)
Block(2,14,4,rustic:leaves0:5)
Block(2,14,5,rustic:leaves0:4)
Block(2,15,0,rustic:leaves0:4)
Block(2,15,1,rustic:leaves0:5)
Block(2,15,2,rustic:leaves0:6)
Block(2,15,3,rustic:leaves0:5)
Block(2,15,4,rustic:leaves0:4)
Block(2,16,1,rustic:leaves0:4)
Block(2,16,2,rustic:leaves0:4)
Block(2,16,3,rustic:leaves0:4)
Block(3,0,5,rustic:ironwoodroot)
Block(3,4,7,rustic:leaves0:4)
Block(3,5,-4,rustic:leaves0:4)
Block(3,5,-3,rustic:leaves0:4)
Block(3,5,2,rustic:ironwoodbranch:6)
Block(3,5,5,rustic:ironwoodbranch:2)
Block(3,5,6,rustic:ironwoodbranch)
Block(3,5,7,rustic:leaves0:7)
Block(3,5,8,rustic:leaves0:4)
Block(3,6,-4,rustic:leaves0:4)
Block(3,6,-3,rustic:leaves0:4)
Block(3,6,6,rustic:leaves0:7)
Block(3,6,7,rustic:leaves0:6)
Block(3,6,8,rustic:leaves0:4)
Block(3,7,-3,rustic:leaves0:4)
Block(3,7,-2,rustic:leaves0:4)
Block(3,7,-1,rustic:ironwoodbranch:1)
Block(3,7,6,rustic:leaves0:5)
Block(3,7,7,rustic:leaves0:4)
Block(3,8,-3,rustic:leaves0:4)
Block(3,8,-2,rustic:leaves0:7)
Block(3,8,-1,rustic:ironwoodbranch)
Block(3,8,6,rustic:leaves0:4)
Block(3,9,-3,rustic:leaves0:4)
Block(3,9,-2,rustic:leaves0:6)
Block(3,9,-1,rustic:leaves0:7)
Block(3,9,5,rustic:leaves0:4)
Block(3,10,-3,rustic:leaves0:4)
Block(3,10,-2,rustic:leaves0:6)
Block(3,10,-1,rustic:leaves0:7)
Block(3,10,4,rustic:leaves0:6)
Block(3,10,5,rustic:leaves0:5)
Block(3,10,6,rustic:leaves0:4)
Block(3,11,-3,rustic:leaves0:4)
Block(3,11,-2,rustic:leaves0:5)
Block(3,11,-1,rustic:leaves0:6)
Block(3,11,0,rustic:leaves0:4)
Block(3,11,4,rustic:leaves0:5)
Block(3,11,5,rustic:leaves0:4)
Block(3,12,-2,rustic:leaves0:4)
Block(3,12,-1,rustic:leaves0:4)
Block(3,12,0,rustic:leaves0:4)
Block(3,12,1,rustic:leaves0:4)
Block(3,12,3,rustic:leaves0:4)
Block(3,12,4,rustic:leaves0:4)
Block(3,12,5,rustic:leaves0:4)
Block(3,13,-1,rustic:leaves0:4)
Block(3,13,0,rustic:leaves0:5)
Block(3,13,1,rustic:leaves0:6)
Block(3,13,2,rustic:leaves0:7)
Block(3,13,3,rustic:leaves0:6)
Block(3,13,4,rustic:leaves0:5)
Block(3,13,5,rustic:leaves0:4)
Block(3,14,0,rustic:leaves0:4)
Block(3,14,1,rustic:leaves0:5)
Block(3,14,2,rustic:leaves0:6)
Block(3,14,3,rustic:leaves0:5)
Block(3,14,4,rustic:leaves0:4)
Block(3,15,1,rustic:leaves0:4)
Block(3,15,2,rustic:leaves0:5)
Block(3,15,3,rustic:leaves0:4)
Block(3,16,2,rustic:leaves0:4)
Block(4,5,1,rustic:ironwoodbranch:3)
Block(4,5,2,rustic:ironwoodbranch:5)
Block(4,5,5,rustic:ironwoodbranch:1)
Block(4,5,7,rustic:leaves0:4)
Block(4,6,-1,rustic:ironwoodbranch)
Block(4,6,0,rustic:ironwoodbranch:2)
Block(4,6,1,rustic:ironwoodbranch:3)
Block(4,6,5,rustic:ironwoodbranch)
Block(4,6,6,rustic:leaves0:7)
Block(4,6,7,rustic:leaves0:4)
Block(4,7,-1,rustic:leaves0:7)
Block(4,7,1,rustic:ironwoodbranch:1)
Block(4,7,5,rustic:leaves0:7)
Block(4,7,6,rustic:leaves0:6)
Block(4,7,7,rustic:leaves0:4)
Block(4,8,-3,rustic:leaves0:4)
Block(4,8,-2,rustic:leaves0:6)
Block(4,8,-1,rustic:leaves0:7)
Block(4,8,0,rustic:leaves0:7)
Block(4,8,1,rustic:ironwoodbranch)
Block(4,8,2,rustic:leaves0:7)
Block(4,8,3,rustic:ironwoodbranch)
Block(4,8,4,rustic:leaves0:7)
Block(4,8,5,rustic:leaves0:6)
Block(4,8,6,rustic:leaves0:5)
Block(4,8,7,rustic:leaves0:4)
Block(4,9,-3,rustic:leaves0:4)
Block(4,9,-2,rustic:leaves0:4)
Block(4,9,-1,rustic:leaves0:6)
Block(4,9,0,rustic:leaves0:6)
Block(4,9,1,rustic:leaves0:7)
Block(4,9,2,rustic:leaves0:6)
Block(4,9,3,rustic:leaves0:7)
Block(4,9,4,rustic:leaves0:6)
Block(4,9,5,rustic:leaves0:5)
Block(4,9,6,rustic:leaves0:4)
Block(4,10,-2,rustic:leaves0:4)
Block(4,10,-1,rustic:leaves0:4)
Block(4,10,0,rustic:leaves0:4)
Block(4,10,1,rustic:leaves0:4)
Block(4,10,2,rustic:leaves0:4)
Block(4,10,3,rustic:leaves0:4)
Block(4,10,4,rustic:leaves0:5)
Block(4,10,5,rustic:leaves0:4)
Block(4,11,-2,rustic:leaves0:4)
Block(4,11,-1,rustic:leaves0:4)
Block(4,11,4,rustic:leaves0:4)
Block(4,13,0,rustic:leaves0:4)
Block(4,13,1,rustic:leaves0:4)
Block(4,13,2,rustic:leaves0:4)
Block(4,13,3,rustic:leaves0:4)
Block(4,13,4,rustic:leaves0:4)
Block(4,14,1,rustic:leaves0:4)
Block(4,14,2,rustic:leaves0:4)
Block(4,14,3,rustic:leaves0:4)
Block(4,15,2,rustic:leaves0:4)
Block(5,5,2,rustic:ironwoodbranch:3)
Block(5,5,5,rustic:ironwoodbranch)
Block(5,5,6,rustic:leaves0:7)
Block(5,5,7,rustic:leaves0:4)
Block(5,6,0,rustic:ironwoodbranch:1)
Block(5,6,2,rustic:ironwoodbranch:3)
Block(5,6,3,rustic:ironwoodbranch)
Block(5,6,5,rustic:leaves0:7)
Block(5,6,6,rustic:leaves0:6)
Block(5,6,7,rustic:leaves0:4)
Block(5,7,-2,rustic:leaves0:4)
Block(5,7,-1,rustic:leaves0:7)
Block(5,7,0,rustic:ironwoodbranch)
Block(5,7,1,rustic:leaves0:7)
Block(5,7,2,rustic:ironwoodbranch:2)
Block(5,7,3,rustic:leaves0:7)
Block(5,7,4,rustic:leaves0:6)
Block(5,7,5,rustic:leaves0:6)
Block(5,7,6,rustic:leaves0:5)
Block(5,7,7,rustic:leaves0:4)
Block(5,8,-2,rustic:leaves0:4)
Block(5,8,-1,rustic:leaves0:6)
Block(5,8,0,rustic:leaves0:7)
Block(5,8,1,rustic:leaves0:7)
Block(5,8,2,rustic:ironwoodbranch:1)
Block(5,8,3,rustic:ironwoodbranch:1)
Block(5,8,4,rustic:leaves0:5)
Block(5,8,5,rustic:leaves0:5)
Block(5,8,6,rustic:leaves0:4)
Block(5,9,-2,rustic:leaves0:4)
Block(5,9,-1,rustic:leaves0:5)
Block(5,9,0,rustic:leaves0:5)
Block(5,9,1,rustic:leaves0:6)
Block(5,9,2,rustic:leaves0:5)
Block(5,9,3,rustic:leaves0:4)
Block(5,9,4,rustic:leaves0:4)
Block(5,9,5,rustic:leaves0:4)
Block(5,10,-1,rustic:leaves0:4)
Block(5,10,0,rustic:leaves0:4)
Block(5,10,1,rustic:leaves0:4)
Block(5,10,2,rustic:leaves0:4)
Block(5,10,4,rustic:leaves0:4)
Block(6,4,6,rustic:leaves0:4)
Block(6,5,2,rustic:ironwoodbranch)
Block(6,5,5,rustic:leaves0:7)
Block(6,5,6,rustic:leaves0:6)
Block(6,5,7,rustic:leaves0:4)
Block(6,6,-1,rustic:leaves0:4)
Block(6,6,0,rustic:leaves0:4)
Block(6,6,1,rustic:leaves0:4)
Block(6,6,2,rustic:leaves0:7)
Block(6,6,5,rustic:leaves0:6)
Block(6,6,6,rustic:leaves0:5)
Block(6,6,7,rustic:leaves0:4)
Block(6,7,-2,rustic:leaves0:4)
Block(6,7,-1,rustic:leaves0:6)
Block(6,7,0,rustic:leaves0:7)
Block(6,7,1,rustic:leaves0:6)
Block(6,7,2,rustic:ironwoodbranch:1)
Block(6,7,3,rustic:ironwoodbranch)
Block(6,7,4,rustic:leaves0:7)
Block(6,7,5,rustic:leaves0:5)
Block(6,7,6,rustic:leaves0:4)
Block(6,8,-2,rustic:leaves0:4)
Block(6,8,-1,rustic:leaves0:5)
Block(6,8,0,rustic:leaves0:6)
Block(6,8,1,rustic:leaves0:5)
Block(6,8,2,rustic:leaves0:4)
Block(6,8,3,rustic:leaves0:7)
Block(6,8,4,rustic:leaves0:6)
Block(6,8,5,rustic:leaves0:4)
Block(6,9,-1,rustic:leaves0:4)
Block(6,9,0,rustic:leaves0:4)
Block(6,9,1,rustic:leaves0:4)
Block(6,9,2,rustic:leaves0:4)
Block(6,9,3,rustic:leaves0:4)
Block(6,9,4,rustic:leaves0:4)
Block(7,5,1,rustic:leaves0:4)
Block(7,5,2,rustic:leaves0:7)
Block(7,5,5,rustic:leaves0:4)
Block(7,5,6,rustic:leaves0:4)
Block(7,6,1,rustic:leaves0:4)
Block(7,6,2,rustic:leaves0:6)
Block(7,6,3,rustic:leaves0:4)
Block(7,6,4,rustic:leaves0:4)
Block(7,6,5,rustic:leaves0:4)
Block(7,6,6,rustic:leaves0:4)
Block(7,7,-1,rustic:leaves0:4)
Block(7,7,0,rustic:leaves0:4)
Block(7,7,1,rustic:leaves0:4)
Block(7,7,2,rustic:leaves0:4)
Block(7,7,3,rustic:leaves0:7)
Block(7,7,4,rustic:leaves0:6)
Block(7,7,5,rustic:leaves0:4)
Block(7,8,-1,rustic:leaves0:4)
Block(7,8,0,rustic:leaves0:4)
Block(7,8,1,rustic:leaves0:4)
Block(7,8,2,rustic:leaves0:4)
Block(7,8,3,rustic:leaves0:6)
Block(7,8,4,rustic:leaves0:5)
Block(7,8,5,rustic:leaves0:4)
Block(7,9,3,rustic:leaves0:4)
Block(7,9,4,rustic:leaves0:4)
Block(8,5,2,rustic:leaves0:4)
Block(8,6,2,rustic:leaves0:4)
Block(8,7,3,rustic:leaves0:4)
Block(8,7,4,rustic:leaves0:4)
Block(8,8,3,rustic:leaves0:4)
Block(8,8,4,rustic:leaves0:4)

#######################################################################
# +-----------------------------------------------------------------+ #
# |                            BO3 checks                           | #
# +-----------------------------------------------------------------+ #
#######################################################################

BlockCheck(1,-1,2,GRASS,DIRT,MYCEL,biomesoplenty:grass,biomesoplenty:dirt)

#######################################################################
# +-----------------------------------------------------------------+ #
# |                             Branches                            | #
# +-----------------------------------------------------------------+ #
#######################################################################


#######################################################################
# +-----------------------------------------------------------------+ #
# |                             Entities                            | #
# +-----------------------------------------------------------------+ #
#######################################################################


#######################################################################
# +-----------------------------------------------------------------+ #
# |                            Particles                            | #
# +-----------------------------------------------------------------+ #
#######################################################################


#######################################################################
# +-----------------------------------------------------------------+ #
# |                             Spawners                            | #
# +-----------------------------------------------------------------+ #
#######################################################################


#######################################################################
# +-----------------------------------------------------------------+ #
# |                             ModData                             | #
# +-----------------------------------------------------------------+ #
#######################################################################

