
#######################################################################
# +-----------------------------------------------------------------+ #
# |                            BO3 object                           | #
# +-----------------------------------------------------------------+ #
#######################################################################

Author: NLBlackHeavenNL

Description: No description given

Version: 3

SettingsMode: WriteWithoutComments


#######################################################################
# +-----------------------------------------------------------------+ #
# |                          Main settings                          | #
# +-----------------------------------------------------------------+ #
#######################################################################

Tree: true

Frequency: 1

Rarity: 100.0

RotateRandomly: false

SpawnHeight: highestSolidBlock

SpawnHeightOffset: -1

SpawnHeightVariance: 0

##############################
# Height Limits for the BO3. #
##############################

MinHeight: 0

MaxHeight: 255

######################
# Extrusion settings #
######################

ExtrudeMode: None

ExtrudeThroughBlocks: AIR

MaxBranchDepth: 10

ExcludedBiomes: All


#######################################################################
# +-----------------------------------------------------------------+ #
# |                      Source block settings                      | #
# +-----------------------------------------------------------------+ #
#######################################################################

SourceBlocks: AIR,GRASS,DIRT,biomesoplenty:dirt,MYCEL

MaxPercentageOutsideSourceBlock: 0

OutsideSourceBlock: placeAnyway

DoReplaceBlocks: true

IsOTGPlus: false


#######################################################################
# +-----------------------------------------------------------------+ #
# |                              Blocks                             | #
# +-----------------------------------------------------------------+ #
#######################################################################

Block(-5,9,1,rustic:leaves0:4)
Block(-5,10,1,rustic:leaves0:4)
Block(-5,11,1,rustic:leaves0:4)
Block(-4,8,1,rustic:leaves0:4)
Block(-4,9,0,rustic:leaves0:4)
Block(-4,9,1,rustic:leaves0:7)
Block(-4,9,2,rustic:leaves0:4)
Block(-4,10,0,rustic:leaves0:4)
Block(-4,10,1,rustic:leaves0:6)
Block(-4,10,2,rustic:leaves0:4)
Block(-4,11,0,rustic:leaves0:4)
Block(-4,11,1,rustic:leaves0:5)
Block(-4,11,2,rustic:leaves0:4)
Block(-4,12,1,rustic:leaves0:4)
Block(-3,8,1,rustic:ironwoodbranch:1)
Block(-3,9,-2,rustic:leaves0:4)
Block(-3,9,1,rustic:ironwoodbranch)
Block(-3,10,-1,rustic:leaves0:4)
Block(-3,10,0,rustic:leaves0:4)
Block(-3,10,1,rustic:leaves0:7)
Block(-3,10,2,rustic:leaves0:4)
Block(-3,11,-2,rustic:leaves0:4)
Block(-3,11,-1,rustic:leaves0:4)
Block(-3,11,0,rustic:leaves0:4)
Block(-3,11,1,rustic:leaves0:6)
Block(-3,11,2,rustic:leaves0:5)
Block(-3,11,3,rustic:leaves0:4)
Block(-3,12,-1,rustic:leaves0:4)
Block(-3,12,0,rustic:leaves0:4)
Block(-3,12,1,rustic:leaves0:4)
Block(-3,12,2,rustic:leaves0:4)
Block(-3,12,3,rustic:leaves0:4)
Block(-3,13,0,rustic:leaves0:4)
Block(-3,13,1,rustic:leaves0:4)
Block(-3,13,2,rustic:leaves0:4)
Block(-2,0,-1,rustic:ironwoodroot:1)
Block(-2,0,1,rustic:ironwoodroot:3)
Block(-2,0,3,rustic:ironwoodroot)
Block(-2,8,-1,rustic:leaves0:7)
Block(-2,8,0,rustic:ironwoodbranch)
Block(-2,8,1,rustic:ironwoodbranch:1)
Block(-2,10,-2,rustic:leaves0:4)
Block(-2,10,-1,rustic:leaves0:5)
Block(-2,10,1,rustic:ironwoodbranch)
Block(-2,10,3,rustic:leaves0:4)
Block(-2,10,4,rustic:leaves0:4)
Block(-2,11,-3,rustic:leaves0:4)
Block(-2,11,-2,rustic:leaves0:5)
Block(-2,11,-1,rustic:leaves0:6)
Block(-2,11,0,rustic:leaves0:7)
Block(-2,11,1,rustic:leaves0:7)
Block(-2,11,2,rustic:leaves0:6)
Block(-2,11,3,rustic:leaves0:4)
Block(-2,11,4,rustic:leaves0:4)
Block(-2,12,-2,rustic:leaves0:4)
Block(-2,12,-1,rustic:leaves0:5)
Block(-2,12,0,rustic:leaves0:6)
Block(-2,12,1,rustic:leaves0:7)
Block(-2,12,2,rustic:leaves0:6)
Block(-2,12,3,rustic:leaves0:5)
Block(-2,12,4,rustic:leaves0:4)
Block(-2,13,-1,rustic:leaves0:4)
Block(-2,13,0,rustic:leaves0:5)
Block(-2,13,1,rustic:leaves0:6)
Block(-2,13,2,rustic:leaves0:5)
Block(-2,13,3,rustic:leaves0:4)
Block(-2,14,0,rustic:leaves0:4)
Block(-2,14,1,rustic:leaves0:4)
Block(-2,14,2,rustic:leaves0:4)
Block(-1,0,-1,rustic:ironwoodroot:2)
Block(-1,0,0,GRASS:0)
Block(-1,0,1,GRASS:0)
Block(-1,0,2,GRASS:0)
Block(-1,0,3,rustic:ironwoodroot:1)
Block(-1,1,0,dynamictrees:trunkshell:5)
Block(-1,1,1,rustic:ironwoodroot:4)
Block(-1,1,2,dynamictrees:trunkshell:7)
Block(-1,2,0,dynamictrees:trunkshell:5)
Block(-1,2,1,dynamictrees:trunkshell:6)
Block(-1,2,2,dynamictrees:trunkshell:7)
Block(-1,3,0,dynamictrees:trunkshell:5)
Block(-1,3,1,dynamictrees:trunkshell:6)
Block(-1,3,2,dynamictrees:trunkshell:7)
Block(-1,4,0,dynamictrees:trunkshell:5)
Block(-1,4,1,dynamictrees:trunkshell:6)
Block(-1,4,2,dynamictrees:trunkshell:7)
Block(-1,5,0,dynamictrees:trunkshell:5)
Block(-1,5,1,dynamictrees:trunkshell:6)
Block(-1,5,2,dynamictrees:trunkshell:7)
Block(-1,6,0,dynamictrees:trunkshell:5)
Block(-1,6,1,dynamictrees:trunkshell:6)
Block(-1,6,2,dynamictrees:trunkshell:7)
Block(-1,8,1,rustic:ironwoodbranch:3)
Block(-1,9,0,rustic:ironwoodbranch)
Block(-1,9,1,rustic:ironwoodbranch:2)
Block(-1,10,-3,rustic:leaves0:4)
Block(-1,10,-2,rustic:leaves0:5)
Block(-1,10,-1,rustic:leaves0:6)
Block(-1,10,0,rustic:leaves0:7)
Block(-1,10,1,rustic:ironwoodbranch:2)
Block(-1,10,2,rustic:ironwoodbranch)
Block(-1,10,4,rustic:leaves0:5)
Block(-1,10,5,rustic:leaves0:4)
Block(-1,11,-3,rustic:leaves0:4)
Block(-1,11,-2,rustic:leaves0:6)
Block(-1,11,-1,rustic:leaves0:7)
Block(-1,11,0,rustic:ironwoodbranch)
Block(-1,11,1,rustic:ironwoodbranch:1)
Block(-1,11,2,rustic:leaves0:7)
Block(-1,11,3,rustic:leaves0:7)
Block(-1,11,4,rustic:leaves0:6)
Block(-1,11,5,rustic:leaves0:4)
Block(-1,12,-3,rustic:leaves0:4)
Block(-1,12,-2,rustic:leaves0:5)
Block(-1,12,-1,rustic:leaves0:6)
Block(-1,12,0,rustic:leaves0:7)
Block(-1,12,1,rustic:ironwoodbranch)
Block(-1,12,2,rustic:leaves0:7)
Block(-1,12,3,rustic:leaves0:6)
Block(-1,12,4,rustic:leaves0:5)
Block(-1,12,5,rustic:leaves0:4)
Block(-1,13,-2,rustic:leaves0:4)
Block(-1,13,-1,rustic:leaves0:5)
Block(-1,13,0,rustic:leaves0:6)
Block(-1,13,1,rustic:leaves0:7)
Block(-1,13,2,rustic:leaves0:6)
Block(-1,13,3,rustic:leaves0:5)
Block(-1,13,4,rustic:leaves0:4)
Block(-1,14,-1,rustic:leaves0:4)
Block(-1,14,0,rustic:leaves0:4)
Block(-1,14,1,rustic:leaves0:4)
Block(-1,14,2,rustic:leaves0:4)
Block(-1,14,3,rustic:leaves0:4)
Block(0,0,-1,rustic:ironwoodroot:3)
Block(0,0,0,GRASS:0)
Block(0,0,1,dynamictrees:rootydirt:0)
Block(0,0,2,GRASS:0)
Block(0,0,3,rustic:ironwoodroot:2)
Block(0,1,0,rustic:ironwoodroot:4)
Block(0,1,1,rustic:ironwoodbranch:13)
Block(0,1,2,rustic:ironwoodroot:3)
Block(0,2,0,dynamictrees:trunkshell)
Block(0,2,1,rustic:ironwoodbranch:12)
Block(0,2,2,dynamictrees:trunkshell:0)
Block(0,3,0,dynamictrees:trunkshell)
Block(0,3,1,rustic:ironwoodbranch:11)
Block(0,3,2,dynamictrees:trunkshell:0)
Block(0,4,0,dynamictrees:trunkshell)
Block(0,4,1,rustic:ironwoodbranch:11)
Block(0,4,2,dynamictrees:trunkshell:0)
Block(0,5,-1,rustic:ironwoodbranch:4)
Block(0,5,0,rustic:ironwoodbranch:5)
Block(0,5,1,rustic:ironwoodbranch:10)
Block(0,5,2,dynamictrees:trunkshell:0)
Block(0,6,-1,rustic:ironwoodbranch:4)
Block(0,6,0,dynamictrees:trunkshell)
Block(0,6,1,rustic:ironwoodbranch:8)
Block(0,6,2,rustic:ironwoodbranch:4)
Block(0,6,3,rustic:ironwoodbranch:4)
Block(0,7,-1,rustic:ironwoodbranch:3)
Block(0,7,1,rustic:ironwoodbranch:6)
Block(0,7,3,rustic:ironwoodbranch:3)
Block(0,8,-1,rustic:ironwoodbranch:3)
Block(0,8,1,rustic:ironwoodbranch:5)
Block(0,8,3,rustic:ironwoodbranch:3)
Block(0,9,-3,rustic:leaves0:4)
Block(0,9,-2,rustic:ironwoodbranch:1)
Block(0,9,-1,rustic:ironwoodbranch:2)
Block(0,9,3,rustic:ironwoodbranch:2)
Block(0,9,4,rustic:ironwoodbranch:1)
Block(0,9,5,rustic:leaves0:4)
Block(0,10,-4,rustic:leaves0:4)
Block(0,10,-3,rustic:leaves0:5)
Block(0,10,-2,rustic:leaves0:6)
Block(0,10,-1,rustic:ironwoodbranch:1)
Block(0,10,3,rustic:ironwoodbranch:1)
Block(0,10,4,rustic:leaves0:6)
Block(0,10,5,rustic:leaves0:5)
Block(0,10,6,rustic:leaves0:4)
Block(0,11,-3,rustic:leaves0:4)
Block(0,11,-2,rustic:leaves0:7)
Block(0,11,-1,rustic:ironwoodbranch)
Block(0,11,0,rustic:leaves0:7)
Block(0,11,1,rustic:leaves0:6)
Block(0,11,2,rustic:leaves0:7)
Block(0,11,3,rustic:ironwoodbranch)
Block(0,11,4,rustic:leaves0:7)
Block(0,11,5,rustic:leaves0:4)
Block(0,12,-3,rustic:leaves0:4)
Block(0,12,-2,rustic:leaves0:6)
Block(0,12,-1,rustic:leaves0:7)
Block(0,12,0,rustic:leaves0:6)
Block(0,12,1,rustic:leaves0:7)
Block(0,12,2,rustic:leaves0:6)
Block(0,12,3,rustic:leaves0:7)
Block(0,12,4,rustic:leaves0:6)
Block(0,12,5,rustic:leaves0:4)
Block(0,13,-2,rustic:leaves0:4)
Block(0,13,-1,rustic:leaves0:4)
Block(0,13,0,rustic:leaves0:5)
Block(0,13,1,rustic:leaves0:6)
Block(0,13,2,rustic:leaves0:5)
Block(0,13,3,rustic:leaves0:4)
Block(0,13,4,rustic:leaves0:4)
Block(0,14,0,rustic:leaves0:4)
Block(0,14,1,rustic:leaves0:4)
Block(0,14,2,rustic:leaves0:4)
Block(1,0,0,GRASS:0)
Block(1,0,1,GRASS:0)
Block(1,0,2,GRASS:0)
Block(1,0,3,rustic:ironwoodroot:1)
Block(1,0,4,rustic:ironwoodroot)
Block(1,1,0,dynamictrees:trunkshell:3)
Block(1,1,1,rustic:ironwoodroot:4)
Block(1,1,2,dynamictrees:trunkshell:1)
Block(1,2,0,dynamictrees:trunkshell:3)
Block(1,2,1,dynamictrees:trunkshell:2)
Block(1,2,2,dynamictrees:trunkshell:1)
Block(1,3,0,dynamictrees:trunkshell:3)
Block(1,3,1,dynamictrees:trunkshell:2)
Block(1,3,2,dynamictrees:trunkshell:1)
Block(1,4,0,dynamictrees:trunkshell:3)
Block(1,4,1,dynamictrees:trunkshell:2)
Block(1,4,2,dynamictrees:trunkshell:1)
Block(1,5,0,dynamictrees:trunkshell:3)
Block(1,5,1,dynamictrees:trunkshell:2)
Block(1,5,2,dynamictrees:trunkshell:1)
Block(1,6,0,dynamictrees:trunkshell:3)
Block(1,6,1,dynamictrees:trunkshell:2)
Block(1,6,2,dynamictrees:trunkshell:1)
Block(1,8,1,rustic:ironwoodbranch:3)
Block(1,9,-4,rustic:leaves0:4)
Block(1,9,-3,rustic:leaves0:7)
Block(1,9,-2,rustic:ironwoodbranch)
Block(1,9,1,rustic:ironwoodbranch:2)
Block(1,9,4,rustic:ironwoodbranch)
Block(1,9,5,rustic:leaves0:7)
Block(1,9,6,rustic:leaves0:4)
Block(1,10,-4,rustic:leaves0:4)
Block(1,10,-3,rustic:leaves0:6)
Block(1,10,-2,rustic:leaves0:7)
Block(1,10,-1,rustic:ironwoodbranch)
Block(1,10,1,rustic:ironwoodbranch:1)
Block(1,10,2,rustic:ironwoodbranch)
Block(1,10,4,rustic:leaves0:7)
Block(1,10,5,rustic:leaves0:6)
Block(1,10,6,rustic:leaves0:4)
Block(1,11,-4,rustic:leaves0:4)
Block(1,11,-3,rustic:leaves0:5)
Block(1,11,-2,rustic:leaves0:6)
Block(1,11,-1,rustic:leaves0:7)
Block(1,11,0,rustic:ironwoodbranch)
Block(1,11,1,rustic:ironwoodbranch:1)
Block(1,11,2,rustic:leaves0:7)
Block(1,11,3,rustic:leaves0:7)
Block(1,11,4,rustic:leaves0:6)
Block(1,11,5,rustic:leaves0:5)
Block(1,11,6,rustic:leaves0:4)
Block(1,12,-3,rustic:leaves0:4)
Block(1,12,-2,rustic:leaves0:5)
Block(1,12,-1,rustic:leaves0:6)
Block(1,12,0,rustic:leaves0:7)
Block(1,12,1,rustic:ironwoodbranch)
Block(1,12,2,rustic:leaves0:7)
Block(1,12,3,rustic:leaves0:6)
Block(1,12,4,rustic:leaves0:5)
Block(1,12,5,rustic:leaves0:4)
Block(1,13,-2,rustic:leaves0:4)
Block(1,13,-1,rustic:leaves0:5)
Block(1,13,0,rustic:leaves0:6)
Block(1,13,1,rustic:leaves0:7)
Block(1,13,2,rustic:leaves0:6)
Block(1,13,3,rustic:leaves0:5)
Block(1,13,4,rustic:leaves0:4)
Block(1,14,-1,rustic:leaves0:4)
Block(1,14,0,rustic:leaves0:4)
Block(1,14,1,rustic:leaves0:4)
Block(1,14,2,rustic:leaves0:4)
Block(1,14,3,rustic:leaves0:4)
Block(2,0,-1,rustic:ironwoodroot:1)
Block(2,0,0,rustic:ironwoodroot:2)
Block(2,0,1,rustic:ironwoodroot:3)
Block(2,8,-3,rustic:leaves0:4)
Block(2,8,5,rustic:leaves0:4)
Block(2,9,-4,rustic:leaves0:4)
Block(2,9,-3,rustic:leaves0:6)
Block(2,9,-2,rustic:leaves0:7)
Block(2,9,1,rustic:ironwoodbranch:1)
Block(2,9,4,rustic:leaves0:7)
Block(2,9,5,rustic:leaves0:6)
Block(2,9,6,rustic:leaves0:4)
Block(2,10,-4,rustic:leaves0:4)
Block(2,10,-3,rustic:leaves0:5)
Block(2,10,-2,rustic:leaves0:6)
Block(2,10,-1,rustic:leaves0:7)
Block(2,10,3,rustic:leaves0:5)
Block(2,10,4,rustic:leaves0:6)
Block(2,10,5,rustic:leaves0:5)
Block(2,10,6,rustic:leaves0:4)
Block(2,11,-3,rustic:leaves0:4)
Block(2,11,-2,rustic:leaves0:5)
Block(2,11,-1,rustic:leaves0:6)
Block(2,11,0,rustic:leaves0:7)
Block(2,11,1,rustic:ironwoodbranch)
Block(2,11,2,rustic:leaves0:7)
Block(2,11,3,rustic:leaves0:6)
Block(2,11,4,rustic:leaves0:5)
Block(2,11,5,rustic:leaves0:4)
Block(2,12,-2,rustic:leaves0:4)
Block(2,12,-1,rustic:leaves0:5)
Block(2,12,0,rustic:leaves0:6)
Block(2,12,1,rustic:leaves0:7)
Block(2,12,2,rustic:leaves0:6)
Block(2,12,3,rustic:leaves0:5)
Block(2,12,4,rustic:leaves0:4)
Block(2,13,-1,rustic:leaves0:4)
Block(2,13,0,rustic:leaves0:5)
Block(2,13,1,rustic:leaves0:6)
Block(2,13,2,rustic:leaves0:5)
Block(2,13,3,rustic:leaves0:4)
Block(2,14,0,rustic:leaves0:4)
Block(2,14,1,rustic:leaves0:4)
Block(2,14,2,rustic:leaves0:4)
Block(3,9,-3,rustic:leaves0:4)
Block(3,9,-2,rustic:leaves0:4)
Block(3,9,-1,rustic:leaves0:4)
Block(3,9,1,rustic:ironwoodbranch:1)
Block(3,9,4,rustic:leaves0:4)
Block(3,9,5,rustic:leaves0:4)
Block(3,10,-3,rustic:leaves0:4)
Block(3,10,-2,rustic:leaves0:5)
Block(3,10,-1,rustic:leaves0:6)
Block(3,10,0,rustic:leaves0:7)
Block(3,10,1,rustic:ironwoodbranch)
Block(3,10,2,rustic:leaves0:7)
Block(3,10,3,rustic:leaves0:4)
Block(3,10,4,rustic:leaves0:4)
Block(3,10,5,rustic:leaves0:4)
Block(3,11,-2,rustic:leaves0:4)
Block(3,11,-1,rustic:leaves0:5)
Block(3,11,0,rustic:leaves0:6)
Block(3,11,1,rustic:leaves0:7)
Block(3,11,2,rustic:leaves0:6)
Block(3,11,3,rustic:leaves0:5)
Block(3,11,4,rustic:leaves0:4)
Block(3,12,-1,rustic:leaves0:4)
Block(3,12,0,rustic:leaves0:5)
Block(3,12,1,rustic:leaves0:6)
Block(3,12,2,rustic:leaves0:5)
Block(3,12,3,rustic:leaves0:4)
Block(3,13,0,rustic:leaves0:4)
Block(3,13,1,rustic:leaves0:5)
Block(3,13,2,rustic:leaves0:4)
Block(3,14,1,rustic:leaves0:4)
Block(4,9,-1,rustic:leaves0:4)
Block(4,9,0,rustic:leaves0:4)
Block(4,9,1,rustic:leaves0:4)
Block(4,9,2,rustic:leaves0:4)
Block(4,10,-2,rustic:leaves0:4)
Block(4,10,-1,rustic:leaves0:5)
Block(4,10,0,rustic:leaves0:6)
Block(4,10,1,rustic:leaves0:7)
Block(4,10,2,rustic:leaves0:6)
Block(4,10,3,rustic:leaves0:4)
Block(4,11,-1,rustic:leaves0:4)
Block(4,11,0,rustic:leaves0:5)
Block(4,11,1,rustic:leaves0:6)
Block(4,11,2,rustic:leaves0:5)
Block(4,11,3,rustic:leaves0:4)
Block(4,12,0,rustic:leaves0:4)
Block(4,12,1,rustic:leaves0:5)
Block(4,12,2,rustic:leaves0:4)
Block(4,13,1,rustic:leaves0:4)
Block(5,10,-1,rustic:leaves0:4)
Block(5,10,0,rustic:leaves0:4)
Block(5,10,1,rustic:leaves0:4)
Block(5,10,2,rustic:leaves0:4)
Block(5,11,0,rustic:leaves0:4)
Block(5,11,1,rustic:leaves0:4)
Block(5,11,2,rustic:leaves0:4)
Block(5,12,1,rustic:leaves0:4)

#######################################################################
# +-----------------------------------------------------------------+ #
# |                            BO3 checks                           | #
# +-----------------------------------------------------------------+ #
#######################################################################

BlockCheck(0,-1,1,GRASS,DIRT,MYCEL,biomesoplenty:grass,biomesoplenty:dirt)

#######################################################################
# +-----------------------------------------------------------------+ #
# |                             Branches                            | #
# +-----------------------------------------------------------------+ #
#######################################################################


#######################################################################
# +-----------------------------------------------------------------+ #
# |                             Entities                            | #
# +-----------------------------------------------------------------+ #
#######################################################################


#######################################################################
# +-----------------------------------------------------------------+ #
# |                            Particles                            | #
# +-----------------------------------------------------------------+ #
#######################################################################


#######################################################################
# +-----------------------------------------------------------------+ #
# |                             Spawners                            | #
# +-----------------------------------------------------------------+ #
#######################################################################


#######################################################################
# +-----------------------------------------------------------------+ #
# |                             ModData                             | #
# +-----------------------------------------------------------------+ #
#######################################################################

