#######################################################################
# +-----------------------------------------------------------------+ #
# |                            BO3 object                           | #
# +-----------------------------------------------------------------+ #
#######################################################################

Author: Bo3 BulkEdit

Description: Converted Schematic - Modified by Bo3BulkEdit

Version: 3

SettingsMode: WriteDisable

#######################################################################
# +-----------------------------------------------------------------+ #
# |                          Main settings                          | #
# +-----------------------------------------------------------------+ #
#######################################################################



Frequency: 0


SpawnHeight: randomY





##############################
# Height Limits for the BO3. #
##############################

MinHeight: 0
MaxHeight: 256

#######################################################################
# +-----------------------------------------------------------------+ #
# |                      Source block settings                      | #
# +-----------------------------------------------------------------+ #
#######################################################################

CanOverride: true
MaxPercentageOutsideSourceBlock: 100
OutsideSourceBlock: placeAnyway

#######################################################################
# +-----------------------------------------------------------------+ #
# |                               OTG+                              | #
# +-----------------------------------------------------------------+ #
#######################################################################

#######################################################################
# +-----------------------------------------------------------------+ #
# |                              Blocks                             | #
# +-----------------------------------------------------------------+ #
#######################################################################

B(0,750,0,AIR)
B(15,750,15,AIR)
B(5,12,15,betternether:quartz_stained_glass:15)
B(2,13,14,betternether:quartz_stained_glass:15)
B(3,13,14,betternether:quartz_stained_glass:15)
B(4,13,14,betternether:quartz_stained_glass:15)
B(5,13,14,betternether:quartz_stained_glass:15)
B(1,13,15,betternether:quartz_stained_glass:15)
B(2,13,15,betternether:quartz_stained_glass:15)
B(3,13,15,betternether:quartz_stained_glass:15)
B(4,13,15,betternether:quartz_stained_glass:15)
B(5,13,15,betternether:quartz_stained_glass:15)
B(2,14,13,betternether:quartz_stained_glass:15)
B(3,14,13,betternether:quartz_stained_glass:15)
B(4,14,13,betternether:quartz_stained_glass:15)
B(5,14,13,betternether:quartz_stained_glass:15)
B(6,14,13,betternether:quartz_stained_glass:15)
B(1,14,14,betternether:quartz_stained_glass:15)
B(2,14,14,betternether:quartz_stained_glass:15)
B(3,14,14,betternether:quartz_stained_glass:15)
B(4,14,14,betternether:quartz_stained_glass:15)
B(5,14,14,betternether:quartz_stained_glass:15)
B(1,14,15,betternether:quartz_stained_glass:15)
B(2,14,15,betternether:quartz_stained_glass:15)
B(3,14,15,betternether:quartz_stained_glass:15)
B(4,14,15,betternether:quartz_stained_glass:15)
B(5,14,15,betternether:quartz_stained_glass:15)
B(2,15,11,betternether:quartz_stained_glass:15)
B(3,15,11,betternether:quartz_stained_glass:15)
B(5,15,11,betternether:quartz_stained_glass:15)
B(1,15,12,betternether:quartz_stained_glass:15)
B(2,15,12,betternether:quartz_stained_glass:15)
B(3,15,12,betternether:quartz_stained_glass:15)
B(4,15,12,betternether:quartz_stained_glass:15)
B(5,15,12,betternether:quartz_stained_glass:15)
B(2,15,13,betternether:quartz_stained_glass:15)
B(3,15,13,betternether:quartz_stained_glass:15)
B(4,15,13,betternether:quartz_stained_glass:15)
B(5,15,13,betternether:quartz_stained_glass:15)
B(6,15,13,betternether:quartz_stained_glass:15)
B(1,15,14,betternether:quartz_stained_glass:15)
B(2,15,14,betternether:quartz_stained_glass:15)
RB(3,15,14,srparasites:parasitestain:1,80,quark:crystal:1,30,srparasites:parasiterubbledense:1,100)
RB(4,15,14,srparasites:parasitestain:1,80,quark:crystal:1,30,srparasites:parasiterubbledense:1,100)
B(5,15,14,betternether:quartz_stained_glass:15)
B(1,15,15,betternether:quartz_stained_glass:15)
B(2,15,15,betternether:quartz_stained_glass:15)
B(3,15,15,betternether:quartz_stained_glass:15)
RB(4,15,15,srparasites:parasitestain:1,80,quark:crystal:1,30,srparasites:parasiterubbledense:1,100)
B(5,15,15,betternether:quartz_stained_glass:15)
B(2,16,10,betternether:quartz_stained_glass:15)
B(3,16,10,betternether:quartz_stained_glass:15)
B(4,16,10,betternether:quartz_stained_glass:15)
B(5,16,10,betternether:quartz_stained_glass:15)
B(1,16,11,betternether:quartz_stained_glass:15)
B(2,16,11,betternether:quartz_stained_glass:15)
B(3,16,11,betternether:quartz_stained_glass:15)
B(4,16,11,betternether:quartz_stained_glass:15)
B(5,16,11,betternether:quartz_stained_glass:15)
B(1,16,12,betternether:quartz_stained_glass:15)
B(2,16,12,betternether:quartz_stained_glass:15)
B(3,16,12,betternether:quartz_stained_glass:15)
B(4,16,12,betternether:quartz_stained_glass:15)
B(5,16,12,betternether:quartz_stained_glass:15)
B(2,16,13,betternether:quartz_stained_glass:15)
RB(3,16,13,srparasites:parasitestain:1,80,quark:crystal:1,30,srparasites:parasiterubbledense:1,100)
RB(4,16,13,srparasites:parasitestain:1,80,quark:crystal:1,30,srparasites:parasiterubbledense:1,100)
B(5,16,13,betternether:quartz_stained_glass:15)
B(6,16,13,betternether:quartz_stained_glass:15)
B(1,16,14,betternether:quartz_stained_glass:15)
B(2,16,14,betternether:quartz_stained_glass:15)
RB(3,16,14,srparasites:parasitestain:1,80,quark:crystal:1,30,srparasites:parasiterubbledense:1,100)
RB(4,16,14,srparasites:parasitestain:1,80,quark:crystal:1,30,srparasites:parasiterubbledense:1,100)
B(5,16,14,betternether:quartz_stained_glass:15)
B(1,16,15,betternether:quartz_stained_glass:15)
B(2,16,15,betternether:quartz_stained_glass:15)
B(3,16,15,betternether:quartz_stained_glass:15)
B(4,16,15,betternether:quartz_stained_glass:15)
B(5,16,15,betternether:quartz_stained_glass:15)
B(3,17,8,betternether:quartz_stained_glass:15)
B(1,17,9,betternether:quartz_stained_glass:15)
B(2,17,9,betternether:quartz_stained_glass:15)
B(3,17,9,betternether:quartz_stained_glass:15)
B(4,17,9,betternether:quartz_stained_glass:15)
B(5,17,9,betternether:quartz_stained_glass:15)
B(1,17,10,betternether:quartz_stained_glass:15)
B(2,17,10,betternether:quartz_stained_glass:15)
B(3,17,10,betternether:quartz_stained_glass:15)
B(4,17,10,betternether:quartz_stained_glass:15)
B(5,17,10,betternether:quartz_stained_glass:15)
B(1,17,11,betternether:quartz_stained_glass:15)
B(2,17,11,betternether:quartz_stained_glass:15)
RB(3,17,11,srparasites:parasitestain:1,80,quark:crystal:1,30,srparasites:parasiterubbledense:1,100)
B(4,17,11,betternether:quartz_stained_glass:15)
B(5,17,11,betternether:quartz_stained_glass:15)
B(1,17,12,betternether:quartz_stained_glass:15)
B(2,17,12,betternether:quartz_stained_glass:15)
B(3,17,12,betternether:quartz_stained_glass:15)
RB(4,17,12,srparasites:parasitestain:1,80,quark:crystal:1,30,srparasites:parasiterubbledense:1,100)
B(5,17,12,betternether:quartz_stained_glass:15)
B(2,17,13,betternether:quartz_stained_glass:15)
RB(3,17,13,srparasites:parasitestain:1,80,quark:crystal:1,30,srparasites:parasiterubbledense:1,100)
B(4,17,13,betternether:quartz_stained_glass:15)
B(5,17,13,betternether:quartz_stained_glass:15)
B(6,17,13,betternether:quartz_stained_glass:15)
B(1,17,14,betternether:quartz_stained_glass:15)
B(2,17,14,betternether:quartz_stained_glass:15)
B(3,17,14,betternether:quartz_stained_glass:15)
B(4,17,14,betternether:quartz_stained_glass:15)
B(5,17,14,betternether:quartz_stained_glass:15)
B(1,17,15,betternether:quartz_stained_glass:15)
B(2,17,15,betternether:quartz_stained_glass:15)
B(3,17,15,betternether:quartz_stained_glass:15)
B(4,17,15,betternether:quartz_stained_glass:15)
B(5,17,15,betternether:quartz_stained_glass:15)
B(1,18,7,betternether:quartz_stained_glass:15)
B(3,18,7,betternether:quartz_stained_glass:15)
B(4,18,7,betternether:quartz_stained_glass:15)
B(5,18,7,betternether:quartz_stained_glass:15)
B(1,18,8,betternether:quartz_stained_glass:15)
B(2,18,8,betternether:quartz_stained_glass:15)
B(3,18,8,betternether:quartz_stained_glass:15)
B(4,18,8,betternether:quartz_stained_glass:15)
B(5,18,8,betternether:quartz_stained_glass:15)
B(1,18,9,betternether:quartz_stained_glass:15)
B(2,18,9,betternether:quartz_stained_glass:15)
B(3,18,9,betternether:quartz_stained_glass:15)
B(4,18,9,betternether:quartz_stained_glass:15)
B(5,18,9,betternether:quartz_stained_glass:15)
B(1,18,10,betternether:quartz_stained_glass:15)
B(2,18,10,betternether:quartz_stained_glass:15)
RB(3,18,10,srparasites:parasitestain:1,80,quark:crystal:1,30,srparasites:parasiterubbledense:1,100)
B(4,18,10,betternether:quartz_stained_glass:15)
B(5,18,10,betternether:quartz_stained_glass:15)
B(1,18,11,betternether:quartz_stained_glass:15)
B(2,18,11,betternether:quartz_stained_glass:15)
RB(3,18,11,srparasites:parasitestain:1,80,quark:crystal:1,30,srparasites:parasiterubbledense:1,100)
B(4,18,11,betternether:quartz_stained_glass:15)
B(5,18,11,betternether:quartz_stained_glass:15)
B(1,18,12,betternether:quartz_stained_glass:15)
B(2,18,12,betternether:quartz_stained_glass:15)
B(3,18,12,betternether:quartz_stained_glass:15)
B(4,18,12,betternether:quartz_stained_glass:15)
B(5,18,12,betternether:quartz_stained_glass:15)
B(2,18,13,betternether:quartz_stained_glass:15)
B(3,18,13,betternether:quartz_stained_glass:15)
B(4,18,13,betternether:quartz_stained_glass:15)
B(5,18,13,betternether:quartz_stained_glass:15)
B(6,18,13,betternether:quartz_stained_glass:15)
B(1,18,14,betternether:quartz_stained_glass:15)
B(2,18,14,betternether:quartz_stained_glass:15)
B(3,18,14,betternether:quartz_stained_glass:15)
B(4,18,14,betternether:quartz_stained_glass:15)
B(5,18,14,betternether:quartz_stained_glass:15)
B(3,18,15,betternether:quartz_stained_glass:15)
B(4,18,15,betternether:quartz_stained_glass:15)
B(4,19,5,betternether:quartz_stained_glass:15)
B(1,19,6,betternether:quartz_stained_glass:15)
B(2,19,6,betternether:quartz_stained_glass:15)
B(3,19,6,betternether:quartz_stained_glass:15)
B(4,19,6,betternether:quartz_stained_glass:15)
B(5,19,6,betternether:quartz_stained_glass:15)
B(1,19,7,betternether:quartz_stained_glass:15)
B(2,19,7,betternether:quartz_stained_glass:15)
B(3,19,7,betternether:quartz_stained_glass:15)
B(4,19,7,betternether:quartz_stained_glass:15)
B(5,19,7,betternether:quartz_stained_glass:15)
B(1,19,8,betternether:quartz_stained_glass:15)
B(2,19,8,betternether:quartz_stained_glass:15)
RB(3,19,8,srparasites:parasitestain:1,80,quark:crystal:1,30,srparasites:parasiterubbledense:1,100)
B(4,19,8,betternether:quartz_stained_glass:15)
B(5,19,8,betternether:quartz_stained_glass:15)
B(1,19,9,betternether:quartz_stained_glass:15)
B(2,19,9,betternether:quartz_stained_glass:15)
RB(3,19,9,srparasites:parasitestain:1,80,quark:crystal:1,30,srparasites:parasiterubbledense:1,100)
RB(4,19,9,srparasites:parasitestain:1,80,quark:crystal:1,30,srparasites:parasiterubbledense:1,100)
B(5,19,9,betternether:quartz_stained_glass:15)
B(1,19,10,betternether:quartz_stained_glass:15)
B(2,19,10,betternether:quartz_stained_glass:15)
RB(3,19,10,srparasites:parasitestain:1,80,quark:crystal:1,30,srparasites:parasiterubbledense:1,100)
B(4,19,10,betternether:quartz_stained_glass:15)
B(5,19,10,betternether:quartz_stained_glass:15)
B(1,19,11,betternether:quartz_stained_glass:15)
B(2,19,11,betternether:quartz_stained_glass:15)
B(3,19,11,betternether:quartz_stained_glass:15)
B(4,19,11,betternether:quartz_stained_glass:15)
B(5,19,11,betternether:quartz_stained_glass:15)
B(1,19,12,betternether:quartz_stained_glass:15)
B(2,19,12,betternether:quartz_stained_glass:15)
B(3,19,12,betternether:quartz_stained_glass:15)
B(4,19,12,betternether:quartz_stained_glass:15)
B(5,19,12,betternether:quartz_stained_glass:15)
B(2,19,13,betternether:quartz_stained_glass:15)
B(3,19,13,betternether:quartz_stained_glass:15)
B(4,19,13,betternether:quartz_stained_glass:15)
B(5,19,13,betternether:quartz_stained_glass:15)
B(1,20,4,betternether:quartz_stained_glass:15)
B(3,20,4,betternether:quartz_stained_glass:15)
B(4,20,4,betternether:quartz_stained_glass:15)
B(1,20,5,betternether:quartz_stained_glass:15)
B(2,20,5,betternether:quartz_stained_glass:15)
B(3,20,5,betternether:quartz_stained_glass:15)
B(4,20,5,betternether:quartz_stained_glass:15)
B(5,20,5,betternether:quartz_stained_glass:15)
B(1,20,6,betternether:quartz_stained_glass:15)
B(2,20,6,betternether:quartz_stained_glass:15)
B(3,20,6,betternether:quartz_stained_glass:15)
B(4,20,6,betternether:quartz_stained_glass:15)
B(5,20,6,betternether:quartz_stained_glass:15)
B(1,20,7,betternether:quartz_stained_glass:15)
B(2,20,7,betternether:quartz_stained_glass:15)
RB(3,20,7,srparasites:parasitestain:1,80,quark:crystal:1,30,srparasites:parasiterubbledense:1,100)
B(4,20,7,betternether:quartz_stained_glass:15)
B(5,20,7,betternether:quartz_stained_glass:15)
B(1,20,8,betternether:quartz_stained_glass:15)
RB(2,20,8,srparasites:parasitestain:1,80,quark:crystal:1,30,srparasites:parasiterubbledense:1,100)
RB(3,20,8,srparasites:parasitestain:1,80,quark:crystal:1,30,srparasites:parasiterubbledense:1,100)
B(4,20,8,betternether:quartz_stained_glass:15)
B(5,20,8,betternether:quartz_stained_glass:15)
B(1,20,9,betternether:quartz_stained_glass:15)
B(2,20,9,betternether:quartz_stained_glass:15)
RB(3,20,9,srparasites:parasitestain:1,80,quark:crystal:1,30,srparasites:parasiterubbledense:1,100)
B(4,20,9,betternether:quartz_stained_glass:15)
B(5,20,9,betternether:quartz_stained_glass:15)
B(1,20,10,betternether:quartz_stained_glass:15)
B(2,20,10,betternether:quartz_stained_glass:15)
B(3,20,10,betternether:quartz_stained_glass:15)
B(4,20,10,betternether:quartz_stained_glass:15)
B(5,20,10,betternether:quartz_stained_glass:15)
B(1,20,11,betternether:quartz_stained_glass:15)
B(2,20,11,betternether:quartz_stained_glass:15)
B(3,20,11,betternether:quartz_stained_glass:15)
B(4,20,11,betternether:quartz_stained_glass:15)
B(5,20,11,betternether:quartz_stained_glass:15)
B(2,20,12,betternether:quartz_stained_glass:15)
B(3,20,12,betternether:quartz_stained_glass:15)
B(4,20,12,betternether:quartz_stained_glass:15)
B(1,21,3,betternether:quartz_stained_glass:15)
B(2,21,3,betternether:quartz_stained_glass:15)
B(3,21,3,betternether:quartz_stained_glass:15)
B(4,21,3,betternether:quartz_stained_glass:15)
B(5,21,3,betternether:quartz_stained_glass:15)
B(0,21,4,betternether:quartz_stained_glass:15)
B(1,21,4,betternether:quartz_stained_glass:15)
B(2,21,4,betternether:quartz_stained_glass:15)
B(3,21,4,betternether:quartz_stained_glass:15)
B(4,21,4,betternether:quartz_stained_glass:15)
B(5,21,4,betternether:quartz_stained_glass:15)
B(1,21,5,betternether:quartz_stained_glass:15)
B(2,21,5,betternether:quartz_stained_glass:15)
B(3,21,5,betternether:quartz_stained_glass:15)
B(4,21,5,betternether:quartz_stained_glass:15)
B(5,21,5,betternether:quartz_stained_glass:15)
B(1,21,6,betternether:quartz_stained_glass:15)
B(2,21,6,betternether:quartz_stained_glass:15)
RB(3,21,6,srparasites:parasitestain:1,80,quark:crystal:1,30,srparasites:parasiterubbledense:1,100)
B(4,21,6,betternether:quartz_stained_glass:15)
B(5,21,6,betternether:quartz_stained_glass:15)
B(1,21,7,betternether:quartz_stained_glass:15)
B(2,21,7,betternether:quartz_stained_glass:15)
RB(3,21,7,srparasites:parasitestain:1,80,quark:crystal:1,30,srparasites:parasiterubbledense:1,100)
B(4,21,7,betternether:quartz_stained_glass:15)
B(5,21,7,betternether:quartz_stained_glass:15)
B(1,21,8,betternether:quartz_stained_glass:15)
B(2,21,8,betternether:quartz_stained_glass:15)
B(3,21,8,betternether:quartz_stained_glass:15)
B(4,21,8,betternether:quartz_stained_glass:15)
B(5,21,8,betternether:quartz_stained_glass:15)
B(1,21,9,betternether:quartz_stained_glass:15)
B(2,21,9,betternether:quartz_stained_glass:15)
B(3,21,9,betternether:quartz_stained_glass:15)
B(4,21,9,betternether:quartz_stained_glass:15)
B(5,21,9,betternether:quartz_stained_glass:15)
B(1,21,10,betternether:quartz_stained_glass:15)
B(2,21,10,betternether:quartz_stained_glass:15)
B(3,21,10,betternether:quartz_stained_glass:15)
B(4,21,10,betternether:quartz_stained_glass:15)
B(4,21,11,betternether:quartz_stained_glass:15)
B(0,22,2,betternether:quartz_stained_glass:15)
B(2,22,2,betternether:quartz_stained_glass:15)
B(3,22,2,betternether:quartz_stained_glass:15)
B(4,22,2,betternether:quartz_stained_glass:15)
B(5,22,2,betternether:quartz_stained_glass:15)
B(1,22,3,betternether:quartz_stained_glass:15)
B(2,22,3,betternether:quartz_stained_glass:15)
B(3,22,3,betternether:quartz_stained_glass:15)
B(4,22,3,betternether:quartz_stained_glass:15)
B(5,22,3,betternether:quartz_stained_glass:15)
B(0,22,4,betternether:quartz_stained_glass:15)
B(1,22,4,betternether:quartz_stained_glass:15)
B(2,22,4,betternether:quartz_stained_glass:15)
RB(3,22,4,srparasites:parasitestain:1,80,quark:crystal:1,30,srparasites:parasiterubbledense:1,100)
B(4,22,4,betternether:quartz_stained_glass:15)
B(5,22,4,betternether:quartz_stained_glass:15)
B(1,22,5,betternether:quartz_stained_glass:15)
B(2,22,5,betternether:quartz_stained_glass:15)
RB(3,22,5,srparasites:parasitestain:1,80,quark:crystal:1,30,srparasites:parasiterubbledense:1,100)
B(4,22,5,betternether:quartz_stained_glass:15)
B(5,22,5,betternether:quartz_stained_glass:15)
B(1,22,6,betternether:quartz_stained_glass:15)
B(2,22,6,betternether:quartz_stained_glass:15)
RB(3,22,6,srparasites:parasitestain:1,80,quark:crystal:1,30,srparasites:parasiterubbledense:1,100)
B(4,22,6,betternether:quartz_stained_glass:15)
B(5,22,6,betternether:quartz_stained_glass:15)
B(1,22,7,betternether:quartz_stained_glass:15)
B(2,22,7,betternether:quartz_stained_glass:15)
B(3,22,7,betternether:quartz_stained_glass:15)
B(4,22,7,betternether:quartz_stained_glass:15)
B(5,22,7,betternether:quartz_stained_glass:15)
B(1,22,8,betternether:quartz_stained_glass:15)
B(2,22,8,betternether:quartz_stained_glass:15)
B(3,22,8,betternether:quartz_stained_glass:15)
B(4,22,8,betternether:quartz_stained_glass:15)
B(5,22,8,betternether:quartz_stained_glass:15)
B(2,22,9,betternether:quartz_stained_glass:15)
B(3,22,9,betternether:quartz_stained_glass:15)
B(4,22,9,betternether:quartz_stained_glass:15)
B(1,23,1,betternether:quartz_stained_glass:15)
B(4,23,1,betternether:quartz_stained_glass:15)
B(0,23,2,betternether:quartz_stained_glass:15)
B(1,23,2,betternether:quartz_stained_glass:15)
B(2,23,2,betternether:quartz_stained_glass:15)
B(3,23,2,betternether:quartz_stained_glass:15)
B(4,23,2,betternether:quartz_stained_glass:15)
B(5,23,2,betternether:quartz_stained_glass:15)
B(1,23,3,betternether:quartz_stained_glass:15)
B(2,23,3,betternether:quartz_stained_glass:15)
B(3,23,3,betternether:quartz_stained_glass:15)
B(4,23,3,betternether:quartz_stained_glass:15)
B(5,23,3,betternether:quartz_stained_glass:15)
B(0,23,4,betternether:quartz_stained_glass:15)
B(1,23,4,betternether:quartz_stained_glass:15)
B(2,23,4,betternether:quartz_stained_glass:15)
RB(3,23,4,srparasites:parasitestain:1,80,quark:crystal:1,30,srparasites:parasiterubbledense:1,100)
B(4,23,4,betternether:quartz_stained_glass:15)
B(5,23,4,betternether:quartz_stained_glass:15)
B(1,23,5,betternether:quartz_stained_glass:15)
B(2,23,5,betternether:quartz_stained_glass:15)
B(3,23,5,betternether:quartz_stained_glass:15)
B(4,23,5,betternether:quartz_stained_glass:15)
B(5,23,5,betternether:quartz_stained_glass:15)
B(1,23,6,betternether:quartz_stained_glass:15)
B(2,23,6,betternether:quartz_stained_glass:15)
B(3,23,6,betternether:quartz_stained_glass:15)
B(4,23,6,betternether:quartz_stained_glass:15)
B(5,23,6,betternether:quartz_stained_glass:15)
B(1,23,7,betternether:quartz_stained_glass:15)
B(2,23,7,betternether:quartz_stained_glass:15)
B(3,23,7,betternether:quartz_stained_glass:15)
B(4,23,7,betternether:quartz_stained_glass:15)
B(2,23,8,betternether:quartz_stained_glass:15)
B(4,23,8,betternether:quartz_stained_glass:15)
B(2,24,0,betternether:quartz_stained_glass:15)
B(1,24,1,betternether:quartz_stained_glass:15)
B(2,24,1,betternether:quartz_stained_glass:15)
B(3,24,1,betternether:quartz_stained_glass:15)
B(4,24,1,betternether:quartz_stained_glass:15)
B(1,24,2,betternether:quartz_stained_glass:15)
B(2,24,2,betternether:quartz_stained_glass:15)
B(3,24,2,betternether:quartz_stained_glass:15)
B(1,24,3,betternether:quartz_stained_glass:15)
B(2,24,3,betternether:quartz_stained_glass:15)
B(3,24,3,betternether:quartz_stained_glass:15)
B(4,24,3,betternether:quartz_stained_glass:15)
B(5,24,3,betternether:quartz_stained_glass:15)
B(0,24,4,betternether:quartz_stained_glass:15)
B(1,24,4,betternether:quartz_stained_glass:15)
B(2,24,4,betternether:quartz_stained_glass:15)
B(3,24,4,betternether:quartz_stained_glass:15)
B(4,24,4,betternether:quartz_stained_glass:15)
B(5,24,4,betternether:quartz_stained_glass:15)
B(1,24,5,betternether:quartz_stained_glass:15)
B(2,24,5,betternether:quartz_stained_glass:15)
B(3,24,5,betternether:quartz_stained_glass:15)
B(4,24,5,betternether:quartz_stained_glass:15)
B(5,24,5,betternether:quartz_stained_glass:15)
B(1,24,6,betternether:quartz_stained_glass:15)
B(2,24,6,betternether:quartz_stained_glass:15)
B(3,24,6,betternether:quartz_stained_glass:15)
B(4,24,6,betternether:quartz_stained_glass:15)
B(2,24,7,betternether:quartz_stained_glass:15)
B(2,25,0,betternether:quartz_stained_glass:15)
B(2,25,1,betternether:quartz_stained_glass:15)
B(3,25,1,betternether:quartz_stained_glass:15)
B(2,25,2,betternether:quartz_stained_glass:15)
B(3,25,2,betternether:quartz_stained_glass:15)
B(2,25,3,betternether:quartz_stained_glass:15)
B(3,25,3,betternether:quartz_stained_glass:15)
B(2,25,4,betternether:quartz_stained_glass:15)
B(3,25,4,betternether:quartz_stained_glass:15)
B(2,25,5,betternether:quartz_stained_glass:15)
B(3,25,5,betternether:quartz_stained_glass:15)
B(2,26,0,betternether:quartz_stained_glass:15)
B(2,26,3,betternether:quartz_stained_glass:15)
B(3,26,3,betternether:quartz_stained_glass:15)

