
#######################################################################
# +-----------------------------------------------------------------+ #
# |                            BO4 object                           | #
# +-----------------------------------------------------------------+ #
#######################################################################

Author: NLBlackEagle

Description: No description given

SettingsMode: WriteDisable


#######################################################################
# +-----------------------------------------------------------------+ #
# |                          Main settings                          | #
# +-----------------------------------------------------------------+ #
#######################################################################

Frequency: 0

SpawnHeight: highestBlock

UseCenterForHighestBlock: true

##############################
# Height Limits for the BO4. #
##############################

MinHeight: 0

MaxHeight: 255

InheritBO3: 

InheritBO3Rotation: NORTH

OverrideChildSettings: true

OverrideParentHeight: false

CanOverride: true

BranchFrequency: 0

BranchFrequencyGroup: 

MustBeBelowOther: false

MustBeInside: 

CannotBeInside: 

ReplacesBO3: 

MustBeInsideWorldBorders: false

CanSpawnOnWater: true

SpawnOnWaterOnly: false

SpawnUnderWater: false

SpawnAtWaterLevel: false

HeightOffset: 0

RemoveAir: true

ReplaceAbove: 

ReplaceBelow: 

ReplaceWithBiomeBlocks: true

ReplaceWithSurfaceBlock: GRASS

ReplaceWithGroundBlock: DIRT

ReplaceWithStoneBlock: STONE

SmoothRadius: 0

SmoothHeightOffset: 0

SmoothStartTop: false

SmoothStartWood: false

SmoothingSurfaceBlock: 

SmoothingGroundBlock: 

BO3Group: 

IsSpawnPoint: false

DoReplaceBlocks: true


#######################################################################
# +-----------------------------------------------------------------+ #
# |                              Blocks                             | #
# +-----------------------------------------------------------------+ #
#######################################################################

Block(2,19,8,PACKED_ICE:0)
Block(2,20,7,PACKED_ICE:0)
Block(2,20,8,PACKED_ICE:0)
Block(2,21,5,PACKED_ICE:0)
Block(3,17,8,PACKED_ICE:0)
Block(3,18,7,PACKED_ICE:0)
Block(3,18,8,PACKED_ICE:0)
Block(3,19,5,PACKED_ICE:0)
Block(3,19,6,PACKED_ICE:0)
Block(3,19,7,PACKED_ICE:0)
Block(3,19,8,PACKED_ICE:0)
Block(3,20,4,PACKED_ICE:0)
Block(3,20,5,PACKED_ICE:0)
Block(3,20,6,PACKED_ICE:0)
Block(3,20,7,PACKED_ICE:0)
Block(3,20,8,PACKED_ICE:0)
Block(3,21,2,PACKED_ICE:0)
Block(3,21,3,PACKED_ICE:0)
Block(3,21,4,PACKED_ICE:0)
Block(3,21,5,PACKED_ICE:0)
Block(3,22,1,PACKED_ICE:0)
Block(3,22,2,PACKED_ICE:0)
Block(4,17,6,PACKED_ICE:0)
Block(4,17,7,PACKED_ICE:0)
Block(4,17,8,PACKED_ICE:0)
Block(4,18,4,PACKED_ICE:0)
Block(4,18,5,PACKED_ICE:0)
Block(4,18,6,PACKED_ICE:0)
Block(4,18,7,PACKED_ICE:0)
Block(4,18,8,PACKED_ICE:0)
Block(4,19,2,PACKED_ICE:0)
Block(4,19,3,PACKED_ICE:0)
Block(4,19,4,PACKED_ICE:0)
Block(4,19,5,PACKED_ICE:0)
Block(4,19,6,PACKED_ICE:0)
Block(4,19,7,PACKED_ICE:0)
Block(4,19,8,PACKED_ICE:0)
Block(4,20,1,PACKED_ICE:0)
Block(4,20,2,PACKED_ICE:0)
Block(4,20,3,PACKED_ICE:0)
Block(4,20,4,PACKED_ICE:0)
Block(4,20,5,PACKED_ICE:0)
Block(4,20,6,PACKED_ICE:0)
Block(4,20,7,PACKED_ICE:0)
Block(4,20,8,PACKED_ICE:0)
Block(4,21,0,PACKED_ICE:0)
Block(4,21,1,PACKED_ICE:0)
Block(4,21,2,PACKED_ICE:0)
Block(4,21,3,PACKED_ICE:0)
Block(4,21,4,PACKED_ICE:0)
Block(4,21,5,PACKED_ICE:0)
Block(4,21,6,PACKED_ICE:0)
Block(4,22,-2,PACKED_ICE:0)
Block(4,22,-1,PACKED_ICE:0)
Block(4,22,0,PACKED_ICE:0)
Block(4,22,1,PACKED_ICE:0)
Block(4,22,2,PACKED_ICE:0)
Block(4,22,3,PACKED_ICE:0)
Block(4,23,-3,PACKED_ICE:0)
Block(4,23,-2,PACKED_ICE:0)
Block(4,23,-1,PACKED_ICE:0)
Block(4,23,0,PACKED_ICE:0)
Block(4,24,-4,PACKED_ICE:0)
Block(4,24,-3,PACKED_ICE:0)
Block(4,25,-6,PACKED_ICE:0)
Block(5,16,8,PACKED_ICE:0)
Block(5,17,6,PACKED_ICE:0)
Block(5,17,7,PACKED_ICE:0)
Block(5,17,8,PACKED_ICE:0)
Block(5,18,4,PACKED_ICE:0)
Block(5,18,5,PACKED_ICE:0)
Block(5,18,6,PACKED_ICE:0)
Block(5,18,7,PACKED_ICE:0)
Block(5,18,8,PACKED_ICE:0)
Block(5,19,2,PACKED_ICE:0)
Block(5,19,3,PACKED_ICE:0)
Block(5,19,4,PACKED_ICE:0)
Block(5,19,5,PACKED_ICE:0)
Block(5,19,6,PACKED_ICE:0)
Block(5,19,7,PACKED_ICE:0)
Block(5,19,8,PACKED_ICE:0)
Block(5,20,0,PACKED_ICE:0)
Block(5,20,1,PACKED_ICE:0)
Block(5,20,2,PACKED_ICE:0)
Block(5,20,3,PACKED_ICE:0)
Block(5,20,4,PACKED_ICE:0)
Block(5,20,5,PACKED_ICE:0)
Block(5,20,6,PACKED_ICE:0)
Block(5,20,7,PACKED_ICE:0)
Block(5,20,8,PACKED_ICE:0)
Block(5,21,-2,PACKED_ICE:0)
Block(5,21,-1,PACKED_ICE:0)
Block(5,21,0,PACKED_ICE:0)
Block(5,21,1,PACKED_ICE:0)
Block(5,21,2,PACKED_ICE:0)
Block(5,21,3,PACKED_ICE:0)
Block(5,21,4,PACKED_ICE:0)
Block(5,21,5,PACKED_ICE:0)
Block(5,21,6,PACKED_ICE:0)
Block(5,22,-4,PACKED_ICE:0)
Block(5,22,-3,PACKED_ICE:0)
Block(5,22,-2,PACKED_ICE:0)
Block(5,22,-1,PACKED_ICE:0)
Block(5,22,0,PACKED_ICE:0)
Block(5,22,1,PACKED_ICE:0)
Block(5,22,2,PACKED_ICE:0)
Block(5,22,3,PACKED_ICE:0)
Block(5,23,-6,PACKED_ICE:0)
Block(5,23,-5,PACKED_ICE:0)
Block(5,23,-4,PACKED_ICE:0)
Block(5,23,-3,PACKED_ICE:0)
Block(5,23,-2,PACKED_ICE:0)
Block(5,23,-1,PACKED_ICE:0)
Block(5,23,0,PACKED_ICE:0)
Block(5,24,-7,PACKED_ICE:0)
Block(5,24,-6,PACKED_ICE:0)
Block(5,24,-5,PACKED_ICE:0)
Block(5,24,-4,PACKED_ICE:0)
Block(5,24,-3,PACKED_ICE:0)
Block(5,25,-7,PACKED_ICE:0)
Block(5,25,-6,PACKED_ICE:0)
Block(5,25,-5,PACKED_ICE:0)
Block(6,16,8,PACKED_ICE:0)
Block(6,17,6,PACKED_ICE:0)
Block(6,17,7,PACKED_ICE:0)
Block(6,17,8,PACKED_ICE:0)
Block(6,18,4,PACKED_ICE:0)
Block(6,18,5,PACKED_ICE:0)
Block(6,18,6,PACKED_ICE:0)
Block(6,18,7,PACKED_ICE:0)
Block(6,18,8,PACKED_ICE:0)
Block(6,19,2,PACKED_ICE:0)
Block(6,19,3,PACKED_ICE:0)
Block(6,19,4,PACKED_ICE:0)
Block(6,19,5,PACKED_ICE:0)
Block(6,19,6,PACKED_ICE:0)
Block(6,19,7,PACKED_ICE:0)
Block(6,19,8,PACKED_ICE:0)
Block(6,20,0,PACKED_ICE:0)
Block(6,20,1,PACKED_ICE:0)
Block(6,20,2,PACKED_ICE:0)
Block(6,20,3,PACKED_ICE:0)
Block(6,20,4,PACKED_ICE:0)
Block(6,20,5,PACKED_ICE:0)
Block(6,20,6,PACKED_ICE:0)
Block(6,20,7,PACKED_ICE:0)
Block(6,20,8,PACKED_ICE:0)
Block(6,21,-2,ICE:0)
Block(6,21,-1,PACKED_ICE:0)
Block(6,21,0,PACKED_ICE:0)
Block(6,21,1,PACKED_ICE:0)
Block(6,21,2,PACKED_ICE:0)
Block(6,21,3,PACKED_ICE:0)
Block(6,21,4,PACKED_ICE:0)
Block(6,21,5,PACKED_ICE:0)
Block(6,21,6,PACKED_ICE:0)
Block(6,21,7,PACKED_ICE:0)
Block(6,22,-4,ICE:0)
Block(6,22,-3,ICE:0)
Block(6,22,-2,ICE:0)
Block(6,22,-1,ICE:0)
Block(6,22,0,PACKED_ICE:0)
Block(6,22,1,PACKED_ICE:0)
Block(6,22,2,PACKED_ICE:0)
Block(6,22,3,PACKED_ICE:0)
Block(6,22,4,PACKED_ICE:0)
Block(6,23,-6,PACKED_ICE:0)
Block(6,23,-5,ICE:0)
Block(6,23,-4,ICE:0)
Block(6,23,-3,ICE:0)
Block(6,23,-2,ICE:0)
Block(6,23,-1,ICE:0)
Block(6,23,0,PACKED_ICE:0)
Block(6,23,1,PACKED_ICE:0)
Block(6,24,-7,PACKED_ICE:0)
Block(6,24,-6,PACKED_ICE:0)
Block(6,24,-5,ICE:0)
Block(6,24,-4,ICE:0)
Block(6,24,-3,ICE:0)
Block(6,24,-2,ICE:0)
Block(6,25,-7,PACKED_ICE:0)
Block(6,25,-6,PACKED_ICE:0)
Block(6,25,-5,PACKED_ICE:0)
Block(7,16,8,ICE:0)
Block(7,17,6,ICE:0)
Block(7,17,7,PACKED_ICE:0)
Block(7,17,8,ICE:0)
Block(7,18,4,ICE:0)
Block(7,18,5,ICE:0)
Block(7,18,6,ICE:0)
Block(7,18,7,ICE:0)
Block(7,18,8,ICE:0)
Block(7,19,2,ICE:0)
Block(7,19,3,ICE:0)
Block(7,19,4,ICE:0)
Block(7,19,5,ICE:0)
Block(7,19,6,ICE:0)
Block(7,19,7,ICE:0)
Block(7,19,8,PACKED_ICE:0)
Block(7,20,0,ICE:0)
Block(7,20,1,ICE:0)
Block(7,20,2,ICE:0)
Block(7,20,3,ICE:0)
Block(7,20,4,ICE:0)
Block(7,20,5,ICE:0)
Block(7,20,6,ICE:0)
Block(7,20,7,ICE:0)
Block(7,20,8,PACKED_ICE:0)
Block(7,21,-2,ICE:0)
Block(7,21,-1,ICE:0)
Block(7,21,0,ICE:0)
Block(7,21,1,ICE:0)
Block(7,21,2,ICE:0)
Block(7,21,3,ICE:0)
Block(7,21,4,ICE:0)
Block(7,21,5,ICE:0)
Block(7,21,6,ICE:0)
Block(7,21,7,PACKED_ICE:0)
Block(7,22,-4,ICE:0)
Block(7,22,-3,ICE:0)
Block(7,22,-2,ICE:0)
Block(7,22,-1,ICE:0)
Block(7,22,0,ICE:0)
Block(7,22,1,ICE:0)
Block(7,22,2,ICE:0)
Block(7,22,3,ICE:0)
Block(7,22,4,PACKED_ICE:0)
Block(7,23,-6,ICE:0)
Block(7,23,-5,ICE:0)
Block(7,23,-4,ICE:0)
Block(7,23,-3,ICE:0)
Block(7,23,-2,ICE:0)
Block(7,23,-1,ICE:0)
Block(7,23,0,ICE:0)
Block(7,23,1,ICE:0)
Block(7,24,-7,PACKED_ICE:0)
Block(7,24,-6,ICE:0)
Block(7,24,-5,ICE:0)
Block(7,24,-4,ICE:0)
Block(7,24,-3,ICE:0)
Block(7,24,-2,ICE:0)
Block(7,24,-1,ICE:0)
Block(7,25,-7,PACKED_ICE:0)
Block(7,25,-6,ICE:0)
Block(7,25,-5,ICE:0)
Block(7,25,-4,ICE:0)
Block(7,26,-7,PACKED_ICE:0)

#######################################################################
# +-----------------------------------------------------------------+ #
# |                             Branches                            | #
# +-----------------------------------------------------------------+ #
#######################################################################


#######################################################################
# +-----------------------------------------------------------------+ #
# |                             Entities                            | #
# +-----------------------------------------------------------------+ #
#######################################################################


#######################################################################
# +-----------------------------------------------------------------+ #
# |                            Particles                            | #
# +-----------------------------------------------------------------+ #
#######################################################################


#######################################################################
# +-----------------------------------------------------------------+ #
# |                             Spawners                            | #
# +-----------------------------------------------------------------+ #
#######################################################################


#######################################################################
# +-----------------------------------------------------------------+ #
# |                             ModData                             | #
# +-----------------------------------------------------------------+ #
#######################################################################

