
#######################################################################
# +-----------------------------------------------------------------+ #
# |                            BO4 object                           | #
# +-----------------------------------------------------------------+ #
#######################################################################

Author: NLBlackEagle

Description: No description given

SettingsMode: WriteDisable


#######################################################################
# +-----------------------------------------------------------------+ #
# |                          Main settings                          | #
# +-----------------------------------------------------------------+ #
#######################################################################

Frequency: 0

SpawnHeight: highestBlock

UseCenterForHighestBlock: true

##############################
# Height Limits for the BO4. #
##############################

MinHeight: 0

MaxHeight: 255

InheritBO3: 

InheritBO3Rotation: NORTH

OverrideChildSettings: true

OverrideParentHeight: false

CanOverride: true

BranchFrequency: 0

BranchFrequencyGroup: 

MustBeBelowOther: false

MustBeInside: 

CannotBeInside: 

ReplacesBO3: 

MustBeInsideWorldBorders: false

CanSpawnOnWater: true

SpawnOnWaterOnly: false

SpawnUnderWater: false

SpawnAtWaterLevel: false

HeightOffset: 0

RemoveAir: true

ReplaceAbove: 

ReplaceBelow: 

ReplaceWithBiomeBlocks: true

ReplaceWithSurfaceBlock: GRASS

ReplaceWithGroundBlock: DIRT

ReplaceWithStoneBlock: STONE

SmoothRadius: 0

SmoothHeightOffset: 0

SmoothStartTop: false

SmoothStartWood: false

SmoothingSurfaceBlock: 

SmoothingGroundBlock: 

BO3Group: 

IsSpawnPoint: false

DoReplaceBlocks: true


#######################################################################
# +-----------------------------------------------------------------+ #
# |                              Blocks                             | #
# +-----------------------------------------------------------------+ #
#######################################################################

Block(-4,8,8,PACKED_ICE:0)
Block(-3,6,8,PACKED_ICE:0)
Block(-3,7,7,PACKED_ICE:0)
Block(-3,7,8,PACKED_ICE:0)
Block(-3,8,5,PACKED_ICE:0)
Block(-3,8,6,PACKED_ICE:0)
Block(-3,8,7,PACKED_ICE:0)
Block(-3,8,8,PACKED_ICE:0)
Block(-3,9,4,PACKED_ICE:0)
Block(-3,9,5,PACKED_ICE:0)
Block(-3,9,6,PACKED_ICE:0)
Block(-3,10,3,PACKED_ICE:0)
Block(-2,4,8,PACKED_ICE:0)
Block(-2,5,7,PACKED_ICE:0)
Block(-2,5,8,ICE:0)
Block(-2,6,5,PACKED_ICE:0)
Block(-2,6,6,PACKED_ICE:0)
Block(-2,6,7,PACKED_ICE:0)
Block(-2,6,8,ICE:0)
Block(-2,7,4,PACKED_ICE:0)
Block(-2,7,5,PACKED_ICE:0)
Block(-2,7,6,PACKED_ICE:0)
Block(-2,7,7,PACKED_ICE:0)
Block(-2,7,8,ICE:0)
Block(-2,8,2,PACKED_ICE:0)
Block(-2,8,3,PACKED_ICE:0)
Block(-2,8,4,PACKED_ICE:0)
Block(-2,8,5,PACKED_ICE:0)
Block(-2,8,6,PACKED_ICE:0)
Block(-2,8,7,ICE:0)
Block(-2,8,8,ICE:0)
Block(-2,9,1,PACKED_ICE:0)
Block(-2,9,2,PACKED_ICE:0)
Block(-2,9,3,PACKED_ICE:0)
Block(-2,9,4,PACKED_ICE:0)
Block(-2,9,5,PACKED_ICE:0)
Block(-2,9,6,PACKED_ICE:0)
Block(-2,10,0,PACKED_ICE:0)
Block(-2,10,1,PACKED_ICE:0)
Block(-2,10,2,PACKED_ICE:0)
Block(-2,10,3,PACKED_ICE:0)
Block(-2,11,-2,PACKED_ICE:0)
Block(-2,11,-1,PACKED_ICE:0)
Block(-2,11,0,PACKED_ICE:0)
Block(-2,12,-3,PACKED_ICE:0)
Block(-1,2,8,PACKED_ICE:0)
Block(-1,3,6,PACKED_ICE:0)
Block(-1,3,7,PACKED_ICE:0)
Block(-1,3,8,PACKED_ICE:0)
Block(-1,4,5,PACKED_ICE:0)
Block(-1,4,6,PACKED_ICE:0)
Block(-1,4,7,PACKED_ICE:0)
Block(-1,4,8,ICE:0)
Block(-1,5,4,PACKED_ICE:0)
Block(-1,5,5,PACKED_ICE:0)
Block(-1,5,6,PACKED_ICE:0)
Block(-1,5,7,PACKED_ICE:0)
Block(-1,5,8,ICE:0)
Block(-1,6,2,PACKED_ICE:0)
Block(-1,6,3,PACKED_ICE:0)
Block(-1,6,4,PACKED_ICE:0)
Block(-1,6,5,PACKED_ICE:0)
Block(-1,6,6,PACKED_ICE:0)
Block(-1,6,7,ICE:0)
Block(-1,6,8,ICE:0)
Block(-1,7,1,PACKED_ICE:0)
Block(-1,7,2,PACKED_ICE:0)
Block(-1,7,3,PACKED_ICE:0)
Block(-1,7,4,PACKED_ICE:0)
Block(-1,7,5,PACKED_ICE:0)
Block(-1,7,6,ICE:0)
Block(-1,7,7,ICE:0)
Block(-1,7,8,ICE:0)
Block(-1,8,0,PACKED_ICE:0)
Block(-1,8,1,PACKED_ICE:0)
Block(-1,8,2,PACKED_ICE:0)
Block(-1,8,3,PACKED_ICE:0)
Block(-1,8,4,PACKED_ICE:0)
Block(-1,8,5,ICE:0)
Block(-1,8,6,ICE:0)
Block(-1,8,7,ICE:0)
Block(-1,8,8,ICE:0)
Block(-1,9,-2,PACKED_ICE:0)
Block(-1,9,-1,PACKED_ICE:0)
Block(-1,9,0,PACKED_ICE:0)
Block(-1,9,1,PACKED_ICE:0)
Block(-1,9,2,PACKED_ICE:0)
Block(-1,9,3,PACKED_ICE:0)
Block(-1,9,4,ICE:0)
Block(-1,9,5,ICE:0)
Block(-1,9,6,ICE:0)
Block(-1,9,7,ICE:0)
Block(-1,10,-3,PACKED_ICE:0)
Block(-1,10,-2,PACKED_ICE:0)
Block(-1,10,-1,PACKED_ICE:0)
Block(-1,10,0,PACKED_ICE:0)
Block(-1,10,1,PACKED_ICE:0)
Block(-1,10,2,PACKED_ICE:0)
Block(-1,10,3,PACKED_ICE:0)
Block(-1,10,4,ICE:0)
Block(-1,11,-4,PACKED_ICE:0)
Block(-1,11,-3,PACKED_ICE:0)
Block(-1,11,-2,PACKED_ICE:0)
Block(-1,11,-1,PACKED_ICE:0)
Block(-1,11,0,PACKED_ICE:0)
Block(-1,11,1,PACKED_ICE:0)
Block(-1,12,-6,PACKED_ICE:0)
Block(-1,12,-5,PACKED_ICE:0)
Block(-1,12,-4,PACKED_ICE:0)
Block(-1,12,-3,PACKED_ICE:0)
Block(-1,12,-2,PACKED_ICE:0)
Block(-1,13,-7,PACKED_ICE:0)
Block(-1,13,-6,PACKED_ICE:0)
Block(-1,13,-5,PACKED_ICE:0)
Block(0,1,8,PACKED_ICE:0)
Block(0,2,6,PACKED_ICE:0)
Block(0,2,7,PACKED_ICE:0)
Block(0,2,8,PACKED_ICE:0)
Block(0,3,4,PACKED_ICE:0)
Block(0,3,5,PACKED_ICE:0)
Block(0,3,6,PACKED_ICE:0)
Block(0,3,7,PACKED_ICE:0)
Block(0,3,8,PACKED_ICE:0)
Block(0,4,2,PACKED_ICE:0)
Block(0,4,3,PACKED_ICE:0)
Block(0,4,4,PACKED_ICE:0)
Block(0,4,5,PACKED_ICE:0)
Block(0,4,6,PACKED_ICE:0)
Block(0,4,7,PACKED_ICE:0)
Block(0,4,8,ICE:0)
Block(0,5,1,PACKED_ICE:0)
Block(0,5,2,PACKED_ICE:0)
Block(0,5,3,PACKED_ICE:0)
Block(0,5,4,PACKED_ICE:0)
Block(0,5,5,PACKED_ICE:0)
Block(0,5,6,PACKED_ICE:0)
Block(0,5,7,ICE:0)
Block(0,5,8,ICE:0)
Block(0,6,-1,PACKED_ICE:0)
Block(0,6,0,PACKED_ICE:0)
Block(0,6,1,PACKED_ICE:0)
Block(0,6,2,PACKED_ICE:0)
Block(0,6,3,PACKED_ICE:0)
Block(0,6,4,PACKED_ICE:0)
Block(0,6,5,PACKED_ICE:0)
Block(0,6,6,ICE:0)
Block(0,6,7,ICE:0)
Block(0,6,8,ICE:0)
Block(0,7,-2,PACKED_ICE:0)
Block(0,7,-1,PACKED_ICE:0)
Block(0,7,0,PACKED_ICE:0)
Block(0,7,1,PACKED_ICE:0)
Block(0,7,2,PACKED_ICE:0)
Block(0,7,3,PACKED_ICE:0)
Block(0,7,4,ICE:0)
Block(0,7,5,ICE:0)
Block(0,7,6,ICE:0)
Block(0,7,7,ICE:0)
Block(0,7,8,ICE:0)
Block(0,8,-3,PACKED_ICE:0)
Block(0,8,-2,PACKED_ICE:0)
Block(0,8,-1,PACKED_ICE:0)
Block(0,8,0,PACKED_ICE:0)
Block(0,8,1,PACKED_ICE:0)
Block(0,8,2,PACKED_ICE:0)
Block(0,8,3,ICE:0)
Block(0,8,4,ICE:0)
Block(0,8,5,ICE:0)
Block(0,8,6,ICE:0)
Block(0,8,7,ICE:0)
Block(0,8,8,ICE:0)
Block(0,9,-5,PACKED_ICE:0)
Block(0,9,-4,PACKED_ICE:0)
Block(0,9,-3,PACKED_ICE:0)
Block(0,9,-2,PACKED_ICE:0)
Block(0,9,-1,PACKED_ICE:0)
Block(0,9,0,PACKED_ICE:0)
Block(0,9,1,PACKED_ICE:0)
Block(0,9,2,PACKED_ICE:0)
Block(0,9,3,ICE:0)
Block(0,9,4,ICE:0)
Block(0,9,5,ICE:0)
Block(0,9,6,ICE:0)
Block(0,9,7,ICE:0)
Block(0,10,-6,PACKED_ICE:0)
Block(0,10,-5,PACKED_ICE:0)
Block(0,10,-4,PACKED_ICE:0)
Block(0,10,-3,PACKED_ICE:0)
Block(0,10,-2,PACKED_ICE:0)
Block(0,10,-1,PACKED_ICE:0)
Block(0,10,0,PACKED_ICE:0)
Block(0,10,1,PACKED_ICE:0)
Block(0,10,2,PACKED_ICE:0)
Block(0,10,3,ICE:0)
Block(0,10,4,ICE:0)
Block(0,11,-7,PACKED_ICE:0)
Block(0,11,-6,PACKED_ICE:0)
Block(0,11,-5,PACKED_ICE:0)
Block(0,11,-4,PACKED_ICE:0)
Block(0,11,-3,PACKED_ICE:0)
Block(0,11,-2,PACKED_ICE:0)
Block(0,11,-1,PACKED_ICE:0)
Block(0,11,0,PACKED_ICE:0)
Block(0,11,1,PACKED_ICE:0)
Block(0,12,-7,PACKED_ICE:0)
Block(0,12,-6,PACKED_ICE:0)
Block(0,12,-5,PACKED_ICE:0)
Block(0,12,-4,PACKED_ICE:0)
Block(0,12,-3,PACKED_ICE:0)
Block(0,12,-2,PACKED_ICE:0)
Block(0,13,-7,PACKED_ICE:0)
Block(0,13,-6,PACKED_ICE:0)
Block(0,13,-5,PACKED_ICE:0)
Block(1,1,8,PACKED_ICE:0)
Block(1,2,6,PACKED_ICE:0)
Block(1,2,7,PACKED_ICE:0)
Block(1,2,8,PACKED_ICE:0)
Block(1,3,4,PACKED_ICE:0)
Block(1,3,5,PACKED_ICE:0)
Block(1,3,6,PACKED_ICE:0)
Block(1,3,7,PACKED_ICE:0)
Block(1,3,8,PACKED_ICE:0)
Block(1,4,2,PACKED_ICE:0)
Block(1,4,3,PACKED_ICE:0)
Block(1,4,4,PACKED_ICE:0)
Block(1,4,5,PACKED_ICE:0)
Block(1,4,6,PACKED_ICE:0)
Block(1,4,7,PACKED_ICE:0)
Block(1,4,8,ICE:0)
Block(1,5,0,PACKED_ICE:0)
Block(1,5,1,PACKED_ICE:0)
Block(1,5,2,PACKED_ICE:0)
Block(1,5,3,PACKED_ICE:0)
Block(1,5,4,PACKED_ICE:0)
Block(1,5,5,PACKED_ICE:0)
Block(1,5,6,ICE:0)
Block(1,5,7,ICE:0)
Block(1,5,8,ICE:0)
Block(1,6,-2,PACKED_ICE:0)
Block(1,6,-1,PACKED_ICE:0)
Block(1,6,0,PACKED_ICE:0)
Block(1,6,1,PACKED_ICE:0)
Block(1,6,2,PACKED_ICE:0)
Block(1,6,3,PACKED_ICE:0)
Block(1,6,4,ICE:0)
Block(1,6,5,ICE:0)
Block(1,6,6,ICE:0)
Block(1,6,7,ICE:0)
Block(1,6,8,ICE:0)
Block(1,7,-4,PACKED_ICE:0)
Block(1,7,-3,PACKED_ICE:0)
Block(1,7,-2,PACKED_ICE:0)
Block(1,7,-1,PACKED_ICE:0)
Block(1,7,0,PACKED_ICE:0)
Block(1,7,1,PACKED_ICE:0)
Block(1,7,2,PACKED_ICE:0)
Block(1,7,3,ICE:0)
Block(1,7,4,ICE:0)
Block(1,7,5,ICE:0)
Block(1,7,6,ICE:0)
Block(1,7,7,ICE:0)
Block(1,7,8,ICE:0)
Block(1,8,-6,PACKED_ICE:0)
Block(1,8,-5,PACKED_ICE:0)
Block(1,8,-4,PACKED_ICE:0)
Block(1,8,-3,PACKED_ICE:0)
Block(1,8,-2,PACKED_ICE:0)
Block(1,8,-1,PACKED_ICE:0)
Block(1,8,0,PACKED_ICE:0)
Block(1,8,1,PACKED_ICE:0)
Block(1,8,2,ICE:0)
Block(1,8,3,ICE:0)
Block(1,8,4,ICE:0)
Block(1,8,5,ICE:0)
Block(1,8,6,ICE:0)
Block(1,8,7,ICE:0)
Block(1,8,8,ICE:0)
Block(1,9,-7,PACKED_ICE:0)
Block(1,9,-6,PACKED_ICE:0)
Block(1,9,-5,PACKED_ICE:0)
Block(1,9,-4,PACKED_ICE:0)
Block(1,9,-3,PACKED_ICE:0)
Block(1,9,-2,PACKED_ICE:0)
Block(1,9,-1,PACKED_ICE:0)
Block(1,9,0,PACKED_ICE:0)
Block(1,9,1,PACKED_ICE:0)
Block(1,9,2,ICE:0)
Block(1,9,3,ICE:0)
Block(1,9,4,ICE:0)
Block(1,9,5,ICE:0)
Block(1,9,6,ICE:0)
Block(1,9,7,ICE:0)
Block(1,9,8,ICE:0)
Block(1,10,-7,PACKED_ICE:0)
Block(1,10,-6,PACKED_ICE:0)
Block(1,10,-5,PACKED_ICE:0)
Block(1,10,-4,PACKED_ICE:0)
Block(1,10,-3,PACKED_ICE:0)
Block(1,10,-2,PACKED_ICE:0)
Block(1,10,-1,PACKED_ICE:0)
Block(1,10,0,PACKED_ICE:0)
Block(1,10,1,PACKED_ICE:0)
Block(1,10,2,ICE:0)
Block(1,10,3,ICE:0)
Block(1,10,4,ICE:0)
Block(1,10,5,ICE:0)
Block(1,11,-7,PACKED_ICE:0)
Block(1,11,-6,PACKED_ICE:0)
Block(1,11,-5,PACKED_ICE:0)
Block(1,11,-4,PACKED_ICE:0)
Block(1,11,-3,PACKED_ICE:0)
Block(1,11,-2,PACKED_ICE:0)
Block(1,11,-1,PACKED_ICE:0)
Block(1,11,0,PACKED_ICE:0)
Block(1,11,1,PACKED_ICE:0)
Block(1,11,2,ICE:0)
Block(1,12,-7,PACKED_ICE:0)
Block(1,12,-6,PACKED_ICE:0)
Block(1,12,-5,PACKED_ICE:0)
Block(1,12,-4,PACKED_ICE:0)
Block(1,12,-3,PACKED_ICE:0)
Block(1,12,-2,PACKED_ICE:0)
Block(1,12,-1,PACKED_ICE:0)
Block(1,13,-7,PACKED_ICE:0)
Block(1,13,-6,PACKED_ICE:0)
Block(1,13,-5,PACKED_ICE:0)
Block(1,13,-4,PACKED_ICE:0)
Block(1,14,-7,PACKED_ICE:0)
Block(2,1,8,PACKED_ICE:0)
Block(2,2,6,PACKED_ICE:0)
Block(2,2,7,PACKED_ICE:0)
Block(2,2,8,PACKED_ICE:0)
Block(2,3,4,PACKED_ICE:0)
Block(2,3,5,PACKED_ICE:0)
Block(2,3,6,PACKED_ICE:0)
Block(2,3,7,PACKED_ICE:0)
Block(2,3,8,PACKED_ICE:0)
Block(2,4,2,PACKED_ICE:0)
Block(2,4,3,PACKED_ICE:0)
Block(2,4,4,PACKED_ICE:0)
Block(2,4,5,PACKED_ICE:0)
Block(2,4,6,PACKED_ICE:0)
Block(2,4,7,ICE:0)
Block(2,4,8,ICE:0)
Block(2,5,0,PACKED_ICE:0)
Block(2,5,1,PACKED_ICE:0)
Block(2,5,2,PACKED_ICE:0)
Block(2,5,3,PACKED_ICE:0)
Block(2,5,4,PACKED_ICE:0)
Block(2,5,5,ICE:0)
Block(2,5,6,ICE:0)
Block(2,5,7,ICE:0)
Block(2,5,8,ICE:0)
Block(2,6,-2,PACKED_ICE:0)
Block(2,6,-1,PACKED_ICE:0)
Block(2,6,0,PACKED_ICE:0)
Block(2,6,1,PACKED_ICE:0)
Block(2,6,2,PACKED_ICE:0)
Block(2,6,3,ICE:0)
Block(2,6,4,ICE:0)
Block(2,6,5,ICE:0)
Block(2,6,6,ICE:0)
Block(2,6,7,ICE:0)
Block(2,6,8,ICE:0)
Block(2,7,-4,PACKED_ICE:0)
Block(2,7,-3,PACKED_ICE:0)
Block(2,7,-2,PACKED_ICE:0)
Block(2,7,-1,PACKED_ICE:0)
Block(2,7,0,PACKED_ICE:0)
Block(2,7,1,PACKED_ICE:0)
Block(2,7,2,ICE:0)
Block(2,7,3,ICE:0)
Block(2,7,4,ICE:0)
Block(2,7,5,ICE:0)
Block(2,7,6,ICE:0)
Block(2,7,7,ICE:0)
Block(2,7,8,ICE:0)
Block(2,8,-7,PACKED_ICE:0)
Block(2,8,-6,PACKED_ICE:0)
Block(2,8,-5,PACKED_ICE:0)
Block(2,8,-4,PACKED_ICE:0)
Block(2,8,-3,PACKED_ICE:0)
Block(2,8,-2,PACKED_ICE:0)
Block(2,8,-1,PACKED_ICE:0)
Block(2,8,0,PACKED_ICE:0)
Block(2,8,1,PACKED_ICE:0)
Block(2,8,2,ICE:0)
Block(2,8,3,ICE:0)
Block(2,8,4,ICE:0)
Block(2,8,5,ICE:0)
Block(2,8,6,ICE:0)
Block(2,8,7,ICE:0)
Block(2,8,8,ICE:0)
Block(2,9,-7,PACKED_ICE:0)
Block(2,9,-6,PACKED_ICE:0)
Block(2,9,-5,PACKED_ICE:0)
Block(2,9,-4,PACKED_ICE:0)
Block(2,9,-3,PACKED_ICE:0)
Block(2,9,-2,PACKED_ICE:0)
Block(2,9,-1,PACKED_ICE:0)
Block(2,9,0,PACKED_ICE:0)
Block(2,9,1,ICE:0)
Block(2,9,2,ICE:0)
Block(2,9,3,ICE:0)
Block(2,9,4,ICE:0)
Block(2,9,5,ICE:0)
Block(2,9,6,ICE:0)
Block(2,9,7,ICE:0)
Block(2,9,8,ICE:0)
Block(2,10,-7,PACKED_ICE:0)
Block(2,10,-6,PACKED_ICE:0)
Block(2,10,-5,PACKED_ICE:0)
Block(2,10,-4,PACKED_ICE:0)
Block(2,10,-3,PACKED_ICE:0)
Block(2,10,-2,PACKED_ICE:0)
Block(2,10,-1,PACKED_ICE:0)
Block(2,10,0,PACKED_ICE:0)
Block(2,10,1,ICE:0)
Block(2,10,2,ICE:0)
Block(2,10,3,ICE:0)
Block(2,10,4,ICE:0)
Block(2,10,5,ICE:0)
Block(2,11,-7,PACKED_ICE:0)
Block(2,11,-6,PACKED_ICE:0)
Block(2,11,-5,PACKED_ICE:0)
Block(2,11,-4,PACKED_ICE:0)
Block(2,11,-3,PACKED_ICE:0)
Block(2,11,-2,PACKED_ICE:0)
Block(2,11,-1,PACKED_ICE:0)
Block(2,11,0,ICE:0)
Block(2,11,1,ICE:0)
Block(2,11,2,ICE:0)
Block(2,12,-7,PACKED_ICE:0)
Block(2,12,-6,PACKED_ICE:0)
Block(2,12,-5,PACKED_ICE:0)
Block(2,12,-4,PACKED_ICE:0)
Block(2,12,-3,PACKED_ICE:0)
Block(2,12,-2,PACKED_ICE:0)
Block(2,12,-1,PACKED_ICE:0)
Block(2,13,-7,PACKED_ICE:0)
Block(2,13,-6,PACKED_ICE:0)
Block(2,13,-5,PACKED_ICE:0)
Block(2,13,-4,PACKED_ICE:0)
Block(2,14,-7,PACKED_ICE:0)
Block(3,1,8,PACKED_ICE:0)
Block(3,2,6,PACKED_ICE:0)
Block(3,2,7,PACKED_ICE:0)
Block(3,2,8,PACKED_ICE:0)
Block(3,3,4,PACKED_ICE:0)
Block(3,3,5,PACKED_ICE:0)
Block(3,3,6,PACKED_ICE:0)
Block(3,3,7,PACKED_ICE:0)
Block(3,3,8,PACKED_ICE:0)
Block(3,4,2,PACKED_ICE:0)
Block(3,4,3,PACKED_ICE:0)
Block(3,4,4,PACKED_ICE:0)
Block(3,4,5,PACKED_ICE:0)
Block(3,4,6,PACKED_ICE:0)
Block(3,4,7,ICE:0)
Block(3,4,8,ICE:0)
Block(3,5,0,PACKED_ICE:0)
Block(3,5,1,PACKED_ICE:0)
Block(3,5,2,PACKED_ICE:0)
Block(3,5,3,PACKED_ICE:0)
Block(3,5,4,ICE:0)
Block(3,5,5,ICE:0)
Block(3,5,6,ICE:0)
Block(3,5,7,ICE:0)
Block(3,5,8,ICE:0)
Block(3,6,-2,PACKED_ICE:0)
Block(3,6,-1,PACKED_ICE:0)
Block(3,6,0,PACKED_ICE:0)
Block(3,6,1,PACKED_ICE:0)
Block(3,6,2,PACKED_ICE:0)
Block(3,6,3,ICE:0)
Block(3,6,4,ICE:0)
Block(3,6,5,ICE:0)
Block(3,6,6,ICE:0)
Block(3,6,7,ICE:0)
Block(3,6,8,ICE:0)
Block(3,7,-5,PACKED_ICE:0)
Block(3,7,-4,PACKED_ICE:0)
Block(3,7,-3,PACKED_ICE:0)
Block(3,7,-2,PACKED_ICE:0)
Block(3,7,-1,PACKED_ICE:0)
Block(3,7,0,PACKED_ICE:0)
Block(3,7,1,PACKED_ICE:0)
Block(3,7,2,ICE:0)
Block(3,7,3,ICE:0)
Block(3,7,4,ICE:0)
Block(3,7,5,ICE:0)
Block(3,7,6,ICE:0)
Block(3,7,7,ICE:0)
Block(3,7,8,ICE:0)
Block(3,8,-7,PACKED_ICE:0)
Block(3,8,-6,PACKED_ICE:0)
Block(3,8,-5,PACKED_ICE:0)
Block(3,8,-4,PACKED_ICE:0)
Block(3,8,-3,PACKED_ICE:0)
Block(3,8,-2,PACKED_ICE:0)
Block(3,8,-1,PACKED_ICE:0)
Block(3,8,0,PACKED_ICE:0)
Block(3,8,1,ICE:0)
Block(3,8,2,ICE:0)
Block(3,8,3,ICE:0)
Block(3,8,4,ICE:0)
Block(3,8,5,ICE:0)
Block(3,8,6,ICE:0)
Block(3,8,7,ICE:0)
Block(3,8,8,ICE:0)
Block(3,9,-7,PACKED_ICE:0)
Block(3,9,-6,PACKED_ICE:0)
Block(3,9,-5,PACKED_ICE:0)
Block(3,9,-4,PACKED_ICE:0)
Block(3,9,-3,PACKED_ICE:0)
Block(3,9,-2,PACKED_ICE:0)
Block(3,9,-1,PACKED_ICE:0)
Block(3,9,0,ICE:0)
Block(3,9,1,ICE:0)
Block(3,9,2,ICE:0)
Block(3,9,3,ICE:0)
Block(3,9,4,ICE:0)
Block(3,9,5,ICE:0)
Block(3,9,6,ICE:0)
Block(3,9,7,ICE:0)
Block(3,9,8,ICE:0)
Block(3,10,-7,PACKED_ICE:0)
Block(3,10,-6,PACKED_ICE:0)
Block(3,10,-5,PACKED_ICE:0)
Block(3,10,-4,PACKED_ICE:0)
Block(3,10,-3,PACKED_ICE:0)
Block(3,10,-2,PACKED_ICE:0)
Block(3,10,-1,ICE:0)
Block(3,10,0,ICE:0)
Block(3,10,1,ICE:0)
Block(3,10,2,ICE:0)
Block(3,10,3,ICE:0)
Block(3,10,4,ICE:0)
Block(3,10,5,ICE:0)
Block(3,10,6,ICE:0)
Block(3,11,-7,PACKED_ICE:0)
Block(3,11,-6,PACKED_ICE:0)
Block(3,11,-5,PACKED_ICE:0)
Block(3,11,-4,PACKED_ICE:0)
Block(3,11,-3,PACKED_ICE:0)
Block(3,11,-2,PACKED_ICE:0)
Block(3,11,-1,ICE:0)
Block(3,11,0,ICE:0)
Block(3,11,1,ICE:0)
Block(3,11,2,ICE:0)
Block(3,11,3,ICE:0)
Block(3,12,-7,PACKED_ICE:0)
Block(3,12,-6,PACKED_ICE:0)
Block(3,12,-5,PACKED_ICE:0)
Block(3,12,-4,PACKED_ICE:0)
Block(3,12,-3,PACKED_ICE:0)
Block(3,12,-2,PACKED_ICE:0)
Block(3,12,-1,ICE:0)
Block(3,12,0,ICE:0)
Block(3,13,-7,PACKED_ICE:0)
Block(3,13,-6,PACKED_ICE:0)
Block(3,13,-5,PACKED_ICE:0)
Block(3,13,-4,PACKED_ICE:0)
Block(3,13,-3,PACKED_ICE:0)
Block(3,14,-7,PACKED_ICE:0)
Block(3,14,-6,PACKED_ICE:0)
Block(4,1,8,PACKED_ICE:0)
Block(4,2,6,PACKED_ICE:0)
Block(4,2,7,PACKED_ICE:0)
Block(4,2,8,PACKED_ICE:0)
Block(4,3,4,PACKED_ICE:0)
Block(4,3,5,PACKED_ICE:0)
Block(4,3,6,PACKED_ICE:0)
Block(4,3,7,PACKED_ICE:0)
Block(4,3,8,PACKED_ICE:0)
Block(4,4,2,PACKED_ICE:0)
Block(4,4,3,PACKED_ICE:0)
Block(4,4,4,PACKED_ICE:0)
Block(4,4,5,PACKED_ICE:0)
Block(4,4,6,PACKED_ICE:0)
Block(4,4,7,ICE:0)
Block(4,4,8,ICE:0)
Block(4,5,0,PACKED_ICE:0)
Block(4,5,1,PACKED_ICE:0)
Block(4,5,2,PACKED_ICE:0)
Block(4,5,3,PACKED_ICE:0)
Block(4,5,4,ICE:0)
Block(4,5,5,ICE:0)
Block(4,5,6,ICE:0)
Block(4,5,7,ICE:0)
Block(4,5,8,ICE:0)
Block(4,6,-3,PACKED_ICE:0)
Block(4,6,-2,PACKED_ICE:0)
Block(4,6,-1,PACKED_ICE:0)
Block(4,6,0,PACKED_ICE:0)
Block(4,6,1,PACKED_ICE:0)
Block(4,6,2,PACKED_ICE:0)
Block(4,6,3,ICE:0)
Block(4,6,4,ICE:0)
Block(4,6,5,ICE:0)
Block(4,6,6,ICE:0)
Block(4,6,7,ICE:0)
Block(4,6,8,ICE:0)
Block(4,7,-5,PACKED_ICE:0)
Block(4,7,-4,PACKED_ICE:0)
Block(4,7,-3,PACKED_ICE:0)
Block(4,7,-2,PACKED_ICE:0)
Block(4,7,-1,PACKED_ICE:0)
Block(4,7,0,PACKED_ICE:0)
Block(4,7,1,PACKED_ICE:0)
Block(4,7,2,ICE:0)
Block(4,7,3,ICE:0)
Block(4,7,4,ICE:0)
Block(4,7,5,ICE:0)
Block(4,7,6,ICE:0)
Block(4,7,7,ICE:0)
Block(4,7,8,ICE:0)
Block(4,8,-7,PACKED_ICE:0)
Block(4,8,-6,PACKED_ICE:0)
Block(4,8,-5,PACKED_ICE:0)
Block(4,8,-4,PACKED_ICE:0)
Block(4,8,-3,PACKED_ICE:0)
Block(4,8,-2,PACKED_ICE:0)
Block(4,8,-1,PACKED_ICE:0)
Block(4,8,0,ICE:0)
Block(4,8,1,ICE:0)
Block(4,8,2,ICE:0)
Block(4,8,3,ICE:0)
Block(4,8,4,ICE:0)
Block(4,8,5,ICE:0)
Block(4,8,6,ICE:0)
Block(4,8,7,ICE:0)
Block(4,8,8,ICE:0)
Block(4,9,-7,PACKED_ICE:0)
Block(4,9,-6,PACKED_ICE:0)
Block(4,9,-5,PACKED_ICE:0)
Block(4,9,-4,PACKED_ICE:0)
Block(4,9,-3,PACKED_ICE:0)
Block(4,9,-2,PACKED_ICE:0)
Block(4,9,-1,ICE:0)
Block(4,9,0,ICE:0)
Block(4,9,1,ICE:0)
Block(4,9,2,ICE:0)
Block(4,9,3,ICE:0)
Block(4,9,4,ICE:0)
Block(4,9,5,ICE:0)
Block(4,9,6,ICE:0)
Block(4,9,7,ICE:0)
Block(4,9,8,ICE:0)
Block(4,10,-7,PACKED_ICE:0)
Block(4,10,-6,PACKED_ICE:0)
Block(4,10,-5,PACKED_ICE:0)
Block(4,10,-4,PACKED_ICE:0)
Block(4,10,-3,PACKED_ICE:0)
Block(4,10,-2,ICE:0)
Block(4,10,-1,ICE:0)
Block(4,10,0,ICE:0)
Block(4,10,1,ICE:0)
Block(4,10,2,ICE:0)
Block(4,10,3,ICE:0)
Block(4,10,4,ICE:0)
Block(4,10,5,ICE:0)
Block(4,10,6,ICE:0)
Block(4,11,-7,PACKED_ICE:0)
Block(4,11,-6,PACKED_ICE:0)
Block(4,11,-5,PACKED_ICE:0)
Block(4,11,-4,PACKED_ICE:0)
Block(4,11,-3,ICE:0)
Block(4,11,-2,ICE:0)
Block(4,11,-1,ICE:0)
Block(4,11,0,ICE:0)
Block(4,11,1,ICE:0)
Block(4,11,2,ICE:0)
Block(4,11,3,ICE:0)
Block(4,12,-7,PACKED_ICE:0)
Block(4,12,-6,PACKED_ICE:0)
Block(4,12,-5,PACKED_ICE:0)
Block(4,12,-4,ICE:0)
Block(4,12,-3,ICE:0)
Block(4,12,-2,ICE:0)
Block(4,12,-1,ICE:0)
Block(4,12,0,ICE:0)
Block(4,13,-7,PACKED_ICE:0)
Block(4,13,-6,PACKED_ICE:0)
Block(4,13,-5,PACKED_ICE:0)
Block(4,13,-4,ICE:0)
Block(4,13,-3,ICE:0)
Block(4,14,-7,PACKED_ICE:0)
Block(4,14,-6,PACKED_ICE:0)
Block(5,1,8,PACKED_ICE:0)
Block(5,2,6,PACKED_ICE:0)
Block(5,2,7,PACKED_ICE:0)
Block(5,2,8,PACKED_ICE:0)
Block(5,3,4,PACKED_ICE:0)
Block(5,3,5,PACKED_ICE:0)
Block(5,3,6,PACKED_ICE:0)
Block(5,3,7,PACKED_ICE:0)
Block(5,3,8,PACKED_ICE:0)
Block(5,4,1,PACKED_ICE:0)
Block(5,4,2,PACKED_ICE:0)
Block(5,4,3,PACKED_ICE:0)
Block(5,4,4,PACKED_ICE:0)
Block(5,4,5,PACKED_ICE:0)
Block(5,4,6,PACKED_ICE:0)
Block(5,4,7,PACKED_ICE:0)
Block(5,4,8,ICE:0)
Block(5,5,-1,PACKED_ICE:0)
Block(5,5,0,PACKED_ICE:0)
Block(5,5,1,PACKED_ICE:0)
Block(5,5,2,PACKED_ICE:0)
Block(5,5,3,PACKED_ICE:0)
Block(5,5,4,ICE:0)
Block(5,5,5,ICE:0)
Block(5,5,6,ICE:0)
Block(5,5,7,ICE:0)
Block(5,5,8,ICE:0)
Block(5,6,-3,PACKED_ICE:0)
Block(5,6,-2,PACKED_ICE:0)
Block(5,6,-1,PACKED_ICE:0)
Block(5,6,0,PACKED_ICE:0)
Block(5,6,1,PACKED_ICE:0)
Block(5,6,2,PACKED_ICE:0)
Block(5,6,3,ICE:0)
Block(5,6,4,ICE:0)
Block(5,6,5,ICE:0)
Block(5,6,6,ICE:0)
Block(5,6,7,ICE:0)
Block(5,6,8,ICE:0)
Block(5,7,-5,PACKED_ICE:0)
Block(5,7,-4,PACKED_ICE:0)
Block(5,7,-3,PACKED_ICE:0)
Block(5,7,-2,PACKED_ICE:0)
Block(5,7,-1,PACKED_ICE:0)
Block(5,7,0,PACKED_ICE:0)
Block(5,7,1,ICE:0)
Block(5,7,2,ICE:0)
Block(5,7,3,ICE:0)
Block(5,7,4,ICE:0)
Block(5,7,5,ICE:0)
Block(5,7,6,ICE:0)
Block(5,7,7,ICE:0)
Block(5,7,8,ICE:0)
Block(5,8,-7,PACKED_ICE:0)
Block(5,8,-6,PACKED_ICE:0)
Block(5,8,-5,PACKED_ICE:0)
Block(5,8,-4,PACKED_ICE:0)
Block(5,8,-3,PACKED_ICE:0)
Block(5,8,-2,PACKED_ICE:0)
Block(5,8,-1,ICE:0)
Block(5,8,0,ICE:0)
Block(5,8,1,ICE:0)
Block(5,8,2,ICE:0)
Block(5,8,3,ICE:0)
Block(5,8,4,ICE:0)
Block(5,8,5,ICE:0)
Block(5,8,6,ICE:0)
Block(5,8,7,ICE:0)
Block(5,8,8,ICE:0)
Block(5,9,-7,PACKED_ICE:0)
Block(5,9,-6,PACKED_ICE:0)
Block(5,9,-5,PACKED_ICE:0)
Block(5,9,-4,PACKED_ICE:0)
Block(5,9,-3,PACKED_ICE:0)
Block(5,9,-2,ICE:0)
Block(5,9,-1,ICE:0)
Block(5,9,0,ICE:0)
Block(5,9,1,ICE:0)
Block(5,9,2,ICE:0)
Block(5,9,3,ICE:0)
Block(5,9,4,ICE:0)
Block(5,9,5,ICE:0)
Block(5,9,6,ICE:0)
Block(5,9,7,ICE:0)
Block(5,9,8,ICE:0)
Block(5,10,-7,PACKED_ICE:0)
Block(5,10,-6,PACKED_ICE:0)
Block(5,10,-5,PACKED_ICE:0)
Block(5,10,-4,ICE:0)
Block(5,10,-3,ICE:0)
Block(5,10,-2,ICE:0)
Block(5,10,-1,ICE:0)
Block(5,10,0,ICE:0)
Block(5,10,1,ICE:0)
Block(5,10,2,ICE:0)
Block(5,10,3,ICE:0)
Block(5,10,4,ICE:0)
Block(5,10,5,ICE:0)
Block(5,10,6,ICE:0)
Block(5,10,7,ICE:0)
Block(5,11,-7,PACKED_ICE:0)
Block(5,11,-6,PACKED_ICE:0)
Block(5,11,-5,ICE:0)
Block(5,11,-4,ICE:0)
Block(5,11,-3,ICE:0)
Block(5,11,-2,ICE:0)
Block(5,11,-1,ICE:0)
Block(5,11,0,ICE:0)
Block(5,11,1,ICE:0)
Block(5,11,2,ICE:0)
Block(5,11,3,ICE:0)
Block(5,11,4,ICE:0)
Block(5,12,-7,PACKED_ICE:0)
Block(5,12,-6,PACKED_ICE:0)
Block(5,12,-5,ICE:0)
Block(5,12,-4,ICE:0)
Block(5,12,-3,ICE:0)
Block(5,12,-2,ICE:0)
Block(5,12,-1,ICE:0)
Block(5,12,0,ICE:0)
Block(5,12,1,ICE:0)
Block(5,13,-7,PACKED_ICE:0)
Block(5,13,-6,PACKED_ICE:0)
Block(5,13,-5,ICE:0)
Block(5,13,-4,ICE:0)
Block(5,13,-3,ICE:0)
Block(5,13,-2,ICE:0)
Block(5,14,-7,PACKED_ICE:0)
Block(5,14,-6,PACKED_ICE:0)
Block(5,14,-5,ICE:0)
Block(6,1,8,PACKED_ICE:0)
Block(6,2,6,PACKED_ICE:0)
Block(6,2,7,PACKED_ICE:0)
Block(6,2,8,PACKED_ICE:0)
Block(6,3,3,PACKED_ICE:0)
Block(6,3,4,PACKED_ICE:0)
Block(6,3,5,PACKED_ICE:0)
Block(6,3,6,PACKED_ICE:0)
Block(6,3,7,PACKED_ICE:0)
Block(6,3,8,PACKED_ICE:0)
Block(6,4,1,PACKED_ICE:0)
Block(6,4,2,PACKED_ICE:0)
Block(6,4,3,PACKED_ICE:0)
Block(6,4,4,PACKED_ICE:0)
Block(6,4,5,PACKED_ICE:0)
Block(6,4,6,PACKED_ICE:0)
Block(6,4,7,PACKED_ICE:0)
Block(6,4,8,PACKED_ICE:0)
Block(6,5,-1,PACKED_ICE:0)
Block(6,5,0,PACKED_ICE:0)
Block(6,5,1,PACKED_ICE:0)
Block(6,5,2,PACKED_ICE:0)
Block(6,5,3,PACKED_ICE:0)
Block(6,5,4,PACKED_ICE:0)
Block(6,5,5,ICE:0)
Block(6,5,6,ICE:0)
Block(6,5,7,ICE:0)
Block(6,5,8,ICE:0)
Block(6,6,-3,PACKED_ICE:0)
Block(6,6,-2,PACKED_ICE:0)
Block(6,6,-1,PACKED_ICE:0)
Block(6,6,0,PACKED_ICE:0)
Block(6,6,1,PACKED_ICE:0)
Block(6,6,2,PACKED_ICE:0)
Block(6,6,3,ICE:0)
Block(6,6,4,ICE:0)
Block(6,6,5,ICE:0)
Block(6,6,6,ICE:0)
Block(6,6,7,ICE:0)
Block(6,6,8,ICE:0)
Block(6,7,-5,PACKED_ICE:0)
Block(6,7,-4,PACKED_ICE:0)
Block(6,7,-3,PACKED_ICE:0)
Block(6,7,-2,PACKED_ICE:0)
Block(6,7,-1,PACKED_ICE:0)
Block(6,7,0,ICE:0)
Block(6,7,1,ICE:0)
Block(6,7,2,ICE:0)
Block(6,7,3,ICE:0)
Block(6,7,4,ICE:0)
Block(6,7,5,ICE:0)
Block(6,7,6,ICE:0)
Block(6,7,7,ICE:0)
Block(6,7,8,ICE:0)
Block(6,8,-7,PACKED_ICE:0)
Block(6,8,-6,PACKED_ICE:0)
Block(6,8,-5,PACKED_ICE:0)
Block(6,8,-4,PACKED_ICE:0)
Block(6,8,-3,PACKED_ICE:0)
Block(6,8,-2,PACKED_ICE:0)
Block(6,8,-1,ICE:0)
Block(6,8,0,ICE:0)
Block(6,8,1,ICE:0)
Block(6,8,2,ICE:0)
Block(6,8,3,ICE:0)
Block(6,8,4,ICE:0)
Block(6,8,5,ICE:0)
Block(6,8,6,ICE:0)
Block(6,8,7,ICE:0)
Block(6,8,8,ICE:0)
Block(6,9,-7,PACKED_ICE:0)
Block(6,9,-6,PACKED_ICE:0)
Block(6,9,-5,PACKED_ICE:0)
Block(6,9,-4,ICE:0)
Block(6,9,-3,ICE:0)
Block(6,9,-2,ICE:0)
Block(6,9,-1,ICE:0)
Block(6,9,0,ICE:0)
Block(6,9,1,ICE:0)
Block(6,9,2,ICE:0)
Block(6,9,3,ICE:0)
Block(6,9,4,ICE:0)
Block(6,9,5,ICE:0)
Block(6,9,6,ICE:0)
Block(6,9,7,ICE:0)
Block(6,9,8,ICE:0)
Block(6,10,-7,PACKED_ICE:0)
Block(6,10,-6,PACKED_ICE:0)
Block(6,10,-5,ICE:0)
Block(6,10,-4,ICE:0)
Block(6,10,-3,ICE:0)
Block(6,10,-2,ICE:0)
Block(6,10,-1,ICE:0)
Block(6,10,0,ICE:0)
Block(6,10,1,ICE:0)
Block(6,10,2,ICE:0)
Block(6,10,3,ICE:0)
Block(6,10,4,ICE:0)
Block(6,10,5,ICE:0)
Block(6,10,6,ICE:0)
Block(6,10,7,ICE:0)
Block(6,11,-7,PACKED_ICE:0)
Block(6,11,-6,ICE:0)
Block(6,11,-5,ICE:0)
Block(6,11,-4,ICE:0)
Block(6,11,-3,ICE:0)
Block(6,11,-2,ICE:0)
Block(6,11,-1,ICE:0)
Block(6,11,0,ICE:0)
Block(6,11,1,ICE:0)
Block(6,11,2,ICE:0)
Block(6,11,3,ICE:0)
Block(6,11,4,ICE:0)
Block(6,12,-7,PACKED_ICE:0)
Block(6,12,-6,ICE:0)
Block(6,12,-5,ICE:0)
Block(6,12,-4,ICE:0)
Block(6,12,-3,ICE:0)
Block(6,12,-2,ICE:0)
Block(6,12,-1,ICE:0)
Block(6,12,0,ICE:0)
Block(6,12,1,ICE:0)
Block(6,13,-7,ICE:0)
Block(6,13,-6,ICE:0)
Block(6,13,-5,ICE:0)
Block(6,13,-4,ICE:0)
Block(6,13,-3,ICE:0)
Block(6,13,-2,ICE:0)
Block(6,14,-7,ICE:0)
Block(6,14,-6,ICE:0)
Block(6,14,-5,ICE:0)
Block(6,14,-4,ICE:0)
Block(6,15,-7,ICE:0)
Block(7,1,8,PACKED_ICE:0)
Block(7,2,5,PACKED_ICE:0)
Block(7,2,6,PACKED_ICE:0)
Block(7,2,7,PACKED_ICE:0)
Block(7,2,8,PACKED_ICE:0)
Block(7,3,3,PACKED_ICE:0)
Block(7,3,4,PACKED_ICE:0)
Block(7,3,5,PACKED_ICE:0)
Block(7,3,6,PACKED_ICE:0)
Block(7,3,7,PACKED_ICE:0)
Block(7,3,8,PACKED_ICE:0)
Block(7,4,1,PACKED_ICE:0)
Block(7,4,2,PACKED_ICE:0)
Block(7,4,3,PACKED_ICE:0)
Block(7,4,4,PACKED_ICE:0)
Block(7,4,5,PACKED_ICE:0)
Block(7,4,6,PACKED_ICE:0)
Block(7,4,7,PACKED_ICE:0)
Block(7,4,8,PACKED_ICE:0)
Block(7,5,-1,PACKED_ICE:0)
Block(7,5,0,PACKED_ICE:0)
Block(7,5,1,PACKED_ICE:0)
Block(7,5,2,PACKED_ICE:0)
Block(7,5,3,PACKED_ICE:0)
Block(7,5,4,PACKED_ICE:0)
Block(7,5,5,PACKED_ICE:0)
Block(7,5,6,PACKED_ICE:0)
Block(7,5,7,PACKED_ICE:0)
Block(7,5,8,PACKED_ICE:0)
Block(7,6,-3,PACKED_ICE:0)
Block(7,6,-2,PACKED_ICE:0)
Block(7,6,-1,PACKED_ICE:0)
Block(7,6,0,PACKED_ICE:0)
Block(7,6,1,PACKED_ICE:0)
Block(7,6,2,PACKED_ICE:0)
Block(7,6,3,PACKED_ICE:0)
Block(7,6,4,ICE:0)
Block(7,6,5,ICE:0)
Block(7,6,6,ICE:0)
Block(7,6,7,ICE:0)
Block(7,6,8,ICE:0)
Block(7,7,-5,PACKED_ICE:0)
Block(7,7,-4,PACKED_ICE:0)
Block(7,7,-3,PACKED_ICE:0)
Block(7,7,-2,PACKED_ICE:0)
Block(7,7,-1,PACKED_ICE:0)
Block(7,7,0,ICE:0)
Block(7,7,1,ICE:0)
Block(7,7,2,ICE:0)
Block(7,7,3,ICE:0)
Block(7,7,4,ICE:0)
Block(7,7,5,ICE:0)
Block(7,7,6,ICE:0)
Block(7,7,7,ICE:0)
Block(7,7,8,ICE:0)
Block(7,8,-7,PACKED_ICE:0)
Block(7,8,-6,PACKED_ICE:0)
Block(7,8,-5,PACKED_ICE:0)
Block(7,8,-4,PACKED_ICE:0)
Block(7,8,-3,ICE:0)
Block(7,8,-2,ICE:0)
Block(7,8,-1,ICE:0)
Block(7,8,0,ICE:0)
Block(7,8,1,ICE:0)
Block(7,8,2,ICE:0)
Block(7,8,3,ICE:0)
Block(7,8,4,ICE:0)
Block(7,8,5,ICE:0)
Block(7,8,6,ICE:0)
Block(7,8,7,ICE:0)
Block(7,8,8,ICE:0)
Block(7,9,-7,PACKED_ICE:0)
Block(7,9,-6,PACKED_ICE:0)
Block(7,9,-5,ICE:0)
Block(7,9,-4,ICE:0)
Block(7,9,-3,ICE:0)
Block(7,9,-2,ICE:0)
Block(7,9,-1,ICE:0)
Block(7,9,0,ICE:0)
Block(7,9,1,ICE:0)
Block(7,9,2,ICE:0)
Block(7,9,3,ICE:0)
Block(7,9,4,ICE:0)
Block(7,9,5,ICE:0)
Block(7,9,6,ICE:0)
Block(7,9,7,ICE:0)
Block(7,9,8,ICE:0)
Block(7,10,-7,PACKED_ICE:0)
Block(7,10,-6,ICE:0)
Block(7,10,-5,ICE:0)
Block(7,10,-4,ICE:0)
Block(7,10,-3,ICE:0)
Block(7,10,-2,ICE:0)
Block(7,10,-1,ICE:0)
Block(7,10,0,ICE:0)
Block(7,10,1,ICE:0)
Block(7,10,2,ICE:0)
Block(7,10,3,ICE:0)
Block(7,10,4,ICE:0)
Block(7,10,5,ICE:0)
Block(7,10,6,ICE:0)
Block(7,10,7,ICE:0)
Block(7,10,8,ICE:0)
Block(7,11,-7,ICE:0)
Block(7,11,-6,ICE:0)
Block(7,11,-5,ICE:0)
Block(7,11,-4,ICE:0)
Block(7,11,-3,ICE:0)
Block(7,11,-2,ICE:0)
Block(7,11,-1,ICE:0)
Block(7,11,0,ICE:0)
Block(7,11,1,ICE:0)
Block(7,11,2,ICE:0)
Block(7,11,3,ICE:0)
Block(7,11,4,ICE:0)
Block(7,11,5,ICE:0)
Block(7,12,-7,ICE:0)
Block(7,12,-6,ICE:0)
Block(7,12,-5,ICE:0)
Block(7,12,-4,ICE:0)
Block(7,12,-3,ICE:0)
Block(7,12,-2,ICE:0)
Block(7,12,-1,ICE:0)
Block(7,12,0,ICE:0)
Block(7,12,1,ICE:0)
Block(7,12,2,ICE:0)
Block(7,13,-7,ICE:0)
Block(7,13,-6,ICE:0)
Block(7,13,-5,ICE:0)
Block(7,13,-4,ICE:0)
Block(7,13,-3,ICE:0)
Block(7,13,-2,ICE:0)
Block(7,13,-1,ICE:0)
Block(7,14,-7,ICE:0)
Block(7,14,-6,ICE:0)
Block(7,14,-5,ICE:0)
Block(7,14,-4,ICE:0)
Block(7,15,-7,ICE:0)

#######################################################################
# +-----------------------------------------------------------------+ #
# |                             Branches                            | #
# +-----------------------------------------------------------------+ #
#######################################################################

Branch(0,0,-16,true,IceSpike_Huge_05C0R2,NORTH,100.0,0)

#######################################################################
# +-----------------------------------------------------------------+ #
# |                             Entities                            | #
# +-----------------------------------------------------------------+ #
#######################################################################


#######################################################################
# +-----------------------------------------------------------------+ #
# |                            Particles                            | #
# +-----------------------------------------------------------------+ #
#######################################################################


#######################################################################
# +-----------------------------------------------------------------+ #
# |                             Spawners                            | #
# +-----------------------------------------------------------------+ #
#######################################################################


#######################################################################
# +-----------------------------------------------------------------+ #
# |                             ModData                             | #
# +-----------------------------------------------------------------+ #
#######################################################################

