Author: BO3 BulkEdit (by LanToaster)
Description: This Object was Created with BO3_BulkEdit
SettingsMode: WriteDisable
Frequency: 100
SpawnHeight: highestBlock
UseCenterForHighestBlock: true
MinHeight: 0
MaxHeight: 255
InheritBO3: 
InheritBO3Rotation: NORTH
OverrideChildSettings: true
OverrideParentHeight: false
CanOverride: true
BranchFrequency: 0
BranchFrequencyGroup: 
MustBeBelowOther: false
MustBeInside: 
CannotBeInside: 
ReplacesBO3: 
MustBeInsideWorldBorders: false
CanSpawnOnWater: false
SpawnOnWaterOnly: false
SpawnUnderWater: false
SpawnAtWaterLevel: false
HeightOffset: 0
RemoveAir: true
ReplaceAbove: 
ReplaceBelow: cobblestone
ReplaceWithBiomeBlocks: true
ReplaceWithSurfaceBlock: GRASS
ReplaceWithGroundBlock: DIRT
ReplaceWithStoneBlock: STONE
SmoothRadius: 0
SmoothHeightOffset: 0
SmoothStartTop: false
SmoothStartWood: false
SmoothingSurfaceBlock: 
SmoothingGroundBlock: 
BO3Group: 
IsSpawnPoint: false
DoReplaceBlocks: true
Block(-4,-1,-6,GRASS_PATH:0)
Block(-3,-1,-6,GRASS_PATH:0)
Block(-5,-1,-5,GRASS_PATH:0)
Block(-4,-1,-5,LOG_2:0)
Block(-3,-1,-5,GRASS_PATH:0)
Block(-2,-1,-5,GRASS_PATH:0)
Block(-1,-1,-5,LOG_2:0)
Block(2,-1,-5,LOG_2:0)
Block(-6,-1,-4,GRASS_PATH:0)
Block(-5,-1,-4,GRASS_PATH:0)
Block(-4,-1,-4,GRASS_PATH:0)
Block(-3,-1,-4,DIRT:0)
Block(-6,-1,-3,GRASS_PATH:0)
Block(-5,-1,-3,GRASS_PATH:0)
Block(-4,-1,-3,LOG_2:0)
Block(-3,-1,-3,GRASS_PATH:0)
Block(-2,-1,-3,GRASS_PATH:0)
Block(-1,-1,-3,LOG_2:0)
Block(2,-1,-3,LOG_2:0)
Block(-5,-1,-2,GRASS_PATH:0)
Block(-4,-1,-2,GRASS_PATH:0)
Block(-3,-1,-2,GRASS_PATH:0)
Block(-5,-1,-1,GRASS_PATH:0)
Block(-4,-1,-1,GRASS_PATH:0)
Block(-5,-1,0,GRASS_PATH:0)
Block(-4,-1,0,GRASS_PATH:0)
Block(-1,-1,0,LOG_2:0)
Block(1,-1,0,GRASS:0)
Block(2,-1,0,LOG_2:0)
Block(-6,-1,1,GRASS_PATH:0)
Block(-5,-1,1,GRASS_PATH:0)
Block(-1,-1,1,GRASS:0)
Block(0,-1,1,GRASS:0)
Block(1,-1,1,GRASS:0)
Block(2,-1,1,GRASS:0)
Block(-6,-1,2,GRASS_PATH:0)
Block(-3,-1,2,LOG_2:0)
Block(-2,-1,2,GRASS:0)
Block(-1,-1,2,GRASS:0)
Block(0,-1,2,GRASS:0)
Block(1,-1,2,GRASS:0)
Block(2,-1,2,GRASS:0)
Block(3,-1,2,GRASS:0)
Block(4,-1,2,LOG_2:0)
Block(-6,-1,3,GRASS_PATH:0)
Block(-5,-1,3,GRASS_PATH:0)
Block(-1,-1,3,GRASS:0)
Block(0,-1,3,GRASS:0)
Block(1,-1,3,GRASS:0)
Block(2,-1,3,GRASS:0)
Block(3,-1,3,GRASS:0)
Block(4,-1,3,GRASS:0)
Block(-6,-1,4,GRASS_PATH:0)
Block(-5,-1,4,GRASS_PATH:0)
Block(-1,-1,4,GRASS:0)
Block(0,-1,4,GRASS:0)
Block(1,-1,4,GRASS:0)
Block(2,-1,4,GRASS:0)
Block(3,-1,4,GRASS:0)
Block(4,-1,4,GRASS:0)
Block(-5,-1,5,GRASS_PATH:0)
Block(-3,-1,5,LOG_2:0)
Block(-2,-1,5,GRASS:0)
Block(-1,-1,5,GRASS:0)
Block(0,-1,5,GRASS:0)
Block(1,-1,5,GRASS:0)
Block(2,-1,5,GRASS:0)
Block(3,-1,5,GRASS:0)
Block(4,-1,5,LOG_2:0)
Block(-1,-1,6,GRASS:0)
Block(0,-1,6,GRASS:0)
Block(1,-1,6,GRASS:0)
Block(2,-1,6,GRASS:0)
Block(-1,-1,7,LOG_2:0)
Block(1,-1,7,GRASS:0)
Block(2,-1,7,LOG_2:0)
Block(-4,0,-5,ACACIA_FENCE:0)
Block(-1,0,-5,LOG_2:0)
Block(2,0,-5,LOG_2:0)
Block(-3,0,-4,BIRCH_WOOD_STAIRS:0)
Block(-2,0,-4,BIRCH_WOOD_STAIRS:5)
Block(-4,0,-3,ACACIA_FENCE:0)
Block(-1,0,-3,LOG_2:0)
Block(2,0,-3,LOG_2:0)
Block(-1,0,0,LOG_2:0)
Block(2,0,0,LOG_2:0)
Block(-1,0,1,ACACIA_FENCE:0)
Block(2,0,1,ACACIA_FENCE:0)
Block(-3,0,2,LOG_2:0)
Block(-2,0,2,ACACIA_FENCE:0)
Block(3,0,2,ACACIA_FENCE:0)
Block(4,0,2,LOG_2:0)
Block(-3,0,5,LOG_2:0)
Block(-2,0,5,ACACIA_FENCE:0)
Block(3,0,5,ACACIA_FENCE:0)
Block(4,0,5,LOG_2:0)
Block(-1,0,6,ACACIA_FENCE:0)
Block(2,0,6,ACACIA_FENCE:0)
Block(-1,0,7,LOG_2:0)
Block(2,0,7,LOG_2:0)
Block(-4,1,-5,TORCH:5)
Block(-1,1,-5,LOG_2:0)
Block(0,1,-5,WOOD_STEP:12)
Block(1,1,-5,WOOD_STEP:12)
Block(2,1,-5,LOG_2:0)
Block(-2,1,-4,BIRCH_WOOD_STAIRS:0)
Block(-1,1,-4,WOOD_STEP:12)
Block(0,1,-4,WOOD_STEP:12)
Block(1,1,-4,WOOD_STEP:12)
Block(2,1,-4,WOOD_STEP:12)
Block(-4,1,-3,TORCH:5)
Block(-1,1,-3,LOG_2:0)
Block(0,1,-3,WOOD_STEP:12)
Block(1,1,-3,WOOD_STEP:12)
Block(2,1,-3,LOG_2:0)
Block(-1,1,-2,BIRCH_WOOD_STAIRS:7)
Block(0,1,-2,WOOD_STEP:12)
Block(1,1,-2,WOOD_STEP:12)
Block(2,1,-2,BIRCH_WOOD_STAIRS:7)
Block(-1,1,-1,BIRCH_WOOD_STAIRS:6)
Block(0,1,-1,WOOD_STEP:12)
Block(1,1,-1,WOOD_STEP:12)
Block(2,1,-1,BIRCH_WOOD_STAIRS:6)
Block(-1,1,0,LOG_2:0)
Block(0,1,0,LOG_2:4)
Block(1,1,0,LOG_2:4)
Block(2,1,0,LOG_2:0)
Block(-3,1,1,STONE_BUTTON:4)
Block(-1,1,1,ACACIA_FENCE:0)
Block(0,1,1,WOOD_STEP:12)
Block(1,1,1,WOOD_STEP:12)
Block(2,1,1,ACACIA_FENCE:0)
Block(4,1,1,STONE_BUTTON:4)
Block(-3,1,2,LOG_2:0)
Block(-2,1,2,ACACIA_FENCE:0)
Block(-1,1,2,WOOD_STEP:12)
Block(0,1,2,WOOD_STEP:12)
Block(1,1,2,WOOD_STEP:12)
Block(2,1,2,WOOD_STEP:12)
Block(3,1,2,ACACIA_FENCE:0)
Block(4,1,2,LOG_2:0)
Block(-3,1,3,LOG_2:8)
Block(-2,1,3,WOOD_STEP:12)
Block(-1,1,3,WOOD_STEP:12)
Block(0,1,3,WOOD_STEP:12)
Block(1,1,3,WOOD_STEP:12)
Block(2,1,3,WOOD_STEP:12)
Block(3,1,3,WOOD_STEP:12)
Block(4,1,3,LOG_2:8)
Block(-3,1,4,LOG_2:8)
Block(-2,1,4,WOOD_STEP:12)
Block(-1,1,4,WOOD_STEP:12)
Block(0,1,4,WOOD_STEP:12)
Block(1,1,4,WOOD_STEP:12)
Block(2,1,4,WOOD_STEP:12)
Block(3,1,4,WOOD_STEP:12)
Block(4,1,4,LOG_2:8)
Block(-3,1,5,LOG_2:0)
Block(-2,1,5,ACACIA_FENCE:0)
Block(-1,1,5,WOOD_STEP:12)
Block(0,1,5,WOOD_STEP:12)
Block(1,1,5,WOOD_STEP:12)
Block(2,1,5,WOOD_STEP:12)
Block(3,1,5,ACACIA_FENCE:0)
Block(4,1,5,LOG_2:0)
Block(-3,1,6,STONE_BUTTON:3)
Block(-1,1,6,ACACIA_FENCE:0)
Block(0,1,6,WOOD_STEP:12)
Block(1,1,6,WOOD_STEP:12)
Block(2,1,6,ACACIA_FENCE:0)
Block(4,1,6,STONE_BUTTON:3)
Block(-2,1,7,STONE_BUTTON:2)
Block(-1,1,7,LOG_2:0)
Block(0,1,7,LOG_2:4)
Block(1,1,7,LOG_2:4)
Block(2,1,7,LOG_2:0)
Block(-1,2,-5,LOG_2:0)
Block(0,2,-5,ACACIA_FENCE:0)
Block(1,2,-5,ACACIA_FENCE:0)
Block(2,2,-5,LOG_2:0)
Block(2,2,-4,ACACIA_FENCE:0)
Block(-1,2,-3,LOG_2:0)
Block(2,2,-3,LOG_2:0)
Block(-1,2,-2,ACACIA_FENCE:0)
Block(2,2,-2,ACACIA_FENCE:0)
Block(-1,2,-1,ACACIA_FENCE:0)
Block(2,2,-1,ACACIA_FENCE:0)
Block(-1,2,0,LOG_2:0)
Block(2,2,0,LOG_2:0)
Block(-1,2,1,ACACIA_FENCE:0)
Block(2,2,1,ACACIA_FENCE:0)
Block(-3,2,2,LOG_2:0)
Block(-2,2,2,ACACIA_FENCE:0)
Block(-1,2,2,LOG_2:0)
Block(2,2,2,LOG_2:0)
Block(3,2,2,ACACIA_FENCE:0)
Block(4,2,2,LOG_2:0)
Block(-2,2,3,ACACIA_FENCE:0)
Block(3,2,3,ACACIA_FENCE:0)
Block(-2,2,4,ACACIA_FENCE:0)
Block(3,2,4,ACACIA_FENCE:0)
Block(-3,2,5,LOG_2:0)
Block(-2,2,5,ACACIA_FENCE:0)
Block(-1,2,5,LOG_2:0)
Block(2,2,5,LOG_2:0)
Block(3,2,5,ACACIA_FENCE:0)
Block(4,2,5,LOG_2:0)
Block(-1,2,6,ACACIA_FENCE:0)
Block(0,2,6,ACACIA_FENCE:0)
Block(1,2,6,ACACIA_FENCE:0)
Block(2,2,6,ACACIA_FENCE:0)
Block(-1,2,7,LOG_2:0)
Block(2,2,7,LOG_2:0)
Block(-1,3,-5,WOOD_STEP:2)
Block(2,3,-5,WOOD_STEP:2)
Block(-1,3,-3,WOOD_STEP:2)
Block(2,3,-3,WOOD_STEP:2)
Block(-1,3,0,WOOD_STEP:4)
Block(2,3,0,WOOD_STEP:4)
Block(-1,3,1,WOOD_STEP:4)
Block(2,3,1,WOOD_STEP:4)
Block(-3,3,2,WOOD_STEP:4)
Block(-2,3,2,WOOD_STEP:4)
Block(-1,3,2,LOG_2:0)
Block(2,3,2,LOG_2:0)
Block(3,3,2,WOOD_STEP:4)
Block(4,3,2,WOOD_STEP:4)
Block(0,3,4,LADDER:2)
Block(-3,3,5,WOOD_STEP:4)
Block(-2,3,5,WOOD_STEP:4)
Block(-1,3,5,LOG_2:0)
Block(2,3,5,LOG_2:0)
Block(3,3,5,WOOD_STEP:4)
Block(4,3,5,WOOD_STEP:4)
Block(-1,3,6,WOOD_STEP:4)
Block(2,3,6,WOOD_STEP:4)
Block(-1,3,7,WOOD_STEP:4)
Block(2,3,7,WOOD_STEP:4)
Block(-1,4,2,LOG_2:0)
Block(2,4,2,LOG_2:0)
Block(0,4,4,LADDER:2)
Block(-1,4,5,LOG_2:0)
Block(2,4,5,LOG_2:0)
Block(-1,5,2,LOG_2:0)
Block(2,5,2,LOG_2:0)
Block(0,5,4,LADDER:2)
Block(-1,5,5,LOG_2:0)
Block(2,5,5,LOG_2:0)
Block(-1,6,1,STONE_BUTTON:4)
Block(2,6,1,STONE_BUTTON:4)
Block(-2,6,2,STONE_BUTTON:2)
Block(-1,6,2,LOG_2:0)
Block(0,6,2,LOG_2:4)
Block(1,6,2,LOG_2:4)
Block(2,6,2,LOG_2:0)
Block(3,6,2,STONE_BUTTON:1)
Block(-1,6,3,LOG_2:8)
Block(2,6,3,LOG_2:8)
Block(-1,6,4,LOG_2:8)
Block(0,6,4,LADDER:2)
Block(2,6,4,LOG_2:8)
Block(-2,6,5,STONE_BUTTON:2)
Block(-1,6,5,LOG_2:0)
Block(0,6,5,LOG_2:4)
Block(1,6,5,LOG_2:4)
Block(2,6,5,LOG_2:0)
Block(3,6,5,STONE_BUTTON:1)
Block(-1,6,6,STONE_BUTTON:3)
Block(2,6,6,STONE_BUTTON:3)
Block(-1,7,2,LOG_2:0)
Block(2,7,2,LOG_2:0)
Block(0,7,4,LADDER:2)
Block(-1,7,5,LOG_2:0)
Block(2,7,5,LOG_2:0)
Block(-1,8,2,LOG_2:0)
Block(2,8,2,LOG_2:0)
Block(0,8,4,LADDER:2)
Block(-1,8,5,LOG_2:0)
Block(2,8,5,LOG_2:0)
Block(0,9,1,WALL_SIGN:2)
Block(1,9,1,WALL_SIGN:2)
Block(-1,9,2,LOG_2:0)
Block(0,9,2,LOG_2:4)
Block(1,9,2,LOG_2:4)
Block(2,9,2,LOG_2:0)
Block(-2,9,3,WALL_SIGN:4)
Block(-1,9,3,LOG_2:8)
Block(0,9,3,WOOD_STEP:10)
Block(1,9,3,WOOD_STEP:10)
Block(2,9,3,LOG_2:8)
Block(3,9,3,WALL_SIGN:5)
Block(-2,9,4,WALL_SIGN:4)
Block(-1,9,4,LOG_2:8)
Block(0,9,4,LADDER:2)
Block(1,9,4,WOOD_STEP:10)
Block(2,9,4,LOG_2:8)
Block(3,9,4,WALL_SIGN:5)
Block(-1,9,5,LOG_2:0)
Block(0,9,5,LOG_2:4)
Block(1,9,5,LOG_2:4)
Block(2,9,5,LOG_2:0)
Block(0,9,6,WALL_SIGN:3)
Block(1,9,6,WALL_SIGN:3)
RandomBlock(-1,10,1,WALL_BANNER:2,../../NBT/banners/JungleBanner01.nbt,8,WALL_BANNER:2,../../NBT/banners/JungleBanner02.nbt,8,WALL_BANNER:2,../../NBT/banners/JungleBanner03.nbt,8,WALL_BANNER:2,../../NBT/banners/JungleBanner04.nbt,8,WALL_BANNER:2,../../NBT/banners/JungleBanner05.nbt,8,WALL_BANNER:2,../../NBT/banners/JungleBanner06.nbt,8,WALL_BANNER:2,../../NBT/banners/JungleBanner07.nbt,8,WALL_BANNER:2,../../NBT/banners/JungleBanner08.nbt,8,WALL_BANNER:2,../../NBT/banners/JungleBanner09.nbt,8,WALL_BANNER:2,../../NBT/banners/JungleBanner10.nbt,8,WALL_BANNER:2,../../NBT/banners/JungleBanner11.nbt,8,WALL_BANNER:2,../../NBT/banners/JungleBanner12.nbt,8,WALL_BANNER:2,../../NBT/banners/JungleBanner13.nbt,8,WALL_BANNER:2,../../NBT/banners/JungleBanner14.nbt,8,WALL_BANNER:2,../../NBT/banners/JungleBanner15.nbt,8,WALL_BANNER:2,../../NBT/banners/JungleBanner16.nbt,8,WALL_BANNER:2,../../NBT/banners/JungleBanner17.nbt,8,WALL_BANNER:2,../../NBT/banners/JungleBanner18.nbt,8,WALL_BANNER:2,../../NBT/banners/JungleBanner19.nbt,8,WALL_BANNER:2,../../NBT/banners/JungleBanner20.nbt,100)
RandomBlock(2,10,1,WALL_BANNER:2,../../NBT/banners/JungleBanner01.nbt,8,WALL_BANNER:2,../../NBT/banners/JungleBanner02.nbt,8,WALL_BANNER:2,../../NBT/banners/JungleBanner03.nbt,8,WALL_BANNER:2,../../NBT/banners/JungleBanner04.nbt,8,WALL_BANNER:2,../../NBT/banners/JungleBanner05.nbt,8,WALL_BANNER:2,../../NBT/banners/JungleBanner06.nbt,8,WALL_BANNER:2,../../NBT/banners/JungleBanner07.nbt,8,WALL_BANNER:2,../../NBT/banners/JungleBanner08.nbt,8,WALL_BANNER:2,../../NBT/banners/JungleBanner09.nbt,8,WALL_BANNER:2,../../NBT/banners/JungleBanner10.nbt,8,WALL_BANNER:2,../../NBT/banners/JungleBanner11.nbt,8,WALL_BANNER:2,../../NBT/banners/JungleBanner12.nbt,8,WALL_BANNER:2,../../NBT/banners/JungleBanner13.nbt,8,WALL_BANNER:2,../../NBT/banners/JungleBanner14.nbt,8,WALL_BANNER:2,../../NBT/banners/JungleBanner15.nbt,8,WALL_BANNER:2,../../NBT/banners/JungleBanner16.nbt,8,WALL_BANNER:2,../../NBT/banners/JungleBanner17.nbt,8,WALL_BANNER:2,../../NBT/banners/JungleBanner18.nbt,8,WALL_BANNER:2,../../NBT/banners/JungleBanner19.nbt,8,WALL_BANNER:2,../../NBT/banners/JungleBanner20.nbt,100)
RandomBlock(-2,10,2,WALL_BANNER:4,../../NBT/banners/JungleBanner01.nbt,8,WALL_BANNER:4,../../NBT/banners/JungleBanner02.nbt,8,WALL_BANNER:4,../../NBT/banners/JungleBanner03.nbt,8,WALL_BANNER:4,../../NBT/banners/JungleBanner04.nbt,8,WALL_BANNER:4,../../NBT/banners/JungleBanner05.nbt,8,WALL_BANNER:4,../../NBT/banners/JungleBanner06.nbt,8,WALL_BANNER:4,../../NBT/banners/JungleBanner07.nbt,8,WALL_BANNER:4,../../NBT/banners/JungleBanner08.nbt,8,WALL_BANNER:4,../../NBT/banners/JungleBanner09.nbt,8,WALL_BANNER:4,../../NBT/banners/JungleBanner10.nbt,8,WALL_BANNER:4,../../NBT/banners/JungleBanner11.nbt,8,WALL_BANNER:4,../../NBT/banners/JungleBanner12.nbt,8,WALL_BANNER:4,../../NBT/banners/JungleBanner13.nbt,8,WALL_BANNER:4,../../NBT/banners/JungleBanner14.nbt,8,WALL_BANNER:4,../../NBT/banners/JungleBanner15.nbt,8,WALL_BANNER:4,../../NBT/banners/JungleBanner16.nbt,8,WALL_BANNER:4,../../NBT/banners/JungleBanner17.nbt,8,WALL_BANNER:4,../../NBT/banners/JungleBanner18.nbt,8,WALL_BANNER:4,../../NBT/banners/JungleBanner19.nbt,8,WALL_BANNER:4,../../NBT/banners/JungleBanner20.nbt,100)
Block(-1,10,2,LOG_2:0)
Block(2,10,2,LOG_2:0)
RandomBlock(3,10,2,WALL_BANNER:5,../../NBT/banners/JungleBanner01.nbt,8,WALL_BANNER:5,../../NBT/banners/JungleBanner02.nbt,8,WALL_BANNER:5,../../NBT/banners/JungleBanner03.nbt,8,WALL_BANNER:5,../../NBT/banners/JungleBanner04.nbt,8,WALL_BANNER:5,../../NBT/banners/JungleBanner05.nbt,8,WALL_BANNER:5,../../NBT/banners/JungleBanner06.nbt,8,WALL_BANNER:5,../../NBT/banners/JungleBanner07.nbt,8,WALL_BANNER:5,../../NBT/banners/JungleBanner08.nbt,8,WALL_BANNER:5,../../NBT/banners/JungleBanner09.nbt,8,WALL_BANNER:5,../../NBT/banners/JungleBanner10.nbt,8,WALL_BANNER:5,../../NBT/banners/JungleBanner11.nbt,8,WALL_BANNER:5,../../NBT/banners/JungleBanner12.nbt,8,WALL_BANNER:5,../../NBT/banners/JungleBanner13.nbt,8,WALL_BANNER:5,../../NBT/banners/JungleBanner14.nbt,8,WALL_BANNER:5,../../NBT/banners/JungleBanner15.nbt,8,WALL_BANNER:5,../../NBT/banners/JungleBanner16.nbt,8,WALL_BANNER:5,../../NBT/banners/JungleBanner17.nbt,8,WALL_BANNER:5,../../NBT/banners/JungleBanner18.nbt,8,WALL_BANNER:5,../../NBT/banners/JungleBanner19.nbt,8,WALL_BANNER:5,../../NBT/banners/JungleBanner20.nbt,100)
Block(1,10,3,AIR)
RandomBlock(-2,10,5,WALL_BANNER:4,../../NBT/banners/JungleBanner01.nbt,8,WALL_BANNER:4,../../NBT/banners/JungleBanner02.nbt,8,WALL_BANNER:4,../../NBT/banners/JungleBanner03.nbt,8,WALL_BANNER:4,../../NBT/banners/JungleBanner04.nbt,8,WALL_BANNER:4,../../NBT/banners/JungleBanner05.nbt,8,WALL_BANNER:4,../../NBT/banners/JungleBanner06.nbt,8,WALL_BANNER:4,../../NBT/banners/JungleBanner07.nbt,8,WALL_BANNER:4,../../NBT/banners/JungleBanner08.nbt,8,WALL_BANNER:4,../../NBT/banners/JungleBanner09.nbt,8,WALL_BANNER:4,../../NBT/banners/JungleBanner10.nbt,8,WALL_BANNER:4,../../NBT/banners/JungleBanner11.nbt,8,WALL_BANNER:4,../../NBT/banners/JungleBanner12.nbt,8,WALL_BANNER:4,../../NBT/banners/JungleBanner13.nbt,8,WALL_BANNER:4,../../NBT/banners/JungleBanner14.nbt,8,WALL_BANNER:4,../../NBT/banners/JungleBanner15.nbt,8,WALL_BANNER:4,../../NBT/banners/JungleBanner16.nbt,8,WALL_BANNER:4,../../NBT/banners/JungleBanner17.nbt,8,WALL_BANNER:4,../../NBT/banners/JungleBanner18.nbt,8,WALL_BANNER:4,../../NBT/banners/JungleBanner19.nbt,8,WALL_BANNER:4,../../NBT/banners/JungleBanner20.nbt,100)
Block(-1,10,5,LOG_2:0)
Block(2,10,5,LOG_2:0)
RandomBlock(3,10,5,WALL_BANNER:5,../../NBT/banners/JungleBanner01.nbt,8,WALL_BANNER:5,../../NBT/banners/JungleBanner02.nbt,8,WALL_BANNER:5,../../NBT/banners/JungleBanner03.nbt,8,WALL_BANNER:5,../../NBT/banners/JungleBanner04.nbt,8,WALL_BANNER:5,../../NBT/banners/JungleBanner05.nbt,8,WALL_BANNER:5,../../NBT/banners/JungleBanner06.nbt,8,WALL_BANNER:5,../../NBT/banners/JungleBanner07.nbt,8,WALL_BANNER:5,../../NBT/banners/JungleBanner08.nbt,8,WALL_BANNER:5,../../NBT/banners/JungleBanner09.nbt,8,WALL_BANNER:5,../../NBT/banners/JungleBanner10.nbt,8,WALL_BANNER:5,../../NBT/banners/JungleBanner11.nbt,8,WALL_BANNER:5,../../NBT/banners/JungleBanner12.nbt,8,WALL_BANNER:5,../../NBT/banners/JungleBanner13.nbt,8,WALL_BANNER:5,../../NBT/banners/JungleBanner14.nbt,8,WALL_BANNER:5,../../NBT/banners/JungleBanner15.nbt,8,WALL_BANNER:5,../../NBT/banners/JungleBanner16.nbt,8,WALL_BANNER:5,../../NBT/banners/JungleBanner17.nbt,8,WALL_BANNER:5,../../NBT/banners/JungleBanner18.nbt,8,WALL_BANNER:5,../../NBT/banners/JungleBanner19.nbt,8,WALL_BANNER:5,../../NBT/banners/JungleBanner20.nbt,100)
RandomBlock(-1,10,6,WALL_BANNER:3,../../NBT/banners/JungleBanner01.nbt,8,WALL_BANNER:3,../../NBT/banners/JungleBanner02.nbt,8,WALL_BANNER:3,../../NBT/banners/JungleBanner03.nbt,8,WALL_BANNER:3,../../NBT/banners/JungleBanner04.nbt,8,WALL_BANNER:3,../../NBT/banners/JungleBanner05.nbt,8,WALL_BANNER:3,../../NBT/banners/JungleBanner06.nbt,8,WALL_BANNER:3,../../NBT/banners/JungleBanner07.nbt,8,WALL_BANNER:3,../../NBT/banners/JungleBanner08.nbt,8,WALL_BANNER:3,../../NBT/banners/JungleBanner09.nbt,8,WALL_BANNER:3,../../NBT/banners/JungleBanner10.nbt,8,WALL_BANNER:3,../../NBT/banners/JungleBanner11.nbt,8,WALL_BANNER:3,../../NBT/banners/JungleBanner12.nbt,8,WALL_BANNER:3,../../NBT/banners/JungleBanner13.nbt,8,WALL_BANNER:3,../../NBT/banners/JungleBanner14.nbt,8,WALL_BANNER:3,../../NBT/banners/JungleBanner15.nbt,8,WALL_BANNER:3,../../NBT/banners/JungleBanner16.nbt,8,WALL_BANNER:3,../../NBT/banners/JungleBanner17.nbt,8,WALL_BANNER:3,../../NBT/banners/JungleBanner18.nbt,8,WALL_BANNER:3,../../NBT/banners/JungleBanner19.nbt,8,WALL_BANNER:3,../../NBT/banners/JungleBanner20.nbt,100)
RandomBlock(2,10,6,WALL_BANNER:3,../../NBT/banners/JungleBanner01.nbt,8,WALL_BANNER:3,../../NBT/banners/JungleBanner02.nbt,8,WALL_BANNER:3,../../NBT/banners/JungleBanner03.nbt,8,WALL_BANNER:3,../../NBT/banners/JungleBanner04.nbt,8,WALL_BANNER:3,../../NBT/banners/JungleBanner05.nbt,8,WALL_BANNER:3,../../NBT/banners/JungleBanner06.nbt,8,WALL_BANNER:3,../../NBT/banners/JungleBanner07.nbt,8,WALL_BANNER:3,../../NBT/banners/JungleBanner08.nbt,8,WALL_BANNER:3,../../NBT/banners/JungleBanner09.nbt,8,WALL_BANNER:3,../../NBT/banners/JungleBanner10.nbt,8,WALL_BANNER:3,../../NBT/banners/JungleBanner11.nbt,8,WALL_BANNER:3,../../NBT/banners/JungleBanner12.nbt,8,WALL_BANNER:3,../../NBT/banners/JungleBanner13.nbt,8,WALL_BANNER:3,../../NBT/banners/JungleBanner14.nbt,8,WALL_BANNER:3,../../NBT/banners/JungleBanner15.nbt,8,WALL_BANNER:3,../../NBT/banners/JungleBanner16.nbt,8,WALL_BANNER:3,../../NBT/banners/JungleBanner17.nbt,8,WALL_BANNER:3,../../NBT/banners/JungleBanner18.nbt,8,WALL_BANNER:3,../../NBT/banners/JungleBanner19.nbt,8,WALL_BANNER:3,../../NBT/banners/JungleBanner20.nbt,100)
Block(-1,11,2,ACACIA_FENCE:0)
Block(2,11,2,ACACIA_FENCE:0)
Block(-1,11,5,ACACIA_FENCE:0)
Block(2,11,5,ACACIA_FENCE:0)
Block(-1,12,2,WOOD_STEP:2)
Block(0,12,2,WOOD_STEP:2)
Block(1,12,2,WOOD_STEP:2)
Block(2,12,2,WOOD_STEP:2)
Block(-1,12,3,WOOD_DOUBLE_STEP:2)
Block(0,12,3,WOOD_DOUBLE_STEP:2)
Block(1,12,3,WOOD_STEP:2)
Block(2,12,3,WOOD_STEP:10)
Block(-1,12,4,WOOD_STEP:10)
Block(0,12,4,WOOD_STEP:10)
Block(1,12,4,WOOD_DOUBLE_STEP:2)
Block(2,12,4,WOOD_DOUBLE_STEP:2)
Block(-1,12,5,ACACIA_FENCE:0)
Block(0,12,5,WOOD_STEP:10)
Block(1,12,5,WOOD_DOUBLE_STEP:2)
Block(2,12,5,WOOD_STEP:2)
Block(-1,13,4,WOOD_STEP:2)
Block(-1,13,5,WOOD_STEP:2)
Block(0,13,5,WOOD_STEP:2)
#Entity(1,10,3,minecraft:villager,1,../../NBT/entities/tribalbowman.txt)
