
#######################################################################
# +-----------------------------------------------------------------+ #
# |                            BO4 object                           | #
# +-----------------------------------------------------------------+ #
#######################################################################

Author: BO3 BulkEdit (by LanToaster)

Description: This Object was Created with BO3_BulkEdit

SettingsMode: WriteDisable


#######################################################################
# +-----------------------------------------------------------------+ #
# |                          Main settings                          | #
# +-----------------------------------------------------------------+ #
#######################################################################

Frequency: 100

SpawnHeight: highestBlock

UseCenterForHighestBlock: true

##############################
# Height Limits for the BO4. #
##############################

MinHeight: 0

MaxHeight: 255

InheritBO3: 

InheritBO3Rotation: NORTH

OverrideChildSettings: true

OverrideParentHeight: false

CanOverride: true

BranchFrequency: 0

BranchFrequencyGroup: 

MustBeBelowOther: false

MustBeInside: 

CannotBeInside: 

ReplacesBO3: 

MustBeInsideWorldBorders: false

CanSpawnOnWater: false

SpawnOnWaterOnly: false

SpawnUnderWater: false

SpawnAtWaterLevel: false

HeightOffset: 0

RemoveAir: true

ReplaceAbove: 

ReplaceBelow: cobblestone

ReplaceWithBiomeBlocks: true

ReplaceWithSurfaceBlock: GRASS

ReplaceWithGroundBlock: DIRT

ReplaceWithStoneBlock: STONE

SmoothRadius: 0

SmoothHeightOffset: 0

SmoothStartTop: false

SmoothStartWood: false

SmoothingSurfaceBlock: 

SmoothingGroundBlock: 

BO3Group: 

IsSpawnPoint: false

DoReplaceBlocks: true


#######################################################################
# +-----------------------------------------------------------------+ #
# |                              Blocks                             | #
# +-----------------------------------------------------------------+ #
#######################################################################

Block(-6,-1,-6,LOG_2:0)
Block(-5,-1,-6,STAINED_CLAY:12)
Block(-4,-1,-6,STAINED_CLAY:12)
Block(-3,-1,-6,STAINED_CLAY:12)
Block(-2,-1,-6,STAINED_CLAY:12)
Block(-1,-1,-6,STAINED_CLAY:12)
Block(0,-1,-6,STAINED_CLAY:12)
Block(1,-1,-6,LOG_2:0)
Block(2,-1,-6,STAINED_CLAY:12)
Block(3,-1,-6,STAINED_CLAY:12)
Block(4,-1,-6,STAINED_CLAY:12)
Block(5,-1,-6,LOG_2:0)
Block(-6,-1,-5,STAINED_CLAY:12)
Block(-5,-1,-5,HAY_BLOCK:0)
Block(-4,-1,-5,HAY_BLOCK:4)
Block(-3,-1,-5,HAY_BLOCK:0)
Block(-2,-1,-5,GRASS:0)
Block(-1,-1,-5,GRASS:0)
Block(0,-1,-5,GRASS_PATH:0)
Block(1,-1,-5,GRASS_PATH:0)
Block(2,-1,-5,GRASS:0)
Block(3,-1,-5,GRASS:0)
Block(4,-1,-5,GRASS:0)
Block(5,-1,-5,STAINED_CLAY:12)
Block(-6,-1,-4,STAINED_CLAY:12)
Block(-5,-1,-4,HAY_BLOCK:0)
Block(-4,-1,-4,HAY_BLOCK:4)
Block(-3,-1,-4,GRASS_PATH:0)
Block(-2,-1,-4,GRASS_PATH:0)
Block(-1,-1,-4,GRASS_PATH:0)
Block(0,-1,-4,GRASS_PATH:0)
Block(1,-1,-4,GRASS:0)
Block(2,-1,-4,GRASS:0)
Block(3,-1,-4,GRASS_PATH:0)
Block(4,-1,-4,GRASS_PATH:0)
Block(5,-1,-4,STAINED_CLAY:12)
Block(-6,-1,-3,STAINED_CLAY:12)
Block(-5,-1,-3,GRASS:0)
Block(-4,-1,-3,HAY_BLOCK:0)
Block(-3,-1,-3,GRASS_PATH:0)
Block(-2,-1,-3,DIRT:0)
Block(-1,-1,-3,GRASS_PATH:0)
Block(0,-1,-3,GRAVEL:0)
Block(1,-1,-3,DIRT:0)
Block(2,-1,-3,GRASS_PATH:0)
Block(3,-1,-3,DIRT:0)
Block(4,-1,-3,GRASS_PATH:0)
Block(5,-1,-3,STAINED_CLAY:12)
Block(-6,-1,-2,STAINED_CLAY:12)
Block(-5,-1,-2,GRASS:0)
Block(-4,-1,-2,GRASS_PATH:0)
Block(-3,-1,-2,GRASS_PATH:0)
Block(-2,-1,-2,LOG_2:0)
Block(-1,-1,-2,GRASS_PATH:0)
Block(0,-1,-2,GRASS_PATH:0)
Block(1,-1,-2,HAY_BLOCK:8)
Block(2,-1,-2,LOG_2:0)
Block(3,-1,-2,GRASS_PATH:0)
Block(4,-1,-2,GRASS_PATH:0)
Block(5,-1,-2,STAINED_CLAY:12)
Block(-6,-1,-1,STAINED_CLAY:12)
Block(-5,-1,-1,GRASS_PATH:0)
Block(-4,-1,-1,GRASS_PATH:0)
Block(-3,-1,-1,GRASS_PATH:0)
Block(-2,-1,-1,GRASS_PATH:0)
Block(-1,-1,-1,GRAVEL:0)
Block(0,-1,-1,HAY_BLOCK:4)
Block(1,-1,-1,HAY_BLOCK:4)
Block(2,-1,-1,GRASS_PATH:0)
Block(3,-1,-1,GRAVEL:0)
Block(4,-1,-1,GRASS_PATH:0)
Block(5,-1,-1,STAINED_CLAY:12)
Block(-6,-1,0,LOG_2:0)
Block(-5,-1,0,GRASS:0)
Block(-4,-1,0,GRASS_PATH:0)
Block(-3,-1,0,GRAVEL:0)
Block(-2,-1,0,GRASS_PATH:0)
Block(-1,-1,0,DIRT:0)
Block(0,-1,0,DIRT:0)
Block(1,-1,0,HAY_BLOCK:0)
Block(2,-1,0,GRASS_PATH:0)
Block(3,-1,0,GRASS_PATH:0)
Block(4,-1,0,GRASS_PATH:0)
Block(5,-1,0,STAINED_CLAY:12)
Block(-6,-1,1,STAINED_CLAY:12)
Block(-5,-1,1,GRASS:0)
Block(-4,-1,1,GRASS_PATH:0)
Block(-3,-1,1,GRAVEL:0)
Block(-2,-1,1,GRASS_PATH:0)
Block(-1,-1,1,DIRT:0)
Block(0,-1,1,GRASS_PATH:0)
Block(1,-1,1,GRAVEL:0)
Block(2,-1,1,GRASS_PATH:0)
Block(3,-1,1,GRASS_PATH:0)
Block(4,-1,1,GRASS_PATH:0)
Block(5,-1,1,LOG_2:0)
Block(-6,-1,2,STAINED_CLAY:12)
Block(-5,-1,2,GRASS:0)
Block(-4,-1,2,GRASS_PATH:0)
Block(-3,-1,2,DIRT:0)
Block(-2,-1,2,GRASS_PATH:0)
Block(-1,-1,2,GRASS_PATH:0)
Block(0,-1,2,GRASS_PATH:0)
Block(1,-1,2,CAULDRON:3)
Block(2,-1,2,GRASS_PATH:0)
Block(4,-1,2,DIRT:0)
Block(5,-1,2,STAINED_CLAY:12)
Block(-6,-1,3,STAINED_CLAY:12)
Block(-5,-1,3,HAY_BLOCK:8)
Block(-4,-1,3,GRASS_PATH:0)
Block(-3,-1,3,GRASS_PATH:0)
Block(-2,-1,3,LOG_2:0)
Block(-1,-1,3,GRASS_PATH:0)
Block(1,-1,3,CAULDRON:3)
Block(2,-1,3,LOG_2:0)
Block(3,-1,3,GRASS_PATH:0)
Block(4,-1,3,GRASS_PATH:0)
Block(5,-1,3,STAINED_CLAY:12)
Block(-6,-1,4,STAINED_CLAY:12)
Block(-5,-1,4,HAY_BLOCK:0)
Block(-4,-1,4,HAY_BLOCK:8)
Block(-3,-1,4,HAY_BLOCK:4)
Block(-2,-1,4,GRASS_PATH:0)
Block(-1,-1,4,GRASS_PATH:0)
Block(0,-1,4,GRASS_PATH:0)
Block(1,-1,4,GRASS_PATH:0)
Block(2,-1,4,DIRT:0)
Block(3,-1,4,GRASS_PATH:0)
Block(4,-1,4,GRASS_PATH:0)
Block(5,-1,4,STAINED_CLAY:12)
Block(-6,-1,5,STAINED_CLAY:12)
Block(-5,-1,5,HAY_BLOCK:0)
Block(-4,-1,5,HAY_BLOCK:0)
Block(-3,-1,5,GRASS:0)
Block(-2,-1,5,GRASS:0)
Block(-1,-1,5,GRASS:0)
Block(0,-1,5,GRASS_PATH:0)
Block(1,-1,5,GRASS_PATH:0)
Block(2,-1,5,GRASS_PATH:0)
Block(3,-1,5,GRASS_PATH:0)
Block(4,-1,5,GRASS:0)
Block(5,-1,5,STAINED_CLAY:12)
Block(-6,-1,6,LOG_2:0)
Block(-5,-1,6,STAINED_CLAY:12)
Block(-4,-1,6,STAINED_CLAY:12)
Block(-3,-1,6,STAINED_CLAY:12)
Block(-2,-1,6,STAINED_CLAY:12)
Block(-1,-1,6,LOG_2:0)
Block(0,-1,6,STAINED_CLAY:12)
Block(1,-1,6,GRASS:0)
Block(2,-1,6,GRASS:0)
Block(3,-1,6,STAINED_CLAY:12)
Block(4,-1,6,STAINED_CLAY:12)
Block(5,-1,6,LOG_2:0)
Block(-6,0,-6,SPRUCE_FENCE:0)
Block(-5,0,-6,SPRUCE_FENCE:0)
Block(-4,0,-6,SPRUCE_FENCE:0)
Block(-3,0,-6,SPRUCE_FENCE:0)
Block(-2,0,-6,SPRUCE_FENCE:0)
Block(-1,0,-6,SPRUCE_FENCE:0)
Block(0,0,-6,SPRUCE_FENCE:0)
Block(1,0,-6,SPRUCE_FENCE:0)
Block(2,0,-6,SPRUCE_FENCE:0)
Block(3,0,-6,SPRUCE_FENCE:0)
Block(4,0,-6,SPRUCE_FENCE:0)
Block(5,0,-6,SPRUCE_FENCE:0)
Block(-6,0,-5,SPRUCE_FENCE:0)
Block(-5,0,-5,AIR)
Block(5,0,-5,SPRUCE_FENCE:0)
Block(-6,0,-4,SPRUCE_FENCE:0)
Block(5,0,-4,SPRUCE_FENCE:0)
Block(-6,0,-3,SPRUCE_FENCE:0)
Block(-4,0,-3,HAY_BLOCK:0)
Block(-2,0,-3,AIR)
Block(0,0,-3,AIR)
Block(1,0,-3,AIR)
Block(3,0,-3,HAY_BLOCK:0)
Block(5,0,-3,SPRUCE_FENCE:0)
Block(-6,0,-2,SPRUCE_FENCE:0)
Block(-2,0,-2,SPRUCE_FENCE:0)
Block(2,0,-2,SPRUCE_FENCE:0)
Block(5,0,-2,SPRUCE_FENCE:0)
Block(-6,0,-1,SPRUCE_FENCE:0)
Block(-1,0,-1,AIR)
Block(0,0,-1,HAY_BLOCK:0)
Block(1,0,-1,HAY_BLOCK:0)
Block(3,0,-1,AIR)
Block(5,0,-1,SPRUCE_FENCE:0)
Block(-6,0,0,SPRUCE_FENCE:0)
Block(-3,0,0,HAY_BLOCK:0)
Block(-1,0,0,AIR)
Block(0,0,0,AIR)
Block(1,0,0,HAY_BLOCK:0)
Block(5,0,0,SPRUCE_FENCE:0)
Block(-6,0,1,SPRUCE_FENCE:0)
Block(-3,0,1,HAY_BLOCK:0)
Block(-1,0,1,AIR)
Block(5,0,1,SPRUCE_FENCE:0)
Block(-6,0,2,SPRUCE_FENCE:0)
Block(-3,0,2,HAY_BLOCK:0)
Block(3,0,2,AIR)
Block(4,0,2,AIR)
Block(5,0,2,SPRUCE_FENCE:0)
Block(-6,0,3,SPRUCE_FENCE:0)
Block(-2,0,3,SPRUCE_FENCE:0)
Block(0,0,3,AIR)
Block(2,0,3,SPRUCE_FENCE:0)
Block(5,0,3,SPRUCE_FENCE:0)
Block(-6,0,4,SPRUCE_FENCE:0)
Block(-3,0,4,AIR)
Block(2,0,4,AIR)
Block(5,0,4,SPRUCE_FENCE:0)
Block(-6,0,5,SPRUCE_FENCE:0)
Block(-5,0,5,AIR)
Block(5,0,5,SPRUCE_FENCE:0)
Block(-6,0,6,SPRUCE_FENCE:0)
Block(-5,0,6,SPRUCE_FENCE:0)
Block(-4,0,6,SPRUCE_FENCE:0)
Block(-3,0,6,SPRUCE_FENCE:0)
Block(-2,0,6,SPRUCE_FENCE:0)
Block(-1,0,6,SPRUCE_FENCE:0)
Block(0,0,6,SPRUCE_FENCE:0)
Block(1,0,6,SPRUCE_FENCE_GATE:2)
Block(2,0,6,SPRUCE_FENCE_GATE:2)
Block(3,0,6,SPRUCE_FENCE:0)
Block(4,0,6,SPRUCE_FENCE:0)
Block(5,0,6,SPRUCE_FENCE:0)
Block(-2,1,-2,SPRUCE_FENCE:0)
Block(2,1,-2,SPRUCE_FENCE:0)
Block(-3,1,1,HAY_BLOCK:0)
Block(-2,1,3,SPRUCE_FENCE:0)
Block(2,1,3,SPRUCE_FENCE:0)
Block(-2,2,-2,SPRUCE_FENCE:0)
Block(2,2,-2,SPRUCE_FENCE:0)
Block(2,2,-1,WOOD_STEP:12)
Block(2,2,0,WOOD_DOUBLE_STEP:3)
Block(1,2,1,WOOD_STEP:12)
Block(2,2,1,WOOD_STEP:4)
Block(-2,2,2,WOOD_STEP:12)
Block(-1,2,2,WOOD_STEP:12)
Block(0,2,2,WOOD_STEP:12)
Block(1,2,2,WOOD_STEP:12)
Block(2,2,2,WOOD_STEP:4)
Block(-2,2,3,WOOD_STEP:4)
Block(-1,2,3,WOOD_STEP:4)
Block(0,2,3,WOOD_STEP:4)
Block(1,2,3,WOOD_STEP:4)
Block(2,2,3,WOOD_STEP:4)
Block(-2,3,-2,SPRUCE_FENCE:0)
Block(-1,3,-2,WOOD_STEP:12)
Block(0,3,-2,WOOD_STEP:12)
Block(1,3,-2,WOOD_STEP:4)
Block(2,3,-2,WOOD_STEP:4)
Block(-1,3,-1,WOOD_STEP:12)
Block(0,3,-1,WOOD_STEP:12)
Block(1,3,-1,WOOD_STEP:4)
Block(-2,3,0,WOOD_STEP:12)
Block(-1,3,0,WOOD_STEP:12)
Block(0,3,0,WOOD_STEP:4)
Block(1,3,0,WOOD_STEP:4)
Block(-2,3,1,WOOD_STEP:4)
Block(-1,3,1,WOOD_STEP:4)
Block(0,3,1,WOOD_STEP:4)
Block(-2,4,-2,WOOD_STEP:4)
Block(-2,4,-1,WOOD_STEP:4)

#######################################################################
# +-----------------------------------------------------------------+ #
# |                             Branches                            | #
# +-----------------------------------------------------------------+ #
#######################################################################


#######################################################################
# +-----------------------------------------------------------------+ #
# |                             Entities                            | #
# +-----------------------------------------------------------------+ #
#######################################################################

Entity(0,0,-3,minecraft:villager,1,../../NBT/entities/tribalherder.txt)
Entity(3,0,-1,minecraft:pig,1,../../NBT/entities/pig.txt)
Entity(-1,0,0,minecraft:pig,1,../../NBT/entities/pig.txt)
Entity(-3,0,4,minecraft:pig,1,../../NBT/entities/pig.txt)

#######################################################################
# +-----------------------------------------------------------------+ #
# |                            Particles                            | #
# +-----------------------------------------------------------------+ #
#######################################################################


#######################################################################
# +-----------------------------------------------------------------+ #
# |                             Spawners                            | #
# +-----------------------------------------------------------------+ #
#######################################################################


#######################################################################
# +-----------------------------------------------------------------+ #
# |                             ModData                             | #
# +-----------------------------------------------------------------+ #
#######################################################################

