
#######################################################################
# +-----------------------------------------------------------------+ #
# |                            BO4 object                           | #
# +-----------------------------------------------------------------+ #
#######################################################################

Author: NLBlackEagle

Description: No description given

SettingsMode: WriteDisable


#######################################################################
# +-----------------------------------------------------------------+ #
# |                          Main settings                          | #
# +-----------------------------------------------------------------+ #
#######################################################################

FixedRotation: 

Frequency: 0

SpawnHeight: highestBlock

UseCenterForHighestBlock: true

##############################
# Height Limits for the BO4. #
##############################

MinHeight: 0

MaxHeight: 255

InheritBO3: 

InheritBO3Rotation: NORTH

OverrideChildSettings: true

OverrideParentHeight: false

CanOverride: true

BranchFrequency: 0

BranchFrequencyGroup: 

MustBeBelowOther: false

MustBeInside: 

CannotBeInside: 

ReplacesBO3: 

MustBeInsideWorldBorders: false

CanSpawnOnWater: true

SpawnOnWaterOnly: false

SpawnUnderWater: false

SpawnAtWaterLevel: false

HeightOffset: 0

RemoveAir: false

ReplaceAbove: 

ReplaceBelow: 

ReplaceWithBiomeBlocks: false

ReplaceWithSurfaceBlock: GRASS

ReplaceWithGroundBlock: DIRT

ReplaceWithStoneBlock: STONE

SmoothRadius: 0

SmoothHeightOffset: 0

SmoothStartTop: false

SmoothStartWood: false

SmoothingSurfaceBlock: 

SmoothingGroundBlock: 

BO3Group: 

IsSpawnPoint: false

DoReplaceBlocks: false


#######################################################################
# +-----------------------------------------------------------------+ #
# |                              Blocks                             | #
# +-----------------------------------------------------------------+ #
#######################################################################

Block(-8,0,-7,contenttweaker:reinforced_concrete)
Block(-8,0,-6,contenttweaker:reinforced_concrete)
Block(-8,0,-5,contenttweaker:reinforced_concrete)
Block(-8,0,-4,contenttweaker:reinforced_concrete)
Block(-8,0,-3,contenttweaker:reinforced_concrete)
Block(-8,0,-2,contenttweaker:reinforced_concrete)
Block(-8,1,-6,contenttweaker:reinforced_concrete)
Block(-8,1,-5,contenttweaker:reinforced_concrete)
Block(-8,1,-4,contenttweaker:reinforced_concrete)
Block(-8,1,-3,contenttweaker:reinforced_concrete)
Block(-8,1,-2,contenttweaker:reinforced_concrete)
Block(-8,2,-6,contenttweaker:reinforced_concrete)
Block(-8,2,-5,contenttweaker:reinforced_concrete)
Block(-8,2,-4,contenttweaker:reinforced_concrete)
Block(-8,2,-3,contenttweaker:reinforced_concrete)
Block(-8,2,-2,contenttweaker:reinforced_concrete)
Block(-8,3,-6,contenttweaker:reinforced_concrete)
Block(-8,3,-5,contenttweaker:resource_crate)
Block(-8,3,-4,AIR:0)
Block(-8,3,-3,AIR:0)
Block(-8,3,-2,contenttweaker:reinforced_concrete)
Block(-8,4,-6,contenttweaker:reinforced_concrete)
Block(-8,4,-5,AIR:0)
Block(-8,4,-4,AIR:0)
Block(-8,4,-3,AIR:0)
Block(-8,4,-2,contenttweaker:reinforced_concrete)
Block(-8,5,-6,contenttweaker:reinforced_concrete)
Block(-8,5,-5,contenttweaker:reinforced_concrete)
Block(-8,5,-4,contenttweaker:reinforced_concrete)
Block(-8,5,-3,contenttweaker:reinforced_concrete)
Block(-8,5,-2,contenttweaker:reinforced_concrete)
Block(-8,6,-6,contenttweaker:reinforced_concrete)
Block(-8,7,-6,contenttweaker:reinforced_concrete)
Block(-8,8,-7,contenttweaker:reinforced_concrete)
Block(-8,8,-6,contenttweaker:reinforced_concrete)
Block(-7,0,-7,contenttweaker:reinforced_concrete)
Block(-7,0,-6,contenttweaker:reinforced_concrete)
Block(-7,0,-5,contenttweaker:reinforced_concrete)
Block(-7,0,-4,contenttweaker:reinforced_concrete)
Block(-7,0,-3,contenttweaker:reinforced_concrete)
Block(-7,0,-2,contenttweaker:reinforced_concrete)
Block(-7,1,-6,contenttweaker:reinforced_concrete)
Block(-7,1,-5,contenttweaker:reinforced_concrete)
Block(-7,1,-4,contenttweaker:reinforced_concrete)
Block(-7,1,-3,contenttweaker:reinforced_concrete)
Block(-7,1,-2,contenttweaker:reinforced_concrete)
Block(-7,2,-6,contenttweaker:reinforced_concrete)
Block(-7,2,-5,contenttweaker:reinforced_concrete)
Block(-7,2,-4,contenttweaker:reinforced_concrete)
Block(-7,2,-3,contenttweaker:reinforced_concrete)
Block(-7,2,-2,contenttweaker:reinforced_concrete)
Block(-7,3,-6,contenttweaker:reinforced_concrete)
Block(-7,3,-5,contenttweaker:resource_crate)
Block(-7,3,-4,contenttweaker:resource_crate)
Block(-7,3,-3,contenttweaker:resource_crate)
Block(-7,3,-2,contenttweaker:reinforced_concrete)
Block(-7,4,-6,contenttweaker:reinforced_concrete)
Block(-7,4,-5,contenttweaker:resource_crate)
Block(-7,4,-4,AIR:0)
Block(-7,4,-3,AIR:0)
Block(-7,4,-2,contenttweaker:reinforced_concrete)
Block(-7,5,-6,contenttweaker:reinforced_concrete)
Block(-7,5,-5,contenttweaker:reinforced_concrete)
Block(-7,5,-4,contenttweaker:reinforced_concrete)
Block(-7,5,-3,contenttweaker:reinforced_concrete)
Block(-7,5,-2,contenttweaker:reinforced_concrete)
Block(-7,6,-6,contenttweaker:reinforced_concrete)
Block(-7,7,-6,contenttweaker:reinforced_concrete)
Block(-7,8,-7,contenttweaker:reinforced_concrete)
Block(-7,8,-6,contenttweaker:reinforced_concrete)
Block(-6,0,-7,contenttweaker:reinforced_concrete)
Block(-6,0,-6,contenttweaker:reinforced_concrete)
Block(-6,0,-5,contenttweaker:reinforced_concrete)
Block(-6,0,-4,contenttweaker:reinforced_concrete)
Block(-6,0,-3,contenttweaker:reinforced_concrete)
Block(-6,0,-2,contenttweaker:reinforced_concrete)
Block(-6,1,-6,contenttweaker:reinforced_concrete)
Block(-6,1,-5,contenttweaker:reinforced_concrete)
Block(-6,1,-4,contenttweaker:reinforced_concrete)
Block(-6,1,-3,contenttweaker:reinforced_concrete)
Block(-6,1,-2,contenttweaker:reinforced_concrete)
Block(-6,2,-6,contenttweaker:reinforced_concrete)
Block(-6,2,-5,contenttweaker:reinforced_concrete)
Block(-6,2,-4,contenttweaker:reinforced_concrete)
Block(-6,2,-3,contenttweaker:reinforced_concrete)
Block(-6,2,-2,contenttweaker:reinforced_concrete)
Block(-6,3,-6,contenttweaker:reinforced_concrete)
Block(-6,3,-5,contenttweaker:reinforced_concrete)
Block(-6,3,-4,contenttweaker:reinforced_concrete)
Block(-6,3,-3,contenttweaker:reinforced_concrete)
Block(-6,3,-2,contenttweaker:reinforced_concrete)
Block(-6,4,-6,contenttweaker:reinforced_concrete)
Block(-6,4,-5,contenttweaker:reinforced_concrete)
Block(-6,4,-4,contenttweaker:reinforced_concrete)
Block(-6,4,-3,contenttweaker:reinforced_concrete)
Block(-6,4,-2,contenttweaker:reinforced_concrete)
Block(-6,5,-6,contenttweaker:reinforced_concrete)
Block(-6,5,-5,contenttweaker:reinforced_concrete)
Block(-6,5,-4,contenttweaker:reinforced_concrete)
Block(-6,5,-3,contenttweaker:reinforced_concrete)
Block(-6,5,-2,contenttweaker:reinforced_concrete)
Block(-6,6,-6,contenttweaker:reinforced_concrete)
Block(-6,7,-6,contenttweaker:reinforced_concrete)
Block(-6,8,-7,contenttweaker:reinforced_concrete)
Block(-6,8,-6,contenttweaker:reinforced_concrete)
Block(-5,0,-7,contenttweaker:reinforced_concrete)
Block(-5,0,-6,contenttweaker:reinforced_concrete)
Block(-5,1,-6,contenttweaker:reinforced_concrete)
Block(-5,2,-6,contenttweaker:reinforced_concrete)
Block(-5,3,-6,contenttweaker:reinforced_concrete)
Block(-5,4,-6,contenttweaker:reinforced_concrete)
Block(-5,5,-6,contenttweaker:reinforced_concrete)
Block(-5,6,-6,contenttweaker:reinforced_concrete)
Block(-5,7,-6,contenttweaker:reinforced_concrete)
Block(-5,8,-7,contenttweaker:reinforced_concrete)
Block(-5,8,-6,contenttweaker:reinforced_concrete)
Block(-4,0,-7,contenttweaker:reinforced_concrete)
Block(-4,0,-6,contenttweaker:reinforced_concrete)
Block(-4,1,-7,contenttweaker:reinforced_concrete)
Block(-4,1,-6,contenttweaker:reinforced_concrete)
Block(-4,2,-7,contenttweaker:reinforced_concrete)
Block(-4,2,-6,contenttweaker:reinforced_concrete)
Block(-4,3,-7,contenttweaker:reinforced_concrete)
Block(-4,3,-6,contenttweaker:reinforced_concrete)
Block(-4,4,-7,contenttweaker:reinforced_concrete)
Block(-4,4,-6,contenttweaker:reinforced_concrete)
Block(-4,5,-7,contenttweaker:reinforced_concrete)
Block(-4,5,-6,contenttweaker:reinforced_concrete)
Block(-4,6,-7,contenttweaker:reinforced_concrete)
Block(-4,6,-6,contenttweaker:reinforced_concrete)
Block(-4,7,-7,contenttweaker:reinforced_concrete)
Block(-4,7,-6,contenttweaker:reinforced_concrete)
Block(-4,8,-7,contenttweaker:reinforced_concrete)
Block(-4,8,-6,contenttweaker:reinforced_concrete)
Block(-8,1,-7,dimstack:bedrock)
Block(-8,2,-7,dimstack:bedrock)
Block(-8,3,-7,dimstack:bedrock)
Block(-8,4,-7,dimstack:bedrock)
Block(-8,5,-7,dimstack:bedrock)
Block(-8,6,-7,dimstack:bedrock)
Block(-8,7,-7,dimstack:bedrock)
Block(-7,1,-7,dimstack:bedrock)
Block(-7,2,-7,dimstack:bedrock)
Block(-7,3,-7,dimstack:bedrock)
Block(-7,4,-7,dimstack:bedrock)
Block(-7,5,-7,dimstack:bedrock)
Block(-7,6,-7,dimstack:bedrock)
Block(-7,7,-7,dimstack:bedrock)
Block(-6,1,-7,dimstack:bedrock)
Block(-6,2,-7,dimstack:bedrock)
Block(-6,3,-7,dimstack:bedrock)
Block(-6,4,-7,dimstack:bedrock)
Block(-6,5,-7,dimstack:bedrock)
Block(-6,6,-7,dimstack:bedrock)
Block(-6,7,-7,dimstack:bedrock)
Block(-5,1,-7,dimstack:bedrock)
Block(-5,2,-7,dimstack:bedrock)
Block(-5,3,-7,dimstack:bedrock)
Block(-5,4,-7,dimstack:bedrock)
Block(-5,5,-7,dimstack:bedrock)
Block(-5,6,-7,dimstack:bedrock)
Block(-5,7,-7,dimstack:bedrock)

#######################################################################
# +-----------------------------------------------------------------+ #
# |                             Branches                            | #
# +-----------------------------------------------------------------+ #
#######################################################################

Branch(-16,0,0,true,TeleportReceiverSG_C0R1,NORTH,100.0,0)

#######################################################################
# +-----------------------------------------------------------------+ #
# |                             Entities                            | #
# +-----------------------------------------------------------------+ #
#######################################################################


#######################################################################
# +-----------------------------------------------------------------+ #
# |                            Particles                            | #
# +-----------------------------------------------------------------+ #
#######################################################################


#######################################################################
# +-----------------------------------------------------------------+ #
# |                             Spawners                            | #
# +-----------------------------------------------------------------+ #
#######################################################################


#######################################################################
# +-----------------------------------------------------------------+ #
# |                             ModData                             | #
# +-----------------------------------------------------------------+ #
#######################################################################

