
#######################################################################
# +-----------------------------------------------------------------+ #
# |                            BO4 object                           | #
# +-----------------------------------------------------------------+ #
#######################################################################

Author: NLBlackEagle

Description: No description given

SettingsMode: WriteDisable


#######################################################################
# +-----------------------------------------------------------------+ #
# |                          Main settings                          | #
# +-----------------------------------------------------------------+ #
#######################################################################

FixedRotation: 

Frequency: 0

SpawnHeight: highestBlock

UseCenterForHighestBlock: true

##############################
# Height Limits for the BO4. #
##############################

MinHeight: 0

MaxHeight: 255

InheritBO3: 

InheritBO3Rotation: NORTH

OverrideChildSettings: true

OverrideParentHeight: false

CanOverride: true

BranchFrequency: 0

BranchFrequencyGroup: 

MustBeBelowOther: false

MustBeInside: 

CannotBeInside: o_bunker_hub_ent

ReplacesBO3: 

MustBeInsideWorldBorders: false

CanSpawnOnWater: true

SpawnOnWaterOnly: false

SpawnUnderWater: false

SpawnAtWaterLevel: false

HeightOffset: 0

RemoveAir: false

ReplaceAbove: 

ReplaceBelow: 

ReplaceWithBiomeBlocks: false

ReplaceWithSurfaceBlock: GRASS

ReplaceWithGroundBlock: DIRT

ReplaceWithStoneBlock: STONE

SmoothRadius: 0

SmoothHeightOffset: 0

SmoothStartTop: false

SmoothStartWood: false

SmoothingSurfaceBlock: 

SmoothingGroundBlock: 

BO3Group: 

IsSpawnPoint: false

DoReplaceBlocks: false


#######################################################################
# +-----------------------------------------------------------------+ #
# |                              Blocks                             | #
# +-----------------------------------------------------------------+ #
#######################################################################

RandomBlock(-7,0,-6,CONCRETE:8,65,QUARK:IRON_PLATE:0,10,QUARK:IRON_PLATE:1,10,STAINED_CLAY:9,15,STAINED_CLAY:7,10,CONCRETE:8,10,RUSTIC:IRON_LATTICE:1,15,RUSTIC:IRON_LATTICE:0,15,LEAVES:4,70,CONCRETE:8,80,AIR:0,100)
RandomBlock(-7,0,-5,CONCRETE:8,65,QUARK:IRON_PLATE:0,10,QUARK:IRON_PLATE:1,10,STAINED_CLAY:9,15,STAINED_CLAY:7,10,CONCRETE:8,10,RUSTIC:IRON_LATTICE:1,15,RUSTIC:IRON_LATTICE:0,15,LEAVES:4,70,CONCRETE:8,80,AIR:0,100)
RandomBlock(-7,0,-4,CONCRETE:8,65,QUARK:IRON_PLATE:0,10,QUARK:IRON_PLATE:1,10,STAINED_CLAY:9,15,STAINED_CLAY:7,10,CONCRETE:8,10,RUSTIC:IRON_LATTICE:1,15,RUSTIC:IRON_LATTICE:0,15,LEAVES:4,70,CONCRETE:8,80,AIR:0,100)
RandomBlock(-7,0,-3,CONCRETE:8,65,QUARK:IRON_PLATE:0,10,QUARK:IRON_PLATE:1,10,STAINED_CLAY:9,15,STAINED_CLAY:7,10,CONCRETE:8,10,RUSTIC:IRON_LATTICE:1,15,RUSTIC:IRON_LATTICE:0,15,LEAVES:4,70,CONCRETE:8,80,AIR:0,100)
RandomBlock(-7,0,-2,CONCRETE:8,65,QUARK:IRON_PLATE:0,10,QUARK:IRON_PLATE:1,10,STAINED_CLAY:9,15,STAINED_CLAY:7,10,CONCRETE:8,10,RUSTIC:IRON_LATTICE:1,15,RUSTIC:IRON_LATTICE:0,15,LEAVES:4,70,CONCRETE:8,80,AIR:0,100)
RandomBlock(-7,0,-1,CONCRETE:8,65,QUARK:IRON_PLATE:0,10,QUARK:IRON_PLATE:1,10,STAINED_CLAY:9,15,STAINED_CLAY:7,10,CONCRETE:8,10,RUSTIC:IRON_LATTICE:1,15,RUSTIC:IRON_LATTICE:0,15,LEAVES:4,70,CONCRETE:8,80,AIR:0,100)
RandomBlock(-7,0,0,CONCRETE:8,65,QUARK:IRON_PLATE:0,10,QUARK:IRON_PLATE:1,10,STAINED_CLAY:9,15,STAINED_CLAY:7,10,CONCRETE:8,10,RUSTIC:IRON_LATTICE:1,15,RUSTIC:IRON_LATTICE:0,15,LEAVES:4,70,CONCRETE:8,80,AIR:0,100)
RandomBlock(-7,0,1,CONCRETE:8,65,QUARK:IRON_PLATE:0,10,QUARK:IRON_PLATE:1,10,STAINED_CLAY:9,15,STAINED_CLAY:7,10,CONCRETE:8,10,RUSTIC:IRON_LATTICE:1,15,RUSTIC:IRON_LATTICE:0,15,LEAVES:4,70,CONCRETE:8,80,AIR:0,100)
RandomBlock(-7,0,2,CONCRETE:8,65,QUARK:IRON_PLATE:0,10,QUARK:IRON_PLATE:1,10,STAINED_CLAY:9,15,STAINED_CLAY:7,10,CONCRETE:8,10,RUSTIC:IRON_LATTICE:1,15,RUSTIC:IRON_LATTICE:0,15,LEAVES:4,70,CONCRETE:8,80,AIR:0,100)
RandomBlock(-7,0,3,CONCRETE:8,65,QUARK:IRON_PLATE:0,10,QUARK:IRON_PLATE:1,10,STAINED_CLAY:9,15,STAINED_CLAY:7,10,CONCRETE:8,10,RUSTIC:IRON_LATTICE:1,15,RUSTIC:IRON_LATTICE:0,15,LEAVES:4,70,CONCRETE:8,80,AIR:0,100)
RandomBlock(-7,0,4,CONCRETE:8,65,QUARK:IRON_PLATE:0,10,QUARK:IRON_PLATE:1,10,STAINED_CLAY:9,15,STAINED_CLAY:7,10,CONCRETE:8,10,RUSTIC:IRON_LATTICE:1,15,RUSTIC:IRON_LATTICE:0,15,LEAVES:4,70,CONCRETE:8,80,AIR:0,100)
RandomBlock(-7,0,5,CONCRETE:8,65,QUARK:IRON_PLATE:0,10,QUARK:IRON_PLATE:1,10,STAINED_CLAY:9,15,STAINED_CLAY:7,10,CONCRETE:8,10,RUSTIC:IRON_LATTICE:1,15,RUSTIC:IRON_LATTICE:0,15,LEAVES:4,70,CONCRETE:8,80,AIR:0,100)
RandomBlock(-7,0,6,CONCRETE:8,65,QUARK:IRON_PLATE:0,10,QUARK:IRON_PLATE:1,10,STAINED_CLAY:9,15,STAINED_CLAY:7,10,CONCRETE:8,10,RUSTIC:IRON_LATTICE:1,15,RUSTIC:IRON_LATTICE:0,15,LEAVES:4,70,CONCRETE:8,80,AIR:0,100)
RandomBlock(-7,0,7,CONCRETE:8,65,QUARK:IRON_PLATE:0,10,QUARK:IRON_PLATE:1,10,STAINED_CLAY:9,15,STAINED_CLAY:7,10,CONCRETE:8,10,RUSTIC:IRON_LATTICE:1,15,RUSTIC:IRON_LATTICE:0,15,LEAVES:4,70,CONCRETE:8,80,AIR:0,100)
RandomBlock(-7,0,8,CONCRETE:8,65,QUARK:IRON_PLATE:0,10,QUARK:IRON_PLATE:1,10,STAINED_CLAY:9,15,STAINED_CLAY:7,10,CONCRETE:8,10,RUSTIC:IRON_LATTICE:1,15,RUSTIC:IRON_LATTICE:0,15,LEAVES:4,70,CONCRETE:8,80,AIR:0,100)
RandomBlock(-7,0,9,CONCRETE:8,65,QUARK:IRON_PLATE:0,10,QUARK:IRON_PLATE:1,10,STAINED_CLAY:9,15,STAINED_CLAY:7,10,CONCRETE:8,10,RUSTIC:IRON_LATTICE:1,15,RUSTIC:IRON_LATTICE:0,15,LEAVES:4,70,CONCRETE:8,80,AIR:0,100)
RandomBlock(-7,1,-6,CONCRETE:8,65,QUARK:IRON_PLATE:0,10,QUARK:IRON_PLATE:1,10,STAINED_CLAY:9,15,STAINED_CLAY:7,10,CONCRETE:8,10,RUSTIC:IRON_LATTICE:1,15,RUSTIC:IRON_LATTICE:0,15,LEAVES:4,70,CONCRETE:8,80,AIR:0,100)
RandomBlock(-7,1,-5,CONCRETE:7,65,QUARK:IRON_PLATE:0,10,QUARK:IRON_PLATE:1,10,STAINED_CLAY:15,10,STAINED_CLAY:9,70,RUSTIC:IRON_LATTICE:1,5,RUSTIC:IRON_LATTICE:0,5,LEAVES:4,40,STAINED_CLAY:9,100)
RandomBlock(-7,1,-4,CONCRETE:7,65,QUARK:IRON_PLATE:0,10,QUARK:IRON_PLATE:1,10,STAINED_CLAY:15,10,STAINED_CLAY:9,70,RUSTIC:IRON_LATTICE:1,5,RUSTIC:IRON_LATTICE:0,5,LEAVES:4,40,STAINED_CLAY:9,100)
RandomBlock(-7,1,-3,CONCRETE:8,65,QUARK:IRON_PLATE:0,10,QUARK:IRON_PLATE:1,10,STAINED_CLAY:9,15,STAINED_CLAY:7,10,CONCRETE:8,10,RUSTIC:IRON_LATTICE:1,15,RUSTIC:IRON_LATTICE:0,15,LEAVES:4,70,CONCRETE:8,80,AIR:0,100)
RandomBlock(-7,1,-2,CONCRETE:7,65,QUARK:IRON_PLATE:0,10,QUARK:IRON_PLATE:1,10,STAINED_CLAY:15,10,STAINED_CLAY:9,70,RUSTIC:IRON_LATTICE:1,5,RUSTIC:IRON_LATTICE:0,5,LEAVES:4,40,STAINED_CLAY:9,100)
RandomBlock(-7,1,-1,CONCRETE:7,65,QUARK:IRON_PLATE:0,10,QUARK:IRON_PLATE:1,10,STAINED_CLAY:15,10,STAINED_CLAY:9,70,RUSTIC:IRON_LATTICE:1,5,RUSTIC:IRON_LATTICE:0,5,LEAVES:4,40,STAINED_CLAY:9,100)
RandomBlock(-7,1,0,CONCRETE:8,65,QUARK:IRON_PLATE:0,10,QUARK:IRON_PLATE:1,10,STAINED_CLAY:9,15,STAINED_CLAY:7,10,CONCRETE:8,10,RUSTIC:IRON_LATTICE:1,15,RUSTIC:IRON_LATTICE:0,15,LEAVES:4,70,CONCRETE:8,80,AIR:0,100)
RandomBlock(-7,1,1,CONCRETE:7,65,QUARK:IRON_PLATE:0,10,QUARK:IRON_PLATE:1,10,STAINED_CLAY:15,10,STAINED_CLAY:9,70,RUSTIC:IRON_LATTICE:1,5,RUSTIC:IRON_LATTICE:0,5,LEAVES:4,40,STAINED_CLAY:9,100)
RandomBlock(-7,1,2,CONCRETE:7,65,QUARK:IRON_PLATE:0,10,QUARK:IRON_PLATE:1,10,STAINED_CLAY:15,10,STAINED_CLAY:9,70,RUSTIC:IRON_LATTICE:1,5,RUSTIC:IRON_LATTICE:0,5,LEAVES:4,40,STAINED_CLAY:9,100)
RandomBlock(-7,1,3,CONCRETE:8,65,QUARK:IRON_PLATE:0,10,QUARK:IRON_PLATE:1,10,STAINED_CLAY:9,15,STAINED_CLAY:7,10,CONCRETE:8,10,RUSTIC:IRON_LATTICE:1,15,RUSTIC:IRON_LATTICE:0,15,LEAVES:4,70,CONCRETE:8,80,AIR:0,100)
RandomBlock(-7,1,4,CONCRETE:7,65,QUARK:IRON_PLATE:0,10,QUARK:IRON_PLATE:1,10,STAINED_CLAY:15,10,STAINED_CLAY:9,70,RUSTIC:IRON_LATTICE:1,5,RUSTIC:IRON_LATTICE:0,5,LEAVES:4,40,STAINED_CLAY:9,100)
RandomBlock(-7,1,5,CONCRETE:7,65,QUARK:IRON_PLATE:0,10,QUARK:IRON_PLATE:1,10,STAINED_CLAY:15,10,STAINED_CLAY:9,70,RUSTIC:IRON_LATTICE:1,5,RUSTIC:IRON_LATTICE:0,5,LEAVES:4,40,STAINED_CLAY:9,100)
RandomBlock(-7,1,6,CONCRETE:8,65,QUARK:IRON_PLATE:0,10,QUARK:IRON_PLATE:1,10,STAINED_CLAY:9,15,STAINED_CLAY:7,10,CONCRETE:8,10,RUSTIC:IRON_LATTICE:1,15,RUSTIC:IRON_LATTICE:0,15,LEAVES:4,70,CONCRETE:8,80,AIR:0,100)
RandomBlock(-7,1,7,CONCRETE:7,65,QUARK:IRON_PLATE:0,10,QUARK:IRON_PLATE:1,10,STAINED_CLAY:15,10,STAINED_CLAY:9,70,RUSTIC:IRON_LATTICE:1,5,RUSTIC:IRON_LATTICE:0,5,LEAVES:4,40,STAINED_CLAY:9,100)
RandomBlock(-7,1,8,CONCRETE:7,65,QUARK:IRON_PLATE:0,10,QUARK:IRON_PLATE:1,10,STAINED_CLAY:15,10,STAINED_CLAY:9,70,RUSTIC:IRON_LATTICE:1,5,RUSTIC:IRON_LATTICE:0,5,LEAVES:4,40,STAINED_CLAY:9,100)
RandomBlock(-7,1,9,CONCRETE:8,65,QUARK:IRON_PLATE:0,10,QUARK:IRON_PLATE:1,10,STAINED_CLAY:9,15,STAINED_CLAY:7,10,CONCRETE:8,10,RUSTIC:IRON_LATTICE:1,15,RUSTIC:IRON_LATTICE:0,15,LEAVES:4,70,CONCRETE:8,80,AIR:0,100)
RandomBlock(-7,2,-6,CONCRETE:8,65,QUARK:IRON_PLATE:0,10,QUARK:IRON_PLATE:1,10,STAINED_CLAY:9,15,STAINED_CLAY:7,10,CONCRETE:8,10,RUSTIC:IRON_LATTICE:1,15,RUSTIC:IRON_LATTICE:0,15,LEAVES:4,70,CONCRETE:8,80,AIR:0,100)
RandomBlock(-7,2,-5,CONCRETE:7,65,QUARK:IRON_PLATE:0,10,QUARK:IRON_PLATE:1,10,STAINED_CLAY:15,10,STAINED_CLAY:9,70,RUSTIC:IRON_LATTICE:1,5,RUSTIC:IRON_LATTICE:0,5,LEAVES:4,40,STAINED_CLAY:9,100)
RandomBlock(-7,2,-4,CONCRETE:7,65,QUARK:IRON_PLATE:0,10,QUARK:IRON_PLATE:1,10,STAINED_CLAY:15,10,STAINED_CLAY:9,70,RUSTIC:IRON_LATTICE:1,5,RUSTIC:IRON_LATTICE:0,5,LEAVES:4,40,STAINED_CLAY:9,100)
RandomBlock(-7,2,-3,CONCRETE:8,65,QUARK:IRON_PLATE:0,10,QUARK:IRON_PLATE:1,10,STAINED_CLAY:9,15,STAINED_CLAY:7,10,CONCRETE:8,10,RUSTIC:IRON_LATTICE:1,15,RUSTIC:IRON_LATTICE:0,15,LEAVES:4,70,CONCRETE:8,80,AIR:0,100)
RandomBlock(-7,2,-2,CONCRETE:7,65,QUARK:IRON_PLATE:0,10,QUARK:IRON_PLATE:1,10,STAINED_CLAY:15,10,STAINED_CLAY:9,70,RUSTIC:IRON_LATTICE:1,5,RUSTIC:IRON_LATTICE:0,5,LEAVES:4,40,STAINED_CLAY:9,100)
RandomBlock(-7,2,-1,CONCRETE:7,65,QUARK:IRON_PLATE:0,10,QUARK:IRON_PLATE:1,10,STAINED_CLAY:15,10,STAINED_CLAY:9,70,RUSTIC:IRON_LATTICE:1,5,RUSTIC:IRON_LATTICE:0,5,LEAVES:4,40,STAINED_CLAY:9,100)
RandomBlock(-7,2,0,CONCRETE:8,65,QUARK:IRON_PLATE:0,10,QUARK:IRON_PLATE:1,10,STAINED_CLAY:9,15,STAINED_CLAY:7,10,CONCRETE:8,10,RUSTIC:IRON_LATTICE:1,15,RUSTIC:IRON_LATTICE:0,15,LEAVES:4,70,CONCRETE:8,80,AIR:0,100)
RandomBlock(-7,2,1,CONCRETE:7,65,QUARK:IRON_PLATE:0,10,QUARK:IRON_PLATE:1,10,STAINED_CLAY:15,10,STAINED_CLAY:9,70,RUSTIC:IRON_LATTICE:1,5,RUSTIC:IRON_LATTICE:0,5,LEAVES:4,40,STAINED_CLAY:9,100)
RandomBlock(-7,2,2,CONCRETE:7,65,QUARK:IRON_PLATE:0,10,QUARK:IRON_PLATE:1,10,STAINED_CLAY:15,10,STAINED_CLAY:9,70,RUSTIC:IRON_LATTICE:1,5,RUSTIC:IRON_LATTICE:0,5,LEAVES:4,40,STAINED_CLAY:9,100)
RandomBlock(-7,2,3,CONCRETE:8,65,QUARK:IRON_PLATE:0,10,QUARK:IRON_PLATE:1,10,STAINED_CLAY:9,15,STAINED_CLAY:7,10,CONCRETE:8,10,RUSTIC:IRON_LATTICE:1,15,RUSTIC:IRON_LATTICE:0,15,LEAVES:4,70,CONCRETE:8,80,AIR:0,100)
RandomBlock(-7,2,4,CONCRETE:7,65,QUARK:IRON_PLATE:0,10,QUARK:IRON_PLATE:1,10,STAINED_CLAY:15,10,STAINED_CLAY:9,70,RUSTIC:IRON_LATTICE:1,5,RUSTIC:IRON_LATTICE:0,5,LEAVES:4,40,STAINED_CLAY:9,100)
RandomBlock(-7,2,5,CONCRETE:7,65,QUARK:IRON_PLATE:0,10,QUARK:IRON_PLATE:1,10,STAINED_CLAY:15,10,STAINED_CLAY:9,70,RUSTIC:IRON_LATTICE:1,5,RUSTIC:IRON_LATTICE:0,5,LEAVES:4,40,STAINED_CLAY:9,100)
RandomBlock(-7,2,6,CONCRETE:8,65,QUARK:IRON_PLATE:0,10,QUARK:IRON_PLATE:1,10,STAINED_CLAY:9,15,STAINED_CLAY:7,10,CONCRETE:8,10,RUSTIC:IRON_LATTICE:1,15,RUSTIC:IRON_LATTICE:0,15,LEAVES:4,70,CONCRETE:8,80,AIR:0,100)
RandomBlock(-7,2,7,CONCRETE:7,65,QUARK:IRON_PLATE:0,10,QUARK:IRON_PLATE:1,10,STAINED_CLAY:15,10,STAINED_CLAY:9,70,RUSTIC:IRON_LATTICE:1,5,RUSTIC:IRON_LATTICE:0,5,LEAVES:4,40,STAINED_CLAY:9,100)
RandomBlock(-7,2,8,CONCRETE:7,65,QUARK:IRON_PLATE:0,10,QUARK:IRON_PLATE:1,10,STAINED_CLAY:15,10,STAINED_CLAY:9,70,RUSTIC:IRON_LATTICE:1,5,RUSTIC:IRON_LATTICE:0,5,LEAVES:4,40,STAINED_CLAY:9,100)
RandomBlock(-7,2,9,CONCRETE:8,65,QUARK:IRON_PLATE:0,10,QUARK:IRON_PLATE:1,10,STAINED_CLAY:9,15,STAINED_CLAY:7,10,CONCRETE:8,10,RUSTIC:IRON_LATTICE:1,15,RUSTIC:IRON_LATTICE:0,15,LEAVES:4,70,CONCRETE:8,80,AIR:0,100)
RandomBlock(-7,3,-6,CONCRETE:8,65,QUARK:IRON_PLATE:0,10,QUARK:IRON_PLATE:1,10,STAINED_CLAY:9,15,STAINED_CLAY:7,10,CONCRETE:8,10,RUSTIC:IRON_LATTICE:1,15,RUSTIC:IRON_LATTICE:0,15,LEAVES:4,70,CONCRETE:8,80,AIR:0,100)
RandomBlock(-7,3,-5,CONCRETE:7,65,QUARK:IRON_PLATE:0,10,QUARK:IRON_PLATE:1,10,STAINED_CLAY:15,10,STAINED_CLAY:9,70,RUSTIC:IRON_LATTICE:1,5,RUSTIC:IRON_LATTICE:0,5,LEAVES:4,40,STAINED_CLAY:9,100)
RandomBlock(-7,3,-4,CONCRETE:7,65,QUARK:IRON_PLATE:0,10,QUARK:IRON_PLATE:1,10,STAINED_CLAY:15,10,STAINED_CLAY:9,70,RUSTIC:IRON_LATTICE:1,5,RUSTIC:IRON_LATTICE:0,5,LEAVES:4,40,STAINED_CLAY:9,100)
RandomBlock(-7,3,-3,CONCRETE:8,65,QUARK:IRON_PLATE:0,10,QUARK:IRON_PLATE:1,10,STAINED_CLAY:9,15,STAINED_CLAY:7,10,CONCRETE:8,10,RUSTIC:IRON_LATTICE:1,15,RUSTIC:IRON_LATTICE:0,15,LEAVES:4,70,CONCRETE:8,80,AIR:0,100)
RandomBlock(-7,3,-2,CONCRETE:7,65,QUARK:IRON_PLATE:0,10,QUARK:IRON_PLATE:1,10,STAINED_CLAY:15,10,STAINED_CLAY:9,70,RUSTIC:IRON_LATTICE:1,5,RUSTIC:IRON_LATTICE:0,5,LEAVES:4,40,STAINED_CLAY:9,100)
RandomBlock(-7,3,-1,CONCRETE:7,65,QUARK:IRON_PLATE:0,10,QUARK:IRON_PLATE:1,10,STAINED_CLAY:15,10,STAINED_CLAY:9,70,RUSTIC:IRON_LATTICE:1,5,RUSTIC:IRON_LATTICE:0,5,LEAVES:4,40,STAINED_CLAY:9,100)
RandomBlock(-7,3,0,CONCRETE:8,65,QUARK:IRON_PLATE:0,10,QUARK:IRON_PLATE:1,10,STAINED_CLAY:9,15,STAINED_CLAY:7,10,CONCRETE:8,10,RUSTIC:IRON_LATTICE:1,15,RUSTIC:IRON_LATTICE:0,15,LEAVES:4,70,CONCRETE:8,80,AIR:0,100)
RandomBlock(-7,3,1,CONCRETE:7,65,QUARK:IRON_PLATE:0,10,QUARK:IRON_PLATE:1,10,STAINED_CLAY:15,10,STAINED_CLAY:9,70,RUSTIC:IRON_LATTICE:1,5,RUSTIC:IRON_LATTICE:0,5,LEAVES:4,40,STAINED_CLAY:9,100)
RandomBlock(-7,3,2,CONCRETE:7,65,QUARK:IRON_PLATE:0,10,QUARK:IRON_PLATE:1,10,STAINED_CLAY:15,10,STAINED_CLAY:9,70,RUSTIC:IRON_LATTICE:1,5,RUSTIC:IRON_LATTICE:0,5,LEAVES:4,40,STAINED_CLAY:9,100)
RandomBlock(-7,3,3,CONCRETE:8,65,QUARK:IRON_PLATE:0,10,QUARK:IRON_PLATE:1,10,STAINED_CLAY:9,15,STAINED_CLAY:7,10,CONCRETE:8,10,RUSTIC:IRON_LATTICE:1,15,RUSTIC:IRON_LATTICE:0,15,LEAVES:4,70,CONCRETE:8,80,AIR:0,100)
RandomBlock(-7,3,4,CONCRETE:7,65,QUARK:IRON_PLATE:0,10,QUARK:IRON_PLATE:1,10,STAINED_CLAY:15,10,STAINED_CLAY:9,70,RUSTIC:IRON_LATTICE:1,5,RUSTIC:IRON_LATTICE:0,5,LEAVES:4,40,STAINED_CLAY:9,100)
RandomBlock(-7,3,5,CONCRETE:7,65,QUARK:IRON_PLATE:0,10,QUARK:IRON_PLATE:1,10,STAINED_CLAY:15,10,STAINED_CLAY:9,70,RUSTIC:IRON_LATTICE:1,5,RUSTIC:IRON_LATTICE:0,5,LEAVES:4,40,STAINED_CLAY:9,100)
RandomBlock(-7,3,6,CONCRETE:8,65,QUARK:IRON_PLATE:0,10,QUARK:IRON_PLATE:1,10,STAINED_CLAY:9,15,STAINED_CLAY:7,10,CONCRETE:8,10,RUSTIC:IRON_LATTICE:1,15,RUSTIC:IRON_LATTICE:0,15,LEAVES:4,70,CONCRETE:8,80,AIR:0,100)
RandomBlock(-7,3,7,CONCRETE:7,65,QUARK:IRON_PLATE:0,10,QUARK:IRON_PLATE:1,10,STAINED_CLAY:15,10,STAINED_CLAY:9,70,RUSTIC:IRON_LATTICE:1,5,RUSTIC:IRON_LATTICE:0,5,LEAVES:4,40,STAINED_CLAY:9,100)
RandomBlock(-7,3,8,CONCRETE:7,65,QUARK:IRON_PLATE:0,10,QUARK:IRON_PLATE:1,10,STAINED_CLAY:15,10,STAINED_CLAY:9,70,RUSTIC:IRON_LATTICE:1,5,RUSTIC:IRON_LATTICE:0,5,LEAVES:4,40,STAINED_CLAY:9,100)
RandomBlock(-7,3,9,CONCRETE:8,65,QUARK:IRON_PLATE:0,10,QUARK:IRON_PLATE:1,10,STAINED_CLAY:9,15,STAINED_CLAY:7,10,CONCRETE:8,10,RUSTIC:IRON_LATTICE:1,15,RUSTIC:IRON_LATTICE:0,15,LEAVES:4,70,CONCRETE:8,80,AIR:0,100)
RandomBlock(-7,4,-6,CONCRETE:8,65,QUARK:IRON_PLATE:0,10,QUARK:IRON_PLATE:1,10,STAINED_CLAY:9,15,STAINED_CLAY:7,10,CONCRETE:8,10,RUSTIC:IRON_LATTICE:1,15,RUSTIC:IRON_LATTICE:0,15,LEAVES:4,70,CONCRETE:8,80,AIR:0,100)
RandomBlock(-7,4,-5,CONCRETE:7,65,QUARK:IRON_PLATE:0,10,QUARK:IRON_PLATE:1,10,STAINED_CLAY:15,10,STAINED_CLAY:9,70,RUSTIC:IRON_LATTICE:1,5,RUSTIC:IRON_LATTICE:0,5,LEAVES:4,40,STAINED_CLAY:9,100)
RandomBlock(-7,4,-4,CONCRETE:7,65,QUARK:IRON_PLATE:0,10,QUARK:IRON_PLATE:1,10,STAINED_CLAY:15,10,STAINED_CLAY:9,70,RUSTIC:IRON_LATTICE:1,5,RUSTIC:IRON_LATTICE:0,5,LEAVES:4,40,STAINED_CLAY:9,100)
RandomBlock(-7,4,-3,CONCRETE:8,65,QUARK:IRON_PLATE:0,10,QUARK:IRON_PLATE:1,10,STAINED_CLAY:9,15,STAINED_CLAY:7,10,CONCRETE:8,10,RUSTIC:IRON_LATTICE:1,15,RUSTIC:IRON_LATTICE:0,15,LEAVES:4,70,CONCRETE:8,80,AIR:0,100)
RandomBlock(-7,4,-2,CONCRETE:7,65,QUARK:IRON_PLATE:0,10,QUARK:IRON_PLATE:1,10,STAINED_CLAY:15,10,STAINED_CLAY:9,70,RUSTIC:IRON_LATTICE:1,5,RUSTIC:IRON_LATTICE:0,5,LEAVES:4,40,STAINED_CLAY:9,100)
RandomBlock(-7,4,-1,CONCRETE:7,65,QUARK:IRON_PLATE:0,10,QUARK:IRON_PLATE:1,10,STAINED_CLAY:15,10,STAINED_CLAY:9,70,RUSTIC:IRON_LATTICE:1,5,RUSTIC:IRON_LATTICE:0,5,LEAVES:4,40,STAINED_CLAY:9,100)
RandomBlock(-7,4,0,CONCRETE:8,65,QUARK:IRON_PLATE:0,10,QUARK:IRON_PLATE:1,10,STAINED_CLAY:9,15,STAINED_CLAY:7,10,CONCRETE:8,10,RUSTIC:IRON_LATTICE:1,15,RUSTIC:IRON_LATTICE:0,15,LEAVES:4,70,CONCRETE:8,80,AIR:0,100)
RandomBlock(-7,4,1,CONCRETE:7,65,QUARK:IRON_PLATE:0,10,QUARK:IRON_PLATE:1,10,STAINED_CLAY:15,10,STAINED_CLAY:9,70,RUSTIC:IRON_LATTICE:1,5,RUSTIC:IRON_LATTICE:0,5,LEAVES:4,40,STAINED_CLAY:9,100)
RandomBlock(-7,4,2,CONCRETE:7,65,QUARK:IRON_PLATE:0,10,QUARK:IRON_PLATE:1,10,STAINED_CLAY:15,10,STAINED_CLAY:9,70,RUSTIC:IRON_LATTICE:1,5,RUSTIC:IRON_LATTICE:0,5,LEAVES:4,40,STAINED_CLAY:9,100)
RandomBlock(-7,4,3,CONCRETE:8,65,QUARK:IRON_PLATE:0,10,QUARK:IRON_PLATE:1,10,STAINED_CLAY:9,15,STAINED_CLAY:7,10,CONCRETE:8,10,RUSTIC:IRON_LATTICE:1,15,RUSTIC:IRON_LATTICE:0,15,LEAVES:4,70,CONCRETE:8,80,AIR:0,100)
RandomBlock(-7,4,4,CONCRETE:7,65,QUARK:IRON_PLATE:0,10,QUARK:IRON_PLATE:1,10,STAINED_CLAY:15,10,STAINED_CLAY:9,70,RUSTIC:IRON_LATTICE:1,5,RUSTIC:IRON_LATTICE:0,5,LEAVES:4,40,STAINED_CLAY:9,100)
RandomBlock(-7,4,5,CONCRETE:7,65,QUARK:IRON_PLATE:0,10,QUARK:IRON_PLATE:1,10,STAINED_CLAY:15,10,STAINED_CLAY:9,70,RUSTIC:IRON_LATTICE:1,5,RUSTIC:IRON_LATTICE:0,5,LEAVES:4,40,STAINED_CLAY:9,100)
RandomBlock(-7,4,6,CONCRETE:8,65,QUARK:IRON_PLATE:0,10,QUARK:IRON_PLATE:1,10,STAINED_CLAY:9,15,STAINED_CLAY:7,10,CONCRETE:8,10,RUSTIC:IRON_LATTICE:1,15,RUSTIC:IRON_LATTICE:0,15,LEAVES:4,70,CONCRETE:8,80,AIR:0,100)
RandomBlock(-7,4,7,CONCRETE:7,65,QUARK:IRON_PLATE:0,10,QUARK:IRON_PLATE:1,10,STAINED_CLAY:15,10,STAINED_CLAY:9,70,RUSTIC:IRON_LATTICE:1,5,RUSTIC:IRON_LATTICE:0,5,LEAVES:4,40,STAINED_CLAY:9,100)
RandomBlock(-7,4,8,CONCRETE:7,65,QUARK:IRON_PLATE:0,10,QUARK:IRON_PLATE:1,10,STAINED_CLAY:15,10,STAINED_CLAY:9,70,RUSTIC:IRON_LATTICE:1,5,RUSTIC:IRON_LATTICE:0,5,LEAVES:4,40,STAINED_CLAY:9,100)
RandomBlock(-7,4,9,CONCRETE:8,65,QUARK:IRON_PLATE:0,10,QUARK:IRON_PLATE:1,10,STAINED_CLAY:9,15,STAINED_CLAY:7,10,CONCRETE:8,10,RUSTIC:IRON_LATTICE:1,15,RUSTIC:IRON_LATTICE:0,15,LEAVES:4,70,CONCRETE:8,80,AIR:0,100)
RandomBlock(-6,0,-6,CONCRETE:8,65,QUARK:IRON_PLATE:0,10,QUARK:IRON_PLATE:1,10,STAINED_CLAY:9,15,STAINED_CLAY:7,10,CONCRETE:8,10,RUSTIC:IRON_LATTICE:1,15,RUSTIC:IRON_LATTICE:0,15,LEAVES:4,70,CONCRETE:8,80,AIR:0,100)
RandomBlock(-6,0,-5,CONCRETE:8,65,QUARK:IRON_PLATE:0,10,QUARK:IRON_PLATE:1,10,STAINED_CLAY:9,15,STAINED_CLAY:7,10,CONCRETE:8,10,RUSTIC:IRON_LATTICE:1,15,RUSTIC:IRON_LATTICE:0,15,LEAVES:4,70,CONCRETE:8,80,AIR:0,100)
RandomBlock(-6,0,-4,CONCRETE:8,65,QUARK:IRON_PLATE:0,10,QUARK:IRON_PLATE:1,10,STAINED_CLAY:9,15,STAINED_CLAY:7,10,CONCRETE:8,10,RUSTIC:IRON_LATTICE:1,15,RUSTIC:IRON_LATTICE:0,15,LEAVES:4,70,CONCRETE:8,80,AIR:0,100)
RandomBlock(-6,0,-3,CONCRETE:8,65,QUARK:IRON_PLATE:0,10,QUARK:IRON_PLATE:1,10,STAINED_CLAY:9,15,STAINED_CLAY:7,10,CONCRETE:8,10,RUSTIC:IRON_LATTICE:1,15,RUSTIC:IRON_LATTICE:0,15,LEAVES:4,70,CONCRETE:8,80,AIR:0,100)
RandomBlock(-6,0,-2,CONCRETE:8,65,QUARK:IRON_PLATE:0,10,QUARK:IRON_PLATE:1,10,STAINED_CLAY:9,15,STAINED_CLAY:7,10,CONCRETE:8,10,RUSTIC:IRON_LATTICE:1,15,RUSTIC:IRON_LATTICE:0,15,LEAVES:4,70,CONCRETE:8,80,AIR:0,100)
RandomBlock(-6,0,-1,CONCRETE:8,65,QUARK:IRON_PLATE:0,10,QUARK:IRON_PLATE:1,10,STAINED_CLAY:9,15,STAINED_CLAY:7,10,CONCRETE:8,10,RUSTIC:IRON_LATTICE:1,15,RUSTIC:IRON_LATTICE:0,15,LEAVES:4,70,CONCRETE:8,80,AIR:0,100)
RandomBlock(-6,0,0,CONCRETE:8,65,QUARK:IRON_PLATE:0,10,QUARK:IRON_PLATE:1,10,STAINED_CLAY:9,15,STAINED_CLAY:7,10,CONCRETE:8,10,RUSTIC:IRON_LATTICE:1,15,RUSTIC:IRON_LATTICE:0,15,LEAVES:4,70,CONCRETE:8,80,AIR:0,100)
RandomBlock(-6,0,1,CONCRETE:8,65,QUARK:IRON_PLATE:0,10,QUARK:IRON_PLATE:1,10,STAINED_CLAY:9,15,STAINED_CLAY:7,10,CONCRETE:8,10,RUSTIC:IRON_LATTICE:1,15,RUSTIC:IRON_LATTICE:0,15,LEAVES:4,70,CONCRETE:8,80,AIR:0,100)
RandomBlock(-6,0,2,CONCRETE:8,65,QUARK:IRON_PLATE:0,10,QUARK:IRON_PLATE:1,10,STAINED_CLAY:9,15,STAINED_CLAY:7,10,CONCRETE:8,10,RUSTIC:IRON_LATTICE:1,15,RUSTIC:IRON_LATTICE:0,15,LEAVES:4,70,CONCRETE:8,80,AIR:0,100)
RandomBlock(-6,0,3,CONCRETE:8,65,QUARK:IRON_PLATE:0,10,QUARK:IRON_PLATE:1,10,STAINED_CLAY:9,15,STAINED_CLAY:7,10,CONCRETE:8,10,RUSTIC:IRON_LATTICE:1,15,RUSTIC:IRON_LATTICE:0,15,LEAVES:4,70,CONCRETE:8,80,AIR:0,100)
RandomBlock(-6,0,4,CONCRETE:8,65,QUARK:IRON_PLATE:0,10,QUARK:IRON_PLATE:1,10,STAINED_CLAY:9,15,STAINED_CLAY:7,10,CONCRETE:8,10,RUSTIC:IRON_LATTICE:1,15,RUSTIC:IRON_LATTICE:0,15,LEAVES:4,70,CONCRETE:8,80,AIR:0,100)
RandomBlock(-6,0,5,CONCRETE:8,65,QUARK:IRON_PLATE:0,10,QUARK:IRON_PLATE:1,10,STAINED_CLAY:9,15,STAINED_CLAY:7,10,CONCRETE:8,10,RUSTIC:IRON_LATTICE:1,15,RUSTIC:IRON_LATTICE:0,15,LEAVES:4,70,CONCRETE:8,80,AIR:0,100)
RandomBlock(-6,0,6,CONCRETE:8,65,QUARK:IRON_PLATE:0,10,QUARK:IRON_PLATE:1,10,STAINED_CLAY:9,15,STAINED_CLAY:7,10,CONCRETE:8,10,RUSTIC:IRON_LATTICE:1,15,RUSTIC:IRON_LATTICE:0,15,LEAVES:4,70,CONCRETE:8,80,AIR:0,100)
RandomBlock(-6,0,7,CONCRETE:8,65,QUARK:IRON_PLATE:0,10,QUARK:IRON_PLATE:1,10,STAINED_CLAY:9,15,STAINED_CLAY:7,10,CONCRETE:8,10,RUSTIC:IRON_LATTICE:1,15,RUSTIC:IRON_LATTICE:0,15,LEAVES:4,70,CONCRETE:8,80,AIR:0,100)
RandomBlock(-6,0,8,CONCRETE:8,65,QUARK:IRON_PLATE:0,10,QUARK:IRON_PLATE:1,10,STAINED_CLAY:9,15,STAINED_CLAY:7,10,CONCRETE:8,10,RUSTIC:IRON_LATTICE:1,15,RUSTIC:IRON_LATTICE:0,15,LEAVES:4,70,CONCRETE:8,80,AIR:0,100)
RandomBlock(-6,0,9,CONCRETE:8,65,QUARK:IRON_PLATE:0,10,QUARK:IRON_PLATE:1,10,STAINED_CLAY:9,15,STAINED_CLAY:7,10,CONCRETE:8,10,RUSTIC:IRON_LATTICE:1,15,RUSTIC:IRON_LATTICE:0,15,LEAVES:4,70,CONCRETE:8,80,AIR:0,100)
RandomBlock(-6,1,-6,CONCRETE:7,65,QUARK:IRON_PLATE:0,10,QUARK:IRON_PLATE:1,10,STAINED_CLAY:15,10,STAINED_CLAY:9,70,RUSTIC:IRON_LATTICE:1,5,RUSTIC:IRON_LATTICE:0,5,LEAVES:4,40,STAINED_CLAY:9,100)
RandomBlock(-6,1,-5,CONCRETE:8,65,QUARK:IRON_PLATE:0,10,QUARK:IRON_PLATE:1,10,STAINED_CLAY:9,15,STAINED_CLAY:7,10,CONCRETE:8,10,RUSTIC:IRON_LATTICE:1,15,RUSTIC:IRON_LATTICE:0,15,LEAVES:4,70,CONCRETE:8,80,AIR:0,100)
RandomBlock(-6,1,-4,CONCRETE:8,65,QUARK:IRON_PLATE:0,10,QUARK:IRON_PLATE:1,10,STAINED_CLAY:9,15,STAINED_CLAY:7,10,CONCRETE:8,10,RUSTIC:IRON_LATTICE:1,15,RUSTIC:IRON_LATTICE:0,15,LEAVES:4,70,CONCRETE:8,80,AIR:0,100)
RandomBlock(-6,1,-3,CONCRETE:8,65,QUARK:IRON_PLATE:0,10,QUARK:IRON_PLATE:1,10,STAINED_CLAY:9,15,STAINED_CLAY:7,10,CONCRETE:8,10,RUSTIC:IRON_LATTICE:1,15,RUSTIC:IRON_LATTICE:0,15,LEAVES:4,70,CONCRETE:8,80,AIR:0,100)
Block(-6,1,-2,QUARTZ_STAIRS:3)
Block(-6,1,-1,AIR:0)
RandomBlock(-6,1,0,CONCRETE:8,65,QUARK:IRON_PLATE:0,10,QUARK:IRON_PLATE:1,10,STAINED_CLAY:9,15,STAINED_CLAY:7,10,CONCRETE:8,10,RUSTIC:IRON_LATTICE:1,15,RUSTIC:IRON_LATTICE:0,15,LEAVES:4,70,CONCRETE:8,80,AIR:0,100)
Block(-6,1,1,SEA_LANTERN:0)
Block(-6,1,2,SEA_LANTERN:0)
RandomBlock(-6,1,3,CONCRETE:8,65,QUARK:IRON_PLATE:0,10,QUARK:IRON_PLATE:1,10,STAINED_CLAY:9,15,STAINED_CLAY:7,10,CONCRETE:8,10,RUSTIC:IRON_LATTICE:1,15,RUSTIC:IRON_LATTICE:0,15,LEAVES:4,70,CONCRETE:8,80,AIR:0,100)
Block(-6,1,4,SEA_LANTERN:0)
Block(-6,1,5,SEA_LANTERN:0)
RandomBlock(-6,1,6,CONCRETE:8,65,QUARK:IRON_PLATE:0,10,QUARK:IRON_PLATE:1,10,STAINED_CLAY:9,15,STAINED_CLAY:7,10,CONCRETE:8,10,RUSTIC:IRON_LATTICE:1,15,RUSTIC:IRON_LATTICE:0,15,LEAVES:4,70,CONCRETE:8,80,AIR:0,100)
Block(-6,1,7,SEA_LANTERN:0)
Block(-6,1,8,SEA_LANTERN:0)
RandomBlock(-6,1,9,CONCRETE:7,65,QUARK:IRON_PLATE:0,10,QUARK:IRON_PLATE:1,10,STAINED_CLAY:15,10,STAINED_CLAY:9,70,RUSTIC:IRON_LATTICE:1,5,RUSTIC:IRON_LATTICE:0,5,LEAVES:4,40,STAINED_CLAY:9,100)
RandomBlock(-6,2,-6,CONCRETE:7,65,QUARK:IRON_PLATE:0,10,QUARK:IRON_PLATE:1,10,STAINED_CLAY:15,10,STAINED_CLAY:9,70,RUSTIC:IRON_LATTICE:1,5,RUSTIC:IRON_LATTICE:0,5,LEAVES:4,40,STAINED_CLAY:9,100)
Block(-6,2,-5,SEA_LANTERN:0)
RandomBlock(-6,2,-4,CONCRETE:8,65,QUARK:IRON_PLATE:0,10,QUARK:IRON_PLATE:1,10,STAINED_CLAY:9,15,STAINED_CLAY:7,10,CONCRETE:8,10,RUSTIC:IRON_LATTICE:1,15,RUSTIC:IRON_LATTICE:0,15,LEAVES:4,70,CONCRETE:8,80,AIR:0,100)
Block(-6,2,-3,QUARTZ_STAIRS:3)
Block(-6,2,-2,AIR:0)
Block(-6,2,-1,AIR:0)
RandomBlock(-6,2,0,CONCRETE:8,65,QUARK:IRON_PLATE:0,10,QUARK:IRON_PLATE:1,10,STAINED_CLAY:9,15,STAINED_CLAY:7,10,CONCRETE:8,10,RUSTIC:IRON_LATTICE:1,15,RUSTIC:IRON_LATTICE:0,15,LEAVES:4,70,CONCRETE:8,80,AIR:0,100)
Block(-6,2,1,STAINED_GLASS:15)
Block(-6,2,2,STAINED_GLASS:15)
RandomBlock(-6,2,3,CONCRETE:8,65,QUARK:IRON_PLATE:0,10,QUARK:IRON_PLATE:1,10,STAINED_CLAY:9,15,STAINED_CLAY:7,10,CONCRETE:8,10,RUSTIC:IRON_LATTICE:1,15,RUSTIC:IRON_LATTICE:0,15,LEAVES:4,70,CONCRETE:8,80,AIR:0,100)
Block(-6,2,4,STAINED_GLASS:15)
Block(-6,2,5,STAINED_GLASS:15)
RandomBlock(-6,2,6,CONCRETE:8,65,QUARK:IRON_PLATE:0,10,QUARK:IRON_PLATE:1,10,STAINED_CLAY:9,15,STAINED_CLAY:7,10,CONCRETE:8,10,RUSTIC:IRON_LATTICE:1,15,RUSTIC:IRON_LATTICE:0,15,LEAVES:4,70,CONCRETE:8,80,AIR:0,100)
Block(-6,2,7,STAINED_GLASS:15)
Block(-6,2,8,STAINED_GLASS:15)
RandomBlock(-6,2,9,CONCRETE:7,65,QUARK:IRON_PLATE:0,10,QUARK:IRON_PLATE:1,10,STAINED_CLAY:15,10,STAINED_CLAY:9,70,RUSTIC:IRON_LATTICE:1,5,RUSTIC:IRON_LATTICE:0,5,LEAVES:4,40,STAINED_CLAY:9,100)
RandomBlock(-6,3,-6,CONCRETE:7,65,QUARK:IRON_PLATE:0,10,QUARK:IRON_PLATE:1,10,STAINED_CLAY:15,10,STAINED_CLAY:9,70,RUSTIC:IRON_LATTICE:1,5,RUSTIC:IRON_LATTICE:0,5,LEAVES:4,40,STAINED_CLAY:9,100)
Block(-6,3,-5,AIR:0)
Block(-6,3,-4,AIR:0)
Block(-6,3,-3,AIR:0)
Block(-6,3,-2,AIR:0)
Block(-6,3,-1,AIR:0)
RandomBlock(-6,3,0,CONCRETE:8,65,QUARK:IRON_PLATE:0,10,QUARK:IRON_PLATE:1,10,STAINED_CLAY:9,15,STAINED_CLAY:7,10,CONCRETE:8,10,RUSTIC:IRON_LATTICE:1,15,RUSTIC:IRON_LATTICE:0,15,LEAVES:4,70,CONCRETE:8,80,AIR:0,100)
Block(-6,3,1,STAINED_GLASS:15)
Block(-6,3,2,STAINED_GLASS:15)
RandomBlock(-6,3,3,CONCRETE:8,65,QUARK:IRON_PLATE:0,10,QUARK:IRON_PLATE:1,10,STAINED_CLAY:9,15,STAINED_CLAY:7,10,CONCRETE:8,10,RUSTIC:IRON_LATTICE:1,15,RUSTIC:IRON_LATTICE:0,15,LEAVES:4,70,CONCRETE:8,80,AIR:0,100)
Block(-6,3,4,STAINED_GLASS:15)
Block(-6,3,5,STAINED_GLASS:15)
RandomBlock(-6,3,6,CONCRETE:8,65,QUARK:IRON_PLATE:0,10,QUARK:IRON_PLATE:1,10,STAINED_CLAY:9,15,STAINED_CLAY:7,10,CONCRETE:8,10,RUSTIC:IRON_LATTICE:1,15,RUSTIC:IRON_LATTICE:0,15,LEAVES:4,70,CONCRETE:8,80,AIR:0,100)
Block(-6,3,7,STAINED_GLASS:15)
Block(-6,3,8,STAINED_GLASS:15)
RandomBlock(-6,3,9,CONCRETE:7,65,QUARK:IRON_PLATE:0,10,QUARK:IRON_PLATE:1,10,STAINED_CLAY:15,10,STAINED_CLAY:9,70,RUSTIC:IRON_LATTICE:1,5,RUSTIC:IRON_LATTICE:0,5,LEAVES:4,40,STAINED_CLAY:9,100)
RandomBlock(-6,4,-6,CONCRETE:7,65,QUARK:IRON_PLATE:0,10,QUARK:IRON_PLATE:1,10,STAINED_CLAY:15,10,STAINED_CLAY:9,70,RUSTIC:IRON_LATTICE:1,5,RUSTIC:IRON_LATTICE:0,5,LEAVES:4,40,STAINED_CLAY:9,100)
Block(-6,4,-5,AIR:0)
Block(-6,4,-4,AIR:0)
Block(-6,4,-3,AIR:0)
Block(-6,4,-2,AIR:0)
Block(-6,4,-1,AIR:0)
RandomBlock(-6,4,0,CONCRETE:8,65,QUARK:IRON_PLATE:0,10,QUARK:IRON_PLATE:1,10,STAINED_CLAY:9,15,STAINED_CLAY:7,10,CONCRETE:8,10,RUSTIC:IRON_LATTICE:1,15,RUSTIC:IRON_LATTICE:0,15,LEAVES:4,70,CONCRETE:8,80,AIR:0,100)
RandomBlock(-6,4,1,CONCRETE:8,65,QUARK:IRON_PLATE:0,10,QUARK:IRON_PLATE:1,10,STAINED_CLAY:9,15,STAINED_CLAY:7,10,CONCRETE:8,10,RUSTIC:IRON_LATTICE:1,15,RUSTIC:IRON_LATTICE:0,15,LEAVES:4,70,CONCRETE:8,80,AIR:0,100)
RandomBlock(-6,4,2,CONCRETE:8,65,QUARK:IRON_PLATE:0,10,QUARK:IRON_PLATE:1,10,STAINED_CLAY:9,15,STAINED_CLAY:7,10,CONCRETE:8,10,RUSTIC:IRON_LATTICE:1,15,RUSTIC:IRON_LATTICE:0,15,LEAVES:4,70,CONCRETE:8,80,AIR:0,100)
RandomBlock(-6,4,3,CONCRETE:8,65,QUARK:IRON_PLATE:0,10,QUARK:IRON_PLATE:1,10,STAINED_CLAY:9,15,STAINED_CLAY:7,10,CONCRETE:8,10,RUSTIC:IRON_LATTICE:1,15,RUSTIC:IRON_LATTICE:0,15,LEAVES:4,70,CONCRETE:8,80,AIR:0,100)
RandomBlock(-6,4,4,CONCRETE:8,65,QUARK:IRON_PLATE:0,10,QUARK:IRON_PLATE:1,10,STAINED_CLAY:9,15,STAINED_CLAY:7,10,CONCRETE:8,10,RUSTIC:IRON_LATTICE:1,15,RUSTIC:IRON_LATTICE:0,15,LEAVES:4,70,CONCRETE:8,80,AIR:0,100)
RandomBlock(-6,4,5,CONCRETE:8,65,QUARK:IRON_PLATE:0,10,QUARK:IRON_PLATE:1,10,STAINED_CLAY:9,15,STAINED_CLAY:7,10,CONCRETE:8,10,RUSTIC:IRON_LATTICE:1,15,RUSTIC:IRON_LATTICE:0,15,LEAVES:4,70,CONCRETE:8,80,AIR:0,100)
RandomBlock(-6,4,6,CONCRETE:8,65,QUARK:IRON_PLATE:0,10,QUARK:IRON_PLATE:1,10,STAINED_CLAY:9,15,STAINED_CLAY:7,10,CONCRETE:8,10,RUSTIC:IRON_LATTICE:1,15,RUSTIC:IRON_LATTICE:0,15,LEAVES:4,70,CONCRETE:8,80,AIR:0,100)
RandomBlock(-6,4,7,CONCRETE:8,65,QUARK:IRON_PLATE:0,10,QUARK:IRON_PLATE:1,10,STAINED_CLAY:9,15,STAINED_CLAY:7,10,CONCRETE:8,10,RUSTIC:IRON_LATTICE:1,15,RUSTIC:IRON_LATTICE:0,15,LEAVES:4,70,CONCRETE:8,80,AIR:0,100)
Block(-6,4,8,SEA_LANTERN:0)
RandomBlock(-6,4,9,CONCRETE:7,65,QUARK:IRON_PLATE:0,10,QUARK:IRON_PLATE:1,10,STAINED_CLAY:15,10,STAINED_CLAY:9,70,RUSTIC:IRON_LATTICE:1,5,RUSTIC:IRON_LATTICE:0,5,LEAVES:4,40,STAINED_CLAY:9,100)
RandomBlock(-5,0,-6,CONCRETE:8,65,QUARK:IRON_PLATE:0,10,QUARK:IRON_PLATE:1,10,STAINED_CLAY:9,15,STAINED_CLAY:7,10,CONCRETE:8,10,RUSTIC:IRON_LATTICE:1,15,RUSTIC:IRON_LATTICE:0,15,LEAVES:4,70,CONCRETE:8,80,AIR:0,100)
RandomBlock(-5,0,-5,CONCRETE:8,65,QUARK:IRON_PLATE:0,10,QUARK:IRON_PLATE:1,10,STAINED_CLAY:9,15,STAINED_CLAY:7,10,CONCRETE:8,10,RUSTIC:IRON_LATTICE:1,15,RUSTIC:IRON_LATTICE:0,15,LEAVES:4,70,CONCRETE:8,80,AIR:0,100)
RandomBlock(-5,0,-4,CONCRETE:8,65,QUARK:IRON_PLATE:0,10,QUARK:IRON_PLATE:1,10,STAINED_CLAY:9,15,STAINED_CLAY:7,10,CONCRETE:8,10,RUSTIC:IRON_LATTICE:1,15,RUSTIC:IRON_LATTICE:0,15,LEAVES:4,70,CONCRETE:8,80,AIR:0,100)
RandomBlock(-5,0,-3,CONCRETE:8,65,QUARK:IRON_PLATE:0,10,QUARK:IRON_PLATE:1,10,STAINED_CLAY:9,15,STAINED_CLAY:7,10,CONCRETE:8,10,RUSTIC:IRON_LATTICE:1,15,RUSTIC:IRON_LATTICE:0,15,LEAVES:4,70,CONCRETE:8,80,AIR:0,100)
RandomBlock(-5,0,-2,CONCRETE:8,65,QUARK:IRON_PLATE:0,10,QUARK:IRON_PLATE:1,10,STAINED_CLAY:9,15,STAINED_CLAY:7,10,CONCRETE:8,10,RUSTIC:IRON_LATTICE:1,15,RUSTIC:IRON_LATTICE:0,15,LEAVES:4,70,CONCRETE:8,80,AIR:0,100)
RandomBlock(-5,0,-1,CONCRETE:8,65,QUARK:IRON_PLATE:0,10,QUARK:IRON_PLATE:1,10,STAINED_CLAY:9,15,STAINED_CLAY:7,10,CONCRETE:8,10,RUSTIC:IRON_LATTICE:1,15,RUSTIC:IRON_LATTICE:0,15,LEAVES:4,70,CONCRETE:8,80,AIR:0,100)
Block(-5,0,0,SEA_LANTERN:0)
RandomBlock(-5,0,1,CONCRETE:8,65,QUARK:IRON_PLATE:0,10,QUARK:IRON_PLATE:1,10,STAINED_CLAY:9,15,STAINED_CLAY:7,10,CONCRETE:8,10,RUSTIC:IRON_LATTICE:1,15,RUSTIC:IRON_LATTICE:0,15,LEAVES:4,70,CONCRETE:8,80,AIR:0,100)
RandomBlock(-5,0,2,CONCRETE:8,65,QUARK:IRON_PLATE:0,10,QUARK:IRON_PLATE:1,10,STAINED_CLAY:9,15,STAINED_CLAY:7,10,CONCRETE:8,10,RUSTIC:IRON_LATTICE:1,15,RUSTIC:IRON_LATTICE:0,15,LEAVES:4,70,CONCRETE:8,80,AIR:0,100)
RandomBlock(-5,0,3,CONCRETE:8,65,QUARK:IRON_PLATE:0,10,QUARK:IRON_PLATE:1,10,STAINED_CLAY:9,15,STAINED_CLAY:7,10,CONCRETE:8,10,RUSTIC:IRON_LATTICE:1,15,RUSTIC:IRON_LATTICE:0,15,LEAVES:4,70,CONCRETE:8,80,AIR:0,100)
RandomBlock(-5,0,4,CONCRETE:8,65,QUARK:IRON_PLATE:0,10,QUARK:IRON_PLATE:1,10,STAINED_CLAY:9,15,STAINED_CLAY:7,10,CONCRETE:8,10,RUSTIC:IRON_LATTICE:1,15,RUSTIC:IRON_LATTICE:0,15,LEAVES:4,70,CONCRETE:8,80,AIR:0,100)
RandomBlock(-5,0,5,CONCRETE:8,65,QUARK:IRON_PLATE:0,10,QUARK:IRON_PLATE:1,10,STAINED_CLAY:9,15,STAINED_CLAY:7,10,CONCRETE:8,10,RUSTIC:IRON_LATTICE:1,15,RUSTIC:IRON_LATTICE:0,15,LEAVES:4,70,CONCRETE:8,80,AIR:0,100)
RandomBlock(-5,0,6,CONCRETE:8,65,QUARK:IRON_PLATE:0,10,QUARK:IRON_PLATE:1,10,STAINED_CLAY:9,15,STAINED_CLAY:7,10,CONCRETE:8,10,RUSTIC:IRON_LATTICE:1,15,RUSTIC:IRON_LATTICE:0,15,LEAVES:4,70,CONCRETE:8,80,AIR:0,100)
RandomBlock(-5,0,7,CONCRETE:8,65,QUARK:IRON_PLATE:0,10,QUARK:IRON_PLATE:1,10,STAINED_CLAY:9,15,STAINED_CLAY:7,10,CONCRETE:8,10,RUSTIC:IRON_LATTICE:1,15,RUSTIC:IRON_LATTICE:0,15,LEAVES:4,70,CONCRETE:8,80,AIR:0,100)
RandomBlock(-5,0,8,CONCRETE:8,65,QUARK:IRON_PLATE:0,10,QUARK:IRON_PLATE:1,10,STAINED_CLAY:9,15,STAINED_CLAY:7,10,CONCRETE:8,10,RUSTIC:IRON_LATTICE:1,15,RUSTIC:IRON_LATTICE:0,15,LEAVES:4,70,CONCRETE:8,80,AIR:0,100)
RandomBlock(-5,0,9,CONCRETE:8,65,QUARK:IRON_PLATE:0,10,QUARK:IRON_PLATE:1,10,STAINED_CLAY:9,15,STAINED_CLAY:7,10,CONCRETE:8,10,RUSTIC:IRON_LATTICE:1,15,RUSTIC:IRON_LATTICE:0,15,LEAVES:4,70,CONCRETE:8,80,AIR:0,100)
RandomBlock(-5,1,-6,CONCRETE:7,65,QUARK:IRON_PLATE:0,10,QUARK:IRON_PLATE:1,10,STAINED_CLAY:15,10,STAINED_CLAY:9,70,RUSTIC:IRON_LATTICE:1,5,RUSTIC:IRON_LATTICE:0,5,LEAVES:4,40,STAINED_CLAY:9,100)
RandomBlock(-5,1,-5,CONCRETE:8,65,QUARK:IRON_PLATE:0,10,QUARK:IRON_PLATE:1,10,STAINED_CLAY:9,15,STAINED_CLAY:7,10,CONCRETE:8,10,RUSTIC:IRON_LATTICE:1,15,RUSTIC:IRON_LATTICE:0,15,LEAVES:4,70,CONCRETE:8,80,AIR:0,100)
RandomBlock(-5,1,-4,CONCRETE:8,65,QUARK:IRON_PLATE:0,10,QUARK:IRON_PLATE:1,10,STAINED_CLAY:9,15,STAINED_CLAY:7,10,CONCRETE:8,10,RUSTIC:IRON_LATTICE:1,15,RUSTIC:IRON_LATTICE:0,15,LEAVES:4,70,CONCRETE:8,80,AIR:0,100)
RandomBlock(-5,1,-3,CONCRETE:8,65,QUARK:IRON_PLATE:0,10,QUARK:IRON_PLATE:1,10,STAINED_CLAY:9,15,STAINED_CLAY:7,10,CONCRETE:8,10,RUSTIC:IRON_LATTICE:1,15,RUSTIC:IRON_LATTICE:0,15,LEAVES:4,70,CONCRETE:8,80,AIR:0,100)
Block(-5,1,-2,QUARTZ_STAIRS:3)
Block(-5,1,-1,AIR:0)
Block(-5,1,0,STAINED_GLASS:15)
RandomBlock(-5,1,1,CONCRETE:8,65,QUARK:IRON_PLATE:0,10,QUARK:IRON_PLATE:1,10,STAINED_CLAY:9,15,STAINED_CLAY:7,10,CONCRETE:8,10,RUSTIC:IRON_LATTICE:1,15,RUSTIC:IRON_LATTICE:0,15,LEAVES:4,70,CONCRETE:8,80,AIR:0,100)
RandomBlock(-5,1,2,CONCRETE:8,65,QUARK:IRON_PLATE:0,10,QUARK:IRON_PLATE:1,10,STAINED_CLAY:9,15,STAINED_CLAY:7,10,CONCRETE:8,10,RUSTIC:IRON_LATTICE:1,15,RUSTIC:IRON_LATTICE:0,15,LEAVES:4,70,CONCRETE:8,80,AIR:0,100)
RandomBlock(-5,1,3,CONCRETE:8,65,QUARK:IRON_PLATE:0,10,QUARK:IRON_PLATE:1,10,STAINED_CLAY:9,15,STAINED_CLAY:7,10,CONCRETE:8,10,RUSTIC:IRON_LATTICE:1,15,RUSTIC:IRON_LATTICE:0,15,LEAVES:4,70,CONCRETE:8,80,AIR:0,100)
Block(-5,1,4,SOIL:7)
Block(-5,1,5,SOIL:7)
Block(-5,1,6,STATIONARY_WATER:0)
Block(-5,1,7,SOIL:7)
Block(-5,1,8,SEA_LANTERN:0)
RandomBlock(-5,1,9,CONCRETE:7,65,QUARK:IRON_PLATE:0,10,QUARK:IRON_PLATE:1,10,STAINED_CLAY:15,10,STAINED_CLAY:9,70,RUSTIC:IRON_LATTICE:1,5,RUSTIC:IRON_LATTICE:0,5,LEAVES:4,40,STAINED_CLAY:9,100)
RandomBlock(-5,2,-6,CONCRETE:7,65,QUARK:IRON_PLATE:0,10,QUARK:IRON_PLATE:1,10,STAINED_CLAY:15,10,STAINED_CLAY:9,70,RUSTIC:IRON_LATTICE:1,5,RUSTIC:IRON_LATTICE:0,5,LEAVES:4,40,STAINED_CLAY:9,100)
RandomBlock(-5,2,-5,CONCRETE:8,65,QUARK:IRON_PLATE:0,10,QUARK:IRON_PLATE:1,10,STAINED_CLAY:9,15,STAINED_CLAY:7,10,CONCRETE:8,10,RUSTIC:IRON_LATTICE:1,15,RUSTIC:IRON_LATTICE:0,15,LEAVES:4,70,CONCRETE:8,80,AIR:0,100)
RandomBlock(-5,2,-4,CONCRETE:8,65,QUARK:IRON_PLATE:0,10,QUARK:IRON_PLATE:1,10,STAINED_CLAY:9,15,STAINED_CLAY:7,10,CONCRETE:8,10,RUSTIC:IRON_LATTICE:1,15,RUSTIC:IRON_LATTICE:0,15,LEAVES:4,70,CONCRETE:8,80,AIR:0,100)
Block(-5,2,-3,QUARTZ_STAIRS:3)
Block(-5,2,-2,AIR:0)
Block(-5,2,-1,AIR:0)
Block(-5,2,0,STAINED_GLASS:15)
Block(-5,2,1,AIR:0)
Block(-5,2,2,AIR:0)
Block(-5,2,3,AIR:0)
Block(-5,2,4,AIR:0)
Block(-5,2,5,AIR:0)
Block(-5,2,6,AIR:0)
Block(-5,2,7,CROPS:1)
Block(-5,2,8,STAINED_GLASS:15)
RandomBlock(-5,2,9,CONCRETE:7,65,QUARK:IRON_PLATE:0,10,QUARK:IRON_PLATE:1,10,STAINED_CLAY:15,10,STAINED_CLAY:9,70,RUSTIC:IRON_LATTICE:1,5,RUSTIC:IRON_LATTICE:0,5,LEAVES:4,40,STAINED_CLAY:9,100)
RandomBlock(-5,3,-6,CONCRETE:7,65,QUARK:IRON_PLATE:0,10,QUARK:IRON_PLATE:1,10,STAINED_CLAY:15,10,STAINED_CLAY:9,70,RUSTIC:IRON_LATTICE:1,5,RUSTIC:IRON_LATTICE:0,5,LEAVES:4,40,STAINED_CLAY:9,100)
Block(-5,3,-5,AIR:0)
Block(-5,3,-4,AIR:0)
Block(-5,3,-3,AIR:0)
Block(-5,3,-2,AIR:0)
Block(-5,3,-1,AIR:0)
Block(-5,3,0,STAINED_GLASS:15)
Block(-5,3,1,AIR:0)
Block(-5,3,2,AIR:0)
Block(-5,3,3,AIR:0)
Block(-5,3,4,AIR:0)
Block(-5,3,5,AIR:0)
Block(-5,3,6,AIR:0)
Block(-5,3,7,AIR:0)
Block(-5,3,8,STAINED_GLASS:15)
RandomBlock(-5,3,9,CONCRETE:7,65,QUARK:IRON_PLATE:0,10,QUARK:IRON_PLATE:1,10,STAINED_CLAY:15,10,STAINED_CLAY:9,70,RUSTIC:IRON_LATTICE:1,5,RUSTIC:IRON_LATTICE:0,5,LEAVES:4,40,STAINED_CLAY:9,100)
RandomBlock(-5,4,-6,CONCRETE:7,65,QUARK:IRON_PLATE:0,10,QUARK:IRON_PLATE:1,10,STAINED_CLAY:15,10,STAINED_CLAY:9,70,RUSTIC:IRON_LATTICE:1,5,RUSTIC:IRON_LATTICE:0,5,LEAVES:4,40,STAINED_CLAY:9,100)
Block(-5,4,-5,AIR:0)
Block(-5,4,-4,AIR:0)
Block(-5,4,-3,AIR:0)
Block(-5,4,-2,AIR:0)
Block(-5,4,-1,AIR:0)
Block(-5,4,0,STAINED_GLASS:15)
RandomBlock(-5,4,1,CONCRETE:8,65,QUARK:IRON_PLATE:0,10,QUARK:IRON_PLATE:1,10,STAINED_CLAY:9,15,STAINED_CLAY:7,10,CONCRETE:8,10,RUSTIC:IRON_LATTICE:1,15,RUSTIC:IRON_LATTICE:0,15,LEAVES:4,70,CONCRETE:8,80,AIR:0,100)
RandomBlock(-5,4,2,CONCRETE:8,65,QUARK:IRON_PLATE:0,10,QUARK:IRON_PLATE:1,10,STAINED_CLAY:9,15,STAINED_CLAY:7,10,CONCRETE:8,10,RUSTIC:IRON_LATTICE:1,15,RUSTIC:IRON_LATTICE:0,15,LEAVES:4,70,CONCRETE:8,80,AIR:0,100)
RandomBlock(-5,4,3,CONCRETE:8,65,QUARK:IRON_PLATE:0,10,QUARK:IRON_PLATE:1,10,STAINED_CLAY:9,15,STAINED_CLAY:7,10,CONCRETE:8,10,RUSTIC:IRON_LATTICE:1,15,RUSTIC:IRON_LATTICE:0,15,LEAVES:4,70,CONCRETE:8,80,AIR:0,100)
RandomBlock(-5,4,4,CONCRETE:8,65,QUARK:IRON_PLATE:0,10,QUARK:IRON_PLATE:1,10,STAINED_CLAY:9,15,STAINED_CLAY:7,10,CONCRETE:8,10,RUSTIC:IRON_LATTICE:1,15,RUSTIC:IRON_LATTICE:0,15,LEAVES:4,70,CONCRETE:8,80,AIR:0,100)
RandomBlock(-5,4,5,CONCRETE:8,65,QUARK:IRON_PLATE:0,10,QUARK:IRON_PLATE:1,10,STAINED_CLAY:9,15,STAINED_CLAY:7,10,CONCRETE:8,10,RUSTIC:IRON_LATTICE:1,15,RUSTIC:IRON_LATTICE:0,15,LEAVES:4,70,CONCRETE:8,80,AIR:0,100)
RandomBlock(-5,4,6,CONCRETE:8,65,QUARK:IRON_PLATE:0,10,QUARK:IRON_PLATE:1,10,STAINED_CLAY:9,15,STAINED_CLAY:7,10,CONCRETE:8,10,RUSTIC:IRON_LATTICE:1,15,RUSTIC:IRON_LATTICE:0,15,LEAVES:4,70,CONCRETE:8,80,AIR:0,100)
RandomBlock(-5,4,7,CONCRETE:8,65,QUARK:IRON_PLATE:0,10,QUARK:IRON_PLATE:1,10,STAINED_CLAY:9,15,STAINED_CLAY:7,10,CONCRETE:8,10,RUSTIC:IRON_LATTICE:1,15,RUSTIC:IRON_LATTICE:0,15,LEAVES:4,70,CONCRETE:8,80,AIR:0,100)
RandomBlock(-5,4,8,CONCRETE:8,65,QUARK:IRON_PLATE:0,10,QUARK:IRON_PLATE:1,10,STAINED_CLAY:9,15,STAINED_CLAY:7,10,CONCRETE:8,10,RUSTIC:IRON_LATTICE:1,15,RUSTIC:IRON_LATTICE:0,15,LEAVES:4,70,CONCRETE:8,80,AIR:0,100)
RandomBlock(-5,4,9,CONCRETE:7,65,QUARK:IRON_PLATE:0,10,QUARK:IRON_PLATE:1,10,STAINED_CLAY:15,10,STAINED_CLAY:9,70,RUSTIC:IRON_LATTICE:1,5,RUSTIC:IRON_LATTICE:0,5,LEAVES:4,40,STAINED_CLAY:9,100)
RandomBlock(-4,0,-6,CONCRETE:8,65,QUARK:IRON_PLATE:0,10,QUARK:IRON_PLATE:1,10,STAINED_CLAY:9,15,STAINED_CLAY:7,10,CONCRETE:8,10,RUSTIC:IRON_LATTICE:1,15,RUSTIC:IRON_LATTICE:0,15,LEAVES:4,70,CONCRETE:8,80,AIR:0,100)
RandomBlock(-4,0,-5,CONCRETE:8,65,QUARK:IRON_PLATE:0,10,QUARK:IRON_PLATE:1,10,STAINED_CLAY:9,15,STAINED_CLAY:7,10,CONCRETE:8,10,RUSTIC:IRON_LATTICE:1,15,RUSTIC:IRON_LATTICE:0,15,LEAVES:4,70,CONCRETE:8,80,AIR:0,100)
RandomBlock(-4,0,-4,CONCRETE:8,65,QUARK:IRON_PLATE:0,10,QUARK:IRON_PLATE:1,10,STAINED_CLAY:9,15,STAINED_CLAY:7,10,CONCRETE:8,10,RUSTIC:IRON_LATTICE:1,15,RUSTIC:IRON_LATTICE:0,15,LEAVES:4,70,CONCRETE:8,80,AIR:0,100)
RandomBlock(-4,0,-3,CONCRETE:8,65,QUARK:IRON_PLATE:0,10,QUARK:IRON_PLATE:1,10,STAINED_CLAY:9,15,STAINED_CLAY:7,10,CONCRETE:8,10,RUSTIC:IRON_LATTICE:1,15,RUSTIC:IRON_LATTICE:0,15,LEAVES:4,70,CONCRETE:8,80,AIR:0,100)
RandomBlock(-4,0,-2,CONCRETE:8,65,QUARK:IRON_PLATE:0,10,QUARK:IRON_PLATE:1,10,STAINED_CLAY:9,15,STAINED_CLAY:7,10,CONCRETE:8,10,RUSTIC:IRON_LATTICE:1,15,RUSTIC:IRON_LATTICE:0,15,LEAVES:4,70,CONCRETE:8,80,AIR:0,100)
RandomBlock(-4,0,-1,CONCRETE:8,65,QUARK:IRON_PLATE:0,10,QUARK:IRON_PLATE:1,10,STAINED_CLAY:9,15,STAINED_CLAY:7,10,CONCRETE:8,10,RUSTIC:IRON_LATTICE:1,15,RUSTIC:IRON_LATTICE:0,15,LEAVES:4,70,CONCRETE:8,80,AIR:0,100)
Block(-4,0,0,SEA_LANTERN:0)
RandomBlock(-4,0,1,CONCRETE:8,65,QUARK:IRON_PLATE:0,10,QUARK:IRON_PLATE:1,10,STAINED_CLAY:9,15,STAINED_CLAY:7,10,CONCRETE:8,10,RUSTIC:IRON_LATTICE:1,15,RUSTIC:IRON_LATTICE:0,15,LEAVES:4,70,CONCRETE:8,80,AIR:0,100)
RandomBlock(-4,0,2,CONCRETE:8,65,QUARK:IRON_PLATE:0,10,QUARK:IRON_PLATE:1,10,STAINED_CLAY:9,15,STAINED_CLAY:7,10,CONCRETE:8,10,RUSTIC:IRON_LATTICE:1,15,RUSTIC:IRON_LATTICE:0,15,LEAVES:4,70,CONCRETE:8,80,AIR:0,100)
RandomBlock(-4,0,3,CONCRETE:8,65,QUARK:IRON_PLATE:0,10,QUARK:IRON_PLATE:1,10,STAINED_CLAY:9,15,STAINED_CLAY:7,10,CONCRETE:8,10,RUSTIC:IRON_LATTICE:1,15,RUSTIC:IRON_LATTICE:0,15,LEAVES:4,70,CONCRETE:8,80,AIR:0,100)
RandomBlock(-4,0,4,CONCRETE:8,65,QUARK:IRON_PLATE:0,10,QUARK:IRON_PLATE:1,10,STAINED_CLAY:9,15,STAINED_CLAY:7,10,CONCRETE:8,10,RUSTIC:IRON_LATTICE:1,15,RUSTIC:IRON_LATTICE:0,15,LEAVES:4,70,CONCRETE:8,80,AIR:0,100)
RandomBlock(-4,0,5,CONCRETE:8,65,QUARK:IRON_PLATE:0,10,QUARK:IRON_PLATE:1,10,STAINED_CLAY:9,15,STAINED_CLAY:7,10,CONCRETE:8,10,RUSTIC:IRON_LATTICE:1,15,RUSTIC:IRON_LATTICE:0,15,LEAVES:4,70,CONCRETE:8,80,AIR:0,100)
RandomBlock(-4,0,6,CONCRETE:8,65,QUARK:IRON_PLATE:0,10,QUARK:IRON_PLATE:1,10,STAINED_CLAY:9,15,STAINED_CLAY:7,10,CONCRETE:8,10,RUSTIC:IRON_LATTICE:1,15,RUSTIC:IRON_LATTICE:0,15,LEAVES:4,70,CONCRETE:8,80,AIR:0,100)
RandomBlock(-4,0,7,CONCRETE:8,65,QUARK:IRON_PLATE:0,10,QUARK:IRON_PLATE:1,10,STAINED_CLAY:9,15,STAINED_CLAY:7,10,CONCRETE:8,10,RUSTIC:IRON_LATTICE:1,15,RUSTIC:IRON_LATTICE:0,15,LEAVES:4,70,CONCRETE:8,80,AIR:0,100)
RandomBlock(-4,0,8,CONCRETE:8,65,QUARK:IRON_PLATE:0,10,QUARK:IRON_PLATE:1,10,STAINED_CLAY:9,15,STAINED_CLAY:7,10,CONCRETE:8,10,RUSTIC:IRON_LATTICE:1,15,RUSTIC:IRON_LATTICE:0,15,LEAVES:4,70,CONCRETE:8,80,AIR:0,100)
RandomBlock(-4,0,9,CONCRETE:8,65,QUARK:IRON_PLATE:0,10,QUARK:IRON_PLATE:1,10,STAINED_CLAY:9,15,STAINED_CLAY:7,10,CONCRETE:8,10,RUSTIC:IRON_LATTICE:1,15,RUSTIC:IRON_LATTICE:0,15,LEAVES:4,70,CONCRETE:8,80,AIR:0,100)
RandomBlock(-4,1,-6,CONCRETE:8,65,QUARK:IRON_PLATE:0,10,QUARK:IRON_PLATE:1,10,STAINED_CLAY:9,15,STAINED_CLAY:7,10,CONCRETE:8,10,RUSTIC:IRON_LATTICE:1,15,RUSTIC:IRON_LATTICE:0,15,LEAVES:4,70,CONCRETE:8,80,AIR:0,100)
RandomBlock(-4,1,-5,CONCRETE:7,65,QUARK:IRON_PLATE:0,10,QUARK:IRON_PLATE:1,10,STAINED_CLAY:15,10,STAINED_CLAY:9,70,RUSTIC:IRON_LATTICE:1,5,RUSTIC:IRON_LATTICE:0,5,LEAVES:4,40,STAINED_CLAY:9,100)
RandomBlock(-4,1,-4,CONCRETE:7,65,QUARK:IRON_PLATE:0,10,QUARK:IRON_PLATE:1,10,STAINED_CLAY:15,10,STAINED_CLAY:9,70,RUSTIC:IRON_LATTICE:1,5,RUSTIC:IRON_LATTICE:0,5,LEAVES:4,40,STAINED_CLAY:9,100)
RandomBlock(-4,1,-3,CONCRETE:8,65,QUARK:IRON_PLATE:0,10,QUARK:IRON_PLATE:1,10,STAINED_CLAY:9,15,STAINED_CLAY:7,10,CONCRETE:8,10,RUSTIC:IRON_LATTICE:1,15,RUSTIC:IRON_LATTICE:0,15,LEAVES:4,70,CONCRETE:8,80,AIR:0,100)
Block(-4,1,-2,AIR:0)
Block(-4,1,-1,AIR:0)
Block(-4,1,0,STAINED_GLASS:15)
Block(-4,1,1,QUARTZ_STAIRS:1)
Block(-4,1,2,QUARTZ_STAIRS:1)
RandomBlock(-4,1,3,CONCRETE:8,65,QUARK:IRON_PLATE:0,10,QUARK:IRON_PLATE:1,10,STAINED_CLAY:9,15,STAINED_CLAY:7,10,CONCRETE:8,10,RUSTIC:IRON_LATTICE:1,15,RUSTIC:IRON_LATTICE:0,15,LEAVES:4,70,CONCRETE:8,80,AIR:0,100)
Block(-4,1,4,SOIL:7)
Block(-4,1,5,SOIL:7)
Block(-4,1,6,STATIONARY_WATER:0)
Block(-4,1,7,SOIL:7)
RandomBlock(-4,1,8,CONCRETE:8,65,QUARK:IRON_PLATE:0,10,QUARK:IRON_PLATE:1,10,STAINED_CLAY:9,15,STAINED_CLAY:7,10,CONCRETE:8,10,RUSTIC:IRON_LATTICE:1,15,RUSTIC:IRON_LATTICE:0,15,LEAVES:4,70,CONCRETE:8,80,AIR:0,100)
RandomBlock(-4,1,9,CONCRETE:8,65,QUARK:IRON_PLATE:0,10,QUARK:IRON_PLATE:1,10,STAINED_CLAY:9,15,STAINED_CLAY:7,10,CONCRETE:8,10,RUSTIC:IRON_LATTICE:1,15,RUSTIC:IRON_LATTICE:0,15,LEAVES:4,70,CONCRETE:8,80,AIR:0,100)
RandomBlock(-4,2,-6,CONCRETE:8,65,QUARK:IRON_PLATE:0,10,QUARK:IRON_PLATE:1,10,STAINED_CLAY:9,15,STAINED_CLAY:7,10,CONCRETE:8,10,RUSTIC:IRON_LATTICE:1,15,RUSTIC:IRON_LATTICE:0,15,LEAVES:4,70,CONCRETE:8,80,AIR:0,100)
RandomBlock(-4,2,-5,CONCRETE:7,65,QUARK:IRON_PLATE:0,10,QUARK:IRON_PLATE:1,10,STAINED_CLAY:15,10,STAINED_CLAY:9,70,RUSTIC:IRON_LATTICE:1,5,RUSTIC:IRON_LATTICE:0,5,LEAVES:4,40,STAINED_CLAY:9,100)
RandomBlock(-4,2,-4,CONCRETE:7,65,QUARK:IRON_PLATE:0,10,QUARK:IRON_PLATE:1,10,STAINED_CLAY:15,10,STAINED_CLAY:9,70,RUSTIC:IRON_LATTICE:1,5,RUSTIC:IRON_LATTICE:0,5,LEAVES:4,40,STAINED_CLAY:9,100)
RandomBlock(-4,2,-3,CONCRETE:8,65,QUARK:IRON_PLATE:0,10,QUARK:IRON_PLATE:1,10,STAINED_CLAY:9,15,STAINED_CLAY:7,10,CONCRETE:8,10,RUSTIC:IRON_LATTICE:1,15,RUSTIC:IRON_LATTICE:0,15,LEAVES:4,70,CONCRETE:8,80,AIR:0,100)
Block(-4,2,-2,AIR:0)
Block(-4,2,-1,AIR:0)
Block(-4,2,0,STAINED_GLASS:15)
Block(-4,2,1,AIR:0)
Block(-4,2,2,AIR:0)
Block(-4,2,3,STAINED_GLASS_PANE:15)
Block(-4,2,4,POTATO:0)
Block(-4,2,5,CROPS:2)
Block(-4,2,6,AIR:0)
Block(-4,2,7,CROPS:1)
RandomBlock(-4,2,8,CONCRETE:8,65,QUARK:IRON_PLATE:0,10,QUARK:IRON_PLATE:1,10,STAINED_CLAY:9,15,STAINED_CLAY:7,10,CONCRETE:8,10,RUSTIC:IRON_LATTICE:1,15,RUSTIC:IRON_LATTICE:0,15,LEAVES:4,70,CONCRETE:8,80,AIR:0,100)
RandomBlock(-4,2,9,CONCRETE:8,65,QUARK:IRON_PLATE:0,10,QUARK:IRON_PLATE:1,10,STAINED_CLAY:9,15,STAINED_CLAY:7,10,CONCRETE:8,10,RUSTIC:IRON_LATTICE:1,15,RUSTIC:IRON_LATTICE:0,15,LEAVES:4,70,CONCRETE:8,80,AIR:0,100)
RandomBlock(-4,3,-6,CONCRETE:8,65,QUARK:IRON_PLATE:0,10,QUARK:IRON_PLATE:1,10,STAINED_CLAY:9,15,STAINED_CLAY:7,10,CONCRETE:8,10,RUSTIC:IRON_LATTICE:1,15,RUSTIC:IRON_LATTICE:0,15,LEAVES:4,70,CONCRETE:8,80,AIR:0,100)
Block(-4,3,-5,QUARTZ_STAIRS:0)
Block(-4,3,-4,QUARTZ_STAIRS:0)
RandomBlock(-4,3,-3,CONCRETE:8,65,QUARK:IRON_PLATE:0,10,QUARK:IRON_PLATE:1,10,STAINED_CLAY:9,15,STAINED_CLAY:7,10,CONCRETE:8,10,RUSTIC:IRON_LATTICE:1,15,RUSTIC:IRON_LATTICE:0,15,LEAVES:4,70,CONCRETE:8,80,AIR:0,100)
Block(-4,3,-2,AIR:0)
Block(-4,3,-1,AIR:0)
Block(-4,3,0,STAINED_GLASS:15)
Block(-4,3,1,AIR:0)
Block(-4,3,2,AIR:0)
Block(-4,3,3,AIR:0)
Block(-4,3,4,AIR:0)
Block(-4,3,5,AIR:0)
Block(-4,3,6,AIR:0)
Block(-4,3,7,AIR:0)
RandomBlock(-4,3,8,CONCRETE:8,65,QUARK:IRON_PLATE:0,10,QUARK:IRON_PLATE:1,10,STAINED_CLAY:9,15,STAINED_CLAY:7,10,CONCRETE:8,10,RUSTIC:IRON_LATTICE:1,15,RUSTIC:IRON_LATTICE:0,15,LEAVES:4,70,CONCRETE:8,80,AIR:0,100)
RandomBlock(-4,3,9,CONCRETE:8,65,QUARK:IRON_PLATE:0,10,QUARK:IRON_PLATE:1,10,STAINED_CLAY:9,15,STAINED_CLAY:7,10,CONCRETE:8,10,RUSTIC:IRON_LATTICE:1,15,RUSTIC:IRON_LATTICE:0,15,LEAVES:4,70,CONCRETE:8,80,AIR:0,100)
RandomBlock(-4,4,-6,CONCRETE:8,65,QUARK:IRON_PLATE:0,10,QUARK:IRON_PLATE:1,10,STAINED_CLAY:9,15,STAINED_CLAY:7,10,CONCRETE:8,10,RUSTIC:IRON_LATTICE:1,15,RUSTIC:IRON_LATTICE:0,15,LEAVES:4,70,CONCRETE:8,80,AIR:0,100)
Block(-4,4,-5,AIR:0)
Block(-4,4,-4,AIR:0)
RandomBlock(-4,4,-3,CONCRETE:8,65,QUARK:IRON_PLATE:0,10,QUARK:IRON_PLATE:1,10,STAINED_CLAY:9,15,STAINED_CLAY:7,10,CONCRETE:8,10,RUSTIC:IRON_LATTICE:1,15,RUSTIC:IRON_LATTICE:0,15,LEAVES:4,70,CONCRETE:8,80,AIR:0,100)
Block(-4,4,-2,QUARTZ_STAIRS:4)
Block(-4,4,-1,QUARTZ_STAIRS:4)
Block(-4,4,0,STAINED_GLASS:15)
RandomBlock(-4,4,1,CONCRETE:8,65,QUARK:IRON_PLATE:0,10,QUARK:IRON_PLATE:1,10,STAINED_CLAY:9,15,STAINED_CLAY:7,10,CONCRETE:8,10,RUSTIC:IRON_LATTICE:1,15,RUSTIC:IRON_LATTICE:0,15,LEAVES:4,70,CONCRETE:8,80,AIR:0,100)
RandomBlock(-4,4,2,CONCRETE:8,65,QUARK:IRON_PLATE:0,10,QUARK:IRON_PLATE:1,10,STAINED_CLAY:9,15,STAINED_CLAY:7,10,CONCRETE:8,10,RUSTIC:IRON_LATTICE:1,15,RUSTIC:IRON_LATTICE:0,15,LEAVES:4,70,CONCRETE:8,80,AIR:0,100)
RandomBlock(-4,4,3,CONCRETE:8,65,QUARK:IRON_PLATE:0,10,QUARK:IRON_PLATE:1,10,STAINED_CLAY:9,15,STAINED_CLAY:7,10,CONCRETE:8,10,RUSTIC:IRON_LATTICE:1,15,RUSTIC:IRON_LATTICE:0,15,LEAVES:4,70,CONCRETE:8,80,AIR:0,100)
RandomBlock(-4,4,4,CONCRETE:8,65,QUARK:IRON_PLATE:0,10,QUARK:IRON_PLATE:1,10,STAINED_CLAY:9,15,STAINED_CLAY:7,10,CONCRETE:8,10,RUSTIC:IRON_LATTICE:1,15,RUSTIC:IRON_LATTICE:0,15,LEAVES:4,70,CONCRETE:8,80,AIR:0,100)
RandomBlock(-4,4,5,CONCRETE:8,65,QUARK:IRON_PLATE:0,10,QUARK:IRON_PLATE:1,10,STAINED_CLAY:9,15,STAINED_CLAY:7,10,CONCRETE:8,10,RUSTIC:IRON_LATTICE:1,15,RUSTIC:IRON_LATTICE:0,15,LEAVES:4,70,CONCRETE:8,80,AIR:0,100)
RandomBlock(-4,4,6,CONCRETE:8,65,QUARK:IRON_PLATE:0,10,QUARK:IRON_PLATE:1,10,STAINED_CLAY:9,15,STAINED_CLAY:7,10,CONCRETE:8,10,RUSTIC:IRON_LATTICE:1,15,RUSTIC:IRON_LATTICE:0,15,LEAVES:4,70,CONCRETE:8,80,AIR:0,100)
RandomBlock(-4,4,7,CONCRETE:8,65,QUARK:IRON_PLATE:0,10,QUARK:IRON_PLATE:1,10,STAINED_CLAY:9,15,STAINED_CLAY:7,10,CONCRETE:8,10,RUSTIC:IRON_LATTICE:1,15,RUSTIC:IRON_LATTICE:0,15,LEAVES:4,70,CONCRETE:8,80,AIR:0,100)
RandomBlock(-4,4,8,CONCRETE:8,65,QUARK:IRON_PLATE:0,10,QUARK:IRON_PLATE:1,10,STAINED_CLAY:9,15,STAINED_CLAY:7,10,CONCRETE:8,10,RUSTIC:IRON_LATTICE:1,15,RUSTIC:IRON_LATTICE:0,15,LEAVES:4,70,CONCRETE:8,80,AIR:0,100)
RandomBlock(-4,4,9,CONCRETE:8,65,QUARK:IRON_PLATE:0,10,QUARK:IRON_PLATE:1,10,STAINED_CLAY:9,15,STAINED_CLAY:7,10,CONCRETE:8,10,RUSTIC:IRON_LATTICE:1,15,RUSTIC:IRON_LATTICE:0,15,LEAVES:4,70,CONCRETE:8,80,AIR:0,100)
RandomBlock(-3,0,-6,CONCRETE:8,65,QUARK:IRON_PLATE:0,10,QUARK:IRON_PLATE:1,10,STAINED_CLAY:9,15,STAINED_CLAY:7,10,CONCRETE:8,10,RUSTIC:IRON_LATTICE:1,15,RUSTIC:IRON_LATTICE:0,15,LEAVES:4,70,CONCRETE:8,80,AIR:0,100)
RandomBlock(-3,0,-5,CONCRETE:8,65,QUARK:IRON_PLATE:0,10,QUARK:IRON_PLATE:1,10,STAINED_CLAY:9,15,STAINED_CLAY:7,10,CONCRETE:8,10,RUSTIC:IRON_LATTICE:1,15,RUSTIC:IRON_LATTICE:0,15,LEAVES:4,70,CONCRETE:8,80,AIR:0,100)
RandomBlock(-3,0,-4,CONCRETE:8,65,QUARK:IRON_PLATE:0,10,QUARK:IRON_PLATE:1,10,STAINED_CLAY:9,15,STAINED_CLAY:7,10,CONCRETE:8,10,RUSTIC:IRON_LATTICE:1,15,RUSTIC:IRON_LATTICE:0,15,LEAVES:4,70,CONCRETE:8,80,AIR:0,100)
RandomBlock(-3,0,-3,CONCRETE:8,65,QUARK:IRON_PLATE:0,10,QUARK:IRON_PLATE:1,10,STAINED_CLAY:9,15,STAINED_CLAY:7,10,CONCRETE:8,10,RUSTIC:IRON_LATTICE:1,15,RUSTIC:IRON_LATTICE:0,15,LEAVES:4,70,CONCRETE:8,80,AIR:0,100)
RandomBlock(-3,0,-2,CONCRETE:8,65,QUARK:IRON_PLATE:0,10,QUARK:IRON_PLATE:1,10,STAINED_CLAY:9,15,STAINED_CLAY:7,10,CONCRETE:8,10,RUSTIC:IRON_LATTICE:1,15,RUSTIC:IRON_LATTICE:0,15,LEAVES:4,70,CONCRETE:8,80,AIR:0,100)
RandomBlock(-3,0,-1,CONCRETE:8,65,QUARK:IRON_PLATE:0,10,QUARK:IRON_PLATE:1,10,STAINED_CLAY:9,15,STAINED_CLAY:7,10,CONCRETE:8,10,RUSTIC:IRON_LATTICE:1,15,RUSTIC:IRON_LATTICE:0,15,LEAVES:4,70,CONCRETE:8,80,AIR:0,100)
RandomBlock(-3,0,0,CONCRETE:8,65,QUARK:IRON_PLATE:0,10,QUARK:IRON_PLATE:1,10,STAINED_CLAY:9,15,STAINED_CLAY:7,10,CONCRETE:8,10,RUSTIC:IRON_LATTICE:1,15,RUSTIC:IRON_LATTICE:0,15,LEAVES:4,70,CONCRETE:8,80,AIR:0,100)
RandomBlock(-3,0,1,CONCRETE:8,65,QUARK:IRON_PLATE:0,10,QUARK:IRON_PLATE:1,10,STAINED_CLAY:9,15,STAINED_CLAY:7,10,CONCRETE:8,10,RUSTIC:IRON_LATTICE:1,15,RUSTIC:IRON_LATTICE:0,15,LEAVES:4,70,CONCRETE:8,80,AIR:0,100)
RandomBlock(-3,0,2,CONCRETE:8,65,QUARK:IRON_PLATE:0,10,QUARK:IRON_PLATE:1,10,STAINED_CLAY:9,15,STAINED_CLAY:7,10,CONCRETE:8,10,RUSTIC:IRON_LATTICE:1,15,RUSTIC:IRON_LATTICE:0,15,LEAVES:4,70,CONCRETE:8,80,AIR:0,100)
RandomBlock(-3,0,3,CONCRETE:8,65,QUARK:IRON_PLATE:0,10,QUARK:IRON_PLATE:1,10,STAINED_CLAY:9,15,STAINED_CLAY:7,10,CONCRETE:8,10,RUSTIC:IRON_LATTICE:1,15,RUSTIC:IRON_LATTICE:0,15,LEAVES:4,70,CONCRETE:8,80,AIR:0,100)
RandomBlock(-3,0,4,CONCRETE:8,65,QUARK:IRON_PLATE:0,10,QUARK:IRON_PLATE:1,10,STAINED_CLAY:9,15,STAINED_CLAY:7,10,CONCRETE:8,10,RUSTIC:IRON_LATTICE:1,15,RUSTIC:IRON_LATTICE:0,15,LEAVES:4,70,CONCRETE:8,80,AIR:0,100)
RandomBlock(-3,0,5,CONCRETE:8,65,QUARK:IRON_PLATE:0,10,QUARK:IRON_PLATE:1,10,STAINED_CLAY:9,15,STAINED_CLAY:7,10,CONCRETE:8,10,RUSTIC:IRON_LATTICE:1,15,RUSTIC:IRON_LATTICE:0,15,LEAVES:4,70,CONCRETE:8,80,AIR:0,100)
RandomBlock(-3,0,6,CONCRETE:8,65,QUARK:IRON_PLATE:0,10,QUARK:IRON_PLATE:1,10,STAINED_CLAY:9,15,STAINED_CLAY:7,10,CONCRETE:8,10,RUSTIC:IRON_LATTICE:1,15,RUSTIC:IRON_LATTICE:0,15,LEAVES:4,70,CONCRETE:8,80,AIR:0,100)
RandomBlock(-3,0,7,CONCRETE:8,65,QUARK:IRON_PLATE:0,10,QUARK:IRON_PLATE:1,10,STAINED_CLAY:9,15,STAINED_CLAY:7,10,CONCRETE:8,10,RUSTIC:IRON_LATTICE:1,15,RUSTIC:IRON_LATTICE:0,15,LEAVES:4,70,CONCRETE:8,80,AIR:0,100)
RandomBlock(-3,0,8,CONCRETE:8,65,QUARK:IRON_PLATE:0,10,QUARK:IRON_PLATE:1,10,STAINED_CLAY:9,15,STAINED_CLAY:7,10,CONCRETE:8,10,RUSTIC:IRON_LATTICE:1,15,RUSTIC:IRON_LATTICE:0,15,LEAVES:4,70,CONCRETE:8,80,AIR:0,100)
RandomBlock(-3,0,9,CONCRETE:8,65,QUARK:IRON_PLATE:0,10,QUARK:IRON_PLATE:1,10,STAINED_CLAY:9,15,STAINED_CLAY:7,10,CONCRETE:8,10,RUSTIC:IRON_LATTICE:1,15,RUSTIC:IRON_LATTICE:0,15,LEAVES:4,70,CONCRETE:8,80,AIR:0,100)
RandomBlock(-3,1,-6,CONCRETE:7,65,QUARK:IRON_PLATE:0,10,QUARK:IRON_PLATE:1,10,STAINED_CLAY:15,10,STAINED_CLAY:9,70,RUSTIC:IRON_LATTICE:1,5,RUSTIC:IRON_LATTICE:0,5,LEAVES:4,40,STAINED_CLAY:9,100)
Block(-3,1,-5,CAULDRON:0)
Block(-3,1,-4,CAULDRON:0)
Block(-3,1,-3,CAULDRON:3)
Block(-3,1,-2,AIR:0)
Block(-3,1,-1,AIR:0)
Block(-3,1,0,AIR:0)
Block(-3,1,1,AIR:0)
Block(-3,1,2,AIR:0)
RandomBlock(-3,1,3,CONCRETE:8,65,QUARK:IRON_PLATE:0,10,QUARK:IRON_PLATE:1,10,STAINED_CLAY:9,15,STAINED_CLAY:7,10,CONCRETE:8,10,RUSTIC:IRON_LATTICE:1,15,RUSTIC:IRON_LATTICE:0,15,LEAVES:4,70,CONCRETE:8,80,AIR:0,100)
Block(-3,1,4,SOIL:7)
Block(-3,1,5,SOIL:7)
Block(-3,1,6,STATIONARY_WATER:0)
Block(-3,1,7,SOIL:7)
Block(-3,1,8,SEA_LANTERN:0)
RandomBlock(-3,1,9,CONCRETE:7,65,QUARK:IRON_PLATE:0,10,QUARK:IRON_PLATE:1,10,STAINED_CLAY:15,10,STAINED_CLAY:9,70,RUSTIC:IRON_LATTICE:1,5,RUSTIC:IRON_LATTICE:0,5,LEAVES:4,40,STAINED_CLAY:9,100)
RandomBlock(-3,2,-6,CONCRETE:7,65,QUARK:IRON_PLATE:0,10,QUARK:IRON_PLATE:1,10,STAINED_CLAY:15,10,STAINED_CLAY:9,70,RUSTIC:IRON_LATTICE:1,5,RUSTIC:IRON_LATTICE:0,5,LEAVES:4,40,STAINED_CLAY:9,100)
Block(-3,2,-5,IRON_TRAPDOOR:1)
Block(-3,2,-4,IRON_TRAPDOOR:1)
Block(-3,2,-3,IRON_TRAPDOOR:1)
Block(-3,2,-2,AIR:0)
Block(-3,2,-1,AIR:0)
Block(-3,2,0,AIR:0)
Block(-3,2,1,AIR:0)
Block(-3,2,2,AIR:0)
Block(-3,2,3,STAINED_GLASS_PANE:15)
Block(-3,2,4,CROPS:1)
Block(-3,2,5,AIR:0)
Block(-3,2,6,AIR:0)
Block(-3,2,7,AIR:0)
Block(-3,2,8,STAINED_GLASS:15)
RandomBlock(-3,2,9,CONCRETE:7,65,QUARK:IRON_PLATE:0,10,QUARK:IRON_PLATE:1,10,STAINED_CLAY:15,10,STAINED_CLAY:9,70,RUSTIC:IRON_LATTICE:1,5,RUSTIC:IRON_LATTICE:0,5,LEAVES:4,40,STAINED_CLAY:9,100)
RandomBlock(-3,3,-6,CONCRETE:7,65,QUARK:IRON_PLATE:0,10,QUARK:IRON_PLATE:1,10,STAINED_CLAY:15,10,STAINED_CLAY:9,70,RUSTIC:IRON_LATTICE:1,5,RUSTIC:IRON_LATTICE:0,5,LEAVES:4,40,STAINED_CLAY:9,100)
RandomBlock(-3,3,-5,CONCRETE:8,65,QUARK:IRON_PLATE:0,10,QUARK:IRON_PLATE:1,10,STAINED_CLAY:9,15,STAINED_CLAY:7,10,CONCRETE:8,10,RUSTIC:IRON_LATTICE:1,15,RUSTIC:IRON_LATTICE:0,15,LEAVES:4,70,CONCRETE:8,80,AIR:0,100)
RandomBlock(-3,3,-4,CONCRETE:8,65,QUARK:IRON_PLATE:0,10,QUARK:IRON_PLATE:1,10,STAINED_CLAY:9,15,STAINED_CLAY:7,10,CONCRETE:8,10,RUSTIC:IRON_LATTICE:1,15,RUSTIC:IRON_LATTICE:0,15,LEAVES:4,70,CONCRETE:8,80,AIR:0,100)
Block(-3,3,-3,QUARTZ_STAIRS:7)
Block(-3,3,-2,AIR:0)
Block(-3,3,-1,AIR:0)
Block(-3,3,0,AIR:0)
Block(-3,3,1,AIR:0)
Block(-3,3,2,AIR:0)
Block(-3,3,3,AIR:0)
Block(-3,3,4,AIR:0)
Block(-3,3,5,AIR:0)
Block(-3,3,6,AIR:0)
Block(-3,3,7,AIR:0)
Block(-3,3,8,STAINED_GLASS:15)
RandomBlock(-3,3,9,CONCRETE:7,65,QUARK:IRON_PLATE:0,10,QUARK:IRON_PLATE:1,10,STAINED_CLAY:15,10,STAINED_CLAY:9,70,RUSTIC:IRON_LATTICE:1,5,RUSTIC:IRON_LATTICE:0,5,LEAVES:4,40,STAINED_CLAY:9,100)
RandomBlock(-3,4,-6,CONCRETE:7,65,QUARK:IRON_PLATE:0,10,QUARK:IRON_PLATE:1,10,STAINED_CLAY:15,10,STAINED_CLAY:9,70,RUSTIC:IRON_LATTICE:1,5,RUSTIC:IRON_LATTICE:0,5,LEAVES:4,40,STAINED_CLAY:9,100)
Block(-3,4,-5,AIR:0)
Block(-3,4,-4,AIR:0)
Block(-3,4,-3,QUARTZ_STAIRS:2)
RandomBlock(-3,4,-2,CONCRETE:8,65,QUARK:IRON_PLATE:0,10,QUARK:IRON_PLATE:1,10,STAINED_CLAY:9,15,STAINED_CLAY:7,10,CONCRETE:8,10,RUSTIC:IRON_LATTICE:1,15,RUSTIC:IRON_LATTICE:0,15,LEAVES:4,70,CONCRETE:8,80,AIR:0,100)
RandomBlock(-3,4,-1,CONCRETE:8,65,QUARK:IRON_PLATE:0,10,QUARK:IRON_PLATE:1,10,STAINED_CLAY:9,15,STAINED_CLAY:7,10,CONCRETE:8,10,RUSTIC:IRON_LATTICE:1,15,RUSTIC:IRON_LATTICE:0,15,LEAVES:4,70,CONCRETE:8,80,AIR:0,100)
RandomBlock(-3,4,0,CONCRETE:8,65,QUARK:IRON_PLATE:0,10,QUARK:IRON_PLATE:1,10,STAINED_CLAY:9,15,STAINED_CLAY:7,10,CONCRETE:8,10,RUSTIC:IRON_LATTICE:1,15,RUSTIC:IRON_LATTICE:0,15,LEAVES:4,70,CONCRETE:8,80,AIR:0,100)
RandomBlock(-3,4,1,CONCRETE:8,65,QUARK:IRON_PLATE:0,10,QUARK:IRON_PLATE:1,10,STAINED_CLAY:9,15,STAINED_CLAY:7,10,CONCRETE:8,10,RUSTIC:IRON_LATTICE:1,15,RUSTIC:IRON_LATTICE:0,15,LEAVES:4,70,CONCRETE:8,80,AIR:0,100)
RandomBlock(-3,4,2,CONCRETE:8,65,QUARK:IRON_PLATE:0,10,QUARK:IRON_PLATE:1,10,STAINED_CLAY:9,15,STAINED_CLAY:7,10,CONCRETE:8,10,RUSTIC:IRON_LATTICE:1,15,RUSTIC:IRON_LATTICE:0,15,LEAVES:4,70,CONCRETE:8,80,AIR:0,100)
RandomBlock(-3,4,3,CONCRETE:8,65,QUARK:IRON_PLATE:0,10,QUARK:IRON_PLATE:1,10,STAINED_CLAY:9,15,STAINED_CLAY:7,10,CONCRETE:8,10,RUSTIC:IRON_LATTICE:1,15,RUSTIC:IRON_LATTICE:0,15,LEAVES:4,70,CONCRETE:8,80,AIR:0,100)
RandomBlock(-3,4,4,CONCRETE:8,65,QUARK:IRON_PLATE:0,10,QUARK:IRON_PLATE:1,10,STAINED_CLAY:9,15,STAINED_CLAY:7,10,CONCRETE:8,10,RUSTIC:IRON_LATTICE:1,15,RUSTIC:IRON_LATTICE:0,15,LEAVES:4,70,CONCRETE:8,80,AIR:0,100)
RandomBlock(-3,4,5,CONCRETE:8,65,QUARK:IRON_PLATE:0,10,QUARK:IRON_PLATE:1,10,STAINED_CLAY:9,15,STAINED_CLAY:7,10,CONCRETE:8,10,RUSTIC:IRON_LATTICE:1,15,RUSTIC:IRON_LATTICE:0,15,LEAVES:4,70,CONCRETE:8,80,AIR:0,100)
RandomBlock(-3,4,6,CONCRETE:8,65,QUARK:IRON_PLATE:0,10,QUARK:IRON_PLATE:1,10,STAINED_CLAY:9,15,STAINED_CLAY:7,10,CONCRETE:8,10,RUSTIC:IRON_LATTICE:1,15,RUSTIC:IRON_LATTICE:0,15,LEAVES:4,70,CONCRETE:8,80,AIR:0,100)
RandomBlock(-3,4,7,CONCRETE:8,65,QUARK:IRON_PLATE:0,10,QUARK:IRON_PLATE:1,10,STAINED_CLAY:9,15,STAINED_CLAY:7,10,CONCRETE:8,10,RUSTIC:IRON_LATTICE:1,15,RUSTIC:IRON_LATTICE:0,15,LEAVES:4,70,CONCRETE:8,80,AIR:0,100)
RandomBlock(-3,4,8,CONCRETE:8,65,QUARK:IRON_PLATE:0,10,QUARK:IRON_PLATE:1,10,STAINED_CLAY:9,15,STAINED_CLAY:7,10,CONCRETE:8,10,RUSTIC:IRON_LATTICE:1,15,RUSTIC:IRON_LATTICE:0,15,LEAVES:4,70,CONCRETE:8,80,AIR:0,100)
RandomBlock(-3,4,9,CONCRETE:7,65,QUARK:IRON_PLATE:0,10,QUARK:IRON_PLATE:1,10,STAINED_CLAY:15,10,STAINED_CLAY:9,70,RUSTIC:IRON_LATTICE:1,5,RUSTIC:IRON_LATTICE:0,5,LEAVES:4,40,STAINED_CLAY:9,100)
RandomBlock(-2,0,-6,CONCRETE:8,65,QUARK:IRON_PLATE:0,10,QUARK:IRON_PLATE:1,10,STAINED_CLAY:9,15,STAINED_CLAY:7,10,CONCRETE:8,10,RUSTIC:IRON_LATTICE:1,15,RUSTIC:IRON_LATTICE:0,15,LEAVES:4,70,CONCRETE:8,80,AIR:0,100)
RandomBlock(-2,0,-5,CONCRETE:8,65,QUARK:IRON_PLATE:0,10,QUARK:IRON_PLATE:1,10,STAINED_CLAY:9,15,STAINED_CLAY:7,10,CONCRETE:8,10,RUSTIC:IRON_LATTICE:1,15,RUSTIC:IRON_LATTICE:0,15,LEAVES:4,70,CONCRETE:8,80,AIR:0,100)
RandomBlock(-2,0,-4,CONCRETE:8,65,QUARK:IRON_PLATE:0,10,QUARK:IRON_PLATE:1,10,STAINED_CLAY:9,15,STAINED_CLAY:7,10,CONCRETE:8,10,RUSTIC:IRON_LATTICE:1,15,RUSTIC:IRON_LATTICE:0,15,LEAVES:4,70,CONCRETE:8,80,AIR:0,100)
RandomBlock(-2,0,-3,CONCRETE:8,65,QUARK:IRON_PLATE:0,10,QUARK:IRON_PLATE:1,10,STAINED_CLAY:9,15,STAINED_CLAY:7,10,CONCRETE:8,10,RUSTIC:IRON_LATTICE:1,15,RUSTIC:IRON_LATTICE:0,15,LEAVES:4,70,CONCRETE:8,80,AIR:0,100)
RandomBlock(-2,0,-2,CONCRETE:8,65,QUARK:IRON_PLATE:0,10,QUARK:IRON_PLATE:1,10,STAINED_CLAY:9,15,STAINED_CLAY:7,10,CONCRETE:8,10,RUSTIC:IRON_LATTICE:1,15,RUSTIC:IRON_LATTICE:0,15,LEAVES:4,70,CONCRETE:8,80,AIR:0,100)
RandomBlock(-2,0,-1,CONCRETE:8,65,QUARK:IRON_PLATE:0,10,QUARK:IRON_PLATE:1,10,STAINED_CLAY:9,15,STAINED_CLAY:7,10,CONCRETE:8,10,RUSTIC:IRON_LATTICE:1,15,RUSTIC:IRON_LATTICE:0,15,LEAVES:4,70,CONCRETE:8,80,AIR:0,100)
RandomBlock(-2,0,0,CONCRETE:8,65,QUARK:IRON_PLATE:0,10,QUARK:IRON_PLATE:1,10,STAINED_CLAY:9,15,STAINED_CLAY:7,10,CONCRETE:8,10,RUSTIC:IRON_LATTICE:1,15,RUSTIC:IRON_LATTICE:0,15,LEAVES:4,70,CONCRETE:8,80,AIR:0,100)
RandomBlock(-2,0,1,CONCRETE:8,65,QUARK:IRON_PLATE:0,10,QUARK:IRON_PLATE:1,10,STAINED_CLAY:9,15,STAINED_CLAY:7,10,CONCRETE:8,10,RUSTIC:IRON_LATTICE:1,15,RUSTIC:IRON_LATTICE:0,15,LEAVES:4,70,CONCRETE:8,80,AIR:0,100)
RandomBlock(-2,0,2,CONCRETE:8,65,QUARK:IRON_PLATE:0,10,QUARK:IRON_PLATE:1,10,STAINED_CLAY:9,15,STAINED_CLAY:7,10,CONCRETE:8,10,RUSTIC:IRON_LATTICE:1,15,RUSTIC:IRON_LATTICE:0,15,LEAVES:4,70,CONCRETE:8,80,AIR:0,100)
RandomBlock(-2,0,3,CONCRETE:8,65,QUARK:IRON_PLATE:0,10,QUARK:IRON_PLATE:1,10,STAINED_CLAY:9,15,STAINED_CLAY:7,10,CONCRETE:8,10,RUSTIC:IRON_LATTICE:1,15,RUSTIC:IRON_LATTICE:0,15,LEAVES:4,70,CONCRETE:8,80,AIR:0,100)
RandomBlock(-2,0,4,CONCRETE:8,65,QUARK:IRON_PLATE:0,10,QUARK:IRON_PLATE:1,10,STAINED_CLAY:9,15,STAINED_CLAY:7,10,CONCRETE:8,10,RUSTIC:IRON_LATTICE:1,15,RUSTIC:IRON_LATTICE:0,15,LEAVES:4,70,CONCRETE:8,80,AIR:0,100)
RandomBlock(-2,0,5,CONCRETE:8,65,QUARK:IRON_PLATE:0,10,QUARK:IRON_PLATE:1,10,STAINED_CLAY:9,15,STAINED_CLAY:7,10,CONCRETE:8,10,RUSTIC:IRON_LATTICE:1,15,RUSTIC:IRON_LATTICE:0,15,LEAVES:4,70,CONCRETE:8,80,AIR:0,100)
RandomBlock(-2,0,6,CONCRETE:8,65,QUARK:IRON_PLATE:0,10,QUARK:IRON_PLATE:1,10,STAINED_CLAY:9,15,STAINED_CLAY:7,10,CONCRETE:8,10,RUSTIC:IRON_LATTICE:1,15,RUSTIC:IRON_LATTICE:0,15,LEAVES:4,70,CONCRETE:8,80,AIR:0,100)
RandomBlock(-2,0,7,CONCRETE:8,65,QUARK:IRON_PLATE:0,10,QUARK:IRON_PLATE:1,10,STAINED_CLAY:9,15,STAINED_CLAY:7,10,CONCRETE:8,10,RUSTIC:IRON_LATTICE:1,15,RUSTIC:IRON_LATTICE:0,15,LEAVES:4,70,CONCRETE:8,80,AIR:0,100)
RandomBlock(-2,0,8,CONCRETE:8,65,QUARK:IRON_PLATE:0,10,QUARK:IRON_PLATE:1,10,STAINED_CLAY:9,15,STAINED_CLAY:7,10,CONCRETE:8,10,RUSTIC:IRON_LATTICE:1,15,RUSTIC:IRON_LATTICE:0,15,LEAVES:4,70,CONCRETE:8,80,AIR:0,100)
RandomBlock(-2,0,9,CONCRETE:8,65,QUARK:IRON_PLATE:0,10,QUARK:IRON_PLATE:1,10,STAINED_CLAY:9,15,STAINED_CLAY:7,10,CONCRETE:8,10,RUSTIC:IRON_LATTICE:1,15,RUSTIC:IRON_LATTICE:0,15,LEAVES:4,70,CONCRETE:8,80,AIR:0,100)
RandomBlock(-2,1,-6,CONCRETE:7,65,QUARK:IRON_PLATE:0,10,QUARK:IRON_PLATE:1,10,STAINED_CLAY:15,10,STAINED_CLAY:9,70,RUSTIC:IRON_LATTICE:1,5,RUSTIC:IRON_LATTICE:0,5,LEAVES:4,40,STAINED_CLAY:9,100)
Block(-2,1,-5,CAULDRON:3)
Block(-2,1,-4,AIR:0)
Block(-2,1,-3,AIR:0)
Block(-2,1,-2,AIR:0)
Block(-2,1,-1,AIR:0)
Block(-2,1,0,AIR:0)
Block(-2,1,1,AIR:0)
Block(-2,1,2,AIR:0)
RandomBlock(-2,1,3,CONCRETE:8,65,QUARK:IRON_PLATE:0,10,QUARK:IRON_PLATE:1,10,STAINED_CLAY:9,15,STAINED_CLAY:7,10,CONCRETE:8,10,RUSTIC:IRON_LATTICE:1,15,RUSTIC:IRON_LATTICE:0,15,LEAVES:4,70,CONCRETE:8,80,AIR:0,100)
Block(-2,1,4,SOIL:7)
Block(-2,1,5,SOIL:7)
Block(-2,1,6,STATIONARY_WATER:0)
Block(-2,1,7,SOIL:7)
Block(-2,1,8,SEA_LANTERN:0)
RandomBlock(-2,1,9,CONCRETE:7,65,QUARK:IRON_PLATE:0,10,QUARK:IRON_PLATE:1,10,STAINED_CLAY:15,10,STAINED_CLAY:9,70,RUSTIC:IRON_LATTICE:1,5,RUSTIC:IRON_LATTICE:0,5,LEAVES:4,40,STAINED_CLAY:9,100)
RandomBlock(-2,2,-6,CONCRETE:7,65,QUARK:IRON_PLATE:0,10,QUARK:IRON_PLATE:1,10,STAINED_CLAY:15,10,STAINED_CLAY:9,70,RUSTIC:IRON_LATTICE:1,5,RUSTIC:IRON_LATTICE:0,5,LEAVES:4,40,STAINED_CLAY:9,100)
Block(-2,2,-5,IRON_TRAPDOOR:1)
Block(-2,2,-4,AIR:0)
Block(-2,2,-3,AIR:0)
Block(-2,2,-2,AIR:0)
Block(-2,2,-1,AIR:0)
Block(-2,2,0,AIR:0)
Block(-2,2,1,AIR:0)
Block(-2,2,2,AIR:0)
Block(-2,2,3,STAINED_GLASS_PANE:15)
Block(-2,2,4,CROPS:0)
Block(-2,2,5,POTATO:2)
Block(-2,2,6,AIR:0)
Block(-2,2,7,CROPS:0)
Block(-2,2,8,STAINED_GLASS:15)
RandomBlock(-2,2,9,CONCRETE:7,65,QUARK:IRON_PLATE:0,10,QUARK:IRON_PLATE:1,10,STAINED_CLAY:15,10,STAINED_CLAY:9,70,RUSTIC:IRON_LATTICE:1,5,RUSTIC:IRON_LATTICE:0,5,LEAVES:4,40,STAINED_CLAY:9,100)
RandomBlock(-2,3,-6,CONCRETE:7,65,QUARK:IRON_PLATE:0,10,QUARK:IRON_PLATE:1,10,STAINED_CLAY:15,10,STAINED_CLAY:9,70,RUSTIC:IRON_LATTICE:1,5,RUSTIC:IRON_LATTICE:0,5,LEAVES:4,40,STAINED_CLAY:9,100)
RandomBlock(-2,3,-5,CONCRETE:8,65,QUARK:IRON_PLATE:0,10,QUARK:IRON_PLATE:1,10,STAINED_CLAY:9,15,STAINED_CLAY:7,10,CONCRETE:8,10,RUSTIC:IRON_LATTICE:1,15,RUSTIC:IRON_LATTICE:0,15,LEAVES:4,70,CONCRETE:8,80,AIR:0,100)
RandomBlock(-2,3,-4,CONCRETE:8,65,QUARK:IRON_PLATE:0,10,QUARK:IRON_PLATE:1,10,STAINED_CLAY:9,15,STAINED_CLAY:7,10,CONCRETE:8,10,RUSTIC:IRON_LATTICE:1,15,RUSTIC:IRON_LATTICE:0,15,LEAVES:4,70,CONCRETE:8,80,AIR:0,100)
Block(-2,3,-3,QUARTZ_STAIRS:7)
Block(-2,3,-2,AIR:0)
Block(-2,3,-1,AIR:0)
Block(-2,3,0,AIR:0)
Block(-2,3,1,AIR:0)
Block(-2,3,2,AIR:0)
Block(-2,3,3,AIR:0)
Block(-2,3,4,AIR:0)
Block(-2,3,5,AIR:0)
Block(-2,3,6,AIR:0)
Block(-2,3,7,AIR:0)
Block(-2,3,8,STAINED_GLASS:15)
RandomBlock(-2,3,9,CONCRETE:7,65,QUARK:IRON_PLATE:0,10,QUARK:IRON_PLATE:1,10,STAINED_CLAY:15,10,STAINED_CLAY:9,70,RUSTIC:IRON_LATTICE:1,5,RUSTIC:IRON_LATTICE:0,5,LEAVES:4,40,STAINED_CLAY:9,100)
RandomBlock(-2,4,-6,CONCRETE:7,65,QUARK:IRON_PLATE:0,10,QUARK:IRON_PLATE:1,10,STAINED_CLAY:15,10,STAINED_CLAY:9,70,RUSTIC:IRON_LATTICE:1,5,RUSTIC:IRON_LATTICE:0,5,LEAVES:4,40,STAINED_CLAY:9,100)
Block(-2,4,-5,AIR:0)
Block(-2,4,-4,AIR:0)
Block(-2,4,-3,QUARTZ_STAIRS:2)
RandomBlock(-2,4,-2,CONCRETE:8,65,QUARK:IRON_PLATE:0,10,QUARK:IRON_PLATE:1,10,STAINED_CLAY:9,15,STAINED_CLAY:7,10,CONCRETE:8,10,RUSTIC:IRON_LATTICE:1,15,RUSTIC:IRON_LATTICE:0,15,LEAVES:4,70,CONCRETE:8,80,AIR:0,100)
RandomBlock(-2,4,-1,CONCRETE:8,65,QUARK:IRON_PLATE:0,10,QUARK:IRON_PLATE:1,10,STAINED_CLAY:9,15,STAINED_CLAY:7,10,CONCRETE:8,10,RUSTIC:IRON_LATTICE:1,15,RUSTIC:IRON_LATTICE:0,15,LEAVES:4,70,CONCRETE:8,80,AIR:0,100)
RandomBlock(-2,4,0,CONCRETE:8,65,QUARK:IRON_PLATE:0,10,QUARK:IRON_PLATE:1,10,STAINED_CLAY:9,15,STAINED_CLAY:7,10,CONCRETE:8,10,RUSTIC:IRON_LATTICE:1,15,RUSTIC:IRON_LATTICE:0,15,LEAVES:4,70,CONCRETE:8,80,AIR:0,100)
RandomBlock(-2,4,1,CONCRETE:8,65,QUARK:IRON_PLATE:0,10,QUARK:IRON_PLATE:1,10,STAINED_CLAY:9,15,STAINED_CLAY:7,10,CONCRETE:8,10,RUSTIC:IRON_LATTICE:1,15,RUSTIC:IRON_LATTICE:0,15,LEAVES:4,70,CONCRETE:8,80,AIR:0,100)
RandomBlock(-2,4,2,CONCRETE:8,65,QUARK:IRON_PLATE:0,10,QUARK:IRON_PLATE:1,10,STAINED_CLAY:9,15,STAINED_CLAY:7,10,CONCRETE:8,10,RUSTIC:IRON_LATTICE:1,15,RUSTIC:IRON_LATTICE:0,15,LEAVES:4,70,CONCRETE:8,80,AIR:0,100)
RandomBlock(-2,4,3,CONCRETE:8,65,QUARK:IRON_PLATE:0,10,QUARK:IRON_PLATE:1,10,STAINED_CLAY:9,15,STAINED_CLAY:7,10,CONCRETE:8,10,RUSTIC:IRON_LATTICE:1,15,RUSTIC:IRON_LATTICE:0,15,LEAVES:4,70,CONCRETE:8,80,AIR:0,100)
RandomBlock(-2,4,4,CONCRETE:8,65,QUARK:IRON_PLATE:0,10,QUARK:IRON_PLATE:1,10,STAINED_CLAY:9,15,STAINED_CLAY:7,10,CONCRETE:8,10,RUSTIC:IRON_LATTICE:1,15,RUSTIC:IRON_LATTICE:0,15,LEAVES:4,70,CONCRETE:8,80,AIR:0,100)
RandomBlock(-2,4,5,CONCRETE:8,65,QUARK:IRON_PLATE:0,10,QUARK:IRON_PLATE:1,10,STAINED_CLAY:9,15,STAINED_CLAY:7,10,CONCRETE:8,10,RUSTIC:IRON_LATTICE:1,15,RUSTIC:IRON_LATTICE:0,15,LEAVES:4,70,CONCRETE:8,80,AIR:0,100)
RandomBlock(-2,4,6,CONCRETE:8,65,QUARK:IRON_PLATE:0,10,QUARK:IRON_PLATE:1,10,STAINED_CLAY:9,15,STAINED_CLAY:7,10,CONCRETE:8,10,RUSTIC:IRON_LATTICE:1,15,RUSTIC:IRON_LATTICE:0,15,LEAVES:4,70,CONCRETE:8,80,AIR:0,100)
RandomBlock(-2,4,7,CONCRETE:8,65,QUARK:IRON_PLATE:0,10,QUARK:IRON_PLATE:1,10,STAINED_CLAY:9,15,STAINED_CLAY:7,10,CONCRETE:8,10,RUSTIC:IRON_LATTICE:1,15,RUSTIC:IRON_LATTICE:0,15,LEAVES:4,70,CONCRETE:8,80,AIR:0,100)
RandomBlock(-2,4,8,CONCRETE:8,65,QUARK:IRON_PLATE:0,10,QUARK:IRON_PLATE:1,10,STAINED_CLAY:9,15,STAINED_CLAY:7,10,CONCRETE:8,10,RUSTIC:IRON_LATTICE:1,15,RUSTIC:IRON_LATTICE:0,15,LEAVES:4,70,CONCRETE:8,80,AIR:0,100)
RandomBlock(-2,4,9,CONCRETE:7,65,QUARK:IRON_PLATE:0,10,QUARK:IRON_PLATE:1,10,STAINED_CLAY:15,10,STAINED_CLAY:9,70,RUSTIC:IRON_LATTICE:1,5,RUSTIC:IRON_LATTICE:0,5,LEAVES:4,40,STAINED_CLAY:9,100)
RandomBlock(-1,0,-6,CONCRETE:8,65,QUARK:IRON_PLATE:0,10,QUARK:IRON_PLATE:1,10,STAINED_CLAY:9,15,STAINED_CLAY:7,10,CONCRETE:8,10,RUSTIC:IRON_LATTICE:1,15,RUSTIC:IRON_LATTICE:0,15,LEAVES:4,70,CONCRETE:8,80,AIR:0,100)
RandomBlock(-1,0,-5,CONCRETE:8,65,QUARK:IRON_PLATE:0,10,QUARK:IRON_PLATE:1,10,STAINED_CLAY:9,15,STAINED_CLAY:7,10,CONCRETE:8,10,RUSTIC:IRON_LATTICE:1,15,RUSTIC:IRON_LATTICE:0,15,LEAVES:4,70,CONCRETE:8,80,AIR:0,100)
Block(-1,0,-4,SEA_LANTERN:0)
Block(-1,0,-3,SEA_LANTERN:0)
Block(-1,0,-2,SEA_LANTERN:0)
Block(-1,0,-1,SEA_LANTERN:0)
Block(-1,0,0,SEA_LANTERN:0)
RandomBlock(-1,0,1,CONCRETE:8,65,QUARK:IRON_PLATE:0,10,QUARK:IRON_PLATE:1,10,STAINED_CLAY:9,15,STAINED_CLAY:7,10,CONCRETE:8,10,RUSTIC:IRON_LATTICE:1,15,RUSTIC:IRON_LATTICE:0,15,LEAVES:4,70,CONCRETE:8,80,AIR:0,100)
RandomBlock(-1,0,2,CONCRETE:8,65,QUARK:IRON_PLATE:0,10,QUARK:IRON_PLATE:1,10,STAINED_CLAY:9,15,STAINED_CLAY:7,10,CONCRETE:8,10,RUSTIC:IRON_LATTICE:1,15,RUSTIC:IRON_LATTICE:0,15,LEAVES:4,70,CONCRETE:8,80,AIR:0,100)
RandomBlock(-1,0,3,CONCRETE:8,65,QUARK:IRON_PLATE:0,10,QUARK:IRON_PLATE:1,10,STAINED_CLAY:9,15,STAINED_CLAY:7,10,CONCRETE:8,10,RUSTIC:IRON_LATTICE:1,15,RUSTIC:IRON_LATTICE:0,15,LEAVES:4,70,CONCRETE:8,80,AIR:0,100)
RandomBlock(-1,0,4,CONCRETE:8,65,QUARK:IRON_PLATE:0,10,QUARK:IRON_PLATE:1,10,STAINED_CLAY:9,15,STAINED_CLAY:7,10,CONCRETE:8,10,RUSTIC:IRON_LATTICE:1,15,RUSTIC:IRON_LATTICE:0,15,LEAVES:4,70,CONCRETE:8,80,AIR:0,100)
RandomBlock(-1,0,5,CONCRETE:8,65,QUARK:IRON_PLATE:0,10,QUARK:IRON_PLATE:1,10,STAINED_CLAY:9,15,STAINED_CLAY:7,10,CONCRETE:8,10,RUSTIC:IRON_LATTICE:1,15,RUSTIC:IRON_LATTICE:0,15,LEAVES:4,70,CONCRETE:8,80,AIR:0,100)
RandomBlock(-1,0,6,CONCRETE:8,65,QUARK:IRON_PLATE:0,10,QUARK:IRON_PLATE:1,10,STAINED_CLAY:9,15,STAINED_CLAY:7,10,CONCRETE:8,10,RUSTIC:IRON_LATTICE:1,15,RUSTIC:IRON_LATTICE:0,15,LEAVES:4,70,CONCRETE:8,80,AIR:0,100)
RandomBlock(-1,0,7,CONCRETE:8,65,QUARK:IRON_PLATE:0,10,QUARK:IRON_PLATE:1,10,STAINED_CLAY:9,15,STAINED_CLAY:7,10,CONCRETE:8,10,RUSTIC:IRON_LATTICE:1,15,RUSTIC:IRON_LATTICE:0,15,LEAVES:4,70,CONCRETE:8,80,AIR:0,100)
RandomBlock(-1,0,8,CONCRETE:8,65,QUARK:IRON_PLATE:0,10,QUARK:IRON_PLATE:1,10,STAINED_CLAY:9,15,STAINED_CLAY:7,10,CONCRETE:8,10,RUSTIC:IRON_LATTICE:1,15,RUSTIC:IRON_LATTICE:0,15,LEAVES:4,70,CONCRETE:8,80,AIR:0,100)
RandomBlock(-1,0,9,CONCRETE:8,65,QUARK:IRON_PLATE:0,10,QUARK:IRON_PLATE:1,10,STAINED_CLAY:9,15,STAINED_CLAY:7,10,CONCRETE:8,10,RUSTIC:IRON_LATTICE:1,15,RUSTIC:IRON_LATTICE:0,15,LEAVES:4,70,CONCRETE:8,80,AIR:0,100)
RandomBlock(-1,1,-6,CONCRETE:8,65,QUARK:IRON_PLATE:0,10,QUARK:IRON_PLATE:1,10,STAINED_CLAY:9,15,STAINED_CLAY:7,10,CONCRETE:8,10,RUSTIC:IRON_LATTICE:1,15,RUSTIC:IRON_LATTICE:0,15,LEAVES:4,70,CONCRETE:8,80,AIR:0,100)
RandomBlock(-1,1,-5,CONCRETE:8,65,QUARK:IRON_PLATE:0,10,QUARK:IRON_PLATE:1,10,STAINED_CLAY:9,15,STAINED_CLAY:7,10,CONCRETE:8,10,RUSTIC:IRON_LATTICE:1,15,RUSTIC:IRON_LATTICE:0,15,LEAVES:4,70,CONCRETE:8,80,AIR:0,100)
Block(-1,1,-4,STAINED_GLASS:15)
Block(-1,1,-3,STAINED_GLASS:15)
Block(-1,1,-2,STAINED_GLASS:15)
Block(-1,1,-1,STAINED_GLASS:15)
Block(-1,1,0,STAINED_GLASS:15)
Block(-1,1,1,AIR:0)
Block(-1,1,2,AIR:0)
RandomBlock(-1,1,3,CONCRETE:8,65,QUARK:IRON_PLATE:0,10,QUARK:IRON_PLATE:1,10,STAINED_CLAY:9,15,STAINED_CLAY:7,10,CONCRETE:8,10,RUSTIC:IRON_LATTICE:1,15,RUSTIC:IRON_LATTICE:0,15,LEAVES:4,70,CONCRETE:8,80,AIR:0,100)
Block(-1,1,4,SOIL:7)
Block(-1,1,5,SOIL:7)
Block(-1,1,6,STATIONARY_WATER:0)
Block(-1,1,7,SOIL:7)
RandomBlock(-1,1,8,CONCRETE:8,65,QUARK:IRON_PLATE:0,10,QUARK:IRON_PLATE:1,10,STAINED_CLAY:9,15,STAINED_CLAY:7,10,CONCRETE:8,10,RUSTIC:IRON_LATTICE:1,15,RUSTIC:IRON_LATTICE:0,15,LEAVES:4,70,CONCRETE:8,80,AIR:0,100)
RandomBlock(-1,1,9,CONCRETE:8,65,QUARK:IRON_PLATE:0,10,QUARK:IRON_PLATE:1,10,STAINED_CLAY:9,15,STAINED_CLAY:7,10,CONCRETE:8,10,RUSTIC:IRON_LATTICE:1,15,RUSTIC:IRON_LATTICE:0,15,LEAVES:4,70,CONCRETE:8,80,AIR:0,100)
RandomBlock(-1,2,-6,CONCRETE:8,65,QUARK:IRON_PLATE:0,10,QUARK:IRON_PLATE:1,10,STAINED_CLAY:9,15,STAINED_CLAY:7,10,CONCRETE:8,10,RUSTIC:IRON_LATTICE:1,15,RUSTIC:IRON_LATTICE:0,15,LEAVES:4,70,CONCRETE:8,80,AIR:0,100)
RandomBlock(-1,2,-5,CONCRETE:8,65,QUARK:IRON_PLATE:0,10,QUARK:IRON_PLATE:1,10,STAINED_CLAY:9,15,STAINED_CLAY:7,10,CONCRETE:8,10,RUSTIC:IRON_LATTICE:1,15,RUSTIC:IRON_LATTICE:0,15,LEAVES:4,70,CONCRETE:8,80,AIR:0,100)
Block(-1,2,-4,STAINED_GLASS:15)
Block(-1,2,-3,STAINED_GLASS:15)
Block(-1,2,-2,STAINED_GLASS:15)
Block(-1,2,-1,STAINED_GLASS:15)
Block(-1,2,0,STAINED_GLASS:15)
Block(-1,2,1,AIR:0)
Block(-1,2,2,AIR:0)
Block(-1,2,3,STAINED_GLASS_PANE:15)
Block(-1,2,4,AIR:0)
Block(-1,2,5,AIR:0)
Block(-1,2,6,AIR:0)
Block(-1,2,7,AIR:0)
RandomBlock(-1,2,8,CONCRETE:8,65,QUARK:IRON_PLATE:0,10,QUARK:IRON_PLATE:1,10,STAINED_CLAY:9,15,STAINED_CLAY:7,10,CONCRETE:8,10,RUSTIC:IRON_LATTICE:1,15,RUSTIC:IRON_LATTICE:0,15,LEAVES:4,70,CONCRETE:8,80,AIR:0,100)
RandomBlock(-1,2,9,CONCRETE:8,65,QUARK:IRON_PLATE:0,10,QUARK:IRON_PLATE:1,10,STAINED_CLAY:9,15,STAINED_CLAY:7,10,CONCRETE:8,10,RUSTIC:IRON_LATTICE:1,15,RUSTIC:IRON_LATTICE:0,15,LEAVES:4,70,CONCRETE:8,80,AIR:0,100)
RandomBlock(-1,3,-6,CONCRETE:8,65,QUARK:IRON_PLATE:0,10,QUARK:IRON_PLATE:1,10,STAINED_CLAY:9,15,STAINED_CLAY:7,10,CONCRETE:8,10,RUSTIC:IRON_LATTICE:1,15,RUSTIC:IRON_LATTICE:0,15,LEAVES:4,70,CONCRETE:8,80,AIR:0,100)
RandomBlock(-1,3,-5,CONCRETE:8,65,QUARK:IRON_PLATE:0,10,QUARK:IRON_PLATE:1,10,STAINED_CLAY:9,15,STAINED_CLAY:7,10,CONCRETE:8,10,RUSTIC:IRON_LATTICE:1,15,RUSTIC:IRON_LATTICE:0,15,LEAVES:4,70,CONCRETE:8,80,AIR:0,100)
Block(-1,3,-4,STAINED_GLASS:15)
Block(-1,3,-3,STAINED_GLASS:15)
Block(-1,3,-2,STAINED_GLASS:15)
Block(-1,3,-1,STAINED_GLASS:15)
Block(-1,3,0,STAINED_GLASS:15)
Block(-1,3,1,AIR:0)
Block(-1,3,2,AIR:0)
Block(-1,3,3,AIR:0)
Block(-1,3,4,AIR:0)
Block(-1,3,5,AIR:0)
Block(-1,3,6,AIR:0)
Block(-1,3,7,AIR:0)
RandomBlock(-1,3,8,CONCRETE:8,65,QUARK:IRON_PLATE:0,10,QUARK:IRON_PLATE:1,10,STAINED_CLAY:9,15,STAINED_CLAY:7,10,CONCRETE:8,10,RUSTIC:IRON_LATTICE:1,15,RUSTIC:IRON_LATTICE:0,15,LEAVES:4,70,CONCRETE:8,80,AIR:0,100)
RandomBlock(-1,3,9,CONCRETE:8,65,QUARK:IRON_PLATE:0,10,QUARK:IRON_PLATE:1,10,STAINED_CLAY:9,15,STAINED_CLAY:7,10,CONCRETE:8,10,RUSTIC:IRON_LATTICE:1,15,RUSTIC:IRON_LATTICE:0,15,LEAVES:4,70,CONCRETE:8,80,AIR:0,100)
RandomBlock(-1,4,-6,CONCRETE:8,65,QUARK:IRON_PLATE:0,10,QUARK:IRON_PLATE:1,10,STAINED_CLAY:9,15,STAINED_CLAY:7,10,CONCRETE:8,10,RUSTIC:IRON_LATTICE:1,15,RUSTIC:IRON_LATTICE:0,15,LEAVES:4,70,CONCRETE:8,80,AIR:0,100)
RandomBlock(-1,4,-5,CONCRETE:8,65,QUARK:IRON_PLATE:0,10,QUARK:IRON_PLATE:1,10,STAINED_CLAY:9,15,STAINED_CLAY:7,10,CONCRETE:8,10,RUSTIC:IRON_LATTICE:1,15,RUSTIC:IRON_LATTICE:0,15,LEAVES:4,70,CONCRETE:8,80,AIR:0,100)
Block(-1,4,-4,STAINED_GLASS:15)
Block(-1,4,-3,STAINED_GLASS:15)
Block(-1,4,-2,STAINED_GLASS:15)
Block(-1,4,-1,STAINED_GLASS:15)
Block(-1,4,0,STAINED_GLASS:15)
RandomBlock(-1,4,1,CONCRETE:8,65,QUARK:IRON_PLATE:0,10,QUARK:IRON_PLATE:1,10,STAINED_CLAY:9,15,STAINED_CLAY:7,10,CONCRETE:8,10,RUSTIC:IRON_LATTICE:1,15,RUSTIC:IRON_LATTICE:0,15,LEAVES:4,70,CONCRETE:8,80,AIR:0,100)
RandomBlock(-1,4,2,CONCRETE:8,65,QUARK:IRON_PLATE:0,10,QUARK:IRON_PLATE:1,10,STAINED_CLAY:9,15,STAINED_CLAY:7,10,CONCRETE:8,10,RUSTIC:IRON_LATTICE:1,15,RUSTIC:IRON_LATTICE:0,15,LEAVES:4,70,CONCRETE:8,80,AIR:0,100)
RandomBlock(-1,4,3,CONCRETE:8,65,QUARK:IRON_PLATE:0,10,QUARK:IRON_PLATE:1,10,STAINED_CLAY:9,15,STAINED_CLAY:7,10,CONCRETE:8,10,RUSTIC:IRON_LATTICE:1,15,RUSTIC:IRON_LATTICE:0,15,LEAVES:4,70,CONCRETE:8,80,AIR:0,100)
RandomBlock(-1,4,4,CONCRETE:8,65,QUARK:IRON_PLATE:0,10,QUARK:IRON_PLATE:1,10,STAINED_CLAY:9,15,STAINED_CLAY:7,10,CONCRETE:8,10,RUSTIC:IRON_LATTICE:1,15,RUSTIC:IRON_LATTICE:0,15,LEAVES:4,70,CONCRETE:8,80,AIR:0,100)
RandomBlock(-1,4,5,CONCRETE:8,65,QUARK:IRON_PLATE:0,10,QUARK:IRON_PLATE:1,10,STAINED_CLAY:9,15,STAINED_CLAY:7,10,CONCRETE:8,10,RUSTIC:IRON_LATTICE:1,15,RUSTIC:IRON_LATTICE:0,15,LEAVES:4,70,CONCRETE:8,80,AIR:0,100)
RandomBlock(-1,4,6,CONCRETE:8,65,QUARK:IRON_PLATE:0,10,QUARK:IRON_PLATE:1,10,STAINED_CLAY:9,15,STAINED_CLAY:7,10,CONCRETE:8,10,RUSTIC:IRON_LATTICE:1,15,RUSTIC:IRON_LATTICE:0,15,LEAVES:4,70,CONCRETE:8,80,AIR:0,100)
RandomBlock(-1,4,7,CONCRETE:8,65,QUARK:IRON_PLATE:0,10,QUARK:IRON_PLATE:1,10,STAINED_CLAY:9,15,STAINED_CLAY:7,10,CONCRETE:8,10,RUSTIC:IRON_LATTICE:1,15,RUSTIC:IRON_LATTICE:0,15,LEAVES:4,70,CONCRETE:8,80,AIR:0,100)
RandomBlock(-1,4,8,CONCRETE:8,65,QUARK:IRON_PLATE:0,10,QUARK:IRON_PLATE:1,10,STAINED_CLAY:9,15,STAINED_CLAY:7,10,CONCRETE:8,10,RUSTIC:IRON_LATTICE:1,15,RUSTIC:IRON_LATTICE:0,15,LEAVES:4,70,CONCRETE:8,80,AIR:0,100)
RandomBlock(-1,4,9,CONCRETE:8,65,QUARK:IRON_PLATE:0,10,QUARK:IRON_PLATE:1,10,STAINED_CLAY:9,15,STAINED_CLAY:7,10,CONCRETE:8,10,RUSTIC:IRON_LATTICE:1,15,RUSTIC:IRON_LATTICE:0,15,LEAVES:4,70,CONCRETE:8,80,AIR:0,100)
RandomBlock(0,0,-6,CONCRETE:8,65,QUARK:IRON_PLATE:0,10,QUARK:IRON_PLATE:1,10,STAINED_CLAY:9,15,STAINED_CLAY:7,10,CONCRETE:8,10,RUSTIC:IRON_LATTICE:1,15,RUSTIC:IRON_LATTICE:0,15,LEAVES:4,70,CONCRETE:8,80,AIR:0,100)
RandomBlock(0,0,-5,CONCRETE:8,65,QUARK:IRON_PLATE:0,10,QUARK:IRON_PLATE:1,10,STAINED_CLAY:9,15,STAINED_CLAY:7,10,CONCRETE:8,10,RUSTIC:IRON_LATTICE:1,15,RUSTIC:IRON_LATTICE:0,15,LEAVES:4,70,CONCRETE:8,80,AIR:0,100)
RandomBlock(0,0,-4,CONCRETE:8,65,QUARK:IRON_PLATE:0,10,QUARK:IRON_PLATE:1,10,STAINED_CLAY:9,15,STAINED_CLAY:7,10,CONCRETE:8,10,RUSTIC:IRON_LATTICE:1,15,RUSTIC:IRON_LATTICE:0,15,LEAVES:4,70,CONCRETE:8,80,AIR:0,100)
RandomBlock(0,0,-3,CONCRETE:8,65,QUARK:IRON_PLATE:0,10,QUARK:IRON_PLATE:1,10,STAINED_CLAY:9,15,STAINED_CLAY:7,10,CONCRETE:8,10,RUSTIC:IRON_LATTICE:1,15,RUSTIC:IRON_LATTICE:0,15,LEAVES:4,70,CONCRETE:8,80,AIR:0,100)
RandomBlock(0,0,-2,CONCRETE:8,65,QUARK:IRON_PLATE:0,10,QUARK:IRON_PLATE:1,10,STAINED_CLAY:9,15,STAINED_CLAY:7,10,CONCRETE:8,10,RUSTIC:IRON_LATTICE:1,15,RUSTIC:IRON_LATTICE:0,15,LEAVES:4,70,CONCRETE:8,80,AIR:0,100)
RandomBlock(0,0,-1,CONCRETE:8,65,QUARK:IRON_PLATE:0,10,QUARK:IRON_PLATE:1,10,STAINED_CLAY:9,15,STAINED_CLAY:7,10,CONCRETE:8,10,RUSTIC:IRON_LATTICE:1,15,RUSTIC:IRON_LATTICE:0,15,LEAVES:4,70,CONCRETE:8,80,AIR:0,100)
RandomBlock(0,0,0,CONCRETE:8,65,QUARK:IRON_PLATE:0,10,QUARK:IRON_PLATE:1,10,STAINED_CLAY:9,15,STAINED_CLAY:7,10,CONCRETE:8,10,RUSTIC:IRON_LATTICE:1,15,RUSTIC:IRON_LATTICE:0,15,LEAVES:4,70,CONCRETE:8,80,AIR:0,100)
RandomBlock(0,0,1,CONCRETE:8,65,QUARK:IRON_PLATE:0,10,QUARK:IRON_PLATE:1,10,STAINED_CLAY:9,15,STAINED_CLAY:7,10,CONCRETE:8,10,RUSTIC:IRON_LATTICE:1,15,RUSTIC:IRON_LATTICE:0,15,LEAVES:4,70,CONCRETE:8,80,AIR:0,100)
RandomBlock(0,0,2,CONCRETE:8,65,QUARK:IRON_PLATE:0,10,QUARK:IRON_PLATE:1,10,STAINED_CLAY:9,15,STAINED_CLAY:7,10,CONCRETE:8,10,RUSTIC:IRON_LATTICE:1,15,RUSTIC:IRON_LATTICE:0,15,LEAVES:4,70,CONCRETE:8,80,AIR:0,100)
RandomBlock(0,0,3,CONCRETE:8,65,QUARK:IRON_PLATE:0,10,QUARK:IRON_PLATE:1,10,STAINED_CLAY:9,15,STAINED_CLAY:7,10,CONCRETE:8,10,RUSTIC:IRON_LATTICE:1,15,RUSTIC:IRON_LATTICE:0,15,LEAVES:4,70,CONCRETE:8,80,AIR:0,100)
RandomBlock(0,0,4,CONCRETE:8,65,QUARK:IRON_PLATE:0,10,QUARK:IRON_PLATE:1,10,STAINED_CLAY:9,15,STAINED_CLAY:7,10,CONCRETE:8,10,RUSTIC:IRON_LATTICE:1,15,RUSTIC:IRON_LATTICE:0,15,LEAVES:4,70,CONCRETE:8,80,AIR:0,100)
RandomBlock(0,0,5,CONCRETE:8,65,QUARK:IRON_PLATE:0,10,QUARK:IRON_PLATE:1,10,STAINED_CLAY:9,15,STAINED_CLAY:7,10,CONCRETE:8,10,RUSTIC:IRON_LATTICE:1,15,RUSTIC:IRON_LATTICE:0,15,LEAVES:4,70,CONCRETE:8,80,AIR:0,100)
RandomBlock(0,0,6,CONCRETE:8,65,QUARK:IRON_PLATE:0,10,QUARK:IRON_PLATE:1,10,STAINED_CLAY:9,15,STAINED_CLAY:7,10,CONCRETE:8,10,RUSTIC:IRON_LATTICE:1,15,RUSTIC:IRON_LATTICE:0,15,LEAVES:4,70,CONCRETE:8,80,AIR:0,100)
RandomBlock(0,0,7,CONCRETE:8,65,QUARK:IRON_PLATE:0,10,QUARK:IRON_PLATE:1,10,STAINED_CLAY:9,15,STAINED_CLAY:7,10,CONCRETE:8,10,RUSTIC:IRON_LATTICE:1,15,RUSTIC:IRON_LATTICE:0,15,LEAVES:4,70,CONCRETE:8,80,AIR:0,100)
RandomBlock(0,0,8,CONCRETE:8,65,QUARK:IRON_PLATE:0,10,QUARK:IRON_PLATE:1,10,STAINED_CLAY:9,15,STAINED_CLAY:7,10,CONCRETE:8,10,RUSTIC:IRON_LATTICE:1,15,RUSTIC:IRON_LATTICE:0,15,LEAVES:4,70,CONCRETE:8,80,AIR:0,100)
RandomBlock(0,0,9,CONCRETE:8,65,QUARK:IRON_PLATE:0,10,QUARK:IRON_PLATE:1,10,STAINED_CLAY:9,15,STAINED_CLAY:7,10,CONCRETE:8,10,RUSTIC:IRON_LATTICE:1,15,RUSTIC:IRON_LATTICE:0,15,LEAVES:4,70,CONCRETE:8,80,AIR:0,100)
Block(0,1,-6,IRON_TRAPDOOR:7)
Block(0,1,-5,AIR:0)
Block(0,1,-4,AIR:0)
Block(0,1,-3,AIR:0)
Block(0,1,-2,AIR:0)
Block(0,1,-1,AIR:0)
Block(0,1,0,AIR:0)
Block(0,1,1,AIR:0)
Block(0,1,2,AIR:0)
RandomBlock(0,1,3,CONCRETE:8,65,QUARK:IRON_PLATE:0,10,QUARK:IRON_PLATE:1,10,STAINED_CLAY:9,15,STAINED_CLAY:7,10,CONCRETE:8,10,RUSTIC:IRON_LATTICE:1,15,RUSTIC:IRON_LATTICE:0,15,LEAVES:4,70,CONCRETE:8,80,AIR:0,100)
Block(0,1,4,SOIL:7)
Block(0,1,5,SOIL:7)
Block(0,1,6,STATIONARY_WATER:0)
Block(0,1,7,SOIL:7)
Block(0,1,8,SEA_LANTERN:0)
RandomBlock(0,1,9,CONCRETE:7,65,QUARK:IRON_PLATE:0,10,QUARK:IRON_PLATE:1,10,STAINED_CLAY:15,10,STAINED_CLAY:9,70,RUSTIC:IRON_LATTICE:1,5,RUSTIC:IRON_LATTICE:0,5,LEAVES:4,40,STAINED_CLAY:9,100)
Block(0,2,-6,IRON_TRAPDOOR:7)
Block(0,2,-5,AIR:0)
Block(0,2,-4,AIR:0)
Block(0,2,-3,AIR:0)
Block(0,2,-2,AIR:0)
Block(0,2,-1,AIR:0)
Block(0,2,0,AIR:0)
Block(0,2,1,AIR:0)
Block(0,2,2,AIR:0)
Block(0,2,3,STAINED_GLASS_PANE:15)
Block(0,2,4,CROPS:1)
Block(0,2,5,POTATO:0)
Block(0,2,6,AIR:0)
Block(0,2,7,CROPS:1)
Block(0,2,8,STAINED_GLASS:15)
RandomBlock(0,2,9,CONCRETE:7,65,QUARK:IRON_PLATE:0,10,QUARK:IRON_PLATE:1,10,STAINED_CLAY:15,10,STAINED_CLAY:9,70,RUSTIC:IRON_LATTICE:1,5,RUSTIC:IRON_LATTICE:0,5,LEAVES:4,40,STAINED_CLAY:9,100)
Block(0,3,-6,DROPPER:0)
Block(0,3,-5,AIR:0)
Block(0,3,-4,AIR:0)
Block(0,3,-3,AIR:0)
Block(0,3,-2,AIR:0)
Block(0,3,-1,AIR:0)
Block(0,3,0,AIR:0)
Block(0,3,1,AIR:0)
Block(0,3,2,AIR:0)
Block(0,3,3,AIR:0)
Block(0,3,4,AIR:0)
Block(0,3,5,AIR:0)
Block(0,3,6,AIR:0)
Block(0,3,7,AIR:0)
Block(0,3,8,STAINED_GLASS:15)
RandomBlock(0,3,9,CONCRETE:7,65,QUARK:IRON_PLATE:0,10,QUARK:IRON_PLATE:1,10,STAINED_CLAY:15,10,STAINED_CLAY:9,70,RUSTIC:IRON_LATTICE:1,5,RUSTIC:IRON_LATTICE:0,5,LEAVES:4,40,STAINED_CLAY:9,100)
RandomBlock(0,4,-6,CONCRETE:7,65,QUARK:IRON_PLATE:0,10,QUARK:IRON_PLATE:1,10,STAINED_CLAY:15,10,STAINED_CLAY:9,70,RUSTIC:IRON_LATTICE:1,5,RUSTIC:IRON_LATTICE:0,5,LEAVES:4,40,STAINED_CLAY:9,100)
RandomBlock(0,4,-5,CONCRETE:8,65,QUARK:IRON_PLATE:0,10,QUARK:IRON_PLATE:1,10,STAINED_CLAY:9,15,STAINED_CLAY:7,10,CONCRETE:8,10,RUSTIC:IRON_LATTICE:1,15,RUSTIC:IRON_LATTICE:0,15,LEAVES:4,70,CONCRETE:8,80,AIR:0,100)
RandomBlock(0,4,-4,CONCRETE:8,65,QUARK:IRON_PLATE:0,10,QUARK:IRON_PLATE:1,10,STAINED_CLAY:9,15,STAINED_CLAY:7,10,CONCRETE:8,10,RUSTIC:IRON_LATTICE:1,15,RUSTIC:IRON_LATTICE:0,15,LEAVES:4,70,CONCRETE:8,80,AIR:0,100)
RandomBlock(0,4,-3,CONCRETE:8,65,QUARK:IRON_PLATE:0,10,QUARK:IRON_PLATE:1,10,STAINED_CLAY:9,15,STAINED_CLAY:7,10,CONCRETE:8,10,RUSTIC:IRON_LATTICE:1,15,RUSTIC:IRON_LATTICE:0,15,LEAVES:4,70,CONCRETE:8,80,AIR:0,100)
RandomBlock(0,4,-2,CONCRETE:8,65,QUARK:IRON_PLATE:0,10,QUARK:IRON_PLATE:1,10,STAINED_CLAY:9,15,STAINED_CLAY:7,10,CONCRETE:8,10,RUSTIC:IRON_LATTICE:1,15,RUSTIC:IRON_LATTICE:0,15,LEAVES:4,70,CONCRETE:8,80,AIR:0,100)
RandomBlock(0,4,-1,CONCRETE:8,65,QUARK:IRON_PLATE:0,10,QUARK:IRON_PLATE:1,10,STAINED_CLAY:9,15,STAINED_CLAY:7,10,CONCRETE:8,10,RUSTIC:IRON_LATTICE:1,15,RUSTIC:IRON_LATTICE:0,15,LEAVES:4,70,CONCRETE:8,80,AIR:0,100)
RandomBlock(0,4,0,CONCRETE:8,65,QUARK:IRON_PLATE:0,10,QUARK:IRON_PLATE:1,10,STAINED_CLAY:9,15,STAINED_CLAY:7,10,CONCRETE:8,10,RUSTIC:IRON_LATTICE:1,15,RUSTIC:IRON_LATTICE:0,15,LEAVES:4,70,CONCRETE:8,80,AIR:0,100)
RandomBlock(0,4,1,CONCRETE:8,65,QUARK:IRON_PLATE:0,10,QUARK:IRON_PLATE:1,10,STAINED_CLAY:9,15,STAINED_CLAY:7,10,CONCRETE:8,10,RUSTIC:IRON_LATTICE:1,15,RUSTIC:IRON_LATTICE:0,15,LEAVES:4,70,CONCRETE:8,80,AIR:0,100)
RandomBlock(0,4,2,CONCRETE:8,65,QUARK:IRON_PLATE:0,10,QUARK:IRON_PLATE:1,10,STAINED_CLAY:9,15,STAINED_CLAY:7,10,CONCRETE:8,10,RUSTIC:IRON_LATTICE:1,15,RUSTIC:IRON_LATTICE:0,15,LEAVES:4,70,CONCRETE:8,80,AIR:0,100)
RandomBlock(0,4,3,CONCRETE:8,65,QUARK:IRON_PLATE:0,10,QUARK:IRON_PLATE:1,10,STAINED_CLAY:9,15,STAINED_CLAY:7,10,CONCRETE:8,10,RUSTIC:IRON_LATTICE:1,15,RUSTIC:IRON_LATTICE:0,15,LEAVES:4,70,CONCRETE:8,80,AIR:0,100)
RandomBlock(0,4,4,CONCRETE:8,65,QUARK:IRON_PLATE:0,10,QUARK:IRON_PLATE:1,10,STAINED_CLAY:9,15,STAINED_CLAY:7,10,CONCRETE:8,10,RUSTIC:IRON_LATTICE:1,15,RUSTIC:IRON_LATTICE:0,15,LEAVES:4,70,CONCRETE:8,80,AIR:0,100)
RandomBlock(0,4,5,CONCRETE:8,65,QUARK:IRON_PLATE:0,10,QUARK:IRON_PLATE:1,10,STAINED_CLAY:9,15,STAINED_CLAY:7,10,CONCRETE:8,10,RUSTIC:IRON_LATTICE:1,15,RUSTIC:IRON_LATTICE:0,15,LEAVES:4,70,CONCRETE:8,80,AIR:0,100)
RandomBlock(0,4,6,CONCRETE:8,65,QUARK:IRON_PLATE:0,10,QUARK:IRON_PLATE:1,10,STAINED_CLAY:9,15,STAINED_CLAY:7,10,CONCRETE:8,10,RUSTIC:IRON_LATTICE:1,15,RUSTIC:IRON_LATTICE:0,15,LEAVES:4,70,CONCRETE:8,80,AIR:0,100)
RandomBlock(0,4,7,CONCRETE:8,65,QUARK:IRON_PLATE:0,10,QUARK:IRON_PLATE:1,10,STAINED_CLAY:9,15,STAINED_CLAY:7,10,CONCRETE:8,10,RUSTIC:IRON_LATTICE:1,15,RUSTIC:IRON_LATTICE:0,15,LEAVES:4,70,CONCRETE:8,80,AIR:0,100)
RandomBlock(0,4,8,CONCRETE:8,65,QUARK:IRON_PLATE:0,10,QUARK:IRON_PLATE:1,10,STAINED_CLAY:9,15,STAINED_CLAY:7,10,CONCRETE:8,10,RUSTIC:IRON_LATTICE:1,15,RUSTIC:IRON_LATTICE:0,15,LEAVES:4,70,CONCRETE:8,80,AIR:0,100)
RandomBlock(0,4,9,CONCRETE:7,65,QUARK:IRON_PLATE:0,10,QUARK:IRON_PLATE:1,10,STAINED_CLAY:15,10,STAINED_CLAY:9,70,RUSTIC:IRON_LATTICE:1,5,RUSTIC:IRON_LATTICE:0,5,LEAVES:4,40,STAINED_CLAY:9,100)
RandomBlock(1,0,-6,CONCRETE:8,65,QUARK:IRON_PLATE:0,10,QUARK:IRON_PLATE:1,10,STAINED_CLAY:9,15,STAINED_CLAY:7,10,CONCRETE:8,10,RUSTIC:IRON_LATTICE:1,15,RUSTIC:IRON_LATTICE:0,15,LEAVES:4,70,CONCRETE:8,80,AIR:0,100)
RandomBlock(1,0,-5,CONCRETE:8,65,QUARK:IRON_PLATE:0,10,QUARK:IRON_PLATE:1,10,STAINED_CLAY:9,15,STAINED_CLAY:7,10,CONCRETE:8,10,RUSTIC:IRON_LATTICE:1,15,RUSTIC:IRON_LATTICE:0,15,LEAVES:4,70,CONCRETE:8,80,AIR:0,100)
RandomBlock(1,0,-4,CONCRETE:8,65,QUARK:IRON_PLATE:0,10,QUARK:IRON_PLATE:1,10,STAINED_CLAY:9,15,STAINED_CLAY:7,10,CONCRETE:8,10,RUSTIC:IRON_LATTICE:1,15,RUSTIC:IRON_LATTICE:0,15,LEAVES:4,70,CONCRETE:8,80,AIR:0,100)
RandomBlock(1,0,-3,CONCRETE:8,65,QUARK:IRON_PLATE:0,10,QUARK:IRON_PLATE:1,10,STAINED_CLAY:9,15,STAINED_CLAY:7,10,CONCRETE:8,10,RUSTIC:IRON_LATTICE:1,15,RUSTIC:IRON_LATTICE:0,15,LEAVES:4,70,CONCRETE:8,80,AIR:0,100)
RandomBlock(1,0,-2,CONCRETE:8,65,QUARK:IRON_PLATE:0,10,QUARK:IRON_PLATE:1,10,STAINED_CLAY:9,15,STAINED_CLAY:7,10,CONCRETE:8,10,RUSTIC:IRON_LATTICE:1,15,RUSTIC:IRON_LATTICE:0,15,LEAVES:4,70,CONCRETE:8,80,AIR:0,100)
RandomBlock(1,0,-1,CONCRETE:8,65,QUARK:IRON_PLATE:0,10,QUARK:IRON_PLATE:1,10,STAINED_CLAY:9,15,STAINED_CLAY:7,10,CONCRETE:8,10,RUSTIC:IRON_LATTICE:1,15,RUSTIC:IRON_LATTICE:0,15,LEAVES:4,70,CONCRETE:8,80,AIR:0,100)
RandomBlock(1,0,0,CONCRETE:8,65,QUARK:IRON_PLATE:0,10,QUARK:IRON_PLATE:1,10,STAINED_CLAY:9,15,STAINED_CLAY:7,10,CONCRETE:8,10,RUSTIC:IRON_LATTICE:1,15,RUSTIC:IRON_LATTICE:0,15,LEAVES:4,70,CONCRETE:8,80,AIR:0,100)
RandomBlock(1,0,1,CONCRETE:8,65,QUARK:IRON_PLATE:0,10,QUARK:IRON_PLATE:1,10,STAINED_CLAY:9,15,STAINED_CLAY:7,10,CONCRETE:8,10,RUSTIC:IRON_LATTICE:1,15,RUSTIC:IRON_LATTICE:0,15,LEAVES:4,70,CONCRETE:8,80,AIR:0,100)
RandomBlock(1,0,2,CONCRETE:8,65,QUARK:IRON_PLATE:0,10,QUARK:IRON_PLATE:1,10,STAINED_CLAY:9,15,STAINED_CLAY:7,10,CONCRETE:8,10,RUSTIC:IRON_LATTICE:1,15,RUSTIC:IRON_LATTICE:0,15,LEAVES:4,70,CONCRETE:8,80,AIR:0,100)
RandomBlock(1,0,3,CONCRETE:8,65,QUARK:IRON_PLATE:0,10,QUARK:IRON_PLATE:1,10,STAINED_CLAY:9,15,STAINED_CLAY:7,10,CONCRETE:8,10,RUSTIC:IRON_LATTICE:1,15,RUSTIC:IRON_LATTICE:0,15,LEAVES:4,70,CONCRETE:8,80,AIR:0,100)
RandomBlock(1,0,4,CONCRETE:8,65,QUARK:IRON_PLATE:0,10,QUARK:IRON_PLATE:1,10,STAINED_CLAY:9,15,STAINED_CLAY:7,10,CONCRETE:8,10,RUSTIC:IRON_LATTICE:1,15,RUSTIC:IRON_LATTICE:0,15,LEAVES:4,70,CONCRETE:8,80,AIR:0,100)
RandomBlock(1,0,5,CONCRETE:8,65,QUARK:IRON_PLATE:0,10,QUARK:IRON_PLATE:1,10,STAINED_CLAY:9,15,STAINED_CLAY:7,10,CONCRETE:8,10,RUSTIC:IRON_LATTICE:1,15,RUSTIC:IRON_LATTICE:0,15,LEAVES:4,70,CONCRETE:8,80,AIR:0,100)
RandomBlock(1,0,6,CONCRETE:8,65,QUARK:IRON_PLATE:0,10,QUARK:IRON_PLATE:1,10,STAINED_CLAY:9,15,STAINED_CLAY:7,10,CONCRETE:8,10,RUSTIC:IRON_LATTICE:1,15,RUSTIC:IRON_LATTICE:0,15,LEAVES:4,70,CONCRETE:8,80,AIR:0,100)
RandomBlock(1,0,7,CONCRETE:8,65,QUARK:IRON_PLATE:0,10,QUARK:IRON_PLATE:1,10,STAINED_CLAY:9,15,STAINED_CLAY:7,10,CONCRETE:8,10,RUSTIC:IRON_LATTICE:1,15,RUSTIC:IRON_LATTICE:0,15,LEAVES:4,70,CONCRETE:8,80,AIR:0,100)
RandomBlock(1,0,8,CONCRETE:8,65,QUARK:IRON_PLATE:0,10,QUARK:IRON_PLATE:1,10,STAINED_CLAY:9,15,STAINED_CLAY:7,10,CONCRETE:8,10,RUSTIC:IRON_LATTICE:1,15,RUSTIC:IRON_LATTICE:0,15,LEAVES:4,70,CONCRETE:8,80,AIR:0,100)
RandomBlock(1,0,9,CONCRETE:8,65,QUARK:IRON_PLATE:0,10,QUARK:IRON_PLATE:1,10,STAINED_CLAY:9,15,STAINED_CLAY:7,10,CONCRETE:8,10,RUSTIC:IRON_LATTICE:1,15,RUSTIC:IRON_LATTICE:0,15,LEAVES:4,70,CONCRETE:8,80,AIR:0,100)
Block(1,1,-6,IRON_TRAPDOOR:6)
Block(1,1,-5,AIR:0)
Block(1,1,-4,AIR:0)
Block(1,1,-3,AIR:0)
Block(1,1,-2,AIR:0)
Block(1,1,-1,AIR:0)
Block(1,1,0,AIR:0)
Block(1,1,1,AIR:0)
Block(1,1,2,AIR:0)
RandomBlock(1,1,3,CONCRETE:8,65,QUARK:IRON_PLATE:0,10,QUARK:IRON_PLATE:1,10,STAINED_CLAY:9,15,STAINED_CLAY:7,10,CONCRETE:8,10,RUSTIC:IRON_LATTICE:1,15,RUSTIC:IRON_LATTICE:0,15,LEAVES:4,70,CONCRETE:8,80,AIR:0,100)
Block(1,1,4,SOIL:7)
Block(1,1,5,SOIL:7)
Block(1,1,6,STATIONARY_WATER:0)
Block(1,1,7,SOIL:7)
Block(1,1,8,SEA_LANTERN:0)
RandomBlock(1,1,9,CONCRETE:7,65,QUARK:IRON_PLATE:0,10,QUARK:IRON_PLATE:1,10,STAINED_CLAY:15,10,STAINED_CLAY:9,70,RUSTIC:IRON_LATTICE:1,5,RUSTIC:IRON_LATTICE:0,5,LEAVES:4,40,STAINED_CLAY:9,100)
Block(1,2,-6,IRON_TRAPDOOR:6)
Block(1,2,-5,AIR:0)
Block(1,2,-4,AIR:0)
Block(1,2,-3,AIR:0)
Block(1,2,-2,AIR:0)
Block(1,2,-1,AIR:0)
Block(1,2,0,AIR:0)
Block(1,2,1,AIR:0)
Block(1,2,3,STAINED_GLASS_PANE:15)
Block(1,2,4,CROPS:0)
Block(1,2,5,AIR:0)
Block(1,2,6,AIR:0)
Block(1,2,7,AIR:0)
Block(1,2,8,STAINED_GLASS:15)
RandomBlock(1,2,9,CONCRETE:7,65,QUARK:IRON_PLATE:0,10,QUARK:IRON_PLATE:1,10,STAINED_CLAY:15,10,STAINED_CLAY:9,70,RUSTIC:IRON_LATTICE:1,5,RUSTIC:IRON_LATTICE:0,5,LEAVES:4,40,STAINED_CLAY:9,100)
Block(1,3,-6,DROPPER:0)
Block(1,3,-5,AIR:0)
Block(1,3,-4,AIR:0)
Block(1,3,-3,AIR:0)
Block(1,3,-2,AIR:0)
Block(1,3,-1,AIR:0)
Block(1,3,0,AIR:0)
Block(1,3,1,AIR:0)
Block(1,3,2,AIR:0)
Block(1,3,3,AIR:0)
Block(1,3,4,AIR:0)
Block(1,3,5,AIR:0)
Block(1,3,6,AIR:0)
Block(1,3,7,AIR:0)
Block(1,3,8,STAINED_GLASS:15)
RandomBlock(1,3,9,CONCRETE:7,65,QUARK:IRON_PLATE:0,10,QUARK:IRON_PLATE:1,10,STAINED_CLAY:15,10,STAINED_CLAY:9,70,RUSTIC:IRON_LATTICE:1,5,RUSTIC:IRON_LATTICE:0,5,LEAVES:4,40,STAINED_CLAY:9,100)
RandomBlock(1,4,-6,CONCRETE:7,65,QUARK:IRON_PLATE:0,10,QUARK:IRON_PLATE:1,10,STAINED_CLAY:15,10,STAINED_CLAY:9,70,RUSTIC:IRON_LATTICE:1,5,RUSTIC:IRON_LATTICE:0,5,LEAVES:4,40,STAINED_CLAY:9,100)
RandomBlock(1,4,-5,CONCRETE:8,65,QUARK:IRON_PLATE:0,10,QUARK:IRON_PLATE:1,10,STAINED_CLAY:9,15,STAINED_CLAY:7,10,CONCRETE:8,10,RUSTIC:IRON_LATTICE:1,15,RUSTIC:IRON_LATTICE:0,15,LEAVES:4,70,CONCRETE:8,80,AIR:0,100)
RandomBlock(1,4,-4,CONCRETE:8,65,QUARK:IRON_PLATE:0,10,QUARK:IRON_PLATE:1,10,STAINED_CLAY:9,15,STAINED_CLAY:7,10,CONCRETE:8,10,RUSTIC:IRON_LATTICE:1,15,RUSTIC:IRON_LATTICE:0,15,LEAVES:4,70,CONCRETE:8,80,AIR:0,100)
RandomBlock(1,4,-3,CONCRETE:8,65,QUARK:IRON_PLATE:0,10,QUARK:IRON_PLATE:1,10,STAINED_CLAY:9,15,STAINED_CLAY:7,10,CONCRETE:8,10,RUSTIC:IRON_LATTICE:1,15,RUSTIC:IRON_LATTICE:0,15,LEAVES:4,70,CONCRETE:8,80,AIR:0,100)
RandomBlock(1,4,-2,CONCRETE:8,65,QUARK:IRON_PLATE:0,10,QUARK:IRON_PLATE:1,10,STAINED_CLAY:9,15,STAINED_CLAY:7,10,CONCRETE:8,10,RUSTIC:IRON_LATTICE:1,15,RUSTIC:IRON_LATTICE:0,15,LEAVES:4,70,CONCRETE:8,80,AIR:0,100)
RandomBlock(1,4,-1,CONCRETE:8,65,QUARK:IRON_PLATE:0,10,QUARK:IRON_PLATE:1,10,STAINED_CLAY:9,15,STAINED_CLAY:7,10,CONCRETE:8,10,RUSTIC:IRON_LATTICE:1,15,RUSTIC:IRON_LATTICE:0,15,LEAVES:4,70,CONCRETE:8,80,AIR:0,100)
RandomBlock(1,4,0,CONCRETE:8,65,QUARK:IRON_PLATE:0,10,QUARK:IRON_PLATE:1,10,STAINED_CLAY:9,15,STAINED_CLAY:7,10,CONCRETE:8,10,RUSTIC:IRON_LATTICE:1,15,RUSTIC:IRON_LATTICE:0,15,LEAVES:4,70,CONCRETE:8,80,AIR:0,100)
RandomBlock(1,4,1,CONCRETE:8,65,QUARK:IRON_PLATE:0,10,QUARK:IRON_PLATE:1,10,STAINED_CLAY:9,15,STAINED_CLAY:7,10,CONCRETE:8,10,RUSTIC:IRON_LATTICE:1,15,RUSTIC:IRON_LATTICE:0,15,LEAVES:4,70,CONCRETE:8,80,AIR:0,100)
RandomBlock(1,4,2,CONCRETE:8,65,QUARK:IRON_PLATE:0,10,QUARK:IRON_PLATE:1,10,STAINED_CLAY:9,15,STAINED_CLAY:7,10,CONCRETE:8,10,RUSTIC:IRON_LATTICE:1,15,RUSTIC:IRON_LATTICE:0,15,LEAVES:4,70,CONCRETE:8,80,AIR:0,100)
RandomBlock(1,4,3,CONCRETE:8,65,QUARK:IRON_PLATE:0,10,QUARK:IRON_PLATE:1,10,STAINED_CLAY:9,15,STAINED_CLAY:7,10,CONCRETE:8,10,RUSTIC:IRON_LATTICE:1,15,RUSTIC:IRON_LATTICE:0,15,LEAVES:4,70,CONCRETE:8,80,AIR:0,100)
RandomBlock(1,4,4,CONCRETE:8,65,QUARK:IRON_PLATE:0,10,QUARK:IRON_PLATE:1,10,STAINED_CLAY:9,15,STAINED_CLAY:7,10,CONCRETE:8,10,RUSTIC:IRON_LATTICE:1,15,RUSTIC:IRON_LATTICE:0,15,LEAVES:4,70,CONCRETE:8,80,AIR:0,100)
RandomBlock(1,4,5,CONCRETE:8,65,QUARK:IRON_PLATE:0,10,QUARK:IRON_PLATE:1,10,STAINED_CLAY:9,15,STAINED_CLAY:7,10,CONCRETE:8,10,RUSTIC:IRON_LATTICE:1,15,RUSTIC:IRON_LATTICE:0,15,LEAVES:4,70,CONCRETE:8,80,AIR:0,100)
RandomBlock(1,4,6,CONCRETE:8,65,QUARK:IRON_PLATE:0,10,QUARK:IRON_PLATE:1,10,STAINED_CLAY:9,15,STAINED_CLAY:7,10,CONCRETE:8,10,RUSTIC:IRON_LATTICE:1,15,RUSTIC:IRON_LATTICE:0,15,LEAVES:4,70,CONCRETE:8,80,AIR:0,100)
RandomBlock(1,4,7,CONCRETE:8,65,QUARK:IRON_PLATE:0,10,QUARK:IRON_PLATE:1,10,STAINED_CLAY:9,15,STAINED_CLAY:7,10,CONCRETE:8,10,RUSTIC:IRON_LATTICE:1,15,RUSTIC:IRON_LATTICE:0,15,LEAVES:4,70,CONCRETE:8,80,AIR:0,100)
RandomBlock(1,4,8,CONCRETE:8,65,QUARK:IRON_PLATE:0,10,QUARK:IRON_PLATE:1,10,STAINED_CLAY:9,15,STAINED_CLAY:7,10,CONCRETE:8,10,RUSTIC:IRON_LATTICE:1,15,RUSTIC:IRON_LATTICE:0,15,LEAVES:4,70,CONCRETE:8,80,AIR:0,100)
RandomBlock(1,4,9,CONCRETE:7,65,QUARK:IRON_PLATE:0,10,QUARK:IRON_PLATE:1,10,STAINED_CLAY:15,10,STAINED_CLAY:9,70,RUSTIC:IRON_LATTICE:1,5,RUSTIC:IRON_LATTICE:0,5,LEAVES:4,40,STAINED_CLAY:9,100)
RandomBlock(2,0,-6,CONCRETE:8,65,QUARK:IRON_PLATE:0,10,QUARK:IRON_PLATE:1,10,STAINED_CLAY:9,15,STAINED_CLAY:7,10,CONCRETE:8,10,RUSTIC:IRON_LATTICE:1,15,RUSTIC:IRON_LATTICE:0,15,LEAVES:4,70,CONCRETE:8,80,AIR:0,100)
RandomBlock(2,0,-5,CONCRETE:8,65,QUARK:IRON_PLATE:0,10,QUARK:IRON_PLATE:1,10,STAINED_CLAY:9,15,STAINED_CLAY:7,10,CONCRETE:8,10,RUSTIC:IRON_LATTICE:1,15,RUSTIC:IRON_LATTICE:0,15,LEAVES:4,70,CONCRETE:8,80,AIR:0,100)
RandomBlock(2,0,-4,CONCRETE:8,65,QUARK:IRON_PLATE:0,10,QUARK:IRON_PLATE:1,10,STAINED_CLAY:9,15,STAINED_CLAY:7,10,CONCRETE:8,10,RUSTIC:IRON_LATTICE:1,15,RUSTIC:IRON_LATTICE:0,15,LEAVES:4,70,CONCRETE:8,80,AIR:0,100)
RandomBlock(2,0,-3,CONCRETE:8,65,QUARK:IRON_PLATE:0,10,QUARK:IRON_PLATE:1,10,STAINED_CLAY:9,15,STAINED_CLAY:7,10,CONCRETE:8,10,RUSTIC:IRON_LATTICE:1,15,RUSTIC:IRON_LATTICE:0,15,LEAVES:4,70,CONCRETE:8,80,AIR:0,100)
RandomBlock(2,0,-2,CONCRETE:8,65,QUARK:IRON_PLATE:0,10,QUARK:IRON_PLATE:1,10,STAINED_CLAY:9,15,STAINED_CLAY:7,10,CONCRETE:8,10,RUSTIC:IRON_LATTICE:1,15,RUSTIC:IRON_LATTICE:0,15,LEAVES:4,70,CONCRETE:8,80,AIR:0,100)
RandomBlock(2,0,-1,CONCRETE:8,65,QUARK:IRON_PLATE:0,10,QUARK:IRON_PLATE:1,10,STAINED_CLAY:9,15,STAINED_CLAY:7,10,CONCRETE:8,10,RUSTIC:IRON_LATTICE:1,15,RUSTIC:IRON_LATTICE:0,15,LEAVES:4,70,CONCRETE:8,80,AIR:0,100)
RandomBlock(2,0,0,CONCRETE:8,65,QUARK:IRON_PLATE:0,10,QUARK:IRON_PLATE:1,10,STAINED_CLAY:9,15,STAINED_CLAY:7,10,CONCRETE:8,10,RUSTIC:IRON_LATTICE:1,15,RUSTIC:IRON_LATTICE:0,15,LEAVES:4,70,CONCRETE:8,80,AIR:0,100)
RandomBlock(2,0,1,CONCRETE:8,65,QUARK:IRON_PLATE:0,10,QUARK:IRON_PLATE:1,10,STAINED_CLAY:9,15,STAINED_CLAY:7,10,CONCRETE:8,10,RUSTIC:IRON_LATTICE:1,15,RUSTIC:IRON_LATTICE:0,15,LEAVES:4,70,CONCRETE:8,80,AIR:0,100)
RandomBlock(2,0,2,CONCRETE:8,65,QUARK:IRON_PLATE:0,10,QUARK:IRON_PLATE:1,10,STAINED_CLAY:9,15,STAINED_CLAY:7,10,CONCRETE:8,10,RUSTIC:IRON_LATTICE:1,15,RUSTIC:IRON_LATTICE:0,15,LEAVES:4,70,CONCRETE:8,80,AIR:0,100)
RandomBlock(2,0,3,CONCRETE:8,65,QUARK:IRON_PLATE:0,10,QUARK:IRON_PLATE:1,10,STAINED_CLAY:9,15,STAINED_CLAY:7,10,CONCRETE:8,10,RUSTIC:IRON_LATTICE:1,15,RUSTIC:IRON_LATTICE:0,15,LEAVES:4,70,CONCRETE:8,80,AIR:0,100)
RandomBlock(2,0,4,CONCRETE:8,65,QUARK:IRON_PLATE:0,10,QUARK:IRON_PLATE:1,10,STAINED_CLAY:9,15,STAINED_CLAY:7,10,CONCRETE:8,10,RUSTIC:IRON_LATTICE:1,15,RUSTIC:IRON_LATTICE:0,15,LEAVES:4,70,CONCRETE:8,80,AIR:0,100)
RandomBlock(2,0,5,CONCRETE:8,65,QUARK:IRON_PLATE:0,10,QUARK:IRON_PLATE:1,10,STAINED_CLAY:9,15,STAINED_CLAY:7,10,CONCRETE:8,10,RUSTIC:IRON_LATTICE:1,15,RUSTIC:IRON_LATTICE:0,15,LEAVES:4,70,CONCRETE:8,80,AIR:0,100)
RandomBlock(2,0,6,CONCRETE:8,65,QUARK:IRON_PLATE:0,10,QUARK:IRON_PLATE:1,10,STAINED_CLAY:9,15,STAINED_CLAY:7,10,CONCRETE:8,10,RUSTIC:IRON_LATTICE:1,15,RUSTIC:IRON_LATTICE:0,15,LEAVES:4,70,CONCRETE:8,80,AIR:0,100)
RandomBlock(2,0,7,CONCRETE:8,65,QUARK:IRON_PLATE:0,10,QUARK:IRON_PLATE:1,10,STAINED_CLAY:9,15,STAINED_CLAY:7,10,CONCRETE:8,10,RUSTIC:IRON_LATTICE:1,15,RUSTIC:IRON_LATTICE:0,15,LEAVES:4,70,CONCRETE:8,80,AIR:0,100)
RandomBlock(2,0,8,CONCRETE:8,65,QUARK:IRON_PLATE:0,10,QUARK:IRON_PLATE:1,10,STAINED_CLAY:9,15,STAINED_CLAY:7,10,CONCRETE:8,10,RUSTIC:IRON_LATTICE:1,15,RUSTIC:IRON_LATTICE:0,15,LEAVES:4,70,CONCRETE:8,80,AIR:0,100)
RandomBlock(2,0,9,CONCRETE:8,65,QUARK:IRON_PLATE:0,10,QUARK:IRON_PLATE:1,10,STAINED_CLAY:9,15,STAINED_CLAY:7,10,CONCRETE:8,10,RUSTIC:IRON_LATTICE:1,15,RUSTIC:IRON_LATTICE:0,15,LEAVES:4,70,CONCRETE:8,80,AIR:0,100)
RandomBlock(2,1,-6,CONCRETE:8,65,QUARK:IRON_PLATE:0,10,QUARK:IRON_PLATE:1,10,STAINED_CLAY:9,15,STAINED_CLAY:7,10,CONCRETE:8,10,RUSTIC:IRON_LATTICE:1,15,RUSTIC:IRON_LATTICE:0,15,LEAVES:4,70,CONCRETE:8,80,AIR:0,100)
RandomBlock(2,1,-5,CONCRETE:8,65,QUARK:IRON_PLATE:0,10,QUARK:IRON_PLATE:1,10,STAINED_CLAY:9,15,STAINED_CLAY:7,10,CONCRETE:8,10,RUSTIC:IRON_LATTICE:1,15,RUSTIC:IRON_LATTICE:0,15,LEAVES:4,70,CONCRETE:8,80,AIR:0,100)
RandomBlock(2,1,-4,CONCRETE:8,65,QUARK:IRON_PLATE:0,10,QUARK:IRON_PLATE:1,10,STAINED_CLAY:9,15,STAINED_CLAY:7,10,CONCRETE:8,10,RUSTIC:IRON_LATTICE:1,15,RUSTIC:IRON_LATTICE:0,15,LEAVES:4,70,CONCRETE:8,80,AIR:0,100)
RandomBlock(2,1,-3,CONCRETE:8,65,QUARK:IRON_PLATE:0,10,QUARK:IRON_PLATE:1,10,STAINED_CLAY:9,15,STAINED_CLAY:7,10,CONCRETE:8,10,RUSTIC:IRON_LATTICE:1,15,RUSTIC:IRON_LATTICE:0,15,LEAVES:4,70,CONCRETE:8,80,AIR:0,100)
RandomBlock(2,1,-2,CONCRETE:8,65,QUARK:IRON_PLATE:0,10,QUARK:IRON_PLATE:1,10,STAINED_CLAY:9,15,STAINED_CLAY:7,10,CONCRETE:8,10,RUSTIC:IRON_LATTICE:1,15,RUSTIC:IRON_LATTICE:0,15,LEAVES:4,70,CONCRETE:8,80,AIR:0,100)
RandomBlock(2,1,-1,CONCRETE:8,65,QUARK:IRON_PLATE:0,10,QUARK:IRON_PLATE:1,10,STAINED_CLAY:9,15,STAINED_CLAY:7,10,CONCRETE:8,10,RUSTIC:IRON_LATTICE:1,15,RUSTIC:IRON_LATTICE:0,15,LEAVES:4,70,CONCRETE:8,80,AIR:0,100)
RandomBlock(2,1,0,CONCRETE:8,65,QUARK:IRON_PLATE:0,10,QUARK:IRON_PLATE:1,10,STAINED_CLAY:9,15,STAINED_CLAY:7,10,CONCRETE:8,10,RUSTIC:IRON_LATTICE:1,15,RUSTIC:IRON_LATTICE:0,15,LEAVES:4,70,CONCRETE:8,80,AIR:0,100)
RandomBlock(2,1,1,CONCRETE:8,65,QUARK:IRON_PLATE:0,10,QUARK:IRON_PLATE:1,10,STAINED_CLAY:9,15,STAINED_CLAY:7,10,CONCRETE:8,10,RUSTIC:IRON_LATTICE:1,15,RUSTIC:IRON_LATTICE:0,15,LEAVES:4,70,CONCRETE:8,80,AIR:0,100)
RandomBlock(2,1,2,CONCRETE:8,65,QUARK:IRON_PLATE:0,10,QUARK:IRON_PLATE:1,10,STAINED_CLAY:9,15,STAINED_CLAY:7,10,CONCRETE:8,10,RUSTIC:IRON_LATTICE:1,15,RUSTIC:IRON_LATTICE:0,15,LEAVES:4,70,CONCRETE:8,80,AIR:0,100)
RandomBlock(2,1,3,CONCRETE:8,65,QUARK:IRON_PLATE:0,10,QUARK:IRON_PLATE:1,10,STAINED_CLAY:9,15,STAINED_CLAY:7,10,CONCRETE:8,10,RUSTIC:IRON_LATTICE:1,15,RUSTIC:IRON_LATTICE:0,15,LEAVES:4,70,CONCRETE:8,80,AIR:0,100)
Block(2,1,4,SOIL:7)
Block(2,1,5,SOIL:7)
Block(2,1,6,STATIONARY_WATER:0)
Block(2,1,7,SOIL:7)
RandomBlock(2,1,8,CONCRETE:8,65,QUARK:IRON_PLATE:0,10,QUARK:IRON_PLATE:1,10,STAINED_CLAY:9,15,STAINED_CLAY:7,10,CONCRETE:8,10,RUSTIC:IRON_LATTICE:1,15,RUSTIC:IRON_LATTICE:0,15,LEAVES:4,70,CONCRETE:8,80,AIR:0,100)
RandomBlock(2,1,9,CONCRETE:8,65,QUARK:IRON_PLATE:0,10,QUARK:IRON_PLATE:1,10,STAINED_CLAY:9,15,STAINED_CLAY:7,10,CONCRETE:8,10,RUSTIC:IRON_LATTICE:1,15,RUSTIC:IRON_LATTICE:0,15,LEAVES:4,70,CONCRETE:8,80,AIR:0,100)
RandomBlock(2,2,-6,CONCRETE:8,65,QUARK:IRON_PLATE:0,10,QUARK:IRON_PLATE:1,10,STAINED_CLAY:9,15,STAINED_CLAY:7,10,CONCRETE:8,10,RUSTIC:IRON_LATTICE:1,15,RUSTIC:IRON_LATTICE:0,15,LEAVES:4,70,CONCRETE:8,80,AIR:0,100)
RandomBlock(2,2,-5,CONCRETE:8,65,QUARK:IRON_PLATE:0,10,QUARK:IRON_PLATE:1,10,STAINED_CLAY:9,15,STAINED_CLAY:7,10,CONCRETE:8,10,RUSTIC:IRON_LATTICE:1,15,RUSTIC:IRON_LATTICE:0,15,LEAVES:4,70,CONCRETE:8,80,AIR:0,100)
Block(2,2,-4,STAINED_GLASS_PANE:15)
Block(2,2,-3,STAINED_GLASS_PANE:15)
Block(2,2,-2,STAINED_GLASS_PANE:15)
Block(2,2,-1,STAINED_GLASS_PANE:15)
Block(2,2,0,STAINED_GLASS_PANE:15)
Block(2,2,1,STAINED_GLASS_PANE:15)
Block(2,2,2,STAINED_GLASS_PANE:15)
Block(2,2,3,STAINED_GLASS_PANE:15)
Block(2,2,4,AIR:0)
Block(2,2,5,CROPS:1)
Block(2,2,6,AIR:0)
Block(2,2,7,CROPS:0)
RandomBlock(2,2,8,CONCRETE:8,65,QUARK:IRON_PLATE:0,10,QUARK:IRON_PLATE:1,10,STAINED_CLAY:9,15,STAINED_CLAY:7,10,CONCRETE:8,10,RUSTIC:IRON_LATTICE:1,15,RUSTIC:IRON_LATTICE:0,15,LEAVES:4,70,CONCRETE:8,80,AIR:0,100)
RandomBlock(2,2,9,CONCRETE:8,65,QUARK:IRON_PLATE:0,10,QUARK:IRON_PLATE:1,10,STAINED_CLAY:9,15,STAINED_CLAY:7,10,CONCRETE:8,10,RUSTIC:IRON_LATTICE:1,15,RUSTIC:IRON_LATTICE:0,15,LEAVES:4,70,CONCRETE:8,80,AIR:0,100)
