Author: NLBlackEagle
Description: No description given
SettingsMode: WriteDisable
Frequency: 0
SpawnHeight: highestBlock
UseCenterForHighestBlock: true
MinHeight: 0
MaxHeight: 255
InheritBO3: 
InheritBO3Rotation: NORTH
OverrideChildSettings: true
OverrideParentHeight: false
CanOverride: true
BranchFrequency: 0
BranchFrequencyGroup: 
MustBeBelowOther: false
MustBeInside: 
CannotBeInside: 
ReplacesBO3: 
MustBeInsideWorldBorders: false
CanSpawnOnWater: false
SpawnOnWaterOnly: false
SpawnUnderWater: false
SpawnAtWaterLevel: false
HeightOffset: 0
RemoveAir: true
ReplaceAbove: 
ReplaceBelow: dirt
ReplaceWithBiomeBlocks: true
ReplaceWithSurfaceBlock: GRASS
ReplaceWithGroundBlock: DIRT
ReplaceWithStoneBlock: STONE
SmoothRadius: 0
SmoothHeightOffset: 0
SmoothStartTop: false
SmoothStartWood: false
SmoothingSurfaceBlock: 
SmoothingGroundBlock: 
BO3Group: 
IsSpawnPoint: false
DoReplaceBlocks: true
Block(-8,0,-2,WOOD:4)
Block(-8,0,-1,DIRT:0)
Block(-8,0,0,DIRT:0)
Block(-8,0,1,DIRT:0)
Block(-8,0,2,DIRT:0)
Block(-8,0,3,DIRT:0)
Block(-8,0,4,DIRT:0)
Block(-8,0,5,DIRT:0)
Block(-8,0,6,DIRT:0)
Block(-8,0,7,DIRT:0)
Block(-8,0,8,DIRT:0)
Block(-8,1,-2,WOOD:4)
Block(-8,1,-1,DIRT:0)
Block(-8,1,0,DIRT:0)
Block(-8,1,1,DIRT:0)
Block(-8,1,2,DIRT:0)
Block(-8,1,3,DIRT:0)
Block(-8,1,4,DIRT:0)
Block(-8,1,5,DIRT:0)
Block(-8,1,6,DIRT:0)
Block(-8,1,7,DIRT:0)
Block(-8,1,8,DIRT:0)
Block(-8,2,-2,WOOD:4)
Block(-8,2,-1,DIRT:0)
Block(-8,2,0,DIRT:0)
Block(-8,2,1,DIRT:0)
Block(-8,2,2,DIRT:0)
Block(-8,2,3,DIRT:0)
Block(-8,2,4,DIRT:0)
Block(-8,2,5,DIRT:0)
Block(-8,2,6,DIRT:0)
Block(-8,2,7,DIRT:0)
Block(-8,2,8,DIRT:0)
Block(-8,3,-2,WOOD:4)
Block(-8,3,-1,DIRT:0)
Block(-8,3,0,DIRT:0)
Block(-8,3,1,DIRT:0)
Block(-8,3,2,DIRT:0)
Block(-8,3,3,DIRT:0)
Block(-8,3,4,DIRT:0)
Block(-8,3,5,DIRT:0)
Block(-8,3,6,DIRT:0)
Block(-8,3,7,DIRT:0)
Block(-8,3,8,DIRT:0)
Block(-8,4,-2,WOOD:4)
Block(-8,4,-1,DIRT:0)
Block(-8,4,0,DIRT:0)
Block(-8,4,1,DIRT:0)
Block(-8,4,2,DIRT:0)
Block(-8,4,3,DIRT:0)
Block(-8,4,4,DIRT:0)
Block(-8,4,5,DIRT:0)
Block(-8,4,6,DIRT:0)
Block(-8,4,7,DIRT:0)
Block(-8,4,8,DIRT:0)
Block(-8,5,-2,WOOD:4)
Block(-8,5,-1,DIRT:0)
Block(-8,5,0,DIRT:0)
Block(-8,5,1,DIRT:0)
Block(-8,5,2,DIRT:0)
Block(-8,5,3,DIRT:0)
Block(-8,5,4,DIRT:0)
Block(-8,5,5,DIRT:0)
Block(-8,5,6,DIRT:0)
Block(-8,5,7,DIRT:0)
Block(-8,5,8,DIRT:0)
Block(-8,6,-2,WOOD:4)
Block(-8,6,-1,DIRT:0)
Block(-8,6,0,DIRT:0)
Block(-8,6,1,DIRT:0)
Block(-8,6,2,DIRT:0)
Block(-8,6,3,DIRT:0)
Block(-8,6,4,DIRT:0)
Block(-8,6,5,DIRT:0)
Block(-8,6,6,DIRT:0)
Block(-8,6,7,DIRT:0)
Block(-8,6,8,DIRT:0)
Block(-8,7,-2,WOOD:4)
Block(-8,7,-1,DIRT:0)
Block(-8,7,0,DIRT:0)
Block(-8,7,1,DIRT:0)
Block(-8,7,2,DIRT:0)
Block(-8,7,3,DIRT:0)
Block(-8,7,4,DIRT:0)
Block(-8,7,5,DIRT:0)
Block(-8,7,6,DIRT:0)
Block(-8,7,7,DIRT:0)
Block(-8,7,8,DIRT:0)
Block(-8,8,-2,WOOD:4)
Block(-8,8,-1,DIRT:0)
Block(-8,8,0,DIRT:0)
Block(-8,8,1,DIRT:0)
Block(-8,8,2,DIRT:0)
Block(-8,8,3,DIRT:0)
Block(-8,8,4,DIRT:0)
Block(-8,8,5,DIRT:0)
Block(-8,8,6,DIRT:0)
Block(-8,8,7,DIRT:0)
Block(-8,8,8,DIRT:0)
Block(-8,9,-2,WOOD:4)
Block(-8,9,-1,DIRT:0)
Block(-8,9,0,DIRT:0)
Block(-8,9,1,DIRT:0)
Block(-8,9,2,DIRT:0)
Block(-8,9,3,DIRT:0)
Block(-8,9,4,DIRT:0)
Block(-8,9,5,DIRT:0)
Block(-8,9,6,DIRT:0)
Block(-8,9,7,DIRT:0)
Block(-8,9,8,DIRT:0)
Block(-8,10,-4,SPRUCE_FENCE:0)
Block(-8,10,-3,SPRUCE_FENCE:0)
Block(-8,10,-2,WOOD:4)
Block(-8,10,-1,DIRT:0)
Block(-8,10,0,DIRT:0)
Block(-8,10,1,DIRT:0)
Block(-8,10,2,DIRT:0)
Block(-8,10,3,DIRT:0)
Block(-8,10,4,DIRT:0)
Block(-8,10,5,DIRT:0)
Block(-8,10,6,DIRT:0)
Block(-8,10,7,DIRT:0)
Block(-8,10,8,DIRT:0)
Block(-8,11,-3,SPRUCE_FENCE:0)
Block(-8,11,-2,WOOD:4)
Block(-8,11,-1,DIRT:0)
Block(-8,11,0,DIRT:0)
Block(-8,11,1,DIRT:0)
Block(-8,11,2,DIRT:0)
Block(-8,11,3,DIRT:0)
Block(-8,11,4,DIRT:0)
Block(-8,11,5,DIRT:0)
Block(-8,11,6,DIRT:0)
Block(-8,11,7,DIRT:0)
Block(-8,11,8,DIRT:0)
Block(-8,12,-3,SPRUCE_FENCE:0)
Block(-8,12,-2,WOOD:4)
Block(-8,12,-1,DIRT:0)
Block(-8,12,0,DIRT:0)
Block(-8,12,1,DIRT:0)
Block(-8,12,2,DIRT:0)
Block(-8,12,3,DIRT:0)
Block(-8,12,4,DIRT:0)
Block(-8,12,5,DIRT:0)
Block(-8,12,6,DIRT:0)
Block(-8,12,7,DIRT:0)
Block(-8,12,8,DIRT:0)
Block(-8,13,-3,SPRUCE_FENCE:0)
Block(-8,13,-2,WOOD:4)
Block(-8,13,-1,DIRT:0)
Block(-8,13,0,DIRT:0)
Block(-8,13,1,DIRT:0)
Block(-8,13,2,DIRT:0)
Block(-8,13,3,DIRT:0)
Block(-8,13,4,DIRT:0)
Block(-8,13,5,DIRT:0)
Block(-8,13,6,DIRT:0)
Block(-8,13,7,DIRT:0)
Block(-8,13,8,DIRT:0)
Block(-8,14,-2,WOOD:4)
Block(-8,14,-1,GRASS:0)
Block(-8,14,0,GRASS:0)
Block(-8,14,1,GRASS:0)
Block(-8,14,2,GRASS:0)
Block(-8,14,3,GRASS:0)
Block(-8,14,4,GRASS:0)
Block(-8,14,5,GRASS:0)
Block(-8,14,6,GRASS:0)
Block(-8,14,7,GRASS:0)
Block(-8,14,8,GRASS:0)
Block(-8,15,-2,WOOD:4)
Block(-8,16,-2,WOOD_STEP:4)
Block(-7,0,-2,WOOD:4)
Block(-7,0,-1,WOOD:4)
Block(-7,0,0,LOG_2:0)
Block(-7,0,1,WOOD:4)
Block(-7,0,2,DIRT:0)
Block(-7,0,3,DIRT:0)
Block(-7,0,4,DIRT:0)
Block(-7,0,5,DIRT:0)
Block(-7,0,6,DIRT:0)
Block(-7,0,7,DIRT:0)
Block(-7,0,8,DIRT:0)
Block(-7,1,-2,WOOD:4)
Block(-7,1,-1,WOOD:4)
Block(-7,1,0,LOG_2:0)
Block(-7,1,1,WOOD:4)
Block(-7,1,2,DIRT:0)
Block(-7,1,3,DIRT:0)
Block(-7,1,4,DIRT:0)
Block(-7,1,5,DIRT:0)
Block(-7,1,6,DIRT:0)
Block(-7,1,7,DIRT:0)
Block(-7,1,8,DIRT:0)
Block(-7,2,-2,WOOD:4)
Block(-7,2,-1,WOOD:4)
Block(-7,2,0,LOG_2:0)
Block(-7,2,1,WOOD:4)
Block(-7,2,2,DIRT:0)
Block(-7,2,3,DIRT:0)
Block(-7,2,4,DIRT:0)
Block(-7,2,5,DIRT:0)
Block(-7,2,6,DIRT:0)
Block(-7,2,7,DIRT:0)
Block(-7,2,8,DIRT:0)
Block(-7,3,-2,WOOD:4)
Block(-7,3,-1,WOOD:4)
Block(-7,3,0,LOG_2:0)
Block(-7,3,1,WOOD:4)
Block(-7,3,2,DIRT:0)
Block(-7,3,3,DIRT:0)
Block(-7,3,4,DIRT:0)
Block(-7,3,5,DIRT:0)
Block(-7,3,6,DIRT:0)
Block(-7,3,7,DIRT:0)
Block(-7,3,8,DIRT:0)
Block(-7,4,-2,WOOD:4)
Block(-7,4,-1,WOOD:4)
Block(-7,4,0,LOG_2:0)
Block(-7,4,1,WOOD:4)
Block(-7,4,2,DIRT:0)
Block(-7,4,3,DIRT:0)
Block(-7,4,4,DIRT:0)
Block(-7,4,5,DIRT:0)
Block(-7,4,6,DIRT:0)
Block(-7,4,7,DIRT:0)
Block(-7,4,8,DIRT:0)
Block(-7,5,-2,WOOD:4)
Block(-7,5,-1,WOOD:4)
Block(-7,5,0,LOG_2:0)
Block(-7,5,1,WOOD:4)
Block(-7,5,2,DIRT:0)
Block(-7,5,3,DIRT:0)
Block(-7,5,4,DIRT:0)
Block(-7,5,5,DIRT:0)
Block(-7,5,6,DIRT:0)
Block(-7,5,7,DIRT:0)
Block(-7,5,8,DIRT:0)
Block(-7,6,-2,WOOD:4)
Block(-7,6,-1,WOOD:4)
Block(-7,6,0,LOG_2:0)
Block(-7,6,1,WOOD:4)
Block(-7,6,2,DIRT:0)
Block(-7,6,3,DIRT:0)
Block(-7,6,4,DIRT:0)
Block(-7,6,5,DIRT:0)
Block(-7,6,6,DIRT:0)
Block(-7,6,7,DIRT:0)
Block(-7,6,8,DIRT:0)
Block(-7,7,-2,WOOD:4)
Block(-7,7,-1,WOOD:4)
Block(-7,7,0,LOG_2:0)
Block(-7,7,1,WOOD:4)
Block(-7,7,2,DIRT:0)
Block(-7,7,3,DIRT:0)
Block(-7,7,4,DIRT:0)
Block(-7,7,5,DIRT:0)
Block(-7,7,6,DIRT:0)
Block(-7,7,7,DIRT:0)
Block(-7,7,8,DIRT:0)
Block(-7,8,-2,WOOD:4)
Block(-7,8,-1,WOOD:4)
Block(-7,8,0,LOG_2:0)
Block(-7,8,1,WOOD:4)
Block(-7,8,2,DIRT:0)
Block(-7,8,3,DIRT:0)
Block(-7,8,4,DIRT:0)
Block(-7,8,5,DIRT:0)
Block(-7,8,6,DIRT:0)
Block(-7,8,7,DIRT:0)
Block(-7,8,8,DIRT:0)
Block(-7,9,-2,WOOD:4)
Block(-7,9,-1,WOOD:4)
Block(-7,9,0,LOG_2:0)
Block(-7,9,1,WOOD:4)
Block(-7,9,2,DIRT:0)
Block(-7,9,3,DIRT:0)
Block(-7,9,4,DIRT:0)
Block(-7,9,5,DIRT:0)
Block(-7,9,6,DIRT:0)
Block(-7,9,7,DIRT:0)
Block(-7,9,8,DIRT:0)
Block(-7,10,-3,SPRUCE_FENCE:0)
Block(-7,10,-2,WOOD:4)
Block(-7,10,-1,WOOD:4)
Block(-7,10,0,LOG_2:0)
Block(-7,10,1,WOOD:4)
Block(-7,10,2,DIRT:0)
Block(-7,10,3,DIRT:0)
Block(-7,10,4,DIRT:0)
Block(-7,10,5,DIRT:0)
Block(-7,10,6,DIRT:0)
Block(-7,10,7,DIRT:0)
Block(-7,10,8,DIRT:0)
Block(-7,11,-2,WOOD:4)
Block(-7,11,-1,WOOD:4)
Block(-7,11,0,LOG_2:0)
Block(-7,11,1,WOOD:4)
Block(-7,11,2,DIRT:0)
Block(-7,11,3,DIRT:0)
Block(-7,11,4,DIRT:0)
Block(-7,11,5,DIRT:0)
Block(-7,11,6,DIRT:0)
Block(-7,11,7,DIRT:0)
Block(-7,11,8,DIRT:0)
Block(-7,12,-2,WOOD:4)
Block(-7,12,-1,WOOD:4)
Block(-7,12,0,LOG_2:0)
Block(-7,12,1,WOOD:4)
Block(-7,12,2,DIRT:0)
Block(-7,12,3,DIRT:0)
Block(-7,12,4,DIRT:0)
Block(-7,12,5,DIRT:0)
Block(-7,12,6,DIRT:0)
Block(-7,12,7,DIRT:0)
Block(-7,12,8,DIRT:0)
Block(-7,13,-2,WOOD:4)
Block(-7,13,-1,WOOD:4)
Block(-7,13,0,LOG_2:0)
Block(-7,13,1,WOOD:4)
Block(-7,13,2,DIRT:0)
Block(-7,13,3,DIRT:0)
Block(-7,13,4,DIRT:0)
Block(-7,13,5,DIRT:0)
Block(-7,13,6,DIRT:0)
Block(-7,13,7,DIRT:0)
Block(-7,13,8,DIRT:0)
Block(-7,14,-2,WOOD:4)
Block(-7,14,-1,WOOD:4)
Block(-7,14,0,LOG_2:0)
Block(-7,14,1,WOOD:4)
Block(-7,14,2,GRASS:0)
Block(-7,14,3,GRASS:0)
Block(-7,14,4,GRASS:0)
Block(-7,14,5,GRASS:0)
Block(-7,14,6,GRASS:0)
Block(-7,14,7,GRASS:0)
Block(-7,14,8,GRASS:0)
Block(-7,15,-2,WOOD:4)
Block(-7,15,-1,WOOD:4)
Block(-7,15,0,LOG_2:0)
Block(-7,15,1,WOOD:4)
Block(-7,16,-2,WOOD_STEP:4)
RandomBlock(-7,16,0,STANDING_BANNER:12,../../NBT/banners/JungleBanner01.nbt,8,STANDING_BANNER:12,../../NBT/banners/JungleBanner02.nbt,8,STANDING_BANNER:12,../../NBT/banners/JungleBanner03.nbt,8,STANDING_BANNER:12,../../NBT/banners/JungleBanner04.nbt,8,STANDING_BANNER:12,../../NBT/banners/JungleBanner05.nbt,8,STANDING_BANNER:12,../../NBT/banners/JungleBanner06.nbt,8,STANDING_BANNER:12,../../NBT/banners/JungleBanner07.nbt,8,STANDING_BANNER:12,../../NBT/banners/JungleBanner08.nbt,8,STANDING_BANNER:12,../../NBT/banners/JungleBanner09.nbt,8,STANDING_BANNER:12,../../NBT/banners/JungleBanner10.nbt,8,STANDING_BANNER:12,../../NBT/banners/JungleBanner11.nbt,8,STANDING_BANNER:12,../../NBT/banners/JungleBanner12.nbt,8,STANDING_BANNER:12,../../NBT/banners/JungleBanner13.nbt,8,STANDING_BANNER:12,../../NBT/banners/JungleBanner14.nbt,8,STANDING_BANNER:12,../../NBT/banners/JungleBanner15.nbt,8,STANDING_BANNER:12,../../NBT/banners/JungleBanner16.nbt,8,STANDING_BANNER:12,../../NBT/banners/JungleBanner17.nbt,8,STANDING_BANNER:12,../../NBT/banners/JungleBanner18.nbt,8,STANDING_BANNER:12,../../NBT/banners/JungleBanner19.nbt,8,STANDING_BANNER:12,../../NBT/banners/JungleBanner20.nbt,100)
Block(-7,16,1,WOOD_STEP:4)
Block(-6,0,2,WOOD:4)
Block(-6,0,3,DIRT:0)
Block(-6,0,4,DIRT:0)
Block(-6,0,5,DIRT:0)
Block(-6,0,6,DIRT:0)
Block(-6,0,7,DIRT:0)
Block(-6,0,8,DIRT:0)
Block(-6,1,2,WOOD:4)
Block(-6,1,3,DIRT:0)
Block(-6,1,4,DIRT:0)
Block(-6,1,5,DIRT:0)
Block(-6,1,6,DIRT:0)
Block(-6,1,7,DIRT:0)
Block(-6,1,8,DIRT:0)
Block(-6,2,2,WOOD:4)
Block(-6,2,3,DIRT:0)
Block(-6,2,4,DIRT:0)
Block(-6,2,5,DIRT:0)
Block(-6,2,6,DIRT:0)
Block(-6,2,7,DIRT:0)
Block(-6,2,8,DIRT:0)
Block(-6,3,2,WOOD:4)
Block(-6,3,3,DIRT:0)
Block(-6,3,4,DIRT:0)
Block(-6,3,5,DIRT:0)
Block(-6,3,6,DIRT:0)
Block(-6,3,7,DIRT:0)
Block(-6,3,8,DIRT:0)
Block(-6,4,2,WOOD:4)
Block(-6,4,3,DIRT:0)
Block(-6,4,4,DIRT:0)
Block(-6,4,5,DIRT:0)
Block(-6,4,6,DIRT:0)
Block(-6,4,7,DIRT:0)
Block(-6,4,8,DIRT:0)
Block(-6,5,2,WOOD:4)
Block(-6,5,3,DIRT:0)
Block(-6,5,4,DIRT:0)
Block(-6,5,5,DIRT:0)
Block(-6,5,6,DIRT:0)
Block(-6,5,7,DIRT:0)
Block(-6,5,8,DIRT:0)
Block(-6,6,2,WOOD:4)
Block(-6,6,3,DIRT:0)
Block(-6,6,4,DIRT:0)
Block(-6,6,5,DIRT:0)
Block(-6,6,6,DIRT:0)
Block(-6,6,7,DIRT:0)
Block(-6,6,8,DIRT:0)
Block(-6,7,2,WOOD:4)
Block(-6,7,3,DIRT:0)
Block(-6,7,4,DIRT:0)
Block(-6,7,5,DIRT:0)
Block(-6,7,6,DIRT:0)
Block(-6,7,7,DIRT:0)
Block(-6,7,8,DIRT:0)
Block(-6,8,2,WOOD:4)
Block(-6,8,3,DIRT:0)
Block(-6,8,4,DIRT:0)
Block(-6,8,5,DIRT:0)
Block(-6,8,6,DIRT:0)
Block(-6,8,7,DIRT:0)
Block(-6,8,8,DIRT:0)
Block(-6,9,2,WOOD:4)
Block(-6,9,3,DIRT:0)
Block(-6,9,4,DIRT:0)
Block(-6,9,5,DIRT:0)
Block(-6,9,6,DIRT:0)
Block(-6,9,7,DIRT:0)
Block(-6,9,8,DIRT:0)
Block(-6,10,1,SPRUCE_FENCE:0)
Block(-6,10,2,WOOD:4)
Block(-6,10,3,DIRT:0)
Block(-6,10,4,DIRT:0)
Block(-6,10,5,DIRT:0)
Block(-6,10,6,DIRT:0)
Block(-6,10,7,DIRT:0)
Block(-6,10,8,DIRT:0)
Block(-6,11,2,WOOD:4)
Block(-6,11,3,DIRT:0)
Block(-6,11,4,DIRT:0)
Block(-6,11,5,DIRT:0)
Block(-6,11,6,DIRT:0)
Block(-6,11,7,DIRT:0)
Block(-6,11,8,DIRT:0)
Block(-6,12,2,WOOD:4)
Block(-6,12,3,DIRT:0)
Block(-6,12,4,DIRT:0)
Block(-6,12,5,DIRT:0)
Block(-6,12,6,DIRT:0)
Block(-6,12,7,DIRT:0)
Block(-6,12,8,DIRT:0)
Block(-6,13,2,WOOD:4)
Block(-6,13,3,DIRT:0)
Block(-6,13,4,DIRT:0)
Block(-6,13,5,DIRT:0)
Block(-6,13,6,DIRT:0)
Block(-6,13,7,DIRT:0)
Block(-6,13,8,DIRT:0)
Block(-6,14,2,WOOD:4)
Block(-6,14,3,GRASS:0)
Block(-6,14,4,GRASS:0)
Block(-6,14,5,GRASS:0)
Block(-6,14,6,GRASS:0)
Block(-6,14,7,GRASS:0)
Block(-6,14,8,GRASS:0)
Block(-6,15,2,WOOD:4)
Block(-6,16,2,WOOD:4)
Block(-5,0,3,WOOD:4)
Block(-5,0,4,LOG_2:0)
Block(-5,0,5,WOOD:4)
Block(-5,0,6,DIRT:0)
Block(-5,0,7,DIRT:0)
Block(-5,0,8,WOOD:4)
Block(-5,1,3,WOOD:4)
Block(-5,1,4,LOG_2:0)
Block(-5,1,5,WOOD:4)
Block(-5,1,6,DIRT:0)
Block(-5,1,7,DIRT:0)
Block(-5,1,8,WOOD:4)
Block(-5,2,3,WOOD:4)
Block(-5,2,4,LOG_2:0)
Block(-5,2,5,WOOD:4)
Block(-5,2,6,DIRT:0)
Block(-5,2,7,DIRT:0)
Block(-5,2,8,WOOD:4)
Block(-5,3,3,WOOD:4)
Block(-5,3,4,LOG_2:0)
Block(-5,3,5,WOOD:4)
Block(-5,3,6,DIRT:0)
Block(-5,3,7,DIRT:0)
Block(-5,3,8,WOOD:4)
Block(-5,4,3,WOOD:4)
Block(-5,4,4,LOG_2:0)
Block(-5,4,5,WOOD:4)
Block(-5,4,6,DIRT:0)
Block(-5,4,7,DIRT:0)
Block(-5,4,8,WOOD:4)
Block(-5,5,3,WOOD:4)
Block(-5,5,4,LOG_2:0)
Block(-5,5,5,WOOD:4)
Block(-5,5,6,DIRT:0)
Block(-5,5,7,DIRT:0)
Block(-5,5,8,WOOD:4)
Block(-5,6,3,WOOD:4)
Block(-5,6,4,LOG_2:0)
Block(-5,6,5,WOOD:4)
Block(-5,6,6,DIRT:0)
Block(-5,6,7,DIRT:0)
Block(-5,6,8,WOOD:4)
Block(-5,7,3,WOOD:4)
Block(-5,7,4,LOG_2:0)
Block(-5,7,5,WOOD:4)
Block(-5,7,6,DIRT:0)
Block(-5,7,7,DIRT:0)
Block(-5,7,8,WOOD:4)
Block(-5,8,3,WOOD:4)
Block(-5,8,4,LOG_2:0)
Block(-5,8,5,WOOD:4)
Block(-5,8,6,DIRT:0)
Block(-5,8,7,DIRT:0)
Block(-5,8,8,WOOD:4)
Block(-5,9,3,WOOD:4)
Block(-5,9,4,LOG_2:0)
Block(-5,9,5,WOOD:4)
Block(-5,9,6,DIRT:0)
Block(-5,9,7,DIRT:0)
Block(-5,9,8,WOOD:4)
Block(-5,10,1,SPRUCE_FENCE:0)
Block(-5,10,2,SPRUCE_FENCE:0)
Block(-5,10,3,WOOD:4)
Block(-5,10,4,LOG_2:0)
Block(-5,10,5,WOOD:4)
Block(-5,10,6,DIRT:0)
Block(-5,10,7,DIRT:0)
Block(-5,10,8,WOOD:4)
Block(-5,11,2,SPRUCE_FENCE:0)
Block(-5,11,3,WOOD:4)
Block(-5,11,4,LOG_2:0)
Block(-5,11,5,WOOD:4)
Block(-5,11,6,DIRT:0)
Block(-5,11,7,DIRT:0)
Block(-5,11,8,WOOD:4)
Block(-5,12,2,SPRUCE_FENCE:0)
Block(-5,12,3,WOOD:4)
Block(-5,12,4,LOG_2:0)
Block(-5,12,5,WOOD:4)
Block(-5,12,6,DIRT:0)
Block(-5,12,7,DIRT:0)
Block(-5,12,8,WOOD:4)
Block(-5,13,2,SPRUCE_FENCE:0)
Block(-5,13,3,WOOD:4)
Block(-5,13,4,LOG_2:0)
Block(-5,13,5,WOOD:4)
Block(-5,13,6,DIRT:0)
Block(-5,13,7,DIRT:0)
Block(-5,13,8,WOOD:4)
Block(-5,14,3,WOOD:4)
Block(-5,14,4,LOG_2:0)
Block(-5,14,5,WOOD:4)
Block(-5,14,6,GRASS:0)
Block(-5,14,7,GRASS:0)
Block(-5,14,8,WOOD:4)
Block(-5,15,3,WOOD:4)
Block(-5,15,4,LOG_2:0)
Block(-5,15,5,WOOD:4)
Block(-5,15,8,WOOD:4)
Block(-5,16,3,WOOD_STEP:4)
RandomBlock(-5,16,4,STANDING_BANNER:11,../../NBT/banners/JungleBanner01.nbt,8,STANDING_BANNER:11,../../NBT/banners/JungleBanner02.nbt,8,STANDING_BANNER:11,../../NBT/banners/JungleBanner03.nbt,8,STANDING_BANNER:11,../../NBT/banners/JungleBanner04.nbt,8,STANDING_BANNER:11,../../NBT/banners/JungleBanner05.nbt,8,STANDING_BANNER:11,../../NBT/banners/JungleBanner06.nbt,8,STANDING_BANNER:11,../../NBT/banners/JungleBanner07.nbt,8,STANDING_BANNER:11,../../NBT/banners/JungleBanner08.nbt,8,STANDING_BANNER:11,../../NBT/banners/JungleBanner09.nbt,8,STANDING_BANNER:11,../../NBT/banners/JungleBanner10.nbt,8,STANDING_BANNER:11,../../NBT/banners/JungleBanner11.nbt,8,STANDING_BANNER:11,../../NBT/banners/JungleBanner12.nbt,8,STANDING_BANNER:11,../../NBT/banners/JungleBanner13.nbt,8,STANDING_BANNER:11,../../NBT/banners/JungleBanner14.nbt,8,STANDING_BANNER:11,../../NBT/banners/JungleBanner15.nbt,8,STANDING_BANNER:11,../../NBT/banners/JungleBanner16.nbt,8,STANDING_BANNER:11,../../NBT/banners/JungleBanner17.nbt,8,STANDING_BANNER:11,../../NBT/banners/JungleBanner18.nbt,8,STANDING_BANNER:11,../../NBT/banners/JungleBanner19.nbt,8,STANDING_BANNER:11,../../NBT/banners/JungleBanner20.nbt,100)
Block(-5,16,5,WOOD_STEP:4)
Block(-4,0,6,WOOD:4)
Block(-4,0,7,LOG_2:0)
Block(-4,1,6,WOOD:4)
Block(-4,1,7,LOG_2:0)
Block(-4,2,6,WOOD:4)
Block(-4,2,7,LOG_2:0)
Block(-4,3,6,WOOD:4)
Block(-4,3,7,LOG_2:0)
Block(-4,4,6,WOOD:4)
Block(-4,4,7,LOG_2:0)
Block(-4,5,6,WOOD:4)
Block(-4,5,7,LOG_2:0)
Block(-4,6,6,WOOD:4)
Block(-4,6,7,LOG_2:0)
Block(-4,7,6,WOOD:4)
Block(-4,7,7,LOG_2:0)
Block(-4,8,6,WOOD:4)
Block(-4,8,7,LOG_2:0)
Block(-4,9,6,WOOD:4)
Block(-4,9,7,LOG_2:0)
Block(-4,10,2,SPRUCE_FENCE:0)
Block(-4,10,3,SPRUCE_FENCE:0)
Block(-4,10,6,WOOD:4)
Block(-4,10,7,LOG_2:0)
Block(-4,10,8,SPRUCE_FENCE:0)
Block(-4,11,6,WOOD:4)
Block(-4,11,7,LOG_2:0)
Block(-4,11,8,SPRUCE_FENCE:0)
Block(-4,12,6,WOOD:4)
Block(-4,12,7,LOG_2:0)
Block(-4,12,8,SPRUCE_FENCE:0)
Block(-4,13,6,WOOD:4)
Block(-4,13,7,LOG_2:0)
Block(-4,14,6,WOOD:4)
Block(-4,14,7,LOG_2:0)
Block(-4,15,6,WOOD:4)
Block(-4,15,7,LOG_2:0)
Block(-4,16,6,WOOD_STEP:4)
RandomBlock(-4,16,7,STANDING_BANNER:11,../../NBT/banners/JungleBanner01.nbt,8,STANDING_BANNER:11,../../NBT/banners/JungleBanner02.nbt,8,STANDING_BANNER:11,../../NBT/banners/JungleBanner03.nbt,8,STANDING_BANNER:11,../../NBT/banners/JungleBanner04.nbt,8,STANDING_BANNER:11,../../NBT/banners/JungleBanner05.nbt,8,STANDING_BANNER:11,../../NBT/banners/JungleBanner06.nbt,8,STANDING_BANNER:11,../../NBT/banners/JungleBanner07.nbt,8,STANDING_BANNER:11,../../NBT/banners/JungleBanner08.nbt,8,STANDING_BANNER:11,../../NBT/banners/JungleBanner09.nbt,8,STANDING_BANNER:11,../../NBT/banners/JungleBanner10.nbt,8,STANDING_BANNER:11,../../NBT/banners/JungleBanner11.nbt,8,STANDING_BANNER:11,../../NBT/banners/JungleBanner12.nbt,8,STANDING_BANNER:11,../../NBT/banners/JungleBanner13.nbt,8,STANDING_BANNER:11,../../NBT/banners/JungleBanner14.nbt,8,STANDING_BANNER:11,../../NBT/banners/JungleBanner15.nbt,8,STANDING_BANNER:11,../../NBT/banners/JungleBanner16.nbt,8,STANDING_BANNER:11,../../NBT/banners/JungleBanner17.nbt,8,STANDING_BANNER:11,../../NBT/banners/JungleBanner18.nbt,8,STANDING_BANNER:11,../../NBT/banners/JungleBanner19.nbt,8,STANDING_BANNER:11,../../NBT/banners/JungleBanner20.nbt,100)
Block(-3,10,7,SPRUCE_FENCE:0)
Block(-3,11,7,SPRUCE_FENCE:0)
Branch(16,0,0,true,AcaciaVillagePath06C6R3,NORTH,100.0,0)