Author: NLBlackEagle
Description: No description given
SettingsMode: WriteDisable
Frequency: 0
SpawnHeight: highestBlock
UseCenterForHighestBlock: true
MinHeight: 0
MaxHeight: 255
InheritBO3: 
InheritBO3Rotation: NORTH
OverrideChildSettings: true
OverrideParentHeight: true
CanOverride: true
BranchFrequency: 0
BranchFrequencyGroup: 
MustBeBelowOther: false
MustBeInside: 
CannotBeInside: 
ReplacesBO3: 
MustBeInsideWorldBorders: false
CanSpawnOnWater: false
SpawnOnWaterOnly: false
SpawnUnderWater: false
SpawnAtWaterLevel: false
HeightOffset: -9
RemoveAir: true
ReplaceAbove: 
ReplaceBelow: dirt
ReplaceWithBiomeBlocks: true
ReplaceWithSurfaceBlock: GRASS
ReplaceWithGroundBlock: DIRT
ReplaceWithStoneBlock: STONE
SmoothRadius: 0
SmoothHeightOffset: 0
SmoothStartTop: false
SmoothStartWood: false
SmoothingSurfaceBlock: 
SmoothingGroundBlock: 
BO3Group: 
IsSpawnPoint: false
DoReplaceBlocks: true
Block(-8,0,3,WOOD:4)
Block(-8,1,3,WOOD:4)
Block(-8,2,3,WOOD:4)
Block(-8,3,3,WOOD:4)
Block(-8,4,3,WOOD:4)
Block(-8,5,3,WOOD:4)
Block(-8,6,3,WOOD:4)
Block(-8,7,3,WOOD:4)
Block(-8,8,3,WOOD:4)
Block(-8,9,3,WOOD:4)
Block(-8,10,2,SPRUCE_FENCE:0)
Block(-8,10,3,WOOD:4)
Block(-8,11,2,SPRUCE_FENCE:0)
Block(-8,11,3,WOOD:4)
Block(-8,12,3,WOOD:4)
Block(-7,0,3,LOG_2:0)
Block(-7,1,3,LOG_2:0)
Block(-7,2,3,LOG_2:0)
Block(-7,3,3,LOG_2:0)
Block(-7,4,3,LOG_2:0)
Block(-7,5,3,LOG_2:0)
Block(-7,6,3,LOG_2:0)
Block(-7,7,3,LOG_2:0)
Block(-7,8,3,LOG_2:0)
Block(-7,9,3,LOG_2:0)
Block(-7,10,2,SPRUCE_FENCE:0)
Block(-7,10,3,LOG_2:0)
Block(-7,11,3,LOG_2:0)
Block(-7,12,3,LOG_2:0)
Block(-7,13,3,LOG_2:0)
RandomBlock(-7,14,3,STANDING_BANNER:9,../../NBT/banners/JungleBanner01.nbt,8,STANDING_BANNER:9,../../NBT/banners/JungleBanner02.nbt,8,STANDING_BANNER:9,../../NBT/banners/JungleBanner03.nbt,8,STANDING_BANNER:9,../../NBT/banners/JungleBanner04.nbt,8,STANDING_BANNER:9,../../NBT/banners/JungleBanner05.nbt,8,STANDING_BANNER:9,../../NBT/banners/JungleBanner06.nbt,8,STANDING_BANNER:9,../../NBT/banners/JungleBanner07.nbt,8,STANDING_BANNER:9,../../NBT/banners/JungleBanner08.nbt,8,STANDING_BANNER:9,../../NBT/banners/JungleBanner09.nbt,8,STANDING_BANNER:9,../../NBT/banners/JungleBanner10.nbt,8,STANDING_BANNER:9,../../NBT/banners/JungleBanner11.nbt,8,STANDING_BANNER:9,../../NBT/banners/JungleBanner12.nbt,8,STANDING_BANNER:9,../../NBT/banners/JungleBanner13.nbt,8,STANDING_BANNER:9,../../NBT/banners/JungleBanner14.nbt,8,STANDING_BANNER:9,../../NBT/banners/JungleBanner15.nbt,8,STANDING_BANNER:9,../../NBT/banners/JungleBanner16.nbt,8,STANDING_BANNER:9,../../NBT/banners/JungleBanner17.nbt,8,STANDING_BANNER:9,../../NBT/banners/JungleBanner18.nbt,8,STANDING_BANNER:9,../../NBT/banners/JungleBanner19.nbt,8,STANDING_BANNER:9,../../NBT/banners/JungleBanner20.nbt,100)
Block(-6,0,4,WOOD:4)
Block(-6,1,4,WOOD:4)
Block(-6,2,4,WOOD:4)
Block(-6,3,4,WOOD:4)
Block(-6,4,4,WOOD:4)
Block(-6,5,4,WOOD:4)
Block(-6,6,4,WOOD:4)
Block(-6,7,4,WOOD:4)
Block(-6,8,4,WOOD:4)
Block(-6,9,4,WOOD:4)
Block(-6,10,3,SPRUCE_FENCE:0)
Block(-6,10,4,WOOD:4)
Block(-6,11,4,WOOD:4)
Block(-6,12,4,WOOD:4)
Block(-6,13,4,WOOD:4)
Block(-6,14,4,WOOD:4)
Block(-5,0,4,WOOD:4)
Block(-5,1,4,WOOD:4)
Block(-5,2,4,WOOD:4)
Block(-5,3,4,WOOD:4)
Block(-5,4,4,WOOD:4)
Block(-5,5,4,WOOD:4)
Block(-5,6,4,WOOD:4)
Block(-5,7,4,WOOD:4)
Block(-5,8,4,WOOD:4)
Block(-5,9,4,WOOD:4)
Block(-5,10,3,SPRUCE_FENCE:0)
Block(-5,10,4,WOOD:4)
Block(-5,11,3,SPRUCE_FENCE:0)
Block(-5,11,4,WOOD:4)
Block(-5,12,3,SPRUCE_FENCE:0)
Block(-5,12,4,WOOD:4)
Block(-5,13,4,WOOD:4)
Block(-5,14,4,WOOD:4)
Block(-4,0,4,WOOD:4)
Block(-4,0,5,WOOD:4)
Block(-4,1,4,WOOD:4)
Block(-4,1,5,WOOD:4)
Block(-4,2,4,WOOD:4)
Block(-4,2,5,WOOD:4)
Block(-4,3,4,WOOD:4)
Block(-4,3,5,WOOD:4)
Block(-4,4,4,WOOD:4)
Block(-4,4,5,WOOD:4)
Block(-4,5,4,WOOD:4)
Block(-4,5,5,WOOD:4)
Block(-4,6,4,WOOD:4)
Block(-4,6,5,WOOD:4)
Block(-4,7,4,WOOD:4)
Block(-4,7,5,WOOD:4)
Block(-4,8,4,WOOD:4)
Block(-4,8,5,WOOD:4)
Block(-4,9,4,WOOD:4)
Block(-4,9,5,WOOD:4)
Block(-4,10,4,WOOD:4)
Block(-4,10,5,WOOD:4)
Block(-4,11,4,WOOD:4)
Block(-4,11,5,WOOD:4)
Block(-4,12,4,WOOD:4)
Block(-4,12,5,WOOD:4)
Block(-4,13,4,WOOD:4)
Block(-4,13,5,WOOD:4)
Block(-3,0,6,WOOD:4)
Block(-3,1,6,WOOD:4)
Block(-3,2,6,WOOD:4)
Block(-3,3,6,WOOD:4)
Block(-3,4,6,WOOD:4)
Block(-3,5,6,WOOD:4)
Block(-3,6,6,WOOD:4)
Block(-3,7,6,WOOD:4)
Block(-3,8,6,WOOD:4)
Block(-3,9,6,WOOD:4)
Block(-3,10,5,SPRUCE_FENCE:0)
Block(-3,10,6,WOOD:4)
Block(-3,11,6,WOOD:4)
Block(-3,12,6,WOOD:4)
Block(-3,13,6,WOOD:4)
Block(-2,0,6,WOOD:4)
Block(-2,1,6,WOOD:4)
Block(-2,2,6,WOOD:4)
Block(-2,3,6,WOOD:4)
Block(-2,4,6,WOOD:4)
Block(-2,5,6,WOOD:4)
Block(-2,6,6,WOOD:4)
Block(-2,7,6,WOOD:4)
Block(-2,8,6,WOOD:4)
Block(-2,9,6,WOOD:4)
Block(-2,10,5,SPRUCE_FENCE:0)
Block(-2,10,6,WOOD:4)
Block(-2,11,6,WOOD:4)
Block(-2,12,6,WOOD:4)
Block(-2,13,6,WOOD:4)
Block(-1,0,7,WOOD:4)
Block(-1,1,7,WOOD:4)
Block(-1,2,7,WOOD:4)
Block(-1,3,7,WOOD:4)
Block(-1,4,7,WOOD:4)
Block(-1,5,7,WOOD:4)
Block(-1,6,7,WOOD:4)
Block(-1,7,7,WOOD:4)
Block(-1,8,7,WOOD:4)
Block(-1,9,7,WOOD:4)
Block(-1,10,6,SPRUCE_FENCE:0)
Block(-1,10,7,WOOD:4)
Block(-1,11,6,SPRUCE_FENCE:0)
Block(-1,11,7,WOOD:4)
Block(-1,12,7,WOOD:4)
Block(-1,13,7,WOOD:4)
Block(-1,14,7,WOOD:4)
Block(0,0,7,WOOD:4)
Block(0,1,7,WOOD:4)
Block(0,2,7,WOOD:4)
Block(0,3,7,WOOD:4)
Block(0,4,7,WOOD:4)
Block(0,5,7,WOOD:4)
Block(0,6,7,WOOD:4)
Block(0,7,7,WOOD:4)
Block(0,8,7,WOOD:4)
Block(0,9,7,WOOD:4)
Block(0,10,7,WOOD:4)
Block(0,11,7,WOOD:4)
Block(0,12,7,WOOD:4)
Block(0,13,7,WOOD:4)
Block(0,14,7,WOOD:4)
Block(1,0,7,LOG_2:0)
Block(1,1,7,LOG_2:0)
Block(1,2,7,LOG_2:0)
Block(1,3,7,LOG_2:0)
Block(1,4,7,LOG_2:0)
Block(1,5,7,LOG_2:0)
Block(1,6,7,LOG_2:0)
Block(1,7,7,LOG_2:0)
Block(1,8,7,LOG_2:0)
Block(1,9,7,LOG_2:0)
Block(1,10,7,LOG_2:0)
Block(1,11,7,LOG_2:0)
Block(1,12,7,LOG_2:0)
Block(1,13,7,LOG_2:0)
Block(1,14,7,LOG_2:0)
Block(1,15,7,LOG_2:0)
RandomBlock(1,16,7,STANDING_BANNER:10,../../NBT/banners/JungleBanner01.nbt,8,STANDING_BANNER:10,../../NBT/banners/JungleBanner02.nbt,8,STANDING_BANNER:10,../../NBT/banners/JungleBanner03.nbt,8,STANDING_BANNER:10,../../NBT/banners/JungleBanner04.nbt,8,STANDING_BANNER:10,../../NBT/banners/JungleBanner05.nbt,8,STANDING_BANNER:10,../../NBT/banners/JungleBanner06.nbt,8,STANDING_BANNER:10,../../NBT/banners/JungleBanner07.nbt,8,STANDING_BANNER:10,../../NBT/banners/JungleBanner08.nbt,8,STANDING_BANNER:10,../../NBT/banners/JungleBanner09.nbt,8,STANDING_BANNER:10,../../NBT/banners/JungleBanner10.nbt,8,STANDING_BANNER:10,../../NBT/banners/JungleBanner11.nbt,8,STANDING_BANNER:10,../../NBT/banners/JungleBanner12.nbt,8,STANDING_BANNER:10,../../NBT/banners/JungleBanner13.nbt,8,STANDING_BANNER:10,../../NBT/banners/JungleBanner14.nbt,8,STANDING_BANNER:10,../../NBT/banners/JungleBanner15.nbt,8,STANDING_BANNER:10,../../NBT/banners/JungleBanner16.nbt,8,STANDING_BANNER:10,../../NBT/banners/JungleBanner17.nbt,8,STANDING_BANNER:10,../../NBT/banners/JungleBanner18.nbt,8,STANDING_BANNER:10,../../NBT/banners/JungleBanner19.nbt,8,STANDING_BANNER:10,../../NBT/banners/JungleBanner20.nbt,100)
Block(2,0,8,WOOD:4)
Block(2,1,8,WOOD:4)
Block(2,2,8,WOOD:4)
Block(2,3,8,WOOD:4)
Block(2,4,8,WOOD:4)
Block(2,5,8,WOOD:4)
Block(2,6,8,WOOD:4)
Block(2,7,8,WOOD:4)
Block(2,8,8,WOOD:4)
Block(2,9,8,WOOD:4)
Block(2,10,7,SPRUCE_FENCE:0)
Block(2,10,8,WOOD:4)
Block(2,11,8,WOOD:4)
Block(2,12,8,WOOD:4)
Block(2,13,8,WOOD:4)
Block(2,14,8,WOOD:4)
Branch(16,0,0,true,AcaciaVillagePath05C5R1,NORTH,100.0,0)
Branch(0,0,-16,true,AcaciaVillagePath05C4R0,NORTH,100.0,0)