Author: NLBlackEagle
Description: No description given
SettingsMode: WriteDisable
Frequency: 0
SpawnHeight: highestBlock
UseCenterForHighestBlock: true
MinHeight: 0
MaxHeight: 255
InheritBO3: 
InheritBO3Rotation: NORTH
OverrideChildSettings: true
OverrideParentHeight: true
CanOverride: true
BranchFrequency: 0
BranchFrequencyGroup: 
MustBeBelowOther: false
MustBeInside: 
CannotBeInside: 
ReplacesBO3: 
MustBeInsideWorldBorders: false
CanSpawnOnWater: false
SpawnOnWaterOnly: false
SpawnUnderWater: false
SpawnAtWaterLevel: false
HeightOffset: -9
RemoveAir: true
ReplaceAbove: 
ReplaceBelow: dirt
ReplaceWithBiomeBlocks: true
ReplaceWithSurfaceBlock: GRASS
ReplaceWithGroundBlock: DIRT
ReplaceWithStoneBlock: STONE
SmoothRadius: 0
SmoothHeightOffset: 0
SmoothStartTop: false
SmoothStartWood: false
SmoothingSurfaceBlock: 
SmoothingGroundBlock: 
BO3Group: 
IsSpawnPoint: false
DoReplaceBlocks: true
Block(-8,10,1,SPRUCE_FENCE:0)
Block(-8,10,2,SPRUCE_FENCE:0)
Block(-8,10,3,SPRUCE_FENCE:0)
RandomBlock(-8,14,-3,WALL_BANNER:4,../../NBT/banners/JungleBanner01.nbt,8,WALL_BANNER:4,../../NBT/banners/JungleBanner02.nbt,8,WALL_BANNER:4,../../NBT/banners/JungleBanner03.nbt,8,WALL_BANNER:4,../../NBT/banners/JungleBanner04.nbt,8,WALL_BANNER:4,../../NBT/banners/JungleBanner05.nbt,8,WALL_BANNER:4,../../NBT/banners/JungleBanner06.nbt,8,WALL_BANNER:4,../../NBT/banners/JungleBanner07.nbt,8,WALL_BANNER:4,../../NBT/banners/JungleBanner08.nbt,8,WALL_BANNER:4,../../NBT/banners/JungleBanner09.nbt,8,WALL_BANNER:4,../../NBT/banners/JungleBanner10.nbt,8,WALL_BANNER:4,../../NBT/banners/JungleBanner11.nbt,8,WALL_BANNER:4,../../NBT/banners/JungleBanner12.nbt,8,WALL_BANNER:4,../../NBT/banners/JungleBanner13.nbt,8,WALL_BANNER:4,../../NBT/banners/JungleBanner14.nbt,8,WALL_BANNER:4,../../NBT/banners/JungleBanner15.nbt,8,WALL_BANNER:4,../../NBT/banners/JungleBanner16.nbt,8,WALL_BANNER:4,../../NBT/banners/JungleBanner17.nbt,8,WALL_BANNER:4,../../NBT/banners/JungleBanner18.nbt,8,WALL_BANNER:4,../../NBT/banners/JungleBanner19.nbt,8,WALL_BANNER:4,../../NBT/banners/JungleBanner20.nbt,100)
RandomBlock(-8,14,3,WALL_BANNER:4,../../NBT/banners/JungleBanner01.nbt,8,WALL_BANNER:4,../../NBT/banners/JungleBanner02.nbt,8,WALL_BANNER:4,../../NBT/banners/JungleBanner03.nbt,8,WALL_BANNER:4,../../NBT/banners/JungleBanner04.nbt,8,WALL_BANNER:4,../../NBT/banners/JungleBanner05.nbt,8,WALL_BANNER:4,../../NBT/banners/JungleBanner06.nbt,8,WALL_BANNER:4,../../NBT/banners/JungleBanner07.nbt,8,WALL_BANNER:4,../../NBT/banners/JungleBanner08.nbt,8,WALL_BANNER:4,../../NBT/banners/JungleBanner09.nbt,8,WALL_BANNER:4,../../NBT/banners/JungleBanner10.nbt,8,WALL_BANNER:4,../../NBT/banners/JungleBanner11.nbt,8,WALL_BANNER:4,../../NBT/banners/JungleBanner12.nbt,8,WALL_BANNER:4,../../NBT/banners/JungleBanner13.nbt,8,WALL_BANNER:4,../../NBT/banners/JungleBanner14.nbt,8,WALL_BANNER:4,../../NBT/banners/JungleBanner15.nbt,8,WALL_BANNER:4,../../NBT/banners/JungleBanner16.nbt,8,WALL_BANNER:4,../../NBT/banners/JungleBanner17.nbt,8,WALL_BANNER:4,../../NBT/banners/JungleBanner18.nbt,8,WALL_BANNER:4,../../NBT/banners/JungleBanner19.nbt,8,WALL_BANNER:4,../../NBT/banners/JungleBanner20.nbt,100)
Block(-7,0,-3,LOG_2:0)
Block(-7,0,-2,WOOD:4)
Block(-7,0,1,WOOD:4)
Block(-7,0,2,WOOD:4)
Block(-7,0,3,LOG_2:0)
Block(-7,0,4,WOOD:4)
Block(-7,1,-3,LOG_2:0)
Block(-7,1,-2,WOOD:4)
Block(-7,1,1,WOOD:4)
Block(-7,1,2,WOOD:4)
Block(-7,1,3,LOG_2:0)
Block(-7,1,4,WOOD:4)
Block(-7,2,-3,LOG_2:0)
Block(-7,2,-2,WOOD:4)
Block(-7,2,1,WOOD:4)
Block(-7,2,2,WOOD:4)
Block(-7,2,3,LOG_2:0)
Block(-7,2,4,WOOD:4)
Block(-7,3,-3,LOG_2:0)
Block(-7,3,-2,WOOD:4)
Block(-7,3,1,WOOD:4)
Block(-7,3,2,WOOD:4)
Block(-7,3,3,LOG_2:0)
Block(-7,3,4,WOOD:4)
Block(-7,4,-3,LOG_2:0)
Block(-7,4,-2,WOOD:4)
Block(-7,4,1,WOOD:4)
Block(-7,4,2,WOOD:4)
Block(-7,4,3,LOG_2:0)
Block(-7,4,4,WOOD:4)
Block(-7,5,-3,LOG_2:0)
Block(-7,5,-2,WOOD:4)
Block(-7,5,1,WOOD:4)
Block(-7,5,2,WOOD:4)
Block(-7,5,3,LOG_2:0)
Block(-7,5,4,WOOD:4)
Block(-7,6,-3,LOG_2:0)
Block(-7,6,-2,WOOD:4)
Block(-7,6,1,WOOD:4)
Block(-7,6,2,WOOD:4)
Block(-7,6,3,LOG_2:0)
Block(-7,6,4,WOOD:4)
Block(-7,7,-3,LOG_2:0)
Block(-7,7,-2,WOOD:4)
Block(-7,7,1,WOOD:4)
Block(-7,7,2,WOOD:4)
Block(-7,7,3,LOG_2:0)
Block(-7,7,4,WOOD:4)
Block(-7,8,-3,LOG_2:0)
Block(-7,8,-2,WOOD:4)
Block(-7,8,1,WOOD:4)
Block(-7,8,2,WOOD:4)
Block(-7,8,3,LOG_2:0)
Block(-7,8,4,WOOD:4)
Block(-7,9,-7,GRASS_PATH:0)
Block(-7,9,-6,GRASS_PATH:0)
Block(-7,9,-3,LOG_2:0)
Block(-7,9,-2,WOOD:4)
Block(-7,9,1,WOOD:4)
Block(-7,9,2,WOOD:4)
Block(-7,9,3,LOG_2:0)
Block(-7,9,4,WOOD:4)
Block(-7,10,-3,LOG_2:0)
Block(-7,10,-2,WOOD:4)
Block(-7,10,-1,SPRUCE_FENCE:0)
Block(-7,10,0,SPRUCE_FENCE:0)
Block(-7,10,1,WOOD:4)
Block(-7,10,2,WOOD:4)
Block(-7,10,3,LOG_2:0)
Block(-7,10,4,WOOD:4)
Block(-7,10,5,SPRUCE_FENCE:0)
Block(-7,10,8,SPRUCE_FENCE:0)
Block(-7,11,-3,LOG_2:0)
Block(-7,11,-2,WOOD:4)
Block(-7,11,0,SPRUCE_FENCE:0)
Block(-7,11,1,WOOD:4)
Block(-7,11,2,WOOD:4)
Block(-7,11,3,LOG_2:0)
Block(-7,11,4,WOOD:4)
Block(-7,12,-3,LOG_2:0)
Block(-7,12,-2,WOOD:4)
Block(-7,12,1,WOOD:4)
Block(-7,12,2,WOOD:4)
Block(-7,12,3,LOG_2:0)
Block(-7,12,4,WOOD:4)
Block(-7,13,-3,LOG_2:0)
Block(-7,13,-2,WOOD:4)
Block(-7,13,1,SPRUCE_FENCE:0)
Block(-7,13,2,WOOD:4)
Block(-7,13,3,LOG_2:0)
Block(-7,13,4,WOOD:4)
Block(-7,14,-3,LOG_2:0)
Block(-7,14,3,LOG_2:0)
RandomBlock(-7,14,8,WALL_BANNER:4,../../NBT/banners/JungleBanner01.nbt,8,WALL_BANNER:4,../../NBT/banners/JungleBanner02.nbt,8,WALL_BANNER:4,../../NBT/banners/JungleBanner03.nbt,8,WALL_BANNER:4,../../NBT/banners/JungleBanner04.nbt,8,WALL_BANNER:4,../../NBT/banners/JungleBanner05.nbt,8,WALL_BANNER:4,../../NBT/banners/JungleBanner06.nbt,8,WALL_BANNER:4,../../NBT/banners/JungleBanner07.nbt,8,WALL_BANNER:4,../../NBT/banners/JungleBanner08.nbt,8,WALL_BANNER:4,../../NBT/banners/JungleBanner09.nbt,8,WALL_BANNER:4,../../NBT/banners/JungleBanner10.nbt,8,WALL_BANNER:4,../../NBT/banners/JungleBanner11.nbt,8,WALL_BANNER:4,../../NBT/banners/JungleBanner12.nbt,8,WALL_BANNER:4,../../NBT/banners/JungleBanner13.nbt,8,WALL_BANNER:4,../../NBT/banners/JungleBanner14.nbt,8,WALL_BANNER:4,../../NBT/banners/JungleBanner15.nbt,8,WALL_BANNER:4,../../NBT/banners/JungleBanner16.nbt,8,WALL_BANNER:4,../../NBT/banners/JungleBanner17.nbt,8,WALL_BANNER:4,../../NBT/banners/JungleBanner18.nbt,8,WALL_BANNER:4,../../NBT/banners/JungleBanner19.nbt,8,WALL_BANNER:4,../../NBT/banners/JungleBanner20.nbt,100)
Block(-6,0,-1,WOOD:4)
Block(-6,0,0,WOOD:4)
Block(-6,0,5,WOOD:4)
Block(-6,0,8,LOG_2:0)
Block(-6,1,-1,WOOD:4)
Block(-6,1,0,WOOD:4)
Block(-6,1,5,WOOD:4)
Block(-6,1,8,LOG_2:0)
Block(-6,2,-1,WOOD:4)
Block(-6,2,0,WOOD:4)
Block(-6,2,5,WOOD:4)
Block(-6,2,8,LOG_2:0)
Block(-6,3,-1,WOOD:4)
Block(-6,3,0,WOOD:4)
Block(-6,3,5,WOOD:4)
Block(-6,3,8,LOG_2:0)
Block(-6,4,-1,WOOD:4)
Block(-6,4,0,WOOD:4)
Block(-6,4,5,WOOD:4)
Block(-6,4,8,LOG_2:0)
Block(-6,5,-1,WOOD:4)
Block(-6,5,0,WOOD:4)
Block(-6,5,5,WOOD:4)
Block(-6,5,8,LOG_2:0)
Block(-6,6,-1,WOOD:4)
Block(-6,6,0,WOOD:4)
Block(-6,6,5,WOOD:4)
Block(-6,6,8,LOG_2:0)
Block(-6,7,-1,WOOD:4)
Block(-6,7,0,WOOD:4)
Block(-6,7,5,WOOD:4)
Block(-6,7,8,LOG_2:0)
Block(-6,8,-1,WOOD:4)
Block(-6,8,0,WOOD:4)
Block(-6,8,5,WOOD:4)
Block(-6,8,8,LOG_2:0)
Block(-6,9,-7,GRASS_PATH:0)
Block(-6,9,-6,GRASS_PATH:0)
Block(-6,9,-5,WOOD:4)
Block(-6,9,-4,GRASS_PATH:0)
Block(-6,9,-1,WOOD:4)
Block(-6,9,0,WOOD:4)
Block(-6,9,5,WOOD:4)
Block(-6,9,8,LOG_2:0)
Block(-6,10,-5,AIR:0)
Block(-6,10,-1,WOOD:4)
Block(-6,10,0,WOOD:4)
Block(-6,10,5,WOOD:4)
Block(-6,10,6,SPRUCE_FENCE:0)
Block(-6,10,7,SPRUCE_FENCE:0)
Block(-6,10,8,LOG_2:0)
Block(-6,11,-3,LOG_2:4)
Block(-6,11,-2,WOOD_STEP:12)
Block(-6,11,-1,WOOD:4)
Block(-6,11,0,WOOD:4)
Block(-6,11,1,WOOD_STEP:12)
Block(-6,11,3,LOG_2:4)
Block(-6,11,5,WOOD:4)
Block(-6,11,8,LOG_2:0)
Block(-6,12,-3,WOOD_STEP:4)
Block(-6,12,-2,WOOD_STEP:4)
Block(-6,12,-1,WOOD:4)
Block(-6,12,0,SPRUCE_FENCE:0)
Block(-6,12,2,WOOD_STEP:4)
Block(-6,12,3,WOOD_STEP:4)
Block(-6,12,4,WOOD_STEP:4)
Block(-6,12,5,WOOD:4)
Block(-6,12,8,LOG_2:0)
Block(-6,13,-1,SPRUCE_FENCE:0)
Block(-6,13,3,AIR:0)
Block(-6,13,5,SPRUCE_FENCE:0)
Block(-6,13,8,LOG_2:0)
RandomBlock(-6,14,7,WALL_BANNER:2,../../NBT/banners/JungleBanner01.nbt,8,WALL_BANNER:2,../../NBT/banners/JungleBanner02.nbt,8,WALL_BANNER:2,../../NBT/banners/JungleBanner03.nbt,8,WALL_BANNER:2,../../NBT/banners/JungleBanner04.nbt,8,WALL_BANNER:2,../../NBT/banners/JungleBanner05.nbt,8,WALL_BANNER:2,../../NBT/banners/JungleBanner06.nbt,8,WALL_BANNER:2,../../NBT/banners/JungleBanner07.nbt,8,WALL_BANNER:2,../../NBT/banners/JungleBanner08.nbt,8,WALL_BANNER:2,../../NBT/banners/JungleBanner09.nbt,8,WALL_BANNER:2,../../NBT/banners/JungleBanner10.nbt,8,WALL_BANNER:2,../../NBT/banners/JungleBanner11.nbt,8,WALL_BANNER:2,../../NBT/banners/JungleBanner12.nbt,8,WALL_BANNER:2,../../NBT/banners/JungleBanner13.nbt,8,WALL_BANNER:2,../../NBT/banners/JungleBanner14.nbt,8,WALL_BANNER:2,../../NBT/banners/JungleBanner15.nbt,8,WALL_BANNER:2,../../NBT/banners/JungleBanner16.nbt,8,WALL_BANNER:2,../../NBT/banners/JungleBanner17.nbt,8,WALL_BANNER:2,../../NBT/banners/JungleBanner18.nbt,8,WALL_BANNER:2,../../NBT/banners/JungleBanner19.nbt,8,WALL_BANNER:2,../../NBT/banners/JungleBanner20.nbt,100)
Block(-6,14,8,LOG_2:0)
Block(-5,0,6,WOOD:4)
Block(-5,0,7,WOOD:4)
Block(-5,1,6,WOOD:4)
Block(-5,1,7,WOOD:4)
Block(-5,2,6,WOOD:4)
Block(-5,2,7,WOOD:4)
Block(-5,3,6,WOOD:4)
Block(-5,3,7,WOOD:4)
Block(-5,4,6,WOOD:4)
Block(-5,4,7,WOOD:4)
Block(-5,5,6,WOOD:4)
Block(-5,5,7,WOOD:4)
Block(-5,6,6,WOOD:4)
Block(-5,6,7,WOOD:4)
Block(-5,7,6,WOOD:4)
Block(-5,7,7,WOOD:4)
Block(-5,8,6,WOOD:4)
Block(-5,8,7,WOOD:4)
Block(-5,9,-7,GRASS_PATH:0)
Block(-5,9,-6,GRASS_PATH:0)
Block(-5,9,-5,WOOD:4)
Block(-5,9,-4,GRASS_PATH:0)
Block(-5,9,-3,GRASS_PATH:0)
Block(-5,9,6,WOOD:4)
Block(-5,9,7,WOOD:4)
Block(-5,10,6,WOOD:4)
Block(-5,10,7,WOOD:4)
Block(-5,11,-3,LOG_2:4)
Block(-5,11,-2,WOOD_STEP:12)
Block(-5,11,-1,WOOD_STEP:12)
Block(-5,11,0,WOOD_STEP:12)
Block(-5,11,1,WOOD_STEP:12)
Block(-5,11,3,LOG_2:4)
Block(-5,11,4,WOOD_STEP:12)
Block(-5,11,5,WOOD_STEP:12)
Block(-5,11,6,WOOD:4)
Block(-5,11,7,WOOD:4)
Block(-5,11,8,LOG_2:4)
Block(-5,12,-3,WOOD_STEP:4)
Block(-5,12,2,WOOD_STEP:4)
Block(-5,12,3,WOOD_STEP:4)
Block(-5,12,6,WOOD:4)
Block(-5,12,7,WOOD:4)
Block(-5,12,8,WOOD_STEP:4)
Block(-5,13,6,SPRUCE_FENCE:0)
Block(-5,13,7,WOOD:4)
Block(-4,0,-3,LOG_2:0)
Block(-4,0,3,LOG_2:0)
Block(-4,1,-3,LOG_2:0)
Block(-4,1,3,LOG_2:0)
Block(-4,2,-3,LOG_2:0)
Block(-4,2,3,LOG_2:0)
Block(-4,3,-3,LOG_2:0)
Block(-4,3,3,LOG_2:0)
Block(-4,4,-3,LOG_2:0)
Block(-4,4,3,LOG_2:0)
Block(-4,5,-3,LOG_2:0)
Block(-4,5,3,LOG_2:0)
Block(-4,6,-3,LOG_2:0)
Block(-4,6,3,LOG_2:0)
Block(-4,7,-3,LOG_2:0)
Block(-4,7,3,LOG_2:0)
Block(-4,8,-3,LOG_2:0)
Block(-4,8,3,LOG_2:0)
Block(-4,9,-6,GRASS_PATH:0)
Block(-4,9,-5,WOOD:4)
Block(-4,9,-4,GRASS_PATH:0)
Block(-4,9,-3,LOG_2:0)
Block(-4,9,3,LOG_2:0)
Block(-4,10,-5,AIR:0)
Block(-4,10,-3,LOG_2:0)
Block(-4,10,3,LOG_2:0)
Block(-4,11,-3,LOG_2:4)
Block(-4,11,3,LOG_2:4)
Block(-4,11,5,WOOD_STEP:12)
Block(-4,11,6,WOOD_STEP:12)
Block(-4,11,8,LOG_2:4)
Block(-4,12,7,WOOD_STEP:4)
Block(-4,12,8,WOOD_STEP:4)
Block(-3,0,8,LOG_2:0)
Block(-3,1,8,LOG_2:0)
Block(-3,2,8,LOG_2:0)
Block(-3,3,8,LOG_2:0)
Block(-3,4,8,LOG_2:0)
Block(-3,5,8,LOG_2:0)
Block(-3,6,8,LOG_2:0)
Block(-3,7,8,LOG_2:0)
Block(-3,8,8,LOG_2:0)
Block(-3,9,-4,GRASS_PATH:0)
Block(-3,9,-3,GRASS_PATH:0)
Block(-3,9,-2,GRASS_PATH:0)
Block(-3,9,8,LOG_2:0)
Block(-3,10,8,LOG_2:0)
Block(-3,11,8,LOG_2:4)
Block(-2,9,-4,GRASS_PATH:0)
Block(-2,9,-3,GRASS_PATH:0)
Block(-2,9,-2,GRASS_PATH:0)
Block(-2,9,-1,GRASS_PATH:0)
Block(-1,9,-2,GRASS_PATH:0)
Block(-1,9,-1,GRASS_PATH:0)
Block(-1,9,0,GRASS_PATH:0)
Block(-1,9,1,GRASS_PATH:0)
Block(-1,9,2,WOOD:4)
Block(-1,10,2,AIR:0)
Block(0,9,-1,GRASS_PATH:0)
Block(0,9,0,GRASS_PATH:0)
Block(0,9,1,GRASS_PATH:0)
Block(0,9,2,WOOD:4)
Block(0,9,3,GRASS_PATH:0)
Block(1,9,0,GRASS_PATH:0)
Block(1,9,1,WOOD:4)
Block(1,9,2,WOOD:4)
Block(1,9,3,GRASS_PATH:0)
Block(1,10,2,AIR:0)
Block(2,9,1,GRASS_PATH:0)
Block(2,9,2,GRASS_PATH:0)
Block(2,9,3,GRASS_PATH:0)
Block(2,9,4,GRASS_PATH:0)
Block(2,9,5,GRASS_PATH:0)
Block(3,9,3,GRASS_PATH:0)
Block(3,9,4,GRASS_PATH:0)
Block(3,9,5,GRASS_PATH:0)
Block(3,9,6,WOOD:4)
Block(3,9,7,WOOD:4)
Block(3,10,6,AIR:0)
Block(3,10,7,AIR:0)
Block(4,9,3,GRASS_PATH:0)
Block(4,9,4,GRASS_PATH:0)
Block(4,9,5,GRASS_PATH:0)
Block(4,9,6,WOOD:4)
Block(4,9,7,GRASS_PATH:0)
Block(4,10,6,AIR:0)
Block(5,9,5,WOOD:4)
Block(5,9,6,GRASS_PATH:0)
Block(5,9,7,GRASS_PATH:0)
Block(5,9,8,GRASS_PATH:0)
Block(5,10,5,AIR:0)
WeightedBranch(0,0,0,true,Acacia-Defence01,NORTH,25.0,10,Defence01,EAST,25.0,10,Defence01,SOUTH,25.0,10,Defence01,WEST,25.0,10,100.0)
Branch(0,0,-16,true,AcaciaVillagePath09C0R2,NORTH,100.0,0)
#Entity(-6,10,-5,minecraft:villager_golem,1,../../NBT/entities/tribalgatekeeper.txt)
#Entity(-6,13,3,minecraft:villager,1,../../NBT/entities/tribalbowman.txt)
#Entity(-4,10,-5,minecraft:villager_golem,1,../../NBT/entities/tribalgatekeeper.txt)
#Entity(-1,10,2,minecraft:villager,1,../../NBT/entities/tribalhunter.txt)
#Entity(1,10,2,minecraft:villager,1,../../NBT/entities/tribalnative.txt)
#Entity(3,10,6,minecraft:villager,1,../../NBT/entities/tribalnative.txt)
#Entity(3,10,7,minecraft:villager,1,../../NBT/entities/tribalhunter.txt)
#Entity(4,10,6,minecraft:villager,1,../../NBT/entities/tribalhunter.txt)
#Entity(5,10,5,minecraft:villager,1,../../NBT/entities/tribalguard.txt)