
#######################################################################
# +-----------------------------------------------------------------+ #
# |                            BO4 object                           | #
# +-----------------------------------------------------------------+ #
#######################################################################

Author: NLBlackEagle

Description: No description given

SettingsMode: WriteDisable


#######################################################################
# +-----------------------------------------------------------------+ #
# |                          Main settings                          | #
# +-----------------------------------------------------------------+ #
#######################################################################

FixedRotation: 

Frequency: 0

SpawnHeight: highestBlock

UseCenterForHighestBlock: true

##############################
# Height Limits for the BO4. #
##############################

MinHeight: 0

MaxHeight: 255

InheritBO3: 

InheritBO3Rotation: NORTH

OverrideChildSettings: true

OverrideParentHeight: false

CanOverride: true

BranchFrequency: 0

BranchFrequencyGroup: 

MustBeBelowOther: false

MustBeInside: 

CannotBeInside: 

ReplacesBO3: 

MustBeInsideWorldBorders: false

CanSpawnOnWater: true

SpawnOnWaterOnly: false

SpawnUnderWater: false

SpawnAtWaterLevel: false

HeightOffset: 0

RemoveAir: false

ReplaceAbove: 

ReplaceBelow: 

ReplaceWithBiomeBlocks: false

ReplaceWithSurfaceBlock: GRASS

ReplaceWithGroundBlock: DIRT

ReplaceWithStoneBlock: STONE

SmoothRadius: 0

SmoothHeightOffset: 0

SmoothStartTop: false

SmoothStartWood: false

SmoothingSurfaceBlock: 

SmoothingGroundBlock: 

BO3Group: 

IsSpawnPoint: false

DoReplaceBlocks: true


#######################################################################
# +-----------------------------------------------------------------+ #
# |                              Blocks                             | #
# +-----------------------------------------------------------------+ #
#######################################################################

RandomBlock(-7,0,-7,contenttweaker:reinforced_concrete,40,SMOOTH_BRICK:1,30,SMOOTH_BRICK:2,30,SMOOTH_STAIRS:0,15,SMOOTH_STAIRS:1,15,SMOOTH_STAIRS:2,15,SMOOTH_STAIRS:3,15,STEP:5,15,STEP:13,15,COBBLE_WALL:0,10,COBBLESTONE_STAIRS:0,10,STEP:3,10,COBBLE_WALL:1,20,COBBLESTONE_STAIRS:2,20,COBBLESTONE_STAIRS:3,20,MOSSY_COBBLESTONE:0,60,COBBLESTONE_STAIRS:1,20,STEP:11,20,COBBLESTONE:0,100)
RandomBlock(-7,1,-7,contenttweaker:reinforced_concrete,40,SMOOTH_BRICK:1,30,SMOOTH_BRICK:2,30,SMOOTH_STAIRS:0,15,SMOOTH_STAIRS:1,15,SMOOTH_STAIRS:2,15,SMOOTH_STAIRS:3,15,STEP:5,15,STEP:13,15,COBBLE_WALL:0,10,COBBLESTONE_STAIRS:0,10,STEP:3,10,COBBLE_WALL:1,20,COBBLESTONE_STAIRS:2,20,COBBLESTONE_STAIRS:3,20,MOSSY_COBBLESTONE:0,60,COBBLESTONE_STAIRS:1,20,STEP:11,20,COBBLESTONE:0,100)
RandomBlock(-7,2,-7,contenttweaker:reinforced_concrete,40,SMOOTH_BRICK:1,30,SMOOTH_BRICK:2,30,SMOOTH_STAIRS:0,15,SMOOTH_STAIRS:1,15,SMOOTH_STAIRS:2,15,SMOOTH_STAIRS:3,15,STEP:5,15,STEP:13,15,COBBLE_WALL:0,10,COBBLESTONE_STAIRS:0,10,STEP:3,10,COBBLE_WALL:1,20,COBBLESTONE_STAIRS:2,20,COBBLESTONE_STAIRS:3,20,MOSSY_COBBLESTONE:0,60,COBBLESTONE_STAIRS:1,20,STEP:11,20,COBBLESTONE:0,100)
RandomBlock(-7,3,-7,contenttweaker:reinforced_concrete,40,SMOOTH_BRICK:1,30,SMOOTH_BRICK:2,30,SMOOTH_STAIRS:0,15,SMOOTH_STAIRS:1,15,SMOOTH_STAIRS:2,15,SMOOTH_STAIRS:3,15,STEP:5,15,STEP:13,15,COBBLE_WALL:0,10,COBBLESTONE_STAIRS:0,10,STEP:3,10,COBBLE_WALL:1,20,COBBLESTONE_STAIRS:2,20,COBBLESTONE_STAIRS:3,20,MOSSY_COBBLESTONE:0,60,COBBLESTONE_STAIRS:1,20,STEP:11,20,COBBLESTONE:0,100)
RandomBlock(-7,4,-7,contenttweaker:reinforced_concrete,40,SMOOTH_BRICK:1,30,SMOOTH_BRICK:2,30,SMOOTH_STAIRS:0,15,SMOOTH_STAIRS:1,15,SMOOTH_STAIRS:2,15,SMOOTH_STAIRS:3,15,STEP:5,15,STEP:13,15,COBBLE_WALL:0,10,COBBLESTONE_STAIRS:0,10,STEP:3,10,COBBLE_WALL:1,20,COBBLESTONE_STAIRS:2,20,COBBLESTONE_STAIRS:3,20,MOSSY_COBBLESTONE:0,60,COBBLESTONE_STAIRS:1,20,STEP:11,20,COBBLESTONE:0,100)
RandomBlock(-7,5,-7,contenttweaker:reinforced_concrete,30,quark:limestone_wall,10,contenttweaker:reinforced_concrete,100)
RandomBlock(-7,6,-7,contenttweaker:reinforced_concrete,30,quark:limestone_wall,10,contenttweaker:reinforced_concrete,100)
RandomBlock(-7,7,-7,contenttweaker:reinforced_concrete,30,quark:limestone_wall,10,contenttweaker:reinforced_concrete,100)
Block(-7,8,-7,inspirations:redstone_barrel)
Block(-7,9,-7,inspirations:redstone_barrel)
RandomBlock(-7,10,-7,contenttweaker:reinforced_concrete,30,quark:limestone_wall,10,contenttweaker:reinforced_concrete,100)
RandomBlock(-7,11,-7,contenttweaker:reinforced_concrete,30,quark:limestone_wall,10,contenttweaker:reinforced_concrete,100)
RandomBlock(-6,0,-7,contenttweaker:reinforced_concrete,40,SMOOTH_BRICK:1,30,SMOOTH_BRICK:2,30,SMOOTH_STAIRS:0,15,SMOOTH_STAIRS:1,15,SMOOTH_STAIRS:2,15,SMOOTH_STAIRS:3,15,STEP:5,15,STEP:13,15,COBBLE_WALL:0,10,COBBLESTONE_STAIRS:0,10,STEP:3,10,COBBLE_WALL:1,20,COBBLESTONE_STAIRS:2,20,COBBLESTONE_STAIRS:3,20,MOSSY_COBBLESTONE:0,60,COBBLESTONE_STAIRS:1,20,STEP:11,20,COBBLESTONE:0,100)
RandomBlock(-6,0,-6,contenttweaker:reinforced_concrete,40,SMOOTH_BRICK:1,30,SMOOTH_BRICK:2,30,SMOOTH_STAIRS:0,15,SMOOTH_STAIRS:1,15,SMOOTH_STAIRS:2,15,SMOOTH_STAIRS:3,15,STEP:5,15,STEP:13,15,COBBLE_WALL:0,10,COBBLESTONE_STAIRS:0,10,STEP:3,10,COBBLE_WALL:1,20,COBBLESTONE_STAIRS:2,20,COBBLESTONE_STAIRS:3,20,MOSSY_COBBLESTONE:0,60,COBBLESTONE_STAIRS:1,20,STEP:11,20,COBBLESTONE:0,100)
RandomBlock(-6,0,-5,contenttweaker:reinforced_concrete,40,SMOOTH_BRICK:1,30,SMOOTH_BRICK:2,30,SMOOTH_STAIRS:0,15,SMOOTH_STAIRS:1,15,SMOOTH_STAIRS:2,15,SMOOTH_STAIRS:3,15,STEP:5,15,STEP:13,15,COBBLE_WALL:0,10,COBBLESTONE_STAIRS:0,10,STEP:3,10,COBBLE_WALL:1,20,COBBLESTONE_STAIRS:2,20,COBBLESTONE_STAIRS:3,20,MOSSY_COBBLESTONE:0,60,COBBLESTONE_STAIRS:1,20,STEP:11,20,COBBLESTONE:0,100)
RandomBlock(-6,1,-7,contenttweaker:reinforced_concrete,40,SMOOTH_BRICK:1,30,SMOOTH_BRICK:2,30,SMOOTH_STAIRS:0,15,SMOOTH_STAIRS:1,15,SMOOTH_STAIRS:2,15,SMOOTH_STAIRS:3,15,STEP:5,15,STEP:13,15,COBBLE_WALL:0,10,COBBLESTONE_STAIRS:0,10,STEP:3,10,COBBLE_WALL:1,20,COBBLESTONE_STAIRS:2,20,COBBLESTONE_STAIRS:3,20,MOSSY_COBBLESTONE:0,60,COBBLESTONE_STAIRS:1,20,STEP:11,20,COBBLESTONE:0,100)
RandomBlock(-6,1,-6,contenttweaker:reinforced_concrete,40,SMOOTH_BRICK:1,30,SMOOTH_BRICK:2,30,SMOOTH_STAIRS:0,15,SMOOTH_STAIRS:1,15,SMOOTH_STAIRS:2,15,SMOOTH_STAIRS:3,15,STEP:5,15,STEP:13,15,COBBLE_WALL:0,10,COBBLESTONE_STAIRS:0,10,STEP:3,10,COBBLE_WALL:1,20,COBBLESTONE_STAIRS:2,20,COBBLESTONE_STAIRS:3,20,MOSSY_COBBLESTONE:0,60,COBBLESTONE_STAIRS:1,20,STEP:11,20,COBBLESTONE:0,100)
RandomBlock(-6,1,-5,contenttweaker:reinforced_concrete,40,SMOOTH_BRICK:1,30,SMOOTH_BRICK:2,30,SMOOTH_STAIRS:0,15,SMOOTH_STAIRS:1,15,SMOOTH_STAIRS:2,15,SMOOTH_STAIRS:3,15,STEP:5,15,STEP:13,15,COBBLE_WALL:0,10,COBBLESTONE_STAIRS:0,10,STEP:3,10,COBBLE_WALL:1,20,COBBLESTONE_STAIRS:2,20,COBBLESTONE_STAIRS:3,20,MOSSY_COBBLESTONE:0,60,COBBLESTONE_STAIRS:1,20,STEP:11,20,COBBLESTONE:0,100)
RandomBlock(-6,2,-7,contenttweaker:reinforced_concrete,40,SMOOTH_BRICK:1,30,SMOOTH_BRICK:2,30,SMOOTH_STAIRS:0,15,SMOOTH_STAIRS:1,15,SMOOTH_STAIRS:2,15,SMOOTH_STAIRS:3,15,STEP:5,15,STEP:13,15,COBBLE_WALL:0,10,COBBLESTONE_STAIRS:0,10,STEP:3,10,COBBLE_WALL:1,20,COBBLESTONE_STAIRS:2,20,COBBLESTONE_STAIRS:3,20,MOSSY_COBBLESTONE:0,60,COBBLESTONE_STAIRS:1,20,STEP:11,20,COBBLESTONE:0,100)
RandomBlock(-6,2,-6,contenttweaker:reinforced_concrete,40,SMOOTH_BRICK:1,30,SMOOTH_BRICK:2,30,SMOOTH_STAIRS:0,15,SMOOTH_STAIRS:1,15,SMOOTH_STAIRS:2,15,SMOOTH_STAIRS:3,15,STEP:5,15,STEP:13,15,COBBLE_WALL:0,10,COBBLESTONE_STAIRS:0,10,STEP:3,10,COBBLE_WALL:1,20,COBBLESTONE_STAIRS:2,20,COBBLESTONE_STAIRS:3,20,MOSSY_COBBLESTONE:0,60,COBBLESTONE_STAIRS:1,20,STEP:11,20,COBBLESTONE:0,100)
RandomBlock(-6,2,-5,contenttweaker:reinforced_concrete,40,SMOOTH_BRICK:1,30,SMOOTH_BRICK:2,30,SMOOTH_STAIRS:0,15,SMOOTH_STAIRS:1,15,SMOOTH_STAIRS:2,15,SMOOTH_STAIRS:3,15,STEP:5,15,STEP:13,15,COBBLE_WALL:0,10,COBBLESTONE_STAIRS:0,10,STEP:3,10,COBBLE_WALL:1,20,COBBLESTONE_STAIRS:2,20,COBBLESTONE_STAIRS:3,20,MOSSY_COBBLESTONE:0,60,COBBLESTONE_STAIRS:1,20,STEP:11,20,COBBLESTONE:0,100)
RandomBlock(-6,3,-7,contenttweaker:reinforced_concrete,40,SMOOTH_BRICK:1,30,SMOOTH_BRICK:2,30,SMOOTH_STAIRS:0,15,SMOOTH_STAIRS:1,15,SMOOTH_STAIRS:2,15,SMOOTH_STAIRS:3,15,STEP:5,15,STEP:13,15,COBBLE_WALL:0,10,COBBLESTONE_STAIRS:0,10,STEP:3,10,COBBLE_WALL:1,20,COBBLESTONE_STAIRS:2,20,COBBLESTONE_STAIRS:3,20,MOSSY_COBBLESTONE:0,60,COBBLESTONE_STAIRS:1,20,STEP:11,20,COBBLESTONE:0,100)
RandomBlock(-6,3,-6,contenttweaker:reinforced_concrete,40,SMOOTH_BRICK:1,30,SMOOTH_BRICK:2,30,SMOOTH_STAIRS:0,15,SMOOTH_STAIRS:1,15,SMOOTH_STAIRS:2,15,SMOOTH_STAIRS:3,15,STEP:5,15,STEP:13,15,COBBLE_WALL:0,10,COBBLESTONE_STAIRS:0,10,STEP:3,10,COBBLE_WALL:1,20,COBBLESTONE_STAIRS:2,20,COBBLESTONE_STAIRS:3,20,MOSSY_COBBLESTONE:0,60,COBBLESTONE_STAIRS:1,20,STEP:11,20,COBBLESTONE:0,100)
RandomBlock(-6,3,-5,contenttweaker:reinforced_concrete,40,SMOOTH_BRICK:1,30,SMOOTH_BRICK:2,30,SMOOTH_STAIRS:0,15,SMOOTH_STAIRS:1,15,SMOOTH_STAIRS:2,15,SMOOTH_STAIRS:3,15,STEP:5,15,STEP:13,15,COBBLE_WALL:0,10,COBBLESTONE_STAIRS:0,10,STEP:3,10,COBBLE_WALL:1,20,COBBLESTONE_STAIRS:2,20,COBBLESTONE_STAIRS:3,20,MOSSY_COBBLESTONE:0,60,COBBLESTONE_STAIRS:1,20,STEP:11,20,COBBLESTONE:0,100)
RandomBlock(-6,4,-7,contenttweaker:reinforced_concrete,40,SMOOTH_BRICK:1,30,SMOOTH_BRICK:2,30,SMOOTH_STAIRS:0,15,SMOOTH_STAIRS:1,15,SMOOTH_STAIRS:2,15,SMOOTH_STAIRS:3,15,STEP:5,15,STEP:13,15,COBBLE_WALL:0,10,COBBLESTONE_STAIRS:0,10,STEP:3,10,COBBLE_WALL:1,20,COBBLESTONE_STAIRS:2,20,COBBLESTONE_STAIRS:3,20,MOSSY_COBBLESTONE:0,60,COBBLESTONE_STAIRS:1,20,STEP:11,20,COBBLESTONE:0,100)
RandomBlock(-6,4,-6,contenttweaker:reinforced_concrete,40,SMOOTH_BRICK:1,30,SMOOTH_BRICK:2,30,SMOOTH_STAIRS:0,15,SMOOTH_STAIRS:1,15,SMOOTH_STAIRS:2,15,SMOOTH_STAIRS:3,15,STEP:5,15,STEP:13,15,COBBLE_WALL:0,10,COBBLESTONE_STAIRS:0,10,STEP:3,10,COBBLE_WALL:1,20,COBBLESTONE_STAIRS:2,20,COBBLESTONE_STAIRS:3,20,MOSSY_COBBLESTONE:0,60,COBBLESTONE_STAIRS:1,20,STEP:11,20,COBBLESTONE:0,100)
RandomBlock(-6,4,-5,contenttweaker:reinforced_concrete,40,SMOOTH_BRICK:1,30,SMOOTH_BRICK:2,30,SMOOTH_STAIRS:0,15,SMOOTH_STAIRS:1,15,SMOOTH_STAIRS:2,15,SMOOTH_STAIRS:3,15,STEP:5,15,STEP:13,15,COBBLE_WALL:0,10,COBBLESTONE_STAIRS:0,10,STEP:3,10,COBBLE_WALL:1,20,COBBLESTONE_STAIRS:2,20,COBBLESTONE_STAIRS:3,20,MOSSY_COBBLESTONE:0,60,COBBLESTONE_STAIRS:1,20,STEP:11,20,COBBLESTONE:0,100)
RandomBlock(-6,5,-7,contenttweaker:reinforced_concrete,40,SMOOTH_BRICK:1,30,SMOOTH_BRICK:2,30,SMOOTH_STAIRS:0,15,SMOOTH_STAIRS:1,15,SMOOTH_STAIRS:2,15,SMOOTH_STAIRS:3,15,STEP:5,15,STEP:13,15,COBBLE_WALL:0,10,COBBLESTONE_STAIRS:0,10,STEP:3,10,COBBLE_WALL:1,20,COBBLESTONE_STAIRS:2,20,COBBLESTONE_STAIRS:3,20,MOSSY_COBBLESTONE:0,60,COBBLESTONE_STAIRS:1,20,STEP:11,20,COBBLESTONE:0,100)
RandomBlock(-6,5,-6,contenttweaker:reinforced_concrete,30,quark:limestone_wall,10,contenttweaker:reinforced_concrete,100)
RandomBlock(-6,5,-5,contenttweaker:reinforced_concrete,30,quark:limestone_wall,10,contenttweaker:reinforced_concrete,100)
RandomBlock(-6,6,-7,contenttweaker:reinforced_concrete,40,SMOOTH_BRICK:1,30,SMOOTH_BRICK:2,30,SMOOTH_STAIRS:0,15,SMOOTH_STAIRS:1,15,SMOOTH_STAIRS:2,15,SMOOTH_STAIRS:3,15,STEP:5,15,STEP:13,15,COBBLE_WALL:0,10,COBBLESTONE_STAIRS:0,10,STEP:3,10,COBBLE_WALL:1,20,COBBLESTONE_STAIRS:2,20,COBBLESTONE_STAIRS:3,20,MOSSY_COBBLESTONE:0,60,COBBLESTONE_STAIRS:1,20,STEP:11,20,COBBLESTONE:0,100)
RandomBlock(-6,6,-6,contenttweaker:reinforced_concrete,30,quark:limestone_wall,10,contenttweaker:reinforced_concrete,100)
RandomBlock(-6,6,-5,contenttweaker:reinforced_concrete,30,quark:limestone_wall,10,contenttweaker:reinforced_concrete,100)
RandomBlock(-6,7,-7,contenttweaker:reinforced_concrete,40,SMOOTH_BRICK:1,30,SMOOTH_BRICK:2,30,SMOOTH_STAIRS:0,15,SMOOTH_STAIRS:1,15,SMOOTH_STAIRS:2,15,SMOOTH_STAIRS:3,15,STEP:5,15,STEP:13,15,COBBLE_WALL:0,10,COBBLESTONE_STAIRS:0,10,STEP:3,10,COBBLE_WALL:1,20,COBBLESTONE_STAIRS:2,20,COBBLESTONE_STAIRS:3,20,MOSSY_COBBLESTONE:0,60,COBBLESTONE_STAIRS:1,20,STEP:11,20,COBBLESTONE:0,100)
RandomBlock(-6,7,-6,contenttweaker:reinforced_concrete,30,quark:limestone_wall,10,contenttweaker:reinforced_concrete,100)
RandomBlock(-6,7,-5,contenttweaker:reinforced_concrete,30,quark:limestone_wall,10,contenttweaker:reinforced_concrete,100)
RandomBlock(-6,8,-7,RUSTIC:IRON_LATTICE:0,30,RUSTIC:IRON_LATTICE:1,100)
Block(-6,8,-5,inspirations:redstone_barrel)
RandomBlock(-6,9,-7,RUSTIC:IRON_LATTICE:0,30,RUSTIC:IRON_LATTICE:1,100)
Block(-6,9,-5,inspirations:redstone_barrel)
RandomBlock(-6,10,-7,RUSTIC:IRON_LATTICE:0,30,RUSTIC:IRON_LATTICE:1,100)
RandomBlock(-6,10,-6,contenttweaker:reinforced_concrete,30,quark:limestone_wall,10,contenttweaker:reinforced_concrete,100)
RandomBlock(-6,10,-5,contenttweaker:reinforced_concrete,30,quark:limestone_wall,10,contenttweaker:reinforced_concrete,100)
RandomBlock(-6,11,-6,contenttweaker:reinforced_concrete,30,quark:limestone_wall,10,contenttweaker:reinforced_concrete,100)
RandomBlock(-6,11,-5,contenttweaker:reinforced_concrete,30,quark:limestone_wall,10,contenttweaker:reinforced_concrete,100)
RandomBlock(-6,12,-7,contenttweaker:reinforced_concrete,30,quark:limestone_wall,10,contenttweaker:reinforced_concrete,100)
Block(-6,12,-6,VINE:4)
RandomBlock(-6,13,-7,contenttweaker:reinforced_concrete,30,quark:limestone_wall,10,contenttweaker:reinforced_concrete,100)
Block(-6,13,-6,VINE:4)
Block(-6,22,-7,VINE:4)
Block(-6,23,-7,VINE:4)
Block(-6,24,-7,VINE:4)
Block(-6,25,-7,VINE:4)
Block(-6,26,-7,VINE:4)
RandomBlock(-5,0,-7,contenttweaker:reinforced_concrete,40,SMOOTH_BRICK:1,30,SMOOTH_BRICK:2,30,SMOOTH_STAIRS:0,15,SMOOTH_STAIRS:1,15,SMOOTH_STAIRS:2,15,SMOOTH_STAIRS:3,15,STEP:5,15,STEP:13,15,COBBLE_WALL:0,10,COBBLESTONE_STAIRS:0,10,STEP:3,10,COBBLE_WALL:1,20,COBBLESTONE_STAIRS:2,20,COBBLESTONE_STAIRS:3,20,MOSSY_COBBLESTONE:0,60,COBBLESTONE_STAIRS:1,20,STEP:11,20,COBBLESTONE:0,100)
RandomBlock(-5,0,-6,contenttweaker:reinforced_concrete,40,SMOOTH_BRICK:1,30,SMOOTH_BRICK:2,30,SMOOTH_STAIRS:0,15,SMOOTH_STAIRS:1,15,SMOOTH_STAIRS:2,15,SMOOTH_STAIRS:3,15,STEP:5,15,STEP:13,15,COBBLE_WALL:0,10,COBBLESTONE_STAIRS:0,10,STEP:3,10,COBBLE_WALL:1,20,COBBLESTONE_STAIRS:2,20,COBBLESTONE_STAIRS:3,20,MOSSY_COBBLESTONE:0,60,COBBLESTONE_STAIRS:1,20,STEP:11,20,COBBLESTONE:0,100)
RandomBlock(-5,0,-5,contenttweaker:reinforced_concrete,40,SMOOTH_BRICK:1,30,SMOOTH_BRICK:2,30,SMOOTH_STAIRS:0,15,SMOOTH_STAIRS:1,15,SMOOTH_STAIRS:2,15,SMOOTH_STAIRS:3,15,STEP:5,15,STEP:13,15,COBBLE_WALL:0,10,COBBLESTONE_STAIRS:0,10,STEP:3,10,COBBLE_WALL:1,20,COBBLESTONE_STAIRS:2,20,COBBLESTONE_STAIRS:3,20,MOSSY_COBBLESTONE:0,60,COBBLESTONE_STAIRS:1,20,STEP:11,20,COBBLESTONE:0,100)
RandomBlock(-5,0,-4,contenttweaker:reinforced_concrete,40,SMOOTH_BRICK:1,30,SMOOTH_BRICK:2,30,SMOOTH_STAIRS:0,15,SMOOTH_STAIRS:1,15,SMOOTH_STAIRS:2,15,SMOOTH_STAIRS:3,15,STEP:5,15,STEP:13,15,COBBLE_WALL:0,10,COBBLESTONE_STAIRS:0,10,STEP:3,10,COBBLE_WALL:1,20,COBBLESTONE_STAIRS:2,20,COBBLESTONE_STAIRS:3,20,MOSSY_COBBLESTONE:0,60,COBBLESTONE_STAIRS:1,20,STEP:11,20,COBBLESTONE:0,100)
RandomBlock(-5,1,-7,contenttweaker:reinforced_concrete,40,SMOOTH_BRICK:1,30,SMOOTH_BRICK:2,30,SMOOTH_STAIRS:0,15,SMOOTH_STAIRS:1,15,SMOOTH_STAIRS:2,15,SMOOTH_STAIRS:3,15,STEP:5,15,STEP:13,15,COBBLE_WALL:0,10,COBBLESTONE_STAIRS:0,10,STEP:3,10,COBBLE_WALL:1,20,COBBLESTONE_STAIRS:2,20,COBBLESTONE_STAIRS:3,20,MOSSY_COBBLESTONE:0,60,COBBLESTONE_STAIRS:1,20,STEP:11,20,COBBLESTONE:0,100)
RandomBlock(-5,1,-6,contenttweaker:reinforced_concrete,40,SMOOTH_BRICK:1,30,SMOOTH_BRICK:2,30,SMOOTH_STAIRS:0,15,SMOOTH_STAIRS:1,15,SMOOTH_STAIRS:2,15,SMOOTH_STAIRS:3,15,STEP:5,15,STEP:13,15,COBBLE_WALL:0,10,COBBLESTONE_STAIRS:0,10,STEP:3,10,COBBLE_WALL:1,20,COBBLESTONE_STAIRS:2,20,COBBLESTONE_STAIRS:3,20,MOSSY_COBBLESTONE:0,60,COBBLESTONE_STAIRS:1,20,STEP:11,20,COBBLESTONE:0,100)
RandomBlock(-5,1,-5,contenttweaker:reinforced_concrete,40,SMOOTH_BRICK:1,30,SMOOTH_BRICK:2,30,SMOOTH_STAIRS:0,15,SMOOTH_STAIRS:1,15,SMOOTH_STAIRS:2,15,SMOOTH_STAIRS:3,15,STEP:5,15,STEP:13,15,COBBLE_WALL:0,10,COBBLESTONE_STAIRS:0,10,STEP:3,10,COBBLE_WALL:1,20,COBBLESTONE_STAIRS:2,20,COBBLESTONE_STAIRS:3,20,MOSSY_COBBLESTONE:0,60,COBBLESTONE_STAIRS:1,20,STEP:11,20,COBBLESTONE:0,100)
RandomBlock(-5,1,-4,contenttweaker:reinforced_concrete,40,SMOOTH_BRICK:1,30,SMOOTH_BRICK:2,30,SMOOTH_STAIRS:0,15,SMOOTH_STAIRS:1,15,SMOOTH_STAIRS:2,15,SMOOTH_STAIRS:3,15,STEP:5,15,STEP:13,15,COBBLE_WALL:0,10,COBBLESTONE_STAIRS:0,10,STEP:3,10,COBBLE_WALL:1,20,COBBLESTONE_STAIRS:2,20,COBBLESTONE_STAIRS:3,20,MOSSY_COBBLESTONE:0,60,COBBLESTONE_STAIRS:1,20,STEP:11,20,COBBLESTONE:0,100)
RandomBlock(-5,2,-7,contenttweaker:reinforced_concrete,40,SMOOTH_BRICK:1,30,SMOOTH_BRICK:2,30,SMOOTH_STAIRS:0,15,SMOOTH_STAIRS:1,15,SMOOTH_STAIRS:2,15,SMOOTH_STAIRS:3,15,STEP:5,15,STEP:13,15,COBBLE_WALL:0,10,COBBLESTONE_STAIRS:0,10,STEP:3,10,COBBLE_WALL:1,20,COBBLESTONE_STAIRS:2,20,COBBLESTONE_STAIRS:3,20,MOSSY_COBBLESTONE:0,60,COBBLESTONE_STAIRS:1,20,STEP:11,20,COBBLESTONE:0,100)
RandomBlock(-5,2,-6,contenttweaker:reinforced_concrete,40,SMOOTH_BRICK:1,30,SMOOTH_BRICK:2,30,SMOOTH_STAIRS:0,15,SMOOTH_STAIRS:1,15,SMOOTH_STAIRS:2,15,SMOOTH_STAIRS:3,15,STEP:5,15,STEP:13,15,COBBLE_WALL:0,10,COBBLESTONE_STAIRS:0,10,STEP:3,10,COBBLE_WALL:1,20,COBBLESTONE_STAIRS:2,20,COBBLESTONE_STAIRS:3,20,MOSSY_COBBLESTONE:0,60,COBBLESTONE_STAIRS:1,20,STEP:11,20,COBBLESTONE:0,100)
RandomBlock(-5,2,-5,contenttweaker:reinforced_concrete,40,SMOOTH_BRICK:1,30,SMOOTH_BRICK:2,30,SMOOTH_STAIRS:0,15,SMOOTH_STAIRS:1,15,SMOOTH_STAIRS:2,15,SMOOTH_STAIRS:3,15,STEP:5,15,STEP:13,15,COBBLE_WALL:0,10,COBBLESTONE_STAIRS:0,10,STEP:3,10,COBBLE_WALL:1,20,COBBLESTONE_STAIRS:2,20,COBBLESTONE_STAIRS:3,20,MOSSY_COBBLESTONE:0,60,COBBLESTONE_STAIRS:1,20,STEP:11,20,COBBLESTONE:0,100)
RandomBlock(-5,2,-4,contenttweaker:reinforced_concrete,40,SMOOTH_BRICK:1,30,SMOOTH_BRICK:2,30,SMOOTH_STAIRS:0,15,SMOOTH_STAIRS:1,15,SMOOTH_STAIRS:2,15,SMOOTH_STAIRS:3,15,STEP:5,15,STEP:13,15,COBBLE_WALL:0,10,COBBLESTONE_STAIRS:0,10,STEP:3,10,COBBLE_WALL:1,20,COBBLESTONE_STAIRS:2,20,COBBLESTONE_STAIRS:3,20,MOSSY_COBBLESTONE:0,60,COBBLESTONE_STAIRS:1,20,STEP:11,20,COBBLESTONE:0,100)
RandomBlock(-5,3,-7,contenttweaker:reinforced_concrete,40,SMOOTH_BRICK:1,30,SMOOTH_BRICK:2,30,SMOOTH_STAIRS:0,15,SMOOTH_STAIRS:1,15,SMOOTH_STAIRS:2,15,SMOOTH_STAIRS:3,15,STEP:5,15,STEP:13,15,COBBLE_WALL:0,10,COBBLESTONE_STAIRS:0,10,STEP:3,10,COBBLE_WALL:1,20,COBBLESTONE_STAIRS:2,20,COBBLESTONE_STAIRS:3,20,MOSSY_COBBLESTONE:0,60,COBBLESTONE_STAIRS:1,20,STEP:11,20,COBBLESTONE:0,100)
RandomBlock(-5,3,-6,contenttweaker:reinforced_concrete,40,SMOOTH_BRICK:1,30,SMOOTH_BRICK:2,30,SMOOTH_STAIRS:0,15,SMOOTH_STAIRS:1,15,SMOOTH_STAIRS:2,15,SMOOTH_STAIRS:3,15,STEP:5,15,STEP:13,15,COBBLE_WALL:0,10,COBBLESTONE_STAIRS:0,10,STEP:3,10,COBBLE_WALL:1,20,COBBLESTONE_STAIRS:2,20,COBBLESTONE_STAIRS:3,20,MOSSY_COBBLESTONE:0,60,COBBLESTONE_STAIRS:1,20,STEP:11,20,COBBLESTONE:0,100)
RandomBlock(-5,3,-5,contenttweaker:reinforced_concrete,40,SMOOTH_BRICK:1,30,SMOOTH_BRICK:2,30,SMOOTH_STAIRS:0,15,SMOOTH_STAIRS:1,15,SMOOTH_STAIRS:2,15,SMOOTH_STAIRS:3,15,STEP:5,15,STEP:13,15,COBBLE_WALL:0,10,COBBLESTONE_STAIRS:0,10,STEP:3,10,COBBLE_WALL:1,20,COBBLESTONE_STAIRS:2,20,COBBLESTONE_STAIRS:3,20,MOSSY_COBBLESTONE:0,60,COBBLESTONE_STAIRS:1,20,STEP:11,20,COBBLESTONE:0,100)
RandomBlock(-5,3,-4,contenttweaker:reinforced_concrete,40,SMOOTH_BRICK:1,30,SMOOTH_BRICK:2,30,SMOOTH_STAIRS:0,15,SMOOTH_STAIRS:1,15,SMOOTH_STAIRS:2,15,SMOOTH_STAIRS:3,15,STEP:5,15,STEP:13,15,COBBLE_WALL:0,10,COBBLESTONE_STAIRS:0,10,STEP:3,10,COBBLE_WALL:1,20,COBBLESTONE_STAIRS:2,20,COBBLESTONE_STAIRS:3,20,MOSSY_COBBLESTONE:0,60,COBBLESTONE_STAIRS:1,20,STEP:11,20,COBBLESTONE:0,100)
RandomBlock(-5,4,-7,contenttweaker:reinforced_concrete,40,SMOOTH_BRICK:1,30,SMOOTH_BRICK:2,30,SMOOTH_STAIRS:0,15,SMOOTH_STAIRS:1,15,SMOOTH_STAIRS:2,15,SMOOTH_STAIRS:3,15,STEP:5,15,STEP:13,15,COBBLE_WALL:0,10,COBBLESTONE_STAIRS:0,10,STEP:3,10,COBBLE_WALL:1,20,COBBLESTONE_STAIRS:2,20,COBBLESTONE_STAIRS:3,20,MOSSY_COBBLESTONE:0,60,COBBLESTONE_STAIRS:1,20,STEP:11,20,COBBLESTONE:0,100)
RandomBlock(-5,4,-6,contenttweaker:reinforced_concrete,40,SMOOTH_BRICK:1,30,SMOOTH_BRICK:2,30,SMOOTH_STAIRS:0,15,SMOOTH_STAIRS:1,15,SMOOTH_STAIRS:2,15,SMOOTH_STAIRS:3,15,STEP:5,15,STEP:13,15,COBBLE_WALL:0,10,COBBLESTONE_STAIRS:0,10,STEP:3,10,COBBLE_WALL:1,20,COBBLESTONE_STAIRS:2,20,COBBLESTONE_STAIRS:3,20,MOSSY_COBBLESTONE:0,60,COBBLESTONE_STAIRS:1,20,STEP:11,20,COBBLESTONE:0,100)
RandomBlock(-5,4,-5,contenttweaker:reinforced_concrete,40,SMOOTH_BRICK:1,30,SMOOTH_BRICK:2,30,SMOOTH_STAIRS:0,15,SMOOTH_STAIRS:1,15,SMOOTH_STAIRS:2,15,SMOOTH_STAIRS:3,15,STEP:5,15,STEP:13,15,COBBLE_WALL:0,10,COBBLESTONE_STAIRS:0,10,STEP:3,10,COBBLE_WALL:1,20,COBBLESTONE_STAIRS:2,20,COBBLESTONE_STAIRS:3,20,MOSSY_COBBLESTONE:0,60,COBBLESTONE_STAIRS:1,20,STEP:11,20,COBBLESTONE:0,100)
RandomBlock(-5,4,-4,contenttweaker:reinforced_concrete,40,SMOOTH_BRICK:1,30,SMOOTH_BRICK:2,30,SMOOTH_STAIRS:0,15,SMOOTH_STAIRS:1,15,SMOOTH_STAIRS:2,15,SMOOTH_STAIRS:3,15,STEP:5,15,STEP:13,15,COBBLE_WALL:0,10,COBBLESTONE_STAIRS:0,10,STEP:3,10,COBBLE_WALL:1,20,COBBLESTONE_STAIRS:2,20,COBBLESTONE_STAIRS:3,20,MOSSY_COBBLESTONE:0,60,COBBLESTONE_STAIRS:1,20,STEP:11,20,COBBLESTONE:0,100)
RandomBlock(-5,5,-7,contenttweaker:reinforced_concrete,40,SMOOTH_BRICK:1,30,SMOOTH_BRICK:2,30,SMOOTH_STAIRS:0,15,SMOOTH_STAIRS:1,15,SMOOTH_STAIRS:2,15,SMOOTH_STAIRS:3,15,STEP:5,15,STEP:13,15,COBBLE_WALL:0,10,COBBLESTONE_STAIRS:0,10,STEP:3,10,COBBLE_WALL:1,20,COBBLESTONE_STAIRS:2,20,COBBLESTONE_STAIRS:3,20,MOSSY_COBBLESTONE:0,60,COBBLESTONE_STAIRS:1,20,STEP:11,20,COBBLESTONE:0,100)
RandomBlock(-5,5,-6,contenttweaker:reinforced_concrete,40,SMOOTH_BRICK:1,30,SMOOTH_BRICK:2,30,SMOOTH_STAIRS:0,15,SMOOTH_STAIRS:1,15,SMOOTH_STAIRS:2,15,SMOOTH_STAIRS:3,15,STEP:5,15,STEP:13,15,COBBLE_WALL:0,10,COBBLESTONE_STAIRS:0,10,STEP:3,10,COBBLE_WALL:1,20,COBBLESTONE_STAIRS:2,20,COBBLESTONE_STAIRS:3,20,MOSSY_COBBLESTONE:0,60,COBBLESTONE_STAIRS:1,20,STEP:11,20,COBBLESTONE:0,100)
RandomBlock(-5,5,-5,contenttweaker:reinforced_concrete,40,SMOOTH_BRICK:1,30,SMOOTH_BRICK:2,30,SMOOTH_STAIRS:0,15,SMOOTH_STAIRS:1,15,SMOOTH_STAIRS:2,15,SMOOTH_STAIRS:3,15,STEP:5,15,STEP:13,15,COBBLE_WALL:0,10,COBBLESTONE_STAIRS:0,10,STEP:3,10,COBBLE_WALL:1,20,COBBLESTONE_STAIRS:2,20,COBBLESTONE_STAIRS:3,20,MOSSY_COBBLESTONE:0,60,COBBLESTONE_STAIRS:1,20,STEP:11,20,COBBLESTONE:0,100)
RandomBlock(-5,5,-4,contenttweaker:reinforced_concrete,30,quark:limestone_wall,10,contenttweaker:reinforced_concrete,100)
RandomBlock(-5,6,-7,contenttweaker:reinforced_concrete,40,SMOOTH_BRICK:1,30,SMOOTH_BRICK:2,30,SMOOTH_STAIRS:0,15,SMOOTH_STAIRS:1,15,SMOOTH_STAIRS:2,15,SMOOTH_STAIRS:3,15,STEP:5,15,STEP:13,15,COBBLE_WALL:0,10,COBBLESTONE_STAIRS:0,10,STEP:3,10,COBBLE_WALL:1,20,COBBLESTONE_STAIRS:2,20,COBBLESTONE_STAIRS:3,20,MOSSY_COBBLESTONE:0,60,COBBLESTONE_STAIRS:1,20,STEP:11,20,COBBLESTONE:0,100)
RandomBlock(-5,6,-6,contenttweaker:reinforced_concrete,40,SMOOTH_BRICK:1,30,SMOOTH_BRICK:2,30,SMOOTH_STAIRS:0,15,SMOOTH_STAIRS:1,15,SMOOTH_STAIRS:2,15,SMOOTH_STAIRS:3,15,STEP:5,15,STEP:13,15,COBBLE_WALL:0,10,COBBLESTONE_STAIRS:0,10,STEP:3,10,COBBLE_WALL:1,20,COBBLESTONE_STAIRS:2,20,COBBLESTONE_STAIRS:3,20,MOSSY_COBBLESTONE:0,60,COBBLESTONE_STAIRS:1,20,STEP:11,20,COBBLESTONE:0,100)
RandomBlock(-5,6,-5,contenttweaker:reinforced_concrete,40,SMOOTH_BRICK:1,30,SMOOTH_BRICK:2,30,SMOOTH_STAIRS:0,15,SMOOTH_STAIRS:1,15,SMOOTH_STAIRS:2,15,SMOOTH_STAIRS:3,15,STEP:5,15,STEP:13,15,COBBLE_WALL:0,10,COBBLESTONE_STAIRS:0,10,STEP:3,10,COBBLE_WALL:1,20,COBBLESTONE_STAIRS:2,20,COBBLESTONE_STAIRS:3,20,MOSSY_COBBLESTONE:0,60,COBBLESTONE_STAIRS:1,20,STEP:11,20,COBBLESTONE:0,100)
RandomBlock(-5,6,-4,contenttweaker:reinforced_concrete,30,quark:limestone_wall,10,contenttweaker:reinforced_concrete,100)
RandomBlock(-5,7,-7,contenttweaker:reinforced_concrete,40,SMOOTH_BRICK:1,30,SMOOTH_BRICK:2,30,SMOOTH_STAIRS:0,15,SMOOTH_STAIRS:1,15,SMOOTH_STAIRS:2,15,SMOOTH_STAIRS:3,15,STEP:5,15,STEP:13,15,COBBLE_WALL:0,10,COBBLESTONE_STAIRS:0,10,STEP:3,10,COBBLE_WALL:1,20,COBBLESTONE_STAIRS:2,20,COBBLESTONE_STAIRS:3,20,MOSSY_COBBLESTONE:0,60,COBBLESTONE_STAIRS:1,20,STEP:11,20,COBBLESTONE:0,100)
RandomBlock(-5,7,-6,contenttweaker:reinforced_concrete,40,SMOOTH_BRICK:1,30,SMOOTH_BRICK:2,30,SMOOTH_STAIRS:0,15,SMOOTH_STAIRS:1,15,SMOOTH_STAIRS:2,15,SMOOTH_STAIRS:3,15,STEP:5,15,STEP:13,15,COBBLE_WALL:0,10,COBBLESTONE_STAIRS:0,10,STEP:3,10,COBBLE_WALL:1,20,COBBLESTONE_STAIRS:2,20,COBBLESTONE_STAIRS:3,20,MOSSY_COBBLESTONE:0,60,COBBLESTONE_STAIRS:1,20,STEP:11,20,COBBLESTONE:0,100)
RandomBlock(-5,7,-5,contenttweaker:reinforced_concrete,40,SMOOTH_BRICK:1,30,SMOOTH_BRICK:2,30,SMOOTH_STAIRS:0,15,SMOOTH_STAIRS:1,15,SMOOTH_STAIRS:2,15,SMOOTH_STAIRS:3,15,STEP:5,15,STEP:13,15,COBBLE_WALL:0,10,COBBLESTONE_STAIRS:0,10,STEP:3,10,COBBLE_WALL:1,20,COBBLESTONE_STAIRS:2,20,COBBLESTONE_STAIRS:3,20,MOSSY_COBBLESTONE:0,60,COBBLESTONE_STAIRS:1,20,STEP:11,20,COBBLESTONE:0,100)
RandomBlock(-5,7,-4,contenttweaker:reinforced_concrete,30,quark:limestone_wall,10,contenttweaker:reinforced_concrete,100)
RandomBlock(-5,8,-7,RUSTIC:IRON_LATTICE:0,30,RUSTIC:IRON_LATTICE:1,100)
RandomBlock(-5,8,-6,RUSTIC:IRON_LATTICE:0,30,RUSTIC:IRON_LATTICE:1,100)
RandomBlock(-5,8,-5,RUSTIC:IRON_LATTICE:0,30,RUSTIC:IRON_LATTICE:1,100)
RandomBlock(-5,9,-7,RUSTIC:IRON_LATTICE:0,30,RUSTIC:IRON_LATTICE:1,100)
RandomBlock(-5,9,-6,RUSTIC:IRON_LATTICE:0,30,RUSTIC:IRON_LATTICE:1,100)
RandomBlock(-5,9,-5,RUSTIC:IRON_LATTICE:0,30,RUSTIC:IRON_LATTICE:1,100)
RandomBlock(-5,10,-7,RUSTIC:IRON_LATTICE:0,30,RUSTIC:IRON_LATTICE:1,100)
RandomBlock(-5,10,-6,RUSTIC:IRON_LATTICE:0,30,RUSTIC:IRON_LATTICE:1,100)
RandomBlock(-5,10,-5,RUSTIC:IRON_LATTICE:0,30,RUSTIC:IRON_LATTICE:1,100)
RandomBlock(-5,10,-4,contenttweaker:reinforced_concrete,30,quark:limestone_wall,10,contenttweaker:reinforced_concrete,100)
RandomBlock(-5,11,-4,contenttweaker:reinforced_concrete,30,quark:limestone_wall,10,contenttweaker:reinforced_concrete,100)
RandomBlock(-5,12,-6,contenttweaker:reinforced_concrete,30,quark:limestone_wall,10,contenttweaker:reinforced_concrete,100)
RandomBlock(-5,12,-5,contenttweaker:reinforced_concrete,30,quark:limestone_wall,10,contenttweaker:reinforced_concrete,100)
RandomBlock(-5,13,-6,contenttweaker:reinforced_concrete,30,quark:limestone_wall,10,contenttweaker:reinforced_concrete,100)
RandomBlock(-5,13,-5,contenttweaker:reinforced_concrete,30,quark:limestone_wall,10,contenttweaker:reinforced_concrete,100)
RandomBlock(-5,14,-7,contenttweaker:reinforced_concrete,30,quark:limestone_wall,10,contenttweaker:reinforced_concrete,100)
RandomBlock(-5,15,-7,contenttweaker:reinforced_concrete,30,quark:limestone_wall,10,contenttweaker:reinforced_concrete,100)
RandomBlock(-5,26,-7,contenttweaker:reinforced_concrete,30,quark:limestone_wall,10,contenttweaker:reinforced_concrete,100)
RandomBlock(-4,0,-7,contenttweaker:reinforced_concrete,40,SMOOTH_BRICK:1,30,SMOOTH_BRICK:2,30,SMOOTH_STAIRS:0,15,SMOOTH_STAIRS:1,15,SMOOTH_STAIRS:2,15,SMOOTH_STAIRS:3,15,STEP:5,15,STEP:13,15,COBBLE_WALL:0,10,COBBLESTONE_STAIRS:0,10,STEP:3,10,COBBLE_WALL:1,20,COBBLESTONE_STAIRS:2,20,COBBLESTONE_STAIRS:3,20,MOSSY_COBBLESTONE:0,60,COBBLESTONE_STAIRS:1,20,STEP:11,20,COBBLESTONE:0,100)
RandomBlock(-4,0,-6,contenttweaker:reinforced_concrete,40,SMOOTH_BRICK:1,30,SMOOTH_BRICK:2,30,SMOOTH_STAIRS:0,15,SMOOTH_STAIRS:1,15,SMOOTH_STAIRS:2,15,SMOOTH_STAIRS:3,15,STEP:5,15,STEP:13,15,COBBLE_WALL:0,10,COBBLESTONE_STAIRS:0,10,STEP:3,10,COBBLE_WALL:1,20,COBBLESTONE_STAIRS:2,20,COBBLESTONE_STAIRS:3,20,MOSSY_COBBLESTONE:0,60,COBBLESTONE_STAIRS:1,20,STEP:11,20,COBBLESTONE:0,100)
RandomBlock(-4,0,-5,contenttweaker:reinforced_concrete,40,SMOOTH_BRICK:1,30,SMOOTH_BRICK:2,30,SMOOTH_STAIRS:0,15,SMOOTH_STAIRS:1,15,SMOOTH_STAIRS:2,15,SMOOTH_STAIRS:3,15,STEP:5,15,STEP:13,15,COBBLE_WALL:0,10,COBBLESTONE_STAIRS:0,10,STEP:3,10,COBBLE_WALL:1,20,COBBLESTONE_STAIRS:2,20,COBBLESTONE_STAIRS:3,20,MOSSY_COBBLESTONE:0,60,COBBLESTONE_STAIRS:1,20,STEP:11,20,COBBLESTONE:0,100)
RandomBlock(-4,0,-4,contenttweaker:reinforced_concrete,40,SMOOTH_BRICK:1,30,SMOOTH_BRICK:2,30,SMOOTH_STAIRS:0,15,SMOOTH_STAIRS:1,15,SMOOTH_STAIRS:2,15,SMOOTH_STAIRS:3,15,STEP:5,15,STEP:13,15,COBBLE_WALL:0,10,COBBLESTONE_STAIRS:0,10,STEP:3,10,COBBLE_WALL:1,20,COBBLESTONE_STAIRS:2,20,COBBLESTONE_STAIRS:3,20,MOSSY_COBBLESTONE:0,60,COBBLESTONE_STAIRS:1,20,STEP:11,20,COBBLESTONE:0,100)
RandomBlock(-4,0,-3,contenttweaker:reinforced_concrete,40,SMOOTH_BRICK:1,30,SMOOTH_BRICK:2,30,SMOOTH_STAIRS:0,15,SMOOTH_STAIRS:1,15,SMOOTH_STAIRS:2,15,SMOOTH_STAIRS:3,15,STEP:5,15,STEP:13,15,COBBLE_WALL:0,10,COBBLESTONE_STAIRS:0,10,STEP:3,10,COBBLE_WALL:1,20,COBBLESTONE_STAIRS:2,20,COBBLESTONE_STAIRS:3,20,MOSSY_COBBLESTONE:0,60,COBBLESTONE_STAIRS:1,20,STEP:11,20,COBBLESTONE:0,100)
RandomBlock(-4,1,-7,contenttweaker:reinforced_concrete,40,SMOOTH_BRICK:1,30,SMOOTH_BRICK:2,30,SMOOTH_STAIRS:0,15,SMOOTH_STAIRS:1,15,SMOOTH_STAIRS:2,15,SMOOTH_STAIRS:3,15,STEP:5,15,STEP:13,15,COBBLE_WALL:0,10,COBBLESTONE_STAIRS:0,10,STEP:3,10,COBBLE_WALL:1,20,COBBLESTONE_STAIRS:2,20,COBBLESTONE_STAIRS:3,20,MOSSY_COBBLESTONE:0,60,COBBLESTONE_STAIRS:1,20,STEP:11,20,COBBLESTONE:0,100)
RandomBlock(-4,1,-6,contenttweaker:reinforced_concrete,40,SMOOTH_BRICK:1,30,SMOOTH_BRICK:2,30,SMOOTH_STAIRS:0,15,SMOOTH_STAIRS:1,15,SMOOTH_STAIRS:2,15,SMOOTH_STAIRS:3,15,STEP:5,15,STEP:13,15,COBBLE_WALL:0,10,COBBLESTONE_STAIRS:0,10,STEP:3,10,COBBLE_WALL:1,20,COBBLESTONE_STAIRS:2,20,COBBLESTONE_STAIRS:3,20,MOSSY_COBBLESTONE:0,60,COBBLESTONE_STAIRS:1,20,STEP:11,20,COBBLESTONE:0,100)
RandomBlock(-4,1,-5,contenttweaker:reinforced_concrete,40,SMOOTH_BRICK:1,30,SMOOTH_BRICK:2,30,SMOOTH_STAIRS:0,15,SMOOTH_STAIRS:1,15,SMOOTH_STAIRS:2,15,SMOOTH_STAIRS:3,15,STEP:5,15,STEP:13,15,COBBLE_WALL:0,10,COBBLESTONE_STAIRS:0,10,STEP:3,10,COBBLE_WALL:1,20,COBBLESTONE_STAIRS:2,20,COBBLESTONE_STAIRS:3,20,MOSSY_COBBLESTONE:0,60,COBBLESTONE_STAIRS:1,20,STEP:11,20,COBBLESTONE:0,100)
RandomBlock(-4,1,-4,contenttweaker:reinforced_concrete,40,SMOOTH_BRICK:1,30,SMOOTH_BRICK:2,30,SMOOTH_STAIRS:0,15,SMOOTH_STAIRS:1,15,SMOOTH_STAIRS:2,15,SMOOTH_STAIRS:3,15,STEP:5,15,STEP:13,15,COBBLE_WALL:0,10,COBBLESTONE_STAIRS:0,10,STEP:3,10,COBBLE_WALL:1,20,COBBLESTONE_STAIRS:2,20,COBBLESTONE_STAIRS:3,20,MOSSY_COBBLESTONE:0,60,COBBLESTONE_STAIRS:1,20,STEP:11,20,COBBLESTONE:0,100)
RandomBlock(-4,1,-3,contenttweaker:reinforced_concrete,40,SMOOTH_BRICK:1,30,SMOOTH_BRICK:2,30,SMOOTH_STAIRS:0,15,SMOOTH_STAIRS:1,15,SMOOTH_STAIRS:2,15,SMOOTH_STAIRS:3,15,STEP:5,15,STEP:13,15,COBBLE_WALL:0,10,COBBLESTONE_STAIRS:0,10,STEP:3,10,COBBLE_WALL:1,20,COBBLESTONE_STAIRS:2,20,COBBLESTONE_STAIRS:3,20,MOSSY_COBBLESTONE:0,60,COBBLESTONE_STAIRS:1,20,STEP:11,20,COBBLESTONE:0,100)
RandomBlock(-4,2,-7,contenttweaker:reinforced_concrete,40,SMOOTH_BRICK:1,30,SMOOTH_BRICK:2,30,SMOOTH_STAIRS:0,15,SMOOTH_STAIRS:1,15,SMOOTH_STAIRS:2,15,SMOOTH_STAIRS:3,15,STEP:5,15,STEP:13,15,COBBLE_WALL:0,10,COBBLESTONE_STAIRS:0,10,STEP:3,10,COBBLE_WALL:1,20,COBBLESTONE_STAIRS:2,20,COBBLESTONE_STAIRS:3,20,MOSSY_COBBLESTONE:0,60,COBBLESTONE_STAIRS:1,20,STEP:11,20,COBBLESTONE:0,100)
RandomBlock(-4,2,-6,contenttweaker:reinforced_concrete,40,SMOOTH_BRICK:1,30,SMOOTH_BRICK:2,30,SMOOTH_STAIRS:0,15,SMOOTH_STAIRS:1,15,SMOOTH_STAIRS:2,15,SMOOTH_STAIRS:3,15,STEP:5,15,STEP:13,15,COBBLE_WALL:0,10,COBBLESTONE_STAIRS:0,10,STEP:3,10,COBBLE_WALL:1,20,COBBLESTONE_STAIRS:2,20,COBBLESTONE_STAIRS:3,20,MOSSY_COBBLESTONE:0,60,COBBLESTONE_STAIRS:1,20,STEP:11,20,COBBLESTONE:0,100)
RandomBlock(-4,2,-5,contenttweaker:reinforced_concrete,40,SMOOTH_BRICK:1,30,SMOOTH_BRICK:2,30,SMOOTH_STAIRS:0,15,SMOOTH_STAIRS:1,15,SMOOTH_STAIRS:2,15,SMOOTH_STAIRS:3,15,STEP:5,15,STEP:13,15,COBBLE_WALL:0,10,COBBLESTONE_STAIRS:0,10,STEP:3,10,COBBLE_WALL:1,20,COBBLESTONE_STAIRS:2,20,COBBLESTONE_STAIRS:3,20,MOSSY_COBBLESTONE:0,60,COBBLESTONE_STAIRS:1,20,STEP:11,20,COBBLESTONE:0,100)
RandomBlock(-4,2,-4,contenttweaker:reinforced_concrete,40,SMOOTH_BRICK:1,30,SMOOTH_BRICK:2,30,SMOOTH_STAIRS:0,15,SMOOTH_STAIRS:1,15,SMOOTH_STAIRS:2,15,SMOOTH_STAIRS:3,15,STEP:5,15,STEP:13,15,COBBLE_WALL:0,10,COBBLESTONE_STAIRS:0,10,STEP:3,10,COBBLE_WALL:1,20,COBBLESTONE_STAIRS:2,20,COBBLESTONE_STAIRS:3,20,MOSSY_COBBLESTONE:0,60,COBBLESTONE_STAIRS:1,20,STEP:11,20,COBBLESTONE:0,100)
RandomBlock(-4,2,-3,contenttweaker:reinforced_concrete,40,SMOOTH_BRICK:1,30,SMOOTH_BRICK:2,30,SMOOTH_STAIRS:0,15,SMOOTH_STAIRS:1,15,SMOOTH_STAIRS:2,15,SMOOTH_STAIRS:3,15,STEP:5,15,STEP:13,15,COBBLE_WALL:0,10,COBBLESTONE_STAIRS:0,10,STEP:3,10,COBBLE_WALL:1,20,COBBLESTONE_STAIRS:2,20,COBBLESTONE_STAIRS:3,20,MOSSY_COBBLESTONE:0,60,COBBLESTONE_STAIRS:1,20,STEP:11,20,COBBLESTONE:0,100)
RandomBlock(-4,3,-7,contenttweaker:reinforced_concrete,40,SMOOTH_BRICK:1,30,SMOOTH_BRICK:2,30,SMOOTH_STAIRS:0,15,SMOOTH_STAIRS:1,15,SMOOTH_STAIRS:2,15,SMOOTH_STAIRS:3,15,STEP:5,15,STEP:13,15,COBBLE_WALL:0,10,COBBLESTONE_STAIRS:0,10,STEP:3,10,COBBLE_WALL:1,20,COBBLESTONE_STAIRS:2,20,COBBLESTONE_STAIRS:3,20,MOSSY_COBBLESTONE:0,60,COBBLESTONE_STAIRS:1,20,STEP:11,20,COBBLESTONE:0,100)
RandomBlock(-4,3,-6,contenttweaker:reinforced_concrete,40,SMOOTH_BRICK:1,30,SMOOTH_BRICK:2,30,SMOOTH_STAIRS:0,15,SMOOTH_STAIRS:1,15,SMOOTH_STAIRS:2,15,SMOOTH_STAIRS:3,15,STEP:5,15,STEP:13,15,COBBLE_WALL:0,10,COBBLESTONE_STAIRS:0,10,STEP:3,10,COBBLE_WALL:1,20,COBBLESTONE_STAIRS:2,20,COBBLESTONE_STAIRS:3,20,MOSSY_COBBLESTONE:0,60,COBBLESTONE_STAIRS:1,20,STEP:11,20,COBBLESTONE:0,100)
RandomBlock(-4,3,-5,contenttweaker:reinforced_concrete,40,SMOOTH_BRICK:1,30,SMOOTH_BRICK:2,30,SMOOTH_STAIRS:0,15,SMOOTH_STAIRS:1,15,SMOOTH_STAIRS:2,15,SMOOTH_STAIRS:3,15,STEP:5,15,STEP:13,15,COBBLE_WALL:0,10,COBBLESTONE_STAIRS:0,10,STEP:3,10,COBBLE_WALL:1,20,COBBLESTONE_STAIRS:2,20,COBBLESTONE_STAIRS:3,20,MOSSY_COBBLESTONE:0,60,COBBLESTONE_STAIRS:1,20,STEP:11,20,COBBLESTONE:0,100)
RandomBlock(-4,3,-4,contenttweaker:reinforced_concrete,40,SMOOTH_BRICK:1,30,SMOOTH_BRICK:2,30,SMOOTH_STAIRS:0,15,SMOOTH_STAIRS:1,15,SMOOTH_STAIRS:2,15,SMOOTH_STAIRS:3,15,STEP:5,15,STEP:13,15,COBBLE_WALL:0,10,COBBLESTONE_STAIRS:0,10,STEP:3,10,COBBLE_WALL:1,20,COBBLESTONE_STAIRS:2,20,COBBLESTONE_STAIRS:3,20,MOSSY_COBBLESTONE:0,60,COBBLESTONE_STAIRS:1,20,STEP:11,20,COBBLESTONE:0,100)
RandomBlock(-4,3,-3,contenttweaker:reinforced_concrete,40,SMOOTH_BRICK:1,30,SMOOTH_BRICK:2,30,SMOOTH_STAIRS:0,15,SMOOTH_STAIRS:1,15,SMOOTH_STAIRS:2,15,SMOOTH_STAIRS:3,15,STEP:5,15,STEP:13,15,COBBLE_WALL:0,10,COBBLESTONE_STAIRS:0,10,STEP:3,10,COBBLE_WALL:1,20,COBBLESTONE_STAIRS:2,20,COBBLESTONE_STAIRS:3,20,MOSSY_COBBLESTONE:0,60,COBBLESTONE_STAIRS:1,20,STEP:11,20,COBBLESTONE:0,100)
RandomBlock(-4,4,-7,contenttweaker:reinforced_concrete,40,SMOOTH_BRICK:1,30,SMOOTH_BRICK:2,30,SMOOTH_STAIRS:0,15,SMOOTH_STAIRS:1,15,SMOOTH_STAIRS:2,15,SMOOTH_STAIRS:3,15,STEP:5,15,STEP:13,15,COBBLE_WALL:0,10,COBBLESTONE_STAIRS:0,10,STEP:3,10,COBBLE_WALL:1,20,COBBLESTONE_STAIRS:2,20,COBBLESTONE_STAIRS:3,20,MOSSY_COBBLESTONE:0,60,COBBLESTONE_STAIRS:1,20,STEP:11,20,COBBLESTONE:0,100)
RandomBlock(-4,4,-6,contenttweaker:reinforced_concrete,40,SMOOTH_BRICK:1,30,SMOOTH_BRICK:2,30,SMOOTH_STAIRS:0,15,SMOOTH_STAIRS:1,15,SMOOTH_STAIRS:2,15,SMOOTH_STAIRS:3,15,STEP:5,15,STEP:13,15,COBBLE_WALL:0,10,COBBLESTONE_STAIRS:0,10,STEP:3,10,COBBLE_WALL:1,20,COBBLESTONE_STAIRS:2,20,COBBLESTONE_STAIRS:3,20,MOSSY_COBBLESTONE:0,60,COBBLESTONE_STAIRS:1,20,STEP:11,20,COBBLESTONE:0,100)
RandomBlock(-4,4,-5,contenttweaker:reinforced_concrete,40,SMOOTH_BRICK:1,30,SMOOTH_BRICK:2,30,SMOOTH_STAIRS:0,15,SMOOTH_STAIRS:1,15,SMOOTH_STAIRS:2,15,SMOOTH_STAIRS:3,15,STEP:5,15,STEP:13,15,COBBLE_WALL:0,10,COBBLESTONE_STAIRS:0,10,STEP:3,10,COBBLE_WALL:1,20,COBBLESTONE_STAIRS:2,20,COBBLESTONE_STAIRS:3,20,MOSSY_COBBLESTONE:0,60,COBBLESTONE_STAIRS:1,20,STEP:11,20,COBBLESTONE:0,100)
RandomBlock(-4,4,-4,contenttweaker:reinforced_concrete,40,SMOOTH_BRICK:1,30,SMOOTH_BRICK:2,30,SMOOTH_STAIRS:0,15,SMOOTH_STAIRS:1,15,SMOOTH_STAIRS:2,15,SMOOTH_STAIRS:3,15,STEP:5,15,STEP:13,15,COBBLE_WALL:0,10,COBBLESTONE_STAIRS:0,10,STEP:3,10,COBBLE_WALL:1,20,COBBLESTONE_STAIRS:2,20,COBBLESTONE_STAIRS:3,20,MOSSY_COBBLESTONE:0,60,COBBLESTONE_STAIRS:1,20,STEP:11,20,COBBLESTONE:0,100)
RandomBlock(-4,4,-3,contenttweaker:reinforced_concrete,40,SMOOTH_BRICK:1,30,SMOOTH_BRICK:2,30,SMOOTH_STAIRS:0,15,SMOOTH_STAIRS:1,15,SMOOTH_STAIRS:2,15,SMOOTH_STAIRS:3,15,STEP:5,15,STEP:13,15,COBBLE_WALL:0,10,COBBLESTONE_STAIRS:0,10,STEP:3,10,COBBLE_WALL:1,20,COBBLESTONE_STAIRS:2,20,COBBLESTONE_STAIRS:3,20,MOSSY_COBBLESTONE:0,60,COBBLESTONE_STAIRS:1,20,STEP:11,20,COBBLESTONE:0,100)
RandomBlock(-4,5,-7,contenttweaker:reinforced_concrete,40,SMOOTH_BRICK:1,30,SMOOTH_BRICK:2,30,SMOOTH_STAIRS:0,15,SMOOTH_STAIRS:1,15,SMOOTH_STAIRS:2,15,SMOOTH_STAIRS:3,15,STEP:5,15,STEP:13,15,COBBLE_WALL:0,10,COBBLESTONE_STAIRS:0,10,STEP:3,10,COBBLE_WALL:1,20,COBBLESTONE_STAIRS:2,20,COBBLESTONE_STAIRS:3,20,MOSSY_COBBLESTONE:0,60,COBBLESTONE_STAIRS:1,20,STEP:11,20,COBBLESTONE:0,100)
RandomBlock(-4,5,-6,contenttweaker:reinforced_concrete,40,SMOOTH_BRICK:1,30,SMOOTH_BRICK:2,30,SMOOTH_STAIRS:0,15,SMOOTH_STAIRS:1,15,SMOOTH_STAIRS:2,15,SMOOTH_STAIRS:3,15,STEP:5,15,STEP:13,15,COBBLE_WALL:0,10,COBBLESTONE_STAIRS:0,10,STEP:3,10,COBBLE_WALL:1,20,COBBLESTONE_STAIRS:2,20,COBBLESTONE_STAIRS:3,20,MOSSY_COBBLESTONE:0,60,COBBLESTONE_STAIRS:1,20,STEP:11,20,COBBLESTONE:0,100)
RandomBlock(-4,5,-5,contenttweaker:reinforced_concrete,40,SMOOTH_BRICK:1,30,SMOOTH_BRICK:2,30,SMOOTH_STAIRS:0,15,SMOOTH_STAIRS:1,15,SMOOTH_STAIRS:2,15,SMOOTH_STAIRS:3,15,STEP:5,15,STEP:13,15,COBBLE_WALL:0,10,COBBLESTONE_STAIRS:0,10,STEP:3,10,COBBLE_WALL:1,20,COBBLESTONE_STAIRS:2,20,COBBLESTONE_STAIRS:3,20,MOSSY_COBBLESTONE:0,60,COBBLESTONE_STAIRS:1,20,STEP:11,20,COBBLESTONE:0,100)
RandomBlock(-4,5,-4,contenttweaker:reinforced_concrete,40,SMOOTH_BRICK:1,30,SMOOTH_BRICK:2,30,SMOOTH_STAIRS:0,15,SMOOTH_STAIRS:1,15,SMOOTH_STAIRS:2,15,SMOOTH_STAIRS:3,15,STEP:5,15,STEP:13,15,COBBLE_WALL:0,10,COBBLESTONE_STAIRS:0,10,STEP:3,10,COBBLE_WALL:1,20,COBBLESTONE_STAIRS:2,20,COBBLESTONE_STAIRS:3,20,MOSSY_COBBLESTONE:0,60,COBBLESTONE_STAIRS:1,20,STEP:11,20,COBBLESTONE:0,100)
RandomBlock(-4,5,-3,contenttweaker:reinforced_concrete,30,quark:limestone_wall,10,contenttweaker:reinforced_concrete,100)
RandomBlock(-4,6,-7,contenttweaker:reinforced_concrete,40,SMOOTH_BRICK:1,30,SMOOTH_BRICK:2,30,SMOOTH_STAIRS:0,15,SMOOTH_STAIRS:1,15,SMOOTH_STAIRS:2,15,SMOOTH_STAIRS:3,15,STEP:5,15,STEP:13,15,COBBLE_WALL:0,10,COBBLESTONE_STAIRS:0,10,STEP:3,10,COBBLE_WALL:1,20,COBBLESTONE_STAIRS:2,20,COBBLESTONE_STAIRS:3,20,MOSSY_COBBLESTONE:0,60,COBBLESTONE_STAIRS:1,20,STEP:11,20,COBBLESTONE:0,100)
RandomBlock(-4,6,-6,contenttweaker:reinforced_concrete,40,SMOOTH_BRICK:1,30,SMOOTH_BRICK:2,30,SMOOTH_STAIRS:0,15,SMOOTH_STAIRS:1,15,SMOOTH_STAIRS:2,15,SMOOTH_STAIRS:3,15,STEP:5,15,STEP:13,15,COBBLE_WALL:0,10,COBBLESTONE_STAIRS:0,10,STEP:3,10,COBBLE_WALL:1,20,COBBLESTONE_STAIRS:2,20,COBBLESTONE_STAIRS:3,20,MOSSY_COBBLESTONE:0,60,COBBLESTONE_STAIRS:1,20,STEP:11,20,COBBLESTONE:0,100)
RandomBlock(-4,6,-5,contenttweaker:reinforced_concrete,40,SMOOTH_BRICK:1,30,SMOOTH_BRICK:2,30,SMOOTH_STAIRS:0,15,SMOOTH_STAIRS:1,15,SMOOTH_STAIRS:2,15,SMOOTH_STAIRS:3,15,STEP:5,15,STEP:13,15,COBBLE_WALL:0,10,COBBLESTONE_STAIRS:0,10,STEP:3,10,COBBLE_WALL:1,20,COBBLESTONE_STAIRS:2,20,COBBLESTONE_STAIRS:3,20,MOSSY_COBBLESTONE:0,60,COBBLESTONE_STAIRS:1,20,STEP:11,20,COBBLESTONE:0,100)
RandomBlock(-4,6,-4,contenttweaker:reinforced_concrete,40,SMOOTH_BRICK:1,30,SMOOTH_BRICK:2,30,SMOOTH_STAIRS:0,15,SMOOTH_STAIRS:1,15,SMOOTH_STAIRS:2,15,SMOOTH_STAIRS:3,15,STEP:5,15,STEP:13,15,COBBLE_WALL:0,10,COBBLESTONE_STAIRS:0,10,STEP:3,10,COBBLE_WALL:1,20,COBBLESTONE_STAIRS:2,20,COBBLESTONE_STAIRS:3,20,MOSSY_COBBLESTONE:0,60,COBBLESTONE_STAIRS:1,20,STEP:11,20,COBBLESTONE:0,100)
RandomBlock(-4,6,-3,contenttweaker:reinforced_concrete,30,quark:limestone_wall,10,contenttweaker:reinforced_concrete,100)
RandomBlock(-4,7,-7,contenttweaker:reinforced_concrete,40,SMOOTH_BRICK:1,30,SMOOTH_BRICK:2,30,SMOOTH_STAIRS:0,15,SMOOTH_STAIRS:1,15,SMOOTH_STAIRS:2,15,SMOOTH_STAIRS:3,15,STEP:5,15,STEP:13,15,COBBLE_WALL:0,10,COBBLESTONE_STAIRS:0,10,STEP:3,10,COBBLE_WALL:1,20,COBBLESTONE_STAIRS:2,20,COBBLESTONE_STAIRS:3,20,MOSSY_COBBLESTONE:0,60,COBBLESTONE_STAIRS:1,20,STEP:11,20,COBBLESTONE:0,100)
RandomBlock(-4,7,-6,contenttweaker:reinforced_concrete,40,SMOOTH_BRICK:1,30,SMOOTH_BRICK:2,30,SMOOTH_STAIRS:0,15,SMOOTH_STAIRS:1,15,SMOOTH_STAIRS:2,15,SMOOTH_STAIRS:3,15,STEP:5,15,STEP:13,15,COBBLE_WALL:0,10,COBBLESTONE_STAIRS:0,10,STEP:3,10,COBBLE_WALL:1,20,COBBLESTONE_STAIRS:2,20,COBBLESTONE_STAIRS:3,20,MOSSY_COBBLESTONE:0,60,COBBLESTONE_STAIRS:1,20,STEP:11,20,COBBLESTONE:0,100)
RandomBlock(-4,7,-5,contenttweaker:reinforced_concrete,40,SMOOTH_BRICK:1,30,SMOOTH_BRICK:2,30,SMOOTH_STAIRS:0,15,SMOOTH_STAIRS:1,15,SMOOTH_STAIRS:2,15,SMOOTH_STAIRS:3,15,STEP:5,15,STEP:13,15,COBBLE_WALL:0,10,COBBLESTONE_STAIRS:0,10,STEP:3,10,COBBLE_WALL:1,20,COBBLESTONE_STAIRS:2,20,COBBLESTONE_STAIRS:3,20,MOSSY_COBBLESTONE:0,60,COBBLESTONE_STAIRS:1,20,STEP:11,20,COBBLESTONE:0,100)
RandomBlock(-4,7,-4,contenttweaker:reinforced_concrete,40,SMOOTH_BRICK:1,30,SMOOTH_BRICK:2,30,SMOOTH_STAIRS:0,15,SMOOTH_STAIRS:1,15,SMOOTH_STAIRS:2,15,SMOOTH_STAIRS:3,15,STEP:5,15,STEP:13,15,COBBLE_WALL:0,10,COBBLESTONE_STAIRS:0,10,STEP:3,10,COBBLE_WALL:1,20,COBBLESTONE_STAIRS:2,20,COBBLESTONE_STAIRS:3,20,MOSSY_COBBLESTONE:0,60,COBBLESTONE_STAIRS:1,20,STEP:11,20,COBBLESTONE:0,100)
RandomBlock(-4,7,-3,contenttweaker:reinforced_concrete,30,quark:limestone_wall,10,contenttweaker:reinforced_concrete,100)
RandomBlock(-4,8,-5,RUSTIC:IRON_LATTICE:0,30,RUSTIC:IRON_LATTICE:1,100)
RandomBlock(-4,8,-4,RUSTIC:IRON_LATTICE:0,30,RUSTIC:IRON_LATTICE:1,100)
Block(-4,8,-3,inspirations:redstone_barrel)
RandomBlock(-4,9,-5,RUSTIC:IRON_LATTICE:0,30,RUSTIC:IRON_LATTICE:1,100)
RandomBlock(-4,9,-4,RUSTIC:IRON_LATTICE:0,30,RUSTIC:IRON_LATTICE:1,100)
Block(-4,9,-3,inspirations:redstone_barrel)
RandomBlock(-4,10,-5,RUSTIC:IRON_LATTICE:0,30,RUSTIC:IRON_LATTICE:1,100)
RandomBlock(-4,10,-4,RUSTIC:IRON_LATTICE:0,30,RUSTIC:IRON_LATTICE:1,100)
RandomBlock(-4,10,-3,contenttweaker:reinforced_concrete,30,quark:limestone_wall,10,contenttweaker:reinforced_concrete,100)
RandomBlock(-4,11,-3,contenttweaker:reinforced_concrete,30,quark:limestone_wall,10,contenttweaker:reinforced_concrete,100)
RandomBlock(-4,12,-4,contenttweaker:reinforced_concrete,30,quark:limestone_wall,10,contenttweaker:reinforced_concrete,100)
RandomBlock(-4,13,-4,contenttweaker:reinforced_concrete,30,quark:limestone_wall,10,contenttweaker:reinforced_concrete,100)
RandomBlock(-4,14,-6,contenttweaker:reinforced_concrete,30,quark:limestone_wall,10,contenttweaker:reinforced_concrete,100)
RandomBlock(-4,14,-5,contenttweaker:reinforced_concrete,30,quark:limestone_wall,10,contenttweaker:reinforced_concrete,100)
Block(-4,14,-4,VINE:4)
RandomBlock(-4,15,-6,contenttweaker:reinforced_concrete,30,quark:limestone_wall,10,contenttweaker:reinforced_concrete,100)
RandomBlock(-4,15,-5,contenttweaker:reinforced_concrete,30,quark:limestone_wall,10,contenttweaker:reinforced_concrete,100)
Block(-4,15,-4,VINE:4)
RandomBlock(-4,16,-7,contenttweaker:reinforced_concrete,30,quark:limestone_wall,10,contenttweaker:reinforced_concrete,100)
Block(-4,16,-6,VINE:8)
RandomBlock(-4,17,-7,contenttweaker:reinforced_concrete,30,quark:limestone_wall,10,contenttweaker:reinforced_concrete,100)
Block(-4,17,-6,VINE:12)
RandomBlock(-4,18,-7,contenttweaker:reinforced_concrete,30,quark:limestone_wall,10,contenttweaker:reinforced_concrete,100)
Block(-4,18,-6,VINE:12)
RandomBlock(-4,19,-7,contenttweaker:reinforced_concrete,30,quark:limestone_wall,10,contenttweaker:reinforced_concrete,100)
Block(-4,19,-6,VINE:12)
Block(-4,20,-6,VINE:4)
Block(-4,21,-6,VINE:4)
Block(-4,22,-6,VINE:12)
Block(-4,23,-6,VINE:12)
Block(-4,23,-5,VINE:8)
RandomBlock(-4,24,-7,contenttweaker:reinforced_concrete,30,quark:limestone_wall,10,contenttweaker:reinforced_concrete,100)
Block(-4,24,-6,VINE:12)
Block(-4,24,-5,VINE:8)
Block(-4,24,-4,VINE:4)
RandomBlock(-4,25,-7,contenttweaker:reinforced_concrete,30,quark:limestone_wall,10,contenttweaker:reinforced_concrete,100)
Block(-4,25,-6,VINE:8)
Block(-4,25,-5,VINE:8)
Block(-4,25,-4,VINE:4)
RandomBlock(-4,26,-6,contenttweaker:reinforced_concrete,30,quark:limestone_wall,10,contenttweaker:reinforced_concrete,100)
Block(-4,26,-5,VINE:8)
Block(-4,26,-4,VINE:4)
RandomBlock(-4,27,-6,contenttweaker:reinforced_concrete,30,quark:limestone_wall,10,contenttweaker:reinforced_concrete,100)
Block(-4,27,-5,VINE:8)
Block(-4,27,-4,VINE:4)
RandomBlock(-4,28,-5,contenttweaker:reinforced_concrete,30,quark:limestone_wall,10,contenttweaker:reinforced_concrete,100)
Block(-4,28,-4,VINE:4)
RandomBlock(-3,0,-7,contenttweaker:reinforced_concrete,40,SMOOTH_BRICK:1,30,SMOOTH_BRICK:2,30,SMOOTH_STAIRS:0,15,SMOOTH_STAIRS:1,15,SMOOTH_STAIRS:2,15,SMOOTH_STAIRS:3,15,STEP:5,15,STEP:13,15,COBBLE_WALL:0,10,COBBLESTONE_STAIRS:0,10,STEP:3,10,COBBLE_WALL:1,20,COBBLESTONE_STAIRS:2,20,COBBLESTONE_STAIRS:3,20,MOSSY_COBBLESTONE:0,60,COBBLESTONE_STAIRS:1,20,STEP:11,20,COBBLESTONE:0,100)
RandomBlock(-3,0,-6,contenttweaker:reinforced_concrete,40,SMOOTH_BRICK:1,30,SMOOTH_BRICK:2,30,SMOOTH_STAIRS:0,15,SMOOTH_STAIRS:1,15,SMOOTH_STAIRS:2,15,SMOOTH_STAIRS:3,15,STEP:5,15,STEP:13,15,COBBLE_WALL:0,10,COBBLESTONE_STAIRS:0,10,STEP:3,10,COBBLE_WALL:1,20,COBBLESTONE_STAIRS:2,20,COBBLESTONE_STAIRS:3,20,MOSSY_COBBLESTONE:0,60,COBBLESTONE_STAIRS:1,20,STEP:11,20,COBBLESTONE:0,100)
RandomBlock(-3,0,-5,contenttweaker:reinforced_concrete,40,SMOOTH_BRICK:1,30,SMOOTH_BRICK:2,30,SMOOTH_STAIRS:0,15,SMOOTH_STAIRS:1,15,SMOOTH_STAIRS:2,15,SMOOTH_STAIRS:3,15,STEP:5,15,STEP:13,15,COBBLE_WALL:0,10,COBBLESTONE_STAIRS:0,10,STEP:3,10,COBBLE_WALL:1,20,COBBLESTONE_STAIRS:2,20,COBBLESTONE_STAIRS:3,20,MOSSY_COBBLESTONE:0,60,COBBLESTONE_STAIRS:1,20,STEP:11,20,COBBLESTONE:0,100)
RandomBlock(-3,0,-4,contenttweaker:reinforced_concrete,40,SMOOTH_BRICK:1,30,SMOOTH_BRICK:2,30,SMOOTH_STAIRS:0,15,SMOOTH_STAIRS:1,15,SMOOTH_STAIRS:2,15,SMOOTH_STAIRS:3,15,STEP:5,15,STEP:13,15,COBBLE_WALL:0,10,COBBLESTONE_STAIRS:0,10,STEP:3,10,COBBLE_WALL:1,20,COBBLESTONE_STAIRS:2,20,COBBLESTONE_STAIRS:3,20,MOSSY_COBBLESTONE:0,60,COBBLESTONE_STAIRS:1,20,STEP:11,20,COBBLESTONE:0,100)
RandomBlock(-3,0,-3,contenttweaker:reinforced_concrete,40,SMOOTH_BRICK:1,30,SMOOTH_BRICK:2,30,SMOOTH_STAIRS:0,15,SMOOTH_STAIRS:1,15,SMOOTH_STAIRS:2,15,SMOOTH_STAIRS:3,15,STEP:5,15,STEP:13,15,COBBLE_WALL:0,10,COBBLESTONE_STAIRS:0,10,STEP:3,10,COBBLE_WALL:1,20,COBBLESTONE_STAIRS:2,20,COBBLESTONE_STAIRS:3,20,MOSSY_COBBLESTONE:0,60,COBBLESTONE_STAIRS:1,20,STEP:11,20,COBBLESTONE:0,100)
RandomBlock(-3,1,-7,contenttweaker:reinforced_concrete,40,SMOOTH_BRICK:1,30,SMOOTH_BRICK:2,30,SMOOTH_STAIRS:0,15,SMOOTH_STAIRS:1,15,SMOOTH_STAIRS:2,15,SMOOTH_STAIRS:3,15,STEP:5,15,STEP:13,15,COBBLE_WALL:0,10,COBBLESTONE_STAIRS:0,10,STEP:3,10,COBBLE_WALL:1,20,COBBLESTONE_STAIRS:2,20,COBBLESTONE_STAIRS:3,20,MOSSY_COBBLESTONE:0,60,COBBLESTONE_STAIRS:1,20,STEP:11,20,COBBLESTONE:0,100)
RandomBlock(-3,1,-6,contenttweaker:reinforced_concrete,40,SMOOTH_BRICK:1,30,SMOOTH_BRICK:2,30,SMOOTH_STAIRS:0,15,SMOOTH_STAIRS:1,15,SMOOTH_STAIRS:2,15,SMOOTH_STAIRS:3,15,STEP:5,15,STEP:13,15,COBBLE_WALL:0,10,COBBLESTONE_STAIRS:0,10,STEP:3,10,COBBLE_WALL:1,20,COBBLESTONE_STAIRS:2,20,COBBLESTONE_STAIRS:3,20,MOSSY_COBBLESTONE:0,60,COBBLESTONE_STAIRS:1,20,STEP:11,20,COBBLESTONE:0,100)
RandomBlock(-3,1,-5,contenttweaker:reinforced_concrete,40,SMOOTH_BRICK:1,30,SMOOTH_BRICK:2,30,SMOOTH_STAIRS:0,15,SMOOTH_STAIRS:1,15,SMOOTH_STAIRS:2,15,SMOOTH_STAIRS:3,15,STEP:5,15,STEP:13,15,COBBLE_WALL:0,10,COBBLESTONE_STAIRS:0,10,STEP:3,10,COBBLE_WALL:1,20,COBBLESTONE_STAIRS:2,20,COBBLESTONE_STAIRS:3,20,MOSSY_COBBLESTONE:0,60,COBBLESTONE_STAIRS:1,20,STEP:11,20,COBBLESTONE:0,100)
RandomBlock(-3,1,-4,contenttweaker:reinforced_concrete,40,SMOOTH_BRICK:1,30,SMOOTH_BRICK:2,30,SMOOTH_STAIRS:0,15,SMOOTH_STAIRS:1,15,SMOOTH_STAIRS:2,15,SMOOTH_STAIRS:3,15,STEP:5,15,STEP:13,15,COBBLE_WALL:0,10,COBBLESTONE_STAIRS:0,10,STEP:3,10,COBBLE_WALL:1,20,COBBLESTONE_STAIRS:2,20,COBBLESTONE_STAIRS:3,20,MOSSY_COBBLESTONE:0,60,COBBLESTONE_STAIRS:1,20,STEP:11,20,COBBLESTONE:0,100)
RandomBlock(-3,1,-3,contenttweaker:reinforced_concrete,40,SMOOTH_BRICK:1,30,SMOOTH_BRICK:2,30,SMOOTH_STAIRS:0,15,SMOOTH_STAIRS:1,15,SMOOTH_STAIRS:2,15,SMOOTH_STAIRS:3,15,STEP:5,15,STEP:13,15,COBBLE_WALL:0,10,COBBLESTONE_STAIRS:0,10,STEP:3,10,COBBLE_WALL:1,20,COBBLESTONE_STAIRS:2,20,COBBLESTONE_STAIRS:3,20,MOSSY_COBBLESTONE:0,60,COBBLESTONE_STAIRS:1,20,STEP:11,20,COBBLESTONE:0,100)
RandomBlock(-3,2,-7,contenttweaker:reinforced_concrete,40,SMOOTH_BRICK:1,30,SMOOTH_BRICK:2,30,SMOOTH_STAIRS:0,15,SMOOTH_STAIRS:1,15,SMOOTH_STAIRS:2,15,SMOOTH_STAIRS:3,15,STEP:5,15,STEP:13,15,COBBLE_WALL:0,10,COBBLESTONE_STAIRS:0,10,STEP:3,10,COBBLE_WALL:1,20,COBBLESTONE_STAIRS:2,20,COBBLESTONE_STAIRS:3,20,MOSSY_COBBLESTONE:0,60,COBBLESTONE_STAIRS:1,20,STEP:11,20,COBBLESTONE:0,100)
RandomBlock(-3,2,-6,contenttweaker:reinforced_concrete,40,SMOOTH_BRICK:1,30,SMOOTH_BRICK:2,30,SMOOTH_STAIRS:0,15,SMOOTH_STAIRS:1,15,SMOOTH_STAIRS:2,15,SMOOTH_STAIRS:3,15,STEP:5,15,STEP:13,15,COBBLE_WALL:0,10,COBBLESTONE_STAIRS:0,10,STEP:3,10,COBBLE_WALL:1,20,COBBLESTONE_STAIRS:2,20,COBBLESTONE_STAIRS:3,20,MOSSY_COBBLESTONE:0,60,COBBLESTONE_STAIRS:1,20,STEP:11,20,COBBLESTONE:0,100)
RandomBlock(-3,2,-5,contenttweaker:reinforced_concrete,40,SMOOTH_BRICK:1,30,SMOOTH_BRICK:2,30,SMOOTH_STAIRS:0,15,SMOOTH_STAIRS:1,15,SMOOTH_STAIRS:2,15,SMOOTH_STAIRS:3,15,STEP:5,15,STEP:13,15,COBBLE_WALL:0,10,COBBLESTONE_STAIRS:0,10,STEP:3,10,COBBLE_WALL:1,20,COBBLESTONE_STAIRS:2,20,COBBLESTONE_STAIRS:3,20,MOSSY_COBBLESTONE:0,60,COBBLESTONE_STAIRS:1,20,STEP:11,20,COBBLESTONE:0,100)
RandomBlock(-3,2,-4,contenttweaker:reinforced_concrete,40,SMOOTH_BRICK:1,30,SMOOTH_BRICK:2,30,SMOOTH_STAIRS:0,15,SMOOTH_STAIRS:1,15,SMOOTH_STAIRS:2,15,SMOOTH_STAIRS:3,15,STEP:5,15,STEP:13,15,COBBLE_WALL:0,10,COBBLESTONE_STAIRS:0,10,STEP:3,10,COBBLE_WALL:1,20,COBBLESTONE_STAIRS:2,20,COBBLESTONE_STAIRS:3,20,MOSSY_COBBLESTONE:0,60,COBBLESTONE_STAIRS:1,20,STEP:11,20,COBBLESTONE:0,100)
RandomBlock(-3,2,-3,contenttweaker:reinforced_concrete,40,SMOOTH_BRICK:1,30,SMOOTH_BRICK:2,30,SMOOTH_STAIRS:0,15,SMOOTH_STAIRS:1,15,SMOOTH_STAIRS:2,15,SMOOTH_STAIRS:3,15,STEP:5,15,STEP:13,15,COBBLE_WALL:0,10,COBBLESTONE_STAIRS:0,10,STEP:3,10,COBBLE_WALL:1,20,COBBLESTONE_STAIRS:2,20,COBBLESTONE_STAIRS:3,20,MOSSY_COBBLESTONE:0,60,COBBLESTONE_STAIRS:1,20,STEP:11,20,COBBLESTONE:0,100)
RandomBlock(-3,3,-7,contenttweaker:reinforced_concrete,40,SMOOTH_BRICK:1,30,SMOOTH_BRICK:2,30,SMOOTH_STAIRS:0,15,SMOOTH_STAIRS:1,15,SMOOTH_STAIRS:2,15,SMOOTH_STAIRS:3,15,STEP:5,15,STEP:13,15,COBBLE_WALL:0,10,COBBLESTONE_STAIRS:0,10,STEP:3,10,COBBLE_WALL:1,20,COBBLESTONE_STAIRS:2,20,COBBLESTONE_STAIRS:3,20,MOSSY_COBBLESTONE:0,60,COBBLESTONE_STAIRS:1,20,STEP:11,20,COBBLESTONE:0,100)
RandomBlock(-3,3,-6,contenttweaker:reinforced_concrete,40,SMOOTH_BRICK:1,30,SMOOTH_BRICK:2,30,SMOOTH_STAIRS:0,15,SMOOTH_STAIRS:1,15,SMOOTH_STAIRS:2,15,SMOOTH_STAIRS:3,15,STEP:5,15,STEP:13,15,COBBLE_WALL:0,10,COBBLESTONE_STAIRS:0,10,STEP:3,10,COBBLE_WALL:1,20,COBBLESTONE_STAIRS:2,20,COBBLESTONE_STAIRS:3,20,MOSSY_COBBLESTONE:0,60,COBBLESTONE_STAIRS:1,20,STEP:11,20,COBBLESTONE:0,100)
RandomBlock(-3,3,-5,contenttweaker:reinforced_concrete,40,SMOOTH_BRICK:1,30,SMOOTH_BRICK:2,30,SMOOTH_STAIRS:0,15,SMOOTH_STAIRS:1,15,SMOOTH_STAIRS:2,15,SMOOTH_STAIRS:3,15,STEP:5,15,STEP:13,15,COBBLE_WALL:0,10,COBBLESTONE_STAIRS:0,10,STEP:3,10,COBBLE_WALL:1,20,COBBLESTONE_STAIRS:2,20,COBBLESTONE_STAIRS:3,20,MOSSY_COBBLESTONE:0,60,COBBLESTONE_STAIRS:1,20,STEP:11,20,COBBLESTONE:0,100)
RandomBlock(-3,3,-4,contenttweaker:reinforced_concrete,40,SMOOTH_BRICK:1,30,SMOOTH_BRICK:2,30,SMOOTH_STAIRS:0,15,SMOOTH_STAIRS:1,15,SMOOTH_STAIRS:2,15,SMOOTH_STAIRS:3,15,STEP:5,15,STEP:13,15,COBBLE_WALL:0,10,COBBLESTONE_STAIRS:0,10,STEP:3,10,COBBLE_WALL:1,20,COBBLESTONE_STAIRS:2,20,COBBLESTONE_STAIRS:3,20,MOSSY_COBBLESTONE:0,60,COBBLESTONE_STAIRS:1,20,STEP:11,20,COBBLESTONE:0,100)
RandomBlock(-3,3,-3,contenttweaker:reinforced_concrete,40,SMOOTH_BRICK:1,30,SMOOTH_BRICK:2,30,SMOOTH_STAIRS:0,15,SMOOTH_STAIRS:1,15,SMOOTH_STAIRS:2,15,SMOOTH_STAIRS:3,15,STEP:5,15,STEP:13,15,COBBLE_WALL:0,10,COBBLESTONE_STAIRS:0,10,STEP:3,10,COBBLE_WALL:1,20,COBBLESTONE_STAIRS:2,20,COBBLESTONE_STAIRS:3,20,MOSSY_COBBLESTONE:0,60,COBBLESTONE_STAIRS:1,20,STEP:11,20,COBBLESTONE:0,100)
RandomBlock(-3,4,-7,contenttweaker:reinforced_concrete,40,SMOOTH_BRICK:1,30,SMOOTH_BRICK:2,30,SMOOTH_STAIRS:0,15,SMOOTH_STAIRS:1,15,SMOOTH_STAIRS:2,15,SMOOTH_STAIRS:3,15,STEP:5,15,STEP:13,15,COBBLE_WALL:0,10,COBBLESTONE_STAIRS:0,10,STEP:3,10,COBBLE_WALL:1,20,COBBLESTONE_STAIRS:2,20,COBBLESTONE_STAIRS:3,20,MOSSY_COBBLESTONE:0,60,COBBLESTONE_STAIRS:1,20,STEP:11,20,COBBLESTONE:0,100)
RandomBlock(-3,4,-6,contenttweaker:reinforced_concrete,40,SMOOTH_BRICK:1,30,SMOOTH_BRICK:2,30,SMOOTH_STAIRS:0,15,SMOOTH_STAIRS:1,15,SMOOTH_STAIRS:2,15,SMOOTH_STAIRS:3,15,STEP:5,15,STEP:13,15,COBBLE_WALL:0,10,COBBLESTONE_STAIRS:0,10,STEP:3,10,COBBLE_WALL:1,20,COBBLESTONE_STAIRS:2,20,COBBLESTONE_STAIRS:3,20,MOSSY_COBBLESTONE:0,60,COBBLESTONE_STAIRS:1,20,STEP:11,20,COBBLESTONE:0,100)
RandomBlock(-3,4,-5,contenttweaker:reinforced_concrete,40,SMOOTH_BRICK:1,30,SMOOTH_BRICK:2,30,SMOOTH_STAIRS:0,15,SMOOTH_STAIRS:1,15,SMOOTH_STAIRS:2,15,SMOOTH_STAIRS:3,15,STEP:5,15,STEP:13,15,COBBLE_WALL:0,10,COBBLESTONE_STAIRS:0,10,STEP:3,10,COBBLE_WALL:1,20,COBBLESTONE_STAIRS:2,20,COBBLESTONE_STAIRS:3,20,MOSSY_COBBLESTONE:0,60,COBBLESTONE_STAIRS:1,20,STEP:11,20,COBBLESTONE:0,100)
RandomBlock(-3,4,-4,contenttweaker:reinforced_concrete,40,SMOOTH_BRICK:1,30,SMOOTH_BRICK:2,30,SMOOTH_STAIRS:0,15,SMOOTH_STAIRS:1,15,SMOOTH_STAIRS:2,15,SMOOTH_STAIRS:3,15,STEP:5,15,STEP:13,15,COBBLE_WALL:0,10,COBBLESTONE_STAIRS:0,10,STEP:3,10,COBBLE_WALL:1,20,COBBLESTONE_STAIRS:2,20,COBBLESTONE_STAIRS:3,20,MOSSY_COBBLESTONE:0,60,COBBLESTONE_STAIRS:1,20,STEP:11,20,COBBLESTONE:0,100)
RandomBlock(-3,4,-3,contenttweaker:reinforced_concrete,40,SMOOTH_BRICK:1,30,SMOOTH_BRICK:2,30,SMOOTH_STAIRS:0,15,SMOOTH_STAIRS:1,15,SMOOTH_STAIRS:2,15,SMOOTH_STAIRS:3,15,STEP:5,15,STEP:13,15,COBBLE_WALL:0,10,COBBLESTONE_STAIRS:0,10,STEP:3,10,COBBLE_WALL:1,20,COBBLESTONE_STAIRS:2,20,COBBLESTONE_STAIRS:3,20,MOSSY_COBBLESTONE:0,60,COBBLESTONE_STAIRS:1,20,STEP:11,20,COBBLESTONE:0,100)
RandomBlock(-3,5,-7,contenttweaker:reinforced_concrete,40,SMOOTH_BRICK:1,30,SMOOTH_BRICK:2,30,SMOOTH_STAIRS:0,15,SMOOTH_STAIRS:1,15,SMOOTH_STAIRS:2,15,SMOOTH_STAIRS:3,15,STEP:5,15,STEP:13,15,COBBLE_WALL:0,10,COBBLESTONE_STAIRS:0,10,STEP:3,10,COBBLE_WALL:1,20,COBBLESTONE_STAIRS:2,20,COBBLESTONE_STAIRS:3,20,MOSSY_COBBLESTONE:0,60,COBBLESTONE_STAIRS:1,20,STEP:11,20,COBBLESTONE:0,100)
RandomBlock(-3,5,-6,contenttweaker:reinforced_concrete,40,SMOOTH_BRICK:1,30,SMOOTH_BRICK:2,30,SMOOTH_STAIRS:0,15,SMOOTH_STAIRS:1,15,SMOOTH_STAIRS:2,15,SMOOTH_STAIRS:3,15,STEP:5,15,STEP:13,15,COBBLE_WALL:0,10,COBBLESTONE_STAIRS:0,10,STEP:3,10,COBBLE_WALL:1,20,COBBLESTONE_STAIRS:2,20,COBBLESTONE_STAIRS:3,20,MOSSY_COBBLESTONE:0,60,COBBLESTONE_STAIRS:1,20,STEP:11,20,COBBLESTONE:0,100)
RandomBlock(-3,5,-5,contenttweaker:reinforced_concrete,40,SMOOTH_BRICK:1,30,SMOOTH_BRICK:2,30,SMOOTH_STAIRS:0,15,SMOOTH_STAIRS:1,15,SMOOTH_STAIRS:2,15,SMOOTH_STAIRS:3,15,STEP:5,15,STEP:13,15,COBBLE_WALL:0,10,COBBLESTONE_STAIRS:0,10,STEP:3,10,COBBLE_WALL:1,20,COBBLESTONE_STAIRS:2,20,COBBLESTONE_STAIRS:3,20,MOSSY_COBBLESTONE:0,60,COBBLESTONE_STAIRS:1,20,STEP:11,20,COBBLESTONE:0,100)
RandomBlock(-3,5,-4,contenttweaker:reinforced_concrete,40,SMOOTH_BRICK:1,30,SMOOTH_BRICK:2,30,SMOOTH_STAIRS:0,15,SMOOTH_STAIRS:1,15,SMOOTH_STAIRS:2,15,SMOOTH_STAIRS:3,15,STEP:5,15,STEP:13,15,COBBLE_WALL:0,10,COBBLESTONE_STAIRS:0,10,STEP:3,10,COBBLE_WALL:1,20,COBBLESTONE_STAIRS:2,20,COBBLESTONE_STAIRS:3,20,MOSSY_COBBLESTONE:0,60,COBBLESTONE_STAIRS:1,20,STEP:11,20,COBBLESTONE:0,100)
RandomBlock(-3,5,-3,contenttweaker:reinforced_concrete,30,quark:limestone_wall,10,contenttweaker:reinforced_concrete,100)
RandomBlock(-3,6,-7,contenttweaker:reinforced_concrete,40,SMOOTH_BRICK:1,30,SMOOTH_BRICK:2,30,SMOOTH_STAIRS:0,15,SMOOTH_STAIRS:1,15,SMOOTH_STAIRS:2,15,SMOOTH_STAIRS:3,15,STEP:5,15,STEP:13,15,COBBLE_WALL:0,10,COBBLESTONE_STAIRS:0,10,STEP:3,10,COBBLE_WALL:1,20,COBBLESTONE_STAIRS:2,20,COBBLESTONE_STAIRS:3,20,MOSSY_COBBLESTONE:0,60,COBBLESTONE_STAIRS:1,20,STEP:11,20,COBBLESTONE:0,100)
RandomBlock(-3,6,-6,contenttweaker:reinforced_concrete,40,SMOOTH_BRICK:1,30,SMOOTH_BRICK:2,30,SMOOTH_STAIRS:0,15,SMOOTH_STAIRS:1,15,SMOOTH_STAIRS:2,15,SMOOTH_STAIRS:3,15,STEP:5,15,STEP:13,15,COBBLE_WALL:0,10,COBBLESTONE_STAIRS:0,10,STEP:3,10,COBBLE_WALL:1,20,COBBLESTONE_STAIRS:2,20,COBBLESTONE_STAIRS:3,20,MOSSY_COBBLESTONE:0,60,COBBLESTONE_STAIRS:1,20,STEP:11,20,COBBLESTONE:0,100)
RandomBlock(-3,6,-5,contenttweaker:reinforced_concrete,40,SMOOTH_BRICK:1,30,SMOOTH_BRICK:2,30,SMOOTH_STAIRS:0,15,SMOOTH_STAIRS:1,15,SMOOTH_STAIRS:2,15,SMOOTH_STAIRS:3,15,STEP:5,15,STEP:13,15,COBBLE_WALL:0,10,COBBLESTONE_STAIRS:0,10,STEP:3,10,COBBLE_WALL:1,20,COBBLESTONE_STAIRS:2,20,COBBLESTONE_STAIRS:3,20,MOSSY_COBBLESTONE:0,60,COBBLESTONE_STAIRS:1,20,STEP:11,20,COBBLESTONE:0,100)
RandomBlock(-3,6,-4,contenttweaker:reinforced_concrete,40,SMOOTH_BRICK:1,30,SMOOTH_BRICK:2,30,SMOOTH_STAIRS:0,15,SMOOTH_STAIRS:1,15,SMOOTH_STAIRS:2,15,SMOOTH_STAIRS:3,15,STEP:5,15,STEP:13,15,COBBLE_WALL:0,10,COBBLESTONE_STAIRS:0,10,STEP:3,10,COBBLE_WALL:1,20,COBBLESTONE_STAIRS:2,20,COBBLESTONE_STAIRS:3,20,MOSSY_COBBLESTONE:0,60,COBBLESTONE_STAIRS:1,20,STEP:11,20,COBBLESTONE:0,100)
RandomBlock(-3,6,-3,contenttweaker:reinforced_concrete,30,quark:limestone_wall,10,contenttweaker:reinforced_concrete,100)
RandomBlock(-3,7,-7,contenttweaker:reinforced_concrete,40,SMOOTH_BRICK:1,30,SMOOTH_BRICK:2,30,SMOOTH_STAIRS:0,15,SMOOTH_STAIRS:1,15,SMOOTH_STAIRS:2,15,SMOOTH_STAIRS:3,15,STEP:5,15,STEP:13,15,COBBLE_WALL:0,10,COBBLESTONE_STAIRS:0,10,STEP:3,10,COBBLE_WALL:1,20,COBBLESTONE_STAIRS:2,20,COBBLESTONE_STAIRS:3,20,MOSSY_COBBLESTONE:0,60,COBBLESTONE_STAIRS:1,20,STEP:11,20,COBBLESTONE:0,100)
RandomBlock(-3,7,-6,contenttweaker:reinforced_concrete,40,SMOOTH_BRICK:1,30,SMOOTH_BRICK:2,30,SMOOTH_STAIRS:0,15,SMOOTH_STAIRS:1,15,SMOOTH_STAIRS:2,15,SMOOTH_STAIRS:3,15,STEP:5,15,STEP:13,15,COBBLE_WALL:0,10,COBBLESTONE_STAIRS:0,10,STEP:3,10,COBBLE_WALL:1,20,COBBLESTONE_STAIRS:2,20,COBBLESTONE_STAIRS:3,20,MOSSY_COBBLESTONE:0,60,COBBLESTONE_STAIRS:1,20,STEP:11,20,COBBLESTONE:0,100)
RandomBlock(-3,7,-5,contenttweaker:reinforced_concrete,40,SMOOTH_BRICK:1,30,SMOOTH_BRICK:2,30,SMOOTH_STAIRS:0,15,SMOOTH_STAIRS:1,15,SMOOTH_STAIRS:2,15,SMOOTH_STAIRS:3,15,STEP:5,15,STEP:13,15,COBBLE_WALL:0,10,COBBLESTONE_STAIRS:0,10,STEP:3,10,COBBLE_WALL:1,20,COBBLESTONE_STAIRS:2,20,COBBLESTONE_STAIRS:3,20,MOSSY_COBBLESTONE:0,60,COBBLESTONE_STAIRS:1,20,STEP:11,20,COBBLESTONE:0,100)
RandomBlock(-3,7,-4,contenttweaker:reinforced_concrete,40,SMOOTH_BRICK:1,30,SMOOTH_BRICK:2,30,SMOOTH_STAIRS:0,15,SMOOTH_STAIRS:1,15,SMOOTH_STAIRS:2,15,SMOOTH_STAIRS:3,15,STEP:5,15,STEP:13,15,COBBLE_WALL:0,10,COBBLESTONE_STAIRS:0,10,STEP:3,10,COBBLE_WALL:1,20,COBBLESTONE_STAIRS:2,20,COBBLESTONE_STAIRS:3,20,MOSSY_COBBLESTONE:0,60,COBBLESTONE_STAIRS:1,20,STEP:11,20,COBBLESTONE:0,100)
RandomBlock(-3,7,-3,contenttweaker:reinforced_concrete,30,quark:limestone_wall,10,contenttweaker:reinforced_concrete,100)
Block(-3,8,-5,VINE:1)
RandomBlock(-3,8,-4,RUSTIC:IRON_LATTICE:0,30,RUSTIC:IRON_LATTICE:1,100)
Block(-3,9,-5,VINE:1)
RandomBlock(-3,9,-4,RUSTIC:IRON_LATTICE:0,30,RUSTIC:IRON_LATTICE:1,100)
Block(-3,10,-5,VINE:1)
RandomBlock(-3,10,-4,RUSTIC:IRON_LATTICE:0,30,RUSTIC:IRON_LATTICE:1,100)
RandomBlock(-3,10,-3,contenttweaker:reinforced_concrete,30,quark:limestone_wall,10,contenttweaker:reinforced_concrete,100)
Block(-3,11,-7,VINE:1)
Block(-3,11,-5,VINE:1)
RandomBlock(-3,11,-3,contenttweaker:reinforced_concrete,30,quark:limestone_wall,10,contenttweaker:reinforced_concrete,100)
Block(-3,12,-7,VINE:1)
Block(-3,12,-5,VINE:1)
RandomBlock(-3,12,-4,contenttweaker:reinforced_concrete,30,quark:limestone_wall,10,contenttweaker:reinforced_concrete,100)
Block(-3,13,-7,VINE:1)
Block(-3,13,-5,VINE:1)
RandomBlock(-3,13,-4,contenttweaker:reinforced_concrete,30,quark:limestone_wall,10,contenttweaker:reinforced_concrete,100)
Block(-3,14,-7,VINE:1)
RandomBlock(-3,14,-5,contenttweaker:reinforced_concrete,30,quark:limestone_wall,10,contenttweaker:reinforced_concrete,100)
Block(-3,15,-7,VINE:3)
RandomBlock(-3,15,-5,contenttweaker:reinforced_concrete,30,quark:limestone_wall,10,contenttweaker:reinforced_concrete,100)
Block(-3,16,-7,VINE:3)
RandomBlock(-3,16,-6,contenttweaker:reinforced_concrete,30,quark:limestone_wall,10,contenttweaker:reinforced_concrete,100)
Block(-3,17,-7,VINE:3)
RandomBlock(-3,17,-6,contenttweaker:reinforced_concrete,30,quark:limestone_wall,10,contenttweaker:reinforced_concrete,100)
Block(-3,18,-7,VINE:3)
RandomBlock(-3,18,-6,contenttweaker:reinforced_concrete,30,quark:limestone_wall,10,contenttweaker:reinforced_concrete,100)
Block(-3,19,-7,VINE:3)
RandomBlock(-3,19,-6,contenttweaker:reinforced_concrete,30,quark:limestone_wall,10,contenttweaker:reinforced_concrete,100)
RandomBlock(-3,20,-7,contenttweaker:reinforced_concrete,30,quark:limestone_wall,10,contenttweaker:reinforced_concrete,100)
RandomBlock(-3,21,-7,contenttweaker:reinforced_concrete,30,quark:limestone_wall,10,contenttweaker:reinforced_concrete,100)
RandomBlock(-3,22,-7,contenttweaker:reinforced_concrete,30,quark:limestone_wall,10,contenttweaker:reinforced_concrete,100)
Block(-3,22,-5,VINE:8)
RandomBlock(-3,23,-7,contenttweaker:reinforced_concrete,30,quark:limestone_wall,10,contenttweaker:reinforced_concrete,100)
Block(-3,23,-5,VINE:8)
RandomBlock(-3,24,-6,contenttweaker:reinforced_concrete,30,quark:limestone_wall,10,contenttweaker:reinforced_concrete,100)
Block(-3,24,-5,VINE:12)
RandomBlock(-3,25,-6,contenttweaker:reinforced_concrete,30,quark:limestone_wall,10,contenttweaker:reinforced_concrete,100)
Block(-3,25,-5,VINE:8)
RandomBlock(-3,26,-5,contenttweaker:reinforced_concrete,30,quark:limestone_wall,10,contenttweaker:reinforced_concrete,100)
Block(-3,26,-3,VINE:8)
RandomBlock(-3,27,-5,contenttweaker:reinforced_concrete,30,quark:limestone_wall,10,contenttweaker:reinforced_concrete,100)
Block(-3,27,-3,VINE:8)
RandomBlock(-3,28,-4,contenttweaker:reinforced_concrete,30,quark:limestone_wall,10,contenttweaker:reinforced_concrete,100)
Block(-3,28,-3,VINE:8)
RandomBlock(-3,29,-4,RUSTIC:IRON_LATTICE:0,30,RUSTIC:IRON_LATTICE:1,100)
RandomBlock(-3,30,-4,RUSTIC:IRON_LATTICE:0,30,RUSTIC:IRON_LATTICE:1,100)
RandomBlock(-2,0,-7,contenttweaker:reinforced_concrete,40,SMOOTH_BRICK:1,30,SMOOTH_BRICK:2,30,SMOOTH_STAIRS:0,15,SMOOTH_STAIRS:1,15,SMOOTH_STAIRS:2,15,SMOOTH_STAIRS:3,15,STEP:5,15,STEP:13,15,COBBLE_WALL:0,10,COBBLESTONE_STAIRS:0,10,STEP:3,10,COBBLE_WALL:1,20,COBBLESTONE_STAIRS:2,20,COBBLESTONE_STAIRS:3,20,MOSSY_COBBLESTONE:0,60,COBBLESTONE_STAIRS:1,20,STEP:11,20,COBBLESTONE:0,100)
RandomBlock(-2,0,-6,contenttweaker:reinforced_concrete,40,SMOOTH_BRICK:1,30,SMOOTH_BRICK:2,30,SMOOTH_STAIRS:0,15,SMOOTH_STAIRS:1,15,SMOOTH_STAIRS:2,15,SMOOTH_STAIRS:3,15,STEP:5,15,STEP:13,15,COBBLE_WALL:0,10,COBBLESTONE_STAIRS:0,10,STEP:3,10,COBBLE_WALL:1,20,COBBLESTONE_STAIRS:2,20,COBBLESTONE_STAIRS:3,20,MOSSY_COBBLESTONE:0,60,COBBLESTONE_STAIRS:1,20,STEP:11,20,COBBLESTONE:0,100)
RandomBlock(-2,0,-5,contenttweaker:reinforced_concrete,40,SMOOTH_BRICK:1,30,SMOOTH_BRICK:2,30,SMOOTH_STAIRS:0,15,SMOOTH_STAIRS:1,15,SMOOTH_STAIRS:2,15,SMOOTH_STAIRS:3,15,STEP:5,15,STEP:13,15,COBBLE_WALL:0,10,COBBLESTONE_STAIRS:0,10,STEP:3,10,COBBLE_WALL:1,20,COBBLESTONE_STAIRS:2,20,COBBLESTONE_STAIRS:3,20,MOSSY_COBBLESTONE:0,60,COBBLESTONE_STAIRS:1,20,STEP:11,20,COBBLESTONE:0,100)
RandomBlock(-2,0,-4,contenttweaker:reinforced_concrete,40,SMOOTH_BRICK:1,30,SMOOTH_BRICK:2,30,SMOOTH_STAIRS:0,15,SMOOTH_STAIRS:1,15,SMOOTH_STAIRS:2,15,SMOOTH_STAIRS:3,15,STEP:5,15,STEP:13,15,COBBLE_WALL:0,10,COBBLESTONE_STAIRS:0,10,STEP:3,10,COBBLE_WALL:1,20,COBBLESTONE_STAIRS:2,20,COBBLESTONE_STAIRS:3,20,MOSSY_COBBLESTONE:0,60,COBBLESTONE_STAIRS:1,20,STEP:11,20,COBBLESTONE:0,100)
RandomBlock(-2,0,-3,contenttweaker:reinforced_concrete,40,SMOOTH_BRICK:1,30,SMOOTH_BRICK:2,30,SMOOTH_STAIRS:0,15,SMOOTH_STAIRS:1,15,SMOOTH_STAIRS:2,15,SMOOTH_STAIRS:3,15,STEP:5,15,STEP:13,15,COBBLE_WALL:0,10,COBBLESTONE_STAIRS:0,10,STEP:3,10,COBBLE_WALL:1,20,COBBLESTONE_STAIRS:2,20,COBBLESTONE_STAIRS:3,20,MOSSY_COBBLESTONE:0,60,COBBLESTONE_STAIRS:1,20,STEP:11,20,COBBLESTONE:0,100)
RandomBlock(-2,0,-2,contenttweaker:reinforced_concrete,40,SMOOTH_BRICK:1,30,SMOOTH_BRICK:2,30,SMOOTH_STAIRS:0,15,SMOOTH_STAIRS:1,15,SMOOTH_STAIRS:2,15,SMOOTH_STAIRS:3,15,STEP:5,15,STEP:13,15,COBBLE_WALL:0,10,COBBLESTONE_STAIRS:0,10,STEP:3,10,COBBLE_WALL:1,20,COBBLESTONE_STAIRS:2,20,COBBLESTONE_STAIRS:3,20,MOSSY_COBBLESTONE:0,60,COBBLESTONE_STAIRS:1,20,STEP:11,20,COBBLESTONE:0,100)
RandomBlock(-2,1,-7,contenttweaker:reinforced_concrete,40,SMOOTH_BRICK:1,30,SMOOTH_BRICK:2,30,SMOOTH_STAIRS:0,15,SMOOTH_STAIRS:1,15,SMOOTH_STAIRS:2,15,SMOOTH_STAIRS:3,15,STEP:5,15,STEP:13,15,COBBLE_WALL:0,10,COBBLESTONE_STAIRS:0,10,STEP:3,10,COBBLE_WALL:1,20,COBBLESTONE_STAIRS:2,20,COBBLESTONE_STAIRS:3,20,MOSSY_COBBLESTONE:0,60,COBBLESTONE_STAIRS:1,20,STEP:11,20,COBBLESTONE:0,100)
RandomBlock(-2,1,-6,contenttweaker:reinforced_concrete,40,SMOOTH_BRICK:1,30,SMOOTH_BRICK:2,30,SMOOTH_STAIRS:0,15,SMOOTH_STAIRS:1,15,SMOOTH_STAIRS:2,15,SMOOTH_STAIRS:3,15,STEP:5,15,STEP:13,15,COBBLE_WALL:0,10,COBBLESTONE_STAIRS:0,10,STEP:3,10,COBBLE_WALL:1,20,COBBLESTONE_STAIRS:2,20,COBBLESTONE_STAIRS:3,20,MOSSY_COBBLESTONE:0,60,COBBLESTONE_STAIRS:1,20,STEP:11,20,COBBLESTONE:0,100)
RandomBlock(-2,1,-5,contenttweaker:reinforced_concrete,40,SMOOTH_BRICK:1,30,SMOOTH_BRICK:2,30,SMOOTH_STAIRS:0,15,SMOOTH_STAIRS:1,15,SMOOTH_STAIRS:2,15,SMOOTH_STAIRS:3,15,STEP:5,15,STEP:13,15,COBBLE_WALL:0,10,COBBLESTONE_STAIRS:0,10,STEP:3,10,COBBLE_WALL:1,20,COBBLESTONE_STAIRS:2,20,COBBLESTONE_STAIRS:3,20,MOSSY_COBBLESTONE:0,60,COBBLESTONE_STAIRS:1,20,STEP:11,20,COBBLESTONE:0,100)
RandomBlock(-2,1,-4,contenttweaker:reinforced_concrete,40,SMOOTH_BRICK:1,30,SMOOTH_BRICK:2,30,SMOOTH_STAIRS:0,15,SMOOTH_STAIRS:1,15,SMOOTH_STAIRS:2,15,SMOOTH_STAIRS:3,15,STEP:5,15,STEP:13,15,COBBLE_WALL:0,10,COBBLESTONE_STAIRS:0,10,STEP:3,10,COBBLE_WALL:1,20,COBBLESTONE_STAIRS:2,20,COBBLESTONE_STAIRS:3,20,MOSSY_COBBLESTONE:0,60,COBBLESTONE_STAIRS:1,20,STEP:11,20,COBBLESTONE:0,100)
RandomBlock(-2,1,-3,contenttweaker:reinforced_concrete,40,SMOOTH_BRICK:1,30,SMOOTH_BRICK:2,30,SMOOTH_STAIRS:0,15,SMOOTH_STAIRS:1,15,SMOOTH_STAIRS:2,15,SMOOTH_STAIRS:3,15,STEP:5,15,STEP:13,15,COBBLE_WALL:0,10,COBBLESTONE_STAIRS:0,10,STEP:3,10,COBBLE_WALL:1,20,COBBLESTONE_STAIRS:2,20,COBBLESTONE_STAIRS:3,20,MOSSY_COBBLESTONE:0,60,COBBLESTONE_STAIRS:1,20,STEP:11,20,COBBLESTONE:0,100)
RandomBlock(-2,1,-2,contenttweaker:reinforced_concrete,40,SMOOTH_BRICK:1,30,SMOOTH_BRICK:2,30,SMOOTH_STAIRS:0,15,SMOOTH_STAIRS:1,15,SMOOTH_STAIRS:2,15,SMOOTH_STAIRS:3,15,STEP:5,15,STEP:13,15,COBBLE_WALL:0,10,COBBLESTONE_STAIRS:0,10,STEP:3,10,COBBLE_WALL:1,20,COBBLESTONE_STAIRS:2,20,COBBLESTONE_STAIRS:3,20,MOSSY_COBBLESTONE:0,60,COBBLESTONE_STAIRS:1,20,STEP:11,20,COBBLESTONE:0,100)
RandomBlock(-2,2,-7,contenttweaker:reinforced_concrete,40,SMOOTH_BRICK:1,30,SMOOTH_BRICK:2,30,SMOOTH_STAIRS:0,15,SMOOTH_STAIRS:1,15,SMOOTH_STAIRS:2,15,SMOOTH_STAIRS:3,15,STEP:5,15,STEP:13,15,COBBLE_WALL:0,10,COBBLESTONE_STAIRS:0,10,STEP:3,10,COBBLE_WALL:1,20,COBBLESTONE_STAIRS:2,20,COBBLESTONE_STAIRS:3,20,MOSSY_COBBLESTONE:0,60,COBBLESTONE_STAIRS:1,20,STEP:11,20,COBBLESTONE:0,100)
RandomBlock(-2,2,-6,contenttweaker:reinforced_concrete,40,SMOOTH_BRICK:1,30,SMOOTH_BRICK:2,30,SMOOTH_STAIRS:0,15,SMOOTH_STAIRS:1,15,SMOOTH_STAIRS:2,15,SMOOTH_STAIRS:3,15,STEP:5,15,STEP:13,15,COBBLE_WALL:0,10,COBBLESTONE_STAIRS:0,10,STEP:3,10,COBBLE_WALL:1,20,COBBLESTONE_STAIRS:2,20,COBBLESTONE_STAIRS:3,20,MOSSY_COBBLESTONE:0,60,COBBLESTONE_STAIRS:1,20,STEP:11,20,COBBLESTONE:0,100)
RandomBlock(-2,2,-5,contenttweaker:reinforced_concrete,40,SMOOTH_BRICK:1,30,SMOOTH_BRICK:2,30,SMOOTH_STAIRS:0,15,SMOOTH_STAIRS:1,15,SMOOTH_STAIRS:2,15,SMOOTH_STAIRS:3,15,STEP:5,15,STEP:13,15,COBBLE_WALL:0,10,COBBLESTONE_STAIRS:0,10,STEP:3,10,COBBLE_WALL:1,20,COBBLESTONE_STAIRS:2,20,COBBLESTONE_STAIRS:3,20,MOSSY_COBBLESTONE:0,60,COBBLESTONE_STAIRS:1,20,STEP:11,20,COBBLESTONE:0,100)
RandomBlock(-2,2,-4,contenttweaker:reinforced_concrete,40,SMOOTH_BRICK:1,30,SMOOTH_BRICK:2,30,SMOOTH_STAIRS:0,15,SMOOTH_STAIRS:1,15,SMOOTH_STAIRS:2,15,SMOOTH_STAIRS:3,15,STEP:5,15,STEP:13,15,COBBLE_WALL:0,10,COBBLESTONE_STAIRS:0,10,STEP:3,10,COBBLE_WALL:1,20,COBBLESTONE_STAIRS:2,20,COBBLESTONE_STAIRS:3,20,MOSSY_COBBLESTONE:0,60,COBBLESTONE_STAIRS:1,20,STEP:11,20,COBBLESTONE:0,100)
RandomBlock(-2,2,-3,contenttweaker:reinforced_concrete,40,SMOOTH_BRICK:1,30,SMOOTH_BRICK:2,30,SMOOTH_STAIRS:0,15,SMOOTH_STAIRS:1,15,SMOOTH_STAIRS:2,15,SMOOTH_STAIRS:3,15,STEP:5,15,STEP:13,15,COBBLE_WALL:0,10,COBBLESTONE_STAIRS:0,10,STEP:3,10,COBBLE_WALL:1,20,COBBLESTONE_STAIRS:2,20,COBBLESTONE_STAIRS:3,20,MOSSY_COBBLESTONE:0,60,COBBLESTONE_STAIRS:1,20,STEP:11,20,COBBLESTONE:0,100)
RandomBlock(-2,2,-2,contenttweaker:reinforced_concrete,40,SMOOTH_BRICK:1,30,SMOOTH_BRICK:2,30,SMOOTH_STAIRS:0,15,SMOOTH_STAIRS:1,15,SMOOTH_STAIRS:2,15,SMOOTH_STAIRS:3,15,STEP:5,15,STEP:13,15,COBBLE_WALL:0,10,COBBLESTONE_STAIRS:0,10,STEP:3,10,COBBLE_WALL:1,20,COBBLESTONE_STAIRS:2,20,COBBLESTONE_STAIRS:3,20,MOSSY_COBBLESTONE:0,60,COBBLESTONE_STAIRS:1,20,STEP:11,20,COBBLESTONE:0,100)
RandomBlock(-2,3,-7,contenttweaker:reinforced_concrete,40,SMOOTH_BRICK:1,30,SMOOTH_BRICK:2,30,SMOOTH_STAIRS:0,15,SMOOTH_STAIRS:1,15,SMOOTH_STAIRS:2,15,SMOOTH_STAIRS:3,15,STEP:5,15,STEP:13,15,COBBLE_WALL:0,10,COBBLESTONE_STAIRS:0,10,STEP:3,10,COBBLE_WALL:1,20,COBBLESTONE_STAIRS:2,20,COBBLESTONE_STAIRS:3,20,MOSSY_COBBLESTONE:0,60,COBBLESTONE_STAIRS:1,20,STEP:11,20,COBBLESTONE:0,100)
RandomBlock(-2,3,-6,contenttweaker:reinforced_concrete,40,SMOOTH_BRICK:1,30,SMOOTH_BRICK:2,30,SMOOTH_STAIRS:0,15,SMOOTH_STAIRS:1,15,SMOOTH_STAIRS:2,15,SMOOTH_STAIRS:3,15,STEP:5,15,STEP:13,15,COBBLE_WALL:0,10,COBBLESTONE_STAIRS:0,10,STEP:3,10,COBBLE_WALL:1,20,COBBLESTONE_STAIRS:2,20,COBBLESTONE_STAIRS:3,20,MOSSY_COBBLESTONE:0,60,COBBLESTONE_STAIRS:1,20,STEP:11,20,COBBLESTONE:0,100)
RandomBlock(-2,3,-5,contenttweaker:reinforced_concrete,40,SMOOTH_BRICK:1,30,SMOOTH_BRICK:2,30,SMOOTH_STAIRS:0,15,SMOOTH_STAIRS:1,15,SMOOTH_STAIRS:2,15,SMOOTH_STAIRS:3,15,STEP:5,15,STEP:13,15,COBBLE_WALL:0,10,COBBLESTONE_STAIRS:0,10,STEP:3,10,COBBLE_WALL:1,20,COBBLESTONE_STAIRS:2,20,COBBLESTONE_STAIRS:3,20,MOSSY_COBBLESTONE:0,60,COBBLESTONE_STAIRS:1,20,STEP:11,20,COBBLESTONE:0,100)
RandomBlock(-2,3,-4,contenttweaker:reinforced_concrete,40,SMOOTH_BRICK:1,30,SMOOTH_BRICK:2,30,SMOOTH_STAIRS:0,15,SMOOTH_STAIRS:1,15,SMOOTH_STAIRS:2,15,SMOOTH_STAIRS:3,15,STEP:5,15,STEP:13,15,COBBLE_WALL:0,10,COBBLESTONE_STAIRS:0,10,STEP:3,10,COBBLE_WALL:1,20,COBBLESTONE_STAIRS:2,20,COBBLESTONE_STAIRS:3,20,MOSSY_COBBLESTONE:0,60,COBBLESTONE_STAIRS:1,20,STEP:11,20,COBBLESTONE:0,100)
RandomBlock(-2,3,-3,contenttweaker:reinforced_concrete,40,SMOOTH_BRICK:1,30,SMOOTH_BRICK:2,30,SMOOTH_STAIRS:0,15,SMOOTH_STAIRS:1,15,SMOOTH_STAIRS:2,15,SMOOTH_STAIRS:3,15,STEP:5,15,STEP:13,15,COBBLE_WALL:0,10,COBBLESTONE_STAIRS:0,10,STEP:3,10,COBBLE_WALL:1,20,COBBLESTONE_STAIRS:2,20,COBBLESTONE_STAIRS:3,20,MOSSY_COBBLESTONE:0,60,COBBLESTONE_STAIRS:1,20,STEP:11,20,COBBLESTONE:0,100)
RandomBlock(-2,3,-2,contenttweaker:reinforced_concrete,40,SMOOTH_BRICK:1,30,SMOOTH_BRICK:2,30,SMOOTH_STAIRS:0,15,SMOOTH_STAIRS:1,15,SMOOTH_STAIRS:2,15,SMOOTH_STAIRS:3,15,STEP:5,15,STEP:13,15,COBBLE_WALL:0,10,COBBLESTONE_STAIRS:0,10,STEP:3,10,COBBLE_WALL:1,20,COBBLESTONE_STAIRS:2,20,COBBLESTONE_STAIRS:3,20,MOSSY_COBBLESTONE:0,60,COBBLESTONE_STAIRS:1,20,STEP:11,20,COBBLESTONE:0,100)
RandomBlock(-2,4,-7,contenttweaker:reinforced_concrete,40,SMOOTH_BRICK:1,30,SMOOTH_BRICK:2,30,SMOOTH_STAIRS:0,15,SMOOTH_STAIRS:1,15,SMOOTH_STAIRS:2,15,SMOOTH_STAIRS:3,15,STEP:5,15,STEP:13,15,COBBLE_WALL:0,10,COBBLESTONE_STAIRS:0,10,STEP:3,10,COBBLE_WALL:1,20,COBBLESTONE_STAIRS:2,20,COBBLESTONE_STAIRS:3,20,MOSSY_COBBLESTONE:0,60,COBBLESTONE_STAIRS:1,20,STEP:11,20,COBBLESTONE:0,100)
RandomBlock(-2,4,-6,contenttweaker:reinforced_concrete,40,SMOOTH_BRICK:1,30,SMOOTH_BRICK:2,30,SMOOTH_STAIRS:0,15,SMOOTH_STAIRS:1,15,SMOOTH_STAIRS:2,15,SMOOTH_STAIRS:3,15,STEP:5,15,STEP:13,15,COBBLE_WALL:0,10,COBBLESTONE_STAIRS:0,10,STEP:3,10,COBBLE_WALL:1,20,COBBLESTONE_STAIRS:2,20,COBBLESTONE_STAIRS:3,20,MOSSY_COBBLESTONE:0,60,COBBLESTONE_STAIRS:1,20,STEP:11,20,COBBLESTONE:0,100)
RandomBlock(-2,4,-5,contenttweaker:reinforced_concrete,40,SMOOTH_BRICK:1,30,SMOOTH_BRICK:2,30,SMOOTH_STAIRS:0,15,SMOOTH_STAIRS:1,15,SMOOTH_STAIRS:2,15,SMOOTH_STAIRS:3,15,STEP:5,15,STEP:13,15,COBBLE_WALL:0,10,COBBLESTONE_STAIRS:0,10,STEP:3,10,COBBLE_WALL:1,20,COBBLESTONE_STAIRS:2,20,COBBLESTONE_STAIRS:3,20,MOSSY_COBBLESTONE:0,60,COBBLESTONE_STAIRS:1,20,STEP:11,20,COBBLESTONE:0,100)
RandomBlock(-2,4,-4,contenttweaker:reinforced_concrete,40,SMOOTH_BRICK:1,30,SMOOTH_BRICK:2,30,SMOOTH_STAIRS:0,15,SMOOTH_STAIRS:1,15,SMOOTH_STAIRS:2,15,SMOOTH_STAIRS:3,15,STEP:5,15,STEP:13,15,COBBLE_WALL:0,10,COBBLESTONE_STAIRS:0,10,STEP:3,10,COBBLE_WALL:1,20,COBBLESTONE_STAIRS:2,20,COBBLESTONE_STAIRS:3,20,MOSSY_COBBLESTONE:0,60,COBBLESTONE_STAIRS:1,20,STEP:11,20,COBBLESTONE:0,100)
RandomBlock(-2,4,-3,contenttweaker:reinforced_concrete,40,SMOOTH_BRICK:1,30,SMOOTH_BRICK:2,30,SMOOTH_STAIRS:0,15,SMOOTH_STAIRS:1,15,SMOOTH_STAIRS:2,15,SMOOTH_STAIRS:3,15,STEP:5,15,STEP:13,15,COBBLE_WALL:0,10,COBBLESTONE_STAIRS:0,10,STEP:3,10,COBBLE_WALL:1,20,COBBLESTONE_STAIRS:2,20,COBBLESTONE_STAIRS:3,20,MOSSY_COBBLESTONE:0,60,COBBLESTONE_STAIRS:1,20,STEP:11,20,COBBLESTONE:0,100)
RandomBlock(-2,4,-2,contenttweaker:reinforced_concrete,40,SMOOTH_BRICK:1,30,SMOOTH_BRICK:2,30,SMOOTH_STAIRS:0,15,SMOOTH_STAIRS:1,15,SMOOTH_STAIRS:2,15,SMOOTH_STAIRS:3,15,STEP:5,15,STEP:13,15,COBBLE_WALL:0,10,COBBLESTONE_STAIRS:0,10,STEP:3,10,COBBLE_WALL:1,20,COBBLESTONE_STAIRS:2,20,COBBLESTONE_STAIRS:3,20,MOSSY_COBBLESTONE:0,60,COBBLESTONE_STAIRS:1,20,STEP:11,20,COBBLESTONE:0,100)
RandomBlock(-2,5,-7,contenttweaker:reinforced_concrete,40,SMOOTH_BRICK:1,30,SMOOTH_BRICK:2,30,SMOOTH_STAIRS:0,15,SMOOTH_STAIRS:1,15,SMOOTH_STAIRS:2,15,SMOOTH_STAIRS:3,15,STEP:5,15,STEP:13,15,COBBLE_WALL:0,10,COBBLESTONE_STAIRS:0,10,STEP:3,10,COBBLE_WALL:1,20,COBBLESTONE_STAIRS:2,20,COBBLESTONE_STAIRS:3,20,MOSSY_COBBLESTONE:0,60,COBBLESTONE_STAIRS:1,20,STEP:11,20,COBBLESTONE:0,100)
RandomBlock(-2,5,-6,contenttweaker:reinforced_concrete,40,SMOOTH_BRICK:1,30,SMOOTH_BRICK:2,30,SMOOTH_STAIRS:0,15,SMOOTH_STAIRS:1,15,SMOOTH_STAIRS:2,15,SMOOTH_STAIRS:3,15,STEP:5,15,STEP:13,15,COBBLE_WALL:0,10,COBBLESTONE_STAIRS:0,10,STEP:3,10,COBBLE_WALL:1,20,COBBLESTONE_STAIRS:2,20,COBBLESTONE_STAIRS:3,20,MOSSY_COBBLESTONE:0,60,COBBLESTONE_STAIRS:1,20,STEP:11,20,COBBLESTONE:0,100)
RandomBlock(-2,5,-5,contenttweaker:reinforced_concrete,40,SMOOTH_BRICK:1,30,SMOOTH_BRICK:2,30,SMOOTH_STAIRS:0,15,SMOOTH_STAIRS:1,15,SMOOTH_STAIRS:2,15,SMOOTH_STAIRS:3,15,STEP:5,15,STEP:13,15,COBBLE_WALL:0,10,COBBLESTONE_STAIRS:0,10,STEP:3,10,COBBLE_WALL:1,20,COBBLESTONE_STAIRS:2,20,COBBLESTONE_STAIRS:3,20,MOSSY_COBBLESTONE:0,60,COBBLESTONE_STAIRS:1,20,STEP:11,20,COBBLESTONE:0,100)
RandomBlock(-2,5,-4,contenttweaker:reinforced_concrete,40,SMOOTH_BRICK:1,30,SMOOTH_BRICK:2,30,SMOOTH_STAIRS:0,15,SMOOTH_STAIRS:1,15,SMOOTH_STAIRS:2,15,SMOOTH_STAIRS:3,15,STEP:5,15,STEP:13,15,COBBLE_WALL:0,10,COBBLESTONE_STAIRS:0,10,STEP:3,10,COBBLE_WALL:1,20,COBBLESTONE_STAIRS:2,20,COBBLESTONE_STAIRS:3,20,MOSSY_COBBLESTONE:0,60,COBBLESTONE_STAIRS:1,20,STEP:11,20,COBBLESTONE:0,100)
RandomBlock(-2,5,-3,contenttweaker:reinforced_concrete,40,SMOOTH_BRICK:1,30,SMOOTH_BRICK:2,30,SMOOTH_STAIRS:0,15,SMOOTH_STAIRS:1,15,SMOOTH_STAIRS:2,15,SMOOTH_STAIRS:3,15,STEP:5,15,STEP:13,15,COBBLE_WALL:0,10,COBBLESTONE_STAIRS:0,10,STEP:3,10,COBBLE_WALL:1,20,COBBLESTONE_STAIRS:2,20,COBBLESTONE_STAIRS:3,20,MOSSY_COBBLESTONE:0,60,COBBLESTONE_STAIRS:1,20,STEP:11,20,COBBLESTONE:0,100)
RandomBlock(-2,5,-2,contenttweaker:reinforced_concrete,30,quark:limestone_wall,10,contenttweaker:reinforced_concrete,100)
RandomBlock(-2,6,-7,contenttweaker:reinforced_concrete,40,SMOOTH_BRICK:1,30,SMOOTH_BRICK:2,30,SMOOTH_STAIRS:0,15,SMOOTH_STAIRS:1,15,SMOOTH_STAIRS:2,15,SMOOTH_STAIRS:3,15,STEP:5,15,STEP:13,15,COBBLE_WALL:0,10,COBBLESTONE_STAIRS:0,10,STEP:3,10,COBBLE_WALL:1,20,COBBLESTONE_STAIRS:2,20,COBBLESTONE_STAIRS:3,20,MOSSY_COBBLESTONE:0,60,COBBLESTONE_STAIRS:1,20,STEP:11,20,COBBLESTONE:0,100)
RandomBlock(-2,6,-6,contenttweaker:reinforced_concrete,40,SMOOTH_BRICK:1,30,SMOOTH_BRICK:2,30,SMOOTH_STAIRS:0,15,SMOOTH_STAIRS:1,15,SMOOTH_STAIRS:2,15,SMOOTH_STAIRS:3,15,STEP:5,15,STEP:13,15,COBBLE_WALL:0,10,COBBLESTONE_STAIRS:0,10,STEP:3,10,COBBLE_WALL:1,20,COBBLESTONE_STAIRS:2,20,COBBLESTONE_STAIRS:3,20,MOSSY_COBBLESTONE:0,60,COBBLESTONE_STAIRS:1,20,STEP:11,20,COBBLESTONE:0,100)
RandomBlock(-2,6,-5,contenttweaker:reinforced_concrete,40,SMOOTH_BRICK:1,30,SMOOTH_BRICK:2,30,SMOOTH_STAIRS:0,15,SMOOTH_STAIRS:1,15,SMOOTH_STAIRS:2,15,SMOOTH_STAIRS:3,15,STEP:5,15,STEP:13,15,COBBLE_WALL:0,10,COBBLESTONE_STAIRS:0,10,STEP:3,10,COBBLE_WALL:1,20,COBBLESTONE_STAIRS:2,20,COBBLESTONE_STAIRS:3,20,MOSSY_COBBLESTONE:0,60,COBBLESTONE_STAIRS:1,20,STEP:11,20,COBBLESTONE:0,100)
RandomBlock(-2,6,-4,contenttweaker:reinforced_concrete,40,SMOOTH_BRICK:1,30,SMOOTH_BRICK:2,30,SMOOTH_STAIRS:0,15,SMOOTH_STAIRS:1,15,SMOOTH_STAIRS:2,15,SMOOTH_STAIRS:3,15,STEP:5,15,STEP:13,15,COBBLE_WALL:0,10,COBBLESTONE_STAIRS:0,10,STEP:3,10,COBBLE_WALL:1,20,COBBLESTONE_STAIRS:2,20,COBBLESTONE_STAIRS:3,20,MOSSY_COBBLESTONE:0,60,COBBLESTONE_STAIRS:1,20,STEP:11,20,COBBLESTONE:0,100)
RandomBlock(-2,6,-3,contenttweaker:reinforced_concrete,40,SMOOTH_BRICK:1,30,SMOOTH_BRICK:2,30,SMOOTH_STAIRS:0,15,SMOOTH_STAIRS:1,15,SMOOTH_STAIRS:2,15,SMOOTH_STAIRS:3,15,STEP:5,15,STEP:13,15,COBBLE_WALL:0,10,COBBLESTONE_STAIRS:0,10,STEP:3,10,COBBLE_WALL:1,20,COBBLESTONE_STAIRS:2,20,COBBLESTONE_STAIRS:3,20,MOSSY_COBBLESTONE:0,60,COBBLESTONE_STAIRS:1,20,STEP:11,20,COBBLESTONE:0,100)
RandomBlock(-2,6,-2,contenttweaker:reinforced_concrete,30,quark:limestone_wall,10,contenttweaker:reinforced_concrete,100)
RandomBlock(-2,7,-7,contenttweaker:reinforced_concrete,40,SMOOTH_BRICK:1,30,SMOOTH_BRICK:2,30,SMOOTH_STAIRS:0,15,SMOOTH_STAIRS:1,15,SMOOTH_STAIRS:2,15,SMOOTH_STAIRS:3,15,STEP:5,15,STEP:13,15,COBBLE_WALL:0,10,COBBLESTONE_STAIRS:0,10,STEP:3,10,COBBLE_WALL:1,20,COBBLESTONE_STAIRS:2,20,COBBLESTONE_STAIRS:3,20,MOSSY_COBBLESTONE:0,60,COBBLESTONE_STAIRS:1,20,STEP:11,20,COBBLESTONE:0,100)
RandomBlock(-2,7,-6,contenttweaker:reinforced_concrete,40,SMOOTH_BRICK:1,30,SMOOTH_BRICK:2,30,SMOOTH_STAIRS:0,15,SMOOTH_STAIRS:1,15,SMOOTH_STAIRS:2,15,SMOOTH_STAIRS:3,15,STEP:5,15,STEP:13,15,COBBLE_WALL:0,10,COBBLESTONE_STAIRS:0,10,STEP:3,10,COBBLE_WALL:1,20,COBBLESTONE_STAIRS:2,20,COBBLESTONE_STAIRS:3,20,MOSSY_COBBLESTONE:0,60,COBBLESTONE_STAIRS:1,20,STEP:11,20,COBBLESTONE:0,100)
RandomBlock(-2,7,-5,contenttweaker:reinforced_concrete,40,SMOOTH_BRICK:1,30,SMOOTH_BRICK:2,30,SMOOTH_STAIRS:0,15,SMOOTH_STAIRS:1,15,SMOOTH_STAIRS:2,15,SMOOTH_STAIRS:3,15,STEP:5,15,STEP:13,15,COBBLE_WALL:0,10,COBBLESTONE_STAIRS:0,10,STEP:3,10,COBBLE_WALL:1,20,COBBLESTONE_STAIRS:2,20,COBBLESTONE_STAIRS:3,20,MOSSY_COBBLESTONE:0,60,COBBLESTONE_STAIRS:1,20,STEP:11,20,COBBLESTONE:0,100)
RandomBlock(-2,7,-4,contenttweaker:reinforced_concrete,40,SMOOTH_BRICK:1,30,SMOOTH_BRICK:2,30,SMOOTH_STAIRS:0,15,SMOOTH_STAIRS:1,15,SMOOTH_STAIRS:2,15,SMOOTH_STAIRS:3,15,STEP:5,15,STEP:13,15,COBBLE_WALL:0,10,COBBLESTONE_STAIRS:0,10,STEP:3,10,COBBLE_WALL:1,20,COBBLESTONE_STAIRS:2,20,COBBLESTONE_STAIRS:3,20,MOSSY_COBBLESTONE:0,60,COBBLESTONE_STAIRS:1,20,STEP:11,20,COBBLESTONE:0,100)
RandomBlock(-2,7,-3,contenttweaker:reinforced_concrete,40,SMOOTH_BRICK:1,30,SMOOTH_BRICK:2,30,SMOOTH_STAIRS:0,15,SMOOTH_STAIRS:1,15,SMOOTH_STAIRS:2,15,SMOOTH_STAIRS:3,15,STEP:5,15,STEP:13,15,COBBLE_WALL:0,10,COBBLESTONE_STAIRS:0,10,STEP:3,10,COBBLE_WALL:1,20,COBBLESTONE_STAIRS:2,20,COBBLESTONE_STAIRS:3,20,MOSSY_COBBLESTONE:0,60,COBBLESTONE_STAIRS:1,20,STEP:11,20,COBBLESTONE:0,100)
RandomBlock(-2,7,-2,contenttweaker:reinforced_concrete,30,quark:limestone_wall,10,contenttweaker:reinforced_concrete,100)
RandomBlock(-2,8,-4,RUSTIC:IRON_LATTICE:0,30,RUSTIC:IRON_LATTICE:1,100)
RandomBlock(-2,8,-3,RUSTIC:IRON_LATTICE:0,30,RUSTIC:IRON_LATTICE:1,100)
Block(-2,8,-2,inspirations:redstone_barrel)
RandomBlock(-2,9,-4,RUSTIC:IRON_LATTICE:0,30,RUSTIC:IRON_LATTICE:1,100)
RandomBlock(-2,9,-3,RUSTIC:IRON_LATTICE:0,30,RUSTIC:IRON_LATTICE:1,100)
Block(-2,9,-2,inspirations:redstone_barrel)
RandomBlock(-2,10,-4,RUSTIC:IRON_LATTICE:0,30,RUSTIC:IRON_LATTICE:1,100)
RandomBlock(-2,10,-3,RUSTIC:IRON_LATTICE:0,30,RUSTIC:IRON_LATTICE:1,100)
RandomBlock(-2,10,-2,contenttweaker:reinforced_concrete,30,quark:limestone_wall,10,contenttweaker:reinforced_concrete,100)
RandomBlock(-2,11,-2,contenttweaker:reinforced_concrete,30,quark:limestone_wall,10,contenttweaker:reinforced_concrete,100)
RandomBlock(-2,12,-3,contenttweaker:reinforced_concrete,30,quark:limestone_wall,10,contenttweaker:reinforced_concrete,100)
RandomBlock(-2,13,-3,contenttweaker:reinforced_concrete,30,quark:limestone_wall,10,contenttweaker:reinforced_concrete,100)
Block(-2,14,-6,VINE:2)
RandomBlock(-2,14,-4,contenttweaker:reinforced_concrete,30,quark:limestone_wall,10,contenttweaker:reinforced_concrete,100)
Block(-2,15,-6,VINE:2)
RandomBlock(-2,15,-4,contenttweaker:reinforced_concrete,30,quark:limestone_wall,10,contenttweaker:reinforced_concrete,100)
Block(-2,16,-6,VINE:2)
RandomBlock(-2,16,-5,contenttweaker:reinforced_concrete,30,quark:limestone_wall,10,contenttweaker:reinforced_concrete,100)
Block(-2,16,-4,VINE:12)
Block(-2,17,-6,VINE:2)
RandomBlock(-2,17,-5,contenttweaker:reinforced_concrete,30,quark:limestone_wall,10,contenttweaker:reinforced_concrete,100)
Block(-2,17,-4,VINE:12)
Block(-2,18,-6,VINE:2)
RandomBlock(-2,18,-5,contenttweaker:reinforced_concrete,30,quark:limestone_wall,10,contenttweaker:reinforced_concrete,100)
RandomBlock(-2,19,-5,contenttweaker:reinforced_concrete,30,quark:limestone_wall,10,contenttweaker:reinforced_concrete,100)
RandomBlock(-2,20,-6,contenttweaker:reinforced_concrete,30,quark:limestone_wall,10,contenttweaker:reinforced_concrete,100)
RandomBlock(-2,21,-6,contenttweaker:reinforced_concrete,30,quark:limestone_wall,10,contenttweaker:reinforced_concrete,100)
Block(-2,21,-4,VINE:4)
RandomBlock(-2,22,-6,contenttweaker:reinforced_concrete,30,quark:limestone_wall,10,contenttweaker:reinforced_concrete,100)
Block(-2,22,-4,VINE:12)
RandomBlock(-2,23,-6,contenttweaker:reinforced_concrete,30,quark:limestone_wall,10,contenttweaker:reinforced_concrete,100)
Block(-2,23,-4,VINE:12)
RandomBlock(-2,24,-5,contenttweaker:reinforced_concrete,30,quark:limestone_wall,10,contenttweaker:reinforced_concrete,100)
Block(-2,24,-4,VINE:12)
RandomBlock(-2,25,-5,contenttweaker:reinforced_concrete,30,quark:limestone_wall,10,contenttweaker:reinforced_concrete,100)
Block(-2,25,-4,VINE:12)
RandomBlock(-2,26,-4,contenttweaker:reinforced_concrete,30,quark:limestone_wall,10,contenttweaker:reinforced_concrete,100)
Block(-2,26,-3,VINE:4)
RandomBlock(-2,27,-4,contenttweaker:reinforced_concrete,30,quark:limestone_wall,10,contenttweaker:reinforced_concrete,100)
Block(-2,27,-3,VINE:12)
RandomBlock(-2,28,-3,contenttweaker:reinforced_concrete,30,quark:limestone_wall,10,contenttweaker:reinforced_concrete,100)
RandomBlock(-1,0,-7,contenttweaker:reinforced_concrete,40,SMOOTH_BRICK:1,30,SMOOTH_BRICK:2,30,SMOOTH_STAIRS:0,15,SMOOTH_STAIRS:1,15,SMOOTH_STAIRS:2,15,SMOOTH_STAIRS:3,15,STEP:5,15,STEP:13,15,COBBLE_WALL:0,10,COBBLESTONE_STAIRS:0,10,STEP:3,10,COBBLE_WALL:1,20,COBBLESTONE_STAIRS:2,20,COBBLESTONE_STAIRS:3,20,MOSSY_COBBLESTONE:0,60,COBBLESTONE_STAIRS:1,20,STEP:11,20,COBBLESTONE:0,100)
RandomBlock(-1,0,-6,contenttweaker:reinforced_concrete,40,SMOOTH_BRICK:1,30,SMOOTH_BRICK:2,30,SMOOTH_STAIRS:0,15,SMOOTH_STAIRS:1,15,SMOOTH_STAIRS:2,15,SMOOTH_STAIRS:3,15,STEP:5,15,STEP:13,15,COBBLE_WALL:0,10,COBBLESTONE_STAIRS:0,10,STEP:3,10,COBBLE_WALL:1,20,COBBLESTONE_STAIRS:2,20,COBBLESTONE_STAIRS:3,20,MOSSY_COBBLESTONE:0,60,COBBLESTONE_STAIRS:1,20,STEP:11,20,COBBLESTONE:0,100)
RandomBlock(-1,0,-5,contenttweaker:reinforced_concrete,40,SMOOTH_BRICK:1,30,SMOOTH_BRICK:2,30,SMOOTH_STAIRS:0,15,SMOOTH_STAIRS:1,15,SMOOTH_STAIRS:2,15,SMOOTH_STAIRS:3,15,STEP:5,15,STEP:13,15,COBBLE_WALL:0,10,COBBLESTONE_STAIRS:0,10,STEP:3,10,COBBLE_WALL:1,20,COBBLESTONE_STAIRS:2,20,COBBLESTONE_STAIRS:3,20,MOSSY_COBBLESTONE:0,60,COBBLESTONE_STAIRS:1,20,STEP:11,20,COBBLESTONE:0,100)
RandomBlock(-1,0,-4,contenttweaker:reinforced_concrete,40,SMOOTH_BRICK:1,30,SMOOTH_BRICK:2,30,SMOOTH_STAIRS:0,15,SMOOTH_STAIRS:1,15,SMOOTH_STAIRS:2,15,SMOOTH_STAIRS:3,15,STEP:5,15,STEP:13,15,COBBLE_WALL:0,10,COBBLESTONE_STAIRS:0,10,STEP:3,10,COBBLE_WALL:1,20,COBBLESTONE_STAIRS:2,20,COBBLESTONE_STAIRS:3,20,MOSSY_COBBLESTONE:0,60,COBBLESTONE_STAIRS:1,20,STEP:11,20,COBBLESTONE:0,100)
RandomBlock(-1,0,-3,contenttweaker:reinforced_concrete,40,SMOOTH_BRICK:1,30,SMOOTH_BRICK:2,30,SMOOTH_STAIRS:0,15,SMOOTH_STAIRS:1,15,SMOOTH_STAIRS:2,15,SMOOTH_STAIRS:3,15,STEP:5,15,STEP:13,15,COBBLE_WALL:0,10,COBBLESTONE_STAIRS:0,10,STEP:3,10,COBBLE_WALL:1,20,COBBLESTONE_STAIRS:2,20,COBBLESTONE_STAIRS:3,20,MOSSY_COBBLESTONE:0,60,COBBLESTONE_STAIRS:1,20,STEP:11,20,COBBLESTONE:0,100)
RandomBlock(-1,0,-2,contenttweaker:reinforced_concrete,40,SMOOTH_BRICK:1,30,SMOOTH_BRICK:2,30,SMOOTH_STAIRS:0,15,SMOOTH_STAIRS:1,15,SMOOTH_STAIRS:2,15,SMOOTH_STAIRS:3,15,STEP:5,15,STEP:13,15,COBBLE_WALL:0,10,COBBLESTONE_STAIRS:0,10,STEP:3,10,COBBLE_WALL:1,20,COBBLESTONE_STAIRS:2,20,COBBLESTONE_STAIRS:3,20,MOSSY_COBBLESTONE:0,60,COBBLESTONE_STAIRS:1,20,STEP:11,20,COBBLESTONE:0,100)
RandomBlock(-1,1,-7,contenttweaker:reinforced_concrete,40,SMOOTH_BRICK:1,30,SMOOTH_BRICK:2,30,SMOOTH_STAIRS:0,15,SMOOTH_STAIRS:1,15,SMOOTH_STAIRS:2,15,SMOOTH_STAIRS:3,15,STEP:5,15,STEP:13,15,COBBLE_WALL:0,10,COBBLESTONE_STAIRS:0,10,STEP:3,10,COBBLE_WALL:1,20,COBBLESTONE_STAIRS:2,20,COBBLESTONE_STAIRS:3,20,MOSSY_COBBLESTONE:0,60,COBBLESTONE_STAIRS:1,20,STEP:11,20,COBBLESTONE:0,100)
RandomBlock(-1,1,-6,contenttweaker:reinforced_concrete,40,SMOOTH_BRICK:1,30,SMOOTH_BRICK:2,30,SMOOTH_STAIRS:0,15,SMOOTH_STAIRS:1,15,SMOOTH_STAIRS:2,15,SMOOTH_STAIRS:3,15,STEP:5,15,STEP:13,15,COBBLE_WALL:0,10,COBBLESTONE_STAIRS:0,10,STEP:3,10,COBBLE_WALL:1,20,COBBLESTONE_STAIRS:2,20,COBBLESTONE_STAIRS:3,20,MOSSY_COBBLESTONE:0,60,COBBLESTONE_STAIRS:1,20,STEP:11,20,COBBLESTONE:0,100)
RandomBlock(-1,1,-5,contenttweaker:reinforced_concrete,40,SMOOTH_BRICK:1,30,SMOOTH_BRICK:2,30,SMOOTH_STAIRS:0,15,SMOOTH_STAIRS:1,15,SMOOTH_STAIRS:2,15,SMOOTH_STAIRS:3,15,STEP:5,15,STEP:13,15,COBBLE_WALL:0,10,COBBLESTONE_STAIRS:0,10,STEP:3,10,COBBLE_WALL:1,20,COBBLESTONE_STAIRS:2,20,COBBLESTONE_STAIRS:3,20,MOSSY_COBBLESTONE:0,60,COBBLESTONE_STAIRS:1,20,STEP:11,20,COBBLESTONE:0,100)
RandomBlock(-1,1,-4,contenttweaker:reinforced_concrete,40,SMOOTH_BRICK:1,30,SMOOTH_BRICK:2,30,SMOOTH_STAIRS:0,15,SMOOTH_STAIRS:1,15,SMOOTH_STAIRS:2,15,SMOOTH_STAIRS:3,15,STEP:5,15,STEP:13,15,COBBLE_WALL:0,10,COBBLESTONE_STAIRS:0,10,STEP:3,10,COBBLE_WALL:1,20,COBBLESTONE_STAIRS:2,20,COBBLESTONE_STAIRS:3,20,MOSSY_COBBLESTONE:0,60,COBBLESTONE_STAIRS:1,20,STEP:11,20,COBBLESTONE:0,100)
RandomBlock(-1,1,-3,contenttweaker:reinforced_concrete,40,SMOOTH_BRICK:1,30,SMOOTH_BRICK:2,30,SMOOTH_STAIRS:0,15,SMOOTH_STAIRS:1,15,SMOOTH_STAIRS:2,15,SMOOTH_STAIRS:3,15,STEP:5,15,STEP:13,15,COBBLE_WALL:0,10,COBBLESTONE_STAIRS:0,10,STEP:3,10,COBBLE_WALL:1,20,COBBLESTONE_STAIRS:2,20,COBBLESTONE_STAIRS:3,20,MOSSY_COBBLESTONE:0,60,COBBLESTONE_STAIRS:1,20,STEP:11,20,COBBLESTONE:0,100)
RandomBlock(-1,1,-2,contenttweaker:reinforced_concrete,40,SMOOTH_BRICK:1,30,SMOOTH_BRICK:2,30,SMOOTH_STAIRS:0,15,SMOOTH_STAIRS:1,15,SMOOTH_STAIRS:2,15,SMOOTH_STAIRS:3,15,STEP:5,15,STEP:13,15,COBBLE_WALL:0,10,COBBLESTONE_STAIRS:0,10,STEP:3,10,COBBLE_WALL:1,20,COBBLESTONE_STAIRS:2,20,COBBLESTONE_STAIRS:3,20,MOSSY_COBBLESTONE:0,60,COBBLESTONE_STAIRS:1,20,STEP:11,20,COBBLESTONE:0,100)
RandomBlock(-1,2,-7,contenttweaker:reinforced_concrete,40,SMOOTH_BRICK:1,30,SMOOTH_BRICK:2,30,SMOOTH_STAIRS:0,15,SMOOTH_STAIRS:1,15,SMOOTH_STAIRS:2,15,SMOOTH_STAIRS:3,15,STEP:5,15,STEP:13,15,COBBLE_WALL:0,10,COBBLESTONE_STAIRS:0,10,STEP:3,10,COBBLE_WALL:1,20,COBBLESTONE_STAIRS:2,20,COBBLESTONE_STAIRS:3,20,MOSSY_COBBLESTONE:0,60,COBBLESTONE_STAIRS:1,20,STEP:11,20,COBBLESTONE:0,100)
RandomBlock(-1,2,-6,contenttweaker:reinforced_concrete,40,SMOOTH_BRICK:1,30,SMOOTH_BRICK:2,30,SMOOTH_STAIRS:0,15,SMOOTH_STAIRS:1,15,SMOOTH_STAIRS:2,15,SMOOTH_STAIRS:3,15,STEP:5,15,STEP:13,15,COBBLE_WALL:0,10,COBBLESTONE_STAIRS:0,10,STEP:3,10,COBBLE_WALL:1,20,COBBLESTONE_STAIRS:2,20,COBBLESTONE_STAIRS:3,20,MOSSY_COBBLESTONE:0,60,COBBLESTONE_STAIRS:1,20,STEP:11,20,COBBLESTONE:0,100)
RandomBlock(-1,2,-5,contenttweaker:reinforced_concrete,40,SMOOTH_BRICK:1,30,SMOOTH_BRICK:2,30,SMOOTH_STAIRS:0,15,SMOOTH_STAIRS:1,15,SMOOTH_STAIRS:2,15,SMOOTH_STAIRS:3,15,STEP:5,15,STEP:13,15,COBBLE_WALL:0,10,COBBLESTONE_STAIRS:0,10,STEP:3,10,COBBLE_WALL:1,20,COBBLESTONE_STAIRS:2,20,COBBLESTONE_STAIRS:3,20,MOSSY_COBBLESTONE:0,60,COBBLESTONE_STAIRS:1,20,STEP:11,20,COBBLESTONE:0,100)
RandomBlock(-1,2,-4,contenttweaker:reinforced_concrete,40,SMOOTH_BRICK:1,30,SMOOTH_BRICK:2,30,SMOOTH_STAIRS:0,15,SMOOTH_STAIRS:1,15,SMOOTH_STAIRS:2,15,SMOOTH_STAIRS:3,15,STEP:5,15,STEP:13,15,COBBLE_WALL:0,10,COBBLESTONE_STAIRS:0,10,STEP:3,10,COBBLE_WALL:1,20,COBBLESTONE_STAIRS:2,20,COBBLESTONE_STAIRS:3,20,MOSSY_COBBLESTONE:0,60,COBBLESTONE_STAIRS:1,20,STEP:11,20,COBBLESTONE:0,100)
RandomBlock(-1,2,-3,contenttweaker:reinforced_concrete,40,SMOOTH_BRICK:1,30,SMOOTH_BRICK:2,30,SMOOTH_STAIRS:0,15,SMOOTH_STAIRS:1,15,SMOOTH_STAIRS:2,15,SMOOTH_STAIRS:3,15,STEP:5,15,STEP:13,15,COBBLE_WALL:0,10,COBBLESTONE_STAIRS:0,10,STEP:3,10,COBBLE_WALL:1,20,COBBLESTONE_STAIRS:2,20,COBBLESTONE_STAIRS:3,20,MOSSY_COBBLESTONE:0,60,COBBLESTONE_STAIRS:1,20,STEP:11,20,COBBLESTONE:0,100)
RandomBlock(-1,2,-2,contenttweaker:reinforced_concrete,40,SMOOTH_BRICK:1,30,SMOOTH_BRICK:2,30,SMOOTH_STAIRS:0,15,SMOOTH_STAIRS:1,15,SMOOTH_STAIRS:2,15,SMOOTH_STAIRS:3,15,STEP:5,15,STEP:13,15,COBBLE_WALL:0,10,COBBLESTONE_STAIRS:0,10,STEP:3,10,COBBLE_WALL:1,20,COBBLESTONE_STAIRS:2,20,COBBLESTONE_STAIRS:3,20,MOSSY_COBBLESTONE:0,60,COBBLESTONE_STAIRS:1,20,STEP:11,20,COBBLESTONE:0,100)
RandomBlock(-1,3,-7,contenttweaker:reinforced_concrete,40,SMOOTH_BRICK:1,30,SMOOTH_BRICK:2,30,SMOOTH_STAIRS:0,15,SMOOTH_STAIRS:1,15,SMOOTH_STAIRS:2,15,SMOOTH_STAIRS:3,15,STEP:5,15,STEP:13,15,COBBLE_WALL:0,10,COBBLESTONE_STAIRS:0,10,STEP:3,10,COBBLE_WALL:1,20,COBBLESTONE_STAIRS:2,20,COBBLESTONE_STAIRS:3,20,MOSSY_COBBLESTONE:0,60,COBBLESTONE_STAIRS:1,20,STEP:11,20,COBBLESTONE:0,100)
RandomBlock(-1,3,-6,contenttweaker:reinforced_concrete,40,SMOOTH_BRICK:1,30,SMOOTH_BRICK:2,30,SMOOTH_STAIRS:0,15,SMOOTH_STAIRS:1,15,SMOOTH_STAIRS:2,15,SMOOTH_STAIRS:3,15,STEP:5,15,STEP:13,15,COBBLE_WALL:0,10,COBBLESTONE_STAIRS:0,10,STEP:3,10,COBBLE_WALL:1,20,COBBLESTONE_STAIRS:2,20,COBBLESTONE_STAIRS:3,20,MOSSY_COBBLESTONE:0,60,COBBLESTONE_STAIRS:1,20,STEP:11,20,COBBLESTONE:0,100)
RandomBlock(-1,3,-5,contenttweaker:reinforced_concrete,40,SMOOTH_BRICK:1,30,SMOOTH_BRICK:2,30,SMOOTH_STAIRS:0,15,SMOOTH_STAIRS:1,15,SMOOTH_STAIRS:2,15,SMOOTH_STAIRS:3,15,STEP:5,15,STEP:13,15,COBBLE_WALL:0,10,COBBLESTONE_STAIRS:0,10,STEP:3,10,COBBLE_WALL:1,20,COBBLESTONE_STAIRS:2,20,COBBLESTONE_STAIRS:3,20,MOSSY_COBBLESTONE:0,60,COBBLESTONE_STAIRS:1,20,STEP:11,20,COBBLESTONE:0,100)
RandomBlock(-1,3,-4,contenttweaker:reinforced_concrete,40,SMOOTH_BRICK:1,30,SMOOTH_BRICK:2,30,SMOOTH_STAIRS:0,15,SMOOTH_STAIRS:1,15,SMOOTH_STAIRS:2,15,SMOOTH_STAIRS:3,15,STEP:5,15,STEP:13,15,COBBLE_WALL:0,10,COBBLESTONE_STAIRS:0,10,STEP:3,10,COBBLE_WALL:1,20,COBBLESTONE_STAIRS:2,20,COBBLESTONE_STAIRS:3,20,MOSSY_COBBLESTONE:0,60,COBBLESTONE_STAIRS:1,20,STEP:11,20,COBBLESTONE:0,100)
RandomBlock(-1,3,-3,contenttweaker:reinforced_concrete,40,SMOOTH_BRICK:1,30,SMOOTH_BRICK:2,30,SMOOTH_STAIRS:0,15,SMOOTH_STAIRS:1,15,SMOOTH_STAIRS:2,15,SMOOTH_STAIRS:3,15,STEP:5,15,STEP:13,15,COBBLE_WALL:0,10,COBBLESTONE_STAIRS:0,10,STEP:3,10,COBBLE_WALL:1,20,COBBLESTONE_STAIRS:2,20,COBBLESTONE_STAIRS:3,20,MOSSY_COBBLESTONE:0,60,COBBLESTONE_STAIRS:1,20,STEP:11,20,COBBLESTONE:0,100)
RandomBlock(-1,3,-2,contenttweaker:reinforced_concrete,40,SMOOTH_BRICK:1,30,SMOOTH_BRICK:2,30,SMOOTH_STAIRS:0,15,SMOOTH_STAIRS:1,15,SMOOTH_STAIRS:2,15,SMOOTH_STAIRS:3,15,STEP:5,15,STEP:13,15,COBBLE_WALL:0,10,COBBLESTONE_STAIRS:0,10,STEP:3,10,COBBLE_WALL:1,20,COBBLESTONE_STAIRS:2,20,COBBLESTONE_STAIRS:3,20,MOSSY_COBBLESTONE:0,60,COBBLESTONE_STAIRS:1,20,STEP:11,20,COBBLESTONE:0,100)
RandomBlock(-1,4,-7,contenttweaker:reinforced_concrete,40,SMOOTH_BRICK:1,30,SMOOTH_BRICK:2,30,SMOOTH_STAIRS:0,15,SMOOTH_STAIRS:1,15,SMOOTH_STAIRS:2,15,SMOOTH_STAIRS:3,15,STEP:5,15,STEP:13,15,COBBLE_WALL:0,10,COBBLESTONE_STAIRS:0,10,STEP:3,10,COBBLE_WALL:1,20,COBBLESTONE_STAIRS:2,20,COBBLESTONE_STAIRS:3,20,MOSSY_COBBLESTONE:0,60,COBBLESTONE_STAIRS:1,20,STEP:11,20,COBBLESTONE:0,100)
RandomBlock(-1,4,-6,contenttweaker:reinforced_concrete,40,SMOOTH_BRICK:1,30,SMOOTH_BRICK:2,30,SMOOTH_STAIRS:0,15,SMOOTH_STAIRS:1,15,SMOOTH_STAIRS:2,15,SMOOTH_STAIRS:3,15,STEP:5,15,STEP:13,15,COBBLE_WALL:0,10,COBBLESTONE_STAIRS:0,10,STEP:3,10,COBBLE_WALL:1,20,COBBLESTONE_STAIRS:2,20,COBBLESTONE_STAIRS:3,20,MOSSY_COBBLESTONE:0,60,COBBLESTONE_STAIRS:1,20,STEP:11,20,COBBLESTONE:0,100)
RandomBlock(-1,4,-5,contenttweaker:reinforced_concrete,40,SMOOTH_BRICK:1,30,SMOOTH_BRICK:2,30,SMOOTH_STAIRS:0,15,SMOOTH_STAIRS:1,15,SMOOTH_STAIRS:2,15,SMOOTH_STAIRS:3,15,STEP:5,15,STEP:13,15,COBBLE_WALL:0,10,COBBLESTONE_STAIRS:0,10,STEP:3,10,COBBLE_WALL:1,20,COBBLESTONE_STAIRS:2,20,COBBLESTONE_STAIRS:3,20,MOSSY_COBBLESTONE:0,60,COBBLESTONE_STAIRS:1,20,STEP:11,20,COBBLESTONE:0,100)
RandomBlock(-1,4,-4,contenttweaker:reinforced_concrete,40,SMOOTH_BRICK:1,30,SMOOTH_BRICK:2,30,SMOOTH_STAIRS:0,15,SMOOTH_STAIRS:1,15,SMOOTH_STAIRS:2,15,SMOOTH_STAIRS:3,15,STEP:5,15,STEP:13,15,COBBLE_WALL:0,10,COBBLESTONE_STAIRS:0,10,STEP:3,10,COBBLE_WALL:1,20,COBBLESTONE_STAIRS:2,20,COBBLESTONE_STAIRS:3,20,MOSSY_COBBLESTONE:0,60,COBBLESTONE_STAIRS:1,20,STEP:11,20,COBBLESTONE:0,100)
RandomBlock(-1,4,-3,contenttweaker:reinforced_concrete,40,SMOOTH_BRICK:1,30,SMOOTH_BRICK:2,30,SMOOTH_STAIRS:0,15,SMOOTH_STAIRS:1,15,SMOOTH_STAIRS:2,15,SMOOTH_STAIRS:3,15,STEP:5,15,STEP:13,15,COBBLE_WALL:0,10,COBBLESTONE_STAIRS:0,10,STEP:3,10,COBBLE_WALL:1,20,COBBLESTONE_STAIRS:2,20,COBBLESTONE_STAIRS:3,20,MOSSY_COBBLESTONE:0,60,COBBLESTONE_STAIRS:1,20,STEP:11,20,COBBLESTONE:0,100)
RandomBlock(-1,4,-2,contenttweaker:reinforced_concrete,40,SMOOTH_BRICK:1,30,SMOOTH_BRICK:2,30,SMOOTH_STAIRS:0,15,SMOOTH_STAIRS:1,15,SMOOTH_STAIRS:2,15,SMOOTH_STAIRS:3,15,STEP:5,15,STEP:13,15,COBBLE_WALL:0,10,COBBLESTONE_STAIRS:0,10,STEP:3,10,COBBLE_WALL:1,20,COBBLESTONE_STAIRS:2,20,COBBLESTONE_STAIRS:3,20,MOSSY_COBBLESTONE:0,60,COBBLESTONE_STAIRS:1,20,STEP:11,20,COBBLESTONE:0,100)
RandomBlock(-1,5,-7,contenttweaker:reinforced_concrete,40,SMOOTH_BRICK:1,30,SMOOTH_BRICK:2,30,SMOOTH_STAIRS:0,15,SMOOTH_STAIRS:1,15,SMOOTH_STAIRS:2,15,SMOOTH_STAIRS:3,15,STEP:5,15,STEP:13,15,COBBLE_WALL:0,10,COBBLESTONE_STAIRS:0,10,STEP:3,10,COBBLE_WALL:1,20,COBBLESTONE_STAIRS:2,20,COBBLESTONE_STAIRS:3,20,MOSSY_COBBLESTONE:0,60,COBBLESTONE_STAIRS:1,20,STEP:11,20,COBBLESTONE:0,100)
RandomBlock(-1,5,-6,contenttweaker:reinforced_concrete,40,SMOOTH_BRICK:1,30,SMOOTH_BRICK:2,30,SMOOTH_STAIRS:0,15,SMOOTH_STAIRS:1,15,SMOOTH_STAIRS:2,15,SMOOTH_STAIRS:3,15,STEP:5,15,STEP:13,15,COBBLE_WALL:0,10,COBBLESTONE_STAIRS:0,10,STEP:3,10,COBBLE_WALL:1,20,COBBLESTONE_STAIRS:2,20,COBBLESTONE_STAIRS:3,20,MOSSY_COBBLESTONE:0,60,COBBLESTONE_STAIRS:1,20,STEP:11,20,COBBLESTONE:0,100)
RandomBlock(-1,5,-5,contenttweaker:reinforced_concrete,40,SMOOTH_BRICK:1,30,SMOOTH_BRICK:2,30,SMOOTH_STAIRS:0,15,SMOOTH_STAIRS:1,15,SMOOTH_STAIRS:2,15,SMOOTH_STAIRS:3,15,STEP:5,15,STEP:13,15,COBBLE_WALL:0,10,COBBLESTONE_STAIRS:0,10,STEP:3,10,COBBLE_WALL:1,20,COBBLESTONE_STAIRS:2,20,COBBLESTONE_STAIRS:3,20,MOSSY_COBBLESTONE:0,60,COBBLESTONE_STAIRS:1,20,STEP:11,20,COBBLESTONE:0,100)
RandomBlock(-1,5,-4,contenttweaker:reinforced_concrete,40,SMOOTH_BRICK:1,30,SMOOTH_BRICK:2,30,SMOOTH_STAIRS:0,15,SMOOTH_STAIRS:1,15,SMOOTH_STAIRS:2,15,SMOOTH_STAIRS:3,15,STEP:5,15,STEP:13,15,COBBLE_WALL:0,10,COBBLESTONE_STAIRS:0,10,STEP:3,10,COBBLE_WALL:1,20,COBBLESTONE_STAIRS:2,20,COBBLESTONE_STAIRS:3,20,MOSSY_COBBLESTONE:0,60,COBBLESTONE_STAIRS:1,20,STEP:11,20,COBBLESTONE:0,100)
RandomBlock(-1,5,-3,contenttweaker:reinforced_concrete,40,SMOOTH_BRICK:1,30,SMOOTH_BRICK:2,30,SMOOTH_STAIRS:0,15,SMOOTH_STAIRS:1,15,SMOOTH_STAIRS:2,15,SMOOTH_STAIRS:3,15,STEP:5,15,STEP:13,15,COBBLE_WALL:0,10,COBBLESTONE_STAIRS:0,10,STEP:3,10,COBBLE_WALL:1,20,COBBLESTONE_STAIRS:2,20,COBBLESTONE_STAIRS:3,20,MOSSY_COBBLESTONE:0,60,COBBLESTONE_STAIRS:1,20,STEP:11,20,COBBLESTONE:0,100)
RandomBlock(-1,5,-2,contenttweaker:reinforced_concrete,30,quark:limestone_wall,10,contenttweaker:reinforced_concrete,100)
RandomBlock(-1,6,-7,contenttweaker:reinforced_concrete,40,SMOOTH_BRICK:1,30,SMOOTH_BRICK:2,30,SMOOTH_STAIRS:0,15,SMOOTH_STAIRS:1,15,SMOOTH_STAIRS:2,15,SMOOTH_STAIRS:3,15,STEP:5,15,STEP:13,15,COBBLE_WALL:0,10,COBBLESTONE_STAIRS:0,10,STEP:3,10,COBBLE_WALL:1,20,COBBLESTONE_STAIRS:2,20,COBBLESTONE_STAIRS:3,20,MOSSY_COBBLESTONE:0,60,COBBLESTONE_STAIRS:1,20,STEP:11,20,COBBLESTONE:0,100)
RandomBlock(-1,6,-6,contenttweaker:reinforced_concrete,40,SMOOTH_BRICK:1,30,SMOOTH_BRICK:2,30,SMOOTH_STAIRS:0,15,SMOOTH_STAIRS:1,15,SMOOTH_STAIRS:2,15,SMOOTH_STAIRS:3,15,STEP:5,15,STEP:13,15,COBBLE_WALL:0,10,COBBLESTONE_STAIRS:0,10,STEP:3,10,COBBLE_WALL:1,20,COBBLESTONE_STAIRS:2,20,COBBLESTONE_STAIRS:3,20,MOSSY_COBBLESTONE:0,60,COBBLESTONE_STAIRS:1,20,STEP:11,20,COBBLESTONE:0,100)
RandomBlock(-1,6,-5,contenttweaker:reinforced_concrete,40,SMOOTH_BRICK:1,30,SMOOTH_BRICK:2,30,SMOOTH_STAIRS:0,15,SMOOTH_STAIRS:1,15,SMOOTH_STAIRS:2,15,SMOOTH_STAIRS:3,15,STEP:5,15,STEP:13,15,COBBLE_WALL:0,10,COBBLESTONE_STAIRS:0,10,STEP:3,10,COBBLE_WALL:1,20,COBBLESTONE_STAIRS:2,20,COBBLESTONE_STAIRS:3,20,MOSSY_COBBLESTONE:0,60,COBBLESTONE_STAIRS:1,20,STEP:11,20,COBBLESTONE:0,100)
RandomBlock(-1,6,-4,contenttweaker:reinforced_concrete,40,SMOOTH_BRICK:1,30,SMOOTH_BRICK:2,30,SMOOTH_STAIRS:0,15,SMOOTH_STAIRS:1,15,SMOOTH_STAIRS:2,15,SMOOTH_STAIRS:3,15,STEP:5,15,STEP:13,15,COBBLE_WALL:0,10,COBBLESTONE_STAIRS:0,10,STEP:3,10,COBBLE_WALL:1,20,COBBLESTONE_STAIRS:2,20,COBBLESTONE_STAIRS:3,20,MOSSY_COBBLESTONE:0,60,COBBLESTONE_STAIRS:1,20,STEP:11,20,COBBLESTONE:0,100)
RandomBlock(-1,6,-3,contenttweaker:reinforced_concrete,40,SMOOTH_BRICK:1,30,SMOOTH_BRICK:2,30,SMOOTH_STAIRS:0,15,SMOOTH_STAIRS:1,15,SMOOTH_STAIRS:2,15,SMOOTH_STAIRS:3,15,STEP:5,15,STEP:13,15,COBBLE_WALL:0,10,COBBLESTONE_STAIRS:0,10,STEP:3,10,COBBLE_WALL:1,20,COBBLESTONE_STAIRS:2,20,COBBLESTONE_STAIRS:3,20,MOSSY_COBBLESTONE:0,60,COBBLESTONE_STAIRS:1,20,STEP:11,20,COBBLESTONE:0,100)
RandomBlock(-1,6,-2,contenttweaker:reinforced_concrete,30,quark:limestone_wall,10,contenttweaker:reinforced_concrete,100)
RandomBlock(-1,7,-7,contenttweaker:reinforced_concrete,40,SMOOTH_BRICK:1,30,SMOOTH_BRICK:2,30,SMOOTH_STAIRS:0,15,SMOOTH_STAIRS:1,15,SMOOTH_STAIRS:2,15,SMOOTH_STAIRS:3,15,STEP:5,15,STEP:13,15,COBBLE_WALL:0,10,COBBLESTONE_STAIRS:0,10,STEP:3,10,COBBLE_WALL:1,20,COBBLESTONE_STAIRS:2,20,COBBLESTONE_STAIRS:3,20,MOSSY_COBBLESTONE:0,60,COBBLESTONE_STAIRS:1,20,STEP:11,20,COBBLESTONE:0,100)
