
#######################################################################
# +-----------------------------------------------------------------+ #
# |                            BO4 object                           | #
# +-----------------------------------------------------------------+ #
#######################################################################

Author: NLBlackEagle

Description: No description given

SettingsMode: WriteWithoutComments


#######################################################################
# +-----------------------------------------------------------------+ #
# |                          Main settings                          | #
# +-----------------------------------------------------------------+ #
#######################################################################

FixedRotation: 

Frequency: 0

SpawnHeight: highestSolidBlock

UseCenterForHighestBlock: true

##############################
# Height Limits for the BO4. #
##############################

MinHeight: 0

MaxHeight: 255

InheritBO3: 

InheritBO3Rotation: NORTH

OverrideChildSettings: true

OverrideParentHeight: false

CanOverride: true

BranchFrequency: 0

BranchFrequencyGroup: 

MustBeBelowOther: false

MustBeInside: 

CannotBeInside: 

ReplacesBO3: 

MustBeInsideWorldBorders: false

CanSpawnOnWater: false

SpawnOnWaterOnly: false

SpawnUnderWater: false

SpawnAtWaterLevel: false

HeightOffset: 0

RemoveAir: false

ReplaceAbove: 

ReplaceBelow: COBBLESTONE

ReplaceWithBiomeBlocks: false

ReplaceWithSurfaceBlock: GRASS

ReplaceWithGroundBlock: DIRT

ReplaceWithStoneBlock: STONE

SmoothRadius: 0

SmoothHeightOffset: 0

SmoothStartTop: false

SmoothStartWood: false

SmoothingSurfaceBlock: 

SmoothingGroundBlock: 

BO3Group: 

IsSpawnPoint: false

DoReplaceBlocks: true


#######################################################################
# +-----------------------------------------------------------------+ #
# |                              Blocks                             | #
# +-----------------------------------------------------------------+ #
#######################################################################

Block(-5,6,-2,IRON_FENCE:0)
Block(-5,6,-1,IRON_FENCE:0)
Block(-5,7,-2,IRON_FENCE:0)
Block(-5,7,-1,IRON_FENCE:0)
Block(-5,8,-2,IRON_FENCE:0)
Block(-5,8,-1,IRON_FENCE:0)
Block(-5,10,-2,IRON_FENCE:0)
Block(-5,10,-1,IRON_FENCE:0)
Block(-5,11,-2,IRON_FENCE:0)
Block(-5,11,-1,IRON_FENCE:0)
Block(-5,12,-2,IRON_FENCE:0)
Block(-5,12,-1,IRON_FENCE:0)
Block(-5,14,-2,IRON_FENCE:0)
Block(-5,14,-1,IRON_FENCE:0)
Block(-5,15,-2,IRON_FENCE:0)
Block(-5,15,-1,IRON_FENCE:0)
Block(-5,16,-2,IRON_FENCE:0)
Block(-5,16,-1,IRON_FENCE:0)
Block(-4,6,-1,IRON_FENCE:0)
Block(-4,7,-1,IRON_FENCE:0)
Block(-4,8,-1,IRON_FENCE:0)
Block(-4,10,-1,IRON_FENCE:0)
Block(-4,11,-1,IRON_FENCE:0)
Block(-4,12,-1,IRON_FENCE:0)
Block(-4,14,-1,IRON_FENCE:0)
Block(-4,15,-1,IRON_FENCE:0)
Block(-4,16,-1,IRON_FENCE:0)
Block(-3,6,-2,IRON_FENCE:0)
Block(-3,6,-1,IRON_FENCE:0)
Block(-3,7,-2,IRON_FENCE:0)
Block(-3,7,-1,IRON_FENCE:0)
Block(-3,8,-2,IRON_FENCE:0)
Block(-3,8,-1,IRON_FENCE:0)
Block(-3,10,-2,IRON_FENCE:0)
Block(-3,10,-1,IRON_FENCE:0)
Block(-3,11,-2,IRON_FENCE:0)
Block(-3,11,-1,IRON_FENCE:0)
Block(-3,12,-2,IRON_FENCE:0)
Block(-3,12,-1,IRON_FENCE:0)
Block(-3,14,-2,IRON_FENCE:0)
Block(-3,14,-1,IRON_FENCE:0)
Block(-3,15,-2,IRON_FENCE:0)
Block(-3,15,-1,IRON_FENCE:0)
Block(-3,16,-2,IRON_FENCE:0)
Block(-3,16,-1,IRON_FENCE:0)
Block(-2,0,-1,STONE:6)
Block(-2,0,0,STONE:6)
Block(-2,0,1,STONE:6)
Block(-2,1,-1,SMOOTH_STAIRS:0)
Block(-2,1,0,SMOOTH_STAIRS:0)
Block(-2,1,1,SMOOTH_STAIRS:0)
Block(-2,6,-1,IRON_FENCE:0)
Block(-2,7,-1,IRON_FENCE:0)
Block(-2,8,-1,IRON_FENCE:0)
Block(-2,10,-1,IRON_FENCE:0)
Block(-2,11,-1,IRON_FENCE:0)
Block(-2,12,-1,IRON_FENCE:0)
Block(-2,14,-1,IRON_FENCE:0)
Block(-2,15,-1,IRON_FENCE:0)
Block(-2,16,-1,IRON_FENCE:0)
Block(-1,0,-2,STONE:6)
Block(-1,0,-1,STONE:6)
Block(-1,0,0,STONE:6)
Block(-1,0,1,STONE:6)
Block(-1,0,2,STONE:6)
Block(-1,1,-2,SMOOTH_STAIRS:2)
Block(-1,1,-1,STONE:6)
Block(-1,1,0,STONE:6)
Block(-1,1,1,STONE:6)
Block(-1,1,2,SMOOTH_STAIRS:3)
Block(-1,2,-1,COBBLE_WALL:0)
Block(-1,2,0,STONE:6)
Block(-1,2,1,COBBLE_WALL:0)
Block(-1,3,-1,COBBLE_WALL:0)
Block(-1,3,0,SMOOTH_STAIRS:0)
Block(-1,3,1,COBBLE_WALL:0)
Block(-1,4,-1,IRON_FENCE:0)
Block(-1,4,0,VINE:8)
Block(-1,4,1,IRON_FENCE:0)
Block(-1,5,-1,STEP:8)
Block(-1,5,0,STEP:8)
Block(-1,6,-2,IRON_FENCE:0)
Block(-1,6,-1,IRON_FENCE:0)
Block(-1,6,0,COBBLE_WALL:0)
Block(-1,7,-2,IRON_FENCE:0)
Block(-1,7,-1,IRON_FENCE:0)
Block(-1,7,0,IRON_FENCE:0)
Block(-1,8,-2,IRON_FENCE:0)
Block(-1,8,-1,IRON_FENCE:0)
Block(-1,8,0,COBBLE_WALL:0)
Block(-1,9,-1,STEP:8)
Block(-1,9,0,STEP:8)
Block(-1,10,-2,IRON_FENCE:0)
Block(-1,10,-1,IRON_FENCE:0)
Block(-1,10,0,COBBLE_WALL:0)
Block(-1,11,-2,IRON_FENCE:0)
Block(-1,11,-1,IRON_FENCE:0)
Block(-1,11,0,IRON_FENCE:0)
Block(-1,12,-2,IRON_FENCE:0)
Block(-1,12,-1,IRON_FENCE:0)
Block(-1,12,0,COBBLE_WALL:0)
Block(-1,13,-1,STEP:8)
Block(-1,13,0,STEP:8)
Block(-1,14,-2,IRON_FENCE:0)
Block(-1,14,-1,IRON_FENCE:0)
Block(-1,14,0,COBBLE_WALL:0)
Block(-1,15,-2,IRON_FENCE:0)
Block(-1,15,-1,IRON_FENCE:0)
Block(-1,15,0,IRON_FENCE:0)
Block(-1,16,-2,IRON_FENCE:0)
Block(-1,16,-1,IRON_FENCE:0)
Block(-1,16,0,COBBLE_WALL:0)
Block(-1,17,0,VINE:8)
Block(0,0,-2,STONE:6)
Block(0,0,-1,STONE:6)
Block(0,0,0,STONE:6)
Block(0,0,1,STONE:6)
Block(0,0,2,STONE:6)
Block(0,1,-2,SMOOTH_STAIRS:2)
Block(0,1,-1,STONE:6)
Block(0,1,0,STONE:6)
Block(0,1,1,STONE:6)
Block(0,1,2,SMOOTH_STAIRS:3)
Block(0,2,-1,STONE:6)
Block(0,2,1,STONE:6)
Block(0,3,-1,SMOOTH_STAIRS:2)
Block(0,3,0,CONCRETE:7)
Block(0,3,1,SMOOTH_STAIRS:3)
Block(0,4,-1,VINE:1)
Block(0,4,0,CONCRETE:7)
Block(0,4,1,VINE:4)
Block(0,5,0,CONCRETE:7)
Block(0,5,1,VINE:4)
Block(0,6,-1,IRON_FENCE:0)
Block(0,6,0,CONCRETE:7)
Block(0,6,1,VINE:4)
Block(0,7,-1,IRON_FENCE:0)
Block(0,7,0,CONCRETE:7)
Block(0,7,1,VINE:4)
Block(0,8,-1,IRON_FENCE:0)
Block(0,8,0,CONCRETE:7)
Block(0,8,1,VINE:4)
Block(0,9,-1,IRON_FENCE:0)
Block(0,9,0,CONCRETE:7)
Block(0,9,1,VINE:4)
Block(0,10,-1,IRON_FENCE:0)
Block(0,10,0,CONCRETE:7)
Block(0,10,1,VINE:4)
Block(0,11,-1,IRON_FENCE:0)
Block(0,11,0,CONCRETE:7)
Block(0,11,1,VINE:4)
Block(0,12,-1,IRON_FENCE:0)
Block(0,12,0,CONCRETE:7)
Block(0,12,1,VINE:4)
Block(0,13,-1,IRON_FENCE:0)
Block(0,13,0,CONCRETE:7)
Block(0,13,1,VINE:4)
Block(0,14,-1,IRON_FENCE:0)
Block(0,14,0,CONCRETE:7)
Block(0,14,1,VINE:4)
Block(0,15,-1,IRON_FENCE:0)
Block(0,15,0,CONCRETE:7)
Block(0,15,1,VINE:4)
Block(0,16,-1,IRON_FENCE:0)
Block(0,16,0,CONCRETE:7)
Block(0,16,1,VINE:4)
Block(0,17,-1,VINE:1)
Block(0,17,0,STONE:6)
Block(0,17,1,VINE:4)
Block(0,18,0,COBBLE_WALL:0)
Block(0,19,0,COBBLE_WALL:0)
Block(0,20,0,IRON_FENCE:0)
Block(0,21,0,IRON_FENCE:0)
Block(0,22,0,IRON_FENCE:0)
Block(1,0,-2,STONE:6)
Block(1,0,-1,STONE:6)
Block(1,0,0,STONE:6)
Block(1,0,1,STONE:6)
Block(1,0,2,STONE:6)
Block(1,1,-2,SMOOTH_STAIRS:2)
Block(1,1,-1,STONE:6)
Block(1,1,0,STONE:6)
Block(1,1,1,STONE:6)
Block(1,1,2,SMOOTH_STAIRS:3)
Block(1,2,-1,COBBLE_WALL:0)
Block(1,2,0,STONE:6)
Block(1,2,1,COBBLE_WALL:0)
Block(1,3,-1,COBBLE_WALL:0)
Block(1,3,0,SMOOTH_STAIRS:1)
Block(1,3,1,COBBLE_WALL:0)
Block(1,4,-1,IRON_FENCE:0)
Block(1,4,0,VINE:2)
Block(1,4,1,IRON_FENCE:0)
Block(1,5,-1,STEP:8)
Block(1,5,0,STEP:8)
Block(1,6,-2,IRON_FENCE:0)
Block(1,6,-1,IRON_FENCE:0)
Block(1,6,0,COBBLE_WALL:0)
Block(1,7,-2,IRON_FENCE:0)
Block(1,7,-1,IRON_FENCE:0)
Block(1,7,0,IRON_FENCE:0)
Block(1,8,-2,IRON_FENCE:0)
Block(1,8,-1,IRON_FENCE:0)
Block(1,8,0,COBBLE_WALL:0)
Block(1,9,-1,STEP:8)
Block(1,9,0,STEP:8)
Block(1,10,-2,IRON_FENCE:0)
Block(1,10,-1,IRON_FENCE:0)
Block(1,10,0,COBBLE_WALL:0)
Block(1,11,-2,IRON_FENCE:0)
Block(1,11,-1,IRON_FENCE:0)
Block(1,11,0,IRON_FENCE:0)
Block(1,12,-2,IRON_FENCE:0)
Block(1,12,-1,IRON_FENCE:0)
Block(1,12,0,COBBLE_WALL:0)
Block(1,13,-1,STEP:8)
Block(1,13,0,STEP:8)
Block(1,14,-2,IRON_FENCE:0)
Block(1,14,-1,IRON_FENCE:0)
Block(1,14,0,COBBLE_WALL:0)
Block(1,15,-2,IRON_FENCE:0)
Block(1,15,-1,IRON_FENCE:0)
Block(1,15,0,IRON_FENCE:0)
Block(1,16,-2,IRON_FENCE:0)
Block(1,16,-1,IRON_FENCE:0)
Block(1,16,0,COBBLE_WALL:0)
Block(1,17,0,VINE:2)
Block(2,0,-1,STONE:6)
Block(2,0,0,STONE:6)
Block(2,0,1,STONE:6)
Block(2,1,-1,SMOOTH_STAIRS:1)
Block(2,1,0,SMOOTH_STAIRS:1)
Block(2,1,1,SMOOTH_STAIRS:1)
Block(2,6,-1,IRON_FENCE:0)
Block(2,7,-1,IRON_FENCE:0)
Block(2,8,-1,IRON_FENCE:0)
Block(2,10,-1,IRON_FENCE:0)
Block(2,11,-1,IRON_FENCE:0)
Block(2,12,-1,IRON_FENCE:0)
Block(2,14,-1,IRON_FENCE:0)
Block(2,15,-1,IRON_FENCE:0)
Block(2,16,-1,IRON_FENCE:0)
Block(3,6,-2,IRON_FENCE:0)
Block(3,6,-1,IRON_FENCE:0)
Block(3,7,-2,IRON_FENCE:0)
Block(3,7,-1,IRON_FENCE:0)
Block(3,8,-2,IRON_FENCE:0)
Block(3,8,-1,IRON_FENCE:0)
Block(3,10,-2,IRON_FENCE:0)
Block(3,10,-1,IRON_FENCE:0)
Block(3,11,-2,IRON_FENCE:0)
Block(3,11,-1,IRON_FENCE:0)
Block(3,12,-2,IRON_FENCE:0)
Block(3,12,-1,IRON_FENCE:0)
Block(3,14,-2,IRON_FENCE:0)
Block(3,14,-1,IRON_FENCE:0)
Block(3,15,-2,IRON_FENCE:0)
Block(3,15,-1,IRON_FENCE:0)
Block(3,16,-2,IRON_FENCE:0)
Block(3,16,-1,IRON_FENCE:0)
Block(4,6,-1,IRON_FENCE:0)
Block(4,7,-1,IRON_FENCE:0)
Block(4,8,-1,IRON_FENCE:0)
Block(4,10,-1,IRON_FENCE:0)
Block(4,11,-1,IRON_FENCE:0)
Block(4,12,-1,IRON_FENCE:0)
Block(4,14,-1,IRON_FENCE:0)
Block(4,15,-1,IRON_FENCE:0)
Block(4,16,-1,IRON_FENCE:0)
Block(5,6,-2,IRON_FENCE:0)
Block(5,6,-1,IRON_FENCE:0)
Block(5,7,-2,IRON_FENCE:0)
Block(5,7,-1,IRON_FENCE:0)
Block(5,8,-2,IRON_FENCE:0)
Block(5,8,-1,IRON_FENCE:0)
Block(5,10,-2,IRON_FENCE:0)
Block(5,10,-1,IRON_FENCE:0)
Block(5,11,-2,IRON_FENCE:0)
Block(5,11,-1,IRON_FENCE:0)
Block(5,12,-2,IRON_FENCE:0)
Block(5,12,-1,IRON_FENCE:0)
Block(5,14,-2,IRON_FENCE:0)
Block(5,14,-1,IRON_FENCE:0)
Block(5,15,-2,IRON_FENCE:0)
Block(5,15,-1,IRON_FENCE:0)
Block(5,16,-2,IRON_FENCE:0)
Block(5,16,-1,IRON_FENCE:0)

#######################################################################
# +-----------------------------------------------------------------+ #
# |                             Branches                            | #
# +-----------------------------------------------------------------+ #
#######################################################################


#######################################################################
# +-----------------------------------------------------------------+ #
# |                             Entities                            | #
# +-----------------------------------------------------------------+ #
#######################################################################


#######################################################################
# +-----------------------------------------------------------------+ #
# |                            Particles                            | #
# +-----------------------------------------------------------------+ #
#######################################################################


#######################################################################
# +-----------------------------------------------------------------+ #
# |                             Spawners                            | #
# +-----------------------------------------------------------------+ #
#######################################################################


#######################################################################
# +-----------------------------------------------------------------+ #
# |                             ModData                             | #
# +-----------------------------------------------------------------+ #
#######################################################################

