
#######################################################################
# +-----------------------------------------------------------------+ #
# |                            BO4 object                           | #
# +-----------------------------------------------------------------+ #
#######################################################################

Author: NLBlackEagle

Description: No description given

SettingsMode: WriteWithoutComments


#######################################################################
# +-----------------------------------------------------------------+ #
# |                          Main settings                          | #
# +-----------------------------------------------------------------+ #
#######################################################################

FixedRotation: 

Frequency: 0

SpawnHeight: highestSolidBlock

UseCenterForHighestBlock: true

##############################
# Height Limits for the BO4. #
##############################

MinHeight: 0

MaxHeight: 255

InheritBO3: 

InheritBO3Rotation: NORTH

OverrideChildSettings: true

OverrideParentHeight: false

CanOverride: true

BranchFrequency: 0

BranchFrequencyGroup: 

MustBeBelowOther: false

MustBeInside: 

CannotBeInside: 

ReplacesBO3: 

MustBeInsideWorldBorders: false

CanSpawnOnWater: false

SpawnOnWaterOnly: false

SpawnUnderWater: false

SpawnAtWaterLevel: false

HeightOffset: 0

RemoveAir: false

ReplaceAbove: 

ReplaceBelow: COBBLESTONE

ReplaceWithBiomeBlocks: false

ReplaceWithSurfaceBlock: GRASS

ReplaceWithGroundBlock: DIRT

ReplaceWithStoneBlock: STONE

SmoothRadius: 0

SmoothHeightOffset: 0

SmoothStartTop: false

SmoothStartWood: false

SmoothingSurfaceBlock: 

SmoothingGroundBlock: 

BO3Group: 

IsSpawnPoint: false

DoReplaceBlocks: true


#######################################################################
# +-----------------------------------------------------------------+ #
# |                              Blocks                             | #
# +-----------------------------------------------------------------+ #
#######################################################################

Block(-5,0,-3,COBBLESTONE:0)
Block(-5,1,-3,COBBLESTONE_STAIRS:2)
Block(-4,0,-4,COBBLESTONE:0)
Block(-4,0,-3,COBBLESTONE:0)
Block(-4,0,0,COBBLESTONE:0)
Block(-4,0,1,COBBLESTONE:0)
Block(-4,1,-4,COBBLESTONE_STAIRS:0)
Block(-4,1,-3,COBBLESTONE_STAIRS:0)
Block(-4,1,0,COBBLESTONE_STAIRS:0)
Block(-4,1,1,COBBLESTONE_STAIRS:0)
Block(-4,3,-6,COBBLESTONE_STAIRS:0)
Block(-4,3,-5,COBBLESTONE_STAIRS:0)
Block(-4,3,2,COBBLESTONE_STAIRS:0)
Block(-4,3,3,COBBLESTONE_STAIRS:3)
Block(-3,0,-5,COBBLESTONE:0)
Block(-3,0,-4,COBBLESTONE:0)
Block(-3,0,-2,COBBLESTONE:0)
Block(-3,0,-1,COBBLESTONE:0)
Block(-3,0,0,COBBLESTONE:0)
Block(-3,0,1,COBBLESTONE:0)
Block(-3,0,2,COBBLESTONE:0)
Block(-3,1,-5,BRICK:0)
Block(-3,1,-4,BRICK:0)
Block(-3,1,-2,BRICK:0)
Block(-3,1,-1,BRICK:0)
Block(-3,1,0,BRICK:0)
Block(-3,1,1,BRICK:0)
Block(-3,1,2,BRICK:0)
Block(-3,2,-5,BRICK:0)
Block(-3,2,-4,BRICK_STAIRS:2)
Block(-3,2,-2,BRICK:0)
Block(-3,2,-1,STEP:12)
Block(-3,2,0,BRICK_STAIRS:3)
Block(-3,2,1,STEP:4)
Block(-3,2,2,BRICK:0)
Block(-3,3,-6,COBBLESTONE_STAIRS:2)
Block(-3,3,-5,BRICK:0)
Block(-3,3,-3,STEP:4)
Block(-3,3,-2,BRICK_STAIRS:2)
Block(-3,3,-1,BRICK_STAIRS:7)
Block(-3,3,0,STEP:12)
Block(-3,3,1,BRICK_STAIRS:6)
Block(-3,3,2,BRICK:0)
Block(-3,3,3,COBBLESTONE_STAIRS:3)
Block(-3,3,4,COBBLESTONE_STAIRS:0)
Block(-3,4,-5,COBBLESTONE_STAIRS:2)
Block(-3,4,-2,COBBLESTONE_STAIRS:0)
Block(-3,4,-1,COBBLESTONE_STAIRS:0)
Block(-3,4,0,COBBLESTONE_STAIRS:0)
Block(-3,4,1,COBBLESTONE_STAIRS:0)
Block(-3,4,2,COBBLESTONE_STAIRS:3)
Block(-2,0,-5,COBBLESTONE:0)
Block(-2,0,3,COBBLESTONE:0)
Block(-2,1,-5,BRICK:0)
Block(-2,1,3,BRICK:0)
Block(-2,2,-5,BRICK:0)
Block(-2,2,3,BRICK:0)
Block(-2,3,-6,COBBLESTONE_STAIRS:2)
Block(-2,3,-5,BRICK:0)
Block(-2,3,3,BRICK:0)
Block(-2,3,4,COBBLESTONE_STAIRS:3)
Block(-2,4,-5,COBBLESTONE_STAIRS:2)
Block(-2,4,1,STEP:12)
Block(-2,4,2,COBBLESTONE_STAIRS:0)
Block(-2,4,3,COBBLESTONE_STAIRS:3)
Block(-2,5,-4,COBBLESTONE_STAIRS:2)
Block(-2,5,-3,COBBLESTONE_STAIRS:0)
Block(-2,5,-2,COBBLESTONE_STAIRS:0)
Block(-2,5,-1,COBBLESTONE_STAIRS:0)
Block(-2,5,0,COBBLESTONE_STAIRS:0)
Block(-2,5,1,COBBLESTONE_STAIRS:0)
Block(-1,0,-5,COBBLESTONE:0)
Block(-1,0,-3,COBBLESTONE_STAIRS:2)
Block(-1,0,3,COBBLESTONE:0)
Block(-1,0,4,COBBLESTONE:0)
Block(-1,1,-5,BRICK:0)
Block(-1,1,-3,COBBLESTONE_STAIRS:2)
Block(-1,1,3,BRICK:0)
Block(-1,1,4,COBBLESTONE_STAIRS:3)
Block(-1,2,-5,BRICK:0)
Block(-1,2,3,STEP:4)
Block(-1,3,-6,COBBLESTONE_STAIRS:2)
Block(-1,3,-5,BRICK:0)
Block(-1,3,3,BRICK_STAIRS:5)
Block(-1,4,-5,COBBLESTONE_STAIRS:2)
Block(-1,4,2,STEP:12)
Block(-1,4,3,COBBLESTONE_STAIRS:3)
Block(-1,5,-4,COBBLESTONE_STAIRS:2)
Block(-1,5,1,COBBLESTONE_STAIRS:3)
Block(-1,5,2,COBBLESTONE_STAIRS:0)
Block(-1,6,-3,COBBLESTONE_STAIRS:2)
Block(-1,6,-2,COBBLESTONE_STAIRS:0)
Block(0,0,-5,COBBLESTONE:0)
Block(0,0,-1,COBBLESTONE:0)
Block(0,0,0,COBBLESTONE:0)
Block(0,0,1,COBBLESTONE:0)
Block(0,0,3,COBBLESTONE:0)
Block(0,0,4,COBBLESTONE:0)
Block(0,1,-5,BRICK:0)
Block(0,1,-1,COBBLESTONE_STAIRS:0)
Block(0,1,0,COBBLESTONE_STAIRS:0)
Block(0,1,1,COBBLESTONE_STAIRS:0)
Block(0,1,3,BRICK:0)
Block(0,1,4,COBBLESTONE_STAIRS:3)
Block(0,2,-5,BRICK_STAIRS:1)
Block(0,2,-2,VINE:8)
Block(0,2,3,BRICK_STAIRS:0)
Block(0,3,-5,BRICK_STAIRS:5)
Block(0,3,-2,VINE:8)
Block(0,3,3,BRICK_STAIRS:4)
Block(0,4,-5,COBBLESTONE_STAIRS:2)
Block(0,4,-2,VINE:8)
Block(0,4,3,COBBLESTONE_STAIRS:3)
Block(0,5,-4,COBBLESTONE_STAIRS:2)
Block(0,5,-2,VINE:8)
Block(0,5,2,COBBLESTONE_STAIRS:3)
Block(0,6,-3,COBBLESTONE_STAIRS:2)
Block(0,6,-2,VINE:8)
Block(1,0,-5,COBBLESTONE:0)
Block(1,0,1,COBBLESTONE:0)
Block(1,0,3,COBBLESTONE:0)
Block(1,1,-5,STEP:4)
Block(1,1,1,COBBLESTONE_STAIRS:3)
Block(1,1,3,BRICK:0)
Block(1,2,-1,VINE:12)
Block(1,2,3,BRICK:0)
Block(1,3,-1,VINE:12)
Block(1,3,0,VINE:8)
Block(1,3,3,BRICK:0)
Block(1,3,5,COBBLESTONE_STAIRS:0)
Block(1,3,6,COBBLESTONE_STAIRS:3)
Block(1,4,-5,COBBLESTONE_STAIRS:2)
Block(1,4,-1,VINE:12)
Block(1,4,0,VINE:8)
Block(1,4,3,COBBLESTONE_STAIRS:3)
Block(1,5,-4,COBBLESTONE_STAIRS:2)
Block(1,5,-1,VINE:12)
Block(1,5,0,VINE:8)
Block(1,5,2,COBBLESTONE_STAIRS:3)
Block(1,6,-3,COBBLESTONE_STAIRS:2)
Block(1,6,-2,COBBLESTONE:0)
Block(1,6,-1,VINE:12)
Block(1,6,0,VINE:8)
Block(2,0,-5,COBBLESTONE:0)
Block(2,0,4,COBBLESTONE:0)
Block(2,0,5,COBBLESTONE:0)
Block(2,1,-5,BRICK_STAIRS:0)
Block(2,1,4,BRICK:0)
Block(2,1,5,BRICK:0)
Block(2,2,4,BRICK_STAIRS:2)
Block(2,2,5,BRICK:0)
Block(2,3,5,STEP:4)
Block(2,3,6,COBBLESTONE_STAIRS:3)
Block(2,3,7,COBBLESTONE_STAIRS:0)
Block(2,4,-5,STEP:4)
Block(2,4,2,BRICK:0)
Block(2,4,3,COBBLESTONE_STAIRS:0)
Block(2,4,5,COBBLESTONE_STAIRS:0)
Block(2,5,-4,COBBLESTONE_STAIRS:2)
Block(2,5,2,COBBLESTONE_STAIRS:3)
Block(2,6,-3,COBBLESTONE_STAIRS:1)
Block(2,6,-2,COBBLESTONE:0)
Block(2,6,-1,COBBLESTONE:0)
Block(2,6,0,COBBLESTONE:0)
Block(2,6,1,COBBLESTONE_STAIRS:3)
Block(3,0,-5,COBBLESTONE:0)
Block(3,0,6,COBBLESTONE:0)
Block(3,1,-5,BRICK:0)
Block(3,1,6,BRICK:0)
Block(3,2,-5,BRICK_STAIRS:0)
Block(3,2,6,BRICK_STAIRS:1)
Block(3,3,-5,BRICK_STAIRS:4)
Block(3,3,6,STEP:4)
Block(3,3,7,COBBLESTONE_STAIRS:3)
Block(3,4,-5,COBBLESTONE_STAIRS:2)
Block(3,4,-4,WEB:0)
Block(3,4,-1,VINE:2)
Block(3,4,2,BRICK:0)
Block(3,4,3,BRICK:0)
Block(3,4,4,BRICK:0)
Block(3,4,5,COBBLESTONE_STAIRS:3)
Block(3,4,6,COBBLESTONE_STAIRS:0)
Block(3,5,-4,COBBLESTONE_STAIRS:1)
Block(3,5,-3,COBBLESTONE_STAIRS:2)
Block(3,5,-1,VINE:2)
Block(3,5,2,COBBLESTONE_STAIRS:3)
Block(3,5,3,COBBLESTONE_STAIRS:0)
Block(3,5,4,COBBLESTONE_STAIRS:0)
Block(3,6,-2,COBBLESTONE_STAIRS:1)
Block(3,6,-1,VINE:2)
Block(3,6,0,COBBLESTONE_STAIRS:1)
Block(3,6,1,COBBLESTONE_STAIRS:3)
Block(4,0,-5,COBBLESTONE:0)
Block(4,0,6,COBBLESTONE:0)
Block(4,1,-5,BRICK:0)
Block(4,1,6,BRICK:0)
Block(4,2,-5,BRICK:0)
Block(4,2,6,BRICK_STAIRS:4)
Block(4,3,-6,COBBLESTONE_STAIRS:2)
Block(4,3,-5,STEP:4)
Block(4,3,-4,WEB:0)
Block(4,3,6,BRICK_STAIRS:2)
Block(4,3,7,COBBLESTONE_STAIRS:3)
Block(4,4,-5,COBBLESTONE_STAIRS:2)
Block(4,4,-4,COBBLESTONE_STAIRS:1)
Block(4,4,-3,WEB:0)
Block(4,4,2,BRICK:0)
Block(4,4,3,BRICK:0)
Block(4,4,4,BRICK:0)
Block(4,5,-3,COBBLESTONE_STAIRS:1)
Block(4,5,-2,COBBLESTONE_STAIRS:1)
Block(4,5,-1,COBBLESTONE_STAIRS:1)
Block(4,5,0,COBBLESTONE_STAIRS:1)
Block(4,5,1,COBBLESTONE_STAIRS:1)
Block(4,5,2,COBBLESTONE_STAIRS:1)
Block(4,5,3,COBBLESTONE_STAIRS:1)
Block(4,5,4,COBBLESTONE_STAIRS:1)
Block(5,0,-4,COBBLESTONE:0)
Block(5,0,-3,COBBLESTONE:0)
Block(5,0,-2,COBBLESTONE:0)
Block(5,0,0,COBBLESTONE:0)
Block(5,0,1,COBBLESTONE:0)
Block(5,0,2,COBBLESTONE:0)
Block(5,0,4,COBBLESTONE:0)
Block(5,0,5,COBBLESTONE:0)
Block(5,1,-4,BRICK:0)
Block(5,1,-3,BRICK:0)
Block(5,1,-2,BRICK:0)
Block(5,1,0,BRICK:0)
Block(5,1,1,BRICK:0)
Block(5,1,2,BRICK_STAIRS:3)
Block(5,1,4,STEP:4)
Block(5,1,5,BRICK:0)
Block(5,2,-4,BRICK:0)
Block(5,2,-3,STEP:4)
Block(5,2,-2,BRICK_STAIRS:2)
Block(5,2,0,BRICK_STAIRS:2)
Block(5,2,1,BRICK:0)
Block(5,2,2,BRICK_STAIRS:7)
Block(5,2,5,BRICK_STAIRS:2)
Block(5,3,-6,COBBLESTONE_STAIRS:1)
Block(5,3,-5,COBBLESTONE_STAIRS:2)
Block(5,3,-4,BRICK:0)
Block(5,3,-3,BRICK_STAIRS:7)
Block(5,3,-2,BRICK:0)
Block(5,3,-1,STEP:4)
Block(5,3,0,STEP:12)
Block(5,3,1,BRICK_STAIRS:7)
Block(5,3,2,STEP:12)
Block(5,3,3,BRICK_STAIRS:7)
Block(5,3,4,STEP:12)
Block(5,3,5,BRICK_STAIRS:6)
Block(5,3,6,COBBLESTONE_STAIRS:3)
Block(5,3,7,COBBLESTONE_STAIRS:1)
Block(5,4,-4,COBBLESTONE_STAIRS:2)
Block(5,4,-3,COBBLESTONE_STAIRS:1)
Block(5,4,-2,COBBLESTONE_STAIRS:1)
Block(5,4,-1,COBBLESTONE_STAIRS:1)
Block(5,4,0,COBBLESTONE_STAIRS:1)
Block(5,4,1,COBBLESTONE_STAIRS:1)
Block(5,4,2,COBBLESTONE_STAIRS:1)
Block(5,4,3,COBBLESTONE_STAIRS:1)
Block(5,4,4,COBBLESTONE_STAIRS:1)
Block(5,4,5,COBBLESTONE_STAIRS:1)
Block(6,3,-5,COBBLESTONE_STAIRS:1)
Block(6,3,-4,COBBLESTONE_STAIRS:1)
Block(6,3,-2,COBBLESTONE_STAIRS:1)
Block(6,3,5,COBBLESTONE_STAIRS:1)
Block(6,3,6,COBBLESTONE_STAIRS:1)

#######################################################################
# +-----------------------------------------------------------------+ #
# |                             Branches                            | #
# +-----------------------------------------------------------------+ #
#######################################################################


#######################################################################
# +-----------------------------------------------------------------+ #
# |                             Entities                            | #
# +-----------------------------------------------------------------+ #
#######################################################################


#######################################################################
# +-----------------------------------------------------------------+ #
# |                            Particles                            | #
# +-----------------------------------------------------------------+ #
#######################################################################


#######################################################################
# +-----------------------------------------------------------------+ #
# |                             Spawners                            | #
# +-----------------------------------------------------------------+ #
#######################################################################


#######################################################################
# +-----------------------------------------------------------------+ #
# |                             ModData                             | #
# +-----------------------------------------------------------------+ #
#######################################################################

