
#######################################################################
# +-----------------------------------------------------------------+ #
# |                            BO4 object                           | #
# +-----------------------------------------------------------------+ #
#######################################################################

Author: NLBlackEagle

Description: No description given

SettingsMode: WriteWithoutComments


#######################################################################
# +-----------------------------------------------------------------+ #
# |                          Main settings                          | #
# +-----------------------------------------------------------------+ #
#######################################################################

FixedRotation: 

Frequency: 0

SpawnHeight: highestSolidBlock

UseCenterForHighestBlock: true

##############################
# Height Limits for the BO4. #
##############################

MinHeight: 0

MaxHeight: 255

InheritBO3: 

InheritBO3Rotation: NORTH

OverrideChildSettings: true

OverrideParentHeight: false

CanOverride: true

BranchFrequency: 0

BranchFrequencyGroup: 

MustBeBelowOther: false

MustBeInside: 

CannotBeInside: 

ReplacesBO3: 

MustBeInsideWorldBorders: false

CanSpawnOnWater: false

SpawnOnWaterOnly: false

SpawnUnderWater: false

SpawnAtWaterLevel: false

HeightOffset: 0

RemoveAir: false

ReplaceAbove: AIR

ReplaceBelow: COBBLESTONE

ReplaceWithBiomeBlocks: false

ReplaceWithSurfaceBlock: GRASS

ReplaceWithGroundBlock: DIRT

ReplaceWithStoneBlock: STONE

SmoothRadius: 7

SmoothHeightOffset: 0

SmoothStartTop: true

SmoothStartWood: false

SmoothingSurfaceBlock: 

SmoothingGroundBlock: 

BO3Group: 

IsSpawnPoint: false

DoReplaceBlocks: true


#######################################################################
# +-----------------------------------------------------------------+ #
# |                              Blocks                             | #
# +-----------------------------------------------------------------+ #
#######################################################################

Block(-5,7,-3,MOSSY_COBBLESTONE:0)
Block(-5,7,0,COBBLESTONE:0)
Block(-5,7,1,COBBLESTONE:0)
Block(-5,7,2,COBBLESTONE:0)
Block(-5,7,3,MOSSY_COBBLESTONE:0)
Block(-4,0,-1,COBBLESTONE:0)
Block(-4,0,0,COBBLESTONE:0)
Block(-4,0,1,COBBLESTONE:0)
Block(-4,1,-1,COBBLESTONE:0)
Block(-4,1,0,MOSSY_COBBLESTONE:0)
Block(-4,1,1,COBBLESTONE:0)
Block(-4,2,-1,MOSSY_COBBLESTONE:0)
Block(-4,2,0,COBBLESTONE:0)
Block(-4,2,1,MOSSY_COBBLESTONE:0)
Block(-4,3,-1,COBBLESTONE:0)
Block(-4,3,0,MOSSY_COBBLESTONE:0)
Block(-4,3,1,COBBLESTONE:0)
Block(-4,4,-1,COBBLESTONE:0)
Block(-4,4,0,COBBLESTONE:0)
Block(-4,4,1,COBBLESTONE:0)
Block(-4,5,-1,COBBLESTONE:0)
Block(-4,5,0,COBBLESTONE:0)
Block(-4,5,1,COBBLESTONE:0)
Block(-4,6,-2,COBBLESTONE:0)
Block(-4,6,-1,COBBLESTONE:0)
Block(-4,6,0,COBBLESTONE:0)
Block(-4,6,1,COBBLESTONE:0)
Block(-4,6,2,COBBLESTONE:0)
Block(-4,7,-4,MOSSY_COBBLESTONE:0)
Block(-4,7,-3,COBBLESTONE:0)
Block(-4,7,-2,COBBLESTONE_STAIRS:1)
Block(-4,7,-1,COBBLESTONE_STAIRS:1)
Block(-4,7,0,COBBLESTONE_STAIRS:1)
Block(-4,7,1,COBBLESTONE_STAIRS:1)
Block(-4,7,2,COBBLESTONE_STAIRS:1)
Block(-4,7,3,COBBLESTONE:0)
Block(-3,0,-2,COBBLESTONE:0)
Block(-3,0,-1,COBBLESTONE:0)
Block(-3,0,0,COBBLESTONE:0)
Block(-3,0,1,COBBLESTONE:0)
Block(-3,0,2,COBBLESTONE:0)
Block(-3,1,-2,MOSSY_COBBLESTONE:0)
Block(-3,1,-1,COBBLESTONE:0)
Block(-3,1,0,COBBLESTONE:0)
Block(-3,1,1,COBBLESTONE:0)
Block(-3,1,2,COBBLESTONE:0)
Block(-3,2,-2,COBBLESTONE:0)
Block(-3,2,-1,COBBLESTONE:0)
Block(-3,2,0,MOSSY_COBBLESTONE:0)
Block(-3,2,1,COBBLESTONE:0)
Block(-3,2,2,MOSSY_COBBLESTONE:0)
Block(-3,3,-2,COBBLESTONE:0)
Block(-3,3,-1,AIR:0)
Block(-3,3,0,AIR:0)
Block(-3,3,1,AIR:0)
Block(-3,3,2,MOSSY_COBBLESTONE:0)
Block(-3,4,-2,COBBLESTONE:0)
Block(-3,4,-1,COBBLESTONE:0)
Block(-3,4,0,AIR:0)
Block(-3,4,1,MOSSY_COBBLESTONE:0)
Block(-3,4,2,COBBLESTONE:0)
Block(-3,5,-2,COBBLESTONE:0)
Block(-3,5,-1,COBBLESTONE:0)
Block(-3,5,0,MOSSY_COBBLESTONE:0)
Block(-3,5,1,COBBLESTONE:0)
Block(-3,5,2,COBBLESTONE:0)
Block(-3,6,-3,COBBLESTONE:0)
Block(-3,6,-2,COBBLESTONE:0)
Block(-3,6,-1,COBBLESTONE:0)
Block(-3,6,0,MOSSY_COBBLESTONE:0)
Block(-3,6,1,MOSSY_COBBLESTONE:0)
Block(-3,6,2,COBBLESTONE:0)
Block(-3,6,3,COBBLESTONE:0)
Block(-3,7,-5,COBBLESTONE:0)
Block(-3,7,-4,COBBLESTONE:0)
Block(-3,7,-3,STEP:3)
Block(-3,7,-2,AIR:0)
Block(-3,7,-1,AIR:0)
Block(-3,7,0,AIR:0)
Block(-3,7,1,AIR:0)
Block(-3,7,2,AIR:0)
Block(-3,7,3,STEP:3)
Block(-3,7,4,COBBLESTONE:0)
Block(-2,0,-3,COBBLESTONE:0)
Block(-2,0,-2,COBBLESTONE:0)
Block(-2,0,-1,COBBLESTONE:0)
Block(-2,0,0,COBBLESTONE:0)
Block(-2,0,1,COBBLESTONE:0)
Block(-2,0,2,COBBLESTONE:0)
Block(-2,0,3,COBBLESTONE:0)
Block(-2,1,-3,MOSSY_COBBLESTONE:0)
Block(-2,1,-2,COBBLESTONE:0)
Block(-2,1,-1,GRAVEL:0)
Block(-2,1,0,GRAVEL:0)
Block(-2,1,1,GRAVEL:0)
Block(-2,1,2,COBBLESTONE:0)
Block(-2,1,3,COBBLESTONE:0)
Block(-2,2,-3,MOSSY_COBBLESTONE:0)
Block(-2,2,-2,MOSSY_COBBLESTONE:0)
Block(-2,2,-1,AIR:0)
Block(-2,2,0,AIR:0)
Block(-2,2,1,AIR:0)
Block(-2,2,2,COBBLESTONE:0)
Block(-2,2,3,COBBLESTONE:0)
Block(-2,3,-3,COBBLESTONE:0)
Block(-2,3,-2,COBBLESTONE:0)
Block(-2,3,-1,AIR:0)
Block(-2,3,0,AIR:0)
Block(-2,3,1,AIR:0)
Block(-2,3,2,COBBLESTONE:0)
Block(-2,3,3,COBBLESTONE:0)
Block(-2,4,-3,COBBLESTONE:0)
Block(-2,4,-2,MOSSY_COBBLESTONE:0)
Block(-2,4,-1,AIR:0)
Block(-2,4,0,AIR:0)
Block(-2,4,1,AIR:0)
Block(-2,4,2,COBBLESTONE:0)
Block(-2,4,3,COBBLESTONE:0)
Block(-2,5,-3,COBBLESTONE:0)
Block(-2,5,-2,MOSSY_COBBLESTONE:0)
Block(-2,5,-1,AIR:0)
Block(-2,5,0,AIR:0)
Block(-2,5,1,AIR:0)
Block(-2,5,2,COBBLESTONE:0)
Block(-2,5,3,MOSSY_COBBLESTONE:0)
Block(-2,6,-4,COBBLESTONE:0)
Block(-2,6,-3,COBBLESTONE:0)
Block(-2,6,-2,MOSSY_COBBLESTONE:0)
Block(-2,6,-1,COBBLESTONE_STAIRS:1)
Block(-2,6,0,COBBLESTONE_STAIRS:1)
Block(-2,6,1,COBBLESTONE_STAIRS:1)
Block(-2,6,2,COBBLESTONE:0)
Block(-2,6,3,COBBLESTONE:0)
Block(-2,6,4,COBBLESTONE:0)
Block(-2,7,-4,COBBLESTONE_STAIRS:3)
Block(-2,7,-3,AIR:0)
Block(-2,7,-2,AIR:0)
Block(-2,7,-1,AIR:0)
Block(-2,7,0,AIR:0)
Block(-2,7,1,AIR:0)
Block(-2,7,2,AIR:0)
Block(-2,7,3,AIR:0)
Block(-2,7,4,COBBLESTONE_STAIRS:2)
Block(-2,7,5,MOSSY_COBBLESTONE:0)
Block(-1,0,-4,COBBLESTONE:0)
Block(-1,0,-3,COBBLESTONE:0)
Block(-1,0,-2,COBBLESTONE:0)
Block(-1,0,-1,COBBLESTONE:0)
Block(-1,0,0,COBBLESTONE:0)
Block(-1,0,1,COBBLESTONE:0)
Block(-1,0,2,COBBLESTONE:0)
Block(-1,0,3,COBBLESTONE:0)
Block(-1,0,4,COBBLESTONE:0)
Block(-1,1,-4,COBBLESTONE:0)
Block(-1,1,-3,MOSSY_COBBLESTONE:0)
Block(-1,1,-2,GRAVEL:0)
Block(-1,1,-1,GRAVEL:0)
Block(-1,1,0,GRAVEL:0)
Block(-1,1,1,GRAVEL:0)
Block(-1,1,2,GRAVEL:0)
Block(-1,1,3,COBBLESTONE:0)
Block(-1,1,4,COBBLESTONE:0)
Block(-1,2,-4,COBBLESTONE:0)
Block(-1,2,-3,COBBLESTONE:0)
Block(-1,2,-2,AIR:0)
Block(-1,2,-1,AIR:0)
Block(-1,2,0,AIR:0)
Block(-1,2,1,AIR:0)
Block(-1,2,2,AIR:0)
Block(-1,2,3,COBBLESTONE:0)
Block(-1,2,4,MOSSY_COBBLESTONE:0)
Block(-1,3,-4,COBBLESTONE:0)
Block(-1,3,-3,AIR:0)
Block(-1,3,-2,AIR:0)
Block(-1,3,-1,AIR:0)
Block(-1,3,0,AIR:0)
Block(-1,3,1,AIR:0)
Block(-1,3,2,AIR:0)
Block(-1,3,3,AIR:0)
Block(-1,3,4,COBBLESTONE:0)
Block(-1,4,-4,COBBLESTONE:0)
Block(-1,4,-3,COBBLESTONE:0)
Block(-1,4,-2,AIR:0)
Block(-1,4,-1,AIR:0)
Block(-1,4,0,AIR:0)
Block(-1,4,1,AIR:0)
Block(-1,4,2,AIR:0)
Block(-1,4,3,MOSSY_COBBLESTONE:0)
Block(-1,4,4,COBBLESTONE:0)
Block(-1,5,-4,MOSSY_COBBLESTONE:0)
Block(-1,5,-3,MOSSY_COBBLESTONE:0)
Block(-1,5,-2,AIR:0)
Block(-1,5,-1,AIR:0)
Block(-1,5,0,AIR:0)
Block(-1,5,1,AIR:0)
Block(-1,5,2,AIR:0)
Block(-1,5,3,COBBLESTONE:0)
Block(-1,5,4,MOSSY_COBBLESTONE:0)
Block(-1,6,-4,COBBLESTONE:0)
Block(-1,6,-3,COBBLESTONE:0)
Block(-1,6,-2,COBBLESTONE_STAIRS:3)
Block(-1,6,-1,AIR:0)
Block(-1,6,0,AIR:0)
Block(-1,6,1,AIR:0)
Block(-1,6,2,COBBLESTONE_STAIRS:2)
Block(-1,6,3,MOSSY_COBBLESTONE:0)
Block(-1,6,4,COBBLESTONE:0)
Block(-1,7,-4,COBBLESTONE_STAIRS:3)
Block(-1,7,-3,AIR:0)
Block(-1,7,-2,AIR:0)
Block(-1,7,-1,AIR:0)
Block(-1,7,0,AIR:0)
Block(-1,7,1,AIR:0)
Block(-1,7,2,AIR:0)
Block(-1,7,3,AIR:0)
Block(-1,7,4,COBBLESTONE_STAIRS:2)
Block(0,0,-4,COBBLESTONE:0)
Block(0,0,-3,COBBLESTONE:0)
Block(0,0,-2,COBBLESTONE:0)
Block(0,0,-1,COBBLESTONE:0)
Block(0,0,0,COBBLESTONE:0)
Block(0,0,1,COBBLESTONE:0)
Block(0,0,2,COBBLESTONE:0)
Block(0,0,3,COBBLESTONE:0)
Block(0,0,4,COBBLESTONE:0)
Block(0,1,-4,MOSSY_COBBLESTONE:0)
Block(0,1,-3,COBBLESTONE:0)
Block(0,1,-2,GRAVEL:0)
Block(0,1,-1,GRAVEL:0)
Block(0,1,0,GRAVEL:0)
Block(0,1,1,GRAVEL:0)
Block(0,1,2,GRAVEL:0)
Block(0,1,3,COBBLESTONE:0)
Block(0,1,4,MOSSY_COBBLESTONE:0)
Block(0,2,-4,COBBLESTONE:0)
Block(0,2,-3,COBBLESTONE:0)
Block(0,2,-2,AIR:0)
Block(0,2,-1,AIR:0)
Block(0,2,0,AIR:0)
Block(0,2,1,AIR:0)
Block(0,2,2,AIR:0)
Block(0,2,3,COBBLESTONE:0)
Block(0,2,4,MOSSY_COBBLESTONE:0)
Block(0,3,-4,MOSSY_COBBLESTONE:0)
Block(0,3,-3,AIR:0)
Block(0,3,-2,AIR:0)
Block(0,3,-1,AIR:0)
Block(0,3,0,AIR:0)
Block(0,3,1,AIR:0)
Block(0,3,2,AIR:0)
Block(0,3,3,AIR:0)
Block(0,3,4,COBBLESTONE:0)
Block(0,4,-4,COBBLESTONE:0)
Block(0,4,-3,AIR:0)
Block(0,4,-2,AIR:0)
Block(0,4,-1,AIR:0)
Block(0,4,0,AIR:0)
Block(0,4,1,AIR:0)
Block(0,4,2,AIR:0)
Block(0,4,3,AIR:0)
Block(0,4,4,COBBLESTONE:0)
Block(0,5,-4,COBBLESTONE:0)
Block(0,5,-3,COBBLESTONE:0)
Block(0,5,-2,AIR:0)
Block(0,5,-1,AIR:0)
Block(0,5,0,AIR:0)
Block(0,5,1,AIR:0)
Block(0,5,2,AIR:0)
Block(0,5,3,COBBLESTONE:0)
Block(0,5,4,COBBLESTONE:0)
Block(0,6,-4,COBBLESTONE:0)
Block(0,6,-3,MOSSY_COBBLESTONE:0)
Block(0,6,-2,COBBLESTONE_STAIRS:3)
Block(0,6,-1,AIR:0)
Block(0,6,0,AIR:0)
Block(0,6,1,AIR:0)
Block(0,6,2,COBBLESTONE_STAIRS:2)
Block(0,6,3,COBBLESTONE:0)
Block(0,6,4,COBBLESTONE:0)
Block(0,7,-5,COBBLESTONE:0)
Block(0,7,-4,COBBLESTONE_STAIRS:3)
Block(0,7,-3,AIR:0)
Block(0,7,-2,AIR:0)
Block(0,7,-1,AIR:0)
Block(0,7,0,AIR:0)
Block(0,7,1,AIR:0)
Block(0,7,2,AIR:0)
Block(0,7,3,AIR:0)
Block(0,7,4,COBBLESTONE_STAIRS:2)
Block(0,7,5,COBBLESTONE:0)
Block(1,0,-4,COBBLESTONE:0)
Block(1,0,-3,COBBLESTONE:0)
Block(1,0,-2,COBBLESTONE:0)
Block(1,0,-1,COBBLESTONE:0)
Block(1,0,0,COBBLESTONE:0)
Block(1,0,1,COBBLESTONE:0)
Block(1,0,2,COBBLESTONE:0)
Block(1,0,3,COBBLESTONE:0)
Block(1,0,4,COBBLESTONE:0)
Block(1,1,-4,COBBLESTONE:0)
Block(1,1,-3,COBBLESTONE:0)
Block(1,1,-2,GRAVEL:0)
Block(1,1,-1,GRAVEL:0)
Block(1,1,0,GRAVEL:0)
Block(1,1,1,GRAVEL:0)
Block(1,1,2,GRAVEL:0)
Block(1,1,3,COBBLESTONE:0)
Block(1,1,4,MOSSY_COBBLESTONE:0)
Block(1,2,-4,COBBLESTONE:0)
Block(1,2,-3,COBBLESTONE:0)
Block(1,2,-2,AIR:0)
Block(1,2,-1,AIR:0)
Block(1,2,0,AIR:0)
Block(1,2,1,AIR:0)
Block(1,2,2,AIR:0)
Block(1,2,3,COBBLESTONE:0)
Block(1,2,4,COBBLESTONE:0)
Block(1,3,-4,COBBLESTONE:0)
Block(1,3,-3,AIR:0)
Block(1,3,-2,AIR:0)
Block(1,3,-1,AIR:0)
Block(1,3,0,AIR:0)
Block(1,3,1,AIR:0)
Block(1,3,2,AIR:0)
Block(1,3,3,AIR:0)
Block(1,3,4,COBBLESTONE:0)
Block(1,4,-4,COBBLESTONE:0)
Block(1,4,-3,COBBLESTONE:0)
Block(1,4,-2,AIR:0)
Block(1,4,-1,AIR:0)
Block(1,4,0,AIR:0)
Block(1,4,1,AIR:0)
Block(1,4,2,AIR:0)
Block(1,4,3,MOSSY_COBBLESTONE:0)
Block(1,4,4,COBBLESTONE:0)
Block(1,5,-4,COBBLESTONE:0)
Block(1,5,-3,COBBLESTONE:0)
Block(1,5,-2,AIR:0)
Block(1,5,-1,AIR:0)
Block(1,5,0,AIR:0)
Block(1,5,1,AIR:0)
Block(1,5,2,AIR:0)
Block(1,5,3,COBBLESTONE:0)
Block(1,5,4,MOSSY_COBBLESTONE:0)
Block(1,6,-4,COBBLESTONE:0)
Block(1,6,-3,COBBLESTONE:0)
Block(1,6,-2,COBBLESTONE_STAIRS:3)
Block(1,6,-1,AIR:0)
Block(1,6,0,AIR:0)
Block(1,6,1,AIR:0)
Block(1,6,2,COBBLESTONE_STAIRS:2)
Block(1,6,3,COBBLESTONE:0)
Block(1,6,4,COBBLESTONE:0)
Block(1,7,-5,COBBLESTONE:0)
Block(1,7,-4,COBBLESTONE_STAIRS:3)
Block(1,7,-3,AIR:0)
Block(1,7,-2,AIR:0)
Block(1,7,-1,AIR:0)
Block(1,7,0,AIR:0)
Block(1,7,1,AIR:0)
Block(1,7,2,AIR:0)
Block(1,7,3,AIR:0)
Block(1,7,4,COBBLESTONE_STAIRS:2)
Block(2,0,-3,COBBLESTONE:0)
Block(2,0,-2,COBBLESTONE:0)
Block(2,0,-1,COBBLESTONE:0)
Block(2,0,0,COBBLESTONE:0)
Block(2,0,1,COBBLESTONE:0)
Block(2,0,2,COBBLESTONE:0)
Block(2,0,3,COBBLESTONE:0)
Block(2,1,-3,COBBLESTONE:0)
Block(2,1,-2,MOSSY_COBBLESTONE:0)
Block(2,1,-1,GRAVEL:0)
Block(2,1,0,GRAVEL:0)
Block(2,1,1,GRAVEL:0)
Block(2,1,2,MOSSY_COBBLESTONE:0)
Block(2,1,3,COBBLESTONE:0)
Block(2,2,-3,MOSSY_COBBLESTONE:0)
Block(2,2,-2,COBBLESTONE:0)
Block(2,2,-1,AIR:0)
Block(2,2,0,AIR:0)
Block(2,2,1,AIR:0)
Block(2,2,2,COBBLESTONE:0)
Block(2,2,3,MOSSY_COBBLESTONE:0)
Block(2,3,-3,COBBLESTONE:0)
Block(2,3,-2,MOSSY_COBBLESTONE:0)
Block(2,3,-1,AIR:0)
Block(2,3,0,AIR:0)
Block(2,3,1,AIR:0)
Block(2,3,2,COBBLESTONE:0)
Block(2,3,3,MOSSY_COBBLESTONE:0)
Block(2,4,-3,COBBLESTONE:0)
Block(2,4,-2,COBBLESTONE:0)
Block(2,4,-1,AIR:0)
Block(2,4,0,AIR:0)
Block(2,4,1,AIR:0)
Block(2,4,2,MOSSY_COBBLESTONE:0)
Block(2,4,3,MOSSY_COBBLESTONE:0)
Block(2,5,-3,COBBLESTONE:0)
Block(2,5,-2,COBBLESTONE:0)
Block(2,5,-1,AIR:0)
Block(2,5,0,AIR:0)
Block(2,5,1,AIR:0)
Block(2,5,2,MOSSY_COBBLESTONE:0)
Block(2,5,3,COBBLESTONE:0)
Block(2,6,-4,COBBLESTONE:0)
Block(2,6,-3,COBBLESTONE:0)
Block(2,6,-2,COBBLESTONE:0)
Block(2,6,-1,COBBLESTONE_STAIRS:0)
Block(2,6,0,COBBLESTONE_STAIRS:0)
Block(2,6,1,COBBLESTONE_STAIRS:0)
Block(2,6,2,MOSSY_COBBLESTONE:0)
Block(2,6,3,COBBLESTONE:0)
Block(2,6,4,COBBLESTONE:0)
Block(2,7,-5,MOSSY_COBBLESTONE:0)
Block(2,7,-4,COBBLESTONE_STAIRS:3)
Block(2,7,-3,AIR:0)
Block(2,7,-2,AIR:0)
Block(2,7,-1,AIR:0)
Block(2,7,0,AIR:0)
Block(2,7,1,AIR:0)
Block(2,7,2,AIR:0)
Block(2,7,3,AIR:0)
Block(2,7,4,COBBLESTONE_STAIRS:2)
Block(3,0,-2,COBBLESTONE:0)
Block(3,0,-1,COBBLESTONE:0)
Block(3,0,0,COBBLESTONE:0)
Block(3,0,1,COBBLESTONE:0)
Block(3,0,2,COBBLESTONE:0)
Block(3,1,-2,COBBLESTONE:0)
Block(3,1,-1,COBBLESTONE:0)
Block(3,1,0,COBBLESTONE:0)
Block(3,1,1,COBBLESTONE:0)
Block(3,1,2,COBBLESTONE:0)
Block(3,2,-2,COBBLESTONE:0)
Block(3,2,-1,COBBLESTONE:0)
Block(3,2,0,MOSSY_COBBLESTONE:0)
Block(3,2,1,MOSSY_COBBLESTONE:0)
Block(3,2,2,MOSSY_COBBLESTONE:0)
Block(3,3,-2,COBBLESTONE:0)
Block(3,3,-1,AIR:0)
Block(3,3,0,AIR:0)
Block(3,3,1,AIR:0)
Block(3,3,2,COBBLESTONE:0)
Block(3,4,-2,COBBLESTONE:0)
Block(3,4,-1,COBBLESTONE:0)
Block(3,4,0,AIR:0)
Block(3,4,1,COBBLESTONE:0)
Block(3,4,2,COBBLESTONE:0)
Block(3,5,-2,MOSSY_COBBLESTONE:0)
Block(3,5,-1,COBBLESTONE:0)
Block(3,5,0,COBBLESTONE:0)
Block(3,5,1,MOSSY_COBBLESTONE:0)
Block(3,5,2,COBBLESTONE:0)
Block(3,6,-3,COBBLESTONE:0)
Block(3,6,-2,MOSSY_COBBLESTONE:0)
Block(3,6,-1,COBBLESTONE:0)
Block(3,6,0,MOSSY_COBBLESTONE:0)
Block(3,6,1,COBBLESTONE:0)
Block(3,6,2,MOSSY_COBBLESTONE:0)
Block(3,6,3,COBBLESTONE:0)
Block(3,7,-4,COBBLESTONE:0)
Block(3,7,-3,STEP:3)
Block(3,7,-2,AIR:0)
Block(3,7,-1,AIR:0)
Block(3,7,0,AIR:0)
Block(3,7,1,AIR:0)
Block(3,7,2,AIR:0)
Block(3,7,3,STEP:3)
Block(3,7,4,COBBLESTONE:0)
Block(3,7,5,COBBLESTONE:0)
Block(4,0,-1,COBBLESTONE:0)
Block(4,0,0,COBBLESTONE:0)
Block(4,0,1,COBBLESTONE:0)
Block(4,1,-1,MOSSY_COBBLESTONE:0)
Block(4,1,0,COBBLESTONE:0)
Block(4,1,1,MOSSY_COBBLESTONE:0)
Block(4,2,-1,COBBLESTONE:0)
Block(4,2,0,COBBLESTONE:0)
Block(4,2,1,MOSSY_COBBLESTONE:0)
Block(4,3,-1,COBBLESTONE:0)
Block(4,3,0,COBBLESTONE:0)
Block(4,3,1,MOSSY_COBBLESTONE:0)
Block(4,4,-1,MOSSY_COBBLESTONE:0)
Block(4,4,0,COBBLESTONE:0)
Block(4,4,1,COBBLESTONE:0)
Block(4,5,-1,COBBLESTONE:0)
Block(4,5,0,COBBLESTONE:0)
Block(4,5,1,COBBLESTONE:0)
Block(4,6,-2,COBBLESTONE:0)
Block(4,6,-1,MOSSY_COBBLESTONE:0)
Block(4,6,0,COBBLESTONE:0)
Block(4,6,1,COBBLESTONE:0)
Block(4,6,2,COBBLESTONE:0)
Block(4,7,-4,MOSSY_COBBLESTONE:0)
Block(4,7,-3,COBBLESTONE:0)
Block(4,7,-2,COBBLESTONE_STAIRS:0)
Block(4,7,-1,COBBLESTONE_STAIRS:0)
Block(4,7,0,COBBLESTONE_STAIRS:0)
Block(4,7,1,COBBLESTONE_STAIRS:0)
Block(4,7,2,COBBLESTONE_STAIRS:0)
Block(4,7,3,MOSSY_COBBLESTONE:0)
Block(5,7,-3,MOSSY_COBBLESTONE:0)
Block(5,7,2,MOSSY_COBBLESTONE:0)
Block(5,7,3,COBBLESTONE:0)

#######################################################################
# +-----------------------------------------------------------------+ #
# |                             Branches                            | #
# +-----------------------------------------------------------------+ #
#######################################################################


#######################################################################
# +-----------------------------------------------------------------+ #
# |                             Entities                            | #
# +-----------------------------------------------------------------+ #
#######################################################################


#######################################################################
# +-----------------------------------------------------------------+ #
# |                            Particles                            | #
# +-----------------------------------------------------------------+ #
#######################################################################


#######################################################################
# +-----------------------------------------------------------------+ #
# |                             Spawners                            | #
# +-----------------------------------------------------------------+ #
#######################################################################


#######################################################################
# +-----------------------------------------------------------------+ #
# |                             ModData                             | #
# +-----------------------------------------------------------------+ #
#######################################################################

