
#######################################################################
# +-----------------------------------------------------------------+ #
# |                            BO4 object                           | #
# +-----------------------------------------------------------------+ #
#######################################################################

Author: NLBlackEagle

Description: No description given

SettingsMode: WriteWithoutComments


#######################################################################
# +-----------------------------------------------------------------+ #
# |                          Main settings                          | #
# +-----------------------------------------------------------------+ #
#######################################################################

FixedRotation: 

Frequency: 0

SpawnHeight: highestBlock

UseCenterForHighestBlock: true

##############################
# Height Limits for the BO4. #
##############################

MinHeight: 0

MaxHeight: 255

InheritBO3: 

InheritBO3Rotation: NORTH

OverrideChildSettings: true

OverrideParentHeight: false

CanOverride: true

BranchFrequency: 0

BranchFrequencyGroup: 

MustBeBelowOther: false

MustBeInside: 

CannotBeInside: 

ReplacesBO3: 

MustBeInsideWorldBorders: false

CanSpawnOnWater: true

SpawnOnWaterOnly: false

SpawnUnderWater: false

SpawnAtWaterLevel: false

HeightOffset: 0

RemoveAir: false

ReplaceAbove: 

ReplaceBelow: 

ReplaceWithBiomeBlocks: false

ReplaceWithSurfaceBlock: GRASS

ReplaceWithGroundBlock: DIRT

ReplaceWithStoneBlock: STONE

SmoothRadius: 0

SmoothHeightOffset: 0

SmoothStartTop: false

SmoothStartWood: false

SmoothingSurfaceBlock: 

SmoothingGroundBlock: 

BO3Group: 

IsSpawnPoint: false

DoReplaceBlocks: true


#######################################################################
# +-----------------------------------------------------------------+ #
# |                              Blocks                             | #
# +-----------------------------------------------------------------+ #
#######################################################################

RandomBlock(-8,0,-7,SMOOTH_BRICK:0,40,SMOOTH_BRICK:1,20,SMOOTH_BRICK:2,30,SMOOTH_BRICK:0,100)
RandomBlock(-8,0,-6,SMOOTH_BRICK:0,40,SMOOTH_BRICK:1,20,SMOOTH_BRICK:2,30,SMOOTH_BRICK:0,100)
Block(-8,1,-7,AIR:0)
Block(-8,1,-6,AIR:0)
RandomBlock(-8,1,-5,SMOOTH_BRICK:0,40,SMOOTH_BRICK:1,20,SMOOTH_BRICK:2,30,SMOOTH_BRICK:0,100)
Block(-8,2,-7,AIR:0)
Block(-8,2,-6,AIR:0)
RandomBlock(-8,2,-5,SMOOTH_BRICK:0,40,SMOOTH_BRICK:1,20,SMOOTH_BRICK:2,30,SMOOTH_BRICK:0,100)
Block(-8,3,-7,AIR:0)
Block(-8,3,-6,AIR:0)
RandomBlock(-8,3,-5,SMOOTH_BRICK:0,40,SMOOTH_BRICK:1,20,SMOOTH_BRICK:2,30,SMOOTH_BRICK:0,100)
RandomBlock(-8,4,-7,SMOOTH_BRICK:0,40,SMOOTH_BRICK:1,20,SMOOTH_BRICK:2,30,SMOOTH_BRICK:0,100)
RandomBlock(-8,4,-6,SMOOTH_BRICK:0,40,SMOOTH_BRICK:1,20,SMOOTH_BRICK:2,30,SMOOTH_BRICK:0,100)
Block(-8,5,-7,WOOD:0)
Block(-8,5,-6,WOOD:0)
Block(-8,5,-5,WOOD:0)
Block(-8,6,-7,AIR:0)
Block(-8,6,-6,AIR:0)
RandomBlock(-8,6,-5,CHEST:3,../../../../Chests/Loot/moderncity_junk_loot.nbt,20,CHEST:3../../../../Chests/Loot/moderncity_common_loot.nbt,15,CHEST:3,../../../../Chests/Loot/moderncity_rare_loot.nbt,10,CHEST:3,../../../../Chests/Loot/moderncity_epic_loot.nbt,5,CHEST:3,../../../../Chests/Loot/spawn_bonus_chest.nbt,50,CHEST:3,../../../../Chests/RLCraft/Ruins/consumables.nbt,100)
Block(-8,6,-4,WOOD:0)
Block(-8,7,-7,AIR:0)
Block(-8,7,-6,AIR:0)
Block(-8,7,-5,AIR:0)
Block(-8,7,-4,WOOD:0)
Block(-8,8,-7,AIR:0)
Block(-8,8,-6,AIR:0)
Block(-8,8,-5,AIR:0)
Block(-8,8,-4,WOOD:0)
Block(-8,9,-7,WOOD:0)
Block(-8,9,-6,WOOD:0)
Block(-8,9,-5,WOOD:0)
Block(-8,10,-7,AIR:0)
Block(-8,10,-6,AIR:0)
RandomBlock(-8,10,-5,CHEST:3,../../../../Chests/Loot/moderncity_junk_loot.nbt,20,CHEST:3../../../../Chests/Loot/moderncity_common_loot.nbt,15,CHEST:3,../../../../Chests/Loot/moderncity_rare_loot.nbt,10,CHEST:3,../../../../Chests/Loot/moderncity_epic_loot.nbt,5,CHEST:3,../../../../Chests/Loot/spawn_bonus_chest.nbt,50,CHEST:3,../../../../Chests/RLCraft/Ruins/consumables.nbt,100)
Block(-8,10,-4,WOOD:0)
Block(-8,11,-7,AIR:0)
Block(-8,11,-6,AIR:0)
Block(-8,11,-5,AIR:0)
Block(-8,11,-4,WOOD:0)
Block(-8,12,-7,AIR:0)
Block(-8,12,-6,AIR:0)
Block(-8,12,-5,AIR:0)
Block(-8,12,-4,WOOD:0)
Block(-8,13,-7,WOOD:0)
Block(-8,13,-6,WOOD:0)
Block(-8,13,-5,WOOD:0)
Block(-8,14,-7,AIR:0)
Block(-8,14,-6,AIR:0)
RandomBlock(-8,14,-5,CHEST:4,../../../../Chests/Loot/moderncity_junk_loot.nbt,20,CHEST:4../../../../Chests/Loot/moderncity_common_loot.nbt,15,CHEST:4,../../../../Chests/Loot/moderncity_rare_loot.nbt,10,CHEST:4,../../../../Chests/Loot/moderncity_epic_loot.nbt,5,CHEST:4,../../../../Chests/Loot/spawn_bonus_chest.nbt,50,CHEST:4,../../../../Chests/RLCraft/Ruins/consumables.nbt,100)
Block(-8,14,-4,WOOD:0)
Block(-8,15,-7,AIR:0)
Block(-8,15,-6,AIR:0)
Block(-8,15,-5,AIR:0)
Block(-8,15,-4,WOOD:0)
Block(-8,16,-7,AIR:0)
Block(-8,16,-6,AIR:0)
Block(-8,16,-5,AIR:0)
Block(-8,16,-4,WOOD:0)
Block(-8,17,-7,WOOD:0)
Block(-8,17,-6,WOOD:0)
Block(-8,17,-5,WOOD:0)
Block(-8,18,-7,AIR:0)
Block(-8,18,-6,AIR:0)
RandomBlock(-8,18,-5,CHEST:3,../../../../Chests/Loot/moderncity_junk_loot.nbt,20,CHEST:3../../../../Chests/Loot/moderncity_common_loot.nbt,15,CHEST:3,../../../../Chests/Loot/moderncity_rare_loot.nbt,10,CHEST:3,../../../../Chests/Loot/moderncity_epic_loot.nbt,5,CHEST:3,../../../../Chests/Loot/spawn_bonus_chest.nbt,50,CHEST:3,../../../../Chests/RLCraft/Ruins/consumables.nbt,100)
Block(-8,18,-4,WOOD:0)
Block(-8,19,-7,AIR:0)
Block(-8,19,-6,AIR:0)
Block(-8,19,-5,AIR:0)
Block(-8,19,-4,WOOD:0)
Block(-8,20,-7,AIR:0)
Block(-8,20,-6,AIR:0)
Block(-8,20,-5,AIR:0)
Block(-8,20,-4,WOOD:0)
Block(-8,21,-7,WOOD:0)
Block(-8,21,-6,WOOD:0)
Block(-8,21,-5,WOOD:0)
Block(-8,22,-7,AIR:0)
Block(-8,22,-6,AIR:0)
RandomBlock(-8,22,-5,CHEST:2,../../../../Chests/Loot/moderncity_junk_loot.nbt,20,CHEST:2../../../../Chests/Loot/moderncity_common_loot.nbt,15,CHEST:2,../../../../Chests/Loot/moderncity_rare_loot.nbt,10,CHEST:2,../../../../Chests/Loot/moderncity_epic_loot.nbt,5,CHEST:2,../../../../Chests/Loot/spawn_bonus_chest.nbt,50,CHEST:2,../../../../Chests/RLCraft/Ruins/consumables.nbt,100)
Block(-8,22,-4,WOOD:0)
Block(-8,23,-7,AIR:0)
Block(-8,23,-6,AIR:0)
Block(-8,23,-5,AIR:0)
Block(-8,23,-4,WOOD:0)
Block(-8,24,-7,AIR:0)
Block(-8,24,-6,AIR:0)
Block(-8,24,-5,AIR:0)
Block(-8,24,-4,WOOD:0)
Block(-8,25,-7,WOOD:0)
Block(-8,25,-6,WOOD:0)
Block(-8,25,-5,WOOD:0)
RandomBlock(-7,0,-7,SMOOTH_BRICK:0,40,SMOOTH_BRICK:1,20,SMOOTH_BRICK:2,30,SMOOTH_BRICK:0,100)
RandomBlock(-7,0,-6,SMOOTH_BRICK:0,40,SMOOTH_BRICK:1,20,SMOOTH_BRICK:2,30,SMOOTH_BRICK:0,100)
Block(-7,1,-7,AIR:0)
RandomBlock(-7,1,-6,CHEST:5,../../../../Chests/Loot/moderncity_junk_loot.nbt,20,CHEST:5../../../../Chests/Loot/moderncity_common_loot.nbt,15,CHEST:5,../../../../Chests/Loot/moderncity_rare_loot.nbt,10,CHEST:5,../../../../Chests/Loot/moderncity_epic_loot.nbt,5,CHEST:5,../../../../Chests/Loot/spawn_bonus_chest.nbt,50,CHEST:5,../../../../Chests/RLCraft/Ruins/consumables.nbt,100)
RandomBlock(-7,1,-5,SMOOTH_BRICK:0,40,SMOOTH_BRICK:1,20,SMOOTH_BRICK:2,30,SMOOTH_BRICK:0,100)
Block(-7,2,-7,AIR:0)
Block(-7,2,-6,AIR:0)
RandomBlock(-7,2,-5,SMOOTH_BRICK:0,40,SMOOTH_BRICK:1,20,SMOOTH_BRICK:2,30,SMOOTH_BRICK:0,100)
Block(-7,3,-7,AIR:0)
Block(-7,3,-6,AIR:0)
RandomBlock(-7,3,-5,SMOOTH_BRICK:0,40,SMOOTH_BRICK:1,20,SMOOTH_BRICK:2,30,SMOOTH_BRICK:0,100)
RandomBlock(-7,4,-7,SMOOTH_BRICK:0,40,SMOOTH_BRICK:1,20,SMOOTH_BRICK:2,30,SMOOTH_BRICK:0,100)
RandomBlock(-7,4,-6,SMOOTH_BRICK:0,40,SMOOTH_BRICK:1,20,SMOOTH_BRICK:2,30,SMOOTH_BRICK:0,100)
Block(-7,5,-7,WOOD:0)
Block(-7,5,-6,WOOD:0)
Block(-7,5,-5,WOOD:0)
Block(-7,6,-7,AIR:0)
Block(-7,6,-6,AIR:0)
Block(-7,6,-5,MOB_SPAWNER:0,../../ruins_spawners/soldiers_multi.nbt)
Block(-7,6,-4,WOOD:0)
Block(-7,7,-7,AIR:0)
Block(-7,7,-6,AIR:0)
Block(-7,7,-5,AIR:0)
Block(-7,7,-4,WOOD:0)
Block(-7,8,-7,AIR:0)
Block(-7,8,-6,AIR:0)
Block(-7,8,-5,AIR:0)
Block(-7,8,-4,WOOD:0)
Block(-7,9,-7,WOOD:0)
Block(-7,9,-6,WOOD:0)
Block(-7,9,-5,WOOD:0)
Block(-7,10,-7,AIR:0)
Block(-7,10,-6,AIR:0)
Block(-7,10,-5,MOB_SPAWNER:0,../../ruins_spawners/soldiers_multi.nbt)
Block(-7,10,-4,WOOD:0)
Block(-7,11,-7,AIR:0)
Block(-7,11,-6,AIR:0)
Block(-7,11,-5,AIR:0)
Block(-7,11,-4,WOOD:0)
Block(-7,12,-7,AIR:0)
Block(-7,12,-6,AIR:0)
Block(-7,12,-5,AIR:0)
Block(-7,12,-4,WOOD:0)
Block(-7,13,-7,WOOD:0)
Block(-7,13,-6,WOOD:0)
Block(-7,13,-5,WOOD:0)
Block(-7,14,-7,AIR:0)
Block(-7,14,-6,AIR:0)
Block(-7,14,-5,MOB_SPAWNER:0,../../ruins_spawners/soldiers_multi.nbt)
Block(-7,14,-4,WOOD:0)
Block(-7,15,-7,AIR:0)
Block(-7,15,-6,AIR:0)
Block(-7,15,-5,AIR:0)
Block(-7,15,-4,WOOD:0)
Block(-7,16,-7,AIR:0)
Block(-7,16,-6,AIR:0)
Block(-7,16,-5,AIR:0)
Block(-7,16,-4,WOOD:0)
Block(-7,17,-7,WOOD:0)
Block(-7,17,-6,WOOD:0)
Block(-7,17,-5,WOOD:0)
Block(-7,18,-7,AIR:0)
Block(-7,18,-6,AIR:0)
Block(-7,18,-5,MOB_SPAWNER:0,../../ruins_spawners/soldiers_multi.nbt)
Block(-7,18,-4,WOOD:0)
Block(-7,19,-7,AIR:0)
Block(-7,19,-6,AIR:0)
Block(-7,19,-5,AIR:0)
Block(-7,19,-4,WOOD:0)
Block(-7,20,-7,AIR:0)
Block(-7,20,-6,AIR:0)
Block(-7,20,-5,AIR:0)
Block(-7,20,-4,WOOD:0)
Block(-7,21,-7,WOOD:0)
Block(-7,21,-6,WOOD:0)
Block(-7,21,-5,WOOD:0)
Block(-7,22,-7,AIR:0)
Block(-7,22,-6,AIR:0)
Block(-7,22,-5,MOB_SPAWNER:0,../../ruins_spawners/soldiers_multi.nbt)
Block(-7,22,-4,WOOD:0)
Block(-7,23,-7,AIR:0)
Block(-7,23,-6,AIR:0)
Block(-7,23,-5,AIR:0)
Block(-7,23,-4,WOOD:0)
Block(-7,24,-7,AIR:0)
Block(-7,24,-6,AIR:0)
Block(-7,24,-5,AIR:0)
Block(-7,24,-4,WOOD:0)
Block(-7,25,-7,WOOD:0)
Block(-7,25,-6,WOOD:0)
Block(-7,25,-5,WOOD:0)
RandomBlock(-6,0,-7,SMOOTH_BRICK:0,40,SMOOTH_BRICK:1,20,SMOOTH_BRICK:2,30,SMOOTH_BRICK:0,100)
RandomBlock(-6,0,-6,SMOOTH_BRICK:0,40,SMOOTH_BRICK:1,20,SMOOTH_BRICK:2,30,SMOOTH_BRICK:0,100)
Block(-6,1,-7,AIR:0)
Block(-6,1,-6,AIR:0)
RandomBlock(-6,1,-5,SMOOTH_BRICK:0,40,SMOOTH_BRICK:1,20,SMOOTH_BRICK:2,30,SMOOTH_BRICK:0,100)
Block(-6,2,-7,AIR:0)
Block(-6,2,-6,AIR:0)
RandomBlock(-6,2,-5,SMOOTH_BRICK:0,40,SMOOTH_BRICK:1,20,SMOOTH_BRICK:2,30,SMOOTH_BRICK:0,100)
Block(-6,3,-7,AIR:0)
Block(-6,3,-6,AIR:0)
RandomBlock(-6,3,-5,SMOOTH_BRICK:0,40,SMOOTH_BRICK:1,20,SMOOTH_BRICK:2,30,SMOOTH_BRICK:0,100)
RandomBlock(-6,4,-7,SMOOTH_BRICK:0,40,SMOOTH_BRICK:1,20,SMOOTH_BRICK:2,30,SMOOTH_BRICK:0,100)
RandomBlock(-6,4,-6,SMOOTH_BRICK:0,40,SMOOTH_BRICK:1,20,SMOOTH_BRICK:2,30,SMOOTH_BRICK:0,100)
Block(-6,5,-7,WOOD:0)
Block(-6,5,-6,WOOD:0)
Block(-6,5,-5,WOOD:0)
Block(-6,6,-7,BED_BLOCK:2)
Block(-6,6,-6,AIR:0)
Block(-6,6,-5,WORKBENCH:0)
Block(-6,6,-4,WOOD:0)
Block(-6,7,-7,AIR:0)
Block(-6,7,-6,AIR:0)
Block(-6,7,-5,AIR:0)
Block(-6,7,-4,WOOD:0)
Block(-6,8,-7,AIR:0)
Block(-6,8,-6,AIR:0)
Block(-6,8,-5,AIR:0)
Block(-6,8,-4,WOOD:0)
Block(-6,9,-7,WOOD:0)
Block(-6,9,-6,WOOD:0)
Block(-6,9,-5,WOOD:0)
Block(-6,10,-7,BED_BLOCK:2)
Block(-6,10,-6,AIR:0)
Block(-6,10,-5,WORKBENCH:0)
Block(-6,10,-4,WOOD:0)
Block(-6,11,-7,AIR:0)
Block(-6,11,-6,AIR:0)
Block(-6,11,-5,AIR:0)
Block(-6,11,-4,WOOD:0)
Block(-6,12,-7,AIR:0)
Block(-6,12,-6,AIR:0)
Block(-6,12,-5,AIR:0)
Block(-6,12,-4,WOOD:0)
Block(-6,13,-7,WOOD:0)
Block(-6,13,-6,WOOD:0)
Block(-6,13,-5,WOOD:0)
Block(-6,14,-7,BED_BLOCK:2)
Block(-6,14,-6,AIR:0)
Block(-6,14,-5,WORKBENCH:0)
Block(-6,14,-4,WOOD:0)
Block(-6,15,-7,AIR:0)
Block(-6,15,-6,AIR:0)
Block(-6,15,-5,AIR:0)
Block(-6,15,-4,WOOD:0)
Block(-6,16,-7,AIR:0)
Block(-6,16,-6,AIR:0)
Block(-6,16,-5,AIR:0)
Block(-6,16,-4,WOOD:0)
Block(-6,17,-7,WOOD:0)
Block(-6,17,-6,WOOD:0)
Block(-6,17,-5,WOOD:0)
Block(-6,18,-7,BED_BLOCK:2)
Block(-6,18,-6,AIR:0)
Block(-6,18,-5,WORKBENCH:0)
Block(-6,18,-4,WOOD:0)
Block(-6,19,-7,AIR:0)
Block(-6,19,-6,AIR:0)
Block(-6,19,-5,AIR:0)
Block(-6,19,-4,WOOD:0)
Block(-6,20,-7,AIR:0)
Block(-6,20,-6,AIR:0)
Block(-6,20,-5,AIR:0)
Block(-6,20,-4,WOOD:0)
Block(-6,21,-7,WOOD:0)
Block(-6,21,-6,WOOD:0)
Block(-6,21,-5,WOOD:0)
Block(-6,22,-7,BED_BLOCK:2)
Block(-6,22,-6,AIR:0)
Block(-6,22,-5,WORKBENCH:0)
Block(-6,22,-4,WOOD:0)
Block(-6,23,-7,AIR:0)
Block(-6,23,-6,AIR:0)
Block(-6,23,-5,AIR:0)
Block(-6,23,-4,WOOD:0)
Block(-6,24,-7,AIR:0)
Block(-6,24,-6,AIR:0)
Block(-6,24,-5,AIR:0)
Block(-6,24,-4,WOOD:0)
Block(-6,25,-7,WOOD:0)
Block(-6,25,-6,WOOD:0)
Block(-6,25,-5,WOOD:0)
RandomBlock(-5,0,-7,SMOOTH_BRICK:0,40,SMOOTH_BRICK:1,20,SMOOTH_BRICK:2,30,SMOOTH_BRICK:0,100)
RandomBlock(-5,0,-6,SMOOTH_BRICK:0,40,SMOOTH_BRICK:1,20,SMOOTH_BRICK:2,30,SMOOTH_BRICK:0,100)
Block(-5,1,-7,AIR:0)
Block(-5,1,-6,AIR:0)
RandomBlock(-5,1,-5,SMOOTH_BRICK:0,40,SMOOTH_BRICK:1,20,SMOOTH_BRICK:2,30,SMOOTH_BRICK:0,100)
Block(-5,2,-7,AIR:0)
Block(-5,2,-6,AIR:0)
RandomBlock(-5,2,-5,SMOOTH_BRICK:0,40,SMOOTH_BRICK:1,20,SMOOTH_BRICK:2,30,SMOOTH_BRICK:0,100)
Block(-5,3,-7,AIR:0)
Block(-5,3,-6,AIR:0)
RandomBlock(-5,3,-5,SMOOTH_BRICK:0,40,SMOOTH_BRICK:1,20,SMOOTH_BRICK:2,30,SMOOTH_BRICK:0,100)
RandomBlock(-5,4,-7,SMOOTH_BRICK:0,40,SMOOTH_BRICK:1,20,SMOOTH_BRICK:2,30,SMOOTH_BRICK:0,100)
RandomBlock(-5,4,-6,SMOOTH_BRICK:0,40,SMOOTH_BRICK:1,20,SMOOTH_BRICK:2,30,SMOOTH_BRICK:0,100)
Block(-5,5,-7,WOOD:0)
Block(-5,5,-6,WOOD:0)
Block(-5,5,-5,WOOD:0)
Block(-5,6,-7,WOOD:0)
Block(-5,6,-6,WOOD:0)
Block(-5,6,-5,WOOD:0)
Block(-5,6,-4,WOOD:0)
Block(-5,7,-7,WOOD:0)
Block(-5,7,-6,WOOD:0)
Block(-5,7,-5,WOOD:0)
Block(-5,7,-4,WOOD:0)
Block(-5,8,-7,WOOD:0)
Block(-5,8,-6,WOOD:0)
Block(-5,8,-5,WOOD:0)
Block(-5,8,-4,WOOD:0)
Block(-5,9,-7,WOOD:0)
Block(-5,9,-6,WOOD:0)
Block(-5,9,-5,WOOD:0)
Block(-5,10,-7,WOOD:0)
Block(-5,10,-6,WOOD:0)
Block(-5,10,-5,WOOD:0)
Block(-5,10,-4,WOOD:0)
Block(-5,11,-7,WOOD:0)
Block(-5,11,-6,WOOD:0)
Block(-5,11,-5,WOOD:0)
Block(-5,11,-4,WOOD:0)
Block(-5,12,-7,WOOD:0)
Block(-5,12,-6,WOOD:0)
Block(-5,12,-5,WOOD:0)
Block(-5,12,-4,WOOD:0)
Block(-5,13,-7,WOOD:0)
Block(-5,13,-6,WOOD:0)
Block(-5,13,-5,WOOD:0)
Block(-5,14,-7,WOOD:0)
Block(-5,14,-6,WOOD:0)
Block(-5,14,-5,WOOD:0)
Block(-5,14,-4,WOOD:0)
Block(-5,15,-7,WOOD:0)
Block(-5,15,-6,WOOD:0)
Block(-5,15,-5,WOOD:0)
Block(-5,15,-4,WOOD:0)
Block(-5,16,-7,WOOD:0)
Block(-5,16,-6,WOOD:0)
Block(-5,16,-5,WOOD:0)
Block(-5,16,-4,WOOD:0)
Block(-5,17,-7,WOOD:0)
Block(-5,17,-6,WOOD:0)
Block(-5,17,-5,WOOD:0)
Block(-5,18,-7,WOOD:0)
Block(-5,18,-6,WOOD:0)
Block(-5,18,-5,WOOD:0)
Block(-5,18,-4,WOOD:0)
Block(-5,19,-7,WOOD:0)
Block(-5,19,-6,WOOD:0)
Block(-5,19,-5,WOOD:0)
Block(-5,19,-4,WOOD:0)
Block(-5,20,-7,WOOD:0)
Block(-5,20,-6,WOOD:0)
Block(-5,20,-5,WOOD:0)
Block(-5,20,-4,WOOD:0)
Block(-5,21,-7,WOOD:0)
Block(-5,21,-6,WOOD:0)
Block(-5,21,-5,WOOD:0)
Block(-5,22,-7,WOOD:0)
Block(-5,22,-6,WOOD:0)
Block(-5,22,-5,WOOD:0)
Block(-5,22,-4,WOOD:0)
Block(-5,23,-7,WOOD:0)
Block(-5,23,-6,WOOD:0)
Block(-5,23,-5,WOOD:0)
Block(-5,23,-4,WOOD:0)
Block(-5,24,-7,WOOD:0)
Block(-5,24,-6,WOOD:0)
Block(-5,24,-5,WOOD:0)
Block(-5,24,-4,WOOD:0)
Block(-5,25,-7,WOOD:0)
Block(-5,25,-6,WOOD:0)
Block(-5,25,-5,WOOD:0)
RandomBlock(-4,0,-7,SMOOTH_BRICK:0,40,SMOOTH_BRICK:1,20,SMOOTH_BRICK:2,30,SMOOTH_BRICK:0,100)
RandomBlock(-4,0,-6,SMOOTH_BRICK:0,40,SMOOTH_BRICK:1,20,SMOOTH_BRICK:2,30,SMOOTH_BRICK:0,100)
Block(-4,1,-7,AIR:0)
Block(-4,1,-6,AIR:0)
RandomBlock(-4,1,-5,SMOOTH_BRICK:0,40,SMOOTH_BRICK:1,20,SMOOTH_BRICK:2,30,SMOOTH_BRICK:0,100)
Block(-4,2,-7,AIR:0)
Block(-4,2,-6,AIR:0)
RandomBlock(-4,2,-5,SMOOTH_BRICK:0,40,SMOOTH_BRICK:1,20,SMOOTH_BRICK:2,30,SMOOTH_BRICK:0,100)
Block(-4,3,-7,AIR:0)
Block(-4,3,-6,AIR:0)
RandomBlock(-4,3,-5,SMOOTH_BRICK:0,40,SMOOTH_BRICK:1,20,SMOOTH_BRICK:2,30,SMOOTH_BRICK:0,100)
RandomBlock(-4,4,-7,SMOOTH_BRICK:0,40,SMOOTH_BRICK:1,20,SMOOTH_BRICK:2,30,SMOOTH_BRICK:0,100)
RandomBlock(-4,4,-6,SMOOTH_BRICK:0,40,SMOOTH_BRICK:1,20,SMOOTH_BRICK:2,30,SMOOTH_BRICK:0,100)
Block(-4,5,-7,WOOD:0)
Block(-4,5,-6,WOOD:0)
Block(-4,5,-5,WOOD:0)
Block(-4,6,-7,AIR:0)
Block(-4,6,-6,AIR:0)
Block(-4,6,-5,FURNACE:2)
Block(-4,6,-4,WOOD:0)
Block(-4,7,-7,AIR:0)
Block(-4,7,-6,AIR:0)
Block(-4,7,-5,AIR:0)
Block(-4,7,-4,WOOD:0)
Block(-4,8,-7,AIR:0)
Block(-4,8,-6,AIR:0)
Block(-4,8,-5,AIR:0)
Block(-4,8,-4,WOOD:0)
Block(-4,9,-7,WOOD:0)
Block(-4,9,-6,WOOD:0)
Block(-4,9,-5,WOOD:0)
Block(-4,10,-7,AIR:0)
Block(-4,10,-6,AIR:0)
Block(-4,10,-5,FURNACE:2)
Block(-4,10,-4,WOOD:0)
Block(-4,11,-7,AIR:0)
Block(-4,11,-6,AIR:0)
Block(-4,11,-5,AIR:0)
Block(-4,11,-4,WOOD:0)
Block(-4,12,-7,AIR:0)
Block(-4,12,-6,AIR:0)
Block(-4,12,-5,AIR:0)
Block(-4,12,-4,WOOD:0)
Block(-4,13,-7,WOOD:0)
Block(-4,13,-6,WOOD:0)
Block(-4,13,-5,WOOD:0)
Block(-4,14,-7,AIR:0)
Block(-4,14,-6,AIR:0)
Block(-4,14,-5,FURNACE:2)
Block(-4,14,-4,WOOD:0)
Block(-4,15,-7,AIR:0)
Block(-4,15,-6,AIR:0)
Block(-4,15,-5,AIR:0)
Block(-4,15,-4,WOOD:0)
Block(-4,16,-7,AIR:0)
Block(-4,16,-6,AIR:0)
Block(-4,16,-5,AIR:0)
Block(-4,16,-4,WOOD:0)
Block(-4,17,-7,WOOD:0)
Block(-4,17,-6,WOOD:0)
Block(-4,17,-5,WOOD:0)
Block(-4,18,-7,AIR:0)
Block(-4,18,-6,AIR:0)
Block(-4,18,-5,FURNACE:2)
Block(-4,18,-4,WOOD:0)
Block(-4,19,-7,AIR:0)
Block(-4,19,-6,AIR:0)
Block(-4,19,-5,AIR:0)
Block(-4,19,-4,WOOD:0)
Block(-4,20,-7,AIR:0)
Block(-4,20,-6,AIR:0)
Block(-4,20,-5,AIR:0)
Block(-4,20,-4,WOOD:0)
Block(-4,21,-7,WOOD:0)
Block(-4,21,-6,WOOD:0)
Block(-4,21,-5,WOOD:0)
Block(-4,22,-7,AIR:0)
Block(-4,22,-6,AIR:0)
Block(-4,22,-5,FURNACE:2)
Block(-4,22,-4,WOOD:0)
Block(-4,23,-7,AIR:0)
Block(-4,23,-6,AIR:0)
Block(-4,23,-5,AIR:0)
Block(-4,23,-4,WOOD:0)
Block(-4,24,-7,AIR:0)
Block(-4,24,-6,AIR:0)
Block(-4,24,-5,AIR:0)
Block(-4,24,-4,WOOD:0)
Block(-4,25,-7,WOOD:0)
Block(-4,25,-6,WOOD:0)
Block(-4,25,-5,WOOD:0)
RandomBlock(-3,0,-7,SMOOTH_BRICK:0,40,SMOOTH_BRICK:1,20,SMOOTH_BRICK:2,30,SMOOTH_BRICK:0,100)
RandomBlock(-3,0,-6,SMOOTH_BRICK:0,40,SMOOTH_BRICK:1,20,SMOOTH_BRICK:2,30,SMOOTH_BRICK:0,100)
Block(-3,1,-7,AIR:0)
Block(-3,1,-6,AIR:0)
RandomBlock(-3,1,-5,SMOOTH_BRICK:0,40,SMOOTH_BRICK:1,20,SMOOTH_BRICK:2,30,SMOOTH_BRICK:0,100)
Block(-3,2,-7,AIR:0)
Block(-3,2,-6,AIR:0)
RandomBlock(-3,2,-5,SMOOTH_BRICK:0,40,SMOOTH_BRICK:1,20,SMOOTH_BRICK:2,30,SMOOTH_BRICK:0,100)
Block(-3,3,-7,AIR:0)
Block(-3,3,-6,AIR:0)
RandomBlock(-3,3,-5,SMOOTH_BRICK:0,40,SMOOTH_BRICK:1,20,SMOOTH_BRICK:2,30,SMOOTH_BRICK:0,100)
RandomBlock(-3,4,-7,SMOOTH_BRICK:0,40,SMOOTH_BRICK:1,20,SMOOTH_BRICK:2,30,SMOOTH_BRICK:0,100)
RandomBlock(-3,4,-6,SMOOTH_BRICK:0,40,SMOOTH_BRICK:1,20,SMOOTH_BRICK:2,30,SMOOTH_BRICK:0,100)
Block(-3,5,-7,WOOD:0)
Block(-3,5,-6,WOOD:0)
Block(-3,5,-5,WOOD:0)
Block(-3,6,-7,AIR:0)
Block(-3,6,-6,AIR:0)
RandomBlock(-3,6,-5,CHEST:5,../../../../Chests/Loot/moderncity_junk_loot.nbt,20,CHEST:5../../../../Chests/Loot/moderncity_common_loot.nbt,15,CHEST:5,../../../../Chests/Loot/moderncity_rare_loot.nbt,10,CHEST:5,../../../../Chests/Loot/moderncity_epic_loot.nbt,5,CHEST:5,../../../../Chests/Loot/spawn_bonus_chest.nbt,50,CHEST:5,../../../../Chests/RLCraft/Ruins/consumables.nbt,100)
Block(-3,6,-4,WOOD:0)
Block(-3,7,-7,AIR:0)
Block(-3,7,-6,AIR:0)
Block(-3,7,-5,AIR:0)
Block(-3,7,-4,WOOD:0)
Block(-3,8,-7,AIR:0)
Block(-3,8,-6,AIR:0)
Block(-3,8,-5,AIR:0)
Block(-3,8,-4,WOOD:0)
Block(-3,9,-7,WOOD:0)
Block(-3,9,-6,WOOD:0)
Block(-3,9,-5,WOOD:0)
Block(-3,10,-7,AIR:0)
Block(-3,10,-6,AIR:0)
RandomBlock(-3,10,-5,CHEST:2,../../../../Chests/Loot/moderncity_junk_loot.nbt,20,CHEST:2../../../../Chests/Loot/moderncity_common_loot.nbt,15,CHEST:2,../../../../Chests/Loot/moderncity_rare_loot.nbt,10,CHEST:2,../../../../Chests/Loot/moderncity_epic_loot.nbt,5,CHEST:2,../../../../Chests/Loot/spawn_bonus_chest.nbt,50,CHEST:2,../../../../Chests/RLCraft/Ruins/consumables.nbt,100)
Block(-3,10,-4,WOOD:0)
Block(-3,11,-7,AIR:0)
Block(-3,11,-6,AIR:0)
Block(-3,11,-5,AIR:0)
Block(-3,11,-4,WOOD:0)
Block(-3,12,-7,AIR:0)
Block(-3,12,-6,AIR:0)
Block(-3,12,-5,AIR:0)
Block(-3,12,-4,WOOD:0)
Block(-3,13,-7,WOOD:0)
Block(-3,13,-6,WOOD:0)
Block(-3,13,-5,WOOD:0)
Block(-3,14,-7,AIR:0)
Block(-3,14,-6,AIR:0)
RandomBlock(-3,14,-5,CHEST:3,../../../../Chests/Loot/moderncity_junk_loot.nbt,20,CHEST:3../../../../Chests/Loot/moderncity_common_loot.nbt,15,CHEST:3,../../../../Chests/Loot/moderncity_rare_loot.nbt,10,CHEST:3,../../../../Chests/Loot/moderncity_epic_loot.nbt,5,CHEST:3,../../../../Chests/Loot/spawn_bonus_chest.nbt,50,CHEST:3,../../../../Chests/RLCraft/Ruins/consumables.nbt,100)
Block(-3,14,-4,WOOD:0)
Block(-3,15,-7,AIR:0)
Block(-3,15,-6,AIR:0)
Block(-3,15,-5,AIR:0)
Block(-3,15,-4,WOOD:0)
Block(-3,16,-7,AIR:0)
Block(-3,16,-6,AIR:0)
Block(-3,16,-5,AIR:0)
Block(-3,16,-4,WOOD:0)
Block(-3,17,-7,WOOD:0)
Block(-3,17,-6,WOOD:0)
Block(-3,17,-5,WOOD:0)
Block(-3,18,-7,AIR:0)
Block(-3,18,-6,AIR:0)
RandomBlock(-3,18,-5,CHEST:2,../../../../Chests/Loot/moderncity_junk_loot.nbt,20,CHEST:2../../../../Chests/Loot/moderncity_common_loot.nbt,15,CHEST:2,../../../../Chests/Loot/moderncity_rare_loot.nbt,10,CHEST:2,../../../../Chests/Loot/moderncity_epic_loot.nbt,5,CHEST:2,../../../../Chests/Loot/spawn_bonus_chest.nbt,50,CHEST:2,../../../../Chests/RLCraft/Ruins/consumables.nbt,100)
Block(-3,18,-4,WOOD:0)
Block(-3,19,-7,AIR:0)
Block(-3,19,-6,AIR:0)
Block(-3,19,-5,AIR:0)
Block(-3,19,-4,WOOD:0)
Block(-3,20,-7,AIR:0)
Block(-3,20,-6,AIR:0)
Block(-3,20,-5,AIR:0)
Block(-3,20,-4,WOOD:0)
Block(-3,21,-7,WOOD:0)
Block(-3,21,-6,WOOD:0)
Block(-3,21,-5,WOOD:0)
Block(-3,22,-7,AIR:0)
Block(-3,22,-6,AIR:0)
RandomBlock(-3,22,-5,CHEST:2,../../../../Chests/Loot/moderncity_junk_loot.nbt,20,CHEST:2../../../../Chests/Loot/moderncity_common_loot.nbt,15,CHEST:2,../../../../Chests/Loot/moderncity_rare_loot.nbt,10,CHEST:2,../../../../Chests/Loot/moderncity_epic_loot.nbt,5,CHEST:2,../../../../Chests/Loot/spawn_bonus_chest.nbt,50,CHEST:2,../../../../Chests/RLCraft/Ruins/consumables.nbt,100)
Block(-3,22,-4,WOOD:0)
Block(-3,23,-7,AIR:0)
Block(-3,23,-6,AIR:0)
Block(-3,23,-5,AIR:0)
Block(-3,23,-4,WOOD:0)
Block(-3,24,-7,AIR:0)
Block(-3,24,-6,AIR:0)
Block(-3,24,-5,AIR:0)
Block(-3,24,-4,WOOD:0)
Block(-3,25,-7,WOOD:0)
Block(-3,25,-6,WOOD:0)
Block(-3,25,-5,WOOD:0)
RandomBlock(-2,0,-7,SMOOTH_BRICK:0,40,SMOOTH_BRICK:1,20,SMOOTH_BRICK:2,30,SMOOTH_BRICK:0,100)
RandomBlock(-2,0,-6,SMOOTH_BRICK:0,40,SMOOTH_BRICK:1,20,SMOOTH_BRICK:2,30,SMOOTH_BRICK:0,100)
Block(-2,1,-7,AIR:0)
Block(-2,1,-6,AIR:0)
RandomBlock(-2,1,-5,SMOOTH_BRICK:0,40,SMOOTH_BRICK:1,20,SMOOTH_BRICK:2,30,SMOOTH_BRICK:0,100)
Block(-2,2,-7,AIR:0)
Block(-2,2,-6,AIR:0)
RandomBlock(-2,2,-5,SMOOTH_BRICK:0,40,SMOOTH_BRICK:1,20,SMOOTH_BRICK:2,30,SMOOTH_BRICK:0,100)
Block(-2,3,-7,AIR:0)
Block(-2,3,-6,AIR:0)
RandomBlock(-2,3,-5,SMOOTH_BRICK:0,40,SMOOTH_BRICK:1,20,SMOOTH_BRICK:2,30,SMOOTH_BRICK:0,100)
RandomBlock(-2,4,-7,SMOOTH_BRICK:0,40,SMOOTH_BRICK:1,20,SMOOTH_BRICK:2,30,SMOOTH_BRICK:0,100)
RandomBlock(-2,4,-6,SMOOTH_BRICK:0,40,SMOOTH_BRICK:1,20,SMOOTH_BRICK:2,30,SMOOTH_BRICK:0,100)
Block(-2,5,-7,WOOD:0)
Block(-2,5,-6,WOOD:0)
Block(-2,5,-5,WOOD:0)
Block(-2,6,-7,AIR:0)
Block(-2,6,-6,AIR:0)
Block(-2,6,-5,MOB_SPAWNER:0,../../ruins_spawners/soldiers_multi.nbt)
Block(-2,6,-4,WOOD:0)
Block(-2,7,-7,AIR:0)
Block(-2,7,-6,AIR:0)
Block(-2,7,-5,AIR:0)
Block(-2,7,-4,WOOD:0)
Block(-2,8,-7,AIR:0)
Block(-2,8,-6,AIR:0)
Block(-2,8,-5,AIR:0)
Block(-2,8,-4,WOOD:0)
Block(-2,9,-7,WOOD:0)
Block(-2,9,-6,WOOD:0)
Block(-2,9,-5,WOOD:0)
Block(-2,10,-7,AIR:0)
Block(-2,10,-6,AIR:0)
Block(-2,10,-5,MOB_SPAWNER:0,../../ruins_spawners/soldiers_multi.nbt)
Block(-2,10,-4,WOOD:0)
Block(-2,11,-7,AIR:0)
Block(-2,11,-6,AIR:0)
Block(-2,11,-5,AIR:0)
Block(-2,11,-4,WOOD:0)
Block(-2,12,-7,AIR:0)
Block(-2,12,-6,AIR:0)
Block(-2,12,-5,AIR:0)
Block(-2,12,-4,WOOD:0)
Block(-2,13,-7,WOOD:0)
Block(-2,13,-6,WOOD:0)
Block(-2,13,-5,WOOD:0)
Block(-2,14,-7,AIR:0)
Block(-2,14,-6,AIR:0)
Block(-2,14,-5,MOB_SPAWNER:0,../../ruins_spawners/soldiers_multi.nbt)
Block(-2,14,-4,WOOD:0)
Block(-2,15,-7,AIR:0)
Block(-2,15,-6,AIR:0)
Block(-2,15,-5,AIR:0)
Block(-2,15,-4,WOOD:0)
Block(-2,16,-7,AIR:0)
Block(-2,16,-6,AIR:0)
Block(-2,16,-5,AIR:0)
Block(-2,16,-4,WOOD:0)
Block(-2,17,-7,WOOD:0)
Block(-2,17,-6,WOOD:0)
Block(-2,17,-5,WOOD:0)
Block(-2,18,-7,AIR:0)
Block(-2,18,-6,AIR:0)
Block(-2,18,-5,MOB_SPAWNER:0,../../ruins_spawners/soldiers_multi.nbt)
Block(-2,18,-4,WOOD:0)
Block(-2,19,-7,AIR:0)
Block(-2,19,-6,AIR:0)
Block(-2,19,-5,AIR:0)
Block(-2,19,-4,WOOD:0)
Block(-2,20,-7,AIR:0)
Block(-2,20,-6,AIR:0)
Block(-2,20,-5,AIR:0)
Block(-2,20,-4,WOOD:0)
Block(-2,21,-7,WOOD:0)
Block(-2,21,-6,WOOD:0)
Block(-2,21,-5,WOOD:0)
Block(-2,22,-7,AIR:0)
Block(-2,22,-6,AIR:0)
Block(-2,22,-5,MOB_SPAWNER:0,../../ruins_spawners/soldiers_multi.nbt)
Block(-2,22,-4,WOOD:0)
Block(-2,23,-7,AIR:0)
Block(-2,23,-6,AIR:0)
Block(-2,23,-5,AIR:0)
Block(-2,23,-4,WOOD:0)
Block(-2,24,-7,AIR:0)
Block(-2,24,-6,AIR:0)
Block(-2,24,-5,AIR:0)
Block(-2,24,-4,WOOD:0)
Block(-2,25,-7,WOOD:0)
Block(-2,25,-6,WOOD:0)
Block(-2,25,-5,WOOD:0)
RandomBlock(-1,0,-7,SMOOTH_BRICK:0,40,SMOOTH_BRICK:1,20,SMOOTH_BRICK:2,30,SMOOTH_BRICK:0,100)
RandomBlock(-1,0,-6,SMOOTH_BRICK:0,40,SMOOTH_BRICK:1,20,SMOOTH_BRICK:2,30,SMOOTH_BRICK:0,100)
RandomBlock(-1,1,-7,CHEST:5,../../../../Chests/Loot/moderncity_junk_loot.nbt,20,CHEST:5../../../../Chests/Loot/moderncity_common_loot.nbt,15,CHEST:5,../../../../Chests/Loot/moderncity_rare_loot.nbt,10,CHEST:5,../../../../Chests/Loot/moderncity_epic_loot.nbt,5,CHEST:5,../../../../Chests/Loot/spawn_bonus_chest.nbt,50,CHEST:5,../../../../Chests/RLCraft/Ruins/consumables.nbt,100)
RandomBlock(-1,1,-6,CHEST:5,../../../../Chests/Loot/moderncity_junk_loot.nbt,20,CHEST:5../../../../Chests/Loot/moderncity_common_loot.nbt,15,CHEST:5,../../../../Chests/Loot/moderncity_rare_loot.nbt,10,CHEST:5,../../../../Chests/Loot/moderncity_epic_loot.nbt,5,CHEST:5,../../../../Chests/Loot/spawn_bonus_chest.nbt,50,CHEST:5,../../../../Chests/RLCraft/Ruins/consumables.nbt,100)
RandomBlock(-1,1,-5,SMOOTH_BRICK:0,40,SMOOTH_BRICK:1,20,SMOOTH_BRICK:2,30,SMOOTH_BRICK:0,100)
Block(-1,2,-7,AIR:0)
Block(-1,2,-6,AIR:0)
RandomBlock(-1,2,-5,SMOOTH_BRICK:0,40,SMOOTH_BRICK:1,20,SMOOTH_BRICK:2,30,SMOOTH_BRICK:0,100)
Block(-1,3,-7,AIR:0)
Block(-1,3,-6,AIR:0)
RandomBlock(-1,3,-5,SMOOTH_BRICK:0,40,SMOOTH_BRICK:1,20,SMOOTH_BRICK:2,30,SMOOTH_BRICK:0,100)
RandomBlock(-1,4,-7,SMOOTH_BRICK:0,40,SMOOTH_BRICK:1,20,SMOOTH_BRICK:2,30,SMOOTH_BRICK:0,100)
RandomBlock(-1,4,-6,SMOOTH_BRICK:0,40,SMOOTH_BRICK:1,20,SMOOTH_BRICK:2,30,SMOOTH_BRICK:0,100)
Block(-1,5,-7,WOOD:0)
Block(-1,5,-6,WOOD:0)
Block(-1,5,-5,WOOD:0)
Block(-1,6,-7,BED_BLOCK:2)
Block(-1,6,-6,AIR:0)
Block(-1,6,-5,WORKBENCH:0)
Block(-1,6,-4,WOOD:0)
Block(-1,7,-7,AIR:0)
Block(-1,7,-6,AIR:0)
Block(-1,7,-5,AIR:0)
Block(-1,7,-4,WOOD:0)
Block(-1,8,-7,AIR:0)
Block(-1,8,-6,AIR:0)
Block(-1,8,-5,AIR:0)
Block(-1,8,-4,WOOD:0)
Block(-1,9,-7,WOOD:0)
Block(-1,9,-6,WOOD:0)
Block(-1,9,-5,WOOD:0)
Block(-1,10,-7,BED_BLOCK:2)
Block(-1,10,-6,AIR:0)
Block(-1,10,-5,WORKBENCH:0)
Block(-1,10,-4,WOOD:0)
Block(-1,11,-7,AIR:0)
Block(-1,11,-6,AIR:0)
Block(-1,11,-5,AIR:0)
Block(-1,11,-4,WOOD:0)
Block(-1,12,-7,AIR:0)
Block(-1,12,-6,AIR:0)
Block(-1,12,-5,AIR:0)
Block(-1,12,-4,WOOD:0)
Block(-1,13,-7,WOOD:0)
Block(-1,13,-6,WOOD:0)
Block(-1,13,-5,WOOD:0)
Block(-1,14,-7,BED_BLOCK:2)
Block(-1,14,-6,AIR:0)
Block(-1,14,-5,WORKBENCH:0)
Block(-1,14,-4,WOOD:0)
Block(-1,15,-7,AIR:0)
Block(-1,15,-6,AIR:0)
Block(-1,15,-5,AIR:0)
Block(-1,15,-4,WOOD:0)
Block(-1,16,-7,AIR:0)
Block(-1,16,-6,AIR:0)
Block(-1,16,-5,AIR:0)
Block(-1,16,-4,WOOD:0)
Block(-1,17,-7,WOOD:0)
Block(-1,17,-6,WOOD:0)
Block(-1,17,-5,WOOD:0)
Block(-1,18,-7,BED_BLOCK:2)
Block(-1,18,-6,AIR:0)
Block(-1,18,-5,WORKBENCH:0)
Block(-1,18,-4,WOOD:0)
Block(-1,19,-7,AIR:0)
Block(-1,19,-6,AIR:0)
Block(-1,19,-5,AIR:0)
Block(-1,19,-4,WOOD:0)
Block(-1,20,-7,AIR:0)
Block(-1,20,-6,AIR:0)
Block(-1,20,-5,AIR:0)
Block(-1,20,-4,WOOD:0)
Block(-1,21,-7,WOOD:0)
Block(-1,21,-6,WOOD:0)
Block(-1,21,-5,WOOD:0)
Block(-1,22,-7,BED_BLOCK:2)
Block(-1,22,-6,AIR:0)
Block(-1,22,-5,WORKBENCH:0)
Block(-1,22,-4,WOOD:0)
Block(-1,23,-7,AIR:0)
Block(-1,23,-6,AIR:0)
Block(-1,23,-5,AIR:0)
Block(-1,23,-4,WOOD:0)
Block(-1,24,-7,AIR:0)
Block(-1,24,-6,AIR:0)
Block(-1,24,-5,AIR:0)
Block(-1,24,-4,WOOD:0)
Block(-1,25,-7,WOOD:0)
Block(-1,25,-6,WOOD:0)
Block(-1,25,-5,WOOD:0)
RandomBlock(0,1,-7,SMOOTH_BRICK:0,40,SMOOTH_BRICK:1,20,SMOOTH_BRICK:2,30,SMOOTH_BRICK:0,100)
RandomBlock(0,1,-6,SMOOTH_BRICK:0,40,SMOOTH_BRICK:1,20,SMOOTH_BRICK:2,30,SMOOTH_BRICK:0,100)
RandomBlock(0,2,-7,SMOOTH_BRICK:0,40,SMOOTH_BRICK:1,20,SMOOTH_BRICK:2,30,SMOOTH_BRICK:0,100)
RandomBlock(0,2,-6,SMOOTH_BRICK:0,40,SMOOTH_BRICK:1,20,SMOOTH_BRICK:2,30,SMOOTH_BRICK:0,100)
RandomBlock(0,3,-7,SMOOTH_BRICK:0,40,SMOOTH_BRICK:1,20,SMOOTH_BRICK:2,30,SMOOTH_BRICK:0,100)
RandomBlock(0,3,-6,SMOOTH_BRICK:0,40,SMOOTH_BRICK:1,20,SMOOTH_BRICK:2,30,SMOOTH_BRICK:0,100)
Block(0,6,-7,WOOD:0)
Block(0,6,-6,WOOD:0)
Block(0,6,-5,WOOD:0)
Block(0,7,-7,WOOD:0)
Block(0,7,-6,WOOD:0)
Block(0,7,-5,WOOD:0)
Block(0,8,-7,WOOD:0)
Block(0,8,-6,WOOD:0)
Block(0,8,-5,WOOD:0)
Block(0,10,-7,WOOD:0)
Block(0,10,-6,WOOD:0)
Block(0,10,-5,WOOD:0)
Block(0,11,-7,WOOD:0)
Block(0,11,-6,WOOD:0)
Block(0,11,-5,WOOD:0)
Block(0,12,-7,WOOD:0)
Block(0,12,-6,WOOD:0)
Block(0,12,-5,WOOD:0)
Block(0,14,-7,WOOD:0)
Block(0,14,-6,WOOD:0)
Block(0,14,-5,WOOD:0)
Block(0,15,-7,WOOD:0)
Block(0,15,-6,WOOD:0)
Block(0,15,-5,WOOD:0)
Block(0,16,-7,WOOD:0)
Block(0,16,-6,WOOD:0)
Block(0,16,-5,WOOD:0)
Block(0,18,-7,WOOD:0)
Block(0,18,-6,WOOD:0)
Block(0,18,-5,WOOD:0)
Block(0,19,-7,WOOD:0)
Block(0,19,-6,WOOD:0)
Block(0,19,-5,WOOD:0)
Block(0,20,-7,WOOD:0)
Block(0,20,-6,WOOD:0)
Block(0,20,-5,WOOD:0)
Block(0,22,-7,WOOD:0)
Block(0,22,-6,WOOD:0)
Block(0,22,-5,WOOD:0)
Block(0,23,-7,WOOD:0)
Block(0,23,-6,WOOD:0)
Block(0,23,-5,WOOD:0)
Block(0,24,-7,WOOD:0)
Block(0,24,-6,WOOD:0)
Block(0,24,-5,WOOD:0)

#######################################################################
# +-----------------------------------------------------------------+ #
# |                             Branches                            | #
# +-----------------------------------------------------------------+ #
#######################################################################

Branch(-16,0,0,true,AdvancedUndergroundHouseC0R1,NORTH,100.0,0)

#######################################################################
# +-----------------------------------------------------------------+ #
# |                             Entities                            | #
# +-----------------------------------------------------------------+ #
#######################################################################


#######################################################################
# +-----------------------------------------------------------------+ #
# |                            Particles                            | #
# +-----------------------------------------------------------------+ #
#######################################################################


#######################################################################
# +-----------------------------------------------------------------+ #
# |                             Spawners                            | #
# +-----------------------------------------------------------------+ #
#######################################################################


#######################################################################
# +-----------------------------------------------------------------+ #
# |                             ModData                             | #
# +-----------------------------------------------------------------+ #
#######################################################################

