#######################################################################
# +-----------------------------------------------------------------+ #
# |                            BO3 object                           | #
# +-----------------------------------------------------------------+ #
#######################################################################

Author: Bo3 BulkEdit

Description: Converted Schematic - Modified by Bo3BulkEdit

Version: 3

SettingsMode: WriteDisable

#######################################################################
# +-----------------------------------------------------------------+ #
# |                          Main settings                          | #
# +-----------------------------------------------------------------+ #
#######################################################################



Frequency: 0


SpawnHeight: randomY





##############################
# Height Limits for the BO3. #
##############################

MinHeight: 0
MaxHeight: 256

#######################################################################
# +-----------------------------------------------------------------+ #
# |                      Source block settings                      | #
# +-----------------------------------------------------------------+ #
#######################################################################

CanOverride: true
MaxPercentageOutsideSourceBlock: 100
OutsideSourceBlock: placeAnyway

#######################################################################
# +-----------------------------------------------------------------+ #
# |                               OTG+                              | #
# +-----------------------------------------------------------------+ #
#######################################################################

#######################################################################
# +-----------------------------------------------------------------+ #
# |                              Blocks                             | #
# +-----------------------------------------------------------------+ #
#######################################################################

B(0,750,0,AIR)
B(15,750,15,AIR)
B(9,-4,11,betternether:quartz_stained_glass:15)
B(10,-4,11,betternether:quartz_stained_glass:15)
B(9,-4,12,betternether:quartz_stained_glass:15)
B(10,-4,12,betternether:quartz_stained_glass:15)
B(8,-3,10,betternether:quartz_stained_glass:15)
B(9,-3,10,betternether:quartz_stained_glass:15)
B(10,-3,10,betternether:quartz_stained_glass:15)
B(8,-3,11,betternether:quartz_stained_glass:15)
B(9,-3,11,betternether:quartz_stained_glass:15)
B(10,-3,11,betternether:quartz_stained_glass:15)
B(9,-3,12,betternether:quartz_stained_glass:15)
B(10,-3,12,betternether:quartz_stained_glass:15)
B(10,-2,8,betternether:quartz_stained_glass:15)
B(7,-2,9,betternether:quartz_stained_glass:15)
B(8,-2,9,betternether:quartz_stained_glass:15)
B(9,-2,9,betternether:quartz_stained_glass:15)
B(10,-2,9,betternether:quartz_stained_glass:15)
B(7,-2,10,betternether:quartz_stained_glass:15)
B(8,-2,10,betternether:quartz_stained_glass:15)
B(9,-2,10,betternether:quartz_stained_glass:15)
B(10,-2,10,betternether:quartz_stained_glass:15)
B(8,-2,11,betternether:quartz_stained_glass:15)
B(9,-2,11,betternether:quartz_stained_glass:15)
B(10,-2,11,betternether:quartz_stained_glass:15)
B(9,-2,12,betternether:quartz_stained_glass:15)
B(9,-1,6,betternether:quartz_stained_glass:15)
B(7,-1,7,betternether:quartz_stained_glass:15)
B(8,-1,7,betternether:quartz_stained_glass:15)
B(9,-1,7,betternether:quartz_stained_glass:15)
B(6,-1,8,betternether:quartz_stained_glass:15)
B(7,-1,8,betternether:quartz_stained_glass:15)
B(8,-1,8,betternether:quartz_stained_glass:15)
B(9,-1,8,betternether:quartz_stained_glass:15)
B(10,-1,8,betternether:quartz_stained_glass:15)
B(6,-1,9,betternether:quartz_stained_glass:15)
B(7,-1,9,betternether:quartz_stained_glass:15)
B(8,-1,9,betternether:quartz_stained_glass:15)
B(9,-1,9,betternether:quartz_stained_glass:15)
B(10,-1,9,betternether:quartz_stained_glass:15)
B(11,-1,9,betternether:quartz_stained_glass:15)
B(8,-1,10,betternether:quartz_stained_glass:15)
B(9,-1,10,betternether:quartz_stained_glass:15)
B(10,-1,10,betternether:quartz_stained_glass:15)
B(11,-1,10,betternether:quartz_stained_glass:15)
B(8,-1,11,betternether:quartz_stained_glass:15)
B(9,-1,11,betternether:quartz_stained_glass:15)
B(10,-1,11,betternether:quartz_stained_glass:15)
B(9,0,5,betternether:quartz_stained_glass:15)
B(5,0,6,betternether:quartz_stained_glass:15)
B(6,0,6,betternether:quartz_stained_glass:15)
B(7,0,6,betternether:quartz_stained_glass:15)
B(8,0,6,betternether:quartz_stained_glass:15)
B(9,0,6,betternether:quartz_stained_glass:15)
B(5,0,7,betternether:quartz_stained_glass:15)
B(7,0,7,betternether:quartz_stained_glass:15)
B(8,0,7,betternether:quartz_stained_glass:15)
B(9,0,7,betternether:quartz_stained_glass:15)
B(10,0,7,betternether:quartz_stained_glass:15)
B(5,0,8,betternether:quartz_stained_glass:15)
B(6,0,8,betternether:quartz_stained_glass:15)
B(7,0,8,betternether:quartz_stained_glass:15)
B(8,0,8,betternether:quartz_stained_glass:15)
B(9,0,8,betternether:quartz_stained_glass:15)
B(10,0,8,betternether:quartz_stained_glass:15)
B(11,0,8,betternether:quartz_stained_glass:15)
B(7,0,9,betternether:quartz_stained_glass:15)
B(9,0,9,betternether:quartz_stained_glass:15)
B(10,0,9,betternether:quartz_stained_glass:15)
B(11,0,9,betternether:quartz_stained_glass:15)
B(7,0,10,betternether:quartz_stained_glass:15)
B(8,0,10,betternether:quartz_stained_glass:15)
B(9,0,10,betternether:quartz_stained_glass:15)
B(10,0,10,betternether:quartz_stained_glass:15)
B(7,0,11,betternether:quartz_stained_glass:15)
B(8,0,11,betternether:quartz_stained_glass:15)
B(8,1,4,betternether:quartz_stained_glass:15)
B(9,1,4,betternether:quartz_stained_glass:15)
B(5,1,5,betternether:quartz_stained_glass:15)
B(6,1,5,betternether:quartz_stained_glass:15)
B(7,1,5,betternether:quartz_stained_glass:15)
B(8,1,5,betternether:quartz_stained_glass:15)
B(9,1,5,betternether:quartz_stained_glass:15)
B(5,1,6,betternether:quartz_stained_glass:15)
B(6,1,6,betternether:quartz_stained_glass:15)
B(7,1,6,betternether:quartz_stained_glass:15)
B(8,1,6,betternether:quartz_stained_glass:15)
B(9,1,6,betternether:quartz_stained_glass:15)
B(10,1,6,betternether:quartz_stained_glass:15)
B(5,1,7,betternether:quartz_stained_glass:15)
B(6,1,7,betternether:quartz_stained_glass:15)
B(7,1,7,betternether:quartz_stained_glass:15)
B(8,1,7,betternether:quartz_stained_glass:15)
B(9,1,7,betternether:quartz_stained_glass:15)
B(10,1,7,betternether:quartz_stained_glass:15)
B(11,1,7,betternether:quartz_stained_glass:15)
B(6,1,8,betternether:quartz_stained_glass:15)
RB(8,1,8,srparasites:parasitestain:1,80,quark:crystal:1,30,srparasites:parasiterubbledense:1,100)
B(9,1,8,srparasites:parasiterubbledense:1)
B(10,1,8,srparasites:parasiterubbledense:1)
B(11,1,8,betternether:quartz_stained_glass:15)
B(6,1,9,betternether:quartz_stained_glass:15)
B(7,1,9,betternether:quartz_stained_glass:15)
B(8,1,9,betternether:quartz_stained_glass:15)
B(9,1,9,betternether:quartz_stained_glass:15)
B(10,1,9,betternether:quartz_stained_glass:15)
B(11,1,9,betternether:quartz_stained_glass:15)
B(6,1,10,betternether:quartz_stained_glass:15)
B(7,1,10,betternether:quartz_stained_glass:15)
B(8,1,10,betternether:quartz_stained_glass:15)
B(9,1,10,betternether:quartz_stained_glass:15)
B(7,1,11,betternether:quartz_stained_glass:15)
B(9,1,11,betternether:quartz_stained_glass:15)
B(10,2,3,betternether:quartz_stained_glass:15)
B(6,2,4,betternether:quartz_stained_glass:15)
B(7,2,4,betternether:quartz_stained_glass:15)
B(8,2,4,betternether:quartz_stained_glass:15)
B(9,2,4,betternether:quartz_stained_glass:15)
B(10,2,4,betternether:quartz_stained_glass:15)
B(5,2,5,betternether:quartz_stained_glass:15)
B(6,2,5,betternether:quartz_stained_glass:15)
B(7,2,5,betternether:quartz_stained_glass:15)
B(8,2,5,betternether:quartz_stained_glass:15)
B(9,2,5,betternether:quartz_stained_glass:15)
B(10,2,5,betternether:quartz_stained_glass:15)
B(5,2,6,betternether:quartz_stained_glass:15)
B(6,2,6,betternether:quartz_stained_glass:15)
RB(7,2,6,srparasites:parasitestain:1,80,quark:crystal:1,30,srparasites:parasiterubbledense:1,100)
B(8,2,6,betternether:quartz_stained_glass:15)
B(9,2,6,betternether:quartz_stained_glass:15)
B(10,2,6,betternether:quartz_stained_glass:15)
B(11,2,6,betternether:quartz_stained_glass:15)
B(5,2,7,betternether:quartz_stained_glass:15)
B(6,2,7,betternether:quartz_stained_glass:15)
B(7,2,7,betternether:quartz_stained_glass:15)
RB(8,2,7,srparasites:parasitestain:1,80,quark:crystal:1,30,srparasites:parasiterubbledense:1,100)
RB(9,2,7,srparasites:parasitestain:1,80,quark:crystal:1,30,srparasites:parasiterubbledense:1,100)
B(10,2,7,betternether:quartz_stained_glass:15)
B(11,2,7,betternether:quartz_stained_glass:15)
B(5,2,8,betternether:quartz_stained_glass:15)
B(6,2,8,betternether:quartz_stained_glass:15)
B(7,2,8,betternether:quartz_stained_glass:15)
B(8,2,8,betternether:quartz_stained_glass:15)
B(9,2,8,betternether:quartz_stained_glass:15)
B(10,2,8,srparasites:parasiterubbledense:1)
B(11,2,8,betternether:quartz_stained_glass:15)
B(6,2,9,betternether:quartz_stained_glass:15)
B(7,2,9,betternether:quartz_stained_glass:15)
B(8,2,9,betternether:quartz_stained_glass:15)
B(9,2,9,betternether:quartz_stained_glass:15)
B(10,2,9,betternether:quartz_stained_glass:15)
B(6,2,10,betternether:quartz_stained_glass:15)
B(8,2,10,betternether:quartz_stained_glass:15)
B(9,3,2,betternether:quartz_stained_glass:15)
B(6,3,3,betternether:quartz_stained_glass:15)
B(8,3,3,betternether:quartz_stained_glass:15)
B(9,3,3,betternether:quartz_stained_glass:15)
B(10,3,3,betternether:quartz_stained_glass:15)
B(5,3,4,betternether:quartz_stained_glass:15)
B(6,3,4,betternether:quartz_stained_glass:15)
B(7,3,4,betternether:quartz_stained_glass:15)
B(8,3,4,betternether:quartz_stained_glass:15)
B(9,3,4,betternether:quartz_stained_glass:15)
B(10,3,4,betternether:quartz_stained_glass:15)
B(5,3,5,betternether:quartz_stained_glass:15)
B(6,3,5,betternether:quartz_stained_glass:15)
B(7,3,5,betternether:quartz_stained_glass:15)
B(8,3,5,betternether:quartz_stained_glass:15)
B(9,3,5,betternether:quartz_stained_glass:15)
B(10,3,5,betternether:quartz_stained_glass:15)
B(11,3,5,betternether:quartz_stained_glass:15)
B(5,3,6,betternether:quartz_stained_glass:15)
B(6,3,6,betternether:quartz_stained_glass:15)
RB(7,3,6,srparasites:parasitestain:1,80,quark:crystal:1,30,srparasites:parasiterubbledense:1,100)
RB(8,3,6,srparasites:parasitestain:1,80,quark:crystal:1,30,srparasites:parasiterubbledense:1,100)
B(9,3,6,srparasites:parasiterubbledense:1)
B(10,3,6,srparasites:parasiterubbledense:1)
B(11,3,6,betternether:quartz_stained_glass:15)
B(12,3,6,betternether:quartz_stained_glass:15)
B(4,3,7,betternether:quartz_stained_glass:15)
B(5,3,7,betternether:quartz_stained_glass:15)
B(6,3,7,betternether:quartz_stained_glass:15)
B(7,3,7,betternether:quartz_stained_glass:15)
RB(8,3,7,srparasites:parasitestain:1,80,quark:crystal:1,30,srparasites:parasiterubbledense:1,100)
B(9,3,7,srparasites:parasiterubbledense:1)
B(10,3,7,srparasites:parasiterubbledense:1)
B(11,3,7,betternether:quartz_stained_glass:15)
B(5,3,8,betternether:quartz_stained_glass:15)
B(6,3,8,betternether:quartz_stained_glass:15)
B(7,3,8,betternether:quartz_stained_glass:15)
B(8,3,8,srparasites:parasiterubbledense:1)
B(9,3,8,betternether:quartz_stained_glass:15)
B(10,3,8,betternether:quartz_stained_glass:15)
B(11,3,8,betternether:quartz_stained_glass:15)
B(6,3,9,betternether:quartz_stained_glass:15)
B(7,3,9,betternether:quartz_stained_glass:15)
B(8,3,9,betternether:quartz_stained_glass:15)
B(9,3,9,betternether:quartz_stained_glass:15)
B(7,4,2,betternether:quartz_stained_glass:15)
B(8,4,2,betternether:quartz_stained_glass:15)
B(9,4,2,betternether:quartz_stained_glass:15)
B(4,4,3,betternether:quartz_stained_glass:15)
B(5,4,3,betternether:quartz_stained_glass:15)
B(6,4,3,betternether:quartz_stained_glass:15)
B(7,4,3,betternether:quartz_stained_glass:15)
B(8,4,3,betternether:quartz_stained_glass:15)
B(9,4,3,betternether:quartz_stained_glass:15)
B(10,4,3,betternether:quartz_stained_glass:15)
B(5,4,4,betternether:quartz_stained_glass:15)
B(6,4,4,betternether:quartz_stained_glass:15)
B(7,4,4,betternether:quartz_stained_glass:15)
RB(8,4,4,srparasites:parasitestain:1,80,quark:crystal:1,30,srparasites:parasiterubbledense:1,100)
B(9,4,4,betternether:quartz_stained_glass:15)
B(10,4,4,betternether:quartz_stained_glass:15)
B(5,4,5,betternether:quartz_stained_glass:15)
B(6,4,5,betternether:quartz_stained_glass:15)
RB(7,4,5,srparasites:parasitestain:1,80,quark:crystal:1,30,srparasites:parasiterubbledense:1,100)
RB(8,4,5,srparasites:parasitestain:1,80,quark:crystal:1,30,srparasites:parasiterubbledense:1,100)
B(9,4,5,betternether:quartz_stained_glass:15)
B(10,4,5,betternether:quartz_stained_glass:15)
B(11,4,5,betternether:quartz_stained_glass:15)
B(5,4,6,betternether:quartz_stained_glass:15)
B(6,4,6,betternether:quartz_stained_glass:15)
RB(7,4,6,srparasites:parasitestain:1,80,quark:crystal:1,30,srparasites:parasiterubbledense:1,100)
B(8,4,6,srparasites:parasiterubbledense:1)
B(9,4,6,srparasites:parasiterubbledense:1)
B(10,4,6,srparasites:parasiterubbledense:1)
B(11,4,6,betternether:quartz_stained_glass:15)
B(4,4,7,betternether:quartz_stained_glass:15)
B(5,4,7,betternether:quartz_stained_glass:15)
B(6,4,7,betternether:quartz_stained_glass:15)
B(7,4,7,betternether:quartz_stained_glass:15)
B(8,4,7,srparasites:parasiterubbledense:1)
B(9,4,7,srparasites:parasiterubbledense:1)
B(10,4,7,srparasites:parasiterubbledense:1)
B(11,4,7,betternether:quartz_stained_glass:15)
B(6,4,8,betternether:quartz_stained_glass:15)
B(7,4,8,betternether:quartz_stained_glass:15)
B(8,4,8,betternether:quartz_stained_glass:15)
B(9,4,8,betternether:quartz_stained_glass:15)
B(8,4,9,betternether:quartz_stained_glass:15)
B(9,5,1,betternether:quartz_stained_glass:15)
B(5,5,2,betternether:quartz_stained_glass:15)
B(6,5,2,betternether:quartz_stained_glass:15)
B(7,5,2,betternether:quartz_stained_glass:15)
B(8,5,2,betternether:quartz_stained_glass:15)
B(9,5,2,betternether:quartz_stained_glass:15)
B(4,5,3,betternether:quartz_stained_glass:15)
B(5,5,3,betternether:quartz_stained_glass:15)
B(6,5,3,betternether:quartz_stained_glass:15)
B(7,5,3,betternether:quartz_stained_glass:15)
B(8,5,3,betternether:quartz_stained_glass:15)
B(9,5,3,betternether:quartz_stained_glass:15)
B(10,5,3,betternether:quartz_stained_glass:15)
B(5,5,4,betternether:quartz_stained_glass:15)
B(6,5,4,betternether:quartz_stained_glass:15)
RB(7,5,4,srparasites:parasitestain:1,80,quark:crystal:1,30,srparasites:parasiterubbledense:1,100)
RB(8,5,4,srparasites:parasitestain:1,80,quark:crystal:1,30,srparasites:parasiterubbledense:1,100)
B(9,5,4,betternether:quartz_stained_glass:15)
B(10,5,4,betternether:quartz_stained_glass:15)
B(11,5,4,betternether:quartz_stained_glass:15)
B(4,5,5,betternether:quartz_stained_glass:15)
B(5,5,5,betternether:quartz_stained_glass:15)
B(6,5,5,betternether:quartz_stained_glass:15)
RB(7,5,5,srparasites:parasitestain:1,80,quark:crystal:1,30,srparasites:parasiterubbledense:1,100)
RB(8,5,5,srparasites:parasitestain:1,80,quark:crystal:1,30,srparasites:parasiterubbledense:1,100)
B(9,5,5,betternether:quartz_stained_glass:15)
B(10,5,5,betternether:quartz_stained_glass:15)
B(11,5,5,betternether:quartz_stained_glass:15)
B(5,5,6,betternether:quartz_stained_glass:15)
B(6,5,6,betternether:quartz_stained_glass:15)
B(7,5,6,betternether:quartz_stained_glass:15)
B(8,5,6,srparasites:parasiterubbledense:1)
B(9,5,6,srparasites:parasiterubbledense:1)
B(10,5,6,betternether:quartz_stained_glass:15)
B(11,5,6,betternether:quartz_stained_glass:15)
B(4,5,7,betternether:quartz_stained_glass:15)
B(5,5,7,betternether:quartz_stained_glass:15)
B(6,5,7,betternether:quartz_stained_glass:15)
B(7,5,7,betternether:quartz_stained_glass:15)
B(8,5,7,srparasites:parasiterubbledense:1)
B(9,5,7,betternether:quartz_stained_glass:15)
B(10,5,7,betternether:quartz_stained_glass:15)
B(6,5,8,betternether:quartz_stained_glass:15)
B(8,5,8,betternether:quartz_stained_glass:15)
B(9,6,0,betternether:quartz_stained_glass:15)
B(5,6,1,betternether:quartz_stained_glass:15)
B(6,6,1,betternether:quartz_stained_glass:15)
B(7,6,1,betternether:quartz_stained_glass:15)
B(8,6,1,betternether:quartz_stained_glass:15)
B(9,6,1,betternether:quartz_stained_glass:15)
B(4,6,2,betternether:quartz_stained_glass:15)
B(5,6,2,betternether:quartz_stained_glass:15)
B(6,6,2,betternether:quartz_stained_glass:15)
B(7,6,2,betternether:quartz_stained_glass:15)
B(8,6,2,betternether:quartz_stained_glass:15)
B(9,6,2,betternether:quartz_stained_glass:15)
B(4,6,3,betternether:quartz_stained_glass:15)
B(5,6,3,betternether:quartz_stained_glass:15)
RB(6,6,3,srparasites:parasitestain:1,80,quark:crystal:1,30,srparasites:parasiterubbledense:1,100)
B(7,6,3,betternether:quartz_stained_glass:15)
RB(8,6,3,srparasites:parasitestain:1,80,quark:crystal:1,30,srparasites:parasiterubbledense:1,100)
B(9,6,3,betternether:quartz_stained_glass:15)
B(10,6,3,betternether:quartz_stained_glass:15)
B(5,6,4,betternether:quartz_stained_glass:15)
B(6,6,4,betternether:quartz_stained_glass:15)
RB(7,6,4,srparasites:parasitestain:1,80,quark:crystal:1,30,srparasites:parasiterubbledense:1,100)
RB(8,6,4,srparasites:parasitestain:1,80,quark:crystal:1,30,srparasites:parasiterubbledense:1,100)
B(9,6,4,betternether:quartz_stained_glass:15)
B(10,6,4,betternether:quartz_stained_glass:15)
B(11,6,4,betternether:quartz_stained_glass:15)
B(4,6,5,betternether:quartz_stained_glass:15)
B(5,6,5,betternether:quartz_stained_glass:15)
B(6,6,5,betternether:quartz_stained_glass:15)
RB(7,6,5,srparasites:parasitestain:1,80,quark:crystal:1,30,srparasites:parasiterubbledense:1,100)
B(8,6,5,srparasites:parasiterubbledense:1)
B(9,6,5,betternether:quartz_stained_glass:15)
B(10,6,5,betternether:quartz_stained_glass:15)
B(5,6,6,betternether:quartz_stained_glass:15)
B(6,6,6,betternether:quartz_stained_glass:15)
B(7,6,6,srparasites:parasiterubbledense:1)
B(8,6,6,betternether:quartz_stained_glass:15)
B(9,6,6,betternether:quartz_stained_glass:15)
B(11,6,6,betternether:quartz_stained_glass:15)
B(5,6,7,betternether:quartz_stained_glass:15)
B(6,6,7,betternether:quartz_stained_glass:15)
B(7,6,7,betternether:quartz_stained_glass:15)
B(8,6,7,betternether:quartz_stained_glass:15)
B(9,6,7,betternether:quartz_stained_glass:15)
B(7,7,0,betternether:quartz_stained_glass:15)
B(8,7,0,betternether:quartz_stained_glass:15)
B(9,7,0,betternether:quartz_stained_glass:15)
B(4,7,1,betternether:quartz_stained_glass:15)
B(5,7,1,betternether:quartz_stained_glass:15)
B(6,7,1,betternether:quartz_stained_glass:15)
B(7,7,1,betternether:quartz_stained_glass:15)
B(8,7,1,betternether:quartz_stained_glass:15)
B(9,7,1,betternether:quartz_stained_glass:15)
B(4,7,2,betternether:quartz_stained_glass:15)
B(5,7,2,betternether:quartz_stained_glass:15)
B(6,7,2,betternether:quartz_stained_glass:15)
RB(7,7,2,srparasites:parasitestain:1,80,quark:crystal:1,30,srparasites:parasiterubbledense:1,100)
B(8,7,2,betternether:quartz_stained_glass:15)
B(9,7,2,betternether:quartz_stained_glass:15)
B(10,7,2,betternether:quartz_stained_glass:15)
B(11,7,2,betternether:quartz_stained_glass:15)
B(4,7,3,betternether:quartz_stained_glass:15)
B(5,7,3,betternether:quartz_stained_glass:15)
RB(6,7,3,srparasites:parasitestain:1,80,quark:crystal:1,30,srparasites:parasiterubbledense:1,100)
RB(7,7,3,srparasites:parasitestain:1,80,quark:crystal:1,30,srparasites:parasiterubbledense:1,100)
RB(8,7,3,srparasites:parasitestain:1,80,quark:crystal:1,30,srparasites:parasiterubbledense:1,100)
B(9,7,3,betternether:quartz_stained_glass:15)
B(10,7,3,betternether:quartz_stained_glass:15)
B(4,7,4,betternether:quartz_stained_glass:15)
B(5,7,4,betternether:quartz_stained_glass:15)
B(6,7,4,betternether:quartz_stained_glass:15)
RB(7,7,4,srparasites:parasitestain:1,80,quark:crystal:1,30,srparasites:parasiterubbledense:1,100)
B(8,7,4,betternether:quartz_stained_glass:15)
B(9,7,4,betternether:quartz_stained_glass:15)
B(10,7,4,betternether:quartz_stained_glass:15)
B(11,7,4,betternether:quartz_stained_glass:15)
B(4,7,5,betternether:quartz_stained_glass:15)
B(5,7,5,betternether:quartz_stained_glass:15)
B(6,7,5,srparasites:parasiterubbledense:1)
B(7,7,5,betternether:quartz_stained_glass:15)
B(8,7,5,srparasites:parasiterubbledense:1)
B(9,7,5,srparasites:parasiterubbledense:1)
B(10,7,5,betternether:quartz_stained_glass:15)
B(5,7,6,betternether:quartz_stained_glass:15)
B(6,7,6,betternether:quartz_stained_glass:15)
B(7,7,6,betternether:quartz_stained_glass:15)
B(8,7,6,betternether:quartz_stained_glass:15)
B(8,7,7,betternether:quartz_stained_glass:15)
B(5,8,0,betternether:quartz_stained_glass:15)
B(6,8,0,betternether:quartz_stained_glass:15)
B(7,8,0,betternether:quartz_stained_glass:15)
B(8,8,0,betternether:quartz_stained_glass:15)
B(9,8,0,betternether:quartz_stained_glass:15)
B(4,8,1,betternether:quartz_stained_glass:15)
B(5,8,1,betternether:quartz_stained_glass:15)
B(6,8,1,betternether:quartz_stained_glass:15)
B(7,8,1,betternether:quartz_stained_glass:15)
B(8,8,1,betternether:quartz_stained_glass:15)
B(9,8,1,betternether:quartz_stained_glass:15)
B(4,8,2,betternether:quartz_stained_glass:15)
B(5,8,2,betternether:quartz_stained_glass:15)
RB(6,8,2,srparasites:parasitestain:1,80,quark:crystal:1,30,srparasites:parasiterubbledense:1,100)
RB(7,8,2,srparasites:parasitestain:1,80,quark:crystal:1,30,srparasites:parasiterubbledense:1,100)
B(8,8,2,betternether:quartz_stained_glass:15)
B(9,8,2,betternether:quartz_stained_glass:15)
B(10,8,2,betternether:quartz_stained_glass:15)
B(11,8,2,betternether:quartz_stained_glass:15)
B(4,8,3,betternether:quartz_stained_glass:15)
B(5,8,3,betternether:quartz_stained_glass:15)
RB(6,8,3,srparasites:parasitestain:1,80,quark:crystal:1,30,srparasites:parasiterubbledense:1,100)
RB(7,8,3,srparasites:parasitestain:1,80,quark:crystal:1,30,srparasites:parasiterubbledense:1,100)
RB(8,8,3,srparasites:parasitestain:1,80,quark:crystal:1,30,srparasites:parasiterubbledense:1,100)
B(9,8,3,betternether:quartz_stained_glass:15)
B(10,8,3,betternether:quartz_stained_glass:15)
B(4,8,4,betternether:quartz_stained_glass:15)
B(5,8,4,betternether:quartz_stained_glass:15)
B(6,8,4,betternether:quartz_stained_glass:15)
B(7,8,4,betternether:quartz_stained_glass:15)
B(8,8,4,betternether:quartz_stained_glass:15)
B(9,8,4,betternether:quartz_stained_glass:15)
B(10,8,4,betternether:quartz_stained_glass:15)
B(5,8,5,betternether:quartz_stained_glass:15)
B(6,8,5,betternether:quartz_stained_glass:15)
B(7,8,5,betternether:quartz_stained_glass:15)
B(8,8,5,betternether:quartz_stained_glass:15)
B(9,8,5,betternether:quartz_stained_glass:15)
B(5,8,6,betternether:quartz_stained_glass:15)
B(7,8,6,betternether:quartz_stained_glass:15)
B(4,9,0,betternether:quartz_stained_glass:15)
B(5,9,0,betternether:quartz_stained_glass:15)
B(6,9,0,betternether:quartz_stained_glass:15)
B(7,9,0,betternether:quartz_stained_glass:15)
B(8,9,0,betternether:quartz_stained_glass:15)
B(9,9,0,betternether:quartz_stained_glass:15)
B(4,9,1,betternether:quartz_stained_glass:15)
B(5,9,1,betternether:quartz_stained_glass:15)
RB(6,9,1,srparasites:parasitestain:1,80,quark:crystal:1,30,srparasites:parasiterubbledense:1,100)
RB(7,9,1,srparasites:parasitestain:1,80,quark:crystal:1,30,srparasites:parasiterubbledense:1,100)
B(8,9,1,betternether:quartz_stained_glass:15)
B(9,9,1,betternether:quartz_stained_glass:15)
B(10,9,1,betternether:quartz_stained_glass:15)
B(4,9,2,betternether:quartz_stained_glass:15)
B(5,9,2,betternether:quartz_stained_glass:15)
RB(6,9,2,srparasites:parasitestain:1,80,quark:crystal:1,30,srparasites:parasiterubbledense:1,100)
RB(7,9,2,srparasites:parasitestain:1,80,quark:crystal:1,30,srparasites:parasiterubbledense:1,100)
B(8,9,2,betternether:quartz_stained_glass:15)
B(9,9,2,betternether:quartz_stained_glass:15)
B(10,9,2,betternether:quartz_stained_glass:15)
B(11,9,2,betternether:quartz_stained_glass:15)
B(3,9,3,betternether:quartz_stained_glass:15)
B(4,9,3,betternether:quartz_stained_glass:15)
B(5,9,3,betternether:quartz_stained_glass:15)
B(6,9,3,betternether:quartz_stained_glass:15)
RB(7,9,3,srparasites:parasitestain:1,80,quark:crystal:1,30,srparasites:parasiterubbledense:1,100)
B(8,9,3,betternether:quartz_stained_glass:15)
B(9,9,3,betternether:quartz_stained_glass:15)
B(10,9,3,betternether:quartz_stained_glass:15)
B(4,9,4,betternether:quartz_stained_glass:15)
B(5,9,4,betternether:quartz_stained_glass:15)
B(6,9,4,betternether:quartz_stained_glass:15)
B(7,9,4,srparasites:parasiterubbledense:1)
B(8,9,4,betternether:quartz_stained_glass:15)
B(9,9,4,betternether:quartz_stained_glass:15)
B(5,9,5,betternether:quartz_stained_glass:15)
B(7,9,5,betternether:quartz_stained_glass:15)
B(8,9,5,betternether:quartz_stained_glass:15)
B(4,10,0,betternether:quartz_stained_glass:15)
B(5,10,0,betternether:quartz_stained_glass:15)
B(6,10,0,betternether:quartz_stained_glass:15)
RB(7,10,0,srparasites:parasitestain:1,80,quark:crystal:1,30,srparasites:parasiterubbledense:1,100)
B(8,10,0,betternether:quartz_stained_glass:15)
B(9,10,0,betternether:quartz_stained_glass:15)
B(4,10,1,betternether:quartz_stained_glass:15)
B(5,10,1,betternether:quartz_stained_glass:15)
RB(6,10,1,srparasites:parasitestain:1,80,quark:crystal:1,30,srparasites:parasiterubbledense:1,100)
RB(7,10,1,srparasites:parasitestain:1,80,quark:crystal:1,30,srparasites:parasiterubbledense:1,100)
B(8,10,1,betternether:quartz_stained_glass:15)
B(9,10,1,betternether:quartz_stained_glass:15)
B(10,10,1,betternether:quartz_stained_glass:15)
B(4,10,2,betternether:quartz_stained_glass:15)
B(5,10,2,betternether:quartz_stained_glass:15)
RB(6,10,2,srparasites:parasitestain:1,80,quark:crystal:1,30,srparasites:parasiterubbledense:1,100)
B(7,10,2,srparasites:parasiterubbledense:1)
B(8,10,2,betternether:quartz_stained_glass:15)
B(9,10,2,betternether:quartz_stained_glass:15)
B(3,10,3,betternether:quartz_stained_glass:15)
B(4,10,3,betternether:quartz_stained_glass:15)
B(5,10,3,betternether:quartz_stained_glass:15)
B(6,10,3,srparasites:parasiterubbledense:1)
B(7,10,3,srparasites:parasiterubbledense:1)
B(8,10,3,srparasites:parasiterubbledense:1)
B(9,10,3,betternether:quartz_stained_glass:15)
B(10,10,3,betternether:quartz_stained_glass:15)
B(5,10,4,betternether:quartz_stained_glass:15)
B(6,10,4,betternether:quartz_stained_glass:15)
B(7,10,4,betternether:quartz_stained_glass:15)
B(8,10,4,betternether:quartz_stained_glass:15)
B(7,10,5,betternether:quartz_stained_glass:15)
B(4,11,0,betternether:quartz_stained_glass:15)
B(5,11,0,betternether:quartz_stained_glass:15)
RB(6,11,0,srparasites:parasitestain:1,80,quark:crystal:1,30,srparasites:parasiterubbledense:1,100)
RB(7,11,0,srparasites:parasitestain:1,80,quark:crystal:1,30,srparasites:parasiterubbledense:1,100)
B(8,11,0,betternether:quartz_stained_glass:15)
B(9,11,0,betternether:quartz_stained_glass:15)
B(3,11,1,betternether:quartz_stained_glass:15)
B(4,11,1,betternether:quartz_stained_glass:15)
B(5,11,1,betternether:quartz_stained_glass:15)
RB(6,11,1,srparasites:parasitestain:1,80,quark:crystal:1,30,srparasites:parasiterubbledense:1,100)
RB(7,11,1,srparasites:parasitestain:1,80,quark:crystal:1,30,srparasites:parasiterubbledense:1,100)
B(8,11,1,betternether:quartz_stained_glass:15)
B(9,11,1,betternether:quartz_stained_glass:15)
B(10,11,1,betternether:quartz_stained_glass:15)
B(4,11,2,betternether:quartz_stained_glass:15)
B(5,11,2,betternether:quartz_stained_glass:15)
B(6,11,2,betternether:quartz_stained_glass:15)
B(7,11,2,srparasites:parasiterubbledense:1)
B(8,11,2,srparasites:parasiterubbledense:1)
B(9,11,2,betternether:quartz_stained_glass:15)
B(3,11,3,betternether:quartz_stained_glass:15)
B(4,11,3,betternether:quartz_stained_glass:15)
B(5,11,3,srparasites:parasiterubbledense:1)
B(6,11,3,betternether:quartz_stained_glass:15)
B(7,11,3,srparasites:parasiterubbledense:1)
B(8,11,3,betternether:quartz_stained_glass:15)
B(9,11,3,betternether:quartz_stained_glass:15)
B(5,11,4,betternether:quartz_stained_glass:15)
B(7,11,4,betternether:quartz_stained_glass:15)
B(4,12,0,betternether:quartz_stained_glass:15)
B(5,12,0,betternether:quartz_stained_glass:15)
RB(6,12,0,srparasites:parasitestain:1,80,quark:crystal:1,30,srparasites:parasiterubbledense:1,100)
RB(7,12,0,srparasites:parasitestain:1,80,quark:crystal:1,30,srparasites:parasiterubbledense:1,100)
B(8,12,0,betternether:quartz_stained_glass:15)
B(9,12,0,betternether:quartz_stained_glass:15)
B(3,12,1,betternether:quartz_stained_glass:15)
B(4,12,1,betternether:quartz_stained_glass:15)
B(5,12,1,betternether:quartz_stained_glass:15)
B(6,12,1,betternether:quartz_stained_glass:15)
B(7,12,1,betternether:quartz_stained_glass:15)
B(8,12,1,betternether:quartz_stained_glass:15)
B(9,12,1,betternether:quartz_stained_glass:15)
B(4,12,2,betternether:quartz_stained_glass:15)
B(5,12,2,betternether:quartz_stained_glass:15)
B(6,12,2,betternether:quartz_stained_glass:15)
B(7,12,2,betternether:quartz_stained_glass:15)
B(8,12,2,betternether:quartz_stained_glass:15)
B(4,12,3,betternether:quartz_stained_glass:15)
B(5,12,3,betternether:quartz_stained_glass:15)
B(6,12,3,betternether:quartz_stained_glass:15)
B(7,12,3,betternether:quartz_stained_glass:15)
B(8,12,3,betternether:quartz_stained_glass:15)
B(2,13,0,betternether:quartz_stained_glass:15)
B(3,13,0,betternether:quartz_stained_glass:15)
B(4,13,0,betternether:quartz_stained_glass:15)
B(5,13,0,betternether:quartz_stained_glass:15)
RB(6,13,0,srparasites:parasitestain:1,80,quark:crystal:1,30,srparasites:parasiterubbledense:1,100)
B(7,13,0,srparasites:parasiterubbledense:1)
B(8,13,0,betternether:quartz_stained_glass:15)
B(9,13,0,betternether:quartz_stained_glass:15)
B(3,13,1,betternether:quartz_stained_glass:15)
B(4,13,1,betternether:quartz_stained_glass:15)
B(5,13,1,betternether:quartz_stained_glass:15)
B(6,13,1,srparasites:parasiterubbledense:1)
B(7,13,1,srparasites:parasiterubbledense:1)
B(8,13,1,srparasites:parasiterubbledense:1)
B(9,13,1,betternether:quartz_stained_glass:15)
B(4,13,2,betternether:quartz_stained_glass:15)
B(5,13,2,betternether:quartz_stained_glass:15)
B(6,13,2,betternether:quartz_stained_glass:15)
B(7,13,2,betternether:quartz_stained_glass:15)
B(7,13,3,betternether:quartz_stained_glass:15)
B(2,14,0,betternether:quartz_stained_glass:15)
B(3,14,0,betternether:quartz_stained_glass:15)
B(4,14,0,betternether:quartz_stained_glass:15)
B(5,14,0,betternether:quartz_stained_glass:15)
B(6,14,0,betternether:quartz_stained_glass:15)
B(7,14,0,srparasites:parasiterubbledense:1)
B(8,14,0,srparasites:parasiterubbledense:1)
B(9,14,0,betternether:quartz_stained_glass:15)
B(4,14,1,betternether:quartz_stained_glass:15)
B(5,14,1,betternether:quartz_stained_glass:15)
B(6,14,1,betternether:quartz_stained_glass:15)
B(7,14,1,betternether:quartz_stained_glass:15)
B(8,14,1,betternether:quartz_stained_glass:15)
B(4,14,2,betternether:quartz_stained_glass:15)
B(6,14,2,betternether:quartz_stained_glass:15)
B(2,15,0,betternether:quartz_stained_glass:15)
B(3,15,0,betternether:quartz_stained_glass:15)
B(4,15,0,betternether:quartz_stained_glass:15)
B(5,15,0,betternether:quartz_stained_glass:15)
B(6,15,0,betternether:quartz_stained_glass:15)
B(7,15,0,betternether:quartz_stained_glass:15)
B(8,15,0,betternether:quartz_stained_glass:15)
B(4,15,1,betternether:quartz_stained_glass:15)
B(6,15,1,betternether:quartz_stained_glass:15)
B(7,15,1,betternether:quartz_stained_glass:15)
B(4,16,0,betternether:quartz_stained_glass:15)
B(5,16,0,betternether:quartz_stained_glass:15)
B(6,16,0,betternether:quartz_stained_glass:15)
B(7,16,0,betternether:quartz_stained_glass:15)
B(4,17,0,betternether:quartz_stained_glass:15)
B(6,17,0,betternether:quartz_stained_glass:15)

#######################################################################
# +-----------------------------------------------------------------+ #
# |                             Branches                            | #
# +-----------------------------------------------------------------+ #
#######################################################################

BR(0,0,-16,true,CRYST-SET-MED-BIG-03_0x0,NORTH,100,0)
