
#######################################################################
# +-----------------------------------------------------------------+ #
# |                            BO4 object                           | #
# +-----------------------------------------------------------------+ #
#######################################################################

Author: NLBlackEagle

Description: No description given

SettingsMode: WriteWithoutComments


#######################################################################
# +-----------------------------------------------------------------+ #
# |                          Main settings                          | #
# +-----------------------------------------------------------------+ #
#######################################################################

FixedRotation: 

Frequency: 0

SpawnHeight: highestBlock

UseCenterForHighestBlock: true

##############################
# Height Limits for the BO4. #
##############################

MinHeight: 0

MaxHeight: 255

InheritBO3: 

InheritBO3Rotation: NORTH

OverrideChildSettings: true

OverrideParentHeight: false

CanOverride: true

BranchFrequency: 0

BranchFrequencyGroup: 

MustBeBelowOther: false

MustBeInside: 

CannotBeInside: 

ReplacesBO3: 

MustBeInsideWorldBorders: false

CanSpawnOnWater: true

SpawnOnWaterOnly: false

SpawnUnderWater: false

SpawnAtWaterLevel: false

HeightOffset: 0

RemoveAir: false

ReplaceAbove: 

ReplaceBelow: 

ReplaceWithBiomeBlocks: true

ReplaceWithSurfaceBlock: GRASS

ReplaceWithGroundBlock: DIRT

ReplaceWithStoneBlock: STONE

SmoothRadius: 0

SmoothHeightOffset: 0

SmoothStartTop: false

SmoothStartWood: false

SmoothingSurfaceBlock: 

SmoothingGroundBlock: 

BO3Group: 

IsSpawnPoint: false

DoReplaceBlocks: false


#######################################################################
# +-----------------------------------------------------------------+ #
# |                              Blocks                             | #
# +-----------------------------------------------------------------+ #
#######################################################################

Block(-8,3,-5,COBBLESTONE_STAIRS:6)
RandomBlock(-8,3,-4,quark:iron_plate:1,70,STAINED_CLAY:15,30,STAINED_CLAY:7,30,null,30,quark:iron_plate:1,100)
RandomBlock(-8,3,-3,quark:iron_plate:1,70,STAINED_CLAY:15,30,STAINED_CLAY:7,30,null,30,quark:iron_plate:1,100)
RandomBlock(-8,3,-2,quark:iron_plate:1,70,STAINED_CLAY:15,30,STAINED_CLAY:7,30,null,30,quark:iron_plate:1,100)
RandomBlock(-8,3,-1,quark:iron_plate:1,70,STAINED_CLAY:15,30,STAINED_CLAY:7,30,null,30,quark:iron_plate:1,100)
RandomBlock(-8,3,0,quark:iron_plate:1,70,STAINED_CLAY:15,30,STAINED_CLAY:7,30,null,30,quark:iron_plate:1,100)
RandomBlock(-8,3,1,quark:iron_plate:1,70,STAINED_CLAY:15,30,STAINED_CLAY:7,30,null,30,quark:iron_plate:1,100)
RandomBlock(-8,3,2,quark:iron_plate:1,70,STAINED_CLAY:15,30,STAINED_CLAY:7,30,null,30,quark:iron_plate:1,100)
Block(-8,3,3,COBBLESTONE_STAIRS:7)
RandomBlock(-8,4,-5,quark:iron_plate:1,70,STAINED_CLAY:15,30,STAINED_CLAY:7,30,null,30,quark:iron_plate:1,100)
Block(-8,4,-4,srparasites:deadblood)
Block(-8,4,-3,srparasites:deadblood)
Block(-8,4,-2,srparasites:deadblood)
Block(-8,4,-1,srparasites:deadblood)
Block(-8,4,0,srparasites:deadblood)
Block(-8,4,1,srparasites:deadblood)
Block(-8,4,2,srparasites:deadblood)
RandomBlock(-8,4,3,quark:iron_plate:1,70,STAINED_CLAY:15,30,STAINED_CLAY:7,30,null,30,quark:iron_plate:1,100)
Block(-8,5,-5,COBBLESTONE_STAIRS:2)
RandomBlock(-8,5,-4,rustic:iron_lattice,30,rustic:iron_lattice,30,biomesoplenty:leaves_2:7,30,quark:iron_plate_stairs:6,10,quark:iron_plate_stairs:0,10,quark:iron_plate_stairs:5,10,quark:iron_plate_stairs,10,quark:iron_plate_slab:8,10,quark:iron_plate_stairs:7,10,quark:iron_plate_stairs:1,10,quark:iron_plate_slab,10,quark:iron_plate_stairs:4,10,quark:iron_plate_stairs:2,10,rustic:iron_lattice,50,rustic:iron_lattice,50,biomesoplenty:leaves_2:7,100)
RandomBlock(-8,5,-3,rustic:iron_lattice,30,rustic:iron_lattice,30,biomesoplenty:leaves_2:7,30,quark:iron_plate_stairs:6,10,quark:iron_plate_stairs:0,10,quark:iron_plate_stairs:5,10,quark:iron_plate_stairs,10,quark:iron_plate_slab:8,10,quark:iron_plate_stairs:7,10,quark:iron_plate_stairs:1,10,quark:iron_plate_slab,10,quark:iron_plate_stairs:4,10,quark:iron_plate_stairs:2,10,rustic:iron_lattice,50,rustic:iron_lattice,50,biomesoplenty:leaves_2:7,100)
RandomBlock(-8,5,-2,rustic:iron_lattice,30,rustic:iron_lattice,30,biomesoplenty:leaves_2:7,30,quark:iron_plate_stairs:6,10,quark:iron_plate_stairs:0,10,quark:iron_plate_stairs:5,10,quark:iron_plate_stairs,10,quark:iron_plate_slab:8,10,quark:iron_plate_stairs:7,10,quark:iron_plate_stairs:1,10,quark:iron_plate_slab,10,quark:iron_plate_stairs:4,10,quark:iron_plate_stairs:2,10,rustic:iron_lattice,50,rustic:iron_lattice,50,biomesoplenty:leaves_2:7,100)
RandomBlock(-8,5,-1,quark:iron_plate:1,70,STAINED_CLAY:15,30,STAINED_CLAY:7,30,null,30,quark:iron_plate:1,100)
RandomBlock(-8,5,0,quark:iron_plate:1,70,STAINED_CLAY:15,30,STAINED_CLAY:7,30,null,30,quark:iron_plate:1,100)
RandomBlock(-8,5,1,quark:iron_plate:1,70,STAINED_CLAY:15,30,STAINED_CLAY:7,30,null,30,quark:iron_plate:1,100)
RandomBlock(-8,5,2,quark:iron_plate:1,70,STAINED_CLAY:15,30,STAINED_CLAY:7,30,null,30,quark:iron_plate:1,100)
Block(-8,5,3,COBBLESTONE_STAIRS:3)
Block(-7,3,-5,COBBLESTONE_STAIRS:6)
RandomBlock(-7,3,-4,quark:iron_plate:1,70,STAINED_CLAY:15,30,STAINED_CLAY:7,30,null,30,quark:iron_plate:1,100)
Block(-7,3,-3,COBBLESTONE_STAIRS:5)
Block(-7,3,-2,COBBLESTONE_STAIRS:5)
Block(-7,3,-1,COBBLESTONE_STAIRS:5)
Block(-7,3,0,COBBLESTONE_STAIRS:5)
Block(-7,3,1,COBBLESTONE_STAIRS:5)
Block(-7,3,2,COBBLESTONE_STAIRS:5)
Block(-7,3,3,COBBLESTONE_STAIRS:5)
RandomBlock(-7,4,-5,quark:iron_plate:1,70,STAINED_CLAY:15,30,STAINED_CLAY:7,30,null,30,quark:iron_plate:1,100)
Block(-7,4,-4,srparasites:deadblood)
RandomBlock(-7,4,-3,quark:iron_plate:1,70,STAINED_CLAY:15,30,STAINED_CLAY:7,30,null,30,quark:iron_plate:1,100)
RandomBlock(-7,4,-2,quark:iron_plate:1,70,STAINED_CLAY:15,30,STAINED_CLAY:7,30,null,30,quark:iron_plate:1,100)
RandomBlock(-7,4,-1,quark:iron_plate:1,70,STAINED_CLAY:15,30,STAINED_CLAY:7,30,null,30,quark:iron_plate:1,100)
RandomBlock(-7,4,0,quark:iron_plate:1,70,STAINED_CLAY:15,30,STAINED_CLAY:7,30,null,30,quark:iron_plate:1,100)
RandomBlock(-7,4,1,quark:iron_plate:1,70,STAINED_CLAY:15,30,STAINED_CLAY:7,30,null,30,quark:iron_plate:1,100)
RandomBlock(-7,4,2,quark:iron_plate:1,70,STAINED_CLAY:15,30,STAINED_CLAY:7,30,null,30,quark:iron_plate:1,100)
RandomBlock(-7,4,3,quark:iron_plate:1,70,STAINED_CLAY:15,30,STAINED_CLAY:7,30,null,30,quark:iron_plate:1,100)
Block(-7,5,-5,COBBLESTONE_STAIRS:2)
RandomBlock(-7,5,-4,quark:iron_plate:1,70,STAINED_CLAY:15,30,STAINED_CLAY:7,30,null,30,quark:iron_plate:1,100)
Block(-7,5,-3,COBBLESTONE_STAIRS:3)
Block(-7,5,-2,COBBLESTONE_STAIRS:1)
Block(-7,5,-1,COBBLESTONE_STAIRS:1)
Block(-7,5,0,COBBLESTONE_STAIRS:1)
Block(-7,5,1,COBBLESTONE_STAIRS:1)
Block(-7,5,2,COBBLESTONE_STAIRS:1)
Block(-7,5,3,COBBLESTONE_STAIRS:3)
Block(-6,0,-1,quark:limestone)
Block(-6,0,0,quark:limestone)
Block(-6,0,1,quark:limestone)
Block(-6,0,2,quark:limestone)
Block(-6,0,3,quark:limestone)
Block(-6,0,4,quark:limestone)
Block(-6,0,5,quark:limestone)
Block(-6,1,-1,COBBLESTONE_STAIRS:0)
Block(-6,1,0,COBBLESTONE_STAIRS:0)
Block(-6,1,1,COBBLESTONE_STAIRS:0)
Block(-6,1,2,COBBLESTONE_STAIRS:0)
Block(-6,1,3,COBBLESTONE_STAIRS:0)
Block(-6,1,4,COBBLESTONE_STAIRS:0)
Block(-6,1,5,COBBLESTONE_STAIRS:3)
Block(-6,3,-5,COBBLESTONE_STAIRS:6)
RandomBlock(-6,3,-4,quark:iron_plate:1,70,STAINED_CLAY:15,30,STAINED_CLAY:7,30,null,30,quark:iron_plate:1,100)
Block(-6,3,-3,COBBLESTONE_STAIRS:7)
RandomBlock(-6,4,-5,quark:iron_plate:1,70,STAINED_CLAY:15,30,STAINED_CLAY:7,30,null,30,quark:iron_plate:1,100)
Block(-6,4,-4,srparasites:deadblood)
RandomBlock(-6,4,-3,quark:iron_plate:1,70,STAINED_CLAY:15,30,STAINED_CLAY:7,30,null,30,quark:iron_plate:1,100)
Block(-6,5,-5,COBBLESTONE_STAIRS:2)
RandomBlock(-6,5,-4,quark:iron_plate:1,70,STAINED_CLAY:15,30,STAINED_CLAY:7,30,null,30,quark:iron_plate:1,100)
Block(-6,5,-3,COBBLESTONE_STAIRS:3)
Block(-5,0,-1,quark:limestone)
RandomBlock(-5,0,0,quark:iron_plate:1,70,STAINED_CLAY:15,30,STAINED_CLAY:7,30,null,30,quark:iron_plate:1,100)
Block(-5,0,1,quark:world_stone_pavement:2)
RandomBlock(-5,0,2,quark:iron_plate:1,70,STAINED_CLAY:15,30,STAINED_CLAY:7,30,null,30,quark:iron_plate:1,100)
Block(-5,0,3,quark:world_stone_pavement:2)
RandomBlock(-5,0,4,quark:iron_plate:1,70,STAINED_CLAY:15,30,STAINED_CLAY:7,30,null,30,quark:iron_plate:1,100)
Block(-5,0,5,quark:limestone)
Block(-5,1,-1,COBBLESTONE_STAIRS:2)
RandomBlock(-5,1,0,quark:iron_plate:1,70,STAINED_CLAY:15,30,STAINED_CLAY:7,30,null,30,quark:iron_plate:1,100)
Block(-5,1,1,quark:world_stone_pavement:2)
RandomBlock(-5,1,2,quark:iron_plate:1,70,STAINED_CLAY:15,30,STAINED_CLAY:7,30,null,30,quark:iron_plate:1,100)
Block(-5,1,3,quark:world_stone_pavement:2)
RandomBlock(-5,1,4,quark:iron_plate:1,70,STAINED_CLAY:15,30,STAINED_CLAY:7,30,null,30,quark:iron_plate:1,100)
Block(-5,1,5,COBBLESTONE_STAIRS:3)
RandomBlock(-5,2,0,quark:iron_plate:1,70,STAINED_CLAY:15,30,STAINED_CLAY:7,30,null,30,quark:iron_plate:1,100)
Block(-5,2,1,quark:world_stone_pavement:2)
RandomBlock(-5,2,2,quark:iron_plate:1,70,STAINED_CLAY:15,30,STAINED_CLAY:7,30,null,30,quark:iron_plate:1,100)
Block(-5,2,3,quark:world_stone_pavement:2)
RandomBlock(-5,2,4,quark:iron_plate:1,70,STAINED_CLAY:15,30,STAINED_CLAY:7,30,null,30,quark:iron_plate:1,100)
Block(-5,3,-5,COBBLESTONE_STAIRS:6)
RandomBlock(-5,3,-4,quark:iron_plate:1,70,STAINED_CLAY:15,30,STAINED_CLAY:7,30,null,30,quark:iron_plate:1,100)
Block(-5,3,-3,COBBLESTONE_STAIRS:7)
RandomBlock(-5,3,0,quark:iron_plate:1,70,STAINED_CLAY:15,30,STAINED_CLAY:7,30,null,30,quark:iron_plate:1,100)
Block(-5,3,1,quark:world_stone_pavement:2)
RandomBlock(-5,3,2,quark:iron_plate:1,70,STAINED_CLAY:15,30,STAINED_CLAY:7,30,null,30,quark:iron_plate:1,100)
Block(-5,3,3,quark:world_stone_pavement:2)
RandomBlock(-5,3,4,quark:iron_plate:1,70,STAINED_CLAY:15,30,STAINED_CLAY:7,30,null,30,quark:iron_plate:1,100)
RandomBlock(-5,4,-5,quark:iron_plate:1,70,STAINED_CLAY:15,30,STAINED_CLAY:7,30,null,30,quark:iron_plate:1,100)
Block(-5,4,-4,srparasites:deadblood)
RandomBlock(-5,4,-3,quark:iron_plate:1,70,STAINED_CLAY:15,30,STAINED_CLAY:7,30,null,30,quark:iron_plate:1,100)
RandomBlock(-5,4,0,quark:iron_plate:1,70,STAINED_CLAY:15,30,STAINED_CLAY:7,30,null,30,quark:iron_plate:1,100)
Block(-5,4,1,quark:world_stone_pavement:2)
Block(-5,4,2,quark:world_stone_pavement:2)
Block(-5,4,3,quark:world_stone_pavement:2)
RandomBlock(-5,4,4,quark:iron_plate:1,70,STAINED_CLAY:15,30,STAINED_CLAY:7,30,null,30,quark:iron_plate:1,100)
Block(-5,5,-5,COBBLESTONE_STAIRS:2)
RandomBlock(-5,5,-4,quark:iron_plate:1,70,STAINED_CLAY:15,30,STAINED_CLAY:7,30,null,30,quark:iron_plate:1,100)
Block(-5,5,-3,COBBLESTONE_STAIRS:3)
RandomBlock(-5,5,0,quark:iron_plate:1,70,STAINED_CLAY:15,30,STAINED_CLAY:7,30,null,30,quark:iron_plate:1,100)
RandomBlock(-5,5,1,quark:iron_plate:1,70,STAINED_CLAY:15,30,STAINED_CLAY:7,30,null,30,quark:iron_plate:1,100)
RandomBlock(-5,5,2,quark:iron_plate:1,70,STAINED_CLAY:15,30,STAINED_CLAY:7,30,null,30,quark:iron_plate:1,100)
RandomBlock(-5,5,3,quark:iron_plate:1,70,STAINED_CLAY:15,30,STAINED_CLAY:7,30,null,30,quark:iron_plate:1,100)
RandomBlock(-5,5,4,quark:iron_plate:1,70,STAINED_CLAY:15,30,STAINED_CLAY:7,30,null,30,quark:iron_plate:1,100)
Block(-5,6,0,rustic:iron_lattice:0)
Block(-5,6,1,rustic:iron_lattice:0)
Block(-5,6,2,rustic:iron_lattice:0)
Block(-5,6,3,rustic:iron_lattice:0)
Block(-5,6,4,rustic:iron_lattice:0)
Block(-4,0,-1,quark:limestone)
RandomBlock(-4,0,0,quark:iron_plate:1,70,STAINED_CLAY:15,30,STAINED_CLAY:7,30,null,30,quark:iron_plate:1,100)
RandomBlock(-4,0,1,quark:iron_plate:1,70,STAINED_CLAY:15,30,STAINED_CLAY:7,30,null,30,quark:iron_plate:1,100)
RandomBlock(-4,0,2,quark:iron_plate:1,70,STAINED_CLAY:15,30,STAINED_CLAY:7,30,null,30,quark:iron_plate:1,100)
RandomBlock(-4,0,3,quark:iron_plate:1,70,STAINED_CLAY:15,30,STAINED_CLAY:7,30,null,30,quark:iron_plate:1,100)
Block(-4,0,4,quark:world_stone_pavement:2)
Block(-4,0,5,quark:limestone)
Block(-4,1,-1,COBBLESTONE_STAIRS:2)
RandomBlock(-4,1,0,quark:iron_plate:1,70,STAINED_CLAY:15,30,STAINED_CLAY:7,30,null,30,quark:iron_plate:1,100)
Block(-4,1,1,srparasites:deadblood)
Block(-4,1,2,srparasites:deadblood)
Block(-4,1,3,srparasites:deadblood)
Block(-4,1,4,quark:world_stone_pavement:2)
Block(-4,1,5,COBBLESTONE_STAIRS:3)
RandomBlock(-4,2,0,quark:iron_plate:1,70,STAINED_CLAY:15,30,STAINED_CLAY:7,30,null,30,quark:iron_plate:1,100)
Block(-4,2,4,quark:world_stone_pavement:2)
Block(-4,3,-5,COBBLESTONE_STAIRS:6)
RandomBlock(-4,3,-4,quark:iron_plate:1,70,STAINED_CLAY:15,30,STAINED_CLAY:7,30,null,30,quark:iron_plate:1,100)
Block(-4,3,-3,COBBLESTONE_STAIRS:7)
Block(-4,3,-2,COBBLESTONE_STAIRS:4)
Block(-4,3,-1,COBBLESTONE_STAIRS:4)
RandomBlock(-4,3,0,quark:iron_plate:1,70,STAINED_CLAY:15,30,STAINED_CLAY:7,30,null,30,quark:iron_plate:1,100)
Block(-4,3,4,quark:world_stone_pavement:2)
RandomBlock(-4,4,-5,quark:iron_plate:1,70,STAINED_CLAY:15,30,STAINED_CLAY:7,30,null,30,quark:iron_plate:1,100)
Block(-4,4,-4,srparasites:deadblood)
RandomBlock(-4,4,-3,quark:iron_plate:1,70,STAINED_CLAY:15,30,STAINED_CLAY:7,30,null,30,quark:iron_plate:1,100)
RandomBlock(-4,4,-2,quark:iron_plate:1,70,STAINED_CLAY:15,30,STAINED_CLAY:7,30,null,30,quark:iron_plate:1,100)
RandomBlock(-4,4,-1,quark:iron_plate:1,70,STAINED_CLAY:15,30,STAINED_CLAY:7,30,null,30,quark:iron_plate:1,100)
RandomBlock(-4,4,0,quark:iron_plate:1,70,STAINED_CLAY:15,30,STAINED_CLAY:7,30,null,30,quark:iron_plate:1,100)
Block(-4,4,4,quark:world_stone_pavement:2)
Block(-4,5,-5,COBBLESTONE_STAIRS:2)
RandomBlock(-4,5,-4,rustic:iron_lattice,30,rustic:iron_lattice,30,biomesoplenty:leaves_2:7,30,quark:iron_plate_stairs:6,10,quark:iron_plate_stairs:0,10,quark:iron_plate_stairs:5,10,quark:iron_plate_stairs,10,quark:iron_plate_slab:8,10,quark:iron_plate_stairs:7,10,quark:iron_plate_stairs:1,10,quark:iron_plate_slab,10,quark:iron_plate_stairs:4,10,quark:iron_plate_stairs:2,10,rustic:iron_lattice,50,rustic:iron_lattice,50,biomesoplenty:leaves_2:7,100)
Block(-4,5,-3,COBBLESTONE_STAIRS:3)
Block(-4,5,-2,COBBLESTONE_STAIRS:0)
Block(-4,5,-1,COBBLESTONE_STAIRS:0)
RandomBlock(-4,5,0,quark:iron_plate:1,70,STAINED_CLAY:15,30,STAINED_CLAY:7,30,null,30,quark:iron_plate:1,100)
Block(-4,5,1,quark:framed_glass)
Block(-4,5,2,quark:framed_glass)
Block(-4,5,3,quark:framed_glass)
RandomBlock(-4,5,4,quark:iron_plate:1,70,STAINED_CLAY:15,30,STAINED_CLAY:7,30,null,30,quark:iron_plate:1,100)
Block(-4,6,0,rustic:iron_lattice:0)
Block(-4,6,4,rustic:iron_lattice:0)
Block(-3,0,-1,quark:limestone)
RandomBlock(-3,0,0,quark:iron_plate:1,70,STAINED_CLAY:15,30,STAINED_CLAY:7,30,null,30,quark:iron_plate:1,100)
RandomBlock(-3,0,1,quark:iron_plate:1,70,STAINED_CLAY:15,30,STAINED_CLAY:7,30,null,30,quark:iron_plate:1,100)
RandomBlock(-3,0,2,quark:iron_plate:1,70,STAINED_CLAY:15,30,STAINED_CLAY:7,30,null,30,quark:iron_plate:1,100)
RandomBlock(-3,0,3,quark:iron_plate:1,70,STAINED_CLAY:15,30,STAINED_CLAY:7,30,null,30,quark:iron_plate:1,100)
RandomBlock(-3,0,4,quark:iron_plate:1,70,STAINED_CLAY:15,30,STAINED_CLAY:7,30,null,30,quark:iron_plate:1,100)
Block(-3,0,5,quark:limestone)
Block(-3,1,-1,COBBLESTONE_STAIRS:2)
RandomBlock(-3,1,0,quark:iron_plate:1,70,STAINED_CLAY:15,30,STAINED_CLAY:7,30,null,30,quark:iron_plate:1,100)
Block(-3,1,1,srparasites:deadblood)
Block(-3,1,2,srparasites:deadblood)
Block(-3,1,3,srparasites:deadblood)
RandomBlock(-3,1,4,quark:iron_plate:1,70,STAINED_CLAY:15,30,STAINED_CLAY:7,30,null,30,quark:iron_plate:1,100)
Block(-3,1,5,COBBLESTONE_STAIRS:3)
RandomBlock(-3,2,0,quark:iron_plate:1,70,STAINED_CLAY:15,30,STAINED_CLAY:7,30,null,30,quark:iron_plate:1,100)
Block(-3,2,1,srparasites:deadblood:1)
RandomBlock(-3,2,4,quark:iron_plate:1,70,STAINED_CLAY:15,30,STAINED_CLAY:7,30,null,30,quark:iron_plate:1,100)
Block(-3,3,-5,COBBLESTONE_STAIRS:6)
RandomBlock(-3,3,-4,quark:iron_plate:1,70,STAINED_CLAY:15,30,STAINED_CLAY:7,30,null,30,quark:iron_plate:1,100)
RandomBlock(-3,3,-3,quark:iron_plate:1,70,STAINED_CLAY:15,30,STAINED_CLAY:7,30,null,30,quark:iron_plate:1,100)
RandomBlock(-3,3,-2,quark:iron_plate:1,70,STAINED_CLAY:15,30,STAINED_CLAY:7,30,null,30,quark:iron_plate:1,100)
RandomBlock(-3,3,-1,quark:iron_plate:1,70,STAINED_CLAY:15,30,STAINED_CLAY:7,30,null,30,quark:iron_plate:1,100)
RandomBlock(-3,3,0,quark:iron_plate:1,70,STAINED_CLAY:15,30,STAINED_CLAY:7,30,null,30,quark:iron_plate:1,100)
Block(-3,3,1,srparasites:deadblood:1)
RandomBlock(-3,3,4,quark:iron_plate:1,70,STAINED_CLAY:15,30,STAINED_CLAY:7,30,null,30,quark:iron_plate:1,100)
RandomBlock(-3,4,-5,quark:iron_plate:1,70,STAINED_CLAY:15,30,STAINED_CLAY:7,30,null,30,quark:iron_plate:1,100)
Block(-3,4,-4,srparasites:deadblood)
Block(-3,4,-3,srparasites:deadblood)
Block(-3,4,-2,srparasites:deadblood)
Block(-3,4,-1,srparasites:deadblood)
Block(-3,4,0,srparasites:deadblood)
Block(-3,4,1,srparasites:deadblood:1)
Block(-3,4,4,quark:world_stone_pavement:2)
Block(-3,5,-5,COBBLESTONE_STAIRS:2)
RandomBlock(-3,5,-4,rustic:iron_lattice,30,rustic:iron_lattice,30,biomesoplenty:leaves_2:7,30,quark:iron_plate_stairs:6,10,quark:iron_plate_stairs:0,10,quark:iron_plate_stairs:5,10,quark:iron_plate_stairs,10,quark:iron_plate_slab:8,10,quark:iron_plate_stairs:7,10,quark:iron_plate_stairs:1,10,quark:iron_plate_slab,10,quark:iron_plate_stairs:4,10,quark:iron_plate_stairs:2,10,rustic:iron_lattice,50,rustic:iron_lattice,50,biomesoplenty:leaves_2:7,100)
RandomBlock(-3,5,-3,rustic:iron_lattice,30,rustic:iron_lattice,30,biomesoplenty:leaves_2:7,30,quark:iron_plate_stairs:6,10,quark:iron_plate_stairs:0,10,quark:iron_plate_stairs:5,10,quark:iron_plate_stairs,10,quark:iron_plate_slab:8,10,quark:iron_plate_stairs:7,10,quark:iron_plate_stairs:1,10,quark:iron_plate_slab,10,quark:iron_plate_stairs:4,10,quark:iron_plate_stairs:2,10,rustic:iron_lattice,50,rustic:iron_lattice,50,biomesoplenty:leaves_2:7,100)
RandomBlock(-3,5,-2,quark:iron_plate:1,70,STAINED_CLAY:15,30,STAINED_CLAY:7,30,null,30,quark:iron_plate:1,100)
RandomBlock(-3,5,-1,quark:iron_plate:1,70,STAINED_CLAY:15,30,STAINED_CLAY:7,30,null,30,quark:iron_plate:1,100)
RandomBlock(-3,5,0,quark:iron_plate:1,70,STAINED_CLAY:15,30,STAINED_CLAY:7,30,null,30,quark:iron_plate:1,100)
Block(-3,5,1,quark:framed_glass)
Block(-3,5,2,quark:framed_glass)
Block(-3,5,3,quark:framed_glass)
RandomBlock(-3,5,4,quark:iron_plate:1,70,STAINED_CLAY:15,30,STAINED_CLAY:7,30,null,30,quark:iron_plate:1,100)
Block(-3,6,0,rustic:iron_lattice:0)
Block(-3,6,4,rustic:iron_lattice:0)
Block(-2,0,-1,quark:limestone)
RandomBlock(-2,0,0,quark:iron_plate:1,70,STAINED_CLAY:15,30,STAINED_CLAY:7,30,null,30,quark:iron_plate:1,100)
RandomBlock(-2,0,1,quark:iron_plate:1,70,STAINED_CLAY:15,30,STAINED_CLAY:7,30,null,30,quark:iron_plate:1,100)
RandomBlock(-2,0,2,quark:iron_plate:1,70,STAINED_CLAY:15,30,STAINED_CLAY:7,30,null,30,quark:iron_plate:1,100)
RandomBlock(-2,0,3,quark:iron_plate:1,70,STAINED_CLAY:15,30,STAINED_CLAY:7,30,null,30,quark:iron_plate:1,100)
Block(-2,0,4,quark:world_stone_pavement:2)
Block(-2,0,5,quark:limestone)
Block(-2,1,-1,COBBLESTONE_STAIRS:2)
RandomBlock(-2,1,0,quark:iron_plate:1,70,STAINED_CLAY:15,30,STAINED_CLAY:7,30,null,30,quark:iron_plate:1,100)
Block(-2,1,1,srparasites:deadblood)
Block(-2,1,2,srparasites:deadblood)
Block(-2,1,3,srparasites:deadblood)
Block(-2,1,4,quark:world_stone_pavement:2)
Block(-2,1,5,COBBLESTONE_STAIRS:3)
RandomBlock(-2,2,0,quark:iron_plate:1,70,STAINED_CLAY:15,30,STAINED_CLAY:7,30,null,30,quark:iron_plate:1,100)
Block(-2,2,4,quark:world_stone_pavement:2)
Block(-2,3,-5,COBBLESTONE_STAIRS:6)
RandomBlock(-2,3,-4,quark:iron_plate:1,70,STAINED_CLAY:15,30,STAINED_CLAY:7,30,null,30,quark:iron_plate:1,100)
Block(-2,3,-3,COBBLESTONE_STAIRS:7)
Block(-2,3,-2,COBBLESTONE_STAIRS:5)
Block(-2,3,-1,COBBLESTONE_STAIRS:5)
RandomBlock(-2,3,0,quark:iron_plate:1,70,STAINED_CLAY:15,30,STAINED_CLAY:7,30,null,30,quark:iron_plate:1,100)
Block(-2,3,4,quark:world_stone_pavement:2)
RandomBlock(-2,4,-5,quark:iron_plate:1,70,STAINED_CLAY:15,30,STAINED_CLAY:7,30,null,30,quark:iron_plate:1,100)
Block(-2,4,-4,srparasites:deadblood)
RandomBlock(-2,4,-3,quark:iron_plate:1,70,STAINED_CLAY:15,30,STAINED_CLAY:7,30,null,30,quark:iron_plate:1,100)
RandomBlock(-2,4,-2,quark:iron_plate:1,70,STAINED_CLAY:15,30,STAINED_CLAY:7,30,null,30,quark:iron_plate:1,100)
RandomBlock(-2,4,-1,quark:iron_plate:1,70,STAINED_CLAY:15,30,STAINED_CLAY:7,30,null,30,quark:iron_plate:1,100)
RandomBlock(-2,4,0,quark:iron_plate:1,70,STAINED_CLAY:15,30,STAINED_CLAY:7,30,null,30,quark:iron_plate:1,100)
Block(-2,4,4,quark:world_stone_pavement:2)
Block(-2,5,-5,COBBLESTONE_STAIRS:2)
RandomBlock(-2,5,-4,rustic:iron_lattice,30,rustic:iron_lattice,30,biomesoplenty:leaves_2:7,30,quark:iron_plate_stairs:6,10,quark:iron_plate_stairs:0,10,quark:iron_plate_stairs:5,10,quark:iron_plate_stairs,10,quark:iron_plate_slab:8,10,quark:iron_plate_stairs:7,10,quark:iron_plate_stairs:1,10,quark:iron_plate_slab,10,quark:iron_plate_stairs:4,10,quark:iron_plate_stairs:2,10,rustic:iron_lattice,50,rustic:iron_lattice,50,biomesoplenty:leaves_2:7,100)
Block(-2,5,-3,COBBLESTONE_STAIRS:3)
Block(-2,5,-2,COBBLESTONE_STAIRS:1)
Block(-2,5,-1,COBBLESTONE_STAIRS:1)
RandomBlock(-2,5,0,quark:iron_plate:1,70,STAINED_CLAY:15,30,STAINED_CLAY:7,30,null,30,quark:iron_plate:1,100)
Block(-2,5,1,quark:framed_glass)
Block(-2,5,2,quark:framed_glass)
Block(-2,5,3,quark:framed_glass)
RandomBlock(-2,5,4,rustic:iron_lattice,30,rustic:iron_lattice,30,biomesoplenty:leaves_2:7,30,quark:iron_plate_stairs:6,10,quark:iron_plate_stairs:0,10,quark:iron_plate_stairs:5,10,quark:iron_plate_stairs,10,quark:iron_plate_slab:8,10,quark:iron_plate_stairs:7,10,quark:iron_plate_stairs:1,10,quark:iron_plate_slab,10,quark:iron_plate_stairs:4,10,quark:iron_plate_stairs:2,10,rustic:iron_lattice,50,rustic:iron_lattice,50,biomesoplenty:leaves_2:7,100)
Block(-2,6,0,rustic:iron_lattice:0)
Block(-2,6,4,rustic:iron_lattice:0)
Block(-1,0,-1,quark:limestone)
RandomBlock(-1,0,0,quark:iron_plate:1,70,STAINED_CLAY:15,30,STAINED_CLAY:7,30,null,30,quark:iron_plate:1,100)
Block(-1,0,1,quark:world_stone_pavement:2)
RandomBlock(-1,0,2,quark:iron_plate:1,70,STAINED_CLAY:15,30,STAINED_CLAY:7,30,null,30,quark:iron_plate:1,100)
Block(-1,0,3,quark:world_stone_pavement:2)
RandomBlock(-1,0,4,quark:iron_plate:1,70,STAINED_CLAY:15,30,STAINED_CLAY:7,30,null,30,quark:iron_plate:1,100)
Block(-1,0,5,quark:limestone)
Block(-1,1,-1,COBBLESTONE_STAIRS:2)
RandomBlock(-1,1,0,quark:iron_plate:1,70,STAINED_CLAY:15,30,STAINED_CLAY:7,30,null,30,quark:iron_plate:1,100)
Block(-1,1,1,quark:world_stone_pavement:2)
RandomBlock(-1,1,2,quark:iron_plate:1,70,STAINED_CLAY:15,30,STAINED_CLAY:7,30,null,30,quark:iron_plate:1,100)
Block(-1,1,3,quark:world_stone_pavement:2)
RandomBlock(-1,1,4,quark:iron_plate:1,70,STAINED_CLAY:15,30,STAINED_CLAY:7,30,null,30,quark:iron_plate:1,100)
Block(-1,1,5,COBBLESTONE_STAIRS:3)
RandomBlock(-1,2,0,quark:iron_plate:1,70,STAINED_CLAY:15,30,STAINED_CLAY:7,30,null,30,quark:iron_plate:1,100)
Block(-1,2,1,quark:world_stone_pavement:2)
RandomBlock(-1,2,2,quark:iron_plate:1,70,STAINED_CLAY:15,30,STAINED_CLAY:7,30,null,30,quark:iron_plate:1,100)
Block(-1,2,3,quark:world_stone_pavement:2)
RandomBlock(-1,2,4,quark:iron_plate:1,70,STAINED_CLAY:15,30,STAINED_CLAY:7,30,null,30,quark:iron_plate:1,100)
Block(-1,3,-5,COBBLESTONE_STAIRS:6)
RandomBlock(-1,3,-4,quark:iron_plate:1,70,STAINED_CLAY:15,30,STAINED_CLAY:7,30,null,30,quark:iron_plate:1,100)
Block(-1,3,-3,COBBLESTONE_STAIRS:7)
RandomBlock(-1,3,0,quark:iron_plate:1,70,STAINED_CLAY:15,30,STAINED_CLAY:7,30,null,30,quark:iron_plate:1,100)
Block(-1,3,1,quark:world_stone_pavement:2)
RandomBlock(-1,3,2,quark:iron_plate:1,70,STAINED_CLAY:15,30,STAINED_CLAY:7,30,null,30,quark:iron_plate:1,100)
Block(-1,3,3,quark:world_stone_pavement:2)
RandomBlock(-1,3,4,quark:iron_plate:1,70,STAINED_CLAY:15,30,STAINED_CLAY:7,30,null,30,quark:iron_plate:1,100)
RandomBlock(-1,4,-5,quark:iron_plate:1,70,STAINED_CLAY:15,30,STAINED_CLAY:7,30,null,30,quark:iron_plate:1,100)
Block(-1,4,-4,srparasites:deadblood)
RandomBlock(-1,4,-3,quark:iron_plate:1,70,STAINED_CLAY:15,30,STAINED_CLAY:7,30,null,30,quark:iron_plate:1,100)
RandomBlock(-1,4,0,quark:iron_plate:1,70,STAINED_CLAY:15,30,STAINED_CLAY:7,30,null,30,quark:iron_plate:1,100)
Block(-1,4,1,quark:world_stone_pavement:2)
Block(-1,4,2,quark:world_stone_pavement:2)
Block(-1,4,3,quark:world_stone_pavement:2)
RandomBlock(-1,4,4,rustic:iron_lattice,30,rustic:iron_lattice,30,biomesoplenty:leaves_2:7,30,quark:iron_plate_stairs:6,10,quark:iron_plate_stairs:0,10,quark:iron_plate_stairs:5,10,quark:iron_plate_stairs,10,quark:iron_plate_slab:8,10,quark:iron_plate_stairs:7,10,quark:iron_plate_stairs:1,10,quark:iron_plate_slab,10,quark:iron_plate_stairs:4,10,quark:iron_plate_stairs:2,10,rustic:iron_lattice,50,rustic:iron_lattice,50,biomesoplenty:leaves_2:7,100)
Block(-1,5,-5,COBBLESTONE_STAIRS:2)
RandomBlock(-1,5,-4,quark:iron_plate:1,70,STAINED_CLAY:15,30,STAINED_CLAY:7,30,null,30,quark:iron_plate:1,100)
Block(-1,5,-3,COBBLESTONE_STAIRS:3)
RandomBlock(-1,5,0,quark:iron_plate:1,70,STAINED_CLAY:15,30,STAINED_CLAY:7,30,null,30,quark:iron_plate:1,100)
RandomBlock(-1,5,1,quark:iron_plate:1,70,STAINED_CLAY:15,30,STAINED_CLAY:7,30,null,30,quark:iron_plate:1,100)
RandomBlock(-1,5,2,quark:iron_plate:1,70,STAINED_CLAY:15,30,STAINED_CLAY:7,30,null,30,quark:iron_plate:1,100)
RandomBlock(-1,5,3,rustic:iron_lattice,30,rustic:iron_lattice,30,biomesoplenty:leaves_2:7,30,quark:iron_plate_stairs:6,10,quark:iron_plate_stairs:0,10,quark:iron_plate_stairs:5,10,quark:iron_plate_stairs,10,quark:iron_plate_slab:8,10,quark:iron_plate_stairs:7,10,quark:iron_plate_stairs:1,10,quark:iron_plate_slab,10,quark:iron_plate_stairs:4,10,quark:iron_plate_stairs:2,10,rustic:iron_lattice,50,rustic:iron_lattice,50,biomesoplenty:leaves_2:7,100)
RandomBlock(-1,5,4,rustic:iron_lattice,30,rustic:iron_lattice,30,biomesoplenty:leaves_2:7,30,quark:iron_plate_stairs:6,10,quark:iron_plate_stairs:0,10,quark:iron_plate_stairs:5,10,quark:iron_plate_stairs,10,quark:iron_plate_slab:8,10,quark:iron_plate_stairs:7,10,quark:iron_plate_stairs:1,10,quark:iron_plate_slab,10,quark:iron_plate_stairs:4,10,quark:iron_plate_stairs:2,10,rustic:iron_lattice,50,rustic:iron_lattice,50,biomesoplenty:leaves_2:7,100)
Block(-1,6,0,rustic:iron_lattice:0)
Block(-1,6,1,rustic:iron_lattice:0)
Block(-1,6,2,rustic:iron_lattice:0)
Block(-1,6,3,rustic:iron_lattice:0)
Block(-1,6,4,rustic:iron_lattice:0)
Block(0,0,-1,quark:limestone)
Block(0,0,0,quark:limestone)
Block(0,0,1,quark:limestone)
Block(0,0,2,quark:limestone)
Block(0,0,3,quark:limestone)
Block(0,0,4,quark:limestone)
Block(0,0,5,quark:limestone)
Block(0,1,-1,COBBLESTONE_STAIRS:2)
Block(0,1,0,quark:limestone)
Block(0,1,1,quark:limestone)
Block(0,1,2,quark:limestone)
Block(0,1,3,quark:limestone)
Block(0,1,4,quark:limestone)
Block(0,1,5,COBBLESTONE_STAIRS:3)
Block(0,3,-5,COBBLESTONE_STAIRS:6)
RandomBlock(0,3,-4,quark:iron_plate:1,70,STAINED_CLAY:15,30,STAINED_CLAY:7,30,null,30,quark:iron_plate:1,100)
Block(0,3,-3,COBBLESTONE_STAIRS:7)
RandomBlock(0,4,-5,quark:iron_plate:1,70,STAINED_CLAY:15,30,STAINED_CLAY:7,30,null,30,quark:iron_plate:1,100)
Block(0,4,-4,srparasites:deadblood)
RandomBlock(0,4,-3,quark:iron_plate:1,70,STAINED_CLAY:15,30,STAINED_CLAY:7,30,null,30,quark:iron_plate:1,100)
Block(0,5,-5,COBBLESTONE_STAIRS:2)
RandomBlock(0,5,-4,quark:iron_plate:1,70,STAINED_CLAY:15,30,STAINED_CLAY:7,30,null,30,quark:iron_plate:1,100)
Block(0,5,-3,COBBLESTONE_STAIRS:3)
Block(1,0,-1,quark:limestone)
RandomBlock(1,0,0,quark:iron_plate:1,70,STAINED_CLAY:15,30,STAINED_CLAY:7,30,null,30,quark:iron_plate:1,100)
Block(1,0,1,quark:world_stone_pavement:2)
RandomBlock(1,0,2,quark:iron_plate:1,70,STAINED_CLAY:15,30,STAINED_CLAY:7,30,null,30,quark:iron_plate:1,100)
Block(1,0,3,quark:world_stone_pavement:2)
RandomBlock(1,0,4,quark:iron_plate:1,70,STAINED_CLAY:15,30,STAINED_CLAY:7,30,null,30,quark:iron_plate:1,100)
Block(1,0,5,quark:limestone)
Block(1,1,-1,COBBLESTONE_STAIRS:2)
RandomBlock(1,1,0,quark:iron_plate:1,70,STAINED_CLAY:15,30,STAINED_CLAY:7,30,null,30,quark:iron_plate:1,100)
Block(1,1,1,quark:world_stone_pavement:2)
RandomBlock(1,1,2,quark:iron_plate:1,70,STAINED_CLAY:15,30,STAINED_CLAY:7,30,null,30,quark:iron_plate:1,100)
Block(1,1,3,quark:world_stone_pavement:2)
RandomBlock(1,1,4,quark:iron_plate:1,70,STAINED_CLAY:15,30,STAINED_CLAY:7,30,null,30,quark:iron_plate:1,100)
Block(1,1,5,COBBLESTONE_STAIRS:3)
RandomBlock(1,2,0,quark:iron_plate:1,70,STAINED_CLAY:15,30,STAINED_CLAY:7,30,null,30,quark:iron_plate:1,100)
Block(1,2,1,quark:world_stone_pavement:2)
RandomBlock(1,2,2,quark:iron_plate:1,70,STAINED_CLAY:15,30,STAINED_CLAY:7,30,null,30,quark:iron_plate:1,100)
Block(1,2,3,quark:world_stone_pavement:2)
RandomBlock(1,2,4,quark:iron_plate:1,70,STAINED_CLAY:15,30,STAINED_CLAY:7,30,null,30,quark:iron_plate:1,100)
Block(1,3,-5,COBBLESTONE_STAIRS:6)
RandomBlock(1,3,-4,quark:iron_plate:1,70,STAINED_CLAY:15,30,STAINED_CLAY:7,30,null,30,quark:iron_plate:1,100)
Block(1,3,-3,COBBLESTONE_STAIRS:7)
RandomBlock(1,3,0,quark:iron_plate:1,70,STAINED_CLAY:15,30,STAINED_CLAY:7,30,null,30,quark:iron_plate:1,100)
Block(1,3,1,quark:world_stone_pavement:2)
RandomBlock(1,3,2,quark:iron_plate:1,70,STAINED_CLAY:15,30,STAINED_CLAY:7,30,null,30,quark:iron_plate:1,100)
Block(1,3,3,quark:world_stone_pavement:2)
RandomBlock(1,3,4,quark:iron_plate:1,70,STAINED_CLAY:15,30,STAINED_CLAY:7,30,null,30,quark:iron_plate:1,100)
RandomBlock(1,4,-5,quark:iron_plate:1,70,STAINED_CLAY:15,30,STAINED_CLAY:7,30,null,30,quark:iron_plate:1,100)
Block(1,4,-4,srparasites:deadblood)
RandomBlock(1,4,-3,quark:iron_plate:1,70,STAINED_CLAY:15,30,STAINED_CLAY:7,30,null,30,quark:iron_plate:1,100)
RandomBlock(1,4,0,quark:iron_plate:1,70,STAINED_CLAY:15,30,STAINED_CLAY:7,30,null,30,quark:iron_plate:1,100)
Block(1,4,1,quark:world_stone_pavement:2)
Block(1,4,2,quark:world_stone_pavement:2)
Block(1,4,3,quark:world_stone_pavement:2)
RandomBlock(1,4,4,quark:iron_plate:1,70,STAINED_CLAY:15,30,STAINED_CLAY:7,30,null,30,quark:iron_plate:1,100)
Block(1,5,-5,COBBLESTONE_STAIRS:2)
RandomBlock(1,5,-4,quark:iron_plate:1,70,STAINED_CLAY:15,30,STAINED_CLAY:7,30,null,30,quark:iron_plate:1,100)
Block(1,5,-3,COBBLESTONE_STAIRS:3)
RandomBlock(1,5,0,quark:iron_plate:1,70,STAINED_CLAY:15,30,STAINED_CLAY:7,30,null,30,quark:iron_plate:1,100)
RandomBlock(1,5,1,quark:iron_plate:1,70,STAINED_CLAY:15,30,STAINED_CLAY:7,30,null,30,quark:iron_plate:1,100)
RandomBlock(1,5,2,quark:iron_plate:1,70,STAINED_CLAY:15,30,STAINED_CLAY:7,30,null,30,quark:iron_plate:1,100)
RandomBlock(1,5,3,quark:iron_plate:1,70,STAINED_CLAY:15,30,STAINED_CLAY:7,30,null,30,quark:iron_plate:1,100)
RandomBlock(1,5,4,quark:iron_plate:1,70,STAINED_CLAY:15,30,STAINED_CLAY:7,30,null,30,quark:iron_plate:1,100)
Block(1,6,0,rustic:iron_lattice:0)
Block(1,6,1,rustic:iron_lattice:0)
Block(1,6,2,rustic:iron_lattice:0)
Block(1,6,3,rustic:iron_lattice:0)
Block(1,6,4,rustic:iron_lattice:0)
Block(2,0,-1,quark:limestone)
RandomBlock(2,0,0,quark:iron_plate:1,70,STAINED_CLAY:15,30,STAINED_CLAY:7,30,null,30,quark:iron_plate:1,100)
RandomBlock(2,0,1,quark:iron_plate:1,70,STAINED_CLAY:15,30,STAINED_CLAY:7,30,null,30,quark:iron_plate:1,100)
RandomBlock(2,0,2,quark:iron_plate:1,70,STAINED_CLAY:15,30,STAINED_CLAY:7,30,null,30,quark:iron_plate:1,100)
RandomBlock(2,0,3,quark:iron_plate:1,70,STAINED_CLAY:15,30,STAINED_CLAY:7,30,null,30,quark:iron_plate:1,100)
Block(2,0,4,quark:world_stone_pavement:2)
Block(2,0,5,quark:limestone)
Block(2,1,-1,COBBLESTONE_STAIRS:2)
RandomBlock(2,1,0,quark:iron_plate:1,70,STAINED_CLAY:15,30,STAINED_CLAY:7,30,null,30,quark:iron_plate:1,100)
Block(2,1,1,srparasites:deadblood)
Block(2,1,2,srparasites:deadblood)
Block(2,1,3,srparasites:deadblood)
Block(2,1,4,quark:world_stone_pavement:2)
Block(2,1,5,COBBLESTONE_STAIRS:3)
RandomBlock(2,2,0,quark:iron_plate:1,70,STAINED_CLAY:15,30,STAINED_CLAY:7,30,null,30,quark:iron_plate:1,100)
Block(2,2,4,quark:world_stone_pavement:2)
Block(2,3,-5,COBBLESTONE_STAIRS:6)
RandomBlock(2,3,-4,quark:iron_plate:1,70,STAINED_CLAY:15,30,STAINED_CLAY:7,30,null,30,quark:iron_plate:1,100)
Block(2,3,-3,COBBLESTONE_STAIRS:7)
Block(2,3,-2,COBBLESTONE_STAIRS:4)
Block(2,3,-1,COBBLESTONE_STAIRS:4)
RandomBlock(2,3,0,quark:iron_plate:1,70,STAINED_CLAY:15,30,STAINED_CLAY:7,30,null,30,quark:iron_plate:1,100)
Block(2,3,4,quark:world_stone_pavement:2)
RandomBlock(2,4,-5,quark:iron_plate:1,70,STAINED_CLAY:15,30,STAINED_CLAY:7,30,null,30,quark:iron_plate:1,100)
Block(2,4,-4,srparasites:deadblood)
RandomBlock(2,4,-3,quark:iron_plate:1,70,STAINED_CLAY:15,30,STAINED_CLAY:7,30,null,30,quark:iron_plate:1,100)
RandomBlock(2,4,-2,quark:iron_plate:1,70,STAINED_CLAY:15,30,STAINED_CLAY:7,30,null,30,quark:iron_plate:1,100)
RandomBlock(2,4,-1,quark:iron_plate:1,70,STAINED_CLAY:15,30,STAINED_CLAY:7,30,null,30,quark:iron_plate:1,100)
RandomBlock(2,4,0,quark:iron_plate:1,70,STAINED_CLAY:15,30,STAINED_CLAY:7,30,null,30,quark:iron_plate:1,100)
Block(2,4,4,quark:world_stone_pavement:2)
Block(2,5,-5,COBBLESTONE_STAIRS:2)
RandomBlock(2,5,-4,quark:iron_plate:1,70,STAINED_CLAY:15,30,STAINED_CLAY:7,30,null,30,quark:iron_plate:1,100)
Block(2,5,-3,COBBLESTONE_STAIRS:3)
Block(2,5,-2,COBBLESTONE_STAIRS:0)
Block(2,5,-1,COBBLESTONE_STAIRS:0)
RandomBlock(2,5,0,quark:iron_plate:1,70,STAINED_CLAY:15,30,STAINED_CLAY:7,30,null,30,quark:iron_plate:1,100)
Block(2,5,1,quark:framed_glass)
Block(2,5,2,quark:framed_glass)
Block(2,5,3,quark:framed_glass)
RandomBlock(2,5,4,rustic:iron_lattice,30,rustic:iron_lattice,30,biomesoplenty:leaves_2:7,30,quark:iron_plate_stairs:6,10,quark:iron_plate_stairs:0,10,quark:iron_plate_stairs:5,10,quark:iron_plate_stairs,10,quark:iron_plate_slab:8,10,quark:iron_plate_stairs:7,10,quark:iron_plate_stairs:1,10,quark:iron_plate_slab,10,quark:iron_plate_stairs:4,10,quark:iron_plate_stairs:2,10,rustic:iron_lattice,50,rustic:iron_lattice,50,biomesoplenty:leaves_2:7,100)
Block(2,6,0,rustic:iron_lattice:0)
Block(2,6,4,rustic:iron_lattice:0)
Block(3,0,-1,quark:limestone)
RandomBlock(3,0,0,quark:iron_plate:1,70,STAINED_CLAY:15,30,STAINED_CLAY:7,30,null,30,quark:iron_plate:1,100)
RandomBlock(3,0,1,quark:iron_plate:1,70,STAINED_CLAY:15,30,STAINED_CLAY:7,30,null,30,quark:iron_plate:1,100)
RandomBlock(3,0,2,quark:iron_plate:1,70,STAINED_CLAY:15,30,STAINED_CLAY:7,30,null,30,quark:iron_plate:1,100)
RandomBlock(3,0,3,quark:iron_plate:1,70,STAINED_CLAY:15,30,STAINED_CLAY:7,30,null,30,quark:iron_plate:1,100)
RandomBlock(3,0,4,quark:iron_plate:1,70,STAINED_CLAY:15,30,STAINED_CLAY:7,30,null,30,quark:iron_plate:1,100)
Block(3,0,5,quark:limestone)
Block(3,1,-1,COBBLESTONE_STAIRS:2)
RandomBlock(3,1,0,quark:iron_plate:1,70,STAINED_CLAY:15,30,STAINED_CLAY:7,30,null,30,quark:iron_plate:1,100)
Block(3,1,1,srparasites:deadblood:1)
Block(3,1,2,srparasites:deadblood)
Block(3,1,3,srparasites:deadblood)
RandomBlock(3,1,4,quark:iron_plate:1,70,STAINED_CLAY:15,30,STAINED_CLAY:7,30,null,30,quark:iron_plate:1,100)
Block(3,1,5,COBBLESTONE_STAIRS:3)
RandomBlock(3,2,0,quark:iron_plate:1,70,STAINED_CLAY:15,30,STAINED_CLAY:7,30,null,30,quark:iron_plate:1,100)
Block(3,2,1,srparasites:deadblood:1)
RandomBlock(3,2,4,quark:iron_plate:1,70,STAINED_CLAY:15,30,STAINED_CLAY:7,30,null,30,quark:iron_plate:1,100)
Block(3,3,-5,COBBLESTONE_STAIRS:6)
RandomBlock(3,3,-4,quark:iron_plate:1,70,STAINED_CLAY:15,30,STAINED_CLAY:7,30,null,30,quark:iron_plate:1,100)
RandomBlock(3,3,-3,quark:iron_plate:1,70,STAINED_CLAY:15,30,STAINED_CLAY:7,30,null,30,quark:iron_plate:1,100)
RandomBlock(3,3,-2,quark:iron_plate:1,70,STAINED_CLAY:15,30,STAINED_CLAY:7,30,null,30,quark:iron_plate:1,100)
RandomBlock(3,3,-1,quark:iron_plate:1,70,STAINED_CLAY:15,30,STAINED_CLAY:7,30,null,30,quark:iron_plate:1,100)
RandomBlock(3,3,0,quark:iron_plate:1,70,STAINED_CLAY:15,30,STAINED_CLAY:7,30,null,30,quark:iron_plate:1,100)
Block(3,3,1,srparasites:deadblood:1)
RandomBlock(3,3,4,quark:iron_plate:1,70,STAINED_CLAY:15,30,STAINED_CLAY:7,30,null,30,quark:iron_plate:1,100)
RandomBlock(3,4,-5,quark:iron_plate:1,70,STAINED_CLAY:15,30,STAINED_CLAY:7,30,null,30,quark:iron_plate:1,100)
Block(3,4,-4,srparasites:deadblood)
Block(3,4,-3,srparasites:deadblood)
Block(3,4,-2,srparasites:deadblood)
Block(3,4,-1,srparasites:deadblood)
Block(3,4,0,srparasites:deadblood)
Block(3,4,1,srparasites:deadblood:1)
Block(3,4,4,quark:world_stone_pavement:2)
Block(3,5,-5,COBBLESTONE_STAIRS:2)
RandomBlock(3,5,-4,rustic:iron_lattice,30,rustic:iron_lattice,30,biomesoplenty:leaves_2:7,30,quark:iron_plate_stairs:6,10,quark:iron_plate_stairs:0,10,quark:iron_plate_stairs:5,10,quark:iron_plate_stairs,10,quark:iron_plate_slab:8,10,quark:iron_plate_stairs:7,10,quark:iron_plate_stairs:1,10,quark:iron_plate_slab,10,quark:iron_plate_stairs:4,10,quark:iron_plate_stairs:2,10,rustic:iron_lattice,50,rustic:iron_lattice,50,biomesoplenty:leaves_2:7,100)
RandomBlock(3,5,-3,rustic:iron_lattice,30,rustic:iron_lattice,30,biomesoplenty:leaves_2:7,30,quark:iron_plate_stairs:6,10,quark:iron_plate_stairs:0,10,quark:iron_plate_stairs:5,10,quark:iron_plate_stairs,10,quark:iron_plate_slab:8,10,quark:iron_plate_stairs:7,10,quark:iron_plate_stairs:1,10,quark:iron_plate_slab,10,quark:iron_plate_stairs:4,10,quark:iron_plate_stairs:2,10,rustic:iron_lattice,50,rustic:iron_lattice,50,biomesoplenty:leaves_2:7,100)
RandomBlock(3,5,-2,rustic:iron_lattice,30,rustic:iron_lattice,30,biomesoplenty:leaves_2:7,30,quark:iron_plate_stairs:6,10,quark:iron_plate_stairs:0,10,quark:iron_plate_stairs:5,10,quark:iron_plate_stairs,10,quark:iron_plate_slab:8,10,quark:iron_plate_stairs:7,10,quark:iron_plate_stairs:1,10,quark:iron_plate_slab,10,quark:iron_plate_stairs:4,10,quark:iron_plate_stairs:2,10,rustic:iron_lattice,50,rustic:iron_lattice,50,biomesoplenty:leaves_2:7,100)
RandomBlock(3,5,-1,rustic:iron_lattice,30,rustic:iron_lattice,30,biomesoplenty:leaves_2:7,30,quark:iron_plate_stairs:6,10,quark:iron_plate_stairs:0,10,quark:iron_plate_stairs:5,10,quark:iron_plate_stairs,10,quark:iron_plate_slab:8,10,quark:iron_plate_stairs:7,10,quark:iron_plate_stairs:1,10,quark:iron_plate_slab,10,quark:iron_plate_stairs:4,10,quark:iron_plate_stairs:2,10,rustic:iron_lattice,50,rustic:iron_lattice,50,biomesoplenty:leaves_2:7,100)
RandomBlock(3,5,0,quark:iron_plate:1,70,STAINED_CLAY:15,30,STAINED_CLAY:7,30,null,30,quark:iron_plate:1,100)
Block(3,5,1,quark:framed_glass)
Block(3,5,2,quark:framed_glass)
Block(3,5,3,quark:framed_glass)
RandomBlock(3,5,4,quark:iron_plate:1,70,STAINED_CLAY:15,30,STAINED_CLAY:7,30,null,30,quark:iron_plate:1,100)
Block(3,6,0,rustic:iron_lattice:0)
Block(3,6,4,rustic:iron_lattice:0)
Block(4,0,-1,quark:limestone)
RandomBlock(4,0,0,quark:iron_plate:1,70,STAINED_CLAY:15,30,STAINED_CLAY:7,30,null,30,quark:iron_plate:1,100)
RandomBlock(4,0,1,quark:iron_plate:1,70,STAINED_CLAY:15,30,STAINED_CLAY:7,30,null,30,quark:iron_plate:1,100)
RandomBlock(4,0,2,quark:iron_plate:1,70,STAINED_CLAY:15,30,STAINED_CLAY:7,30,null,30,quark:iron_plate:1,100)
RandomBlock(4,0,3,quark:iron_plate:1,70,STAINED_CLAY:15,30,STAINED_CLAY:7,30,null,30,quark:iron_plate:1,100)
Block(4,0,4,quark:world_stone_pavement:2)
Block(4,0,5,quark:limestone)
Block(4,1,-1,COBBLESTONE_STAIRS:2)
RandomBlock(4,1,0,quark:iron_plate:1,70,STAINED_CLAY:15,30,STAINED_CLAY:7,30,null,30,quark:iron_plate:1,100)
Block(4,1,1,srparasites:deadblood)
Block(4,1,2,srparasites:deadblood)
Block(4,1,3,srparasites:deadblood)
Block(4,1,4,quark:world_stone_pavement:2)
Block(4,1,5,COBBLESTONE_STAIRS:3)
RandomBlock(4,2,0,quark:iron_plate:1,70,STAINED_CLAY:15,30,STAINED_CLAY:7,30,null,30,quark:iron_plate:1,100)
Block(4,2,4,quark:world_stone_pavement:2)
Block(4,3,-5,COBBLESTONE_STAIRS:6)
RandomBlock(4,3,-4,quark:iron_plate:1,70,STAINED_CLAY:15,30,STAINED_CLAY:7,30,null,30,quark:iron_plate:1,100)
Block(4,3,-3,COBBLESTONE_STAIRS:7)
Block(4,3,-2,COBBLESTONE_STAIRS:5)
Block(4,3,-1,COBBLESTONE_STAIRS:5)
RandomBlock(4,3,0,quark:iron_plate:1,70,STAINED_CLAY:15,30,STAINED_CLAY:7,30,null,30,quark:iron_plate:1,100)
Block(4,3,4,quark:world_stone_pavement:2)
RandomBlock(4,4,-5,quark:iron_plate:1,70,STAINED_CLAY:15,30,STAINED_CLAY:7,30,null,30,quark:iron_plate:1,100)
Block(4,4,-4,srparasites:deadblood)
RandomBlock(4,4,-3,quark:iron_plate:1,70,STAINED_CLAY:15,30,STAINED_CLAY:7,30,null,30,quark:iron_plate:1,100)
RandomBlock(4,4,-2,quark:iron_plate:1,70,STAINED_CLAY:15,30,STAINED_CLAY:7,30,null,30,quark:iron_plate:1,100)
RandomBlock(4,4,-1,quark:iron_plate:1,70,STAINED_CLAY:15,30,STAINED_CLAY:7,30,null,30,quark:iron_plate:1,100)
RandomBlock(4,4,0,quark:iron_plate:1,70,STAINED_CLAY:15,30,STAINED_CLAY:7,30,null,30,quark:iron_plate:1,100)
Block(4,4,4,quark:world_stone_pavement:2)
Block(4,5,-5,COBBLESTONE_STAIRS:2)
RandomBlock(4,5,-4,rustic:iron_lattice,30,rustic:iron_lattice,30,biomesoplenty:leaves_2:7,30,quark:iron_plate_stairs:6,10,quark:iron_plate_stairs:0,10,quark:iron_plate_stairs:5,10,quark:iron_plate_stairs,10,quark:iron_plate_slab:8,10,quark:iron_plate_stairs:7,10,quark:iron_plate_stairs:1,10,quark:iron_plate_slab,10,quark:iron_plate_stairs:4,10,quark:iron_plate_stairs:2,10,rustic:iron_lattice,50,rustic:iron_lattice,50,biomesoplenty:leaves_2:7,100)
Block(4,5,-3,COBBLESTONE_STAIRS:3)
Block(4,5,-2,COBBLESTONE_STAIRS:1)
Block(4,5,-1,COBBLESTONE_STAIRS:1)
RandomBlock(4,5,0,quark:iron_plate:1,70,STAINED_CLAY:15,30,STAINED_CLAY:7,30,null,30,quark:iron_plate:1,100)
Block(4,5,1,quark:framed_glass)
Block(4,5,2,quark:framed_glass)
Block(4,5,3,quark:framed_glass)
RandomBlock(4,5,4,quark:iron_plate:1,70,STAINED_CLAY:15,30,STAINED_CLAY:7,30,null,30,quark:iron_plate:1,100)
Block(4,6,0,rustic:iron_lattice:0)
Block(4,6,4,rustic:iron_lattice:0)
Block(5,0,-1,quark:limestone)
RandomBlock(5,0,0,quark:iron_plate:1,70,STAINED_CLAY:15,30,STAINED_CLAY:7,30,null,30,quark:iron_plate:1,100)
Block(5,0,1,quark:world_stone_pavement:2)
RandomBlock(5,0,2,quark:iron_plate:1,70,STAINED_CLAY:15,30,STAINED_CLAY:7,30,null,30,quark:iron_plate:1,100)
Block(5,0,3,quark:world_stone_pavement:2)
RandomBlock(5,0,4,quark:iron_plate:1,70,STAINED_CLAY:15,30,STAINED_CLAY:7,30,null,30,quark:iron_plate:1,100)
Block(5,0,5,quark:limestone)
Block(5,1,-1,COBBLESTONE_STAIRS:2)
RandomBlock(5,1,0,quark:iron_plate:1,70,STAINED_CLAY:15,30,STAINED_CLAY:7,30,null,30,quark:iron_plate:1,100)
Block(5,1,1,quark:world_stone_pavement:2)
RandomBlock(5,1,2,quark:iron_plate:1,70,STAINED_CLAY:15,30,STAINED_CLAY:7,30,null,30,quark:iron_plate:1,100)
Block(5,1,3,quark:world_stone_pavement:2)
RandomBlock(5,1,4,quark:iron_plate:1,70,STAINED_CLAY:15,30,STAINED_CLAY:7,30,null,30,quark:iron_plate:1,100)
Block(5,1,5,COBBLESTONE_STAIRS:3)
RandomBlock(5,2,0,quark:iron_plate:1,70,STAINED_CLAY:15,30,STAINED_CLAY:7,30,null,30,quark:iron_plate:1,100)
Block(5,2,1,quark:world_stone_pavement:2)
RandomBlock(5,2,2,quark:iron_plate:1,70,STAINED_CLAY:15,30,STAINED_CLAY:7,30,null,30,quark:iron_plate:1,100)
Block(5,2,3,quark:world_stone_pavement:2)
RandomBlock(5,2,4,quark:iron_plate:1,70,STAINED_CLAY:15,30,STAINED_CLAY:7,30,null,30,quark:iron_plate:1,100)
Block(5,3,-5,COBBLESTONE_STAIRS:6)
RandomBlock(5,3,-4,quark:iron_plate:1,70,STAINED_CLAY:15,30,STAINED_CLAY:7,30,null,30,quark:iron_plate:1,100)
Block(5,3,-3,COBBLESTONE_STAIRS:7)
RandomBlock(5,3,0,quark:iron_plate:1,70,STAINED_CLAY:15,30,STAINED_CLAY:7,30,null,30,quark:iron_plate:1,100)
Block(5,3,1,quark:world_stone_pavement:2)
RandomBlock(5,3,2,quark:iron_plate:1,70,STAINED_CLAY:15,30,STAINED_CLAY:7,30,null,30,quark:iron_plate:1,100)
Block(5,3,3,quark:world_stone_pavement:2)
RandomBlock(5,3,4,quark:iron_plate:1,70,STAINED_CLAY:15,30,STAINED_CLAY:7,30,null,30,quark:iron_plate:1,100)
RandomBlock(5,4,-5,quark:iron_plate:1,70,STAINED_CLAY:15,30,STAINED_CLAY:7,30,null,30,quark:iron_plate:1,100)
Block(5,4,-4,srparasites:deadblood)
RandomBlock(5,4,-3,quark:iron_plate:1,70,STAINED_CLAY:15,30,STAINED_CLAY:7,30,null,30,quark:iron_plate:1,100)
RandomBlock(5,4,0,quark:iron_plate:1,70,STAINED_CLAY:15,30,STAINED_CLAY:7,30,null,30,quark:iron_plate:1,100)
Block(5,4,1,quark:world_stone_pavement:2)
Block(5,4,2,quark:world_stone_pavement:2)
Block(5,4,3,quark:world_stone_pavement:2)
RandomBlock(5,4,4,quark:iron_plate:1,70,STAINED_CLAY:15,30,STAINED_CLAY:7,30,null,30,quark:iron_plate:1,100)
Block(5,5,-5,COBBLESTONE_STAIRS:2)
RandomBlock(5,5,-4,rustic:iron_lattice,30,rustic:iron_lattice,30,biomesoplenty:leaves_2:7,30,quark:iron_plate_stairs:6,10,quark:iron_plate_stairs:0,10,quark:iron_plate_stairs:5,10,quark:iron_plate_stairs,10,quark:iron_plate_slab:8,10,quark:iron_plate_stairs:7,10,quark:iron_plate_stairs:1,10,quark:iron_plate_slab,10,quark:iron_plate_stairs:4,10,quark:iron_plate_stairs:2,10,rustic:iron_lattice,50,rustic:iron_lattice,50,biomesoplenty:leaves_2:7,100)
Block(5,5,-3,COBBLESTONE_STAIRS:3)
RandomBlock(5,5,0,quark:iron_plate:1,70,STAINED_CLAY:15,30,STAINED_CLAY:7,30,null,30,quark:iron_plate:1,100)
RandomBlock(5,5,1,quark:iron_plate:1,70,STAINED_CLAY:15,30,STAINED_CLAY:7,30,null,30,quark:iron_plate:1,100)
RandomBlock(5,5,2,quark:iron_plate:1,70,STAINED_CLAY:15,30,STAINED_CLAY:7,30,null,30,quark:iron_plate:1,100)
RandomBlock(5,5,3,quark:iron_plate:1,70,STAINED_CLAY:15,30,STAINED_CLAY:7,30,null,30,quark:iron_plate:1,100)
RandomBlock(5,5,4,quark:iron_plate:1,70,STAINED_CLAY:15,30,STAINED_CLAY:7,30,null,30,quark:iron_plate:1,100)
Block(5,6,0,rustic:iron_lattice:0)
Block(5,6,1,rustic:iron_lattice:0)
Block(5,6,2,rustic:iron_lattice:0)
Block(5,6,3,rustic:iron_lattice:0)
Block(5,6,4,rustic:iron_lattice:0)
Block(6,0,-1,quark:limestone)
Block(6,0,0,quark:limestone)
Block(6,0,1,quark:limestone)
Block(6,0,2,quark:limestone)
Block(6,0,3,quark:limestone)
Block(6,0,4,quark:limestone)
Block(6,0,5,quark:limestone)
Block(6,1,-1,COBBLESTONE_STAIRS:2)
Block(6,1,0,COBBLESTONE_STAIRS:1)
Block(6,1,1,COBBLESTONE_STAIRS:1)
Block(6,1,2,COBBLESTONE_STAIRS:1)
Block(6,1,3,COBBLESTONE_STAIRS:1)
Block(6,1,4,COBBLESTONE_STAIRS:1)
Block(6,1,5,COBBLESTONE_STAIRS:3)
Block(6,3,-5,COBBLESTONE_STAIRS:6)
RandomBlock(6,3,-4,quark:iron_plate:1,70,STAINED_CLAY:15,30,STAINED_CLAY:7,30,null,30,quark:iron_plate:1,100)
Block(6,3,-3,COBBLESTONE_STAIRS:7)
RandomBlock(6,4,-5,quark:iron_plate:1,70,STAINED_CLAY:15,30,STAINED_CLAY:7,30,null,30,quark:iron_plate:1,100)
Block(6,4,-4,srparasites:deadblood)
RandomBlock(6,4,-3,quark:iron_plate:1,70,STAINED_CLAY:15,30,STAINED_CLAY:7,30,null,30,quark:iron_plate:1,100)
Block(6,5,-5,COBBLESTONE_STAIRS:2)
RandomBlock(6,5,-4,quark:iron_plate:1,70,STAINED_CLAY:15,30,STAINED_CLAY:7,30,null,30,quark:iron_plate:1,100)
Block(6,5,-3,COBBLESTONE_STAIRS:3)
Block(7,3,-5,COBBLESTONE_STAIRS:6)
RandomBlock(7,3,-4,quark:iron_plate:1,70,STAINED_CLAY:15,30,STAINED_CLAY:7,30,null,30,quark:iron_plate:1,100)
Block(7,3,-3,COBBLESTONE_STAIRS:7)
Block(7,3,-2,COBBLESTONE_STAIRS:4)
Block(7,3,-1,COBBLESTONE_STAIRS:4)
Block(7,3,0,COBBLESTONE_STAIRS:4)
Block(7,3,1,COBBLESTONE_STAIRS:4)
Block(7,3,2,COBBLESTONE_STAIRS:4)
Block(7,3,3,COBBLESTONE_STAIRS:4)
Block(7,3,4,COBBLESTONE_STAIRS:4)
Block(7,3,5,COBBLESTONE_STAIRS:4)
Block(7,3,6,COBBLESTONE_STAIRS:4)
Block(7,3,7,COBBLESTONE_STAIRS:4)
Block(7,3,8,rustic:iron_lattice:0)
RandomBlock(7,4,-5,quark:iron_plate:1,70,STAINED_CLAY:15,30,STAINED_CLAY:7,30,null,30,quark:iron_plate:1,100)
Block(7,4,-4,srparasites:deadblood)
RandomBlock(7,4,-3,quark:iron_plate:1,70,STAINED_CLAY:15,30,STAINED_CLAY:7,30,null,30,quark:iron_plate:1,100)
RandomBlock(7,4,-2,quark:iron_plate:1,70,STAINED_CLAY:15,30,STAINED_CLAY:7,30,null,30,quark:iron_plate:1,100)
RandomBlock(7,4,-1,quark:iron_plate:1,70,STAINED_CLAY:15,30,STAINED_CLAY:7,30,null,30,quark:iron_plate:1,100)
RandomBlock(7,4,0,quark:iron_plate:1,70,STAINED_CLAY:15,30,STAINED_CLAY:7,30,null,30,quark:iron_plate:1,100)
RandomBlock(7,4,1,quark:iron_plate:1,70,STAINED_CLAY:15,30,STAINED_CLAY:7,30,null,30,quark:iron_plate:1,100)
RandomBlock(7,4,2,quark:iron_plate:1,70,STAINED_CLAY:15,30,STAINED_CLAY:7,30,null,30,quark:iron_plate:1,100)
RandomBlock(7,4,3,quark:iron_plate:1,70,STAINED_CLAY:15,30,STAINED_CLAY:7,30,null,30,quark:iron_plate:1,100)
RandomBlock(7,4,4,quark:iron_plate:1,70,STAINED_CLAY:15,30,STAINED_CLAY:7,30,null,30,quark:iron_plate:1,100)
RandomBlock(7,4,5,quark:iron_plate:1,70,STAINED_CLAY:15,30,STAINED_CLAY:7,30,null,30,quark:iron_plate:1,100)
RandomBlock(7,4,6,quark:iron_plate:1,70,STAINED_CLAY:15,30,STAINED_CLAY:7,30,null,30,quark:iron_plate:1,100)
Block(7,4,7,COBBLE_WALL:0)
Block(7,4,8,rustic:iron_lattice:0)
Block(7,5,-5,COBBLESTONE_STAIRS:2)
RandomBlock(7,5,-4,quark:iron_plate:1,70,STAINED_CLAY:15,30,STAINED_CLAY:7,30,null,30,quark:iron_plate:1,100)
Block(7,5,-3,COBBLESTONE_STAIRS:0)
Block(7,5,-2,COBBLESTONE_STAIRS:0)
Block(7,5,-1,COBBLESTONE_STAIRS:0)
Block(7,5,0,COBBLESTONE_STAIRS:0)
Block(7,5,1,COBBLESTONE_STAIRS:0)
Block(7,5,2,COBBLESTONE_STAIRS:0)
Block(7,5,3,COBBLESTONE_STAIRS:0)
Block(7,5,4,COBBLESTONE_STAIRS:0)
Block(7,5,5,COBBLESTONE_STAIRS:0)
Block(7,5,6,COBBLESTONE_STAIRS:0)
Block(7,5,7,COBBLESTONE_STAIRS:0)
Block(7,5,8,rustic:iron_lattice:0)

#######################################################################
# +-----------------------------------------------------------------+ #
# |                             Branches                            | #
# +-----------------------------------------------------------------+ #
#######################################################################

Branch(16,0,0,true,brutal_pipesmall_01C2R0,NORTH,100.0,0)

#######################################################################
# +-----------------------------------------------------------------+ #
# |                             Entities                            | #
# +-----------------------------------------------------------------+ #
#######################################################################


#######################################################################
# +-----------------------------------------------------------------+ #
# |                            Particles                            | #
# +-----------------------------------------------------------------+ #
#######################################################################


#######################################################################
# +-----------------------------------------------------------------+ #
# |                             Spawners                            | #
# +-----------------------------------------------------------------+ #
#######################################################################


#######################################################################
# +-----------------------------------------------------------------+ #
# |                             ModData                             | #
# +-----------------------------------------------------------------+ #
#######################################################################

