
#######################################################################
# +-----------------------------------------------------------------+ #
# |                            BO4 object                           | #
# +-----------------------------------------------------------------+ #
#######################################################################

Author: NLBlackEagle

Description: No description given

SettingsMode: WriteDisable


#######################################################################
# +-----------------------------------------------------------------+ #
# |                          Main settings                          | #
# +-----------------------------------------------------------------+ #
#######################################################################

Frequency: 0

SpawnHeight: highestBlock

UseCenterForHighestBlock: true

##############################
# Height Limits for the BO4. #
##############################

MinHeight: 0

MaxHeight: 255

InheritBO3: 

InheritBO3Rotation: NORTH

OverrideChildSettings: true

OverrideParentHeight: false

CanOverride: true

BranchFrequency: 0

BranchFrequencyGroup: 

MustBeBelowOther: false

MustBeInside: 

CannotBeInside: 

ReplacesBO3: 

MustBeInsideWorldBorders: false

CanSpawnOnWater: true

SpawnOnWaterOnly: false

SpawnUnderWater: false

SpawnAtWaterLevel: false

HeightOffset: 0

RemoveAir: true

ReplaceAbove: 

ReplaceBelow: 

ReplaceWithBiomeBlocks: true

ReplaceWithSurfaceBlock: GRASS

ReplaceWithGroundBlock: DIRT

ReplaceWithStoneBlock: STONE

SmoothRadius: 0

SmoothHeightOffset: 0

SmoothStartTop: false

SmoothStartWood: false

SmoothingSurfaceBlock: 

SmoothingGroundBlock: 

BO3Group: 

IsSpawnPoint: false

DoReplaceBlocks: true


#######################################################################
# +-----------------------------------------------------------------+ #
# |                              Blocks                             | #
# +-----------------------------------------------------------------+ #
#######################################################################

Block(-8,0,-7,DIRT:1)
Block(-8,0,-6,STAINED_CLAY:0)
Block(-8,0,-5,STAINED_CLAY:0)
Block(-8,0,-4,STAINED_CLAY:0)
Block(-8,0,-3,STAINED_CLAY:0)
Block(-8,0,-2,STAINED_CLAY:0)
Block(-8,0,-1,STAINED_CLAY:0)
Block(-8,0,0,STAINED_CLAY:0)
Block(-8,0,1,DIRT:1)
Block(-8,0,2,DIRT:1)
Block(-8,0,3,DIRT:1)
Block(-8,0,4,DIRT:1)
Block(-8,0,5,DIRT:1)
Block(-8,0,6,DIRT:1)
Block(-8,0,7,DIRT:1)
Block(-8,0,8,DIRT:1)
Block(-8,1,-7,DIRT:1)
Block(-8,1,-6,STAINED_CLAY:0)
Block(-8,1,-5,STAINED_CLAY:0)
Block(-8,1,-4,STAINED_CLAY:0)
Block(-8,1,-3,STAINED_CLAY:0)
Block(-8,1,-2,STAINED_CLAY:0)
Block(-8,1,-1,STAINED_CLAY:0)
Block(-8,1,0,STAINED_CLAY:0)
Block(-8,1,1,DIRT:1)
Block(-8,1,2,DIRT:1)
Block(-8,1,3,DIRT:1)
Block(-8,1,4,DIRT:1)
Block(-8,1,5,DIRT:1)
Block(-8,1,6,DIRT:1)
Block(-8,1,7,DIRT:1)
Block(-8,1,8,DIRT:1)
Block(-8,2,-7,DIRT:1)
Block(-8,2,-6,STAINED_CLAY:0)
Block(-8,2,-5,STAINED_CLAY:0)
Block(-8,2,-4,STAINED_CLAY:0)
Block(-8,2,-3,STAINED_CLAY:0)
Block(-8,2,-2,STAINED_CLAY:0)
Block(-8,2,-1,STAINED_CLAY:0)
Block(-8,2,0,STAINED_CLAY:0)
Block(-8,2,1,DIRT:1)
Block(-8,2,2,DIRT:1)
Block(-8,2,3,DIRT:1)
Block(-8,2,4,DIRT:1)
Block(-8,2,5,DIRT:1)
Block(-8,2,6,DIRT:1)
Block(-8,2,7,DIRT:1)
Block(-8,2,8,DIRT:1)
Block(-8,3,-7,DIRT:1)
Block(-8,3,-6,STAINED_CLAY:0)
Block(-8,3,-5,STAINED_CLAY:0)
Block(-8,3,-4,STAINED_CLAY:0)
Block(-8,3,-3,STAINED_CLAY:0)
Block(-8,3,-2,STAINED_CLAY:0)
Block(-8,3,-1,STAINED_CLAY:0)
Block(-8,3,0,STAINED_CLAY:0)
Block(-8,3,1,DIRT:1)
Block(-8,3,2,DIRT:1)
Block(-8,3,3,DIRT:1)
Block(-8,3,4,DIRT:1)
Block(-8,3,5,DIRT:1)
Block(-8,3,6,DIRT:1)
Block(-8,3,7,DIRT:1)
Block(-8,3,8,DIRT:1)
Block(-8,4,-7,STAINED_CLAY:0)
Block(-8,4,-6,STAINED_CLAY:0)
Block(-8,4,-5,STAINED_CLAY:0)
Block(-8,4,-4,STAINED_CLAY:0)
Block(-8,4,-3,STAINED_CLAY:0)
Block(-8,4,-2,STAINED_CLAY:0)
Block(-8,4,-1,STAINED_CLAY:0)
Block(-8,4,0,STAINED_CLAY:0)
Block(-8,4,1,DIRT:1)
Block(-8,4,2,DIRT:1)
Block(-8,4,3,DIRT:1)
Block(-8,4,4,DIRT:1)
Block(-8,4,5,DIRT:1)
Block(-8,4,6,DIRT:1)
Block(-8,4,7,DIRT:1)
Block(-8,4,8,DIRT:1)
Block(-8,5,-7,STAINED_CLAY:0)
Block(-8,5,-6,STAINED_CLAY:0)
Block(-8,5,-5,STAINED_CLAY:0)
Block(-8,5,-4,STAINED_CLAY:0)
Block(-8,5,-3,STAINED_CLAY:0)
Block(-8,5,-2,STAINED_CLAY:0)
Block(-8,5,-1,STAINED_CLAY:0)
Block(-8,5,0,DIRT:1)
Block(-8,5,1,DIRT:1)
Block(-8,5,2,DIRT:1)
Block(-8,5,3,DIRT:1)
Block(-8,5,4,DIRT:1)
Block(-8,5,5,DIRT:1)
Block(-8,5,6,DIRT:1)
Block(-8,5,7,DIRT:1)
Block(-8,5,8,DIRT:1)
Block(-8,6,-7,STAINED_CLAY:0)
Block(-8,6,-6,STAINED_CLAY:0)
Block(-8,6,-5,STAINED_CLAY:0)
Block(-8,6,-4,STAINED_CLAY:0)
Block(-8,6,-3,STAINED_CLAY:0)
Block(-8,6,-2,DIRT:1)
Block(-8,6,-1,DIRT:1)
Block(-8,6,0,DIRT:1)
Block(-8,6,1,DIRT:1)
Block(-8,6,2,DIRT:1)
Block(-8,6,3,DIRT:1)
Block(-8,6,4,DIRT:1)
Block(-8,6,5,DIRT:1)
Block(-8,6,6,DIRT:1)
Block(-8,6,7,DIRT:1)
Block(-8,7,-7,STAINED_CLAY:0)
Block(-8,7,-6,STAINED_CLAY:0)
Block(-8,7,-5,STAINED_CLAY:0)
Block(-8,7,-4,STAINED_CLAY:0)
Block(-8,7,-3,DIRT:1)
Block(-8,7,-2,DIRT:1)
Block(-8,7,-1,DIRT:1)
Block(-8,7,0,DIRT:1)
Block(-8,7,1,DIRT:1)
Block(-8,7,2,DIRT:1)
Block(-8,7,3,DIRT:1)
Block(-8,7,4,DIRT:1)
Block(-8,7,5,DIRT:1)
Block(-8,8,-7,STAINED_CLAY:0)
Block(-8,8,-6,STAINED_CLAY:0)
Block(-8,8,-5,DIRT:1)
Block(-8,8,-4,DIRT:1)
Block(-8,8,-3,DIRT:1)
Block(-8,8,-2,DIRT:1)
Block(-8,8,-1,DIRT:1)
Block(-8,8,0,DIRT:1)
Block(-8,8,1,DIRT:1)
Block(-8,8,2,DIRT:1)
Block(-8,8,3,DIRT:1)
Block(-8,9,-7,STAINED_CLAY:0)
Block(-8,9,-6,STAINED_CLAY:0)
Block(-8,9,-5,DIRT:1)
Block(-8,9,-4,DIRT:1)
Block(-8,9,-3,DIRT:1)
Block(-8,9,-2,DIRT:1)
Block(-8,9,-1,DIRT:1)
Block(-8,9,0,DIRT:1)
Block(-8,9,1,DIRT:1)
Block(-8,10,-7,STAINED_CLAY:0)
Block(-8,10,-6,STAINED_CLAY:0)
Block(-8,10,-5,DIRT:1)
Block(-8,10,-4,DIRT:1)
Block(-8,10,-3,DIRT:1)
Block(-8,10,-2,DIRT:1)
Block(-8,10,-1,DIRT:1)
Block(-8,11,-7,STAINED_CLAY:0)
Block(-8,11,-6,STAINED_CLAY:0)
Block(-8,11,-5,DIRT:1)
Block(-8,11,-4,DIRT:1)
Block(-8,11,-3,DIRT:1)
Block(-8,11,-2,DIRT:1)
Block(-8,12,-7,STAINED_CLAY:0)
Block(-8,12,-6,DIRT:1)
Block(-8,12,-5,DIRT:1)
Block(-8,12,-4,DIRT:1)
Block(-8,13,-7,STAINED_CLAY:0)
Block(-8,13,-6,STAINED_CLAY:0)
Block(-7,0,-7,STAINED_CLAY:0)
Block(-7,0,-6,STAINED_CLAY:0)
Block(-7,0,-5,STAINED_CLAY:0)
Block(-7,0,-4,STAINED_CLAY:0)
Block(-7,0,-3,STAINED_CLAY:0)
Block(-7,0,-2,STAINED_CLAY:0)
Block(-7,0,-1,STAINED_CLAY:0)
Block(-7,0,0,STAINED_CLAY:0)
Block(-7,0,1,STAINED_CLAY:0)
Block(-7,0,2,DIRT:1)
Block(-7,0,3,DIRT:1)
Block(-7,0,4,DIRT:1)
Block(-7,0,5,DIRT:1)
Block(-7,0,6,DIRT:1)
Block(-7,0,7,DIRT:1)
Block(-7,0,8,DIRT:1)
Block(-7,1,-7,STAINED_CLAY:0)
Block(-7,1,-6,STAINED_CLAY:0)
Block(-7,1,-5,STAINED_CLAY:0)
Block(-7,1,-4,STAINED_CLAY:0)
Block(-7,1,-3,STAINED_CLAY:0)
Block(-7,1,-2,STAINED_CLAY:0)
Block(-7,1,-1,STAINED_CLAY:0)
Block(-7,1,0,STAINED_CLAY:0)
Block(-7,1,1,STAINED_CLAY:0)
Block(-7,1,2,DIRT:1)
Block(-7,1,3,DIRT:1)
Block(-7,1,4,DIRT:1)
Block(-7,1,5,DIRT:1)
Block(-7,1,6,DIRT:1)
Block(-7,1,7,DIRT:1)
Block(-7,1,8,DIRT:1)
Block(-7,2,-7,STAINED_CLAY:0)
Block(-7,2,-6,STAINED_CLAY:0)
Block(-7,2,-5,STAINED_CLAY:0)
Block(-7,2,-4,STAINED_CLAY:0)
Block(-7,2,-3,STAINED_CLAY:0)
Block(-7,2,-2,STAINED_CLAY:0)
Block(-7,2,-1,STAINED_CLAY:0)
Block(-7,2,0,STAINED_CLAY:0)
Block(-7,2,1,STAINED_CLAY:0)
Block(-7,2,2,DIRT:1)
Block(-7,2,3,DIRT:1)
Block(-7,2,4,DIRT:1)
Block(-7,2,5,DIRT:1)
Block(-7,2,6,DIRT:1)
Block(-7,2,7,DIRT:1)
Block(-7,2,8,DIRT:1)
Block(-7,3,-7,STAINED_CLAY:0)
Block(-7,3,-6,STAINED_CLAY:0)
Block(-7,3,-5,STAINED_CLAY:0)
Block(-7,3,-4,STAINED_CLAY:0)
Block(-7,3,-3,STAINED_CLAY:0)
Block(-7,3,-2,STAINED_CLAY:0)
Block(-7,3,-1,STAINED_CLAY:0)
Block(-7,3,0,STAINED_CLAY:0)
Block(-7,3,1,STAINED_CLAY:0)
Block(-7,3,2,DIRT:1)
Block(-7,3,3,DIRT:1)
Block(-7,3,4,DIRT:1)
Block(-7,3,5,DIRT:1)
Block(-7,3,6,DIRT:1)
Block(-7,3,7,DIRT:1)
Block(-7,3,8,DIRT:1)
Block(-7,4,-7,STAINED_CLAY:0)
Block(-7,4,-6,STAINED_CLAY:0)
Block(-7,4,-5,STAINED_CLAY:0)
Block(-7,4,-4,STAINED_CLAY:0)
Block(-7,4,-3,STAINED_CLAY:0)
Block(-7,4,-2,STAINED_CLAY:0)
Block(-7,4,-1,STAINED_CLAY:0)
Block(-7,4,0,STAINED_CLAY:0)
Block(-7,4,1,STAINED_CLAY:0)
Block(-7,4,2,DIRT:1)
Block(-7,4,3,DIRT:1)
Block(-7,4,4,DIRT:1)
Block(-7,4,5,DIRT:1)
Block(-7,4,6,DIRT:1)
Block(-7,4,7,DIRT:1)
Block(-7,4,8,DIRT:1)
Block(-7,5,-7,STAINED_CLAY:0)
Block(-7,5,-6,STAINED_CLAY:0)
Block(-7,5,-5,STAINED_CLAY:0)
Block(-7,5,-4,STAINED_CLAY:0)
Block(-7,5,-3,STAINED_CLAY:0)
Block(-7,5,-2,STAINED_CLAY:0)
Block(-7,5,-1,STAINED_CLAY:0)
Block(-7,5,0,STAINED_CLAY:0)
Block(-7,5,1,DIRT:1)
Block(-7,5,2,DIRT:1)
Block(-7,5,3,DIRT:1)
Block(-7,5,4,DIRT:1)
Block(-7,5,5,DIRT:1)
Block(-7,5,6,DIRT:1)
Block(-7,5,7,DIRT:1)
Block(-7,6,-7,STAINED_CLAY:0)
Block(-7,6,-6,STAINED_CLAY:0)
Block(-7,6,-5,STAINED_CLAY:0)
Block(-7,6,-4,STAINED_CLAY:0)
Block(-7,6,-3,STAINED_CLAY:0)
Block(-7,6,-2,STAINED_CLAY:0)
Block(-7,6,-1,STAINED_CLAY:0)
Block(-7,6,0,DIRT:1)
Block(-7,6,1,DIRT:1)
Block(-7,6,2,DIRT:1)
Block(-7,6,3,DIRT:1)
Block(-7,6,4,DIRT:1)
Block(-7,6,5,DIRT:1)
Block(-7,7,-7,STAINED_CLAY:0)
Block(-7,7,-6,STAINED_CLAY:0)
Block(-7,7,-5,STAINED_CLAY:0)
Block(-7,7,-4,STAINED_CLAY:0)
Block(-7,7,-3,STAINED_CLAY:0)
Block(-7,7,-2,STAINED_CLAY:0)
Block(-7,7,-1,DIRT:1)
Block(-7,7,0,DIRT:1)
Block(-7,7,1,DIRT:1)
Block(-7,7,2,DIRT:1)
Block(-7,7,3,DIRT:1)
Block(-7,8,-7,STAINED_CLAY:0)
Block(-7,8,-6,STAINED_CLAY:0)
Block(-7,8,-5,STAINED_CLAY:0)
Block(-7,8,-4,STAINED_CLAY:0)
Block(-7,8,-3,STAINED_CLAY:0)
Block(-7,8,-2,DIRT:1)
Block(-7,8,-1,DIRT:1)
Block(-7,8,0,DIRT:1)
Block(-7,8,1,DIRT:1)
Block(-7,9,-7,STAINED_CLAY:0)
Block(-7,9,-6,STAINED_CLAY:0)
Block(-7,9,-5,STAINED_CLAY:0)
Block(-7,9,-4,DIRT:1)
Block(-7,9,-3,DIRT:1)
Block(-7,9,-2,DIRT:1)
Block(-7,9,-1,DIRT:1)
Block(-7,10,-7,STAINED_CLAY:0)
Block(-7,10,-6,STAINED_CLAY:0)
Block(-7,10,-5,STAINED_CLAY:0)
Block(-7,10,-4,DIRT:1)
Block(-7,10,-3,DIRT:1)
Block(-7,10,-2,DIRT:1)
Block(-7,11,-7,STAINED_CLAY:0)
Block(-7,11,-6,STAINED_CLAY:0)
Block(-7,11,-5,DIRT:1)
Block(-7,11,-4,DIRT:1)
Block(-7,12,-7,STAINED_CLAY:0)
Block(-7,12,-6,STAINED_CLAY:0)
Block(-6,0,-6,STAINED_CLAY:0)
Block(-6,0,-5,STAINED_CLAY:0)
Block(-6,0,-4,STAINED_CLAY:0)
Block(-6,0,-3,STAINED_CLAY:0)
Block(-6,0,-2,STAINED_CLAY:0)
Block(-6,0,-1,STAINED_CLAY:0)
Block(-6,0,0,STAINED_CLAY:0)
Block(-6,0,1,STAINED_CLAY:0)
Block(-6,0,2,DIRT:1)
Block(-6,0,3,DIRT:1)
Block(-6,0,4,DIRT:1)
Block(-6,0,5,DIRT:1)
Block(-6,0,6,DIRT:1)
Block(-6,0,7,DIRT:1)
Block(-6,0,8,DIRT:1)
Block(-6,1,-7,STAINED_CLAY:0)
Block(-6,1,-6,STAINED_CLAY:0)
Block(-6,1,-5,STAINED_CLAY:0)
Block(-6,1,-4,STAINED_CLAY:0)
Block(-6,1,-3,STAINED_CLAY:0)
Block(-6,1,-2,STAINED_CLAY:0)
Block(-6,1,-1,STAINED_CLAY:0)
Block(-6,1,0,STAINED_CLAY:0)
Block(-6,1,1,STAINED_CLAY:0)
Block(-6,1,2,STAINED_CLAY:0)
Block(-6,1,3,DIRT:1)
Block(-6,1,4,DIRT:1)
Block(-6,1,5,DIRT:1)
Block(-6,1,6,DIRT:1)
Block(-6,1,7,DIRT:1)
Block(-6,1,8,DIRT:1)
Block(-6,2,-7,STAINED_CLAY:0)
Block(-6,2,-6,STAINED_CLAY:0)
Block(-6,2,-5,STAINED_CLAY:0)
Block(-6,2,-4,STAINED_CLAY:0)
Block(-6,2,-3,STAINED_CLAY:0)
Block(-6,2,-2,STAINED_CLAY:0)
Block(-6,2,-1,STAINED_CLAY:0)
Block(-6,2,0,STAINED_CLAY:0)
Block(-6,2,1,STAINED_CLAY:0)
Block(-6,2,2,STAINED_CLAY:0)
Block(-6,2,3,DIRT:1)
Block(-6,2,4,DIRT:1)
Block(-6,2,5,DIRT:1)
Block(-6,2,6,DIRT:1)
Block(-6,2,7,DIRT:1)
Block(-6,2,8,DIRT:1)
Block(-6,3,-7,STAINED_CLAY:0)
Block(-6,3,-6,STAINED_CLAY:0)
Block(-6,3,-5,STAINED_CLAY:0)
Block(-6,3,-4,STAINED_CLAY:0)
Block(-6,3,-3,STAINED_CLAY:0)
Block(-6,3,-2,STAINED_CLAY:0)
Block(-6,3,-1,STAINED_CLAY:0)
Block(-6,3,0,STAINED_CLAY:0)
Block(-6,3,1,STAINED_CLAY:0)
Block(-6,3,2,STAINED_CLAY:0)
Block(-6,3,3,DIRT:1)
Block(-6,3,4,DIRT:1)
Block(-6,3,5,DIRT:1)
Block(-6,3,6,DIRT:1)
Block(-6,3,7,DIRT:1)
Block(-6,3,8,DIRT:1)
Block(-6,4,-7,STAINED_CLAY:0)
Block(-6,4,-6,STAINED_CLAY:0)
Block(-6,4,-5,STAINED_CLAY:0)
Block(-6,4,-4,STAINED_CLAY:0)
Block(-6,4,-3,STAINED_CLAY:0)
Block(-6,4,-2,STAINED_CLAY:0)
Block(-6,4,-1,STAINED_CLAY:0)
Block(-6,4,0,STAINED_CLAY:0)
Block(-6,4,1,STAINED_CLAY:0)
Block(-6,4,2,DIRT:1)
Block(-6,4,3,DIRT:1)
Block(-6,4,4,DIRT:1)
Block(-6,4,5,DIRT:1)
Block(-6,4,6,DIRT:1)
Block(-6,4,7,DIRT:1)
Block(-6,5,-7,STAINED_CLAY:0)
Block(-6,5,-6,STAINED_CLAY:0)
Block(-6,5,-5,STAINED_CLAY:0)
Block(-6,5,-4,STAINED_CLAY:0)
Block(-6,5,-3,STAINED_CLAY:0)
Block(-6,5,-2,STAINED_CLAY:0)
Block(-6,5,-1,STAINED_CLAY:0)
Block(-6,5,0,STAINED_CLAY:0)
Block(-6,5,1,STAINED_CLAY:0)
Block(-6,5,2,DIRT:1)
Block(-6,5,3,DIRT:1)
Block(-6,5,4,DIRT:1)
Block(-6,5,5,DIRT:1)
Block(-6,6,-7,STAINED_CLAY:0)
Block(-6,6,-6,STAINED_CLAY:0)
Block(-6,6,-5,STAINED_CLAY:0)
Block(-6,6,-4,STAINED_CLAY:0)
Block(-6,6,-3,STAINED_CLAY:0)
Block(-6,6,-2,STAINED_CLAY:0)
Block(-6,6,-1,STAINED_CLAY:0)
Block(-6,6,0,STAINED_CLAY:0)
Block(-6,6,1,DIRT:1)
Block(-6,6,2,DIRT:1)
Block(-6,6,3,DIRT:1)
Block(-6,7,-7,STAINED_CLAY:0)
Block(-6,7,-6,STAINED_CLAY:0)
Block(-6,7,-5,STAINED_CLAY:0)
Block(-6,7,-4,STAINED_CLAY:0)
Block(-6,7,-3,STAINED_CLAY:0)
Block(-6,7,-2,STAINED_CLAY:0)
Block(-6,7,-1,STAINED_CLAY:0)
Block(-6,7,0,DIRT:1)
Block(-6,7,1,DIRT:1)
Block(-6,8,-7,STAINED_CLAY:0)
Block(-6,8,-6,STAINED_CLAY:0)
Block(-6,8,-5,STAINED_CLAY:0)
Block(-6,8,-4,STAINED_CLAY:0)
Block(-6,8,-3,STAINED_CLAY:0)
Block(-6,8,-2,STAINED_CLAY:0)
Block(-6,8,-1,DIRT:1)
Block(-6,9,-7,STAINED_CLAY:0)
Block(-6,9,-6,STAINED_CLAY:0)
Block(-6,9,-5,STAINED_CLAY:0)
Block(-6,9,-4,STAINED_CLAY:0)
Block(-6,9,-3,STAINED_CLAY:0)
Block(-6,9,-2,DIRT:1)
Block(-6,10,-7,STAINED_CLAY:0)
Block(-6,10,-6,STAINED_CLAY:0)
Block(-6,10,-5,STAINED_CLAY:0)
Block(-6,10,-4,DIRT:1)
Block(-6,11,-7,STAINED_CLAY:0)
Block(-6,11,-6,STAINED_CLAY:0)
Block(-5,0,-4,STAINED_CLAY:0)
Block(-5,0,-3,STAINED_CLAY:0)
Block(-5,0,-2,STAINED_CLAY:0)
Block(-5,0,-1,STAINED_CLAY:0)
Block(-5,0,0,STAINED_CLAY:0)
Block(-5,0,1,STAINED_CLAY:0)
Block(-5,0,2,STAINED_CLAY:0)
Block(-5,0,3,DIRT:1)
Block(-5,0,4,DIRT:1)
Block(-5,0,5,DIRT:1)
Block(-5,0,6,DIRT:1)
Block(-5,0,7,DIRT:1)
Block(-5,0,8,DIRT:1)
Block(-5,1,-5,STAINED_CLAY:0)
Block(-5,1,-4,STAINED_CLAY:0)
Block(-5,1,-3,STAINED_CLAY:0)
Block(-5,1,-2,STAINED_CLAY:0)
Block(-5,1,-1,STAINED_CLAY:0)
Block(-5,1,0,STAINED_CLAY:0)
Block(-5,1,1,STAINED_CLAY:0)
Block(-5,1,2,STAINED_CLAY:0)
Block(-5,1,3,DIRT:1)
Block(-5,1,4,DIRT:1)
Block(-5,1,5,DIRT:1)
Block(-5,1,6,DIRT:1)
Block(-5,1,7,DIRT:1)
Block(-5,1,8,DIRT:1)
Block(-5,2,-6,STAINED_CLAY:0)
Block(-5,2,-5,STAINED_CLAY:0)
Block(-5,2,-4,STAINED_CLAY:0)
Block(-5,2,-3,STAINED_CLAY:0)
Block(-5,2,-2,STAINED_CLAY:0)
Block(-5,2,-1,STAINED_CLAY:0)
Block(-5,2,0,STAINED_CLAY:0)
Block(-5,2,1,STAINED_CLAY:0)
Block(-5,2,2,STAINED_CLAY:0)
Block(-5,2,3,DIRT:1)
Block(-5,2,4,DIRT:1)
Block(-5,2,5,DIRT:1)
Block(-5,2,6,DIRT:1)
Block(-5,2,7,DIRT:1)
Block(-5,2,8,DIRT:1)
Block(-5,3,-6,STAINED_CLAY:0)
Block(-5,3,-5,STAINED_CLAY:0)
Block(-5,3,-4,STAINED_CLAY:0)
Block(-5,3,-3,STAINED_CLAY:0)
Block(-5,3,-2,STAINED_CLAY:0)
Block(-5,3,-1,STAINED_CLAY:0)
Block(-5,3,0,STAINED_CLAY:0)
Block(-5,3,1,STAINED_CLAY:0)
Block(-5,3,2,STAINED_CLAY:0)
Block(-5,3,3,DIRT:1)
Block(-5,3,4,DIRT:1)
Block(-5,3,5,DIRT:1)
Block(-5,3,6,DIRT:1)
Block(-5,3,7,DIRT:1)
Block(-5,4,-7,STAINED_CLAY:0)
Block(-5,4,-6,STAINED_CLAY:0)
Block(-5,4,-5,STAINED_CLAY:0)
Block(-5,4,-4,STAINED_CLAY:0)
Block(-5,4,-3,STAINED_CLAY:0)
Block(-5,4,-2,STAINED_CLAY:0)
Block(-5,4,-1,STAINED_CLAY:0)
Block(-5,4,0,STAINED_CLAY:0)
Block(-5,4,1,STAINED_CLAY:0)
Block(-5,4,2,STAINED_CLAY:0)
Block(-5,4,3,DIRT:1)
Block(-5,4,4,DIRT:1)
Block(-5,4,5,DIRT:1)
Block(-5,5,-7,STAINED_CLAY:0)
Block(-5,5,-6,STAINED_CLAY:0)
Block(-5,5,-5,STAINED_CLAY:0)
Block(-5,5,-4,STAINED_CLAY:0)
Block(-5,5,-3,STAINED_CLAY:0)
Block(-5,5,-2,STAINED_CLAY:0)
Block(-5,5,-1,STAINED_CLAY:0)
Block(-5,5,0,STAINED_CLAY:0)
Block(-5,5,1,STAINED_CLAY:0)
Block(-5,5,2,DIRT:1)
Block(-5,5,3,DIRT:1)
Block(-5,6,-7,STAINED_CLAY:0)
Block(-5,6,-6,STAINED_CLAY:0)
Block(-5,6,-5,STAINED_CLAY:0)
Block(-5,6,-4,STAINED_CLAY:0)
Block(-5,6,-3,STAINED_CLAY:0)
Block(-5,6,-2,STAINED_CLAY:0)
Block(-5,6,-1,STAINED_CLAY:0)
Block(-5,6,0,STAINED_CLAY:0)
Block(-5,6,1,STAINED_CLAY:0)
Block(-5,7,-7,STAINED_CLAY:0)
Block(-5,7,-6,STAINED_CLAY:0)
Block(-5,7,-5,STAINED_CLAY:0)
Block(-5,7,-4,STAINED_CLAY:0)
Block(-5,7,-3,STAINED_CLAY:0)
Block(-5,7,-2,STAINED_CLAY:0)
Block(-5,7,-1,STAINED_CLAY:0)
Block(-5,7,0,STAINED_CLAY:0)
Block(-5,8,-7,STAINED_CLAY:0)
Block(-5,8,-6,STAINED_CLAY:0)
Block(-5,8,-5,STAINED_CLAY:0)
Block(-5,8,-4,STAINED_CLAY:0)
Block(-5,8,-3,STAINED_CLAY:0)
Block(-5,8,-2,STAINED_CLAY:0)
Block(-5,9,-7,STAINED_CLAY:0)
Block(-5,9,-6,STAINED_CLAY:0)
Block(-5,9,-5,STAINED_CLAY:0)
Block(-5,9,-4,STAINED_CLAY:0)
Block(-5,10,-7,STAINED_CLAY:0)
Block(-5,10,-6,STAINED_CLAY:0)
Block(-4,0,-2,STAINED_CLAY:0)
Block(-4,0,-1,STAINED_CLAY:0)
Block(-4,0,0,STAINED_CLAY:0)
Block(-4,0,1,STAINED_CLAY:0)
Block(-4,0,2,STAINED_CLAY:0)
Block(-4,0,3,DIRT:1)
Block(-4,0,4,DIRT:1)
Block(-4,0,5,DIRT:1)
Block(-4,0,6,DIRT:1)
Block(-4,0,7,DIRT:1)
Block(-4,0,8,DIRT:1)
Block(-4,1,-3,STAINED_CLAY:0)
Block(-4,1,-2,STAINED_CLAY:0)
Block(-4,1,-1,STAINED_CLAY:0)
Block(-4,1,0,STAINED_CLAY:0)
Block(-4,1,1,STAINED_CLAY:0)
Block(-4,1,2,STAINED_CLAY:0)
Block(-4,1,3,DIRT:1)
Block(-4,1,4,DIRT:1)
Block(-4,1,5,DIRT:1)
Block(-4,1,6,DIRT:1)
Block(-4,1,7,DIRT:1)
Block(-4,1,8,DIRT:1)
Block(-4,2,-4,STAINED_CLAY:0)
Block(-4,2,-3,STAINED_CLAY:0)
Block(-4,2,-2,STAINED_CLAY:0)
Block(-4,2,-1,STAINED_CLAY:0)
Block(-4,2,0,STAINED_CLAY:0)
Block(-4,2,1,STAINED_CLAY:0)
Block(-4,2,2,STAINED_CLAY:0)
Block(-4,2,3,DIRT:1)
Block(-4,2,4,DIRT:1)
Block(-4,2,5,DIRT:1)
Block(-4,2,6,DIRT:1)
Block(-4,2,7,DIRT:1)
Block(-4,3,-5,STAINED_CLAY:0)
Block(-4,3,-4,STAINED_CLAY:0)
Block(-4,3,-3,STAINED_CLAY:0)
Block(-4,3,-2,STAINED_CLAY:0)
Block(-4,3,-1,STAINED_CLAY:0)
Block(-4,3,0,STAINED_CLAY:0)
Block(-4,3,1,STAINED_CLAY:0)
Block(-4,3,2,STAINED_CLAY:0)
Block(-4,3,3,DIRT:1)
Block(-4,3,4,DIRT:1)
Block(-4,3,5,DIRT:1)
Block(-4,4,-6,STAINED_CLAY:0)
Block(-4,4,-5,STAINED_CLAY:0)
Block(-4,4,-4,STAINED_CLAY:0)
Block(-4,4,-3,STAINED_CLAY:0)
Block(-4,4,-2,STAINED_CLAY:0)
Block(-4,4,-1,STAINED_CLAY:0)
Block(-4,4,0,STAINED_CLAY:0)
Block(-4,4,1,STAINED_CLAY:0)
Block(-4,4,2,STAINED_CLAY:0)
Block(-4,4,3,DIRT:1)
Block(-4,5,-6,STAINED_CLAY:0)
Block(-4,5,-5,STAINED_CLAY:0)
Block(-4,5,-4,STAINED_CLAY:0)
Block(-4,5,-3,STAINED_CLAY:0)
Block(-4,5,-2,STAINED_CLAY:0)
Block(-4,5,-1,STAINED_CLAY:0)
Block(-4,5,0,STAINED_CLAY:0)
Block(-4,5,1,STAINED_CLAY:0)
Block(-4,6,-7,STAINED_CLAY:0)
Block(-4,6,-6,STAINED_CLAY:0)
Block(-4,6,-5,STAINED_CLAY:0)
Block(-4,6,-4,STAINED_CLAY:0)
Block(-4,6,-3,STAINED_CLAY:0)
Block(-4,6,-2,STAINED_CLAY:0)
Block(-4,6,-1,STAINED_CLAY:0)
Block(-4,6,0,STAINED_CLAY:0)
Block(-4,7,-7,STAINED_CLAY:0)
Block(-4,7,-6,STAINED_CLAY:0)
Block(-4,7,-5,STAINED_CLAY:0)
Block(-4,7,-4,STAINED_CLAY:0)
Block(-4,7,-3,STAINED_CLAY:0)
Block(-4,7,-2,STAINED_CLAY:0)
Block(-4,8,-7,STAINED_CLAY:0)
Block(-4,8,-6,STAINED_CLAY:0)
Block(-4,8,-5,STAINED_CLAY:0)
Block(-4,8,-4,STAINED_CLAY:0)
Block(-4,9,-7,STAINED_CLAY:0)
Block(-4,9,-6,STAINED_CLAY:0)
Block(-3,0,-1,STAINED_CLAY:0)
Block(-3,0,0,STAINED_CLAY:0)
Block(-3,0,1,STAINED_CLAY:0)
Block(-3,0,2,STAINED_CLAY:0)
Block(-3,0,3,DIRT:1)
Block(-3,0,4,DIRT:1)
Block(-3,0,5,DIRT:1)
Block(-3,0,6,DIRT:1)
Block(-3,0,7,DIRT:1)
Block(-3,0,8,DIRT:1)
Block(-3,1,-1,STAINED_CLAY:0)
Block(-3,1,0,STAINED_CLAY:0)
Block(-3,1,1,STAINED_CLAY:0)
Block(-3,1,2,STAINED_CLAY:0)
Block(-3,1,3,DIRT:1)
Block(-3,1,4,DIRT:1)
Block(-3,1,5,DIRT:1)
Block(-3,1,6,DIRT:1)
Block(-3,1,7,DIRT:1)
Block(-3,2,-2,STAINED_CLAY:0)
Block(-3,2,-1,STAINED_CLAY:0)
Block(-3,2,0,STAINED_CLAY:0)
Block(-3,2,1,STAINED_CLAY:0)
Block(-3,2,2,STAINED_CLAY:0)
Block(-3,2,3,DIRT:1)
Block(-3,2,4,DIRT:1)
Block(-3,2,5,DIRT:1)
Block(-3,3,-3,STAINED_CLAY:0)
Block(-3,3,-2,STAINED_CLAY:0)
Block(-3,3,-1,STAINED_CLAY:0)
Block(-3,3,0,STAINED_CLAY:0)
Block(-3,3,1,STAINED_CLAY:0)
Block(-3,3,2,STAINED_CLAY:0)
Block(-3,3,3,DIRT:1)
Block(-3,4,-4,STAINED_CLAY:0)
Block(-3,4,-3,STAINED_CLAY:0)
Block(-3,4,-2,STAINED_CLAY:0)
Block(-3,4,-1,STAINED_CLAY:0)
Block(-3,4,0,STAINED_CLAY:0)
Block(-3,4,1,STAINED_CLAY:0)
Block(-3,5,-5,STAINED_CLAY:0)
Block(-3,5,-4,STAINED_CLAY:0)
Block(-3,5,-3,STAINED_CLAY:0)
Block(-3,5,-2,STAINED_CLAY:0)
Block(-3,5,-1,STAINED_CLAY:0)
Block(-3,5,0,STAINED_CLAY:0)
Block(-3,6,-5,STAINED_CLAY:0)
Block(-3,6,-4,STAINED_CLAY:0)
Block(-3,6,-3,STAINED_CLAY:0)
Block(-3,6,-2,STAINED_CLAY:0)
Block(-3,7,-6,STAINED_CLAY:0)
Block(-3,7,-5,STAINED_CLAY:0)
Block(-3,7,-4,STAINED_CLAY:0)
Block(-3,8,-7,STAINED_CLAY:0)
Block(-3,8,-6,STAINED_CLAY:0)
Block(-2,0,1,STAINED_CLAY:0)
Block(-2,0,2,DIRT:1)
Block(-2,0,3,DIRT:1)
Block(-2,0,4,DIRT:1)
Block(-2,0,5,DIRT:1)
Block(-2,0,6,DIRT:1)
Block(-2,0,7,DIRT:1)
Block(-2,1,0,STAINED_CLAY:0)
Block(-2,1,1,STAINED_CLAY:0)
Block(-2,1,2,STAINED_CLAY:0)
Block(-2,1,3,DIRT:1)
Block(-2,1,4,DIRT:1)
Block(-2,1,5,DIRT:1)
Block(-2,2,-1,STAINED_CLAY:0)
Block(-2,2,0,STAINED_CLAY:0)
Block(-2,2,1,STAINED_CLAY:0)
Block(-2,2,2,STAINED_CLAY:0)
Block(-2,2,3,DIRT:1)
Block(-2,3,-1,STAINED_CLAY:0)
Block(-2,3,0,STAINED_CLAY:0)
Block(-2,3,1,STAINED_CLAY:0)
Block(-2,3,2,STAINED_CLAY:0)
Block(-2,4,-2,STAINED_CLAY:0)
Block(-2,4,-1,STAINED_CLAY:0)
Block(-2,4,0,STAINED_CLAY:0)
Block(-2,5,-3,STAINED_CLAY:0)
Block(-2,5,-2,STAINED_CLAY:0)
Block(-2,6,-4,STAINED_CLAY:0)
Block(-1,0,3,DIRT:1)
Block(-1,0,4,DIRT:1)
Block(-1,0,5,DIRT:1)
Block(-1,1,2,DIRT:1)
Block(-1,1,3,DIRT:1)
Block(-1,2,1,STAINED_CLAY:0)
Block(-1,2,2,STAINED_CLAY:0)
Block(-1,3,0,STAINED_CLAY:0)
Block(0,0,4,DIRT:1)

#######################################################################
# +-----------------------------------------------------------------+ #
# |                             Branches                            | #
# +-----------------------------------------------------------------+ #
#######################################################################

Branch(0,0,16,true,MudSpike_Huge_08C1R4,NORTH,100.0,0)

#######################################################################
# +-----------------------------------------------------------------+ #
# |                             Entities                            | #
# +-----------------------------------------------------------------+ #
#######################################################################


#######################################################################
# +-----------------------------------------------------------------+ #
# |                            Particles                            | #
# +-----------------------------------------------------------------+ #
#######################################################################


#######################################################################
# +-----------------------------------------------------------------+ #
# |                             Spawners                            | #
# +-----------------------------------------------------------------+ #
#######################################################################


#######################################################################
# +-----------------------------------------------------------------+ #
# |                             ModData                             | #
# +-----------------------------------------------------------------+ #
#######################################################################

