
#######################################################################
# +-----------------------------------------------------------------+ #
# |                            BO4 object                           | #
# +-----------------------------------------------------------------+ #
#######################################################################

Author: NLBlackEagle

Description: No description given

SettingsMode: WriteDisable


#######################################################################
# +-----------------------------------------------------------------+ #
# |                          Main settings                          | #
# +-----------------------------------------------------------------+ #
#######################################################################

Frequency: 0

SpawnHeight: highestBlock

UseCenterForHighestBlock: true

##############################
# Height Limits for the BO4. #
##############################

MinHeight: 0

MaxHeight: 255

InheritBO3: 

InheritBO3Rotation: NORTH

OverrideChildSettings: true

OverrideParentHeight: false

CanOverride: false

BranchFrequency: 0

BranchFrequencyGroup: 

MustBeBelowOther: false

MustBeInside: 

CannotBeInside: 

ReplacesBO3: 

MustBeInsideWorldBorders: false

CanSpawnOnWater: true

SpawnOnWaterOnly: false

SpawnUnderWater: false

SpawnAtWaterLevel: false

HeightOffset: 0

RemoveAir: true

ReplaceAbove: 

ReplaceBelow: 

ReplaceWithBiomeBlocks: true

ReplaceWithSurfaceBlock: GRASS

ReplaceWithGroundBlock: DIRT

ReplaceWithStoneBlock: STONE

SmoothRadius: 0

SmoothHeightOffset: 0

SmoothStartTop: false

SmoothStartWood: false

SmoothingSurfaceBlock: 

SmoothingGroundBlock: 

BO3Group: 

IsSpawnPoint: false

DoReplaceBlocks: true


#######################################################################
# +-----------------------------------------------------------------+ #
# |                              Blocks                             | #
# +-----------------------------------------------------------------+ #
#######################################################################

Block(-8,-14,4,CONCRETE:15)
Block(-8,-14,5,CONCRETE:15)
Block(-8,-14,6,CONCRETE:15)
Block(-8,-14,7,CONCRETE:15)
Block(-8,-14,8,CONCRETE:15)
Block(-8,-13,3,CONCRETE:15)
Block(-8,-13,4,CONCRETE:15)
Block(-8,-13,5,CONCRETE:15)
Block(-8,-13,6,CONCRETE:15)
Block(-8,-13,7,CONCRETE:15)
Block(-8,-13,8,CONCRETE:15)
Block(-8,-12,3,CONCRETE:15)
Block(-8,-12,4,CONCRETE:15)
Block(-8,-12,5,CONCRETE:15)
Block(-8,-12,6,CONCRETE:15)
Block(-8,-12,7,CONCRETE:15)
Block(-8,-12,8,CONCRETE:15)
Block(-8,-11,2,CONCRETE:15)
Block(-8,-11,3,CONCRETE:15)
Block(-8,-11,4,CONCRETE:15)
Block(-8,-11,5,CONCRETE:15)
Block(-8,-11,6,CONCRETE:15)
Block(-8,-11,7,CONCRETE:15)
Block(-8,-11,8,CONCRETE:15)
Block(-8,-10,3,CONCRETE:15)
Block(-8,-10,4,CONCRETE:15)
Block(-8,-10,5,CONCRETE:15)
Block(-8,-10,6,CONCRETE:15)
Block(-8,-10,7,CONCRETE:15)
Block(-8,-10,8,CONCRETE:15)
Block(-8,-9,4,CONCRETE:15)
Block(-8,-9,5,CONCRETE:15)
Block(-8,-9,6,CONCRETE:15)
Block(-8,-9,7,CONCRETE:15)
Block(-8,-9,8,CONCRETE:15)
Block(-8,-8,4,CONCRETE:15)
Block(-8,-8,5,CONCRETE:15)
Block(-8,-8,6,CONCRETE:15)
Block(-8,-8,7,CONCRETE:15)
Block(-8,-8,8,CONCRETE:15)
Block(-8,-7,5,CONCRETE:15)
Block(-8,-7,6,CONCRETE:15)
Block(-8,-7,7,CONCRETE:15)
Block(-8,-7,8,CONCRETE:15)
Block(-8,-6,6,CONCRETE:15)
Block(-8,-6,7,CONCRETE:15)
Block(-8,-6,8,CONCRETE:15)
Block(-8,-5,8,CONCRETE:15)
Block(-7,-14,3,CONCRETE:15)
Block(-7,-14,4,CONCRETE:15)
Block(-7,-14,5,CONCRETE:15)
Block(-7,-14,6,CONCRETE:15)
Block(-7,-14,7,CONCRETE:15)
Block(-7,-14,8,CONCRETE:15)
Block(-7,-13,3,CONCRETE:15)
Block(-7,-13,4,CONCRETE:15)
Block(-7,-13,5,CONCRETE:15)
Block(-7,-13,6,CONCRETE:15)
Block(-7,-13,7,CONCRETE:15)
Block(-7,-13,8,CONCRETE:15)
Block(-7,-12,2,CONCRETE:15)
Block(-7,-12,3,CONCRETE:15)
Block(-7,-12,4,CONCRETE:15)
Block(-7,-12,5,CONCRETE:15)
Block(-7,-12,6,CONCRETE:15)
Block(-7,-12,7,CONCRETE:15)
Block(-7,-12,8,CONCRETE:15)
Block(-7,-11,2,CONCRETE:15)
Block(-7,-11,3,CONCRETE:15)
Block(-7,-11,4,CONCRETE:15)
Block(-7,-11,5,CONCRETE:15)
Block(-7,-11,6,CONCRETE:15)
Block(-7,-11,7,CONCRETE:15)
Block(-7,-11,8,CONCRETE:15)
Block(-7,-10,3,CONCRETE:15)
Block(-7,-10,4,CONCRETE:15)
Block(-7,-10,5,CONCRETE:15)
Block(-7,-10,6,CONCRETE:15)
Block(-7,-10,7,CONCRETE:15)
Block(-7,-10,8,CONCRETE:15)
Block(-7,-9,3,CONCRETE:15)
Block(-7,-9,4,CONCRETE:15)
Block(-7,-9,5,CONCRETE:15)
Block(-7,-9,6,CONCRETE:15)
Block(-7,-9,7,CONCRETE:15)
Block(-7,-9,8,CONCRETE:15)
Block(-7,-8,4,CONCRETE:15)
Block(-7,-8,5,CONCRETE:15)
Block(-7,-8,6,CONCRETE:15)
Block(-7,-8,7,CONCRETE:15)
Block(-7,-8,8,CONCRETE:15)
Block(-7,-7,5,CONCRETE:15)
Block(-7,-7,6,CONCRETE:15)
Block(-7,-7,7,CONCRETE:15)
Block(-7,-7,8,CONCRETE:15)
Block(-7,-6,6,CONCRETE:15)
Block(-7,-6,7,CONCRETE:15)
Block(-7,-6,8,CONCRETE:15)
Block(-7,-5,8,CONCRETE:15)
Block(-6,-14,3,CONCRETE:15)
Block(-6,-14,4,CONCRETE:15)
Block(-6,-14,5,CONCRETE:15)
Block(-6,-14,6,CONCRETE:15)
Block(-6,-14,7,CONCRETE:15)
Block(-6,-14,8,CONCRETE:15)
Block(-6,-13,2,CONCRETE:15)
Block(-6,-13,3,CONCRETE:15)
Block(-6,-13,4,CONCRETE:15)
Block(-6,-13,5,CONCRETE:15)
Block(-6,-13,6,CONCRETE:15)
Block(-6,-13,7,CONCRETE:15)
Block(-6,-13,8,CONCRETE:15)
Block(-6,-12,2,CONCRETE:15)
Block(-6,-12,3,CONCRETE:15)
Block(-6,-12,4,CONCRETE:15)
Block(-6,-12,5,CONCRETE:15)
Block(-6,-12,6,CONCRETE:15)
Block(-6,-12,7,CONCRETE:15)
Block(-6,-12,8,CONCRETE:15)
Block(-6,-11,2,CONCRETE:15)
Block(-6,-11,3,CONCRETE:15)
Block(-6,-11,4,CONCRETE:15)
Block(-6,-11,5,CONCRETE:15)
Block(-6,-11,6,CONCRETE:15)
Block(-6,-11,7,CONCRETE:15)
Block(-6,-11,8,CONCRETE:15)
Block(-6,-10,2,CONCRETE:15)
Block(-6,-10,3,CONCRETE:15)
Block(-6,-10,4,CONCRETE:15)
Block(-6,-10,5,CONCRETE:15)
Block(-6,-10,6,CONCRETE:15)
Block(-6,-10,7,CONCRETE:15)
Block(-6,-10,8,CONCRETE:15)
Block(-6,-9,3,CONCRETE:15)
Block(-6,-9,4,CONCRETE:15)
Block(-6,-9,5,CONCRETE:15)
Block(-6,-9,6,CONCRETE:15)
Block(-6,-9,7,CONCRETE:15)
Block(-6,-9,8,CONCRETE:15)
Block(-6,-8,4,CONCRETE:15)
Block(-6,-8,5,CONCRETE:15)
Block(-6,-8,6,CONCRETE:15)
Block(-6,-8,7,CONCRETE:15)
Block(-6,-8,8,CONCRETE:15)
Block(-6,-7,4,CONCRETE:15)
Block(-6,-7,5,CONCRETE:15)
Block(-6,-7,6,CONCRETE:15)
Block(-6,-7,7,CONCRETE:15)
Block(-6,-7,8,CONCRETE:15)
Block(-6,-6,6,CONCRETE:15)
Block(-6,-6,7,CONCRETE:15)
Block(-6,-6,8,CONCRETE:15)
Block(-6,-5,7,CONCRETE:15)
Block(-6,-5,8,CONCRETE:15)
Block(-5,-14,2,CONCRETE:15)
Block(-5,-14,3,CONCRETE:15)
Block(-5,-14,4,CONCRETE:15)
Block(-5,-14,5,CONCRETE:15)
Block(-5,-14,6,CONCRETE:15)
Block(-5,-14,7,CONCRETE:15)
Block(-5,-14,8,CONCRETE:15)
Block(-5,-13,2,CONCRETE:15)
Block(-5,-13,3,CONCRETE:15)
Block(-5,-13,4,CONCRETE:15)
Block(-5,-13,5,CONCRETE:15)
Block(-5,-13,6,CONCRETE:15)
Block(-5,-13,7,CONCRETE:15)
Block(-5,-13,8,CONCRETE:15)
Block(-5,-12,1,CONCRETE:15)
Block(-5,-12,2,CONCRETE:15)
Block(-5,-12,3,CONCRETE:15)
Block(-5,-12,4,CONCRETE:15)
Block(-5,-12,5,CONCRETE:15)
Block(-5,-12,6,CONCRETE:15)
Block(-5,-12,7,CONCRETE:15)
Block(-5,-12,8,CONCRETE:15)
Block(-5,-11,1,CONCRETE:15)
Block(-5,-11,2,CONCRETE:15)
Block(-5,-11,3,CONCRETE:15)
Block(-5,-11,4,CONCRETE:15)
Block(-5,-11,5,CONCRETE:15)
Block(-5,-11,6,CONCRETE:15)
Block(-5,-11,7,CONCRETE:15)
Block(-5,-11,8,CONCRETE:15)
Block(-5,-10,2,CONCRETE:15)
Block(-5,-10,3,CONCRETE:15)
Block(-5,-10,4,CONCRETE:15)
Block(-5,-10,5,CONCRETE:15)
Block(-5,-10,6,CONCRETE:15)
Block(-5,-10,7,CONCRETE:15)
Block(-5,-10,8,CONCRETE:15)
Block(-5,-9,3,CONCRETE:15)
Block(-5,-9,4,CONCRETE:15)
Block(-5,-9,5,CONCRETE:15)
Block(-5,-9,6,CONCRETE:15)
Block(-5,-9,7,CONCRETE:15)
Block(-5,-9,8,CONCRETE:15)
Block(-5,-8,3,CONCRETE:15)
Block(-5,-8,4,CONCRETE:15)
Block(-5,-8,5,CONCRETE:15)
Block(-5,-8,6,CONCRETE:15)
Block(-5,-8,7,CONCRETE:15)
Block(-5,-8,8,CONCRETE:15)
Block(-5,-7,4,CONCRETE:15)
Block(-5,-7,5,CONCRETE:15)
Block(-5,-7,6,CONCRETE:15)
Block(-5,-7,7,CONCRETE:15)
Block(-5,-7,8,CONCRETE:15)
Block(-5,-6,5,CONCRETE:15)
Block(-5,-6,6,CONCRETE:15)
Block(-5,-6,7,CONCRETE:15)
Block(-5,-6,8,CONCRETE:15)
Block(-5,-5,7,CONCRETE:15)
Block(-5,-5,8,CONCRETE:15)
Block(-4,-14,1,CONCRETE:15)
Block(-4,-14,2,CONCRETE:15)
Block(-4,-14,3,CONCRETE:15)
Block(-4,-14,4,CONCRETE:15)
Block(-4,-14,5,CONCRETE:15)
Block(-4,-14,6,CONCRETE:15)
Block(-4,-14,7,CONCRETE:15)
Block(-4,-14,8,CONCRETE:15)
Block(-4,-13,1,CONCRETE:15)
Block(-4,-13,2,CONCRETE:15)
Block(-4,-13,3,CONCRETE:15)
Block(-4,-13,4,CONCRETE:15)
Block(-4,-13,5,CONCRETE:15)
Block(-4,-13,6,CONCRETE:15)
Block(-4,-13,7,CONCRETE:15)
Block(-4,-13,8,CONCRETE:15)
Block(-4,-12,1,CONCRETE:15)
Block(-4,-12,2,CONCRETE:15)
Block(-4,-12,3,CONCRETE:15)
Block(-4,-12,4,CONCRETE:15)
Block(-4,-12,5,CONCRETE:15)
Block(-4,-12,6,CONCRETE:15)
Block(-4,-12,7,CONCRETE:15)
Block(-4,-12,8,CONCRETE:15)
Block(-4,-11,1,CONCRETE:15)
Block(-4,-11,2,CONCRETE:15)
Block(-4,-11,3,CONCRETE:15)
Block(-4,-11,4,CONCRETE:15)
Block(-4,-11,5,CONCRETE:15)
Block(-4,-11,6,CONCRETE:15)
Block(-4,-11,7,CONCRETE:15)
Block(-4,-11,8,CONCRETE:15)
Block(-4,-10,2,CONCRETE:15)
Block(-4,-10,3,CONCRETE:15)
Block(-4,-10,4,CONCRETE:15)
Block(-4,-10,5,CONCRETE:15)
Block(-4,-10,6,CONCRETE:15)
Block(-4,-10,7,CONCRETE:15)
Block(-4,-10,8,CONCRETE:15)
Block(-4,-9,2,CONCRETE:15)
Block(-4,-9,3,CONCRETE:15)
Block(-4,-9,4,CONCRETE:15)
Block(-4,-9,5,CONCRETE:15)
Block(-4,-9,6,CONCRETE:15)
Block(-4,-9,7,CONCRETE:15)
Block(-4,-9,8,CONCRETE:15)
Block(-4,-8,3,CONCRETE:15)
Block(-4,-8,4,CONCRETE:15)
Block(-4,-8,5,CONCRETE:15)
Block(-4,-8,6,CONCRETE:15)
Block(-4,-8,7,CONCRETE:15)
Block(-4,-8,8,CONCRETE:15)
Block(-4,-7,4,CONCRETE:15)
Block(-4,-7,5,CONCRETE:15)
Block(-4,-7,6,CONCRETE:15)
Block(-4,-7,7,CONCRETE:15)
Block(-4,-7,8,CONCRETE:15)
Block(-4,-6,5,CONCRETE:15)
Block(-4,-6,6,CONCRETE:15)
Block(-4,-6,7,CONCRETE:15)
Block(-4,-6,8,CONCRETE:15)
Block(-4,-5,7,CONCRETE:15)
Block(-4,-5,8,CONCRETE:15)
Block(-4,-4,8,CONCRETE:15)
Block(-3,-14,1,CONCRETE:15)
Block(-3,-14,2,CONCRETE:15)
Block(-3,-14,3,CONCRETE:15)
Block(-3,-14,4,CONCRETE:15)
Block(-3,-14,5,CONCRETE:15)
Block(-3,-14,6,CONCRETE:15)
Block(-3,-14,7,CONCRETE:15)
Block(-3,-14,8,CONCRETE:15)
Block(-3,-13,0,CONCRETE:15)
Block(-3,-13,1,CONCRETE:15)
Block(-3,-13,2,CONCRETE:15)
Block(-3,-13,3,CONCRETE:15)
Block(-3,-13,4,CONCRETE:15)
Block(-3,-13,5,CONCRETE:15)
Block(-3,-13,6,CONCRETE:15)
Block(-3,-13,7,CONCRETE:15)
Block(-3,-13,8,CONCRETE:15)
Block(-3,-12,0,CONCRETE:15)
Block(-3,-12,1,CONCRETE:15)
Block(-3,-12,2,CONCRETE:15)
Block(-3,-12,3,CONCRETE:15)
Block(-3,-12,4,CONCRETE:15)
Block(-3,-12,5,CONCRETE:15)
Block(-3,-12,6,CONCRETE:15)
Block(-3,-12,7,CONCRETE:15)
Block(-3,-12,8,CONCRETE:15)
Block(-3,-11,1,CONCRETE:15)
Block(-3,-11,2,CONCRETE:15)
Block(-3,-11,3,CONCRETE:15)
Block(-3,-11,4,CONCRETE:15)
Block(-3,-11,5,CONCRETE:15)
Block(-3,-11,6,CONCRETE:15)
Block(-3,-11,7,CONCRETE:15)
Block(-3,-11,8,CONCRETE:15)
Block(-3,-10,1,CONCRETE:15)
Block(-3,-10,2,CONCRETE:15)
Block(-3,-10,3,CONCRETE:15)
Block(-3,-10,4,CONCRETE:15)
Block(-3,-10,5,CONCRETE:15)
Block(-3,-10,6,CONCRETE:15)
Block(-3,-10,7,CONCRETE:15)
Block(-3,-10,8,CONCRETE:15)
Block(-3,-9,2,CONCRETE:15)
Block(-3,-9,3,CONCRETE:15)
Block(-3,-9,4,CONCRETE:15)
Block(-3,-9,5,CONCRETE:15)
Block(-3,-9,6,CONCRETE:15)
Block(-3,-9,7,CONCRETE:15)
Block(-3,-9,8,CONCRETE:15)
Block(-3,-8,3,CONCRETE:15)
Block(-3,-8,4,CONCRETE:15)
Block(-3,-8,5,CONCRETE:15)
Block(-3,-8,6,CONCRETE:15)
Block(-3,-8,7,CONCRETE:15)
Block(-3,-8,8,CONCRETE:15)
Block(-3,-7,4,CONCRETE:15)
Block(-3,-7,5,CONCRETE:15)
Block(-3,-7,6,CONCRETE:15)
Block(-3,-7,7,CONCRETE:15)
Block(-3,-7,8,CONCRETE:15)
Block(-3,-6,5,CONCRETE:15)
Block(-3,-6,6,CONCRETE:15)
Block(-3,-6,7,CONCRETE:15)
Block(-3,-6,8,CONCRETE:15)
Block(-3,-5,6,CONCRETE:15)
Block(-3,-5,7,CONCRETE:15)
Block(-3,-5,8,CONCRETE:15)
Block(-3,-4,8,CONCRETE:15)
Block(-2,-14,0,CONCRETE:15)
Block(-2,-14,1,CONCRETE:15)
Block(-2,-14,2,CONCRETE:15)
Block(-2,-14,3,CONCRETE:15)
Block(-2,-14,4,CONCRETE:15)
Block(-2,-14,5,CONCRETE:15)
Block(-2,-14,6,CONCRETE:15)
Block(-2,-14,7,CONCRETE:15)
Block(-2,-14,8,CONCRETE:15)
Block(-2,-13,0,CONCRETE:15)
Block(-2,-13,1,CONCRETE:15)
Block(-2,-13,2,CONCRETE:15)
Block(-2,-13,3,CONCRETE:15)
Block(-2,-13,4,CONCRETE:15)
Block(-2,-13,5,CONCRETE:15)
Block(-2,-13,6,CONCRETE:15)
Block(-2,-13,7,CONCRETE:15)
Block(-2,-13,8,CONCRETE:15)
Block(-2,-12,0,CONCRETE:15)
Block(-2,-12,1,CONCRETE:15)
Block(-2,-12,2,CONCRETE:15)
Block(-2,-12,3,CONCRETE:15)
Block(-2,-12,4,CONCRETE:15)
Block(-2,-12,5,CONCRETE:15)
Block(-2,-12,6,CONCRETE:15)
Block(-2,-12,7,CONCRETE:15)
Block(-2,-12,8,CONCRETE:15)
Block(-2,-11,1,CONCRETE:15)
Block(-2,-11,2,CONCRETE:15)
Block(-2,-11,3,CONCRETE:15)
Block(-2,-11,4,CONCRETE:15)
Block(-2,-11,5,CONCRETE:15)
Block(-2,-11,6,CONCRETE:15)
Block(-2,-11,7,CONCRETE:15)
Block(-2,-11,8,CONCRETE:15)
Block(-2,-10,1,CONCRETE:15)
Block(-2,-10,2,CONCRETE:15)
Block(-2,-10,3,CONCRETE:15)
Block(-2,-10,4,CONCRETE:15)
Block(-2,-10,5,CONCRETE:15)
Block(-2,-10,6,CONCRETE:15)
Block(-2,-10,7,CONCRETE:15)
Block(-2,-10,8,CONCRETE:15)
Block(-2,-9,2,CONCRETE:15)
Block(-2,-9,3,CONCRETE:15)
Block(-2,-9,4,CONCRETE:15)
Block(-2,-9,5,CONCRETE:15)
Block(-2,-9,6,CONCRETE:15)
Block(-2,-9,7,CONCRETE:15)
Block(-2,-9,8,CONCRETE:15)
Block(-2,-8,3,CONCRETE:15)
Block(-2,-8,4,CONCRETE:15)
Block(-2,-8,5,CONCRETE:15)
Block(-2,-8,6,CONCRETE:15)
Block(-2,-8,7,CONCRETE:15)
Block(-2,-8,8,CONCRETE:15)
Block(-2,-7,3,CONCRETE:15)
Block(-2,-7,4,CONCRETE:15)
Block(-2,-7,5,CONCRETE:15)
Block(-2,-7,6,CONCRETE:15)
Block(-2,-7,7,CONCRETE:15)
Block(-2,-7,8,CONCRETE:15)
Block(-2,-6,4,CONCRETE:15)
Block(-2,-6,5,CONCRETE:15)
Block(-2,-6,6,CONCRETE:15)
Block(-2,-6,7,CONCRETE:15)
Block(-2,-6,8,CONCRETE:15)
Block(-2,-5,6,CONCRETE:15)
Block(-2,-5,7,CONCRETE:15)
Block(-2,-5,8,CONCRETE:15)
Block(-2,-4,8,CONCRETE:15)
Block(-1,-14,0,CONCRETE:15)
Block(-1,-14,1,CONCRETE:15)
Block(-1,-14,2,CONCRETE:15)
Block(-1,-14,3,CONCRETE:15)
Block(-1,-14,4,CONCRETE:15)
Block(-1,-14,5,CONCRETE:15)
Block(-1,-14,6,CONCRETE:15)
Block(-1,-14,7,CONCRETE:15)
Block(-1,-14,8,CONCRETE:15)
Block(-1,-13,-1,CONCRETE:15)
Block(-1,-13,0,CONCRETE:15)
Block(-1,-13,1,CONCRETE:15)
Block(-1,-13,2,CONCRETE:15)
Block(-1,-13,3,CONCRETE:15)
Block(-1,-13,4,CONCRETE:15)
Block(-1,-13,5,CONCRETE:15)
Block(-1,-13,6,CONCRETE:15)
Block(-1,-13,7,CONCRETE:15)
Block(-1,-13,8,CONCRETE:15)
Block(-1,-12,0,CONCRETE:15)
Block(-1,-12,1,CONCRETE:15)
Block(-1,-12,2,CONCRETE:15)
Block(-1,-12,3,CONCRETE:15)
Block(-1,-12,4,CONCRETE:15)
Block(-1,-12,5,CONCRETE:15)
Block(-1,-12,6,CONCRETE:15)
Block(-1,-12,7,CONCRETE:15)
Block(-1,-12,8,CONCRETE:15)
Block(-1,-11,0,CONCRETE:15)
Block(-1,-11,1,CONCRETE:15)
Block(-1,-11,2,CONCRETE:15)
Block(-1,-11,3,CONCRETE:15)
Block(-1,-11,4,CONCRETE:15)
Block(-1,-11,5,CONCRETE:15)
Block(-1,-11,6,CONCRETE:15)
Block(-1,-11,7,CONCRETE:15)
Block(-1,-11,8,CONCRETE:15)
Block(-1,-10,1,CONCRETE:15)
Block(-1,-10,2,CONCRETE:15)
Block(-1,-10,3,CONCRETE:15)
Block(-1,-10,4,CONCRETE:15)
Block(-1,-10,5,CONCRETE:15)
Block(-1,-10,6,CONCRETE:15)
Block(-1,-10,7,CONCRETE:15)
Block(-1,-10,8,CONCRETE:15)
Block(-1,-9,2,CONCRETE:15)
Block(-1,-9,3,CONCRETE:15)
Block(-1,-9,4,CONCRETE:15)
Block(-1,-9,5,CONCRETE:15)
Block(-1,-9,6,CONCRETE:15)
Block(-1,-9,7,CONCRETE:15)
Block(-1,-9,8,CONCRETE:15)
Block(-1,-8,2,CONCRETE:15)
Block(-1,-8,3,CONCRETE:15)
Block(-1,-8,4,CONCRETE:15)
Block(-1,-8,5,CONCRETE:15)
Block(-1,-8,6,CONCRETE:15)
Block(-1,-8,7,CONCRETE:15)
Block(-1,-8,8,CONCRETE:15)
Block(-1,-7,3,CONCRETE:15)
Block(-1,-7,4,CONCRETE:15)
Block(-1,-7,5,CONCRETE:15)
Block(-1,-7,6,CONCRETE:15)
Block(-1,-7,7,CONCRETE:15)
Block(-1,-7,8,CONCRETE:15)
Block(-1,-6,4,CONCRETE:15)
Block(-1,-6,5,CONCRETE:15)
Block(-1,-6,6,CONCRETE:15)
Block(-1,-6,7,CONCRETE:15)
Block(-1,-6,8,CONCRETE:15)
Block(-1,-5,6,CONCRETE:15)
Block(-1,-5,7,CONCRETE:15)
Block(-1,-5,8,CONCRETE:15)
Block(-1,-4,7,CONCRETE:15)
Block(-1,-4,8,CONCRETE:15)
Block(0,-14,-1,CONCRETE:15)
Block(0,-14,0,CONCRETE:15)
Block(0,-14,1,CONCRETE:15)
Block(0,-14,2,CONCRETE:15)
Block(0,-14,3,CONCRETE:15)
Block(0,-14,4,CONCRETE:15)
Block(0,-14,5,CONCRETE:15)
Block(0,-14,6,CONCRETE:15)
Block(0,-14,7,CONCRETE:15)
Block(0,-14,8,CONCRETE:15)
Block(0,-13,-1,CONCRETE:15)
Block(0,-13,0,CONCRETE:15)
Block(0,-13,1,CONCRETE:15)
Block(0,-13,2,CONCRETE:15)
Block(0,-13,3,CONCRETE:15)
Block(0,-13,4,CONCRETE:15)
Block(0,-13,5,CONCRETE:15)
Block(0,-13,6,CONCRETE:15)
Block(0,-13,7,CONCRETE:15)
Block(0,-13,8,CONCRETE:15)
Block(0,-12,-1,CONCRETE:15)
Block(0,-12,0,CONCRETE:15)
Block(0,-12,1,CONCRETE:15)
Block(0,-12,2,CONCRETE:15)
Block(0,-12,3,CONCRETE:15)
Block(0,-12,4,CONCRETE:15)
Block(0,-12,5,CONCRETE:15)
Block(0,-12,6,CONCRETE:15)
Block(0,-12,7,CONCRETE:15)
Block(0,-12,8,CONCRETE:15)
Block(0,-11,0,CONCRETE:15)
Block(0,-11,1,CONCRETE:15)
Block(0,-11,2,CONCRETE:15)
Block(0,-11,3,CONCRETE:15)
Block(0,-11,4,CONCRETE:15)
Block(0,-11,5,CONCRETE:15)
Block(0,-11,6,CONCRETE:15)
Block(0,-11,7,CONCRETE:15)
Block(0,-11,8,CONCRETE:15)
Block(0,-10,1,CONCRETE:15)
Block(0,-10,2,CONCRETE:15)
Block(0,-10,3,CONCRETE:15)
Block(0,-10,4,CONCRETE:15)
Block(0,-10,5,CONCRETE:15)
Block(0,-10,6,CONCRETE:15)
Block(0,-10,7,CONCRETE:15)
Block(0,-10,8,CONCRETE:15)
Block(0,-9,1,CONCRETE:15)
Block(0,-9,2,CONCRETE:15)
Block(0,-9,3,CONCRETE:15)
Block(0,-9,4,CONCRETE:15)
Block(0,-9,5,CONCRETE:15)
Block(0,-9,6,CONCRETE:15)
Block(0,-9,7,CONCRETE:15)
Block(0,-9,8,CONCRETE:15)
Block(0,-8,2,CONCRETE:15)
Block(0,-8,3,CONCRETE:15)
Block(0,-8,4,CONCRETE:15)
Block(0,-8,5,CONCRETE:15)
Block(0,-8,6,CONCRETE:15)
Block(0,-8,7,CONCRETE:15)
Block(0,-8,8,CONCRETE:15)
Block(0,-7,3,CONCRETE:15)
Block(0,-7,4,CONCRETE:15)
Block(0,-7,5,CONCRETE:15)
Block(0,-7,6,CONCRETE:15)
Block(0,-7,7,CONCRETE:15)
Block(0,-7,8,CONCRETE:15)
Block(0,-6,3,CONCRETE:15)
Block(0,-6,4,CONCRETE:15)
Block(0,-6,5,CONCRETE:15)
Block(0,-6,6,CONCRETE:15)
Block(0,-6,7,CONCRETE:15)
Block(0,-6,8,CONCRETE:15)
Block(0,-5,5,CONCRETE:15)
Block(0,-5,6,CONCRETE:15)
Block(0,-5,7,CONCRETE:15)
Block(0,-5,8,CONCRETE:15)
Block(0,-4,7,CONCRETE:15)
Block(0,-4,8,CONCRETE:15)
Block(1,-14,-1,CONCRETE:15)
Block(1,-14,0,CONCRETE:15)
Block(1,-14,1,CONCRETE:15)
Block(1,-14,2,CONCRETE:15)
Block(1,-14,3,CONCRETE:15)
Block(1,-14,4,CONCRETE:15)
Block(1,-14,5,CONCRETE:15)
Block(1,-14,6,CONCRETE:15)
Block(1,-14,7,CONCRETE:15)
Block(1,-14,8,CONCRETE:15)
Block(1,-13,-2,CONCRETE:15)
Block(1,-13,-1,CONCRETE:15)
Block(1,-13,0,CONCRETE:15)
Block(1,-13,1,CONCRETE:15)
Block(1,-13,2,CONCRETE:15)
Block(1,-13,3,CONCRETE:15)
Block(1,-13,4,CONCRETE:15)
Block(1,-13,5,CONCRETE:15)
Block(1,-13,6,CONCRETE:15)
Block(1,-13,7,CONCRETE:15)
Block(1,-13,8,CONCRETE:15)
Block(1,-12,-1,CONCRETE:15)
Block(1,-12,0,CONCRETE:15)
Block(1,-12,1,CONCRETE:15)
Block(1,-12,2,CONCRETE:15)
Block(1,-12,3,CONCRETE:15)
Block(1,-12,4,CONCRETE:15)
Block(1,-12,5,CONCRETE:15)
Block(1,-12,6,CONCRETE:15)
Block(1,-12,7,CONCRETE:15)
Block(1,-12,8,CONCRETE:15)
Block(1,-11,0,CONCRETE:15)
Block(1,-11,1,CONCRETE:15)
Block(1,-11,2,CONCRETE:15)
Block(1,-11,3,CONCRETE:15)
Block(1,-11,4,CONCRETE:15)
Block(1,-11,5,CONCRETE:15)
Block(1,-11,6,CONCRETE:15)
Block(1,-11,7,CONCRETE:15)
Block(1,-11,8,CONCRETE:15)
Block(1,-10,0,CONCRETE:15)
Block(1,-10,1,CONCRETE:15)
Block(1,-10,2,CONCRETE:15)
Block(1,-10,3,CONCRETE:15)
Block(1,-10,4,CONCRETE:15)
Block(1,-10,5,CONCRETE:15)
Block(1,-10,6,CONCRETE:15)
Block(1,-10,7,CONCRETE:15)
Block(1,-10,8,CONCRETE:15)
Block(1,-9,1,CONCRETE:15)
Block(1,-9,2,CONCRETE:15)
Block(1,-9,3,CONCRETE:15)
Block(1,-9,4,CONCRETE:15)
Block(1,-9,5,CONCRETE:15)
Block(1,-9,6,CONCRETE:15)
Block(1,-9,7,CONCRETE:15)
Block(1,-9,8,CONCRETE:15)
Block(1,-8,2,CONCRETE:15)
Block(1,-8,3,CONCRETE:15)
Block(1,-8,4,CONCRETE:15)
Block(1,-8,5,CONCRETE:15)
Block(1,-8,6,CONCRETE:15)
Block(1,-8,7,CONCRETE:15)
Block(1,-8,8,CONCRETE:15)
Block(1,-7,3,CONCRETE:15)
Block(1,-7,4,CONCRETE:15)
Block(1,-7,5,CONCRETE:15)
Block(1,-7,6,CONCRETE:15)
Block(1,-7,7,CONCRETE:15)
Block(1,-7,8,CONCRETE:15)
Block(1,-6,4,CONCRETE:15)
Block(1,-6,5,CONCRETE:15)
Block(1,-6,6,CONCRETE:15)
Block(1,-6,7,CONCRETE:15)
Block(1,-6,8,CONCRETE:15)
Block(1,-5,6,CONCRETE:15)
Block(1,-5,7,CONCRETE:15)
Block(1,-5,8,CONCRETE:15)
Block(1,-4,7,CONCRETE:15)
Block(1,-4,8,CONCRETE:15)
Block(2,-14,-2,CONCRETE:15)
Block(2,-14,-1,CONCRETE:15)
Block(2,-14,0,CONCRETE:15)
Block(2,-14,1,CONCRETE:15)
Block(2,-14,2,CONCRETE:15)
Block(2,-14,3,CONCRETE:15)
Block(2,-14,4,CONCRETE:15)
Block(2,-14,5,CONCRETE:15)
Block(2,-14,6,CONCRETE:15)
Block(2,-14,7,CONCRETE:15)
Block(2,-14,8,CONCRETE:15)
Block(2,-13,-2,CONCRETE:15)
Block(2,-13,-1,CONCRETE:15)
Block(2,-13,0,CONCRETE:15)
Block(2,-13,1,CONCRETE:15)
Block(2,-13,2,CONCRETE:15)
Block(2,-13,3,CONCRETE:15)
Block(2,-13,4,CONCRETE:15)
Block(2,-13,5,CONCRETE:15)
Block(2,-13,6,CONCRETE:15)
Block(2,-13,7,CONCRETE:15)
Block(2,-13,8,CONCRETE:15)
Block(2,-12,-1,CONCRETE:15)
Block(2,-12,0,CONCRETE:15)
Block(2,-12,1,CONCRETE:15)
Block(2,-12,2,CONCRETE:15)
Block(2,-12,3,CONCRETE:15)
Block(2,-12,4,CONCRETE:15)
Block(2,-12,5,CONCRETE:15)
Block(2,-12,6,CONCRETE:15)
Block(2,-12,7,CONCRETE:15)
Block(2,-12,8,CONCRETE:15)
Block(2,-11,-1,CONCRETE:15)
Block(2,-11,0,CONCRETE:15)
Block(2,-11,1,CONCRETE:15)
Block(2,-11,2,CONCRETE:15)
Block(2,-11,3,CONCRETE:15)
Block(2,-11,4,CONCRETE:15)
Block(2,-11,5,CONCRETE:15)
Block(2,-11,6,CONCRETE:15)
Block(2,-11,7,CONCRETE:15)
Block(2,-11,8,CONCRETE:15)
Block(2,-10,0,CONCRETE:15)
Block(2,-10,1,CONCRETE:15)
Block(2,-10,2,CONCRETE:15)
Block(2,-10,3,CONCRETE:15)
Block(2,-10,4,CONCRETE:15)
Block(2,-10,5,CONCRETE:15)
Block(2,-10,6,CONCRETE:15)
Block(2,-10,7,CONCRETE:15)
Block(2,-10,8,CONCRETE:15)
Block(2,-9,1,CONCRETE:15)
Block(2,-9,2,CONCRETE:15)
Block(2,-9,3,CONCRETE:15)
Block(2,-9,4,CONCRETE:15)
Block(2,-9,5,CONCRETE:15)
Block(2,-9,6,CONCRETE:15)
Block(2,-9,7,CONCRETE:15)
Block(2,-9,8,CONCRETE:15)
Block(2,-8,2,CONCRETE:15)
Block(2,-8,3,CONCRETE:15)
Block(2,-8,4,CONCRETE:15)
Block(2,-8,5,CONCRETE:15)
Block(2,-8,6,CONCRETE:15)
Block(2,-8,7,CONCRETE:15)
Block(2,-8,8,CONCRETE:15)
Block(2,-7,4,CONCRETE:15)
Block(2,-7,5,CONCRETE:15)
Block(2,-7,6,CONCRETE:15)
Block(2,-7,7,CONCRETE:15)
Block(2,-7,8,CONCRETE:15)
Block(2,-6,5,CONCRETE:15)
Block(2,-6,6,CONCRETE:15)
Block(2,-6,7,CONCRETE:15)
Block(2,-6,8,CONCRETE:15)
Block(2,-5,7,CONCRETE:15)
Block(2,-5,8,CONCRETE:15)
Block(2,-4,8,CONCRETE:15)
Block(3,-14,-2,CONCRETE:15)
Block(3,-14,-1,CONCRETE:15)
Block(3,-14,0,CONCRETE:15)
Block(3,-14,1,CONCRETE:15)
Block(3,-14,2,CONCRETE:15)
Block(3,-14,3,CONCRETE:15)
Block(3,-14,4,CONCRETE:15)
Block(3,-14,5,CONCRETE:15)
Block(3,-14,6,CONCRETE:15)
Block(3,-14,7,CONCRETE:15)
Block(3,-14,8,CONCRETE:15)
Block(3,-13,-2,CONCRETE:15)
Block(3,-13,-1,CONCRETE:15)
Block(3,-13,0,CONCRETE:15)
Block(3,-13,1,CONCRETE:15)
Block(3,-13,2,CONCRETE:15)
Block(3,-13,3,CONCRETE:15)
Block(3,-13,4,CONCRETE:15)
Block(3,-13,5,CONCRETE:15)
Block(3,-13,6,CONCRETE:15)
Block(3,-13,7,CONCRETE:15)
Block(3,-13,8,CONCRETE:15)
Block(3,-12,-2,CONCRETE:15)
Block(3,-12,-1,CONCRETE:15)
Block(3,-12,0,CONCRETE:15)
Block(3,-12,1,CONCRETE:15)
Block(3,-12,2,CONCRETE:15)
Block(3,-12,3,CONCRETE:15)
Block(3,-12,4,CONCRETE:15)
Block(3,-12,5,CONCRETE:15)
Block(3,-12,6,CONCRETE:15)
Block(3,-12,7,CONCRETE:15)
Block(3,-12,8,CONCRETE:15)
Block(3,-11,-1,CONCRETE:15)
Block(3,-11,0,CONCRETE:15)
Block(3,-11,1,CONCRETE:15)
Block(3,-11,2,CONCRETE:15)
Block(3,-11,3,CONCRETE:15)
Block(3,-11,4,CONCRETE:15)
Block(3,-11,5,CONCRETE:15)
Block(3,-11,6,CONCRETE:15)
Block(3,-11,7,CONCRETE:15)
Block(3,-11,8,CONCRETE:15)
Block(3,-10,0,CONCRETE:15)
Block(3,-10,1,CONCRETE:15)
Block(3,-10,2,CONCRETE:15)
Block(3,-10,3,CONCRETE:15)
Block(3,-10,4,CONCRETE:15)
Block(3,-10,5,CONCRETE:15)
Block(3,-10,6,CONCRETE:15)
Block(3,-10,7,CONCRETE:15)
Block(3,-10,8,CONCRETE:15)
Block(3,-9,2,CONCRETE:15)
Block(3,-9,3,CONCRETE:15)
Block(3,-9,4,CONCRETE:15)
Block(3,-9,5,CONCRETE:15)
Block(3,-9,6,CONCRETE:15)
Block(3,-9,7,CONCRETE:15)
Block(3,-9,8,CONCRETE:15)
Block(3,-8,3,CONCRETE:15)
Block(3,-8,4,CONCRETE:15)
Block(3,-8,5,CONCRETE:15)
Block(3,-8,6,CONCRETE:15)
Block(3,-8,7,CONCRETE:15)
Block(3,-8,8,CONCRETE:15)
Block(3,-7,5,CONCRETE:15)
Block(3,-7,6,CONCRETE:15)
Block(3,-7,7,CONCRETE:15)
Block(3,-7,8,CONCRETE:15)
Block(3,-6,6,CONCRETE:15)
Block(3,-6,7,CONCRETE:15)
Block(3,-6,8,CONCRETE:15)
Block(3,-5,8,CONCRETE:15)
Block(4,-14,-3,CONCRETE:15)
Block(4,-14,-2,CONCRETE:15)
Block(4,-14,-1,CONCRETE:15)
Block(4,-14,0,CONCRETE:15)
Block(4,-14,1,CONCRETE:15)
Block(4,-14,2,CONCRETE:15)
Block(4,-14,3,CONCRETE:15)
Block(4,-14,4,CONCRETE:15)
Block(4,-14,5,CONCRETE:15)
Block(4,-13,-3,CONCRETE:15)
Block(4,-13,-2,CONCRETE:15)
Block(4,-13,-1,CONCRETE:15)
Block(4,-13,0,CONCRETE:15)
Block(4,-13,1,CONCRETE:15)
Block(4,-13,2,CONCRETE:15)
Block(4,-13,3,CONCRETE:15)
Block(4,-13,4,CONCRETE:15)
Block(4,-13,5,CONCRETE:15)
Block(4,-13,6,CONCRETE:15)
Block(4,-13,7,CONCRETE:15)
Block(4,-13,8,CONCRETE:15)
Block(4,-12,-2,CONCRETE:15)
Block(4,-12,-1,CONCRETE:15)
Block(4,-12,0,CONCRETE:15)
Block(4,-12,1,CONCRETE:15)
Block(4,-12,2,CONCRETE:15)
Block(4,-12,3,CONCRETE:15)
Block(4,-12,4,CONCRETE:15)
Block(4,-12,5,CONCRETE:15)
Block(4,-12,6,CONCRETE:15)
Block(4,-12,7,CONCRETE:15)
Block(4,-12,8,CONCRETE:15)
Block(4,-11,0,CONCRETE:15)
Block(4,-11,1,CONCRETE:15)
Block(4,-11,2,CONCRETE:15)
Block(4,-11,3,CONCRETE:15)
Block(4,-11,4,CONCRETE:15)
Block(4,-11,5,CONCRETE:15)
Block(4,-11,6,CONCRETE:15)
Block(4,-11,7,CONCRETE:15)
Block(4,-11,8,CONCRETE:15)
Block(4,-10,1,CONCRETE:15)
Block(4,-10,2,CONCRETE:15)
Block(4,-10,3,CONCRETE:15)
Block(4,-10,4,CONCRETE:15)
Block(4,-10,5,CONCRETE:15)
Block(4,-10,6,CONCRETE:15)
Block(4,-10,7,CONCRETE:15)
Block(4,-10,8,CONCRETE:15)
Block(4,-9,3,CONCRETE:15)
Block(4,-9,4,CONCRETE:15)
Block(4,-9,5,CONCRETE:15)
Block(4,-9,6,CONCRETE:15)
Block(4,-9,7,CONCRETE:15)
Block(4,-9,8,CONCRETE:15)
Block(4,-8,4,CONCRETE:15)
Block(4,-8,5,CONCRETE:15)
Block(4,-8,6,CONCRETE:15)
Block(4,-8,7,CONCRETE:15)
Block(4,-8,8,CONCRETE:15)
Block(4,-7,6,CONCRETE:15)
Block(4,-7,7,CONCRETE:15)
Block(4,-7,8,CONCRETE:15)
Block(4,-6,7,CONCRETE:15)
Block(4,-6,8,CONCRETE:15)
Block(5,-14,-4,CONCRETE:15)
Block(5,-13,-2,CONCRETE:15)
Block(5,-13,-1,CONCRETE:15)
Block(5,-13,0,CONCRETE:15)
Block(5,-13,1,CONCRETE:15)
Block(5,-13,2,CONCRETE:15)
Block(5,-13,3,CONCRETE:15)
Block(5,-12,-1,CONCRETE:15)
Block(5,-12,0,CONCRETE:15)
Block(5,-12,1,CONCRETE:15)
Block(5,-12,2,CONCRETE:15)
Block(5,-12,3,CONCRETE:15)
Block(5,-12,4,CONCRETE:15)
Block(5,-12,5,CONCRETE:15)
Block(5,-12,6,CONCRETE:15)
Block(5,-12,7,CONCRETE:15)
Block(5,-12,8,CONCRETE:15)
Block(5,-11,1,CONCRETE:15)
Block(5,-11,2,CONCRETE:15)
Block(5,-11,3,CONCRETE:15)
Block(5,-11,4,CONCRETE:15)
Block(5,-11,5,CONCRETE:15)
Block(5,-11,6,CONCRETE:15)
Block(5,-11,7,CONCRETE:15)
Block(5,-11,8,CONCRETE:15)
Block(5,-10,2,CONCRETE:15)
Block(5,-10,3,CONCRETE:15)
Block(5,-10,4,CONCRETE:15)
Block(5,-10,5,CONCRETE:15)
Block(5,-10,6,CONCRETE:15)
Block(5,-10,7,CONCRETE:15)
Block(5,-10,8,CONCRETE:15)
Block(5,-9,4,CONCRETE:15)
Block(5,-9,5,CONCRETE:15)
Block(5,-9,6,CONCRETE:15)
Block(5,-9,7,CONCRETE:15)
Block(5,-9,8,CONCRETE:15)
Block(5,-8,5,CONCRETE:15)
Block(5,-8,6,CONCRETE:15)
Block(5,-8,7,CONCRETE:15)
Block(5,-8,8,CONCRETE:15)
Block(5,-7,7,CONCRETE:15)
Block(5,-7,8,CONCRETE:15)
Block(5,-6,8,CONCRETE:15)
Block(6,-12,0,CONCRETE:15)
Block(6,-11,2,CONCRETE:15)
Block(6,-11,3,CONCRETE:15)
Block(6,-11,4,CONCRETE:15)
Block(6,-11,5,CONCRETE:15)
Block(6,-11,6,CONCRETE:15)
Block(6,-11,7,CONCRETE:15)
Block(6,-10,3,CONCRETE:15)
Block(6,-10,4,CONCRETE:15)
Block(6,-10,5,CONCRETE:15)
Block(6,-10,6,CONCRETE:15)
Block(6,-10,7,CONCRETE:15)
Block(6,-10,8,CONCRETE:15)
Block(6,-9,5,CONCRETE:15)
Block(6,-9,6,CONCRETE:15)
Block(6,-9,7,CONCRETE:15)
Block(6,-9,8,CONCRETE:15)
Block(6,-8,6,CONCRETE:15)
Block(6,-8,7,CONCRETE:15)
Block(6,-8,8,CONCRETE:15)
Block(6,-7,8,CONCRETE:15)
Block(7,-10,4,CONCRETE:15)
Block(7,-10,5,CONCRETE:15)
Block(7,-9,6,CONCRETE:15)
Block(7,-9,7,CONCRETE:15)
Block(7,-9,8,CONCRETE:15)
Block(7,-8,7,CONCRETE:15)
Block(7,-8,8,CONCRETE:15)

#######################################################################
# +-----------------------------------------------------------------+ #
# |                             Branches                            | #
# +-----------------------------------------------------------------+ #
#######################################################################

Branch(16,0,0,true,MountainRockBlack_Huge_01C3R0,NORTH,100.0,0)

#######################################################################
# +-----------------------------------------------------------------+ #
# |                             Entities                            | #
# +-----------------------------------------------------------------+ #
#######################################################################


#######################################################################
# +-----------------------------------------------------------------+ #
# |                            Particles                            | #
# +-----------------------------------------------------------------+ #
#######################################################################


#######################################################################
# +-----------------------------------------------------------------+ #
# |                             Spawners                            | #
# +-----------------------------------------------------------------+ #
#######################################################################


#######################################################################
# +-----------------------------------------------------------------+ #
# |                             ModData                             | #
# +-----------------------------------------------------------------+ #
#######################################################################

