
#######################################################################
# +-----------------------------------------------------------------+ #
# |                            BO4 object                           | #
# +-----------------------------------------------------------------+ #
#######################################################################

Author: NLBlackEagle

Description: No description given

SettingsMode: WriteDisable


#######################################################################
# +-----------------------------------------------------------------+ #
# |                          Main settings                          | #
# +-----------------------------------------------------------------+ #
#######################################################################

Frequency: 0

SpawnHeight: highestBlock

UseCenterForHighestBlock: true

##############################
# Height Limits for the BO4. #
##############################

MinHeight: 0

MaxHeight: 255

InheritBO3: 

InheritBO3Rotation: NORTH

OverrideChildSettings: true

OverrideParentHeight: false

CanOverride: false

BranchFrequency: 0

BranchFrequencyGroup: 

MustBeBelowOther: false

MustBeInside: 

CannotBeInside: 

ReplacesBO3: 

MustBeInsideWorldBorders: false

CanSpawnOnWater: true

SpawnOnWaterOnly: false

SpawnUnderWater: false

SpawnAtWaterLevel: false

HeightOffset: 0

RemoveAir: true

ReplaceAbove: 

ReplaceBelow: 

ReplaceWithBiomeBlocks: true

ReplaceWithSurfaceBlock: GRASS

ReplaceWithGroundBlock: DIRT

ReplaceWithStoneBlock: STONE

SmoothRadius: 0

SmoothHeightOffset: 0

SmoothStartTop: false

SmoothStartWood: false

SmoothingSurfaceBlock: 

SmoothingGroundBlock: 

BO3Group: 

IsSpawnPoint: false

DoReplaceBlocks: true


#######################################################################
# +-----------------------------------------------------------------+ #
# |                              Blocks                             | #
# +-----------------------------------------------------------------+ #
#######################################################################

Block(0,19,-7,PACKED_ICE:0)
Block(0,19,-4,PACKED_ICE:0)
Block(1,18,-7,PACKED_ICE:0)
Block(1,18,-4,PACKED_ICE:0)
Block(1,18,-3,PACKED_ICE:0)
Block(1,19,-7,PACKED_ICE:0)
Block(1,19,-6,PACKED_ICE:0)
Block(1,19,-5,PACKED_ICE:0)
Block(1,19,-4,PACKED_ICE:0)
Block(1,19,-3,PACKED_ICE:0)
Block(1,19,-2,PACKED_ICE:0)
Block(1,19,-1,PACKED_ICE:0)
Block(1,20,-7,PACKED_ICE:0)
Block(1,20,-6,PACKED_ICE:0)
Block(1,20,-5,PACKED_ICE:0)
Block(1,20,-4,PACKED_ICE:0)
Block(1,20,-3,PACKED_ICE:0)
Block(1,20,-2,PACKED_ICE:0)
Block(1,21,-4,PACKED_ICE:0)
Block(2,17,-7,PACKED_ICE:0)
Block(2,17,-5,PACKED_ICE:0)
Block(2,17,-4,PACKED_ICE:0)
Block(2,17,-2,PACKED_ICE:0)
Block(2,18,-7,PACKED_ICE:0)
Block(2,18,-6,PACKED_ICE:0)
Block(2,18,-5,PACKED_ICE:0)
Block(2,18,-4,PACKED_ICE:0)
Block(2,18,-3,PACKED_ICE:0)
Block(2,18,-2,PACKED_ICE:0)
Block(2,19,-7,PACKED_ICE:0)
Block(2,19,-6,PACKED_ICE:0)
Block(2,19,-5,PACKED_ICE:0)
Block(2,19,-4,PACKED_ICE:0)
Block(2,19,-3,PACKED_ICE:0)
Block(2,19,-2,PACKED_ICE:0)
Block(2,19,-1,PACKED_ICE:0)
Block(2,19,0,PACKED_ICE:0)
Block(2,19,1,PACKED_ICE:0)
Block(2,20,-7,PACKED_ICE:0)
Block(2,20,-6,PACKED_ICE:0)
Block(2,20,-5,PACKED_ICE:0)
Block(2,20,-4,PACKED_ICE:0)
Block(2,20,-3,PACKED_ICE:0)
Block(2,20,-2,PACKED_ICE:0)
Block(2,20,-1,PACKED_ICE:0)
Block(2,21,-7,PACKED_ICE:0)
Block(2,21,-5,PACKED_ICE:0)
Block(2,21,-2,PACKED_ICE:0)
Block(3,16,-7,PACKED_ICE:0)
Block(3,16,-5,PACKED_ICE:0)
Block(3,16,-4,PACKED_ICE:0)
Block(3,16,-2,PACKED_ICE:0)
Block(3,17,-7,PACKED_ICE:0)
Block(3,17,-6,PACKED_ICE:0)
Block(3,17,-5,PACKED_ICE:0)
Block(3,17,-4,PACKED_ICE:0)
Block(3,17,-3,PACKED_ICE:0)
Block(3,17,-2,PACKED_ICE:0)
Block(3,17,-1,PACKED_ICE:0)
Block(3,18,-7,PACKED_ICE:0)
Block(3,18,-6,PACKED_ICE:0)
Block(3,18,-5,PACKED_ICE:0)
Block(3,18,-4,PACKED_ICE:0)
Block(3,18,-3,PACKED_ICE:0)
Block(3,18,-2,PACKED_ICE:0)
Block(3,18,-1,PACKED_ICE:0)
Block(3,18,0,PACKED_ICE:0)
Block(3,18,1,PACKED_ICE:0)
Block(3,19,-7,PACKED_ICE:0)
Block(3,19,-6,PACKED_ICE:0)
Block(3,19,-5,PACKED_ICE:0)
Block(3,19,-4,PACKED_ICE:0)
Block(3,19,-3,PACKED_ICE:0)
Block(3,19,-2,PACKED_ICE:0)
Block(3,19,-1,PACKED_ICE:0)
Block(3,19,0,PACKED_ICE:0)
Block(3,19,1,PACKED_ICE:0)
Block(3,19,2,PACKED_ICE:0)
Block(3,19,3,PACKED_ICE:0)
Block(3,20,-7,PACKED_ICE:0)
Block(3,20,-6,PACKED_ICE:0)
Block(3,20,-5,PACKED_ICE:0)
Block(3,20,-4,PACKED_ICE:0)
Block(3,20,-3,PACKED_ICE:0)
Block(3,20,-2,PACKED_ICE:0)
Block(3,20,-1,PACKED_ICE:0)
Block(3,20,0,PACKED_ICE:0)
Block(3,20,1,PACKED_ICE:0)
Block(3,20,2,PACKED_ICE:0)
Block(3,21,-7,PACKED_ICE:0)
Block(3,21,-6,PACKED_ICE:0)
Block(3,21,-5,PACKED_ICE:0)
Block(3,21,-4,PACKED_ICE:0)
Block(3,21,-3,PACKED_ICE:0)
Block(3,21,-2,PACKED_ICE:0)
Block(3,21,-1,PACKED_ICE:0)
Block(3,22,-7,ICE:0)
Block(3,22,-6,PACKED_ICE:0)
Block(3,22,-5,PACKED_ICE:0)
Block(3,22,-4,ICE:0)
Block(3,22,-3,PACKED_ICE:0)
Block(3,22,-2,ICE:0)
Block(4,16,-7,PACKED_ICE:0)
Block(4,16,-6,PACKED_ICE:0)
Block(4,16,-5,PACKED_ICE:0)
Block(4,16,-4,PACKED_ICE:0)
Block(4,16,-3,PACKED_ICE:0)
Block(4,16,-2,PACKED_ICE:0)
Block(4,16,-1,PACKED_ICE:0)
Block(4,16,0,PACKED_ICE:0)
Block(4,17,-7,PACKED_ICE:0)
Block(4,17,-6,PACKED_ICE:0)
Block(4,17,-5,PACKED_ICE:0)
Block(4,17,-4,PACKED_ICE:0)
Block(4,17,-3,PACKED_ICE:0)
Block(4,17,-2,PACKED_ICE:0)
Block(4,17,-1,PACKED_ICE:0)
Block(4,17,0,PACKED_ICE:0)
Block(4,17,1,PACKED_ICE:0)
Block(4,17,2,PACKED_ICE:0)
Block(4,18,-7,PACKED_ICE:0)
Block(4,18,-6,PACKED_ICE:0)
Block(4,18,-5,PACKED_ICE:0)
Block(4,18,-4,PACKED_ICE:0)
Block(4,18,-3,PACKED_ICE:0)
Block(4,18,-2,PACKED_ICE:0)
Block(4,18,-1,PACKED_ICE:0)
Block(4,18,0,PACKED_ICE:0)
Block(4,18,1,PACKED_ICE:0)
Block(4,18,2,PACKED_ICE:0)
Block(4,19,-7,PACKED_ICE:0)
Block(4,19,-6,PACKED_ICE:0)
Block(4,19,-5,PACKED_ICE:0)
Block(4,19,-4,PACKED_ICE:0)
Block(4,19,-3,PACKED_ICE:0)
Block(4,19,-2,PACKED_ICE:0)
Block(4,19,-1,PACKED_ICE:0)
Block(4,19,0,PACKED_ICE:0)
Block(4,19,1,PACKED_ICE:0)
Block(4,19,2,PACKED_ICE:0)
Block(4,19,3,PACKED_ICE:0)
Block(4,20,-7,PACKED_ICE:0)
Block(4,20,-6,PACKED_ICE:0)
Block(4,20,-5,PACKED_ICE:0)
Block(4,20,-4,PACKED_ICE:0)
Block(4,20,-3,PACKED_ICE:0)
Block(4,20,-2,PACKED_ICE:0)
Block(4,20,-1,PACKED_ICE:0)
Block(4,20,0,PACKED_ICE:0)
Block(4,20,1,PACKED_ICE:0)
Block(4,20,2,PACKED_ICE:0)
Block(4,20,3,PACKED_ICE:0)
Block(4,21,-7,PACKED_ICE:0)
Block(4,21,-6,PACKED_ICE:0)
Block(4,21,-5,PACKED_ICE:0)
Block(4,21,-4,PACKED_ICE:0)
Block(4,21,-3,PACKED_ICE:0)
Block(4,21,-2,PACKED_ICE:0)
Block(4,21,-1,PACKED_ICE:0)
Block(4,21,0,PACKED_ICE:0)
Block(4,21,2,PACKED_ICE:0)
Block(4,22,-7,ICE:0)
Block(4,22,-6,PACKED_ICE:0)
Block(4,22,-5,PACKED_ICE:0)
Block(4,22,-4,PACKED_ICE:0)
Block(4,22,-3,PACKED_ICE:0)
Block(4,22,-2,ICE:0)
Block(4,22,-1,PACKED_ICE:0)
Block(4,23,-5,PACKED_ICE:0)
Block(4,23,-3,PACKED_ICE:0)
Block(5,17,2,PACKED_ICE:0)
Block(5,18,-7,PACKED_ICE:0)
Block(5,18,-6,PACKED_ICE:0)
Block(5,18,-5,PACKED_ICE:0)
Block(5,18,-4,PACKED_ICE:0)
Block(5,18,-3,PACKED_ICE:0)
Block(5,18,-2,PACKED_ICE:0)
Block(5,18,-1,PACKED_ICE:0)
Block(5,18,0,PACKED_ICE:0)
Block(5,18,1,PACKED_ICE:0)
Block(5,18,2,PACKED_ICE:0)
Block(5,18,3,PACKED_ICE:0)
Block(5,19,-7,PACKED_ICE:0)
Block(5,19,-6,PACKED_ICE:0)
Block(5,19,-5,PACKED_ICE:0)
Block(5,19,-4,PACKED_ICE:0)
Block(5,19,-3,PACKED_ICE:0)
Block(5,19,-2,PACKED_ICE:0)
Block(5,19,-1,PACKED_ICE:0)
Block(5,19,0,PACKED_ICE:0)
Block(5,19,1,PACKED_ICE:0)
Block(5,19,2,PACKED_ICE:0)
Block(5,19,3,PACKED_ICE:0)
Block(5,19,4,PACKED_ICE:0)
Block(5,20,-7,PACKED_ICE:0)
Block(5,20,-6,PACKED_ICE:0)
Block(5,20,-5,PACKED_ICE:0)
Block(5,20,-4,PACKED_ICE:0)
Block(5,20,-3,PACKED_ICE:0)
Block(5,20,-2,PACKED_ICE:0)
Block(5,20,-1,PACKED_ICE:0)
Block(5,20,0,PACKED_ICE:0)
Block(5,20,1,PACKED_ICE:0)
Block(5,20,2,PACKED_ICE:0)
Block(5,20,3,PACKED_ICE:0)
Block(5,21,-7,PACKED_ICE:0)
Block(5,21,-6,PACKED_ICE:0)
Block(5,21,-5,PACKED_ICE:0)
Block(5,21,-4,PACKED_ICE:0)
Block(5,21,-3,PACKED_ICE:0)
Block(5,21,-2,PACKED_ICE:0)
Block(5,21,-1,PACKED_ICE:0)
Block(5,21,0,PACKED_ICE:0)
Block(5,21,1,PACKED_ICE:0)
Block(5,21,2,PACKED_ICE:0)
Block(5,21,3,PACKED_ICE:0)
Block(5,22,-7,PACKED_ICE:0)
Block(5,22,-6,ICE:0)
Block(5,22,-5,PACKED_ICE:0)
Block(5,22,-4,PACKED_ICE:0)
Block(5,22,-3,PACKED_ICE:0)
Block(5,22,-2,PACKED_ICE:0)
Block(5,22,-1,PACKED_ICE:0)
Block(5,22,0,ICE:0)
Block(5,22,1,PACKED_ICE:0)
Block(5,23,-7,ICE:0)
Block(5,23,-6,ICE:0)
Block(5,23,-5,ICE:0)
Block(5,23,-4,PACKED_ICE:0)
Block(5,23,-3,PACKED_ICE:0)
Block(5,23,-2,PACKED_ICE:0)
Block(5,24,-7,ICE:0)
Block(5,24,-5,ICE:0)
Block(5,24,-3,ICE:0)
Block(6,17,2,PACKED_ICE:0)
Block(6,18,-7,PACKED_ICE:0)
Block(6,18,-6,PACKED_ICE:0)
Block(6,18,-5,PACKED_ICE:0)
Block(6,18,-4,PACKED_ICE:0)
Block(6,18,-3,PACKED_ICE:0)
Block(6,18,-2,PACKED_ICE:0)
Block(6,18,-1,PACKED_ICE:0)
Block(6,18,0,PACKED_ICE:0)
Block(6,18,1,PACKED_ICE:0)
Block(6,18,2,PACKED_ICE:0)
Block(6,18,3,PACKED_ICE:0)
Block(6,19,-7,PACKED_ICE:0)
Block(6,19,-6,PACKED_ICE:0)
Block(6,19,-5,PACKED_ICE:0)
Block(6,19,-4,PACKED_ICE:0)
Block(6,19,-3,PACKED_ICE:0)
Block(6,19,-2,PACKED_ICE:0)
Block(6,19,-1,PACKED_ICE:0)
Block(6,19,0,PACKED_ICE:0)
Block(6,19,1,PACKED_ICE:0)
Block(6,19,2,PACKED_ICE:0)
Block(6,19,3,PACKED_ICE:0)
Block(6,19,4,PACKED_ICE:0)
Block(6,20,-7,PACKED_ICE:0)
Block(6,20,-6,PACKED_ICE:0)
Block(6,20,-5,PACKED_ICE:0)
Block(6,20,-4,PACKED_ICE:0)
Block(6,20,-3,PACKED_ICE:0)
Block(6,20,-2,PACKED_ICE:0)
Block(6,20,-1,PACKED_ICE:0)
Block(6,20,0,PACKED_ICE:0)
Block(6,20,1,PACKED_ICE:0)
Block(6,20,2,PACKED_ICE:0)
Block(6,20,3,PACKED_ICE:0)
Block(6,20,4,PACKED_ICE:0)
Block(6,21,-7,PACKED_ICE:0)
Block(6,21,-6,PACKED_ICE:0)
Block(6,21,-5,PACKED_ICE:0)
Block(6,21,-4,PACKED_ICE:0)
Block(6,21,-3,PACKED_ICE:0)
Block(6,21,-2,PACKED_ICE:0)
Block(6,21,-1,PACKED_ICE:0)
Block(6,21,0,PACKED_ICE:0)
Block(6,21,1,PACKED_ICE:0)
Block(6,21,2,PACKED_ICE:0)
Block(6,22,-7,PACKED_ICE:0)
Block(6,22,-6,ICE:0)
Block(6,22,-5,PACKED_ICE:0)
Block(6,22,-4,ICE:0)
Block(6,22,-3,PACKED_ICE:0)
Block(6,22,-2,PACKED_ICE:0)
Block(6,22,-1,PACKED_ICE:0)
Block(6,22,0,ICE:0)
Block(6,22,1,PACKED_ICE:0)
Block(6,22,2,ICE:0)
Block(6,23,-7,ICE:0)
Block(6,23,-6,ICE:0)
Block(6,23,-5,ICE:0)
Block(6,23,-4,ICE:0)
Block(6,23,-3,PACKED_ICE:0)
Block(6,23,-2,PACKED_ICE:0)
Block(6,23,-1,PACKED_ICE:0)
Block(6,23,0,ICE:0)
Block(6,24,-7,ICE:0)
Block(6,24,-6,ICE:0)
Block(6,24,-5,ICE:0)
Block(6,24,-4,ICE:0)
Block(6,24,-3,PACKED_ICE:0)
Block(6,24,-2,PACKED_ICE:0)
Block(6,25,-5,ICE:0)
Block(7,17,2,PACKED_ICE:0)
Block(7,17,3,PACKED_ICE:0)
Block(7,18,-7,PACKED_ICE:0)
Block(7,18,-6,PACKED_ICE:0)
Block(7,18,-5,PACKED_ICE:0)
Block(7,18,-4,PACKED_ICE:0)
Block(7,18,-3,PACKED_ICE:0)
Block(7,18,-2,PACKED_ICE:0)
Block(7,18,-1,PACKED_ICE:0)
Block(7,18,0,PACKED_ICE:0)
Block(7,18,1,PACKED_ICE:0)
Block(7,18,2,PACKED_ICE:0)
Block(7,18,3,PACKED_ICE:0)
Block(7,18,4,PACKED_ICE:0)
Block(7,19,-7,PACKED_ICE:0)
Block(7,19,-6,PACKED_ICE:0)
Block(7,19,-5,PACKED_ICE:0)
Block(7,19,-4,PACKED_ICE:0)
Block(7,19,-3,PACKED_ICE:0)
Block(7,19,-2,PACKED_ICE:0)
Block(7,19,-1,PACKED_ICE:0)
Block(7,19,0,PACKED_ICE:0)
Block(7,19,1,PACKED_ICE:0)
Block(7,19,2,PACKED_ICE:0)
Block(7,19,3,PACKED_ICE:0)
Block(7,19,4,PACKED_ICE:0)
Block(7,20,-7,PACKED_ICE:0)
Block(7,20,-6,PACKED_ICE:0)
Block(7,20,-5,PACKED_ICE:0)
Block(7,20,-4,PACKED_ICE:0)
Block(7,20,-3,PACKED_ICE:0)
Block(7,20,-2,PACKED_ICE:0)
Block(7,20,-1,PACKED_ICE:0)
Block(7,20,0,PACKED_ICE:0)
Block(7,20,1,PACKED_ICE:0)
Block(7,20,2,PACKED_ICE:0)
Block(7,20,3,PACKED_ICE:0)
Block(7,20,4,PACKED_ICE:0)
Block(7,21,-7,PACKED_ICE:0)
Block(7,21,-6,PACKED_ICE:0)
Block(7,21,-5,PACKED_ICE:0)
Block(7,21,-4,PACKED_ICE:0)
Block(7,21,-3,PACKED_ICE:0)
Block(7,21,-2,PACKED_ICE:0)
Block(7,21,-1,PACKED_ICE:0)
Block(7,21,0,PACKED_ICE:0)
Block(7,21,1,PACKED_ICE:0)
Block(7,21,2,PACKED_ICE:0)
Block(7,21,3,PACKED_ICE:0)
Block(7,22,-7,PACKED_ICE:0)
Block(7,22,-6,ICE:0)
Block(7,22,-5,PACKED_ICE:0)
Block(7,22,-4,PACKED_ICE:0)
Block(7,22,-3,PACKED_ICE:0)
Block(7,22,-2,PACKED_ICE:0)
Block(7,22,-1,ICE:0)
Block(7,22,0,ICE:0)
Block(7,22,1,ICE:0)
Block(7,22,2,PACKED_ICE:0)
Block(7,23,-7,ICE:0)
Block(7,23,-6,ICE:0)
Block(7,23,-5,ICE:0)
Block(7,23,-4,PACKED_ICE:0)
Block(7,23,-3,PACKED_ICE:0)
Block(7,23,-2,PACKED_ICE:0)
Block(7,23,-1,ICE:0)
Block(7,23,0,ICE:0)
Block(7,24,-7,ICE:0)
Block(7,24,-6,PACKED_ICE:0)
Block(7,24,-5,PACKED_ICE:0)
Block(7,24,-4,ICE:0)
Block(7,24,-3,PACKED_ICE:0)
Block(7,24,-2,ICE:0)
Block(7,24,-1,PACKED_ICE:0)
Block(7,25,-7,PACKED_ICE:0)
Block(7,25,-6,PACKED_ICE:0)
Block(7,25,-5,ICE:0)
Block(7,25,-4,PACKED_ICE:0)
Block(7,25,-3,ICE:0)
Block(7,25,-2,PACKED_ICE:0)
Block(7,26,-3,ICE:0)

#######################################################################
# +-----------------------------------------------------------------+ #
# |                             Branches                            | #
# +-----------------------------------------------------------------+ #
#######################################################################


#######################################################################
# +-----------------------------------------------------------------+ #
# |                             Entities                            | #
# +-----------------------------------------------------------------+ #
#######################################################################


#######################################################################
# +-----------------------------------------------------------------+ #
# |                            Particles                            | #
# +-----------------------------------------------------------------+ #
#######################################################################


#######################################################################
# +-----------------------------------------------------------------+ #
# |                             Spawners                            | #
# +-----------------------------------------------------------------+ #
#######################################################################


#######################################################################
# +-----------------------------------------------------------------+ #
# |                             ModData                             | #
# +-----------------------------------------------------------------+ #
#######################################################################

