
#######################################################################
# +-----------------------------------------------------------------+ #
# |                            BO4 object                           | #
# +-----------------------------------------------------------------+ #
#######################################################################

Author: NLBlackEagle

Description: No description given

SettingsMode: WriteDisable


#######################################################################
# +-----------------------------------------------------------------+ #
# |                          Main settings                          | #
# +-----------------------------------------------------------------+ #
#######################################################################

Frequency: 0

SpawnHeight: highestBlock

UseCenterForHighestBlock: true

##############################
# Height Limits for the BO4. #
##############################

MinHeight: 0

MaxHeight: 255

InheritBO3: 

InheritBO3Rotation: NORTH

OverrideChildSettings: true

OverrideParentHeight: false

CanOverride: false

BranchFrequency: 0

BranchFrequencyGroup: 

MustBeBelowOther: false

MustBeInside: 

CannotBeInside: 

ReplacesBO3: 

MustBeInsideWorldBorders: false

CanSpawnOnWater: true

SpawnOnWaterOnly: false

SpawnUnderWater: false

SpawnAtWaterLevel: false

HeightOffset: 0

RemoveAir: true

ReplaceAbove: 

ReplaceBelow: 

ReplaceWithBiomeBlocks: true

ReplaceWithSurfaceBlock: GRASS

ReplaceWithGroundBlock: DIRT

ReplaceWithStoneBlock: STONE

SmoothRadius: 0

SmoothHeightOffset: 0

SmoothStartTop: false

SmoothStartWood: false

SmoothingSurfaceBlock: 

SmoothingGroundBlock: 

BO3Group: 

IsSpawnPoint: false

DoReplaceBlocks: true


#######################################################################
# +-----------------------------------------------------------------+ #
# |                              Blocks                             | #
# +-----------------------------------------------------------------+ #
#######################################################################

Block(-8,17,2,PACKED_ICE:0)
Block(-8,17,3,PACKED_ICE:0)
Block(-8,18,-7,PACKED_ICE:0)
Block(-8,18,-6,PACKED_ICE:0)
Block(-8,18,-5,PACKED_ICE:0)
Block(-8,18,-4,PACKED_ICE:0)
Block(-8,18,-3,PACKED_ICE:0)
Block(-8,18,-2,PACKED_ICE:0)
Block(-8,18,-1,PACKED_ICE:0)
Block(-8,18,0,PACKED_ICE:0)
Block(-8,18,1,PACKED_ICE:0)
Block(-8,18,2,PACKED_ICE:0)
Block(-8,18,3,PACKED_ICE:0)
Block(-8,19,-7,PACKED_ICE:0)
Block(-8,19,-6,PACKED_ICE:0)
Block(-8,19,-5,PACKED_ICE:0)
Block(-8,19,-4,PACKED_ICE:0)
Block(-8,19,-3,PACKED_ICE:0)
Block(-8,19,-2,PACKED_ICE:0)
Block(-8,19,-1,PACKED_ICE:0)
Block(-8,19,0,PACKED_ICE:0)
Block(-8,19,1,PACKED_ICE:0)
Block(-8,19,2,PACKED_ICE:0)
Block(-8,19,3,PACKED_ICE:0)
Block(-8,19,4,PACKED_ICE:0)
Block(-8,20,-7,PACKED_ICE:0)
Block(-8,20,-6,PACKED_ICE:0)
Block(-8,20,-5,PACKED_ICE:0)
Block(-8,20,-4,PACKED_ICE:0)
Block(-8,20,-3,PACKED_ICE:0)
Block(-8,20,-2,PACKED_ICE:0)
Block(-8,20,-1,PACKED_ICE:0)
Block(-8,20,0,PACKED_ICE:0)
Block(-8,20,1,PACKED_ICE:0)
Block(-8,20,2,PACKED_ICE:0)
Block(-8,20,3,PACKED_ICE:0)
Block(-8,21,-7,PACKED_ICE:0)
Block(-8,21,-6,PACKED_ICE:0)
Block(-8,21,-5,PACKED_ICE:0)
Block(-8,21,-4,PACKED_ICE:0)
Block(-8,21,-3,PACKED_ICE:0)
Block(-8,21,-2,PACKED_ICE:0)
Block(-8,21,-1,PACKED_ICE:0)
Block(-8,21,0,PACKED_ICE:0)
Block(-8,21,1,PACKED_ICE:0)
Block(-8,21,2,PACKED_ICE:0)
Block(-8,22,-7,ICE:0)
Block(-8,22,-6,ICE:0)
Block(-8,22,-5,PACKED_ICE:0)
Block(-8,22,-4,PACKED_ICE:0)
Block(-8,22,-3,ICE:0)
Block(-8,22,-2,ICE:0)
Block(-8,22,-1,ICE:0)
Block(-8,22,0,ICE:0)
Block(-8,22,1,ICE:0)
Block(-8,22,2,PACKED_ICE:0)
Block(-8,23,-7,ICE:0)
Block(-8,23,-6,ICE:0)
Block(-8,23,-5,ICE:0)
Block(-8,23,-4,PACKED_ICE:0)
Block(-8,23,-3,ICE:0)
Block(-8,23,-2,ICE:0)
Block(-8,23,-1,ICE:0)
Block(-8,23,0,ICE:0)
Block(-8,24,-7,ICE:0)
Block(-8,24,-6,ICE:0)
Block(-8,24,-5,ICE:0)
Block(-8,24,-4,PACKED_ICE:0)
Block(-8,24,-3,ICE:0)
Block(-8,24,-2,ICE:0)
Block(-8,24,-1,ICE:0)
Block(-8,25,-7,ICE:0)
Block(-8,25,-6,ICE:0)
Block(-8,25,-5,ICE:0)
Block(-8,25,-4,PACKED_ICE:0)
Block(-8,25,-3,ICE:0)
Block(-8,25,-2,ICE:0)
Block(-8,26,-6,ICE:0)
Block(-8,26,-5,ICE:0)
Block(-8,27,-6,PACKED_ICE:0)
Block(-8,27,-3,ICE:0)
Block(-7,17,2,PACKED_ICE:0)
Block(-7,18,-7,PACKED_ICE:0)
Block(-7,18,-6,PACKED_ICE:0)
Block(-7,18,-5,PACKED_ICE:0)
Block(-7,18,-4,PACKED_ICE:0)
Block(-7,18,-3,PACKED_ICE:0)
Block(-7,18,-2,PACKED_ICE:0)
Block(-7,18,-1,PACKED_ICE:0)
Block(-7,18,0,PACKED_ICE:0)
Block(-7,18,1,PACKED_ICE:0)
Block(-7,18,2,PACKED_ICE:0)
Block(-7,18,3,PACKED_ICE:0)
Block(-7,19,-7,PACKED_ICE:0)
Block(-7,19,-6,PACKED_ICE:0)
Block(-7,19,-5,PACKED_ICE:0)
Block(-7,19,-4,PACKED_ICE:0)
Block(-7,19,-3,PACKED_ICE:0)
Block(-7,19,-2,PACKED_ICE:0)
Block(-7,19,-1,PACKED_ICE:0)
Block(-7,19,0,PACKED_ICE:0)
Block(-7,19,1,PACKED_ICE:0)
Block(-7,19,2,PACKED_ICE:0)
Block(-7,19,3,PACKED_ICE:0)
Block(-7,19,4,PACKED_ICE:0)
Block(-7,20,-7,PACKED_ICE:0)
Block(-7,20,-6,PACKED_ICE:0)
Block(-7,20,-5,PACKED_ICE:0)
Block(-7,20,-4,PACKED_ICE:0)
Block(-7,20,-3,PACKED_ICE:0)
Block(-7,20,-2,PACKED_ICE:0)
Block(-7,20,-1,PACKED_ICE:0)
Block(-7,20,0,PACKED_ICE:0)
Block(-7,20,1,PACKED_ICE:0)
Block(-7,20,2,PACKED_ICE:0)
Block(-7,20,3,PACKED_ICE:0)
Block(-7,21,-7,PACKED_ICE:0)
Block(-7,21,-6,PACKED_ICE:0)
Block(-7,21,-5,PACKED_ICE:0)
Block(-7,21,-4,PACKED_ICE:0)
Block(-7,21,-3,PACKED_ICE:0)
Block(-7,21,-2,PACKED_ICE:0)
Block(-7,21,-1,PACKED_ICE:0)
Block(-7,21,0,PACKED_ICE:0)
Block(-7,21,1,PACKED_ICE:0)
Block(-7,21,2,PACKED_ICE:0)
Block(-7,21,3,PACKED_ICE:0)
Block(-7,22,-7,ICE:0)
Block(-7,22,-6,ICE:0)
Block(-7,22,-5,ICE:0)
Block(-7,22,-4,ICE:0)
Block(-7,22,-3,ICE:0)
Block(-7,22,-2,PACKED_ICE:0)
Block(-7,22,-1,PACKED_ICE:0)
Block(-7,22,0,ICE:0)
Block(-7,22,1,ICE:0)
Block(-7,22,2,PACKED_ICE:0)
Block(-7,23,-7,ICE:0)
Block(-7,23,-6,ICE:0)
Block(-7,23,-5,ICE:0)
Block(-7,23,-4,ICE:0)
Block(-7,23,-3,ICE:0)
Block(-7,23,-2,ICE:0)
Block(-7,23,-1,ICE:0)
Block(-7,24,-7,ICE:0)
Block(-7,24,-6,ICE:0)
Block(-7,24,-5,PACKED_ICE:0)
Block(-7,24,-4,PACKED_ICE:0)
Block(-7,24,-3,PACKED_ICE:0)
Block(-7,24,-2,ICE:0)
Block(-7,25,-7,ICE:0)
Block(-7,25,-6,ICE:0)
Block(-7,25,-5,ICE:0)
Block(-7,25,-4,ICE:0)
Block(-7,25,-3,ICE:0)
Block(-7,25,-2,PACKED_ICE:0)
Block(-7,26,-7,ICE:0)
Block(-7,26,-6,PACKED_ICE:0)
Block(-7,26,-5,ICE:0)
Block(-7,26,-4,PACKED_ICE:0)
Block(-7,26,-2,PACKED_ICE:0)
Block(-7,27,-6,PACKED_ICE:0)
Block(-7,27,-5,ICE:0)
Block(-7,28,-6,PACKED_ICE:0)
Block(-7,28,-5,PACKED_ICE:0)
Block(-7,29,-5,PACKED_ICE:0)
Block(-6,18,-7,PACKED_ICE:0)
Block(-6,18,-6,PACKED_ICE:0)
Block(-6,18,-5,PACKED_ICE:0)
Block(-6,18,-4,PACKED_ICE:0)
Block(-6,18,-3,PACKED_ICE:0)
Block(-6,18,-2,PACKED_ICE:0)
Block(-6,18,-1,PACKED_ICE:0)
Block(-6,18,0,PACKED_ICE:0)
Block(-6,18,1,PACKED_ICE:0)
Block(-6,18,2,PACKED_ICE:0)
Block(-6,19,-7,PACKED_ICE:0)
Block(-6,19,-6,PACKED_ICE:0)
Block(-6,19,-5,PACKED_ICE:0)
Block(-6,19,-4,PACKED_ICE:0)
Block(-6,19,-3,PACKED_ICE:0)
Block(-6,19,-2,PACKED_ICE:0)
Block(-6,19,-1,PACKED_ICE:0)
Block(-6,19,0,PACKED_ICE:0)
Block(-6,19,1,PACKED_ICE:0)
Block(-6,19,2,PACKED_ICE:0)
Block(-6,19,3,PACKED_ICE:0)
Block(-6,20,-7,PACKED_ICE:0)
Block(-6,20,-6,PACKED_ICE:0)
Block(-6,20,-5,PACKED_ICE:0)
Block(-6,20,-4,PACKED_ICE:0)
Block(-6,20,-3,PACKED_ICE:0)
Block(-6,20,-2,PACKED_ICE:0)
Block(-6,20,-1,PACKED_ICE:0)
Block(-6,20,0,PACKED_ICE:0)
Block(-6,20,1,PACKED_ICE:0)
Block(-6,20,2,PACKED_ICE:0)
Block(-6,20,3,PACKED_ICE:0)
Block(-6,21,-7,PACKED_ICE:0)
Block(-6,21,-6,PACKED_ICE:0)
Block(-6,21,-5,PACKED_ICE:0)
Block(-6,21,-4,PACKED_ICE:0)
Block(-6,21,-3,PACKED_ICE:0)
Block(-6,21,-2,PACKED_ICE:0)
Block(-6,21,-1,PACKED_ICE:0)
Block(-6,21,0,PACKED_ICE:0)
Block(-6,21,1,PACKED_ICE:0)
Block(-6,21,2,PACKED_ICE:0)
Block(-6,22,-7,ICE:0)
Block(-6,22,-6,ICE:0)
Block(-6,22,-5,ICE:0)
Block(-6,22,-4,ICE:0)
Block(-6,22,-3,PACKED_ICE:0)
Block(-6,22,-2,PACKED_ICE:0)
Block(-6,22,-1,PACKED_ICE:0)
Block(-6,22,0,ICE:0)
Block(-6,22,1,ICE:0)
Block(-6,23,-7,ICE:0)
Block(-6,23,-6,ICE:0)
Block(-6,23,-5,ICE:0)
Block(-6,23,-4,ICE:0)
Block(-6,23,-3,ICE:0)
Block(-6,23,-2,PACKED_ICE:0)
Block(-6,23,-1,PACKED_ICE:0)
Block(-6,23,0,PACKED_ICE:0)
Block(-6,23,1,PACKED_ICE:0)
Block(-6,24,-7,PACKED_ICE:0)
Block(-6,24,-6,PACKED_ICE:0)
Block(-6,24,-5,PACKED_ICE:0)
Block(-6,24,-4,PACKED_ICE:0)
Block(-6,24,-3,PACKED_ICE:0)
Block(-6,24,-2,PACKED_ICE:0)
Block(-6,24,-1,PACKED_ICE:0)
Block(-6,25,-7,PACKED_ICE:0)
Block(-6,25,-6,PACKED_ICE:0)
Block(-6,25,-5,ICE:0)
Block(-6,25,-4,ICE:0)
Block(-6,25,-3,PACKED_ICE:0)
Block(-6,25,-2,PACKED_ICE:0)
Block(-6,25,-1,ICE:0)
Block(-6,26,-5,ICE:0)
Block(-6,26,-4,ICE:0)
Block(-6,26,-3,PACKED_ICE:0)
Block(-6,27,-5,ICE:0)
Block(-5,18,-7,PACKED_ICE:0)
Block(-5,18,-6,PACKED_ICE:0)
Block(-5,18,-5,PACKED_ICE:0)
Block(-5,18,-4,PACKED_ICE:0)
Block(-5,18,-3,PACKED_ICE:0)
Block(-5,18,-2,PACKED_ICE:0)
Block(-5,18,-1,PACKED_ICE:0)
Block(-5,18,0,PACKED_ICE:0)
Block(-5,18,1,PACKED_ICE:0)
Block(-5,18,2,PACKED_ICE:0)
Block(-5,18,3,PACKED_ICE:0)
Block(-5,19,-7,PACKED_ICE:0)
Block(-5,19,-6,PACKED_ICE:0)
Block(-5,19,-5,PACKED_ICE:0)
Block(-5,19,-4,PACKED_ICE:0)
Block(-5,19,-3,PACKED_ICE:0)
Block(-5,19,-2,PACKED_ICE:0)
Block(-5,19,-1,PACKED_ICE:0)
Block(-5,19,0,PACKED_ICE:0)
Block(-5,19,1,PACKED_ICE:0)
Block(-5,19,2,PACKED_ICE:0)
Block(-5,19,3,PACKED_ICE:0)
Block(-5,19,4,PACKED_ICE:0)
Block(-5,20,-7,PACKED_ICE:0)
Block(-5,20,-6,PACKED_ICE:0)
Block(-5,20,-5,PACKED_ICE:0)
Block(-5,20,-4,PACKED_ICE:0)
Block(-5,20,-3,PACKED_ICE:0)
Block(-5,20,-2,PACKED_ICE:0)
Block(-5,20,-1,PACKED_ICE:0)
Block(-5,20,0,PACKED_ICE:0)
Block(-5,20,1,PACKED_ICE:0)
Block(-5,20,2,PACKED_ICE:0)
Block(-5,20,3,PACKED_ICE:0)
Block(-5,21,-7,PACKED_ICE:0)
Block(-5,21,-6,PACKED_ICE:0)
Block(-5,21,-5,PACKED_ICE:0)
Block(-5,21,-4,PACKED_ICE:0)
Block(-5,21,-3,PACKED_ICE:0)
Block(-5,21,-2,PACKED_ICE:0)
Block(-5,21,-1,PACKED_ICE:0)
Block(-5,21,0,PACKED_ICE:0)
Block(-5,21,1,PACKED_ICE:0)
Block(-5,21,2,PACKED_ICE:0)
Block(-5,22,-7,ICE:0)
Block(-5,22,-6,ICE:0)
Block(-5,22,-5,ICE:0)
Block(-5,22,-4,ICE:0)
Block(-5,22,-3,ICE:0)
Block(-5,22,-2,ICE:0)
Block(-5,22,-1,PACKED_ICE:0)
Block(-5,22,0,ICE:0)
Block(-5,22,1,PACKED_ICE:0)
Block(-5,23,-7,ICE:0)
Block(-5,23,-6,ICE:0)
Block(-5,23,-5,ICE:0)
Block(-5,23,-4,ICE:0)
Block(-5,23,-3,ICE:0)
Block(-5,23,-2,ICE:0)
Block(-5,23,-1,PACKED_ICE:0)
Block(-5,23,0,ICE:0)
Block(-5,24,-7,PACKED_ICE:0)
Block(-5,24,-6,PACKED_ICE:0)
Block(-5,24,-5,ICE:0)
Block(-5,24,-4,ICE:0)
Block(-5,24,-3,ICE:0)
Block(-5,24,-2,ICE:0)
Block(-5,24,-1,PACKED_ICE:0)
Block(-5,25,-7,ICE:0)
Block(-5,25,-6,ICE:0)
Block(-5,25,-5,ICE:0)
Block(-5,25,-4,ICE:0)
Block(-5,25,-3,ICE:0)
Block(-5,25,-2,ICE:0)
Block(-5,25,-1,ICE:0)
Block(-5,26,-4,PACKED_ICE:0)
Block(-5,26,-2,ICE:0)
Block(-4,18,-7,PACKED_ICE:0)
Block(-4,18,-6,PACKED_ICE:0)
Block(-4,18,-5,PACKED_ICE:0)
Block(-4,18,-4,PACKED_ICE:0)
Block(-4,18,-3,PACKED_ICE:0)
Block(-4,18,-2,PACKED_ICE:0)
Block(-4,18,-1,PACKED_ICE:0)
Block(-4,18,0,PACKED_ICE:0)
Block(-4,18,1,PACKED_ICE:0)
Block(-4,18,2,PACKED_ICE:0)
Block(-4,18,3,PACKED_ICE:0)
Block(-4,18,4,PACKED_ICE:0)
Block(-4,19,-7,PACKED_ICE:0)
Block(-4,19,-6,PACKED_ICE:0)
Block(-4,19,-5,PACKED_ICE:0)
Block(-4,19,-4,PACKED_ICE:0)
Block(-4,19,-3,PACKED_ICE:0)
Block(-4,19,-2,PACKED_ICE:0)
Block(-4,19,-1,PACKED_ICE:0)
Block(-4,19,0,PACKED_ICE:0)
Block(-4,19,1,PACKED_ICE:0)
Block(-4,19,2,PACKED_ICE:0)
Block(-4,19,3,PACKED_ICE:0)
Block(-4,19,4,PACKED_ICE:0)
Block(-4,20,-7,PACKED_ICE:0)
Block(-4,20,-6,PACKED_ICE:0)
Block(-4,20,-5,PACKED_ICE:0)
Block(-4,20,-4,PACKED_ICE:0)
Block(-4,20,-3,PACKED_ICE:0)
Block(-4,20,-2,PACKED_ICE:0)
Block(-4,20,-1,PACKED_ICE:0)
Block(-4,20,0,PACKED_ICE:0)
Block(-4,20,1,PACKED_ICE:0)
Block(-4,20,2,PACKED_ICE:0)
Block(-4,20,3,PACKED_ICE:0)
Block(-4,21,-7,PACKED_ICE:0)
Block(-4,21,-6,PACKED_ICE:0)
Block(-4,21,-5,PACKED_ICE:0)
Block(-4,21,-4,PACKED_ICE:0)
Block(-4,21,-3,PACKED_ICE:0)
Block(-4,21,-2,PACKED_ICE:0)
Block(-4,21,-1,PACKED_ICE:0)
Block(-4,21,0,PACKED_ICE:0)
Block(-4,21,1,PACKED_ICE:0)
Block(-4,22,-7,ICE:0)
Block(-4,22,-6,ICE:0)
Block(-4,22,-5,ICE:0)
Block(-4,22,-4,PACKED_ICE:0)
Block(-4,22,-3,ICE:0)
Block(-4,22,-2,PACKED_ICE:0)
Block(-4,22,-1,PACKED_ICE:0)
Block(-4,22,0,PACKED_ICE:0)
Block(-4,23,-7,ICE:0)
Block(-4,23,-6,ICE:0)
Block(-4,23,-5,ICE:0)
Block(-4,23,-4,ICE:0)
Block(-4,23,-3,ICE:0)
Block(-4,23,-2,ICE:0)
Block(-4,23,-1,PACKED_ICE:0)
Block(-4,23,0,ICE:0)
Block(-4,24,-7,PACKED_ICE:0)
Block(-4,24,-6,PACKED_ICE:0)
Block(-4,24,-5,ICE:0)
Block(-4,24,-4,ICE:0)
Block(-4,24,-3,ICE:0)
Block(-4,24,-2,PACKED_ICE:0)
Block(-4,24,-1,PACKED_ICE:0)
Block(-4,24,0,ICE:0)
Block(-4,25,-7,PACKED_ICE:0)
Block(-4,25,-6,ICE:0)
Block(-4,25,-5,ICE:0)
Block(-4,25,-4,ICE:0)
Block(-4,25,-3,PACKED_ICE:0)
Block(-4,25,-2,ICE:0)
Block(-4,25,-1,ICE:0)
Block(-4,26,-7,PACKED_ICE:0)
Block(-4,26,-4,ICE:0)
Block(-4,26,-2,ICE:0)
Block(-4,27,-4,ICE:0)
Block(-4,27,-3,ICE:0)
Block(-4,28,-4,ICE:0)
Block(-3,18,-7,PACKED_ICE:0)
Block(-3,18,-6,PACKED_ICE:0)
Block(-3,18,-5,PACKED_ICE:0)
Block(-3,18,-4,PACKED_ICE:0)
Block(-3,18,-3,PACKED_ICE:0)
Block(-3,18,-2,PACKED_ICE:0)
Block(-3,18,-1,PACKED_ICE:0)
Block(-3,18,0,PACKED_ICE:0)
Block(-3,18,1,PACKED_ICE:0)
Block(-3,18,2,PACKED_ICE:0)
Block(-3,18,3,PACKED_ICE:0)
Block(-3,18,4,PACKED_ICE:0)
Block(-3,19,-7,PACKED_ICE:0)
Block(-3,19,-6,PACKED_ICE:0)
Block(-3,19,-5,PACKED_ICE:0)
Block(-3,19,-4,PACKED_ICE:0)
Block(-3,19,-3,PACKED_ICE:0)
Block(-3,19,-2,PACKED_ICE:0)
Block(-3,19,-1,PACKED_ICE:0)
Block(-3,19,0,PACKED_ICE:0)
Block(-3,19,1,PACKED_ICE:0)
Block(-3,19,2,PACKED_ICE:0)
Block(-3,19,3,PACKED_ICE:0)
Block(-3,19,4,PACKED_ICE:0)
Block(-3,19,5,PACKED_ICE:0)
Block(-3,20,-7,PACKED_ICE:0)
Block(-3,20,-6,PACKED_ICE:0)
Block(-3,20,-5,PACKED_ICE:0)
Block(-3,20,-4,PACKED_ICE:0)
Block(-3,20,-3,PACKED_ICE:0)
Block(-3,20,-2,PACKED_ICE:0)
Block(-3,20,-1,PACKED_ICE:0)
Block(-3,20,0,PACKED_ICE:0)
Block(-3,20,1,PACKED_ICE:0)
Block(-3,20,2,PACKED_ICE:0)
Block(-3,20,3,PACKED_ICE:0)
Block(-3,20,4,PACKED_ICE:0)
Block(-3,21,-7,PACKED_ICE:0)
Block(-3,21,-6,PACKED_ICE:0)
Block(-3,21,-5,PACKED_ICE:0)
Block(-3,21,-4,PACKED_ICE:0)
Block(-3,21,-3,PACKED_ICE:0)
Block(-3,21,-2,PACKED_ICE:0)
Block(-3,21,-1,PACKED_ICE:0)
Block(-3,21,0,PACKED_ICE:0)
Block(-3,21,1,PACKED_ICE:0)
Block(-3,21,2,PACKED_ICE:0)
Block(-3,22,-7,ICE:0)
Block(-3,22,-6,ICE:0)
Block(-3,22,-5,ICE:0)
Block(-3,22,-4,PACKED_ICE:0)
Block(-3,22,-3,ICE:0)
Block(-3,22,-2,ICE:0)
Block(-3,22,-1,ICE:0)
Block(-3,22,0,PACKED_ICE:0)
Block(-3,22,1,PACKED_ICE:0)
Block(-3,23,-7,ICE:0)
Block(-3,23,-6,ICE:0)
Block(-3,23,-5,ICE:0)
Block(-3,23,-4,ICE:0)
Block(-3,23,-3,ICE:0)
Block(-3,23,-2,ICE:0)
Block(-3,23,-1,ICE:0)
Block(-3,23,0,PACKED_ICE:0)
Block(-3,24,-7,PACKED_ICE:0)
Block(-3,24,-6,PACKED_ICE:0)
Block(-3,24,-5,ICE:0)
Block(-3,24,-4,ICE:0)
Block(-3,24,-3,PACKED_ICE:0)
Block(-3,24,-2,PACKED_ICE:0)
Block(-3,24,-1,PACKED_ICE:0)
Block(-3,25,-7,ICE:0)
Block(-3,25,-6,ICE:0)
Block(-3,25,-5,PACKED_ICE:0)
Block(-3,25,-4,PACKED_ICE:0)
Block(-3,25,-3,PACKED_ICE:0)
Block(-3,25,-2,PACKED_ICE:0)
Block(-3,26,-7,PACKED_ICE:0)
Block(-3,26,-6,PACKED_ICE:0)
Block(-3,26,-3,PACKED_ICE:0)
Block(-3,27,-7,PACKED_ICE:0)
Block(-2,18,-7,PACKED_ICE:0)
Block(-2,18,-6,PACKED_ICE:0)
Block(-2,18,-5,PACKED_ICE:0)
Block(-2,18,-4,PACKED_ICE:0)
Block(-2,18,-3,PACKED_ICE:0)
Block(-2,18,-2,PACKED_ICE:0)
Block(-2,18,-1,PACKED_ICE:0)
Block(-2,18,0,PACKED_ICE:0)
Block(-2,18,1,PACKED_ICE:0)
Block(-2,18,2,PACKED_ICE:0)
Block(-2,18,3,PACKED_ICE:0)
Block(-2,19,-7,PACKED_ICE:0)
Block(-2,19,-6,PACKED_ICE:0)
Block(-2,19,-5,PACKED_ICE:0)
Block(-2,19,-4,PACKED_ICE:0)
Block(-2,19,-3,PACKED_ICE:0)
Block(-2,19,-2,PACKED_ICE:0)
Block(-2,19,-1,PACKED_ICE:0)
Block(-2,19,0,PACKED_ICE:0)
Block(-2,19,1,PACKED_ICE:0)
Block(-2,19,2,PACKED_ICE:0)
Block(-2,19,3,PACKED_ICE:0)
Block(-2,19,4,PACKED_ICE:0)
Block(-2,20,-7,PACKED_ICE:0)
Block(-2,20,-6,PACKED_ICE:0)
Block(-2,20,-5,PACKED_ICE:0)
Block(-2,20,-4,PACKED_ICE:0)
Block(-2,20,-3,PACKED_ICE:0)
Block(-2,20,-2,PACKED_ICE:0)
Block(-2,20,-1,PACKED_ICE:0)
Block(-2,20,0,PACKED_ICE:0)
Block(-2,20,1,PACKED_ICE:0)
Block(-2,20,2,PACKED_ICE:0)
Block(-2,20,3,PACKED_ICE:0)
Block(-2,21,-7,PACKED_ICE:0)
Block(-2,21,-6,PACKED_ICE:0)
Block(-2,21,-5,PACKED_ICE:0)
Block(-2,21,-4,PACKED_ICE:0)
Block(-2,21,-3,PACKED_ICE:0)
Block(-2,21,-2,PACKED_ICE:0)
Block(-2,21,-1,PACKED_ICE:0)
Block(-2,21,0,PACKED_ICE:0)
Block(-2,21,1,PACKED_ICE:0)
Block(-2,21,2,PACKED_ICE:0)
Block(-2,21,3,PACKED_ICE:0)
Block(-2,22,-7,ICE:0)
Block(-2,22,-6,ICE:0)
Block(-2,22,-5,ICE:0)
Block(-2,22,-4,ICE:0)
Block(-2,22,-3,PACKED_ICE:0)
Block(-2,22,-2,ICE:0)
Block(-2,22,-1,ICE:0)
Block(-2,22,0,ICE:0)
Block(-2,22,1,PACKED_ICE:0)
Block(-2,22,2,PACKED_ICE:0)
Block(-2,23,-7,ICE:0)
Block(-2,23,-6,ICE:0)
Block(-2,23,-5,ICE:0)
Block(-2,23,-4,ICE:0)
Block(-2,23,-3,ICE:0)
Block(-2,23,-2,ICE:0)
Block(-2,23,-1,ICE:0)
Block(-2,23,0,ICE:0)
Block(-2,24,-7,ICE:0)
Block(-2,24,-6,ICE:0)
Block(-2,24,-5,ICE:0)
Block(-2,24,-4,PACKED_ICE:0)
Block(-2,24,-3,PACKED_ICE:0)
Block(-2,24,-2,PACKED_ICE:0)
Block(-2,24,-1,PACKED_ICE:0)
Block(-2,25,-7,ICE:0)
Block(-2,25,-6,ICE:0)
Block(-2,25,-5,ICE:0)
Block(-2,25,-4,ICE:0)
Block(-2,25,-3,ICE:0)
Block(-2,25,-2,PACKED_ICE:0)
Block(-2,26,-7,PACKED_ICE:0)
Block(-2,26,-6,PACKED_ICE:0)
Block(-2,26,-5,PACKED_ICE:0)
Block(-2,26,-2,PACKED_ICE:0)
Block(-2,27,-7,PACKED_ICE:0)
Block(-2,27,-6,ICE:0)
Block(-2,27,-4,ICE:0)
Block(-2,27,-3,PACKED_ICE:0)
Block(-2,28,-7,ICE:0)
Block(-1,18,-7,PACKED_ICE:0)
Block(-1,18,-6,PACKED_ICE:0)
Block(-1,18,-5,PACKED_ICE:0)
Block(-1,18,-4,PACKED_ICE:0)
Block(-1,18,-3,PACKED_ICE:0)
Block(-1,18,-2,PACKED_ICE:0)
Block(-1,18,-1,PACKED_ICE:0)
Block(-1,18,0,PACKED_ICE:0)
Block(-1,18,1,PACKED_ICE:0)
Block(-1,18,2,PACKED_ICE:0)
Block(-1,18,3,PACKED_ICE:0)
Block(-1,18,4,PACKED_ICE:0)
Block(-1,19,-7,PACKED_ICE:0)
Block(-1,19,-6,PACKED_ICE:0)
Block(-1,19,-5,PACKED_ICE:0)
Block(-1,19,-4,PACKED_ICE:0)
Block(-1,19,-3,PACKED_ICE:0)
Block(-1,19,-2,PACKED_ICE:0)
Block(-1,19,-1,PACKED_ICE:0)
Block(-1,19,0,PACKED_ICE:0)
Block(-1,19,1,PACKED_ICE:0)
Block(-1,19,2,PACKED_ICE:0)
Block(-1,19,3,PACKED_ICE:0)
Block(-1,19,4,PACKED_ICE:0)
Block(-1,20,-7,PACKED_ICE:0)
Block(-1,20,-6,PACKED_ICE:0)
Block(-1,20,-5,PACKED_ICE:0)
Block(-1,20,-4,PACKED_ICE:0)
Block(-1,20,-3,PACKED_ICE:0)
Block(-1,20,-2,PACKED_ICE:0)
Block(-1,20,-1,PACKED_ICE:0)
Block(-1,20,0,PACKED_ICE:0)
Block(-1,20,1,PACKED_ICE:0)
Block(-1,20,2,PACKED_ICE:0)
Block(-1,20,3,PACKED_ICE:0)
Block(-1,21,-7,PACKED_ICE:0)
Block(-1,21,-6,PACKED_ICE:0)
Block(-1,21,-5,PACKED_ICE:0)
Block(-1,21,-4,PACKED_ICE:0)
Block(-1,21,-3,PACKED_ICE:0)
Block(-1,21,-2,PACKED_ICE:0)
Block(-1,21,-1,PACKED_ICE:0)
Block(-1,21,0,PACKED_ICE:0)
Block(-1,21,1,PACKED_ICE:0)
Block(-1,21,2,PACKED_ICE:0)
Block(-1,22,-7,ICE:0)
Block(-1,22,-6,ICE:0)
Block(-1,22,-5,PACKED_ICE:0)
Block(-1,22,-4,PACKED_ICE:0)
Block(-1,22,-3,PACKED_ICE:0)
Block(-1,22,-2,PACKED_ICE:0)
Block(-1,22,-1,ICE:0)
Block(-1,22,0,ICE:0)
Block(-1,22,1,ICE:0)
Block(-1,22,2,PACKED_ICE:0)
Block(-1,23,-7,PACKED_ICE:0)
Block(-1,23,-6,ICE:0)
Block(-1,23,-5,ICE:0)
Block(-1,23,-4,ICE:0)
Block(-1,23,-3,ICE:0)
Block(-1,23,-2,ICE:0)
Block(-1,23,-1,ICE:0)
Block(-1,23,0,ICE:0)
Block(-1,23,1,ICE:0)
Block(-1,24,-7,PACKED_ICE:0)
Block(-1,24,-6,ICE:0)
Block(-1,24,-5,ICE:0)
Block(-1,24,-4,ICE:0)
Block(-1,24,-3,ICE:0)
Block(-1,24,-2,PACKED_ICE:0)
Block(-1,24,-1,ICE:0)
Block(-1,24,0,PACKED_ICE:0)
Block(-1,25,-7,PACKED_ICE:0)
Block(-1,25,-6,ICE:0)
Block(-1,25,-5,ICE:0)
Block(-1,25,-4,PACKED_ICE:0)
Block(-1,25,-3,ICE:0)
Block(-1,25,-2,ICE:0)
Block(-1,25,-1,ICE:0)
Block(-1,26,-7,PACKED_ICE:0)
Block(-1,26,-6,PACKED_ICE:0)
Block(-1,26,-5,PACKED_ICE:0)
Block(-1,26,-3,ICE:0)
Block(-1,26,-2,ICE:0)
Block(-1,27,-7,PACKED_ICE:0)
Block(-1,27,-6,PACKED_ICE:0)
Block(-1,27,-4,PACKED_ICE:0)
Block(-1,27,-3,PACKED_ICE:0)
Block(-1,28,-7,PACKED_ICE:0)
Block(-1,28,-4,PACKED_ICE:0)
Block(0,18,-7,PACKED_ICE:0)
Block(0,18,-6,PACKED_ICE:0)
Block(0,18,-5,PACKED_ICE:0)
Block(0,18,-4,PACKED_ICE:0)
Block(0,18,-3,PACKED_ICE:0)
Block(0,18,-2,PACKED_ICE:0)
Block(0,18,-1,PACKED_ICE:0)
Block(0,18,0,PACKED_ICE:0)
Block(0,18,1,PACKED_ICE:0)
Block(0,18,2,PACKED_ICE:0)
Block(0,18,3,PACKED_ICE:0)
Block(0,18,4,PACKED_ICE:0)
Block(0,19,-7,PACKED_ICE:0)
Block(0,19,-6,PACKED_ICE:0)
Block(0,19,-5,PACKED_ICE:0)
Block(0,19,-4,PACKED_ICE:0)
Block(0,19,-3,PACKED_ICE:0)
Block(0,19,-2,PACKED_ICE:0)
Block(0,19,-1,PACKED_ICE:0)
Block(0,19,0,PACKED_ICE:0)
Block(0,19,1,PACKED_ICE:0)
Block(0,19,2,PACKED_ICE:0)
Block(0,19,3,PACKED_ICE:0)
Block(0,19,4,PACKED_ICE:0)
Block(0,19,5,PACKED_ICE:0)
Block(0,20,-7,PACKED_ICE:0)
Block(0,20,-6,PACKED_ICE:0)
Block(0,20,-5,PACKED_ICE:0)
Block(0,20,-4,PACKED_ICE:0)
Block(0,20,-3,PACKED_ICE:0)
Block(0,20,-2,PACKED_ICE:0)
Block(0,20,-1,PACKED_ICE:0)
Block(0,20,0,PACKED_ICE:0)
Block(0,20,1,PACKED_ICE:0)
Block(0,20,2,PACKED_ICE:0)
Block(0,20,3,PACKED_ICE:0)
Block(0,20,4,PACKED_ICE:0)
Block(0,21,-7,PACKED_ICE:0)
Block(0,21,-6,PACKED_ICE:0)
Block(0,21,-5,PACKED_ICE:0)
Block(0,21,-4,PACKED_ICE:0)
Block(0,21,-3,PACKED_ICE:0)
Block(0,21,-2,PACKED_ICE:0)
Block(0,21,-1,PACKED_ICE:0)
Block(0,21,0,PACKED_ICE:0)
Block(0,21,1,PACKED_ICE:0)
Block(0,21,2,PACKED_ICE:0)
Block(0,21,3,PACKED_ICE:0)
Block(0,22,-7,ICE:0)
Block(0,22,-6,ICE:0)
Block(0,22,-5,ICE:0)
Block(0,22,-4,PACKED_ICE:0)
Block(0,22,-3,PACKED_ICE:0)
Block(0,22,-2,PACKED_ICE:0)
Block(0,22,-1,ICE:0)
Block(0,22,0,ICE:0)
Block(0,22,1,PACKED_ICE:0)
Block(0,22,2,ICE:0)
Block(0,23,-7,PACKED_ICE:0)
Block(0,23,-6,PACKED_ICE:0)
Block(0,23,-5,PACKED_ICE:0)
Block(0,23,-4,ICE:0)
Block(0,23,-3,ICE:0)
Block(0,23,-2,PACKED_ICE:0)
Block(0,23,-1,ICE:0)
Block(0,23,0,ICE:0)
Block(0,23,1,PACKED_ICE:0)
Block(0,24,-7,PACKED_ICE:0)
Block(0,24,-6,PACKED_ICE:0)
Block(0,24,-5,ICE:0)
Block(0,24,-4,PACKED_ICE:0)
Block(0,24,-3,PACKED_ICE:0)
Block(0,24,-2,PACKED_ICE:0)
Block(0,24,-1,PACKED_ICE:0)
Block(0,24,0,PACKED_ICE:0)
Block(0,25,-7,PACKED_ICE:0)
Block(0,25,-6,ICE:0)
Block(0,25,-5,ICE:0)
Block(0,25,-4,PACKED_ICE:0)
Block(0,25,-3,PACKED_ICE:0)
Block(0,25,-2,PACKED_ICE:0)
Block(0,26,-7,PACKED_ICE:0)
Block(0,26,-6,PACKED_ICE:0)
Block(0,26,-5,PACKED_ICE:0)
Block(0,27,-7,PACKED_ICE:0)
Block(0,27,-6,PACKED_ICE:0)
Block(0,27,-5,PACKED_ICE:0)
Block(0,28,-7,PACKED_ICE:0)
Block(0,28,-6,ICE:0)
Block(0,29,-7,PACKED_ICE:0)
Block(1,18,-7,PACKED_ICE:0)
Block(1,18,-6,PACKED_ICE:0)
Block(1,18,-5,PACKED_ICE:0)
Block(1,18,-4,PACKED_ICE:0)
Block(1,18,-3,PACKED_ICE:0)
Block(1,18,-2,PACKED_ICE:0)
Block(1,18,-1,PACKED_ICE:0)
Block(1,18,0,PACKED_ICE:0)
Block(1,18,1,PACKED_ICE:0)
Block(1,18,2,PACKED_ICE:0)
Block(1,18,3,PACKED_ICE:0)
Block(1,18,4,PACKED_ICE:0)
Block(1,19,-7,PACKED_ICE:0)
Block(1,19,-6,PACKED_ICE:0)
Block(1,19,-5,PACKED_ICE:0)
Block(1,19,-4,PACKED_ICE:0)
Block(1,19,-3,PACKED_ICE:0)
Block(1,19,-2,PACKED_ICE:0)
Block(1,19,-1,PACKED_ICE:0)
Block(1,19,0,PACKED_ICE:0)
Block(1,19,1,PACKED_ICE:0)
Block(1,19,2,PACKED_ICE:0)
Block(1,19,3,PACKED_ICE:0)
Block(1,19,4,PACKED_ICE:0)
Block(1,19,5,PACKED_ICE:0)
Block(1,20,-7,PACKED_ICE:0)
Block(1,20,-6,PACKED_ICE:0)
Block(1,20,-5,PACKED_ICE:0)
Block(1,20,-4,PACKED_ICE:0)
Block(1,20,-3,PACKED_ICE:0)
Block(1,20,-2,PACKED_ICE:0)
Block(1,20,-1,PACKED_ICE:0)
Block(1,20,0,PACKED_ICE:0)
Block(1,20,1,PACKED_ICE:0)
Block(1,20,2,PACKED_ICE:0)
Block(1,20,3,PACKED_ICE:0)
Block(1,20,4,PACKED_ICE:0)
Block(1,21,-7,PACKED_ICE:0)
Block(1,21,-6,PACKED_ICE:0)
Block(1,21,-5,PACKED_ICE:0)
Block(1,21,-4,PACKED_ICE:0)
Block(1,21,-3,PACKED_ICE:0)
Block(1,21,-2,PACKED_ICE:0)
Block(1,21,-1,PACKED_ICE:0)
Block(1,21,0,PACKED_ICE:0)
Block(1,21,1,PACKED_ICE:0)
Block(1,21,2,PACKED_ICE:0)
Block(1,21,3,PACKED_ICE:0)
Block(1,22,-7,ICE:0)
Block(1,22,-6,ICE:0)
Block(1,22,-5,ICE:0)
Block(1,22,-4,ICE:0)
Block(1,22,-3,PACKED_ICE:0)
Block(1,22,-2,PACKED_ICE:0)
Block(1,22,-1,ICE:0)
Block(1,22,0,ICE:0)
Block(1,22,1,PACKED_ICE:0)
Block(1,23,-7,PACKED_ICE:0)
Block(1,23,-6,PACKED_ICE:0)
Block(1,23,-5,ICE:0)
Block(1,23,-4,ICE:0)
Block(1,23,-3,ICE:0)
Block(1,23,-2,PACKED_ICE:0)
Block(1,23,-1,ICE:0)
Block(1,23,0,ICE:0)
Block(1,24,-7,PACKED_ICE:0)
Block(1,24,-6,PACKED_ICE:0)
Block(1,24,-5,ICE:0)
Block(1,24,-4,ICE:0)
Block(1,24,-3,PACKED_ICE:0)
Block(1,24,-2,PACKED_ICE:0)
Block(1,24,-1,PACKED_ICE:0)
Block(1,24,0,ICE:0)
Block(1,25,-7,PACKED_ICE:0)
Block(1,25,-6,PACKED_ICE:0)
Block(1,25,-5,ICE:0)
Block(1,25,-4,ICE:0)
Block(1,25,-3,ICE:0)
Block(1,25,-2,ICE:0)
Block(1,25,-1,ICE:0)
Block(1,26,-7,PACKED_ICE:0)
Block(1,26,-6,PACKED_ICE:0)
Block(1,26,-5,PACKED_ICE:0)
Block(1,26,-4,PACKED_ICE:0)
Block(1,26,-2,ICE:0)
Block(1,27,-7,PACKED_ICE:0)
Block(1,27,-6,PACKED_ICE:0)
Block(1,27,-5,ICE:0)
Block(1,28,-7,PACKED_ICE:0)
Block(1,28,-6,PACKED_ICE:0)
Block(1,29,-7,ICE:0)
Block(2,18,-7,PACKED_ICE:0)
Block(2,18,-6,PACKED_ICE:0)
Block(2,18,-5,PACKED_ICE:0)
Block(2,18,-4,PACKED_ICE:0)
Block(2,18,-3,PACKED_ICE:0)
Block(2,18,-2,PACKED_ICE:0)
Block(2,18,-1,PACKED_ICE:0)
Block(2,18,0,PACKED_ICE:0)
Block(2,18,1,PACKED_ICE:0)
Block(2,18,2,PACKED_ICE:0)
Block(2,18,3,PACKED_ICE:0)
Block(2,19,-7,PACKED_ICE:0)
Block(2,19,-6,PACKED_ICE:0)
Block(2,19,-5,PACKED_ICE:0)
Block(2,19,-4,PACKED_ICE:0)
Block(2,19,-3,PACKED_ICE:0)
Block(2,19,-2,PACKED_ICE:0)
Block(2,19,-1,PACKED_ICE:0)
Block(2,19,0,PACKED_ICE:0)
Block(2,19,1,PACKED_ICE:0)
Block(2,19,2,PACKED_ICE:0)
Block(2,19,3,PACKED_ICE:0)
Block(2,19,4,PACKED_ICE:0)
Block(2,20,-7,PACKED_ICE:0)
Block(2,20,-6,PACKED_ICE:0)
Block(2,20,-5,PACKED_ICE:0)
Block(2,20,-4,PACKED_ICE:0)
Block(2,20,-3,PACKED_ICE:0)
Block(2,20,-2,PACKED_ICE:0)
Block(2,20,-1,PACKED_ICE:0)
Block(2,20,0,PACKED_ICE:0)
Block(2,20,1,PACKED_ICE:0)
Block(2,20,2,PACKED_ICE:0)
Block(2,20,3,PACKED_ICE:0)
Block(2,21,-7,PACKED_ICE:0)
Block(2,21,-6,PACKED_ICE:0)
Block(2,21,-5,PACKED_ICE:0)
Block(2,21,-4,PACKED_ICE:0)
Block(2,21,-3,PACKED_ICE:0)
Block(2,21,-2,PACKED_ICE:0)
Block(2,21,-1,PACKED_ICE:0)
Block(2,21,0,PACKED_ICE:0)
Block(2,21,1,PACKED_ICE:0)
Block(2,21,2,PACKED_ICE:0)
Block(2,21,3,PACKED_ICE:0)
Block(2,22,-7,ICE:0)
Block(2,22,-6,ICE:0)
Block(2,22,-5,ICE:0)
Block(2,22,-4,PACKED_ICE:0)
Block(2,22,-3,PACKED_ICE:0)
Block(2,22,-2,PACKED_ICE:0)
Block(2,22,-1,ICE:0)
Block(2,22,0,PACKED_ICE:0)
Block(2,22,1,ICE:0)
Block(2,23,-7,ICE:0)
Block(2,23,-6,ICE:0)
Block(2,23,-5,ICE:0)
Block(2,23,-4,ICE:0)
Block(2,23,-3,ICE:0)
Block(2,23,-2,PACKED_ICE:0)
Block(2,23,-1,ICE:0)
Block(2,23,0,ICE:0)
Block(2,24,-7,PACKED_ICE:0)
Block(2,24,-6,PACKED_ICE:0)
Block(2,24,-5,PACKED_ICE:0)
Block(2,24,-4,PACKED_ICE:0)
Block(2,24,-3,ICE:0)
Block(2,24,-2,ICE:0)
Block(2,24,-1,PACKED_ICE:0)
Block(2,25,-7,PACKED_ICE:0)
Block(2,25,-6,PACKED_ICE:0)
Block(2,25,-5,PACKED_ICE:0)
Block(2,25,-4,ICE:0)
Block(2,25,-3,PACKED_ICE:0)
Block(2,25,-2,ICE:0)
Block(2,26,-7,PACKED_ICE:0)
Block(2,26,-6,PACKED_ICE:0)
Block(2,26,-5,PACKED_ICE:0)
Block(2,27,-7,PACKED_ICE:0)
Block(2,27,-6,PACKED_ICE:0)
Block(2,28,-7,PACKED_ICE:0)
Block(2,28,-6,ICE:0)
Block(2,29,-7,PACKED_ICE:0)
Block(2,30,-7,PACKED_ICE:0)
Block(2,35,-7,ICE:0)
Block(2,36,-7,ICE:0)
Block(2,37,-7,ICE:0)
Block(3,18,-7,PACKED_ICE:0)
Block(3,18,-6,PACKED_ICE:0)
Block(3,18,-5,PACKED_ICE:0)
Block(3,18,-4,PACKED_ICE:0)
Block(3,18,-3,PACKED_ICE:0)
Block(3,18,-2,PACKED_ICE:0)
Block(3,18,-1,PACKED_ICE:0)
Block(3,18,0,PACKED_ICE:0)
Block(3,18,1,PACKED_ICE:0)
Block(3,18,2,PACKED_ICE:0)
Block(3,19,-7,PACKED_ICE:0)
Block(3,19,-6,PACKED_ICE:0)
Block(3,19,-5,PACKED_ICE:0)
Block(3,19,-4,PACKED_ICE:0)
Block(3,19,-3,PACKED_ICE:0)
Block(3,19,-2,PACKED_ICE:0)
Block(3,19,-1,PACKED_ICE:0)
Block(3,19,0,PACKED_ICE:0)
Block(3,19,1,PACKED_ICE:0)
Block(3,19,2,PACKED_ICE:0)
Block(3,19,3,PACKED_ICE:0)
Block(3,20,-7,PACKED_ICE:0)
Block(3,20,-6,PACKED_ICE:0)
Block(3,20,-5,PACKED_ICE:0)
Block(3,20,-4,PACKED_ICE:0)
Block(3,20,-3,PACKED_ICE:0)
Block(3,20,-2,PACKED_ICE:0)
Block(3,20,-1,PACKED_ICE:0)
Block(3,20,0,PACKED_ICE:0)
Block(3,20,1,PACKED_ICE:0)
Block(3,20,2,PACKED_ICE:0)
Block(3,20,3,PACKED_ICE:0)
Block(3,21,-7,PACKED_ICE:0)
Block(3,21,-6,PACKED_ICE:0)
Block(3,21,-5,PACKED_ICE:0)
Block(3,21,-4,PACKED_ICE:0)
Block(3,21,-3,PACKED_ICE:0)
Block(3,21,-2,PACKED_ICE:0)
Block(3,21,-1,PACKED_ICE:0)
Block(3,21,0,PACKED_ICE:0)
Block(3,21,1,PACKED_ICE:0)
Block(3,21,2,PACKED_ICE:0)
Block(3,22,-7,PACKED_ICE:0)
Block(3,22,-6,ICE:0)
Block(3,22,-5,PACKED_ICE:0)
Block(3,22,-4,PACKED_ICE:0)
Block(3,22,-3,PACKED_ICE:0)
Block(3,22,-2,ICE:0)
Block(3,22,-1,ICE:0)
Block(3,22,0,PACKED_ICE:0)
Block(3,23,-7,ICE:0)
Block(3,23,-6,ICE:0)
Block(3,23,-5,ICE:0)
Block(3,23,-4,ICE:0)
Block(3,23,-3,PACKED_ICE:0)
Block(3,23,-2,ICE:0)
Block(3,23,-1,ICE:0)
Block(3,24,-7,PACKED_ICE:0)
Block(3,24,-6,ICE:0)
Block(3,24,-5,ICE:0)
Block(3,24,-4,ICE:0)
Block(3,24,-3,PACKED_ICE:0)
Block(3,24,-2,PACKED_ICE:0)
Block(3,25,-7,PACKED_ICE:0)
Block(3,25,-6,ICE:0)
Block(3,25,-5,ICE:0)
Block(3,25,-4,ICE:0)
Block(3,25,-3,PACKED_ICE:0)
Block(3,26,-7,PACKED_ICE:0)
Block(3,26,-6,PACKED_ICE:0)
Block(3,26,-5,PACKED_ICE:0)
Block(3,26,-4,PACKED_ICE:0)
Block(3,27,-7,PACKED_ICE:0)
Block(3,27,-6,PACKED_ICE:0)
Block(3,27,-5,PACKED_ICE:0)
Block(3,28,-7,PACKED_ICE:0)
Block(3,33,-7,PACKED_ICE:0)
Block(3,34,-7,PACKED_ICE:0)
Block(3,35,-7,PACKED_ICE:0)
Block(3,36,-7,PACKED_ICE:0)
Block(3,37,-7,WOOD_DOUBLE_STEP:5)
Block(3,38,-7,SNOW:2)
Block(4,18,-7,PACKED_ICE:0)
Block(4,18,-6,PACKED_ICE:0)
Block(4,18,-5,PACKED_ICE:0)
Block(4,18,-4,PACKED_ICE:0)
Block(4,18,-3,PACKED_ICE:0)
Block(4,18,-2,PACKED_ICE:0)
Block(4,18,-1,PACKED_ICE:0)
Block(4,18,0,PACKED_ICE:0)
Block(4,18,1,PACKED_ICE:0)
Block(4,18,2,PACKED_ICE:0)
Block(4,19,-7,PACKED_ICE:0)
Block(4,19,-6,PACKED_ICE:0)
Block(4,19,-5,PACKED_ICE:0)
Block(4,19,-4,PACKED_ICE:0)
Block(4,19,-3,PACKED_ICE:0)
Block(4,19,-2,PACKED_ICE:0)
Block(4,19,-1,PACKED_ICE:0)
Block(4,19,0,PACKED_ICE:0)
Block(4,19,1,PACKED_ICE:0)
Block(4,19,2,PACKED_ICE:0)
Block(4,19,3,PACKED_ICE:0)
Block(4,20,-7,PACKED_ICE:0)
Block(4,20,-6,PACKED_ICE:0)
Block(4,20,-5,PACKED_ICE:0)
Block(4,20,-4,PACKED_ICE:0)
Block(4,20,-3,PACKED_ICE:0)
Block(4,20,-2,PACKED_ICE:0)
Block(4,20,-1,PACKED_ICE:0)
Block(4,20,0,PACKED_ICE:0)
Block(4,20,1,PACKED_ICE:0)
Block(4,20,2,PACKED_ICE:0)
Block(4,20,3,PACKED_ICE:0)
Block(4,21,-7,PACKED_ICE:0)
Block(4,21,-6,PACKED_ICE:0)
Block(4,21,-5,PACKED_ICE:0)
Block(4,21,-4,PACKED_ICE:0)
Block(4,21,-3,PACKED_ICE:0)
Block(4,21,-2,PACKED_ICE:0)
Block(4,21,-1,PACKED_ICE:0)
Block(4,21,0,PACKED_ICE:0)
Block(4,21,1,PACKED_ICE:0)
Block(4,22,-7,ICE:0)
Block(4,22,-6,ICE:0)
Block(4,22,-5,PACKED_ICE:0)
Block(4,22,-4,ICE:0)
Block(4,22,-3,ICE:0)
Block(4,22,-2,ICE:0)
Block(4,22,-1,ICE:0)
Block(4,22,0,ICE:0)
Block(4,23,-7,ICE:0)
Block(4,23,-6,ICE:0)
Block(4,23,-5,ICE:0)
Block(4,23,-4,ICE:0)
Block(4,23,-3,ICE:0)
Block(4,23,-2,ICE:0)
Block(4,23,-1,PACKED_ICE:0)
Block(4,24,-7,PACKED_ICE:0)
Block(4,24,-6,ICE:0)
Block(4,24,-5,ICE:0)
Block(4,24,-4,ICE:0)
Block(4,24,-3,ICE:0)
Block(4,24,-2,ICE:0)
Block(4,24,-1,ICE:0)
Block(4,25,-7,PACKED_ICE:0)
Block(4,25,-6,ICE:0)
Block(4,25,-5,ICE:0)
Block(4,25,-4,PACKED_ICE:0)
Block(4,25,-3,PACKED_ICE:0)
Block(4,25,-2,PACKED_ICE:0)
Block(4,26,-7,PACKED_ICE:0)
Block(4,26,-6,PACKED_ICE:0)
Block(4,26,-5,PACKED_ICE:0)
Block(4,26,-4,ICE:0)
Block(4,27,-7,ICE:0)
Block(4,31,-7,ICE:0)
Block(4,32,-7,ICE:0)
Block(4,33,-7,ICE:0)
Block(5,18,-7,PACKED_ICE:0)
Block(5,18,-6,PACKED_ICE:0)
Block(5,18,-5,PACKED_ICE:0)
Block(5,18,-4,PACKED_ICE:0)
Block(5,18,-3,PACKED_ICE:0)
Block(5,18,-2,PACKED_ICE:0)
Block(5,18,-1,PACKED_ICE:0)
Block(5,18,0,PACKED_ICE:0)
Block(5,18,1,PACKED_ICE:0)
Block(5,18,2,PACKED_ICE:0)
Block(5,19,-7,PACKED_ICE:0)
Block(5,19,-6,PACKED_ICE:0)
Block(5,19,-5,PACKED_ICE:0)
Block(5,19,-4,PACKED_ICE:0)
Block(5,19,-3,PACKED_ICE:0)
Block(5,19,-2,PACKED_ICE:0)
Block(5,19,-1,PACKED_ICE:0)
Block(5,19,0,PACKED_ICE:0)
Block(5,19,1,PACKED_ICE:0)
Block(5,19,2,PACKED_ICE:0)
Block(5,20,-7,PACKED_ICE:0)
Block(5,20,-6,PACKED_ICE:0)
Block(5,20,-5,PACKED_ICE:0)
Block(5,20,-4,PACKED_ICE:0)
Block(5,20,-3,PACKED_ICE:0)
Block(5,20,-2,PACKED_ICE:0)
Block(5,20,-1,PACKED_ICE:0)
Block(5,20,0,PACKED_ICE:0)
Block(5,20,1,PACKED_ICE:0)
Block(5,20,2,PACKED_ICE:0)
Block(5,20,3,PACKED_ICE:0)
Block(5,21,-7,PACKED_ICE:0)
Block(5,21,-6,PACKED_ICE:0)
Block(5,21,-5,PACKED_ICE:0)
Block(5,21,-4,PACKED_ICE:0)
Block(5,21,-3,PACKED_ICE:0)
Block(5,21,-2,PACKED_ICE:0)
Block(5,21,-1,PACKED_ICE:0)
Block(5,21,0,PACKED_ICE:0)
Block(5,21,1,PACKED_ICE:0)
Block(5,21,2,PACKED_ICE:0)
Block(5,22,-7,ICE:0)
Block(5,22,-6,ICE:0)
Block(5,22,-5,PACKED_ICE:0)
Block(5,22,-4,ICE:0)
Block(5,22,-3,ICE:0)
Block(5,22,-2,ICE:0)
Block(5,22,-1,ICE:0)
Block(5,22,0,ICE:0)
Block(5,22,1,PACKED_ICE:0)
Block(5,23,-7,ICE:0)
Block(5,23,-6,ICE:0)
Block(5,23,-5,ICE:0)
Block(5,23,-4,ICE:0)
Block(5,23,-3,ICE:0)
Block(5,23,-2,PACKED_ICE:0)
Block(5,23,-1,ICE:0)
Block(5,23,0,PACKED_ICE:0)
Block(5,24,-7,ICE:0)
Block(5,24,-6,ICE:0)
Block(5,24,-5,PACKED_ICE:0)
Block(5,24,-4,ICE:0)
Block(5,24,-3,ICE:0)
Block(5,24,-2,ICE:0)
Block(5,24,-1,PACKED_ICE:0)
Block(5,25,-7,PACKED_ICE:0)
Block(5,25,-6,PACKED_ICE:0)
Block(5,25,-5,ICE:0)
Block(5,25,-4,PACKED_ICE:0)
Block(5,25,-3,PACKED_ICE:0)
Block(5,25,-2,PACKED_ICE:0)
Block(5,26,-7,PACKED_ICE:0)
Block(5,27,-6,PACKED_ICE:0)
Block(5,33,-7,DISPENSER:3)
Block(5,34,-7,SNOW:1)
Block(6,18,-7,PACKED_ICE:0)
Block(6,18,-6,PACKED_ICE:0)
Block(6,18,-5,PACKED_ICE:0)
Block(6,18,-4,PACKED_ICE:0)
Block(6,18,-3,PACKED_ICE:0)
Block(6,18,-2,PACKED_ICE:0)
Block(6,18,-1,PACKED_ICE:0)
Block(6,18,0,PACKED_ICE:0)
Block(6,18,1,PACKED_ICE:0)
Block(6,18,2,PACKED_ICE:0)
Block(6,19,-7,PACKED_ICE:0)
Block(6,19,-6,PACKED_ICE:0)
Block(6,19,-5,PACKED_ICE:0)
Block(6,19,-4,PACKED_ICE:0)
Block(6,19,-3,PACKED_ICE:0)
Block(6,19,-2,PACKED_ICE:0)
Block(6,19,-1,PACKED_ICE:0)
Block(6,19,0,PACKED_ICE:0)
Block(6,19,1,PACKED_ICE:0)
Block(6,19,2,PACKED_ICE:0)
Block(6,19,3,PACKED_ICE:0)
Block(6,20,-7,PACKED_ICE:0)
Block(6,20,-6,PACKED_ICE:0)
Block(6,20,-5,PACKED_ICE:0)
Block(6,20,-4,PACKED_ICE:0)
Block(6,20,-3,PACKED_ICE:0)
Block(6,20,-2,PACKED_ICE:0)
Block(6,20,-1,PACKED_ICE:0)
Block(6,20,0,PACKED_ICE:0)
Block(6,20,1,PACKED_ICE:0)
Block(6,20,2,PACKED_ICE:0)
Block(6,21,-7,PACKED_ICE:0)
Block(6,21,-6,PACKED_ICE:0)
Block(6,21,-5,PACKED_ICE:0)
Block(6,21,-4,PACKED_ICE:0)
Block(6,21,-3,PACKED_ICE:0)
Block(6,21,-2,PACKED_ICE:0)
Block(6,21,-1,PACKED_ICE:0)
Block(6,21,0,PACKED_ICE:0)
Block(6,21,1,PACKED_ICE:0)
Block(6,22,-7,PACKED_ICE:0)
Block(6,22,-6,PACKED_ICE:0)
Block(6,22,-5,ICE:0)
Block(6,22,-4,ICE:0)
Block(6,22,-3,PACKED_ICE:0)
Block(6,22,-2,PACKED_ICE:0)
Block(6,22,-1,PACKED_ICE:0)
Block(6,22,0,PACKED_ICE:0)
Block(6,23,-7,PACKED_ICE:0)
Block(6,23,-6,ICE:0)
Block(6,23,-5,ICE:0)
Block(6,23,-4,ICE:0)
Block(6,23,-3,ICE:0)
Block(6,23,-2,PACKED_ICE:0)
Block(6,23,-1,PACKED_ICE:0)
Block(6,24,-7,ICE:0)
Block(6,24,-6,ICE:0)
Block(6,24,-5,PACKED_ICE:0)
Block(6,24,-4,ICE:0)
Block(6,24,-3,PACKED_ICE:0)
Block(6,24,-2,PACKED_ICE:0)
Block(6,25,-7,PACKED_ICE:0)
Block(6,25,-6,PACKED_ICE:0)
Block(6,25,-5,ICE:0)
Block(6,25,-4,PACKED_ICE:0)
Block(6,25,-3,PACKED_ICE:0)
Block(6,26,-7,ICE:0)
Block(6,26,-6,PACKED_ICE:0)
Block(6,26,-5,PACKED_ICE:0)
Block(6,26,-3,PACKED_ICE:0)
Block(6,27,-7,PACKED_ICE:0)
Block(6,29,-7,PACKED_ICE:0)
Block(6,30,-7,PACKED_ICE:0)
Block(6,31,-7,PACKED_ICE:0)
Block(6,32,-7,ICE:0)
Block(6,32,-6,PACKED_ICE:0)
Block(6,33,-7,PACKED_ICE:0)
Block(7,18,-7,PACKED_ICE:0)
Block(7,18,-6,PACKED_ICE:0)
Block(7,18,-5,PACKED_ICE:0)
Block(7,18,-4,PACKED_ICE:0)
Block(7,18,-3,PACKED_ICE:0)
Block(7,18,-2,PACKED_ICE:0)
Block(7,18,-1,PACKED_ICE:0)
Block(7,18,0,PACKED_ICE:0)
Block(7,18,1,PACKED_ICE:0)
Block(7,18,2,PACKED_ICE:0)
Block(7,19,-7,PACKED_ICE:0)
Block(7,19,-6,PACKED_ICE:0)
Block(7,19,-5,PACKED_ICE:0)
Block(7,19,-4,PACKED_ICE:0)
Block(7,19,-3,PACKED_ICE:0)
Block(7,19,-2,PACKED_ICE:0)
Block(7,19,-1,PACKED_ICE:0)
Block(7,19,0,PACKED_ICE:0)
Block(7,19,1,PACKED_ICE:0)
Block(7,19,2,PACKED_ICE:0)
Block(7,19,3,PACKED_ICE:0)
Block(7,20,-7,PACKED_ICE:0)
Block(7,20,-6,PACKED_ICE:0)
Block(7,20,-5,PACKED_ICE:0)
Block(7,20,-4,PACKED_ICE:0)
Block(7,20,-3,PACKED_ICE:0)
Block(7,20,-2,PACKED_ICE:0)
Block(7,20,-1,PACKED_ICE:0)
Block(7,20,0,PACKED_ICE:0)
Block(7,20,1,PACKED_ICE:0)
Block(7,20,2,PACKED_ICE:0)
Block(7,21,-7,PACKED_ICE:0)
Block(7,21,-6,PACKED_ICE:0)
Block(7,21,-5,PACKED_ICE:0)
Block(7,21,-4,PACKED_ICE:0)
Block(7,21,-3,PACKED_ICE:0)
Block(7,21,-2,PACKED_ICE:0)
Block(7,21,-1,PACKED_ICE:0)
Block(7,21,0,PACKED_ICE:0)
Block(7,21,1,PACKED_ICE:0)
Block(7,22,-7,ICE:0)
Block(7,22,-6,ICE:0)
Block(7,22,-5,PACKED_ICE:0)
Block(7,22,-4,PACKED_ICE:0)
Block(7,22,-3,PACKED_ICE:0)
Block(7,22,-2,PACKED_ICE:0)
Block(7,22,-1,PACKED_ICE:0)
Block(7,22,0,ICE:0)
Block(7,22,1,PACKED_ICE:0)
Block(7,23,-7,ICE:0)
Block(7,23,-6,ICE:0)
Block(7,23,-5,ICE:0)
Block(7,23,-4,ICE:0)
Block(7,23,-3,ICE:0)
Block(7,23,-2,ICE:0)
Block(7,23,-1,ICE:0)
Block(7,24,-7,PACKED_ICE:0)
Block(7,24,-6,PACKED_ICE:0)
Block(7,24,-5,PACKED_ICE:0)
Block(7,24,-4,ICE:0)
Block(7,24,-3,PACKED_ICE:0)
Block(7,24,-2,PACKED_ICE:0)
Block(7,24,-1,ICE:0)
Block(7,25,-7,ICE:0)
Block(7,25,-6,ICE:0)
Block(7,25,-5,ICE:0)
Block(7,25,-4,PACKED_ICE:0)
Block(7,25,-3,PACKED_ICE:0)
Block(7,25,-2,PACKED_ICE:0)
Block(7,26,-6,PACKED_ICE:0)
Block(7,26,-3,ICE:0)
Block(7,27,-4,ICE:0)
Block(7,30,-7,ICE:0)
Block(7,31,-7,PACKED_ICE:0)
Block(7,31,-6,PACKED_ICE:0)
Block(7,32,-7,PACKED_ICE:0)
Block(7,32,-6,ICE:0)
Block(7,33,-7,ICE:0)
Block(7,34,-7,ICE:0)
Block(7,35,-7,WOOL:15)
Block(7,36,-7,WOOL:15)
Block(7,37,-7,WOOL:15)
Block(7,38,-7,WOOL:15)
Block(7,39,-7,SNOW:0)

#######################################################################
# +-----------------------------------------------------------------+ #
# |                             Branches                            | #
# +-----------------------------------------------------------------+ #
#######################################################################

Branch(-16,0,0,true,FrozenShip-3C0R2,NORTH,100.0,0)

#######################################################################
# +-----------------------------------------------------------------+ #
# |                             Entities                            | #
# +-----------------------------------------------------------------+ #
#######################################################################


#######################################################################
# +-----------------------------------------------------------------+ #
# |                            Particles                            | #
# +-----------------------------------------------------------------+ #
#######################################################################


#######################################################################
# +-----------------------------------------------------------------+ #
# |                             Spawners                            | #
# +-----------------------------------------------------------------+ #
#######################################################################


#######################################################################
# +-----------------------------------------------------------------+ #
# |                             ModData                             | #
# +-----------------------------------------------------------------+ #
#######################################################################

