
#######################################################################
# +-----------------------------------------------------------------+ #
# |                            BO3 object                           | #
# +-----------------------------------------------------------------+ #
#######################################################################

Author: NLBlackHeavenNL

Description: No description given

Version: 3

SettingsMode: WriteWithoutComments


#######################################################################
# +-----------------------------------------------------------------+ #
# |                          Main settings                          | #
# +-----------------------------------------------------------------+ #
#######################################################################

Tree: true

Frequency: 1

Rarity: 100.0

RotateRandomly: false

SpawnHeight: highestSolidBlock

SpawnHeightOffset: -1

SpawnHeightVariance: 0

##############################
# Height Limits for the BO3. #
##############################

MinHeight: 0

MaxHeight: 255

######################
# Extrusion settings #
######################

ExtrudeMode: None

ExtrudeThroughBlocks: AIR

MaxBranchDepth: 10

ExcludedBiomes: All


#######################################################################
# +-----------------------------------------------------------------+ #
# |                      Source block settings                      | #
# +-----------------------------------------------------------------+ #
#######################################################################

SourceBlocks: AIR,GRASS,DIRT,biomesoplenty:dirt,biomesoplenty:grass,MYCEL

MaxPercentageOutsideSourceBlock: 0

OutsideSourceBlock: placeAnyway

DoReplaceBlocks: true

IsOTGPlus: false


#######################################################################
# +-----------------------------------------------------------------+ #
# |                              Blocks                             | #
# +-----------------------------------------------------------------+ #
#######################################################################

Block(-2,3,-2,dynamictreesbop:leaves2:0)
Block(-2,4,-2,dynamictreesbop:leaves2:0)
Block(-2,4,-1,dynamictreesbop:leaves2:0)
Block(-2,4,0,dynamictreesbop:leaves2:0)
Block(-2,5,-2,dynamictreesbop:leaves2:0)
Block(-2,5,-1,dynamictreesbop:leaves2:0)
Block(-2,5,0,dynamictreesbop:leaves2:0)
Block(-1,3,-3,dynamictreesbop:leaves2:0)
Block(-1,3,-2,dynamictreesbop:leaves2:1)
Block(-1,3,-1,dynamictreesbop:leaves2:0)
Block(-1,3,0,dynamictreesbop:leaves2:0)
Block(-1,4,-3,dynamictreesbop:leaves2:0)
Block(-1,4,-2,dynamictreesbop:leaves2:2)
Block(-1,4,-1,dynamictreesbop:leaves2)
Block(-1,4,0,dynamictreesbop:leaves2:2)
Block(-1,4,1,dynamictreesbop:leaves2:0)
Block(-1,5,-3,dynamictreesbop:leaves2:0)
Block(-1,5,-2,dynamictreesbop:leaves2:1)
Block(-1,5,-1,dynamictreesbop:leaves2:2)
Block(-1,5,0,dynamictreesbop:leaves2:1)
Block(-1,5,1,dynamictreesbop:leaves2:0)
Block(-1,6,-2,dynamictreesbop:leaves2:0)
Block(-1,6,-1,dynamictreesbop:leaves2:0)
Block(-1,6,0,dynamictreesbop:leaves2:0)
Block(0,0,1,dynamictrees:rootydirtspecies,DT_BPWCherry_Med_10/1-species_tile_entity.nbt)
Block(0,1,1,dynamictreesbop:cherrybranch:4)
Block(0,2,1,dynamictreesbop:cherrybranch:3)
Block(0,3,-3,dynamictreesbop:leaves2:0)
Block(0,3,-2,dynamictreesbop:leaves2:2)
Block(0,3,-1,dynamictreesbop:cherrybranch:1)
Block(0,3,0,dynamictreesbop:cherrybranch:1)
Block(0,3,1,dynamictreesbop:cherrybranch:3)
Block(0,4,-3,dynamictreesbop:leaves2:0)
Block(0,4,-2,dynamictreesbop:leaves2)
Block(0,4,-1,dynamictreesbop:cherrybranch)
Block(0,4,0,dynamictreesbop:leaves2)
Block(0,4,1,dynamictreesbop:leaves2:0)
Block(0,5,-3,dynamictreesbop:leaves2:0)
Block(0,5,-2,dynamictreesbop:leaves2:2)
Block(0,5,-1,dynamictreesbop:leaves2)
Block(0,5,0,dynamictreesbop:leaves2:2)
Block(0,5,1,dynamictreesbop:leaves2:0)
Block(0,6,-2,dynamictreesbop:leaves2:0)
Block(0,6,-1,dynamictreesbop:leaves2:0)
Block(0,6,0,dynamictreesbop:leaves2:0)
Block(1,3,-3,dynamictreesbop:leaves2:0)
Block(1,3,-2,dynamictreesbop:leaves2)
Block(1,3,-1,dynamictreesbop:cherrybranch)
Block(1,3,0,dynamictreesbop:leaves2)
Block(1,3,1,dynamictreesbop:cherrybranch:2)
Block(1,4,-3,dynamictreesbop:leaves2:0)
Block(1,4,-2,dynamictreesbop:leaves2:2)
Block(1,4,-1,dynamictreesbop:leaves2)
Block(1,4,0,dynamictreesbop:cherrybranch)
Block(1,4,1,dynamictreesbop:cherrybranch:1)
Block(1,4,2,dynamictreesbop:leaves2:0)
Block(1,5,-3,dynamictreesbop:leaves2:0)
Block(1,5,-2,dynamictreesbop:leaves2:1)
Block(1,5,-1,dynamictreesbop:leaves2:2)
Block(1,5,0,dynamictreesbop:leaves2)
Block(1,5,1,dynamictreesbop:leaves2:0)
Block(1,6,-2,dynamictreesbop:leaves2:0)
Block(1,6,-1,dynamictreesbop:leaves2:0)
Block(1,6,0,dynamictreesbop:leaves2:0)
Block(2,2,-2,dynamictreesbop:leaves2:0)
Block(2,2,2,dynamictreesbop:leaves2:0)
Block(2,3,-3,dynamictreesbop:leaves2:0)
Block(2,3,-2,dynamictreesbop:leaves2:2)
Block(2,3,-1,dynamictreesbop:leaves2)
Block(2,3,0,dynamictreesbop:leaves2:2)
Block(2,3,1,dynamictreesbop:cherrybranch:1)
Block(2,3,2,dynamictreesbop:leaves2:0)
Block(2,4,-3,dynamictreesbop:leaves2:0)
Block(2,4,-2,dynamictreesbop:leaves2:1)
Block(2,4,-1,dynamictreesbop:leaves2:2)
Block(2,4,0,dynamictreesbop:leaves2)
Block(2,4,1,dynamictreesbop:leaves2:2)
Block(2,4,2,dynamictreesbop:leaves2:1)
Block(2,4,3,dynamictreesbop:leaves2:0)
Block(2,5,-2,dynamictreesbop:leaves2:0)
Block(2,5,-1,dynamictreesbop:leaves2:1)
Block(2,5,0,dynamictreesbop:leaves2:2)
Block(2,5,1,dynamictreesbop:leaves2:1)
Block(2,5,2,dynamictreesbop:leaves2:0)
Block(2,6,-1,dynamictreesbop:leaves2:0)
Block(2,6,0,dynamictreesbop:leaves2:0)
Block(2,6,1,dynamictreesbop:leaves2:0)
Block(3,2,-2,dynamictreesbop:leaves2:0)
Block(3,2,-1,dynamictreesbop:leaves2:0)
Block(3,2,1,dynamictreesbop:leaves2)
Block(3,2,2,dynamictreesbop:leaves2:2)
Block(3,2,3,dynamictreesbop:leaves2:0)
Block(3,3,-3,dynamictreesbop:leaves2:0)
Block(3,3,-2,dynamictreesbop:leaves2:1)
Block(3,3,-1,dynamictreesbop:leaves2:2)
Block(3,3,0,dynamictreesbop:leaves2)
Block(3,3,1,dynamictreesbop:cherrybranch)
Block(3,3,2,dynamictreesbop:leaves2)
Block(3,3,3,dynamictreesbop:leaves2:0)
Block(3,4,-2,dynamictreesbop:leaves2:0)
Block(3,4,-1,dynamictreesbop:leaves2:1)
Block(3,4,0,dynamictreesbop:leaves2:2)
Block(3,4,1,dynamictreesbop:leaves2)
Block(3,4,2,dynamictreesbop:leaves2:2)
Block(3,4,3,dynamictreesbop:leaves2:0)
Block(3,5,-1,dynamictreesbop:leaves2:0)
Block(3,5,0,dynamictreesbop:leaves2:1)
Block(3,5,1,dynamictreesbop:leaves2:0)
Block(3,5,2,dynamictreesbop:leaves2:0)
Block(3,6,0,dynamictreesbop:leaves2:0)
Block(4,2,-1,dynamictreesbop:leaves2:0)
Block(4,2,0,dynamictreesbop:leaves2:1)
Block(4,2,1,dynamictreesbop:leaves2:2)
Block(4,2,2,dynamictreesbop:leaves2:1)
Block(4,2,3,dynamictreesbop:leaves2:0)
Block(4,3,-2,dynamictreesbop:leaves2:0)
Block(4,3,-1,dynamictreesbop:leaves2:1)
Block(4,3,0,dynamictreesbop:leaves2:2)
Block(4,3,1,dynamictreesbop:leaves2)
Block(4,3,2,dynamictreesbop:leaves2:2)
Block(4,3,3,dynamictreesbop:leaves2:0)
Block(4,4,-1,dynamictreesbop:leaves2:0)
Block(4,4,0,dynamictreesbop:leaves2:1)
Block(4,4,1,dynamictreesbop:leaves2:2)
Block(4,4,2,dynamictreesbop:leaves2:1)
Block(4,4,3,dynamictreesbop:leaves2:0)
Block(4,5,0,dynamictreesbop:leaves2:0)
Block(4,5,1,dynamictreesbop:leaves2:0)
Block(4,5,2,dynamictreesbop:leaves2:0)
Block(5,2,0,dynamictreesbop:leaves2:0)
Block(5,2,1,dynamictreesbop:leaves2:0)
Block(5,2,2,dynamictreesbop:leaves2:0)
Block(5,3,-1,dynamictreesbop:leaves2:0)
Block(5,3,0,dynamictreesbop:leaves2:0)
Block(5,3,1,dynamictreesbop:leaves2:0)
Block(5,3,2,dynamictreesbop:leaves2:0)
Block(5,4,0,dynamictreesbop:leaves2:0)
Block(5,4,1,dynamictreesbop:leaves2:0)
Block(5,4,2,dynamictreesbop:leaves2:0)

#######################################################################
# +-----------------------------------------------------------------+ #
# |                            BO3 checks                           | #
# +-----------------------------------------------------------------+ #
#######################################################################

BlockCheck(0,-1,1,GRASS,DIRT,MYCEL,biomesoplenty:grass,biomesoplenty:dirt)

#######################################################################
# +-----------------------------------------------------------------+ #
# |                             Branches                            | #
# +-----------------------------------------------------------------+ #
#######################################################################


#######################################################################
# +-----------------------------------------------------------------+ #
# |                             Entities                            | #
# +-----------------------------------------------------------------+ #
#######################################################################


#######################################################################
# +-----------------------------------------------------------------+ #
# |                            Particles                            | #
# +-----------------------------------------------------------------+ #
#######################################################################


#######################################################################
# +-----------------------------------------------------------------+ #
# |                             Spawners                            | #
# +-----------------------------------------------------------------+ #
#######################################################################


#######################################################################
# +-----------------------------------------------------------------+ #
# |                             ModData                             | #
# +-----------------------------------------------------------------+ #
#######################################################################

