
#######################################################################
# +-----------------------------------------------------------------+ #
# |                            BO4 object                           | #
# +-----------------------------------------------------------------+ #
#######################################################################

Author: NLBlackEagle

Description: No description given

SettingsMode: WriteWithoutComments


#######################################################################
# +-----------------------------------------------------------------+ #
# |                          Main settings                          | #
# +-----------------------------------------------------------------+ #
#######################################################################

FixedRotation: 

Frequency: 0

SpawnHeight: highestBlock

UseCenterForHighestBlock: true

##############################
# Height Limits for the BO4. #
##############################

MinHeight: 0

MaxHeight: 255

InheritBO3: 

InheritBO3Rotation: NORTH

OverrideChildSettings: true

OverrideParentHeight: false

CanOverride: true

BranchFrequency: 0

BranchFrequencyGroup: 

MustBeBelowOther: false

MustBeInside: 

CannotBeInside: 

ReplacesBO3: 

MustBeInsideWorldBorders: false

CanSpawnOnWater: true

SpawnOnWaterOnly: false

SpawnUnderWater: false

SpawnAtWaterLevel: false

HeightOffset: 0

RemoveAir: true

ReplaceAbove: 

ReplaceBelow: 

ReplaceWithBiomeBlocks: false

ReplaceWithSurfaceBlock: GRASS

ReplaceWithGroundBlock: DIRT

ReplaceWithStoneBlock: STONE

SmoothRadius: 0

SmoothHeightOffset: 0

SmoothStartTop: false

SmoothStartWood: false

SmoothingSurfaceBlock: 

SmoothingGroundBlock: 

BO3Group: 

IsSpawnPoint: false

DoReplaceBlocks: true


#######################################################################
# +-----------------------------------------------------------------+ #
# |                              Blocks                             | #
# +-----------------------------------------------------------------+ #
#######################################################################

Block(-8,34,-7,rustic:iron_lattice:0)
Block(-8,34,-6,rustic:iron_lattice:0)
Block(-8,35,-7,rustic:iron_lattice:0)
Block(-8,36,-5,rustic:iron_lattice:0)
Block(-8,36,-4,rustic:iron_lattice:0)
Block(-8,37,-5,rustic:iron_lattice:0)
Block(-8,37,-4,rustic:iron_lattice:0)
Block(-8,38,-6,rustic:iron_lattice:0)
Block(-8,38,-5,rustic:iron_lattice:0)
Block(-8,39,-6,rustic:iron_lattice:0)
Block(-8,39,-5,rustic:iron_lattice:0)
Block(-8,40,-7,rustic:iron_lattice:0)
Block(-8,40,-6,rustic:iron_lattice:0)
Block(-8,40,-5,rustic:iron_lattice:0)
Block(-8,41,-7,rustic:iron_lattice:0)
Block(-8,41,-6,rustic:iron_lattice:0)
Block(-8,41,-5,rustic:iron_lattice:0)
Block(-8,42,-6,rustic:iron_lattice:0)
Block(-8,42,-5,rustic:iron_lattice:0)
Block(-8,43,-7,rustic:iron_lattice:0)
Block(-8,43,-6,rustic:iron_lattice:0)
Block(-8,43,-5,rustic:iron_lattice:0)
Block(-8,44,-6,rustic:iron_lattice:0)
Block(-8,44,-5,rustic:iron_lattice:0)
Block(-8,45,-7,rustic:iron_lattice:0)
Block(-8,45,-6,rustic:iron_lattice:0)
Block(-8,45,-5,rustic:iron_lattice:0)
Block(-8,46,-6,rustic:iron_lattice:0)
Block(-8,46,-5,rustic:iron_lattice:0)
Block(-7,34,-7,rustic:iron_lattice:0)
Block(-7,35,-7,rustic:iron_lattice:0)
Block(-7,36,-7,rustic:iron_lattice:0)
Block(-7,36,-6,rustic:iron_lattice:0)
Block(-7,37,-7,rustic:iron_lattice:0)
Block(-7,37,-6,rustic:iron_lattice:0)
Block(-7,38,-6,rustic:iron_lattice:0)
Block(-7,38,-5,rustic:iron_lattice:0)
Block(-7,39,-6,rustic:iron_lattice:0)
Block(-7,39,-5,rustic:iron_lattice:0)
Block(-7,40,-6,rustic:iron_lattice:0)
Block(-7,40,-5,rustic:iron_lattice:0)
Block(-7,40,-4,rustic:iron_lattice:0)
Block(-7,41,-6,rustic:iron_lattice:0)
Block(-7,41,-5,rustic:iron_lattice:0)
Block(-7,42,-6,rustic:iron_lattice:0)
Block(-7,42,-5,rustic:iron_lattice:0)
Block(-7,43,-6,rustic:iron_lattice:0)
Block(-7,43,-5,rustic:iron_lattice:0)
Block(-7,43,-4,rustic:iron_lattice:0)
Block(-7,44,-6,rustic:iron_lattice:0)
Block(-7,44,-5,rustic:iron_lattice:0)
Block(-7,45,-6,rustic:iron_lattice:0)
Block(-7,45,-5,rustic:iron_lattice:0)
Block(-7,46,-6,rustic:iron_lattice:0)
Block(-7,46,-5,rustic:iron_lattice:0)
Block(-6,36,-7,rustic:iron_lattice:0)
Block(-6,36,-6,rustic:iron_lattice:0)
Block(-6,37,-7,rustic:iron_lattice:0)
Block(-6,37,-6,rustic:iron_lattice:0)
Block(-6,40,-5,rustic:iron_lattice:0)
Block(-6,40,-4,rustic:iron_lattice:0)
Block(-6,40,-3,rustic:iron_lattice:0)
Block(-6,42,-4,rustic:iron_lattice:0)
Block(-6,42,-3,rustic:iron_lattice:0)
Block(-6,43,-5,rustic:iron_lattice:0)
Block(-6,43,-4,rustic:iron_lattice:0)
Block(-5,40,-4,rustic:iron_lattice:0)
Block(-5,40,-3,rustic:iron_lattice:0)
Block(-5,40,-2,rustic:iron_lattice:0)
Block(-5,41,-3,rustic:iron_lattice:0)
Block(-5,41,-2,rustic:iron_lattice:0)
Block(-5,42,-4,rustic:iron_lattice:0)
Block(-5,42,-3,rustic:iron_lattice:0)
Block(-4,37,-2,quark:basalt_wall)
Block(-4,37,-1,quark:basalt_wall)
Block(-4,38,-2,IRON_FENCE:0)
Block(-4,38,-1,IRON_FENCE:0)
Block(-4,39,-2,quark:basalt_wall)
Block(-4,39,-1,quark:basalt_wall)
Block(-4,40,-3,rustic:iron_lattice:0)
Block(-4,40,-2,rustic:iron_lattice:0)
Block(-4,40,-1,rustic:iron_lattice:0)
Block(-4,41,-3,rustic:iron_lattice:0)
Block(-4,41,-2,rustic:iron_lattice:0)
Block(-3,36,-1,quark:basalt_wall)
Block(-3,37,-1,quark:basalt_wall)
Block(-3,38,-2,IRON_FENCE:0)
Block(-3,38,-1,IRON_FENCE:0)
Block(-3,39,-2,quark:basalt_wall)
Block(-3,39,-1,quark:basalt_wall)
Block(-3,40,-2,rustic:iron_lattice:0)
Block(-3,40,-1,rustic:iron_lattice:0)

#######################################################################
# +-----------------------------------------------------------------+ #
# |                             Branches                            | #
# +-----------------------------------------------------------------+ #
#######################################################################

Branch(-16,0,0,true,PowerLineNewC0R1,NORTH,100.0,0)

#######################################################################
# +-----------------------------------------------------------------+ #
# |                             Entities                            | #
# +-----------------------------------------------------------------+ #
#######################################################################


#######################################################################
# +-----------------------------------------------------------------+ #
# |                            Particles                            | #
# +-----------------------------------------------------------------+ #
#######################################################################


#######################################################################
# +-----------------------------------------------------------------+ #
# |                             Spawners                            | #
# +-----------------------------------------------------------------+ #
#######################################################################


#######################################################################
# +-----------------------------------------------------------------+ #
# |                             ModData                             | #
# +-----------------------------------------------------------------+ #
#######################################################################

