
#######################################################################
# +-----------------------------------------------------------------+ #
# |                            BO4 object                           | #
# +-----------------------------------------------------------------+ #
#######################################################################

Author: NLBlackEagle

Description: No description given

SettingsMode: WriteDisable


#######################################################################
# +-----------------------------------------------------------------+ #
# |                          Main settings                          | #
# +-----------------------------------------------------------------+ #
#######################################################################

Frequency: 0

SpawnHeight: highestBlock

UseCenterForHighestBlock: true

##############################
# Height Limits for the BO4. #
##############################

MinHeight: 0

MaxHeight: 255

InheritBO3: 

InheritBO3Rotation: NORTH

OverrideChildSettings: true

OverrideParentHeight: false

CanOverride: true

BranchFrequency: 0

BranchFrequencyGroup: 

MustBeBelowOther: false

MustBeInside: 

CannotBeInside: 

ReplacesBO3: 

MustBeInsideWorldBorders: false

CanSpawnOnWater: true

SpawnOnWaterOnly: false

SpawnUnderWater: false

SpawnAtWaterLevel: false

HeightOffset: 0

RemoveAir: true

ReplaceAbove: 

ReplaceBelow: 

ReplaceWithBiomeBlocks: true

ReplaceWithSurfaceBlock: GRASS

ReplaceWithGroundBlock: DIRT

ReplaceWithStoneBlock: STONE

SmoothRadius: 0

SmoothHeightOffset: 0

SmoothStartTop: false

SmoothStartWood: false

SmoothingSurfaceBlock: 

SmoothingGroundBlock: 

BO3Group: 

IsSpawnPoint: false

DoReplaceBlocks: true


#######################################################################
# +-----------------------------------------------------------------+ #
# |                              Blocks                             | #
# +-----------------------------------------------------------------+ #
#######################################################################

Block(1,0,-7,STAINED_CLAY:3)
Block(1,0,-6,STAINED_CLAY:3)
Block(1,1,-7,STAINED_CLAY:3)
Block(1,1,-6,STAINED_CLAY:3)
Block(1,2,-7,STAINED_CLAY:3)
Block(1,2,-6,STAINED_CLAY:3)
Block(1,3,-7,STAINED_CLAY:3)
Block(1,3,-6,STAINED_CLAY:3)
Block(1,4,-7,STAINED_CLAY:3)
Block(1,4,-6,STAINED_CLAY:3)
Block(1,5,-7,STAINED_CLAY:3)
Block(1,5,-6,STAINED_CLAY:3)
Block(1,6,-7,STAINED_CLAY:3)
Block(1,7,-7,OBSIDIAN:0)
Block(1,8,-7,OBSIDIAN:0)
Block(1,9,-7,OBSIDIAN:0)
Block(1,10,-7,OBSIDIAN:0)
Block(1,11,-7,OBSIDIAN:0)
Block(1,12,-7,OBSIDIAN:0)
Block(1,13,-7,OBSIDIAN:0)
Block(2,0,-7,STAINED_CLAY:3)
Block(2,0,-6,STAINED_CLAY:3)
Block(2,0,-5,STAINED_CLAY:3)
Block(2,0,-4,STAINED_CLAY:3)
Block(2,1,-7,STAINED_CLAY:3)
Block(2,1,-6,STAINED_CLAY:3)
Block(2,1,-5,STAINED_CLAY:3)
Block(2,1,-4,STAINED_CLAY:3)
Block(2,2,-7,STAINED_CLAY:3)
Block(2,2,-6,STAINED_CLAY:3)
Block(2,2,-5,STAINED_CLAY:3)
Block(2,2,-4,STAINED_CLAY:3)
Block(2,3,-7,STAINED_CLAY:3)
Block(2,3,-6,STAINED_CLAY:3)
Block(2,3,-5,STAINED_CLAY:3)
Block(2,4,-7,STAINED_CLAY:3)
Block(2,4,-6,STAINED_CLAY:3)
Block(2,4,-5,STAINED_CLAY:3)
Block(2,5,-7,STAINED_CLAY:3)
Block(2,5,-6,STAINED_CLAY:3)
Block(2,5,-5,STAINED_CLAY:3)
Block(2,6,-7,STAINED_CLAY:3)
Block(2,6,-6,OBSIDIAN:0)
Block(2,6,-5,OBSIDIAN:0)
Block(2,7,-7,OBSIDIAN:0)
Block(2,7,-6,OBSIDIAN:0)
Block(2,7,-5,OBSIDIAN:0)
Block(2,8,-7,OBSIDIAN:0)
Block(2,8,-6,OBSIDIAN:0)
Block(2,8,-5,OBSIDIAN:0)
Block(2,9,-7,OBSIDIAN:0)
Block(2,9,-6,OBSIDIAN:0)
Block(2,9,-5,OBSIDIAN:0)
Block(2,10,-7,OBSIDIAN:0)
Block(2,10,-6,OBSIDIAN:0)
Block(2,10,-5,OBSIDIAN:0)
Block(2,11,-7,OBSIDIAN:0)
Block(2,11,-6,OBSIDIAN:0)
Block(2,11,-5,OBSIDIAN:0)
Block(2,12,-7,OBSIDIAN:0)
Block(2,12,-6,OBSIDIAN:0)
Block(2,13,-7,OBSIDIAN:0)
Block(2,13,-6,OBSIDIAN:0)
Block(3,0,-7,STAINED_CLAY:3)
Block(3,0,-6,STAINED_CLAY:3)
Block(3,0,-5,STAINED_CLAY:3)
Block(3,0,-4,STAINED_CLAY:3)
Block(3,0,-3,STAINED_CLAY:3)
Block(3,0,-2,STAINED_CLAY:3)
Block(3,1,-7,STAINED_CLAY:3)
Block(3,1,-6,STAINED_CLAY:3)
Block(3,1,-5,STAINED_CLAY:3)
Block(3,1,-4,STAINED_CLAY:3)
Block(3,1,-3,STAINED_CLAY:3)
Block(3,2,-7,STAINED_CLAY:3)
Block(3,2,-6,STAINED_CLAY:3)
Block(3,2,-5,STAINED_CLAY:3)
Block(3,2,-4,STAINED_CLAY:3)
Block(3,2,-3,STAINED_CLAY:3)
Block(3,3,-7,STAINED_CLAY:3)
Block(3,3,-6,STAINED_CLAY:3)
Block(3,3,-5,STAINED_CLAY:3)
Block(3,3,-4,STAINED_CLAY:3)
Block(3,3,-3,STAINED_CLAY:3)
Block(3,4,-7,STAINED_CLAY:3)
Block(3,4,-6,STAINED_CLAY:3)
Block(3,4,-5,STAINED_CLAY:3)
Block(3,4,-4,STAINED_CLAY:3)
Block(3,4,-3,STAINED_CLAY:3)
Block(3,5,-7,STAINED_CLAY:3)
Block(3,5,-6,STAINED_CLAY:3)
Block(3,5,-5,OBSIDIAN:0)
Block(3,5,-4,OBSIDIAN:0)
Block(3,5,-3,OBSIDIAN:0)
Block(3,6,-7,OBSIDIAN:0)
Block(3,6,-6,OBSIDIAN:0)
Block(3,6,-5,OBSIDIAN:0)
Block(3,6,-4,OBSIDIAN:0)
Block(3,6,-3,OBSIDIAN:0)
Block(3,7,-7,OBSIDIAN:0)
Block(3,7,-6,OBSIDIAN:0)
Block(3,7,-5,OBSIDIAN:0)
Block(3,7,-4,OBSIDIAN:0)
Block(3,7,-3,OBSIDIAN:0)
Block(3,8,-7,OBSIDIAN:0)
Block(3,8,-6,OBSIDIAN:0)
Block(3,8,-5,OBSIDIAN:0)
Block(3,8,-4,OBSIDIAN:0)
Block(3,8,-3,OBSIDIAN:0)
Block(3,9,-7,OBSIDIAN:0)
Block(3,9,-6,OBSIDIAN:0)
Block(3,9,-5,OBSIDIAN:0)
Block(3,9,-4,OBSIDIAN:0)
Block(3,10,-7,OBSIDIAN:0)
Block(3,10,-6,OBSIDIAN:0)
Block(3,10,-5,OBSIDIAN:0)
Block(3,10,-4,OBSIDIAN:0)
Block(3,11,-7,OBSIDIAN:0)
Block(3,11,-6,OBSIDIAN:0)
Block(3,11,-5,OBSIDIAN:0)
Block(3,11,-4,OBSIDIAN:0)
Block(3,12,-7,OBSIDIAN:0)
Block(3,12,-6,OBSIDIAN:0)
Block(3,12,-5,OBSIDIAN:0)
Block(3,13,-7,OBSIDIAN:0)
Block(4,0,-7,STAINED_CLAY:3)
Block(4,0,-6,STAINED_CLAY:3)
Block(4,0,-5,STAINED_CLAY:3)
Block(4,0,-4,STAINED_CLAY:3)
Block(4,0,-3,STAINED_CLAY:3)
Block(4,0,-2,STAINED_CLAY:3)
Block(4,0,-1,STAINED_CLAY:3)
Block(4,1,-7,STAINED_CLAY:3)
Block(4,1,-6,STAINED_CLAY:3)
Block(4,1,-5,STAINED_CLAY:3)
Block(4,1,-4,STAINED_CLAY:3)
Block(4,1,-3,STAINED_CLAY:3)
Block(4,1,-2,STAINED_CLAY:3)
Block(4,1,-1,STAINED_CLAY:3)
Block(4,2,-7,STAINED_CLAY:3)
Block(4,2,-6,STAINED_CLAY:3)
Block(4,2,-5,STAINED_CLAY:3)
Block(4,2,-4,STAINED_CLAY:3)
Block(4,2,-3,STAINED_CLAY:3)
Block(4,2,-2,STAINED_CLAY:3)
Block(4,2,-1,STAINED_CLAY:3)
Block(4,3,-7,STAINED_CLAY:3)
Block(4,3,-6,STAINED_CLAY:3)
Block(4,3,-5,STAINED_CLAY:3)
Block(4,3,-4,STAINED_CLAY:3)
Block(4,3,-3,STAINED_CLAY:3)
Block(4,3,-2,OBSIDIAN:0)
Block(4,3,-1,OBSIDIAN:0)
Block(4,4,-7,STAINED_CLAY:3)
Block(4,4,-6,STAINED_CLAY:3)
Block(4,4,-5,STAINED_CLAY:3)
Block(4,4,-4,STAINED_CLAY:3)
Block(4,4,-3,OBSIDIAN:0)
Block(4,4,-2,OBSIDIAN:0)
Block(4,4,-1,OBSIDIAN:0)
Block(4,5,-7,STAINED_CLAY:3)
Block(4,5,-6,STAINED_CLAY:3)
Block(4,5,-5,OBSIDIAN:0)
Block(4,5,-4,OBSIDIAN:0)
Block(4,5,-3,OBSIDIAN:0)
Block(4,5,-2,OBSIDIAN:0)
Block(4,5,-1,OBSIDIAN:0)
Block(4,6,-7,OBSIDIAN:0)
Block(4,6,-6,OBSIDIAN:0)
Block(4,6,-5,OBSIDIAN:0)
Block(4,6,-4,OBSIDIAN:0)
Block(4,6,-3,OBSIDIAN:0)
Block(4,6,-2,OBSIDIAN:0)
Block(4,6,-1,OBSIDIAN:0)
Block(4,7,-7,OBSIDIAN:0)
Block(4,7,-6,OBSIDIAN:0)
Block(4,7,-5,OBSIDIAN:0)
Block(4,7,-4,OBSIDIAN:0)
Block(4,7,-3,OBSIDIAN:0)
Block(4,7,-2,OBSIDIAN:0)
Block(4,8,-7,OBSIDIAN:0)
Block(4,8,-6,OBSIDIAN:0)
Block(4,8,-5,OBSIDIAN:0)
Block(4,8,-4,OBSIDIAN:0)
Block(4,8,-3,OBSIDIAN:0)
Block(4,8,-2,OBSIDIAN:0)
Block(4,9,-7,OBSIDIAN:0)
Block(4,9,-6,OBSIDIAN:0)
Block(4,9,-5,OBSIDIAN:0)
Block(4,9,-4,OBSIDIAN:0)
Block(4,9,-3,OBSIDIAN:0)
Block(4,9,-2,OBSIDIAN:0)
Block(4,10,-7,OBSIDIAN:0)
Block(4,10,-6,OBSIDIAN:0)
Block(4,10,-5,OBSIDIAN:0)
Block(4,10,-4,OBSIDIAN:0)
Block(4,10,-3,OBSIDIAN:0)
Block(4,11,-7,OBSIDIAN:0)
Block(4,11,-6,OBSIDIAN:0)
Block(4,11,-5,OBSIDIAN:0)
Block(4,12,-7,OBSIDIAN:0)
Block(4,12,-6,OBSIDIAN:0)
Block(5,0,-7,STAINED_CLAY:3)
Block(5,0,-6,STAINED_CLAY:3)
Block(5,0,-5,STAINED_CLAY:3)
Block(5,0,-4,STAINED_CLAY:3)
Block(5,0,-3,STAINED_CLAY:3)
Block(5,0,-2,STAINED_CLAY:3)
Block(5,0,-1,STAINED_CLAY:3)
Block(5,0,0,STAINED_CLAY:3)
Block(5,0,1,STAINED_CLAY:3)
Block(5,1,-7,STAINED_CLAY:3)
Block(5,1,-6,STAINED_CLAY:3)
Block(5,1,-5,STAINED_CLAY:3)
Block(5,1,-4,STAINED_CLAY:3)
Block(5,1,-3,STAINED_CLAY:3)
Block(5,1,-2,STAINED_CLAY:3)
Block(5,1,-1,STAINED_CLAY:3)
Block(5,1,0,OBSIDIAN:0)
Block(5,1,1,OBSIDIAN:0)
Block(5,2,-7,STAINED_CLAY:3)
Block(5,2,-6,STAINED_CLAY:3)
Block(5,2,-5,STAINED_CLAY:3)
Block(5,2,-4,STAINED_CLAY:3)
Block(5,2,-3,STAINED_CLAY:3)
Block(5,2,-2,STAINED_CLAY:3)
Block(5,2,-1,OBSIDIAN:0)
Block(5,2,0,OBSIDIAN:0)
Block(5,2,1,OBSIDIAN:0)
Block(5,3,-7,STAINED_CLAY:3)
Block(5,3,-6,STAINED_CLAY:3)
Block(5,3,-5,STAINED_CLAY:3)
Block(5,3,-4,STAINED_CLAY:3)
Block(5,3,-3,OBSIDIAN:0)
Block(5,3,-2,OBSIDIAN:0)
Block(5,3,-1,OBSIDIAN:0)
Block(5,3,0,OBSIDIAN:0)
Block(5,3,1,OBSIDIAN:0)
Block(5,4,-7,STAINED_CLAY:3)
Block(5,4,-6,STAINED_CLAY:3)
Block(5,4,-5,STAINED_CLAY:3)
Block(5,4,-4,OBSIDIAN:0)
Block(5,4,-3,OBSIDIAN:0)
Block(5,4,-2,OBSIDIAN:0)
Block(5,4,-1,OBSIDIAN:0)
Block(5,4,0,OBSIDIAN:0)
Block(5,4,1,OBSIDIAN:0)
Block(5,5,-7,STAINED_CLAY:3)
Block(5,5,-6,STAINED_CLAY:3)
Block(5,5,-5,OBSIDIAN:0)
Block(5,5,-4,OBSIDIAN:0)
Block(5,5,-3,OBSIDIAN:0)
Block(5,5,-2,OBSIDIAN:0)
Block(5,5,-1,OBSIDIAN:0)
Block(5,5,0,OBSIDIAN:0)
Block(5,6,-7,OBSIDIAN:0)
Block(5,6,-6,OBSIDIAN:0)
Block(5,6,-5,OBSIDIAN:0)
Block(5,6,-4,OBSIDIAN:0)
Block(5,6,-3,OBSIDIAN:0)
Block(5,6,-2,OBSIDIAN:0)
Block(5,6,-1,OBSIDIAN:0)
Block(5,6,0,OBSIDIAN:0)
Block(5,7,-7,OBSIDIAN:0)
Block(5,7,-6,OBSIDIAN:0)
Block(5,7,-5,OBSIDIAN:0)
Block(5,7,-4,OBSIDIAN:0)
Block(5,7,-3,OBSIDIAN:0)
Block(5,7,-2,OBSIDIAN:0)
Block(5,7,-1,OBSIDIAN:0)
Block(5,7,0,OBSIDIAN:0)
Block(5,8,-7,OBSIDIAN:0)
Block(5,8,-6,OBSIDIAN:0)
Block(5,8,-5,OBSIDIAN:0)
Block(5,8,-4,OBSIDIAN:0)
Block(5,8,-3,OBSIDIAN:0)
Block(5,8,-2,OBSIDIAN:0)
Block(5,8,-1,OBSIDIAN:0)
Block(5,8,0,OBSIDIAN:0)
Block(5,9,-7,OBSIDIAN:0)
Block(5,9,-6,OBSIDIAN:0)
Block(5,9,-5,OBSIDIAN:0)
Block(5,9,-4,OBSIDIAN:0)
Block(5,9,-3,OBSIDIAN:0)
Block(5,9,-2,OBSIDIAN:0)
Block(5,10,-7,OBSIDIAN:0)
Block(5,10,-6,OBSIDIAN:0)
Block(5,10,-5,OBSIDIAN:0)
Block(5,10,-4,OBSIDIAN:0)
Block(5,11,-7,OBSIDIAN:0)
Block(5,11,-6,OBSIDIAN:0)
Block(5,11,-5,OBSIDIAN:0)
Block(5,12,-7,OBSIDIAN:0)
Block(6,0,-7,STAINED_CLAY:3)
Block(6,0,-6,STAINED_CLAY:3)
Block(6,0,-5,STAINED_CLAY:3)
Block(6,0,-4,STAINED_CLAY:3)
Block(6,0,-3,STAINED_CLAY:3)
Block(6,0,-2,STAINED_CLAY:3)
Block(6,0,-1,STAINED_CLAY:3)
Block(6,0,0,STAINED_CLAY:3)
Block(6,0,1,OBSIDIAN:0)
Block(6,0,2,OBSIDIAN:0)
Block(6,0,3,OBSIDIAN:0)
Block(6,1,-7,STAINED_CLAY:3)
Block(6,1,-6,STAINED_CLAY:3)
Block(6,1,-5,STAINED_CLAY:3)
Block(6,1,-4,STAINED_CLAY:3)
Block(6,1,-3,STAINED_CLAY:3)
Block(6,1,-2,STAINED_CLAY:3)
Block(6,1,-1,OBSIDIAN:0)
Block(6,1,0,OBSIDIAN:0)
Block(6,1,1,OBSIDIAN:0)
Block(6,1,2,OBSIDIAN:0)
Block(6,1,3,OBSIDIAN:0)
Block(6,2,-7,STAINED_CLAY:3)
Block(6,2,-6,STAINED_CLAY:3)
Block(6,2,-5,STAINED_CLAY:3)
Block(6,2,-4,STAINED_CLAY:3)
Block(6,2,-3,STAINED_CLAY:3)
Block(6,2,-2,OBSIDIAN:0)
Block(6,2,-1,OBSIDIAN:0)
Block(6,2,0,OBSIDIAN:0)
Block(6,2,1,OBSIDIAN:0)
Block(6,2,2,OBSIDIAN:0)
Block(6,3,-7,STAINED_CLAY:3)
Block(6,3,-6,STAINED_CLAY:3)
Block(6,3,-5,STAINED_CLAY:3)
Block(6,3,-4,STAINED_CLAY:3)
Block(6,3,-3,OBSIDIAN:0)
Block(6,3,-2,OBSIDIAN:0)
Block(6,3,-1,OBSIDIAN:0)
Block(6,3,0,OBSIDIAN:0)
Block(6,3,1,OBSIDIAN:0)
Block(6,3,2,OBSIDIAN:0)
Block(6,4,-7,STAINED_CLAY:3)
Block(6,4,-6,STAINED_CLAY:3)
Block(6,4,-5,STAINED_CLAY:3)
Block(6,4,-4,OBSIDIAN:0)
Block(6,4,-3,OBSIDIAN:0)
Block(6,4,-2,OBSIDIAN:0)
Block(6,4,-1,OBSIDIAN:0)
Block(6,4,0,OBSIDIAN:0)
Block(6,4,1,OBSIDIAN:0)
Block(6,4,2,OBSIDIAN:0)
Block(6,5,-7,STAINED_CLAY:3)
Block(6,5,-6,STAINED_CLAY:3)
Block(6,5,-5,OBSIDIAN:0)
Block(6,5,-4,OBSIDIAN:0)
Block(6,5,-3,OBSIDIAN:0)
Block(6,5,-2,OBSIDIAN:0)
Block(6,5,-1,OBSIDIAN:0)
Block(6,5,0,OBSIDIAN:0)
Block(6,5,1,OBSIDIAN:0)
Block(6,5,2,OBSIDIAN:0)
Block(6,6,-7,STAINED_CLAY:3)
Block(6,6,-6,OBSIDIAN:0)
Block(6,6,-5,OBSIDIAN:0)
Block(6,6,-4,OBSIDIAN:0)
Block(6,6,-3,OBSIDIAN:0)
Block(6,6,-2,OBSIDIAN:0)
Block(6,6,-1,OBSIDIAN:0)
Block(6,6,0,OBSIDIAN:0)
Block(6,6,1,OBSIDIAN:0)
Block(6,6,2,OBSIDIAN:0)
Block(6,7,-7,OBSIDIAN:0)
Block(6,7,-6,OBSIDIAN:0)
Block(6,7,-5,OBSIDIAN:0)
Block(6,7,-4,OBSIDIAN:0)
Block(6,7,-3,OBSIDIAN:0)
Block(6,7,-2,OBSIDIAN:0)
Block(6,7,-1,OBSIDIAN:0)
Block(6,7,0,OBSIDIAN:0)
Block(6,7,1,OBSIDIAN:0)
Block(6,8,-7,OBSIDIAN:0)
Block(6,8,-6,OBSIDIAN:0)
Block(6,8,-5,OBSIDIAN:0)
Block(6,8,-4,OBSIDIAN:0)
Block(6,8,-3,OBSIDIAN:0)
Block(6,8,-2,OBSIDIAN:0)
Block(6,8,-1,OBSIDIAN:0)
Block(6,9,-7,OBSIDIAN:0)
Block(6,9,-6,OBSIDIAN:0)
Block(6,9,-5,OBSIDIAN:0)
Block(6,9,-4,OBSIDIAN:0)
Block(6,9,-3,OBSIDIAN:0)
Block(6,10,-7,OBSIDIAN:0)
Block(6,10,-6,OBSIDIAN:0)
Block(6,10,-5,OBSIDIAN:0)
Block(6,10,-4,OBSIDIAN:0)
Block(6,11,-7,OBSIDIAN:0)
Block(6,11,-6,OBSIDIAN:0)
Block(7,0,-7,STAINED_CLAY:3)
Block(7,0,-6,STAINED_CLAY:3)
Block(7,0,-5,STAINED_CLAY:3)
Block(7,0,-4,STAINED_CLAY:3)
Block(7,0,-3,STAINED_CLAY:3)
Block(7,0,-2,STAINED_CLAY:3)
Block(7,0,-1,STAINED_CLAY:3)
Block(7,0,0,OBSIDIAN:0)
Block(7,0,1,OBSIDIAN:0)
Block(7,0,2,OBSIDIAN:0)
Block(7,0,3,OBSIDIAN:0)
Block(7,0,4,OBSIDIAN:0)
Block(7,1,-7,STAINED_CLAY:3)
Block(7,1,-6,STAINED_CLAY:3)
Block(7,1,-5,STAINED_CLAY:3)
Block(7,1,-4,STAINED_CLAY:3)
Block(7,1,-3,STAINED_CLAY:3)
Block(7,1,-2,STAINED_CLAY:3)
Block(7,1,-1,OBSIDIAN:0)
Block(7,1,0,OBSIDIAN:0)
Block(7,1,1,OBSIDIAN:0)
Block(7,1,2,OBSIDIAN:0)
Block(7,1,3,OBSIDIAN:0)
Block(7,1,4,OBSIDIAN:0)
Block(7,2,-7,STAINED_CLAY:3)
Block(7,2,-6,STAINED_CLAY:3)
Block(7,2,-5,STAINED_CLAY:3)
Block(7,2,-4,STAINED_CLAY:3)
Block(7,2,-3,STAINED_CLAY:3)
Block(7,2,-2,OBSIDIAN:0)
Block(7,2,-1,OBSIDIAN:0)
Block(7,2,0,OBSIDIAN:0)
Block(7,2,1,OBSIDIAN:0)
Block(7,2,2,OBSIDIAN:0)
Block(7,2,3,OBSIDIAN:0)
Block(7,2,4,OBSIDIAN:0)
Block(7,3,-7,STAINED_CLAY:3)
Block(7,3,-6,STAINED_CLAY:3)
Block(7,3,-5,STAINED_CLAY:3)
Block(7,3,-4,STAINED_CLAY:3)
Block(7,3,-3,OBSIDIAN:0)
Block(7,3,-2,OBSIDIAN:0)
Block(7,3,-1,OBSIDIAN:0)
Block(7,3,0,OBSIDIAN:0)
Block(7,3,1,OBSIDIAN:0)
Block(7,3,2,OBSIDIAN:0)
Block(7,3,3,OBSIDIAN:0)
Block(7,3,4,OBSIDIAN:0)
Block(7,4,-7,STAINED_CLAY:3)
Block(7,4,-6,STAINED_CLAY:3)
Block(7,4,-5,STAINED_CLAY:3)
Block(7,4,-4,OBSIDIAN:0)
Block(7,4,-3,OBSIDIAN:0)
Block(7,4,-2,OBSIDIAN:0)
Block(7,4,-1,OBSIDIAN:0)
Block(7,4,0,OBSIDIAN:0)
Block(7,4,1,OBSIDIAN:0)
Block(7,4,2,OBSIDIAN:0)
Block(7,4,3,OBSIDIAN:0)
Block(7,4,4,OBSIDIAN:0)
Block(7,5,-7,STAINED_CLAY:3)
Block(7,5,-6,STAINED_CLAY:3)
Block(7,5,-5,OBSIDIAN:0)
Block(7,5,-4,OBSIDIAN:0)
Block(7,5,-3,OBSIDIAN:0)
Block(7,5,-2,OBSIDIAN:0)
Block(7,5,-1,OBSIDIAN:0)
Block(7,5,0,OBSIDIAN:0)
Block(7,5,1,OBSIDIAN:0)
Block(7,5,2,OBSIDIAN:0)
Block(7,5,3,OBSIDIAN:0)
Block(7,6,-7,STAINED_CLAY:3)
Block(7,6,-6,STAINED_CLAY:3)
Block(7,6,-5,OBSIDIAN:0)
Block(7,6,-4,OBSIDIAN:0)
Block(7,6,-3,OBSIDIAN:0)
Block(7,6,-2,OBSIDIAN:0)
Block(7,6,-1,OBSIDIAN:0)
Block(7,6,0,OBSIDIAN:0)
Block(7,6,1,OBSIDIAN:0)
Block(7,7,-7,OBSIDIAN:0)
Block(7,7,-6,OBSIDIAN:0)
Block(7,7,-5,OBSIDIAN:0)
Block(7,7,-4,OBSIDIAN:0)
Block(7,7,-3,OBSIDIAN:0)
Block(7,7,-2,OBSIDIAN:0)
Block(7,7,-1,OBSIDIAN:0)
Block(7,7,0,OBSIDIAN:0)
Block(7,8,-7,OBSIDIAN:0)
Block(7,8,-6,OBSIDIAN:0)
Block(7,8,-5,OBSIDIAN:0)
Block(7,8,-4,OBSIDIAN:0)
Block(7,8,-3,OBSIDIAN:0)
Block(7,8,-2,OBSIDIAN:0)
Block(7,9,-7,OBSIDIAN:0)
Block(7,9,-6,OBSIDIAN:0)
Block(7,9,-5,OBSIDIAN:0)
Block(7,9,-4,OBSIDIAN:0)
Block(7,9,-3,OBSIDIAN:0)
Block(7,10,-7,OBSIDIAN:0)
Block(7,10,-6,OBSIDIAN:0)
Block(7,10,-5,OBSIDIAN:0)
Block(7,11,-7,OBSIDIAN:0)

#######################################################################
# +-----------------------------------------------------------------+ #
# |                             Branches                            | #
# +-----------------------------------------------------------------+ #
#######################################################################


#######################################################################
# +-----------------------------------------------------------------+ #
# |                             Entities                            | #
# +-----------------------------------------------------------------+ #
#######################################################################


#######################################################################
# +-----------------------------------------------------------------+ #
# |                            Particles                            | #
# +-----------------------------------------------------------------+ #
#######################################################################


#######################################################################
# +-----------------------------------------------------------------+ #
# |                             Spawners                            | #
# +-----------------------------------------------------------------+ #
#######################################################################


#######################################################################
# +-----------------------------------------------------------------+ #
# |                             ModData                             | #
# +-----------------------------------------------------------------+ #
#######################################################################

