
#######################################################################
# +-----------------------------------------------------------------+ #
# |                            BO4 object                           | #
# +-----------------------------------------------------------------+ #
#######################################################################

Author: NLBlackEagle

Description: No description given

SettingsMode: WriteDisable


#######################################################################
# +-----------------------------------------------------------------+ #
# |                          Main settings                          | #
# +-----------------------------------------------------------------+ #
#######################################################################

Frequency: 0

SpawnHeight: highestBlock

UseCenterForHighestBlock: true

##############################
# Height Limits for the BO4. #
##############################

MinHeight: 0

MaxHeight: 255

InheritBO3: 

InheritBO3Rotation: NORTH

OverrideChildSettings: true

OverrideParentHeight: false

CanOverride: true

BranchFrequency: 0

BranchFrequencyGroup: 

MustBeBelowOther: false

MustBeInside: 

CannotBeInside: 

ReplacesBO3: 

MustBeInsideWorldBorders: false

CanSpawnOnWater: true

SpawnOnWaterOnly: false

SpawnUnderWater: false

SpawnAtWaterLevel: false

HeightOffset: 0

RemoveAir: true

ReplaceAbove: 

ReplaceBelow: 

ReplaceWithBiomeBlocks: true

ReplaceWithSurfaceBlock: GRASS

ReplaceWithGroundBlock: DIRT

ReplaceWithStoneBlock: STONE

SmoothRadius: 0

SmoothHeightOffset: 0

SmoothStartTop: false

SmoothStartWood: false

SmoothingSurfaceBlock: 

SmoothingGroundBlock: 

BO3Group: 

IsSpawnPoint: false

DoReplaceBlocks: true


#######################################################################
# +-----------------------------------------------------------------+ #
# |                              Blocks                             | #
# +-----------------------------------------------------------------+ #
#######################################################################

Block(-8,0,2,STAINED_CLAY:0)
Block(-8,0,3,STAINED_CLAY:0)
Block(-8,0,4,STAINED_CLAY:0)
Block(-8,0,5,STAINED_CLAY:0)
Block(-8,0,6,STAINED_CLAY:0)
Block(-8,0,7,DIRT:1)
Block(-8,0,8,DIRT:1)
Block(-8,1,1,STAINED_CLAY:0)
Block(-8,1,2,STAINED_CLAY:0)
Block(-8,1,3,STAINED_CLAY:0)
Block(-8,1,4,STAINED_CLAY:0)
Block(-8,1,5,STAINED_CLAY:0)
Block(-8,1,6,STAINED_CLAY:0)
Block(-8,1,7,DIRT:1)
Block(-8,1,8,DIRT:1)
Block(-8,2,1,STAINED_CLAY:0)
Block(-8,2,2,STAINED_CLAY:0)
Block(-8,2,3,STAINED_CLAY:0)
Block(-8,2,4,STAINED_CLAY:0)
Block(-8,2,5,STAINED_CLAY:0)
Block(-8,2,6,STAINED_CLAY:0)
Block(-8,2,7,DIRT:1)
Block(-8,2,8,DIRT:1)
Block(-8,3,1,STAINED_CLAY:0)
Block(-8,3,2,STAINED_CLAY:0)
Block(-8,3,3,STAINED_CLAY:0)
Block(-8,3,4,STAINED_CLAY:0)
Block(-8,3,5,STAINED_CLAY:0)
Block(-8,3,6,STAINED_CLAY:0)
Block(-8,3,7,STAINED_CLAY:0)
Block(-8,3,8,DIRT:1)
Block(-8,4,1,STAINED_CLAY:0)
Block(-8,4,2,STAINED_CLAY:0)
Block(-8,4,3,STAINED_CLAY:0)
Block(-8,4,4,STAINED_CLAY:0)
Block(-8,4,5,STAINED_CLAY:0)
Block(-8,4,6,STAINED_CLAY:0)
Block(-8,4,7,STAINED_CLAY:0)
Block(-8,4,8,DIRT:1)
Block(-8,5,1,STAINED_CLAY:0)
Block(-8,5,2,STAINED_CLAY:0)
Block(-8,5,3,STAINED_CLAY:0)
Block(-8,5,4,STAINED_CLAY:0)
Block(-8,5,5,STAINED_CLAY:0)
Block(-8,5,6,STAINED_CLAY:0)
Block(-8,6,1,STAINED_CLAY:0)
Block(-7,0,2,STAINED_CLAY:0)
Block(-7,0,3,STAINED_CLAY:0)
Block(-7,0,4,STAINED_CLAY:0)
Block(-7,0,5,STAINED_CLAY:0)
Block(-7,0,6,STAINED_CLAY:0)
Block(-7,0,7,STAINED_CLAY:0)
Block(-7,0,8,DIRT:1)
Block(-7,1,2,STAINED_CLAY:0)
Block(-7,1,3,STAINED_CLAY:0)
Block(-7,1,4,STAINED_CLAY:0)
Block(-7,1,5,STAINED_CLAY:0)
Block(-7,1,6,STAINED_CLAY:0)
Block(-7,1,7,STAINED_CLAY:0)
Block(-7,1,8,DIRT:1)
Block(-7,2,2,STAINED_CLAY:0)
Block(-7,2,3,STAINED_CLAY:0)
Block(-7,2,4,STAINED_CLAY:0)
Block(-7,2,5,STAINED_CLAY:0)
Block(-7,2,6,STAINED_CLAY:0)
Block(-7,2,7,DIRT:1)
Block(-7,2,8,DIRT:1)
Block(-7,3,2,STAINED_CLAY:0)
Block(-7,3,3,STAINED_CLAY:0)
Block(-7,3,4,STAINED_CLAY:0)
Block(-7,3,5,STAINED_CLAY:0)
Block(-7,3,6,STAINED_CLAY:0)
Block(-7,3,7,STAINED_CLAY:0)
Block(-7,3,8,DIRT:1)
Block(-7,4,2,STAINED_CLAY:0)
Block(-7,4,3,STAINED_CLAY:0)
Block(-7,4,4,STAINED_CLAY:0)
Block(-7,4,5,STAINED_CLAY:0)
Block(-7,4,6,STAINED_CLAY:0)
Block(-7,5,1,STAINED_CLAY:0)
Block(-6,0,3,STAINED_CLAY:0)
Block(-6,0,4,STAINED_CLAY:0)
Block(-6,0,5,STAINED_CLAY:0)
Block(-6,0,6,STAINED_CLAY:0)
Block(-6,0,7,STAINED_CLAY:0)
Block(-6,0,8,STAINED_CLAY:0)
Block(-6,1,3,STAINED_CLAY:0)
Block(-6,1,4,STAINED_CLAY:0)
Block(-6,1,5,STAINED_CLAY:0)
Block(-6,1,6,STAINED_CLAY:0)
Block(-6,1,7,STAINED_CLAY:0)
Block(-6,1,8,DIRT:1)
Block(-6,2,3,STAINED_CLAY:0)
Block(-6,2,4,STAINED_CLAY:0)
Block(-6,2,5,STAINED_CLAY:0)
Block(-6,2,6,STAINED_CLAY:0)
Block(-6,2,7,STAINED_CLAY:0)
Block(-6,2,8,DIRT:1)
Block(-6,3,2,STAINED_CLAY:0)
Block(-6,3,3,STAINED_CLAY:0)
Block(-6,3,4,STAINED_CLAY:0)
Block(-6,3,5,STAINED_CLAY:0)
Block(-6,3,6,STAINED_CLAY:0)
Block(-5,0,4,STAINED_CLAY:0)
Block(-5,0,5,STAINED_CLAY:0)
Block(-5,0,6,STAINED_CLAY:0)
Block(-5,0,7,STAINED_CLAY:0)
Block(-5,0,8,STAINED_CLAY:0)
Block(-5,1,3,STAINED_CLAY:0)
Block(-5,1,4,STAINED_CLAY:0)
Block(-5,1,5,STAINED_CLAY:0)
Block(-5,1,6,STAINED_CLAY:0)
Block(-5,1,7,STAINED_CLAY:0)
Block(-5,1,8,STAINED_CLAY:0)
Block(-5,2,3,STAINED_CLAY:0)
Block(-5,2,4,STAINED_CLAY:0)
Block(-5,2,5,STAINED_CLAY:0)
Block(-5,2,6,STAINED_CLAY:0)
Block(-4,0,4,STAINED_CLAY:0)
Block(-4,0,5,STAINED_CLAY:0)
Block(-4,0,6,STAINED_CLAY:0)
Block(-4,0,7,STAINED_CLAY:0)
Block(-4,0,8,STAINED_CLAY:0)
Block(-4,1,4,STAINED_CLAY:0)
Block(-4,1,5,STAINED_CLAY:0)
Block(-4,1,6,STAINED_CLAY:0)
Block(-3,0,5,STAINED_CLAY:0)
Block(-3,0,6,STAINED_CLAY:0)

#######################################################################
# +-----------------------------------------------------------------+ #
# |                             Branches                            | #
# +-----------------------------------------------------------------+ #
#######################################################################

Branch(0,0,16,true,MudSpike_Huge_01C4R4,NORTH,100.0,0)

#######################################################################
# +-----------------------------------------------------------------+ #
# |                             Entities                            | #
# +-----------------------------------------------------------------+ #
#######################################################################


#######################################################################
# +-----------------------------------------------------------------+ #
# |                            Particles                            | #
# +-----------------------------------------------------------------+ #
#######################################################################


#######################################################################
# +-----------------------------------------------------------------+ #
# |                             Spawners                            | #
# +-----------------------------------------------------------------+ #
#######################################################################


#######################################################################
# +-----------------------------------------------------------------+ #
# |                             ModData                             | #
# +-----------------------------------------------------------------+ #
#######################################################################

