
#######################################################################
# +-----------------------------------------------------------------+ #
# |                            BO3 object                           | #
# +-----------------------------------------------------------------+ #
#######################################################################

Author: NLBlackHeavenNL

Description: No description given

Version: 3

SettingsMode: WriteWithoutComments


#######################################################################
# +-----------------------------------------------------------------+ #
# |                          Main settings                          | #
# +-----------------------------------------------------------------+ #
#######################################################################

Tree: true

Frequency: 1

Rarity: 100.0

RotateRandomly: false

SpawnHeight: highestSolidBlock

SpawnHeightOffset: -1

SpawnHeightVariance: 0

##############################
# Height Limits for the BO3. #
##############################

MinHeight: 0

MaxHeight: 255

######################
# Extrusion settings #
######################

ExtrudeMode: None

ExtrudeThroughBlocks: AIR

MaxBranchDepth: 10

ExcludedBiomes: All


#######################################################################
# +-----------------------------------------------------------------+ #
# |                      Source block settings                      | #
# +-----------------------------------------------------------------+ #
#######################################################################

SourceBlocks: AIR,GRASS,DIRT,biomesoplenty:dirt,biomesoplenty:grass,GRAVEL,STAINED_CLAY

MaxPercentageOutsideSourceBlock: 0

OutsideSourceBlock: placeAnyway

DoReplaceBlocks: true

IsOTGPlus: false


#######################################################################
# +-----------------------------------------------------------------+ #
# |                              Blocks                             | #
# +-----------------------------------------------------------------+ #
#######################################################################

Block(-2,5,1,dynamictreesbop:leaves4:0)
Block(-2,7,1,dynamictreesbop:leaves4:0)
Block(-2,11,1,dynamictreesbop:leaves4:0)
Block(-1,5,0,dynamictreesbop:leaves4:0)
Block(-1,5,1,dynamictreesbop:leaves4:1)
Block(-1,5,2,dynamictreesbop:leaves4:0)
Block(-1,6,1,dynamictreesbop:leaves4:0)
Block(-1,7,0,dynamictreesbop:leaves4:0)
Block(-1,7,1,dynamictreesbop:leaves4:1)
Block(-1,7,2,dynamictreesbop:leaves4:0)
Block(-1,8,1,dynamictreesbop:leaves4:0)
Block(-1,9,0,dynamictreesbop:leaves4:0)
Block(-1,11,0,dynamictreesbop:leaves4:0)
Block(-1,11,1,dynamictreesbop:leaves4:1)
Block(-1,11,2,dynamictreesbop:leaves4:0)
Block(-1,12,1,dynamictreesbop:leaves4:0)
Block(-1,13,2,dynamictreesbop:leaves4:0)
Block(-1,16,1,dynamictreesbop:leaves4:0)
Block(0,5,-1,dynamictreesbop:leaves4:0)
Block(0,5,0,dynamictreesbop:leaves4:1)
Block(0,5,1,dynamictreesbop:pinebranch)
Block(0,5,2,dynamictreesbop:leaves4:1)
Block(0,5,3,dynamictreesbop:leaves4:0)
Block(0,6,0,dynamictreesbop:leaves4:0)
Block(0,6,1,dynamictreesbop:leaves4:0)
Block(0,6,2,dynamictreesbop:leaves4:0)
Block(0,7,-1,dynamictreesbop:leaves4:0)
Block(0,7,0,dynamictreesbop:leaves4:1)
Block(0,7,1,dynamictreesbop:pinebranch)
Block(0,7,2,dynamictreesbop:leaves4:1)
Block(0,7,3,dynamictreesbop:leaves4:0)
Block(0,8,0,dynamictreesbop:leaves4:0)
Block(0,8,1,dynamictreesbop:leaves4:0)
Block(0,8,2,dynamictreesbop:leaves4:0)
Block(0,9,-1,dynamictreesbop:leaves4:0)
Block(0,9,0,dynamictreesbop:leaves4:1)
Block(0,10,0,dynamictreesbop:leaves4:0)
Block(0,11,-1,dynamictreesbop:leaves4:0)
Block(0,11,0,dynamictreesbop:leaves4:1)
Block(0,11,1,dynamictreesbop:pinebranch)
Block(0,11,2,dynamictreesbop:leaves4:1)
Block(0,11,3,dynamictreesbop:leaves4:0)
Block(0,12,0,dynamictreesbop:leaves4:0)
Block(0,12,1,dynamictreesbop:leaves4:0)
Block(0,12,2,dynamictreesbop:leaves4:0)
Block(0,13,1,dynamictreesbop:leaves4:0)
Block(0,13,2,dynamictreesbop:leaves4:1)
Block(0,13,3,dynamictreesbop:leaves4:0)
Block(0,14,2,dynamictreesbop:leaves4:0)
Block(0,16,0,dynamictreesbop:leaves4:0)
Block(0,16,1,dynamictreesbop:leaves4:1)
Block(0,16,2,dynamictreesbop:leaves4:0)
Block(0,17,1,dynamictreesbop:leaves4:0)
Block(1,0,1,dynamictrees:rootydirt)
Block(1,1,1,dynamictreesbop:pinebranch:7)
Block(1,2,1,dynamictreesbop:pinebranch:7)
Block(1,3,1,dynamictreesbop:pinebranch:6)
Block(1,4,1,dynamictreesbop:pinebranch:6)
Block(1,5,-2,dynamictreesbop:leaves4:0)
Block(1,5,-1,dynamictreesbop:leaves4:1)
Block(1,5,0,dynamictreesbop:pinebranch)
Block(1,5,1,dynamictreesbop:pinebranch:6)
Block(1,5,2,dynamictreesbop:pinebranch)
Block(1,5,3,dynamictreesbop:leaves4:1)
Block(1,5,4,dynamictreesbop:leaves4:0)
Block(1,6,-1,dynamictreesbop:leaves4:0)
Block(1,6,0,dynamictreesbop:leaves4:0)
Block(1,6,1,dynamictreesbop:pinebranch:5)
Block(1,6,2,dynamictreesbop:leaves4:0)
Block(1,6,3,dynamictreesbop:leaves4:0)
Block(1,7,-2,dynamictreesbop:leaves4:0)
Block(1,7,-1,dynamictreesbop:leaves4:1)
Block(1,7,0,dynamictreesbop:pinebranch)
Block(1,7,1,dynamictreesbop:pinebranch:5)
Block(1,7,2,dynamictreesbop:pinebranch)
Block(1,7,3,dynamictreesbop:leaves4:1)
Block(1,7,4,dynamictreesbop:leaves4:0)
Block(1,8,-1,dynamictreesbop:leaves4:0)
Block(1,8,0,dynamictreesbop:leaves4:0)
Block(1,8,1,dynamictreesbop:pinebranch:4)
Block(1,8,2,dynamictreesbop:leaves4:0)
Block(1,8,3,dynamictreesbop:leaves4:0)
Block(1,9,-2,dynamictreesbop:leaves4:0)
Block(1,9,-1,dynamictreesbop:leaves4:1)
Block(1,9,0,dynamictreesbop:pinebranch)
Block(1,9,1,dynamictreesbop:pinebranch:4)
Block(1,10,-1,dynamictreesbop:leaves4:0)
Block(1,10,0,dynamictreesbop:leaves4:0)
Block(1,10,1,dynamictreesbop:pinebranch:3)
Block(1,11,0,dynamictreesbop:leaves4:0)
Block(1,11,1,dynamictreesbop:pinebranch:3)
Block(1,12,1,dynamictreesbop:pinebranch:2)
Block(1,13,1,dynamictreesbop:pinebranch:2)
Block(1,13,2,dynamictreesbop:pinebranch)
Block(1,13,3,dynamictreesbop:leaves4:1)
Block(1,13,4,dynamictreesbop:leaves4:0)
Block(1,14,1,dynamictreesbop:pinebranch:1)
Block(1,14,2,dynamictreesbop:leaves4:0)
Block(1,14,3,dynamictreesbop:leaves4:0)
Block(1,15,1,dynamictreesbop:pinebranch:1)
Block(1,16,-1,dynamictreesbop:leaves4:0)
Block(1,16,0,dynamictreesbop:leaves4:1)
Block(1,16,1,dynamictreesbop:pinebranch)
Block(1,16,2,dynamictreesbop:leaves4:1)
Block(1,16,3,dynamictreesbop:leaves4:0)
Block(1,17,0,dynamictreesbop:leaves4:0)
Block(1,17,1,dynamictreesbop:leaves4)
Block(1,17,2,dynamictreesbop:leaves4:0)
Block(1,18,1,dynamictreesbop:leaves4:2)
Block(1,19,1,dynamictreesbop:leaves4:0)
Block(2,5,-1,dynamictreesbop:leaves4:0)
Block(2,5,0,dynamictreesbop:leaves4:1)
Block(2,5,1,dynamictreesbop:pinebranch)
Block(2,5,2,dynamictreesbop:leaves4:1)
Block(2,5,3,dynamictreesbop:leaves4:0)
Block(2,6,0,dynamictreesbop:leaves4:0)
Block(2,6,1,dynamictreesbop:leaves4:0)
Block(2,6,2,dynamictreesbop:leaves4:0)
Block(2,7,-1,dynamictreesbop:leaves4:0)
Block(2,7,0,dynamictreesbop:leaves4:1)
Block(2,7,1,dynamictreesbop:pinebranch)
Block(2,7,2,dynamictreesbop:leaves4:1)
Block(2,7,3,dynamictreesbop:leaves4:0)
Block(2,8,0,dynamictreesbop:leaves4:0)
Block(2,8,1,dynamictreesbop:leaves4:0)
Block(2,8,2,dynamictreesbop:leaves4:0)
Block(2,9,-1,dynamictreesbop:leaves4:0)
Block(2,9,0,dynamictreesbop:leaves4:1)
Block(2,9,1,dynamictreesbop:leaves4:0)
Block(2,10,0,dynamictreesbop:leaves4:0)
Block(2,13,1,dynamictreesbop:leaves4:0)
Block(2,13,2,dynamictreesbop:leaves4:1)
Block(2,13,3,dynamictreesbop:leaves4:0)
Block(2,14,2,dynamictreesbop:leaves4:0)
Block(2,16,0,dynamictreesbop:leaves4:0)
Block(2,16,1,dynamictreesbop:leaves4:1)
Block(2,16,2,dynamictreesbop:leaves4:0)
Block(2,17,1,dynamictreesbop:leaves4:0)
Block(3,5,0,dynamictreesbop:leaves4:0)
Block(3,5,1,dynamictreesbop:leaves4:1)
Block(3,5,2,dynamictreesbop:leaves4:0)
Block(3,6,1,dynamictreesbop:leaves4:0)
Block(3,7,0,dynamictreesbop:leaves4:0)
Block(3,7,1,dynamictreesbop:leaves4:1)
Block(3,7,2,dynamictreesbop:leaves4:0)
Block(3,8,1,dynamictreesbop:leaves4:0)
Block(3,9,0,dynamictreesbop:leaves4:0)
Block(3,13,2,dynamictreesbop:leaves4:0)
Block(3,16,1,dynamictreesbop:leaves4:0)
Block(4,5,1,dynamictreesbop:leaves4:0)
Block(4,7,1,dynamictreesbop:leaves4:0)

#######################################################################
# +-----------------------------------------------------------------+ #
# |                            BO3 checks                           | #
# +-----------------------------------------------------------------+ #
#######################################################################

BlockCheck(1,-1,1,GRASS,DIRT,GRAVEL,STAINED_CLAY,biomesoplenty:grass,biomesoplenty:dirt)

#######################################################################
# +-----------------------------------------------------------------+ #
# |                             Branches                            | #
# +-----------------------------------------------------------------+ #
#######################################################################


#######################################################################
# +-----------------------------------------------------------------+ #
# |                             Entities                            | #
# +-----------------------------------------------------------------+ #
#######################################################################


#######################################################################
# +-----------------------------------------------------------------+ #
# |                            Particles                            | #
# +-----------------------------------------------------------------+ #
#######################################################################


#######################################################################
# +-----------------------------------------------------------------+ #
# |                             Spawners                            | #
# +-----------------------------------------------------------------+ #
#######################################################################


#######################################################################
# +-----------------------------------------------------------------+ #
# |                             ModData                             | #
# +-----------------------------------------------------------------+ #
#######################################################################

