#######################################################################
# +-----------------------------------------------------------------+ #
# |                            BO3 object                           | #
# +-----------------------------------------------------------------+ #
#######################################################################

Author: Bo3 BulkEdit

Description: Converted Schematic - Modified by Bo3BulkEdit

Version: 3

SettingsMode: WriteDisable

#######################################################################
# +-----------------------------------------------------------------+ #
# |                          Main settings                          | #
# +-----------------------------------------------------------------+ #
#######################################################################



Frequency: 0


SpawnHeight: randomY





##############################
# Height Limits for the BO3. #
##############################

MinHeight: 0
MaxHeight: 256

#######################################################################
# +-----------------------------------------------------------------+ #
# |                      Source block settings                      | #
# +-----------------------------------------------------------------+ #
#######################################################################

CanOverride: true
MaxPercentageOutsideSourceBlock: 100
OutsideSourceBlock: placeAnyway

#######################################################################
# +-----------------------------------------------------------------+ #
# |                               OTG+                              | #
# +-----------------------------------------------------------------+ #
#######################################################################

#######################################################################
# +-----------------------------------------------------------------+ #
# |                              Blocks                             | #
# +-----------------------------------------------------------------+ #
#######################################################################

B(0,750,0,AIR)
B(15,750,15,AIR)
B(13,-1,0,betternether:quartz_stained_glass:15)
B(14,-1,0,betternether:quartz_stained_glass:15)
B(15,-1,0,betternether:quartz_stained_glass:15)
B(14,-1,1,betternether:quartz_stained_glass:15)
B(15,-1,1,betternether:quartz_stained_glass:15)
B(14,-1,2,betternether:quartz_stained_glass:15)
B(15,-1,2,betternether:quartz_stained_glass:15)
B(15,-1,3,betternether:quartz_stained_glass:15)
B(11,0,0,betternether:quartz_stained_glass:15)
B(12,0,0,betternether:quartz_stained_glass:15)
B(13,0,0,betternether:quartz_stained_glass:15)
B(14,0,0,betternether:quartz_stained_glass:15)
RB(15,0,0,srparasites:parasitestain:1,80,quark:crystal:1,30,srparasites:parasiterubbledense:1,100)
B(11,0,1,betternether:quartz_stained_glass:15)
B(12,0,1,betternether:quartz_stained_glass:15)
B(13,0,1,betternether:quartz_stained_glass:15)
B(14,0,1,betternether:quartz_stained_glass:15)
B(12,0,2,betternether:quartz_stained_glass:15)
B(13,0,2,betternether:quartz_stained_glass:15)
B(14,0,2,betternether:quartz_stained_glass:15)
B(14,0,3,betternether:quartz_stained_glass:15)
B(15,0,3,betternether:quartz_stained_glass:15)
B(10,1,0,betternether:quartz_stained_glass:15)
B(11,1,0,betternether:quartz_stained_glass:15)
B(12,1,0,betternether:quartz_stained_glass:15)
B(13,1,0,betternether:quartz_stained_glass:15)
B(14,1,0,betternether:quartz_stained_glass:15)
B(15,1,0,betternether:quartz_stained_glass:15)
B(11,1,1,betternether:quartz_stained_glass:15)
B(12,1,1,betternether:quartz_stained_glass:15)
B(13,1,1,betternether:quartz_stained_glass:15)
B(14,1,1,betternether:quartz_stained_glass:15)
B(15,1,1,betternether:quartz_stained_glass:15)
B(12,1,2,betternether:quartz_stained_glass:15)
B(13,1,2,betternether:quartz_stained_glass:15)
B(14,1,2,betternether:quartz_stained_glass:15)
B(15,1,2,betternether:quartz_stained_glass:15)
B(13,1,3,betternether:quartz_stained_glass:15)
B(14,1,3,betternether:quartz_stained_glass:15)
B(15,1,3,betternether:quartz_stained_glass:15)
B(10,2,0,betternether:quartz_stained_glass:15)
B(11,2,0,betternether:quartz_stained_glass:15)
B(12,2,0,betternether:quartz_stained_glass:15)
B(13,2,0,betternether:quartz_stained_glass:15)
B(14,2,0,betternether:quartz_stained_glass:15)
B(15,2,0,betternether:quartz_stained_glass:15)
B(11,2,1,betternether:quartz_stained_glass:15)
B(12,2,1,betternether:quartz_stained_glass:15)
B(13,2,1,betternether:quartz_stained_glass:15)
B(14,2,1,betternether:quartz_stained_glass:15)
B(15,2,1,betternether:quartz_stained_glass:15)
B(12,2,2,betternether:quartz_stained_glass:15)
B(13,2,2,betternether:quartz_stained_glass:15)
B(14,2,2,betternether:quartz_stained_glass:15)
B(15,2,2,betternether:quartz_stained_glass:15)
B(14,2,3,betternether:quartz_stained_glass:15)
B(10,3,0,betternether:quartz_stained_glass:15)
B(11,3,0,betternether:quartz_stained_glass:15)
B(12,3,0,betternether:quartz_stained_glass:15)
B(13,3,0,betternether:quartz_stained_glass:15)
B(14,3,0,betternether:quartz_stained_glass:15)
B(15,3,0,betternether:quartz_stained_glass:15)
B(11,3,1,betternether:quartz_stained_glass:15)
B(12,3,1,betternether:quartz_stained_glass:15)
B(13,3,1,betternether:quartz_stained_glass:15)
B(14,3,1,betternether:quartz_stained_glass:15)
B(15,3,1,betternether:quartz_stained_glass:15)
B(12,3,2,betternether:quartz_stained_glass:15)
B(13,3,2,betternether:quartz_stained_glass:15)
B(14,3,2,betternether:quartz_stained_glass:15)
B(10,4,0,betternether:quartz_stained_glass:15)
B(11,4,0,betternether:quartz_stained_glass:15)
B(12,4,0,betternether:quartz_stained_glass:15)
B(13,4,0,betternether:quartz_stained_glass:15)
B(14,4,0,betternether:quartz_stained_glass:15)
B(15,4,0,betternether:quartz_stained_glass:15)
B(11,4,1,betternether:quartz_stained_glass:15)
B(12,4,1,betternether:quartz_stained_glass:15)
B(13,4,1,betternether:quartz_stained_glass:15)
B(14,4,1,betternether:quartz_stained_glass:15)
B(15,4,1,betternether:quartz_stained_glass:15)
B(13,4,2,betternether:quartz_stained_glass:15)
B(10,5,0,betternether:quartz_stained_glass:15)
B(11,5,0,betternether:quartz_stained_glass:15)
B(12,5,0,betternether:quartz_stained_glass:15)
B(13,5,0,betternether:quartz_stained_glass:15)
B(14,5,0,betternether:quartz_stained_glass:15)
B(15,5,0,betternether:quartz_stained_glass:15)
B(11,5,1,betternether:quartz_stained_glass:15)
B(12,5,1,betternether:quartz_stained_glass:15)
B(13,5,1,betternether:quartz_stained_glass:15)
B(10,6,0,betternether:quartz_stained_glass:15)
B(11,6,0,betternether:quartz_stained_glass:15)
B(12,6,0,betternether:quartz_stained_glass:15)
B(13,6,0,betternether:quartz_stained_glass:15)
B(14,6,0,betternether:quartz_stained_glass:15)
B(12,6,1,betternether:quartz_stained_glass:15)
B(10,7,0,betternether:quartz_stained_glass:15)
B(11,7,0,betternether:quartz_stained_glass:15)
B(12,7,0,betternether:quartz_stained_glass:15)
B(11,8,0,betternether:quartz_stained_glass:15)

#######################################################################
# +-----------------------------------------------------------------+ #
# |                             Branches                            | #
# +-----------------------------------------------------------------+ #
#######################################################################

BR(16,0,0,true,CRYST-FAT-SMALL-04_1x1,NORTH,100,0)
