
#######################################################################
# +-----------------------------------------------------------------+ #
# |                            BO3 object                           | #
# +-----------------------------------------------------------------+ #
#######################################################################

Author: NLBlackEagle

Description: No description given

Version: 3

SettingsMode: WriteDisable


#######################################################################
# +-----------------------------------------------------------------+ #
# |                          Main settings                          | #
# +-----------------------------------------------------------------+ #
#######################################################################

Tree: true

Frequency: 0

Rarity: 100.0

RotateRandomly: true

SpawnHeight: highestSolidBlock

SpawnHeightOffset: -2

SpawnHeightVariance: 0

##############################
# Height Limits for the BO3. #
##############################

MinHeight: 0

MaxHeight: 255

######################
# Extrusion settings #
######################

ExtrudeMode: None

ExtrudeThroughBlocks: AIR

MaxBranchDepth: 10

ExcludedBiomes: All


#######################################################################
# +-----------------------------------------------------------------+ #
# |                      Source block settings                      | #
# +-----------------------------------------------------------------+ #
#######################################################################

SourceBlocks: AIR,FLOWING_WATER,DIRT,GRAVEL,STONE,BIOMESOPLENTY:DIRT,BIOMESOPLENTY:GRASS,GRASS,BIOMESOPLENTY:SAND,BIOMESOPLENTY:MUD

MaxPercentageOutsideSourceBlock: 0

OutsideSourceBlock: placeAnyway

DoReplaceBlocks: true

IsOTGPlus: false


#######################################################################
# +-----------------------------------------------------------------+ #
# |                              Blocks                             | #
# +-----------------------------------------------------------------+ #
#######################################################################

Block(-9,1,-5,SANDSTONE:0)
Block(-9,1,-4,SANDSTONE:0)
Block(-9,1,-3,SANDSTONE:0)
Block(-9,1,-2,SANDSTONE:0)
Block(-9,1,-1,SANDSTONE:0)
Block(-9,1,0,SANDSTONE:0)
Block(-9,1,1,SANDSTONE:0)
Block(-9,1,2,SANDSTONE:0)
Block(-9,1,3,SANDSTONE:0)
Block(-9,1,4,SANDSTONE:0)
Block(-9,1,5,SANDSTONE:0)
Block(-9,2,-5,SANDSTONE:1)
Block(-9,2,-4,SANDSTONE:1)
Block(-9,2,-3,SANDSTONE:1)
Block(-9,2,-2,SANDSTONE:1)
Block(-9,2,-1,SANDSTONE:1)
Block(-9,2,0,SANDSTONE:1)
Block(-9,2,1,SANDSTONE:1)
Block(-9,2,2,SANDSTONE:1)
Block(-9,2,3,SANDSTONE:1)
Block(-9,2,4,SANDSTONE:1)
Block(-9,2,5,SANDSTONE:1)
Block(-8,1,-5,SANDSTONE:0)
Block(-8,1,-4,SANDSTONE:0)
Block(-8,1,-3,SANDSTONE:0)
Block(-8,1,-2,SANDSTONE:0)
Block(-8,1,-1,SANDSTONE:0)
Block(-8,1,0,SANDSTONE:0)
Block(-8,1,1,SANDSTONE:0)
Block(-8,1,2,SANDSTONE:0)
Block(-8,1,3,SANDSTONE:0)
Block(-8,1,4,SANDSTONE:0)
Block(-8,1,5,SANDSTONE:0)
Block(-8,2,-5,SANDSTONE:1)
Block(-8,2,-4,SANDSTONE:0)
Block(-8,2,-3,SANDSTONE:0)
Block(-8,2,-2,SANDSTONE:0)
Block(-8,2,-1,SANDSTONE:0)
Block(-8,2,0,SANDSTONE:0)
Block(-8,2,1,SANDSTONE:0)
Block(-8,2,2,SANDSTONE:0)
Block(-8,2,3,SANDSTONE:0)
Block(-8,2,4,SANDSTONE:0)
Block(-8,2,5,SANDSTONE:1)
Block(-8,3,-4,STEP:1)
Block(-8,3,-3,STEP:1)
Block(-8,3,-2,STEP:1)
Block(-8,3,-1,STEP:1)
Block(-8,3,0,STEP:1)
Block(-8,3,1,STEP:1)
Block(-8,3,2,STEP:1)
Block(-8,3,3,STEP:1)
Block(-8,3,4,STEP:1)
Block(-7,1,-5,SANDSTONE:0)
Block(-7,1,-4,SANDSTONE:0)
Block(-7,1,-3,SANDSTONE:0)
Block(-7,1,-2,SANDSTONE:0)
Block(-7,1,-1,SANDSTONE:0)
Block(-7,1,0,SANDSTONE:0)
Block(-7,1,1,SANDSTONE:0)
Block(-7,1,2,SANDSTONE:0)
Block(-7,1,3,SANDSTONE:0)
Block(-7,1,4,SANDSTONE:0)
Block(-7,1,5,SANDSTONE:0)
Block(-7,2,-5,SANDSTONE:1)
Block(-7,2,-4,SANDSTONE:0)
RandomBlock(-7,2,-3,biomesoplenty:mud,40,SAND:0,100)
RandomBlock(-7,2,-2,biomesoplenty:mud,40,SAND:0,100)
RandomBlock(-7,2,-1,biomesoplenty:mud,40,SAND:0,100)
RandomBlock(-7,2,0,biomesoplenty:mud,40,SAND:0,100)
RandomBlock(-7,2,1,biomesoplenty:mud,40,SAND:0,100)
RandomBlock(-7,2,2,biomesoplenty:mud,40,SAND:0,100)
RandomBlock(-7,2,3,biomesoplenty:mud,40,SAND:0,100)
Block(-7,2,4,SANDSTONE:0)
Block(-7,2,5,SANDSTONE:1)
Block(-7,3,-4,STEP:1)
Block(-7,3,-3,SANDSTONE:2)
Block(-7,3,-2,SANDSTONE:2)
Block(-7,3,-1,SANDSTONE:2)
Block(-7,3,0,SANDSTONE:2)
Block(-7,3,1,SANDSTONE:2)
Block(-7,3,2,SANDSTONE:2)
Block(-7,3,3,SANDSTONE:2)
Block(-7,3,4,STEP:1)
Block(-7,4,-3,AIR:0)
Block(-7,4,-2,AIR:0)
Block(-7,4,-1,AIR:0)
Block(-7,4,0,AIR:0)
Block(-7,4,1,AIR:0)
Block(-7,4,2,AIR:0)
Block(-7,4,3,AIR:0)
Block(-6,1,-5,SANDSTONE:0)
Block(-6,1,-4,SANDSTONE:0)
Block(-6,1,-3,SANDSTONE:0)
Block(-6,1,-2,SANDSTONE:0)
Block(-6,1,-1,SANDSTONE:0)
Block(-6,1,0,SANDSTONE:0)
Block(-6,1,1,SANDSTONE:0)
Block(-6,1,2,SANDSTONE:0)
Block(-6,1,3,SANDSTONE:0)
Block(-6,1,4,SANDSTONE:0)
Block(-6,1,5,SANDSTONE:0)
Block(-6,2,-5,SANDSTONE:1)
Block(-6,2,-4,SANDSTONE:0)
RandomBlock(-6,2,-3,biomesoplenty:mud,40,SAND:0,100)
RandomBlock(-6,2,-2,biomesoplenty:mud,40,SAND:0,100)
RandomBlock(-6,2,-1,biomesoplenty:mud,40,SAND:0,100)
RandomBlock(-6,2,0,biomesoplenty:mud,40,SAND:0,100)
RandomBlock(-6,2,1,biomesoplenty:mud,40,SAND:0,100)
RandomBlock(-6,2,2,biomesoplenty:mud,40,SAND:0,100)
RandomBlock(-6,2,3,biomesoplenty:mud,40,SAND:0,100)
Block(-6,2,4,SANDSTONE:0)
Block(-6,2,5,SANDSTONE:1)
Block(-6,3,-4,STEP:1)
Block(-6,3,-3,SANDSTONE:2)
RandomBlock(-6,3,-2,AIR:0,70,DEADBUSH:0,3,BIOMESOPLENTY:PLANT_1:2,3,BIOMESOPLENTY:PLANT_0:13,6,SAND:0,100)
RandomBlock(-6,3,-1,AIR:0,70,DEADBUSH:0,3,BIOMESOPLENTY:PLANT_1:2,3,BIOMESOPLENTY:PLANT_0:13,6,SAND:0,100)
RandomBlock(-6,3,0,AIR:0,70,DEADBUSH:0,3,BIOMESOPLENTY:PLANT_1:2,3,BIOMESOPLENTY:PLANT_0:13,6,SAND:0,100)
RandomBlock(-6,3,1,AIR:0,70,DEADBUSH:0,3,BIOMESOPLENTY:PLANT_1:2,3,BIOMESOPLENTY:PLANT_0:13,6,SAND:0,100)
RandomBlock(-6,3,2,AIR:0,70,DEADBUSH:0,3,BIOMESOPLENTY:PLANT_1:2,3,BIOMESOPLENTY:PLANT_0:13,6,SAND:0,100)
Block(-6,3,3,SANDSTONE:2)
Block(-6,3,4,STEP:1)
Block(-6,4,-3,AIR:0)
Block(-6,4,-2,AIR:0)
Block(-6,4,-1,AIR:0)
Block(-6,4,0,AIR:0)
Block(-6,4,1,AIR:0)
Block(-6,4,2,AIR:0)
Block(-6,4,3,AIR:0)
Block(-6,5,-2,AIR:0)
Block(-6,5,-1,AIR:0)
Block(-6,5,0,AIR:0)
Block(-6,5,1,AIR:0)
Block(-6,5,2,AIR:0)
Block(-5,1,-5,SANDSTONE:0)
Block(-5,1,-4,SANDSTONE:0)
Block(-5,1,-3,SANDSTONE:0)
Block(-5,1,-2,SANDSTONE:0)
Block(-5,1,-1,SANDSTONE:0)
Block(-5,1,0,SANDSTONE:0)
Block(-5,1,1,SANDSTONE:0)
Block(-5,1,2,SANDSTONE:0)
Block(-5,1,3,SANDSTONE:0)
Block(-5,1,4,SANDSTONE:0)
Block(-5,1,5,SANDSTONE:0)
Block(-5,2,-5,SANDSTONE:1)
Block(-5,2,-4,SANDSTONE:0)
RandomBlock(-5,2,-3,biomesoplenty:mud,40,SAND:0,100)
RandomBlock(-5,2,-2,biomesoplenty:mud,40,SAND:0,100)
RandomBlock(-5,2,-1,biomesoplenty:mud,40,SAND:0,100)
RandomBlock(-5,2,0,biomesoplenty:mud,40,SAND:0,100)
RandomBlock(-5,2,1,biomesoplenty:mud,40,SAND:0,100)
RandomBlock(-5,2,2,biomesoplenty:mud,40,SAND:0,100)
RandomBlock(-5,2,3,biomesoplenty:mud,40,SAND:0,100)
Block(-5,2,4,SANDSTONE:0)
Block(-5,2,5,SANDSTONE:1)
Block(-5,3,-4,STEP:1)
Block(-5,3,-3,SANDSTONE:2)
RandomBlock(-5,3,-2,AIR:0,70,DEADBUSH:0,3,BIOMESOPLENTY:PLANT_1:2,3,BIOMESOPLENTY:PLANT_0:13,6,SAND:0,100)
RandomBlock(-5,3,-1,AIR:0,70,DEADBUSH:0,3,BIOMESOPLENTY:PLANT_1:2,3,BIOMESOPLENTY:PLANT_0:13,6,SAND:0,100)
RandomBlock(-5,3,0,AIR:0,70,DEADBUSH:0,3,BIOMESOPLENTY:PLANT_1:2,3,BIOMESOPLENTY:PLANT_0:13,6,SAND:0,100)
RandomBlock(-5,3,1,AIR:0,70,DEADBUSH:0,3,BIOMESOPLENTY:PLANT_1:2,3,BIOMESOPLENTY:PLANT_0:13,6,SAND:0,100)
RandomBlock(-5,3,2,AIR:0,70,DEADBUSH:0,3,BIOMESOPLENTY:PLANT_1:2,3,BIOMESOPLENTY:PLANT_0:13,6,SAND:0,100)
Block(-5,3,3,SANDSTONE:2)
Block(-5,3,4,STEP:1)
Block(-5,4,-3,AIR:0)
Block(-5,4,-2,AIR:0)
Block(-5,4,-1,AIR:0)
Block(-5,4,0,AIR:0)
Block(-5,4,1,AIR:0)
Block(-5,4,2,AIR:0)
Block(-5,4,3,AIR:0)
Block(-5,5,-2,AIR:0)
Block(-5,5,-1,AIR:0)
Block(-5,5,0,AIR:0)
Block(-5,5,1,AIR:0)
Block(-5,5,2,AIR:0)
Block(-4,1,-5,SANDSTONE:0)
Block(-4,1,-4,SANDSTONE:0)
Block(-4,1,-3,SANDSTONE:0)
Block(-4,1,-2,SANDSTONE:0)
Block(-4,1,-1,SANDSTONE:0)
Block(-4,1,0,SANDSTONE:0)
Block(-4,1,1,SANDSTONE:0)
Block(-4,1,2,SANDSTONE:0)
Block(-4,1,3,SANDSTONE:0)
Block(-4,1,4,SANDSTONE:0)
Block(-4,1,5,SANDSTONE:0)
Block(-4,2,-5,SANDSTONE:1)
Block(-4,2,-4,SANDSTONE:0)
RandomBlock(-4,2,-3,biomesoplenty:mud,40,SAND:0,100)
RandomBlock(-4,2,-2,biomesoplenty:mud,40,SAND:0,100)
RandomBlock(-4,2,-1,biomesoplenty:mud,40,SAND:0,100)
RandomBlock(-4,2,0,biomesoplenty:mud,40,SAND:0,100)
RandomBlock(-4,2,1,biomesoplenty:mud,40,SAND:0,100)
RandomBlock(-4,2,2,biomesoplenty:mud,40,SAND:0,100)
RandomBlock(-4,2,3,biomesoplenty:mud,40,SAND:0,100)
Block(-4,2,4,SANDSTONE:0)
Block(-4,2,5,SANDSTONE:1)
Block(-4,3,-4,STEP:1)
Block(-4,3,-3,SANDSTONE:2)
RandomBlock(-4,3,-2,AIR:0,70,DEADBUSH:0,3,BIOMESOPLENTY:PLANT_1:2,3,BIOMESOPLENTY:PLANT_0:13,6,SAND:0,100)
RandomBlock(-4,3,-1,AIR:0,70,DEADBUSH:0,3,BIOMESOPLENTY:PLANT_1:2,3,BIOMESOPLENTY:PLANT_0:13,6,SAND:0,100)
Block(-4,3,0,SANDSTONE:2)
RandomBlock(-4,3,1,AIR:0,70,DEADBUSH:0,3,BIOMESOPLENTY:PLANT_1:2,3,BIOMESOPLENTY:PLANT_0:13,6,SAND:0,100)
RandomBlock(-4,3,2,AIR:0,70,DEADBUSH:0,3,BIOMESOPLENTY:PLANT_1:2,3,BIOMESOPLENTY:PLANT_0:13,6,SAND:0,100)
Block(-4,3,3,SANDSTONE:2)
Block(-4,3,4,STEP:1)
Block(-4,4,-3,AIR:0)
Block(-4,4,-2,AIR:0)
Block(-4,4,-1,AIR:0)
Block(-4,4,0,SANDSTONE:2)
Block(-4,4,1,AIR:0)
Block(-4,4,2,AIR:0)
Block(-4,4,3,AIR:0)
Block(-4,5,-2,AIR:0)
Block(-4,5,-1,AIR:0)
Block(-4,5,1,AIR:0)
Block(-4,5,2,AIR:0)
Block(-3,1,-5,SANDSTONE:0)
Block(-3,1,-4,SANDSTONE:0)
Block(-3,1,-3,SANDSTONE:0)
Block(-3,1,-2,SANDSTONE:0)
Block(-3,1,-1,SANDSTONE:0)
Block(-3,1,0,SANDSTONE:0)
Block(-3,1,1,SANDSTONE:0)
Block(-3,1,2,SANDSTONE:0)
Block(-3,1,3,SANDSTONE:0)
Block(-3,1,4,SANDSTONE:0)
Block(-3,1,5,SANDSTONE:0)
Block(-3,2,-5,SANDSTONE:1)
Block(-3,2,-4,SANDSTONE:0)
RandomBlock(-3,2,-3,biomesoplenty:mud,40,SAND:0,100)
RandomBlock(-3,2,-2,biomesoplenty:mud,40,SAND:0,100)
RandomBlock(-3,2,-1,biomesoplenty:mud,40,SAND:0,100)
RandomBlock(-3,2,0,biomesoplenty:mud,40,SAND:0,100)
RandomBlock(-3,2,1,biomesoplenty:mud,40,SAND:0,100)
RandomBlock(-3,2,2,biomesoplenty:mud,40,SAND:0,100)
RandomBlock(-3,2,3,biomesoplenty:mud,40,SAND:0,100)
Block(-3,2,4,SANDSTONE:0)
Block(-3,2,5,SANDSTONE:1)
Block(-3,3,-4,STEP:1)
Block(-3,3,-3,SANDSTONE:2)
RandomBlock(-3,3,-2,AIR:0,70,DEADBUSH:0,3,BIOMESOPLENTY:PLANT_1:2,3,BIOMESOPLENTY:PLANT_0:13,6,SAND:0,100)
RandomBlock(-3,3,-1,AIR:0,70,DEADBUSH:0,3,BIOMESOPLENTY:PLANT_1:2,3,BIOMESOPLENTY:PLANT_0:13,6,SAND:0,100)
RandomBlock(-3,3,0,AIR:0,70,DEADBUSH:0,3,BIOMESOPLENTY:PLANT_1:2,3,BIOMESOPLENTY:PLANT_0:13,6,SAND:0,100)
RandomBlock(-3,3,1,AIR:0,70,DEADBUSH:0,3,BIOMESOPLENTY:PLANT_1:2,3,BIOMESOPLENTY:PLANT_0:13,6,SAND:0,100)
RandomBlock(-3,3,2,AIR:0,70,DEADBUSH:0,3,BIOMESOPLENTY:PLANT_1:2,3,BIOMESOPLENTY:PLANT_0:13,6,SAND:0,100)
Block(-3,3,3,SANDSTONE:2)
Block(-3,3,4,STEP:1)
Block(-3,4,-3,AIR:0)
Block(-3,4,-2,AIR:0)
Block(-3,4,-1,AIR:0)
Block(-3,4,0,AIR:0)
Block(-3,4,1,AIR:0)
Block(-3,4,2,AIR:0)
Block(-3,4,3,AIR:0)
Block(-3,5,-2,AIR:0)
Block(-3,5,-1,AIR:0)
Block(-3,5,0,AIR:0)
Block(-3,5,1,AIR:0)
Block(-3,5,2,AIR:0)
Block(-2,1,-5,SANDSTONE:0)
Block(-2,1,-4,SANDSTONE:0)
Block(-2,1,-3,SANDSTONE:0)
Block(-2,1,-2,SANDSTONE:0)
Block(-2,1,-1,SANDSTONE:0)
Block(-2,1,0,SANDSTONE:0)
Block(-2,1,1,SANDSTONE:0)
Block(-2,1,2,SANDSTONE:0)
Block(-2,1,3,SANDSTONE:0)
Block(-2,1,4,SANDSTONE:0)
Block(-2,1,5,SANDSTONE:0)
Block(-2,2,-5,SANDSTONE:1)
Block(-2,2,-4,SANDSTONE:0)
RandomBlock(-2,2,-3,biomesoplenty:mud,40,SAND:0,100)
RandomBlock(-2,2,-2,biomesoplenty:mud,40,SAND:0,100)
RandomBlock(-2,2,-1,biomesoplenty:mud,40,SAND:0,100)
RandomBlock(-2,2,0,biomesoplenty:mud,40,SAND:0,100)
RandomBlock(-2,2,1,biomesoplenty:mud,40,SAND:0,100)
RandomBlock(-2,2,2,biomesoplenty:mud,40,SAND:0,100)
RandomBlock(-2,2,3,biomesoplenty:mud,40,SAND:0,100)
Block(-2,2,4,SANDSTONE:0)
Block(-2,2,5,SANDSTONE:1)
Block(-2,3,-4,STEP:1)
Block(-2,3,-3,SANDSTONE:2)
RandomBlock(-2,3,-2,AIR:0,70,DEADBUSH:0,3,BIOMESOPLENTY:PLANT_1:2,3,BIOMESOPLENTY:PLANT_0:13,6,SAND:0,100)
RandomBlock(-2,3,-1,AIR:0,70,DEADBUSH:0,3,BIOMESOPLENTY:PLANT_1:2,3,BIOMESOPLENTY:PLANT_0:13,6,SAND:0,100)
RandomBlock(-2,3,0,AIR:0,70,DEADBUSH:0,3,BIOMESOPLENTY:PLANT_1:2,3,BIOMESOPLENTY:PLANT_0:13,6,SAND:0,100)
RandomBlock(-2,3,1,AIR:0,70,DEADBUSH:0,3,BIOMESOPLENTY:PLANT_1:2,3,BIOMESOPLENTY:PLANT_0:13,6,SAND:0,100)
RandomBlock(-2,3,2,AIR:0,70,DEADBUSH:0,3,BIOMESOPLENTY:PLANT_1:2,3,BIOMESOPLENTY:PLANT_0:13,6,SAND:0,100)
Block(-2,3,3,SANDSTONE:2)
Block(-2,3,4,STEP:1)
Block(-2,4,-3,AIR:0)
Block(-2,4,-2,AIR:0)
Block(-2,4,-1,AIR:0)
Block(-2,4,0,AIR:0)
Block(-2,4,1,AIR:0)
Block(-2,4,2,AIR:0)
Block(-2,4,3,AIR:0)
Block(-2,5,-2,AIR:0)
Block(-2,5,-1,AIR:0)
Block(-2,5,0,AIR:0)
Block(-2,5,1,AIR:0)
Block(-2,5,2,AIR:0)
Block(-1,1,-5,SANDSTONE:0)
Block(-1,1,-4,SANDSTONE:0)
Block(-1,1,-3,SANDSTONE:0)
Block(-1,1,-2,SANDSTONE:0)
Block(-1,1,-1,SANDSTONE:0)
Block(-1,1,0,SANDSTONE:0)
Block(-1,1,1,SANDSTONE:0)
Block(-1,1,2,SANDSTONE:0)
Block(-1,1,3,SANDSTONE:0)
Block(-1,1,4,SANDSTONE:0)
Block(-1,1,5,SANDSTONE:0)
Block(-1,2,-5,SANDSTONE:1)
Block(-1,2,-4,SANDSTONE:0)
RandomBlock(-1,2,-3,biomesoplenty:mud,40,SAND:0,100)
RandomBlock(-1,2,-2,biomesoplenty:mud,40,SAND:0,100)
RandomBlock(-1,2,-1,biomesoplenty:mud,40,SAND:0,100)
RandomBlock(-1,2,0,biomesoplenty:mud,40,SAND:0,100)
RandomBlock(-1,2,1,biomesoplenty:mud,40,SAND:0,100)
RandomBlock(-1,2,2,biomesoplenty:mud,40,SAND:0,100)
RandomBlock(-1,2,3,biomesoplenty:mud,40,SAND:0,100)
Block(-1,2,4,SANDSTONE:0)
Block(-1,2,5,SANDSTONE:1)
Block(-1,3,-4,STEP:1)
Block(-1,3,-3,SANDSTONE:2)
RandomBlock(-1,3,-2,AIR:0,70,DEADBUSH:0,3,BIOMESOPLENTY:PLANT_1:2,3,BIOMESOPLENTY:PLANT_0:13,6,SAND:0,100)
RandomBlock(-1,3,-1,AIR:0,70,DEADBUSH:0,3,BIOMESOPLENTY:PLANT_1:2,3,BIOMESOPLENTY:PLANT_0:13,6,SAND:0,100)
RandomBlock(-1,3,0,AIR:0,70,DEADBUSH:0,3,BIOMESOPLENTY:PLANT_1:2,3,BIOMESOPLENTY:PLANT_0:13,6,SAND:0,100)
RandomBlock(-1,3,1,AIR:0,70,DEADBUSH:0,3,BIOMESOPLENTY:PLANT_1:2,3,BIOMESOPLENTY:PLANT_0:13,6,SAND:0,100)
RandomBlock(-1,3,2,AIR:0,70,DEADBUSH:0,3,BIOMESOPLENTY:PLANT_1:2,3,BIOMESOPLENTY:PLANT_0:13,6,SAND:0,100)
Block(-1,3,3,SANDSTONE:2)
Block(-1,3,4,STEP:1)
Block(-1,4,-3,AIR:0)
Block(-1,4,-2,AIR:0)
Block(-1,4,-1,AIR:0)
Block(-1,4,0,AIR:0)
Block(-1,4,1,AIR:0)
Block(-1,4,2,AIR:0)
Block(-1,4,3,AIR:0)
Block(-1,5,-2,AIR:0)
Block(-1,5,-1,AIR:0)
Block(-1,5,0,AIR:0)
Block(-1,5,1,AIR:0)
Block(-1,5,2,AIR:0)
Block(0,1,-5,SANDSTONE:0)
Block(0,1,-4,SANDSTONE:0)
Block(0,1,-3,SANDSTONE:0)
Block(0,1,-2,SANDSTONE:0)
Block(0,1,-1,SANDSTONE:0)
Block(0,1,0,SANDSTONE:0)
Block(0,1,1,SANDSTONE:0)
Block(0,1,2,SANDSTONE:0)
Block(0,1,3,SANDSTONE:0)
Block(0,1,4,SANDSTONE:0)
Block(0,1,5,SANDSTONE:0)
Block(0,2,-5,SANDSTONE:1)
Block(0,2,-4,SANDSTONE:0)
RandomBlock(0,2,-3,biomesoplenty:mud,40,SAND:0,100)
RandomBlock(0,2,-2,biomesoplenty:mud,40,SAND:0,100)
RandomBlock(0,2,-1,biomesoplenty:mud,40,SAND:0,100)
RandomBlock(0,2,0,biomesoplenty:mud,40,SAND:0,100)
RandomBlock(0,2,1,biomesoplenty:mud,40,SAND:0,100)
RandomBlock(0,2,2,biomesoplenty:mud,40,SAND:0,100)
RandomBlock(0,2,3,biomesoplenty:mud,40,SAND:0,100)
Block(0,2,4,SANDSTONE:0)
Block(0,2,5,SANDSTONE:1)
Block(0,3,-4,STEP:1)
Block(0,3,-3,SANDSTONE:2)
RandomBlock(0,3,-2,AIR:0,70,DEADBUSH:0,3,BIOMESOPLENTY:PLANT_1:2,3,BIOMESOPLENTY:PLANT_0:13,6,SAND:0,100)
RandomBlock(0,3,-1,AIR:0,70,DEADBUSH:0,3,BIOMESOPLENTY:PLANT_1:2,3,BIOMESOPLENTY:PLANT_0:13,6,SAND:0,100)
Block(0,3,0,SANDSTONE:2)
RandomBlock(0,3,1,AIR:0,70,DEADBUSH:0,3,BIOMESOPLENTY:PLANT_1:2,3,BIOMESOPLENTY:PLANT_0:13,6,SAND:0,100)
RandomBlock(0,3,2,AIR:0,70,DEADBUSH:0,3,BIOMESOPLENTY:PLANT_1:2,3,BIOMESOPLENTY:PLANT_0:13,6,SAND:0,100)
Block(0,3,3,SANDSTONE:2)
Block(0,3,4,STEP:1)
Block(0,4,-3,AIR:0)
Block(0,4,-2,AIR:0)
Block(0,4,-1,AIR:0)
Block(0,4,0,SANDSTONE:2)
Block(0,4,1,AIR:0)
Block(0,4,2,AIR:0)
Block(0,4,3,AIR:0)
Block(0,5,-2,AIR:0)
Block(0,5,-1,AIR:0)
Block(0,5,1,AIR:0)
Block(0,5,2,AIR:0)
Block(1,1,-5,SANDSTONE:0)
Block(1,1,-4,SANDSTONE:0)
Block(1,1,-3,SANDSTONE:0)
Block(1,1,-2,SANDSTONE:0)
Block(1,1,-1,SANDSTONE:0)
Block(1,1,0,SANDSTONE:0)
Block(1,1,1,SANDSTONE:0)
Block(1,1,2,SANDSTONE:0)
Block(1,1,3,SANDSTONE:0)
Block(1,1,4,SANDSTONE:0)
Block(1,1,5,SANDSTONE:0)
Block(1,2,-5,SANDSTONE:1)
Block(1,2,-4,SANDSTONE:0)
RandomBlock(1,2,-3,biomesoplenty:mud,40,SAND:0,100)
RandomBlock(1,2,-2,biomesoplenty:mud,40,SAND:0,100)
RandomBlock(1,2,-1,biomesoplenty:mud,40,SAND:0,100)
RandomBlock(1,2,0,biomesoplenty:mud,40,SAND:0,100)
RandomBlock(1,2,1,biomesoplenty:mud,40,SAND:0,100)
RandomBlock(1,2,2,biomesoplenty:mud,40,SAND:0,100)
RandomBlock(1,2,3,biomesoplenty:mud,40,SAND:0,100)
Block(1,2,4,SANDSTONE:0)
Block(1,2,5,SANDSTONE:1)
Block(1,3,-4,STEP:1)
Block(1,3,-3,SANDSTONE:2)
RandomBlock(1,3,-2,AIR:0,70,DEADBUSH:0,3,BIOMESOPLENTY:PLANT_1:2,3,BIOMESOPLENTY:PLANT_0:13,6,SAND:0,100)
RandomBlock(1,3,-1,AIR:0,70,DEADBUSH:0,3,BIOMESOPLENTY:PLANT_1:2,3,BIOMESOPLENTY:PLANT_0:13,6,SAND:0,100)
RandomBlock(1,3,0,AIR:0,70,DEADBUSH:0,3,BIOMESOPLENTY:PLANT_1:2,3,BIOMESOPLENTY:PLANT_0:13,6,SAND:0,100)
RandomBlock(1,3,1,AIR:0,70,DEADBUSH:0,3,BIOMESOPLENTY:PLANT_1:2,3,BIOMESOPLENTY:PLANT_0:13,6,SAND:0,100)
RandomBlock(1,3,2,AIR:0,70,DEADBUSH:0,3,BIOMESOPLENTY:PLANT_1:2,3,BIOMESOPLENTY:PLANT_0:13,6,SAND:0,100)
Block(1,3,3,SANDSTONE:2)
Block(1,3,4,STEP:1)
Block(1,4,-3,AIR:0)
Block(1,4,-2,AIR:0)
Block(1,4,-1,AIR:0)
Block(1,4,0,AIR:0)
Block(1,4,1,AIR:0)
Block(1,4,2,AIR:0)
Block(1,4,3,AIR:0)
Block(1,5,-2,AIR:0)
Block(1,5,-1,AIR:0)
Block(1,5,0,AIR:0)
Block(1,5,1,AIR:0)
Block(1,5,2,AIR:0)
Block(2,1,-5,SANDSTONE:0)
Block(2,1,-4,SANDSTONE:0)
Block(2,1,-3,SANDSTONE:0)
Block(2,1,-2,SANDSTONE:0)
Block(2,1,-1,SANDSTONE:0)
Block(2,1,0,SANDSTONE:0)
Block(2,1,1,SANDSTONE:0)
Block(2,1,2,SANDSTONE:0)
Block(2,1,3,SANDSTONE:0)
Block(2,1,4,SANDSTONE:0)
Block(2,1,5,SANDSTONE:0)
Block(2,2,-5,SANDSTONE:1)
Block(2,2,-4,SANDSTONE:0)
RandomBlock(2,2,-3,biomesoplenty:mud,40,SAND:0,100)
RandomBlock(2,2,-2,biomesoplenty:mud,40,SAND:0,100)
RandomBlock(2,2,-1,biomesoplenty:mud,40,SAND:0,100)
RandomBlock(2,2,0,biomesoplenty:mud,40,SAND:0,100)
RandomBlock(2,2,1,biomesoplenty:mud,40,SAND:0,100)
RandomBlock(2,2,2,biomesoplenty:mud,40,SAND:0,100)
RandomBlock(2,2,3,biomesoplenty:mud,40,SAND:0,100)
Block(2,2,4,SANDSTONE:0)
Block(2,2,5,SANDSTONE:1)
Block(2,3,-4,STEP:1)
Block(2,3,-3,SANDSTONE:2)
RandomBlock(2,3,-2,AIR:0,70,DEADBUSH:0,3,BIOMESOPLENTY:PLANT_1:2,3,BIOMESOPLENTY:PLANT_0:13,6,SAND:0,100)
RandomBlock(2,3,-1,AIR:0,70,DEADBUSH:0,3,BIOMESOPLENTY:PLANT_1:2,3,BIOMESOPLENTY:PLANT_0:13,6,SAND:0,100)
RandomBlock(2,3,0,AIR:0,70,DEADBUSH:0,3,BIOMESOPLENTY:PLANT_1:2,3,BIOMESOPLENTY:PLANT_0:13,6,SAND:0,100)
RandomBlock(2,3,1,AIR:0,70,DEADBUSH:0,3,BIOMESOPLENTY:PLANT_1:2,3,BIOMESOPLENTY:PLANT_0:13,6,SAND:0,100)
RandomBlock(2,3,2,AIR:0,70,DEADBUSH:0,3,BIOMESOPLENTY:PLANT_1:2,3,BIOMESOPLENTY:PLANT_0:13,6,SAND:0,100)
Block(2,3,3,SANDSTONE:2)
Block(2,3,4,STEP:1)
Block(2,4,-3,AIR:0)
Block(2,4,-2,AIR:0)
Block(2,4,-1,AIR:0)
Block(2,4,0,AIR:0)
Block(2,4,1,AIR:0)
Block(2,4,2,AIR:0)
Block(2,4,3,AIR:0)
Block(2,5,-2,AIR:0)
Block(2,5,-1,AIR:0)
Block(2,5,0,AIR:0)
Block(2,5,1,AIR:0)
Block(2,5,2,AIR:0)
Block(3,1,-5,SANDSTONE:0)
Block(3,1,-4,SANDSTONE:0)
Block(3,1,-3,SANDSTONE:0)
Block(3,1,-2,SANDSTONE:0)
Block(3,1,-1,SANDSTONE:0)
Block(3,1,0,SANDSTONE:0)
Block(3,1,1,SANDSTONE:0)
Block(3,1,2,SANDSTONE:0)
Block(3,1,3,SANDSTONE:0)
Block(3,1,4,SANDSTONE:0)
Block(3,1,5,SANDSTONE:0)
Block(3,2,-5,SANDSTONE:1)
Block(3,2,-4,SANDSTONE:0)
RandomBlock(3,2,-3,biomesoplenty:mud,40,SAND:0,100)
RandomBlock(3,2,-2,biomesoplenty:mud,40,SAND:0,100)
RandomBlock(3,2,-1,biomesoplenty:mud,40,SAND:0,100)
RandomBlock(3,2,0,biomesoplenty:mud,40,SAND:0,100)
RandomBlock(3,2,1,biomesoplenty:mud,40,SAND:0,100)
RandomBlock(3,2,2,biomesoplenty:mud,40,SAND:0,100)
RandomBlock(3,2,3,biomesoplenty:mud,40,SAND:0,100)
Block(3,2,4,SANDSTONE:0)
Block(3,2,5,SANDSTONE:1)
Block(3,3,-4,STEP:1)
Block(3,3,-3,SANDSTONE:2)
RandomBlock(3,3,-2,AIR:0,70,DEADBUSH:0,3,BIOMESOPLENTY:PLANT_1:2,3,BIOMESOPLENTY:PLANT_0:13,6,SAND:0,100)
RandomBlock(3,3,-1,AIR:0,70,DEADBUSH:0,3,BIOMESOPLENTY:PLANT_1:2,3,BIOMESOPLENTY:PLANT_0:13,6,SAND:0,100)
RandomBlock(3,3,0,AIR:0,70,DEADBUSH:0,3,BIOMESOPLENTY:PLANT_1:2,3,BIOMESOPLENTY:PLANT_0:13,6,SAND:0,100)
RandomBlock(3,3,1,AIR:0,70,DEADBUSH:0,3,BIOMESOPLENTY:PLANT_1:2,3,BIOMESOPLENTY:PLANT_0:13,6,SAND:0,100)
RandomBlock(3,3,2,AIR:0,70,DEADBUSH:0,3,BIOMESOPLENTY:PLANT_1:2,3,BIOMESOPLENTY:PLANT_0:13,6,SAND:0,100)
Block(3,3,3,SANDSTONE:2)
Block(3,3,4,STEP:1)
Block(3,4,-3,AIR:0)
Block(3,4,-2,AIR:0)
Block(3,4,-1,AIR:0)
Block(3,4,0,AIR:0)
Block(3,4,1,AIR:0)
Block(3,4,2,AIR:0)
Block(3,4,3,AIR:0)
Block(3,5,-2,AIR:0)
Block(3,5,-1,AIR:0)
Block(3,5,0,AIR:0)
Block(3,5,1,AIR:0)
Block(3,5,2,AIR:0)
Block(4,1,-5,SANDSTONE:0)
Block(4,1,-4,SANDSTONE:0)
Block(4,1,-3,SANDSTONE:0)
Block(4,1,-2,SANDSTONE:0)
Block(4,1,-1,SANDSTONE:0)
Block(4,1,0,SANDSTONE:0)
Block(4,1,1,SANDSTONE:0)
Block(4,1,2,SANDSTONE:0)
Block(4,1,3,SANDSTONE:0)
Block(4,1,4,SANDSTONE:0)
Block(4,1,5,SANDSTONE:0)
Block(4,2,-5,SANDSTONE:1)
Block(4,2,-4,SANDSTONE:0)
RandomBlock(4,2,-3,biomesoplenty:mud,40,SAND:0,100)
RandomBlock(4,2,-2,biomesoplenty:mud,40,SAND:0,100)
RandomBlock(4,2,-1,biomesoplenty:mud,40,SAND:0,100)
RandomBlock(4,2,0,biomesoplenty:mud,40,SAND:0,100)
RandomBlock(4,2,1,biomesoplenty:mud,40,SAND:0,100)
RandomBlock(4,2,2,biomesoplenty:mud,40,SAND:0,100)
RandomBlock(4,2,3,biomesoplenty:mud,40,SAND:0,100)
Block(4,2,4,SANDSTONE:0)
Block(4,2,5,SANDSTONE:1)
Block(4,3,-4,STEP:1)
Block(4,3,-3,SANDSTONE:2)
RandomBlock(4,3,-2,AIR:0,70,DEADBUSH:0,3,BIOMESOPLENTY:PLANT_1:2,3,BIOMESOPLENTY:PLANT_0:13,6,SAND:0,100)
RandomBlock(4,3,-1,AIR:0,70,DEADBUSH:0,3,BIOMESOPLENTY:PLANT_1:2,3,BIOMESOPLENTY:PLANT_0:13,6,SAND:0,100)
Block(4,3,0,SANDSTONE:2)
RandomBlock(4,3,1,AIR:0,70,DEADBUSH:0,3,BIOMESOPLENTY:PLANT_1:2,3,BIOMESOPLENTY:PLANT_0:13,6,SAND:0,100)
RandomBlock(4,3,2,AIR:0,70,DEADBUSH:0,3,BIOMESOPLENTY:PLANT_1:2,3,BIOMESOPLENTY:PLANT_0:13,6,SAND:0,100)
Block(4,3,3,SANDSTONE:2)
Block(4,3,4,STEP:1)
Block(4,4,-3,AIR:0)
Block(4,4,-2,AIR:0)
Block(4,4,-1,AIR:0)
Block(4,4,0,SANDSTONE:2)
Block(4,4,1,AIR:0)
Block(4,4,2,AIR:0)
Block(4,4,3,AIR:0)
Block(4,5,-2,AIR:0)
Block(4,5,-1,AIR:0)
Block(4,5,1,AIR:0)
Block(4,5,2,AIR:0)
Block(5,1,-5,SANDSTONE:0)
Block(5,1,-4,SANDSTONE:0)
Block(5,1,-3,SANDSTONE:0)
Block(5,1,-2,SANDSTONE:0)
Block(5,1,-1,SANDSTONE:0)
Block(5,1,0,SANDSTONE:0)
Block(5,1,1,SANDSTONE:0)
Block(5,1,2,SANDSTONE:0)
Block(5,1,3,SANDSTONE:0)
Block(5,1,4,SANDSTONE:0)
Block(5,1,5,SANDSTONE:0)
Block(5,2,-5,SANDSTONE:1)
Block(5,2,-4,SANDSTONE:0)
RandomBlock(5,2,-3,biomesoplenty:mud,40,SAND:0,100)
RandomBlock(5,2,-2,biomesoplenty:mud,40,SAND:0,100)
RandomBlock(5,2,-1,biomesoplenty:mud,40,SAND:0,100)
RandomBlock(5,2,0,biomesoplenty:mud,40,SAND:0,100)
RandomBlock(5,2,1,biomesoplenty:mud,40,SAND:0,100)
RandomBlock(5,2,2,biomesoplenty:mud,40,SAND:0,100)
RandomBlock(5,2,3,biomesoplenty:mud,40,SAND:0,100)
Block(5,2,4,SANDSTONE:0)
Block(5,2,5,SANDSTONE:1)
Block(5,3,-4,STEP:1)
Block(5,3,-3,SANDSTONE:2)
RandomBlock(5,3,-2,AIR:0,70,DEADBUSH:0,3,BIOMESOPLENTY:PLANT_1:2,3,BIOMESOPLENTY:PLANT_0:13,6,SAND:0,100)
RandomBlock(5,3,-1,AIR:0,70,DEADBUSH:0,3,BIOMESOPLENTY:PLANT_1:2,3,BIOMESOPLENTY:PLANT_0:13,6,SAND:0,100)
RandomBlock(5,3,0,AIR:0,70,DEADBUSH:0,3,BIOMESOPLENTY:PLANT_1:2,3,BIOMESOPLENTY:PLANT_0:13,6,SAND:0,100)
RandomBlock(5,3,1,AIR:0,70,DEADBUSH:0,3,BIOMESOPLENTY:PLANT_1:2,3,BIOMESOPLENTY:PLANT_0:13,6,SAND:0,100)
RandomBlock(5,3,2,AIR:0,70,DEADBUSH:0,3,BIOMESOPLENTY:PLANT_1:2,3,BIOMESOPLENTY:PLANT_0:13,6,SAND:0,100)
Block(5,3,3,SANDSTONE:2)
Block(5,3,4,STEP:1)
Block(5,4,-3,AIR:0)
Block(5,4,-2,AIR:0)
Block(5,4,-1,AIR:0)
Block(5,4,0,AIR:0)
Block(5,4,1,AIR:0)
Block(5,4,2,AIR:0)
Block(5,4,3,AIR:0)
Block(5,5,-2,AIR:0)
Block(5,5,-1,AIR:0)
Block(5,5,0,AIR:0)
Block(5,5,1,AIR:0)
Block(5,5,2,AIR:0)
Block(6,1,-5,SANDSTONE:0)
Block(6,1,-4,SANDSTONE:0)
Block(6,1,-3,SANDSTONE:0)
Block(6,1,-2,SANDSTONE:0)
Block(6,1,-1,SANDSTONE:0)
Block(6,1,0,SANDSTONE:0)
Block(6,1,1,SANDSTONE:0)
Block(6,1,2,SANDSTONE:0)
Block(6,1,3,SANDSTONE:0)
Block(6,1,4,SANDSTONE:0)
Block(6,1,5,SANDSTONE:0)
Block(6,2,-5,SANDSTONE:1)
Block(6,2,-4,SANDSTONE:0)
RandomBlock(6,2,-3,biomesoplenty:mud,40,SAND:0,100)
RandomBlock(6,2,-2,biomesoplenty:mud,40,SAND:0,100)
RandomBlock(6,2,-1,biomesoplenty:mud,40,SAND:0,100)
RandomBlock(6,2,0,biomesoplenty:mud,40,SAND:0,100)
RandomBlock(6,2,1,biomesoplenty:mud,40,SAND:0,100)
RandomBlock(6,2,2,biomesoplenty:mud,40,SAND:0,100)
RandomBlock(6,2,3,biomesoplenty:mud,40,SAND:0,100)
Block(6,2,4,SANDSTONE:0)
Block(6,2,5,SANDSTONE:1)
Block(6,3,-4,STEP:1)
Block(6,3,-3,SANDSTONE:2)
RandomBlock(6,3,-2,AIR:0,70,DEADBUSH:0,3,BIOMESOPLENTY:PLANT_1:2,3,BIOMESOPLENTY:PLANT_0:13,6,SAND:0,100)
RandomBlock(6,3,-1,AIR:0,70,DEADBUSH:0,3,BIOMESOPLENTY:PLANT_1:2,3,BIOMESOPLENTY:PLANT_0:13,6,SAND:0,100)
RandomBlock(6,3,0,AIR:0,70,DEADBUSH:0,3,BIOMESOPLENTY:PLANT_1:2,3,BIOMESOPLENTY:PLANT_0:13,6,SAND:0,100)
RandomBlock(6,3,1,AIR:0,70,DEADBUSH:0,3,BIOMESOPLENTY:PLANT_1:2,3,BIOMESOPLENTY:PLANT_0:13,6,SAND:0,100)
RandomBlock(6,3,2,AIR:0,70,DEADBUSH:0,3,BIOMESOPLENTY:PLANT_1:2,3,BIOMESOPLENTY:PLANT_0:13,6,SAND:0,100)
Block(6,3,3,SANDSTONE:2)
Block(6,3,4,STEP:1)
Block(6,4,-3,AIR:0)
Block(6,4,-2,AIR:0)
Block(6,4,-1,AIR:0)
Block(6,4,0,AIR:0)
Block(6,4,1,AIR:0)
Block(6,4,2,AIR:0)
Block(6,4,3,AIR:0)
Block(6,5,-2,AIR:0)
Block(6,5,-1,AIR:0)
Block(6,5,0,AIR:0)
Block(6,5,1,AIR:0)
Block(6,5,2,AIR:0)
Block(7,1,-5,SANDSTONE:0)
Block(7,1,-4,SANDSTONE:0)
Block(7,1,-3,SANDSTONE:0)
Block(7,1,-2,SANDSTONE:0)
Block(7,1,-1,SANDSTONE:0)
Block(7,1,0,SANDSTONE:0)
Block(7,1,1,SANDSTONE:0)
Block(7,1,2,SANDSTONE:0)
Block(7,1,3,SANDSTONE:0)
Block(7,1,4,SANDSTONE:0)
Block(7,1,5,SANDSTONE:0)
Block(7,2,-5,SANDSTONE:1)
Block(7,2,-4,SANDSTONE:0)
RandomBlock(7,2,-3,biomesoplenty:mud,40,SAND:0,100)
RandomBlock(7,2,-2,biomesoplenty:mud,40,SAND:0,100)
RandomBlock(7,2,-1,biomesoplenty:mud,40,SAND:0,100)
RandomBlock(7,2,0,biomesoplenty:mud,40,SAND:0,100)
RandomBlock(7,2,1,biomesoplenty:mud,40,SAND:0,100)
RandomBlock(7,2,2,biomesoplenty:mud,40,SAND:0,100)
RandomBlock(7,2,3,biomesoplenty:mud,40,SAND:0,100)
Block(7,2,4,SANDSTONE:0)
Block(7,2,5,SANDSTONE:1)
Block(7,3,-4,STEP:1)
Block(7,3,-3,SANDSTONE:2)
Block(7,3,-2,SANDSTONE:2)
Block(7,3,-1,SANDSTONE:2)
Block(7,3,0,SANDSTONE:2)
Block(7,3,1,SANDSTONE:2)
Block(7,3,2,SANDSTONE:2)
Block(7,3,3,SANDSTONE:2)
Block(7,3,4,STEP:1)
Block(7,4,-3,AIR:0)
Block(7,4,-2,AIR:0)
Block(7,4,-1,AIR:0)
Block(7,4,0,AIR:0)
Block(7,4,1,AIR:0)
Block(7,4,2,AIR:0)
Block(7,4,3,AIR:0)
Block(8,1,-5,SANDSTONE:0)
Block(8,1,-4,SANDSTONE:0)
Block(8,1,-3,SANDSTONE:0)
Block(8,1,-2,SANDSTONE:0)
Block(8,1,-1,SANDSTONE:0)
Block(8,1,0,SANDSTONE:0)
Block(8,1,1,SANDSTONE:0)
Block(8,1,2,SANDSTONE:0)
Block(8,1,3,SANDSTONE:0)
Block(8,1,4,SANDSTONE:0)
Block(8,1,5,SANDSTONE:0)
Block(8,2,-5,SANDSTONE:1)
Block(8,2,-4,SANDSTONE:0)
Block(8,2,-3,SANDSTONE:0)
Block(8,2,-2,SANDSTONE:0)
Block(8,2,-1,SANDSTONE:0)
Block(8,2,0,SANDSTONE:0)
Block(8,2,1,SANDSTONE:0)
Block(8,2,2,SANDSTONE:0)
Block(8,2,3,SANDSTONE:0)
Block(8,2,4,SANDSTONE:0)
Block(8,2,5,SANDSTONE:1)
Block(8,3,-4,STEP:1)
Block(8,3,-3,STEP:1)
Block(8,3,-2,STEP:1)
Block(8,3,-1,STEP:1)
Block(8,3,0,STEP:1)
Block(8,3,1,STEP:1)
Block(8,3,2,STEP:1)
Block(8,3,3,STEP:1)
Block(8,3,4,STEP:1)
Block(9,1,-5,SANDSTONE:0)
Block(9,1,-4,SANDSTONE:0)
Block(9,1,-3,SANDSTONE:0)
Block(9,1,-2,SANDSTONE:0)
Block(9,1,-1,SANDSTONE:0)
Block(9,1,0,SANDSTONE:0)
Block(9,1,1,SANDSTONE:0)
Block(9,1,2,SANDSTONE:0)
Block(9,1,3,SANDSTONE:0)
Block(9,1,4,SANDSTONE:0)
Block(9,1,5,SANDSTONE:0)
Block(9,2,-5,SANDSTONE:1)
Block(9,2,-4,SANDSTONE:1)
Block(9,2,-3,SANDSTONE:1)
Block(9,2,-2,SANDSTONE:1)
Block(9,2,-1,SANDSTONE:1)
Block(9,2,0,SANDSTONE:1)
Block(9,2,1,SANDSTONE:1)
Block(9,2,2,SANDSTONE:1)
Block(9,2,3,SANDSTONE:1)
Block(9,2,4,SANDSTONE:1)
Block(9,2,5,SANDSTONE:1)

#######################################################################
# +-----------------------------------------------------------------+ #
# |                            BO3 checks                           | #
# +-----------------------------------------------------------------+ #
#######################################################################

RandomBlock(-4,5,0,WATER:0,10,AIR:0,100)
RandomBlock(0,5,0,WATER:0,10,AIR:0,100)
RandomBlock(4,5,0,WATER:0,10,AIR:0,100)

BlockCheck(-9,0,-5,Solid)
BlockCheck(-9,0,5,Solid)
BlockCheck(9,0,-5,Solid)
BlockCheck(9,0,5,Solid)


#######################################################################
# +-----------------------------------------------------------------+ #
# |                             Branches                            | #
# +-----------------------------------------------------------------+ #
#######################################################################


#######################################################################
# +-----------------------------------------------------------------+ #
# |                             Entities                            | #
# +-----------------------------------------------------------------+ #
#######################################################################


#######################################################################
# +-----------------------------------------------------------------+ #
# |                            Particles                            | #
# +-----------------------------------------------------------------+ #
#######################################################################


#######################################################################
# +-----------------------------------------------------------------+ #
# |                             Spawners                            | #
# +-----------------------------------------------------------------+ #
#######################################################################


#######################################################################
# +-----------------------------------------------------------------+ #
# |                             ModData                             | #
# +-----------------------------------------------------------------+ #
#######################################################################

