
#######################################################################
# +-----------------------------------------------------------------+ #
# |                            BO3 object                           | #
# +-----------------------------------------------------------------+ #
#######################################################################

Author: NLBlackEagle

Description: No description given

Version: 3

SettingsMode: WriteWithoutComments


#######################################################################
# +-----------------------------------------------------------------+ #
# |                          Main settings                          | #
# +-----------------------------------------------------------------+ #
#######################################################################

Tree: true

Frequency: 0

Rarity: 100.0

RotateRandomly: true

SpawnHeight: highestSolidBlock

SpawnHeightOffset: -1

SpawnHeightVariance: 0

##############################
# Height Limits for the BO3. #
##############################

MinHeight: 0

MaxHeight: 255

######################
# Extrusion settings #
######################

ExtrudeMode: None

ExtrudeThroughBlocks: AIR

MaxBranchDepth: 10

ExcludedBiomes: All


#######################################################################
# +-----------------------------------------------------------------+ #
# |                      Source block settings                      | #
# +-----------------------------------------------------------------+ #
#######################################################################

SourceBlocks: ICE,SNOW

MaxPercentageOutsideSourceBlock: 80

OutsideSourceBlock: placeAnyway

DoReplaceBlocks: true

IsOTGPlus: false


#######################################################################
# +-----------------------------------------------------------------+ #
# |                              Blocks                             | #
# +-----------------------------------------------------------------+ #
#######################################################################

Block(-2,0,-2,ICE:0)
Block(-2,0,-1,ICE:0)
Block(-2,0,0,ICE:0)
Block(-2,0,1,ICE:0)
Block(-2,0,2,ICE:0)
Block(-2,0,3,ICE:0)
Block(-2,1,-2,SNOW_BLOCK:0)
Block(-2,1,-1,SNOW_BLOCK:0)
Block(-2,1,0,SNOW_BLOCK:0)
Block(-2,1,2,SNOW_BLOCK:0)
Block(-2,1,3,SNOW_BLOCK:0)
Block(-2,2,-2,SNOW_BLOCK:0)
Block(-2,2,-1,SNOW_BLOCK:0)
Block(-2,2,0,SNOW_BLOCK:0)
Block(-2,2,2,SNOW_BLOCK:0)
Block(-2,2,3,SNOW_BLOCK:0)
Block(-2,3,-2,AIR:0)
Block(-2,3,-1,SNOW_BLOCK:0)
Block(-2,3,0,SNOW_BLOCK:0)
Block(-2,3,2,SNOW_BLOCK:0)
Block(-2,3,3,AIR:0)
Block(-2,4,-2,AIR:0)
Block(-2,4,-1,AIR:0)
Block(-2,4,0,AIR:0)
Block(-2,4,1,AIR:0)
Block(-2,4,2,AIR:0)
Block(-2,4,3,AIR:0)
Block(-1,0,-2,ICE:0)
Block(-1,0,-1,ICE:0)
Block(-1,0,0,ICE:0)
Block(-1,0,1,ICE:0)
Block(-1,0,2,ICE:0)
Block(-1,0,3,ICE:0)
Block(-1,1,-2,SNOW_BLOCK:0)
Block(-1,1,-1,AIR:0)
Block(-1,1,0,AIR:0)
Block(-1,1,1,AIR:0)
Block(-1,1,2,AIR:0)
Block(-1,1,3,SNOW_BLOCK:0)
Block(-1,2,-2,SNOW_BLOCK:0)
Block(-1,2,-1,AIR:0)
Block(-1,2,0,AIR:0)
Block(-1,2,1,AIR:0)
Block(-1,2,2,AIR:0)
Block(-1,2,3,SNOW_BLOCK:0)
Block(-1,3,-2,SNOW_BLOCK:0)
Block(-1,3,-1,SNOW_BLOCK:0)
Block(-1,3,0,AIR:0)
Block(-1,3,1,AIR:0)
Block(-1,3,2,SNOW_BLOCK:0)
Block(-1,3,3,SNOW_BLOCK:0)
Block(-1,4,-2,AIR:0)
Block(-1,4,0,SNOW_BLOCK:0)
Block(-1,4,1,SNOW_BLOCK:0)
Block(-1,4,3,AIR:0)
Block(0,0,-2,ICE:0)
Block(0,0,-1,ICE:0)
Block(0,0,0,ICE:0)
Block(0,0,1,ICE:0)
Block(0,0,2,ICE:0)
Block(0,0,3,ICE:0)
Block(0,1,-1,AIR:0)
Block(0,1,0,AIR:0)
Block(0,1,1,AIR:0)
Block(0,1,2,AIR:0)
Block(0,1,3,SNOW_BLOCK:0)
Block(0,2,-2,AIR:0)
Block(0,2,-1,AIR:0)
Block(0,2,0,AIR:0)
Block(0,2,1,AIR:0)
Block(0,2,2,AIR:0)
Block(0,2,3,AIR:0)
Block(0,3,-1,AIR:0)
Block(0,3,0,AIR:0)
Block(0,3,1,AIR:0)
Block(0,3,2,AIR:0)
Block(0,3,3,SNOW_BLOCK:0)
Block(0,4,-2,AIR:0)
Block(0,4,-1,SNOW_BLOCK:0)
Block(0,4,0,SNOW_BLOCK:0)
Block(0,4,1,SNOW_BLOCK:0)
Block(0,4,2,SNOW_BLOCK:0)
Block(0,4,3,AIR:0)
Block(1,0,-2,ICE:0)
Block(1,0,-1,ICE:0)
Block(1,0,0,ICE:0)
Block(1,0,1,ICE:0)
Block(1,0,2,ICE:0)
Block(1,0,3,ICE:0)
Block(1,1,-2,SNOW_BLOCK:0)
Block(1,1,-1,AIR:0)
Block(1,1,0,AIR:0)
Block(1,1,1,AIR:0)
Block(1,1,2,AIR:0)
Block(1,1,3,SNOW_BLOCK:0)
Block(1,2,-2,AIR:0)
Block(1,2,-1,AIR:0)
Block(1,2,0,AIR:0)
Block(1,2,1,AIR:0)
Block(1,2,2,AIR:0)
Block(1,2,3,AIR:0)
Block(1,3,-2,SNOW_BLOCK:0)
Block(1,3,-1,AIR:0)
Block(1,3,0,AIR:0)
Block(1,3,1,AIR:0)
Block(1,3,2,AIR:0)
Block(1,3,3,SNOW_BLOCK:0)
Block(1,4,-2,AIR:0)
Block(1,4,-1,SNOW_BLOCK:0)
Block(1,4,0,SNOW_BLOCK:0)
Block(1,4,1,SNOW_BLOCK:0)
Block(1,4,2,SNOW_BLOCK:0)
Block(1,4,3,AIR:0)
Block(2,0,-2,ICE:0)
Block(2,0,-1,ICE:0)
Block(2,0,0,ICE:0)
Block(2,0,1,ICE:0)
Block(2,0,2,ICE:0)
Block(2,0,3,ICE:0)
Block(2,1,-2,SNOW_BLOCK:0)
Block(2,1,-1,AIR:0)
Block(2,1,0,AIR:0)
Block(2,1,1,AIR:0)
Block(2,1,2,AIR:0)
Block(2,1,3,SNOW_BLOCK:0)
Block(2,2,-2,SNOW_BLOCK:0)
Block(2,2,-1,AIR:0)
Block(2,2,0,AIR:0)
Block(2,2,1,AIR:0)
Block(2,2,2,AIR:0)
Block(2,2,3,SNOW_BLOCK:0)
Block(2,3,-2,SNOW_BLOCK:0)
Block(2,3,-1,SNOW_BLOCK:0)
Block(2,3,0,AIR:0)
Block(2,3,1,AIR:0)
Block(2,3,2,SNOW_BLOCK:0)
Block(2,3,3,SNOW_BLOCK:0)
Block(2,4,-2,AIR:0)
Block(2,4,-1,SNOW_BLOCK:0)
Block(2,4,0,SNOW_BLOCK:0)
Block(2,4,1,SNOW_BLOCK:0)
Block(2,4,2,SNOW_BLOCK:0)
Block(2,4,3,AIR:0)
Block(3,0,-2,ICE:0)
Block(3,0,-1,ICE:0)
Block(3,0,0,ICE:0)
Block(3,0,1,ICE:0)
Block(3,0,2,ICE:0)
Block(3,0,3,ICE:0)
Block(3,1,-2,SNOW_BLOCK:0)
Block(3,1,-1,SNOW_BLOCK:0)
Block(3,1,1,AIR:0)
Block(3,1,3,SNOW_BLOCK:0)
Block(3,2,-2,SNOW_BLOCK:0)
Block(3,2,-1,SNOW_BLOCK:0)
Block(3,2,1,AIR:0)
Block(3,2,3,SNOW_BLOCK:0)
Block(3,3,-2,AIR:0)
Block(3,3,-1,SNOW_BLOCK:0)
Block(3,3,1,SNOW_BLOCK:0)
Block(3,3,3,AIR:0)
Block(3,4,-2,AIR:0)
Block(3,4,-1,AIR:0)
Block(3,4,0,AIR:0)
Block(3,4,1,AIR:0)
Block(3,4,2,AIR:0)
Block(3,4,3,AIR:0)

#######################################################################
# +-----------------------------------------------------------------+ #
# |                            BO3 checks                           | #
# +-----------------------------------------------------------------+ #
#######################################################################


#######################################################################
# +-----------------------------------------------------------------+ #
# |                             Branches                            | #
# +-----------------------------------------------------------------+ #
#######################################################################


#######################################################################
# +-----------------------------------------------------------------+ #
# |                             Entities                            | #
# +-----------------------------------------------------------------+ #
#######################################################################


#######################################################################
# +-----------------------------------------------------------------+ #
# |                            Particles                            | #
# +-----------------------------------------------------------------+ #
#######################################################################


#######################################################################
# +-----------------------------------------------------------------+ #
# |                             Spawners                            | #
# +-----------------------------------------------------------------+ #
#######################################################################


#######################################################################
# +-----------------------------------------------------------------+ #
# |                             ModData                             | #
# +-----------------------------------------------------------------+ #
#######################################################################

