
#######################################################################
# +-----------------------------------------------------------------+ #
# |                            BO4 object                           | #
# +-----------------------------------------------------------------+ #
#######################################################################

Author: NLBlackEagle

Description: No description given

SettingsMode: WriteWithoutComments


#######################################################################
# +-----------------------------------------------------------------+ #
# |                          Main settings                          | #
# +-----------------------------------------------------------------+ #
#######################################################################

FixedRotation: 

Frequency: 0

SpawnHeight: highestBlock

UseCenterForHighestBlock: true

##############################
# Height Limits for the BO4. #
##############################

MinHeight: 0

MaxHeight: 255

InheritBO3: 

InheritBO3Rotation: NORTH

OverrideChildSettings: true

OverrideParentHeight: false

CanOverride: false

BranchFrequency: 0

BranchFrequencyGroup: 

MustBeBelowOther: false

MustBeInside: 

CannotBeInside: 

ReplacesBO3: 

MustBeInsideWorldBorders: false

CanSpawnOnWater: true

SpawnOnWaterOnly: false

SpawnUnderWater: false

SpawnAtWaterLevel: false

HeightOffset: 0

RemoveAir: false

ReplaceAbove: 

ReplaceBelow: 

ReplaceWithBiomeBlocks: true

ReplaceWithSurfaceBlock: STONE, SAND, BIOMESOPLENTY:DRIED_SAND

ReplaceWithGroundBlock: STONE, SAND, BIOMESOPLENTY:DRIED_SAND

ReplaceWithStoneBlock: STONE, SAND, BIOMESOPLENTY:DRIED_SAND

SmoothRadius: 0

SmoothHeightOffset: 0

SmoothStartTop: false

SmoothStartWood: false

SmoothingSurfaceBlock: 

SmoothingGroundBlock: 

BO3Group: 

IsSpawnPoint: false

DoReplaceBlocks: false


#######################################################################
# +-----------------------------------------------------------------+ #
# |                              Blocks                             | #
# +-----------------------------------------------------------------+ #
#######################################################################

Block(-8,0,-1,biomesoplenty:dried_sand)
Block(-8,0,0,biomesoplenty:dried_sand)
Block(-8,0,1,biomesoplenty:dried_sand)
Block(-8,0,2,biomesoplenty:dried_sand)
Block(-8,0,3,biomesoplenty:dried_sand)
Block(-8,0,4,biomesoplenty:dried_sand)
Block(-8,0,5,biomesoplenty:dried_sand)
Block(-8,0,6,biomesoplenty:dried_sand)
Block(-8,0,7,biomesoplenty:dried_sand)
Block(-8,0,8,biomesoplenty:dried_sand)
Block(-8,1,-1,biomesoplenty:dried_sand)
Block(-8,1,0,biomesoplenty:dried_sand)
Block(-8,1,1,biomesoplenty:dried_sand)
Block(-8,1,2,biomesoplenty:dried_sand)
Block(-8,1,3,biomesoplenty:dried_sand)
Block(-8,1,4,biomesoplenty:dried_sand)
Block(-8,1,5,biomesoplenty:dried_sand)
Block(-8,1,6,biomesoplenty:dried_sand)
Block(-8,1,7,biomesoplenty:dried_sand)
Block(-8,1,8,biomesoplenty:dried_sand)
Block(-8,2,0,biomesoplenty:dried_sand)
Block(-8,2,1,biomesoplenty:dried_sand)
Block(-8,2,2,biomesoplenty:dried_sand)
Block(-8,2,3,biomesoplenty:dried_sand)
Block(-8,2,4,biomesoplenty:dried_sand)
Block(-8,2,5,biomesoplenty:dried_sand)
Block(-8,2,6,biomesoplenty:dried_sand)
Block(-8,2,7,biomesoplenty:dried_sand)
Block(-8,2,8,biomesoplenty:dried_sand)
Block(-8,3,2,biomesoplenty:dried_sand)
Block(-8,3,3,biomesoplenty:dried_sand)
Block(-8,3,4,biomesoplenty:dried_sand)
Block(-8,3,5,biomesoplenty:dried_sand)
Block(-8,3,6,biomesoplenty:dried_sand)
Block(-8,3,7,biomesoplenty:dried_sand)
Block(-8,3,8,biomesoplenty:dried_sand)
Block(-8,4,3,biomesoplenty:dried_sand)
Block(-8,4,4,biomesoplenty:dried_sand)
Block(-8,4,5,biomesoplenty:dried_sand)
Block(-8,4,6,biomesoplenty:dried_sand)
Block(-8,4,7,biomesoplenty:dried_sand)
Block(-8,4,8,biomesoplenty:dried_sand)
Block(-8,5,4,biomesoplenty:dried_sand)
Block(-8,5,5,biomesoplenty:dried_sand)
Block(-8,5,6,biomesoplenty:dried_sand)
Block(-8,5,7,biomesoplenty:dried_sand)
Block(-8,5,8,biomesoplenty:dried_sand)
Block(-8,6,5,biomesoplenty:dried_sand)
RandomBlock(-8,6,6,SAND:0,50,biomesoplenty:dried_sand,100)
Block(-8,6,7,biomesoplenty:dried_sand)
Block(-8,6,8,biomesoplenty:dried_sand)
RandomBlock(-8,7,7,SAND:0,50,biomesoplenty:dried_sand,100)
RandomBlock(-8,7,8,SAND:0,50,biomesoplenty:dried_sand,100)
Block(-7,0,-1,biomesoplenty:dried_sand)
Block(-7,0,0,biomesoplenty:dried_sand)
Block(-7,0,1,biomesoplenty:dried_sand)
Block(-7,0,2,biomesoplenty:dried_sand)
Block(-7,0,3,biomesoplenty:dried_sand)
Block(-7,0,4,biomesoplenty:dried_sand)
Block(-7,0,5,biomesoplenty:dried_sand)
Block(-7,0,6,biomesoplenty:dried_sand)
Block(-7,0,7,biomesoplenty:dried_sand)
Block(-7,0,8,biomesoplenty:dried_sand)
Block(-7,1,-1,biomesoplenty:dried_sand)
Block(-7,1,0,biomesoplenty:dried_sand)
Block(-7,1,1,biomesoplenty:dried_sand)
Block(-7,1,2,biomesoplenty:dried_sand)
Block(-7,1,3,biomesoplenty:dried_sand)
Block(-7,1,4,biomesoplenty:dried_sand)
Block(-7,1,5,biomesoplenty:dried_sand)
Block(-7,1,6,biomesoplenty:dried_sand)
Block(-7,1,7,biomesoplenty:dried_sand)
Block(-7,1,8,biomesoplenty:dried_sand)
Block(-7,2,1,biomesoplenty:dried_sand)
Block(-7,2,2,biomesoplenty:dried_sand)
Block(-7,2,3,biomesoplenty:dried_sand)
Block(-7,2,4,biomesoplenty:dried_sand)
Block(-7,2,5,biomesoplenty:dried_sand)
Block(-7,2,6,biomesoplenty:dried_sand)
Block(-7,2,7,biomesoplenty:dried_sand)
Block(-7,2,8,biomesoplenty:dried_sand)
Block(-7,3,2,biomesoplenty:dried_sand)
Block(-7,3,3,biomesoplenty:dried_sand)
Block(-7,3,4,biomesoplenty:dried_sand)
Block(-7,3,5,biomesoplenty:dried_sand)
Block(-7,3,6,biomesoplenty:dried_sand)
Block(-7,3,7,biomesoplenty:dried_sand)
Block(-7,3,8,biomesoplenty:dried_sand)
Block(-7,4,4,biomesoplenty:dried_sand)
Block(-7,4,5,biomesoplenty:dried_sand)
Block(-7,4,6,biomesoplenty:dried_sand)
Block(-7,4,7,biomesoplenty:dried_sand)
Block(-7,4,8,biomesoplenty:dried_sand)
Block(-7,5,5,biomesoplenty:dried_sand)
Block(-7,5,6,biomesoplenty:dried_sand)
Block(-7,5,7,biomesoplenty:dried_sand)
Block(-7,5,8,biomesoplenty:dried_sand)
Block(-7,6,6,biomesoplenty:dried_sand)
Block(-7,6,7,biomesoplenty:dried_sand)
Block(-7,6,8,biomesoplenty:dried_sand)
RandomBlock(-7,7,8,SAND:0,50,biomesoplenty:dried_sand,100)
Block(-6,0,1,biomesoplenty:dried_sand)
Block(-6,0,2,biomesoplenty:dried_sand)
Block(-6,0,3,biomesoplenty:dried_sand)
Block(-6,0,4,biomesoplenty:dried_sand)
Block(-6,0,5,biomesoplenty:dried_sand)
Block(-6,0,6,biomesoplenty:dried_sand)
Block(-6,0,7,biomesoplenty:dried_sand)
Block(-6,0,8,biomesoplenty:dried_sand)
Block(-6,1,1,biomesoplenty:dried_sand)
Block(-6,1,2,biomesoplenty:dried_sand)
Block(-6,1,3,biomesoplenty:dried_sand)
Block(-6,1,4,biomesoplenty:dried_sand)
Block(-6,1,5,biomesoplenty:dried_sand)
Block(-6,1,6,biomesoplenty:dried_sand)
Block(-6,1,7,biomesoplenty:dried_sand)
Block(-6,1,8,biomesoplenty:dried_sand)
Block(-6,2,2,biomesoplenty:dried_sand)
Block(-6,2,3,biomesoplenty:dried_sand)
Block(-6,2,4,biomesoplenty:dried_sand)
Block(-6,2,5,biomesoplenty:dried_sand)
Block(-6,2,6,biomesoplenty:dried_sand)
Block(-6,2,7,biomesoplenty:dried_sand)
Block(-6,2,8,biomesoplenty:dried_sand)
Block(-6,3,3,biomesoplenty:dried_sand)
Block(-6,3,4,biomesoplenty:dried_sand)
Block(-6,3,5,biomesoplenty:dried_sand)
Block(-6,3,6,biomesoplenty:dried_sand)
Block(-6,3,7,biomesoplenty:dried_sand)
Block(-6,3,8,biomesoplenty:dried_sand)
Block(-6,4,5,biomesoplenty:dried_sand)
Block(-6,4,6,biomesoplenty:dried_sand)
Block(-6,4,7,biomesoplenty:dried_sand)
Block(-6,4,8,biomesoplenty:dried_sand)
Block(-6,5,6,biomesoplenty:dried_sand)
Block(-6,5,7,biomesoplenty:dried_sand)
Block(-6,5,8,biomesoplenty:dried_sand)
Block(-6,6,7,biomesoplenty:dried_sand)
Block(-6,6,8,biomesoplenty:dried_sand)
Block(-5,0,2,biomesoplenty:dried_sand)
Block(-5,0,3,biomesoplenty:dried_sand)
Block(-5,0,4,biomesoplenty:dried_sand)
Block(-5,0,5,biomesoplenty:dried_sand)
Block(-5,0,6,biomesoplenty:dried_sand)
Block(-5,0,7,biomesoplenty:dried_sand)
Block(-5,0,8,biomesoplenty:dried_sand)
Block(-5,1,2,biomesoplenty:dried_sand)
Block(-5,1,3,biomesoplenty:dried_sand)
Block(-5,1,4,biomesoplenty:dried_sand)
Block(-5,1,5,biomesoplenty:dried_sand)
Block(-5,1,6,biomesoplenty:dried_sand)
Block(-5,1,7,biomesoplenty:dried_sand)
Block(-5,1,8,biomesoplenty:dried_sand)
Block(-5,2,3,biomesoplenty:dried_sand)
Block(-5,2,4,biomesoplenty:dried_sand)
Block(-5,2,5,biomesoplenty:dried_sand)
Block(-5,2,6,biomesoplenty:dried_sand)
Block(-5,2,7,biomesoplenty:dried_sand)
Block(-5,2,8,biomesoplenty:dried_sand)
Block(-5,3,5,biomesoplenty:dried_sand)
Block(-5,3,6,biomesoplenty:dried_sand)
Block(-5,3,7,biomesoplenty:dried_sand)
Block(-5,3,8,biomesoplenty:dried_sand)
Block(-5,4,5,biomesoplenty:dried_sand)
Block(-5,4,6,biomesoplenty:dried_sand)
Block(-5,4,7,biomesoplenty:dried_sand)
Block(-5,4,8,biomesoplenty:dried_sand)
Block(-5,5,7,biomesoplenty:dried_sand)
Block(-5,5,8,biomesoplenty:dried_sand)
Block(-4,0,4,biomesoplenty:dried_sand)
Block(-4,0,5,biomesoplenty:dried_sand)
Block(-4,0,6,biomesoplenty:dried_sand)
Block(-4,0,7,biomesoplenty:dried_sand)
Block(-4,0,8,biomesoplenty:dried_sand)
Block(-4,1,4,biomesoplenty:dried_sand)
Block(-4,1,5,biomesoplenty:dried_sand)
Block(-4,1,6,biomesoplenty:dried_sand)
Block(-4,1,7,biomesoplenty:dried_sand)
Block(-4,1,8,biomesoplenty:dried_sand)
Block(-4,2,5,biomesoplenty:dried_sand)
Block(-4,2,6,biomesoplenty:dried_sand)
Block(-4,2,7,biomesoplenty:dried_sand)
Block(-4,2,8,biomesoplenty:dried_sand)
Block(-4,3,5,biomesoplenty:dried_sand)
Block(-4,3,6,biomesoplenty:dried_sand)
Block(-4,3,7,biomesoplenty:dried_sand)
Block(-4,3,8,biomesoplenty:dried_sand)
Block(-4,4,7,biomesoplenty:dried_sand)
Block(-4,4,8,biomesoplenty:dried_sand)
Block(-4,5,8,biomesoplenty:dried_sand)
Block(-3,0,5,biomesoplenty:dried_sand)
Block(-3,0,6,biomesoplenty:dried_sand)
Block(-3,0,7,biomesoplenty:dried_sand)
Block(-3,0,8,biomesoplenty:dried_sand)
Block(-3,1,5,biomesoplenty:dried_sand)
Block(-3,1,6,biomesoplenty:dried_sand)
Block(-3,1,7,biomesoplenty:dried_sand)
Block(-3,1,8,biomesoplenty:dried_sand)
Block(-3,2,6,biomesoplenty:dried_sand)
Block(-3,2,7,biomesoplenty:dried_sand)
Block(-3,2,8,biomesoplenty:dried_sand)
Block(-3,3,6,biomesoplenty:dried_sand)
Block(-3,3,7,biomesoplenty:dried_sand)
Block(-3,3,8,biomesoplenty:dried_sand)
Block(-3,4,8,biomesoplenty:dried_sand)
Block(-2,0,5,biomesoplenty:dried_sand)
Block(-2,0,6,biomesoplenty:dried_sand)
Block(-2,0,7,biomesoplenty:dried_sand)
Block(-2,0,8,biomesoplenty:dried_sand)
Block(-2,1,5,biomesoplenty:dried_sand)
Block(-2,1,6,biomesoplenty:dried_sand)
Block(-2,1,7,biomesoplenty:dried_sand)
Block(-2,1,8,biomesoplenty:dried_sand)
Block(-2,2,7,biomesoplenty:dried_sand)
Block(-2,2,8,biomesoplenty:dried_sand)
Block(-2,3,7,biomesoplenty:dried_sand)
Block(-2,3,8,biomesoplenty:dried_sand)
Block(-1,0,7,biomesoplenty:dried_sand)
Block(-1,0,8,biomesoplenty:dried_sand)
Block(-1,1,7,biomesoplenty:dried_sand)
Block(-1,1,8,biomesoplenty:dried_sand)
Block(-1,2,8,biomesoplenty:dried_sand)
Block(0,0,8,biomesoplenty:dried_sand)
Block(0,1,8,biomesoplenty:dried_sand)

#######################################################################
# +-----------------------------------------------------------------+ #
# |                             Branches                            | #
# +-----------------------------------------------------------------+ #
#######################################################################

Branch(16,0,0,true,GorgonTempleC12R0,NORTH,100.0,0)

#######################################################################
# +-----------------------------------------------------------------+ #
# |                             Entities                            | #
# +-----------------------------------------------------------------+ #
#######################################################################


#######################################################################
# +-----------------------------------------------------------------+ #
# |                            Particles                            | #
# +-----------------------------------------------------------------+ #
#######################################################################


#######################################################################
# +-----------------------------------------------------------------+ #
# |                             Spawners                            | #
# +-----------------------------------------------------------------+ #
#######################################################################


#######################################################################
# +-----------------------------------------------------------------+ #
# |                             ModData                             | #
# +-----------------------------------------------------------------+ #
#######################################################################

