
#######################################################################
# +-----------------------------------------------------------------+ #
# |                            BO4 object                           | #
# +-----------------------------------------------------------------+ #
#######################################################################

Author: NLBlackEagle

Description: No description given

SettingsMode: WriteWithoutComments


#######################################################################
# +-----------------------------------------------------------------+ #
# |                          Main settings                          | #
# +-----------------------------------------------------------------+ #
#######################################################################

FixedRotation: 

Frequency: 0

SpawnHeight: highestBlock

UseCenterForHighestBlock: true

##############################
# Height Limits for the BO4. #
##############################

MinHeight: 0

MaxHeight: 255

InheritBO3: 

InheritBO3Rotation: NORTH

OverrideChildSettings: true

OverrideParentHeight: false

CanOverride: false

BranchFrequency: 0

BranchFrequencyGroup: 

MustBeBelowOther: false

MustBeInside: 

CannotBeInside: 

ReplacesBO3: 

MustBeInsideWorldBorders: false

CanSpawnOnWater: true

SpawnOnWaterOnly: false

SpawnUnderWater: false

SpawnAtWaterLevel: false

HeightOffset: 0

RemoveAir: false

ReplaceAbove: 

ReplaceBelow: 

ReplaceWithBiomeBlocks: true

ReplaceWithSurfaceBlock: STONE, SAND, BIOMESOPLENTY:DRIED_SAND

ReplaceWithGroundBlock: STONE, SAND, BIOMESOPLENTY:DRIED_SAND

ReplaceWithStoneBlock: STONE, SAND, BIOMESOPLENTY:DRIED_SAND

SmoothRadius: 0

SmoothHeightOffset: 0

SmoothStartTop: false

SmoothStartWood: false

SmoothingSurfaceBlock: 

SmoothingGroundBlock: 

BO3Group: 

IsSpawnPoint: false

DoReplaceBlocks: false


#######################################################################
# +-----------------------------------------------------------------+ #
# |                              Blocks                             | #
# +-----------------------------------------------------------------+ #
#######################################################################

Block(-8,0,-7,biomesoplenty:dried_sand)
Block(-8,0,-6,OBSIDIAN:0)
Block(-8,0,-5,OBSIDIAN:0)
Block(-8,0,-4,OBSIDIAN:0)
Block(-8,0,-3,OBSIDIAN:0)
Block(-8,0,-2,OBSIDIAN:0)
Block(-8,0,-1,OBSIDIAN:0)
Block(-8,0,0,OBSIDIAN:0)
Block(-8,0,1,OBSIDIAN:0)
Block(-8,0,2,OBSIDIAN:0)
Block(-8,0,3,OBSIDIAN:0)
Block(-8,0,4,OBSIDIAN:0)
Block(-8,0,5,OBSIDIAN:0)
Block(-8,0,6,OBSIDIAN:0)
Block(-8,0,7,OBSIDIAN:0)
Block(-8,0,8,OBSIDIAN:0)
Block(-8,1,-7,biomesoplenty:dried_sand)
Block(-8,1,-6,OBSIDIAN:0)
Block(-8,1,-5,OBSIDIAN:0)
Block(-8,1,-4,OBSIDIAN:0)
Block(-8,1,-3,OBSIDIAN:0)
Block(-8,1,-2,OBSIDIAN:0)
Block(-8,1,-1,OBSIDIAN:0)
Block(-8,1,0,OBSIDIAN:0)
Block(-8,1,1,OBSIDIAN:0)
Block(-8,1,2,OBSIDIAN:0)
Block(-8,1,3,OBSIDIAN:0)
Block(-8,1,4,OBSIDIAN:0)
Block(-8,1,5,OBSIDIAN:0)
Block(-8,1,6,OBSIDIAN:0)
Block(-8,1,7,OBSIDIAN:0)
Block(-8,1,8,OBSIDIAN:0)
Block(-8,2,-7,biomesoplenty:dried_sand)
Block(-8,2,-6,OBSIDIAN:0)
Block(-8,2,-5,OBSIDIAN:0)
Block(-8,2,-4,OBSIDIAN:0)
Block(-8,2,-3,OBSIDIAN:0)
Block(-8,2,-2,OBSIDIAN:0)
Block(-8,2,-1,OBSIDIAN:0)
Block(-8,2,0,OBSIDIAN:0)
Block(-8,2,1,OBSIDIAN:0)
Block(-8,2,2,OBSIDIAN:0)
Block(-8,2,3,OBSIDIAN:0)
Block(-8,2,4,OBSIDIAN:0)
Block(-8,2,5,OBSIDIAN:0)
Block(-8,2,6,OBSIDIAN:0)
Block(-8,2,7,OBSIDIAN:0)
Block(-8,2,8,OBSIDIAN:0)
Block(-8,3,-7,biomesoplenty:dried_sand)
Block(-8,3,-6,OBSIDIAN:0)
Block(-8,3,-5,OBSIDIAN:0)
Block(-8,3,-4,OBSIDIAN:0)
Block(-8,3,-3,OBSIDIAN:0)
Block(-8,3,-2,OBSIDIAN:0)
Block(-8,3,-1,OBSIDIAN:0)
Block(-8,3,0,OBSIDIAN:0)
Block(-8,3,1,OBSIDIAN:0)
Block(-8,3,2,OBSIDIAN:0)
Block(-8,3,3,OBSIDIAN:0)
Block(-8,3,4,OBSIDIAN:0)
Block(-8,3,5,OBSIDIAN:0)
Block(-8,3,6,OBSIDIAN:0)
Block(-8,3,7,OBSIDIAN:0)
Block(-8,3,8,OBSIDIAN:0)
Block(-8,4,-7,biomesoplenty:dried_sand)
Block(-8,4,-6,OBSIDIAN:0)
Block(-8,4,-5,OBSIDIAN:0)
Block(-8,4,-4,OBSIDIAN:0)
Block(-8,4,-3,OBSIDIAN:0)
Block(-8,4,-2,OBSIDIAN:0)
Block(-8,4,-1,OBSIDIAN:0)
Block(-8,4,0,OBSIDIAN:0)
Block(-8,4,1,OBSIDIAN:0)
Block(-8,4,2,OBSIDIAN:0)
Block(-8,4,3,OBSIDIAN:0)
Block(-8,4,4,OBSIDIAN:0)
Block(-8,4,5,OBSIDIAN:0)
Block(-8,4,6,OBSIDIAN:0)
Block(-8,4,7,OBSIDIAN:0)
Block(-8,4,8,OBSIDIAN:0)
Block(-8,5,-7,biomesoplenty:dried_sand)
Block(-8,5,-6,OBSIDIAN:0)
Block(-8,5,-5,OBSIDIAN:0)
Block(-8,5,-4,OBSIDIAN:0)
Block(-8,5,-3,OBSIDIAN:0)
Block(-8,5,-2,OBSIDIAN:0)
Block(-8,5,-1,OBSIDIAN:0)
Block(-8,5,0,OBSIDIAN:0)
Block(-8,5,1,OBSIDIAN:0)
Block(-8,5,2,OBSIDIAN:0)
Block(-8,5,3,OBSIDIAN:0)
Block(-8,5,4,OBSIDIAN:0)
Block(-8,5,5,OBSIDIAN:0)
Block(-8,5,6,OBSIDIAN:0)
Block(-8,5,7,OBSIDIAN:0)
Block(-8,5,8,OBSIDIAN:0)
Block(-8,6,-7,biomesoplenty:dried_sand)
Block(-8,6,-6,OBSIDIAN:0)
Block(-8,6,-5,OBSIDIAN:0)
Block(-8,6,-4,OBSIDIAN:0)
Block(-8,6,-3,OBSIDIAN:0)
Block(-8,6,-2,OBSIDIAN:0)
Block(-8,6,-1,OBSIDIAN:0)
Block(-8,6,0,OBSIDIAN:0)
Block(-8,6,1,OBSIDIAN:0)
Block(-8,6,2,OBSIDIAN:0)
Block(-8,6,3,OBSIDIAN:0)
Block(-8,6,4,OBSIDIAN:0)
Block(-8,6,5,OBSIDIAN:0)
Block(-8,6,6,OBSIDIAN:0)
Block(-8,6,7,OBSIDIAN:0)
Block(-8,6,8,OBSIDIAN:0)
Block(-8,7,-7,biomesoplenty:dried_sand)
Block(-8,7,-6,OBSIDIAN:0)
Block(-8,7,-5,OBSIDIAN:0)
Block(-8,7,-4,OBSIDIAN:0)
Block(-8,7,-3,OBSIDIAN:0)
Block(-8,7,-2,OBSIDIAN:0)
Block(-8,7,-1,OBSIDIAN:0)
Block(-8,7,0,OBSIDIAN:0)
Block(-8,7,1,OBSIDIAN:0)
Block(-8,7,2,OBSIDIAN:0)
Block(-8,7,3,OBSIDIAN:0)
Block(-8,7,4,OBSIDIAN:0)
Block(-8,7,5,OBSIDIAN:0)
Block(-8,7,6,OBSIDIAN:0)
Block(-8,7,7,OBSIDIAN:0)
Block(-8,7,8,OBSIDIAN:0)
Block(-8,8,-7,biomesoplenty:dried_sand)
Block(-8,8,-6,OBSIDIAN:0)
Block(-8,8,-5,OBSIDIAN:0)
Block(-8,8,-4,OBSIDIAN:0)
Block(-8,8,-3,OBSIDIAN:0)
Block(-8,8,-2,OBSIDIAN:0)
Block(-8,8,-1,OBSIDIAN:0)
Block(-8,8,0,OBSIDIAN:0)
Block(-8,8,1,OBSIDIAN:0)
Block(-8,8,2,OBSIDIAN:0)
Block(-8,8,3,OBSIDIAN:0)
Block(-8,8,4,OBSIDIAN:0)
Block(-8,8,5,OBSIDIAN:0)
Block(-8,8,6,OBSIDIAN:0)
Block(-8,8,7,OBSIDIAN:0)
Block(-8,8,8,OBSIDIAN:0)
Block(-8,9,-7,biomesoplenty:dried_sand)
Block(-8,9,-6,OBSIDIAN:0)
Block(-8,9,-5,OBSIDIAN:0)
Block(-8,9,-4,OBSIDIAN:0)
Block(-8,9,-3,OBSIDIAN:0)
Block(-8,9,-2,OBSIDIAN:0)
Block(-8,9,-1,OBSIDIAN:0)
Block(-8,9,0,OBSIDIAN:0)
Block(-8,9,1,OBSIDIAN:0)
Block(-8,9,2,OBSIDIAN:0)
Block(-8,9,3,OBSIDIAN:0)
Block(-8,9,4,OBSIDIAN:0)
Block(-8,9,5,OBSIDIAN:0)
Block(-8,9,6,OBSIDIAN:0)
Block(-8,9,7,OBSIDIAN:0)
Block(-8,9,8,OBSIDIAN:0)
Block(-8,10,-7,biomesoplenty:dried_sand)
Block(-8,10,-6,OBSIDIAN:0)
Block(-8,10,-5,OBSIDIAN:0)
Block(-8,10,-4,OBSIDIAN:0)
Block(-8,10,-3,OBSIDIAN:0)
Block(-8,10,-2,OBSIDIAN:0)
Block(-8,10,-1,OBSIDIAN:0)
Block(-8,10,0,OBSIDIAN:0)
Block(-8,10,1,OBSIDIAN:0)
Block(-8,10,2,OBSIDIAN:0)
Block(-8,10,3,OBSIDIAN:0)
Block(-8,10,4,OBSIDIAN:0)
Block(-8,10,5,OBSIDIAN:0)
Block(-8,10,6,OBSIDIAN:0)
Block(-8,10,7,OBSIDIAN:0)
Block(-8,10,8,OBSIDIAN:0)
Block(-8,11,-7,biomesoplenty:dried_sand)
Block(-8,11,-6,OBSIDIAN:0)
Block(-8,11,-5,OBSIDIAN:0)
Block(-8,11,-4,OBSIDIAN:0)
Block(-8,11,-3,OBSIDIAN:0)
Block(-8,11,-2,OBSIDIAN:0)
Block(-8,11,-1,OBSIDIAN:0)
Block(-8,11,0,OBSIDIAN:0)
Block(-8,11,1,OBSIDIAN:0)
Block(-8,11,2,OBSIDIAN:0)
Block(-8,11,3,OBSIDIAN:0)
Block(-8,11,4,OBSIDIAN:0)
Block(-8,11,5,OBSIDIAN:0)
Block(-8,11,6,OBSIDIAN:0)
Block(-8,11,7,OBSIDIAN:0)
Block(-8,11,8,OBSIDIAN:0)
Block(-8,12,-7,biomesoplenty:dried_sand)
Block(-8,12,-6,OBSIDIAN:0)
Block(-8,12,-5,OBSIDIAN:0)
Block(-8,12,-4,OBSIDIAN:0)
Block(-8,12,-3,OBSIDIAN:0)
Block(-8,12,-2,OBSIDIAN:0)
Block(-8,12,-1,OBSIDIAN:0)
Block(-8,12,0,OBSIDIAN:0)
Block(-8,12,1,OBSIDIAN:0)
Block(-8,12,2,OBSIDIAN:0)
Block(-8,12,3,OBSIDIAN:0)
Block(-8,12,4,OBSIDIAN:0)
Block(-8,12,5,OBSIDIAN:0)
Block(-8,12,6,OBSIDIAN:0)
Block(-8,12,7,OBSIDIAN:0)
Block(-8,12,8,OBSIDIAN:0)
Block(-8,13,-7,biomesoplenty:dried_sand)
Block(-8,13,-6,OBSIDIAN:0)
Block(-8,13,-5,OBSIDIAN:0)
Block(-8,13,-4,OBSIDIAN:0)
Block(-8,13,-3,OBSIDIAN:0)
Block(-8,13,-2,OBSIDIAN:0)
Block(-8,13,-1,OBSIDIAN:0)
Block(-8,13,0,OBSIDIAN:0)
Block(-8,13,1,OBSIDIAN:0)
Block(-8,13,2,OBSIDIAN:0)
Block(-8,13,3,OBSIDIAN:0)
Block(-8,13,4,OBSIDIAN:0)
Block(-8,13,5,OBSIDIAN:0)
Block(-8,13,6,OBSIDIAN:0)
Block(-8,13,7,OBSIDIAN:0)
Block(-8,13,8,OBSIDIAN:0)
Block(-8,14,-7,biomesoplenty:dried_sand)
Block(-8,14,-6,OBSIDIAN:0)
Block(-8,14,-5,OBSIDIAN:0)
Block(-8,14,-4,OBSIDIAN:0)
Block(-8,14,-3,OBSIDIAN:0)
Block(-8,14,-2,OBSIDIAN:0)
Block(-8,14,-1,OBSIDIAN:0)
Block(-8,14,0,OBSIDIAN:0)
Block(-8,14,1,OBSIDIAN:0)
Block(-8,14,2,OBSIDIAN:0)
Block(-8,14,3,OBSIDIAN:0)
Block(-8,14,4,OBSIDIAN:0)
Block(-8,14,5,OBSIDIAN:0)
Block(-8,14,6,OBSIDIAN:0)
Block(-8,14,7,OBSIDIAN:0)
Block(-8,14,8,OBSIDIAN:0)
Block(-8,15,-7,biomesoplenty:dried_sand)
Block(-8,15,-6,OBSIDIAN:0)
Block(-8,15,-5,OBSIDIAN:0)
Block(-8,15,-4,OBSIDIAN:0)
Block(-8,15,-3,OBSIDIAN:0)
Block(-8,15,-2,OBSIDIAN:0)
Block(-8,15,-1,OBSIDIAN:0)
Block(-8,15,0,OBSIDIAN:0)
Block(-8,15,1,OBSIDIAN:0)
Block(-8,15,2,OBSIDIAN:0)
Block(-8,15,3,OBSIDIAN:0)
Block(-8,15,4,OBSIDIAN:0)
Block(-8,15,5,OBSIDIAN:0)
Block(-8,15,6,OBSIDIAN:0)
Block(-8,15,7,OBSIDIAN:0)
Block(-8,15,8,OBSIDIAN:0)
Block(-8,16,-7,biomesoplenty:dried_sand)
Block(-8,16,-6,OBSIDIAN:0)
Block(-8,16,-5,OBSIDIAN:0)
Block(-8,16,-4,OBSIDIAN:0)
Block(-8,16,-3,OBSIDIAN:0)
Block(-8,16,-2,OBSIDIAN:0)
Block(-8,16,-1,OBSIDIAN:0)
Block(-8,16,0,OBSIDIAN:0)
Block(-8,16,1,OBSIDIAN:0)
Block(-8,16,2,OBSIDIAN:0)
Block(-8,16,3,OBSIDIAN:0)
Block(-8,16,4,OBSIDIAN:0)
Block(-8,16,5,OBSIDIAN:0)
Block(-8,16,6,OBSIDIAN:0)
Block(-8,16,7,OBSIDIAN:0)
Block(-8,16,8,OBSIDIAN:0)
Block(-8,17,-7,biomesoplenty:dried_sand)
Block(-8,17,-6,OBSIDIAN:0)
Block(-8,17,-5,OBSIDIAN:0)
Block(-8,17,-4,OBSIDIAN:0)
Block(-8,17,-3,OBSIDIAN:0)
Block(-8,17,-2,OBSIDIAN:0)
Block(-8,17,-1,OBSIDIAN:0)
Block(-8,17,0,OBSIDIAN:0)
Block(-8,17,1,OBSIDIAN:0)
Block(-8,17,2,OBSIDIAN:0)
Block(-8,17,3,OBSIDIAN:0)
Block(-8,17,4,OBSIDIAN:0)
Block(-8,17,5,OBSIDIAN:0)
Block(-8,17,6,OBSIDIAN:0)
Block(-8,17,7,OBSIDIAN:0)
Block(-8,17,8,OBSIDIAN:0)
Block(-8,18,-7,biomesoplenty:dried_sand)
Block(-8,18,-6,OBSIDIAN:0)
Block(-8,18,-5,OBSIDIAN:0)
Block(-8,18,-4,OBSIDIAN:0)
Block(-8,18,-3,OBSIDIAN:0)
Block(-8,18,-2,OBSIDIAN:0)
Block(-8,18,-1,OBSIDIAN:0)
Block(-8,18,0,OBSIDIAN:0)
Block(-8,18,1,OBSIDIAN:0)
Block(-8,18,2,OBSIDIAN:0)
Block(-8,18,3,OBSIDIAN:0)
Block(-8,18,4,OBSIDIAN:0)
Block(-8,18,5,OBSIDIAN:0)
Block(-8,18,6,OBSIDIAN:0)
Block(-8,18,7,OBSIDIAN:0)
Block(-8,18,8,OBSIDIAN:0)
Block(-8,19,-7,biomesoplenty:dried_sand)
Block(-8,19,-6,OBSIDIAN:0)
Block(-8,19,-5,OBSIDIAN:0)
Block(-8,19,-4,OBSIDIAN:0)
Block(-8,19,-3,OBSIDIAN:0)
Block(-8,19,-2,OBSIDIAN:0)
Block(-8,19,-1,OBSIDIAN:0)
Block(-8,19,0,OBSIDIAN:0)
Block(-8,19,1,OBSIDIAN:0)
Block(-8,19,2,OBSIDIAN:0)
Block(-8,19,3,OBSIDIAN:0)
Block(-8,19,4,OBSIDIAN:0)
Block(-8,19,5,OBSIDIAN:0)
Block(-8,19,6,OBSIDIAN:0)
Block(-8,19,7,OBSIDIAN:0)
Block(-8,19,8,OBSIDIAN:0)
Block(-8,20,-7,biomesoplenty:dried_sand)
Block(-8,20,-6,OBSIDIAN:0)
Block(-8,20,-5,OBSIDIAN:0)
Block(-8,20,-4,OBSIDIAN:0)
Block(-8,20,-3,OBSIDIAN:0)
Block(-8,20,-2,OBSIDIAN:0)
Block(-8,20,-1,OBSIDIAN:0)
Block(-8,20,0,OBSIDIAN:0)
Block(-8,20,1,OBSIDIAN:0)
Block(-8,20,2,OBSIDIAN:0)
Block(-8,20,3,OBSIDIAN:0)
Block(-8,20,4,OBSIDIAN:0)
Block(-8,20,5,OBSIDIAN:0)
Block(-8,20,6,OBSIDIAN:0)
Block(-8,20,7,OBSIDIAN:0)
Block(-8,20,8,OBSIDIAN:0)
Block(-8,21,-7,biomesoplenty:dried_sand)
Block(-8,21,-6,OBSIDIAN:0)
Block(-8,21,-5,OBSIDIAN:0)
Block(-8,21,-4,OBSIDIAN:0)
Block(-8,21,-3,OBSIDIAN:0)
Block(-8,21,-2,OBSIDIAN:0)
Block(-8,21,-1,OBSIDIAN:0)
Block(-8,21,0,OBSIDIAN:0)
Block(-8,21,1,OBSIDIAN:0)
Block(-8,21,2,OBSIDIAN:0)
Block(-8,21,3,OBSIDIAN:0)
Block(-8,21,4,OBSIDIAN:0)
Block(-8,21,5,OBSIDIAN:0)
Block(-8,21,6,OBSIDIAN:0)
Block(-8,21,7,OBSIDIAN:0)
Block(-8,21,8,OBSIDIAN:0)
Block(-8,22,-7,biomesoplenty:dried_sand)
Block(-8,22,-6,OBSIDIAN:0)
Block(-8,22,-5,OBSIDIAN:0)
Block(-8,22,-4,OBSIDIAN:0)
Block(-8,22,-3,OBSIDIAN:0)
Block(-8,22,-2,OBSIDIAN:0)
Block(-8,22,-1,OBSIDIAN:0)
Block(-8,22,0,OBSIDIAN:0)
Block(-8,22,1,OBSIDIAN:0)
Block(-8,22,2,OBSIDIAN:0)
Block(-8,22,3,OBSIDIAN:0)
Block(-8,22,4,OBSIDIAN:0)
Block(-8,22,5,OBSIDIAN:0)
Block(-8,22,6,OBSIDIAN:0)
Block(-8,22,7,OBSIDIAN:0)
Block(-8,22,8,OBSIDIAN:0)
Block(-8,23,-7,biomesoplenty:dried_sand)
Block(-8,23,-6,OBSIDIAN:0)
Block(-8,23,-5,OBSIDIAN:0)
Block(-8,23,-4,OBSIDIAN:0)
Block(-8,23,-3,OBSIDIAN:0)
Block(-8,23,-2,OBSIDIAN:0)
Block(-8,23,-1,OBSIDIAN:0)
Block(-8,23,0,OBSIDIAN:0)
Block(-8,23,1,OBSIDIAN:0)
Block(-8,23,2,OBSIDIAN:0)
Block(-8,23,3,OBSIDIAN:0)
Block(-8,23,4,OBSIDIAN:0)
Block(-8,23,5,OBSIDIAN:0)
Block(-8,23,6,OBSIDIAN:0)
Block(-8,23,7,OBSIDIAN:0)
Block(-8,23,8,OBSIDIAN:0)
Block(-8,24,-7,biomesoplenty:dried_sand)
Block(-8,24,-6,OBSIDIAN:0)
Block(-8,24,-5,OBSIDIAN:0)
Block(-8,24,-4,OBSIDIAN:0)
Block(-8,24,-3,OBSIDIAN:0)
Block(-8,24,-2,OBSIDIAN:0)
Block(-8,24,-1,OBSIDIAN:0)
Block(-8,24,0,OBSIDIAN:0)
Block(-8,24,1,OBSIDIAN:0)
Block(-8,24,2,OBSIDIAN:0)
Block(-8,24,3,OBSIDIAN:0)
Block(-8,24,4,OBSIDIAN:0)
Block(-8,24,5,OBSIDIAN:0)
Block(-8,24,6,OBSIDIAN:0)
Block(-8,24,7,OBSIDIAN:0)
Block(-8,24,8,OBSIDIAN:0)
Block(-8,25,-7,biomesoplenty:dried_sand)
Block(-8,25,-6,OBSIDIAN:0)
Block(-8,25,-5,OBSIDIAN:0)
Block(-8,25,-4,OBSIDIAN:0)
Block(-8,25,-3,OBSIDIAN:0)
Block(-8,25,-2,OBSIDIAN:0)
Block(-8,25,-1,OBSIDIAN:0)
Block(-8,25,0,OBSIDIAN:0)
Block(-8,25,1,OBSIDIAN:0)
Block(-8,25,2,OBSIDIAN:0)
Block(-8,25,3,OBSIDIAN:0)
Block(-8,25,4,OBSIDIAN:0)
Block(-8,25,5,OBSIDIAN:0)
Block(-8,25,6,OBSIDIAN:0)
Block(-8,25,7,OBSIDIAN:0)
Block(-8,25,8,OBSIDIAN:0)
Block(-8,26,-7,biomesoplenty:dried_sand)
Block(-8,26,-6,OBSIDIAN:0)
Block(-8,26,-5,OBSIDIAN:0)
Block(-8,26,-4,OBSIDIAN:0)
Block(-8,26,-3,OBSIDIAN:0)
Block(-8,26,-2,OBSIDIAN:0)
Block(-8,26,-1,OBSIDIAN:0)
Block(-8,26,0,OBSIDIAN:0)
Block(-8,26,1,OBSIDIAN:0)
Block(-8,26,2,OBSIDIAN:0)
Block(-8,26,3,OBSIDIAN:0)
Block(-8,26,4,OBSIDIAN:0)
Block(-8,26,5,OBSIDIAN:0)
Block(-8,26,6,OBSIDIAN:0)
Block(-8,26,7,OBSIDIAN:0)
Block(-8,26,8,OBSIDIAN:0)
Block(-8,27,-7,biomesoplenty:dried_sand)
Block(-8,27,-6,OBSIDIAN:0)
Block(-8,27,-5,OBSIDIAN:0)
Block(-8,27,-4,OBSIDIAN:0)
Block(-8,27,-3,OBSIDIAN:0)
Block(-8,27,-2,OBSIDIAN:0)
Block(-8,27,-1,OBSIDIAN:0)
Block(-8,27,0,OBSIDIAN:0)
Block(-8,27,1,OBSIDIAN:0)
Block(-8,27,2,OBSIDIAN:0)
Block(-8,27,3,OBSIDIAN:0)
Block(-8,27,4,OBSIDIAN:0)
Block(-8,27,5,OBSIDIAN:0)
Block(-8,27,6,OBSIDIAN:0)
Block(-8,27,7,OBSIDIAN:0)
Block(-8,27,8,OBSIDIAN:0)
Block(-8,28,-7,biomesoplenty:dried_sand)
Block(-8,28,-6,OBSIDIAN:0)
Block(-8,28,-5,OBSIDIAN:0)
Block(-8,28,-4,OBSIDIAN:0)
Block(-8,28,-3,OBSIDIAN:0)
Block(-8,28,-2,OBSIDIAN:0)
Block(-8,28,-1,OBSIDIAN:0)
Block(-8,28,0,OBSIDIAN:0)
Block(-8,28,1,OBSIDIAN:0)
Block(-8,28,2,OBSIDIAN:0)
Block(-8,28,3,OBSIDIAN:0)
Block(-8,28,4,OBSIDIAN:0)
Block(-8,28,5,OBSIDIAN:0)
Block(-8,28,6,OBSIDIAN:0)
Block(-8,28,7,OBSIDIAN:0)
Block(-8,28,8,OBSIDIAN:0)
Block(-8,29,-7,biomesoplenty:dried_sand)
Block(-8,29,-6,OBSIDIAN:0)
Block(-8,29,-5,OBSIDIAN:0)
Block(-8,29,-4,OBSIDIAN:0)
Block(-8,29,-3,OBSIDIAN:0)
Block(-8,29,-2,OBSIDIAN:0)
Block(-8,29,-1,OBSIDIAN:0)
Block(-8,29,0,OBSIDIAN:0)
Block(-8,29,1,OBSIDIAN:0)
Block(-8,29,2,OBSIDIAN:0)
Block(-8,29,3,OBSIDIAN:0)
Block(-8,29,4,OBSIDIAN:0)
Block(-8,29,5,OBSIDIAN:0)
Block(-8,29,6,OBSIDIAN:0)
Block(-8,29,7,OBSIDIAN:0)
Block(-8,29,8,OBSIDIAN:0)
Block(-8,30,-7,biomesoplenty:dried_sand)
Block(-8,30,-6,OBSIDIAN:0)
Block(-8,30,-5,OBSIDIAN:0)
Block(-8,30,-4,OBSIDIAN:0)
Block(-8,30,-3,OBSIDIAN:0)
Block(-8,30,-2,OBSIDIAN:0)
Block(-8,30,-1,OBSIDIAN:0)
Block(-8,30,0,OBSIDIAN:0)
Block(-8,30,1,OBSIDIAN:0)
Block(-8,30,2,OBSIDIAN:0)
Block(-8,30,3,OBSIDIAN:0)
Block(-8,30,4,OBSIDIAN:0)
Block(-8,30,5,OBSIDIAN:0)
Block(-8,30,6,OBSIDIAN:0)
Block(-8,30,7,OBSIDIAN:0)
Block(-8,30,8,OBSIDIAN:0)
Block(-8,31,-7,biomesoplenty:dried_sand)
Block(-8,31,-6,OBSIDIAN:0)
Block(-8,31,-5,OBSIDIAN:0)
Block(-8,31,-4,OBSIDIAN:0)
Block(-8,31,-3,OBSIDIAN:0)
Block(-8,31,-2,OBSIDIAN:0)
Block(-8,31,-1,OBSIDIAN:0)
Block(-8,31,0,OBSIDIAN:0)
Block(-8,31,1,OBSIDIAN:0)
Block(-8,31,2,OBSIDIAN:0)
Block(-8,31,3,OBSIDIAN:0)
Block(-8,31,4,OBSIDIAN:0)
Block(-8,31,5,OBSIDIAN:0)
Block(-8,31,6,OBSIDIAN:0)
Block(-8,31,7,OBSIDIAN:0)
Block(-8,31,8,OBSIDIAN:0)
Block(-8,32,-7,biomesoplenty:dried_sand)
Block(-8,32,-6,OBSIDIAN:0)
Block(-8,32,-5,OBSIDIAN:0)
Block(-8,32,-4,OBSIDIAN:0)
Block(-8,32,-3,OBSIDIAN:0)
Block(-8,32,-2,OBSIDIAN:0)
Block(-8,32,-1,OBSIDIAN:0)
Block(-8,32,0,OBSIDIAN:0)
Block(-8,32,1,OBSIDIAN:0)
Block(-8,32,2,OBSIDIAN:0)
Block(-8,32,3,OBSIDIAN:0)
Block(-8,32,4,OBSIDIAN:0)
Block(-8,32,5,OBSIDIAN:0)
Block(-8,32,6,OBSIDIAN:0)
Block(-8,32,7,OBSIDIAN:0)
Block(-8,32,8,OBSIDIAN:0)
Block(-8,33,-7,biomesoplenty:dried_sand)
Block(-8,33,-6,OBSIDIAN:0)
Block(-8,33,-5,OBSIDIAN:0)
Block(-8,33,-4,OBSIDIAN:0)
Block(-8,33,-3,OBSIDIAN:0)
Block(-8,33,-2,OBSIDIAN:0)
Block(-8,33,-1,OBSIDIAN:0)
Block(-8,33,0,OBSIDIAN:0)
Block(-8,33,1,OBSIDIAN:0)
Block(-8,33,2,OBSIDIAN:0)
Block(-8,33,3,OBSIDIAN:0)
Block(-8,33,4,OBSIDIAN:0)
Block(-8,33,5,OBSIDIAN:0)
Block(-8,33,6,OBSIDIAN:0)
Block(-8,33,7,OBSIDIAN:0)
Block(-8,33,8,OBSIDIAN:0)
Block(-8,34,-7,biomesoplenty:dried_sand)
Block(-8,34,-6,OBSIDIAN:0)
Block(-8,34,-5,OBSIDIAN:0)
Block(-8,34,-4,OBSIDIAN:0)
Block(-8,34,-3,OBSIDIAN:0)
Block(-8,34,-2,OBSIDIAN:0)
Block(-8,34,-1,OBSIDIAN:0)
Block(-8,34,0,OBSIDIAN:0)
Block(-8,34,1,OBSIDIAN:0)
Block(-8,34,2,OBSIDIAN:0)
Block(-8,34,3,OBSIDIAN:0)
Block(-8,34,4,OBSIDIAN:0)
Block(-8,34,5,OBSIDIAN:0)
Block(-8,34,6,OBSIDIAN:0)
Block(-8,34,7,OBSIDIAN:0)
Block(-8,34,8,OBSIDIAN:0)
Block(-8,35,-7,biomesoplenty:dried_sand)
Block(-8,35,-6,OBSIDIAN:0)
Block(-8,35,-5,OBSIDIAN:0)
Block(-8,35,-4,OBSIDIAN:0)
Block(-8,35,-3,OBSIDIAN:0)
Block(-8,35,-2,OBSIDIAN:0)
Block(-8,35,-1,OBSIDIAN:0)
Block(-8,35,0,OBSIDIAN:0)
Block(-8,35,1,OBSIDIAN:0)
Block(-8,35,2,OBSIDIAN:0)
Block(-8,35,3,OBSIDIAN:0)
Block(-8,35,4,OBSIDIAN:0)
Block(-8,35,5,OBSIDIAN:0)
Block(-8,35,6,OBSIDIAN:0)
Block(-8,35,7,OBSIDIAN:0)
Block(-8,35,8,OBSIDIAN:0)
Block(-8,36,-7,biomesoplenty:dried_sand)
Block(-8,36,-6,OBSIDIAN:0)
Block(-8,36,-5,OBSIDIAN:0)
Block(-8,36,-4,OBSIDIAN:0)
Block(-8,36,-3,OBSIDIAN:0)
Block(-8,36,-2,OBSIDIAN:0)
Block(-8,36,-1,OBSIDIAN:0)
Block(-8,36,0,OBSIDIAN:0)
Block(-8,36,1,OBSIDIAN:0)
Block(-8,36,2,OBSIDIAN:0)
Block(-8,36,3,OBSIDIAN:0)
Block(-8,36,4,OBSIDIAN:0)
Block(-8,36,5,OBSIDIAN:0)
Block(-8,36,6,OBSIDIAN:0)
Block(-8,36,7,OBSIDIAN:0)
Block(-8,36,8,OBSIDIAN:0)
Block(-8,37,-7,biomesoplenty:dried_sand)
Block(-8,37,-6,OBSIDIAN:0)
Block(-8,37,-5,OBSIDIAN:0)
Block(-8,37,-4,OBSIDIAN:0)
Block(-8,37,-3,OBSIDIAN:0)
Block(-8,37,-2,OBSIDIAN:0)
Block(-8,37,-1,OBSIDIAN:0)
Block(-8,37,0,OBSIDIAN:0)
Block(-8,37,1,OBSIDIAN:0)
Block(-8,37,2,OBSIDIAN:0)
Block(-8,37,3,OBSIDIAN:0)
Block(-8,37,4,OBSIDIAN:0)
Block(-8,37,5,OBSIDIAN:0)
Block(-8,37,6,OBSIDIAN:0)
Block(-8,37,7,OBSIDIAN:0)
Block(-8,37,8,OBSIDIAN:0)
Block(-8,38,-7,biomesoplenty:dried_sand)
Block(-8,38,-6,OBSIDIAN:0)
Block(-8,38,-5,OBSIDIAN:0)
Block(-8,38,-4,OBSIDIAN:0)
Block(-8,38,-3,OBSIDIAN:0)
Block(-8,38,-2,OBSIDIAN:0)
Block(-8,38,-1,OBSIDIAN:0)
Block(-8,38,0,OBSIDIAN:0)
Block(-8,38,1,OBSIDIAN:0)
Block(-8,38,2,OBSIDIAN:0)
Block(-8,38,3,OBSIDIAN:0)
Block(-8,38,4,OBSIDIAN:0)
Block(-8,38,5,OBSIDIAN:0)
Block(-8,38,6,OBSIDIAN:0)
Block(-8,38,7,OBSIDIAN:0)
Block(-8,38,8,OBSIDIAN:0)
Block(-8,39,-7,biomesoplenty:dried_sand)
Block(-8,39,-6,OBSIDIAN:0)
Block(-8,39,-5,OBSIDIAN:0)
Block(-8,39,-4,OBSIDIAN:0)
Block(-8,39,-3,OBSIDIAN:0)
Block(-8,39,-2,OBSIDIAN:0)
Block(-8,39,-1,OBSIDIAN:0)
Block(-8,39,0,OBSIDIAN:0)
Block(-8,39,1,OBSIDIAN:0)
Block(-8,39,2,OBSIDIAN:0)
Block(-8,39,3,OBSIDIAN:0)
Block(-8,39,4,OBSIDIAN:0)
Block(-8,39,5,OBSIDIAN:0)
Block(-8,39,6,OBSIDIAN:0)
Block(-8,39,7,OBSIDIAN:0)
Block(-8,39,8,OBSIDIAN:0)
Block(-8,40,-7,biomesoplenty:dried_sand)
Block(-8,40,-6,OBSIDIAN:0)
Block(-8,40,-5,OBSIDIAN:0)
Block(-8,40,-4,OBSIDIAN:0)
Block(-8,40,-3,OBSIDIAN:0)
Block(-8,40,-2,OBSIDIAN:0)
Block(-8,40,-1,OBSIDIAN:0)
Block(-8,40,0,OBSIDIAN:0)
Block(-8,40,1,OBSIDIAN:0)
Block(-8,40,2,OBSIDIAN:0)
Block(-8,40,3,OBSIDIAN:0)
Block(-8,40,4,OBSIDIAN:0)
Block(-8,40,5,OBSIDIAN:0)
Block(-8,40,6,OBSIDIAN:0)
Block(-8,40,7,OBSIDIAN:0)
Block(-8,40,8,OBSIDIAN:0)
Block(-8,41,-7,biomesoplenty:dried_sand)
Block(-8,41,-6,OBSIDIAN:0)
Block(-8,41,-5,OBSIDIAN:0)
Block(-8,41,-4,OBSIDIAN:0)
Block(-8,41,-3,OBSIDIAN:0)
Block(-8,41,-2,OBSIDIAN:0)
Block(-8,41,-1,OBSIDIAN:0)
Block(-8,41,0,OBSIDIAN:0)
Block(-8,41,1,OBSIDIAN:0)
Block(-8,41,2,OBSIDIAN:0)
Block(-8,41,3,OBSIDIAN:0)
Block(-8,41,4,OBSIDIAN:0)
Block(-8,41,5,OBSIDIAN:0)
Block(-8,41,6,OBSIDIAN:0)
Block(-8,41,7,OBSIDIAN:0)
Block(-8,41,8,OBSIDIAN:0)
Block(-8,42,-7,biomesoplenty:dried_sand)
Block(-8,42,-6,OBSIDIAN:0)
Block(-8,42,-5,OBSIDIAN:0)
Block(-8,42,-4,OBSIDIAN:0)
Block(-8,42,-3,OBSIDIAN:0)
Block(-8,42,-2,OBSIDIAN:0)
Block(-8,42,-1,OBSIDIAN:0)
Block(-8,42,0,OBSIDIAN:0)
Block(-8,42,1,OBSIDIAN:0)
Block(-8,42,2,OBSIDIAN:0)
Block(-8,42,3,OBSIDIAN:0)
Block(-8,42,4,OBSIDIAN:0)
Block(-8,42,5,OBSIDIAN:0)
Block(-8,42,6,OBSIDIAN:0)
Block(-8,42,7,OBSIDIAN:0)
Block(-8,42,8,OBSIDIAN:0)
Block(-8,43,-7,biomesoplenty:dried_sand)
Block(-8,43,-6,OBSIDIAN:0)
Block(-8,43,-5,OBSIDIAN:0)
Block(-8,43,-4,OBSIDIAN:0)
Block(-8,43,-3,OBSIDIAN:0)
Block(-8,43,-2,OBSIDIAN:0)
Block(-8,43,-1,OBSIDIAN:0)
Block(-8,43,0,OBSIDIAN:0)
Block(-8,43,1,OBSIDIAN:0)
Block(-8,43,2,OBSIDIAN:0)
Block(-8,43,3,OBSIDIAN:0)
Block(-8,43,4,OBSIDIAN:0)
Block(-8,43,5,OBSIDIAN:0)
Block(-8,43,6,OBSIDIAN:0)
Block(-8,43,7,OBSIDIAN:0)
Block(-8,43,8,OBSIDIAN:0)
Block(-8,44,-7,biomesoplenty:dried_sand)
Block(-8,44,-6,OBSIDIAN:0)
Block(-8,44,-5,OBSIDIAN:0)
Block(-8,44,-4,OBSIDIAN:0)
Block(-8,44,-3,OBSIDIAN:0)
Block(-8,44,-2,OBSIDIAN:0)
Block(-8,44,-1,OBSIDIAN:0)
Block(-8,44,0,OBSIDIAN:0)
Block(-8,44,1,OBSIDIAN:0)
Block(-8,44,2,OBSIDIAN:0)
Block(-8,44,3,OBSIDIAN:0)
Block(-8,44,4,OBSIDIAN:0)
Block(-8,44,5,OBSIDIAN:0)
Block(-8,44,6,OBSIDIAN:0)
Block(-8,44,7,OBSIDIAN:0)
Block(-8,44,8,OBSIDIAN:0)
Block(-8,45,-7,biomesoplenty:dried_sand)
Block(-8,45,-6,OBSIDIAN:0)
Block(-8,45,-5,OBSIDIAN:0)
Block(-8,45,-4,OBSIDIAN:0)
Block(-8,45,-3,OBSIDIAN:0)
Block(-8,45,-2,OBSIDIAN:0)
Block(-8,45,-1,OBSIDIAN:0)
Block(-8,45,0,OBSIDIAN:0)
Block(-8,45,1,OBSIDIAN:0)
Block(-8,45,2,OBSIDIAN:0)
Block(-8,45,3,OBSIDIAN:0)
Block(-8,45,4,OBSIDIAN:0)
Block(-8,45,5,OBSIDIAN:0)
Block(-8,45,6,OBSIDIAN:0)
Block(-8,45,7,OBSIDIAN:0)
Block(-8,45,8,OBSIDIAN:0)
Block(-8,46,-7,biomesoplenty:dried_sand)
Block(-8,46,-6,OBSIDIAN:0)
Block(-8,46,-5,OBSIDIAN:0)
Block(-8,46,-4,OBSIDIAN:0)
Block(-8,46,-3,OBSIDIAN:0)
Block(-8,46,-2,OBSIDIAN:0)
Block(-8,46,-1,OBSIDIAN:0)
Block(-8,46,0,OBSIDIAN:0)
Block(-8,46,1,OBSIDIAN:0)
Block(-8,46,2,OBSIDIAN:0)
Block(-8,46,3,OBSIDIAN:0)
Block(-8,46,4,OBSIDIAN:0)
Block(-8,46,5,OBSIDIAN:0)
Block(-8,46,6,OBSIDIAN:0)
Block(-8,46,7,OBSIDIAN:0)
Block(-8,46,8,OBSIDIAN:0)
Block(-8,47,-7,biomesoplenty:dried_sand)
Block(-8,47,-6,OBSIDIAN:0)
Block(-8,47,-5,OBSIDIAN:0)
Block(-8,47,-4,OBSIDIAN:0)
Block(-8,47,-3,OBSIDIAN:0)
Block(-8,47,-2,OBSIDIAN:0)
Block(-8,47,-1,OBSIDIAN:0)
Block(-8,47,0,OBSIDIAN:0)
Block(-8,47,1,OBSIDIAN:0)
Block(-8,47,2,OBSIDIAN:0)
Block(-8,47,3,OBSIDIAN:0)
Block(-8,47,4,OBSIDIAN:0)
Block(-8,47,5,OBSIDIAN:0)
Block(-8,47,6,OBSIDIAN:0)
Block(-8,47,7,OBSIDIAN:0)
Block(-8,47,8,OBSIDIAN:0)
Block(-8,48,-7,biomesoplenty:dried_sand)
Block(-8,48,-6,OBSIDIAN:0)
Block(-8,48,-5,OBSIDIAN:0)
Block(-8,48,-4,OBSIDIAN:0)
Block(-8,48,-3,OBSIDIAN:0)
Block(-8,48,-2,OBSIDIAN:0)
Block(-8,48,-1,OBSIDIAN:0)
Block(-8,48,0,OBSIDIAN:0)
Block(-8,48,1,OBSIDIAN:0)
Block(-8,48,2,OBSIDIAN:0)
Block(-8,48,3,OBSIDIAN:0)
Block(-8,48,4,OBSIDIAN:0)
Block(-8,48,5,OBSIDIAN:0)
Block(-8,48,6,OBSIDIAN:0)
Block(-8,48,7,OBSIDIAN:0)
Block(-8,48,8,OBSIDIAN:0)
Block(-8,49,-7,biomesoplenty:dried_sand)
Block(-8,49,-6,OBSIDIAN:0)
Block(-8,49,-5,OBSIDIAN:0)
Block(-8,49,-4,OBSIDIAN:0)
Block(-8,49,-3,OBSIDIAN:0)
Block(-8,49,-2,OBSIDIAN:0)
Block(-8,49,-1,OBSIDIAN:0)
Block(-8,49,0,OBSIDIAN:0)
Block(-8,49,1,OBSIDIAN:0)
Block(-8,49,2,OBSIDIAN:0)
Block(-8,49,3,OBSIDIAN:0)
Block(-8,49,4,OBSIDIAN:0)
Block(-8,49,5,OBSIDIAN:0)
Block(-8,49,6,OBSIDIAN:0)
Block(-8,49,7,OBSIDIAN:0)
Block(-8,49,8,OBSIDIAN:0)
Block(-8,50,-7,biomesoplenty:dried_sand)
Block(-8,50,-6,OBSIDIAN:0)
Block(-8,50,-5,OBSIDIAN:0)
Block(-8,50,-4,OBSIDIAN:0)
Block(-8,50,-3,OBSIDIAN:0)
Block(-8,50,-2,OBSIDIAN:0)
Block(-8,50,-1,OBSIDIAN:0)
Block(-8,50,0,OBSIDIAN:0)
Block(-8,50,1,OBSIDIAN:0)
Block(-8,50,2,OBSIDIAN:0)
Block(-8,50,3,OBSIDIAN:0)
Block(-8,50,4,OBSIDIAN:0)
Block(-8,50,5,OBSIDIAN:0)
Block(-8,50,6,OBSIDIAN:0)
Block(-8,50,7,OBSIDIAN:0)
Block(-8,50,8,OBSIDIAN:0)
Block(-8,51,-7,biomesoplenty:dried_sand)
Block(-8,51,-6,OBSIDIAN:0)
Block(-8,51,-5,OBSIDIAN:0)
Block(-8,51,-4,OBSIDIAN:0)
Block(-8,51,-3,OBSIDIAN:0)
Block(-8,51,-2,OBSIDIAN:0)
Block(-8,51,-1,OBSIDIAN:0)
Block(-8,51,0,OBSIDIAN:0)
Block(-8,51,1,OBSIDIAN:0)
Block(-8,51,2,OBSIDIAN:0)
Block(-8,51,3,OBSIDIAN:0)
Block(-8,51,4,OBSIDIAN:0)
Block(-8,51,5,OBSIDIAN:0)
Block(-8,51,6,OBSIDIAN:0)
Block(-8,51,7,OBSIDIAN:0)
Block(-8,51,8,OBSIDIAN:0)
Block(-8,52,-7,biomesoplenty:dried_sand)
Block(-8,52,-6,OBSIDIAN:0)
Block(-8,52,-5,OBSIDIAN:0)
Block(-8,52,-4,OBSIDIAN:0)
Block(-8,52,-3,OBSIDIAN:0)
Block(-8,52,-2,OBSIDIAN:0)
Block(-8,52,-1,OBSIDIAN:0)
Block(-8,52,0,OBSIDIAN:0)
Block(-8,52,1,OBSIDIAN:0)
Block(-8,52,2,OBSIDIAN:0)
Block(-8,52,3,OBSIDIAN:0)
Block(-8,52,4,OBSIDIAN:0)
Block(-8,52,5,OBSIDIAN:0)
Block(-8,52,6,OBSIDIAN:0)
Block(-8,52,7,OBSIDIAN:0)
Block(-8,52,8,OBSIDIAN:0)
Block(-8,53,-7,biomesoplenty:dried_sand)
Block(-8,53,-6,OBSIDIAN:0)
Block(-8,53,-5,OBSIDIAN:0)
Block(-8,53,-4,OBSIDIAN:0)
Block(-8,53,-3,OBSIDIAN:0)
Block(-8,53,-2,OBSIDIAN:0)
Block(-8,53,-1,OBSIDIAN:0)
Block(-8,53,0,OBSIDIAN:0)
Block(-8,53,1,OBSIDIAN:0)
Block(-8,53,2,OBSIDIAN:0)
Block(-8,53,3,OBSIDIAN:0)
Block(-8,53,4,OBSIDIAN:0)
Block(-8,53,5,OBSIDIAN:0)
Block(-8,53,6,OBSIDIAN:0)
Block(-8,53,7,OBSIDIAN:0)
Block(-8,53,8,OBSIDIAN:0)
Block(-8,54,-7,biomesoplenty:dried_sand)
Block(-8,54,-6,OBSIDIAN:0)
Block(-8,54,-5,OBSIDIAN:0)
Block(-8,54,-4,OBSIDIAN:0)
Block(-8,54,-3,OBSIDIAN:0)
Block(-8,54,-2,OBSIDIAN:0)
Block(-8,54,-1,OBSIDIAN:0)
Block(-8,54,0,OBSIDIAN:0)
Block(-8,54,1,OBSIDIAN:0)
Block(-8,54,2,OBSIDIAN:0)
Block(-8,54,3,OBSIDIAN:0)
Block(-8,54,4,OBSIDIAN:0)
Block(-8,54,5,OBSIDIAN:0)
Block(-8,54,6,OBSIDIAN:0)
Block(-8,54,7,OBSIDIAN:0)
Block(-8,54,8,OBSIDIAN:0)
Block(-8,55,-7,biomesoplenty:dried_sand)
Block(-8,55,-6,OBSIDIAN:0)
Block(-8,55,-5,OBSIDIAN:0)
Block(-8,55,-4,OBSIDIAN:0)
Block(-8,55,-3,OBSIDIAN:0)
Block(-8,55,-2,OBSIDIAN:0)
Block(-8,55,-1,OBSIDIAN:0)
Block(-8,55,0,OBSIDIAN:0)
Block(-8,55,1,OBSIDIAN:0)
Block(-8,55,2,OBSIDIAN:0)
Block(-8,55,3,OBSIDIAN:0)
Block(-8,55,4,OBSIDIAN:0)
Block(-8,55,5,OBSIDIAN:0)
Block(-8,55,6,OBSIDIAN:0)
Block(-8,55,7,OBSIDIAN:0)
Block(-8,55,8,OBSIDIAN:0)
Block(-8,56,-7,biomesoplenty:dried_sand)
Block(-8,56,-6,OBSIDIAN:0)
Block(-8,56,-5,OBSIDIAN:0)
Block(-8,56,-4,OBSIDIAN:0)
Block(-8,56,-3,OBSIDIAN:0)
Block(-8,56,-2,OBSIDIAN:0)
Block(-8,56,-1,OBSIDIAN:0)
Block(-8,56,0,OBSIDIAN:0)
Block(-8,56,1,OBSIDIAN:0)
Block(-8,56,2,OBSIDIAN:0)
Block(-8,56,3,OBSIDIAN:0)
Block(-8,56,4,OBSIDIAN:0)
Block(-8,56,5,OBSIDIAN:0)
Block(-8,56,6,OBSIDIAN:0)
Block(-8,56,7,OBSIDIAN:0)
Block(-8,56,8,OBSIDIAN:0)
Block(-8,57,-7,biomesoplenty:dried_sand)
Block(-8,57,-6,OBSIDIAN:0)
Block(-8,57,-5,OBSIDIAN:0)
Block(-8,57,-4,OBSIDIAN:0)
Block(-8,57,-3,OBSIDIAN:0)
Block(-8,57,-2,OBSIDIAN:0)
Block(-8,57,-1,OBSIDIAN:0)
Block(-8,57,0,OBSIDIAN:0)
Block(-8,57,1,OBSIDIAN:0)
Block(-8,57,2,OBSIDIAN:0)
Block(-8,57,3,OBSIDIAN:0)
Block(-8,57,4,OBSIDIAN:0)
Block(-8,57,5,OBSIDIAN:0)
Block(-8,57,6,OBSIDIAN:0)
Block(-8,57,7,OBSIDIAN:0)
Block(-8,57,8,OBSIDIAN:0)
Block(-8,58,-7,biomesoplenty:dried_sand)
Block(-8,58,-6,OBSIDIAN:0)
Block(-8,58,-5,OBSIDIAN:0)
Block(-8,58,-4,OBSIDIAN:0)
Block(-8,58,-3,OBSIDIAN:0)
Block(-8,58,-2,OBSIDIAN:0)
Block(-8,58,-1,OBSIDIAN:0)
Block(-8,58,0,OBSIDIAN:0)
Block(-8,58,1,OBSIDIAN:0)
Block(-8,58,2,OBSIDIAN:0)
Block(-8,58,3,OBSIDIAN:0)
Block(-8,58,4,OBSIDIAN:0)
Block(-8,58,5,OBSIDIAN:0)
Block(-8,58,6,OBSIDIAN:0)
Block(-8,58,7,OBSIDIAN:0)
Block(-8,58,8,OBSIDIAN:0)
Block(-8,59,-7,biomesoplenty:dried_sand)
Block(-8,59,-6,OBSIDIAN:0)
Block(-8,59,-5,OBSIDIAN:0)
Block(-8,59,-4,OBSIDIAN:0)
Block(-8,59,-3,OBSIDIAN:0)
Block(-8,59,-2,OBSIDIAN:0)
Block(-8,59,-1,OBSIDIAN:0)
Block(-8,59,0,OBSIDIAN:0)
Block(-8,59,1,OBSIDIAN:0)
Block(-8,59,2,OBSIDIAN:0)
Block(-8,59,3,OBSIDIAN:0)
Block(-8,59,4,OBSIDIAN:0)
Block(-8,59,5,OBSIDIAN:0)
Block(-8,59,6,OBSIDIAN:0)
Block(-8,59,7,OBSIDIAN:0)
Block(-8,59,8,OBSIDIAN:0)
Block(-8,60,-7,biomesoplenty:dried_sand)
Block(-8,60,-6,OBSIDIAN:0)
Block(-8,60,-5,OBSIDIAN:0)
Block(-8,60,-4,OBSIDIAN:0)
Block(-8,60,-3,OBSIDIAN:0)
Block(-8,60,-2,OBSIDIAN:0)
Block(-8,60,-1,OBSIDIAN:0)
Block(-8,60,0,OBSIDIAN:0)
Block(-8,60,1,OBSIDIAN:0)
Block(-8,60,2,OBSIDIAN:0)
Block(-8,60,3,OBSIDIAN:0)
Block(-8,60,4,OBSIDIAN:0)
Block(-8,60,5,OBSIDIAN:0)
Block(-8,60,6,OBSIDIAN:0)
Block(-8,60,7,OBSIDIAN:0)
Block(-8,60,8,OBSIDIAN:0)
RandomBlock(-8,61,-7,SMOOTH_BRICK:1,10,SMOOTH_BRICK:2,10,COBBLESTONE,10,MOSSY_COBBLESTONE,10,SMOOTH_BRICK,100)
Block(-8,61,-6,OBSIDIAN:0)
Block(-8,61,-5,OBSIDIAN:0)
Block(-8,61,-4,OBSIDIAN:0)
Block(-8,61,-3,OBSIDIAN:0)
Block(-8,61,-2,OBSIDIAN:0)
Block(-8,61,-1,OBSIDIAN:0)
Block(-8,61,0,OBSIDIAN:0)
Block(-8,61,1,OBSIDIAN:0)
Block(-8,61,2,OBSIDIAN:0)
Block(-8,61,3,OBSIDIAN:0)
Block(-8,61,4,OBSIDIAN:0)
Block(-8,61,5,OBSIDIAN:0)
Block(-8,61,6,OBSIDIAN:0)
Block(-8,61,7,OBSIDIAN:0)
Block(-8,61,8,OBSIDIAN:0)
RandomBlock(-8,62,-7,SMOOTH_BRICK:1,10,SMOOTH_BRICK:2,10,COBBLESTONE,10,MOSSY_COBBLESTONE,10,SMOOTH_BRICK,100)
Block(-8,62,-6,biomesoplenty:dried_sand)
Block(-8,62,-5,OBSIDIAN:0)
Block(-8,62,-4,OBSIDIAN:0)
Block(-8,62,-3,OBSIDIAN:0)
Block(-8,62,-2,OBSIDIAN:0)
Block(-8,62,-1,OBSIDIAN:0)
Block(-8,62,0,OBSIDIAN:0)
Block(-8,62,1,OBSIDIAN:0)
Block(-8,62,2,OBSIDIAN:0)
Block(-8,62,3,OBSIDIAN:0)
Block(-8,62,4,OBSIDIAN:0)
Block(-8,62,5,OBSIDIAN:0)
Block(-8,62,6,OBSIDIAN:0)
Block(-8,62,7,OBSIDIAN:0)
Block(-8,62,8,OBSIDIAN:0)
RandomBlock(-8,63,-7,SMOOTH_BRICK:1,10,SMOOTH_BRICK:2,10,COBBLESTONE,10,MOSSY_COBBLESTONE,10,SMOOTH_BRICK,100)
Block(-8,63,-6,biomesoplenty:dried_sand)
Block(-8,63,-5,OBSIDIAN:0)
Block(-8,63,-4,OBSIDIAN:0)
Block(-8,63,-3,OBSIDIAN:0)
Block(-8,63,-2,OBSIDIAN:0)
Block(-8,63,-1,OBSIDIAN:0)
Block(-8,63,0,OBSIDIAN:0)
Block(-8,63,1,OBSIDIAN:0)
Block(-8,63,2,OBSIDIAN:0)
Block(-8,63,3,OBSIDIAN:0)
Block(-8,63,4,OBSIDIAN:0)
Block(-8,63,5,OBSIDIAN:0)
Block(-8,63,6,OBSIDIAN:0)
Block(-8,63,7,OBSIDIAN:0)
Block(-8,63,8,OBSIDIAN:0)
RandomBlock(-8,64,-7,SMOOTH_BRICK:1,10,SMOOTH_BRICK:2,10,COBBLESTONE,10,MOSSY_COBBLESTONE,10,SMOOTH_BRICK,100)
Block(-8,64,-6,biomesoplenty:dried_sand)
Block(-8,64,-5,OBSIDIAN:0)
Block(-8,64,-4,OBSIDIAN:0)
Block(-8,64,-3,OBSIDIAN:0)
Block(-8,64,-2,OBSIDIAN:0)
Block(-8,64,-1,OBSIDIAN:0)
Block(-8,64,0,OBSIDIAN:0)
Block(-8,64,1,OBSIDIAN:0)
Block(-8,64,2,OBSIDIAN:0)
Block(-8,64,3,OBSIDIAN:0)
Block(-8,64,4,OBSIDIAN:0)
Block(-8,64,5,biomesoplenty:dried_sand)
Block(-8,64,6,OBSIDIAN:0)
Block(-8,64,7,OBSIDIAN:0)
Block(-8,64,8,OBSIDIAN:0)
RandomBlock(-8,65,-7,SMOOTH_BRICK:1,10,SMOOTH_BRICK:2,10,COBBLESTONE,10,MOSSY_COBBLESTONE,10,SMOOTH_BRICK,100)
Block(-8,65,-6,OBSIDIAN:0)
Block(-8,65,-5,OBSIDIAN:0)
Block(-8,65,-4,OBSIDIAN:0)
Block(-8,65,-3,OBSIDIAN:0)
Block(-8,65,-2,OBSIDIAN:0)
Block(-8,65,-1,OBSIDIAN:0)
Block(-8,65,0,OBSIDIAN:0)
Block(-8,65,1,OBSIDIAN:0)
Block(-8,65,2,OBSIDIAN:0)
Block(-8,65,3,OBSIDIAN:0)
Block(-8,65,4,OBSIDIAN:0)
RandomBlock(-8,65,5,SMOOTH_BRICK:1,10,SMOOTH_BRICK:2,10,COBBLESTONE,10,MOSSY_COBBLESTONE,10,SMOOTH_BRICK,100)
Block(-8,65,6,OBSIDIAN:0)
Block(-8,65,7,OBSIDIAN:0)
Block(-8,65,8,OBSIDIAN:0)
Block(-8,66,-7,biomesoplenty:dried_sand)
Block(-8,66,-6,OBSIDIAN:0)
Block(-8,66,-5,OBSIDIAN:0)
Block(-8,66,-4,OBSIDIAN:0)
Block(-8,66,-3,OBSIDIAN:0)
Block(-8,66,-2,OBSIDIAN:0)
Block(-8,66,-1,OBSIDIAN:0)
Block(-8,66,0,OBSIDIAN:0)
Block(-8,66,1,OBSIDIAN:0)
Block(-8,66,2,OBSIDIAN:0)
Block(-8,66,3,OBSIDIAN:0)
Block(-8,66,4,OBSIDIAN:0)
RandomBlock(-8,66,5,SMOOTH_BRICK:1,10,SMOOTH_BRICK:2,10,COBBLESTONE,10,MOSSY_COBBLESTONE,10,SMOOTH_BRICK,100)
Block(-8,66,6,OBSIDIAN:0)
Block(-8,66,7,OBSIDIAN:0)
RandomBlock(-8,66,8,SMOOTH_BRICK:1,10,SMOOTH_BRICK:2,10,COBBLESTONE,10,MOSSY_COBBLESTONE,10,SMOOTH_BRICK,100)
Block(-8,67,-7,biomesoplenty:dried_sand)
Block(-8,67,-6,OBSIDIAN:0)
Block(-8,67,-5,OBSIDIAN:0)
Block(-8,67,-4,OBSIDIAN:0)
Block(-8,67,-3,OBSIDIAN:0)
Block(-8,67,-2,OBSIDIAN:0)
Block(-8,67,-1,OBSIDIAN:0)
Block(-8,67,0,OBSIDIAN:0)
Block(-8,67,1,OBSIDIAN:0)
Block(-8,67,2,OBSIDIAN:0)
Block(-8,67,3,OBSIDIAN:0)
Block(-8,67,4,OBSIDIAN:0)
RandomBlock(-8,67,5,SMOOTH_BRICK:1,10,SMOOTH_BRICK:2,10,COBBLESTONE,10,MOSSY_COBBLESTONE,10,SMOOTH_BRICK,100)
RandomBlock(-8,67,6,SMOOTH_BRICK:1,10,SMOOTH_BRICK:2,10,COBBLESTONE,10,MOSSY_COBBLESTONE,10,SMOOTH_BRICK,100)
Block(-8,67,7,OBSIDIAN:0)
RandomBlock(-8,67,8,SMOOTH_BRICK:1,10,SMOOTH_BRICK:2,10,COBBLESTONE,10,MOSSY_COBBLESTONE,10,SMOOTH_BRICK,100)
Block(-8,68,-7,biomesoplenty:dried_sand)
Block(-8,68,-6,OBSIDIAN:0)
Block(-8,68,-5,OBSIDIAN:0)
Block(-8,68,-4,OBSIDIAN:0)
Block(-8,68,-3,OBSIDIAN:0)
Block(-8,68,-2,OBSIDIAN:0)
Block(-8,68,-1,OBSIDIAN:0)
Block(-8,68,0,OBSIDIAN:0)
Block(-8,68,1,OBSIDIAN:0)
Block(-8,68,2,OBSIDIAN:0)
Block(-8,68,3,OBSIDIAN:0)
Block(-8,68,4,OBSIDIAN:0)
RandomBlock(-8,68,5,SMOOTH_BRICK:1,10,SMOOTH_BRICK:2,10,COBBLESTONE,10,MOSSY_COBBLESTONE,10,SMOOTH_BRICK,100)
RandomBlock(-8,68,6,SMOOTH_BRICK:1,10,SMOOTH_BRICK:2,10,COBBLESTONE,10,MOSSY_COBBLESTONE,10,SMOOTH_BRICK,100)
Block(-8,68,7,OBSIDIAN:0)
RandomBlock(-8,68,8,SMOOTH_BRICK:1,10,SMOOTH_BRICK:2,10,COBBLESTONE,10,MOSSY_COBBLESTONE,10,SMOOTH_BRICK,100)
Block(-8,69,-7,biomesoplenty:dried_sand)
Block(-8,69,-6,biomesoplenty:dried_sand)
Block(-8,69,-5,biomesoplenty:dried_sand)
Block(-8,69,-4,biomesoplenty:dried_sand)
Block(-8,69,-3,biomesoplenty:dried_sand)
Block(-8,69,-2,OBSIDIAN:0)
Block(-8,69,-1,OBSIDIAN:0)
Block(-8,69,0,OBSIDIAN:0)
Block(-8,69,1,OBSIDIAN:0)
Block(-8,69,2,OBSIDIAN:0)
Block(-8,69,3,OBSIDIAN:0)
Block(-8,69,4,OBSIDIAN:0)
RandomBlock(-8,69,5,SMOOTH_BRICK:1,10,SMOOTH_BRICK:2,10,COBBLESTONE,10,MOSSY_COBBLESTONE,10,SMOOTH_BRICK,100)
RandomBlock(-8,69,6,SMOOTH_BRICK:1,10,SMOOTH_BRICK:2,10,COBBLESTONE,10,MOSSY_COBBLESTONE,10,SMOOTH_BRICK,100)
RandomBlock(-8,69,7,SMOOTH_BRICK:1,10,SMOOTH_BRICK:2,10,COBBLESTONE,10,MOSSY_COBBLESTONE,10,SMOOTH_BRICK,100)
RandomBlock(-8,69,8,SMOOTH_BRICK:1,10,SMOOTH_BRICK:2,10,COBBLESTONE,10,MOSSY_COBBLESTONE,10,SMOOTH_BRICK,100)
Block(-8,70,-7,biomesoplenty:dried_sand)
Block(-8,70,-6,biomesoplenty:dried_sand)
Block(-8,70,-5,biomesoplenty:dried_sand)
Block(-8,70,-4,biomesoplenty:dried_sand)
Block(-8,70,-3,biomesoplenty:dried_sand)
Block(-8,70,-2,biomesoplenty:dried_sand)
Block(-8,70,-1,biomesoplenty:dried_sand)
Block(-8,70,0,biomesoplenty:dried_sand)
Block(-8,70,1,biomesoplenty:dried_sand)
Block(-8,70,2,OBSIDIAN:0)
Block(-8,70,3,OBSIDIAN:0)
Block(-8,70,4,biomesoplenty:dried_sand)
RandomBlock(-8,70,5,SMOOTH_BRICK:1,10,SMOOTH_BRICK:2,10,COBBLESTONE,10,MOSSY_COBBLESTONE,10,SMOOTH_BRICK,100)
RandomBlock(-8,70,6,SMOOTH_STAIRS:3,50,quark:stonebrick_mossy_stairs,100)
Block(-8,71,-7,biomesoplenty:dried_sand)
Block(-8,71,-6,biomesoplenty:dried_sand)
Block(-8,71,-5,biomesoplenty:dried_sand)
Block(-8,71,-4,biomesoplenty:dried_sand)
Block(-8,71,-3,biomesoplenty:dried_sand)
RandomBlock(-8,71,-2,SAND:0,50,biomesoplenty:dried_sand,100)
Block(-8,71,-1,biomesoplenty:dried_sand)
Block(-8,71,0,biomesoplenty:dried_sand)
Block(-8,71,1,biomesoplenty:dried_sand)
Block(-8,71,2,biomesoplenty:dried_sand)
Block(-8,71,3,biomesoplenty:dried_sand)
Block(-8,71,4,biomesoplenty:dried_sand)
RandomBlock(-8,71,5,SMOOTH_BRICK:1,10,SMOOTH_BRICK:2,10,COBBLESTONE,10,MOSSY_COBBLESTONE,10,SMOOTH_BRICK,100)
Block(-8,72,-6,biomesoplenty:dried_sand)
Block(-8,72,-5,biomesoplenty:dried_sand)
Block(-8,72,-4,biomesoplenty:dried_sand)
Block(-8,72,-3,biomesoplenty:dried_sand)
RandomBlock(-8,72,-2,SAND:0,50,biomesoplenty:dried_sand,100)
RandomBlock(-8,72,-1,SAND:0,50,biomesoplenty:dried_sand,100)
RandomBlock(-8,72,0,SAND:0,50,biomesoplenty:dried_sand,100)
RandomBlock(-8,72,1,SAND:0,50,biomesoplenty:dried_sand,100)
Block(-8,73,-6,biomesoplenty:dried_sand)
Block(-8,73,-5,biomesoplenty:dried_sand)
Block(-8,73,-4,biomesoplenty:dried_sand)
Block(-8,73,-3,biomesoplenty:dried_sand)
RandomBlock(-8,73,-2,SAND:0,50,biomesoplenty:dried_sand,100)
RandomBlock(-8,73,-1,SAND:0,50,biomesoplenty:dried_sand,100)
RandomBlock(-8,73,0,SAND:0,50,biomesoplenty:dried_sand,100)
RandomBlock(-8,73,1,SAND:0,50,biomesoplenty:dried_sand,100)
Block(-8,74,-4,biomesoplenty:dried_sand)
Block(-8,74,-3,biomesoplenty:dried_sand)
RandomBlock(-8,74,-2,SAND:0,50,biomesoplenty:dried_sand,100)
RandomBlock(-8,74,-1,SAND:0,50,biomesoplenty:dried_sand,100)
RandomBlock(-8,74,0,SAND:0,50,biomesoplenty:dried_sand,100)
RandomBlock(-8,74,1,SAND:0,50,biomesoplenty:dried_sand,100)
RandomBlock(-8,75,-2,SAND:0,50,biomesoplenty:dried_sand,100)
RandomBlock(-8,75,-1,SAND:0,50,biomesoplenty:dried_sand,100)
RandomBlock(-8,75,0,SAND:0,50,biomesoplenty:dried_sand,100)
RandomBlock(-8,75,1,SAND:0,50,biomesoplenty:dried_sand,100)
Block(-7,0,-7,biomesoplenty:dried_sand)
Block(-7,0,-6,biomesoplenty:dried_sand)
Block(-7,0,-5,biomesoplenty:dried_sand)
Block(-7,0,-4,biomesoplenty:dried_sand)
Block(-7,0,-3,biomesoplenty:dried_sand)
Block(-7,0,-2,biomesoplenty:dried_sand)
Block(-7,0,-1,biomesoplenty:dried_sand)
Block(-7,0,0,biomesoplenty:dried_sand)
Block(-7,0,1,biomesoplenty:dried_sand)
Block(-7,0,2,biomesoplenty:dried_sand)
Block(-7,0,3,biomesoplenty:dried_sand)
Block(-7,0,4,biomesoplenty:dried_sand)
Block(-7,0,5,biomesoplenty:dried_sand)
Block(-7,0,6,biomesoplenty:dried_sand)
Block(-7,0,7,biomesoplenty:dried_sand)
Block(-7,0,8,biomesoplenty:dried_sand)
Block(-7,1,-7,biomesoplenty:dried_sand)
Block(-7,1,-6,biomesoplenty:dried_sand)
Block(-7,1,-5,biomesoplenty:dried_sand)
Block(-7,1,-4,biomesoplenty:dried_sand)
Block(-7,1,-3,biomesoplenty:dried_sand)
Block(-7,1,-2,biomesoplenty:dried_sand)
Block(-7,1,-1,biomesoplenty:dried_sand)
Block(-7,1,0,biomesoplenty:dried_sand)
Block(-7,1,1,biomesoplenty:dried_sand)
Block(-7,1,2,biomesoplenty:dried_sand)
Block(-7,1,3,biomesoplenty:dried_sand)
Block(-7,1,4,biomesoplenty:dried_sand)
Block(-7,1,5,biomesoplenty:dried_sand)
Block(-7,1,6,biomesoplenty:dried_sand)
Block(-7,1,7,biomesoplenty:dried_sand)
Block(-7,1,8,biomesoplenty:dried_sand)
Block(-7,2,-7,biomesoplenty:dried_sand)
Block(-7,2,-6,biomesoplenty:dried_sand)
Block(-7,2,-5,biomesoplenty:dried_sand)
Block(-7,2,-4,biomesoplenty:dried_sand)
Block(-7,2,-3,biomesoplenty:dried_sand)
Block(-7,2,-2,biomesoplenty:dried_sand)
Block(-7,2,-1,biomesoplenty:dried_sand)
Block(-7,2,0,biomesoplenty:dried_sand)
Block(-7,2,1,biomesoplenty:dried_sand)
Block(-7,2,2,biomesoplenty:dried_sand)
Block(-7,2,3,biomesoplenty:dried_sand)
Block(-7,2,4,biomesoplenty:dried_sand)
Block(-7,2,5,biomesoplenty:dried_sand)
Block(-7,2,6,biomesoplenty:dried_sand)
Block(-7,2,7,biomesoplenty:dried_sand)
Block(-7,2,8,biomesoplenty:dried_sand)
Block(-7,3,-7,biomesoplenty:dried_sand)
Block(-7,3,-6,biomesoplenty:dried_sand)
Block(-7,3,-5,biomesoplenty:dried_sand)
Block(-7,3,-4,biomesoplenty:dried_sand)
Block(-7,3,-3,biomesoplenty:dried_sand)
Block(-7,3,-2,biomesoplenty:dried_sand)
Block(-7,3,-1,biomesoplenty:dried_sand)
Block(-7,3,0,biomesoplenty:dried_sand)
Block(-7,3,1,biomesoplenty:dried_sand)
Block(-7,3,2,biomesoplenty:dried_sand)
Block(-7,3,3,biomesoplenty:dried_sand)
Block(-7,3,4,biomesoplenty:dried_sand)
Block(-7,3,5,biomesoplenty:dried_sand)
Block(-7,3,6,biomesoplenty:dried_sand)
Block(-7,3,7,biomesoplenty:dried_sand)
Block(-7,3,8,biomesoplenty:dried_sand)
Block(-7,4,-7,biomesoplenty:dried_sand)
Block(-7,4,-6,biomesoplenty:dried_sand)
Block(-7,4,-5,biomesoplenty:dried_sand)
Block(-7,4,-4,biomesoplenty:dried_sand)
Block(-7,4,-3,biomesoplenty:dried_sand)
Block(-7,4,-2,biomesoplenty:dried_sand)
Block(-7,4,-1,biomesoplenty:dried_sand)
Block(-7,4,0,biomesoplenty:dried_sand)
Block(-7,4,1,biomesoplenty:dried_sand)
Block(-7,4,2,biomesoplenty:dried_sand)
Block(-7,4,3,biomesoplenty:dried_sand)
Block(-7,4,4,biomesoplenty:dried_sand)
Block(-7,4,5,biomesoplenty:dried_sand)
Block(-7,4,6,biomesoplenty:dried_sand)
Block(-7,4,7,biomesoplenty:dried_sand)
Block(-7,4,8,biomesoplenty:dried_sand)
Block(-7,5,-7,biomesoplenty:dried_sand)
Block(-7,5,-6,biomesoplenty:dried_sand)
Block(-7,5,-5,biomesoplenty:dried_sand)
Block(-7,5,-4,biomesoplenty:dried_sand)
Block(-7,5,-3,biomesoplenty:dried_sand)
Block(-7,5,-2,biomesoplenty:dried_sand)
Block(-7,5,-1,biomesoplenty:dried_sand)
Block(-7,5,0,biomesoplenty:dried_sand)
Block(-7,5,1,biomesoplenty:dried_sand)
Block(-7,5,2,biomesoplenty:dried_sand)
Block(-7,5,3,biomesoplenty:dried_sand)
Block(-7,5,4,biomesoplenty:dried_sand)
Block(-7,5,5,biomesoplenty:dried_sand)
Block(-7,5,6,biomesoplenty:dried_sand)
Block(-7,5,7,biomesoplenty:dried_sand)
Block(-7,5,8,biomesoplenty:dried_sand)
Block(-7,6,-7,biomesoplenty:dried_sand)
Block(-7,6,-6,biomesoplenty:dried_sand)
Block(-7,6,-5,biomesoplenty:dried_sand)
Block(-7,6,-4,biomesoplenty:dried_sand)
Block(-7,6,-3,biomesoplenty:dried_sand)
Block(-7,6,-2,biomesoplenty:dried_sand)
Block(-7,6,-1,biomesoplenty:dried_sand)
Block(-7,6,0,biomesoplenty:dried_sand)
Block(-7,6,1,biomesoplenty:dried_sand)
Block(-7,6,2,biomesoplenty:dried_sand)
Block(-7,6,3,biomesoplenty:dried_sand)
Block(-7,6,4,biomesoplenty:dried_sand)
Block(-7,6,5,biomesoplenty:dried_sand)
Block(-7,6,6,biomesoplenty:dried_sand)
Block(-7,6,7,biomesoplenty:dried_sand)
Block(-7,6,8,biomesoplenty:dried_sand)
Block(-7,7,-7,biomesoplenty:dried_sand)
Block(-7,7,-6,biomesoplenty:dried_sand)
Block(-7,7,-5,biomesoplenty:dried_sand)
Block(-7,7,-4,biomesoplenty:dried_sand)
Block(-7,7,-3,biomesoplenty:dried_sand)
Block(-7,7,-2,biomesoplenty:dried_sand)
Block(-7,7,-1,biomesoplenty:dried_sand)
Block(-7,7,0,biomesoplenty:dried_sand)
Block(-7,7,1,biomesoplenty:dried_sand)
Block(-7,7,2,biomesoplenty:dried_sand)
Block(-7,7,3,biomesoplenty:dried_sand)
Block(-7,7,4,biomesoplenty:dried_sand)
Block(-7,7,5,biomesoplenty:dried_sand)
Block(-7,7,6,biomesoplenty:dried_sand)
Block(-7,7,7,biomesoplenty:dried_sand)
Block(-7,7,8,biomesoplenty:dried_sand)
Block(-7,8,-7,biomesoplenty:dried_sand)
Block(-7,8,-6,biomesoplenty:dried_sand)
Block(-7,8,-5,biomesoplenty:dried_sand)
Block(-7,8,-4,biomesoplenty:dried_sand)
Block(-7,8,-3,biomesoplenty:dried_sand)
Block(-7,8,-2,biomesoplenty:dried_sand)
Block(-7,8,-1,biomesoplenty:dried_sand)
Block(-7,8,0,biomesoplenty:dried_sand)
Block(-7,8,1,biomesoplenty:dried_sand)
Block(-7,8,2,biomesoplenty:dried_sand)
Block(-7,8,3,biomesoplenty:dried_sand)
Block(-7,8,4,biomesoplenty:dried_sand)
Block(-7,8,5,biomesoplenty:dried_sand)
Block(-7,8,6,biomesoplenty:dried_sand)
Block(-7,8,7,biomesoplenty:dried_sand)
Block(-7,8,8,biomesoplenty:dried_sand)
Block(-7,9,-7,biomesoplenty:dried_sand)
Block(-7,9,-6,biomesoplenty:dried_sand)
Block(-7,9,-5,biomesoplenty:dried_sand)
Block(-7,9,-4,biomesoplenty:dried_sand)
Block(-7,9,-3,biomesoplenty:dried_sand)
Block(-7,9,-2,biomesoplenty:dried_sand)
Block(-7,9,-1,biomesoplenty:dried_sand)
Block(-7,9,0,biomesoplenty:dried_sand)
Block(-7,9,1,biomesoplenty:dried_sand)
Block(-7,9,2,biomesoplenty:dried_sand)
Block(-7,9,3,biomesoplenty:dried_sand)
Block(-7,9,4,biomesoplenty:dried_sand)
Block(-7,9,5,biomesoplenty:dried_sand)
Block(-7,9,6,biomesoplenty:dried_sand)
Block(-7,9,7,biomesoplenty:dried_sand)
Block(-7,9,8,biomesoplenty:dried_sand)
Block(-7,10,-7,biomesoplenty:dried_sand)
Block(-7,10,-6,biomesoplenty:dried_sand)
Block(-7,10,-5,biomesoplenty:dried_sand)
Block(-7,10,-4,biomesoplenty:dried_sand)
Block(-7,10,-3,biomesoplenty:dried_sand)
Block(-7,10,-2,biomesoplenty:dried_sand)
Block(-7,10,-1,biomesoplenty:dried_sand)
Block(-7,10,0,biomesoplenty:dried_sand)
Block(-7,10,1,biomesoplenty:dried_sand)
Block(-7,10,2,biomesoplenty:dried_sand)
Block(-7,10,3,biomesoplenty:dried_sand)
Block(-7,10,4,biomesoplenty:dried_sand)
Block(-7,10,5,biomesoplenty:dried_sand)
Block(-7,10,6,biomesoplenty:dried_sand)
Block(-7,10,7,biomesoplenty:dried_sand)
Block(-7,10,8,biomesoplenty:dried_sand)
Block(-7,11,-7,biomesoplenty:dried_sand)
Block(-7,11,-6,biomesoplenty:dried_sand)
Block(-7,11,-5,biomesoplenty:dried_sand)
Block(-7,11,-4,biomesoplenty:dried_sand)
Block(-7,11,-3,biomesoplenty:dried_sand)
Block(-7,11,-2,biomesoplenty:dried_sand)
Block(-7,11,-1,biomesoplenty:dried_sand)
Block(-7,11,0,biomesoplenty:dried_sand)
Block(-7,11,1,biomesoplenty:dried_sand)
Block(-7,11,2,biomesoplenty:dried_sand)
Block(-7,11,3,biomesoplenty:dried_sand)
Block(-7,11,4,biomesoplenty:dried_sand)
Block(-7,11,5,biomesoplenty:dried_sand)
Block(-7,11,6,biomesoplenty:dried_sand)
Block(-7,11,7,biomesoplenty:dried_sand)
Block(-7,11,8,biomesoplenty:dried_sand)
Block(-7,12,-7,biomesoplenty:dried_sand)
Block(-7,12,-6,biomesoplenty:dried_sand)
Block(-7,12,-5,biomesoplenty:dried_sand)
Block(-7,12,-4,biomesoplenty:dried_sand)
Block(-7,12,-3,biomesoplenty:dried_sand)
Block(-7,12,-2,biomesoplenty:dried_sand)
Block(-7,12,-1,biomesoplenty:dried_sand)
Block(-7,12,0,biomesoplenty:dried_sand)
Block(-7,12,1,biomesoplenty:dried_sand)
Block(-7,12,2,biomesoplenty:dried_sand)
Block(-7,12,3,biomesoplenty:dried_sand)
Block(-7,12,4,biomesoplenty:dried_sand)
Block(-7,12,5,biomesoplenty:dried_sand)
Block(-7,12,6,biomesoplenty:dried_sand)
Block(-7,12,7,biomesoplenty:dried_sand)
Block(-7,12,8,biomesoplenty:dried_sand)
Block(-7,13,-7,biomesoplenty:dried_sand)
Block(-7,13,-6,biomesoplenty:dried_sand)
Block(-7,13,-5,biomesoplenty:dried_sand)
Block(-7,13,-4,biomesoplenty:dried_sand)
Block(-7,13,-3,biomesoplenty:dried_sand)
Block(-7,13,-2,biomesoplenty:dried_sand)
Block(-7,13,-1,biomesoplenty:dried_sand)
Block(-7,13,0,biomesoplenty:dried_sand)
Block(-7,13,1,biomesoplenty:dried_sand)
Block(-7,13,2,biomesoplenty:dried_sand)
Block(-7,13,3,biomesoplenty:dried_sand)
Block(-7,13,4,biomesoplenty:dried_sand)
Block(-7,13,5,biomesoplenty:dried_sand)
Block(-7,13,6,biomesoplenty:dried_sand)
Block(-7,13,7,biomesoplenty:dried_sand)
Block(-7,13,8,biomesoplenty:dried_sand)
Block(-7,14,-7,biomesoplenty:dried_sand)
Block(-7,14,-6,biomesoplenty:dried_sand)
Block(-7,14,-5,biomesoplenty:dried_sand)
Block(-7,14,-4,biomesoplenty:dried_sand)
Block(-7,14,-3,biomesoplenty:dried_sand)
Block(-7,14,-2,biomesoplenty:dried_sand)
Block(-7,14,-1,biomesoplenty:dried_sand)
Block(-7,14,0,biomesoplenty:dried_sand)
Block(-7,14,1,biomesoplenty:dried_sand)
Block(-7,14,2,biomesoplenty:dried_sand)
Block(-7,14,3,biomesoplenty:dried_sand)
Block(-7,14,4,biomesoplenty:dried_sand)
Block(-7,14,5,biomesoplenty:dried_sand)
Block(-7,14,6,biomesoplenty:dried_sand)
Block(-7,14,7,biomesoplenty:dried_sand)
Block(-7,14,8,biomesoplenty:dried_sand)
Block(-7,15,-7,biomesoplenty:dried_sand)
Block(-7,15,-6,biomesoplenty:dried_sand)
Block(-7,15,-5,biomesoplenty:dried_sand)
Block(-7,15,-4,biomesoplenty:dried_sand)
Block(-7,15,-3,biomesoplenty:dried_sand)
Block(-7,15,-2,biomesoplenty:dried_sand)
Block(-7,15,-1,biomesoplenty:dried_sand)
Block(-7,15,0,biomesoplenty:dried_sand)
Block(-7,15,1,biomesoplenty:dried_sand)
Block(-7,15,2,biomesoplenty:dried_sand)
Block(-7,15,3,biomesoplenty:dried_sand)
Block(-7,15,4,biomesoplenty:dried_sand)
Block(-7,15,5,biomesoplenty:dried_sand)
Block(-7,15,6,biomesoplenty:dried_sand)
Block(-7,15,7,biomesoplenty:dried_sand)
Block(-7,15,8,biomesoplenty:dried_sand)
Block(-7,16,-7,biomesoplenty:dried_sand)
Block(-7,16,-6,biomesoplenty:dried_sand)
Block(-7,16,-5,biomesoplenty:dried_sand)
Block(-7,16,-4,biomesoplenty:dried_sand)
Block(-7,16,-3,biomesoplenty:dried_sand)
Block(-7,16,-2,biomesoplenty:dried_sand)
Block(-7,16,-1,biomesoplenty:dried_sand)
Block(-7,16,0,biomesoplenty:dried_sand)
Block(-7,16,1,biomesoplenty:dried_sand)
Block(-7,16,2,biomesoplenty:dried_sand)
Block(-7,16,3,biomesoplenty:dried_sand)
Block(-7,16,4,biomesoplenty:dried_sand)
Block(-7,16,5,biomesoplenty:dried_sand)
Block(-7,16,6,biomesoplenty:dried_sand)
Block(-7,16,7,biomesoplenty:dried_sand)
Block(-7,16,8,biomesoplenty:dried_sand)
Block(-7,17,-7,biomesoplenty:dried_sand)
Block(-7,17,-6,biomesoplenty:dried_sand)
Block(-7,17,-5,biomesoplenty:dried_sand)
Block(-7,17,-4,biomesoplenty:dried_sand)
Block(-7,17,-3,biomesoplenty:dried_sand)
Block(-7,17,-2,biomesoplenty:dried_sand)
Block(-7,17,-1,biomesoplenty:dried_sand)
Block(-7,17,0,biomesoplenty:dried_sand)
Block(-7,17,1,biomesoplenty:dried_sand)
Block(-7,17,2,biomesoplenty:dried_sand)
Block(-7,17,3,biomesoplenty:dried_sand)
Block(-7,17,4,biomesoplenty:dried_sand)
Block(-7,17,5,biomesoplenty:dried_sand)
Block(-7,17,6,biomesoplenty:dried_sand)
Block(-7,17,7,biomesoplenty:dried_sand)
Block(-7,17,8,biomesoplenty:dried_sand)
Block(-7,18,-7,biomesoplenty:dried_sand)
Block(-7,18,-6,biomesoplenty:dried_sand)
Block(-7,18,-5,biomesoplenty:dried_sand)
Block(-7,18,-4,biomesoplenty:dried_sand)
Block(-7,18,-3,biomesoplenty:dried_sand)
Block(-7,18,-2,biomesoplenty:dried_sand)
Block(-7,18,-1,biomesoplenty:dried_sand)
Block(-7,18,0,biomesoplenty:dried_sand)
Block(-7,18,1,biomesoplenty:dried_sand)
Block(-7,18,2,biomesoplenty:dried_sand)
Block(-7,18,3,biomesoplenty:dried_sand)
Block(-7,18,4,biomesoplenty:dried_sand)
Block(-7,18,5,biomesoplenty:dried_sand)
Block(-7,18,6,biomesoplenty:dried_sand)
Block(-7,18,7,biomesoplenty:dried_sand)
Block(-7,18,8,biomesoplenty:dried_sand)
Block(-7,19,-7,biomesoplenty:dried_sand)
Block(-7,19,-6,biomesoplenty:dried_sand)
Block(-7,19,-5,biomesoplenty:dried_sand)
Block(-7,19,-4,biomesoplenty:dried_sand)
Block(-7,19,-3,biomesoplenty:dried_sand)
Block(-7,19,-2,biomesoplenty:dried_sand)
Block(-7,19,-1,biomesoplenty:dried_sand)
Block(-7,19,0,biomesoplenty:dried_sand)
Block(-7,19,1,biomesoplenty:dried_sand)
Block(-7,19,2,biomesoplenty:dried_sand)
Block(-7,19,3,biomesoplenty:dried_sand)
Block(-7,19,4,biomesoplenty:dried_sand)
Block(-7,19,5,biomesoplenty:dried_sand)
Block(-7,19,6,biomesoplenty:dried_sand)
Block(-7,19,7,biomesoplenty:dried_sand)
Block(-7,19,8,biomesoplenty:dried_sand)
Block(-7,20,-7,biomesoplenty:dried_sand)
Block(-7,20,-6,biomesoplenty:dried_sand)
Block(-7,20,-5,biomesoplenty:dried_sand)
Block(-7,20,-4,biomesoplenty:dried_sand)
Block(-7,20,-3,biomesoplenty:dried_sand)
Block(-7,20,-2,biomesoplenty:dried_sand)
Block(-7,20,-1,biomesoplenty:dried_sand)
Block(-7,20,0,biomesoplenty:dried_sand)
Block(-7,20,1,biomesoplenty:dried_sand)
Block(-7,20,2,biomesoplenty:dried_sand)
Block(-7,20,3,biomesoplenty:dried_sand)
Block(-7,20,4,biomesoplenty:dried_sand)
Block(-7,20,5,biomesoplenty:dried_sand)
Block(-7,20,6,biomesoplenty:dried_sand)
Block(-7,20,7,biomesoplenty:dried_sand)
Block(-7,20,8,biomesoplenty:dried_sand)
Block(-7,21,-7,biomesoplenty:dried_sand)
Block(-7,21,-6,biomesoplenty:dried_sand)
Block(-7,21,-5,biomesoplenty:dried_sand)
Block(-7,21,-4,biomesoplenty:dried_sand)
Block(-7,21,-3,biomesoplenty:dried_sand)
Block(-7,21,-2,biomesoplenty:dried_sand)
Block(-7,21,-1,biomesoplenty:dried_sand)
Block(-7,21,0,biomesoplenty:dried_sand)
Block(-7,21,1,biomesoplenty:dried_sand)
Block(-7,21,2,biomesoplenty:dried_sand)
Block(-7,21,3,biomesoplenty:dried_sand)
Block(-7,21,4,biomesoplenty:dried_sand)
Block(-7,21,5,biomesoplenty:dried_sand)
Block(-7,21,6,biomesoplenty:dried_sand)
Block(-7,21,7,biomesoplenty:dried_sand)
Block(-7,21,8,biomesoplenty:dried_sand)
Block(-7,22,-7,biomesoplenty:dried_sand)
Block(-7,22,-6,biomesoplenty:dried_sand)
Block(-7,22,-5,biomesoplenty:dried_sand)
Block(-7,22,-4,biomesoplenty:dried_sand)
Block(-7,22,-3,biomesoplenty:dried_sand)
Block(-7,22,-2,biomesoplenty:dried_sand)
Block(-7,22,-1,biomesoplenty:dried_sand)
Block(-7,22,0,biomesoplenty:dried_sand)
Block(-7,22,1,biomesoplenty:dried_sand)
Block(-7,22,2,biomesoplenty:dried_sand)
Block(-7,22,3,biomesoplenty:dried_sand)
Block(-7,22,4,biomesoplenty:dried_sand)
Block(-7,22,5,biomesoplenty:dried_sand)
Block(-7,22,6,biomesoplenty:dried_sand)
Block(-7,22,7,biomesoplenty:dried_sand)
Block(-7,22,8,biomesoplenty:dried_sand)
Block(-7,23,-7,biomesoplenty:dried_sand)
Block(-7,23,-6,biomesoplenty:dried_sand)
Block(-7,23,-5,biomesoplenty:dried_sand)
Block(-7,23,-4,biomesoplenty:dried_sand)
Block(-7,23,-3,biomesoplenty:dried_sand)
Block(-7,23,-2,biomesoplenty:dried_sand)
Block(-7,23,-1,biomesoplenty:dried_sand)
Block(-7,23,0,biomesoplenty:dried_sand)
Block(-7,23,1,biomesoplenty:dried_sand)
Block(-7,23,2,biomesoplenty:dried_sand)
Block(-7,23,3,biomesoplenty:dried_sand)
Block(-7,23,4,biomesoplenty:dried_sand)
Block(-7,23,5,biomesoplenty:dried_sand)
Block(-7,23,6,biomesoplenty:dried_sand)
Block(-7,23,7,biomesoplenty:dried_sand)
Block(-7,23,8,biomesoplenty:dried_sand)
Block(-7,24,-7,biomesoplenty:dried_sand)
Block(-7,24,-6,biomesoplenty:dried_sand)
Block(-7,24,-5,biomesoplenty:dried_sand)
Block(-7,24,-4,biomesoplenty:dried_sand)
Block(-7,24,-3,biomesoplenty:dried_sand)
Block(-7,24,-2,biomesoplenty:dried_sand)
Block(-7,24,-1,biomesoplenty:dried_sand)
Block(-7,24,0,biomesoplenty:dried_sand)
Block(-7,24,1,biomesoplenty:dried_sand)
Block(-7,24,2,biomesoplenty:dried_sand)
Block(-7,24,3,biomesoplenty:dried_sand)
Block(-7,24,4,biomesoplenty:dried_sand)
Block(-7,24,5,biomesoplenty:dried_sand)
Block(-7,24,6,biomesoplenty:dried_sand)
Block(-7,24,7,biomesoplenty:dried_sand)
Block(-7,24,8,biomesoplenty:dried_sand)
Block(-7,25,-7,biomesoplenty:dried_sand)
Block(-7,25,-6,biomesoplenty:dried_sand)
Block(-7,25,-5,biomesoplenty:dried_sand)
Block(-7,25,-4,biomesoplenty:dried_sand)
Block(-7,25,-3,biomesoplenty:dried_sand)
Block(-7,25,-2,biomesoplenty:dried_sand)
Block(-7,25,-1,biomesoplenty:dried_sand)
Block(-7,25,0,biomesoplenty:dried_sand)
Block(-7,25,1,biomesoplenty:dried_sand)
Block(-7,25,2,biomesoplenty:dried_sand)
Block(-7,25,3,biomesoplenty:dried_sand)
Block(-7,25,4,biomesoplenty:dried_sand)
Block(-7,25,5,biomesoplenty:dried_sand)
Block(-7,25,6,biomesoplenty:dried_sand)
Block(-7,25,7,biomesoplenty:dried_sand)
Block(-7,25,8,biomesoplenty:dried_sand)
Block(-7,26,-7,biomesoplenty:dried_sand)
Block(-7,26,-6,biomesoplenty:dried_sand)
Block(-7,26,-5,biomesoplenty:dried_sand)
Block(-7,26,-4,biomesoplenty:dried_sand)
Block(-7,26,-3,biomesoplenty:dried_sand)
Block(-7,26,-2,biomesoplenty:dried_sand)
Block(-7,26,-1,biomesoplenty:dried_sand)
Block(-7,26,0,biomesoplenty:dried_sand)
Block(-7,26,1,biomesoplenty:dried_sand)
Block(-7,26,2,biomesoplenty:dried_sand)
Block(-7,26,3,biomesoplenty:dried_sand)
Block(-7,26,4,biomesoplenty:dried_sand)
Block(-7,26,5,biomesoplenty:dried_sand)
Block(-7,26,6,biomesoplenty:dried_sand)
Block(-7,26,7,biomesoplenty:dried_sand)
Block(-7,26,8,biomesoplenty:dried_sand)
Block(-7,27,-7,biomesoplenty:dried_sand)
Block(-7,27,-6,biomesoplenty:dried_sand)
Block(-7,27,-5,biomesoplenty:dried_sand)
Block(-7,27,-4,biomesoplenty:dried_sand)
Block(-7,27,-3,biomesoplenty:dried_sand)
Block(-7,27,-2,biomesoplenty:dried_sand)
Block(-7,27,-1,biomesoplenty:dried_sand)
Block(-7,27,0,biomesoplenty:dried_sand)
Block(-7,27,1,biomesoplenty:dried_sand)
Block(-7,27,2,biomesoplenty:dried_sand)
Block(-7,27,3,biomesoplenty:dried_sand)
Block(-7,27,4,biomesoplenty:dried_sand)
Block(-7,27,5,biomesoplenty:dried_sand)
Block(-7,27,6,biomesoplenty:dried_sand)
Block(-7,27,7,biomesoplenty:dried_sand)
Block(-7,27,8,biomesoplenty:dried_sand)
Block(-7,28,-7,biomesoplenty:dried_sand)
Block(-7,28,-6,biomesoplenty:dried_sand)
Block(-7,28,-5,biomesoplenty:dried_sand)
Block(-7,28,-4,biomesoplenty:dried_sand)
Block(-7,28,-3,biomesoplenty:dried_sand)
Block(-7,28,-2,biomesoplenty:dried_sand)
Block(-7,28,-1,biomesoplenty:dried_sand)
Block(-7,28,0,biomesoplenty:dried_sand)
Block(-7,28,1,biomesoplenty:dried_sand)
Block(-7,28,2,biomesoplenty:dried_sand)
Block(-7,28,3,biomesoplenty:dried_sand)
Block(-7,28,4,biomesoplenty:dried_sand)
Block(-7,28,5,biomesoplenty:dried_sand)
Block(-7,28,6,biomesoplenty:dried_sand)
Block(-7,28,7,biomesoplenty:dried_sand)
Block(-7,28,8,biomesoplenty:dried_sand)
Block(-7,29,-7,biomesoplenty:dried_sand)
Block(-7,29,-6,biomesoplenty:dried_sand)
Block(-7,29,-5,biomesoplenty:dried_sand)
Block(-7,29,-4,biomesoplenty:dried_sand)
Block(-7,29,-3,biomesoplenty:dried_sand)
Block(-7,29,-2,biomesoplenty:dried_sand)
Block(-7,29,-1,biomesoplenty:dried_sand)
Block(-7,29,0,biomesoplenty:dried_sand)
Block(-7,29,1,biomesoplenty:dried_sand)
Block(-7,29,2,biomesoplenty:dried_sand)
Block(-7,29,3,biomesoplenty:dried_sand)
Block(-7,29,4,biomesoplenty:dried_sand)
Block(-7,29,5,biomesoplenty:dried_sand)
Block(-7,29,6,biomesoplenty:dried_sand)
Block(-7,29,7,biomesoplenty:dried_sand)
Block(-7,29,8,biomesoplenty:dried_sand)
Block(-7,30,-7,biomesoplenty:dried_sand)
Block(-7,30,-6,biomesoplenty:dried_sand)
Block(-7,30,-5,biomesoplenty:dried_sand)
Block(-7,30,-4,biomesoplenty:dried_sand)
Block(-7,30,-3,biomesoplenty:dried_sand)
Block(-7,30,-2,biomesoplenty:dried_sand)
Block(-7,30,-1,biomesoplenty:dried_sand)
Block(-7,30,0,biomesoplenty:dried_sand)
Block(-7,30,1,biomesoplenty:dried_sand)
Block(-7,30,2,biomesoplenty:dried_sand)
Block(-7,30,3,biomesoplenty:dried_sand)
Block(-7,30,4,biomesoplenty:dried_sand)
Block(-7,30,5,biomesoplenty:dried_sand)
Block(-7,30,6,biomesoplenty:dried_sand)
Block(-7,30,7,biomesoplenty:dried_sand)
Block(-7,30,8,biomesoplenty:dried_sand)
Block(-7,31,-7,biomesoplenty:dried_sand)
Block(-7,31,-6,biomesoplenty:dried_sand)
Block(-7,31,-5,biomesoplenty:dried_sand)
Block(-7,31,-4,biomesoplenty:dried_sand)
Block(-7,31,-3,biomesoplenty:dried_sand)
Block(-7,31,-2,biomesoplenty:dried_sand)
Block(-7,31,-1,biomesoplenty:dried_sand)
Block(-7,31,0,biomesoplenty:dried_sand)
Block(-7,31,1,biomesoplenty:dried_sand)
Block(-7,31,2,biomesoplenty:dried_sand)
Block(-7,31,3,biomesoplenty:dried_sand)
Block(-7,31,4,biomesoplenty:dried_sand)
Block(-7,31,5,biomesoplenty:dried_sand)
Block(-7,31,6,biomesoplenty:dried_sand)
Block(-7,31,7,biomesoplenty:dried_sand)
Block(-7,31,8,biomesoplenty:dried_sand)
Block(-7,32,-7,biomesoplenty:dried_sand)
Block(-7,32,-6,biomesoplenty:dried_sand)
Block(-7,32,-5,biomesoplenty:dried_sand)
Block(-7,32,-4,biomesoplenty:dried_sand)
Block(-7,32,-3,biomesoplenty:dried_sand)
Block(-7,32,-2,biomesoplenty:dried_sand)
Block(-7,32,-1,biomesoplenty:dried_sand)
Block(-7,32,0,biomesoplenty:dried_sand)
Block(-7,32,1,biomesoplenty:dried_sand)
Block(-7,32,2,biomesoplenty:dried_sand)
Block(-7,32,3,biomesoplenty:dried_sand)
Block(-7,32,4,biomesoplenty:dried_sand)
Block(-7,32,5,biomesoplenty:dried_sand)
Block(-7,32,6,biomesoplenty:dried_sand)
Block(-7,32,7,biomesoplenty:dried_sand)
Block(-7,32,8,biomesoplenty:dried_sand)
Block(-7,33,-7,biomesoplenty:dried_sand)
Block(-7,33,-6,biomesoplenty:dried_sand)
Block(-7,33,-5,biomesoplenty:dried_sand)
Block(-7,33,-4,biomesoplenty:dried_sand)
Block(-7,33,-3,biomesoplenty:dried_sand)
Block(-7,33,-2,biomesoplenty:dried_sand)
Block(-7,33,-1,biomesoplenty:dried_sand)
Block(-7,33,0,biomesoplenty:dried_sand)
Block(-7,33,1,biomesoplenty:dried_sand)
Block(-7,33,2,biomesoplenty:dried_sand)
Block(-7,33,3,biomesoplenty:dried_sand)
Block(-7,33,4,biomesoplenty:dried_sand)
Block(-7,33,5,biomesoplenty:dried_sand)
Block(-7,33,6,biomesoplenty:dried_sand)
Block(-7,33,7,biomesoplenty:dried_sand)
Block(-7,33,8,biomesoplenty:dried_sand)
Block(-7,34,-7,biomesoplenty:dried_sand)
Block(-7,34,-6,biomesoplenty:dried_sand)
Block(-7,34,-5,biomesoplenty:dried_sand)
Block(-7,34,-4,biomesoplenty:dried_sand)
Block(-7,34,-3,biomesoplenty:dried_sand)
Block(-7,34,-2,biomesoplenty:dried_sand)
Block(-7,34,-1,biomesoplenty:dried_sand)
Block(-7,34,0,biomesoplenty:dried_sand)
Block(-7,34,1,biomesoplenty:dried_sand)
Block(-7,34,2,biomesoplenty:dried_sand)
Block(-7,34,3,biomesoplenty:dried_sand)
Block(-7,34,4,biomesoplenty:dried_sand)
Block(-7,34,5,biomesoplenty:dried_sand)
Block(-7,34,6,biomesoplenty:dried_sand)
Block(-7,34,7,biomesoplenty:dried_sand)
Block(-7,34,8,biomesoplenty:dried_sand)
Block(-7,35,-7,biomesoplenty:dried_sand)
Block(-7,35,-6,biomesoplenty:dried_sand)
Block(-7,35,-5,biomesoplenty:dried_sand)
Block(-7,35,-4,biomesoplenty:dried_sand)
Block(-7,35,-3,biomesoplenty:dried_sand)
Block(-7,35,-2,biomesoplenty:dried_sand)
Block(-7,35,-1,biomesoplenty:dried_sand)
Block(-7,35,0,biomesoplenty:dried_sand)
Block(-7,35,1,biomesoplenty:dried_sand)
Block(-7,35,2,biomesoplenty:dried_sand)
Block(-7,35,3,biomesoplenty:dried_sand)
Block(-7,35,4,biomesoplenty:dried_sand)
Block(-7,35,5,biomesoplenty:dried_sand)
Block(-7,35,6,biomesoplenty:dried_sand)
Block(-7,35,7,biomesoplenty:dried_sand)
Block(-7,35,8,biomesoplenty:dried_sand)
Block(-7,36,-7,biomesoplenty:dried_sand)
Block(-7,36,-6,biomesoplenty:dried_sand)
Block(-7,36,-5,biomesoplenty:dried_sand)
Block(-7,36,-4,biomesoplenty:dried_sand)
Block(-7,36,-3,biomesoplenty:dried_sand)
Block(-7,36,-2,biomesoplenty:dried_sand)
Block(-7,36,-1,biomesoplenty:dried_sand)
Block(-7,36,0,biomesoplenty:dried_sand)
Block(-7,36,1,biomesoplenty:dried_sand)
Block(-7,36,2,biomesoplenty:dried_sand)
Block(-7,36,3,biomesoplenty:dried_sand)
Block(-7,36,4,biomesoplenty:dried_sand)
Block(-7,36,5,biomesoplenty:dried_sand)
Block(-7,36,6,biomesoplenty:dried_sand)
Block(-7,36,7,biomesoplenty:dried_sand)
Block(-7,36,8,biomesoplenty:dried_sand)
Block(-7,37,-7,biomesoplenty:dried_sand)
Block(-7,37,-6,biomesoplenty:dried_sand)
Block(-7,37,-5,biomesoplenty:dried_sand)
Block(-7,37,-4,biomesoplenty:dried_sand)
Block(-7,37,-3,biomesoplenty:dried_sand)
Block(-7,37,-2,biomesoplenty:dried_sand)
Block(-7,37,-1,biomesoplenty:dried_sand)
Block(-7,37,0,biomesoplenty:dried_sand)
Block(-7,37,1,biomesoplenty:dried_sand)
Block(-7,37,2,biomesoplenty:dried_sand)
Block(-7,37,3,biomesoplenty:dried_sand)
Block(-7,37,4,biomesoplenty:dried_sand)
Block(-7,37,5,biomesoplenty:dried_sand)
Block(-7,37,6,biomesoplenty:dried_sand)
Block(-7,37,7,biomesoplenty:dried_sand)
Block(-7,37,8,biomesoplenty:dried_sand)
Block(-7,38,-7,biomesoplenty:dried_sand)
Block(-7,38,-6,biomesoplenty:dried_sand)
Block(-7,38,-5,biomesoplenty:dried_sand)
Block(-7,38,-4,biomesoplenty:dried_sand)
Block(-7,38,-3,biomesoplenty:dried_sand)
Block(-7,38,-2,biomesoplenty:dried_sand)
Block(-7,38,-1,biomesoplenty:dried_sand)
Block(-7,38,0,biomesoplenty:dried_sand)
Block(-7,38,1,biomesoplenty:dried_sand)
Block(-7,38,2,biomesoplenty:dried_sand)
Block(-7,38,3,biomesoplenty:dried_sand)
Block(-7,38,4,biomesoplenty:dried_sand)
Block(-7,38,5,biomesoplenty:dried_sand)
Block(-7,38,6,biomesoplenty:dried_sand)
Block(-7,38,7,biomesoplenty:dried_sand)
Block(-7,38,8,biomesoplenty:dried_sand)
Block(-7,39,-7,biomesoplenty:dried_sand)
Block(-7,39,-6,biomesoplenty:dried_sand)
Block(-7,39,-5,biomesoplenty:dried_sand)
Block(-7,39,-4,biomesoplenty:dried_sand)
Block(-7,39,-3,biomesoplenty:dried_sand)
Block(-7,39,-2,biomesoplenty:dried_sand)
Block(-7,39,-1,biomesoplenty:dried_sand)
Block(-7,39,0,biomesoplenty:dried_sand)
Block(-7,39,1,biomesoplenty:dried_sand)
Block(-7,39,2,biomesoplenty:dried_sand)
Block(-7,39,3,biomesoplenty:dried_sand)
Block(-7,39,4,biomesoplenty:dried_sand)
Block(-7,39,5,biomesoplenty:dried_sand)
Block(-7,39,6,biomesoplenty:dried_sand)
Block(-7,39,7,biomesoplenty:dried_sand)
Block(-7,39,8,biomesoplenty:dried_sand)
Block(-7,40,-7,biomesoplenty:dried_sand)
Block(-7,40,-6,biomesoplenty:dried_sand)
Block(-7,40,-5,biomesoplenty:dried_sand)
Block(-7,40,-4,biomesoplenty:dried_sand)
Block(-7,40,-3,biomesoplenty:dried_sand)
Block(-7,40,-2,biomesoplenty:dried_sand)
Block(-7,40,-1,biomesoplenty:dried_sand)
Block(-7,40,0,biomesoplenty:dried_sand)
Block(-7,40,1,biomesoplenty:dried_sand)
Block(-7,40,2,biomesoplenty:dried_sand)
Block(-7,40,3,biomesoplenty:dried_sand)
Block(-7,40,4,biomesoplenty:dried_sand)
Block(-7,40,5,biomesoplenty:dried_sand)
Block(-7,40,6,biomesoplenty:dried_sand)
Block(-7,40,7,biomesoplenty:dried_sand)
Block(-7,40,8,biomesoplenty:dried_sand)
Block(-7,41,-7,biomesoplenty:dried_sand)
Block(-7,41,-6,biomesoplenty:dried_sand)
Block(-7,41,-5,biomesoplenty:dried_sand)
Block(-7,41,-4,biomesoplenty:dried_sand)
Block(-7,41,-3,biomesoplenty:dried_sand)
Block(-7,41,-2,biomesoplenty:dried_sand)
Block(-7,41,-1,biomesoplenty:dried_sand)
Block(-7,41,0,biomesoplenty:dried_sand)
Block(-7,41,1,biomesoplenty:dried_sand)
Block(-7,41,2,biomesoplenty:dried_sand)
Block(-7,41,3,biomesoplenty:dried_sand)
Block(-7,41,4,biomesoplenty:dried_sand)
Block(-7,41,5,biomesoplenty:dried_sand)
Block(-7,41,6,biomesoplenty:dried_sand)
Block(-7,41,7,biomesoplenty:dried_sand)
Block(-7,41,8,biomesoplenty:dried_sand)
Block(-7,42,-7,biomesoplenty:dried_sand)
Block(-7,42,-6,biomesoplenty:dried_sand)
Block(-7,42,-5,biomesoplenty:dried_sand)
Block(-7,42,-4,biomesoplenty:dried_sand)
Block(-7,42,-3,biomesoplenty:dried_sand)
Block(-7,42,-2,biomesoplenty:dried_sand)
Block(-7,42,-1,biomesoplenty:dried_sand)
Block(-7,42,0,biomesoplenty:dried_sand)
Block(-7,42,1,biomesoplenty:dried_sand)
Block(-7,42,2,biomesoplenty:dried_sand)
Block(-7,42,3,biomesoplenty:dried_sand)
Block(-7,42,4,biomesoplenty:dried_sand)
Block(-7,42,5,biomesoplenty:dried_sand)
Block(-7,42,6,biomesoplenty:dried_sand)
Block(-7,42,7,biomesoplenty:dried_sand)
Block(-7,42,8,biomesoplenty:dried_sand)
Block(-7,43,-7,biomesoplenty:dried_sand)
Block(-7,43,-6,biomesoplenty:dried_sand)
Block(-7,43,-5,biomesoplenty:dried_sand)
Block(-7,43,-4,biomesoplenty:dried_sand)
Block(-7,43,-3,biomesoplenty:dried_sand)
Block(-7,43,-2,biomesoplenty:dried_sand)
Block(-7,43,-1,biomesoplenty:dried_sand)
Block(-7,43,0,biomesoplenty:dried_sand)
Block(-7,43,1,biomesoplenty:dried_sand)
Block(-7,43,2,biomesoplenty:dried_sand)
Block(-7,43,3,biomesoplenty:dried_sand)
Block(-7,43,4,biomesoplenty:dried_sand)
Block(-7,43,5,biomesoplenty:dried_sand)
Block(-7,43,6,biomesoplenty:dried_sand)
Block(-7,43,7,biomesoplenty:dried_sand)
Block(-7,43,8,biomesoplenty:dried_sand)
Block(-7,44,-7,biomesoplenty:dried_sand)
Block(-7,44,-6,biomesoplenty:dried_sand)
Block(-7,44,-5,biomesoplenty:dried_sand)
Block(-7,44,-4,biomesoplenty:dried_sand)
Block(-7,44,-3,biomesoplenty:dried_sand)
Block(-7,44,-2,biomesoplenty:dried_sand)
Block(-7,44,-1,biomesoplenty:dried_sand)
Block(-7,44,0,biomesoplenty:dried_sand)
Block(-7,44,1,biomesoplenty:dried_sand)
Block(-7,44,2,biomesoplenty:dried_sand)
Block(-7,44,3,biomesoplenty:dried_sand)
Block(-7,44,4,biomesoplenty:dried_sand)
Block(-7,44,5,biomesoplenty:dried_sand)
Block(-7,44,6,biomesoplenty:dried_sand)
Block(-7,44,7,biomesoplenty:dried_sand)
Block(-7,44,8,biomesoplenty:dried_sand)
Block(-7,45,-7,biomesoplenty:dried_sand)
Block(-7,45,-6,biomesoplenty:dried_sand)
Block(-7,45,-5,biomesoplenty:dried_sand)
Block(-7,45,-4,biomesoplenty:dried_sand)
Block(-7,45,-3,biomesoplenty:dried_sand)
Block(-7,45,-2,biomesoplenty:dried_sand)
Block(-7,45,-1,biomesoplenty:dried_sand)
Block(-7,45,0,biomesoplenty:dried_sand)
Block(-7,45,1,biomesoplenty:dried_sand)
Block(-7,45,2,biomesoplenty:dried_sand)
Block(-7,45,3,biomesoplenty:dried_sand)
Block(-7,45,4,biomesoplenty:dried_sand)
Block(-7,45,5,biomesoplenty:dried_sand)
Block(-7,45,6,biomesoplenty:dried_sand)
Block(-7,45,7,biomesoplenty:dried_sand)
Block(-7,45,8,biomesoplenty:dried_sand)
Block(-7,46,-7,biomesoplenty:dried_sand)
Block(-7,46,-6,biomesoplenty:dried_sand)
Block(-7,46,-5,biomesoplenty:dried_sand)
Block(-7,46,-4,biomesoplenty:dried_sand)
Block(-7,46,-3,biomesoplenty:dried_sand)
Block(-7,46,-2,biomesoplenty:dried_sand)
Block(-7,46,-1,biomesoplenty:dried_sand)
Block(-7,46,0,biomesoplenty:dried_sand)
Block(-7,46,1,biomesoplenty:dried_sand)
Block(-7,46,2,biomesoplenty:dried_sand)
Block(-7,46,3,biomesoplenty:dried_sand)
Block(-7,46,4,biomesoplenty:dried_sand)
Block(-7,46,5,biomesoplenty:dried_sand)
Block(-7,46,6,biomesoplenty:dried_sand)
Block(-7,46,7,biomesoplenty:dried_sand)
Block(-7,46,8,biomesoplenty:dried_sand)
Block(-7,47,-7,biomesoplenty:dried_sand)
Block(-7,47,-6,biomesoplenty:dried_sand)
Block(-7,47,-5,biomesoplenty:dried_sand)
Block(-7,47,-4,biomesoplenty:dried_sand)
Block(-7,47,-3,biomesoplenty:dried_sand)
Block(-7,47,-2,biomesoplenty:dried_sand)
Block(-7,47,-1,biomesoplenty:dried_sand)
Block(-7,47,0,biomesoplenty:dried_sand)
Block(-7,47,1,biomesoplenty:dried_sand)
Block(-7,47,2,biomesoplenty:dried_sand)
Block(-7,47,3,biomesoplenty:dried_sand)
Block(-7,47,4,biomesoplenty:dried_sand)
Block(-7,47,5,biomesoplenty:dried_sand)
Block(-7,47,6,biomesoplenty:dried_sand)
Block(-7,47,7,biomesoplenty:dried_sand)
Block(-7,47,8,biomesoplenty:dried_sand)
Block(-7,48,-7,biomesoplenty:dried_sand)
Block(-7,48,-6,biomesoplenty:dried_sand)
Block(-7,48,-5,biomesoplenty:dried_sand)
Block(-7,48,-4,biomesoplenty:dried_sand)
Block(-7,48,-3,biomesoplenty:dried_sand)
Block(-7,48,-2,biomesoplenty:dried_sand)
Block(-7,48,-1,biomesoplenty:dried_sand)
Block(-7,48,0,biomesoplenty:dried_sand)
Block(-7,48,1,biomesoplenty:dried_sand)
Block(-7,48,2,biomesoplenty:dried_sand)
Block(-7,48,3,biomesoplenty:dried_sand)
Block(-7,48,4,biomesoplenty:dried_sand)
Block(-7,48,5,biomesoplenty:dried_sand)
Block(-7,48,6,biomesoplenty:dried_sand)
Block(-7,48,7,biomesoplenty:dried_sand)
Block(-7,48,8,biomesoplenty:dried_sand)
Block(-7,49,-7,biomesoplenty:dried_sand)
Block(-7,49,-6,biomesoplenty:dried_sand)
Block(-7,49,-5,biomesoplenty:dried_sand)
Block(-7,49,-4,biomesoplenty:dried_sand)
Block(-7,49,-3,biomesoplenty:dried_sand)
Block(-7,49,-2,biomesoplenty:dried_sand)
Block(-7,49,-1,biomesoplenty:dried_sand)
Block(-7,49,0,biomesoplenty:dried_sand)
Block(-7,49,1,biomesoplenty:dried_sand)
Block(-7,49,2,biomesoplenty:dried_sand)
Block(-7,49,3,biomesoplenty:dried_sand)
Block(-7,49,4,biomesoplenty:dried_sand)
Block(-7,49,5,biomesoplenty:dried_sand)
Block(-7,49,6,biomesoplenty:dried_sand)
Block(-7,49,7,biomesoplenty:dried_sand)
Block(-7,49,8,biomesoplenty:dried_sand)
Block(-7,50,-7,biomesoplenty:dried_sand)
Block(-7,50,-6,biomesoplenty:dried_sand)
Block(-7,50,-5,biomesoplenty:dried_sand)
Block(-7,50,-4,biomesoplenty:dried_sand)
Block(-7,50,-3,biomesoplenty:dried_sand)
Block(-7,50,-2,biomesoplenty:dried_sand)
Block(-7,50,-1,biomesoplenty:dried_sand)
Block(-7,50,0,biomesoplenty:dried_sand)
Block(-7,50,1,biomesoplenty:dried_sand)
Block(-7,50,2,biomesoplenty:dried_sand)
Block(-7,50,3,biomesoplenty:dried_sand)
Block(-7,50,4,biomesoplenty:dried_sand)
Block(-7,50,5,biomesoplenty:dried_sand)
Block(-7,50,6,biomesoplenty:dried_sand)
Block(-7,50,7,biomesoplenty:dried_sand)
Block(-7,50,8,biomesoplenty:dried_sand)
Block(-7,51,-7,biomesoplenty:dried_sand)
Block(-7,51,-6,biomesoplenty:dried_sand)
Block(-7,51,-5,biomesoplenty:dried_sand)
Block(-7,51,-4,biomesoplenty:dried_sand)
Block(-7,51,-3,biomesoplenty:dried_sand)
Block(-7,51,-2,biomesoplenty:dried_sand)
Block(-7,51,-1,biomesoplenty:dried_sand)
Block(-7,51,0,biomesoplenty:dried_sand)
Block(-7,51,1,biomesoplenty:dried_sand)
Block(-7,51,2,biomesoplenty:dried_sand)
Block(-7,51,3,biomesoplenty:dried_sand)
Block(-7,51,4,biomesoplenty:dried_sand)
Block(-7,51,5,biomesoplenty:dried_sand)
Block(-7,51,6,biomesoplenty:dried_sand)
Block(-7,51,7,biomesoplenty:dried_sand)
Block(-7,51,8,biomesoplenty:dried_sand)
Block(-7,52,-7,biomesoplenty:dried_sand)
Block(-7,52,-6,biomesoplenty:dried_sand)
Block(-7,52,-5,biomesoplenty:dried_sand)
Block(-7,52,-4,biomesoplenty:dried_sand)
Block(-7,52,-3,biomesoplenty:dried_sand)
Block(-7,52,-2,biomesoplenty:dried_sand)
Block(-7,52,-1,biomesoplenty:dried_sand)
Block(-7,52,0,biomesoplenty:dried_sand)
Block(-7,52,1,biomesoplenty:dried_sand)
Block(-7,52,2,biomesoplenty:dried_sand)
Block(-7,52,3,biomesoplenty:dried_sand)
Block(-7,52,4,biomesoplenty:dried_sand)
Block(-7,52,5,biomesoplenty:dried_sand)
Block(-7,52,6,biomesoplenty:dried_sand)
Block(-7,52,7,biomesoplenty:dried_sand)
Block(-7,52,8,biomesoplenty:dried_sand)
Block(-7,53,-7,biomesoplenty:dried_sand)
Block(-7,53,-6,biomesoplenty:dried_sand)
Block(-7,53,-5,biomesoplenty:dried_sand)
Block(-7,53,-4,biomesoplenty:dried_sand)
Block(-7,53,-3,biomesoplenty:dried_sand)
Block(-7,53,-2,biomesoplenty:dried_sand)
Block(-7,53,-1,biomesoplenty:dried_sand)
Block(-7,53,0,biomesoplenty:dried_sand)
Block(-7,53,1,biomesoplenty:dried_sand)
Block(-7,53,2,biomesoplenty:dried_sand)
Block(-7,53,3,biomesoplenty:dried_sand)
Block(-7,53,4,biomesoplenty:dried_sand)
Block(-7,53,5,biomesoplenty:dried_sand)
Block(-7,53,6,biomesoplenty:dried_sand)
Block(-7,53,7,biomesoplenty:dried_sand)
Block(-7,53,8,biomesoplenty:dried_sand)
Block(-7,54,-7,biomesoplenty:dried_sand)
Block(-7,54,-6,biomesoplenty:dried_sand)
Block(-7,54,-5,biomesoplenty:dried_sand)
Block(-7,54,-4,biomesoplenty:dried_sand)
Block(-7,54,-3,biomesoplenty:dried_sand)
Block(-7,54,-2,biomesoplenty:dried_sand)
Block(-7,54,-1,biomesoplenty:dried_sand)
Block(-7,54,0,biomesoplenty:dried_sand)
Block(-7,54,1,biomesoplenty:dried_sand)
Block(-7,54,2,biomesoplenty:dried_sand)
Block(-7,54,3,biomesoplenty:dried_sand)
Block(-7,54,4,biomesoplenty:dried_sand)
Block(-7,54,5,biomesoplenty:dried_sand)
Block(-7,54,6,biomesoplenty:dried_sand)
Block(-7,54,7,biomesoplenty:dried_sand)
Block(-7,54,8,biomesoplenty:dried_sand)
Block(-7,55,-7,biomesoplenty:dried_sand)
Block(-7,55,-6,biomesoplenty:dried_sand)
Block(-7,55,-5,biomesoplenty:dried_sand)
Block(-7,55,-4,biomesoplenty:dried_sand)
Block(-7,55,-3,biomesoplenty:dried_sand)
Block(-7,55,-2,biomesoplenty:dried_sand)
Block(-7,55,-1,biomesoplenty:dried_sand)
Block(-7,55,0,biomesoplenty:dried_sand)
Block(-7,55,1,biomesoplenty:dried_sand)
Block(-7,55,2,biomesoplenty:dried_sand)
Block(-7,55,3,biomesoplenty:dried_sand)
Block(-7,55,4,biomesoplenty:dried_sand)
Block(-7,55,5,biomesoplenty:dried_sand)
Block(-7,55,6,biomesoplenty:dried_sand)
Block(-7,55,7,biomesoplenty:dried_sand)
Block(-7,55,8,biomesoplenty:dried_sand)
Block(-7,56,-7,biomesoplenty:dried_sand)
Block(-7,56,-6,biomesoplenty:dried_sand)
Block(-7,56,-5,biomesoplenty:dried_sand)
Block(-7,56,-4,biomesoplenty:dried_sand)
Block(-7,56,-3,biomesoplenty:dried_sand)
Block(-7,56,-2,biomesoplenty:dried_sand)
Block(-7,56,-1,biomesoplenty:dried_sand)
Block(-7,56,0,biomesoplenty:dried_sand)
Block(-7,56,1,biomesoplenty:dried_sand)
Block(-7,56,2,biomesoplenty:dried_sand)
Block(-7,56,3,biomesoplenty:dried_sand)
Block(-7,56,4,biomesoplenty:dried_sand)
Block(-7,56,5,biomesoplenty:dried_sand)
Block(-7,56,6,biomesoplenty:dried_sand)
Block(-7,56,7,biomesoplenty:dried_sand)
Block(-7,56,8,biomesoplenty:dried_sand)
Block(-7,57,-7,biomesoplenty:dried_sand)
Block(-7,57,-6,biomesoplenty:dried_sand)
Block(-7,57,-5,biomesoplenty:dried_sand)
Block(-7,57,-4,biomesoplenty:dried_sand)
Block(-7,57,-3,biomesoplenty:dried_sand)
Block(-7,57,-2,biomesoplenty:dried_sand)
Block(-7,57,-1,biomesoplenty:dried_sand)
Block(-7,57,0,biomesoplenty:dried_sand)
Block(-7,57,1,biomesoplenty:dried_sand)
Block(-7,57,2,biomesoplenty:dried_sand)
Block(-7,57,3,biomesoplenty:dried_sand)
Block(-7,57,4,biomesoplenty:dried_sand)
Block(-7,57,5,biomesoplenty:dried_sand)
Block(-7,57,6,biomesoplenty:dried_sand)
Block(-7,57,7,biomesoplenty:dried_sand)
Block(-7,57,8,biomesoplenty:dried_sand)
Block(-7,58,-7,biomesoplenty:dried_sand)
Block(-7,58,-6,biomesoplenty:dried_sand)
Block(-7,58,-5,biomesoplenty:dried_sand)
Block(-7,58,-4,biomesoplenty:dried_sand)
Block(-7,58,-3,biomesoplenty:dried_sand)
Block(-7,58,-2,biomesoplenty:dried_sand)
Block(-7,58,-1,biomesoplenty:dried_sand)
Block(-7,58,0,biomesoplenty:dried_sand)
Block(-7,58,1,biomesoplenty:dried_sand)
Block(-7,58,2,biomesoplenty:dried_sand)
Block(-7,58,3,biomesoplenty:dried_sand)
Block(-7,58,4,biomesoplenty:dried_sand)
Block(-7,58,5,biomesoplenty:dried_sand)
Block(-7,58,6,biomesoplenty:dried_sand)
Block(-7,58,7,biomesoplenty:dried_sand)
Block(-7,58,8,biomesoplenty:dried_sand)
Block(-7,59,-7,biomesoplenty:dried_sand)
Block(-7,59,-6,biomesoplenty:dried_sand)
Block(-7,59,-5,biomesoplenty:dried_sand)
Block(-7,59,-4,biomesoplenty:dried_sand)
Block(-7,59,-3,biomesoplenty:dried_sand)
Block(-7,59,-2,biomesoplenty:dried_sand)
Block(-7,59,-1,biomesoplenty:dried_sand)
Block(-7,59,0,biomesoplenty:dried_sand)
Block(-7,59,1,biomesoplenty:dried_sand)
Block(-7,59,2,biomesoplenty:dried_sand)
Block(-7,59,3,biomesoplenty:dried_sand)
Block(-7,59,4,biomesoplenty:dried_sand)
Block(-7,59,5,biomesoplenty:dried_sand)
Block(-7,59,6,biomesoplenty:dried_sand)
Block(-7,59,7,biomesoplenty:dried_sand)
Block(-7,59,8,biomesoplenty:dried_sand)
Block(-7,60,-7,biomesoplenty:dried_sand)
Block(-7,60,-6,biomesoplenty:dried_sand)
Block(-7,60,-5,biomesoplenty:dried_sand)
Block(-7,60,-4,biomesoplenty:dried_sand)
Block(-7,60,-3,biomesoplenty:dried_sand)
Block(-7,60,-2,biomesoplenty:dried_sand)
Block(-7,60,-1,biomesoplenty:dried_sand)
Block(-7,60,0,biomesoplenty:dried_sand)
Block(-7,60,1,biomesoplenty:dried_sand)
Block(-7,60,2,biomesoplenty:dried_sand)
Block(-7,60,3,biomesoplenty:dried_sand)
Block(-7,60,4,biomesoplenty:dried_sand)
Block(-7,60,5,biomesoplenty:dried_sand)
Block(-7,60,6,biomesoplenty:dried_sand)
Block(-7,60,7,biomesoplenty:dried_sand)
Block(-7,60,8,biomesoplenty:dried_sand)
RandomBlock(-7,61,-7,SMOOTH_BRICK:1,10,SMOOTH_BRICK:2,10,COBBLESTONE,10,MOSSY_COBBLESTONE,10,SMOOTH_BRICK,100)
Block(-7,61,-6,biomesoplenty:dried_sand)
Block(-7,61,-5,biomesoplenty:dried_sand)
Block(-7,61,-4,biomesoplenty:dried_sand)
Block(-7,61,-3,biomesoplenty:dried_sand)
Block(-7,61,-2,biomesoplenty:dried_sand)
Block(-7,61,-1,biomesoplenty:dried_sand)
Block(-7,61,0,biomesoplenty:dried_sand)
Block(-7,61,1,biomesoplenty:dried_sand)
Block(-7,61,2,biomesoplenty:dried_sand)
Block(-7,61,3,biomesoplenty:dried_sand)
Block(-7,61,4,biomesoplenty:dried_sand)
Block(-7,61,5,biomesoplenty:dried_sand)
Block(-7,61,6,biomesoplenty:dried_sand)
Block(-7,61,7,biomesoplenty:dried_sand)
Block(-7,61,8,biomesoplenty:dried_sand)
Block(-7,62,-5,biomesoplenty:dried_sand)
Block(-7,62,-4,biomesoplenty:dried_sand)
Block(-7,62,-3,biomesoplenty:dried_sand)
Block(-7,62,-2,biomesoplenty:dried_sand)
Block(-7,62,-1,biomesoplenty:dried_sand)
Block(-7,62,0,biomesoplenty:dried_sand)
Block(-7,62,1,biomesoplenty:dried_sand)
Block(-7,62,2,biomesoplenty:dried_sand)
Block(-7,62,3,biomesoplenty:dried_sand)
Block(-7,62,4,biomesoplenty:dried_sand)
Block(-7,62,5,biomesoplenty:dried_sand)
Block(-7,62,6,biomesoplenty:dried_sand)
Block(-7,62,7,biomesoplenty:dried_sand)
Block(-7,62,8,biomesoplenty:dried_sand)
Block(-7,63,-5,biomesoplenty:dried_sand)
Block(-7,63,-4,biomesoplenty:dried_sand)
Block(-7,63,-3,biomesoplenty:dried_sand)
Block(-7,63,-2,biomesoplenty:dried_sand)
Block(-7,63,-1,biomesoplenty:dried_sand)
Block(-7,63,0,biomesoplenty:dried_sand)
Block(-7,63,1,biomesoplenty:dried_sand)
Block(-7,63,2,biomesoplenty:dried_sand)
Block(-7,63,3,biomesoplenty:dried_sand)
Block(-7,63,4,biomesoplenty:dried_sand)
Block(-7,63,5,biomesoplenty:dried_sand)
Block(-7,63,6,biomesoplenty:dried_sand)
Block(-7,63,7,biomesoplenty:dried_sand)
Block(-7,63,8,biomesoplenty:dried_sand)
Block(-7,64,-5,biomesoplenty:dried_sand)
Block(-7,64,-4,biomesoplenty:dried_sand)
Block(-7,64,-3,biomesoplenty:dried_sand)
Block(-7,64,-2,biomesoplenty:dried_sand)
Block(-7,64,-1,biomesoplenty:dried_sand)
Block(-7,64,0,biomesoplenty:dried_sand)
Block(-7,64,1,biomesoplenty:dried_sand)
Block(-7,64,2,biomesoplenty:dried_sand)
Block(-7,64,3,biomesoplenty:dried_sand)
Block(-7,64,4,biomesoplenty:dried_sand)
Block(-7,64,5,biomesoplenty:dried_sand)
Block(-7,64,6,DOUBLE_STEP:5)
Block(-7,64,7,biomesoplenty:dried_sand)
Block(-7,64,8,biomesoplenty:dried_sand)
RandomBlock(-7,65,-7,SMOOTH_STAIRS:5,50,quark:stonebrick_mossy_stairs:5,100)
Block(-7,65,-6,biomesoplenty:dried_sand)
Block(-7,65,-5,biomesoplenty:dried_sand)
Block(-7,65,-4,biomesoplenty:dried_sand)
Block(-7,65,-3,biomesoplenty:dried_sand)
Block(-7,65,-2,biomesoplenty:dried_sand)
Block(-7,65,-1,biomesoplenty:dried_sand)
Block(-7,65,0,biomesoplenty:dried_sand)
Block(-7,65,1,biomesoplenty:dried_sand)
Block(-7,65,2,biomesoplenty:dried_sand)
Block(-7,65,3,biomesoplenty:dried_sand)
Block(-7,65,4,biomesoplenty:dried_sand)
Block(-7,65,5,biomesoplenty:dried_sand)
Block(-7,65,6,biomesoplenty:dried_sand)
Block(-7,65,7,biomesoplenty:dried_sand)
Block(-7,65,8,biomesoplenty:dried_sand)
Block(-7,66,-7,biomesoplenty:dried_sand)
Block(-7,66,-6,biomesoplenty:dried_sand)
Block(-7,66,-5,biomesoplenty:dried_sand)
Block(-7,66,-4,biomesoplenty:dried_sand)
Block(-7,66,-3,biomesoplenty:dried_sand)
Block(-7,66,-2,biomesoplenty:dried_sand)
Block(-7,66,-1,biomesoplenty:dried_sand)
Block(-7,66,0,biomesoplenty:dried_sand)
Block(-7,66,1,biomesoplenty:dried_sand)
Block(-7,66,2,biomesoplenty:dried_sand)
Block(-7,66,3,biomesoplenty:dried_sand)
Block(-7,66,4,biomesoplenty:dried_sand)
Block(-7,66,5,biomesoplenty:dried_sand)
Block(-7,66,6,biomesoplenty:dried_sand)
Block(-7,66,7,biomesoplenty:dried_sand)
Block(-7,67,-7,biomesoplenty:dried_sand)
Block(-7,67,-6,biomesoplenty:dried_sand)
Block(-7,67,-5,biomesoplenty:dried_sand)
Block(-7,67,-4,biomesoplenty:dried_sand)
Block(-7,67,-3,biomesoplenty:dried_sand)
Block(-7,67,-2,biomesoplenty:dried_sand)
Block(-7,67,-1,biomesoplenty:dried_sand)
Block(-7,67,0,biomesoplenty:dried_sand)
Block(-7,67,1,biomesoplenty:dried_sand)
Block(-7,67,2,biomesoplenty:dried_sand)
Block(-7,67,3,biomesoplenty:dried_sand)
Block(-7,67,4,biomesoplenty:dried_sand)
Block(-7,67,5,biomesoplenty:dried_sand)
Block(-7,67,7,biomesoplenty:dried_sand)
Block(-7,68,-7,biomesoplenty:dried_sand)
Block(-7,68,-6,biomesoplenty:dried_sand)
Block(-7,68,-5,biomesoplenty:dried_sand)
Block(-7,68,-4,biomesoplenty:dried_sand)
Block(-7,68,-3,biomesoplenty:dried_sand)
Block(-7,68,-2,biomesoplenty:dried_sand)
Block(-7,68,-1,biomesoplenty:dried_sand)
Block(-7,68,0,biomesoplenty:dried_sand)
Block(-7,68,1,biomesoplenty:dried_sand)
Block(-7,68,2,biomesoplenty:dried_sand)
Block(-7,68,3,biomesoplenty:dried_sand)
Block(-7,68,4,biomesoplenty:dried_sand)
Block(-7,68,7,biomesoplenty:dried_sand)
Block(-7,69,-7,biomesoplenty:dried_sand)
Block(-7,69,-6,biomesoplenty:dried_sand)
Block(-7,69,-5,biomesoplenty:dried_sand)
Block(-7,69,-4,biomesoplenty:dried_sand)
Block(-7,69,-3,biomesoplenty:dried_sand)
Block(-7,69,-2,biomesoplenty:dried_sand)
Block(-7,69,-1,biomesoplenty:dried_sand)
Block(-7,69,0,biomesoplenty:dried_sand)
Block(-7,69,1,biomesoplenty:dried_sand)
Block(-7,69,2,biomesoplenty:dried_sand)
Block(-7,69,3,biomesoplenty:dried_sand)
Block(-7,69,4,biomesoplenty:dried_sand)
Block(-7,70,-7,biomesoplenty:dried_sand)
Block(-7,70,-6,biomesoplenty:dried_sand)
Block(-7,70,-5,biomesoplenty:dried_sand)
Block(-7,70,-4,biomesoplenty:dried_sand)
Block(-7,70,-3,biomesoplenty:dried_sand)
Block(-7,70,-2,biomesoplenty:dried_sand)
Block(-7,70,-1,biomesoplenty:dried_sand)
Block(-7,70,0,biomesoplenty:dried_sand)
Block(-7,70,1,biomesoplenty:dried_sand)
Block(-7,70,2,biomesoplenty:dried_sand)
Block(-7,70,3,biomesoplenty:dried_sand)
Block(-7,71,-6,biomesoplenty:dried_sand)
Block(-7,71,-5,biomesoplenty:dried_sand)
Block(-7,71,-4,biomesoplenty:dried_sand)
Block(-7,71,-3,biomesoplenty:dried_sand)
Block(-7,71,-2,biomesoplenty:dried_sand)
Block(-7,71,-1,biomesoplenty:dried_sand)
Block(-7,71,0,biomesoplenty:dried_sand)
Block(-7,71,2,biomesoplenty:dried_sand)
Block(-7,71,3,biomesoplenty:dried_sand)
Block(-7,72,-5,biomesoplenty:dried_sand)
Block(-7,72,-4,biomesoplenty:dried_sand)
Block(-7,72,-3,biomesoplenty:dried_sand)
Block(-7,72,-2,biomesoplenty:dried_sand)
Block(-7,72,-1,biomesoplenty:dried_sand)
Block(-7,72,0,biomesoplenty:dried_sand)
Block(-7,73,-5,biomesoplenty:dried_sand)
Block(-7,73,-4,biomesoplenty:dried_sand)
Block(-7,73,-3,biomesoplenty:dried_sand)
Block(-7,73,-2,biomesoplenty:dried_sand)
Block(-7,73,-1,biomesoplenty:dried_sand)
RandomBlock(-7,73,0,SAND:0,50,biomesoplenty:dried_sand,100)
RandomBlock(-7,74,-2,SAND:0,50,biomesoplenty:dried_sand,100)
RandomBlock(-7,74,-1,SAND:0,50,biomesoplenty:dried_sand,100)
RandomBlock(-7,74,0,SAND:0,50,biomesoplenty:dried_sand,100)
Block(-6,0,-7,biomesoplenty:dried_sand)
Block(-6,0,-6,biomesoplenty:dried_sand)
Block(-6,0,-5,biomesoplenty:dried_sand)
Block(-6,0,-4,biomesoplenty:dried_sand)
Block(-6,0,-3,biomesoplenty:dried_sand)
Block(-6,0,-2,biomesoplenty:dried_sand)
Block(-6,0,-1,biomesoplenty:dried_sand)
Block(-6,0,0,biomesoplenty:dried_sand)
Block(-6,0,1,biomesoplenty:dried_sand)
Block(-6,0,2,biomesoplenty:dried_sand)
Block(-6,0,3,biomesoplenty:dried_sand)
Block(-6,0,4,biomesoplenty:dried_sand)
Block(-6,0,5,biomesoplenty:dried_sand)
Block(-6,0,6,biomesoplenty:dried_sand)
Block(-6,0,7,biomesoplenty:dried_sand)
Block(-6,0,8,biomesoplenty:dried_sand)
Block(-6,1,-7,biomesoplenty:dried_sand)
Block(-6,1,-6,biomesoplenty:dried_sand)
Block(-6,1,-5,biomesoplenty:dried_sand)
Block(-6,1,-4,biomesoplenty:dried_sand)
Block(-6,1,-3,biomesoplenty:dried_sand)
Block(-6,1,-2,biomesoplenty:dried_sand)
Block(-6,1,-1,biomesoplenty:dried_sand)
Block(-6,1,0,biomesoplenty:dried_sand)
Block(-6,1,1,biomesoplenty:dried_sand)
Block(-6,1,2,biomesoplenty:dried_sand)
Block(-6,1,3,biomesoplenty:dried_sand)
Block(-6,1,4,biomesoplenty:dried_sand)
Block(-6,1,5,biomesoplenty:dried_sand)
Block(-6,1,6,biomesoplenty:dried_sand)
Block(-6,1,7,biomesoplenty:dried_sand)
Block(-6,1,8,biomesoplenty:dried_sand)
Block(-6,2,-7,biomesoplenty:dried_sand)
Block(-6,2,-6,biomesoplenty:dried_sand)
Block(-6,2,-5,biomesoplenty:dried_sand)
Block(-6,2,-4,biomesoplenty:dried_sand)
Block(-6,2,-3,biomesoplenty:dried_sand)
Block(-6,2,-2,biomesoplenty:dried_sand)
Block(-6,2,-1,biomesoplenty:dried_sand)
Block(-6,2,0,biomesoplenty:dried_sand)
Block(-6,2,1,biomesoplenty:dried_sand)
Block(-6,2,2,biomesoplenty:dried_sand)
Block(-6,2,3,biomesoplenty:dried_sand)
Block(-6,2,4,biomesoplenty:dried_sand)
Block(-6,2,5,biomesoplenty:dried_sand)
Block(-6,2,6,biomesoplenty:dried_sand)
Block(-6,2,7,biomesoplenty:dried_sand)
Block(-6,2,8,biomesoplenty:dried_sand)
Block(-6,3,-7,biomesoplenty:dried_sand)
Block(-6,3,-6,biomesoplenty:dried_sand)
Block(-6,3,-5,biomesoplenty:dried_sand)
Block(-6,3,-4,biomesoplenty:dried_sand)
Block(-6,3,-3,biomesoplenty:dried_sand)
Block(-6,3,-2,biomesoplenty:dried_sand)
Block(-6,3,-1,biomesoplenty:dried_sand)
Block(-6,3,0,biomesoplenty:dried_sand)
Block(-6,3,1,biomesoplenty:dried_sand)
Block(-6,3,2,biomesoplenty:dried_sand)
Block(-6,3,3,biomesoplenty:dried_sand)
Block(-6,3,4,biomesoplenty:dried_sand)
Block(-6,3,5,biomesoplenty:dried_sand)
Block(-6,3,6,biomesoplenty:dried_sand)
Block(-6,3,7,biomesoplenty:dried_sand)
Block(-6,3,8,biomesoplenty:dried_sand)
Block(-6,4,-7,biomesoplenty:dried_sand)
Block(-6,4,-6,biomesoplenty:dried_sand)
Block(-6,4,-5,biomesoplenty:dried_sand)
Block(-6,4,-4,biomesoplenty:dried_sand)
Block(-6,4,-3,biomesoplenty:dried_sand)
Block(-6,4,-2,biomesoplenty:dried_sand)
Block(-6,4,-1,biomesoplenty:dried_sand)
Block(-6,4,0,biomesoplenty:dried_sand)
Block(-6,4,1,biomesoplenty:dried_sand)
Block(-6,4,2,biomesoplenty:dried_sand)
Block(-6,4,3,biomesoplenty:dried_sand)
Block(-6,4,4,biomesoplenty:dried_sand)
Block(-6,4,5,biomesoplenty:dried_sand)
Block(-6,4,6,biomesoplenty:dried_sand)
Block(-6,4,7,biomesoplenty:dried_sand)
Block(-6,4,8,biomesoplenty:dried_sand)
Block(-6,5,-7,biomesoplenty:dried_sand)
Block(-6,5,-6,biomesoplenty:dried_sand)
Block(-6,5,-5,biomesoplenty:dried_sand)
Block(-6,5,-4,biomesoplenty:dried_sand)
Block(-6,5,-3,biomesoplenty:dried_sand)
Block(-6,5,-2,biomesoplenty:dried_sand)
Block(-6,5,-1,biomesoplenty:dried_sand)
Block(-6,5,0,biomesoplenty:dried_sand)
Block(-6,5,1,biomesoplenty:dried_sand)
Block(-6,5,2,biomesoplenty:dried_sand)
Block(-6,5,3,biomesoplenty:dried_sand)
Block(-6,5,4,biomesoplenty:dried_sand)
Block(-6,5,5,biomesoplenty:dried_sand)
Block(-6,5,6,biomesoplenty:dried_sand)
Block(-6,5,7,biomesoplenty:dried_sand)
Block(-6,5,8,biomesoplenty:dried_sand)
Block(-6,6,-7,biomesoplenty:dried_sand)
Block(-6,6,-6,biomesoplenty:dried_sand)
Block(-6,6,-5,biomesoplenty:dried_sand)
Block(-6,6,-4,biomesoplenty:dried_sand)
Block(-6,6,-3,biomesoplenty:dried_sand)
Block(-6,6,-2,biomesoplenty:dried_sand)
Block(-6,6,-1,biomesoplenty:dried_sand)
Block(-6,6,0,biomesoplenty:dried_sand)
Block(-6,6,1,biomesoplenty:dried_sand)
Block(-6,6,2,biomesoplenty:dried_sand)
Block(-6,6,3,biomesoplenty:dried_sand)
Block(-6,6,4,biomesoplenty:dried_sand)
Block(-6,6,5,biomesoplenty:dried_sand)
Block(-6,6,6,biomesoplenty:dried_sand)
Block(-6,6,7,biomesoplenty:dried_sand)
Block(-6,6,8,biomesoplenty:dried_sand)
Block(-6,7,-7,biomesoplenty:dried_sand)
Block(-6,7,-6,biomesoplenty:dried_sand)
Block(-6,7,-5,biomesoplenty:dried_sand)
Block(-6,7,-4,biomesoplenty:dried_sand)
Block(-6,7,-3,biomesoplenty:dried_sand)
Block(-6,7,-2,biomesoplenty:dried_sand)
Block(-6,7,-1,biomesoplenty:dried_sand)
Block(-6,7,0,biomesoplenty:dried_sand)
Block(-6,7,1,biomesoplenty:dried_sand)
Block(-6,7,2,biomesoplenty:dried_sand)
Block(-6,7,3,biomesoplenty:dried_sand)
Block(-6,7,4,biomesoplenty:dried_sand)
Block(-6,7,5,biomesoplenty:dried_sand)
Block(-6,7,6,biomesoplenty:dried_sand)
Block(-6,7,7,biomesoplenty:dried_sand)
Block(-6,7,8,biomesoplenty:dried_sand)
Block(-6,8,-7,biomesoplenty:dried_sand)
Block(-6,8,-6,biomesoplenty:dried_sand)
Block(-6,8,-5,biomesoplenty:dried_sand)
Block(-6,8,-4,biomesoplenty:dried_sand)
Block(-6,8,-3,biomesoplenty:dried_sand)
Block(-6,8,-2,biomesoplenty:dried_sand)
Block(-6,8,-1,biomesoplenty:dried_sand)
Block(-6,8,0,biomesoplenty:dried_sand)
Block(-6,8,1,biomesoplenty:dried_sand)
Block(-6,8,2,biomesoplenty:dried_sand)
Block(-6,8,3,biomesoplenty:dried_sand)
Block(-6,8,4,biomesoplenty:dried_sand)
Block(-6,8,5,biomesoplenty:dried_sand)
Block(-6,8,6,biomesoplenty:dried_sand)
Block(-6,8,7,biomesoplenty:dried_sand)
Block(-6,8,8,biomesoplenty:dried_sand)
Block(-6,9,-7,biomesoplenty:dried_sand)
Block(-6,9,-6,biomesoplenty:dried_sand)
Block(-6,9,-5,biomesoplenty:dried_sand)
Block(-6,9,-4,biomesoplenty:dried_sand)
Block(-6,9,-3,biomesoplenty:dried_sand)
Block(-6,9,-2,biomesoplenty:dried_sand)
Block(-6,9,-1,biomesoplenty:dried_sand)
Block(-6,9,0,biomesoplenty:dried_sand)
Block(-6,9,1,biomesoplenty:dried_sand)
Block(-6,9,2,biomesoplenty:dried_sand)
Block(-6,9,3,biomesoplenty:dried_sand)
Block(-6,9,4,biomesoplenty:dried_sand)
Block(-6,9,5,biomesoplenty:dried_sand)
Block(-6,9,6,biomesoplenty:dried_sand)
Block(-6,9,7,biomesoplenty:dried_sand)
Block(-6,9,8,biomesoplenty:dried_sand)
Block(-6,10,-7,biomesoplenty:dried_sand)
Block(-6,10,-6,biomesoplenty:dried_sand)
Block(-6,10,-5,biomesoplenty:dried_sand)
Block(-6,10,-4,biomesoplenty:dried_sand)
Block(-6,10,-3,biomesoplenty:dried_sand)
Block(-6,10,-2,biomesoplenty:dried_sand)
Block(-6,10,-1,biomesoplenty:dried_sand)
Block(-6,10,0,biomesoplenty:dried_sand)
Block(-6,10,1,biomesoplenty:dried_sand)
Block(-6,10,2,biomesoplenty:dried_sand)
Block(-6,10,3,biomesoplenty:dried_sand)
Block(-6,10,4,biomesoplenty:dried_sand)
Block(-6,10,5,biomesoplenty:dried_sand)
Block(-6,10,6,biomesoplenty:dried_sand)
Block(-6,10,7,biomesoplenty:dried_sand)
Block(-6,10,8,biomesoplenty:dried_sand)
Block(-6,11,-7,biomesoplenty:dried_sand)
Block(-6,11,-6,biomesoplenty:dried_sand)
Block(-6,11,-5,biomesoplenty:dried_sand)
Block(-6,11,-4,biomesoplenty:dried_sand)
Block(-6,11,-3,biomesoplenty:dried_sand)
Block(-6,11,-2,biomesoplenty:dried_sand)
Block(-6,11,-1,biomesoplenty:dried_sand)
Block(-6,11,0,biomesoplenty:dried_sand)
Block(-6,11,1,biomesoplenty:dried_sand)
Block(-6,11,2,biomesoplenty:dried_sand)
Block(-6,11,3,biomesoplenty:dried_sand)
Block(-6,11,4,biomesoplenty:dried_sand)
Block(-6,11,5,biomesoplenty:dried_sand)
Block(-6,11,6,biomesoplenty:dried_sand)
Block(-6,11,7,biomesoplenty:dried_sand)
Block(-6,11,8,biomesoplenty:dried_sand)
Block(-6,12,-7,biomesoplenty:dried_sand)
Block(-6,12,-6,biomesoplenty:dried_sand)
Block(-6,12,-5,biomesoplenty:dried_sand)
Block(-6,12,-4,biomesoplenty:dried_sand)
Block(-6,12,-3,biomesoplenty:dried_sand)
Block(-6,12,-2,biomesoplenty:dried_sand)
Block(-6,12,-1,biomesoplenty:dried_sand)
Block(-6,12,0,biomesoplenty:dried_sand)
Block(-6,12,1,biomesoplenty:dried_sand)
Block(-6,12,2,biomesoplenty:dried_sand)
Block(-6,12,3,biomesoplenty:dried_sand)
Block(-6,12,4,biomesoplenty:dried_sand)
Block(-6,12,5,biomesoplenty:dried_sand)
Block(-6,12,6,biomesoplenty:dried_sand)
Block(-6,12,7,biomesoplenty:dried_sand)
Block(-6,12,8,biomesoplenty:dried_sand)
Block(-6,13,-7,biomesoplenty:dried_sand)
Block(-6,13,-6,biomesoplenty:dried_sand)
Block(-6,13,-5,biomesoplenty:dried_sand)
Block(-6,13,-4,biomesoplenty:dried_sand)
Block(-6,13,-3,biomesoplenty:dried_sand)
Block(-6,13,-2,biomesoplenty:dried_sand)
Block(-6,13,-1,biomesoplenty:dried_sand)
Block(-6,13,0,biomesoplenty:dried_sand)
Block(-6,13,1,biomesoplenty:dried_sand)
Block(-6,13,2,biomesoplenty:dried_sand)
Block(-6,13,3,biomesoplenty:dried_sand)
Block(-6,13,4,biomesoplenty:dried_sand)
Block(-6,13,5,biomesoplenty:dried_sand)
Block(-6,13,6,biomesoplenty:dried_sand)
Block(-6,13,7,biomesoplenty:dried_sand)
Block(-6,13,8,biomesoplenty:dried_sand)
Block(-6,14,-7,biomesoplenty:dried_sand)
Block(-6,14,-6,biomesoplenty:dried_sand)
Block(-6,14,-5,biomesoplenty:dried_sand)
Block(-6,14,-4,biomesoplenty:dried_sand)
Block(-6,14,-3,biomesoplenty:dried_sand)
Block(-6,14,-2,biomesoplenty:dried_sand)
Block(-6,14,-1,biomesoplenty:dried_sand)
Block(-6,14,0,biomesoplenty:dried_sand)
Block(-6,14,1,biomesoplenty:dried_sand)
Block(-6,14,2,biomesoplenty:dried_sand)
Block(-6,14,3,biomesoplenty:dried_sand)
Block(-6,14,4,biomesoplenty:dried_sand)
Block(-6,14,5,biomesoplenty:dried_sand)
Block(-6,14,6,biomesoplenty:dried_sand)
Block(-6,14,7,biomesoplenty:dried_sand)
Block(-6,14,8,biomesoplenty:dried_sand)
Block(-6,15,-7,biomesoplenty:dried_sand)
Block(-6,15,-6,biomesoplenty:dried_sand)
Block(-6,15,-5,biomesoplenty:dried_sand)
Block(-6,15,-4,biomesoplenty:dried_sand)
Block(-6,15,-3,biomesoplenty:dried_sand)
Block(-6,15,-2,biomesoplenty:dried_sand)
Block(-6,15,-1,biomesoplenty:dried_sand)
Block(-6,15,0,biomesoplenty:dried_sand)
Block(-6,15,1,biomesoplenty:dried_sand)
Block(-6,15,2,biomesoplenty:dried_sand)
Block(-6,15,3,biomesoplenty:dried_sand)
Block(-6,15,4,biomesoplenty:dried_sand)
Block(-6,15,5,biomesoplenty:dried_sand)
Block(-6,15,6,biomesoplenty:dried_sand)
Block(-6,15,7,biomesoplenty:dried_sand)
Block(-6,15,8,biomesoplenty:dried_sand)
Block(-6,16,-7,biomesoplenty:dried_sand)
Block(-6,16,-6,biomesoplenty:dried_sand)
Block(-6,16,-5,biomesoplenty:dried_sand)
Block(-6,16,-4,biomesoplenty:dried_sand)
Block(-6,16,-3,biomesoplenty:dried_sand)
Block(-6,16,-2,biomesoplenty:dried_sand)
Block(-6,16,-1,biomesoplenty:dried_sand)
Block(-6,16,0,biomesoplenty:dried_sand)
Block(-6,16,1,biomesoplenty:dried_sand)
Block(-6,16,2,biomesoplenty:dried_sand)
Block(-6,16,3,biomesoplenty:dried_sand)
Block(-6,16,4,biomesoplenty:dried_sand)
Block(-6,16,5,biomesoplenty:dried_sand)
Block(-6,16,6,biomesoplenty:dried_sand)
Block(-6,16,7,biomesoplenty:dried_sand)
Block(-6,16,8,biomesoplenty:dried_sand)
Block(-6,17,-7,biomesoplenty:dried_sand)
Block(-6,17,-6,biomesoplenty:dried_sand)
Block(-6,17,-5,biomesoplenty:dried_sand)
Block(-6,17,-4,biomesoplenty:dried_sand)
Block(-6,17,-3,biomesoplenty:dried_sand)
Block(-6,17,-2,biomesoplenty:dried_sand)
Block(-6,17,-1,biomesoplenty:dried_sand)
Block(-6,17,0,biomesoplenty:dried_sand)
Block(-6,17,1,biomesoplenty:dried_sand)
Block(-6,17,2,biomesoplenty:dried_sand)
Block(-6,17,3,biomesoplenty:dried_sand)
Block(-6,17,4,biomesoplenty:dried_sand)
Block(-6,17,5,biomesoplenty:dried_sand)
Block(-6,17,6,biomesoplenty:dried_sand)
Block(-6,17,7,biomesoplenty:dried_sand)
Block(-6,17,8,biomesoplenty:dried_sand)
Block(-6,18,-7,biomesoplenty:dried_sand)
Block(-6,18,-6,biomesoplenty:dried_sand)
Block(-6,18,-5,biomesoplenty:dried_sand)
Block(-6,18,-4,biomesoplenty:dried_sand)
Block(-6,18,-3,biomesoplenty:dried_sand)
Block(-6,18,-2,biomesoplenty:dried_sand)
Block(-6,18,-1,biomesoplenty:dried_sand)
Block(-6,18,0,biomesoplenty:dried_sand)
Block(-6,18,1,biomesoplenty:dried_sand)
Block(-6,18,2,biomesoplenty:dried_sand)
Block(-6,18,3,biomesoplenty:dried_sand)
Block(-6,18,4,biomesoplenty:dried_sand)
Block(-6,18,5,biomesoplenty:dried_sand)
Block(-6,18,6,biomesoplenty:dried_sand)
Block(-6,18,7,biomesoplenty:dried_sand)
Block(-6,18,8,biomesoplenty:dried_sand)
Block(-6,19,-7,biomesoplenty:dried_sand)
Block(-6,19,-6,biomesoplenty:dried_sand)
Block(-6,19,-5,biomesoplenty:dried_sand)
Block(-6,19,-4,biomesoplenty:dried_sand)
Block(-6,19,-3,biomesoplenty:dried_sand)
Block(-6,19,-2,biomesoplenty:dried_sand)
Block(-6,19,-1,biomesoplenty:dried_sand)
Block(-6,19,0,biomesoplenty:dried_sand)
Block(-6,19,1,biomesoplenty:dried_sand)
Block(-6,19,2,biomesoplenty:dried_sand)
Block(-6,19,3,biomesoplenty:dried_sand)
Block(-6,19,4,biomesoplenty:dried_sand)
Block(-6,19,5,biomesoplenty:dried_sand)
Block(-6,19,6,biomesoplenty:dried_sand)
Block(-6,19,7,biomesoplenty:dried_sand)
Block(-6,19,8,biomesoplenty:dried_sand)
Block(-6,20,-7,biomesoplenty:dried_sand)
Block(-6,20,-6,biomesoplenty:dried_sand)
Block(-6,20,-5,biomesoplenty:dried_sand)
Block(-6,20,-4,biomesoplenty:dried_sand)
Block(-6,20,-3,biomesoplenty:dried_sand)
Block(-6,20,-2,biomesoplenty:dried_sand)
Block(-6,20,-1,biomesoplenty:dried_sand)
Block(-6,20,0,biomesoplenty:dried_sand)
Block(-6,20,1,biomesoplenty:dried_sand)
Block(-6,20,2,biomesoplenty:dried_sand)
Block(-6,20,3,biomesoplenty:dried_sand)
Block(-6,20,4,biomesoplenty:dried_sand)
Block(-6,20,5,biomesoplenty:dried_sand)
Block(-6,20,6,biomesoplenty:dried_sand)
Block(-6,20,7,biomesoplenty:dried_sand)
Block(-6,20,8,biomesoplenty:dried_sand)
Block(-6,21,-7,biomesoplenty:dried_sand)
Block(-6,21,-6,biomesoplenty:dried_sand)
Block(-6,21,-5,biomesoplenty:dried_sand)
Block(-6,21,-4,biomesoplenty:dried_sand)
Block(-6,21,-3,biomesoplenty:dried_sand)
Block(-6,21,-2,biomesoplenty:dried_sand)
Block(-6,21,-1,biomesoplenty:dried_sand)
Block(-6,21,0,biomesoplenty:dried_sand)
Block(-6,21,1,biomesoplenty:dried_sand)
Block(-6,21,2,biomesoplenty:dried_sand)
Block(-6,21,3,biomesoplenty:dried_sand)
Block(-6,21,4,biomesoplenty:dried_sand)
Block(-6,21,5,biomesoplenty:dried_sand)
Block(-6,21,6,biomesoplenty:dried_sand)
Block(-6,21,7,biomesoplenty:dried_sand)
Block(-6,21,8,biomesoplenty:dried_sand)
Block(-6,22,-7,biomesoplenty:dried_sand)
Block(-6,22,-6,biomesoplenty:dried_sand)
Block(-6,22,-5,biomesoplenty:dried_sand)
Block(-6,22,-4,biomesoplenty:dried_sand)
Block(-6,22,-3,biomesoplenty:dried_sand)
Block(-6,22,-2,biomesoplenty:dried_sand)
Block(-6,22,-1,biomesoplenty:dried_sand)
Block(-6,22,0,biomesoplenty:dried_sand)
Block(-6,22,1,biomesoplenty:dried_sand)
Block(-6,22,2,biomesoplenty:dried_sand)
Block(-6,22,3,biomesoplenty:dried_sand)
Block(-6,22,4,biomesoplenty:dried_sand)
Block(-6,22,5,biomesoplenty:dried_sand)
Block(-6,22,6,biomesoplenty:dried_sand)
Block(-6,22,7,biomesoplenty:dried_sand)
Block(-6,22,8,biomesoplenty:dried_sand)
Block(-6,23,-7,biomesoplenty:dried_sand)
Block(-6,23,-6,biomesoplenty:dried_sand)
Block(-6,23,-5,biomesoplenty:dried_sand)
Block(-6,23,-4,biomesoplenty:dried_sand)
Block(-6,23,-3,biomesoplenty:dried_sand)
Block(-6,23,-2,biomesoplenty:dried_sand)
Block(-6,23,-1,biomesoplenty:dried_sand)
Block(-6,23,0,biomesoplenty:dried_sand)
Block(-6,23,1,biomesoplenty:dried_sand)
Block(-6,23,2,biomesoplenty:dried_sand)
Block(-6,23,3,biomesoplenty:dried_sand)
Block(-6,23,4,biomesoplenty:dried_sand)
Block(-6,23,5,biomesoplenty:dried_sand)
Block(-6,23,6,biomesoplenty:dried_sand)
Block(-6,23,7,biomesoplenty:dried_sand)
Block(-6,23,8,biomesoplenty:dried_sand)
Block(-6,24,-7,biomesoplenty:dried_sand)
Block(-6,24,-6,biomesoplenty:dried_sand)
Block(-6,24,-5,biomesoplenty:dried_sand)
Block(-6,24,-4,biomesoplenty:dried_sand)
Block(-6,24,-3,biomesoplenty:dried_sand)
Block(-6,24,-2,biomesoplenty:dried_sand)
Block(-6,24,-1,biomesoplenty:dried_sand)
Block(-6,24,0,biomesoplenty:dried_sand)
Block(-6,24,1,biomesoplenty:dried_sand)
Block(-6,24,2,biomesoplenty:dried_sand)
Block(-6,24,3,biomesoplenty:dried_sand)
Block(-6,24,4,biomesoplenty:dried_sand)
Block(-6,24,5,biomesoplenty:dried_sand)
Block(-6,24,6,biomesoplenty:dried_sand)
Block(-6,24,7,biomesoplenty:dried_sand)
Block(-6,24,8,biomesoplenty:dried_sand)
Block(-6,25,-7,biomesoplenty:dried_sand)
Block(-6,25,-6,biomesoplenty:dried_sand)
Block(-6,25,-5,biomesoplenty:dried_sand)
Block(-6,25,-4,biomesoplenty:dried_sand)
Block(-6,25,-3,biomesoplenty:dried_sand)
Block(-6,25,-2,biomesoplenty:dried_sand)
Block(-6,25,-1,biomesoplenty:dried_sand)
Block(-6,25,0,biomesoplenty:dried_sand)
Block(-6,25,1,biomesoplenty:dried_sand)
Block(-6,25,2,biomesoplenty:dried_sand)
Block(-6,25,3,biomesoplenty:dried_sand)
Block(-6,25,4,biomesoplenty:dried_sand)
Block(-6,25,5,biomesoplenty:dried_sand)
Block(-6,25,6,biomesoplenty:dried_sand)
Block(-6,25,7,biomesoplenty:dried_sand)
Block(-6,25,8,biomesoplenty:dried_sand)
Block(-6,26,-7,biomesoplenty:dried_sand)
Block(-6,26,-6,biomesoplenty:dried_sand)
Block(-6,26,-5,biomesoplenty:dried_sand)
Block(-6,26,-4,biomesoplenty:dried_sand)
Block(-6,26,-3,biomesoplenty:dried_sand)
Block(-6,26,-2,biomesoplenty:dried_sand)
Block(-6,26,-1,biomesoplenty:dried_sand)
Block(-6,26,0,biomesoplenty:dried_sand)
Block(-6,26,1,biomesoplenty:dried_sand)
