
#######################################################################
# +-----------------------------------------------------------------+ #
# |                            BO4 object                           | #
# +-----------------------------------------------------------------+ #
#######################################################################

Author: NLBlackEagle

Description: No description given

SettingsMode: WriteDisable


#######################################################################
# +-----------------------------------------------------------------+ #
# |                          Main settings                          | #
# +-----------------------------------------------------------------+ #
#######################################################################

Frequency: 0

SpawnHeight: highestBlock

UseCenterForHighestBlock: true

##############################
# Height Limits for the BO4. #
##############################

MinHeight: 0

MaxHeight: 255

InheritBO3: 

InheritBO3Rotation: NORTH

OverrideChildSettings: true

OverrideParentHeight: false

CanOverride: true

BranchFrequency: 0

BranchFrequencyGroup: 

MustBeBelowOther: false

MustBeInside: 

CannotBeInside: 

ReplacesBO3: 

MustBeInsideWorldBorders: false

CanSpawnOnWater: true

SpawnOnWaterOnly: false

SpawnUnderWater: false

SpawnAtWaterLevel: false

HeightOffset: 0

RemoveAir: true

ReplaceAbove: 

ReplaceBelow: 

ReplaceWithBiomeBlocks: true

ReplaceWithSurfaceBlock: GRASS

ReplaceWithGroundBlock: DIRT

ReplaceWithStoneBlock: STONE

SmoothRadius: 0

SmoothHeightOffset: 0

SmoothStartTop: false

SmoothStartWood: false

SmoothingSurfaceBlock: 

SmoothingGroundBlock: 

BO3Group: 

IsSpawnPoint: false

DoReplaceBlocks: true


#######################################################################
# +-----------------------------------------------------------------+ #
# |                              Blocks                             | #
# +-----------------------------------------------------------------+ #
#######################################################################

Block(-8,0,-7,OBSIDIAN)
Block(-8,0,-6,OBSIDIAN)
Block(-8,0,-5,OBSIDIAN)
Block(-8,0,-4,OBSIDIAN)
Block(-8,0,-3,OBSIDIAN)
Block(-8,0,-2,OBSIDIAN)
Block(-8,0,-1,OBSIDIAN)
Block(-8,0,0,OBSIDIAN)
Block(-8,0,1,OBSIDIAN)
Block(-8,0,2,OBSIDIAN)
Block(-8,1,-7,OBSIDIAN)
Block(-8,1,-6,OBSIDIAN)
Block(-8,1,-5,OBSIDIAN)
Block(-8,1,-4,OBSIDIAN)
Block(-8,1,-3,OBSIDIAN)
Block(-8,1,-2,OBSIDIAN)
Block(-8,1,-1,OBSIDIAN)
Block(-8,1,0,OBSIDIAN)
Block(-8,1,1,OBSIDIAN)
Block(-8,2,-7,OBSIDIAN)
Block(-8,2,-6,OBSIDIAN)
Block(-8,2,-5,OBSIDIAN)
Block(-8,2,-4,OBSIDIAN)
Block(-8,2,-3,OBSIDIAN)
Block(-8,2,-2,OBSIDIAN)
Block(-8,2,-1,OBSIDIAN)
Block(-8,2,0,OBSIDIAN)
Block(-8,3,-7,OBSIDIAN)
Block(-8,3,-6,OBSIDIAN)
Block(-8,3,-5,OBSIDIAN)
Block(-8,3,-4,OBSIDIAN)
Block(-8,3,-3,OBSIDIAN)
Block(-8,3,-2,OBSIDIAN)
Block(-8,3,-1,OBSIDIAN)
Block(-8,4,-7,OBSIDIAN)
Block(-8,4,-6,OBSIDIAN)
Block(-8,4,-5,OBSIDIAN)
Block(-8,4,-4,OBSIDIAN)
Block(-8,4,-3,OBSIDIAN)
Block(-8,4,-2,OBSIDIAN)
Block(-8,5,-7,OBSIDIAN)
Block(-8,5,-6,OBSIDIAN)
Block(-8,5,-5,OBSIDIAN)
Block(-8,5,-4,OBSIDIAN)
Block(-8,5,-3,OBSIDIAN)
Block(-8,6,-7,OBSIDIAN)
Block(-8,6,-6,OBSIDIAN)
Block(-8,6,-5,OBSIDIAN)
Block(-8,6,-4,OBSIDIAN)
Block(-8,7,-7,OBSIDIAN)
Block(-8,7,-6,OBSIDIAN)
Block(-8,7,-5,OBSIDIAN)
Block(-8,8,-7,OBSIDIAN)
Block(-8,8,-6,OBSIDIAN)
Block(-8,9,-7,OBSIDIAN)
Block(-7,0,-7,OBSIDIAN)
Block(-7,0,-6,OBSIDIAN)
Block(-7,0,-5,OBSIDIAN)
Block(-7,0,-4,OBSIDIAN)
Block(-7,0,-3,OBSIDIAN)
Block(-7,0,-2,OBSIDIAN)
Block(-7,0,-1,OBSIDIAN)
Block(-7,0,0,OBSIDIAN)
Block(-7,0,1,OBSIDIAN)
Block(-7,0,2,OBSIDIAN)
Block(-7,1,-7,OBSIDIAN)
Block(-7,1,-6,OBSIDIAN)
Block(-7,1,-5,OBSIDIAN)
Block(-7,1,-4,OBSIDIAN)
Block(-7,1,-3,OBSIDIAN)
Block(-7,1,-2,OBSIDIAN)
Block(-7,1,-1,OBSIDIAN)
Block(-7,1,0,OBSIDIAN)
Block(-7,1,1,OBSIDIAN)
Block(-7,2,-7,OBSIDIAN)
Block(-7,2,-6,OBSIDIAN)
Block(-7,2,-5,OBSIDIAN)
Block(-7,2,-4,OBSIDIAN)
Block(-7,2,-3,OBSIDIAN)
Block(-7,2,-2,OBSIDIAN)
Block(-7,2,-1,OBSIDIAN)
Block(-7,2,0,OBSIDIAN)
Block(-7,3,-7,OBSIDIAN)
Block(-7,3,-6,OBSIDIAN)
Block(-7,3,-5,OBSIDIAN)
Block(-7,3,-4,OBSIDIAN)
Block(-7,3,-3,OBSIDIAN)
Block(-7,3,-2,OBSIDIAN)
Block(-7,3,-1,OBSIDIAN)
Block(-7,4,-7,OBSIDIAN)
Block(-7,4,-6,OBSIDIAN)
Block(-7,4,-5,OBSIDIAN)
Block(-7,4,-4,OBSIDIAN)
Block(-7,4,-3,OBSIDIAN)
Block(-7,4,-2,OBSIDIAN)
Block(-7,5,-7,OBSIDIAN)
Block(-7,5,-6,OBSIDIAN)
Block(-7,5,-5,OBSIDIAN)
Block(-7,5,-4,OBSIDIAN)
Block(-7,5,-3,OBSIDIAN)
Block(-7,6,-7,OBSIDIAN)
Block(-7,6,-6,OBSIDIAN)
Block(-7,6,-5,OBSIDIAN)
Block(-7,6,-4,OBSIDIAN)
Block(-7,7,-7,OBSIDIAN)
Block(-7,7,-6,OBSIDIAN)
Block(-7,7,-5,OBSIDIAN)
Block(-7,8,-7,OBSIDIAN)
Block(-7,8,-6,OBSIDIAN)
Block(-7,9,-7,OBSIDIAN)
Block(-6,0,-7,OBSIDIAN)
Block(-6,0,-6,OBSIDIAN)
Block(-6,0,-5,OBSIDIAN)
Block(-6,0,-4,OBSIDIAN)
Block(-6,0,-3,OBSIDIAN)
Block(-6,0,-2,OBSIDIAN)
Block(-6,0,-1,OBSIDIAN)
Block(-6,0,0,OBSIDIAN)
Block(-6,0,1,OBSIDIAN)
Block(-6,0,2,OBSIDIAN)
Block(-6,1,-7,OBSIDIAN)
Block(-6,1,-6,OBSIDIAN)
Block(-6,1,-5,OBSIDIAN)
Block(-6,1,-4,OBSIDIAN)
Block(-6,1,-3,OBSIDIAN)
Block(-6,1,-2,OBSIDIAN)
Block(-6,1,-1,OBSIDIAN)
Block(-6,1,0,OBSIDIAN)
Block(-6,1,1,OBSIDIAN)
Block(-6,2,-7,OBSIDIAN)
Block(-6,2,-6,OBSIDIAN)
Block(-6,2,-5,OBSIDIAN)
Block(-6,2,-4,OBSIDIAN)
Block(-6,2,-3,OBSIDIAN)
Block(-6,2,-2,OBSIDIAN)
Block(-6,2,-1,OBSIDIAN)
Block(-6,2,0,OBSIDIAN)
Block(-6,3,-7,OBSIDIAN)
Block(-6,3,-6,OBSIDIAN)
Block(-6,3,-5,OBSIDIAN)
Block(-6,3,-4,OBSIDIAN)
Block(-6,3,-3,OBSIDIAN)
Block(-6,3,-2,OBSIDIAN)
Block(-6,3,-1,OBSIDIAN)
Block(-6,4,-7,OBSIDIAN)
Block(-6,4,-6,OBSIDIAN)
Block(-6,4,-5,OBSIDIAN)
Block(-6,4,-4,OBSIDIAN)
Block(-6,4,-3,OBSIDIAN)
Block(-6,4,-2,OBSIDIAN)
Block(-6,5,-7,OBSIDIAN)
Block(-6,5,-6,OBSIDIAN)
Block(-6,5,-5,OBSIDIAN)
Block(-6,5,-4,OBSIDIAN)
Block(-6,5,-3,OBSIDIAN)
Block(-6,6,-7,OBSIDIAN)
Block(-6,6,-6,OBSIDIAN)
Block(-6,6,-5,OBSIDIAN)
Block(-6,6,-4,OBSIDIAN)
Block(-6,7,-7,OBSIDIAN)
Block(-6,7,-6,OBSIDIAN)
Block(-6,7,-5,OBSIDIAN)
Block(-6,8,-7,OBSIDIAN)
Block(-6,8,-6,OBSIDIAN)
Block(-6,9,-7,OBSIDIAN)
Block(-5,0,-7,OBSIDIAN)
Block(-5,0,-6,OBSIDIAN)
Block(-5,0,-5,OBSIDIAN)
Block(-5,0,-4,OBSIDIAN)
Block(-5,0,-3,OBSIDIAN)
Block(-5,0,-2,OBSIDIAN)
Block(-5,0,-1,OBSIDIAN)
Block(-5,0,0,SANDSTONE)
Block(-5,0,1,SANDSTONE)
Block(-5,0,2,SANDSTONE)
Block(-5,1,-7,OBSIDIAN)
Block(-5,1,-6,OBSIDIAN)
Block(-5,1,-5,OBSIDIAN)
Block(-5,1,-4,OBSIDIAN)
Block(-5,1,-3,OBSIDIAN)
Block(-5,1,-2,OBSIDIAN)
Block(-5,1,-1,OBSIDIAN)
Block(-5,1,0,SANDSTONE)
Block(-5,1,1,SANDSTONE)
Block(-5,2,-7,OBSIDIAN)
Block(-5,2,-6,OBSIDIAN)
Block(-5,2,-5,OBSIDIAN)
Block(-5,2,-4,OBSIDIAN)
Block(-5,2,-3,OBSIDIAN)
Block(-5,2,-2,OBSIDIAN)
Block(-5,2,-1,OBSIDIAN)
Block(-5,2,0,SANDSTONE)
Block(-5,3,-7,OBSIDIAN)
Block(-5,3,-6,OBSIDIAN)
Block(-5,3,-5,OBSIDIAN)
Block(-5,3,-4,OBSIDIAN)
Block(-5,3,-3,OBSIDIAN)
Block(-5,3,-2,OBSIDIAN)
Block(-5,3,-1,OBSIDIAN)
Block(-5,4,-7,OBSIDIAN)
Block(-5,4,-6,OBSIDIAN)
Block(-5,4,-5,OBSIDIAN)
Block(-5,4,-4,OBSIDIAN)
Block(-5,4,-3,OBSIDIAN)
Block(-5,4,-2,OBSIDIAN)
Block(-5,5,-7,OBSIDIAN)
Block(-5,5,-6,OBSIDIAN)
Block(-5,5,-5,OBSIDIAN)
Block(-5,5,-4,OBSIDIAN)
Block(-5,5,-3,OBSIDIAN)
Block(-5,6,-7,OBSIDIAN)
Block(-5,6,-6,OBSIDIAN)
Block(-5,6,-5,OBSIDIAN)
Block(-5,6,-4,OBSIDIAN)
Block(-5,7,-7,OBSIDIAN)
Block(-5,7,-6,OBSIDIAN)
Block(-5,7,-5,OBSIDIAN)
Block(-5,8,-7,OBSIDIAN)
Block(-5,8,-6,OBSIDIAN)
Block(-5,9,-7,OBSIDIAN)
Block(-4,0,-7,OBSIDIAN)
Block(-4,0,-6,OBSIDIAN)
Block(-4,0,-5,OBSIDIAN)
Block(-4,0,-4,OBSIDIAN)
Block(-4,0,-3,OBSIDIAN)
Block(-4,0,-2,OBSIDIAN)
Block(-4,0,-1,SANDSTONE)
Block(-4,0,0,SANDSTONE)
Block(-4,0,1,SANDSTONE)
Block(-4,0,2,SANDSTONE)
Block(-4,1,-7,OBSIDIAN)
Block(-4,1,-6,OBSIDIAN)
Block(-4,1,-5,OBSIDIAN)
Block(-4,1,-4,OBSIDIAN)
Block(-4,1,-3,OBSIDIAN)
Block(-4,1,-2,OBSIDIAN)
Block(-4,1,-1,SANDSTONE)
Block(-4,1,0,SANDSTONE)
Block(-4,1,1,SANDSTONE)
Block(-4,2,-7,OBSIDIAN)
Block(-4,2,-6,OBSIDIAN)
Block(-4,2,-5,OBSIDIAN)
Block(-4,2,-4,OBSIDIAN)
Block(-4,2,-3,OBSIDIAN)
Block(-4,2,-2,OBSIDIAN)
Block(-4,2,-1,SANDSTONE)
Block(-4,2,0,SANDSTONE)
Block(-4,3,-7,OBSIDIAN)
Block(-4,3,-6,OBSIDIAN)
Block(-4,3,-5,OBSIDIAN)
Block(-4,3,-4,OBSIDIAN)
Block(-4,3,-3,OBSIDIAN)
Block(-4,3,-2,OBSIDIAN)
Block(-4,3,-1,SANDSTONE)
Block(-4,4,-7,OBSIDIAN)
Block(-4,4,-6,OBSIDIAN)
Block(-4,4,-5,OBSIDIAN)
Block(-4,4,-4,OBSIDIAN)
Block(-4,4,-3,OBSIDIAN)
Block(-4,4,-2,OBSIDIAN)
Block(-4,5,-7,OBSIDIAN)
Block(-4,5,-6,OBSIDIAN)
Block(-4,5,-5,OBSIDIAN)
Block(-4,5,-4,OBSIDIAN)
Block(-4,5,-3,OBSIDIAN)
Block(-4,6,-7,OBSIDIAN)
Block(-4,6,-6,OBSIDIAN)
Block(-4,6,-5,OBSIDIAN)
Block(-4,6,-4,OBSIDIAN)
Block(-4,7,-7,OBSIDIAN)
Block(-4,7,-6,OBSIDIAN)
Block(-4,7,-5,OBSIDIAN)
Block(-4,8,-7,OBSIDIAN)
Block(-4,8,-6,OBSIDIAN)
Block(-4,9,-7,SANDSTONE)
Block(-3,0,-7,OBSIDIAN)
Block(-3,0,-6,OBSIDIAN)
Block(-3,0,-5,OBSIDIAN)
Block(-3,0,-4,OBSIDIAN)
Block(-3,0,-3,OBSIDIAN)
Block(-3,0,-2,SANDSTONE)
Block(-3,0,-1,SANDSTONE)
Block(-3,0,0,SANDSTONE)
Block(-3,0,1,SANDSTONE)
Block(-3,0,2,SANDSTONE)
Block(-3,1,-7,OBSIDIAN)
Block(-3,1,-6,OBSIDIAN)
Block(-3,1,-5,OBSIDIAN)
Block(-3,1,-4,OBSIDIAN)
Block(-3,1,-3,OBSIDIAN)
Block(-3,1,-2,SANDSTONE)
Block(-3,1,-1,SANDSTONE)
Block(-3,1,0,SANDSTONE)
Block(-3,1,1,SANDSTONE)
Block(-3,2,-7,OBSIDIAN)
Block(-3,2,-6,OBSIDIAN)
Block(-3,2,-5,OBSIDIAN)
Block(-3,2,-4,OBSIDIAN)
Block(-3,2,-3,OBSIDIAN)
Block(-3,2,-2,SANDSTONE)
Block(-3,2,-1,SANDSTONE)
Block(-3,2,0,SANDSTONE)
Block(-3,3,-7,OBSIDIAN)
Block(-3,3,-6,OBSIDIAN)
Block(-3,3,-5,OBSIDIAN)
Block(-3,3,-4,OBSIDIAN)
Block(-3,3,-3,OBSIDIAN)
Block(-3,3,-2,OBSIDIAN)
Block(-3,3,-1,SANDSTONE)
Block(-3,4,-7,OBSIDIAN)
Block(-3,4,-6,OBSIDIAN)
Block(-3,4,-5,OBSIDIAN)
Block(-3,4,-4,OBSIDIAN)
Block(-3,4,-3,OBSIDIAN)
Block(-3,4,-2,OBSIDIAN)
Block(-3,5,-7,OBSIDIAN)
Block(-3,5,-6,OBSIDIAN)
Block(-3,5,-5,OBSIDIAN)
Block(-3,5,-4,OBSIDIAN)
Block(-3,5,-3,OBSIDIAN)
Block(-3,6,-7,OBSIDIAN)
Block(-3,6,-6,OBSIDIAN)
Block(-3,6,-5,OBSIDIAN)
Block(-3,6,-4,OBSIDIAN)
Block(-3,7,-7,OBSIDIAN)
Block(-3,7,-6,OBSIDIAN)
Block(-3,7,-5,OBSIDIAN)
Block(-3,8,-7,OBSIDIAN)
Block(-3,8,-6,OBSIDIAN)
Block(-3,9,-7,SANDSTONE)
Block(-2,0,-7,OBSIDIAN)
Block(-2,0,-6,OBSIDIAN)
Block(-2,0,-5,OBSIDIAN)
Block(-2,0,-4,OBSIDIAN)
Block(-2,0,-3,OBSIDIAN)
Block(-2,0,-2,SANDSTONE)
Block(-2,0,-1,SANDSTONE)
Block(-2,0,0,SANDSTONE)
Block(-2,0,1,SANDSTONE)
Block(-2,0,2,SANDSTONE)
Block(-2,1,-7,OBSIDIAN)
Block(-2,1,-6,OBSIDIAN)
Block(-2,1,-5,OBSIDIAN)
Block(-2,1,-4,OBSIDIAN)
Block(-2,1,-3,OBSIDIAN)
Block(-2,1,-2,SANDSTONE)
Block(-2,1,-1,SANDSTONE)
Block(-2,1,0,SANDSTONE)
Block(-2,1,1,SANDSTONE)
Block(-2,2,-7,OBSIDIAN)
Block(-2,2,-6,OBSIDIAN)
Block(-2,2,-5,OBSIDIAN)
Block(-2,2,-4,OBSIDIAN)
Block(-2,2,-3,OBSIDIAN)
Block(-2,2,-2,SANDSTONE)
Block(-2,2,-1,SANDSTONE)
Block(-2,2,0,SANDSTONE)
Block(-2,3,-7,OBSIDIAN)
Block(-2,3,-6,OBSIDIAN)
Block(-2,3,-5,OBSIDIAN)
Block(-2,3,-4,OBSIDIAN)
Block(-2,3,-3,OBSIDIAN)
Block(-2,3,-2,OBSIDIAN)
Block(-2,3,-1,SANDSTONE)
Block(-2,4,-7,OBSIDIAN)
Block(-2,4,-6,OBSIDIAN)
Block(-2,4,-5,OBSIDIAN)
Block(-2,4,-4,OBSIDIAN)
Block(-2,4,-3,OBSIDIAN)
Block(-2,4,-2,OBSIDIAN)
Block(-2,5,-7,OBSIDIAN)
Block(-2,5,-6,OBSIDIAN)
Block(-2,5,-5,OBSIDIAN)
Block(-2,5,-4,OBSIDIAN)
Block(-2,5,-3,OBSIDIAN)
Block(-2,6,-7,OBSIDIAN)
Block(-2,6,-6,OBSIDIAN)
Block(-2,6,-5,OBSIDIAN)
Block(-2,6,-4,OBSIDIAN)
Block(-2,7,-7,OBSIDIAN)
Block(-2,7,-6,OBSIDIAN)
Block(-2,7,-5,OBSIDIAN)
Block(-2,8,-7,SANDSTONE)
Block(-2,8,-6,SANDSTONE)
Block(-2,9,-7,SANDSTONE)
Block(-1,0,-7,OBSIDIAN)
Block(-1,0,-6,OBSIDIAN)
Block(-1,0,-5,OBSIDIAN)
Block(-1,0,-4,OBSIDIAN)
Block(-1,0,-3,OBSIDIAN)
Block(-1,0,-2,SANDSTONE)
Block(-1,0,-1,SANDSTONE)
Block(-1,0,0,SANDSTONE)
Block(-1,0,1,SANDSTONE)
Block(-1,0,2,SANDSTONE)
Block(-1,1,-7,OBSIDIAN)
Block(-1,1,-6,OBSIDIAN)
Block(-1,1,-5,OBSIDIAN)
Block(-1,1,-4,OBSIDIAN)
Block(-1,1,-3,OBSIDIAN)
Block(-1,1,-2,SANDSTONE)
Block(-1,1,-1,SANDSTONE)
Block(-1,1,0,SANDSTONE)
Block(-1,1,1,SANDSTONE)
Block(-1,2,-7,OBSIDIAN)
Block(-1,2,-6,OBSIDIAN)
Block(-1,2,-5,OBSIDIAN)
Block(-1,2,-4,OBSIDIAN)
Block(-1,2,-3,OBSIDIAN)
Block(-1,2,-2,SANDSTONE)
Block(-1,2,-1,SANDSTONE)
Block(-1,2,0,SANDSTONE)
Block(-1,3,-7,OBSIDIAN)
Block(-1,3,-6,OBSIDIAN)
Block(-1,3,-5,OBSIDIAN)
Block(-1,3,-4,OBSIDIAN)
Block(-1,3,-3,OBSIDIAN)
Block(-1,3,-2,OBSIDIAN)
Block(-1,3,-1,SANDSTONE)
Block(-1,4,-7,OBSIDIAN)
Block(-1,4,-6,OBSIDIAN)
Block(-1,4,-5,OBSIDIAN)
Block(-1,4,-4,OBSIDIAN)
Block(-1,4,-3,OBSIDIAN)
Block(-1,4,-2,OBSIDIAN)
Block(-1,5,-7,OBSIDIAN)
Block(-1,5,-6,OBSIDIAN)
Block(-1,5,-5,OBSIDIAN)
Block(-1,5,-4,OBSIDIAN)
Block(-1,5,-3,OBSIDIAN)
Block(-1,6,-7,OBSIDIAN)
Block(-1,6,-6,OBSIDIAN)
Block(-1,6,-5,OBSIDIAN)
Block(-1,6,-4,OBSIDIAN)
Block(-1,7,-7,SANDSTONE)
Block(-1,7,-6,OBSIDIAN)
Block(-1,7,-5,OBSIDIAN)
Block(-1,8,-7,SANDSTONE)
Block(-1,8,-6,SANDSTONE)
Block(-1,9,-7,SANDSTONE)
Block(0,0,-7,OBSIDIAN)
Block(0,0,-6,OBSIDIAN)
Block(0,0,-5,OBSIDIAN)
Block(0,0,-4,OBSIDIAN)
Block(0,0,-3,OBSIDIAN)
Block(0,0,-2,OBSIDIAN)
Block(0,0,-1,SANDSTONE)
Block(0,0,0,SANDSTONE)
Block(0,0,1,SANDSTONE)
Block(0,0,2,SANDSTONE)
Block(0,1,-7,OBSIDIAN)
Block(0,1,-6,OBSIDIAN)
Block(0,1,-5,OBSIDIAN)
Block(0,1,-4,OBSIDIAN)
Block(0,1,-3,OBSIDIAN)
Block(0,1,-2,OBSIDIAN)
Block(0,1,-1,SANDSTONE)
Block(0,1,0,SANDSTONE)
Block(0,1,1,SANDSTONE)
Block(0,2,-7,OBSIDIAN)
Block(0,2,-6,OBSIDIAN)
Block(0,2,-5,OBSIDIAN)
Block(0,2,-4,OBSIDIAN)
Block(0,2,-3,OBSIDIAN)
Block(0,2,-2,OBSIDIAN)
Block(0,2,-1,SANDSTONE)
Block(0,2,0,SANDSTONE)
Block(0,3,-7,OBSIDIAN)
Block(0,3,-6,OBSIDIAN)
Block(0,3,-5,OBSIDIAN)
Block(0,3,-4,OBSIDIAN)
Block(0,3,-3,OBSIDIAN)
Block(0,3,-2,OBSIDIAN)
Block(0,3,-1,SANDSTONE)
Block(0,4,-7,OBSIDIAN)
Block(0,4,-6,OBSIDIAN)
Block(0,4,-5,OBSIDIAN)
Block(0,4,-4,OBSIDIAN)
Block(0,4,-3,OBSIDIAN)
Block(0,4,-2,OBSIDIAN)
Block(0,5,-7,OBSIDIAN)
Block(0,5,-6,OBSIDIAN)
Block(0,5,-5,OBSIDIAN)
Block(0,5,-4,OBSIDIAN)
Block(0,5,-3,OBSIDIAN)
Block(0,6,-7,OBSIDIAN)
Block(0,6,-6,OBSIDIAN)
Block(0,6,-5,OBSIDIAN)
Block(0,6,-4,OBSIDIAN)
Block(0,7,-7,SANDSTONE)
Block(0,7,-6,SANDSTONE)
Block(0,7,-5,OBSIDIAN)
Block(0,8,-7,SANDSTONE)
Block(0,8,-6,SANDSTONE)
Block(0,9,-7,SANDSTONE)
Block(1,0,-7,OBSIDIAN)
Block(1,0,-6,OBSIDIAN)
Block(1,0,-5,OBSIDIAN)
Block(1,0,-4,OBSIDIAN)
Block(1,0,-3,OBSIDIAN)
Block(1,0,-2,OBSIDIAN)
Block(1,0,-1,SANDSTONE)
Block(1,0,0,SANDSTONE)
Block(1,0,1,SANDSTONE)
Block(1,0,2,SANDSTONE)
Block(1,1,-7,OBSIDIAN)
Block(1,1,-6,OBSIDIAN)
Block(1,1,-5,OBSIDIAN)
Block(1,1,-4,OBSIDIAN)
Block(1,1,-3,OBSIDIAN)
Block(1,1,-2,OBSIDIAN)
Block(1,1,-1,SANDSTONE)
Block(1,1,0,SANDSTONE)
Block(1,1,1,SANDSTONE)
Block(1,2,-7,OBSIDIAN)
Block(1,2,-6,OBSIDIAN)
Block(1,2,-5,OBSIDIAN)
Block(1,2,-4,OBSIDIAN)
Block(1,2,-3,OBSIDIAN)
Block(1,2,-2,OBSIDIAN)
Block(1,2,-1,OBSIDIAN)
Block(1,2,0,SANDSTONE)
Block(1,3,-7,OBSIDIAN)
Block(1,3,-6,OBSIDIAN)
Block(1,3,-5,OBSIDIAN)
Block(1,3,-4,OBSIDIAN)
Block(1,3,-3,OBSIDIAN)
Block(1,3,-2,OBSIDIAN)
Block(1,3,-1,OBSIDIAN)
Block(1,4,-7,OBSIDIAN)
Block(1,4,-6,OBSIDIAN)
Block(1,4,-5,OBSIDIAN)
Block(1,4,-4,OBSIDIAN)
Block(1,4,-3,OBSIDIAN)
Block(1,4,-2,OBSIDIAN)
Block(1,5,-7,OBSIDIAN)
Block(1,5,-6,OBSIDIAN)
Block(1,5,-5,OBSIDIAN)
Block(1,5,-4,OBSIDIAN)
Block(1,5,-3,OBSIDIAN)
Block(1,6,-7,SANDSTONE)
Block(1,6,-6,OBSIDIAN)
Block(1,6,-5,OBSIDIAN)
Block(1,6,-4,OBSIDIAN)
Block(1,7,-7,SANDSTONE)
Block(1,7,-6,SANDSTONE)
Block(1,7,-5,OBSIDIAN)
Block(1,8,-7,SANDSTONE)
Block(1,8,-6,SANDSTONE)
Block(1,9,-7,SANDSTONE)
Block(2,0,-7,OBSIDIAN)
Block(2,0,-6,OBSIDIAN)
Block(2,0,-5,OBSIDIAN)
Block(2,0,-4,OBSIDIAN)
Block(2,0,-3,OBSIDIAN)
Block(2,0,-2,OBSIDIAN)
Block(2,0,-1,OBSIDIAN)
Block(2,0,0,SANDSTONE)
Block(2,0,1,SANDSTONE)
Block(2,0,2,SANDSTONE)
Block(2,1,-7,OBSIDIAN)
Block(2,1,-6,OBSIDIAN)
Block(2,1,-5,OBSIDIAN)
Block(2,1,-4,OBSIDIAN)
Block(2,1,-3,OBSIDIAN)
Block(2,1,-2,OBSIDIAN)
Block(2,1,-1,OBSIDIAN)
Block(2,1,0,SANDSTONE)
Block(2,1,1,SANDSTONE)
Block(2,2,-7,OBSIDIAN)
Block(2,2,-6,OBSIDIAN)
Block(2,2,-5,OBSIDIAN)
Block(2,2,-4,OBSIDIAN)
Block(2,2,-3,OBSIDIAN)
Block(2,2,-2,OBSIDIAN)
Block(2,2,-1,OBSIDIAN)
Block(2,2,0,SANDSTONE)
Block(2,3,-7,OBSIDIAN)
Block(2,3,-6,OBSIDIAN)
Block(2,3,-5,OBSIDIAN)
Block(2,3,-4,OBSIDIAN)
Block(2,3,-3,OBSIDIAN)
Block(2,3,-2,OBSIDIAN)
Block(2,3,-1,OBSIDIAN)
Block(2,4,-7,OBSIDIAN)
Block(2,4,-6,OBSIDIAN)
Block(2,4,-5,OBSIDIAN)
Block(2,4,-4,OBSIDIAN)
Block(2,4,-3,OBSIDIAN)
Block(2,4,-2,OBSIDIAN)
Block(2,5,-7,OBSIDIAN)
Block(2,5,-6,OBSIDIAN)
Block(2,5,-5,OBSIDIAN)
Block(2,5,-4,OBSIDIAN)
Block(2,5,-3,OBSIDIAN)
Block(2,6,-7,SANDSTONE)
Block(2,6,-6,OBSIDIAN)
Block(2,6,-5,OBSIDIAN)
Block(2,6,-4,OBSIDIAN)
Block(2,7,-7,SANDSTONE)
Block(2,7,-6,SANDSTONE)
Block(2,7,-5,SANDSTONE)
Block(2,8,-7,SANDSTONE)
Block(2,8,-6,SANDSTONE)
Block(2,9,-7,SANDSTONE)
Block(3,0,-7,OBSIDIAN)
Block(3,0,-6,OBSIDIAN)
Block(3,0,-5,OBSIDIAN)
Block(3,0,-4,OBSIDIAN)
Block(3,0,-3,OBSIDIAN)
Block(3,0,-2,OBSIDIAN)
Block(3,0,-1,OBSIDIAN)
Block(3,0,0,OBSIDIAN)
Block(3,0,1,SANDSTONE)
Block(3,0,2,SANDSTONE)
Block(3,1,-7,OBSIDIAN)
Block(3,1,-6,OBSIDIAN)
Block(3,1,-5,OBSIDIAN)
Block(3,1,-4,OBSIDIAN)
Block(3,1,-3,OBSIDIAN)
Block(3,1,-2,OBSIDIAN)
Block(3,1,-1,OBSIDIAN)
Block(3,1,0,OBSIDIAN)
Block(3,1,1,SANDSTONE)
Block(3,2,-7,OBSIDIAN)
Block(3,2,-6,OBSIDIAN)
Block(3,2,-5,OBSIDIAN)
Block(3,2,-4,OBSIDIAN)
Block(3,2,-3,OBSIDIAN)
Block(3,2,-2,OBSIDIAN)
Block(3,2,-1,OBSIDIAN)
Block(3,2,0,OBSIDIAN)
Block(3,3,-7,OBSIDIAN)
Block(3,3,-6,OBSIDIAN)
Block(3,3,-5,OBSIDIAN)
Block(3,3,-4,OBSIDIAN)
Block(3,3,-3,OBSIDIAN)
Block(3,3,-2,OBSIDIAN)
Block(3,3,-1,OBSIDIAN)
Block(3,4,-7,OBSIDIAN)
Block(3,4,-6,OBSIDIAN)
Block(3,4,-5,OBSIDIAN)
Block(3,4,-4,OBSIDIAN)
Block(3,4,-3,OBSIDIAN)
Block(3,4,-2,OBSIDIAN)
Block(3,5,-7,OBSIDIAN)
Block(3,5,-6,OBSIDIAN)
Block(3,5,-5,OBSIDIAN)
Block(3,5,-4,OBSIDIAN)
Block(3,5,-3,OBSIDIAN)
Block(3,6,-7,SANDSTONE)
Block(3,6,-6,SANDSTONE)
Block(3,6,-5,OBSIDIAN)
Block(3,6,-4,OBSIDIAN)
Block(3,7,-7,SANDSTONE)
Block(3,7,-6,SANDSTONE)
Block(3,7,-5,SANDSTONE)
Block(3,8,-7,SANDSTONE)
Block(3,8,-6,SANDSTONE)
Block(3,9,-7,SANDSTONE)
Block(4,0,-7,OBSIDIAN)
Block(4,0,-6,OBSIDIAN)
Block(4,0,-5,OBSIDIAN)
Block(4,0,-4,OBSIDIAN)
Block(4,0,-3,OBSIDIAN)
Block(4,0,-2,OBSIDIAN)
Block(4,0,-1,OBSIDIAN)
Block(4,0,0,OBSIDIAN)
Block(4,0,1,OBSIDIAN)
Block(4,0,2,OBSIDIAN)
Block(4,1,-7,OBSIDIAN)
Block(4,1,-6,OBSIDIAN)
Block(4,1,-5,OBSIDIAN)
Block(4,1,-4,OBSIDIAN)
Block(4,1,-3,OBSIDIAN)
Block(4,1,-2,OBSIDIAN)
Block(4,1,-1,OBSIDIAN)
Block(4,1,0,OBSIDIAN)
Block(4,1,1,OBSIDIAN)
Block(4,2,-7,OBSIDIAN)
Block(4,2,-6,OBSIDIAN)
Block(4,2,-5,OBSIDIAN)
Block(4,2,-4,OBSIDIAN)
Block(4,2,-3,OBSIDIAN)
Block(4,2,-2,OBSIDIAN)
Block(4,2,-1,OBSIDIAN)
Block(4,2,0,OBSIDIAN)
Block(4,3,-7,OBSIDIAN)
Block(4,3,-6,OBSIDIAN)
Block(4,3,-5,OBSIDIAN)
Block(4,3,-4,OBSIDIAN)
Block(4,3,-3,OBSIDIAN)
Block(4,3,-2,OBSIDIAN)
Block(4,3,-1,OBSIDIAN)
Block(4,4,-7,OBSIDIAN)
Block(4,4,-6,OBSIDIAN)
Block(4,4,-5,OBSIDIAN)
Block(4,4,-4,OBSIDIAN)
Block(4,4,-3,OBSIDIAN)
Block(4,4,-2,OBSIDIAN)
Block(4,5,-7,OBSIDIAN)
Block(4,5,-6,OBSIDIAN)
Block(4,5,-5,OBSIDIAN)
Block(4,5,-4,OBSIDIAN)
Block(4,5,-3,OBSIDIAN)
Block(4,6,-7,SANDSTONE)
Block(4,6,-6,SANDSTONE)
Block(4,6,-5,SANDSTONE)
Block(4,6,-4,SANDSTONE)
Block(4,7,-7,SANDSTONE)
Block(4,7,-6,SANDSTONE)
Block(4,7,-5,SANDSTONE)
Block(4,8,-7,SANDSTONE)
Block(4,8,-6,SANDSTONE)
Block(4,9,-7,SANDSTONE)
Block(5,0,-7,OBSIDIAN)
Block(5,0,-6,OBSIDIAN)
Block(5,0,-5,OBSIDIAN)
Block(5,0,-4,OBSIDIAN)
Block(5,0,-3,OBSIDIAN)
Block(5,0,-2,OBSIDIAN)
Block(5,0,-1,OBSIDIAN)
Block(5,0,0,OBSIDIAN)
Block(5,0,1,OBSIDIAN)
Block(5,0,2,OBSIDIAN)
Block(5,1,-7,OBSIDIAN)
Block(5,1,-6,OBSIDIAN)
Block(5,1,-5,OBSIDIAN)
Block(5,1,-4,OBSIDIAN)
Block(5,1,-3,OBSIDIAN)
Block(5,1,-2,OBSIDIAN)
Block(5,1,-1,OBSIDIAN)
Block(5,1,0,OBSIDIAN)
Block(5,1,1,OBSIDIAN)
Block(5,2,-7,OBSIDIAN)
Block(5,2,-6,OBSIDIAN)
Block(5,2,-5,OBSIDIAN)
Block(5,2,-4,OBSIDIAN)
Block(5,2,-3,OBSIDIAN)
Block(5,2,-2,OBSIDIAN)
Block(5,2,-1,OBSIDIAN)
Block(5,2,0,OBSIDIAN)
Block(5,3,-7,OBSIDIAN)
Block(5,3,-6,OBSIDIAN)
Block(5,3,-5,OBSIDIAN)
Block(5,3,-4,OBSIDIAN)
Block(5,3,-3,OBSIDIAN)
Block(5,3,-2,OBSIDIAN)
Block(5,3,-1,OBSIDIAN)
Block(5,4,-7,OBSIDIAN)
Block(5,4,-6,OBSIDIAN)
Block(5,4,-5,OBSIDIAN)
Block(5,4,-4,OBSIDIAN)
Block(5,4,-3,OBSIDIAN)
Block(5,4,-2,OBSIDIAN)
Block(5,5,-7,SANDSTONE)
Block(5,5,-6,SANDSTONE)
Block(5,5,-5,SANDSTONE)
Block(5,5,-4,OBSIDIAN)
Block(5,5,-3,OBSIDIAN)
Block(5,6,-7,SANDSTONE)
Block(5,6,-6,SANDSTONE)
Block(5,6,-5,SANDSTONE)
Block(5,6,-4,SANDSTONE)
Block(5,7,-7,SANDSTONE)
Block(5,7,-6,SANDSTONE)
Block(5,7,-5,SANDSTONE)
Block(5,8,-7,SANDSTONE)
Block(5,8,-6,SANDSTONE)
Block(5,9,-7,SANDSTONE)
Block(6,0,-7,OBSIDIAN)
Block(6,0,-6,OBSIDIAN)
Block(6,0,-5,OBSIDIAN)
Block(6,0,-4,OBSIDIAN)
Block(6,0,-3,OBSIDIAN)
Block(6,0,-2,OBSIDIAN)
Block(6,0,-1,OBSIDIAN)
Block(6,0,0,OBSIDIAN)
Block(6,0,1,OBSIDIAN)
Block(6,0,2,OBSIDIAN)
Block(6,1,-7,OBSIDIAN)
Block(6,1,-6,OBSIDIAN)
Block(6,1,-5,OBSIDIAN)
Block(6,1,-4,OBSIDIAN)
Block(6,1,-3,OBSIDIAN)
Block(6,1,-2,OBSIDIAN)
Block(6,1,-1,OBSIDIAN)
Block(6,1,0,OBSIDIAN)
Block(6,1,1,OBSIDIAN)
Block(6,2,-7,OBSIDIAN)
Block(6,2,-6,OBSIDIAN)
Block(6,2,-5,OBSIDIAN)
Block(6,2,-4,OBSIDIAN)
Block(6,2,-3,OBSIDIAN)
Block(6,2,-2,OBSIDIAN)
Block(6,2,-1,OBSIDIAN)
Block(6,2,0,OBSIDIAN)
Block(6,3,-7,OBSIDIAN)
Block(6,3,-6,OBSIDIAN)
Block(6,3,-5,OBSIDIAN)
Block(6,3,-4,OBSIDIAN)
Block(6,3,-3,OBSIDIAN)
Block(6,3,-2,OBSIDIAN)
Block(6,3,-1,OBSIDIAN)
Block(6,4,-7,OBSIDIAN)
Block(6,4,-6,OBSIDIAN)
Block(6,4,-5,OBSIDIAN)
Block(6,4,-4,OBSIDIAN)
Block(6,4,-3,OBSIDIAN)
Block(6,4,-2,OBSIDIAN)
Block(6,5,-7,SANDSTONE)
Block(6,5,-6,SANDSTONE)
Block(6,5,-5,SANDSTONE)
Block(6,5,-4,OBSIDIAN)
Block(6,5,-3,OBSIDIAN)
Block(6,6,-7,SANDSTONE)
Block(6,6,-6,SANDSTONE)
Block(6,6,-5,SANDSTONE)
Block(6,6,-4,SANDSTONE)
Block(6,7,-7,SANDSTONE)
Block(6,7,-6,SANDSTONE)
Block(6,7,-5,SANDSTONE)
Block(6,8,-7,SANDSTONE)
Block(6,8,-6,SANDSTONE)
Block(6,9,-7,SANDSTONE)
Block(7,0,-7,OBSIDIAN)
Block(7,0,-6,OBSIDIAN)
Block(7,0,-5,OBSIDIAN)
Block(7,0,-4,OBSIDIAN)
Block(7,0,-3,OBSIDIAN)
Block(7,0,-2,OBSIDIAN)
Block(7,0,-1,OBSIDIAN)
Block(7,0,0,OBSIDIAN)
Block(7,0,1,OBSIDIAN)
Block(7,0,2,OBSIDIAN)
Block(7,1,-7,OBSIDIAN)
Block(7,1,-6,OBSIDIAN)
Block(7,1,-5,OBSIDIAN)
Block(7,1,-4,OBSIDIAN)
Block(7,1,-3,OBSIDIAN)
Block(7,1,-2,OBSIDIAN)
Block(7,1,-1,OBSIDIAN)
Block(7,1,0,OBSIDIAN)
Block(7,1,1,OBSIDIAN)
Block(7,2,-7,OBSIDIAN)
Block(7,2,-6,OBSIDIAN)
Block(7,2,-5,OBSIDIAN)
Block(7,2,-4,OBSIDIAN)
Block(7,2,-3,OBSIDIAN)
Block(7,2,-2,OBSIDIAN)
Block(7,2,-1,OBSIDIAN)
Block(7,2,0,OBSIDIAN)
Block(7,3,-7,OBSIDIAN)
Block(7,3,-6,OBSIDIAN)
Block(7,3,-5,OBSIDIAN)
Block(7,3,-4,OBSIDIAN)
Block(7,3,-3,OBSIDIAN)
Block(7,3,-2,OBSIDIAN)
Block(7,3,-1,OBSIDIAN)
Block(7,4,-7,OBSIDIAN)
Block(7,4,-6,OBSIDIAN)
Block(7,4,-5,OBSIDIAN)
Block(7,4,-4,OBSIDIAN)
Block(7,4,-3,OBSIDIAN)
Block(7,4,-2,OBSIDIAN)
Block(7,5,-7,SANDSTONE)
Block(7,5,-6,SANDSTONE)
Block(7,5,-5,SANDSTONE)
Block(7,5,-4,SANDSTONE)
Block(7,5,-3,SANDSTONE)
Block(7,6,-7,SANDSTONE)
Block(7,6,-6,SANDSTONE)
Block(7,6,-5,SANDSTONE)
Block(7,6,-4,SANDSTONE)
Block(7,7,-7,SANDSTONE)
Block(7,7,-6,SANDSTONE)
Block(7,7,-5,SANDSTONE)
Block(7,8,-7,SANDSTONE)
Block(7,8,-6,SANDSTONE)
Block(7,9,-7,SANDSTONE)

#######################################################################
# +-----------------------------------------------------------------+ #
# |                             Branches                            | #
# +-----------------------------------------------------------------+ #
#######################################################################

Branch(0,0,-16,true,DesertSpike_Huge_15C2R2,NORTH,100.0,0)

#######################################################################
# +-----------------------------------------------------------------+ #
# |                             Entities                            | #
# +-----------------------------------------------------------------+ #
#######################################################################


#######################################################################
# +-----------------------------------------------------------------+ #
# |                            Particles                            | #
# +-----------------------------------------------------------------+ #
#######################################################################


#######################################################################
# +-----------------------------------------------------------------+ #
# |                             Spawners                            | #
# +-----------------------------------------------------------------+ #
#######################################################################


#######################################################################
# +-----------------------------------------------------------------+ #
# |                             ModData                             | #
# +-----------------------------------------------------------------+ #
#######################################################################

