
#######################################################################
# +-----------------------------------------------------------------+ #
# |                            BO3 object                           | #
# +-----------------------------------------------------------------+ #
#######################################################################

Author: Bo3 BulkEdit

Description: Converted Schematic - Modified by Bo3BulkEdit

Version: 3

SettingsMode: WriteWithoutComments


#######################################################################
# +-----------------------------------------------------------------+ #
# |                          Main settings                          | #
# +-----------------------------------------------------------------+ #
#######################################################################

Tree: true

Frequency: 5

Rarity: 100.0

RotateRandomly: true

SpawnHeight: randomY

SpawnHeightOffset: 0

SpawnHeightVariance: 0

##############################
# Height Limits for the BO3. #
##############################

MinHeight: 8

MaxHeight: 20

######################
# Extrusion settings #
######################

ExtrudeMode: None

ExtrudeThroughBlocks: AIR

MaxBranchDepth: 10

ExcludedBiomes: All


#######################################################################
# +-----------------------------------------------------------------+ #
# |                      Source block settings                      | #
# +-----------------------------------------------------------------+ #
#######################################################################

SourceBlocks: AIR,GRASS,DIRT,SAND,STATIONARY_WATER,biomesoplenty:blood

MaxPercentageOutsideSourceBlock: 0

OutsideSourceBlock: placeAnyway

DoReplaceBlocks: true

IsOTGPlus: false


#######################################################################
# +-----------------------------------------------------------------+ #
# |                              Blocks                             | #
# +-----------------------------------------------------------------+ #
#######################################################################

Block(0,0,-2,HUGE_MUSHROOM_2:10)
Block(-1,0,-1,HUGE_MUSHROOM_2:10)
Block(0,0,-1,HUGE_MUSHROOM_2:10)
Block(1,0,-1,HUGE_MUSHROOM_2:10)
Block(-2,0,0,HUGE_MUSHROOM_2:10)
Block(-1,0,0,HUGE_MUSHROOM_2:10)
Block(0,0,0,HUGE_MUSHROOM_2:10)
Block(1,0,0,HUGE_MUSHROOM_2:10)
Block(2,0,0,HUGE_MUSHROOM_2:10)
Block(-1,0,1,HUGE_MUSHROOM_2:10)
Block(0,0,1,HUGE_MUSHROOM_2:10)
Block(1,0,1,HUGE_MUSHROOM_2:10)
Block(0,0,2,HUGE_MUSHROOM_2:10)
Block(0,1,-2,HUGE_MUSHROOM_2:10)
Block(-1,1,-1,HUGE_MUSHROOM_2:10)
Block(0,1,-1,DIRT:0)
Block(1,1,-1,HUGE_MUSHROOM_2:10)
Block(-2,1,0,HUGE_MUSHROOM_2:10)
Block(-1,1,0,HUGE_MUSHROOM_2:10)
Block(0,1,0,HUGE_MUSHROOM_2:10)
Block(1,1,0,DIRT:0)
Block(2,1,0,HUGE_MUSHROOM_2:10)
Block(-1,1,1,HUGE_MUSHROOM_2:10)
Block(0,1,1,HUGE_MUSHROOM_2:10)
Block(1,1,1,HUGE_MUSHROOM_2:10)
Block(0,1,2,HUGE_MUSHROOM_2:10)
Block(0,2,-1,HUGE_MUSHROOM_2:10)
Block(-1,2,0,HUGE_MUSHROOM_2:10)
Block(0,2,0,HUGE_MUSHROOM_2:10)
Block(1,2,0,HUGE_MUSHROOM_2:10)
Block(-1,2,1,HUGE_MUSHROOM_2:10)
Block(0,2,1,HUGE_MUSHROOM_2:10)
Block(-1,3,0,HUGE_MUSHROOM_2:10)
Block(0,3,0,HUGE_MUSHROOM_2:10)
Block(-2,3,1,HUGE_MUSHROOM_2:10)
Block(-1,3,1,HUGE_MUSHROOM_2:10)
Block(0,3,1,HUGE_MUSHROOM_2:10)
Block(-2,4,1,HUGE_MUSHROOM_2:10)
Block(-1,4,1,HUGE_MUSHROOM_2:10)
Block(-1,4,2,HUGE_MUSHROOM_2:10)
Block(-3,5,-2,HUGE_MUSHROOM_2:1)
Block(-2,5,-2,HUGE_MUSHROOM_2:1)
Block(-1,5,-2,HUGE_MUSHROOM_2:3)
Block(0,5,-2,HUGE_MUSHROOM_2:3)
Block(-4,5,-1,HUGE_MUSHROOM_2:1)
Block(-3,5,-1,HUGE_MUSHROOM_2:1)
Block(-2,5,-1,HUGE_MUSHROOM_2:1)
Block(-1,5,-1,HUGE_MUSHROOM_2:3)
Block(0,5,-1,HUGE_MUSHROOM_2:3)
Block(1,5,-1,HUGE_MUSHROOM_2:3)
Block(-5,5,0,HUGE_MUSHROOM_2:1)
Block(-4,5,0,HUGE_MUSHROOM_2:1)
Block(1,5,0,HUGE_MUSHROOM_2:3)
Block(2,5,0,HUGE_MUSHROOM_2:3)
Block(-5,5,1,HUGE_MUSHROOM_2:1)
Block(-4,5,1,HUGE_MUSHROOM_2:1)
Block(-2,5,1,HUGE_MUSHROOM_2:10)
Block(-1,5,1,HUGE_MUSHROOM_2:10)
Block(1,5,1,HUGE_MUSHROOM_2:3)
Block(2,5,1,HUGE_MUSHROOM_2:3)
Block(-5,5,2,HUGE_MUSHROOM_2:7)
Block(-4,5,2,HUGE_MUSHROOM_2:7)
Block(-2,5,2,HUGE_MUSHROOM_2:10)
Block(-1,5,2,HUGE_MUSHROOM_2:10)
Block(1,5,2,HUGE_MUSHROOM_2:9)
Block(2,5,2,HUGE_MUSHROOM_2:9)
Block(-5,5,3,HUGE_MUSHROOM_2:7)
Block(-4,5,3,HUGE_MUSHROOM_2:7)
Block(1,5,3,HUGE_MUSHROOM_2:9)
Block(2,5,3,HUGE_MUSHROOM_2:9)
Block(-4,5,4,HUGE_MUSHROOM_2:7)
Block(-3,5,4,HUGE_MUSHROOM_2:7)
Block(-2,5,4,HUGE_MUSHROOM_2:7)
Block(-1,5,4,HUGE_MUSHROOM_2:9)
Block(0,5,4,HUGE_MUSHROOM_2:9)
Block(1,5,4,HUGE_MUSHROOM_2:9)
Block(-3,5,5,HUGE_MUSHROOM_2:7)
Block(-2,5,5,HUGE_MUSHROOM_2:7)
Block(-1,5,5,HUGE_MUSHROOM_2:9)
Block(0,5,5,HUGE_MUSHROOM_2:9)
Block(-3,6,-1,HUGE_MUSHROOM_2:1)
Block(-2,6,-1,HUGE_MUSHROOM_2:1)
Block(-1,6,-1,HUGE_MUSHROOM_2:3)
Block(0,6,-1,HUGE_MUSHROOM_2:3)
Block(-4,6,0,HUGE_MUSHROOM_2:1)
Block(-3,6,0,HUGE_MUSHROOM_2:1)
Block(0,6,0,HUGE_MUSHROOM_2:3)
Block(1,6,0,HUGE_MUSHROOM_2:3)
Block(-4,6,1,HUGE_MUSHROOM_2:1)
Block(-2,6,1,HUGE_MUSHROOM_2:10)
Block(-1,6,1,HUGE_MUSHROOM_2:10)
Block(0,6,1,HUGE_MUSHROOM_2:10)
Block(1,6,1,HUGE_MUSHROOM_2:3)
Block(-4,6,2,HUGE_MUSHROOM_2:7)
Block(-2,6,2,HUGE_MUSHROOM_2:10)
Block(-1,6,2,HUGE_MUSHROOM_2:10)
Block(1,6,2,HUGE_MUSHROOM_2:9)
Block(-4,6,3,HUGE_MUSHROOM_2:7)
Block(-3,6,3,HUGE_MUSHROOM_2:7)
Block(0,6,3,HUGE_MUSHROOM_2:9)
Block(1,6,3,HUGE_MUSHROOM_2:9)
Block(-3,6,4,HUGE_MUSHROOM_2:7)
Block(-2,6,4,HUGE_MUSHROOM_2:7)
Block(-1,6,4,HUGE_MUSHROOM_2:9)
Block(0,6,4,HUGE_MUSHROOM_2:9)
Block(-2,7,0,HUGE_MUSHROOM_2:1)
Block(-1,7,0,HUGE_MUSHROOM_2:3)
Block(-3,7,1,HUGE_MUSHROOM_2:1)
Block(-2,7,1,HUGE_MUSHROOM_2:9)
Block(-1,7,1,HUGE_MUSHROOM_2:9)
Block(0,7,1,HUGE_MUSHROOM_2:3)
Block(-3,7,2,HUGE_MUSHROOM_2:7)
Block(-2,7,2,HUGE_MUSHROOM_2:9)
Block(-1,7,2,HUGE_MUSHROOM_2:9)
Block(0,7,2,HUGE_MUSHROOM_2:9)
Block(-2,7,3,HUGE_MUSHROOM_2:7)
Block(-1,7,3,HUGE_MUSHROOM_2:9)

#######################################################################
# +-----------------------------------------------------------------+ #
# |                            BO3 checks                           | #
# +-----------------------------------------------------------------+ #
#######################################################################

BlockCheck(0,-1,-2,DIRT,STAINED_CLAY:14,MYCEL,STAINED_CLAY:15)
BlockCheck(-1,-1,-1,DIRT,STAINED_CLAY:14,MYCEL,STAINED_CLAY:15)
BlockCheck(0,-1,-1,DIRT,STAINED_CLAY:14,MYCEL,STAINED_CLAY:15)
BlockCheck(1,-1,-1,DIRT,STAINED_CLAY:14,MYCEL,STAINED_CLAY:15)
BlockCheck(-2,-1,0,DIRT,STAINED_CLAY:14,MYCEL,STAINED_CLAY:15)
BlockCheck(-1,-1,0,DIRT,STAINED_CLAY:14,MYCEL,STAINED_CLAY:15)
BlockCheck(0,-1,0,DIRT,STAINED_CLAY:14,MYCEL,STAINED_CLAY:15)
BlockCheck(1,-1,0,DIRT,STAINED_CLAY:14,MYCEL,STAINED_CLAY:15)
BlockCheck(2,-1,0,DIRT,STAINED_CLAY:14,MYCEL,STAINED_CLAY:15)
BlockCheck(-1,-1,1,DIRT,STAINED_CLAY:14,MYCEL,STAINED_CLAY:15)
BlockCheck(0,-1,1,DIRT,STAINED_CLAY:14,MYCEL,STAINED_CLAY:15)
BlockCheck(1,-1,1,DIRT,STAINED_CLAY:14,MYCEL,STAINED_CLAY:15)
BlockCheck(0,-1,2,DIRT,STAINED_CLAY:14,MYCEL,STAINED_CLAY:15)

#######################################################################
# +-----------------------------------------------------------------+ #
# |                             Branches                            | #
# +-----------------------------------------------------------------+ #
#######################################################################


#######################################################################
# +-----------------------------------------------------------------+ #
# |                             Entities                            | #
# +-----------------------------------------------------------------+ #
#######################################################################


#######################################################################
# +-----------------------------------------------------------------+ #
# |                            Particles                            | #
# +-----------------------------------------------------------------+ #
#######################################################################


#######################################################################
# +-----------------------------------------------------------------+ #
# |                             Spawners                            | #
# +-----------------------------------------------------------------+ #
#######################################################################


#######################################################################
# +-----------------------------------------------------------------+ #
# |                             ModData                             | #
# +-----------------------------------------------------------------+ #
#######################################################################

