
#######################################################################
# +-----------------------------------------------------------------+ #
# |                            BO4 object                           | #
# +-----------------------------------------------------------------+ #
#######################################################################

Author: NLBlackEagle

Description: No description given

SettingsMode: WriteWithoutComments


#######################################################################
# +-----------------------------------------------------------------+ #
# |                          Main settings                          | #
# +-----------------------------------------------------------------+ #
#######################################################################

FixedRotation: 

Frequency: 0

SpawnHeight: highestBlock

UseCenterForHighestBlock: true

##############################
# Height Limits for the BO4. #
##############################

MinHeight: 0

MaxHeight: 255

InheritBO3: 

InheritBO3Rotation: NORTH

OverrideChildSettings: true

OverrideParentHeight: false

CanOverride: true

BranchFrequency: 0

BranchFrequencyGroup: 

MustBeBelowOther: false

MustBeInside: 

CannotBeInside: 

ReplacesBO3: 

MustBeInsideWorldBorders: false

CanSpawnOnWater: true

SpawnOnWaterOnly: false

SpawnUnderWater: false

SpawnAtWaterLevel: false

HeightOffset: 0

RemoveAir: true

ReplaceAbove: 

ReplaceBelow: 

ReplaceWithBiomeBlocks: false

ReplaceWithSurfaceBlock: GRASS

ReplaceWithGroundBlock: DIRT

ReplaceWithStoneBlock: STONE

SmoothRadius: 0

SmoothHeightOffset: 0

SmoothStartTop: false

SmoothStartWood: false

SmoothingSurfaceBlock: 

SmoothingGroundBlock: 

BO3Group: 

IsSpawnPoint: false

DoReplaceBlocks: true


#######################################################################
# +-----------------------------------------------------------------+ #
# |                              Blocks                             | #
# +-----------------------------------------------------------------+ #
#######################################################################

Block(-6,43,4,STONE:6)
Block(-6,43,6,STONE:6)
Block(-6,44,4,STONE:6)
Block(-6,44,6,STONE:6)
Block(-6,45,4,STONE:6)
Block(-6,45,6,STONE:6)
Block(-6,46,4,STONE:6)
Block(-6,46,6,STONE:6)
Block(-6,47,4,STONE:6)
Block(-6,47,6,STONE:6)
Block(-6,48,4,STONE:6)
Block(-6,48,6,STONE:6)
Block(-6,49,4,STONE:6)
Block(-6,49,6,STONE:6)
Block(-6,53,7,quark:iron_plate:1)
Block(-6,54,7,quark:iron_plate:1)
Block(-6,55,7,quark:iron_plate:1)
Block(-6,56,7,quark:iron_plate:1)
Block(-6,57,7,quark:iron_plate:1)
Block(-6,58,7,quark:iron_plate:1)
Block(-6,59,7,quark:iron_plate:1)
Block(-5,43,4,STONE:6)
Block(-5,43,6,STONE:6)
RandomBlock(-5,44,-1,rustic:iron_lattice:0,5,STAINED_CLAY:15,5,STAINED_CLAY:7,5,quark:iron_plate_slab:8,15,quark:world_stone_pavement:2,15,STAINED_CLAY:9,100)
RandomBlock(-5,44,0,rustic:iron_lattice:0,5,STAINED_CLAY:15,5,STAINED_CLAY:7,5,quark:iron_plate_slab:8,15,quark:world_stone_pavement:2,15,STAINED_CLAY:9,100)
RandomBlock(-5,44,1,rustic:iron_lattice:0,5,STAINED_CLAY:15,5,STAINED_CLAY:7,5,quark:iron_plate_slab:8,15,quark:world_stone_pavement:2,15,STAINED_CLAY:9,100)
RandomBlock(-5,44,2,rustic:iron_lattice:0,5,STAINED_CLAY:15,5,STAINED_CLAY:7,5,quark:iron_plate_slab:8,15,quark:world_stone_pavement:2,15,STAINED_CLAY:9,100)
RandomBlock(-5,44,3,rustic:iron_lattice:0,5,STAINED_CLAY:15,5,STAINED_CLAY:7,5,quark:iron_plate_slab:8,15,quark:world_stone_pavement:2,15,STAINED_CLAY:9,100)
RandomBlock(-5,44,4,rustic:iron_lattice:0,5,STAINED_CLAY:15,5,STAINED_CLAY:7,5,quark:iron_plate_slab:8,15,quark:world_stone_pavement:2,15,STAINED_CLAY:9,100)
RandomBlock(-5,44,5,rustic:iron_lattice:0,5,STAINED_CLAY:15,5,STAINED_CLAY:7,5,quark:iron_plate_slab:8,15,quark:world_stone_pavement:2,15,STAINED_CLAY:9,100)
RandomBlock(-5,44,6,rustic:iron_lattice:0,5,STAINED_CLAY:15,5,STAINED_CLAY:7,5,quark:iron_plate_slab:8,15,quark:world_stone_pavement:2,15,STAINED_CLAY:9,100)
RandomBlock(-5,44,7,rustic:iron_lattice:0,5,STAINED_CLAY:15,5,STAINED_CLAY:7,5,quark:iron_plate_slab:8,15,quark:world_stone_pavement:2,15,STAINED_CLAY:9,100)
RandomBlock(-5,44,8,rustic:iron_lattice:0,5,STAINED_CLAY:15,5,STAINED_CLAY:7,5,quark:iron_plate_slab:8,15,quark:world_stone_pavement:2,15,STAINED_CLAY:9,100)
RandomBlock(-5,45,-1,rustic:iron_lattice:0,5,CONCRETE_POWDER:8,10,quark:limestone:1,15,quark:limestone,15,quark:world_stone_pavement:2,15,CONCRETE:8,100)
RandomBlock(-5,45,0,rustic:iron_lattice:0,5,CONCRETE_POWDER:8,10,quark:limestone:1,15,quark:limestone,15,quark:world_stone_pavement:2,15,CONCRETE:8,100)
RandomBlock(-5,45,1,rustic:iron_lattice:0,5,CONCRETE_POWDER:8,10,quark:limestone:1,15,quark:limestone,15,quark:world_stone_pavement:2,15,CONCRETE:8,100)
RandomBlock(-5,45,2,rustic:iron_lattice:0,5,CONCRETE_POWDER:8,10,quark:limestone:1,15,quark:limestone,15,quark:world_stone_pavement:2,15,CONCRETE:8,100)
RandomBlock(-5,45,3,rustic:iron_lattice:0,5,CONCRETE_POWDER:8,10,quark:limestone:1,15,quark:limestone,15,quark:world_stone_pavement:2,15,CONCRETE:8,100)
RandomBlock(-5,45,4,rustic:iron_lattice:0,5,CONCRETE_POWDER:8,10,quark:limestone:1,15,quark:limestone,15,quark:world_stone_pavement:2,15,CONCRETE:8,100)
RandomBlock(-5,45,5,rustic:iron_lattice:0,5,CONCRETE_POWDER:8,10,quark:limestone:1,15,quark:limestone,15,quark:world_stone_pavement:2,15,CONCRETE:8,100)
RandomBlock(-5,45,6,rustic:iron_lattice:0,5,CONCRETE_POWDER:8,10,quark:limestone:1,15,quark:limestone,15,quark:world_stone_pavement:2,15,CONCRETE:8,100)
RandomBlock(-5,45,7,rustic:iron_lattice:0,5,CONCRETE_POWDER:8,10,quark:limestone:1,15,quark:limestone,15,quark:world_stone_pavement:2,15,CONCRETE:8,100)
RandomBlock(-5,45,8,rustic:iron_lattice:0,5,CONCRETE_POWDER:8,10,quark:limestone:1,15,quark:limestone,15,quark:world_stone_pavement:2,15,CONCRETE:8,100)
Block(-5,46,-1,CONCRETE:15)
Block(-5,46,0,CONCRETE:15)
Block(-5,46,1,STAINED_GLASS_PANE:7)
Block(-5,46,2,STAINED_GLASS_PANE:7)
Block(-5,46,3,CONCRETE:15)
Block(-5,46,4,CONCRETE:15)
Block(-5,46,5,CONCRETE:15)
Block(-5,46,6,CONCRETE:15)
Block(-5,46,7,CONCRETE:15)
Block(-5,46,8,STAINED_GLASS_PANE:7)
RandomBlock(-5,47,-1,rustic:iron_lattice:0,5,CONCRETE_POWDER:8,10,quark:limestone:1,15,quark:limestone,15,quark:world_stone_pavement:2,15,CONCRETE:8,100)
RandomBlock(-5,47,0,rustic:iron_lattice:0,5,CONCRETE_POWDER:8,10,quark:limestone:1,15,quark:limestone,15,quark:world_stone_pavement:2,15,CONCRETE:8,100)
RandomBlock(-5,47,1,rustic:iron_lattice:0,5,CONCRETE_POWDER:8,10,quark:limestone:1,15,quark:limestone,15,quark:world_stone_pavement:2,15,CONCRETE:8,100)
RandomBlock(-5,47,2,rustic:iron_lattice:0,5,CONCRETE_POWDER:8,10,quark:limestone:1,15,quark:limestone,15,quark:world_stone_pavement:2,15,CONCRETE:8,100)
RandomBlock(-5,47,3,rustic:iron_lattice:0,5,CONCRETE_POWDER:8,10,quark:limestone:1,15,quark:limestone,15,quark:world_stone_pavement:2,15,CONCRETE:8,100)
RandomBlock(-5,47,4,rustic:iron_lattice:0,5,CONCRETE_POWDER:8,10,quark:limestone:1,15,quark:limestone,15,quark:world_stone_pavement:2,15,CONCRETE:8,100)
RandomBlock(-5,47,5,rustic:iron_lattice:0,5,CONCRETE_POWDER:8,10,quark:limestone:1,15,quark:limestone,15,quark:world_stone_pavement:2,15,CONCRETE:8,100)
RandomBlock(-5,47,6,rustic:iron_lattice:0,5,CONCRETE_POWDER:8,10,quark:limestone:1,15,quark:limestone,15,quark:world_stone_pavement:2,15,CONCRETE:8,100)
RandomBlock(-5,47,7,rustic:iron_lattice:0,5,CONCRETE_POWDER:8,10,quark:limestone:1,15,quark:limestone,15,quark:world_stone_pavement:2,15,CONCRETE:8,100)
RandomBlock(-5,47,8,rustic:iron_lattice:0,5,CONCRETE_POWDER:8,10,quark:limestone:1,15,quark:limestone,15,quark:world_stone_pavement:2,15,CONCRETE:8,100)
RandomBlock(-5,48,-1,rustic:iron_lattice:0,5,CONCRETE_POWDER:8,10,quark:limestone:1,15,quark:limestone,15,quark:world_stone_pavement:2,15,CONCRETE:8,100)
RandomBlock(-5,48,0,rustic:iron_lattice:0,5,CONCRETE_POWDER:8,10,quark:limestone:1,15,quark:limestone,15,quark:world_stone_pavement:2,15,CONCRETE:8,100)
RandomBlock(-5,48,1,rustic:iron_lattice:0,5,CONCRETE_POWDER:8,10,quark:limestone:1,15,quark:limestone,15,quark:world_stone_pavement:2,15,CONCRETE:8,100)
RandomBlock(-5,48,2,rustic:iron_lattice:0,5,CONCRETE_POWDER:8,10,quark:limestone:1,15,quark:limestone,15,quark:world_stone_pavement:2,15,CONCRETE:8,100)
RandomBlock(-5,48,3,rustic:iron_lattice:0,5,CONCRETE_POWDER:8,10,quark:limestone:1,15,quark:limestone,15,quark:world_stone_pavement:2,15,CONCRETE:8,100)
RandomBlock(-5,48,4,rustic:iron_lattice:0,5,CONCRETE_POWDER:8,10,quark:limestone:1,15,quark:limestone,15,quark:world_stone_pavement:2,15,CONCRETE:8,100)
RandomBlock(-5,48,5,rustic:iron_lattice:0,5,CONCRETE_POWDER:8,10,quark:limestone:1,15,quark:limestone,15,quark:world_stone_pavement:2,15,CONCRETE:8,100)
RandomBlock(-5,48,6,rustic:iron_lattice:0,5,CONCRETE_POWDER:8,10,quark:limestone:1,15,quark:limestone,15,quark:world_stone_pavement:2,15,CONCRETE:8,100)
RandomBlock(-5,48,7,rustic:iron_lattice:0,5,CONCRETE_POWDER:8,10,quark:limestone:1,15,quark:limestone,15,quark:world_stone_pavement:2,15,CONCRETE:8,100)
RandomBlock(-5,48,8,rustic:iron_lattice:0,5,CONCRETE_POWDER:8,10,quark:limestone:1,15,quark:limestone,15,quark:world_stone_pavement:2,15,CONCRETE:8,100)
RandomBlock(-5,49,-1,rustic:iron_lattice:0,5,CONCRETE_POWDER:8,10,quark:limestone:1,15,quark:limestone,15,quark:world_stone_pavement:2,15,CONCRETE:8,100)
RandomBlock(-5,49,0,rustic:iron_lattice:0,5,CONCRETE_POWDER:8,10,quark:limestone:1,15,quark:limestone,15,quark:world_stone_pavement:2,15,CONCRETE:8,100)
RandomBlock(-5,49,1,rustic:iron_lattice:0,5,CONCRETE_POWDER:8,10,quark:limestone:1,15,quark:limestone,15,quark:world_stone_pavement:2,15,CONCRETE:8,100)
RandomBlock(-5,49,2,rustic:iron_lattice:0,5,CONCRETE_POWDER:8,10,quark:limestone:1,15,quark:limestone,15,quark:world_stone_pavement:2,15,CONCRETE:8,100)
RandomBlock(-5,49,3,rustic:iron_lattice:0,5,CONCRETE_POWDER:8,10,quark:limestone:1,15,quark:limestone,15,quark:world_stone_pavement:2,15,CONCRETE:8,100)
RandomBlock(-5,49,4,rustic:iron_lattice:0,5,CONCRETE_POWDER:8,10,quark:limestone:1,15,quark:limestone,15,quark:world_stone_pavement:2,15,CONCRETE:8,100)
RandomBlock(-5,49,5,rustic:iron_lattice:0,5,CONCRETE_POWDER:8,10,quark:limestone:1,15,quark:limestone,15,quark:world_stone_pavement:2,15,CONCRETE:8,100)
RandomBlock(-5,49,6,rustic:iron_lattice:0,5,CONCRETE_POWDER:8,10,quark:limestone:1,15,quark:limestone,15,quark:world_stone_pavement:2,15,CONCRETE:8,100)
RandomBlock(-5,49,7,rustic:iron_lattice:0,5,CONCRETE_POWDER:8,10,quark:limestone:1,15,quark:limestone,15,quark:world_stone_pavement:2,15,CONCRETE:8,100)
RandomBlock(-5,49,8,rustic:iron_lattice:0,5,CONCRETE_POWDER:8,10,quark:limestone:1,15,quark:limestone,15,quark:world_stone_pavement:2,15,CONCRETE:8,100)
RandomBlock(-5,50,-1,rustic:iron_lattice:0,5,CONCRETE_POWDER:8,10,quark:limestone:1,15,quark:limestone,15,quark:world_stone_pavement:2,15,CONCRETE:8,100)
RandomBlock(-5,50,0,rustic:iron_lattice:0,5,CONCRETE_POWDER:8,10,quark:limestone:1,15,quark:limestone,15,quark:world_stone_pavement:2,15,CONCRETE:8,100)
RandomBlock(-5,50,1,rustic:iron_lattice:0,5,CONCRETE_POWDER:8,10,quark:limestone:1,15,quark:limestone,15,quark:world_stone_pavement:2,15,CONCRETE:8,100)
RandomBlock(-5,50,2,rustic:iron_lattice:0,5,CONCRETE_POWDER:8,10,quark:limestone:1,15,quark:limestone,15,quark:world_stone_pavement:2,15,CONCRETE:8,100)
RandomBlock(-5,50,3,rustic:iron_lattice:0,5,CONCRETE_POWDER:8,10,quark:limestone:1,15,quark:limestone,15,quark:world_stone_pavement:2,15,CONCRETE:8,100)
RandomBlock(-5,50,4,rustic:iron_lattice:0,5,CONCRETE_POWDER:8,10,quark:limestone:1,15,quark:limestone,15,quark:world_stone_pavement:2,15,CONCRETE:8,100)
RandomBlock(-5,50,5,rustic:iron_lattice:0,5,CONCRETE_POWDER:8,10,quark:limestone:1,15,quark:limestone,15,quark:world_stone_pavement:2,15,CONCRETE:8,100)
RandomBlock(-5,50,6,rustic:iron_lattice:0,5,CONCRETE_POWDER:8,10,quark:limestone:1,15,quark:limestone,15,quark:world_stone_pavement:2,15,CONCRETE:8,100)
RandomBlock(-5,50,7,rustic:iron_lattice:0,5,CONCRETE_POWDER:8,10,quark:limestone:1,15,quark:limestone,15,quark:world_stone_pavement:2,15,CONCRETE:8,100)
RandomBlock(-5,50,8,rustic:iron_lattice:0,5,CONCRETE_POWDER:8,10,quark:limestone:1,15,quark:limestone,15,quark:world_stone_pavement:2,15,CONCRETE:8,100)
RandomBlock(-5,51,-1,rustic:iron_lattice:0,5,CONCRETE_POWDER:8,10,quark:limestone:1,15,quark:limestone,15,quark:world_stone_pavement:2,15,CONCRETE:8,100)
RandomBlock(-5,51,0,rustic:iron_lattice:0,5,CONCRETE_POWDER:8,10,quark:limestone:1,15,quark:limestone,15,quark:world_stone_pavement:2,15,CONCRETE:8,100)
RandomBlock(-5,51,1,rustic:iron_lattice:0,5,CONCRETE_POWDER:8,10,quark:limestone:1,15,quark:limestone,15,quark:world_stone_pavement:2,15,CONCRETE:8,100)
RandomBlock(-5,51,2,rustic:iron_lattice:0,5,CONCRETE_POWDER:8,10,quark:limestone:1,15,quark:limestone,15,quark:world_stone_pavement:2,15,CONCRETE:8,100)
RandomBlock(-5,51,3,rustic:iron_lattice:0,5,CONCRETE_POWDER:8,10,quark:limestone:1,15,quark:limestone,15,quark:world_stone_pavement:2,15,CONCRETE:8,100)
RandomBlock(-5,51,4,rustic:iron_lattice:0,5,CONCRETE_POWDER:8,10,quark:limestone:1,15,quark:limestone,15,quark:world_stone_pavement:2,15,CONCRETE:8,100)
RandomBlock(-5,51,5,rustic:iron_lattice:0,5,CONCRETE_POWDER:8,10,quark:limestone:1,15,quark:limestone,15,quark:world_stone_pavement:2,15,CONCRETE:8,100)
Block(-5,51,6,rustic:iron_lattice:0)
Block(-5,51,7,rustic:iron_lattice:0)
Block(-5,51,8,rustic:iron_lattice:0)
Block(-5,52,-1,CONCRETE:15)
Block(-5,52,0,CONCRETE:15)
Block(-5,52,1,STAINED_GLASS_PANE:7)
Block(-5,52,2,STAINED_GLASS_PANE:7)
Block(-5,52,3,CONCRETE:15)
Block(-5,52,4,CONCRETE:15)
Block(-5,52,5,CONCRETE:15)
Block(-5,52,6,rustic:iron_lattice:0)
Block(-5,52,7,rustic:iron_lattice:0)
Block(-5,52,8,rustic:iron_lattice:0)
RandomBlock(-5,53,-1,rustic:iron_lattice:0,5,CONCRETE_POWDER:8,10,quark:limestone:1,15,quark:limestone,15,quark:world_stone_pavement:2,15,CONCRETE:8,100)
RandomBlock(-5,53,0,rustic:iron_lattice:0,5,CONCRETE_POWDER:8,10,quark:limestone:1,15,quark:limestone,15,quark:world_stone_pavement:2,15,CONCRETE:8,100)
RandomBlock(-5,53,1,rustic:iron_lattice:0,5,CONCRETE_POWDER:8,10,quark:limestone:1,15,quark:limestone,15,quark:world_stone_pavement:2,15,CONCRETE:8,100)
RandomBlock(-5,53,2,rustic:iron_lattice:0,5,CONCRETE_POWDER:8,10,quark:limestone:1,15,quark:limestone,15,quark:world_stone_pavement:2,15,CONCRETE:8,100)
RandomBlock(-5,53,3,rustic:iron_lattice:0,5,CONCRETE_POWDER:8,10,quark:limestone:1,15,quark:limestone,15,quark:world_stone_pavement:2,15,CONCRETE:8,100)
RandomBlock(-5,53,4,rustic:iron_lattice:0,5,CONCRETE_POWDER:8,10,quark:limestone:1,15,quark:limestone,15,quark:world_stone_pavement:2,15,CONCRETE:8,100)
RandomBlock(-5,53,5,rustic:iron_lattice:0,5,CONCRETE_POWDER:8,10,quark:limestone:1,15,quark:limestone,15,quark:world_stone_pavement:2,15,CONCRETE:8,100)
Block(-5,53,7,quark:iron_plate:1)
RandomBlock(-5,54,-1,rustic:iron_lattice:0,5,CONCRETE_POWDER:8,10,quark:limestone:1,15,quark:limestone,15,quark:world_stone_pavement:2,15,CONCRETE:8,100)
RandomBlock(-5,54,0,rustic:iron_lattice:0,5,CONCRETE_POWDER:8,10,quark:limestone:1,15,quark:limestone,15,quark:world_stone_pavement:2,15,CONCRETE:8,100)
RandomBlock(-5,54,1,rustic:iron_lattice:0,5,CONCRETE_POWDER:8,10,quark:limestone:1,15,quark:limestone,15,quark:world_stone_pavement:2,15,CONCRETE:8,100)
RandomBlock(-5,54,2,rustic:iron_lattice:0,5,CONCRETE_POWDER:8,10,quark:limestone:1,15,quark:limestone,15,quark:world_stone_pavement:2,15,CONCRETE:8,100)
RandomBlock(-5,54,3,rustic:iron_lattice:0,5,CONCRETE_POWDER:8,10,quark:limestone:1,15,quark:limestone,15,quark:world_stone_pavement:2,15,CONCRETE:8,100)
RandomBlock(-5,54,4,rustic:iron_lattice:0,5,CONCRETE_POWDER:8,10,quark:limestone:1,15,quark:limestone,15,quark:world_stone_pavement:2,15,CONCRETE:8,100)
RandomBlock(-5,54,5,rustic:iron_lattice:0,5,CONCRETE_POWDER:8,10,quark:limestone:1,15,quark:limestone,15,quark:world_stone_pavement:2,15,CONCRETE:8,100)
RandomBlock(-5,54,6,rustic:iron_lattice:0,5,CONCRETE_POWDER:8,10,quark:limestone:1,15,quark:limestone,15,quark:world_stone_pavement:2,15,CONCRETE:8,100)
RandomBlock(-5,54,7,rustic:iron_lattice:0,5,CONCRETE_POWDER:8,10,quark:limestone:1,15,quark:limestone,15,quark:world_stone_pavement:2,15,CONCRETE:8,100)
RandomBlock(-5,54,8,rustic:iron_lattice:0,5,CONCRETE_POWDER:8,10,quark:limestone:1,15,quark:limestone,15,quark:world_stone_pavement:2,15,CONCRETE:8,100)
RandomBlock(-5,55,-1,rustic:iron_lattice:0,5,CONCRETE_POWDER:8,10,quark:limestone:1,15,quark:limestone,15,quark:world_stone_pavement:2,15,CONCRETE:8,100)
RandomBlock(-5,55,0,rustic:iron_lattice:0,5,CONCRETE_POWDER:8,10,quark:limestone:1,15,quark:limestone,15,quark:world_stone_pavement:2,15,CONCRETE:8,100)
RandomBlock(-5,55,1,rustic:iron_lattice:0,5,CONCRETE_POWDER:8,10,quark:limestone:1,15,quark:limestone,15,quark:world_stone_pavement:2,15,CONCRETE:8,100)
RandomBlock(-5,55,2,rustic:iron_lattice:0,5,CONCRETE_POWDER:8,10,quark:limestone:1,15,quark:limestone,15,quark:world_stone_pavement:2,15,CONCRETE:8,100)
RandomBlock(-5,55,3,rustic:iron_lattice:0,5,CONCRETE_POWDER:8,10,quark:limestone:1,15,quark:limestone,15,quark:world_stone_pavement:2,15,CONCRETE:8,100)
RandomBlock(-5,55,4,rustic:iron_lattice:0,5,CONCRETE_POWDER:8,10,quark:limestone:1,15,quark:limestone,15,quark:world_stone_pavement:2,15,CONCRETE:8,100)
RandomBlock(-5,55,5,rustic:iron_lattice:0,5,CONCRETE_POWDER:8,10,quark:limestone:1,15,quark:limestone,15,quark:world_stone_pavement:2,15,CONCRETE:8,100)
RandomBlock(-5,55,6,rustic:iron_lattice:0,5,CONCRETE_POWDER:8,10,quark:limestone:1,15,quark:limestone,15,quark:world_stone_pavement:2,15,CONCRETE:8,100)
RandomBlock(-5,55,7,rustic:iron_lattice:0,5,CONCRETE_POWDER:8,10,quark:limestone:1,15,quark:limestone,15,quark:world_stone_pavement:2,15,CONCRETE:8,100)
RandomBlock(-5,55,8,rustic:iron_lattice:0,5,CONCRETE_POWDER:8,10,quark:limestone:1,15,quark:limestone,15,quark:world_stone_pavement:2,15,CONCRETE:8,100)
RandomBlock(-5,56,-1,rustic:iron_lattice:0,5,CONCRETE_POWDER:8,10,quark:limestone:1,15,quark:limestone,15,quark:world_stone_pavement:2,15,CONCRETE:8,100)
RandomBlock(-5,56,0,rustic:iron_lattice:0,5,CONCRETE_POWDER:8,10,quark:limestone:1,15,quark:limestone,15,quark:world_stone_pavement:2,15,CONCRETE:8,100)
Block(-5,56,1,STAINED_GLASS_PANE:7)
Block(-5,56,2,STAINED_GLASS_PANE:7)
RandomBlock(-5,56,3,rustic:iron_lattice:0,5,CONCRETE_POWDER:8,10,quark:limestone:1,15,quark:limestone,15,quark:world_stone_pavement:2,15,CONCRETE:8,100)
RandomBlock(-5,56,4,rustic:iron_lattice:0,5,CONCRETE_POWDER:8,10,quark:limestone:1,15,quark:limestone,15,quark:world_stone_pavement:2,15,CONCRETE:8,100)
RandomBlock(-5,56,5,rustic:iron_lattice:0,5,CONCRETE_POWDER:8,10,quark:limestone:1,15,quark:limestone,15,quark:world_stone_pavement:2,15,CONCRETE:8,100)
RandomBlock(-5,56,6,rustic:iron_lattice:0,5,CONCRETE_POWDER:8,10,quark:limestone:1,15,quark:limestone,15,quark:world_stone_pavement:2,15,CONCRETE:8,100)
RandomBlock(-5,56,7,rustic:iron_lattice:0,5,CONCRETE_POWDER:8,10,quark:limestone:1,15,quark:limestone,15,quark:world_stone_pavement:2,15,CONCRETE:8,100)
RandomBlock(-5,56,8,rustic:iron_lattice:0,5,CONCRETE_POWDER:8,10,quark:limestone:1,15,quark:limestone,15,quark:world_stone_pavement:2,15,CONCRETE:8,100)
RandomBlock(-5,57,-1,rustic:iron_lattice:0,5,CONCRETE_POWDER:8,10,quark:limestone:1,15,quark:limestone,15,quark:world_stone_pavement:2,15,CONCRETE:8,100)
RandomBlock(-5,57,0,rustic:iron_lattice:0,5,CONCRETE_POWDER:8,10,quark:limestone:1,15,quark:limestone,15,quark:world_stone_pavement:2,15,CONCRETE:8,100)
RandomBlock(-5,57,1,rustic:iron_lattice:0,5,CONCRETE_POWDER:8,10,quark:limestone:1,15,quark:limestone,15,quark:world_stone_pavement:2,15,CONCRETE:8,100)
RandomBlock(-5,57,2,rustic:iron_lattice:0,5,CONCRETE_POWDER:8,10,quark:limestone:1,15,quark:limestone,15,quark:world_stone_pavement:2,15,CONCRETE:8,100)
RandomBlock(-5,57,3,rustic:iron_lattice:0,5,CONCRETE_POWDER:8,10,quark:limestone:1,15,quark:limestone,15,quark:world_stone_pavement:2,15,CONCRETE:8,100)
RandomBlock(-5,57,4,rustic:iron_lattice:0,5,CONCRETE_POWDER:8,10,quark:limestone:1,15,quark:limestone,15,quark:world_stone_pavement:2,15,CONCRETE:8,100)
RandomBlock(-5,57,5,rustic:iron_lattice:0,5,CONCRETE_POWDER:8,10,quark:limestone:1,15,quark:limestone,15,quark:world_stone_pavement:2,15,CONCRETE:8,100)
RandomBlock(-5,57,6,rustic:iron_lattice:0,5,CONCRETE_POWDER:8,10,quark:limestone:1,15,quark:limestone,15,quark:world_stone_pavement:2,15,CONCRETE:8,100)
RandomBlock(-5,57,7,rustic:iron_lattice:0,5,CONCRETE_POWDER:8,10,quark:limestone:1,15,quark:limestone,15,quark:world_stone_pavement:2,15,CONCRETE:8,100)
RandomBlock(-5,57,8,rustic:iron_lattice:0,5,CONCRETE_POWDER:8,10,quark:limestone:1,15,quark:limestone,15,quark:world_stone_pavement:2,15,CONCRETE:8,100)
RandomBlock(-5,58,-1,rustic:iron_lattice:0,5,CONCRETE_POWDER:8,10,quark:limestone:1,15,quark:limestone,15,quark:world_stone_pavement:2,15,CONCRETE:8,100)
RandomBlock(-5,58,0,rustic:iron_lattice:0,5,CONCRETE_POWDER:8,10,quark:limestone:1,15,quark:limestone,15,quark:world_stone_pavement:2,15,CONCRETE:8,100)
RandomBlock(-5,58,1,rustic:iron_lattice:0,5,CONCRETE_POWDER:8,10,quark:limestone:1,15,quark:limestone,15,quark:world_stone_pavement:2,15,CONCRETE:8,100)
RandomBlock(-5,58,2,rustic:iron_lattice:0,5,CONCRETE_POWDER:8,10,quark:limestone:1,15,quark:limestone,15,quark:world_stone_pavement:2,15,CONCRETE:8,100)
RandomBlock(-5,58,3,rustic:iron_lattice:0,5,CONCRETE_POWDER:8,10,quark:limestone:1,15,quark:limestone,15,quark:world_stone_pavement:2,15,CONCRETE:8,100)
RandomBlock(-5,58,4,rustic:iron_lattice:0,5,CONCRETE_POWDER:8,10,quark:limestone:1,15,quark:limestone,15,quark:world_stone_pavement:2,15,CONCRETE:8,100)
RandomBlock(-5,58,5,rustic:iron_lattice:0,5,CONCRETE_POWDER:8,10,quark:limestone:1,15,quark:limestone,15,quark:world_stone_pavement:2,15,CONCRETE:8,100)
RandomBlock(-5,58,6,rustic:iron_lattice:0,5,CONCRETE_POWDER:8,10,quark:limestone:1,15,quark:limestone,15,quark:world_stone_pavement:2,15,CONCRETE:8,100)
RandomBlock(-5,58,8,rustic:iron_lattice:0,5,CONCRETE_POWDER:8,10,quark:limestone:1,15,quark:limestone,15,quark:world_stone_pavement:2,15,CONCRETE:8,100)
Block(-5,59,-1,IRON_FENCE:0)
Block(-5,59,0,IRON_FENCE:0)
Block(-5,59,1,IRON_FENCE:0)
Block(-5,59,2,IRON_FENCE:0)
Block(-5,59,3,IRON_FENCE:0)
Block(-5,59,4,IRON_FENCE:0)
Block(-5,59,5,IRON_FENCE:0)
Block(-5,59,6,IRON_FENCE:0)
Block(-5,59,7,quark:iron_plate:1)
Block(-5,59,8,IRON_FENCE:0)
Block(-4,43,-2,STONE:6)
Block(-4,43,-1,STONE:6)
Block(-4,43,0,STONE:6)
Block(-4,43,1,STONE:6)
Block(-4,43,2,STONE:6)
Block(-4,43,3,STONE:6)
Block(-4,43,4,STONE:6)
Block(-4,43,5,STONE:6)
Block(-4,43,6,STONE:6)
Block(-4,44,-2,STONE:6)
RandomBlock(-4,44,-1,rustic:iron_lattice:0,5,STAINED_CLAY:15,5,STAINED_CLAY:7,5,quark:iron_plate_slab:8,15,quark:world_stone_pavement:2,15,STAINED_CLAY:9,100)
RandomBlock(-4,44,0,rustic:iron_lattice:0,5,STAINED_CLAY:15,5,STAINED_CLAY:7,5,quark:iron_plate_slab:8,15,quark:world_stone_pavement:2,15,STAINED_CLAY:9,100)
RandomBlock(-4,44,1,rustic:iron_lattice:0,5,STAINED_CLAY:15,5,STAINED_CLAY:7,5,quark:iron_plate_slab:8,15,quark:world_stone_pavement:2,15,STAINED_CLAY:9,100)
RandomBlock(-4,44,2,rustic:iron_lattice:0,5,STAINED_CLAY:15,5,STAINED_CLAY:7,5,quark:iron_plate_slab:8,15,quark:world_stone_pavement:2,15,STAINED_CLAY:9,100)
RandomBlock(-4,44,3,rustic:iron_lattice:0,5,STAINED_CLAY:15,5,STAINED_CLAY:7,5,quark:iron_plate_slab:8,15,quark:world_stone_pavement:2,15,STAINED_CLAY:9,100)
RandomBlock(-4,44,4,rustic:iron_lattice:0,5,STAINED_CLAY:15,5,STAINED_CLAY:7,5,quark:iron_plate_slab:8,15,quark:world_stone_pavement:2,15,STAINED_CLAY:9,100)
RandomBlock(-4,44,5,rustic:iron_lattice:0,5,STAINED_CLAY:15,5,STAINED_CLAY:7,5,quark:iron_plate_slab:8,15,quark:world_stone_pavement:2,15,STAINED_CLAY:9,100)
RandomBlock(-4,44,6,rustic:iron_lattice:0,5,STAINED_CLAY:15,5,STAINED_CLAY:7,5,quark:iron_plate_slab:8,15,quark:world_stone_pavement:2,15,STAINED_CLAY:9,100)
RandomBlock(-4,44,7,rustic:iron_lattice:0,5,STAINED_CLAY:15,5,STAINED_CLAY:7,5,quark:iron_plate_slab:8,15,quark:world_stone_pavement:2,15,STAINED_CLAY:9,100)
RandomBlock(-4,44,8,rustic:iron_lattice:0,5,STAINED_CLAY:15,5,STAINED_CLAY:7,5,quark:iron_plate_slab:8,15,quark:world_stone_pavement:2,15,STAINED_CLAY:9,100)
Block(-4,45,-2,STONE:6)
RandomBlock(-4,45,-1,rustic:iron_lattice:0,5,CONCRETE_POWDER:8,10,quark:limestone:1,15,quark:limestone,15,quark:world_stone_pavement:2,15,CONCRETE:8,100)
Block(-4,45,0,MOB_SPAWNER:0,../../ruins_spawners/industrial_multi.nbt)
RandomBlock(-4,45,1,variedcommodities:crate:5,5,charm:crate_sealed:5,../../../../Chests/RLCraft/Containers/charm_crate.nbt,10,charm:crate_sealed:5,../../../../Chests/RLCraft/Containers/charm_crate.nbt,100)
RandomBlock(-4,45,2,variedcommodities:crate:5,5,charm:crate_sealed:5,../../../../Chests/RLCraft/Containers/charm_crate.nbt,10,charm:crate_sealed:5,../../../../Chests/RLCraft/Containers/charm_crate.nbt,100)
RandomBlock(-4,45,5,rustic:iron_lattice:0,5,CONCRETE_POWDER:8,10,quark:limestone:1,15,quark:limestone,15,quark:world_stone_pavement:2,15,CONCRETE:8,100)
Block(-4,45,6,SMOOTH_STAIRS:5)
Block(-4,46,-2,STONE:6)
Block(-4,46,-1,CONCRETE:15)
RandomBlock(-4,46,0,variedcommodities:crate:5,5,charm:crate_sealed:5,../../../../Chests/RLCraft/Containers/charm_crate.nbt,10,charm:crate_sealed:5,../../../../Chests/RLCraft/Containers/charm_crate.nbt,100)
Block(-4,46,5,CONCRETE:15)
Block(-4,47,-2,STONE:6)
RandomBlock(-4,47,-1,rustic:iron_lattice:0,5,CONCRETE_POWDER:8,10,quark:limestone:1,15,quark:limestone,15,quark:world_stone_pavement:2,15,CONCRETE:8,100)
RandomBlock(-4,47,5,rustic:iron_lattice:0,5,CONCRETE_POWDER:8,10,quark:limestone:1,15,quark:limestone,15,quark:world_stone_pavement:2,15,CONCRETE:8,100)
Block(-4,48,-2,STONE:6)
RandomBlock(-4,48,-1,rustic:iron_lattice:0,5,CONCRETE_POWDER:8,10,quark:limestone:1,15,quark:limestone,15,quark:world_stone_pavement:2,15,CONCRETE:8,100)
RandomBlock(-4,48,5,rustic:iron_lattice:0,5,CONCRETE_POWDER:8,10,quark:limestone:1,15,quark:limestone,15,quark:world_stone_pavement:2,15,CONCRETE:8,100)
Block(-4,49,-2,STONE:6)
RandomBlock(-4,49,-1,rustic:iron_lattice:0,5,CONCRETE_POWDER:8,10,quark:limestone:1,15,quark:limestone,15,quark:world_stone_pavement:2,15,CONCRETE:8,100)
RandomBlock(-4,49,0,rustic:iron_lattice:0,5,CONCRETE_POWDER:8,10,quark:limestone:1,15,quark:limestone,15,quark:world_stone_pavement:2,15,CONCRETE:8,100)
RandomBlock(-4,49,1,rustic:iron_lattice:0,5,CONCRETE_POWDER:8,10,quark:limestone:1,15,quark:limestone,15,quark:world_stone_pavement:2,15,CONCRETE:8,100)
RandomBlock(-4,49,2,rustic:iron_lattice:0,5,CONCRETE_POWDER:8,10,quark:limestone:1,15,quark:limestone,15,quark:world_stone_pavement:2,15,CONCRETE:8,100)
RandomBlock(-4,49,3,rustic:iron_lattice:0,5,CONCRETE_POWDER:8,10,quark:limestone:1,15,quark:limestone,15,quark:world_stone_pavement:2,15,CONCRETE:8,100)
RandomBlock(-4,49,4,rustic:iron_lattice:0,5,CONCRETE_POWDER:8,10,quark:limestone:1,15,quark:limestone,15,quark:world_stone_pavement:2,15,CONCRETE:8,100)
RandomBlock(-4,49,5,rustic:iron_lattice:0,5,CONCRETE_POWDER:8,10,quark:limestone:1,15,quark:limestone,15,quark:world_stone_pavement:2,15,CONCRETE:8,100)
Block(-4,50,-2,STONE:6)
RandomBlock(-4,50,-1,rustic:iron_lattice:0,5,CONCRETE_POWDER:8,10,quark:limestone:1,15,quark:limestone,15,quark:world_stone_pavement:2,15,CONCRETE:8,100)
RandomBlock(-4,50,0,rustic:iron_lattice:0,5,STAINED_CLAY:15,5,STAINED_CLAY:7,5,quark:iron_plate_slab:8,15,quark:world_stone_pavement:2,15,STAINED_CLAY:9,100)
RandomBlock(-4,50,1,rustic:iron_lattice:0,5,STAINED_CLAY:15,5,STAINED_CLAY:7,5,quark:iron_plate_slab:8,15,quark:world_stone_pavement:2,15,STAINED_CLAY:9,100)
RandomBlock(-4,50,2,rustic:iron_lattice:0,5,STAINED_CLAY:15,5,STAINED_CLAY:7,5,quark:iron_plate_slab:8,15,quark:world_stone_pavement:2,15,STAINED_CLAY:9,100)
RandomBlock(-4,50,3,rustic:iron_lattice:0,5,STAINED_CLAY:15,5,STAINED_CLAY:7,5,quark:iron_plate_slab:8,15,quark:world_stone_pavement:2,15,STAINED_CLAY:9,100)
RandomBlock(-4,50,4,rustic:iron_lattice:0,5,STAINED_CLAY:15,5,STAINED_CLAY:7,5,quark:iron_plate_slab:8,15,quark:world_stone_pavement:2,15,STAINED_CLAY:9,100)
RandomBlock(-4,50,5,rustic:iron_lattice:0,5,CONCRETE_POWDER:8,10,quark:limestone:1,15,quark:limestone,15,quark:world_stone_pavement:2,15,CONCRETE:8,100)
RandomBlock(-4,50,6,rustic:iron_lattice:0,5,STAINED_CLAY:15,5,STAINED_CLAY:7,5,quark:iron_plate_slab:8,15,quark:world_stone_pavement:2,15,STAINED_CLAY:9,100)
RandomBlock(-4,50,7,rustic:iron_lattice:0,5,STAINED_CLAY:15,5,STAINED_CLAY:7,5,quark:iron_plate_slab:8,15,quark:world_stone_pavement:2,15,STAINED_CLAY:9,100)
RandomBlock(-4,50,8,rustic:iron_lattice:0,5,STAINED_CLAY:15,5,STAINED_CLAY:7,5,quark:iron_plate_slab:8,15,quark:world_stone_pavement:2,15,STAINED_CLAY:9,100)
Block(-4,51,-2,STONE:6)
RandomBlock(-4,51,-1,rustic:iron_lattice:0,5,CONCRETE_POWDER:8,10,quark:limestone:1,15,quark:limestone,15,quark:world_stone_pavement:2,15,CONCRETE:8,100)
RandomBlock(-4,51,0,CHEST:5,../../../../Chests/Loot/moderncity_junk_loot.nbt,20,CHEST:5../../../../Chests/Loot/moderncity_rare_loot.nbt,10,CHEST:5,../../../../Chests/RLCraft/Ruins/industrial.nbt,50,CHEST:5,../../../../Chests/RLCraft/Ruins/rubble.nbt,100)
Block(-4,51,1,SMOOTH_STAIRS:1)
RandomBlock(-4,51,2,rustic:iron_lattice:0,5,CONCRETE_POWDER:8,10,quark:limestone:1,15,quark:limestone,15,quark:world_stone_pavement:2,15,CONCRETE:8,100)
RandomBlock(-4,51,5,rustic:iron_lattice:0,5,CONCRETE_POWDER:8,10,quark:limestone:1,15,quark:limestone,15,quark:world_stone_pavement:2,15,CONCRETE:8,100)
Block(-4,52,-2,STONE:6)
Block(-4,52,-1,CONCRETE:15)
RandomBlock(-4,52,2,rustic:iron_lattice:0,5,CONCRETE_POWDER:8,10,quark:limestone:1,15,quark:limestone,15,quark:world_stone_pavement:2,15,CONCRETE:8,100)
Block(-4,52,5,CONCRETE:15)
Block(-4,53,-2,STONE:6)
RandomBlock(-4,53,-1,rustic:iron_lattice:0,5,CONCRETE_POWDER:8,10,quark:limestone:1,15,quark:limestone,15,quark:world_stone_pavement:2,15,CONCRETE:8,100)
RandomBlock(-4,53,2,rustic:iron_lattice:0,5,CONCRETE_POWDER:8,10,quark:limestone:1,15,quark:limestone,15,quark:world_stone_pavement:2,15,CONCRETE:8,100)
RandomBlock(-4,53,5,rustic:iron_lattice:0,5,CONCRETE_POWDER:8,10,quark:limestone:1,15,quark:limestone,15,quark:world_stone_pavement:2,15,CONCRETE:8,100)
Block(-4,53,7,quark:iron_plate:1)
Block(-4,54,-2,STONE:6)
RandomBlock(-4,54,-1,rustic:iron_lattice:0,5,CONCRETE_POWDER:8,10,quark:limestone:1,15,quark:limestone,15,quark:world_stone_pavement:2,15,CONCRETE:8,100)
RandomBlock(-4,54,0,rustic:iron_lattice:0,5,CONCRETE_POWDER:8,10,quark:limestone:1,15,quark:limestone,15,quark:world_stone_pavement:2,15,CONCRETE:8,100)
RandomBlock(-4,54,1,rustic:iron_lattice:0,5,CONCRETE_POWDER:8,10,quark:limestone:1,15,quark:limestone,15,quark:world_stone_pavement:2,15,CONCRETE:8,100)
RandomBlock(-4,54,2,rustic:iron_lattice:0,5,CONCRETE_POWDER:8,10,quark:limestone:1,15,quark:limestone,15,quark:world_stone_pavement:2,15,CONCRETE:8,100)
RandomBlock(-4,54,3,rustic:iron_lattice:0,5,CONCRETE_POWDER:8,10,quark:limestone:1,15,quark:limestone,15,quark:world_stone_pavement:2,15,CONCRETE:8,100)
RandomBlock(-4,54,4,rustic:iron_lattice:0,5,CONCRETE_POWDER:8,10,quark:limestone:1,15,quark:limestone,15,quark:world_stone_pavement:2,15,CONCRETE:8,100)
RandomBlock(-4,54,5,rustic:iron_lattice:0,5,CONCRETE_POWDER:8,10,quark:limestone:1,15,quark:limestone,15,quark:world_stone_pavement:2,15,CONCRETE:8,100)
RandomBlock(-4,54,6,rustic:iron_lattice:0,5,CONCRETE_POWDER:8,10,quark:limestone:1,15,quark:limestone,15,quark:world_stone_pavement:2,15,CONCRETE:8,100)
RandomBlock(-4,54,7,rustic:iron_lattice:0,5,CONCRETE_POWDER:8,10,quark:limestone:1,15,quark:limestone,15,quark:world_stone_pavement:2,15,CONCRETE:8,100)
RandomBlock(-4,54,8,rustic:iron_lattice:0,5,CONCRETE_POWDER:8,10,quark:limestone:1,15,quark:limestone,15,quark:world_stone_pavement:2,15,CONCRETE:8,100)
Block(-4,55,-2,STONE:6)
RandomBlock(-4,55,-1,rustic:iron_lattice:0,5,CONCRETE_POWDER:8,10,quark:limestone:1,15,quark:limestone,15,quark:world_stone_pavement:2,15,CONCRETE:8,100)
Block(-4,56,-2,STONE:6)
RandomBlock(-4,56,-1,rustic:iron_lattice:0,5,CONCRETE_POWDER:8,10,quark:limestone:1,15,quark:limestone,15,quark:world_stone_pavement:2,15,CONCRETE:8,100)
Block(-4,57,-2,STONE:6)
RandomBlock(-4,57,-1,rustic:iron_lattice:0,5,CONCRETE_POWDER:8,10,quark:limestone:1,15,quark:limestone,15,quark:world_stone_pavement:2,15,CONCRETE:8,100)
Block(-4,58,-2,STONE:6)
RandomBlock(-4,58,-1,rustic:iron_lattice:0,5,CONCRETE_POWDER:8,10,quark:limestone:1,15,quark:limestone,15,quark:world_stone_pavement:2,15,CONCRETE:8,100)
RandomBlock(-4,58,0,SMOOTH_BRICK:0,40,SMOOTH_BRICK:1,20,SMOOTH_BRICK:2,30,SMOOTH_BRICK:0,100)
Block(-4,58,1,STEP:5)
Block(-4,58,2,STEP:5)
Block(-4,58,3,STEP:5)
Block(-4,58,4,STEP:5)
Block(-4,58,5,STEP:5)
Block(-4,58,6,STEP:5)
Block(-4,58,7,STEP:5)
Block(-4,58,8,STEP:5)
Block(-4,59,-2,STONE:6)
Block(-4,59,-1,STONE:6)
Block(-4,59,0,STONE:6)
Block(-4,59,7,quark:iron_plate:1)
Block(-3,43,4,STONE:6)
Block(-3,43,6,STONE:6)
RandomBlock(-3,44,-1,rustic:iron_lattice:0,5,STAINED_CLAY:15,5,STAINED_CLAY:7,5,quark:iron_plate_slab:8,15,quark:world_stone_pavement:2,15,STAINED_CLAY:9,100)
RandomBlock(-3,44,0,rustic:iron_lattice:0,5,STAINED_CLAY:15,5,STAINED_CLAY:7,5,quark:iron_plate_slab:8,15,quark:world_stone_pavement:2,15,STAINED_CLAY:9,100)
RandomBlock(-3,44,1,rustic:iron_lattice:0,5,STAINED_CLAY:15,5,STAINED_CLAY:7,5,quark:iron_plate_slab:8,15,quark:world_stone_pavement:2,15,STAINED_CLAY:9,100)
RandomBlock(-3,44,2,rustic:iron_lattice:0,5,STAINED_CLAY:15,5,STAINED_CLAY:7,5,quark:iron_plate_slab:8,15,quark:world_stone_pavement:2,15,STAINED_CLAY:9,100)
RandomBlock(-3,44,3,rustic:iron_lattice:0,5,STAINED_CLAY:15,5,STAINED_CLAY:7,5,quark:iron_plate_slab:8,15,quark:world_stone_pavement:2,15,STAINED_CLAY:9,100)
RandomBlock(-3,44,4,rustic:iron_lattice:0,5,STAINED_CLAY:15,5,STAINED_CLAY:7,5,quark:iron_plate_slab:8,15,quark:world_stone_pavement:2,15,STAINED_CLAY:9,100)
RandomBlock(-3,44,5,rustic:iron_lattice:0,5,STAINED_CLAY:15,5,STAINED_CLAY:7,5,quark:iron_plate_slab:8,15,quark:world_stone_pavement:2,15,STAINED_CLAY:9,100)
RandomBlock(-3,44,6,rustic:iron_lattice:0,5,STAINED_CLAY:15,5,STAINED_CLAY:7,5,quark:iron_plate_slab:8,15,quark:world_stone_pavement:2,15,STAINED_CLAY:9,100)
RandomBlock(-3,44,7,rustic:iron_lattice:0,5,STAINED_CLAY:15,5,STAINED_CLAY:7,5,quark:iron_plate_slab:8,15,quark:world_stone_pavement:2,15,STAINED_CLAY:9,100)
RandomBlock(-3,44,8,rustic:iron_lattice:0,5,STAINED_CLAY:15,5,STAINED_CLAY:7,5,quark:iron_plate_slab:8,15,quark:world_stone_pavement:2,15,STAINED_CLAY:9,100)
RandomBlock(-3,45,-1,rustic:iron_lattice:0,5,CONCRETE_POWDER:8,10,quark:limestone:1,15,quark:limestone,15,quark:world_stone_pavement:2,15,CONCRETE:8,100)
Block(-3,45,0,quark:iron_plate_stairs:5)
Block(-3,45,5,biomesoplenty:fir_door_block:1)
Block(-3,46,-1,CONCRETE:15)
Block(-3,46,5,biomesoplenty:fir_door_block:9)
Block(-3,46,8,quark:iron_button:2)
RandomBlock(-3,47,-1,rustic:iron_lattice:0,5,CONCRETE_POWDER:8,10,quark:limestone:1,15,quark:limestone,15,quark:world_stone_pavement:2,15,CONCRETE:8,100)
RandomBlock(-3,47,5,rustic:iron_lattice:0,5,CONCRETE_POWDER:8,10,quark:limestone:1,15,quark:limestone,15,quark:world_stone_pavement:2,15,CONCRETE:8,100)
RandomBlock(-3,48,-1,rustic:iron_lattice:0,5,CONCRETE_POWDER:8,10,quark:limestone:1,15,quark:limestone,15,quark:world_stone_pavement:2,15,CONCRETE:8,100)
RandomBlock(-3,48,5,rustic:iron_lattice:0,5,CONCRETE_POWDER:8,10,quark:limestone:1,15,quark:limestone,15,quark:world_stone_pavement:2,15,CONCRETE:8,100)
RandomBlock(-3,49,-1,rustic:iron_lattice:0,5,CONCRETE_POWDER:8,10,quark:limestone:1,15,quark:limestone,15,quark:world_stone_pavement:2,15,CONCRETE:8,100)
RandomBlock(-3,49,0,rustic:iron_lattice:0,5,CONCRETE_POWDER:8,10,quark:limestone:1,15,quark:limestone,15,quark:world_stone_pavement:2,15,CONCRETE:8,100)
RandomBlock(-3,49,1,rustic:iron_lattice:0,5,CONCRETE_POWDER:8,10,quark:limestone:1,15,quark:limestone,15,quark:world_stone_pavement:2,15,CONCRETE:8,100)
Block(-3,49,2,REDSTONE_LAMP_OFF:0)
RandomBlock(-3,49,3,rustic:iron_lattice:0,5,CONCRETE_POWDER:8,10,quark:limestone:1,15,quark:limestone,15,quark:world_stone_pavement:2,15,CONCRETE:8,100)
RandomBlock(-3,49,4,rustic:iron_lattice:0,5,CONCRETE_POWDER:8,10,quark:limestone:1,15,quark:limestone,15,quark:world_stone_pavement:2,15,CONCRETE:8,100)
RandomBlock(-3,49,5,rustic:iron_lattice:0,5,CONCRETE_POWDER:8,10,quark:limestone:1,15,quark:limestone,15,quark:world_stone_pavement:2,15,CONCRETE:8,100)
RandomBlock(-3,50,-1,rustic:iron_lattice:0,5,CONCRETE_POWDER:8,10,quark:limestone:1,15,quark:limestone,15,quark:world_stone_pavement:2,15,CONCRETE:8,100)
RandomBlock(-3,50,0,rustic:iron_lattice:0,5,STAINED_CLAY:15,5,STAINED_CLAY:7,5,quark:iron_plate_slab:8,15,quark:world_stone_pavement:2,15,STAINED_CLAY:9,100)
RandomBlock(-3,50,1,rustic:iron_lattice:0,5,STAINED_CLAY:15,5,STAINED_CLAY:7,5,quark:iron_plate_slab:8,15,quark:world_stone_pavement:2,15,STAINED_CLAY:9,100)
RandomBlock(-3,50,2,rustic:iron_lattice:0,5,STAINED_CLAY:15,5,STAINED_CLAY:7,5,quark:iron_plate_slab:8,15,quark:world_stone_pavement:2,15,STAINED_CLAY:9,100)
RandomBlock(-3,50,3,rustic:iron_lattice:0,5,STAINED_CLAY:15,5,STAINED_CLAY:7,5,quark:iron_plate_slab:8,15,quark:world_stone_pavement:2,15,STAINED_CLAY:9,100)
RandomBlock(-3,50,4,rustic:iron_lattice:0,5,STAINED_CLAY:15,5,STAINED_CLAY:7,5,quark:iron_plate_slab:8,15,quark:world_stone_pavement:2,15,STAINED_CLAY:9,100)
RandomBlock(-3,50,5,rustic:iron_lattice:0,5,CONCRETE_POWDER:8,10,quark:limestone:1,15,quark:limestone,15,quark:world_stone_pavement:2,15,CONCRETE:8,100)
RandomBlock(-3,50,6,rustic:iron_lattice:0,5,STAINED_CLAY:15,5,STAINED_CLAY:7,5,quark:iron_plate_slab:8,15,quark:world_stone_pavement:2,15,STAINED_CLAY:9,100)
RandomBlock(-3,50,7,rustic:iron_lattice:0,5,STAINED_CLAY:15,5,STAINED_CLAY:7,5,quark:iron_plate_slab:8,15,quark:world_stone_pavement:2,15,STAINED_CLAY:9,100)
RandomBlock(-3,50,8,rustic:iron_lattice:0,5,STAINED_CLAY:15,5,STAINED_CLAY:7,5,quark:iron_plate_slab:8,15,quark:world_stone_pavement:2,15,STAINED_CLAY:9,100)
RandomBlock(-3,51,-1,rustic:iron_lattice:0,5,CONCRETE_POWDER:8,10,quark:limestone:1,15,quark:limestone,15,quark:world_stone_pavement:2,15,CONCRETE:8,100)
RandomBlock(-3,51,2,rustic:iron_lattice:0,5,CONCRETE_POWDER:8,10,quark:limestone:1,15,quark:limestone,15,quark:world_stone_pavement:2,15,CONCRETE:8,100)
RandomBlock(-3,51,5,rustic:iron_lattice:0,5,CONCRETE_POWDER:8,10,quark:limestone:1,15,quark:limestone,15,quark:world_stone_pavement:2,15,CONCRETE:8,100)
Block(-3,52,-1,CONCRETE:15)
RandomBlock(-3,52,2,rustic:iron_lattice:0,5,CONCRETE_POWDER:8,10,quark:limestone:1,15,quark:limestone,15,quark:world_stone_pavement:2,15,CONCRETE:8,100)
Block(-3,52,5,CONCRETE:15)
RandomBlock(-3,53,-1,rustic:iron_lattice:0,5,CONCRETE_POWDER:8,10,quark:limestone:1,15,quark:limestone,15,quark:world_stone_pavement:2,15,CONCRETE:8,100)
RandomBlock(-3,53,2,rustic:iron_lattice:0,5,CONCRETE_POWDER:8,10,quark:limestone:1,15,quark:limestone,15,quark:world_stone_pavement:2,15,CONCRETE:8,100)
RandomBlock(-3,53,5,rustic:iron_lattice:0,5,CONCRETE_POWDER:8,10,quark:limestone:1,15,quark:limestone,15,quark:world_stone_pavement:2,15,CONCRETE:8,100)
Block(-3,53,7,quark:iron_plate:1)
RandomBlock(-3,54,-1,rustic:iron_lattice:0,5,CONCRETE_POWDER:8,10,quark:limestone:1,15,quark:limestone,15,quark:world_stone_pavement:2,15,CONCRETE:8,100)
RandomBlock(-3,54,0,rustic:iron_lattice:0,5,CONCRETE_POWDER:8,10,quark:limestone:1,15,quark:limestone,15,quark:world_stone_pavement:2,15,CONCRETE:8,100)
RandomBlock(-3,54,1,rustic:iron_lattice:0,5,CONCRETE_POWDER:8,10,quark:limestone:1,15,quark:limestone,15,quark:world_stone_pavement:2,15,CONCRETE:8,100)
RandomBlock(-3,54,2,rustic:iron_lattice:0,5,CONCRETE_POWDER:8,10,quark:limestone:1,15,quark:limestone,15,quark:world_stone_pavement:2,15,CONCRETE:8,100)
RandomBlock(-3,54,3,rustic:iron_lattice:0,5,CONCRETE_POWDER:8,10,quark:limestone:1,15,quark:limestone,15,quark:world_stone_pavement:2,15,CONCRETE:8,100)
RandomBlock(-3,54,4,rustic:iron_lattice:0,5,CONCRETE_POWDER:8,10,quark:limestone:1,15,quark:limestone,15,quark:world_stone_pavement:2,15,CONCRETE:8,100)
RandomBlock(-3,54,5,rustic:iron_lattice:0,5,CONCRETE_POWDER:8,10,quark:limestone:1,15,quark:limestone,15,quark:world_stone_pavement:2,15,CONCRETE:8,100)
RandomBlock(-3,54,6,rustic:iron_lattice:0,5,CONCRETE_POWDER:8,10,quark:limestone:1,15,quark:limestone,15,quark:world_stone_pavement:2,15,CONCRETE:8,100)
RandomBlock(-3,54,7,rustic:iron_lattice:0,5,CONCRETE_POWDER:8,10,quark:limestone:1,15,quark:limestone,15,quark:world_stone_pavement:2,15,CONCRETE:8,100)
RandomBlock(-3,54,8,rustic:iron_lattice:0,5,CONCRETE_POWDER:8,10,quark:limestone:1,15,quark:limestone,15,quark:world_stone_pavement:2,15,CONCRETE:8,100)
RandomBlock(-3,55,-1,rustic:iron_lattice:0,5,CONCRETE_POWDER:8,10,quark:limestone:1,15,quark:limestone,15,quark:world_stone_pavement:2,15,CONCRETE:8,100)
Block(-3,55,1,DOUBLE_STEP:0)
Block(-3,55,2,DOUBLE_STEP:0)
Block(-3,55,6,DOUBLE_STEP:0)
Block(-3,55,7,DOUBLE_STEP:0)
RandomBlock(-3,56,-1,rustic:iron_lattice:0,5,CONCRETE_POWDER:8,10,quark:limestone:1,15,quark:limestone,15,quark:world_stone_pavement:2,15,CONCRETE:8,100)
Block(-3,56,1,rustic:iron_lattice:0)
Block(-3,56,2,rustic:iron_lattice:0)
Block(-3,56,6,rustic:iron_lattice:0)
Block(-3,56,7,rustic:iron_lattice:0)
RandomBlock(-3,57,-1,rustic:iron_lattice:0,5,CONCRETE_POWDER:8,10,quark:limestone:1,15,quark:limestone,15,quark:world_stone_pavement:2,15,CONCRETE:8,100)
Block(-3,57,1,quark:basalt_wall)
Block(-3,57,2,STEP:0)
Block(-3,57,6,quark:basalt_wall)
Block(-3,57,7,STEP:0)
RandomBlock(-3,58,-1,rustic:iron_lattice:0,5,CONCRETE_POWDER:8,10,quark:limestone:1,15,quark:limestone,15,quark:world_stone_pavement:2,15,CONCRETE:8,100)
Block(-3,58,0,STEP:5)
Block(-3,58,1,STEP:5)
Block(-3,58,2,STEP:5)
Block(-3,58,3,STEP:5)
Block(-3,58,4,STEP:5)
Block(-3,58,5,STEP:5)
Block(-3,58,6,STEP:5)
Block(-3,58,7,STEP:5)
Block(-3,58,8,STEP:5)
Block(-3,59,-1,IRON_FENCE:0)
Block(-3,59,7,quark:iron_plate:1)
Block(-2,43,-2,STONE:6)
Block(-2,43,-1,STONE:6)
Block(-2,43,0,STONE:6)
Block(-2,43,1,STONE:6)
Block(-2,43,2,STONE:6)
Block(-2,43,3,STONE:6)
Block(-2,43,4,STONE:6)
Block(-2,43,6,STONE:6)
Block(-2,44,-2,STONE:6)
RandomBlock(-2,44,-1,rustic:iron_lattice:0,5,STAINED_CLAY:15,5,STAINED_CLAY:7,5,quark:iron_plate_slab:8,15,quark:world_stone_pavement:2,15,STAINED_CLAY:9,100)
RandomBlock(-2,44,0,rustic:iron_lattice:0,5,STAINED_CLAY:15,5,STAINED_CLAY:7,5,quark:iron_plate_slab:8,15,quark:world_stone_pavement:2,15,STAINED_CLAY:9,100)
RandomBlock(-2,44,1,rustic:iron_lattice:0,5,STAINED_CLAY:15,5,STAINED_CLAY:7,5,quark:iron_plate_slab:8,15,quark:world_stone_pavement:2,15,STAINED_CLAY:9,100)
RandomBlock(-2,44,2,rustic:iron_lattice:0,5,STAINED_CLAY:15,5,STAINED_CLAY:7,5,quark:iron_plate_slab:8,15,quark:world_stone_pavement:2,15,STAINED_CLAY:9,100)
RandomBlock(-2,44,3,rustic:iron_lattice:0,5,STAINED_CLAY:15,5,STAINED_CLAY:7,5,quark:iron_plate_slab:8,15,quark:world_stone_pavement:2,15,STAINED_CLAY:9,100)
RandomBlock(-2,44,4,rustic:iron_lattice:0,5,STAINED_CLAY:15,5,STAINED_CLAY:7,5,quark:iron_plate_slab:8,15,quark:world_stone_pavement:2,15,STAINED_CLAY:9,100)
RandomBlock(-2,44,5,rustic:iron_lattice:0,5,STAINED_CLAY:15,5,STAINED_CLAY:7,5,quark:iron_plate_slab:8,15,quark:world_stone_pavement:2,15,STAINED_CLAY:9,100)
RandomBlock(-2,44,6,rustic:iron_lattice:0,5,STAINED_CLAY:15,5,STAINED_CLAY:7,5,quark:iron_plate_slab:8,15,quark:world_stone_pavement:2,15,STAINED_CLAY:9,100)
RandomBlock(-2,44,7,rustic:iron_lattice:0,5,STAINED_CLAY:15,5,STAINED_CLAY:7,5,quark:iron_plate_slab:8,15,quark:world_stone_pavement:2,15,STAINED_CLAY:9,100)
RandomBlock(-2,44,8,rustic:iron_lattice:0,5,STAINED_CLAY:15,5,STAINED_CLAY:7,5,quark:iron_plate_slab:8,15,quark:world_stone_pavement:2,15,STAINED_CLAY:9,100)
Block(-2,45,-2,STONE:6)
RandomBlock(-2,45,-1,rustic:iron_lattice:0,5,CONCRETE_POWDER:8,10,quark:limestone:1,15,quark:limestone,15,quark:world_stone_pavement:2,15,CONCRETE:8,100)
Block(-2,45,0,quark:iron_plate_slab:8)
RandomBlock(-2,45,5,rustic:iron_lattice:0,5,CONCRETE_POWDER:8,10,quark:limestone:1,15,quark:limestone,15,quark:world_stone_pavement:2,15,CONCRETE:8,100)
RandomBlock(-2,45,6,rustic:iron_lattice:0,5,CONCRETE_POWDER:8,10,quark:limestone:1,15,quark:limestone,15,quark:world_stone_pavement:2,15,CONCRETE:8,100)
RandomBlock(-2,45,7,rustic:iron_lattice:0,5,CONCRETE_POWDER:8,10,quark:limestone:1,15,quark:limestone,15,quark:world_stone_pavement:2,15,CONCRETE:8,100)
RandomBlock(-2,45,8,rustic:iron_lattice:0,5,CONCRETE_POWDER:8,10,quark:limestone:1,15,quark:limestone,15,quark:world_stone_pavement:2,15,CONCRETE:8,100)
Block(-2,46,-2,STONE:6)
Block(-2,46,-1,CONCRETE:15)
Block(-2,46,5,CONCRETE:15)
Block(-2,46,6,CONCRETE:15)
Block(-2,46,7,CONCRETE:15)
Block(-2,46,8,CONCRETE:15)
Block(-2,47,-2,STONE:6)
RandomBlock(-2,47,-1,rustic:iron_lattice:0,5,CONCRETE_POWDER:8,10,quark:limestone:1,15,quark:limestone,15,quark:world_stone_pavement:2,15,CONCRETE:8,100)
RandomBlock(-2,47,5,rustic:iron_lattice:0,5,CONCRETE_POWDER:8,10,quark:limestone:1,15,quark:limestone,15,quark:world_stone_pavement:2,15,CONCRETE:8,100)
RandomBlock(-2,47,6,rustic:iron_lattice:0,5,CONCRETE_POWDER:8,10,quark:limestone:1,15,quark:limestone,15,quark:world_stone_pavement:2,15,CONCRETE:8,100)
RandomBlock(-2,47,7,rustic:iron_lattice:0,5,CONCRETE_POWDER:8,10,quark:limestone:1,15,quark:limestone,15,quark:world_stone_pavement:2,15,CONCRETE:8,100)
RandomBlock(-2,47,8,rustic:iron_lattice:0,5,CONCRETE_POWDER:8,10,quark:limestone:1,15,quark:limestone,15,quark:world_stone_pavement:2,15,CONCRETE:8,100)
Block(-2,48,-2,STONE:6)
RandomBlock(-2,48,-1,rustic:iron_lattice:0,5,CONCRETE_POWDER:8,10,quark:limestone:1,15,quark:limestone,15,quark:world_stone_pavement:2,15,CONCRETE:8,100)
RandomBlock(-2,48,5,rustic:iron_lattice:0,5,CONCRETE_POWDER:8,10,quark:limestone:1,15,quark:limestone,15,quark:world_stone_pavement:2,15,CONCRETE:8,100)
RandomBlock(-2,48,6,rustic:iron_lattice:0,5,CONCRETE_POWDER:8,10,quark:limestone:1,15,quark:limestone,15,quark:world_stone_pavement:2,15,CONCRETE:8,100)
RandomBlock(-2,48,7,rustic:iron_lattice:0,5,CONCRETE_POWDER:8,10,quark:limestone:1,15,quark:limestone,15,quark:world_stone_pavement:2,15,CONCRETE:8,100)
RandomBlock(-2,48,8,rustic:iron_lattice:0,5,CONCRETE_POWDER:8,10,quark:limestone:1,15,quark:limestone,15,quark:world_stone_pavement:2,15,CONCRETE:8,100)
Block(-2,49,-2,STONE:6)
RandomBlock(-2,49,-1,rustic:iron_lattice:0,5,CONCRETE_POWDER:8,10,quark:limestone:1,15,quark:limestone,15,quark:world_stone_pavement:2,15,CONCRETE:8,100)
RandomBlock(-2,49,0,rustic:iron_lattice:0,5,CONCRETE_POWDER:8,10,quark:limestone:1,15,quark:limestone,15,quark:world_stone_pavement:2,15,CONCRETE:8,100)
RandomBlock(-2,49,1,rustic:iron_lattice:0,5,CONCRETE_POWDER:8,10,quark:limestone:1,15,quark:limestone,15,quark:world_stone_pavement:2,15,CONCRETE:8,100)
Block(-2,49,2,REDSTONE_LAMP_OFF:0)
RandomBlock(-2,49,3,rustic:iron_lattice:0,5,CONCRETE_POWDER:8,10,quark:limestone:1,15,quark:limestone,15,quark:world_stone_pavement:2,15,CONCRETE:8,100)
RandomBlock(-2,49,4,rustic:iron_lattice:0,5,CONCRETE_POWDER:8,10,quark:limestone:1,15,quark:limestone,15,quark:world_stone_pavement:2,15,CONCRETE:8,100)
RandomBlock(-2,49,5,rustic:iron_lattice:0,5,CONCRETE_POWDER:8,10,quark:limestone:1,15,quark:limestone,15,quark:world_stone_pavement:2,15,CONCRETE:8,100)
RandomBlock(-2,49,6,rustic:iron_lattice:0,5,CONCRETE_POWDER:8,10,quark:limestone:1,15,quark:limestone,15,quark:world_stone_pavement:2,15,CONCRETE:8,100)
RandomBlock(-2,49,7,rustic:iron_lattice:0,5,CONCRETE_POWDER:8,10,quark:limestone:1,15,quark:limestone,15,quark:world_stone_pavement:2,15,CONCRETE:8,100)
RandomBlock(-2,49,8,rustic:iron_lattice:0,5,CONCRETE_POWDER:8,10,quark:limestone:1,15,quark:limestone,15,quark:world_stone_pavement:2,15,CONCRETE:8,100)
Block(-2,50,-2,STONE:6)
RandomBlock(-2,50,-1,rustic:iron_lattice:0,5,CONCRETE_POWDER:8,10,quark:limestone:1,15,quark:limestone,15,quark:world_stone_pavement:2,15,CONCRETE:8,100)
RandomBlock(-2,50,0,rustic:iron_lattice:0,5,STAINED_CLAY:15,5,STAINED_CLAY:7,5,quark:iron_plate_slab:8,15,quark:world_stone_pavement:2,15,STAINED_CLAY:9,100)
RandomBlock(-2,50,1,rustic:iron_lattice:0,5,STAINED_CLAY:15,5,STAINED_CLAY:7,5,quark:iron_plate_slab:8,15,quark:world_stone_pavement:2,15,STAINED_CLAY:9,100)
RandomBlock(-2,50,2,rustic:iron_lattice:0,5,STAINED_CLAY:15,5,STAINED_CLAY:7,5,quark:iron_plate_slab:8,15,quark:world_stone_pavement:2,15,STAINED_CLAY:9,100)
RandomBlock(-2,50,3,rustic:iron_lattice:0,5,STAINED_CLAY:15,5,STAINED_CLAY:7,5,quark:iron_plate_slab:8,15,quark:world_stone_pavement:2,15,STAINED_CLAY:9,100)
Block(-2,50,4,SMOOTH_STAIRS:1)
RandomBlock(-2,50,5,rustic:iron_lattice:0,5,CONCRETE_POWDER:8,10,quark:limestone:1,15,quark:limestone,15,quark:world_stone_pavement:2,15,CONCRETE:8,100)
RandomBlock(-2,50,6,rustic:iron_lattice:0,5,STAINED_CLAY:15,5,STAINED_CLAY:7,5,quark:iron_plate_slab:8,15,quark:world_stone_pavement:2,15,STAINED_CLAY:9,100)
RandomBlock(-2,50,7,rustic:iron_lattice:0,5,STAINED_CLAY:15,5,STAINED_CLAY:7,5,quark:iron_plate_slab:8,15,quark:world_stone_pavement:2,15,STAINED_CLAY:9,100)
RandomBlock(-2,50,8,rustic:iron_lattice:0,5,STAINED_CLAY:15,5,STAINED_CLAY:7,5,quark:iron_plate_slab:8,15,quark:world_stone_pavement:2,15,STAINED_CLAY:9,100)
Block(-2,51,-2,STONE:6)
RandomBlock(-2,51,-1,rustic:iron_lattice:0,5,CONCRETE_POWDER:8,10,quark:limestone:1,15,quark:limestone,15,quark:world_stone_pavement:2,15,CONCRETE:8,100)
RandomBlock(-2,51,2,rustic:iron_lattice:0,5,CONCRETE_POWDER:8,10,quark:limestone:1,15,quark:limestone,15,quark:world_stone_pavement:2,15,CONCRETE:8,100)
RandomBlock(-2,51,5,rustic:iron_lattice:0,5,CONCRETE_POWDER:8,10,quark:limestone:1,15,quark:limestone,15,quark:world_stone_pavement:2,15,CONCRETE:8,100)
Block(-2,51,7,IRON_FENCE:0)
Block(-2,52,-2,STONE:6)
Block(-2,52,-1,CONCRETE:15)
RandomBlock(-2,52,2,rustic:iron_lattice:0,5,CONCRETE_POWDER:8,10,quark:limestone:1,15,quark:limestone,15,quark:world_stone_pavement:2,15,CONCRETE:8,100)
Block(-2,52,5,CONCRETE:15)
Block(-2,52,7,IRON_FENCE:0)
Block(-2,53,-2,STONE:6)
RandomBlock(-2,53,-1,rustic:iron_lattice:0,5,CONCRETE_POWDER:8,10,quark:limestone:1,15,quark:limestone,15,quark:world_stone_pavement:2,15,CONCRETE:8,100)
RandomBlock(-2,53,2,rustic:iron_lattice:0,5,CONCRETE_POWDER:8,10,quark:limestone:1,15,quark:limestone,15,quark:world_stone_pavement:2,15,CONCRETE:8,100)
RandomBlock(-2,53,5,rustic:iron_lattice:0,5,CONCRETE_POWDER:8,10,quark:limestone:1,15,quark:limestone,15,quark:world_stone_pavement:2,15,CONCRETE:8,100)
Block(-2,53,7,quark:iron_plate:1)
Block(-2,54,-2,STONE:6)
RandomBlock(-2,54,-1,rustic:iron_lattice:0,5,CONCRETE_POWDER:8,10,quark:limestone:1,15,quark:limestone,15,quark:world_stone_pavement:2,15,CONCRETE:8,100)
RandomBlock(-2,54,0,rustic:iron_lattice:0,5,CONCRETE_POWDER:8,10,quark:limestone:1,15,quark:limestone,15,quark:world_stone_pavement:2,15,CONCRETE:8,100)
RandomBlock(-2,54,1,rustic:iron_lattice:0,5,CONCRETE_POWDER:8,10,quark:limestone:1,15,quark:limestone,15,quark:world_stone_pavement:2,15,CONCRETE:8,100)
RandomBlock(-2,54,2,rustic:iron_lattice:0,5,CONCRETE_POWDER:8,10,quark:limestone:1,15,quark:limestone,15,quark:world_stone_pavement:2,15,CONCRETE:8,100)
RandomBlock(-2,54,3,rustic:iron_lattice:0,5,CONCRETE_POWDER:8,10,quark:limestone:1,15,quark:limestone,15,quark:world_stone_pavement:2,15,CONCRETE:8,100)
RandomBlock(-2,54,4,rustic:iron_lattice:0,5,CONCRETE_POWDER:8,10,quark:limestone:1,15,quark:limestone,15,quark:world_stone_pavement:2,15,CONCRETE:8,100)
RandomBlock(-2,54,5,rustic:iron_lattice:0,5,CONCRETE_POWDER:8,10,quark:limestone:1,15,quark:limestone,15,quark:world_stone_pavement:2,15,CONCRETE:8,100)
RandomBlock(-2,54,6,rustic:iron_lattice:0,5,CONCRETE_POWDER:8,10,quark:limestone:1,15,quark:limestone,15,quark:world_stone_pavement:2,15,CONCRETE:8,100)
RandomBlock(-2,54,7,rustic:iron_lattice:0,5,CONCRETE_POWDER:8,10,quark:limestone:1,15,quark:limestone,15,quark:world_stone_pavement:2,15,CONCRETE:8,100)
RandomBlock(-2,54,8,rustic:iron_lattice:0,5,CONCRETE_POWDER:8,10,quark:limestone:1,15,quark:limestone,15,quark:world_stone_pavement:2,15,CONCRETE:8,100)
Block(-2,55,-2,STONE:6)
RandomBlock(-2,55,-1,rustic:iron_lattice:0,5,CONCRETE_POWDER:8,10,quark:limestone:1,15,quark:limestone,15,quark:world_stone_pavement:2,15,CONCRETE:8,100)
Block(-2,55,1,SMOOTH_STAIRS:6)
Block(-2,55,2,SMOOTH_STAIRS:7)
Block(-2,55,6,SMOOTH_STAIRS:6)
Block(-2,55,7,SMOOTH_STAIRS:7)
Block(-2,56,-2,STONE:6)
RandomBlock(-2,56,-1,rustic:iron_lattice:0,5,CONCRETE_POWDER:8,10,quark:limestone:1,15,quark:limestone,15,quark:world_stone_pavement:2,15,CONCRETE:8,100)
Block(-2,56,1,SMOOTH_STAIRS:2)
Block(-2,56,2,SMOOTH_STAIRS:3)
Block(-2,56,6,SMOOTH_STAIRS:2)
Block(-2,56,7,SMOOTH_STAIRS:3)
Block(-2,57,-2,STONE:6)
RandomBlock(-2,57,-1,rustic:iron_lattice:0,5,CONCRETE_POWDER:8,10,quark:limestone:1,15,quark:limestone,15,quark:world_stone_pavement:2,15,CONCRETE:8,100)
Block(-2,57,1,STEP:0)
Block(-2,57,2,STEP:0)
Block(-2,57,6,STEP:0)
Block(-2,57,7,STEP:0)
Block(-2,58,-2,STONE:6)
RandomBlock(-2,58,-1,rustic:iron_lattice:0,5,CONCRETE_POWDER:8,10,quark:limestone:1,15,quark:limestone,15,quark:world_stone_pavement:2,15,CONCRETE:8,100)
RandomBlock(-2,58,0,SMOOTH_BRICK:0,40,SMOOTH_BRICK:1,20,SMOOTH_BRICK:2,30,SMOOTH_BRICK:0,100)
Block(-2,58,1,STEP:5)
Block(-2,58,2,STEP:5)
Block(-2,58,3,STEP:5)
Block(-2,58,4,STEP:5)
Block(-2,58,5,STEP:5)
Block(-2,58,6,STEP:5)
Block(-2,58,7,STEP:5)
Block(-2,58,8,STEP:5)
Block(-2,59,-2,STONE:6)
Block(-2,59,-1,STONE:6)
Block(-2,59,0,STONE:6)
Block(-2,59,6,quark:iron_plate:1)
Block(-2,59,7,quark:iron_plate:1)
Block(-2,60,1,SMOOTH_STAIRS:4)
Block(-2,60,2,SMOOTH_STAIRS:4)
Block(-2,61,1,SMOOTH_STAIRS:0)
Block(-2,61,2,SMOOTH_STAIRS:0)
Block(-1,43,4,STONE:6)
Block(-1,43,6,STONE:6)
RandomBlock(-1,44,-1,rustic:iron_lattice:0,5,STAINED_CLAY:15,5,STAINED_CLAY:7,5,quark:iron_plate_slab:8,15,quark:world_stone_pavement:2,15,STAINED_CLAY:9,100)
RandomBlock(-1,44,0,rustic:iron_lattice:0,5,STAINED_CLAY:15,5,STAINED_CLAY:7,5,quark:iron_plate_slab:8,15,quark:world_stone_pavement:2,15,STAINED_CLAY:9,100)
RandomBlock(-1,44,1,rustic:iron_lattice:0,5,STAINED_CLAY:15,5,STAINED_CLAY:7,5,quark:iron_plate_slab:8,15,quark:world_stone_pavement:2,15,STAINED_CLAY:9,100)
RandomBlock(-1,44,2,rustic:iron_lattice:0,5,STAINED_CLAY:15,5,STAINED_CLAY:7,5,quark:iron_plate_slab:8,15,quark:world_stone_pavement:2,15,STAINED_CLAY:9,100)
RandomBlock(-1,44,3,rustic:iron_lattice:0,5,STAINED_CLAY:15,5,STAINED_CLAY:7,5,quark:iron_plate_slab:8,15,quark:world_stone_pavement:2,15,STAINED_CLAY:9,100)
RandomBlock(-1,44,4,rustic:iron_lattice:0,5,STAINED_CLAY:15,5,STAINED_CLAY:7,5,quark:iron_plate_slab:8,15,quark:world_stone_pavement:2,15,STAINED_CLAY:9,100)
RandomBlock(-1,44,5,rustic:iron_lattice:0,5,STAINED_CLAY:15,5,STAINED_CLAY:7,5,quark:iron_plate_slab:8,15,quark:world_stone_pavement:2,15,STAINED_CLAY:9,100)
RandomBlock(-1,44,6,rustic:iron_lattice:0,5,STAINED_CLAY:15,5,STAINED_CLAY:7,5,quark:iron_plate_slab:8,15,quark:world_stone_pavement:2,15,STAINED_CLAY:9,100)
RandomBlock(-1,44,7,rustic:iron_lattice:0,5,STAINED_CLAY:15,5,STAINED_CLAY:7,5,quark:iron_plate_slab:8,15,quark:world_stone_pavement:2,15,STAINED_CLAY:9,100)
RandomBlock(-1,44,8,rustic:iron_lattice:0,5,STAINED_CLAY:15,5,STAINED_CLAY:7,5,quark:iron_plate_slab:8,15,quark:world_stone_pavement:2,15,STAINED_CLAY:9,100)
RandomBlock(-1,45,-1,rustic:iron_lattice:0,5,CONCRETE_POWDER:8,10,quark:limestone:1,15,quark:limestone,15,quark:world_stone_pavement:2,15,CONCRETE:8,100)
Block(-1,45,0,quark:iron_plate_slab:8)
RandomBlock(-1,45,4,variedcommodities:crate:5,5,charm:crate_sealed:5,../../../../Chests/RLCraft/Containers/charm_crate.nbt,10,charm:crate_sealed:5,../../../../Chests/RLCraft/Containers/charm_crate.nbt,100)
RandomBlock(-1,45,5,rustic:iron_lattice:0,5,CONCRETE_POWDER:8,10,quark:limestone:1,15,quark:limestone,15,quark:world_stone_pavement:2,15,CONCRETE:8,100)
Block(-1,46,-1,CONCRETE:15)
RandomBlock(-1,46,0,variedcommodities:crate:5,5,charm:crate_sealed:5,../../../../Chests/RLCraft/Containers/charm_crate.nbt,10,charm:crate_sealed:5,../../../../Chests/RLCraft/Containers/charm_crate.nbt,100)
Block(-1,46,5,CONCRETE:15)
Block(-1,46,8,quark:iron_button:1)
RandomBlock(-1,47,-1,rustic:iron_lattice:0,5,CONCRETE_POWDER:8,10,quark:limestone:1,15,quark:limestone,15,quark:world_stone_pavement:2,15,CONCRETE:8,100)
RandomBlock(-1,47,5,rustic:iron_lattice:0,5,CONCRETE_POWDER:8,10,quark:limestone:1,15,quark:limestone,15,quark:world_stone_pavement:2,15,CONCRETE:8,100)
RandomBlock(-1,48,-1,rustic:iron_lattice:0,5,CONCRETE_POWDER:8,10,quark:limestone:1,15,quark:limestone,15,quark:world_stone_pavement:2,15,CONCRETE:8,100)
Block(-1,48,4,SMOOTH_STAIRS:4)
RandomBlock(-1,48,5,rustic:iron_lattice:0,5,CONCRETE_POWDER:8,10,quark:limestone:1,15,quark:limestone,15,quark:world_stone_pavement:2,15,CONCRETE:8,100)
RandomBlock(-1,49,-1,rustic:iron_lattice:0,5,CONCRETE_POWDER:8,10,quark:limestone:1,15,quark:limestone,15,quark:world_stone_pavement:2,15,CONCRETE:8,100)
RandomBlock(-1,49,0,rustic:iron_lattice:0,5,CONCRETE_POWDER:8,10,quark:limestone:1,15,quark:limestone,15,quark:world_stone_pavement:2,15,CONCRETE:8,100)
RandomBlock(-1,49,1,rustic:iron_lattice:0,5,CONCRETE_POWDER:8,10,quark:limestone:1,15,quark:limestone,15,quark:world_stone_pavement:2,15,CONCRETE:8,100)
Block(-1,49,2,REDSTONE_LAMP_OFF:0)
RandomBlock(-1,49,3,rustic:iron_lattice:0,5,CONCRETE_POWDER:8,10,quark:limestone:1,15,quark:limestone,15,quark:world_stone_pavement:2,15,CONCRETE:8,100)
Block(-1,49,4,SMOOTH_STAIRS:1)
RandomBlock(-1,49,5,rustic:iron_lattice:0,5,CONCRETE_POWDER:8,10,quark:limestone:1,15,quark:limestone,15,quark:world_stone_pavement:2,15,CONCRETE:8,100)
RandomBlock(-1,50,-1,rustic:iron_lattice:0,5,CONCRETE_POWDER:8,10,quark:limestone:1,15,quark:limestone,15,quark:world_stone_pavement:2,15,CONCRETE:8,100)
RandomBlock(-1,50,0,rustic:iron_lattice:0,5,STAINED_CLAY:15,5,STAINED_CLAY:7,5,quark:iron_plate_slab:8,15,quark:world_stone_pavement:2,15,STAINED_CLAY:9,100)
RandomBlock(-1,50,1,rustic:iron_lattice:0,5,STAINED_CLAY:15,5,STAINED_CLAY:7,5,quark:iron_plate_slab:8,15,quark:world_stone_pavement:2,15,STAINED_CLAY:9,100)
RandomBlock(-1,50,2,rustic:iron_lattice:0,5,STAINED_CLAY:15,5,STAINED_CLAY:7,5,quark:iron_plate_slab:8,15,quark:world_stone_pavement:2,15,STAINED_CLAY:9,100)
RandomBlock(-1,50,3,rustic:iron_lattice:0,5,STAINED_CLAY:15,5,STAINED_CLAY:7,5,quark:iron_plate_slab:8,15,quark:world_stone_pavement:2,15,STAINED_CLAY:9,100)
RandomBlock(-1,50,5,rustic:iron_lattice:0,5,CONCRETE_POWDER:8,10,quark:limestone:1,15,quark:limestone,15,quark:world_stone_pavement:2,15,CONCRETE:8,100)
RandomBlock(-1,50,6,rustic:iron_lattice:0,5,STAINED_CLAY:15,5,STAINED_CLAY:7,5,quark:iron_plate_slab:8,15,quark:world_stone_pavement:2,15,STAINED_CLAY:9,100)
RandomBlock(-1,50,7,rustic:iron_lattice:0,5,STAINED_CLAY:15,5,STAINED_CLAY:7,5,quark:iron_plate_slab:8,15,quark:world_stone_pavement:2,15,STAINED_CLAY:9,100)
RandomBlock(-1,50,8,rustic:iron_lattice:0,5,STAINED_CLAY:15,5,STAINED_CLAY:7,5,quark:iron_plate_slab:8,15,quark:world_stone_pavement:2,15,STAINED_CLAY:9,100)
RandomBlock(-1,51,-1,rustic:iron_lattice:0,5,CONCRETE_POWDER:8,10,quark:limestone:1,15,quark:limestone,15,quark:world_stone_pavement:2,15,CONCRETE:8,100)
Block(-1,51,1,MOB_SPAWNER:0,../../ruins_spawners/industrial_multi.nbt)
RandomBlock(-1,51,2,rustic:iron_lattice:0,5,CONCRETE_POWDER:8,10,quark:limestone:1,15,quark:limestone,15,quark:world_stone_pavement:2,15,CONCRETE:8,100)
RandomBlock(-1,51,5,rustic:iron_lattice:0,5,CONCRETE_POWDER:8,10,quark:limestone:1,15,quark:limestone,15,quark:world_stone_pavement:2,15,CONCRETE:8,100)
Block(-1,52,-1,CONCRETE:15)
RandomBlock(-1,52,2,rustic:iron_lattice:0,5,CONCRETE_POWDER:8,10,quark:limestone:1,15,quark:limestone,15,quark:world_stone_pavement:2,15,CONCRETE:8,100)
Block(-1,52,5,CONCRETE:15)
RandomBlock(-1,53,-1,rustic:iron_lattice:0,5,CONCRETE_POWDER:8,10,quark:limestone:1,15,quark:limestone,15,quark:world_stone_pavement:2,15,CONCRETE:8,100)
RandomBlock(-1,53,2,rustic:iron_lattice:0,5,CONCRETE_POWDER:8,10,quark:limestone:1,15,quark:limestone,15,quark:world_stone_pavement:2,15,CONCRETE:8,100)
RandomBlock(-1,53,5,rustic:iron_lattice:0,5,CONCRETE_POWDER:8,10,quark:limestone:1,15,quark:limestone,15,quark:world_stone_pavement:2,15,CONCRETE:8,100)
Block(-1,53,7,quark:iron_plate:1)
RandomBlock(-1,54,-1,rustic:iron_lattice:0,5,CONCRETE_POWDER:8,10,quark:limestone:1,15,quark:limestone,15,quark:world_stone_pavement:2,15,CONCRETE:8,100)
RandomBlock(-1,54,0,rustic:iron_lattice:0,5,CONCRETE_POWDER:8,10,quark:limestone:1,15,quark:limestone,15,quark:world_stone_pavement:2,15,CONCRETE:8,100)
RandomBlock(-1,54,1,rustic:iron_lattice:0,5,CONCRETE_POWDER:8,10,quark:limestone:1,15,quark:limestone,15,quark:world_stone_pavement:2,15,CONCRETE:8,100)
RandomBlock(-1,54,2,rustic:iron_lattice:0,5,CONCRETE_POWDER:8,10,quark:limestone:1,15,quark:limestone,15,quark:world_stone_pavement:2,15,CONCRETE:8,100)
RandomBlock(-1,54,3,rustic:iron_lattice:0,5,CONCRETE_POWDER:8,10,quark:limestone:1,15,quark:limestone,15,quark:world_stone_pavement:2,15,CONCRETE:8,100)
RandomBlock(-1,54,4,rustic:iron_lattice:0,5,CONCRETE_POWDER:8,10,quark:limestone:1,15,quark:limestone,15,quark:world_stone_pavement:2,15,CONCRETE:8,100)
RandomBlock(-1,54,5,rustic:iron_lattice:0,5,CONCRETE_POWDER:8,10,quark:limestone:1,15,quark:limestone,15,quark:world_stone_pavement:2,15,CONCRETE:8,100)
RandomBlock(-1,54,6,rustic:iron_lattice:0,5,CONCRETE_POWDER:8,10,quark:limestone:1,15,quark:limestone,15,quark:world_stone_pavement:2,15,CONCRETE:8,100)
RandomBlock(-1,54,7,rustic:iron_lattice:0,5,CONCRETE_POWDER:8,10,quark:limestone:1,15,quark:limestone,15,quark:world_stone_pavement:2,15,CONCRETE:8,100)
RandomBlock(-1,54,8,rustic:iron_lattice:0,5,CONCRETE_POWDER:8,10,quark:limestone:1,15,quark:limestone,15,quark:world_stone_pavement:2,15,CONCRETE:8,100)
RandomBlock(-1,55,-1,rustic:iron_lattice:0,5,CONCRETE_POWDER:8,10,quark:limestone:1,15,quark:limestone,15,quark:world_stone_pavement:2,15,CONCRETE:8,100)
Block(-1,55,1,PISTON_BASE:1)
Block(-1,55,2,PISTON_BASE:1)
Block(-1,55,6,PISTON_BASE:1)
Block(-1,55,7,PISTON_BASE:1)
RandomBlock(-1,56,-1,rustic:iron_lattice:0,5,CONCRETE_POWDER:8,10,quark:limestone:1,15,quark:limestone,15,quark:world_stone_pavement:2,15,CONCRETE:8,100)
Block(-1,56,1,ANVIL:1)
Block(-1,56,2,ANVIL:3)
Block(-1,56,6,ANVIL:1)
Block(-1,56,7,ANVIL:3)
RandomBlock(-1,57,-1,rustic:iron_lattice:0,5,CONCRETE_POWDER:8,10,quark:limestone:1,15,quark:limestone,15,quark:world_stone_pavement:2,15,CONCRETE:8,100)
Block(-1,57,1,STEP:0)
Block(-1,57,2,STEP:0)
Block(-1,57,6,STEP:0)
Block(-1,57,7,STEP:0)
RandomBlock(-1,58,-1,rustic:iron_lattice:0,5,CONCRETE_POWDER:8,10,quark:limestone:1,15,quark:limestone,15,quark:world_stone_pavement:2,15,CONCRETE:8,100)
Block(-1,58,0,STEP:5)
RandomBlock(-1,58,1,SMOOTH_BRICK:0,40,SMOOTH_BRICK:1,20,SMOOTH_BRICK:2,30,SMOOTH_BRICK:0,100)
RandomBlock(-1,58,2,SMOOTH_BRICK:0,40,SMOOTH_BRICK:1,20,SMOOTH_BRICK:2,30,SMOOTH_BRICK:0,100)
Block(-1,58,3,STEP:5)
Block(-1,58,4,STEP:5)
Block(-1,58,5,STEP:5)
Block(-1,58,6,STEP:5)
RandomBlock(-1,58,7,SMOOTH_BRICK:0,40,SMOOTH_BRICK:1,20,SMOOTH_BRICK:2,30,SMOOTH_BRICK:0,100)
RandomBlock(-1,58,8,SMOOTH_BRICK:0,40,SMOOTH_BRICK:1,20,SMOOTH_BRICK:2,30,SMOOTH_BRICK:0,100)
Block(-1,59,-1,IRON_FENCE:0)
RandomBlock(-1,59,2,CONCRETE_POWDER:7,25,CONCRETE:7,100)
Block(-1,59,6,quark:iron_plate:1)
Block(-1,59,7,quark:iron_plate:1)
Block(-1,60,1,SMOOTH_STAIRS:6)
RandomBlock(-1,60,2,CONCRETE_POWDER:7,25,CONCRETE:7,100)
Block(-1,60,3,SMOOTH_STAIRS:7)
Block(-1,61,1,SMOOTH_STAIRS:2)
RandomBlock(-1,61,2,SMOOTH_BRICK:0,40,SMOOTH_BRICK:1,20,SMOOTH_BRICK:2,30,SMOOTH_BRICK:0,100)
RandomBlock(-1,61,3,SMOOTH_BRICK:0,40,SMOOTH_BRICK:1,20,SMOOTH_BRICK:2,30,SMOOTH_BRICK:0,100)
Block(-1,61,4,SMOOTH_STAIRS:7)
Block(-1,62,2,SMOOTH_STAIRS:2)
RandomBlock(-1,62,3,SMOOTH_BRICK:0,40,SMOOTH_BRICK:1,20,SMOOTH_BRICK:2,30,SMOOTH_BRICK:0,100)
RandomBlock(-1,62,4,CONCRETE_POWDER:7,25,CONCRETE:7,100)
RandomBlock(-1,62,5,CONCRETE_POWDER:7,25,CONCRETE:7,100)
RandomBlock(-1,62,6,CONCRETE_POWDER:7,25,CONCRETE:7,100)
RandomBlock(-1,62,7,CONCRETE_POWDER:7,25,CONCRETE:7,100)
RandomBlock(-1,62,8,CONCRETE_POWDER:7,25,CONCRETE:7,100)
Block(0,43,4,STONE:6)
Block(0,43,6,STONE:6)
RandomBlock(0,44,-1,rustic:iron_lattice:0,5,STAINED_CLAY:15,5,STAINED_CLAY:7,5,quark:iron_plate_slab:8,15,quark:world_stone_pavement:2,15,STAINED_CLAY:9,100)
RandomBlock(0,44,0,rustic:iron_lattice:0,5,STAINED_CLAY:15,5,STAINED_CLAY:7,5,quark:iron_plate_slab:8,15,quark:world_stone_pavement:2,15,STAINED_CLAY:9,100)
RandomBlock(0,44,1,rustic:iron_lattice:0,5,STAINED_CLAY:15,5,STAINED_CLAY:7,5,quark:iron_plate_slab:8,15,quark:world_stone_pavement:2,15,STAINED_CLAY:9,100)
RandomBlock(0,44,2,rustic:iron_lattice:0,5,STAINED_CLAY:15,5,STAINED_CLAY:7,5,quark:iron_plate_slab:8,15,quark:world_stone_pavement:2,15,STAINED_CLAY:9,100)
RandomBlock(0,44,3,rustic:iron_lattice:0,5,STAINED_CLAY:15,5,STAINED_CLAY:7,5,quark:iron_plate_slab:8,15,quark:world_stone_pavement:2,15,STAINED_CLAY:9,100)
RandomBlock(0,44,4,rustic:iron_lattice:0,5,STAINED_CLAY:15,5,STAINED_CLAY:7,5,quark:iron_plate_slab:8,15,quark:world_stone_pavement:2,15,STAINED_CLAY:9,100)
RandomBlock(0,44,5,rustic:iron_lattice:0,5,STAINED_CLAY:15,5,STAINED_CLAY:7,5,quark:iron_plate_slab:8,15,quark:world_stone_pavement:2,15,STAINED_CLAY:9,100)
RandomBlock(0,44,6,rustic:iron_lattice:0,5,STAINED_CLAY:15,5,STAINED_CLAY:7,5,quark:iron_plate_slab:8,15,quark:world_stone_pavement:2,15,STAINED_CLAY:9,100)
RandomBlock(0,44,7,rustic:iron_lattice:0,5,STAINED_CLAY:15,5,STAINED_CLAY:7,5,quark:iron_plate_slab:8,15,quark:world_stone_pavement:2,15,STAINED_CLAY:9,100)
RandomBlock(0,44,8,rustic:iron_lattice:0,5,STAINED_CLAY:15,5,STAINED_CLAY:7,5,quark:iron_plate_slab:8,15,quark:world_stone_pavement:2,15,STAINED_CLAY:9,100)
RandomBlock(0,45,-1,rustic:iron_lattice:0,5,CONCRETE_POWDER:8,10,quark:limestone:1,15,quark:limestone,15,quark:world_stone_pavement:2,15,CONCRETE:8,100)
Block(0,45,0,quark:iron_plate_stairs:4)
RandomBlock(0,45,4,variedcommodities:crate:5,5,charm:crate_sealed:5,../../../../Chests/RLCraft/Containers/charm_crate.nbt,10,charm:crate_sealed:5,../../../../Chests/RLCraft/Containers/charm_crate.nbt,100)
RandomBlock(0,45,5,rustic:iron_lattice:0,5,CONCRETE_POWDER:8,10,quark:limestone:1,15,quark:limestone,15,quark:world_stone_pavement:2,15,CONCRETE:8,100)
Block(0,46,-1,CONCRETE:15)
RandomBlock(0,46,4,variedcommodities:crate:5,5,charm:crate_sealed:5,../../../../Chests/RLCraft/Containers/charm_crate.nbt,10,charm:crate_sealed:5,../../../../Chests/RLCraft/Containers/charm_crate.nbt,100)
Block(0,46,5,CONCRETE:15)
RandomBlock(0,47,-1,rustic:iron_lattice:0,5,CONCRETE_POWDER:8,10,quark:limestone:1,15,quark:limestone,15,quark:world_stone_pavement:2,15,CONCRETE:8,100)
Block(0,47,4,SMOOTH_STAIRS:4)
RandomBlock(0,47,5,rustic:iron_lattice:0,5,CONCRETE_POWDER:8,10,quark:limestone:1,15,quark:limestone,15,quark:world_stone_pavement:2,15,CONCRETE:8,100)
RandomBlock(0,48,-1,rustic:iron_lattice:0,5,CONCRETE_POWDER:8,10,quark:limestone:1,15,quark:limestone,15,quark:world_stone_pavement:2,15,CONCRETE:8,100)
RandomBlock(0,48,3,rustic:iron_lattice:0,5,CONCRETE_POWDER:8,10,quark:limestone:1,15,quark:limestone,15,quark:world_stone_pavement:2,15,CONCRETE:8,100)
Block(0,48,4,SMOOTH_STAIRS:1)
RandomBlock(0,48,5,rustic:iron_lattice:0,5,CONCRETE_POWDER:8,10,quark:limestone:1,15,quark:limestone,15,quark:world_stone_pavement:2,15,CONCRETE:8,100)
RandomBlock(0,49,-1,rustic:iron_lattice:0,5,CONCRETE_POWDER:8,10,quark:limestone:1,15,quark:limestone,15,quark:world_stone_pavement:2,15,CONCRETE:8,100)
RandomBlock(0,49,0,rustic:iron_lattice:0,5,CONCRETE_POWDER:8,10,quark:limestone:1,15,quark:limestone,15,quark:world_stone_pavement:2,15,CONCRETE:8,100)
RandomBlock(0,49,1,rustic:iron_lattice:0,5,CONCRETE_POWDER:8,10,quark:limestone:1,15,quark:limestone,15,quark:world_stone_pavement:2,15,CONCRETE:8,100)
RandomBlock(0,49,2,rustic:iron_lattice:0,5,CONCRETE_POWDER:8,10,quark:limestone:1,15,quark:limestone,15,quark:world_stone_pavement:2,15,CONCRETE:8,100)
RandomBlock(0,49,3,rustic:iron_lattice:0,5,CONCRETE_POWDER:8,10,quark:limestone:1,15,quark:limestone,15,quark:world_stone_pavement:2,15,CONCRETE:8,100)
RandomBlock(0,49,5,rustic:iron_lattice:0,5,CONCRETE_POWDER:8,10,quark:limestone:1,15,quark:limestone,15,quark:world_stone_pavement:2,15,CONCRETE:8,100)
Block(0,49,6,quark:iron_plate:1)
Block(0,49,7,quark:iron_plate:1)
Block(0,49,8,quark:iron_plate:1)
RandomBlock(0,50,-1,rustic:iron_lattice:0,5,CONCRETE_POWDER:8,10,quark:limestone:1,15,quark:limestone,15,quark:world_stone_pavement:2,15,CONCRETE:8,100)
RandomBlock(0,50,0,rustic:iron_lattice:0,5,STAINED_CLAY:15,5,STAINED_CLAY:7,5,quark:iron_plate_slab:8,15,quark:world_stone_pavement:2,15,STAINED_CLAY:9,100)
RandomBlock(0,50,1,rustic:iron_lattice:0,5,STAINED_CLAY:15,5,STAINED_CLAY:7,5,quark:iron_plate_slab:8,15,quark:world_stone_pavement:2,15,STAINED_CLAY:9,100)
RandomBlock(0,50,2,rustic:iron_lattice:0,5,STAINED_CLAY:15,5,STAINED_CLAY:7,5,quark:iron_plate_slab:8,15,quark:world_stone_pavement:2,15,STAINED_CLAY:9,100)
RandomBlock(0,50,3,rustic:iron_lattice:0,5,STAINED_CLAY:15,5,STAINED_CLAY:7,5,quark:iron_plate_slab:8,15,quark:world_stone_pavement:2,15,STAINED_CLAY:9,100)
RandomBlock(0,50,5,rustic:iron_lattice:0,5,CONCRETE_POWDER:8,10,quark:limestone:1,15,quark:limestone,15,quark:world_stone_pavement:2,15,CONCRETE:8,100)
RandomBlock(0,50,6,rustic:iron_lattice:0,5,STAINED_CLAY:15,5,STAINED_CLAY:7,5,quark:iron_plate_slab:8,15,quark:world_stone_pavement:2,15,STAINED_CLAY:9,100)
RandomBlock(0,50,7,rustic:iron_lattice:0,5,STAINED_CLAY:15,5,STAINED_CLAY:7,5,quark:iron_plate_slab:8,15,quark:world_stone_pavement:2,15,STAINED_CLAY:9,100)
RandomBlock(0,50,8,rustic:iron_lattice:0,5,STAINED_CLAY:15,5,STAINED_CLAY:7,5,quark:iron_plate_slab:8,15,quark:world_stone_pavement:2,15,STAINED_CLAY:9,100)
RandomBlock(0,51,-1,rustic:iron_lattice:0,5,CONCRETE_POWDER:8,10,quark:limestone:1,15,quark:limestone,15,quark:world_stone_pavement:2,15,CONCRETE:8,100)
Block(0,51,0,biomesoplenty:fir_door_block:2)
RandomBlock(0,51,1,rustic:iron_lattice:0,5,CONCRETE_POWDER:8,10,quark:limestone:1,15,quark:limestone,15,quark:world_stone_pavement:2,15,CONCRETE:8,100)
RandomBlock(0,51,2,rustic:iron_lattice:0,5,CONCRETE_POWDER:8,10,quark:limestone:1,15,quark:limestone,15,quark:world_stone_pavement:2,15,CONCRETE:8,100)
RandomBlock(0,51,5,rustic:iron_lattice:0,5,CONCRETE_POWDER:8,10,quark:limestone:1,15,quark:limestone,15,quark:world_stone_pavement:2,15,CONCRETE:8,100)
Block(0,51,7,IRON_FENCE:0)
Block(0,52,-1,CONCRETE:15)
Block(0,52,0,biomesoplenty:fir_door_block:9)
RandomBlock(0,52,1,rustic:iron_lattice:0,5,CONCRETE_POWDER:8,10,quark:limestone:1,15,quark:limestone,15,quark:world_stone_pavement:2,15,CONCRETE:8,100)
RandomBlock(0,52,2,rustic:iron_lattice:0,5,CONCRETE_POWDER:8,10,quark:limestone:1,15,quark:limestone,15,quark:world_stone_pavement:2,15,CONCRETE:8,100)
Block(0,52,5,CONCRETE:15)
Block(0,52,7,IRON_FENCE:0)
RandomBlock(0,53,-1,rustic:iron_lattice:0,5,CONCRETE_POWDER:8,10,quark:limestone:1,15,quark:limestone,15,quark:world_stone_pavement:2,15,CONCRETE:8,100)
RandomBlock(0,53,0,rustic:iron_lattice:0,5,CONCRETE_POWDER:8,10,quark:limestone:1,15,quark:limestone,15,quark:world_stone_pavement:2,15,CONCRETE:8,100)
RandomBlock(0,53,1,rustic:iron_lattice:0,5,CONCRETE_POWDER:8,10,quark:limestone:1,15,quark:limestone,15,quark:world_stone_pavement:2,15,CONCRETE:8,100)
RandomBlock(0,53,2,rustic:iron_lattice:0,5,CONCRETE_POWDER:8,10,quark:limestone:1,15,quark:limestone,15,quark:world_stone_pavement:2,15,CONCRETE:8,100)
RandomBlock(0,53,5,rustic:iron_lattice:0,5,CONCRETE_POWDER:8,10,quark:limestone:1,15,quark:limestone,15,quark:world_stone_pavement:2,15,CONCRETE:8,100)
Block(0,53,7,quark:iron_plate:1)
RandomBlock(0,54,-1,rustic:iron_lattice:0,5,CONCRETE_POWDER:8,10,quark:limestone:1,15,quark:limestone,15,quark:world_stone_pavement:2,15,CONCRETE:8,100)
RandomBlock(0,54,0,rustic:iron_lattice:0,5,CONCRETE_POWDER:8,10,quark:limestone:1,15,quark:limestone,15,quark:world_stone_pavement:2,15,CONCRETE:8,100)
RandomBlock(0,54,1,rustic:iron_lattice:0,5,CONCRETE_POWDER:8,10,quark:limestone:1,15,quark:limestone,15,quark:world_stone_pavement:2,15,CONCRETE:8,100)
RandomBlock(0,54,2,rustic:iron_lattice:0,5,CONCRETE_POWDER:8,10,quark:limestone:1,15,quark:limestone,15,quark:world_stone_pavement:2,15,CONCRETE:8,100)
RandomBlock(0,54,3,rustic:iron_lattice:0,5,CONCRETE_POWDER:8,10,quark:limestone:1,15,quark:limestone,15,quark:world_stone_pavement:2,15,CONCRETE:8,100)
RandomBlock(0,54,4,rustic:iron_lattice:0,5,CONCRETE_POWDER:8,10,quark:limestone:1,15,quark:limestone,15,quark:world_stone_pavement:2,15,CONCRETE:8,100)
RandomBlock(0,54,5,rustic:iron_lattice:0,5,CONCRETE_POWDER:8,10,quark:limestone:1,15,quark:limestone,15,quark:world_stone_pavement:2,15,CONCRETE:8,100)
RandomBlock(0,54,6,rustic:iron_lattice:0,5,CONCRETE_POWDER:8,10,quark:limestone:1,15,quark:limestone,15,quark:world_stone_pavement:2,15,CONCRETE:8,100)
RandomBlock(0,54,7,rustic:iron_lattice:0,5,CONCRETE_POWDER:8,10,quark:limestone:1,15,quark:limestone,15,quark:world_stone_pavement:2,15,CONCRETE:8,100)
RandomBlock(0,54,8,rustic:iron_lattice:0,5,CONCRETE_POWDER:8,10,quark:limestone:1,15,quark:limestone,15,quark:world_stone_pavement:2,15,CONCRETE:8,100)
RandomBlock(0,55,-1,rustic:iron_lattice:0,5,CONCRETE_POWDER:8,10,quark:limestone:1,15,quark:limestone,15,quark:world_stone_pavement:2,15,CONCRETE:8,100)
Block(0,55,1,PISTON_BASE:1)
Block(0,55,2,PISTON_BASE:1)
Block(0,55,6,PISTON_BASE:1)
Block(0,55,7,PISTON_BASE:1)
RandomBlock(0,56,-1,rustic:iron_lattice:0,5,CONCRETE_POWDER:8,10,quark:limestone:1,15,quark:limestone,15,quark:world_stone_pavement:2,15,CONCRETE:8,100)
Block(0,56,1,ANVIL:1)
Block(0,56,2,ANVIL:3)
Block(0,56,6,ANVIL:1)
Block(0,56,7,ANVIL:3)
RandomBlock(0,57,-1,rustic:iron_lattice:0,5,CONCRETE_POWDER:8,10,quark:limestone:1,15,quark:limestone,15,quark:world_stone_pavement:2,15,CONCRETE:8,100)
Block(0,57,1,STEP:0)
Block(0,57,2,STEP:0)
Block(0,57,6,STEP:0)
Block(0,57,7,STEP:0)
RandomBlock(0,58,-1,rustic:iron_lattice:0,5,CONCRETE_POWDER:8,10,quark:limestone:1,15,quark:limestone,15,quark:world_stone_pavement:2,15,CONCRETE:8,100)
RandomBlock(0,58,0,SMOOTH_BRICK:0,40,SMOOTH_BRICK:1,20,SMOOTH_BRICK:2,30,SMOOTH_BRICK:0,100)
Block(0,58,1,REDSTONE_LAMP_OFF:0)
Block(0,58,2,REDSTONE_LAMP_OFF:0)
RandomBlock(0,58,3,SMOOTH_BRICK:0,40,SMOOTH_BRICK:1,20,SMOOTH_BRICK:2,30,SMOOTH_BRICK:0,100)
RandomBlock(0,58,4,SMOOTH_BRICK:0,40,SMOOTH_BRICK:1,20,SMOOTH_BRICK:2,30,SMOOTH_BRICK:0,100)
RandomBlock(0,58,5,SMOOTH_BRICK:0,40,SMOOTH_BRICK:1,20,SMOOTH_BRICK:2,30,SMOOTH_BRICK:0,100)
RandomBlock(0,58,6,SMOOTH_BRICK:0,40,SMOOTH_BRICK:1,20,SMOOTH_BRICK:2,30,SMOOTH_BRICK:0,100)
Block(0,58,7,REDSTONE_LAMP_OFF:0)
Block(0,58,8,REDSTONE_LAMP_OFF:0)
Block(0,59,-1,IRON_FENCE:0)
Block(0,59,1,STEP:5)
Block(0,59,2,STEP:5)
Block(0,59,6,quark:iron_plate:1)
Block(0,59,7,STEP:5)
Block(0,59,8,SMOOTH_STAIRS:2)
Block(0,60,1,SMOOTH_STAIRS:5)
Block(0,60,2,SMOOTH_STAIRS:5)
Block(0,61,1,SMOOTH_STAIRS:1)
Block(0,61,2,SMOOTH_STAIRS:1)
Block(1,43,4,STONE:6)
Block(1,43,6,STONE:6)
RandomBlock(1,44,-5,rustic:iron_lattice:0,5,STAINED_CLAY:15,5,STAINED_CLAY:7,5,quark:iron_plate_slab:8,15,quark:world_stone_pavement:2,15,STAINED_CLAY:9,100)
RandomBlock(1,44,-4,rustic:iron_lattice:0,5,STAINED_CLAY:15,5,STAINED_CLAY:7,5,quark:iron_plate_slab:8,15,quark:world_stone_pavement:2,15,STAINED_CLAY:9,100)
RandomBlock(1,44,-3,rustic:iron_lattice:0,5,STAINED_CLAY:15,5,STAINED_CLAY:7,5,quark:iron_plate_slab:8,15,quark:world_stone_pavement:2,15,STAINED_CLAY:9,100)
RandomBlock(1,44,-2,rustic:iron_lattice:0,5,STAINED_CLAY:15,5,STAINED_CLAY:7,5,quark:iron_plate_slab:8,15,quark:world_stone_pavement:2,15,STAINED_CLAY:9,100)
RandomBlock(1,44,-1,rustic:iron_lattice:0,5,STAINED_CLAY:15,5,STAINED_CLAY:7,5,quark:iron_plate_slab:8,15,quark:world_stone_pavement:2,15,STAINED_CLAY:9,100)
RandomBlock(1,44,0,rustic:iron_lattice:0,5,STAINED_CLAY:15,5,STAINED_CLAY:7,5,quark:iron_plate_slab:8,15,quark:world_stone_pavement:2,15,STAINED_CLAY:9,100)
RandomBlock(1,44,1,rustic:iron_lattice:0,5,STAINED_CLAY:15,5,STAINED_CLAY:7,5,quark:iron_plate_slab:8,15,quark:world_stone_pavement:2,15,STAINED_CLAY:9,100)
RandomBlock(1,44,2,rustic:iron_lattice:0,5,STAINED_CLAY:15,5,STAINED_CLAY:7,5,quark:iron_plate_slab:8,15,quark:world_stone_pavement:2,15,STAINED_CLAY:9,100)
RandomBlock(1,44,3,rustic:iron_lattice:0,5,STAINED_CLAY:15,5,STAINED_CLAY:7,5,quark:iron_plate_slab:8,15,quark:world_stone_pavement:2,15,STAINED_CLAY:9,100)
RandomBlock(1,44,4,rustic:iron_lattice:0,5,STAINED_CLAY:15,5,STAINED_CLAY:7,5,quark:iron_plate_slab:8,15,quark:world_stone_pavement:2,15,STAINED_CLAY:9,100)
RandomBlock(1,44,5,rustic:iron_lattice:0,5,STAINED_CLAY:15,5,STAINED_CLAY:7,5,quark:iron_plate_slab:8,15,quark:world_stone_pavement:2,15,STAINED_CLAY:9,100)
RandomBlock(1,44,6,rustic:iron_lattice:0,5,STAINED_CLAY:15,5,STAINED_CLAY:7,5,quark:iron_plate_slab:8,15,quark:world_stone_pavement:2,15,STAINED_CLAY:9,100)
RandomBlock(1,44,7,rustic:iron_lattice:0,5,STAINED_CLAY:15,5,STAINED_CLAY:7,5,quark:iron_plate_slab:8,15,quark:world_stone_pavement:2,15,STAINED_CLAY:9,100)
RandomBlock(1,44,8,rustic:iron_lattice:0,5,STAINED_CLAY:15,5,STAINED_CLAY:7,5,quark:iron_plate_slab:8,15,quark:world_stone_pavement:2,15,STAINED_CLAY:9,100)
RandomBlock(1,45,-5,rustic:iron_lattice:0,5,CONCRETE_POWDER:8,10,quark:limestone:1,15,quark:limestone,15,quark:world_stone_pavement:2,15,CONCRETE:8,100)
RandomBlock(1,45,-4,rustic:iron_lattice:0,5,CONCRETE_POWDER:8,10,quark:limestone:1,15,quark:limestone,15,quark:world_stone_pavement:2,15,CONCRETE:8,100)
RandomBlock(1,45,-3,rustic:iron_lattice:0,5,CONCRETE_POWDER:8,10,quark:limestone:1,15,quark:limestone,15,quark:world_stone_pavement:2,15,CONCRETE:8,100)
RandomBlock(1,45,-2,rustic:iron_lattice:0,5,CONCRETE_POWDER:8,10,quark:limestone:1,15,quark:limestone,15,quark:world_stone_pavement:2,15,CONCRETE:8,100)
RandomBlock(1,45,-1,rustic:iron_lattice:0,5,CONCRETE_POWDER:8,10,quark:limestone:1,15,quark:limestone,15,quark:world_stone_pavement:2,15,CONCRETE:8,100)
RandomBlock(1,45,0,CHEST:3,../../../../Chests/Loot/moderncity_junk_loot.nbt,20,CHEST:3../../../../Chests/Loot/moderncity_rare_loot.nbt,10,CHEST:3,../../../../Chests/RLCraft/Ruins/industrial.nbt,50,CHEST:3,../../../../Chests/RLCraft/Ruins/rubble.nbt,100)
RandomBlock(1,45,5,rustic:iron_lattice:0,5,CONCRETE_POWDER:8,10,quark:limestone:1,15,quark:limestone,15,quark:world_stone_pavement:2,15,CONCRETE:8,100)
Block(1,46,-5,CONCRETE:15)
Block(1,46,-4,STAINED_GLASS_PANE:7)
Block(1,46,-3,STAINED_GLASS_PANE:7)
Block(1,46,-2,CONCRETE:15)
Block(1,46,-1,CONCRETE:15)
Block(1,46,4,SMOOTH_STAIRS:4)
Block(1,46,5,CONCRETE:15)
RandomBlock(1,47,-5,rustic:iron_lattice:0,5,CONCRETE_POWDER:8,10,quark:limestone:1,15,quark:limestone,15,quark:world_stone_pavement:2,15,CONCRETE:8,100)
RandomBlock(1,47,-4,rustic:iron_lattice:0,5,CONCRETE_POWDER:8,10,quark:limestone:1,15,quark:limestone,15,quark:world_stone_pavement:2,15,CONCRETE:8,100)
RandomBlock(1,47,-3,rustic:iron_lattice:0,5,CONCRETE_POWDER:8,10,quark:limestone:1,15,quark:limestone,15,quark:world_stone_pavement:2,15,CONCRETE:8,100)
RandomBlock(1,47,-2,rustic:iron_lattice:0,5,CONCRETE_POWDER:8,10,quark:limestone:1,15,quark:limestone,15,quark:world_stone_pavement:2,15,CONCRETE:8,100)
RandomBlock(1,47,-1,rustic:iron_lattice:0,5,CONCRETE_POWDER:8,10,quark:limestone:1,15,quark:limestone,15,quark:world_stone_pavement:2,15,CONCRETE:8,100)
RandomBlock(1,47,3,rustic:iron_lattice:0,5,CONCRETE_POWDER:8,10,quark:limestone:1,15,quark:limestone,15,quark:world_stone_pavement:2,15,CONCRETE:8,100)
Block(1,47,4,SMOOTH_STAIRS:1)
RandomBlock(1,47,5,rustic:iron_lattice:0,5,CONCRETE_POWDER:8,10,quark:limestone:1,15,quark:limestone,15,quark:world_stone_pavement:2,15,CONCRETE:8,100)
RandomBlock(1,48,-5,rustic:iron_lattice:0,5,CONCRETE_POWDER:8,10,quark:limestone:1,15,quark:limestone,15,quark:world_stone_pavement:2,15,CONCRETE:8,100)
RandomBlock(1,48,-4,rustic:iron_lattice:0,5,CONCRETE_POWDER:8,10,quark:limestone:1,15,quark:limestone,15,quark:world_stone_pavement:2,15,CONCRETE:8,100)
RandomBlock(1,48,-3,rustic:iron_lattice:0,5,CONCRETE_POWDER:8,10,quark:limestone:1,15,quark:limestone,15,quark:world_stone_pavement:2,15,CONCRETE:8,100)
RandomBlock(1,48,-2,rustic:iron_lattice:0,5,CONCRETE_POWDER:8,10,quark:limestone:1,15,quark:limestone,15,quark:world_stone_pavement:2,15,CONCRETE:8,100)
RandomBlock(1,48,-1,rustic:iron_lattice:0,5,CONCRETE_POWDER:8,10,quark:limestone:1,15,quark:limestone,15,quark:world_stone_pavement:2,15,CONCRETE:8,100)
RandomBlock(1,48,3,rustic:iron_lattice:0,5,CONCRETE_POWDER:8,10,quark:limestone:1,15,quark:limestone,15,quark:world_stone_pavement:2,15,CONCRETE:8,100)
RandomBlock(1,48,5,rustic:iron_lattice:0,5,CONCRETE_POWDER:8,10,quark:limestone:1,15,quark:limestone,15,quark:world_stone_pavement:2,15,CONCRETE:8,100)
RandomBlock(1,49,-5,rustic:iron_lattice:0,5,CONCRETE_POWDER:8,10,quark:limestone:1,15,quark:limestone,15,quark:world_stone_pavement:2,15,CONCRETE:8,100)
RandomBlock(1,49,-4,rustic:iron_lattice:0,5,CONCRETE_POWDER:8,10,quark:limestone:1,15,quark:limestone,15,quark:world_stone_pavement:2,15,CONCRETE:8,100)
RandomBlock(1,49,-3,rustic:iron_lattice:0,5,CONCRETE_POWDER:8,10,quark:limestone:1,15,quark:limestone,15,quark:world_stone_pavement:2,15,CONCRETE:8,100)
RandomBlock(1,49,-2,rustic:iron_lattice:0,5,CONCRETE_POWDER:8,10,quark:limestone:1,15,quark:limestone,15,quark:world_stone_pavement:2,15,CONCRETE:8,100)
RandomBlock(1,49,-1,rustic:iron_lattice:0,5,CONCRETE_POWDER:8,10,quark:limestone:1,15,quark:limestone,15,quark:world_stone_pavement:2,15,CONCRETE:8,100)
RandomBlock(1,49,0,rustic:iron_lattice:0,5,CONCRETE_POWDER:8,10,quark:limestone:1,15,quark:limestone,15,quark:world_stone_pavement:2,15,CONCRETE:8,100)
RandomBlock(1,49,1,rustic:iron_lattice:0,5,CONCRETE_POWDER:8,10,quark:limestone:1,15,quark:limestone,15,quark:world_stone_pavement:2,15,CONCRETE:8,100)
RandomBlock(1,49,2,rustic:iron_lattice:0,5,CONCRETE_POWDER:8,10,quark:limestone:1,15,quark:limestone,15,quark:world_stone_pavement:2,15,CONCRETE:8,100)
RandomBlock(1,49,3,rustic:iron_lattice:0,5,CONCRETE_POWDER:8,10,quark:limestone:1,15,quark:limestone,15,quark:world_stone_pavement:2,15,CONCRETE:8,100)
RandomBlock(1,49,5,rustic:iron_lattice:0,5,CONCRETE_POWDER:8,10,quark:limestone:1,15,quark:limestone,15,quark:world_stone_pavement:2,15,CONCRETE:8,100)
Block(1,49,8,quark:iron_plate:1)
RandomBlock(1,50,-5,rustic:iron_lattice:0,5,CONCRETE_POWDER:8,10,quark:limestone:1,15,quark:limestone,15,quark:world_stone_pavement:2,15,CONCRETE:8,100)
RandomBlock(1,50,-4,rustic:iron_lattice:0,5,CONCRETE_POWDER:8,10,quark:limestone:1,15,quark:limestone,15,quark:world_stone_pavement:2,15,CONCRETE:8,100)
RandomBlock(1,50,-3,rustic:iron_lattice:0,5,CONCRETE_POWDER:8,10,quark:limestone:1,15,quark:limestone,15,quark:world_stone_pavement:2,15,CONCRETE:8,100)
RandomBlock(1,50,-2,rustic:iron_lattice:0,5,CONCRETE_POWDER:8,10,quark:limestone:1,15,quark:limestone,15,quark:world_stone_pavement:2,15,CONCRETE:8,100)
RandomBlock(1,50,-1,rustic:iron_lattice:0,5,CONCRETE_POWDER:8,10,quark:limestone:1,15,quark:limestone,15,quark:world_stone_pavement:2,15,CONCRETE:8,100)
RandomBlock(1,50,0,rustic:iron_lattice:0,5,STAINED_CLAY:15,5,STAINED_CLAY:7,5,quark:iron_plate_slab:8,15,quark:world_stone_pavement:2,15,STAINED_CLAY:9,100)
RandomBlock(1,50,1,rustic:iron_lattice:0,5,STAINED_CLAY:15,5,STAINED_CLAY:7,5,quark:iron_plate_slab:8,15,quark:world_stone_pavement:2,15,STAINED_CLAY:9,100)
RandomBlock(1,50,2,rustic:iron_lattice:0,5,STAINED_CLAY:15,5,STAINED_CLAY:7,5,quark:iron_plate_slab:8,15,quark:world_stone_pavement:2,15,STAINED_CLAY:9,100)
RandomBlock(1,50,3,rustic:iron_lattice:0,5,STAINED_CLAY:15,5,STAINED_CLAY:7,5,quark:iron_plate_slab:8,15,quark:world_stone_pavement:2,15,STAINED_CLAY:9,100)
RandomBlock(1,50,5,rustic:iron_lattice:0,5,CONCRETE_POWDER:8,10,quark:limestone:1,15,quark:limestone,15,quark:world_stone_pavement:2,15,CONCRETE:8,100)
RandomBlock(1,50,6,rustic:iron_lattice:0,5,STAINED_CLAY:15,5,STAINED_CLAY:7,5,quark:iron_plate_slab:8,15,quark:world_stone_pavement:2,15,STAINED_CLAY:9,100)
RandomBlock(1,50,7,rustic:iron_lattice:0,5,STAINED_CLAY:15,5,STAINED_CLAY:7,5,quark:iron_plate_slab:8,15,quark:world_stone_pavement:2,15,STAINED_CLAY:9,100)
RandomBlock(1,50,8,rustic:iron_lattice:0,5,STAINED_CLAY:15,5,STAINED_CLAY:7,5,quark:iron_plate_slab:8,15,quark:world_stone_pavement:2,15,STAINED_CLAY:9,100)
RandomBlock(1,51,-5,rustic:iron_lattice:0,5,CONCRETE_POWDER:8,10,quark:limestone:1,15,quark:limestone,15,quark:world_stone_pavement:2,15,CONCRETE:8,100)
RandomBlock(1,51,-4,rustic:iron_lattice:0,5,CONCRETE_POWDER:8,10,quark:limestone:1,15,quark:limestone,15,quark:world_stone_pavement:2,15,CONCRETE:8,100)
RandomBlock(1,51,-3,rustic:iron_lattice:0,5,CONCRETE_POWDER:8,10,quark:limestone:1,15,quark:limestone,15,quark:world_stone_pavement:2,15,CONCRETE:8,100)
RandomBlock(1,51,-2,rustic:iron_lattice:0,5,CONCRETE_POWDER:8,10,quark:limestone:1,15,quark:limestone,15,quark:world_stone_pavement:2,15,CONCRETE:8,100)
RandomBlock(1,51,-1,rustic:iron_lattice:0,5,CONCRETE_POWDER:8,10,quark:limestone:1,15,quark:limestone,15,quark:world_stone_pavement:2,15,CONCRETE:8,100)
RandomBlock(1,51,5,rustic:iron_lattice:0,5,CONCRETE_POWDER:8,10,quark:limestone:1,15,quark:limestone,15,quark:world_stone_pavement:2,15,CONCRETE:8,100)
Block(1,52,-5,CONCRETE:15)
Block(1,52,-4,STAINED_GLASS_PANE:7)
Block(1,52,-3,STAINED_GLASS_PANE:7)
Block(1,52,-2,CONCRETE:15)
RandomBlock(1,52,-1,rustic:iron_lattice:0,5,CONCRETE_POWDER:8,10,quark:limestone:1,15,quark:limestone,15,quark:world_stone_pavement:2,15,CONCRETE:8,100)
Block(1,52,5,CONCRETE:15)
RandomBlock(1,53,-5,rustic:iron_lattice:0,5,CONCRETE_POWDER:8,10,quark:limestone:1,15,quark:limestone,15,quark:world_stone_pavement:2,15,CONCRETE:8,100)
RandomBlock(1,53,-4,rustic:iron_lattice:0,5,CONCRETE_POWDER:8,10,quark:limestone:1,15,quark:limestone,15,quark:world_stone_pavement:2,15,CONCRETE:8,100)
RandomBlock(1,53,-3,rustic:iron_lattice:0,5,CONCRETE_POWDER:8,10,quark:limestone:1,15,quark:limestone,15,quark:world_stone_pavement:2,15,CONCRETE:8,100)
RandomBlock(1,53,-2,rustic:iron_lattice:0,5,CONCRETE_POWDER:8,10,quark:limestone:1,15,quark:limestone,15,quark:world_stone_pavement:2,15,CONCRETE:8,100)
RandomBlock(1,53,-1,rustic:iron_lattice:0,5,CONCRETE_POWDER:8,10,quark:limestone:1,15,quark:limestone,15,quark:world_stone_pavement:2,15,CONCRETE:8,100)
RandomBlock(1,53,5,rustic:iron_lattice:0,5,CONCRETE_POWDER:8,10,quark:limestone:1,15,quark:limestone,15,quark:world_stone_pavement:2,15,CONCRETE:8,100)
Block(1,53,7,quark:iron_plate:1)
RandomBlock(1,54,-5,rustic:iron_lattice:0,5,CONCRETE_POWDER:8,10,quark:limestone:1,15,quark:limestone,15,quark:world_stone_pavement:2,15,CONCRETE:8,100)
RandomBlock(1,54,-4,rustic:iron_lattice:0,5,CONCRETE_POWDER:8,10,quark:limestone:1,15,quark:limestone,15,quark:world_stone_pavement:2,15,CONCRETE:8,100)
RandomBlock(1,54,-3,rustic:iron_lattice:0,5,CONCRETE_POWDER:8,10,quark:limestone:1,15,quark:limestone,15,quark:world_stone_pavement:2,15,CONCRETE:8,100)
RandomBlock(1,54,-2,rustic:iron_lattice:0,5,CONCRETE_POWDER:8,10,quark:limestone:1,15,quark:limestone,15,quark:world_stone_pavement:2,15,CONCRETE:8,100)
RandomBlock(1,54,-1,rustic:iron_lattice:0,5,CONCRETE_POWDER:8,10,quark:limestone:1,15,quark:limestone,15,quark:world_stone_pavement:2,15,CONCRETE:8,100)
RandomBlock(1,54,0,rustic:iron_lattice:0,5,CONCRETE_POWDER:8,10,quark:limestone:1,15,quark:limestone,15,quark:world_stone_pavement:2,15,CONCRETE:8,100)
RandomBlock(1,54,1,rustic:iron_lattice:0,5,CONCRETE_POWDER:8,10,quark:limestone:1,15,quark:limestone,15,quark:world_stone_pavement:2,15,CONCRETE:8,100)
RandomBlock(1,54,2,rustic:iron_lattice:0,5,CONCRETE_POWDER:8,10,quark:limestone:1,15,quark:limestone,15,quark:world_stone_pavement:2,15,CONCRETE:8,100)
RandomBlock(1,54,3,rustic:iron_lattice:0,5,CONCRETE_POWDER:8,10,quark:limestone:1,15,quark:limestone,15,quark:world_stone_pavement:2,15,CONCRETE:8,100)
RandomBlock(1,54,4,rustic:iron_lattice:0,5,CONCRETE_POWDER:8,10,quark:limestone:1,15,quark:limestone,15,quark:world_stone_pavement:2,15,CONCRETE:8,100)
RandomBlock(1,54,5,rustic:iron_lattice:0,5,CONCRETE_POWDER:8,10,quark:limestone:1,15,quark:limestone,15,quark:world_stone_pavement:2,15,CONCRETE:8,100)
RandomBlock(1,54,6,rustic:iron_lattice:0,5,CONCRETE_POWDER:8,10,quark:limestone:1,15,quark:limestone,15,quark:world_stone_pavement:2,15,CONCRETE:8,100)
RandomBlock(1,54,7,rustic:iron_lattice:0,5,CONCRETE_POWDER:8,10,quark:limestone:1,15,quark:limestone,15,quark:world_stone_pavement:2,15,CONCRETE:8,100)
RandomBlock(1,54,8,rustic:iron_lattice:0,5,CONCRETE_POWDER:8,10,quark:limestone:1,15,quark:limestone,15,quark:world_stone_pavement:2,15,CONCRETE:8,100)
RandomBlock(1,55,-5,rustic:iron_lattice:0,5,CONCRETE_POWDER:8,10,quark:limestone:1,15,quark:limestone,15,quark:world_stone_pavement:2,15,CONCRETE:8,100)
RandomBlock(1,55,-4,rustic:iron_lattice:0,5,CONCRETE_POWDER:8,10,quark:limestone:1,15,quark:limestone,15,quark:world_stone_pavement:2,15,CONCRETE:8,100)
RandomBlock(1,55,-3,rustic:iron_lattice:0,5,CONCRETE_POWDER:8,10,quark:limestone:1,15,quark:limestone,15,quark:world_stone_pavement:2,15,CONCRETE:8,100)
RandomBlock(1,55,-2,rustic:iron_lattice:0,5,CONCRETE_POWDER:8,10,quark:limestone:1,15,quark:limestone,15,quark:world_stone_pavement:2,15,CONCRETE:8,100)
RandomBlock(1,55,-1,rustic:iron_lattice:0,5,CONCRETE_POWDER:8,10,quark:limestone:1,15,quark:limestone,15,quark:world_stone_pavement:2,15,CONCRETE:8,100)
Block(1,55,1,PISTON_BASE:1)
Block(1,55,2,PISTON_BASE:1)
Block(1,55,6,PISTON_BASE:1)
Block(1,55,7,PISTON_BASE:1)
RandomBlock(1,56,-5,rustic:iron_lattice:0,5,CONCRETE_POWDER:8,10,quark:limestone:1,15,quark:limestone,15,quark:world_stone_pavement:2,15,CONCRETE:8,100)
Block(1,56,-4,STAINED_GLASS_PANE:7)
Block(1,56,-3,STAINED_GLASS_PANE:7)
RandomBlock(1,56,-2,rustic:iron_lattice:0,5,CONCRETE_POWDER:8,10,quark:limestone:1,15,quark:limestone,15,quark:world_stone_pavement:2,15,CONCRETE:8,100)
RandomBlock(1,56,-1,rustic:iron_lattice:0,5,CONCRETE_POWDER:8,10,quark:limestone:1,15,quark:limestone,15,quark:world_stone_pavement:2,15,CONCRETE:8,100)
Block(1,56,1,ANVIL:1)
Block(1,56,2,ANVIL:3)
Block(1,56,6,ANVIL:1)
Block(1,56,7,ANVIL:3)
RandomBlock(1,57,-5,rustic:iron_lattice:0,5,CONCRETE_POWDER:8,10,quark:limestone:1,15,quark:limestone,15,quark:world_stone_pavement:2,15,CONCRETE:8,100)
RandomBlock(1,57,-4,rustic:iron_lattice:0,5,CONCRETE_POWDER:8,10,quark:limestone:1,15,quark:limestone,15,quark:world_stone_pavement:2,15,CONCRETE:8,100)
RandomBlock(1,57,-3,rustic:iron_lattice:0,5,CONCRETE_POWDER:8,10,quark:limestone:1,15,quark:limestone,15,quark:world_stone_pavement:2,15,CONCRETE:8,100)
RandomBlock(1,57,-2,rustic:iron_lattice:0,5,CONCRETE_POWDER:8,10,quark:limestone:1,15,quark:limestone,15,quark:world_stone_pavement:2,15,CONCRETE:8,100)
RandomBlock(1,57,-1,rustic:iron_lattice:0,5,CONCRETE_POWDER:8,10,quark:limestone:1,15,quark:limestone,15,quark:world_stone_pavement:2,15,CONCRETE:8,100)
Block(1,57,1,STEP:0)
Block(1,57,2,STEP:0)
Block(1,57,6,STEP:0)
Block(1,57,7,STEP:0)
RandomBlock(1,58,-5,rustic:iron_lattice:0,5,CONCRETE_POWDER:8,10,quark:limestone:1,15,quark:limestone,15,quark:world_stone_pavement:2,15,CONCRETE:8,100)
RandomBlock(1,58,-4,rustic:iron_lattice:0,5,CONCRETE_POWDER:8,10,quark:limestone:1,15,quark:limestone,15,quark:world_stone_pavement:2,15,CONCRETE:8,100)
RandomBlock(1,58,-3,rustic:iron_lattice:0,5,CONCRETE_POWDER:8,10,quark:limestone:1,15,quark:limestone,15,quark:world_stone_pavement:2,15,CONCRETE:8,100)
RandomBlock(1,58,-2,rustic:iron_lattice:0,5,CONCRETE_POWDER:8,10,quark:limestone:1,15,quark:limestone,15,quark:world_stone_pavement:2,15,CONCRETE:8,100)
RandomBlock(1,58,-1,rustic:iron_lattice:0,5,CONCRETE_POWDER:8,10,quark:limestone:1,15,quark:limestone,15,quark:world_stone_pavement:2,15,CONCRETE:8,100)
Block(1,58,0,STEP:5)
RandomBlock(1,58,1,SMOOTH_BRICK:0,40,SMOOTH_BRICK:1,20,SMOOTH_BRICK:2,30,SMOOTH_BRICK:0,100)
RandomBlock(1,58,2,SMOOTH_BRICK:0,40,SMOOTH_BRICK:1,20,SMOOTH_BRICK:2,30,SMOOTH_BRICK:0,100)
Block(1,58,3,STEP:5)
Block(1,58,4,STEP:5)
Block(1,58,5,STEP:5)
Block(1,58,6,STEP:5)
RandomBlock(1,58,7,SMOOTH_BRICK:0,40,SMOOTH_BRICK:1,20,SMOOTH_BRICK:2,30,SMOOTH_BRICK:0,100)
RandomBlock(1,58,8,SMOOTH_BRICK:0,40,SMOOTH_BRICK:1,20,SMOOTH_BRICK:2,30,SMOOTH_BRICK:0,100)
Block(1,59,-5,IRON_FENCE:0)
Block(1,59,-4,IRON_FENCE:0)
Block(1,59,-3,IRON_FENCE:0)
Block(1,59,-2,IRON_FENCE:0)
Block(1,59,-1,IRON_FENCE:0)
Block(2,43,4,STONE:6)
Block(2,43,6,STONE:6)
RandomBlock(2,44,-5,rustic:iron_lattice:0,5,STAINED_CLAY:15,5,STAINED_CLAY:7,5,quark:iron_plate_slab:8,15,quark:world_stone_pavement:2,15,STAINED_CLAY:9,100)
RandomBlock(2,44,-4,rustic:iron_lattice:0,5,STAINED_CLAY:15,5,STAINED_CLAY:7,5,quark:iron_plate_slab:8,15,quark:world_stone_pavement:2,15,STAINED_CLAY:9,100)
RandomBlock(2,44,-3,rustic:iron_lattice:0,5,STAINED_CLAY:15,5,STAINED_CLAY:7,5,quark:iron_plate_slab:8,15,quark:world_stone_pavement:2,15,STAINED_CLAY:9,100)
RandomBlock(2,44,-2,rustic:iron_lattice:0,5,STAINED_CLAY:15,5,STAINED_CLAY:7,5,quark:iron_plate_slab:8,15,quark:world_stone_pavement:2,15,STAINED_CLAY:9,100)
RandomBlock(2,44,-1,rustic:iron_lattice:0,5,STAINED_CLAY:15,5,STAINED_CLAY:7,5,quark:iron_plate_slab:8,15,quark:world_stone_pavement:2,15,STAINED_CLAY:9,100)
RandomBlock(2,44,0,rustic:iron_lattice:0,5,STAINED_CLAY:15,5,STAINED_CLAY:7,5,quark:iron_plate_slab:8,15,quark:world_stone_pavement:2,15,STAINED_CLAY:9,100)
RandomBlock(2,44,1,rustic:iron_lattice:0,5,STAINED_CLAY:15,5,STAINED_CLAY:7,5,quark:iron_plate_slab:8,15,quark:world_stone_pavement:2,15,STAINED_CLAY:9,100)
RandomBlock(2,44,2,rustic:iron_lattice:0,5,STAINED_CLAY:15,5,STAINED_CLAY:7,5,quark:iron_plate_slab:8,15,quark:world_stone_pavement:2,15,STAINED_CLAY:9,100)
RandomBlock(2,44,3,rustic:iron_lattice:0,5,STAINED_CLAY:15,5,STAINED_CLAY:7,5,quark:iron_plate_slab:8,15,quark:world_stone_pavement:2,15,STAINED_CLAY:9,100)
RandomBlock(2,44,4,rustic:iron_lattice:0,5,STAINED_CLAY:15,5,STAINED_CLAY:7,5,quark:iron_plate_slab:8,15,quark:world_stone_pavement:2,15,STAINED_CLAY:9,100)
RandomBlock(2,44,5,rustic:iron_lattice:0,5,STAINED_CLAY:15,5,STAINED_CLAY:7,5,quark:iron_plate_slab:8,15,quark:world_stone_pavement:2,15,STAINED_CLAY:9,100)
RandomBlock(2,44,6,rustic:iron_lattice:0,5,STAINED_CLAY:15,5,STAINED_CLAY:7,5,quark:iron_plate_slab:8,15,quark:world_stone_pavement:2,15,STAINED_CLAY:9,100)
RandomBlock(2,44,7,rustic:iron_lattice:0,5,STAINED_CLAY:15,5,STAINED_CLAY:7,5,quark:iron_plate_slab:8,15,quark:world_stone_pavement:2,15,STAINED_CLAY:9,100)
RandomBlock(2,44,8,rustic:iron_lattice:0,5,STAINED_CLAY:15,5,STAINED_CLAY:7,5,quark:iron_plate_slab:8,15,quark:world_stone_pavement:2,15,STAINED_CLAY:9,100)
RandomBlock(2,45,-5,rustic:iron_lattice:0,5,CONCRETE_POWDER:8,10,quark:limestone:1,15,quark:limestone,15,quark:world_stone_pavement:2,15,CONCRETE:8,100)
Block(2,45,-4,STEP:15)
Block(2,45,-3,STEP:15)
Block(2,45,-2,CAULDRON:0)
RandomBlock(2,45,-1,rustic:iron_lattice:0,5,CONCRETE_POWDER:8,10,quark:limestone:1,15,quark:limestone,15,quark:world_stone_pavement:2,15,CONCRETE:8,100)
RandomBlock(2,45,0,rustic:iron_lattice:0,5,CONCRETE_POWDER:8,10,quark:limestone:1,15,quark:limestone,15,quark:world_stone_pavement:2,15,CONCRETE:8,100)
RandomBlock(2,45,3,rustic:iron_lattice:0,5,CONCRETE_POWDER:8,10,quark:limestone:1,15,quark:limestone,15,quark:world_stone_pavement:2,15,CONCRETE:8,100)
RandomBlock(2,45,4,SMOOTH_BRICK:0,40,SMOOTH_BRICK:1,20,SMOOTH_BRICK:2,30,SMOOTH_BRICK:0,100)
RandomBlock(2,45,5,rustic:iron_lattice:0,5,CONCRETE_POWDER:8,10,quark:limestone:1,15,quark:limestone,15,quark:world_stone_pavement:2,15,CONCRETE:8,100)
Block(2,45,6,SMOOTH_STAIRS:2)
Block(2,45,7,CONCRETE:15)
RandomBlock(2,45,8,SMOOTH_BRICK:0,40,SMOOTH_BRICK:1,20,SMOOTH_BRICK:2,30,SMOOTH_BRICK:0,100)
Block(2,46,-5,CONCRETE:15)
Block(2,46,-1,CONCRETE:15)
RandomBlock(2,46,0,rustic:iron_lattice:0,5,CONCRETE_POWDER:8,10,quark:limestone:1,15,quark:limestone,15,quark:world_stone_pavement:2,15,CONCRETE:8,100)
RandomBlock(2,46,3,rustic:iron_lattice:0,5,CONCRETE_POWDER:8,10,quark:limestone:1,15,quark:limestone,15,quark:world_stone_pavement:2,15,CONCRETE:8,100)
Block(2,46,4,SMOOTH_STAIRS:1)
Block(2,46,5,CONCRETE:15)
Block(2,46,6,SMOOTH_STAIRS:2)
Block(2,46,7,CONCRETE:15)
RandomBlock(2,46,8,SMOOTH_BRICK:0,40,SMOOTH_BRICK:1,20,SMOOTH_BRICK:2,30,SMOOTH_BRICK:0,100)
RandomBlock(2,47,-5,rustic:iron_lattice:0,5,CONCRETE_POWDER:8,10,quark:limestone:1,15,quark:limestone,15,quark:world_stone_pavement:2,15,CONCRETE:8,100)
RandomBlock(2,47,-1,rustic:iron_lattice:0,5,CONCRETE_POWDER:8,10,quark:limestone:1,15,quark:limestone,15,quark:world_stone_pavement:2,15,CONCRETE:8,100)
RandomBlock(2,47,0,rustic:iron_lattice:0,5,CONCRETE_POWDER:8,10,quark:limestone:1,15,quark:limestone,15,quark:world_stone_pavement:2,15,CONCRETE:8,100)
RandomBlock(2,47,1,rustic:iron_lattice:0,5,CONCRETE_POWDER:8,10,quark:limestone:1,15,quark:limestone,15,quark:world_stone_pavement:2,15,CONCRETE:8,100)
RandomBlock(2,47,2,rustic:iron_lattice:0,5,CONCRETE_POWDER:8,10,quark:limestone:1,15,quark:limestone,15,quark:world_stone_pavement:2,15,CONCRETE:8,100)
RandomBlock(2,47,3,rustic:iron_lattice:0,5,CONCRETE_POWDER:8,10,quark:limestone:1,15,quark:limestone,15,quark:world_stone_pavement:2,15,CONCRETE:8,100)
RandomBlock(2,47,5,rustic:iron_lattice:0,5,CONCRETE_POWDER:8,10,quark:limestone:1,15,quark:limestone,15,quark:world_stone_pavement:2,15,CONCRETE:8,100)
Block(2,47,6,SMOOTH_STAIRS:2)
Block(2,47,7,CONCRETE:15)
RandomBlock(2,47,8,SMOOTH_BRICK:0,40,SMOOTH_BRICK:1,20,SMOOTH_BRICK:2,30,SMOOTH_BRICK:0,100)
RandomBlock(2,48,-5,rustic:iron_lattice:0,5,CONCRETE_POWDER:8,10,quark:limestone:1,15,quark:limestone,15,quark:world_stone_pavement:2,15,CONCRETE:8,100)
RandomBlock(2,48,-1,rustic:iron_lattice:0,5,CONCRETE_POWDER:8,10,quark:limestone:1,15,quark:limestone,15,quark:world_stone_pavement:2,15,CONCRETE:8,100)
RandomBlock(2,48,0,rustic:iron_lattice:0,5,CONCRETE_POWDER:8,10,quark:limestone:1,15,quark:limestone,15,quark:world_stone_pavement:2,15,CONCRETE:8,100)
RandomBlock(2,48,1,rustic:iron_lattice:0,5,CONCRETE_POWDER:8,10,quark:limestone:1,15,quark:limestone,15,quark:world_stone_pavement:2,15,CONCRETE:8,100)
RandomBlock(2,48,2,rustic:iron_lattice:0,5,CONCRETE_POWDER:8,10,quark:limestone:1,15,quark:limestone,15,quark:world_stone_pavement:2,15,CONCRETE:8,100)
RandomBlock(2,48,3,rustic:iron_lattice:0,5,CONCRETE_POWDER:8,10,quark:limestone:1,15,quark:limestone,15,quark:world_stone_pavement:2,15,CONCRETE:8,100)
RandomBlock(2,48,5,rustic:iron_lattice:0,5,CONCRETE_POWDER:8,10,quark:limestone:1,15,quark:limestone,15,quark:world_stone_pavement:2,15,CONCRETE:8,100)
Block(2,48,6,SMOOTH_STAIRS:2)
Block(2,48,7,CONCRETE:15)
RandomBlock(2,48,8,SMOOTH_BRICK:0,40,SMOOTH_BRICK:1,20,SMOOTH_BRICK:2,30,SMOOTH_BRICK:0,100)
RandomBlock(2,49,-5,rustic:iron_lattice:0,5,CONCRETE_POWDER:8,10,quark:limestone:1,15,quark:limestone,15,quark:world_stone_pavement:2,15,CONCRETE:8,100)
RandomBlock(2,49,-4,rustic:iron_lattice:0,5,CONCRETE_POWDER:8,10,quark:limestone:1,15,quark:limestone,15,quark:world_stone_pavement:2,15,CONCRETE:8,100)
RandomBlock(2,49,-3,rustic:iron_lattice:0,5,CONCRETE_POWDER:8,10,quark:limestone:1,15,quark:limestone,15,quark:world_stone_pavement:2,15,CONCRETE:8,100)
RandomBlock(2,49,-2,rustic:iron_lattice:0,5,CONCRETE_POWDER:8,10,quark:limestone:1,15,quark:limestone,15,quark:world_stone_pavement:2,15,CONCRETE:8,100)
RandomBlock(2,49,-1,rustic:iron_lattice:0,5,CONCRETE_POWDER:8,10,quark:limestone:1,15,quark:limestone,15,quark:world_stone_pavement:2,15,CONCRETE:8,100)
RandomBlock(2,49,0,rustic:iron_lattice:0,5,CONCRETE_POWDER:8,10,quark:limestone:1,15,quark:limestone,15,quark:world_stone_pavement:2,15,CONCRETE:8,100)
RandomBlock(2,49,1,rustic:iron_lattice:0,5,CONCRETE_POWDER:8,10,quark:limestone:1,15,quark:limestone,15,quark:world_stone_pavement:2,15,CONCRETE:8,100)
RandomBlock(2,49,2,rustic:iron_lattice:0,5,CONCRETE_POWDER:8,10,quark:limestone:1,15,quark:limestone,15,quark:world_stone_pavement:2,15,CONCRETE:8,100)
