
#######################################################################
# +-----------------------------------------------------------------+ #
# |                            BO4 object                           | #
# +-----------------------------------------------------------------+ #
#######################################################################

Author: NLBlackEagle

Description: No description given

SettingsMode: WriteWithoutComments


#######################################################################
# +-----------------------------------------------------------------+ #
# |                          Main settings                          | #
# +-----------------------------------------------------------------+ #
#######################################################################

FixedRotation: 

Frequency: 0

SpawnHeight: highestBlock

UseCenterForHighestBlock: true

##############################
# Height Limits for the BO4. #
##############################

MinHeight: 0

MaxHeight: 255

InheritBO3: 

InheritBO3Rotation: NORTH

OverrideChildSettings: true

OverrideParentHeight: false

CanOverride: true

BranchFrequency: 0

BranchFrequencyGroup: 

MustBeBelowOther: false

MustBeInside: 

CannotBeInside: 

ReplacesBO3: 

MustBeInsideWorldBorders: false

CanSpawnOnWater: true

SpawnOnWaterOnly: false

SpawnUnderWater: false

SpawnAtWaterLevel: false

HeightOffset: 0

RemoveAir: true

ReplaceAbove: 

ReplaceBelow: 

ReplaceWithBiomeBlocks: false

ReplaceWithSurfaceBlock: GRASS

ReplaceWithGroundBlock: DIRT

ReplaceWithStoneBlock: STONE

SmoothRadius: 0

SmoothHeightOffset: 0

SmoothStartTop: false

SmoothStartWood: false

SmoothingSurfaceBlock: 

SmoothingGroundBlock: 

BO3Group: 

IsSpawnPoint: false

DoReplaceBlocks: true


#######################################################################
# +-----------------------------------------------------------------+ #
# |                              Blocks                             | #
# +-----------------------------------------------------------------+ #
#######################################################################

RandomBlock(-8,0,-7,rustic:iron_lattice:0,5,quark:iron_plate:1,15,STAINED_CLAY:15,15,STAINED_CLAY:7,100)
RandomBlock(-8,0,-6,rustic:iron_lattice:0,5,quark:iron_plate:1,15,STAINED_CLAY:15,15,STAINED_CLAY:7,100)
RandomBlock(-8,1,-7,rustic:iron_lattice:0,5,quark:iron_plate:1,15,STAINED_CLAY:15,15,STAINED_CLAY:7,100)
RandomBlock(-8,1,-6,rustic:iron_lattice:0,5,quark:iron_plate:1,15,STAINED_CLAY:15,15,STAINED_CLAY:7,100)
RandomBlock(-8,2,-7,rustic:iron_lattice:0,5,quark:iron_plate:1,15,STAINED_CLAY:15,15,STAINED_CLAY:7,100)
RandomBlock(-8,2,-6,rustic:iron_lattice:0,5,quark:iron_plate:1,15,STAINED_CLAY:15,15,STAINED_CLAY:7,100)
RandomBlock(-8,3,-7,rustic:iron_lattice:0,5,quark:iron_plate:1,15,STAINED_CLAY:15,15,STAINED_CLAY:7,100)
RandomBlock(-8,3,-6,rustic:iron_lattice:0,5,quark:iron_plate:1,15,STAINED_CLAY:15,15,STAINED_CLAY:7,100)
RandomBlock(-8,4,-7,rustic:iron_lattice:0,5,quark:iron_plate:1,15,STAINED_CLAY:15,15,STAINED_CLAY:7,100)
RandomBlock(-8,4,-6,rustic:iron_lattice:0,5,quark:iron_plate:1,15,STAINED_CLAY:15,15,STAINED_CLAY:7,100)
RandomBlock(-8,5,-7,rustic:iron_lattice:0,5,quark:iron_plate:1,15,STAINED_CLAY:15,15,STAINED_CLAY:7,100)
RandomBlock(-8,5,-6,rustic:iron_lattice:0,5,quark:iron_plate:1,15,STAINED_CLAY:15,15,STAINED_CLAY:7,100)
RandomBlock(-8,6,-7,rustic:iron_lattice:0,5,quark:iron_plate:1,15,STAINED_CLAY:15,15,STAINED_CLAY:7,100)
RandomBlock(-8,6,-6,rustic:iron_lattice:0,5,quark:iron_plate:1,15,STAINED_CLAY:15,15,STAINED_CLAY:7,100)
RandomBlock(-8,7,-7,rustic:iron_lattice:0,5,quark:iron_plate:1,15,STAINED_CLAY:15,15,STAINED_CLAY:7,100)
RandomBlock(-8,7,-6,rustic:iron_lattice:0,5,quark:iron_plate:1,15,STAINED_CLAY:15,15,STAINED_CLAY:7,100)
RandomBlock(-8,8,-7,rustic:iron_lattice:0,5,quark:iron_plate:1,15,STAINED_CLAY:15,15,STAINED_CLAY:7,100)
RandomBlock(-8,8,-6,rustic:iron_lattice:0,5,quark:iron_plate:1,15,STAINED_CLAY:15,15,STAINED_CLAY:7,100)
RandomBlock(-8,9,-7,rustic:iron_lattice:0,5,quark:iron_plate:1,15,STAINED_CLAY:15,15,STAINED_CLAY:7,100)
RandomBlock(-8,9,-6,rustic:iron_lattice:0,5,quark:iron_plate:1,15,STAINED_CLAY:15,15,STAINED_CLAY:7,100)
RandomBlock(-8,10,-7,rustic:iron_lattice:0,5,quark:iron_plate:1,15,STAINED_CLAY:15,15,STAINED_CLAY:7,100)
RandomBlock(-8,10,-6,rustic:iron_lattice:0,5,quark:iron_plate:1,15,STAINED_CLAY:15,15,STAINED_CLAY:7,100)
RandomBlock(-8,11,-7,rustic:iron_lattice:0,5,quark:iron_plate:1,15,STAINED_CLAY:15,15,STAINED_CLAY:7,100)
RandomBlock(-8,11,-6,rustic:iron_lattice:0,5,quark:iron_plate:1,15,STAINED_CLAY:15,15,STAINED_CLAY:7,100)
RandomBlock(-8,12,-7,rustic:iron_lattice:0,5,quark:iron_plate:1,15,STAINED_CLAY:15,15,STAINED_CLAY:7,100)
RandomBlock(-8,12,-6,rustic:iron_lattice:0,5,quark:iron_plate:1,15,STAINED_CLAY:15,15,STAINED_CLAY:7,100)
RandomBlock(-8,13,-7,rustic:iron_lattice:0,5,quark:iron_plate:1,15,STAINED_CLAY:15,15,STAINED_CLAY:7,100)
RandomBlock(-8,13,-6,rustic:iron_lattice:0,5,quark:iron_plate:1,15,STAINED_CLAY:15,15,STAINED_CLAY:7,100)
RandomBlock(-8,14,-7,rustic:iron_lattice:0,5,quark:iron_plate:1,15,STAINED_CLAY:15,15,STAINED_CLAY:7,100)
RandomBlock(-8,14,-6,rustic:iron_lattice:0,5,quark:iron_plate:1,15,STAINED_CLAY:15,15,STAINED_CLAY:7,100)
RandomBlock(-8,15,-7,rustic:iron_lattice:0,5,quark:iron_plate:1,15,STAINED_CLAY:15,15,STAINED_CLAY:7,100)
RandomBlock(-8,15,-6,rustic:iron_lattice:0,5,quark:iron_plate:1,15,STAINED_CLAY:15,15,STAINED_CLAY:7,100)
RandomBlock(-8,16,-7,rustic:iron_lattice:0,5,quark:iron_plate:1,15,STAINED_CLAY:15,15,STAINED_CLAY:7,100)
RandomBlock(-8,16,-6,rustic:iron_lattice:0,5,quark:iron_plate:1,15,STAINED_CLAY:15,15,STAINED_CLAY:7,100)
RandomBlock(-8,17,-7,rustic:iron_lattice:0,5,quark:iron_plate:1,15,STAINED_CLAY:15,15,STAINED_CLAY:7,100)
RandomBlock(-8,17,-6,rustic:iron_lattice:0,5,quark:iron_plate:1,15,STAINED_CLAY:15,15,STAINED_CLAY:7,100)
RandomBlock(-8,18,-7,rustic:iron_lattice:0,5,quark:iron_plate:1,15,STAINED_CLAY:15,15,STAINED_CLAY:7,100)
RandomBlock(-8,18,-6,rustic:iron_lattice:0,5,quark:iron_plate:1,15,STAINED_CLAY:15,15,STAINED_CLAY:7,100)
RandomBlock(-8,19,-7,rustic:iron_lattice:0,5,quark:iron_plate:1,15,STAINED_CLAY:15,15,STAINED_CLAY:7,100)
RandomBlock(-8,19,-6,rustic:iron_lattice:0,5,quark:iron_plate:1,15,STAINED_CLAY:15,15,STAINED_CLAY:7,100)
RandomBlock(-8,20,-7,rustic:iron_lattice:0,5,quark:iron_plate:1,15,STAINED_CLAY:15,15,STAINED_CLAY:7,100)
RandomBlock(-8,20,-6,rustic:iron_lattice:0,5,quark:iron_plate:1,15,STAINED_CLAY:15,15,STAINED_CLAY:7,100)
RandomBlock(-8,21,-7,rustic:iron_lattice:0,5,quark:iron_plate:1,15,STAINED_CLAY:15,15,STAINED_CLAY:7,100)
RandomBlock(-8,21,-6,rustic:iron_lattice:0,5,quark:iron_plate:1,15,STAINED_CLAY:15,15,STAINED_CLAY:7,100)
RandomBlock(-8,22,-7,rustic:iron_lattice:0,5,quark:iron_plate:1,15,STAINED_CLAY:15,15,STAINED_CLAY:7,100)
RandomBlock(-8,22,-6,rustic:iron_lattice:0,5,quark:iron_plate:1,15,STAINED_CLAY:15,15,STAINED_CLAY:7,100)
RandomBlock(-8,23,-7,rustic:iron_lattice:0,5,quark:iron_plate:1,15,STAINED_CLAY:15,15,STAINED_CLAY:7,100)
RandomBlock(-8,23,-6,rustic:iron_lattice:0,5,quark:iron_plate:1,15,STAINED_CLAY:15,15,STAINED_CLAY:7,100)
RandomBlock(-8,24,-7,rustic:iron_lattice:0,5,quark:iron_plate:1,15,STAINED_CLAY:15,15,STAINED_CLAY:7,100)
RandomBlock(-8,24,-6,rustic:iron_lattice:0,5,quark:iron_plate:1,15,STAINED_CLAY:15,15,STAINED_CLAY:7,100)
RandomBlock(-8,25,-7,rustic:iron_lattice:0,5,quark:iron_plate:1,15,STAINED_CLAY:15,15,STAINED_CLAY:7,100)
RandomBlock(-8,25,-6,rustic:iron_lattice:0,5,quark:iron_plate:1,15,STAINED_CLAY:15,15,STAINED_CLAY:7,100)
RandomBlock(-8,26,-7,rustic:iron_lattice:0,5,quark:iron_plate:1,15,STAINED_CLAY:15,15,STAINED_CLAY:7,100)
RandomBlock(-8,26,-6,rustic:iron_lattice:0,5,quark:iron_plate:1,15,STAINED_CLAY:15,15,STAINED_CLAY:7,100)
RandomBlock(-8,27,-7,rustic:iron_lattice:0,5,quark:iron_plate:1,15,STAINED_CLAY:15,15,STAINED_CLAY:7,100)
RandomBlock(-8,27,-6,rustic:iron_lattice:0,5,quark:iron_plate:1,15,STAINED_CLAY:15,15,STAINED_CLAY:7,100)
RandomBlock(-8,28,-7,rustic:iron_lattice:0,5,quark:iron_plate:1,15,STAINED_CLAY:15,15,STAINED_CLAY:7,100)
RandomBlock(-8,28,-6,rustic:iron_lattice:0,5,quark:iron_plate:1,15,STAINED_CLAY:15,15,STAINED_CLAY:7,100)
RandomBlock(-8,29,-7,rustic:iron_lattice:0,5,quark:iron_plate:1,15,STAINED_CLAY:15,15,STAINED_CLAY:7,100)
RandomBlock(-8,29,-6,rustic:iron_lattice:0,5,quark:iron_plate:1,15,STAINED_CLAY:15,15,STAINED_CLAY:7,100)
RandomBlock(-8,30,-7,rustic:iron_lattice:0,5,quark:iron_plate:1,15,STAINED_CLAY:15,15,STAINED_CLAY:7,100)
RandomBlock(-8,30,-6,rustic:iron_lattice:0,5,quark:iron_plate:1,15,STAINED_CLAY:15,15,STAINED_CLAY:7,100)
RandomBlock(-8,31,-7,rustic:iron_lattice:0,5,quark:iron_plate:1,15,STAINED_CLAY:15,15,STAINED_CLAY:7,100)
RandomBlock(-8,31,-6,rustic:iron_lattice:0,5,quark:iron_plate:1,15,STAINED_CLAY:15,15,STAINED_CLAY:7,100)
RandomBlock(-8,32,-7,rustic:iron_lattice:0,5,quark:iron_plate:1,15,STAINED_CLAY:15,15,STAINED_CLAY:7,100)
RandomBlock(-8,32,-6,rustic:iron_lattice:0,5,quark:iron_plate:1,15,STAINED_CLAY:15,15,STAINED_CLAY:7,100)
RandomBlock(-8,33,-7,rustic:iron_lattice:0,5,quark:iron_plate:1,15,STAINED_CLAY:15,15,STAINED_CLAY:7,100)
RandomBlock(-8,33,-6,rustic:iron_lattice:0,5,quark:iron_plate:1,15,STAINED_CLAY:15,15,STAINED_CLAY:7,100)
RandomBlock(-8,34,-7,rustic:iron_lattice:0,5,quark:iron_plate:1,15,STAINED_CLAY:15,15,STAINED_CLAY:7,100)
RandomBlock(-8,34,-6,rustic:iron_lattice:0,5,quark:iron_plate:1,15,STAINED_CLAY:15,15,STAINED_CLAY:7,100)
RandomBlock(-8,35,-7,rustic:iron_lattice:0,5,quark:iron_plate:1,15,STAINED_CLAY:15,15,STAINED_CLAY:7,100)
RandomBlock(-8,35,-6,rustic:iron_lattice:0,5,quark:iron_plate:1,15,STAINED_CLAY:15,15,STAINED_CLAY:7,100)
RandomBlock(-8,36,-7,rustic:iron_lattice:0,5,quark:iron_plate:1,15,STAINED_CLAY:15,15,STAINED_CLAY:7,100)
RandomBlock(-8,36,-6,rustic:iron_lattice:0,5,quark:iron_plate:1,15,STAINED_CLAY:15,15,STAINED_CLAY:7,100)
RandomBlock(-8,37,-7,rustic:iron_lattice:0,5,quark:iron_plate:1,15,STAINED_CLAY:15,15,STAINED_CLAY:7,100)
RandomBlock(-8,37,-6,rustic:iron_lattice:0,5,quark:iron_plate:1,15,STAINED_CLAY:15,15,STAINED_CLAY:7,100)
RandomBlock(-8,38,-7,rustic:iron_lattice:0,5,quark:iron_plate:1,15,STAINED_CLAY:15,15,STAINED_CLAY:7,100)
RandomBlock(-8,38,-6,rustic:iron_lattice:0,5,quark:iron_plate:1,15,STAINED_CLAY:15,15,STAINED_CLAY:7,100)
RandomBlock(-8,39,-7,rustic:iron_lattice:0,5,quark:iron_plate:1,15,STAINED_CLAY:15,15,STAINED_CLAY:7,100)
RandomBlock(-8,39,-6,rustic:iron_lattice:0,5,quark:iron_plate:1,15,STAINED_CLAY:15,15,STAINED_CLAY:7,100)
RandomBlock(-8,40,-7,rustic:iron_lattice:0,5,quark:iron_plate:1,15,STAINED_CLAY:15,15,STAINED_CLAY:7,100)
RandomBlock(-8,40,-6,rustic:iron_lattice:0,5,quark:iron_plate:1,15,STAINED_CLAY:15,15,STAINED_CLAY:7,100)
RandomBlock(-8,41,-7,rustic:iron_lattice:0,5,quark:iron_plate:1,15,STAINED_CLAY:15,15,STAINED_CLAY:7,100)
RandomBlock(-8,41,-6,rustic:iron_lattice:0,5,quark:iron_plate:1,15,STAINED_CLAY:15,15,STAINED_CLAY:7,100)
RandomBlock(-8,42,-7,rustic:iron_lattice:0,5,quark:iron_plate:1,15,STAINED_CLAY:15,15,STAINED_CLAY:7,100)
RandomBlock(-8,42,-6,rustic:iron_lattice:0,5,quark:iron_plate:1,15,STAINED_CLAY:15,15,STAINED_CLAY:7,100)
RandomBlock(-8,43,-7,rustic:iron_lattice:0,5,quark:iron_plate:1,15,STAINED_CLAY:15,15,STAINED_CLAY:7,100)
RandomBlock(-8,43,-6,rustic:iron_lattice:0,5,quark:iron_plate:1,15,STAINED_CLAY:15,15,STAINED_CLAY:7,100)
RandomBlock(-8,44,-7,rustic:iron_lattice:0,5,STAINED_CLAY:15,5,STAINED_CLAY:7,5,quark:iron_plate_slab:8,15,quark:world_stone_pavement:2,15,STAINED_CLAY:9,100)
RandomBlock(-8,44,-6,rustic:iron_lattice:0,5,STAINED_CLAY:15,5,STAINED_CLAY:7,5,quark:iron_plate_slab:8,15,quark:world_stone_pavement:2,15,STAINED_CLAY:9,100)
RandomBlock(-8,44,-5,rustic:iron_lattice:0,5,STAINED_CLAY:15,5,STAINED_CLAY:7,5,quark:iron_plate_slab:8,15,quark:world_stone_pavement:2,15,STAINED_CLAY:9,100)
Block(-8,44,-4,STEP:13)
Block(-8,44,-3,STEP:13)
Block(-8,44,-2,STEP:13)
RandomBlock(-8,44,-1,rustic:iron_lattice:0,5,STAINED_CLAY:15,5,STAINED_CLAY:7,5,quark:iron_plate_slab:8,15,quark:world_stone_pavement:2,15,STAINED_CLAY:9,100)
Block(-8,45,-1,rustic:iron_lattice:0)
Block(-8,46,-1,rustic:iron_lattice:0)
RandomBlock(-8,50,-7,rustic:iron_lattice:0,5,STAINED_CLAY:15,5,STAINED_CLAY:7,5,quark:iron_plate_slab:8,15,quark:world_stone_pavement:2,15,STAINED_CLAY:9,100)
RandomBlock(-8,50,-6,rustic:iron_lattice:0,5,STAINED_CLAY:15,5,STAINED_CLAY:7,5,quark:iron_plate_slab:8,15,quark:world_stone_pavement:2,15,STAINED_CLAY:9,100)
RandomBlock(-8,50,-5,rustic:iron_lattice:0,5,STAINED_CLAY:15,5,STAINED_CLAY:7,5,quark:iron_plate_slab:8,15,quark:world_stone_pavement:2,15,STAINED_CLAY:9,100)
RandomBlock(-8,50,-4,rustic:iron_lattice:0,5,STAINED_CLAY:15,5,STAINED_CLAY:7,5,quark:iron_plate_slab:8,15,quark:world_stone_pavement:2,15,STAINED_CLAY:9,100)
RandomBlock(-8,50,-3,rustic:iron_lattice:0,5,STAINED_CLAY:15,5,STAINED_CLAY:7,5,quark:iron_plate_slab:8,15,quark:world_stone_pavement:2,15,STAINED_CLAY:9,100)
RandomBlock(-8,50,-2,rustic:iron_lattice:0,5,CONCRETE_POWDER:8,10,quark:limestone:1,15,quark:limestone,15,quark:world_stone_pavement:2,15,CONCRETE:8,100)
Block(-8,51,-2,rustic:iron_lattice:0)
Block(-8,52,-2,rustic:iron_lattice:0)
Block(-8,65,-7,STEP:13)
Block(-8,65,-6,rustic:iron_lattice:0)
RandomBlock(-8,66,-7,CONCRETE_POWDER:7,25,CONCRETE:7,100)
Block(-8,66,-6,IRON_FENCE:0)
Block(-8,67,-7,STEP:5)
Block(-8,68,-7,rustic:iron_lattice:0)
RandomBlock(-7,0,-7,rustic:iron_lattice:0,5,quark:iron_plate:1,15,STAINED_CLAY:15,15,STAINED_CLAY:7,100)
RandomBlock(-7,0,-6,rustic:iron_lattice:0,5,quark:iron_plate:1,15,STAINED_CLAY:15,15,STAINED_CLAY:7,100)
RandomBlock(-7,1,-7,rustic:iron_lattice:0,5,quark:iron_plate:1,15,STAINED_CLAY:15,15,STAINED_CLAY:7,100)
RandomBlock(-7,1,-6,rustic:iron_lattice:0,5,quark:iron_plate:1,15,STAINED_CLAY:15,15,STAINED_CLAY:7,100)
RandomBlock(-7,2,-7,rustic:iron_lattice:0,5,quark:iron_plate:1,15,STAINED_CLAY:15,15,STAINED_CLAY:7,100)
RandomBlock(-7,2,-6,rustic:iron_lattice:0,5,quark:iron_plate:1,15,STAINED_CLAY:15,15,STAINED_CLAY:7,100)
RandomBlock(-7,3,-7,rustic:iron_lattice:0,5,quark:iron_plate:1,15,STAINED_CLAY:15,15,STAINED_CLAY:7,100)
RandomBlock(-7,3,-6,rustic:iron_lattice:0,5,quark:iron_plate:1,15,STAINED_CLAY:15,15,STAINED_CLAY:7,100)
RandomBlock(-7,4,-7,rustic:iron_lattice:0,5,quark:iron_plate:1,15,STAINED_CLAY:15,15,STAINED_CLAY:7,100)
RandomBlock(-7,4,-6,rustic:iron_lattice:0,5,quark:iron_plate:1,15,STAINED_CLAY:15,15,STAINED_CLAY:7,100)
RandomBlock(-7,5,-7,rustic:iron_lattice:0,5,quark:iron_plate:1,15,STAINED_CLAY:15,15,STAINED_CLAY:7,100)
RandomBlock(-7,5,-6,rustic:iron_lattice:0,5,quark:iron_plate:1,15,STAINED_CLAY:15,15,STAINED_CLAY:7,100)
RandomBlock(-7,6,-7,rustic:iron_lattice:0,5,quark:iron_plate:1,15,STAINED_CLAY:15,15,STAINED_CLAY:7,100)
RandomBlock(-7,6,-6,rustic:iron_lattice:0,5,quark:iron_plate:1,15,STAINED_CLAY:15,15,STAINED_CLAY:7,100)
RandomBlock(-7,7,-7,rustic:iron_lattice:0,5,quark:iron_plate:1,15,STAINED_CLAY:15,15,STAINED_CLAY:7,100)
RandomBlock(-7,7,-6,rustic:iron_lattice:0,5,quark:iron_plate:1,15,STAINED_CLAY:15,15,STAINED_CLAY:7,100)
RandomBlock(-7,8,-7,rustic:iron_lattice:0,5,quark:iron_plate:1,15,STAINED_CLAY:15,15,STAINED_CLAY:7,100)
RandomBlock(-7,8,-6,rustic:iron_lattice:0,5,quark:iron_plate:1,15,STAINED_CLAY:15,15,STAINED_CLAY:7,100)
RandomBlock(-7,9,-7,rustic:iron_lattice:0,5,quark:iron_plate:1,15,STAINED_CLAY:15,15,STAINED_CLAY:7,100)
RandomBlock(-7,9,-6,rustic:iron_lattice:0,5,quark:iron_plate:1,15,STAINED_CLAY:15,15,STAINED_CLAY:7,100)
RandomBlock(-7,10,-7,rustic:iron_lattice:0,5,quark:iron_plate:1,15,STAINED_CLAY:15,15,STAINED_CLAY:7,100)
RandomBlock(-7,10,-6,rustic:iron_lattice:0,5,quark:iron_plate:1,15,STAINED_CLAY:15,15,STAINED_CLAY:7,100)
RandomBlock(-7,11,-7,rustic:iron_lattice:0,5,quark:iron_plate:1,15,STAINED_CLAY:15,15,STAINED_CLAY:7,100)
RandomBlock(-7,11,-6,rustic:iron_lattice:0,5,quark:iron_plate:1,15,STAINED_CLAY:15,15,STAINED_CLAY:7,100)
RandomBlock(-7,12,-7,rustic:iron_lattice:0,5,quark:iron_plate:1,15,STAINED_CLAY:15,15,STAINED_CLAY:7,100)
RandomBlock(-7,12,-6,rustic:iron_lattice:0,5,quark:iron_plate:1,15,STAINED_CLAY:15,15,STAINED_CLAY:7,100)
RandomBlock(-7,13,-7,rustic:iron_lattice:0,5,quark:iron_plate:1,15,STAINED_CLAY:15,15,STAINED_CLAY:7,100)
RandomBlock(-7,13,-6,rustic:iron_lattice:0,5,quark:iron_plate:1,15,STAINED_CLAY:15,15,STAINED_CLAY:7,100)
RandomBlock(-7,14,-7,rustic:iron_lattice:0,5,quark:iron_plate:1,15,STAINED_CLAY:15,15,STAINED_CLAY:7,100)
RandomBlock(-7,14,-6,rustic:iron_lattice:0,5,quark:iron_plate:1,15,STAINED_CLAY:15,15,STAINED_CLAY:7,100)
RandomBlock(-7,15,-7,rustic:iron_lattice:0,5,quark:iron_plate:1,15,STAINED_CLAY:15,15,STAINED_CLAY:7,100)
RandomBlock(-7,15,-6,rustic:iron_lattice:0,5,quark:iron_plate:1,15,STAINED_CLAY:15,15,STAINED_CLAY:7,100)
RandomBlock(-7,16,-7,rustic:iron_lattice:0,5,quark:iron_plate:1,15,STAINED_CLAY:15,15,STAINED_CLAY:7,100)
RandomBlock(-7,16,-6,rustic:iron_lattice:0,5,quark:iron_plate:1,15,STAINED_CLAY:15,15,STAINED_CLAY:7,100)
RandomBlock(-7,17,-7,rustic:iron_lattice:0,5,quark:iron_plate:1,15,STAINED_CLAY:15,15,STAINED_CLAY:7,100)
RandomBlock(-7,17,-6,rustic:iron_lattice:0,5,quark:iron_plate:1,15,STAINED_CLAY:15,15,STAINED_CLAY:7,100)
RandomBlock(-7,18,-7,rustic:iron_lattice:0,5,quark:iron_plate:1,15,STAINED_CLAY:15,15,STAINED_CLAY:7,100)
RandomBlock(-7,18,-6,rustic:iron_lattice:0,5,quark:iron_plate:1,15,STAINED_CLAY:15,15,STAINED_CLAY:7,100)
RandomBlock(-7,19,-7,rustic:iron_lattice:0,5,quark:iron_plate:1,15,STAINED_CLAY:15,15,STAINED_CLAY:7,100)
RandomBlock(-7,19,-6,rustic:iron_lattice:0,5,quark:iron_plate:1,15,STAINED_CLAY:15,15,STAINED_CLAY:7,100)
RandomBlock(-7,20,-7,rustic:iron_lattice:0,5,quark:iron_plate:1,15,STAINED_CLAY:15,15,STAINED_CLAY:7,100)
RandomBlock(-7,20,-6,rustic:iron_lattice:0,5,quark:iron_plate:1,15,STAINED_CLAY:15,15,STAINED_CLAY:7,100)
RandomBlock(-7,21,-7,rustic:iron_lattice:0,5,quark:iron_plate:1,15,STAINED_CLAY:15,15,STAINED_CLAY:7,100)
RandomBlock(-7,21,-6,rustic:iron_lattice:0,5,quark:iron_plate:1,15,STAINED_CLAY:15,15,STAINED_CLAY:7,100)
RandomBlock(-7,22,-7,rustic:iron_lattice:0,5,quark:iron_plate:1,15,STAINED_CLAY:15,15,STAINED_CLAY:7,100)
RandomBlock(-7,22,-6,rustic:iron_lattice:0,5,quark:iron_plate:1,15,STAINED_CLAY:15,15,STAINED_CLAY:7,100)
RandomBlock(-7,23,-7,rustic:iron_lattice:0,5,quark:iron_plate:1,15,STAINED_CLAY:15,15,STAINED_CLAY:7,100)
RandomBlock(-7,23,-6,rustic:iron_lattice:0,5,quark:iron_plate:1,15,STAINED_CLAY:15,15,STAINED_CLAY:7,100)
RandomBlock(-7,24,-7,rustic:iron_lattice:0,5,quark:iron_plate:1,15,STAINED_CLAY:15,15,STAINED_CLAY:7,100)
RandomBlock(-7,24,-6,rustic:iron_lattice:0,5,quark:iron_plate:1,15,STAINED_CLAY:15,15,STAINED_CLAY:7,100)
RandomBlock(-7,25,-7,rustic:iron_lattice:0,5,quark:iron_plate:1,15,STAINED_CLAY:15,15,STAINED_CLAY:7,100)
RandomBlock(-7,25,-6,rustic:iron_lattice:0,5,quark:iron_plate:1,15,STAINED_CLAY:15,15,STAINED_CLAY:7,100)
RandomBlock(-7,26,-7,rustic:iron_lattice:0,5,quark:iron_plate:1,15,STAINED_CLAY:15,15,STAINED_CLAY:7,100)
RandomBlock(-7,26,-6,rustic:iron_lattice:0,5,quark:iron_plate:1,15,STAINED_CLAY:15,15,STAINED_CLAY:7,100)
RandomBlock(-7,27,-7,rustic:iron_lattice:0,5,quark:iron_plate:1,15,STAINED_CLAY:15,15,STAINED_CLAY:7,100)
RandomBlock(-7,27,-6,rustic:iron_lattice:0,5,quark:iron_plate:1,15,STAINED_CLAY:15,15,STAINED_CLAY:7,100)
RandomBlock(-7,28,-7,rustic:iron_lattice:0,5,quark:iron_plate:1,15,STAINED_CLAY:15,15,STAINED_CLAY:7,100)
RandomBlock(-7,28,-6,rustic:iron_lattice:0,5,quark:iron_plate:1,15,STAINED_CLAY:15,15,STAINED_CLAY:7,100)
RandomBlock(-7,29,-7,rustic:iron_lattice:0,5,quark:iron_plate:1,15,STAINED_CLAY:15,15,STAINED_CLAY:7,100)
RandomBlock(-7,29,-6,rustic:iron_lattice:0,5,quark:iron_plate:1,15,STAINED_CLAY:15,15,STAINED_CLAY:7,100)
RandomBlock(-7,30,-7,rustic:iron_lattice:0,5,quark:iron_plate:1,15,STAINED_CLAY:15,15,STAINED_CLAY:7,100)
RandomBlock(-7,30,-6,rustic:iron_lattice:0,5,quark:iron_plate:1,15,STAINED_CLAY:15,15,STAINED_CLAY:7,100)
RandomBlock(-7,31,-7,rustic:iron_lattice:0,5,quark:iron_plate:1,15,STAINED_CLAY:15,15,STAINED_CLAY:7,100)
RandomBlock(-7,31,-6,rustic:iron_lattice:0,5,quark:iron_plate:1,15,STAINED_CLAY:15,15,STAINED_CLAY:7,100)
RandomBlock(-7,32,-7,rustic:iron_lattice:0,5,quark:iron_plate:1,15,STAINED_CLAY:15,15,STAINED_CLAY:7,100)
RandomBlock(-7,32,-6,rustic:iron_lattice:0,5,quark:iron_plate:1,15,STAINED_CLAY:15,15,STAINED_CLAY:7,100)
RandomBlock(-7,33,-7,rustic:iron_lattice:0,5,quark:iron_plate:1,15,STAINED_CLAY:15,15,STAINED_CLAY:7,100)
RandomBlock(-7,33,-6,rustic:iron_lattice:0,5,quark:iron_plate:1,15,STAINED_CLAY:15,15,STAINED_CLAY:7,100)
RandomBlock(-7,34,-7,rustic:iron_lattice:0,5,quark:iron_plate:1,15,STAINED_CLAY:15,15,STAINED_CLAY:7,100)
RandomBlock(-7,34,-6,rustic:iron_lattice:0,5,quark:iron_plate:1,15,STAINED_CLAY:15,15,STAINED_CLAY:7,100)
RandomBlock(-7,35,-7,rustic:iron_lattice:0,5,quark:iron_plate:1,15,STAINED_CLAY:15,15,STAINED_CLAY:7,100)
RandomBlock(-7,35,-6,rustic:iron_lattice:0,5,quark:iron_plate:1,15,STAINED_CLAY:15,15,STAINED_CLAY:7,100)
RandomBlock(-7,36,-7,rustic:iron_lattice:0,5,quark:iron_plate:1,15,STAINED_CLAY:15,15,STAINED_CLAY:7,100)
RandomBlock(-7,36,-6,rustic:iron_lattice:0,5,quark:iron_plate:1,15,STAINED_CLAY:15,15,STAINED_CLAY:7,100)
RandomBlock(-7,37,-7,rustic:iron_lattice:0,5,quark:iron_plate:1,15,STAINED_CLAY:15,15,STAINED_CLAY:7,100)
RandomBlock(-7,37,-6,rustic:iron_lattice:0,5,quark:iron_plate:1,15,STAINED_CLAY:15,15,STAINED_CLAY:7,100)
RandomBlock(-7,38,-7,rustic:iron_lattice:0,5,quark:iron_plate:1,15,STAINED_CLAY:15,15,STAINED_CLAY:7,100)
RandomBlock(-7,38,-6,rustic:iron_lattice:0,5,quark:iron_plate:1,15,STAINED_CLAY:15,15,STAINED_CLAY:7,100)
RandomBlock(-7,39,-7,rustic:iron_lattice:0,5,quark:iron_plate:1,15,STAINED_CLAY:15,15,STAINED_CLAY:7,100)
RandomBlock(-7,39,-6,rustic:iron_lattice:0,5,quark:iron_plate:1,15,STAINED_CLAY:15,15,STAINED_CLAY:7,100)
RandomBlock(-7,40,-7,rustic:iron_lattice:0,5,quark:iron_plate:1,15,STAINED_CLAY:15,15,STAINED_CLAY:7,100)
RandomBlock(-7,40,-6,rustic:iron_lattice:0,5,quark:iron_plate:1,15,STAINED_CLAY:15,15,STAINED_CLAY:7,100)
RandomBlock(-7,41,-7,rustic:iron_lattice:0,5,quark:iron_plate:1,15,STAINED_CLAY:15,15,STAINED_CLAY:7,100)
RandomBlock(-7,41,-6,rustic:iron_lattice:0,5,quark:iron_plate:1,15,STAINED_CLAY:15,15,STAINED_CLAY:7,100)
RandomBlock(-7,42,-7,rustic:iron_lattice:0,5,quark:iron_plate:1,15,STAINED_CLAY:15,15,STAINED_CLAY:7,100)
RandomBlock(-7,42,-6,rustic:iron_lattice:0,5,quark:iron_plate:1,15,STAINED_CLAY:15,15,STAINED_CLAY:7,100)
RandomBlock(-7,43,-7,rustic:iron_lattice:0,5,quark:iron_plate:1,15,STAINED_CLAY:15,15,STAINED_CLAY:7,100)
RandomBlock(-7,43,-6,rustic:iron_lattice:0,5,quark:iron_plate:1,15,STAINED_CLAY:15,15,STAINED_CLAY:7,100)
RandomBlock(-7,44,-7,rustic:iron_lattice:0,5,STAINED_CLAY:15,5,STAINED_CLAY:7,5,quark:iron_plate_slab:8,15,quark:world_stone_pavement:2,15,STAINED_CLAY:9,100)
RandomBlock(-7,44,-6,rustic:iron_lattice:0,5,STAINED_CLAY:15,5,STAINED_CLAY:7,5,quark:iron_plate_slab:8,15,quark:world_stone_pavement:2,15,STAINED_CLAY:9,100)
RandomBlock(-7,44,-5,rustic:iron_lattice:0,5,STAINED_CLAY:15,5,STAINED_CLAY:7,5,quark:iron_plate_slab:8,15,quark:world_stone_pavement:2,15,STAINED_CLAY:9,100)
RandomBlock(-7,44,-4,rustic:iron_lattice:0,5,STAINED_CLAY:15,5,STAINED_CLAY:7,5,quark:iron_plate_slab:8,15,quark:world_stone_pavement:2,15,STAINED_CLAY:9,100)
RandomBlock(-7,44,-3,rustic:iron_lattice:0,5,STAINED_CLAY:15,5,STAINED_CLAY:7,5,quark:iron_plate_slab:8,15,quark:world_stone_pavement:2,15,STAINED_CLAY:9,100)
RandomBlock(-7,44,-2,rustic:iron_lattice:0,5,STAINED_CLAY:15,5,STAINED_CLAY:7,5,quark:iron_plate_slab:8,15,quark:world_stone_pavement:2,15,STAINED_CLAY:9,100)
RandomBlock(-7,44,-1,rustic:iron_lattice:0,5,STAINED_CLAY:15,5,STAINED_CLAY:7,5,quark:iron_plate_slab:8,15,quark:world_stone_pavement:2,15,STAINED_CLAY:9,100)
Block(-7,45,-2,rustic:iron_lattice:0)
Block(-7,45,-1,rustic:iron_lattice:0)
Block(-7,46,-2,rustic:iron_lattice:0)
Block(-7,46,-1,rustic:iron_lattice:0)
RandomBlock(-7,50,-7,rustic:iron_lattice:0,5,STAINED_CLAY:15,5,STAINED_CLAY:7,5,quark:iron_plate_slab:8,15,quark:world_stone_pavement:2,15,STAINED_CLAY:9,100)
RandomBlock(-7,50,-6,rustic:iron_lattice:0,5,STAINED_CLAY:15,5,STAINED_CLAY:7,5,quark:iron_plate_slab:8,15,quark:world_stone_pavement:2,15,STAINED_CLAY:9,100)
RandomBlock(-7,50,-5,rustic:iron_lattice:0,5,STAINED_CLAY:15,5,STAINED_CLAY:7,5,quark:iron_plate_slab:8,15,quark:world_stone_pavement:2,15,STAINED_CLAY:9,100)
RandomBlock(-7,50,-4,rustic:iron_lattice:0,5,STAINED_CLAY:15,5,STAINED_CLAY:7,5,quark:iron_plate_slab:8,15,quark:world_stone_pavement:2,15,STAINED_CLAY:9,100)
RandomBlock(-7,50,-3,rustic:iron_lattice:0,5,STAINED_CLAY:15,5,STAINED_CLAY:7,5,quark:iron_plate_slab:8,15,quark:world_stone_pavement:2,15,STAINED_CLAY:9,100)
RandomBlock(-7,50,-2,rustic:iron_lattice:0,5,CONCRETE_POWDER:8,10,quark:limestone:1,15,quark:limestone,15,quark:world_stone_pavement:2,15,CONCRETE:8,100)
Block(-7,51,-2,rustic:iron_lattice:0)
Block(-7,52,-2,rustic:iron_lattice:0)
Block(-7,65,-7,STEP:13)
Block(-7,65,-6,rustic:iron_lattice:0)
RandomBlock(-7,66,-7,CONCRETE_POWDER:7,25,CONCRETE:7,100)
Block(-7,66,-6,IRON_FENCE:0)
Block(-7,67,-7,STEP:5)
Block(-7,68,-7,rustic:iron_lattice:0)
RandomBlock(-6,0,-7,rustic:iron_lattice:0,5,quark:iron_plate:1,15,STAINED_CLAY:15,15,STAINED_CLAY:7,100)
RandomBlock(-6,1,-7,rustic:iron_lattice:0,5,quark:iron_plate:1,15,STAINED_CLAY:15,15,STAINED_CLAY:7,100)
RandomBlock(-6,2,-7,rustic:iron_lattice:0,5,quark:iron_plate:1,15,STAINED_CLAY:15,15,STAINED_CLAY:7,100)
RandomBlock(-6,3,-7,rustic:iron_lattice:0,5,quark:iron_plate:1,15,STAINED_CLAY:15,15,STAINED_CLAY:7,100)
RandomBlock(-6,4,-7,rustic:iron_lattice:0,5,quark:iron_plate:1,15,STAINED_CLAY:15,15,STAINED_CLAY:7,100)
RandomBlock(-6,5,-7,rustic:iron_lattice:0,5,quark:iron_plate:1,15,STAINED_CLAY:15,15,STAINED_CLAY:7,100)
RandomBlock(-6,6,-7,rustic:iron_lattice:0,5,quark:iron_plate:1,15,STAINED_CLAY:15,15,STAINED_CLAY:7,100)
RandomBlock(-6,7,-7,rustic:iron_lattice:0,5,quark:iron_plate:1,15,STAINED_CLAY:15,15,STAINED_CLAY:7,100)
RandomBlock(-6,8,-7,rustic:iron_lattice:0,5,quark:iron_plate:1,15,STAINED_CLAY:15,15,STAINED_CLAY:7,100)
RandomBlock(-6,9,-7,rustic:iron_lattice:0,5,quark:iron_plate:1,15,STAINED_CLAY:15,15,STAINED_CLAY:7,100)
RandomBlock(-6,10,-7,rustic:iron_lattice:0,5,quark:iron_plate:1,15,STAINED_CLAY:15,15,STAINED_CLAY:7,100)
RandomBlock(-6,11,-7,rustic:iron_lattice:0,5,quark:iron_plate:1,15,STAINED_CLAY:15,15,STAINED_CLAY:7,100)
RandomBlock(-6,12,-7,rustic:iron_lattice:0,5,quark:iron_plate:1,15,STAINED_CLAY:15,15,STAINED_CLAY:7,100)
RandomBlock(-6,13,-7,rustic:iron_lattice:0,5,quark:iron_plate:1,15,STAINED_CLAY:15,15,STAINED_CLAY:7,100)
RandomBlock(-6,14,-7,rustic:iron_lattice:0,5,quark:iron_plate:1,15,STAINED_CLAY:15,15,STAINED_CLAY:7,100)
RandomBlock(-6,15,-7,rustic:iron_lattice:0,5,quark:iron_plate:1,15,STAINED_CLAY:15,15,STAINED_CLAY:7,100)
RandomBlock(-6,16,-7,rustic:iron_lattice:0,5,quark:iron_plate:1,15,STAINED_CLAY:15,15,STAINED_CLAY:7,100)
RandomBlock(-6,17,-7,rustic:iron_lattice:0,5,quark:iron_plate:1,15,STAINED_CLAY:15,15,STAINED_CLAY:7,100)
RandomBlock(-6,18,-7,rustic:iron_lattice:0,5,quark:iron_plate:1,15,STAINED_CLAY:15,15,STAINED_CLAY:7,100)
RandomBlock(-6,19,-7,rustic:iron_lattice:0,5,quark:iron_plate:1,15,STAINED_CLAY:15,15,STAINED_CLAY:7,100)
RandomBlock(-6,20,-7,rustic:iron_lattice:0,5,quark:iron_plate:1,15,STAINED_CLAY:15,15,STAINED_CLAY:7,100)
RandomBlock(-6,21,-7,rustic:iron_lattice:0,5,quark:iron_plate:1,15,STAINED_CLAY:15,15,STAINED_CLAY:7,100)
RandomBlock(-6,22,-7,rustic:iron_lattice:0,5,quark:iron_plate:1,15,STAINED_CLAY:15,15,STAINED_CLAY:7,100)
RandomBlock(-6,23,-7,rustic:iron_lattice:0,5,quark:iron_plate:1,15,STAINED_CLAY:15,15,STAINED_CLAY:7,100)
RandomBlock(-6,24,-7,rustic:iron_lattice:0,5,quark:iron_plate:1,15,STAINED_CLAY:15,15,STAINED_CLAY:7,100)
RandomBlock(-6,25,-7,rustic:iron_lattice:0,5,quark:iron_plate:1,15,STAINED_CLAY:15,15,STAINED_CLAY:7,100)
RandomBlock(-6,26,-7,rustic:iron_lattice:0,5,quark:iron_plate:1,15,STAINED_CLAY:15,15,STAINED_CLAY:7,100)
RandomBlock(-6,27,-7,rustic:iron_lattice:0,5,quark:iron_plate:1,15,STAINED_CLAY:15,15,STAINED_CLAY:7,100)
RandomBlock(-6,28,-7,rustic:iron_lattice:0,5,quark:iron_plate:1,15,STAINED_CLAY:15,15,STAINED_CLAY:7,100)
RandomBlock(-6,29,-7,rustic:iron_lattice:0,5,quark:iron_plate:1,15,STAINED_CLAY:15,15,STAINED_CLAY:7,100)
RandomBlock(-6,30,-7,rustic:iron_lattice:0,5,quark:iron_plate:1,15,STAINED_CLAY:15,15,STAINED_CLAY:7,100)
RandomBlock(-6,31,-7,rustic:iron_lattice:0,5,quark:iron_plate:1,15,STAINED_CLAY:15,15,STAINED_CLAY:7,100)
RandomBlock(-6,32,-7,rustic:iron_lattice:0,5,quark:iron_plate:1,15,STAINED_CLAY:15,15,STAINED_CLAY:7,100)
RandomBlock(-6,33,-7,rustic:iron_lattice:0,5,quark:iron_plate:1,15,STAINED_CLAY:15,15,STAINED_CLAY:7,100)
RandomBlock(-6,34,-7,rustic:iron_lattice:0,5,quark:iron_plate:1,15,STAINED_CLAY:15,15,STAINED_CLAY:7,100)
RandomBlock(-6,35,-7,rustic:iron_lattice:0,5,quark:iron_plate:1,15,STAINED_CLAY:15,15,STAINED_CLAY:7,100)
RandomBlock(-6,36,-7,rustic:iron_lattice:0,5,quark:iron_plate:1,15,STAINED_CLAY:15,15,STAINED_CLAY:7,100)
RandomBlock(-6,37,-7,rustic:iron_lattice:0,5,quark:iron_plate:1,15,STAINED_CLAY:15,15,STAINED_CLAY:7,100)
RandomBlock(-6,38,-7,rustic:iron_lattice:0,5,quark:iron_plate:1,15,STAINED_CLAY:15,15,STAINED_CLAY:7,100)
RandomBlock(-6,39,-7,rustic:iron_lattice:0,5,quark:iron_plate:1,15,STAINED_CLAY:15,15,STAINED_CLAY:7,100)
RandomBlock(-6,40,-7,rustic:iron_lattice:0,5,quark:iron_plate:1,15,STAINED_CLAY:15,15,STAINED_CLAY:7,100)
RandomBlock(-6,41,-7,rustic:iron_lattice:0,5,quark:iron_plate:1,15,STAINED_CLAY:15,15,STAINED_CLAY:7,100)
RandomBlock(-6,42,-7,rustic:iron_lattice:0,5,quark:iron_plate:1,15,STAINED_CLAY:15,15,STAINED_CLAY:7,100)
RandomBlock(-6,43,-7,rustic:iron_lattice:0,5,quark:iron_plate:1,15,STAINED_CLAY:15,15,STAINED_CLAY:7,100)
RandomBlock(-6,44,-7,rustic:iron_lattice:0,5,STAINED_CLAY:15,5,STAINED_CLAY:7,5,quark:iron_plate_slab:8,15,quark:world_stone_pavement:2,15,STAINED_CLAY:9,100)
RandomBlock(-6,44,-6,rustic:iron_lattice:0,5,STAINED_CLAY:15,5,STAINED_CLAY:7,5,quark:iron_plate_slab:8,15,quark:world_stone_pavement:2,15,STAINED_CLAY:9,100)
RandomBlock(-6,44,-5,rustic:iron_lattice:0,5,STAINED_CLAY:15,5,STAINED_CLAY:7,5,quark:iron_plate_slab:8,15,quark:world_stone_pavement:2,15,STAINED_CLAY:9,100)
RandomBlock(-6,44,-4,rustic:iron_lattice:0,5,STAINED_CLAY:15,5,STAINED_CLAY:7,5,quark:iron_plate_slab:8,15,quark:world_stone_pavement:2,15,STAINED_CLAY:9,100)
RandomBlock(-6,44,-3,rustic:iron_lattice:0,5,STAINED_CLAY:15,5,STAINED_CLAY:7,5,quark:iron_plate_slab:8,15,quark:world_stone_pavement:2,15,STAINED_CLAY:9,100)
RandomBlock(-6,44,-2,rustic:iron_lattice:0,5,STAINED_CLAY:15,5,STAINED_CLAY:7,5,quark:iron_plate_slab:8,15,quark:world_stone_pavement:2,15,STAINED_CLAY:9,100)
Block(-6,45,-2,rustic:iron_lattice:0)
Block(-6,46,-2,rustic:iron_lattice:0)
RandomBlock(-6,50,-7,rustic:iron_lattice:0,5,STAINED_CLAY:15,5,STAINED_CLAY:7,5,quark:iron_plate_slab:8,15,quark:world_stone_pavement:2,15,STAINED_CLAY:9,100)
RandomBlock(-6,50,-6,rustic:iron_lattice:0,5,STAINED_CLAY:15,5,STAINED_CLAY:7,5,quark:iron_plate_slab:8,15,quark:world_stone_pavement:2,15,STAINED_CLAY:9,100)
RandomBlock(-6,50,-5,rustic:iron_lattice:0,5,STAINED_CLAY:15,5,STAINED_CLAY:7,5,quark:iron_plate_slab:8,15,quark:world_stone_pavement:2,15,STAINED_CLAY:9,100)
RandomBlock(-6,50,-4,rustic:iron_lattice:0,5,STAINED_CLAY:15,5,STAINED_CLAY:7,5,quark:iron_plate_slab:8,15,quark:world_stone_pavement:2,15,STAINED_CLAY:9,100)
RandomBlock(-6,50,-3,rustic:iron_lattice:0,5,STAINED_CLAY:15,5,STAINED_CLAY:7,5,quark:iron_plate_slab:8,15,quark:world_stone_pavement:2,15,STAINED_CLAY:9,100)
RandomBlock(-6,50,-2,rustic:iron_lattice:0,5,CONCRETE_POWDER:8,10,quark:limestone:1,15,quark:limestone,15,quark:world_stone_pavement:2,15,CONCRETE:8,100)
Block(-6,51,-2,rustic:iron_lattice:0)
Block(-6,52,-2,rustic:iron_lattice:0)
Block(-6,65,-7,STEP:13)
Block(-6,65,-6,rustic:iron_lattice:0)
RandomBlock(-6,66,-7,CONCRETE_POWDER:7,25,CONCRETE:7,100)
Block(-6,66,-6,IRON_FENCE:0)
Block(-6,67,-7,STEP:5)
Block(-6,68,-7,rustic:iron_lattice:0)
Block(-5,43,-7,quark:iron_plate:1)
RandomBlock(-5,44,-7,rustic:iron_lattice:0,5,STAINED_CLAY:15,5,STAINED_CLAY:7,5,quark:iron_plate_slab:8,15,quark:world_stone_pavement:2,15,STAINED_CLAY:9,100)
RandomBlock(-5,44,-6,rustic:iron_lattice:0,5,STAINED_CLAY:15,5,STAINED_CLAY:7,5,quark:iron_plate_slab:8,15,quark:world_stone_pavement:2,15,STAINED_CLAY:9,100)
RandomBlock(-5,44,-5,rustic:iron_lattice:0,5,STAINED_CLAY:15,5,STAINED_CLAY:7,5,quark:iron_plate_slab:8,15,quark:world_stone_pavement:2,15,STAINED_CLAY:9,100)
RandomBlock(-5,44,-4,rustic:iron_lattice:0,5,STAINED_CLAY:15,5,STAINED_CLAY:7,5,quark:iron_plate_slab:8,15,quark:world_stone_pavement:2,15,STAINED_CLAY:9,100)
RandomBlock(-5,44,-3,rustic:iron_lattice:0,5,STAINED_CLAY:15,5,STAINED_CLAY:7,5,quark:iron_plate_slab:8,15,quark:world_stone_pavement:2,15,STAINED_CLAY:9,100)
RandomBlock(-5,44,-2,rustic:iron_lattice:0,5,STAINED_CLAY:15,5,STAINED_CLAY:7,5,quark:iron_plate_slab:8,15,quark:world_stone_pavement:2,15,STAINED_CLAY:9,100)
Block(-5,45,-2,rustic:iron_lattice:0)
Block(-5,46,-2,rustic:iron_lattice:0)
RandomBlock(-5,50,-7,rustic:iron_lattice:0,5,STAINED_CLAY:15,5,STAINED_CLAY:7,5,quark:iron_plate_slab:8,15,quark:world_stone_pavement:2,15,STAINED_CLAY:9,100)
RandomBlock(-5,50,-6,rustic:iron_lattice:0,5,STAINED_CLAY:15,5,STAINED_CLAY:7,5,quark:iron_plate_slab:8,15,quark:world_stone_pavement:2,15,STAINED_CLAY:9,100)
RandomBlock(-5,50,-5,rustic:iron_lattice:0,5,STAINED_CLAY:15,5,STAINED_CLAY:7,5,quark:iron_plate_slab:8,15,quark:world_stone_pavement:2,15,STAINED_CLAY:9,100)
RandomBlock(-5,50,-4,rustic:iron_lattice:0,5,STAINED_CLAY:15,5,STAINED_CLAY:7,5,quark:iron_plate_slab:8,15,quark:world_stone_pavement:2,15,STAINED_CLAY:9,100)
RandomBlock(-5,50,-3,rustic:iron_lattice:0,5,STAINED_CLAY:15,5,STAINED_CLAY:7,5,quark:iron_plate_slab:8,15,quark:world_stone_pavement:2,15,STAINED_CLAY:9,100)
RandomBlock(-5,50,-2,rustic:iron_lattice:0,5,CONCRETE_POWDER:8,10,quark:limestone:1,15,quark:limestone,15,quark:world_stone_pavement:2,15,CONCRETE:8,100)
Block(-5,51,-2,rustic:iron_lattice:0)
Block(-5,52,-2,rustic:iron_lattice:0)
Block(-5,65,-7,STEP:13)
Block(-5,65,-6,rustic:iron_lattice:0)
RandomBlock(-5,66,-7,CONCRETE_POWDER:7,25,CONCRETE:7,100)
Block(-5,66,-6,IRON_FENCE:0)
Block(-5,67,-7,STEP:5)
Block(-5,68,-7,rustic:iron_lattice:0)
Block(-4,43,-7,quark:iron_plate:1)
RandomBlock(-4,44,-7,rustic:iron_lattice:0,5,STAINED_CLAY:15,5,STAINED_CLAY:7,5,quark:iron_plate_slab:8,15,quark:world_stone_pavement:2,15,STAINED_CLAY:9,100)
RandomBlock(-4,44,-6,rustic:iron_lattice:0,5,STAINED_CLAY:15,5,STAINED_CLAY:7,5,quark:iron_plate_slab:8,15,quark:world_stone_pavement:2,15,STAINED_CLAY:9,100)
RandomBlock(-4,44,-5,rustic:iron_lattice:0,5,STAINED_CLAY:15,5,STAINED_CLAY:7,5,quark:iron_plate_slab:8,15,quark:world_stone_pavement:2,15,STAINED_CLAY:9,100)
RandomBlock(-4,44,-4,rustic:iron_lattice:0,5,STAINED_CLAY:15,5,STAINED_CLAY:7,5,quark:iron_plate_slab:8,15,quark:world_stone_pavement:2,15,STAINED_CLAY:9,100)
RandomBlock(-4,44,-3,rustic:iron_lattice:0,5,STAINED_CLAY:15,5,STAINED_CLAY:7,5,quark:iron_plate_slab:8,15,quark:world_stone_pavement:2,15,STAINED_CLAY:9,100)
RandomBlock(-4,44,-2,rustic:iron_lattice:0,5,STAINED_CLAY:15,5,STAINED_CLAY:7,5,quark:iron_plate_slab:8,15,quark:world_stone_pavement:2,15,STAINED_CLAY:9,100)
Block(-4,45,-2,rustic:iron_lattice:0)
Block(-4,46,-2,rustic:iron_lattice:0)
RandomBlock(-4,50,-7,rustic:iron_lattice:0,5,STAINED_CLAY:15,5,STAINED_CLAY:7,5,quark:iron_plate_slab:8,15,quark:world_stone_pavement:2,15,STAINED_CLAY:9,100)
RandomBlock(-4,50,-6,rustic:iron_lattice:0,5,STAINED_CLAY:15,5,STAINED_CLAY:7,5,quark:iron_plate_slab:8,15,quark:world_stone_pavement:2,15,STAINED_CLAY:9,100)
RandomBlock(-4,50,-5,rustic:iron_lattice:0,5,STAINED_CLAY:15,5,STAINED_CLAY:7,5,quark:iron_plate_slab:8,15,quark:world_stone_pavement:2,15,STAINED_CLAY:9,100)
RandomBlock(-4,50,-4,rustic:iron_lattice:0,5,STAINED_CLAY:15,5,STAINED_CLAY:7,5,quark:iron_plate_slab:8,15,quark:world_stone_pavement:2,15,STAINED_CLAY:9,100)
RandomBlock(-4,50,-3,rustic:iron_lattice:0,5,STAINED_CLAY:15,5,STAINED_CLAY:7,5,quark:iron_plate_slab:8,15,quark:world_stone_pavement:2,15,STAINED_CLAY:9,100)
RandomBlock(-4,50,-2,rustic:iron_lattice:0,5,CONCRETE_POWDER:8,10,quark:limestone:1,15,quark:limestone,15,quark:world_stone_pavement:2,15,CONCRETE:8,100)
Block(-4,51,-2,rustic:iron_lattice:0)
Block(-4,52,-2,rustic:iron_lattice:0)
Block(-4,65,-7,STEP:13)
Block(-4,65,-6,rustic:iron_lattice:0)
RandomBlock(-4,66,-7,CONCRETE_POWDER:7,25,CONCRETE:7,100)
Block(-4,66,-6,IRON_FENCE:0)
Block(-4,67,-7,STEP:5)
Block(-4,68,-7,rustic:iron_lattice:0)
Block(-3,43,-7,quark:iron_plate:1)
RandomBlock(-3,44,-7,rustic:iron_lattice:0,5,STAINED_CLAY:15,5,STAINED_CLAY:7,5,quark:iron_plate_slab:8,15,quark:world_stone_pavement:2,15,STAINED_CLAY:9,100)
RandomBlock(-3,44,-6,rustic:iron_lattice:0,5,STAINED_CLAY:15,5,STAINED_CLAY:7,5,quark:iron_plate_slab:8,15,quark:world_stone_pavement:2,15,STAINED_CLAY:9,100)
RandomBlock(-3,44,-5,rustic:iron_lattice:0,5,STAINED_CLAY:15,5,STAINED_CLAY:7,5,quark:iron_plate_slab:8,15,quark:world_stone_pavement:2,15,STAINED_CLAY:9,100)
RandomBlock(-3,44,-4,rustic:iron_lattice:0,5,STAINED_CLAY:15,5,STAINED_CLAY:7,5,quark:iron_plate_slab:8,15,quark:world_stone_pavement:2,15,STAINED_CLAY:9,100)
RandomBlock(-3,44,-3,rustic:iron_lattice:0,5,STAINED_CLAY:15,5,STAINED_CLAY:7,5,quark:iron_plate_slab:8,15,quark:world_stone_pavement:2,15,STAINED_CLAY:9,100)
RandomBlock(-3,44,-2,rustic:iron_lattice:0,5,STAINED_CLAY:15,5,STAINED_CLAY:7,5,quark:iron_plate_slab:8,15,quark:world_stone_pavement:2,15,STAINED_CLAY:9,100)
Block(-3,45,-6,rustic:iron_lattice:0)
Block(-3,45,-2,rustic:iron_lattice:0)
Block(-3,46,-6,rustic:iron_lattice:0)
Block(-3,46,-2,rustic:iron_lattice:0)
Block(-3,47,-6,rustic:iron_lattice:0)
Block(-3,47,-2,rustic:iron_lattice:0)
Block(-3,48,-6,rustic:iron_lattice:0)
Block(-3,48,-2,rustic:iron_lattice:0)
Block(-3,49,-6,rustic:iron_lattice:0)
Block(-3,49,-2,rustic:iron_lattice:0)
RandomBlock(-3,50,-7,rustic:iron_lattice:0,5,CONCRETE_POWDER:8,10,quark:limestone:1,15,quark:limestone,15,quark:world_stone_pavement:2,15,CONCRETE:8,100)
RandomBlock(-3,50,-6,rustic:iron_lattice:0,5,CONCRETE_POWDER:8,10,quark:limestone:1,15,quark:limestone,15,quark:world_stone_pavement:2,15,CONCRETE:8,100)
RandomBlock(-3,50,-5,rustic:iron_lattice:0,5,CONCRETE_POWDER:8,10,quark:limestone:1,15,quark:limestone,15,quark:world_stone_pavement:2,15,CONCRETE:8,100)
RandomBlock(-3,50,-4,rustic:iron_lattice:0,5,CONCRETE_POWDER:8,10,quark:limestone:1,15,quark:limestone,15,quark:world_stone_pavement:2,15,CONCRETE:8,100)
RandomBlock(-3,50,-3,rustic:iron_lattice:0,5,CONCRETE_POWDER:8,10,quark:limestone:1,15,quark:limestone,15,quark:world_stone_pavement:2,15,CONCRETE:8,100)
RandomBlock(-3,50,-2,rustic:iron_lattice:0,5,CONCRETE_POWDER:8,10,quark:limestone:1,15,quark:limestone,15,quark:world_stone_pavement:2,15,CONCRETE:8,100)
Block(-3,51,-6,rustic:iron_lattice:0)
Block(-3,51,-5,rustic:iron_lattice:0)
Block(-3,51,-4,rustic:iron_lattice:0)
Block(-3,51,-3,rustic:iron_lattice:0)
Block(-3,51,-2,rustic:iron_lattice:0)
Block(-3,52,-6,rustic:iron_lattice:0)
Block(-3,52,-5,rustic:iron_lattice:0)
Block(-3,52,-4,rustic:iron_lattice:0)
Block(-3,52,-3,rustic:iron_lattice:0)
Block(-3,52,-2,rustic:iron_lattice:0)
Block(-3,65,-7,STEP:13)
Block(-3,65,-6,rustic:iron_lattice:0)
RandomBlock(-3,66,-7,CONCRETE_POWDER:7,25,CONCRETE:7,100)
Block(-3,66,-6,IRON_FENCE:0)
Block(-3,67,-7,STEP:5)
Block(-3,68,-7,rustic:iron_lattice:0)
Block(-2,43,-7,quark:iron_plate:1)
RandomBlock(-2,44,-7,rustic:iron_lattice:0,5,STAINED_CLAY:15,5,STAINED_CLAY:7,5,quark:iron_plate_slab:8,15,quark:world_stone_pavement:2,15,STAINED_CLAY:9,100)
RandomBlock(-2,44,-6,rustic:iron_lattice:0,5,STAINED_CLAY:15,5,STAINED_CLAY:7,5,quark:iron_plate_slab:8,15,quark:world_stone_pavement:2,15,STAINED_CLAY:9,100)
RandomBlock(-2,44,-5,rustic:iron_lattice:0,5,STAINED_CLAY:15,5,STAINED_CLAY:7,5,quark:iron_plate_slab:8,15,quark:world_stone_pavement:2,15,STAINED_CLAY:9,100)
RandomBlock(-2,44,-4,rustic:iron_lattice:0,5,STAINED_CLAY:15,5,STAINED_CLAY:7,5,quark:iron_plate_slab:8,15,quark:world_stone_pavement:2,15,STAINED_CLAY:9,100)
RandomBlock(-2,44,-3,rustic:iron_lattice:0,5,STAINED_CLAY:15,5,STAINED_CLAY:7,5,quark:iron_plate_slab:8,15,quark:world_stone_pavement:2,15,STAINED_CLAY:9,100)
RandomBlock(-2,44,-2,rustic:iron_lattice:0,5,STAINED_CLAY:15,5,STAINED_CLAY:7,5,quark:iron_plate_slab:8,15,quark:world_stone_pavement:2,15,STAINED_CLAY:9,100)
Block(-2,45,-2,rustic:iron_lattice:0)
Block(-2,46,-2,rustic:iron_lattice:0)
Block(-2,65,-7,STEP:13)
Block(-2,65,-6,rustic:iron_lattice:0)
RandomBlock(-2,66,-7,CONCRETE_POWDER:7,25,CONCRETE:7,100)
Block(-2,66,-6,IRON_FENCE:0)
Block(-2,67,-7,STEP:5)
Block(-2,68,-7,rustic:iron_lattice:0)
Block(-1,43,-7,quark:iron_plate:1)
RandomBlock(-1,44,-7,rustic:iron_lattice:0,5,STAINED_CLAY:15,5,STAINED_CLAY:7,5,quark:iron_plate_slab:8,15,quark:world_stone_pavement:2,15,STAINED_CLAY:9,100)
RandomBlock(-1,44,-6,rustic:iron_lattice:0,5,STAINED_CLAY:15,5,STAINED_CLAY:7,5,quark:iron_plate_slab:8,15,quark:world_stone_pavement:2,15,STAINED_CLAY:9,100)
RandomBlock(-1,44,-5,rustic:iron_lattice:0,5,STAINED_CLAY:15,5,STAINED_CLAY:7,5,quark:iron_plate_slab:8,15,quark:world_stone_pavement:2,15,STAINED_CLAY:9,100)
RandomBlock(-1,44,-4,rustic:iron_lattice:0,5,STAINED_CLAY:15,5,STAINED_CLAY:7,5,quark:iron_plate_slab:8,15,quark:world_stone_pavement:2,15,STAINED_CLAY:9,100)
RandomBlock(-1,44,-3,rustic:iron_lattice:0,5,STAINED_CLAY:15,5,STAINED_CLAY:7,5,quark:iron_plate_slab:8,15,quark:world_stone_pavement:2,15,STAINED_CLAY:9,100)
RandomBlock(-1,44,-2,rustic:iron_lattice:0,5,STAINED_CLAY:15,5,STAINED_CLAY:7,5,quark:iron_plate_slab:8,15,quark:world_stone_pavement:2,15,STAINED_CLAY:9,100)
Block(-1,45,-2,rustic:iron_lattice:0)
Block(-1,46,-2,rustic:iron_lattice:0)
Block(-1,65,-7,STEP:13)
Block(-1,65,-6,rustic:iron_lattice:0)
RandomBlock(-1,66,-7,CONCRETE_POWDER:7,25,CONCRETE:7,100)
Block(-1,66,-6,IRON_FENCE:0)
Block(-1,67,-7,STEP:5)
Block(-1,68,-7,rustic:iron_lattice:0)
Block(0,43,-7,quark:iron_plate:1)
RandomBlock(0,44,-7,rustic:iron_lattice:0,5,STAINED_CLAY:15,5,STAINED_CLAY:7,5,quark:iron_plate_slab:8,15,quark:world_stone_pavement:2,15,STAINED_CLAY:9,100)
RandomBlock(0,44,-6,rustic:iron_lattice:0,5,STAINED_CLAY:15,5,STAINED_CLAY:7,5,quark:iron_plate_slab:8,15,quark:world_stone_pavement:2,15,STAINED_CLAY:9,100)
RandomBlock(0,44,-5,rustic:iron_lattice:0,5,STAINED_CLAY:15,5,STAINED_CLAY:7,5,quark:iron_plate_slab:8,15,quark:world_stone_pavement:2,15,STAINED_CLAY:9,100)
RandomBlock(0,44,-4,rustic:iron_lattice:0,5,STAINED_CLAY:15,5,STAINED_CLAY:7,5,quark:iron_plate_slab:8,15,quark:world_stone_pavement:2,15,STAINED_CLAY:9,100)
RandomBlock(0,44,-3,rustic:iron_lattice:0,5,STAINED_CLAY:15,5,STAINED_CLAY:7,5,quark:iron_plate_slab:8,15,quark:world_stone_pavement:2,15,STAINED_CLAY:9,100)
RandomBlock(0,44,-2,rustic:iron_lattice:0,5,STAINED_CLAY:15,5,STAINED_CLAY:7,5,quark:iron_plate_slab:8,15,quark:world_stone_pavement:2,15,STAINED_CLAY:9,100)
Block(0,45,-2,rustic:iron_lattice:0)
Block(0,46,-2,rustic:iron_lattice:0)
Block(0,47,-5,quark:iron_plate:1)
Block(0,47,-4,quark:iron_plate:1)
Block(0,48,-5,quark:iron_plate:1)
Block(0,49,-5,quark:iron_plate:1)
Block(0,50,-5,quark:iron_plate:1)
Block(0,65,-7,STEP:13)
Block(0,65,-6,rustic:iron_lattice:0)
RandomBlock(0,66,-7,CONCRETE_POWDER:7,25,CONCRETE:7,100)
Block(0,66,-6,IRON_FENCE:0)
Block(0,67,-7,STEP:5)
Block(0,68,-7,rustic:iron_lattice:0)
Block(1,43,-7,quark:iron_plate:1)
RandomBlock(1,44,-7,rustic:iron_lattice:0,5,STAINED_CLAY:15,5,STAINED_CLAY:7,5,quark:iron_plate_slab:8,15,quark:world_stone_pavement:2,15,STAINED_CLAY:9,100)
RandomBlock(1,44,-6,rustic:iron_lattice:0,5,STAINED_CLAY:15,5,STAINED_CLAY:7,5,quark:iron_plate_slab:8,15,quark:world_stone_pavement:2,15,STAINED_CLAY:9,100)
RandomBlock(1,44,-5,rustic:iron_lattice:0,5,STAINED_CLAY:15,5,STAINED_CLAY:7,5,quark:iron_plate_slab:8,15,quark:world_stone_pavement:2,15,STAINED_CLAY:9,100)
RandomBlock(1,44,-4,rustic:iron_lattice:0,5,STAINED_CLAY:15,5,STAINED_CLAY:7,5,quark:iron_plate_slab:8,15,quark:world_stone_pavement:2,15,STAINED_CLAY:9,100)
RandomBlock(1,44,-3,rustic:iron_lattice:0,5,STAINED_CLAY:15,5,STAINED_CLAY:7,5,quark:iron_plate_slab:8,15,quark:world_stone_pavement:2,15,STAINED_CLAY:9,100)
RandomBlock(1,44,-2,rustic:iron_lattice:0,5,STAINED_CLAY:15,5,STAINED_CLAY:7,5,quark:iron_plate_slab:8,15,quark:world_stone_pavement:2,15,STAINED_CLAY:9,100)
RandomBlock(1,45,-7,rustic:iron_lattice:0,5,CONCRETE_POWDER:8,10,quark:limestone:1,15,quark:limestone,15,quark:world_stone_pavement:2,15,CONCRETE:8,100)
RandomBlock(1,45,-6,rustic:iron_lattice:0,5,CONCRETE_POWDER:8,10,quark:limestone:1,15,quark:limestone,15,quark:world_stone_pavement:2,15,CONCRETE:8,100)
RandomBlock(1,45,-5,rustic:iron_lattice:0,5,CONCRETE_POWDER:8,10,quark:limestone:1,15,quark:limestone,15,quark:world_stone_pavement:2,15,CONCRETE:8,100)
Block(1,45,-2,rustic:iron_lattice:0)
Block(1,46,-7,STAINED_GLASS_PANE:7)
Block(1,46,-6,CONCRETE:15)
Block(1,46,-5,CONCRETE:15)
Block(1,46,-2,rustic:iron_lattice:0)
RandomBlock(1,47,-7,rustic:iron_lattice:0,5,CONCRETE_POWDER:8,10,quark:limestone:1,15,quark:limestone,15,quark:world_stone_pavement:2,15,CONCRETE:8,100)
RandomBlock(1,47,-6,rustic:iron_lattice:0,5,CONCRETE_POWDER:8,10,quark:limestone:1,15,quark:limestone,15,quark:world_stone_pavement:2,15,CONCRETE:8,100)
RandomBlock(1,47,-5,rustic:iron_lattice:0,5,CONCRETE_POWDER:8,10,quark:limestone:1,15,quark:limestone,15,quark:world_stone_pavement:2,15,CONCRETE:8,100)
Block(1,47,-4,quark:iron_plate:1)
RandomBlock(1,48,-7,rustic:iron_lattice:0,5,CONCRETE_POWDER:8,10,quark:limestone:1,15,quark:limestone,15,quark:world_stone_pavement:2,15,CONCRETE:8,100)
RandomBlock(1,48,-6,rustic:iron_lattice:0,5,CONCRETE_POWDER:8,10,quark:limestone:1,15,quark:limestone,15,quark:world_stone_pavement:2,15,CONCRETE:8,100)
RandomBlock(1,48,-5,rustic:iron_lattice:0,5,CONCRETE_POWDER:8,10,quark:limestone:1,15,quark:limestone,15,quark:world_stone_pavement:2,15,CONCRETE:8,100)
RandomBlock(1,48,-4,rustic:iron_lattice:0,5,CONCRETE_POWDER:8,10,quark:limestone:1,15,quark:limestone,15,quark:world_stone_pavement:2,15,CONCRETE:8,100)
RandomBlock(1,49,-7,rustic:iron_lattice:0,5,CONCRETE_POWDER:8,10,quark:limestone:1,15,quark:limestone,15,quark:world_stone_pavement:2,15,CONCRETE:8,100)
RandomBlock(1,49,-6,rustic:iron_lattice:0,5,CONCRETE_POWDER:8,10,quark:limestone:1,15,quark:limestone,15,quark:world_stone_pavement:2,15,CONCRETE:8,100)
RandomBlock(1,49,-5,rustic:iron_lattice:0,5,CONCRETE_POWDER:8,10,quark:limestone:1,15,quark:limestone,15,quark:world_stone_pavement:2,15,CONCRETE:8,100)
RandomBlock(1,49,-4,rustic:iron_lattice:0,5,CONCRETE_POWDER:8,10,quark:limestone:1,15,quark:limestone,15,quark:world_stone_pavement:2,15,CONCRETE:8,100)
RandomBlock(1,49,-3,rustic:iron_lattice:0,5,CONCRETE_POWDER:8,10,quark:limestone:1,15,quark:limestone,15,quark:world_stone_pavement:2,15,CONCRETE:8,100)
RandomBlock(1,50,-7,rustic:iron_lattice:0,5,STAINED_CLAY:15,5,STAINED_CLAY:7,5,quark:iron_plate_slab:8,15,quark:world_stone_pavement:2,15,STAINED_CLAY:9,100)
Block(1,50,-6,rustic:iron_lattice:0)
Block(1,50,-5,quark:iron_plate:1)
Block(1,50,-4,rustic:iron_lattice:0)
Block(1,50,-3,rustic:iron_lattice:0)
Block(1,51,-6,rustic:iron_lattice:0)
Block(1,51,-5,rustic:iron_lattice:0)
Block(1,51,-4,rustic:iron_lattice:0)
Block(1,51,-3,rustic:iron_lattice:0)
Block(1,65,-7,STEP:13)
Block(1,65,-6,rustic:iron_lattice:0)
RandomBlock(1,66,-7,CONCRETE_POWDER:7,25,CONCRETE:7,100)
Block(1,66,-6,IRON_FENCE:0)
Block(1,67,-7,STEP:5)
Block(1,68,-7,rustic:iron_lattice:0)
Block(2,43,-7,quark:iron_plate:1)
RandomBlock(2,44,-7,rustic:iron_lattice:0,5,STAINED_CLAY:15,5,STAINED_CLAY:7,5,quark:iron_plate_slab:8,15,quark:world_stone_pavement:2,15,STAINED_CLAY:9,100)
RandomBlock(2,44,-6,rustic:iron_lattice:0,5,STAINED_CLAY:15,5,STAINED_CLAY:7,5,quark:iron_plate_slab:8,15,quark:world_stone_pavement:2,15,STAINED_CLAY:9,100)
RandomBlock(2,44,-5,rustic:iron_lattice:0,5,STAINED_CLAY:15,5,STAINED_CLAY:7,5,quark:iron_plate_slab:8,15,quark:world_stone_pavement:2,15,STAINED_CLAY:9,100)
RandomBlock(2,44,-4,rustic:iron_lattice:0,5,STAINED_CLAY:15,5,STAINED_CLAY:7,5,quark:iron_plate_slab:8,15,quark:world_stone_pavement:2,15,STAINED_CLAY:9,100)
RandomBlock(2,44,-3,rustic:iron_lattice:0,5,STAINED_CLAY:15,5,STAINED_CLAY:7,5,quark:iron_plate_slab:8,15,quark:world_stone_pavement:2,15,STAINED_CLAY:9,100)
RandomBlock(2,44,-2,rustic:iron_lattice:0,5,STAINED_CLAY:15,5,STAINED_CLAY:7,5,quark:iron_plate_slab:8,15,quark:world_stone_pavement:2,15,STAINED_CLAY:9,100)
RandomBlock(2,45,-5,rustic:iron_lattice:0,5,CONCRETE_POWDER:8,10,quark:limestone:1,15,quark:limestone,15,quark:world_stone_pavement:2,15,CONCRETE:8,100)
Block(2,45,-2,rustic:iron_lattice:0)
Block(2,46,-7,STONE_BUTTON:2)
Block(2,46,-5,CONCRETE:15)
Block(2,46,-2,rustic:iron_lattice:0)
RandomBlock(2,47,-5,rustic:iron_lattice:0,5,CONCRETE_POWDER:8,10,quark:limestone:1,15,quark:limestone,15,quark:world_stone_pavement:2,15,CONCRETE:8,100)
Block(2,47,-4,quark:iron_plate:1)
Block(2,48,-5,REDSTONE_LAMP_OFF:0)
RandomBlock(2,48,-4,rustic:iron_lattice:0,5,CONCRETE_POWDER:8,10,quark:limestone:1,15,quark:limestone,15,quark:world_stone_pavement:2,15,CONCRETE:8,100)
RandomBlock(2,49,-7,rustic:iron_lattice:0,5,STAINED_CLAY:15,5,STAINED_CLAY:7,5,quark:iron_plate_slab:8,15,quark:world_stone_pavement:2,15,STAINED_CLAY:9,100)
RandomBlock(2,49,-6,rustic:iron_lattice:0,5,STAINED_CLAY:15,5,STAINED_CLAY:7,5,quark:iron_plate_slab:8,15,quark:world_stone_pavement:2,15,STAINED_CLAY:9,100)
Block(2,49,-5,quark:iron_plate:1)
RandomBlock(2,49,-4,rustic:iron_lattice:0,5,STAINED_CLAY:15,5,STAINED_CLAY:7,5,quark:iron_plate_slab:8,15,quark:world_stone_pavement:2,15,STAINED_CLAY:9,100)
RandomBlock(2,49,-3,rustic:iron_lattice:0,5,CONCRETE_POWDER:8,10,quark:limestone:1,15,quark:limestone,15,quark:world_stone_pavement:2,15,CONCRETE:8,100)
Block(2,50,-7,quark:iron_plate_stairs)
Block(2,50,-5,quark:iron_plate:1)
Block(2,50,-3,rustic:iron_lattice:0)
Block(2,51,-3,rustic:iron_lattice:0)
Block(2,65,-7,STEP:13)
Block(2,65,-6,rustic:iron_lattice:0)
RandomBlock(2,66,-7,CONCRETE_POWDER:7,25,CONCRETE:7,100)
Block(2,66,-6,IRON_FENCE:0)
Block(2,67,-7,STEP:5)
Block(2,68,-7,rustic:iron_lattice:0)
Block(3,43,-7,quark:iron_plate:1)
Block(3,43,-6,quark:iron_plate:1)
Block(3,43,-5,quark:iron_plate:1)
Block(3,43,-4,quark:iron_plate:1)
RandomBlock(3,44,-7,rustic:iron_lattice:0,5,STAINED_CLAY:15,5,STAINED_CLAY:7,5,quark:iron_plate_slab:8,15,quark:world_stone_pavement:2,15,STAINED_CLAY:9,100)
RandomBlock(3,44,-6,rustic:iron_lattice:0,5,STAINED_CLAY:15,5,STAINED_CLAY:7,5,quark:iron_plate_slab:8,15,quark:world_stone_pavement:2,15,STAINED_CLAY:9,100)
RandomBlock(3,44,-5,rustic:iron_lattice:0,5,STAINED_CLAY:15,5,STAINED_CLAY:7,5,quark:iron_plate_slab:8,15,quark:world_stone_pavement:2,15,STAINED_CLAY:9,100)
Block(3,44,-4,quark:iron_plate:1)
RandomBlock(3,44,-3,rustic:iron_lattice:0,5,STAINED_CLAY:15,5,STAINED_CLAY:7,5,quark:iron_plate_slab:8,15,quark:world_stone_pavement:2,15,STAINED_CLAY:9,100)
RandomBlock(3,44,-2,rustic:iron_lattice:0,5,STAINED_CLAY:15,5,STAINED_CLAY:7,5,quark:iron_plate_slab:8,15,quark:world_stone_pavement:2,15,STAINED_CLAY:9,100)
Block(3,45,-7,DISPENSER:1)
RandomBlock(3,45,-5,rustic:iron_lattice:0,5,CONCRETE_POWDER:8,10,quark:limestone:1,15,quark:limestone,15,quark:world_stone_pavement:2,15,CONCRETE:8,100)
Block(3,45,-4,quark:iron_plate:1)
Block(3,45,-2,rustic:iron_lattice:0)
Block(3,46,-7,DOUBLE_STEP:0)
Block(3,46,-6,LEVER:3)
Block(3,46,-5,CONCRETE:15)
Block(3,46,-4,quark:iron_plate:1)
Block(3,46,-2,rustic:iron_lattice:0)
RandomBlock(3,47,-5,rustic:iron_lattice:0,5,CONCRETE_POWDER:8,10,quark:limestone:1,15,quark:limestone,15,quark:world_stone_pavement:2,15,CONCRETE:8,100)
Block(3,47,-4,quark:iron_plate:1)
RandomBlock(3,48,-5,rustic:iron_lattice:0,5,CONCRETE_POWDER:8,10,quark:limestone:1,15,quark:limestone,15,quark:world_stone_pavement:2,15,CONCRETE:8,100)
RandomBlock(3,48,-4,rustic:iron_lattice:0,5,CONCRETE_POWDER:8,10,quark:limestone:1,15,quark:limestone,15,quark:world_stone_pavement:2,15,CONCRETE:8,100)
RandomBlock(3,49,-7,rustic:iron_lattice:0,5,STAINED_CLAY:15,5,STAINED_CLAY:7,5,quark:iron_plate_slab:8,15,quark:world_stone_pavement:2,15,STAINED_CLAY:9,100)
RandomBlock(3,49,-6,rustic:iron_lattice:0,5,STAINED_CLAY:15,5,STAINED_CLAY:7,5,quark:iron_plate_slab:8,15,quark:world_stone_pavement:2,15,STAINED_CLAY:9,100)
RandomBlock(3,49,-5,rustic:iron_lattice:0,5,STAINED_CLAY:15,5,STAINED_CLAY:7,5,quark:iron_plate_slab:8,15,quark:world_stone_pavement:2,15,STAINED_CLAY:9,100)
RandomBlock(3,49,-4,rustic:iron_lattice:0,5,STAINED_CLAY:15,5,STAINED_CLAY:7,5,quark:iron_plate_slab:8,15,quark:world_stone_pavement:2,15,STAINED_CLAY:9,100)
RandomBlock(3,49,-3,rustic:iron_lattice:0,5,CONCRETE_POWDER:8,10,quark:limestone:1,15,quark:limestone,15,quark:world_stone_pavement:2,15,CONCRETE:8,100)
Block(3,50,-3,rustic:iron_lattice:0)
Block(3,51,-3,rustic:iron_lattice:0)
Block(3,65,-7,STEP:13)
Block(3,65,-6,rustic:iron_lattice:0)
RandomBlock(3,66,-7,CONCRETE_POWDER:7,25,CONCRETE:7,100)
Block(3,66,-6,IRON_FENCE:0)
Block(3,67,-7,STEP:5)
Block(3,68,-7,rustic:iron_lattice:0)
Block(4,43,-7,STONE:6)
Block(4,43,-6,STONE:6)
Block(4,43,-5,STONE:6)
Block(4,43,-4,STONE:6)
Block(4,43,-3,STONE:6)
Block(4,43,-2,STONE:6)
Block(4,43,-1,STONE:6)
RandomBlock(4,44,-7,rustic:iron_lattice:0,5,STAINED_CLAY:15,5,STAINED_CLAY:7,5,quark:iron_plate_slab:8,15,quark:world_stone_pavement:2,15,STAINED_CLAY:9,100)
RandomBlock(4,44,-6,rustic:iron_lattice:0,5,STAINED_CLAY:15,5,STAINED_CLAY:7,5,quark:iron_plate_slab:8,15,quark:world_stone_pavement:2,15,STAINED_CLAY:9,100)
RandomBlock(4,44,-5,rustic:iron_lattice:0,5,STAINED_CLAY:15,5,STAINED_CLAY:7,5,quark:iron_plate_slab:8,15,quark:world_stone_pavement:2,15,STAINED_CLAY:9,100)
RandomBlock(4,44,-4,rustic:iron_lattice:0,5,CONCRETE_POWDER:8,10,quark:limestone:1,15,quark:limestone,15,quark:world_stone_pavement:2,15,CONCRETE:8,100)
RandomBlock(4,44,-3,rustic:iron_lattice:0,5,STAINED_CLAY:15,5,STAINED_CLAY:7,5,quark:iron_plate_slab:8,15,quark:world_stone_pavement:2,15,STAINED_CLAY:9,100)
RandomBlock(4,44,-2,rustic:iron_lattice:0,5,STAINED_CLAY:15,5,STAINED_CLAY:7,5,quark:iron_plate_slab:8,15,quark:world_stone_pavement:2,15,STAINED_CLAY:9,100)
Block(4,44,-1,STONE:6)
RandomBlock(4,45,-5,rustic:iron_lattice:0,5,CONCRETE_POWDER:8,10,quark:limestone:1,15,quark:limestone,15,quark:world_stone_pavement:2,15,CONCRETE:8,100)
Block(4,45,-2,rustic:iron_lattice:0)
Block(4,45,-1,STONE:6)
Block(4,46,-7,STONE_BUTTON:1)
Block(4,46,-5,CONCRETE:15)
Block(4,46,-2,rustic:iron_lattice:0)
Block(4,46,-1,STONE:6)
RandomBlock(4,47,-5,rustic:iron_lattice:0,5,CONCRETE_POWDER:8,10,quark:limestone:1,15,quark:limestone,15,quark:world_stone_pavement:2,15,CONCRETE:8,100)
Block(4,47,-1,STONE:6)
RandomBlock(4,48,-5,rustic:iron_lattice:0,5,CONCRETE_POWDER:8,10,quark:limestone:1,15,quark:limestone,15,quark:world_stone_pavement:2,15,CONCRETE:8,100)
RandomBlock(4,48,-4,rustic:iron_lattice:0,5,CONCRETE_POWDER:8,10,quark:limestone:1,15,quark:limestone,15,quark:world_stone_pavement:2,15,CONCRETE:8,100)
Block(4,48,-1,STONE:6)
RandomBlock(4,49,-7,rustic:iron_lattice:0,5,STAINED_CLAY:15,5,STAINED_CLAY:7,5,quark:iron_plate_slab:8,15,quark:world_stone_pavement:2,15,STAINED_CLAY:9,100)
RandomBlock(4,49,-6,rustic:iron_lattice:0,5,STAINED_CLAY:15,5,STAINED_CLAY:7,5,quark:iron_plate_slab:8,15,quark:world_stone_pavement:2,15,STAINED_CLAY:9,100)
Block(4,49,-5,STONE:6)
RandomBlock(4,49,-4,rustic:iron_lattice:0,5,STAINED_CLAY:15,5,STAINED_CLAY:7,5,quark:iron_plate_slab:8,15,quark:world_stone_pavement:2,15,STAINED_CLAY:9,100)
RandomBlock(4,49,-3,rustic:iron_lattice:0,5,CONCRETE_POWDER:8,10,quark:limestone:1,15,quark:limestone,15,quark:world_stone_pavement:2,15,CONCRETE:8,100)
Block(4,49,-1,STONE:6)
Block(4,50,-6,STONE:6)
Block(4,50,-5,STONE:6)
Block(4,50,-4,STONE:6)
Block(4,50,-3,STONE:6)
Block(4,50,-2,STONE:6)
Block(4,50,-1,STONE:6)
Block(4,51,-3,rustic:iron_lattice:0)
Block(4,65,-7,STEP:13)
Block(4,65,-6,rustic:iron_lattice:0)
RandomBlock(4,66,-7,CONCRETE_POWDER:7,25,CONCRETE:7,100)
Block(4,66,-6,IRON_FENCE:0)
Block(4,67,-7,STEP:5)
Block(4,68,-7,rustic:iron_lattice:0)
Block(5,43,-7,rustic:iron_lattice:0)
Block(5,43,-5,rustic:iron_lattice:0)
Block(5,43,-3,rustic:iron_lattice:0)
RandomBlock(5,44,-7,rustic:iron_lattice:0,5,STAINED_CLAY:15,5,STAINED_CLAY:7,5,quark:iron_plate_slab:8,15,quark:world_stone_pavement:2,15,STAINED_CLAY:9,100)
RandomBlock(5,44,-6,rustic:iron_lattice:0,5,STAINED_CLAY:15,5,STAINED_CLAY:7,5,quark:iron_plate_slab:8,15,quark:world_stone_pavement:2,15,STAINED_CLAY:9,100)
RandomBlock(5,44,-5,rustic:iron_lattice:0,5,STAINED_CLAY:15,5,STAINED_CLAY:7,5,quark:iron_plate_slab:8,15,quark:world_stone_pavement:2,15,STAINED_CLAY:9,100)
RandomBlock(5,44,-4,rustic:iron_lattice:0,5,STAINED_CLAY:15,5,STAINED_CLAY:7,5,quark:iron_plate_slab:8,15,quark:world_stone_pavement:2,15,STAINED_CLAY:9,100)
RandomBlock(5,44,-3,rustic:iron_lattice:0,5,STAINED_CLAY:15,5,STAINED_CLAY:7,5,quark:iron_plate_slab:8,15,quark:world_stone_pavement:2,15,STAINED_CLAY:9,100)
RandomBlock(5,44,-2,rustic:iron_lattice:0,5,STAINED_CLAY:15,5,STAINED_CLAY:7,5,quark:iron_plate_slab:8,15,quark:world_stone_pavement:2,15,STAINED_CLAY:9,100)
RandomBlock(5,45,-5,rustic:iron_lattice:0,5,CONCRETE_POWDER:8,10,quark:limestone:1,15,quark:limestone,15,quark:world_stone_pavement:2,15,CONCRETE:8,100)
Block(5,45,-2,rustic:iron_lattice:0)
Block(5,46,-7,STONE_BUTTON:2)
Block(5,46,-5,CONCRETE:15)
Block(5,46,-2,rustic:iron_lattice:0)
RandomBlock(5,47,-5,rustic:iron_lattice:0,5,CONCRETE_POWDER:8,10,quark:limestone:1,15,quark:limestone,15,quark:world_stone_pavement:2,15,CONCRETE:8,100)
RandomBlock(5,48,-5,rustic:iron_lattice:0,5,CONCRETE_POWDER:8,10,quark:limestone:1,15,quark:limestone,15,quark:world_stone_pavement:2,15,CONCRETE:8,100)
RandomBlock(5,48,-4,rustic:iron_lattice:0,5,CONCRETE_POWDER:8,10,quark:limestone:1,15,quark:limestone,15,quark:world_stone_pavement:2,15,CONCRETE:8,100)
RandomBlock(5,49,-7,rustic:iron_lattice:0,5,STAINED_CLAY:15,5,STAINED_CLAY:7,5,quark:iron_plate_slab:8,15,quark:world_stone_pavement:2,15,STAINED_CLAY:9,100)
RandomBlock(5,49,-6,rustic:iron_lattice:0,5,STAINED_CLAY:15,5,STAINED_CLAY:7,5,quark:iron_plate_slab:8,15,quark:world_stone_pavement:2,15,STAINED_CLAY:9,100)
RandomBlock(5,49,-5,rustic:iron_lattice:0,5,STAINED_CLAY:15,5,STAINED_CLAY:7,5,quark:iron_plate_slab:8,15,quark:world_stone_pavement:2,15,STAINED_CLAY:9,100)
RandomBlock(5,49,-4,rustic:iron_lattice:0,5,STAINED_CLAY:15,5,STAINED_CLAY:7,5,quark:iron_plate_slab:8,15,quark:world_stone_pavement:2,15,STAINED_CLAY:9,100)
RandomBlock(5,49,-3,rustic:iron_lattice:0,5,CONCRETE_POWDER:8,10,quark:limestone:1,15,quark:limestone,15,quark:world_stone_pavement:2,15,CONCRETE:8,100)
Block(5,50,-6,STONE:6)
Block(5,50,-3,rustic:iron_lattice:0)
Block(5,51,-3,rustic:iron_lattice:0)
Block(5,65,-7,STEP:13)
Block(5,65,-6,rustic:iron_lattice:0)
RandomBlock(5,66,-7,CONCRETE_POWDER:7,25,CONCRETE:7,100)
Block(5,66,-6,IRON_FENCE:0)
Block(5,67,-7,STEP:5)
Block(5,68,-7,rustic:iron_lattice:0)
Block(6,43,-7,STONE:6)
Block(6,43,-6,STONE:6)
Block(6,43,-5,STONE:6)
Block(6,43,-4,STONE:6)
Block(6,43,-3,STONE:6)
Block(6,43,-2,STONE:6)
Block(6,43,-1,STONE:6)
RandomBlock(6,44,-7,rustic:iron_lattice:0,5,STAINED_CLAY:15,5,STAINED_CLAY:7,5,quark:iron_plate_slab:8,15,quark:world_stone_pavement:2,15,STAINED_CLAY:9,100)
RandomBlock(6,44,-6,rustic:iron_lattice:0,5,STAINED_CLAY:15,5,STAINED_CLAY:7,5,quark:iron_plate_slab:8,15,quark:world_stone_pavement:2,15,STAINED_CLAY:9,100)
RandomBlock(6,44,-5,rustic:iron_lattice:0,5,STAINED_CLAY:15,5,STAINED_CLAY:7,5,quark:iron_plate_slab:8,15,quark:world_stone_pavement:2,15,STAINED_CLAY:9,100)
RandomBlock(6,44,-4,rustic:iron_lattice:0,5,STAINED_CLAY:15,5,STAINED_CLAY:7,5,quark:iron_plate_slab:8,15,quark:world_stone_pavement:2,15,STAINED_CLAY:9,100)
RandomBlock(6,44,-3,rustic:iron_lattice:0,5,STAINED_CLAY:15,5,STAINED_CLAY:7,5,quark:iron_plate_slab:8,15,quark:world_stone_pavement:2,15,STAINED_CLAY:9,100)
RandomBlock(6,44,-2,rustic:iron_lattice:0,5,STAINED_CLAY:15,5,STAINED_CLAY:7,5,quark:iron_plate_slab:8,15,quark:world_stone_pavement:2,15,STAINED_CLAY:9,100)
Block(6,44,-1,STONE:6)
Block(6,45,-7,DISPENSER:1)
RandomBlock(6,45,-5,rustic:iron_lattice:0,5,CONCRETE_POWDER:8,10,quark:limestone:1,15,quark:limestone,15,quark:world_stone_pavement:2,15,CONCRETE:8,100)
Block(6,45,-2,rustic:iron_lattice:0)
Block(6,45,-1,STONE:6)
Block(6,46,-7,DOUBLE_STEP:0)
Block(6,46,-6,LEVER:3)
Block(6,46,-5,CONCRETE:15)
Block(6,46,-2,rustic:iron_lattice:0)
Block(6,46,-1,STONE:6)
RandomBlock(6,47,-5,rustic:iron_lattice:0,5,CONCRETE_POWDER:8,10,quark:limestone:1,15,quark:limestone,15,quark:world_stone_pavement:2,15,CONCRETE:8,100)
Block(6,47,-1,STONE:6)
RandomBlock(6,48,-5,rustic:iron_lattice:0,5,CONCRETE_POWDER:8,10,quark:limestone:1,15,quark:limestone,15,quark:world_stone_pavement:2,15,CONCRETE:8,100)
RandomBlock(6,48,-4,rustic:iron_lattice:0,5,CONCRETE_POWDER:8,10,quark:limestone:1,15,quark:limestone,15,quark:world_stone_pavement:2,15,CONCRETE:8,100)
Block(6,48,-1,STONE:6)
RandomBlock(6,49,-7,rustic:iron_lattice:0,5,STAINED_CLAY:15,5,STAINED_CLAY:7,5,quark:iron_plate_slab:8,15,quark:world_stone_pavement:2,15,STAINED_CLAY:9,100)
RandomBlock(6,49,-6,rustic:iron_lattice:0,5,STAINED_CLAY:15,5,STAINED_CLAY:7,5,quark:iron_plate_slab:8,15,quark:world_stone_pavement:2,15,STAINED_CLAY:9,100)
Block(6,49,-5,STONE:6)
RandomBlock(6,49,-4,rustic:iron_lattice:0,5,STAINED_CLAY:15,5,STAINED_CLAY:7,5,quark:iron_plate_slab:8,15,quark:world_stone_pavement:2,15,STAINED_CLAY:9,100)
RandomBlock(6,49,-3,rustic:iron_lattice:0,5,CONCRETE_POWDER:8,10,quark:limestone:1,15,quark:limestone,15,quark:world_stone_pavement:2,15,CONCRETE:8,100)
Block(6,49,-1,STONE:6)
Block(6,50,-6,STONE:6)
Block(6,50,-5,STONE:6)
Block(6,50,-4,STONE:6)
Block(6,50,-3,STONE:6)
Block(6,50,-2,STONE:6)
Block(6,50,-1,STONE:6)
Block(6,51,-3,rustic:iron_lattice:0)
Block(6,65,-7,STEP:13)
Block(6,65,-6,rustic:iron_lattice:0)
RandomBlock(6,66,-7,CONCRETE_POWDER:7,25,CONCRETE:7,100)
Block(6,66,-6,IRON_FENCE:0)
Block(6,67,-7,STEP:5)
Block(6,68,-7,rustic:iron_lattice:0)
RandomBlock(7,44,-7,rustic:iron_lattice:0,5,STAINED_CLAY:15,5,STAINED_CLAY:7,5,quark:iron_plate_slab:8,15,quark:world_stone_pavement:2,15,STAINED_CLAY:9,100)
RandomBlock(7,44,-6,rustic:iron_lattice:0,5,STAINED_CLAY:15,5,STAINED_CLAY:7,5,quark:iron_plate_slab:8,15,quark:world_stone_pavement:2,15,STAINED_CLAY:9,100)
RandomBlock(7,44,-5,rustic:iron_lattice:0,5,STAINED_CLAY:15,5,STAINED_CLAY:7,5,quark:iron_plate_slab:8,15,quark:world_stone_pavement:2,15,STAINED_CLAY:9,100)
RandomBlock(7,44,-4,rustic:iron_lattice:0,5,STAINED_CLAY:15,5,STAINED_CLAY:7,5,quark:iron_plate_slab:8,15,quark:world_stone_pavement:2,15,STAINED_CLAY:9,100)
RandomBlock(7,44,-3,rustic:iron_lattice:0,5,STAINED_CLAY:15,5,STAINED_CLAY:7,5,quark:iron_plate_slab:8,15,quark:world_stone_pavement:2,15,STAINED_CLAY:9,100)
RandomBlock(7,44,-2,rustic:iron_lattice:0,5,STAINED_CLAY:15,5,STAINED_CLAY:7,5,quark:iron_plate_slab:8,15,quark:world_stone_pavement:2,15,STAINED_CLAY:9,100)
RandomBlock(7,45,-5,rustic:iron_lattice:0,5,CONCRETE_POWDER:8,10,quark:limestone:1,15,quark:limestone,15,quark:world_stone_pavement:2,15,CONCRETE:8,100)
Block(7,45,-2,rustic:iron_lattice:0)
Block(7,46,-7,STONE_BUTTON:1)
Block(7,46,-5,STAINED_GLASS_PANE:7)
Block(7,46,-2,rustic:iron_lattice:0)
RandomBlock(7,47,-5,rustic:iron_lattice:0,5,CONCRETE_POWDER:8,10,quark:limestone:1,15,quark:limestone,15,quark:world_stone_pavement:2,15,CONCRETE:8,100)
Block(7,48,-5,REDSTONE_LAMP_OFF:0)
RandomBlock(7,48,-4,rustic:iron_lattice:0,5,CONCRETE_POWDER:8,10,quark:limestone:1,15,quark:limestone,15,quark:world_stone_pavement:2,15,CONCRETE:8,100)
RandomBlock(7,49,-7,rustic:iron_lattice:0,5,STAINED_CLAY:15,5,STAINED_CLAY:7,5,quark:iron_plate_slab:8,15,quark:world_stone_pavement:2,15,STAINED_CLAY:9,100)
RandomBlock(7,49,-6,rustic:iron_lattice:0,5,STAINED_CLAY:15,5,STAINED_CLAY:7,5,quark:iron_plate_slab:8,15,quark:world_stone_pavement:2,15,STAINED_CLAY:9,100)
RandomBlock(7,49,-5,rustic:iron_lattice:0,5,STAINED_CLAY:15,5,STAINED_CLAY:7,5,quark:iron_plate_slab:8,15,quark:world_stone_pavement:2,15,STAINED_CLAY:9,100)
RandomBlock(7,49,-4,rustic:iron_lattice:0,5,STAINED_CLAY:15,5,STAINED_CLAY:7,5,quark:iron_plate_slab:8,15,quark:world_stone_pavement:2,15,STAINED_CLAY:9,100)
RandomBlock(7,49,-3,rustic:iron_lattice:0,5,CONCRETE_POWDER:8,10,quark:limestone:1,15,quark:limestone,15,quark:world_stone_pavement:2,15,CONCRETE:8,100)
Block(7,50,-6,STONE:6)
Block(7,50,-3,rustic:iron_lattice:0)
Block(7,51,-3,rustic:iron_lattice:0)
Block(7,65,-7,STEP:13)
Block(7,65,-6,rustic:iron_lattice:0)
RandomBlock(7,66,-7,CONCRETE_POWDER:7,25,CONCRETE:7,100)
Block(7,66,-6,IRON_FENCE:0)
Block(7,67,-7,STEP:5)
Block(7,68,-7,rustic:iron_lattice:0)

#######################################################################
# +-----------------------------------------------------------------+ #
# |                             Branches                            | #
# +-----------------------------------------------------------------+ #
#######################################################################

Branch(0,0,-16,true,OilRigC1R1,NORTH,100.0,0)

#######################################################################
# +-----------------------------------------------------------------+ #
# |                             Entities                            | #
# +-----------------------------------------------------------------+ #
#######################################################################


#######################################################################
# +-----------------------------------------------------------------+ #
# |                            Particles                            | #
# +-----------------------------------------------------------------+ #
#######################################################################


#######################################################################
# +-----------------------------------------------------------------+ #
# |                             Spawners                            | #
# +-----------------------------------------------------------------+ #
#######################################################################


#######################################################################
# +-----------------------------------------------------------------+ #
# |                             ModData                             | #
# +-----------------------------------------------------------------+ #
#######################################################################

