
#######################################################################
# +-----------------------------------------------------------------+ #
# |                            BO3 object                           | #
# +-----------------------------------------------------------------+ #
#######################################################################

Author: NLBlackHeavenNL

Description: No description given

Version: 3

SettingsMode: WriteWithoutComments


#######################################################################
# +-----------------------------------------------------------------+ #
# |                          Main settings                          | #
# +-----------------------------------------------------------------+ #
#######################################################################

Tree: true

Frequency: 1

Rarity: 100.0

RotateRandomly: false

SpawnHeight: highestSolidBlock

SpawnHeightOffset: -1

SpawnHeightVariance: 0

##############################
# Height Limits for the BO3. #
##############################

MinHeight: 0

MaxHeight: 255

######################
# Extrusion settings #
######################

ExtrudeMode: None

ExtrudeThroughBlocks: AIR

MaxBranchDepth: 10

ExcludedBiomes: All


#######################################################################
# +-----------------------------------------------------------------+ #
# |                      Source block settings                      | #
# +-----------------------------------------------------------------+ #
#######################################################################

SourceBlocks: AIR,GRASS,DIRT,biomesoplenty:dirt

MaxPercentageOutsideSourceBlock: 0

OutsideSourceBlock: placeAnyway

DoReplaceBlocks: true

IsOTGPlus: false


#######################################################################
# +-----------------------------------------------------------------+ #
# |                              Blocks                             | #
# +-----------------------------------------------------------------+ #
#######################################################################

Block(-4,7,1,dttraverse:leaves4:0)
Block(-4,8,2,dttraverse:leaves4:0)
Block(-4,9,1,dttraverse:leaves4:0)
Block(-4,9,2,dttraverse:leaves4:0)
Block(-3,6,1,dttraverse:leaves4:0)
Block(-3,7,0,dttraverse:leaves4:0)
Block(-3,7,1,dttraverse:leaves4)
Block(-3,7,2,dttraverse:leaves4:0)
Block(-3,8,1,dynamictrees:oakbranch)
Block(-3,8,2,dttraverse:leaves4)
Block(-3,9,1,dttraverse:leaves4)
Block(-3,9,2,dttraverse:leaves4:2)
Block(-3,9,3,dttraverse:leaves4:0)
Block(-3,10,1,dttraverse:leaves4:0)
Block(-3,10,2,dttraverse:leaves4:0)
Block(-2,4,1,dynamictrees:oakbranch)
Block(-2,5,0,dttraverse:leaves4:0)
Block(-2,5,1,dttraverse:leaves4)
Block(-2,5,2,dynamictrees:oakbranch)
Block(-2,6,0,dttraverse:leaves4:0)
Block(-2,6,1,dttraverse:leaves4)
Block(-2,6,2,dttraverse:leaves4)
Block(-2,7,0,dttraverse:leaves4:0)
Block(-2,7,1,dttraverse:leaves4:2)
Block(-2,7,2,dttraverse:leaves4:1)
Block(-2,7,3,dttraverse:leaves4:0)
Block(-2,8,1,dynamictrees:oakbranch:1)
Block(-2,8,2,dttraverse:leaves4:0)
Block(-2,9,2,dttraverse:leaves4:0)
Block(-2,10,-1,dttraverse:leaves4:0)
Block(-2,10,2,dttraverse:leaves4:0)
Block(-2,11,0,dttraverse:leaves4:0)
Block(-2,11,2,dttraverse:leaves4:0)
Block(-2,12,1,dttraverse:leaves4:0)
Block(-1,4,1,dynamictrees:oakbranch:2)
Block(-1,5,1,dynamictrees:oakbranch:2)
Block(-1,5,2,dynamictrees:oakbranch:1)
Block(-1,6,-1,dttraverse:leaves4:2)
Block(-1,6,1,dynamictrees:oakbranch)
Block(-1,6,2,dttraverse:leaves4)
Block(-1,7,1,dttraverse:leaves4)
Block(-1,7,2,dttraverse:leaves4:2)
Block(-1,8,0,dynamictrees:oakbranch)
Block(-1,8,1,dynamictrees:oakbranch:1)
Block(-1,8,2,dttraverse:leaves4:0)
Block(-1,9,-1,dttraverse:leaves4:0)
Block(-1,9,0,dttraverse:leaves4)
Block(-1,9,1,dynamictrees:oakbranch)
Block(-1,9,2,dttraverse:leaves4)
Block(-1,10,-1,dttraverse:leaves4:1)
Block(-1,10,0,dttraverse:leaves4:2)
Block(-1,10,1,dttraverse:leaves4)
Block(-1,10,2,dttraverse:leaves4:2)
Block(-1,10,4,dttraverse:leaves4:0)
Block(-1,11,-1,dttraverse:leaves4:0)
Block(-1,11,0,dttraverse:leaves4:1)
Block(-1,11,1,dttraverse:leaves4:2)
Block(-1,11,2,dttraverse:leaves4:1)
Block(-1,11,3,dttraverse:leaves4:0)
Block(-1,12,-2,dttraverse:leaves4:0)
Block(-1,12,-1,dttraverse:leaves4:0)
Block(-1,12,0,dttraverse:leaves4:0)
Block(-1,12,1,dttraverse:leaves4:1)
Block(-1,12,2,dttraverse:leaves4:0)
Block(-1,13,-1,dttraverse:leaves4:0)
Block(-1,13,0,dttraverse:leaves4:0)
Block(-1,13,1,dttraverse:leaves4:0)
Block(-1,13,2,dttraverse:leaves4:0)
Block(-1,14,0,dttraverse:leaves4:0)
Block(-1,14,1,dttraverse:leaves4:0)
Block(-1,14,2,dttraverse:leaves4:0)
Block(0,4,0,dynamictrees:oakbranch)
Block(0,4,1,dynamictrees:oakbranch:3)
Block(0,4,2,dynamictrees:oakbranch)
Block(0,5,-1,dynamictrees:oakbranch)
Block(0,5,0,dttraverse:leaves4)
Block(0,5,1,dttraverse:leaves4:2)
Block(0,5,2,dttraverse:leaves4)
Block(0,6,-2,dttraverse:leaves4:0)
Block(0,6,-1,dttraverse:leaves4)
Block(0,6,0,dttraverse:leaves4:2)
Block(0,6,2,dynamictrees:oakbranch:1)
Block(0,6,3,dynamictrees:oakbranch)
Block(0,7,-2,dttraverse:leaves4)
Block(0,7,-1,dttraverse:leaves4:0)
Block(0,7,0,dttraverse:leaves4:1)
Block(0,7,2,dttraverse:leaves4:0)
Block(0,7,3,dttraverse:leaves4)
Block(0,8,-1,dttraverse:leaves4:0)
Block(0,8,0,dttraverse:leaves4)
Block(0,8,1,dynamictrees:oakbranch:2)
Block(0,8,2,dttraverse:leaves4)
Block(0,8,3,dttraverse:leaves4:2)
Block(0,9,-2,dttraverse:leaves4:0)
Block(0,9,-1,dttraverse:leaves4:1)
Block(0,9,0,dttraverse:leaves4:2)
Block(0,9,2,dynamictrees:oakbranch)
Block(0,9,3,dttraverse:leaves4)
Block(0,10,-2,dttraverse:leaves4:1)
Block(0,10,-1,dttraverse:leaves4:2)
Block(0,10,0,dttraverse:leaves4)
Block(0,10,1,dynamictrees:oakbranch)
Block(0,10,2,dttraverse:leaves4)
Block(0,10,3,dttraverse:leaves4:2)
Block(0,11,-2,dttraverse:leaves4:2)
Block(0,11,-1,dttraverse:leaves4)
Block(0,11,0,dttraverse:leaves4:2)
Block(0,11,1,dttraverse:leaves4)
Block(0,11,2,dttraverse:leaves4:2)
Block(0,11,3,dttraverse:leaves4:1)
Block(0,11,4,dttraverse:leaves4:0)
Block(0,12,-3,dttraverse:leaves4:0)
Block(0,12,-2,dttraverse:leaves4:1)
Block(0,12,-1,dttraverse:leaves4:2)
Block(0,12,0,dttraverse:leaves4:1)
Block(0,12,1,dttraverse:leaves4:2)
Block(0,12,2,dttraverse:leaves4:1)
Block(0,12,3,dttraverse:leaves4:0)
Block(0,13,-2,dttraverse:leaves4:0)
Block(0,13,-1,dttraverse:leaves4:1)
Block(0,13,0,dttraverse:leaves4:2)
Block(0,13,1,dttraverse:leaves4)
Block(0,13,2,dttraverse:leaves4:2)
Block(0,13,3,dttraverse:leaves4:0)
Block(0,14,-1,dttraverse:leaves4:0)
Block(0,14,0,dttraverse:leaves4:1)
Block(0,14,1,dttraverse:leaves4:2)
Block(0,14,2,dttraverse:leaves4:1)
Block(0,14,3,dttraverse:leaves4:0)
Block(0,15,0,dttraverse:leaves4:0)
Block(0,15,1,dttraverse:leaves4:0)
Block(0,15,2,dttraverse:leaves4:0)
Block(1,0,1,dynamictrees:rootydirtspecies:5,DT_TBOak_Big_14/1-species_tile_entity.nbt)
Block(1,1,1,dynamictrees:oakbranch:7)
Block(1,2,1,dynamictrees:oakbranch:7)
Block(1,3,0,dynamictrees:oakbranch)
Block(1,3,1,dynamictrees:oakbranch:7)
Block(1,3,2,dynamictrees:oakbranch)
Block(1,4,0,dttraverse:leaves4)
Block(1,4,1,dynamictrees:oakbranch:7)
Block(1,4,2,dttraverse:leaves4)
Block(1,5,-1,dynamictrees:oakbranch:2)
Block(1,5,0,dynamictrees:oakbranch:2)
Block(1,5,1,dynamictrees:oakbranch:7)
Block(1,5,2,dttraverse:leaves4:2)
Block(1,5,3,dttraverse:leaves4:0)
Block(1,6,-1,dynamictrees:oakbranch:1)
Block(1,6,1,dynamictrees:oakbranch:6)
Block(1,6,2,dynamictrees:oakbranch:1)
Block(1,6,3,dttraverse:leaves4)
Block(1,7,-2,dynamictrees:oakbranch)
Block(1,7,-1,dynamictrees:oakbranch:1)
Block(1,7,1,dynamictrees:oakbranch:5)
Block(1,7,2,dttraverse:leaves4:0)
Block(1,7,3,dttraverse:leaves4:2)
Block(1,8,-3,dttraverse:leaves4:0)
Block(1,8,-2,dttraverse:leaves4)
Block(1,8,1,dynamictrees:oakbranch:5)
Block(1,8,2,dttraverse:leaves4:0)
Block(1,8,3,dttraverse:leaves4:1)
Block(1,9,-3,dttraverse:leaves4:0)
Block(1,9,-2,dttraverse:leaves4:2)
Block(1,9,1,dynamictrees:oakbranch:4)
Block(1,9,2,dynamictrees:oakbranch:1)
Block(1,9,3,dynamictrees:oakbranch:1)
Block(1,9,4,dynamictrees:oakbranch)
Block(1,10,-3,dttraverse:leaves4:0)
Block(1,10,-2,dttraverse:leaves4:2)
Block(1,10,1,dynamictrees:oakbranch:2)
Block(1,10,4,dttraverse:leaves4)
Block(1,10,5,dttraverse:leaves4:0)
Block(1,11,-3,dttraverse:leaves4:0)
Block(1,11,-2,dttraverse:leaves4)
Block(1,11,-1,dynamictrees:oakbranch)
Block(1,11,0,dynamictrees:oakbranch:1)
Block(1,11,1,dynamictrees:oakbranch:2)
Block(1,11,2,dttraverse:leaves4:0)
Block(1,11,3,dttraverse:leaves4:0)
Block(1,11,4,dttraverse:leaves4:0)
Block(1,12,-3,dttraverse:leaves4:0)
Block(1,12,-2,dttraverse:leaves4:2)
Block(1,12,-1,dttraverse:leaves4)
Block(1,12,1,dynamictrees:oakbranch:1)
Block(1,13,-3,dttraverse:leaves4:0)
Block(1,13,-2,dttraverse:leaves4:1)
Block(1,13,-1,dttraverse:leaves4:0)
Block(1,13,1,dynamictrees:oakbranch)
Block(1,14,-2,dttraverse:leaves4:0)
Block(1,14,0,dttraverse:leaves4:0)
Block(1,14,1,dttraverse:leaves4)
Block(1,15,1,dttraverse:leaves4:0)
Block(2,4,1,dynamictrees:oakbranch:4)
Block(2,4,2,dynamictrees:oakbranch:1)
Block(2,5,0,dynamictrees:oakbranch)
Block(2,5,2,dynamictrees:oakbranch:1)
Block(2,5,3,dynamictrees:oakbranch:1)
Block(2,5,4,dynamictrees:oakbranch)
Block(2,6,-1,dttraverse:leaves4:0)
Block(2,6,0,dttraverse:leaves4)
Block(2,6,3,dynamictrees:oakbranch)
Block(2,6,4,dttraverse:leaves4)
Block(2,7,0,dttraverse:leaves4:0)
Block(2,7,1,dttraverse:leaves4)
Block(2,7,3,dttraverse:leaves4)
Block(2,7,4,dttraverse:leaves4:2)
Block(2,7,5,dttraverse:leaves4:0)
Block(2,8,0,dttraverse:leaves4:0)
Block(2,8,1,dttraverse:leaves4:2)
Block(2,8,2,dttraverse:leaves4:0)
Block(2,8,3,dttraverse:leaves4:0)
Block(2,8,4,dttraverse:leaves4:0)
Block(2,9,-1,dynamictrees:oakbranch)
Block(2,9,0,dynamictrees:oakbranch:1)
Block(2,9,1,dynamictrees:oakbranch:2)
Block(2,9,3,dttraverse:leaves4:0)
Block(2,9,4,dttraverse:leaves4)
Block(2,10,-2,dttraverse:leaves4:0)
Block(2,10,-1,dttraverse:leaves4)
Block(2,10,3,dttraverse:leaves4:0)
Block(2,10,4,dttraverse:leaves4:2)
Block(2,10,5,dttraverse:leaves4:0)
Block(2,11,-2,dttraverse:leaves4:2)
Block(2,11,-1,dttraverse:leaves4)
Block(2,11,1,dttraverse:leaves4:0)
Block(2,11,4,dttraverse:leaves4:0)
Block(2,12,-3,dttraverse:leaves4:0)
Block(2,12,-2,dttraverse:leaves4:1)
Block(2,12,-1,dttraverse:leaves4:2)
Block(2,13,-2,dttraverse:leaves4:0)
Block(2,13,-1,dttraverse:leaves4:0)
Block(2,14,1,dttraverse:leaves4:0)
Block(3,4,-1,dynamictrees:oakbranch:1)
Block(3,4,0,dynamictrees:oakbranch:2)
Block(3,4,1,dynamictrees:oakbranch:3)
Block(3,5,-1,dynamictrees:oakbranch:1)
Block(3,5,1,dynamictrees:oakbranch:1)
Block(3,5,2,dttraverse:leaves4:0)
Block(3,6,-2,dttraverse:leaves4:0)
Block(3,6,0,dttraverse:leaves4:0)
Block(3,6,1,dynamictrees:oakbranch:1)
Block(3,7,0,dttraverse:leaves4)
Block(3,7,1,dynamictrees:oakbranch)
Block(3,7,3,dttraverse:leaves4:0)
Block(3,7,4,dttraverse:leaves4:0)
Block(3,8,0,dttraverse:leaves4:0)
Block(3,8,1,dttraverse:leaves4)
Block(3,8,2,dttraverse:leaves4:0)
Block(3,9,1,dynamictrees:oakbranch:1)
Block(3,10,-1,dttraverse:leaves4:0)
Block(3,10,1,dynamictrees:oakbranch)
Block(3,10,4,dttraverse:leaves4:0)
Block(3,11,-1,dttraverse:leaves4:0)
Block(3,11,0,dttraverse:leaves4:0)
Block(3,11,1,dttraverse:leaves4)
Block(3,11,2,dttraverse:leaves4:0)
Block(3,12,-2,dttraverse:leaves4:0)
Block(3,12,-1,dttraverse:leaves4:0)
Block(3,12,1,dttraverse:leaves4:0)
Block(4,4,1,dynamictrees:oakbranch:1)
Block(4,4,2,dynamictrees:oakbranch)
Block(4,5,-2,dynamictrees:oakbranch)
Block(4,5,-1,dynamictrees:oakbranch:1)
Block(4,5,1,dttraverse:leaves4:0)
Block(4,5,2,dttraverse:leaves4)
Block(4,5,3,dttraverse:leaves4:0)
Block(4,6,-3,dttraverse:leaves4:0)
Block(4,6,-2,dttraverse:leaves4)
Block(4,6,-1,dttraverse:leaves4:0)
Block(4,6,2,dttraverse:leaves4:0)
Block(4,7,-2,dttraverse:leaves4:0)
Block(4,8,1,dttraverse:leaves4:0)
Block(4,11,1,dttraverse:leaves4:0)
Block(5,5,2,dttraverse:leaves4:0)
Block(5,6,-2,dttraverse:leaves4:0)

#######################################################################
# +-----------------------------------------------------------------+ #
# |                            BO3 checks                           | #
# +-----------------------------------------------------------------+ #
#######################################################################

BlockCheck(1,-1,1,GRASS,DIRT,biomesoplenty:grass,UNKNOWN_BLOCK)

#######################################################################
# +-----------------------------------------------------------------+ #
# |                             Branches                            | #
# +-----------------------------------------------------------------+ #
#######################################################################


#######################################################################
# +-----------------------------------------------------------------+ #
# |                             Entities                            | #
# +-----------------------------------------------------------------+ #
#######################################################################


#######################################################################
# +-----------------------------------------------------------------+ #
# |                            Particles                            | #
# +-----------------------------------------------------------------+ #
#######################################################################


#######################################################################
# +-----------------------------------------------------------------+ #
# |                             Spawners                            | #
# +-----------------------------------------------------------------+ #
#######################################################################


#######################################################################
# +-----------------------------------------------------------------+ #
# |                             ModData                             | #
# +-----------------------------------------------------------------+ #
#######################################################################

