
#######################################################################
# +-----------------------------------------------------------------+ #
# |                            BO4 object                           | #
# +-----------------------------------------------------------------+ #
#######################################################################

Author: NLBlackEagle

Description: No description given

SettingsMode: WriteDisable


#######################################################################
# +-----------------------------------------------------------------+ #
# |                          Main settings                          | #
# +-----------------------------------------------------------------+ #
#######################################################################

Frequency: 0

SpawnHeight: highestBlock

UseCenterForHighestBlock: true

##############################
# Height Limits for the BO4. #
##############################

MinHeight: 0

MaxHeight: 255

InheritBO3: 

InheritBO3Rotation: NORTH

OverrideChildSettings: true

OverrideParentHeight: false

CanOverride: false

BranchFrequency: 0

BranchFrequencyGroup: 

MustBeBelowOther: false

MustBeInside: 

CannotBeInside: 

ReplacesBO3: 

MustBeInsideWorldBorders: false

CanSpawnOnWater: true

SpawnOnWaterOnly: false

SpawnUnderWater: false

SpawnAtWaterLevel: false

HeightOffset: 0

RemoveAir: false

ReplaceAbove: 

ReplaceBelow: 

ReplaceWithBiomeBlocks: false

ReplaceWithSurfaceBlock: 

ReplaceWithGroundBlock: 

ReplaceWithStoneBlock: 

SmoothRadius: 0

SmoothHeightOffset: 0

SmoothStartTop: false

SmoothStartWood: false

SmoothingSurfaceBlock: 

SmoothingGroundBlock: 

BO3Group: 

IsSpawnPoint: false

DoReplaceBlocks: false


#######################################################################
# +-----------------------------------------------------------------+ #
# |                              Blocks                             | #
# +-----------------------------------------------------------------+ #
#######################################################################

Block(-8,14,8,STONE:5)
Block(-8,15,5,STONE:5)
Block(-8,15,6,STONE:5)
Block(-8,15,7,STONE:5)
Block(-8,15,8,STONE:5)
Block(-8,16,3,STONE:5)
Block(-8,16,4,STONE:5)
Block(-8,16,5,STONE:5)
Block(-8,16,6,STONE:5)
Block(-8,16,7,STONE:5)
Block(-8,16,8,STONE:5)
Block(-8,17,3,STONE:5)
Block(-8,17,4,STONE:5)
Block(-8,17,5,STONE:5)
Block(-8,17,6,STONE:5)
Block(-8,17,7,STONE:5)
Block(-8,17,8,STONE:5)
Block(-8,18,2,STONE:5)
Block(-8,18,3,STONE:5)
Block(-8,18,4,STONE:5)
Block(-8,18,5,STONE:5)
Block(-8,18,6,STONE:5)
Block(-8,18,7,STONE:5)
Block(-8,18,8,STONE:5)
Block(-8,19,1,STONE:5)
Block(-8,19,2,STONE:5)
Block(-8,19,3,STONE:5)
Block(-8,19,4,STONE:5)
Block(-8,19,5,STONE:5)
Block(-8,19,6,STONE:5)
Block(-8,19,7,STONE:5)
Block(-8,19,8,STONE:5)
Block(-8,20,1,STONE:5)
Block(-8,20,2,STONE:5)
Block(-8,20,3,STONE:5)
Block(-8,20,4,STONE:5)
Block(-8,20,5,STONE:5)
Block(-8,20,6,STONE:5)
Block(-8,20,7,STONE:5)
Block(-8,20,8,STONE:5)
Block(-8,21,0,STONE:5)
Block(-8,21,1,STONE:5)
Block(-8,21,2,STONE:5)
Block(-8,21,3,STONE:5)
Block(-8,21,4,STONE:5)
Block(-8,21,5,STONE:5)
Block(-8,21,6,STONE:5)
Block(-8,21,7,STONE:5)
Block(-8,21,8,STONE:5)
Block(-8,22,-1,STONE:5)
Block(-8,22,0,STONE:5)
Block(-8,22,1,STONE:5)
Block(-8,22,2,STONE:5)
Block(-8,22,3,STONE:5)
Block(-8,22,4,STONE:5)
Block(-8,22,5,STONE:5)
Block(-8,22,6,STONE:5)
Block(-8,22,7,STONE:5)
Block(-8,22,8,STONE:5)
Block(-8,23,-1,STONE:5)
Block(-8,23,0,STONE:5)
Block(-8,23,1,STONE:5)
Block(-8,23,2,STONE:5)
Block(-8,23,3,STONE:5)
Block(-8,23,4,STONE:5)
Block(-8,23,5,STONE:5)
Block(-8,23,6,STONE:5)
Block(-8,23,7,STONE:5)
Block(-8,23,8,STONE:5)
Block(-8,24,0,STONE:5)
Block(-8,24,1,STONE:5)
Block(-8,24,2,STONE:5)
Block(-8,24,3,STONE:5)
Block(-8,24,4,STONE:5)
Block(-8,24,5,STONE:5)
Block(-8,24,6,STONE:5)
Block(-8,24,7,STONE:5)
Block(-8,24,8,STONE:5)
Block(-8,25,1,STONE:5)
Block(-8,25,2,STONE:5)
Block(-8,25,3,STONE:5)
Block(-8,25,4,STONE:5)
Block(-8,25,5,STONE:5)
Block(-8,25,6,STONE:5)
Block(-8,25,7,STONE:5)
Block(-8,25,8,STONE:5)
Block(-8,26,0,STONE:5)
Block(-8,26,1,STONE:5)
Block(-8,26,2,STONE:5)
Block(-8,26,3,STONE:5)
Block(-8,26,4,STONE:5)
Block(-8,26,5,STONE:5)
Block(-8,26,6,STONE:5)
Block(-8,26,7,STONE:5)
Block(-8,26,8,STONE:5)
Block(-8,27,0,STONE:5)
Block(-8,27,1,STONE:5)
Block(-8,27,2,STONE:5)
Block(-8,27,3,STONE:5)
Block(-8,27,4,STONE:5)
Block(-8,27,5,STONE:5)
Block(-8,27,6,STONE:5)
Block(-8,27,7,STONE:5)
Block(-8,27,8,STONE:5)
Block(-8,28,-2,STONE:5)
Block(-8,28,-1,STONE:5)
Block(-8,28,0,STONE:5)
Block(-8,28,1,STONE:5)
Block(-8,28,2,STONE:5)
Block(-8,28,3,STONE:5)
Block(-8,28,4,STONE:5)
Block(-8,28,5,STONE:5)
Block(-8,28,6,STONE:5)
Block(-8,28,7,STONE:5)
Block(-8,28,8,STONE:5)
Block(-8,29,-2,STONE:5)
Block(-8,29,-1,STONE:5)
Block(-8,29,0,STONE:5)
Block(-8,29,1,STONE:5)
Block(-8,29,2,STONE:5)
Block(-8,29,3,STONE:5)
Block(-8,29,4,STONE:5)
Block(-8,29,5,STONE:5)
Block(-8,29,6,STONE:5)
Block(-8,29,7,STONE:5)
Block(-8,29,8,STONE:5)
Block(-8,30,-1,OBSIDIAN:0)
Block(-8,30,0,OBSIDIAN:0)
Block(-8,30,1,STONE:5)
Block(-8,30,2,STONE:5)
Block(-8,30,3,STONE:5)
Block(-8,30,4,STONE:5)
Block(-8,30,5,STONE:5)
Block(-8,30,6,STONE:5)
Block(-8,30,7,STONE:5)
Block(-8,30,8,STONE:5)
Block(-8,31,-1,OBSIDIAN:0)
Block(-8,31,0,OBSIDIAN:0)
Block(-8,31,1,OBSIDIAN:0)
Block(-8,31,2,OBSIDIAN:0)
Block(-8,31,3,STONE:5)
Block(-8,31,4,STONE:5)
Block(-8,31,5,STONE:5)
Block(-8,31,6,STONE:5)
Block(-8,31,7,STONE:5)
Block(-8,31,8,STONE:5)
Block(-8,32,-1,OBSIDIAN:0)
Block(-8,32,0,OBSIDIAN:0)
Block(-8,32,1,OBSIDIAN:0)
Block(-8,32,2,OBSIDIAN:0)
Block(-8,32,3,STONE:5)
Block(-8,32,4,STONE:5)
Block(-8,32,5,STONE:5)
Block(-8,32,6,STONE:5)
Block(-8,32,7,STONE:5)
Block(-8,32,8,STONE:5)
Block(-8,33,-1,OBSIDIAN:0)
Block(-8,33,0,OBSIDIAN:0)
Block(-8,33,1,OBSIDIAN:0)
Block(-8,33,2,OBSIDIAN:0)
Block(-8,33,3,STONE:5)
Block(-8,33,4,STONE:5)
Block(-8,33,5,STONE:5)
Block(-8,33,6,STONE:5)
Block(-8,33,7,STONE:5)
Block(-8,33,8,STONE:5)
Block(-8,34,0,OBSIDIAN:0)
Block(-8,34,1,STONE:5)
Block(-8,34,2,STONE:5)
Block(-8,34,3,STONE:5)
Block(-8,34,4,STONE:5)
Block(-8,34,5,STONE:5)
Block(-8,34,6,STONE:5)
Block(-8,34,7,STONE:5)
Block(-8,34,8,STONE:5)
Block(-8,35,1,STONE:5)
Block(-8,35,2,STONE:5)
Block(-8,35,3,STONE:5)
Block(-8,35,4,STONE:5)
Block(-8,35,5,STONE:5)
Block(-8,35,6,STONE:5)
Block(-8,35,7,STONE:5)
Block(-8,35,8,STONE:5)
Block(-8,36,7,STONE:5)
Block(-8,36,8,STONE:5)
Block(-7,16,5,STONE:5)
Block(-7,16,7,STONE:5)
Block(-7,16,8,STONE:5)
Block(-7,17,4,STONE:5)
Block(-7,17,5,STONE:5)
Block(-7,17,6,STONE:5)
Block(-7,17,7,STONE:5)
Block(-7,17,8,STONE:5)
Block(-7,18,3,STONE:5)
Block(-7,18,4,STONE:5)
Block(-7,18,5,STONE:5)
Block(-7,18,6,STONE:5)
Block(-7,18,7,STONE:5)
Block(-7,18,8,STONE:5)
Block(-7,19,2,STONE:5)
Block(-7,19,3,STONE:5)
Block(-7,19,4,STONE:5)
Block(-7,19,5,STONE:5)
Block(-7,19,6,STONE:5)
Block(-7,19,7,STONE:5)
Block(-7,19,8,STONE:5)
Block(-7,20,2,STONE:5)
Block(-7,20,3,STONE:5)
Block(-7,20,4,STONE:5)
Block(-7,20,5,STONE:5)
Block(-7,20,6,STONE:5)
Block(-7,20,7,STONE:5)
Block(-7,20,8,STONE:5)
Block(-7,21,3,STONE:5)
Block(-7,21,4,STONE:5)
Block(-7,21,5,STONE:5)
Block(-7,21,6,STONE:5)
Block(-7,21,7,STONE:5)
Block(-7,21,8,STONE:5)
Block(-7,22,2,STONE:5)
Block(-7,22,3,STONE:5)
Block(-7,22,4,STONE:5)
Block(-7,22,5,STONE:5)
Block(-7,22,6,STONE:5)
Block(-7,22,7,STONE:5)
Block(-7,22,8,STONE:5)
Block(-7,23,3,STONE:5)
Block(-7,23,4,STONE:5)
Block(-7,23,5,STONE:5)
Block(-7,23,6,STONE:5)
Block(-7,23,7,STONE:5)
Block(-7,23,8,STONE:5)
Block(-7,24,6,STONE:5)
Block(-7,24,7,STONE:5)
Block(-7,24,8,STONE:5)
Block(-7,25,6,STONE:5)
Block(-7,25,7,STONE:5)
Block(-7,25,8,STONE:5)
Block(-7,26,3,STONE:5)
Block(-7,26,4,STONE:5)
Block(-7,26,5,STONE:5)
Block(-7,26,6,STONE:5)
Block(-7,26,7,STONE:5)
Block(-7,26,8,STONE:5)
Block(-7,27,2,STONE:5)
Block(-7,27,3,STONE:5)
Block(-7,27,4,STONE:5)
Block(-7,27,5,STONE:5)
Block(-7,27,6,STONE:5)
Block(-7,27,7,STONE:5)
Block(-7,27,8,STONE:5)
Block(-7,28,-1,STONE:5)
Block(-7,28,0,STONE:5)
Block(-7,28,1,STONE:5)
Block(-7,28,2,STONE:5)
Block(-7,28,3,STONE:5)
Block(-7,28,4,STONE:5)
Block(-7,28,5,STONE:5)
Block(-7,28,6,STONE:5)
Block(-7,28,7,STONE:5)
Block(-7,28,8,STONE:5)
Block(-7,29,-1,STONE:5)
Block(-7,29,0,STONE:5)
Block(-7,29,1,STONE:5)
Block(-7,29,2,OBSIDIAN:0)
Block(-7,29,3,OBSIDIAN:0)
Block(-7,29,4,OBSIDIAN:0)
Block(-7,29,5,STONE:5)
Block(-7,29,6,STONE:5)
Block(-7,29,7,STONE:5)
Block(-7,29,8,STONE:5)
Block(-7,30,0,OBSIDIAN:0)
Block(-7,30,1,OBSIDIAN:0)
Block(-7,30,2,OBSIDIAN:0)
Block(-7,30,3,OBSIDIAN:0)
Block(-7,30,4,OBSIDIAN:0)
Block(-7,30,5,STONE:5)
Block(-7,30,6,STONE:5)
Block(-7,30,7,STONE:5)
Block(-7,30,8,STONE:5)
Block(-7,31,0,OBSIDIAN:0)
Block(-7,31,1,OBSIDIAN:0)
Block(-7,31,2,OBSIDIAN:0)
Block(-7,31,3,OBSIDIAN:0)
Block(-7,31,4,OBSIDIAN:0)
Block(-7,31,5,STONE:5)
Block(-7,31,6,STONE:5)
Block(-7,31,7,STONE:5)
Block(-7,31,8,STONE:5)
Block(-7,32,0,OBSIDIAN:0)
Block(-7,32,1,OBSIDIAN:0)
Block(-7,32,2,OBSIDIAN:0)
Block(-7,32,3,OBSIDIAN:0)
Block(-7,32,4,STONE:5)
Block(-7,32,5,STONE:5)
Block(-7,32,6,STONE:5)
Block(-7,32,7,STONE:5)
Block(-7,32,8,STONE:5)
Block(-7,33,0,OBSIDIAN:0)
Block(-7,33,1,OBSIDIAN:0)
Block(-7,33,2,OBSIDIAN:0)
Block(-7,33,3,OBSIDIAN:0)
Block(-7,33,4,STONE:5)
Block(-7,33,5,STONE:5)
Block(-7,33,6,STONE:5)
Block(-7,33,7,STONE:5)
Block(-7,33,8,STONE:5)
Block(-7,34,1,OBSIDIAN:0)
Block(-7,34,2,OBSIDIAN:0)
Block(-7,34,3,STONE:5)
Block(-7,34,4,STONE:5)
Block(-7,34,5,STONE:5)
Block(-7,34,6,STONE:5)
Block(-7,34,7,STONE:5)
Block(-7,34,8,STONE:5)
Block(-7,35,3,STONE:5)
Block(-7,35,4,STONE:5)
Block(-7,35,5,STONE:5)
Block(-7,35,6,STONE:5)
Block(-7,35,7,STONE:5)
Block(-7,35,8,STONE:5)
Block(-6,18,5,STONE:5)
Block(-6,18,6,STONE:5)
Block(-6,18,7,STONE:5)
Block(-6,18,8,STONE:5)
Block(-6,19,4,STONE:5)
Block(-6,19,5,STONE:5)
Block(-6,19,6,STONE:5)
Block(-6,19,7,STONE:5)
Block(-6,19,8,STONE:5)
Block(-6,20,4,STONE:5)
Block(-6,20,5,STONE:5)
Block(-6,20,6,STONE:5)
Block(-6,20,7,STONE:5)
Block(-6,20,8,STONE:5)
Block(-6,21,5,STONE:5)
Block(-6,21,6,STONE:5)
Block(-6,21,7,STONE:5)
Block(-6,21,8,STONE:5)
Block(-6,22,7,STONE:5)
Block(-6,22,8,STONE:5)
Block(-6,23,7,STONE:5)
Block(-6,23,8,STONE:5)
Block(-6,24,7,STONE:5)
Block(-6,24,8,STONE:5)
Block(-6,25,7,STONE:5)
Block(-6,25,8,STONE:5)
Block(-6,26,4,STONE:5)
Block(-6,26,5,STONE:5)
Block(-6,26,6,STONE:5)
Block(-6,26,7,STONE:5)
Block(-6,26,8,STONE:5)
Block(-6,27,3,STONE:5)
Block(-6,27,4,STONE:5)
Block(-6,27,5,STONE:5)
Block(-6,27,6,STONE:5)
Block(-6,27,7,STONE:5)
Block(-6,27,8,STONE:5)
Block(-6,28,1,STONE:5)
Block(-6,28,2,OBSIDIAN:0)
Block(-6,28,3,OBSIDIAN:0)
Block(-6,28,4,OBSIDIAN:0)
Block(-6,28,5,OBSIDIAN:0)
Block(-6,28,6,OBSIDIAN:0)
Block(-6,28,7,STONE:5)
Block(-6,28,8,STONE:5)
Block(-6,29,0,STONE:5)
Block(-6,29,1,OBSIDIAN:0)
Block(-6,29,2,OBSIDIAN:0)
Block(-6,29,3,OBSIDIAN:0)
Block(-6,29,4,OBSIDIAN:0)
Block(-6,29,5,OBSIDIAN:0)
Block(-6,29,6,OBSIDIAN:0)
Block(-6,29,7,STONE:5)
Block(-6,29,8,STONE:5)
Block(-6,30,1,OBSIDIAN:0)
Block(-6,30,2,OBSIDIAN:0)
Block(-6,30,3,OBSIDIAN:0)
Block(-6,30,4,OBSIDIAN:0)
Block(-6,30,5,OBSIDIAN:0)
Block(-6,30,6,OBSIDIAN:0)
Block(-6,30,7,STONE:5)
Block(-6,30,8,STONE:5)
Block(-6,31,1,OBSIDIAN:0)
Block(-6,31,2,OBSIDIAN:0)
Block(-6,31,3,OBSIDIAN:0)
Block(-6,31,4,OBSIDIAN:0)
Block(-6,31,5,OBSIDIAN:0)
Block(-6,31,6,STONE:5)
Block(-6,31,7,STONE:5)
Block(-6,31,8,STONE:5)
Block(-6,32,1,OBSIDIAN:0)
Block(-6,32,2,OBSIDIAN:0)
Block(-6,32,3,OBSIDIAN:0)
Block(-6,32,4,OBSIDIAN:0)
Block(-6,32,5,STONE:5)
Block(-6,32,6,STONE:5)
Block(-6,32,7,STONE:5)
Block(-6,32,8,STONE:5)
Block(-6,33,1,OBSIDIAN:0)
Block(-6,33,2,OBSIDIAN:0)
Block(-6,33,3,OBSIDIAN:0)
Block(-6,33,4,STONE:5)
Block(-6,33,5,STONE:5)
Block(-6,33,6,STONE:5)
Block(-6,33,7,STONE:5)
Block(-6,33,8,STONE:5)
Block(-6,34,3,STONE:5)
Block(-6,34,4,STONE:5)
Block(-6,34,5,STONE:5)
Block(-6,34,6,STONE:5)
Block(-6,34,7,STONE:5)
Block(-6,34,8,STONE:5)
Block(-6,35,8,STONE:5)
Block(-5,26,5,STONE:5)
Block(-5,26,6,STONE:5)
Block(-5,26,7,STONE:5)
Block(-5,26,8,STONE:5)
Block(-5,27,4,OBSIDIAN:0)
Block(-5,27,5,OBSIDIAN:0)
Block(-5,27,6,OBSIDIAN:0)
Block(-5,27,7,OBSIDIAN:0)
Block(-5,27,8,OBSIDIAN:0)
Block(-5,28,4,OBSIDIAN:0)
Block(-5,28,5,OBSIDIAN:0)
Block(-5,28,6,OBSIDIAN:0)
Block(-5,28,7,OBSIDIAN:0)
Block(-5,28,8,OBSIDIAN:0)
Block(-5,29,2,OBSIDIAN:0)
Block(-5,29,3,OBSIDIAN:0)
Block(-5,29,4,OBSIDIAN:0)
Block(-5,29,5,OBSIDIAN:0)
Block(-5,29,6,OBSIDIAN:0)
Block(-5,29,7,OBSIDIAN:0)
Block(-5,29,8,OBSIDIAN:0)
Block(-5,30,3,OBSIDIAN:0)
Block(-5,30,4,OBSIDIAN:0)
Block(-5,30,5,OBSIDIAN:0)
Block(-5,30,6,OBSIDIAN:0)
Block(-5,30,7,OBSIDIAN:0)
Block(-5,30,8,STONE:5)
Block(-5,31,3,OBSIDIAN:0)
Block(-5,31,4,OBSIDIAN:0)
Block(-5,31,5,OBSIDIAN:0)
Block(-5,31,6,OBSIDIAN:0)
Block(-5,31,7,STONE:5)
Block(-5,31,8,STONE:5)
Block(-5,32,4,OBSIDIAN:0)
Block(-5,32,5,STONE:5)
Block(-5,32,6,STONE:5)
Block(-5,32,7,STONE:5)
Block(-5,32,8,STONE:5)
Block(-5,33,6,STONE:5)
Block(-5,33,7,STONE:5)
Block(-5,33,8,STONE:5)
Block(-5,34,7,STONE:5)
Block(-5,34,8,STONE:5)
Block(-4,26,7,OBSIDIAN:0)
Block(-4,26,8,OBSIDIAN:0)
Block(-4,27,6,OBSIDIAN:0)
Block(-4,27,7,OBSIDIAN:0)
Block(-4,27,8,OBSIDIAN:0)
Block(-4,28,5,OBSIDIAN:0)
Block(-4,28,6,OBSIDIAN:0)
Block(-4,28,7,OBSIDIAN:0)
Block(-4,28,8,OBSIDIAN:0)
Block(-4,29,5,OBSIDIAN:0)
Block(-4,29,6,OBSIDIAN:0)
Block(-4,29,7,OBSIDIAN:0)
Block(-4,29,8,OBSIDIAN:0)
Block(-4,30,5,OBSIDIAN:0)
Block(-4,30,6,OBSIDIAN:0)
Block(-4,30,7,OBSIDIAN:0)
Block(-4,30,8,OBSIDIAN:0)
Block(-4,31,6,OBSIDIAN:0)
Block(-4,31,7,STONE:5)
Block(-4,31,8,STONE:5)
Block(-4,32,7,STONE:5)
Block(-4,32,8,STONE:5)
Block(-4,33,8,STONE:5)
Block(-3,27,7,OBSIDIAN:0)
Block(-3,27,8,OBSIDIAN:0)
Block(-3,28,7,OBSIDIAN:0)
Block(-3,28,8,OBSIDIAN:0)
Block(-3,29,7,OBSIDIAN:0)
Block(-3,29,8,OBSIDIAN:0)
Block(-3,30,7,OBSIDIAN:0)
Block(-3,30,8,OBSIDIAN:0)
Block(-3,31,8,STONE:5)
Block(-2,28,8,OBSIDIAN:0)
Block(-2,29,8,OBSIDIAN:0)

#######################################################################
# +-----------------------------------------------------------------+ #
# |                             Branches                            | #
# +-----------------------------------------------------------------+ #
#######################################################################

Branch(0,0,16,true,Amethyst_Desert_NormalC4R5,NORTH,100.0,0)

#######################################################################
# +-----------------------------------------------------------------+ #
# |                             Entities                            | #
# +-----------------------------------------------------------------+ #
#######################################################################


#######################################################################
# +-----------------------------------------------------------------+ #
# |                            Particles                            | #
# +-----------------------------------------------------------------+ #
#######################################################################


#######################################################################
# +-----------------------------------------------------------------+ #
# |                             Spawners                            | #
# +-----------------------------------------------------------------+ #
#######################################################################


#######################################################################
# +-----------------------------------------------------------------+ #
# |                             ModData                             | #
# +-----------------------------------------------------------------+ #
#######################################################################

