
#######################################################################
# +-----------------------------------------------------------------+ #
# |                            BO4 object                           | #
# +-----------------------------------------------------------------+ #
#######################################################################

Author: BO3 BulkEdit (by LanToaster)

Description: This Object was Created with BO3_BulkEdit

SettingsMode: WriteDisable


#######################################################################
# +-----------------------------------------------------------------+ #
# |                          Main settings                          | #
# +-----------------------------------------------------------------+ #
#######################################################################

Frequency: 100

SpawnHeight: highestBlock

UseCenterForHighestBlock: true

##############################
# Height Limits for the BO4. #
##############################

MinHeight: 0

MaxHeight: 255

InheritBO3: 

InheritBO3Rotation: NORTH

OverrideChildSettings: true

OverrideParentHeight: true

CanOverride: true

BranchFrequency: 0

BranchFrequencyGroup: 

MustBeBelowOther: false

MustBeInside: 

CannotBeInside: 

ReplacesBO3: 

MustBeInsideWorldBorders: false

CanSpawnOnWater: false

SpawnOnWaterOnly: false

SpawnUnderWater: false

SpawnAtWaterLevel: false

HeightOffset: 1

RemoveAir: true

ReplaceAbove: 

ReplaceBelow: COBBLESTONE:

ReplaceWithBiomeBlocks: true

ReplaceWithSurfaceBlock: GRASS

ReplaceWithGroundBlock: DIRT

ReplaceWithStoneBlock: STONE

SmoothRadius: 0

SmoothHeightOffset: 0

SmoothStartTop: false

SmoothStartWood: false

SmoothingSurfaceBlock: 

SmoothingGroundBlock: 

BO3Group: 

IsSpawnPoint: false

DoReplaceBlocks: true


#######################################################################
# +-----------------------------------------------------------------+ #
# |                              Blocks                             | #
# +-----------------------------------------------------------------+ #
#######################################################################

Block(2,-1,-6,SMOOTH_STAIRS:2)
Block(3,-1,-6,LEAVES:7)
Block(4,-1,-6,LEAVES:7)
RandomBlock(-2,-1,-5,SMOOTH_BRICK:1,10,SMOOTH_BRICK:2,10,COBBLESTONE,10,MOSSY_COBBLESTONE,10,SMOOTH_BRICK,100)
Block(-1,-1,-5,LEAVES:7)
Block(1,-1,-5,LEAVES:7)
RandomBlock(2,-1,-5,SMOOTH_BRICK:1,10,SMOOTH_BRICK:2,10,COBBLESTONE,10,MOSSY_COBBLESTONE,10,SMOOTH_BRICK,100)
Block(3,-1,-5,LEAVES:7)
RandomBlock(4,-1,-5,SMOOTH_BRICK:1,10,SMOOTH_BRICK:2,10,COBBLESTONE,10,MOSSY_COBBLESTONE,10,SMOOTH_BRICK,100)
RandomBlock(5,-1,-5,SMOOTH_BRICK:1,10,SMOOTH_BRICK:2,10,COBBLESTONE,10,MOSSY_COBBLESTONE,10,SMOOTH_BRICK,100)
RandomBlock(-5,-1,-4,SMOOTH_BRICK:1,10,SMOOTH_BRICK:2,10,COBBLESTONE,10,MOSSY_COBBLESTONE,10,SMOOTH_BRICK,100)
Block(-4,-1,-4,LEAVES:7)
RandomBlock(-2,-1,-4,SMOOTH_BRICK:1,10,SMOOTH_BRICK:2,10,COBBLESTONE,10,MOSSY_COBBLESTONE,10,SMOOTH_BRICK,100)
Block(-1,-1,-4,LEAVES:7)
Block(0,-1,-4,LEAVES:7)
Block(1,-1,-4,LEAVES:7)
Block(2,-1,-4,LEAVES:7)
Block(3,-1,-4,LEAVES:7)
Block(4,-1,-4,LEAVES:7)
RandomBlock(5,-1,-4,SMOOTH_BRICK:1,10,SMOOTH_BRICK:2,10,COBBLESTONE,10,MOSSY_COBBLESTONE,10,SMOOTH_BRICK,100)
Block(6,-1,-4,LEAVES:7)
Block(-6,-1,-3,LEAVES:7)
RandomBlock(-5,-1,-3,SMOOTH_BRICK:1,10,SMOOTH_BRICK:2,10,COBBLESTONE,10,MOSSY_COBBLESTONE,10,SMOOTH_BRICK,100)
Block(-4,-1,-3,LEAVES:7)
Block(-3,-1,-3,LEAVES:7)
RandomBlock(-2,-1,-3,SMOOTH_BRICK:1,10,SMOOTH_BRICK:2,10,COBBLESTONE,10,MOSSY_COBBLESTONE,10,SMOOTH_BRICK,100)
Block(-1,-1,-3,LEAVES:7)
RandomBlock(0,-1,-3,SMOOTH_BRICK:1,10,SMOOTH_BRICK:2,10,COBBLESTONE,10,MOSSY_COBBLESTONE,10,SMOOTH_BRICK,100)
RandomBlock(1,-1,-3,SMOOTH_BRICK:1,10,SMOOTH_BRICK:2,10,COBBLESTONE,10,MOSSY_COBBLESTONE,10,SMOOTH_BRICK,100)
RandomBlock(2,-1,-3,SMOOTH_BRICK:1,10,SMOOTH_BRICK:2,10,COBBLESTONE,10,MOSSY_COBBLESTONE,10,SMOOTH_BRICK,100)
Block(3,-1,-3,LEAVES:7)
Block(4,-1,-3,LEAVES:7)
RandomBlock(5,-1,-3,SMOOTH_BRICK:1,10,SMOOTH_BRICK:2,10,COBBLESTONE,10,MOSSY_COBBLESTONE,10,SMOOTH_BRICK,100)
Block(6,-1,-3,LEAVES:7)
Block(-6,-1,-2,LEAVES:7)
RandomBlock(-5,-1,-2,SMOOTH_BRICK:1,10,SMOOTH_BRICK:2,10,COBBLESTONE,10,MOSSY_COBBLESTONE,10,SMOOTH_BRICK,100)
RandomBlock(-4,-1,-2,SMOOTH_BRICK:1,10,SMOOTH_BRICK:2,10,COBBLESTONE,10,MOSSY_COBBLESTONE,10,SMOOTH_BRICK,100)
RandomBlock(-3,-1,-2,SMOOTH_BRICK:1,10,SMOOTH_BRICK:2,10,COBBLESTONE,10,MOSSY_COBBLESTONE,10,SMOOTH_BRICK,100)
RandomBlock(-2,-1,-2,SMOOTH_BRICK:1,10,SMOOTH_BRICK:2,10,COBBLESTONE,10,MOSSY_COBBLESTONE,10,SMOOTH_BRICK,100)
Block(-1,-1,-2,LEAVES:7)
RandomBlock(0,-1,-2,SMOOTH_BRICK:1,10,SMOOTH_BRICK:2,10,COBBLESTONE,10,MOSSY_COBBLESTONE,10,SMOOTH_BRICK,100)
RandomBlock(1,-1,-2,SMOOTH_BRICK:1,10,SMOOTH_BRICK:2,10,COBBLESTONE,10,MOSSY_COBBLESTONE,10,SMOOTH_BRICK,100)
RandomBlock(2,-1,-2,SMOOTH_BRICK:1,10,SMOOTH_BRICK:2,10,COBBLESTONE,10,MOSSY_COBBLESTONE,10,SMOOTH_BRICK,100)
RandomBlock(5,-1,-2,SMOOTH_BRICK:1,10,SMOOTH_BRICK:2,10,COBBLESTONE,10,MOSSY_COBBLESTONE,10,SMOOTH_BRICK,100)
Block(6,-1,-2,LEAVES:7)
Block(-6,-1,-1,LEAVES:7)
Block(-4,-1,-1,LEAVES:15)
Block(-3,-1,-1,LEAVES:15)
RandomBlock(-2,-1,-1,SMOOTH_BRICK:1,10,SMOOTH_BRICK:2,10,COBBLESTONE,10,MOSSY_COBBLESTONE,10,SMOOTH_BRICK,100)
RandomBlock(0,-1,-1,SMOOTH_BRICK:1,10,SMOOTH_BRICK:2,10,COBBLESTONE,10,MOSSY_COBBLESTONE,10,SMOOTH_BRICK,100)
RandomBlock(1,-1,-1,SMOOTH_BRICK:1,10,SMOOTH_BRICK:2,10,COBBLESTONE,10,MOSSY_COBBLESTONE,10,SMOOTH_BRICK,100)
RandomBlock(2,-1,-1,SMOOTH_BRICK:1,10,SMOOTH_BRICK:2,10,COBBLESTONE,10,MOSSY_COBBLESTONE,10,SMOOTH_BRICK,100)
Block(4,-1,-1,LEAVES:7)
RandomBlock(5,-1,-1,SMOOTH_BRICK:1,10,SMOOTH_BRICK:2,10,COBBLESTONE,10,MOSSY_COBBLESTONE,10,SMOOTH_BRICK,100)
Block(6,-1,-1,LEAVES:7)
Block(-3,-1,0,LEAVES:7)
RandomBlock(-2,-1,0,SMOOTH_BRICK:1,10,SMOOTH_BRICK:2,10,COBBLESTONE,10,MOSSY_COBBLESTONE,10,SMOOTH_BRICK,100)
Block(4,-1,0,LEAVES:7)
RandomBlock(5,-1,0,SMOOTH_BRICK:1,10,SMOOTH_BRICK:2,10,COBBLESTONE,10,MOSSY_COBBLESTONE,10,SMOOTH_BRICK,100)
Block(-5,-1,1,STEP:5)
RandomBlock(-2,-1,1,SMOOTH_BRICK:1,10,SMOOTH_BRICK:2,10,COBBLESTONE,10,MOSSY_COBBLESTONE,10,SMOOTH_BRICK,100)
RandomBlock(-1,-1,1,SMOOTH_BRICK:1,10,SMOOTH_BRICK:2,10,COBBLESTONE,10,MOSSY_COBBLESTONE,10,SMOOTH_BRICK,100)
RandomBlock(0,-1,1,SMOOTH_BRICK:1,10,SMOOTH_BRICK:2,10,COBBLESTONE,10,MOSSY_COBBLESTONE,10,SMOOTH_BRICK,100)
RandomBlock(1,-1,1,SMOOTH_BRICK:1,10,SMOOTH_BRICK:2,10,COBBLESTONE,10,MOSSY_COBBLESTONE,10,SMOOTH_BRICK,100)
RandomBlock(2,-1,1,SMOOTH_BRICK:1,10,SMOOTH_BRICK:2,10,COBBLESTONE,10,MOSSY_COBBLESTONE,10,SMOOTH_BRICK,100)
RandomBlock(5,-1,1,SMOOTH_BRICK:1,10,SMOOTH_BRICK:2,10,COBBLESTONE,10,MOSSY_COBBLESTONE,10,SMOOTH_BRICK,100)
Block(-7,-1,2,STEP:5)
Block(-6,-1,2,STEP:5)
Block(-5,-1,2,STEP:5)
Block(-2,-1,2,LEAVES:7)
Block(-1,-1,2,LEAVES:7)
Block(0,-1,2,LEAVES:7)
Block(-5,-1,3,STEP:5)
Block(1,-1,3,LEAVES:7)
Block(2,-1,3,LEAVES:7)
Block(3,-1,3,LEAVES:7)
Block(4,-1,3,LEAVES:7)
Block(-6,-1,4,STEP:5)
Block(-5,-1,4,STEP:5)
Block(-4,-1,4,STEP:5)
Block(-3,-1,4,STEP:5)
RandomBlock(-1,-1,4,SMOOTH_BRICK:1,10,SMOOTH_BRICK:2,10,COBBLESTONE,10,MOSSY_COBBLESTONE,10,SMOOTH_BRICK,100)
RandomBlock(0,-1,4,SMOOTH_BRICK:1,10,SMOOTH_BRICK:2,10,COBBLESTONE,10,MOSSY_COBBLESTONE,10,SMOOTH_BRICK,100)
RandomBlock(1,-1,4,SMOOTH_BRICK:1,10,SMOOTH_BRICK:2,10,COBBLESTONE,10,MOSSY_COBBLESTONE,10,SMOOTH_BRICK,100)
RandomBlock(2,-1,4,SMOOTH_BRICK:1,10,SMOOTH_BRICK:2,10,COBBLESTONE,10,MOSSY_COBBLESTONE,10,SMOOTH_BRICK,100)
RandomBlock(3,-1,4,SMOOTH_BRICK:1,10,SMOOTH_BRICK:2,10,COBBLESTONE,10,MOSSY_COBBLESTONE,10,SMOOTH_BRICK,100)
Block(4,-1,4,LEAVES:7)
Block(0,-1,5,LEAVES:7)
Block(1,-1,5,LEAVES:7)
Block(2,-1,5,LEAVES:7)
RandomBlock(2,0,-5,SMOOTH_BRICK:1,10,SMOOTH_BRICK:2,10,COBBLESTONE,10,MOSSY_COBBLESTONE,10,SMOOTH_BRICK,100)
Block(-2,0,-4,STEP:5)
Block(2,0,-4,LEAVES:7)
Block(5,0,-4,STEP:5)
Block(-4,0,-3,LEAVES:7)
Block(-3,0,-3,LEAVES:7)
RandomBlock(-2,0,-3,SMOOTH_BRICK:1,10,SMOOTH_BRICK:2,10,COBBLESTONE,10,MOSSY_COBBLESTONE,10,SMOOTH_BRICK,100)
Block(-1,0,-3,LEAVES:7)
Block(0,0,-3,STEP:5)
Block(1,0,-3,SMOOTH_STAIRS:2)
Block(2,0,-3,LEAVES:7)
Block(3,0,-3,LEAVES:7)
RandomBlock(5,0,-3,SMOOTH_BRICK:1,10,SMOOTH_BRICK:2,10,COBBLESTONE,10,MOSSY_COBBLESTONE,10,SMOOTH_BRICK,100)
Block(6,0,-3,LEAVES:7)
Block(-4,0,-2,STEP:5)
RandomBlock(-3,0,-2,SMOOTH_BRICK:1,10,SMOOTH_BRICK:2,10,COBBLESTONE,10,MOSSY_COBBLESTONE,10,SMOOTH_BRICK,100)
RandomBlock(-2,0,-2,SMOOTH_BRICK:1,10,SMOOTH_BRICK:2,10,COBBLESTONE,10,MOSSY_COBBLESTONE,10,SMOOTH_BRICK,100)
Block(0,0,-2,LEAVES:7)
RandomBlock(1,0,-2,SMOOTH_BRICK:1,10,SMOOTH_BRICK:2,10,COBBLESTONE,10,MOSSY_COBBLESTONE,10,SMOOTH_BRICK,100)
Block(2,0,-2,LEAVES:7)
RandomBlock(5,0,-2,SMOOTH_BRICK:1,10,SMOOTH_BRICK:2,10,COBBLESTONE,10,MOSSY_COBBLESTONE,10,SMOOTH_BRICK,100)
Block(6,0,-2,LEAVES:7)
Block(-3,0,-1,LEAVES:7)
Block(-2,0,-1,DOUBLE_STEP:5)
Block(5,0,-1,DOUBLE_STEP:5)
Block(-2,0,0,STEP:5)
Block(5,0,0,STEP:5)
Block(-2,0,1,STEP:5)
RandomBlock(-1,0,1,SMOOTH_BRICK:1,10,SMOOTH_BRICK:2,10,COBBLESTONE,10,MOSSY_COBBLESTONE,10,SMOOTH_BRICK,100)
RandomBlock(0,0,1,SMOOTH_BRICK:1,10,SMOOTH_BRICK:2,10,COBBLESTONE,10,MOSSY_COBBLESTONE,10,SMOOTH_BRICK,100)
Block(1,0,1,STEP:5)
Block(0,0,2,LEAVES:7)
Block(0,0,4,STEP:5)
Block(1,0,4,DOUBLE_STEP:5)
Block(2,0,4,DOUBLE_STEP:5)
Block(1,0,5,LEAVES:7)
RandomBlock(2,1,-5,SMOOTH_BRICK:1,10,SMOOTH_BRICK:2,10,COBBLESTONE,10,MOSSY_COBBLESTONE,10,SMOOTH_BRICK,100)
RandomBlock(5,1,-3,SMOOTH_BRICK:1,10,SMOOTH_BRICK:2,10,COBBLESTONE,10,MOSSY_COBBLESTONE,10,SMOOTH_BRICK,100)
RandomBlock(-2,1,-2,SMOOTH_BRICK:1,10,SMOOTH_BRICK:2,10,COBBLESTONE,10,MOSSY_COBBLESTONE,10,SMOOTH_BRICK,100)
RandomBlock(1,1,-2,SMOOTH_BRICK:1,10,SMOOTH_BRICK:2,10,COBBLESTONE,10,MOSSY_COBBLESTONE,10,SMOOTH_BRICK,100)
RandomBlock(5,1,-2,SMOOTH_BRICK:1,10,SMOOTH_BRICK:2,10,COBBLESTONE,10,MOSSY_COBBLESTONE,10,SMOOTH_BRICK,100)
Block(6,1,-2,LEAVES:7)
Block(0,1,1,STEP:5)
Block(1,2,-3,SMOOTH_STAIRS:6)
RandomBlock(-2,2,-2,SMOOTH_BRICK:1,10,SMOOTH_BRICK:2,10,COBBLESTONE,10,MOSSY_COBBLESTONE,10,SMOOTH_BRICK,100)
Block(-1,2,-2,SMOOTH_STAIRS:5)
Block(0,2,-2,SMOOTH_STAIRS:4)
RandomBlock(1,2,-2,SMOOTH_BRICK:1,10,SMOOTH_BRICK:2,10,COBBLESTONE,10,MOSSY_COBBLESTONE,10,SMOOTH_BRICK,100)
Block(2,2,-2,SMOOTH_STAIRS:5)
Block(4,2,-2,SMOOTH_STAIRS:4)
RandomBlock(5,2,-2,SMOOTH_BRICK:1,10,SMOOTH_BRICK:2,10,COBBLESTONE,10,MOSSY_COBBLESTONE,10,SMOOTH_BRICK,100)
Block(1,2,-1,SMOOTH_STAIRS:7)
Block(1,3,-3,STEP:5)
Block(-1,3,-2,STEP:5)
Block(0,3,-2,STEP:5)
RandomBlock(1,3,-2,SMOOTH_BRICK:1,10,SMOOTH_BRICK:2,10,COBBLESTONE,10,MOSSY_COBBLESTONE,10,SMOOTH_BRICK,100)
Block(2,3,-2,STEP:5)
Block(3,3,-2,STEP:5)
Block(4,3,-2,STEP:5)
RandomBlock(5,3,-2,SMOOTH_BRICK:1,10,SMOOTH_BRICK:2,10,COBBLESTONE,10,MOSSY_COBBLESTONE,10,SMOOTH_BRICK,100)
Block(1,3,-1,STEP:5)

#######################################################################
# +-----------------------------------------------------------------+ #
# |                             Branches                            | #
# +-----------------------------------------------------------------+ #
#######################################################################


#######################################################################
# +-----------------------------------------------------------------+ #
# |                             Entities                            | #
# +-----------------------------------------------------------------+ #
#######################################################################


#######################################################################
# +-----------------------------------------------------------------+ #
# |                            Particles                            | #
# +-----------------------------------------------------------------+ #
#######################################################################


#######################################################################
# +-----------------------------------------------------------------+ #
# |                             Spawners                            | #
# +-----------------------------------------------------------------+ #
#######################################################################


#######################################################################
# +-----------------------------------------------------------------+ #
# |                             ModData                             | #
# +-----------------------------------------------------------------+ #
#######################################################################

