
#######################################################################
# +-----------------------------------------------------------------+ #
# |                            BO3 object                           | #
# +-----------------------------------------------------------------+ #
#######################################################################

Author: NLBlackHeavenNL

Description: No description given

Version: 3

SettingsMode: WriteWithoutComments


#######################################################################
# +-----------------------------------------------------------------+ #
# |                          Main settings                          | #
# +-----------------------------------------------------------------+ #
#######################################################################

Tree: true

Frequency: 1

Rarity: 100.0

RotateRandomly: false

SpawnHeight: highestSolidBlock

SpawnHeightOffset: -1

SpawnHeightVariance: 0

##############################
# Height Limits for the BO3. #
##############################

MinHeight: 0

MaxHeight: 255

######################
# Extrusion settings #
######################

ExtrudeMode: None

ExtrudeThroughBlocks: AIR

MaxBranchDepth: 10

ExcludedBiomes: All


#######################################################################
# +-----------------------------------------------------------------+ #
# |                      Source block settings                      | #
# +-----------------------------------------------------------------+ #
#######################################################################

SourceBlocks: AIR,GRASS,DIRT,biomesoplenty:dirt,dynamictrees:leaves1

MaxPercentageOutsideSourceBlock: 0

OutsideSourceBlock: placeAnyway

DoReplaceBlocks: true

IsOTGPlus: false


#######################################################################
# +-----------------------------------------------------------------+ #
# |                              Blocks                             | #
# +-----------------------------------------------------------------+ #
#######################################################################

Block(-6,6,0,dynamictrees:leaves1:4)
Block(-6,6,1,dynamictrees:leaves1:4)
Block(-5,5,0,dynamictrees:leaves1:4)
Block(-5,5,1,dynamictrees:leaves1:4)
Block(-5,6,-1,dynamictrees:leaves1:4)
Block(-5,6,0,dynamictrees:leaves1:5)
Block(-5,6,1,dynamictrees:leaves1:5)
Block(-5,6,2,dynamictrees:leaves1:4)
Block(-5,7,0,dynamictrees:leaves1:4)
Block(-5,7,1,dynamictrees:leaves1:4)
Block(-5,7,4,dynamictrees:leaves1:4)
Block(-5,7,5,dynamictrees:leaves1:4)
Block(-4,5,-1,dynamictrees:leaves1:4)
Block(-4,5,2,dynamictrees:leaves1:4)
Block(-4,6,-2,dynamictrees:leaves1:4)
Block(-4,6,-1,dynamictrees:leaves1:5)
Block(-4,6,0,dynamictrees:leaves1:6)
Block(-4,6,1,dynamictrees:leaves1:7)
Block(-4,6,2,dynamictrees:leaves1:5)
Block(-4,6,3,dynamictrees:leaves1:4)
Block(-4,6,4,dynamictrees:leaves1:4)
Block(-4,6,5,dynamictrees:leaves1:4)
Block(-4,7,-1,dynamictrees:leaves1:4)
Block(-4,7,0,dynamictrees:leaves1:5)
Block(-4,7,1,dynamictrees:leaves1:5)
Block(-4,7,2,dynamictrees:leaves1:4)
Block(-4,7,3,dynamictrees:leaves1:4)
Block(-4,7,4,dynamictrees:leaves1:5)
Block(-4,7,5,dynamictrees:leaves1:5)
Block(-4,7,6,dynamictrees:leaves1:4)
Block(-4,7,7,dynamictrees:leaves1:4)
Block(-4,7,8,dynamictrees:leaves1:4)
Block(-4,8,0,dynamictrees:leaves1:4)
Block(-4,8,1,dynamictrees:leaves1:4)
Block(-4,8,4,dynamictrees:leaves1:4)
Block(-4,8,5,dynamictrees:leaves1:4)
Block(-4,12,0,dynamictrees:leaves1:4)
Block(-4,12,1,dynamictrees:leaves1:4)
Block(-4,12,2,dynamictrees:leaves1:4)
Block(-3,5,-2,dynamictrees:leaves1:4)
Block(-3,6,-3,dynamictrees:leaves1:4)
Block(-3,6,-2,dynamictrees:leaves1:5)
Block(-3,6,-1,dynamictrees:leaves1:6)
Block(-3,6,0,dynamictrees:leaves1:7)
Block(-3,6,1,dynamictrees:darkoakbranch)
Block(-3,6,3,dynamictrees:leaves1:4)
Block(-3,6,6,dynamictrees:leaves1:4)
Block(-3,6,7,dynamictrees:leaves1:4)
Block(-3,6,8,dynamictrees:leaves1:4)
Block(-3,7,-2,dynamictrees:leaves1:4)
Block(-3,7,-1,dynamictrees:leaves1:5)
Block(-3,7,0,dynamictrees:leaves1:5)
Block(-3,7,1,dynamictrees:leaves1:7)
Block(-3,7,2,dynamictrees:leaves1:5)
Block(-3,7,3,dynamictrees:leaves1:5)
Block(-3,7,4,dynamictrees:leaves1:7)
Block(-3,7,5,dynamictrees:leaves1:6)
Block(-3,7,6,dynamictrees:leaves1:5)
Block(-3,7,7,dynamictrees:leaves1:5)
Block(-3,7,8,dynamictrees:leaves1:5)
Block(-3,7,9,dynamictrees:leaves1:4)
Block(-3,8,-1,dynamictrees:leaves1:4)
Block(-3,8,0,dynamictrees:leaves1:4)
Block(-3,8,1,dynamictrees:leaves1:5)
Block(-3,8,2,dynamictrees:leaves1:4)
Block(-3,8,3,dynamictrees:leaves1:4)
Block(-3,8,4,dynamictrees:leaves1:5)
Block(-3,8,5,dynamictrees:leaves1:5)
Block(-3,8,6,dynamictrees:leaves1:4)
Block(-3,8,7,dynamictrees:leaves1:4)
Block(-3,8,8,dynamictrees:leaves1:4)
Block(-3,9,1,dynamictrees:leaves1:4)
Block(-3,9,4,dynamictrees:leaves1:4)
Block(-3,9,5,dynamictrees:leaves1:4)
Block(-3,11,0,dynamictrees:leaves1:4)
Block(-3,11,1,dynamictrees:leaves1:4)
Block(-3,11,2,dynamictrees:leaves1:4)
Block(-3,12,-1,dynamictrees:leaves1:4)
Block(-3,12,0,dynamictrees:leaves1:5)
Block(-3,12,1,dynamictrees:leaves1:5)
Block(-3,12,2,dynamictrees:leaves1:5)
Block(-3,12,3,dynamictrees:leaves1:4)
Block(-3,13,0,dynamictrees:leaves1:4)
Block(-3,13,1,dynamictrees:leaves1:4)
Block(-3,13,2,dynamictrees:leaves1:4)
Block(-2,5,-2,dynamictrees:leaves1:4)
Block(-2,6,-3,dynamictrees:leaves1:4)
Block(-2,6,-2,dynamictrees:leaves1:5)
Block(-2,6,-1,dynamictrees:leaves1:7)
Block(-2,6,0,dynamictrees:darkoakbranch)
Block(-2,6,1,dynamictrees:darkoakbranch:1)
Block(-2,6,2,dynamictrees:darkoakbranch)
Block(-2,6,9,dynamictrees:leaves1:4)
Block(-2,7,-2,dynamictrees:leaves1:4)
Block(-2,7,-1,dynamictrees:leaves1:5)
Block(-2,7,4,dynamictrees:darkoakbranch)
Block(-2,7,5,dynamictrees:leaves1:7)
Block(-2,7,6,dynamictrees:leaves1:6)
Block(-2,7,7,dynamictrees:leaves1:7)
Block(-2,7,8,dynamictrees:leaves1:6)
Block(-2,7,9,dynamictrees:leaves1:5)
Block(-2,7,10,dynamictrees:leaves1:4)
Block(-2,8,-1,dynamictrees:leaves1:4)
Block(-2,8,5,dynamictrees:leaves1:5)
Block(-2,8,6,dynamictrees:leaves1:5)
Block(-2,8,7,dynamictrees:leaves1:5)
Block(-2,8,8,dynamictrees:leaves1:5)
Block(-2,8,9,dynamictrees:leaves1:4)
Block(-2,9,5,dynamictrees:leaves1:4)
Block(-2,9,6,dynamictrees:leaves1:4)
Block(-2,9,7,dynamictrees:leaves1:4)
Block(-2,9,8,dynamictrees:leaves1:4)
Block(-2,11,-1,dynamictrees:leaves1:4)
Block(-2,11,3,dynamictrees:leaves1:4)
Block(-2,12,-2,dynamictrees:leaves1:4)
Block(-2,12,-1,dynamictrees:leaves1:5)
Block(-2,12,0,dynamictrees:leaves1:6)
Block(-2,12,1,dynamictrees:leaves1:7)
Block(-2,12,2,dynamictrees:leaves1:6)
Block(-2,12,3,dynamictrees:leaves1:5)
Block(-2,12,4,dynamictrees:leaves1:4)
Block(-2,13,-1,dynamictrees:leaves1:4)
Block(-2,13,0,dynamictrees:leaves1:5)
Block(-2,13,1,dynamictrees:leaves1:5)
Block(-2,13,2,dynamictrees:leaves1:5)
Block(-2,13,3,dynamictrees:leaves1:4)
Block(-2,14,0,dynamictrees:leaves1:4)
Block(-2,14,1,dynamictrees:leaves1:4)
Block(-2,14,2,dynamictrees:leaves1:4)
Block(-1,0,0,GRASS:0)
Block(-1,0,1,GRASS:0)
Block(-1,0,2,GRASS:0)
Block(-1,1,0,dynamictrees:trunkshell:5)
Block(-1,1,1,dynamictrees:trunkshell:6)
Block(-1,1,2,dynamictrees:trunkshell:7)
Block(-1,2,0,dynamictrees:trunkshell:5)
Block(-1,2,1,dynamictrees:trunkshell:6)
Block(-1,2,2,dynamictrees:trunkshell:7)
Block(-1,3,0,dynamictrees:trunkshell:5)
Block(-1,3,1,dynamictrees:trunkshell:6)
Block(-1,3,2,dynamictrees:trunkshell:7)
Block(-1,4,0,dynamictrees:trunkshell:5)
Block(-1,4,1,dynamictrees:trunkshell:6)
Block(-1,4,2,dynamictrees:trunkshell:7)
Block(-1,5,-1,dynamictrees:leaves1:4)
Block(-1,5,0,dynamictrees:trunkshell:5)
Block(-1,5,1,dynamictrees:trunkshell:6)
Block(-1,5,2,dynamictrees:trunkshell:7)
Block(-1,6,-2,dynamictrees:leaves1:4)
Block(-1,6,-1,dynamictrees:leaves1:5)
Block(-1,6,0,dynamictrees:trunkshell:5)
Block(-1,6,1,dynamictrees:darkoakbranch:2)
Block(-1,6,2,dynamictrees:trunkshell:7)
Block(-1,6,9,dynamictrees:leaves1:4)
Block(-1,7,-1,dynamictrees:leaves1:4)
Block(-1,7,3,dynamictrees:darkoakbranch:2)
Block(-1,7,4,dynamictrees:darkoakbranch:2)
Block(-1,7,5,dynamictrees:darkoakbranch:1)
Block(-1,7,6,dynamictrees:darkoakbranch:1)
Block(-1,7,7,dynamictrees:darkoakbranch)
Block(-1,7,8,dynamictrees:leaves1:7)
Block(-1,7,9,dynamictrees:leaves1:5)
Block(-1,7,10,dynamictrees:leaves1:4)
Block(-1,8,5,dynamictrees:leaves1:5)
Block(-1,8,6,dynamictrees:leaves1:5)
Block(-1,8,7,dynamictrees:leaves1:7)
Block(-1,8,8,dynamictrees:leaves1:5)
Block(-1,8,9,dynamictrees:leaves1:4)
Block(-1,9,5,dynamictrees:leaves1:4)
Block(-1,9,6,dynamictrees:leaves1:4)
Block(-1,9,7,dynamictrees:leaves1:5)
Block(-1,9,8,dynamictrees:leaves1:4)
Block(-1,10,7,dynamictrees:leaves1:4)
Block(-1,11,-1,dynamictrees:leaves1:4)
Block(-1,11,3,dynamictrees:leaves1:5)
Block(-1,11,4,dynamictrees:leaves1:4)
Block(-1,12,-2,dynamictrees:leaves1:4)
Block(-1,12,-1,dynamictrees:leaves1:5)
Block(-1,12,0,dynamictrees:leaves1:7)
Block(-1,12,1,dynamictrees:darkoakbranch)
Block(-1,12,2,dynamictrees:leaves1:7)
Block(-1,12,3,dynamictrees:leaves1:5)
Block(-1,12,4,dynamictrees:leaves1:4)
Block(-1,13,-1,dynamictrees:leaves1:4)
Block(-1,13,0,dynamictrees:leaves1:5)
Block(-1,13,1,dynamictrees:leaves1:7)
Block(-1,13,2,dynamictrees:leaves1:5)
Block(-1,13,3,dynamictrees:leaves1:4)
Block(-1,14,0,dynamictrees:leaves1:4)
Block(-1,14,1,dynamictrees:leaves1:5)
Block(-1,14,2,dynamictrees:leaves1:4)
Block(-1,15,1,dynamictrees:leaves1:4)
Block(0,0,0,GRASS:0)
Block(0,0,1,dynamictrees:rootydirt:0)
Block(0,0,2,GRASS:0)
Block(0,1,0,dynamictrees:trunkshell)
Block(0,1,1,dynamictrees:darkoakbranch:11)
Block(0,1,2,dynamictrees:trunkshell:0)
Block(0,2,0,dynamictrees:trunkshell)
Block(0,2,1,dynamictrees:darkoakbranch:10)
Block(0,2,2,dynamictrees:trunkshell:0)
Block(0,3,0,dynamictrees:trunkshell)
Block(0,3,1,dynamictrees:darkoakbranch:9)
Block(0,3,2,dynamictrees:trunkshell:0)
Block(0,4,0,dynamictrees:trunkshell)
Block(0,4,1,dynamictrees:darkoakbranch:8)
Block(0,4,2,dynamictrees:trunkshell:0)
Block(0,5,0,dynamictrees:trunkshell)
Block(0,5,1,dynamictrees:darkoakbranch:8)
Block(0,5,2,dynamictrees:trunkshell:0)
Block(0,6,-1,dynamictrees:leaves1:4)
Block(0,6,0,dynamictrees:trunkshell)
Block(0,6,1,dynamictrees:darkoakbranch:8)
Block(0,6,2,dynamictrees:trunkshell:0)
Block(0,6,9,dynamictrees:leaves1:4)
Block(0,7,1,dynamictrees:darkoakbranch:7)
Block(0,7,2,dynamictrees:darkoakbranch:4)
Block(0,7,3,dynamictrees:darkoakbranch:4)
Block(0,7,5,dynamictrees:darkoakbranch)
Block(0,7,7,dynamictrees:leaves1:7)
Block(0,7,8,dynamictrees:leaves1:6)
Block(0,7,9,dynamictrees:leaves1:5)
Block(0,7,10,dynamictrees:leaves1:4)
Block(0,8,1,dynamictrees:darkoakbranch:5)
Block(0,8,5,dynamictrees:leaves1:7)
Block(0,8,6,dynamictrees:leaves1:5)
Block(0,8,7,dynamictrees:leaves1:5)
Block(0,8,8,dynamictrees:leaves1:5)
Block(0,8,9,dynamictrees:leaves1:4)
Block(0,9,1,dynamictrees:darkoakbranch:2)
Block(0,9,5,dynamictrees:leaves1:5)
Block(0,9,6,dynamictrees:leaves1:4)
Block(0,9,7,dynamictrees:leaves1:4)
Block(0,9,8,dynamictrees:leaves1:4)
Block(0,10,1,dynamictrees:darkoakbranch:2)
Block(0,10,4,dynamictrees:leaves1:4)
Block(0,10,5,dynamictrees:leaves1:4)
Block(0,11,-1,dynamictrees:leaves1:4)
Block(0,11,1,dynamictrees:darkoakbranch:2)
Block(0,11,2,dynamictrees:darkoakbranch)
Block(0,11,3,dynamictrees:leaves1:7)
Block(0,11,4,dynamictrees:leaves1:5)
Block(0,11,5,dynamictrees:leaves1:4)
Block(0,12,-2,dynamictrees:leaves1:4)
Block(0,12,-1,dynamictrees:leaves1:5)
Block(0,12,0,dynamictrees:leaves1:6)
Block(0,12,1,dynamictrees:darkoakbranch:1)
Block(0,12,2,dynamictrees:leaves1:7)
Block(0,12,3,dynamictrees:leaves1:5)
Block(0,12,4,dynamictrees:leaves1:4)
Block(0,13,-1,dynamictrees:leaves1:4)
Block(0,13,0,dynamictrees:leaves1:5)
Block(0,13,1,dynamictrees:leaves1:6)
Block(0,13,2,dynamictrees:leaves1:5)
Block(0,13,3,dynamictrees:leaves1:4)
Block(0,14,0,dynamictrees:leaves1:4)
Block(0,14,1,dynamictrees:leaves1:5)
Block(0,14,2,dynamictrees:leaves1:4)
Block(0,15,1,dynamictrees:leaves1:4)
Block(1,0,0,GRASS:0)
Block(1,0,1,GRASS:0)
Block(1,0,2,GRASS:0)
Block(1,1,0,dynamictrees:trunkshell:3)
Block(1,1,1,dynamictrees:trunkshell:2)
Block(1,1,2,dynamictrees:trunkshell:1)
Block(1,2,0,dynamictrees:trunkshell:3)
Block(1,2,1,dynamictrees:trunkshell:2)
Block(1,2,2,dynamictrees:trunkshell:1)
Block(1,3,0,dynamictrees:trunkshell:3)
Block(1,3,1,dynamictrees:trunkshell:2)
Block(1,3,2,dynamictrees:trunkshell:1)
Block(1,4,0,dynamictrees:trunkshell:3)
Block(1,4,1,dynamictrees:trunkshell:2)
Block(1,4,2,dynamictrees:trunkshell:1)
Block(1,5,0,dynamictrees:trunkshell:3)
Block(1,5,1,dynamictrees:trunkshell:2)
Block(1,5,2,dynamictrees:trunkshell:1)
Block(1,6,0,dynamictrees:trunkshell:3)
Block(1,6,1,dynamictrees:trunkshell:2)
Block(1,6,2,dynamictrees:trunkshell:1)
Block(1,6,7,dynamictrees:leaves1:4)
Block(1,6,8,dynamictrees:leaves1:4)
Block(1,7,3,dynamictrees:darkoakbranch:2)
Block(1,7,6,dynamictrees:leaves1:4)
Block(1,7,7,dynamictrees:leaves1:5)
Block(1,7,8,dynamictrees:leaves1:5)
Block(1,7,9,dynamictrees:leaves1:4)
Block(1,8,1,dynamictrees:darkoakbranch)
Block(1,8,4,dynamictrees:leaves1:4)
Block(1,8,5,dynamictrees:leaves1:5)
Block(1,8,6,dynamictrees:leaves1:4)
Block(1,8,7,dynamictrees:leaves1:4)
Block(1,8,8,dynamictrees:leaves1:4)
Block(1,9,1,dynamictrees:leaves1:7)
Block(1,9,5,dynamictrees:leaves1:4)
Block(1,10,1,dynamictrees:leaves1:5)
Block(1,11,-1,dynamictrees:leaves1:4)
Block(1,11,1,dynamictrees:leaves1:7)
Block(1,11,3,dynamictrees:leaves1:5)
Block(1,11,4,dynamictrees:leaves1:4)
Block(1,12,-2,dynamictrees:leaves1:4)
Block(1,12,-1,dynamictrees:leaves1:5)
Block(1,12,0,dynamictrees:leaves1:7)
Block(1,12,1,dynamictrees:darkoakbranch)
Block(1,12,2,dynamictrees:leaves1:7)
Block(1,12,3,dynamictrees:leaves1:5)
Block(1,12,4,dynamictrees:leaves1:4)
Block(1,13,-1,dynamictrees:leaves1:4)
Block(1,13,0,dynamictrees:leaves1:5)
Block(1,13,1,dynamictrees:leaves1:7)
Block(1,13,2,dynamictrees:leaves1:5)
Block(1,13,3,dynamictrees:leaves1:4)
Block(1,14,0,dynamictrees:leaves1:4)
Block(1,14,1,dynamictrees:leaves1:5)
Block(1,14,2,dynamictrees:leaves1:4)
Block(1,15,1,dynamictrees:leaves1:4)
Block(2,6,6,dynamictrees:leaves1:4)
Block(2,7,3,dynamictrees:darkoakbranch:2)
Block(2,7,4,dynamictrees:darkoakbranch:1)
Block(2,7,5,dynamictrees:darkoakbranch:1)
Block(2,7,6,dynamictrees:leaves1:5)
Block(2,7,7,dynamictrees:leaves1:4)
Block(2,7,8,dynamictrees:leaves1:4)
Block(2,8,4,dynamictrees:leaves1:4)
Block(2,8,5,dynamictrees:leaves1:5)
Block(2,8,6,dynamictrees:leaves1:4)
Block(2,9,5,dynamictrees:leaves1:4)
Block(2,11,-1,dynamictrees:leaves1:4)
Block(2,11,3,dynamictrees:leaves1:4)
Block(2,12,-2,dynamictrees:leaves1:4)
Block(2,12,-1,dynamictrees:leaves1:5)
Block(2,12,0,dynamictrees:leaves1:6)
Block(2,12,1,dynamictrees:leaves1:7)
Block(2,12,2,dynamictrees:leaves1:6)
Block(2,12,3,dynamictrees:leaves1:5)
Block(2,12,4,dynamictrees:leaves1:4)
Block(2,13,-1,dynamictrees:leaves1:4)
Block(2,13,0,dynamictrees:leaves1:5)
Block(2,13,1,dynamictrees:leaves1:5)
Block(2,13,2,dynamictrees:leaves1:5)
Block(2,13,3,dynamictrees:leaves1:4)
Block(2,14,0,dynamictrees:leaves1:4)
Block(2,14,1,dynamictrees:leaves1:4)
Block(2,14,2,dynamictrees:leaves1:4)
Block(3,6,0,dynamictrees:leaves1:4)
Block(3,6,7,dynamictrees:leaves1:4)
Block(3,7,-1,dynamictrees:leaves1:4)
Block(3,7,0,dynamictrees:leaves1:5)
Block(3,7,1,dynamictrees:leaves1:7)
Block(3,7,2,dynamictrees:darkoakbranch)
Block(3,7,3,dynamictrees:darkoakbranch:1)
Block(3,7,5,dynamictrees:darkoakbranch)
Block(3,7,6,dynamictrees:leaves1:7)
Block(3,7,7,dynamictrees:leaves1:5)
Block(3,7,8,dynamictrees:leaves1:4)
Block(3,8,0,dynamictrees:leaves1:4)
Block(3,8,1,dynamictrees:leaves1:5)
Block(3,8,2,dynamictrees:leaves1:7)
Block(3,8,3,dynamictrees:leaves1:5)
Block(3,8,4,dynamictrees:leaves1:5)
Block(3,8,5,dynamictrees:leaves1:7)
Block(3,8,6,dynamictrees:leaves1:5)
Block(3,8,7,dynamictrees:leaves1:4)
Block(3,9,1,dynamictrees:leaves1:4)
Block(3,9,2,dynamictrees:leaves1:5)
Block(3,9,3,dynamictrees:leaves1:4)
Block(3,9,4,dynamictrees:leaves1:4)
Block(3,9,5,dynamictrees:leaves1:5)
Block(3,9,6,dynamictrees:leaves1:4)
Block(3,10,2,dynamictrees:leaves1:4)
Block(3,10,5,dynamictrees:leaves1:4)
Block(3,11,0,dynamictrees:leaves1:4)
Block(3,11,1,dynamictrees:leaves1:4)
Block(3,11,2,dynamictrees:leaves1:4)
Block(3,12,-1,dynamictrees:leaves1:4)
Block(3,12,0,dynamictrees:leaves1:5)
Block(3,12,1,dynamictrees:leaves1:5)
Block(3,12,2,dynamictrees:leaves1:5)
Block(3,12,3,dynamictrees:leaves1:4)
Block(3,13,0,dynamictrees:leaves1:4)
Block(3,13,1,dynamictrees:leaves1:4)
Block(3,13,2,dynamictrees:leaves1:4)
Block(4,6,0,dynamictrees:leaves1:4)
Block(4,6,3,dynamictrees:leaves1:4)
Block(4,6,4,dynamictrees:leaves1:4)
Block(4,6,7,dynamictrees:leaves1:4)
Block(4,7,-1,dynamictrees:leaves1:4)
Block(4,7,0,dynamictrees:leaves1:5)
Block(4,7,1,dynamictrees:leaves1:6)
Block(4,7,2,dynamictrees:leaves1:7)
Block(4,7,3,dynamictrees:leaves1:5)
Block(4,7,4,dynamictrees:leaves1:5)
Block(4,7,5,dynamictrees:leaves1:7)
Block(4,7,6,dynamictrees:leaves1:6)
Block(4,7,7,dynamictrees:leaves1:5)
Block(4,7,8,dynamictrees:leaves1:4)
Block(4,8,0,dynamictrees:leaves1:4)
Block(4,8,1,dynamictrees:leaves1:5)
Block(4,8,2,dynamictrees:leaves1:5)
Block(4,8,3,dynamictrees:leaves1:4)
Block(4,8,4,dynamictrees:leaves1:4)
Block(4,8,5,dynamictrees:leaves1:5)
Block(4,8,6,dynamictrees:leaves1:5)
Block(4,8,7,dynamictrees:leaves1:4)
Block(4,9,1,dynamictrees:leaves1:4)
Block(4,9,2,dynamictrees:leaves1:4)
Block(4,9,5,dynamictrees:leaves1:4)
Block(4,9,6,dynamictrees:leaves1:4)
Block(4,12,0,dynamictrees:leaves1:4)
Block(4,12,1,dynamictrees:leaves1:4)
Block(4,12,2,dynamictrees:leaves1:4)
Block(5,6,1,dynamictrees:leaves1:4)
Block(5,6,2,dynamictrees:leaves1:4)
Block(5,6,5,dynamictrees:leaves1:4)
Block(5,6,6,dynamictrees:leaves1:4)
Block(5,7,0,dynamictrees:leaves1:4)
Block(5,7,1,dynamictrees:leaves1:5)
Block(5,7,2,dynamictrees:leaves1:5)
Block(5,7,3,dynamictrees:leaves1:4)
Block(5,7,4,dynamictrees:leaves1:4)
Block(5,7,5,dynamictrees:leaves1:5)
Block(5,7,6,dynamictrees:leaves1:5)
Block(5,7,7,dynamictrees:leaves1:4)
Block(5,8,1,dynamictrees:leaves1:4)
Block(5,8,2,dynamictrees:leaves1:4)
Block(5,8,5,dynamictrees:leaves1:4)
Block(5,8,6,dynamictrees:leaves1:4)
Block(6,7,1,dynamictrees:leaves1:4)
Block(6,7,2,dynamictrees:leaves1:4)
Block(6,7,5,dynamictrees:leaves1:4)
Block(6,7,6,dynamictrees:leaves1:4)

#######################################################################
# +-----------------------------------------------------------------+ #
# |                            BO3 checks                           | #
# +-----------------------------------------------------------------+ #
#######################################################################

BlockCheck(0,-1,1,GRASS,DIRT,biomesoplenty:grass,biomesoplenty:dirt)

#######################################################################
# +-----------------------------------------------------------------+ #
# |                             Branches                            | #
# +-----------------------------------------------------------------+ #
#######################################################################


#######################################################################
# +-----------------------------------------------------------------+ #
# |                             Entities                            | #
# +-----------------------------------------------------------------+ #
#######################################################################


#######################################################################
# +-----------------------------------------------------------------+ #
# |                            Particles                            | #
# +-----------------------------------------------------------------+ #
#######################################################################


#######################################################################
# +-----------------------------------------------------------------+ #
# |                             Spawners                            | #
# +-----------------------------------------------------------------+ #
#######################################################################


#######################################################################
# +-----------------------------------------------------------------+ #
# |                             ModData                             | #
# +-----------------------------------------------------------------+ #
#######################################################################

