
#######################################################################
# +-----------------------------------------------------------------+ #
# |                            BO4 object                           | #
# +-----------------------------------------------------------------+ #
#######################################################################

Author: NLBlackEagle

Description: No description given

SettingsMode: WriteDisable


#######################################################################
# +-----------------------------------------------------------------+ #
# |                          Main settings                          | #
# +-----------------------------------------------------------------+ #
#######################################################################

Frequency: 0

SpawnHeight: highestBlock

UseCenterForHighestBlock: true

##############################
# Height Limits for the BO4. #
##############################

MinHeight: 0

MaxHeight: 255

InheritBO3: 

InheritBO3Rotation: NORTH

OverrideChildSettings: true

OverrideParentHeight: false

CanOverride: true

BranchFrequency: 0

BranchFrequencyGroup: 

MustBeBelowOther: false

MustBeInside: 

CannotBeInside: 

ReplacesBO3: 

MustBeInsideWorldBorders: false

CanSpawnOnWater: true

SpawnOnWaterOnly: false

SpawnUnderWater: false

SpawnAtWaterLevel: false

HeightOffset: 0

RemoveAir: true

ReplaceAbove: 

ReplaceBelow: 

ReplaceWithBiomeBlocks: true

ReplaceWithSurfaceBlock: GRASS

ReplaceWithGroundBlock: DIRT

ReplaceWithStoneBlock: STONE

SmoothRadius: 0

SmoothHeightOffset: 0

SmoothStartTop: false

SmoothStartWood: false

SmoothingSurfaceBlock: 

SmoothingGroundBlock: 

BO3Group: 

IsSpawnPoint: false

DoReplaceBlocks: true


#######################################################################
# +-----------------------------------------------------------------+ #
# |                              Blocks                             | #
# +-----------------------------------------------------------------+ #
#######################################################################

Block(-8,-1,-2,LOG:15)
Block(-8,0,-3,LOG:15)
Block(-8,0,-2,LOG:15)
Block(-8,0,-1,LOG:15)
Block(-8,1,-4,LOG:15)
Block(-8,1,-3,LOG:15)
Block(-8,1,-2,LOG:15)
Block(-8,2,-4,LOG:15)
Block(-8,2,-3,LOG:15)
Block(-8,2,-2,LOG:15)
Block(-8,3,-5,LOG:15)
Block(-8,3,-4,LOG:15)
Block(-8,3,-3,LOG:15)
Block(-8,3,-2,LOG:15)
Block(-8,4,-5,LOG:15)
Block(-8,4,-4,LOG:15)
Block(-8,4,-3,LOG:15)
Block(-8,4,-2,LOG:15)
Block(-8,5,-5,LOG:15)
Block(-8,5,-4,LOG:15)
Block(-8,5,-3,LOG:15)
Block(-8,6,-4,LOG:15)
Block(-8,55,7,minecraft:black_glazed_terracotta:0)
Block(-8,55,8,minecraft:black_glazed_terracotta:0)
Block(-8,56,5,minecraft:black_glazed_terracotta:0)
Block(-8,56,6,minecraft:black_glazed_terracotta:0)
Block(-8,56,7,minecraft:black_glazed_terracotta:0)
Block(-8,57,4,minecraft:gray_glazed_terracotta:0)
Block(-8,57,5,minecraft:gray_glazed_terracotta:0)
Block(-8,58,-6,LEAVES:7)
Block(-8,58,-5,LEAVES:7)
Block(-8,58,-2,LEAVES:7)
Block(-8,59,-6,LEAVES:7)
Block(-8,59,-5,LEAVES:7)
Block(-8,59,-4,LEAVES:7)
Block(-8,59,-2,LEAVES:7)
Block(-8,59,-1,LEAVES:7)
Block(-8,60,-5,LEAVES:7)
Block(-8,60,-4,LEAVES:7)
Block(-8,60,-3,LEAVES:7)
Block(-8,60,-2,LEAVES:7)
Block(-8,60,-1,LEAVES:7)
Block(-8,60,0,LEAVES:7)
Block(-8,61,-5,LEAVES:7)
Block(-8,61,-4,LEAVES:7)
Block(-8,61,-3,LEAVES:7)
Block(-8,61,-2,LEAVES:7)
Block(-8,61,-1,LEAVES:7)
Block(-8,61,0,LEAVES:7)
Block(-8,61,1,LEAVES:7)
Block(-8,62,-5,LEAVES:7)
Block(-8,62,-4,LEAVES:7)
Block(-8,62,-3,LEAVES:7)
Block(-8,62,-2,LEAVES:7)
Block(-8,62,-1,LEAVES:7)
Block(-8,62,0,LEAVES:7)
Block(-8,62,1,LEAVES:7)
Block(-8,63,-5,LEAVES:7)
Block(-8,63,-4,LEAVES:7)
Block(-8,63,-3,LEAVES:7)
Block(-8,63,-2,LEAVES:7)
Block(-8,63,-1,LEAVES:7)
Block(-8,63,0,LEAVES:7)
Block(-8,63,5,LEAVES:7)
Block(-8,63,8,LEAVES:7)
Block(-8,64,-4,LEAVES:7)
Block(-8,64,-3,LEAVES:7)
Block(-8,64,-2,LEAVES:7)
Block(-8,64,-1,LEAVES:7)
Block(-8,64,0,LEAVES:7)
Block(-8,64,7,LEAVES:7)
Block(-8,64,8,LEAVES:7)
Block(-8,65,-4,LEAVES:7)
Block(-8,65,-3,LEAVES:7)
Block(-8,65,-2,LEAVES:7)
Block(-8,65,-1,LEAVES:7)
Block(-8,65,0,LEAVES:7)
Block(-8,65,1,LEAVES:7)
Block(-8,65,3,LEAVES:7)
Block(-8,65,4,LEAVES:7)
Block(-8,65,8,LOG:15)
Block(-8,66,-2,LEAVES:7)
Block(-8,66,1,LEAVES:7)
Block(-8,66,3,LEAVES:7)
Block(-8,66,5,LEAVES:7)
Block(-8,66,7,LOG:15)
Block(-8,66,8,LOG:15)
Block(-8,67,3,LEAVES:7)
Block(-8,67,4,LEAVES:7)
Block(-8,70,-2,LEAVES:7)
Block(-8,70,0,LEAVES:7)
Block(-8,71,-3,LEAVES:7)
Block(-8,71,-2,LEAVES:7)
Block(-8,71,-1,LEAVES:7)
Block(-8,71,0,LEAVES:7)
Block(-8,71,7,LEAVES:7)
Block(-8,72,-3,LEAVES:7)
Block(-8,72,-2,LEAVES:7)
Block(-8,72,0,LEAVES:7)
Block(-8,72,2,LEAVES:7)
Block(-8,72,5,LEAVES:7)
Block(-8,72,6,LEAVES:7)
Block(-8,72,7,LEAVES:7)
Block(-8,72,8,LEAVES:7)
Block(-8,73,-4,LEAVES:7)
Block(-8,73,-3,LEAVES:7)
Block(-8,73,-2,LEAVES:7)
Block(-8,73,0,LEAVES:7)
Block(-8,73,1,LEAVES:7)
Block(-8,73,5,LEAVES:7)
Block(-8,73,6,LEAVES:7)
Block(-8,73,7,LEAVES:7)
Block(-8,73,8,LEAVES:7)
Block(-8,74,-3,LEAVES:7)
Block(-8,74,0,LEAVES:7)
Block(-8,74,1,LEAVES:7)
Block(-8,74,4,LEAVES:7)
Block(-8,74,6,LEAVES:7)
Block(-8,74,7,LEAVES:7)
Block(-8,74,8,LEAVES:7)
Block(-8,75,1,LEAVES:7)
Block(-8,75,2,LEAVES:7)
Block(-8,75,4,LEAVES:7)
Block(-8,75,5,LEAVES:7)
Block(-8,75,6,LEAVES:7)
Block(-8,75,7,LEAVES:7)
Block(-8,75,8,LEAVES:7)
Block(-8,76,1,LEAVES:7)
Block(-8,76,2,LEAVES:7)
Block(-8,76,4,LEAVES:7)
Block(-8,76,5,LEAVES:7)
Block(-8,76,6,LEAVES:7)
Block(-8,76,7,LEAVES:7)
Block(-8,76,8,LEAVES:7)
Block(-8,77,3,LEAVES:7)
Block(-8,77,4,LEAVES:7)
Block(-8,77,5,LEAVES:7)
Block(-8,77,6,LEAVES:7)
Block(-8,77,7,LEAVES:7)
Block(-8,77,8,LEAVES:7)
Block(-8,78,1,LEAVES:7)
Block(-8,78,2,LEAVES:7)
Block(-8,78,3,LEAVES:7)
Block(-8,78,4,LEAVES:7)
Block(-8,78,8,LEAVES:7)
Block(-8,79,2,LEAVES:7)
Block(-8,79,8,LEAVES:7)
Block(-7,1,-3,LOG:15)
Block(-7,2,-4,LOG:15)
Block(-7,2,-3,LOG:15)
Block(-7,2,-2,LOG:15)
Block(-7,3,-4,LOG:15)
Block(-7,3,-3,LOG:15)
Block(-7,3,-2,LOG:15)
Block(-7,4,-5,LOG:15)
Block(-7,4,-4,LOG:15)
Block(-7,4,-3,LOG:15)
Block(-7,4,-2,LOG:15)
Block(-7,5,-5,LOG:15)
Block(-7,5,-4,LOG:15)
Block(-7,5,-3,LOG:15)
Block(-7,6,-5,LOG:15)
Block(-7,6,-4,LOG:15)
Block(-7,6,-3,LOG:15)
Block(-7,7,-5,LOG:15)
Block(-7,7,-4,LOG:15)
Block(-7,7,-3,LOG:15)
Block(-7,8,-5,LOG:15)
Block(-7,8,-4,LOG:15)
Block(-7,8,-3,LOG:15)
Block(-7,9,-4,LOG:15)
Block(-7,57,-2,LEAVES:7)
Block(-7,57,4,minecraft:gray_glazed_terracotta:0)
Block(-7,58,-4,LEAVES:7)
Block(-7,58,-3,LEAVES:7)
Block(-7,58,-1,LEAVES:7)
Block(-7,58,0,LEAVES:7)
Block(-7,58,2,minecraft:gray_glazed_terracotta:0)
Block(-7,58,3,minecraft:gray_glazed_terracotta:0)
Block(-7,59,-5,LEAVES:7)
Block(-7,59,-4,LEAVES:7)
Block(-7,59,-3,LEAVES:7)
Block(-7,59,-2,LEAVES:7)
Block(-7,59,-1,LEAVES:7)
Block(-7,59,0,LEAVES:7)
Block(-7,59,1,minecraft:gray_glazed_terracotta:0)
Block(-7,59,2,minecraft:gray_glazed_terracotta:0)
Block(-7,60,-5,LEAVES:7)
Block(-7,60,-4,LEAVES:7)
Block(-7,60,-3,LEAVES:7)
Block(-7,60,0,LEAVES:7)
Block(-7,61,-5,LEAVES:7)
Block(-7,61,-4,LEAVES:7)
Block(-7,61,-3,LEAVES:7)
Block(-7,61,-2,LEAVES:7)
Block(-7,61,-1,LEAVES:7)
Block(-7,61,0,LEAVES:7)
Block(-7,62,-5,LEAVES:7)
Block(-7,62,-4,LEAVES:7)
Block(-7,62,-3,LEAVES:7)
Block(-7,62,-1,LEAVES:7)
Block(-7,62,0,LEAVES:7)
Block(-7,62,7,LEAVES:7)
Block(-7,62,8,LEAVES:7)
Block(-7,63,-4,LEAVES:7)
Block(-7,63,-3,LEAVES:7)
Block(-7,63,-2,LEAVES:7)
Block(-7,63,-1,LEAVES:7)
Block(-7,63,0,LEAVES:7)
Block(-7,64,-4,LEAVES:7)
Block(-7,64,-3,LEAVES:7)
Block(-7,64,-2,LEAVES:7)
Block(-7,64,-1,LEAVES:7)
Block(-7,64,0,LEAVES:7)
Block(-7,64,2,LEAVES:7)
Block(-7,64,3,LEAVES:7)
Block(-7,64,4,LEAVES:7)
Block(-7,64,5,LEAVES:7)
Block(-7,64,6,LOG:15)
Block(-7,64,7,LOG:15)
Block(-7,64,8,LEAVES:7)
Block(-7,65,-3,LEAVES:7)
Block(-7,65,2,LEAVES:7)
Block(-7,65,5,LEAVES:7)
Block(-7,65,8,LEAVES:7)
Block(-7,66,2,LEAVES:7)
Block(-7,66,4,LEAVES:7)
Block(-7,67,3,LEAVES:7)
Block(-7,68,6,LEAVES:7)
Block(-7,70,-3,LEAVES:7)
Block(-7,70,-2,LEAVES:7)
Block(-7,70,-1,LEAVES:7)
Block(-7,70,0,LEAVES:7)
Block(-7,70,1,LEAVES:7)
Block(-7,71,-3,LEAVES:7)
Block(-7,71,-2,LEAVES:7)
Block(-7,71,-1,LEAVES:7)
Block(-7,71,0,LEAVES:7)
Block(-7,71,3,LEAVES:7)
Block(-7,71,4,LEAVES:7)
Block(-7,71,6,LEAVES:7)
Block(-7,72,-5,LEAVES:7)
Block(-7,72,-4,LEAVES:7)
Block(-7,72,-3,LEAVES:7)
Block(-7,72,-2,LEAVES:7)
Block(-7,72,-1,LEAVES:7)
Block(-7,72,0,LEAVES:7)
Block(-7,72,7,LEAVES:7)
Block(-7,73,-5,LEAVES:7)
Block(-7,73,-4,LEAVES:7)
Block(-7,73,-3,LEAVES:7)
Block(-7,73,-2,LEAVES:7)
Block(-7,73,0,LEAVES:7)
Block(-7,73,1,LOG:15)
Block(-7,73,5,LEAVES:7)
Block(-7,73,6,LEAVES:7)
Block(-7,73,7,LEAVES:7)
Block(-7,73,8,LEAVES:7)
Block(-7,74,-4,LEAVES:7)
Block(-7,74,-3,LEAVES:7)
Block(-7,74,-1,LEAVES:7)
Block(-7,74,0,LEAVES:7)
Block(-7,74,1,LEAVES:7)
Block(-7,74,5,LEAVES:7)
Block(-7,74,6,LEAVES:7)
Block(-7,74,7,LEAVES:7)
Block(-7,74,8,LEAVES:7)
Block(-7,75,1,LEAVES:7)
Block(-7,75,2,LEAVES:7)
Block(-7,75,4,LEAVES:7)
Block(-7,75,5,LEAVES:7)
Block(-7,75,6,LEAVES:7)
Block(-7,75,7,LEAVES:7)
Block(-7,75,8,LEAVES:7)
Block(-7,76,1,LEAVES:7)
Block(-7,76,2,LEAVES:7)
Block(-7,76,3,LEAVES:7)
Block(-7,76,4,LEAVES:7)
Block(-7,76,5,LEAVES:7)
Block(-7,76,6,LEAVES:7)
Block(-7,76,7,LEAVES:7)
Block(-7,76,8,LEAVES:7)
Block(-7,77,0,LEAVES:7)
Block(-7,77,1,LEAVES:7)
Block(-7,77,2,LEAVES:7)
Block(-7,77,3,LEAVES:7)
Block(-7,77,4,LEAVES:7)
Block(-7,77,5,LEAVES:7)
Block(-7,77,6,LEAVES:7)
Block(-7,77,7,LEAVES:7)
Block(-7,77,8,LEAVES:7)
Block(-7,78,1,LEAVES:7)
Block(-7,78,7,LEAVES:7)
Block(-7,78,8,LEAVES:7)
Block(-7,79,0,LEAVES:7)
Block(-7,79,1,LEAVES:7)
Block(-7,79,8,LEAVES:7)
Block(-7,80,1,LEAVES:7)
Block(-7,80,2,LEAVES:7)
Block(-6,0,-3,LOG:15)
Block(-6,1,-4,LOG:15)
Block(-6,1,-3,LOG:15)
Block(-6,1,-2,LOG:15)
Block(-6,2,-4,LOG:15)
Block(-6,2,-3,LOG:15)
Block(-6,2,-2,LOG:15)
Block(-6,3,-4,LOG:15)
Block(-6,3,-3,LOG:15)
Block(-6,3,-2,LOG:15)
Block(-6,4,-4,LOG:15)
Block(-6,4,-3,LOG:15)
Block(-6,5,-5,LOG:15)
Block(-6,5,-4,LOG:15)
Block(-6,5,-3,LOG:15)
Block(-6,6,-5,LOG:15)
Block(-6,6,-4,LOG:15)
Block(-6,6,-3,LOG:15)
Block(-6,7,-5,LOG:15)
Block(-6,7,-4,LOG:15)
Block(-6,7,-3,LOG:15)
Block(-6,8,-5,LOG:15)
Block(-6,8,-4,LOG:15)
Block(-6,8,-3,LOG:15)
Block(-6,8,-2,LOG:15)
Block(-6,9,-5,LOG:15)
Block(-6,9,-4,LOG:15)
Block(-6,9,-3,LOG:15)
Block(-6,9,-2,LOG:15)
Block(-6,9,-1,LOG:15)
Block(-6,10,-2,LOG:15)
Block(-6,58,-3,LEAVES:7)
Block(-6,58,-2,LEAVES:7)
Block(-6,58,-1,LEAVES:7)
Block(-6,59,-4,LEAVES:7)
Block(-6,59,-3,LEAVES:7)
Block(-6,59,-2,LEAVES:7)
Block(-6,59,-1,LEAVES:7)
Block(-6,59,0,LEAVES:7)
Block(-6,59,1,LEAVES:7)
Block(-6,60,-5,LEAVES:7)
Block(-6,60,-4,LEAVES:7)
Block(-6,60,-3,LEAVES:7)
Block(-6,60,-2,LEAVES:7)
Block(-6,60,-1,LEAVES:7)
Block(-6,60,0,LEAVES:7)
Block(-6,61,-5,LEAVES:7)
Block(-6,61,-4,LEAVES:7)
Block(-6,61,-3,LEAVES:7)
Block(-6,61,-2,LEAVES:7)
Block(-6,61,-1,LEAVES:7)
Block(-6,61,7,LEAVES:7)
Block(-6,61,8,LEAVES:7)
Block(-6,62,-4,LEAVES:7)
Block(-6,62,-3,LEAVES:7)
Block(-6,62,-2,LEAVES:7)
Block(-6,62,-1,LEAVES:7)
Block(-6,62,0,LEAVES:7)
Block(-6,62,8,LEAVES:7)
Block(-6,63,-4,LEAVES:7)
Block(-6,63,-2,LEAVES:7)
Block(-6,63,-1,LEAVES:7)
Block(-6,63,0,LEAVES:7)
Block(-6,63,3,LEAVES:7)
Block(-6,63,6,LEAVES:7)
Block(-6,63,8,LEAVES:7)
Block(-6,64,-4,LEAVES:7)
Block(-6,64,-3,LEAVES:7)
Block(-6,64,-2,LEAVES:7)
Block(-6,64,-1,LEAVES:7)
Block(-6,64,0,LEAVES:7)
Block(-6,64,1,LEAVES:7)
Block(-6,64,2,LEAVES:7)
Block(-6,64,3,LEAVES:7)
Block(-6,64,4,LEAVES:7)
Block(-6,64,5,LOG:15)
Block(-6,64,6,LOG:15)
Block(-6,64,8,LEAVES:7)
Block(-6,65,-2,LEAVES:7)
Block(-6,65,3,LEAVES:7)
Block(-6,65,4,LEAVES:7)
Block(-6,65,7,LEAVES:7)
Block(-6,65,8,LEAVES:7)
Block(-6,66,5,LEAVES:7)
Block(-6,67,1,LEAVES:7)
Block(-6,67,5,LEAVES:7)
Block(-6,68,1,LEAVES:7)
Block(-6,68,2,LEAVES:7)
Block(-6,68,5,LEAVES:7)
Block(-6,69,-3,LEAVES:7)
Block(-6,69,-2,LEAVES:7)
Block(-6,69,-1,LEAVES:7)
Block(-6,69,1,LEAVES:7)
Block(-6,70,-4,LEAVES:7)
Block(-6,70,-3,LEAVES:7)
Block(-6,70,-2,LEAVES:7)
Block(-6,70,-1,LEAVES:7)
Block(-6,70,0,LEAVES:7)
Block(-6,70,1,LEAVES:7)
Block(-6,70,2,LEAVES:7)
Block(-6,70,3,LEAVES:7)
Block(-6,71,-5,LEAVES:7)
Block(-6,71,-3,LEAVES:7)
Block(-6,71,-2,LOG:15)
Block(-6,71,-1,LEAVES:7)
Block(-6,71,0,LEAVES:7)
Block(-6,71,1,LEAVES:7)
Block(-6,71,2,LEAVES:7)
Block(-6,71,3,LEAVES:7)
Block(-6,71,4,LEAVES:7)
Block(-6,71,5,LEAVES:7)
Block(-6,71,6,LEAVES:7)
Block(-6,71,8,LEAVES:7)
Block(-6,72,-6,LEAVES:7)
Block(-6,72,-5,LEAVES:7)
Block(-6,72,-4,LEAVES:7)
Block(-6,72,-2,LEAVES:7)
Block(-6,72,0,LEAVES:7)
Block(-6,72,2,LOG:15)
Block(-6,72,3,LEAVES:7)
Block(-6,72,4,LEAVES:7)
Block(-6,72,5,LEAVES:7)
Block(-6,72,6,LEAVES:7)
Block(-6,72,7,LEAVES:7)
Block(-6,73,-5,LEAVES:7)
Block(-6,73,-4,LEAVES:7)
Block(-6,73,-3,LEAVES:7)
Block(-6,73,-1,LEAVES:7)
Block(-6,73,0,LEAVES:7)
Block(-6,73,1,LEAVES:7)
Block(-6,73,2,LEAVES:7)
Block(-6,73,5,LEAVES:7)
Block(-6,73,7,LEAVES:7)
Block(-6,73,8,LEAVES:7)
Block(-6,74,-3,LEAVES:7)
Block(-6,74,-1,LEAVES:7)
Block(-6,74,0,LEAVES:7)
Block(-6,74,1,LEAVES:7)
Block(-6,74,4,LEAVES:7)
Block(-6,74,5,LEAVES:7)
Block(-6,74,6,LEAVES:7)
Block(-6,74,7,LEAVES:7)
Block(-6,74,8,LEAVES:7)
Block(-6,75,0,LEAVES:7)
Block(-6,75,1,LEAVES:7)
Block(-6,75,2,LEAVES:7)
Block(-6,75,4,LEAVES:7)
Block(-6,75,5,LEAVES:7)
Block(-6,75,6,LEAVES:7)
Block(-6,75,7,LEAVES:7)
Block(-6,75,8,LEAVES:7)
Block(-6,76,0,LEAVES:7)
Block(-6,76,3,LEAVES:7)
Block(-6,76,4,LEAVES:7)
Block(-6,76,5,LEAVES:7)
Block(-6,76,6,LEAVES:7)
Block(-6,76,7,LEAVES:7)
Block(-6,76,8,LEAVES:7)
Block(-6,77,-1,LEAVES:7)
Block(-6,77,0,LEAVES:7)
Block(-6,77,1,LEAVES:7)
Block(-6,77,2,LEAVES:7)
Block(-6,77,3,LEAVES:7)
Block(-6,77,4,LEAVES:7)
Block(-6,77,5,LEAVES:7)
Block(-6,77,6,LEAVES:7)
Block(-6,77,7,LEAVES:7)
Block(-6,77,8,LEAVES:7)
Block(-6,78,-1,LEAVES:7)
Block(-6,78,0,LEAVES:7)
Block(-6,78,1,LEAVES:7)
Block(-6,78,2,LEAVES:7)
Block(-6,78,4,LEAVES:7)
Block(-6,78,6,LEAVES:7)
Block(-6,78,7,LEAVES:7)
Block(-6,78,8,LEAVES:7)
Block(-6,79,-1,LEAVES:7)
Block(-6,79,0,LEAVES:7)
Block(-6,79,1,LEAVES:7)
Block(-6,79,2,LEAVES:7)
Block(-6,79,3,LEAVES:7)
Block(-6,79,4,LEAVES:7)
Block(-6,80,1,LEAVES:7)
Block(-6,80,2,LEAVES:7)
Block(-6,80,3,LEAVES:7)
Block(-5,-2,-3,LOG:15)
Block(-5,-1,-4,LOG:15)
Block(-5,-1,-3,LOG:15)
Block(-5,-1,-2,LOG:15)
Block(-5,0,-4,LOG:15)
Block(-5,0,-3,LOG:15)
Block(-5,0,-2,LOG:15)
Block(-5,1,-4,LOG:15)
Block(-5,1,-3,LOG:15)
Block(-5,1,-2,LOG:15)
Block(-5,2,-4,LOG:15)
Block(-5,2,-3,LOG:15)
Block(-5,2,-2,LOG:15)
Block(-5,3,-3,LOG:15)
Block(-5,5,-4,LOG:15)
Block(-5,6,-5,LOG:15)
Block(-5,6,-4,LOG:15)
Block(-5,6,-3,LOG:15)
Block(-5,7,-5,LOG:15)
Block(-5,7,-4,LOG:15)
Block(-5,7,-3,LOG:15)
Block(-5,7,8,LOG:15)
Block(-5,8,-5,LOG:15)
Block(-5,8,-4,LOG:15)
Block(-5,8,-3,LOG:15)
Block(-5,8,-2,LOG:15)
Block(-5,8,-1,LOG:15)
Block(-5,9,-4,LOG:15)
Block(-5,9,-3,LOG:15)
Block(-5,9,-2,LOG:15)
Block(-5,9,-1,LOG:15)
Block(-5,9,8,LOG:15)
Block(-5,10,-3,LOG:15)
Block(-5,10,-2,LOG:15)
Block(-5,10,-1,LOG:15)
Block(-5,11,-2,LOG:15)
Block(-5,49,1,minecraft:gray_glazed_terracotta:0)
Block(-5,49,2,minecraft:gray_glazed_terracotta:0)
Block(-5,50,1,minecraft:gray_glazed_terracotta:0)
Block(-5,51,0,minecraft:gray_glazed_terracotta:0)
Block(-5,52,-1,minecraft:gray_glazed_terracotta:0)
Block(-5,52,0,minecraft:gray_glazed_terracotta:0)
Block(-5,53,-2,minecraft:gray_glazed_terracotta:0)
Block(-5,53,-1,minecraft:gray_glazed_terracotta:0)
Block(-5,54,-3,minecraft:gray_glazed_terracotta:0)
Block(-5,54,-2,minecraft:gray_glazed_terracotta:0)
Block(-5,55,-3,minecraft:gray_glazed_terracotta:0)
Block(-5,56,-4,minecraft:gray_glazed_terracotta:0)
Block(-5,57,-3,LEAVES:7)
Block(-5,58,-4,LEAVES:7)
Block(-5,58,-3,LEAVES:7)
Block(-5,58,-1,LEAVES:7)
Block(-5,59,-6,LEAVES:7)
Block(-5,59,-5,LEAVES:7)
Block(-5,59,-4,LEAVES:7)
Block(-5,59,-3,LEAVES:7)
Block(-5,59,-2,LEAVES:7)
Block(-5,59,-1,LEAVES:7)
Block(-5,59,0,LEAVES:7)
Block(-5,60,-6,LEAVES:7)
Block(-5,60,-5,LEAVES:7)
Block(-5,60,-4,LEAVES:7)
Block(-5,60,-3,LEAVES:7)
Block(-5,60,-1,LEAVES:7)
Block(-5,61,-6,LEAVES:7)
Block(-5,61,-5,LEAVES:7)
Block(-5,61,-4,LEAVES:7)
Block(-5,61,-3,LEAVES:7)
Block(-5,61,-2,LEAVES:7)
Block(-5,61,6,LEAVES:7)
Block(-5,61,7,LEAVES:7)
Block(-5,62,-5,LEAVES:7)
Block(-5,62,-4,LEAVES:7)
Block(-5,62,-3,LEAVES:7)
Block(-5,62,-2,LEAVES:7)
Block(-5,62,-1,LEAVES:7)
Block(-5,62,0,LEAVES:7)
Block(-5,62,8,LEAVES:7)
Block(-5,63,-4,LEAVES:7)
Block(-5,63,0,LEAVES:7)
Block(-5,63,1,LEAVES:7)
Block(-5,63,2,LEAVES:7)
Block(-5,63,3,LEAVES:7)
Block(-5,63,4,LEAVES:7)
Block(-5,63,5,LEAVES:7)
Block(-5,63,6,LEAVES:7)
Block(-5,63,7,LEAVES:7)
Block(-5,64,-1,LEAVES:7)
Block(-5,64,0,LEAVES:7)
Block(-5,64,1,LEAVES:7)
Block(-5,64,2,LEAVES:7)
Block(-5,64,3,LEAVES:7)
Block(-5,64,4,LEAVES:7)
Block(-5,64,5,LEAVES:7)
Block(-5,65,0,LEAVES:7)
Block(-5,65,1,LEAVES:7)
Block(-5,65,2,LEAVES:7)
Block(-5,65,3,LEAVES:7)
Block(-5,65,4,LOG:15)
Block(-5,65,5,LEAVES:7)
Block(-5,65,6,LEAVES:7)
Block(-5,65,7,LEAVES:7)
Block(-5,65,8,LEAVES:7)
Block(-5,66,3,LOG:15)
Block(-5,66,5,LEAVES:7)
Block(-5,66,7,LEAVES:7)
Block(-5,67,3,LEAVES:7)
Block(-5,67,4,LEAVES:7)
Block(-5,68,2,LEAVES:7)
Block(-5,68,4,LEAVES:7)
Block(-5,68,5,LEAVES:7)
Block(-5,69,-4,LEAVES:7)
Block(-5,69,-3,LEAVES:7)
Block(-5,69,-2,LEAVES:7)
Block(-5,69,-1,LEAVES:7)
Block(-5,69,0,LEAVES:7)
Block(-5,69,1,LEAVES:7)
Block(-5,69,2,LEAVES:7)
Block(-5,70,-4,LEAVES:7)
Block(-5,70,-3,LEAVES:7)
Block(-5,70,-2,LEAVES:7)
Block(-5,70,-1,LEAVES:7)
Block(-5,70,0,LEAVES:7)
Block(-5,70,1,LEAVES:7)
Block(-5,70,2,LEAVES:7)
Block(-5,70,3,LEAVES:7)
Block(-5,71,-4,LEAVES:7)
Block(-5,71,-3,LEAVES:7)
Block(-5,71,-2,LEAVES:7)
Block(-5,71,-1,LEAVES:7)
Block(-5,71,0,LEAVES:7)
Block(-5,71,1,LEAVES:7)
Block(-5,71,2,LEAVES:7)
Block(-5,71,3,LEAVES:7)
Block(-5,71,8,LEAVES:7)
Block(-5,72,-5,LEAVES:7)
Block(-5,72,-4,LEAVES:7)
Block(-5,72,-3,LEAVES:7)
Block(-5,72,-2,LEAVES:7)
Block(-5,72,-1,LEAVES:7)
Block(-5,72,0,LEAVES:7)
Block(-5,72,1,LEAVES:7)
Block(-5,72,2,LEAVES:7)
Block(-5,72,3,LEAVES:7)
Block(-5,72,5,LEAVES:7)
Block(-5,72,7,LEAVES:7)
Block(-5,72,8,LEAVES:7)
Block(-5,73,-6,LEAVES:7)
Block(-5,73,-5,LEAVES:7)
Block(-5,73,-4,LEAVES:7)
Block(-5,73,-3,LEAVES:7)
Block(-5,73,-2,LEAVES:7)
Block(-5,73,-1,LEAVES:7)
Block(-5,73,0,LEAVES:7)
Block(-5,73,1,LEAVES:7)
Block(-5,73,2,LEAVES:7)
Block(-5,73,6,LEAVES:7)
Block(-5,73,7,LEAVES:7)
Block(-5,73,8,LEAVES:7)
Block(-5,74,-6,LEAVES:7)
Block(-5,74,-3,LEAVES:7)
Block(-5,74,-2,LEAVES:7)
Block(-5,74,-1,LEAVES:7)
Block(-5,74,0,LEAVES:7)
Block(-5,74,1,LEAVES:7)
Block(-5,74,3,LEAVES:7)
Block(-5,74,4,LEAVES:7)
Block(-5,74,5,LEAVES:7)
Block(-5,74,6,LEAVES:7)
Block(-5,74,7,LEAVES:7)
Block(-5,74,8,LEAVES:7)
Block(-5,75,-4,LEAVES:7)
Block(-5,75,-3,LEAVES:7)
Block(-5,75,-2,LEAVES:7)
Block(-5,75,-1,LEAVES:7)
Block(-5,75,0,LEAVES:7)
Block(-5,75,1,LEAVES:7)
Block(-5,75,3,LEAVES:7)
Block(-5,75,4,LEAVES:7)
Block(-5,75,5,LEAVES:7)
Block(-5,75,6,LEAVES:7)
Block(-5,75,7,LEAVES:7)
Block(-5,75,8,LEAVES:7)
Block(-5,76,-3,LEAVES:7)
Block(-5,76,-1,LEAVES:7)
Block(-5,76,0,LEAVES:7)
Block(-5,76,1,LEAVES:7)
Block(-5,76,2,LEAVES:7)
Block(-5,76,3,LEAVES:7)
Block(-5,76,4,LEAVES:7)
Block(-5,76,5,LEAVES:7)
Block(-5,76,6,LEAVES:7)
Block(-5,76,7,LEAVES:7)
Block(-5,76,8,LEAVES:7)
Block(-5,77,-1,LEAVES:7)
Block(-5,77,0,LEAVES:7)
Block(-5,77,1,LEAVES:7)
Block(-5,77,2,LEAVES:7)
Block(-5,77,4,LEAVES:7)
Block(-5,77,5,LEAVES:7)
Block(-5,77,6,LEAVES:7)
Block(-5,77,7,LEAVES:7)
Block(-5,77,8,LEAVES:7)
Block(-5,78,-2,LEAVES:7)
Block(-5,78,-1,LEAVES:7)
Block(-5,78,0,LEAVES:7)
Block(-5,78,1,LEAVES:7)
Block(-5,78,2,LEAVES:7)
Block(-5,78,3,LEAVES:7)
Block(-5,78,4,LEAVES:7)
Block(-5,78,5,LEAVES:7)
Block(-5,78,6,LEAVES:7)
Block(-5,78,7,LEAVES:7)
Block(-5,78,8,LEAVES:7)
Block(-5,79,-1,LEAVES:7)
Block(-5,79,0,LEAVES:7)
Block(-5,79,1,LEAVES:7)
Block(-5,79,2,LEAVES:7)
Block(-5,79,4,LEAVES:7)
Block(-5,80,-1,LEAVES:7)
Block(-5,80,1,LEAVES:7)
Block(-5,80,2,LEAVES:7)
Block(-5,80,3,LEAVES:7)
Block(-5,81,2,LEAVES:7)
Block(-4,-5,-1,LOG:15)
Block(-4,-4,-2,LOG:15)
Block(-4,-4,-1,LOG:15)
Block(-4,-4,0,LOG:15)
Block(-4,-3,-3,LOG:15)
Block(-4,-3,-2,LOG:15)
Block(-4,-3,-1,LOG:15)
Block(-4,-2,-4,LOG:15)
Block(-4,-2,-3,LOG:15)
Block(-4,-2,-2,LOG:15)
Block(-4,-1,-4,LOG:15)
Block(-4,-1,-3,LOG:15)
Block(-4,-1,-2,LOG:15)
Block(-4,0,-4,LOG:15)
Block(-4,0,-3,LOG:15)
Block(-4,0,-2,LOG:15)
Block(-4,1,-4,LOG:15)
Block(-4,1,-3,LOG:15)
Block(-4,1,-2,LOG:15)
Block(-4,2,-3,LOG:15)
Block(-4,6,8,LOG:15)
Block(-4,7,8,LOG:15)
Block(-4,8,-4,LOG:15)
Block(-4,8,-3,LOG:15)
Block(-4,8,-2,LOG:15)
Block(-4,8,8,LOG:15)
Block(-4,9,-3,LOG:15)
Block(-4,9,-2,LOG:15)
Block(-4,9,-1,LOG:15)
Block(-4,9,8,LOG:15)
Block(-4,10,-3,LOG:15)
Block(-4,10,-2,LOG:15)
Block(-4,10,-1,LOG:15)
Block(-4,10,0,LOG:15)
Block(-4,10,8,LOG:15)
Block(-4,11,-3,LOG:15)
Block(-4,11,-2,LOG:15)
Block(-4,11,-1,LOG:15)
Block(-4,11,0,LOG:15)
Block(-4,11,1,LOG:15)
Block(-4,12,0,LOG:15)
Block(-4,40,8,minecraft:black_glazed_terracotta:1)
Block(-4,41,8,minecraft:black_glazed_terracotta:1)
Block(-4,42,2,minecraft:gray_glazed_terracotta)
Block(-4,42,8,minecraft:black_glazed_terracotta:1)
Block(-4,43,2,minecraft:gray_glazed_terracotta)
Block(-4,43,8,minecraft:black_glazed_terracotta:1)
Block(-4,44,2,minecraft:gray_glazed_terracotta)
Block(-4,44,8,minecraft:black_glazed_terracotta:1)
Block(-4,45,2,minecraft:gray_glazed_terracotta)
Block(-4,45,6,minecraft:black_glazed_terracotta:0)
Block(-4,45,7,minecraft:black_glazed_terracotta:0)
Block(-4,45,8,minecraft:black_glazed_terracotta:0)
Block(-4,46,2,minecraft:gray_glazed_terracotta)
Block(-4,46,4,minecraft:black_glazed_terracotta:0)
Block(-4,46,5,minecraft:black_glazed_terracotta:0)
Block(-4,46,6,minecraft:black_glazed_terracotta:0)
Block(-4,47,2,minecraft:gray_glazed_terracotta)
Block(-4,47,3,minecraft:black_glazed_terracotta:0)
Block(-4,47,4,minecraft:black_glazed_terracotta:0)
Block(-4,48,2,minecraft:gray_glazed_terracotta:0)
Block(-4,48,3,minecraft:gray_glazed_terracotta:0)
Block(-4,49,2,minecraft:gray_glazed_terracotta:0)
Block(-4,56,-3,LEAVES:7)
Block(-4,57,-4,LEAVES:7)
Block(-4,57,-3,LEAVES:7)
Block(-4,58,-4,LEAVES:7)
Block(-4,58,-3,LEAVES:7)
Block(-4,59,-5,LEAVES:7)
Block(-4,59,-4,LEAVES:7)
Block(-4,59,-3,LEAVES:7)
Block(-4,59,-1,LEAVES:7)
Block(-4,60,-5,LEAVES:7)
Block(-4,60,-4,LEAVES:7)
Block(-4,60,-3,LEAVES:7)
Block(-4,60,8,LEAVES:7)
Block(-4,61,-5,LEAVES:7)
Block(-4,61,-4,LEAVES:7)
Block(-4,61,-3,LEAVES:7)
Block(-4,61,-2,LEAVES:7)
Block(-4,61,6,LEAVES:7)
Block(-4,62,-3,LEAVES:7)
Block(-4,62,6,LEAVES:7)
Block(-4,63,1,LEAVES:7)
Block(-4,63,2,LEAVES:7)
Block(-4,63,3,LEAVES:7)
Block(-4,63,6,LEAVES:7)
Block(-4,64,0,LEAVES:7)
Block(-4,64,1,LEAVES:7)
Block(-4,64,2,LEAVES:7)
Block(-4,64,3,LEAVES:7)
Block(-4,64,4,LEAVES:7)
Block(-4,64,8,LEAVES:7)
Block(-4,65,2,LEAVES:7)
Block(-4,65,3,LEAVES:7)
Block(-4,65,6,LEAVES:7)
Block(-4,65,7,LEAVES:7)
Block(-4,65,8,LEAVES:7)
Block(-4,66,3,LEAVES:7)
Block(-4,66,7,LEAVES:7)
Block(-4,67,5,LEAVES:7)
Block(-4,67,7,LEAVES:7)
Block(-4,67,8,LEAVES:7)
Block(-4,68,2,LEAVES:7)
Block(-4,68,3,LEAVES:7)
Block(-4,68,4,LEAVES:7)
Block(-4,68,5,LEAVES:7)
Block(-4,68,6,LEAVES:7)
Block(-4,69,-3,LEAVES:7)
Block(-4,69,-2,LEAVES:7)
Block(-4,69,-1,LEAVES:7)
Block(-4,69,0,LEAVES:7)
Block(-4,69,1,LEAVES:7)
Block(-4,69,2,LEAVES:7)
Block(-4,70,-4,LEAVES:7)
Block(-4,70,-3,LEAVES:7)
Block(-4,70,-2,LEAVES:7)
Block(-4,70,-1,LEAVES:7)
Block(-4,70,0,LEAVES:7)
Block(-4,70,1,LEAVES:7)
Block(-4,70,2,LEAVES:7)
Block(-4,70,3,LOG:15)
Block(-4,70,4,LEAVES:7)
Block(-4,71,-6,LEAVES:7)
Block(-4,71,-5,LEAVES:7)
Block(-4,71,-4,LEAVES:7)
Block(-4,71,-3,LEAVES:7)
Block(-4,71,-2,LEAVES:7)
Block(-4,71,-1,LEAVES:7)
Block(-4,71,0,LEAVES:7)
Block(-4,71,1,LEAVES:7)
Block(-4,71,2,LOG:15)
Block(-4,71,3,LEAVES:7)
Block(-4,71,4,LEAVES:7)
Block(-4,71,5,LEAVES:7)
Block(-4,72,-6,LEAVES:7)
Block(-4,72,-5,LEAVES:7)
Block(-4,72,-4,LEAVES:7)
Block(-4,72,-3,LEAVES:7)
Block(-4,72,-2,LEAVES:7)
Block(-4,72,-1,LEAVES:7)
Block(-4,72,0,LEAVES:7)
Block(-4,72,1,LEAVES:7)
Block(-4,72,2,LEAVES:7)
Block(-4,72,3,LEAVES:7)
Block(-4,72,4,LEAVES:7)
Block(-4,72,8,LEAVES:7)
Block(-4,73,-7,LEAVES:7)
Block(-4,73,-6,LEAVES:7)
Block(-4,73,-5,LEAVES:7)
Block(-4,73,-4,LEAVES:7)
Block(-4,73,-3,LEAVES:7)
Block(-4,73,-2,LEAVES:7)
Block(-4,73,-1,LEAVES:7)
Block(-4,73,0,LEAVES:7)
Block(-4,73,1,LEAVES:7)
Block(-4,73,2,LEAVES:7)
Block(-4,73,3,LEAVES:7)
Block(-4,73,4,LEAVES:7)
Block(-4,73,7,LEAVES:7)
Block(-4,73,8,LEAVES:7)
Block(-4,74,-6,LEAVES:7)
Block(-4,74,-5,LEAVES:7)
Block(-4,74,-4,LEAVES:7)
Block(-4,74,-3,LEAVES:7)
Block(-4,74,-2,LEAVES:7)
Block(-4,74,-1,LEAVES:7)
Block(-4,74,0,LEAVES:7)
Block(-4,74,1,LEAVES:7)
Block(-4,74,3,LEAVES:7)
Block(-4,74,4,LEAVES:7)
Block(-4,74,6,LEAVES:7)
Block(-4,74,7,LEAVES:7)
Block(-4,74,8,LEAVES:7)
Block(-4,75,-4,LEAVES:7)
Block(-4,75,-3,LEAVES:7)
Block(-4,75,-2,LEAVES:7)
Block(-4,75,0,LEAVES:7)
Block(-4,75,1,LEAVES:7)
Block(-4,75,2,LEAVES:7)
Block(-4,75,4,LEAVES:7)
Block(-4,75,5,LEAVES:7)
Block(-4,75,6,LEAVES:7)
Block(-4,75,7,LEAVES:7)
Block(-4,75,8,LEAVES:7)
Block(-4,76,-4,LEAVES:7)
Block(-4,76,-3,LEAVES:7)
Block(-4,76,-2,LEAVES:7)
Block(-4,76,-1,LEAVES:7)
Block(-4,76,0,LEAVES:7)
Block(-4,76,1,LEAVES:7)
Block(-4,76,3,LEAVES:7)
Block(-4,76,4,LEAVES:7)
Block(-4,76,5,LEAVES:7)
Block(-4,76,6,LEAVES:7)
Block(-4,76,7,LEAVES:7)
Block(-4,76,8,LEAVES:7)
Block(-4,77,-2,LEAVES:7)
Block(-4,77,-1,LEAVES:7)
Block(-4,77,0,LEAVES:7)
Block(-4,77,1,LEAVES:7)
Block(-4,77,2,LEAVES:7)
Block(-4,77,3,LEAVES:7)
Block(-4,77,4,LEAVES:7)
Block(-4,77,5,LEAVES:7)
Block(-4,77,6,LEAVES:7)
Block(-4,77,7,LEAVES:7)
Block(-4,77,8,LEAVES:7)
Block(-4,78,-3,LEAVES:7)
Block(-4,78,-2,LEAVES:7)
Block(-4,78,-1,LEAVES:7)
Block(-4,78,0,LEAVES:7)
Block(-4,78,1,LEAVES:7)
Block(-4,78,2,LEAVES:7)
Block(-4,78,4,LEAVES:7)
Block(-4,78,5,LEAVES:7)
Block(-4,78,6,LEAVES:7)
Block(-4,78,7,LEAVES:7)
Block(-4,78,8,LEAVES:7)
Block(-4,79,-2,LEAVES:7)
Block(-4,79,-1,LEAVES:7)
Block(-4,79,0,LEAVES:7)
Block(-4,79,1,LEAVES:7)
Block(-4,79,2,LEAVES:7)
Block(-4,79,3,LEAVES:7)
Block(-4,80,-1,LEAVES:7)
Block(-4,80,1,LEAVES:7)
Block(-4,80,2,LEAVES:7)
Block(-4,80,3,LEAVES:7)
Block(-4,81,1,LEAVES:7)
Block(-4,81,2,LEAVES:7)
Block(-4,81,3,LEAVES:7)
Block(-3,-5,-3,LOG:15)
Block(-3,-5,-2,LOG:15)
Block(-3,-5,-1,LOG:15)
Block(-3,-5,0,LOG:15)
Block(-3,-4,-3,LOG:15)
Block(-3,-4,-2,LOG:15)
Block(-3,-4,-1,LOG:15)
Block(-3,-4,0,LOG:15)
Block(-3,-3,-4,LOG:15)
Block(-3,-3,-3,LOG:15)
Block(-3,-3,-2,LOG:15)
Block(-3,-3,-1,LOG:15)
Block(-3,-3,0,LOG:15)
Block(-3,-2,-4,LOG:15)
Block(-3,-2,-3,LOG:15)
Block(-3,-2,-2,LOG:15)
Block(-3,-2,-1,LOG:15)
Block(-3,-1,-4,LOG:15)
Block(-3,-1,-3,LOG:15)
Block(-3,-1,-2,LOG:15)
Block(-3,0,-4,LOG:15)
Block(-3,0,-3,LOG:15)
Block(-3,0,-2,LOG:15)
Block(-3,1,-3,LOG:15)
Block(-3,3,8,LOG:15)
Block(-3,4,7,LOG:15)
Block(-3,4,8,LOG:15)
Block(-3,5,8,LOG:15)
Block(-3,6,7,LOG:15)
Block(-3,6,8,LOG:15)
Block(-3,7,8,LOG:15)
Block(-3,8,8,LOG:15)
Block(-3,9,-2,LOG:15)
Block(-3,9,-1,LOG:15)
Block(-3,9,0,LOG:15)
Block(-3,9,8,LOG:15)
Block(-3,10,-3,LOG:15)
Block(-3,10,-2,LOG:15)
Block(-3,10,-1,LOG:15)
Block(-3,10,0,LOG:15)
Block(-3,10,1,LOG:15)
Block(-3,11,-2,LOG:15)
Block(-3,11,-1,LOG:15)
Block(-3,11,0,LOG:15)
Block(-3,11,1,LOG:15)
Block(-3,12,-1,LOG:15)
Block(-3,12,0,LOG:15)
Block(-3,12,1,LOG:15)
Block(-3,13,-1,LOG:15)
Block(-3,13,0,LOG:15)
Block(-3,13,1,LOG:15)
Block(-3,14,0,LOG:15)
Block(-3,14,1,LOG:15)
Block(-3,14,2,LOG:15)
Block(-3,15,1,LOG:15)
Block(-3,15,2,LOG:15)
Block(-3,15,3,LOG:15)
Block(-3,16,2,LOG:15)
Block(-3,59,-4,LEAVES:7)
Block(-3,60,-4,LEAVES:7)
Block(-3,61,-3,LEAVES:7)
Block(-3,61,6,LEAVES:7)
Block(-3,61,8,LEAVES:7)
Block(-3,62,8,LEAVES:7)
Block(-3,63,1,LEAVES:7)
Block(-3,63,2,LEAVES:7)
Block(-3,63,3,LEAVES:7)
Block(-3,63,4,LEAVES:7)
Block(-3,63,5,LEAVES:7)
Block(-3,63,6,LEAVES:7)
Block(-3,63,7,LEAVES:7)
Block(-3,64,0,LEAVES:7)
Block(-3,64,1,LEAVES:7)
Block(-3,64,2,LEAVES:7)
Block(-3,64,3,LEAVES:7)
Block(-3,64,4,LEAVES:7)
Block(-3,64,6,LEAVES:7)
Block(-3,64,7,LEAVES:7)
Block(-3,65,1,LEAVES:7)
Block(-3,65,2,LEAVES:7)
Block(-3,65,3,LEAVES:7)
Block(-3,65,6,LEAVES:7)
Block(-3,65,7,LEAVES:7)
Block(-3,66,1,LEAVES:7)
Block(-3,66,2,LEAVES:7)
Block(-3,66,3,LEAVES:7)
Block(-3,66,7,LEAVES:7)
Block(-3,67,2,LEAVES:7)
Block(-3,67,3,LEAVES:7)
Block(-3,67,4,LEAVES:7)
Block(-3,67,5,LEAVES:7)
Block(-3,68,1,LEAVES:7)
Block(-3,68,2,LEAVES:7)
Block(-3,68,4,LEAVES:7)
Block(-3,69,0,LEAVES:7)
Block(-3,69,1,LEAVES:7)
Block(-3,69,2,LEAVES:7)
Block(-3,69,3,LEAVES:7)
Block(-3,69,4,minecraft:black_glazed_terracotta:0)
Block(-3,70,-3,LEAVES:7)
Block(-3,70,-1,LEAVES:7)
Block(-3,70,0,LEAVES:7)
Block(-3,70,1,LEAVES:7)
Block(-3,70,2,LEAVES:7)
Block(-3,70,3,LEAVES:7)
Block(-3,70,4,LEAVES:7)
Block(-3,71,-4,LEAVES:7)
Block(-3,71,-3,LEAVES:7)
Block(-3,71,-2,LEAVES:7)
Block(-3,71,-1,LEAVES:7)
Block(-3,71,0,LEAVES:7)
Block(-3,71,1,LEAVES:7)
Block(-3,71,2,LEAVES:7)
Block(-3,71,3,LEAVES:7)
Block(-3,71,4,LEAVES:7)
Block(-3,72,-5,LEAVES:7)
Block(-3,72,-4,LEAVES:7)
Block(-3,72,-3,LEAVES:7)
Block(-3,72,-2,LEAVES:7)
Block(-3,72,-1,LEAVES:7)
Block(-3,72,0,LEAVES:7)
Block(-3,72,1,LEAVES:7)
Block(-3,72,3,LEAVES:7)
Block(-3,72,4,LEAVES:7)
Block(-3,72,5,LEAVES:7)
Block(-3,72,7,LEAVES:7)
Block(-3,72,8,LEAVES:7)
Block(-3,73,-6,LEAVES:7)
Block(-3,73,-5,LEAVES:7)
Block(-3,73,-4,LEAVES:7)
Block(-3,73,-3,LEAVES:7)
Block(-3,73,-2,LEAVES:7)
Block(-3,73,-1,LEAVES:7)
Block(-3,73,2,LEAVES:7)
Block(-3,73,3,LEAVES:7)
Block(-3,73,4,LEAVES:7)
Block(-3,73,5,LEAVES:7)
Block(-3,73,6,LEAVES:7)
Block(-3,73,7,LEAVES:7)
Block(-3,73,8,LEAVES:7)
Block(-3,74,-4,LEAVES:7)
Block(-3,74,-3,LEAVES:7)
Block(-3,74,-2,LEAVES:7)
Block(-3,74,-1,LEAVES:7)
Block(-3,74,0,LEAVES:7)
Block(-3,74,1,LEAVES:7)
Block(-3,74,3,LEAVES:7)
Block(-3,74,6,LEAVES:7)
Block(-3,74,7,LEAVES:7)
Block(-3,75,-4,LEAVES:7)
Block(-3,75,-3,LEAVES:7)
Block(-3,75,-2,LEAVES:7)
Block(-3,75,0,LEAVES:7)
Block(-3,75,1,LEAVES:7)
Block(-3,75,2,LOG:15)
Block(-3,75,6,LEAVES:7)
Block(-3,75,7,LEAVES:7)
Block(-3,75,8,LEAVES:7)
Block(-3,76,-3,LEAVES:7)
Block(-3,76,-2,LEAVES:7)
Block(-3,76,-1,LEAVES:7)
Block(-3,76,0,LEAVES:7)
Block(-3,76,1,LOG:15)
Block(-3,76,3,LEAVES:7)
Block(-3,76,4,LEAVES:7)
Block(-3,76,5,LEAVES:7)
Block(-3,76,6,LEAVES:7)
Block(-3,76,7,LEAVES:7)
Block(-3,76,8,LEAVES:7)
Block(-3,77,-3,LEAVES:7)
Block(-3,77,-2,LEAVES:7)
Block(-3,77,-1,LEAVES:7)
Block(-3,77,0,LEAVES:7)
Block(-3,77,1,LEAVES:7)
Block(-3,77,2,LEAVES:7)
Block(-3,77,3,LEAVES:7)
Block(-3,77,4,LEAVES:7)
Block(-3,77,5,LEAVES:7)
Block(-3,77,6,LEAVES:7)
Block(-3,77,7,LEAVES:7)
Block(-3,77,8,LEAVES:7)
Block(-3,78,-3,LEAVES:7)
Block(-3,78,-2,LEAVES:7)
Block(-3,78,-1,LEAVES:7)
Block(-3,78,0,LEAVES:7)
Block(-3,78,1,LEAVES:7)
Block(-3,78,3,LEAVES:7)
Block(-3,78,4,LEAVES:7)
Block(-3,78,5,LEAVES:7)
Block(-3,78,6,LEAVES:7)
Block(-3,78,7,LEAVES:7)
Block(-3,78,8,LEAVES:7)
Block(-3,79,-3,LEAVES:7)
Block(-3,79,-2,LEAVES:7)
Block(-3,79,-1,LEAVES:7)
Block(-3,79,0,LEAVES:7)
Block(-3,79,2,LEAVES:7)
Block(-3,79,4,LEAVES:7)
Block(-3,79,8,LEAVES:7)
Block(-3,80,-1,LEAVES:7)
Block(-3,80,0,LEAVES:7)
Block(-3,80,1,LEAVES:7)
Block(-3,80,2,LEAVES:7)
Block(-3,80,3,LEAVES:7)
Block(-3,81,0,LEAVES:7)
Block(-3,81,2,LEAVES:7)
Block(-2,-5,-3,LOG:15)
Block(-2,-5,-2,LOG:15)
Block(-2,-5,-1,LOG:15)
Block(-2,-5,0,LOG:15)
Block(-2,-4,-3,LOG:15)
Block(-2,-4,-2,LOG:15)
Block(-2,-4,-1,LOG:15)
Block(-2,-4,0,LOG:15)
Block(-2,-3,-3,LOG:15)
Block(-2,-3,-2,LOG:15)
Block(-2,-3,-1,LOG:15)
Block(-2,-3,0,LOG:15)
Block(-2,-2,-4,LOG:15)
Block(-2,-2,-3,LOG:15)
Block(-2,-2,-2,LOG:15)
Block(-2,-1,-3,LOG:15)
Block(-2,2,7,LOG:15)
Block(-2,3,6,LOG:15)
Block(-2,3,7,LOG:15)
Block(-2,3,8,LOG:15)
Block(-2,4,6,LOG:15)
Block(-2,4,7,LOG:15)
Block(-2,4,8,LOG:15)
Block(-2,5,7,LOG:15)
Block(-2,5,8,LOG:15)
Block(-2,6,7,LOG:15)
Block(-2,6,8,LOG:15)
Block(-2,7,7,LOG:15)
Block(-2,7,8,LOG:15)
Block(-2,8,8,LOG:15)
Block(-2,9,-1,LOG:15)
Block(-2,10,-2,LOG:15)
Block(-2,10,-1,LOG:15)
Block(-2,10,0,LOG:15)
Block(-2,11,-1,LOG:15)
Block(-2,11,0,LOG:15)
Block(-2,11,1,LOG:15)
Block(-2,12,-1,LOG:15)
Block(-2,12,0,LOG:15)
Block(-2,12,1,LOG:15)
Block(-2,13,-1,LOG:15)
Block(-2,13,0,LOG:15)
Block(-2,13,1,LOG:15)
Block(-2,13,2,LOG:15)
Block(-2,14,-1,LOG:15)
Block(-2,14,0,LOG:15)
Block(-2,14,1,LOG:15)
Block(-2,14,2,LOG:15)
Block(-2,14,3,LOG:15)
Block(-2,15,0,LOG:15)
Block(-2,15,1,LOG:15)
Block(-2,15,2,LOG:15)
Block(-2,15,3,LOG:15)
Block(-2,16,1,LOG:15)
Block(-2,16,2,LOG:15)
Block(-2,16,3,LOG:15)
Block(-2,17,1,LOG:15)
Block(-2,17,2,LOG:15)
Block(-2,17,3,LOG:15)
Block(-2,18,2,LOG:15)
Block(-2,18,3,LOG:15)
Block(-2,18,4,LOG:15)
Block(-2,19,3,LOG:15)
Block(-2,62,8,LEAVES:7)
Block(-2,63,1,LEAVES:7)
Block(-2,63,2,LEAVES:7)
Block(-2,63,3,LEAVES:7)
Block(-2,63,5,LEAVES:7)
Block(-2,63,6,LEAVES:7)
Block(-2,63,8,LEAVES:7)
Block(-2,64,0,LEAVES:7)
Block(-2,64,1,LEAVES:7)
Block(-2,64,2,LEAVES:7)
Block(-2,64,3,LEAVES:7)
Block(-2,64,8,LEAVES:7)
Block(-2,65,1,LEAVES:7)
Block(-2,65,2,LEAVES:7)
Block(-2,65,4,LEAVES:7)
Block(-2,65,7,LEAVES:7)
Block(-2,65,8,LEAVES:7)
Block(-2,66,1,LEAVES:7)
Block(-2,66,4,LEAVES:7)
Block(-2,67,1,LEAVES:7)
Block(-2,67,2,LEAVES:7)
Block(-2,67,3,LEAVES:7)
Block(-2,67,4,LEAVES:7)
Block(-2,68,0,LEAVES:7)
Block(-2,68,1,LEAVES:7)
Block(-2,68,2,LEAVES:7)
Block(-2,68,5,LEAVES:7)
Block(-2,69,0,LEAVES:7)
Block(-2,69,1,LEAVES:7)
Block(-2,69,2,LEAVES:7)
Block(-2,69,3,LEAVES:7)
Block(-2,69,4,LEAVES:7)
Block(-2,69,5,minecraft:black_glazed_terracotta:0)
Block(-2,70,-1,LEAVES:7)
Block(-2,70,0,LEAVES:7)
Block(-2,70,1,LEAVES:7)
Block(-2,70,2,LEAVES:7)
Block(-2,70,4,LEAVES:7)
Block(-2,71,-4,LEAVES:7)
Block(-2,71,-3,LEAVES:7)
Block(-2,71,-2,LEAVES:7)
Block(-2,71,-1,LEAVES:7)
Block(-2,71,0,LEAVES:7)
Block(-2,71,1,LEAVES:7)
Block(-2,71,2,LEAVES:7)
Block(-2,71,3,LEAVES:7)
Block(-2,71,4,LEAVES:7)
Block(-2,71,6,minecraft:black_glazed_terracotta:0)
Block(-2,71,7,LEAVES:7)
Block(-2,71,8,LEAVES:7)
Block(-2,72,-4,LEAVES:7)
Block(-2,72,-3,LEAVES:7)
Block(-2,72,-2,LEAVES:7)
Block(-2,72,-1,LEAVES:7)
Block(-2,72,0,LEAVES:7)
Block(-2,72,1,LEAVES:7)
Block(-2,72,3,LEAVES:7)
Block(-2,72,4,LEAVES:7)
Block(-2,72,6,LEAVES:7)
Block(-2,72,7,LEAVES:7)
Block(-2,73,-4,LEAVES:7)
Block(-2,73,-3,LEAVES:7)
Block(-2,73,-2,LEAVES:7)
Block(-2,73,-1,LEAVES:7)
Block(-2,73,0,LEAVES:7)
Block(-2,73,1,LEAVES:7)
Block(-2,73,2,LEAVES:7)
Block(-2,73,3,LEAVES:7)
Block(-2,73,6,LEAVES:7)
Block(-2,73,7,LEAVES:7)
Block(-2,74,-4,LEAVES:7)
Block(-2,74,-3,LEAVES:7)
Block(-2,74,-2,LEAVES:7)
Block(-2,74,-1,LEAVES:7)
Block(-2,74,0,LEAVES:7)
Block(-2,74,1,LEAVES:7)
Block(-2,74,2,LOG:15)
Block(-2,74,3,LEAVES:7)
Block(-2,74,4,LEAVES:7)
Block(-2,74,5,LEAVES:7)
Block(-2,74,6,LEAVES:7)
Block(-2,74,7,LEAVES:7)
Block(-2,74,8,LEAVES:7)
Block(-2,75,-4,LEAVES:7)
Block(-2,75,-3,LEAVES:7)
Block(-2,75,-2,LEAVES:7)
Block(-2,75,-1,LEAVES:7)
Block(-2,75,0,LEAVES:7)
Block(-2,75,1,LEAVES:7)
Block(-2,75,2,LEAVES:7)
Block(-2,75,6,LEAVES:7)
Block(-2,75,7,LEAVES:7)
Block(-2,75,8,LEAVES:7)
Block(-2,76,-3,LEAVES:7)
Block(-2,76,-2,LEAVES:7)
Block(-2,76,-1,LEAVES:7)
Block(-2,76,0,LEAVES:7)
Block(-2,76,1,LEAVES:7)
Block(-2,76,3,LEAVES:7)
Block(-2,76,4,LEAVES:7)
Block(-2,76,5,LEAVES:7)
Block(-2,76,6,LEAVES:7)
Block(-2,76,7,LEAVES:7)
Block(-2,76,8,LEAVES:7)
Block(-2,77,-3,LEAVES:7)
Block(-2,77,-2,LEAVES:7)
Block(-2,77,-1,LEAVES:7)
Block(-2,77,0,LEAVES:7)
Block(-2,77,1,LEAVES:7)
Block(-2,77,3,LEAVES:7)
Block(-2,77,4,LEAVES:7)
Block(-2,77,5,LEAVES:7)
Block(-2,77,6,LEAVES:7)
Block(-2,77,7,LEAVES:7)
Block(-2,77,8,LEAVES:7)
Block(-2,78,-3,LEAVES:7)
Block(-2,78,-2,LEAVES:7)
Block(-2,78,-1,LEAVES:7)
Block(-2,78,0,LEAVES:7)
Block(-2,78,1,LEAVES:7)
Block(-2,78,2,LEAVES:7)
Block(-2,78,3,LEAVES:7)
Block(-2,78,4,LEAVES:7)
Block(-2,78,5,LEAVES:7)
Block(-2,78,8,LEAVES:7)
Block(-2,79,-2,LEAVES:7)
Block(-2,79,-1,LEAVES:7)
Block(-2,79,0,LEAVES:7)
Block(-2,79,1,LEAVES:7)
Block(-2,79,3,LEAVES:7)
Block(-2,79,4,LEAVES:7)
Block(-2,79,5,LEAVES:7)
Block(-2,80,-1,LEAVES:7)
Block(-2,80,0,LEAVES:7)
Block(-2,80,1,LEAVES:7)
Block(-2,80,2,LEAVES:7)
Block(-2,80,3,LEAVES:7)
Block(-2,81,-1,LEAVES:7)
Block(-2,81,0,LEAVES:7)
Block(-2,81,1,LEAVES:7)
Block(-1,-5,-3,LOG:15)
Block(-1,-5,-2,LOG:15)
Block(-1,-5,-1,LOG:15)
Block(-1,-4,-3,LOG:15)
Block(-1,-4,-2,LOG:15)
Block(-1,-4,-1,LOG:15)
Block(-1,-4,0,LOG:15)
Block(-1,-3,-3,LOG:15)
Block(-1,-3,-2,LOG:15)
Block(-1,-3,-1,LOG:15)
Block(-1,0,7,LOG:15)
Block(-1,1,6,LOG:15)
Block(-1,1,7,LOG:15)
Block(-1,1,8,LOG:15)
Block(-1,2,6,LOG:15)
Block(-1,2,7,LOG:15)
Block(-1,2,8,LOG:15)
Block(-1,3,6,LOG:15)
Block(-1,3,7,LOG:15)
Block(-1,3,8,LOG:15)
Block(-1,4,6,LOG:15)
Block(-1,4,7,LOG:15)
Block(-1,4,8,LOG:15)
Block(-1,5,6,LOG:15)
Block(-1,5,7,LOG:15)
Block(-1,5,8,LOG:15)
Block(-1,6,7,LOG:15)
Block(-1,6,8,LOG:15)
Block(-1,7,8,LOG:15)
Block(-1,11,0,LOG:15)
Block(-1,12,-1,LOG:15)
Block(-1,12,0,LOG:15)
Block(-1,12,1,LOG:15)
Block(-1,13,-1,LOG:15)
Block(-1,13,0,LOG:15)
Block(-1,13,1,LOG:15)
Block(-1,14,0,LOG:15)
Block(-1,14,1,LOG:15)
Block(-1,14,2,LOG:15)
Block(-1,15,1,LOG:15)
Block(-1,15,2,LOG:15)
Block(-1,15,3,LOG:15)
Block(-1,16,1,LOG:15)
Block(-1,16,2,LOG:15)
Block(-1,16,3,LOG:15)
Block(-1,17,1,LOG:15)
Block(-1,17,2,LOG:15)
Block(-1,17,3,LOG:15)
Block(-1,17,4,LOG:15)
Block(-1,18,1,LOG:15)
Block(-1,18,2,LOG:15)
Block(-1,18,3,LOG:15)
Block(-1,18,4,LOG:15)
Block(-1,19,2,LOG:15)
Block(-1,19,3,LOG:15)
Block(-1,19,4,LOG:15)
Block(-1,20,3,LOG:15)
Block(-1,20,4,LOG:15)
Block(-1,20,5,LOG:15)
Block(-1,21,4,LOG:15)
Block(-1,61,8,LEAVES:7)
Block(-1,63,1,LEAVES:7)
Block(-1,64,0,LEAVES:7)
Block(-1,64,1,LEAVES:7)
Block(-1,64,2,LEAVES:7)
Block(-1,65,1,LEAVES:7)
Block(-1,67,1,LEAVES:7)
Block(-1,68,1,LEAVES:7)
Block(-1,68,2,LEAVES:7)
Block(-1,68,4,LEAVES:7)
Block(-1,68,5,LOG:15)
Block(-1,68,6,LOG:15)
Block(-1,68,7,LOG:15)
Block(-1,69,0,LEAVES:7)
Block(-1,69,1,LEAVES:7)
Block(-1,69,2,LEAVES:7)
Block(-1,69,3,LEAVES:7)
Block(-1,69,5,LOG:15)
Block(-1,70,-1,LEAVES:7)
Block(-1,70,0,LEAVES:7)
Block(-1,70,1,LEAVES:7)
Block(-1,70,2,LEAVES:7)
Block(-1,70,3,LEAVES:7)
Block(-1,70,4,LEAVES:7)
Block(-1,70,5,LOG:15)
Block(-1,70,7,LEAVES:7)
Block(-1,71,-1,LEAVES:7)
Block(-1,71,0,LEAVES:7)
Block(-1,71,1,LEAVES:7)
Block(-1,71,3,LEAVES:7)
Block(-1,71,4,LEAVES:7)
Block(-1,71,5,LEAVES:7)
Block(-1,71,6,LOG:15)
Block(-1,71,7,LEAVES:7)
Block(-1,71,8,LEAVES:7)
Block(-1,72,-2,LEAVES:7)
Block(-1,72,-1,LEAVES:7)
Block(-1,72,0,LEAVES:7)
Block(-1,72,1,LEAVES:7)
Block(-1,72,2,LEAVES:7)
Block(-1,72,3,LEAVES:7)
Block(-1,72,4,LEAVES:7)
Block(-1,72,5,LEAVES:7)
Block(-1,72,6,LEAVES:7)
Block(-1,72,7,LEAVES:7)
Block(-1,72,8,LEAVES:7)
Block(-1,73,-4,LEAVES:7)
Block(-1,73,-3,LEAVES:7)
Block(-1,73,-2,LEAVES:7)
Block(-1,73,0,LEAVES:7)
Block(-1,73,1,LEAVES:7)
Block(-1,73,3,LOG:15)
Block(-1,73,4,LOG:15)
Block(-1,73,5,LEAVES:7)
Block(-1,73,6,LEAVES:7)
Block(-1,73,7,LEAVES:7)
Block(-1,73,8,LEAVES:7)
Block(-1,74,-4,LEAVES:7)
Block(-1,74,-3,LEAVES:7)
Block(-1,74,-2,LEAVES:7)
Block(-1,74,-1,LEAVES:7)
Block(-1,74,0,LEAVES:7)
Block(-1,74,1,LEAVES:7)
Block(-1,74,2,LEAVES:7)
Block(-1,74,3,LEAVES:7)
Block(-1,74,4,LEAVES:7)
Block(-1,74,6,LEAVES:7)
Block(-1,74,7,LEAVES:7)
Block(-1,74,8,LEAVES:7)
Block(-1,75,-4,LEAVES:7)
Block(-1,75,-3,LEAVES:7)
Block(-1,75,-2,LEAVES:7)
Block(-1,75,-1,LEAVES:7)
Block(-1,75,0,LEAVES:7)
Block(-1,75,1,LEAVES:7)
Block(-1,75,2,LEAVES:7)
Block(-1,75,3,LEAVES:7)
Block(-1,75,4,LEAVES:7)
Block(-1,75,5,LEAVES:7)
Block(-1,75,6,LEAVES:7)
Block(-1,75,7,LEAVES:7)
Block(-1,75,8,LEAVES:7)
Block(-1,76,-3,LEAVES:7)
Block(-1,76,-2,LEAVES:7)
Block(-1,76,-1,LEAVES:7)
Block(-1,76,0,LEAVES:7)
Block(-1,76,1,LEAVES:7)
Block(-1,76,2,LEAVES:7)
Block(-1,76,4,LEAVES:7)
Block(-1,76,6,LEAVES:7)
Block(-1,76,7,LEAVES:7)
Block(-1,76,8,LEAVES:7)
Block(-1,77,-3,LEAVES:7)
Block(-1,77,-2,LEAVES:7)
Block(-1,77,-1,LEAVES:7)
Block(-1,77,0,LEAVES:7)
Block(-1,77,1,LEAVES:7)
Block(-1,77,2,LEAVES:7)
Block(-1,77,3,LEAVES:7)
Block(-1,77,4,LEAVES:7)
Block(-1,77,5,LEAVES:7)
Block(-1,77,7,LEAVES:7)
Block(-1,77,8,LEAVES:7)
Block(-1,78,-2,LEAVES:7)
Block(-1,78,-1,LEAVES:7)
Block(-1,78,0,LEAVES:7)
Block(-1,78,1,LEAVES:7)
Block(-1,78,2,LEAVES:7)
Block(-1,78,3,LEAVES:7)
Block(-1,78,4,LEAVES:7)
Block(-1,78,5,LEAVES:7)
Block(-1,78,7,LEAVES:7)
Block(-1,78,8,LEAVES:7)
Block(-1,79,0,LEAVES:7)
Block(-1,79,2,LEAVES:7)
Block(-1,79,3,LEAVES:7)
Block(-1,79,4,LEAVES:7)
Block(-1,80,-1,LEAVES:7)
Block(-1,80,0,LEAVES:7)
Block(-1,80,1,LEAVES:7)
Block(-1,81,0,LEAVES:7)
Block(0,-5,-4,LOG:15)
Block(0,-5,-3,LOG:15)
Block(0,-5,-2,LOG:15)
Block(0,-4,-3,LOG:15)
Block(0,-4,-2,LOG:15)
Block(0,-4,-1,LOG:15)
Block(0,-3,-2,LOG:15)
Block(0,-2,5,LOG:15)
Block(0,-1,4,LOG:15)
Block(0,-1,5,LOG:15)
Block(0,-1,6,LOG:15)
Block(0,-1,7,LOG:15)
Block(0,0,5,LOG:15)
Block(0,0,6,LOG:15)
Block(0,0,7,LOG:15)
Block(0,0,8,LOG:15)
Block(0,1,6,LOG:15)
Block(0,1,7,LOG:15)
Block(0,1,8,LOG:15)
Block(0,2,6,LOG:15)
Block(0,2,7,LOG:15)
Block(0,2,8,LOG:15)
Block(0,3,6,LOG:15)
Block(0,3,7,LOG:15)
Block(0,3,8,LOG:15)
Block(0,4,6,LOG:15)
Block(0,4,7,LOG:15)
Block(0,4,8,LOG:15)
Block(0,5,7,LOG:15)
Block(0,5,8,LOG:15)
Block(0,6,8,LOG:15)
Block(0,15,2,LOG:15)
Block(0,16,1,LOG:15)
Block(0,16,2,LOG:15)
Block(0,16,3,LOG:15)
Block(0,17,1,LOG:15)
Block(0,17,2,LOG:15)
Block(0,17,3,LOG:15)
Block(0,18,2,LOG:15)
Block(0,18,3,LOG:15)
Block(0,18,4,LOG:15)
Block(0,19,2,LOG:15)
Block(0,19,3,LOG:15)
Block(0,19,4,LOG:15)
Block(0,19,5,LOG:15)
Block(0,20,2,LOG:15)
Block(0,20,3,LOG:15)
Block(0,20,4,LOG:15)
Block(0,20,5,LOG:15)
Block(0,21,3,LOG:15)
Block(0,21,4,LOG:15)
Block(0,21,5,LOG:15)
Block(0,22,3,LOG:15)
Block(0,22,4,LOG:15)
Block(0,22,5,LOG:15)
Block(0,23,4,LOG:15)
Block(0,64,1,LEAVES:7)
Block(0,67,7,LOG:15)
Block(0,67,8,LOG:15)
Block(0,68,0,LEAVES:7)
Block(0,68,1,LEAVES:7)
Block(0,68,2,LEAVES:7)
Block(0,68,3,LOG:15)
Block(0,68,4,LOG:15)
Block(0,68,7,LOG:15)
Block(0,69,1,LEAVES:7)
Block(0,69,2,LEAVES:7)
Block(0,69,5,LEAVES:7)
Block(0,69,6,LEAVES:7)
Block(0,70,-1,LEAVES:7)
Block(0,70,0,LEAVES:7)
Block(0,70,4,LEAVES:7)
Block(0,70,5,LEAVES:7)
Block(0,70,7,LEAVES:7)
Block(0,71,-4,LEAVES:7)
Block(0,71,-2,LEAVES:7)
Block(0,71,-1,LEAVES:7)
Block(0,71,0,LEAVES:7)
Block(0,71,4,LEAVES:7)
Block(0,71,5,LEAVES:7)
Block(0,71,6,LEAVES:7)
Block(0,71,8,LEAVES:7)
Block(0,72,-4,LEAVES:7)
Block(0,72,-3,LEAVES:7)
Block(0,72,-2,LEAVES:7)
Block(0,72,1,LEAVES:7)
Block(0,72,3,LEAVES:7)
Block(0,72,4,LEAVES:7)
Block(0,72,5,LEAVES:7)
Block(0,72,6,LEAVES:7)
Block(0,72,7,LEAVES:7)
Block(0,72,8,LEAVES:7)
Block(0,73,-5,LEAVES:7)
Block(0,73,-4,LEAVES:7)
Block(0,73,-3,LEAVES:7)
Block(0,73,-2,LEAVES:7)
Block(0,73,2,LEAVES:7)
Block(0,73,3,LEAVES:7)
Block(0,73,4,LEAVES:7)
Block(0,73,5,LEAVES:7)
Block(0,73,6,LEAVES:7)
Block(0,73,7,LEAVES:7)
Block(0,74,-5,LEAVES:7)
Block(0,74,-4,LEAVES:7)
Block(0,74,-3,LEAVES:7)
Block(0,74,-2,LEAVES:7)
Block(0,74,-1,LEAVES:7)
Block(0,74,0,LEAVES:7)
Block(0,74,1,LEAVES:7)
Block(0,74,2,LEAVES:7)
Block(0,74,3,LEAVES:7)
Block(0,74,4,LEAVES:7)
Block(0,74,5,LEAVES:7)
Block(0,74,6,LEAVES:7)
Block(0,74,7,LEAVES:7)
Block(0,75,-4,LEAVES:7)
Block(0,75,-3,LEAVES:7)
Block(0,75,-2,LEAVES:7)
Block(0,75,-1,LEAVES:7)
Block(0,75,0,LEAVES:7)
Block(0,75,1,LEAVES:7)
Block(0,75,2,LEAVES:7)
Block(0,75,3,LEAVES:7)
Block(0,75,4,LEAVES:7)
Block(0,75,6,LEAVES:7)
Block(0,76,-4,LEAVES:7)
Block(0,76,-3,LEAVES:7)
Block(0,76,-2,LEAVES:7)
Block(0,76,-1,LEAVES:7)
Block(0,76,0,LEAVES:7)
Block(0,76,1,LEAVES:7)
Block(0,76,2,LEAVES:7)
Block(0,76,3,LEAVES:7)
Block(0,76,4,LEAVES:7)
Block(0,76,5,LEAVES:7)
Block(0,76,6,LEAVES:7)
Block(0,76,7,LEAVES:7)
Block(0,76,8,LEAVES:7)
Block(0,77,-3,LEAVES:7)
Block(0,77,-2,LEAVES:7)
Block(0,77,-1,LEAVES:7)
Block(0,77,0,LEAVES:7)
Block(0,77,1,LEAVES:7)
Block(0,77,2,LEAVES:7)
Block(0,77,3,LEAVES:7)
Block(0,77,5,LEAVES:7)
Block(0,77,6,LEAVES:7)
Block(0,77,7,LEAVES:7)
Block(0,77,8,LEAVES:7)
Block(0,78,-1,LEAVES:7)
Block(0,78,0,LEAVES:7)
Block(0,78,1,LEAVES:7)
Block(0,78,2,LEAVES:7)
Block(0,78,3,LEAVES:7)
Block(0,78,4,LEAVES:7)
Block(0,78,6,LEAVES:7)
Block(0,78,8,LEAVES:7)
Block(0,79,3,LEAVES:7)
Block(0,79,5,LEAVES:7)
Block(0,79,6,LEAVES:7)
Block(0,79,7,LEAVES:7)
Block(0,80,4,LEAVES:7)
Block(0,80,6,LEAVES:7)
Block(1,-5,-4,LOG:15)
Block(1,-5,-3,LOG:15)
Block(1,-5,-2,LOG:15)
Block(1,-4,-4,LOG:15)
Block(1,-4,-3,LOG:15)
Block(1,-4,-2,LOG:15)
Block(1,-3,4,LOG:15)
Block(1,-2,3,LOG:15)
Block(1,-2,4,LOG:15)
Block(1,-2,5,LOG:15)
Block(1,-2,6,LOG:15)
Block(1,-2,7,LOG:15)
Block(1,-1,3,LOG:15)
Block(1,-1,4,LOG:15)
Block(1,-1,5,LOG:15)
Block(1,-1,6,LOG:15)
Block(1,-1,7,LOG:15)
Block(1,-1,8,LOG:15)
Block(1,0,4,LOG:15)
Block(1,0,5,LOG:15)
Block(1,0,6,LOG:15)
Block(1,0,7,LOG:15)
Block(1,0,8,LOG:15)
Block(1,1,5,LOG:15)
Block(1,1,6,LOG:15)
Block(1,1,7,LOG:15)
Block(1,1,8,LOG:15)
Block(1,2,6,LOG:15)
Block(1,2,7,LOG:15)
Block(1,2,8,LOG:15)
Block(1,3,7,LOG:15)
Block(1,18,3,LOG:15)
Block(1,19,2,LOG:15)
Block(1,19,3,LOG:15)
Block(1,19,4,LOG:15)
Block(1,20,3,LOG:15)
Block(1,20,4,LOG:15)
Block(1,20,5,LOG:15)
Block(1,21,3,LOG:15)
Block(1,21,4,LOG:15)
Block(1,21,5,LOG:15)
Block(1,22,3,LOG:15)
Block(1,22,4,LOG:15)
Block(1,22,5,LOG:15)
Block(1,22,6,LOG:15)
Block(1,23,3,LOG:15)
Block(1,23,4,LOG:15)
Block(1,23,5,LOG:15)
Block(1,23,6,LOG:15)
Block(1,23,7,LOG:15)
Block(1,24,6,LOG:15)
Block(1,63,7,LEAVES:7)
Block(1,63,8,LEAVES:7)
Block(1,64,7,LEAVES:7)
Block(1,64,8,LEAVES:7)
Block(1,65,6,LEAVES:7)
Block(1,65,7,LEAVES:7)
Block(1,65,8,LEAVES:7)
Block(1,66,8,LEAVES:7)
Block(1,67,1,LEAVES:7)
Block(1,67,2,LEAVES:7)
Block(1,67,5,LEAVES:7)
Block(1,67,6,LEAVES:7)
Block(1,68,0,LEAVES:7)
Block(1,68,1,LEAVES:7)
Block(1,68,2,LEAVES:7)
Block(1,68,3,LOG:15)
Block(1,68,5,LEAVES:7)
Block(1,69,1,LEAVES:7)
Block(1,69,2,LOG:15)
Block(1,69,3,LOG:15)
Block(1,69,4,LEAVES:7)
Block(1,69,5,LEAVES:7)
Block(1,70,-2,LEAVES:7)
Block(1,70,5,LEAVES:7)
Block(1,71,-3,LEAVES:7)
Block(1,71,-2,LEAVES:7)
Block(1,71,-1,LEAVES:7)
Block(1,71,3,LEAVES:7)
Block(1,71,5,LEAVES:7)
Block(1,71,6,LEAVES:7)
Block(1,72,-4,LEAVES:7)
Block(1,72,-3,LEAVES:7)
Block(1,72,-2,LEAVES:7)
Block(1,72,-1,LEAVES:7)
Block(1,72,4,LEAVES:7)
Block(1,72,5,LEAVES:7)
Block(1,72,7,LEAVES:7)
Block(1,72,8,LEAVES:7)
Block(1,73,-5,LEAVES:7)
Block(1,73,-4,LEAVES:7)
Block(1,73,-3,LEAVES:7)
Block(1,73,-2,LEAVES:7)
Block(1,73,3,LEAVES:7)
Block(1,73,4,LOG:15)
Block(1,73,5,LEAVES:7)
Block(1,73,6,LEAVES:7)
Block(1,74,-5,LEAVES:7)
Block(1,74,-4,LEAVES:7)
Block(1,74,-3,LEAVES:7)
Block(1,74,-2,LEAVES:7)
Block(1,74,-1,LEAVES:7)
Block(1,74,0,LEAVES:7)
Block(1,74,1,LEAVES:7)
Block(1,74,2,LEAVES:7)
Block(1,74,3,LEAVES:7)
Block(1,74,4,LEAVES:7)
Block(1,74,5,LEAVES:7)
Block(1,74,6,LEAVES:7)
Block(1,75,-4,LEAVES:7)
Block(1,75,-3,LEAVES:7)
Block(1,75,-2,LEAVES:7)
Block(1,75,-1,LEAVES:7)
Block(1,75,0,LEAVES:7)
Block(1,75,1,LEAVES:7)
Block(1,75,2,LEAVES:7)
Block(1,75,3,LEAVES:7)
Block(1,75,4,LOG:15)
Block(1,75,5,LEAVES:7)
Block(1,75,6,LEAVES:7)
Block(1,75,8,LEAVES:7)
Block(1,76,-4,LEAVES:7)
Block(1,76,-3,LEAVES:7)
Block(1,76,-2,LEAVES:7)
Block(1,76,-1,LEAVES:7)
Block(1,76,0,LEAVES:7)
Block(1,76,1,LEAVES:7)
Block(1,76,2,LEAVES:7)
Block(1,76,3,LEAVES:7)
Block(1,76,4,LEAVES:7)
Block(1,76,6,LEAVES:7)
Block(1,76,8,LEAVES:7)
Block(1,77,-3,LEAVES:7)
Block(1,77,-2,LEAVES:7)
Block(1,77,0,LEAVES:7)
Block(1,77,1,LEAVES:7)
Block(1,77,2,LEAVES:7)
Block(1,77,3,LEAVES:7)
Block(1,77,4,LEAVES:7)
Block(1,77,5,LEAVES:7)
Block(1,77,6,LEAVES:7)
Block(1,77,8,LEAVES:7)
Block(1,78,0,LEAVES:7)
Block(1,78,1,LEAVES:7)
Block(1,78,2,LEAVES:7)
Block(1,78,3,LEAVES:7)
Block(1,78,4,LEAVES:7)
Block(1,78,5,LEAVES:7)
Block(1,78,6,LEAVES:7)
Block(1,78,7,LEAVES:7)
Block(1,79,2,LEAVES:7)
Block(1,79,3,LEAVES:7)
Block(1,79,4,LEAVES:7)
Block(1,79,5,LEAVES:7)
Block(1,79,6,LEAVES:7)
Block(1,79,7,LEAVES:7)
Block(1,79,8,LEAVES:7)
Block(1,80,3,LEAVES:7)
Block(1,80,5,LEAVES:7)
Block(1,80,6,LEAVES:7)
Block(1,80,7,LEAVES:7)
Block(1,80,8,LEAVES:7)
Block(2,-5,-5,LOG:15)
Block(2,-5,-4,LOG:15)
Block(2,-5,-3,LOG:15)
Block(2,-5,-2,LOG:15)
Block(2,-4,-4,LOG:15)
Block(2,-4,-3,LOG:15)
Block(2,-4,2,LOG:15)
Block(2,-3,1,LOG:15)
Block(2,-3,2,LOG:15)
Block(2,-3,3,LOG:15)
Block(2,-3,4,LOG:15)
Block(2,-3,5,LOG:15)
Block(2,-2,2,LOG:15)
Block(2,-2,3,LOG:15)
Block(2,-2,4,LOG:15)
Block(2,-2,5,LOG:15)
Block(2,-2,6,LOG:15)
Block(2,-2,7,LOG:15)
Block(2,-2,8,LOG:15)
Block(2,-1,3,LOG:15)
Block(2,-1,4,LOG:15)
Block(2,-1,5,LOG:15)
Block(2,-1,6,LOG:15)
Block(2,-1,7,LOG:15)
Block(2,-1,8,LOG:15)
Block(2,0,3,LOG:15)
Block(2,0,4,LOG:15)
Block(2,0,5,LOG:15)
Block(2,0,6,LOG:15)
Block(2,0,7,LOG:15)
Block(2,0,8,LOG:15)
Block(2,1,6,LOG:15)
Block(2,1,7,LOG:15)
Block(2,20,4,LOG:15)
Block(2,21,3,LOG:15)
Block(2,21,4,LOG:15)
Block(2,21,5,LOG:15)
Block(2,21,6,LOG:15)
Block(2,22,3,LOG:15)
Block(2,22,4,LOG:15)
Block(2,22,5,LOG:15)
Block(2,22,6,LOG:15)
Block(2,22,7,LOG:15)
Block(2,23,4,LOG:15)
Block(2,23,5,LOG:15)
Block(2,23,6,LOG:15)
Block(2,23,7,LOG:15)
Block(2,23,8,LOG:15)
Block(2,24,5,LOG:15)
Block(2,24,6,LOG:15)
Block(2,24,7,LOG:15)
Block(2,62,8,LEAVES:7)
Block(2,63,8,LEAVES:7)
Block(2,64,5,LEAVES:7)
Block(2,65,5,LEAVES:7)
Block(2,65,6,LEAVES:7)
Block(2,66,4,LEAVES:7)
Block(2,66,7,LEAVES:7)
Block(2,66,8,LEAVES:7)
Block(2,67,2,LEAVES:7)
Block(2,67,3,LEAVES:7)
Block(2,67,5,LEAVES:7)
Block(2,68,1,LEAVES:7)
Block(2,68,2,LEAVES:7)
Block(2,68,3,LEAVES:7)
Block(2,68,5,LEAVES:7)
Block(2,69,1,LEAVES:7)
Block(2,69,2,minecraft:black_glazed_terracotta:0)
Block(2,70,-3,LEAVES:15)
Block(2,70,3,LEAVES:7)
Block(2,71,-4,LEAVES:7)
Block(2,71,-3,LEAVES:7)
Block(2,71,-2,LEAVES:7)
Block(2,71,0,LEAVES:7)
Block(2,71,1,LEAVES:7)
Block(2,71,2,LEAVES:7)
Block(2,71,3,LEAVES:7)
Block(2,71,6,LEAVES:7)
Block(2,72,-5,LEAVES:7)
Block(2,72,-4,LEAVES:7)
Block(2,72,-3,LOG:15)
Block(2,72,-2,LEAVES:7)
Block(2,72,0,LEAVES:7)
Block(2,72,1,LEAVES:7)
Block(2,72,2,LEAVES:7)
Block(2,72,4,LEAVES:7)
Block(2,72,6,LEAVES:7)
Block(2,72,8,LEAVES:7)
Block(2,73,-5,LEAVES:7)
Block(2,73,-4,LOG:15)
Block(2,73,-3,LEAVES:7)
Block(2,73,-2,LEAVES:7)
Block(2,73,-1,LEAVES:7)
Block(2,73,4,LEAVES:7)
Block(2,73,5,LEAVES:7)
Block(2,73,6,LEAVES:7)
Block(2,73,7,LEAVES:7)
Block(2,74,-5,LEAVES:7)
Block(2,74,-4,LEAVES:7)
Block(2,74,-3,LEAVES:7)
Block(2,74,-2,LEAVES:7)
Block(2,74,-1,LEAVES:7)
Block(2,74,1,LEAVES:7)
Block(2,74,2,LEAVES:7)
Block(2,74,3,LEAVES:7)
Block(2,74,6,LEAVES:7)
Block(2,75,-4,LEAVES:7)
Block(2,75,-3,LEAVES:7)
Block(2,75,-2,LEAVES:7)
Block(2,75,-1,LEAVES:7)
Block(2,75,0,LEAVES:7)
Block(2,75,1,LEAVES:7)
Block(2,75,2,LEAVES:7)
Block(2,75,3,LEAVES:7)
Block(2,75,4,LOG:15)
Block(2,75,5,LOG:15)
Block(2,75,6,LEAVES:7)
Block(2,76,-6,LEAVES:7)
Block(2,76,-4,LEAVES:7)
Block(2,76,-3,LEAVES:7)
Block(2,76,-2,LEAVES:7)
Block(2,76,-1,LEAVES:7)
Block(2,76,0,LEAVES:7)
Block(2,76,1,LEAVES:7)
Block(2,76,2,LEAVES:7)
Block(2,76,3,LEAVES:7)
Block(2,76,4,LEAVES:7)
Block(2,76,6,LEAVES:7)
Block(2,76,8,LEAVES:7)
Block(2,77,-4,LEAVES:7)
Block(2,77,-3,LEAVES:7)
Block(2,77,-2,LEAVES:7)
Block(2,77,0,LEAVES:7)
Block(2,77,1,LEAVES:7)
Block(2,77,2,LEAVES:7)
Block(2,77,3,LEAVES:7)
Block(2,77,4,LEAVES:7)
Block(2,77,5,LEAVES:7)
Block(2,77,8,LEAVES:7)
Block(2,78,0,LEAVES:7)
Block(2,78,1,LEAVES:7)
Block(2,78,2,LEAVES:7)
Block(2,78,3,LEAVES:7)
Block(2,78,4,LEAVES:7)
Block(2,78,5,LEAVES:7)
Block(2,78,6,LEAVES:7)
Block(2,78,7,LEAVES:7)
Block(2,79,1,LEAVES:7)
Block(2,79,2,LEAVES:7)
Block(2,79,3,LEAVES:7)
Block(2,79,4,LEAVES:7)
Block(2,79,5,LEAVES:7)
Block(2,79,6,LEAVES:7)
Block(2,79,7,LEAVES:7)
Block(2,79,8,LEAVES:7)
Block(2,80,3,LEAVES:7)
Block(2,80,4,LEAVES:7)
Block(2,80,5,LEAVES:7)
Block(2,80,6,LEAVES:7)
Block(2,80,8,LEAVES:7)
Block(2,81,8,LEAVES:7)
Block(3,-5,-5,LOG:15)
Block(3,-5,-4,LOG:15)
Block(3,-5,-3,LOG:15)
Block(3,-5,2,LOG:15)
Block(3,-4,-5,LOG:15)
Block(3,-4,-4,LOG:15)
Block(3,-4,-3,LOG:15)
Block(3,-4,1,LOG:15)
Block(3,-4,2,LOG:15)
Block(3,-4,3,LOG:15)
Block(3,-3,1,LOG:15)
Block(3,-3,2,LOG:15)
Block(3,-3,3,LOG:15)
Block(3,-3,4,LOG:15)
Block(3,-3,8,LOG:15)
Block(3,-2,1,LOG:15)
Block(3,-2,2,LOG:15)
Block(3,-2,3,LOG:15)
Block(3,-2,4,LOG:15)
Block(3,-2,5,LOG:15)
Block(3,-2,7,LOG:15)
Block(3,-2,8,LOG:15)
Block(3,-1,2,LOG:15)
Block(3,-1,3,LOG:15)
Block(3,-1,4,LOG:15)
Block(3,-1,5,LOG:15)
Block(3,-1,6,LOG:15)
Block(3,-1,7,LOG:15)
Block(3,-1,8,LOG:15)
Block(3,0,4,LOG:15)
Block(3,0,7,LOG:15)
Block(3,0,8,LOG:15)
Block(3,21,5,LOG:15)
Block(3,22,4,LOG:15)
Block(3,22,5,LOG:15)
Block(3,22,6,LOG:15)
Block(3,22,7,LOG:15)
Block(3,22,8,LOG:15)
Block(3,23,5,LOG:15)
Block(3,23,6,LOG:15)
Block(3,23,7,LOG:15)
Block(3,23,8,LOG:15)
Block(3,24,6,LOG:15)
Block(3,24,7,LOG:15)
Block(3,24,8,LOG:15)
Block(3,25,7,LOG:15)
Block(3,55,8,minecraft:gray_glazed_terracotta:0)
Block(3,56,8,minecraft:gray_glazed_terracotta:0)
Block(3,62,7,LEAVES:7)
Block(3,63,7,LEAVES:7)
Block(3,64,5,LEAVES:7)
Block(3,64,8,LEAVES:7)
Block(3,65,4,LEAVES:7)
Block(3,65,5,LEAVES:7)
Block(3,65,6,LEAVES:7)
Block(3,65,8,LEAVES:7)
Block(3,66,5,LEAVES:7)
Block(3,66,6,LEAVES:7)
Block(3,66,7,LEAVES:7)
Block(3,67,2,LEAVES:7)
Block(3,67,5,LEAVES:7)
Block(3,67,6,LEAVES:7)
Block(3,67,7,LEAVES:7)
Block(3,67,8,LEAVES:7)
Block(3,68,2,LEAVES:7)
Block(3,68,3,LEAVES:7)
Block(3,68,5,LEAVES:7)
Block(3,69,0,LEAVES:7)
Block(3,69,1,minecraft:black_glazed_terracotta:0)
Block(3,69,2,LEAVES:7)
Block(3,69,3,LEAVES:7)
Block(3,69,4,LEAVES:7)
Block(3,69,5,LEAVES:7)
Block(3,70,-3,LEAVES:11)
Block(3,70,-2,LEAVES:7)
Block(3,70,-1,LEAVES:7)
Block(3,70,0,LEAVES:7)
Block(3,70,1,LEAVES:7)
Block(3,70,2,LEAVES:7)
Block(3,70,3,LEAVES:7)
Block(3,70,4,LEAVES:7)
Block(3,70,6,LEAVES:7)
Block(3,71,-5,LEAVES:7)
Block(3,71,-4,LEAVES:7)
Block(3,71,-3,LEAVES:7)
Block(3,71,-2,LOG:15)
Block(3,71,-1,LEAVES:7)
Block(3,71,0,LEAVES:7)
Block(3,71,1,LEAVES:7)
Block(3,71,2,LEAVES:7)
Block(3,71,3,LEAVES:7)
Block(3,71,4,LEAVES:7)
Block(3,71,5,LEAVES:7)
Block(3,71,6,LEAVES:7)
Block(3,72,-6,LEAVES:7)
Block(3,72,-5,LEAVES:7)
Block(3,72,-4,LEAVES:7)
Block(3,72,-3,LEAVES:7)
Block(3,72,-2,LOG:15)
Block(3,72,-1,LOG:15)
Block(3,72,0,LEAVES:7)
Block(3,72,1,LEAVES:7)
Block(3,72,3,LEAVES:7)
Block(3,72,4,LEAVES:7)
Block(3,72,6,LEAVES:7)
Block(3,73,-6,LEAVES:7)
Block(3,73,-5,LEAVES:7)
Block(3,73,-4,LEAVES:7)
Block(3,73,-3,LEAVES:7)
Block(3,73,-2,LEAVES:7)
Block(3,73,-1,LEAVES:7)
Block(3,73,1,LEAVES:7)
Block(3,73,2,LEAVES:7)
Block(3,73,3,LEAVES:7)
Block(3,73,4,LEAVES:7)
Block(3,73,5,LEAVES:7)
Block(3,73,6,LEAVES:7)
Block(3,74,-6,LEAVES:7)
Block(3,74,-5,LEAVES:7)
Block(3,74,-4,LEAVES:7)
Block(3,74,-3,LEAVES:7)
Block(3,74,-2,LEAVES:7)
Block(3,74,-1,LEAVES:7)
Block(3,74,1,LEAVES:7)
Block(3,74,2,LEAVES:7)
Block(3,74,3,LEAVES:7)
Block(3,74,4,LEAVES:7)
Block(3,74,6,LEAVES:7)
Block(3,74,7,LEAVES:7)
Block(3,75,-6,LEAVES:7)
Block(3,75,-5,LEAVES:7)
Block(3,75,-4,LEAVES:7)
Block(3,75,-3,LEAVES:7)
Block(3,75,-2,LEAVES:7)
Block(3,75,-1,LEAVES:7)
Block(3,75,0,LEAVES:7)
Block(3,75,1,LEAVES:7)
Block(3,75,2,LEAVES:7)
Block(3,75,3,LEAVES:7)
Block(3,75,5,LOG:15)
Block(3,75,6,LEAVES:7)
Block(3,75,8,LEAVES:7)
Block(3,76,-6,LEAVES:7)
Block(3,76,-5,LEAVES:7)
Block(3,76,-4,LEAVES:7)
Block(3,76,-3,LEAVES:7)
Block(3,76,-2,LEAVES:7)
Block(3,76,-1,LEAVES:7)
Block(3,76,0,LEAVES:7)
Block(3,76,1,LEAVES:7)
Block(3,76,2,LEAVES:7)
Block(3,76,3,LEAVES:7)
Block(3,76,4,LEAVES:7)
Block(3,76,5,LEAVES:7)
Block(3,76,6,LEAVES:7)
Block(3,77,-4,LEAVES:7)
Block(3,77,-3,LEAVES:7)
Block(3,77,-2,LEAVES:7)
Block(3,77,0,LEAVES:7)
Block(3,77,1,LEAVES:7)
Block(3,77,2,LEAVES:7)
Block(3,77,3,LEAVES:7)
Block(3,77,4,LEAVES:7)
Block(3,77,5,LEAVES:7)
Block(3,78,0,LEAVES:7)
Block(3,78,1,LEAVES:7)
Block(3,78,2,LEAVES:7)
Block(3,78,3,LEAVES:7)
Block(3,78,4,LEAVES:7)
Block(3,78,5,LEAVES:7)
Block(3,78,7,LEAVES:7)
Block(3,78,8,LEAVES:7)
Block(3,79,1,LEAVES:7)
Block(3,79,2,LEAVES:7)
Block(3,79,3,LEAVES:7)
Block(3,79,4,LEAVES:7)
Block(3,79,5,LEAVES:7)
Block(3,79,6,LEAVES:7)
Block(3,79,7,LEAVES:7)
Block(3,80,2,LEAVES:7)
Block(3,80,3,LEAVES:7)
Block(3,80,4,LEAVES:7)
Block(3,80,5,LEAVES:7)
Block(3,80,8,LEAVES:7)
Block(4,-5,-5,LOG:15)
Block(4,-5,-4,LOG:15)
Block(4,-5,-3,LOG:15)
Block(4,-5,0,LOG:15)
Block(4,-5,1,LOG:15)
Block(4,-5,2,LOG:15)
Block(4,-5,3,LOG:15)
Block(4,-4,-5,LOG:15)
Block(4,-4,-4,LOG:15)
Block(4,-4,-3,LOG:15)
Block(4,-4,0,LOG:15)
Block(4,-4,1,LOG:15)
Block(4,-4,2,LOG:15)
Block(4,-4,3,LOG:15)
Block(4,-4,8,LOG:15)
Block(4,-3,1,LOG:15)
Block(4,-3,2,LOG:15)
Block(4,-3,3,LOG:15)
Block(4,-3,8,LOG:15)
Block(4,-2,2,LOG:15)
Block(4,-2,3,LOG:15)
Block(4,-2,4,LOG:15)
Block(4,-2,8,LOG:15)
Block(4,-1,3,LOG:15)
Block(4,-1,7,LOG:15)
Block(4,-1,8,LOG:15)
Block(4,0,8,LOG:15)
Block(4,20,6,LOG:15)
Block(4,21,5,LOG:15)
Block(4,21,6,LOG:15)
Block(4,21,7,LOG:15)
Block(4,22,6,LOG:15)
Block(4,22,7,LOG:15)
Block(4,22,8,LOG:15)
Block(4,23,6,LOG:15)
Block(4,23,7,LOG:15)
Block(4,23,8,LOG:15)
Block(4,24,6,LOG:15)
Block(4,24,7,LOG:15)
Block(4,24,8,LOG:15)
Block(4,25,6,LOG:15)
Block(4,25,7,LOG:15)
Block(4,25,8,LOG:15)
Block(4,54,7,minecraft:gray_glazed_terracotta:0)
Block(4,55,7,minecraft:gray_glazed_terracotta:0)
Block(4,55,8,minecraft:gray_glazed_terracotta:0)
Block(4,61,4,LEAVES:7)
Block(4,62,3,LEAVES:7)
Block(4,62,4,LEAVES:7)
Block(4,62,5,LEAVES:7)
Block(4,62,7,LEAVES:7)
Block(4,62,8,LEAVES:7)
Block(4,63,2,LEAVES:7)
Block(4,63,3,LEAVES:7)
Block(4,63,4,LEAVES:7)
Block(4,63,7,LEAVES:7)
Block(4,64,5,LEAVES:7)
Block(4,64,6,LEAVES:7)
Block(4,64,7,LEAVES:7)
Block(4,65,4,LEAVES:7)
Block(4,65,5,LEAVES:7)
Block(4,65,6,LEAVES:7)
Block(4,65,7,LOG:15)
Block(4,65,8,LEAVES:7)
Block(4,66,5,LEAVES:7)
Block(4,66,6,LEAVES:7)
Block(4,66,7,LEAVES:7)
Block(4,67,3,LEAVES:7)
Block(4,67,6,LEAVES:7)
Block(4,67,7,LEAVES:7)
Block(4,67,8,LEAVES:7)
Block(4,68,2,LEAVES:7)
Block(4,68,6,LEAVES:7)
Block(4,69,1,LOG:15)
Block(4,69,2,LEAVES:7)
Block(4,69,3,LEAVES:7)
Block(4,69,5,LEAVES:7)
Block(4,70,-3,LEAVES:11)
Block(4,70,-2,LEAVES:7)
Block(4,70,-1,LEAVES:7)
Block(4,70,0,LEAVES:7)
Block(4,70,1,LOG:15)
Block(4,70,2,LEAVES:7)
Block(4,70,3,LEAVES:7)
Block(4,70,4,LEAVES:7)
Block(4,70,5,LEAVES:7)
Block(4,71,-5,LEAVES:7)
Block(4,71,-4,LEAVES:7)
Block(4,71,-3,LEAVES:7)
Block(4,71,-2,LEAVES:7)
Block(4,71,-1,LEAVES:7)
Block(4,71,0,LEAVES:7)
Block(4,71,1,LEAVES:7)
Block(4,71,2,LEAVES:7)
Block(4,71,3,LEAVES:7)
Block(4,71,4,LEAVES:7)
Block(4,72,-6,LEAVES:7)
Block(4,72,-5,LEAVES:7)
Block(4,72,-4,LEAVES:7)
Block(4,72,-3,LEAVES:7)
Block(4,72,-2,LEAVES:7)
Block(4,72,-1,LOG:15)
Block(4,72,0,LEAVES:7)
Block(4,72,1,LEAVES:7)
Block(4,72,2,LEAVES:7)
Block(4,72,8,LEAVES:7)
Block(4,73,-6,LEAVES:7)
Block(4,73,-5,LEAVES:7)
Block(4,73,-4,LEAVES:7)
Block(4,73,-2,LEAVES:7)
Block(4,73,-1,LEAVES:7)
Block(4,73,0,LEAVES:7)
Block(4,73,1,LEAVES:7)
Block(4,73,2,LEAVES:7)
Block(4,73,3,LEAVES:7)
Block(4,73,4,LEAVES:7)
Block(4,73,5,LEAVES:7)
Block(4,73,6,LEAVES:7)
Block(4,73,7,LEAVES:7)
Block(4,73,8,LEAVES:7)
Block(4,74,-7,LEAVES:7)
Block(4,74,-6,LEAVES:7)
Block(4,74,-5,LEAVES:7)
Block(4,74,-4,LEAVES:7)
Block(4,74,-3,LEAVES:7)
Block(4,74,-2,LEAVES:7)
Block(4,74,0,LEAVES:7)
Block(4,74,1,LEAVES:7)
Block(4,74,2,LEAVES:7)
Block(4,74,3,LEAVES:7)
Block(4,74,4,LEAVES:7)
Block(4,74,6,LEAVES:7)
Block(4,74,7,LEAVES:7)
Block(4,74,8,LEAVES:7)
Block(4,75,-6,LEAVES:7)
Block(4,75,-5,LEAVES:7)
Block(4,75,-4,LEAVES:7)
Block(4,75,-3,LEAVES:7)
Block(4,75,-2,LEAVES:7)
Block(4,75,0,LEAVES:7)
Block(4,75,1,LEAVES:7)
Block(4,75,2,LEAVES:7)
Block(4,75,3,LEAVES:7)
Block(4,75,7,LEAVES:7)
Block(4,75,8,LEAVES:7)
Block(4,76,-4,LEAVES:7)
Block(4,76,-3,LEAVES:7)
Block(4,76,-2,LEAVES:7)
Block(4,76,0,LEAVES:7)
Block(4,76,1,LEAVES:7)
Block(4,76,2,LEAVES:7)
Block(4,76,3,LEAVES:7)
Block(4,76,4,LEAVES:7)
Block(4,76,5,LEAVES:7)
Block(4,76,6,LEAVES:7)
Block(4,76,8,LEAVES:7)
Block(4,77,-3,LEAVES:7)
Block(4,77,0,LEAVES:7)
Block(4,77,1,LEAVES:7)
Block(4,77,2,LEAVES:7)
Block(4,77,3,LEAVES:7)
Block(4,77,4,LEAVES:7)
Block(4,77,5,LEAVES:7)
Block(4,77,6,LEAVES:7)
Block(4,77,7,LEAVES:7)
Block(4,77,8,LEAVES:7)
Block(4,78,0,LEAVES:7)
Block(4,78,1,LEAVES:7)
Block(4,78,2,LEAVES:7)
Block(4,78,3,LEAVES:7)
Block(4,78,4,LEAVES:7)
Block(4,78,5,LEAVES:7)
Block(4,78,6,LEAVES:7)
Block(4,78,7,LEAVES:7)
Block(4,78,8,LEAVES:7)
Block(4,79,1,LEAVES:7)
Block(4,79,2,LEAVES:7)
Block(4,79,3,LEAVES:7)
Block(4,79,4,LEAVES:7)
Block(4,79,5,LEAVES:7)
Block(4,79,7,LEAVES:7)
Block(4,79,8,LEAVES:7)
Block(4,80,2,LEAVES:7)
Block(4,80,3,LEAVES:7)
Block(4,80,4,LEAVES:7)
Block(4,80,5,LEAVES:7)
Block(4,80,8,LEAVES:7)
Block(5,-5,-5,LOG:15)
Block(5,-5,-4,LOG:15)
Block(5,-5,-3,LOG:15)
Block(5,-5,0,LOG:15)
Block(5,-5,1,LOG:15)
Block(5,-5,2,LOG:15)
Block(5,-4,-4,LOG:15)
Block(5,-4,0,LOG:15)
Block(5,-4,1,LOG:15)
Block(5,-4,2,LOG:15)
Block(5,-4,3,LOG:15)
Block(5,-3,0,LOG:15)
Block(5,-3,1,LOG:15)
Block(5,-3,2,LOG:15)
Block(5,-3,8,LOG:15)
Block(5,19,6,LOG:15)
Block(5,20,5,LOG:15)
Block(5,20,6,LOG:15)
Block(5,20,7,LOG:15)
Block(5,21,5,LOG:15)
Block(5,21,6,LOG:15)
Block(5,21,7,LOG:15)
Block(5,21,8,LOG:15)
Block(5,22,5,LOG:15)
Block(5,22,6,LOG:15)
Block(5,22,7,LOG:15)
Block(5,22,8,LOG:15)
Block(5,23,6,LOG:15)
Block(5,23,7,LOG:15)
Block(5,23,8,LOG:15)
Block(5,24,6,LOG:15)
Block(5,24,7,LOG:15)
Block(5,24,8,LOG:15)
Block(5,25,7,LOG:15)
Block(5,25,8,minecraft:black_glazed_terracotta:0)
Block(5,54,5,minecraft:black_glazed_terracotta:0)
Block(5,54,6,minecraft:black_glazed_terracotta:0)
Block(5,54,7,minecraft:gray_glazed_terracotta:0)
Block(5,59,5,minecraft:black_glazed_terracotta:0)
Block(5,60,5,minecraft:black_glazed_terracotta:0)
Block(5,61,5,LEAVES:7)
Block(5,61,6,LEAVES:7)
Block(5,61,7,LEAVES:7)
Block(5,62,1,LEAVES:7)
Block(5,62,2,LEAVES:7)
Block(5,62,3,LEAVES:7)
Block(5,62,4,LEAVES:7)
Block(5,62,5,LEAVES:7)
Block(5,62,6,LEAVES:7)
Block(5,62,7,LEAVES:7)
Block(5,62,8,LEAVES:7)
Block(5,63,0,LEAVES:7)
Block(5,63,1,LEAVES:7)
Block(5,63,2,LEAVES:7)
Block(5,63,3,LEAVES:7)
Block(5,63,4,LEAVES:7)
Block(5,63,5,LEAVES:7)
Block(5,63,6,LEAVES:7)
Block(5,63,7,LEAVES:7)
Block(5,64,1,LEAVES:7)
Block(5,64,2,LEAVES:7)
Block(5,64,3,LEAVES:7)
Block(5,64,4,LEAVES:7)
Block(5,64,5,LEAVES:7)
Block(5,64,6,LEAVES:7)
Block(5,64,7,LEAVES:7)
Block(5,65,2,LEAVES:7)
Block(5,65,3,LEAVES:7)
Block(5,65,4,LEAVES:7)
Block(5,65,5,LEAVES:7)
Block(5,65,6,LOG:15)
Block(5,65,7,LEAVES:7)
Block(5,66,3,LEAVES:7)
Block(5,66,6,LEAVES:7)
Block(5,66,7,LEAVES:7)
Block(5,67,6,LEAVES:7)
Block(5,67,8,LEAVES:7)
Block(5,68,2,LEAVES:7)
Block(5,69,1,LEAVES:7)
Block(5,69,2,LEAVES:7)
Block(5,69,3,LEAVES:7)
Block(5,69,4,LEAVES:7)
Block(5,70,-1,LEAVES:7)
Block(5,70,0,LEAVES:7)
Block(5,70,1,LEAVES:7)
Block(5,70,2,LEAVES:7)
Block(5,70,4,LEAVES:7)
Block(5,70,8,minecraft:black_glazed_terracotta:0)
Block(5,71,-4,LEAVES:7)
Block(5,71,-3,LEAVES:7)
Block(5,71,-2,LEAVES:7)
Block(5,71,-1,LEAVES:7)
Block(5,71,0,LEAVES:7)
Block(5,71,1,LEAVES:7)
Block(5,71,2,LEAVES:7)
Block(5,71,3,LEAVES:7)
Block(5,71,4,LEAVES:7)
Block(5,71,5,LEAVES:7)
Block(5,71,7,minecraft:black_glazed_terracotta:0)
Block(5,71,8,minecraft:black_glazed_terracotta:0)
Block(5,72,-5,LEAVES:7)
Block(5,72,-4,LEAVES:7)
Block(5,72,-3,LEAVES:7)
Block(5,72,-2,LEAVES:7)
Block(5,72,-1,LEAVES:7)
Block(5,72,0,LEAVES:7)
Block(5,72,1,LEAVES:7)
Block(5,72,2,LEAVES:7)
Block(5,73,-6,LEAVES:7)
Block(5,73,-5,LEAVES:7)
Block(5,73,-4,LEAVES:7)
Block(5,73,-3,LEAVES:7)
Block(5,73,-2,LEAVES:7)
Block(5,73,-1,LEAVES:7)
Block(5,73,0,LEAVES:7)
Block(5,73,1,LEAVES:7)
Block(5,73,2,LEAVES:7)
Block(5,73,3,LEAVES:7)
Block(5,73,5,LEAVES:7)
Block(5,73,7,LEAVES:7)
Block(5,73,8,LOG:15)
Block(5,74,-6,LEAVES:7)
Block(5,74,-5,LEAVES:7)
Block(5,74,-3,LEAVES:7)
Block(5,74,-2,LEAVES:7)
Block(5,74,-1,LEAVES:7)
Block(5,74,1,LEAVES:7)
Block(5,74,2,LEAVES:7)
Block(5,74,3,LEAVES:7)
Block(5,74,4,LEAVES:7)
Block(5,74,5,LEAVES:7)
Block(5,74,6,LEAVES:7)
Block(5,75,-5,LEAVES:7)
Block(5,75,-4,LEAVES:7)
Block(5,75,-3,LEAVES:7)
Block(5,75,-2,LEAVES:7)
Block(5,75,-1,LEAVES:7)
Block(5,75,0,LEAVES:7)
Block(5,75,1,LEAVES:7)
Block(5,75,2,LEAVES:7)
Block(5,75,5,LEAVES:7)
Block(5,75,6,LEAVES:7)
Block(5,75,8,LEAVES:7)
Block(5,76,-3,LEAVES:7)
Block(5,76,0,LEAVES:7)
Block(5,76,1,LEAVES:7)
Block(5,76,2,LEAVES:7)
Block(5,76,3,LEAVES:7)
Block(5,76,4,LEAVES:7)
Block(5,76,5,LEAVES:7)
Block(5,76,6,LEAVES:7)
Block(5,76,8,LEAVES:7)
Block(5,77,0,LEAVES:7)
Block(5,77,1,LEAVES:7)
Block(5,77,2,LEAVES:7)
Block(5,77,3,LEAVES:7)
Block(5,77,4,LEAVES:7)
Block(5,77,5,LEAVES:7)
Block(5,77,6,LEAVES:7)
Block(5,77,7,LEAVES:7)
Block(5,77,8,LEAVES:7)
Block(5,78,1,LEAVES:7)
Block(5,78,2,LEAVES:7)
Block(5,78,3,LEAVES:7)
Block(5,78,4,LEAVES:7)
Block(5,78,5,LEAVES:7)
Block(5,78,6,LEAVES:7)
Block(5,78,7,LEAVES:7)
Block(5,78,8,LEAVES:7)
Block(5,79,1,LEAVES:7)
Block(5,79,2,LEAVES:7)
Block(5,79,3,LEAVES:7)
Block(5,79,4,LEAVES:7)
Block(5,79,5,LEAVES:7)
Block(5,79,6,LEAVES:7)
Block(5,79,7,LEAVES:7)
Block(5,79,8,LEAVES:7)
Block(5,80,2,LEAVES:7)
Block(5,80,3,LEAVES:7)
Block(5,80,4,LEAVES:7)
Block(5,80,7,LEAVES:7)
Block(5,80,8,LEAVES:7)
Block(6,-5,-1,LOG:15)
Block(6,-5,0,LOG:15)
Block(6,-5,1,LOG:15)
Block(6,-5,2,LOG:15)
Block(6,-4,0,LOG:15)
Block(6,-4,1,LOG:15)
Block(6,-4,2,LOG:15)
Block(6,-3,1,LOG:15)
Block(6,18,6,LOG:15)
Block(6,19,5,LOG:15)
Block(6,19,6,LOG:15)
Block(6,19,7,LOG:15)
Block(6,20,5,LOG:15)
Block(6,20,6,LOG:15)
Block(6,20,7,LOG:15)
Block(6,21,5,LOG:15)
Block(6,21,6,LOG:15)
Block(6,21,7,LOG:15)
Block(6,22,6,minecraft:gray_glazed_terracotta:0)
Block(6,22,7,LOG:15)
Block(6,22,8,LOG:15)
Block(6,23,7,minecraft:black_glazed_terracotta:0)
Block(6,23,8,LOG:15)
Block(6,24,7,LOG:15)
Block(6,24,8,minecraft:gray_glazed_terracotta:0)
Block(6,25,8,minecraft:gray_glazed_terracotta:0)
Block(6,54,5,minecraft:black_glazed_terracotta:0)
Block(6,55,4,minecraft:black_glazed_terracotta:0)
Block(6,58,6,minecraft:black_glazed_terracotta:0)
Block(6,59,5,minecraft:black_glazed_terracotta:0)
Block(6,59,6,minecraft:black_glazed_terracotta:0)
Block(6,61,1,LEAVES:7)
Block(6,61,2,LEAVES:7)
Block(6,61,3,LEAVES:7)
Block(6,61,4,LEAVES:7)
Block(6,61,5,LEAVES:7)
Block(6,61,7,LEAVES:7)
Block(6,62,0,LEAVES:7)
Block(6,62,1,LEAVES:7)
Block(6,62,2,LEAVES:7)
Block(6,62,3,LEAVES:7)
Block(6,62,4,LEAVES:7)
Block(6,62,5,LEAVES:7)
Block(6,62,7,LEAVES:7)
Block(6,63,0,LEAVES:7)
Block(6,63,1,LEAVES:7)
Block(6,63,2,LEAVES:7)
Block(6,63,3,LEAVES:7)
Block(6,63,4,LEAVES:7)
Block(6,63,5,LEAVES:7)
Block(6,64,0,LEAVES:7)
Block(6,64,1,LEAVES:7)
Block(6,64,2,LEAVES:7)
Block(6,64,3,LEAVES:7)
Block(6,64,5,LEAVES:7)
Block(6,64,6,LEAVES:7)
Block(6,64,7,LEAVES:7)
Block(6,64,8,LEAVES:7)
Block(6,65,1,LEAVES:7)
Block(6,65,2,LEAVES:7)
Block(6,65,3,LEAVES:7)
Block(6,65,4,LEAVES:7)
Block(6,65,5,LEAVES:7)
Block(6,65,6,LEAVES:7)
Block(6,65,7,LEAVES:7)
Block(6,65,8,LEAVES:7)
Block(6,66,2,LEAVES:7)
Block(6,66,3,LEAVES:7)
Block(6,66,5,LEAVES:7)
Block(6,66,6,LEAVES:7)
Block(6,66,7,LEAVES:7)
Block(6,67,7,LEAVES:7)
Block(6,69,1,LEAVES:7)
Block(6,69,2,LEAVES:7)
Block(6,69,3,LEAVES:7)
Block(6,69,4,LEAVES:7)
Block(6,70,-2,LEAVES:7)
Block(6,70,-1,LEAVES:7)
Block(6,70,0,LEAVES:7)
Block(6,70,1,LEAVES:7)
Block(6,70,2,LEAVES:7)
Block(6,70,3,LEAVES:7)
Block(6,70,4,LEAVES:7)
Block(6,70,7,LOG:15)
Block(6,70,8,LEAVES:7)
Block(6,71,-3,LEAVES:7)
Block(6,71,-2,LEAVES:7)
Block(6,71,-1,LEAVES:7)
Block(6,71,0,LEAVES:7)
Block(6,71,1,LEAVES:7)
Block(6,71,2,LEAVES:7)
Block(6,71,4,LEAVES:7)
Block(6,71,5,LEAVES:7)
Block(6,71,6,LEAVES:7)
Block(6,71,7,LOG:15)
Block(6,71,8,LEAVES:7)
Block(6,72,-2,LEAVES:7)
Block(6,72,-1,LEAVES:7)
Block(6,72,0,LEAVES:7)
Block(6,72,1,LEAVES:7)
Block(6,72,2,LEAVES:7)
Block(6,72,3,LEAVES:7)
Block(6,72,4,LEAVES:7)
Block(6,72,5,LEAVES:7)
Block(6,72,6,minecraft:black_glazed_terracotta:0)
Block(6,72,7,LEAVES:7)
Block(6,73,-2,LEAVES:7)
Block(6,73,-1,LEAVES:7)
Block(6,73,0,LEAVES:7)
Block(6,73,1,LEAVES:7)
Block(6,73,2,LEAVES:7)
Block(6,73,3,LEAVES:7)
Block(6,73,4,LEAVES:7)
Block(6,73,8,LEAVES:7)
Block(6,74,-2,LEAVES:7)
Block(6,74,-1,LEAVES:7)
Block(6,74,2,LEAVES:7)
Block(6,74,4,LEAVES:7)
Block(6,74,5,LEAVES:7)
Block(6,74,6,LEAVES:7)
Block(6,74,8,LEAVES:7)
Block(6,75,-1,LEAVES:7)
Block(6,75,2,LEAVES:7)
Block(6,75,3,LEAVES:7)
Block(6,75,4,LEAVES:7)
Block(6,75,5,LEAVES:7)
Block(6,75,6,LEAVES:7)
Block(6,75,8,LEAVES:7)
Block(6,76,1,LEAVES:7)
Block(6,76,2,LEAVES:7)
Block(6,76,3,LEAVES:7)
Block(6,76,4,LEAVES:7)
Block(6,76,5,LEAVES:7)
Block(6,76,6,LEAVES:7)
Block(6,76,8,LEAVES:7)
Block(6,77,1,LEAVES:7)
Block(6,77,2,LEAVES:7)
Block(6,77,3,LEAVES:7)
Block(6,77,4,LEAVES:7)
Block(6,77,5,LEAVES:7)
Block(6,77,6,LEAVES:7)
Block(6,77,7,LEAVES:7)
Block(6,77,8,LEAVES:7)
Block(6,78,1,LEAVES:7)
Block(6,78,2,LEAVES:7)
Block(6,78,3,LEAVES:7)
Block(6,78,4,LEAVES:7)
Block(6,78,5,LEAVES:7)
Block(6,78,6,LEAVES:7)
Block(6,78,7,LEAVES:7)
Block(6,78,8,LEAVES:7)
Block(6,79,2,LEAVES:7)
Block(6,79,3,LEAVES:7)
Block(6,79,5,LEAVES:7)
Block(6,79,6,LEAVES:7)
Block(6,79,7,LEAVES:7)
Block(6,79,8,LEAVES:7)
Block(6,80,7,LEAVES:7)
Block(6,80,8,LEAVES:7)
Block(7,-5,-2,LOG:15)
Block(7,-5,-1,LOG:15)
Block(7,-5,0,LOG:15)
Block(7,17,6,LOG:15)
Block(7,18,5,LOG:15)
Block(7,18,6,LOG:15)
Block(7,18,7,LOG:15)
Block(7,19,5,LOG:15)
Block(7,19,6,LOG:15)
Block(7,19,7,LOG:15)
Block(7,20,5,LOG:15)
Block(7,20,6,LOG:15)
Block(7,20,7,LOG:15)
Block(7,21,6,minecraft:black_glazed_terracotta:0)
Block(7,55,3,minecraft:black_glazed_terracotta:0)
Block(7,55,4,minecraft:black_glazed_terracotta:0)
Block(7,56,3,minecraft:black_glazed_terracotta:0)
Block(7,56,7,minecraft:black_glazed_terracotta:0)
Block(7,57,7,minecraft:black_glazed_terracotta:0)
Block(7,58,6,minecraft:black_glazed_terracotta:0)
Block(7,60,2,LEAVES:7)
Block(7,61,0,LEAVES:7)
Block(7,61,1,LEAVES:7)
Block(7,61,2,LEAVES:7)
Block(7,61,3,LEAVES:7)
Block(7,61,4,LEAVES:7)
Block(7,61,5,LEAVES:7)
Block(7,61,6,LEAVES:7)
Block(7,62,0,LEAVES:7)
Block(7,62,1,LEAVES:7)
Block(7,62,2,LEAVES:7)
Block(7,62,3,LEAVES:7)
Block(7,62,5,LEAVES:7)
Block(7,62,6,LEAVES:7)
Block(7,63,0,LEAVES:7)
Block(7,63,1,LEAVES:7)
Block(7,63,2,LEAVES:7)
Block(7,63,3,LOG:15)
Block(7,63,4,LOG:15)
Block(7,63,7,LEAVES:7)
Block(7,64,0,LEAVES:7)
Block(7,64,1,LEAVES:7)
Block(7,64,2,LEAVES:7)
Block(7,64,3,LEAVES:7)
Block(7,64,4,LEAVES:7)
Block(7,64,5,LOG:15)
Block(7,64,6,LOG:15)
Block(7,64,7,LEAVES:7)
Block(7,65,1,LEAVES:7)
Block(7,65,2,LEAVES:7)
Block(7,65,3,LEAVES:7)
Block(7,65,4,LEAVES:7)
Block(7,66,2,LEAVES:7)
Block(7,66,3,LEAVES:7)
Block(7,66,6,LEAVES:7)
Block(7,66,7,LEAVES:7)
Block(7,67,5,LEAVES:7)
Block(7,67,7,LEAVES:7)
Block(7,67,8,LEAVES:7)
Block(7,69,2,LEAVES:7)
Block(7,69,3,LEAVES:7)
Block(7,69,4,LEAVES:7)
Block(7,69,5,LEAVES:7)
Block(7,69,7,LEAVES:7)
Block(7,69,8,LEAVES:7)
Block(7,70,1,LEAVES:7)
Block(7,70,2,LEAVES:7)
Block(7,70,3,LEAVES:7)
Block(7,70,4,LEAVES:7)
Block(7,70,5,LEAVES:7)
Block(7,70,6,LEAVES:7)
Block(7,70,7,LEAVES:7)
Block(7,70,8,LOG:15)
Block(7,71,-2,LEAVES:7)
Block(7,71,-1,LEAVES:7)
Block(7,71,0,LEAVES:7)
Block(7,71,2,LEAVES:7)
Block(7,71,3,LEAVES:7)
Block(7,71,4,LEAVES:7)
Block(7,71,5,LEAVES:7)
Block(7,71,6,LEAVES:7)
Block(7,71,7,LEAVES:7)
Block(7,71,8,LEAVES:7)
Block(7,72,-2,LEAVES:7)
Block(7,72,-1,LEAVES:7)
Block(7,72,0,LEAVES:7)
Block(7,72,1,LEAVES:7)
Block(7,72,2,LEAVES:7)
Block(7,72,3,LEAVES:7)
Block(7,72,4,LEAVES:7)
Block(7,72,5,minecraft:black_glazed_terracotta:0)
Block(7,72,6,LEAVES:7)
Block(7,72,7,LEAVES:7)
Block(7,72,8,LEAVES:7)
Block(7,73,-2,LEAVES:7)
Block(7,73,-1,LEAVES:7)
Block(7,73,0,LEAVES:7)
Block(7,73,3,LEAVES:7)
Block(7,73,4,LEAVES:7)
Block(7,73,5,LEAVES:7)
Block(7,73,6,LEAVES:7)
Block(7,73,7,LOG:15)
Block(7,73,8,LOG:15)
Block(7,74,-1,LEAVES:7)
Block(7,74,2,LEAVES:7)
Block(7,74,3,LEAVES:7)
Block(7,74,4,LEAVES:7)
Block(7,74,5,LEAVES:7)
Block(7,74,7,LEAVES:7)
Block(7,75,-1,LEAVES:7)
Block(7,75,3,LEAVES:7)
Block(7,75,4,LEAVES:7)
Block(7,75,5,LEAVES:7)
Block(7,75,6,LEAVES:7)
Block(7,75,7,LEAVES:7)
Block(7,75,8,LEAVES:7)
Block(7,76,2,LEAVES:7)
Block(7,76,3,LEAVES:7)
Block(7,76,4,LEAVES:7)
Block(7,76,5,LEAVES:7)
Block(7,76,6,LEAVES:7)
Block(7,76,7,LEAVES:7)
Block(7,76,8,LEAVES:7)
Block(7,77,2,LEAVES:7)
Block(7,77,3,LEAVES:7)
Block(7,77,4,LEAVES:7)
Block(7,77,5,LEAVES:7)
Block(7,77,6,LEAVES:7)
Block(7,77,7,LEAVES:7)
Block(7,77,8,LEAVES:7)
Block(7,78,2,LEAVES:7)
Block(7,78,3,LEAVES:7)
Block(7,78,4,LEAVES:7)
Block(7,78,5,LEAVES:7)
Block(7,78,6,LEAVES:7)
Block(7,78,7,LEAVES:7)
Block(7,78,8,LEAVES:7)
Block(7,79,5,LEAVES:7)
Block(7,79,6,LEAVES:7)
Block(7,79,7,LEAVES:7)
Block(7,79,8,LEAVES:7)
Block(7,80,6,LEAVES:7)
Block(7,80,7,LEAVES:7)
Block(7,80,8,LEAVES:7)

#######################################################################
# +-----------------------------------------------------------------+ #
# |                             Branches                            | #
# +-----------------------------------------------------------------+ #
#######################################################################

Branch(16,0,0,true,CorruptedJungleGiant01C2R0,NORTH,100.0,0)

#######################################################################
# +-----------------------------------------------------------------+ #
# |                             Entities                            | #
# +-----------------------------------------------------------------+ #
#######################################################################


#######################################################################
# +-----------------------------------------------------------------+ #
# |                            Particles                            | #
# +-----------------------------------------------------------------+ #
#######################################################################


#######################################################################
# +-----------------------------------------------------------------+ #
# |                             Spawners                            | #
# +-----------------------------------------------------------------+ #
#######################################################################


#######################################################################
# +-----------------------------------------------------------------+ #
# |                             ModData                             | #
# +-----------------------------------------------------------------+ #
#######################################################################

