
#######################################################################
# +-----------------------------------------------------------------+ #
# |                            BO4 object                           | #
# +-----------------------------------------------------------------+ #
#######################################################################

Author: NLBlackEagle

Description: No description given

SettingsMode: WriteDisable


#######################################################################
# +-----------------------------------------------------------------+ #
# |                          Main settings                          | #
# +-----------------------------------------------------------------+ #
#######################################################################

Frequency: 0

SpawnHeight: highestBlock

UseCenterForHighestBlock: true

##############################
# Height Limits for the BO4. #
##############################

MinHeight: 0

MaxHeight: 255

InheritBO3: 

InheritBO3Rotation: NORTH

OverrideChildSettings: true

OverrideParentHeight: false

CanOverride: true

BranchFrequency: 0

BranchFrequencyGroup: 

MustBeBelowOther: false

MustBeInside: 

CannotBeInside: 

ReplacesBO3: 

MustBeInsideWorldBorders: false

CanSpawnOnWater: true

SpawnOnWaterOnly: false

SpawnUnderWater: false

SpawnAtWaterLevel: false

HeightOffset: 0

RemoveAir: true

ReplaceAbove: 

ReplaceBelow: 

ReplaceWithBiomeBlocks: true

ReplaceWithSurfaceBlock: GRASS

ReplaceWithGroundBlock: DIRT

ReplaceWithStoneBlock: STONE

SmoothRadius: 0

SmoothHeightOffset: 0

SmoothStartTop: false

SmoothStartWood: false

SmoothingSurfaceBlock: 

SmoothingGroundBlock: 

BO3Group: 

IsSpawnPoint: false

DoReplaceBlocks: true


#######################################################################
# +-----------------------------------------------------------------+ #
# |                              Blocks                             | #
# +-----------------------------------------------------------------+ #
#######################################################################

Block(-8,-5,-4,LOG:15)
Block(-8,-5,-3,LOG:15)
Block(-8,-5,-2,LOG:15)
Block(-8,-5,-1,LOG:15)
Block(-8,-4,-3,LOG:15)
Block(-8,16,6,LOG:15)
Block(-8,17,5,LOG:15)
Block(-8,17,6,LOG:15)
Block(-8,17,7,LOG:15)
Block(-8,18,5,LOG:15)
Block(-8,18,6,LOG:15)
Block(-8,18,7,LOG:15)
Block(-8,19,5,minecraft:black_glazed_terracotta:0)
Block(-8,19,6,LOG:15)
Block(-8,19,7,LOG:15)
Block(-8,20,6,minecraft:black_glazed_terracotta:0)
Block(-8,55,8,minecraft:gray_glazed_terracotta:0)
Block(-8,56,2,minecraft:black_glazed_terracotta:0)
Block(-8,56,3,minecraft:black_glazed_terracotta:0)
Block(-8,56,7,minecraft:black_glazed_terracotta:0)
Block(-8,56,8,minecraft:gray_glazed_terracotta:0)
Block(-8,57,2,minecraft:black_glazed_terracotta:0)
Block(-8,59,4,LEAVES:7)
Block(-8,59,5,LEAVES:7)
Block(-8,60,0,LEAVES:7)
Block(-8,60,1,LEAVES:7)
Block(-8,60,2,LEAVES:7)
Block(-8,60,5,LEAVES:7)
Block(-8,60,6,LEAVES:7)
Block(-8,61,-1,LEAVES:7)
Block(-8,61,0,LEAVES:7)
Block(-8,61,1,LEAVES:7)
Block(-8,61,2,LEAVES:7)
Block(-8,61,3,LEAVES:7)
Block(-8,61,4,LEAVES:7)
Block(-8,61,5,LEAVES:7)
Block(-8,62,0,LEAVES:7)
Block(-8,62,1,LEAVES:7)
Block(-8,62,2,LEAVES:7)
Block(-8,62,3,LOG:15)
Block(-8,62,4,LEAVES:7)
Block(-8,62,5,LEAVES:7)
Block(-8,62,6,LEAVES:7)
Block(-8,62,7,LEAVES:7)
Block(-8,62,8,LEAVES:7)
Block(-8,63,0,LEAVES:7)
Block(-8,63,1,LEAVES:7)
Block(-8,63,2,LEAVES:7)
Block(-8,63,3,LOG:15)
Block(-8,63,5,LEAVES:7)
Block(-8,63,7,LEAVES:7)
Block(-8,63,8,LEAVES:7)
Block(-8,64,-1,LEAVES:7)
Block(-8,64,0,LEAVES:7)
Block(-8,64,1,LEAVES:7)
Block(-8,64,2,LEAVES:7)
Block(-8,64,3,LEAVES:7)
Block(-8,64,4,LEAVES:7)
Block(-8,64,5,LEAVES:7)
Block(-8,64,6,LEAVES:7)
Block(-8,64,7,LEAVES:7)
Block(-8,65,0,LEAVES:7)
Block(-8,65,1,LEAVES:7)
Block(-8,65,2,LEAVES:7)
Block(-8,65,3,LEAVES:7)
Block(-8,65,4,LEAVES:7)
Block(-8,65,5,LEAVES:7)
Block(-8,66,6,LEAVES:7)
Block(-8,66,7,LEAVES:7)
Block(-8,68,8,LEAVES:7)
Block(-8,69,8,LEAVES:7)
Block(-8,70,3,LEAVES:7)
Block(-8,70,4,LEAVES:7)
Block(-8,70,5,LEAVES:7)
Block(-8,70,6,LEAVES:7)
Block(-8,70,7,LEAVES:7)
Block(-8,70,8,LEAVES:7)
Block(-8,71,3,LEAVES:7)
Block(-8,71,4,LEAVES:7)
Block(-8,71,5,LEAVES:7)
Block(-8,71,6,LEAVES:7)
Block(-8,71,7,LEAVES:7)
Block(-8,71,8,LEAVES:7)
Block(-8,72,1,LEAVES:7)
Block(-8,72,2,LEAVES:7)
Block(-8,72,3,LEAVES:7)
Block(-8,72,4,LEAVES:7)
Block(-8,72,5,minecraft:black_glazed_terracotta:0)
Block(-8,72,6,LEAVES:7)
Block(-8,72,7,LEAVES:7)
Block(-8,72,8,LEAVES:7)
Block(-8,73,2,LEAVES:7)
Block(-8,73,3,LEAVES:7)
Block(-8,73,4,LEAVES:7)
Block(-8,73,5,LEAVES:7)
Block(-8,73,6,LEAVES:7)
Block(-8,73,7,LEAVES:7)
Block(-8,73,8,LOG:15)
Block(-8,74,3,LEAVES:7)
Block(-8,74,4,LEAVES:7)
Block(-8,74,5,LEAVES:7)
Block(-8,74,6,LEAVES:7)
Block(-8,74,7,LEAVES:7)
Block(-8,74,8,LOG:15)
Block(-8,75,3,LEAVES:7)
Block(-8,75,4,LEAVES:7)
Block(-8,75,5,LEAVES:7)
Block(-8,75,6,LEAVES:7)
Block(-8,75,8,LEAVES:7)
Block(-8,76,3,LEAVES:7)
Block(-8,76,4,LEAVES:7)
Block(-8,76,5,LEAVES:7)
Block(-8,76,6,LEAVES:7)
Block(-8,76,7,LEAVES:7)
Block(-8,76,8,LEAVES:7)
Block(-8,77,2,LEAVES:7)
Block(-8,77,3,LEAVES:7)
Block(-8,77,4,LEAVES:7)
Block(-8,77,5,LEAVES:7)
Block(-8,77,6,LEAVES:7)
Block(-8,77,7,LEAVES:7)
Block(-8,78,3,LEAVES:7)
Block(-8,78,4,LEAVES:7)
Block(-8,78,5,LEAVES:7)
Block(-8,78,6,LEAVES:7)
Block(-8,78,7,LEAVES:7)
Block(-8,78,8,LEAVES:7)
Block(-8,79,4,LEAVES:7)
Block(-8,79,5,LEAVES:7)
Block(-8,79,6,LEAVES:7)
Block(-8,79,7,LEAVES:7)
Block(-8,79,8,LEAVES:7)
Block(-8,80,6,LEAVES:7)
Block(-8,80,7,LEAVES:7)
Block(-8,80,8,LEAVES:7)
Block(-7,-5,-4,LOG:15)
Block(-7,-5,-3,LOG:15)
Block(-7,-5,-2,LOG:15)
Block(-7,-5,-1,LOG:15)
Block(-7,-4,-4,LOG:15)
Block(-7,-4,-3,LOG:15)
Block(-7,-4,-2,LOG:15)
Block(-7,15,6,LOG:15)
Block(-7,16,5,LOG:15)
Block(-7,16,6,LOG:15)
Block(-7,16,7,LOG:15)
Block(-7,17,5,minecraft:black_glazed_terracotta:0)
Block(-7,17,6,LOG:15)
Block(-7,17,7,LOG:15)
Block(-7,18,5,minecraft:black_glazed_terracotta:0)
Block(-7,18,6,LOG:15)
Block(-7,18,7,LOG:15)
Block(-7,19,6,LOG:15)
Block(-7,54,8,minecraft:gray_glazed_terracotta:0)
Block(-7,55,8,minecraft:gray_glazed_terracotta:0)
Block(-7,57,1,minecraft:black_glazed_terracotta:0)
Block(-7,57,2,minecraft:black_glazed_terracotta:0)
Block(-7,58,1,minecraft:black_glazed_terracotta:0)
Block(-7,59,1,LEAVES:7)
Block(-7,60,-1,LEAVES:7)
Block(-7,60,0,LEAVES:7)
Block(-7,60,1,LEAVES:7)
Block(-7,60,2,LEAVES:7)
Block(-7,60,3,LEAVES:7)
Block(-7,60,5,LEAVES:7)
Block(-7,61,-2,LEAVES:7)
Block(-7,61,-1,LEAVES:7)
Block(-7,61,0,LEAVES:7)
Block(-7,61,1,LEAVES:7)
Block(-7,61,2,LEAVES:7)
Block(-7,61,4,LEAVES:7)
Block(-7,61,5,LEAVES:7)
Block(-7,61,8,LEAVES:7)
Block(-7,62,-3,LEAVES:7)
Block(-7,62,-2,LEAVES:7)
Block(-7,62,-1,LEAVES:7)
Block(-7,62,0,LEAVES:7)
Block(-7,62,1,LEAVES:7)
Block(-7,62,2,LOG:15)
Block(-7,62,3,LEAVES:7)
Block(-7,62,4,LEAVES:7)
Block(-7,62,5,LEAVES:7)
Block(-7,62,6,LEAVES:7)
Block(-7,62,7,LEAVES:7)
Block(-7,62,8,LEAVES:7)
Block(-7,63,-3,LEAVES:7)
Block(-7,63,-2,LEAVES:7)
Block(-7,63,-1,LEAVES:7)
Block(-7,63,0,LEAVES:7)
Block(-7,63,1,LEAVES:7)
Block(-7,63,2,LEAVES:7)
Block(-7,63,3,LEAVES:7)
Block(-7,63,4,LEAVES:7)
Block(-7,63,5,LEAVES:7)
Block(-7,63,6,LEAVES:7)
Block(-7,63,7,LEAVES:7)
Block(-7,63,8,LEAVES:7)
Block(-7,64,-2,LEAVES:7)
Block(-7,64,-1,LEAVES:7)
Block(-7,64,0,LEAVES:7)
Block(-7,64,1,LEAVES:7)
Block(-7,64,2,LEAVES:7)
Block(-7,64,3,LEAVES:7)
Block(-7,64,4,LEAVES:7)
Block(-7,64,5,LEAVES:7)
Block(-7,64,6,LEAVES:7)
Block(-7,64,7,LOG:15)
Block(-7,64,8,LEAVES:7)
Block(-7,65,1,LEAVES:7)
Block(-7,65,2,LEAVES:7)
Block(-7,65,4,LEAVES:7)
Block(-7,65,7,LEAVES:7)
Block(-7,65,8,LEAVES:7)
Block(-7,66,6,LEAVES:7)
Block(-7,68,8,LEAVES:7)
Block(-7,69,7,LEAVES:7)
Block(-7,69,8,LEAVES:7)
Block(-7,70,6,LEAVES:7)
Block(-7,70,7,LEAVES:7)
Block(-7,70,8,LEAVES:7)
Block(-7,71,2,LEAVES:7)
Block(-7,71,3,LEAVES:7)
Block(-7,71,4,LEAVES:7)
Block(-7,71,5,LEAVES:7)
Block(-7,71,6,LEAVES:7)
Block(-7,71,7,LEAVES:7)
Block(-7,71,8,LEAVES:7)
Block(-7,72,1,LEAVES:7)
Block(-7,72,2,LEAVES:7)
Block(-7,72,3,LEAVES:7)
Block(-7,72,4,LEAVES:7)
Block(-7,72,5,LEAVES:7)
Block(-7,72,6,LEAVES:7)
Block(-7,72,7,LEAVES:7)
Block(-7,72,8,LEAVES:7)
Block(-7,73,0,LEAVES:7)
Block(-7,73,1,LEAVES:7)
Block(-7,73,2,LEAVES:7)
Block(-7,73,3,LEAVES:7)
Block(-7,73,4,LEAVES:7)
Block(-7,73,5,LEAVES:7)
Block(-7,73,6,LEAVES:7)
Block(-7,73,7,LEAVES:7)
Block(-7,73,8,LEAVES:7)
Block(-7,74,1,LEAVES:7)
Block(-7,74,2,LEAVES:7)
Block(-7,74,3,LEAVES:7)
Block(-7,74,4,LEAVES:7)
Block(-7,74,5,LEAVES:7)
Block(-7,74,6,LEAVES:7)
Block(-7,74,7,LEAVES:7)
Block(-7,74,8,LOG:15)
Block(-7,75,1,LEAVES:7)
Block(-7,75,2,LEAVES:7)
Block(-7,75,3,LEAVES:7)
Block(-7,75,4,LEAVES:7)
Block(-7,75,5,LEAVES:7)
Block(-7,75,7,LEAVES:7)
Block(-7,76,2,LEAVES:7)
Block(-7,76,3,LEAVES:7)
Block(-7,76,4,LEAVES:7)
Block(-7,76,5,LEAVES:7)
Block(-7,76,6,LEAVES:7)
Block(-7,76,7,LEAVES:7)
Block(-7,76,8,LEAVES:7)
Block(-7,77,2,LEAVES:7)
Block(-7,77,3,LEAVES:7)
Block(-7,77,4,LEAVES:7)
Block(-7,77,5,LEAVES:7)
Block(-7,77,6,LEAVES:7)
Block(-7,77,7,LEAVES:7)
Block(-7,78,3,LEAVES:7)
Block(-7,78,4,LEAVES:7)
Block(-7,78,5,LEAVES:7)
Block(-7,78,6,LEAVES:7)
Block(-7,78,7,LEAVES:7)
Block(-7,78,8,LEAVES:7)
Block(-7,79,5,LEAVES:7)
Block(-7,79,6,LEAVES:7)
Block(-7,79,7,LEAVES:7)
Block(-7,79,8,LEAVES:7)
Block(-7,80,5,LEAVES:7)
Block(-7,80,6,LEAVES:7)
Block(-7,80,7,LEAVES:7)
Block(-7,80,8,LEAVES:7)
Block(-7,81,6,LEAVES:7)
Block(-7,81,7,LEAVES:7)
Block(-6,-5,-4,LOG:15)
Block(-6,-5,-3,LOG:15)
Block(-6,-5,-2,LOG:15)
Block(-6,-4,-3,LOG:15)
Block(-6,14,6,LOG:15)
Block(-6,15,5,LOG:15)
Block(-6,15,6,LOG:15)
Block(-6,15,7,LOG:15)
Block(-6,16,5,LOG:15)
Block(-6,16,6,LOG:15)
Block(-6,16,7,LOG:15)
Block(-6,17,5,minecraft:black_glazed_terracotta:0)
Block(-6,17,6,LOG:15)
Block(-6,17,7,LOG:15)
Block(-6,18,6,LOG:15)
Block(-6,58,1,minecraft:black_glazed_terracotta:0)
Block(-6,59,0,minecraft:black_glazed_terracotta:0)
Block(-6,59,1,LEAVES:7)
Block(-6,59,3,LEAVES:7)
Block(-6,60,0,LEAVES:7)
Block(-6,60,1,LEAVES:7)
Block(-6,60,2,LEAVES:7)
Block(-6,60,3,LEAVES:7)
Block(-6,60,4,LEAVES:7)
Block(-6,61,-1,LEAVES:7)
Block(-6,61,0,LEAVES:7)
Block(-6,61,1,LEAVES:7)
Block(-6,61,2,LEAVES:7)
Block(-6,61,3,LEAVES:7)
Block(-6,61,4,LEAVES:7)
Block(-6,61,5,LEAVES:7)
Block(-6,61,6,LEAVES:7)
Block(-6,62,-3,LEAVES:7)
Block(-6,62,-2,LEAVES:7)
Block(-6,62,-1,LEAVES:7)
Block(-6,62,0,LEAVES:7)
Block(-6,62,1,LEAVES:7)
Block(-6,62,2,LEAVES:7)
Block(-6,62,4,LEAVES:7)
Block(-6,62,5,LEAVES:7)
Block(-6,62,8,LEAVES:7)
Block(-6,63,-3,LEAVES:7)
Block(-6,63,-2,LEAVES:7)
Block(-6,63,-1,LEAVES:7)
Block(-6,63,0,LEAVES:7)
Block(-6,63,1,LEAVES:7)
Block(-6,63,2,LEAVES:7)
Block(-6,63,3,LEAVES:7)
Block(-6,63,6,LEAVES:7)
Block(-6,64,-2,LEAVES:7)
Block(-6,64,-1,LEAVES:7)
Block(-6,64,0,LEAVES:7)
Block(-6,64,1,LEAVES:7)
Block(-6,64,2,LEAVES:7)
Block(-6,64,3,LEAVES:7)
Block(-6,64,4,LEAVES:7)
Block(-6,64,5,LEAVES:7)
Block(-6,64,7,LOG:15)
Block(-6,64,8,LEAVES:7)
Block(-6,65,-1,LEAVES:7)
Block(-6,65,1,LEAVES:7)
Block(-6,65,2,LEAVES:7)
Block(-6,65,3,LEAVES:7)
Block(-6,65,4,LEAVES:7)
Block(-6,65,5,LEAVES:7)
Block(-6,66,4,LEAVES:7)
Block(-6,66,5,LEAVES:7)
Block(-6,70,6,LEAVES:7)
Block(-6,70,7,LEAVES:7)
Block(-6,70,8,LEAVES:7)
Block(-6,71,2,LEAVES:7)
Block(-6,71,3,LEAVES:7)
Block(-6,71,4,LEAVES:7)
Block(-6,71,5,LEAVES:7)
Block(-6,71,6,LEAVES:7)
Block(-6,71,7,LEAVES:7)
Block(-6,71,8,LEAVES:7)
Block(-6,72,0,LEAVES:7)
Block(-6,72,1,LEAVES:7)
Block(-6,72,2,LEAVES:7)
Block(-6,72,3,LEAVES:7)
Block(-6,72,4,LEAVES:7)
Block(-6,72,5,LEAVES:7)
Block(-6,72,6,LEAVES:7)
Block(-6,72,7,LEAVES:7)
Block(-6,72,8,LEAVES:7)
Block(-6,73,0,LEAVES:7)
Block(-6,73,1,LEAVES:7)
Block(-6,73,2,LEAVES:7)
Block(-6,73,3,LEAVES:7)
Block(-6,73,4,LEAVES:7)
Block(-6,73,5,LEAVES:7)
Block(-6,73,6,LEAVES:7)
Block(-6,73,7,LEAVES:7)
Block(-6,73,8,LEAVES:7)
Block(-6,74,0,LEAVES:7)
Block(-6,74,1,LEAVES:7)
Block(-6,74,2,LEAVES:7)
Block(-6,74,3,LEAVES:7)
Block(-6,74,4,LEAVES:7)
Block(-6,74,5,LEAVES:7)
Block(-6,74,6,LEAVES:7)
Block(-6,74,7,LEAVES:7)
Block(-6,74,8,LEAVES:7)
Block(-6,75,-1,LEAVES:7)
Block(-6,75,1,LEAVES:7)
Block(-6,75,3,LEAVES:7)
Block(-6,75,4,LEAVES:7)
Block(-6,75,5,LEAVES:7)
Block(-6,75,6,LEAVES:7)
Block(-6,75,8,LEAVES:7)
Block(-6,76,-1,LEAVES:7)
Block(-6,76,0,LEAVES:7)
Block(-6,76,1,LEAVES:7)
Block(-6,76,2,LEAVES:7)
Block(-6,76,3,LEAVES:7)
Block(-6,76,4,LEAVES:7)
Block(-6,76,5,LEAVES:7)
Block(-6,76,6,LEAVES:7)
Block(-6,76,7,LEAVES:7)
Block(-6,76,8,LEAVES:7)
Block(-6,77,0,LEAVES:7)
Block(-6,77,1,LEAVES:7)
Block(-6,77,2,LEAVES:7)
Block(-6,77,3,LEAVES:7)
Block(-6,77,4,LEAVES:7)
Block(-6,77,5,LEAVES:7)
Block(-6,77,6,LEAVES:7)
Block(-6,77,8,LEAVES:7)
Block(-6,78,2,LEAVES:7)
Block(-6,78,3,LEAVES:7)
Block(-6,78,4,LEAVES:7)
Block(-6,78,5,LEAVES:7)
Block(-6,78,6,LEAVES:7)
Block(-6,78,7,LEAVES:7)
Block(-6,78,8,LEAVES:7)
Block(-6,79,4,LEAVES:7)
Block(-6,79,5,LEAVES:7)
Block(-6,79,6,LEAVES:7)
Block(-6,79,7,LEAVES:7)
Block(-6,79,8,LEAVES:7)
Block(-6,80,5,LEAVES:7)
Block(-6,80,6,LEAVES:7)
Block(-6,80,7,LEAVES:7)
Block(-6,80,8,LEAVES:7)
Block(-6,81,6,LEAVES:7)
Block(-6,81,7,LEAVES:7)
Block(-6,81,8,LEAVES:7)
Block(-5,13,7,LOG:15)
Block(-5,14,5,LOG:15)
Block(-5,14,6,LOG:15)
Block(-5,14,7,LOG:15)
Block(-5,14,8,LOG:15)
Block(-5,15,5,LOG:15)
Block(-5,15,6,LOG:15)
Block(-5,15,7,LOG:15)
Block(-5,16,5,LOG:15)
Block(-5,16,6,minecraft:black_glazed_terracotta:0)
Block(-5,16,7,LOG:15)
Block(-5,17,6,minecraft:gray_glazed_terracotta:0)
Block(-5,59,2,LEAVES:7)
Block(-5,60,-1,LEAVES:7)
Block(-5,60,1,LEAVES:7)
Block(-5,60,2,LEAVES:7)
Block(-5,60,3,LEAVES:7)
Block(-5,61,-2,LEAVES:7)
Block(-5,61,-1,LEAVES:7)
Block(-5,61,0,LEAVES:7)
Block(-5,61,1,LEAVES:7)
Block(-5,61,2,LEAVES:7)
Block(-5,61,3,LEAVES:7)
Block(-5,61,5,LEAVES:7)
Block(-5,61,6,LEAVES:7)
Block(-5,62,-2,LEAVES:7)
Block(-5,62,-1,LOG:15)
Block(-5,62,0,LEAVES:7)
Block(-5,62,1,LEAVES:7)
Block(-5,62,3,LEAVES:7)
Block(-5,62,4,LEAVES:7)
Block(-5,62,5,LEAVES:7)
Block(-5,62,6,LEAVES:7)
Block(-5,62,7,LEAVES:7)
Block(-5,63,-3,LEAVES:7)
Block(-5,63,-2,LEAVES:7)
Block(-5,63,-1,LEAVES:7)
Block(-5,63,0,LEAVES:7)
Block(-5,63,1,LEAVES:7)
Block(-5,63,2,LEAVES:7)
Block(-5,63,3,LEAVES:7)
Block(-5,63,4,LEAVES:7)
Block(-5,63,5,LEAVES:7)
Block(-5,63,7,LEAVES:7)
Block(-5,63,8,LEAVES:7)
Block(-5,64,-2,LEAVES:7)
Block(-5,64,-1,LEAVES:7)
Block(-5,64,1,LEAVES:7)
Block(-5,64,2,LEAVES:7)
Block(-5,64,3,LEAVES:7)
Block(-5,64,4,LEAVES:7)
Block(-5,64,5,LEAVES:7)
Block(-5,64,6,LEAVES:7)
Block(-5,64,7,LEAVES:7)
Block(-5,64,8,LEAVES:7)
Block(-5,65,-2,LEAVES:7)
Block(-5,65,-1,LEAVES:7)
Block(-5,65,1,LEAVES:7)
Block(-5,65,2,LEAVES:7)
Block(-5,65,3,LEAVES:7)
Block(-5,65,4,LEAVES:7)
Block(-5,65,5,LEAVES:7)
Block(-5,65,6,LEAVES:7)
Block(-5,65,7,LEAVES:7)
Block(-5,65,8,LEAVES:7)
Block(-5,66,5,LEAVES:7)
Block(-5,66,6,LEAVES:7)
Block(-5,66,7,LEAVES:7)
Block(-5,66,8,LEAVES:7)
Block(-5,67,6,LEAVES:7)
Block(-5,70,6,LEAVES:7)
Block(-5,70,7,LEAVES:7)
Block(-5,70,8,LEAVES:7)
Block(-5,71,3,LEAVES:7)
Block(-5,71,4,LEAVES:7)
Block(-5,71,5,LEAVES:7)
Block(-5,71,6,LEAVES:7)
Block(-5,71,7,LEAVES:7)
Block(-5,71,8,LEAVES:7)
Block(-5,72,1,LEAVES:7)
Block(-5,72,2,LEAVES:7)
Block(-5,72,3,LEAVES:7)
Block(-5,72,4,LEAVES:7)
Block(-5,72,5,LEAVES:7)
Block(-5,72,6,LEAVES:7)
Block(-5,72,7,LEAVES:7)
Block(-5,72,8,LEAVES:7)
Block(-5,73,0,LEAVES:7)
Block(-5,73,1,LEAVES:7)
Block(-5,73,2,LEAVES:7)
Block(-5,73,3,LEAVES:7)
Block(-5,73,4,LEAVES:7)
Block(-5,73,5,LEAVES:7)
Block(-5,73,6,LEAVES:7)
Block(-5,73,7,LEAVES:7)
Block(-5,73,8,LEAVES:7)
Block(-5,74,-1,LEAVES:7)
Block(-5,74,0,LEAVES:7)
Block(-5,74,1,LEAVES:7)
Block(-5,74,2,LEAVES:7)
Block(-5,74,3,LEAVES:7)
Block(-5,74,4,LEAVES:7)
Block(-5,74,5,LEAVES:7)
Block(-5,74,6,LEAVES:7)
Block(-5,74,7,LEAVES:7)
Block(-5,74,8,LEAVES:7)
Block(-5,75,-1,LEAVES:7)
Block(-5,75,1,LEAVES:7)
Block(-5,75,3,LEAVES:7)
Block(-5,75,5,LEAVES:7)
Block(-5,76,-1,LEAVES:7)
Block(-5,76,0,LEAVES:7)
Block(-5,76,2,LEAVES:7)
Block(-5,76,3,LEAVES:7)
Block(-5,76,4,LEAVES:7)
Block(-5,76,5,LEAVES:7)
Block(-5,76,6,LEAVES:7)
Block(-5,76,8,LEAVES:7)
Block(-5,77,-1,LEAVES:7)
Block(-5,77,0,LEAVES:7)
Block(-5,77,1,LEAVES:7)
Block(-5,77,2,LEAVES:7)
Block(-5,77,3,LEAVES:7)
Block(-5,77,4,LEAVES:7)
Block(-5,77,5,LEAVES:7)
Block(-5,77,6,LEAVES:7)
Block(-5,77,7,LEAVES:7)
Block(-5,77,8,LEAVES:7)
Block(-5,78,0,LEAVES:7)
Block(-5,78,2,LEAVES:7)
Block(-5,78,3,LEAVES:7)
Block(-5,78,4,LEAVES:7)
Block(-5,78,5,LEAVES:7)
Block(-5,78,6,LEAVES:7)
Block(-5,78,7,LEAVES:7)
Block(-5,79,4,LEAVES:7)
Block(-5,79,5,LEAVES:7)
Block(-5,79,6,LEAVES:7)
Block(-5,79,7,LEAVES:7)
Block(-5,79,8,LEAVES:7)
Block(-5,80,5,LEAVES:7)
Block(-5,80,6,LEAVES:7)
Block(-5,80,7,LEAVES:7)
Block(-5,80,8,LEAVES:7)
Block(-5,81,6,LEAVES:7)
Block(-5,81,7,LEAVES:7)
Block(-5,81,8,LEAVES:7)
Block(-4,-2,8,LOG:15)
Block(-4,12,7,LOG:15)
Block(-4,12,8,LOG:15)
Block(-4,13,6,LOG:15)
Block(-4,13,7,LOG:15)
Block(-4,13,8,LOG:15)
Block(-4,14,5,LOG:15)
Block(-4,14,6,LOG:15)
Block(-4,14,7,LOG:15)
Block(-4,14,8,LOG:15)
Block(-4,15,5,minecraft:gray_glazed_terracotta:0)
Block(-4,15,6,minecraft:black_glazed_terracotta:0)
Block(-4,15,7,LOG:15)
Block(-4,15,8,LOG:15)
Block(-4,59,3,LEAVES:7)
Block(-4,60,-1,LEAVES:7)
Block(-4,60,1,LEAVES:7)
Block(-4,60,4,LEAVES:7)
Block(-4,61,-2,LEAVES:7)
Block(-4,61,-1,LEAVES:7)
Block(-4,61,0,LEAVES:7)
Block(-4,61,1,LEAVES:7)
Block(-4,61,2,LEAVES:7)
Block(-4,61,4,LEAVES:7)
Block(-4,61,5,LEAVES:7)
Block(-4,61,6,LEAVES:7)
Block(-4,61,7,LEAVES:7)
Block(-4,62,-2,LEAVES:7)
Block(-4,62,-1,LEAVES:7)
Block(-4,62,0,LEAVES:7)
Block(-4,62,1,LEAVES:7)
Block(-4,62,2,LEAVES:7)
Block(-4,62,3,LEAVES:7)
Block(-4,62,4,LEAVES:7)
Block(-4,62,5,LEAVES:7)
Block(-4,62,6,LEAVES:7)
Block(-4,62,7,LEAVES:7)
Block(-4,62,8,LEAVES:7)
Block(-4,63,-2,LEAVES:7)
Block(-4,63,-1,LEAVES:7)
Block(-4,63,2,LEAVES:7)
Block(-4,63,3,LEAVES:7)
Block(-4,63,4,LEAVES:7)
Block(-4,63,5,LEAVES:7)
Block(-4,63,6,LEAVES:7)
Block(-4,63,7,LEAVES:7)
Block(-4,63,8,LEAVES:7)
Block(-4,64,-3,LEAVES:7)
Block(-4,64,0,LEAVES:7)
Block(-4,64,1,LEAVES:7)
Block(-4,64,4,LEAVES:7)
Block(-4,64,5,LEAVES:7)
Block(-4,64,6,LEAVES:7)
Block(-4,64,8,LEAVES:7)
Block(-4,65,1,LEAVES:7)
Block(-4,65,3,LEAVES:7)
Block(-4,65,4,LEAVES:7)
Block(-4,65,5,LEAVES:7)
Block(-4,65,6,LEAVES:7)
Block(-4,65,7,LEAVES:7)
Block(-4,65,8,LEAVES:7)
Block(-4,66,4,LEAVES:7)
Block(-4,66,5,LEAVES:7)
Block(-4,66,8,LEAVES:7)
Block(-4,67,5,LEAVES:7)
Block(-4,67,8,LEAVES:7)
Block(-4,70,7,LEAVES:7)
Block(-4,70,8,LEAVES:7)
Block(-4,71,2,LEAVES:7)
Block(-4,71,3,LEAVES:7)
Block(-4,71,4,LEAVES:7)
Block(-4,71,5,LEAVES:7)
Block(-4,71,6,LEAVES:7)
Block(-4,71,7,LEAVES:7)
Block(-4,71,8,LEAVES:7)
Block(-4,72,0,LEAVES:7)
Block(-4,72,1,LEAVES:7)
Block(-4,72,2,LEAVES:7)
Block(-4,72,3,LEAVES:7)
Block(-4,72,4,LEAVES:7)
Block(-4,72,5,LEAVES:7)
Block(-4,72,6,LEAVES:7)
Block(-4,72,7,LEAVES:7)
Block(-4,72,8,LEAVES:7)
Block(-4,73,-1,LEAVES:7)
Block(-4,73,0,LEAVES:7)
Block(-4,73,1,LEAVES:7)
Block(-4,73,2,LEAVES:7)
Block(-4,73,3,LEAVES:7)
Block(-4,73,4,LEAVES:7)
Block(-4,73,5,LEAVES:7)
Block(-4,73,6,LEAVES:7)
Block(-4,73,7,LEAVES:7)
Block(-4,73,8,LEAVES:7)
Block(-4,74,-1,LEAVES:7)
Block(-4,74,0,LEAVES:7)
Block(-4,74,1,LEAVES:7)
Block(-4,74,2,LEAVES:7)
Block(-4,74,3,LEAVES:7)
Block(-4,74,4,LEAVES:7)
Block(-4,74,5,LEAVES:7)
Block(-4,74,6,LEAVES:7)
Block(-4,74,7,LEAVES:7)
Block(-4,74,8,LEAVES:7)
Block(-4,75,-2,LEAVES:7)
Block(-4,75,0,LEAVES:7)
Block(-4,75,1,LEAVES:7)
Block(-4,75,2,LEAVES:7)
Block(-4,75,3,LEAVES:7)
Block(-4,75,4,LEAVES:7)
Block(-4,76,-2,LEAVES:7)
Block(-4,76,-1,LEAVES:7)
Block(-4,76,1,LEAVES:7)
Block(-4,76,2,LEAVES:7)
Block(-4,77,0,LEAVES:7)
Block(-4,77,1,LEAVES:7)
Block(-4,77,2,LEAVES:7)
Block(-4,77,3,LEAVES:7)
Block(-4,77,5,LEAVES:7)
Block(-4,77,6,LEAVES:7)
Block(-4,77,7,LEAVES:7)
Block(-4,77,8,LEAVES:7)
Block(-4,78,0,LEAVES:7)
Block(-4,78,1,LEAVES:7)
Block(-4,78,2,LEAVES:7)
Block(-4,78,3,LEAVES:7)
Block(-4,78,5,LEAVES:7)
Block(-4,78,6,LEAVES:7)
Block(-4,78,8,LEAVES:7)
Block(-4,79,5,LEAVES:7)
Block(-4,79,6,LEAVES:7)
Block(-4,79,7,LEAVES:7)
Block(-4,79,8,LEAVES:7)
Block(-4,80,5,LEAVES:7)
Block(-4,80,6,LEAVES:7)
Block(-4,80,7,LEAVES:7)
Block(-4,80,8,LEAVES:7)
Block(-4,81,8,LEAVES:7)
Block(-4,82,8,LEAVES:7)
Block(-3,-3,8,LOG:15)
Block(-3,-2,8,LOG:15)
Block(-3,-1,8,LOG:15)
Block(-3,0,7,LOG:15)
Block(-3,0,8,LOG:15)
Block(-3,1,8,LOG:15)
Block(-3,11,8,LOG:15)
Block(-3,12,6,LOG:15)
Block(-3,12,7,LOG:15)
Block(-3,12,8,LOG:15)
Block(-3,13,6,LOG:15)
Block(-3,13,7,LOG:15)
Block(-3,13,8,LOG:15)
Block(-3,14,6,LOG:15)
Block(-3,14,7,LOG:15)
Block(-3,14,8,LOG:15)
Block(-3,15,7,minecraft:black_glazed_terracotta:0)
Block(-3,59,1,minecraft:black_glazed_terracotta:0)
Block(-3,59,3,LEAVES:7)
Block(-3,60,0,minecraft:black_glazed_terracotta:0)
Block(-3,60,4,LEAVES:7)
Block(-3,60,5,LEAVES:7)
Block(-3,60,6,LEAVES:7)
Block(-3,61,-2,LEAVES:7)
Block(-3,61,-1,LEAVES:7)
Block(-3,61,0,LEAVES:7)
Block(-3,61,1,LEAVES:7)
Block(-3,61,4,LEAVES:7)
Block(-3,61,5,LEAVES:7)
Block(-3,61,6,LEAVES:7)
Block(-3,61,7,LEAVES:7)
Block(-3,61,8,LEAVES:7)
Block(-3,62,-3,LEAVES:7)
Block(-3,62,-2,LEAVES:7)
Block(-3,62,-1,LEAVES:7)
Block(-3,62,0,LEAVES:7)
Block(-3,62,2,LEAVES:7)
Block(-3,62,4,LEAVES:7)
Block(-3,62,5,LEAVES:7)
Block(-3,62,6,LEAVES:7)
Block(-3,62,7,LEAVES:7)
Block(-3,62,8,LEAVES:7)
Block(-3,63,-2,LEAVES:7)
Block(-3,63,-1,LEAVES:7)
Block(-3,63,1,LEAVES:7)
Block(-3,63,3,LEAVES:7)
Block(-3,63,4,LEAVES:7)
Block(-3,63,5,LEAVES:7)
Block(-3,63,6,LEAVES:7)
Block(-3,63,7,LEAVES:7)
Block(-3,63,8,LEAVES:7)
Block(-3,64,-1,LEAVES:7)
Block(-3,64,0,LEAVES:7)
Block(-3,64,1,LEAVES:7)
Block(-3,64,2,LEAVES:7)
Block(-3,64,4,LEAVES:7)
Block(-3,64,5,LEAVES:7)
Block(-3,64,6,LEAVES:7)
Block(-3,64,7,LEAVES:7)
Block(-3,64,8,LEAVES:7)
Block(-3,65,-2,LEAVES:7)
Block(-3,65,1,LEAVES:7)
Block(-3,65,3,LEAVES:7)
Block(-3,65,4,LEAVES:7)
Block(-3,65,5,LEAVES:7)
Block(-3,65,6,LEAVES:7)
Block(-3,65,7,LEAVES:7)
Block(-3,65,8,LEAVES:7)
Block(-3,66,4,LEAVES:7)
Block(-3,66,5,LEAVES:7)
Block(-3,66,7,LEAVES:7)
Block(-3,66,8,LEAVES:7)
Block(-3,67,8,LEAVES:7)
Block(-3,70,8,LEAVES:7)
Block(-3,71,2,LEAVES:7)
Block(-3,71,3,LEAVES:7)
Block(-3,71,4,LEAVES:7)
Block(-3,71,7,LEAVES:7)
Block(-3,71,8,LEAVES:7)
Block(-3,72,1,LEAVES:7)
Block(-3,72,2,LEAVES:7)
Block(-3,72,3,LEAVES:7)
Block(-3,72,4,LEAVES:7)
Block(-3,72,7,LEAVES:7)
Block(-3,72,8,LEAVES:7)
Block(-3,73,-2,LEAVES:7)
Block(-3,73,-1,LEAVES:7)
Block(-3,73,0,LEAVES:7)
Block(-3,73,1,LEAVES:7)
Block(-3,73,2,LEAVES:7)
Block(-3,73,3,LEAVES:7)
Block(-3,73,4,LEAVES:7)
Block(-3,73,7,LEAVES:7)
Block(-3,73,8,LEAVES:7)
Block(-3,74,-2,LEAVES:7)
Block(-3,74,-1,LEAVES:7)
Block(-3,74,0,LEAVES:7)
Block(-3,74,1,LEAVES:7)
Block(-3,74,2,LEAVES:7)
Block(-3,74,3,LEAVES:7)
Block(-3,74,8,LEAVES:7)
Block(-3,75,-1,LEAVES:7)
Block(-3,75,0,LEAVES:7)
Block(-3,75,1,LEAVES:7)
Block(-3,75,2,LEAVES:7)
Block(-3,75,4,LEAVES:7)
Block(-3,75,7,LEAVES:7)
Block(-3,75,8,LEAVES:7)
Block(-3,76,-2,LEAVES:7)
Block(-3,76,-1,LEAVES:7)
Block(-3,76,0,LEAVES:7)
Block(-3,76,1,LEAVES:7)
Block(-3,76,2,LEAVES:7)
Block(-3,76,7,LEAVES:7)
Block(-3,77,-2,LEAVES:7)
Block(-3,77,-1,LEAVES:7)
Block(-3,77,0,LEAVES:7)
Block(-3,77,1,LEAVES:7)
Block(-3,77,2,LEAVES:7)
Block(-3,77,3,LEAVES:7)
Block(-3,77,6,LEAVES:7)
Block(-3,77,7,LEAVES:7)
Block(-3,78,-2,LEAVES:7)
Block(-3,78,-1,LEAVES:7)
Block(-3,78,0,LEAVES:7)
Block(-3,78,2,LEAVES:7)
Block(-3,78,3,LEAVES:7)
Block(-3,78,4,LEAVES:7)
Block(-3,78,5,LEAVES:7)
Block(-3,78,6,LEAVES:7)
Block(-3,78,7,LEAVES:7)
Block(-3,78,8,LEAVES:7)
Block(-3,79,5,LEAVES:7)
Block(-3,79,6,LEAVES:7)
Block(-3,79,7,LEAVES:7)
Block(-3,79,8,LEAVES:7)
Block(-3,80,5,LEAVES:7)
Block(-3,80,6,LEAVES:7)
Block(-3,80,8,LEAVES:7)
Block(-3,81,8,LEAVES:7)
Block(-2,-2,8,LOG:15)
Block(-2,-1,7,LOG:15)
Block(-2,-1,8,LOG:15)
Block(-2,0,7,LOG:15)
Block(-2,0,8,LOG:15)
Block(-2,1,7,LOG:15)
Block(-2,1,8,LOG:15)
Block(-2,2,8,LOG:15)
Block(-2,9,8,LOG:15)
Block(-2,11,7,LOG:15)
Block(-2,11,8,LOG:15)
Block(-2,12,7,LOG:15)
Block(-2,12,8,LOG:15)
Block(-2,13,6,LOG:15)
Block(-2,13,7,minecraft:gray_glazed_terracotta:0)
Block(-2,13,8,LOG:15)
Block(-2,14,7,minecraft:black_glazed_terracotta:0)
Block(-2,58,2,minecraft:black_glazed_terracotta:0)
Block(-2,59,1,minecraft:black_glazed_terracotta:0)
Block(-2,59,2,minecraft:black_glazed_terracotta:0)
Block(-2,60,0,LEAVES:7)
Block(-2,60,2,LEAVES:7)
Block(-2,60,4,LEAVES:7)
Block(-2,60,5,LEAVES:7)
Block(-2,61,4,LEAVES:7)
Block(-2,61,5,LEAVES:7)
Block(-2,61,6,LEAVES:7)
Block(-2,61,7,LEAVES:7)
Block(-2,61,8,LEAVES:7)
Block(-2,62,-2,LEAVES:7)
Block(-2,62,2,LEAVES:7)
Block(-2,62,3,LEAVES:7)
Block(-2,62,4,LEAVES:7)
Block(-2,62,5,LEAVES:7)
Block(-2,62,6,LEAVES:7)
Block(-2,62,7,LEAVES:7)
Block(-2,62,8,LEAVES:7)
Block(-2,63,0,LEAVES:7)
Block(-2,63,2,LEAVES:7)
Block(-2,63,3,LEAVES:7)
Block(-2,63,4,LEAVES:7)
Block(-2,63,5,LEAVES:7)
Block(-2,63,6,LEAVES:7)
Block(-2,63,7,LEAVES:7)
Block(-2,63,8,LEAVES:7)
Block(-2,64,3,LEAVES:7)
Block(-2,64,4,LEAVES:7)
Block(-2,64,5,LEAVES:7)
Block(-2,64,6,LEAVES:7)
Block(-2,64,7,LEAVES:7)
Block(-2,64,8,LEAVES:7)
Block(-2,65,1,LEAVES:7)
Block(-2,65,3,LEAVES:7)
Block(-2,65,4,LEAVES:7)
Block(-2,65,5,LEAVES:7)
Block(-2,65,6,LEAVES:7)
Block(-2,65,7,LEAVES:7)
Block(-2,65,8,LEAVES:7)
Block(-2,66,3,LEAVES:7)
Block(-2,66,4,LEAVES:7)
Block(-2,66,5,LEAVES:7)
Block(-2,66,7,LEAVES:7)
Block(-2,66,8,LEAVES:7)
Block(-2,67,4,LEAVES:7)
Block(-2,67,5,LEAVES:7)
Block(-2,67,6,LEAVES:7)
Block(-2,71,3,LEAVES:7)
Block(-2,71,4,LEAVES:7)
Block(-2,71,8,LEAVES:7)
Block(-2,72,0,LEAVES:7)
Block(-2,72,1,LEAVES:7)
Block(-2,72,2,LEAVES:7)
Block(-2,72,3,LEAVES:7)
Block(-2,72,4,LEAVES:7)
Block(-2,72,8,LEAVES:7)
Block(-2,73,-1,LEAVES:7)
Block(-2,73,0,LEAVES:7)
Block(-2,73,1,LEAVES:7)
Block(-2,73,2,LEAVES:7)
Block(-2,73,3,LEAVES:7)
Block(-2,73,4,LEAVES:7)
Block(-2,73,7,LEAVES:7)
Block(-2,74,-2,LEAVES:7)
Block(-2,74,0,LEAVES:7)
Block(-2,74,1,LEAVES:7)
Block(-2,74,2,LEAVES:7)
Block(-2,74,3,LEAVES:7)
Block(-2,75,-2,LEAVES:7)
Block(-2,75,-1,LEAVES:7)
Block(-2,75,0,LEAVES:7)
Block(-2,75,1,LEAVES:7)
Block(-2,75,2,LEAVES:7)
Block(-2,75,4,LEAVES:7)
Block(-2,76,-1,LEAVES:7)
Block(-2,76,0,LEAVES:7)
Block(-2,76,2,LEAVES:7)
Block(-2,76,3,LEAVES:7)
Block(-2,76,6,LEAVES:7)
Block(-2,77,0,LEAVES:7)
Block(-2,77,1,LEAVES:7)
Block(-2,77,2,LEAVES:7)
Block(-2,77,3,LEAVES:7)
Block(-2,77,5,LEAVES:7)
Block(-2,77,6,LEAVES:7)
Block(-2,77,7,LEAVES:7)
Block(-2,77,8,LEAVES:7)
Block(-2,78,0,LEAVES:7)
Block(-2,78,1,LEAVES:7)
Block(-2,78,2,LEAVES:7)
Block(-2,78,3,LEAVES:7)
Block(-2,78,4,LEAVES:7)
Block(-2,78,5,LEAVES:7)
Block(-2,78,6,LEAVES:7)
Block(-2,78,7,LEAVES:7)
Block(-2,78,8,LEAVES:7)
Block(-2,79,4,LEAVES:7)
Block(-2,79,5,LEAVES:7)
Block(-2,79,6,LEAVES:7)
Block(-2,79,7,LEAVES:7)
Block(-2,80,5,LEAVES:7)
Block(-2,80,6,LEAVES:7)
Block(-1,-1,8,LOG:15)
Block(-1,0,7,LOG:15)
Block(-1,0,8,LOG:15)
Block(-1,1,6,LOG:15)
Block(-1,1,7,LOG:15)
Block(-1,1,8,LOG:15)
Block(-1,2,7,LOG:15)
Block(-1,2,8,LOG:15)
Block(-1,4,8,LOG:15)
Block(-1,5,7,LOG:15)
Block(-1,5,8,LOG:15)
Block(-1,6,7,LOG:15)
Block(-1,6,8,LOG:15)
Block(-1,7,7,LOG:15)
Block(-1,7,8,LOG:15)
Block(-1,8,8,LOG:15)
Block(-1,9,8,LOG:15)
Block(-1,10,8,LOG:15)
Block(-1,11,8,LOG:15)
Block(-1,12,7,LOG:15)
Block(-1,12,8,LOG:15)
Block(-1,13,8,minecraft:black_glazed_terracotta:0)
Block(-1,56,4,minecraft:gray_glazed_terracotta:0)
Block(-1,57,3,minecraft:gray_glazed_terracotta:0)
Block(-1,57,4,minecraft:gray_glazed_terracotta:0)
Block(-1,58,3,minecraft:gray_glazed_terracotta:0)
Block(-1,61,4,LEAVES:7)
Block(-1,61,5,LEAVES:7)
Block(-1,61,6,LEAVES:7)
Block(-1,61,7,LEAVES:7)
Block(-1,61,8,LEAVES:7)
Block(-1,62,4,LEAVES:7)
Block(-1,62,5,LEAVES:7)
Block(-1,62,6,LEAVES:7)
Block(-1,62,7,LEAVES:7)
Block(-1,62,8,LEAVES:7)
Block(-1,63,3,LEAVES:7)
Block(-1,63,4,LEAVES:7)
Block(-1,63,5,LEAVES:7)
Block(-1,63,6,LEAVES:7)
Block(-1,63,7,LEAVES:7)
Block(-1,63,8,LEAVES:7)
Block(-1,64,3,LEAVES:7)
Block(-1,64,4,LEAVES:7)
Block(-1,64,5,LEAVES:7)
Block(-1,64,6,LEAVES:7)
Block(-1,64,7,LEAVES:7)
Block(-1,64,8,LEAVES:7)
Block(-1,65,4,LEAVES:7)
Block(-1,65,5,LEAVES:7)
Block(-1,65,6,LEAVES:7)
Block(-1,65,7,LEAVES:7)
Block(-1,65,8,LEAVES:7)
Block(-1,66,7,LEAVES:7)
Block(-1,67,4,LEAVES:7)
Block(-1,71,8,LEAVES:7)
Block(-1,72,0,LEAVES:7)
Block(-1,72,1,LEAVES:7)
Block(-1,72,2,LEAVES:7)
Block(-1,72,3,LEAVES:7)
Block(-1,72,8,LEAVES:7)
Block(-1,73,0,LEAVES:7)
Block(-1,73,1,LEAVES:7)
Block(-1,73,2,LEAVES:7)
Block(-1,73,8,LEAVES:7)
Block(-1,74,-1,LEAVES:7)
Block(-1,74,0,LEAVES:7)
Block(-1,74,1,LEAVES:7)
Block(-1,74,2,LEAVES:7)
Block(-1,74,3,LEAVES:7)
Block(-1,74,8,LEAVES:7)
Block(-1,75,0,LEAVES:7)
Block(-1,75,8,LEAVES:7)
Block(-1,76,1,LEAVES:7)
Block(-1,76,2,LEAVES:7)
Block(-1,76,6,LEAVES:7)
Block(-1,77,-1,LEAVES:7)
Block(-1,77,2,LEAVES:7)
Block(-1,77,5,LEAVES:7)
Block(-1,77,6,LEAVES:7)
Block(-1,77,7,LEAVES:7)
Block(-1,78,-1,LEAVES:7)
Block(-1,78,0,LEAVES:7)
Block(-1,78,4,LEAVES:7)
Block(-1,78,5,LEAVES:7)
Block(-1,78,6,LEAVES:7)
Block(-1,78,7,LEAVES:7)
Block(-1,78,8,LEAVES:7)
Block(-1,79,5,LEAVES:7)
Block(-1,79,6,LEAVES:7)
Block(-1,79,7,LEAVES:7)
Block(-1,79,8,LEAVES:7)
Block(-1,80,5,LEAVES:7)
Block(-1,80,6,LEAVES:7)
Block(0,-2,6,LOG:15)
Block(0,-1,5,LOG:15)
Block(0,-1,6,LOG:15)
Block(0,-1,7,LOG:15)
Block(0,0,5,LOG:15)
Block(0,0,6,LOG:15)
Block(0,0,7,LOG:15)
Block(0,0,8,LOG:15)
Block(0,1,5,LOG:15)
Block(0,1,6,LOG:15)
Block(0,1,7,LOG:15)
Block(0,1,8,LOG:15)
Block(0,2,6,LOG:15)
Block(0,2,7,LOG:15)
Block(0,2,8,LOG:15)
Block(0,3,6,LOG:15)
Block(0,3,7,LOG:15)
Block(0,3,8,LOG:15)
Block(0,4,7,LOG:15)
Block(0,4,8,LOG:15)
Block(0,5,7,LOG:15)
Block(0,5,8,LOG:15)
Block(0,6,7,LOG:15)
Block(0,6,8,LOG:15)
Block(0,7,7,LOG:15)
Block(0,7,8,LOG:15)
Block(0,8,7,LOG:15)
Block(0,8,8,LOG:15)
Block(0,9,8,LOG:15)
Block(0,56,4,minecraft:gray_glazed_terracotta:0)
Block(0,56,5,minecraft:gray_glazed_terracotta:0)
Block(0,56,6,minecraft:gray_glazed_terracotta:0)
Block(0,61,5,LEAVES:7)
Block(0,61,6,LEAVES:7)
Block(0,61,7,LEAVES:7)
Block(0,62,4,LEAVES:7)
Block(0,62,5,LEAVES:7)
Block(0,62,6,LEAVES:7)
Block(0,62,7,LEAVES:7)
Block(0,62,8,LEAVES:7)
Block(0,63,4,LEAVES:7)
Block(0,63,5,LEAVES:7)
Block(0,63,6,LEAVES:7)
Block(0,63,7,LEAVES:7)
Block(0,63,8,LEAVES:7)
Block(0,64,4,LEAVES:7)
Block(0,64,5,LEAVES:7)
Block(0,64,6,LEAVES:7)
Block(0,64,7,LEAVES:7)
Block(0,64,8,LEAVES:7)
Block(0,65,5,LEAVES:7)
Block(0,65,6,LEAVES:7)
Block(0,65,7,LEAVES:7)
Block(0,65,8,LEAVES:7)
Block(0,66,5,LEAVES:7)
Block(0,66,6,LEAVES:7)
Block(0,66,7,LEAVES:7)
Block(0,66,8,LEAVES:7)
Block(0,67,6,LEAVES:7)
Block(0,71,8,LEAVES:7)
Block(0,72,2,LEAVES:7)
Block(0,72,8,LEAVES:7)
Block(0,73,8,LEAVES:7)
Block(0,74,0,LEAVES:7)
Block(0,74,8,LEAVES:7)
Block(0,76,8,LEAVES:7)
Block(0,77,6,LEAVES:7)
Block(0,78,6,LEAVES:7)
Block(1,-4,5,LOG:15)
Block(1,-3,4,LOG:15)
Block(1,-3,5,LOG:15)
Block(1,-3,6,LOG:15)
Block(1,-2,5,LOG:15)
Block(1,-2,6,LOG:15)
Block(1,-2,7,LOG:15)
Block(1,-1,5,LOG:15)
Block(1,-1,6,LOG:15)
Block(1,-1,7,LOG:15)
Block(1,0,5,LOG:15)
Block(1,0,6,LOG:15)
Block(1,0,7,LOG:15)
Block(1,1,5,LOG:15)
Block(1,1,6,LOG:15)
Block(1,1,7,LOG:15)
Block(1,1,8,LOG:15)
Block(1,2,5,LOG:15)
Block(1,2,6,LOG:15)
Block(1,2,7,LOG:15)
Block(1,2,8,LOG:15)
Block(1,3,6,LOG:15)
Block(1,3,7,LOG:15)
Block(1,3,8,LOG:15)
Block(1,4,6,LOG:15)
Block(1,4,7,LOG:15)
Block(1,4,8,LOG:15)
Block(1,5,7,LOG:15)
Block(1,5,8,LOG:15)
Block(1,6,7,LOG:15)
Block(1,6,8,LOG:15)
Block(1,7,7,LOG:15)
Block(1,7,8,LOG:15)
Block(1,8,8,LOG:15)
Block(1,56,6,minecraft:black_glazed_terracotta:0)
Block(1,56,7,minecraft:black_glazed_terracotta:0)
Block(1,57,7,minecraft:black_glazed_terracotta:0)
Block(1,57,8,minecraft:black_glazed_terracotta:0)
Block(1,59,8,LEAVES:7)
Block(1,60,8,LEAVES:7)
Block(1,61,8,LEAVES:7)
Block(1,71,8,LEAVES:7)
Block(1,74,7,LEAVES:7)
Block(1,74,8,LEAVES:7)
Block(1,75,8,LEAVES:7)
Block(2,-5,1,LOG:15)
Block(2,-5,2,LOG:15)
Block(2,-5,3,LOG:15)
Block(2,-4,2,LOG:15)
Block(2,-4,3,LOG:15)
Block(2,-4,4,LOG:15)
Block(2,-4,5,LOG:15)
Block(2,-4,6,LOG:15)
Block(2,-3,3,LOG:15)
Block(2,-3,4,LOG:15)
Block(2,-3,5,LOG:15)
Block(2,-3,6,LOG:15)
Block(2,-3,7,LOG:15)
Block(2,-2,4,LOG:15)
Block(2,-2,5,LOG:15)
Block(2,-2,6,LOG:15)
Block(2,-2,7,LOG:15)
Block(2,-1,5,LOG:15)
Block(2,-1,6,LOG:15)
Block(2,-1,7,LOG:15)
Block(2,0,5,LOG:15)
Block(2,0,6,LOG:15)
Block(2,0,7,LOG:15)
Block(2,1,5,LOG:15)
Block(2,1,6,LOG:15)
Block(2,1,7,LOG:15)
Block(2,2,6,LOG:15)
Block(2,2,7,LOG:15)
Block(2,2,8,LOG:15)
Block(2,3,6,LOG:15)
Block(2,3,7,LOG:15)
Block(2,3,8,LOG:15)
Block(2,4,7,LOG:15)
Block(2,4,8,LOG:15)
Block(2,5,8,LOG:15)
Block(2,57,8,minecraft:black_glazed_terracotta:0)
Block(2,58,8,minecraft:black_glazed_terracotta:0)
Block(2,59,8,LEAVES:7)
Block(2,60,8,LEAVES:7)
Block(2,61,7,LEAVES:7)
Block(2,61,8,LEAVES:7)
Block(2,62,7,LEAVES:7)
Block(2,62,8,LEAVES:7)
Block(2,63,8,LEAVES:7)
Block(2,72,8,LEAVES:7)
Block(2,73,8,LEAVES:7)
Block(2,74,8,LEAVES:7)
Block(3,-5,1,LOG:15)
Block(3,-5,2,LOG:15)
Block(3,-5,3,LOG:15)
Block(3,-5,4,LOG:15)
Block(3,-4,1,LOG:15)
Block(3,-4,2,LOG:15)
Block(3,-4,3,LOG:15)
Block(3,-4,4,LOG:15)
Block(3,-4,5,LOG:15)
Block(3,-3,2,LOG:15)
Block(3,-3,3,LOG:15)
Block(3,-3,4,LOG:15)
Block(3,-3,5,LOG:15)
Block(3,-3,6,LOG:15)
Block(3,-2,3,LOG:15)
Block(3,-2,4,LOG:15)
Block(3,-2,5,LOG:15)
Block(3,-2,6,LOG:15)
Block(3,-2,7,LOG:15)
Block(3,-1,6,LOG:15)
Block(3,59,8,LEAVES:7)
Block(3,60,8,LEAVES:7)
Block(3,61,7,LEAVES:7)
Block(3,61,8,LEAVES:7)
Block(3,62,7,LEAVES:7)
Block(3,62,8,LEAVES:7)
Block(3,63,8,LEAVES:7)
Block(3,72,8,LEAVES:7)
Block(3,73,8,LEAVES:7)
Block(4,-5,1,LOG:15)
Block(4,-5,2,LOG:15)
Block(4,-5,3,LOG:15)
Block(4,-4,2,LOG:15)
Block(4,-4,3,LOG:15)
Block(4,-4,4,LOG:15)
Block(4,-3,3,LOG:15)
Block(4,-3,4,LOG:15)
Block(4,-3,5,LOG:15)
Block(4,-2,4,LOG:15)
Block(4,60,8,LEAVES:7)
Block(4,61,8,LEAVES:7)
Block(4,62,8,LEAVES:7)
Block(4,63,8,LEAVES:7)
Block(5,60,8,LEAVES:7)
Block(5,61,8,LEAVES:7)
Block(5,62,8,LEAVES:7)
Block(5,63,8,LEAVES:7)

#######################################################################
# +-----------------------------------------------------------------+ #
# |                             Branches                            | #
# +-----------------------------------------------------------------+ #
#######################################################################

Branch(0,0,16,true,CorruptedJungleGiant01C2R1,NORTH,100.0,0)

#######################################################################
# +-----------------------------------------------------------------+ #
# |                             Entities                            | #
# +-----------------------------------------------------------------+ #
#######################################################################


#######################################################################
# +-----------------------------------------------------------------+ #
# |                            Particles                            | #
# +-----------------------------------------------------------------+ #
#######################################################################


#######################################################################
# +-----------------------------------------------------------------+ #
# |                             Spawners                            | #
# +-----------------------------------------------------------------+ #
#######################################################################


#######################################################################
# +-----------------------------------------------------------------+ #
# |                             ModData                             | #
# +-----------------------------------------------------------------+ #
#######################################################################

