
#######################################################################
# +-----------------------------------------------------------------+ #
# |                            BO3 object                           | #
# +-----------------------------------------------------------------+ #
#######################################################################

Author: NLBlackHeavenNL

Description: No description given

Version: 3

SettingsMode: WriteWithoutComments


#######################################################################
# +-----------------------------------------------------------------+ #
# |                          Main settings                          | #
# +-----------------------------------------------------------------+ #
#######################################################################

Tree: true

Frequency: 1

Rarity: 100.0

RotateRandomly: false

SpawnHeight: highestSolidBlock

SpawnHeightOffset: -1

SpawnHeightVariance: 0

##############################
# Height Limits for the BO3. #
##############################

MinHeight: 0

MaxHeight: 255

######################
# Extrusion settings #
######################

ExtrudeMode: None

ExtrudeThroughBlocks: AIR

MaxBranchDepth: 10

ExcludedBiomes: All


#######################################################################
# +-----------------------------------------------------------------+ #
# |                      Source block settings                      | #
# +-----------------------------------------------------------------+ #
#######################################################################

SourceBlocks: AIR,GRASS,DIRT,biomesoplenty:dirt,defiledlands:dirt_defiled,defiledlands:grass_defiled,defiledlands:sand_defiled

MaxPercentageOutsideSourceBlock: 0

OutsideSourceBlock: placeAnyway

DoReplaceBlocks: true

IsOTGPlus: false


#######################################################################
# +-----------------------------------------------------------------+ #
# |                              Blocks                             | #
# +-----------------------------------------------------------------+ #
#######################################################################

Block(-1,3,0,dynamictreesdefiledlands:leaves0:0)
Block(-1,11,0,dynamictreesdefiledlands:leaves0:0)
Block(-1,15,0,dynamictreesdefiledlands:leaves0:0)
Block(0,3,-1,dynamictreesdefiledlands:leaves0:0)
Block(0,3,0,dynamictreesdefiledlands:tenebrabranch)
Block(0,3,1,dynamictreesdefiledlands:leaves0:0)
Block(0,4,0,dynamictreesdefiledlands:leaves0:0)
Block(0,9,-1,dynamictreesdefiledlands:leaves0:0)
Block(0,11,-1,dynamictreesdefiledlands:leaves0:0)
Block(0,11,0,dynamictreesdefiledlands:tenebrabranch)
Block(0,11,1,dynamictreesdefiledlands:leaves0:0)
Block(0,12,0,dynamictreesdefiledlands:leaves0:0)
Block(0,13,0,dynamictreesdefiledlands:tenebrabranch:1)
Block(0,14,0,dynamictreesdefiledlands:tenebrabranch:1)
Block(0,15,-1,dynamictreesdefiledlands:leaves0:0)
Block(0,15,0,dynamictreesdefiledlands:tenebrabranch)
Block(0,15,1,dynamictreesdefiledlands:leaves0:0)
Block(0,16,0,dynamictreesdefiledlands:leaves0:0)
Block(1,0,0,dynamictreesdefiledlands:rootydefileddirt:0)
Block(1,1,0,dynamictreesdefiledlands:tenebrabranch:5)
Block(1,2,0,dynamictreesdefiledlands:tenebrabranch:5)
Block(1,3,-2,dynamictreesdefiledlands:leaves0:0)
Block(1,3,-1,dynamictreesdefiledlands:tenebrabranch)
Block(1,3,0,dynamictreesdefiledlands:tenebrabranch:4)
Block(1,3,1,dynamictreesdefiledlands:tenebrabranch)
Block(1,3,2,dynamictreesdefiledlands:leaves0:0)
Block(1,4,-1,dynamictreesdefiledlands:leaves0:0)
Block(1,4,0,dynamictreesdefiledlands:tenebrabranch:4)
Block(1,4,1,dynamictreesdefiledlands:leaves0:0)
Block(1,5,0,dynamictreesdefiledlands:tenebrabranch:3)
Block(1,6,0,dynamictreesdefiledlands:tenebrabranch:3)
Block(1,7,0,dynamictreesdefiledlands:tenebrabranch:2)
Block(1,8,0,dynamictreesdefiledlands:tenebrabranch:2)
Block(1,9,-2,dynamictreesdefiledlands:leaves0:0)
Block(1,9,-1,dynamictreesdefiledlands:tenebrabranch)
Block(1,9,0,dynamictreesdefiledlands:tenebrabranch:1)
Block(1,10,-1,dynamictreesdefiledlands:leaves0:0)
Block(1,10,0,dynamictreesdefiledlands:tenebrabranch:1)
Block(1,10,1,dynamictreesdefiledlands:tenebrabranch)
Block(1,10,2,dynamictreesdefiledlands:leaves0:0)
Block(1,11,-2,dynamictreesdefiledlands:leaves0:0)
Block(1,11,-1,dynamictreesdefiledlands:tenebrabranch)
Block(1,11,0,dynamictreesdefiledlands:tenebrabranch:1)
Block(1,11,1,dynamictreesdefiledlands:leaves0:0)
Block(1,12,-1,dynamictreesdefiledlands:leaves0:0)
Block(1,12,0,dynamictreesdefiledlands:tenebrabranch:1)
Block(1,13,0,dynamictreesdefiledlands:tenebrabranch:1)
Block(1,15,0,dynamictreesdefiledlands:leaves0:0)
Block(2,3,-1,dynamictreesdefiledlands:leaves0:0)
Block(2,3,0,dynamictreesdefiledlands:tenebrabranch)
Block(2,3,1,dynamictreesdefiledlands:leaves0:0)
Block(2,4,0,dynamictreesdefiledlands:leaves0:0)
Block(2,9,-1,dynamictreesdefiledlands:leaves0:0)
Block(2,9,0,dynamictreesdefiledlands:tenebrabranch)
Block(2,10,0,dynamictreesdefiledlands:leaves0:0)
Block(2,10,1,dynamictreesdefiledlands:leaves0:0)
Block(2,12,-1,dynamictreesdefiledlands:leaves0:0)
Block(2,12,0,dynamictreesdefiledlands:tenebrabranch)
Block(2,12,1,dynamictreesdefiledlands:leaves0:0)
Block(2,13,0,dynamictreesdefiledlands:leaves0:0)
Block(3,3,0,dynamictreesdefiledlands:leaves0:0)
Block(3,9,0,dynamictreesdefiledlands:leaves0:0)
Block(3,12,0,dynamictreesdefiledlands:leaves0:0)

#######################################################################
# +-----------------------------------------------------------------+ #
# |                            BO3 checks                           | #
# +-----------------------------------------------------------------+ #
#######################################################################

BlockCheck(1,-1,0,GRASS,DIRT,biomesoplenty:grass,biomesoplenty:dirt,defiledlands:dirt_defiled,defiledlands:grass_defiled,defiledlands:sand_defiled)

#######################################################################
# +-----------------------------------------------------------------+ #
# |                             Branches                            | #
# +-----------------------------------------------------------------+ #
#######################################################################


#######################################################################
# +-----------------------------------------------------------------+ #
# |                             Entities                            | #
# +-----------------------------------------------------------------+ #
#######################################################################


#######################################################################
# +-----------------------------------------------------------------+ #
# |                            Particles                            | #
# +-----------------------------------------------------------------+ #
#######################################################################


#######################################################################
# +-----------------------------------------------------------------+ #
# |                             Spawners                            | #
# +-----------------------------------------------------------------+ #
#######################################################################


#######################################################################
# +-----------------------------------------------------------------+ #
# |                             ModData                             | #
# +-----------------------------------------------------------------+ #
#######################################################################

