
#######################################################################
# +-----------------------------------------------------------------+ #
# |                            BO3 object                           | #
# +-----------------------------------------------------------------+ #
#######################################################################

Author: NLBlackHeavenNL

Description: No description given

Version: 3

SettingsMode: WriteWithoutComments


#######################################################################
# +-----------------------------------------------------------------+ #
# |                          Main settings                          | #
# +-----------------------------------------------------------------+ #
#######################################################################

Tree: true

Frequency: 1

Rarity: 100.0

RotateRandomly: false

SpawnHeight: highestSolidBlock

SpawnHeightOffset: -1

SpawnHeightVariance: 0

##############################
# Height Limits for the BO3. #
##############################

MinHeight: 0

MaxHeight: 255

######################
# Extrusion settings #
######################

ExtrudeMode: None

ExtrudeThroughBlocks: AIR

MaxBranchDepth: 10

ExcludedBiomes: All


#######################################################################
# +-----------------------------------------------------------------+ #
# |                      Source block settings                      | #
# +-----------------------------------------------------------------+ #
#######################################################################

SourceBlocks: AIR,GRASS,DIRT,biomesoplenty:dirt,defiledlands:dirt_defiled,defiledlands:grass_defiled,defiledlands:sand_defiled

MaxPercentageOutsideSourceBlock: 0

OutsideSourceBlock: placeAnyway

DoReplaceBlocks: true

IsOTGPlus: false


#######################################################################
# +-----------------------------------------------------------------+ #
# |                              Blocks                             | #
# +-----------------------------------------------------------------+ #
#######################################################################

Block(-3,16,0,dynamictreesdefiledlands:leaves0:0)
Block(-2,11,0,dynamictreesdefiledlands:leaves0:0)
Block(-2,13,-1,dynamictreesdefiledlands:leaves0:0)
Block(-2,15,0,dynamictreesdefiledlands:tenebrabranch:1)
Block(-2,16,-1,dynamictreesdefiledlands:leaves0:0)
Block(-2,16,0,dynamictreesdefiledlands:tenebrabranch)
Block(-2,16,1,dynamictreesdefiledlands:leaves0:0)
Block(-2,17,0,dynamictreesdefiledlands:leaves0:0)
Block(-1,11,-1,dynamictreesdefiledlands:leaves0:0)
Block(-1,11,0,dynamictreesdefiledlands:tenebrabranch)
Block(-1,11,1,dynamictreesdefiledlands:leaves0:0)
Block(-1,12,0,dynamictreesdefiledlands:leaves0:0)
Block(-1,13,-2,dynamictreesdefiledlands:leaves0:0)
Block(-1,13,-1,dynamictreesdefiledlands:tenebrabranch)
Block(-1,13,0,dynamictreesdefiledlands:tenebrabranch:2)
Block(-1,14,-1,dynamictreesdefiledlands:leaves0:0)
Block(-1,14,0,dynamictreesdefiledlands:tenebrabranch:2)
Block(-1,15,0,dynamictreesdefiledlands:tenebrabranch:2)
Block(-1,15,1,dynamictreesdefiledlands:tenebrabranch:1)
Block(-1,16,0,dynamictreesdefiledlands:leaves0:0)
Block(-1,16,1,dynamictreesdefiledlands:tenebrabranch)
Block(-1,16,2,dynamictreesdefiledlands:leaves0:0)
Block(-1,17,1,dynamictreesdefiledlands:leaves0:0)
Block(0,6,0,dynamictreesdefiledlands:tenebrabranch)
Block(0,7,-1,dynamictreesdefiledlands:leaves0:0)
Block(0,7,0,dynamictreesdefiledlands:leaves0:0)
Block(0,11,0,dynamictreesdefiledlands:tenebrabranch:3)
Block(0,11,1,dynamictreesdefiledlands:tenebrabranch)
Block(0,11,2,dynamictreesdefiledlands:leaves0:0)
Block(0,12,0,dynamictreesdefiledlands:tenebrabranch:3)
Block(0,12,1,dynamictreesdefiledlands:leaves0:0)
Block(0,13,-1,dynamictreesdefiledlands:leaves0:0)
Block(0,13,0,dynamictreesdefiledlands:tenebrabranch:3)
Block(0,16,1,dynamictreesdefiledlands:leaves0:0)
Block(1,0,0,dynamictreesdefiledlands:rootydefileddirt)
Block(1,1,0,dynamictreesdefiledlands:tenebrabranch:7)
Block(1,2,0,dynamictreesdefiledlands:tenebrabranch:7)
Block(1,3,0,dynamictreesdefiledlands:tenebrabranch:7)
Block(1,3,1,dynamictreesdefiledlands:tenebrabranch)
Block(1,4,-1,dynamictreesdefiledlands:tenebrabranch)
Block(1,4,0,dynamictreesdefiledlands:tenebrabranch:6)
Block(1,4,1,dynamictreesdefiledlands:leaves0:0)
Block(1,5,-1,dynamictreesdefiledlands:leaves0:0)
Block(1,5,0,dynamictreesdefiledlands:tenebrabranch:6)
Block(1,6,0,dynamictreesdefiledlands:tenebrabranch:6)
Block(1,6,1,dynamictreesdefiledlands:tenebrabranch)
Block(1,7,-2,dynamictreesdefiledlands:leaves0:0)
Block(1,7,-1,dynamictreesdefiledlands:tenebrabranch)
Block(1,7,0,dynamictreesdefiledlands:tenebrabranch:5)
Block(1,7,1,dynamictreesdefiledlands:leaves0:0)
Block(1,8,-1,dynamictreesdefiledlands:leaves0:0)
Block(1,8,0,dynamictreesdefiledlands:tenebrabranch:5)
Block(1,9,-1,dynamictreesdefiledlands:tenebrabranch)
Block(1,9,0,dynamictreesdefiledlands:tenebrabranch:4)
Block(1,10,-1,dynamictreesdefiledlands:leaves0:0)
Block(1,10,0,dynamictreesdefiledlands:tenebrabranch:4)
Block(1,11,-2,dynamictreesdefiledlands:tenebrabranch)
Block(1,11,-1,dynamictreesdefiledlands:tenebrabranch:1)
Block(1,11,0,dynamictreesdefiledlands:tenebrabranch:4)
Block(1,11,1,dynamictreesdefiledlands:leaves0:0)
Block(1,12,-2,dynamictreesdefiledlands:leaves0:0)
Block(2,6,0,dynamictreesdefiledlands:tenebrabranch)
Block(2,7,-1,dynamictreesdefiledlands:leaves0:0)
Block(2,7,0,dynamictreesdefiledlands:leaves0:0)
Block(2,11,-2,dynamictreesdefiledlands:leaves0:0)
Block(2,11,-1,dynamictreesdefiledlands:leaves0:0)
Block(2,11,0,dynamictreesdefiledlands:tenebrabranch)
Block(2,11,1,dynamictreesdefiledlands:leaves0:0)
Block(2,12,0,dynamictreesdefiledlands:leaves0:0)
Block(3,11,0,dynamictreesdefiledlands:leaves0:0)

#######################################################################
# +-----------------------------------------------------------------+ #
# |                            BO3 checks                           | #
# +-----------------------------------------------------------------+ #
#######################################################################

BlockCheck(1,-1,0,GRASS,DIRT,biomesoplenty:grass,biomesoplenty:dirt,defiledlands:dirt_defiled,defiledlands:grass_defiled,defiledlands:sand_defiled)

#######################################################################
# +-----------------------------------------------------------------+ #
# |                             Branches                            | #
# +-----------------------------------------------------------------+ #
#######################################################################


#######################################################################
# +-----------------------------------------------------------------+ #
# |                             Entities                            | #
# +-----------------------------------------------------------------+ #
#######################################################################


#######################################################################
# +-----------------------------------------------------------------+ #
# |                            Particles                            | #
# +-----------------------------------------------------------------+ #
#######################################################################


#######################################################################
# +-----------------------------------------------------------------+ #
# |                             Spawners                            | #
# +-----------------------------------------------------------------+ #
#######################################################################


#######################################################################
# +-----------------------------------------------------------------+ #
# |                             ModData                             | #
# +-----------------------------------------------------------------+ #
#######################################################################

