
#######################################################################
# +-----------------------------------------------------------------+ #
# |                            BO4 object                           | #
# +-----------------------------------------------------------------+ #
#######################################################################

Author: NLBlackEagle

Description: No description given

SettingsMode: WriteDisable


#######################################################################
# +-----------------------------------------------------------------+ #
# |                          Main settings                          | #
# +-----------------------------------------------------------------+ #
#######################################################################

Frequency: 0

SpawnHeight: highestBlock

UseCenterForHighestBlock: true

##############################
# Height Limits for the BO4. #
##############################

MinHeight: 0

MaxHeight: 255

InheritBO3: 

InheritBO3Rotation: NORTH

OverrideChildSettings: true

OverrideParentHeight: false

CanOverride: true

BranchFrequency: 0

BranchFrequencyGroup: 

MustBeBelowOther: false

MustBeInside: 

CannotBeInside: 

ReplacesBO3: 

MustBeInsideWorldBorders: false

CanSpawnOnWater: true

SpawnOnWaterOnly: false

SpawnUnderWater: false

SpawnAtWaterLevel: false

HeightOffset: 0

RemoveAir: false

ReplaceAbove: 

ReplaceBelow: 

ReplaceWithBiomeBlocks: true

ReplaceWithSurfaceBlock: GRASS

ReplaceWithGroundBlock: DIRT

ReplaceWithStoneBlock: STONE

SmoothRadius: 0

SmoothHeightOffset: 0

SmoothStartTop: false

SmoothStartWood: false

SmoothingSurfaceBlock: 

SmoothingGroundBlock: 

BO3Group: 

IsSpawnPoint: false

DoReplaceBlocks: false


#######################################################################
# +-----------------------------------------------------------------+ #
# |                              Blocks                             | #
# +-----------------------------------------------------------------+ #
#######################################################################

Block(-7,750,-6,AIR:0)
Block(-5,0,0,SPRUCE_FENCE:0)
Block(-5,0,1,SPRUCE_FENCE:0)
Block(-5,0,2,SPRUCE_FENCE:0)
Block(-5,0,3,SPRUCE_FENCE:0)
Block(-5,1,0,SPRUCE_FENCE:0)
Block(-5,1,1,SPRUCE_FENCE:0)
Block(-5,1,2,SPRUCE_FENCE:0)
Block(-5,1,3,SPRUCE_FENCE:0)
Block(-5,2,0,SPRUCE_FENCE:0)
Block(-5,2,1,SPRUCE_FENCE:0)
Block(-5,2,2,SPRUCE_FENCE:0)
Block(-5,2,3,SPRUCE_FENCE:0)
Block(-5,3,0,SPRUCE_FENCE:0)
Block(-5,3,1,SPRUCE_FENCE:0)
Block(-5,3,2,SPRUCE_FENCE:0)
Block(-5,3,3,SPRUCE_FENCE:0)
Block(-5,4,0,SPRUCE_FENCE:0)
Block(-5,4,1,SPRUCE_FENCE:0)
Block(-5,4,2,SPRUCE_FENCE:0)
Block(-5,4,3,SPRUCE_FENCE:0)
Block(-5,5,0,SPRUCE_FENCE:0)
Block(-5,5,1,SPRUCE_FENCE:0)
Block(-5,5,2,SPRUCE_FENCE:0)
Block(-5,5,3,SPRUCE_FENCE:0)
Block(-5,6,0,SPRUCE_FENCE:0)
Block(-5,6,1,SPRUCE_FENCE:0)
Block(-5,6,2,SPRUCE_FENCE:0)
Block(-5,6,3,SPRUCE_FENCE:0)
Block(-5,7,0,SPRUCE_FENCE:0)
Block(-5,7,1,SPRUCE_FENCE:0)
Block(-5,7,2,SPRUCE_FENCE:0)
Block(-5,7,3,SPRUCE_FENCE:0)
Block(-5,8,0,SPRUCE_FENCE:0)
Block(-5,8,1,SPRUCE_FENCE:0)
Block(-5,8,2,SPRUCE_FENCE:0)
Block(-5,8,3,SPRUCE_FENCE:0)
Block(-5,9,0,SPRUCE_FENCE:0)
Block(-5,9,1,SPRUCE_FENCE:0)
Block(-5,9,2,SPRUCE_FENCE:0)
Block(-5,9,3,SPRUCE_FENCE:0)
Block(-5,10,0,SPRUCE_FENCE:0)
Block(-5,10,1,SPRUCE_FENCE:0)
Block(-5,10,2,SPRUCE_FENCE:0)
Block(-5,10,3,SPRUCE_FENCE:0)
Block(-5,11,0,SPRUCE_FENCE:0)
Block(-5,11,1,SPRUCE_FENCE:0)
Block(-5,11,2,SPRUCE_FENCE:0)
Block(-5,11,3,SPRUCE_FENCE:0)
Block(-5,12,0,SPRUCE_FENCE:0)
Block(-5,12,1,SPRUCE_FENCE:0)
Block(-5,12,2,SPRUCE_FENCE:0)
Block(-5,12,3,SPRUCE_FENCE:0)
Block(-5,13,0,SPRUCE_FENCE:0)
Block(-5,13,1,SPRUCE_FENCE:0)
Block(-5,13,2,SPRUCE_FENCE:0)
Block(-5,13,3,SPRUCE_FENCE:0)
Block(-5,14,0,SPRUCE_FENCE:0)
Block(-5,14,1,SPRUCE_FENCE:0)
Block(-5,14,2,SPRUCE_FENCE:0)
Block(-5,14,3,SPRUCE_FENCE:0)
Block(-5,15,0,SPRUCE_FENCE:0)
Block(-5,15,1,SPRUCE_FENCE:0)
Block(-5,15,2,SPRUCE_FENCE:0)
Block(-5,15,3,SPRUCE_FENCE:0)
Block(-5,16,0,SPRUCE_FENCE:0)
Block(-5,16,1,SPRUCE_FENCE:0)
Block(-5,16,2,SPRUCE_FENCE:0)
Block(-5,16,3,SPRUCE_FENCE:0)
Block(-5,17,0,SPRUCE_FENCE:0)
Block(-5,17,1,SPRUCE_FENCE:0)
Block(-5,17,2,SPRUCE_FENCE:0)
Block(-5,17,3,SPRUCE_FENCE:0)
Block(-5,18,0,SPRUCE_FENCE:0)
Block(-5,18,1,SPRUCE_FENCE:0)
Block(-5,18,2,SPRUCE_FENCE:0)
Block(-5,18,3,SPRUCE_FENCE:0)
Block(-5,19,0,SPRUCE_FENCE:0)
Block(-5,19,1,SPRUCE_FENCE:0)
Block(-5,19,2,SPRUCE_FENCE:0)
Block(-5,19,3,SPRUCE_FENCE:0)
Block(-5,20,0,SPRUCE_FENCE:0)
Block(-5,20,1,SPRUCE_FENCE:0)
Block(-5,20,2,SPRUCE_FENCE:0)
Block(-5,20,3,SPRUCE_FENCE:0)
Block(-5,21,0,SPRUCE_FENCE:0)
Block(-5,21,1,SPRUCE_FENCE:0)
Block(-5,21,2,SPRUCE_FENCE:0)
Block(-5,21,3,SPRUCE_FENCE:0)
Block(-5,22,0,SPRUCE_FENCE:0)
Block(-5,22,1,SPRUCE_FENCE:0)
Block(-5,22,2,SPRUCE_FENCE:0)
Block(-5,22,3,SPRUCE_FENCE:0)
Block(-5,23,0,SPRUCE_FENCE:0)
Block(-5,23,1,SPRUCE_FENCE:0)
Block(-5,23,2,SPRUCE_FENCE:0)
Block(-5,23,3,SPRUCE_FENCE:0)
Block(-5,24,0,SPRUCE_FENCE:0)
Block(-5,24,1,SPRUCE_FENCE:0)
Block(-5,24,2,SPRUCE_FENCE:0)
Block(-5,24,3,SPRUCE_FENCE:0)
Block(-5,25,0,SPRUCE_FENCE:0)
Block(-5,25,1,SPRUCE_FENCE:0)
Block(-5,25,2,SPRUCE_FENCE:0)
Block(-5,25,3,SPRUCE_FENCE:0)
Block(-5,26,0,SPRUCE_FENCE:0)
Block(-5,26,1,SPRUCE_FENCE:0)
Block(-5,26,2,SPRUCE_FENCE:0)
Block(-5,26,3,SPRUCE_FENCE:0)
Block(-5,27,0,SPRUCE_FENCE:0)
Block(-5,27,1,SPRUCE_FENCE:0)
Block(-5,27,2,SPRUCE_FENCE:0)
Block(-5,27,3,SPRUCE_FENCE:0)
Block(-5,28,0,SPRUCE_FENCE:0)
Block(-5,28,1,SPRUCE_FENCE:0)
Block(-5,28,2,SPRUCE_FENCE:0)
Block(-5,28,3,SPRUCE_FENCE:0)
Block(-5,29,0,SPRUCE_FENCE:0)
Block(-5,29,1,SPRUCE_FENCE:0)
Block(-5,29,2,SPRUCE_FENCE:0)
Block(-5,29,3,SPRUCE_FENCE:0)
Block(-5,30,0,SPRUCE_FENCE:0)
Block(-5,30,1,SPRUCE_FENCE:0)
Block(-5,30,2,SPRUCE_FENCE:0)
Block(-5,30,3,SPRUCE_FENCE:0)
Block(-5,31,0,SPRUCE_FENCE:0)
Block(-5,31,1,SPRUCE_FENCE:0)
Block(-5,31,2,SPRUCE_FENCE:0)
Block(-5,31,3,SPRUCE_FENCE:0)
Block(-5,32,0,SPRUCE_FENCE:0)
Block(-5,32,1,SPRUCE_FENCE:0)
Block(-5,32,2,SPRUCE_FENCE:0)
Block(-5,32,3,SPRUCE_FENCE:0)
Block(-5,33,0,SPRUCE_FENCE:0)
Block(-5,33,1,SPRUCE_FENCE:0)
Block(-5,33,2,SPRUCE_FENCE:0)
Block(-5,33,3,SPRUCE_FENCE:0)
Block(-5,34,0,SPRUCE_FENCE:0)
Block(-5,34,1,SPRUCE_FENCE:0)
Block(-5,34,2,SPRUCE_FENCE:0)
Block(-5,34,3,SPRUCE_FENCE:0)
Block(-5,35,0,SPRUCE_FENCE:0)
Block(-5,35,1,SPRUCE_FENCE:0)
Block(-5,35,2,SPRUCE_FENCE:0)
Block(-5,35,3,SPRUCE_FENCE:0)
Block(-5,36,0,SPRUCE_FENCE:0)
Block(-5,36,1,SPRUCE_FENCE:0)
Block(-5,36,2,SPRUCE_FENCE:0)
Block(-5,36,3,SPRUCE_FENCE:0)
Block(-4,0,-2,SPRUCE_FENCE:0)
Block(-4,0,-1,SPRUCE_FENCE:0)
Block(-4,0,0,SPRUCE_FENCE:0)
Block(-4,0,1,LADDER:4)
Block(-4,0,2,LADDER:4)
Block(-4,0,3,SPRUCE_FENCE:0)
Block(-4,0,4,SPRUCE_FENCE:0)
Block(-4,0,5,SPRUCE_FENCE:0)
Block(-4,1,-2,SPRUCE_FENCE:0)
Block(-4,1,-1,SPRUCE_FENCE:0)
Block(-4,1,0,SPRUCE_FENCE:0)
Block(-4,1,1,LADDER:4)
Block(-4,1,2,LADDER:4)
Block(-4,1,3,SPRUCE_FENCE:0)
Block(-4,1,4,SPRUCE_FENCE:0)
Block(-4,1,5,SPRUCE_FENCE:0)
Block(-4,2,-2,SPRUCE_FENCE:0)
Block(-4,2,-1,SPRUCE_FENCE:0)
Block(-4,2,0,SPRUCE_FENCE:0)
Block(-4,2,1,LADDER:4)
Block(-4,2,2,LADDER:4)
Block(-4,2,3,SPRUCE_FENCE:0)
Block(-4,2,4,SPRUCE_FENCE:0)
Block(-4,2,5,SPRUCE_FENCE:0)
Block(-4,3,-2,SPRUCE_FENCE:0)
Block(-4,3,-1,SPRUCE_FENCE:0)
Block(-4,3,0,SPRUCE_FENCE:0)
Block(-4,3,1,LADDER:4)
Block(-4,3,2,LADDER:4)
Block(-4,3,3,SPRUCE_FENCE:0)
Block(-4,3,4,SPRUCE_FENCE:0)
Block(-4,3,5,SPRUCE_FENCE:0)
Block(-4,4,-2,SPRUCE_FENCE:0)
Block(-4,4,-1,SPRUCE_FENCE:0)
Block(-4,4,0,SPRUCE_FENCE:0)
Block(-4,4,1,LADDER:4)
Block(-4,4,2,LADDER:4)
Block(-4,4,3,SPRUCE_FENCE:0)
Block(-4,4,4,SPRUCE_FENCE:0)
Block(-4,4,5,SPRUCE_FENCE:0)
Block(-4,5,-2,SPRUCE_FENCE:0)
Block(-4,5,-1,SPRUCE_FENCE:0)
Block(-4,5,0,SPRUCE_FENCE:0)
Block(-4,5,1,LADDER:4)
Block(-4,5,2,LADDER:4)
Block(-4,5,3,SPRUCE_FENCE:0)
Block(-4,5,4,SPRUCE_FENCE:0)
Block(-4,5,5,SPRUCE_FENCE:0)
Block(-4,6,-2,SPRUCE_FENCE:0)
Block(-4,6,-1,SPRUCE_FENCE:0)
Block(-4,6,0,SPRUCE_FENCE:0)
Block(-4,6,1,LADDER:4)
Block(-4,6,2,LADDER:4)
Block(-4,6,3,SPRUCE_FENCE:0)
Block(-4,6,4,SPRUCE_FENCE:0)
Block(-4,6,5,SPRUCE_FENCE:0)
Block(-4,7,-2,SPRUCE_FENCE:0)
Block(-4,7,-1,SPRUCE_FENCE:0)
Block(-4,7,0,SPRUCE_FENCE:0)
Block(-4,7,1,LADDER:4)
Block(-4,7,2,LADDER:4)
Block(-4,7,3,SPRUCE_FENCE:0)
Block(-4,7,4,SPRUCE_FENCE:0)
Block(-4,7,5,SPRUCE_FENCE:0)
Block(-4,8,-2,SPRUCE_FENCE:0)
Block(-4,8,-1,SPRUCE_FENCE:0)
Block(-4,8,0,SPRUCE_FENCE:0)
Block(-4,8,1,LADDER:4)
Block(-4,8,2,LADDER:4)
Block(-4,8,3,SPRUCE_FENCE:0)
Block(-4,8,4,SPRUCE_FENCE:0)
Block(-4,8,5,SPRUCE_FENCE:0)
Block(-4,9,-2,SPRUCE_FENCE:0)
Block(-4,9,-1,SPRUCE_FENCE:0)
Block(-4,9,0,SPRUCE_FENCE:0)
Block(-4,9,1,LADDER:4)
Block(-4,9,2,LADDER:4)
Block(-4,9,3,SPRUCE_FENCE:0)
Block(-4,9,4,SPRUCE_FENCE:0)
Block(-4,9,5,SPRUCE_FENCE:0)
Block(-4,10,-2,SPRUCE_FENCE:0)
Block(-4,10,-1,SPRUCE_FENCE:0)
Block(-4,10,0,SPRUCE_FENCE:0)
Block(-4,10,1,LADDER:4)
Block(-4,10,2,LADDER:4)
Block(-4,10,3,SPRUCE_FENCE:0)
Block(-4,10,4,SPRUCE_FENCE:0)
Block(-4,10,5,SPRUCE_FENCE:0)
Block(-4,11,-2,SPRUCE_FENCE:0)
Block(-4,11,-1,SPRUCE_FENCE:0)
Block(-4,11,0,SPRUCE_FENCE:0)
Block(-4,11,1,LADDER:4)
Block(-4,11,2,LADDER:4)
Block(-4,11,3,SPRUCE_FENCE:0)
Block(-4,11,4,SPRUCE_FENCE:0)
Block(-4,11,5,SPRUCE_FENCE:0)
Block(-4,12,-2,SPRUCE_FENCE:0)
Block(-4,12,-1,SPRUCE_FENCE:0)
Block(-4,12,0,SPRUCE_FENCE:0)
Block(-4,12,1,LADDER:4)
Block(-4,12,2,LADDER:4)
Block(-4,12,3,SPRUCE_FENCE:0)
Block(-4,12,4,SPRUCE_FENCE:0)
Block(-4,12,5,SPRUCE_FENCE:0)
Block(-4,13,-2,SPRUCE_FENCE:0)
Block(-4,13,-1,SPRUCE_FENCE:0)
Block(-4,13,0,SPRUCE_FENCE:0)
Block(-4,13,1,LADDER:4)
Block(-4,13,2,LADDER:4)
Block(-4,13,3,SPRUCE_FENCE:0)
Block(-4,13,4,SPRUCE_FENCE:0)
Block(-4,13,5,SPRUCE_FENCE:0)
Block(-4,14,-2,SPRUCE_FENCE:0)
Block(-4,14,-1,SPRUCE_FENCE:0)
Block(-4,14,0,SPRUCE_FENCE:0)
Block(-4,14,1,LADDER:4)
Block(-4,14,2,LADDER:4)
Block(-4,14,3,SPRUCE_FENCE:0)
Block(-4,14,4,SPRUCE_FENCE:0)
Block(-4,14,5,SPRUCE_FENCE:0)
Block(-4,15,-2,SPRUCE_FENCE:0)
Block(-4,15,-1,SPRUCE_FENCE:0)
Block(-4,15,0,SPRUCE_FENCE:0)
Block(-4,15,1,LADDER:4)
Block(-4,15,2,LADDER:4)
Block(-4,15,3,SPRUCE_FENCE:0)
Block(-4,15,4,SPRUCE_FENCE:0)
Block(-4,15,5,SPRUCE_FENCE:0)
Block(-4,16,-2,SPRUCE_FENCE:0)
Block(-4,16,-1,SPRUCE_FENCE:0)
Block(-4,16,0,SPRUCE_FENCE:0)
Block(-4,16,1,LADDER:4)
Block(-4,16,2,LADDER:4)
Block(-4,16,3,SPRUCE_FENCE:0)
Block(-4,16,4,SPRUCE_FENCE:0)
Block(-4,16,5,SPRUCE_FENCE:0)
Block(-4,17,-2,SPRUCE_FENCE:0)
Block(-4,17,-1,SPRUCE_FENCE:0)
Block(-4,17,0,SPRUCE_FENCE:0)
Block(-4,17,1,LADDER:4)
Block(-4,17,2,LADDER:4)
Block(-4,17,3,SPRUCE_FENCE:0)
Block(-4,17,4,SPRUCE_FENCE:0)
Block(-4,17,5,SPRUCE_FENCE:0)
Block(-4,18,-2,SPRUCE_FENCE:0)
Block(-4,18,-1,SPRUCE_FENCE:0)
Block(-4,18,0,SPRUCE_FENCE:0)
Block(-4,18,1,LADDER:4)
Block(-4,18,2,LADDER:4)
Block(-4,18,3,SPRUCE_FENCE:0)
Block(-4,18,4,SPRUCE_FENCE:0)
Block(-4,18,5,SPRUCE_FENCE:0)
Block(-4,19,-2,SPRUCE_FENCE:0)
Block(-4,19,-1,SPRUCE_FENCE:0)
Block(-4,19,0,SPRUCE_FENCE:0)
Block(-4,19,1,LADDER:4)
Block(-4,19,2,LADDER:4)
Block(-4,19,3,SPRUCE_FENCE:0)
Block(-4,19,4,SPRUCE_FENCE:0)
Block(-4,19,5,SPRUCE_FENCE:0)
Block(-4,20,-2,SPRUCE_FENCE:0)
Block(-4,20,-1,SPRUCE_FENCE:0)
Block(-4,20,0,SPRUCE_FENCE:0)
Block(-4,20,1,LADDER:4)
Block(-4,20,2,LADDER:4)
Block(-4,20,3,SPRUCE_FENCE:0)
Block(-4,20,4,SPRUCE_FENCE:0)
Block(-4,20,5,SPRUCE_FENCE:0)
Block(-4,21,-2,SPRUCE_FENCE:0)
Block(-4,21,-1,SPRUCE_FENCE:0)
Block(-4,21,0,SPRUCE_FENCE:0)
Block(-4,21,1,LADDER:4)
Block(-4,21,2,LADDER:4)
Block(-4,21,3,SPRUCE_FENCE:0)
Block(-4,21,4,SPRUCE_FENCE:0)
Block(-4,21,5,SPRUCE_FENCE:0)
Block(-4,22,-2,SPRUCE_FENCE:0)
Block(-4,22,-1,SPRUCE_FENCE:0)
Block(-4,22,0,SPRUCE_FENCE:0)
Block(-4,22,1,LADDER:4)
Block(-4,22,2,LADDER:4)
Block(-4,22,3,SPRUCE_FENCE:0)
Block(-4,22,4,SPRUCE_FENCE:0)
Block(-4,22,5,SPRUCE_FENCE:0)
Block(-4,23,-2,SPRUCE_FENCE:0)
Block(-4,23,-1,SPRUCE_FENCE:0)
Block(-4,23,0,SPRUCE_FENCE:0)
Block(-4,23,1,LADDER:4)
Block(-4,23,2,LADDER:4)
Block(-4,23,3,SPRUCE_FENCE:0)
Block(-4,23,4,SPRUCE_FENCE:0)
Block(-4,23,5,SPRUCE_FENCE:0)
Block(-4,24,-2,SPRUCE_FENCE:0)
Block(-4,24,-1,SPRUCE_FENCE:0)
Block(-4,24,0,SPRUCE_FENCE:0)
Block(-4,24,1,LADDER:4)
Block(-4,24,2,LADDER:4)
Block(-4,24,3,SPRUCE_FENCE:0)
Block(-4,24,4,SPRUCE_FENCE:0)
Block(-4,24,5,SPRUCE_FENCE:0)
Block(-4,25,-2,SPRUCE_FENCE:0)
Block(-4,25,-1,SPRUCE_FENCE:0)
Block(-4,25,0,SPRUCE_FENCE:0)
Block(-4,25,1,LADDER:4)
Block(-4,25,2,LADDER:4)
Block(-4,25,3,SPRUCE_FENCE:0)
Block(-4,25,4,SPRUCE_FENCE:0)
Block(-4,25,5,SPRUCE_FENCE:0)
Block(-4,26,-2,SPRUCE_FENCE:0)
Block(-4,26,-1,SPRUCE_FENCE:0)
Block(-4,26,0,SPRUCE_FENCE:0)
Block(-4,26,1,LADDER:4)
Block(-4,26,2,LADDER:4)
Block(-4,26,3,SPRUCE_FENCE:0)
Block(-4,26,4,SPRUCE_FENCE:0)
Block(-4,26,5,SPRUCE_FENCE:0)
Block(-4,27,-2,SPRUCE_FENCE:0)
Block(-4,27,-1,SPRUCE_FENCE:0)
Block(-4,27,0,SPRUCE_FENCE:0)
Block(-4,27,1,LADDER:4)
Block(-4,27,2,LADDER:4)
Block(-4,27,3,SPRUCE_FENCE:0)
Block(-4,27,4,SPRUCE_FENCE:0)
Block(-4,27,5,SPRUCE_FENCE:0)
Block(-4,28,-2,SPRUCE_FENCE:0)
Block(-4,28,-1,SPRUCE_FENCE:0)
Block(-4,28,0,SPRUCE_FENCE:0)
Block(-4,28,1,LADDER:4)
Block(-4,28,2,LADDER:4)
Block(-4,28,3,SPRUCE_FENCE:0)
Block(-4,28,4,SPRUCE_FENCE:0)
Block(-4,28,5,SPRUCE_FENCE:0)
Block(-4,29,-2,SPRUCE_FENCE:0)
Block(-4,29,-1,SPRUCE_FENCE:0)
Block(-4,29,0,SPRUCE_FENCE:0)
Block(-4,29,1,LADDER:4)
Block(-4,29,2,LADDER:4)
Block(-4,29,3,SPRUCE_FENCE:0)
Block(-4,29,4,SPRUCE_FENCE:0)
Block(-4,29,5,SPRUCE_FENCE:0)
Block(-4,30,-2,SPRUCE_FENCE:0)
Block(-4,30,-1,SPRUCE_FENCE:0)
Block(-4,30,0,SPRUCE_FENCE:0)
Block(-4,30,1,LADDER:4)
Block(-4,30,2,LADDER:4)
Block(-4,30,3,SPRUCE_FENCE:0)
Block(-4,30,4,SPRUCE_FENCE:0)
Block(-4,30,5,SPRUCE_FENCE:0)
Block(-4,31,-2,SPRUCE_FENCE:0)
Block(-4,31,-1,SPRUCE_FENCE:0)
Block(-4,31,0,SPRUCE_FENCE:0)
Block(-4,31,1,LADDER:4)
Block(-4,31,2,LADDER:4)
Block(-4,31,3,SPRUCE_FENCE:0)
Block(-4,31,4,SPRUCE_FENCE:0)
Block(-4,31,5,SPRUCE_FENCE:0)
Block(-4,32,-2,SPRUCE_FENCE:0)
Block(-4,32,-1,SPRUCE_FENCE:0)
Block(-4,32,0,SPRUCE_FENCE:0)
Block(-4,32,1,LADDER:4)
Block(-4,32,2,LADDER:4)
Block(-4,32,3,SPRUCE_FENCE:0)
Block(-4,32,4,SPRUCE_FENCE:0)
Block(-4,32,5,SPRUCE_FENCE:0)
Block(-4,33,-2,SPRUCE_FENCE:0)
Block(-4,33,-1,SPRUCE_FENCE:0)
Block(-4,33,0,SPRUCE_FENCE:0)
Block(-4,33,1,LADDER:4)
Block(-4,33,2,LADDER:4)
Block(-4,33,3,SPRUCE_FENCE:0)
Block(-4,33,4,SPRUCE_FENCE:0)
Block(-4,33,5,SPRUCE_FENCE:0)
Block(-4,34,-2,SPRUCE_FENCE:0)
Block(-4,34,-1,SPRUCE_FENCE:0)
Block(-4,34,0,SPRUCE_FENCE:0)
Block(-4,34,1,LADDER:4)
Block(-4,34,2,LADDER:4)
Block(-4,34,3,SPRUCE_FENCE:0)
Block(-4,34,4,SPRUCE_FENCE:0)
Block(-4,34,5,SPRUCE_FENCE:0)
Block(-4,35,-2,SPRUCE_FENCE:0)
Block(-4,35,-1,SPRUCE_FENCE:0)
Block(-4,35,0,SPRUCE_FENCE:0)
Block(-4,35,1,LADDER:4)
Block(-4,35,2,LADDER:4)
Block(-4,35,3,SPRUCE_FENCE:0)
Block(-4,35,4,SPRUCE_FENCE:0)
Block(-4,35,5,SPRUCE_FENCE:0)
Block(-4,36,-2,SPRUCE_FENCE:0)
Block(-4,36,-1,SPRUCE_FENCE:0)
Block(-4,36,0,SPRUCE_FENCE:0)
Block(-4,36,1,LADDER:4)
Block(-4,36,2,LADDER:4)
Block(-4,36,3,SPRUCE_FENCE:0)
Block(-4,36,4,SPRUCE_FENCE:0)
Block(-4,36,5,SPRUCE_FENCE:0)
Block(-3,0,-2,SPRUCE_FENCE:0)
Block(-3,0,-1,AIR:0)
Block(-3,0,0,WOOD:1)
Block(-3,0,1,AIR:0)
Block(-3,0,2,AIR:0)
Block(-3,0,3,WOOD:1)
Block(-3,0,4,AIR:0)
Block(-3,0,5,SPRUCE_FENCE:0)
Block(-3,1,-2,SPRUCE_FENCE:0)
Block(-3,1,-1,AIR:0)
Block(-3,1,0,WOOD:1)
Block(-3,1,1,WOOD:1)
Block(-3,1,2,WOOD:1)
Block(-3,1,3,WOOD:1)
Block(-3,1,4,AIR:0)
Block(-3,1,5,SPRUCE_FENCE:0)
Block(-3,2,-2,SPRUCE_FENCE:0)
Block(-3,2,-1,AIR:0)
Block(-3,2,0,WOOD:1)
Block(-3,2,1,AIR:0)
Block(-3,2,2,AIR:0)
Block(-3,2,3,WOOD:1)
Block(-3,2,4,AIR:0)
Block(-3,2,5,SPRUCE_FENCE:0)
Block(-3,3,-2,SPRUCE_FENCE:0)
Block(-3,3,-1,AIR:0)
Block(-3,3,0,WOOD:1)
Block(-3,3,1,AIR:0)
Block(-3,3,2,AIR:0)
Block(-3,3,3,WOOD:1)
Block(-3,3,4,AIR:0)
Block(-3,3,5,SPRUCE_FENCE:0)
Block(-3,4,-2,SPRUCE_FENCE:0)
Block(-3,4,-1,AIR:0)
Block(-3,4,0,WOOD:1)
Block(-3,4,1,WOOD:1)
Block(-3,4,2,WOOD:1)
Block(-3,4,3,WOOD:1)
Block(-3,4,4,AIR:0)
Block(-3,4,5,SPRUCE_FENCE:0)
Block(-3,5,-2,SPRUCE_FENCE:0)
Block(-3,5,-1,AIR:0)
Block(-3,5,0,WOOD:1)
Block(-3,5,1,AIR:0)
Block(-3,5,2,AIR:0)
Block(-3,5,3,WOOD:1)
Block(-3,5,4,AIR:0)
Block(-3,5,5,SPRUCE_FENCE:0)
Block(-3,6,-2,SPRUCE_FENCE:0)
Block(-3,6,-1,AIR:0)
Block(-3,6,0,WOOD:1)
Block(-3,6,1,AIR:0)
Block(-3,6,2,AIR:0)
Block(-3,6,3,WOOD:1)
Block(-3,6,4,AIR:0)
Block(-3,6,5,SPRUCE_FENCE:0)
Block(-3,7,-2,SPRUCE_FENCE:0)
Block(-3,7,-1,AIR:0)
Block(-3,7,0,WOOD:1)
Block(-3,7,1,WOOD:1)
Block(-3,7,2,WOOD:1)
Block(-3,7,3,WOOD:1)
Block(-3,7,4,AIR:0)
Block(-3,7,5,SPRUCE_FENCE:0)
Block(-3,8,-2,SPRUCE_FENCE:0)
Block(-3,8,-1,AIR:0)
Block(-3,8,0,WOOD:1)
Block(-3,8,1,AIR:0)
Block(-3,8,2,AIR:0)
Block(-3,8,3,WOOD:1)
Block(-3,8,4,AIR:0)
Block(-3,8,5,SPRUCE_FENCE:0)
Block(-3,9,-2,SPRUCE_FENCE:0)
Block(-3,9,-1,AIR:0)
Block(-3,9,0,WOOD:1)
Block(-3,9,1,WOOD:1)
Block(-3,9,2,WOOD:1)
Block(-3,9,3,WOOD:1)
Block(-3,9,4,AIR:0)
Block(-3,9,5,SPRUCE_FENCE:0)
Block(-3,10,-2,SPRUCE_FENCE:0)
Block(-3,10,-1,AIR:0)
Block(-3,10,0,WOOD:1)
Block(-3,10,1,AIR:0)
Block(-3,10,2,AIR:0)
Block(-3,10,3,WOOD:1)
Block(-3,10,4,AIR:0)
Block(-3,10,5,SPRUCE_FENCE:0)
Block(-3,11,-2,SPRUCE_FENCE:0)
Block(-3,11,-1,AIR:0)
Block(-3,11,0,WOOD:1)
Block(-3,11,1,AIR:0)
Block(-3,11,2,AIR:0)
Block(-3,11,3,WOOD:1)
Block(-3,11,4,AIR:0)
Block(-3,11,5,SPRUCE_FENCE:0)
Block(-3,12,-2,SPRUCE_FENCE:0)
Block(-3,12,-1,AIR:0)
Block(-3,12,0,WOOD:1)
Block(-3,12,1,WOOD:1)
Block(-3,12,2,WOOD:1)
Block(-3,12,3,WOOD:1)
Block(-3,12,4,AIR:0)
Block(-3,12,5,SPRUCE_FENCE:0)
Block(-3,13,-2,SPRUCE_FENCE:0)
Block(-3,13,-1,AIR:0)
Block(-3,13,0,WOOD:1)
Block(-3,13,1,AIR:0)
Block(-3,13,2,AIR:0)
Block(-3,13,3,WOOD:1)
Block(-3,13,4,AIR:0)
Block(-3,13,5,SPRUCE_FENCE:0)
Block(-3,14,-2,SPRUCE_FENCE:0)
Block(-3,14,-1,AIR:0)
Block(-3,14,0,WOOD:1)
Block(-3,14,1,AIR:0)
Block(-3,14,2,AIR:0)
Block(-3,14,3,WOOD:1)
Block(-3,14,4,AIR:0)
Block(-3,14,5,SPRUCE_FENCE:0)
Block(-3,15,-2,SPRUCE_FENCE:0)
Block(-3,15,-1,AIR:0)
Block(-3,15,0,WOOD:1)
Block(-3,15,1,WOOD:1)
Block(-3,15,2,WOOD:1)
Block(-3,15,3,WOOD:1)
Block(-3,15,4,AIR:0)
Block(-3,15,5,SPRUCE_FENCE:0)
Block(-3,16,-2,SPRUCE_FENCE:0)
Block(-3,16,-1,AIR:0)
Block(-3,16,0,WOOD:1)
Block(-3,16,1,AIR:0)
Block(-3,16,2,AIR:0)
Block(-3,16,3,WOOD:1)
Block(-3,16,4,AIR:0)
Block(-3,16,5,SPRUCE_FENCE:0)
Block(-3,17,-2,SPRUCE_FENCE:0)
Block(-3,17,-1,AIR:0)
Block(-3,17,0,WOOD:1)
Block(-3,17,1,WOOD:1)
Block(-3,17,2,WOOD:1)
Block(-3,17,3,WOOD:1)
Block(-3,17,4,AIR:0)
Block(-3,17,5,SPRUCE_FENCE:0)
Block(-3,18,-2,SPRUCE_FENCE:0)
Block(-3,18,-1,AIR:0)
Block(-3,18,0,WOOD:1)
Block(-3,18,1,AIR:0)
Block(-3,18,2,AIR:0)
Block(-3,18,3,WOOD:1)
Block(-3,18,4,AIR:0)
Block(-3,18,5,SPRUCE_FENCE:0)
Block(-3,19,-2,SPRUCE_FENCE:0)
Block(-3,19,-1,AIR:0)
Block(-3,19,0,WOOD:1)
Block(-3,19,1,AIR:0)
Block(-3,19,2,AIR:0)
Block(-3,19,3,WOOD:1)
Block(-3,19,4,AIR:0)
Block(-3,19,5,SPRUCE_FENCE:0)
Block(-3,20,-2,SPRUCE_FENCE:0)
Block(-3,20,-1,AIR:0)
Block(-3,20,0,WOOD:1)
Block(-3,20,1,WOOD:1)
Block(-3,20,2,WOOD:1)
Block(-3,20,3,WOOD:1)
Block(-3,20,4,AIR:0)
Block(-3,20,5,SPRUCE_FENCE:0)
Block(-3,21,-2,SPRUCE_FENCE:0)
Block(-3,21,-1,AIR:0)
Block(-3,21,0,WOOD:1)
Block(-3,21,1,AIR:0)
Block(-3,21,2,AIR:0)
Block(-3,21,3,WOOD:1)
Block(-3,21,4,AIR:0)
Block(-3,21,5,SPRUCE_FENCE:0)
Block(-3,22,-2,SPRUCE_FENCE:0)
Block(-3,22,-1,AIR:0)
Block(-3,22,0,WOOD:1)
Block(-3,22,1,AIR:0)
Block(-3,22,2,AIR:0)
Block(-3,22,3,WOOD:1)
Block(-3,22,4,AIR:0)
Block(-3,22,5,SPRUCE_FENCE:0)
Block(-3,23,-2,SPRUCE_FENCE:0)
Block(-3,23,-1,AIR:0)
Block(-3,23,0,WOOD:1)
Block(-3,23,1,WOOD:1)
Block(-3,23,2,WOOD:1)
Block(-3,23,3,WOOD:1)
Block(-3,23,4,AIR:0)
Block(-3,23,5,SPRUCE_FENCE:0)
Block(-3,24,-2,SPRUCE_FENCE:0)
Block(-3,24,-1,AIR:0)
Block(-3,24,0,WOOD:1)
Block(-3,24,1,AIR:0)
Block(-3,24,2,AIR:0)
Block(-3,24,3,WOOD:1)
Block(-3,24,4,AIR:0)
Block(-3,24,5,SPRUCE_FENCE:0)
Block(-3,25,-2,SPRUCE_FENCE:0)
Block(-3,25,-1,AIR:0)
Block(-3,25,0,WOOD:1)
Block(-3,25,1,WOOD:1)
Block(-3,25,2,WOOD:1)
Block(-3,25,3,WOOD:1)
Block(-3,25,4,AIR:0)
Block(-3,25,5,SPRUCE_FENCE:0)
Block(-3,26,-2,SPRUCE_FENCE:0)
Block(-3,26,-1,AIR:0)
Block(-3,26,0,WOOD:1)
Block(-3,26,1,AIR:0)
Block(-3,26,2,AIR:0)
Block(-3,26,3,WOOD:1)
Block(-3,26,4,AIR:0)
Block(-3,26,5,SPRUCE_FENCE:0)
Block(-3,27,-2,SPRUCE_FENCE:0)
Block(-3,27,-1,AIR:0)
Block(-3,27,0,WOOD:1)
Block(-3,27,1,AIR:0)
Block(-3,27,2,AIR:0)
Block(-3,27,3,WOOD:1)
Block(-3,27,4,AIR:0)
Block(-3,27,5,SPRUCE_FENCE:0)
Block(-3,28,-2,SPRUCE_FENCE:0)
Block(-3,28,-1,AIR:0)
Block(-3,28,0,WOOD:1)
Block(-3,28,1,WOOD:1)
Block(-3,28,2,WOOD:1)
Block(-3,28,3,WOOD:1)
Block(-3,28,4,AIR:0)
Block(-3,28,5,SPRUCE_FENCE:0)
Block(-3,29,-2,SPRUCE_FENCE:0)
Block(-3,29,-1,AIR:0)
Block(-3,29,0,WOOD:1)
Block(-3,29,1,AIR:0)
Block(-3,29,2,AIR:0)
Block(-3,29,3,WOOD:1)
Block(-3,29,4,AIR:0)
Block(-3,29,5,SPRUCE_FENCE:0)
Block(-3,30,-2,SPRUCE_FENCE:0)
Block(-3,30,-1,AIR:0)
Block(-3,30,0,WOOD:1)
Block(-3,30,1,AIR:0)
Block(-3,30,2,AIR:0)
Block(-3,30,3,WOOD:1)
Block(-3,30,4,AIR:0)
Block(-3,30,5,SPRUCE_FENCE:0)
Block(-3,31,-2,SPRUCE_FENCE:0)
Block(-3,31,-1,AIR:0)
Block(-3,31,0,WOOD:1)
Block(-3,31,1,WOOD:1)
Block(-3,31,2,WOOD:1)
Block(-3,31,3,WOOD:1)
Block(-3,31,4,AIR:0)
Block(-3,31,5,SPRUCE_FENCE:0)
Block(-3,32,-2,SPRUCE_FENCE:0)
Block(-3,32,-1,AIR:0)
Block(-3,32,0,WOOD:1)
Block(-3,32,1,AIR:0)
Block(-3,32,2,AIR:0)
Block(-3,32,3,WOOD:1)
Block(-3,32,4,AIR:0)
Block(-3,32,5,SPRUCE_FENCE:0)
Block(-3,33,-2,SPRUCE_FENCE:0)
Block(-3,33,-1,AIR:0)
Block(-3,33,0,WOOD:1)
Block(-3,33,1,WOOD:1)
Block(-3,33,2,WOOD:1)
Block(-3,33,3,WOOD:1)
Block(-3,33,4,AIR:0)
Block(-3,33,5,SPRUCE_FENCE:0)
Block(-3,34,-2,SPRUCE_FENCE:0)
Block(-3,34,-1,AIR:0)
Block(-3,34,0,WOOD:1)
Block(-3,34,1,AIR:0)
Block(-3,34,2,AIR:0)
Block(-3,34,3,WOOD:1)
Block(-3,34,4,AIR:0)
Block(-3,34,5,SPRUCE_FENCE:0)
Block(-3,35,-2,SPRUCE_FENCE:0)
Block(-3,35,-1,AIR:0)
Block(-3,35,0,WOOD:1)
Block(-3,35,1,AIR:0)
Block(-3,35,2,AIR:0)
Block(-3,35,3,WOOD:1)
Block(-3,35,4,AIR:0)
Block(-3,35,5,SPRUCE_FENCE:0)
Block(-3,36,-2,SPRUCE_FENCE:0)
Block(-3,36,-1,AIR:0)
Block(-3,36,0,WOOD:1)
Block(-3,36,1,WOOD:1)
Block(-3,36,2,WOOD:1)
Block(-3,36,3,WOOD:1)
Block(-3,36,4,AIR:0)
Block(-3,36,5,SPRUCE_FENCE:0)
Block(-2,0,-2,SPRUCE_FENCE:0)
Block(-2,0,-1,AIR:0)
Block(-2,0,0,AIR:0)
Block(-2,0,1,AIR:0)
Block(-2,0,2,AIR:0)
Block(-2,0,3,AIR:0)
Block(-2,0,4,AIR:0)
Block(-2,0,5,SPRUCE_FENCE:0)
Block(-2,1,-2,SPRUCE_FENCE:0)
Block(-2,1,-1,AIR:0)
Block(-2,1,0,AIR:0)
Block(-2,1,1,AIR:0)
Block(-2,1,2,AIR:0)
Block(-2,1,3,AIR:0)
Block(-2,1,4,AIR:0)
Block(-2,1,5,SPRUCE_FENCE:0)
Block(-2,2,-2,SPRUCE_FENCE:0)
Block(-2,2,-1,AIR:0)
Block(-2,2,0,AIR:0)
Block(-2,2,1,AIR:0)
Block(-2,2,2,AIR:0)
Block(-2,2,3,AIR:0)
Block(-2,2,4,AIR:0)
Block(-2,2,5,SPRUCE_FENCE:0)
Block(-2,3,-2,SPRUCE_FENCE:0)
Block(-2,3,-1,AIR:0)
Block(-2,3,0,AIR:0)
Block(-2,3,1,AIR:0)
Block(-2,3,2,AIR:0)
Block(-2,3,3,AIR:0)
Block(-2,3,4,AIR:0)
Block(-2,3,5,SPRUCE_FENCE:0)
Block(-2,4,-2,SPRUCE_FENCE:0)
Block(-2,4,-1,AIR:0)
Block(-2,4,0,AIR:0)
Block(-2,4,1,AIR:0)
Block(-2,4,2,AIR:0)
Block(-2,4,3,AIR:0)
Block(-2,4,4,AIR:0)
Block(-2,4,5,SPRUCE_FENCE:0)
Block(-2,5,-2,SPRUCE_FENCE:0)
Block(-2,5,-1,AIR:0)
Block(-2,5,0,AIR:0)
Block(-2,5,1,AIR:0)
Block(-2,5,2,AIR:0)
Block(-2,5,3,AIR:0)
Block(-2,5,4,AIR:0)
Block(-2,5,5,SPRUCE_FENCE:0)
Block(-2,6,-2,SPRUCE_FENCE:0)
Block(-2,6,-1,AIR:0)
Block(-2,6,0,AIR:0)
Block(-2,6,1,AIR:0)
Block(-2,6,2,AIR:0)
Block(-2,6,3,AIR:0)
Block(-2,6,4,AIR:0)
Block(-2,6,5,SPRUCE_FENCE:0)
Block(-2,7,-2,SPRUCE_FENCE:0)
Block(-2,7,-1,AIR:0)
Block(-2,7,0,AIR:0)
Block(-2,7,1,AIR:0)
Block(-2,7,2,AIR:0)
Block(-2,7,3,AIR:0)
Block(-2,7,4,AIR:0)
Block(-2,7,5,SPRUCE_FENCE:0)
Block(-2,8,-2,SPRUCE_FENCE:0)
Block(-2,8,-1,AIR:0)
Block(-2,8,0,AIR:0)
Block(-2,8,1,AIR:0)
Block(-2,8,2,AIR:0)
Block(-2,8,3,AIR:0)
Block(-2,8,4,AIR:0)
Block(-2,8,5,SPRUCE_FENCE:0)
Block(-2,9,-2,SPRUCE_FENCE:0)
Block(-2,9,-1,AIR:0)
Block(-2,9,0,AIR:0)
Block(-2,9,1,AIR:0)
Block(-2,9,2,AIR:0)
Block(-2,9,3,AIR:0)
Block(-2,9,4,AIR:0)
Block(-2,9,5,SPRUCE_FENCE:0)
Block(-2,10,-2,SPRUCE_FENCE:0)
Block(-2,10,-1,AIR:0)
Block(-2,10,0,AIR:0)
Block(-2,10,1,AIR:0)
Block(-2,10,2,AIR:0)
Block(-2,10,3,AIR:0)
Block(-2,10,4,AIR:0)
Block(-2,10,5,SPRUCE_FENCE:0)
Block(-2,11,-2,SPRUCE_FENCE:0)
Block(-2,11,-1,AIR:0)
Block(-2,11,0,AIR:0)
Block(-2,11,1,AIR:0)
Block(-2,11,2,AIR:0)
Block(-2,11,3,AIR:0)
Block(-2,11,4,AIR:0)
Block(-2,11,5,SPRUCE_FENCE:0)
Block(-2,12,-2,SPRUCE_FENCE:0)
Block(-2,12,-1,AIR:0)
Block(-2,12,0,AIR:0)
Block(-2,12,1,AIR:0)
Block(-2,12,2,AIR:0)
Block(-2,12,3,AIR:0)
Block(-2,12,4,AIR:0)
Block(-2,12,5,SPRUCE_FENCE:0)
Block(-2,13,-2,SPRUCE_FENCE:0)
Block(-2,13,-1,AIR:0)
Block(-2,13,0,AIR:0)
Block(-2,13,1,AIR:0)
Block(-2,13,2,AIR:0)
Block(-2,13,3,AIR:0)
Block(-2,13,4,AIR:0)
Block(-2,13,5,SPRUCE_FENCE:0)
Block(-2,14,-2,SPRUCE_FENCE:0)
Block(-2,14,-1,AIR:0)
Block(-2,14,0,AIR:0)
Block(-2,14,1,AIR:0)
Block(-2,14,2,AIR:0)
Block(-2,14,3,AIR:0)
Block(-2,14,4,AIR:0)
Block(-2,14,5,SPRUCE_FENCE:0)
Block(-2,15,-2,SPRUCE_FENCE:0)
Block(-2,15,-1,AIR:0)
Block(-2,15,0,AIR:0)
Block(-2,15,1,AIR:0)
Block(-2,15,2,AIR:0)
Block(-2,15,3,AIR:0)
Block(-2,15,4,AIR:0)
Block(-2,15,5,SPRUCE_FENCE:0)
Block(-2,16,-2,SPRUCE_FENCE:0)
Block(-2,16,-1,AIR:0)
Block(-2,16,0,AIR:0)
Block(-2,16,1,AIR:0)
Block(-2,16,2,AIR:0)
Block(-2,16,3,AIR:0)
Block(-2,16,4,AIR:0)
Block(-2,16,5,SPRUCE_FENCE:0)
Block(-2,17,-2,SPRUCE_FENCE:0)
Block(-2,17,-1,AIR:0)
Block(-2,17,0,AIR:0)
Block(-2,17,1,AIR:0)
Block(-2,17,2,AIR:0)
Block(-2,17,3,AIR:0)
Block(-2,17,4,AIR:0)
Block(-2,17,5,SPRUCE_FENCE:0)
Block(-2,18,-2,SPRUCE_FENCE:0)
Block(-2,18,-1,AIR:0)
Block(-2,18,0,AIR:0)
Block(-2,18,1,AIR:0)
Block(-2,18,2,AIR:0)
Block(-2,18,3,AIR:0)
Block(-2,18,4,AIR:0)
Block(-2,18,5,SPRUCE_FENCE:0)
Block(-2,19,-2,SPRUCE_FENCE:0)
Block(-2,19,-1,AIR:0)
Block(-2,19,0,AIR:0)
Block(-2,19,1,AIR:0)
Block(-2,19,2,AIR:0)
Block(-2,19,3,AIR:0)
Block(-2,19,4,AIR:0)
Block(-2,19,5,SPRUCE_FENCE:0)
Block(-2,20,-2,SPRUCE_FENCE:0)
Block(-2,20,-1,AIR:0)
Block(-2,20,0,AIR:0)
Block(-2,20,1,AIR:0)
Block(-2,20,2,AIR:0)
Block(-2,20,3,AIR:0)
Block(-2,20,4,AIR:0)
Block(-2,20,5,SPRUCE_FENCE:0)
Block(-2,21,-2,SPRUCE_FENCE:0)
Block(-2,21,-1,AIR:0)
Block(-2,21,0,AIR:0)
Block(-2,21,1,AIR:0)
Block(-2,21,2,AIR:0)
Block(-2,21,3,AIR:0)
Block(-2,21,4,AIR:0)
Block(-2,21,5,SPRUCE_FENCE:0)
Block(-2,22,-2,SPRUCE_FENCE:0)
Block(-2,22,-1,AIR:0)
Block(-2,22,0,AIR:0)
Block(-2,22,1,AIR:0)
Block(-2,22,2,AIR:0)
Block(-2,22,3,AIR:0)
Block(-2,22,4,AIR:0)
Block(-2,22,5,SPRUCE_FENCE:0)
Block(-2,23,-2,SPRUCE_FENCE:0)
Block(-2,23,-1,AIR:0)
Block(-2,23,0,AIR:0)
Block(-2,23,1,AIR:0)
Block(-2,23,2,AIR:0)
Block(-2,23,3,AIR:0)
Block(-2,23,4,AIR:0)
Block(-2,23,5,SPRUCE_FENCE:0)
Block(-2,24,-2,SPRUCE_FENCE:0)
Block(-2,24,-1,AIR:0)
Block(-2,24,0,AIR:0)
Block(-2,24,1,AIR:0)
Block(-2,24,2,AIR:0)
Block(-2,24,3,AIR:0)
Block(-2,24,4,AIR:0)
Block(-2,24,5,SPRUCE_FENCE:0)
Block(-2,25,-2,SPRUCE_FENCE:0)
Block(-2,25,-1,AIR:0)
Block(-2,25,0,AIR:0)
Block(-2,25,1,AIR:0)
Block(-2,25,2,AIR:0)
Block(-2,25,3,AIR:0)
Block(-2,25,4,AIR:0)
Block(-2,25,5,SPRUCE_FENCE:0)
Block(-2,26,-2,SPRUCE_FENCE:0)
Block(-2,26,-1,AIR:0)
Block(-2,26,0,AIR:0)
Block(-2,26,1,AIR:0)
Block(-2,26,2,AIR:0)
Block(-2,26,3,AIR:0)
Block(-2,26,4,AIR:0)
Block(-2,26,5,SPRUCE_FENCE:0)
Block(-2,27,-2,SPRUCE_FENCE:0)
Block(-2,27,-1,AIR:0)
Block(-2,27,0,AIR:0)
Block(-2,27,1,AIR:0)
Block(-2,27,2,AIR:0)
Block(-2,27,3,AIR:0)
Block(-2,27,4,AIR:0)
Block(-2,27,5,SPRUCE_FENCE:0)
Block(-2,28,-2,SPRUCE_FENCE:0)
Block(-2,28,-1,AIR:0)
Block(-2,28,0,AIR:0)
Block(-2,28,1,AIR:0)
Block(-2,28,2,AIR:0)
Block(-2,28,3,AIR:0)
Block(-2,28,4,AIR:0)
Block(-2,28,5,SPRUCE_FENCE:0)
Block(-2,29,-2,SPRUCE_FENCE:0)
Block(-2,29,-1,AIR:0)
Block(-2,29,0,AIR:0)
Block(-2,29,1,AIR:0)
Block(-2,29,2,AIR:0)
Block(-2,29,3,AIR:0)
Block(-2,29,4,AIR:0)
Block(-2,29,5,SPRUCE_FENCE:0)
Block(-2,30,-2,SPRUCE_FENCE:0)
Block(-2,30,-1,AIR:0)
Block(-2,30,0,AIR:0)
Block(-2,30,1,AIR:0)
Block(-2,30,2,AIR:0)
Block(-2,30,3,AIR:0)
Block(-2,30,4,AIR:0)
Block(-2,30,5,SPRUCE_FENCE:0)
Block(-2,31,-2,SPRUCE_FENCE:0)
Block(-2,31,-1,AIR:0)
Block(-2,31,0,AIR:0)
Block(-2,31,1,AIR:0)
Block(-2,31,2,AIR:0)
Block(-2,31,3,AIR:0)
Block(-2,31,4,AIR:0)
Block(-2,31,5,SPRUCE_FENCE:0)
Block(-2,32,-2,SPRUCE_FENCE:0)
Block(-2,32,-1,AIR:0)
Block(-2,32,0,AIR:0)
Block(-2,32,1,AIR:0)
Block(-2,32,2,AIR:0)
Block(-2,32,3,AIR:0)
Block(-2,32,4,AIR:0)
Block(-2,32,5,SPRUCE_FENCE:0)
Block(-2,33,-2,SPRUCE_FENCE:0)
Block(-2,33,-1,AIR:0)
Block(-2,33,0,AIR:0)
Block(-2,33,1,AIR:0)
Block(-2,33,2,AIR:0)
Block(-2,33,3,AIR:0)
Block(-2,33,4,AIR:0)
Block(-2,33,5,SPRUCE_FENCE:0)
Block(-2,34,-2,SPRUCE_FENCE:0)
Block(-2,34,-1,AIR:0)
Block(-2,34,0,AIR:0)
Block(-2,34,1,AIR:0)
Block(-2,34,2,AIR:0)
Block(-2,34,3,AIR:0)
Block(-2,34,4,AIR:0)
Block(-2,34,5,SPRUCE_FENCE:0)
Block(-2,35,-2,SPRUCE_FENCE:0)
Block(-2,35,-1,AIR:0)
Block(-2,35,0,AIR:0)
Block(-2,35,1,AIR:0)
Block(-2,35,2,AIR:0)
Block(-2,35,3,AIR:0)
Block(-2,35,4,AIR:0)
Block(-2,35,5,SPRUCE_FENCE:0)
Block(-2,36,-2,SPRUCE_FENCE:0)
Block(-2,36,-1,AIR:0)
Block(-2,36,0,AIR:0)
Block(-2,36,1,AIR:0)
Block(-2,36,2,AIR:0)
Block(-2,36,3,AIR:0)
Block(-2,36,4,AIR:0)
Block(-2,36,5,SPRUCE_FENCE:0)
Block(-1,0,-2,WOOD:1)
Block(-1,0,-1,COBBLESTONE_STAIRS:3)
Block(-1,0,0,AIR:0)
Block(-1,0,1,AIR:0)
Block(-1,0,2,AIR:0)
Block(-1,0,3,AIR:0)
Block(-1,0,4,COBBLESTONE_STAIRS:2)
Block(-1,0,5,WOOD:1)
Block(-1,1,-2,WOOD:1)
Block(-1,1,-1,COBBLESTONE_STAIRS:7)
Block(-1,1,0,AIR:0)
Block(-1,1,1,AIR:0)
Block(-1,1,2,AIR:0)
Block(-1,1,3,AIR:0)
Block(-1,1,4,COBBLESTONE_STAIRS:6)
Block(-1,1,5,WOOD:1)
Block(-1,2,-2,WOOD:1)
Block(-1,2,-1,COBBLESTONE_STAIRS:3)
Block(-1,2,0,AIR:0)
Block(-1,2,1,AIR:0)
Block(-1,2,2,AIR:0)
Block(-1,2,3,AIR:0)
Block(-1,2,4,COBBLESTONE_STAIRS:2)
Block(-1,2,5,WOOD:1)
Block(-1,3,-2,WOOD:1)
Block(-1,3,-1,COBBLESTONE_STAIRS:7)
Block(-1,3,0,AIR:0)
Block(-1,3,1,AIR:0)
Block(-1,3,2,AIR:0)
Block(-1,3,3,AIR:0)
Block(-1,3,4,COBBLESTONE_STAIRS:6)
Block(-1,3,5,WOOD:1)
Block(-1,4,-2,WOOD:1)
Block(-1,4,-1,COBBLESTONE_STAIRS:3)
Block(-1,4,0,AIR:0)
Block(-1,4,1,AIR:0)
Block(-1,4,2,AIR:0)
Block(-1,4,3,AIR:0)
Block(-1,4,4,COBBLESTONE_STAIRS:2)
Block(-1,4,5,WOOD:1)
Block(-1,5,-2,WOOD:1)
Block(-1,5,-1,COBBLESTONE_STAIRS:7)
Block(-1,5,0,AIR:0)
Block(-1,5,1,AIR:0)
Block(-1,5,2,AIR:0)
Block(-1,5,3,AIR:0)
Block(-1,5,4,COBBLESTONE_STAIRS:6)
Block(-1,5,5,WOOD:1)
Block(-1,6,-2,WOOD:1)
Block(-1,6,-1,COBBLESTONE_STAIRS:3)
Block(-1,6,0,AIR:0)
Block(-1,6,1,AIR:0)
Block(-1,6,2,AIR:0)
Block(-1,6,3,AIR:0)
Block(-1,6,4,COBBLESTONE_STAIRS:2)
Block(-1,6,5,WOOD:1)
Block(-1,7,-2,WOOD:1)
Block(-1,7,-1,COBBLESTONE_STAIRS:7)
Block(-1,7,0,AIR:0)
Block(-1,7,1,AIR:0)
Block(-1,7,2,AIR:0)
Block(-1,7,3,AIR:0)
Block(-1,7,4,COBBLESTONE_STAIRS:6)
Block(-1,7,5,WOOD:1)
Block(-1,8,-2,WOOD:1)
Block(-1,8,-1,COBBLESTONE_STAIRS:3)
Block(-1,8,0,AIR:0)
Block(-1,8,1,AIR:0)
Block(-1,8,2,AIR:0)
Block(-1,8,3,AIR:0)
Block(-1,8,4,COBBLESTONE_STAIRS:2)
Block(-1,8,5,WOOD:1)
Block(-1,9,-2,WOOD:1)
Block(-1,9,-1,COBBLESTONE_STAIRS:7)
Block(-1,9,0,AIR:0)
Block(-1,9,1,AIR:0)
Block(-1,9,2,AIR:0)
Block(-1,9,3,AIR:0)
Block(-1,9,4,COBBLESTONE_STAIRS:6)
Block(-1,9,5,WOOD:1)
Block(-1,10,-2,WOOD:1)
Block(-1,10,-1,COBBLESTONE_STAIRS:3)
Block(-1,10,0,AIR:0)
Block(-1,10,1,AIR:0)
Block(-1,10,2,AIR:0)
Block(-1,10,3,AIR:0)
Block(-1,10,4,COBBLESTONE_STAIRS:2)
Block(-1,10,5,WOOD:1)
Block(-1,11,-2,WOOD:1)
Block(-1,11,-1,COBBLESTONE_STAIRS:7)
Block(-1,11,0,AIR:0)
Block(-1,11,1,AIR:0)
Block(-1,11,2,AIR:0)
Block(-1,11,3,AIR:0)
Block(-1,11,4,COBBLESTONE_STAIRS:6)
Block(-1,11,5,WOOD:1)
Block(-1,12,-2,WOOD:1)
Block(-1,12,-1,COBBLESTONE_STAIRS:3)
Block(-1,12,0,AIR:0)
Block(-1,12,1,AIR:0)
Block(-1,12,2,AIR:0)
Block(-1,12,3,AIR:0)
Block(-1,12,4,COBBLESTONE_STAIRS:2)
Block(-1,12,5,WOOD:1)
Block(-1,13,-2,WOOD:1)
Block(-1,13,-1,COBBLESTONE_STAIRS:7)
Block(-1,13,0,AIR:0)
Block(-1,13,1,AIR:0)
Block(-1,13,2,AIR:0)
Block(-1,13,3,AIR:0)
Block(-1,13,4,COBBLESTONE_STAIRS:6)
Block(-1,13,5,WOOD:1)
Block(-1,14,-2,WOOD:1)
Block(-1,14,-1,COBBLESTONE_STAIRS:3)
Block(-1,14,0,AIR:0)
Block(-1,14,1,AIR:0)
Block(-1,14,2,AIR:0)
Block(-1,14,3,AIR:0)
Block(-1,14,4,COBBLESTONE_STAIRS:2)
Block(-1,14,5,WOOD:1)
Block(-1,15,-2,WOOD:1)
Block(-1,15,-1,COBBLESTONE_STAIRS:7)
Block(-1,15,0,AIR:0)
Block(-1,15,1,AIR:0)
Block(-1,15,2,AIR:0)
Block(-1,15,3,AIR:0)
Block(-1,15,4,COBBLESTONE_STAIRS:6)
Block(-1,15,5,WOOD:1)
Block(-1,16,-2,WOOD:1)
Block(-1,16,-1,COBBLESTONE_STAIRS:3)
Block(-1,16,0,AIR:0)
Block(-1,16,1,AIR:0)
Block(-1,16,2,AIR:0)
Block(-1,16,3,AIR:0)
Block(-1,16,4,COBBLESTONE_STAIRS:2)
Block(-1,16,5,WOOD:1)
Block(-1,17,-2,WOOD:1)
Block(-1,17,-1,COBBLESTONE_STAIRS:7)
Block(-1,17,0,AIR:0)
Block(-1,17,1,AIR:0)
Block(-1,17,2,AIR:0)
Block(-1,17,3,AIR:0)
Block(-1,17,4,COBBLESTONE_STAIRS:6)
Block(-1,17,5,WOOD:1)
Block(-1,18,-2,WOOD:1)
Block(-1,18,-1,COBBLESTONE_STAIRS:3)
Block(-1,18,0,AIR:0)
Block(-1,18,1,AIR:0)
Block(-1,18,2,AIR:0)
Block(-1,18,3,AIR:0)
Block(-1,18,4,COBBLESTONE_STAIRS:2)
Block(-1,18,5,WOOD:1)
Block(-1,19,-2,WOOD:1)
Block(-1,19,-1,COBBLESTONE_STAIRS:7)
Block(-1,19,0,AIR:0)
Block(-1,19,1,AIR:0)
Block(-1,19,2,AIR:0)
Block(-1,19,3,AIR:0)
Block(-1,19,4,COBBLESTONE_STAIRS:6)
Block(-1,19,5,WOOD:1)
Block(-1,20,-2,WOOD:1)
Block(-1,20,-1,COBBLESTONE_STAIRS:3)
Block(-1,20,0,AIR:0)
Block(-1,20,1,AIR:0)
Block(-1,20,2,AIR:0)
Block(-1,20,3,AIR:0)
Block(-1,20,4,COBBLESTONE_STAIRS:2)
Block(-1,20,5,WOOD:1)
Block(-1,21,-2,WOOD:1)
Block(-1,21,-1,COBBLESTONE_STAIRS:7)
Block(-1,21,0,AIR:0)
Block(-1,21,1,AIR:0)
Block(-1,21,2,AIR:0)
Block(-1,21,3,AIR:0)
Block(-1,21,4,COBBLESTONE_STAIRS:6)
Block(-1,21,5,WOOD:1)
Block(-1,22,-2,WOOD:1)
Block(-1,22,-1,COBBLESTONE_STAIRS:3)
Block(-1,22,0,AIR:0)
Block(-1,22,1,AIR:0)
Block(-1,22,2,AIR:0)
Block(-1,22,3,AIR:0)
Block(-1,22,4,COBBLESTONE_STAIRS:2)
Block(-1,22,5,WOOD:1)
Block(-1,23,-2,WOOD:1)
Block(-1,23,-1,COBBLESTONE_STAIRS:7)
Block(-1,23,0,AIR:0)
Block(-1,23,1,AIR:0)
Block(-1,23,2,AIR:0)
Block(-1,23,3,AIR:0)
Block(-1,23,4,COBBLESTONE_STAIRS:6)
Block(-1,23,5,WOOD:1)
Block(-1,24,-2,WOOD:1)
Block(-1,24,-1,COBBLESTONE_STAIRS:3)
Block(-1,24,0,AIR:0)
Block(-1,24,1,AIR:0)
Block(-1,24,2,AIR:0)
Block(-1,24,3,AIR:0)
Block(-1,24,4,COBBLESTONE_STAIRS:2)
Block(-1,24,5,WOOD:1)
Block(-1,25,-2,WOOD:1)
Block(-1,25,-1,COBBLESTONE_STAIRS:7)
Block(-1,25,0,AIR:0)
Block(-1,25,1,AIR:0)
Block(-1,25,2,AIR:0)
Block(-1,25,3,AIR:0)
Block(-1,25,4,COBBLESTONE_STAIRS:6)
Block(-1,25,5,WOOD:1)
Block(-1,26,-2,WOOD:1)
Block(-1,26,-1,COBBLESTONE_STAIRS:3)
Block(-1,26,0,AIR:0)
Block(-1,26,1,AIR:0)
Block(-1,26,2,AIR:0)
Block(-1,26,3,AIR:0)
Block(-1,26,4,COBBLESTONE_STAIRS:2)
Block(-1,26,5,WOOD:1)
Block(-1,27,-2,WOOD:1)
Block(-1,27,-1,COBBLESTONE_STAIRS:7)
Block(-1,27,0,AIR:0)
Block(-1,27,1,AIR:0)
Block(-1,27,2,AIR:0)
Block(-1,27,3,AIR:0)
Block(-1,27,4,COBBLESTONE_STAIRS:6)
Block(-1,27,5,WOOD:1)
Block(-1,28,-2,WOOD:1)
Block(-1,28,-1,COBBLESTONE_STAIRS:3)
Block(-1,28,0,AIR:0)
Block(-1,28,1,AIR:0)
Block(-1,28,2,AIR:0)
Block(-1,28,3,AIR:0)
Block(-1,28,4,COBBLESTONE_STAIRS:2)
Block(-1,28,5,WOOD:1)
Block(-1,29,-2,WOOD:1)
Block(-1,29,-1,COBBLESTONE_STAIRS:7)
Block(-1,29,0,AIR:0)
Block(-1,29,1,AIR:0)
Block(-1,29,2,AIR:0)
Block(-1,29,3,AIR:0)
Block(-1,29,4,COBBLESTONE_STAIRS:6)
Block(-1,29,5,WOOD:1)
Block(-1,30,-2,WOOD:1)
Block(-1,30,-1,COBBLESTONE_STAIRS:3)
Block(-1,30,0,AIR:0)
Block(-1,30,1,AIR:0)
Block(-1,30,2,AIR:0)
Block(-1,30,3,AIR:0)
Block(-1,30,4,COBBLESTONE_STAIRS:2)
Block(-1,30,5,WOOD:1)
Block(-1,31,-2,WOOD:1)
Block(-1,31,-1,COBBLESTONE_STAIRS:7)
Block(-1,31,0,AIR:0)
Block(-1,31,1,AIR:0)
Block(-1,31,2,AIR:0)
Block(-1,31,3,AIR:0)
Block(-1,31,4,COBBLESTONE_STAIRS:6)
Block(-1,31,5,WOOD:1)
Block(-1,32,-2,WOOD:1)
Block(-1,32,-1,COBBLESTONE_STAIRS:3)
Block(-1,32,0,AIR:0)
Block(-1,32,1,AIR:0)
Block(-1,32,2,AIR:0)
Block(-1,32,3,AIR:0)
Block(-1,32,4,COBBLESTONE_STAIRS:2)
Block(-1,32,5,WOOD:1)
Block(-1,33,-2,WOOD:1)
Block(-1,33,-1,COBBLESTONE_STAIRS:7)
Block(-1,33,0,AIR:0)
Block(-1,33,1,AIR:0)
Block(-1,33,2,AIR:0)
Block(-1,33,3,AIR:0)
Block(-1,33,4,COBBLESTONE_STAIRS:6)
Block(-1,33,5,WOOD:1)
Block(-1,34,-2,WOOD:1)
Block(-1,34,-1,COBBLESTONE_STAIRS:3)
Block(-1,34,0,AIR:0)
Block(-1,34,1,AIR:0)
Block(-1,34,2,AIR:0)
Block(-1,34,3,AIR:0)
Block(-1,34,4,COBBLESTONE_STAIRS:2)
Block(-1,34,5,WOOD:1)
Block(-1,35,-2,WOOD:1)
Block(-1,35,-1,COBBLESTONE_STAIRS:7)
Block(-1,35,0,AIR:0)
Block(-1,35,1,AIR:0)
Block(-1,35,2,AIR:0)
Block(-1,35,3,AIR:0)
Block(-1,35,4,COBBLESTONE_STAIRS:6)
Block(-1,35,5,WOOD:1)
Block(-1,36,-2,WOOD:1)
Block(-1,36,-1,COBBLESTONE_STAIRS:3)
Block(-1,36,0,AIR:0)
Block(-1,36,1,AIR:0)
Block(-1,36,2,AIR:0)
Block(-1,36,3,AIR:0)
Block(-1,36,4,COBBLESTONE_STAIRS:2)
Block(-1,36,5,WOOD:1)
Block(0,0,-2,SPRUCE_FENCE:0)
Block(0,0,-1,AIR:0)
Block(0,0,0,AIR:0)
Block(0,0,1,AIR:0)
Block(0,0,2,AIR:0)
Block(0,0,3,AIR:0)
Block(0,0,4,AIR:0)
Block(0,0,5,SPRUCE_FENCE:0)
Block(0,1,-2,SPRUCE_FENCE:0)
Block(0,1,-1,AIR:0)
Block(0,1,0,AIR:0)
Block(0,1,1,AIR:0)
Block(0,1,2,AIR:0)
Block(0,1,3,AIR:0)
Block(0,1,4,AIR:0)
Block(0,1,5,SPRUCE_FENCE:0)
Block(0,2,-2,SPRUCE_FENCE:0)
Block(0,2,-1,AIR:0)
Block(0,2,0,AIR:0)
Block(0,2,1,AIR:0)
Block(0,2,2,AIR:0)
Block(0,2,3,AIR:0)
Block(0,2,4,AIR:0)
Block(0,2,5,SPRUCE_FENCE:0)
Block(0,3,-2,SPRUCE_FENCE:0)
Block(0,3,-1,AIR:0)
Block(0,3,0,AIR:0)
Block(0,3,1,AIR:0)
Block(0,3,2,AIR:0)
Block(0,3,3,AIR:0)
Block(0,3,4,AIR:0)
Block(0,3,5,SPRUCE_FENCE:0)
Block(0,4,-2,SPRUCE_FENCE:0)
Block(0,4,-1,AIR:0)
Block(0,4,0,AIR:0)
Block(0,4,1,AIR:0)
Block(0,4,2,AIR:0)
Block(0,4,3,AIR:0)
Block(0,4,4,AIR:0)
Block(0,4,5,SPRUCE_FENCE:0)
Block(0,5,-2,SPRUCE_FENCE:0)
Block(0,5,-1,AIR:0)
Block(0,5,0,AIR:0)
Block(0,5,1,AIR:0)
Block(0,5,2,AIR:0)
Block(0,5,3,AIR:0)
Block(0,5,4,AIR:0)
Block(0,5,5,SPRUCE_FENCE:0)
Block(0,6,-2,SPRUCE_FENCE:0)
Block(0,6,-1,AIR:0)
Block(0,6,0,AIR:0)
Block(0,6,1,AIR:0)
Block(0,6,2,AIR:0)
Block(0,6,3,AIR:0)
Block(0,6,4,AIR:0)
Block(0,6,5,SPRUCE_FENCE:0)
Block(0,7,-2,SPRUCE_FENCE:0)
Block(0,7,-1,AIR:0)
Block(0,7,0,AIR:0)
Block(0,7,1,AIR:0)
Block(0,7,2,AIR:0)
Block(0,7,3,AIR:0)
Block(0,7,4,AIR:0)
Block(0,7,5,SPRUCE_FENCE:0)
Block(0,8,-2,SPRUCE_FENCE:0)
Block(0,8,-1,AIR:0)
Block(0,8,0,AIR:0)
Block(0,8,1,AIR:0)
Block(0,8,2,AIR:0)
Block(0,8,3,AIR:0)
Block(0,8,4,AIR:0)
Block(0,8,5,SPRUCE_FENCE:0)
Block(0,9,-2,SPRUCE_FENCE:0)
Block(0,9,-1,AIR:0)
Block(0,9,0,AIR:0)
Block(0,9,1,AIR:0)
Block(0,9,2,AIR:0)
Block(0,9,3,AIR:0)
Block(0,9,4,AIR:0)
Block(0,9,5,SPRUCE_FENCE:0)
Block(0,10,-2,SPRUCE_FENCE:0)
Block(0,10,-1,AIR:0)
Block(0,10,0,AIR:0)
Block(0,10,1,AIR:0)
Block(0,10,2,AIR:0)
Block(0,10,3,AIR:0)
Block(0,10,4,AIR:0)
Block(0,10,5,SPRUCE_FENCE:0)
Block(0,11,-2,SPRUCE_FENCE:0)
Block(0,11,-1,AIR:0)
Block(0,11,0,AIR:0)
Block(0,11,1,AIR:0)
Block(0,11,2,AIR:0)
Block(0,11,3,AIR:0)
Block(0,11,4,AIR:0)
Block(0,11,5,SPRUCE_FENCE:0)
Block(0,12,-2,SPRUCE_FENCE:0)
Block(0,12,-1,AIR:0)
Block(0,12,0,AIR:0)
Block(0,12,1,AIR:0)
Block(0,12,2,AIR:0)
Block(0,12,3,AIR:0)
Block(0,12,4,AIR:0)
Block(0,12,5,SPRUCE_FENCE:0)
Block(0,13,-2,SPRUCE_FENCE:0)
Block(0,13,-1,AIR:0)
Block(0,13,0,AIR:0)
Block(0,13,1,AIR:0)
Block(0,13,2,AIR:0)
Block(0,13,3,AIR:0)
Block(0,13,4,AIR:0)
Block(0,13,5,SPRUCE_FENCE:0)
Block(0,14,-2,SPRUCE_FENCE:0)
Block(0,14,-1,AIR:0)
Block(0,14,0,AIR:0)
Block(0,14,1,AIR:0)
Block(0,14,2,AIR:0)
Block(0,14,3,AIR:0)
Block(0,14,4,AIR:0)
Block(0,14,5,SPRUCE_FENCE:0)
Block(0,15,-2,SPRUCE_FENCE:0)
Block(0,15,-1,AIR:0)
Block(0,15,0,AIR:0)
Block(0,15,1,AIR:0)
Block(0,15,2,AIR:0)
Block(0,15,3,AIR:0)
Block(0,15,4,AIR:0)
Block(0,15,5,SPRUCE_FENCE:0)
Block(0,16,-2,SPRUCE_FENCE:0)
Block(0,16,-1,AIR:0)
Block(0,16,0,AIR:0)
Block(0,16,1,AIR:0)
Block(0,16,2,AIR:0)
Block(0,16,3,AIR:0)
Block(0,16,4,AIR:0)
Block(0,16,5,SPRUCE_FENCE:0)
Block(0,17,-2,SPRUCE_FENCE:0)
Block(0,17,-1,AIR:0)
Block(0,17,0,AIR:0)
Block(0,17,1,AIR:0)
Block(0,17,2,AIR:0)
Block(0,17,3,AIR:0)
Block(0,17,4,AIR:0)
Block(0,17,5,SPRUCE_FENCE:0)
Block(0,18,-2,SPRUCE_FENCE:0)
Block(0,18,-1,AIR:0)
Block(0,18,0,AIR:0)
Block(0,18,1,AIR:0)
Block(0,18,2,AIR:0)
Block(0,18,3,AIR:0)
Block(0,18,4,AIR:0)
Block(0,18,5,SPRUCE_FENCE:0)
Block(0,19,-2,SPRUCE_FENCE:0)
Block(0,19,-1,AIR:0)
Block(0,19,0,AIR:0)
Block(0,19,1,AIR:0)
Block(0,19,2,AIR:0)
Block(0,19,3,AIR:0)
Block(0,19,4,AIR:0)
Block(0,19,5,SPRUCE_FENCE:0)
Block(0,20,-2,SPRUCE_FENCE:0)
Block(0,20,-1,AIR:0)
Block(0,20,0,AIR:0)
Block(0,20,1,AIR:0)
Block(0,20,2,AIR:0)
Block(0,20,3,AIR:0)
Block(0,20,4,AIR:0)
Block(0,20,5,SPRUCE_FENCE:0)
Block(0,21,-2,SPRUCE_FENCE:0)
Block(0,21,-1,AIR:0)
Block(0,21,0,AIR:0)
Block(0,21,1,AIR:0)
Block(0,21,2,AIR:0)
Block(0,21,3,AIR:0)
Block(0,21,4,AIR:0)
Block(0,21,5,SPRUCE_FENCE:0)
Block(0,22,-2,SPRUCE_FENCE:0)
Block(0,22,-1,AIR:0)
Block(0,22,0,AIR:0)
Block(0,22,1,AIR:0)
Block(0,22,2,AIR:0)
Block(0,22,3,AIR:0)
Block(0,22,4,AIR:0)
Block(0,22,5,SPRUCE_FENCE:0)
Block(0,23,-2,SPRUCE_FENCE:0)
Block(0,23,-1,AIR:0)
Block(0,23,0,AIR:0)
Block(0,23,1,AIR:0)
Block(0,23,2,AIR:0)
Block(0,23,3,AIR:0)
Block(0,23,4,AIR:0)
Block(0,23,5,SPRUCE_FENCE:0)
Block(0,24,-2,SPRUCE_FENCE:0)
Block(0,24,-1,AIR:0)
Block(0,24,0,AIR:0)
Block(0,24,1,AIR:0)
Block(0,24,2,AIR:0)
Block(0,24,3,AIR:0)
Block(0,24,4,AIR:0)
Block(0,24,5,SPRUCE_FENCE:0)
Block(0,25,-2,SPRUCE_FENCE:0)
Block(0,25,-1,AIR:0)
Block(0,25,0,AIR:0)
Block(0,25,1,AIR:0)
Block(0,25,2,AIR:0)
Block(0,25,3,AIR:0)
Block(0,25,4,AIR:0)
Block(0,25,5,SPRUCE_FENCE:0)
Block(0,26,-2,SPRUCE_FENCE:0)
Block(0,26,-1,AIR:0)
Block(0,26,0,AIR:0)
Block(0,26,1,AIR:0)
Block(0,26,2,AIR:0)
Block(0,26,3,AIR:0)
Block(0,26,4,AIR:0)
Block(0,26,5,SPRUCE_FENCE:0)
Block(0,27,-2,SPRUCE_FENCE:0)
Block(0,27,-1,AIR:0)
Block(0,27,0,AIR:0)
Block(0,27,1,AIR:0)
Block(0,27,2,AIR:0)
Block(0,27,3,AIR:0)
Block(0,27,4,AIR:0)
Block(0,27,5,SPRUCE_FENCE:0)
Block(0,28,-2,SPRUCE_FENCE:0)
Block(0,28,-1,AIR:0)
Block(0,28,0,AIR:0)
Block(0,28,1,AIR:0)
Block(0,28,2,AIR:0)
Block(0,28,3,AIR:0)
Block(0,28,4,AIR:0)
Block(0,28,5,SPRUCE_FENCE:0)
Block(0,29,-2,SPRUCE_FENCE:0)
Block(0,29,-1,AIR:0)
Block(0,29,0,AIR:0)
Block(0,29,1,AIR:0)
Block(0,29,2,AIR:0)
Block(0,29,3,AIR:0)
Block(0,29,4,AIR:0)
Block(0,29,5,SPRUCE_FENCE:0)
Block(0,30,-2,SPRUCE_FENCE:0)
Block(0,30,-1,AIR:0)
Block(0,30,0,AIR:0)
Block(0,30,1,AIR:0)
Block(0,30,2,AIR:0)
Block(0,30,3,AIR:0)
Block(0,30,4,AIR:0)
Block(0,30,5,SPRUCE_FENCE:0)
Block(0,31,-2,SPRUCE_FENCE:0)
Block(0,31,-1,AIR:0)
Block(0,31,0,AIR:0)
Block(0,31,1,AIR:0)
Block(0,31,2,AIR:0)
Block(0,31,3,AIR:0)
Block(0,31,4,AIR:0)
Block(0,31,5,SPRUCE_FENCE:0)
Block(0,32,-2,SPRUCE_FENCE:0)
Block(0,32,-1,AIR:0)
Block(0,32,0,AIR:0)
Block(0,32,1,AIR:0)
Block(0,32,2,AIR:0)
Block(0,32,3,AIR:0)
Block(0,32,4,AIR:0)
Block(0,32,5,SPRUCE_FENCE:0)
Block(0,33,-2,SPRUCE_FENCE:0)
Block(0,33,-1,AIR:0)
Block(0,33,0,AIR:0)
Block(0,33,1,AIR:0)
Block(0,33,2,AIR:0)
Block(0,33,3,AIR:0)
Block(0,33,4,AIR:0)
Block(0,33,5,SPRUCE_FENCE:0)
Block(0,34,-2,SPRUCE_FENCE:0)
Block(0,34,-1,AIR:0)
Block(0,34,0,AIR:0)
Block(0,34,1,AIR:0)
Block(0,34,2,AIR:0)
Block(0,34,3,AIR:0)
Block(0,34,4,AIR:0)
Block(0,34,5,SPRUCE_FENCE:0)
Block(0,35,-2,SPRUCE_FENCE:0)
Block(0,35,-1,AIR:0)
Block(0,35,0,AIR:0)
Block(0,35,1,AIR:0)
Block(0,35,2,AIR:0)
Block(0,35,3,AIR:0)
Block(0,35,4,AIR:0)
Block(0,35,5,SPRUCE_FENCE:0)
Block(0,36,-2,SPRUCE_FENCE:0)
Block(0,36,-1,AIR:0)
Block(0,36,0,AIR:0)
Block(0,36,1,AIR:0)
Block(0,36,2,AIR:0)
Block(0,36,3,AIR:0)
Block(0,36,4,AIR:0)
Block(0,36,5,SPRUCE_FENCE:0)
Block(1,0,-2,SPRUCE_FENCE:0)
Block(1,0,-1,AIR:0)
Block(1,0,0,AIR:0)
Block(1,0,1,AIR:0)
Block(1,0,2,AIR:0)
Block(1,0,3,AIR:0)
Block(1,0,4,AIR:0)
Block(1,0,5,SPRUCE_FENCE:0)
Block(1,1,-2,SPRUCE_FENCE:0)
Block(1,1,-1,AIR:0)
Block(1,1,0,AIR:0)
Block(1,1,1,AIR:0)
Block(1,1,2,AIR:0)
Block(1,1,3,AIR:0)
Block(1,1,4,AIR:0)
Block(1,1,5,SPRUCE_FENCE:0)
Block(1,2,-2,SPRUCE_FENCE:0)
Block(1,2,-1,AIR:0)
Block(1,2,0,AIR:0)
Block(1,2,1,AIR:0)
Block(1,2,2,AIR:0)
Block(1,2,3,AIR:0)
Block(1,2,4,AIR:0)
Block(1,2,5,SPRUCE_FENCE:0)
Block(1,3,-2,SPRUCE_FENCE:0)
Block(1,3,-1,AIR:0)
Block(1,3,0,AIR:0)
Block(1,3,1,AIR:0)
Block(1,3,2,AIR:0)
Block(1,3,3,AIR:0)
Block(1,3,4,AIR:0)
Block(1,3,5,SPRUCE_FENCE:0)
Block(1,4,-2,SPRUCE_FENCE:0)
Block(1,4,-1,AIR:0)
Block(1,4,0,AIR:0)
Block(1,4,1,AIR:0)
Block(1,4,2,AIR:0)
Block(1,4,3,AIR:0)
Block(1,4,4,AIR:0)
Block(1,4,5,SPRUCE_FENCE:0)
Block(1,5,-2,SPRUCE_FENCE:0)
Block(1,5,-1,AIR:0)
Block(1,5,0,AIR:0)
Block(1,5,1,AIR:0)
Block(1,5,2,AIR:0)
Block(1,5,3,AIR:0)
Block(1,5,4,AIR:0)
Block(1,5,5,SPRUCE_FENCE:0)
Block(1,6,-2,SPRUCE_FENCE:0)
Block(1,6,-1,AIR:0)
Block(1,6,0,AIR:0)
Block(1,6,1,AIR:0)
Block(1,6,2,AIR:0)
Block(1,6,3,AIR:0)
Block(1,6,4,AIR:0)
Block(1,6,5,SPRUCE_FENCE:0)
Block(1,7,-2,SPRUCE_FENCE:0)
Block(1,7,-1,AIR:0)
Block(1,7,0,AIR:0)
Block(1,7,1,AIR:0)
Block(1,7,2,AIR:0)
Block(1,7,3,AIR:0)
Block(1,7,4,AIR:0)
Block(1,7,5,SPRUCE_FENCE:0)
Block(1,8,-2,SPRUCE_FENCE:0)
Block(1,8,-1,AIR:0)
Block(1,8,0,AIR:0)
Block(1,8,1,AIR:0)
Block(1,8,2,AIR:0)
Block(1,8,3,AIR:0)
Block(1,8,4,AIR:0)
Block(1,8,5,SPRUCE_FENCE:0)
Block(1,9,-2,SPRUCE_FENCE:0)
Block(1,9,-1,AIR:0)
Block(1,9,0,AIR:0)
Block(1,9,1,AIR:0)
Block(1,9,2,AIR:0)
Block(1,9,3,AIR:0)
Block(1,9,4,AIR:0)
Block(1,9,5,SPRUCE_FENCE:0)
Block(1,10,-2,SPRUCE_FENCE:0)
Block(1,10,-1,AIR:0)
Block(1,10,0,AIR:0)
Block(1,10,1,AIR:0)
Block(1,10,2,AIR:0)
Block(1,10,3,AIR:0)
Block(1,10,4,AIR:0)
Block(1,10,5,SPRUCE_FENCE:0)
Block(1,11,-2,SPRUCE_FENCE:0)
Block(1,11,-1,AIR:0)
Block(1,11,0,AIR:0)
Block(1,11,1,AIR:0)
Block(1,11,2,AIR:0)
Block(1,11,3,AIR:0)
Block(1,11,4,AIR:0)
Block(1,11,5,SPRUCE_FENCE:0)
Block(1,12,-2,SPRUCE_FENCE:0)
Block(1,12,-1,AIR:0)
Block(1,12,0,AIR:0)
Block(1,12,1,AIR:0)
Block(1,12,2,AIR:0)
Block(1,12,3,AIR:0)
Block(1,12,4,AIR:0)
Block(1,12,5,SPRUCE_FENCE:0)
Block(1,13,-2,SPRUCE_FENCE:0)
Block(1,13,-1,AIR:0)
Block(1,13,0,AIR:0)
Block(1,13,1,AIR:0)
Block(1,13,2,AIR:0)
Block(1,13,3,AIR:0)
Block(1,13,4,AIR:0)
Block(1,13,5,SPRUCE_FENCE:0)
Block(1,14,-2,SPRUCE_FENCE:0)
Block(1,14,-1,AIR:0)
Block(1,14,0,AIR:0)
Block(1,14,1,AIR:0)
Block(1,14,2,AIR:0)
Block(1,14,3,AIR:0)
Block(1,14,4,AIR:0)
Block(1,14,5,SPRUCE_FENCE:0)
Block(1,15,-2,SPRUCE_FENCE:0)
Block(1,15,-1,AIR:0)
Block(1,15,0,AIR:0)
Block(1,15,1,AIR:0)
Block(1,15,2,AIR:0)
Block(1,15,3,AIR:0)
Block(1,15,4,AIR:0)
Block(1,15,5,SPRUCE_FENCE:0)
Block(1,16,-2,SPRUCE_FENCE:0)
Block(1,16,-1,AIR:0)
Block(1,16,0,AIR:0)
Block(1,16,1,AIR:0)
Block(1,16,2,AIR:0)
Block(1,16,3,AIR:0)
Block(1,16,4,AIR:0)
Block(1,16,5,SPRUCE_FENCE:0)
Block(1,17,-2,SPRUCE_FENCE:0)
Block(1,17,-1,AIR:0)
Block(1,17,0,AIR:0)
Block(1,17,1,AIR:0)
Block(1,17,2,AIR:0)
Block(1,17,3,AIR:0)
Block(1,17,4,AIR:0)
Block(1,17,5,SPRUCE_FENCE:0)
Block(1,18,-2,SPRUCE_FENCE:0)
Block(1,18,-1,AIR:0)
Block(1,18,0,AIR:0)
Block(1,18,1,AIR:0)
Block(1,18,2,AIR:0)
Block(1,18,3,AIR:0)
Block(1,18,4,AIR:0)
Block(1,18,5,SPRUCE_FENCE:0)
Block(1,19,-2,SPRUCE_FENCE:0)
Block(1,19,-1,AIR:0)
Block(1,19,0,AIR:0)
Block(1,19,1,AIR:0)
Block(1,19,2,AIR:0)
Block(1,19,3,AIR:0)
Block(1,19,4,AIR:0)
Block(1,19,5,SPRUCE_FENCE:0)
Block(1,20,-2,SPRUCE_FENCE:0)
Block(1,20,-1,AIR:0)
Block(1,20,0,AIR:0)
Block(1,20,1,AIR:0)
Block(1,20,2,AIR:0)
Block(1,20,3,AIR:0)
Block(1,20,4,AIR:0)
Block(1,20,5,SPRUCE_FENCE:0)
Block(1,21,-2,SPRUCE_FENCE:0)
Block(1,21,-1,AIR:0)
Block(1,21,0,AIR:0)
Block(1,21,1,AIR:0)
Block(1,21,2,AIR:0)
Block(1,21,3,AIR:0)
Block(1,21,4,AIR:0)
Block(1,21,5,SPRUCE_FENCE:0)
Block(1,22,-2,SPRUCE_FENCE:0)
Block(1,22,-1,AIR:0)
Block(1,22,0,AIR:0)
Block(1,22,1,AIR:0)
Block(1,22,2,AIR:0)
Block(1,22,3,AIR:0)
Block(1,22,4,AIR:0)
Block(1,22,5,SPRUCE_FENCE:0)
Block(1,23,-2,SPRUCE_FENCE:0)
Block(1,23,-1,AIR:0)
Block(1,23,0,AIR:0)
Block(1,23,1,AIR:0)
Block(1,23,2,AIR:0)
Block(1,23,3,AIR:0)
Block(1,23,4,AIR:0)
Block(1,23,5,SPRUCE_FENCE:0)
Block(1,24,-2,SPRUCE_FENCE:0)
Block(1,24,-1,AIR:0)
Block(1,24,0,AIR:0)
Block(1,24,1,AIR:0)
Block(1,24,2,AIR:0)
Block(1,24,3,AIR:0)
Block(1,24,4,AIR:0)
Block(1,24,5,SPRUCE_FENCE:0)
Block(1,25,-2,SPRUCE_FENCE:0)
Block(1,25,-1,AIR:0)
Block(1,25,0,AIR:0)
Block(1,25,1,AIR:0)
Block(1,25,2,AIR:0)
Block(1,25,3,AIR:0)
Block(1,25,4,AIR:0)
Block(1,25,5,SPRUCE_FENCE:0)
Block(1,26,-2,SPRUCE_FENCE:0)
Block(1,26,-1,AIR:0)
Block(1,26,0,AIR:0)
Block(1,26,1,AIR:0)
Block(1,26,2,AIR:0)
Block(1,26,3,AIR:0)
Block(1,26,4,AIR:0)
Block(1,26,5,SPRUCE_FENCE:0)
Block(1,27,-2,SPRUCE_FENCE:0)
Block(1,27,-1,AIR:0)
Block(1,27,0,AIR:0)
Block(1,27,1,AIR:0)
Block(1,27,2,AIR:0)
Block(1,27,3,AIR:0)
Block(1,27,4,AIR:0)
Block(1,27,5,SPRUCE_FENCE:0)
Block(1,28,-2,SPRUCE_FENCE:0)
Block(1,28,-1,AIR:0)
Block(1,28,0,AIR:0)
Block(1,28,1,AIR:0)
Block(1,28,2,AIR:0)
Block(1,28,3,AIR:0)
Block(1,28,4,AIR:0)
Block(1,28,5,SPRUCE_FENCE:0)
Block(1,29,-2,SPRUCE_FENCE:0)
Block(1,29,-1,AIR:0)
Block(1,29,0,AIR:0)
Block(1,29,1,AIR:0)
Block(1,29,2,AIR:0)
Block(1,29,3,AIR:0)
Block(1,29,4,AIR:0)
Block(1,29,5,SPRUCE_FENCE:0)
Block(1,30,-2,SPRUCE_FENCE:0)
Block(1,30,-1,AIR:0)
Block(1,30,0,AIR:0)
Block(1,30,1,AIR:0)
Block(1,30,2,AIR:0)
Block(1,30,3,AIR:0)
Block(1,30,4,AIR:0)
Block(1,30,5,SPRUCE_FENCE:0)
Block(1,31,-2,SPRUCE_FENCE:0)
Block(1,31,-1,AIR:0)
Block(1,31,0,AIR:0)
Block(1,31,1,AIR:0)
Block(1,31,2,AIR:0)
Block(1,31,3,AIR:0)
Block(1,31,4,AIR:0)
Block(1,31,5,SPRUCE_FENCE:0)
Block(1,32,-2,SPRUCE_FENCE:0)
Block(1,32,-1,AIR:0)
Block(1,32,0,AIR:0)
Block(1,32,1,AIR:0)
Block(1,32,2,AIR:0)
Block(1,32,3,AIR:0)
Block(1,32,4,AIR:0)
Block(1,32,5,SPRUCE_FENCE:0)
Block(1,33,-2,SPRUCE_FENCE:0)
Block(1,33,-1,AIR:0)
Block(1,33,0,AIR:0)
Block(1,33,1,AIR:0)
Block(1,33,2,AIR:0)
Block(1,33,3,AIR:0)
Block(1,33,4,AIR:0)
Block(1,33,5,SPRUCE_FENCE:0)
Block(1,34,-2,SPRUCE_FENCE:0)
Block(1,34,-1,AIR:0)
Block(1,34,0,AIR:0)
Block(1,34,1,AIR:0)
Block(1,34,2,AIR:0)
Block(1,34,3,AIR:0)
Block(1,34,4,AIR:0)
Block(1,34,5,SPRUCE_FENCE:0)
Block(1,35,-2,SPRUCE_FENCE:0)
Block(1,35,-1,AIR:0)
Block(1,35,0,AIR:0)
Block(1,35,1,AIR:0)
Block(1,35,2,AIR:0)
Block(1,35,3,AIR:0)
Block(1,35,4,AIR:0)
Block(1,35,5,SPRUCE_FENCE:0)
Block(1,36,-2,SPRUCE_FENCE:0)
Block(1,36,-1,AIR:0)
Block(1,36,0,AIR:0)
Block(1,36,1,AIR:0)
Block(1,36,2,AIR:0)
Block(1,36,3,AIR:0)
Block(1,36,4,AIR:0)
Block(1,36,5,SPRUCE_FENCE:0)
Block(2,0,-2,WOOD:1)
Block(2,0,-1,COBBLESTONE_STAIRS:3)
Block(2,0,0,AIR:0)
Block(2,0,1,AIR:0)
Block(2,0,2,AIR:0)
Block(2,0,3,AIR:0)
Block(2,0,4,COBBLESTONE_STAIRS:2)
Block(2,0,5,WOOD:1)
Block(2,1,-2,WOOD:1)
Block(2,1,-1,COBBLESTONE_STAIRS:7)
Block(2,1,0,AIR:0)
Block(2,1,1,AIR:0)
Block(2,1,2,AIR:0)
Block(2,1,3,AIR:0)
Block(2,1,4,COBBLESTONE_STAIRS:6)
Block(2,1,5,WOOD:1)
Block(2,2,-2,WOOD:1)
Block(2,2,-1,COBBLESTONE_STAIRS:3)
Block(2,2,0,AIR:0)
Block(2,2,1,AIR:0)
Block(2,2,2,AIR:0)
Block(2,2,3,AIR:0)
Block(2,2,4,COBBLESTONE_STAIRS:2)
Block(2,2,5,WOOD:1)
Block(2,3,-2,WOOD:1)
Block(2,3,-1,COBBLESTONE_STAIRS:7)
Block(2,3,0,AIR:0)
Block(2,3,1,AIR:0)
Block(2,3,2,AIR:0)
Block(2,3,3,AIR:0)
Block(2,3,4,COBBLESTONE_STAIRS:6)
Block(2,3,5,WOOD:1)
Block(2,4,-2,WOOD:1)
Block(2,4,-1,COBBLESTONE_STAIRS:3)
Block(2,4,0,AIR:0)
Block(2,4,1,AIR:0)
Block(2,4,2,AIR:0)
Block(2,4,3,AIR:0)
Block(2,4,4,COBBLESTONE_STAIRS:2)
Block(2,4,5,WOOD:1)
Block(2,5,-2,WOOD:1)
Block(2,5,-1,COBBLESTONE_STAIRS:7)
Block(2,5,0,AIR:0)
Block(2,5,1,AIR:0)
Block(2,5,2,AIR:0)
Block(2,5,3,AIR:0)
Block(2,5,4,COBBLESTONE_STAIRS:6)
Block(2,5,5,WOOD:1)
Block(2,6,-2,WOOD:1)
Block(2,6,-1,COBBLESTONE_STAIRS:3)
Block(2,6,0,AIR:0)
Block(2,6,1,AIR:0)
Block(2,6,2,AIR:0)
Block(2,6,3,AIR:0)
Block(2,6,4,COBBLESTONE_STAIRS:2)
Block(2,6,5,WOOD:1)
Block(2,7,-2,WOOD:1)
Block(2,7,-1,COBBLESTONE_STAIRS:7)
Block(2,7,0,AIR:0)
Block(2,7,1,AIR:0)
Block(2,7,2,AIR:0)
Block(2,7,3,AIR:0)
Block(2,7,4,COBBLESTONE_STAIRS:6)
Block(2,7,5,WOOD:1)
Block(2,8,-2,WOOD:1)
Block(2,8,-1,COBBLESTONE_STAIRS:3)
Block(2,8,0,AIR:0)
Block(2,8,1,AIR:0)
Block(2,8,2,AIR:0)
Block(2,8,3,AIR:0)
Block(2,8,4,COBBLESTONE_STAIRS:2)
Block(2,8,5,WOOD:1)
Block(2,9,-2,WOOD:1)
Block(2,9,-1,COBBLESTONE_STAIRS:7)
Block(2,9,0,AIR:0)
Block(2,9,1,AIR:0)
Block(2,9,2,AIR:0)
Block(2,9,3,AIR:0)
Block(2,9,4,COBBLESTONE_STAIRS:6)
Block(2,9,5,WOOD:1)
Block(2,10,-2,WOOD:1)
Block(2,10,-1,COBBLESTONE_STAIRS:3)
Block(2,10,0,AIR:0)
Block(2,10,1,AIR:0)
Block(2,10,2,AIR:0)
Block(2,10,3,AIR:0)
Block(2,10,4,COBBLESTONE_STAIRS:2)
Block(2,10,5,WOOD:1)
Block(2,11,-2,WOOD:1)
Block(2,11,-1,COBBLESTONE_STAIRS:7)
Block(2,11,0,AIR:0)
Block(2,11,1,AIR:0)
Block(2,11,2,AIR:0)
Block(2,11,3,AIR:0)
Block(2,11,4,COBBLESTONE_STAIRS:6)
Block(2,11,5,WOOD:1)
Block(2,12,-2,WOOD:1)
Block(2,12,-1,COBBLESTONE_STAIRS:3)
Block(2,12,0,AIR:0)
Block(2,12,1,AIR:0)
Block(2,12,2,AIR:0)
Block(2,12,3,AIR:0)
Block(2,12,4,COBBLESTONE_STAIRS:2)
Block(2,12,5,WOOD:1)
Block(2,13,-2,WOOD:1)
Block(2,13,-1,COBBLESTONE_STAIRS:7)
Block(2,13,0,AIR:0)
Block(2,13,1,AIR:0)
Block(2,13,2,AIR:0)
Block(2,13,3,AIR:0)
Block(2,13,4,COBBLESTONE_STAIRS:6)
Block(2,13,5,WOOD:1)
Block(2,14,-2,WOOD:1)
Block(2,14,-1,COBBLESTONE_STAIRS:3)
Block(2,14,0,AIR:0)
Block(2,14,1,AIR:0)
Block(2,14,2,AIR:0)
Block(2,14,3,AIR:0)
Block(2,14,4,COBBLESTONE_STAIRS:2)
Block(2,14,5,WOOD:1)
Block(2,15,-2,WOOD:1)
Block(2,15,-1,COBBLESTONE_STAIRS:7)
Block(2,15,0,AIR:0)
Block(2,15,1,AIR:0)
Block(2,15,2,AIR:0)
Block(2,15,3,AIR:0)
Block(2,15,4,COBBLESTONE_STAIRS:6)
Block(2,15,5,WOOD:1)
Block(2,16,-2,WOOD:1)
Block(2,16,-1,COBBLESTONE_STAIRS:3)
Block(2,16,0,AIR:0)
Block(2,16,1,AIR:0)
Block(2,16,2,AIR:0)
Block(2,16,3,AIR:0)
Block(2,16,4,COBBLESTONE_STAIRS:2)
Block(2,16,5,WOOD:1)
Block(2,17,-2,WOOD:1)
Block(2,17,-1,COBBLESTONE_STAIRS:7)
Block(2,17,0,AIR:0)
Block(2,17,1,AIR:0)
Block(2,17,2,AIR:0)
Block(2,17,3,AIR:0)
Block(2,17,4,COBBLESTONE_STAIRS:6)
Block(2,17,5,WOOD:1)
Block(2,18,-2,WOOD:1)
Block(2,18,-1,COBBLESTONE_STAIRS:3)
Block(2,18,0,AIR:0)
Block(2,18,1,AIR:0)
Block(2,18,2,AIR:0)
Block(2,18,3,AIR:0)
Block(2,18,4,COBBLESTONE_STAIRS:2)
Block(2,18,5,WOOD:1)
Block(2,19,-2,WOOD:1)
Block(2,19,-1,COBBLESTONE_STAIRS:7)
Block(2,19,0,AIR:0)
Block(2,19,1,AIR:0)
Block(2,19,2,AIR:0)
Block(2,19,3,AIR:0)
Block(2,19,4,COBBLESTONE_STAIRS:6)
Block(2,19,5,WOOD:1)
Block(2,20,-2,WOOD:1)
Block(2,20,-1,COBBLESTONE_STAIRS:3)
Block(2,20,0,AIR:0)
Block(2,20,1,AIR:0)
Block(2,20,2,AIR:0)
Block(2,20,3,AIR:0)
Block(2,20,4,COBBLESTONE_STAIRS:2)
Block(2,20,5,WOOD:1)
Block(2,21,-2,WOOD:1)
Block(2,21,-1,COBBLESTONE_STAIRS:7)
Block(2,21,0,AIR:0)
Block(2,21,1,AIR:0)
Block(2,21,2,AIR:0)
Block(2,21,3,AIR:0)
Block(2,21,4,COBBLESTONE_STAIRS:6)
Block(2,21,5,WOOD:1)
Block(2,22,-2,WOOD:1)
Block(2,22,-1,COBBLESTONE_STAIRS:3)
Block(2,22,0,AIR:0)
Block(2,22,1,AIR:0)
Block(2,22,2,AIR:0)
Block(2,22,3,AIR:0)
Block(2,22,4,COBBLESTONE_STAIRS:2)
Block(2,22,5,WOOD:1)
Block(2,23,-2,WOOD:1)
Block(2,23,-1,COBBLESTONE_STAIRS:7)
Block(2,23,0,AIR:0)
Block(2,23,1,AIR:0)
Block(2,23,2,AIR:0)
Block(2,23,3,AIR:0)
Block(2,23,4,COBBLESTONE_STAIRS:6)
Block(2,23,5,WOOD:1)
Block(2,24,-2,WOOD:1)
Block(2,24,-1,COBBLESTONE_STAIRS:3)
Block(2,24,0,AIR:0)
Block(2,24,1,AIR:0)
Block(2,24,2,AIR:0)
Block(2,24,3,AIR:0)
Block(2,24,4,COBBLESTONE_STAIRS:2)
Block(2,24,5,WOOD:1)
Block(2,25,-2,WOOD:1)
Block(2,25,-1,COBBLESTONE_STAIRS:7)
Block(2,25,0,AIR:0)
Block(2,25,1,AIR:0)
Block(2,25,2,AIR:0)
Block(2,25,3,AIR:0)
Block(2,25,4,COBBLESTONE_STAIRS:6)
Block(2,25,5,WOOD:1)
Block(2,26,-2,WOOD:1)
Block(2,26,-1,COBBLESTONE_STAIRS:3)
Block(2,26,0,AIR:0)
Block(2,26,1,AIR:0)
Block(2,26,2,AIR:0)
Block(2,26,3,AIR:0)
Block(2,26,4,COBBLESTONE_STAIRS:2)
Block(2,26,5,WOOD:1)
Block(2,27,-2,WOOD:1)
Block(2,27,-1,COBBLESTONE_STAIRS:7)
Block(2,27,0,AIR:0)
Block(2,27,1,AIR:0)
Block(2,27,2,AIR:0)
Block(2,27,3,AIR:0)
Block(2,27,4,COBBLESTONE_STAIRS:6)
Block(2,27,5,WOOD:1)
Block(2,28,-2,WOOD:1)
Block(2,28,-1,COBBLESTONE_STAIRS:3)
Block(2,28,0,AIR:0)
Block(2,28,1,AIR:0)
Block(2,28,2,AIR:0)
Block(2,28,3,AIR:0)
Block(2,28,4,COBBLESTONE_STAIRS:2)
Block(2,28,5,WOOD:1)
Block(2,29,-2,WOOD:1)
Block(2,29,-1,COBBLESTONE_STAIRS:7)
Block(2,29,0,AIR:0)
Block(2,29,1,AIR:0)
Block(2,29,2,AIR:0)
Block(2,29,3,AIR:0)
Block(2,29,4,COBBLESTONE_STAIRS:6)
Block(2,29,5,WOOD:1)
Block(2,30,-2,WOOD:1)
Block(2,30,-1,COBBLESTONE_STAIRS:3)
Block(2,30,0,AIR:0)
Block(2,30,1,AIR:0)
Block(2,30,2,AIR:0)
Block(2,30,3,AIR:0)
Block(2,30,4,COBBLESTONE_STAIRS:2)
Block(2,30,5,WOOD:1)
Block(2,31,-2,WOOD:1)
Block(2,31,-1,COBBLESTONE_STAIRS:7)
Block(2,31,0,AIR:0)
Block(2,31,1,AIR:0)
Block(2,31,2,AIR:0)
Block(2,31,3,AIR:0)
Block(2,31,4,COBBLESTONE_STAIRS:6)
Block(2,31,5,WOOD:1)
Block(2,32,-2,WOOD:1)
Block(2,32,-1,COBBLESTONE_STAIRS:3)
Block(2,32,0,AIR:0)
Block(2,32,1,AIR:0)
Block(2,32,2,AIR:0)
Block(2,32,3,AIR:0)
Block(2,32,4,COBBLESTONE_STAIRS:2)
Block(2,32,5,WOOD:1)
Block(2,33,-2,WOOD:1)
Block(2,33,-1,COBBLESTONE_STAIRS:7)
Block(2,33,0,AIR:0)
Block(2,33,1,AIR:0)
Block(2,33,2,AIR:0)
Block(2,33,3,AIR:0)
Block(2,33,4,COBBLESTONE_STAIRS:6)
Block(2,33,5,WOOD:1)
Block(2,34,-2,WOOD:1)
Block(2,34,-1,COBBLESTONE_STAIRS:3)
Block(2,34,0,AIR:0)
Block(2,34,1,AIR:0)
Block(2,34,2,AIR:0)
Block(2,34,3,AIR:0)
Block(2,34,4,COBBLESTONE_STAIRS:2)
Block(2,34,5,WOOD:1)
Block(2,35,-2,WOOD:1)
Block(2,35,-1,COBBLESTONE_STAIRS:7)
Block(2,35,0,AIR:0)
Block(2,35,1,AIR:0)
Block(2,35,2,AIR:0)
Block(2,35,3,AIR:0)
Block(2,35,4,COBBLESTONE_STAIRS:6)
Block(2,35,5,WOOD:1)
Block(2,36,-2,WOOD:1)
Block(2,36,-1,COBBLESTONE_STAIRS:3)
Block(2,36,0,AIR:0)
Block(2,36,1,AIR:0)
Block(2,36,2,AIR:0)
Block(2,36,3,AIR:0)
Block(2,36,4,COBBLESTONE_STAIRS:2)
Block(2,36,5,WOOD:1)
Block(3,0,-2,SPRUCE_FENCE:0)
Block(3,0,-1,AIR:0)
Block(3,0,0,AIR:0)
Block(3,0,1,AIR:0)
Block(3,0,2,AIR:0)
Block(3,0,3,AIR:0)
Block(3,0,4,AIR:0)
Block(3,0,5,SPRUCE_FENCE:0)
Block(3,1,-2,SPRUCE_FENCE:0)
Block(3,1,-1,AIR:0)
Block(3,1,0,AIR:0)
Block(3,1,1,AIR:0)
Block(3,1,2,AIR:0)
Block(3,1,3,AIR:0)
Block(3,1,4,AIR:0)
Block(3,1,5,SPRUCE_FENCE:0)
Block(3,2,-2,SPRUCE_FENCE:0)
Block(3,2,-1,AIR:0)
Block(3,2,0,AIR:0)
Block(3,2,1,AIR:0)
Block(3,2,2,AIR:0)
Block(3,2,3,AIR:0)
Block(3,2,4,AIR:0)
Block(3,2,5,SPRUCE_FENCE:0)
Block(3,3,-2,SPRUCE_FENCE:0)
Block(3,3,-1,AIR:0)
Block(3,3,0,AIR:0)
Block(3,3,1,AIR:0)
Block(3,3,2,AIR:0)
Block(3,3,3,AIR:0)
Block(3,3,4,AIR:0)
Block(3,3,5,SPRUCE_FENCE:0)
Block(3,4,-2,SPRUCE_FENCE:0)
Block(3,4,-1,AIR:0)
Block(3,4,0,AIR:0)
Block(3,4,1,AIR:0)
Block(3,4,2,AIR:0)
Block(3,4,3,AIR:0)
Block(3,4,4,AIR:0)
Block(3,4,5,SPRUCE_FENCE:0)
Block(3,5,-2,SPRUCE_FENCE:0)
Block(3,5,-1,AIR:0)
Block(3,5,0,AIR:0)
Block(3,5,1,AIR:0)
Block(3,5,2,AIR:0)
Block(3,5,3,AIR:0)
Block(3,5,4,AIR:0)
Block(3,5,5,SPRUCE_FENCE:0)
Block(3,6,-2,SPRUCE_FENCE:0)
Block(3,6,-1,AIR:0)
Block(3,6,0,AIR:0)
Block(3,6,1,AIR:0)
Block(3,6,2,AIR:0)
Block(3,6,3,AIR:0)
Block(3,6,4,AIR:0)
Block(3,6,5,SPRUCE_FENCE:0)
Block(3,7,-2,SPRUCE_FENCE:0)
Block(3,7,-1,AIR:0)
Block(3,7,0,AIR:0)
Block(3,7,1,AIR:0)
Block(3,7,2,AIR:0)
Block(3,7,3,AIR:0)
Block(3,7,4,AIR:0)
Block(3,7,5,SPRUCE_FENCE:0)
Block(3,8,-2,SPRUCE_FENCE:0)
Block(3,8,-1,AIR:0)
Block(3,8,0,AIR:0)
Block(3,8,1,AIR:0)
Block(3,8,2,AIR:0)
Block(3,8,3,AIR:0)
Block(3,8,4,AIR:0)
Block(3,8,5,SPRUCE_FENCE:0)
Block(3,9,-2,SPRUCE_FENCE:0)
Block(3,9,-1,AIR:0)
Block(3,9,0,AIR:0)
Block(3,9,1,AIR:0)
Block(3,9,2,AIR:0)
Block(3,9,3,AIR:0)
Block(3,9,4,AIR:0)
Block(3,9,5,SPRUCE_FENCE:0)
Block(3,10,-2,SPRUCE_FENCE:0)
Block(3,10,-1,AIR:0)
Block(3,10,0,AIR:0)
Block(3,10,1,AIR:0)
Block(3,10,2,AIR:0)
Block(3,10,3,AIR:0)
Block(3,10,4,AIR:0)
Block(3,10,5,SPRUCE_FENCE:0)
Block(3,11,-2,SPRUCE_FENCE:0)
Block(3,11,-1,AIR:0)
Block(3,11,0,AIR:0)
Block(3,11,1,AIR:0)
Block(3,11,2,AIR:0)
Block(3,11,3,AIR:0)
Block(3,11,4,AIR:0)
Block(3,11,5,SPRUCE_FENCE:0)
Block(3,12,-2,SPRUCE_FENCE:0)
Block(3,12,-1,AIR:0)
Block(3,12,0,AIR:0)
Block(3,12,1,AIR:0)
Block(3,12,2,AIR:0)
Block(3,12,3,AIR:0)
Block(3,12,4,AIR:0)
Block(3,12,5,SPRUCE_FENCE:0)
Block(3,13,-2,SPRUCE_FENCE:0)
Block(3,13,-1,AIR:0)
Block(3,13,0,AIR:0)
Block(3,13,1,AIR:0)
Block(3,13,2,AIR:0)
Block(3,13,3,AIR:0)
Block(3,13,4,AIR:0)
Block(3,13,5,SPRUCE_FENCE:0)
Block(3,14,-2,SPRUCE_FENCE:0)
Block(3,14,-1,AIR:0)
Block(3,14,0,AIR:0)
Block(3,14,1,AIR:0)
Block(3,14,2,AIR:0)
Block(3,14,3,AIR:0)
Block(3,14,4,AIR:0)
Block(3,14,5,SPRUCE_FENCE:0)
Block(3,15,-2,SPRUCE_FENCE:0)
Block(3,15,-1,AIR:0)
Block(3,15,0,AIR:0)
Block(3,15,1,AIR:0)
Block(3,15,2,AIR:0)
Block(3,15,3,AIR:0)
Block(3,15,4,AIR:0)
Block(3,15,5,SPRUCE_FENCE:0)
Block(3,16,-2,SPRUCE_FENCE:0)
Block(3,16,-1,AIR:0)
Block(3,16,0,AIR:0)
Block(3,16,1,AIR:0)
Block(3,16,2,AIR:0)
Block(3,16,3,AIR:0)
Block(3,16,4,AIR:0)
Block(3,16,5,SPRUCE_FENCE:0)
Block(3,17,-2,SPRUCE_FENCE:0)
Block(3,17,-1,AIR:0)
Block(3,17,0,AIR:0)
Block(3,17,1,AIR:0)
Block(3,17,2,AIR:0)
Block(3,17,3,AIR:0)
Block(3,17,4,AIR:0)
Block(3,17,5,SPRUCE_FENCE:0)
Block(3,18,-2,SPRUCE_FENCE:0)
Block(3,18,-1,AIR:0)
Block(3,18,0,AIR:0)
Block(3,18,1,AIR:0)
Block(3,18,2,AIR:0)
Block(3,18,3,AIR:0)
Block(3,18,4,AIR:0)
Block(3,18,5,SPRUCE_FENCE:0)
Block(3,19,-2,SPRUCE_FENCE:0)
Block(3,19,-1,AIR:0)
Block(3,19,0,AIR:0)
Block(3,19,1,AIR:0)
Block(3,19,2,AIR:0)
Block(3,19,3,AIR:0)
Block(3,19,4,AIR:0)
Block(3,19,5,SPRUCE_FENCE:0)
Block(3,20,-2,SPRUCE_FENCE:0)
Block(3,20,-1,AIR:0)
Block(3,20,0,AIR:0)
Block(3,20,1,AIR:0)
Block(3,20,2,AIR:0)
Block(3,20,3,AIR:0)
Block(3,20,4,AIR:0)
Block(3,20,5,SPRUCE_FENCE:0)
Block(3,21,-2,SPRUCE_FENCE:0)
Block(3,21,-1,AIR:0)
Block(3,21,0,AIR:0)
Block(3,21,1,AIR:0)
Block(3,21,2,AIR:0)
Block(3,21,3,AIR:0)
Block(3,21,4,AIR:0)
Block(3,21,5,SPRUCE_FENCE:0)
Block(3,22,-2,SPRUCE_FENCE:0)
Block(3,22,-1,AIR:0)
Block(3,22,0,AIR:0)
Block(3,22,1,AIR:0)
Block(3,22,2,AIR:0)
Block(3,22,3,AIR:0)
Block(3,22,4,AIR:0)
Block(3,22,5,SPRUCE_FENCE:0)
Block(3,23,-2,SPRUCE_FENCE:0)
Block(3,23,-1,AIR:0)
Block(3,23,0,AIR:0)
Block(3,23,1,AIR:0)
Block(3,23,2,AIR:0)
Block(3,23,3,AIR:0)
Block(3,23,4,AIR:0)
Block(3,23,5,SPRUCE_FENCE:0)
Block(3,24,-2,SPRUCE_FENCE:0)
Block(3,24,-1,AIR:0)
Block(3,24,0,AIR:0)
Block(3,24,1,AIR:0)
Block(3,24,2,AIR:0)
Block(3,24,3,AIR:0)
Block(3,24,4,AIR:0)
Block(3,24,5,SPRUCE_FENCE:0)
Block(3,25,-2,SPRUCE_FENCE:0)
Block(3,25,-1,AIR:0)
Block(3,25,0,AIR:0)
Block(3,25,1,AIR:0)
Block(3,25,2,AIR:0)
Block(3,25,3,AIR:0)
Block(3,25,4,AIR:0)
Block(3,25,5,SPRUCE_FENCE:0)
Block(3,26,-2,SPRUCE_FENCE:0)
Block(3,26,-1,AIR:0)
Block(3,26,0,AIR:0)
Block(3,26,1,AIR:0)
Block(3,26,2,AIR:0)
Block(3,26,3,AIR:0)
Block(3,26,4,AIR:0)
Block(3,26,5,SPRUCE_FENCE:0)
Block(3,27,-2,SPRUCE_FENCE:0)
Block(3,27,-1,AIR:0)
Block(3,27,0,AIR:0)
Block(3,27,1,AIR:0)
Block(3,27,2,AIR:0)
Block(3,27,3,AIR:0)
Block(3,27,4,AIR:0)
Block(3,27,5,SPRUCE_FENCE:0)
Block(3,28,-2,SPRUCE_FENCE:0)
Block(3,28,-1,AIR:0)
Block(3,28,0,AIR:0)
Block(3,28,1,AIR:0)
Block(3,28,2,AIR:0)
Block(3,28,3,AIR:0)
Block(3,28,4,AIR:0)
Block(3,28,5,SPRUCE_FENCE:0)
Block(3,29,-2,SPRUCE_FENCE:0)
Block(3,29,-1,AIR:0)
Block(3,29,0,AIR:0)
Block(3,29,1,AIR:0)
Block(3,29,2,AIR:0)
Block(3,29,3,AIR:0)
Block(3,29,4,AIR:0)
Block(3,29,5,SPRUCE_FENCE:0)
Block(3,30,-2,SPRUCE_FENCE:0)
Block(3,30,-1,AIR:0)
Block(3,30,0,AIR:0)
Block(3,30,1,AIR:0)
Block(3,30,2,AIR:0)
Block(3,30,3,AIR:0)
Block(3,30,4,AIR:0)
Block(3,30,5,SPRUCE_FENCE:0)
Block(3,31,-2,SPRUCE_FENCE:0)
Block(3,31,-1,AIR:0)
Block(3,31,0,AIR:0)
Block(3,31,1,AIR:0)
Block(3,31,2,AIR:0)
Block(3,31,3,AIR:0)
Block(3,31,4,AIR:0)
Block(3,31,5,SPRUCE_FENCE:0)
Block(3,32,-2,SPRUCE_FENCE:0)
Block(3,32,-1,AIR:0)
Block(3,32,0,AIR:0)
Block(3,32,1,AIR:0)
Block(3,32,2,AIR:0)
Block(3,32,3,AIR:0)
Block(3,32,4,AIR:0)
Block(3,32,5,SPRUCE_FENCE:0)
Block(3,33,-2,SPRUCE_FENCE:0)
Block(3,33,-1,AIR:0)
Block(3,33,0,AIR:0)
Block(3,33,1,AIR:0)
Block(3,33,2,AIR:0)
Block(3,33,3,AIR:0)
Block(3,33,4,AIR:0)
Block(3,33,5,SPRUCE_FENCE:0)
Block(3,34,-2,SPRUCE_FENCE:0)
Block(3,34,-1,AIR:0)
Block(3,34,0,AIR:0)
Block(3,34,1,AIR:0)
Block(3,34,2,AIR:0)
Block(3,34,3,AIR:0)
Block(3,34,4,AIR:0)
Block(3,34,5,SPRUCE_FENCE:0)
Block(3,35,-2,SPRUCE_FENCE:0)
Block(3,35,-1,AIR:0)
Block(3,35,0,AIR:0)
Block(3,35,1,AIR:0)
Block(3,35,2,AIR:0)
Block(3,35,3,AIR:0)
Block(3,35,4,AIR:0)
Block(3,35,5,SPRUCE_FENCE:0)
Block(3,36,-2,SPRUCE_FENCE:0)
Block(3,36,-1,AIR:0)
Block(3,36,0,AIR:0)
Block(3,36,1,AIR:0)
Block(3,36,2,AIR:0)
Block(3,36,3,AIR:0)
Block(3,36,4,AIR:0)
Block(3,36,5,SPRUCE_FENCE:0)
Block(4,0,-2,SPRUCE_FENCE:0)
Block(4,0,-1,AIR:0)
Block(4,0,0,WOOD:1)
Block(4,0,1,AIR:0)
Block(4,0,2,AIR:0)
Block(4,0,3,WOOD:1)
Block(4,0,4,AIR:0)
Block(4,0,5,SPRUCE_FENCE:0)
Block(4,1,-2,SPRUCE_FENCE:0)
Block(4,1,-1,AIR:0)
Block(4,1,0,WOOD:1)
Block(4,1,1,WOOD:1)
Block(4,1,2,WOOD:1)
Block(4,1,3,WOOD:1)
Block(4,1,4,AIR:0)
Block(4,1,5,SPRUCE_FENCE:0)
Block(4,2,-2,SPRUCE_FENCE:0)
Block(4,2,-1,AIR:0)
Block(4,2,0,WOOD:1)
Block(4,2,1,AIR:0)
Block(4,2,2,AIR:0)
Block(4,2,3,WOOD:1)
Block(4,2,4,AIR:0)
Block(4,2,5,SPRUCE_FENCE:0)
Block(4,3,-2,SPRUCE_FENCE:0)
Block(4,3,-1,AIR:0)
Block(4,3,0,WOOD:1)
Block(4,3,1,AIR:0)
Block(4,3,2,AIR:0)
Block(4,3,3,WOOD:1)
Block(4,3,4,AIR:0)
Block(4,3,5,SPRUCE_FENCE:0)
Block(4,4,-2,SPRUCE_FENCE:0)
Block(4,4,-1,AIR:0)
Block(4,4,0,WOOD:1)
Block(4,4,1,WOOD:1)
Block(4,4,2,WOOD:1)
Block(4,4,3,WOOD:1)
Block(4,4,4,AIR:0)
Block(4,4,5,SPRUCE_FENCE:0)
Block(4,5,-2,SPRUCE_FENCE:0)
Block(4,5,-1,AIR:0)
Block(4,5,0,WOOD:1)
Block(4,5,1,AIR:0)
Block(4,5,2,AIR:0)
Block(4,5,3,WOOD:1)
Block(4,5,4,AIR:0)
Block(4,5,5,SPRUCE_FENCE:0)
Block(4,6,-2,SPRUCE_FENCE:0)
Block(4,6,-1,AIR:0)
Block(4,6,0,WOOD:1)
Block(4,6,1,AIR:0)
Block(4,6,2,AIR:0)
Block(4,6,3,WOOD:1)
Block(4,6,4,AIR:0)
Block(4,6,5,SPRUCE_FENCE:0)
Block(4,7,-2,SPRUCE_FENCE:0)
Block(4,7,-1,AIR:0)
Block(4,7,0,WOOD:1)
Block(4,7,1,WOOD:1)
Block(4,7,2,WOOD:1)
Block(4,7,3,WOOD:1)
Block(4,7,4,AIR:0)
Block(4,7,5,SPRUCE_FENCE:0)
Block(4,8,-2,SPRUCE_FENCE:0)
Block(4,8,-1,AIR:0)
Block(4,8,0,WOOD:1)
Block(4,8,1,AIR:0)
Block(4,8,2,AIR:0)
Block(4,8,3,WOOD:1)
Block(4,8,4,AIR:0)
Block(4,8,5,SPRUCE_FENCE:0)
Block(4,9,-2,SPRUCE_FENCE:0)
Block(4,9,-1,AIR:0)
Block(4,9,0,WOOD:1)
Block(4,9,1,WOOD:1)
Block(4,9,2,WOOD:1)
Block(4,9,3,WOOD:1)
Block(4,9,4,AIR:0)
Block(4,9,5,SPRUCE_FENCE:0)
Block(4,10,-2,SPRUCE_FENCE:0)
Block(4,10,-1,AIR:0)
Block(4,10,0,WOOD:1)
Block(4,10,1,AIR:0)
Block(4,10,2,AIR:0)
Block(4,10,3,WOOD:1)
Block(4,10,4,AIR:0)
Block(4,10,5,SPRUCE_FENCE:0)
Block(4,11,-2,SPRUCE_FENCE:0)
Block(4,11,-1,AIR:0)
Block(4,11,0,WOOD:1)
Block(4,11,1,AIR:0)
Block(4,11,2,AIR:0)
Block(4,11,3,WOOD:1)
Block(4,11,4,AIR:0)
Block(4,11,5,SPRUCE_FENCE:0)
Block(4,12,-2,SPRUCE_FENCE:0)
Block(4,12,-1,AIR:0)
Block(4,12,0,WOOD:1)
Block(4,12,1,WOOD:1)
Block(4,12,2,WOOD:1)
Block(4,12,3,WOOD:1)
Block(4,12,4,AIR:0)
Block(4,12,5,SPRUCE_FENCE:0)
Block(4,13,-2,SPRUCE_FENCE:0)
Block(4,13,-1,AIR:0)
Block(4,13,0,WOOD:1)
Block(4,13,1,AIR:0)
Block(4,13,2,AIR:0)
Block(4,13,3,WOOD:1)
Block(4,13,4,AIR:0)
Block(4,13,5,SPRUCE_FENCE:0)
Block(4,14,-2,SPRUCE_FENCE:0)
Block(4,14,-1,AIR:0)
Block(4,14,0,WOOD:1)
Block(4,14,1,AIR:0)
Block(4,14,2,AIR:0)
Block(4,14,3,WOOD:1)
Block(4,14,4,AIR:0)
Block(4,14,5,SPRUCE_FENCE:0)
Block(4,15,-2,SPRUCE_FENCE:0)
Block(4,15,-1,AIR:0)
Block(4,15,0,WOOD:1)
Block(4,15,1,WOOD:1)
Block(4,15,2,WOOD:1)
Block(4,15,3,WOOD:1)
Block(4,15,4,AIR:0)
Block(4,15,5,SPRUCE_FENCE:0)
Block(4,16,-2,SPRUCE_FENCE:0)
Block(4,16,-1,AIR:0)
Block(4,16,0,WOOD:1)
Block(4,16,1,AIR:0)
Block(4,16,2,AIR:0)
Block(4,16,3,WOOD:1)
Block(4,16,4,AIR:0)
Block(4,16,5,SPRUCE_FENCE:0)
Block(4,17,-2,SPRUCE_FENCE:0)
Block(4,17,-1,AIR:0)
Block(4,17,0,WOOD:1)
Block(4,17,1,WOOD:1)
Block(4,17,2,WOOD:1)
Block(4,17,3,WOOD:1)
Block(4,17,4,AIR:0)
Block(4,17,5,SPRUCE_FENCE:0)
Block(4,18,-2,SPRUCE_FENCE:0)
Block(4,18,-1,AIR:0)
Block(4,18,0,WOOD:1)
Block(4,18,1,AIR:0)
Block(4,18,2,AIR:0)
Block(4,18,3,WOOD:1)
Block(4,18,4,AIR:0)
Block(4,18,5,SPRUCE_FENCE:0)
Block(4,19,-2,SPRUCE_FENCE:0)
Block(4,19,-1,AIR:0)
Block(4,19,0,WOOD:1)
Block(4,19,1,AIR:0)
Block(4,19,2,AIR:0)
Block(4,19,3,WOOD:1)
Block(4,19,4,AIR:0)
Block(4,19,5,SPRUCE_FENCE:0)
Block(4,20,-2,SPRUCE_FENCE:0)
Block(4,20,-1,AIR:0)
Block(4,20,0,WOOD:1)
Block(4,20,1,WOOD:1)
Block(4,20,2,WOOD:1)
Block(4,20,3,WOOD:1)
Block(4,20,4,AIR:0)
Block(4,20,5,SPRUCE_FENCE:0)
Block(4,21,-2,SPRUCE_FENCE:0)
Block(4,21,-1,AIR:0)
Block(4,21,0,WOOD:1)
Block(4,21,1,AIR:0)
Block(4,21,2,AIR:0)
Block(4,21,3,WOOD:1)
Block(4,21,4,AIR:0)
Block(4,21,5,SPRUCE_FENCE:0)
Block(4,22,-2,SPRUCE_FENCE:0)
Block(4,22,-1,AIR:0)
Block(4,22,0,WOOD:1)
Block(4,22,1,AIR:0)
Block(4,22,2,AIR:0)
Block(4,22,3,WOOD:1)
Block(4,22,4,AIR:0)
Block(4,22,5,SPRUCE_FENCE:0)
Block(4,23,-2,SPRUCE_FENCE:0)
Block(4,23,-1,AIR:0)
Block(4,23,0,WOOD:1)
Block(4,23,1,WOOD:1)
Block(4,23,2,WOOD:1)
Block(4,23,3,WOOD:1)
Block(4,23,4,AIR:0)
Block(4,23,5,SPRUCE_FENCE:0)
Block(4,24,-2,SPRUCE_FENCE:0)
Block(4,24,-1,AIR:0)
Block(4,24,0,WOOD:1)
Block(4,24,1,AIR:0)
Block(4,24,2,AIR:0)
Block(4,24,3,WOOD:1)
Block(4,24,4,AIR:0)
Block(4,24,5,SPRUCE_FENCE:0)
Block(4,25,-2,SPRUCE_FENCE:0)
Block(4,25,-1,AIR:0)
Block(4,25,0,WOOD:1)
Block(4,25,1,WOOD:1)
Block(4,25,2,WOOD:1)
Block(4,25,3,WOOD:1)
Block(4,25,4,AIR:0)
Block(4,25,5,SPRUCE_FENCE:0)
Block(4,26,-2,SPRUCE_FENCE:0)
Block(4,26,-1,AIR:0)
Block(4,26,0,WOOD:1)
Block(4,26,1,AIR:0)
Block(4,26,2,AIR:0)
Block(4,26,3,WOOD:1)
Block(4,26,4,AIR:0)
Block(4,26,5,SPRUCE_FENCE:0)
Block(4,27,-2,SPRUCE_FENCE:0)
Block(4,27,-1,AIR:0)
Block(4,27,0,WOOD:1)
Block(4,27,1,AIR:0)
Block(4,27,2,AIR:0)
Block(4,27,3,WOOD:1)
Block(4,27,4,AIR:0)
Block(4,27,5,SPRUCE_FENCE:0)
Block(4,28,-2,SPRUCE_FENCE:0)
Block(4,28,-1,AIR:0)
Block(4,28,0,WOOD:1)
Block(4,28,1,WOOD:1)
Block(4,28,2,WOOD:1)
Block(4,28,3,WOOD:1)
Block(4,28,4,AIR:0)
Block(4,28,5,SPRUCE_FENCE:0)
Block(4,29,-2,SPRUCE_FENCE:0)
Block(4,29,-1,AIR:0)
Block(4,29,0,WOOD:1)
Block(4,29,1,AIR:0)
Block(4,29,2,AIR:0)
Block(4,29,3,WOOD:1)
Block(4,29,4,AIR:0)
Block(4,29,5,SPRUCE_FENCE:0)
Block(4,30,-2,SPRUCE_FENCE:0)
Block(4,30,-1,AIR:0)
Block(4,30,0,WOOD:1)
Block(4,30,1,AIR:0)
Block(4,30,2,AIR:0)
Block(4,30,3,WOOD:1)
Block(4,30,4,AIR:0)
Block(4,30,5,SPRUCE_FENCE:0)
Block(4,31,-2,SPRUCE_FENCE:0)
Block(4,31,-1,AIR:0)
Block(4,31,0,WOOD:1)
Block(4,31,1,WOOD:1)
Block(4,31,2,WOOD:1)
Block(4,31,3,WOOD:1)
Block(4,31,4,AIR:0)
Block(4,31,5,SPRUCE_FENCE:0)
Block(4,32,-2,SPRUCE_FENCE:0)
Block(4,32,-1,AIR:0)
Block(4,32,0,WOOD:1)
Block(4,32,1,AIR:0)
Block(4,32,2,AIR:0)
Block(4,32,3,WOOD:1)
Block(4,32,4,AIR:0)
Block(4,32,5,SPRUCE_FENCE:0)
Block(4,33,-2,SPRUCE_FENCE:0)
Block(4,33,-1,AIR:0)
Block(4,33,0,WOOD:1)
Block(4,33,1,WOOD:1)
Block(4,33,2,WOOD:1)
Block(4,33,3,WOOD:1)
Block(4,33,4,AIR:0)
Block(4,33,5,SPRUCE_FENCE:0)
Block(4,34,-2,SPRUCE_FENCE:0)
Block(4,34,-1,AIR:0)
Block(4,34,0,WOOD:1)
Block(4,34,1,AIR:0)
Block(4,34,2,AIR:0)
Block(4,34,3,WOOD:1)
Block(4,34,4,AIR:0)
Block(4,34,5,SPRUCE_FENCE:0)
Block(4,35,-2,SPRUCE_FENCE:0)
Block(4,35,-1,AIR:0)
Block(4,35,0,WOOD:1)
Block(4,35,1,AIR:0)
Block(4,35,2,AIR:0)
Block(4,35,3,WOOD:1)
Block(4,35,4,AIR:0)
Block(4,35,5,SPRUCE_FENCE:0)
Block(4,36,-2,SPRUCE_FENCE:0)
Block(4,36,-1,AIR:0)
Block(4,36,0,WOOD:1)
Block(4,36,1,WOOD:1)
Block(4,36,2,WOOD:1)
Block(4,36,3,WOOD:1)
Block(4,36,4,AIR:0)
Block(4,36,5,SPRUCE_FENCE:0)
Block(5,0,-2,SPRUCE_FENCE:0)
Block(5,0,-1,SPRUCE_FENCE:0)
Block(5,0,0,SPRUCE_FENCE:0)
Block(5,0,1,LADDER:5)
Block(5,0,2,LADDER:5)
Block(5,0,3,SPRUCE_FENCE:0)
Block(5,0,4,SPRUCE_FENCE:0)
Block(5,0,5,SPRUCE_FENCE:0)
Block(5,1,-2,SPRUCE_FENCE:0)
Block(5,1,-1,SPRUCE_FENCE:0)
Block(5,1,0,SPRUCE_FENCE:0)
Block(5,1,1,LADDER:5)
Block(5,1,2,LADDER:5)
Block(5,1,3,SPRUCE_FENCE:0)
Block(5,1,4,SPRUCE_FENCE:0)
Block(5,1,5,SPRUCE_FENCE:0)
Block(5,2,-2,SPRUCE_FENCE:0)
Block(5,2,-1,SPRUCE_FENCE:0)
Block(5,2,0,SPRUCE_FENCE:0)
Block(5,2,1,LADDER:5)
Block(5,2,2,LADDER:5)
Block(5,2,3,SPRUCE_FENCE:0)
Block(5,2,4,SPRUCE_FENCE:0)
Block(5,2,5,SPRUCE_FENCE:0)
Block(5,3,-2,SPRUCE_FENCE:0)
Block(5,3,-1,SPRUCE_FENCE:0)
Block(5,3,0,SPRUCE_FENCE:0)
Block(5,3,1,LADDER:5)
Block(5,3,2,LADDER:5)
Block(5,3,3,SPRUCE_FENCE:0)
Block(5,3,4,SPRUCE_FENCE:0)
Block(5,3,5,SPRUCE_FENCE:0)
Block(5,4,-2,SPRUCE_FENCE:0)
Block(5,4,-1,SPRUCE_FENCE:0)
Block(5,4,0,SPRUCE_FENCE:0)
Block(5,4,1,LADDER:5)
Block(5,4,2,LADDER:5)
Block(5,4,3,SPRUCE_FENCE:0)
Block(5,4,4,SPRUCE_FENCE:0)
Block(5,4,5,SPRUCE_FENCE:0)
Block(5,5,-2,SPRUCE_FENCE:0)
Block(5,5,-1,SPRUCE_FENCE:0)
Block(5,5,0,SPRUCE_FENCE:0)
Block(5,5,1,LADDER:5)
Block(5,5,2,LADDER:5)
Block(5,5,3,SPRUCE_FENCE:0)
Block(5,5,4,SPRUCE_FENCE:0)
Block(5,5,5,SPRUCE_FENCE:0)
Block(5,6,-2,SPRUCE_FENCE:0)
Block(5,6,-1,SPRUCE_FENCE:0)
Block(5,6,0,SPRUCE_FENCE:0)
Block(5,6,1,LADDER:5)
Block(5,6,2,LADDER:5)
Block(5,6,3,SPRUCE_FENCE:0)
Block(5,6,4,SPRUCE_FENCE:0)
Block(5,6,5,SPRUCE_FENCE:0)
Block(5,7,-2,SPRUCE_FENCE:0)
Block(5,7,-1,SPRUCE_FENCE:0)
Block(5,7,0,SPRUCE_FENCE:0)
Block(5,7,1,LADDER:5)
Block(5,7,2,LADDER:5)
Block(5,7,3,SPRUCE_FENCE:0)
Block(5,7,4,SPRUCE_FENCE:0)
Block(5,7,5,SPRUCE_FENCE:0)
Block(5,8,-2,SPRUCE_FENCE:0)
Block(5,8,-1,SPRUCE_FENCE:0)
Block(5,8,0,SPRUCE_FENCE:0)
Block(5,8,1,LADDER:5)
Block(5,8,2,LADDER:5)
Block(5,8,3,SPRUCE_FENCE:0)
Block(5,8,4,SPRUCE_FENCE:0)
Block(5,8,5,SPRUCE_FENCE:0)
Block(5,9,-2,SPRUCE_FENCE:0)
Block(5,9,-1,SPRUCE_FENCE:0)
Block(5,9,0,SPRUCE_FENCE:0)
Block(5,9,1,LADDER:5)
Block(5,9,2,LADDER:5)
Block(5,9,3,SPRUCE_FENCE:0)
Block(5,9,4,SPRUCE_FENCE:0)
Block(5,9,5,SPRUCE_FENCE:0)
Block(5,10,-2,SPRUCE_FENCE:0)
Block(5,10,-1,SPRUCE_FENCE:0)
Block(5,10,0,SPRUCE_FENCE:0)
Block(5,10,1,LADDER:5)
Block(5,10,2,LADDER:5)
Block(5,10,3,SPRUCE_FENCE:0)
Block(5,10,4,SPRUCE_FENCE:0)
Block(5,10,5,SPRUCE_FENCE:0)
Block(5,11,-2,SPRUCE_FENCE:0)
Block(5,11,-1,SPRUCE_FENCE:0)
Block(5,11,0,SPRUCE_FENCE:0)
Block(5,11,1,LADDER:5)
Block(5,11,2,LADDER:5)
Block(5,11,3,SPRUCE_FENCE:0)
Block(5,11,4,SPRUCE_FENCE:0)
Block(5,11,5,SPRUCE_FENCE:0)
Block(5,12,-2,SPRUCE_FENCE:0)
Block(5,12,-1,SPRUCE_FENCE:0)
Block(5,12,0,SPRUCE_FENCE:0)
Block(5,12,1,LADDER:5)
Block(5,12,2,LADDER:5)
Block(5,12,3,SPRUCE_FENCE:0)
Block(5,12,4,SPRUCE_FENCE:0)
Block(5,12,5,SPRUCE_FENCE:0)
Block(5,13,-2,SPRUCE_FENCE:0)
Block(5,13,-1,SPRUCE_FENCE:0)
Block(5,13,0,SPRUCE_FENCE:0)
Block(5,13,1,LADDER:5)
Block(5,13,2,LADDER:5)
Block(5,13,3,SPRUCE_FENCE:0)
Block(5,13,4,SPRUCE_FENCE:0)
Block(5,13,5,SPRUCE_FENCE:0)
Block(5,14,-2,SPRUCE_FENCE:0)
Block(5,14,-1,SPRUCE_FENCE:0)
Block(5,14,0,SPRUCE_FENCE:0)
Block(5,14,1,LADDER:5)
Block(5,14,2,LADDER:5)
Block(5,14,3,SPRUCE_FENCE:0)
Block(5,14,4,SPRUCE_FENCE:0)
Block(5,14,5,SPRUCE_FENCE:0)
Block(5,15,-2,SPRUCE_FENCE:0)
Block(5,15,-1,SPRUCE_FENCE:0)
Block(5,15,0,SPRUCE_FENCE:0)
Block(5,15,1,LADDER:5)
Block(5,15,2,LADDER:5)
Block(5,15,3,SPRUCE_FENCE:0)
Block(5,15,4,SPRUCE_FENCE:0)
Block(5,15,5,SPRUCE_FENCE:0)
Block(5,16,-2,SPRUCE_FENCE:0)
Block(5,16,-1,SPRUCE_FENCE:0)
Block(5,16,0,SPRUCE_FENCE:0)
Block(5,16,1,LADDER:5)
Block(5,16,2,LADDER:5)
Block(5,16,3,SPRUCE_FENCE:0)
Block(5,16,4,SPRUCE_FENCE:0)
Block(5,16,5,SPRUCE_FENCE:0)
Block(5,17,-2,SPRUCE_FENCE:0)
Block(5,17,-1,SPRUCE_FENCE:0)
Block(5,17,0,SPRUCE_FENCE:0)
Block(5,17,1,LADDER:5)
Block(5,17,2,LADDER:5)
Block(5,17,3,SPRUCE_FENCE:0)
Block(5,17,4,SPRUCE_FENCE:0)
Block(5,17,5,SPRUCE_FENCE:0)
Block(5,18,-2,SPRUCE_FENCE:0)
Block(5,18,-1,SPRUCE_FENCE:0)
Block(5,18,0,SPRUCE_FENCE:0)
Block(5,18,1,LADDER:5)
Block(5,18,2,LADDER:5)
Block(5,18,3,SPRUCE_FENCE:0)
Block(5,18,4,SPRUCE_FENCE:0)
Block(5,18,5,SPRUCE_FENCE:0)
Block(5,19,-2,SPRUCE_FENCE:0)
Block(5,19,-1,SPRUCE_FENCE:0)
Block(5,19,0,SPRUCE_FENCE:0)
Block(5,19,1,LADDER:5)
Block(5,19,2,LADDER:5)
Block(5,19,3,SPRUCE_FENCE:0)
Block(5,19,4,SPRUCE_FENCE:0)
Block(5,19,5,SPRUCE_FENCE:0)
Block(5,20,-2,SPRUCE_FENCE:0)
Block(5,20,-1,SPRUCE_FENCE:0)
Block(5,20,0,SPRUCE_FENCE:0)
Block(5,20,1,LADDER:5)
Block(5,20,2,LADDER:5)
Block(5,20,3,SPRUCE_FENCE:0)
Block(5,20,4,SPRUCE_FENCE:0)
Block(5,20,5,SPRUCE_FENCE:0)
Block(5,21,-2,SPRUCE_FENCE:0)
Block(5,21,-1,SPRUCE_FENCE:0)
Block(5,21,0,SPRUCE_FENCE:0)
Block(5,21,1,LADDER:5)
Block(5,21,2,LADDER:5)
Block(5,21,3,SPRUCE_FENCE:0)
Block(5,21,4,SPRUCE_FENCE:0)
Block(5,21,5,SPRUCE_FENCE:0)
Block(5,22,-2,SPRUCE_FENCE:0)
Block(5,22,-1,SPRUCE_FENCE:0)
Block(5,22,0,SPRUCE_FENCE:0)
Block(5,22,1,LADDER:5)
Block(5,22,2,LADDER:5)
Block(5,22,3,SPRUCE_FENCE:0)
Block(5,22,4,SPRUCE_FENCE:0)
Block(5,22,5,SPRUCE_FENCE:0)
Block(5,23,-2,SPRUCE_FENCE:0)
Block(5,23,-1,SPRUCE_FENCE:0)
Block(5,23,0,SPRUCE_FENCE:0)
Block(5,23,1,LADDER:5)
Block(5,23,2,LADDER:5)
Block(5,23,3,SPRUCE_FENCE:0)
Block(5,23,4,SPRUCE_FENCE:0)
Block(5,23,5,SPRUCE_FENCE:0)
Block(5,24,-2,SPRUCE_FENCE:0)
Block(5,24,-1,SPRUCE_FENCE:0)
Block(5,24,0,SPRUCE_FENCE:0)
Block(5,24,1,LADDER:5)
Block(5,24,2,LADDER:5)
Block(5,24,3,SPRUCE_FENCE:0)
Block(5,24,4,SPRUCE_FENCE:0)
Block(5,24,5,SPRUCE_FENCE:0)
Block(5,25,-2,SPRUCE_FENCE:0)
Block(5,25,-1,SPRUCE_FENCE:0)
Block(5,25,0,SPRUCE_FENCE:0)
Block(5,25,1,LADDER:5)
Block(5,25,2,LADDER:5)
Block(5,25,3,SPRUCE_FENCE:0)
Block(5,25,4,SPRUCE_FENCE:0)
Block(5,25,5,SPRUCE_FENCE:0)
Block(5,26,-2,SPRUCE_FENCE:0)
Block(5,26,-1,SPRUCE_FENCE:0)
Block(5,26,0,SPRUCE_FENCE:0)
Block(5,26,1,LADDER:5)
Block(5,26,2,LADDER:5)
Block(5,26,3,SPRUCE_FENCE:0)
Block(5,26,4,SPRUCE_FENCE:0)
Block(5,26,5,SPRUCE_FENCE:0)
Block(5,27,-2,SPRUCE_FENCE:0)
Block(5,27,-1,SPRUCE_FENCE:0)
Block(5,27,0,SPRUCE_FENCE:0)
Block(5,27,1,LADDER:5)
Block(5,27,2,LADDER:5)
Block(5,27,3,SPRUCE_FENCE:0)
Block(5,27,4,SPRUCE_FENCE:0)
Block(5,27,5,SPRUCE_FENCE:0)
Block(5,28,-2,SPRUCE_FENCE:0)
Block(5,28,-1,SPRUCE_FENCE:0)
Block(5,28,0,SPRUCE_FENCE:0)
Block(5,28,1,LADDER:5)
Block(5,28,2,LADDER:5)
Block(5,28,3,SPRUCE_FENCE:0)
Block(5,28,4,SPRUCE_FENCE:0)
Block(5,28,5,SPRUCE_FENCE:0)
Block(5,29,-2,SPRUCE_FENCE:0)
Block(5,29,-1,SPRUCE_FENCE:0)
Block(5,29,0,SPRUCE_FENCE:0)
Block(5,29,1,LADDER:5)
Block(5,29,2,LADDER:5)
Block(5,29,3,SPRUCE_FENCE:0)
Block(5,29,4,SPRUCE_FENCE:0)
Block(5,29,5,SPRUCE_FENCE:0)
Block(5,30,-2,SPRUCE_FENCE:0)
Block(5,30,-1,SPRUCE_FENCE:0)
Block(5,30,0,SPRUCE_FENCE:0)
Block(5,30,1,LADDER:5)
Block(5,30,2,LADDER:5)
Block(5,30,3,SPRUCE_FENCE:0)
Block(5,30,4,SPRUCE_FENCE:0)
Block(5,30,5,SPRUCE_FENCE:0)
Block(5,31,-2,SPRUCE_FENCE:0)
Block(5,31,-1,SPRUCE_FENCE:0)
Block(5,31,0,SPRUCE_FENCE:0)
Block(5,31,1,LADDER:5)
Block(5,31,2,LADDER:5)
Block(5,31,3,SPRUCE_FENCE:0)
Block(5,31,4,SPRUCE_FENCE:0)
Block(5,31,5,SPRUCE_FENCE:0)
Block(5,32,-2,SPRUCE_FENCE:0)
Block(5,32,-1,SPRUCE_FENCE:0)
Block(5,32,0,SPRUCE_FENCE:0)
Block(5,32,1,LADDER:5)
Block(5,32,2,LADDER:5)
Block(5,32,3,SPRUCE_FENCE:0)
Block(5,32,4,SPRUCE_FENCE:0)
Block(5,32,5,SPRUCE_FENCE:0)
Block(5,33,-2,SPRUCE_FENCE:0)
Block(5,33,-1,SPRUCE_FENCE:0)
Block(5,33,0,SPRUCE_FENCE:0)
Block(5,33,1,LADDER:5)
Block(5,33,2,LADDER:5)
Block(5,33,3,SPRUCE_FENCE:0)
Block(5,33,4,SPRUCE_FENCE:0)
Block(5,33,5,SPRUCE_FENCE:0)
Block(5,34,-2,SPRUCE_FENCE:0)
Block(5,34,-1,SPRUCE_FENCE:0)
Block(5,34,0,SPRUCE_FENCE:0)
Block(5,34,1,LADDER:5)
Block(5,34,2,LADDER:5)
Block(5,34,3,SPRUCE_FENCE:0)
Block(5,34,4,SPRUCE_FENCE:0)
Block(5,34,5,SPRUCE_FENCE:0)
Block(5,35,-2,SPRUCE_FENCE:0)
Block(5,35,-1,SPRUCE_FENCE:0)
Block(5,35,0,SPRUCE_FENCE:0)
Block(5,35,1,LADDER:5)
Block(5,35,2,LADDER:5)
Block(5,35,3,SPRUCE_FENCE:0)
Block(5,35,4,SPRUCE_FENCE:0)
Block(5,35,5,SPRUCE_FENCE:0)
Block(5,36,-2,SPRUCE_FENCE:0)
Block(5,36,-1,SPRUCE_FENCE:0)
Block(5,36,0,SPRUCE_FENCE:0)
Block(5,36,1,LADDER:5)
Block(5,36,2,LADDER:5)
Block(5,36,3,SPRUCE_FENCE:0)
Block(5,36,4,SPRUCE_FENCE:0)
Block(5,36,5,SPRUCE_FENCE:0)
Block(6,0,0,SPRUCE_FENCE:0)
Block(6,0,1,SPRUCE_FENCE:0)
Block(6,0,2,SPRUCE_FENCE:0)
Block(6,0,3,SPRUCE_FENCE:0)
Block(6,1,0,SPRUCE_FENCE:0)
Block(6,1,1,SPRUCE_FENCE:0)
Block(6,1,2,SPRUCE_FENCE:0)
Block(6,1,3,SPRUCE_FENCE:0)
Block(6,2,0,SPRUCE_FENCE:0)
Block(6,2,1,SPRUCE_FENCE:0)
Block(6,2,2,SPRUCE_FENCE:0)
Block(6,2,3,SPRUCE_FENCE:0)
Block(6,3,0,SPRUCE_FENCE:0)
Block(6,3,1,SPRUCE_FENCE:0)
Block(6,3,2,SPRUCE_FENCE:0)
Block(6,3,3,SPRUCE_FENCE:0)
Block(6,4,0,SPRUCE_FENCE:0)
Block(6,4,1,SPRUCE_FENCE:0)
Block(6,4,2,SPRUCE_FENCE:0)
Block(6,4,3,SPRUCE_FENCE:0)
Block(6,5,0,SPRUCE_FENCE:0)
Block(6,5,1,SPRUCE_FENCE:0)
Block(6,5,2,SPRUCE_FENCE:0)
Block(6,5,3,SPRUCE_FENCE:0)
Block(6,6,0,SPRUCE_FENCE:0)
Block(6,6,1,SPRUCE_FENCE:0)
Block(6,6,2,SPRUCE_FENCE:0)
Block(6,6,3,SPRUCE_FENCE:0)
Block(6,7,0,SPRUCE_FENCE:0)
Block(6,7,1,SPRUCE_FENCE:0)
Block(6,7,2,SPRUCE_FENCE:0)
Block(6,7,3,SPRUCE_FENCE:0)
Block(6,8,0,SPRUCE_FENCE:0)
Block(6,8,1,SPRUCE_FENCE:0)
Block(6,8,2,SPRUCE_FENCE:0)
Block(6,8,3,SPRUCE_FENCE:0)
Block(6,9,0,SPRUCE_FENCE:0)
Block(6,9,1,SPRUCE_FENCE:0)
Block(6,9,2,SPRUCE_FENCE:0)
Block(6,9,3,SPRUCE_FENCE:0)
Block(6,10,0,SPRUCE_FENCE:0)
Block(6,10,1,SPRUCE_FENCE:0)
Block(6,10,2,SPRUCE_FENCE:0)
Block(6,10,3,SPRUCE_FENCE:0)
Block(6,11,0,SPRUCE_FENCE:0)
Block(6,11,1,SPRUCE_FENCE:0)
Block(6,11,2,SPRUCE_FENCE:0)
Block(6,11,3,SPRUCE_FENCE:0)
Block(6,12,0,SPRUCE_FENCE:0)
Block(6,12,1,SPRUCE_FENCE:0)
Block(6,12,2,SPRUCE_FENCE:0)
Block(6,12,3,SPRUCE_FENCE:0)
Block(6,13,0,SPRUCE_FENCE:0)
Block(6,13,1,SPRUCE_FENCE:0)
Block(6,13,2,SPRUCE_FENCE:0)
Block(6,13,3,SPRUCE_FENCE:0)
Block(6,14,0,SPRUCE_FENCE:0)
Block(6,14,1,SPRUCE_FENCE:0)
Block(6,14,2,SPRUCE_FENCE:0)
Block(6,14,3,SPRUCE_FENCE:0)
Block(6,15,0,SPRUCE_FENCE:0)
Block(6,15,1,SPRUCE_FENCE:0)
Block(6,15,2,SPRUCE_FENCE:0)
Block(6,15,3,SPRUCE_FENCE:0)
Block(6,16,0,SPRUCE_FENCE:0)
Block(6,16,1,SPRUCE_FENCE:0)
Block(6,16,2,SPRUCE_FENCE:0)
Block(6,16,3,SPRUCE_FENCE:0)
Block(6,17,0,SPRUCE_FENCE:0)
Block(6,17,1,SPRUCE_FENCE:0)
Block(6,17,2,SPRUCE_FENCE:0)
Block(6,17,3,SPRUCE_FENCE:0)
Block(6,18,0,SPRUCE_FENCE:0)
Block(6,18,1,SPRUCE_FENCE:0)
Block(6,18,2,SPRUCE_FENCE:0)
Block(6,18,3,SPRUCE_FENCE:0)
Block(6,19,0,SPRUCE_FENCE:0)
Block(6,19,1,SPRUCE_FENCE:0)
Block(6,19,2,SPRUCE_FENCE:0)
Block(6,19,3,SPRUCE_FENCE:0)
Block(6,20,0,SPRUCE_FENCE:0)
Block(6,20,1,SPRUCE_FENCE:0)
Block(6,20,2,SPRUCE_FENCE:0)
Block(6,20,3,SPRUCE_FENCE:0)
Block(6,21,0,SPRUCE_FENCE:0)
Block(6,21,1,SPRUCE_FENCE:0)
Block(6,21,2,SPRUCE_FENCE:0)
Block(6,21,3,SPRUCE_FENCE:0)
Block(6,22,0,SPRUCE_FENCE:0)
Block(6,22,1,SPRUCE_FENCE:0)
Block(6,22,2,SPRUCE_FENCE:0)
Block(6,22,3,SPRUCE_FENCE:0)
Block(6,23,0,SPRUCE_FENCE:0)
Block(6,23,1,SPRUCE_FENCE:0)
Block(6,23,2,SPRUCE_FENCE:0)
Block(6,23,3,SPRUCE_FENCE:0)
Block(6,24,0,SPRUCE_FENCE:0)
Block(6,24,1,SPRUCE_FENCE:0)
Block(6,24,2,SPRUCE_FENCE:0)
Block(6,24,3,SPRUCE_FENCE:0)
Block(6,25,0,SPRUCE_FENCE:0)
Block(6,25,1,SPRUCE_FENCE:0)
Block(6,25,2,SPRUCE_FENCE:0)
Block(6,25,3,SPRUCE_FENCE:0)
Block(6,26,0,SPRUCE_FENCE:0)
Block(6,26,1,SPRUCE_FENCE:0)
Block(6,26,2,SPRUCE_FENCE:0)
Block(6,26,3,SPRUCE_FENCE:0)
Block(6,27,0,SPRUCE_FENCE:0)
Block(6,27,1,SPRUCE_FENCE:0)
Block(6,27,2,SPRUCE_FENCE:0)
Block(6,27,3,SPRUCE_FENCE:0)
Block(6,28,0,SPRUCE_FENCE:0)
Block(6,28,1,SPRUCE_FENCE:0)
Block(6,28,2,SPRUCE_FENCE:0)
Block(6,28,3,SPRUCE_FENCE:0)
Block(6,29,0,SPRUCE_FENCE:0)
Block(6,29,1,SPRUCE_FENCE:0)
Block(6,29,2,SPRUCE_FENCE:0)
Block(6,29,3,SPRUCE_FENCE:0)
Block(6,30,0,SPRUCE_FENCE:0)
Block(6,30,1,SPRUCE_FENCE:0)
Block(6,30,2,SPRUCE_FENCE:0)
Block(6,30,3,SPRUCE_FENCE:0)
Block(6,31,0,SPRUCE_FENCE:0)
Block(6,31,1,SPRUCE_FENCE:0)
Block(6,31,2,SPRUCE_FENCE:0)
Block(6,31,3,SPRUCE_FENCE:0)
Block(6,32,0,SPRUCE_FENCE:0)
Block(6,32,1,SPRUCE_FENCE:0)
Block(6,32,2,SPRUCE_FENCE:0)
Block(6,32,3,SPRUCE_FENCE:0)
Block(6,33,0,SPRUCE_FENCE:0)
Block(6,33,1,SPRUCE_FENCE:0)
Block(6,33,2,SPRUCE_FENCE:0)
Block(6,33,3,SPRUCE_FENCE:0)
Block(6,34,0,SPRUCE_FENCE:0)
Block(6,34,1,SPRUCE_FENCE:0)
Block(6,34,2,SPRUCE_FENCE:0)
Block(6,34,3,SPRUCE_FENCE:0)
Block(6,35,0,SPRUCE_FENCE:0)
Block(6,35,1,SPRUCE_FENCE:0)
Block(6,35,2,SPRUCE_FENCE:0)
Block(6,35,3,SPRUCE_FENCE:0)
Block(6,36,0,SPRUCE_FENCE:0)
Block(6,36,1,SPRUCE_FENCE:0)
Block(6,36,2,SPRUCE_FENCE:0)
Block(6,36,3,SPRUCE_FENCE:0)
Block(8,750,9,AIR:0)

#######################################################################
# +-----------------------------------------------------------------+ #
# |                             Branches                            | #
# +-----------------------------------------------------------------+ #
#######################################################################


#######################################################################
# +-----------------------------------------------------------------+ #
# |                             Entities                            | #
# +-----------------------------------------------------------------+ #
#######################################################################


#######################################################################
# +-----------------------------------------------------------------+ #
# |                            Particles                            | #
# +-----------------------------------------------------------------+ #
#######################################################################


#######################################################################
# +-----------------------------------------------------------------+ #
# |                             Spawners                            | #
# +-----------------------------------------------------------------+ #
#######################################################################


#######################################################################
# +-----------------------------------------------------------------+ #
# |                             ModData                             | #
# +-----------------------------------------------------------------+ #
#######################################################################

