
#######################################################################
# +-----------------------------------------------------------------+ #
# |                            BO4 object                           | #
# +-----------------------------------------------------------------+ #
#######################################################################

Author: NLBlackEagle

Description: No description given

SettingsMode: WriteWithoutComments


#######################################################################
# +-----------------------------------------------------------------+ #
# |                          Main settings                          | #
# +-----------------------------------------------------------------+ #
#######################################################################

FixedRotation: 

Frequency: 0

SpawnHeight: highestBlock

UseCenterForHighestBlock: true

##############################
# Height Limits for the BO4. #
##############################

MinHeight: 0

MaxHeight: 255

InheritBO3: 

InheritBO3Rotation: NORTH

OverrideChildSettings: true

OverrideParentHeight: false

CanOverride: true

BranchFrequency: 0

BranchFrequencyGroup: 

MustBeBelowOther: false

MustBeInside: 

CannotBeInside: 

ReplacesBO3: 

MustBeInsideWorldBorders: false

CanSpawnOnWater: true

SpawnOnWaterOnly: false

SpawnUnderWater: false

SpawnAtWaterLevel: false

HeightOffset: 0

RemoveAir: false

ReplaceAbove: 

ReplaceBelow: 

ReplaceWithBiomeBlocks: false

ReplaceWithSurfaceBlock: GRASS

ReplaceWithGroundBlock: DIRT

ReplaceWithStoneBlock: STONE

SmoothRadius: 0

SmoothHeightOffset: 0

SmoothStartTop: false

SmoothStartWood: false

SmoothingSurfaceBlock: 

SmoothingGroundBlock: 

BO3Group: 

IsSpawnPoint: false

DoReplaceBlocks: true


#######################################################################
# +-----------------------------------------------------------------+ #
# |                              Blocks                             | #
# +-----------------------------------------------------------------+ #
#######################################################################

Block(-8,0,-7,STAINED_CLAY:7)
Block(-8,0,-1,STAINED_CLAY:7)
Block(-8,1,-7,STAINED_CLAY:12)
Block(-8,1,-1,STAINED_CLAY:12)
Block(-8,2,-7,STAINED_CLAY:12)
Block(-8,2,-6,STAINED_CLAY:12)
Block(-8,2,-5,STAINED_CLAY:12)
Block(-8,2,-4,STAINED_CLAY:12)
Block(-8,2,-3,STAINED_CLAY:12)
Block(-8,2,-2,STAINED_CLAY:12)
Block(-8,2,-1,STAINED_CLAY:12)
Block(-7,0,-7,STAINED_CLAY:7)
Block(-7,0,-6,STAINED_CLAY:12)
Block(-7,0,-5,STAINED_CLAY:12)
Block(-7,0,-4,STAINED_CLAY:12)
Block(-7,0,-3,STAINED_CLAY:12)
Block(-7,0,-2,STAINED_CLAY:12)
Block(-7,0,-1,STAINED_CLAY:7)
Block(-7,1,-7,STAINED_CLAY:12)
Block(-7,1,-6,STAINED_CLAY:12)
Block(-7,1,-5,STAINED_CLAY:12)
Block(-7,1,-4,STAINED_CLAY:12)
Block(-7,1,-3,STAINED_CLAY:12)
Block(-7,1,-2,STAINED_CLAY:12)
Block(-7,1,-1,STAINED_CLAY:12)
Block(-7,2,-7,STAINED_CLAY:12)
Block(-7,2,-6,STAINED_CLAY:12)
Block(-7,2,-5,STAINED_CLAY:12)
Block(-7,2,-4,STAINED_CLAY:12)
Block(-7,2,-3,STAINED_CLAY:12)
Block(-7,2,-2,STAINED_CLAY:12)
Block(-7,2,-1,STAINED_CLAY:12)
Block(-6,0,-7,STAINED_CLAY:7)
Block(-6,0,-6,COAL_BLOCK:0)
Block(-6,0,-5,COAL_BLOCK:0)
Block(-6,0,-4,COAL_BLOCK:0)
Block(-6,0,-3,COAL_BLOCK:0)
Block(-6,0,-2,COAL_BLOCK:0)
Block(-6,0,-1,STAINED_CLAY:7)
Block(-6,1,-7,STAINED_CLAY:12)
Block(-6,1,-6,COAL_BLOCK:0)
Block(-6,1,-5,COAL_BLOCK:0)
Block(-6,1,-4,COAL_BLOCK:0)
Block(-6,1,-3,COAL_BLOCK:0)
Block(-6,1,-2,COAL_BLOCK:0)
Block(-6,1,-1,STAINED_CLAY:12)
Block(-6,2,-7,STAINED_CLAY:12)
Block(-6,2,-6,STAINED_CLAY:12)
Block(-6,2,-5,STAINED_CLAY:12)
Block(-6,2,-4,STAINED_CLAY:12)
Block(-6,2,-3,STAINED_CLAY:12)
Block(-6,2,-2,STAINED_CLAY:12)
Block(-6,2,-1,STAINED_CLAY:12)
Block(-5,0,-7,STAINED_CLAY:7)
Block(-5,0,-6,COAL_BLOCK:0)
Block(-5,0,-5,COAL_BLOCK:0)
Block(-5,0,-4,COAL_BLOCK:0)
Block(-5,0,-3,COAL_BLOCK:0)
Block(-5,0,-2,COAL_BLOCK:0)
Block(-5,0,-1,STAINED_CLAY:7)
Block(-5,1,-7,STAINED_CLAY:12)
Block(-5,1,-6,COAL_BLOCK:0)
Block(-5,1,-5,COAL_BLOCK:0)
Block(-5,1,-4,COAL_BLOCK:0)
Block(-5,1,-3,COAL_BLOCK:0)
Block(-5,1,-2,COAL_BLOCK:0)
Block(-5,1,-1,STAINED_CLAY:12)
Block(-5,2,-7,STAINED_CLAY:12)
Block(-5,2,-6,STAINED_CLAY:12)
Block(-5,2,-5,STAINED_CLAY:12)
Block(-5,2,-4,STAINED_CLAY:12)
Block(-5,2,-3,STAINED_CLAY:12)
Block(-5,2,-2,STAINED_CLAY:12)
Block(-5,2,-1,STAINED_CLAY:12)
Block(-4,0,-7,STAINED_CLAY:7)
Block(-4,0,-6,COAL_BLOCK:0)
Block(-4,0,-5,COAL_BLOCK:0)
Block(-4,0,-4,COAL_BLOCK:0)
Block(-4,0,-3,COAL_BLOCK:0)
Block(-4,0,-2,COAL_BLOCK:0)
Block(-4,0,-1,STAINED_CLAY:7)
Block(-4,1,-7,STAINED_CLAY:12)
Block(-4,1,-6,COAL_BLOCK:0)
Block(-4,1,-5,COAL_BLOCK:0)
Block(-4,1,-4,COAL_BLOCK:0)
Block(-4,1,-3,COAL_BLOCK:0)
Block(-4,1,-2,COAL_BLOCK:0)
Block(-4,1,-1,STAINED_CLAY:12)
Block(-4,2,-7,STAINED_CLAY:12)
Block(-4,2,-6,STAINED_CLAY:12)
Block(-4,2,-5,STAINED_CLAY:12)
Block(-4,2,-4,STAINED_CLAY:12)
Block(-4,2,-3,STAINED_CLAY:12)
Block(-4,2,-2,STAINED_CLAY:12)
Block(-4,2,-1,STAINED_CLAY:12)
Block(-3,0,-7,STAINED_CLAY:7)
Block(-3,0,-6,COAL_BLOCK:0)
Block(-3,0,-5,COAL_BLOCK:0)
Block(-3,0,-4,COAL_BLOCK:0)
Block(-3,0,-3,COAL_BLOCK:0)
Block(-3,0,-2,COAL_BLOCK:0)
Block(-3,0,-1,STAINED_CLAY:7)
Block(-3,1,-7,STAINED_CLAY:12)
Block(-3,1,-6,COAL_BLOCK:0)
Block(-3,1,-5,COAL_BLOCK:0)
Block(-3,1,-4,COAL_BLOCK:0)
Block(-3,1,-3,COAL_BLOCK:0)
Block(-3,1,-2,COAL_BLOCK:0)
Block(-3,1,-1,STAINED_CLAY:12)
Block(-3,2,-7,STAINED_CLAY:12)
Block(-3,2,-6,STAINED_CLAY:12)
Block(-3,2,-5,STAINED_CLAY:12)
Block(-3,2,-4,STAINED_CLAY:12)
Block(-3,2,-3,STAINED_CLAY:12)
Block(-3,2,-2,STAINED_CLAY:12)
Block(-3,2,-1,STAINED_CLAY:12)
Block(-2,0,-7,STAINED_CLAY:7)
Block(-2,0,-6,COAL_BLOCK:0)
Block(-2,0,-5,COAL_BLOCK:0)
Block(-2,0,-4,COAL_BLOCK:0)
Block(-2,0,-3,COAL_BLOCK:0)
Block(-2,0,-2,COAL_BLOCK:0)
Block(-2,0,-1,STAINED_CLAY:7)
Block(-2,1,-7,STAINED_CLAY:12)
Block(-2,1,-6,COAL_BLOCK:0)
Block(-2,1,-5,COAL_BLOCK:0)
Block(-2,1,-4,COAL_BLOCK:0)
Block(-2,1,-3,COAL_BLOCK:0)
Block(-2,1,-2,COAL_BLOCK:0)
Block(-2,1,-1,STAINED_CLAY:12)
Block(-2,2,-7,STAINED_CLAY:12)
Block(-2,2,-6,STAINED_CLAY:12)
Block(-2,2,-5,STAINED_CLAY:12)
Block(-2,2,-4,STAINED_CLAY:12)
Block(-2,2,-3,STAINED_CLAY:12)
Block(-2,2,-2,STAINED_CLAY:12)
Block(-2,2,-1,STAINED_CLAY:12)
Block(-1,0,-7,STAINED_CLAY:7)
Block(-1,0,-6,COAL_BLOCK:0)
Block(-1,0,-5,COAL_BLOCK:0)
Block(-1,0,-4,COAL_BLOCK:0)
Block(-1,0,-3,COAL_BLOCK:0)
Block(-1,0,-2,COAL_BLOCK:0)
Block(-1,0,-1,STAINED_CLAY:7)
Block(-1,1,-7,STAINED_CLAY:12)
Block(-1,1,-6,COAL_BLOCK:0)
Block(-1,1,-5,COAL_BLOCK:0)
Block(-1,1,-4,COAL_BLOCK:0)
Block(-1,1,-3,COAL_BLOCK:0)
Block(-1,1,-2,COAL_BLOCK:0)
Block(-1,1,-1,STAINED_CLAY:12)
Block(-1,2,-7,STAINED_CLAY:12)
Block(-1,2,-6,STAINED_CLAY:12)
Block(-1,2,-5,STAINED_CLAY:12)
Block(-1,2,-4,STAINED_CLAY:12)
Block(-1,2,-3,STAINED_CLAY:12)
Block(-1,2,-2,STAINED_CLAY:12)
Block(-1,2,-1,STAINED_CLAY:12)
Block(0,0,-7,STAINED_CLAY:7)
Block(0,0,-6,COAL_BLOCK:0)
Block(0,0,-5,COAL_BLOCK:0)
Block(0,0,-4,COAL_BLOCK:0)
Block(0,0,-3,COAL_BLOCK:0)
Block(0,0,-2,COAL_BLOCK:0)
Block(0,0,-1,STAINED_CLAY:7)
Block(0,1,-7,STAINED_CLAY:12)
Block(0,1,-6,COAL_BLOCK:0)
Block(0,1,-5,COAL_BLOCK:0)
Block(0,1,-4,COAL_BLOCK:0)
Block(0,1,-3,COAL_BLOCK:0)
Block(0,1,-2,COAL_BLOCK:0)
Block(0,1,-1,STAINED_CLAY:12)
Block(0,2,-7,STAINED_CLAY:12)
Block(0,2,-6,STAINED_CLAY:12)
Block(0,2,-5,STAINED_CLAY:12)
Block(0,2,-4,STAINED_CLAY:12)
Block(0,2,-3,STAINED_CLAY:12)
Block(0,2,-2,STAINED_CLAY:12)
Block(0,2,-1,STAINED_CLAY:12)
Block(1,0,-7,STAINED_CLAY:7)
Block(1,0,-6,COAL_BLOCK:0)
Block(1,0,-5,COAL_BLOCK:0)
Block(1,0,-4,COAL_BLOCK:0)
Block(1,0,-3,COAL_BLOCK:0)
Block(1,0,-2,COAL_BLOCK:0)
Block(1,0,-1,STAINED_CLAY:7)
Block(1,1,-7,STAINED_CLAY:12)
Block(1,1,-6,COAL_BLOCK:0)
Block(1,1,-5,COAL_BLOCK:0)
Block(1,1,-4,COAL_BLOCK:0)
Block(1,1,-3,COAL_BLOCK:0)
Block(1,1,-2,COAL_BLOCK:0)
Block(1,1,-1,STAINED_CLAY:12)
Block(1,2,-7,STAINED_CLAY:12)
Block(1,2,-6,STAINED_CLAY:12)
Block(1,2,-5,STAINED_CLAY:12)
Block(1,2,-4,STAINED_CLAY:12)
Block(1,2,-3,STAINED_CLAY:12)
Block(1,2,-2,STAINED_CLAY:12)
Block(1,2,-1,STAINED_CLAY:12)
Block(2,0,-7,STAINED_CLAY:7)
Block(2,0,-6,COAL_BLOCK:0)
Block(2,0,-5,COAL_BLOCK:0)
Block(2,0,-4,COAL_BLOCK:0)
Block(2,0,-3,COAL_BLOCK:0)
Block(2,0,-2,COAL_BLOCK:0)
Block(2,0,-1,STAINED_CLAY:7)
Block(2,1,-7,STAINED_CLAY:12)
Block(2,1,-6,COAL_BLOCK:0)
Block(2,1,-5,COAL_BLOCK:0)
Block(2,1,-4,COAL_BLOCK:0)
Block(2,1,-3,COAL_BLOCK:0)
Block(2,1,-2,COAL_BLOCK:0)
Block(2,1,-1,STAINED_CLAY:12)
Block(2,2,-7,STAINED_CLAY:12)
Block(2,2,-6,STAINED_CLAY:12)
Block(2,2,-5,STAINED_CLAY:12)
Block(2,2,-4,STAINED_CLAY:12)
Block(2,2,-3,STAINED_CLAY:12)
Block(2,2,-2,STAINED_CLAY:12)
Block(2,2,-1,STAINED_CLAY:12)
Block(3,0,-7,STAINED_CLAY:7)
Block(3,0,-6,COAL_BLOCK:0)
Block(3,0,-5,COAL_BLOCK:0)
Block(3,0,-4,COAL_BLOCK:0)
Block(3,0,-3,COAL_BLOCK:0)
Block(3,0,-2,COAL_BLOCK:0)
Block(3,0,-1,STAINED_CLAY:7)
Block(3,1,-7,STAINED_CLAY:12)
Block(3,1,-6,COAL_BLOCK:0)
Block(3,1,-5,COAL_BLOCK:0)
Block(3,1,-4,COAL_BLOCK:0)
Block(3,1,-3,COAL_BLOCK:0)
Block(3,1,-2,COAL_BLOCK:0)
Block(3,1,-1,STAINED_CLAY:12)
Block(3,2,-7,STAINED_CLAY:12)
Block(3,2,-6,STAINED_CLAY:12)
Block(3,2,-5,STAINED_CLAY:12)
Block(3,2,-4,STAINED_CLAY:12)
Block(3,2,-3,STAINED_CLAY:12)
Block(3,2,-2,STAINED_CLAY:12)
Block(3,2,-1,STAINED_CLAY:12)
Block(4,0,-7,STAINED_CLAY:7)
Block(4,0,-6,COAL_BLOCK:0)
Block(4,0,-5,COAL_BLOCK:0)
Block(4,0,-4,COAL_BLOCK:0)
Block(4,0,-3,COAL_BLOCK:0)
Block(4,0,-2,COAL_BLOCK:0)
Block(4,0,-1,STAINED_CLAY:7)
Block(4,1,-7,STAINED_CLAY:12)
Block(4,1,-6,COAL_BLOCK:0)
Block(4,1,-5,COAL_BLOCK:0)
Block(4,1,-4,COAL_BLOCK:0)
Block(4,1,-3,COAL_BLOCK:0)
Block(4,1,-2,COAL_BLOCK:0)
Block(4,1,-1,STAINED_CLAY:12)
Block(4,2,-7,STAINED_CLAY:12)
Block(4,2,-6,STAINED_CLAY:12)
Block(4,2,-5,STAINED_CLAY:12)
Block(4,2,-4,STAINED_CLAY:12)
Block(4,2,-3,STAINED_CLAY:12)
Block(4,2,-2,STAINED_CLAY:12)
Block(4,2,-1,STAINED_CLAY:12)
Block(5,0,-7,STAINED_CLAY:7)
Block(5,0,-6,COAL_BLOCK:0)
Block(5,0,-5,COAL_BLOCK:0)
Block(5,0,-4,COAL_BLOCK:0)
Block(5,0,-3,COAL_BLOCK:0)
Block(5,0,-2,COAL_BLOCK:0)
Block(5,0,-1,STAINED_CLAY:7)
Block(5,1,-7,STAINED_CLAY:12)
Block(5,1,-6,COAL_BLOCK:0)
Block(5,1,-5,COAL_BLOCK:0)
Block(5,1,-4,COAL_BLOCK:0)
Block(5,1,-3,COAL_BLOCK:0)
Block(5,1,-2,COAL_BLOCK:0)
Block(5,1,-1,STAINED_CLAY:12)
Block(5,2,-7,STAINED_CLAY:12)
Block(5,2,-6,STAINED_CLAY:12)
Block(5,2,-5,STAINED_CLAY:12)
Block(5,2,-4,STAINED_CLAY:12)
Block(5,2,-3,STAINED_CLAY:12)
Block(5,2,-2,STAINED_CLAY:12)
Block(5,2,-1,STAINED_CLAY:12)
Block(6,0,-7,STAINED_CLAY:7)
Block(6,0,-6,COAL_BLOCK:0)
Block(6,0,-5,COAL_BLOCK:0)
Block(6,0,-4,COAL_BLOCK:0)
Block(6,0,-3,COAL_BLOCK:0)
Block(6,0,-2,COAL_BLOCK:0)
Block(6,0,-1,STAINED_CLAY:7)
Block(6,1,-7,STAINED_CLAY:12)
Block(6,1,-6,COAL_BLOCK:0)
Block(6,1,-5,COAL_BLOCK:0)
Block(6,1,-4,COAL_BLOCK:0)
Block(6,1,-3,COAL_BLOCK:0)
Block(6,1,-2,COAL_BLOCK:0)
Block(6,1,-1,STAINED_CLAY:12)
Block(6,2,-7,STAINED_CLAY:12)
Block(6,2,-6,STAINED_CLAY:12)
Block(6,2,-5,STAINED_CLAY:12)
Block(6,2,-4,STAINED_CLAY:12)
Block(6,2,-3,STAINED_CLAY:12)
Block(6,2,-2,STAINED_CLAY:12)
Block(6,2,-1,STAINED_CLAY:12)
Block(7,0,-7,STAINED_CLAY:7)
Block(7,0,-6,COAL_BLOCK:0)
Block(7,0,-5,COAL_BLOCK:0)
Block(7,0,-4,COAL_BLOCK:0)
Block(7,0,-3,COAL_BLOCK:0)
Block(7,0,-2,COAL_BLOCK:0)
Block(7,0,-1,STAINED_CLAY:7)
Block(7,1,-7,STAINED_CLAY:12)
Block(7,1,-6,COAL_BLOCK:0)
Block(7,1,-5,COAL_BLOCK:0)
Block(7,1,-4,COAL_BLOCK:0)
Block(7,1,-3,COAL_BLOCK:0)
Block(7,1,-2,COAL_BLOCK:0)
Block(7,1,-1,STAINED_CLAY:12)
Block(7,2,-7,STAINED_CLAY:12)
Block(7,2,-6,STAINED_CLAY:12)
Block(7,2,-5,STAINED_CLAY:12)
Block(7,2,-4,STAINED_CLAY:12)
Block(7,2,-3,STAINED_CLAY:12)
Block(7,2,-2,STAINED_CLAY:12)
Block(7,2,-1,STAINED_CLAY:12)
Block(7,3,-7,STAINED_CLAY:12)
Block(7,3,-5,STAINED_CLAY:12)
Block(7,3,-4,STAINED_CLAY:12)
Block(7,3,-3,STAINED_CLAY:12)
Block(7,3,-2,STAINED_CLAY:12)
Block(7,3,-1,STAINED_CLAY:12)
Block(7,4,-7,STAINED_CLAY:12)
Block(7,4,-5,STAINED_CLAY:12)
Block(7,4,-3,STAINED_CLAY:12)
Block(7,4,-1,STAINED_CLAY:12)
Block(7,5,-7,STAINED_CLAY:12)
Block(7,5,-6,STAINED_CLAY:12)
Block(7,5,-5,STAINED_CLAY:12)
Block(7,5,-4,STAINED_CLAY:12)
Block(7,5,-3,STAINED_CLAY:12)
Block(7,5,-2,STAINED_CLAY:12)
Block(7,5,-1,STAINED_CLAY:12)
Block(7,6,-7,STAINED_CLAY:12)
Block(7,6,-6,STAINED_CLAY:12)
Block(7,6,-5,STAINED_CLAY:12)
Block(7,6,-4,STAINED_CLAY:12)
Block(7,6,-3,STAINED_CLAY:12)
Block(7,6,-2,STAINED_CLAY:12)
Block(7,6,-1,STAINED_CLAY:12)
Block(7,7,-7,STAINED_CLAY:12)
Block(7,7,-1,STAINED_CLAY:12)
Block(7,8,-6,STAINED_CLAY:12)
Block(7,8,-5,STAINED_CLAY:12)
Block(7,8,-4,STAINED_CLAY:12)
Block(7,8,-3,STAINED_CLAY:12)
Block(7,8,-2,STAINED_CLAY:12)

#######################################################################
# +-----------------------------------------------------------------+ #
# |                             Branches                            | #
# +-----------------------------------------------------------------+ #
#######################################################################

Branch(16,0,0,true,Ship4C2R0,NORTH,100.0,0)

#######################################################################
# +-----------------------------------------------------------------+ #
# |                             Entities                            | #
# +-----------------------------------------------------------------+ #
#######################################################################


#######################################################################
# +-----------------------------------------------------------------+ #
# |                            Particles                            | #
# +-----------------------------------------------------------------+ #
#######################################################################


#######################################################################
# +-----------------------------------------------------------------+ #
# |                             Spawners                            | #
# +-----------------------------------------------------------------+ #
#######################################################################


#######################################################################
# +-----------------------------------------------------------------+ #
# |                             ModData                             | #
# +-----------------------------------------------------------------+ #
#######################################################################

