
#######################################################################
# +-----------------------------------------------------------------+ #
# |                            BO3 object                           | #
# +-----------------------------------------------------------------+ #
#######################################################################

Author: NLBlackEagle

Description: No description given

Version: 3

SettingsMode: WriteDisable


#######################################################################
# +-----------------------------------------------------------------+ #
# |                          Main settings                          | #
# +-----------------------------------------------------------------+ #
#######################################################################

Tree: true

Frequency: 0

Rarity: 100.0

RotateRandomly: true

SpawnHeight: highestSolidBlock

SpawnHeightOffset: 0

SpawnHeightVariance: 0

##############################
# Height Limits for the BO3. #
##############################

MinHeight: 0

MaxHeight: 255

######################
# Extrusion settings #
######################

ExtrudeMode: None

ExtrudeThroughBlocks: AIR

MaxBranchDepth: 10

ExcludedBiomes: All


#######################################################################
# +-----------------------------------------------------------------+ #
# |                      Source block settings                      | #
# +-----------------------------------------------------------------+ #
#######################################################################

SourceBlocks: AIR

MaxPercentageOutsideSourceBlock: 100

OutsideSourceBlock: placeAnyway

DoReplaceBlocks: true

IsOTGPlus: false


#######################################################################
# +-----------------------------------------------------------------+ #
# |                              Blocks                             | #
# +-----------------------------------------------------------------+ #
#######################################################################

Block(-6,0,0,SAND:0)
Block(-5,0,-1,SAND:0)
Block(-5,0,0,SAND:0)
Block(-5,0,1,SAND:0)
Block(-5,0,2,SAND:0)
Block(-5,0,3,SAND:0)
Block(-5,0,4,SAND:0)
Block(-4,0,-3,SAND:0)
Block(-4,0,-2,SAND:0)
Block(-4,0,-1,SAND:0)
Block(-4,0,0,SAND:0)
Block(-4,0,1,SAND:0)
Block(-4,0,2,SAND:0)
Block(-4,0,3,SAND:0)
Block(-4,0,4,SAND:0)
Block(-4,0,5,SAND:0)
Block(-4,1,0,SAND:0)
Block(-4,1,1,SAND:0)
Block(-4,1,2,SAND:0)
Block(-4,1,3,SAND:0)
Block(-3,0,-5,SAND:0)
Block(-3,0,-4,SAND:0)
Block(-3,0,-3,SAND:0)
Block(-3,0,-2,SAND:0)
Block(-3,0,-1,SAND:0)
Block(-3,0,0,SAND:0)
Block(-3,0,1,SAND:0)
Block(-3,0,2,SAND:0)
Block(-3,0,3,SAND:0)
Block(-3,0,4,SAND:0)
Block(-3,0,5,SAND:0)
Block(-3,0,6,SAND:0)
Block(-3,1,-1,SAND:0)
Block(-3,1,0,SAND:0)
Block(-3,1,1,SAND:0)
Block(-3,1,2,SAND:0)
Block(-3,1,3,SAND:0)
Block(-3,1,4,SAND:0)
RandomBlock(-3,6,-1,WALL_BANNER:4,../../NBT/banners/JungleBanner01.nbt,8,WALL_BANNER:4,../../NBT/banners/JungleBanner02.nbt,8,WALL_BANNER:4,../../NBT/banners/JungleBanner03.nbt,8,WALL_BANNER:4,../../NBT/banners/JungleBanner04.nbt,8,WALL_BANNER:4,../../NBT/banners/JungleBanner05.nbt,8,WALL_BANNER:4,../../NBT/banners/JungleBanner06.nbt,8,WALL_BANNER:4,../../NBT/banners/JungleBanner07.nbt,8,WALL_BANNER:4,../../NBT/banners/JungleBanner08.nbt,8,WALL_BANNER:4,../../NBT/banners/JungleBanner09.nbt,8,WALL_BANNER:4,../../NBT/banners/JungleBanner10.nbt,8,WALL_BANNER:4,../../NBT/banners/JungleBanner11.nbt,8,WALL_BANNER:4,../../NBT/banners/JungleBanner12.nbt,8,WALL_BANNER:4,../../NBT/banners/JungleBanner13.nbt,8,WALL_BANNER:4,../../NBT/banners/JungleBanner14.nbt,8,WALL_BANNER:4,../../NBT/banners/JungleBanner15.nbt,8,WALL_BANNER:4,../../NBT/banners/JungleBanner16.nbt,8,WALL_BANNER:4,../../NBT/banners/JungleBanner17.nbt,8,WALL_BANNER:4,../../NBT/banners/JungleBanner18.nbt,8,WALL_BANNER:4,../../NBT/banners/JungleBanner19.nbt,8,WALL_BANNER:4,../../NBT/banners/JungleBanner20.nbt,100)
RandomBlock(-3,6,4,WALL_BANNER:4,../../NBT/banners/JungleBanner01.nbt,8,WALL_BANNER:4,../../NBT/banners/JungleBanner02.nbt,8,WALL_BANNER:4,../../NBT/banners/JungleBanner03.nbt,8,WALL_BANNER:4,../../NBT/banners/JungleBanner04.nbt,8,WALL_BANNER:4,../../NBT/banners/JungleBanner05.nbt,8,WALL_BANNER:4,../../NBT/banners/JungleBanner06.nbt,8,WALL_BANNER:4,../../NBT/banners/JungleBanner07.nbt,8,WALL_BANNER:4,../../NBT/banners/JungleBanner08.nbt,8,WALL_BANNER:4,../../NBT/banners/JungleBanner09.nbt,8,WALL_BANNER:4,../../NBT/banners/JungleBanner10.nbt,8,WALL_BANNER:4,../../NBT/banners/JungleBanner11.nbt,8,WALL_BANNER:4,../../NBT/banners/JungleBanner12.nbt,8,WALL_BANNER:4,../../NBT/banners/JungleBanner13.nbt,8,WALL_BANNER:4,../../NBT/banners/JungleBanner14.nbt,8,WALL_BANNER:4,../../NBT/banners/JungleBanner15.nbt,8,WALL_BANNER:4,../../NBT/banners/JungleBanner16.nbt,8,WALL_BANNER:4,../../NBT/banners/JungleBanner17.nbt,8,WALL_BANNER:4,../../NBT/banners/JungleBanner18.nbt,8,WALL_BANNER:4,../../NBT/banners/JungleBanner19.nbt,8,WALL_BANNER:4,../../NBT/banners/JungleBanner20.nbt,100)
Block(-3,7,-2,WOOD_STEP:3)
Block(-3,7,-1,WOOD_STEP:3)
Block(-3,7,0,WOOD_STEP:3)
Block(-3,7,1,WOOD_STEP:3)
Block(-3,7,2,WOOD_STEP:3)
Block(-3,7,3,WOOD_STEP:3)
Block(-3,7,4,WOOD_STEP:3)
Block(-3,7,5,WOOD_STEP:3)
Block(-2,0,-6,SAND:0)
Block(-2,0,-5,SAND:0)
Block(-2,0,-4,SAND:0)
Block(-2,0,-3,SAND:0)
Block(-2,0,-2,SAND:0)
Block(-2,0,-1,SAND:0)
Block(-2,0,0,SAND:0)
Block(-2,0,1,SAND:0)
Block(-2,0,2,SAND:0)
Block(-2,0,3,SAND:0)
Block(-2,0,4,SAND:0)
Block(-2,0,5,SAND:0)
Block(-2,0,6,SAND:0)
Block(-2,0,7,SAND:0)
Block(-2,1,-4,SAND:0)
Block(-2,1,-3,SAND:0)
Block(-2,1,-2,SAND:0)
Block(-2,1,-1,SAND:0)
Block(-2,1,0,SAND:0)
Block(-2,1,1,SAND:0)
Block(-2,1,2,SAND:0)
Block(-2,1,3,SAND:0)
Block(-2,1,4,SAND:0)
Block(-2,1,5,SAND:0)
Block(-2,2,-1,WOOD:3)
Block(-2,2,0,JUNGLE_FENCE:0)
Block(-2,2,1,JUNGLE_FENCE:0)
Block(-2,2,2,JUNGLE_FENCE:0)
Block(-2,2,4,WOOD:3)
Block(-2,3,-1,WOOD:3)
Block(-2,3,4,WOOD:3)
Block(-2,4,-1,WOOD:3)
Block(-2,4,0,WOOD:3)
Block(-2,4,1,WOOD:3)
Block(-2,4,2,WOOD:3)
Block(-2,4,3,WOOD:3)
Block(-2,4,4,WOOD:3)
Block(-2,5,-1,WOOD:3)
Block(-2,5,0,JUNGLE_FENCE:0)
Block(-2,5,1,JUNGLE_FENCE:0)
Block(-2,5,2,JUNGLE_FENCE:0)
Block(-2,5,3,JUNGLE_FENCE:0)
Block(-2,5,4,WOOD:3)
Block(-2,6,-1,WOOD:3)
Block(-2,6,4,WOOD:3)
RandomBlock(-2,6,5,WALL_BANNER:3,../../NBT/banners/JungleBanner01.nbt,8,WALL_BANNER:3,../../NBT/banners/JungleBanner02.nbt,8,WALL_BANNER:3,../../NBT/banners/JungleBanner03.nbt,8,WALL_BANNER:3,../../NBT/banners/JungleBanner04.nbt,8,WALL_BANNER:3,../../NBT/banners/JungleBanner05.nbt,8,WALL_BANNER:3,../../NBT/banners/JungleBanner06.nbt,8,WALL_BANNER:3,../../NBT/banners/JungleBanner07.nbt,8,WALL_BANNER:3,../../NBT/banners/JungleBanner08.nbt,8,WALL_BANNER:3,../../NBT/banners/JungleBanner09.nbt,8,WALL_BANNER:3,../../NBT/banners/JungleBanner10.nbt,8,WALL_BANNER:3,../../NBT/banners/JungleBanner11.nbt,8,WALL_BANNER:3,../../NBT/banners/JungleBanner12.nbt,8,WALL_BANNER:3,../../NBT/banners/JungleBanner13.nbt,8,WALL_BANNER:3,../../NBT/banners/JungleBanner14.nbt,8,WALL_BANNER:3,../../NBT/banners/JungleBanner15.nbt,8,WALL_BANNER:3,../../NBT/banners/JungleBanner16.nbt,8,WALL_BANNER:3,../../NBT/banners/JungleBanner17.nbt,8,WALL_BANNER:3,../../NBT/banners/JungleBanner18.nbt,8,WALL_BANNER:3,../../NBT/banners/JungleBanner19.nbt,8,WALL_BANNER:3,../../NBT/banners/JungleBanner20.nbt,100)
Block(-2,7,-2,WOOD_STEP:3)
Block(-2,7,-1,WOOD:3)
Block(-2,7,0,WOOD:3)
Block(-2,7,1,WOOD_STEP:3)
Block(-2,7,2,WOOD_STEP:3)
Block(-2,7,3,WOOD:3)
Block(-2,7,4,WOOD_STEP:3)
Block(-2,7,5,WOOD_STEP:3)
Block(-1,0,-6,SAND:0)
Block(-1,0,-5,SAND:0)
Block(-1,0,-4,SAND:0)
Block(-1,0,-3,SAND:0)
Block(-1,0,-2,SAND:0)
Block(-1,0,-1,SAND:0)
Block(-1,0,0,SAND:0)
Block(-1,0,1,SAND:0)
Block(-1,0,2,SAND:0)
Block(-1,0,3,SAND:0)
Block(-1,0,4,SAND:0)
Block(-1,0,5,SAND:0)
Block(-1,0,6,SAND:0)
Block(-1,0,7,SAND:0)
Block(-1,1,-5,SAND:0)
Block(-1,1,-4,SAND:0)
Block(-1,1,-3,SAND:0)
Block(-1,1,-2,SAND:0)
Block(-1,1,-1,SAND:0)
Block(-1,1,0,GRAVEL:0)
Block(-1,1,1,SAND:0)
Block(-1,1,2,GRAVEL:0)
Block(-1,1,3,GRAVEL:0)
Block(-1,1,4,SAND:0)
Block(-1,1,5,SAND:0)
Block(-1,1,6,SAND:0)
Block(-1,2,-4,WOOD_STEP:3)
Block(-1,2,-3,WOOD_STEP:3)
Block(-1,2,5,JUNGLE_WOOD_STAIRS:0)
Block(-1,4,-1,WOOD:3)
Block(-1,4,0,WOOD_STEP:11)
Block(-1,4,1,WOOD_STEP:11)
Block(-1,4,2,WOOD_STEP:11)
Block(-1,4,3,WOOD_STEP:11)
Block(-1,4,4,WOOD:3)
Block(-1,5,-1,WOOD:3)
Block(-1,5,1,CARPET:12)
Block(-1,5,2,CARPET:12)
Block(-1,5,3,CARPET:12)
Block(-1,5,4,WOOD:3)
Block(-1,6,-1,STAINED_CLAY:0)
Block(-1,6,4,STAINED_CLAY:0)
RandomBlock(-1,6,5,WALL_BANNER:3,../../NBT/banners/JungleBanner01.nbt,8,WALL_BANNER:3,../../NBT/banners/JungleBanner02.nbt,8,WALL_BANNER:3,../../NBT/banners/JungleBanner03.nbt,8,WALL_BANNER:3,../../NBT/banners/JungleBanner04.nbt,8,WALL_BANNER:3,../../NBT/banners/JungleBanner05.nbt,8,WALL_BANNER:3,../../NBT/banners/JungleBanner06.nbt,8,WALL_BANNER:3,../../NBT/banners/JungleBanner07.nbt,8,WALL_BANNER:3,../../NBT/banners/JungleBanner08.nbt,8,WALL_BANNER:3,../../NBT/banners/JungleBanner09.nbt,8,WALL_BANNER:3,../../NBT/banners/JungleBanner10.nbt,8,WALL_BANNER:3,../../NBT/banners/JungleBanner11.nbt,8,WALL_BANNER:3,../../NBT/banners/JungleBanner12.nbt,8,WALL_BANNER:3,../../NBT/banners/JungleBanner13.nbt,8,WALL_BANNER:3,../../NBT/banners/JungleBanner14.nbt,8,WALL_BANNER:3,../../NBT/banners/JungleBanner15.nbt,8,WALL_BANNER:3,../../NBT/banners/JungleBanner16.nbt,8,WALL_BANNER:3,../../NBT/banners/JungleBanner17.nbt,8,WALL_BANNER:3,../../NBT/banners/JungleBanner18.nbt,8,WALL_BANNER:3,../../NBT/banners/JungleBanner19.nbt,8,WALL_BANNER:3,../../NBT/banners/JungleBanner20.nbt,100)
Block(-1,7,-2,WOOD_STEP:3)
Block(-1,7,-1,WOOD:3)
Block(-1,7,0,WOOD:3)
Block(-1,7,1,WOOD:3)
Block(-1,7,2,WOOD:3)
Block(-1,7,3,WOOD:3)
Block(-1,7,4,WOOD_STEP:3)
Block(-1,7,5,WOOD_STEP:3)
Block(0,0,-6,SAND:0)
Block(0,0,-5,SAND:0)
Block(0,0,-4,SAND:0)
Block(0,0,-3,SAND:0)
Block(0,0,-2,SAND:0)
Block(0,0,-1,SAND:0)
Block(0,0,0,SAND:0)
Block(0,0,1,SAND:0)
Block(0,0,2,SAND:0)
Block(0,0,3,SAND:0)
Block(0,0,4,SAND:0)
Block(0,0,5,SAND:0)
Block(0,0,6,SAND:0)
Block(0,0,7,SAND:0)
Block(0,1,-5,SAND:0)
Block(0,1,-4,SAND:0)
Block(0,1,-3,SAND:0)
Block(0,1,-2,SAND:0)
Block(0,1,-1,SAND:0)
Block(0,1,0,GRAVEL:0)
Block(0,1,1,GRAVEL:0)
Block(0,1,2,GRAVEL:0)
Block(0,1,3,GRAVEL:0)
Block(0,1,4,SAND:0)
Block(0,1,5,SAND:0)
Block(0,1,6,SAND:0)
Block(0,2,5,JUNGLE_WOOD_STAIRS:5)
Block(0,3,5,JUNGLE_WOOD_STAIRS:0)
Block(0,4,-1,WOOD:3)
Block(0,4,0,WOOD_STEP:11)
Block(0,4,1,WOOD_STEP:11)
Block(0,4,2,WOOD_STEP:11)
Block(0,4,3,WOOD_STEP:11)
Block(0,4,4,WOOD:3)
Block(0,5,-1,WOOD:3)
Block(0,5,1,JUNGLE_FENCE:0)
Block(0,5,3,CARPET:12)
Block(0,5,4,STAINED_CLAY:0)
RandomBlock(0,6,-2,WALL_BANNER:2,../../NBT/banners/JungleBanner01.nbt,8,WALL_BANNER:2,../../NBT/banners/JungleBanner02.nbt,8,WALL_BANNER:2,../../NBT/banners/JungleBanner03.nbt,8,WALL_BANNER:2,../../NBT/banners/JungleBanner04.nbt,8,WALL_BANNER:2,../../NBT/banners/JungleBanner05.nbt,8,WALL_BANNER:2,../../NBT/banners/JungleBanner06.nbt,8,WALL_BANNER:2,../../NBT/banners/JungleBanner07.nbt,8,WALL_BANNER:2,../../NBT/banners/JungleBanner08.nbt,8,WALL_BANNER:2,../../NBT/banners/JungleBanner09.nbt,8,WALL_BANNER:2,../../NBT/banners/JungleBanner10.nbt,8,WALL_BANNER:2,../../NBT/banners/JungleBanner11.nbt,8,WALL_BANNER:2,../../NBT/banners/JungleBanner12.nbt,8,WALL_BANNER:2,../../NBT/banners/JungleBanner13.nbt,8,WALL_BANNER:2,../../NBT/banners/JungleBanner14.nbt,8,WALL_BANNER:2,../../NBT/banners/JungleBanner15.nbt,8,WALL_BANNER:2,../../NBT/banners/JungleBanner16.nbt,8,WALL_BANNER:2,../../NBT/banners/JungleBanner17.nbt,8,WALL_BANNER:2,../../NBT/banners/JungleBanner18.nbt,8,WALL_BANNER:2,../../NBT/banners/JungleBanner19.nbt,8,WALL_BANNER:2,../../NBT/banners/JungleBanner20.nbt,100)
Block(0,6,-1,STAINED_CLAY:0)
Block(0,6,1,TORCH:5)
Block(0,6,2,AIR:0)
Block(0,6,4,STAINED_CLAY:0)
RandomBlock(0,6,5,WALL_BANNER:3,../../NBT/banners/JungleBanner01.nbt,8,WALL_BANNER:3,../../NBT/banners/JungleBanner02.nbt,8,WALL_BANNER:3,../../NBT/banners/JungleBanner03.nbt,8,WALL_BANNER:3,../../NBT/banners/JungleBanner04.nbt,8,WALL_BANNER:3,../../NBT/banners/JungleBanner05.nbt,8,WALL_BANNER:3,../../NBT/banners/JungleBanner06.nbt,8,WALL_BANNER:3,../../NBT/banners/JungleBanner07.nbt,8,WALL_BANNER:3,../../NBT/banners/JungleBanner08.nbt,8,WALL_BANNER:3,../../NBT/banners/JungleBanner09.nbt,8,WALL_BANNER:3,../../NBT/banners/JungleBanner10.nbt,8,WALL_BANNER:3,../../NBT/banners/JungleBanner11.nbt,8,WALL_BANNER:3,../../NBT/banners/JungleBanner12.nbt,8,WALL_BANNER:3,../../NBT/banners/JungleBanner13.nbt,8,WALL_BANNER:3,../../NBT/banners/JungleBanner14.nbt,8,WALL_BANNER:3,../../NBT/banners/JungleBanner15.nbt,8,WALL_BANNER:3,../../NBT/banners/JungleBanner16.nbt,8,WALL_BANNER:3,../../NBT/banners/JungleBanner17.nbt,8,WALL_BANNER:3,../../NBT/banners/JungleBanner18.nbt,8,WALL_BANNER:3,../../NBT/banners/JungleBanner19.nbt,8,WALL_BANNER:3,../../NBT/banners/JungleBanner20.nbt,100)
Block(0,7,-2,WOOD_STEP:3)
Block(0,7,-1,WOOD_STEP:3)
Block(0,7,0,WOOD:3)
Block(0,7,1,WOOD:3)
Block(0,7,2,WOOD:3)
Block(0,7,3,WOOD:3)
Block(0,7,4,WOOD:3)
Block(0,7,5,WOOD_STEP:3)
Block(1,0,-6,SAND:0)
Block(1,0,-5,SAND:0)
Block(1,0,-4,SAND:0)
Block(1,0,-3,SAND:0)
Block(1,0,-2,SAND:0)
Block(1,0,-1,SAND:0)
Block(1,0,0,SAND:0)
Block(1,0,1,SAND:0)
Block(1,0,2,SAND:0)
Block(1,0,3,SAND:0)
Block(1,0,4,SAND:0)
Block(1,0,5,SAND:0)
Block(1,0,6,SAND:0)
Block(1,0,7,SAND:0)
Block(1,0,8,SAND:0)
Block(1,1,-6,SAND:0)
Block(1,1,-5,COBBLESTONE_STAIRS:1)
Block(1,1,-4,MONSTER_EGGS:1)
Block(1,1,-3,COBBLESTONE_STAIRS:1)
Block(1,1,-2,SAND:0)
Block(1,1,-1,SAND:0)
Block(1,1,0,SAND:0)
Block(1,1,1,GRAVEL:0)
Block(1,1,2,GRAVEL:0)
Block(1,1,3,GRAVEL:0)
Block(1,1,4,GRAVEL:0)
Block(1,1,5,SAND:0)
Block(1,1,6,SAND:0)
Block(1,2,-4,COBBLE_WALL:0)
Block(1,2,-1,WOOD_STEP:3)
Block(1,3,5,JUNGLE_WOOD_STAIRS:5)
Block(1,4,-1,WOOD:3)
Block(1,4,0,WOOD_STEP:11)
Block(1,4,1,WOOD_STEP:11)
Block(1,4,2,WOOD_STEP:11)
Block(1,4,3,WOOD_STEP:11)
Block(1,4,4,WOOD:3)
Block(1,4,5,JUNGLE_WOOD_STAIRS:0)
Block(1,5,-1,STAINED_CLAY:0)
Block(1,5,1,JUNGLE_FENCE:0)
Block(1,5,2,JUNGLE_WOOD_STAIRS:1)
Block(1,5,4,WOOD:3)
RandomBlock(1,6,-2,WALL_BANNER:2,../../NBT/banners/JungleBanner01.nbt,8,WALL_BANNER:2,../../NBT/banners/JungleBanner02.nbt,8,WALL_BANNER:2,../../NBT/banners/JungleBanner03.nbt,8,WALL_BANNER:2,../../NBT/banners/JungleBanner04.nbt,8,WALL_BANNER:2,../../NBT/banners/JungleBanner05.nbt,8,WALL_BANNER:2,../../NBT/banners/JungleBanner06.nbt,8,WALL_BANNER:2,../../NBT/banners/JungleBanner07.nbt,8,WALL_BANNER:2,../../NBT/banners/JungleBanner08.nbt,8,WALL_BANNER:2,../../NBT/banners/JungleBanner09.nbt,8,WALL_BANNER:2,../../NBT/banners/JungleBanner10.nbt,8,WALL_BANNER:2,../../NBT/banners/JungleBanner11.nbt,8,WALL_BANNER:2,../../NBT/banners/JungleBanner12.nbt,8,WALL_BANNER:2,../../NBT/banners/JungleBanner13.nbt,8,WALL_BANNER:2,../../NBT/banners/JungleBanner14.nbt,8,WALL_BANNER:2,../../NBT/banners/JungleBanner15.nbt,8,WALL_BANNER:2,../../NBT/banners/JungleBanner16.nbt,8,WALL_BANNER:2,../../NBT/banners/JungleBanner17.nbt,8,WALL_BANNER:2,../../NBT/banners/JungleBanner18.nbt,8,WALL_BANNER:2,../../NBT/banners/JungleBanner19.nbt,8,WALL_BANNER:2,../../NBT/banners/JungleBanner20.nbt,100)
Block(1,6,-1,STAINED_CLAY:0)
Block(1,6,1,JUNGLE_FENCE:0)
Block(1,6,4,WOOD:3)
Block(1,7,-2,WOOD_STEP:3)
Block(1,7,-1,WOOD_STEP:3)
Block(1,7,0,WOOD:3)
Block(1,7,1,WOOD:3)
Block(1,7,2,WOOD:3)
Block(1,7,3,WOOD:3)
Block(1,7,4,WOOD_STEP:3)
Block(1,7,5,WOOD_STEP:3)
Block(2,0,-6,SAND:0)
Block(2,0,-5,SAND:0)
Block(2,0,-4,MAGMA:0)
Block(2,0,-3,SAND:0)
Block(2,0,-2,SAND:0)
Block(2,0,-1,SAND:0)
Block(2,0,0,SAND:0)
Block(2,0,1,SAND:0)
Block(2,0,2,SAND:0)
Block(2,0,3,SAND:0)
Block(2,0,4,SAND:0)
Block(2,0,5,SAND:0)
Block(2,0,6,SAND:0)
Block(2,0,7,SAND:0)
Block(2,0,8,SAND:0)
Block(2,1,-6,SAND:0)
Block(2,1,-5,COBBLESTONE_STAIRS:3)
Block(2,1,-3,COBBLESTONE_STAIRS:2)
Block(2,1,-2,SAND:0)
Block(2,1,-1,SAND:0)
Block(2,1,0,SAND:0)
Block(2,1,1,GRAVEL:0)
Block(2,1,2,GRAVEL:0)
Block(2,1,3,SAND:0)
Block(2,1,4,SAND:0)
Block(2,1,5,SAND:0)
Block(2,1,6,SAND:0)
Block(2,2,-1,WOOD_STEP:3)
Block(2,2,4,JUNGLE_FENCE:0)
Block(2,4,-1,WOOD:3)
Block(2,4,0,WOOD_STEP:11)
Block(2,4,1,WOOD_STEP:11)
Block(2,4,2,WOOD_STEP:11)
Block(2,4,3,WOOD_STEP:11)
Block(2,4,4,WOOD:3)
Block(2,4,5,JUNGLE_WOOD_STAIRS:5)
Block(2,5,-1,STAINED_CLAY:0)
Block(2,5,0,BED_BLOCK:3)
Block(2,5,1,STAINED_CLAY:0)
Block(2,5,2,JUNGLE_FENCE:0)
Block(2,5,4,JUNGLE_DOOR:1)
RandomBlock(2,6,-2,WALL_BANNER:2,../../NBT/banners/JungleBanner01.nbt,8,WALL_BANNER:2,../../NBT/banners/JungleBanner02.nbt,8,WALL_BANNER:2,../../NBT/banners/JungleBanner03.nbt,8,WALL_BANNER:2,../../NBT/banners/JungleBanner04.nbt,8,WALL_BANNER:2,../../NBT/banners/JungleBanner05.nbt,8,WALL_BANNER:2,../../NBT/banners/JungleBanner06.nbt,8,WALL_BANNER:2,../../NBT/banners/JungleBanner07.nbt,8,WALL_BANNER:2,../../NBT/banners/JungleBanner08.nbt,8,WALL_BANNER:2,../../NBT/banners/JungleBanner09.nbt,8,WALL_BANNER:2,../../NBT/banners/JungleBanner10.nbt,8,WALL_BANNER:2,../../NBT/banners/JungleBanner11.nbt,8,WALL_BANNER:2,../../NBT/banners/JungleBanner12.nbt,8,WALL_BANNER:2,../../NBT/banners/JungleBanner13.nbt,8,WALL_BANNER:2,../../NBT/banners/JungleBanner14.nbt,8,WALL_BANNER:2,../../NBT/banners/JungleBanner15.nbt,8,WALL_BANNER:2,../../NBT/banners/JungleBanner16.nbt,8,WALL_BANNER:2,../../NBT/banners/JungleBanner17.nbt,8,WALL_BANNER:2,../../NBT/banners/JungleBanner18.nbt,8,WALL_BANNER:2,../../NBT/banners/JungleBanner19.nbt,8,WALL_BANNER:2,../../NBT/banners/JungleBanner20.nbt,100)
Block(2,6,-1,STAINED_CLAY:0)
Block(2,6,1,STAINED_CLAY:0)
Block(2,6,2,CARPET:0)
Block(2,6,4,JUNGLE_DOOR:8)
Block(2,7,-2,WOOD_STEP:3)
Block(2,7,-1,WOOD:3)
Block(2,7,0,WOOD:3)
Block(2,7,1,WOOD:3)
Block(2,7,2,WOOD:3)
Block(2,7,3,WOOD:3)
Block(2,7,4,WOOD:3)
Block(2,7,5,WOOD_STEP:3)
Block(3,0,-6,SAND:0)
Block(3,0,-5,SAND:0)
Block(3,0,-4,SAND:0)
Block(3,0,-3,SAND:0)
Block(3,0,-2,SAND:0)
Block(3,0,-1,SAND:0)
Block(3,0,0,SAND:0)
Block(3,0,1,SAND:0)
Block(3,0,2,SAND:0)
Block(3,0,3,SAND:0)
Block(3,0,4,SAND:0)
Block(3,0,5,SAND:0)
Block(3,0,6,SAND:0)
Block(3,0,7,SAND:0)
Block(3,1,-6,SAND:0)
Block(3,1,-5,COBBLESTONE_STAIRS:0)
Block(3,1,-4,MONSTER_EGGS:1)
Block(3,1,-3,COBBLESTONE_STAIRS:0)
Block(3,1,-2,SAND:0)
Block(3,1,-1,SAND:0)
Block(3,1,0,SAND:0)
Block(3,1,1,SAND:0)
Block(3,1,2,GRAVEL:0)
Block(3,1,3,GRAVEL:0)
Block(3,1,4,SAND:0)
Block(3,1,5,SAND:0)
Block(3,1,6,SAND:0)
Block(3,2,-4,COBBLE_WALL:0)
Block(3,2,4,JUNGLE_FENCE:0)
Block(3,4,-1,WOOD:3)
Block(3,4,0,WOOD_STEP:11)
Block(3,4,1,WOOD_STEP:11)
Block(3,4,2,WOOD_STEP:11)
Block(3,4,3,WOOD_STEP:11)
Block(3,4,4,WOOD:3)
Block(3,5,-1,STAINED_CLAY:0)
Block(3,5,0,BED_BLOCK:11)
Block(3,5,1,STAINED_CLAY:0)
Block(3,5,2,JUNGLE_WOOD_STAIRS:0)
Block(3,5,3,CARPET:12)
Block(3,5,4,WOOD:3)
Block(3,6,-1,STAINED_CLAY:0)
Block(3,6,1,STAINED_CLAY:0)
Block(3,6,4,WOOD:3)
Block(3,7,-2,WOOD_STEP:3)
Block(3,7,-1,WOOD_STEP:3)
Block(3,7,0,WOOD:3)
Block(3,7,1,WOOD:3)
Block(3,7,2,WOOD:3)
Block(3,7,3,WOOD:3)
Block(3,7,4,WOOD_STEP:3)
Block(3,7,5,WOOD_STEP:3)
Block(4,0,-6,SAND:0)
Block(4,0,-5,SAND:0)
Block(4,0,-4,SAND:0)
Block(4,0,-3,SAND:0)
Block(4,0,-2,SAND:0)
Block(4,0,-1,SAND:0)
Block(4,0,0,SAND:0)
Block(4,0,1,SAND:0)
Block(4,0,2,SAND:0)
Block(4,0,3,SAND:0)
Block(4,0,4,WOOD:3)
Block(4,0,5,SAND:0)
Block(4,0,6,SAND:0)
Block(4,0,7,SAND:0)
Block(4,1,-5,SAND:0)
Block(4,1,-4,SAND:0)
Block(4,1,-3,SAND:0)
Block(4,1,-2,SAND:0)
Block(4,1,-1,SAND:0)
Block(4,1,0,SAND:0)
Block(4,1,1,SAND:0)
Block(4,1,2,SAND:0)
Block(4,1,3,SAND:0)
Block(4,1,4,WOOD:3)
Block(4,1,5,SAND:0)
Block(4,1,6,SAND:0)
Block(4,2,-1,WOOD:3)
Block(4,2,0,JUNGLE_FENCE:0)
Block(4,2,1,JUNGLE_FENCE:0)
Block(4,2,2,JUNGLE_FENCE:0)
Block(4,2,4,WOOD:3)
Block(4,3,-1,WOOD:3)
Block(4,3,4,WOOD:3)
Block(4,4,-1,WOOD:3)
Block(4,4,0,WOOD:3)
Block(4,4,1,WOOD:3)
Block(4,4,2,WOOD:3)
Block(4,4,3,WOOD:3)
Block(4,4,4,WOOD:3)
Block(4,5,-1,WOOD:3)
Block(4,5,0,STAINED_CLAY:0)
Block(4,5,1,STAINED_CLAY:0)
Block(4,5,2,JUNGLE_FENCE:0)
Block(4,5,3,JUNGLE_FENCE:0)
Block(4,5,4,WOOD:3)
RandomBlock(4,6,-2,WALL_BANNER:2,../../NBT/banners/JungleBanner01.nbt,8,WALL_BANNER:2,../../NBT/banners/JungleBanner02.nbt,8,WALL_BANNER:2,../../NBT/banners/JungleBanner03.nbt,8,WALL_BANNER:2,../../NBT/banners/JungleBanner04.nbt,8,WALL_BANNER:2,../../NBT/banners/JungleBanner05.nbt,8,WALL_BANNER:2,../../NBT/banners/JungleBanner06.nbt,8,WALL_BANNER:2,../../NBT/banners/JungleBanner07.nbt,8,WALL_BANNER:2,../../NBT/banners/JungleBanner08.nbt,8,WALL_BANNER:2,../../NBT/banners/JungleBanner09.nbt,8,WALL_BANNER:2,../../NBT/banners/JungleBanner10.nbt,8,WALL_BANNER:2,../../NBT/banners/JungleBanner11.nbt,8,WALL_BANNER:2,../../NBT/banners/JungleBanner12.nbt,8,WALL_BANNER:2,../../NBT/banners/JungleBanner13.nbt,8,WALL_BANNER:2,../../NBT/banners/JungleBanner14.nbt,8,WALL_BANNER:2,../../NBT/banners/JungleBanner15.nbt,8,WALL_BANNER:2,../../NBT/banners/JungleBanner16.nbt,8,WALL_BANNER:2,../../NBT/banners/JungleBanner17.nbt,8,WALL_BANNER:2,../../NBT/banners/JungleBanner18.nbt,8,WALL_BANNER:2,../../NBT/banners/JungleBanner19.nbt,8,WALL_BANNER:2,../../NBT/banners/JungleBanner20.nbt,100)
Block(4,6,-1,WOOD:3)
Block(4,6,0,STAINED_CLAY:0)
Block(4,6,1,STAINED_CLAY:0)
Block(4,6,4,WOOD:3)
RandomBlock(4,6,5,WALL_BANNER:3,../../NBT/banners/JungleBanner01.nbt,8,WALL_BANNER:3,../../NBT/banners/JungleBanner02.nbt,8,WALL_BANNER:3,../../NBT/banners/JungleBanner03.nbt,8,WALL_BANNER:3,../../NBT/banners/JungleBanner04.nbt,8,WALL_BANNER:3,../../NBT/banners/JungleBanner05.nbt,8,WALL_BANNER:3,../../NBT/banners/JungleBanner06.nbt,8,WALL_BANNER:3,../../NBT/banners/JungleBanner07.nbt,8,WALL_BANNER:3,../../NBT/banners/JungleBanner08.nbt,8,WALL_BANNER:3,../../NBT/banners/JungleBanner09.nbt,8,WALL_BANNER:3,../../NBT/banners/JungleBanner10.nbt,8,WALL_BANNER:3,../../NBT/banners/JungleBanner11.nbt,8,WALL_BANNER:3,../../NBT/banners/JungleBanner12.nbt,8,WALL_BANNER:3,../../NBT/banners/JungleBanner13.nbt,8,WALL_BANNER:3,../../NBT/banners/JungleBanner14.nbt,8,WALL_BANNER:3,../../NBT/banners/JungleBanner15.nbt,8,WALL_BANNER:3,../../NBT/banners/JungleBanner16.nbt,8,WALL_BANNER:3,../../NBT/banners/JungleBanner17.nbt,8,WALL_BANNER:3,../../NBT/banners/JungleBanner18.nbt,8,WALL_BANNER:3,../../NBT/banners/JungleBanner19.nbt,8,WALL_BANNER:3,../../NBT/banners/JungleBanner20.nbt,100)
Block(4,7,-2,WOOD_STEP:3)
Block(4,7,-1,WOOD_STEP:3)
Block(4,7,0,WOOD_STEP:3)
Block(4,7,1,WOOD:3)
Block(4,7,2,WOOD:3)
Block(4,7,3,WOOD_STEP:3)
Block(4,7,4,WOOD_STEP:3)
Block(4,7,5,WOOD_STEP:3)
Block(5,0,-5,SAND:0)
Block(5,0,-4,SAND:0)
Block(5,0,-3,SAND:0)
Block(5,0,-2,SAND:0)
Block(5,0,-1,SAND:0)
Block(5,0,0,SAND:0)
Block(5,0,1,SAND:0)
Block(5,0,2,SAND:0)
Block(5,0,3,SAND:0)
Block(5,0,4,SAND:0)
Block(5,0,5,SAND:0)
Block(5,0,6,SAND:0)
Block(5,0,7,SAND:0)
Block(5,1,-3,SAND:0)
Block(5,1,-2,SAND:0)
Block(5,1,-1,SAND:0)
Block(5,1,0,SAND:0)
Block(5,1,1,SAND:0)
Block(5,1,2,SAND:0)
Block(5,1,3,SAND:0)
Block(5,1,4,SAND:0)
Block(5,1,5,SAND:0)
Block(5,1,6,SAND:0)
RandomBlock(5,6,-1,WALL_BANNER:5,../../NBT/banners/JungleBanner01.nbt,8,WALL_BANNER:5,../../NBT/banners/JungleBanner02.nbt,8,WALL_BANNER:5,../../NBT/banners/JungleBanner03.nbt,8,WALL_BANNER:5,../../NBT/banners/JungleBanner04.nbt,8,WALL_BANNER:5,../../NBT/banners/JungleBanner05.nbt,8,WALL_BANNER:5,../../NBT/banners/JungleBanner06.nbt,8,WALL_BANNER:5,../../NBT/banners/JungleBanner07.nbt,8,WALL_BANNER:5,../../NBT/banners/JungleBanner08.nbt,8,WALL_BANNER:5,../../NBT/banners/JungleBanner09.nbt,8,WALL_BANNER:5,../../NBT/banners/JungleBanner10.nbt,8,WALL_BANNER:5,../../NBT/banners/JungleBanner11.nbt,8,WALL_BANNER:5,../../NBT/banners/JungleBanner12.nbt,8,WALL_BANNER:5,../../NBT/banners/JungleBanner13.nbt,8,WALL_BANNER:5,../../NBT/banners/JungleBanner14.nbt,8,WALL_BANNER:5,../../NBT/banners/JungleBanner15.nbt,8,WALL_BANNER:5,../../NBT/banners/JungleBanner16.nbt,8,WALL_BANNER:5,../../NBT/banners/JungleBanner17.nbt,8,WALL_BANNER:5,../../NBT/banners/JungleBanner18.nbt,8,WALL_BANNER:5,../../NBT/banners/JungleBanner19.nbt,8,WALL_BANNER:5,../../NBT/banners/JungleBanner20.nbt,100)
RandomBlock(5,6,1,WALL_BANNER:5,../../NBT/banners/JungleBanner01.nbt,8,WALL_BANNER:5,../../NBT/banners/JungleBanner02.nbt,8,WALL_BANNER:5,../../NBT/banners/JungleBanner03.nbt,8,WALL_BANNER:5,../../NBT/banners/JungleBanner04.nbt,8,WALL_BANNER:5,../../NBT/banners/JungleBanner05.nbt,8,WALL_BANNER:5,../../NBT/banners/JungleBanner06.nbt,8,WALL_BANNER:5,../../NBT/banners/JungleBanner07.nbt,8,WALL_BANNER:5,../../NBT/banners/JungleBanner08.nbt,8,WALL_BANNER:5,../../NBT/banners/JungleBanner09.nbt,8,WALL_BANNER:5,../../NBT/banners/JungleBanner10.nbt,8,WALL_BANNER:5,../../NBT/banners/JungleBanner11.nbt,8,WALL_BANNER:5,../../NBT/banners/JungleBanner12.nbt,8,WALL_BANNER:5,../../NBT/banners/JungleBanner13.nbt,8,WALL_BANNER:5,../../NBT/banners/JungleBanner14.nbt,8,WALL_BANNER:5,../../NBT/banners/JungleBanner15.nbt,8,WALL_BANNER:5,../../NBT/banners/JungleBanner16.nbt,8,WALL_BANNER:5,../../NBT/banners/JungleBanner17.nbt,8,WALL_BANNER:5,../../NBT/banners/JungleBanner18.nbt,8,WALL_BANNER:5,../../NBT/banners/JungleBanner19.nbt,8,WALL_BANNER:5,../../NBT/banners/JungleBanner20.nbt,100)
Block(5,7,-2,WOOD_STEP:3)
Block(5,7,-1,WOOD_STEP:3)
Block(5,7,0,WOOD_STEP:3)
Block(5,7,1,WOOD_STEP:3)
Block(5,7,2,WOOD_STEP:3)
Block(5,7,3,WOOD_STEP:3)
Block(5,7,4,WOOD_STEP:3)
Block(5,7,5,WOOD_STEP:3)
Block(6,0,-4,SAND:0)
Block(6,0,-3,SAND:0)
Block(6,0,-2,SAND:0)
Block(6,0,-1,SAND:0)
Block(6,0,0,SAND:0)
Block(6,0,1,SAND:0)
Block(6,0,2,SAND:0)
Block(6,0,3,SAND:0)
Block(6,0,4,SAND:0)
Block(6,0,5,SAND:0)
Block(6,0,6,SAND:0)
Block(6,0,7,SAND:0)
Block(6,1,-1,SAND:0)
Block(6,1,2,SAND:0)
Block(6,1,3,SAND:0)
Block(6,1,4,SAND:0)
Block(7,0,-2,SAND:0)
Block(7,0,-1,SAND:0)
Block(7,0,0,SAND:0)
Block(7,0,2,SAND:0)
Block(7,0,3,SAND:0)
Block(7,0,4,SAND:0)
Block(7,0,5,SAND:0)

#######################################################################
# +-----------------------------------------------------------------+ #
# |                            BO3 checks                           | #
# +-----------------------------------------------------------------+ #
#######################################################################

BlockCheck(-6,0,-1,Solid)
BlockCheck(-6,0,4,Solid)
BlockCheck(-4,0,-4,Solid)
BlockCheck(-4,0,6,Solid)
BlockCheck(-3,0,-6,Solid)
BlockCheck(-3,2,1,AIR:0)
BlockCheck(-1,0,8,Solid)
BlockCheck(2,2,-6,AIR:0)
BlockCheck(2,2,6,AIR:0)
BlockCheck(4,0,8,Solid)
BlockCheck(5,2,2,AIR:0)
BlockCheck(6,0,-5,Solid)
BlockCheck(7,0,1,Solid)
BlockCheck(7,0,6,Solid)

#######################################################################
# +-----------------------------------------------------------------+ #
# |                             Branches                            | #
# +-----------------------------------------------------------------+ #
#######################################################################


#######################################################################
# +-----------------------------------------------------------------+ #
# |                             Entities                            | #
# +-----------------------------------------------------------------+ #
#######################################################################

Entity(0,6,2,minecraft:villager,1,../../NBT/entities/tribalbanished.txt)

#######################################################################
# +-----------------------------------------------------------------+ #
# |                            Particles                            | #
# +-----------------------------------------------------------------+ #
#######################################################################


#######################################################################
# +-----------------------------------------------------------------+ #
# |                             Spawners                            | #
# +-----------------------------------------------------------------+ #
#######################################################################


#######################################################################
# +-----------------------------------------------------------------+ #
# |                             ModData                             | #
# +-----------------------------------------------------------------+ #
#######################################################################

