#######################################################################
# +-----------------------------------------------------------------+ #
# |                            BO3 object                           | #
# +-----------------------------------------------------------------+ #
#######################################################################

Author: Bo3 BulkEdit

Description: Converted Schematic - Modified by Bo3BulkEdit

Version: 3

SettingsMode: WriteDisable

#######################################################################
# +-----------------------------------------------------------------+ #
# |                          Main settings                          | #
# +-----------------------------------------------------------------+ #
#######################################################################

IsOTGPlus: true
Tree: false
Frequency: 1
Rarity: 100.0
RotateRandomly: false
SpawnHeight: randomY
MaxBranchDepth: 10
ExcludedBiomes: All

##############################
# Height Limits for the BO3. #
##############################

MinHeight: 0
MaxHeight: 255

#######################################################################
# +-----------------------------------------------------------------+ #
# |                      Source block settings                      | #
# +-----------------------------------------------------------------+ #
#######################################################################

CanOverride: true
MaxPercentageOutsideSourceBlock: 100
OutsideSourceBlock: placeAnyway

#######################################################################
# +-----------------------------------------------------------------+ #
# |                               OTG+                              | #
# +-----------------------------------------------------------------+ #
#######################################################################

BO3Group: CeilingCrystals:0

#######################################################################
# +-----------------------------------------------------------------+ #
# |                              Blocks                             | #
# +-----------------------------------------------------------------+ #
#######################################################################

B(0,750,0,AIR)
B(15,750,15,AIR)
B(15,-10,13,betternether:quartz_stained_glass:15)
B(14,-10,14,betternether:quartz_stained_glass:15)
B(15,-10,14,betternether:quartz_stained_glass:15)
B(13,-10,15,betternether:quartz_stained_glass:15)
B(14,-10,15,betternether:quartz_stained_glass:15)
B(15,-10,15,betternether:quartz_stained_glass:15)
B(14,-9,11,betternether:quartz_stained_glass:15)
B(13,-9,12,betternether:quartz_stained_glass:15)
B(14,-9,12,betternether:quartz_stained_glass:15)
B(15,-9,12,betternether:quartz_stained_glass:15)
B(12,-9,13,betternether:quartz_stained_glass:15)
B(13,-9,13,betternether:quartz_stained_glass:15)
B(14,-9,13,betternether:quartz_stained_glass:15)
B(15,-9,13,betternether:quartz_stained_glass:15)
B(11,-9,14,betternether:quartz_stained_glass:15)
B(12,-9,14,betternether:quartz_stained_glass:15)
B(13,-9,14,betternether:quartz_stained_glass:15)
RB(14,-9,14,srparasites:parasitestain:1,80,quark:crystal:1,30,srparasites:parasiterubbledense:1,100)
B(15,-9,14,betternether:quartz_stained_glass:15)
B(12,-9,15,betternether:quartz_stained_glass:15)
B(13,-9,15,betternether:quartz_stained_glass:15)
B(14,-9,15,betternether:quartz_stained_glass:15)
B(15,-9,15,betternether:quartz_stained_glass:15)
B(12,-8,10,betternether:quartz_stained_glass:15)
B(13,-8,10,betternether:quartz_stained_glass:15)
B(11,-8,11,betternether:quartz_stained_glass:15)
B(12,-8,11,betternether:quartz_stained_glass:15)
B(13,-8,11,betternether:quartz_stained_glass:15)
B(14,-8,11,betternether:quartz_stained_glass:15)
B(10,-8,12,betternether:quartz_stained_glass:15)
B(11,-8,12,betternether:quartz_stained_glass:15)
B(12,-8,12,betternether:quartz_stained_glass:15)
B(13,-8,12,betternether:quartz_stained_glass:15)
B(14,-8,12,betternether:quartz_stained_glass:15)
B(15,-8,12,betternether:quartz_stained_glass:15)
B(10,-8,13,betternether:quartz_stained_glass:15)
B(11,-8,13,betternether:quartz_stained_glass:15)
B(12,-8,13,betternether:quartz_stained_glass:15)
RB(13,-8,13,srparasites:parasitestain:1,80,quark:crystal:1,30,srparasites:parasiterubbledense:1,100)
B(14,-8,13,betternether:quartz_stained_glass:15)
B(15,-8,13,betternether:quartz_stained_glass:15)
B(11,-8,14,betternether:quartz_stained_glass:15)
B(12,-8,14,betternether:quartz_stained_glass:15)
B(13,-8,14,betternether:quartz_stained_glass:15)
RB(14,-8,14,srparasites:parasitestain:1,80,quark:crystal:1,30,srparasites:parasiterubbledense:1,100)
RB(15,-8,14,srparasites:parasitestain:1,80,quark:crystal:1,30,srparasites:parasiterubbledense:1,100)
B(12,-8,15,betternether:quartz_stained_glass:15)
B(13,-8,15,betternether:quartz_stained_glass:15)
B(14,-8,15,betternether:quartz_stained_glass:15)
RB(15,-8,15,srparasites:parasitestain:1,80,quark:crystal:1,30,srparasites:parasiterubbledense:1,100)
B(11,-7,8,betternether:quartz_stained_glass:15)
B(10,-7,9,betternether:quartz_stained_glass:15)
B(11,-7,9,betternether:quartz_stained_glass:15)
B(12,-7,9,betternether:quartz_stained_glass:15)
B(9,-7,10,betternether:quartz_stained_glass:15)
B(10,-7,10,betternether:quartz_stained_glass:15)
B(11,-7,10,betternether:quartz_stained_glass:15)
B(12,-7,10,betternether:quartz_stained_glass:15)
B(13,-7,10,betternether:quartz_stained_glass:15)
B(8,-7,11,betternether:quartz_stained_glass:15)
B(9,-7,11,betternether:quartz_stained_glass:15)
B(10,-7,11,betternether:quartz_stained_glass:15)
RB(11,-7,11,srparasites:parasitestain:1,80,quark:crystal:1,30,srparasites:parasiterubbledense:1,100)
B(12,-7,11,betternether:quartz_stained_glass:15)
B(13,-7,11,betternether:quartz_stained_glass:15)
B(14,-7,11,betternether:quartz_stained_glass:15)
B(9,-7,12,betternether:quartz_stained_glass:15)
B(10,-7,12,betternether:quartz_stained_glass:15)
B(11,-7,12,betternether:quartz_stained_glass:15)
RB(12,-7,12,srparasites:parasitestain:1,80,quark:crystal:1,30,srparasites:parasiterubbledense:1,100)
B(13,-7,12,betternether:quartz_stained_glass:15)
B(14,-7,12,betternether:quartz_stained_glass:15)
B(15,-7,12,betternether:quartz_stained_glass:15)
B(10,-7,13,betternether:quartz_stained_glass:15)
B(11,-7,13,betternether:quartz_stained_glass:15)
B(12,-7,13,betternether:quartz_stained_glass:15)
RB(13,-7,13,srparasites:parasitestain:1,80,quark:crystal:1,30,srparasites:parasiterubbledense:1,100)
RB(14,-7,13,srparasites:parasitestain:1,80,quark:crystal:1,30,srparasites:parasiterubbledense:1,100)
B(15,-7,13,betternether:quartz_stained_glass:15)
B(11,-7,14,betternether:quartz_stained_glass:15)
B(12,-7,14,betternether:quartz_stained_glass:15)
B(13,-7,14,betternether:quartz_stained_glass:15)
RB(14,-7,14,srparasites:parasitestain:1,80,quark:crystal:1,30,srparasites:parasiterubbledense:1,100)
B(15,-7,14,betternether:quartz_stained_glass:15)
B(12,-7,15,betternether:quartz_stained_glass:15)
B(13,-7,15,betternether:quartz_stained_glass:15)
B(14,-7,15,betternether:quartz_stained_glass:15)
B(15,-7,15,betternether:quartz_stained_glass:15)
B(9,-6,7,betternether:quartz_stained_glass:15)
B(10,-6,7,betternether:quartz_stained_glass:15)
B(8,-6,8,betternether:quartz_stained_glass:15)
B(9,-6,8,betternether:quartz_stained_glass:15)
B(10,-6,8,betternether:quartz_stained_glass:15)
B(11,-6,8,betternether:quartz_stained_glass:15)
B(7,-6,9,betternether:quartz_stained_glass:15)
B(8,-6,9,betternether:quartz_stained_glass:15)
B(9,-6,9,betternether:quartz_stained_glass:15)
B(10,-6,9,betternether:quartz_stained_glass:15)
B(11,-6,9,betternether:quartz_stained_glass:15)
B(12,-6,9,betternether:quartz_stained_glass:15)
B(7,-6,10,betternether:quartz_stained_glass:15)
B(8,-6,10,betternether:quartz_stained_glass:15)
B(9,-6,10,betternether:quartz_stained_glass:15)
RB(10,-6,10,srparasites:parasitestain:1,80,quark:crystal:1,30,srparasites:parasiterubbledense:1,100)
B(11,-6,10,betternether:quartz_stained_glass:15)
B(12,-6,10,betternether:quartz_stained_glass:15)
B(13,-6,10,betternether:quartz_stained_glass:15)
B(8,-6,11,betternether:quartz_stained_glass:15)
B(9,-6,11,betternether:quartz_stained_glass:15)
B(10,-6,11,betternether:quartz_stained_glass:15)
RB(11,-6,11,srparasites:parasitestain:1,80,quark:crystal:1,30,srparasites:parasiterubbledense:1,100)
RB(12,-6,11,srparasites:parasitestain:1,80,quark:crystal:1,30,srparasites:parasiterubbledense:1,100)
B(13,-6,11,betternether:quartz_stained_glass:15)
B(14,-6,11,betternether:quartz_stained_glass:15)
B(9,-6,12,betternether:quartz_stained_glass:15)
B(10,-6,12,betternether:quartz_stained_glass:15)
B(11,-6,12,betternether:quartz_stained_glass:15)
B(12,-6,12,betternether:quartz_stained_glass:15)
B(13,-6,12,betternether:quartz_stained_glass:15)
B(14,-6,12,betternether:quartz_stained_glass:15)
B(15,-6,12,betternether:quartz_stained_glass:15)
B(10,-6,13,betternether:quartz_stained_glass:15)
B(11,-6,13,betternether:quartz_stained_glass:15)
B(12,-6,13,betternether:quartz_stained_glass:15)
B(13,-6,13,betternether:quartz_stained_glass:15)
B(14,-6,13,betternether:quartz_stained_glass:15)
B(15,-6,13,betternether:quartz_stained_glass:15)
B(11,-6,14,betternether:quartz_stained_glass:15)
B(12,-6,14,betternether:quartz_stained_glass:15)
B(13,-6,14,betternether:quartz_stained_glass:15)
B(14,-6,14,betternether:quartz_stained_glass:15)
B(15,-6,14,betternether:quartz_stained_glass:15)
B(12,-6,15,betternether:quartz_stained_glass:15)
B(13,-6,15,betternether:quartz_stained_glass:15)
B(14,-6,15,betternether:quartz_stained_glass:15)
B(15,-6,15,betternether:quartz_stained_glass:15)
B(8,-5,5,betternether:quartz_stained_glass:15)
B(7,-5,6,betternether:quartz_stained_glass:15)
B(8,-5,6,betternether:quartz_stained_glass:15)
B(9,-5,6,betternether:quartz_stained_glass:15)
B(6,-5,7,betternether:quartz_stained_glass:15)
B(7,-5,7,betternether:quartz_stained_glass:15)
B(8,-5,7,betternether:quartz_stained_glass:15)
B(9,-5,7,betternether:quartz_stained_glass:15)
B(10,-5,7,betternether:quartz_stained_glass:15)
B(5,-5,8,betternether:quartz_stained_glass:15)
B(6,-5,8,betternether:quartz_stained_glass:15)
B(7,-5,8,betternether:quartz_stained_glass:15)
B(8,-5,8,betternether:quartz_stained_glass:15)
RB(9,-5,8,srparasites:parasitestain:1,80,quark:crystal:1,30,srparasites:parasiterubbledense:1,100)
B(10,-5,8,betternether:quartz_stained_glass:15)
B(11,-5,8,betternether:quartz_stained_glass:15)
B(6,-5,9,betternether:quartz_stained_glass:15)
B(7,-5,9,betternether:quartz_stained_glass:15)
B(8,-5,9,betternether:quartz_stained_glass:15)
RB(9,-5,9,srparasites:parasitestain:1,80,quark:crystal:1,30,srparasites:parasiterubbledense:1,100)
B(10,-5,9,betternether:quartz_stained_glass:15)
B(11,-5,9,betternether:quartz_stained_glass:15)
B(12,-5,9,betternether:quartz_stained_glass:15)
B(7,-5,10,betternether:quartz_stained_glass:15)
B(8,-5,10,betternether:quartz_stained_glass:15)
B(9,-5,10,betternether:quartz_stained_glass:15)
RB(10,-5,10,srparasites:parasitestain:1,80,quark:crystal:1,30,srparasites:parasiterubbledense:1,100)
RB(11,-5,10,srparasites:parasitestain:1,80,quark:crystal:1,30,srparasites:parasiterubbledense:1,100)
B(12,-5,10,betternether:quartz_stained_glass:15)
B(13,-5,10,betternether:quartz_stained_glass:15)
B(8,-5,11,betternether:quartz_stained_glass:15)
B(9,-5,11,betternether:quartz_stained_glass:15)
B(10,-5,11,betternether:quartz_stained_glass:15)
RB(11,-5,11,srparasites:parasitestain:1,80,quark:crystal:1,30,srparasites:parasiterubbledense:1,100)
B(12,-5,11,betternether:quartz_stained_glass:15)
B(13,-5,11,betternether:quartz_stained_glass:15)
B(14,-5,11,betternether:quartz_stained_glass:15)
B(9,-5,12,betternether:quartz_stained_glass:15)
B(10,-5,12,betternether:quartz_stained_glass:15)
B(11,-5,12,betternether:quartz_stained_glass:15)
RB(12,-5,12,srparasites:parasitestain:1,80,quark:crystal:1,30,srparasites:parasiterubbledense:1,100)
B(13,-5,12,betternether:quartz_stained_glass:15)
B(14,-5,12,betternether:quartz_stained_glass:15)
B(15,-5,12,betternether:quartz_stained_glass:15)
B(10,-5,13,betternether:quartz_stained_glass:15)
B(11,-5,13,betternether:quartz_stained_glass:15)
B(12,-5,13,betternether:quartz_stained_glass:15)
B(13,-5,13,betternether:quartz_stained_glass:15)
B(14,-5,13,betternether:quartz_stained_glass:15)
B(15,-5,13,betternether:quartz_stained_glass:15)
B(11,-5,14,betternether:quartz_stained_glass:15)
B(12,-5,14,betternether:quartz_stained_glass:15)
B(13,-5,14,betternether:quartz_stained_glass:15)
B(14,-5,14,betternether:quartz_stained_glass:15)
B(15,-5,14,betternether:quartz_stained_glass:15)
B(12,-5,15,betternether:quartz_stained_glass:15)
B(13,-5,15,betternether:quartz_stained_glass:15)
B(14,-5,15,betternether:quartz_stained_glass:15)
B(6,-4,4,betternether:quartz_stained_glass:15)
B(7,-4,4,betternether:quartz_stained_glass:15)
B(5,-4,5,betternether:quartz_stained_glass:15)
B(6,-4,5,betternether:quartz_stained_glass:15)
B(7,-4,5,betternether:quartz_stained_glass:15)
B(8,-4,5,betternether:quartz_stained_glass:15)
B(4,-4,6,betternether:quartz_stained_glass:15)
B(5,-4,6,betternether:quartz_stained_glass:15)
B(6,-4,6,betternether:quartz_stained_glass:15)
RB(7,-4,6,srparasites:parasitestain:1,80,quark:crystal:1,30,srparasites:parasiterubbledense:1,100)
B(8,-4,6,betternether:quartz_stained_glass:15)
B(9,-4,6,betternether:quartz_stained_glass:15)
B(4,-4,7,betternether:quartz_stained_glass:15)
B(5,-4,7,betternether:quartz_stained_glass:15)
B(6,-4,7,betternether:quartz_stained_glass:15)
RB(7,-4,7,srparasites:parasitestain:1,80,quark:crystal:1,30,srparasites:parasiterubbledense:1,100)
B(8,-4,7,betternether:quartz_stained_glass:15)
B(9,-4,7,betternether:quartz_stained_glass:15)
B(10,-4,7,betternether:quartz_stained_glass:15)
B(5,-4,8,betternether:quartz_stained_glass:15)
B(6,-4,8,betternether:quartz_stained_glass:15)
B(7,-4,8,betternether:quartz_stained_glass:15)
RB(8,-4,8,srparasites:parasitestain:1,80,quark:crystal:1,30,srparasites:parasiterubbledense:1,100)
RB(9,-4,8,srparasites:parasitestain:1,80,quark:crystal:1,30,srparasites:parasiterubbledense:1,100)
B(10,-4,8,betternether:quartz_stained_glass:15)
B(11,-4,8,betternether:quartz_stained_glass:15)
B(6,-4,9,betternether:quartz_stained_glass:15)
B(7,-4,9,betternether:quartz_stained_glass:15)
B(8,-4,9,betternether:quartz_stained_glass:15)
RB(9,-4,9,srparasites:parasitestain:1,80,quark:crystal:1,30,srparasites:parasiterubbledense:1,100)
RB(10,-4,9,srparasites:parasitestain:1,80,quark:crystal:1,30,srparasites:parasiterubbledense:1,100)
B(11,-4,9,betternether:quartz_stained_glass:15)
B(12,-4,9,betternether:quartz_stained_glass:15)
B(7,-4,10,betternether:quartz_stained_glass:15)
B(8,-4,10,betternether:quartz_stained_glass:15)
B(9,-4,10,betternether:quartz_stained_glass:15)
B(10,-4,10,betternether:quartz_stained_glass:15)
B(11,-4,10,betternether:quartz_stained_glass:15)
B(12,-4,10,betternether:quartz_stained_glass:15)
B(13,-4,10,betternether:quartz_stained_glass:15)
B(8,-4,11,betternether:quartz_stained_glass:15)
B(9,-4,11,betternether:quartz_stained_glass:15)
B(10,-4,11,betternether:quartz_stained_glass:15)
B(11,-4,11,betternether:quartz_stained_glass:15)
B(12,-4,11,betternether:quartz_stained_glass:15)
B(13,-4,11,betternether:quartz_stained_glass:15)
B(14,-4,11,betternether:quartz_stained_glass:15)
B(9,-4,12,betternether:quartz_stained_glass:15)
B(10,-4,12,betternether:quartz_stained_glass:15)
B(11,-4,12,betternether:quartz_stained_glass:15)
B(12,-4,12,betternether:quartz_stained_glass:15)
B(13,-4,12,betternether:quartz_stained_glass:15)
B(14,-4,12,betternether:quartz_stained_glass:15)
B(10,-4,13,betternether:quartz_stained_glass:15)
B(11,-4,13,betternether:quartz_stained_glass:15)
B(12,-4,13,betternether:quartz_stained_glass:15)
B(13,-4,13,betternether:quartz_stained_glass:15)
B(11,-4,14,betternether:quartz_stained_glass:15)
B(12,-4,14,betternether:quartz_stained_glass:15)
B(5,-3,2,betternether:quartz_stained_glass:15)
B(4,-3,3,betternether:quartz_stained_glass:15)
B(5,-3,3,betternether:quartz_stained_glass:15)
B(6,-3,3,betternether:quartz_stained_glass:15)
B(3,-3,4,betternether:quartz_stained_glass:15)
B(4,-3,4,betternether:quartz_stained_glass:15)
B(5,-3,4,betternether:quartz_stained_glass:15)
B(6,-3,4,betternether:quartz_stained_glass:15)
B(7,-3,4,betternether:quartz_stained_glass:15)
B(2,-3,5,betternether:quartz_stained_glass:15)
B(3,-3,5,betternether:quartz_stained_glass:15)
B(4,-3,5,betternether:quartz_stained_glass:15)
RB(5,-3,5,srparasites:parasitestain:1,80,quark:crystal:1,30,srparasites:parasiterubbledense:1,100)
RB(6,-3,5,srparasites:parasitestain:1,80,quark:crystal:1,30,srparasites:parasiterubbledense:1,100)
B(7,-3,5,betternether:quartz_stained_glass:15)
B(8,-3,5,betternether:quartz_stained_glass:15)
B(3,-3,6,betternether:quartz_stained_glass:15)
B(4,-3,6,betternether:quartz_stained_glass:15)
B(5,-3,6,betternether:quartz_stained_glass:15)
RB(6,-3,6,srparasites:parasitestain:1,80,quark:crystal:1,30,srparasites:parasiterubbledense:1,100)
B(7,-3,6,betternether:quartz_stained_glass:15)
B(8,-3,6,betternether:quartz_stained_glass:15)
B(9,-3,6,betternether:quartz_stained_glass:15)
B(4,-3,7,betternether:quartz_stained_glass:15)
B(5,-3,7,betternether:quartz_stained_glass:15)
B(6,-3,7,betternether:quartz_stained_glass:15)
RB(7,-3,7,srparasites:parasitestain:1,80,quark:crystal:1,30,srparasites:parasiterubbledense:1,100)
RB(8,-3,7,srparasites:parasitestain:1,80,quark:crystal:1,30,srparasites:parasiterubbledense:1,100)
B(9,-3,7,betternether:quartz_stained_glass:15)
B(10,-3,7,betternether:quartz_stained_glass:15)
B(5,-3,8,betternether:quartz_stained_glass:15)
B(6,-3,8,betternether:quartz_stained_glass:15)
B(7,-3,8,betternether:quartz_stained_glass:15)
RB(8,-3,8,srparasites:parasitestain:1,80,quark:crystal:1,30,srparasites:parasiterubbledense:1,100)
RB(9,-3,8,srparasites:parasitestain:1,80,quark:crystal:1,30,srparasites:parasiterubbledense:1,100)
B(10,-3,8,betternether:quartz_stained_glass:15)
B(11,-3,8,betternether:quartz_stained_glass:15)
B(6,-3,9,betternether:quartz_stained_glass:15)
B(7,-3,9,betternether:quartz_stained_glass:15)
B(8,-3,9,betternether:quartz_stained_glass:15)
B(9,-3,9,betternether:quartz_stained_glass:15)
B(10,-3,9,betternether:quartz_stained_glass:15)
B(11,-3,9,betternether:quartz_stained_glass:15)
B(12,-3,9,betternether:quartz_stained_glass:15)
B(7,-3,10,betternether:quartz_stained_glass:15)
B(8,-3,10,betternether:quartz_stained_glass:15)
B(9,-3,10,betternether:quartz_stained_glass:15)
B(10,-3,10,betternether:quartz_stained_glass:15)
B(11,-3,10,betternether:quartz_stained_glass:15)
B(12,-3,10,betternether:quartz_stained_glass:15)
B(13,-3,10,betternether:quartz_stained_glass:15)
B(8,-3,11,betternether:quartz_stained_glass:15)
B(9,-3,11,betternether:quartz_stained_glass:15)
B(10,-3,11,betternether:quartz_stained_glass:15)
B(11,-3,11,betternether:quartz_stained_glass:15)
B(12,-3,11,betternether:quartz_stained_glass:15)
B(9,-3,12,betternether:quartz_stained_glass:15)
B(10,-3,12,betternether:quartz_stained_glass:15)
B(11,-3,12,betternether:quartz_stained_glass:15)
B(10,-3,13,betternether:quartz_stained_glass:15)
B(4,-2,1,betternether:quartz_stained_glass:15)
B(3,-2,2,betternether:quartz_stained_glass:15)
B(4,-2,2,betternether:quartz_stained_glass:15)
B(5,-2,2,betternether:quartz_stained_glass:15)
B(2,-2,3,betternether:quartz_stained_glass:15)
B(3,-2,3,betternether:quartz_stained_glass:15)
RB(4,-2,3,srparasites:parasitestain:1,80,quark:crystal:1,30,srparasites:parasiterubbledense:1,100)
B(5,-2,3,betternether:quartz_stained_glass:15)
B(6,-2,3,betternether:quartz_stained_glass:15)
B(1,-2,4,betternether:quartz_stained_glass:15)
B(2,-2,4,betternether:quartz_stained_glass:15)
B(3,-2,4,betternether:quartz_stained_glass:15)
RB(4,-2,4,srparasites:parasitestain:1,80,quark:crystal:1,30,srparasites:parasiterubbledense:1,100)
B(5,-2,4,betternether:quartz_stained_glass:15)
B(6,-2,4,betternether:quartz_stained_glass:15)
B(7,-2,4,betternether:quartz_stained_glass:15)
B(2,-2,5,betternether:quartz_stained_glass:15)
B(3,-2,5,betternether:quartz_stained_glass:15)
B(4,-2,5,betternether:quartz_stained_glass:15)
RB(5,-2,5,srparasites:parasitestain:1,80,quark:crystal:1,30,srparasites:parasiterubbledense:1,100)
RB(6,-2,5,srparasites:parasitestain:1,80,quark:crystal:1,30,srparasites:parasiterubbledense:1,100)
B(7,-2,5,betternether:quartz_stained_glass:15)
B(8,-2,5,betternether:quartz_stained_glass:15)
B(3,-2,6,betternether:quartz_stained_glass:15)
B(4,-2,6,betternether:quartz_stained_glass:15)
B(5,-2,6,betternether:quartz_stained_glass:15)
RB(6,-2,6,srparasites:parasitestain:1,80,quark:crystal:1,30,srparasites:parasiterubbledense:1,100)
RB(7,-2,6,srparasites:parasitestain:1,80,quark:crystal:1,30,srparasites:parasiterubbledense:1,100)
B(8,-2,6,betternether:quartz_stained_glass:15)
B(9,-2,6,betternether:quartz_stained_glass:15)
B(4,-2,7,betternether:quartz_stained_glass:15)
B(5,-2,7,betternether:quartz_stained_glass:15)
B(6,-2,7,betternether:quartz_stained_glass:15)
RB(7,-2,7,srparasites:parasitestain:1,80,quark:crystal:1,30,srparasites:parasiterubbledense:1,100)
RB(8,-2,7,srparasites:parasitestain:1,80,quark:crystal:1,30,srparasites:parasiterubbledense:1,100)
B(9,-2,7,betternether:quartz_stained_glass:15)
B(10,-2,7,betternether:quartz_stained_glass:15)
B(5,-2,8,betternether:quartz_stained_glass:15)
B(6,-2,8,betternether:quartz_stained_glass:15)
B(7,-2,8,betternether:quartz_stained_glass:15)
B(8,-2,8,betternether:quartz_stained_glass:15)
B(9,-2,8,betternether:quartz_stained_glass:15)
B(10,-2,8,betternether:quartz_stained_glass:15)
B(11,-2,8,betternether:quartz_stained_glass:15)
B(6,-2,9,betternether:quartz_stained_glass:15)
B(7,-2,9,betternether:quartz_stained_glass:15)
B(8,-2,9,betternether:quartz_stained_glass:15)
B(9,-2,9,betternether:quartz_stained_glass:15)
B(10,-2,9,betternether:quartz_stained_glass:15)
B(11,-2,9,betternether:quartz_stained_glass:15)
B(7,-2,10,betternether:quartz_stained_glass:15)
B(8,-2,10,betternether:quartz_stained_glass:15)
B(9,-2,10,betternether:quartz_stained_glass:15)
B(10,-2,10,betternether:quartz_stained_glass:15)
B(8,-2,11,betternether:quartz_stained_glass:15)
B(9,-2,11,betternether:quartz_stained_glass:15)
B(3,-1,1,betternether:quartz_stained_glass:15)
B(4,-1,1,betternether:quartz_stained_glass:15)
B(2,-1,2,betternether:quartz_stained_glass:15)
B(3,-1,2,betternether:quartz_stained_glass:15)
B(4,-1,2,betternether:quartz_stained_glass:15)
B(5,-1,2,betternether:quartz_stained_glass:15)
B(1,-1,3,betternether:quartz_stained_glass:15)
B(2,-1,3,betternether:quartz_stained_glass:15)
RB(3,-1,3,srparasites:parasitestain:1,80,quark:crystal:1,30,srparasites:parasiterubbledense:1,100)
B(4,-1,3,betternether:quartz_stained_glass:15)
B(5,-1,3,betternether:quartz_stained_glass:15)
B(6,-1,3,betternether:quartz_stained_glass:15)
B(1,-1,4,betternether:quartz_stained_glass:15)
B(2,-1,4,betternether:quartz_stained_glass:15)
RB(3,-1,4,srparasites:parasitestain:1,80,quark:crystal:1,30,srparasites:parasiterubbledense:1,100)
RB(4,-1,4,srparasites:parasitestain:1,80,quark:crystal:1,30,srparasites:parasiterubbledense:1,100)
RB(5,-1,4,srparasites:parasitestain:1,80,quark:crystal:1,30,srparasites:parasiterubbledense:1,100)
B(6,-1,4,betternether:quartz_stained_glass:15)
B(7,-1,4,betternether:quartz_stained_glass:15)
B(2,-1,5,betternether:quartz_stained_glass:15)
B(3,-1,5,betternether:quartz_stained_glass:15)
B(4,-1,5,betternether:quartz_stained_glass:15)
B(5,-1,5,betternether:quartz_stained_glass:15)
RB(6,-1,5,srparasites:parasitestain:1,80,quark:crystal:1,30,srparasites:parasiterubbledense:1,100)
B(7,-1,5,betternether:quartz_stained_glass:15)
B(8,-1,5,betternether:quartz_stained_glass:15)
B(3,-1,6,betternether:quartz_stained_glass:15)
B(4,-1,6,betternether:quartz_stained_glass:15)
B(5,-1,6,betternether:quartz_stained_glass:15)
B(6,-1,6,betternether:quartz_stained_glass:15)
B(7,-1,6,betternether:quartz_stained_glass:15)
B(8,-1,6,betternether:quartz_stained_glass:15)
B(9,-1,6,betternether:quartz_stained_glass:15)
B(4,-1,7,betternether:quartz_stained_glass:15)
B(5,-1,7,betternether:quartz_stained_glass:15)
B(6,-1,7,betternether:quartz_stained_glass:15)
B(7,-1,7,betternether:quartz_stained_glass:15)
B(8,-1,7,betternether:quartz_stained_glass:15)
B(9,-1,7,betternether:quartz_stained_glass:15)
B(10,-1,7,betternether:quartz_stained_glass:15)
B(5,-1,8,betternether:quartz_stained_glass:15)
B(6,-1,8,betternether:quartz_stained_glass:15)
B(7,-1,8,betternether:quartz_stained_glass:15)
B(8,-1,8,betternether:quartz_stained_glass:15)
B(9,-1,8,betternether:quartz_stained_glass:15)
B(6,-1,9,betternether:quartz_stained_glass:15)
B(7,-1,9,betternether:quartz_stained_glass:15)
B(8,-1,9,betternether:quartz_stained_glass:15)
B(7,-1,10,betternether:quartz_stained_glass:15)
B(1,0,1,betternether:quartz_stained_glass:15)
B(2,0,1,betternether:quartz_stained_glass:15)
B(3,0,1,betternether:quartz_stained_glass:15)
B(1,0,2,betternether:quartz_stained_glass:15)
RB(2,0,2,srparasites:parasitestain:1,80,quark:crystal:1,30,srparasites:parasiterubbledense:1,100)
B(3,0,2,betternether:quartz_stained_glass:15)
B(4,0,2,betternether:quartz_stained_glass:15)
B(5,0,2,betternether:quartz_stained_glass:15)
B(1,0,3,betternether:quartz_stained_glass:15)
B(2,0,3,betternether:quartz_stained_glass:15)
B(4,0,3,betternether:quartz_stained_glass:15)
B(5,0,3,betternether:quartz_stained_glass:15)
B(6,0,3,betternether:quartz_stained_glass:15)
B(2,0,4,betternether:quartz_stained_glass:15)
RB(3,0,4,srparasites:parasitestain:1,80,quark:crystal:1,30,srparasites:parasiterubbledense:1,100)
B(4,0,4,betternether:quartz_stained_glass:15)
B(5,0,4,betternether:quartz_stained_glass:15)
B(6,0,4,betternether:quartz_stained_glass:15)
B(7,0,4,betternether:quartz_stained_glass:15)
B(2,0,5,betternether:quartz_stained_glass:15)
B(3,0,5,betternether:quartz_stained_glass:15)
B(4,0,5,betternether:quartz_stained_glass:15)
B(5,0,5,betternether:quartz_stained_glass:15)
B(6,0,5,betternether:quartz_stained_glass:15)
B(7,0,5,betternether:quartz_stained_glass:15)
B(8,0,5,betternether:quartz_stained_glass:15)
B(3,0,6,betternether:quartz_stained_glass:15)
B(4,0,6,betternether:quartz_stained_glass:15)
B(5,0,6,betternether:quartz_stained_glass:15)
B(6,0,6,betternether:quartz_stained_glass:15)
B(7,0,6,betternether:quartz_stained_glass:15)
B(8,0,6,betternether:quartz_stained_glass:15)
B(4,0,7,betternether:quartz_stained_glass:15)
B(5,0,7,betternether:quartz_stained_glass:15)
B(6,0,7,betternether:quartz_stained_glass:15)
B(7,0,7,betternether:quartz_stained_glass:15)
B(5,0,8,betternether:quartz_stained_glass:15)
B(6,0,8,betternether:quartz_stained_glass:15)
B(1,1,0,betternether:quartz_stained_glass:15)
B(2,1,0,betternether:quartz_stained_glass:15)
B(0,1,1,betternether:quartz_stained_glass:15)
B(1,1,1,betternether:quartz_stained_glass:15)
B(2,1,1,betternether:quartz_stained_glass:15)
B(3,1,1,betternether:quartz_stained_glass:15)
B(0,1,2,betternether:quartz_stained_glass:15)
B(1,1,2,betternether:quartz_stained_glass:15)
RB(2,1,2,srparasites:parasitestain:1,80,quark:crystal:1,30,srparasites:parasiterubbledense:1,100)
B(3,1,2,betternether:quartz_stained_glass:15)
B(4,1,2,betternether:quartz_stained_glass:15)
B(5,1,2,betternether:quartz_stained_glass:15)
B(1,1,3,betternether:quartz_stained_glass:15)
B(2,1,3,betternether:quartz_stained_glass:15)
B(3,1,3,betternether:quartz_stained_glass:15)
B(4,1,3,betternether:quartz_stained_glass:15)
B(5,1,3,betternether:quartz_stained_glass:15)
B(6,1,3,betternether:quartz_stained_glass:15)
B(2,1,4,betternether:quartz_stained_glass:15)
B(3,1,4,betternether:quartz_stained_glass:15)
B(4,1,4,betternether:quartz_stained_glass:15)
B(5,1,4,betternether:quartz_stained_glass:15)
B(6,1,4,betternether:quartz_stained_glass:15)
B(2,1,5,betternether:quartz_stained_glass:15)
B(3,1,5,betternether:quartz_stained_glass:15)
B(4,1,5,betternether:quartz_stained_glass:15)
B(5,1,5,betternether:quartz_stained_glass:15)
B(3,1,6,betternether:quartz_stained_glass:15)
B(4,1,6,betternether:quartz_stained_glass:15)
B(0,2,0,betternether:quartz_stained_glass:15)
B(1,2,0,betternether:quartz_stained_glass:15)
B(0,2,1,betternether:quartz_stained_glass:15)
B(1,2,1,betternether:quartz_stained_glass:15)
B(2,2,1,betternether:quartz_stained_glass:15)
B(1,2,2,betternether:quartz_stained_glass:15)
B(2,2,2,betternether:quartz_stained_glass:15)
B(3,2,2,betternether:quartz_stained_glass:15)
B(2,2,3,betternether:quartz_stained_glass:15)
B(3,2,3,betternether:quartz_stained_glass:15)
B(4,2,3,betternether:quartz_stained_glass:15)
B(3,2,4,betternether:quartz_stained_glass:15)
B(0,3,0,betternether:quartz_stained_glass:15)
B(1,3,1,betternether:quartz_stained_glass:15)

#######################################################################
# +-----------------------------------------------------------------+ #
# |                             Branches                            | #
# +-----------------------------------------------------------------+ #
#######################################################################

BR(0,0,16,true,CEILING_SPIKE-DIAG-SMALL-01_0x1,NORTH,100,0)
BR(16,0,0,true,CEILING_SPIKE-DIAG-SMALL-01_1x0,NORTH,100,0)
