
#######################################################################
# +-----------------------------------------------------------------+ #
# |                            BO4 object                           | #
# +-----------------------------------------------------------------+ #
#######################################################################

Author: NLBlackEagle

Description: No description given

SettingsMode: WriteDisable


#######################################################################
# +-----------------------------------------------------------------+ #
# |                          Main settings                          | #
# +-----------------------------------------------------------------+ #
#######################################################################

Frequency: 0

SpawnHeight: highestBlock

UseCenterForHighestBlock: true

##############################
# Height Limits for the BO4. #
##############################

MinHeight: 0

MaxHeight: 255

InheritBO3: 

InheritBO3Rotation: NORTH

OverrideChildSettings: true

OverrideParentHeight: false

CanOverride: true

BranchFrequency: 0

BranchFrequencyGroup: 

MustBeBelowOther: false

MustBeInside: 

CannotBeInside: 

ReplacesBO3: 

MustBeInsideWorldBorders: false

CanSpawnOnWater: true

SpawnOnWaterOnly: false

SpawnUnderWater: false

SpawnAtWaterLevel: false

HeightOffset: 0

RemoveAir: true

ReplaceAbove: 

ReplaceBelow: 

ReplaceWithBiomeBlocks: true

ReplaceWithSurfaceBlock: GRASS

ReplaceWithGroundBlock: DIRT

ReplaceWithStoneBlock: STONE

SmoothRadius: 0

SmoothHeightOffset: 0

SmoothStartTop: false

SmoothStartWood: false

SmoothingSurfaceBlock: 

SmoothingGroundBlock: 

BO3Group: 

IsSpawnPoint: false

DoReplaceBlocks: true


#######################################################################
# +-----------------------------------------------------------------+ #
# |                              Blocks                             | #
# +-----------------------------------------------------------------+ #
#######################################################################

Block(-8,0,-7,SANDSTONE)
Block(-8,0,-6,SANDSTONE)
Block(-8,0,-5,SANDSTONE)
Block(-8,0,-4,SANDSTONE)
Block(-8,0,-3,SANDSTONE)
Block(-8,0,-2,SANDSTONE)
Block(-8,0,-1,SANDSTONE)
Block(-8,0,0,SANDSTONE)
Block(-8,0,1,SANDSTONE)
Block(-8,0,2,SANDSTONE)
Block(-8,0,3,OBSIDIAN)
Block(-7,0,-7,SANDSTONE)
Block(-7,0,-6,SANDSTONE)
Block(-7,0,-5,SANDSTONE)
Block(-7,0,-4,SANDSTONE)
Block(-7,0,-3,SANDSTONE)
Block(-7,0,-2,SANDSTONE)
Block(-7,0,-1,SANDSTONE)
Block(-7,0,0,SANDSTONE)
Block(-7,0,1,SANDSTONE)
Block(-7,0,2,SANDSTONE)
Block(-7,0,3,OBSIDIAN)
Block(-7,1,-7,SANDSTONE)
Block(-7,1,-6,SANDSTONE)
Block(-7,1,-5,SANDSTONE)
Block(-7,1,-4,SANDSTONE)
Block(-7,1,-3,SANDSTONE)
Block(-7,1,-2,SANDSTONE)
Block(-7,1,-1,SANDSTONE)
Block(-7,1,0,SANDSTONE)
Block(-7,2,-7,SANDSTONE)
Block(-7,2,-6,SANDSTONE)
Block(-7,2,-5,SANDSTONE)
Block(-7,2,-4,SANDSTONE)
Block(-7,2,-3,SANDSTONE)
Block(-7,2,-2,SANDSTONE)
Block(-6,0,-7,SANDSTONE)
Block(-6,0,-6,SANDSTONE)
Block(-6,0,-5,SANDSTONE)
Block(-6,0,-4,SANDSTONE)
Block(-6,0,-3,SANDSTONE)
Block(-6,0,-2,SANDSTONE)
Block(-6,0,-1,SANDSTONE)
Block(-6,0,0,SANDSTONE)
Block(-6,0,1,SANDSTONE)
Block(-6,0,2,SANDSTONE)
Block(-6,0,3,SANDSTONE)
Block(-6,1,-7,SANDSTONE)
Block(-6,1,-6,SANDSTONE)
Block(-6,1,-5,SANDSTONE)
Block(-6,1,-4,SANDSTONE)
Block(-6,1,-3,SANDSTONE)
Block(-6,1,-2,SANDSTONE)
Block(-6,1,-1,SANDSTONE)
Block(-6,1,0,SANDSTONE)
Block(-6,2,-7,SANDSTONE)
Block(-6,2,-6,SANDSTONE)
Block(-6,2,-5,SANDSTONE)
Block(-6,2,-4,SANDSTONE)
Block(-6,2,-3,SANDSTONE)
Block(-6,2,-2,SANDSTONE)
Block(-6,3,-7,SANDSTONE)
Block(-6,3,-6,SANDSTONE)
Block(-6,3,-5,SANDSTONE)
Block(-6,3,-4,SANDSTONE)
Block(-6,4,-7,SANDSTONE)
Block(-5,0,-7,SANDSTONE)
Block(-5,0,-6,SANDSTONE)
Block(-5,0,-5,SANDSTONE)
Block(-5,0,-4,SANDSTONE)
Block(-5,0,-3,SANDSTONE)
Block(-5,0,-2,SANDSTONE)
Block(-5,0,-1,SANDSTONE)
Block(-5,0,0,SANDSTONE)
Block(-5,0,1,SANDSTONE)
Block(-5,0,2,SANDSTONE)
Block(-5,0,3,SANDSTONE)
Block(-5,1,-7,SANDSTONE)
Block(-5,1,-6,SANDSTONE)
Block(-5,1,-5,SANDSTONE)
Block(-5,1,-4,SANDSTONE)
Block(-5,1,-3,SANDSTONE)
Block(-5,1,-2,SANDSTONE)
Block(-5,1,-1,SANDSTONE)
Block(-5,1,0,SANDSTONE)
Block(-5,1,1,SANDSTONE)
Block(-5,2,-7,SANDSTONE)
Block(-5,2,-6,SANDSTONE)
Block(-5,2,-5,SANDSTONE)
Block(-5,2,-4,SANDSTONE)
Block(-5,2,-3,SANDSTONE)
Block(-5,2,-2,SANDSTONE)
Block(-5,3,-7,SANDSTONE)
Block(-5,3,-6,SANDSTONE)
Block(-5,3,-5,SANDSTONE)
Block(-5,3,-4,SANDSTONE)
Block(-5,4,-7,SANDSTONE)
Block(-4,0,-7,SANDSTONE)
Block(-4,0,-6,SANDSTONE)
Block(-4,0,-5,SANDSTONE)
Block(-4,0,-4,SANDSTONE)
Block(-4,0,-3,SANDSTONE)
Block(-4,0,-2,SANDSTONE)
Block(-4,0,-1,SANDSTONE)
Block(-4,0,0,SANDSTONE)
Block(-4,0,1,SANDSTONE)
Block(-4,0,2,SANDSTONE)
Block(-4,0,3,SANDSTONE)
Block(-4,1,-7,SANDSTONE)
Block(-4,1,-6,SANDSTONE)
Block(-4,1,-5,SANDSTONE)
Block(-4,1,-4,SANDSTONE)
Block(-4,1,-3,SANDSTONE)
Block(-4,1,-2,SANDSTONE)
Block(-4,1,-1,SANDSTONE)
Block(-4,1,0,SANDSTONE)
Block(-4,1,1,SANDSTONE)
Block(-4,2,-7,SANDSTONE)
Block(-4,2,-6,SANDSTONE)
Block(-4,2,-5,SANDSTONE)
Block(-4,2,-4,SANDSTONE)
Block(-4,2,-3,SANDSTONE)
Block(-4,2,-2,SANDSTONE)
Block(-4,3,-7,SANDSTONE)
Block(-4,3,-6,SANDSTONE)
Block(-4,3,-5,SANDSTONE)
Block(-4,3,-4,SANDSTONE)
Block(-4,4,-7,SANDSTONE)
Block(-4,4,-6,SANDSTONE)
Block(-3,0,-7,SANDSTONE)
Block(-3,0,-6,SANDSTONE)
Block(-3,0,-5,SANDSTONE)
Block(-3,0,-4,SANDSTONE)
Block(-3,0,-3,SANDSTONE)
Block(-3,0,-2,SANDSTONE)
Block(-3,0,-1,SANDSTONE)
Block(-3,0,0,SANDSTONE)
Block(-3,0,1,SANDSTONE)
Block(-3,0,2,SANDSTONE)
Block(-3,0,3,OBSIDIAN)
Block(-3,0,4,OBSIDIAN)
Block(-3,1,-7,SANDSTONE)
Block(-3,1,-6,SANDSTONE)
Block(-3,1,-5,SANDSTONE)
Block(-3,1,-4,SANDSTONE)
Block(-3,1,-3,SANDSTONE)
Block(-3,1,-2,SANDSTONE)
Block(-3,1,-1,SANDSTONE)
Block(-3,1,0,SANDSTONE)
Block(-3,1,1,SANDSTONE)
Block(-3,2,-7,SANDSTONE)
Block(-3,2,-6,SANDSTONE)
Block(-3,2,-5,SANDSTONE)
Block(-3,2,-4,SANDSTONE)
Block(-3,2,-3,SANDSTONE)
Block(-3,2,-2,SANDSTONE)
Block(-3,2,-1,SANDSTONE)
Block(-3,3,-7,SANDSTONE)
Block(-3,3,-6,SANDSTONE)
Block(-3,3,-5,SANDSTONE)
Block(-3,3,-4,SANDSTONE)
Block(-3,4,-7,SANDSTONE)
Block(-3,4,-6,SANDSTONE)
Block(-2,0,-7,SANDSTONE)
Block(-2,0,-6,SANDSTONE)
Block(-2,0,-5,SANDSTONE)
Block(-2,0,-4,SANDSTONE)
Block(-2,0,-3,SANDSTONE)
Block(-2,0,-2,SANDSTONE)
Block(-2,0,-1,SANDSTONE)
Block(-2,0,0,SANDSTONE)
Block(-2,0,1,SANDSTONE)
Block(-2,0,2,SANDSTONE)
Block(-2,0,3,OBSIDIAN)
Block(-2,0,4,OBSIDIAN)
Block(-2,1,-7,SANDSTONE)
Block(-2,1,-6,SANDSTONE)
Block(-2,1,-5,SANDSTONE)
Block(-2,1,-4,SANDSTONE)
Block(-2,1,-3,SANDSTONE)
Block(-2,1,-2,SANDSTONE)
Block(-2,1,-1,SANDSTONE)
Block(-2,1,0,SANDSTONE)
Block(-2,1,1,SANDSTONE)
Block(-2,2,-7,SANDSTONE)
Block(-2,2,-6,SANDSTONE)
Block(-2,2,-5,SANDSTONE)
Block(-2,2,-4,SANDSTONE)
Block(-2,2,-3,SANDSTONE)
Block(-2,2,-2,SANDSTONE)
Block(-2,2,-1,SANDSTONE)
Block(-2,3,-7,SANDSTONE)
Block(-2,3,-6,SANDSTONE)
Block(-2,3,-5,SANDSTONE)
Block(-2,3,-4,SANDSTONE)
Block(-2,4,-7,SANDSTONE)
Block(-2,4,-6,SANDSTONE)
Block(-1,0,-7,OBSIDIAN)
Block(-1,0,-6,OBSIDIAN)
Block(-1,0,-5,SANDSTONE)
Block(-1,0,-4,SANDSTONE)
Block(-1,0,-3,SANDSTONE)
Block(-1,0,-2,SANDSTONE)
Block(-1,0,-1,SANDSTONE)
Block(-1,0,0,SANDSTONE)
Block(-1,0,1,SANDSTONE)
Block(-1,0,2,OBSIDIAN)
Block(-1,0,3,OBSIDIAN)
Block(-1,0,4,OBSIDIAN)
Block(-1,1,-7,SANDSTONE)
Block(-1,1,-6,SANDSTONE)
Block(-1,1,-5,SANDSTONE)
Block(-1,1,-4,SANDSTONE)
Block(-1,1,-3,SANDSTONE)
Block(-1,1,-2,SANDSTONE)
Block(-1,1,-1,SANDSTONE)
Block(-1,1,0,SANDSTONE)
Block(-1,1,1,SANDSTONE)
Block(-1,2,-7,SANDSTONE)
Block(-1,2,-6,SANDSTONE)
Block(-1,2,-5,SANDSTONE)
Block(-1,2,-4,SANDSTONE)
Block(-1,2,-3,SANDSTONE)
Block(-1,2,-2,SANDSTONE)
Block(-1,2,-1,SANDSTONE)
Block(-1,3,-7,SANDSTONE)
Block(-1,3,-6,SANDSTONE)
Block(-1,3,-5,SANDSTONE)
Block(-1,3,-4,SANDSTONE)
Block(-1,3,-3,SANDSTONE)
Block(-1,4,-7,SANDSTONE)
Block(-1,4,-6,SANDSTONE)
Block(0,0,-7,OBSIDIAN)
Block(0,0,-6,OBSIDIAN)
Block(0,0,-5,OBSIDIAN)
Block(0,0,-4,OBSIDIAN)
Block(0,0,-3,SANDSTONE)
Block(0,0,-2,SANDSTONE)
Block(0,0,-1,SANDSTONE)
Block(0,0,0,OBSIDIAN)
Block(0,0,1,OBSIDIAN)
Block(0,0,2,OBSIDIAN)
Block(0,0,3,OBSIDIAN)
Block(0,0,4,OBSIDIAN)
Block(0,1,-7,OBSIDIAN)
Block(0,1,-6,OBSIDIAN)
Block(0,1,-5,OBSIDIAN)
Block(0,1,-4,SANDSTONE)
Block(0,1,-3,SANDSTONE)
Block(0,1,-2,SANDSTONE)
Block(0,1,-1,SANDSTONE)
Block(0,1,0,SANDSTONE)
Block(0,1,1,OBSIDIAN)
Block(0,1,2,OBSIDIAN)
Block(0,2,-7,SANDSTONE)
Block(0,2,-6,OBSIDIAN)
Block(0,2,-5,OBSIDIAN)
Block(0,2,-4,SANDSTONE)
Block(0,2,-3,SANDSTONE)
Block(0,2,-2,SANDSTONE)
Block(0,2,-1,SANDSTONE)
Block(0,3,-7,SANDSTONE)
Block(0,3,-6,SANDSTONE)
Block(0,3,-5,OBSIDIAN)
Block(0,3,-4,SANDSTONE)
Block(0,3,-3,SANDSTONE)
Block(0,4,-7,SANDSTONE)
Block(0,4,-6,SANDSTONE)
Block(1,0,-7,OBSIDIAN)
Block(1,0,-6,OBSIDIAN)
Block(1,0,-5,OBSIDIAN)
Block(1,0,-4,OBSIDIAN)
Block(1,0,-3,OBSIDIAN)
Block(1,0,-2,OBSIDIAN)
Block(1,0,-1,OBSIDIAN)
Block(1,0,0,OBSIDIAN)
Block(1,0,1,OBSIDIAN)
Block(1,0,2,OBSIDIAN)
Block(1,0,3,OBSIDIAN)
Block(1,0,4,OBSIDIAN)
Block(1,1,-7,OBSIDIAN)
Block(1,1,-6,OBSIDIAN)
Block(1,1,-5,OBSIDIAN)
Block(1,1,-4,OBSIDIAN)
Block(1,1,-3,OBSIDIAN)
Block(1,1,-2,OBSIDIAN)
Block(1,1,-1,OBSIDIAN)
Block(1,1,0,OBSIDIAN)
Block(1,1,1,OBSIDIAN)
Block(1,1,2,OBSIDIAN)
Block(1,2,-7,OBSIDIAN)
Block(1,2,-6,OBSIDIAN)
Block(1,2,-5,OBSIDIAN)
Block(1,2,-4,OBSIDIAN)
Block(1,2,-3,OBSIDIAN)
Block(1,2,-2,OBSIDIAN)
Block(1,2,-1,OBSIDIAN)
Block(1,3,-7,OBSIDIAN)
Block(1,3,-6,OBSIDIAN)
Block(1,3,-5,OBSIDIAN)
Block(1,3,-4,OBSIDIAN)
Block(1,3,-3,OBSIDIAN)
Block(1,4,-7,OBSIDIAN)
Block(1,4,-6,OBSIDIAN)
Block(1,4,-5,OBSIDIAN)
Block(2,0,-7,OBSIDIAN)
Block(2,0,-6,OBSIDIAN)
Block(2,0,-5,OBSIDIAN)
Block(2,0,-4,OBSIDIAN)
Block(2,0,-3,OBSIDIAN)
Block(2,0,-2,OBSIDIAN)
Block(2,0,-1,OBSIDIAN)
Block(2,0,0,OBSIDIAN)
Block(2,0,1,OBSIDIAN)
Block(2,0,2,OBSIDIAN)
Block(2,0,3,OBSIDIAN)
Block(2,0,4,OBSIDIAN)
Block(2,0,5,OBSIDIAN)
Block(2,1,-7,OBSIDIAN)
Block(2,1,-6,OBSIDIAN)
Block(2,1,-5,OBSIDIAN)
Block(2,1,-4,OBSIDIAN)
Block(2,1,-3,OBSIDIAN)
Block(2,1,-2,OBSIDIAN)
Block(2,1,-1,OBSIDIAN)
Block(2,1,0,OBSIDIAN)
Block(2,1,1,OBSIDIAN)
Block(2,1,2,OBSIDIAN)
Block(2,2,-7,OBSIDIAN)
Block(2,2,-6,OBSIDIAN)
Block(2,2,-5,OBSIDIAN)
Block(2,2,-4,OBSIDIAN)
Block(2,2,-3,OBSIDIAN)
Block(2,2,-2,OBSIDIAN)
Block(2,2,-1,OBSIDIAN)
Block(2,2,0,OBSIDIAN)
Block(2,3,-7,OBSIDIAN)
Block(2,3,-6,OBSIDIAN)
Block(2,3,-5,OBSIDIAN)
Block(2,3,-4,OBSIDIAN)
Block(2,3,-3,OBSIDIAN)
Block(2,4,-7,OBSIDIAN)
Block(2,4,-6,OBSIDIAN)
Block(2,4,-5,OBSIDIAN)
Block(3,0,-6,OBSIDIAN)
Block(3,0,-5,OBSIDIAN)
Block(3,0,-4,OBSIDIAN)
Block(3,0,-3,OBSIDIAN)
Block(3,0,-2,OBSIDIAN)
Block(3,0,-1,OBSIDIAN)
Block(3,0,0,OBSIDIAN)
Block(3,0,1,OBSIDIAN)
Block(3,0,2,OBSIDIAN)
Block(3,0,3,OBSIDIAN)
Block(3,0,4,OBSIDIAN)
Block(3,0,5,OBSIDIAN)
Block(3,1,-7,OBSIDIAN)
Block(3,1,-6,OBSIDIAN)
Block(3,1,-5,OBSIDIAN)
Block(3,1,-4,OBSIDIAN)
Block(3,1,-3,OBSIDIAN)
Block(3,1,-2,OBSIDIAN)
Block(3,1,-1,OBSIDIAN)
Block(3,1,0,OBSIDIAN)
Block(3,1,1,OBSIDIAN)
Block(3,1,2,OBSIDIAN)
Block(3,2,-7,OBSIDIAN)
Block(3,2,-6,OBSIDIAN)
Block(3,2,-5,OBSIDIAN)
Block(3,2,-4,OBSIDIAN)
Block(3,2,-3,OBSIDIAN)
Block(3,2,-2,OBSIDIAN)
Block(3,2,-1,OBSIDIAN)
Block(3,2,0,OBSIDIAN)
Block(3,3,-7,SANDSTONE)
Block(3,3,-6,OBSIDIAN)
Block(3,3,-5,OBSIDIAN)
Block(3,3,-4,OBSIDIAN)
Block(3,3,-3,OBSIDIAN)
Block(3,4,-7,SANDSTONE)
Block(3,4,-6,SANDSTONE)
Block(3,4,-5,OBSIDIAN)
Block(3,5,-7,SANDSTONE)
Block(4,0,-6,OBSIDIAN)
Block(4,0,-5,OBSIDIAN)
Block(4,0,-4,SANDSTONE)
Block(4,0,-3,SANDSTONE)
Block(4,0,-2,SANDSTONE)
Block(4,0,-1,OBSIDIAN)
Block(4,0,0,OBSIDIAN)
Block(4,0,1,OBSIDIAN)
Block(4,0,2,OBSIDIAN)
Block(4,0,3,OBSIDIAN)
Block(4,0,4,OBSIDIAN)
Block(4,0,5,OBSIDIAN)
Block(4,1,-7,OBSIDIAN)
Block(4,1,-6,OBSIDIAN)
Block(4,1,-5,SANDSTONE)
Block(4,1,-4,SANDSTONE)
Block(4,1,-3,SANDSTONE)
Block(4,1,-2,SANDSTONE)
Block(4,1,-1,SANDSTONE)
Block(4,1,0,OBSIDIAN)
Block(4,1,1,OBSIDIAN)
Block(4,1,2,OBSIDIAN)
Block(4,2,-7,SANDSTONE)
Block(4,2,-6,SANDSTONE)
Block(4,2,-5,SANDSTONE)
Block(4,2,-4,SANDSTONE)
Block(4,2,-3,SANDSTONE)
Block(4,2,-2,SANDSTONE)
Block(4,2,-1,SANDSTONE)
Block(4,2,0,OBSIDIAN)
Block(4,3,-7,SANDSTONE)
Block(4,3,-6,SANDSTONE)
Block(4,3,-5,SANDSTONE)
Block(4,3,-4,SANDSTONE)
Block(4,3,-3,SANDSTONE)
Block(4,3,-2,SANDSTONE)
Block(4,4,-7,SANDSTONE)
Block(4,4,-6,SANDSTONE)
Block(4,4,-5,SANDSTONE)
Block(4,5,-7,SANDSTONE)
Block(5,0,-5,SANDSTONE)
Block(5,0,-4,SANDSTONE)
Block(5,0,-3,SANDSTONE)
Block(5,0,-2,SANDSTONE)
Block(5,0,-1,SANDSTONE)
Block(5,0,0,SANDSTONE)
Block(5,0,1,OBSIDIAN)
Block(5,0,2,OBSIDIAN)
Block(5,0,3,OBSIDIAN)
Block(5,0,4,OBSIDIAN)
Block(5,0,5,OBSIDIAN)
Block(5,1,-7,SANDSTONE)
Block(5,1,-6,SANDSTONE)
Block(5,1,-5,SANDSTONE)
Block(5,1,-4,SANDSTONE)
Block(5,1,-3,SANDSTONE)
Block(5,1,-2,SANDSTONE)
Block(5,1,-1,SANDSTONE)
Block(5,1,0,SANDSTONE)
Block(5,1,1,OBSIDIAN)
Block(5,1,2,OBSIDIAN)
Block(5,1,3,OBSIDIAN)
Block(5,2,-7,SANDSTONE)
Block(5,2,-6,SANDSTONE)
Block(5,2,-5,SANDSTONE)
Block(5,2,-4,SANDSTONE)
Block(5,2,-3,SANDSTONE)
Block(5,2,-2,SANDSTONE)
Block(5,2,-1,SANDSTONE)
Block(5,2,0,SANDSTONE)
Block(5,3,-7,SANDSTONE)
Block(5,3,-6,SANDSTONE)
Block(5,3,-5,SANDSTONE)
Block(5,3,-4,SANDSTONE)
Block(5,3,-3,SANDSTONE)
Block(5,3,-2,SANDSTONE)
Block(5,4,-7,SANDSTONE)
Block(5,4,-6,SANDSTONE)
Block(5,4,-5,SANDSTONE)
Block(5,5,-7,SANDSTONE)
Block(6,0,-5,SANDSTONE)
Block(6,0,-4,SANDSTONE)
Block(6,0,-3,SANDSTONE)
Block(6,0,-2,SANDSTONE)
Block(6,0,-1,SANDSTONE)
Block(6,0,0,SANDSTONE)
Block(6,0,1,SANDSTONE)
Block(6,0,2,OBSIDIAN)
Block(6,0,3,OBSIDIAN)
Block(6,0,4,OBSIDIAN)
Block(6,0,5,OBSIDIAN)
Block(6,1,-7,SANDSTONE)
Block(6,1,-6,SANDSTONE)
Block(6,1,-5,SANDSTONE)
Block(6,1,-4,SANDSTONE)
Block(6,1,-3,SANDSTONE)
Block(6,1,-2,SANDSTONE)
Block(6,1,-1,SANDSTONE)
Block(6,1,0,SANDSTONE)
Block(6,1,1,SANDSTONE)
Block(6,1,2,OBSIDIAN)
Block(6,1,3,OBSIDIAN)
Block(6,2,-7,SANDSTONE)
Block(6,2,-6,SANDSTONE)
Block(6,2,-5,SANDSTONE)
Block(6,2,-4,SANDSTONE)
Block(6,2,-3,SANDSTONE)
Block(6,2,-2,SANDSTONE)
Block(6,2,-1,SANDSTONE)
Block(6,2,0,SANDSTONE)
Block(6,3,-7,SANDSTONE)
Block(6,3,-6,SANDSTONE)
Block(6,3,-5,SANDSTONE)
Block(6,3,-4,SANDSTONE)
Block(6,3,-3,SANDSTONE)
Block(6,3,-2,SANDSTONE)
Block(6,4,-7,SANDSTONE)
Block(6,4,-6,SANDSTONE)
Block(6,4,-5,SANDSTONE)
Block(6,4,-4,SANDSTONE)
Block(6,5,-7,SANDSTONE)
Block(7,0,-5,SANDSTONE)
Block(7,0,-4,SANDSTONE)
Block(7,0,-3,SANDSTONE)
Block(7,0,-2,SANDSTONE)
Block(7,0,-1,SANDSTONE)
Block(7,0,0,SANDSTONE)
Block(7,0,1,SANDSTONE)
Block(7,0,2,OBSIDIAN)
Block(7,0,3,OBSIDIAN)
Block(7,0,4,OBSIDIAN)
Block(7,0,5,OBSIDIAN)
Block(7,0,6,OBSIDIAN)
Block(7,1,-7,SANDSTONE)
Block(7,1,-6,SANDSTONE)
Block(7,1,-5,SANDSTONE)
Block(7,1,-4,SANDSTONE)
Block(7,1,-3,SANDSTONE)
Block(7,1,-2,SANDSTONE)
Block(7,1,-1,SANDSTONE)
Block(7,1,0,SANDSTONE)
Block(7,1,1,SANDSTONE)
Block(7,1,2,SANDSTONE)
Block(7,1,3,OBSIDIAN)
Block(7,2,-7,SANDSTONE)
Block(7,2,-6,SANDSTONE)
Block(7,2,-5,SANDSTONE)
Block(7,2,-4,SANDSTONE)
Block(7,2,-3,SANDSTONE)
Block(7,2,-2,SANDSTONE)
Block(7,2,-1,SANDSTONE)
Block(7,2,0,SANDSTONE)
Block(7,2,1,SANDSTONE)
Block(7,3,-7,SANDSTONE)
Block(7,3,-6,SANDSTONE)
Block(7,3,-5,SANDSTONE)
Block(7,3,-4,SANDSTONE)
Block(7,3,-3,SANDSTONE)
Block(7,3,-2,SANDSTONE)
Block(7,4,-7,SANDSTONE)
Block(7,4,-6,SANDSTONE)
Block(7,4,-5,SANDSTONE)
Block(7,4,-4,SANDSTONE)
Block(7,5,-7,SANDSTONE)

#######################################################################
# +-----------------------------------------------------------------+ #
# |                             Branches                            | #
# +-----------------------------------------------------------------+ #
#######################################################################

Branch(0,0,-16,true,DesertSpike_Huge_07C0R3,NORTH,100.0,0)

#######################################################################
# +-----------------------------------------------------------------+ #
# |                             Entities                            | #
# +-----------------------------------------------------------------+ #
#######################################################################


#######################################################################
# +-----------------------------------------------------------------+ #
# |                            Particles                            | #
# +-----------------------------------------------------------------+ #
#######################################################################


#######################################################################
# +-----------------------------------------------------------------+ #
# |                             Spawners                            | #
# +-----------------------------------------------------------------+ #
#######################################################################


#######################################################################
# +-----------------------------------------------------------------+ #
# |                             ModData                             | #
# +-----------------------------------------------------------------+ #
#######################################################################

