
#######################################################################
# +-----------------------------------------------------------------+ #
# |                            BO3 object                           | #
# +-----------------------------------------------------------------+ #
#######################################################################

Author: NLBlackHeavenNL

Description: No description given

Version: 3

SettingsMode: WriteWithoutComments


#######################################################################
# +-----------------------------------------------------------------+ #
# |                          Main settings                          | #
# +-----------------------------------------------------------------+ #
#######################################################################

Tree: true

Frequency: 1

Rarity: 100.0

RotateRandomly: false

SpawnHeight: highestSolidBlock

SpawnHeightOffset: -1

SpawnHeightVariance: 0

##############################
# Height Limits for the BO3. #
##############################

MinHeight: 0

MaxHeight: 255

######################
# Extrusion settings #
######################

ExtrudeMode: None

ExtrudeThroughBlocks: AIR

MaxBranchDepth: 10

ExcludedBiomes: All


#######################################################################
# +-----------------------------------------------------------------+ #
# |                      Source block settings                      | #
# +-----------------------------------------------------------------+ #
#######################################################################

SourceBlocks: AIR,GRASS,DIRT,biomesoplenty:dirt

MaxPercentageOutsideSourceBlock: 0

OutsideSourceBlock: placeAnyway

DoReplaceBlocks: true

IsOTGPlus: false


#######################################################################
# +-----------------------------------------------------------------+ #
# |                              Blocks                             | #
# +-----------------------------------------------------------------+ #
#######################################################################

Block(-4,15,0,dynamictrees:leaves0:8)
Block(-4,15,1,dynamictrees:leaves0:8)
Block(-4,16,0,dynamictrees:leaves0:8)
Block(-4,16,1,dynamictrees:leaves0:8)
Block(-4,17,0,dynamictrees:leaves0:8)
Block(-4,17,1,dynamictrees:leaves0:8)
Block(-4,18,0,dynamictrees:leaves0:8)
Block(-4,18,1,dynamictrees:leaves0:8)
Block(-3,15,-1,dynamictrees:leaves0:8)
Block(-3,15,0,dynamictrees:leaves0:10)
Block(-3,15,3,dynamictrees:leaves0:8)
Block(-3,15,4,dynamictrees:leaves0:8)
Block(-3,16,-1,dynamictrees:leaves0:8)
Block(-3,16,0,dynamictrees:leaves0:9)
Block(-3,16,1,dynamictrees:leaves0:10)
Block(-3,16,3,dynamictrees:leaves0:8)
Block(-3,16,4,dynamictrees:leaves0:8)
Block(-3,17,-1,dynamictrees:leaves0:8)
Block(-3,17,0,dynamictrees:leaves0:10)
Block(-3,17,1,dynamictrees:leaves0:11)
Block(-3,17,2,dynamictrees:leaves0:8)
Block(-3,17,3,dynamictrees:leaves0:8)
Block(-3,17,4,dynamictrees:leaves0:8)
Block(-3,18,-1,dynamictrees:leaves0:8)
Block(-3,18,0,dynamictrees:leaves0:9)
Block(-3,18,1,dynamictrees:leaves0:10)
Block(-3,18,2,dynamictrees:leaves0:8)
Block(-3,19,0,dynamictrees:leaves0:8)
Block(-3,19,1,dynamictrees:leaves0:8)
Block(-3,19,2,dynamictrees:leaves0:8)
Block(-3,20,1,dynamictrees:leaves0:8)
Block(-3,20,2,dynamictrees:leaves0:8)
Block(-3,21,1,dynamictrees:leaves0:8)
Block(-2,13,1,dynamictrees:birchbranch)
Block(-2,14,-2,dynamictrees:leaves0:8)
Block(-2,14,-1,dynamictrees:leaves0:9)
Block(-2,14,1,dynamictrees:leaves0:11)
Block(-2,14,3,dynamictrees:birchbranch)
Block(-2,15,-1,dynamictrees:leaves0:8)
Block(-2,15,1,dynamictrees:birchbranch)
Block(-2,15,3,dynamictrees:leaves0:11)
Block(-2,15,4,dynamictrees:leaves0:9)
Block(-2,15,5,dynamictrees:leaves0:8)
Block(-2,16,1,dynamictrees:leaves0:11)
Block(-2,16,3,dynamictrees:leaves0:11)
Block(-2,16,4,dynamictrees:leaves0:10)
Block(-2,16,5,dynamictrees:leaves0:8)
Block(-2,17,-1,dynamictrees:leaves0:8)
Block(-2,17,0,dynamictrees:leaves0:11)
Block(-2,17,1,dynamictrees:birchbranch)
Block(-2,17,3,dynamictrees:leaves0:10)
Block(-2,17,4,dynamictrees:leaves0:9)
Block(-2,17,5,dynamictrees:leaves0:8)
Block(-2,18,-1,dynamictrees:leaves0:8)
Block(-2,18,0,dynamictrees:leaves0:10)
Block(-2,18,1,dynamictrees:leaves0:11)
Block(-2,18,2,dynamictrees:leaves0:8)
Block(-2,18,3,dynamictrees:leaves0:8)
Block(-2,18,4,dynamictrees:leaves0:8)
Block(-2,19,0,dynamictrees:leaves0:8)
Block(-2,19,1,dynamictrees:leaves0:11)
Block(-2,19,2,dynamictrees:leaves0:8)
Block(-2,20,0,dynamictrees:leaves0:8)
Block(-2,20,1,dynamictrees:leaves0:10)
Block(-2,20,2,dynamictrees:leaves0:9)
Block(-2,20,3,dynamictrees:leaves0:8)
Block(-2,21,-1,dynamictrees:leaves0:8)
Block(-2,21,0,dynamictrees:leaves0:8)
Block(-2,21,1,dynamictrees:leaves0:9)
Block(-2,21,2,dynamictrees:leaves0:8)
Block(-2,22,-1,dynamictrees:leaves0:8)
Block(-2,22,0,dynamictrees:leaves0:8)
Block(-2,22,1,dynamictrees:leaves0:8)
Block(-2,23,-1,dynamictrees:leaves0:8)
Block(-2,23,0,dynamictrees:leaves0:8)
Block(-2,23,1,dynamictrees:leaves0:8)
Block(-1,7,1,dynamictrees:birchbranch:5)
Block(-1,8,1,dynamictrees:birchbranch:5)
Block(-1,9,1,dynamictrees:birchbranch:5)
Block(-1,10,1,dynamictrees:birchbranch:4)
Block(-1,11,1,dynamictrees:birchbranch:4)
Block(-1,12,1,dynamictrees:birchbranch:3)
Block(-1,13,-1,dynamictrees:leaves0:8)
Block(-1,13,1,dynamictrees:birchbranch:3)
Block(-1,13,2,dynamictrees:birchbranch:1)
Block(-1,13,3,dynamictrees:birchbranch:1)
Block(-1,14,1,dynamictrees:birchbranch:2)
Block(-1,14,3,dynamictrees:birchbranch:1)
Block(-1,15,-2,dynamictrees:leaves0:8)
Block(-1,15,-1,dynamictrees:leaves0:8)
Block(-1,15,1,dynamictrees:birchbranch:2)
Block(-1,15,3,dynamictrees:leaves0:11)
Block(-1,15,4,dynamictrees:leaves0:10)
Block(-1,15,5,dynamictrees:leaves0:8)
Block(-1,16,-2,dynamictrees:leaves0:8)
Block(-1,16,-1,dynamictrees:leaves0:8)
Block(-1,16,1,dynamictrees:birchbranch:2)
Block(-1,16,2,dynamictrees:birchbranch:1)
Block(-1,16,3,dynamictrees:birchbranch)
Block(-1,16,4,dynamictrees:leaves0:11)
Block(-1,16,5,dynamictrees:leaves0:8)
Block(-1,17,1,dynamictrees:birchbranch:1)
Block(-1,17,3,dynamictrees:leaves0:11)
Block(-1,17,4,dynamictrees:leaves0:10)
Block(-1,17,5,dynamictrees:leaves0:8)
Block(-1,18,1,dynamictrees:birchbranch:1)
Block(-1,18,3,dynamictrees:leaves0:8)
Block(-1,18,4,dynamictrees:leaves0:8)
Block(-1,19,1,dynamictrees:birchbranch)
Block(-1,20,-2,dynamictrees:leaves0:8)
Block(-1,20,1,dynamictrees:leaves0:11)
Block(-1,20,2,dynamictrees:leaves0:10)
Block(-1,20,3,dynamictrees:leaves0:8)
Block(-1,21,-2,dynamictrees:leaves0:8)
Block(-1,21,-1,dynamictrees:leaves0:9)
Block(-1,21,0,dynamictrees:leaves0:8)
Block(-1,21,1,dynamictrees:leaves0:10)
Block(-1,21,2,dynamictrees:leaves0:9)
Block(-1,21,3,dynamictrees:leaves0:8)
Block(-1,22,-2,dynamictrees:leaves0:8)
Block(-1,22,-1,dynamictrees:leaves0:10)
Block(-1,22,0,dynamictrees:leaves0:11)
Block(-1,22,1,dynamictrees:leaves0:10)
Block(-1,22,2,dynamictrees:leaves0:8)
Block(-1,23,-2,dynamictrees:leaves0:8)
Block(-1,23,-1,dynamictrees:leaves0:9)
Block(-1,23,0,dynamictrees:leaves0:10)
Block(-1,23,1,dynamictrees:leaves0:9)
Block(-1,23,2,dynamictrees:leaves0:8)
Block(-1,24,-1,dynamictrees:leaves0:8)
Block(-1,24,0,dynamictrees:leaves0:8)
Block(-1,24,1,dynamictrees:leaves0:8)
Block(0,0,1,dynamictrees:rootydirt:0)
Block(0,1,1,dynamictrees:birchbranch:7)
Block(0,2,1,dynamictrees:birchbranch:7)
Block(0,3,1,dynamictrees:birchbranch:7)
Block(0,4,1,dynamictrees:birchbranch:7)
Block(0,5,1,dynamictrees:birchbranch:7)
Block(0,6,1,dynamictrees:birchbranch:7)
Block(0,7,0,dynamictrees:birchbranch:5)
Block(0,7,1,dynamictrees:birchbranch:7)
Block(0,8,0,dynamictrees:birchbranch:5)
Block(0,9,0,dynamictrees:birchbranch:5)
Block(0,10,0,dynamictrees:birchbranch:4)
Block(0,11,0,dynamictrees:birchbranch:4)
Block(0,12,0,dynamictrees:birchbranch:4)
Block(0,13,0,dynamictrees:birchbranch:4)
Block(0,14,-3,dynamictrees:leaves0:8)
Block(0,14,-1,dynamictrees:birchbranch)
Block(0,14,0,dynamictrees:birchbranch:4)
Block(0,15,-1,dynamictrees:leaves0:11)
Block(0,15,0,dynamictrees:birchbranch:3)
Block(0,15,2,dynamictrees:leaves0:9)
Block(0,15,3,dynamictrees:leaves0:10)
Block(0,15,4,dynamictrees:leaves0:9)
Block(0,15,5,dynamictrees:leaves0:8)
Block(0,16,-3,dynamictrees:leaves0:8)
Block(0,16,-2,dynamictrees:leaves0:9)
Block(0,16,-1,dynamictrees:leaves0:10)
Block(0,16,0,dynamictrees:birchbranch:2)
Block(0,16,2,dynamictrees:leaves0:8)
Block(0,16,3,dynamictrees:leaves0:11)
Block(0,16,4,dynamictrees:leaves0:10)
Block(0,16,5,dynamictrees:leaves0:8)
Block(0,17,-2,dynamictrees:leaves0:8)
Block(0,17,-1,dynamictrees:birchbranch:1)
Block(0,17,0,dynamictrees:birchbranch:2)
Block(0,17,2,dynamictrees:leaves0:8)
Block(0,17,3,dynamictrees:leaves0:10)
Block(0,17,4,dynamictrees:leaves0:9)
Block(0,17,5,dynamictrees:leaves0:8)
Block(0,18,-2,dynamictrees:leaves0:8)
Block(0,18,0,dynamictrees:birchbranch:2)
Block(0,18,3,dynamictrees:leaves0:8)
Block(0,18,4,dynamictrees:leaves0:8)
Block(0,19,-3,dynamictrees:leaves0:8)
Block(0,19,-2,dynamictrees:leaves0:11)
Block(0,19,-1,dynamictrees:birchbranch)
Block(0,19,0,dynamictrees:birchbranch:2)
Block(0,20,-3,dynamictrees:leaves0:8)
Block(0,20,-2,dynamictrees:leaves0:10)
Block(0,20,-1,dynamictrees:leaves0:11)
Block(0,20,0,dynamictrees:birchbranch:1)
Block(0,20,1,dynamictrees:birchbranch)
Block(0,20,2,dynamictrees:leaves0:11)
Block(0,20,3,dynamictrees:leaves0:8)
Block(0,21,-3,dynamictrees:leaves0:8)
Block(0,21,-2,dynamictrees:leaves0:9)
Block(0,21,-1,dynamictrees:leaves0:10)
Block(0,21,0,dynamictrees:birchbranch:1)
Block(0,21,1,dynamictrees:leaves0:11)
Block(0,21,2,dynamictrees:leaves0:10)
Block(0,21,3,dynamictrees:leaves0:8)
Block(0,22,-2,dynamictrees:leaves0:8)
Block(0,22,-1,dynamictrees:leaves0:11)
Block(0,22,0,dynamictrees:birchbranch)
Block(0,22,1,dynamictrees:leaves0:11)
Block(0,22,2,dynamictrees:leaves0:8)
Block(0,23,-2,dynamictrees:leaves0:8)
Block(0,23,-1,dynamictrees:leaves0:10)
Block(0,23,0,dynamictrees:leaves0:11)
Block(0,23,1,dynamictrees:leaves0:10)
Block(0,23,2,dynamictrees:leaves0:8)
Block(0,24,-1,dynamictrees:leaves0:8)
Block(0,24,0,dynamictrees:leaves0:8)
Block(0,24,1,dynamictrees:leaves0:8)
Block(1,7,1,dynamictrees:birchbranch:4)
Block(1,8,1,dynamictrees:birchbranch:2)
Block(1,9,1,dynamictrees:birchbranch:2)
Block(1,10,1,dynamictrees:birchbranch:2)
Block(1,11,1,dynamictrees:birchbranch:2)
Block(1,12,1,dynamictrees:birchbranch:1)
Block(1,13,1,dynamictrees:birchbranch:1)
Block(1,13,2,dynamictrees:birchbranch)
Block(1,14,1,dynamictrees:birchbranch)
Block(1,14,2,dynamictrees:leaves0:11)
Block(1,14,3,dynamictrees:leaves0:8)
Block(1,15,-1,dynamictrees:birchbranch)
Block(1,15,0,dynamictrees:birchbranch:2)
Block(1,15,1,dynamictrees:leaves0:11)
Block(1,15,2,dynamictrees:leaves0:10)
Block(1,15,3,dynamictrees:leaves0:9)
Block(1,15,4,dynamictrees:leaves0:8)
Block(1,16,-1,dynamictrees:leaves0:11)
Block(1,16,3,dynamictrees:leaves0:8)
Block(1,16,4,dynamictrees:leaves0:8)
Block(1,17,-3,dynamictrees:leaves0:8)
Block(1,17,-2,dynamictrees:leaves0:11)
Block(1,17,-1,dynamictrees:birchbranch)
Block(1,17,3,dynamictrees:leaves0:8)
Block(1,17,4,dynamictrees:leaves0:8)
Block(1,18,-3,dynamictrees:leaves0:8)
Block(1,18,-2,dynamictrees:leaves0:10)
Block(1,18,-1,dynamictrees:leaves0:11)
Block(1,18,1,dynamictrees:leaves0:8)
Block(1,19,-3,dynamictrees:leaves0:8)
Block(1,19,-2,dynamictrees:leaves0:10)
Block(1,19,-1,dynamictrees:leaves0:11)
Block(1,20,-3,dynamictrees:leaves0:8)
Block(1,20,-2,dynamictrees:leaves0:9)
Block(1,20,-1,dynamictrees:leaves0:10)
Block(1,20,2,dynamictrees:leaves0:8)
Block(1,21,-2,dynamictrees:leaves0:8)
Block(1,21,-1,dynamictrees:leaves0:11)
Block(1,21,0,dynamictrees:birchbranch)
Block(1,21,1,dynamictrees:leaves0:11)
Block(1,21,2,dynamictrees:leaves0:8)
Block(1,22,-2,dynamictrees:leaves0:8)
Block(1,22,-1,dynamictrees:leaves0:10)
Block(1,22,0,dynamictrees:leaves0:11)
Block(1,22,1,dynamictrees:leaves0:10)
Block(1,22,2,dynamictrees:leaves0:8)
Block(1,23,-2,dynamictrees:leaves0:8)
Block(1,23,-1,dynamictrees:leaves0:9)
Block(1,23,0,dynamictrees:leaves0:10)
Block(1,23,1,dynamictrees:leaves0:9)
Block(1,23,2,dynamictrees:leaves0:8)
Block(1,24,-1,dynamictrees:leaves0:8)
Block(1,24,0,dynamictrees:leaves0:8)
Block(1,24,1,dynamictrees:leaves0:8)
Block(2,7,0,dynamictrees:birchbranch:2)
Block(2,7,1,dynamictrees:birchbranch:3)
Block(2,8,0,dynamictrees:birchbranch:1)
Block(2,9,0,dynamictrees:birchbranch:1)
Block(2,10,0,dynamictrees:birchbranch:1)
Block(2,11,0,dynamictrees:birchbranch:1)
Block(2,12,0,dynamictrees:birchbranch:1)
Block(2,13,0,dynamictrees:birchbranch)
Block(2,14,0,dynamictrees:leaves0:11)
Block(2,15,0,dynamictrees:birchbranch:1)
Block(2,15,1,dynamictrees:birchbranch)
Block(2,15,2,dynamictrees:leaves0:11)
Block(2,15,3,dynamictrees:leaves0:8)
Block(2,16,0,dynamictrees:birchbranch:1)
Block(2,16,1,dynamictrees:leaves0:11)
Block(2,16,2,dynamictrees:leaves0:10)
Block(2,16,3,dynamictrees:leaves0:8)
Block(2,17,-1,dynamictrees:leaves0:11)
Block(2,17,0,dynamictrees:birchbranch)
Block(2,17,1,dynamictrees:leaves0:11)
Block(2,17,2,dynamictrees:leaves0:8)
Block(2,18,-3,dynamictrees:leaves0:8)
Block(2,18,-2,dynamictrees:leaves0:9)
Block(2,18,-1,dynamictrees:leaves0:10)
Block(2,18,0,dynamictrees:leaves0:11)
Block(2,18,1,dynamictrees:leaves0:10)
Block(2,18,2,dynamictrees:leaves0:8)
Block(2,19,-2,dynamictrees:leaves0:8)
Block(2,19,-1,dynamictrees:leaves0:8)
Block(2,19,0,dynamictrees:leaves0:8)
Block(2,19,1,dynamictrees:leaves0:8)
Block(2,20,-2,dynamictrees:leaves0:8)
Block(2,20,-1,dynamictrees:leaves0:9)
Block(2,20,0,dynamictrees:leaves0:8)
Block(2,20,1,dynamictrees:leaves0:8)
Block(2,21,-2,dynamictrees:leaves0:8)
Block(2,21,-1,dynamictrees:leaves0:10)
Block(2,21,0,dynamictrees:leaves0:11)
Block(2,21,1,dynamictrees:leaves0:10)
Block(2,21,2,dynamictrees:leaves0:8)
Block(2,22,-2,dynamictrees:leaves0:8)
Block(2,22,-1,dynamictrees:leaves0:9)
Block(2,22,0,dynamictrees:leaves0:10)
Block(2,22,1,dynamictrees:leaves0:9)
Block(2,22,2,dynamictrees:leaves0:8)
Block(2,23,-1,dynamictrees:leaves0:8)
Block(2,23,0,dynamictrees:leaves0:9)
Block(2,23,1,dynamictrees:leaves0:8)
Block(2,24,0,dynamictrees:leaves0:8)
Block(3,15,2,dynamictrees:leaves0:8)
Block(3,16,0,dynamictrees:birchbranch)
Block(3,16,1,dynamictrees:leaves0:11)
Block(3,16,2,dynamictrees:leaves0:8)
Block(3,17,-3,dynamictrees:leaves0:8)
Block(3,17,-2,dynamictrees:leaves0:8)
Block(3,17,0,dynamictrees:leaves0:11)
Block(3,17,1,dynamictrees:leaves0:10)
Block(3,17,2,dynamictrees:leaves0:8)
Block(3,18,-2,dynamictrees:leaves0:8)
Block(3,18,0,dynamictrees:leaves0:10)
Block(3,18,1,dynamictrees:leaves0:9)
Block(3,18,2,dynamictrees:leaves0:8)
Block(3,19,-1,dynamictrees:leaves0:8)
Block(3,19,0,dynamictrees:leaves0:8)
Block(3,19,1,dynamictrees:leaves0:8)
Block(3,20,-1,dynamictrees:leaves0:8)
Block(3,21,-1,dynamictrees:leaves0:8)
Block(3,21,0,dynamictrees:leaves0:8)
Block(3,21,1,dynamictrees:leaves0:8)
Block(3,22,-1,dynamictrees:leaves0:8)
Block(3,22,0,dynamictrees:leaves0:8)
Block(3,22,1,dynamictrees:leaves0:8)
Block(3,23,0,dynamictrees:leaves0:8)
Block(4,15,1,dynamictrees:leaves0:8)
Block(4,16,-2,dynamictrees:leaves0:8)
Block(4,16,-1,dynamictrees:leaves0:8)
Block(4,16,0,dynamictrees:leaves0:11)
Block(4,16,1,dynamictrees:leaves0:10)
Block(4,16,2,dynamictrees:leaves0:8)
Block(4,17,-2,dynamictrees:leaves0:8)
Block(4,17,-1,dynamictrees:leaves0:8)
Block(4,17,0,dynamictrees:leaves0:10)
Block(4,17,1,dynamictrees:leaves0:9)
Block(4,17,2,dynamictrees:leaves0:8)
Block(4,18,-1,dynamictrees:leaves0:8)
Block(4,18,0,dynamictrees:leaves0:9)
Block(4,18,1,dynamictrees:leaves0:8)
Block(4,19,0,dynamictrees:leaves0:8)
Block(5,16,-1,dynamictrees:leaves0:8)
Block(5,16,0,dynamictrees:leaves0:8)
Block(5,16,1,dynamictrees:leaves0:8)
Block(5,17,0,dynamictrees:leaves0:8)
Block(5,17,1,dynamictrees:leaves0:8)
Block(5,18,0,dynamictrees:leaves0:8)

#######################################################################
# +-----------------------------------------------------------------+ #
# |                            BO3 checks                           | #
# +-----------------------------------------------------------------+ #
#######################################################################

BlockCheck(0,-1,1,GRASS,DIRT,biomesoplenty:grass,UNKNOWN_BLOCK)

#######################################################################
# +-----------------------------------------------------------------+ #
# |                             Branches                            | #
# +-----------------------------------------------------------------+ #
#######################################################################


#######################################################################
# +-----------------------------------------------------------------+ #
# |                             Entities                            | #
# +-----------------------------------------------------------------+ #
#######################################################################


#######################################################################
# +-----------------------------------------------------------------+ #
# |                            Particles                            | #
# +-----------------------------------------------------------------+ #
#######################################################################


#######################################################################
# +-----------------------------------------------------------------+ #
# |                             Spawners                            | #
# +-----------------------------------------------------------------+ #
#######################################################################


#######################################################################
# +-----------------------------------------------------------------+ #
# |                             ModData                             | #
# +-----------------------------------------------------------------+ #
#######################################################################

