
#######################################################################
# +-----------------------------------------------------------------+ #
# |                            BO3 object                           | #
# +-----------------------------------------------------------------+ #
#######################################################################

Author: NLBlackHeavenNL

Description: No description given

Version: 3

SettingsMode: WriteWithoutComments


#######################################################################
# +-----------------------------------------------------------------+ #
# |                          Main settings                          | #
# +-----------------------------------------------------------------+ #
#######################################################################

Tree: true

Frequency: 1

Rarity: 100.0

RotateRandomly: false

SpawnHeight: highestSolidBlock

SpawnHeightOffset: -1

SpawnHeightVariance: 0

##############################
# Height Limits for the BO3. #
##############################

MinHeight: 0

MaxHeight: 255

######################
# Extrusion settings #
######################

ExtrudeMode: None

ExtrudeThroughBlocks: AIR

MaxBranchDepth: 10

ExcludedBiomes: All


#######################################################################
# +-----------------------------------------------------------------+ #
# |                      Source block settings                      | #
# +-----------------------------------------------------------------+ #
#######################################################################

SourceBlocks: AIR,GRASS,DIRT,biomesoplenty:dirt

MaxPercentageOutsideSourceBlock: 0

OutsideSourceBlock: placeAnyway

DoReplaceBlocks: true

IsOTGPlus: false


#######################################################################
# +-----------------------------------------------------------------+ #
# |                              Blocks                             | #
# +-----------------------------------------------------------------+ #
#######################################################################

Block(-3,22,3,dynamictrees:leaves0:8)
Block(-3,23,1,dynamictrees:leaves0:8)
Block(-3,23,2,dynamictrees:leaves0:8)
Block(-3,23,3,dynamictrees:leaves0:8)
Block(-3,24,1,dynamictrees:leaves0:8)
Block(-3,24,2,dynamictrees:leaves0:8)
Block(-3,24,3,dynamictrees:leaves0:8)
Block(-2,18,1,dynamictrees:leaves0:8)
Block(-2,18,2,dynamictrees:leaves0:11)
Block(-2,19,2,dynamictrees:leaves0:8)
Block(-2,22,1,dynamictrees:leaves0:8)
Block(-2,22,2,dynamictrees:leaves0:8)
Block(-2,22,3,dynamictrees:leaves0:9)
Block(-2,22,4,dynamictrees:leaves0:8)
Block(-2,23,0,dynamictrees:leaves0:8)
Block(-2,23,1,dynamictrees:leaves0:10)
Block(-2,23,2,dynamictrees:leaves0:11)
Block(-2,23,3,dynamictrees:leaves0:10)
Block(-2,23,4,dynamictrees:leaves0:8)
Block(-2,24,0,dynamictrees:leaves0:8)
Block(-2,24,1,dynamictrees:leaves0:9)
Block(-2,24,2,dynamictrees:leaves0:10)
Block(-2,24,3,dynamictrees:leaves0:9)
Block(-2,24,4,dynamictrees:leaves0:8)
Block(-2,25,1,dynamictrees:leaves0:8)
Block(-2,25,2,dynamictrees:leaves0:8)
Block(-2,25,3,dynamictrees:leaves0:8)
Block(-1,0,2,dynamictrees:rootydirt:0)
Block(-1,1,2,dynamictrees:birchbranch:6)
Block(-1,2,2,dynamictrees:birchbranch:6)
Block(-1,3,2,dynamictrees:birchbranch:6)
Block(-1,4,2,dynamictrees:birchbranch:6)
Block(-1,5,2,dynamictrees:birchbranch:6)
Block(-1,6,2,dynamictrees:birchbranch:6)
Block(-1,7,2,dynamictrees:birchbranch:6)
Block(-1,8,2,dynamictrees:birchbranch:5)
Block(-1,9,2,dynamictrees:birchbranch:5)
Block(-1,10,2,dynamictrees:birchbranch:4)
Block(-1,11,2,dynamictrees:birchbranch:4)
Block(-1,12,2,dynamictrees:birchbranch:4)
Block(-1,13,2,dynamictrees:birchbranch:4)
Block(-1,14,2,dynamictrees:birchbranch:3)
Block(-1,15,2,dynamictrees:birchbranch:3)
Block(-1,16,0,dynamictrees:leaves0:8)
Block(-1,16,2,dynamictrees:birchbranch:2)
Block(-1,17,-1,dynamictrees:leaves0:8)
Block(-1,17,0,dynamictrees:leaves0:8)
Block(-1,17,2,dynamictrees:birchbranch:2)
Block(-1,18,0,dynamictrees:leaves0:8)
Block(-1,18,1,dynamictrees:leaves0:8)
Block(-1,18,2,dynamictrees:birchbranch:1)
Block(-1,18,3,dynamictrees:leaves0:8)
Block(-1,19,2,dynamictrees:birchbranch:1)
Block(-1,20,2,dynamictrees:birchbranch:1)
Block(-1,20,3,dynamictrees:birchbranch)
Block(-1,21,2,dynamictrees:birchbranch:1)
Block(-1,21,3,dynamictrees:leaves0:11)
Block(-1,21,4,dynamictrees:leaves0:8)
Block(-1,22,1,dynamictrees:leaves0:8)
Block(-1,22,2,dynamictrees:birchbranch:1)
Block(-1,22,3,dynamictrees:leaves0:10)
Block(-1,22,4,dynamictrees:leaves0:8)
Block(-1,23,0,dynamictrees:leaves0:8)
Block(-1,23,1,dynamictrees:leaves0:11)
Block(-1,23,2,dynamictrees:birchbranch)
Block(-1,23,3,dynamictrees:leaves0:11)
Block(-1,23,4,dynamictrees:leaves0:8)
Block(-1,24,0,dynamictrees:leaves0:8)
Block(-1,24,1,dynamictrees:leaves0:10)
Block(-1,24,2,dynamictrees:leaves0:11)
Block(-1,24,3,dynamictrees:leaves0:10)
Block(-1,24,4,dynamictrees:leaves0:8)
Block(-1,25,1,dynamictrees:leaves0:8)
Block(-1,25,2,dynamictrees:leaves0:8)
Block(-1,25,3,dynamictrees:leaves0:8)
Block(0,16,0,dynamictrees:leaves0:8)
Block(0,16,2,dynamictrees:leaves0:11)
Block(0,17,-1,dynamictrees:leaves0:8)
Block(0,17,0,dynamictrees:leaves0:11)
Block(0,17,1,dynamictrees:birchbranch)
Block(0,17,2,dynamictrees:birchbranch:1)
Block(0,18,-1,dynamictrees:leaves0:8)
Block(0,18,0,dynamictrees:leaves0:10)
Block(0,18,1,dynamictrees:leaves0:11)
Block(0,18,2,dynamictrees:leaves0:8)
Block(0,18,3,dynamictrees:leaves0:8)
Block(0,19,0,dynamictrees:leaves0:8)
Block(0,19,1,dynamictrees:leaves0:8)
Block(0,22,1,dynamictrees:leaves0:8)
Block(0,22,2,dynamictrees:leaves0:8)
Block(0,22,3,dynamictrees:leaves0:9)
Block(0,22,4,dynamictrees:leaves0:8)
Block(0,23,0,dynamictrees:leaves0:8)
Block(0,23,1,dynamictrees:leaves0:10)
Block(0,23,2,dynamictrees:leaves0:11)
Block(0,23,3,dynamictrees:leaves0:10)
Block(0,23,4,dynamictrees:leaves0:8)
Block(0,24,0,dynamictrees:leaves0:8)
Block(0,24,1,dynamictrees:leaves0:9)
Block(0,24,2,dynamictrees:leaves0:10)
Block(0,24,3,dynamictrees:leaves0:9)
Block(0,24,4,dynamictrees:leaves0:8)
Block(0,25,1,dynamictrees:leaves0:8)
Block(0,25,2,dynamictrees:leaves0:8)
Block(0,25,3,dynamictrees:leaves0:8)
Block(1,16,0,dynamictrees:leaves0:8)
Block(1,16,1,dynamictrees:leaves0:8)
Block(1,16,2,dynamictrees:leaves0:8)
Block(1,17,-1,dynamictrees:leaves0:8)
Block(1,17,0,dynamictrees:leaves0:10)
Block(1,17,1,dynamictrees:leaves0:11)
Block(1,17,2,dynamictrees:leaves0:8)
Block(1,18,-1,dynamictrees:leaves0:8)
Block(1,18,0,dynamictrees:leaves0:9)
Block(1,18,1,dynamictrees:leaves0:10)
Block(1,18,2,dynamictrees:leaves0:8)
Block(1,19,0,dynamictrees:leaves0:8)
Block(1,19,1,dynamictrees:leaves0:8)
Block(1,22,3,dynamictrees:leaves0:8)
Block(1,23,1,dynamictrees:leaves0:8)
Block(1,23,2,dynamictrees:leaves0:8)
Block(1,23,3,dynamictrees:leaves0:8)
Block(1,24,1,dynamictrees:leaves0:8)
Block(1,24,2,dynamictrees:leaves0:8)
Block(1,24,3,dynamictrees:leaves0:8)
Block(2,17,0,dynamictrees:leaves0:8)
Block(2,17,1,dynamictrees:leaves0:8)
Block(2,18,0,dynamictrees:leaves0:8)
Block(2,18,1,dynamictrees:leaves0:8)

#######################################################################
# +-----------------------------------------------------------------+ #
# |                            BO3 checks                           | #
# +-----------------------------------------------------------------+ #
#######################################################################

BlockCheck(-1,-1,2,GRASS,DIRT,biomesoplenty:grass,UNKNOWN_BLOCK)

#######################################################################
# +-----------------------------------------------------------------+ #
# |                             Branches                            | #
# +-----------------------------------------------------------------+ #
#######################################################################


#######################################################################
# +-----------------------------------------------------------------+ #
# |                             Entities                            | #
# +-----------------------------------------------------------------+ #
#######################################################################


#######################################################################
# +-----------------------------------------------------------------+ #
# |                            Particles                            | #
# +-----------------------------------------------------------------+ #
#######################################################################


#######################################################################
# +-----------------------------------------------------------------+ #
# |                             Spawners                            | #
# +-----------------------------------------------------------------+ #
#######################################################################


#######################################################################
# +-----------------------------------------------------------------+ #
# |                             ModData                             | #
# +-----------------------------------------------------------------+ #
#######################################################################

