
#######################################################################
# +-----------------------------------------------------------------+ #
# |                            BO3 object                           | #
# +-----------------------------------------------------------------+ #
#######################################################################

Author: NLBlackHeavenNL

Description: No description given

Version: 3

SettingsMode: WriteWithoutComments


#######################################################################
# +-----------------------------------------------------------------+ #
# |                          Main settings                          | #
# +-----------------------------------------------------------------+ #
#######################################################################

Tree: true

Frequency: 1

Rarity: 100.0

RotateRandomly: false

SpawnHeight: highestSolidBlock

SpawnHeightOffset: -1

SpawnHeightVariance: 0

##############################
# Height Limits for the BO3. #
##############################

MinHeight: 0

MaxHeight: 255

######################
# Extrusion settings #
######################

ExtrudeMode: None

ExtrudeThroughBlocks: AIR

MaxBranchDepth: 10

ExcludedBiomes: All


#######################################################################
# +-----------------------------------------------------------------+ #
# |                      Source block settings                      | #
# +-----------------------------------------------------------------+ #
#######################################################################

SourceBlocks: AIR,GRASS,DIRT,biomesoplenty:dirt

MaxPercentageOutsideSourceBlock: 0

OutsideSourceBlock: placeAnyway

DoReplaceBlocks: true

IsOTGPlus: false


#######################################################################
# +-----------------------------------------------------------------+ #
# |                              Blocks                             | #
# +-----------------------------------------------------------------+ #
#######################################################################

Block(-5,11,0,dynamictrees:leaves0:8)
Block(-5,11,1,dynamictrees:leaves0:8)
Block(-5,11,2,dynamictrees:leaves0:8)
Block(-5,11,3,dynamictrees:leaves0:8)
Block(-5,12,1,dynamictrees:leaves0:8)
Block(-5,12,2,dynamictrees:leaves0:8)
Block(-5,12,3,dynamictrees:leaves0:8)
Block(-5,13,2,dynamictrees:leaves0:8)
Block(-4,10,0,dynamictrees:leaves0:8)
Block(-4,10,1,dynamictrees:leaves0:8)
Block(-4,10,3,dynamictrees:leaves0:8)
Block(-4,11,-1,dynamictrees:leaves0:8)
Block(-4,11,0,dynamictrees:leaves0:9)
Block(-4,11,1,dynamictrees:leaves0:10)
Block(-4,11,2,dynamictrees:leaves0:11)
Block(-4,11,3,dynamictrees:leaves0:10)
Block(-4,11,4,dynamictrees:leaves0:8)
Block(-4,12,0,dynamictrees:leaves0:8)
Block(-4,12,1,dynamictrees:leaves0:9)
Block(-4,12,2,dynamictrees:leaves0:10)
Block(-4,12,3,dynamictrees:leaves0:9)
Block(-4,12,4,dynamictrees:leaves0:8)
Block(-4,13,1,dynamictrees:leaves0:8)
Block(-4,13,2,dynamictrees:leaves0:9)
Block(-4,13,3,dynamictrees:leaves0:8)
Block(-4,14,2,dynamictrees:leaves0:8)
Block(-3,10,0,dynamictrees:leaves0:8)
Block(-3,11,-1,dynamictrees:leaves0:8)
Block(-3,11,0,dynamictrees:leaves0:10)
Block(-3,11,1,dynamictrees:leaves0:11)
Block(-3,11,2,dynamictrees:birchbranch)
Block(-3,11,3,dynamictrees:leaves0:11)
Block(-3,11,4,dynamictrees:leaves0:8)
Block(-3,12,-1,dynamictrees:leaves0:8)
Block(-3,12,0,dynamictrees:leaves0:9)
Block(-3,12,1,dynamictrees:leaves0:10)
Block(-3,12,2,dynamictrees:leaves0:11)
Block(-3,12,3,dynamictrees:leaves0:10)
Block(-3,12,4,dynamictrees:leaves0:8)
Block(-3,13,0,dynamictrees:leaves0:8)
Block(-3,13,1,dynamictrees:leaves0:9)
Block(-3,13,2,dynamictrees:leaves0:10)
Block(-3,13,3,dynamictrees:leaves0:9)
Block(-3,13,4,dynamictrees:leaves0:8)
Block(-3,14,1,dynamictrees:leaves0:8)
Block(-3,14,2,dynamictrees:leaves0:8)
Block(-3,14,3,dynamictrees:leaves0:8)
Block(-2,10,2,dynamictrees:birchbranch:1)
Block(-2,10,4,dynamictrees:leaves0:8)
Block(-2,11,-1,dynamictrees:leaves0:8)
Block(-2,11,0,dynamictrees:leaves0:11)
Block(-2,11,1,dynamictrees:birchbranch)
Block(-2,11,2,dynamictrees:birchbranch:1)
Block(-2,11,3,dynamictrees:leaves0:10)
Block(-2,11,4,dynamictrees:leaves0:9)
Block(-2,11,5,dynamictrees:leaves0:8)
Block(-2,12,-1,dynamictrees:leaves0:8)
Block(-2,12,0,dynamictrees:leaves0:10)
Block(-2,12,1,dynamictrees:leaves0:11)
Block(-2,12,2,dynamictrees:birchbranch)
Block(-2,12,3,dynamictrees:leaves0:11)
Block(-2,12,4,dynamictrees:leaves0:8)
Block(-2,13,-1,dynamictrees:leaves0:8)
Block(-2,13,0,dynamictrees:leaves0:9)
Block(-2,13,1,dynamictrees:leaves0:10)
Block(-2,13,2,dynamictrees:leaves0:11)
Block(-2,13,3,dynamictrees:leaves0:10)
Block(-2,13,4,dynamictrees:leaves0:8)
Block(-2,14,0,dynamictrees:leaves0:8)
Block(-2,14,1,dynamictrees:leaves0:8)
Block(-2,14,2,dynamictrees:leaves0:8)
Block(-2,14,3,dynamictrees:leaves0:8)
Block(-2,21,0,dynamictrees:leaves0:8)
Block(-2,21,1,dynamictrees:leaves0:8)
Block(-2,21,2,dynamictrees:leaves0:8)
Block(-2,21,3,dynamictrees:leaves0:8)
Block(-2,21,4,dynamictrees:leaves0:8)
Block(-2,22,1,dynamictrees:leaves0:8)
Block(-2,22,2,dynamictrees:leaves0:8)
Block(-2,22,3,dynamictrees:leaves0:8)
Block(-2,23,2,dynamictrees:leaves0:8)
Block(-1,8,2,dynamictrees:birchbranch)
Block(-1,9,1,dynamictrees:leaves0:8)
Block(-1,9,2,dynamictrees:leaves0:11)
Block(-1,10,2,dynamictrees:birchbranch:1)
Block(-1,10,3,dynamictrees:birchbranch)
Block(-1,10,4,dynamictrees:leaves0:11)
Block(-1,10,5,dynamictrees:leaves0:8)
Block(-1,11,0,dynamictrees:leaves0:8)
Block(-1,11,2,dynamictrees:leaves0:8)
Block(-1,11,3,dynamictrees:leaves0:11)
Block(-1,11,4,dynamictrees:leaves0:10)
Block(-1,11,5,dynamictrees:leaves0:8)
Block(-1,12,0,dynamictrees:leaves0:8)
Block(-1,12,3,dynamictrees:leaves0:10)
Block(-1,12,4,dynamictrees:leaves0:9)
Block(-1,12,5,dynamictrees:leaves0:8)
Block(-1,13,0,dynamictrees:leaves0:8)
Block(-1,13,4,dynamictrees:leaves0:8)
Block(-1,20,0,dynamictrees:leaves0:8)
Block(-1,20,1,dynamictrees:leaves0:8)
Block(-1,20,3,dynamictrees:leaves0:8)
Block(-1,20,4,dynamictrees:leaves0:8)
Block(-1,21,-1,dynamictrees:leaves0:8)
Block(-1,21,0,dynamictrees:leaves0:9)
Block(-1,21,1,dynamictrees:leaves0:10)
Block(-1,21,2,dynamictrees:leaves0:11)
Block(-1,21,3,dynamictrees:leaves0:10)
Block(-1,21,4,dynamictrees:leaves0:9)
Block(-1,21,5,dynamictrees:leaves0:8)
Block(-1,22,0,dynamictrees:leaves0:8)
Block(-1,22,1,dynamictrees:leaves0:9)
Block(-1,22,2,dynamictrees:leaves0:10)
Block(-1,22,3,dynamictrees:leaves0:9)
Block(-1,22,4,dynamictrees:leaves0:8)
Block(-1,23,1,dynamictrees:leaves0:8)
Block(-1,23,2,dynamictrees:leaves0:9)
Block(-1,23,3,dynamictrees:leaves0:8)
Block(-1,24,2,dynamictrees:leaves0:8)
Block(0,0,2,dynamictrees:rootydirt:0)
Block(0,1,2,dynamictrees:birchbranch:4)
Block(0,2,2,dynamictrees:birchbranch:3)
Block(0,3,2,dynamictrees:birchbranch:3)
Block(0,4,2,dynamictrees:birchbranch:3)
Block(0,5,2,dynamictrees:birchbranch:3)
Block(0,6,2,dynamictrees:birchbranch:3)
Block(0,7,2,dynamictrees:birchbranch:3)
Block(0,8,2,dynamictrees:birchbranch:3)
Block(0,9,2,dynamictrees:birchbranch:3)
Block(0,10,2,dynamictrees:birchbranch:3)
Block(0,10,4,dynamictrees:leaves0:8)
Block(0,11,2,dynamictrees:birchbranch:2)
Block(0,11,4,dynamictrees:leaves0:8)
Block(0,12,4,dynamictrees:leaves0:8)
Block(0,20,0,dynamictrees:leaves0:8)
Block(0,20,4,dynamictrees:leaves0:8)
Block(0,21,-1,dynamictrees:leaves0:8)
Block(0,21,0,dynamictrees:leaves0:10)
Block(0,21,1,dynamictrees:leaves0:11)
Block(0,21,2,dynamictrees:birchbranch)
Block(0,21,3,dynamictrees:leaves0:11)
Block(0,21,4,dynamictrees:leaves0:10)
Block(0,21,5,dynamictrees:leaves0:8)
Block(0,22,-1,dynamictrees:leaves0:8)
Block(0,22,0,dynamictrees:leaves0:9)
Block(0,22,1,dynamictrees:leaves0:10)
Block(0,22,2,dynamictrees:leaves0:11)
Block(0,22,3,dynamictrees:leaves0:10)
Block(0,22,4,dynamictrees:leaves0:9)
Block(0,22,5,dynamictrees:leaves0:8)
Block(0,23,0,dynamictrees:leaves0:8)
Block(0,23,1,dynamictrees:leaves0:9)
Block(0,23,2,dynamictrees:leaves0:10)
Block(0,23,3,dynamictrees:leaves0:9)
Block(0,23,4,dynamictrees:leaves0:8)
Block(0,24,1,dynamictrees:leaves0:8)
Block(0,24,2,dynamictrees:leaves0:8)
Block(0,24,3,dynamictrees:leaves0:8)
Block(1,11,2,dynamictrees:birchbranch:2)
Block(1,12,2,dynamictrees:birchbranch:2)
Block(1,13,2,dynamictrees:birchbranch:1)
Block(1,14,2,dynamictrees:birchbranch:1)
Block(1,15,2,dynamictrees:birchbranch:1)
Block(1,16,2,dynamictrees:birchbranch:1)
Block(1,17,2,dynamictrees:birchbranch:1)
Block(1,18,2,dynamictrees:birchbranch:1)
Block(1,18,3,dynamictrees:birchbranch)
Block(1,18,4,dynamictrees:leaves0:11)
Block(1,19,1,dynamictrees:birchbranch)
Block(1,19,2,dynamictrees:birchbranch:1)
Block(1,19,3,dynamictrees:leaves0:11)
Block(1,19,4,dynamictrees:leaves0:8)
Block(1,20,1,dynamictrees:leaves0:11)
Block(1,20,2,dynamictrees:birchbranch:1)
Block(1,20,4,dynamictrees:leaves0:8)
Block(1,21,-1,dynamictrees:leaves0:8)
Block(1,21,0,dynamictrees:leaves0:11)
Block(1,21,1,dynamictrees:birchbranch)
Block(1,21,2,dynamictrees:birchbranch:1)
Block(1,21,3,dynamictrees:birchbranch)
Block(1,21,4,dynamictrees:leaves0:11)
Block(1,21,5,dynamictrees:leaves0:8)
Block(1,22,-1,dynamictrees:leaves0:8)
Block(1,22,0,dynamictrees:leaves0:10)
Block(1,22,1,dynamictrees:leaves0:11)
Block(1,22,2,dynamictrees:birchbranch)
Block(1,22,3,dynamictrees:leaves0:11)
Block(1,22,4,dynamictrees:leaves0:10)
Block(1,22,5,dynamictrees:leaves0:8)
Block(1,23,-1,dynamictrees:leaves0:8)
Block(1,23,0,dynamictrees:leaves0:9)
Block(1,23,1,dynamictrees:leaves0:10)
Block(1,23,2,dynamictrees:leaves0:11)
Block(1,23,3,dynamictrees:leaves0:10)
Block(1,23,4,dynamictrees:leaves0:9)
Block(1,23,5,dynamictrees:leaves0:8)
Block(1,24,0,dynamictrees:leaves0:8)
Block(1,24,1,dynamictrees:leaves0:8)
Block(1,24,2,dynamictrees:leaves0:8)
Block(1,24,3,dynamictrees:leaves0:8)
Block(1,24,4,dynamictrees:leaves0:8)
Block(2,12,0,dynamictrees:leaves0:8)
Block(2,12,1,dynamictrees:leaves0:10)
Block(2,12,2,dynamictrees:leaves0:11)
Block(2,12,3,dynamictrees:leaves0:10)
Block(2,12,4,dynamictrees:leaves0:8)
Block(2,13,0,dynamictrees:leaves0:8)
Block(2,13,1,dynamictrees:leaves0:11)
Block(2,13,2,dynamictrees:birchbranch)
Block(2,13,3,dynamictrees:leaves0:11)
Block(2,13,4,dynamictrees:leaves0:8)
Block(2,14,0,dynamictrees:leaves0:8)
Block(2,14,1,dynamictrees:leaves0:10)
Block(2,14,2,dynamictrees:leaves0:11)
Block(2,14,3,dynamictrees:leaves0:10)
Block(2,14,4,dynamictrees:leaves0:8)
Block(2,15,1,dynamictrees:leaves0:8)
Block(2,15,2,dynamictrees:leaves0:8)
Block(2,15,3,dynamictrees:leaves0:8)
Block(2,18,3,dynamictrees:leaves0:11)
Block(2,19,3,dynamictrees:leaves0:8)
Block(2,20,0,dynamictrees:leaves0:8)
Block(2,20,3,dynamictrees:leaves0:8)
Block(2,20,4,dynamictrees:leaves0:8)
Block(2,21,-1,dynamictrees:leaves0:8)
Block(2,21,0,dynamictrees:leaves0:10)
Block(2,21,1,dynamictrees:leaves0:11)
Block(2,21,2,dynamictrees:leaves0:10)
Block(2,21,3,dynamictrees:leaves0:11)
Block(2,21,4,dynamictrees:leaves0:10)
Block(2,21,5,dynamictrees:leaves0:8)
Block(2,22,-1,dynamictrees:leaves0:8)
Block(2,22,0,dynamictrees:leaves0:9)
Block(2,22,1,dynamictrees:leaves0:10)
Block(2,22,2,dynamictrees:leaves0:11)
Block(2,22,3,dynamictrees:leaves0:10)
Block(2,22,4,dynamictrees:leaves0:9)
Block(2,22,5,dynamictrees:leaves0:8)
Block(2,23,0,dynamictrees:leaves0:8)
Block(2,23,1,dynamictrees:leaves0:9)
Block(2,23,2,dynamictrees:leaves0:10)
Block(2,23,3,dynamictrees:leaves0:9)
Block(2,23,4,dynamictrees:leaves0:8)
Block(2,24,1,dynamictrees:leaves0:8)
Block(2,24,2,dynamictrees:leaves0:8)
Block(2,24,3,dynamictrees:leaves0:8)
Block(3,12,0,dynamictrees:leaves0:8)
Block(3,12,1,dynamictrees:leaves0:9)
Block(3,12,2,dynamictrees:leaves0:10)
Block(3,12,3,dynamictrees:leaves0:9)
Block(3,12,4,dynamictrees:leaves0:8)
Block(3,13,0,dynamictrees:leaves0:8)
Block(3,13,1,dynamictrees:leaves0:10)
Block(3,13,2,dynamictrees:leaves0:11)
Block(3,13,3,dynamictrees:leaves0:10)
Block(3,13,4,dynamictrees:leaves0:8)
Block(3,14,0,dynamictrees:leaves0:8)
Block(3,14,1,dynamictrees:leaves0:9)
Block(3,14,2,dynamictrees:leaves0:10)
Block(3,14,3,dynamictrees:leaves0:9)
Block(3,14,4,dynamictrees:leaves0:8)
Block(3,15,1,dynamictrees:leaves0:8)
Block(3,15,2,dynamictrees:leaves0:8)
Block(3,15,3,dynamictrees:leaves0:8)
Block(3,21,0,dynamictrees:leaves0:8)
Block(3,21,1,dynamictrees:leaves0:8)
Block(3,21,2,dynamictrees:leaves0:8)
Block(3,21,3,dynamictrees:leaves0:8)
Block(3,21,4,dynamictrees:leaves0:8)
Block(3,22,0,dynamictrees:leaves0:8)
Block(3,22,1,dynamictrees:leaves0:8)
Block(3,22,2,dynamictrees:leaves0:8)
Block(3,22,3,dynamictrees:leaves0:8)
Block(3,22,4,dynamictrees:leaves0:8)
Block(3,23,1,dynamictrees:leaves0:8)
Block(3,23,2,dynamictrees:leaves0:8)
Block(3,23,3,dynamictrees:leaves0:8)
Block(4,12,1,dynamictrees:leaves0:8)
Block(4,12,2,dynamictrees:leaves0:8)
Block(4,12,3,dynamictrees:leaves0:8)
Block(4,13,1,dynamictrees:leaves0:8)
Block(4,13,2,dynamictrees:leaves0:8)
Block(4,13,3,dynamictrees:leaves0:8)
Block(4,14,1,dynamictrees:leaves0:8)
Block(4,14,2,dynamictrees:leaves0:8)
Block(4,14,3,dynamictrees:leaves0:8)

#######################################################################
# +-----------------------------------------------------------------+ #
# |                            BO3 checks                           | #
# +-----------------------------------------------------------------+ #
#######################################################################

BlockCheck(0,-1,2,GRASS,DIRT,biomesoplenty:grass,UNKNOWN_BLOCK)

#######################################################################
# +-----------------------------------------------------------------+ #
# |                             Branches                            | #
# +-----------------------------------------------------------------+ #
#######################################################################


#######################################################################
# +-----------------------------------------------------------------+ #
# |                             Entities                            | #
# +-----------------------------------------------------------------+ #
#######################################################################


#######################################################################
# +-----------------------------------------------------------------+ #
# |                            Particles                            | #
# +-----------------------------------------------------------------+ #
#######################################################################


#######################################################################
# +-----------------------------------------------------------------+ #
# |                             Spawners                            | #
# +-----------------------------------------------------------------+ #
#######################################################################


#######################################################################
# +-----------------------------------------------------------------+ #
# |                             ModData                             | #
# +-----------------------------------------------------------------+ #
#######################################################################

