
#######################################################################
# +-----------------------------------------------------------------+ #
# |                            BO3 object                           | #
# +-----------------------------------------------------------------+ #
#######################################################################

Author: NLBlackHeavenNL

Description: No description given

Version: 3

SettingsMode: WriteWithoutComments


#######################################################################
# +-----------------------------------------------------------------+ #
# |                          Main settings                          | #
# +-----------------------------------------------------------------+ #
#######################################################################

Tree: true

Frequency: 1

Rarity: 100.0

RotateRandomly: false

SpawnHeight: highestSolidBlock

SpawnHeightOffset: -1

SpawnHeightVariance: 0

##############################
# Height Limits for the BO3. #
##############################

MinHeight: 0

MaxHeight: 255

######################
# Extrusion settings #
######################

ExtrudeMode: None

ExtrudeThroughBlocks: AIR

MaxBranchDepth: 10

ExcludedBiomes: All


#######################################################################
# +-----------------------------------------------------------------+ #
# |                      Source block settings                      | #
# +-----------------------------------------------------------------+ #
#######################################################################

SourceBlocks: AIR,GRASS,DIRT,biomesoplenty:dirt

MaxPercentageOutsideSourceBlock: 0

OutsideSourceBlock: placeAnyway

DoReplaceBlocks: true

IsOTGPlus: false


#######################################################################
# +-----------------------------------------------------------------+ #
# |                              Blocks                             | #
# +-----------------------------------------------------------------+ #
#######################################################################

Block(-1,15,3,dynamictrees:leaves0:8)
Block(-1,15,4,dynamictrees:leaves0:9)
Block(-1,15,5,dynamictrees:leaves0:8)
Block(-1,16,3,dynamictrees:leaves0:8)
Block(-1,20,2,dynamictrees:leaves0:8)
Block(-1,20,3,dynamictrees:leaves0:8)
Block(-1,20,4,dynamictrees:leaves0:8)
Block(-1,21,2,dynamictrees:leaves0:8)
Block(-1,21,3,dynamictrees:leaves0:8)
Block(-1,21,4,dynamictrees:leaves0:8)
Block(0,14,5,dynamictrees:leaves0:8)
Block(0,15,4,dynamictrees:leaves0:11)
Block(0,15,5,dynamictrees:leaves0:8)
Block(0,16,4,dynamictrees:leaves0:8)
Block(0,16,5,dynamictrees:leaves0:8)
Block(0,19,2,dynamictrees:leaves0:8)
Block(0,19,3,dynamictrees:leaves0:8)
Block(0,19,4,dynamictrees:leaves0:8)
Block(0,20,1,dynamictrees:leaves0:8)
Block(0,20,2,dynamictrees:leaves0:10)
Block(0,20,3,dynamictrees:leaves0:11)
Block(0,20,4,dynamictrees:leaves0:10)
Block(0,20,5,dynamictrees:leaves0:8)
Block(0,21,1,dynamictrees:leaves0:8)
Block(0,21,2,dynamictrees:leaves0:9)
Block(0,21,3,dynamictrees:leaves0:10)
Block(0,21,4,dynamictrees:leaves0:9)
Block(0,21,5,dynamictrees:leaves0:8)
Block(0,22,2,dynamictrees:leaves0:8)
Block(0,22,3,dynamictrees:leaves0:8)
Block(0,22,4,dynamictrees:leaves0:8)
Block(1,0,3,dynamictrees:rootydirt:0)
Block(1,1,3,dynamictrees:birchbranch:6)
Block(1,2,3,dynamictrees:birchbranch:6)
Block(1,3,3,dynamictrees:birchbranch:5)
Block(1,4,3,dynamictrees:birchbranch:5)
Block(1,5,3,dynamictrees:birchbranch:5)
Block(1,6,3,dynamictrees:birchbranch:5)
Block(1,7,3,dynamictrees:birchbranch:5)
Block(1,8,3,dynamictrees:birchbranch:4)
Block(1,9,3,dynamictrees:birchbranch:4)
Block(1,10,3,dynamictrees:birchbranch:3)
Block(1,11,3,dynamictrees:birchbranch:3)
Block(1,12,3,dynamictrees:birchbranch:3)
Block(1,13,3,dynamictrees:birchbranch:2)
Block(1,14,3,dynamictrees:birchbranch:2)
Block(1,14,5,dynamictrees:leaves0:11)
Block(1,15,3,dynamictrees:birchbranch:1)
Block(1,15,4,dynamictrees:birchbranch)
Block(1,15,5,dynamictrees:leaves0:11)
Block(1,15,6,dynamictrees:leaves0:8)
Block(1,16,3,dynamictrees:birchbranch:1)
Block(1,16,4,dynamictrees:leaves0:11)
Block(1,16,5,dynamictrees:leaves0:10)
Block(1,16,6,dynamictrees:leaves0:8)
Block(1,17,3,dynamictrees:birchbranch:1)
Block(1,17,4,dynamictrees:leaves0:8)
Block(1,17,5,dynamictrees:leaves0:8)
Block(1,18,3,dynamictrees:birchbranch:1)
Block(1,19,2,dynamictrees:leaves0:8)
Block(1,19,3,dynamictrees:birchbranch:1)
Block(1,19,4,dynamictrees:leaves0:8)
Block(1,20,1,dynamictrees:leaves0:8)
Block(1,20,2,dynamictrees:leaves0:11)
Block(1,20,3,dynamictrees:birchbranch)
Block(1,20,4,dynamictrees:leaves0:11)
Block(1,20,5,dynamictrees:leaves0:8)
Block(1,21,1,dynamictrees:leaves0:8)
Block(1,21,2,dynamictrees:leaves0:10)
Block(1,21,3,dynamictrees:leaves0:11)
Block(1,21,4,dynamictrees:leaves0:10)
Block(1,21,5,dynamictrees:leaves0:8)
Block(1,22,2,dynamictrees:leaves0:8)
Block(1,22,3,dynamictrees:leaves0:8)
Block(1,22,4,dynamictrees:leaves0:8)
Block(2,14,5,dynamictrees:leaves0:11)
Block(2,15,2,dynamictrees:leaves0:11)
Block(2,15,4,dynamictrees:leaves0:11)
Block(2,15,5,dynamictrees:leaves0:10)
Block(2,15,6,dynamictrees:leaves0:8)
Block(2,16,2,dynamictrees:leaves0:8)
Block(2,16,4,dynamictrees:leaves0:10)
Block(2,16,5,dynamictrees:leaves0:9)
Block(2,16,6,dynamictrees:leaves0:8)
Block(2,17,3,dynamictrees:birchbranch)
Block(2,17,4,dynamictrees:leaves0:11)
Block(2,17,5,dynamictrees:leaves0:8)
Block(2,18,3,dynamictrees:leaves0:11)
Block(2,18,5,dynamictrees:leaves0:8)
Block(2,19,1,dynamictrees:leaves0:8)
Block(2,19,2,dynamictrees:leaves0:9)
Block(2,19,3,dynamictrees:leaves0:10)
Block(2,19,4,dynamictrees:leaves0:9)
Block(2,19,5,dynamictrees:leaves0:8)
Block(2,20,1,dynamictrees:leaves0:8)
Block(2,20,2,dynamictrees:leaves0:10)
Block(2,20,3,dynamictrees:leaves0:11)
Block(2,20,4,dynamictrees:leaves0:10)
Block(2,20,5,dynamictrees:leaves0:8)
Block(2,21,1,dynamictrees:leaves0:8)
Block(2,21,2,dynamictrees:leaves0:9)
Block(2,21,3,dynamictrees:leaves0:10)
Block(2,21,4,dynamictrees:leaves0:9)
Block(2,21,5,dynamictrees:leaves0:8)
Block(2,22,2,dynamictrees:leaves0:8)
Block(2,22,3,dynamictrees:leaves0:8)
Block(2,22,4,dynamictrees:leaves0:8)
Block(3,15,3,dynamictrees:leaves0:8)
Block(3,15,4,dynamictrees:leaves0:8)
Block(3,15,5,dynamictrees:leaves0:8)
Block(3,16,5,dynamictrees:leaves0:8)
Block(3,18,3,dynamictrees:leaves0:8)
Block(3,18,4,dynamictrees:leaves0:8)
Block(3,19,2,dynamictrees:leaves0:8)
Block(3,19,3,dynamictrees:leaves0:8)
Block(3,19,4,dynamictrees:leaves0:8)
Block(3,20,2,dynamictrees:leaves0:8)
Block(3,20,3,dynamictrees:leaves0:8)
Block(3,20,4,dynamictrees:leaves0:8)
Block(3,21,2,dynamictrees:leaves0:8)
Block(3,21,3,dynamictrees:leaves0:8)
Block(3,21,4,dynamictrees:leaves0:8)

#######################################################################
# +-----------------------------------------------------------------+ #
# |                            BO3 checks                           | #
# +-----------------------------------------------------------------+ #
#######################################################################

BlockCheck(1,-1,3,GRASS,DIRT,biomesoplenty:grass,UNKNOWN_BLOCK)

#######################################################################
# +-----------------------------------------------------------------+ #
# |                             Branches                            | #
# +-----------------------------------------------------------------+ #
#######################################################################


#######################################################################
# +-----------------------------------------------------------------+ #
# |                             Entities                            | #
# +-----------------------------------------------------------------+ #
#######################################################################


#######################################################################
# +-----------------------------------------------------------------+ #
# |                            Particles                            | #
# +-----------------------------------------------------------------+ #
#######################################################################


#######################################################################
# +-----------------------------------------------------------------+ #
# |                             Spawners                            | #
# +-----------------------------------------------------------------+ #
#######################################################################


#######################################################################
# +-----------------------------------------------------------------+ #
# |                             ModData                             | #
# +-----------------------------------------------------------------+ #
#######################################################################

