
#######################################################################
# +-----------------------------------------------------------------+ #
# |                            BO3 object                           | #
# +-----------------------------------------------------------------+ #
#######################################################################

Author: NLBlackEagle

Description: No description given

Version: 3

SettingsMode: WriteDisable


#######################################################################
# +-----------------------------------------------------------------+ #
# |                          Main settings                          | #
# +-----------------------------------------------------------------+ #
#######################################################################

Tree: true

Frequency: 1

Rarity: 50.0

RotateRandomly: true

SpawnHeight: highestSolidblock

SpawnHeightOffset: 0

SpawnHeightVariance: 0

##############################
# Height Limits for the BO3. #
##############################

MinHeight: 0

MaxHeight: 255

######################
# Extrusion settings #
######################

ExtrudeMode: None

ExtrudeThroughBlocks: AIR

MaxBranchDepth: 10

ExcludedBiomes: All


#######################################################################
# +-----------------------------------------------------------------+ #
# |                      Source block settings                      | #
# +-----------------------------------------------------------------+ #
#######################################################################

SourceBlocks: AIR,SNOW,STONE,ICE,PACKED_ICE,SNOW_BLOCK

MaxPercentageOutsideSourceBlock: 100

OutsideSourceBlock: placeAnyway

IsOTGPlus: false

InheritBO3: 

InheritBO3Rotation: NORTH

OverrideChildSettings: true

OverrideParentHeight: false

CanOverride: false

BranchFrequency: 0

BranchFrequencyGroup: 

MustBeBelowOther: false

MustBeInside: 

CannotBeInside: 

ReplacesBO3: 

CanSpawnOnWater: true

SpawnOnWaterOnly: false

SpawnUnderWater: false

SpawnAtWaterLevel: false

HeightOffset: 0

RemoveAir: true

ReplaceAbove: 

ReplaceBelow: 

ReplaceWithBiomeBlocks: true

ReplaceWithGroundBlock: DIRT

ReplaceWithSurfaceBlock: GRASS

SmoothRadius: 0

SmoothHeightOffset: 0

SmoothStartTop: false

SmoothStartWood: false

SmoothingSurfaceBlock: 

SmoothingGroundBlock: 

BO3Group: 

IsSpawnPoint: false


#######################################################################
# +-----------------------------------------------------------------+ #
# |                              Blocks                             | #
# +-----------------------------------------------------------------+ #
#######################################################################

Block(-7,-4,8,CONCRETE:15)
Block(-7,-4,9,CONCRETE:15)
Block(-7,-4,10,CONCRETE:15)
Block(-7,-3,8,CONCRETE:15)
Block(-7,-3,9,SNOW_BLOCK)
Block(-7,-3,10,SNOW_BLOCK)
Block(-7,-2,8,CONCRETE:15)
Block(-7,-2,9,SNOW_BLOCK)
Block(-7,-2,10,SNOW_BLOCK)
Block(-6,-10,-13,CONCRETE:15)
Block(-6,-9,-14,CONCRETE:15)
Block(-6,-9,-13,CONCRETE:15)
Block(-6,-5,7,CONCRETE:15)
Block(-6,-5,8,CONCRETE:15)
Block(-6,-5,9,CONCRETE:15)
Block(-6,-5,10,CONCRETE:15)
Block(-6,-5,11,CONCRETE:15)
Block(-6,-4,7,CONCRETE:15)
Block(-6,-4,8,CONCRETE:15)
Block(-6,-4,9,CONCRETE:15)
Block(-6,-4,10,CONCRETE:15)
Block(-6,-4,11,CONCRETE:15)
Block(-6,-3,7,CONCRETE:15)
Block(-6,-3,8,CONCRETE:15)
Block(-6,-3,9,SNOW_BLOCK)
Block(-6,-3,10,SNOW_BLOCK)
Block(-6,-3,11,SNOW_BLOCK)
Block(-6,-2,7,CONCRETE:15)
Block(-6,-2,8,CONCRETE:15)
Block(-6,-2,9,SNOW_BLOCK)
Block(-6,-2,10,SNOW_BLOCK)
Block(-6,-2,11,SNOW_BLOCK)
Block(-6,-1,9,SNOW_BLOCK)
Block(-5,-11,-15,CONCRETE:15)
Block(-5,-11,-14,CONCRETE:15)
Block(-5,-11,-13,CONCRETE:15)
Block(-5,-10,-15,CONCRETE:15)
Block(-5,-10,-14,CONCRETE:15)
Block(-5,-10,-13,CONCRETE:15)
Block(-5,-9,-14,CONCRETE:15)
Block(-5,-9,-13,CONCRETE:15)
Block(-5,-9,-12,CONCRETE:15)
Block(-5,-8,-14,CONCRETE:15)
Block(-5,-8,-13,CONCRETE:15)
Block(-5,-8,11,CONCRETE:15)
Block(-5,-8,12,CONCRETE:15)
Block(-5,-7,-14,CONCRETE:15)
Block(-5,-7,-13,CONCRETE:15)
Block(-5,-7,10,CONCRETE:15)
Block(-5,-7,11,CONCRETE:15)
Block(-5,-7,12,CONCRETE:15)
Block(-5,-6,9,CONCRETE:15)
Block(-5,-6,10,CONCRETE:15)
Block(-5,-6,11,CONCRETE:15)
Block(-5,-6,12,CONCRETE:15)
Block(-5,-5,-13,CONCRETE:15)
Block(-5,-5,7,CONCRETE:15)
Block(-5,-5,8,CONCRETE:15)
Block(-5,-5,9,CONCRETE:15)
Block(-5,-5,10,CONCRETE:15)
Block(-5,-5,11,CONCRETE:15)
Block(-5,-4,-13,CONCRETE:15)
Block(-5,-4,6,CONCRETE:15)
Block(-5,-4,7,CONCRETE:15)
Block(-5,-4,8,CONCRETE:15)
Block(-5,-4,9,CONCRETE:15)
Block(-5,-4,10,CONCRETE:15)
Block(-5,-4,11,CONCRETE:15)
Block(-5,-4,12,CONCRETE:15)
Block(-5,-3,-13,CONCRETE:15)
Block(-5,-3,-12,CONCRETE:15)
Block(-5,-3,6,CONCRETE:15)
Block(-5,-3,7,CONCRETE:15)
Block(-5,-3,8,CONCRETE:15)
Block(-5,-3,9,CONCRETE:15)
Block(-5,-3,10,SNOW_BLOCK)
Block(-5,-3,11,SNOW_BLOCK)
Block(-5,-3,12,SNOW_BLOCK)
Block(-5,-2,-12,CONCRETE:15)
Block(-5,-2,6,CONCRETE:15)
Block(-5,-2,7,CONCRETE:15)
Block(-5,-2,8,CONCRETE:15)
Block(-5,-2,9,CONCRETE:15)
Block(-5,-2,10,SNOW_BLOCK)
Block(-5,-2,11,SNOW_BLOCK)
Block(-5,-2,12,SNOW_BLOCK)
Block(-5,-1,-13,SNOW_BLOCK)
Block(-5,-1,8,CONCRETE:15)
Block(-5,-1,9,CONCRETE:15)
Block(-5,-1,10,SNOW_BLOCK)
Block(-5,0,-13,SNOW_BLOCK)
Block(-4,-12,-13,CONCRETE:15)
Block(-4,-11,-15,CONCRETE:15)
Block(-4,-11,-14,CONCRETE:15)
Block(-4,-11,-13,CONCRETE:15)
Block(-4,-11,-12,CONCRETE:15)
Block(-4,-10,-15,CONCRETE:15)
Block(-4,-10,-14,CONCRETE:15)
Block(-4,-10,-13,CONCRETE:15)
Block(-4,-10,-12,CONCRETE:15)
Block(-4,-9,-15,CONCRETE:15)
Block(-4,-9,-14,CONCRETE:15)
Block(-4,-9,-13,CONCRETE:15)
Block(-4,-9,-12,CONCRETE:15)
Block(-4,-9,10,CONCRETE:15)
Block(-4,-9,11,CONCRETE:15)
Block(-4,-9,12,CONCRETE:15)
Block(-4,-9,13,CONCRETE:15)
Block(-4,-8,-15,CONCRETE:15)
Block(-4,-8,-14,CONCRETE:15)
Block(-4,-8,-13,CONCRETE:15)
Block(-4,-8,-12,CONCRETE:15)
Block(-4,-8,9,CONCRETE:15)
Block(-4,-8,10,CONCRETE:15)
Block(-4,-8,11,CONCRETE:15)
Block(-4,-8,12,CONCRETE:15)
Block(-4,-8,13,CONCRETE:15)
Block(-4,-7,-15,CONCRETE:15)
Block(-4,-7,-14,CONCRETE:15)
Block(-4,-7,-13,CONCRETE:15)
Block(-4,-7,-12,CONCRETE:15)
Block(-4,-7,9,CONCRETE:15)
Block(-4,-7,10,CONCRETE:15)
Block(-4,-7,11,CONCRETE:15)
Block(-4,-7,12,CONCRETE:15)
Block(-4,-7,13,CONCRETE:15)
Block(-4,-6,-14,CONCRETE:15)
Block(-4,-6,-13,CONCRETE:15)
Block(-4,-6,-12,CONCRETE:15)
Block(-4,-6,8,CONCRETE:15)
Block(-4,-6,9,CONCRETE:15)
Block(-4,-6,10,CONCRETE:15)
Block(-4,-6,11,CONCRETE:15)
Block(-4,-6,12,CONCRETE:15)
Block(-4,-6,13,CONCRETE:15)
Block(-4,-5,-14,CONCRETE:15)
Block(-4,-5,-13,CONCRETE:15)
Block(-4,-5,-12,CONCRETE:15)
Block(-4,-5,7,CONCRETE:15)
Block(-4,-5,8,CONCRETE:15)
Block(-4,-5,9,CONCRETE:15)
Block(-4,-5,10,CONCRETE:15)
Block(-4,-5,11,CONCRETE:15)
Block(-4,-5,12,CONCRETE:15)
Block(-4,-5,13,CONCRETE:15)
Block(-4,-4,-14,CONCRETE:15)
Block(-4,-4,-13,CONCRETE:15)
Block(-4,-4,-12,CONCRETE:15)
Block(-4,-4,6,CONCRETE:15)
Block(-4,-4,7,CONCRETE:15)
Block(-4,-4,8,CONCRETE:15)
Block(-4,-4,9,CONCRETE:15)
Block(-4,-4,10,CONCRETE:15)
Block(-4,-4,11,CONCRETE:15)
Block(-4,-4,12,CONCRETE:15)
Block(-4,-3,-14,CONCRETE:15)
Block(-4,-3,-13,CONCRETE:15)
Block(-4,-3,-12,CONCRETE:15)
Block(-4,-3,-11,CONCRETE:15)
Block(-4,-3,7,CONCRETE:15)
Block(-4,-3,8,CONCRETE:15)
Block(-4,-3,9,CONCRETE:15)
Block(-4,-3,10,CONCRETE:15)
Block(-4,-3,11,SNOW_BLOCK)
Block(-4,-3,12,SNOW_BLOCK)
Block(-4,-2,-14,CONCRETE:15)
Block(-4,-2,-13,CONCRETE:15)
Block(-4,-2,-12,CONCRETE:15)
Block(-4,-2,-11,CONCRETE:15)
Block(-4,-2,8,CONCRETE:15)
Block(-4,-2,9,CONCRETE:15)
Block(-4,-2,10,CONCRETE:15)
Block(-4,-2,11,SNOW_BLOCK)
Block(-4,-2,12,SNOW_BLOCK)
Block(-4,-1,-14,SNOW_BLOCK)
Block(-4,-1,-13,SNOW_BLOCK)
Block(-4,-1,-12,CONCRETE:15)
Block(-4,-1,-11,CONCRETE:15)
Block(-4,-1,9,CONCRETE:15)
Block(-4,-1,10,CONCRETE:15)
Block(-4,-1,11,SNOW_BLOCK)
Block(-4,0,-13,SNOW_BLOCK)
Block(-3,-12,-13,CONCRETE:15)
Block(-3,-12,-12,CONCRETE:15)
Block(-3,-11,-15,CONCRETE:15)
Block(-3,-11,-14,CONCRETE:15)
Block(-3,-11,-13,CONCRETE:15)
Block(-3,-11,-12,CONCRETE:15)
Block(-3,-10,-15,CONCRETE:15)
Block(-3,-10,-14,CONCRETE:15)
Block(-3,-10,-13,CONCRETE:15)
Block(-3,-10,-12,CONCRETE:15)
Block(-3,-10,-11,CONCRETE:15)
Block(-3,-10,10,CONCRETE:15)
Block(-3,-10,11,CONCRETE:15)
Block(-3,-10,12,CONCRETE:15)
Block(-3,-10,13,CONCRETE:15)
Block(-3,-9,-15,CONCRETE:15)
Block(-3,-9,-14,CONCRETE:15)
Block(-3,-9,-13,CONCRETE:15)
Block(-3,-9,-12,CONCRETE:15)
Block(-3,-9,-11,CONCRETE:15)
Block(-3,-9,9,CONCRETE:15)
Block(-3,-9,10,CONCRETE:15)
Block(-3,-9,11,CONCRETE:15)
Block(-3,-9,12,CONCRETE:15)
Block(-3,-9,13,CONCRETE:15)
Block(-3,-8,-15,CONCRETE:15)
Block(-3,-8,-14,CONCRETE:15)
Block(-3,-8,-13,CONCRETE:15)
Block(-3,-8,-12,CONCRETE:15)
Block(-3,-8,-11,CONCRETE:15)
Block(-3,-8,9,CONCRETE:15)
Block(-3,-8,10,CONCRETE:15)
Block(-3,-8,11,CONCRETE:15)
Block(-3,-8,12,CONCRETE:15)
Block(-3,-8,13,CONCRETE:15)
Block(-3,-7,-15,CONCRETE:15)
Block(-3,-7,-14,CONCRETE:15)
Block(-3,-7,-13,CONCRETE:15)
Block(-3,-7,-12,CONCRETE:15)
Block(-3,-7,-11,CONCRETE:15)
Block(-3,-7,8,CONCRETE:15)
Block(-3,-7,9,CONCRETE:15)
Block(-3,-7,10,CONCRETE:15)
Block(-3,-7,11,CONCRETE:15)
Block(-3,-7,12,CONCRETE:15)
Block(-3,-7,13,CONCRETE:15)
Block(-3,-7,14,CONCRETE:15)
Block(-3,-6,-15,CONCRETE:15)
Block(-3,-6,-14,CONCRETE:15)
Block(-3,-6,-13,CONCRETE:15)
Block(-3,-6,-12,CONCRETE:15)
Block(-3,-6,-11,CONCRETE:15)
Block(-3,-6,8,CONCRETE:15)
Block(-3,-6,9,CONCRETE:15)
Block(-3,-6,10,CONCRETE:15)
Block(-3,-6,11,CONCRETE:15)
Block(-3,-6,12,CONCRETE:15)
Block(-3,-6,13,CONCRETE:15)
Block(-3,-6,14,CONCRETE:15)
Block(-3,-5,-15,CONCRETE:15)
Block(-3,-5,-14,CONCRETE:15)
Block(-3,-5,-13,CONCRETE:15)
Block(-3,-5,-12,CONCRETE:15)
Block(-3,-5,-11,CONCRETE:15)
Block(-3,-5,8,CONCRETE:15)
Block(-3,-5,9,CONCRETE:15)
Block(-3,-5,10,CONCRETE:15)
Block(-3,-5,11,CONCRETE:15)
Block(-3,-5,12,CONCRETE:15)
Block(-3,-5,13,CONCRETE:15)
Block(-3,-4,-15,CONCRETE:15)
Block(-3,-4,-14,CONCRETE:15)
Block(-3,-4,-13,CONCRETE:15)
Block(-3,-4,-12,CONCRETE:15)
Block(-3,-4,-11,CONCRETE:15)
Block(-3,-4,7,CONCRETE:15)
Block(-3,-4,8,CONCRETE:15)
Block(-3,-4,9,CONCRETE:15)
Block(-3,-4,10,CONCRETE:15)
Block(-3,-4,11,CONCRETE:15)
Block(-3,-4,12,SNOW_BLOCK)
Block(-3,-3,-15,CONCRETE:15)
Block(-3,-3,-14,CONCRETE:15)
Block(-3,-3,-13,CONCRETE:15)
Block(-3,-3,-12,CONCRETE:15)
Block(-3,-3,-11,CONCRETE:15)
Block(-3,-3,7,CONCRETE:15)
Block(-3,-3,8,CONCRETE:15)
Block(-3,-3,9,CONCRETE:15)
Block(-3,-3,10,CONCRETE:15)
Block(-3,-3,11,CONCRETE:15)
Block(-3,-3,12,SNOW_BLOCK)
Block(-3,-2,-14,CONCRETE:15)
Block(-3,-2,-13,CONCRETE:15)
Block(-3,-2,-12,CONCRETE:15)
Block(-3,-2,-11,CONCRETE:15)
Block(-3,-2,9,CONCRETE:15)
Block(-3,-2,10,CONCRETE:15)
Block(-3,-2,11,CONCRETE:15)
Block(-3,-2,12,SNOW_BLOCK)
Block(-3,-1,-13,CONCRETE:15)
Block(-3,-1,-12,CONCRETE:15)
Block(-3,-1,-11,CONCRETE:15)
Block(-3,-1,10,CONCRETE:15)
Block(-3,-1,11,CONCRETE:15)
Block(-3,-1,12,SNOW_BLOCK)
Block(-3,0,-13,SNOW_BLOCK)
Block(-3,0,-12,CONCRETE:15)
Block(-3,1,-13,SNOW_BLOCK)
Block(-2,-12,-13,CONCRETE:15)
Block(-2,-12,-12,CONCRETE:15)
Block(-2,-11,-14,CONCRETE:15)
Block(-2,-11,-13,CONCRETE:15)
Block(-2,-11,-12,CONCRETE:15)
Block(-2,-11,-11,CONCRETE:15)
Block(-2,-11,11,CONCRETE:15)
Block(-2,-11,12,CONCRETE:15)
Block(-2,-11,13,CONCRETE:15)
Block(-2,-10,-15,CONCRETE:15)
Block(-2,-10,-14,CONCRETE:15)
Block(-2,-10,-13,CONCRETE:15)
Block(-2,-10,-12,CONCRETE:15)
Block(-2,-10,-11,CONCRETE:15)
Block(-2,-10,-10,CONCRETE:15)
Block(-2,-10,10,CONCRETE:15)
Block(-2,-10,11,CONCRETE:15)
Block(-2,-10,12,CONCRETE:15)
Block(-2,-10,13,CONCRETE:15)
Block(-2,-9,-15,CONCRETE:15)
Block(-2,-9,-14,CONCRETE:15)
Block(-2,-9,-13,CONCRETE:15)
Block(-2,-9,-12,CONCRETE:15)
Block(-2,-9,-11,CONCRETE:15)
Block(-2,-9,-10,CONCRETE:15)
Block(-2,-9,9,CONCRETE:15)
Block(-2,-9,10,CONCRETE:15)
Block(-2,-9,11,CONCRETE:15)
Block(-2,-9,12,CONCRETE:15)
Block(-2,-9,13,CONCRETE:15)
Block(-2,-8,-15,CONCRETE:15)
Block(-2,-8,-14,CONCRETE:15)
Block(-2,-8,-13,CONCRETE:15)
Block(-2,-8,-12,CONCRETE:15)
Block(-2,-8,-11,CONCRETE:15)
Block(-2,-8,-10,CONCRETE:15)
Block(-2,-8,9,CONCRETE:15)
Block(-2,-8,10,CONCRETE:15)
Block(-2,-8,11,CONCRETE:15)
Block(-2,-8,12,CONCRETE:15)
Block(-2,-8,13,CONCRETE:15)
Block(-2,-8,14,CONCRETE:15)
Block(-2,-7,-15,CONCRETE:15)
Block(-2,-7,-14,CONCRETE:15)
Block(-2,-7,-13,CONCRETE:15)
Block(-2,-7,-12,CONCRETE:15)
Block(-2,-7,-11,CONCRETE:15)
Block(-2,-7,-10,CONCRETE:15)
Block(-2,-7,8,CONCRETE:15)
Block(-2,-7,9,CONCRETE:15)
Block(-2,-7,10,CONCRETE:15)
Block(-2,-7,11,CONCRETE:15)
Block(-2,-7,12,CONCRETE:15)
Block(-2,-7,13,CONCRETE:15)
Block(-2,-7,14,CONCRETE:15)
Block(-2,-6,-15,CONCRETE:15)
Block(-2,-6,-14,CONCRETE:15)
Block(-2,-6,-13,CONCRETE:15)
Block(-2,-6,-12,CONCRETE:15)
Block(-2,-6,-11,CONCRETE:15)
Block(-2,-6,-10,CONCRETE:15)
Block(-2,-6,8,CONCRETE:15)
Block(-2,-6,9,CONCRETE:15)
Block(-2,-6,10,CONCRETE:15)
Block(-2,-6,11,CONCRETE:15)
Block(-2,-6,12,CONCRETE:15)
Block(-2,-6,13,CONCRETE:15)
Block(-2,-6,14,CONCRETE:15)
Block(-2,-5,-15,CONCRETE:15)
Block(-2,-5,-14,CONCRETE:15)
Block(-2,-5,-13,CONCRETE:15)
Block(-2,-5,-12,CONCRETE:15)
Block(-2,-5,-11,CONCRETE:15)
Block(-2,-5,-10,CONCRETE:15)
Block(-2,-5,8,CONCRETE:15)
Block(-2,-5,9,CONCRETE:15)
Block(-2,-5,10,CONCRETE:15)
Block(-2,-5,11,CONCRETE:15)
Block(-2,-5,12,CONCRETE:15)
Block(-2,-5,13,CONCRETE:15)
Block(-2,-4,-15,CONCRETE:15)
Block(-2,-4,-14,CONCRETE:15)
Block(-2,-4,-13,CONCRETE:15)
Block(-2,-4,-12,CONCRETE:15)
Block(-2,-4,-11,CONCRETE:15)
Block(-2,-4,-10,CONCRETE:15)
Block(-2,-4,8,CONCRETE:15)
Block(-2,-4,9,CONCRETE:15)
Block(-2,-4,10,CONCRETE:15)
Block(-2,-4,11,CONCRETE:15)
Block(-2,-4,12,SNOW_BLOCK)
Block(-2,-4,13,SNOW_BLOCK)
Block(-2,-3,-15,CONCRETE:15)
Block(-2,-3,-14,CONCRETE:15)
Block(-2,-3,-13,CONCRETE:15)
Block(-2,-3,-12,CONCRETE:15)
Block(-2,-3,-11,CONCRETE:15)
Block(-2,-3,-10,CONCRETE:15)
Block(-2,-3,8,CONCRETE:15)
Block(-2,-3,9,CONCRETE:15)
Block(-2,-3,10,CONCRETE:15)
Block(-2,-3,11,CONCRETE:15)
Block(-2,-3,12,SNOW_BLOCK)
Block(-2,-3,13,SNOW_BLOCK)
Block(-2,-2,-14,CONCRETE:15)
Block(-2,-2,-13,CONCRETE:15)
Block(-2,-2,-12,CONCRETE:15)
Block(-2,-2,-11,CONCRETE:15)
Block(-2,-2,9,CONCRETE:15)
Block(-2,-2,10,CONCRETE:15)
Block(-2,-2,11,CONCRETE:15)
Block(-2,-2,12,SNOW_BLOCK)
Block(-2,-2,13,SNOW_BLOCK)
Block(-2,-1,-14,CONCRETE:15)
Block(-2,-1,-13,CONCRETE:15)
Block(-2,-1,-12,CONCRETE:15)
Block(-2,-1,-11,CONCRETE:15)
Block(-2,-1,-10,CONCRETE:15)
Block(-2,-1,10,CONCRETE:15)
Block(-2,-1,11,CONCRETE:15)
Block(-2,-1,12,SNOW_BLOCK)
Block(-2,-1,13,SNOW_BLOCK)
Block(-2,0,-14,SNOW_BLOCK)
Block(-2,0,-13,STAINED_CLAY)
Block(-2,0,-12,CONCRETE:15)
Block(-2,0,-11,CONCRETE:15)
Block(-2,0,-10,CONCRETE:15)
Block(-2,0,11,CONCRETE:15)
Block(-2,0,12,SNOW_BLOCK)
Block(-2,1,-13,SNOW_BLOCK)
Block(-2,1,-12,SNOW_BLOCK)
Block(-2,1,-11,SNOW_BLOCK)
Block(-1,-12,-13,CONCRETE:15)
Block(-1,-12,-12,CONCRETE:15)
Block(-1,-11,-14,CONCRETE:15)
Block(-1,-11,-13,CONCRETE:15)
Block(-1,-11,-12,CONCRETE:15)
Block(-1,-11,-11,CONCRETE:15)
Block(-1,-11,11,CONCRETE:15)
Block(-1,-11,12,CONCRETE:15)
Block(-1,-11,13,CONCRETE:15)
Block(-1,-10,-15,CONCRETE:15)
Block(-1,-10,-14,CONCRETE:15)
Block(-1,-10,-13,CONCRETE:15)
Block(-1,-10,-12,CONCRETE:15)
Block(-1,-10,-11,CONCRETE:15)
Block(-1,-10,-10,CONCRETE:15)
Block(-1,-10,10,CONCRETE:15)
Block(-1,-10,11,CONCRETE:15)
Block(-1,-10,12,CONCRETE:15)
Block(-1,-10,13,CONCRETE:15)
Block(-1,-9,-15,CONCRETE:15)
Block(-1,-9,-14,CONCRETE:15)
Block(-1,-9,-13,CONCRETE:15)
Block(-1,-9,-12,CONCRETE:15)
Block(-1,-9,-11,CONCRETE:15)
Block(-1,-9,-10,CONCRETE:15)
Block(-1,-9,-9,CONCRETE:15)
Block(-1,-9,9,CONCRETE:15)
Block(-1,-9,10,CONCRETE:15)
Block(-1,-9,11,CONCRETE:15)
Block(-1,-9,12,CONCRETE:15)
Block(-1,-9,13,CONCRETE:15)
Block(-1,-9,14,CONCRETE:15)
Block(-1,-8,-15,CONCRETE:15)
Block(-1,-8,-14,CONCRETE:15)
Block(-1,-8,-13,CONCRETE:15)
Block(-1,-8,-12,CONCRETE:15)
Block(-1,-8,-11,CONCRETE:15)
Block(-1,-8,-10,CONCRETE:15)
Block(-1,-8,-9,CONCRETE:15)
Block(-1,-8,9,CONCRETE:15)
Block(-1,-8,10,CONCRETE:15)
Block(-1,-8,11,CONCRETE:15)
Block(-1,-8,12,CONCRETE:15)
Block(-1,-8,13,CONCRETE:15)
Block(-1,-8,14,CONCRETE:15)
Block(-1,-7,-15,CONCRETE:15)
Block(-1,-7,-14,CONCRETE:15)
Block(-1,-7,-13,CONCRETE:15)
Block(-1,-7,-12,CONCRETE:15)
Block(-1,-7,-11,CONCRETE:15)
Block(-1,-7,-10,CONCRETE:15)
Block(-1,-7,-9,CONCRETE:15)
Block(-1,-7,9,CONCRETE:15)
Block(-1,-7,10,CONCRETE:15)
Block(-1,-7,11,CONCRETE:15)
Block(-1,-7,12,CONCRETE:15)
Block(-1,-7,13,CONCRETE:15)
Block(-1,-7,14,CONCRETE:15)
Block(-1,-6,-15,CONCRETE:15)
Block(-1,-6,-14,CONCRETE:15)
Block(-1,-6,-13,CONCRETE:15)
Block(-1,-6,-12,CONCRETE:15)
Block(-1,-6,-11,CONCRETE:15)
Block(-1,-6,-10,CONCRETE:15)
Block(-1,-6,-9,CONCRETE:15)
Block(-1,-6,8,CONCRETE:15)
Block(-1,-6,9,CONCRETE:15)
Block(-1,-6,10,CONCRETE:15)
Block(-1,-6,11,CONCRETE:15)
Block(-1,-6,12,CONCRETE:15)
Block(-1,-6,13,CONCRETE:15)
Block(-1,-6,14,CONCRETE:15)
Block(-1,-5,-15,CONCRETE:15)
Block(-1,-5,-14,CONCRETE:15)
Block(-1,-5,-13,CONCRETE:15)
Block(-1,-5,-12,CONCRETE:15)
Block(-1,-5,-11,CONCRETE:15)
Block(-1,-5,-10,CONCRETE:15)
Block(-1,-5,-9,CONCRETE:15)
Block(-1,-5,8,CONCRETE:15)
Block(-1,-5,9,CONCRETE:15)
Block(-1,-5,10,CONCRETE:15)
Block(-1,-5,11,CONCRETE:15)
Block(-1,-5,12,CONCRETE:15)
Block(-1,-5,13,CONCRETE:15)
Block(-1,-5,14,CONCRETE:15)
Block(-1,-4,-15,CONCRETE:15)
Block(-1,-4,-14,CONCRETE:15)
Block(-1,-4,-13,CONCRETE:15)
Block(-1,-4,-12,CONCRETE:15)
Block(-1,-4,-11,CONCRETE:15)
Block(-1,-4,-10,CONCRETE:15)
Block(-1,-4,-9,CONCRETE:15)
Block(-1,-4,8,CONCRETE:15)
Block(-1,-4,9,CONCRETE:15)
Block(-1,-4,10,CONCRETE:15)
Block(-1,-4,11,CONCRETE:15)
Block(-1,-4,12,SNOW_BLOCK)
Block(-1,-4,13,SNOW_BLOCK)
Block(-1,-4,14,SNOW_BLOCK)
Block(-1,-3,-15,CONCRETE:15)
Block(-1,-3,-14,CONCRETE:15)
Block(-1,-3,-13,CONCRETE:15)
Block(-1,-3,-12,CONCRETE:15)
Block(-1,-3,-11,CONCRETE:15)
Block(-1,-3,-10,CONCRETE:15)
Block(-1,-3,8,CONCRETE:15)
Block(-1,-3,9,CONCRETE:15)
Block(-1,-3,10,CONCRETE:15)
Block(-1,-3,11,CONCRETE:15)
Block(-1,-3,12,SNOW_BLOCK)
Block(-1,-3,13,SNOW_BLOCK)
Block(-1,-3,14,SNOW_BLOCK)
Block(-1,-2,-14,CONCRETE:15)
Block(-1,-2,-13,CONCRETE:15)
Block(-1,-2,-12,CONCRETE:15)
Block(-1,-2,-11,CONCRETE:15)
Block(-1,-2,-10,CONCRETE:15)
Block(-1,-2,9,CONCRETE:15)
Block(-1,-2,10,CONCRETE:15)
Block(-1,-2,11,CONCRETE:15)
Block(-1,-2,12,SNOW_BLOCK)
Block(-1,-2,13,SNOW_BLOCK)
Block(-1,-2,14,SNOW_BLOCK)
Block(-1,-1,-14,CONCRETE:15)
Block(-1,-1,-13,CONCRETE:15)
Block(-1,-1,-12,CONCRETE:15)
Block(-1,-1,-11,CONCRETE:15)
Block(-1,-1,-10,CONCRETE:15)
Block(-1,-1,10,CONCRETE:15)
Block(-1,-1,11,CONCRETE:15)
Block(-1,-1,12,SNOW_BLOCK)
Block(-1,-1,13,SNOW_BLOCK)
Block(-1,-1,14,SNOW_BLOCK)
Block(-1,0,-14,SNOW_BLOCK)
Block(-1,0,-13,STAINED_CLAY)
Block(-1,0,-12,CONCRETE:15)
Block(-1,0,-11,CONCRETE:15)
Block(-1,0,-10,SNOW_BLOCK)
Block(-1,0,10,CONCRETE:15)
Block(-1,0,11,CONCRETE:15)
Block(-1,0,12,SNOW_BLOCK)
Block(-1,0,13,SNOW_BLOCK)
Block(-1,0,14,SNOW_BLOCK)
Block(-1,1,-13,SNOW_BLOCK)
Block(-1,1,-12,SNOW_BLOCK)
Block(-1,1,-11,SNOW_BLOCK)
Block(-1,1,-10,SNOW_BLOCK)
Block(-1,1,11,CONCRETE:15)
Block(-1,1,12,CONCRETE:15)
Block(-1,1,13,SNOW_BLOCK)
B(0,-12,-12,CONCRETE:15)
B(0,-12,-11,CONCRETE:15)
B(0,-12,12,CONCRETE:15)
B(0,-12,13,CONCRETE:15)
B(0,-11,-14,CONCRETE:15)
B(0,-11,-13,CONCRETE:15)
B(0,-11,-12,CONCRETE:15)
B(0,-11,-11,CONCRETE:15)
B(0,-11,-10,CONCRETE:15)
B(0,-11,11,CONCRETE:15)
B(0,-11,12,CONCRETE:15)
B(0,-11,13,CONCRETE:15)
B(0,-10,-14,CONCRETE:15)
B(0,-10,-13,CONCRETE:15)
B(0,-10,-12,CONCRETE:15)
B(0,-10,-11,CONCRETE:15)
B(0,-10,-10,CONCRETE:15)
B(0,-10,-9,CONCRETE:15)
B(0,-10,10,CONCRETE:15)
B(0,-10,11,CONCRETE:15)
B(0,-10,12,CONCRETE:15)
B(0,-10,13,CONCRETE:15)
B(0,-10,14,CONCRETE:15)
B(0,-9,-15,CONCRETE:15)
B(0,-9,-14,CONCRETE:15)
B(0,-9,-13,CONCRETE:15)
B(0,-9,-12,CONCRETE:15)
B(0,-9,-11,CONCRETE:15)
B(0,-9,-10,CONCRETE:15)
B(0,-9,-9,CONCRETE:15)
B(0,-9,-8,CONCRETE:15)
B(0,-9,9,CONCRETE:15)
B(0,-9,10,CONCRETE:15)
B(0,-9,11,CONCRETE:15)
B(0,-9,12,CONCRETE:15)
B(0,-9,13,CONCRETE:15)
B(0,-9,14,CONCRETE:15)
B(0,-8,-15,CONCRETE:15)
B(0,-8,-14,CONCRETE:15)
B(0,-8,-13,CONCRETE:15)
B(0,-8,-12,CONCRETE:15)
B(0,-8,-11,CONCRETE:15)
B(0,-8,-10,CONCRETE:15)
B(0,-8,-9,CONCRETE:15)
B(0,-8,-8,CONCRETE:15)
B(0,-8,9,CONCRETE:15)
B(0,-8,10,CONCRETE:15)
B(0,-8,11,CONCRETE:15)
B(0,-8,12,CONCRETE:15)
B(0,-8,13,CONCRETE:15)
B(0,-8,14,CONCRETE:15)
B(0,-7,-15,CONCRETE:15)
B(0,-7,-14,CONCRETE:15)
B(0,-7,-13,CONCRETE:15)
B(0,-7,-12,CONCRETE:15)
B(0,-7,-11,CONCRETE:15)
B(0,-7,-10,CONCRETE:15)
B(0,-7,-9,CONCRETE:15)
B(0,-7,-8,CONCRETE:15)
B(0,-7,9,CONCRETE:15)
B(0,-7,10,CONCRETE:15)
B(0,-7,11,CONCRETE:15)
B(0,-7,12,CONCRETE:15)
B(0,-7,13,CONCRETE:15)
B(0,-7,14,CONCRETE:15)
B(0,-6,-15,CONCRETE:15)
B(0,-6,-14,CONCRETE:15)
B(0,-6,-13,CONCRETE:15)
B(0,-6,-12,CONCRETE:15)
B(0,-6,-11,CONCRETE:15)
B(0,-6,-10,CONCRETE:15)
B(0,-6,-9,CONCRETE:15)
B(0,-6,-8,CONCRETE:15)
B(0,-6,9,CONCRETE:15)
B(0,-6,10,CONCRETE:15)
B(0,-6,11,CONCRETE:15)
B(0,-6,12,CONCRETE:15)
B(0,-6,13,CONCRETE:15)
B(0,-6,14,CONCRETE:15)
B(0,-6,15,CONCRETE:15)
B(0,-5,-15,CONCRETE:15)
B(0,-5,-14,CONCRETE:15)
B(0,-5,-13,CONCRETE:15)
B(0,-5,-12,CONCRETE:15)
B(0,-5,-11,CONCRETE:15)
B(0,-5,-10,CONCRETE:15)
B(0,-5,-9,CONCRETE:15)
B(0,-5,-8,CONCRETE:15)
B(0,-5,8,CONCRETE:15)
B(0,-5,9,CONCRETE:15)
B(0,-5,10,CONCRETE:15)
B(0,-5,11,CONCRETE:15)
B(0,-5,12,CONCRETE:15)
B(0,-5,13,CONCRETE:15)
B(0,-5,14,CONCRETE:15)
B(0,-5,15,CONCRETE:15)
B(0,-4,-15,CONCRETE:15)
B(0,-4,-14,CONCRETE:15)
B(0,-4,-13,CONCRETE:15)
B(0,-4,-12,CONCRETE:15)
B(0,-4,-11,CONCRETE:15)
B(0,-4,-10,CONCRETE:15)
B(0,-4,-9,CONCRETE:15)
B(0,-4,-8,CONCRETE:15)
B(0,-4,8,CONCRETE:15)
B(0,-4,9,CONCRETE:15)
B(0,-4,10,CONCRETE:15)
B(0,-4,11,CONCRETE:15)
B(0,-4,12,CONCRETE:15)
B(0,-4,13,CONCRETE:15)
B(0,-4,14,CONCRETE:15)
B(0,-4,15,CONCRETE:15)
B(0,-3,-15,CONCRETE:15)
B(0,-3,-14,CONCRETE:15)
B(0,-3,-13,CONCRETE:15)
B(0,-3,-12,CONCRETE:15)
B(0,-3,-11,CONCRETE:15)
B(0,-3,-10,CONCRETE:15)
B(0,-3,-9,CONCRETE:15)
B(0,-3,-8,CONCRETE:15)
B(0,-3,8,CONCRETE:15)
B(0,-3,9,CONCRETE:15)
B(0,-3,10,CONCRETE:15)
B(0,-3,11,CONCRETE:15)
B(0,-3,12,CONCRETE:15)
B(0,-3,13,CONCRETE:15)
B(0,-3,14,CONCRETE:15)
B(0,-3,15,CONCRETE:15)
B(0,-2,-14,CONCRETE:15)
B(0,-2,-13,CONCRETE:15)
B(0,-2,-12,CONCRETE:15)
B(0,-2,-11,CONCRETE:15)
B(0,-2,-10,CONCRETE:15)
B(0,-2,9,CONCRETE:15)
B(0,-2,10,CONCRETE:15)
B(0,-2,11,CONCRETE:15)
B(0,-2,12,CONCRETE:15)
B(0,-2,13,CONCRETE:15)
B(0,-2,14,CONCRETE:15)
B(0,-1,-14,CONCRETE:15)
B(0,-1,-13,CONCRETE:15)
B(0,-1,-12,CONCRETE:15)
B(0,-1,-11,CONCRETE:15)
B(0,-1,-10,CONCRETE:15)
B(0,-1,-9,CONCRETE:15)
B(0,-1,9,CONCRETE:15)
B(0,-1,10,CONCRETE:15)
B(0,-1,11,CONCRETE:15)
B(0,-1,12,CONCRETE:15)
B(0,-1,13,SNOW_BLOCK)
B(0,-1,14,SNOW_BLOCK)
B(0,0,-14,SNOW_BLOCK)
B(0,0,-13,SNOW_BLOCK)
B(0,0,-12,CONCRETE:15)
B(0,0,-11,CONCRETE:15)
B(0,0,-10,SNOW_BLOCK)
B(0,0,-9,SNOW_BLOCK)
B(0,0,10,CONCRETE:15)
B(0,0,11,CONCRETE:15)
B(0,0,12,CONCRETE:15)
B(0,0,13,SNOW_BLOCK)
B(0,0,14,SNOW_BLOCK)
B(0,1,-13,SNOW_BLOCK)
B(0,1,-12,SNOW_BLOCK)
B(0,1,-11,SNOW_BLOCK)
B(0,1,-10,SNOW_BLOCK)
B(0,1,-9,SNOW_BLOCK)
B(0,1,10,CONCRETE:15)
B(0,1,11,CONCRETE:15)
B(0,1,12,CONCRETE:15)
B(0,1,13,SNOW_BLOCK)
B(0,1,14,SNOW_BLOCK)
B(0,2,-12,SNOW_BLOCK)
B(0,2,11,CONCRETE:15)
B(0,2,12,CONCRETE:15)
B(1,-12,10,CONCRETE:15)
B(1,-12,11,CONCRETE:15)
B(1,-12,12,CONCRETE:15)
B(1,-12,13,CONCRETE:15)
B(1,-11,-13,CONCRETE:15)
B(1,-11,-12,CONCRETE:15)
B(1,-11,-11,CONCRETE:15)
B(1,-11,-10,CONCRETE:15)
B(1,-11,10,CONCRETE:15)
B(1,-11,11,CONCRETE:15)
B(1,-11,12,CONCRETE:15)
B(1,-11,13,CONCRETE:15)
B(1,-10,-14,CONCRETE:15)
B(1,-10,-13,CONCRETE:15)
B(1,-10,-12,CONCRETE:15)
B(1,-10,-11,CONCRETE:15)
B(1,-10,-10,CONCRETE:15)
B(1,-10,-9,CONCRETE:15)
B(1,-10,-8,CONCRETE:15)
B(1,-10,10,CONCRETE:15)
B(1,-10,11,CONCRETE:15)
B(1,-10,12,CONCRETE:15)
B(1,-10,13,CONCRETE:15)
B(1,-10,14,CONCRETE:15)
B(1,-9,-14,CONCRETE:15)
B(1,-9,-13,CONCRETE:15)
B(1,-9,-12,CONCRETE:15)
B(1,-9,-11,CONCRETE:15)
B(1,-9,-10,CONCRETE:15)
B(1,-9,-9,CONCRETE:15)
B(1,-9,-8,CONCRETE:15)
B(1,-9,-7,CONCRETE:15)
B(1,-9,9,CONCRETE:15)
B(1,-9,10,CONCRETE:15)
B(1,-9,11,CONCRETE:15)
B(1,-9,12,CONCRETE:15)
B(1,-9,13,CONCRETE:15)
B(1,-9,14,CONCRETE:15)
B(1,-8,-15,CONCRETE:15)
B(1,-8,-14,CONCRETE:15)
B(1,-8,-13,CONCRETE:15)
B(1,-8,-12,CONCRETE:15)
B(1,-8,-11,CONCRETE:15)
B(1,-8,-10,CONCRETE:15)
B(1,-8,-9,CONCRETE:15)
B(1,-8,-8,CONCRETE:15)
B(1,-8,-7,CONCRETE:15)
B(1,-8,9,CONCRETE:15)
B(1,-8,10,CONCRETE:15)
B(1,-8,11,CONCRETE:15)
B(1,-8,12,CONCRETE:15)
B(1,-8,13,CONCRETE:15)
B(1,-8,14,CONCRETE:15)
B(1,-7,-15,CONCRETE:15)
B(1,-7,-14,CONCRETE:15)
B(1,-7,-13,CONCRETE:15)
B(1,-7,-12,CONCRETE:15)
B(1,-7,-11,CONCRETE:15)
B(1,-7,-10,CONCRETE:15)
B(1,-7,-9,CONCRETE:15)
B(1,-7,-8,CONCRETE:15)
B(1,-7,-7,CONCRETE:15)
B(1,-7,9,CONCRETE:15)
B(1,-7,10,CONCRETE:15)
B(1,-7,11,CONCRETE:15)
B(1,-7,12,CONCRETE:15)
B(1,-7,13,CONCRETE:15)
B(1,-7,14,CONCRETE:15)
B(1,-6,-15,CONCRETE:15)
B(1,-6,-14,CONCRETE:15)
B(1,-6,-13,CONCRETE:15)
B(1,-6,-12,CONCRETE:15)
B(1,-6,-11,CONCRETE:15)
B(1,-6,-10,CONCRETE:15)
B(1,-6,-9,CONCRETE:15)
B(1,-6,-8,CONCRETE:15)
B(1,-6,-7,CONCRETE:15)
B(1,-6,9,CONCRETE:15)
B(1,-6,10,CONCRETE:15)
B(1,-6,11,CONCRETE:15)
B(1,-6,12,CONCRETE:15)
B(1,-6,13,CONCRETE:15)
B(1,-6,14,CONCRETE:15)
B(1,-6,15,CONCRETE:15)
B(1,-5,-15,CONCRETE:15)
B(1,-5,-14,CONCRETE:15)
B(1,-5,-13,CONCRETE:15)
B(1,-5,-12,CONCRETE:15)
B(1,-5,-11,CONCRETE:15)
B(1,-5,-10,CONCRETE:15)
B(1,-5,-9,CONCRETE:15)
B(1,-5,-8,CONCRETE:15)
B(1,-5,-7,CONCRETE:15)
B(1,-5,9,CONCRETE:15)
B(1,-5,10,CONCRETE:15)
B(1,-5,11,CONCRETE:15)
B(1,-5,12,CONCRETE:15)
B(1,-5,13,CONCRETE:15)
B(1,-5,14,CONCRETE:15)
B(1,-5,15,CONCRETE:15)
B(1,-4,-15,CONCRETE:15)
B(1,-4,-14,CONCRETE:15)
B(1,-4,-13,CONCRETE:15)
B(1,-4,-12,CONCRETE:15)
B(1,-4,-11,CONCRETE:15)
B(1,-4,-10,CONCRETE:15)
B(1,-4,-9,CONCRETE:15)
B(1,-4,-8,CONCRETE:15)
B(1,-4,-7,CONCRETE:15)
B(1,-4,8,CONCRETE:15)
B(1,-4,9,CONCRETE:15)
B(1,-4,10,CONCRETE:15)
B(1,-4,11,CONCRETE:15)
B(1,-4,12,CONCRETE:15)
B(1,-4,13,CONCRETE:15)
B(1,-4,14,CONCRETE:15)
B(1,-4,15,CONCRETE:15)
B(1,-3,-14,CONCRETE:15)
B(1,-3,-13,CONCRETE:15)
B(1,-3,-12,CONCRETE:15)
B(1,-3,-11,CONCRETE:15)
B(1,-3,-10,CONCRETE:15)
B(1,-3,-9,CONCRETE:15)
B(1,-3,-8,CONCRETE:15)
B(1,-3,8,CONCRETE:15)
B(1,-3,9,CONCRETE:15)
B(1,-3,10,CONCRETE:15)
B(1,-3,11,CONCRETE:15)
B(1,-3,12,CONCRETE:15)
B(1,-3,13,CONCRETE:15)
B(1,-3,14,CONCRETE:15)
B(1,-3,15,CONCRETE:15)
B(1,-2,-14,CONCRETE:15)
B(1,-2,-13,CONCRETE:15)
B(1,-2,-12,CONCRETE:15)
B(1,-2,-11,CONCRETE:15)
B(1,-2,-10,CONCRETE:15)
B(1,-2,-9,CONCRETE:15)
B(1,-2,-8,CONCRETE:15)
B(1,-2,-7,CONCRETE:15)
B(1,-2,8,CONCRETE:15)
B(1,-2,9,CONCRETE:15)
B(1,-2,10,CONCRETE:15)
B(1,-2,11,CONCRETE:15)
B(1,-2,12,CONCRETE:15)
B(1,-2,13,CONCRETE:15)
B(1,-2,14,CONCRETE:15)
B(1,-1,-15,SNOW_BLOCK)
B(1,-1,-14,SNOW_BLOCK)
B(1,-1,-13,CONCRETE:15)
B(1,-1,-12,CONCRETE:15)
B(1,-1,-11,CONCRETE:15)
B(1,-1,-10,CONCRETE:15)
B(1,-1,-9,CONCRETE:15)
B(1,-1,-8,CONCRETE:15)
B(1,-1,9,CONCRETE:15)
B(1,-1,10,CONCRETE:15)
B(1,-1,11,CONCRETE:15)
B(1,-1,12,CONCRETE:15)
B(1,-1,13,CONCRETE:15)
B(1,-1,14,CONCRETE:15)
B(1,-1,15,CONCRETE:15)
B(1,0,-14,SNOW_BLOCK)
B(1,0,-13,SNOW_BLOCK)
B(1,0,-12,CONCRETE:15)
B(1,0,-11,CONCRETE:15)
B(1,0,-10,SNOW_BLOCK)
B(1,0,-9,SNOW_BLOCK)
B(1,0,-8,CONCRETE:15)
B(1,0,9,CONCRETE:15)
B(1,0,10,CONCRETE:15)
B(1,0,11,CONCRETE:15)
B(1,0,12,CONCRETE:15)
B(1,0,13,SNOW_BLOCK)
B(1,0,14,SNOW_BLOCK)
B(1,0,15,SNOW_BLOCK)
B(1,1,-14,SNOW_BLOCK)
B(1,1,-13,CONCRETE:15)
B(1,1,-12,CONCRETE:15)
B(1,1,-11,CONCRETE:15)
B(1,1,-10,SNOW_BLOCK)
B(1,1,-9,SNOW_BLOCK)
B(1,1,-8,SNOW_BLOCK)
B(1,1,9,CONCRETE:15)
B(1,1,10,CONCRETE:15)
B(1,1,11,CONCRETE:15)
B(1,1,12,CONCRETE:15)
B(1,1,13,SNOW_BLOCK)
B(1,1,14,SNOW_BLOCK)
B(1,2,-12,CONCRETE:15)
B(1,2,-11,CONCRETE:15)
B(1,2,-10,SNOW_BLOCK)
B(1,2,-9,SNOW_BLOCK)
B(1,2,9,CONCRETE:15)
B(1,2,10,CONCRETE:15)
B(1,2,11,CONCRETE:15)
B(1,2,12,CONCRETE:15)
B(1,2,13,SNOW_BLOCK)
B(1,3,10,CONCRETE:15)
B(1,3,11,CONCRETE:15)
B(1,3,12,CONCRETE:15)
B(2,-12,10,CONCRETE:15)
B(2,-12,11,CONCRETE:15)
B(2,-12,12,CONCRETE:15)
B(2,-12,13,CONCRETE:15)
B(2,-11,-12,CONCRETE:15)
B(2,-11,-11,CONCRETE:15)
B(2,-11,-10,CONCRETE:15)
B(2,-11,-9,CONCRETE:15)
B(2,-11,9,CONCRETE:15)
B(2,-11,10,CONCRETE:15)
B(2,-11,11,CONCRETE:15)
B(2,-11,12,CONCRETE:15)
B(2,-11,13,CONCRETE:15)
B(2,-10,-13,CONCRETE:15)
B(2,-10,-12,CONCRETE:15)
B(2,-10,-11,CONCRETE:15)
B(2,-10,-10,CONCRETE:15)
B(2,-10,-9,CONCRETE:15)
B(2,-10,-8,CONCRETE:15)
B(2,-10,-7,CONCRETE:15)
B(2,-10,9,CONCRETE:15)
B(2,-10,10,CONCRETE:15)
B(2,-10,11,CONCRETE:15)
B(2,-10,12,CONCRETE:15)
B(2,-10,13,CONCRETE:15)
B(2,-10,14,CONCRETE:15)
B(2,-9,-14,CONCRETE:15)
B(2,-9,-13,CONCRETE:15)
B(2,-9,-12,CONCRETE:15)
B(2,-9,-11,CONCRETE:15)
B(2,-9,-10,CONCRETE:15)
B(2,-9,-9,CONCRETE:15)
B(2,-9,-8,CONCRETE:15)
B(2,-9,-7,CONCRETE:15)
B(2,-9,-6,CONCRETE:15)
B(2,-9,9,CONCRETE:15)
B(2,-9,10,CONCRETE:15)
B(2,-9,11,CONCRETE:15)
B(2,-9,12,CONCRETE:15)
B(2,-9,13,CONCRETE:15)
B(2,-9,14,CONCRETE:15)
B(2,-8,-14,CONCRETE:15)
B(2,-8,-13,CONCRETE:15)
B(2,-8,-12,CONCRETE:15)
B(2,-8,-11,CONCRETE:15)
B(2,-8,-10,CONCRETE:15)
B(2,-8,-9,CONCRETE:15)
B(2,-8,-8,CONCRETE:15)
B(2,-8,-7,CONCRETE:15)
B(2,-8,-6,CONCRETE:15)
B(2,-8,9,CONCRETE:15)
B(2,-8,10,CONCRETE:15)
B(2,-8,11,CONCRETE:15)
B(2,-8,12,CONCRETE:15)
B(2,-8,13,CONCRETE:15)
B(2,-8,14,CONCRETE:15)
B(2,-7,-14,CONCRETE:15)
B(2,-7,-13,CONCRETE:15)
B(2,-7,-12,CONCRETE:15)
B(2,-7,-11,CONCRETE:15)
B(2,-7,-10,CONCRETE:15)
B(2,-7,-9,CONCRETE:15)
B(2,-7,-8,CONCRETE:15)
B(2,-7,-7,CONCRETE:15)
B(2,-7,-6,CONCRETE:15)
B(2,-7,9,CONCRETE:15)
B(2,-7,10,CONCRETE:15)
B(2,-7,11,CONCRETE:15)
B(2,-7,12,CONCRETE:15)
B(2,-7,13,CONCRETE:15)
B(2,-7,14,CONCRETE:15)
B(2,-6,-14,CONCRETE:15)
B(2,-6,-13,CONCRETE:15)
B(2,-6,-12,CONCRETE:15)
B(2,-6,-11,CONCRETE:15)
B(2,-6,-10,CONCRETE:15)
B(2,-6,-9,CONCRETE:15)
B(2,-6,-8,CONCRETE:15)
B(2,-6,-7,CONCRETE:15)
B(2,-6,-6,CONCRETE:15)
B(2,-6,9,CONCRETE:15)
B(2,-6,10,CONCRETE:15)
B(2,-6,11,CONCRETE:15)
B(2,-6,12,CONCRETE:15)
B(2,-6,13,CONCRETE:15)
B(2,-6,14,CONCRETE:15)
B(2,-5,-14,CONCRETE:15)
B(2,-5,-13,CONCRETE:15)
B(2,-5,-12,CONCRETE:15)
B(2,-5,-11,CONCRETE:15)
B(2,-5,-10,CONCRETE:15)
B(2,-5,-9,CONCRETE:15)
B(2,-5,-8,CONCRETE:15)
B(2,-5,-7,CONCRETE:15)
B(2,-5,-6,CONCRETE:15)
B(2,-5,8,CONCRETE:15)
B(2,-5,9,CONCRETE:15)
B(2,-5,10,CONCRETE:15)
B(2,-5,11,CONCRETE:15)
B(2,-5,12,CONCRETE:15)
B(2,-5,13,CONCRETE:15)
B(2,-5,14,CONCRETE:15)
B(2,-5,15,CONCRETE:15)
B(2,-4,-14,CONCRETE:15)
B(2,-4,-13,CONCRETE:15)
B(2,-4,-12,CONCRETE:15)
B(2,-4,-11,CONCRETE:15)
B(2,-4,-10,CONCRETE:15)
B(2,-4,-9,CONCRETE:15)
B(2,-4,-8,CONCRETE:15)
B(2,-4,-7,CONCRETE:15)
B(2,-4,8,CONCRETE:15)
B(2,-4,9,CONCRETE:15)
B(2,-4,10,CONCRETE:15)
B(2,-4,11,CONCRETE:15)
B(2,-4,12,CONCRETE:15)
B(2,-4,13,CONCRETE:15)
B(2,-4,14,CONCRETE:15)
B(2,-4,15,CONCRETE:15)
B(2,-3,-14,CONCRETE:15)
B(2,-3,-13,CONCRETE:15)
B(2,-3,-12,CONCRETE:15)
B(2,-3,-11,CONCRETE:15)
B(2,-3,-10,CONCRETE:15)
B(2,-3,-9,CONCRETE:15)
B(2,-3,-8,CONCRETE:15)
B(2,-3,-7,CONCRETE:15)
B(2,-3,-6,CONCRETE:15)
B(2,-3,8,CONCRETE:15)
B(2,-3,9,CONCRETE:15)
B(2,-3,10,CONCRETE:15)
B(2,-3,11,CONCRETE:15)
B(2,-3,12,CONCRETE:15)
B(2,-3,13,CONCRETE:15)
B(2,-3,14,CONCRETE:15)
B(2,-3,15,CONCRETE:15)
B(2,-2,-14,CONCRETE:15)
B(2,-2,-13,CONCRETE:15)
B(2,-2,-12,CONCRETE:15)
B(2,-2,-11,CONCRETE:15)
B(2,-2,-10,CONCRETE:15)
B(2,-2,-9,CONCRETE:15)
B(2,-2,-8,CONCRETE:15)
B(2,-2,-7,CONCRETE:15)
B(2,-2,-6,SNOW_BLOCK)
B(2,-2,8,CONCRETE:15)
B(2,-2,9,CONCRETE:15)
B(2,-2,10,CONCRETE:15)
B(2,-2,11,CONCRETE:15)
B(2,-2,12,CONCRETE:15)
B(2,-2,13,CONCRETE:15)
B(2,-2,14,CONCRETE:15)
B(2,-2,15,CONCRETE:15)
B(2,-1,-14,SNOW_BLOCK)
B(2,-1,-13,SNOW_BLOCK)
B(2,-1,-12,CONCRETE:15)
B(2,-1,-11,CONCRETE:15)
B(2,-1,-10,CONCRETE:15)
B(2,-1,-9,CONCRETE:15)
B(2,-1,-8,CONCRETE:15)
B(2,-1,-7,SNOW_BLOCK)
B(2,-1,-6,SNOW_BLOCK)
B(2,-1,8,CONCRETE:15)
B(2,-1,9,CONCRETE:15)
B(2,-1,10,CONCRETE:15)
B(2,-1,11,CONCRETE:15)
B(2,-1,12,CONCRETE:15)
B(2,-1,13,CONCRETE:15)
B(2,-1,14,CONCRETE:15)
B(2,-1,15,CONCRETE:15)
B(2,0,-14,SNOW_BLOCK)
B(2,0,-13,SNOW_BLOCK)
B(2,0,-12,CONCRETE:15)
B(2,0,-11,CONCRETE:15)
B(2,0,-10,CONCRETE:15)
B(2,0,-9,CONCRETE:15)
B(2,0,-8,CONCRETE:15)
B(2,0,-7,SNOW_BLOCK)
B(2,0,-6,SNOW_BLOCK)
B(2,0,8,CONCRETE:15)
B(2,0,9,CONCRETE:15)
B(2,0,10,CONCRETE:15)
B(2,0,11,CONCRETE:15)
B(2,0,12,CONCRETE:15)
B(2,0,13,CONCRETE:15)
B(2,0,14,SNOW_BLOCK)
B(2,0,15,SNOW_BLOCK)
B(2,1,-14,SNOW_BLOCK)
B(2,1,-13,SNOW_BLOCK)
B(2,1,-12,CONCRETE:15)
B(2,1,-11,CONCRETE:15)
B(2,1,-10,SNOW_BLOCK)
B(2,1,-9,SNOW_BLOCK)
B(2,1,-8,SNOW_BLOCK)
B(2,1,-7,SNOW_BLOCK)
B(2,1,-6,SNOW_BLOCK)
B(2,1,8,CONCRETE:15)
B(2,1,9,CONCRETE:15)
B(2,1,10,CONCRETE:15)
B(2,1,11,CONCRETE:15)
B(2,1,12,CONCRETE:15)
B(2,1,13,CONCRETE:15)
B(2,1,14,SNOW_BLOCK)
B(2,1,15,SNOW_BLOCK)
B(2,2,-13,CONCRETE:15)
B(2,2,-12,CONCRETE:15)
B(2,2,-11,CONCRETE:15)
B(2,2,-10,SNOW_BLOCK)
B(2,2,-9,SNOW_BLOCK)
B(2,2,-8,SNOW_BLOCK)
B(2,2,-7,SNOW_BLOCK)
B(2,2,8,CONCRETE:15)
B(2,2,9,CONCRETE:15)
B(2,2,10,CONCRETE:15)
B(2,2,11,CONCRETE:15)
B(2,2,12,CONCRETE:15)
B(2,2,13,CONCRETE:15)
B(2,2,14,SNOW_BLOCK)
B(2,3,-12,CONCRETE:15)
B(2,3,-10,SNOW_BLOCK)
B(2,3,-9,SNOW_BLOCK)
B(2,3,-8,SNOW_BLOCK)
B(2,3,8,CONCRETE:15)
B(2,3,9,CONCRETE:15)
B(2,3,10,CONCRETE:15)
B(2,3,11,CONCRETE:15)
B(2,3,12,CONCRETE:15)
B(2,3,13,CONCRETE:15)
B(2,4,9,CONCRETE:15)
B(2,4,10,CONCRETE:15)
B(2,4,11,CONCRETE:15)
B(3,-12,10,CONCRETE:15)
B(3,-12,11,CONCRETE:15)
B(3,-12,12,CONCRETE:15)
B(3,-12,13,CONCRETE:15)
B(3,-11,-10,CONCRETE:15)
B(3,-11,-9,CONCRETE:15)
B(3,-11,-8,CONCRETE:15)
B(3,-11,8,CONCRETE:15)
B(3,-11,9,CONCRETE:15)
B(3,-11,10,CONCRETE:15)
B(3,-11,11,CONCRETE:15)
B(3,-11,12,CONCRETE:15)
B(3,-11,13,CONCRETE:15)
B(3,-10,-12,CONCRETE:15)
B(3,-10,-11,CONCRETE:15)
B(3,-10,-10,CONCRETE:15)
B(3,-10,-9,CONCRETE:15)
B(3,-10,-8,CONCRETE:15)
B(3,-10,-7,CONCRETE:15)
B(3,-10,8,CONCRETE:15)
B(3,-10,9,CONCRETE:15)
B(3,-10,10,CONCRETE:15)
B(3,-10,11,CONCRETE:15)
B(3,-10,12,CONCRETE:15)
B(3,-10,13,CONCRETE:15)
B(3,-10,14,CONCRETE:15)
B(3,-9,-13,CONCRETE:15)
B(3,-9,-12,CONCRETE:15)
B(3,-9,-11,CONCRETE:15)
B(3,-9,-10,CONCRETE:15)
B(3,-9,-9,CONCRETE:15)
B(3,-9,-8,CONCRETE:15)
B(3,-9,-7,CONCRETE:15)
B(3,-9,-6,CONCRETE:15)
B(3,-9,8,CONCRETE:15)
B(3,-9,9,CONCRETE:15)
B(3,-9,10,CONCRETE:15)
B(3,-9,11,CONCRETE:15)
B(3,-9,12,CONCRETE:15)
B(3,-9,13,CONCRETE:15)
B(3,-9,14,CONCRETE:15)
B(3,-8,-13,CONCRETE:15)
B(3,-8,-12,CONCRETE:15)
B(3,-8,-11,CONCRETE:15)
B(3,-8,-10,CONCRETE:15)
B(3,-8,-9,CONCRETE:15)
B(3,-8,-8,CONCRETE:15)
B(3,-8,-7,CONCRETE:15)
B(3,-8,-6,CONCRETE:15)
B(3,-8,-5,CONCRETE:15)
B(3,-8,8,CONCRETE:15)
B(3,-8,9,CONCRETE:15)
B(3,-8,10,CONCRETE:15)
B(3,-8,11,CONCRETE:15)
B(3,-8,12,CONCRETE:15)
B(3,-8,13,CONCRETE:15)
B(3,-8,14,CONCRETE:15)
B(3,-7,-13,CONCRETE:15)
B(3,-7,-12,CONCRETE:15)
B(3,-7,-11,CONCRETE:15)
B(3,-7,-10,CONCRETE:15)
B(3,-7,-9,CONCRETE:15)
B(3,-7,-8,CONCRETE:15)
B(3,-7,-7,CONCRETE:15)
B(3,-7,-6,CONCRETE:15)
B(3,-7,-5,CONCRETE:15)
B(3,-7,8,CONCRETE:15)
B(3,-7,9,CONCRETE:15)
B(3,-7,10,CONCRETE:15)
B(3,-7,11,CONCRETE:15)
B(3,-7,12,CONCRETE:15)
B(3,-7,13,CONCRETE:15)
B(3,-7,14,CONCRETE:15)
B(3,-6,-13,CONCRETE:15)
B(3,-6,-12,CONCRETE:15)
B(3,-6,-11,CONCRETE:15)
B(3,-6,-10,CONCRETE:15)
B(3,-6,-9,CONCRETE:15)
B(3,-6,-8,CONCRETE:15)
B(3,-6,-7,CONCRETE:15)
B(3,-6,-6,CONCRETE:15)
B(3,-6,-5,CONCRETE:15)
B(3,-6,8,CONCRETE:15)
B(3,-6,9,CONCRETE:15)
B(3,-6,10,CONCRETE:15)
B(3,-6,11,CONCRETE:15)
B(3,-6,12,CONCRETE:15)
B(3,-6,13,CONCRETE:15)
B(3,-6,14,CONCRETE:15)
B(3,-5,-13,CONCRETE:15)
B(3,-5,-12,CONCRETE:15)
B(3,-5,-11,CONCRETE:15)
B(3,-5,-10,CONCRETE:15)
B(3,-5,-9,CONCRETE:15)
B(3,-5,-8,CONCRETE:15)
B(3,-5,-7,CONCRETE:15)
B(3,-5,-6,CONCRETE:15)
B(3,-5,8,CONCRETE:15)
B(3,-5,9,CONCRETE:15)
B(3,-5,10,CONCRETE:15)
B(3,-5,11,CONCRETE:15)
B(3,-5,12,CONCRETE:15)
B(3,-5,13,CONCRETE:15)
B(3,-5,14,CONCRETE:15)
B(3,-4,-13,CONCRETE:15)
B(3,-4,-12,CONCRETE:15)
B(3,-4,-11,CONCRETE:15)
B(3,-4,-10,CONCRETE:15)
B(3,-4,-9,CONCRETE:15)
B(3,-4,-8,CONCRETE:15)
B(3,-4,-7,CONCRETE:15)
B(3,-4,-6,CONCRETE:15)
B(3,-4,8,CONCRETE:15)
B(3,-4,9,CONCRETE:15)
B(3,-4,10,CONCRETE:15)
B(3,-4,11,CONCRETE:15)
B(3,-4,12,CONCRETE:15)
B(3,-4,13,CONCRETE:15)
B(3,-4,14,CONCRETE:15)
B(3,-3,-12,CONCRETE:15)
B(3,-3,-11,CONCRETE:15)
B(3,-3,-10,CONCRETE:15)
B(3,-3,-9,CONCRETE:15)
B(3,-3,-8,CONCRETE:15)
B(3,-3,-7,CONCRETE:15)
B(3,-3,-6,CONCRETE:15)
B(3,-3,8,CONCRETE:15)
B(3,-3,9,CONCRETE:15)
B(3,-3,10,CONCRETE:15)
B(3,-3,11,CONCRETE:15)
B(3,-3,12,CONCRETE:15)
B(3,-3,13,CONCRETE:15)
B(3,-3,14,CONCRETE:15)
B(3,-3,15,CONCRETE:15)
B(3,-2,-13,CONCRETE:15)
B(3,-2,-12,CONCRETE:15)
B(3,-2,-11,CONCRETE:15)
B(3,-2,-10,CONCRETE:15)
B(3,-2,-9,CONCRETE:15)
B(3,-2,-8,CONCRETE:15)
B(3,-2,-7,CONCRETE:15)
B(3,-2,-6,SNOW_BLOCK)
B(3,-2,-5,SNOW_BLOCK)
B(3,-2,7,CONCRETE:15)
B(3,-2,8,CONCRETE:15)
B(3,-2,9,CONCRETE:15)
B(3,-2,10,CONCRETE:15)
B(3,-2,11,CONCRETE:15)
B(3,-2,12,CONCRETE:15)
B(3,-2,13,CONCRETE:15)
B(3,-2,14,CONCRETE:15)
B(3,-2,15,CONCRETE:15)
B(3,-2,16,CONCRETE:15)
B(3,-1,-14,SNOW_BLOCK)
B(3,-1,-13,SNOW_BLOCK)
B(3,-1,-12,CONCRETE:15)
B(3,-1,-11,CONCRETE:15)
B(3,-1,-10,CONCRETE:15)
B(3,-1,-9,CONCRETE:15)
B(3,-1,-8,CONCRETE:15)
B(3,-1,-7,SNOW_BLOCK)
B(3,-1,-6,SNOW_BLOCK)
B(3,-1,-5,SNOW_BLOCK)
B(3,-1,-4,SNOW_BLOCK)
B(3,-1,-3,CONCRETE:15)
B(3,-1,7,CONCRETE:15)
B(3,-1,8,CONCRETE:15)
B(3,-1,9,CONCRETE:15)
B(3,-1,10,CONCRETE:15)
B(3,-1,11,CONCRETE:15)
B(3,-1,12,CONCRETE:15)
B(3,-1,13,CONCRETE:15)
B(3,-1,14,CONCRETE:15)
B(3,-1,15,SNOW_BLOCK)
B(3,-1,16,SNOW_BLOCK)
B(3,0,-14,SNOW_BLOCK)
B(3,0,-13,SNOW_BLOCK)
B(3,0,-12,CONCRETE:15)
B(3,0,-11,CONCRETE:15)
B(3,0,-10,CONCRETE:15)
B(3,0,-9,CONCRETE:15)
B(3,0,-8,CONCRETE:15)
B(3,0,-7,SNOW_BLOCK)
B(3,0,-6,SNOW_BLOCK)
B(3,0,-5,SNOW_BLOCK)
B(3,0,-4,SNOW_BLOCK)
B(3,0,-3,CONCRETE:15)
B(3,0,7,CONCRETE:15)
B(3,0,8,CONCRETE:15)
B(3,0,9,CONCRETE:15)
B(3,0,10,CONCRETE:15)
B(3,0,11,CONCRETE:15)
B(3,0,12,CONCRETE:15)
B(3,0,13,CONCRETE:15)
B(3,0,14,SNOW_BLOCK)
B(3,0,15,SNOW_BLOCK)
B(3,1,-13,SNOW_BLOCK)
B(3,1,-12,CONCRETE:15)
B(3,1,-11,CONCRETE:15)
B(3,1,-10,CONCRETE:15)
B(3,1,-9,CONCRETE:15)
B(3,1,-8,CONCRETE:15)
B(3,1,-7,SNOW_BLOCK)
B(3,1,-6,SNOW_BLOCK)
B(3,1,-5,SNOW_BLOCK)
B(3,1,-4,CONCRETE:15)
B(3,1,-3,SNOW_BLOCK)
B(3,1,7,CONCRETE:15)
B(3,1,8,CONCRETE:15)
B(3,1,9,CONCRETE:15)
B(3,1,10,CONCRETE:15)
B(3,1,11,CONCRETE:15)
B(3,1,12,CONCRETE:15)
B(3,1,13,CONCRETE:15)
B(3,1,14,SNOW_BLOCK)
B(3,1,15,SNOW_BLOCK)
B(3,2,-13,CONCRETE:15)
B(3,2,-12,CONCRETE:15)
B(3,2,-11,CONCRETE:15)
B(3,2,-10,CONCRETE:15)
B(3,2,-9,CONCRETE:15)
B(3,2,-8,CONCRETE:15)
B(3,2,-7,SNOW_BLOCK)
B(3,2,-6,SNOW_BLOCK)
B(3,2,-5,SNOW_BLOCK)
B(3,2,-4,SNOW_BLOCK)
B(3,2,7,CONCRETE:15)
B(3,2,8,CONCRETE:15)
B(3,2,9,CONCRETE:15)
B(3,2,10,CONCRETE:15)
B(3,2,11,CONCRETE:15)
B(3,2,12,CONCRETE:15)
B(3,2,13,CONCRETE:15)
B(3,2,14,SNOW_BLOCK)
B(3,3,-11,CONCRETE:15)
B(3,3,-10,CONCRETE:15)
B(3,3,-9,CONCRETE:15)
B(3,3,-8,CONCRETE:15)
B(3,3,-7,SNOW_BLOCK)
B(3,3,-6,SNOW_BLOCK)
B(3,3,-5,SNOW_BLOCK)
B(3,3,7,CONCRETE:15)
B(3,3,8,CONCRETE:15)
B(3,3,9,CONCRETE:15)
B(3,3,10,CONCRETE:15)
B(3,3,11,CONCRETE:15)
B(3,3,12,CONCRETE:15)
B(3,3,13,CONCRETE:15)
B(3,4,-8,CONCRETE:15)
B(3,4,-7,CONCRETE:15)
B(3,4,-6,SNOW_BLOCK)
B(3,4,7,CONCRETE:15)
B(3,4,8,CONCRETE:15)
B(3,4,9,CONCRETE:15)
B(3,4,10,CONCRETE:15)
B(3,4,11,CONCRETE:15)
B(3,4,12,CONCRETE:15)
B(3,5,8,CONCRETE:15)
B(3,5,9,CONCRETE:15)
B(3,5,10,CONCRETE:15)
B(4,-12,9,CONCRETE:15)
B(4,-12,10,CONCRETE:15)
B(4,-12,11,CONCRETE:15)
B(4,-12,12,CONCRETE:15)
B(4,-12,13,CONCRETE:15)
B(4,-11,-9,CONCRETE:15)
B(4,-11,-8,CONCRETE:15)
B(4,-11,-7,CONCRETE:15)
B(4,-11,6,CONCRETE:15)
B(4,-11,7,CONCRETE:15)
B(4,-11,8,CONCRETE:15)
B(4,-11,9,CONCRETE:15)
B(4,-11,10,CONCRETE:15)
B(4,-11,11,CONCRETE:15)
B(4,-11,12,CONCRETE:15)
B(4,-11,13,CONCRETE:15)
B(4,-10,-11,CONCRETE:15)
B(4,-10,-10,CONCRETE:15)
B(4,-10,-9,CONCRETE:15)
B(4,-10,-8,CONCRETE:15)
B(4,-10,-7,CONCRETE:15)
B(4,-10,-6,CONCRETE:15)
B(4,-10,6,CONCRETE:15)
B(4,-10,7,CONCRETE:15)
B(4,-10,8,CONCRETE:15)
B(4,-10,9,CONCRETE:15)
B(4,-10,10,CONCRETE:15)
B(4,-10,11,CONCRETE:15)
B(4,-10,12,CONCRETE:15)
B(4,-10,13,CONCRETE:15)
B(4,-10,14,CONCRETE:15)
B(4,-9,-12,CONCRETE:15)
B(4,-9,-11,CONCRETE:15)
B(4,-9,-10,CONCRETE:15)
B(4,-9,-9,CONCRETE:15)
B(4,-9,-8,CONCRETE:15)
B(4,-9,-7,CONCRETE:15)
B(4,-9,-6,CONCRETE:15)
B(4,-9,-5,CONCRETE:15)
B(4,-9,4,CONCRETE:15)
B(4,-9,5,CONCRETE:15)
B(4,-9,6,CONCRETE:15)
B(4,-9,7,CONCRETE:15)
B(4,-9,8,CONCRETE:15)
B(4,-9,9,CONCRETE:15)
B(4,-9,10,CONCRETE:15)
B(4,-9,11,CONCRETE:15)
B(4,-9,12,CONCRETE:15)
B(4,-9,13,CONCRETE:15)
B(4,-9,14,CONCRETE:15)
B(4,-8,-12,CONCRETE:15)
B(4,-8,-11,CONCRETE:15)
B(4,-8,-10,CONCRETE:15)
B(4,-8,-9,CONCRETE:15)
B(4,-8,-8,CONCRETE:15)
B(4,-8,-7,CONCRETE:15)
B(4,-8,-6,CONCRETE:15)
B(4,-8,-5,CONCRETE:15)
B(4,-8,-4,CONCRETE:15)
B(4,-8,-3,CONCRETE:15)
B(4,-8,-2,CONCRETE:15)
B(4,-8,-1,CONCRETE:15)
B(4,-8,0,CONCRETE:15)
B(4,-8,1,CONCRETE:15)
B(4,-8,2,CONCRETE:15)
B(4,-8,3,CONCRETE:15)
B(4,-8,4,CONCRETE:15)
B(4,-8,5,CONCRETE:15)
B(4,-8,6,CONCRETE:15)
B(4,-8,7,CONCRETE:15)
B(4,-8,8,CONCRETE:15)
B(4,-8,9,CONCRETE:15)
B(4,-8,10,CONCRETE:15)
B(4,-8,11,CONCRETE:15)
B(4,-8,12,CONCRETE:15)
B(4,-8,13,CONCRETE:15)
B(4,-8,14,CONCRETE:15)
B(4,-7,-12,CONCRETE:15)
B(4,-7,-11,CONCRETE:15)
B(4,-7,-10,CONCRETE:15)
B(4,-7,-9,CONCRETE:15)
B(4,-7,-8,CONCRETE:15)
B(4,-7,-7,CONCRETE:15)
B(4,-7,-6,CONCRETE:15)
B(4,-7,-5,CONCRETE:15)
B(4,-7,-4,CONCRETE:15)
B(4,-7,-3,CONCRETE:15)
B(4,-7,-2,CONCRETE:15)
B(4,-7,-1,CONCRETE:15)
B(4,-7,0,CONCRETE:15)
B(4,-7,1,CONCRETE:15)
B(4,-7,2,CONCRETE:15)
B(4,-7,3,CONCRETE:15)
B(4,-7,4,CONCRETE:15)
B(4,-7,5,CONCRETE:15)
B(4,-7,6,CONCRETE:15)
B(4,-7,7,CONCRETE:15)
B(4,-7,8,CONCRETE:15)
B(4,-7,9,CONCRETE:15)
B(4,-7,10,CONCRETE:15)
B(4,-7,11,CONCRETE:15)
B(4,-7,12,CONCRETE:15)
B(4,-7,13,CONCRETE:15)
B(4,-7,14,CONCRETE:15)
B(4,-6,-12,CONCRETE:15)
B(4,-6,-11,CONCRETE:15)
B(4,-6,-10,CONCRETE:15)
B(4,-6,-9,CONCRETE:15)
B(4,-6,-8,CONCRETE:15)
B(4,-6,-7,CONCRETE:15)
B(4,-6,-6,CONCRETE:15)
B(4,-6,-5,CONCRETE:15)
B(4,-6,-4,CONCRETE:15)
B(4,-6,7,CONCRETE:15)
B(4,-6,8,CONCRETE:15)
B(4,-6,9,CONCRETE:15)
B(4,-6,10,CONCRETE:15)
B(4,-6,11,CONCRETE:15)
B(4,-6,12,CONCRETE:15)
B(4,-6,13,CONCRETE:15)
B(4,-6,14,CONCRETE:15)
B(4,-5,-12,CONCRETE:15)
B(4,-5,-11,CONCRETE:15)
B(4,-5,-10,CONCRETE:15)
B(4,-5,-9,CONCRETE:15)
B(4,-5,-8,CONCRETE:15)
B(4,-5,-7,CONCRETE:15)
B(4,-5,-6,CONCRETE:15)
B(4,-5,-5,CONCRETE:15)
B(4,-5,7,CONCRETE:15)
B(4,-5,8,CONCRETE:15)
B(4,-5,9,CONCRETE:15)
B(4,-5,10,CONCRETE:15)
B(4,-5,11,CONCRETE:15)
B(4,-5,12,CONCRETE:15)
B(4,-5,13,CONCRETE:15)
B(4,-5,14,CONCRETE:15)
B(4,-4,-12,CONCRETE:15)
B(4,-4,-11,CONCRETE:15)
B(4,-4,-10,CONCRETE:15)
B(4,-4,-9,CONCRETE:15)
B(4,-4,-8,CONCRETE:15)
B(4,-4,-7,CONCRETE:15)
B(4,-4,-6,CONCRETE:15)
B(4,-4,-5,CONCRETE:15)
B(4,-4,-2,SNOW_BLOCK)
B(4,-4,-1,CONCRETE:15)
B(4,-4,8,CONCRETE:15)
B(4,-4,9,CONCRETE:15)
B(4,-4,10,CONCRETE:15)
B(4,-4,11,CONCRETE:15)
B(4,-4,12,CONCRETE:15)
B(4,-4,13,CONCRETE:15)
B(4,-4,14,CONCRETE:15)
B(4,-3,-12,CONCRETE:15)
B(4,-3,-11,CONCRETE:15)
B(4,-3,-10,CONCRETE:15)
B(4,-3,-9,CONCRETE:15)
B(4,-3,-8,CONCRETE:15)
B(4,-3,-7,CONCRETE:15)
B(4,-3,-6,CONCRETE:15)
B(4,-3,-5,SNOW_BLOCK)
B(4,-3,-4,SNOW_BLOCK)
B(4,-3,-3,SNOW_BLOCK)
B(4,-3,-2,CONCRETE:15)
B(4,-3,-1,CONCRETE:15)
B(4,-3,7,CONCRETE:15)
B(4,-3,8,CONCRETE:15)
B(4,-3,9,CONCRETE:15)
B(4,-3,10,CONCRETE:15)
B(4,-3,11,CONCRETE:15)
B(4,-3,12,CONCRETE:15)
B(4,-3,13,CONCRETE:15)
B(4,-3,14,CONCRETE:15)
B(4,-3,15,CONCRETE:15)
B(4,-2,-13,CONCRETE:15)
B(4,-2,-12,CONCRETE:15)
B(4,-2,-11,CONCRETE:15)
B(4,-2,-10,CONCRETE:15)
B(4,-2,-9,CONCRETE:15)
B(4,-2,-8,CONCRETE:15)
B(4,-2,-7,CONCRETE:15)
B(4,-2,-6,SNOW_BLOCK)
B(4,-2,-5,SNOW_BLOCK)
B(4,-2,-4,SNOW_BLOCK)
B(4,-2,-3,SNOW_BLOCK)
B(4,-2,-2,CONCRETE:15)
B(4,-2,-1,CONCRETE:15)
B(4,-2,1,CONCRETE:15)
B(4,-2,2,CONCRETE:15)
B(4,-2,3,CONCRETE:15)
B(4,-2,6,CONCRETE:15)
B(4,-2,7,CONCRETE:15)
B(4,-2,8,CONCRETE:15)
B(4,-2,9,CONCRETE:15)
B(4,-2,10,CONCRETE:15)
B(4,-2,11,CONCRETE:15)
B(4,-2,12,CONCRETE:15)
B(4,-2,13,CONCRETE:15)
B(4,-2,14,CONCRETE:15)
B(4,-2,15,CONCRETE:15)
B(4,-2,16,CONCRETE:15)
B(4,-1,-14,SNOW_BLOCK)
B(4,-1,-13,SNOW_BLOCK)
B(4,-1,-12,CONCRETE:15)
B(4,-1,-11,CONCRETE:15)
B(4,-1,-10,CONCRETE:15)
B(4,-1,-9,CONCRETE:15)
B(4,-1,-8,CONCRETE:15)
B(4,-1,-7,SNOW_BLOCK)
B(4,-1,-6,SNOW_BLOCK)
B(4,-1,-5,SNOW_BLOCK)
B(4,-1,-4,SNOW_BLOCK)
B(4,-1,-3,CONCRETE:15)
B(4,-1,-2,CONCRETE:15)
B(4,-1,-1,CONCRETE:15)
B(4,-1,0,CONCRETE:15)
B(4,-1,1,CONCRETE:15)
B(4,-1,2,CONCRETE:15)
B(4,-1,3,CONCRETE:15)
B(4,-1,4,CONCRETE:15)
B(4,-1,5,CONCRETE:15)
B(4,-1,6,CONCRETE:15)
B(4,-1,7,CONCRETE:15)
B(4,-1,8,CONCRETE:15)
B(4,-1,9,CONCRETE:15)
B(4,-1,10,CONCRETE:15)
B(4,-1,11,CONCRETE:15)
B(4,-1,12,CONCRETE:15)
B(4,-1,13,CONCRETE:15)
B(4,-1,14,CONCRETE:15)
B(4,-1,15,SNOW_BLOCK)
B(4,-1,16,SNOW_BLOCK)
B(4,0,-13,SNOW_BLOCK)
B(4,0,-12,SNOW_BLOCK)
B(4,0,-11,CONCRETE:15)
B(4,0,-10,CONCRETE:15)
B(4,0,-9,CONCRETE:15)
B(4,0,-8,CONCRETE:15)
B(4,0,-7,SNOW_BLOCK)
B(4,0,-6,SNOW_BLOCK)
B(4,0,-5,SNOW_BLOCK)
B(4,0,-4,SNOW_BLOCK)
B(4,0,-3,CONCRETE:15)
B(4,0,-2,CONCRETE:15)
B(4,0,-1,CONCRETE:15)
B(4,0,0,CONCRETE:15)
B(4,0,1,CONCRETE:15)
B(4,0,2,CONCRETE:15)
B(4,0,3,CONCRETE:15)
B(4,0,4,CONCRETE:15)
B(4,0,5,CONCRETE:15)
B(4,0,6,CONCRETE:15)
B(4,0,7,CONCRETE:15)
B(4,0,8,CONCRETE:15)
B(4,0,9,CONCRETE:15)
B(4,0,10,CONCRETE:15)
B(4,0,11,CONCRETE:15)
B(4,0,12,CONCRETE:15)
B(4,0,13,CONCRETE:15)
B(4,0,14,CONCRETE:15)
B(4,0,15,SNOW_BLOCK)
B(4,0,16,SNOW_BLOCK)
B(4,1,-13,SNOW_BLOCK)
B(4,1,-12,SNOW_BLOCK)
B(4,1,-11,CONCRETE:15)
B(4,1,-10,CONCRETE:15)
B(4,1,-9,CONCRETE:15)
B(4,1,-8,CONCRETE:15)
B(4,1,-7,SNOW_BLOCK)
B(4,1,-6,SNOW_BLOCK)
B(4,1,-5,SNOW_BLOCK)
B(4,1,-4,CONCRETE:15)
B(4,1,-3,SNOW_BLOCK)
B(4,1,-2,SNOW_BLOCK)
B(4,1,-1,SNOW_BLOCK)
B(4,1,0,SNOW_BLOCK)
B(4,1,2,CONCRETE:15)
B(4,1,3,CONCRETE:15)
B(4,1,4,CONCRETE:15)
B(4,1,5,CONCRETE:15)
B(4,1,6,CONCRETE:15)
B(4,1,7,CONCRETE:15)
B(4,1,8,CONCRETE:15)
B(4,1,9,CONCRETE:15)
B(4,1,10,CONCRETE:15)
B(4,1,11,CONCRETE:15)
B(4,1,12,CONCRETE:15)
B(4,1,13,SNOW_BLOCK)
B(4,1,14,SNOW_BLOCK)
B(4,1,15,SNOW_BLOCK)
B(4,2,-12,SNOW_BLOCK)
B(4,2,-11,CONCRETE:15)
B(4,2,-10,CONCRETE:15)
B(4,2,-9,CONCRETE:15)
B(4,2,-8,CONCRETE:15)
B(4,2,-7,SNOW_BLOCK)
B(4,2,-6,SNOW_BLOCK)
B(4,2,-5,SNOW_BLOCK)
B(4,2,-4,SNOW_BLOCK)
B(4,2,-3,SNOW_BLOCK)
B(4,2,-2,SNOW_BLOCK)
B(4,2,-1,SNOW_BLOCK)
B(4,2,0,SNOW_BLOCK)
B(4,2,4,SNOW_BLOCK)
B(4,2,5,CONCRETE:15)
B(4,2,6,CONCRETE:15)
B(4,2,7,CONCRETE:15)
B(4,2,8,CONCRETE:15)
B(4,2,9,CONCRETE:15)
B(4,2,10,CONCRETE:15)
B(4,2,11,CONCRETE:15)
B(4,2,12,SNOW_BLOCK)
B(4,2,13,SNOW_BLOCK)
B(4,2,14,SNOW_BLOCK)
B(4,3,-11,CONCRETE:15)
B(4,3,-10,CONCRETE:15)
B(4,3,-9,CONCRETE:15)
B(4,3,-8,CONCRETE:15)
B(4,3,-7,SNOW_BLOCK)
B(4,3,-6,SNOW_BLOCK)
B(4,3,-5,SNOW_BLOCK)
B(4,3,-4,SNOW_BLOCK)
B(4,3,-3,SNOW_BLOCK)
B(4,3,-2,SNOW_BLOCK)
B(4,3,-1,SNOW_BLOCK)
B(4,3,6,CONCRETE:15)
B(4,3,7,CONCRETE:15)
B(4,3,8,CONCRETE:15)
B(4,3,9,CONCRETE:15)
B(4,3,10,CONCRETE:15)
B(4,3,11,CONCRETE:15)
B(4,3,12,SNOW_BLOCK)
B(4,3,13,SNOW_BLOCK)
B(4,4,-10,CONCRETE:15)
B(4,4,-9,CONCRETE:15)
B(4,4,-8,CONCRETE:15)
B(4,4,-7,CONCRETE:15)
B(4,4,-6,SNOW_BLOCK)
B(4,4,-5,SNOW_BLOCK)
B(4,4,-4,SNOW_BLOCK)
B(4,4,-3,CONCRETE:15)
B(4,4,6,CONCRETE:15)
B(4,4,7,CONCRETE:15)
B(4,4,8,CONCRETE:15)
B(4,4,9,CONCRETE:15)
B(4,4,10,CONCRETE:15)
B(4,4,11,CONCRETE:15)
B(4,4,12,SNOW_BLOCK)
B(4,5,-8,CONCRETE:15)
B(4,5,-7,CONCRETE:15)
B(4,5,-6,CONCRETE:15)
B(4,5,-5,CONCRETE:15)
B(4,5,-4,CONCRETE:15)
B(4,5,7,CONCRETE:15)
B(4,5,8,CONCRETE:15)
B(4,5,9,CONCRETE:15)
B(4,5,10,CONCRETE:15)
B(4,5,11,CONCRETE:15)
B(4,6,8,CONCRETE:15)
B(5,-12,7,CONCRETE:15)
B(5,-12,8,CONCRETE:15)
B(5,-12,9,CONCRETE:15)
B(5,-12,10,CONCRETE:15)
B(5,-12,11,CONCRETE:15)
B(5,-12,12,CONCRETE:15)
B(5,-11,-8,CONCRETE:15)
B(5,-11,-7,CONCRETE:15)
B(5,-11,6,CONCRETE:15)
B(5,-11,7,CONCRETE:15)
B(5,-11,8,CONCRETE:15)
B(5,-11,9,CONCRETE:15)
B(5,-11,10,CONCRETE:15)
B(5,-11,11,CONCRETE:15)
B(5,-11,12,CONCRETE:15)
B(5,-11,13,CONCRETE:15)
B(5,-10,-10,CONCRETE:15)
B(5,-10,-9,CONCRETE:15)
B(5,-10,-8,CONCRETE:15)
B(5,-10,-7,CONCRETE:15)
B(5,-10,-6,CONCRETE:15)
B(5,-10,2,CONCRETE:15)
B(5,-10,3,CONCRETE:15)
B(5,-10,4,CONCRETE:15)
B(5,-10,5,CONCRETE:15)
B(5,-10,6,CONCRETE:15)
B(5,-10,7,CONCRETE:15)
B(5,-10,8,CONCRETE:15)
B(5,-10,9,CONCRETE:15)
B(5,-10,10,CONCRETE:15)
B(5,-10,11,CONCRETE:15)
B(5,-10,12,CONCRETE:15)
B(5,-10,13,CONCRETE:15)
B(5,-9,-11,CONCRETE:15)
B(5,-9,-10,CONCRETE:15)
B(5,-9,-9,CONCRETE:15)
B(5,-9,-8,CONCRETE:15)
B(5,-9,-7,CONCRETE:15)
B(5,-9,-6,CONCRETE:15)
B(5,-9,-5,CONCRETE:15)
B(5,-9,-4,CONCRETE:15)
B(5,-9,-3,CONCRETE:15)
B(5,-9,-2,CONCRETE:15)
B(5,-9,-1,CONCRETE:15)
B(5,-9,0,CONCRETE:15)
B(5,-9,1,CONCRETE:15)
B(5,-9,2,CONCRETE:15)
B(5,-9,3,CONCRETE:15)
B(5,-9,4,CONCRETE:15)
B(5,-9,5,CONCRETE:15)
B(5,-9,6,CONCRETE:15)
B(5,-9,7,CONCRETE:15)
B(5,-9,8,CONCRETE:15)
B(5,-9,9,CONCRETE:15)
B(5,-9,10,CONCRETE:15)
B(5,-9,11,CONCRETE:15)
B(5,-9,12,CONCRETE:15)
B(5,-9,13,CONCRETE:15)
B(5,-8,-11,CONCRETE:15)
B(5,-8,-10,CONCRETE:15)
B(5,-8,-9,CONCRETE:15)
B(5,-8,-8,CONCRETE:15)
B(5,-8,-7,CONCRETE:15)
B(5,-8,-6,CONCRETE:15)
B(5,-8,-5,CONCRETE:15)
B(5,-8,-4,CONCRETE:15)
B(5,-8,-3,CONCRETE:15)
B(5,-8,-2,CONCRETE:15)
B(5,-8,-1,CONCRETE:15)
B(5,-8,0,CONCRETE:15)
B(5,-8,1,CONCRETE:15)
B(5,-8,2,CONCRETE:15)
B(5,-8,3,CONCRETE:15)
B(5,-8,4,CONCRETE:15)
B(5,-8,5,CONCRETE:15)
B(5,-8,6,CONCRETE:15)
B(5,-8,7,CONCRETE:15)
B(5,-8,8,CONCRETE:15)
B(5,-8,9,CONCRETE:15)
B(5,-8,10,CONCRETE:15)
B(5,-8,11,CONCRETE:15)
B(5,-8,12,CONCRETE:15)
B(5,-8,13,CONCRETE:15)
B(5,-7,-11,CONCRETE:15)
B(5,-7,-10,CONCRETE:15)
B(5,-7,-9,CONCRETE:15)
B(5,-7,-8,CONCRETE:15)
B(5,-7,-7,CONCRETE:15)
B(5,-7,-6,CONCRETE:15)
B(5,-7,-5,CONCRETE:15)
B(5,-7,-4,CONCRETE:15)
B(5,-7,-3,CONCRETE:15)
B(5,-7,-2,CONCRETE:15)
B(5,-7,-1,CONCRETE:15)
B(5,-7,0,CONCRETE:15)
B(5,-7,1,CONCRETE:15)
B(5,-7,2,CONCRETE:15)
B(5,-7,3,CONCRETE:15)
B(5,-7,4,CONCRETE:15)
B(5,-7,5,CONCRETE:15)
B(5,-7,6,CONCRETE:15)
B(5,-7,7,CONCRETE:15)
B(5,-7,8,CONCRETE:15)
B(5,-7,9,CONCRETE:15)
B(5,-7,10,CONCRETE:15)
B(5,-7,11,CONCRETE:15)
B(5,-7,12,CONCRETE:15)
B(5,-7,13,CONCRETE:15)
B(5,-6,-12,CONCRETE:15)
B(5,-6,-11,CONCRETE:15)
B(5,-6,-10,CONCRETE:15)
B(5,-6,-9,CONCRETE:15)
B(5,-6,-8,CONCRETE:15)
B(5,-6,-7,CONCRETE:15)
B(5,-6,-6,CONCRETE:15)
B(5,-6,-5,CONCRETE:15)
B(5,-6,-4,CONCRETE:15)
B(5,-6,-3,CONCRETE:15)
B(5,-6,-2,CONCRETE:15)
B(5,-6,-1,CONCRETE:15)
B(5,-6,0,CONCRETE:15)
B(5,-6,1,CONCRETE:15)
B(5,-6,2,CONCRETE:15)
B(5,-6,3,CONCRETE:15)
B(5,-6,4,CONCRETE:15)
B(5,-6,5,CONCRETE:15)
B(5,-6,6,CONCRETE:15)
B(5,-6,7,CONCRETE:15)
B(5,-6,8,CONCRETE:15)
B(5,-6,9,CONCRETE:15)
B(5,-6,10,CONCRETE:15)
B(5,-6,11,CONCRETE:15)
B(5,-6,12,CONCRETE:15)
B(5,-6,13,CONCRETE:15)
B(5,-6,14,CONCRETE:15)
B(5,-5,-12,CONCRETE:15)
B(5,-5,-11,CONCRETE:15)
B(5,-5,-10,CONCRETE:15)
B(5,-5,-9,CONCRETE:15)
B(5,-5,-8,CONCRETE:15)
B(5,-5,-7,CONCRETE:15)
B(5,-5,-6,CONCRETE:15)
B(5,-5,-5,CONCRETE:15)
B(5,-5,-4,CONCRETE:15)
B(5,-5,-3,SNOW_BLOCK)
B(5,-5,-2,SNOW_BLOCK)
B(5,-5,-1,CONCRETE:15)
B(5,-5,0,CONCRETE:15)
B(5,-5,1,CONCRETE:15)
B(5,-5,2,CONCRETE:15)
B(5,-5,3,CONCRETE:15)
B(5,-5,6,CONCRETE:15)
B(5,-5,7,CONCRETE:15)
B(5,-5,8,CONCRETE:15)
B(5,-5,9,CONCRETE:15)
B(5,-5,10,CONCRETE:15)
B(5,-5,11,CONCRETE:15)
B(5,-5,12,CONCRETE:15)
B(5,-5,13,CONCRETE:15)
B(5,-5,14,CONCRETE:15)
B(5,-4,-12,CONCRETE:15)
B(5,-4,-11,CONCRETE:15)
B(5,-4,-10,CONCRETE:15)
B(5,-4,-9,CONCRETE:15)
B(5,-4,-8,CONCRETE:15)
B(5,-4,-7,CONCRETE:15)
B(5,-4,-6,CONCRETE:15)
B(5,-4,-5,CONCRETE:15)
B(5,-4,-4,SNOW_BLOCK)
B(5,-4,-3,SNOW_BLOCK)
B(5,-4,-2,SNOW_BLOCK)
B(5,-4,-1,CONCRETE:15)
B(5,-4,0,CONCRETE:15)
B(5,-4,1,CONCRETE:15)
B(5,-4,2,CONCRETE:15)
B(5,-4,7,CONCRETE:15)
B(5,-4,8,CONCRETE:15)
B(5,-4,9,CONCRETE:15)
B(5,-4,10,CONCRETE:15)
B(5,-4,11,CONCRETE:15)
B(5,-4,12,CONCRETE:15)
B(5,-4,13,CONCRETE:15)
B(5,-4,14,CONCRETE:15)
B(5,-3,-11,CONCRETE:15)
B(5,-3,-10,CONCRETE:15)
B(5,-3,-9,CONCRETE:15)
B(5,-3,-8,CONCRETE:15)
B(5,-3,-7,CONCRETE:15)
B(5,-3,-6,CONCRETE:15)
B(5,-3,-5,SNOW_BLOCK)
B(5,-3,-4,SNOW_BLOCK)
B(5,-3,-3,SNOW_BLOCK)
B(5,-3,-2,CONCRETE:15)
B(5,-3,-1,CONCRETE:15)
B(5,-3,0,CONCRETE:15)
B(5,-3,1,CONCRETE:15)
B(5,-3,2,CONCRETE:15)
B(5,-3,3,CONCRETE:15)
B(5,-3,4,CONCRETE:15)
B(5,-3,6,CONCRETE:15)
B(5,-3,7,CONCRETE:15)
B(5,-3,8,CONCRETE:15)
B(5,-3,9,CONCRETE:15)
B(5,-3,10,CONCRETE:15)
B(5,-3,11,CONCRETE:15)
B(5,-3,12,CONCRETE:15)
B(5,-3,13,CONCRETE:15)
B(5,-3,14,CONCRETE:15)
B(5,-3,15,CONCRETE:15)
B(5,-2,-13,CONCRETE:15)
B(5,-2,-12,CONCRETE:15)
B(5,-2,-11,CONCRETE:15)
B(5,-2,-10,CONCRETE:15)
B(5,-2,-9,CONCRETE:15)
B(5,-2,-8,CONCRETE:15)
B(5,-2,-7,CONCRETE:15)
B(5,-2,-6,CONCRETE:15)
B(5,-2,-5,SNOW_BLOCK)
B(5,-2,-4,SNOW_BLOCK)
B(5,-2,-3,SNOW_BLOCK)
B(5,-2,-2,CONCRETE:15)
B(5,-2,-1,CONCRETE:15)
B(5,-2,0,CONCRETE:15)
B(5,-2,1,CONCRETE:15)
B(5,-2,2,CONCRETE:15)
B(5,-2,3,CONCRETE:15)
B(5,-2,4,CONCRETE:15)
B(5,-2,5,CONCRETE:15)
B(5,-2,6,CONCRETE:15)
B(5,-2,7,CONCRETE:15)
B(5,-2,8,CONCRETE:15)
B(5,-2,9,CONCRETE:15)
B(5,-2,10,CONCRETE:15)
B(5,-2,11,CONCRETE:15)
B(5,-2,12,CONCRETE:15)
B(5,-2,13,CONCRETE:15)
B(5,-2,14,CONCRETE:15)
B(5,-2,15,CONCRETE:15)
B(5,-2,16,CONCRETE:15)
B(5,-1,-13,CONCRETE:15)
B(5,-1,-12,CONCRETE:15)
B(5,-1,-11,CONCRETE:15)
B(5,-1,-10,CONCRETE:15)
B(5,-1,-9,CONCRETE:15)
B(5,-1,-8,CONCRETE:15)
B(5,-1,-7,CONCRETE:15)
B(5,-1,-6,CONCRETE:15)
B(5,-1,-5,CONCRETE:15)
B(5,-1,-4,CONCRETE:15)
B(5,-1,-3,CONCRETE:15)
B(5,-1,-2,CONCRETE:15)
B(5,-1,-1,CONCRETE:15)
B(5,-1,0,CONCRETE:15)
B(5,-1,1,CONCRETE:15)
B(5,-1,2,CONCRETE:15)
B(5,-1,3,CONCRETE:15)
B(5,-1,4,CONCRETE:15)
B(5,-1,5,CONCRETE:15)
B(5,-1,6,CONCRETE:15)
B(5,-1,7,CONCRETE:15)
B(5,-1,8,CONCRETE:15)
B(5,-1,9,CONCRETE:15)
B(5,-1,10,CONCRETE:15)
B(5,-1,11,CONCRETE:15)
B(5,-1,12,CONCRETE:15)
B(5,-1,13,CONCRETE:15)
B(5,-1,14,CONCRETE:15)
B(5,-1,15,SNOW_BLOCK)
B(5,-1,16,SNOW_BLOCK)
B(5,0,-13,SNOW_BLOCK)
B(5,0,-12,SNOW_BLOCK)
B(5,0,-11,SNOW_BLOCK)
B(5,0,-10,SNOW_BLOCK)
B(5,0,-9,CONCRETE:15)
B(5,0,-8,CONCRETE:15)
B(5,0,-7,CONCRETE:15)
B(5,0,-6,CONCRETE:15)
B(5,0,-5,CONCRETE:15)
B(5,0,-4,CONCRETE:15)
B(5,0,-3,CONCRETE:15)
B(5,0,-2,CONCRETE:15)
B(5,0,-1,CONCRETE:15)
B(5,0,0,CONCRETE:15)
B(5,0,1,CONCRETE:15)
B(5,0,2,CONCRETE:15)
B(5,0,3,CONCRETE:15)
B(5,0,4,CONCRETE:15)
B(5,0,5,CONCRETE:15)
B(5,0,6,CONCRETE:15)
B(5,0,7,CONCRETE:15)
B(5,0,8,CONCRETE:15)
B(5,0,9,CONCRETE:15)
B(5,0,10,CONCRETE:15)
B(5,0,11,CONCRETE:15)
B(5,0,12,CONCRETE:15)
B(5,0,13,CONCRETE:15)
B(5,0,14,CONCRETE:15)
B(5,0,15,SNOW_BLOCK)
B(5,1,-13,SNOW_BLOCK)
B(5,1,-12,SNOW_BLOCK)
B(5,1,-11,SNOW_BLOCK)
B(5,1,-10,SNOW_BLOCK)
B(5,1,-9,CONCRETE:15)
B(5,1,-8,CONCRETE:15)
B(5,1,-7,CONCRETE:15)
B(5,1,-6,CONCRETE:15)
B(5,1,-5,CONCRETE:15)
B(5,1,-4,CONCRETE:15)
B(5,1,-3,SNOW_BLOCK)
B(5,1,-2,SNOW_BLOCK)
B(5,1,-1,SNOW_BLOCK)
B(5,1,0,SNOW_BLOCK)
B(5,1,1,SNOW_BLOCK)
B(5,1,2,CONCRETE:15)
B(5,1,3,CONCRETE:15)
B(5,1,4,CONCRETE:15)
B(5,1,5,CONCRETE:15)
B(5,1,6,CONCRETE:15)
B(5,1,7,CONCRETE:15)
B(5,1,8,CONCRETE:15)
B(5,1,9,CONCRETE:15)
B(5,1,10,CONCRETE:15)
B(5,1,11,CONCRETE:15)
B(5,1,12,CONCRETE:15)
B(5,1,13,SNOW_BLOCK)
B(5,1,14,SNOW_BLOCK)
B(5,1,15,SNOW_BLOCK)
B(5,2,-12,SNOW_BLOCK)
B(5,2,-11,SNOW_BLOCK)
B(5,2,-10,SNOW_BLOCK)
B(5,2,-9,CONCRETE:15)
B(5,2,-8,CONCRETE:15)
B(5,2,-7,CONCRETE:15)
B(5,2,-6,CONCRETE:15)
B(5,2,-5,CONCRETE:15)
B(5,2,-4,CONCRETE:15)
B(5,2,-3,SNOW_BLOCK)
B(5,2,-2,SNOW_BLOCK)
B(5,2,-1,SNOW_BLOCK)
B(5,2,0,SNOW_BLOCK)
B(5,2,1,SNOW_BLOCK)
B(5,2,2,SNOW_BLOCK)
B(5,2,3,SNOW_BLOCK)
B(5,2,4,SNOW_BLOCK)
B(5,2,5,CONCRETE:15)
B(5,2,6,CONCRETE:15)
B(5,2,7,CONCRETE:15)
B(5,2,8,CONCRETE:15)
B(5,2,9,CONCRETE:15)
B(5,2,10,CONCRETE:15)
B(5,2,11,SNOW_BLOCK)
B(5,2,12,SNOW_BLOCK)
B(5,2,13,SNOW_BLOCK)
B(5,2,14,SNOW_BLOCK)
B(5,3,-10,CONCRETE:15)
B(5,3,-9,CONCRETE:15)
B(5,3,-8,CONCRETE:15)
B(5,3,-7,CONCRETE:15)
B(5,3,-6,CONCRETE:15)
B(5,3,-5,CONCRETE:15)
B(5,3,-4,CONCRETE:15)
B(5,3,-3,SNOW_BLOCK)
B(5,3,-2,SNOW_BLOCK)
B(5,3,-1,SNOW_BLOCK)
B(5,3,0,SNOW_BLOCK)
B(5,3,1,SNOW_BLOCK)
B(5,3,2,SNOW_BLOCK)
B(5,3,3,SNOW_BLOCK)
B(5,3,4,SNOW_BLOCK)
B(5,3,5,CONCRETE:15)
B(5,3,6,CONCRETE:15)
B(5,3,7,CONCRETE:15)
B(5,3,8,CONCRETE:15)
B(5,3,9,CONCRETE:15)
B(5,3,10,CONCRETE:15)
B(5,3,11,SNOW_BLOCK)
B(5,3,12,SNOW_BLOCK)
B(5,3,13,SNOW_BLOCK)
B(5,4,-10,CONCRETE:15)
B(5,4,-9,CONCRETE:15)
B(5,4,-8,CONCRETE:15)
B(5,4,-7,CONCRETE:15)
B(5,4,-6,CONCRETE:15)
B(5,4,-5,CONCRETE:15)
B(5,4,-4,CONCRETE:15)
B(5,4,-3,CONCRETE:15)
B(5,4,-2,CONCRETE:15)
B(5,4,-1,CONCRETE:15)
B(5,4,5,CONCRETE:15)
B(5,4,6,CONCRETE:15)
B(5,4,7,CONCRETE:15)
B(5,4,8,CONCRETE:15)
B(5,4,9,CONCRETE:15)
B(5,4,10,CONCRETE:15)
B(5,4,11,SNOW_BLOCK)
B(5,4,12,SNOW_BLOCK)
B(5,5,-9,CONCRETE:15)
B(5,5,-8,CONCRETE:15)
B(5,5,-7,CONCRETE:15)
B(5,5,-6,CONCRETE:15)
B(5,5,-5,CONCRETE:15)
B(5,5,-4,CONCRETE:15)
B(5,5,-3,CONCRETE:15)
B(5,5,-2,CONCRETE:15)
B(5,5,6,CONCRETE:15)
B(5,5,7,CONCRETE:15)
B(5,5,8,CONCRETE:15)
B(5,5,9,CONCRETE:15)
B(5,5,10,CONCRETE:15)
B(5,5,11,CONCRETE:15)
B(5,6,-5,CONCRETE:15)
B(5,6,7,CONCRETE:15)
B(5,6,8,CONCRETE:15)
B(6,-12,7,CONCRETE:15)
B(6,-12,8,CONCRETE:15)
B(6,-12,9,CONCRETE:15)
B(6,-11,1,CONCRETE:15)
B(6,-11,2,CONCRETE:15)
B(6,-11,3,CONCRETE:15)
B(6,-11,4,CONCRETE:15)
B(6,-11,5,CONCRETE:15)
B(6,-11,6,CONCRETE:15)
B(6,-11,7,CONCRETE:15)
B(6,-11,8,CONCRETE:15)
B(6,-11,9,CONCRETE:15)
B(6,-11,10,CONCRETE:15)
B(6,-11,11,CONCRETE:15)
B(6,-10,-9,CONCRETE:15)
B(6,-10,-8,CONCRETE:15)
B(6,-10,-7,CONCRETE:15)
B(6,-10,-6,CONCRETE:15)
B(6,-10,-1,CONCRETE:15)
B(6,-10,0,CONCRETE:15)
B(6,-10,1,CONCRETE:15)
B(6,-10,2,CONCRETE:15)
B(6,-10,3,CONCRETE:15)
B(6,-10,4,CONCRETE:15)
B(6,-10,5,CONCRETE:15)
B(6,-10,6,CONCRETE:15)
B(6,-10,7,CONCRETE:15)
B(6,-10,8,CONCRETE:15)
B(6,-10,9,CONCRETE:15)
B(6,-10,10,CONCRETE:15)
B(6,-10,11,CONCRETE:15)
B(6,-10,12,CONCRETE:15)
B(6,-9,-9,CONCRETE:15)
B(6,-9,-8,CONCRETE:15)
B(6,-9,-7,CONCRETE:15)
B(6,-9,-6,CONCRETE:15)
B(6,-9,-5,CONCRETE:15)
B(6,-9,-4,CONCRETE:15)
B(6,-9,-3,CONCRETE:15)
B(6,-9,-2,CONCRETE:15)
B(6,-9,-1,CONCRETE:15)
B(6,-9,0,CONCRETE:15)
B(6,-9,1,CONCRETE:15)
B(6,-9,2,CONCRETE:15)
B(6,-9,3,CONCRETE:15)
B(6,-9,4,CONCRETE:15)
B(6,-9,5,CONCRETE:15)
B(6,-9,6,CONCRETE:15)
B(6,-9,7,CONCRETE:15)
B(6,-9,8,CONCRETE:15)
B(6,-9,9,CONCRETE:15)
B(6,-9,10,CONCRETE:15)
B(6,-9,11,CONCRETE:15)
B(6,-9,12,CONCRETE:15)
B(6,-9,13,CONCRETE:15)
B(6,-8,-10,CONCRETE:15)
B(6,-8,-9,CONCRETE:15)
B(6,-8,-8,CONCRETE:15)
B(6,-8,-7,CONCRETE:15)
B(6,-8,-6,CONCRETE:15)
B(6,-8,-5,CONCRETE:15)
B(6,-8,-4,CONCRETE:15)
B(6,-8,-3,CONCRETE:15)
B(6,-8,-2,CONCRETE:15)
B(6,-8,-1,CONCRETE:15)
B(6,-8,0,CONCRETE:15)
B(6,-8,1,CONCRETE:15)
B(6,-8,2,CONCRETE:15)
B(6,-8,3,CONCRETE:15)
B(6,-8,4,CONCRETE:15)
B(6,-8,5,CONCRETE:15)
B(6,-8,6,CONCRETE:15)
B(6,-8,7,CONCRETE:15)
B(6,-8,8,CONCRETE:15)
B(6,-8,9,CONCRETE:15)
B(6,-8,10,CONCRETE:15)
B(6,-8,11,CONCRETE:15)
B(6,-8,12,CONCRETE:15)
B(6,-8,13,CONCRETE:15)
B(6,-7,-11,CONCRETE:15)
B(6,-7,-10,CONCRETE:15)
B(6,-7,-9,CONCRETE:15)
B(6,-7,-8,CONCRETE:15)
B(6,-7,-7,CONCRETE:15)
B(6,-7,-6,CONCRETE:15)
B(6,-7,-5,CONCRETE:15)
B(6,-7,-4,CONCRETE:15)
B(6,-7,-3,CONCRETE:15)
B(6,-7,-2,CONCRETE:15)
B(6,-7,-1,CONCRETE:15)
B(6,-7,0,CONCRETE:15)
B(6,-7,1,CONCRETE:15)
B(6,-7,2,CONCRETE:15)
B(6,-7,3,CONCRETE:15)
B(6,-7,4,CONCRETE:15)
B(6,-7,5,CONCRETE:15)
B(6,-7,6,CONCRETE:15)
B(6,-7,7,CONCRETE:15)
B(6,-7,8,CONCRETE:15)
B(6,-7,9,CONCRETE:15)
B(6,-7,10,CONCRETE:15)
B(6,-7,11,CONCRETE:15)
B(6,-7,12,CONCRETE:15)
B(6,-7,13,CONCRETE:15)
B(6,-6,-12,CONCRETE:15)
B(6,-6,-11,CONCRETE:15)
B(6,-6,-10,CONCRETE:15)
B(6,-6,-9,CONCRETE:15)
B(6,-6,-8,CONCRETE:15)
B(6,-6,-7,CONCRETE:15)
B(6,-6,-6,CONCRETE:15)
B(6,-6,-5,CONCRETE:15)
B(6,-6,-4,CONCRETE:15)
B(6,-6,-3,CONCRETE:15)
B(6,-6,-2,CONCRETE:15)
B(6,-6,-1,CONCRETE:15)
B(6,-6,0,CONCRETE:15)
B(6,-6,1,CONCRETE:15)
B(6,-6,2,CONCRETE:15)
B(6,-6,3,CONCRETE:15)
B(6,-6,4,CONCRETE:15)
B(6,-6,5,CONCRETE:15)
B(6,-6,6,CONCRETE:15)
B(6,-6,7,CONCRETE:15)
B(6,-6,8,CONCRETE:15)
B(6,-6,9,CONCRETE:15)
B(6,-6,10,CONCRETE:15)
B(6,-6,11,CONCRETE:15)
B(6,-6,12,CONCRETE:15)
B(6,-6,13,CONCRETE:15)
B(6,-5,-12,CONCRETE:15)
B(6,-5,-11,CONCRETE:15)
B(6,-5,-10,CONCRETE:15)
B(6,-5,-9,CONCRETE:15)
B(6,-5,-8,CONCRETE:15)
B(6,-5,-7,CONCRETE:15)
B(6,-5,-6,CONCRETE:15)
B(6,-5,-5,CONCRETE:15)
B(6,-5,-4,CONCRETE:15)
B(6,-5,-3,SNOW_BLOCK)
B(6,-5,-2,SNOW_BLOCK)
B(6,-5,-1,CONCRETE:15)
B(6,-5,0,CONCRETE:15)
B(6,-5,1,CONCRETE:15)
B(6,-5,2,CONCRETE:15)
B(6,-5,3,CONCRETE:15)
B(6,-5,4,CONCRETE:15)
B(6,-5,5,CONCRETE:15)
B(6,-5,6,CONCRETE:15)
B(6,-5,7,CONCRETE:15)
B(6,-5,8,CONCRETE:15)
B(6,-5,9,CONCRETE:15)
B(6,-5,10,CONCRETE:15)
B(6,-5,11,CONCRETE:15)
B(6,-5,12,CONCRETE:15)
B(6,-5,13,CONCRETE:15)
B(6,-4,-12,CONCRETE:15)
B(6,-4,-11,CONCRETE:15)
B(6,-4,-10,CONCRETE:15)
B(6,-4,-9,CONCRETE:15)
B(6,-4,-8,CONCRETE:15)
B(6,-4,-7,CONCRETE:15)
B(6,-4,-6,CONCRETE:15)
B(6,-4,-5,CONCRETE:15)
B(6,-4,-4,SNOW_BLOCK)
B(6,-4,-3,SNOW_BLOCK)
B(6,-4,-2,SNOW_BLOCK)
B(6,-4,-1,CONCRETE:15)
B(6,-4,0,CONCRETE:15)
B(6,-4,1,CONCRETE:15)
B(6,-4,2,CONCRETE:15)
B(6,-4,3,CONCRETE:15)
B(6,-4,4,CONCRETE:15)
B(6,-4,5,CONCRETE:15)
B(6,-4,6,CONCRETE:15)
B(6,-4,7,CONCRETE:15)
B(6,-4,8,CONCRETE:15)
B(6,-4,9,CONCRETE:15)
B(6,-4,10,CONCRETE:15)
B(6,-4,11,CONCRETE:15)
B(6,-4,12,CONCRETE:15)
B(6,-4,13,CONCRETE:15)
B(6,-3,-11,CONCRETE:15)
B(6,-3,-10,CONCRETE:15)
B(6,-3,-9,CONCRETE:15)
B(6,-3,-8,CONCRETE:15)
B(6,-3,-7,CONCRETE:15)
B(6,-3,-6,CONCRETE:15)
B(6,-3,-5,CONCRETE:15)
B(6,-3,-4,CONCRETE:15)
B(6,-3,-3,CONCRETE:15)
B(6,-3,-2,CONCRETE:15)
B(6,-3,-1,CONCRETE:15)
B(6,-3,0,CONCRETE:15)
B(6,-3,1,CONCRETE:15)
B(6,-3,2,CONCRETE:15)
B(6,-3,3,CONCRETE:15)
B(6,-3,4,CONCRETE:15)
B(6,-3,5,CONCRETE:15)
B(6,-3,6,CONCRETE:15)
B(6,-3,7,CONCRETE:15)
B(6,-3,8,CONCRETE:15)
B(6,-3,9,CONCRETE:15)
B(6,-3,10,CONCRETE:15)
B(6,-3,11,CONCRETE:15)
B(6,-3,12,CONCRETE:15)
B(6,-3,13,CONCRETE:15)
B(6,-3,14,CONCRETE:15)
B(6,-3,15,CONCRETE:15)
B(6,-2,-11,CONCRETE:15)
B(6,-2,-10,CONCRETE:15)
B(6,-2,-9,CONCRETE:15)
B(6,-2,-8,CONCRETE:15)
B(6,-2,-7,CONCRETE:15)
B(6,-2,-6,CONCRETE:15)
B(6,-2,-5,CONCRETE:15)
B(6,-2,-4,CONCRETE:15)
B(6,-2,-3,CONCRETE:15)
B(6,-2,-2,CONCRETE:15)
B(6,-2,-1,CONCRETE:15)
B(6,-2,0,CONCRETE:15)
B(6,-2,1,CONCRETE:15)
B(6,-2,2,CONCRETE:15)
B(6,-2,3,CONCRETE:15)
B(6,-2,4,CONCRETE:15)
B(6,-2,5,CONCRETE:15)
B(6,-2,6,CONCRETE:15)
B(6,-2,7,CONCRETE:15)
B(6,-2,8,CONCRETE:15)
B(6,-2,9,CONCRETE:15)
B(6,-2,10,CONCRETE:15)
B(6,-2,11,CONCRETE:15)
B(6,-2,12,CONCRETE:15)
B(6,-2,13,CONCRETE:15)
B(6,-2,14,CONCRETE:15)
B(6,-2,15,CONCRETE:15)
B(6,-1,-12,CONCRETE:15)
B(6,-1,-11,CONCRETE:15)
B(6,-1,-10,CONCRETE:15)
B(6,-1,-9,CONCRETE:15)
B(6,-1,-8,CONCRETE:15)
B(6,-1,-7,CONCRETE:15)
B(6,-1,-6,CONCRETE:15)
B(6,-1,-5,CONCRETE:15)
B(6,-1,-4,CONCRETE:15)
B(6,-1,-3,CONCRETE:15)
B(6,-1,-2,CONCRETE:15)
B(6,-1,-1,CONCRETE:15)
B(6,-1,0,CONCRETE:15)
B(6,-1,1,CONCRETE:15)
B(6,-1,2,CONCRETE:15)
B(6,-1,3,CONCRETE:15)
B(6,-1,4,CONCRETE:15)
B(6,-1,5,CONCRETE:15)
B(6,-1,6,CONCRETE:15)
B(6,-1,7,CONCRETE:15)
B(6,-1,8,CONCRETE:15)
B(6,-1,9,CONCRETE:15)
B(6,-1,10,CONCRETE:15)
B(6,-1,11,CONCRETE:15)
B(6,-1,12,SNOW_BLOCK)
B(6,-1,13,SNOW_BLOCK)
B(6,-1,14,SNOW_BLOCK)
B(6,-1,15,CONCRETE:15)
B(6,0,-12,SNOW_BLOCK)
B(6,0,-11,SNOW_BLOCK)
B(6,0,-10,SNOW_BLOCK)
B(6,0,-9,CONCRETE:15)
B(6,0,-8,CONCRETE:15)
B(6,0,-7,CONCRETE:15)
B(6,0,-6,CONCRETE:15)
B(6,0,-5,CONCRETE:15)
B(6,0,-4,CONCRETE:15)
B(6,0,-3,CONCRETE:15)
B(6,0,-2,CONCRETE:15)
B(6,0,-1,CONCRETE:15)
B(6,0,0,CONCRETE:15)
B(6,0,1,CONCRETE:15)
B(6,0,2,CONCRETE:15)
B(6,0,3,CONCRETE:15)
B(6,0,4,CONCRETE:15)
B(6,0,5,CONCRETE:15)
B(6,0,6,CONCRETE:15)
B(6,0,7,CONCRETE:15)
B(6,0,8,CONCRETE:15)
B(6,0,9,CONCRETE:15)
B(6,0,10,CONCRETE:15)
B(6,0,11,CONCRETE:15)
B(6,0,12,SNOW_BLOCK)
B(6,0,13,SNOW_BLOCK)
B(6,0,14,SNOW_BLOCK)
B(6,0,15,CONCRETE:15)
B(6,1,-11,SNOW_BLOCK)
B(6,1,-10,SNOW_BLOCK)
B(6,1,-9,CONCRETE:15)
B(6,1,-8,CONCRETE:15)
B(6,1,-7,CONCRETE:15)
B(6,1,-6,CONCRETE:15)
B(6,1,-5,CONCRETE:15)
B(6,1,-4,CONCRETE:15)
B(6,1,-3,CONCRETE:15)
B(6,1,-2,CONCRETE:15)
B(6,1,-1,CONCRETE:15)
B(6,1,0,CONCRETE:15)
B(6,1,1,CONCRETE:15)
B(6,1,2,CONCRETE:15)
B(6,1,3,CONCRETE:15)
B(6,1,4,CONCRETE:15)
B(6,1,5,CONCRETE:15)
B(6,1,6,CONCRETE:15)
B(6,1,7,CONCRETE:15)
B(6,1,8,CONCRETE:15)
B(6,1,9,CONCRETE:15)
B(6,1,10,CONCRETE:15)
B(6,1,11,CONCRETE:15)
B(6,1,12,SNOW_BLOCK)
B(6,1,13,SNOW_BLOCK)
B(6,1,14,SNOW_BLOCK)
B(6,2,-10,SNOW_BLOCK)
B(6,2,-9,CONCRETE:15)
B(6,2,-8,CONCRETE:15)
B(6,2,-7,CONCRETE:15)
B(6,2,-6,CONCRETE:15)
B(6,2,-5,CONCRETE:15)
B(6,2,-4,CONCRETE:15)
B(6,2,-3,CONCRETE:15)
B(6,2,-2,CONCRETE:15)
B(6,2,-1,CONCRETE:15)
B(6,2,0,CONCRETE:15)
B(6,2,1,SNOW_BLOCK)
B(6,2,2,SNOW_BLOCK)
B(6,2,3,SNOW_BLOCK)
B(6,2,4,SNOW_BLOCK)
B(6,2,5,CONCRETE:15)
B(6,2,6,CONCRETE:15)
B(6,2,7,CONCRETE:15)
B(6,2,8,CONCRETE:15)
B(6,2,9,SNOW_BLOCK)
B(6,2,10,SNOW_BLOCK)
B(6,2,11,SNOW_BLOCK)
B(6,2,12,SNOW_BLOCK)
B(6,2,13,SNOW_BLOCK)
B(6,3,-10,CONCRETE:15)
B(6,3,-9,CONCRETE:15)
B(6,3,-8,CONCRETE:15)
B(6,3,-7,CONCRETE:15)
B(6,3,-6,CONCRETE:15)
B(6,3,-5,CONCRETE:15)
B(6,3,-4,CONCRETE:15)
B(6,3,-3,CONCRETE:15)
B(6,3,-2,CONCRETE:15)
B(6,3,-1,CONCRETE:15)
B(6,3,0,CONCRETE:15)
B(6,3,1,SNOW_BLOCK)
B(6,3,2,SNOW_BLOCK)
B(6,3,3,SNOW_BLOCK)
B(6,3,4,SNOW_BLOCK)
B(6,3,5,SNOW_BLOCK)
B(6,3,6,CONCRETE:15)
B(6,3,7,SNOW_BLOCK)
B(6,3,8,SNOW_BLOCK)
B(6,3,9,SNOW_BLOCK)
B(6,3,10,SNOW_BLOCK)
B(6,3,11,SNOW_BLOCK)
B(6,3,12,SNOW_BLOCK)
B(6,4,-9,CONCRETE:15)
B(6,4,-8,CONCRETE:15)
B(6,4,-7,CONCRETE:15)
B(6,4,-6,CONCRETE:15)
B(6,4,-5,CONCRETE:15)
B(6,4,-4,CONCRETE:15)
B(6,4,-3,CONCRETE:15)
B(6,4,-2,CONCRETE:15)
B(6,4,-1,CONCRETE:15)
B(6,4,0,CONCRETE:15)
B(6,4,1,SNOW_BLOCK)
B(6,4,2,SNOW_BLOCK)
B(6,4,3,SNOW_BLOCK)
B(6,4,4,SNOW_BLOCK)
B(6,4,5,SNOW_BLOCK)
B(6,4,6,SNOW_BLOCK)
B(6,4,7,SNOW_BLOCK)
B(6,4,8,SNOW_BLOCK)
B(6,4,9,SNOW_BLOCK)
B(6,4,10,SNOW_BLOCK)
B(6,4,11,SNOW_BLOCK)
B(6,5,-8,CONCRETE:15)
B(6,5,-7,CONCRETE:15)
B(6,5,-6,CONCRETE:15)
B(6,5,-5,CONCRETE:15)
B(6,5,-4,CONCRETE:15)
B(6,5,-3,CONCRETE:15)
B(6,5,-2,CONCRETE:15)
B(6,5,6,SNOW_BLOCK)
B(6,5,7,SNOW_BLOCK)
B(6,5,8,SNOW_BLOCK)
B(6,5,9,SNOW_BLOCK)
B(6,6,-6,CONCRETE:15)
B(6,6,-5,CONCRETE:15)
B(6,6,-4,CONCRETE:15)
B(6,6,7,SNOW_BLOCK)
B(6,6,8,CONCRETE:15)
B(7,-12,7,CONCRETE:15)
B(7,-11,1,CONCRETE:15)
B(7,-11,2,CONCRETE:15)
B(7,-11,3,CONCRETE:15)
B(7,-11,4,CONCRETE:15)
B(7,-11,5,CONCRETE:15)
B(7,-11,6,CONCRETE:15)
B(7,-11,7,CONCRETE:15)
B(7,-11,8,CONCRETE:15)
B(7,-11,9,CONCRETE:15)
B(7,-11,10,CONCRETE:15)
B(7,-10,-7,CONCRETE:15)
B(7,-10,-6,CONCRETE:15)
B(7,-10,-2,CONCRETE:15)
B(7,-10,-1,CONCRETE:15)
B(7,-10,0,CONCRETE:15)
B(7,-10,1,CONCRETE:15)
B(7,-10,2,CONCRETE:15)
B(7,-10,3,CONCRETE:15)
B(7,-10,4,CONCRETE:15)
B(7,-10,5,CONCRETE:15)
B(7,-10,6,CONCRETE:15)
B(7,-10,7,CONCRETE:15)
B(7,-10,8,CONCRETE:15)
B(7,-10,9,CONCRETE:15)
B(7,-10,10,CONCRETE:15)
B(7,-10,11,CONCRETE:15)
B(7,-9,-8,CONCRETE:15)
B(7,-9,-7,CONCRETE:15)
B(7,-9,-6,CONCRETE:15)
B(7,-9,-5,CONCRETE:15)
B(7,-9,-4,CONCRETE:15)
B(7,-9,-3,CONCRETE:15)
B(7,-9,-2,CONCRETE:15)
B(7,-9,-1,CONCRETE:15)
B(7,-9,0,CONCRETE:15)
B(7,-9,1,CONCRETE:15)
B(7,-9,2,CONCRETE:15)
B(7,-9,3,CONCRETE:15)
B(7,-9,4,CONCRETE:15)
B(7,-9,5,CONCRETE:15)
B(7,-9,6,CONCRETE:15)
B(7,-9,7,CONCRETE:15)
B(7,-9,8,CONCRETE:15)
B(7,-9,9,CONCRETE:15)
B(7,-9,10,CONCRETE:15)
B(7,-9,11,CONCRETE:15)
B(7,-8,-9,CONCRETE:15)
B(7,-8,-8,CONCRETE:15)
B(7,-8,-7,CONCRETE:15)
B(7,-8,-6,CONCRETE:15)
B(7,-8,-5,CONCRETE:15)
B(7,-8,-4,CONCRETE:15)
B(7,-8,-3,CONCRETE:15)
B(7,-8,-2,CONCRETE:15)
B(7,-8,-1,CONCRETE:15)
B(7,-8,0,CONCRETE:15)
B(7,-8,1,CONCRETE:15)
B(7,-8,2,CONCRETE:15)
B(7,-8,3,CONCRETE:15)
B(7,-8,4,CONCRETE:15)
B(7,-8,5,CONCRETE:15)
B(7,-8,6,CONCRETE:15)
B(7,-8,7,CONCRETE:15)
B(7,-8,8,CONCRETE:15)
B(7,-8,9,CONCRETE:15)
B(7,-8,10,CONCRETE:15)
B(7,-8,11,CONCRETE:15)
B(7,-8,12,CONCRETE:15)
B(7,-7,-10,CONCRETE:15)
B(7,-7,-9,CONCRETE:15)
B(7,-7,-8,CONCRETE:15)
B(7,-7,-7,CONCRETE:15)
B(7,-7,-6,CONCRETE:15)
B(7,-7,-5,CONCRETE:15)
B(7,-7,-4,CONCRETE:15)
B(7,-7,-3,CONCRETE:15)
B(7,-7,-2,CONCRETE:15)
B(7,-7,-1,CONCRETE:15)
B(7,-7,0,CONCRETE:15)
B(7,-7,1,CONCRETE:15)
B(7,-7,2,CONCRETE:15)
B(7,-7,3,CONCRETE:15)
B(7,-7,4,CONCRETE:15)
B(7,-7,5,CONCRETE:15)
B(7,-7,6,CONCRETE:15)
B(7,-7,7,CONCRETE:15)
B(7,-7,8,CONCRETE:15)
B(7,-7,9,CONCRETE:15)
B(7,-7,10,CONCRETE:15)
B(7,-7,11,CONCRETE:15)
B(7,-7,12,CONCRETE:15)
B(7,-6,-11,CONCRETE:15)
B(7,-6,-10,CONCRETE:15)
B(7,-6,-9,CONCRETE:15)
B(7,-6,-8,CONCRETE:15)
B(7,-6,-7,CONCRETE:15)
B(7,-6,-6,CONCRETE:15)
B(7,-6,-5,CONCRETE:15)
B(7,-6,-4,CONCRETE:15)
B(7,-6,-3,CONCRETE:15)
B(7,-6,-2,CONCRETE:15)
B(7,-6,-1,CONCRETE:15)
B(7,-6,0,CONCRETE:15)
B(7,-6,1,CONCRETE:15)
B(7,-6,2,CONCRETE:15)
B(7,-6,3,CONCRETE:15)
B(7,-6,4,CONCRETE:15)
B(7,-6,5,CONCRETE:15)
B(7,-6,6,CONCRETE:15)
B(7,-6,7,CONCRETE:15)
B(7,-6,8,CONCRETE:15)
B(7,-6,9,CONCRETE:15)
B(7,-6,10,CONCRETE:15)
B(7,-6,11,CONCRETE:15)
B(7,-6,12,CONCRETE:15)
B(7,-5,-11,CONCRETE:15)
B(7,-5,-10,CONCRETE:15)
B(7,-5,-9,CONCRETE:15)
B(7,-5,-8,CONCRETE:15)
B(7,-5,-7,CONCRETE:15)
B(7,-5,-6,CONCRETE:15)
B(7,-5,-5,CONCRETE:15)
B(7,-5,-4,CONCRETE:15)
B(7,-5,-3,SNOW_BLOCK)
B(7,-5,-2,CONCRETE:15)
B(7,-5,-1,CONCRETE:15)
B(7,-5,0,CONCRETE:15)
B(7,-5,1,CONCRETE:15)
B(7,-5,2,CONCRETE:15)
B(7,-5,3,CONCRETE:15)
B(7,-5,4,CONCRETE:15)
B(7,-5,5,CONCRETE:15)
B(7,-5,6,CONCRETE:15)
B(7,-5,7,CONCRETE:15)
B(7,-5,8,CONCRETE:15)
B(7,-5,9,CONCRETE:15)
B(7,-5,10,CONCRETE:15)
B(7,-5,11,CONCRETE:15)
B(7,-5,12,CONCRETE:15)
B(7,-4,-11,CONCRETE:15)
B(7,-4,-10,CONCRETE:15)
B(7,-4,-9,CONCRETE:15)
B(7,-4,-8,CONCRETE:15)
B(7,-4,-7,CONCRETE:15)
B(7,-4,-6,CONCRETE:15)
B(7,-4,-5,CONCRETE:15)
B(7,-4,-4,CONCRETE:15)
B(7,-4,-3,CONCRETE:15)
B(7,-4,-2,CONCRETE:15)
B(7,-4,-1,CONCRETE:15)
B(7,-4,0,CONCRETE:15)
B(7,-4,1,CONCRETE:15)
B(7,-4,2,CONCRETE:15)
B(7,-4,3,CONCRETE:15)
B(7,-4,4,CONCRETE:15)
B(7,-4,5,CONCRETE:15)
B(7,-4,6,CONCRETE:15)
B(7,-4,7,CONCRETE:15)
B(7,-4,8,CONCRETE:15)
B(7,-4,9,CONCRETE:15)
B(7,-4,10,CONCRETE:15)
B(7,-4,11,CONCRETE:15)
B(7,-4,12,CONCRETE:15)
B(7,-3,-11,CONCRETE:15)
B(7,-3,-10,CONCRETE:15)
B(7,-3,-9,CONCRETE:15)
B(7,-3,-8,CONCRETE:15)
B(7,-3,-7,CONCRETE:15)
B(7,-3,-6,CONCRETE:15)
B(7,-3,-5,CONCRETE:15)
B(7,-3,-4,CONCRETE:15)
B(7,-3,-3,CONCRETE:15)
B(7,-3,-2,CONCRETE:15)
B(7,-3,-1,CONCRETE:15)
B(7,-3,0,CONCRETE:15)
B(7,-3,1,CONCRETE:15)
B(7,-3,2,CONCRETE:15)
B(7,-3,3,CONCRETE:15)
B(7,-3,4,CONCRETE:15)
B(7,-3,5,CONCRETE:15)
B(7,-3,6,CONCRETE:15)
B(7,-3,7,CONCRETE:15)
B(7,-3,8,CONCRETE:15)
B(7,-3,9,CONCRETE:15)
B(7,-3,10,CONCRETE:15)
B(7,-3,11,CONCRETE:15)
B(7,-3,12,CONCRETE:15)
B(7,-2,-11,CONCRETE:15)
B(7,-2,-10,CONCRETE:15)
B(7,-2,-9,CONCRETE:15)
B(7,-2,-8,CONCRETE:15)
B(7,-2,-7,CONCRETE:15)
B(7,-2,-6,CONCRETE:15)
B(7,-2,-5,CONCRETE:15)
B(7,-2,-4,CONCRETE:15)
B(7,-2,-3,CONCRETE:15)
B(7,-2,-2,CONCRETE:15)
B(7,-2,-1,CONCRETE:15)
B(7,-2,0,CONCRETE:15)
B(7,-2,1,CONCRETE:15)
B(7,-2,2,CONCRETE:15)
B(7,-2,3,CONCRETE:15)
B(7,-2,4,CONCRETE:15)
B(7,-2,5,CONCRETE:15)
B(7,-2,6,CONCRETE:15)
B(7,-2,7,CONCRETE:15)
B(7,-2,8,CONCRETE:15)
B(7,-2,9,CONCRETE:15)
B(7,-2,10,SNOW_BLOCK)
B(7,-2,11,SNOW_BLOCK)
B(7,-2,12,SNOW_BLOCK)
B(7,-2,13,CONCRETE:15)
B(7,-2,14,CONCRETE:15)
B(7,-1,-10,SNOW_BLOCK)
B(7,-1,-9,SNOW_BLOCK)
B(7,-1,-8,CONCRETE:15)
B(7,-1,-7,CONCRETE:15)
B(7,-1,-6,CONCRETE:15)
B(7,-1,-5,CONCRETE:15)
B(7,-1,-4,CONCRETE:15)
B(7,-1,-3,CONCRETE:15)
B(7,-1,-2,CONCRETE:15)
B(7,-1,-1,CONCRETE:15)
B(7,-1,0,CONCRETE:15)
B(7,-1,1,CONCRETE:15)
B(7,-1,2,CONCRETE:15)
B(7,-1,3,CONCRETE:15)
B(7,-1,4,CONCRETE:15)
B(7,-1,5,CONCRETE:15)
B(7,-1,6,CONCRETE:15)
B(7,-1,7,CONCRETE:15)
B(7,-1,8,CONCRETE:15)
B(7,-1,9,CONCRETE:15)
B(7,-1,10,SNOW_BLOCK)
B(7,-1,11,SNOW_BLOCK)
B(7,-1,12,SNOW_BLOCK)
B(7,-1,13,SNOW_BLOCK)
B(7,-1,14,SNOW_BLOCK)
B(7,0,-10,SNOW_BLOCK)
B(7,0,-9,SNOW_BLOCK)
B(7,0,-8,CONCRETE:15)
B(7,0,-7,CONCRETE:15)
B(7,0,-6,CONCRETE:15)
B(7,0,-5,CONCRETE:15)
B(7,0,-4,CONCRETE:15)
B(7,0,-3,CONCRETE:15)
B(7,0,-2,CONCRETE:15)
B(7,0,-1,CONCRETE:15)
B(7,0,0,CONCRETE:15)
B(7,0,1,CONCRETE:15)
B(7,0,2,CONCRETE:15)
B(7,0,3,CONCRETE:15)
B(7,0,4,CONCRETE:15)
B(7,0,5,CONCRETE:15)
B(7,0,6,CONCRETE:15)
B(7,0,7,CONCRETE:15)
B(7,0,8,CONCRETE:15)
B(7,0,9,CONCRETE:15)
B(7,0,10,SNOW_BLOCK)
B(7,0,11,SNOW_BLOCK)
B(7,0,12,SNOW_BLOCK)
B(7,0,13,SNOW_BLOCK)
B(7,1,-10,SNOW_BLOCK)
B(7,1,-9,SNOW_BLOCK)
B(7,1,-8,CONCRETE:15)
B(7,1,-7,CONCRETE:15)
B(7,1,-6,CONCRETE:15)
B(7,1,-5,CONCRETE:15)
B(7,1,-4,CONCRETE:15)
B(7,1,-3,CONCRETE:15)
B(7,1,-2,CONCRETE:15)
B(7,1,-1,CONCRETE:15)
B(7,1,0,CONCRETE:15)
B(7,1,1,CONCRETE:15)
B(7,1,2,CONCRETE:15)
B(7,1,3,CONCRETE:15)
B(7,1,4,CONCRETE:15)
B(7,1,5,CONCRETE:15)
B(7,1,6,CONCRETE:15)
B(7,1,7,CONCRETE:15)
B(7,1,8,CONCRETE:15)
B(7,1,9,CONCRETE:15)
B(7,1,10,CONCRETE:15)
B(7,1,11,CONCRETE:15)
B(7,1,12,SNOW_BLOCK)
B(7,2,-10,SNOW_BLOCK)
B(7,2,-9,CONCRETE:15)
B(7,2,-8,CONCRETE:15)
B(7,2,-7,CONCRETE:15)
B(7,2,-6,CONCRETE:15)
B(7,2,-5,CONCRETE:15)
B(7,2,-4,CONCRETE:15)
B(7,2,-3,CONCRETE:15)
B(7,2,-2,CONCRETE:15)
B(7,2,-1,CONCRETE:15)
B(7,2,0,CONCRETE:15)
B(7,2,1,CONCRETE:15)
B(7,2,2,CONCRETE:15)
B(7,2,3,CONCRETE:15)
B(7,2,4,CONCRETE:15)
B(7,2,5,CONCRETE:15)
B(7,2,6,CONCRETE:15)
B(7,2,7,CONCRETE:15)
B(7,2,8,CONCRETE:15)
B(7,2,9,SNOW_BLOCK)
B(7,2,10,SNOW_BLOCK)
B(7,2,11,SNOW_BLOCK)
B(7,3,-9,CONCRETE:15)
B(7,3,-8,CONCRETE:15)
B(7,3,-7,CONCRETE:15)
B(7,3,-6,CONCRETE:15)
B(7,3,-5,CONCRETE:15)
B(7,3,-4,CONCRETE:15)
B(7,3,-3,CONCRETE:15)
B(7,3,-2,CONCRETE:15)
B(7,3,-1,CONCRETE:15)
B(7,3,0,CONCRETE:15)
B(7,3,1,CONCRETE:15)
B(7,3,2,CONCRETE:15)
B(7,3,3,SNOW_BLOCK)
B(7,3,4,SNOW_BLOCK)
B(7,3,5,SNOW_BLOCK)
B(7,3,6,CONCRETE:15)
B(7,3,7,SNOW_BLOCK)
B(7,3,8,SNOW_BLOCK)
B(7,3,9,SNOW_BLOCK)
B(7,3,10,SNOW_BLOCK)
B(7,4,-8,CONCRETE:15)
B(7,4,-7,CONCRETE:15)
B(7,4,-6,CONCRETE:15)
B(7,4,-5,CONCRETE:15)
B(7,4,-4,CONCRETE:15)
B(7,4,-3,CONCRETE:15)
B(7,4,-2,CONCRETE:15)
B(7,4,-1,CONCRETE:15)
B(7,4,0,CONCRETE:15)
B(7,4,3,SNOW_BLOCK)
B(7,4,4,SNOW_BLOCK)
B(7,4,5,SNOW_BLOCK)
B(7,4,6,SNOW_BLOCK)
B(7,4,7,SNOW_BLOCK)
B(7,4,8,SNOW_BLOCK)
B(7,4,9,SNOW_BLOCK)
B(7,5,-6,CONCRETE:15)
B(7,5,-5,CONCRETE:15)
B(7,5,-4,CONCRETE:15)
B(7,5,-3,CONCRETE:15)
B(7,5,-2,CONCRETE:15)
B(7,5,6,SNOW_BLOCK)
B(7,5,7,SNOW_BLOCK)
B(7,6,-4,CONCRETE:15)
B(8,-11,1,CONCRETE:15)
B(8,-11,2,CONCRETE:15)
B(8,-11,3,CONCRETE:15)
B(8,-11,4,CONCRETE:15)
B(8,-11,5,CONCRETE:15)
B(8,-11,6,CONCRETE:15)
B(8,-11,7,CONCRETE:15)
B(8,-10,-2,CONCRETE:15)
B(8,-10,-1,CONCRETE:15)
B(8,-10,0,CONCRETE:15)
B(8,-10,1,CONCRETE:15)
B(8,-10,2,CONCRETE:15)
B(8,-10,3,CONCRETE:15)
B(8,-10,4,CONCRETE:15)
B(8,-10,5,CONCRETE:15)
B(8,-10,6,CONCRETE:15)
B(8,-10,7,CONCRETE:15)
B(8,-10,8,CONCRETE:15)
B(8,-10,9,CONCRETE:15)
B(8,-9,-7,CONCRETE:15)
B(8,-9,-6,CONCRETE:15)
B(8,-9,-5,CONCRETE:15)
B(8,-9,-4,CONCRETE:15)
B(8,-9,-3,CONCRETE:15)
B(8,-9,-2,CONCRETE:15)
B(8,-9,-1,CONCRETE:15)
B(8,-9,0,CONCRETE:15)
B(8,-9,1,CONCRETE:15)
B(8,-9,2,CONCRETE:15)
B(8,-9,3,CONCRETE:15)
B(8,-9,4,CONCRETE:15)
B(8,-9,5,CONCRETE:15)
B(8,-9,6,CONCRETE:15)
B(8,-9,7,CONCRETE:15)
B(8,-9,8,CONCRETE:15)
B(8,-9,9,CONCRETE:15)
B(8,-9,10,CONCRETE:15)
B(8,-8,-8,CONCRETE:15)
B(8,-8,-7,CONCRETE:15)
B(8,-8,-6,CONCRETE:15)
B(8,-8,-5,CONCRETE:15)
B(8,-8,-4,CONCRETE:15)
B(8,-8,-3,CONCRETE:15)
B(8,-8,-2,CONCRETE:15)
B(8,-8,-1,CONCRETE:15)
B(8,-8,0,CONCRETE:15)
B(8,-8,1,CONCRETE:15)
B(8,-8,2,CONCRETE:15)
B(8,-8,3,CONCRETE:15)
B(8,-8,4,CONCRETE:15)
B(8,-8,5,CONCRETE:15)
B(8,-8,6,CONCRETE:15)
B(8,-8,7,CONCRETE:15)
B(8,-8,8,CONCRETE:15)
B(8,-8,9,CONCRETE:15)
B(8,-8,10,CONCRETE:15)
B(8,-7,-8,CONCRETE:15)
B(8,-7,-7,CONCRETE:15)
B(8,-7,-6,CONCRETE:15)
B(8,-7,-5,CONCRETE:15)
B(8,-7,-4,CONCRETE:15)
B(8,-7,-3,CONCRETE:15)
B(8,-7,-2,CONCRETE:15)
B(8,-7,-1,CONCRETE:15)
B(8,-7,0,SNOW_BLOCK)
B(8,-7,1,SNOW_BLOCK)
B(8,-7,2,CONCRETE:15)
B(8,-7,3,CONCRETE:15)
B(8,-7,4,CONCRETE:15)
B(8,-7,5,CONCRETE:15)
B(8,-7,6,CONCRETE:15)
B(8,-7,7,CONCRETE:15)
B(8,-7,8,CONCRETE:15)
B(8,-7,9,CONCRETE:15)
B(8,-7,10,CONCRETE:15)
B(8,-6,-10,CONCRETE:15)
B(8,-6,-9,CONCRETE:15)
B(8,-6,-8,CONCRETE:15)
B(8,-6,-7,CONCRETE:15)
B(8,-6,-6,CONCRETE:15)
B(8,-6,-5,CONCRETE:15)
B(8,-6,-4,CONCRETE:15)
B(8,-6,-3,CONCRETE:15)
B(8,-6,-2,CONCRETE:15)
B(8,-6,-1,SNOW_BLOCK)
B(8,-6,0,SNOW_BLOCK)
B(8,-6,1,SNOW_BLOCK)
B(8,-6,2,SNOW_BLOCK)
B(8,-6,3,SNOW_BLOCK)
B(8,-6,4,SNOW_BLOCK)
B(8,-6,5,CONCRETE:15)
B(8,-6,6,CONCRETE:15)
B(8,-6,7,CONCRETE:15)
B(8,-5,-10,CONCRETE:15)
B(8,-5,-9,CONCRETE:15)
B(8,-5,-8,CONCRETE:15)
B(8,-5,-7,CONCRETE:15)
B(8,-5,-6,CONCRETE:15)
B(8,-5,-5,CONCRETE:15)
B(8,-5,-4,CONCRETE:15)
B(8,-5,-3,CONCRETE:15)
B(8,-5,-2,CONCRETE:15)
B(8,-5,-1,CONCRETE:15)
B(8,-5,0,CONCRETE:15)
B(8,-5,1,CONCRETE:15)
B(8,-5,2,CONCRETE:15)
B(8,-5,3,CONCRETE:15)
B(8,-5,4,CONCRETE:15)
B(8,-5,5,CONCRETE:15)
B(8,-5,6,CONCRETE:15)
B(8,-5,7,CONCRETE:15)
B(8,-5,8,CONCRETE:15)
B(8,-5,9,CONCRETE:15)
B(8,-4,-11,CONCRETE:15)
B(8,-4,-10,CONCRETE:15)
B(8,-4,-9,CONCRETE:15)
B(8,-4,-8,CONCRETE:15)
B(8,-4,-7,CONCRETE:15)
B(8,-4,-6,CONCRETE:15)
B(8,-4,-5,CONCRETE:15)
B(8,-4,-4,CONCRETE:15)
B(8,-4,-3,CONCRETE:15)
B(8,-4,-2,CONCRETE:15)
B(8,-4,-1,CONCRETE:15)
B(8,-4,0,CONCRETE:15)
B(8,-4,1,CONCRETE:15)
B(8,-4,2,CONCRETE:15)
B(8,-4,3,CONCRETE:15)
B(8,-4,4,CONCRETE:15)
B(8,-4,5,CONCRETE:15)
B(8,-4,6,CONCRETE:15)
B(8,-4,7,CONCRETE:15)
B(8,-4,8,CONCRETE:15)
B(8,-4,9,CONCRETE:15)
B(8,-4,10,CONCRETE:15)
B(8,-3,-11,CONCRETE:15)
B(8,-3,-10,CONCRETE:15)
B(8,-3,-9,CONCRETE:15)
B(8,-3,-8,CONCRETE:15)
B(8,-3,-7,CONCRETE:15)
B(8,-3,-6,CONCRETE:15)
B(8,-3,-5,CONCRETE:15)
B(8,-3,-4,CONCRETE:15)
B(8,-3,-3,CONCRETE:15)
B(8,-3,-2,CONCRETE:15)
B(8,-3,-1,CONCRETE:15)
B(8,-3,0,CONCRETE:15)
B(8,-3,1,CONCRETE:15)
B(8,-3,2,CONCRETE:15)
B(8,-3,3,CONCRETE:15)
B(8,-3,4,CONCRETE:15)
B(8,-3,5,CONCRETE:15)
B(8,-3,6,CONCRETE:15)
B(8,-3,7,CONCRETE:15)
B(8,-3,8,SNOW_BLOCK)
B(8,-3,9,SNOW_BLOCK)
B(8,-3,10,SNOW_BLOCK)
B(8,-2,-11,CONCRETE:15)
B(8,-2,-10,CONCRETE:15)
B(8,-2,-9,CONCRETE:15)
B(8,-2,-8,CONCRETE:15)
B(8,-2,-7,CONCRETE:15)
B(8,-2,-6,CONCRETE:15)
B(8,-2,-5,CONCRETE:15)
B(8,-2,-4,CONCRETE:15)
B(8,-2,-3,CONCRETE:15)
B(8,-2,-2,CONCRETE:15)
B(8,-2,-1,CONCRETE:15)
B(8,-2,0,CONCRETE:15)
B(8,-2,1,CONCRETE:15)
B(8,-2,2,CONCRETE:15)
B(8,-2,3,CONCRETE:15)
B(8,-2,4,CONCRETE:15)
B(8,-2,5,CONCRETE:15)
B(8,-2,6,CONCRETE:15)
B(8,-2,7,CONCRETE:15)
B(8,-2,8,SNOW_BLOCK)
B(8,-2,9,SNOW_BLOCK)
B(8,-2,10,SNOW_BLOCK)
B(8,-2,11,SNOW_BLOCK)
B(8,-1,-10,SNOW_BLOCK)
B(8,-1,-9,SNOW_BLOCK)
B(8,-1,-8,SNOW_BLOCK)
B(8,-1,-7,CONCRETE:15)
B(8,-1,-6,CONCRETE:15)
B(8,-1,-5,CONCRETE:15)
B(8,-1,-4,CONCRETE:15)
B(8,-1,-3,CONCRETE:15)
B(8,-1,-2,CONCRETE:15)
B(8,-1,-1,CONCRETE:15)
B(8,-1,0,CONCRETE:15)
B(8,-1,1,CONCRETE:15)
B(8,-1,2,CONCRETE:15)
B(8,-1,3,CONCRETE:15)
B(8,-1,4,CONCRETE:15)
B(8,-1,5,CONCRETE:15)
B(8,-1,6,CONCRETE:15)
B(8,-1,7,CONCRETE:15)
B(8,-1,8,SNOW_BLOCK)
B(8,-1,9,SNOW_BLOCK)
B(8,-1,10,SNOW_BLOCK)
B(8,-1,11,SNOW_BLOCK)
B(8,0,-10,SNOW_BLOCK)
B(8,0,-9,SNOW_BLOCK)
B(8,0,-8,SNOW_BLOCK)
B(8,0,-7,CONCRETE:15)
B(8,0,-6,CONCRETE:15)
B(8,0,-5,CONCRETE:15)
B(8,0,-4,CONCRETE:15)
B(8,0,-3,CONCRETE:15)
B(8,0,-2,CONCRETE:15)
B(8,0,-1,CONCRETE:15)
B(8,0,0,CONCRETE:15)
B(8,0,1,CONCRETE:15)
B(8,0,2,CONCRETE:15)
B(8,0,3,CONCRETE:15)
B(8,0,4,CONCRETE:15)
B(8,0,5,CONCRETE:15)
B(8,0,6,CONCRETE:15)
B(8,0,7,CONCRETE:15)
B(8,0,8,CONCRETE:15)
B(8,0,9,CONCRETE:15)
B(8,0,10,SNOW_BLOCK)
B(8,1,-10,SNOW_BLOCK)
B(8,1,-9,SNOW_BLOCK)
B(8,1,-8,SNOW_BLOCK)
B(8,1,-7,CONCRETE:15)
B(8,1,-6,CONCRETE:15)
B(8,1,-5,CONCRETE:15)
B(8,1,-4,CONCRETE:15)
B(8,1,-3,CONCRETE:15)
B(8,1,-2,CONCRETE:15)
B(8,1,-1,CONCRETE:15)
B(8,1,0,CONCRETE:15)
B(8,1,1,CONCRETE:15)
B(8,1,2,CONCRETE:15)
B(8,1,3,CONCRETE:15)
B(8,1,4,CONCRETE:15)
B(8,1,5,CONCRETE:15)
B(8,1,6,CONCRETE:15)
B(8,1,7,CONCRETE:15)
B(8,1,8,CONCRETE:15)
B(8,1,9,CONCRETE:15)
B(8,2,-9,CONCRETE:15)
B(8,2,-8,CONCRETE:15)
B(8,2,-7,CONCRETE:15)
B(8,2,-6,CONCRETE:15)
B(8,2,-5,CONCRETE:15)
B(8,2,-4,CONCRETE:15)
B(8,2,-3,CONCRETE:15)
B(8,2,-2,CONCRETE:15)
B(8,2,-1,CONCRETE:15)
B(8,2,0,CONCRETE:15)
B(8,2,1,CONCRETE:15)
B(8,2,2,CONCRETE:15)
B(8,2,3,CONCRETE:15)
B(8,2,4,CONCRETE:15)
B(8,2,5,CONCRETE:15)
B(8,2,6,CONCRETE:15)
B(8,2,7,CONCRETE:15)
B(8,2,8,CONCRETE:15)
B(8,2,9,SNOW_BLOCK)
B(8,3,-8,CONCRETE:15)
B(8,3,-7,CONCRETE:15)
B(8,3,-6,CONCRETE:15)
B(8,3,-5,CONCRETE:15)
B(8,3,-4,CONCRETE:15)
B(8,3,-3,CONCRETE:15)
B(8,3,-2,CONCRETE:15)
B(8,3,-1,CONCRETE:15)
B(8,3,3,SNOW_BLOCK)
B(8,3,4,SNOW_BLOCK)
B(8,3,5,SNOW_BLOCK)
B(8,3,6,CONCRETE:15)
B(8,3,7,SNOW_BLOCK)
B(8,3,8,SNOW_BLOCK)
B(8,4,-6,CONCRETE:15)
B(8,4,-5,CONCRETE:15)
B(8,4,-4,CONCRETE:15)
B(8,4,-3,CONCRETE:15)
B(8,4,-2,CONCRETE:15)
B(8,4,5,SNOW_BLOCK)
B(8,4,6,SNOW_BLOCK)
B(8,4,7,SNOW_BLOCK)
B(8,5,-4,CONCRETE:15)
B(9,-10,0,CONCRETE:15)
B(9,-10,1,CONCRETE:15)
B(9,-10,2,CONCRETE:15)
B(9,-10,3,CONCRETE:15)
B(9,-10,4,CONCRETE:15)
B(9,-10,5,CONCRETE:15)
B(9,-10,6,CONCRETE:15)
B(9,-10,7,CONCRETE:15)
B(9,-9,-4,CONCRETE:15)
B(9,-9,-3,CONCRETE:15)
B(9,-9,-2,CONCRETE:15)
B(9,-9,-1,CONCRETE:15)
B(9,-9,0,CONCRETE:15)
B(9,-9,1,CONCRETE:15)
B(9,-9,2,CONCRETE:15)
B(9,-9,3,CONCRETE:15)
B(9,-9,4,CONCRETE:15)
B(9,-9,5,CONCRETE:15)
B(9,-9,6,CONCRETE:15)
B(9,-9,7,CONCRETE:15)
B(9,-8,-6,CONCRETE:15)
B(9,-8,-5,CONCRETE:15)
B(9,-8,-4,CONCRETE:15)
B(9,-8,-3,CONCRETE:15)
B(9,-8,-2,CONCRETE:15)
B(9,-8,-1,CONCRETE:15)
B(9,-8,0,CONCRETE:15)
B(9,-8,1,CONCRETE:15)
B(9,-8,2,CONCRETE:15)
B(9,-8,3,CONCRETE:15)
B(9,-8,4,CONCRETE:15)
B(9,-8,5,CONCRETE:15)
B(9,-8,6,CONCRETE:15)
B(9,-8,7,CONCRETE:15)
B(9,-7,-7,CONCRETE:15)
B(9,-7,-6,CONCRETE:15)
B(9,-7,-5,CONCRETE:15)
B(9,-7,-4,CONCRETE:15)
B(9,-7,-3,CONCRETE:15)
B(9,-7,-2,CONCRETE:15)
B(9,-7,-1,CONCRETE:15)
B(9,-7,0,CONCRETE:15)
B(9,-7,1,CONCRETE:15)
B(9,-7,2,CONCRETE:15)
B(9,-7,3,SNOW_BLOCK)
B(9,-7,4,CONCRETE:15)
B(9,-7,5,CONCRETE:15)
B(9,-7,6,CONCRETE:15)
B(9,-7,7,CONCRETE:15)
B(9,-6,-7,CONCRETE:15)
B(9,-6,-6,CONCRETE:15)
B(9,-6,-5,CONCRETE:15)
B(9,-6,-4,CONCRETE:15)
B(9,-6,-3,CONCRETE:15)
B(9,-6,-2,CONCRETE:15)
B(9,-6,-1,SNOW_BLOCK)
B(9,-6,0,SNOW_BLOCK)
B(9,-6,1,CONCRETE:15)
B(9,-6,2,SNOW_BLOCK)
B(9,-6,3,SNOW_BLOCK)
B(9,-6,4,SNOW_BLOCK)
B(9,-6,5,SNOW_BLOCK)
B(9,-6,6,SNOW_BLOCK)
B(9,-6,7,CONCRETE:15)
B(9,-5,-10,CONCRETE:15)
B(9,-5,-9,CONCRETE:15)
B(9,-5,-8,CONCRETE:15)
B(9,-5,-7,CONCRETE:15)
B(9,-5,-6,CONCRETE:15)
B(9,-5,-5,CONCRETE:15)
B(9,-5,-4,CONCRETE:15)
B(9,-5,-3,CONCRETE:15)
B(9,-5,-2,SNOW_BLOCK)
B(9,-5,-1,SNOW_BLOCK)
B(9,-5,0,SNOW_BLOCK)
B(9,-5,1,CONCRETE:15)
B(9,-5,2,CONCRETE:15)
B(9,-5,3,CONCRETE:15)
B(9,-5,4,SNOW_BLOCK)
B(9,-5,5,SNOW_BLOCK)
B(9,-5,6,SNOW_BLOCK)
B(9,-5,7,SNOW_BLOCK)
B(9,-5,8,SNOW_BLOCK)
B(9,-4,-10,CONCRETE:15)
B(9,-4,-9,CONCRETE:15)
B(9,-4,-8,CONCRETE:15)
B(9,-4,-7,CONCRETE:15)
B(9,-4,-6,CONCRETE:15)
B(9,-4,-5,CONCRETE:15)
B(9,-4,-4,SNOW_BLOCK)
B(9,-4,-3,SNOW_BLOCK)
B(9,-4,-2,SNOW_BLOCK)
B(9,-4,-1,SNOW_BLOCK)
B(9,-4,0,SNOW_BLOCK)
B(9,-4,1,CONCRETE:15)
B(9,-4,2,CONCRETE:15)
B(9,-4,3,CONCRETE:15)
B(9,-4,4,CONCRETE:15)
B(9,-4,5,CONCRETE:15)
B(9,-4,6,CONCRETE:15)
B(9,-4,7,SNOW_BLOCK)
B(9,-4,8,SNOW_BLOCK)
B(9,-4,9,SNOW_BLOCK)
B(9,-3,-10,CONCRETE:15)
B(9,-3,-9,CONCRETE:15)
B(9,-3,-8,CONCRETE:15)
B(9,-3,-7,CONCRETE:15)
B(9,-3,-6,SNOW_BLOCK)
B(9,-3,-5,SNOW_BLOCK)
B(9,-3,-4,SNOW_BLOCK)
B(9,-3,-3,SNOW_BLOCK)
B(9,-3,-2,SNOW_BLOCK)
B(9,-3,-1,CONCRETE:15)
B(9,-3,0,CONCRETE:15)
B(9,-3,1,CONCRETE:15)
B(9,-3,2,CONCRETE:15)
B(9,-3,3,CONCRETE:15)
B(9,-3,4,CONCRETE:15)
B(9,-3,5,CONCRETE:15)
B(9,-3,6,CONCRETE:15)
B(9,-3,7,SNOW_BLOCK)
B(9,-3,8,SNOW_BLOCK)
B(9,-3,9,SNOW_BLOCK)
B(9,-2,-10,CONCRETE:15)
B(9,-2,-9,CONCRETE:15)
B(9,-2,-8,SNOW_BLOCK)
B(9,-2,-7,SNOW_BLOCK)
B(9,-2,-6,SNOW_BLOCK)
B(9,-2,-5,SNOW_BLOCK)
B(9,-2,-4,SNOW_BLOCK)
B(9,-2,-3,SNOW_BLOCK)
B(9,-2,-2,SNOW_BLOCK)
B(9,-2,-1,CONCRETE:15)
B(9,-2,0,CONCRETE:15)
B(9,-2,1,CONCRETE:15)
B(9,-2,2,CONCRETE:15)
B(9,-2,3,CONCRETE:15)
B(9,-2,4,CONCRETE:15)
B(9,-2,5,CONCRETE:15)
B(9,-2,6,CONCRETE:15)
B(9,-2,7,SNOW_BLOCK)
B(9,-2,8,SNOW_BLOCK)
B(9,-2,9,SNOW_BLOCK)
B(9,-1,-10,SNOW_BLOCK)
B(9,-1,-9,SNOW_BLOCK)
B(9,-1,-8,SNOW_BLOCK)
B(9,-1,-7,SNOW_BLOCK)
B(9,-1,-6,SNOW_BLOCK)
B(9,-1,-5,SNOW_BLOCK)
B(9,-1,-4,SNOW_BLOCK)
B(9,-1,-3,CONCRETE:15)
B(9,-1,-2,CONCRETE:15)
B(9,-1,-1,CONCRETE:15)
B(9,-1,0,CONCRETE:15)
B(9,-1,1,CONCRETE:15)
B(9,-1,2,CONCRETE:15)
B(9,-1,3,CONCRETE:15)
B(9,-1,4,CONCRETE:15)
B(9,-1,5,CONCRETE:15)
B(9,-1,6,CONCRETE:15)
B(9,-1,7,CONCRETE:15)
B(9,-1,8,SNOW_BLOCK)
B(9,-1,9,SNOW_BLOCK)
B(9,0,-9,SNOW_BLOCK)
B(9,0,-8,SNOW_BLOCK)
B(9,0,-7,SNOW_BLOCK)
B(9,0,-6,SNOW_BLOCK)
B(9,0,-5,CONCRETE:15)
B(9,0,-4,CONCRETE:15)
B(9,0,-3,CONCRETE:15)
B(9,0,-2,CONCRETE:15)
B(9,0,-1,CONCRETE:15)
B(9,0,0,CONCRETE:15)
B(9,0,1,CONCRETE:15)
B(9,0,2,CONCRETE:15)
B(9,0,3,CONCRETE:15)
B(9,0,4,CONCRETE:15)
B(9,0,5,CONCRETE:15)
B(9,0,6,CONCRETE:15)
B(9,0,7,CONCRETE:15)
B(9,0,8,CONCRETE:15)
B(9,1,-9,SNOW_BLOCK)
B(9,1,-8,SNOW_BLOCK)
B(9,1,-7,CONCRETE:15)
B(9,1,-6,CONCRETE:15)
B(9,1,-5,CONCRETE:15)
B(9,1,-4,CONCRETE:15)
B(9,1,-3,CONCRETE:15)
B(9,1,-2,CONCRETE:15)
B(9,1,2,CONCRETE:15)
B(9,1,3,CONCRETE:15)
B(9,1,4,CONCRETE:15)
B(9,1,5,CONCRETE:15)
B(9,1,6,CONCRETE:15)
B(9,1,7,CONCRETE:15)
B(9,1,8,CONCRETE:15)
B(9,2,-8,CONCRETE:15)
B(9,2,-7,CONCRETE:15)
B(9,2,-6,CONCRETE:15)
B(9,2,-5,CONCRETE:15)
B(9,2,-4,CONCRETE:15)
B(9,2,-3,CONCRETE:15)
B(9,2,3,CONCRETE:15)
B(9,2,4,CONCRETE:15)
B(9,2,5,CONCRETE:15)
B(9,2,6,CONCRETE:15)
B(9,2,7,CONCRETE:15)
B(9,3,-6,CONCRETE:15)
B(9,3,-5,CONCRETE:15)
B(9,3,-4,CONCRETE:15)
B(10,-9,2,CONCRETE:15)
B(10,-9,3,CONCRETE:15)
B(10,-9,4,CONCRETE:15)
B(10,-8,-5,CONCRETE:15)
B(10,-8,-4,CONCRETE:15)
B(10,-8,-3,CONCRETE:15)
B(10,-8,-2,CONCRETE:15)
B(10,-8,-1,CONCRETE:15)
B(10,-8,0,CONCRETE:15)
B(10,-8,1,CONCRETE:15)
B(10,-8,2,CONCRETE:15)
B(10,-8,3,CONCRETE:15)
B(10,-8,4,CONCRETE:15)
B(10,-7,-6,CONCRETE:15)
B(10,-7,-5,CONCRETE:15)
B(10,-7,-4,CONCRETE:15)
B(10,-7,-3,CONCRETE:15)
B(10,-7,-2,CONCRETE:15)
B(10,-7,-1,CONCRETE:15)
B(10,-7,0,CONCRETE:15)
B(10,-7,1,CONCRETE:15)
B(10,-7,2,CONCRETE:15)
B(10,-6,-6,CONCRETE:15)
B(10,-6,-5,CONCRETE:15)
B(10,-6,-4,CONCRETE:15)
B(10,-6,-3,CONCRETE:15)
B(10,-6,-2,CONCRETE:15)
B(10,-6,-1,SNOW_BLOCK)
B(10,-6,0,SNOW_BLOCK)
B(10,-6,1,CONCRETE:15)
B(10,-6,2,SNOW_BLOCK)
B(10,-6,3,SNOW_BLOCK)
B(10,-6,4,SNOW_BLOCK)
B(10,-6,5,SNOW_BLOCK)
B(10,-6,6,SNOW_BLOCK)
B(10,-6,7,SNOW_BLOCK)
B(10,-5,-6,CONCRETE:15)
B(10,-5,-5,CONCRETE:15)
B(10,-5,-4,CONCRETE:15)
B(10,-5,-3,CONCRETE:15)
B(10,-5,-2,CONCRETE:15)
B(10,-5,-1,SNOW_BLOCK)
B(10,-5,0,SNOW_BLOCK)
B(10,-5,1,CONCRETE:15)
B(10,-5,2,CONCRETE:15)
B(10,-5,3,CONCRETE:15)
B(10,-5,4,SNOW_BLOCK)
B(10,-5,5,SNOW_BLOCK)
B(10,-5,6,SNOW_BLOCK)
B(10,-5,7,SNOW_BLOCK)
B(10,-5,8,SNOW_BLOCK)
B(10,-4,-9,CONCRETE:15)
B(10,-4,-8,CONCRETE:15)
B(10,-4,-7,CONCRETE:15)
B(10,-4,-6,CONCRETE:15)
B(10,-4,-5,CONCRETE:15)
B(10,-4,-4,SNOW_BLOCK)
B(10,-4,-3,SNOW_BLOCK)
B(10,-4,-2,SNOW_BLOCK)
B(10,-4,-1,SNOW_BLOCK)
B(10,-4,0,SNOW_BLOCK)
B(10,-4,1,CONCRETE:15)
B(10,-4,2,CONCRETE:15)
B(10,-4,3,CONCRETE:15)
B(10,-4,4,CONCRETE:15)
B(10,-4,5,SNOW_BLOCK)
B(10,-4,6,SNOW_BLOCK)
B(10,-4,7,SNOW_BLOCK)
B(10,-4,8,SNOW_BLOCK)
B(10,-3,-9,CONCRETE:15)
B(10,-3,-8,CONCRETE:15)
B(10,-3,-7,CONCRETE:15)
B(10,-3,-6,SNOW_BLOCK)
B(10,-3,-5,SNOW_BLOCK)
B(10,-3,-4,SNOW_BLOCK)
B(10,-3,-3,SNOW_BLOCK)
B(10,-3,-2,SNOW_BLOCK)
B(10,-3,-1,CONCRETE:15)
B(10,-3,0,CONCRETE:15)
B(10,-3,1,CONCRETE:15)
B(10,-3,2,CONCRETE:15)
B(10,-3,3,CONCRETE:15)
B(10,-3,4,CONCRETE:15)
B(10,-3,5,CONCRETE:15)
B(10,-3,6,CONCRETE:15)
B(10,-3,7,SNOW_BLOCK)
B(10,-3,8,SNOW_BLOCK)
B(10,-2,-9,CONCRETE:15)
B(10,-2,-8,SNOW_BLOCK)
B(10,-2,-7,SNOW_BLOCK)
B(10,-2,-6,SNOW_BLOCK)
B(10,-2,-5,SNOW_BLOCK)
B(10,-2,-4,SNOW_BLOCK)
B(10,-2,-3,SNOW_BLOCK)
B(10,-2,-2,SNOW_BLOCK)
B(10,-2,-1,CONCRETE:15)
B(10,-2,0,CONCRETE:15)
B(10,-2,1,CONCRETE:15)
B(10,-2,2,CONCRETE:15)
B(10,-2,3,CONCRETE:15)
B(10,-2,4,CONCRETE:15)
B(10,-2,5,CONCRETE:15)
B(10,-2,6,CONCRETE:15)
B(10,-2,7,SNOW_BLOCK)
B(10,-2,8,SNOW_BLOCK)
B(10,-1,-8,SNOW_BLOCK)
B(10,-1,-7,SNOW_BLOCK)
B(10,-1,-6,SNOW_BLOCK)
B(10,-1,1,CONCRETE:15)
B(10,-1,2,CONCRETE:15)
B(10,-1,3,CONCRETE:15)
B(10,-1,4,CONCRETE:15)
B(10,-1,5,CONCRETE:15)
B(10,-1,6,CONCRETE:15)
B(10,-1,7,CONCRETE:15)
B(10,0,-8,SNOW_BLOCK)
B(10,0,-7,SNOW_BLOCK)
B(10,0,-6,SNOW_BLOCK)
B(10,0,3,CONCRETE:15)
B(10,0,4,CONCRETE:15)
B(10,0,5,CONCRETE:15)
B(10,0,6,CONCRETE:15)
B(10,0,7,CONCRETE:15)
B(10,1,-8,SNOW_BLOCK)
B(10,1,-7,CONCRETE:15)
B(10,1,-6,CONCRETE:15)
B(10,1,4,CONCRETE:15)
B(10,1,5,CONCRETE:15)
B(10,1,6,CONCRETE:15)
B(11,-7,-5,CONCRETE:15)
B(11,-7,-4,CONCRETE:15)
B(11,-7,-3,CONCRETE:15)
B(11,-6,-5,CONCRETE:15)
B(11,-6,-4,CONCRETE:15)
B(11,-6,-3,CONCRETE:15)
B(11,-5,-5,CONCRETE:15)
B(11,-5,-4,CONCRETE:15)
B(11,-5,-3,CONCRETE:15)
B(11,-5,0,SNOW_BLOCK)
B(11,-5,1,CONCRETE:15)
B(11,-5,2,CONCRETE:15)
B(11,-5,3,CONCRETE:15)
B(11,-5,4,SNOW_BLOCK)
B(11,-5,5,SNOW_BLOCK)
B(11,-5,6,SNOW_BLOCK)
B(11,-4,0,SNOW_BLOCK)
B(11,-4,1,CONCRETE:15)
B(11,-4,2,CONCRETE:15)
B(11,-4,3,CONCRETE:15)
B(11,-4,4,CONCRETE:15)
B(11,-4,5,SNOW_BLOCK)
B(11,-4,6,SNOW_BLOCK)
B(11,-3,0,CONCRETE:15)
B(11,-3,1,CONCRETE:15)
B(11,-3,2,CONCRETE:15)
B(11,-3,3,CONCRETE:15)
B(11,-3,4,CONCRETE:15)
B(11,-3,5,CONCRETE:15)
B(11,-3,6,CONCRETE:15)

#######################################################################
# +-----------------------------------------------------------------+ #
# |                            BO3 checks                           | #
# +-----------------------------------------------------------------+ #
#######################################################################

BlockCheck(0,-1,0,SNOW,SNOW_BLOCK)

#######################################################################
# +-----------------------------------------------------------------+ #
# |                             Branches                            | #
# +-----------------------------------------------------------------+ #
#######################################################################


#######################################################################
# +-----------------------------------------------------------------+ #
# |                             Entities                            | #
# +-----------------------------------------------------------------+ #
#######################################################################


#######################################################################
# +-----------------------------------------------------------------+ #
# |                            Particles                            | #
# +-----------------------------------------------------------------+ #
#######################################################################


#######################################################################
# +-----------------------------------------------------------------+ #
# |                             Spawners                            | #
# +-----------------------------------------------------------------+ #
#######################################################################


#######################################################################
# +-----------------------------------------------------------------+ #
# |                             ModData                             | #
# +-----------------------------------------------------------------+ #
#######################################################################

