
#######################################################################
# +-----------------------------------------------------------------+ #
# |                            BO3 object                           | #
# +-----------------------------------------------------------------+ #
#######################################################################

Author: NLBlackHeavenNL

Description: No description given

Version: 3

SettingsMode: WriteWithoutComments


#######################################################################
# +-----------------------------------------------------------------+ #
# |                          Main settings                          | #
# +-----------------------------------------------------------------+ #
#######################################################################

Tree: true

Frequency: 1

Rarity: 100.0

RotateRandomly: false

SpawnHeight: highestSolidBlock

SpawnHeightOffset: -1

SpawnHeightVariance: 0

##############################
# Height Limits for the BO3. #
##############################

MinHeight: 0

MaxHeight: 255

######################
# Extrusion settings #
######################

ExtrudeMode: None

ExtrudeThroughBlocks: AIR

MaxBranchDepth: 10

ExcludedBiomes: All


#######################################################################
# +-----------------------------------------------------------------+ #
# |                      Source block settings                      | #
# +-----------------------------------------------------------------+ #
#######################################################################

SourceBlocks: AIR,GRASS,DIRT,biomesoplenty:dirt,biomesoplenty:grass,MYCEL

MaxPercentageOutsideSourceBlock: 0

OutsideSourceBlock: placeAnyway

DoReplaceBlocks: true

IsOTGPlus: false


#######################################################################
# +-----------------------------------------------------------------+ #
# |                              Blocks                             | #
# +-----------------------------------------------------------------+ #
#######################################################################

Block(-4,5,0,dynamictreesbop:leaves3:0)
Block(-4,6,0,dynamictreesbop:leaves3:0)
Block(-4,7,0,dynamictreesbop:leaves3:0)
Block(-3,5,-1,dynamictreesbop:leaves3:0)
Block(-3,5,0,dynamictreesbop:leaves3)
Block(-3,6,-1,dynamictreesbop:leaves3:0)
Block(-3,6,0,dynamictreesbop:leaves3:2)
Block(-3,6,1,dynamictreesbop:leaves3:0)
Block(-3,7,-1,dynamictreesbop:leaves3:0)
Block(-3,7,0,dynamictreesbop:leaves3:1)
Block(-3,7,1,dynamictreesbop:leaves3:0)
Block(-3,7,2,dynamictreesbop:leaves3:0)
Block(-3,7,3,dynamictreesbop:leaves3:0)
Block(-3,8,0,dynamictreesbop:leaves3:0)
Block(-3,8,1,dynamictreesbop:leaves3:0)
Block(-3,8,2,dynamictreesbop:leaves3:0)
Block(-3,9,1,dynamictreesbop:leaves3:0)
Block(-2,5,0,dynamictreesbop:jacarandabranch)
Block(-2,6,-1,dynamictreesbop:leaves3:0)
Block(-2,6,0,dynamictreesbop:leaves3)
Block(-2,6,2,dynamictreesbop:leaves3:0)
Block(-2,6,3,dynamictreesbop:leaves3:0)
Block(-2,7,-2,dynamictreesbop:leaves3:0)
Block(-2,7,-1,dynamictreesbop:leaves3:1)
Block(-2,7,0,dynamictreesbop:leaves3:2)
Block(-2,7,1,dynamictreesbop:leaves3)
Block(-2,7,2,dynamictreesbop:leaves3:2)
Block(-2,7,3,dynamictreesbop:leaves3:1)
Block(-2,7,4,dynamictreesbop:leaves3:0)
Block(-2,8,-2,dynamictreesbop:leaves3:0)
Block(-2,8,-1,dynamictreesbop:leaves3:0)
Block(-2,8,0,dynamictreesbop:leaves3:1)
Block(-2,8,1,dynamictreesbop:leaves3:2)
Block(-2,8,2,dynamictreesbop:leaves3:1)
Block(-2,8,3,dynamictreesbop:leaves3:0)
Block(-2,9,-2,dynamictreesbop:leaves3:0)
Block(-2,9,-1,dynamictreesbop:leaves3:0)
Block(-2,9,0,dynamictreesbop:leaves3:0)
Block(-2,9,1,dynamictreesbop:leaves3:1)
Block(-2,9,2,dynamictreesbop:leaves3:0)
Block(-2,10,1,dynamictreesbop:leaves3:0)
Block(-1,5,-5,dynamictreesbop:leaves3:0)
Block(-1,5,-4,dynamictreesbop:leaves3:0)
Block(-1,5,0,dynamictreesbop:jacarandabranch:1)
Block(-1,6,-5,dynamictreesbop:leaves3:0)
Block(-1,6,-4,dynamictreesbop:leaves3:0)
Block(-1,6,0,dynamictreesbop:jacarandabranch)
Block(-1,6,3,dynamictreesbop:leaves3:0)
Block(-1,6,4,dynamictreesbop:leaves3:0)
Block(-1,6,5,dynamictreesbop:leaves3:0)
Block(-1,7,-5,dynamictreesbop:leaves3:0)
Block(-1,7,-4,dynamictreesbop:leaves3:0)
Block(-1,7,-3,dynamictreesbop:leaves3:0)
Block(-1,7,-2,dynamictreesbop:leaves3:1)
Block(-1,7,-1,dynamictreesbop:leaves3:2)
Block(-1,7,0,dynamictreesbop:leaves3)
Block(-1,7,1,dynamictreesbop:jacarandabranch)
Block(-1,7,2,dynamictreesbop:leaves3)
Block(-1,7,3,dynamictreesbop:leaves3:2)
Block(-1,7,4,dynamictreesbop:leaves3:1)
Block(-1,7,5,dynamictreesbop:leaves3:0)
Block(-1,8,-3,dynamictreesbop:leaves3:0)
Block(-1,8,-2,dynamictreesbop:leaves3:2)
Block(-1,8,-1,dynamictreesbop:leaves3)
Block(-1,8,0,dynamictreesbop:leaves3:2)
Block(-1,8,1,dynamictreesbop:leaves3)
Block(-1,8,2,dynamictreesbop:leaves3:2)
Block(-1,8,3,dynamictreesbop:leaves3:1)
Block(-1,8,4,dynamictreesbop:leaves3:0)
Block(-1,9,-3,dynamictreesbop:leaves3:0)
Block(-1,9,-2,dynamictreesbop:leaves3:1)
Block(-1,9,-1,dynamictreesbop:leaves3:2)
Block(-1,9,0,dynamictreesbop:leaves3:1)
Block(-1,9,1,dynamictreesbop:leaves3:2)
Block(-1,9,2,dynamictreesbop:leaves3:1)
Block(-1,9,3,dynamictreesbop:leaves3:0)
Block(-1,10,-2,dynamictreesbop:leaves3:0)
Block(-1,10,-1,dynamictreesbop:leaves3:0)
Block(-1,10,0,dynamictreesbop:leaves3:0)
Block(-1,10,1,dynamictreesbop:leaves3:0)
Block(-1,10,2,dynamictreesbop:leaves3:0)
Block(0,3,0,dynamictreesbop:jacarandabranch)
Block(0,5,-6,dynamictreesbop:leaves3:0)
Block(0,5,-5,dynamictreesbop:leaves3:1)
Block(0,5,-4,dynamictreesbop:leaves3:2)
Block(0,5,0,dynamictreesbop:jacarandabranch:1)
Block(0,5,5,dynamictreesbop:leaves3:0)
Block(0,6,-6,dynamictreesbop:leaves3:0)
Block(0,6,-5,dynamictreesbop:leaves3:2)
Block(0,6,-4,dynamictreesbop:leaves3)
Block(0,6,-3,dynamictreesbop:leaves3:0)
Block(0,6,4,dynamictreesbop:leaves3)
Block(0,6,5,dynamictreesbop:leaves3:2)
Block(0,6,6,dynamictreesbop:leaves3:0)
Block(0,7,-6,dynamictreesbop:leaves3:0)
Block(0,7,-5,dynamictreesbop:leaves3:1)
Block(0,7,-4,dynamictreesbop:leaves3:2)
Block(0,7,-3,dynamictreesbop:leaves3:0)
Block(0,7,-2,dynamictreesbop:leaves3:0)
Block(0,7,0,dynamictreesbop:jacarandabranch:1)
Block(0,7,1,dynamictreesbop:jacarandabranch:1)
Block(0,7,2,dynamictreesbop:leaves3:2)
Block(0,7,3,dynamictreesbop:leaves3)
Block(0,7,4,dynamictreesbop:leaves3:2)
Block(0,7,5,dynamictreesbop:leaves3:1)
Block(0,7,6,dynamictreesbop:leaves3:0)
Block(0,8,-5,dynamictreesbop:leaves3:0)
Block(0,8,-4,dynamictreesbop:leaves3:0)
Block(0,8,-3,dynamictreesbop:leaves3:0)
Block(0,8,-2,dynamictreesbop:leaves3)
Block(0,8,-1,dynamictreesbop:jacarandabranch)
Block(0,8,0,dynamictreesbop:leaves3)
Block(0,8,1,dynamictreesbop:jacarandabranch)
Block(0,8,2,dynamictreesbop:leaves3)
Block(0,8,3,dynamictreesbop:leaves3:2)
Block(0,8,4,dynamictreesbop:leaves3:1)
Block(0,8,5,dynamictreesbop:leaves3:0)
Block(0,9,-3,dynamictreesbop:leaves3:0)
Block(0,9,-2,dynamictreesbop:leaves3:2)
Block(0,9,-1,dynamictreesbop:leaves3)
Block(0,9,0,dynamictreesbop:leaves3)
Block(0,9,1,dynamictreesbop:leaves3)
Block(0,9,2,dynamictreesbop:leaves3:2)
Block(0,9,3,dynamictreesbop:leaves3:1)
Block(0,9,4,dynamictreesbop:leaves3:0)
Block(0,10,-2,dynamictreesbop:leaves3:0)
Block(0,10,-1,dynamictreesbop:leaves3:1)
Block(0,10,0,dynamictreesbop:leaves3:2)
Block(0,10,1,dynamictreesbop:leaves3:1)
Block(0,10,2,dynamictreesbop:leaves3:0)
Block(0,10,3,dynamictreesbop:leaves3:0)
Block(0,11,-1,dynamictreesbop:leaves3:0)
Block(0,11,0,dynamictreesbop:leaves3:0)
Block(0,11,1,dynamictreesbop:leaves3:0)
Block(1,0,0,dynamictrees:rootydirt)
Block(1,1,0,dynamictreesbop:jacarandabranch:7)
Block(1,2,0,dynamictreesbop:jacarandabranch:7)
Block(1,3,-1,dynamictreesbop:jacarandabranch)
Block(1,3,0,dynamictreesbop:jacarandabranch:7)
Block(1,4,0,dynamictreesbop:jacarandabranch:6)
Block(1,5,-6,dynamictreesbop:leaves3:0)
Block(1,5,-5,dynamictreesbop:leaves3:2)
Block(1,5,-4,dynamictreesbop:leaves3)
Block(1,5,0,dynamictreesbop:jacarandabranch:6)
Block(1,6,-6,dynamictreesbop:leaves3:0)
Block(1,6,-5,dynamictreesbop:leaves3)
Block(1,6,-4,dynamictreesbop:jacarandabranch)
Block(1,6,-3,dynamictreesbop:jacarandabranch:1)
Block(1,6,-2,dynamictreesbop:jacarandabranch:1)
Block(1,6,-1,dynamictreesbop:jacarandabranch:1)
Block(1,6,0,dynamictreesbop:jacarandabranch:5)
Block(1,6,1,dynamictreesbop:jacarandabranch:2)
Block(1,6,2,dynamictreesbop:jacarandabranch:1)
Block(1,6,3,dynamictreesbop:jacarandabranch:1)
Block(1,6,4,dynamictreesbop:jacarandabranch)
Block(1,6,5,dynamictreesbop:leaves3)
Block(1,6,6,dynamictreesbop:leaves3:0)
Block(1,7,-6,dynamictreesbop:leaves3:0)
Block(1,7,-5,dynamictreesbop:leaves3:2)
Block(1,7,-4,dynamictreesbop:leaves3)
Block(1,7,-3,dynamictreesbop:leaves3:0)
Block(1,7,0,dynamictreesbop:jacarandabranch:3)
Block(1,7,2,dynamictreesbop:leaves3)
Block(1,7,3,dynamictreesbop:jacarandabranch)
Block(1,7,4,dynamictreesbop:leaves3)
Block(1,7,5,dynamictreesbop:leaves3:2)
Block(1,7,6,dynamictreesbop:leaves3:0)
Block(1,8,-5,dynamictreesbop:leaves3:0)
Block(1,8,-4,dynamictreesbop:leaves3:0)
Block(1,8,-2,dynamictreesbop:leaves3:0)
Block(1,8,-1,dynamictreesbop:jacarandabranch:1)
Block(1,8,0,dynamictreesbop:jacarandabranch:2)
Block(1,8,1,dynamictreesbop:leaves3)
Block(1,8,2,dynamictreesbop:leaves3:2)
Block(1,8,3,dynamictreesbop:leaves3)
Block(1,8,4,dynamictreesbop:leaves3:2)
Block(1,8,5,dynamictreesbop:leaves3:1)
Block(1,8,6,dynamictreesbop:leaves3:0)
Block(1,9,-2,dynamictreesbop:leaves3:0)
Block(1,9,-1,dynamictreesbop:leaves3)
Block(1,9,0,dynamictreesbop:jacarandabranch)
Block(1,9,1,dynamictreesbop:leaves3)
Block(1,9,2,dynamictreesbop:leaves3:1)
Block(1,9,3,dynamictreesbop:leaves3:0)
Block(1,9,4,dynamictreesbop:leaves3:0)
Block(1,9,5,dynamictreesbop:leaves3:0)
Block(1,10,-2,dynamictreesbop:leaves3:0)
Block(1,10,-1,dynamictreesbop:leaves3:2)
Block(1,10,0,dynamictreesbop:leaves3)
Block(1,10,1,dynamictreesbop:leaves3:2)
Block(1,10,2,dynamictreesbop:leaves3:0)
Block(1,11,-1,dynamictreesbop:leaves3:0)
Block(1,11,0,dynamictreesbop:leaves3:0)
Block(1,11,1,dynamictreesbop:leaves3:0)
Block(2,3,0,dynamictreesbop:jacarandabranch:4)
Block(2,3,1,dynamictreesbop:jacarandabranch:1)
Block(2,4,1,dynamictreesbop:jacarandabranch:1)
Block(2,5,-6,dynamictreesbop:leaves3:0)
Block(2,5,-5,dynamictreesbop:leaves3:1)
Block(2,5,-4,dynamictreesbop:leaves3:2)
Block(2,5,0,dynamictreesbop:jacarandabranch:2)
Block(2,5,5,dynamictreesbop:leaves3:0)
Block(2,6,-6,dynamictreesbop:leaves3:0)
Block(2,6,-5,dynamictreesbop:leaves3:2)
Block(2,6,-4,dynamictreesbop:leaves3)
Block(2,6,-3,dynamictreesbop:leaves3:2)
Block(2,6,1,dynamictreesbop:jacarandabranch:1)
Block(2,6,3,dynamictreesbop:leaves3:2)
Block(2,6,4,dynamictreesbop:leaves3)
Block(2,6,5,dynamictreesbop:leaves3:2)
Block(2,6,6,dynamictreesbop:leaves3:0)
Block(2,7,-6,dynamictreesbop:leaves3:0)
Block(2,7,-5,dynamictreesbop:leaves3:1)
Block(2,7,-4,dynamictreesbop:leaves3:2)
Block(2,7,-3,dynamictreesbop:leaves3:1)
Block(2,7,-2,dynamictreesbop:leaves3:0)
Block(2,7,1,dynamictreesbop:jacarandabranch)
Block(2,7,2,dynamictreesbop:leaves3)
Block(2,7,3,dynamictreesbop:leaves3)
Block(2,7,4,dynamictreesbop:leaves3:2)
Block(2,7,5,dynamictreesbop:leaves3:1)
Block(2,7,6,dynamictreesbop:leaves3:0)
Block(2,8,-5,dynamictreesbop:leaves3:0)
Block(2,8,-4,dynamictreesbop:leaves3:0)
Block(2,8,-3,dynamictreesbop:leaves3:0)
Block(2,8,-2,dynamictreesbop:leaves3:0)
Block(2,8,-1,dynamictreesbop:leaves3:0)
Block(2,8,0,dynamictreesbop:jacarandabranch:1)
Block(2,8,1,dynamictreesbop:leaves3)
Block(2,8,2,dynamictreesbop:leaves3:2)
Block(2,8,3,dynamictreesbop:leaves3:2)
Block(2,8,4,dynamictreesbop:leaves3:1)
Block(2,8,5,dynamictreesbop:leaves3:0)
Block(2,9,-2,dynamictreesbop:leaves3:0)
Block(2,9,-1,dynamictreesbop:leaves3:2)
Block(2,9,0,dynamictreesbop:leaves3)
Block(2,9,1,dynamictreesbop:leaves3:2)
Block(2,9,2,dynamictreesbop:leaves3:1)
Block(2,9,3,dynamictreesbop:leaves3:0)
Block(2,9,4,dynamictreesbop:leaves3:0)
Block(2,10,-2,dynamictreesbop:leaves3:0)
Block(2,10,-1,dynamictreesbop:leaves3:1)
Block(2,10,0,dynamictreesbop:leaves3:2)
Block(2,10,1,dynamictreesbop:leaves3:1)
Block(2,10,2,dynamictreesbop:leaves3:0)
Block(2,11,-1,dynamictreesbop:leaves3:0)
Block(2,11,0,dynamictreesbop:leaves3:0)
Block(2,11,1,dynamictreesbop:leaves3:0)
Block(3,3,-2,dynamictreesbop:jacarandabranch:1)
Block(3,3,-1,dynamictreesbop:jacarandabranch:1)
Block(3,3,0,dynamictreesbop:jacarandabranch:3)
Block(3,4,-2,dynamictreesbop:jacarandabranch)
Block(3,4,1,dynamictreesbop:jacarandabranch)
Block(3,5,-5,dynamictreesbop:leaves3:0)
Block(3,5,-4,dynamictreesbop:leaves3:1)
Block(3,5,-2,dynamictreesbop:leaves3)
Block(3,5,-1,dynamictreesbop:jacarandabranch:1)
Block(3,5,0,dynamictreesbop:jacarandabranch:1)
Block(3,5,1,dynamictreesbop:leaves3)
Block(3,6,-6,dynamictreesbop:leaves3:0)
Block(3,6,-5,dynamictreesbop:leaves3:1)
Block(3,6,-4,dynamictreesbop:leaves3:2)
Block(3,6,-3,dynamictreesbop:leaves3)
Block(3,6,-2,dynamictreesbop:jacarandabranch)
Block(3,6,-1,dynamictreesbop:jacarandabranch:1)
Block(3,6,1,dynamictreesbop:jacarandabranch)
Block(3,6,2,dynamictreesbop:leaves3)
Block(3,6,3,dynamictreesbop:leaves3:0)
Block(3,6,4,dynamictreesbop:leaves3:0)
Block(3,6,5,dynamictreesbop:leaves3:0)
Block(3,7,-5,dynamictreesbop:leaves3:0)
Block(3,7,-4,dynamictreesbop:leaves3:1)
Block(3,7,-3,dynamictreesbop:leaves3:2)
Block(3,7,-2,dynamictreesbop:leaves3)
Block(3,7,-1,dynamictreesbop:leaves3:2)
Block(3,7,1,dynamictreesbop:leaves3)
Block(3,7,2,dynamictreesbop:leaves3:2)
Block(3,7,3,dynamictreesbop:leaves3:0)
Block(3,7,4,dynamictreesbop:leaves3:0)
Block(3,7,5,dynamictreesbop:leaves3:0)
Block(3,8,-4,dynamictreesbop:leaves3:0)
Block(3,8,-3,dynamictreesbop:leaves3:1)
Block(3,8,-2,dynamictreesbop:leaves3:2)
Block(3,8,-1,dynamictreesbop:leaves3)
Block(3,8,0,dynamictreesbop:jacarandabranch)
Block(3,8,1,dynamictreesbop:leaves3)
Block(3,8,2,dynamictreesbop:leaves3:1)
Block(3,8,3,dynamictreesbop:leaves3:0)
Block(3,8,4,dynamictreesbop:leaves3:0)
Block(3,9,-3,dynamictreesbop:leaves3:0)
Block(3,9,-2,dynamictreesbop:leaves3:1)
Block(3,9,-1,dynamictreesbop:leaves3:2)
Block(3,9,0,dynamictreesbop:leaves3)
Block(3,9,1,dynamictreesbop:leaves3:2)
Block(3,9,2,dynamictreesbop:leaves3:0)
Block(3,10,-2,dynamictreesbop:leaves3:0)
Block(3,10,-1,dynamictreesbop:leaves3:0)
Block(3,10,0,dynamictreesbop:leaves3:0)
Block(3,10,1,dynamictreesbop:leaves3:0)
Block(4,3,0,dynamictreesbop:jacarandabranch:2)
Block(4,3,1,dynamictreesbop:jacarandabranch)
Block(4,4,-1,dynamictreesbop:jacarandabranch)
Block(4,4,0,dynamictreesbop:jacarandabranch:1)
Block(4,4,1,dynamictreesbop:leaves3)
Block(4,5,-4,dynamictreesbop:leaves3:0)
Block(4,5,-3,dynamictreesbop:leaves3:0)
Block(4,5,-1,dynamictreesbop:leaves3)
Block(4,5,1,dynamictreesbop:leaves3:2)
Block(4,6,-5,dynamictreesbop:leaves3:0)
Block(4,6,-4,dynamictreesbop:leaves3:1)
Block(4,6,-3,dynamictreesbop:leaves3:2)
Block(4,6,-2,dynamictreesbop:leaves3)
Block(4,6,-1,dynamictreesbop:leaves3:2)
Block(4,6,1,dynamictreesbop:leaves3)
Block(4,6,2,dynamictreesbop:leaves3:2)
Block(4,6,3,dynamictreesbop:leaves3:0)
Block(4,7,-4,dynamictreesbop:leaves3:0)
Block(4,7,-3,dynamictreesbop:leaves3:1)
Block(4,7,-2,dynamictreesbop:leaves3:2)
Block(4,7,-1,dynamictreesbop:leaves3:1)
Block(4,7,0,dynamictreesbop:leaves3:0)
Block(4,7,1,dynamictreesbop:leaves3:2)
Block(4,7,2,dynamictreesbop:leaves3:1)
Block(4,7,3,dynamictreesbop:leaves3:0)
Block(4,8,-3,dynamictreesbop:leaves3:0)
Block(4,8,-2,dynamictreesbop:leaves3:1)
Block(4,8,-1,dynamictreesbop:leaves3:2)
Block(4,8,0,dynamictreesbop:leaves3)
Block(4,8,1,dynamictreesbop:leaves3:2)
Block(4,8,2,dynamictreesbop:leaves3:0)
Block(4,9,-2,dynamictreesbop:leaves3:0)
Block(4,9,-1,dynamictreesbop:leaves3:1)
Block(4,9,0,dynamictreesbop:leaves3:2)
Block(4,9,1,dynamictreesbop:leaves3:1)
Block(4,9,2,dynamictreesbop:leaves3:0)
Block(4,10,-1,dynamictreesbop:leaves3:0)
Block(4,10,0,dynamictreesbop:leaves3:0)
Block(4,10,1,dynamictreesbop:leaves3:0)
Block(5,3,0,dynamictreesbop:leaves3:2)
Block(5,4,0,dynamictreesbop:jacarandabranch:1)
Block(5,5,0,dynamictreesbop:leaves3:0)
Block(5,6,-4,dynamictreesbop:leaves3:0)
Block(5,6,-3,dynamictreesbop:leaves3:0)
Block(5,6,-2,dynamictreesbop:leaves3:0)
Block(5,6,-1,dynamictreesbop:leaves3:0)
Block(5,6,1,dynamictreesbop:leaves3:0)
Block(5,6,2,dynamictreesbop:leaves3:0)
Block(5,7,-3,dynamictreesbop:leaves3:0)
Block(5,7,-2,dynamictreesbop:leaves3:0)
Block(5,7,-1,dynamictreesbop:leaves3:0)
Block(5,7,1,dynamictreesbop:leaves3:0)
Block(5,7,2,dynamictreesbop:leaves3:0)
Block(5,8,-2,dynamictreesbop:leaves3:0)
Block(5,8,-1,dynamictreesbop:leaves3:0)
Block(5,8,0,dynamictreesbop:leaves3:0)
Block(5,8,1,dynamictreesbop:leaves3:0)
Block(5,9,-1,dynamictreesbop:leaves3:0)
Block(5,9,0,dynamictreesbop:leaves3:0)
Block(5,9,1,dynamictreesbop:leaves3:0)
Block(6,3,-2,dynamictreesbop:leaves3:0)
Block(6,3,-1,dynamictreesbop:leaves3:2)
Block(6,3,0,dynamictreesbop:leaves3)
Block(6,3,1,dynamictreesbop:leaves3:2)
Block(6,3,2,dynamictreesbop:leaves3:0)
Block(6,4,-2,dynamictreesbop:leaves3:0)
Block(6,4,-1,dynamictreesbop:leaves3)
Block(6,4,0,dynamictreesbop:jacarandabranch)
Block(6,4,1,dynamictreesbop:leaves3)
Block(6,4,2,dynamictreesbop:leaves3:0)
Block(6,5,-2,dynamictreesbop:leaves3:0)
Block(6,5,-1,dynamictreesbop:leaves3:2)
Block(6,5,0,dynamictreesbop:leaves3)
Block(6,5,1,dynamictreesbop:leaves3:2)
Block(6,5,2,dynamictreesbop:leaves3:0)
Block(6,6,-1,dynamictreesbop:leaves3:0)
Block(6,6,0,dynamictreesbop:leaves3:0)
Block(6,6,1,dynamictreesbop:leaves3:0)
Block(7,3,-2,dynamictreesbop:leaves3:0)
Block(7,3,-1,dynamictreesbop:leaves3:1)
Block(7,3,0,dynamictreesbop:leaves3:2)
Block(7,3,1,dynamictreesbop:leaves3:1)
Block(7,3,2,dynamictreesbop:leaves3:0)
Block(7,4,-2,dynamictreesbop:leaves3:0)
Block(7,4,-1,dynamictreesbop:leaves3:2)
Block(7,4,0,dynamictreesbop:leaves3)
Block(7,4,1,dynamictreesbop:leaves3:2)
Block(7,4,2,dynamictreesbop:leaves3:0)
Block(7,5,-2,dynamictreesbop:leaves3:0)
Block(7,5,-1,dynamictreesbop:leaves3:1)
Block(7,5,0,dynamictreesbop:leaves3:2)
Block(7,5,1,dynamictreesbop:leaves3:1)
Block(7,5,2,dynamictreesbop:leaves3:0)
Block(7,6,-1,dynamictreesbop:leaves3:0)
Block(7,6,0,dynamictreesbop:leaves3:0)
Block(7,6,1,dynamictreesbop:leaves3:0)
Block(8,3,-1,dynamictreesbop:leaves3:0)
Block(8,3,0,dynamictreesbop:leaves3:0)
Block(8,3,1,dynamictreesbop:leaves3:0)
Block(8,4,-1,dynamictreesbop:leaves3:0)
Block(8,4,0,dynamictreesbop:leaves3:0)
Block(8,4,1,dynamictreesbop:leaves3:0)
Block(8,5,-1,dynamictreesbop:leaves3:0)
Block(8,5,0,dynamictreesbop:leaves3:0)
Block(8,5,1,dynamictreesbop:leaves3:0)

#######################################################################
# +-----------------------------------------------------------------+ #
# |                            BO3 checks                           | #
# +-----------------------------------------------------------------+ #
#######################################################################

BlockCheck(1,-1,-1,GRASS,DIRT,MYCEL,biomesoplenty:grass,biomesoplenty:dirt)

#######################################################################
# +-----------------------------------------------------------------+ #
# |                             Branches                            | #
# +-----------------------------------------------------------------+ #
#######################################################################


#######################################################################
# +-----------------------------------------------------------------+ #
# |                             Entities                            | #
# +-----------------------------------------------------------------+ #
#######################################################################


#######################################################################
# +-----------------------------------------------------------------+ #
# |                            Particles                            | #
# +-----------------------------------------------------------------+ #
#######################################################################


#######################################################################
# +-----------------------------------------------------------------+ #
# |                             Spawners                            | #
# +-----------------------------------------------------------------+ #
#######################################################################


#######################################################################
# +-----------------------------------------------------------------+ #
# |                             ModData                             | #
# +-----------------------------------------------------------------+ #
#######################################################################

