
#######################################################################
# +-----------------------------------------------------------------+ #
# |                            BO3 object                           | #
# +-----------------------------------------------------------------+ #
#######################################################################

Author: NLBlackHeavenNL

Description: No description given

Version: 3

SettingsMode: WriteWithoutComments


#######################################################################
# +-----------------------------------------------------------------+ #
# |                          Main settings                          | #
# +-----------------------------------------------------------------+ #
#######################################################################

Tree: true

Frequency: 1

Rarity: 100.0

RotateRandomly: false

SpawnHeight: highestSolidBlock

SpawnHeightOffset: -1

SpawnHeightVariance: 0

##############################
# Height Limits for the BO3. #
##############################

MinHeight: 0

MaxHeight: 255

######################
# Extrusion settings #
######################

ExtrudeMode: None

ExtrudeThroughBlocks: AIR

MaxBranchDepth: 10

ExcludedBiomes: All


#######################################################################
# +-----------------------------------------------------------------+ #
# |                      Source block settings                      | #
# +-----------------------------------------------------------------+ #
#######################################################################

SourceBlocks: AIR,GRASS,DIRT,biomesoplenty:dirt,biomesoplenty:grass

MaxPercentageOutsideSourceBlock: 0

OutsideSourceBlock: placeAnyway

DoReplaceBlocks: true

IsOTGPlus: false


#######################################################################
# +-----------------------------------------------------------------+ #
# |                              Blocks                             | #
# +-----------------------------------------------------------------+ #
#######################################################################

Block(-3,4,0,dynamictreesbop:leaves0:4)
Block(-3,4,1,dynamictreesbop:leaves0:4)
Block(-3,4,2,dynamictreesbop:leaves0:4)
Block(-3,5,0,dynamictreesbop:leaves0:4)
Block(-3,5,1,dynamictreesbop:leaves0:4)
Block(-3,5,2,dynamictreesbop:leaves0:4)
Block(-3,6,0,dynamictreesbop:leaves0:4)
Block(-3,6,1,dynamictreesbop:leaves0:4)
Block(-3,6,2,dynamictreesbop:leaves0:4)
Block(-2,3,-2,dynamictreesbop:leaves0:4)
Block(-2,3,-1,dynamictreesbop:leaves0:4)
Block(-2,4,-2,dynamictreesbop:leaves0:4)
Block(-2,4,-1,dynamictreesbop:leaves0:4)
Block(-2,4,0,dynamictreesbop:leaves0:5)
Block(-2,4,1,dynamictreesbop:leaves0:6)
Block(-2,4,2,dynamictreesbop:leaves0:5)
Block(-2,4,3,dynamictreesbop:leaves0:4)
Block(-2,5,-1,dynamictreesbop:leaves0:4)
Block(-2,5,0,dynamictreesbop:leaves0:6)
Block(-2,5,1,dynamictreesbop:leaves0:7)
Block(-2,5,2,dynamictreesbop:leaves0:6)
Block(-2,5,3,dynamictreesbop:leaves0:4)
Block(-2,6,-1,dynamictreesbop:leaves0:4)
Block(-2,6,0,dynamictreesbop:leaves0:5)
Block(-2,6,1,dynamictreesbop:leaves0:6)
Block(-2,6,2,dynamictreesbop:leaves0:5)
Block(-2,6,3,dynamictreesbop:leaves0:4)
Block(-2,7,0,dynamictreesbop:leaves0:4)
Block(-2,7,1,dynamictreesbop:leaves0:4)
Block(-2,7,2,dynamictreesbop:leaves0:4)
Block(-1,2,-2,dynamictreesbop:leaves0:4)
Block(-1,3,-3,dynamictreesbop:leaves0:4)
Block(-1,3,-2,dynamictreesbop:leaves0:6)
Block(-1,3,-1,dynamictreesbop:leaves0:7)
Block(-1,4,-3,dynamictreesbop:leaves0:4)
Block(-1,4,-2,dynamictreesbop:leaves0:5)
Block(-1,4,-1,dynamictreesbop:leaves0:6)
Block(-1,4,0,dynamictreesbop:leaves0:6)
Block(-1,4,1,dynamictreesbop:leaves0:7)
Block(-1,4,2,dynamictreesbop:leaves0:6)
Block(-1,4,3,dynamictreesbop:leaves0:4)
Block(-1,5,-2,dynamictreesbop:leaves0:4)
Block(-1,5,-1,dynamictreesbop:leaves0:4)
Block(-1,5,0,dynamictreesbop:leaves0:7)
Block(-1,5,1,dynamictrees:darkoakbranch)
Block(-1,5,2,dynamictreesbop:leaves0:7)
Block(-1,5,3,dynamictreesbop:leaves0:4)
Block(-1,6,-1,dynamictreesbop:leaves0:4)
Block(-1,6,0,dynamictreesbop:leaves0:6)
Block(-1,6,1,dynamictreesbop:leaves0:7)
Block(-1,6,2,dynamictreesbop:leaves0:6)
Block(-1,6,3,dynamictreesbop:leaves0:4)
Block(-1,7,0,dynamictreesbop:leaves0:4)
Block(-1,7,1,dynamictreesbop:leaves0:4)
Block(-1,7,2,dynamictreesbop:leaves0:4)
Block(0,0,1,dynamictrees:rootydirtspecies:0,DT_BPOrangeOak_Med_03/1-species_tile_entity.nbt)
Block(0,1,1,dynamictrees:darkoakbranch:3)
Block(0,2,-2,dynamictreesbop:leaves0:4)
Block(0,2,1,dynamictrees:darkoakbranch:3)
Block(0,3,-3,dynamictreesbop:leaves0:4)
Block(0,3,-2,dynamictreesbop:leaves0:7)
Block(0,3,-1,dynamictrees:darkoakbranch)
Block(0,3,0,dynamictrees:darkoakbranch:1)
Block(0,3,1,dynamictrees:darkoakbranch:2)
Block(0,4,-3,dynamictreesbop:leaves0:4)
Block(0,4,-2,dynamictreesbop:leaves0:6)
Block(0,4,-1,dynamictreesbop:leaves0:7)
Block(0,4,0,dynamictreesbop:leaves0:7)
Block(0,4,1,dynamictrees:darkoakbranch:1)
Block(0,4,2,dynamictreesbop:leaves0:4)
Block(0,5,-2,dynamictreesbop:leaves0:4)
Block(0,5,-1,dynamictreesbop:leaves0:7)
Block(0,5,0,dynamictrees:darkoakbranch)
Block(0,5,1,dynamictrees:darkoakbranch:1)
Block(0,5,2,dynamictreesbop:leaves0:4)
Block(0,6,-1,dynamictreesbop:leaves0:4)
Block(0,6,0,dynamictreesbop:leaves0:7)
Block(0,6,1,dynamictreesbop:leaves0:6)
Block(0,6,2,dynamictreesbop:leaves0:5)
Block(0,6,3,dynamictreesbop:leaves0:4)
Block(0,7,0,dynamictreesbop:leaves0:4)
Block(0,7,1,dynamictreesbop:leaves0:4)
Block(0,7,2,dynamictreesbop:leaves0:4)
Block(1,1,0,dynamictreesbop:leaves0:4)
Block(1,2,-2,dynamictreesbop:leaves0:4)
Block(1,2,-1,dynamictreesbop:leaves0:4)
Block(1,2,0,dynamictreesbop:leaves0:6)
Block(1,3,-3,dynamictreesbop:leaves0:4)
Block(1,3,-2,dynamictreesbop:leaves0:6)
Block(1,3,-1,dynamictreesbop:leaves0:7)
Block(1,3,0,dynamictreesbop:leaves0:7)
Block(1,3,1,dynamictrees:darkoakbranch)
Block(1,3,2,dynamictreesbop:leaves0:7)
Block(1,4,-3,dynamictreesbop:leaves0:4)
Block(1,4,-2,dynamictreesbop:leaves0:5)
Block(1,4,-1,dynamictreesbop:leaves0:6)
Block(1,4,0,dynamictreesbop:leaves0:6)
Block(1,4,1,dynamictreesbop:leaves0:7)
Block(1,4,2,dynamictreesbop:leaves0:6)
Block(1,4,3,dynamictreesbop:leaves0:4)
Block(1,5,-2,dynamictreesbop:leaves0:4)
Block(1,5,-1,dynamictreesbop:leaves0:4)
Block(1,5,0,dynamictreesbop:leaves0:7)
Block(1,5,1,dynamictreesbop:leaves0:6)
Block(1,5,2,dynamictreesbop:leaves0:5)
Block(1,5,3,dynamictreesbop:leaves0:4)
Block(1,6,-1,dynamictreesbop:leaves0:4)
Block(1,6,0,dynamictreesbop:leaves0:6)
Block(1,6,1,dynamictreesbop:leaves0:5)
Block(1,6,2,dynamictreesbop:leaves0:4)
Block(1,7,0,dynamictreesbop:leaves0:4)
Block(1,7,1,dynamictreesbop:leaves0:4)
Block(2,2,0,dynamictreesbop:leaves0:4)
Block(2,2,1,dynamictreesbop:leaves0:4)
Block(2,3,-2,dynamictreesbop:leaves0:4)
Block(2,3,-1,dynamictreesbop:leaves0:4)
Block(2,3,0,dynamictreesbop:leaves0:6)
Block(2,3,1,dynamictreesbop:leaves0:7)
Block(2,3,2,dynamictreesbop:leaves0:4)
Block(2,4,-2,dynamictreesbop:leaves0:4)
Block(2,4,-1,dynamictreesbop:leaves0:4)
Block(2,4,0,dynamictreesbop:leaves0:5)
Block(2,4,1,dynamictreesbop:leaves0:6)
Block(2,4,2,dynamictreesbop:leaves0:5)
Block(2,4,3,dynamictreesbop:leaves0:4)
Block(2,5,0,dynamictreesbop:leaves0:4)
Block(2,5,1,dynamictreesbop:leaves0:5)
Block(2,5,2,dynamictreesbop:leaves0:4)
Block(2,6,0,dynamictreesbop:leaves0:4)
Block(2,6,1,dynamictreesbop:leaves0:4)
Block(3,3,0,dynamictreesbop:leaves0:4)
Block(3,3,1,dynamictreesbop:leaves0:4)
Block(3,4,0,dynamictreesbop:leaves0:4)
Block(3,4,1,dynamictreesbop:leaves0:4)
Block(3,4,2,dynamictreesbop:leaves0:4)
Block(3,5,1,dynamictreesbop:leaves0:4)

#######################################################################
# +-----------------------------------------------------------------+ #
# |                            BO3 checks                           | #
# +-----------------------------------------------------------------+ #
#######################################################################

BlockCheck(0,-1,1,GRASS,DIRT,biomesoplenty:grass,biomesoplenty:dirt)

#######################################################################
# +-----------------------------------------------------------------+ #
# |                             Branches                            | #
# +-----------------------------------------------------------------+ #
#######################################################################


#######################################################################
# +-----------------------------------------------------------------+ #
# |                             Entities                            | #
# +-----------------------------------------------------------------+ #
#######################################################################


#######################################################################
# +-----------------------------------------------------------------+ #
# |                            Particles                            | #
# +-----------------------------------------------------------------+ #
#######################################################################


#######################################################################
# +-----------------------------------------------------------------+ #
# |                             Spawners                            | #
# +-----------------------------------------------------------------+ #
#######################################################################


#######################################################################
# +-----------------------------------------------------------------+ #
# |                             ModData                             | #
# +-----------------------------------------------------------------+ #
#######################################################################

