
#######################################################################
# +-----------------------------------------------------------------+ #
# |                            BO3 object                           | #
# +-----------------------------------------------------------------+ #
#######################################################################

Author: NLBlackEagle

Description: No description given

Version: 3

SettingsMode: WriteWithoutComments


#######################################################################
# +-----------------------------------------------------------------+ #
# |                          Main settings                          | #
# +-----------------------------------------------------------------+ #
#######################################################################

Tree: true

Frequency: 200

Rarity: 100.0

RotateRandomly: true

SpawnHeight: randomY

SpawnHeightOffset: 0

SpawnHeightVariance: 0

##############################
# Height Limits for the BO3. #
##############################

MinHeight: 20

MaxHeight: 90

######################
# Extrusion settings #
######################

ExtrudeMode: None

ExtrudeThroughBlocks: AIR

MaxBranchDepth: 10

ExcludedBiomes: All


#######################################################################
# +-----------------------------------------------------------------+ #
# |                      Source block settings                      | #
# +-----------------------------------------------------------------+ #
#######################################################################

SourceBlocks: Solid

MaxPercentageOutsideSourceBlock: 5

OutsideSourceBlock: placeAnyway

DoReplaceBlocks: false

IsOTGPlus: false


#######################################################################
# +-----------------------------------------------------------------+ #
# |                              Blocks                             | #
# +-----------------------------------------------------------------+ #
#######################################################################

Block(-10,14,-2,STONE:0)
Block(-9,9,-3,STONE:0)
Block(-9,9,-2,STONE:0)
Block(-9,9,-1,STONE:0)
Block(-9,10,-3,STONE:0)
Block(-9,10,-2,STONE:0)
Block(-9,10,-1,STONE:0)
Block(-9,11,-3,STONE:0)
Block(-9,11,-2,STONE:0)
Block(-9,11,-1,STONE:0)
Block(-9,12,-3,STONE:0)
Block(-9,12,-2,STONE:0)
Block(-9,12,-1,STONE:0)
Block(-9,13,-4,STONE:0)
Block(-9,13,-3,STONE:0)
Block(-9,13,-2,STONE:0)
Block(-9,13,-1,STONE:0)
Block(-9,13,0,STONE:0)
Block(-9,14,-4,STONE:0)
Block(-9,14,-3,STONE:0)
Block(-9,14,-2,STONE:0)
Block(-9,14,-1,STONE:0)
Block(-9,14,0,STONE:0)
Block(-9,15,-4,STONE:0)
Block(-9,15,-3,STONE:0)
Block(-9,15,-2,STONE:0)
Block(-9,15,-1,STONE:0)
Block(-9,15,0,STONE:0)
Block(-9,16,-3,STONE:0)
Block(-9,16,-2,STONE:0)
Block(-9,16,-1,STONE:0)
Block(-8,8,-3,STONE:0)
Block(-8,8,-2,STONE:0)
Block(-8,8,-1,STONE:0)
Block(-8,9,-4,STONE:0)
Block(-8,9,-3,STONE:0)
Block(-8,9,-2,STONE:0)
Block(-8,9,-1,STONE:0)
Block(-8,9,0,STONE:0)
Block(-8,10,-4,STONE:0)
Block(-8,10,-3,STONE:0)
Block(-8,10,-2,STONE:0)
Block(-8,10,-1,STONE:0)
Block(-8,10,0,STONE:0)
Block(-8,11,-4,STONE:0)
Block(-8,11,-3,STONE:0)
Block(-8,11,-2,STONE:0)
Block(-8,11,-1,STONE:0)
Block(-8,11,0,LEAVES:4)
Block(-8,11,1,STONE:0)
Block(-8,12,-4,STONE:0)
Block(-8,12,-3,STONE:0)
Block(-8,12,-2,LEAVES:4)
Block(-8,12,-1,STONE:0)
Block(-8,12,0,STONE:0)
Block(-8,12,1,STONE:0)
Block(-8,13,-4,STONE:0)
Block(-8,13,-3,STONE:0)
Block(-8,13,-2,LEAVES:4)
Block(-8,13,-1,STONE:0)
Block(-8,13,0,STONE:0)
Block(-8,13,1,STONE:0)
Block(-8,13,3,STONE:0)
Block(-8,14,-4,STONE:0)
Block(-8,14,-3,STONE:0)
Block(-8,14,-2,STONE:0)
Block(-8,14,-1,STONE:0)
Block(-8,14,0,STONE:0)
Block(-8,15,-4,STONE:0)
Block(-8,15,-3,STONE:0)
Block(-8,15,-2,STONE:0)
Block(-8,15,-1,STONE:0)
Block(-8,15,0,STONE:0)
Block(-8,16,-4,STONE:0)
Block(-8,16,-3,STONE:0)
Block(-8,16,-2,STONE:0)
Block(-8,16,-1,STONE:0)
Block(-8,16,0,STONE:0)
Block(-7,7,-3,STONE:0)
Block(-7,7,-2,STONE:0)
Block(-7,7,-1,STONE:0)
Block(-7,8,-4,STONE:0)
Block(-7,8,-3,STONE:0)
Block(-7,8,-2,STONE:0)
Block(-7,8,-1,STONE:0)
Block(-7,8,0,STONE:0)
Block(-7,9,-4,STONE:0)
Block(-7,9,-3,STONE:0)
Block(-7,9,-2,biomesoplenty:grass:1)
Block(-7,9,-1,STONE:0)
Block(-7,9,0,STONE:0)
Block(-7,9,1,STONE:0)
Block(-7,10,-5,STONE:0)
Block(-7,10,-4,STONE:0)
Block(-7,10,-3,STONE:0)
Block(-7,10,-2,biomesoplenty:flower_0:3)
Block(-7,10,-1,STONE:0)
Block(-7,10,0,STONE:0)
Block(-7,10,1,STONE:0)
Block(-7,10,2,STONE:0)
Block(-7,10,3,STONE:0)
Block(-7,11,-5,STONE:0)
Block(-7,11,-4,STONE:0)
Block(-7,11,-3,STONE:0)
Block(-7,11,-2,biomesoplenty:willow_vine:4)
Block(-7,11,-1,LEAVES:4)
Block(-7,11,0,LEAVES:4)
Block(-7,11,1,STONE:0)
Block(-7,11,2,STONE:0)
Block(-7,11,3,STONE:0)
Block(-7,11,4,STONE:0)
Block(-7,12,-5,STONE:0)
Block(-7,12,-4,STONE:0)
Block(-7,12,-3,STONE:0)
Block(-7,12,-2,biomesoplenty:willow_vine:4)
Block(-7,12,-1,LEAVES:4)
Block(-7,12,0,STONE:0)
Block(-7,12,1,STONE:0)
Block(-7,12,2,STONE:0)
Block(-7,12,3,STONE:0)
Block(-7,12,4,STONE:0)
Block(-7,12,5,STONE:0)
Block(-7,13,-6,STONE:0)
Block(-7,13,-5,STONE:0)
Block(-7,13,-4,STONE:0)
Block(-7,13,-3,STONE:0)
Block(-7,13,-2,biomesoplenty:willow_vine:4)
Block(-7,13,-1,AIR:0)
Block(-7,13,0,STONE:0)
Block(-7,13,1,STONE:0)
Block(-7,13,2,STONE:0)
Block(-7,13,3,STONE:0)
Block(-7,13,4,STONE:0)
Block(-7,13,5,STONE:0)
Block(-7,14,-6,STONE:0)
Block(-7,14,-5,STONE:0)
Block(-7,14,-4,STONE:0)
Block(-7,14,-3,LEAVES:4)
Block(-7,14,-2,biomesoplenty:willow_vine:4)
Block(-7,14,-1,STONE:0)
Block(-7,14,0,STONE:0)
Block(-7,14,1,STONE:0)
Block(-7,14,2,STONE:0)
Block(-7,14,3,STONE:0)
Block(-7,14,4,STONE:0)
Block(-7,14,5,STONE:0)
Block(-7,15,-6,STONE:0)
Block(-7,15,-5,STONE:0)
Block(-7,15,-4,STONE:0)
Block(-7,15,-3,STONE:0)
Block(-7,15,-2,biomesoplenty:willow_vine:4)
Block(-7,15,-1,STONE:0)
Block(-7,15,0,STONE:0)
Block(-7,15,2,STONE:0)
Block(-7,15,3,STONE:0)
Block(-7,15,4,STONE:0)
Block(-7,16,-4,STONE:0)
Block(-7,16,-3,STONE:0)
Block(-7,16,-2,STONE:0)
Block(-7,16,-1,STONE:0)
Block(-7,16,0,STONE:0)
Block(-7,17,-4,STONE:0)
Block(-7,17,-3,STONE:0)
Block(-7,17,-2,STONE:0)
Block(-6,5,12,STONE:0)
Block(-6,5,13,STONE:0)
Block(-6,5,14,STONE:0)
Block(-6,6,5,STONE:0)
Block(-6,6,6,STONE:0)
Block(-6,6,7,STONE:0)
Block(-6,6,12,STONE:0)
Block(-6,6,13,STONE:0)
Block(-6,6,14,STONE:0)
Block(-6,7,-3,STONE:0)
Block(-6,7,-2,STONE:0)
Block(-6,7,-1,STONE:0)
Block(-6,7,0,STONE:0)
Block(-6,7,1,STONE:0)
Block(-6,7,2,STONE:0)
Block(-6,7,3,STONE:0)
Block(-6,7,5,STONE:0)
Block(-6,7,6,STONE:0)
Block(-6,7,7,STONE:0)
Block(-6,7,12,STONE:0)
Block(-6,7,13,STONE:0)
Block(-6,7,14,STONE:0)
Block(-6,8,-4,STONE:0)
Block(-6,8,-3,STONE:0)
Block(-6,8,-2,STONE:0)
Block(-6,8,-1,STONE:0)
Block(-6,8,0,STONE:0)
Block(-6,8,1,STONE:0)
Block(-6,8,2,STONE:0)
Block(-6,8,3,STONE:0)
Block(-6,8,5,STONE:0)
Block(-6,8,6,STONE:0)
Block(-6,8,7,STONE:0)
Block(-6,9,-5,STONE:0)
Block(-6,9,-4,STONE:0)
Block(-6,9,-3,STONE:0)
Block(-6,9,-2,biomesoplenty:grass:1)
Block(-6,9,-1,biomesoplenty:grass:1)
Block(-6,9,0,biomesoplenty:grass:1)
Block(-6,9,1,STONE:0)
Block(-6,9,2,STONE:0)
Block(-6,9,3,STONE:0)
Block(-6,10,-5,STONE:0)
Block(-6,10,-4,STONE:0)
Block(-6,10,-3,STONE:0)
Block(-6,10,-2,AIR:0)
Block(-6,10,-1,biomesoplenty:plant_0:11)
Block(-6,10,0,biomesoplenty:willow_vine:2)
Block(-6,10,1,biomesoplenty:flower_1:3)
Block(-6,10,2,STONE:0)
Block(-6,10,3,STONE:0)
Block(-6,10,4,STONE:0)
Block(-6,11,-5,STONE:0)
Block(-6,11,-4,STONE:0)
Block(-6,11,-3,STONE:0)
Block(-6,11,-2,AIR:0)
Block(-6,11,-1,biomesoplenty:willow_vine:2)
Block(-6,11,0,biomesoplenty:willow_vine:2)
Block(-6,11,1,AIR:0)
Block(-6,11,2,STONE:0)
Block(-6,11,3,STONE:0)
Block(-6,11,4,STONE:0)
Block(-6,11,5,STONE:0)
Block(-6,12,-6,STONE:0)
Block(-6,12,-5,STONE:0)
Block(-6,12,-4,STONE:0)
Block(-6,12,-3,BROWN_MUSHROOM:0)
Block(-6,12,-2,AIR:0)
Block(-6,12,-1,biomesoplenty:willow_vine:2)
Block(-6,12,0,biomesoplenty:willow_vine:2)
Block(-6,12,1,STONE:0)
Block(-6,12,2,STONE:0)
Block(-6,12,3,STONE:0)
Block(-6,12,4,STONE:0)
Block(-6,12,5,STONE:0)
Block(-6,13,-7,STONE:0)
Block(-6,13,-6,STONE:0)
Block(-6,13,-5,STONE:0)
Block(-6,13,-4,LEAVES:4)
Block(-6,13,-3,biomesoplenty:willow_vine:2)
Block(-6,13,-2,AIR:0)
Block(-6,13,-1,AIR:0)
Block(-6,13,0,biomesoplenty:willow_vine:2)
Block(-6,13,1,STONE:0)
Block(-6,13,2,STONE:0)
Block(-6,13,3,STONE:0)
Block(-6,13,4,STONE:0)
Block(-6,13,5,STONE:0)
Block(-6,14,-7,STONE:0)
Block(-6,14,-6,STONE:0)
Block(-6,14,-5,STONE:0)
Block(-6,14,-4,STONE:0)
Block(-6,14,-3,biomesoplenty:willow_vine:2)
Block(-6,14,-2,AIR:0)
Block(-6,14,-1,AIR:0)
Block(-6,14,0,LEAVES:4)
Block(-6,14,1,STONE:0)
Block(-6,14,2,STONE:0)
Block(-6,14,3,STONE:0)
Block(-6,14,4,STONE:0)
Block(-6,14,5,STONE:0)
Block(-6,15,-7,STONE:0)
Block(-6,15,-6,STONE:0)
Block(-6,15,-5,STONE:0)
Block(-6,15,-4,STONE:0)
Block(-6,15,-3,biomesoplenty:willow_vine:2)
Block(-6,15,-2,AIR:0)
Block(-6,15,-1,LEAVES:4)
Block(-6,15,0,STONE:0)
Block(-6,15,1,STONE:0)
Block(-6,15,2,STONE:0)
Block(-6,15,3,STONE:0)
Block(-6,15,4,STONE:0)
Block(-6,15,5,STONE:0)
Block(-6,16,-7,STONE:0)
Block(-6,16,-6,STONE:0)
Block(-6,16,-5,STONE:0)
Block(-6,16,-4,STONE:0)
Block(-6,16,-3,biomesoplenty:willow_vine:2)
Block(-6,16,-2,AIR:0)
Block(-6,16,-1,STONE:0)
Block(-6,16,0,STONE:0)
Block(-6,16,1,STONE:0)
Block(-6,17,-7,STONE:0)
Block(-6,17,-6,STONE:0)
Block(-6,17,-5,STONE:0)
Block(-6,17,-4,STONE:0)
Block(-6,17,-3,STONE:0)
Block(-6,17,-2,STONE:0)
Block(-6,17,-1,STONE:0)
Block(-6,17,0,STONE:0)
Block(-6,17,1,STONE:0)
Block(-6,18,-4,STONE:0)
Block(-6,18,-3,STONE:0)
Block(-6,18,-2,STONE:0)
Block(-6,18,-1,STONE:0)
Block(-6,18,0,STONE:0)
Block(-6,19,-4,STONE:0)
Block(-6,19,-3,STONE:0)
Block(-6,19,-2,STONE:0)
Block(-5,4,10,STONE:0)
Block(-5,4,11,STONE:0)
Block(-5,4,12,STONE:0)
Block(-5,4,13,STONE:0)
Block(-5,4,14,STONE:0)
Block(-5,5,5,STONE:0)
Block(-5,5,6,STONE:0)
Block(-5,5,7,STONE:0)
Block(-5,5,8,STONE:0)
Block(-5,5,10,STONE:0)
Block(-5,5,11,STONE:0)
Block(-5,5,12,STONE:0)
Block(-5,5,13,STONE:0)
Block(-5,5,14,STONE:0)
Block(-5,5,15,STONE:0)
Block(-5,6,1,STONE:0)
Block(-5,6,2,STONE:0)
Block(-5,6,3,STONE:0)
Block(-5,6,4,STONE:0)
Block(-5,6,5,STONE:0)
Block(-5,6,6,STONE:0)
Block(-5,6,7,STONE:0)
Block(-5,6,8,STONE:0)
Block(-5,6,10,STONE:0)
Block(-5,6,11,STONE:0)
Block(-5,6,12,STONE:0)
Block(-5,6,13,STONE:0)
Block(-5,6,14,STONE:0)
Block(-5,6,15,STONE:0)
Block(-5,7,-3,STONE:0)
Block(-5,7,-2,STONE:0)
Block(-5,7,-1,STONE:0)
Block(-5,7,0,STONE:0)
Block(-5,7,1,STONE:0)
Block(-5,7,2,STONE:0)
Block(-5,7,3,STONE:0)
Block(-5,7,4,STONE:0)
Block(-5,7,5,STONE:0)
Block(-5,7,6,STONE:0)
Block(-5,7,7,STONE:0)
Block(-5,7,8,STONE:0)
Block(-5,7,11,STONE:0)
Block(-5,7,12,STONE:0)
Block(-5,7,13,STONE:0)
Block(-5,7,14,STONE:0)
Block(-5,7,15,STONE:0)
Block(-5,8,-4,STONE:0)
Block(-5,8,-3,STONE:0)
Block(-5,8,-2,STONE:0)
Block(-5,8,-1,STONE:0)
Block(-5,8,0,STONE:0)
Block(-5,8,1,biomesoplenty:grass:1)
Block(-5,8,2,STONE:0)
Block(-5,8,3,STONE:0)
Block(-5,8,4,STONE:0)
Block(-5,8,5,STONE:0)
Block(-5,8,6,STONE:0)
Block(-5,8,7,STONE:0)
Block(-5,8,8,STONE:0)
Block(-5,8,10,STONE:0)
Block(-5,8,11,STONE:0)
Block(-5,8,12,STONE:0)
Block(-5,8,13,STONE:0)
Block(-5,8,14,STONE:0)
Block(-5,8,15,STONE:0)
Block(-5,9,-5,STONE:0)
Block(-5,9,-4,STONE:0)
Block(-5,9,-3,STONE:0)
Block(-5,9,-2,STONE:0)
Block(-5,9,-1,LEAVES:4)
Block(-5,9,0,BROWN_MUSHROOM:0)
Block(-5,9,1,biomesoplenty:plant_0:11)
Block(-5,9,2,STONE:0)
Block(-5,9,3,STONE:0)
Block(-5,9,4,STONE:0)
Block(-5,9,5,STONE:0)
Block(-5,9,6,STONE:0)
Block(-5,9,7,STONE:0)
Block(-5,9,12,STONE:0)
Block(-5,9,13,STONE:0)
Block(-5,9,14,STONE:0)
Block(-5,10,-6,STONE:0)
Block(-5,10,-5,STONE:0)
Block(-5,10,-4,STONE:0)
Block(-5,10,-3,STONE:0)
Block(-5,10,-2,BROWN_MUSHROOM:0)
Block(-5,10,-1,AIR:0)
Block(-5,10,0,biomesoplenty:willow_vine:2)
Block(-5,10,1,AIR:0)
Block(-5,10,2,BROWN_MUSHROOM:0)
Block(-5,10,3,STONE:0)
Block(-5,10,4,STONE:0)
Block(-5,11,-6,STONE:0)
Block(-5,11,-5,STONE:0)
Block(-5,11,-4,STONE:0)
Block(-5,11,-3,BROWN_MUSHROOM:0)
Block(-5,11,-2,AIR:0)
Block(-5,11,-1,AIR:0)
Block(-5,11,0,biomesoplenty:willow_vine:2)
Block(-5,11,1,inspirations:rope:2)
Block(-5,11,2,biomesoplenty:willow_vine:1)
Block(-5,11,3,BROWN_MUSHROOM:0)
Block(-5,11,4,STONE:0)
Block(-5,11,5,STONE:0)
Block(-5,12,-7,STONE:0)
Block(-5,12,-6,STONE:0)
Block(-5,12,-5,biomesoplenty:grass:1)
Block(-5,12,-4,biomesoplenty:grass:1)
Block(-5,12,-3,AIR:0)
Block(-5,12,-2,AIR:0)
Block(-5,12,-1,AIR:0)
Block(-5,12,0,biomesoplenty:willow_vine:2)
Block(-5,12,1,inspirations:rope:2)
Block(-5,12,2,biomesoplenty:willow_vine:1)
Block(-5,12,3,AIR:0)
Block(-5,12,4,STONE:0)
Block(-5,12,5,STONE:0)
Block(-5,13,-7,STONE:0)
Block(-5,13,-6,biomesoplenty:plant_0:11)
Block(-5,13,-5,biomesoplenty:willow_vine:2)
Block(-5,13,-4,biomesoplenty:plant_0:11)
Block(-5,13,-3,inspirations:rope:2)
Block(-5,13,-2,AIR:0)
Block(-5,13,-1,AIR:0)
Block(-5,13,0,biomesoplenty:willow_vine:2)
Block(-5,13,1,inspirations:rope:2)
Block(-5,13,2,biomesoplenty:willow_vine:1)
Block(-5,13,3,LEAVES:4)
Block(-5,13,4,STONE:0)
Block(-5,13,5,STONE:0)
Block(-5,13,6,STONE:0)
Block(-5,14,-7,STONE:0)
Block(-5,14,-6,AIR:0)
Block(-5,14,-5,biomesoplenty:willow_vine:2)
Block(-5,14,-4,AIR:0)
Block(-5,14,-3,inspirations:rope:2)
Block(-5,14,-2,AIR:0)
Block(-5,14,-1,AIR:0)
Block(-5,14,0,biomesoplenty:willow_vine:2)
Block(-5,14,1,inspirations:rope:2)
Block(-5,14,2,biomesoplenty:willow_vine:1)
Block(-5,14,3,LEAVES:4)
Block(-5,14,4,STONE:0)
Block(-5,14,5,STONE:0)
Block(-5,15,-8,STONE:0)
Block(-5,15,-7,STONE:0)
Block(-5,15,-6,AIR:0)
Block(-5,15,-5,biomesoplenty:willow_vine:2)
Block(-5,15,-4,AIR:0)
Block(-5,15,-3,inspirations:rope:2)
Block(-5,15,-2,AIR:0)
Block(-5,15,-1,AIR:0)
Block(-5,15,0,LEAVES:4)
Block(-5,15,1,LEAVES:4)
Block(-5,15,2,LEAVES:4)
Block(-5,15,3,STONE:0)
Block(-5,15,4,STONE:0)
Block(-5,15,5,STONE:0)
Block(-5,16,-8,STONE:0)
Block(-5,16,-7,STONE:0)
Block(-5,16,-6,STONE:0)
Block(-5,16,-5,biomesoplenty:willow_vine:2)
Block(-5,16,-4,AIR:0)
Block(-5,16,-3,inspirations:rope:2)
Block(-5,16,-2,AIR:0)
Block(-5,16,-1,LEAVES:4)
Block(-5,16,0,STONE:0)
Block(-5,16,1,STONE:0)
Block(-5,16,2,STONE:0)
Block(-5,16,3,STONE:0)
Block(-5,17,-10,STONE:0)
Block(-5,17,-9,STONE:0)
Block(-5,17,-8,STONE:0)
Block(-5,17,-7,STONE:0)
Block(-5,17,-6,STONE:0)
Block(-5,17,-5,STONE:0)
Block(-5,17,-4,STONE:0)
Block(-5,17,-3,inspirations:rope:2)
Block(-5,17,-2,STONE:0)
Block(-5,17,-1,STONE:0)
Block(-5,17,0,STONE:0)
Block(-5,17,1,STONE:0)
Block(-5,17,2,STONE:0)
Block(-5,18,-10,STONE:0)
Block(-5,18,-9,STONE:0)
Block(-5,18,-8,STONE:0)
Block(-5,18,-7,STONE:0)
Block(-5,18,-6,STONE:0)
Block(-5,18,-5,STONE:0)
Block(-5,18,-4,STONE:0)
Block(-5,18,-3,STONE:0)
Block(-5,18,-2,STONE:0)
Block(-5,18,-1,STONE:0)
Block(-5,18,0,STONE:0)
Block(-5,18,1,STONE:0)
Block(-5,19,-10,STONE:0)
Block(-5,19,-9,STONE:0)
Block(-5,19,-8,STONE:0)
Block(-5,19,-7,STONE:0)
Block(-5,19,-6,STONE:0)
Block(-5,19,-5,STONE:0)
Block(-5,19,-4,STONE:0)
Block(-5,19,-3,STONE:0)
Block(-5,19,-2,STONE:0)
Block(-5,19,-1,STONE:0)
Block(-5,19,0,STONE:0)
Block(-5,20,-8,STONE:0)
Block(-5,20,-7,STONE:0)
Block(-5,20,-6,STONE:0)
Block(-5,20,-5,STONE:0)
Block(-5,20,-4,STONE:0)
Block(-5,20,-3,STONE:0)
Block(-5,20,-2,STONE:0)
Block(-4,3,10,STONE:0)
Block(-4,3,11,STONE:0)
Block(-4,3,12,STONE:0)
Block(-4,4,6,STONE:0)
Block(-4,4,7,STONE:0)
Block(-4,4,8,STONE:0)
Block(-4,4,9,STONE:0)
Block(-4,4,10,STONE:0)
Block(-4,4,11,STONE:0)
Block(-4,4,12,STONE:0)
Block(-4,4,13,STONE:0)
Block(-4,4,14,STONE:0)
Block(-4,4,15,STONE:0)
Block(-4,5,5,STONE:0)
Block(-4,5,6,STONE:0)
Block(-4,5,7,STONE:0)
Block(-4,5,8,STONE:0)
Block(-4,5,9,STONE:0)
Block(-4,5,10,STONE:0)
Block(-4,5,11,STONE:0)
Block(-4,5,12,STONE:0)
Block(-4,5,13,STONE:0)
Block(-4,5,14,STONE:0)
Block(-4,5,15,STONE:0)
Block(-4,5,16,STONE:0)
Block(-4,6,0,STONE:0)
Block(-4,6,1,STONE:0)
Block(-4,6,2,STONE:0)
Block(-4,6,3,STONE:0)
Block(-4,6,4,STONE:0)
Block(-4,6,5,STONE:0)
Block(-4,6,6,STONE:0)
Block(-4,6,7,STONE:0)
Block(-4,6,8,STONE:0)
Block(-4,6,9,STONE:0)
Block(-4,6,10,STONE:0)
Block(-4,6,11,STONE:0)
Block(-4,6,12,STONE:0)
Block(-4,6,13,LEAVES:4)
Block(-4,6,14,STONE:0)
Block(-4,6,15,STONE:0)
Block(-4,6,16,STONE:0)
Block(-4,7,-2,STONE:0)
Block(-4,7,-1,STONE:0)
Block(-4,7,0,STONE:0)
Block(-4,7,1,STONE:0)
Block(-4,7,2,biomesoplenty:grass:1)
Block(-4,7,3,biomesoplenty:grass:1)
Block(-4,7,4,STONE:0)
Block(-4,7,5,STONE:0)
Block(-4,7,6,STONE:0)
Block(-4,7,7,STONE:0)
Block(-4,7,8,STONE:0)
Block(-4,7,9,STONE:0)
Block(-4,7,10,STONE:0)
Block(-4,7,11,LEAVES:4)
Block(-4,7,12,LEAVES:4)
Block(-4,7,13,STONE:0)
Block(-4,7,14,STONE:0)
Block(-4,7,15,STONE:0)
Block(-4,7,16,STONE:0)
Block(-4,8,-4,STONE:0)
Block(-4,8,-3,STONE:0)
Block(-4,8,-2,STONE:0)
Block(-4,8,-1,biomesoplenty:grass:1)
Block(-4,8,0,STONE:0)
Block(-4,8,1,biomesoplenty:plant_0:11)
Block(-4,8,2,biomesoplenty:plant_0:11)
Block(-4,8,3,quark:leaf_carpet)
Block(-4,8,4,quark:leaf_carpet)
Block(-4,8,5,STONE:0)
Block(-4,8,6,STONE:0)
Block(-4,8,7,STONE:0)
Block(-4,8,8,STONE:0)
Block(-4,8,9,STONE:0)
Block(-4,8,10,STONE:0)
Block(-4,8,11,STONE:0)
Block(-4,8,12,STONE:0)
Block(-4,8,13,STONE:0)
Block(-4,8,14,STONE:0)
Block(-4,8,15,STONE:0)
Block(-4,9,-5,STONE:0)
Block(-4,9,-4,STONE:0)
Block(-4,9,-3,STONE:0)
Block(-4,9,-2,STONE:0)
Block(-4,9,-1,AIR:0)
Block(-4,9,0,quark:leaf_carpet)
Block(-4,9,1,AIR:0)
Block(-4,9,2,AIR:0)
Block(-4,9,3,AIR:0)
Block(-4,9,4,biomesoplenty:willow_vine:1)
Block(-4,9,5,STONE:0)
Block(-4,9,6,STONE:0)
Block(-4,9,7,STONE:0)
Block(-4,9,8,STONE:0)
Block(-4,9,9,STONE:0)
Block(-4,9,10,STONE:0)
Block(-4,9,11,STONE:0)
Block(-4,9,12,STONE:0)
Block(-4,9,13,STONE:0)
Block(-4,9,14,STONE:0)
Block(-4,9,15,STONE:0)
Block(-4,10,-6,STONE:0)
Block(-4,10,-5,STONE:0)
Block(-4,10,-4,STONE:0)
Block(-4,10,-3,biomesoplenty:grass:1)
Block(-4,10,-2,biomesoplenty:plant_0:11)
Block(-4,10,-1,AIR:0)
Block(-4,10,0,AIR:0)
Block(-4,10,1,AIR:0)
Block(-4,10,2,AIR:0)
Block(-4,10,3,HUGE_MUSHROOM_1:14)
Block(-4,10,4,HUGE_MUSHROOM_1:14)
Block(-4,10,5,STONE:0)
Block(-4,10,6,STONE:0)
Block(-4,10,7,STONE:0)
Block(-4,10,9,STONE:0)
Block(-4,10,10,STONE:0)
Block(-4,10,11,STONE:0)
Block(-4,11,-6,STONE:0)
Block(-4,11,-5,STONE:0)
Block(-4,11,-4,STONE:0)
Block(-4,11,-3,AIR:0)
Block(-4,11,-2,AIR:0)
Block(-4,11,-1,AIR:0)
Block(-4,11,0,AIR:0)
Block(-4,11,1,AIR:0)
Block(-4,11,2,AIR:0)
Block(-4,11,3,BROWN_MUSHROOM:0)
Block(-4,11,4,biomesoplenty:willow_vine:1)
Block(-4,11,5,STONE:0)
Block(-4,11,6,STONE:0)
Block(-4,11,7,STONE:0)
Block(-4,12,-7,STONE:0)
Block(-4,12,-6,STONE:0)
Block(-4,12,-5,biomesoplenty:grass:1)
Block(-4,12,-4,quark:leaf_carpet)
Block(-4,12,-3,AIR:0)
Block(-4,12,-2,AIR:0)
Block(-4,12,-1,AIR:0)
Block(-4,12,0,AIR:0)
Block(-4,12,1,AIR:0)
Block(-4,12,2,AIR:0)
Block(-4,12,3,AIR:0)
Block(-4,12,4,LEAVES:4)
Block(-4,12,5,STONE:0)
Block(-4,13,-7,biomesoplenty:grass:1)
Block(-4,13,-6,biomesoplenty:grass:1)
Block(-4,13,-5,quark:leaf_carpet)
Block(-4,13,-4,AIR:0)
Block(-4,13,-3,AIR:0)
Block(-4,13,-2,AIR:0)
Block(-4,13,-1,AIR:0)
Block(-4,13,0,AIR:0)
Block(-4,13,1,AIR:0)
Block(-4,13,2,AIR:0)
Block(-4,13,3,LEAVES:4)
Block(-4,13,4,STONE:0)
Block(-4,13,5,STONE:0)
Block(-4,14,-8,STONE:0)
Block(-4,14,-7,LEAVES:4)
Block(-4,14,-6,biomesoplenty:willow_vine:4)
Block(-4,14,-5,AIR:0)
Block(-4,14,-4,AIR:0)
Block(-4,14,-3,AIR:0)
Block(-4,14,-2,AIR:0)
Block(-4,14,-1,AIR:0)
Block(-4,14,0,AIR:0)
Block(-4,14,1,AIR:0)
Block(-4,14,2,AIR:0)
Block(-4,14,3,LEAVES:4)
Block(-4,14,4,STONE:0)
Block(-4,14,5,STONE:0)
Block(-4,15,-10,STONE:0)
Block(-4,15,-9,STONE:0)
Block(-4,15,-8,STONE:0)
Block(-4,15,-7,biomesoplenty:willow_vine:2)
Block(-4,15,-6,biomesoplenty:willow_vine:4)
Block(-4,15,-5,AIR:0)
Block(-4,15,-4,AIR:0)
Block(-4,15,-3,AIR:0)
Block(-4,15,-2,AIR:0)
Block(-4,15,-1,AIR:0)
Block(-4,15,0,AIR:0)
Block(-4,15,1,LEAVES:4)
Block(-4,15,2,LEAVES:4)
Block(-4,15,3,STONE:0)
Block(-4,15,4,STONE:0)
Block(-4,15,5,STONE:0)
Block(-4,16,-10,STONE:0)
Block(-4,16,-9,STONE:0)
Block(-4,16,-8,BROWN_MUSHROOM:0)
Block(-4,16,-7,biomesoplenty:willow_vine:2)
Block(-4,16,-6,biomesoplenty:willow_vine:4)
Block(-4,16,-5,AIR:0)
Block(-4,16,-4,AIR:0)
Block(-4,16,-3,AIR:0)
Block(-4,16,-2,AIR:0)
Block(-4,16,-1,AIR:0)
Block(-4,16,0,LEAVES:4)
Block(-4,16,1,STONE:0)
Block(-4,16,2,STONE:0)
Block(-4,16,3,STONE:0)
Block(-4,16,4,STONE:0)
Block(-4,17,-11,STONE:0)
Block(-4,17,-10,STONE:0)
Block(-4,17,-9,STONE:0)
Block(-4,17,-8,STONE:0)
Block(-4,17,-7,biomesoplenty:willow_vine:2)
Block(-4,17,-6,biomesoplenty:willow_vine:4)
Block(-4,17,-5,AIR:0)
Block(-4,17,-4,AIR:0)
Block(-4,17,-3,AIR:0)
Block(-4,17,-2,LEAVES:4)
Block(-4,17,-1,STONE:0)
Block(-4,17,0,STONE:0)
Block(-4,17,1,STONE:0)
Block(-4,17,2,STONE:0)
Block(-4,17,3,STONE:0)
Block(-4,18,-11,STONE:0)
Block(-4,18,-10,STONE:0)
Block(-4,18,-9,STONE:0)
Block(-4,18,-8,STONE:0)
Block(-4,18,-7,STONE:0)
Block(-4,18,-6,biomesoplenty:willow_vine:4)
Block(-4,18,-5,AIR:0)
Block(-4,18,-4,AIR:0)
Block(-4,18,-3,LEAVES:12)
Block(-4,18,-2,STONE:0)
Block(-4,18,-1,STONE:0)
Block(-4,18,0,STONE:0)
Block(-4,18,1,STONE:0)
Block(-4,18,2,STONE:0)
Block(-4,19,-11,STONE:0)
Block(-4,19,-10,STONE:0)
Block(-4,19,-9,STONE:0)
Block(-4,19,-8,STONE:0)
Block(-4,19,-7,STONE:0)
Block(-4,19,-6,STONE:0)
Block(-4,19,-5,LEAVES:12)
Block(-4,19,-4,LEAVES:12)
Block(-4,19,-3,STONE:0)
Block(-4,19,-2,STONE:0)
Block(-4,19,-1,STONE:0)
Block(-4,19,0,STONE:0)
Block(-4,20,-10,STONE:0)
Block(-4,20,-9,STONE:0)
Block(-4,20,-8,STONE:0)
Block(-4,20,-7,STONE:0)
Block(-4,20,-6,STONE:0)
Block(-4,20,-5,STONE:0)
Block(-4,20,-4,STONE:0)
Block(-4,20,-3,STONE:0)
Block(-4,20,-2,STONE:0)
Block(-4,21,-8,STONE:0)
Block(-4,21,-7,STONE:0)
Block(-4,21,-6,STONE:0)
Block(-4,21,-5,STONE:0)
Block(-4,21,-4,STONE:0)
Block(-4,21,-3,STONE:0)
Block(-3,3,7,STONE:0)
Block(-3,3,8,STONE:0)
Block(-3,3,9,STONE:0)
Block(-3,3,10,STONE:0)
Block(-3,3,11,STONE:0)
Block(-3,3,12,iceandfire:chared_stone)
Block(-3,3,13,STONE:0)
Block(-3,3,14,STONE:0)
Block(-3,4,6,STONE:0)
Block(-3,4,7,STONE:0)
Block(-3,4,8,STONE:0)
Block(-3,4,9,STONE:0)
Block(-3,4,10,STONE:0)
Block(-3,4,11,biomesoplenty:grass:1)
Block(-3,4,12,STONE:0)
Block(-3,4,13,biomesoplenty:grass:1)
Block(-3,4,14,STONE:0)
Block(-3,4,15,STONE:0)
Block(-3,4,16,STONE:0)
Block(-3,5,2,STONE:0)
Block(-3,5,3,STONE:0)
Block(-3,5,4,STONE:0)
Block(-3,5,5,STONE:0)
Block(-3,5,6,STONE:0)
Block(-3,5,7,STONE:0)
Block(-3,5,8,STONE:0)
Block(-3,5,9,STONE:0)
Block(-3,5,10,STONE:0)
Block(-3,5,11,BROWN_MUSHROOM:0)
Block(-3,5,12,biomesoplenty:grass:1)
Block(-3,5,13,quark:leaf_carpet)
Block(-3,5,14,STONE:0)
Block(-3,5,15,STONE:0)
Block(-3,5,16,STONE:0)
Block(-3,6,-1,STONE:0)
Block(-3,6,0,STONE:0)
Block(-3,6,1,STONE:0)
Block(-3,6,2,biomesoplenty:grass:1)
Block(-3,6,3,biomesoplenty:grass:1)
Block(-3,6,4,biomesoplenty:grass:1)
Block(-3,6,5,STONE:0)
Block(-3,6,6,AIR:0)
Block(-3,6,7,biomesoplenty:grass:1)
Block(-3,6,8,STONE:0)
Block(-3,6,9,STONE:0)
Block(-3,6,10,STONE:0)
Block(-3,6,11,AIR:0)
Block(-3,6,12,biomesoplenty:flower_0:3)
Block(-3,6,13,AIR:0)
Block(-3,6,14,LEAVES:4)
Block(-3,6,15,STONE:0)
Block(-3,6,16,STONE:0)
Block(-3,7,-2,STONE:0)
Block(-3,7,-1,STONE:0)
Block(-3,7,0,STONE:0)
Block(-3,7,1,biomesoplenty:grass:1)
Block(-3,7,2,AIR:0)
Block(-3,7,3,quark:leaf_carpet)
Block(-3,7,4,AIR:0)
Block(-3,7,5,biomesoplenty:plant_0:11)
Block(-3,7,6,AIR:0)
Block(-3,7,7,AIR:0)
Block(-3,7,8,STONE:0)
Block(-3,7,9,STONE:0)
Block(-3,7,10,STONE:0)
Block(-3,7,11,LEAVES:4)
Block(-3,7,12,LEAVES:4)
Block(-3,7,13,STONE:0)
Block(-3,7,14,STONE:0)
Block(-3,7,15,STONE:0)
Block(-3,7,16,STONE:0)
Block(-3,8,-2,STONE:0)
Block(-3,8,-1,biomesoplenty:grass:1)
Block(-3,8,0,biomesoplenty:plant_0:11)
Block(-3,8,1,BROWN_MUSHROOM:0)
Block(-3,8,2,AIR:0)
Block(-3,8,3,biomesoplenty:willow_vine:2)
Block(-3,8,4,AIR:0)
Block(-3,8,5,biomesoplenty:willow_vine:2)
Block(-3,8,6,AIR:0)
Block(-3,8,7,STONE:0)
Block(-3,8,8,STONE:0)
Block(-3,8,9,STONE:0)
Block(-3,8,10,LEAVES:4)
Block(-3,8,11,STONE:0)
Block(-3,8,12,STONE:0)
Block(-3,8,13,STONE:0)
Block(-3,8,14,STONE:0)
Block(-3,8,15,STONE:0)
Block(-3,8,16,STONE:0)
Block(-3,9,-5,STONE:0)
Block(-3,9,-4,STONE:0)
Block(-3,9,-3,STONE:0)
Block(-3,9,-2,STONE:0)
Block(-3,9,-1,biomesoplenty:flower_0:3)
Block(-3,9,0,AIR:0)
Block(-3,9,1,AIR:0)
Block(-3,9,2,AIR:0)
Block(-3,9,3,biomesoplenty:willow_vine:2)
Block(-3,9,4,AIR:0)
Block(-3,9,5,biomesoplenty:willow_vine:2)
Block(-3,9,6,STONE:0)
Block(-3,9,7,STONE:0)
Block(-3,9,8,STONE:0)
Block(-3,9,9,LEAVES:12)
Block(-3,9,10,LEAVES:4)
Block(-3,9,11,STONE:0)
Block(-3,9,12,STONE:0)
Block(-3,9,13,STONE:0)
Block(-3,9,14,STONE:0)
Block(-3,9,15,STONE:0)
Block(-3,10,-6,STONE:0)
Block(-3,10,-5,STONE:0)
Block(-3,10,-4,biomesoplenty:grass:1)
Block(-3,10,-3,biomesoplenty:grass:1)
Block(-3,10,-2,biomesoplenty:plant_0:11)
Block(-3,10,-1,AIR:0)
Block(-3,10,0,AIR:0)
Block(-3,10,1,AIR:0)
Block(-3,10,2,AIR:0)
Block(-3,10,3,biomesoplenty:willow_vine:2)
Block(-3,10,4,HUGE_MUSHROOM_1:14)
Block(-3,10,5,HUGE_MUSHROOM_1:14)
Block(-3,10,6,STONE:0)
Block(-3,10,7,STONE:0)
Block(-3,10,8,STONE:0)
Block(-3,10,9,STONE:0)
Block(-3,10,10,STONE:0)
Block(-3,10,11,STONE:0)
Block(-3,10,12,STONE:0)
Block(-3,10,13,STONE:0)
Block(-3,11,-6,STONE:0)
Block(-3,11,-5,STONE:0)
Block(-3,11,-4,BROWN_MUSHROOM:0)
Block(-3,11,-3,biomesoplenty:plant_0:11)
Block(-3,11,-2,AIR:0)
Block(-3,11,-1,AIR:0)
Block(-3,11,0,AIR:0)
Block(-3,11,1,AIR:0)
Block(-3,11,2,AIR:0)
Block(-3,11,3,AIR:0)
Block(-3,11,4,AIR:0)
Block(-3,11,5,STONE:0)
Block(-3,11,6,STONE:0)
Block(-3,11,7,STONE:0)
Block(-3,11,8,STONE:0)
Block(-3,12,-7,STONE:0)
Block(-3,12,-6,STONE:0)
Block(-3,12,-5,BROWN_MUSHROOM:0)
Block(-3,12,-4,AIR:0)
Block(-3,12,-3,AIR:0)
Block(-3,12,-2,AIR:0)
Block(-3,12,-1,AIR:0)
Block(-3,12,0,AIR:0)
Block(-3,12,1,AIR:0)
Block(-3,12,2,AIR:0)
Block(-3,12,3,AIR:0)
Block(-3,12,4,LEAVES:4)
Block(-3,12,5,STONE:0)
Block(-3,12,6,STONE:0)
Block(-3,12,7,STONE:0)
Block(-3,13,-8,STONE:0)
Block(-3,13,-7,STONE:0)
Block(-3,13,-6,biomesoplenty:grass:1)
Block(-3,13,-5,AIR:0)
Block(-3,13,-4,AIR:0)
Block(-3,13,-3,AIR:0)
Block(-3,13,-2,AIR:0)
Block(-3,13,-1,AIR:0)
Block(-3,13,0,AIR:0)
Block(-3,13,1,AIR:0)
Block(-3,13,2,AIR:0)
Block(-3,13,3,AIR:0)
Block(-3,13,4,LEAVES:4)
Block(-3,13,5,STONE:0)
Block(-3,13,6,STONE:0)
Block(-3,14,-10,STONE:0)
Block(-3,14,-9,STONE:0)
Block(-3,14,-8,biomesoplenty:grass:1)
Block(-3,14,-7,AIR:0)
Block(-3,14,-6,biomesoplenty:plant_0:11)
Block(-3,14,-5,AIR:0)
Block(-3,14,-4,AIR:0)
Block(-3,14,-3,AIR:0)
Block(-3,14,-2,AIR:0)
Block(-3,14,-1,AIR:0)
Block(-3,14,0,AIR:0)
Block(-3,14,1,AIR:0)
Block(-3,14,2,AIR:0)
Block(-3,14,3,LEAVES:4)
Block(-3,14,4,STONE:0)
Block(-3,14,5,STONE:0)
Block(-3,14,6,STONE:0)
Block(-3,15,-11,STONE:0)
Block(-3,15,-10,STONE:0)
Block(-3,15,-9,LEAVES:4)
Block(-3,15,-8,quark:leaf_carpet)
Block(-3,15,-7,AIR:0)
Block(-3,15,-6,AIR:0)
Block(-3,15,-5,AIR:0)
Block(-3,15,-4,AIR:0)
Block(-3,15,-3,AIR:0)
Block(-3,15,-2,AIR:0)
Block(-3,15,-1,AIR:0)
Block(-3,15,0,AIR:0)
Block(-3,15,1,AIR:0)
Block(-3,15,2,LEAVES:4)
Block(-3,15,3,STONE:0)
Block(-3,15,4,STONE:0)
Block(-3,15,5,STONE:0)
Block(-3,16,-11,STONE:0)
Block(-3,16,-10,STONE:0)
Block(-3,16,-9,AIR:0)
Block(-3,16,-8,AIR:0)
Block(-3,16,-7,AIR:0)
Block(-3,16,-6,AIR:0)
Block(-3,16,-5,AIR:0)
Block(-3,16,-4,AIR:0)
Block(-3,16,-3,AIR:0)
Block(-3,16,-2,AIR:0)
Block(-3,16,-1,AIR:0)
Block(-3,16,0,LEAVES:4)
Block(-3,16,1,LEAVES:4)
Block(-3,16,2,LEAVES:4)
Block(-3,16,3,LEAVES:4)
Block(-3,16,4,STONE:0)
Block(-3,16,5,STONE:0)
Block(-3,17,-11,STONE:0)
Block(-3,17,-10,STONE:0)
Block(-3,17,-9,AIR:0)
Block(-3,17,-8,AIR:0)
Block(-3,17,-7,AIR:0)
Block(-3,17,-6,AIR:0)
Block(-3,17,-5,AIR:0)
Block(-3,17,-4,AIR:0)
Block(-3,17,-3,AIR:0)
Block(-3,17,-2,LEAVES:4)
Block(-3,17,-1,LEAVES:4)
Block(-3,17,0,STONE:0)
Block(-3,17,1,STONE:0)
Block(-3,17,2,STONE:0)
Block(-3,17,3,STONE:0)
Block(-3,17,4,STONE:0)
Block(-3,18,-11,STONE:0)
Block(-3,18,-10,STONE:0)
Block(-3,18,-9,LEAVES:4)
Block(-3,18,-8,AIR:0)
Block(-3,18,-7,AIR:0)
Block(-3,18,-6,AIR:0)
Block(-3,18,-5,AIR:0)
Block(-3,18,-4,AIR:0)
Block(-3,18,-3,LEAVES:4)
Block(-3,18,-2,LEAVES:4)
Block(-3,18,-1,STONE:0)
Block(-3,18,0,STONE:0)
Block(-3,18,1,STONE:0)
Block(-3,18,2,STONE:0)
Block(-3,18,3,STONE:0)
Block(-3,19,-13,STONE:0)
Block(-3,19,-12,STONE:0)
Block(-3,19,-11,STONE:0)
Block(-3,19,-10,STONE:0)
Block(-3,19,-9,LEAVES:4)
Block(-3,19,-8,LEAVES:4)
Block(-3,19,-7,LEAVES:4)
Block(-3,19,-6,STONE:0)
Block(-3,19,-5,AIR:0)
Block(-3,19,-4,LEAVES:12)
Block(-3,19,-3,STONE:0)
Block(-3,19,-2,STONE:0)
Block(-3,19,-1,STONE:0)
Block(-3,19,0,STONE:0)
Block(-3,20,-13,STONE:0)
Block(-3,20,-12,STONE:0)
Block(-3,20,-11,STONE:0)
Block(-3,20,-10,STONE:0)
Block(-3,20,-9,STONE:0)
Block(-3,20,-8,STONE:0)
Block(-3,20,-7,STONE:0)
Block(-3,20,-6,STONE:0)
Block(-3,20,-5,STONE:0)
Block(-3,20,-4,STONE:0)
Block(-3,20,-3,STONE:0)
Block(-3,20,-2,STONE:0)
Block(-3,21,-13,STONE:0)
Block(-3,21,-12,STONE:0)
Block(-3,21,-11,STONE:0)
Block(-3,21,-9,STONE:0)
Block(-3,21,-8,STONE:0)
Block(-3,21,-7,STONE:0)
Block(-3,21,-6,STONE:0)
Block(-3,21,-5,STONE:0)
Block(-3,21,-4,STONE:0)
Block(-3,21,-3,STONE:0)
Block(-3,22,-8,STONE:0)
Block(-3,22,-7,STONE:0)
Block(-3,22,-6,STONE:0)
Block(-2,2,12,iceandfire:chared_stone)
Block(-2,2,13,iceandfire:chared_cobblestone)
Block(-2,2,14,STONE:0)
Block(-2,3,7,STONE:0)
Block(-2,3,8,STONE:0)
Block(-2,3,9,STONE:0)
Block(-2,3,10,STONE:0)
Block(-2,3,11,MAGMA:0)
Block(-2,3,12,STATIONARY_WATER:0)
Block(-2,3,13,iceandfire:chared_cobblestone)
Block(-2,3,14,iceandfire:chared_stone)
Block(-2,3,15,STONE:0)
Block(-2,3,16,STONE:0)
Block(-2,4,2,STONE:0)
Block(-2,4,3,STONE:0)
Block(-2,4,4,STONE:0)
Block(-2,4,6,STONE:0)
Block(-2,4,7,STONE:0)
Block(-2,4,8,STONE:0)
Block(-2,4,9,STONE:0)
Block(-2,4,10,iceandfire:chared_stone)
Block(-2,4,11,STATIONARY_WATER:0)
Block(-2,4,12,STATIONARY_WATER:0)
Block(-2,4,13,STATIONARY_WATER:0)
Block(-2,4,14,STATIONARY_WATER:0)
Block(-2,4,15,STONE:0)
Block(-2,4,16,STONE:0)
Block(-2,5,1,STONE:0)
Block(-2,5,2,STONE:0)
Block(-2,5,3,STONE:0)
Block(-2,5,4,STONE:0)
Block(-2,5,5,STONE:0)
Block(-2,5,6,STATIONARY_WATER:15)
Block(-2,5,7,STATIONARY_WATER:1)
Block(-2,5,8,STATIONARY_WATER:2)
Block(-2,5,9,STONE:0)
Block(-2,5,10,biomesoplenty:grass:1)
Block(-2,5,11,AIR:0)
Block(-2,5,12,AIR:0)
Block(-2,5,13,AIR:0)
Block(-2,5,14,LEAVES:4)
Block(-2,5,15,STONE:0)
Block(-2,5,16,STONE:0)
Block(-2,6,-1,STONE:0)
Block(-2,6,0,STONE:0)
Block(-2,6,1,biomesoplenty:grass:1)
Block(-2,6,2,biomesoplenty:grass:1)
Block(-2,6,3,STATIONARY_WATER:4)
Block(-2,6,4,STATIONARY_WATER:5)
Block(-2,6,5,STATIONARY_WATER:6)
Block(-2,6,6,STATIONARY_WATER:7)
Block(-2,6,7,AIR:0)
Block(-2,6,8,AIR:0)
Block(-2,6,9,AIR:0)
Block(-2,6,10,BROWN_MUSHROOM:0)
Block(-2,6,11,AIR:0)
Block(-2,6,12,AIR:0)
Block(-2,6,13,AIR:0)
Block(-2,6,14,LEAVES:4)
Block(-2,6,15,LEAVES:4)
Block(-2,6,16,STONE:0)
Block(-2,7,-2,STONE:0)
Block(-2,7,-1,STONE:0)
Block(-2,7,0,STONE:0)
Block(-2,7,1,quark:leaf_carpet)
Block(-2,7,2,quark:leaf_carpet)
Block(-2,7,3,AIR:0)
Block(-2,7,4,biomesoplenty:willow_vine:1)
Block(-2,7,5,AIR:0)
Block(-2,7,6,AIR:0)
Block(-2,7,7,AIR:0)
Block(-2,7,8,AIR:0)
Block(-2,7,9,AIR:0)
Block(-2,7,10,AIR:0)
Block(-2,7,11,AIR:0)
Block(-2,7,12,AIR:0)
Block(-2,7,13,AIR:0)
Block(-2,7,14,LEAVES:4)
Block(-2,7,15,LEAVES:4)
Block(-2,7,16,STONE:0)
Block(-2,8,-2,STONE:0)
Block(-2,8,-1,STONE:0)
Block(-2,8,0,BROWN_MUSHROOM:0)
Block(-2,8,1,AIR:0)
Block(-2,8,2,AIR:0)
Block(-2,8,3,AIR:0)
Block(-2,8,4,biomesoplenty:willow_vine:1)
Block(-2,8,5,AIR:0)
Block(-2,8,6,AIR:0)
Block(-2,8,7,AIR:0)
Block(-2,8,8,AIR:0)
Block(-2,8,9,AIR:0)
Block(-2,8,10,LEAVES:12)
Block(-2,8,11,LEAVES:4)
Block(-2,8,12,STONE:0)
Block(-2,8,13,STONE:0)
Block(-2,8,14,STONE:0)
Block(-2,8,15,STONE:0)
Block(-2,8,16,STONE:0)
Block(-2,9,-4,STONE:0)
Block(-2,9,-3,STONE:0)
Block(-2,9,-2,STONE:0)
Block(-2,9,-1,STONE:0)
Block(-2,9,0,AIR:0)
Block(-2,9,1,AIR:0)
Block(-2,9,2,AIR:0)
Block(-2,9,3,AIR:0)
Block(-2,9,4,biomesoplenty:willow_vine:1)
Block(-2,9,5,AIR:0)
Block(-2,9,6,AIR:0)
Block(-2,9,7,AIR:0)
Block(-2,9,8,AIR:0)
Block(-2,9,9,LEAVES:4)
Block(-2,9,10,LEAVES:4)
Block(-2,9,11,STONE:0)
Block(-2,9,12,STONE:0)
Block(-2,9,13,STONE:0)
Block(-2,9,14,STONE:0)
Block(-2,9,15,STONE:0)
Block(-2,10,-5,STONE:0)
Block(-2,10,-4,STONE:0)
Block(-2,10,-3,STONE:0)
Block(-2,10,-2,STONE:0)
Block(-2,10,-1,quark:leaf_carpet)
Block(-2,10,0,AIR:0)
Block(-2,10,1,AIR:0)
Block(-2,10,2,AIR:0)
Block(-2,10,3,AIR:0)
Block(-2,10,4,biomesoplenty:willow_vine:1)
Block(-2,10,5,HUGE_MUSHROOM_1:14)
Block(-2,10,6,HUGE_MUSHROOM_1:14)
Block(-2,10,7,STONE:0)
Block(-2,10,8,LEAVES:12)
Block(-2,10,9,STONE:0)
Block(-2,10,10,STONE:0)
Block(-2,10,11,STONE:0)
Block(-2,10,12,STONE:0)
Block(-2,10,13,STONE:0)
Block(-2,10,14,STONE:0)
Block(-2,11,-5,STONE:0)
Block(-2,11,-4,STONE:0)
Block(-2,11,-3,biomesoplenty:grass:1)
Block(-2,11,-2,BROWN_MUSHROOM:0)
Block(-2,11,-1,biomesoplenty:willow_vine:8)
Block(-2,11,0,AIR:0)
Block(-2,11,1,inspirations:rope:2)
Block(-2,11,2,AIR:0)
Block(-2,11,3,AIR:0)
Block(-2,11,4,AIR:0)
Block(-2,11,5,AIR:0)
Block(-2,11,6,STONE:0)
Block(-2,11,7,STONE:0)
Block(-2,11,8,STONE:0)
Block(-2,11,9,STONE:0)
Block(-2,11,10,STONE:0)
Block(-2,12,-6,STONE:0)
Block(-2,12,-5,STONE:0)
Block(-2,12,-4,biomesoplenty:grass:1)
Block(-2,12,-3,quark:leaf_carpet)
Block(-2,12,-2,biomesoplenty:willow_vine:1)
Block(-2,12,-1,biomesoplenty:willow_vine:8)
Block(-2,12,0,AIR:0)
Block(-2,12,1,inspirations:rope:2)
Block(-2,12,2,AIR:0)
Block(-2,12,3,AIR:0)
Block(-2,12,4,AIR:0)
Block(-2,12,5,STONE:0)
Block(-2,12,6,STONE:0)
Block(-2,12,7,STONE:0)
Block(-2,12,8,STONE:0)
Block(-2,12,9,STONE:0)
Block(-2,13,-8,STONE:0)
Block(-2,13,-7,STONE:0)
Block(-2,13,-6,STONE:0)
Block(-2,13,-5,biomesoplenty:grass:1)
Block(-2,13,-4,quark:leaf_carpet)
Block(-2,13,-3,biomesoplenty:willow_vine:8)
Block(-2,13,-2,biomesoplenty:willow_vine:1)
Block(-2,13,-1,biomesoplenty:willow_vine:8)
Block(-2,13,0,AIR:0)
Block(-2,13,1,inspirations:rope:2)
Block(-2,13,2,AIR:0)
Block(-2,13,3,AIR:0)
Block(-2,13,4,LEAVES:4)
Block(-2,13,5,STONE:0)
Block(-2,13,6,STONE:0)
Block(-2,13,7,STONE:0)
Block(-2,13,8,STONE:0)
Block(-2,14,-10,STONE:0)
Block(-2,14,-9,STONE:0)
Block(-2,14,-8,STONE:0)
Block(-2,14,-7,STONE:0)
Block(-2,14,-6,quark:leaf_carpet)
Block(-2,14,-5,quark:leaf_carpet)
Block(-2,14,-4,AIR:0)
Block(-2,14,-3,biomesoplenty:willow_vine:8)
Block(-2,14,-2,biomesoplenty:willow_vine:1)
Block(-2,14,-1,biomesoplenty:willow_vine:8)
Block(-2,14,0,AIR:0)
Block(-2,14,1,inspirations:rope:2)
Block(-2,14,2,AIR:0)
Block(-2,14,3,AIR:0)
Block(-2,14,4,STONE:0)
Block(-2,14,5,STONE:0)
Block(-2,14,6,STONE:0)
Block(-2,15,-11,STONE:0)
Block(-2,15,-10,STONE:0)
Block(-2,15,-9,STONE:0)
Block(-2,15,-8,BROWN_MUSHROOM:0)
Block(-2,15,-7,quark:leaf_carpet)
Block(-2,15,-6,AIR:0)
Block(-2,15,-5,AIR:0)
Block(-2,15,-4,AIR:0)
Block(-2,15,-3,biomesoplenty:willow_vine:8)
Block(-2,15,-2,biomesoplenty:willow_vine:1)
Block(-2,15,-1,biomesoplenty:willow_vine:8)
Block(-2,15,0,AIR:0)
Block(-2,15,1,inspirations:rope:2)
Block(-2,15,2,AIR:0)
Block(-2,15,3,LEAVES:4)
Block(-2,15,4,STONE:0)
Block(-2,15,5,STONE:0)
Block(-2,15,6,STONE:0)
Block(-2,16,-11,STONE:0)
Block(-2,16,-10,STONE:0)
Block(-2,16,-9,biomesoplenty:plant_0:11)
Block(-2,16,-8,AIR:0)
Block(-2,16,-7,AIR:0)
Block(-2,16,-6,AIR:0)
Block(-2,16,-5,AIR:0)
Block(-2,16,-4,AIR:0)
Block(-2,16,-3,biomesoplenty:willow_vine:8)
Block(-2,16,-2,biomesoplenty:willow_vine:1)
Block(-2,16,-1,LEAVES:4)
Block(-2,16,0,LEAVES:4)
Block(-2,16,1,inspirations:rope:2)
Block(-2,16,2,LEAVES:4)
Block(-2,16,3,STONE:0)
Block(-2,16,4,STONE:0)
Block(-2,16,5,STONE:0)
Block(-2,17,-14,STONE:0)
Block(-2,17,-13,STONE:0)
Block(-2,17,-11,STONE:0)
Block(-2,17,-10,STONE:0)
Block(-2,17,-9,AIR:0)
Block(-2,17,-8,AIR:0)
Block(-2,17,-7,AIR:0)
Block(-2,17,-6,AIR:0)
Block(-2,17,-5,AIR:0)
Block(-2,17,-4,AIR:0)
Block(-2,17,-3,biomesoplenty:willow_vine:8)
Block(-2,17,-2,LEAVES:4)
Block(-2,17,-1,STONE:0)
Block(-2,17,0,STONE:0)
Block(-2,17,1,STONE:0)
Block(-2,17,2,LEAVES:4)
Block(-2,17,3,STONE:0)
Block(-2,17,4,STONE:0)
Block(-2,18,-14,STONE:0)
Block(-2,18,-13,STONE:0)
Block(-2,18,-12,STONE:0)
Block(-2,18,-11,STONE:0)
Block(-2,18,-10,STONE:0)
Block(-2,18,-9,AIR:0)
Block(-2,18,-8,inspirations:rope:2)
Block(-2,18,-7,AIR:0)
Block(-2,18,-6,AIR:0)
Block(-2,18,-5,AIR:0)
Block(-2,18,-4,LEAVES:12)
Block(-2,18,-3,LEAVES:12)
Block(-2,18,-2,STONE:0)
Block(-2,18,-1,STONE:0)
Block(-2,18,0,STONE:0)
Block(-2,18,1,STONE:0)
Block(-2,18,2,STONE:0)
Block(-2,18,3,STONE:0)
Block(-2,19,-14,STONE:0)
Block(-2,19,-13,STONE:0)
Block(-2,19,-12,STONE:0)
Block(-2,19,-11,STONE:0)
Block(-2,19,-10,STONE:0)
Block(-2,19,-9,LEAVES:4)
Block(-2,19,-8,inspirations:rope:2)
Block(-2,19,-7,AIR:0)
Block(-2,19,-6,AIR:0)
Block(-2,19,-5,AIR:0)
Block(-2,19,-4,LEAVES:12)
Block(-2,19,-3,STONE:0)
Block(-2,19,-2,STONE:0)
Block(-2,19,-1,STONE:0)
Block(-2,19,0,STONE:0)
Block(-2,20,-14,STONE:0)
Block(-2,20,-13,STONE:0)
Block(-2,20,-12,STONE:0)
Block(-2,20,-11,STONE:0)
Block(-2,20,-10,STONE:0)
Block(-2,20,-9,STONE:0)
Block(-2,20,-8,STONE:0)
Block(-2,20,-7,STONE:0)
Block(-2,20,-6,STONE:0)
Block(-2,20,-5,LEAVES:4)
Block(-2,20,-4,STONE:0)
Block(-2,20,-3,STONE:0)
Block(-2,20,-2,STONE:0)
Block(-2,21,-14,STONE:0)
Block(-2,21,-13,STONE:0)
Block(-2,21,-12,STONE:0)
Block(-2,21,-11,STONE:0)
Block(-2,21,-10,STONE:0)
Block(-2,21,-9,STONE:0)
Block(-2,21,-8,STONE:0)
Block(-2,21,-7,STONE:0)
Block(-2,21,-6,STONE:0)
Block(-2,21,-5,STONE:0)
Block(-2,21,-4,STONE:0)
Block(-2,21,-3,STONE:0)
Block(-2,22,-13,STONE:0)
Block(-2,22,-12,STONE:0)
Block(-2,22,-11,STONE:0)
Block(-2,22,-10,STONE:0)
Block(-2,22,-9,STONE:0)
Block(-2,22,-8,STONE:0)
Block(-2,22,-7,STONE:0)
Block(-2,22,-6,STONE:0)
Block(-1,2,11,STONE:0)
Block(-1,2,12,iceandfire:chared_stone)
Block(-1,2,13,iceandfire:chared_stone)
Block(-1,2,14,STONE:0)
Block(-1,2,15,STONE:0)
Block(-1,2,16,STONE:0)
Block(-1,3,7,STONE:0)
Block(-1,3,8,STONE:0)
Block(-1,3,9,STONE:0)
Block(-1,3,10,iceandfire:chared_stone)
Block(-1,3,11,iceandfire:chared_stone)
Block(-1,3,12,STATIONARY_WATER:0)
Block(-1,3,13,STATIONARY_WATER:0)
Block(-1,3,14,MAGMA:0)
Block(-1,3,15,iceandfire:chared_stone)
Block(-1,3,16,STONE:0)
Block(-1,4,2,STONE:0)
Block(-1,4,3,STONE:0)
Block(-1,4,4,STONE:0)
Block(-1,4,6,STONE:0)
Block(-1,4,7,STONE:0)
Block(-1,4,8,STONE:0)
Block(-1,4,9,iceandfire:chared_stone)
Block(-1,4,10,STATIONARY_WATER:0)
Block(-1,4,11,STATIONARY_WATER:0)
Block(-1,4,12,STATIONARY_WATER:0)
Block(-1,4,13,STATIONARY_WATER:0)
Block(-1,4,14,STATIONARY_WATER:0)
Block(-1,4,15,STATIONARY_WATER:0)
Block(-1,4,16,iceandfire:chared_stone)
Block(-1,5,0,STONE:0)
Block(-1,5,1,STONE:0)
Block(-1,5,2,STONE:0)
Block(-1,5,3,STONE:0)
Block(-1,5,4,STONE:0)
Block(-1,5,5,STONE:0)
Block(-1,5,6,STONE:0)
Block(-1,5,7,biomesoplenty:grass:1)
Block(-1,5,8,STATIONARY_WATER:3)
Block(-1,5,9,STATIONARY_WATER:4)
Block(-1,5,10,STATIONARY_WATER:5)
Block(-1,5,11,AIR:0)
Block(-1,5,12,AIR:0)
Block(-1,5,13,AIR:0)
Block(-1,5,14,AIR:0)
Block(-1,5,15,AIR:0)
Block(-1,5,16,STONE:0)
Block(-1,6,-1,STONE:0)
Block(-1,6,0,STONE:0)
Block(-1,6,1,STONE:0)
Block(-1,6,2,STONE:0)
Block(-1,6,3,STATIONARY_WATER:3)
Block(-1,6,4,STONE:0)
Block(-1,6,5,biomesoplenty:grass:1)
Block(-1,6,6,STONE:0)
Block(-1,6,7,AIR:0)
Block(-1,6,8,AIR:0)
Block(-1,6,9,AIR:0)
Block(-1,6,10,AIR:0)
Block(-1,6,11,AIR:0)
Block(-1,6,12,AIR:0)
Block(-1,6,13,AIR:0)
Block(-1,6,14,AIR:0)
Block(-1,6,15,STONE:0)
Block(-1,6,16,STONE:0)
Block(-1,7,-2,STONE:0)
Block(-1,7,-1,STONE:0)
Block(-1,7,0,STONE:0)
Block(-1,7,1,BROWN_MUSHROOM:0)
Block(-1,7,2,biomesoplenty:plant_0:11)
Block(-1,7,3,AIR:0)
Block(-1,7,4,biomesoplenty:plant_0:11)
Block(-1,7,5,quark:leaf_carpet)
Block(-1,7,6,BROWN_MUSHROOM:0)
Block(-1,7,7,AIR:0)
Block(-1,7,8,AIR:0)
Block(-1,7,9,AIR:0)
Block(-1,7,10,AIR:0)
Block(-1,7,11,AIR:0)
Block(-1,7,12,AIR:0)
Block(-1,7,13,AIR:0)
Block(-1,7,14,LEAVES:4)
Block(-1,7,15,LEAVES:4)
Block(-1,7,16,STONE:0)
Block(-1,8,-2,STONE:0)
Block(-1,8,-1,STONE:0)
Block(-1,8,0,STONE:0)
Block(-1,8,1,AIR:0)
Block(-1,8,2,AIR:0)
Block(-1,8,3,AIR:0)
Block(-1,8,4,AIR:0)
Block(-1,8,5,biomesoplenty:willow_vine:3)
Block(-1,8,6,AIR:0)
Block(-1,8,7,AIR:0)
Block(-1,8,8,AIR:0)
Block(-1,8,9,AIR:0)
Block(-1,8,10,AIR:0)
Block(-1,8,11,AIR:0)
Block(-1,8,12,LEAVES:4)
Block(-1,8,13,LEAVES:12)
Block(-1,8,14,LEAVES:4)
Block(-1,8,15,STONE:0)
Block(-1,8,16,STONE:0)
Block(-1,9,-3,STONE:0)
Block(-1,9,-2,STONE:0)
Block(-1,9,-1,STONE:0)
Block(-1,9,0,BROWN_MUSHROOM:0)
Block(-1,9,1,AIR:0)
Block(-1,9,2,AIR:0)
Block(-1,9,3,AIR:0)
Block(-1,9,4,AIR:0)
Block(-1,9,5,biomesoplenty:willow_vine:3)
Block(-1,9,6,AIR:0)
Block(-1,9,7,AIR:0)
Block(-1,9,8,AIR:0)
Block(-1,9,9,AIR:0)
Block(-1,9,10,AIR:0)
Block(-1,9,11,LEAVES:4)
Block(-1,9,12,STONE:0)
Block(-1,9,13,STONE:0)
Block(-1,9,14,STONE:0)
Block(-1,9,15,STONE:0)
Block(-1,10,-4,STONE:0)
Block(-1,10,-3,STONE:0)
Block(-1,10,-2,STONE:0)
Block(-1,10,-1,AIR:0)
Block(-1,10,0,AIR:0)
Block(-1,10,1,AIR:0)
Block(-1,10,2,AIR:0)
Block(-1,10,3,AIR:0)
Block(-1,10,4,AIR:0)
Block(-1,10,5,biomesoplenty:willow_vine:3)
Block(-1,10,6,AIR:0)
Block(-1,10,7,LEAVES:12)
Block(-1,10,8,LEAVES:12)
Block(-1,10,9,STONE:0)
Block(-1,10,10,STONE:0)
Block(-1,10,11,STONE:0)
Block(-1,10,12,STONE:0)
Block(-1,10,13,STONE:0)
Block(-1,10,14,STONE:0)
Block(-1,10,15,STONE:0)
Block(-1,11,-5,STONE:0)
Block(-1,11,-4,STONE:0)
Block(-1,11,-3,STONE:0)
Block(-1,11,-2,quark:leaf_carpet)
Block(-1,11,-1,AIR:0)
Block(-1,11,0,AIR:0)
Block(-1,11,1,AIR:0)
Block(-1,11,2,AIR:0)
Block(-1,11,3,AIR:0)
Block(-1,11,4,AIR:0)
Block(-1,11,5,biomesoplenty:willow_vine:1)
Block(-1,11,6,LEAVES:4)
Block(-1,11,7,LEAVES:4)
Block(-1,11,8,STONE:0)
Block(-1,11,9,STONE:0)
Block(-1,11,10,STONE:0)
Block(-1,12,-6,STONE:0)
Block(-1,12,-5,STONE:0)
Block(-1,12,-4,STONE:0)
Block(-1,12,-3,STONE:0)
Block(-1,12,-2,AIR:0)
Block(-1,12,-1,AIR:0)
Block(-1,12,0,AIR:0)
Block(-1,12,1,AIR:0)
Block(-1,12,2,AIR:0)
Block(-1,12,3,AIR:0)
Block(-1,12,4,AIR:0)
Block(-1,12,5,LEAVES:4)
Block(-1,12,6,STONE:0)
Block(-1,12,7,STONE:0)
Block(-1,12,8,STONE:0)
Block(-1,12,9,STONE:0)
Block(-1,13,-8,STONE:0)
Block(-1,13,-7,STONE:0)
Block(-1,13,-6,STONE:0)
Block(-1,13,-5,STONE:0)
Block(-1,13,-4,biomesoplenty:grass:1)
Block(-1,13,-3,BROWN_MUSHROOM:0)
Block(-1,13,-2,AIR:0)
Block(-1,13,-1,AIR:0)
Block(-1,13,0,AIR:0)
Block(-1,13,1,AIR:0)
Block(-1,13,2,AIR:0)
Block(-1,13,3,AIR:0)
Block(-1,13,4,LEAVES:4)
Block(-1,13,5,STONE:0)
Block(-1,13,6,STONE:0)
Block(-1,13,7,STONE:0)
Block(-1,13,8,STONE:0)
Block(-1,13,9,STONE:0)
Block(-1,14,-10,STONE:0)
Block(-1,14,-9,STONE:0)
Block(-1,14,-8,STONE:0)
Block(-1,14,-7,STONE:0)
Block(-1,14,-6,biomesoplenty:grass:1)
Block(-1,14,-5,biomesoplenty:grass:1)
Block(-1,14,-4,biomesoplenty:flower_0:3)
Block(-1,14,-3,biomesoplenty:willow_vine:8)
Block(-1,14,-2,AIR:0)
Block(-1,14,-1,AIR:0)
Block(-1,14,0,AIR:0)
Block(-1,14,1,AIR:0)
Block(-1,14,2,AIR:0)
Block(-1,14,3,AIR:0)
Block(-1,14,4,STONE:0)
Block(-1,14,5,STONE:0)
Block(-1,14,6,STONE:0)
Block(-1,14,7,STONE:0)
Block(-1,15,-11,STONE:0)
Block(-1,15,-10,STONE:0)
Block(-1,15,-9,biomesoplenty:grass:1)
Block(-1,15,-8,STONE:0)
Block(-1,15,-7,biomesoplenty:grass:1)
Block(-1,15,-6,BROWN_MUSHROOM:0)
Block(-1,15,-5,BROWN_MUSHROOM:0)
Block(-1,15,-4,AIR:0)
Block(-1,15,-3,biomesoplenty:willow_vine:8)
Block(-1,15,-2,AIR:0)
Block(-1,15,-1,LEAVES:4)
Block(-1,15,0,LEAVES:4)
Block(-1,15,1,LEAVES:4)
Block(-1,15,2,AIR:0)
Block(-1,15,3,LEAVES:4)
Block(-1,15,4,LEAVES:4)
Block(-1,15,5,STONE:0)
Block(-1,15,6,STONE:0)
Block(-1,16,-14,STONE:0)
Block(-1,16,-13,STONE:0)
Block(-1,16,-12,STONE:0)
Block(-1,16,-11,biomesoplenty:grass:1)
Block(-1,16,-10,STONE:0)
Block(-1,16,-9,biomesoplenty:willow_vine:2)
Block(-1,16,-8,AIR:0)
Block(-1,16,-7,biomesoplenty:plant_0:11)
Block(-1,16,-6,AIR:0)
Block(-1,16,-5,AIR:0)
Block(-1,16,-4,AIR:0)
Block(-1,16,-3,biomesoplenty:willow_vine:8)
Block(-1,16,-2,LEAVES:4)
Block(-1,16,-1,STONE:0)
Block(-1,16,0,STONE:0)
Block(-1,16,1,STONE:0)
Block(-1,16,2,LEAVES:4)
Block(-1,16,3,STONE:0)
Block(-1,16,4,STONE:0)
Block(-1,16,5,STONE:0)
Block(-1,17,-14,STONE:0)
Block(-1,17,-13,STONE:0)
Block(-1,17,-12,STONE:0)
Block(-1,17,-11,biomesoplenty:flower_0:3)
Block(-1,17,-10,biomesoplenty:willow_vine:4)
Block(-1,17,-9,biomesoplenty:willow_vine:2)
Block(-1,17,-8,AIR:0)
Block(-1,17,-7,AIR:0)
Block(-1,17,-6,AIR:0)
Block(-1,17,-5,AIR:0)
Block(-1,17,-4,AIR:0)
Block(-1,17,-3,LEAVES:4)
Block(-1,17,-2,STONE:0)
Block(-1,17,-1,STONE:0)
Block(-1,17,0,STONE:0)
Block(-1,17,1,STONE:0)
Block(-1,17,2,STONE:0)
Block(-1,17,3,STONE:0)
Block(-1,17,4,STONE:0)
Block(-1,18,-14,STONE:0)
Block(-1,18,-13,STONE:0)
Block(-1,18,-12,STONE:0)
Block(-1,18,-11,STONE:0)
Block(-1,18,-10,biomesoplenty:willow_vine:4)
Block(-1,18,-9,biomesoplenty:willow_vine:2)
Block(-1,18,-8,AIR:0)
Block(-1,18,-7,AIR:0)
Block(-1,18,-6,AIR:0)
Block(-1,18,-5,LEAVES:4)
Block(-1,18,-4,STONE:0)
Block(-1,18,-3,STONE:0)
Block(-1,18,-2,STONE:0)
Block(-1,18,-1,STONE:0)
Block(-1,18,0,STONE:0)
Block(-1,18,1,STONE:0)
Block(-1,18,2,STONE:0)
Block(-1,18,3,STONE:0)
Block(-1,19,-15,STONE:0)
Block(-1,19,-14,STONE:0)
Block(-1,19,-13,STONE:0)
Block(-1,19,-12,STONE:0)
Block(-1,19,-11,STONE:0)
Block(-1,19,-10,biomesoplenty:willow_vine:4)
Block(-1,19,-9,biomesoplenty:willow_vine:2)
Block(-1,19,-8,AIR:0)
Block(-1,19,-7,AIR:0)
Block(-1,19,-6,STONE:0)
Block(-1,19,-5,STONE:0)
Block(-1,19,-4,STONE:0)
Block(-1,19,-3,STONE:0)
Block(-1,20,-15,STONE:0)
Block(-1,20,-14,STONE:0)
Block(-1,20,-13,STONE:0)
Block(-1,20,-12,STONE:0)
Block(-1,20,-11,STONE:0)
Block(-1,20,-10,STONE:0)
Block(-1,20,-9,STONE:0)
Block(-1,20,-8,STONE:0)
Block(-1,20,-7,STONE:0)
Block(-1,20,-6,STONE:0)
Block(-1,20,-5,STONE:0)
Block(-1,20,-4,STONE:0)
Block(-1,20,-3,STONE:0)
Block(-1,21,-14,STONE:0)
Block(-1,21,-13,STONE:0)
Block(-1,21,-12,STONE:0)
Block(-1,21,-11,STONE:0)
Block(-1,21,-10,STONE:0)
Block(-1,21,-9,STONE:0)
Block(-1,21,-8,STONE:0)
Block(-1,21,-7,STONE:0)
Block(-1,21,-6,STONE:0)
Block(-1,21,-5,STONE:0)
Block(-1,22,-14,STONE:0)
Block(-1,22,-13,STONE:0)
Block(-1,22,-12,STONE:0)
Block(-1,22,-11,STONE:0)
Block(-1,22,-10,STONE:0)
Block(-1,22,-9,STONE:0)
Block(-1,22,-8,STONE:0)
Block(-1,22,-7,STONE:0)
Block(-1,22,-6,STONE:0)
Block(0,2,11,STONE:0)
Block(0,2,12,MAGMA:0)
Block(0,2,13,iceandfire:chared_cobblestone)
Block(0,2,14,iceandfire:chared_stone)
Block(0,2,15,STONE:0)
Block(0,2,16,STONE:0)
Block(0,3,7,STONE:0)
Block(0,3,8,STONE:0)
Block(0,3,9,STONE:0)
Block(0,3,10,STONE:0)
Block(0,3,11,iceandfire:chared_cobblestone)
Block(0,3,12,STATIONARY_WATER:0)
Block(0,3,13,STATIONARY_WATER:0)
Block(0,3,14,STATIONARY_WATER:0)
Block(0,3,15,iceandfire:chared_stone)
Block(0,3,16,STONE:0)
Block(0,4,2,STONE:0)
Block(0,4,3,STONE:0)
Block(0,4,4,STONE:0)
Block(0,4,6,STONE:0)
Block(0,4,7,STONE:0)
Block(0,4,8,STONE:0)
Block(0,4,9,biomesoplenty:grass:1)
Block(0,4,10,biomesoplenty:grass:1)
Block(0,4,11,STATIONARY_WATER:0)
Block(0,4,12,STATIONARY_WATER:0)
Block(0,4,13,STATIONARY_WATER:0)
Block(0,4,14,STATIONARY_WATER:0)
Block(0,4,15,STATIONARY_WATER:0)
Block(0,4,16,STONE:0)
Block(0,5,0,STONE:0)
Block(0,5,1,STONE:0)
Block(0,5,2,STONE:0)
Block(0,5,3,STONE:0)
Block(0,5,4,STONE:0)
Block(0,5,5,STONE:0)
Block(0,5,6,STONE:0)
Block(0,5,7,STONE:0)
Block(0,5,8,STONE:0)
Block(0,5,9,BROWN_MUSHROOM:0)
Block(0,5,10,AIR:0)
Block(0,5,11,AIR:0)
Block(0,5,12,AIR:0)
Block(0,5,13,AIR:0)
Block(0,5,14,AIR:0)
Block(0,5,15,AIR:0)
Block(0,5,16,STONE:0)
Block(0,6,-1,STONE:0)
Block(0,6,0,STONE:0)
Block(0,6,1,STATIONARY_WATER:0)
Block(0,6,2,STATIONARY_WATER:1)
Block(0,6,3,STATIONARY_WATER:2)
Block(0,6,4,biomesoplenty:grass:1)
Block(0,6,5,biomesoplenty:grass:1)
Block(0,6,6,biomesoplenty:grass:1)
Block(0,6,7,STONE:0)
Block(0,6,8,biomesoplenty:grass:1)
Block(0,6,9,AIR:0)
Block(0,6,10,AIR:0)
Block(0,6,11,AIR:0)
Block(0,6,12,AIR:0)
Block(0,6,13,AIR:0)
Block(0,6,14,AIR:0)
Block(0,6,15,AIR:0)
Block(0,6,16,STONE:0)
Block(0,7,-2,STONE:0)
Block(0,7,-1,STONE:0)
Block(0,7,0,STATIONARY_WATER:9)
Block(0,7,1,STATIONARY_WATER:1)
Block(0,7,2,biomesoplenty:willow_vine:8)
Block(0,7,3,AIR:0)
Block(0,7,4,quark:leaf_carpet)
Block(0,7,5,biomesoplenty:plant_0:11)
Block(0,7,6,quark:leaf_carpet)
Block(0,7,7,quark:leaf_carpet)
Block(0,7,8,AIR:0)
Block(0,7,9,AIR:0)
Block(0,7,10,AIR:0)
Block(0,7,11,AIR:0)
Block(0,7,12,AIR:0)
Block(0,7,13,AIR:0)
Block(0,7,14,AIR:0)
Block(0,7,15,LEAVES:4)
Block(0,7,16,STONE:0)
Block(0,8,-2,STONE:0)
Block(0,8,-1,STATIONARY_WATER:9)
Block(0,8,0,STATIONARY_WATER:1)
Block(0,8,1,AIR:0)
Block(0,8,2,biomesoplenty:willow_vine:8)
Block(0,8,3,AIR:0)
Block(0,8,4,AIR:0)
Block(0,8,5,AIR:0)
Block(0,8,6,AIR:0)
Block(0,8,7,AIR:0)
Block(0,8,8,LEAVES:4)
Block(0,8,9,AIR:0)
Block(0,8,10,AIR:0)
Block(0,8,11,AIR:0)
Block(0,8,12,AIR:0)
Block(0,8,13,STONE:0)
Block(0,8,14,STONE:0)
Block(0,8,15,STONE:0)
Block(0,8,16,STONE:0)
Block(0,9,-3,STONE:0)
Block(0,9,-2,STATIONARY_WATER:9)
Block(0,9,-1,STATIONARY_WATER:1)
Block(0,9,0,biomesoplenty:willow_vine:8)
Block(0,9,1,AIR:0)
Block(0,9,2,biomesoplenty:willow_vine:8)
Block(0,9,3,AIR:0)
Block(0,9,4,AIR:0)
Block(0,9,5,AIR:0)
Block(0,9,6,AIR:0)
Block(0,9,7,AIR:0)
Block(0,9,8,LEAVES:4)
Block(0,9,9,LEAVES:4)
Block(0,9,10,AIR:0)
Block(0,9,11,LEAVES:12)
Block(0,9,12,LEAVES:4)
Block(0,9,13,STONE:0)
Block(0,9,14,STONE:0)
Block(0,9,15,STONE:0)
Block(0,10,-3,STONE:0)
Block(0,10,-2,STATIONARY_WATER:9)
Block(0,10,-1,biomesoplenty:willow_vine:8)
Block(0,10,0,biomesoplenty:willow_vine:8)
Block(0,10,1,AIR:0)
Block(0,10,2,biomesoplenty:willow_vine:8)
Block(0,10,3,AIR:0)
Block(0,10,4,AIR:0)
Block(0,10,5,AIR:0)
Block(0,10,6,AIR:0)
Block(0,10,7,STONE:0)
Block(0,10,8,LEAVES:12)
Block(0,10,9,STONE:0)
Block(0,10,10,STONE:0)
Block(0,10,11,STONE:0)
Block(0,10,12,STONE:0)
Block(0,10,13,STONE:0)
Block(0,10,14,STONE:0)
Block(0,10,15,STONE:0)
Block(0,11,-4,STONE:0)
Block(0,11,-3,STONE:0)
Block(0,11,-2,STATIONARY_WATER:9)
Block(0,11,-1,biomesoplenty:willow_vine:8)
Block(0,11,0,biomesoplenty:willow_vine:8)
Block(0,11,1,AIR:0)
Block(0,11,2,biomesoplenty:willow_vine:8)
Block(0,11,3,AIR:0)
Block(0,11,4,AIR:0)
Block(0,11,5,AIR:0)
Block(0,11,6,LEAVES:4)
Block(0,11,7,STONE:0)
Block(0,11,8,STONE:0)
Block(0,11,9,STONE:0)
Block(0,11,10,STONE:0)
Block(0,11,13,STONE:0)
Block(0,12,-5,STONE:0)
Block(0,12,-4,STONE:0)
Block(0,12,-3,STATIONARY_WATER:9)
Block(0,12,-2,STATIONARY_WATER:1)
Block(0,12,-1,biomesoplenty:willow_vine:8)
Block(0,12,0,biomesoplenty:willow_vine:8)
Block(0,12,1,AIR:0)
Block(0,12,2,biomesoplenty:willow_vine:8)
Block(0,12,3,AIR:0)
Block(0,12,4,AIR:0)
Block(0,12,5,STONE:0)
Block(0,12,6,STONE:0)
Block(0,12,7,STONE:0)
Block(0,12,8,STONE:0)
Block(0,12,9,STONE:0)
Block(0,13,-7,STONE:0)
Block(0,13,-6,STONE:0)
Block(0,13,-5,STONE:0)
Block(0,13,-4,STATIONARY_WATER:9)
Block(0,13,-3,STATIONARY_WATER:1)
Block(0,13,-2,AIR:0)
Block(0,13,-1,biomesoplenty:willow_vine:8)
Block(0,13,0,biomesoplenty:willow_vine:8)
Block(0,13,1,AIR:0)
Block(0,13,2,biomesoplenty:willow_vine:8)
Block(0,13,3,AIR:0)
Block(0,13,4,AIR:0)
Block(0,13,5,STONE:0)
Block(0,13,6,STONE:0)
Block(0,13,7,STONE:0)
Block(0,13,8,STONE:0)
Block(0,13,9,STONE:0)
Block(0,14,-9,STONE:0)
Block(0,14,-8,STONE:0)
Block(0,14,-7,STONE:0)
Block(0,14,-6,STATIONARY_WATER:11)
Block(0,14,-5,STATIONARY_WATER:12)
Block(0,14,-4,STATIONARY_WATER:1)
Block(0,14,-3,AIR:0)
Block(0,14,-2,AIR:0)
Block(0,14,-1,biomesoplenty:willow_vine:8)
Block(0,14,0,LEAVES:12)
Block(0,14,1,LEAVES:12)
Block(0,14,2,LEAVES:4)
Block(0,14,3,LEAVES:4)
Block(0,14,4,STONE:0)
Block(0,14,5,STONE:0)
Block(0,14,6,STONE:0)
Block(0,14,7,STONE:0)
Block(0,15,-11,STONE:0)
Block(0,15,-10,STONE:0)
Block(0,15,-9,biomesoplenty:grass:1)
Block(0,15,-8,biomesoplenty:grass:1)
Block(0,15,-7,biomesoplenty:grass:1)
Block(0,15,-6,STATIONARY_WATER:3)
Block(0,15,-5,STATIONARY_WATER:4)
Block(0,15,-4,AIR:0)
Block(0,15,-3,AIR:0)
Block(0,15,-2,LEAVES:4)
Block(0,15,-1,STONE:0)
Block(0,15,0,STONE:0)
Block(0,15,1,STONE:0)
Block(0,15,2,LEAVES:4)
Block(0,15,3,STONE:0)
Block(0,15,4,STONE:0)
Block(0,15,5,STONE:0)
Block(0,15,6,STONE:0)
Block(0,16,-14,STONE:0)
Block(0,16,-13,STONE:0)
Block(0,16,-12,STONE:0)
Block(0,16,-11,STONE:0)
Block(0,16,-10,biomesoplenty:grass:1)
Block(0,16,-9,quark:leaf_carpet)
Block(0,16,-8,quark:leaf_carpet)
Block(0,16,-7,biomesoplenty:willow_vine:1)
Block(0,16,-6,biomesoplenty:willow_vine:8)
Block(0,16,-5,AIR:0)
Block(0,16,-4,inspirations:rope:2)
Block(0,16,-3,LEAVES:4)
Block(0,16,-2,STONE:0)
Block(0,16,-1,STONE:0)
Block(0,16,0,STONE:0)
Block(0,16,1,STONE:0)
Block(0,16,2,STONE:0)
Block(0,16,3,STONE:0)
Block(0,16,4,STONE:0)
Block(0,16,5,STONE:0)
Block(0,17,-15,STONE:0)
Block(0,17,-14,STONE:0)
Block(0,17,-13,STONE:0)
Block(0,17,-12,quark:leaf_carpet)
Block(0,17,-11,biomesoplenty:willow_vine:2)
Block(0,17,-10,quark:leaf_carpet)
Block(0,17,-9,AIR:0)
Block(0,17,-8,AIR:0)
Block(0,17,-7,biomesoplenty:willow_vine:1)
Block(0,17,-6,biomesoplenty:willow_vine:8)
Block(0,17,-5,AIR:0)
Block(0,17,-4,inspirations:rope:2)
Block(0,17,-3,STONE:0)
Block(0,17,-2,STONE:0)
Block(0,17,-1,STONE:0)
Block(0,17,0,STONE:0)
Block(0,17,1,STONE:0)
Block(0,17,2,STONE:0)
Block(0,17,3,STONE:0)
Block(0,17,4,STONE:0)
Block(0,18,-15,STONE:0)
Block(0,18,-14,STONE:0)
Block(0,18,-13,STONE:0)
Block(0,18,-12,AIR:0)
Block(0,18,-11,biomesoplenty:willow_vine:2)
Block(0,18,-10,AIR:0)
Block(0,18,-9,AIR:0)
Block(0,18,-8,AIR:0)
Block(0,18,-7,biomesoplenty:willow_vine:1)
Block(0,18,-6,STONE:0)
Block(0,18,-5,STONE:0)
Block(0,18,-4,STONE:0)
Block(0,18,-3,STONE:0)
Block(0,19,-15,STONE:0)
Block(0,19,-14,STONE:0)
Block(0,19,-13,biomesoplenty:willow_vine:2)
Block(0,19,-12,AIR:0)
Block(0,19,-11,biomesoplenty:willow_vine:2)
Block(0,19,-10,AIR:0)
Block(0,19,-9,AIR:0)
Block(0,19,-8,AIR:0)
Block(0,19,-7,STONE:0)
Block(0,19,-6,STONE:0)
Block(0,19,-5,STONE:0)
Block(0,19,-4,STONE:0)
Block(0,20,-15,STONE:0)
Block(0,20,-14,STONE:0)
Block(0,20,-13,biomesoplenty:willow_vine:2)
Block(0,20,-12,AIR:0)
Block(0,20,-11,biomesoplenty:willow_vine:2)
Block(0,20,-10,AIR:0)
Block(0,20,-9,AIR:0)
Block(0,20,-8,STONE:0)
Block(0,20,-7,STONE:0)
Block(0,20,-6,STONE:0)
Block(0,20,-5,STONE:0)
Block(0,20,-4,STONE:0)
Block(0,21,-15,STONE:0)
Block(0,21,-14,STONE:0)
Block(0,21,-13,STONE:0)
Block(0,21,-12,STONE:0)
Block(0,21,-11,STONE:0)
Block(0,21,-10,STONE:0)
Block(0,21,-9,STONE:0)
Block(0,21,-8,STONE:0)
Block(0,21,-7,STONE:0)
Block(0,21,-6,STONE:0)
Block(0,21,-5,STONE:0)
Block(0,22,-15,STONE:0)
Block(0,22,-14,STONE:0)
Block(0,22,-13,STONE:0)
Block(0,22,-12,STONE:0)
Block(0,22,-11,STONE:0)
Block(0,22,-10,STONE:0)
Block(0,22,-9,STONE:0)
Block(0,22,-8,STONE:0)
Block(0,22,-7,STONE:0)
Block(1,2,11,STONE:0)
Block(1,2,12,STONE:0)
Block(1,2,13,iceandfire:chared_cobblestone)
Block(1,2,14,iceandfire:chared_stone)
Block(1,2,15,STONE:0)
Block(1,2,16,STONE:0)
Block(1,3,9,STONE:0)
Block(1,3,10,STONE:0)
Block(1,3,11,STONE:0)
Block(1,3,12,MAGMA:0)
Block(1,3,13,STATIONARY_WATER:0)
Block(1,3,14,STATIONARY_WATER:0)
Block(1,3,15,iceandfire:chared_stone)
Block(1,3,16,STONE:0)
Block(1,4,2,STONE:0)
Block(1,4,3,STONE:0)
Block(1,4,4,STONE:0)
Block(1,4,5,STONE:0)
Block(1,4,6,STONE:0)
Block(1,4,7,STONE:0)
Block(1,4,8,STONE:0)
Block(1,4,9,STONE:0)
Block(1,4,10,STONE:0)
Block(1,4,11,biomesoplenty:grass:1)
Block(1,4,12,STATIONARY_WATER:0)
Block(1,4,13,STATIONARY_WATER:0)
Block(1,4,14,STATIONARY_WATER:0)
Block(1,4,15,biomesoplenty:grass:1)
Block(1,4,16,STONE:0)
Block(1,5,-1,STONE:0)
Block(1,5,0,STONE:0)
Block(1,5,1,STONE:0)
Block(1,5,2,STONE:0)
Block(1,5,3,STONE:0)
Block(1,5,4,STONE:0)
Block(1,5,5,STONE:0)
Block(1,5,6,biomesoplenty:grass:1)
Block(1,5,7,STONE:0)
Block(1,5,8,STONE:0)
Block(1,5,9,STONE:0)
Block(1,5,10,STONE:0)
Block(1,5,11,biomesoplenty:flower_0:3)
Block(1,5,12,AIR:0)
Block(1,5,13,AIR:0)
Block(1,5,14,AIR:0)
Block(1,5,15,BROWN_MUSHROOM:0)
Block(1,5,16,STONE:0)
Block(1,6,-2,STONE:0)
Block(1,6,-1,STONE:0)
Block(1,6,0,STONE:0)
Block(1,6,1,STONE:0)
Block(1,6,2,biomesoplenty:grass:1)
Block(1,6,3,biomesoplenty:grass:1)
Block(1,6,4,STONE:0)
Block(1,6,5,BROWN_MUSHROOM:0)
Block(1,6,6,biomesoplenty:willow_vine:1)
Block(1,6,7,STONE:0)
Block(1,6,8,STONE:0)
Block(1,6,9,STONE:0)
Block(1,6,10,quark:leaf_carpet)
Block(1,6,11,AIR:0)
Block(1,6,12,AIR:0)
Block(1,6,13,AIR:0)
Block(1,6,14,AIR:0)
Block(1,6,15,STONE:0)
Block(1,6,16,STONE:0)
Block(1,7,-2,STONE:0)
Block(1,7,-1,STONE:0)
Block(1,7,0,STONE:0)
Block(1,7,1,STONE:0)
Block(1,7,2,quark:leaf_carpet)
Block(1,7,3,AIR:0)
Block(1,7,4,biomesoplenty:plant_0:11)
Block(1,7,5,AIR:0)
Block(1,7,6,biomesoplenty:willow_vine:1)
Block(1,7,7,STONE:0)
Block(1,7,8,STONE:0)
Block(1,7,9,STONE:0)
Block(1,7,10,AIR:0)
Block(1,7,11,AIR:0)
Block(1,7,12,AIR:0)
Block(1,7,13,HUGE_MUSHROOM_1:14)
Block(1,7,14,HUGE_MUSHROOM_1:14)
Block(1,7,15,STONE:0)
Block(1,7,16,STONE:0)
Block(1,8,-2,STONE:0)
Block(1,8,-1,STONE:0)
Block(1,8,0,STONE:0)
Block(1,8,1,biomesoplenty:willow_vine:4)
Block(1,8,2,AIR:0)
Block(1,8,3,AIR:0)
Block(1,8,4,AIR:0)
Block(1,8,5,AIR:0)
Block(1,8,6,biomesoplenty:willow_vine:1)
Block(1,8,7,biomesoplenty:willow_vine:1)
Block(1,8,8,STONE:0)
Block(1,8,9,AIR:0)
Block(1,8,10,AIR:0)
Block(1,8,11,AIR:0)
Block(1,8,12,AIR:0)
Block(1,8,13,STONE:0)
Block(1,8,14,STONE:0)
Block(1,8,15,STONE:0)
Block(1,8,16,STONE:0)
Block(1,9,-3,STONE:0)
Block(1,9,-2,STONE:0)
Block(1,9,-1,STONE:0)
Block(1,9,0,STONE:0)
Block(1,9,1,biomesoplenty:willow_vine:4)
Block(1,9,2,AIR:0)
Block(1,9,3,AIR:0)
Block(1,9,4,AIR:0)
Block(1,9,5,AIR:0)
Block(1,9,6,biomesoplenty:willow_vine:1)
Block(1,9,7,biomesoplenty:willow_vine:1)
Block(1,9,8,STONE:0)
Block(1,9,9,LEAVES:12)
Block(1,9,10,LEAVES:4)
Block(1,9,11,LEAVES:4)
Block(1,9,12,STONE:0)
Block(1,9,13,STONE:0)
Block(1,9,14,STONE:0)
Block(1,9,15,STONE:0)
Block(1,10,-3,STONE:0)
Block(1,10,-2,STONE:0)
Block(1,10,-1,STONE:0)
Block(1,10,0,LEAVES:4)
Block(1,10,1,biomesoplenty:willow_vine:4)
Block(1,10,2,AIR:0)
Block(1,10,3,AIR:0)
Block(1,10,4,AIR:0)
Block(1,10,5,AIR:0)
Block(1,10,6,biomesoplenty:willow_vine:1)
Block(1,10,7,STONE:0)
Block(1,10,8,STONE:0)
Block(1,10,9,STONE:0)
Block(1,10,10,STONE:0)
Block(1,10,11,STONE:0)
Block(1,10,12,STONE:0)
Block(1,10,13,STONE:0)
Block(1,10,14,STONE:0)
Block(1,10,15,STONE:0)
Block(1,11,-3,STONE:0)
Block(1,11,-2,STONE:0)
Block(1,11,-1,STONE:0)
Block(1,11,0,LEAVES:4)
Block(1,11,1,biomesoplenty:willow_vine:4)
Block(1,11,2,AIR:0)
Block(1,11,3,AIR:0)
Block(1,11,4,AIR:0)
Block(1,11,5,AIR:0)
Block(1,11,6,biomesoplenty:willow_vine:1)
Block(1,11,7,STONE:0)
Block(1,11,8,STONE:0)
Block(1,11,9,STONE:0)
Block(1,11,10,STONE:0)
Block(1,12,-5,STONE:0)
Block(1,12,-4,STONE:0)
Block(1,12,-3,STONE:0)
Block(1,12,-2,STONE:0)
Block(1,12,-1,STONE:0)
Block(1,12,0,STONE:0)
Block(1,12,1,LEAVES:4)
Block(1,12,2,LEAVES:4)
Block(1,12,3,AIR:0)
Block(1,12,4,AIR:0)
Block(1,12,5,STONE:0)
Block(1,12,6,STONE:0)
Block(1,12,7,STONE:0)
Block(1,12,8,STONE:0)
Block(1,12,9,STONE:0)
Block(1,13,-7,STONE:0)
Block(1,13,-6,STONE:0)
Block(1,13,-5,STONE:0)
Block(1,13,-4,STONE:0)
Block(1,13,-3,STONE:0)
Block(1,13,-2,STONE:0)
Block(1,13,-1,STONE:0)
Block(1,13,0,STONE:0)
Block(1,13,1,STONE:0)
Block(1,13,2,STONE:0)
Block(1,13,3,LEAVES:4)
Block(1,13,4,STONE:0)
Block(1,13,5,STONE:0)
Block(1,13,6,STONE:0)
Block(1,13,7,STONE:0)
Block(1,13,8,STONE:0)
Block(1,13,9,STONE:0)
Block(1,14,-10,STONE:0)
Block(1,14,-9,STONE:0)
Block(1,14,-8,STONE:0)
Block(1,14,-7,STONE:0)
Block(1,14,-6,STONE:0)
Block(1,14,-5,STONE:0)
Block(1,14,-4,STONE:0)
Block(1,14,-3,STONE:0)
Block(1,14,-2,STONE:0)
Block(1,14,-1,STONE:0)
Block(1,14,0,STONE:0)
Block(1,14,1,STONE:0)
Block(1,14,2,STONE:0)
Block(1,14,3,STONE:0)
Block(1,14,4,STONE:0)
Block(1,14,5,STONE:0)
Block(1,14,6,STONE:0)
Block(1,14,7,STONE:0)
Block(1,15,-11,STONE:0)
Block(1,15,-10,STONE:0)
Block(1,15,-9,STONE:0)
Block(1,15,-8,biomesoplenty:grass:1)
Block(1,15,-7,STATIONARY_WATER:1)
Block(1,15,-6,STATIONARY_WATER:2)
Block(1,15,-5,STONE:0)
Block(1,15,-4,STONE:0)
Block(1,15,-3,STONE:0)
Block(1,15,-2,STONE:0)
Block(1,15,-1,STONE:0)
Block(1,15,0,STONE:0)
Block(1,15,1,STONE:0)
Block(1,15,2,STONE:0)
Block(1,15,3,STONE:0)
Block(1,15,4,STONE:0)
Block(1,15,5,STONE:0)
Block(1,15,6,STONE:0)
Block(1,16,-14,STONE:0)
Block(1,16,-13,STONE:0)
Block(1,16,-12,STONE:0)
Block(1,16,-11,STONE:0)
Block(1,16,-10,STONE:0)
Block(1,16,-9,STONE:0)
Block(1,16,-8,biomesoplenty:willow_vine:9)
Block(1,16,-7,AIR:0)
Block(1,16,-6,STONE:0)
Block(1,16,-5,STONE:0)
Block(1,16,-4,STONE:0)
Block(1,16,-3,STONE:0)
Block(1,16,-2,STONE:0)
Block(1,16,-1,STONE:0)
Block(1,16,1,STONE:0)
Block(1,16,2,STONE:0)
Block(1,16,3,STONE:0)
Block(1,16,4,STONE:0)
Block(1,16,5,STONE:0)
Block(1,17,-15,STONE:0)
Block(1,17,-14,STONE:0)
Block(1,17,-13,STONE:0)
Block(1,17,-12,biomesoplenty:grass:1)
Block(1,17,-11,biomesoplenty:plant_0:11)
Block(1,17,-10,AIR:0)
Block(1,17,-9,BROWN_MUSHROOM:0)
Block(1,17,-8,biomesoplenty:willow_vine:9)
Block(1,17,-7,STONE:0)
Block(1,17,-6,STONE:0)
Block(1,17,-5,STONE:0)
Block(1,17,-4,STONE:0)
Block(1,17,-3,STONE:0)
Block(1,17,-2,STONE:0)
Block(1,18,-14,AIR:0)
Block(1,18,-13,AIR:0)
Block(1,18,-12,AIR:0)
Block(1,18,-11,AIR:0)
Block(1,18,-10,AIR:0)
Block(1,18,-9,AIR:0)
Block(1,18,-8,biomesoplenty:willow_vine:9)
Block(1,18,-7,STONE:0)
Block(1,18,-6,STONE:0)
Block(1,18,-5,STONE:0)
Block(1,18,-4,STONE:0)
Block(1,18,-3,STONE:0)
Block(1,19,-14,AIR:0)
Block(1,19,-13,AIR:0)
Block(1,19,-12,AIR:0)
Block(1,19,-11,AIR:0)
Block(1,19,-10,AIR:0)
Block(1,19,-9,AIR:0)
Block(1,19,-8,biomesoplenty:willow_vine:9)
Block(1,19,-7,STONE:0)
Block(1,19,-6,STONE:0)
Block(1,19,-5,STONE:0)
Block(1,19,-4,STONE:0)
Block(1,20,-14,AIR:0)
Block(1,20,-13,AIR:0)
Block(1,20,-12,AIR:0)
Block(1,20,-11,AIR:0)
Block(1,20,-10,AIR:0)
Block(1,20,-9,LEAVES:4)
Block(1,20,-8,STONE:0)
Block(1,20,-7,STONE:0)
Block(1,20,-6,STONE:0)
Block(1,20,-5,STONE:0)
Block(1,20,-4,STONE:0)
Block(1,21,-14,AIR:0)
Block(1,21,-13,AIR:0)
Block(1,21,-12,AIR:0)
Block(1,21,-11,AIR:0)
Block(1,21,-10,STONE:0)
Block(1,21,-9,STONE:0)
Block(1,21,-8,STONE:0)
Block(1,21,-7,STONE:0)
Block(1,21,-6,STONE:0)
Block(1,21,-5,STONE:0)
Block(1,22,-15,STONE:0)
Block(1,22,-14,STONE:0)
Block(1,22,-13,STONE:0)
Block(1,22,-12,STONE:0)
Block(1,22,-11,STONE:0)
Block(1,22,-10,STONE:0)
Block(1,22,-9,STONE:0)
Block(1,22,-8,STONE:0)
Block(1,22,-7,STONE:0)
Block(2,2,13,iceandfire:chared_cobblestone)
Block(2,3,3,STONE:0)
Block(2,3,4,STONE:0)
Block(2,3,5,STONE:0)
Block(2,3,9,STONE:0)
Block(2,3,10,STONE:0)
Block(2,3,11,STONE:0)
Block(2,3,12,iceandfire:chared_stone)
Block(2,3,13,STATIONARY_WATER:0)
Block(2,3,14,MAGMA:0)
Block(2,3,15,STONE:0)
Block(2,3,16,STONE:0)
Block(2,4,-2,STONE:0)
Block(2,4,-1,STONE:0)
Block(2,4,0,STONE:0)
Block(2,4,2,STONE:0)
Block(2,4,3,STONE:0)
Block(2,4,4,STONE:0)
Block(2,4,5,STONE:0)
Block(2,4,6,STONE:0)
Block(2,4,8,STONE:0)
Block(2,4,9,STONE:0)
Block(2,4,10,STONE:0)
Block(2,4,11,STONE:0)
Block(2,4,12,biomesoplenty:grass:1)
Block(2,4,13,STATIONARY_WATER:0)
Block(2,4,14,STATIONARY_WATER:0)
Block(2,4,15,iceandfire:chared_cobblestone)
Block(2,4,16,STONE:0)
Block(2,5,-2,STONE:0)
Block(2,5,-1,STONE:0)
Block(2,5,0,STONE:0)
Block(2,5,1,STONE:0)
Block(2,5,2,STONE:0)
Block(2,5,3,STONE:0)
Block(2,5,4,STONE:0)
Block(2,5,5,STONE:0)
Block(2,5,6,STONE:0)
Block(2,5,7,STONE:0)
Block(2,5,8,STONE:0)
Block(2,5,9,STONE:0)
Block(2,5,10,STONE:0)
Block(2,5,11,biomesoplenty:grass:1)
Block(2,5,12,biomesoplenty:flower_0:3)
Block(2,5,13,AIR:0)
Block(2,5,14,AIR:0)
Block(2,5,15,STONE:0)
Block(2,5,16,STONE:0)
Block(2,6,-2,STONE:0)
Block(2,6,-1,STONE:0)
Block(2,6,0,STONE:0)
Block(2,6,1,biomesoplenty:grass:1)
Block(2,6,2,STONE:0)
Block(2,6,3,AIR:0)
Block(2,6,4,quark:leaf_carpet)
Block(2,6,5,biomesoplenty:plant_0:11)
Block(2,6,6,quark:leaf_carpet)
Block(2,6,7,STONE:0)
Block(2,6,8,STONE:0)
Block(2,6,9,STONE:0)
Block(2,6,10,STONE:0)
Block(2,6,11,BROWN_MUSHROOM:0)
Block(2,6,12,AIR:0)
Block(2,6,13,AIR:0)
Block(2,6,14,AIR:0)
Block(2,6,15,STONE:0)
Block(2,6,16,STONE:0)
Block(2,7,-2,STONE:0)
Block(2,7,-1,STONE:0)
Block(2,7,0,STONE:0)
Block(2,7,1,quark:leaf_carpet)
Block(2,7,2,AIR:0)
Block(2,7,3,AIR:0)
Block(2,7,4,AIR:0)
Block(2,7,5,AIR:0)
Block(2,7,6,biomesoplenty:willow_vine:1)
Block(2,7,7,BROWN_MUSHROOM:0)
Block(2,7,8,STONE:0)
Block(2,7,9,STONE:0)
Block(2,7,10,STONE:0)
Block(2,7,11,AIR:0)
Block(2,7,12,STONE:0)
Block(2,7,13,HUGE_MUSHROOM_1:14)
Block(2,7,14,HUGE_MUSHROOM_1:14)
Block(2,7,15,STONE:0)
Block(2,7,16,STONE:0)
Block(2,8,-2,STONE:0)
Block(2,8,-1,STONE:0)
Block(2,8,0,STONE:0)
Block(2,8,1,AIR:0)
Block(2,8,2,AIR:0)
Block(2,8,3,AIR:0)
Block(2,8,4,AIR:0)
Block(2,8,5,AIR:0)
Block(2,8,6,biomesoplenty:willow_vine:1)
Block(2,8,7,biomesoplenty:willow_vine:1)
Block(2,8,8,BROWN_MUSHROOM:0)
Block(2,8,9,STONE:0)
Block(2,8,10,STONE:0)
Block(2,8,11,STONE:0)
Block(2,8,12,STONE:0)
Block(2,8,13,STONE:0)
Block(2,8,14,STONE:0)
Block(2,8,15,STONE:0)
Block(2,8,16,STONE:0)
Block(2,9,-2,STONE:0)
Block(2,9,-1,STONE:0)
Block(2,9,0,STONE:0)
Block(2,9,1,AIR:0)
Block(2,9,2,AIR:0)
Block(2,9,3,AIR:0)
Block(2,9,4,AIR:0)
Block(2,9,5,AIR:0)
Block(2,9,6,biomesoplenty:willow_vine:1)
Block(2,9,7,biomesoplenty:willow_vine:1)
Block(2,9,8,STONE:0)
Block(2,9,9,STONE:0)
Block(2,9,10,STONE:0)
Block(2,9,11,STONE:0)
Block(2,9,12,STONE:0)
Block(2,9,13,STONE:0)
Block(2,9,14,STONE:0)
Block(2,9,15,STONE:0)
Block(2,10,-2,STONE:0)
Block(2,10,-1,STONE:0)
Block(2,10,0,STONE:0)
Block(2,10,1,AIR:0)
Block(2,10,2,AIR:0)
Block(2,10,3,AIR:0)
Block(2,10,4,AIR:0)
Block(2,10,5,AIR:0)
Block(2,10,6,biomesoplenty:willow_vine:1)
Block(2,10,7,STONE:0)
Block(2,10,8,STONE:0)
Block(2,10,9,STONE:0)
Block(2,10,10,STONE:0)
Block(2,10,12,STONE:0)
Block(2,10,13,STONE:0)
Block(2,10,14,STONE:0)
Block(2,11,-2,STONE:0)
Block(2,11,-1,STONE:0)
Block(2,11,0,STONE:0)
Block(2,11,1,HUGE_MUSHROOM_1:14)
Block(2,11,2,AIR:0)
Block(2,11,3,AIR:0)
Block(2,11,4,AIR:0)
Block(2,11,5,AIR:0)
Block(2,11,6,biomesoplenty:willow_vine:1)
Block(2,11,7,STONE:0)
Block(2,11,8,STONE:0)
Block(2,11,9,STONE:0)
Block(2,12,-2,STONE:0)
Block(2,12,-1,STONE:0)
Block(2,12,0,STONE:0)
Block(2,12,1,STONE:0)
Block(2,12,2,AIR:0)
Block(2,12,3,AIR:0)
Block(2,12,4,AIR:0)
Block(2,12,5,AIR:0)
Block(2,12,6,STONE:0)
Block(2,12,7,STONE:0)
Block(2,12,8,STONE:0)
Block(2,12,9,STONE:0)
Block(2,13,-8,STONE:0)
Block(2,13,-5,STONE:0)
Block(2,13,-4,STONE:0)
Block(2,13,-3,STONE:0)
Block(2,13,-2,STONE:0)
Block(2,13,0,STONE:0)
Block(2,13,1,STONE:0)
Block(2,13,2,STONE:0)
Block(2,13,3,STONE:0)
Block(2,13,4,STONE:0)
Block(2,13,5,STONE:0)
Block(2,13,6,STONE:0)
Block(2,13,7,STONE:0)
Block(2,13,8,STONE:0)
Block(2,14,-10,STONE:0)
Block(2,14,-9,STONE:0)
Block(2,14,-8,STONE:0)
Block(2,14,-7,STONE:0)
Block(2,14,-6,STONE:0)
Block(2,14,-5,STONE:0)
Block(2,14,-4,STONE:0)
Block(2,14,-3,STONE:0)
Block(2,14,-2,STONE:0)
Block(2,14,-1,STONE:0)
Block(2,14,0,STONE:0)
Block(2,14,1,STONE:0)
Block(2,14,2,STONE:0)
Block(2,14,3,STONE:0)
Block(2,14,4,STONE:0)
Block(2,14,5,STONE:0)
Block(2,14,6,STONE:0)
Block(2,14,7,STONE:0)
Block(2,15,-12,STONE:0)
Block(2,15,-11,STONE:0)
Block(2,15,-10,STONE:0)
Block(2,15,-9,STONE:0)
Block(2,15,-8,STATIONARY_WATER:13)
Block(2,15,-7,STATIONARY_WATER:14)
Block(2,15,-6,STONE:0)
Block(2,15,-5,STONE:0)
Block(2,15,-4,STONE:0)
Block(2,15,-3,STONE:0)
Block(2,15,-2,STONE:0)
Block(2,15,-1,STONE:0)
Block(2,15,1,STONE:0)
Block(2,15,2,STONE:0)
Block(2,15,3,STONE:0)
Block(2,15,4,STONE:0)
Block(2,15,5,STONE:0)
Block(2,15,6,STONE:0)
Block(2,16,-15,STONE:0)
Block(2,16,-14,STONE:0)
Block(2,16,-13,STONE:0)
Block(2,16,-12,STONE:0)
Block(2,16,-11,STONE:0)
Block(2,16,-10,biomesoplenty:grass:1)
Block(2,16,-9,biomesoplenty:grass:1)
Block(2,16,-8,STATIONARY_WATER:5)
Block(2,16,-7,STATIONARY_WATER:6)
Block(2,16,-6,STONE:0)
Block(2,16,-5,STONE:0)
Block(2,16,-4,STONE:0)
Block(2,16,-3,STONE:0)
Block(2,16,-2,STONE:0)
Block(2,16,-1,STONE:0)
Block(2,16,2,STONE:0)
Block(2,16,3,STONE:0)
Block(2,16,4,STONE:0)
Block(2,17,-15,STONE:0)
Block(2,17,-14,STONE:0)
Block(2,17,-13,STONE:0)
Block(2,17,-12,STONE:0)
Block(2,17,-11,biomesoplenty:willow_vine:8)
Block(2,17,-10,quark:leaf_carpet)
Block(2,17,-9,biomesoplenty:plant_0:11)
Block(2,17,-8,AIR:0)
Block(2,17,-7,STONE:0)
Block(2,17,-6,STONE:0)
Block(2,17,-5,STONE:0)
Block(2,17,-4,STONE:0)
Block(2,17,-3,STONE:0)
Block(2,17,-2,STONE:0)
Block(2,18,-14,AIR:0)
Block(2,18,-13,quark:leaf_carpet)
Block(2,18,-12,biomesoplenty:plant_0:11)
Block(2,18,-11,biomesoplenty:willow_vine:8)
Block(2,18,-10,biomesoplenty:willow_vine:8)
Block(2,18,-9,biomesoplenty:willow_vine:9)
Block(2,18,-8,STONE:0)
Block(2,18,-7,STONE:0)
Block(2,18,-6,STONE:0)
Block(2,18,-5,STONE:0)
Block(2,18,-4,STONE:0)
Block(2,19,-14,AIR:0)
Block(2,19,-13,AIR:0)
Block(2,19,-12,AIR:0)
Block(2,19,-11,biomesoplenty:willow_vine:8)
Block(2,19,-10,biomesoplenty:willow_vine:8)
Block(2,19,-9,biomesoplenty:willow_vine:9)
Block(2,19,-8,STONE:0)
Block(2,19,-7,STONE:0)
Block(2,19,-6,STONE:0)
Block(2,19,-5,STONE:0)
Block(2,20,-14,AIR:0)
Block(2,20,-13,AIR:0)
Block(2,20,-12,AIR:0)
Block(2,20,-11,biomesoplenty:willow_vine:8)
Block(2,20,-10,LEAVES:4)
Block(2,20,-9,STONE:0)
Block(2,20,-8,STONE:0)
Block(2,20,-7,STONE:0)
Block(2,20,-6,STONE:0)
Block(2,20,-5,STONE:0)
Block(2,21,-14,AIR:0)
Block(2,21,-13,AIR:0)
Block(2,21,-12,AIR:0)
Block(2,21,-11,STONE:0)
Block(2,21,-10,STONE:0)
Block(2,21,-9,STONE:0)
Block(2,21,-8,STONE:0)
Block(2,21,-7,STONE:0)
Block(2,22,-15,STONE:0)
Block(2,22,-14,STONE:0)
Block(2,22,-13,STONE:0)
Block(2,22,-12,STONE:0)
Block(2,22,-11,STONE:0)
Block(2,22,-10,STONE:0)
Block(2,22,-9,STONE:0)
Block(3,2,3,STONE:0)
Block(3,2,4,STONE:0)
Block(3,2,5,STONE:0)
Block(3,2,6,STONE:0)
Block(3,3,-2,STONE:0)
Block(3,3,-1,STONE:0)
Block(3,3,0,STONE:0)
Block(3,3,2,STONE:0)
Block(3,3,3,STONE:0)
Block(3,3,4,STONE:0)
Block(3,3,5,STONE:0)
Block(3,3,6,STONE:0)
Block(3,3,7,STONE:0)
Block(3,3,11,STONE:0)
Block(3,3,12,STONE:0)
Block(3,3,13,iceandfire:chared_stone)
Block(3,3,14,STONE:0)
Block(3,3,15,STONE:0)
Block(3,4,-3,STONE:0)
Block(3,4,-2,STONE:0)
Block(3,4,-1,STONE:0)
Block(3,4,0,STONE:0)
Block(3,4,1,STONE:0)
Block(3,4,2,STONE:0)
Block(3,4,3,STONE:0)
Block(3,4,4,STONE:0)
Block(3,4,5,STONE:0)
Block(3,4,6,STONE:0)
Block(3,4,7,STONE:0)
Block(3,4,9,STONE:0)
Block(3,4,10,STONE:0)
Block(3,4,11,STONE:0)
Block(3,4,12,STONE:0)
Block(3,4,13,biomesoplenty:grass:1)
Block(3,4,14,biomesoplenty:grass:1)
Block(3,4,15,STONE:0)
Block(3,4,16,STONE:0)
Block(3,5,-3,STONE:0)
Block(3,5,-2,STONE:0)
Block(3,5,-1,STONE:0)
Block(3,5,0,STONE:0)
Block(3,5,1,STONE:0)
Block(3,5,2,STONE:0)
Block(3,5,3,biomesoplenty:plant_0:11)
Block(3,5,4,quark:leaf_carpet)
Block(3,5,5,biomesoplenty:plant_0:11)
Block(3,5,6,biomesoplenty:grass:1)
Block(3,5,7,STONE:0)
Block(3,5,8,STONE:0)
Block(3,5,9,STONE:0)
Block(3,5,10,STONE:0)
Block(3,5,11,STONE:0)
Block(3,5,12,STONE:0)
Block(3,5,13,biomesoplenty:flower_0:3)
Block(3,5,14,quark:leaf_carpet)
Block(3,5,15,STONE:0)
Block(3,5,16,STONE:0)
Block(3,6,-3,STONE:0)
Block(3,6,-2,STONE:0)
Block(3,6,-1,STONE:0)
Block(3,6,0,STONE:0)
Block(3,6,1,STONE:0)
Block(3,6,2,biomesoplenty:plant_0:11)
Block(3,6,3,AIR:0)
Block(3,6,4,AIR:0)
Block(3,6,5,AIR:0)
Block(3,6,6,AIR:0)
Block(3,6,7,biomesoplenty:grass:1)
Block(3,6,8,STONE:0)
Block(3,6,9,STONE:0)
Block(3,6,10,STONE:0)
Block(3,6,11,STONE:0)
Block(3,6,12,STONE:0)
Block(3,6,13,STONE:0)
Block(3,6,14,STONE:0)
Block(3,6,15,STONE:0)
Block(3,6,16,STONE:0)
Block(3,7,-2,STONE:0)
Block(3,7,-1,STONE:0)
Block(3,7,0,AIR:0)
Block(3,7,1,biomesoplenty:willow_vine:4)
Block(3,7,2,AIR:0)
Block(3,7,3,AIR:0)
Block(3,7,4,AIR:0)
Block(3,7,5,AIR:0)
Block(3,7,6,AIR:0)
Block(3,7,7,biomesoplenty:flower_0:3)
Block(3,7,8,BROWN_MUSHROOM:0)
Block(3,7,9,STONE:0)
Block(3,7,10,STONE:0)
Block(3,7,11,STONE:0)
Block(3,7,12,STONE:0)
Block(3,7,13,STONE:0)
Block(3,7,14,STONE:0)
Block(3,7,15,STONE:0)
Block(3,7,16,STONE:0)
Block(3,8,-2,STONE:0)
Block(3,8,-1,STONE:0)
Block(3,8,0,AIR:0)
Block(3,8,1,biomesoplenty:willow_vine:4)
Block(3,8,2,AIR:0)
Block(3,8,3,AIR:0)
Block(3,8,4,inspirations:rope:2)
Block(3,8,5,AIR:0)
Block(3,8,6,AIR:0)
Block(3,8,7,AIR:0)
Block(3,8,8,AIR:0)
Block(3,8,9,STONE:0)
Block(3,8,10,STONE:0)
Block(3,8,11,STONE:0)
Block(3,8,12,STONE:0)
Block(3,8,13,STONE:0)
Block(3,8,14,STONE:0)
Block(3,9,-2,STONE:0)
Block(3,9,-1,STONE:0)
Block(3,9,0,STONE:0)
Block(3,9,1,biomesoplenty:willow_vine:4)
Block(3,9,2,AIR:0)
Block(3,9,3,AIR:0)
Block(3,9,4,inspirations:rope:2)
Block(3,9,5,AIR:0)
Block(3,9,6,AIR:0)
Block(3,9,7,AIR:0)
Block(3,9,8,LEAVES:4)
Block(3,9,9,STONE:0)
Block(3,9,10,STONE:0)
Block(3,9,11,STONE:0)
Block(3,9,12,STONE:0)
Block(3,9,13,STONE:0)
Block(3,10,-1,STONE:0)
Block(3,10,0,STONE:0)
Block(3,10,1,biomesoplenty:willow_vine:4)
Block(3,10,2,AIR:0)
Block(3,10,3,AIR:0)
Block(3,10,4,inspirations:rope:2)
Block(3,10,5,AIR:0)
Block(3,10,6,AIR:0)
Block(3,10,7,AIR:0)
Block(3,10,8,STONE:0)
Block(3,10,9,STONE:0)
Block(3,10,10,STONE:0)
Block(3,11,-1,STONE:0)
Block(3,11,0,STONE:0)
Block(3,11,1,STONE:0)
Block(3,11,2,AIR:0)
Block(3,11,3,AIR:0)
Block(3,11,4,inspirations:rope:2)
Block(3,11,5,AIR:0)
Block(3,11,6,AIR:0)
Block(3,11,7,AIR:0)
Block(3,11,8,STONE:0)
Block(3,11,9,STONE:0)
Block(3,11,10,STONE:0)
Block(3,12,-1,STONE:0)
Block(3,12,0,STONE:0)
Block(3,12,1,STONE:0)
Block(3,12,2,STONE:0)
Block(3,12,3,AIR:0)
Block(3,12,4,inspirations:rope:2)
Block(3,12,5,AIR:0)
Block(3,12,6,AIR:0)
Block(3,12,7,STONE:0)
Block(3,12,8,STONE:0)
Block(3,12,9,STONE:0)
Block(3,13,0,STONE:0)
Block(3,13,1,STONE:0)
Block(3,13,2,STONE:0)
Block(3,13,3,STONE:0)
Block(3,13,4,STONE:0)
Block(3,13,5,LEAVES:4)
Block(3,13,6,STONE:0)
Block(3,13,7,STONE:0)
Block(3,13,8,STONE:0)
Block(3,14,-10,STONE:0)
Block(3,14,-9,STONE:0)
Block(3,14,-8,STONE:0)
Block(3,14,-7,STONE:0)
Block(3,14,-6,STONE:0)
Block(3,14,-4,STONE:0)
Block(3,14,-3,STONE:0)
Block(3,14,-2,STONE:0)
Block(3,14,1,STONE:0)
Block(3,14,2,STONE:0)
Block(3,14,3,STONE:0)
Block(3,14,4,STONE:0)
Block(3,14,5,STONE:0)
Block(3,14,6,STONE:0)
Block(3,14,7,STONE:0)
Block(3,15,-12,STONE:0)
Block(3,15,-11,STONE:0)
Block(3,15,-10,STONE:0)
Block(3,15,-9,STONE:0)
Block(3,15,-8,STONE:0)
Block(3,15,-7,STONE:0)
Block(3,15,-6,STONE:0)
Block(3,15,-5,STONE:0)
Block(3,15,-4,STONE:0)
Block(3,15,-3,STONE:0)
Block(3,15,-2,STONE:0)
Block(3,15,4,STONE:0)
Block(3,15,5,STONE:0)
Block(3,15,6,STONE:0)
Block(3,16,-15,STONE:0)
Block(3,16,-14,STONE:0)
Block(3,16,-13,STONE:0)
Block(3,16,-12,STONE:0)
Block(3,16,-11,biomesoplenty:grass:1)
Block(3,16,-10,biomesoplenty:grass:1)
Block(3,16,-9,STATIONARY_WATER:3)
Block(3,16,-8,STATIONARY_WATER:4)
Block(3,16,-7,STONE:0)
Block(3,16,-6,STONE:0)
Block(3,16,-5,STONE:0)
Block(3,16,-4,STONE:0)
Block(3,16,-3,STONE:0)
Block(3,16,-2,STONE:0)
Block(3,17,-15,STONE:0)
Block(3,17,-14,STONE:0)
Block(3,17,-13,biomesoplenty:grass:1)
Block(3,17,-12,biomesoplenty:grass:1)
Block(3,17,-11,BROWN_MUSHROOM:0)
Block(3,17,-10,biomesoplenty:plant_0:11)
Block(3,17,-9,AIR:0)
Block(3,17,-8,AIR:0)
Block(3,17,-7,STONE:0)
Block(3,17,-6,STONE:0)
Block(3,17,-5,STONE:0)
Block(3,17,-4,STONE:0)
Block(3,18,-15,STONE:0)
Block(3,18,-14,STONE:0)
Block(3,18,-13,BROWN_MUSHROOM:0)
Block(3,18,-12,quark:leaf_carpet)
Block(3,18,-11,AIR:0)
Block(3,18,-10,AIR:0)
Block(3,18,-9,STONE:0)
Block(3,18,-8,STONE:0)
Block(3,18,-7,STONE:0)
Block(3,18,-6,STONE:0)
Block(3,19,-15,STONE:0)
Block(3,19,-14,STONE:0)
Block(3,19,-13,AIR:0)
Block(3,19,-12,AIR:0)
Block(3,19,-11,AIR:0)
Block(3,19,-10,LEAVES:4)
Block(3,19,-9,LEAVES:4)
Block(3,19,-8,STONE:0)
Block(3,19,-7,STONE:0)
Block(3,20,-15,STONE:0)
Block(3,20,-14,AIR:0)
Block(3,20,-13,AIR:0)
Block(3,20,-12,AIR:0)
Block(3,20,-11,LEAVES:4)
Block(3,20,-10,STONE:0)
Block(3,20,-9,STONE:0)
Block(3,20,-8,STONE:0)
Block(3,20,-7,STONE:0)
Block(3,21,-15,STONE:0)
Block(3,21,-14,STONE:0)
Block(3,21,-13,AIR:0)
Block(3,21,-12,AIR:0)
Block(3,21,-11,STONE:0)
Block(3,21,-10,STONE:0)
Block(3,21,-9,STONE:0)
Block(3,22,-15,STONE:0)
Block(3,22,-14,STONE:0)
Block(3,22,-13,STONE:0)
Block(3,22,-12,STONE:0)
Block(3,22,-11,STONE:0)
Block(3,22,-10,STONE:0)
Block(4,2,1,STONE:0)
Block(4,2,2,STONE:0)
Block(4,2,3,STONE:0)
Block(4,2,4,STONE:0)
Block(4,2,5,STONE:0)
Block(4,2,6,STONE:0)
Block(4,2,7,STONE:0)
Block(4,3,-2,STONE:0)
Block(4,3,-1,STONE:0)
Block(4,3,0,STONE:0)
Block(4,3,1,STONE:0)
Block(4,3,2,STONE:0)
Block(4,3,3,STONE:0)
Block(4,3,4,STONE:0)
Block(4,3,5,STONE:0)
Block(4,3,6,STONE:0)
Block(4,3,7,STONE:0)
Block(4,3,12,STONE:0)
Block(4,3,13,STONE:0)
Block(4,3,14,STONE:0)
Block(4,3,15,STONE:0)
Block(4,4,-3,STONE:0)
Block(4,4,-2,STONE:0)
Block(4,4,-1,STONE:0)
Block(4,4,0,STONE:0)
Block(4,4,1,STONE:0)
Block(4,4,2,STONE:0)
Block(4,4,3,STONE:0)
Block(4,4,4,biomesoplenty:grass:1)
Block(4,4,5,STONE:0)
Block(4,4,6,STONE:0)
Block(4,4,7,STONE:0)
Block(4,4,8,STONE:0)
Block(4,4,9,STONE:0)
Block(4,4,11,STONE:0)
Block(4,4,12,STONE:0)
Block(4,4,13,STONE:0)
Block(4,4,14,STONE:0)
Block(4,4,15,STONE:0)
Block(4,4,16,STONE:0)
Block(4,5,-5,STONE:0)
Block(4,5,-4,STONE:0)
Block(4,5,-3,STONE:0)
Block(4,5,-2,STONE:0)
Block(4,5,-1,STONE:0)
Block(4,5,0,STONE:0)
Block(4,5,1,biomesoplenty:grass:1)
Block(4,5,2,STONE:0)
Block(4,5,3,quark:leaf_carpet)
Block(4,5,4,AIR:0)
Block(4,5,5,biomesoplenty:plant_0:11)
Block(4,5,6,quark:leaf_carpet)
Block(4,5,7,STONE:0)
Block(4,5,8,STONE:0)
Block(4,5,9,STONE:0)
Block(4,5,10,STONE:0)
Block(4,5,11,STONE:0)
Block(4,5,12,STONE:0)
Block(4,5,13,STONE:0)
Block(4,5,14,STONE:0)
Block(4,5,15,STONE:0)
Block(4,5,16,STONE:0)
Block(4,6,-5,STONE:0)
Block(4,6,-4,STONE:0)
Block(4,6,-3,STONE:0)
Block(4,6,-2,STONE:0)
Block(4,6,-1,STONE:0)
Block(4,6,0,BROWN_MUSHROOM:0)
Block(4,6,1,AIR:0)
Block(4,6,2,quark:leaf_carpet)
Block(4,6,3,AIR:0)
Block(4,6,4,AIR:0)
Block(4,6,5,AIR:0)
Block(4,6,6,AIR:0)
Block(4,6,7,quark:leaf_carpet)
Block(4,6,8,STONE:0)
Block(4,6,9,STONE:0)
Block(4,6,10,STONE:0)
Block(4,6,11,STONE:0)
Block(4,6,12,STONE:0)
Block(4,6,13,STONE:0)
Block(4,6,14,STONE:0)
Block(4,6,15,STONE:0)
Block(4,6,16,STONE:0)
Block(4,7,-5,STONE:0)
Block(4,7,-4,STONE:0)
Block(4,7,-3,STONE:0)
Block(4,7,-2,STONE:0)
Block(4,7,-1,AIR:0)
Block(4,7,0,AIR:0)
Block(4,7,1,AIR:0)
Block(4,7,2,AIR:0)
Block(4,7,3,AIR:0)
Block(4,7,4,AIR:0)
Block(4,7,5,AIR:0)
Block(4,7,6,AIR:0)
Block(4,7,7,AIR:0)
Block(4,7,8,AIR:0)
Block(4,7,9,biomesoplenty:flower_1:3)
Block(4,7,10,STONE:0)
Block(4,7,11,STONE:0)
Block(4,7,12,STONE:0)
Block(4,7,13,STONE:0)
Block(4,7,14,STONE:0)
Block(4,7,15,STONE:0)
Block(4,8,-2,STONE:0)
Block(4,8,-1,AIR:0)
Block(4,8,0,AIR:0)
Block(4,8,1,AIR:0)
Block(4,8,2,AIR:0)
Block(4,8,3,AIR:0)
Block(4,8,4,AIR:0)
Block(4,8,5,AIR:0)
Block(4,8,6,AIR:0)
Block(4,8,7,AIR:0)
Block(4,8,8,AIR:0)
Block(4,8,9,AIR:0)
Block(4,8,10,STONE:0)
Block(4,8,11,STONE:0)
Block(4,8,12,STONE:0)
Block(4,8,13,STONE:0)
Block(4,9,-2,STONE:0)
Block(4,9,-1,STONE:0)
Block(4,9,0,AIR:0)
Block(4,9,1,AIR:0)
Block(4,9,2,AIR:0)
Block(4,9,3,AIR:0)
Block(4,9,4,AIR:0)
Block(4,9,5,AIR:0)
Block(4,9,6,AIR:0)
Block(4,9,7,AIR:0)
Block(4,9,8,AIR:0)
Block(4,9,9,LEAVES:4)
Block(4,9,10,STONE:0)
Block(4,9,11,STONE:0)
Block(4,10,-2,STONE:0)
Block(4,10,-1,STONE:0)
Block(4,10,0,STONE:0)
Block(4,10,1,AIR:0)
Block(4,10,2,AIR:0)
Block(4,10,3,AIR:0)
Block(4,10,4,AIR:0)
Block(4,10,5,AIR:0)
Block(4,10,6,LEAVES:4)
Block(4,10,7,AIR:0)
Block(4,10,8,STONE:0)
Block(4,10,9,STONE:0)
Block(4,10,10,STONE:0)
Block(4,11,-1,STONE:0)
Block(4,11,0,STONE:0)
Block(4,11,1,STONE:0)
Block(4,11,2,AIR:0)
Block(4,11,3,AIR:0)
Block(4,11,4,AIR:0)
Block(4,11,5,AIR:0)
Block(4,11,6,LEAVES:4)
Block(4,11,7,AIR:0)
Block(4,11,8,STONE:0)
Block(4,11,9,STONE:0)
Block(4,11,10,STONE:0)
Block(4,12,-1,STONE:0)
Block(4,12,0,STONE:0)
Block(4,12,1,STONE:0)
Block(4,12,2,LEAVES:12)
Block(4,12,3,LEAVES:12)
Block(4,12,4,AIR:0)
Block(4,12,5,AIR:0)
Block(4,12,6,LEAVES:4)
Block(4,12,7,STONE:0)
Block(4,12,8,STONE:0)
Block(4,12,9,STONE:0)
Block(4,12,10,STONE:0)
Block(4,13,0,STONE:0)
Block(4,13,1,STONE:0)
Block(4,13,2,STONE:0)
Block(4,13,3,STONE:0)
Block(4,13,4,LEAVES:4)
Block(4,13,5,LEAVES:4)
Block(4,13,6,LEAVES:4)
Block(4,13,7,STONE:0)
Block(4,13,8,STONE:0)
Block(4,13,9,STONE:0)
Block(4,14,-9,STONE:0)
Block(4,14,-8,STONE:0)
Block(4,14,-7,STONE:0)
Block(4,14,2,STONE:0)
Block(4,14,3,STONE:0)
Block(4,14,4,STONE:0)
Block(4,14,5,STONE:0)
Block(4,14,6,LEAVES:4)
Block(4,14,7,STONE:0)
Block(4,14,8,STONE:0)
Block(4,15,-12,STONE:0)
Block(4,15,-11,STONE:0)
Block(4,15,-10,STONE:0)
Block(4,15,-9,STONE:0)
Block(4,15,-8,STONE:0)
Block(4,15,-7,STONE:0)
Block(4,15,-6,STONE:0)
Block(4,15,3,STONE:0)
Block(4,15,4,STONE:0)
Block(4,15,5,STONE:0)
Block(4,15,6,STONE:0)
Block(4,16,-14,STONE:0)
Block(4,16,-13,STONE:0)
Block(4,16,-12,STONE:0)
Block(4,16,-11,STONE:0)
Block(4,16,-10,STONE:0)
Block(4,16,-9,STATIONARY_WATER:2)
Block(4,16,-8,STONE:0)
Block(4,16,-7,STONE:0)
Block(4,16,-6,STONE:0)
Block(4,17,-15,STONE:0)
Block(4,17,-14,STONE:0)
Block(4,17,-13,STONE:0)
Block(4,17,-12,STONE:0)
Block(4,17,-11,biomesoplenty:grass:1)
Block(4,17,-10,BROWN_MUSHROOM:0)
Block(4,17,-9,AIR:0)
Block(4,17,-8,STONE:0)
Block(4,17,-7,STONE:0)
Block(4,17,-6,STONE:0)
Block(4,18,-14,STONE:0)
Block(4,18,-13,STONE:0)
Block(4,18,-12,biomesoplenty:grass:1)
Block(4,18,-11,BROWN_MUSHROOM:0)
Block(4,18,-10,AIR:0)
Block(4,18,-9,STONE:0)
Block(4,18,-8,STONE:0)
Block(4,18,-7,STONE:0)
Block(4,19,-14,STONE:0)
Block(4,19,-13,biomesoplenty:grass:1)
Block(4,19,-12,AIR:0)
Block(4,19,-11,AIR:0)
Block(4,19,-10,STONE:0)
Block(4,19,-9,STONE:0)
Block(4,19,-8,STONE:0)
Block(4,19,-7,STONE:0)
Block(4,20,-15,STONE:0)
Block(4,20,-14,STONE:0)
Block(4,20,-13,AIR:0)
Block(4,20,-12,AIR:0)
Block(4,20,-11,STONE:0)
Block(4,20,-10,STONE:0)
Block(4,20,-9,STONE:0)
Block(4,20,-8,STONE:0)
Block(4,21,-14,STONE:0)
Block(4,21,-13,STONE:0)
Block(4,21,-12,STONE:0)
Block(4,21,-11,STONE:0)
Block(4,21,-10,STONE:0)
Block(4,22,-14,STONE:0)
Block(4,22,-13,STONE:0)
Block(4,22,-12,STONE:0)
Block(4,22,-11,STONE:0)
Block(4,22,-10,STONE:0)
Block(5,1,0,STONE:0)
Block(5,1,1,STONE:0)
Block(5,1,2,STONE:0)
Block(5,1,5,STONE:0)
Block(5,1,6,STONE:0)
Block(5,1,7,STONE:0)
Block(5,2,-1,STONE:0)
Block(5,2,0,STONE:0)
Block(5,2,1,STONE:0)
Block(5,2,2,STONE:0)
Block(5,2,3,STONE:0)
Block(5,2,4,STONE:0)
Block(5,2,5,STONE:0)
Block(5,2,6,STONE:0)
Block(5,2,7,STONE:0)
Block(5,2,8,STONE:0)
Block(5,3,-6,STONE:0)
Block(5,3,-5,STONE:0)
Block(5,3,-4,STONE:0)
Block(5,3,-2,STONE:0)
Block(5,3,-1,STONE:0)
Block(5,3,0,STONE:0)
Block(5,3,1,STONE:0)
Block(5,3,2,STONE:0)
Block(5,3,3,biomesoplenty:grass:1)
Block(5,3,4,biomesoplenty:grass:1)
Block(5,3,5,STONE:0)
Block(5,3,6,STONE:0)
Block(5,3,7,STONE:0)
Block(5,3,8,STONE:0)
Block(5,3,9,STONE:0)
Block(5,3,10,STONE:0)
Block(5,4,-6,STONE:0)
Block(5,4,-5,STONE:0)
Block(5,4,-4,STONE:0)
Block(5,4,-3,STONE:0)
Block(5,4,-2,STONE:0)
Block(5,4,-1,STONE:0)
Block(5,4,0,STONE:0)
Block(5,4,1,STONE:0)
Block(5,4,2,STONE:0)
Block(5,4,3,AIR:0)
Block(5,4,4,quark:leaf_carpet)
Block(5,4,5,biomesoplenty:grass:1)
Block(5,4,6,STONE:0)
Block(5,4,7,STONE:0)
Block(5,4,8,STONE:0)
Block(5,4,9,STONE:0)
Block(5,4,10,STONE:0)
Block(5,4,11,STONE:0)
Block(5,4,12,STONE:0)
Block(5,4,13,STONE:0)
Block(5,4,14,STONE:0)
Block(5,4,15,STONE:0)
Block(5,5,-6,STONE:0)
Block(5,5,-5,STONE:0)
Block(5,5,-4,STONE:0)
Block(5,5,-3,STONE:0)
Block(5,5,-2,STONE:0)
Block(5,5,-1,STONE:0)
Block(5,5,0,LEAVES:4)
Block(5,5,1,BROWN_MUSHROOM:0)
Block(5,5,2,BROWN_MUSHROOM:0)
Block(5,5,3,AIR:0)
Block(5,5,4,AIR:0)
Block(5,5,5,AIR:0)
Block(5,5,6,BROWN_MUSHROOM:0)
Block(5,5,7,biomesoplenty:grass:1)
Block(5,5,8,STONE:0)
Block(5,5,9,STONE:0)
Block(5,5,10,STONE:0)
Block(5,5,11,STONE:0)
Block(5,5,12,STONE:0)
Block(5,5,13,STONE:0)
Block(5,5,14,STONE:0)
Block(5,5,15,STONE:0)
Block(5,6,-6,STONE:0)
Block(5,6,-5,STONE:0)
Block(5,6,-4,STONE:0)
Block(5,6,-3,STONE:0)
Block(5,6,-2,STONE:0)
Block(5,6,-1,BROWN_MUSHROOM:0)
Block(5,6,0,biomesoplenty:willow_vine:4)
Block(5,6,1,AIR:0)
Block(5,6,2,AIR:0)
Block(5,6,3,AIR:0)
Block(5,6,4,AIR:0)
Block(5,6,5,AIR:0)
Block(5,6,6,AIR:0)
Block(5,6,7,quark:leaf_carpet)
Block(5,6,8,LEAVES:4)
Block(5,6,9,STONE:0)
Block(5,6,10,STONE:0)
Block(5,6,11,STONE:0)
Block(5,6,12,STONE:0)
Block(5,6,13,STONE:0)
Block(5,6,14,STONE:0)
Block(5,6,15,STONE:0)
Block(5,7,-6,STONE:0)
Block(5,7,-5,STONE:0)
Block(5,7,-4,STONE:0)
Block(5,7,-3,STONE:0)
Block(5,7,-2,STONE:0)
Block(5,7,-1,AIR:0)
Block(5,7,0,biomesoplenty:willow_vine:4)
Block(5,7,1,AIR:0)
Block(5,7,2,AIR:0)
Block(5,7,3,AIR:0)
Block(5,7,4,AIR:0)
Block(5,7,5,AIR:0)
Block(5,7,6,AIR:0)
Block(5,7,7,AIR:0)
Block(5,7,8,AIR:0)
Block(5,7,9,STONE:0)
Block(5,7,10,STONE:0)
Block(5,7,11,STONE:0)
Block(5,7,12,STONE:0)
Block(5,8,-5,STONE:0)
Block(5,8,-4,STONE:0)
Block(5,8,-3,STONE:0)
Block(5,8,-2,STONE:0)
Block(5,8,-1,AIR:0)
Block(5,8,0,biomesoplenty:willow_vine:4)
Block(5,8,1,AIR:0)
Block(5,8,2,AIR:0)
Block(5,8,3,AIR:0)
Block(5,8,4,AIR:0)
Block(5,8,5,AIR:0)
Block(5,8,6,AIR:0)
Block(5,8,7,AIR:0)
Block(5,8,8,AIR:0)
Block(5,8,9,AIR:0)
Block(5,8,10,STONE:0)
Block(5,8,11,STONE:0)
Block(5,8,12,STONE:0)
Block(5,9,-2,STONE:0)
Block(5,9,-1,STONE:0)
Block(5,9,0,biomesoplenty:willow_vine:4)
Block(5,9,1,AIR:0)
Block(5,9,2,AIR:0)
Block(5,9,3,AIR:0)
Block(5,9,4,AIR:0)
Block(5,9,5,AIR:0)
Block(5,9,6,AIR:0)
Block(5,9,7,AIR:0)
Block(5,9,8,AIR:0)
Block(5,9,9,LEAVES:4)
Block(5,9,10,STONE:0)
Block(5,9,11,STONE:0)
Block(5,10,-2,STONE:0)
Block(5,10,-1,STONE:0)
Block(5,10,0,biomesoplenty:willow_vine:4)
Block(5,10,1,AIR:0)
Block(5,10,2,AIR:0)
Block(5,10,3,AIR:0)
Block(5,10,4,AIR:0)
Block(5,10,5,AIR:0)
Block(5,10,6,AIR:0)
Block(5,10,7,AIR:0)
Block(5,10,8,STONE:0)
Block(5,10,9,STONE:0)
Block(5,10,10,STONE:0)
Block(5,10,11,STONE:0)
Block(5,11,-1,STONE:0)
Block(5,11,0,STONE:0)
Block(5,11,1,LEAVES:12)
Block(5,11,2,LEAVES:12)
Block(5,11,3,AIR:0)
Block(5,11,4,AIR:0)
Block(5,11,5,AIR:0)
Block(5,11,6,AIR:0)
Block(5,11,7,AIR:0)
Block(5,11,8,STONE:0)
Block(5,11,9,STONE:0)
Block(5,11,10,STONE:0)
Block(5,12,-1,STONE:0)
Block(5,12,0,STONE:0)
Block(5,12,1,LEAVES:4)
Block(5,12,2,STONE:0)
Block(5,12,3,LEAVES:4)
Block(5,12,4,AIR:0)
Block(5,12,5,LEAVES:12)
Block(5,12,6,STONE:0)
Block(5,12,7,STONE:0)
Block(5,12,8,STONE:0)
Block(5,12,9,STONE:0)
Block(5,12,10,STONE:0)
Block(5,13,0,STONE:0)
Block(5,13,1,STONE:0)
Block(5,13,2,STONE:0)
Block(5,13,3,STONE:0)
Block(5,13,4,LEAVES:12)
Block(5,13,5,STONE:0)
Block(5,13,6,STONE:0)
Block(5,13,7,STONE:0)
Block(5,13,8,STONE:0)
Block(5,13,9,STONE:0)
Block(5,14,2,STONE:0)
Block(5,14,3,STONE:0)
Block(5,14,4,STONE:0)
Block(5,14,5,STONE:0)
Block(5,14,6,STONE:0)
Block(5,14,7,STONE:0)
Block(5,14,8,STONE:0)
Block(5,15,-11,STONE:0)
Block(5,15,-10,STONE:0)
Block(5,15,-9,STONE:0)
Block(5,15,3,STONE:0)
Block(5,15,4,STONE:0)
Block(5,15,5,STONE:0)
Block(5,15,6,STONE:0)
Block(5,16,-12,STONE:0)
Block(5,16,-11,STONE:0)
Block(5,16,-10,STATIONARY_WATER:9)
Block(5,16,-9,STATIONARY_WATER:1)
Block(5,16,-8,STONE:0)
Block(5,17,-14,STONE:0)
Block(5,17,-13,STONE:0)
Block(5,17,-12,STONE:0)
Block(5,17,-11,STATIONARY_WATER:10)
Block(5,17,-10,STATIONARY_WATER:1)
Block(5,17,-9,AIR:0)
Block(5,17,-8,STONE:0)
Block(5,18,-14,STONE:0)
Block(5,18,-13,STONE:0)
Block(5,18,-12,STATIONARY_WATER:1)
Block(5,18,-11,STATIONARY_WATER:2)
Block(5,18,-10,AIR:0)
Block(5,18,-9,STONE:0)
Block(5,18,-8,STONE:0)
Block(5,19,-14,STONE:0)
Block(5,19,-13,STONE:0)
Block(5,19,-12,AIR:0)
Block(5,19,-11,STONE:0)
Block(5,19,-10,STONE:0)
Block(5,19,-9,STONE:0)
Block(5,20,-14,STONE:0)
Block(5,20,-13,AIR:0)
Block(5,20,-12,AIR:0)
Block(5,20,-11,STONE:0)
Block(5,20,-10,STONE:0)
Block(5,20,-9,STONE:0)
Block(5,21,-14,STONE:0)
Block(5,21,-13,STONE:0)
Block(5,21,-12,STONE:0)
Block(5,21,-11,STONE:0)
Block(5,21,-10,STONE:0)
Block(5,22,-14,STONE:0)
Block(5,22,-13,STONE:0)
Block(5,22,-12,STONE:0)
Block(5,22,-11,STONE:0)
Block(6,1,-1,STONE:0)
Block(6,1,0,STONE:0)
Block(6,1,1,STONE:0)
Block(6,1,2,STONE:0)
Block(6,1,3,STONE:0)
Block(6,1,5,STONE:0)
Block(6,1,6,STONE:0)
Block(6,1,7,STONE:0)
Block(6,1,8,AIR:0)
Block(6,1,9,AIR:0)
Block(6,2,-6,STONE:0)
Block(6,2,-5,STONE:0)
Block(6,2,-4,STONE:0)
Block(6,2,-3,STONE:0)
Block(6,2,-1,STONE:0)
Block(6,2,0,STONE:0)
Block(6,2,1,STONE:0)
Block(6,2,2,STONE:0)
Block(6,2,3,STONE:0)
Block(6,2,4,STONE:0)
Block(6,2,5,STONE:0)
Block(6,2,6,STONE:0)
Block(6,2,7,STONE:0)
Block(6,2,8,STONE:0)
Block(6,2,9,AIR:0)
Block(6,2,10,STONE:0)
Block(6,3,-7,STONE:0)
Block(6,3,-6,STONE:0)
Block(6,3,-5,STONE:0)
Block(6,3,-4,STONE:0)
Block(6,3,-3,STONE:0)
Block(6,3,-2,STONE:0)
Block(6,3,-1,biomesoplenty:grass:1)
Block(6,3,0,biomesoplenty:grass:1)
Block(6,3,1,biomesoplenty:grass:1)
Block(6,3,2,STONE:0)
Block(6,3,3,iceandfire:chared_stone)
Block(6,3,4,STONE:0)
Block(6,3,5,biomesoplenty:grass:1)
Block(6,3,6,STONE:0)
Block(6,3,7,STONE:0)
Block(6,3,8,STONE:0)
Block(6,3,9,STONE:0)
Block(6,3,10,STONE:0)
Block(6,3,11,STONE:0)
Block(6,3,12,STONE:0)
Block(6,3,13,STONE:0)
Block(6,4,-7,STONE:0)
Block(6,4,-6,STONE:0)
Block(6,4,-5,STONE:0)
Block(6,4,-4,STONE:0)
Block(6,4,-3,quark:leaf_carpet)
Block(6,4,-2,rustic:iron_lattice:0)
Block(6,4,-1,LEAVES:4)
Block(6,4,0,quark:leaf_carpet)
Block(6,4,1,BROWN_MUSHROOM:0)
Block(6,4,2,quark:leaf_carpet)
Block(6,4,3,AIR:0)
Block(6,4,4,quark:leaf_carpet)
Block(6,4,5,BROWN_MUSHROOM:0)
Block(6,4,6,AIR:0)
Block(6,4,7,AIR:0)
Block(6,4,8,rustic:iron_lattice:0)
Block(6,4,9,quark:leaf_carpet)
Block(6,4,10,AIR:0)
Block(6,4,11,AIR:0)
Block(6,4,12,STONE:0)
Block(6,4,13,STONE:0)
Block(6,4,14,STONE:0)
Block(6,5,-7,STONE:0)
Block(6,5,-6,STONE:0)
Block(6,5,-5,STONE:0)
Block(6,5,-4,STONE:0)
Block(6,5,-3,STONE:0)
Block(6,5,-2,rustic:iron_lattice:0)
Block(6,5,-1,AIR:0)
Block(6,5,0,AIR:0)
Block(6,5,1,AIR:0)
Block(6,5,2,AIR:0)
Block(6,5,3,AIR:0)
Block(6,5,4,AIR:0)
Block(6,5,5,AIR:0)
Block(6,5,6,AIR:0)
Block(6,5,7,AIR:0)
Block(6,5,8,rustic:iron_lattice:0)
Block(6,5,9,AIR:0)
Block(6,5,10,AIR:0)
Block(6,5,11,AIR:0)
Block(6,5,12,STONE:0)
Block(6,5,13,STONE:0)
Block(6,5,14,STONE:0)
Block(6,6,-6,STONE:0)
Block(6,6,-5,STONE:0)
Block(6,6,-4,STONE:0)
Block(6,6,-3,STONE:0)
Block(6,6,-2,STONE:0)
Block(6,6,-1,AIR:0)
Block(6,6,0,AIR:0)
Block(6,6,1,AIR:0)
Block(6,6,2,AIR:0)
Block(6,6,3,AIR:0)
Block(6,6,4,AIR:0)
Block(6,6,5,AIR:0)
Block(6,6,6,AIR:0)
Block(6,6,7,AIR:0)
Block(6,6,8,STONE:0)
Block(6,6,9,AIR:0)
Block(6,6,10,STONE:0)
Block(6,6,11,STONE:0)
Block(6,6,12,STONE:0)
Block(6,6,13,STONE:0)
Block(6,6,14,STONE:0)
Block(6,7,-6,STONE:0)
Block(6,7,-5,STONE:0)
Block(6,7,-4,STONE:0)
Block(6,7,-3,STONE:0)
Block(6,7,-2,STONE:0)
Block(6,7,-1,AIR:0)
Block(6,7,0,AIR:0)
Block(6,7,1,AIR:0)
Block(6,7,2,AIR:0)
Block(6,7,3,AIR:0)
Block(6,7,4,AIR:0)
Block(6,7,5,AIR:0)
Block(6,7,6,AIR:0)
Block(6,7,7,AIR:0)
Block(6,7,8,STONE:0)
Block(6,7,9,STONE:0)
Block(6,7,10,STONE:0)
Block(6,7,11,STONE:0)
Block(6,7,12,STONE:0)
Block(6,7,13,STONE:0)
Block(6,8,-5,STONE:0)
Block(6,8,-4,STONE:0)
Block(6,8,-3,STONE:0)
Block(6,8,-2,STONE:0)
Block(6,8,-1,AIR:0)
Block(6,8,0,AIR:0)
Block(6,8,1,AIR:0)
Block(6,8,2,AIR:0)
Block(6,8,3,AIR:0)
Block(6,8,4,AIR:0)
Block(6,8,5,AIR:0)
Block(6,8,6,AIR:0)
Block(6,8,7,AIR:0)
Block(6,8,8,AIR:0)
Block(6,8,9,AIR:0)
Block(6,8,10,STONE:0)
Block(6,8,11,STONE:0)
Block(6,9,-3,STONE:0)
Block(6,9,-2,STONE:0)
Block(6,9,-1,STONE:0)
Block(6,9,0,AIR:0)
Block(6,9,1,AIR:0)
Block(6,9,2,AIR:0)
Block(6,9,3,AIR:0)
Block(6,9,4,AIR:0)
Block(6,9,5,AIR:0)
Block(6,9,6,AIR:0)
Block(6,9,7,AIR:0)
Block(6,9,8,AIR:0)
Block(6,9,9,LEAVES:4)
Block(6,9,10,STONE:0)
Block(6,10,-2,STONE:0)
Block(6,10,-1,STONE:0)
Block(6,10,0,STONE:0)
Block(6,10,1,AIR:0)
Block(6,10,2,AIR:0)
Block(6,10,3,AIR:0)
Block(6,10,4,AIR:0)
Block(6,10,5,AIR:0)
Block(6,10,6,AIR:0)
Block(6,10,7,AIR:0)
Block(6,10,8,LEAVES:4)
Block(6,10,9,STONE:0)
Block(6,10,10,STONE:0)
Block(6,10,11,STONE:0)
Block(6,11,-1,STONE:0)
Block(6,11,0,STONE:0)
Block(6,11,1,STONE:0)
Block(6,11,2,STONE:0)
Block(6,11,3,LEAVES:4)
Block(6,11,4,AIR:0)
Block(6,11,5,AIR:0)
Block(6,11,6,AIR:0)
Block(6,11,7,AIR:0)
Block(6,11,8,STONE:0)
Block(6,11,9,STONE:0)
Block(6,11,10,STONE:0)
Block(6,12,0,STONE:0)
Block(6,12,1,STONE:0)
Block(6,12,2,STONE:0)
Block(6,12,3,LEAVES:4)
Block(6,12,4,AIR:0)
Block(6,12,5,AIR:0)
Block(6,12,6,STONE:0)
Block(6,12,7,STONE:0)
Block(6,12,8,STONE:0)
Block(6,12,9,STONE:0)
Block(6,12,10,STONE:0)
Block(6,13,1,STONE:0)
Block(6,13,2,STONE:0)
Block(6,13,3,STONE:0)
Block(6,13,4,LEAVES:4)
Block(6,13,5,LEAVES:12)
Block(6,13,6,STONE:0)
Block(6,13,7,STONE:0)
Block(6,13,8,STONE:0)
Block(6,13,9,STONE:0)
Block(6,13,10,STONE:0)
Block(6,14,2,STONE:0)
Block(6,14,3,STONE:0)
Block(6,14,4,STONE:0)
Block(6,14,5,STONE:0)
Block(6,14,6,STONE:0)
Block(6,14,7,STONE:0)
Block(6,14,8,STONE:0)
Block(6,15,-11,STONE:0)
Block(6,15,-10,STONE:0)
Block(6,15,-9,STONE:0)
Block(6,15,3,STONE:0)
Block(6,15,4,STONE:0)
Block(6,15,5,STONE:0)
Block(6,16,-12,STONE:0)
Block(6,16,-11,STONE:0)
Block(6,16,-10,STONE:0)
Block(6,16,-9,STONE:0)
Block(6,16,-8,STONE:0)
Block(6,17,-12,STONE:0)
Block(6,17,-11,STONE:0)
Block(6,17,-10,STONE:0)
Block(6,17,-9,STONE:0)
Block(6,17,-8,STONE:0)
Block(6,18,-14,STONE:0)
Block(6,18,-13,STONE:0)
Block(6,18,-12,STATIONARY_WATER:9)
Block(6,18,-11,STONE:0)
Block(6,18,-10,STONE:0)
Block(6,18,-9,STONE:0)
Block(6,18,-8,STONE:0)
Block(6,19,-14,STONE:0)
Block(6,19,-13,STATIONARY_WATER:10)
Block(6,19,-12,STATIONARY_WATER:1)
Block(6,19,-11,STONE:0)
Block(6,19,-10,STONE:0)
Block(6,19,-9,STONE:0)
Block(6,20,-14,STONE:0)
Block(6,20,-13,STATIONARY_WATER:10)
Block(6,20,-12,STONE:0)
Block(6,20,-11,STONE:0)
Block(6,20,-10,STONE:0)
Block(6,20,-9,STONE:0)
Block(6,21,-14,STONE:0)
Block(6,21,-13,STATIONARY_WATER:2)
Block(6,21,-12,STONE:0)
Block(6,21,-11,STONE:0)
Block(6,21,-10,STONE:0)
Block(6,22,-14,STONE:0)
Block(6,22,-13,STONE:0)
Block(6,22,-12,STONE:0)
Block(6,22,-11,STONE:0)
Block(7,0,1,STONE:0)
Block(7,1,-5,STONE:0)
Block(7,1,-4,STONE:0)
Block(7,1,-3,STONE:0)
Block(7,1,-1,STONE:0)
Block(7,1,0,STONE:0)
Block(7,1,1,STONE:0)
Block(7,1,2,STONE:0)
Block(7,1,3,STONE:0)
Block(7,1,4,STONE:0)
Block(7,1,5,STONE:0)
Block(7,1,6,STONE:0)
Block(7,1,7,STONE:0)
Block(7,2,-6,STONE:0)
Block(7,2,-5,STONE:0)
Block(7,2,-4,STONE:0)
Block(7,2,-3,STONE:0)
Block(7,2,-2,STONE:0)
Block(7,2,-1,STONE:0)
Block(7,2,0,STONE:0)
Block(7,2,1,STONE:0)
Block(7,2,2,STONE:0)
Block(7,2,3,STONE:0)
Block(7,2,4,STONE:0)
Block(7,2,5,STONE:0)
Block(7,2,6,STONE:0)
Block(7,2,7,STONE:0)
Block(7,2,8,STONE:0)
Block(7,2,9,STONE:0)
Block(7,2,10,STONE:0)
Block(7,2,11,STONE:0)
Block(7,3,-7,STONE:0)
Block(7,3,-6,STONE:0)
Block(7,3,-5,STONE:0)
Block(7,3,-4,STONE:0)
Block(7,3,-3,STONE:0)
Block(7,3,-2,STONE:0)
Block(7,3,-1,biomesoplenty:grass:1)
Block(7,3,0,biomesoplenty:grass:1)
Block(7,3,1,biomesoplenty:grass:1)
Block(7,3,2,iceandfire:chared_stone)
Block(7,3,3,iceandfire:chared_stone)
Block(7,3,4,iceandfire:chared_stone)
Block(7,3,5,STONE:0)
Block(7,3,6,STONE:0)
Block(7,3,7,STONE:0)
Block(7,3,8,STONE:0)
Block(7,3,9,STONE:0)
Block(7,3,10,STONE:0)
Block(7,3,11,STONE:0)
Block(7,3,12,STONE:0)
Block(7,3,13,STONE:0)
Block(7,4,-7,STONE:0)
Block(7,4,-6,STONE:0)
Block(7,4,-5,contenttweaker:bone_pile)
Block(7,4,-4,quark:leaf_carpet)
Block(7,4,-3,quark:leaf_carpet)
Block(7,4,-2,rustic:iron_lattice:0)
Block(7,4,-1,quark:leaf_carpet)
Block(7,4,0,AIR:0)
Block(7,4,1,AIR:0)
Block(7,4,2,AIR:0)
Block(7,4,3,AIR:0)
Block(7,4,4,AIR:0)
Block(7,4,5,AIR:0)
Block(7,4,6,AIR:0)
Block(7,4,7,quark:leaf_carpet)
Block(7,4,8,rustic:iron_lattice:0)
Block(7,4,9,quark:leaf_carpet)
Block(7,4,10,AIR:0)
Block(7,4,11,quark:leaf_carpet)
Block(7,4,12,STONE:0)
Block(7,4,13,STONE:0)
Block(7,4,14,STONE:0)
Block(7,5,-7,STONE:0)
Block(7,5,-6,STONE:0)
Block(7,5,-5,AIR:0)
Block(7,5,-4,AIR:0)
Block(7,5,-3,AIR:0)
Block(7,5,-2,rustic:iron_lattice:0)
Block(7,5,-1,AIR:0)
Block(7,5,0,AIR:0)
Block(7,5,1,AIR:0)
Block(7,5,2,AIR:0)
Block(7,5,3,AIR:0)
Block(7,5,4,AIR:0)
Block(7,5,5,AIR:0)
Block(7,5,6,AIR:0)
Block(7,5,7,AIR:0)
Block(7,5,8,rustic:iron_lattice:0)
Block(7,5,9,AIR:0)
Block(7,5,10,AIR:0)
Block(7,5,11,AIR:0)
Block(7,5,12,STONE:0)
Block(7,5,13,STONE:0)
Block(7,5,14,STONE:0)
Block(7,6,-6,STONE:0)
Block(7,6,-5,STONE:0)
Block(7,6,-4,AIR:0)
Block(7,6,-3,AIR:0)
Block(7,6,-2,rustic:iron_lattice:0)
Block(7,6,-1,AIR:0)
Block(7,6,0,AIR:0)
Block(7,6,1,AIR:0)
Block(7,6,2,AIR:0)
Block(7,6,3,AIR:0)
Block(7,6,4,AIR:0)
Block(7,6,5,AIR:0)
Block(7,6,6,AIR:0)
Block(7,6,7,AIR:0)
Block(7,6,8,rustic:iron_lattice:0)
Block(7,6,9,AIR:0)
Block(7,6,10,AIR:0)
Block(7,6,11,AIR:0)
Block(7,6,12,STONE:0)
Block(7,6,13,STONE:0)
Block(7,6,14,STONE:0)
Block(7,7,-6,STONE:0)
Block(7,7,-5,STONE:0)
Block(7,7,-4,STONE:0)
Block(7,7,-3,STONE:0)
Block(7,7,-2,STONE:0)
Block(7,7,-1,AIR:0)
Block(7,7,0,AIR:0)
Block(7,7,1,AIR:0)
Block(7,7,2,AIR:0)
Block(7,7,3,AIR:0)
Block(7,7,4,AIR:0)
Block(7,7,5,AIR:0)
Block(7,7,6,AIR:0)
Block(7,7,7,AIR:0)
Block(7,7,8,STONE:0)
Block(7,7,9,STONE:0)
Block(7,7,10,STONE:0)
Block(7,7,11,STONE:0)
Block(7,7,12,STONE:0)
Block(7,7,13,STONE:0)
Block(7,8,-5,STONE:0)
Block(7,8,-4,STONE:0)
Block(7,8,-3,STONE:0)
Block(7,8,-2,STONE:0)
Block(7,8,-1,LEAVES:12)
Block(7,8,0,AIR:0)
Block(7,8,1,AIR:0)
Block(7,8,2,AIR:0)
Block(7,8,3,AIR:0)
Block(7,8,4,AIR:0)
Block(7,8,5,AIR:0)
Block(7,8,6,AIR:0)
Block(7,8,7,AIR:0)
Block(7,8,8,AIR:0)
Block(7,8,9,AIR:0)
Block(7,8,10,STONE:0)
Block(7,8,11,STONE:0)
Block(7,8,12,STONE:0)
Block(7,9,-3,STONE:0)
Block(7,9,-2,STONE:0)
Block(7,9,-1,STONE:0)
Block(7,9,0,AIR:0)
Block(7,9,1,AIR:0)
Block(7,9,2,AIR:0)
Block(7,9,3,AIR:0)
Block(7,9,4,AIR:0)
Block(7,9,5,AIR:0)
Block(7,9,6,AIR:0)
Block(7,9,7,AIR:0)
Block(7,9,8,LEAVES:4)
Block(7,9,9,STONE:0)
Block(7,9,10,STONE:0)
Block(7,10,-2,STONE:0)
Block(7,10,-1,STONE:0)
Block(7,10,0,STONE:0)
Block(7,10,1,HUGE_MUSHROOM_1:14)
Block(7,10,2,AIR:0)
Block(7,10,3,AIR:0)
Block(7,10,4,AIR:0)
Block(7,10,5,AIR:0)
Block(7,10,6,AIR:0)
Block(7,10,7,AIR:0)
Block(7,10,8,STONE:0)
Block(7,10,9,STONE:0)
Block(7,10,10,STONE:0)
Block(7,11,0,STONE:0)
Block(7,11,1,STONE:0)
Block(7,11,2,STONE:0)
Block(7,11,3,STONE:0)
Block(7,11,4,AIR:0)
Block(7,11,5,AIR:0)
Block(7,11,6,AIR:0)
Block(7,11,7,AIR:0)
Block(7,11,8,STONE:0)
Block(7,11,9,STONE:0)
Block(7,11,10,STONE:0)
Block(7,11,11,STONE:0)
Block(7,12,0,STONE:0)
Block(7,12,1,STONE:0)
Block(7,12,2,STONE:0)
Block(7,12,3,STONE:0)
Block(7,12,4,STONE:0)
Block(7,12,5,AIR:0)
Block(7,12,6,STONE:0)
Block(7,12,7,LEAVES:12)
Block(7,12,8,STONE:0)
Block(7,12,9,STONE:0)
Block(7,12,10,STONE:0)
Block(7,13,1,STONE:0)
Block(7,13,2,STONE:0)
Block(7,13,3,STONE:0)
Block(7,13,4,STONE:0)
Block(7,13,5,LEAVES:12)
Block(7,13,6,STONE:0)
Block(7,13,7,STONE:0)
Block(7,13,8,STONE:0)
Block(7,13,9,STONE:0)
Block(7,13,10,STONE:0)
Block(7,14,3,STONE:0)
Block(7,14,4,STONE:0)
Block(7,14,5,STONE:0)
Block(7,14,6,STONE:0)
Block(7,14,7,STONE:0)
Block(7,14,8,STONE:0)
Block(7,16,-11,STONE:0)
Block(7,16,-10,STONE:0)
Block(7,16,-9,STONE:0)
Block(7,17,-11,STONE:0)
Block(7,17,-10,STONE:0)
Block(7,17,-9,STONE:0)
Block(7,18,-14,STONE:0)
Block(7,18,-13,STONE:0)
Block(7,18,-12,STONE:0)
Block(7,18,-11,STONE:0)
Block(7,18,-10,STONE:0)
Block(7,18,-9,STONE:0)
Block(7,19,-14,STONE:0)
Block(7,19,-13,STONE:0)
Block(7,19,-12,STONE:0)
Block(7,19,-11,STONE:0)
Block(7,19,-10,STONE:0)
Block(7,20,-14,STONE:0)
Block(7,20,-13,STONE:0)
Block(7,20,-12,STONE:0)
Block(7,20,-11,STONE:0)
Block(7,20,-10,STONE:0)
Block(7,21,-15,STONE:0)
Block(7,21,-14,STATIONARY_WATER:0)
Block(7,21,-13,STATIONARY_WATER:1)
Block(7,21,-12,STONE:0)
Block(7,21,-11,STONE:0)
Block(7,22,-14,STONE:0)
Block(7,22,-13,STONE:0)
Block(7,22,-12,STONE:0)
Block(8,1,-5,STONE:0)
Block(8,1,-4,STONE:0)
Block(8,1,-3,STONE:0)
Block(8,1,-1,STONE:0)
Block(8,1,0,STONE:0)
Block(8,1,1,STONE:0)
Block(8,1,2,STONE:0)
Block(8,1,3,STONE:0)
Block(8,1,4,STONE:0)
Block(8,1,5,STONE:0)
Block(8,1,6,STONE:0)
Block(8,2,-6,STONE:0)
Block(8,2,-5,STONE:0)
Block(8,2,-4,STONE:0)
Block(8,2,-3,STONE:0)
Block(8,2,-2,STONE:0)
Block(8,2,-1,STONE:0)
Block(8,2,0,STONE:0)
Block(8,2,1,STONE:0)
Block(8,2,2,MAGMA:0)
Block(8,2,3,MAGMA:0)
Block(8,2,4,STONE:0)
Block(8,2,5,STONE:0)
Block(8,2,6,STONE:0)
Block(8,2,7,STONE:0)
Block(8,2,8,STONE:0)
Block(8,2,9,STONE:0)
Block(8,2,10,STONE:0)
Block(8,2,11,STONE:0)
Block(8,3,-7,STONE:0)
Block(8,3,-6,STONE:0)
Block(8,3,-5,STONE:0)
Block(8,3,-4,STONE:0)
Block(8,3,-3,STONE:0)
Block(8,3,-2,biomesoplenty:grass:1)
Block(8,3,-1,biomesoplenty:grass:1)
Block(8,3,0,STONE:0)
Block(8,3,1,iceandfire:chared_stone)
Block(8,3,2,FIRE:15)
Block(8,3,3,FIRE:15)
Block(8,3,4,iceandfire:chared_stone)
Block(8,3,5,biomesoplenty:grass:1)
Block(8,3,6,STONE:0)
Block(8,3,7,STONE:0)
Block(8,3,8,STONE:0)
Block(8,3,9,STONE:0)
Block(8,3,10,STONE:0)
Block(8,3,11,STONE:0)
Block(8,3,12,STONE:0)
Block(8,3,13,STONE:0)
Block(8,4,-7,STONE:0)
Block(8,4,-6,STONE:0)
Block(8,4,-5,quark:leaf_carpet)
Block(8,4,-4,AIR:0)
Block(8,4,-3,AIR:0)
Block(8,4,-2,rustic:iron_lattice:0)
Block(8,4,-1,AIR:0)
Block(8,4,0,quark:leaf_carpet)
Block(8,4,1,rustic:iron_lattice:0)
Block(8,4,2,AIR:0)
Block(8,4,3,AIR:0)
Block(8,4,4,rustic:iron_lattice:0)
Block(8,4,5,AIR:0)
Block(8,4,6,quark:leaf_carpet)
Block(8,4,7,LEAVES:4)
Block(8,4,8,rustic:iron_lattice:0)
Block(8,4,9,AIR:0)
Block(8,4,10,quark:leaf_carpet)
Block(8,4,11,quark:leaf_carpet)
Block(8,4,12,STONE:0)
Block(8,4,13,STONE:0)
Block(8,4,14,STONE:0)
Block(8,5,-7,STONE:0)
Block(8,5,-6,STONE:0)
Block(8,5,-5,AIR:0)
Block(8,5,-4,AIR:0)
Block(8,5,-3,AIR:0)
Block(8,5,-2,rustic:iron_lattice:0)
Block(8,5,-1,AIR:0)
Block(8,5,0,AIR:0)
Block(8,5,1,rustic:iron_lattice:0)
Block(8,5,2,biomesoplenty:flesh)
Block(8,5,3,biomesoplenty:flesh)
Block(8,5,4,rustic:iron_lattice:0)
Block(8,5,5,AIR:0)
Block(8,5,6,AIR:0)
Block(8,5,7,AIR:0)
Block(8,5,8,rustic:iron_lattice:0)
Block(8,5,9,AIR:0)
Block(8,5,10,AIR:0)
Block(8,5,11,AIR:0)
Block(8,5,12,STONE:0)
Block(8,5,13,STONE:0)
Block(8,5,14,STONE:0)
Block(8,6,-7,STONE:0)
Block(8,6,-6,STONE:0)
Block(8,6,-5,STONE:0)
Block(8,6,-4,AIR:0)
Block(8,6,-3,AIR:0)
Block(8,6,-2,rustic:iron_lattice:0)
Block(8,6,-1,AIR:0)
