
#######################################################################
# +-----------------------------------------------------------------+ #
# |                            BO4 object                           | #
# +-----------------------------------------------------------------+ #
#######################################################################

Author: NLBlackEagle

Description: No description given

SettingsMode: WriteWithoutComments


#######################################################################
# +-----------------------------------------------------------------+ #
# |                          Main settings                          | #
# +-----------------------------------------------------------------+ #
#######################################################################

FixedRotation: 

Frequency: 0

SpawnHeight: randomY

UseCenterForHighestBlock: true

##############################
# Height Limits for the BO4. #
##############################

MinHeight: 1

MaxHeight: 1

InheritBO3: 

InheritBO3Rotation: NORTH

OverrideChildSettings: true

OverrideParentHeight: true

CanOverride: true

BranchFrequency: 0

BranchFrequencyGroup: 

MustBeBelowOther: false

MustBeInside: 

CannotBeInside: 

ReplacesBO3: 

MustBeInsideWorldBorders: false

CanSpawnOnWater: true

SpawnOnWaterOnly: false

SpawnUnderWater: false

SpawnAtWaterLevel: false

HeightOffset: 0

RemoveAir: false

ReplaceAbove: 

ReplaceBelow: 

ReplaceWithBiomeBlocks: true

ReplaceWithSurfaceBlock: GRASS

ReplaceWithGroundBlock: DIRT

ReplaceWithStoneBlock: STONE

SmoothRadius: 0

SmoothHeightOffset: 0

SmoothStartTop: false

SmoothStartWood: false

SmoothingSurfaceBlock: 

SmoothingGroundBlock: 

BO3Group: 

IsSpawnPoint: false

DoReplaceBlocks: false


#######################################################################
# +-----------------------------------------------------------------+ #
# |                              Blocks                             | #
# +-----------------------------------------------------------------+ #
#######################################################################

RandomBlock(-6,0,1,quark:iron_plate:1,70,STAINED_CLAY:15,30,STAINED_CLAY:7,30,null,30,quark:iron_plate:1,100)
RandomBlock(-6,0,2,quark:iron_plate:1,70,STAINED_CLAY:15,30,STAINED_CLAY:7,30,null,30,quark:iron_plate:1,100)
RandomBlock(-6,0,3,quark:iron_plate:1,70,STAINED_CLAY:15,30,STAINED_CLAY:7,30,null,30,quark:iron_plate:1,100)
RandomBlock(-6,1,1,quark:iron_plate:1,70,STAINED_CLAY:15,30,STAINED_CLAY:7,30,null,30,quark:iron_plate:1,100)
RandomBlock(-6,1,2,quark:iron_plate:1,70,STAINED_CLAY:15,30,STAINED_CLAY:7,30,null,30,quark:iron_plate:1,100)
RandomBlock(-6,1,3,quark:iron_plate:1,70,STAINED_CLAY:15,30,STAINED_CLAY:7,30,null,30,quark:iron_plate:1,100)
RandomBlock(-6,2,1,quark:iron_plate:1,70,STAINED_CLAY:15,30,STAINED_CLAY:7,30,null,30,quark:iron_plate:1,100)
RandomBlock(-6,2,2,quark:iron_plate:1,70,STAINED_CLAY:15,30,STAINED_CLAY:7,30,null,30,quark:iron_plate:1,100)
RandomBlock(-6,2,3,quark:iron_plate:1,70,STAINED_CLAY:15,30,STAINED_CLAY:7,30,null,30,quark:iron_plate:1,100)
RandomBlock(-6,3,1,quark:iron_plate:1,70,STAINED_CLAY:15,30,STAINED_CLAY:7,30,null,30,quark:iron_plate:1,100)
RandomBlock(-6,3,2,quark:iron_plate:1,70,STAINED_CLAY:15,30,STAINED_CLAY:7,30,null,30,quark:iron_plate:1,100)
RandomBlock(-6,3,3,quark:iron_plate:1,70,STAINED_CLAY:15,30,STAINED_CLAY:7,30,null,30,quark:iron_plate:1,100)
RandomBlock(-6,4,1,quark:iron_plate:1,70,STAINED_CLAY:15,30,STAINED_CLAY:7,30,null,30,quark:iron_plate:1,100)
RandomBlock(-6,4,2,quark:iron_plate:1,70,STAINED_CLAY:15,30,STAINED_CLAY:7,30,null,30,quark:iron_plate:1,100)
RandomBlock(-6,4,3,rustic:iron_lattice,30,rustic:iron_lattice,30,biomesoplenty:leaves_2:7,30,quark:iron_plate_stairs:6,10,quark:iron_plate_stairs:0,10,quark:iron_plate_stairs:5,10,quark:iron_plate_stairs,10,quark:iron_plate_slab:8,10,quark:iron_plate_stairs:7,10,quark:iron_plate_stairs:1,10,quark:iron_plate_slab,10,quark:iron_plate_stairs:4,10,quark:iron_plate_stairs:2,10,rustic:iron_lattice,50,rustic:iron_lattice,50,biomesoplenty:leaves_2:7,100)
RandomBlock(-6,5,1,quark:iron_plate:1,70,STAINED_CLAY:15,30,STAINED_CLAY:7,30,null,30,quark:iron_plate:1,100)
RandomBlock(-6,5,2,rustic:iron_lattice,30,rustic:iron_lattice,30,biomesoplenty:leaves_2:7,30,quark:iron_plate_stairs:6,10,quark:iron_plate_stairs:0,10,quark:iron_plate_stairs:5,10,quark:iron_plate_stairs,10,quark:iron_plate_slab:8,10,quark:iron_plate_stairs:7,10,quark:iron_plate_stairs:1,10,quark:iron_plate_slab,10,quark:iron_plate_stairs:4,10,quark:iron_plate_stairs:2,10,rustic:iron_lattice,50,rustic:iron_lattice,50,biomesoplenty:leaves_2:7,100)
RandomBlock(-6,5,3,rustic:iron_lattice,30,rustic:iron_lattice,30,biomesoplenty:leaves_2:7,30,quark:iron_plate_stairs:6,10,quark:iron_plate_stairs:0,10,quark:iron_plate_stairs:5,10,quark:iron_plate_stairs,10,quark:iron_plate_slab:8,10,quark:iron_plate_stairs:7,10,quark:iron_plate_stairs:1,10,quark:iron_plate_slab,10,quark:iron_plate_stairs:4,10,quark:iron_plate_stairs:2,10,rustic:iron_lattice,50,rustic:iron_lattice,50,biomesoplenty:leaves_2:7,100)
RandomBlock(-6,6,1,quark:iron_plate:1,70,STAINED_CLAY:15,30,STAINED_CLAY:7,30,null,30,quark:iron_plate:1,100)
RandomBlock(-6,6,2,quark:iron_plate:1,70,STAINED_CLAY:15,30,STAINED_CLAY:7,30,null,30,quark:iron_plate:1,100)
RandomBlock(-6,6,3,rustic:iron_lattice,30,rustic:iron_lattice,30,biomesoplenty:leaves_2:7,30,quark:iron_plate_stairs:6,10,quark:iron_plate_stairs:0,10,quark:iron_plate_stairs:5,10,quark:iron_plate_stairs,10,quark:iron_plate_slab:8,10,quark:iron_plate_stairs:7,10,quark:iron_plate_stairs:1,10,quark:iron_plate_slab,10,quark:iron_plate_stairs:4,10,quark:iron_plate_stairs:2,10,rustic:iron_lattice,50,rustic:iron_lattice,50,biomesoplenty:leaves_2:7,100)
RandomBlock(-6,7,1,rustic:iron_lattice,30,rustic:iron_lattice,30,biomesoplenty:leaves_2:7,30,quark:iron_plate_stairs:6,10,quark:iron_plate_stairs:0,10,quark:iron_plate_stairs:5,10,quark:iron_plate_stairs,10,quark:iron_plate_slab:8,10,quark:iron_plate_stairs:7,10,quark:iron_plate_stairs:1,10,quark:iron_plate_slab,10,quark:iron_plate_stairs:4,10,quark:iron_plate_stairs:2,10,rustic:iron_lattice,50,rustic:iron_lattice,50,biomesoplenty:leaves_2:7,100)
RandomBlock(-6,7,2,rustic:iron_lattice,30,rustic:iron_lattice,30,biomesoplenty:leaves_2:7,30,quark:iron_plate_stairs:6,10,quark:iron_plate_stairs:0,10,quark:iron_plate_stairs:5,10,quark:iron_plate_stairs,10,quark:iron_plate_slab:8,10,quark:iron_plate_stairs:7,10,quark:iron_plate_stairs:1,10,quark:iron_plate_slab,10,quark:iron_plate_stairs:4,10,quark:iron_plate_stairs:2,10,rustic:iron_lattice,50,rustic:iron_lattice,50,biomesoplenty:leaves_2:7,100)
RandomBlock(-6,7,3,rustic:iron_lattice,30,rustic:iron_lattice,30,biomesoplenty:leaves_2:7,30,quark:iron_plate_stairs:6,10,quark:iron_plate_stairs:0,10,quark:iron_plate_stairs:5,10,quark:iron_plate_stairs,10,quark:iron_plate_slab:8,10,quark:iron_plate_stairs:7,10,quark:iron_plate_stairs:1,10,quark:iron_plate_slab,10,quark:iron_plate_stairs:4,10,quark:iron_plate_stairs:2,10,rustic:iron_lattice,50,rustic:iron_lattice,50,biomesoplenty:leaves_2:7,100)
RandomBlock(-6,8,1,quark:iron_plate:1,70,STAINED_CLAY:15,30,STAINED_CLAY:7,30,null,30,quark:iron_plate:1,100)
RandomBlock(-6,8,2,rustic:iron_lattice,30,rustic:iron_lattice,30,biomesoplenty:leaves_2:7,30,quark:iron_plate_stairs:6,10,quark:iron_plate_stairs:0,10,quark:iron_plate_stairs:5,10,quark:iron_plate_stairs,10,quark:iron_plate_slab:8,10,quark:iron_plate_stairs:7,10,quark:iron_plate_stairs:1,10,quark:iron_plate_slab,10,quark:iron_plate_stairs:4,10,quark:iron_plate_stairs:2,10,rustic:iron_lattice,50,rustic:iron_lattice,50,biomesoplenty:leaves_2:7,100)
RandomBlock(-6,8,3,rustic:iron_lattice,30,rustic:iron_lattice,30,biomesoplenty:leaves_2:7,30,quark:iron_plate_stairs:6,10,quark:iron_plate_stairs:0,10,quark:iron_plate_stairs:5,10,quark:iron_plate_stairs,10,quark:iron_plate_slab:8,10,quark:iron_plate_stairs:7,10,quark:iron_plate_stairs:1,10,quark:iron_plate_slab,10,quark:iron_plate_stairs:4,10,quark:iron_plate_stairs:2,10,rustic:iron_lattice,50,rustic:iron_lattice,50,biomesoplenty:leaves_2:7,100)
RandomBlock(-6,9,1,rustic:iron_lattice,30,rustic:iron_lattice,30,biomesoplenty:leaves_2:7,30,quark:iron_plate_stairs:6,10,quark:iron_plate_stairs:0,10,quark:iron_plate_stairs:5,10,quark:iron_plate_stairs,10,quark:iron_plate_slab:8,10,quark:iron_plate_stairs:7,10,quark:iron_plate_stairs:1,10,quark:iron_plate_slab,10,quark:iron_plate_stairs:4,10,quark:iron_plate_stairs:2,10,rustic:iron_lattice,50,rustic:iron_lattice,50,biomesoplenty:leaves_2:7,100)
RandomBlock(-6,9,2,rustic:iron_lattice,30,rustic:iron_lattice,30,biomesoplenty:leaves_2:7,30,quark:iron_plate_stairs:6,10,quark:iron_plate_stairs:0,10,quark:iron_plate_stairs:5,10,quark:iron_plate_stairs,10,quark:iron_plate_slab:8,10,quark:iron_plate_stairs:7,10,quark:iron_plate_stairs:1,10,quark:iron_plate_slab,10,quark:iron_plate_stairs:4,10,quark:iron_plate_stairs:2,10,rustic:iron_lattice,50,rustic:iron_lattice,50,biomesoplenty:leaves_2:7,100)
RandomBlock(-6,9,3,rustic:iron_lattice,30,rustic:iron_lattice,30,biomesoplenty:leaves_2:7,30,quark:iron_plate_stairs:6,10,quark:iron_plate_stairs:0,10,quark:iron_plate_stairs:5,10,quark:iron_plate_stairs,10,quark:iron_plate_slab:8,10,quark:iron_plate_stairs:7,10,quark:iron_plate_stairs:1,10,quark:iron_plate_slab,10,quark:iron_plate_stairs:4,10,quark:iron_plate_stairs:2,10,rustic:iron_lattice,50,rustic:iron_lattice,50,biomesoplenty:leaves_2:7,100)
RandomBlock(-6,10,1,quark:iron_plate:1,70,STAINED_CLAY:15,30,STAINED_CLAY:7,30,null,30,quark:iron_plate:1,100)
RandomBlock(-6,10,2,quark:iron_plate:1,70,STAINED_CLAY:15,30,STAINED_CLAY:7,30,null,30,quark:iron_plate:1,100)
RandomBlock(-6,10,3,rustic:iron_lattice,30,rustic:iron_lattice,30,biomesoplenty:leaves_2:7,30,quark:iron_plate_stairs:6,10,quark:iron_plate_stairs:0,10,quark:iron_plate_stairs:5,10,quark:iron_plate_stairs,10,quark:iron_plate_slab:8,10,quark:iron_plate_stairs:7,10,quark:iron_plate_stairs:1,10,quark:iron_plate_slab,10,quark:iron_plate_stairs:4,10,quark:iron_plate_stairs:2,10,rustic:iron_lattice,50,rustic:iron_lattice,50,biomesoplenty:leaves_2:7,100)
RandomBlock(-6,11,1,quark:iron_plate:1,70,STAINED_CLAY:15,30,STAINED_CLAY:7,30,null,30,quark:iron_plate:1,100)
RandomBlock(-6,11,2,quark:iron_plate:1,70,STAINED_CLAY:15,30,STAINED_CLAY:7,30,null,30,quark:iron_plate:1,100)
RandomBlock(-6,11,3,quark:iron_plate:1,70,STAINED_CLAY:15,30,STAINED_CLAY:7,30,null,30,quark:iron_plate:1,100)
RandomBlock(-6,12,1,rustic:iron_lattice,30,rustic:iron_lattice,30,biomesoplenty:leaves_2:7,30,quark:iron_plate_stairs:6,10,quark:iron_plate_stairs:0,10,quark:iron_plate_stairs:5,10,quark:iron_plate_stairs,10,quark:iron_plate_slab:8,10,quark:iron_plate_stairs:7,10,quark:iron_plate_stairs:1,10,quark:iron_plate_slab,10,quark:iron_plate_stairs:4,10,quark:iron_plate_stairs:2,10,rustic:iron_lattice,50,rustic:iron_lattice,50,biomesoplenty:leaves_2:7,100)
RandomBlock(-6,12,2,quark:iron_plate:1,70,STAINED_CLAY:15,30,STAINED_CLAY:7,30,null,30,quark:iron_plate:1,100)
RandomBlock(-6,12,3,quark:iron_plate:1,70,STAINED_CLAY:15,30,STAINED_CLAY:7,30,null,30,quark:iron_plate:1,100)
RandomBlock(-6,13,1,rustic:iron_lattice,30,rustic:iron_lattice,30,biomesoplenty:leaves_2:7,30,quark:iron_plate_stairs:6,10,quark:iron_plate_stairs:0,10,quark:iron_plate_stairs:5,10,quark:iron_plate_stairs,10,quark:iron_plate_slab:8,10,quark:iron_plate_stairs:7,10,quark:iron_plate_stairs:1,10,quark:iron_plate_slab,10,quark:iron_plate_stairs:4,10,quark:iron_plate_stairs:2,10,rustic:iron_lattice,50,rustic:iron_lattice,50,biomesoplenty:leaves_2:7,100)
RandomBlock(-6,13,2,rustic:iron_lattice,30,rustic:iron_lattice,30,biomesoplenty:leaves_2:7,30,quark:iron_plate_stairs:6,10,quark:iron_plate_stairs:0,10,quark:iron_plate_stairs:5,10,quark:iron_plate_stairs,10,quark:iron_plate_slab:8,10,quark:iron_plate_stairs:7,10,quark:iron_plate_stairs:1,10,quark:iron_plate_slab,10,quark:iron_plate_stairs:4,10,quark:iron_plate_stairs:2,10,rustic:iron_lattice,50,rustic:iron_lattice,50,biomesoplenty:leaves_2:7,100)
RandomBlock(-6,13,3,quark:iron_plate:1,70,STAINED_CLAY:15,30,STAINED_CLAY:7,30,null,30,quark:iron_plate:1,100)
RandomBlock(-6,14,1,rustic:iron_lattice,30,rustic:iron_lattice,30,biomesoplenty:leaves_2:7,30,quark:iron_plate_stairs:6,10,quark:iron_plate_stairs:0,10,quark:iron_plate_stairs:5,10,quark:iron_plate_stairs,10,quark:iron_plate_slab:8,10,quark:iron_plate_stairs:7,10,quark:iron_plate_stairs:1,10,quark:iron_plate_slab,10,quark:iron_plate_stairs:4,10,quark:iron_plate_stairs:2,10,rustic:iron_lattice,50,rustic:iron_lattice,50,biomesoplenty:leaves_2:7,100)
RandomBlock(-6,14,2,quark:iron_plate:1,70,STAINED_CLAY:15,30,STAINED_CLAY:7,30,null,30,quark:iron_plate:1,100)
RandomBlock(-6,14,3,quark:iron_plate:1,70,STAINED_CLAY:15,30,STAINED_CLAY:7,30,null,30,quark:iron_plate:1,100)
RandomBlock(-6,15,1,rustic:iron_lattice,30,rustic:iron_lattice,30,biomesoplenty:leaves_2:7,30,quark:iron_plate_stairs:6,10,quark:iron_plate_stairs:0,10,quark:iron_plate_stairs:5,10,quark:iron_plate_stairs,10,quark:iron_plate_slab:8,10,quark:iron_plate_stairs:7,10,quark:iron_plate_stairs:1,10,quark:iron_plate_slab,10,quark:iron_plate_stairs:4,10,quark:iron_plate_stairs:2,10,rustic:iron_lattice,50,rustic:iron_lattice,50,biomesoplenty:leaves_2:7,100)
RandomBlock(-6,15,2,rustic:iron_lattice,30,rustic:iron_lattice,30,biomesoplenty:leaves_2:7,30,quark:iron_plate_stairs:6,10,quark:iron_plate_stairs:0,10,quark:iron_plate_stairs:5,10,quark:iron_plate_stairs,10,quark:iron_plate_slab:8,10,quark:iron_plate_stairs:7,10,quark:iron_plate_stairs:1,10,quark:iron_plate_slab,10,quark:iron_plate_stairs:4,10,quark:iron_plate_stairs:2,10,rustic:iron_lattice,50,rustic:iron_lattice,50,biomesoplenty:leaves_2:7,100)
RandomBlock(-6,15,3,quark:iron_plate:1,70,STAINED_CLAY:15,30,STAINED_CLAY:7,30,null,30,quark:iron_plate:1,100)
RandomBlock(-6,16,1,rustic:iron_lattice,30,rustic:iron_lattice,30,biomesoplenty:leaves_2:7,30,quark:iron_plate_stairs:6,10,quark:iron_plate_stairs:0,10,quark:iron_plate_stairs:5,10,quark:iron_plate_stairs,10,quark:iron_plate_slab:8,10,quark:iron_plate_stairs:7,10,quark:iron_plate_stairs:1,10,quark:iron_plate_slab,10,quark:iron_plate_stairs:4,10,quark:iron_plate_stairs:2,10,rustic:iron_lattice,50,rustic:iron_lattice,50,biomesoplenty:leaves_2:7,100)
RandomBlock(-6,16,2,quark:iron_plate:1,70,STAINED_CLAY:15,30,STAINED_CLAY:7,30,null,30,quark:iron_plate:1,100)
RandomBlock(-6,16,3,quark:iron_plate:1,70,STAINED_CLAY:15,30,STAINED_CLAY:7,30,null,30,quark:iron_plate:1,100)
RandomBlock(-6,17,1,rustic:iron_lattice,30,rustic:iron_lattice,30,biomesoplenty:leaves_2:7,30,quark:iron_plate_stairs:6,10,quark:iron_plate_stairs:0,10,quark:iron_plate_stairs:5,10,quark:iron_plate_stairs,10,quark:iron_plate_slab:8,10,quark:iron_plate_stairs:7,10,quark:iron_plate_stairs:1,10,quark:iron_plate_slab,10,quark:iron_plate_stairs:4,10,quark:iron_plate_stairs:2,10,rustic:iron_lattice,50,rustic:iron_lattice,50,biomesoplenty:leaves_2:7,100)
RandomBlock(-6,17,2,quark:iron_plate:1,70,STAINED_CLAY:15,30,STAINED_CLAY:7,30,null,30,quark:iron_plate:1,100)
RandomBlock(-6,17,3,quark:iron_plate:1,70,STAINED_CLAY:15,30,STAINED_CLAY:7,30,null,30,quark:iron_plate:1,100)
RandomBlock(-6,18,1,quark:iron_plate:1,70,STAINED_CLAY:15,30,STAINED_CLAY:7,30,null,30,quark:iron_plate:1,100)
RandomBlock(-6,18,2,quark:iron_plate:1,70,STAINED_CLAY:15,30,STAINED_CLAY:7,30,null,30,quark:iron_plate:1,100)
RandomBlock(-6,18,3,quark:iron_plate:1,70,STAINED_CLAY:15,30,STAINED_CLAY:7,30,null,30,quark:iron_plate:1,100)
RandomBlock(-6,19,1,quark:iron_plate:1,70,STAINED_CLAY:15,30,STAINED_CLAY:7,30,null,30,quark:iron_plate:1,100)
RandomBlock(-6,19,2,quark:iron_plate:1,70,STAINED_CLAY:15,30,STAINED_CLAY:7,30,null,30,quark:iron_plate:1,100)
RandomBlock(-6,19,3,quark:iron_plate:1,70,STAINED_CLAY:15,30,STAINED_CLAY:7,30,null,30,quark:iron_plate:1,100)
RandomBlock(-6,20,1,quark:iron_plate:1,70,STAINED_CLAY:15,30,STAINED_CLAY:7,30,null,30,quark:iron_plate:1,100)
RandomBlock(-6,20,2,quark:iron_plate:1,70,STAINED_CLAY:15,30,STAINED_CLAY:7,30,null,30,quark:iron_plate:1,100)
RandomBlock(-6,20,3,quark:iron_plate:1,70,STAINED_CLAY:15,30,STAINED_CLAY:7,30,null,30,quark:iron_plate:1,100)
RandomBlock(-6,21,1,quark:iron_plate:1,70,STAINED_CLAY:15,30,STAINED_CLAY:7,30,null,30,quark:iron_plate:1,100)
RandomBlock(-6,21,2,quark:iron_plate:1,70,STAINED_CLAY:15,30,STAINED_CLAY:7,30,null,30,quark:iron_plate:1,100)
RandomBlock(-6,21,3,quark:iron_plate:1,70,STAINED_CLAY:15,30,STAINED_CLAY:7,30,null,30,quark:iron_plate:1,100)
RandomBlock(-6,22,1,quark:iron_plate:1,70,STAINED_CLAY:15,30,STAINED_CLAY:7,30,null,30,quark:iron_plate:1,100)
RandomBlock(-6,22,2,quark:iron_plate:1,70,STAINED_CLAY:15,30,STAINED_CLAY:7,30,null,30,quark:iron_plate:1,100)
RandomBlock(-6,22,3,quark:iron_plate:1,70,STAINED_CLAY:15,30,STAINED_CLAY:7,30,null,30,quark:iron_plate:1,100)
RandomBlock(-6,23,1,rustic:iron_lattice,30,rustic:iron_lattice,30,biomesoplenty:leaves_2:7,30,quark:iron_plate_stairs:6,10,quark:iron_plate_stairs:0,10,quark:iron_plate_stairs:5,10,quark:iron_plate_stairs,10,quark:iron_plate_slab:8,10,quark:iron_plate_stairs:7,10,quark:iron_plate_stairs:1,10,quark:iron_plate_slab,10,quark:iron_plate_stairs:4,10,quark:iron_plate_stairs:2,10,rustic:iron_lattice,50,rustic:iron_lattice,50,biomesoplenty:leaves_2:7,100)
RandomBlock(-6,23,2,quark:iron_plate:1,70,STAINED_CLAY:15,30,STAINED_CLAY:7,30,null,30,quark:iron_plate:1,100)
RandomBlock(-6,23,3,quark:iron_plate:1,70,STAINED_CLAY:15,30,STAINED_CLAY:7,30,null,30,quark:iron_plate:1,100)
RandomBlock(-6,24,1,rustic:iron_lattice,30,rustic:iron_lattice,30,biomesoplenty:leaves_2:7,30,quark:iron_plate_stairs:6,10,quark:iron_plate_stairs:0,10,quark:iron_plate_stairs:5,10,quark:iron_plate_stairs,10,quark:iron_plate_slab:8,10,quark:iron_plate_stairs:7,10,quark:iron_plate_stairs:1,10,quark:iron_plate_slab,10,quark:iron_plate_stairs:4,10,quark:iron_plate_stairs:2,10,rustic:iron_lattice,50,rustic:iron_lattice,50,biomesoplenty:leaves_2:7,100)
RandomBlock(-6,24,2,quark:iron_plate:1,70,STAINED_CLAY:15,30,STAINED_CLAY:7,30,null,30,quark:iron_plate:1,100)
RandomBlock(-6,24,3,quark:iron_plate:1,70,STAINED_CLAY:15,30,STAINED_CLAY:7,30,null,30,quark:iron_plate:1,100)
RandomBlock(-6,25,1,rustic:iron_lattice,30,rustic:iron_lattice,30,biomesoplenty:leaves_2:7,30,quark:iron_plate_stairs:6,10,quark:iron_plate_stairs:0,10,quark:iron_plate_stairs:5,10,quark:iron_plate_stairs,10,quark:iron_plate_slab:8,10,quark:iron_plate_stairs:7,10,quark:iron_plate_stairs:1,10,quark:iron_plate_slab,10,quark:iron_plate_stairs:4,10,quark:iron_plate_stairs:2,10,rustic:iron_lattice,50,rustic:iron_lattice,50,biomesoplenty:leaves_2:7,100)
RandomBlock(-6,25,2,rustic:iron_lattice,30,rustic:iron_lattice,30,biomesoplenty:leaves_2:7,30,quark:iron_plate_stairs:6,10,quark:iron_plate_stairs:0,10,quark:iron_plate_stairs:5,10,quark:iron_plate_stairs,10,quark:iron_plate_slab:8,10,quark:iron_plate_stairs:7,10,quark:iron_plate_stairs:1,10,quark:iron_plate_slab,10,quark:iron_plate_stairs:4,10,quark:iron_plate_stairs:2,10,rustic:iron_lattice,50,rustic:iron_lattice,50,biomesoplenty:leaves_2:7,100)
RandomBlock(-6,25,3,quark:iron_plate:1,70,STAINED_CLAY:15,30,STAINED_CLAY:7,30,null,30,quark:iron_plate:1,100)
RandomBlock(-6,26,1,rustic:iron_lattice,30,rustic:iron_lattice,30,biomesoplenty:leaves_2:7,30,quark:iron_plate_stairs:6,10,quark:iron_plate_stairs:0,10,quark:iron_plate_stairs:5,10,quark:iron_plate_stairs,10,quark:iron_plate_slab:8,10,quark:iron_plate_stairs:7,10,quark:iron_plate_stairs:1,10,quark:iron_plate_slab,10,quark:iron_plate_stairs:4,10,quark:iron_plate_stairs:2,10,rustic:iron_lattice,50,rustic:iron_lattice,50,biomesoplenty:leaves_2:7,100)
RandomBlock(-6,26,2,quark:iron_plate:1,70,STAINED_CLAY:15,30,STAINED_CLAY:7,30,null,30,quark:iron_plate:1,100)
RandomBlock(-6,26,3,quark:iron_plate:1,70,STAINED_CLAY:15,30,STAINED_CLAY:7,30,null,30,quark:iron_plate:1,100)
RandomBlock(-6,27,1,quark:iron_plate:1,70,STAINED_CLAY:15,30,STAINED_CLAY:7,30,null,30,quark:iron_plate:1,100)
RandomBlock(-6,27,2,quark:iron_plate:1,70,STAINED_CLAY:15,30,STAINED_CLAY:7,30,null,30,quark:iron_plate:1,100)
RandomBlock(-6,27,3,quark:iron_plate:1,70,STAINED_CLAY:15,30,STAINED_CLAY:7,30,null,30,quark:iron_plate:1,100)
RandomBlock(-6,28,1,rustic:iron_lattice,30,rustic:iron_lattice,30,biomesoplenty:leaves_2:7,30,quark:iron_plate_stairs:6,10,quark:iron_plate_stairs:0,10,quark:iron_plate_stairs:5,10,quark:iron_plate_stairs,10,quark:iron_plate_slab:8,10,quark:iron_plate_stairs:7,10,quark:iron_plate_stairs:1,10,quark:iron_plate_slab,10,quark:iron_plate_stairs:4,10,quark:iron_plate_stairs:2,10,rustic:iron_lattice,50,rustic:iron_lattice,50,biomesoplenty:leaves_2:7,100)
RandomBlock(-6,28,2,quark:iron_plate:1,70,STAINED_CLAY:15,30,STAINED_CLAY:7,30,null,30,quark:iron_plate:1,100)
RandomBlock(-6,28,3,quark:iron_plate:1,70,STAINED_CLAY:15,30,STAINED_CLAY:7,30,null,30,quark:iron_plate:1,100)
RandomBlock(-6,29,1,rustic:iron_lattice,30,rustic:iron_lattice,30,biomesoplenty:leaves_2:7,30,quark:iron_plate_stairs:6,10,quark:iron_plate_stairs:0,10,quark:iron_plate_stairs:5,10,quark:iron_plate_stairs,10,quark:iron_plate_slab:8,10,quark:iron_plate_stairs:7,10,quark:iron_plate_stairs:1,10,quark:iron_plate_slab,10,quark:iron_plate_stairs:4,10,quark:iron_plate_stairs:2,10,rustic:iron_lattice,50,rustic:iron_lattice,50,biomesoplenty:leaves_2:7,100)
RandomBlock(-6,29,2,quark:iron_plate:1,70,STAINED_CLAY:15,30,STAINED_CLAY:7,30,null,30,quark:iron_plate:1,100)
RandomBlock(-6,29,3,quark:iron_plate:1,70,STAINED_CLAY:15,30,STAINED_CLAY:7,30,null,30,quark:iron_plate:1,100)
RandomBlock(-6,30,1,rustic:iron_lattice,30,rustic:iron_lattice,30,biomesoplenty:leaves_2:7,30,quark:iron_plate_stairs:6,10,quark:iron_plate_stairs:0,10,quark:iron_plate_stairs:5,10,quark:iron_plate_stairs,10,quark:iron_plate_slab:8,10,quark:iron_plate_stairs:7,10,quark:iron_plate_stairs:1,10,quark:iron_plate_slab,10,quark:iron_plate_stairs:4,10,quark:iron_plate_stairs:2,10,rustic:iron_lattice,50,rustic:iron_lattice,50,biomesoplenty:leaves_2:7,100)
RandomBlock(-6,30,2,rustic:iron_lattice,30,rustic:iron_lattice,30,biomesoplenty:leaves_2:7,30,quark:iron_plate_stairs:6,10,quark:iron_plate_stairs:0,10,quark:iron_plate_stairs:5,10,quark:iron_plate_stairs,10,quark:iron_plate_slab:8,10,quark:iron_plate_stairs:7,10,quark:iron_plate_stairs:1,10,quark:iron_plate_slab,10,quark:iron_plate_stairs:4,10,quark:iron_plate_stairs:2,10,rustic:iron_lattice,50,rustic:iron_lattice,50,biomesoplenty:leaves_2:7,100)
RandomBlock(-6,30,3,quark:iron_plate:1,70,STAINED_CLAY:15,30,STAINED_CLAY:7,30,null,30,quark:iron_plate:1,100)
RandomBlock(-6,31,1,rustic:iron_lattice,30,rustic:iron_lattice,30,biomesoplenty:leaves_2:7,30,quark:iron_plate_stairs:6,10,quark:iron_plate_stairs:0,10,quark:iron_plate_stairs:5,10,quark:iron_plate_stairs,10,quark:iron_plate_slab:8,10,quark:iron_plate_stairs:7,10,quark:iron_plate_stairs:1,10,quark:iron_plate_slab,10,quark:iron_plate_stairs:4,10,quark:iron_plate_stairs:2,10,rustic:iron_lattice,50,rustic:iron_lattice,50,biomesoplenty:leaves_2:7,100)
RandomBlock(-6,31,2,quark:iron_plate:1,70,STAINED_CLAY:15,30,STAINED_CLAY:7,30,null,30,quark:iron_plate:1,100)
RandomBlock(-6,31,3,quark:iron_plate:1,70,STAINED_CLAY:15,30,STAINED_CLAY:7,30,null,30,quark:iron_plate:1,100)
RandomBlock(-6,32,1,rustic:iron_lattice,30,rustic:iron_lattice,30,biomesoplenty:leaves_2:7,30,quark:iron_plate_stairs:6,10,quark:iron_plate_stairs:0,10,quark:iron_plate_stairs:5,10,quark:iron_plate_stairs,10,quark:iron_plate_slab:8,10,quark:iron_plate_stairs:7,10,quark:iron_plate_stairs:1,10,quark:iron_plate_slab,10,quark:iron_plate_stairs:4,10,quark:iron_plate_stairs:2,10,rustic:iron_lattice,50,rustic:iron_lattice,50,biomesoplenty:leaves_2:7,100)
RandomBlock(-6,32,2,rustic:iron_lattice,30,rustic:iron_lattice,30,biomesoplenty:leaves_2:7,30,quark:iron_plate_stairs:6,10,quark:iron_plate_stairs:0,10,quark:iron_plate_stairs:5,10,quark:iron_plate_stairs,10,quark:iron_plate_slab:8,10,quark:iron_plate_stairs:7,10,quark:iron_plate_stairs:1,10,quark:iron_plate_slab,10,quark:iron_plate_stairs:4,10,quark:iron_plate_stairs:2,10,rustic:iron_lattice,50,rustic:iron_lattice,50,biomesoplenty:leaves_2:7,100)
RandomBlock(-6,32,3,quark:iron_plate:1,70,STAINED_CLAY:15,30,STAINED_CLAY:7,30,null,30,quark:iron_plate:1,100)
RandomBlock(-6,33,1,rustic:iron_lattice,30,rustic:iron_lattice,30,biomesoplenty:leaves_2:7,30,quark:iron_plate_stairs:6,10,quark:iron_plate_stairs:0,10,quark:iron_plate_stairs:5,10,quark:iron_plate_stairs,10,quark:iron_plate_slab:8,10,quark:iron_plate_stairs:7,10,quark:iron_plate_stairs:1,10,quark:iron_plate_slab,10,quark:iron_plate_stairs:4,10,quark:iron_plate_stairs:2,10,rustic:iron_lattice,50,rustic:iron_lattice,50,biomesoplenty:leaves_2:7,100)
RandomBlock(-6,33,2,quark:iron_plate:1,70,STAINED_CLAY:15,30,STAINED_CLAY:7,30,null,30,quark:iron_plate:1,100)
RandomBlock(-6,33,3,quark:iron_plate:1,70,STAINED_CLAY:15,30,STAINED_CLAY:7,30,null,30,quark:iron_plate:1,100)
RandomBlock(-6,34,1,quark:iron_plate:1,70,STAINED_CLAY:15,30,STAINED_CLAY:7,30,null,30,quark:iron_plate:1,100)
RandomBlock(-6,34,2,quark:iron_plate:1,70,STAINED_CLAY:15,30,STAINED_CLAY:7,30,null,30,quark:iron_plate:1,100)
RandomBlock(-6,34,3,quark:iron_plate:1,70,STAINED_CLAY:15,30,STAINED_CLAY:7,30,null,30,quark:iron_plate:1,100)
RandomBlock(-6,35,1,quark:iron_plate:1,70,STAINED_CLAY:15,30,STAINED_CLAY:7,30,null,30,quark:iron_plate:1,100)
RandomBlock(-6,35,2,quark:iron_plate:1,70,STAINED_CLAY:15,30,STAINED_CLAY:7,30,null,30,quark:iron_plate:1,100)
RandomBlock(-6,35,3,rustic:iron_lattice,30,rustic:iron_lattice,30,biomesoplenty:leaves_2:7,30,quark:iron_plate_stairs:6,10,quark:iron_plate_stairs:0,10,quark:iron_plate_stairs:5,10,quark:iron_plate_stairs,10,quark:iron_plate_slab:8,10,quark:iron_plate_stairs:7,10,quark:iron_plate_stairs:1,10,quark:iron_plate_slab,10,quark:iron_plate_stairs:4,10,quark:iron_plate_stairs:2,10,rustic:iron_lattice,50,rustic:iron_lattice,50,biomesoplenty:leaves_2:7,100)
RandomBlock(-6,36,1,quark:iron_plate:1,70,STAINED_CLAY:15,30,STAINED_CLAY:7,30,null,30,quark:iron_plate:1,100)
RandomBlock(-6,36,2,rustic:iron_lattice,30,rustic:iron_lattice,30,biomesoplenty:leaves_2:7,30,quark:iron_plate_stairs:6,10,quark:iron_plate_stairs:0,10,quark:iron_plate_stairs:5,10,quark:iron_plate_stairs,10,quark:iron_plate_slab:8,10,quark:iron_plate_stairs:7,10,quark:iron_plate_stairs:1,10,quark:iron_plate_slab,10,quark:iron_plate_stairs:4,10,quark:iron_plate_stairs:2,10,rustic:iron_lattice,50,rustic:iron_lattice,50,biomesoplenty:leaves_2:7,100)
RandomBlock(-6,36,3,rustic:iron_lattice,30,rustic:iron_lattice,30,biomesoplenty:leaves_2:7,30,quark:iron_plate_stairs:6,10,quark:iron_plate_stairs:0,10,quark:iron_plate_stairs:5,10,quark:iron_plate_stairs,10,quark:iron_plate_slab:8,10,quark:iron_plate_stairs:7,10,quark:iron_plate_stairs:1,10,quark:iron_plate_slab,10,quark:iron_plate_stairs:4,10,quark:iron_plate_stairs:2,10,rustic:iron_lattice,50,rustic:iron_lattice,50,biomesoplenty:leaves_2:7,100)
RandomBlock(-6,37,1,quark:iron_plate:1,70,STAINED_CLAY:15,30,STAINED_CLAY:7,30,null,30,quark:iron_plate:1,100)
RandomBlock(-6,37,2,rustic:iron_lattice,30,rustic:iron_lattice,30,biomesoplenty:leaves_2:7,30,quark:iron_plate_stairs:6,10,quark:iron_plate_stairs:0,10,quark:iron_plate_stairs:5,10,quark:iron_plate_stairs,10,quark:iron_plate_slab:8,10,quark:iron_plate_stairs:7,10,quark:iron_plate_stairs:1,10,quark:iron_plate_slab,10,quark:iron_plate_stairs:4,10,quark:iron_plate_stairs:2,10,rustic:iron_lattice,50,rustic:iron_lattice,50,biomesoplenty:leaves_2:7,100)
RandomBlock(-6,37,3,rustic:iron_lattice,30,rustic:iron_lattice,30,biomesoplenty:leaves_2:7,30,quark:iron_plate_stairs:6,10,quark:iron_plate_stairs:0,10,quark:iron_plate_stairs:5,10,quark:iron_plate_stairs,10,quark:iron_plate_slab:8,10,quark:iron_plate_stairs:7,10,quark:iron_plate_stairs:1,10,quark:iron_plate_slab,10,quark:iron_plate_stairs:4,10,quark:iron_plate_stairs:2,10,rustic:iron_lattice,50,rustic:iron_lattice,50,biomesoplenty:leaves_2:7,100)
RandomBlock(-6,38,1,quark:iron_plate:1,70,STAINED_CLAY:15,30,STAINED_CLAY:7,30,null,30,quark:iron_plate:1,100)
RandomBlock(-6,38,2,quark:iron_plate:1,70,STAINED_CLAY:15,30,STAINED_CLAY:7,30,null,30,quark:iron_plate:1,100)
RandomBlock(-6,38,3,rustic:iron_lattice,30,rustic:iron_lattice,30,biomesoplenty:leaves_2:7,30,quark:iron_plate_stairs:6,10,quark:iron_plate_stairs:0,10,quark:iron_plate_stairs:5,10,quark:iron_plate_stairs,10,quark:iron_plate_slab:8,10,quark:iron_plate_stairs:7,10,quark:iron_plate_stairs:1,10,quark:iron_plate_slab,10,quark:iron_plate_stairs:4,10,quark:iron_plate_stairs:2,10,rustic:iron_lattice,50,rustic:iron_lattice,50,biomesoplenty:leaves_2:7,100)
RandomBlock(-6,39,1,quark:iron_plate:1,70,STAINED_CLAY:15,30,STAINED_CLAY:7,30,null,30,quark:iron_plate:1,100)
RandomBlock(-6,39,2,quark:iron_plate:1,70,STAINED_CLAY:15,30,STAINED_CLAY:7,30,null,30,quark:iron_plate:1,100)
RandomBlock(-6,39,3,quark:iron_plate:1,70,STAINED_CLAY:15,30,STAINED_CLAY:7,30,null,30,quark:iron_plate:1,100)
RandomBlock(-6,40,1,quark:iron_plate:1,70,STAINED_CLAY:15,30,STAINED_CLAY:7,30,null,30,quark:iron_plate:1,100)
RandomBlock(-6,40,2,quark:iron_plate:1,70,STAINED_CLAY:15,30,STAINED_CLAY:7,30,null,30,quark:iron_plate:1,100)
RandomBlock(-6,40,3,quark:iron_plate:1,70,STAINED_CLAY:15,30,STAINED_CLAY:7,30,null,30,quark:iron_plate:1,100)
RandomBlock(-6,41,1,rustic:iron_lattice,30,rustic:iron_lattice,30,biomesoplenty:leaves_2:7,30,quark:iron_plate_stairs:6,10,quark:iron_plate_stairs:0,10,quark:iron_plate_stairs:5,10,quark:iron_plate_stairs,10,quark:iron_plate_slab:8,10,quark:iron_plate_stairs:7,10,quark:iron_plate_stairs:1,10,quark:iron_plate_slab,10,quark:iron_plate_stairs:4,10,quark:iron_plate_stairs:2,10,rustic:iron_lattice,50,rustic:iron_lattice,50,biomesoplenty:leaves_2:7,100)
RandomBlock(-6,41,2,quark:iron_plate:1,70,STAINED_CLAY:15,30,STAINED_CLAY:7,30,null,30,quark:iron_plate:1,100)
RandomBlock(-6,41,3,quark:iron_plate:1,70,STAINED_CLAY:15,30,STAINED_CLAY:7,30,null,30,quark:iron_plate:1,100)
RandomBlock(-6,42,1,quark:iron_plate:1,70,STAINED_CLAY:15,30,STAINED_CLAY:7,30,null,30,quark:iron_plate:1,100)
RandomBlock(-6,42,2,quark:iron_plate:1,70,STAINED_CLAY:15,30,STAINED_CLAY:7,30,null,30,quark:iron_plate:1,100)
RandomBlock(-6,42,3,quark:iron_plate:1,70,STAINED_CLAY:15,30,STAINED_CLAY:7,30,null,30,quark:iron_plate:1,100)
RandomBlock(-6,43,1,rustic:iron_lattice,30,rustic:iron_lattice,30,biomesoplenty:leaves_2:7,30,quark:iron_plate_stairs:6,10,quark:iron_plate_stairs:0,10,quark:iron_plate_stairs:5,10,quark:iron_plate_stairs,10,quark:iron_plate_slab:8,10,quark:iron_plate_stairs:7,10,quark:iron_plate_stairs:1,10,quark:iron_plate_slab,10,quark:iron_plate_stairs:4,10,quark:iron_plate_stairs:2,10,rustic:iron_lattice,50,rustic:iron_lattice,50,biomesoplenty:leaves_2:7,100)
RandomBlock(-6,43,2,quark:iron_plate:1,70,STAINED_CLAY:15,30,STAINED_CLAY:7,30,null,30,quark:iron_plate:1,100)
RandomBlock(-6,43,3,rustic:iron_lattice,30,rustic:iron_lattice,30,biomesoplenty:leaves_2:7,30,quark:iron_plate_stairs:6,10,quark:iron_plate_stairs:0,10,quark:iron_plate_stairs:5,10,quark:iron_plate_stairs,10,quark:iron_plate_slab:8,10,quark:iron_plate_stairs:7,10,quark:iron_plate_stairs:1,10,quark:iron_plate_slab,10,quark:iron_plate_stairs:4,10,quark:iron_plate_stairs:2,10,rustic:iron_lattice,50,rustic:iron_lattice,50,biomesoplenty:leaves_2:7,100)
RandomBlock(-6,44,1,quark:iron_plate:1,70,STAINED_CLAY:15,30,STAINED_CLAY:7,30,null,30,quark:iron_plate:1,100)
RandomBlock(-6,44,2,quark:iron_plate:1,70,STAINED_CLAY:15,30,STAINED_CLAY:7,30,null,30,quark:iron_plate:1,100)
RandomBlock(-6,44,3,quark:iron_plate:1,70,STAINED_CLAY:15,30,STAINED_CLAY:7,30,null,30,quark:iron_plate:1,100)
RandomBlock(-6,45,1,rustic:iron_lattice,30,rustic:iron_lattice,30,biomesoplenty:leaves_2:7,30,quark:iron_plate_stairs:6,10,quark:iron_plate_stairs:0,10,quark:iron_plate_stairs:5,10,quark:iron_plate_stairs,10,quark:iron_plate_slab:8,10,quark:iron_plate_stairs:7,10,quark:iron_plate_stairs:1,10,quark:iron_plate_slab,10,quark:iron_plate_stairs:4,10,quark:iron_plate_stairs:2,10,rustic:iron_lattice,50,rustic:iron_lattice,50,biomesoplenty:leaves_2:7,100)
RandomBlock(-6,45,2,quark:iron_plate:1,70,STAINED_CLAY:15,30,STAINED_CLAY:7,30,null,30,quark:iron_plate:1,100)
RandomBlock(-6,45,3,rustic:iron_lattice,30,rustic:iron_lattice,30,biomesoplenty:leaves_2:7,30,quark:iron_plate_stairs:6,10,quark:iron_plate_stairs:0,10,quark:iron_plate_stairs:5,10,quark:iron_plate_stairs,10,quark:iron_plate_slab:8,10,quark:iron_plate_stairs:7,10,quark:iron_plate_stairs:1,10,quark:iron_plate_slab,10,quark:iron_plate_stairs:4,10,quark:iron_plate_stairs:2,10,rustic:iron_lattice,50,rustic:iron_lattice,50,biomesoplenty:leaves_2:7,100)
RandomBlock(-6,46,1,quark:iron_plate:1,70,STAINED_CLAY:15,30,STAINED_CLAY:7,30,null,30,quark:iron_plate:1,100)
RandomBlock(-6,46,2,quark:iron_plate:1,70,STAINED_CLAY:15,30,STAINED_CLAY:7,30,null,30,quark:iron_plate:1,100)
RandomBlock(-6,46,3,rustic:iron_lattice,30,rustic:iron_lattice,30,biomesoplenty:leaves_2:7,30,quark:iron_plate_stairs:6,10,quark:iron_plate_stairs:0,10,quark:iron_plate_stairs:5,10,quark:iron_plate_stairs,10,quark:iron_plate_slab:8,10,quark:iron_plate_stairs:7,10,quark:iron_plate_stairs:1,10,quark:iron_plate_slab,10,quark:iron_plate_stairs:4,10,quark:iron_plate_stairs:2,10,rustic:iron_lattice,50,rustic:iron_lattice,50,biomesoplenty:leaves_2:7,100)
RandomBlock(-6,47,1,rustic:iron_lattice,30,rustic:iron_lattice,30,biomesoplenty:leaves_2:7,30,quark:iron_plate_stairs:6,10,quark:iron_plate_stairs:0,10,quark:iron_plate_stairs:5,10,quark:iron_plate_stairs,10,quark:iron_plate_slab:8,10,quark:iron_plate_stairs:7,10,quark:iron_plate_stairs:1,10,quark:iron_plate_slab,10,quark:iron_plate_stairs:4,10,quark:iron_plate_stairs:2,10,rustic:iron_lattice,50,rustic:iron_lattice,50,biomesoplenty:leaves_2:7,100)
RandomBlock(-6,47,2,rustic:iron_lattice,30,rustic:iron_lattice,30,biomesoplenty:leaves_2:7,30,quark:iron_plate_stairs:6,10,quark:iron_plate_stairs:0,10,quark:iron_plate_stairs:5,10,quark:iron_plate_stairs,10,quark:iron_plate_slab:8,10,quark:iron_plate_stairs:7,10,quark:iron_plate_stairs:1,10,quark:iron_plate_slab,10,quark:iron_plate_stairs:4,10,quark:iron_plate_stairs:2,10,rustic:iron_lattice,50,rustic:iron_lattice,50,biomesoplenty:leaves_2:7,100)
RandomBlock(-6,47,3,rustic:iron_lattice,30,rustic:iron_lattice,30,biomesoplenty:leaves_2:7,30,quark:iron_plate_stairs:6,10,quark:iron_plate_stairs:0,10,quark:iron_plate_stairs:5,10,quark:iron_plate_stairs,10,quark:iron_plate_slab:8,10,quark:iron_plate_stairs:7,10,quark:iron_plate_stairs:1,10,quark:iron_plate_slab,10,quark:iron_plate_stairs:4,10,quark:iron_plate_stairs:2,10,rustic:iron_lattice,50,rustic:iron_lattice,50,biomesoplenty:leaves_2:7,100)
RandomBlock(-6,48,1,rustic:iron_lattice,30,rustic:iron_lattice,30,biomesoplenty:leaves_2:7,30,quark:iron_plate_stairs:6,10,quark:iron_plate_stairs:0,10,quark:iron_plate_stairs:5,10,quark:iron_plate_stairs,10,quark:iron_plate_slab:8,10,quark:iron_plate_stairs:7,10,quark:iron_plate_stairs:1,10,quark:iron_plate_slab,10,quark:iron_plate_stairs:4,10,quark:iron_plate_stairs:2,10,rustic:iron_lattice,50,rustic:iron_lattice,50,biomesoplenty:leaves_2:7,100)
RandomBlock(-6,48,2,rustic:iron_lattice,30,rustic:iron_lattice,30,biomesoplenty:leaves_2:7,30,quark:iron_plate_stairs:6,10,quark:iron_plate_stairs:0,10,quark:iron_plate_stairs:5,10,quark:iron_plate_stairs,10,quark:iron_plate_slab:8,10,quark:iron_plate_stairs:7,10,quark:iron_plate_stairs:1,10,quark:iron_plate_slab,10,quark:iron_plate_stairs:4,10,quark:iron_plate_stairs:2,10,rustic:iron_lattice,50,rustic:iron_lattice,50,biomesoplenty:leaves_2:7,100)
RandomBlock(-6,48,3,rustic:iron_lattice,30,rustic:iron_lattice,30,biomesoplenty:leaves_2:7,30,quark:iron_plate_stairs:6,10,quark:iron_plate_stairs:0,10,quark:iron_plate_stairs:5,10,quark:iron_plate_stairs,10,quark:iron_plate_slab:8,10,quark:iron_plate_stairs:7,10,quark:iron_plate_stairs:1,10,quark:iron_plate_slab,10,quark:iron_plate_stairs:4,10,quark:iron_plate_stairs:2,10,rustic:iron_lattice,50,rustic:iron_lattice,50,biomesoplenty:leaves_2:7,100)
RandomBlock(-6,49,1,rustic:iron_lattice,30,rustic:iron_lattice,30,biomesoplenty:leaves_2:7,30,quark:iron_plate_stairs:6,10,quark:iron_plate_stairs:0,10,quark:iron_plate_stairs:5,10,quark:iron_plate_stairs,10,quark:iron_plate_slab:8,10,quark:iron_plate_stairs:7,10,quark:iron_plate_stairs:1,10,quark:iron_plate_slab,10,quark:iron_plate_stairs:4,10,quark:iron_plate_stairs:2,10,rustic:iron_lattice,50,rustic:iron_lattice,50,biomesoplenty:leaves_2:7,100)
RandomBlock(-6,49,2,rustic:iron_lattice,30,rustic:iron_lattice,30,biomesoplenty:leaves_2:7,30,quark:iron_plate_stairs:6,10,quark:iron_plate_stairs:0,10,quark:iron_plate_stairs:5,10,quark:iron_plate_stairs,10,quark:iron_plate_slab:8,10,quark:iron_plate_stairs:7,10,quark:iron_plate_stairs:1,10,quark:iron_plate_slab,10,quark:iron_plate_stairs:4,10,quark:iron_plate_stairs:2,10,rustic:iron_lattice,50,rustic:iron_lattice,50,biomesoplenty:leaves_2:7,100)
RandomBlock(-6,49,3,rustic:iron_lattice,30,rustic:iron_lattice,30,biomesoplenty:leaves_2:7,30,quark:iron_plate_stairs:6,10,quark:iron_plate_stairs:0,10,quark:iron_plate_stairs:5,10,quark:iron_plate_stairs,10,quark:iron_plate_slab:8,10,quark:iron_plate_stairs:7,10,quark:iron_plate_stairs:1,10,quark:iron_plate_slab,10,quark:iron_plate_stairs:4,10,quark:iron_plate_stairs:2,10,rustic:iron_lattice,50,rustic:iron_lattice,50,biomesoplenty:leaves_2:7,100)
RandomBlock(-6,50,1,rustic:iron_lattice,30,rustic:iron_lattice,30,biomesoplenty:leaves_2:7,30,quark:iron_plate_stairs:6,10,quark:iron_plate_stairs:0,10,quark:iron_plate_stairs:5,10,quark:iron_plate_stairs,10,quark:iron_plate_slab:8,10,quark:iron_plate_stairs:7,10,quark:iron_plate_stairs:1,10,quark:iron_plate_slab,10,quark:iron_plate_stairs:4,10,quark:iron_plate_stairs:2,10,rustic:iron_lattice,50,rustic:iron_lattice,50,biomesoplenty:leaves_2:7,100)
RandomBlock(-6,50,2,quark:iron_plate:1,70,STAINED_CLAY:15,30,STAINED_CLAY:7,30,null,30,quark:iron_plate:1,100)
RandomBlock(-6,50,3,rustic:iron_lattice,30,rustic:iron_lattice,30,biomesoplenty:leaves_2:7,30,quark:iron_plate_stairs:6,10,quark:iron_plate_stairs:0,10,quark:iron_plate_stairs:5,10,quark:iron_plate_stairs,10,quark:iron_plate_slab:8,10,quark:iron_plate_stairs:7,10,quark:iron_plate_stairs:1,10,quark:iron_plate_slab,10,quark:iron_plate_stairs:4,10,quark:iron_plate_stairs:2,10,rustic:iron_lattice,50,rustic:iron_lattice,50,biomesoplenty:leaves_2:7,100)
RandomBlock(-6,51,1,rustic:iron_lattice,30,rustic:iron_lattice,30,biomesoplenty:leaves_2:7,30,quark:iron_plate_stairs:6,10,quark:iron_plate_stairs:0,10,quark:iron_plate_stairs:5,10,quark:iron_plate_stairs,10,quark:iron_plate_slab:8,10,quark:iron_plate_stairs:7,10,quark:iron_plate_stairs:1,10,quark:iron_plate_slab,10,quark:iron_plate_stairs:4,10,quark:iron_plate_stairs:2,10,rustic:iron_lattice,50,rustic:iron_lattice,50,biomesoplenty:leaves_2:7,100)
RandomBlock(-6,51,2,rustic:iron_lattice,30,rustic:iron_lattice,30,biomesoplenty:leaves_2:7,30,quark:iron_plate_stairs:6,10,quark:iron_plate_stairs:0,10,quark:iron_plate_stairs:5,10,quark:iron_plate_stairs,10,quark:iron_plate_slab:8,10,quark:iron_plate_stairs:7,10,quark:iron_plate_stairs:1,10,quark:iron_plate_slab,10,quark:iron_plate_stairs:4,10,quark:iron_plate_stairs:2,10,rustic:iron_lattice,50,rustic:iron_lattice,50,biomesoplenty:leaves_2:7,100)
RandomBlock(-6,51,3,rustic:iron_lattice,30,rustic:iron_lattice,30,biomesoplenty:leaves_2:7,30,quark:iron_plate_stairs:6,10,quark:iron_plate_stairs:0,10,quark:iron_plate_stairs:5,10,quark:iron_plate_stairs,10,quark:iron_plate_slab:8,10,quark:iron_plate_stairs:7,10,quark:iron_plate_stairs:1,10,quark:iron_plate_slab,10,quark:iron_plate_stairs:4,10,quark:iron_plate_stairs:2,10,rustic:iron_lattice,50,rustic:iron_lattice,50,biomesoplenty:leaves_2:7,100)
RandomBlock(-6,52,1,rustic:iron_lattice,30,rustic:iron_lattice,30,biomesoplenty:leaves_2:7,30,quark:iron_plate_stairs:6,10,quark:iron_plate_stairs:0,10,quark:iron_plate_stairs:5,10,quark:iron_plate_stairs,10,quark:iron_plate_slab:8,10,quark:iron_plate_stairs:7,10,quark:iron_plate_stairs:1,10,quark:iron_plate_slab,10,quark:iron_plate_stairs:4,10,quark:iron_plate_stairs:2,10,rustic:iron_lattice,50,rustic:iron_lattice,50,biomesoplenty:leaves_2:7,100)
RandomBlock(-6,52,2,quark:iron_plate:1,70,STAINED_CLAY:15,30,STAINED_CLAY:7,30,null,30,quark:iron_plate:1,100)
RandomBlock(-6,52,3,quark:iron_plate:1,70,STAINED_CLAY:15,30,STAINED_CLAY:7,30,null,30,quark:iron_plate:1,100)
RandomBlock(-6,53,1,quark:iron_plate:1,70,STAINED_CLAY:15,30,STAINED_CLAY:7,30,null,30,quark:iron_plate:1,100)
RandomBlock(-6,53,2,quark:iron_plate:1,70,STAINED_CLAY:15,30,STAINED_CLAY:7,30,null,30,quark:iron_plate:1,100)
RandomBlock(-6,53,3,quark:iron_plate:1,70,STAINED_CLAY:15,30,STAINED_CLAY:7,30,null,30,quark:iron_plate:1,100)
RandomBlock(-6,54,1,quark:iron_plate:1,70,STAINED_CLAY:15,30,STAINED_CLAY:7,30,null,30,quark:iron_plate:1,100)
RandomBlock(-6,54,2,quark:iron_plate:1,70,STAINED_CLAY:15,30,STAINED_CLAY:7,30,null,30,quark:iron_plate:1,100)
RandomBlock(-6,54,3,quark:iron_plate:1,70,STAINED_CLAY:15,30,STAINED_CLAY:7,30,null,30,quark:iron_plate:1,100)
RandomBlock(-6,55,1,quark:iron_plate:1,70,STAINED_CLAY:15,30,STAINED_CLAY:7,30,null,30,quark:iron_plate:1,100)
RandomBlock(-6,55,2,quark:iron_plate:1,70,STAINED_CLAY:15,30,STAINED_CLAY:7,30,null,30,quark:iron_plate:1,100)
RandomBlock(-6,55,3,quark:iron_plate:1,70,STAINED_CLAY:15,30,STAINED_CLAY:7,30,null,30,quark:iron_plate:1,100)
RandomBlock(-6,56,1,quark:iron_plate:1,70,STAINED_CLAY:15,30,STAINED_CLAY:7,30,null,30,quark:iron_plate:1,100)
RandomBlock(-6,56,2,quark:iron_plate:1,70,STAINED_CLAY:15,30,STAINED_CLAY:7,30,null,30,quark:iron_plate:1,100)
RandomBlock(-6,56,3,quark:iron_plate:1,70,STAINED_CLAY:15,30,STAINED_CLAY:7,30,null,30,quark:iron_plate:1,100)
RandomBlock(-6,57,1,quark:iron_plate:1,70,STAINED_CLAY:15,30,STAINED_CLAY:7,30,null,30,quark:iron_plate:1,100)
RandomBlock(-6,57,2,quark:iron_plate:1,70,STAINED_CLAY:15,30,STAINED_CLAY:7,30,null,30,quark:iron_plate:1,100)
RandomBlock(-6,57,3,quark:iron_plate:1,70,STAINED_CLAY:15,30,STAINED_CLAY:7,30,null,30,quark:iron_plate:1,100)
RandomBlock(-6,58,1,quark:iron_plate:1,70,STAINED_CLAY:15,30,STAINED_CLAY:7,30,null,30,quark:iron_plate:1,100)
RandomBlock(-6,58,2,quark:iron_plate:1,70,STAINED_CLAY:15,30,STAINED_CLAY:7,30,null,30,quark:iron_plate:1,100)
RandomBlock(-6,58,3,quark:iron_plate:1,70,STAINED_CLAY:15,30,STAINED_CLAY:7,30,null,30,quark:iron_plate:1,100)
RandomBlock(-6,59,1,quark:iron_plate:1,70,STAINED_CLAY:15,30,STAINED_CLAY:7,30,null,30,quark:iron_plate:1,100)
RandomBlock(-6,59,2,quark:iron_plate:1,70,STAINED_CLAY:15,30,STAINED_CLAY:7,30,null,30,quark:iron_plate:1,100)
RandomBlock(-6,59,3,quark:iron_plate:1,70,STAINED_CLAY:15,30,STAINED_CLAY:7,30,null,30,quark:iron_plate:1,100)
RandomBlock(-6,60,1,quark:iron_plate:1,70,STAINED_CLAY:15,30,STAINED_CLAY:7,30,null,30,quark:iron_plate:1,100)
RandomBlock(-6,60,2,quark:iron_plate:1,70,STAINED_CLAY:15,30,STAINED_CLAY:7,30,null,30,quark:iron_plate:1,100)
RandomBlock(-6,60,3,quark:iron_plate:1,70,STAINED_CLAY:15,30,STAINED_CLAY:7,30,null,30,quark:iron_plate:1,100)
RandomBlock(-6,61,1,quark:iron_plate:1,70,STAINED_CLAY:15,30,STAINED_CLAY:7,30,null,30,quark:iron_plate:1,100)
RandomBlock(-6,61,2,quark:iron_plate:1,70,STAINED_CLAY:15,30,STAINED_CLAY:7,30,null,30,quark:iron_plate:1,100)
RandomBlock(-6,61,3,quark:iron_plate:1,70,STAINED_CLAY:15,30,STAINED_CLAY:7,30,null,30,quark:iron_plate:1,100)
RandomBlock(-6,62,1,quark:iron_plate:1,70,STAINED_CLAY:15,30,STAINED_CLAY:7,30,null,30,quark:iron_plate:1,100)
RandomBlock(-6,62,2,quark:iron_plate:1,70,STAINED_CLAY:15,30,STAINED_CLAY:7,30,null,30,quark:iron_plate:1,100)
RandomBlock(-6,62,3,quark:iron_plate:1,70,STAINED_CLAY:15,30,STAINED_CLAY:7,30,null,30,quark:iron_plate:1,100)
RandomBlock(-6,63,1,quark:iron_plate:1,70,STAINED_CLAY:15,30,STAINED_CLAY:7,30,null,30,quark:iron_plate:1,100)
RandomBlock(-6,63,2,quark:iron_plate:1,70,STAINED_CLAY:15,30,STAINED_CLAY:7,30,null,30,quark:iron_plate:1,100)
RandomBlock(-6,63,3,quark:iron_plate:1,70,STAINED_CLAY:15,30,STAINED_CLAY:7,30,null,30,quark:iron_plate:1,100)
RandomBlock(-6,64,1,quark:iron_plate:1,70,STAINED_CLAY:15,30,STAINED_CLAY:7,30,null,30,quark:iron_plate:1,100)
RandomBlock(-6,64,2,quark:iron_plate:1,70,STAINED_CLAY:15,30,STAINED_CLAY:7,30,null,30,quark:iron_plate:1,100)
RandomBlock(-6,64,3,quark:iron_plate:1,70,STAINED_CLAY:15,30,STAINED_CLAY:7,30,null,30,quark:iron_plate:1,100)
RandomBlock(-6,65,1,quark:iron_plate:1,70,STAINED_CLAY:15,30,STAINED_CLAY:7,30,null,30,quark:iron_plate:1,100)
RandomBlock(-6,65,2,quark:iron_plate:1,70,STAINED_CLAY:15,30,STAINED_CLAY:7,30,null,30,quark:iron_plate:1,100)
RandomBlock(-6,65,3,quark:iron_plate:1,70,STAINED_CLAY:15,30,STAINED_CLAY:7,30,null,30,quark:iron_plate:1,100)
RandomBlock(-5,0,1,quark:iron_plate:1,70,STAINED_CLAY:15,30,STAINED_CLAY:7,30,null,30,quark:iron_plate:1,100)
Block(-5,0,2,AIR:0)
RandomBlock(-5,0,3,quark:iron_plate:1,70,STAINED_CLAY:15,30,STAINED_CLAY:7,30,null,30,quark:iron_plate:1,100)
RandomBlock(-5,1,1,quark:iron_plate:1,70,STAINED_CLAY:15,30,STAINED_CLAY:7,30,null,30,quark:iron_plate:1,100)
Block(-5,1,2,AIR:0)
RandomBlock(-5,1,3,quark:iron_plate:1,70,STAINED_CLAY:15,30,STAINED_CLAY:7,30,null,30,quark:iron_plate:1,100)
RandomBlock(-5,2,1,rustic:iron_lattice,30,rustic:iron_lattice,30,biomesoplenty:leaves_2:7,30,quark:iron_plate_stairs:6,10,quark:iron_plate_stairs:0,10,quark:iron_plate_stairs:5,10,quark:iron_plate_stairs,10,quark:iron_plate_slab:8,10,quark:iron_plate_stairs:7,10,quark:iron_plate_stairs:1,10,quark:iron_plate_slab,10,quark:iron_plate_stairs:4,10,quark:iron_plate_stairs:2,10,rustic:iron_lattice,50,rustic:iron_lattice,50,biomesoplenty:leaves_2:7,100)
Block(-5,2,2,AIR:0)
RandomBlock(-5,2,3,quark:iron_plate:1,70,STAINED_CLAY:15,30,STAINED_CLAY:7,30,null,30,quark:iron_plate:1,100)
RandomBlock(-5,3,1,rustic:iron_lattice,30,rustic:iron_lattice,30,biomesoplenty:leaves_2:7,30,quark:iron_plate_stairs:6,10,quark:iron_plate_stairs:0,10,quark:iron_plate_stairs:5,10,quark:iron_plate_stairs,10,quark:iron_plate_slab:8,10,quark:iron_plate_stairs:7,10,quark:iron_plate_stairs:1,10,quark:iron_plate_slab,10,quark:iron_plate_stairs:4,10,quark:iron_plate_stairs:2,10,rustic:iron_lattice,50,rustic:iron_lattice,50,biomesoplenty:leaves_2:7,100)
Block(-5,3,2,AIR:0)
RandomBlock(-5,3,3,rustic:iron_lattice,30,rustic:iron_lattice,30,biomesoplenty:leaves_2:7,30,quark:iron_plate_stairs:6,10,quark:iron_plate_stairs:0,10,quark:iron_plate_stairs:5,10,quark:iron_plate_stairs,10,quark:iron_plate_slab:8,10,quark:iron_plate_stairs:7,10,quark:iron_plate_stairs:1,10,quark:iron_plate_slab,10,quark:iron_plate_stairs:4,10,quark:iron_plate_stairs:2,10,rustic:iron_lattice,50,rustic:iron_lattice,50,biomesoplenty:leaves_2:7,100)
RandomBlock(-5,4,1,quark:iron_plate:1,70,STAINED_CLAY:15,30,STAINED_CLAY:7,30,null,30,quark:iron_plate:1,100)
Block(-5,4,2,AIR:0)
RandomBlock(-5,4,3,rustic:iron_lattice,30,rustic:iron_lattice,30,biomesoplenty:leaves_2:7,30,quark:iron_plate_stairs:6,10,quark:iron_plate_stairs:0,10,quark:iron_plate_stairs:5,10,quark:iron_plate_stairs,10,quark:iron_plate_slab:8,10,quark:iron_plate_stairs:7,10,quark:iron_plate_stairs:1,10,quark:iron_plate_slab,10,quark:iron_plate_stairs:4,10,quark:iron_plate_stairs:2,10,rustic:iron_lattice,50,rustic:iron_lattice,50,biomesoplenty:leaves_2:7,100)
RandomBlock(-5,5,1,quark:iron_plate:1,70,STAINED_CLAY:15,30,STAINED_CLAY:7,30,null,30,quark:iron_plate:1,100)
Block(-5,5,2,AIR:0)
RandomBlock(-5,5,3,rustic:iron_lattice,30,rustic:iron_lattice,30,biomesoplenty:leaves_2:7,30,quark:iron_plate_stairs:6,10,quark:iron_plate_stairs:0,10,quark:iron_plate_stairs:5,10,quark:iron_plate_stairs,10,quark:iron_plate_slab:8,10,quark:iron_plate_stairs:7,10,quark:iron_plate_stairs:1,10,quark:iron_plate_slab,10,quark:iron_plate_stairs:4,10,quark:iron_plate_stairs:2,10,rustic:iron_lattice,50,rustic:iron_lattice,50,biomesoplenty:leaves_2:7,100)
RandomBlock(-5,6,1,rustic:iron_lattice,30,rustic:iron_lattice,30,biomesoplenty:leaves_2:7,30,quark:iron_plate_stairs:6,10,quark:iron_plate_stairs:0,10,quark:iron_plate_stairs:5,10,quark:iron_plate_stairs,10,quark:iron_plate_slab:8,10,quark:iron_plate_stairs:7,10,quark:iron_plate_stairs:1,10,quark:iron_plate_slab,10,quark:iron_plate_stairs:4,10,quark:iron_plate_stairs:2,10,rustic:iron_lattice,50,rustic:iron_lattice,50,biomesoplenty:leaves_2:7,100)
Block(-5,6,2,AIR:0)
RandomBlock(-5,6,3,quark:iron_plate:1,70,STAINED_CLAY:15,30,STAINED_CLAY:7,30,null,30,quark:iron_plate:1,100)
RandomBlock(-5,7,1,rustic:iron_lattice,30,rustic:iron_lattice,30,biomesoplenty:leaves_2:7,30,quark:iron_plate_stairs:6,10,quark:iron_plate_stairs:0,10,quark:iron_plate_stairs:5,10,quark:iron_plate_stairs,10,quark:iron_plate_slab:8,10,quark:iron_plate_stairs:7,10,quark:iron_plate_stairs:1,10,quark:iron_plate_slab,10,quark:iron_plate_stairs:4,10,quark:iron_plate_stairs:2,10,rustic:iron_lattice,50,rustic:iron_lattice,50,biomesoplenty:leaves_2:7,100)
Block(-5,7,2,AIR:0)
RandomBlock(-5,7,3,rustic:iron_lattice,30,rustic:iron_lattice,30,biomesoplenty:leaves_2:7,30,quark:iron_plate_stairs:6,10,quark:iron_plate_stairs:0,10,quark:iron_plate_stairs:5,10,quark:iron_plate_stairs,10,quark:iron_plate_slab:8,10,quark:iron_plate_stairs:7,10,quark:iron_plate_stairs:1,10,quark:iron_plate_slab,10,quark:iron_plate_stairs:4,10,quark:iron_plate_stairs:2,10,rustic:iron_lattice,50,rustic:iron_lattice,50,biomesoplenty:leaves_2:7,100)
RandomBlock(-5,8,1,rustic:iron_lattice,30,rustic:iron_lattice,30,biomesoplenty:leaves_2:7,30,quark:iron_plate_stairs:6,10,quark:iron_plate_stairs:0,10,quark:iron_plate_stairs:5,10,quark:iron_plate_stairs,10,quark:iron_plate_slab:8,10,quark:iron_plate_stairs:7,10,quark:iron_plate_stairs:1,10,quark:iron_plate_slab,10,quark:iron_plate_stairs:4,10,quark:iron_plate_stairs:2,10,rustic:iron_lattice,50,rustic:iron_lattice,50,biomesoplenty:leaves_2:7,100)
Block(-5,8,2,AIR:0)
RandomBlock(-5,8,3,rustic:iron_lattice,30,rustic:iron_lattice,30,biomesoplenty:leaves_2:7,30,quark:iron_plate_stairs:6,10,quark:iron_plate_stairs:0,10,quark:iron_plate_stairs:5,10,quark:iron_plate_stairs,10,quark:iron_plate_slab:8,10,quark:iron_plate_stairs:7,10,quark:iron_plate_stairs:1,10,quark:iron_plate_slab,10,quark:iron_plate_stairs:4,10,quark:iron_plate_stairs:2,10,rustic:iron_lattice,50,rustic:iron_lattice,50,biomesoplenty:leaves_2:7,100)
RandomBlock(-5,9,1,rustic:iron_lattice,30,rustic:iron_lattice,30,biomesoplenty:leaves_2:7,30,quark:iron_plate_stairs:6,10,quark:iron_plate_stairs:0,10,quark:iron_plate_stairs:5,10,quark:iron_plate_stairs,10,quark:iron_plate_slab:8,10,quark:iron_plate_stairs:7,10,quark:iron_plate_stairs:1,10,quark:iron_plate_slab,10,quark:iron_plate_stairs:4,10,quark:iron_plate_stairs:2,10,rustic:iron_lattice,50,rustic:iron_lattice,50,biomesoplenty:leaves_2:7,100)
Block(-5,9,2,AIR:0)
RandomBlock(-5,9,3,rustic:iron_lattice,30,rustic:iron_lattice,30,biomesoplenty:leaves_2:7,30,quark:iron_plate_stairs:6,10,quark:iron_plate_stairs:0,10,quark:iron_plate_stairs:5,10,quark:iron_plate_stairs,10,quark:iron_plate_slab:8,10,quark:iron_plate_stairs:7,10,quark:iron_plate_stairs:1,10,quark:iron_plate_slab,10,quark:iron_plate_stairs:4,10,quark:iron_plate_stairs:2,10,rustic:iron_lattice,50,rustic:iron_lattice,50,biomesoplenty:leaves_2:7,100)
RandomBlock(-5,10,1,rustic:iron_lattice,30,rustic:iron_lattice,30,biomesoplenty:leaves_2:7,30,quark:iron_plate_stairs:6,10,quark:iron_plate_stairs:0,10,quark:iron_plate_stairs:5,10,quark:iron_plate_stairs,10,quark:iron_plate_slab:8,10,quark:iron_plate_stairs:7,10,quark:iron_plate_stairs:1,10,quark:iron_plate_slab,10,quark:iron_plate_stairs:4,10,quark:iron_plate_stairs:2,10,rustic:iron_lattice,50,rustic:iron_lattice,50,biomesoplenty:leaves_2:7,100)
Block(-5,10,2,AIR:0)
RandomBlock(-5,10,3,quark:iron_plate:1,70,STAINED_CLAY:15,30,STAINED_CLAY:7,30,null,30,quark:iron_plate:1,100)
RandomBlock(-5,11,1,quark:iron_plate:1,70,STAINED_CLAY:15,30,STAINED_CLAY:7,30,null,30,quark:iron_plate:1,100)
Block(-5,11,2,AIR:0)
RandomBlock(-5,11,3,quark:iron_plate:1,70,STAINED_CLAY:15,30,STAINED_CLAY:7,30,null,30,quark:iron_plate:1,100)
RandomBlock(-5,12,1,quark:iron_plate:1,70,STAINED_CLAY:15,30,STAINED_CLAY:7,30,null,30,quark:iron_plate:1,100)
Block(-5,12,2,AIR:0)
RandomBlock(-5,12,3,quark:iron_plate:1,70,STAINED_CLAY:15,30,STAINED_CLAY:7,30,null,30,quark:iron_plate:1,100)
RandomBlock(-5,13,1,rustic:iron_lattice,30,rustic:iron_lattice,30,biomesoplenty:leaves_2:7,30,quark:iron_plate_stairs:6,10,quark:iron_plate_stairs:0,10,quark:iron_plate_stairs:5,10,quark:iron_plate_stairs,10,quark:iron_plate_slab:8,10,quark:iron_plate_stairs:7,10,quark:iron_plate_stairs:1,10,quark:iron_plate_slab,10,quark:iron_plate_stairs:4,10,quark:iron_plate_stairs:2,10,rustic:iron_lattice,50,rustic:iron_lattice,50,biomesoplenty:leaves_2:7,100)
Block(-5,13,2,AIR:0)
RandomBlock(-5,13,3,quark:iron_plate:1,70,STAINED_CLAY:15,30,STAINED_CLAY:7,30,null,30,quark:iron_plate:1,100)
RandomBlock(-5,14,1,quark:iron_plate:1,70,STAINED_CLAY:15,30,STAINED_CLAY:7,30,null,30,quark:iron_plate:1,100)
Block(-5,14,2,AIR:0)
RandomBlock(-5,14,3,quark:iron_plate:1,70,STAINED_CLAY:15,30,STAINED_CLAY:7,30,null,30,quark:iron_plate:1,100)
RandomBlock(-5,15,1,rustic:iron_lattice,30,rustic:iron_lattice,30,biomesoplenty:leaves_2:7,30,quark:iron_plate_stairs:6,10,quark:iron_plate_stairs:0,10,quark:iron_plate_stairs:5,10,quark:iron_plate_stairs,10,quark:iron_plate_slab:8,10,quark:iron_plate_stairs:7,10,quark:iron_plate_stairs:1,10,quark:iron_plate_slab,10,quark:iron_plate_stairs:4,10,quark:iron_plate_stairs:2,10,rustic:iron_lattice,50,rustic:iron_lattice,50,biomesoplenty:leaves_2:7,100)
Block(-5,15,2,AIR:0)
RandomBlock(-5,15,3,quark:iron_plate:1,70,STAINED_CLAY:15,30,STAINED_CLAY:7,30,null,30,quark:iron_plate:1,100)
RandomBlock(-5,16,1,rustic:iron_lattice,30,rustic:iron_lattice,30,biomesoplenty:leaves_2:7,30,quark:iron_plate_stairs:6,10,quark:iron_plate_stairs:0,10,quark:iron_plate_stairs:5,10,quark:iron_plate_stairs,10,quark:iron_plate_slab:8,10,quark:iron_plate_stairs:7,10,quark:iron_plate_stairs:1,10,quark:iron_plate_slab,10,quark:iron_plate_stairs:4,10,quark:iron_plate_stairs:2,10,rustic:iron_lattice,50,rustic:iron_lattice,50,biomesoplenty:leaves_2:7,100)
Block(-5,16,2,AIR:0)
RandomBlock(-5,16,3,quark:iron_plate:1,70,STAINED_CLAY:15,30,STAINED_CLAY:7,30,null,30,quark:iron_plate:1,100)
RandomBlock(-5,17,1,rustic:iron_lattice,30,rustic:iron_lattice,30,biomesoplenty:leaves_2:7,30,quark:iron_plate_stairs:6,10,quark:iron_plate_stairs:0,10,quark:iron_plate_stairs:5,10,quark:iron_plate_stairs,10,quark:iron_plate_slab:8,10,quark:iron_plate_stairs:7,10,quark:iron_plate_stairs:1,10,quark:iron_plate_slab,10,quark:iron_plate_stairs:4,10,quark:iron_plate_stairs:2,10,rustic:iron_lattice,50,rustic:iron_lattice,50,biomesoplenty:leaves_2:7,100)
Block(-5,17,2,AIR:0)
RandomBlock(-5,17,3,quark:iron_plate:1,70,STAINED_CLAY:15,30,STAINED_CLAY:7,30,null,30,quark:iron_plate:1,100)
RandomBlock(-5,18,1,rustic:iron_lattice,30,rustic:iron_lattice,30,biomesoplenty:leaves_2:7,30,quark:iron_plate_stairs:6,10,quark:iron_plate_stairs:0,10,quark:iron_plate_stairs:5,10,quark:iron_plate_stairs,10,quark:iron_plate_slab:8,10,quark:iron_plate_stairs:7,10,quark:iron_plate_stairs:1,10,quark:iron_plate_slab,10,quark:iron_plate_stairs:4,10,quark:iron_plate_stairs:2,10,rustic:iron_lattice,50,rustic:iron_lattice,50,biomesoplenty:leaves_2:7,100)
Block(-5,18,2,AIR:0)
RandomBlock(-5,18,3,quark:iron_plate:1,70,STAINED_CLAY:15,30,STAINED_CLAY:7,30,null,30,quark:iron_plate:1,100)
RandomBlock(-5,19,1,quark:iron_plate:1,70,STAINED_CLAY:15,30,STAINED_CLAY:7,30,null,30,quark:iron_plate:1,100)
Block(-5,19,2,AIR:0)
RandomBlock(-5,19,3,quark:iron_plate:1,70,STAINED_CLAY:15,30,STAINED_CLAY:7,30,null,30,quark:iron_plate:1,100)
RandomBlock(-5,20,1,quark:iron_plate:1,70,STAINED_CLAY:15,30,STAINED_CLAY:7,30,null,30,quark:iron_plate:1,100)
Block(-5,20,2,AIR:0)
RandomBlock(-5,20,3,quark:iron_plate:1,70,STAINED_CLAY:15,30,STAINED_CLAY:7,30,null,30,quark:iron_plate:1,100)
RandomBlock(-5,21,1,quark:iron_plate:1,70,STAINED_CLAY:15,30,STAINED_CLAY:7,30,null,30,quark:iron_plate:1,100)
Block(-5,21,2,AIR:0)
RandomBlock(-5,21,3,quark:iron_plate:1,70,STAINED_CLAY:15,30,STAINED_CLAY:7,30,null,30,quark:iron_plate:1,100)
RandomBlock(-5,22,1,rustic:iron_lattice,30,rustic:iron_lattice,30,biomesoplenty:leaves_2:7,30,quark:iron_plate_stairs:6,10,quark:iron_plate_stairs:0,10,quark:iron_plate_stairs:5,10,quark:iron_plate_stairs,10,quark:iron_plate_slab:8,10,quark:iron_plate_stairs:7,10,quark:iron_plate_stairs:1,10,quark:iron_plate_slab,10,quark:iron_plate_stairs:4,10,quark:iron_plate_stairs:2,10,rustic:iron_lattice,50,rustic:iron_lattice,50,biomesoplenty:leaves_2:7,100)
Block(-5,22,2,AIR:0)
RandomBlock(-5,22,3,quark:iron_plate:1,70,STAINED_CLAY:15,30,STAINED_CLAY:7,30,null,30,quark:iron_plate:1,100)
RandomBlock(-5,23,1,rustic:iron_lattice,30,rustic:iron_lattice,30,biomesoplenty:leaves_2:7,30,quark:iron_plate_stairs:6,10,quark:iron_plate_stairs:0,10,quark:iron_plate_stairs:5,10,quark:iron_plate_stairs,10,quark:iron_plate_slab:8,10,quark:iron_plate_stairs:7,10,quark:iron_plate_stairs:1,10,quark:iron_plate_slab,10,quark:iron_plate_stairs:4,10,quark:iron_plate_stairs:2,10,rustic:iron_lattice,50,rustic:iron_lattice,50,biomesoplenty:leaves_2:7,100)
Block(-5,23,2,AIR:0)
RandomBlock(-5,23,3,quark:iron_plate:1,70,STAINED_CLAY:15,30,STAINED_CLAY:7,30,null,30,quark:iron_plate:1,100)
RandomBlock(-5,24,1,rustic:iron_lattice,30,rustic:iron_lattice,30,biomesoplenty:leaves_2:7,30,quark:iron_plate_stairs:6,10,quark:iron_plate_stairs:0,10,quark:iron_plate_stairs:5,10,quark:iron_plate_stairs,10,quark:iron_plate_slab:8,10,quark:iron_plate_stairs:7,10,quark:iron_plate_stairs:1,10,quark:iron_plate_slab,10,quark:iron_plate_stairs:4,10,quark:iron_plate_stairs:2,10,rustic:iron_lattice,50,rustic:iron_lattice,50,biomesoplenty:leaves_2:7,100)
Block(-5,24,2,AIR:0)
RandomBlock(-5,24,3,quark:iron_plate:1,70,STAINED_CLAY:15,30,STAINED_CLAY:7,30,null,30,quark:iron_plate:1,100)
RandomBlock(-5,25,1,rustic:iron_lattice,30,rustic:iron_lattice,30,biomesoplenty:leaves_2:7,30,quark:iron_plate_stairs:6,10,quark:iron_plate_stairs:0,10,quark:iron_plate_stairs:5,10,quark:iron_plate_stairs,10,quark:iron_plate_slab:8,10,quark:iron_plate_stairs:7,10,quark:iron_plate_stairs:1,10,quark:iron_plate_slab,10,quark:iron_plate_stairs:4,10,quark:iron_plate_stairs:2,10,rustic:iron_lattice,50,rustic:iron_lattice,50,biomesoplenty:leaves_2:7,100)
Block(-5,25,2,AIR:0)
RandomBlock(-5,25,3,quark:iron_plate:1,70,STAINED_CLAY:15,30,STAINED_CLAY:7,30,null,30,quark:iron_plate:1,100)
RandomBlock(-5,26,1,quark:iron_plate:1,70,STAINED_CLAY:15,30,STAINED_CLAY:7,30,null,30,quark:iron_plate:1,100)
Block(-5,26,2,AIR:0)
RandomBlock(-5,26,3,quark:iron_plate:1,70,STAINED_CLAY:15,30,STAINED_CLAY:7,30,null,30,quark:iron_plate:1,100)
RandomBlock(-5,27,1,rustic:iron_lattice,30,rustic:iron_lattice,30,biomesoplenty:leaves_2:7,30,quark:iron_plate_stairs:6,10,quark:iron_plate_stairs:0,10,quark:iron_plate_stairs:5,10,quark:iron_plate_stairs,10,quark:iron_plate_slab:8,10,quark:iron_plate_stairs:7,10,quark:iron_plate_stairs:1,10,quark:iron_plate_slab,10,quark:iron_plate_stairs:4,10,quark:iron_plate_stairs:2,10,rustic:iron_lattice,50,rustic:iron_lattice,50,biomesoplenty:leaves_2:7,100)
Block(-5,27,2,AIR:0)
RandomBlock(-5,27,3,quark:iron_plate:1,70,STAINED_CLAY:15,30,STAINED_CLAY:7,30,null,30,quark:iron_plate:1,100)
RandomBlock(-5,28,1,rustic:iron_lattice,30,rustic:iron_lattice,30,biomesoplenty:leaves_2:7,30,quark:iron_plate_stairs:6,10,quark:iron_plate_stairs:0,10,quark:iron_plate_stairs:5,10,quark:iron_plate_stairs,10,quark:iron_plate_slab:8,10,quark:iron_plate_stairs:7,10,quark:iron_plate_stairs:1,10,quark:iron_plate_slab,10,quark:iron_plate_stairs:4,10,quark:iron_plate_stairs:2,10,rustic:iron_lattice,50,rustic:iron_lattice,50,biomesoplenty:leaves_2:7,100)
Block(-5,28,2,AIR:0)
RandomBlock(-5,28,3,quark:iron_plate:1,70,STAINED_CLAY:15,30,STAINED_CLAY:7,30,null,30,quark:iron_plate:1,100)
RandomBlock(-5,29,1,rustic:iron_lattice,30,rustic:iron_lattice,30,biomesoplenty:leaves_2:7,30,quark:iron_plate_stairs:6,10,quark:iron_plate_stairs:0,10,quark:iron_plate_stairs:5,10,quark:iron_plate_stairs,10,quark:iron_plate_slab:8,10,quark:iron_plate_stairs:7,10,quark:iron_plate_stairs:1,10,quark:iron_plate_slab,10,quark:iron_plate_stairs:4,10,quark:iron_plate_stairs:2,10,rustic:iron_lattice,50,rustic:iron_lattice,50,biomesoplenty:leaves_2:7,100)
Block(-5,29,2,AIR:0)
RandomBlock(-5,29,3,quark:iron_plate:1,70,STAINED_CLAY:15,30,STAINED_CLAY:7,30,null,30,quark:iron_plate:1,100)
RandomBlock(-5,30,1,rustic:iron_lattice,30,rustic:iron_lattice,30,biomesoplenty:leaves_2:7,30,quark:iron_plate_stairs:6,10,quark:iron_plate_stairs:0,10,quark:iron_plate_stairs:5,10,quark:iron_plate_stairs,10,quark:iron_plate_slab:8,10,quark:iron_plate_stairs:7,10,quark:iron_plate_stairs:1,10,quark:iron_plate_slab,10,quark:iron_plate_stairs:4,10,quark:iron_plate_stairs:2,10,rustic:iron_lattice,50,rustic:iron_lattice,50,biomesoplenty:leaves_2:7,100)
Block(-5,30,2,AIR:0)
RandomBlock(-5,30,3,quark:iron_plate:1,70,STAINED_CLAY:15,30,STAINED_CLAY:7,30,null,30,quark:iron_plate:1,100)
RandomBlock(-5,31,1,quark:iron_plate:1,70,STAINED_CLAY:15,30,STAINED_CLAY:7,30,null,30,quark:iron_plate:1,100)
Block(-5,31,2,AIR:0)
RandomBlock(-5,31,3,quark:iron_plate:1,70,STAINED_CLAY:15,30,STAINED_CLAY:7,30,null,30,quark:iron_plate:1,100)
RandomBlock(-5,32,1,rustic:iron_lattice,30,rustic:iron_lattice,30,biomesoplenty:leaves_2:7,30,quark:iron_plate_stairs:6,10,quark:iron_plate_stairs:0,10,quark:iron_plate_stairs:5,10,quark:iron_plate_stairs,10,quark:iron_plate_slab:8,10,quark:iron_plate_stairs:7,10,quark:iron_plate_stairs:1,10,quark:iron_plate_slab,10,quark:iron_plate_stairs:4,10,quark:iron_plate_stairs:2,10,rustic:iron_lattice,50,rustic:iron_lattice,50,biomesoplenty:leaves_2:7,100)
Block(-5,32,2,AIR:0)
RandomBlock(-5,32,3,quark:iron_plate:1,70,STAINED_CLAY:15,30,STAINED_CLAY:7,30,null,30,quark:iron_plate:1,100)
RandomBlock(-5,33,1,quark:iron_plate:1,70,STAINED_CLAY:15,30,STAINED_CLAY:7,30,null,30,quark:iron_plate:1,100)
Block(-5,33,2,AIR:0)
RandomBlock(-5,33,3,quark:iron_plate:1,70,STAINED_CLAY:15,30,STAINED_CLAY:7,30,null,30,quark:iron_plate:1,100)
RandomBlock(-5,34,1,quark:iron_plate:1,70,STAINED_CLAY:15,30,STAINED_CLAY:7,30,null,30,quark:iron_plate:1,100)
Block(-5,34,2,AIR:0)
RandomBlock(-5,34,3,quark:iron_plate:1,70,STAINED_CLAY:15,30,STAINED_CLAY:7,30,null,30,quark:iron_plate:1,100)
RandomBlock(-5,35,1,quark:iron_plate:1,70,STAINED_CLAY:15,30,STAINED_CLAY:7,30,null,30,quark:iron_plate:1,100)
Block(-5,35,2,AIR:0)
RandomBlock(-5,35,3,quark:iron_plate:1,70,STAINED_CLAY:15,30,STAINED_CLAY:7,30,null,30,quark:iron_plate:1,100)
RandomBlock(-5,36,1,rustic:iron_lattice,30,rustic:iron_lattice,30,biomesoplenty:leaves_2:7,30,quark:iron_plate_stairs:6,10,quark:iron_plate_stairs:0,10,quark:iron_plate_stairs:5,10,quark:iron_plate_stairs,10,quark:iron_plate_slab:8,10,quark:iron_plate_stairs:7,10,quark:iron_plate_stairs:1,10,quark:iron_plate_slab,10,quark:iron_plate_stairs:4,10,quark:iron_plate_stairs:2,10,rustic:iron_lattice,50,rustic:iron_lattice,50,biomesoplenty:leaves_2:7,100)
Block(-5,36,2,AIR:0)
RandomBlock(-5,36,3,rustic:iron_lattice,30,rustic:iron_lattice,30,biomesoplenty:leaves_2:7,30,quark:iron_plate_stairs:6,10,quark:iron_plate_stairs:0,10,quark:iron_plate_stairs:5,10,quark:iron_plate_stairs,10,quark:iron_plate_slab:8,10,quark:iron_plate_stairs:7,10,quark:iron_plate_stairs:1,10,quark:iron_plate_slab,10,quark:iron_plate_stairs:4,10,quark:iron_plate_stairs:2,10,rustic:iron_lattice,50,rustic:iron_lattice,50,biomesoplenty:leaves_2:7,100)
RandomBlock(-5,37,1,quark:iron_plate:1,70,STAINED_CLAY:15,30,STAINED_CLAY:7,30,null,30,quark:iron_plate:1,100)
Block(-5,37,2,AIR:0)
RandomBlock(-5,37,3,rustic:iron_lattice,30,rustic:iron_lattice,30,biomesoplenty:leaves_2:7,30,quark:iron_plate_stairs:6,10,quark:iron_plate_stairs:0,10,quark:iron_plate_stairs:5,10,quark:iron_plate_stairs,10,quark:iron_plate_slab:8,10,quark:iron_plate_stairs:7,10,quark:iron_plate_stairs:1,10,quark:iron_plate_slab,10,quark:iron_plate_stairs:4,10,quark:iron_plate_stairs:2,10,rustic:iron_lattice,50,rustic:iron_lattice,50,biomesoplenty:leaves_2:7,100)
RandomBlock(-5,38,1,rustic:iron_lattice,30,rustic:iron_lattice,30,biomesoplenty:leaves_2:7,30,quark:iron_plate_stairs:6,10,quark:iron_plate_stairs:0,10,quark:iron_plate_stairs:5,10,quark:iron_plate_stairs,10,quark:iron_plate_slab:8,10,quark:iron_plate_stairs:7,10,quark:iron_plate_stairs:1,10,quark:iron_plate_slab,10,quark:iron_plate_stairs:4,10,quark:iron_plate_stairs:2,10,rustic:iron_lattice,50,rustic:iron_lattice,50,biomesoplenty:leaves_2:7,100)
Block(-5,38,2,AIR:0)
RandomBlock(-5,38,3,quark:iron_plate:1,70,STAINED_CLAY:15,30,STAINED_CLAY:7,30,null,30,quark:iron_plate:1,100)
RandomBlock(-5,39,1,quark:iron_plate:1,70,STAINED_CLAY:15,30,STAINED_CLAY:7,30,null,30,quark:iron_plate:1,100)
Block(-5,39,2,AIR:0)
RandomBlock(-5,39,3,quark:iron_plate:1,70,STAINED_CLAY:15,30,STAINED_CLAY:7,30,null,30,quark:iron_plate:1,100)
RandomBlock(-5,40,1,rustic:iron_lattice,30,rustic:iron_lattice,30,biomesoplenty:leaves_2:7,30,quark:iron_plate_stairs:6,10,quark:iron_plate_stairs:0,10,quark:iron_plate_stairs:5,10,quark:iron_plate_stairs,10,quark:iron_plate_slab:8,10,quark:iron_plate_stairs:7,10,quark:iron_plate_stairs:1,10,quark:iron_plate_slab,10,quark:iron_plate_stairs:4,10,quark:iron_plate_stairs:2,10,rustic:iron_lattice,50,rustic:iron_lattice,50,biomesoplenty:leaves_2:7,100)
Block(-5,40,2,AIR:0)
RandomBlock(-5,40,3,quark:iron_plate:1,70,STAINED_CLAY:15,30,STAINED_CLAY:7,30,null,30,quark:iron_plate:1,100)
RandomBlock(-5,41,1,rustic:iron_lattice,30,rustic:iron_lattice,30,biomesoplenty:leaves_2:7,30,quark:iron_plate_stairs:6,10,quark:iron_plate_stairs:0,10,quark:iron_plate_stairs:5,10,quark:iron_plate_stairs,10,quark:iron_plate_slab:8,10,quark:iron_plate_stairs:7,10,quark:iron_plate_stairs:1,10,quark:iron_plate_slab,10,quark:iron_plate_stairs:4,10,quark:iron_plate_stairs:2,10,rustic:iron_lattice,50,rustic:iron_lattice,50,biomesoplenty:leaves_2:7,100)
Block(-5,41,2,AIR:0)
RandomBlock(-5,41,3,quark:iron_plate:1,70,STAINED_CLAY:15,30,STAINED_CLAY:7,30,null,30,quark:iron_plate:1,100)
RandomBlock(-5,42,1,rustic:iron_lattice,30,rustic:iron_lattice,30,biomesoplenty:leaves_2:7,30,quark:iron_plate_stairs:6,10,quark:iron_plate_stairs:0,10,quark:iron_plate_stairs:5,10,quark:iron_plate_stairs,10,quark:iron_plate_slab:8,10,quark:iron_plate_stairs:7,10,quark:iron_plate_stairs:1,10,quark:iron_plate_slab,10,quark:iron_plate_stairs:4,10,quark:iron_plate_stairs:2,10,rustic:iron_lattice,50,rustic:iron_lattice,50,biomesoplenty:leaves_2:7,100)
Block(-5,42,2,AIR:0)
RandomBlock(-5,42,3,rustic:iron_lattice,30,rustic:iron_lattice,30,biomesoplenty:leaves_2:7,30,quark:iron_plate_stairs:6,10,quark:iron_plate_stairs:0,10,quark:iron_plate_stairs:5,10,quark:iron_plate_stairs,10,quark:iron_plate_slab:8,10,quark:iron_plate_stairs:7,10,quark:iron_plate_stairs:1,10,quark:iron_plate_slab,10,quark:iron_plate_stairs:4,10,quark:iron_plate_stairs:2,10,rustic:iron_lattice,50,rustic:iron_lattice,50,biomesoplenty:leaves_2:7,100)
RandomBlock(-5,43,1,rustic:iron_lattice,30,rustic:iron_lattice,30,biomesoplenty:leaves_2:7,30,quark:iron_plate_stairs:6,10,quark:iron_plate_stairs:0,10,quark:iron_plate_stairs:5,10,quark:iron_plate_stairs,10,quark:iron_plate_slab:8,10,quark:iron_plate_stairs:7,10,quark:iron_plate_stairs:1,10,quark:iron_plate_slab,10,quark:iron_plate_stairs:4,10,quark:iron_plate_stairs:2,10,rustic:iron_lattice,50,rustic:iron_lattice,50,biomesoplenty:leaves_2:7,100)
Block(-5,43,2,AIR:0)
RandomBlock(-5,43,3,rustic:iron_lattice,30,rustic:iron_lattice,30,biomesoplenty:leaves_2:7,30,quark:iron_plate_stairs:6,10,quark:iron_plate_stairs:0,10,quark:iron_plate_stairs:5,10,quark:iron_plate_stairs,10,quark:iron_plate_slab:8,10,quark:iron_plate_stairs:7,10,quark:iron_plate_stairs:1,10,quark:iron_plate_slab,10,quark:iron_plate_stairs:4,10,quark:iron_plate_stairs:2,10,rustic:iron_lattice,50,rustic:iron_lattice,50,biomesoplenty:leaves_2:7,100)
RandomBlock(-5,44,1,rustic:iron_lattice,30,rustic:iron_lattice,30,biomesoplenty:leaves_2:7,30,quark:iron_plate_stairs:6,10,quark:iron_plate_stairs:0,10,quark:iron_plate_stairs:5,10,quark:iron_plate_stairs,10,quark:iron_plate_slab:8,10,quark:iron_plate_stairs:7,10,quark:iron_plate_stairs:1,10,quark:iron_plate_slab,10,quark:iron_plate_stairs:4,10,quark:iron_plate_stairs:2,10,rustic:iron_lattice,50,rustic:iron_lattice,50,biomesoplenty:leaves_2:7,100)
Block(-5,44,2,AIR:0)
RandomBlock(-5,44,3,rustic:iron_lattice,30,rustic:iron_lattice,30,biomesoplenty:leaves_2:7,30,quark:iron_plate_stairs:6,10,quark:iron_plate_stairs:0,10,quark:iron_plate_stairs:5,10,quark:iron_plate_stairs,10,quark:iron_plate_slab:8,10,quark:iron_plate_stairs:7,10,quark:iron_plate_stairs:1,10,quark:iron_plate_slab,10,quark:iron_plate_stairs:4,10,quark:iron_plate_stairs:2,10,rustic:iron_lattice,50,rustic:iron_lattice,50,biomesoplenty:leaves_2:7,100)
RandomBlock(-5,45,1,rustic:iron_lattice,30,rustic:iron_lattice,30,biomesoplenty:leaves_2:7,30,quark:iron_plate_stairs:6,10,quark:iron_plate_stairs:0,10,quark:iron_plate_stairs:5,10,quark:iron_plate_stairs,10,quark:iron_plate_slab:8,10,quark:iron_plate_stairs:7,10,quark:iron_plate_stairs:1,10,quark:iron_plate_slab,10,quark:iron_plate_stairs:4,10,quark:iron_plate_stairs:2,10,rustic:iron_lattice,50,rustic:iron_lattice,50,biomesoplenty:leaves_2:7,100)
Block(-5,45,2,AIR:0)
RandomBlock(-5,45,3,rustic:iron_lattice,30,rustic:iron_lattice,30,biomesoplenty:leaves_2:7,30,quark:iron_plate_stairs:6,10,quark:iron_plate_stairs:0,10,quark:iron_plate_stairs:5,10,quark:iron_plate_stairs,10,quark:iron_plate_slab:8,10,quark:iron_plate_stairs:7,10,quark:iron_plate_stairs:1,10,quark:iron_plate_slab,10,quark:iron_plate_stairs:4,10,quark:iron_plate_stairs:2,10,rustic:iron_lattice,50,rustic:iron_lattice,50,biomesoplenty:leaves_2:7,100)
RandomBlock(-5,46,1,rustic:iron_lattice,30,rustic:iron_lattice,30,biomesoplenty:leaves_2:7,30,quark:iron_plate_stairs:6,10,quark:iron_plate_stairs:0,10,quark:iron_plate_stairs:5,10,quark:iron_plate_stairs,10,quark:iron_plate_slab:8,10,quark:iron_plate_stairs:7,10,quark:iron_plate_stairs:1,10,quark:iron_plate_slab,10,quark:iron_plate_stairs:4,10,quark:iron_plate_stairs:2,10,rustic:iron_lattice,50,rustic:iron_lattice,50,biomesoplenty:leaves_2:7,100)
Block(-5,46,2,AIR:0)
RandomBlock(-5,46,3,rustic:iron_lattice,30,rustic:iron_lattice,30,biomesoplenty:leaves_2:7,30,quark:iron_plate_stairs:6,10,quark:iron_plate_stairs:0,10,quark:iron_plate_stairs:5,10,quark:iron_plate_stairs,10,quark:iron_plate_slab:8,10,quark:iron_plate_stairs:7,10,quark:iron_plate_stairs:1,10,quark:iron_plate_slab,10,quark:iron_plate_stairs:4,10,quark:iron_plate_stairs:2,10,rustic:iron_lattice,50,rustic:iron_lattice,50,biomesoplenty:leaves_2:7,100)
RandomBlock(-5,47,1,quark:iron_plate:1,70,STAINED_CLAY:15,30,STAINED_CLAY:7,30,null,30,quark:iron_plate:1,100)
Block(-5,47,2,AIR:0)
RandomBlock(-5,47,3,rustic:iron_lattice,30,rustic:iron_lattice,30,biomesoplenty:leaves_2:7,30,quark:iron_plate_stairs:6,10,quark:iron_plate_stairs:0,10,quark:iron_plate_stairs:5,10,quark:iron_plate_stairs,10,quark:iron_plate_slab:8,10,quark:iron_plate_stairs:7,10,quark:iron_plate_stairs:1,10,quark:iron_plate_slab,10,quark:iron_plate_stairs:4,10,quark:iron_plate_stairs:2,10,rustic:iron_lattice,50,rustic:iron_lattice,50,biomesoplenty:leaves_2:7,100)
RandomBlock(-5,48,1,rustic:iron_lattice,30,rustic:iron_lattice,30,biomesoplenty:leaves_2:7,30,quark:iron_plate_stairs:6,10,quark:iron_plate_stairs:0,10,quark:iron_plate_stairs:5,10,quark:iron_plate_stairs,10,quark:iron_plate_slab:8,10,quark:iron_plate_stairs:7,10,quark:iron_plate_stairs:1,10,quark:iron_plate_slab,10,quark:iron_plate_stairs:4,10,quark:iron_plate_stairs:2,10,rustic:iron_lattice,50,rustic:iron_lattice,50,biomesoplenty:leaves_2:7,100)
Block(-5,48,2,AIR:0)
RandomBlock(-5,48,3,quark:iron_plate:1,70,STAINED_CLAY:15,30,STAINED_CLAY:7,30,null,30,quark:iron_plate:1,100)
RandomBlock(-5,49,1,quark:iron_plate:1,70,STAINED_CLAY:15,30,STAINED_CLAY:7,30,null,30,quark:iron_plate:1,100)
Block(-5,49,2,AIR:0)
RandomBlock(-5,49,3,rustic:iron_lattice,30,rustic:iron_lattice,30,biomesoplenty:leaves_2:7,30,quark:iron_plate_stairs:6,10,quark:iron_plate_stairs:0,10,quark:iron_plate_stairs:5,10,quark:iron_plate_stairs,10,quark:iron_plate_slab:8,10,quark:iron_plate_stairs:7,10,quark:iron_plate_stairs:1,10,quark:iron_plate_slab,10,quark:iron_plate_stairs:4,10,quark:iron_plate_stairs:2,10,rustic:iron_lattice,50,rustic:iron_lattice,50,biomesoplenty:leaves_2:7,100)
RandomBlock(-5,50,1,quark:iron_plate:1,70,STAINED_CLAY:15,30,STAINED_CLAY:7,30,null,30,quark:iron_plate:1,100)
Block(-5,50,2,AIR:0)
RandomBlock(-5,50,3,rustic:iron_lattice,30,rustic:iron_lattice,30,biomesoplenty:leaves_2:7,30,quark:iron_plate_stairs:6,10,quark:iron_plate_stairs:0,10,quark:iron_plate_stairs:5,10,quark:iron_plate_stairs,10,quark:iron_plate_slab:8,10,quark:iron_plate_stairs:7,10,quark:iron_plate_stairs:1,10,quark:iron_plate_slab,10,quark:iron_plate_stairs:4,10,quark:iron_plate_stairs:2,10,rustic:iron_lattice,50,rustic:iron_lattice,50,biomesoplenty:leaves_2:7,100)
RandomBlock(-5,51,1,rustic:iron_lattice,30,rustic:iron_lattice,30,biomesoplenty:leaves_2:7,30,quark:iron_plate_stairs:6,10,quark:iron_plate_stairs:0,10,quark:iron_plate_stairs:5,10,quark:iron_plate_stairs,10,quark:iron_plate_slab:8,10,quark:iron_plate_stairs:7,10,quark:iron_plate_stairs:1,10,quark:iron_plate_slab,10,quark:iron_plate_stairs:4,10,quark:iron_plate_stairs:2,10,rustic:iron_lattice,50,rustic:iron_lattice,50,biomesoplenty:leaves_2:7,100)
Block(-5,51,2,AIR:0)
RandomBlock(-5,51,3,rustic:iron_lattice,30,rustic:iron_lattice,30,biomesoplenty:leaves_2:7,30,quark:iron_plate_stairs:6,10,quark:iron_plate_stairs:0,10,quark:iron_plate_stairs:5,10,quark:iron_plate_stairs,10,quark:iron_plate_slab:8,10,quark:iron_plate_stairs:7,10,quark:iron_plate_stairs:1,10,quark:iron_plate_slab,10,quark:iron_plate_stairs:4,10,quark:iron_plate_stairs:2,10,rustic:iron_lattice,50,rustic:iron_lattice,50,biomesoplenty:leaves_2:7,100)
RandomBlock(-5,52,1,quark:iron_plate:1,70,STAINED_CLAY:15,30,STAINED_CLAY:7,30,null,30,quark:iron_plate:1,100)
Block(-5,52,2,AIR:0)
RandomBlock(-5,52,3,rustic:iron_lattice,30,rustic:iron_lattice,30,biomesoplenty:leaves_2:7,30,quark:iron_plate_stairs:6,10,quark:iron_plate_stairs:0,10,quark:iron_plate_stairs:5,10,quark:iron_plate_stairs,10,quark:iron_plate_slab:8,10,quark:iron_plate_stairs:7,10,quark:iron_plate_stairs:1,10,quark:iron_plate_slab,10,quark:iron_plate_stairs:4,10,quark:iron_plate_stairs:2,10,rustic:iron_lattice,50,rustic:iron_lattice,50,biomesoplenty:leaves_2:7,100)
RandomBlock(-5,53,1,quark:iron_plate:1,70,STAINED_CLAY:15,30,STAINED_CLAY:7,30,null,30,quark:iron_plate:1,100)
Block(-5,53,2,AIR:0)
RandomBlock(-5,53,3,quark:iron_plate:1,70,STAINED_CLAY:15,30,STAINED_CLAY:7,30,null,30,quark:iron_plate:1,100)
RandomBlock(-5,54,1,quark:iron_plate:1,70,STAINED_CLAY:15,30,STAINED_CLAY:7,30,null,30,quark:iron_plate:1,100)
Block(-5,54,2,AIR:0)
RandomBlock(-5,54,3,quark:iron_plate:1,70,STAINED_CLAY:15,30,STAINED_CLAY:7,30,null,30,quark:iron_plate:1,100)
RandomBlock(-5,55,1,quark:iron_plate:1,70,STAINED_CLAY:15,30,STAINED_CLAY:7,30,null,30,quark:iron_plate:1,100)
Block(-5,55,2,AIR:0)
RandomBlock(-5,55,3,quark:iron_plate:1,70,STAINED_CLAY:15,30,STAINED_CLAY:7,30,null,30,quark:iron_plate:1,100)
RandomBlock(-5,56,1,quark:iron_plate:1,70,STAINED_CLAY:15,30,STAINED_CLAY:7,30,null,30,quark:iron_plate:1,100)
Block(-5,56,2,AIR:0)
RandomBlock(-5,56,3,quark:iron_plate:1,70,STAINED_CLAY:15,30,STAINED_CLAY:7,30,null,30,quark:iron_plate:1,100)
RandomBlock(-5,57,1,quark:iron_plate:1,70,STAINED_CLAY:15,30,STAINED_CLAY:7,30,null,30,quark:iron_plate:1,100)
Block(-5,57,2,AIR:0)
RandomBlock(-5,57,3,quark:iron_plate:1,70,STAINED_CLAY:15,30,STAINED_CLAY:7,30,null,30,quark:iron_plate:1,100)
RandomBlock(-5,58,1,rustic:iron_lattice,30,rustic:iron_lattice,30,biomesoplenty:leaves_2:7,30,quark:iron_plate_stairs:6,10,quark:iron_plate_stairs:0,10,quark:iron_plate_stairs:5,10,quark:iron_plate_stairs,10,quark:iron_plate_slab:8,10,quark:iron_plate_stairs:7,10,quark:iron_plate_stairs:1,10,quark:iron_plate_slab,10,quark:iron_plate_stairs:4,10,quark:iron_plate_stairs:2,10,rustic:iron_lattice,50,rustic:iron_lattice,50,biomesoplenty:leaves_2:7,100)
Block(-5,58,2,AIR:0)
RandomBlock(-5,58,3,quark:iron_plate:1,70,STAINED_CLAY:15,30,STAINED_CLAY:7,30,null,30,quark:iron_plate:1,100)
RandomBlock(-5,59,1,quark:iron_plate:1,70,STAINED_CLAY:15,30,STAINED_CLAY:7,30,null,30,quark:iron_plate:1,100)
Block(-5,59,2,AIR:0)
RandomBlock(-5,59,3,quark:iron_plate:1,70,STAINED_CLAY:15,30,STAINED_CLAY:7,30,null,30,quark:iron_plate:1,100)
RandomBlock(-5,60,1,quark:iron_plate:1,70,STAINED_CLAY:15,30,STAINED_CLAY:7,30,null,30,quark:iron_plate:1,100)
Block(-5,60,2,AIR:0)
RandomBlock(-5,60,3,quark:iron_plate:1,70,STAINED_CLAY:15,30,STAINED_CLAY:7,30,null,30,quark:iron_plate:1,100)
RandomBlock(-5,61,1,quark:iron_plate:1,70,STAINED_CLAY:15,30,STAINED_CLAY:7,30,null,30,quark:iron_plate:1,100)
Block(-5,61,2,AIR:0)
RandomBlock(-5,61,3,quark:iron_plate:1,70,STAINED_CLAY:15,30,STAINED_CLAY:7,30,null,30,quark:iron_plate:1,100)
RandomBlock(-5,62,1,quark:iron_plate:1,70,STAINED_CLAY:15,30,STAINED_CLAY:7,30,null,30,quark:iron_plate:1,100)
Block(-5,62,2,AIR:0)
RandomBlock(-5,62,3,quark:iron_plate:1,70,STAINED_CLAY:15,30,STAINED_CLAY:7,30,null,30,quark:iron_plate:1,100)
RandomBlock(-5,63,1,quark:iron_plate:1,70,STAINED_CLAY:15,30,STAINED_CLAY:7,30,null,30,quark:iron_plate:1,100)
Block(-5,63,2,AIR:0)
RandomBlock(-5,63,3,quark:iron_plate:1,70,STAINED_CLAY:15,30,STAINED_CLAY:7,30,null,30,quark:iron_plate:1,100)
RandomBlock(-5,64,1,quark:iron_plate:1,70,STAINED_CLAY:15,30,STAINED_CLAY:7,30,null,30,quark:iron_plate:1,100)
Block(-5,64,2,AIR:0)
RandomBlock(-5,64,3,quark:iron_plate:1,70,STAINED_CLAY:15,30,STAINED_CLAY:7,30,null,30,quark:iron_plate:1,100)
RandomBlock(-5,65,1,quark:iron_plate:1,70,STAINED_CLAY:15,30,STAINED_CLAY:7,30,null,30,quark:iron_plate:1,100)
Block(-5,65,2,AIR:0)
RandomBlock(-5,65,3,quark:iron_plate:1,70,STAINED_CLAY:15,30,STAINED_CLAY:7,30,null,30,quark:iron_plate:1,100)
RandomBlock(-4,0,1,quark:iron_plate:1,70,STAINED_CLAY:15,30,STAINED_CLAY:7,30,null,30,quark:iron_plate:1,100)
RandomBlock(-4,0,2,quark:iron_plate:1,70,STAINED_CLAY:15,30,STAINED_CLAY:7,30,null,30,quark:iron_plate:1,100)
RandomBlock(-4,0,3,quark:iron_plate:1,70,STAINED_CLAY:15,30,STAINED_CLAY:7,30,null,30,quark:iron_plate:1,100)
RandomBlock(-4,1,1,rustic:iron_lattice,30,rustic:iron_lattice,30,biomesoplenty:leaves_2:7,30,quark:iron_plate_stairs:6,10,quark:iron_plate_stairs:0,10,quark:iron_plate_stairs:5,10,quark:iron_plate_stairs,10,quark:iron_plate_slab:8,10,quark:iron_plate_stairs:7,10,quark:iron_plate_stairs:1,10,quark:iron_plate_slab,10,quark:iron_plate_stairs:4,10,quark:iron_plate_stairs:2,10,rustic:iron_lattice,50,rustic:iron_lattice,50,biomesoplenty:leaves_2:7,100)
RandomBlock(-4,1,2,quark:iron_plate:1,70,STAINED_CLAY:15,30,STAINED_CLAY:7,30,null,30,quark:iron_plate:1,100)
RandomBlock(-4,1,3,quark:iron_plate:1,70,STAINED_CLAY:15,30,STAINED_CLAY:7,30,null,30,quark:iron_plate:1,100)
RandomBlock(-4,2,1,rustic:iron_lattice,30,rustic:iron_lattice,30,biomesoplenty:leaves_2:7,30,quark:iron_plate_stairs:6,10,quark:iron_plate_stairs:0,10,quark:iron_plate_stairs:5,10,quark:iron_plate_stairs,10,quark:iron_plate_slab:8,10,quark:iron_plate_stairs:7,10,quark:iron_plate_stairs:1,10,quark:iron_plate_slab,10,quark:iron_plate_stairs:4,10,quark:iron_plate_stairs:2,10,rustic:iron_lattice,50,rustic:iron_lattice,50,biomesoplenty:leaves_2:7,100)
RandomBlock(-4,2,2,rustic:iron_lattice,30,rustic:iron_lattice,30,biomesoplenty:leaves_2:7,30,quark:iron_plate_stairs:6,10,quark:iron_plate_stairs:0,10,quark:iron_plate_stairs:5,10,quark:iron_plate_stairs,10,quark:iron_plate_slab:8,10,quark:iron_plate_stairs:7,10,quark:iron_plate_stairs:1,10,quark:iron_plate_slab,10,quark:iron_plate_stairs:4,10,quark:iron_plate_stairs:2,10,rustic:iron_lattice,50,rustic:iron_lattice,50,biomesoplenty:leaves_2:7,100)
RandomBlock(-4,2,3,quark:iron_plate:1,70,STAINED_CLAY:15,30,STAINED_CLAY:7,30,null,30,quark:iron_plate:1,100)
RandomBlock(-4,3,1,rustic:iron_lattice,30,rustic:iron_lattice,30,biomesoplenty:leaves_2:7,30,quark:iron_plate_stairs:6,10,quark:iron_plate_stairs:0,10,quark:iron_plate_stairs:5,10,quark:iron_plate_stairs,10,quark:iron_plate_slab:8,10,quark:iron_plate_stairs:7,10,quark:iron_plate_stairs:1,10,quark:iron_plate_slab,10,quark:iron_plate_stairs:4,10,quark:iron_plate_stairs:2,10,rustic:iron_lattice,50,rustic:iron_lattice,50,biomesoplenty:leaves_2:7,100)
RandomBlock(-4,3,2,rustic:iron_lattice,30,rustic:iron_lattice,30,biomesoplenty:leaves_2:7,30,quark:iron_plate_stairs:6,10,quark:iron_plate_stairs:0,10,quark:iron_plate_stairs:5,10,quark:iron_plate_stairs,10,quark:iron_plate_slab:8,10,quark:iron_plate_stairs:7,10,quark:iron_plate_stairs:1,10,quark:iron_plate_slab,10,quark:iron_plate_stairs:4,10,quark:iron_plate_stairs:2,10,rustic:iron_lattice,50,rustic:iron_lattice,50,biomesoplenty:leaves_2:7,100)
RandomBlock(-4,3,3,quark:iron_plate:1,70,STAINED_CLAY:15,30,STAINED_CLAY:7,30,null,30,quark:iron_plate:1,100)
RandomBlock(-4,4,1,rustic:iron_lattice,30,rustic:iron_lattice,30,biomesoplenty:leaves_2:7,30,quark:iron_plate_stairs:6,10,quark:iron_plate_stairs:0,10,quark:iron_plate_stairs:5,10,quark:iron_plate_stairs,10,quark:iron_plate_slab:8,10,quark:iron_plate_stairs:7,10,quark:iron_plate_stairs:1,10,quark:iron_plate_slab,10,quark:iron_plate_stairs:4,10,quark:iron_plate_stairs:2,10,rustic:iron_lattice,50,rustic:iron_lattice,50,biomesoplenty:leaves_2:7,100)
RandomBlock(-4,4,2,quark:iron_plate:1,70,STAINED_CLAY:15,30,STAINED_CLAY:7,30,null,30,quark:iron_plate:1,100)
RandomBlock(-4,4,3,rustic:iron_lattice,30,rustic:iron_lattice,30,biomesoplenty:leaves_2:7,30,quark:iron_plate_stairs:6,10,quark:iron_plate_stairs:0,10,quark:iron_plate_stairs:5,10,quark:iron_plate_stairs,10,quark:iron_plate_slab:8,10,quark:iron_plate_stairs:7,10,quark:iron_plate_stairs:1,10,quark:iron_plate_slab,10,quark:iron_plate_stairs:4,10,quark:iron_plate_stairs:2,10,rustic:iron_lattice,50,rustic:iron_lattice,50,biomesoplenty:leaves_2:7,100)
RandomBlock(-4,5,1,rustic:iron_lattice,30,rustic:iron_lattice,30,biomesoplenty:leaves_2:7,30,quark:iron_plate_stairs:6,10,quark:iron_plate_stairs:0,10,quark:iron_plate_stairs:5,10,quark:iron_plate_stairs,10,quark:iron_plate_slab:8,10,quark:iron_plate_stairs:7,10,quark:iron_plate_stairs:1,10,quark:iron_plate_slab,10,quark:iron_plate_stairs:4,10,quark:iron_plate_stairs:2,10,rustic:iron_lattice,50,rustic:iron_lattice,50,biomesoplenty:leaves_2:7,100)
RandomBlock(-4,5,2,quark:iron_plate:1,70,STAINED_CLAY:15,30,STAINED_CLAY:7,30,null,30,quark:iron_plate:1,100)
RandomBlock(-4,5,3,quark:iron_plate:1,70,STAINED_CLAY:15,30,STAINED_CLAY:7,30,null,30,quark:iron_plate:1,100)
RandomBlock(-4,6,1,rustic:iron_lattice,30,rustic:iron_lattice,30,biomesoplenty:leaves_2:7,30,quark:iron_plate_stairs:6,10,quark:iron_plate_stairs:0,10,quark:iron_plate_stairs:5,10,quark:iron_plate_stairs,10,quark:iron_plate_slab:8,10,quark:iron_plate_stairs:7,10,quark:iron_plate_stairs:1,10,quark:iron_plate_slab,10,quark:iron_plate_stairs:4,10,quark:iron_plate_stairs:2,10,rustic:iron_lattice,50,rustic:iron_lattice,50,biomesoplenty:leaves_2:7,100)
RandomBlock(-4,6,2,rustic:iron_lattice,30,rustic:iron_lattice,30,biomesoplenty:leaves_2:7,30,quark:iron_plate_stairs:6,10,quark:iron_plate_stairs:0,10,quark:iron_plate_stairs:5,10,quark:iron_plate_stairs,10,quark:iron_plate_slab:8,10,quark:iron_plate_stairs:7,10,quark:iron_plate_stairs:1,10,quark:iron_plate_slab,10,quark:iron_plate_stairs:4,10,quark:iron_plate_stairs:2,10,rustic:iron_lattice,50,rustic:iron_lattice,50,biomesoplenty:leaves_2:7,100)
RandomBlock(-4,6,3,quark:iron_plate:1,70,STAINED_CLAY:15,30,STAINED_CLAY:7,30,null,30,quark:iron_plate:1,100)
RandomBlock(-4,7,1,rustic:iron_lattice,30,rustic:iron_lattice,30,biomesoplenty:leaves_2:7,30,quark:iron_plate_stairs:6,10,quark:iron_plate_stairs:0,10,quark:iron_plate_stairs:5,10,quark:iron_plate_stairs,10,quark:iron_plate_slab:8,10,quark:iron_plate_stairs:7,10,quark:iron_plate_stairs:1,10,quark:iron_plate_slab,10,quark:iron_plate_stairs:4,10,quark:iron_plate_stairs:2,10,rustic:iron_lattice,50,rustic:iron_lattice,50,biomesoplenty:leaves_2:7,100)
RandomBlock(-4,7,2,quark:iron_plate:1,70,STAINED_CLAY:15,30,STAINED_CLAY:7,30,null,30,quark:iron_plate:1,100)
RandomBlock(-4,7,3,quark:iron_plate:1,70,STAINED_CLAY:15,30,STAINED_CLAY:7,30,null,30,quark:iron_plate:1,100)
RandomBlock(-4,8,1,quark:iron_plate:1,70,STAINED_CLAY:15,30,STAINED_CLAY:7,30,null,30,quark:iron_plate:1,100)
RandomBlock(-4,8,2,quark:iron_plate:1,70,STAINED_CLAY:15,30,STAINED_CLAY:7,30,null,30,quark:iron_plate:1,100)
RandomBlock(-4,8,3,quark:iron_plate:1,70,STAINED_CLAY:15,30,STAINED_CLAY:7,30,null,30,quark:iron_plate:1,100)
RandomBlock(-4,9,1,rustic:iron_lattice,30,rustic:iron_lattice,30,biomesoplenty:leaves_2:7,30,quark:iron_plate_stairs:6,10,quark:iron_plate_stairs:0,10,quark:iron_plate_stairs:5,10,quark:iron_plate_stairs,10,quark:iron_plate_slab:8,10,quark:iron_plate_stairs:7,10,quark:iron_plate_stairs:1,10,quark:iron_plate_slab,10,quark:iron_plate_stairs:4,10,quark:iron_plate_stairs:2,10,rustic:iron_lattice,50,rustic:iron_lattice,50,biomesoplenty:leaves_2:7,100)
RandomBlock(-4,9,2,quark:iron_plate:1,70,STAINED_CLAY:15,30,STAINED_CLAY:7,30,null,30,quark:iron_plate:1,100)
RandomBlock(-4,9,3,quark:iron_plate:1,70,STAINED_CLAY:15,30,STAINED_CLAY:7,30,null,30,quark:iron_plate:1,100)
RandomBlock(-4,10,1,quark:iron_plate:1,70,STAINED_CLAY:15,30,STAINED_CLAY:7,30,null,30,quark:iron_plate:1,100)
RandomBlock(-4,10,2,quark:iron_plate:1,70,STAINED_CLAY:15,30,STAINED_CLAY:7,30,null,30,quark:iron_plate:1,100)
RandomBlock(-4,10,3,quark:iron_plate:1,70,STAINED_CLAY:15,30,STAINED_CLAY:7,30,null,30,quark:iron_plate:1,100)
RandomBlock(-4,11,1,quark:iron_plate:1,70,STAINED_CLAY:15,30,STAINED_CLAY:7,30,null,30,quark:iron_plate:1,100)
RandomBlock(-4,11,2,quark:iron_plate:1,70,STAINED_CLAY:15,30,STAINED_CLAY:7,30,null,30,quark:iron_plate:1,100)
RandomBlock(-4,11,3,quark:iron_plate:1,70,STAINED_CLAY:15,30,STAINED_CLAY:7,30,null,30,quark:iron_plate:1,100)
RandomBlock(-4,12,1,quark:iron_plate:1,70,STAINED_CLAY:15,30,STAINED_CLAY:7,30,null,30,quark:iron_plate:1,100)
RandomBlock(-4,12,2,quark:iron_plate:1,70,STAINED_CLAY:15,30,STAINED_CLAY:7,30,null,30,quark:iron_plate:1,100)
RandomBlock(-4,12,3,quark:iron_plate:1,70,STAINED_CLAY:15,30,STAINED_CLAY:7,30,null,30,quark:iron_plate:1,100)
RandomBlock(-4,13,1,quark:iron_plate:1,70,STAINED_CLAY:15,30,STAINED_CLAY:7,30,null,30,quark:iron_plate:1,100)
RandomBlock(-4,13,2,quark:iron_plate:1,70,STAINED_CLAY:15,30,STAINED_CLAY:7,30,null,30,quark:iron_plate:1,100)
RandomBlock(-4,13,3,quark:iron_plate:1,70,STAINED_CLAY:15,30,STAINED_CLAY:7,30,null,30,quark:iron_plate:1,100)
RandomBlock(-4,14,1,quark:iron_plate:1,70,STAINED_CLAY:15,30,STAINED_CLAY:7,30,null,30,quark:iron_plate:1,100)
RandomBlock(-4,14,2,quark:iron_plate:1,70,STAINED_CLAY:15,30,STAINED_CLAY:7,30,null,30,quark:iron_plate:1,100)
RandomBlock(-4,14,3,quark:iron_plate:1,70,STAINED_CLAY:15,30,STAINED_CLAY:7,30,null,30,quark:iron_plate:1,100)
RandomBlock(-4,15,1,quark:iron_plate:1,70,STAINED_CLAY:15,30,STAINED_CLAY:7,30,null,30,quark:iron_plate:1,100)
RandomBlock(-4,15,2,quark:iron_plate:1,70,STAINED_CLAY:15,30,STAINED_CLAY:7,30,null,30,quark:iron_plate:1,100)
RandomBlock(-4,15,3,quark:iron_plate:1,70,STAINED_CLAY:15,30,STAINED_CLAY:7,30,null,30,quark:iron_plate:1,100)
RandomBlock(-4,16,1,rustic:iron_lattice,30,rustic:iron_lattice,30,biomesoplenty:leaves_2:7,30,quark:iron_plate_stairs:6,10,quark:iron_plate_stairs:0,10,quark:iron_plate_stairs:5,10,quark:iron_plate_stairs,10,quark:iron_plate_slab:8,10,quark:iron_plate_stairs:7,10,quark:iron_plate_stairs:1,10,quark:iron_plate_slab,10,quark:iron_plate_stairs:4,10,quark:iron_plate_stairs:2,10,rustic:iron_lattice,50,rustic:iron_lattice,50,biomesoplenty:leaves_2:7,100)
RandomBlock(-4,16,2,quark:iron_plate:1,70,STAINED_CLAY:15,30,STAINED_CLAY:7,30,null,30,quark:iron_plate:1,100)
RandomBlock(-4,16,3,quark:iron_plate:1,70,STAINED_CLAY:15,30,STAINED_CLAY:7,30,null,30,quark:iron_plate:1,100)
RandomBlock(-4,17,1,rustic:iron_lattice,30,rustic:iron_lattice,30,biomesoplenty:leaves_2:7,30,quark:iron_plate_stairs:6,10,quark:iron_plate_stairs:0,10,quark:iron_plate_stairs:5,10,quark:iron_plate_stairs,10,quark:iron_plate_slab:8,10,quark:iron_plate_stairs:7,10,quark:iron_plate_stairs:1,10,quark:iron_plate_slab,10,quark:iron_plate_stairs:4,10,quark:iron_plate_stairs:2,10,rustic:iron_lattice,50,rustic:iron_lattice,50,biomesoplenty:leaves_2:7,100)
RandomBlock(-4,17,2,quark:iron_plate:1,70,STAINED_CLAY:15,30,STAINED_CLAY:7,30,null,30,quark:iron_plate:1,100)
RandomBlock(-4,17,3,quark:iron_plate:1,70,STAINED_CLAY:15,30,STAINED_CLAY:7,30,null,30,quark:iron_plate:1,100)
RandomBlock(-4,18,1,quark:iron_plate:1,70,STAINED_CLAY:15,30,STAINED_CLAY:7,30,null,30,quark:iron_plate:1,100)
RandomBlock(-4,18,2,quark:iron_plate:1,70,STAINED_CLAY:15,30,STAINED_CLAY:7,30,null,30,quark:iron_plate:1,100)
RandomBlock(-4,18,3,quark:iron_plate:1,70,STAINED_CLAY:15,30,STAINED_CLAY:7,30,null,30,quark:iron_plate:1,100)
RandomBlock(-4,19,1,quark:iron_plate:1,70,STAINED_CLAY:15,30,STAINED_CLAY:7,30,null,30,quark:iron_plate:1,100)
RandomBlock(-4,19,2,quark:iron_plate:1,70,STAINED_CLAY:15,30,STAINED_CLAY:7,30,null,30,quark:iron_plate:1,100)
RandomBlock(-4,19,3,quark:iron_plate:1,70,STAINED_CLAY:15,30,STAINED_CLAY:7,30,null,30,quark:iron_plate:1,100)
RandomBlock(-4,20,1,quark:iron_plate:1,70,STAINED_CLAY:15,30,STAINED_CLAY:7,30,null,30,quark:iron_plate:1,100)
RandomBlock(-4,20,2,quark:iron_plate:1,70,STAINED_CLAY:15,30,STAINED_CLAY:7,30,null,30,quark:iron_plate:1,100)
RandomBlock(-4,20,3,quark:iron_plate:1,70,STAINED_CLAY:15,30,STAINED_CLAY:7,30,null,30,quark:iron_plate:1,100)
RandomBlock(-4,21,1,quark:iron_plate:1,70,STAINED_CLAY:15,30,STAINED_CLAY:7,30,null,30,quark:iron_plate:1,100)
RandomBlock(-4,21,2,quark:iron_plate:1,70,STAINED_CLAY:15,30,STAINED_CLAY:7,30,null,30,quark:iron_plate:1,100)
RandomBlock(-4,21,3,quark:iron_plate:1,70,STAINED_CLAY:15,30,STAINED_CLAY:7,30,null,30,quark:iron_plate:1,100)
RandomBlock(-4,22,1,quark:iron_plate:1,70,STAINED_CLAY:15,30,STAINED_CLAY:7,30,null,30,quark:iron_plate:1,100)
RandomBlock(-4,22,2,quark:iron_plate:1,70,STAINED_CLAY:15,30,STAINED_CLAY:7,30,null,30,quark:iron_plate:1,100)
RandomBlock(-4,22,3,quark:iron_plate:1,70,STAINED_CLAY:15,30,STAINED_CLAY:7,30,null,30,quark:iron_plate:1,100)
RandomBlock(-4,23,1,rustic:iron_lattice,30,rustic:iron_lattice,30,biomesoplenty:leaves_2:7,30,quark:iron_plate_stairs:6,10,quark:iron_plate_stairs:0,10,quark:iron_plate_stairs:5,10,quark:iron_plate_stairs,10,quark:iron_plate_slab:8,10,quark:iron_plate_stairs:7,10,quark:iron_plate_stairs:1,10,quark:iron_plate_slab,10,quark:iron_plate_stairs:4,10,quark:iron_plate_stairs:2,10,rustic:iron_lattice,50,rustic:iron_lattice,50,biomesoplenty:leaves_2:7,100)
RandomBlock(-4,23,2,quark:iron_plate:1,70,STAINED_CLAY:15,30,STAINED_CLAY:7,30,null,30,quark:iron_plate:1,100)
RandomBlock(-4,23,3,quark:iron_plate:1,70,STAINED_CLAY:15,30,STAINED_CLAY:7,30,null,30,quark:iron_plate:1,100)
RandomBlock(-4,24,1,quark:iron_plate:1,70,STAINED_CLAY:15,30,STAINED_CLAY:7,30,null,30,quark:iron_plate:1,100)
RandomBlock(-4,24,2,quark:iron_plate:1,70,STAINED_CLAY:15,30,STAINED_CLAY:7,30,null,30,quark:iron_plate:1,100)
RandomBlock(-4,24,3,quark:iron_plate:1,70,STAINED_CLAY:15,30,STAINED_CLAY:7,30,null,30,quark:iron_plate:1,100)
RandomBlock(-4,25,1,quark:iron_plate:1,70,STAINED_CLAY:15,30,STAINED_CLAY:7,30,null,30,quark:iron_plate:1,100)
RandomBlock(-4,25,2,quark:iron_plate:1,70,STAINED_CLAY:15,30,STAINED_CLAY:7,30,null,30,quark:iron_plate:1,100)
RandomBlock(-4,25,3,quark:iron_plate:1,70,STAINED_CLAY:15,30,STAINED_CLAY:7,30,null,30,quark:iron_plate:1,100)
RandomBlock(-4,26,1,quark:iron_plate:1,70,STAINED_CLAY:15,30,STAINED_CLAY:7,30,null,30,quark:iron_plate:1,100)
RandomBlock(-4,26,2,quark:iron_plate:1,70,STAINED_CLAY:15,30,STAINED_CLAY:7,30,null,30,quark:iron_plate:1,100)
RandomBlock(-4,26,3,quark:iron_plate:1,70,STAINED_CLAY:15,30,STAINED_CLAY:7,30,null,30,quark:iron_plate:1,100)
RandomBlock(-4,27,1,quark:iron_plate:1,70,STAINED_CLAY:15,30,STAINED_CLAY:7,30,null,30,quark:iron_plate:1,100)
RandomBlock(-4,27,2,quark:iron_plate:1,70,STAINED_CLAY:15,30,STAINED_CLAY:7,30,null,30,quark:iron_plate:1,100)
RandomBlock(-4,27,3,quark:iron_plate:1,70,STAINED_CLAY:15,30,STAINED_CLAY:7,30,null,30,quark:iron_plate:1,100)
RandomBlock(-4,28,1,rustic:iron_lattice,30,rustic:iron_lattice,30,biomesoplenty:leaves_2:7,30,quark:iron_plate_stairs:6,10,quark:iron_plate_stairs:0,10,quark:iron_plate_stairs:5,10,quark:iron_plate_stairs,10,quark:iron_plate_slab:8,10,quark:iron_plate_stairs:7,10,quark:iron_plate_stairs:1,10,quark:iron_plate_slab,10,quark:iron_plate_stairs:4,10,quark:iron_plate_stairs:2,10,rustic:iron_lattice,50,rustic:iron_lattice,50,biomesoplenty:leaves_2:7,100)
RandomBlock(-4,28,2,quark:iron_plate:1,70,STAINED_CLAY:15,30,STAINED_CLAY:7,30,null,30,quark:iron_plate:1,100)
RandomBlock(-4,28,3,quark:iron_plate:1,70,STAINED_CLAY:15,30,STAINED_CLAY:7,30,null,30,quark:iron_plate:1,100)
RandomBlock(-4,29,1,quark:iron_plate:1,70,STAINED_CLAY:15,30,STAINED_CLAY:7,30,null,30,quark:iron_plate:1,100)
RandomBlock(-4,29,2,quark:iron_plate:1,70,STAINED_CLAY:15,30,STAINED_CLAY:7,30,null,30,quark:iron_plate:1,100)
RandomBlock(-4,29,3,quark:iron_plate:1,70,STAINED_CLAY:15,30,STAINED_CLAY:7,30,null,30,quark:iron_plate:1,100)
RandomBlock(-4,30,1,quark:iron_plate:1,70,STAINED_CLAY:15,30,STAINED_CLAY:7,30,null,30,quark:iron_plate:1,100)
RandomBlock(-4,30,2,quark:iron_plate:1,70,STAINED_CLAY:15,30,STAINED_CLAY:7,30,null,30,quark:iron_plate:1,100)
RandomBlock(-4,30,3,quark:iron_plate:1,70,STAINED_CLAY:15,30,STAINED_CLAY:7,30,null,30,quark:iron_plate:1,100)
RandomBlock(-4,31,1,quark:iron_plate:1,70,STAINED_CLAY:15,30,STAINED_CLAY:7,30,null,30,quark:iron_plate:1,100)
RandomBlock(-4,31,2,quark:iron_plate:1,70,STAINED_CLAY:15,30,STAINED_CLAY:7,30,null,30,quark:iron_plate:1,100)
RandomBlock(-4,31,3,quark:iron_plate:1,70,STAINED_CLAY:15,30,STAINED_CLAY:7,30,null,30,quark:iron_plate:1,100)
RandomBlock(-4,32,1,quark:iron_plate:1,70,STAINED_CLAY:15,30,STAINED_CLAY:7,30,null,30,quark:iron_plate:1,100)
RandomBlock(-4,32,2,quark:iron_plate:1,70,STAINED_CLAY:15,30,STAINED_CLAY:7,30,null,30,quark:iron_plate:1,100)
RandomBlock(-4,32,3,quark:iron_plate:1,70,STAINED_CLAY:15,30,STAINED_CLAY:7,30,null,30,quark:iron_plate:1,100)
RandomBlock(-4,33,1,quark:iron_plate:1,70,STAINED_CLAY:15,30,STAINED_CLAY:7,30,null,30,quark:iron_plate:1,100)
RandomBlock(-4,33,2,quark:iron_plate:1,70,STAINED_CLAY:15,30,STAINED_CLAY:7,30,null,30,quark:iron_plate:1,100)
RandomBlock(-4,33,3,quark:iron_plate:1,70,STAINED_CLAY:15,30,STAINED_CLAY:7,30,null,30,quark:iron_plate:1,100)
RandomBlock(-4,34,1,quark:iron_plate:1,70,STAINED_CLAY:15,30,STAINED_CLAY:7,30,null,30,quark:iron_plate:1,100)
RandomBlock(-4,34,2,quark:iron_plate:1,70,STAINED_CLAY:15,30,STAINED_CLAY:7,30,null,30,quark:iron_plate:1,100)
RandomBlock(-4,34,3,quark:iron_plate:1,70,STAINED_CLAY:15,30,STAINED_CLAY:7,30,null,30,quark:iron_plate:1,100)
RandomBlock(-4,35,1,rustic:iron_lattice,30,rustic:iron_lattice,30,biomesoplenty:leaves_2:7,30,quark:iron_plate_stairs:6,10,quark:iron_plate_stairs:0,10,quark:iron_plate_stairs:5,10,quark:iron_plate_stairs,10,quark:iron_plate_slab:8,10,quark:iron_plate_stairs:7,10,quark:iron_plate_stairs:1,10,quark:iron_plate_slab,10,quark:iron_plate_stairs:4,10,quark:iron_plate_stairs:2,10,rustic:iron_lattice,50,rustic:iron_lattice,50,biomesoplenty:leaves_2:7,100)
RandomBlock(-4,35,2,quark:iron_plate:1,70,STAINED_CLAY:15,30,STAINED_CLAY:7,30,null,30,quark:iron_plate:1,100)
RandomBlock(-4,35,3,quark:iron_plate:1,70,STAINED_CLAY:15,30,STAINED_CLAY:7,30,null,30,quark:iron_plate:1,100)
RandomBlock(-4,36,1,rustic:iron_lattice,30,rustic:iron_lattice,30,biomesoplenty:leaves_2:7,30,quark:iron_plate_stairs:6,10,quark:iron_plate_stairs:0,10,quark:iron_plate_stairs:5,10,quark:iron_plate_stairs,10,quark:iron_plate_slab:8,10,quark:iron_plate_stairs:7,10,quark:iron_plate_stairs:1,10,quark:iron_plate_slab,10,quark:iron_plate_stairs:4,10,quark:iron_plate_stairs:2,10,rustic:iron_lattice,50,rustic:iron_lattice,50,biomesoplenty:leaves_2:7,100)
RandomBlock(-4,36,2,rustic:iron_lattice,30,rustic:iron_lattice,30,biomesoplenty:leaves_2:7,30,quark:iron_plate_stairs:6,10,quark:iron_plate_stairs:0,10,quark:iron_plate_stairs:5,10,quark:iron_plate_stairs,10,quark:iron_plate_slab:8,10,quark:iron_plate_stairs:7,10,quark:iron_plate_stairs:1,10,quark:iron_plate_slab,10,quark:iron_plate_stairs:4,10,quark:iron_plate_stairs:2,10,rustic:iron_lattice,50,rustic:iron_lattice,50,biomesoplenty:leaves_2:7,100)
RandomBlock(-4,36,3,quark:iron_plate:1,70,STAINED_CLAY:15,30,STAINED_CLAY:7,30,null,30,quark:iron_plate:1,100)
RandomBlock(-4,37,1,rustic:iron_lattice,30,rustic:iron_lattice,30,biomesoplenty:leaves_2:7,30,quark:iron_plate_stairs:6,10,quark:iron_plate_stairs:0,10,quark:iron_plate_stairs:5,10,quark:iron_plate_stairs,10,quark:iron_plate_slab:8,10,quark:iron_plate_stairs:7,10,quark:iron_plate_stairs:1,10,quark:iron_plate_slab,10,quark:iron_plate_stairs:4,10,quark:iron_plate_stairs:2,10,rustic:iron_lattice,50,rustic:iron_lattice,50,biomesoplenty:leaves_2:7,100)
RandomBlock(-4,37,2,quark:iron_plate:1,70,STAINED_CLAY:15,30,STAINED_CLAY:7,30,null,30,quark:iron_plate:1,100)
RandomBlock(-4,37,3,quark:iron_plate:1,70,STAINED_CLAY:15,30,STAINED_CLAY:7,30,null,30,quark:iron_plate:1,100)
RandomBlock(-4,38,1,rustic:iron_lattice,30,rustic:iron_lattice,30,biomesoplenty:leaves_2:7,30,quark:iron_plate_stairs:6,10,quark:iron_plate_stairs:0,10,quark:iron_plate_stairs:5,10,quark:iron_plate_stairs,10,quark:iron_plate_slab:8,10,quark:iron_plate_stairs:7,10,quark:iron_plate_stairs:1,10,quark:iron_plate_slab,10,quark:iron_plate_stairs:4,10,quark:iron_plate_stairs:2,10,rustic:iron_lattice,50,rustic:iron_lattice,50,biomesoplenty:leaves_2:7,100)
RandomBlock(-4,38,2,rustic:iron_lattice,30,rustic:iron_lattice,30,biomesoplenty:leaves_2:7,30,quark:iron_plate_stairs:6,10,quark:iron_plate_stairs:0,10,quark:iron_plate_stairs:5,10,quark:iron_plate_stairs,10,quark:iron_plate_slab:8,10,quark:iron_plate_stairs:7,10,quark:iron_plate_stairs:1,10,quark:iron_plate_slab,10,quark:iron_plate_stairs:4,10,quark:iron_plate_stairs:2,10,rustic:iron_lattice,50,rustic:iron_lattice,50,biomesoplenty:leaves_2:7,100)
RandomBlock(-4,38,3,quark:iron_plate:1,70,STAINED_CLAY:15,30,STAINED_CLAY:7,30,null,30,quark:iron_plate:1,100)
RandomBlock(-4,39,1,rustic:iron_lattice,30,rustic:iron_lattice,30,biomesoplenty:leaves_2:7,30,quark:iron_plate_stairs:6,10,quark:iron_plate_stairs:0,10,quark:iron_plate_stairs:5,10,quark:iron_plate_stairs,10,quark:iron_plate_slab:8,10,quark:iron_plate_stairs:7,10,quark:iron_plate_stairs:1,10,quark:iron_plate_slab,10,quark:iron_plate_stairs:4,10,quark:iron_plate_stairs:2,10,rustic:iron_lattice,50,rustic:iron_lattice,50,biomesoplenty:leaves_2:7,100)
RandomBlock(-4,39,2,quark:iron_plate:1,70,STAINED_CLAY:15,30,STAINED_CLAY:7,30,null,30,quark:iron_plate:1,100)
RandomBlock(-4,39,3,quark:iron_plate:1,70,STAINED_CLAY:15,30,STAINED_CLAY:7,30,null,30,quark:iron_plate:1,100)
RandomBlock(-4,40,1,quark:iron_plate:1,70,STAINED_CLAY:15,30,STAINED_CLAY:7,30,null,30,quark:iron_plate:1,100)
RandomBlock(-4,40,2,quark:iron_plate:1,70,STAINED_CLAY:15,30,STAINED_CLAY:7,30,null,30,quark:iron_plate:1,100)
RandomBlock(-4,40,3,quark:iron_plate:1,70,STAINED_CLAY:15,30,STAINED_CLAY:7,30,null,30,quark:iron_plate:1,100)
