
#######################################################################
# +-----------------------------------------------------------------+ #
# |                            BO4 object                           | #
# +-----------------------------------------------------------------+ #
#######################################################################

Author: NLBlackEagle

Description: No description given

SettingsMode: WriteWithoutComments


#######################################################################
# +-----------------------------------------------------------------+ #
# |                          Main settings                          | #
# +-----------------------------------------------------------------+ #
#######################################################################

FixedRotation: 

Frequency: 0

SpawnHeight: highestBlock

UseCenterForHighestBlock: true

##############################
# Height Limits for the BO4. #
##############################

MinHeight: 0

MaxHeight: 255

InheritBO3: 

InheritBO3Rotation: NORTH

OverrideChildSettings: true

OverrideParentHeight: false

CanOverride: true

BranchFrequency: 0

BranchFrequencyGroup: 

MustBeBelowOther: false

MustBeInside: 

CannotBeInside: 

ReplacesBO3: 

MustBeInsideWorldBorders: false

CanSpawnOnWater: true

SpawnOnWaterOnly: false

SpawnUnderWater: false

SpawnAtWaterLevel: false

HeightOffset: 0

RemoveAir: false

ReplaceAbove: 

ReplaceBelow: 

ReplaceWithBiomeBlocks: true

ReplaceWithSurfaceBlock: GRASS

ReplaceWithGroundBlock: DIRT

ReplaceWithStoneBlock: STONE

SmoothRadius: 0

SmoothHeightOffset: 0

SmoothStartTop: false

SmoothStartWood: false

SmoothingSurfaceBlock: 

SmoothingGroundBlock: 

BO3Group: 

IsSpawnPoint: false

DoReplaceBlocks: false


#######################################################################
# +-----------------------------------------------------------------+ #
# |                              Blocks                             | #
# +-----------------------------------------------------------------+ #
#######################################################################

Block(-8,0,-6,quark:limestone)
Block(-8,0,-5,quark:limestone)
Block(-8,0,-4,quark:limestone)
Block(-8,0,-3,quark:limestone)
Block(-8,0,-2,quark:limestone)
Block(-8,0,-1,quark:limestone)
Block(-8,0,0,quark:limestone)
Block(-8,0,1,quark:limestone)
Block(-8,0,2,quark:limestone)
Block(-8,0,4,quark:limestone)
Block(-8,0,5,quark:limestone)
Block(-8,0,6,quark:limestone)
Block(-8,0,7,quark:limestone)
Block(-8,0,8,quark:limestone)
Block(-8,1,-6,SMOOTH_STAIRS:2)
RandomBlock(-8,1,-5,quark:iron_plate:1,70,STAINED_CLAY:15,30,STAINED_CLAY:7,30,null,30,quark:iron_plate:1,100)
RandomBlock(-8,1,-4,quark:iron_plate:1,70,STAINED_CLAY:15,30,STAINED_CLAY:7,30,null,30,quark:iron_plate:1,100)
RandomBlock(-8,1,-3,quark:iron_plate:1,70,STAINED_CLAY:15,30,STAINED_CLAY:7,30,null,30,quark:iron_plate:1,100)
RandomBlock(-8,1,-2,quark:iron_plate:1,70,STAINED_CLAY:15,30,STAINED_CLAY:7,30,null,30,quark:iron_plate:1,100)
RandomBlock(-8,1,-1,quark:iron_plate:1,70,STAINED_CLAY:15,30,STAINED_CLAY:7,30,null,30,quark:iron_plate:1,100)
RandomBlock(-8,1,0,quark:iron_plate:1,70,STAINED_CLAY:15,30,STAINED_CLAY:7,30,null,30,quark:iron_plate:1,100)
RandomBlock(-8,1,1,quark:iron_plate:1,70,STAINED_CLAY:15,30,STAINED_CLAY:7,30,null,30,quark:iron_plate:1,100)
Block(-8,1,2,SMOOTH_STAIRS:3)
Block(-8,1,4,COBBLESTONE_STAIRS:0)
Block(-8,1,5,COBBLESTONE_STAIRS:0)
Block(-8,1,6,COBBLESTONE_STAIRS:0)
Block(-8,1,7,COBBLESTONE_STAIRS:0)
Block(-8,1,8,COBBLESTONE_STAIRS:3)
Block(-8,2,-6,SMOOTH_STAIRS:6)
Block(-8,2,-5,srparasites:deadblood:1)
Block(-8,2,-4,srparasites:deadblood:2)
Block(-8,2,-3,srparasites:deadblood:1)
Block(-8,2,-2,srparasites:deadblood:2)
Block(-8,2,-1,srparasites:deadblood:1)
Block(-8,2,0,srparasites:deadblood)
Block(-8,2,1,srparasites:deadblood:1)
Block(-8,2,2,SMOOTH_STAIRS:7)
Block(-8,3,-6,quark:world_stone_pavement:2)
Block(-8,3,-5,quark:framed_glass)
RandomBlock(-8,3,-4,quark:iron_plate:1,70,STAINED_CLAY:15,30,STAINED_CLAY:7,30,null,30,quark:iron_plate:1,100)
RandomBlock(-8,3,-3,quark:iron_plate:1,70,STAINED_CLAY:15,30,STAINED_CLAY:7,30,null,30,quark:iron_plate:1,100)
RandomBlock(-8,3,-2,quark:iron_plate:1,70,STAINED_CLAY:15,30,STAINED_CLAY:7,30,null,30,quark:iron_plate:1,100)
Block(-8,3,-1,quark:framed_glass)
Block(-8,3,0,quark:framed_glass)
Block(-8,3,1,quark:framed_glass)
Block(-8,3,2,quark:world_stone_pavement:2)
Block(-8,4,-7,quark:world_stone_pavement:2)
Block(-8,4,-6,quark:world_stone_pavement:2)
Block(-8,4,-5,AIR:0)
Block(-8,4,-4,quark:framed_glass)
Block(-8,4,-3,quark:framed_glass)
Block(-8,4,-2,quark:framed_glass)
Block(-8,4,-1,AIR:0)
Block(-8,4,0,AIR:0)
Block(-8,4,1,AIR:0)
Block(-8,4,2,quark:world_stone_pavement:2)
Block(-8,5,-7,quark:basalt_wall)
Block(-8,5,-6,quark:world_stone_pavement:2)
Block(-8,5,-5,AIR:0)
Block(-8,5,-4,quark:framed_glass)
Block(-8,5,-3,quark:framed_glass)
Block(-8,5,-2,quark:framed_glass)
Block(-8,5,-1,AIR:0)
Block(-8,5,0,AIR:0)
Block(-8,5,1,AIR:0)
Block(-8,5,2,quark:world_stone_pavement:2)
Block(-8,6,-7,quark:basalt_wall)
Block(-8,6,-6,quark:world_stone_pavement:2)
Block(-8,6,-5,AIR:0)
RandomBlock(-8,6,-4,quark:iron_plate:1,70,STAINED_CLAY:15,30,STAINED_CLAY:7,30,null,30,quark:iron_plate:1,100)
RandomBlock(-8,6,-3,quark:iron_plate:1,70,STAINED_CLAY:15,30,STAINED_CLAY:7,30,null,30,quark:iron_plate:1,100)
RandomBlock(-8,6,-2,quark:iron_plate:1,70,STAINED_CLAY:15,30,STAINED_CLAY:7,30,null,30,quark:iron_plate:1,100)
Block(-8,6,-1,AIR:0)
Block(-8,6,0,AIR:0)
Block(-8,6,1,AIR:0)
Block(-8,6,2,quark:world_stone_pavement:2)
Block(-8,7,-7,COBBLESTONE_STAIRS:2)
Block(-8,7,-6,quark:world_stone_pavement:2)
Block(-8,7,-5,AIR:0)
Block(-8,7,-4,COBBLESTONE_STAIRS:2)
Block(-8,7,-3,COBBLESTONE_STAIRS:1)
Block(-8,7,-2,COBBLESTONE_STAIRS:3)
Block(-8,7,-1,AIR:0)
Block(-8,7,0,AIR:0)
Block(-8,7,1,AIR:0)
Block(-8,7,2,quark:world_stone_pavement:2)
Block(-8,8,-6,quark:world_stone_pavement:2)
Block(-8,8,-5,quark:world_stone_pavement:2)
Block(-8,8,-4,quark:world_stone_pavement:2)
Block(-8,8,-3,quark:world_stone_pavement:2)
Block(-8,8,-2,quark:world_stone_pavement:2)
Block(-8,8,-1,quark:world_stone_pavement:2)
Block(-8,8,0,quark:world_stone_pavement:2)
Block(-8,8,1,quark:world_stone_pavement:2)
Block(-8,8,2,quark:world_stone_pavement:2)
RandomBlock(-8,9,-3,quark:iron_plate:1,70,STAINED_CLAY:15,30,STAINED_CLAY:7,30,null,30,quark:iron_plate:1,100)
RandomBlock(-8,9,0,quark:iron_plate:1,70,STAINED_CLAY:15,30,STAINED_CLAY:7,30,null,30,quark:iron_plate:1,100)
Block(-8,9,2,quark:stone_basalt_slab)
Block(-7,0,-6,quark:limestone)
Block(-7,0,-5,quark:limestone)
Block(-7,0,-4,quark:limestone)
Block(-7,0,-3,quark:limestone)
Block(-7,0,-2,quark:limestone)
Block(-7,0,-1,quark:limestone)
Block(-7,0,0,quark:limestone)
Block(-7,0,1,quark:limestone)
Block(-7,0,2,quark:limestone)
Block(-7,0,4,quark:limestone)
RandomBlock(-7,0,5,quark:iron_plate:1,70,STAINED_CLAY:15,30,STAINED_CLAY:7,30,null,30,quark:iron_plate:1,100)
RandomBlock(-7,0,6,quark:iron_plate:1,70,STAINED_CLAY:15,30,STAINED_CLAY:7,30,null,30,quark:iron_plate:1,100)
RandomBlock(-7,0,7,quark:iron_plate:1,70,STAINED_CLAY:15,30,STAINED_CLAY:7,30,null,30,quark:iron_plate:1,100)
Block(-7,0,8,quark:limestone)
Block(-7,1,-6,SMOOTH_STAIRS:2)
RandomBlock(-7,1,-5,quark:iron_plate:1,70,STAINED_CLAY:15,30,STAINED_CLAY:7,30,null,30,quark:iron_plate:1,100)
RandomBlock(-7,1,-4,quark:iron_plate:1,70,STAINED_CLAY:15,30,STAINED_CLAY:7,30,null,30,quark:iron_plate:1,100)
RandomBlock(-7,1,-3,quark:iron_plate:1,70,STAINED_CLAY:15,30,STAINED_CLAY:7,30,null,30,quark:iron_plate:1,100)
RandomBlock(-7,1,-2,quark:iron_plate:1,70,STAINED_CLAY:15,30,STAINED_CLAY:7,30,null,30,quark:iron_plate:1,100)
RandomBlock(-7,1,-1,quark:iron_plate:1,70,STAINED_CLAY:15,30,STAINED_CLAY:7,30,null,30,quark:iron_plate:1,100)
RandomBlock(-7,1,0,quark:iron_plate:1,70,STAINED_CLAY:15,30,STAINED_CLAY:7,30,null,30,quark:iron_plate:1,100)
RandomBlock(-7,1,1,quark:iron_plate:1,70,STAINED_CLAY:15,30,STAINED_CLAY:7,30,null,30,quark:iron_plate:1,100)
Block(-7,1,2,SMOOTH_STAIRS:3)
Block(-7,1,4,COBBLESTONE_STAIRS:2)
RandomBlock(-7,1,5,quark:iron_plate:1,70,STAINED_CLAY:15,30,STAINED_CLAY:7,30,null,30,quark:iron_plate:1,100)
RandomBlock(-7,1,6,quark:iron_plate:1,70,STAINED_CLAY:15,30,STAINED_CLAY:7,30,null,30,quark:iron_plate:1,100)
RandomBlock(-7,1,7,quark:iron_plate:1,70,STAINED_CLAY:15,30,STAINED_CLAY:7,30,null,30,quark:iron_plate:1,100)
Block(-7,1,8,COBBLESTONE_STAIRS:3)
Block(-7,2,-6,SMOOTH_STAIRS:6)
Block(-7,2,-5,srparasites:deadblood:1)
Block(-7,2,-4,srparasites:deadblood:1)
Block(-7,2,-3,srparasites:deadblood)
Block(-7,2,-2,srparasites:deadblood:1)
Block(-7,2,-1,srparasites:deadblood)
Block(-7,2,0,srparasites:deadblood:1)
Block(-7,2,1,srparasites:deadblood:1)
Block(-7,2,2,SMOOTH_STAIRS:7)
RandomBlock(-7,2,5,quark:iron_plate:1,70,STAINED_CLAY:15,30,STAINED_CLAY:7,30,null,30,quark:iron_plate:1,100)
RandomBlock(-7,2,6,quark:iron_plate:1,70,STAINED_CLAY:15,30,STAINED_CLAY:7,30,null,30,quark:iron_plate:1,100)
RandomBlock(-7,2,7,rustic:iron_lattice,30,rustic:iron_lattice,30,biomesoplenty:leaves_2:7,30,quark:iron_plate_stairs:6,10,quark:iron_plate_stairs:0,10,quark:iron_plate_stairs:5,10,quark:iron_plate_stairs,10,quark:iron_plate_slab:8,10,quark:iron_plate_stairs:7,10,quark:iron_plate_stairs:1,10,quark:iron_plate_slab,10,quark:iron_plate_stairs:4,10,quark:iron_plate_stairs:2,10,rustic:iron_lattice,50,rustic:iron_lattice,50,biomesoplenty:leaves_2:7,100)
Block(-7,3,-6,quark:world_stone_pavement:2)
Block(-7,3,-5,quark:framed_glass)
Block(-7,3,-4,quark:framed_glass)
Block(-7,3,-3,quark:framed_glass)
Block(-7,3,-2,quark:framed_glass)
Block(-7,3,-1,quark:framed_glass)
RandomBlock(-7,3,0,quark:iron_plate:1,70,STAINED_CLAY:15,30,STAINED_CLAY:7,30,null,30,quark:iron_plate:1,100)
RandomBlock(-7,3,1,quark:iron_plate:1,70,STAINED_CLAY:15,30,STAINED_CLAY:7,30,null,30,quark:iron_plate:1,100)
Block(-7,3,2,quark:world_stone_pavement:2)
RandomBlock(-7,3,5,quark:iron_plate:1,70,STAINED_CLAY:15,30,STAINED_CLAY:7,30,null,30,quark:iron_plate:1,100)
RandomBlock(-7,3,6,quark:iron_plate:1,70,STAINED_CLAY:15,30,STAINED_CLAY:7,30,null,30,quark:iron_plate:1,100)
RandomBlock(-7,3,7,quark:iron_plate:1,70,STAINED_CLAY:15,30,STAINED_CLAY:7,30,null,30,quark:iron_plate:1,100)
Block(-7,4,-7,quark:world_stone_pavement:2)
Block(-7,4,-6,quark:world_stone_pavement:2)
Block(-7,4,-5,AIR:0)
Block(-7,4,-4,AIR:0)
Block(-7,4,-3,AIR:0)
Block(-7,4,-2,AIR:0)
Block(-7,4,-1,AIR:0)
Block(-7,4,0,quark:framed_glass)
Block(-7,4,1,quark:framed_glass)
Block(-7,4,2,quark:world_stone_pavement:2)
Block(-7,4,3,COBBLESTONE_STAIRS:4)
Block(-7,4,4,COBBLESTONE_STAIRS:4)
RandomBlock(-7,4,5,quark:iron_plate:1,70,STAINED_CLAY:15,30,STAINED_CLAY:7,30,null,30,quark:iron_plate:1,100)
RandomBlock(-7,4,6,quark:iron_plate:1,70,STAINED_CLAY:15,30,STAINED_CLAY:7,30,null,30,quark:iron_plate:1,100)
RandomBlock(-7,4,7,rustic:iron_lattice,30,rustic:iron_lattice,30,biomesoplenty:leaves_2:7,30,quark:iron_plate_stairs:6,10,quark:iron_plate_stairs:0,10,quark:iron_plate_stairs:5,10,quark:iron_plate_stairs,10,quark:iron_plate_slab:8,10,quark:iron_plate_stairs:7,10,quark:iron_plate_stairs:1,10,quark:iron_plate_slab,10,quark:iron_plate_stairs:4,10,quark:iron_plate_stairs:2,10,rustic:iron_lattice,50,rustic:iron_lattice,50,biomesoplenty:leaves_2:7,100)
Block(-7,5,-6,quark:framed_glass_pane)
Block(-7,5,-5,AIR:0)
Block(-7,5,-4,AIR:0)
Block(-7,5,-3,AIR:0)
Block(-7,5,-2,AIR:0)
Block(-7,5,-1,AIR:0)
RandomBlock(-7,5,0,quark:iron_plate:1,70,STAINED_CLAY:15,30,STAINED_CLAY:7,30,null,30,quark:iron_plate:1,100)
RandomBlock(-7,5,1,quark:iron_plate:1,70,STAINED_CLAY:15,30,STAINED_CLAY:7,30,null,30,quark:iron_plate:1,100)
Block(-7,5,2,quark:world_stone_pavement:2)
RandomBlock(-7,5,3,quark:iron_plate:1,70,STAINED_CLAY:15,30,STAINED_CLAY:7,30,null,30,quark:iron_plate:1,100)
RandomBlock(-7,5,4,quark:iron_plate:1,70,STAINED_CLAY:15,30,STAINED_CLAY:7,30,null,30,quark:iron_plate:1,100)
RandomBlock(-7,5,5,quark:iron_plate:1,70,STAINED_CLAY:15,30,STAINED_CLAY:7,30,null,30,quark:iron_plate:1,100)
RandomBlock(-7,5,6,quark:iron_plate:1,70,STAINED_CLAY:15,30,STAINED_CLAY:7,30,null,30,quark:iron_plate:1,100)
RandomBlock(-7,5,7,rustic:iron_lattice,30,rustic:iron_lattice,30,biomesoplenty:leaves_2:7,30,quark:iron_plate_stairs:6,10,quark:iron_plate_stairs:0,10,quark:iron_plate_stairs:5,10,quark:iron_plate_stairs,10,quark:iron_plate_slab:8,10,quark:iron_plate_stairs:7,10,quark:iron_plate_stairs:1,10,quark:iron_plate_slab,10,quark:iron_plate_stairs:4,10,quark:iron_plate_stairs:2,10,rustic:iron_lattice,50,rustic:iron_lattice,50,biomesoplenty:leaves_2:7,100)
Block(-7,6,-6,quark:framed_glass_pane)
Block(-7,6,-5,AIR:0)
Block(-7,6,-4,AIR:0)
Block(-7,6,-3,AIR:0)
Block(-7,6,-2,AIR:0)
Block(-7,6,-1,AIR:0)
Block(-7,6,0,COBBLESTONE_STAIRS:0)
Block(-7,6,1,COBBLESTONE_STAIRS:0)
Block(-7,6,2,quark:world_stone_pavement:2)
Block(-7,6,3,COBBLESTONE_STAIRS:0)
Block(-7,6,4,COBBLESTONE_STAIRS:0)
RandomBlock(-7,6,5,rustic:iron_lattice,30,rustic:iron_lattice,30,biomesoplenty:leaves_2:7,30,quark:iron_plate_stairs:6,10,quark:iron_plate_stairs:0,10,quark:iron_plate_stairs:5,10,quark:iron_plate_stairs,10,quark:iron_plate_slab:8,10,quark:iron_plate_stairs:7,10,quark:iron_plate_stairs:1,10,quark:iron_plate_slab,10,quark:iron_plate_stairs:4,10,quark:iron_plate_stairs:2,10,rustic:iron_lattice,50,rustic:iron_lattice,50,biomesoplenty:leaves_2:7,100)
RandomBlock(-7,6,6,rustic:iron_lattice,30,rustic:iron_lattice,30,biomesoplenty:leaves_2:7,30,quark:iron_plate_stairs:6,10,quark:iron_plate_stairs:0,10,quark:iron_plate_stairs:5,10,quark:iron_plate_stairs,10,quark:iron_plate_slab:8,10,quark:iron_plate_stairs:7,10,quark:iron_plate_stairs:1,10,quark:iron_plate_slab,10,quark:iron_plate_stairs:4,10,quark:iron_plate_stairs:2,10,rustic:iron_lattice,50,rustic:iron_lattice,50,biomesoplenty:leaves_2:7,100)
RandomBlock(-7,6,7,rustic:iron_lattice,30,rustic:iron_lattice,30,biomesoplenty:leaves_2:7,30,quark:iron_plate_stairs:6,10,quark:iron_plate_stairs:0,10,quark:iron_plate_stairs:5,10,quark:iron_plate_stairs,10,quark:iron_plate_slab:8,10,quark:iron_plate_stairs:7,10,quark:iron_plate_stairs:1,10,quark:iron_plate_slab,10,quark:iron_plate_stairs:4,10,quark:iron_plate_stairs:2,10,rustic:iron_lattice,50,rustic:iron_lattice,50,biomesoplenty:leaves_2:7,100)
Block(-7,7,-7,COBBLESTONE_STAIRS:2)
Block(-7,7,-6,quark:world_stone_pavement:2)
Block(-7,7,-5,AIR:0)
Block(-7,7,-4,AIR:0)
Block(-7,7,-3,AIR:0)
Block(-7,7,-2,AIR:0)
Block(-7,7,-1,AIR:0)
Block(-7,7,0,AIR:0)
Block(-7,7,1,AIR:0)
Block(-7,7,2,quark:world_stone_pavement:2)
Block(-7,7,5,rustic:iron_lattice:0)
Block(-7,7,6,rustic:iron_lattice:0)
Block(-7,7,7,rustic:iron_lattice:0)
Block(-7,8,-6,quark:world_stone_pavement:2)
Block(-7,8,-5,quark:world_stone_pavement:2)
Block(-7,8,-4,quark:world_stone_pavement:2)
Block(-7,8,-3,quark:world_stone_pavement:2)
Block(-7,8,-2,quark:world_stone_pavement:2)
Block(-7,8,-1,quark:world_stone_pavement:2)
Block(-7,8,0,quark:world_stone_pavement:2)
Block(-7,8,1,quark:world_stone_pavement:2)
Block(-7,8,2,quark:world_stone_pavement:2)
Block(-7,9,-5,DISPENSER:1)
Block(-7,9,-4,quark:iron_plate_slab)
RandomBlock(-7,9,-3,quark:iron_plate:1,70,STAINED_CLAY:15,30,STAINED_CLAY:7,30,null,30,quark:iron_plate:1,100)
RandomBlock(-7,9,0,quark:iron_plate:1,70,STAINED_CLAY:15,30,STAINED_CLAY:7,30,null,30,quark:iron_plate:1,100)
Block(-7,9,2,quark:stone_basalt_slab)
Block(-7,10,-5,quark:basalt_wall)
Block(-6,0,-6,quark:limestone)
Block(-6,0,-5,quark:limestone)
Block(-6,0,-4,quark:limestone)
Block(-6,0,-3,quark:limestone)
Block(-6,0,-2,quark:limestone)
Block(-6,0,-1,quark:limestone)
Block(-6,0,0,quark:limestone)
Block(-6,0,1,quark:limestone)
Block(-6,0,2,quark:limestone)
Block(-6,0,4,quark:limestone)
RandomBlock(-6,0,5,quark:iron_plate:1,70,STAINED_CLAY:15,30,STAINED_CLAY:7,30,null,30,quark:iron_plate:1,100)
Block(-6,0,6,srparasites:deadblood)
RandomBlock(-6,0,7,quark:iron_plate:1,70,STAINED_CLAY:15,30,STAINED_CLAY:7,30,null,30,quark:iron_plate:1,100)
Block(-6,0,8,quark:limestone)
Block(-6,1,-6,SMOOTH_STAIRS:2)
RandomBlock(-6,1,-5,quark:iron_plate:1,70,STAINED_CLAY:15,30,STAINED_CLAY:7,30,null,30,quark:iron_plate:1,100)
RandomBlock(-6,1,-4,quark:iron_plate:1,70,STAINED_CLAY:15,30,STAINED_CLAY:7,30,null,30,quark:iron_plate:1,100)
RandomBlock(-6,1,-3,quark:iron_plate:1,70,STAINED_CLAY:15,30,STAINED_CLAY:7,30,null,30,quark:iron_plate:1,100)
RandomBlock(-6,1,-2,quark:iron_plate:1,70,STAINED_CLAY:15,30,STAINED_CLAY:7,30,null,30,quark:iron_plate:1,100)
RandomBlock(-6,1,-1,quark:iron_plate:1,70,STAINED_CLAY:15,30,STAINED_CLAY:7,30,null,30,quark:iron_plate:1,100)
RandomBlock(-6,1,0,quark:iron_plate:1,70,STAINED_CLAY:15,30,STAINED_CLAY:7,30,null,30,quark:iron_plate:1,100)
RandomBlock(-6,1,1,quark:iron_plate:1,70,STAINED_CLAY:15,30,STAINED_CLAY:7,30,null,30,quark:iron_plate:1,100)
Block(-6,1,2,SMOOTH_STAIRS:3)
Block(-6,1,4,COBBLESTONE_STAIRS:2)
RandomBlock(-6,1,5,quark:iron_plate:1,70,STAINED_CLAY:15,30,STAINED_CLAY:7,30,null,30,quark:iron_plate:1,100)
Block(-6,1,6,srparasites:deadblood)
RandomBlock(-6,1,7,quark:iron_plate:1,70,STAINED_CLAY:15,30,STAINED_CLAY:7,30,null,30,quark:iron_plate:1,100)
Block(-6,1,8,COBBLESTONE_STAIRS:3)
Block(-6,2,-6,SMOOTH_STAIRS:6)
Block(-6,2,-5,srparasites:deadblood)
Block(-6,2,-4,srparasites:deadblood:1)
Block(-6,2,-3,srparasites:deadblood:1)
Block(-6,2,-2,srparasites:deadblood:1)
Block(-6,2,-1,srparasites:deadblood)
Block(-6,2,0,srparasites:deadblood:1)
Block(-6,2,1,srparasites:deadblood:1)
Block(-6,2,2,SMOOTH_STAIRS:7)
RandomBlock(-6,2,5,quark:iron_plate:1,70,STAINED_CLAY:15,30,STAINED_CLAY:7,30,null,30,quark:iron_plate:1,100)
Block(-6,2,6,srparasites:deadblood)
RandomBlock(-6,2,7,quark:iron_plate:1,70,STAINED_CLAY:15,30,STAINED_CLAY:7,30,null,30,quark:iron_plate:1,100)
Block(-6,3,-6,quark:world_stone_pavement:2)
Block(-6,3,-5,quark:framed_glass)
Block(-6,3,-4,quark:framed_glass)
Block(-6,3,-3,quark:framed_glass)
Block(-6,3,-2,quark:framed_glass)
Block(-6,3,-1,quark:framed_glass)
RandomBlock(-6,3,0,quark:iron_plate:1,70,STAINED_CLAY:15,30,STAINED_CLAY:7,30,null,30,quark:iron_plate:1,100)
Block(-6,3,1,srparasites:deadblood:1)
Block(-6,3,2,quark:world_stone_pavement:2)
RandomBlock(-6,3,5,quark:iron_plate:1,70,STAINED_CLAY:15,30,STAINED_CLAY:7,30,null,30,quark:iron_plate:1,100)
Block(-6,3,6,srparasites:deadblood)
RandomBlock(-6,3,7,quark:iron_plate:1,70,STAINED_CLAY:15,30,STAINED_CLAY:7,30,null,30,quark:iron_plate:1,100)
Block(-6,4,-7,quark:world_stone_pavement:2)
Block(-6,4,-6,quark:world_stone_pavement:2)
Block(-6,4,-5,AIR:0)
Block(-6,4,-4,AIR:0)
Block(-6,4,-3,AIR:0)
Block(-6,4,-2,AIR:0)
Block(-6,4,-1,AIR:0)
Block(-6,4,0,quark:framed_glass)
Block(-6,4,1,srparasites:deadblood)
Block(-6,4,2,quark:world_stone_pavement:2)
RandomBlock(-6,4,3,quark:iron_plate:1,70,STAINED_CLAY:15,30,STAINED_CLAY:7,30,null,30,quark:iron_plate:1,100)
RandomBlock(-6,4,4,quark:iron_plate:1,70,STAINED_CLAY:15,30,STAINED_CLAY:7,30,null,30,quark:iron_plate:1,100)
RandomBlock(-6,4,5,quark:iron_plate:1,70,STAINED_CLAY:15,30,STAINED_CLAY:7,30,null,30,quark:iron_plate:1,100)
Block(-6,4,6,srparasites:deadblood)
RandomBlock(-6,4,7,quark:iron_plate:1,70,STAINED_CLAY:15,30,STAINED_CLAY:7,30,null,30,quark:iron_plate:1,100)
Block(-6,5,-6,quark:framed_glass_pane)
Block(-6,5,-5,AIR:0)
Block(-6,5,-4,AIR:0)
Block(-6,5,-3,AIR:0)
Block(-6,5,-2,AIR:0)
Block(-6,5,-1,AIR:0)
RandomBlock(-6,5,0,quark:iron_plate:1,70,STAINED_CLAY:15,30,STAINED_CLAY:7,30,null,30,quark:iron_plate:1,100)
Block(-6,5,1,srparasites:deadblood)
Block(-6,5,2,srparasites:deadblood)
Block(-6,5,3,srparasites:deadblood)
Block(-6,5,4,srparasites:deadblood)
Block(-6,5,5,srparasites:deadblood)
Block(-6,5,6,srparasites:deadblood)
RandomBlock(-6,5,7,quark:iron_plate:1,70,STAINED_CLAY:15,30,STAINED_CLAY:7,30,null,30,quark:iron_plate:1,100)
Block(-6,6,-6,quark:framed_glass_pane)
Block(-6,6,-5,AIR:0)
Block(-6,6,-4,AIR:0)
Block(-6,6,-3,AIR:0)
Block(-6,6,-2,AIR:0)
Block(-6,6,-1,AIR:0)
Block(-6,6,0,COBBLESTONE_STAIRS:2)
RandomBlock(-6,6,1,quark:iron_plate:1,70,STAINED_CLAY:15,30,STAINED_CLAY:7,30,null,30,quark:iron_plate:1,100)
Block(-6,6,2,quark:world_stone_pavement:2)
RandomBlock(-6,6,3,quark:iron_plate:1,70,STAINED_CLAY:15,30,STAINED_CLAY:7,30,null,30,quark:iron_plate:1,100)
RandomBlock(-6,6,4,rustic:iron_lattice,30,rustic:iron_lattice,30,biomesoplenty:leaves_2:7,30,quark:iron_plate_stairs:6,10,quark:iron_plate_stairs:0,10,quark:iron_plate_stairs:5,10,quark:iron_plate_stairs,10,quark:iron_plate_slab:8,10,quark:iron_plate_stairs:7,10,quark:iron_plate_stairs:1,10,quark:iron_plate_slab,10,quark:iron_plate_stairs:4,10,quark:iron_plate_stairs:2,10,rustic:iron_lattice,50,rustic:iron_lattice,50,biomesoplenty:leaves_2:7,100)
RandomBlock(-6,6,5,rustic:iron_lattice,30,rustic:iron_lattice,30,biomesoplenty:leaves_2:7,30,quark:iron_plate_stairs:6,10,quark:iron_plate_stairs:0,10,quark:iron_plate_stairs:5,10,quark:iron_plate_stairs,10,quark:iron_plate_slab:8,10,quark:iron_plate_stairs:7,10,quark:iron_plate_stairs:1,10,quark:iron_plate_slab,10,quark:iron_plate_stairs:4,10,quark:iron_plate_stairs:2,10,rustic:iron_lattice,50,rustic:iron_lattice,50,biomesoplenty:leaves_2:7,100)
RandomBlock(-6,6,6,quark:iron_plate:1,70,STAINED_CLAY:15,30,STAINED_CLAY:7,30,null,30,quark:iron_plate:1,100)
RandomBlock(-6,6,7,quark:iron_plate:1,70,STAINED_CLAY:15,30,STAINED_CLAY:7,30,null,30,quark:iron_plate:1,100)
Block(-6,7,-7,COBBLESTONE_STAIRS:2)
Block(-6,7,-6,quark:world_stone_pavement:2)
Block(-6,7,-5,AIR:0)
Block(-6,7,-4,AIR:0)
Block(-6,7,-3,AIR:0)
Block(-6,7,-2,AIR:0)
Block(-6,7,-1,AIR:0)
Block(-6,7,0,AIR:0)
Block(-6,7,1,AIR:0)
Block(-6,7,2,quark:world_stone_pavement:2)
Block(-6,7,5,rustic:iron_lattice:0)
Block(-6,7,7,rustic:iron_lattice:0)
Block(-6,8,-6,quark:world_stone_pavement:2)
Block(-6,8,-5,quark:world_stone_pavement:2)
Block(-6,8,-4,quark:world_stone_pavement:2)
Block(-6,8,-3,quark:world_stone_pavement:2)
Block(-6,8,-2,quark:world_stone_pavement:2)
Block(-6,8,-1,quark:world_stone_pavement:2)
Block(-6,8,0,quark:world_stone_pavement:2)
Block(-6,8,1,quark:world_stone_pavement:2)
Block(-6,8,2,quark:world_stone_pavement:2)
RandomBlock(-6,9,-3,quark:iron_plate:1,70,STAINED_CLAY:15,30,STAINED_CLAY:7,30,null,30,quark:iron_plate:1,100)
RandomBlock(-6,9,0,quark:iron_plate:1,70,STAINED_CLAY:15,30,STAINED_CLAY:7,30,null,30,quark:iron_plate:1,100)
Block(-6,9,2,quark:stone_basalt_slab)
Block(-5,0,-6,quark:limestone)
Block(-5,0,-5,quark:limestone)
Block(-5,0,-4,quark:limestone)
Block(-5,0,-3,quark:limestone)
Block(-5,0,-2,quark:limestone)
Block(-5,0,-1,quark:limestone)
Block(-5,0,0,quark:limestone)
Block(-5,0,1,quark:limestone)
Block(-5,0,2,quark:limestone)
Block(-5,0,4,quark:limestone)
RandomBlock(-5,0,5,quark:iron_plate:1,70,STAINED_CLAY:15,30,STAINED_CLAY:7,30,null,30,quark:iron_plate:1,100)
RandomBlock(-5,0,6,quark:iron_plate:1,70,STAINED_CLAY:15,30,STAINED_CLAY:7,30,null,30,quark:iron_plate:1,100)
RandomBlock(-5,0,7,quark:iron_plate:1,70,STAINED_CLAY:15,30,STAINED_CLAY:7,30,null,30,quark:iron_plate:1,100)
Block(-5,0,8,quark:limestone)
Block(-5,1,-6,SMOOTH_STAIRS:2)
RandomBlock(-5,1,-5,quark:iron_plate:1,70,STAINED_CLAY:15,30,STAINED_CLAY:7,30,null,30,quark:iron_plate:1,100)
RandomBlock(-5,1,-4,quark:iron_plate:1,70,STAINED_CLAY:15,30,STAINED_CLAY:7,30,null,30,quark:iron_plate:1,100)
RandomBlock(-5,1,-3,quark:iron_plate:1,70,STAINED_CLAY:15,30,STAINED_CLAY:7,30,null,30,quark:iron_plate:1,100)
RandomBlock(-5,1,-2,quark:iron_plate:1,70,STAINED_CLAY:15,30,STAINED_CLAY:7,30,null,30,quark:iron_plate:1,100)
RandomBlock(-5,1,-1,quark:iron_plate:1,70,STAINED_CLAY:15,30,STAINED_CLAY:7,30,null,30,quark:iron_plate:1,100)
RandomBlock(-5,1,0,quark:iron_plate:1,70,STAINED_CLAY:15,30,STAINED_CLAY:7,30,null,30,quark:iron_plate:1,100)
RandomBlock(-5,1,1,quark:iron_plate:1,70,STAINED_CLAY:15,30,STAINED_CLAY:7,30,null,30,quark:iron_plate:1,100)
Block(-5,1,2,SMOOTH_STAIRS:3)
Block(-5,1,4,COBBLESTONE_STAIRS:2)
RandomBlock(-5,1,5,quark:iron_plate:1,70,STAINED_CLAY:15,30,STAINED_CLAY:7,30,null,30,quark:iron_plate:1,100)
RandomBlock(-5,1,6,quark:iron_plate:1,70,STAINED_CLAY:15,30,STAINED_CLAY:7,30,null,30,quark:iron_plate:1,100)
RandomBlock(-5,1,7,quark:iron_plate:1,70,STAINED_CLAY:15,30,STAINED_CLAY:7,30,null,30,quark:iron_plate:1,100)
Block(-5,1,8,COBBLESTONE_STAIRS:3)
Block(-5,2,-6,SMOOTH_STAIRS:6)
Block(-5,2,-5,srparasites:deadblood:1)
Block(-5,2,-4,srparasites:deadblood:2)
Block(-5,2,-3,srparasites:deadblood:2)
Block(-5,2,-2,srparasites:deadblood:1)
Block(-5,2,-1,srparasites:deadblood)
Block(-5,2,0,srparasites:deadblood:1)
Block(-5,2,1,srparasites:deadblood:1)
Block(-5,2,2,SMOOTH_STAIRS:7)
RandomBlock(-5,2,5,quark:iron_plate:1,70,STAINED_CLAY:15,30,STAINED_CLAY:7,30,null,30,quark:iron_plate:1,100)
RandomBlock(-5,2,6,quark:iron_plate:1,70,STAINED_CLAY:15,30,STAINED_CLAY:7,30,null,30,quark:iron_plate:1,100)
RandomBlock(-5,2,7,rustic:iron_lattice,30,rustic:iron_lattice,30,biomesoplenty:leaves_2:7,30,quark:iron_plate_stairs:6,10,quark:iron_plate_stairs:0,10,quark:iron_plate_stairs:5,10,quark:iron_plate_stairs,10,quark:iron_plate_slab:8,10,quark:iron_plate_stairs:7,10,quark:iron_plate_stairs:1,10,quark:iron_plate_slab,10,quark:iron_plate_stairs:4,10,quark:iron_plate_stairs:2,10,rustic:iron_lattice,50,rustic:iron_lattice,50,biomesoplenty:leaves_2:7,100)
Block(-5,3,-6,quark:world_stone_pavement:2)
Block(-5,3,-5,quark:framed_glass)
Block(-5,3,-4,quark:framed_glass)
Block(-5,3,-3,quark:framed_glass)
Block(-5,3,-2,quark:framed_glass)
Block(-5,3,-1,quark:framed_glass)
RandomBlock(-5,3,0,quark:iron_plate:1,70,STAINED_CLAY:15,30,STAINED_CLAY:7,30,null,30,quark:iron_plate:1,100)
RandomBlock(-5,3,1,quark:iron_plate:1,70,STAINED_CLAY:15,30,STAINED_CLAY:7,30,null,30,quark:iron_plate:1,100)
Block(-5,3,2,quark:world_stone_pavement:2)
RandomBlock(-5,3,5,rustic:iron_lattice,30,rustic:iron_lattice,30,biomesoplenty:leaves_2:7,30,quark:iron_plate_stairs:6,10,quark:iron_plate_stairs:0,10,quark:iron_plate_stairs:5,10,quark:iron_plate_stairs,10,quark:iron_plate_slab:8,10,quark:iron_plate_stairs:7,10,quark:iron_plate_stairs:1,10,quark:iron_plate_slab,10,quark:iron_plate_stairs:4,10,quark:iron_plate_stairs:2,10,rustic:iron_lattice,50,rustic:iron_lattice,50,biomesoplenty:leaves_2:7,100)
RandomBlock(-5,3,6,quark:iron_plate:1,70,STAINED_CLAY:15,30,STAINED_CLAY:7,30,null,30,quark:iron_plate:1,100)
RandomBlock(-5,3,7,rustic:iron_lattice,30,rustic:iron_lattice,30,biomesoplenty:leaves_2:7,30,quark:iron_plate_stairs:6,10,quark:iron_plate_stairs:0,10,quark:iron_plate_stairs:5,10,quark:iron_plate_stairs,10,quark:iron_plate_slab:8,10,quark:iron_plate_stairs:7,10,quark:iron_plate_stairs:1,10,quark:iron_plate_slab,10,quark:iron_plate_stairs:4,10,quark:iron_plate_stairs:2,10,rustic:iron_lattice,50,rustic:iron_lattice,50,biomesoplenty:leaves_2:7,100)
Block(-5,4,-7,quark:world_stone_pavement:2)
Block(-5,4,-6,quark:world_stone_pavement:2)
Block(-5,4,-5,AIR:0)
Block(-5,4,-4,AIR:0)
Block(-5,4,-3,AIR:0)
Block(-5,4,-2,AIR:0)
Block(-5,4,-1,AIR:0)
Block(-5,4,0,quark:framed_glass)
Block(-5,4,1,quark:framed_glass)
Block(-5,4,2,quark:world_stone_pavement:2)
Block(-5,4,3,COBBLESTONE_STAIRS:5)
Block(-5,4,4,COBBLESTONE_STAIRS:5)
RandomBlock(-5,4,5,rustic:iron_lattice,30,rustic:iron_lattice,30,biomesoplenty:leaves_2:7,30,quark:iron_plate_stairs:6,10,quark:iron_plate_stairs:0,10,quark:iron_plate_stairs:5,10,quark:iron_plate_stairs,10,quark:iron_plate_slab:8,10,quark:iron_plate_stairs:7,10,quark:iron_plate_stairs:1,10,quark:iron_plate_slab,10,quark:iron_plate_stairs:4,10,quark:iron_plate_stairs:2,10,rustic:iron_lattice,50,rustic:iron_lattice,50,biomesoplenty:leaves_2:7,100)
RandomBlock(-5,4,6,quark:iron_plate:1,70,STAINED_CLAY:15,30,STAINED_CLAY:7,30,null,30,quark:iron_plate:1,100)
RandomBlock(-5,4,7,quark:iron_plate:1,70,STAINED_CLAY:15,30,STAINED_CLAY:7,30,null,30,quark:iron_plate:1,100)
Block(-5,5,-6,quark:framed_glass_pane)
Block(-5,5,-5,AIR:0)
Block(-5,5,-4,AIR:0)
Block(-5,5,-3,AIR:0)
Block(-5,5,-2,AIR:0)
Block(-5,5,-1,AIR:0)
RandomBlock(-5,5,0,quark:iron_plate:1,70,STAINED_CLAY:15,30,STAINED_CLAY:7,30,null,30,quark:iron_plate:1,100)
RandomBlock(-5,5,1,quark:iron_plate:1,70,STAINED_CLAY:15,30,STAINED_CLAY:7,30,null,30,quark:iron_plate:1,100)
Block(-5,5,2,quark:world_stone_pavement:2)
RandomBlock(-5,5,3,quark:iron_plate:1,70,STAINED_CLAY:15,30,STAINED_CLAY:7,30,null,30,quark:iron_plate:1,100)
RandomBlock(-5,5,4,quark:iron_plate:1,70,STAINED_CLAY:15,30,STAINED_CLAY:7,30,null,30,quark:iron_plate:1,100)
RandomBlock(-5,5,5,quark:iron_plate:1,70,STAINED_CLAY:15,30,STAINED_CLAY:7,30,null,30,quark:iron_plate:1,100)
RandomBlock(-5,5,6,quark:iron_plate:1,70,STAINED_CLAY:15,30,STAINED_CLAY:7,30,null,30,quark:iron_plate:1,100)
RandomBlock(-5,5,7,rustic:iron_lattice,30,rustic:iron_lattice,30,biomesoplenty:leaves_2:7,30,quark:iron_plate_stairs:6,10,quark:iron_plate_stairs:0,10,quark:iron_plate_stairs:5,10,quark:iron_plate_stairs,10,quark:iron_plate_slab:8,10,quark:iron_plate_stairs:7,10,quark:iron_plate_stairs:1,10,quark:iron_plate_slab,10,quark:iron_plate_stairs:4,10,quark:iron_plate_stairs:2,10,rustic:iron_lattice,50,rustic:iron_lattice,50,biomesoplenty:leaves_2:7,100)
Block(-5,6,-6,quark:framed_glass_pane)
Block(-5,6,-5,AIR:0)
Block(-5,6,-4,AIR:0)
Block(-5,6,-3,AIR:0)
Block(-5,6,-2,AIR:0)
Block(-5,6,-1,AIR:0)
Block(-5,6,0,COBBLESTONE_STAIRS:1)
Block(-5,6,1,COBBLESTONE_STAIRS:1)
Block(-5,6,2,quark:world_stone_pavement:2)
Block(-5,6,3,COBBLESTONE_STAIRS:1)
Block(-5,6,4,COBBLESTONE_STAIRS:1)
RandomBlock(-5,6,5,quark:iron_plate:1,70,STAINED_CLAY:15,30,STAINED_CLAY:7,30,null,30,quark:iron_plate:1,100)
RandomBlock(-5,6,6,quark:iron_plate:1,70,STAINED_CLAY:15,30,STAINED_CLAY:7,30,null,30,quark:iron_plate:1,100)
RandomBlock(-5,6,7,quark:iron_plate:1,70,STAINED_CLAY:15,30,STAINED_CLAY:7,30,null,30,quark:iron_plate:1,100)
Block(-5,7,-7,COBBLESTONE_STAIRS:2)
Block(-5,7,-6,quark:world_stone_pavement:2)
Block(-5,7,-5,AIR:0)
Block(-5,7,-4,AIR:0)
Block(-5,7,-3,AIR:0)
Block(-5,7,-2,AIR:0)
Block(-5,7,-1,AIR:0)
Block(-5,7,0,AIR:0)
Block(-5,7,1,AIR:0)
Block(-5,7,2,quark:world_stone_pavement:2)
Block(-5,7,5,rustic:iron_lattice:0)
Block(-5,7,6,rustic:iron_lattice:0)
Block(-5,7,7,rustic:iron_lattice:0)
Block(-5,8,-6,quark:world_stone_pavement:2)
Block(-5,8,-5,quark:world_stone_pavement:2)
Block(-5,8,-4,quark:world_stone_pavement:2)
Block(-5,8,-3,quark:world_stone_pavement:2)
Block(-5,8,-2,quark:world_stone_pavement:2)
Block(-5,8,-1,quark:world_stone_pavement:2)
Block(-5,8,0,quark:world_stone_pavement:2)
Block(-5,8,1,quark:world_stone_pavement:2)
Block(-5,8,2,quark:world_stone_pavement:2)
Block(-5,9,-5,DISPENSER:1)
Block(-5,9,-4,quark:iron_plate_slab)
RandomBlock(-5,9,-3,quark:iron_plate:1,70,STAINED_CLAY:15,30,STAINED_CLAY:7,30,null,30,quark:iron_plate:1,100)
RandomBlock(-5,9,0,quark:iron_plate:1,70,STAINED_CLAY:15,30,STAINED_CLAY:7,30,null,30,quark:iron_plate:1,100)
Block(-5,9,2,quark:stone_basalt_slab)
Block(-5,10,-5,quark:basalt_wall)
Block(-4,0,-6,quark:limestone)
Block(-4,0,-5,quark:limestone)
Block(-4,0,-4,quark:limestone)
Block(-4,0,-3,quark:limestone)
Block(-4,0,-2,quark:limestone)
Block(-4,0,-1,quark:limestone)
Block(-4,0,0,quark:limestone)
Block(-4,0,1,quark:limestone)
Block(-4,0,2,quark:limestone)
Block(-4,0,4,quark:limestone)
Block(-4,0,5,quark:limestone)
Block(-4,0,6,quark:limestone)
Block(-4,0,7,quark:limestone)
Block(-4,0,8,quark:limestone)
Block(-4,1,-6,SMOOTH_STAIRS:2)
RandomBlock(-4,1,-5,quark:iron_plate:1,70,STAINED_CLAY:15,30,STAINED_CLAY:7,30,null,30,quark:iron_plate:1,100)
RandomBlock(-4,1,-4,quark:iron_plate:1,70,STAINED_CLAY:15,30,STAINED_CLAY:7,30,null,30,quark:iron_plate:1,100)
RandomBlock(-4,1,-3,quark:iron_plate:1,70,STAINED_CLAY:15,30,STAINED_CLAY:7,30,null,30,quark:iron_plate:1,100)
RandomBlock(-4,1,-2,quark:iron_plate:1,70,STAINED_CLAY:15,30,STAINED_CLAY:7,30,null,30,quark:iron_plate:1,100)
RandomBlock(-4,1,-1,quark:iron_plate:1,70,STAINED_CLAY:15,30,STAINED_CLAY:7,30,null,30,quark:iron_plate:1,100)
RandomBlock(-4,1,0,quark:iron_plate:1,70,STAINED_CLAY:15,30,STAINED_CLAY:7,30,null,30,quark:iron_plate:1,100)
RandomBlock(-4,1,1,quark:iron_plate:1,70,STAINED_CLAY:15,30,STAINED_CLAY:7,30,null,30,quark:iron_plate:1,100)
Block(-4,1,2,SMOOTH_STAIRS:3)
Block(-4,1,4,COBBLESTONE_STAIRS:2)
Block(-4,1,5,COBBLESTONE_STAIRS:1)
Block(-4,1,6,COBBLESTONE_STAIRS:1)
Block(-4,1,7,COBBLESTONE_STAIRS:1)
Block(-4,1,8,COBBLESTONE_STAIRS:1)
Block(-4,2,-6,SMOOTH_STAIRS:6)
Block(-4,2,-5,srparasites:deadblood:2)
Block(-4,2,-4,srparasites:deadblood:1)
Block(-4,2,-3,srparasites:deadblood:1)
Block(-4,2,-2,srparasites:deadblood:2)
Block(-4,2,-1,srparasites:deadblood:1)
Block(-4,2,0,srparasites:deadblood:2)
Block(-4,2,1,srparasites:deadblood:2)
Block(-4,2,2,SMOOTH_STAIRS:7)
Block(-4,3,-6,quark:world_stone_pavement:2)
Block(-4,3,-5,quark:framed_glass)
Block(-4,3,-4,quark:framed_glass)
Block(-4,3,-3,quark:framed_glass)
Block(-4,3,-2,quark:framed_glass)
Block(-4,3,-1,quark:framed_glass)
Block(-4,3,0,quark:framed_glass)
Block(-4,3,1,quark:framed_glass)
Block(-4,3,2,quark:world_stone_pavement:2)
Block(-4,4,-7,quark:world_stone_pavement:2)
Block(-4,4,-6,quark:world_stone_pavement:2)
Block(-4,4,-5,AIR:0)
Block(-4,4,-4,AIR:0)
Block(-4,4,-3,AIR:0)
Block(-4,4,-2,AIR:0)
Block(-4,4,-1,AIR:0)
Block(-4,4,0,AIR:0)
Block(-4,4,1,AIR:0)
Block(-4,4,2,quark:world_stone_pavement:2)
Block(-4,5,-7,quark:basalt_wall)
Block(-4,5,-6,quark:world_stone_pavement:2)
Block(-4,5,-5,AIR:0)
Block(-4,5,-4,AIR:0)
Block(-4,5,-3,AIR:0)
Block(-4,5,-2,AIR:0)
Block(-4,5,-1,AIR:0)
Block(-4,5,0,AIR:0)
Block(-4,5,1,AIR:0)
Block(-4,5,2,quark:world_stone_pavement:2)
Block(-4,6,-7,quark:basalt_wall)
Block(-4,6,-6,quark:world_stone_pavement:2)
Block(-4,6,-5,AIR:0)
Block(-4,6,-4,AIR:0)
Block(-4,6,-3,AIR:0)
Block(-4,6,-2,AIR:0)
Block(-4,6,-1,AIR:0)
Block(-4,6,0,AIR:0)
Block(-4,6,1,AIR:0)
Block(-4,6,2,quark:world_stone_pavement:2)
Block(-4,7,-7,COBBLESTONE_STAIRS:2)
Block(-4,7,-6,quark:world_stone_pavement:2)
Block(-4,7,-5,AIR:0)
Block(-4,7,-4,AIR:0)
Block(-4,7,-3,AIR:0)
Block(-4,7,-2,AIR:0)
Block(-4,7,-1,AIR:0)
Block(-4,7,0,AIR:0)
Block(-4,7,1,AIR:0)
Block(-4,7,2,quark:world_stone_pavement:2)
Block(-4,8,-6,quark:world_stone_pavement:2)
Block(-4,8,-5,quark:world_stone_pavement:2)
Block(-4,8,-4,quark:world_stone_pavement:2)
Block(-4,8,-3,quark:world_stone_pavement:2)
Block(-4,8,-2,quark:world_stone_pavement:2)
Block(-4,8,-1,quark:world_stone_pavement:2)
Block(-4,8,0,quark:world_stone_pavement:2)
Block(-4,8,1,quark:world_stone_pavement:2)
Block(-4,8,2,quark:world_stone_pavement:2)
RandomBlock(-4,9,-3,quark:iron_plate:1,70,STAINED_CLAY:15,30,STAINED_CLAY:7,30,null,30,quark:iron_plate:1,100)
RandomBlock(-4,9,0,quark:iron_plate:1,70,STAINED_CLAY:15,30,STAINED_CLAY:7,30,null,30,quark:iron_plate:1,100)
Block(-4,9,2,quark:stone_basalt_slab)
Block(-3,0,-6,quark:limestone)
Block(-3,0,-5,quark:limestone)
Block(-3,0,-4,quark:limestone)
Block(-3,0,-3,quark:limestone)
Block(-3,0,-2,quark:limestone)
Block(-3,0,-1,quark:limestone)
Block(-3,0,0,quark:limestone)
Block(-3,0,1,quark:limestone)
Block(-3,0,2,quark:limestone)
Block(-3,1,-6,SMOOTH_STAIRS:2)
RandomBlock(-3,1,-5,quark:iron_plate:1,70,STAINED_CLAY:15,30,STAINED_CLAY:7,30,null,30,quark:iron_plate:1,100)
RandomBlock(-3,1,-4,quark:iron_plate:1,70,STAINED_CLAY:15,30,STAINED_CLAY:7,30,null,30,quark:iron_plate:1,100)
RandomBlock(-3,1,-3,quark:iron_plate:1,70,STAINED_CLAY:15,30,STAINED_CLAY:7,30,null,30,quark:iron_plate:1,100)
RandomBlock(-3,1,-2,quark:iron_plate:1,70,STAINED_CLAY:15,30,STAINED_CLAY:7,30,null,30,quark:iron_plate:1,100)
RandomBlock(-3,1,-1,quark:iron_plate:1,70,STAINED_CLAY:15,30,STAINED_CLAY:7,30,null,30,quark:iron_plate:1,100)
RandomBlock(-3,1,0,quark:iron_plate:1,70,STAINED_CLAY:15,30,STAINED_CLAY:7,30,null,30,quark:iron_plate:1,100)
RandomBlock(-3,1,1,quark:iron_plate:1,70,STAINED_CLAY:15,30,STAINED_CLAY:7,30,null,30,quark:iron_plate:1,100)
Block(-3,1,2,SMOOTH_STAIRS:3)
Block(-3,2,-6,SMOOTH_STAIRS:6)
Block(-3,2,-5,srparasites:deadblood:1)
Block(-3,2,-4,srparasites:deadblood)
Block(-3,2,-3,srparasites:deadblood)
Block(-3,2,-2,srparasites:deadblood:1)
Block(-3,2,-1,srparasites:deadblood:2)
Block(-3,2,0,srparasites:deadblood:1)
Block(-3,2,1,srparasites:deadblood:2)
Block(-3,2,2,SMOOTH_STAIRS:7)
Block(-3,3,-6,quark:world_stone_pavement:2)
Block(-3,3,-5,quark:framed_glass)
Block(-3,3,-4,quark:framed_glass)
Block(-3,3,-3,quark:framed_glass)
Block(-3,3,-2,quark:framed_glass)
Block(-3,3,-1,quark:framed_glass)
Block(-3,3,0,quark:framed_glass)
Block(-3,3,1,quark:framed_glass)
Block(-3,3,2,quark:world_stone_pavement:2)
Block(-3,4,-6,quark:world_stone_pavement:2)
Block(-3,4,-5,AIR:0)
Block(-3,4,-4,AIR:0)
Block(-3,4,-3,AIR:0)
Block(-3,4,-2,AIR:0)
Block(-3,4,-1,AIR:0)
Block(-3,4,0,AIR:0)
Block(-3,4,1,AIR:0)
Block(-3,4,2,quark:world_stone_pavement:2)
Block(-3,5,-6,quark:world_stone_pavement:2)
Block(-3,5,-5,AIR:0)
Block(-3,5,-4,AIR:0)
Block(-3,5,-3,AIR:0)
Block(-3,5,-2,AIR:0)
Block(-3,5,-1,AIR:0)
Block(-3,5,0,AIR:0)
Block(-3,5,1,AIR:0)
Block(-3,5,2,quark:framed_glass_pane)
Block(-3,6,-6,quark:world_stone_pavement:2)
Block(-3,6,-5,AIR:0)
Block(-3,6,-4,AIR:0)
Block(-3,6,-3,AIR:0)
Block(-3,6,-2,AIR:0)
Block(-3,6,-1,AIR:0)
Block(-3,6,0,AIR:0)
Block(-3,6,1,AIR:0)
Block(-3,6,2,quark:framed_glass_pane)
Block(-3,7,-6,quark:world_stone_pavement:2)
Block(-3,7,-5,AIR:0)
Block(-3,7,-4,AIR:0)
Block(-3,7,-3,AIR:0)
Block(-3,7,-2,AIR:0)
Block(-3,7,-1,AIR:0)
Block(-3,7,0,AIR:0)
Block(-3,7,1,AIR:0)
Block(-3,7,2,quark:framed_glass_pane)
Block(-3,8,-6,quark:world_stone_pavement:2)
Block(-3,8,-5,quark:world_stone_pavement:2)
Block(-3,8,-4,quark:world_stone_pavement:2)
Block(-3,8,-3,quark:world_stone_pavement:2)
Block(-3,8,-2,quark:world_stone_pavement:2)
Block(-3,8,-1,quark:world_stone_pavement:2)
Block(-3,8,0,quark:world_stone_pavement:2)
Block(-3,8,1,quark:world_stone_pavement:2)
Block(-3,8,2,quark:world_stone_pavement:2)
RandomBlock(-3,9,-3,quark:iron_plate:1,70,STAINED_CLAY:15,30,STAINED_CLAY:7,30,null,30,quark:iron_plate:1,100)
RandomBlock(-3,9,0,quark:iron_plate:1,70,STAINED_CLAY:15,30,STAINED_CLAY:7,30,null,30,quark:iron_plate:1,100)
Block(-3,9,2,quark:stone_basalt_slab)
RandomBlock(-2,0,-7,quark:iron_plate:1,70,STAINED_CLAY:15,30,STAINED_CLAY:7,30,null,30,quark:iron_plate:1,100)
Block(-2,0,-6,quark:limestone)
Block(-2,0,-5,quark:limestone)
Block(-2,0,-4,quark:limestone)
Block(-2,0,-3,quark:limestone)
Block(-2,0,-2,quark:limestone)
Block(-2,0,-1,quark:limestone)
Block(-2,0,0,quark:limestone)
Block(-2,0,1,quark:limestone)
Block(-2,0,2,quark:limestone)
RandomBlock(-2,1,-7,quark:iron_plate:1,70,STAINED_CLAY:15,30,STAINED_CLAY:7,30,null,30,quark:iron_plate:1,100)
Block(-2,1,-6,SMOOTH_STAIRS:2)
RandomBlock(-2,1,-5,quark:iron_plate:1,70,STAINED_CLAY:15,30,STAINED_CLAY:7,30,null,30,quark:iron_plate:1,100)
RandomBlock(-2,1,-4,quark:iron_plate:1,70,STAINED_CLAY:15,30,STAINED_CLAY:7,30,null,30,quark:iron_plate:1,100)
RandomBlock(-2,1,-3,quark:iron_plate:1,70,STAINED_CLAY:15,30,STAINED_CLAY:7,30,null,30,quark:iron_plate:1,100)
RandomBlock(-2,1,-2,quark:iron_plate:1,70,STAINED_CLAY:15,30,STAINED_CLAY:7,30,null,30,quark:iron_plate:1,100)
RandomBlock(-2,1,-1,quark:iron_plate:1,70,STAINED_CLAY:15,30,STAINED_CLAY:7,30,null,30,quark:iron_plate:1,100)
RandomBlock(-2,1,0,quark:iron_plate:1,70,STAINED_CLAY:15,30,STAINED_CLAY:7,30,null,30,quark:iron_plate:1,100)
RandomBlock(-2,1,1,quark:iron_plate:1,70,STAINED_CLAY:15,30,STAINED_CLAY:7,30,null,30,quark:iron_plate:1,100)
Block(-2,1,2,SMOOTH_STAIRS:3)
RandomBlock(-2,2,-7,quark:iron_plate:1,70,STAINED_CLAY:15,30,STAINED_CLAY:7,30,null,30,quark:iron_plate:1,100)
Block(-2,2,-6,SMOOTH_STAIRS:6)
Block(-2,2,-5,srparasites:deadblood:2)
Block(-2,2,-4,srparasites:deadblood:1)
Block(-2,2,-3,srparasites:deadblood)
Block(-2,2,-2,srparasites:deadblood)
Block(-2,2,-1,srparasites:deadblood:1)
Block(-2,2,0,srparasites:deadblood)
Block(-2,2,1,srparasites:deadblood:1)
Block(-2,2,2,SMOOTH_STAIRS:7)
RandomBlock(-2,3,-7,quark:iron_plate:1,70,STAINED_CLAY:15,30,STAINED_CLAY:7,30,null,30,quark:iron_plate:1,100)
Block(-2,3,-6,quark:world_stone_pavement:2)
Block(-2,3,-5,quark:framed_glass)
Block(-2,3,-4,quark:framed_glass)
Block(-2,3,-3,quark:framed_glass)
Block(-2,3,-2,quark:framed_glass)
Block(-2,3,-1,quark:framed_glass)
Block(-2,3,0,quark:framed_glass)
Block(-2,3,1,quark:framed_glass)
Block(-2,3,2,quark:world_stone_pavement:2)
RandomBlock(-2,4,-7,quark:iron_plate:1,70,STAINED_CLAY:15,30,STAINED_CLAY:7,30,null,30,quark:iron_plate:1,100)
Block(-2,4,-6,quark:world_stone_pavement:2)
Block(-2,4,-5,AIR:0)
Block(-2,4,-4,AIR:0)
Block(-2,4,-3,AIR:0)
Block(-2,4,-2,AIR:0)
Block(-2,4,-1,AIR:0)
Block(-2,4,0,AIR:0)
Block(-2,4,1,AIR:0)
Block(-2,4,2,quark:world_stone_pavement:2)
RandomBlock(-2,5,-7,quark:iron_plate:1,70,STAINED_CLAY:15,30,STAINED_CLAY:7,30,null,30,quark:iron_plate:1,100)
Block(-2,5,-6,quark:world_stone_pavement:2)
Block(-2,5,-5,AIR:0)
Block(-2,5,-4,AIR:0)
Block(-2,5,-3,AIR:0)
Block(-2,5,-2,AIR:0)
Block(-2,5,-1,AIR:0)
Block(-2,5,0,AIR:0)
Block(-2,5,1,AIR:0)
Block(-2,5,2,quark:world_stone_pavement:2)
RandomBlock(-2,6,-7,quark:iron_plate:1,70,STAINED_CLAY:15,30,STAINED_CLAY:7,30,null,30,quark:iron_plate:1,100)
Block(-2,6,-6,quark:world_stone_pavement:2)
Block(-2,6,-5,AIR:0)
Block(-2,6,-4,AIR:0)
Block(-2,6,-3,AIR:0)
Block(-2,6,-2,AIR:0)
Block(-2,6,-1,AIR:0)
Block(-2,6,0,AIR:0)
Block(-2,6,1,AIR:0)
Block(-2,6,2,quark:world_stone_pavement:2)
RandomBlock(-2,7,-7,quark:iron_plate:1,70,STAINED_CLAY:15,30,STAINED_CLAY:7,30,null,30,quark:iron_plate:1,100)
Block(-2,7,-6,quark:world_stone_pavement:2)
Block(-2,7,-5,AIR:0)
Block(-2,7,-4,AIR:0)
Block(-2,7,-3,AIR:0)
Block(-2,7,-2,AIR:0)
Block(-2,7,-1,AIR:0)
Block(-2,7,0,AIR:0)
Block(-2,7,1,AIR:0)
Block(-2,7,2,quark:world_stone_pavement:2)
RandomBlock(-2,8,-7,quark:iron_plate:1,70,STAINED_CLAY:15,30,STAINED_CLAY:7,30,null,30,quark:iron_plate:1,100)
Block(-2,8,-6,quark:world_stone_pavement:2)
Block(-2,8,-5,quark:world_stone_pavement:2)
Block(-2,8,-4,quark:world_stone_pavement:2)
Block(-2,8,-3,quark:world_stone_pavement:2)
Block(-2,8,-2,quark:world_stone_pavement:2)
Block(-2,8,-1,quark:world_stone_pavement:2)
Block(-2,8,0,quark:world_stone_pavement:2)
Block(-2,8,1,quark:world_stone_pavement:2)
Block(-2,8,2,quark:world_stone_pavement:2)
RandomBlock(-2,9,-7,quark:iron_plate:1,70,STAINED_CLAY:15,30,STAINED_CLAY:7,30,null,30,quark:iron_plate:1,100)
RandomBlock(-2,9,-6,quark:iron_plate:1,70,STAINED_CLAY:15,30,STAINED_CLAY:7,30,null,30,quark:iron_plate:1,100)
RandomBlock(-2,9,-5,quark:iron_plate:1,70,STAINED_CLAY:15,30,STAINED_CLAY:7,30,null,30,quark:iron_plate:1,100)
RandomBlock(-2,9,-4,quark:iron_plate:1,70,STAINED_CLAY:15,30,STAINED_CLAY:7,30,null,30,quark:iron_plate:1,100)
RandomBlock(-2,9,-3,quark:iron_plate:1,70,STAINED_CLAY:15,30,STAINED_CLAY:7,30,null,30,quark:iron_plate:1,100)
RandomBlock(-2,9,0,quark:iron_plate:1,70,STAINED_CLAY:15,30,STAINED_CLAY:7,30,null,30,quark:iron_plate:1,100)
Block(-2,9,2,quark:stone_basalt_slab)
Block(-1,0,-6,quark:limestone)
Block(-1,0,-5,quark:limestone)
Block(-1,0,-4,quark:limestone)
Block(-1,0,-3,quark:limestone)
Block(-1,0,-2,quark:limestone)
Block(-1,0,-1,quark:limestone)
Block(-1,0,0,quark:limestone)
Block(-1,0,1,quark:limestone)
Block(-1,0,2,quark:limestone)
Block(-1,1,-6,SMOOTH_STAIRS:2)
RandomBlock(-1,1,-5,quark:iron_plate:1,70,STAINED_CLAY:15,30,STAINED_CLAY:7,30,null,30,quark:iron_plate:1,100)
RandomBlock(-1,1,-4,quark:iron_plate:1,70,STAINED_CLAY:15,30,STAINED_CLAY:7,30,null,30,quark:iron_plate:1,100)
RandomBlock(-1,1,-3,quark:iron_plate:1,70,STAINED_CLAY:15,30,STAINED_CLAY:7,30,null,30,quark:iron_plate:1,100)
RandomBlock(-1,1,-2,quark:iron_plate:1,70,STAINED_CLAY:15,30,STAINED_CLAY:7,30,null,30,quark:iron_plate:1,100)
RandomBlock(-1,1,-1,quark:iron_plate:1,70,STAINED_CLAY:15,30,STAINED_CLAY:7,30,null,30,quark:iron_plate:1,100)
RandomBlock(-1,1,0,quark:iron_plate:1,70,STAINED_CLAY:15,30,STAINED_CLAY:7,30,null,30,quark:iron_plate:1,100)
RandomBlock(-1,1,1,quark:iron_plate:1,70,STAINED_CLAY:15,30,STAINED_CLAY:7,30,null,30,quark:iron_plate:1,100)
Block(-1,1,2,SMOOTH_STAIRS:3)
Block(-1,2,-6,SMOOTH_STAIRS:6)
Block(-1,2,-5,srparasites:deadblood:2)
Block(-1,2,-4,srparasites:deadblood:1)
Block(-1,2,-3,srparasites:deadblood)
Block(-1,2,-2,srparasites:deadblood)
Block(-1,2,-1,srparasites:deadblood)
Block(-1,2,0,srparasites:deadblood:1)
Block(-1,2,1,srparasites:deadblood:2)
Block(-1,2,2,SMOOTH_STAIRS:7)
Block(-1,3,-6,quark:world_stone_pavement:2)
Block(-1,3,-5,quark:framed_glass)
Block(-1,3,-4,quark:framed_glass)
Block(-1,3,-3,quark:framed_glass)
Block(-1,3,-2,quark:framed_glass)
Block(-1,3,-1,quark:framed_glass)
Block(-1,3,0,quark:framed_glass)
Block(-1,3,1,quark:framed_glass)
Block(-1,3,2,quark:world_stone_pavement:2)
Block(-1,4,-6,quark:world_stone_pavement:2)
Block(-1,4,-5,AIR:0)
Block(-1,4,-4,AIR:0)
Block(-1,4,-3,AIR:0)
Block(-1,4,-2,AIR:0)
Block(-1,4,-1,AIR:0)
Block(-1,4,0,AIR:0)
Block(-1,4,1,AIR:0)
Block(-1,4,2,quark:world_stone_pavement:2)
Block(-1,5,-6,quark:world_stone_pavement:2)
Block(-1,5,-5,AIR:0)
Block(-1,5,-4,AIR:0)
Block(-1,5,-3,AIR:0)
Block(-1,5,-2,AIR:0)
Block(-1,5,-1,AIR:0)
Block(-1,5,0,AIR:0)
Block(-1,5,1,AIR:0)
Block(-1,5,2,quark:framed_glass_pane)
Block(-1,6,-6,quark:world_stone_pavement:2)
Block(-1,6,-5,AIR:0)
Block(-1,6,-4,AIR:0)
Block(-1,6,-3,AIR:0)
Block(-1,6,-2,AIR:0)
Block(-1,6,-1,AIR:0)
Block(-1,6,0,AIR:0)
Block(-1,6,1,AIR:0)
Block(-1,6,2,quark:framed_glass_pane)
Block(-1,7,-6,quark:world_stone_pavement:2)
Block(-1,7,-5,AIR:0)
Block(-1,7,-4,AIR:0)
Block(-1,7,-3,AIR:0)
Block(-1,7,-2,AIR:0)
Block(-1,7,-1,AIR:0)
Block(-1,7,0,AIR:0)
Block(-1,7,1,AIR:0)
Block(-1,7,2,quark:framed_glass_pane)
Block(-1,8,-6,quark:world_stone_pavement:2)
Block(-1,8,-5,quark:world_stone_pavement:2)
Block(-1,8,-4,quark:world_stone_pavement:2)
Block(-1,8,-3,quark:world_stone_pavement:2)
Block(-1,8,-2,quark:world_stone_pavement:2)
Block(-1,8,-1,quark:world_stone_pavement:2)
Block(-1,8,0,quark:world_stone_pavement:2)
Block(-1,8,1,quark:world_stone_pavement:2)
Block(-1,8,2,quark:world_stone_pavement:2)
RandomBlock(-1,9,0,quark:iron_plate:1,70,STAINED_CLAY:15,30,STAINED_CLAY:7,30,null,30,quark:iron_plate:1,100)
Block(-1,9,2,quark:stone_basalt_slab)
RandomBlock(0,0,-7,quark:iron_plate:1,70,STAINED_CLAY:15,30,STAINED_CLAY:7,30,null,30,quark:iron_plate:1,100)
Block(0,0,-6,quark:limestone)
Block(0,0,-5,quark:limestone)
Block(0,0,-4,quark:limestone)
Block(0,0,-3,quark:limestone)
Block(0,0,-2,quark:limestone)
Block(0,0,-1,quark:limestone)
Block(0,0,0,quark:limestone)
Block(0,0,1,quark:limestone)
Block(0,0,2,quark:limestone)
RandomBlock(0,1,-7,quark:iron_plate:1,70,STAINED_CLAY:15,30,STAINED_CLAY:7,30,null,30,quark:iron_plate:1,100)
Block(0,1,-6,SMOOTH_STAIRS:2)
RandomBlock(0,1,-5,quark:iron_plate:1,70,STAINED_CLAY:15,30,STAINED_CLAY:7,30,null,30,quark:iron_plate:1,100)
RandomBlock(0,1,-4,quark:iron_plate:1,70,STAINED_CLAY:15,30,STAINED_CLAY:7,30,null,30,quark:iron_plate:1,100)
RandomBlock(0,1,-3,quark:iron_plate:1,70,STAINED_CLAY:15,30,STAINED_CLAY:7,30,null,30,quark:iron_plate:1,100)
RandomBlock(0,1,-2,quark:iron_plate:1,70,STAINED_CLAY:15,30,STAINED_CLAY:7,30,null,30,quark:iron_plate:1,100)
RandomBlock(0,1,-1,quark:iron_plate:1,70,STAINED_CLAY:15,30,STAINED_CLAY:7,30,null,30,quark:iron_plate:1,100)
RandomBlock(0,1,0,quark:iron_plate:1,70,STAINED_CLAY:15,30,STAINED_CLAY:7,30,null,30,quark:iron_plate:1,100)
RandomBlock(0,1,1,quark:iron_plate:1,70,STAINED_CLAY:15,30,STAINED_CLAY:7,30,null,30,quark:iron_plate:1,100)
Block(0,1,2,SMOOTH_STAIRS:3)
RandomBlock(0,2,-7,quark:iron_plate:1,70,STAINED_CLAY:15,30,STAINED_CLAY:7,30,null,30,quark:iron_plate:1,100)
Block(0,2,-6,SMOOTH_STAIRS:6)
Block(0,2,-5,srparasites:deadblood:1)
Block(0,2,-4,srparasites:deadblood)
Block(0,2,-3,srparasites:deadblood:1)
Block(0,2,-2,srparasites:deadblood:1)
Block(0,2,-1,srparasites:deadblood:1)
Block(0,2,0,srparasites:deadblood:1)
Block(0,2,1,srparasites:deadblood:1)
Block(0,2,2,SMOOTH_STAIRS:7)
RandomBlock(0,3,-7,quark:iron_plate:1,70,STAINED_CLAY:15,30,STAINED_CLAY:7,30,null,30,quark:iron_plate:1,100)
Block(0,3,-6,quark:world_stone_pavement:2)
Block(0,3,-5,quark:framed_glass)
Block(0,3,-4,quark:framed_glass)
Block(0,3,-3,quark:framed_glass)
Block(0,3,-2,quark:framed_glass)
Block(0,3,-1,quark:framed_glass)
Block(0,3,0,quark:framed_glass)
Block(0,3,1,quark:framed_glass)
Block(0,3,2,quark:world_stone_pavement:2)
RandomBlock(0,4,-7,quark:iron_plate:1,70,STAINED_CLAY:15,30,STAINED_CLAY:7,30,null,30,quark:iron_plate:1,100)
Block(0,4,-6,quark:world_stone_pavement:2)
Block(0,4,-5,AIR:0)
Block(0,4,-4,AIR:0)
Block(0,4,-3,AIR:0)
Block(0,4,-2,AIR:0)
Block(0,4,-1,AIR:0)
Block(0,4,0,AIR:0)
Block(0,4,1,AIR:0)
Block(0,4,2,quark:world_stone_pavement:2)
RandomBlock(0,5,-7,quark:iron_plate:1,70,STAINED_CLAY:15,30,STAINED_CLAY:7,30,null,30,quark:iron_plate:1,100)
Block(0,5,-6,quark:world_stone_pavement:2)
Block(0,5,-5,AIR:0)
Block(0,5,-4,AIR:0)
Block(0,5,-3,AIR:0)
Block(0,5,-2,AIR:0)
Block(0,5,-1,AIR:0)
Block(0,5,0,AIR:0)
Block(0,5,1,AIR:0)
Block(0,5,2,quark:world_stone_pavement:2)
RandomBlock(0,6,-7,quark:iron_plate:1,70,STAINED_CLAY:15,30,STAINED_CLAY:7,30,null,30,quark:iron_plate:1,100)
Block(0,6,-6,quark:world_stone_pavement:2)
Block(0,6,-5,AIR:0)
Block(0,6,-4,AIR:0)
Block(0,6,-3,AIR:0)
Block(0,6,-2,AIR:0)
Block(0,6,-1,AIR:0)
Block(0,6,0,AIR:0)
Block(0,6,1,AIR:0)
Block(0,6,2,quark:world_stone_pavement:2)
RandomBlock(0,7,-7,quark:iron_plate:1,70,STAINED_CLAY:15,30,STAINED_CLAY:7,30,null,30,quark:iron_plate:1,100)
Block(0,7,-6,quark:world_stone_pavement:2)
Block(0,7,-5,AIR:0)
Block(0,7,-4,AIR:0)
Block(0,7,-3,AIR:0)
Block(0,7,-2,AIR:0)
Block(0,7,-1,AIR:0)
Block(0,7,0,AIR:0)
Block(0,7,1,AIR:0)
Block(0,7,2,quark:world_stone_pavement:2)
RandomBlock(0,8,-7,quark:iron_plate:1,70,STAINED_CLAY:15,30,STAINED_CLAY:7,30,null,30,quark:iron_plate:1,100)
Block(0,8,-6,quark:world_stone_pavement:2)
Block(0,8,-5,quark:world_stone_pavement:2)
Block(0,8,-4,quark:world_stone_pavement:2)
Block(0,8,-3,quark:world_stone_pavement:2)
Block(0,8,-2,quark:world_stone_pavement:2)
Block(0,8,-1,quark:world_stone_pavement:2)
Block(0,8,0,quark:world_stone_pavement:2)
Block(0,8,1,quark:world_stone_pavement:2)
Block(0,8,2,quark:world_stone_pavement:2)
RandomBlock(0,9,-7,quark:iron_plate:1,70,STAINED_CLAY:15,30,STAINED_CLAY:7,30,null,30,quark:iron_plate:1,100)
RandomBlock(0,9,-6,quark:iron_plate:1,70,STAINED_CLAY:15,30,STAINED_CLAY:7,30,null,30,quark:iron_plate:1,100)
RandomBlock(0,9,-5,quark:iron_plate:1,70,STAINED_CLAY:15,30,STAINED_CLAY:7,30,null,30,quark:iron_plate:1,100)
RandomBlock(0,9,-4,quark:iron_plate:1,70,STAINED_CLAY:15,30,STAINED_CLAY:7,30,null,30,quark:iron_plate:1,100)
RandomBlock(0,9,-3,quark:iron_plate:1,70,STAINED_CLAY:15,30,STAINED_CLAY:7,30,null,30,quark:iron_plate:1,100)
RandomBlock(0,9,-2,quark:iron_plate:1,70,STAINED_CLAY:15,30,STAINED_CLAY:7,30,null,30,quark:iron_plate:1,100)
RandomBlock(0,9,-1,quark:iron_plate:1,70,STAINED_CLAY:15,30,STAINED_CLAY:7,30,null,30,quark:iron_plate:1,100)
RandomBlock(0,9,0,quark:iron_plate:1,70,STAINED_CLAY:15,30,STAINED_CLAY:7,30,null,30,quark:iron_plate:1,100)
Block(0,9,2,quark:stone_basalt_slab)
Block(1,0,-6,quark:limestone)
Block(1,0,-5,quark:limestone)
Block(1,0,-4,quark:limestone)
Block(1,0,-3,quark:limestone)
Block(1,0,-2,quark:limestone)
Block(1,0,-1,quark:limestone)
Block(1,0,0,quark:limestone)
Block(1,0,1,quark:limestone)
Block(1,0,2,quark:limestone)
Block(1,1,-6,SMOOTH_STAIRS:2)
RandomBlock(1,1,-5,quark:iron_plate:1,70,STAINED_CLAY:15,30,STAINED_CLAY:7,30,null,30,quark:iron_plate:1,100)
RandomBlock(1,1,-4,quark:iron_plate:1,70,STAINED_CLAY:15,30,STAINED_CLAY:7,30,null,30,quark:iron_plate:1,100)
RandomBlock(1,1,-3,quark:iron_plate:1,70,STAINED_CLAY:15,30,STAINED_CLAY:7,30,null,30,quark:iron_plate:1,100)
RandomBlock(1,1,-2,quark:iron_plate:1,70,STAINED_CLAY:15,30,STAINED_CLAY:7,30,null,30,quark:iron_plate:1,100)
RandomBlock(1,1,-1,quark:iron_plate:1,70,STAINED_CLAY:15,30,STAINED_CLAY:7,30,null,30,quark:iron_plate:1,100)
RandomBlock(1,1,0,quark:iron_plate:1,70,STAINED_CLAY:15,30,STAINED_CLAY:7,30,null,30,quark:iron_plate:1,100)
RandomBlock(1,1,1,quark:iron_plate:1,70,STAINED_CLAY:15,30,STAINED_CLAY:7,30,null,30,quark:iron_plate:1,100)
Block(1,1,2,SMOOTH_STAIRS:3)
Block(1,2,-6,SMOOTH_STAIRS:6)
Block(1,2,-5,srparasites:deadblood:1)
Block(1,2,-4,srparasites:deadblood)
Block(1,2,-3,srparasites:deadblood:1)
Block(1,2,-2,srparasites:deadblood)
Block(1,2,-1,srparasites:deadblood)
Block(1,2,0,srparasites:deadblood)
Block(1,2,1,srparasites:deadblood)
Block(1,2,2,SMOOTH_STAIRS:7)
Block(1,3,-6,quark:world_stone_pavement:2)
Block(1,3,-5,quark:framed_glass)
RandomBlock(1,3,-4,quark:iron_plate:1,70,STAINED_CLAY:15,30,STAINED_CLAY:7,30,null,30,quark:iron_plate:1,100)
RandomBlock(1,3,-3,quark:iron_plate:1,70,STAINED_CLAY:15,30,STAINED_CLAY:7,30,null,30,quark:iron_plate:1,100)
RandomBlock(1,3,-2,quark:iron_plate:1,70,STAINED_CLAY:15,30,STAINED_CLAY:7,30,null,30,quark:iron_plate:1,100)
Block(1,3,-1,quark:framed_glass)
Block(1,3,0,quark:framed_glass)
Block(1,3,1,quark:framed_glass)
Block(1,3,2,quark:world_stone_pavement:2)
Block(1,4,-6,quark:world_stone_pavement:2)
Block(1,4,-5,AIR:0)
Block(1,4,-4,quark:framed_glass)
Block(1,4,-3,quark:framed_glass)
Block(1,4,-2,quark:framed_glass)
Block(1,4,-1,AIR:0)
Block(1,4,0,AIR:0)
Block(1,4,1,AIR:0)
Block(1,4,2,quark:world_stone_pavement:2)
Block(1,5,-6,quark:world_stone_pavement:2)
Block(1,5,-5,AIR:0)
Block(1,5,-4,quark:framed_glass)
Block(1,5,-3,quark:framed_glass)
Block(1,5,-2,quark:framed_glass)
Block(1,5,-1,AIR:0)
Block(1,5,0,AIR:0)
Block(1,5,1,AIR:0)
Block(1,5,2,quark:world_stone_pavement:2)
Block(1,6,-6,quark:world_stone_pavement:2)
Block(1,6,-5,AIR:0)
RandomBlock(1,6,-4,quark:iron_plate:1,70,STAINED_CLAY:15,30,STAINED_CLAY:7,30,null,30,quark:iron_plate:1,100)
RandomBlock(1,6,-3,quark:iron_plate:1,70,STAINED_CLAY:15,30,STAINED_CLAY:7,30,null,30,quark:iron_plate:1,100)
RandomBlock(1,6,-2,quark:iron_plate:1,70,STAINED_CLAY:15,30,STAINED_CLAY:7,30,null,30,quark:iron_plate:1,100)
Block(1,6,-1,AIR:0)
Block(1,6,0,AIR:0)
Block(1,6,1,AIR:0)
Block(1,6,2,quark:world_stone_pavement:2)
Block(1,7,-6,quark:world_stone_pavement:2)
Block(1,7,-5,AIR:0)
Block(1,7,-4,COBBLESTONE_STAIRS:0)
Block(1,7,-3,COBBLESTONE_STAIRS:0)
Block(1,7,-2,COBBLESTONE_STAIRS:3)
Block(1,7,-1,AIR:0)
Block(1,7,0,AIR:0)
Block(1,7,1,AIR:0)
Block(1,7,2,quark:world_stone_pavement:2)
Block(1,8,-6,quark:world_stone_pavement:2)
Block(1,8,-5,quark:world_stone_pavement:2)
Block(1,8,-4,quark:world_stone_pavement:2)
Block(1,8,-3,quark:world_stone_pavement:2)
Block(1,8,-2,quark:world_stone_pavement:2)
Block(1,8,-1,quark:world_stone_pavement:2)
Block(1,8,0,quark:world_stone_pavement:2)
Block(1,8,1,quark:world_stone_pavement:2)
Block(1,8,2,quark:world_stone_pavement:2)
Block(1,9,-6,quark:stone_basalt_slab)
Block(1,9,-4,quark:iron_plate_slab)
Block(1,9,-1,quark:iron_plate_slab)
Block(1,9,2,quark:stone_basalt_slab)
Block(2,0,-6,quark:limestone)
Block(2,0,-5,quark:limestone)
Block(2,0,-4,quark:limestone)
Block(2,0,-3,quark:limestone)
Block(2,0,-2,quark:limestone)
Block(2,0,-1,quark:limestone)
Block(2,0,0,quark:limestone)
Block(2,0,1,quark:limestone)
Block(2,0,2,quark:limestone)
Block(2,1,-6,SMOOTH_STAIRS:2)
RandomBlock(2,1,-5,quark:iron_plate:1,70,STAINED_CLAY:15,30,STAINED_CLAY:7,30,null,30,quark:iron_plate:1,100)
RandomBlock(2,1,-4,quark:iron_plate:1,70,STAINED_CLAY:15,30,STAINED_CLAY:7,30,null,30,quark:iron_plate:1,100)
RandomBlock(2,1,-3,quark:iron_plate:1,70,STAINED_CLAY:15,30,STAINED_CLAY:7,30,null,30,quark:iron_plate:1,100)
RandomBlock(2,1,-2,quark:iron_plate:1,70,STAINED_CLAY:15,30,STAINED_CLAY:7,30,null,30,quark:iron_plate:1,100)
RandomBlock(2,1,-1,quark:iron_plate:1,70,STAINED_CLAY:15,30,STAINED_CLAY:7,30,null,30,quark:iron_plate:1,100)
RandomBlock(2,1,0,quark:iron_plate:1,70,STAINED_CLAY:15,30,STAINED_CLAY:7,30,null,30,quark:iron_plate:1,100)
RandomBlock(2,1,1,quark:iron_plate:1,70,STAINED_CLAY:15,30,STAINED_CLAY:7,30,null,30,quark:iron_plate:1,100)
Block(2,1,2,SMOOTH_STAIRS:3)
Block(2,2,-6,SMOOTH_STAIRS:6)
Block(2,2,-5,srparasites:deadblood:2)
Block(2,2,-4,srparasites:deadblood:1)
Block(2,2,-3,srparasites:deadblood:1)
Block(2,2,-2,srparasites:deadblood:1)
Block(2,2,-1,srparasites:deadblood:1)
Block(2,2,0,srparasites:deadblood)
Block(2,2,1,srparasites:deadblood:1)
Block(2,2,2,SMOOTH_STAIRS:7)
RandomBlock(2,3,-6,quark:iron_plate:1,70,STAINED_CLAY:15,30,STAINED_CLAY:7,30,null,30,quark:iron_plate:1,100)
Block(2,3,-5,quark:framed_glass)
RandomBlock(2,3,-4,quark:iron_plate:1,70,STAINED_CLAY:15,30,STAINED_CLAY:7,30,null,30,quark:iron_plate:1,100)
Block(2,3,-3,srparasites:deadblood)
RandomBlock(2,3,-2,quark:iron_plate:1,70,STAINED_CLAY:15,30,STAINED_CLAY:7,30,null,30,quark:iron_plate:1,100)
Block(2,3,-1,quark:framed_glass)
Block(2,3,0,quark:framed_glass)
Block(2,3,1,quark:framed_glass)
RandomBlock(2,3,2,quark:iron_plate:1,70,STAINED_CLAY:15,30,STAINED_CLAY:7,30,null,30,quark:iron_plate:1,100)
Block(2,4,-6,quark:world_stone_pavement:2)
Block(2,4,-5,AIR:0)
Block(2,4,-4,quark:framed_glass)
Block(2,4,-3,srparasites:deadblood)
Block(2,4,-2,quark:framed_glass)
Block(2,4,-1,AIR:0)
Block(2,4,0,AIR:0)
Block(2,4,1,AIR:0)
Block(2,4,2,quark:world_stone_pavement:2)
RandomBlock(2,5,-6,quark:iron_plate:1,70,STAINED_CLAY:15,30,STAINED_CLAY:7,30,null,30,quark:iron_plate:1,100)
Block(2,5,-5,AIR:0)
Block(2,5,-4,quark:framed_glass)
Block(2,5,-3,srparasites:deadblood)
Block(2,5,-2,quark:framed_glass)
Block(2,5,-1,AIR:0)
Block(2,5,0,AIR:0)
Block(2,5,1,AIR:0)
RandomBlock(2,5,2,quark:iron_plate:1,70,STAINED_CLAY:15,30,STAINED_CLAY:7,30,null,30,quark:iron_plate:1,100)
Block(2,6,-6,quark:world_stone_pavement:2)
Block(2,6,-5,AIR:0)
RandomBlock(2,6,-4,quark:iron_plate:1,70,STAINED_CLAY:15,30,STAINED_CLAY:7,30,null,30,quark:iron_plate:1,100)
Block(2,6,-3,srparasites:deadblood)
RandomBlock(2,6,-2,quark:iron_plate:1,70,STAINED_CLAY:15,30,STAINED_CLAY:7,30,null,30,quark:iron_plate:1,100)
Block(2,6,-1,AIR:0)
Block(2,6,0,AIR:0)
Block(2,6,1,AIR:0)
Block(2,6,2,quark:world_stone_pavement:2)
RandomBlock(2,7,-6,quark:iron_plate:1,70,STAINED_CLAY:15,30,STAINED_CLAY:7,30,null,30,quark:iron_plate:1,100)
Block(2,7,-5,AIR:0)
Block(2,7,-4,COBBLESTONE_STAIRS:2)
RandomBlock(2,7,-3,quark:iron_plate:1,70,STAINED_CLAY:15,30,STAINED_CLAY:7,30,null,30,quark:iron_plate:1,100)
Block(2,7,-2,COBBLESTONE_STAIRS:3)
Block(2,7,-1,AIR:0)
Block(2,7,0,AIR:0)
Block(2,7,1,AIR:0)
RandomBlock(2,7,2,quark:iron_plate:1,70,STAINED_CLAY:15,30,STAINED_CLAY:7,30,null,30,quark:iron_plate:1,100)
Block(2,8,-6,quark:world_stone_pavement:2)
Block(2,8,-5,quark:world_stone_pavement:2)
Block(2,8,-4,quark:world_stone_pavement:2)
Block(2,8,-3,quark:world_stone_pavement:2)
Block(2,8,-2,quark:world_stone_pavement:2)
Block(2,8,-1,quark:world_stone_pavement:2)
Block(2,8,0,quark:world_stone_pavement:2)
Block(2,8,1,quark:world_stone_pavement:2)
Block(2,8,2,quark:world_stone_pavement:2)
Block(2,9,-6,quark:stone_basalt_slab)
Block(2,9,-4,DISPENSER:1)
Block(2,9,-1,DISPENSER:1)
Block(2,9,2,quark:stone_basalt_slab)
Block(2,10,-4,IRON_TRAPDOOR:2)
Block(2,10,-1,IRON_TRAPDOOR:2)
Block(3,0,-6,quark:limestone)
Block(3,0,-5,quark:limestone)
Block(3,0,-4,quark:limestone)
Block(3,0,-3,quark:limestone)
Block(3,0,-2,quark:limestone)
Block(3,0,-1,quark:limestone)
Block(3,0,0,quark:limestone)
Block(3,0,1,quark:limestone)
Block(3,0,2,quark:limestone)
RandomBlock(3,1,-6,quark:iron_plate:1,70,STAINED_CLAY:15,30,STAINED_CLAY:7,30,null,30,quark:iron_plate:1,100)
Block(3,1,-5,SMOOTH_STAIRS:1)
Block(3,1,-4,SMOOTH_STAIRS:1)
Block(3,1,-3,SMOOTH_STAIRS:1)
Block(3,1,-2,SMOOTH_STAIRS:1)
Block(3,1,-1,SMOOTH_STAIRS:1)
Block(3,1,0,SMOOTH_STAIRS:1)
Block(3,1,1,SMOOTH_STAIRS:1)
RandomBlock(3,1,2,quark:iron_plate:1,70,STAINED_CLAY:15,30,STAINED_CLAY:7,30,null,30,quark:iron_plate:1,100)
RandomBlock(3,2,-6,quark:iron_plate:1,70,STAINED_CLAY:15,30,STAINED_CLAY:7,30,null,30,quark:iron_plate:1,100)
Block(3,2,-5,SMOOTH_STAIRS:5)
Block(3,2,-4,SMOOTH_STAIRS:5)
Block(3,2,-3,SMOOTH_STAIRS:5)
Block(3,2,-2,SMOOTH_STAIRS:5)
Block(3,2,-1,SMOOTH_STAIRS:5)
Block(3,2,0,SMOOTH_STAIRS:5)
Block(3,2,1,SMOOTH_STAIRS:5)
RandomBlock(3,2,2,quark:iron_plate:1,70,STAINED_CLAY:15,30,STAINED_CLAY:7,30,null,30,quark:iron_plate:1,100)
RandomBlock(3,3,-6,quark:iron_plate:1,70,STAINED_CLAY:15,30,STAINED_CLAY:7,30,null,30,quark:iron_plate:1,100)
RandomBlock(3,3,-5,quark:iron_plate:1,70,STAINED_CLAY:15,30,STAINED_CLAY:7,30,null,30,quark:iron_plate:1,100)
Block(3,3,-4,quark:world_stone_pavement:2)
Block(3,3,-3,quark:world_stone_pavement:2)
Block(3,3,-2,quark:world_stone_pavement:2)
Block(3,3,-1,quark:world_stone_pavement:2)
Block(3,3,0,quark:world_stone_pavement:2)
RandomBlock(3,3,1,quark:iron_plate:1,70,STAINED_CLAY:15,30,STAINED_CLAY:7,30,null,30,quark:iron_plate:1,100)
RandomBlock(3,3,2,quark:iron_plate:1,70,STAINED_CLAY:15,30,STAINED_CLAY:7,30,null,30,quark:iron_plate:1,100)
RandomBlock(3,4,-6,quark:iron_plate:1,70,STAINED_CLAY:15,30,STAINED_CLAY:7,30,null,30,quark:iron_plate:1,100)
Block(3,4,-5,quark:world_stone_pavement:2)
Block(3,4,-4,quark:world_stone_pavement:2)
Block(3,4,-3,quark:world_stone_pavement:2)
Block(3,4,-2,quark:world_stone_pavement:2)
Block(3,4,-1,quark:world_stone_pavement:2)
Block(3,4,0,quark:world_stone_pavement:2)
Block(3,4,1,quark:world_stone_pavement:2)
RandomBlock(3,4,2,quark:iron_plate:1,70,STAINED_CLAY:15,30,STAINED_CLAY:7,30,null,30,quark:iron_plate:1,100)
RandomBlock(3,5,-6,quark:iron_plate:1,70,STAINED_CLAY:15,30,STAINED_CLAY:7,30,null,30,quark:iron_plate:1,100)
RandomBlock(3,5,-5,quark:iron_plate:1,70,STAINED_CLAY:15,30,STAINED_CLAY:7,30,null,30,quark:iron_plate:1,100)
Block(3,5,-4,quark:world_stone_pavement:2)
Block(3,5,-3,quark:world_stone_pavement:2)
Block(3,5,-2,quark:world_stone_pavement:2)
Block(3,5,-1,quark:world_stone_pavement:2)
Block(3,5,0,quark:world_stone_pavement:2)
RandomBlock(3,5,1,quark:iron_plate:1,70,STAINED_CLAY:15,30,STAINED_CLAY:7,30,null,30,quark:iron_plate:1,100)
RandomBlock(3,5,2,quark:iron_plate:1,70,STAINED_CLAY:15,30,STAINED_CLAY:7,30,null,30,quark:iron_plate:1,100)
RandomBlock(3,6,-6,quark:iron_plate:1,70,STAINED_CLAY:15,30,STAINED_CLAY:7,30,null,30,quark:iron_plate:1,100)
Block(3,6,-5,quark:world_stone_pavement:2)
Block(3,6,-4,quark:world_stone_pavement:2)
Block(3,6,-3,srparasites:deadblood)
Block(3,6,-2,quark:world_stone_pavement:2)
Block(3,6,-1,quark:world_stone_pavement:2)
Block(3,6,0,quark:world_stone_pavement:2)
Block(3,6,1,quark:world_stone_pavement:2)
RandomBlock(3,6,2,quark:iron_plate:1,70,STAINED_CLAY:15,30,STAINED_CLAY:7,30,null,30,quark:iron_plate:1,100)
RandomBlock(3,7,-6,quark:iron_plate:1,70,STAINED_CLAY:15,30,STAINED_CLAY:7,30,null,30,quark:iron_plate:1,100)
RandomBlock(3,7,-5,quark:iron_plate:1,70,STAINED_CLAY:15,30,STAINED_CLAY:7,30,null,30,quark:iron_plate:1,100)
Block(3,7,-4,quark:world_stone_pavement:2)
Block(3,7,-3,quark:world_stone_pavement:2)
Block(3,7,-2,quark:world_stone_pavement:2)
Block(3,7,-1,quark:world_stone_pavement:2)
Block(3,7,0,quark:world_stone_pavement:2)
RandomBlock(3,7,1,quark:iron_plate:1,70,STAINED_CLAY:15,30,STAINED_CLAY:7,30,null,30,quark:iron_plate:1,100)
RandomBlock(3,7,2,quark:iron_plate:1,70,STAINED_CLAY:15,30,STAINED_CLAY:7,30,null,30,quark:iron_plate:1,100)
RandomBlock(3,8,-6,quark:iron_plate:1,70,STAINED_CLAY:15,30,STAINED_CLAY:7,30,null,30,quark:iron_plate:1,100)
Block(3,8,-5,quark:world_stone_pavement:2)
Block(3,8,-4,quark:world_stone_pavement:2)
Block(3,8,-3,quark:world_stone_pavement:2)
Block(3,8,-2,quark:world_stone_pavement:2)
Block(3,8,-1,quark:world_stone_pavement:2)
Block(3,8,0,quark:world_stone_pavement:2)
Block(3,8,1,quark:world_stone_pavement:2)
RandomBlock(3,8,2,quark:iron_plate:1,70,STAINED_CLAY:15,30,STAINED_CLAY:7,30,null,30,quark:iron_plate:1,100)
Block(3,9,-6,quark:stone_basalt_slab)
Block(3,9,-5,quark:stone_basalt_slab)
Block(3,9,-4,quark:stone_basalt_slab)
Block(3,9,-3,quark:stone_basalt_slab)
Block(3,9,-2,quark:stone_basalt_slab)
Block(3,9,-1,quark:stone_basalt_slab)
Block(3,9,0,quark:stone_basalt_slab)
Block(3,9,1,quark:stone_basalt_slab)
Block(3,9,2,quark:stone_basalt_slab)
Block(4,5,-4,COBBLESTONE_STAIRS:6)
RandomBlock(4,5,-3,quark:iron_plate:1,70,STAINED_CLAY:15,30,STAINED_CLAY:7,30,null,30,quark:iron_plate:1,100)
Block(4,5,-2,COBBLESTONE_STAIRS:7)
RandomBlock(4,6,-4,quark:iron_plate:1,70,STAINED_CLAY:15,30,STAINED_CLAY:7,30,null,30,quark:iron_plate:1,100)
Block(4,6,-3,srparasites:deadblood)
RandomBlock(4,6,-2,quark:iron_plate:1,70,STAINED_CLAY:15,30,STAINED_CLAY:7,30,null,30,quark:iron_plate:1,100)
Block(4,7,-4,COBBLESTONE_STAIRS:2)
RandomBlock(4,7,-3,quark:iron_plate:1,70,STAINED_CLAY:15,30,STAINED_CLAY:7,30,null,30,quark:iron_plate:1,100)
Block(4,7,-2,COBBLESTONE_STAIRS:3)
Block(5,5,-4,COBBLESTONE_STAIRS:6)
RandomBlock(5,5,-3,quark:iron_plate:1,70,STAINED_CLAY:15,30,STAINED_CLAY:7,30,null,30,quark:iron_plate:1,100)
Block(5,5,-2,COBBLESTONE_STAIRS:7)
RandomBlock(5,6,-4,quark:iron_plate:1,70,STAINED_CLAY:15,30,STAINED_CLAY:7,30,null,30,quark:iron_plate:1,100)
Block(5,6,-3,srparasites:deadblood)
RandomBlock(5,6,-2,quark:iron_plate:1,70,STAINED_CLAY:15,30,STAINED_CLAY:7,30,null,30,quark:iron_plate:1,100)
Block(5,7,-4,COBBLESTONE_STAIRS:2)
RandomBlock(5,7,-3,quark:iron_plate:1,70,STAINED_CLAY:15,30,STAINED_CLAY:7,30,null,30,quark:iron_plate:1,100)
Block(5,7,-2,COBBLESTONE_STAIRS:3)
Block(6,5,-4,COBBLESTONE_STAIRS:6)
RandomBlock(6,5,-3,quark:iron_plate:1,70,STAINED_CLAY:15,30,STAINED_CLAY:7,30,null,30,quark:iron_plate:1,100)
Block(6,5,-2,COBBLESTONE_STAIRS:7)
RandomBlock(6,6,-4,quark:iron_plate:1,70,STAINED_CLAY:15,30,STAINED_CLAY:7,30,null,30,quark:iron_plate:1,100)
Block(6,6,-3,srparasites:deadblood)
RandomBlock(6,6,-2,quark:iron_plate:1,70,STAINED_CLAY:15,30,STAINED_CLAY:7,30,null,30,quark:iron_plate:1,100)
Block(6,7,-4,COBBLESTONE_STAIRS:2)
RandomBlock(6,7,-3,quark:iron_plate:1,70,STAINED_CLAY:15,30,STAINED_CLAY:7,30,null,30,quark:iron_plate:1,100)
Block(6,7,-2,COBBLESTONE_STAIRS:3)
Block(7,5,-4,COBBLESTONE_STAIRS:6)
RandomBlock(7,5,-3,quark:iron_plate:1,70,STAINED_CLAY:15,30,STAINED_CLAY:7,30,null,30,quark:iron_plate:1,100)
Block(7,5,-2,COBBLESTONE_STAIRS:7)
RandomBlock(7,6,-4,quark:iron_plate:1,70,STAINED_CLAY:15,30,STAINED_CLAY:7,30,null,30,quark:iron_plate:1,100)
Block(7,6,-3,srparasites:deadblood)
RandomBlock(7,6,-2,quark:iron_plate:1,70,STAINED_CLAY:15,30,STAINED_CLAY:7,30,null,30,quark:iron_plate:1,100)
Block(7,7,-4,COBBLESTONE_STAIRS:2)
RandomBlock(7,7,-3,rustic:iron_lattice,30,rustic:iron_lattice,30,biomesoplenty:leaves_2:7,30,quark:iron_plate_stairs:6,10,quark:iron_plate_stairs:0,10,quark:iron_plate_stairs:5,10,quark:iron_plate_stairs,10,quark:iron_plate_slab:8,10,quark:iron_plate_stairs:7,10,quark:iron_plate_stairs:1,10,quark:iron_plate_slab,10,quark:iron_plate_stairs:4,10,quark:iron_plate_stairs:2,10,rustic:iron_lattice,50,rustic:iron_lattice,50,biomesoplenty:leaves_2:7,100)
Block(7,7,-2,COBBLESTONE_STAIRS:3)

#######################################################################
# +-----------------------------------------------------------------+ #
# |                             Branches                            | #
# +-----------------------------------------------------------------+ #
#######################################################################

Branch(16,0,0,true,brutal_pipesmall_03C2R0,NORTH,100.0,0)

#######################################################################
# +-----------------------------------------------------------------+ #
# |                             Entities                            | #
# +-----------------------------------------------------------------+ #
#######################################################################


#######################################################################
# +-----------------------------------------------------------------+ #
# |                            Particles                            | #
# +-----------------------------------------------------------------+ #
#######################################################################


#######################################################################
# +-----------------------------------------------------------------+ #
# |                             Spawners                            | #
# +-----------------------------------------------------------------+ #
#######################################################################


#######################################################################
# +-----------------------------------------------------------------+ #
# |                             ModData                             | #
# +-----------------------------------------------------------------+ #
#######################################################################

