
#######################################################################
# +-----------------------------------------------------------------+ #
# |                            BO4 object                           | #
# +-----------------------------------------------------------------+ #
#######################################################################

Author: NLBlackEagle

Description: No description given

SettingsMode: WriteWithoutComments


#######################################################################
# +-----------------------------------------------------------------+ #
# |                          Main settings                          | #
# +-----------------------------------------------------------------+ #
#######################################################################

FixedRotation: 

Frequency: 0

SpawnHeight: highestBlock

UseCenterForHighestBlock: true

##############################
# Height Limits for the BO4. #
##############################

MinHeight: 0

MaxHeight: 255

InheritBO3: 

InheritBO3Rotation: NORTH

OverrideChildSettings: true

OverrideParentHeight: false

CanOverride: true

BranchFrequency: 0

BranchFrequencyGroup: 

MustBeBelowOther: false

MustBeInside: 

CannotBeInside: 

ReplacesBO3: 

MustBeInsideWorldBorders: false

CanSpawnOnWater: true

SpawnOnWaterOnly: false

SpawnUnderWater: false

SpawnAtWaterLevel: false

HeightOffset: 0

RemoveAir: false

ReplaceAbove: 

ReplaceBelow: 

ReplaceWithBiomeBlocks: true

ReplaceWithSurfaceBlock: GRASS

ReplaceWithGroundBlock: DIRT

ReplaceWithStoneBlock: STONE

SmoothRadius: 0

SmoothHeightOffset: 0

SmoothStartTop: false

SmoothStartWood: false

SmoothingSurfaceBlock: 

SmoothingGroundBlock: 

BO3Group: 

IsSpawnPoint: false

DoReplaceBlocks: false


#######################################################################
# +-----------------------------------------------------------------+ #
# |                              Blocks                             | #
# +-----------------------------------------------------------------+ #
#######################################################################

Block(-8,750,-7,AIR:0)
RandomBlock(-7,0,-4,quark:iron_plate:1,70,STAINED_CLAY:15,30,STAINED_CLAY:7,30,null,30,quark:iron_plate:1,100)
RandomBlock(-7,0,-3,quark:iron_plate:1,70,STAINED_CLAY:15,30,STAINED_CLAY:7,30,null,30,quark:iron_plate:1,100)
RandomBlock(-7,0,-2,rustic:iron_lattice,30,rustic:iron_lattice,30,biomesoplenty:leaves_2:7,30,quark:iron_plate_stairs:6,10,quark:iron_plate_stairs:0,10,quark:iron_plate_stairs:5,10,quark:iron_plate_stairs,10,quark:iron_plate_slab:8,10,quark:iron_plate_stairs:7,10,quark:iron_plate_stairs:1,10,quark:iron_plate_slab,10,quark:iron_plate_stairs:4,10,quark:iron_plate_stairs:2,10,rustic:iron_lattice,50,rustic:iron_lattice,50,biomesoplenty:leaves_2:7,100)
RandomBlock(-7,1,-4,rustic:iron_lattice,30,rustic:iron_lattice,30,biomesoplenty:leaves_2:7,30,quark:iron_plate_stairs:6,10,quark:iron_plate_stairs:0,10,quark:iron_plate_stairs:5,10,quark:iron_plate_stairs,10,quark:iron_plate_slab:8,10,quark:iron_plate_stairs:7,10,quark:iron_plate_stairs:1,10,quark:iron_plate_slab,10,quark:iron_plate_stairs:4,10,quark:iron_plate_stairs:2,10,rustic:iron_lattice,50,rustic:iron_lattice,50,biomesoplenty:leaves_2:7,100)
RandomBlock(-7,1,-3,rustic:iron_lattice,30,rustic:iron_lattice,30,biomesoplenty:leaves_2:7,30,quark:iron_plate_stairs:6,10,quark:iron_plate_stairs:0,10,quark:iron_plate_stairs:5,10,quark:iron_plate_stairs,10,quark:iron_plate_slab:8,10,quark:iron_plate_stairs:7,10,quark:iron_plate_stairs:1,10,quark:iron_plate_slab,10,quark:iron_plate_stairs:4,10,quark:iron_plate_stairs:2,10,rustic:iron_lattice,50,rustic:iron_lattice,50,biomesoplenty:leaves_2:7,100)
RandomBlock(-7,1,-2,rustic:iron_lattice,30,rustic:iron_lattice,30,biomesoplenty:leaves_2:7,30,quark:iron_plate_stairs:6,10,quark:iron_plate_stairs:0,10,quark:iron_plate_stairs:5,10,quark:iron_plate_stairs,10,quark:iron_plate_slab:8,10,quark:iron_plate_stairs:7,10,quark:iron_plate_stairs:1,10,quark:iron_plate_slab,10,quark:iron_plate_stairs:4,10,quark:iron_plate_stairs:2,10,rustic:iron_lattice,50,rustic:iron_lattice,50,biomesoplenty:leaves_2:7,100)
RandomBlock(-7,2,-4,rustic:iron_lattice,30,rustic:iron_lattice,30,biomesoplenty:leaves_2:7,30,quark:iron_plate_stairs:6,10,quark:iron_plate_stairs:0,10,quark:iron_plate_stairs:5,10,quark:iron_plate_stairs,10,quark:iron_plate_slab:8,10,quark:iron_plate_stairs:7,10,quark:iron_plate_stairs:1,10,quark:iron_plate_slab,10,quark:iron_plate_stairs:4,10,quark:iron_plate_stairs:2,10,rustic:iron_lattice,50,rustic:iron_lattice,50,biomesoplenty:leaves_2:7,100)
RandomBlock(-7,2,-3,rustic:iron_lattice,30,rustic:iron_lattice,30,biomesoplenty:leaves_2:7,30,quark:iron_plate_stairs:6,10,quark:iron_plate_stairs:0,10,quark:iron_plate_stairs:5,10,quark:iron_plate_stairs,10,quark:iron_plate_slab:8,10,quark:iron_plate_stairs:7,10,quark:iron_plate_stairs:1,10,quark:iron_plate_slab,10,quark:iron_plate_stairs:4,10,quark:iron_plate_stairs:2,10,rustic:iron_lattice,50,rustic:iron_lattice,50,biomesoplenty:leaves_2:7,100)
RandomBlock(-7,2,-2,rustic:iron_lattice,30,rustic:iron_lattice,30,biomesoplenty:leaves_2:7,30,quark:iron_plate_stairs:6,10,quark:iron_plate_stairs:0,10,quark:iron_plate_stairs:5,10,quark:iron_plate_stairs,10,quark:iron_plate_slab:8,10,quark:iron_plate_stairs:7,10,quark:iron_plate_stairs:1,10,quark:iron_plate_slab,10,quark:iron_plate_stairs:4,10,quark:iron_plate_stairs:2,10,rustic:iron_lattice,50,rustic:iron_lattice,50,biomesoplenty:leaves_2:7,100)
RandomBlock(-7,3,-4,rustic:iron_lattice,30,rustic:iron_lattice,30,biomesoplenty:leaves_2:7,30,quark:iron_plate_stairs:6,10,quark:iron_plate_stairs:0,10,quark:iron_plate_stairs:5,10,quark:iron_plate_stairs,10,quark:iron_plate_slab:8,10,quark:iron_plate_stairs:7,10,quark:iron_plate_stairs:1,10,quark:iron_plate_slab,10,quark:iron_plate_stairs:4,10,quark:iron_plate_stairs:2,10,rustic:iron_lattice,50,rustic:iron_lattice,50,biomesoplenty:leaves_2:7,100)
RandomBlock(-7,3,-3,rustic:iron_lattice,30,rustic:iron_lattice,30,biomesoplenty:leaves_2:7,30,quark:iron_plate_stairs:6,10,quark:iron_plate_stairs:0,10,quark:iron_plate_stairs:5,10,quark:iron_plate_stairs,10,quark:iron_plate_slab:8,10,quark:iron_plate_stairs:7,10,quark:iron_plate_stairs:1,10,quark:iron_plate_slab,10,quark:iron_plate_stairs:4,10,quark:iron_plate_stairs:2,10,rustic:iron_lattice,50,rustic:iron_lattice,50,biomesoplenty:leaves_2:7,100)
RandomBlock(-7,3,-2,rustic:iron_lattice,30,rustic:iron_lattice,30,biomesoplenty:leaves_2:7,30,quark:iron_plate_stairs:6,10,quark:iron_plate_stairs:0,10,quark:iron_plate_stairs:5,10,quark:iron_plate_stairs,10,quark:iron_plate_slab:8,10,quark:iron_plate_stairs:7,10,quark:iron_plate_stairs:1,10,quark:iron_plate_slab,10,quark:iron_plate_stairs:4,10,quark:iron_plate_stairs:2,10,rustic:iron_lattice,50,rustic:iron_lattice,50,biomesoplenty:leaves_2:7,100)
RandomBlock(-7,4,-4,rustic:iron_lattice,30,rustic:iron_lattice,30,biomesoplenty:leaves_2:7,30,quark:iron_plate_stairs:6,10,quark:iron_plate_stairs:0,10,quark:iron_plate_stairs:5,10,quark:iron_plate_stairs,10,quark:iron_plate_slab:8,10,quark:iron_plate_stairs:7,10,quark:iron_plate_stairs:1,10,quark:iron_plate_slab,10,quark:iron_plate_stairs:4,10,quark:iron_plate_stairs:2,10,rustic:iron_lattice,50,rustic:iron_lattice,50,biomesoplenty:leaves_2:7,100)
RandomBlock(-7,4,-3,quark:iron_plate:1,70,STAINED_CLAY:15,30,STAINED_CLAY:7,30,null,30,quark:iron_plate:1,100)
RandomBlock(-7,4,-2,rustic:iron_lattice,30,rustic:iron_lattice,30,biomesoplenty:leaves_2:7,30,quark:iron_plate_stairs:6,10,quark:iron_plate_stairs:0,10,quark:iron_plate_stairs:5,10,quark:iron_plate_stairs,10,quark:iron_plate_slab:8,10,quark:iron_plate_stairs:7,10,quark:iron_plate_stairs:1,10,quark:iron_plate_slab,10,quark:iron_plate_stairs:4,10,quark:iron_plate_stairs:2,10,rustic:iron_lattice,50,rustic:iron_lattice,50,biomesoplenty:leaves_2:7,100)
RandomBlock(-7,5,-4,rustic:iron_lattice,30,rustic:iron_lattice,30,biomesoplenty:leaves_2:7,30,quark:iron_plate_stairs:6,10,quark:iron_plate_stairs:0,10,quark:iron_plate_stairs:5,10,quark:iron_plate_stairs,10,quark:iron_plate_slab:8,10,quark:iron_plate_stairs:7,10,quark:iron_plate_stairs:1,10,quark:iron_plate_slab,10,quark:iron_plate_stairs:4,10,quark:iron_plate_stairs:2,10,rustic:iron_lattice,50,rustic:iron_lattice,50,biomesoplenty:leaves_2:7,100)
RandomBlock(-7,5,-3,rustic:iron_lattice,30,rustic:iron_lattice,30,biomesoplenty:leaves_2:7,30,quark:iron_plate_stairs:6,10,quark:iron_plate_stairs:0,10,quark:iron_plate_stairs:5,10,quark:iron_plate_stairs,10,quark:iron_plate_slab:8,10,quark:iron_plate_stairs:7,10,quark:iron_plate_stairs:1,10,quark:iron_plate_slab,10,quark:iron_plate_stairs:4,10,quark:iron_plate_stairs:2,10,rustic:iron_lattice,50,rustic:iron_lattice,50,biomesoplenty:leaves_2:7,100)
RandomBlock(-7,5,-2,rustic:iron_lattice,30,rustic:iron_lattice,30,biomesoplenty:leaves_2:7,30,quark:iron_plate_stairs:6,10,quark:iron_plate_stairs:0,10,quark:iron_plate_stairs:5,10,quark:iron_plate_stairs,10,quark:iron_plate_slab:8,10,quark:iron_plate_stairs:7,10,quark:iron_plate_stairs:1,10,quark:iron_plate_slab,10,quark:iron_plate_stairs:4,10,quark:iron_plate_stairs:2,10,rustic:iron_lattice,50,rustic:iron_lattice,50,biomesoplenty:leaves_2:7,100)
RandomBlock(-7,6,-4,rustic:iron_lattice,30,rustic:iron_lattice,30,biomesoplenty:leaves_2:7,30,quark:iron_plate_stairs:6,10,quark:iron_plate_stairs:0,10,quark:iron_plate_stairs:5,10,quark:iron_plate_stairs,10,quark:iron_plate_slab:8,10,quark:iron_plate_stairs:7,10,quark:iron_plate_stairs:1,10,quark:iron_plate_slab,10,quark:iron_plate_stairs:4,10,quark:iron_plate_stairs:2,10,rustic:iron_lattice,50,rustic:iron_lattice,50,biomesoplenty:leaves_2:7,100)
RandomBlock(-7,6,-3,quark:iron_plate:1,70,STAINED_CLAY:15,30,STAINED_CLAY:7,30,null,30,quark:iron_plate:1,100)
RandomBlock(-7,6,-2,quark:iron_plate:1,70,STAINED_CLAY:15,30,STAINED_CLAY:7,30,null,30,quark:iron_plate:1,100)
RandomBlock(-7,7,-4,quark:iron_plate:1,70,STAINED_CLAY:15,30,STAINED_CLAY:7,30,null,30,quark:iron_plate:1,100)
RandomBlock(-7,7,-3,quark:iron_plate:1,70,STAINED_CLAY:15,30,STAINED_CLAY:7,30,null,30,quark:iron_plate:1,100)
RandomBlock(-7,7,-2,quark:iron_plate:1,70,STAINED_CLAY:15,30,STAINED_CLAY:7,30,null,30,quark:iron_plate:1,100)
RandomBlock(-7,8,-4,quark:iron_plate:1,70,STAINED_CLAY:15,30,STAINED_CLAY:7,30,null,30,quark:iron_plate:1,100)
RandomBlock(-7,8,-3,quark:iron_plate:1,70,STAINED_CLAY:15,30,STAINED_CLAY:7,30,null,30,quark:iron_plate:1,100)
RandomBlock(-7,8,-2,quark:iron_plate:1,70,STAINED_CLAY:15,30,STAINED_CLAY:7,30,null,30,quark:iron_plate:1,100)
RandomBlock(-7,9,-4,quark:iron_plate:1,70,STAINED_CLAY:15,30,STAINED_CLAY:7,30,null,30,quark:iron_plate:1,100)
RandomBlock(-7,9,-3,quark:iron_plate:1,70,STAINED_CLAY:15,30,STAINED_CLAY:7,30,null,30,quark:iron_plate:1,100)
RandomBlock(-7,9,-2,quark:iron_plate:1,70,STAINED_CLAY:15,30,STAINED_CLAY:7,30,null,30,quark:iron_plate:1,100)
RandomBlock(-7,10,-4,quark:iron_plate:1,70,STAINED_CLAY:15,30,STAINED_CLAY:7,30,null,30,quark:iron_plate:1,100)
RandomBlock(-7,10,-3,quark:iron_plate:1,70,STAINED_CLAY:15,30,STAINED_CLAY:7,30,null,30,quark:iron_plate:1,100)
RandomBlock(-7,10,-2,quark:iron_plate:1,70,STAINED_CLAY:15,30,STAINED_CLAY:7,30,null,30,quark:iron_plate:1,100)
RandomBlock(-7,11,-4,quark:iron_plate:1,70,STAINED_CLAY:15,30,STAINED_CLAY:7,30,null,30,quark:iron_plate:1,100)
RandomBlock(-7,11,-3,quark:iron_plate:1,70,STAINED_CLAY:15,30,STAINED_CLAY:7,30,null,30,quark:iron_plate:1,100)
RandomBlock(-7,11,-2,quark:iron_plate:1,70,STAINED_CLAY:15,30,STAINED_CLAY:7,30,null,30,quark:iron_plate:1,100)
RandomBlock(-7,12,-4,quark:iron_plate:1,70,STAINED_CLAY:15,30,STAINED_CLAY:7,30,null,30,quark:iron_plate:1,100)
RandomBlock(-7,12,-3,quark:iron_plate:1,70,STAINED_CLAY:15,30,STAINED_CLAY:7,30,null,30,quark:iron_plate:1,100)
RandomBlock(-7,12,-2,quark:iron_plate:1,70,STAINED_CLAY:15,30,STAINED_CLAY:7,30,null,30,quark:iron_plate:1,100)
RandomBlock(-7,13,-4,quark:iron_plate:1,70,STAINED_CLAY:15,30,STAINED_CLAY:7,30,null,30,quark:iron_plate:1,100)
RandomBlock(-7,13,-3,quark:iron_plate:1,70,STAINED_CLAY:15,30,STAINED_CLAY:7,30,null,30,quark:iron_plate:1,100)
RandomBlock(-7,13,-2,quark:iron_plate:1,70,STAINED_CLAY:15,30,STAINED_CLAY:7,30,null,30,quark:iron_plate:1,100)
RandomBlock(-7,14,-4,quark:iron_plate:1,70,STAINED_CLAY:15,30,STAINED_CLAY:7,30,null,30,quark:iron_plate:1,100)
RandomBlock(-7,14,-3,quark:iron_plate:1,70,STAINED_CLAY:15,30,STAINED_CLAY:7,30,null,30,quark:iron_plate:1,100)
RandomBlock(-7,14,-2,quark:iron_plate:1,70,STAINED_CLAY:15,30,STAINED_CLAY:7,30,null,30,quark:iron_plate:1,100)
RandomBlock(-7,15,-4,quark:iron_plate:1,70,STAINED_CLAY:15,30,STAINED_CLAY:7,30,null,30,quark:iron_plate:1,100)
RandomBlock(-7,15,-3,quark:iron_plate:1,70,STAINED_CLAY:15,30,STAINED_CLAY:7,30,null,30,quark:iron_plate:1,100)
RandomBlock(-7,15,-2,quark:iron_plate:1,70,STAINED_CLAY:15,30,STAINED_CLAY:7,30,null,30,quark:iron_plate:1,100)
RandomBlock(-7,16,-4,quark:iron_plate:1,70,STAINED_CLAY:15,30,STAINED_CLAY:7,30,null,30,quark:iron_plate:1,100)
RandomBlock(-7,16,-3,quark:iron_plate:1,70,STAINED_CLAY:15,30,STAINED_CLAY:7,30,null,30,quark:iron_plate:1,100)
RandomBlock(-7,16,-2,quark:iron_plate:1,70,STAINED_CLAY:15,30,STAINED_CLAY:7,30,null,30,quark:iron_plate:1,100)
RandomBlock(-7,17,-4,quark:iron_plate:1,70,STAINED_CLAY:15,30,STAINED_CLAY:7,30,null,30,quark:iron_plate:1,100)
RandomBlock(-7,17,-3,quark:iron_plate:1,70,STAINED_CLAY:15,30,STAINED_CLAY:7,30,null,30,quark:iron_plate:1,100)
RandomBlock(-7,17,-2,quark:iron_plate:1,70,STAINED_CLAY:15,30,STAINED_CLAY:7,30,null,30,quark:iron_plate:1,100)
RandomBlock(-7,18,-4,quark:iron_plate:1,70,STAINED_CLAY:15,30,STAINED_CLAY:7,30,null,30,quark:iron_plate:1,100)
RandomBlock(-7,18,-3,quark:iron_plate:1,70,STAINED_CLAY:15,30,STAINED_CLAY:7,30,null,30,quark:iron_plate:1,100)
RandomBlock(-7,18,-2,quark:iron_plate:1,70,STAINED_CLAY:15,30,STAINED_CLAY:7,30,null,30,quark:iron_plate:1,100)
RandomBlock(-7,19,-4,quark:iron_plate:1,70,STAINED_CLAY:15,30,STAINED_CLAY:7,30,null,30,quark:iron_plate:1,100)
RandomBlock(-7,19,-3,quark:iron_plate:1,70,STAINED_CLAY:15,30,STAINED_CLAY:7,30,null,30,quark:iron_plate:1,100)
RandomBlock(-7,19,-2,quark:iron_plate:1,70,STAINED_CLAY:15,30,STAINED_CLAY:7,30,null,30,quark:iron_plate:1,100)
RandomBlock(-6,0,-4,rustic:iron_lattice,30,rustic:iron_lattice,30,biomesoplenty:leaves_2:7,30,quark:iron_plate_stairs:6,10,quark:iron_plate_stairs:0,10,quark:iron_plate_stairs:5,10,quark:iron_plate_stairs,10,quark:iron_plate_slab:8,10,quark:iron_plate_stairs:7,10,quark:iron_plate_stairs:1,10,quark:iron_plate_slab,10,quark:iron_plate_stairs:4,10,quark:iron_plate_stairs:2,10,rustic:iron_lattice,50,rustic:iron_lattice,50,biomesoplenty:leaves_2:7,100)
Block(-6,0,-3,AIR:0)
RandomBlock(-6,0,-2,rustic:iron_lattice,30,rustic:iron_lattice,30,biomesoplenty:leaves_2:7,30,quark:iron_plate_stairs:6,10,quark:iron_plate_stairs:0,10,quark:iron_plate_stairs:5,10,quark:iron_plate_stairs,10,quark:iron_plate_slab:8,10,quark:iron_plate_stairs:7,10,quark:iron_plate_stairs:1,10,quark:iron_plate_slab,10,quark:iron_plate_stairs:4,10,quark:iron_plate_stairs:2,10,rustic:iron_lattice,50,rustic:iron_lattice,50,biomesoplenty:leaves_2:7,100)
RandomBlock(-6,1,-4,quark:iron_plate:1,70,STAINED_CLAY:15,30,STAINED_CLAY:7,30,null,30,quark:iron_plate:1,100)
Block(-6,1,-3,AIR:0)
RandomBlock(-6,1,-2,rustic:iron_lattice,30,rustic:iron_lattice,30,biomesoplenty:leaves_2:7,30,quark:iron_plate_stairs:6,10,quark:iron_plate_stairs:0,10,quark:iron_plate_stairs:5,10,quark:iron_plate_stairs,10,quark:iron_plate_slab:8,10,quark:iron_plate_stairs:7,10,quark:iron_plate_stairs:1,10,quark:iron_plate_slab,10,quark:iron_plate_stairs:4,10,quark:iron_plate_stairs:2,10,rustic:iron_lattice,50,rustic:iron_lattice,50,biomesoplenty:leaves_2:7,100)
RandomBlock(-6,2,-4,rustic:iron_lattice,30,rustic:iron_lattice,30,biomesoplenty:leaves_2:7,30,quark:iron_plate_stairs:6,10,quark:iron_plate_stairs:0,10,quark:iron_plate_stairs:5,10,quark:iron_plate_stairs,10,quark:iron_plate_slab:8,10,quark:iron_plate_stairs:7,10,quark:iron_plate_stairs:1,10,quark:iron_plate_slab,10,quark:iron_plate_stairs:4,10,quark:iron_plate_stairs:2,10,rustic:iron_lattice,50,rustic:iron_lattice,50,biomesoplenty:leaves_2:7,100)
Block(-6,2,-3,AIR:0)
RandomBlock(-6,2,-2,quark:iron_plate:1,70,STAINED_CLAY:15,30,STAINED_CLAY:7,30,null,30,quark:iron_plate:1,100)
RandomBlock(-6,3,-4,quark:iron_plate:1,70,STAINED_CLAY:15,30,STAINED_CLAY:7,30,null,30,quark:iron_plate:1,100)
Block(-6,3,-3,AIR:0)
RandomBlock(-6,3,-2,rustic:iron_lattice,30,rustic:iron_lattice,30,biomesoplenty:leaves_2:7,30,quark:iron_plate_stairs:6,10,quark:iron_plate_stairs:0,10,quark:iron_plate_stairs:5,10,quark:iron_plate_stairs,10,quark:iron_plate_slab:8,10,quark:iron_plate_stairs:7,10,quark:iron_plate_stairs:1,10,quark:iron_plate_slab,10,quark:iron_plate_stairs:4,10,quark:iron_plate_stairs:2,10,rustic:iron_lattice,50,rustic:iron_lattice,50,biomesoplenty:leaves_2:7,100)
RandomBlock(-6,4,-4,quark:iron_plate:1,70,STAINED_CLAY:15,30,STAINED_CLAY:7,30,null,30,quark:iron_plate:1,100)
Block(-6,4,-3,AIR:0)
RandomBlock(-6,4,-2,rustic:iron_lattice,30,rustic:iron_lattice,30,biomesoplenty:leaves_2:7,30,quark:iron_plate_stairs:6,10,quark:iron_plate_stairs:0,10,quark:iron_plate_stairs:5,10,quark:iron_plate_stairs,10,quark:iron_plate_slab:8,10,quark:iron_plate_stairs:7,10,quark:iron_plate_stairs:1,10,quark:iron_plate_slab,10,quark:iron_plate_stairs:4,10,quark:iron_plate_stairs:2,10,rustic:iron_lattice,50,rustic:iron_lattice,50,biomesoplenty:leaves_2:7,100)
RandomBlock(-6,5,-4,rustic:iron_lattice,30,rustic:iron_lattice,30,biomesoplenty:leaves_2:7,30,quark:iron_plate_stairs:6,10,quark:iron_plate_stairs:0,10,quark:iron_plate_stairs:5,10,quark:iron_plate_stairs,10,quark:iron_plate_slab:8,10,quark:iron_plate_stairs:7,10,quark:iron_plate_stairs:1,10,quark:iron_plate_slab,10,quark:iron_plate_stairs:4,10,quark:iron_plate_stairs:2,10,rustic:iron_lattice,50,rustic:iron_lattice,50,biomesoplenty:leaves_2:7,100)
Block(-6,5,-3,AIR:0)
RandomBlock(-6,5,-2,rustic:iron_lattice,30,rustic:iron_lattice,30,biomesoplenty:leaves_2:7,30,quark:iron_plate_stairs:6,10,quark:iron_plate_stairs:0,10,quark:iron_plate_stairs:5,10,quark:iron_plate_stairs,10,quark:iron_plate_slab:8,10,quark:iron_plate_stairs:7,10,quark:iron_plate_stairs:1,10,quark:iron_plate_slab,10,quark:iron_plate_stairs:4,10,quark:iron_plate_stairs:2,10,rustic:iron_lattice,50,rustic:iron_lattice,50,biomesoplenty:leaves_2:7,100)
RandomBlock(-6,6,-4,quark:iron_plate:1,70,STAINED_CLAY:15,30,STAINED_CLAY:7,30,null,30,quark:iron_plate:1,100)
Block(-6,6,-3,AIR:0)
RandomBlock(-6,6,-2,rustic:iron_lattice,30,rustic:iron_lattice,30,biomesoplenty:leaves_2:7,30,quark:iron_plate_stairs:6,10,quark:iron_plate_stairs:0,10,quark:iron_plate_stairs:5,10,quark:iron_plate_stairs,10,quark:iron_plate_slab:8,10,quark:iron_plate_stairs:7,10,quark:iron_plate_stairs:1,10,quark:iron_plate_slab,10,quark:iron_plate_stairs:4,10,quark:iron_plate_stairs:2,10,rustic:iron_lattice,50,rustic:iron_lattice,50,biomesoplenty:leaves_2:7,100)
RandomBlock(-6,7,-4,quark:iron_plate:1,70,STAINED_CLAY:15,30,STAINED_CLAY:7,30,null,30,quark:iron_plate:1,100)
Block(-6,7,-3,AIR:0)
RandomBlock(-6,7,-2,quark:iron_plate:1,70,STAINED_CLAY:15,30,STAINED_CLAY:7,30,null,30,quark:iron_plate:1,100)
RandomBlock(-6,8,-4,quark:iron_plate:1,70,STAINED_CLAY:15,30,STAINED_CLAY:7,30,null,30,quark:iron_plate:1,100)
Block(-6,8,-3,AIR:0)
RandomBlock(-6,8,-2,quark:iron_plate:1,70,STAINED_CLAY:15,30,STAINED_CLAY:7,30,null,30,quark:iron_plate:1,100)
RandomBlock(-6,9,-4,quark:iron_plate:1,70,STAINED_CLAY:15,30,STAINED_CLAY:7,30,null,30,quark:iron_plate:1,100)
Block(-6,9,-3,AIR:0)
RandomBlock(-6,9,-2,quark:iron_plate:1,70,STAINED_CLAY:15,30,STAINED_CLAY:7,30,null,30,quark:iron_plate:1,100)
RandomBlock(-6,10,-4,quark:iron_plate:1,70,STAINED_CLAY:15,30,STAINED_CLAY:7,30,null,30,quark:iron_plate:1,100)
Block(-6,10,-3,AIR:0)
RandomBlock(-6,10,-2,quark:iron_plate:1,70,STAINED_CLAY:15,30,STAINED_CLAY:7,30,null,30,quark:iron_plate:1,100)
RandomBlock(-6,11,-4,quark:iron_plate:1,70,STAINED_CLAY:15,30,STAINED_CLAY:7,30,null,30,quark:iron_plate:1,100)
Block(-6,11,-3,AIR:0)
RandomBlock(-6,11,-2,quark:iron_plate:1,70,STAINED_CLAY:15,30,STAINED_CLAY:7,30,null,30,quark:iron_plate:1,100)
RandomBlock(-6,12,-4,rustic:iron_lattice,30,rustic:iron_lattice,30,biomesoplenty:leaves_2:7,30,quark:iron_plate_stairs:6,10,quark:iron_plate_stairs:0,10,quark:iron_plate_stairs:5,10,quark:iron_plate_stairs,10,quark:iron_plate_slab:8,10,quark:iron_plate_stairs:7,10,quark:iron_plate_stairs:1,10,quark:iron_plate_slab,10,quark:iron_plate_stairs:4,10,quark:iron_plate_stairs:2,10,rustic:iron_lattice,50,rustic:iron_lattice,50,biomesoplenty:leaves_2:7,100)
Block(-6,12,-3,AIR:0)
RandomBlock(-6,12,-2,quark:iron_plate:1,70,STAINED_CLAY:15,30,STAINED_CLAY:7,30,null,30,quark:iron_plate:1,100)
RandomBlock(-6,13,-4,quark:iron_plate:1,70,STAINED_CLAY:15,30,STAINED_CLAY:7,30,null,30,quark:iron_plate:1,100)
Block(-6,13,-3,AIR:0)
RandomBlock(-6,13,-2,quark:iron_plate:1,70,STAINED_CLAY:15,30,STAINED_CLAY:7,30,null,30,quark:iron_plate:1,100)
RandomBlock(-6,14,-4,quark:iron_plate:1,70,STAINED_CLAY:15,30,STAINED_CLAY:7,30,null,30,quark:iron_plate:1,100)
Block(-6,14,-3,AIR:0)
RandomBlock(-6,14,-2,quark:iron_plate:1,70,STAINED_CLAY:15,30,STAINED_CLAY:7,30,null,30,quark:iron_plate:1,100)
RandomBlock(-6,15,-4,quark:iron_plate:1,70,STAINED_CLAY:15,30,STAINED_CLAY:7,30,null,30,quark:iron_plate:1,100)
Block(-6,15,-3,AIR:0)
RandomBlock(-6,15,-2,quark:iron_plate:1,70,STAINED_CLAY:15,30,STAINED_CLAY:7,30,null,30,quark:iron_plate:1,100)
RandomBlock(-6,16,-4,quark:iron_plate:1,70,STAINED_CLAY:15,30,STAINED_CLAY:7,30,null,30,quark:iron_plate:1,100)
Block(-6,16,-3,AIR:0)
RandomBlock(-6,16,-2,quark:iron_plate:1,70,STAINED_CLAY:15,30,STAINED_CLAY:7,30,null,30,quark:iron_plate:1,100)
RandomBlock(-6,17,-4,quark:iron_plate:1,70,STAINED_CLAY:15,30,STAINED_CLAY:7,30,null,30,quark:iron_plate:1,100)
Block(-6,17,-3,AIR:0)
RandomBlock(-6,17,-2,quark:iron_plate:1,70,STAINED_CLAY:15,30,STAINED_CLAY:7,30,null,30,quark:iron_plate:1,100)
RandomBlock(-6,18,-4,quark:iron_plate:1,70,STAINED_CLAY:15,30,STAINED_CLAY:7,30,null,30,quark:iron_plate:1,100)
Block(-6,18,-3,AIR:0)
RandomBlock(-6,18,-2,quark:iron_plate:1,70,STAINED_CLAY:15,30,STAINED_CLAY:7,30,null,30,quark:iron_plate:1,100)
RandomBlock(-6,19,-4,quark:iron_plate:1,70,STAINED_CLAY:15,30,STAINED_CLAY:7,30,null,30,quark:iron_plate:1,100)
Block(-6,19,-3,AIR:0)
RandomBlock(-6,19,-2,quark:iron_plate:1,70,STAINED_CLAY:15,30,STAINED_CLAY:7,30,null,30,quark:iron_plate:1,100)
RandomBlock(-5,0,-4,quark:iron_plate:1,70,STAINED_CLAY:15,30,STAINED_CLAY:7,30,null,30,quark:iron_plate:1,100)
RandomBlock(-5,0,-3,quark:iron_plate:1,70,STAINED_CLAY:15,30,STAINED_CLAY:7,30,null,30,quark:iron_plate:1,100)
RandomBlock(-5,0,-2,quark:iron_plate:1,70,STAINED_CLAY:15,30,STAINED_CLAY:7,30,null,30,quark:iron_plate:1,100)
RandomBlock(-5,1,-4,quark:iron_plate:1,70,STAINED_CLAY:15,30,STAINED_CLAY:7,30,null,30,quark:iron_plate:1,100)
RandomBlock(-5,1,-3,quark:iron_plate:1,70,STAINED_CLAY:15,30,STAINED_CLAY:7,30,null,30,quark:iron_plate:1,100)
RandomBlock(-5,1,-2,quark:iron_plate:1,70,STAINED_CLAY:15,30,STAINED_CLAY:7,30,null,30,quark:iron_plate:1,100)
RandomBlock(-5,2,-4,quark:iron_plate:1,70,STAINED_CLAY:15,30,STAINED_CLAY:7,30,null,30,quark:iron_plate:1,100)
RandomBlock(-5,2,-3,quark:iron_plate:1,70,STAINED_CLAY:15,30,STAINED_CLAY:7,30,null,30,quark:iron_plate:1,100)
RandomBlock(-5,2,-2,quark:iron_plate:1,70,STAINED_CLAY:15,30,STAINED_CLAY:7,30,null,30,quark:iron_plate:1,100)
RandomBlock(-5,3,-4,quark:iron_plate:1,70,STAINED_CLAY:15,30,STAINED_CLAY:7,30,null,30,quark:iron_plate:1,100)
RandomBlock(-5,3,-3,quark:iron_plate:1,70,STAINED_CLAY:15,30,STAINED_CLAY:7,30,null,30,quark:iron_plate:1,100)
RandomBlock(-5,3,-2,quark:iron_plate:1,70,STAINED_CLAY:15,30,STAINED_CLAY:7,30,null,30,quark:iron_plate:1,100)
RandomBlock(-5,4,-4,quark:iron_plate:1,70,STAINED_CLAY:15,30,STAINED_CLAY:7,30,null,30,quark:iron_plate:1,100)
RandomBlock(-5,4,-3,quark:iron_plate:1,70,STAINED_CLAY:15,30,STAINED_CLAY:7,30,null,30,quark:iron_plate:1,100)
RandomBlock(-5,4,-2,quark:iron_plate:1,70,STAINED_CLAY:15,30,STAINED_CLAY:7,30,null,30,quark:iron_plate:1,100)
RandomBlock(-5,5,-4,quark:iron_plate:1,70,STAINED_CLAY:15,30,STAINED_CLAY:7,30,null,30,quark:iron_plate:1,100)
RandomBlock(-5,5,-3,quark:iron_plate:1,70,STAINED_CLAY:15,30,STAINED_CLAY:7,30,null,30,quark:iron_plate:1,100)
RandomBlock(-5,5,-2,rustic:iron_lattice,30,rustic:iron_lattice,30,biomesoplenty:leaves_2:7,30,quark:iron_plate_stairs:6,10,quark:iron_plate_stairs:0,10,quark:iron_plate_stairs:5,10,quark:iron_plate_stairs,10,quark:iron_plate_slab:8,10,quark:iron_plate_stairs:7,10,quark:iron_plate_stairs:1,10,quark:iron_plate_slab,10,quark:iron_plate_stairs:4,10,quark:iron_plate_stairs:2,10,rustic:iron_lattice,50,rustic:iron_lattice,50,biomesoplenty:leaves_2:7,100)
RandomBlock(-5,6,-4,quark:iron_plate:1,70,STAINED_CLAY:15,30,STAINED_CLAY:7,30,null,30,quark:iron_plate:1,100)
RandomBlock(-5,6,-3,rustic:iron_lattice,30,rustic:iron_lattice,30,biomesoplenty:leaves_2:7,30,quark:iron_plate_stairs:6,10,quark:iron_plate_stairs:0,10,quark:iron_plate_stairs:5,10,quark:iron_plate_stairs,10,quark:iron_plate_slab:8,10,quark:iron_plate_stairs:7,10,quark:iron_plate_stairs:1,10,quark:iron_plate_slab,10,quark:iron_plate_stairs:4,10,quark:iron_plate_stairs:2,10,rustic:iron_lattice,50,rustic:iron_lattice,50,biomesoplenty:leaves_2:7,100)
RandomBlock(-5,6,-2,rustic:iron_lattice,30,rustic:iron_lattice,30,biomesoplenty:leaves_2:7,30,quark:iron_plate_stairs:6,10,quark:iron_plate_stairs:0,10,quark:iron_plate_stairs:5,10,quark:iron_plate_stairs,10,quark:iron_plate_slab:8,10,quark:iron_plate_stairs:7,10,quark:iron_plate_stairs:1,10,quark:iron_plate_slab,10,quark:iron_plate_stairs:4,10,quark:iron_plate_stairs:2,10,rustic:iron_lattice,50,rustic:iron_lattice,50,biomesoplenty:leaves_2:7,100)
RandomBlock(-5,7,-4,quark:iron_plate:1,70,STAINED_CLAY:15,30,STAINED_CLAY:7,30,null,30,quark:iron_plate:1,100)
RandomBlock(-5,7,-3,quark:iron_plate:1,70,STAINED_CLAY:15,30,STAINED_CLAY:7,30,null,30,quark:iron_plate:1,100)
RandomBlock(-5,7,-2,rustic:iron_lattice,30,rustic:iron_lattice,30,biomesoplenty:leaves_2:7,30,quark:iron_plate_stairs:6,10,quark:iron_plate_stairs:0,10,quark:iron_plate_stairs:5,10,quark:iron_plate_stairs,10,quark:iron_plate_slab:8,10,quark:iron_plate_stairs:7,10,quark:iron_plate_stairs:1,10,quark:iron_plate_slab,10,quark:iron_plate_stairs:4,10,quark:iron_plate_stairs:2,10,rustic:iron_lattice,50,rustic:iron_lattice,50,biomesoplenty:leaves_2:7,100)
RandomBlock(-5,8,-4,quark:iron_plate:1,70,STAINED_CLAY:15,30,STAINED_CLAY:7,30,null,30,quark:iron_plate:1,100)
RandomBlock(-5,8,-3,quark:iron_plate:1,70,STAINED_CLAY:15,30,STAINED_CLAY:7,30,null,30,quark:iron_plate:1,100)
RandomBlock(-5,8,-2,quark:iron_plate:1,70,STAINED_CLAY:15,30,STAINED_CLAY:7,30,null,30,quark:iron_plate:1,100)
RandomBlock(-5,9,-4,quark:iron_plate:1,70,STAINED_CLAY:15,30,STAINED_CLAY:7,30,null,30,quark:iron_plate:1,100)
RandomBlock(-5,9,-3,quark:iron_plate:1,70,STAINED_CLAY:15,30,STAINED_CLAY:7,30,null,30,quark:iron_plate:1,100)
RandomBlock(-5,9,-2,quark:iron_plate:1,70,STAINED_CLAY:15,30,STAINED_CLAY:7,30,null,30,quark:iron_plate:1,100)
RandomBlock(-5,10,-4,quark:iron_plate:1,70,STAINED_CLAY:15,30,STAINED_CLAY:7,30,null,30,quark:iron_plate:1,100)
RandomBlock(-5,10,-3,quark:iron_plate:1,70,STAINED_CLAY:15,30,STAINED_CLAY:7,30,null,30,quark:iron_plate:1,100)
RandomBlock(-5,10,-2,quark:iron_plate:1,70,STAINED_CLAY:15,30,STAINED_CLAY:7,30,null,30,quark:iron_plate:1,100)
RandomBlock(-5,11,-4,rustic:iron_lattice,30,rustic:iron_lattice,30,biomesoplenty:leaves_2:7,30,quark:iron_plate_stairs:6,10,quark:iron_plate_stairs:0,10,quark:iron_plate_stairs:5,10,quark:iron_plate_stairs,10,quark:iron_plate_slab:8,10,quark:iron_plate_stairs:7,10,quark:iron_plate_stairs:1,10,quark:iron_plate_slab,10,quark:iron_plate_stairs:4,10,quark:iron_plate_stairs:2,10,rustic:iron_lattice,50,rustic:iron_lattice,50,biomesoplenty:leaves_2:7,100)
RandomBlock(-5,11,-3,quark:iron_plate:1,70,STAINED_CLAY:15,30,STAINED_CLAY:7,30,null,30,quark:iron_plate:1,100)
RandomBlock(-5,11,-2,quark:iron_plate:1,70,STAINED_CLAY:15,30,STAINED_CLAY:7,30,null,30,quark:iron_plate:1,100)
RandomBlock(-5,12,-4,rustic:iron_lattice,30,rustic:iron_lattice,30,biomesoplenty:leaves_2:7,30,quark:iron_plate_stairs:6,10,quark:iron_plate_stairs:0,10,quark:iron_plate_stairs:5,10,quark:iron_plate_stairs,10,quark:iron_plate_slab:8,10,quark:iron_plate_stairs:7,10,quark:iron_plate_stairs:1,10,quark:iron_plate_slab,10,quark:iron_plate_stairs:4,10,quark:iron_plate_stairs:2,10,rustic:iron_lattice,50,rustic:iron_lattice,50,biomesoplenty:leaves_2:7,100)
RandomBlock(-5,12,-3,rustic:iron_lattice,30,rustic:iron_lattice,30,biomesoplenty:leaves_2:7,30,quark:iron_plate_stairs:6,10,quark:iron_plate_stairs:0,10,quark:iron_plate_stairs:5,10,quark:iron_plate_stairs,10,quark:iron_plate_slab:8,10,quark:iron_plate_stairs:7,10,quark:iron_plate_stairs:1,10,quark:iron_plate_slab,10,quark:iron_plate_stairs:4,10,quark:iron_plate_stairs:2,10,rustic:iron_lattice,50,rustic:iron_lattice,50,biomesoplenty:leaves_2:7,100)
RandomBlock(-5,12,-2,quark:iron_plate:1,70,STAINED_CLAY:15,30,STAINED_CLAY:7,30,null,30,quark:iron_plate:1,100)
RandomBlock(-5,13,-4,rustic:iron_lattice,30,rustic:iron_lattice,30,biomesoplenty:leaves_2:7,30,quark:iron_plate_stairs:6,10,quark:iron_plate_stairs:0,10,quark:iron_plate_stairs:5,10,quark:iron_plate_stairs,10,quark:iron_plate_slab:8,10,quark:iron_plate_stairs:7,10,quark:iron_plate_stairs:1,10,quark:iron_plate_slab,10,quark:iron_plate_stairs:4,10,quark:iron_plate_stairs:2,10,rustic:iron_lattice,50,rustic:iron_lattice,50,biomesoplenty:leaves_2:7,100)
RandomBlock(-5,13,-3,quark:iron_plate:1,70,STAINED_CLAY:15,30,STAINED_CLAY:7,30,null,30,quark:iron_plate:1,100)
RandomBlock(-5,13,-2,quark:iron_plate:1,70,STAINED_CLAY:15,30,STAINED_CLAY:7,30,null,30,quark:iron_plate:1,100)
RandomBlock(-5,14,-4,quark:iron_plate:1,70,STAINED_CLAY:15,30,STAINED_CLAY:7,30,null,30,quark:iron_plate:1,100)
RandomBlock(-5,14,-3,quark:iron_plate:1,70,STAINED_CLAY:15,30,STAINED_CLAY:7,30,null,30,quark:iron_plate:1,100)
RandomBlock(-5,14,-2,quark:iron_plate:1,70,STAINED_CLAY:15,30,STAINED_CLAY:7,30,null,30,quark:iron_plate:1,100)
RandomBlock(-5,15,-4,quark:iron_plate:1,70,STAINED_CLAY:15,30,STAINED_CLAY:7,30,null,30,quark:iron_plate:1,100)
RandomBlock(-5,15,-3,quark:iron_plate:1,70,STAINED_CLAY:15,30,STAINED_CLAY:7,30,null,30,quark:iron_plate:1,100)
RandomBlock(-5,15,-2,quark:iron_plate:1,70,STAINED_CLAY:15,30,STAINED_CLAY:7,30,null,30,quark:iron_plate:1,100)
RandomBlock(-5,16,-4,quark:iron_plate:1,70,STAINED_CLAY:15,30,STAINED_CLAY:7,30,null,30,quark:iron_plate:1,100)
RandomBlock(-5,16,-3,quark:iron_plate:1,70,STAINED_CLAY:15,30,STAINED_CLAY:7,30,null,30,quark:iron_plate:1,100)
RandomBlock(-5,16,-2,quark:iron_plate:1,70,STAINED_CLAY:15,30,STAINED_CLAY:7,30,null,30,quark:iron_plate:1,100)
RandomBlock(-5,17,-4,quark:iron_plate:1,70,STAINED_CLAY:15,30,STAINED_CLAY:7,30,null,30,quark:iron_plate:1,100)
RandomBlock(-5,17,-3,quark:iron_plate:1,70,STAINED_CLAY:15,30,STAINED_CLAY:7,30,null,30,quark:iron_plate:1,100)
RandomBlock(-5,17,-2,quark:iron_plate:1,70,STAINED_CLAY:15,30,STAINED_CLAY:7,30,null,30,quark:iron_plate:1,100)
RandomBlock(-5,18,-4,quark:iron_plate:1,70,STAINED_CLAY:15,30,STAINED_CLAY:7,30,null,30,quark:iron_plate:1,100)
RandomBlock(-5,18,-3,quark:iron_plate:1,70,STAINED_CLAY:15,30,STAINED_CLAY:7,30,null,30,quark:iron_plate:1,100)
RandomBlock(-5,18,-2,quark:iron_plate:1,70,STAINED_CLAY:15,30,STAINED_CLAY:7,30,null,30,quark:iron_plate:1,100)
RandomBlock(-5,19,-4,quark:iron_plate:1,70,STAINED_CLAY:15,30,STAINED_CLAY:7,30,null,30,quark:iron_plate:1,100)
RandomBlock(-5,19,-3,quark:iron_plate:1,70,STAINED_CLAY:15,30,STAINED_CLAY:7,30,null,30,quark:iron_plate:1,100)
RandomBlock(-5,19,-2,quark:iron_plate:1,70,STAINED_CLAY:15,30,STAINED_CLAY:7,30,null,30,quark:iron_plate:1,100)

#######################################################################
# +-----------------------------------------------------------------+ #
# |                             Branches                            | #
# +-----------------------------------------------------------------+ #
#######################################################################

Branch(16,0,0,true,brutal_pipesmall_03_D1C1R0,NORTH,100.0,0)

#######################################################################
# +-----------------------------------------------------------------+ #
# |                             Entities                            | #
# +-----------------------------------------------------------------+ #
#######################################################################


#######################################################################
# +-----------------------------------------------------------------+ #
# |                            Particles                            | #
# +-----------------------------------------------------------------+ #
#######################################################################


#######################################################################
# +-----------------------------------------------------------------+ #
# |                             Spawners                            | #
# +-----------------------------------------------------------------+ #
#######################################################################


#######################################################################
# +-----------------------------------------------------------------+ #
# |                             ModData                             | #
# +-----------------------------------------------------------------+ #
#######################################################################

