
#######################################################################
# +-----------------------------------------------------------------+ #
# |                            BO3 object                           | #
# +-----------------------------------------------------------------+ #
#######################################################################

Author: NLBlackHeavenNL

Description: No description given

Version: 3

SettingsMode: WriteWithoutComments


#######################################################################
# +-----------------------------------------------------------------+ #
# |                          Main settings                          | #
# +-----------------------------------------------------------------+ #
#######################################################################

Tree: true

Frequency: 1

Rarity: 100.0

RotateRandomly: false

SpawnHeight: highestSolidBlock

SpawnHeightOffset: -1

SpawnHeightVariance: 0

##############################
# Height Limits for the BO3. #
##############################

MinHeight: 0

MaxHeight: 255

######################
# Extrusion settings #
######################

ExtrudeMode: None

ExtrudeThroughBlocks: AIR

MaxBranchDepth: 10

ExcludedBiomes: All


#######################################################################
# +-----------------------------------------------------------------+ #
# |                      Source block settings                      | #
# +-----------------------------------------------------------------+ #
#######################################################################

SourceBlocks: AIR,GRASS,DIRT,biomesoplenty:dirt,dynamictrees:leaves1

MaxPercentageOutsideSourceBlock: 0

OutsideSourceBlock: placeAnyway

DoReplaceBlocks: true

IsOTGPlus: false


#######################################################################
# +-----------------------------------------------------------------+ #
# |                              Blocks                             | #
# +-----------------------------------------------------------------+ #
#######################################################################

Block(-2,4,-1,dynamictrees:leaves1:4)
Block(-2,4,0,dynamictrees:leaves1:4)
Block(-2,4,1,dynamictrees:leaves1:4)
Block(-1,3,-1,dynamictrees:leaves1:4)
Block(-1,3,0,dynamictrees:leaves1:4)
Block(-1,3,1,dynamictrees:leaves1:4)
Block(-1,4,-2,dynamictrees:leaves1:4)
Block(-1,4,-1,dynamictrees:leaves1:5)
Block(-1,4,0,dynamictrees:leaves1:5)
Block(-1,4,1,dynamictrees:leaves1:5)
Block(-1,4,2,dynamictrees:leaves1:4)
Block(-1,5,-1,dynamictrees:leaves1:4)
Block(-1,5,0,dynamictrees:leaves1:4)
Block(-1,5,1,dynamictrees:leaves1:4)
Block(-1,6,0,dynamictrees:leaves1:4)
Block(0,3,-2,dynamictrees:leaves1:4)
Block(0,3,2,dynamictrees:leaves1:4)
Block(0,4,-3,dynamictrees:leaves1:4)
Block(0,4,-2,dynamictrees:leaves1:5)
Block(0,4,-1,dynamictrees:leaves1:6)
Block(0,4,0,dynamictrees:leaves1:5)
Block(0,4,1,dynamictrees:leaves1:5)
Block(0,4,2,dynamictrees:leaves1:4)
Block(0,5,-2,dynamictrees:leaves1:4)
Block(0,5,-1,dynamictrees:leaves1:5)
Block(0,5,0,dynamictrees:leaves1:7)
Block(0,5,1,dynamictrees:leaves1:5)
Block(0,5,2,dynamictrees:leaves1:4)
Block(0,6,-1,dynamictrees:leaves1:4)
Block(0,6,0,dynamictrees:leaves1:5)
Block(0,6,1,dynamictrees:leaves1:4)
Block(0,7,0,dynamictrees:leaves1:4)
Block(1,0,0,dynamictrees:rootydirt)
Block(1,1,0,dynamictrees:darkoakbranch:2)
Block(1,2,0,dynamictrees:darkoakbranch:1)
Block(1,3,-2,dynamictrees:leaves1:4)
Block(1,3,0,dynamictrees:darkoakbranch:1)
Block(1,4,-3,dynamictrees:leaves1:4)
Block(1,4,-2,dynamictrees:leaves1:5)
Block(1,4,-1,dynamictrees:leaves1:5)
Block(1,4,0,dynamictrees:darkoakbranch:1)
Block(1,4,2,dynamictrees:leaves1:4)
Block(1,5,-2,dynamictrees:leaves1:4)
Block(1,5,-1,dynamictrees:leaves1:7)
Block(1,5,0,dynamictrees:darkoakbranch)
Block(1,5,1,dynamictrees:leaves1:7)
Block(1,5,2,dynamictrees:leaves1:5)
Block(1,5,3,dynamictrees:leaves1:4)
Block(1,6,-2,dynamictrees:leaves1:4)
Block(1,6,-1,dynamictrees:leaves1:5)
Block(1,6,0,dynamictrees:leaves1:7)
Block(1,6,1,dynamictrees:leaves1:5)
Block(1,6,2,dynamictrees:leaves1:4)
Block(1,7,-1,dynamictrees:leaves1:4)
Block(1,7,0,dynamictrees:leaves1:5)
Block(1,7,1,dynamictrees:leaves1:4)
Block(1,8,0,dynamictrees:leaves1:4)
Block(2,3,-2,dynamictrees:leaves1:4)
Block(2,4,-3,dynamictrees:leaves1:4)
Block(2,4,-2,dynamictrees:leaves1:5)
Block(2,4,-1,dynamictrees:leaves1:5)
Block(2,4,0,dynamictrees:leaves1:5)
Block(2,4,1,dynamictrees:leaves1:4)
Block(2,4,2,dynamictrees:leaves1:4)
Block(2,5,-2,dynamictrees:leaves1:4)
Block(2,5,-1,dynamictrees:leaves1:5)
Block(2,5,0,dynamictrees:leaves1:7)
Block(2,5,1,dynamictrees:leaves1:6)
Block(2,5,2,dynamictrees:leaves1:5)
Block(2,5,3,dynamictrees:leaves1:4)
Block(2,6,-1,dynamictrees:leaves1:4)
Block(2,6,0,dynamictrees:leaves1:5)
Block(2,6,1,dynamictrees:leaves1:5)
Block(2,6,2,dynamictrees:leaves1:4)
Block(2,7,0,dynamictrees:leaves1:4)
Block(2,7,1,dynamictrees:leaves1:4)
Block(3,3,-1,dynamictrees:leaves1:4)
Block(3,3,0,dynamictrees:leaves1:4)
Block(3,3,1,dynamictrees:leaves1:4)
Block(3,4,-2,dynamictrees:leaves1:4)
Block(3,4,-1,dynamictrees:leaves1:4)
Block(3,4,0,dynamictrees:leaves1:4)
Block(3,4,1,dynamictrees:leaves1:4)
Block(3,5,-1,dynamictrees:leaves1:4)
Block(3,5,0,dynamictrees:leaves1:5)
Block(3,5,1,dynamictrees:leaves1:5)
Block(3,5,2,dynamictrees:leaves1:4)
Block(3,6,0,dynamictrees:leaves1:4)
Block(3,6,1,dynamictrees:leaves1:4)
Block(4,5,0,dynamictrees:leaves1:4)
Block(4,5,1,dynamictrees:leaves1:4)

#######################################################################
# +-----------------------------------------------------------------+ #
# |                            BO3 checks                           | #
# +-----------------------------------------------------------------+ #
#######################################################################

BlockCheck(1,-1,-1,GRASS,DIRT,biomesoplenty:grass,biomesoplenty:dirt)

#######################################################################
# +-----------------------------------------------------------------+ #
# |                             Branches                            | #
# +-----------------------------------------------------------------+ #
#######################################################################


#######################################################################
# +-----------------------------------------------------------------+ #
# |                             Entities                            | #
# +-----------------------------------------------------------------+ #
#######################################################################


#######################################################################
# +-----------------------------------------------------------------+ #
# |                            Particles                            | #
# +-----------------------------------------------------------------+ #
#######################################################################


#######################################################################
# +-----------------------------------------------------------------+ #
# |                             Spawners                            | #
# +-----------------------------------------------------------------+ #
#######################################################################


#######################################################################
# +-----------------------------------------------------------------+ #
# |                             ModData                             | #
# +-----------------------------------------------------------------+ #
#######################################################################

