
#######################################################################
# +-----------------------------------------------------------------+ #
# |                            BO4 object                           | #
# +-----------------------------------------------------------------+ #
#######################################################################

Author: NLBlackEagle

Description: No description given

SettingsMode: WriteDisable


#######################################################################
# +-----------------------------------------------------------------+ #
# |                          Main settings                          | #
# +-----------------------------------------------------------------+ #
#######################################################################

Frequency: 10

SpawnHeight: highestBlock

UseCenterForHighestBlock: true

##############################
# Height Limits for the BO4. #
##############################

MinHeight: 63

MaxHeight: 255

InheritBO3: 

InheritBO3Rotation: NORTH

OverrideChildSettings: true

OverrideParentHeight: false

CanOverride: true

BranchFrequency: 5

BranchFrequencyGroup: 

MustBeBelowOther: false

MustBeInside: 

CannotBeInside: 

ReplacesBO3: 

MustBeInsideWorldBorders: false

CanSpawnOnWater: false

SpawnOnWaterOnly: false

SpawnUnderWater: false

SpawnAtWaterLevel: false

HeightOffset: -1

RemoveAir: false

ReplaceAbove: 

ReplaceBelow: cobblestone

ReplaceWithBiomeBlocks: true

ReplaceWithSurfaceBlock: GRASS

ReplaceWithGroundBlock: DIRT

ReplaceWithStoneBlock: STONE

SmoothRadius: 0

SmoothHeightOffset: 0

SmoothStartTop: false

SmoothStartWood: false

SmoothingSurfaceBlock: 

SmoothingGroundBlock: 

BO3Group: 

IsSpawnPoint: false

DoReplaceBlocks: true


#######################################################################
# +-----------------------------------------------------------------+ #
# |                              Blocks                             | #
# +-----------------------------------------------------------------+ #
#######################################################################

Block(-4,0,-3,DIRT:0)
Block(-4,0,-2,DIRT:0)
Block(-4,0,-1,DIRT:0)
Block(-4,0,0,DIRT:0)
Block(-4,0,1,DIRT:0)
Block(-4,0,2,DIRT:0)
Block(-4,0,3,DIRT:0)
Block(-4,0,4,DIRT:0)
Block(-4,0,5,DIRT:0)
Block(-4,0,6,DIRT:0)
Block(-4,1,-3,GRASS:0)
Block(-4,1,-2,GRASS:0)
Block(-4,1,-1,GRASS:0)
Block(-4,1,0,GRASS:0)
Block(-4,1,1,GRASS:0)
Block(-4,1,2,GRASS:0)
Block(-4,1,3,GRASS:0)
Block(-4,1,4,GRASS:0)
Block(-4,1,5,GRASS:0)
Block(-4,1,6,GRASS:0)
Block(-4,2,-3,SPRUCE_FENCE:0)
Block(-4,2,-2,SPRUCE_FENCE:0)
Block(-4,2,-1,SPRUCE_FENCE:0)
Block(-4,2,0,SPRUCE_FENCE:0)
Block(-4,2,1,SPRUCE_FENCE:0)
Block(-4,2,2,SPRUCE_FENCE:0)
Block(-4,2,3,SPRUCE_FENCE:0)
Block(-4,2,4,SPRUCE_FENCE:0)
Block(-4,2,5,SPRUCE_FENCE:0)
Block(-4,2,6,SPRUCE_FENCE:0)
Block(-3,0,-3,DIRT:0)
Block(-3,0,-2,DIRT:0)
Block(-3,0,-1,DIRT:0)
Block(-3,0,0,DIRT:0)
Block(-3,0,1,DIRT:0)
Block(-3,0,2,DIRT:0)
Block(-3,0,3,DIRT:0)
Block(-3,0,4,DIRT:0)
Block(-3,0,5,DIRT:0)
Block(-3,0,6,DIRT:0)
Block(-3,1,-3,GRASS:0)
Block(-3,1,-2,GRASS_PATH:0)
Block(-3,1,-1,GRASS:0)
Block(-3,1,0,GRASS:0)
Block(-3,1,1,GRASS:0)
Block(-3,1,2,GRASS:0)
Block(-3,1,3,GRASS:0)
Block(-3,1,5,GRASS:0)
Block(-3,1,6,GRASS:0)
Block(-3,2,-3,SPRUCE_FENCE:0)
Block(-3,2,6,SPRUCE_FENCE:0)
Block(-2,0,-3,DIRT:0)
Block(-2,0,-2,DIRT:0)
Block(-2,0,-1,DIRT:0)
Block(-2,0,0,DIRT:0)
Block(-2,0,1,DIRT:0)
Block(-2,0,2,DIRT:0)
Block(-2,0,3,DIRT:0)
Block(-2,0,4,DIRT:0)
Block(-2,0,5,DIRT:0)
Block(-2,0,6,DIRT:0)
Block(-2,1,-3,GRASS:0)
Block(-2,1,-2,GRASS:0)
Block(-2,1,-1,GRASS:0)
Block(-2,1,0,GRASS_PATH:0)
Block(-2,1,1,GRASS:0)
Block(-2,1,2,GRASS:0)
Block(-2,1,3,GRASS:0)
Block(-2,1,5,GRASS_PATH:0)
Block(-2,1,6,GRASS:0)
Block(-2,2,-3,SPRUCE_FENCE:0)
Block(-2,2,6,SPRUCE_FENCE:0)
Block(-1,0,-3,DIRT:0)
Block(-1,0,-2,DIRT:0)
Block(-1,0,-1,DIRT:0)
Block(-1,0,0,DIRT:0)
Block(-1,0,1,DIRT:0)
Block(-1,0,2,DIRT:0)
Block(-1,0,3,DIRT:0)
Block(-1,0,4,DIRT:0)
Block(-1,0,5,DIRT:0)
Block(-1,0,6,DIRT:0)
Block(-1,1,-3,GRASS:0)
Block(-1,1,-2,GRASS:0)
Block(-1,1,-1,GRASS:0)
Block(-1,1,0,GRASS:0)
Block(-1,1,1,GRASS:0)
Block(-1,1,2,GRASS:0)
Block(-1,1,4,GRASS:0)
Block(-1,1,5,GRASS:0)
Block(-1,1,6,GRASS:0)
Block(-1,2,-3,SPRUCE_FENCE:0)
Block(-1,2,3,AIR:0)
Block(-1,2,6,SPRUCE_FENCE:0)
Block(0,0,-3,DIRT:0)
Block(0,0,-2,DIRT:0)
Block(0,0,-1,DIRT:0)
Block(0,0,0,DIRT:0)
Block(0,0,1,DIRT:0)
Block(0,0,2,DIRT:0)
Block(0,0,3,DIRT:0)
Block(0,0,4,DIRT:0)
Block(0,0,5,DIRT:0)
Block(0,0,6,DIRT:0)
Block(0,1,-3,GRASS:0)
Block(0,1,-1,GRASS:0)
Block(0,1,0,GRASS_PATH:0)
Block(0,1,1,GRASS:0)
Block(0,1,2,GRASS:0)
Block(0,1,3,GRASS_PATH:0)
Block(0,1,4,GRASS:0)
Block(0,1,5,GRASS:0)
Block(0,1,6,GRASS:0)
Block(0,2,-3,SPRUCE_FENCE:0)
Block(0,2,-2,AIR:0)
Block(0,2,6,SPRUCE_FENCE:0)
Block(1,0,-3,DIRT:0)
Block(1,0,-2,DIRT:0)
Block(1,0,-1,DIRT:0)
Block(1,0,0,DIRT:0)
Block(1,0,1,DIRT:0)
Block(1,0,2,DIRT:0)
Block(1,0,3,DIRT:0)
Block(1,0,4,DIRT:0)
Block(1,0,5,DIRT:0)
Block(1,0,6,DIRT:0)
Block(1,1,-3,GRASS:0)
Block(1,1,-2,GRASS:0)
Block(1,1,-1,GRASS_PATH:0)
Block(1,1,0,GRASS:0)
Block(1,1,1,GRASS:0)
Block(1,1,2,GRASS:0)
Block(1,1,3,GRASS:0)
Block(1,1,4,GRASS:0)
Block(1,1,5,GRASS:0)
Block(1,1,6,GRASS:0)
Block(1,2,-3,SPRUCE_FENCE:0)
Block(1,2,3,SPRUCE_FENCE:0)
Block(1,2,6,SPRUCE_FENCE:0)
Block(1,3,3,SPRUCE_FENCE:0)
Block(1,3,5,WOOD_DOUBLE_STEP:1)
Block(2,0,-3,DIRT:0)
Block(2,0,-2,DIRT:0)
Block(2,0,-1,DIRT:0)
Block(2,0,0,DIRT:0)
Block(2,0,1,DIRT:0)
Block(2,0,2,DIRT:0)
Block(2,0,3,DIRT:0)
Block(2,0,4,DIRT:0)
Block(2,0,5,DIRT:0)
Block(2,0,6,DIRT:0)
Block(2,1,-3,GRASS:0)
Block(2,1,-2,GRASS:0)
Block(2,1,-1,GRASS:0)
Block(2,1,1,GRASS:0)
Block(2,1,2,GRASS:0)
Block(2,1,3,GRASS:0)
Block(2,1,4,GRASS:0)
Block(2,1,5,GRASS:0)
Block(2,1,6,GRASS:0)
Block(2,2,-3,SPRUCE_FENCE:0)
Block(2,2,6,SPRUCE_FENCE:0)
Block(3,0,-3,DIRT:0)
Block(3,0,-2,DIRT:0)
Block(3,0,-1,DIRT:0)
Block(3,0,0,DIRT:0)
Block(3,0,1,DIRT:0)
Block(3,0,2,DIRT:0)
Block(3,0,3,DIRT:0)
Block(3,0,4,DIRT:0)
Block(3,0,5,DIRT:0)
Block(3,0,6,DIRT:0)
Block(3,1,-3,GRASS:0)
Block(3,1,-2,GRASS:0)
Block(3,1,-1,GRASS_PATH:0)
Block(3,1,0,GRASS:0)
Block(3,1,1,GRASS:0)
Block(3,1,2,GRASS_PATH:0)
Block(3,1,3,GRASS_PATH:0)
Block(3,1,4,GRASS:0)
Block(3,1,5,GRASS:0)
Block(3,1,6,GRASS:0)
Block(3,2,-3,SPRUCE_FENCE:0)
Block(3,2,6,SPRUCE_FENCE:0)
Block(4,0,-3,DIRT:0)
Block(4,0,-2,DIRT:0)
Block(4,0,-1,DIRT:0)
Block(4,0,0,DIRT:0)
Block(4,0,1,DIRT:0)
Block(4,0,2,DIRT:0)
Block(4,0,3,DIRT:0)
Block(4,0,4,DIRT:0)
Block(4,0,5,DIRT:0)
Block(4,0,6,DIRT:0)
Block(4,1,-3,GRASS:0)
Block(4,1,-2,GRASS:0)
Block(4,1,-1,GRASS_PATH:0)
Block(4,1,0,GRASS:0)
Block(4,1,1,GRASS:0)
Block(4,1,2,GRASS:0)
Block(4,1,3,GRASS_PATH:0)
Block(4,1,4,GRASS:0)
Block(4,1,5,GRASS:0)
Block(4,1,6,GRASS:0)
Block(4,2,-3,SPRUCE_FENCE:0)
Block(4,2,6,SPRUCE_FENCE:0)
Block(5,0,-3,DIRT:0)
Block(5,0,-2,DIRT:0)
Block(5,0,-1,DIRT:0)
Block(5,0,0,DIRT:0)
Block(5,0,1,DIRT:0)
Block(5,0,2,DIRT:0)
Block(5,0,3,DIRT:0)
Block(5,0,4,DIRT:0)
Block(5,0,5,DIRT:0)
Block(5,0,6,DIRT:0)
Block(5,1,-3,GRASS:0)
Block(5,1,-2,GRASS:0)
Block(5,1,-1,GRASS:0)
Block(5,1,0,GRASS:0)
Block(5,1,1,GRASS:0)
Block(5,1,2,GRASS:0)
Block(5,1,3,GRASS:0)
Block(5,1,4,GRASS:0)
Block(5,1,5,GRASS:0)
Block(5,1,6,GRASS:0)
Block(5,2,-3,SPRUCE_FENCE:0)
Block(5,2,-2,SPRUCE_FENCE:0)
Block(5,2,-1,SPRUCE_FENCE:0)
Block(5,2,0,SPRUCE_FENCE:0)
Block(5,2,1,SPRUCE_FENCE:0)
Block(5,2,2,SPRUCE_FENCE:0)
Block(5,2,3,SPRUCE_FENCE:0)
Block(5,2,4,SPRUCE_FENCE:0)
Block(5,2,5,SPRUCE_FENCE:0)
Block(5,2,6,SPRUCE_FENCE:0)
Block(5,3,3,SPRUCE_FENCE:0)
Block(5,3,5,WOOD_DOUBLE_STEP:1)


Block(-5,0,-4,COBBLESTONE:0)
Block(-5,0,-3,COBBLESTONE:0)
Block(-5,0,-2,COBBLESTONE:0)
Block(-5,0,-1,COBBLESTONE:0)
Block(-5,0,0,COBBLESTONE:0)
Block(-5,0,1,COBBLESTONE:0)
Block(-5,0,2,COBBLESTONE:0)
Block(-5,0,3,COBBLESTONE:0)
Block(-5,0,4,COBBLESTONE:0)
Block(-5,0,5,COBBLESTONE:0)
Block(-5,0,6,COBBLESTONE:0)
Block(-5,0,7,COBBLESTONE:0)
Block(-4,0,-4,COBBLESTONE:0)
Block(-4,0,7,COBBLESTONE:0)
Block(-3,0,-4,COBBLESTONE:0)
Block(-3,0,7,COBBLESTONE:0)
Block(-3,1,4,COBBLESTONE:0)
Block(-2,0,-4,COBBLESTONE:0)
Block(-2,0,7,COBBLESTONE:0)
Block(-2,1,4,COBBLESTONE:0)
Block(-1,0,-4,COBBLESTONE:0)
Block(-1,0,7,COBBLESTONE:0)
Block(-1,1,3,COBBLESTONE:0)
Block(0,0,-4,COBBLESTONE:0)
Block(0,0,7,COBBLESTONE:0)
Block(0,1,-2,COBBLESTONE:0)
Block(1,0,-4,COBBLESTONE:0)
Block(1,0,7,COBBLESTONE:0)
Block(2,0,-4,COBBLESTONE:0)
Block(2,0,7,COBBLESTONE:0)
Block(2,1,0,COBBLESTONE:0)
Block(3,0,-4,COBBLESTONE:0)
Block(3,0,7,COBBLESTONE:0)
Block(4,0,-4,COBBLESTONE:0)
Block(4,0,7,COBBLESTONE:0)
Block(5,0,-4,COBBLESTONE:0)
Block(5,0,7,COBBLESTONE:0)
Block(6,0,-4,COBBLESTONE:0)
Block(6,0,-3,COBBLESTONE:0)
Block(6,0,-2,COBBLESTONE:0)
Block(6,0,-1,COBBLESTONE:0)
Block(6,0,0,COBBLESTONE:0)
Block(6,0,1,COBBLESTONE:0)
Block(6,0,2,COBBLESTONE:0)
Block(6,0,3,COBBLESTONE:0)
Block(6,0,4,COBBLESTONE:0)
Block(6,0,5,COBBLESTONE:0)
Block(6,0,6,COBBLESTONE:0)
Block(6,0,7,COBBLESTONE:0)

Block(1,3,4,WOOD_STEP:9)
Block(1,3,6,WOOD_STEP:1)
Block(1,4,3,WOOD_STEP:1)
Block(1,4,4,WOOD_STEP:1)
Block(2,3,5,WOOD_STEP:9)
Block(2,3,6,WOOD_STEP:1)
Block(2,4,3,WOOD_STEP:1)
Block(2,4,4,WOOD_STEP:1)
Block(3,3,5,WOOD_STEP:9)
Block(3,3,6,WOOD_STEP:1)
Block(3,4,3,WOOD_STEP:1)
Block(3,4,4,WOOD_STEP:1)
Block(4,3,5,WOOD_STEP:9)
Block(4,3,6,WOOD_STEP:1)
Block(4,4,3,WOOD_STEP:1)
Block(4,4,4,WOOD_STEP:1)
Block(5,3,4,WOOD_STEP:9)
Block(5,3,6,WOOD_STEP:1)
Block(5,4,3,WOOD_STEP:1)
Block(5,4,4,WOOD_STEP:1)


#######################################################################
# +-----------------------------------------------------------------+ #
# |                             Branches                            | #
# +-----------------------------------------------------------------+ #
#######################################################################


#######################################################################
# +-----------------------------------------------------------------+ #
# |                             Entities                            | #
# +-----------------------------------------------------------------+ #
#######################################################################
Entity(-2,2,4,minecraft:sheep,3)
Entity(-1,2,3,minecraft:villager,1,../../NBT/Entities/VikingVillage/villager_farmer.txt)
Entity(2,2,0,minecraft:sheep,3)
#######################################################################
# +-----------------------------------------------------------------+ #
# |                            Particles                            | #
# +-----------------------------------------------------------------+ #
#######################################################################


#######################################################################
# +-----------------------------------------------------------------+ #
# |                             Spawners                            | #
# +-----------------------------------------------------------------+ #
#######################################################################


#######################################################################
# +-----------------------------------------------------------------+ #
# |                             ModData                             | #
# +-----------------------------------------------------------------+ #
#######################################################################

