Author: NLBlackEagle
Description: No description given
SettingsMode: WriteDisable
Frequency: 10
SpawnHeight: highestBlock
UseCenterForHighestBlock: true
MinHeight: 63
MaxHeight: 255
InheritBO3: 
InheritBO3Rotation: NORTH
OverrideChildSettings: true
OverrideParentHeight: false
CanOverride: true
BranchFrequency: 5
BranchFrequencyGroup: 
MustBeBelowOther: false
MustBeInside: 
CannotBeInside: 
ReplacesBO3: 
MustBeInsideWorldBorders: false
CanSpawnOnWater: false
SpawnOnWaterOnly: false
SpawnUnderWater: false
SpawnAtWaterLevel: false
HeightOffset: -2
RemoveAir: false
ReplaceAbove: 
ReplaceBelow: cobblestone
ReplaceWithBiomeBlocks: true
ReplaceWithSurfaceBlock: GRASS
ReplaceWithGroundBlock: DIRT
ReplaceWithStoneBlock: STONE
SmoothRadius: 0
SmoothHeightOffset: 0
SmoothStartTop: false
SmoothStartWood: false
SmoothingSurfaceBlock: 
SmoothingGroundBlock: 
BO3Group: Viking_Housing:1
IsSpawnPoint: false
DoReplaceBlocks: true
Block(-6,3,-3,LEAVES:13)
Block(-6,3,-2,GRASS:0)
Block(-6,3,3,DIRT:2)
Block(-6,3,4,LEAVES:5)
Block(-6,3,5,DIRT:2)
Block(-5,2,-2,HAY_BLOCK:4)
Block(-5,2,0,HAY_BLOCK:0)
Block(-5,2,1,HAY_BLOCK:0)
Block(-5,2,2,HAY_BLOCK:4)
Block(-5,2,3,HAY_BLOCK:4)
Block(-5,2,4,HAY_BLOCK:4)
Block(-5,3,-3,STAINED_CLAY:12)
Block(-5,3,5,STAINED_CLAY:12)
Block(-5,4,-3,DIRT:2)
Block(-5,4,-2,LEAVES:13)
Block(-5,4,2,DIRT:2)
Block(-5,4,3,LEAVES:13)
Block(-5,4,4,DIRT:1)
Block(-4,2,-2,HAY_BLOCK:0)
Block(-4,2,-1,HAY_BLOCK:0)
Block(-4,2,0,CARPET:4)
Block(-4,2,3,HAY_BLOCK:0)
Block(-4,2,4,HAY_BLOCK:4)
Block(-4,3,-3,STAINED_CLAY:12)
Block(-4,3,-2,HAY_BLOCK:0)
Block(-4,3,3,HAY_BLOCK:0)
Block(-4,3,4,HAY_BLOCK:4)
Block(-4,3,5,STAINED_CLAY:12)
Block(-4,4,-3,STAINED_CLAY:12)
RandomBlock(-4,4,0,AIR,70,WALL_BANNER:5,../../NBT/Banners/viking_regular_1.nbt,20,WALL_BANNER:5,../../NBT/Banners/viking_regular_2.nbt,20,WALL_BANNER:5,../../NBT/Banners/viking_regular_3.nbt,20,WALL_BANNER:5,../../NBT/Banners/viking_regular_4.nbt,20,WALL_BANNER:5,../../NBT/Banners/viking_regular_5.nbt,20,WALL_BANNER:5,../../NBT/Banners/viking_regular_6.nbt,20,WALL_BANNER:5,../../NBT/Banners/viking_regular_7.nbt,20,WALL_BANNER:5,../../NBT/Banners/viking_regular_8.nbt,100)
Block(-4,4,5,STAINED_CLAY:12)
Block(-4,5,-3,LEAVES:5)
Block(-4,5,-2,DIRT:1)
Block(-4,5,-1,DIRT:2)
Block(-4,5,1,LEAVES:13)
Block(-4,5,3,DIRT:2)
Block(-4,5,4,LEAVES:13)
Block(-4,5,5,GRASS:0)
Block(-3,1,-1,SMOOTH_STAIRS:1)
Block(-3,1,0,SMOOTH_STAIRS:1)
Block(-3,1,1,SMOOTH_STAIRS:1)
Block(-3,1,2,SMOOTH_STAIRS:1)
Block(-3,1,3,SMOOTH_STAIRS:2)
Block(-3,2,-2,HAY_BLOCK:8)
Block(-3,2,4,HAY_BLOCK:0)
Block(-3,3,-3,STAINED_CLAY:12)
Block(-3,3,-2,HAY_BLOCK:8)
Block(-3,3,5,DARK_OAK_FENCE:0)
Block(-3,4,-3,STAINED_CLAY:0)
RandomBlock(-3,4,4,AIR,70,WALL_BANNER:2,../../NBT/Banners/viking_regular_1.nbt,20,WALL_BANNER:2,../../NBT/Banners/viking_regular_2.nbt,20,WALL_BANNER:2,../../NBT/Banners/viking_regular_3.nbt,20,WALL_BANNER:2,../../NBT/Banners/viking_regular_4.nbt,20,WALL_BANNER:2,../../NBT/Banners/viking_regular_5.nbt,20,WALL_BANNER:2,../../NBT/Banners/viking_regular_6.nbt,20,WALL_BANNER:2,../../NBT/Banners/viking_regular_7.nbt,20,WALL_BANNER:2,../../NBT/Banners/viking_regular_8.nbt,100)
Block(-3,4,5,STAINED_CLAY:12)
Block(-3,5,-3,STAINED_CLAY:12)
Block(-3,5,5,STAINED_CLAY:12)
Block(-3,6,-3,DIRT:1)
Block(-3,6,-2,DIRT:2)
Block(-3,6,0,DIRT:1)
Block(-3,6,1,LEAVES:13)
Block(-3,6,2,GRASS:0)
Block(-3,6,4,DIRT:1)
Block(-3,6,5,LEAVES:13)
Block(-2,1,-1,SMOOTH_STAIRS:3)
Block(-2,1,0,DISPENSER:1)
Block(-2,1,1,SMOOTH_STAIRS:2)
Block(-2,1,2,STEP:0)
Block(-2,1,3,SMOOTH_STAIRS:2)
Block(-2,2,-2,CARPET:4)
Block(-2,2,4,CARPET:4)
Block(-2,3,-3,STAINED_CLAY:0)
Block(-2,3,5,DARK_OAK_FENCE:0)
Block(-2,4,-3,STAINED_CLAY:0)
Block(-2,4,3,IRON_FENCE:0)
RandomBlock(-2,4,4,AIR,70,WALL_BANNER:2,../../NBT/Banners/viking_regular_1.nbt,20,WALL_BANNER:2,../../NBT/Banners/viking_regular_2.nbt,20,WALL_BANNER:2,../../NBT/Banners/viking_regular_3.nbt,20,WALL_BANNER:2,../../NBT/Banners/viking_regular_4.nbt,20,WALL_BANNER:2,../../NBT/Banners/viking_regular_5.nbt,20,WALL_BANNER:2,../../NBT/Banners/viking_regular_6.nbt,20,WALL_BANNER:2,../../NBT/Banners/viking_regular_7.nbt,20,WALL_BANNER:2,../../NBT/Banners/viking_regular_8.nbt,100)
Block(-2,4,5,STAINED_CLAY:0)
Block(-2,5,-3,STAINED_CLAY:0)
RandomBlock(-2,5,-2,AIR,70,WALL_BANNER:3,../../NBT/Banners/viking_regular_1.nbt,20,WALL_BANNER:3,../../NBT/Banners/viking_regular_2.nbt,20,WALL_BANNER:3,../../NBT/Banners/viking_regular_3.nbt,20,WALL_BANNER:3,../../NBT/Banners/viking_regular_4.nbt,20,WALL_BANNER:3,../../NBT/Banners/viking_regular_5.nbt,20,WALL_BANNER:3,../../NBT/Banners/viking_regular_6.nbt,20,WALL_BANNER:3,../../NBT/Banners/viking_regular_7.nbt,20,WALL_BANNER:3,../../NBT/Banners/viking_regular_8.nbt,100)
Block(-2,5,3,IRON_FENCE:0)
RandomBlock(-2,5,4,AIR,70,WALL_BANNER:2,../../NBT/Banners/viking_regular_1.nbt,20,WALL_BANNER:2,../../NBT/Banners/viking_regular_2.nbt,20,WALL_BANNER:2,../../NBT/Banners/viking_regular_3.nbt,20,WALL_BANNER:2,../../NBT/Banners/viking_regular_4.nbt,20,WALL_BANNER:2,../../NBT/Banners/viking_regular_5.nbt,20,WALL_BANNER:2,../../NBT/Banners/viking_regular_6.nbt,20,WALL_BANNER:2,../../NBT/Banners/viking_regular_7.nbt,20,WALL_BANNER:2,../../NBT/Banners/viking_regular_8.nbt,100)
Block(-2,5,5,STAINED_CLAY:0)
Block(-2,6,-3,STAINED_CLAY:12)
Block(-2,6,5,STAINED_CLAY:12)
Block(-2,7,-3,DIRT:1)
Block(-2,7,-2,LEAVES:5)
Block(-2,7,-1,LEAVES:5)
Block(-2,7,0,GRASS:0)
Block(-2,7,2,LEAVES:13)
Block(-2,7,3,DIRT:2)
Block(-2,7,4,DIRT:1)
Block(-2,7,5,DIRT:1)
Block(-1,1,-1,SMOOTH_STAIRS:3)
Block(-1,1,0,SMOOTH_STAIRS:0)
Block(-1,1,1,SMOOTH_STAIRS:2)
Block(-1,1,2,SMOOTH_STAIRS:0)
Block(-1,1,3,SMOOTH_STAIRS:0)
Block(-1,2,-2,CARPET:4)
Block(-1,2,5,LOG:1)
Block(-1,3,-3,STAINED_CLAY:12)
RandomBlock(-1,3,-2,AIR,70,WALL_BANNER:3,../../NBT/Banners/viking_regular_1.nbt,20,WALL_BANNER:3,../../NBT/Banners/viking_regular_2.nbt,20,WALL_BANNER:3,../../NBT/Banners/viking_regular_3.nbt,20,WALL_BANNER:3,../../NBT/Banners/viking_regular_4.nbt,20,WALL_BANNER:3,../../NBT/Banners/viking_regular_5.nbt,20,WALL_BANNER:3,../../NBT/Banners/viking_regular_6.nbt,20,WALL_BANNER:3,../../NBT/Banners/viking_regular_7.nbt,20,WALL_BANNER:3,../../NBT/Banners/viking_regular_8.nbt,100)
Block(-1,3,5,LOG:1)
Block(-1,4,-3,STAINED_CLAY:0)
Block(-1,4,5,LOG:1)
Block(-1,4,6,WOOD_BUTTON:3)
Block(-1,5,-3,STAINED_CLAY:0)
Block(-1,5,-1,IRON_FENCE:0)
Block(-1,5,5,LOG:1)
Block(-1,5,6,WOOD_BUTTON:3)
Block(-1,6,-3,STAINED_CLAY:12)
Block(-1,6,-1,IRON_FENCE:0)
Block(-1,6,5,LOG:1)
Block(-1,6,6,WOOD_BUTTON:3)
Block(-1,7,-3,STAINED_CLAY:12)
Block(-1,7,5,LOG:1)
Block(-1,8,-3,LEAVES:5)
Block(-1,8,-2,DIRT:1)
Block(-1,8,0,GRASS:0)
Block(-1,8,1,LEAVES:13)
Block(-1,8,3,DIRT:2)
Block(0,2,-2,HAY_BLOCK:8)
Block(0,2,-1,CARPET:4)
Block(0,2,0,WOOD_STEP:5)
Block(0,2,1,CARPET:4)
Block(0,2,2,CARPET:4)
Block(0,2,5,SPRUCE_DOOR:1)
Block(0,3,-3,STAINED_CLAY:12)
Block(0,3,-2,HAY_BLOCK:8)
Block(0,3,5,SPRUCE_DOOR:9)
Block(0,4,-3,STAINED_CLAY:12)
Block(0,4,5,STAINED_CLAY:0)
Block(0,5,-3,STAINED_CLAY:12)
RandomBlock(0,5,-2,AIR,70,WALL_BANNER:3,../../NBT/Banners/viking_regular_1.nbt,20,WALL_BANNER:3,../../NBT/Banners/viking_regular_2.nbt,20,WALL_BANNER:3,../../NBT/Banners/viking_regular_3.nbt,20,WALL_BANNER:3,../../NBT/Banners/viking_regular_4.nbt,20,WALL_BANNER:3,../../NBT/Banners/viking_regular_5.nbt,20,WALL_BANNER:3,../../NBT/Banners/viking_regular_6.nbt,20,WALL_BANNER:3,../../NBT/Banners/viking_regular_7.nbt,20,WALL_BANNER:3,../../NBT/Banners/viking_regular_8.nbt,100)
RandomBlock(0,5,4,AIR,70,WALL_BANNER:2,../../NBT/Banners/viking_regular_1.nbt,20,WALL_BANNER:2,../../NBT/Banners/viking_regular_2.nbt,20,WALL_BANNER:2,../../NBT/Banners/viking_regular_3.nbt,20,WALL_BANNER:2,../../NBT/Banners/viking_regular_4.nbt,20,WALL_BANNER:2,../../NBT/Banners/viking_regular_5.nbt,20,WALL_BANNER:2,../../NBT/Banners/viking_regular_6.nbt,20,WALL_BANNER:2,../../NBT/Banners/viking_regular_7.nbt,20,WALL_BANNER:2,../../NBT/Banners/viking_regular_8.nbt,100)
Block(0,5,5,STAINED_CLAY:12)
Block(0,6,-3,STAINED_CLAY:0)
RandomBlock(0,6,-2,AIR,70,WALL_BANNER:3,../../NBT/Banners/viking_regular_1.nbt,20,WALL_BANNER:3,../../NBT/Banners/viking_regular_2.nbt,20,WALL_BANNER:3,../../NBT/Banners/viking_regular_3.nbt,20,WALL_BANNER:3,../../NBT/Banners/viking_regular_4.nbt,20,WALL_BANNER:3,../../NBT/Banners/viking_regular_5.nbt,20,WALL_BANNER:3,../../NBT/Banners/viking_regular_6.nbt,20,WALL_BANNER:3,../../NBT/Banners/viking_regular_7.nbt,20,WALL_BANNER:3,../../NBT/Banners/viking_regular_8.nbt,100)
RandomBlock(0,6,4,AIR,70,WALL_BANNER:2,../../NBT/Banners/viking_regular_1.nbt,20,WALL_BANNER:2,../../NBT/Banners/viking_regular_2.nbt,20,WALL_BANNER:2,../../NBT/Banners/viking_regular_3.nbt,20,WALL_BANNER:2,../../NBT/Banners/viking_regular_4.nbt,20,WALL_BANNER:2,../../NBT/Banners/viking_regular_5.nbt,20,WALL_BANNER:2,../../NBT/Banners/viking_regular_6.nbt,20,WALL_BANNER:2,../../NBT/Banners/viking_regular_7.nbt,20,WALL_BANNER:2,../../NBT/Banners/viking_regular_8.nbt,100)
Block(0,6,5,STAINED_CLAY:12)
Block(0,7,-3,STAINED_CLAY:0)
Block(0,7,-2,AIR:0)
Block(0,7,5,STAINED_CLAY:12)
Block(0,8,-6,WOOD_BUTTON:4)
Block(0,8,-5,LOG:9)
Block(0,8,-4,LOG:9)
Block(0,8,-3,LOG:9)
Block(0,8,-2,LOG:9)
Block(0,8,-1,LOG:9)
Block(0,8,0,LOG:9)
Block(0,8,1,LOG:9)
Block(0,8,2,LOG:9)
Block(0,8,3,LOG:9)
Block(0,8,4,LOG:9)
Block(0,8,5,LOG:9)
Block(0,8,6,LOG:9)
Block(0,8,7,LOG:9)
Block(0,8,8,WOOD_BUTTON:3)
Block(0,9,-3,SPRUCE_FENCE:0)
Block(0,9,-2,SPRUCE_FENCE:0)
Block(0,9,-1,SPRUCE_FENCE:0)
Block(0,9,3,SPRUCE_FENCE:0)
Block(0,9,4,SPRUCE_FENCE:0)
Block(0,9,5,SPRUCE_FENCE:0)
Block(1,2,-2,HAY_BLOCK:8)
Block(1,2,-1,HAY_BLOCK:0)
Block(1,2,0,CARPET:4)
Block(1,2,2,WOOD_STEP:5)
Block(1,2,5,LOG:1)
Block(1,3,-3,STAINED_CLAY:0)
Block(1,3,-2,CARPET:4)
Block(1,3,5,LOG:1)
Block(1,4,-3,STAINED_CLAY:0)
Block(1,4,1,IRON_FENCE:0)
Block(1,4,5,LOG:1)
Block(1,4,6,WOOD_BUTTON:3)
Block(1,5,-3,STAINED_CLAY:12)
RandomBlock(1,5,-2,AIR,70,WALL_BANNER:3,../../NBT/Banners/viking_regular_1.nbt,20,WALL_BANNER:3,../../NBT/Banners/viking_regular_2.nbt,20,WALL_BANNER:3,../../NBT/Banners/viking_regular_3.nbt,20,WALL_BANNER:3,../../NBT/Banners/viking_regular_4.nbt,20,WALL_BANNER:3,../../NBT/Banners/viking_regular_5.nbt,20,WALL_BANNER:3,../../NBT/Banners/viking_regular_6.nbt,20,WALL_BANNER:3,../../NBT/Banners/viking_regular_7.nbt,20,WALL_BANNER:3,../../NBT/Banners/viking_regular_8.nbt,100)
Block(1,5,1,IRON_FENCE:0)
Block(1,5,5,LOG:1)
Block(1,5,6,WOOD_BUTTON:3)
Block(1,6,-3,STAINED_CLAY:12)
Block(1,6,1,IRON_FENCE:0)
Block(1,6,2,AIR:0)
Block(1,6,5,LOG:1)
Block(1,6,6,WOOD_BUTTON:3)
Block(1,7,-3,STAINED_CLAY:12)
Block(1,7,5,LOG:1)
Block(1,8,-2,GRASS:0)
Block(1,8,2,GRASS:0)
Block(1,8,3,DIRT:2)
Block(2,1,-1,SMOOTH_STAIRS:1)
Block(2,1,0,SMOOTH_STAIRS:1)
Block(2,1,1,SMOOTH_STAIRS:3)
Block(2,1,2,SMOOTH_STAIRS:1)
Block(2,1,3,SMOOTH_STAIRS:1)
Block(2,2,-2,HAY_BLOCK:0)
Block(2,2,4,CARPET:4)
Block(2,3,-3,STAINED_CLAY:12)
Block(2,3,-2,CARPET:4)
Block(2,3,5,STAINED_CLAY:12)
Block(2,4,-3,STAINED_CLAY:0)
RandomBlock(2,4,4,AIR,70,WALL_BANNER:2,../../NBT/Banners/viking_regular_1.nbt,20,WALL_BANNER:2,../../NBT/Banners/viking_regular_2.nbt,20,WALL_BANNER:2,../../NBT/Banners/viking_regular_3.nbt,20,WALL_BANNER:2,../../NBT/Banners/viking_regular_4.nbt,20,WALL_BANNER:2,../../NBT/Banners/viking_regular_5.nbt,20,WALL_BANNER:2,../../NBT/Banners/viking_regular_6.nbt,20,WALL_BANNER:2,../../NBT/Banners/viking_regular_7.nbt,20,WALL_BANNER:2,../../NBT/Banners/viking_regular_8.nbt,100)
Block(2,4,5,STAINED_CLAY:12)
Block(2,5,-3,STAINED_CLAY:0)
RandomBlock(2,5,-2,AIR,70,WALL_BANNER:3,../../NBT/Banners/viking_regular_1.nbt,20,WALL_BANNER:3,../../NBT/Banners/viking_regular_2.nbt,20,WALL_BANNER:3,../../NBT/Banners/viking_regular_3.nbt,20,WALL_BANNER:3,../../NBT/Banners/viking_regular_4.nbt,20,WALL_BANNER:3,../../NBT/Banners/viking_regular_5.nbt,20,WALL_BANNER:3,../../NBT/Banners/viking_regular_6.nbt,20,WALL_BANNER:3,../../NBT/Banners/viking_regular_7.nbt,20,WALL_BANNER:3,../../NBT/Banners/viking_regular_8.nbt,100)
Block(2,5,5,STAINED_CLAY:12)
Block(2,6,-3,STAINED_CLAY:0)
Block(2,6,5,STAINED_CLAY:0)
Block(2,7,-3,LEAVES:5)
Block(2,7,-2,LEAVES:5)
Block(2,7,0,DIRT:2)
Block(2,7,1,DIRT:2)
Block(2,7,2,LEAVES:13)
Block(2,7,3,DIRT:2)
Block(2,7,4,LEAVES:13)
Block(2,7,5,DIRT:2)
Block(3,1,-1,SMOOTH_STAIRS:3)
Block(3,1,0,STEP:0)
Block(3,1,1,SMOOTH_STAIRS:3)
Block(3,1,2,DISPENSER:1)
Block(3,1,3,SMOOTH_STAIRS:2)
Block(3,2,-2,HAY_BLOCK:0)
Block(3,2,4,CARPET:4)
Block(3,3,-3,STAINED_CLAY:12)
RandomBlock(3,3,-2,AIR,70,WALL_BANNER:3,../../NBT/Banners/viking_regular_1.nbt,20,WALL_BANNER:3,../../NBT/Banners/viking_regular_2.nbt,20,WALL_BANNER:3,../../NBT/Banners/viking_regular_3.nbt,20,WALL_BANNER:3,../../NBT/Banners/viking_regular_4.nbt,20,WALL_BANNER:3,../../NBT/Banners/viking_regular_5.nbt,20,WALL_BANNER:3,../../NBT/Banners/viking_regular_6.nbt,20,WALL_BANNER:3,../../NBT/Banners/viking_regular_7.nbt,20,WALL_BANNER:3,../../NBT/Banners/viking_regular_8.nbt,100)
Block(3,3,5,DARK_OAK_FENCE:0)
Block(3,4,-3,STAINED_CLAY:12)
RandomBlock(3,4,0,AIR,70,WALL_BANNER:4,../../NBT/Banners/viking_regular_1.nbt,20,WALL_BANNER:4,../../NBT/Banners/viking_regular_2.nbt,20,WALL_BANNER:4,../../NBT/Banners/viking_regular_3.nbt,20,WALL_BANNER:4,../../NBT/Banners/viking_regular_4.nbt,20,WALL_BANNER:4,../../NBT/Banners/viking_regular_5.nbt,20,WALL_BANNER:4,../../NBT/Banners/viking_regular_6.nbt,20,WALL_BANNER:4,../../NBT/Banners/viking_regular_7.nbt,20,WALL_BANNER:4,../../NBT/Banners/viking_regular_8.nbt,100)
RandomBlock(3,4,4,AIR,70,WALL_BANNER:2,../../NBT/Banners/viking_regular_1.nbt,20,WALL_BANNER:2,../../NBT/Banners/viking_regular_2.nbt,20,WALL_BANNER:2,../../NBT/Banners/viking_regular_3.nbt,20,WALL_BANNER:2,../../NBT/Banners/viking_regular_4.nbt,20,WALL_BANNER:2,../../NBT/Banners/viking_regular_5.nbt,20,WALL_BANNER:2,../../NBT/Banners/viking_regular_6.nbt,20,WALL_BANNER:2,../../NBT/Banners/viking_regular_7.nbt,20,WALL_BANNER:2,../../NBT/Banners/viking_regular_8.nbt,100)
Block(3,4,5,STAINED_CLAY:0)
Block(3,5,-3,STAINED_CLAY:12)
Block(3,5,5,STAINED_CLAY:0)
Block(3,6,-3,LEAVES:13)
Block(3,6,-2,GRASS:0)
Block(3,6,-1,DIRT:2)
Block(3,6,0,DIRT:1)
Block(3,6,1,GRASS:0)
Block(3,6,3,DIRT:1)
Block(3,6,5,LEAVES:13)
Block(4,1,-1,SMOOTH_STAIRS:3)
Block(4,1,0,SMOOTH_STAIRS:0)
Block(4,1,1,SMOOTH_STAIRS:0)
Block(4,1,2,SMOOTH_STAIRS:0)
Block(4,1,3,SMOOTH_STAIRS:2)
Block(4,2,-2,HAY_BLOCK:4)
Block(4,2,4,HAY_BLOCK:0)
Block(4,3,-3,STAINED_CLAY:12)
Block(4,3,-2,HAY_BLOCK:4)
Block(4,3,4,CARPET:4)
Block(4,3,5,STAINED_CLAY:12)
Block(4,4,-3,STAINED_CLAY:12)
RandomBlock(4,4,2,AIR,70,WALL_BANNER:4,../../NBT/Banners/viking_regular_1.nbt,20,WALL_BANNER:4,../../NBT/Banners/viking_regular_2.nbt,20,WALL_BANNER:4,../../NBT/Banners/viking_regular_3.nbt,20,WALL_BANNER:4,../../NBT/Banners/viking_regular_4.nbt,20,WALL_BANNER:4,../../NBT/Banners/viking_regular_5.nbt,20,WALL_BANNER:4,../../NBT/Banners/viking_regular_6.nbt,20,WALL_BANNER:4,../../NBT/Banners/viking_regular_7.nbt,20,WALL_BANNER:4,../../NBT/Banners/viking_regular_8.nbt,100)
Block(4,4,5,STAINED_CLAY:12)
Block(4,5,-3,GRASS:0)
Block(4,5,-2,LEAVES:5)
Block(4,5,-1,DIRT:2)
Block(4,5,0,DIRT:2)
Block(4,5,3,DIRT:2)
Block(4,5,4,DIRT:1)
Block(4,5,5,DIRT:2)
Block(5,2,-2,HAY_BLOCK:0)
Block(5,2,-1,HAY_BLOCK:0)
Block(5,2,1,HAY_BLOCK:4)
Block(5,2,2,HAY_BLOCK:4)
Block(5,2,3,HAY_BLOCK:4)
Block(5,2,4,HAY_BLOCK:8)
Block(5,3,-3,STAINED_CLAY:12)
Block(5,3,5,STAINED_CLAY:12)
Block(5,4,-3,LEAVES:13)
Block(5,4,-2,DIRT:1)
Block(5,4,-1,DIRT:1)
Block(5,4,0,GRASS:0)
Block(5,4,4,DIRT:2)
Block(5,4,5,DIRT:1)
Block(6,3,-3,DIRT:1)
Block(6,3,0,LEAVES:5)
Block(6,3,4,LEAVES:5)
Block(6,3,5,GRASS:0)


Block(-6,0,-3,COBBLESTONE:0)
Block(-6,0,-2,COBBLESTONE:0)
Block(-6,0,-1,COBBLESTONE:0)
Block(-6,0,0,COBBLESTONE:0)
Block(-6,0,1,COBBLESTONE:0)
Block(-6,0,2,COBBLESTONE:0)
Block(-6,0,3,COBBLESTONE:0)
Block(-6,0,4,COBBLESTONE:0)
Block(-6,0,5,COBBLESTONE:0)
Block(-6,1,-3,COBBLESTONE:0)
Block(-6,1,-2,COBBLESTONE:0)
Block(-6,1,-1,COBBLESTONE:0)
Block(-6,1,0,COBBLESTONE:0)
Block(-6,1,1,COBBLESTONE:0)
Block(-6,1,2,COBBLESTONE:0)
Block(-6,1,3,COBBLESTONE:0)
Block(-6,1,4,COBBLESTONE:0)
Block(-6,1,5,COBBLESTONE:0)
Block(-6,2,-3,COBBLESTONE:0)
Block(-6,2,-2,COBBLESTONE:0)
Block(-6,2,-1,COBBLESTONE:0)
Block(-6,2,0,COBBLESTONE:0)
Block(-6,2,1,COBBLESTONE:0)
Block(-6,2,2,COBBLESTONE:0)
Block(-6,2,3,COBBLESTONE:0)
Block(-6,2,4,COBBLESTONE:0)
Block(-6,2,5,COBBLESTONE:0)
Block(-6,3,-4,SPRUCE_WOOD_STAIRS:0)
Block(-6,3,-1,SPRUCE_WOOD_STAIRS:0)
Block(-6,3,0,SPRUCE_WOOD_STAIRS:0)
Block(-6,3,1,SPRUCE_WOOD_STAIRS:0)
Block(-6,3,2,SPRUCE_WOOD_STAIRS:0)
Block(-6,3,6,SPRUCE_WOOD_STAIRS:0)
Block(-5,0,-3,COBBLESTONE:0)
Block(-5,0,-2,COBBLESTONE:0)
Block(-5,0,-1,COBBLESTONE:0)
Block(-5,0,0,COBBLESTONE:0)
Block(-5,0,1,COBBLESTONE:0)
Block(-5,0,2,COBBLESTONE:0)
Block(-5,0,3,COBBLESTONE:0)
Block(-5,0,4,COBBLESTONE:0)
Block(-5,0,5,COBBLESTONE:0)
Block(-5,1,-3,COBBLESTONE:0)
Block(-5,1,-2,COBBLESTONE:0)
Block(-5,1,-1,COBBLESTONE:0)
Block(-5,1,0,COBBLESTONE:0)
Block(-5,1,1,COBBLESTONE:0)
Block(-5,1,2,COBBLESTONE:0)
Block(-5,1,3,COBBLESTONE:0)
Block(-5,1,4,COBBLESTONE:0)
Block(-5,1,5,COBBLESTONE:0)
Block(-5,2,-3,COBBLESTONE:0)
Block(-5,2,5,COBBLESTONE:0)
Block(-5,3,-4,SPRUCE_WOOD_STAIRS:5)
Block(-5,3,-2,SPRUCE_WOOD_STAIRS:5)
Block(-5,3,-1,SPRUCE_WOOD_STAIRS:5)
Block(-5,3,0,SPRUCE_WOOD_STAIRS:5)
Block(-5,3,1,SPRUCE_WOOD_STAIRS:5)
Block(-5,3,2,SPRUCE_WOOD_STAIRS:5)
Block(-5,3,3,SPRUCE_WOOD_STAIRS:5)
Block(-5,3,4,SPRUCE_WOOD_STAIRS:5)
Block(-5,3,6,SPRUCE_WOOD_STAIRS:5)
Block(-5,4,-4,SPRUCE_WOOD_STAIRS:0)
Block(-5,4,-1,SPRUCE_WOOD_STAIRS:2)
Block(-5,4,1,SPRUCE_WOOD_STAIRS:3)
Block(-5,4,5,SPRUCE_WOOD_STAIRS:0)
Block(-5,4,6,SPRUCE_WOOD_STAIRS:0)
Block(-4,0,-3,COBBLESTONE:0)
Block(-4,0,-2,COBBLESTONE:0)
Block(-4,0,-1,COBBLESTONE:0)
Block(-4,0,0,COBBLESTONE:0)
Block(-4,0,1,COBBLESTONE:0)
Block(-4,0,2,COBBLESTONE:0)
Block(-4,0,3,COBBLESTONE:0)
Block(-4,0,4,COBBLESTONE:0)
Block(-4,0,5,COBBLESTONE:0)
Block(-4,1,-3,COBBLESTONE:0)
Block(-4,1,-2,COBBLESTONE:0)
Block(-4,1,-1,COBBLESTONE:0)
Block(-4,1,0,COBBLESTONE:0)
Block(-4,1,1,COBBLESTONE:0)
Block(-4,1,2,COBBLESTONE:0)
Block(-4,1,3,COBBLESTONE:0)
Block(-4,1,4,COBBLESTONE:0)
Block(-4,1,5,COBBLESTONE:0)
Block(-4,2,-3,COBBLESTONE:0)
Block(-4,2,5,COBBLESTONE:0)
Block(-4,4,-4,SPRUCE_WOOD_STAIRS:5)
Block(-4,4,-2,SPRUCE_WOOD_STAIRS:5)
Block(-4,4,-1,SPRUCE_WOOD_STAIRS:5)
Block(-4,4,1,SPRUCE_WOOD_STAIRS:5)
Block(-4,4,2,SPRUCE_WOOD_STAIRS:5)
Block(-4,4,3,SPRUCE_WOOD_STAIRS:5)
Block(-4,4,4,SPRUCE_WOOD_STAIRS:5)
Block(-4,4,6,SPRUCE_WOOD_STAIRS:5)
Block(-4,5,-4,SPRUCE_WOOD_STAIRS:0)
Block(-4,5,0,SPRUCE_WOOD_STAIRS:0)
Block(-4,5,2,SPRUCE_WOOD_STAIRS:0)
Block(-4,5,6,SPRUCE_WOOD_STAIRS:0)
Block(-3,0,-3,COBBLESTONE:0)
Block(-3,0,-2,COBBLESTONE:0)
Block(-3,0,-1,COBBLESTONE:0)
Block(-3,0,0,COBBLESTONE:0)
Block(-3,0,1,COBBLESTONE:0)
Block(-3,0,2,COBBLESTONE:0)
Block(-3,0,3,COBBLESTONE:0)
Block(-3,0,4,COBBLESTONE:0)
Block(-3,0,5,COBBLESTONE:0)
Block(-3,1,-3,COBBLESTONE:0)
Block(-3,1,-2,COBBLESTONE:0)
Block(-3,1,4,COBBLESTONE:0)
Block(-3,1,5,COBBLESTONE:0)
Block(-3,2,-3,COBBLESTONE:0)
Block(-3,2,5,COBBLESTONE:0)
Block(-3,5,-4,SPRUCE_WOOD_STAIRS:5)
Block(-3,5,-2,SPRUCE_WOOD_STAIRS:5)
Block(-3,5,-1,SPRUCE_WOOD_STAIRS:5)
Block(-3,5,0,SPRUCE_WOOD_STAIRS:5)
Block(-3,5,1,SPRUCE_WOOD_STAIRS:5)
Block(-3,5,2,SPRUCE_WOOD_STAIRS:5)
Block(-3,5,3,SPRUCE_WOOD_STAIRS:5)
Block(-3,5,4,SPRUCE_WOOD_STAIRS:5)
Block(-3,5,6,SPRUCE_WOOD_STAIRS:5)
Block(-3,6,-4,SPRUCE_WOOD_STAIRS:0)
Block(-3,6,-1,SPRUCE_WOOD_STAIRS:0)
Block(-3,6,3,SPRUCE_WOOD_STAIRS:0)
Block(-3,6,6,SPRUCE_WOOD_STAIRS:0)
Block(-2,0,-3,COBBLESTONE:0)
Block(-2,0,-2,COBBLESTONE:0)
Block(-2,0,-1,COBBLESTONE:0)
Block(-2,0,0,COBBLESTONE:0)
Block(-2,0,1,COBBLESTONE:0)
Block(-2,0,2,COBBLESTONE:0)
Block(-2,0,3,COBBLESTONE:0)
Block(-2,0,4,COBBLESTONE:0)
Block(-2,0,5,COBBLESTONE:0)
Block(-2,1,-3,COBBLESTONE:0)
Block(-2,1,-2,COBBLESTONE:0)
Block(-2,1,4,COBBLESTONE:0)
Block(-2,1,5,COBBLESTONE:0)
Block(-2,2,-3,COBBLESTONE:0)
Block(-2,2,5,COBBLESTONE:0)
Block(-2,6,-4,SPRUCE_WOOD_STAIRS:5)
Block(-2,6,-2,SPRUCE_WOOD_STAIRS:5)
Block(-2,6,-1,SPRUCE_WOOD_STAIRS:5)
Block(-2,6,0,SPRUCE_WOOD_STAIRS:5)
Block(-2,6,1,SPRUCE_WOOD_STAIRS:5)
Block(-2,6,2,SPRUCE_WOOD_STAIRS:5)
Block(-2,6,3,SPRUCE_WOOD_STAIRS:5)
Block(-2,6,4,SPRUCE_WOOD_STAIRS:5)
Block(-2,6,6,SPRUCE_WOOD_STAIRS:5)
Block(-2,7,-4,SPRUCE_WOOD_STAIRS:0)
Block(-2,7,1,SPRUCE_WOOD_STAIRS:0)
Block(-2,7,6,SPRUCE_WOOD_STAIRS:0)
Block(-1,0,-3,COBBLESTONE:0)
Block(-1,0,-2,COBBLESTONE:0)
Block(-1,0,-1,COBBLESTONE:0)
Block(-1,0,0,COBBLESTONE:0)
Block(-1,0,1,COBBLESTONE:0)
Block(-1,0,2,COBBLESTONE:0)
Block(-1,0,3,COBBLESTONE:0)
Block(-1,0,4,COBBLESTONE:0)
Block(-1,0,5,COBBLESTONE:0)
Block(-1,0,6,COBBLESTONE:0)
Block(-1,0,7,COBBLESTONE:0)
Block(-1,0,8,COBBLESTONE:0)
Block(-1,1,-3,COBBLESTONE:0)
Block(-1,1,-2,COBBLESTONE:0)
Block(-1,1,4,COBBLESTONE:0)
Block(-1,1,5,COBBLESTONE:0)
Block(-1,1,6,COBBLESTONE:0)
Block(-1,1,7,COBBLESTONE:0)
Block(-1,1,8,COBBLESTONE:0)
Block(-1,2,-3,COBBLESTONE:0)
Block(-1,2,6,COBBLESTONE:0)
Block(-1,2,7,COBBLESTONE:0)
Block(-1,2,8,COBBLESTONE:0)
Block(-1,7,-4,SPRUCE_WOOD_STAIRS:5)
Block(-1,7,-2,SPRUCE_WOOD_STAIRS:5)
Block(-1,7,-1,SPRUCE_WOOD_STAIRS:5)
Block(-1,7,0,SPRUCE_WOOD_STAIRS:5)
Block(-1,7,1,SPRUCE_WOOD_STAIRS:5)
Block(-1,7,2,SPRUCE_WOOD_STAIRS:5)
Block(-1,7,3,SPRUCE_WOOD_STAIRS:5)
Block(-1,7,4,SPRUCE_WOOD_STAIRS:5)
Block(-1,7,6,SPRUCE_WOOD_STAIRS:5)
Block(-1,8,-4,SPRUCE_WOOD_STAIRS:0)
Block(-1,8,6,SPRUCE_WOOD_STAIRS:0)
Block(-1,9,-4,SPRUCE_WOOD_STAIRS:4)
Block(-1,9,6,SPRUCE_WOOD_STAIRS:4)
Block(0,0,-3,COBBLESTONE:0)
Block(0,0,-2,COBBLESTONE:0)
Block(0,0,-1,COBBLESTONE:0)
Block(0,0,0,COBBLESTONE:0)
Block(0,0,1,COBBLESTONE:0)
Block(0,0,2,COBBLESTONE:0)
Block(0,0,3,COBBLESTONE:0)
Block(0,0,4,COBBLESTONE:0)
Block(0,0,5,COBBLESTONE:0)
Block(0,0,6,COBBLESTONE:0)
Block(0,0,7,COBBLESTONE:0)
Block(0,0,8,COBBLESTONE:0)
Block(0,1,-3,COBBLESTONE:0)
Block(0,1,-2,COBBLESTONE:0)
Block(0,1,-1,COBBLESTONE:0)
Block(0,1,0,COBBLESTONE:0)
Block(0,1,1,COBBLESTONE:0)
Block(0,1,2,COBBLESTONE:0)
Block(0,1,3,COBBLESTONE:0)
Block(0,1,4,COBBLESTONE:0)
Block(0,1,5,COBBLESTONE:0)
Block(0,1,6,COBBLESTONE:0)
Block(0,1,7,COBBLESTONE:0)
Block(0,1,8,COBBLESTONE:0)
Block(0,2,-3,COBBLESTONE:0)
Block(0,2,7,COBBLESTONE_STAIRS:2)
Block(0,2,8,COBBLESTONE:0)
Block(1,0,-3,COBBLESTONE:0)
Block(1,0,-2,COBBLESTONE:0)
Block(1,0,-1,COBBLESTONE:0)
Block(1,0,0,COBBLESTONE:0)
Block(1,0,1,COBBLESTONE:0)
Block(1,0,2,COBBLESTONE:0)
Block(1,0,3,COBBLESTONE:0)
Block(1,0,4,COBBLESTONE:0)
Block(1,0,5,COBBLESTONE:0)
Block(1,0,6,COBBLESTONE:0)
Block(1,0,7,COBBLESTONE:0)
Block(1,0,8,COBBLESTONE:0)
Block(1,1,-3,COBBLESTONE:0)
Block(1,1,-2,COBBLESTONE:0)
Block(1,1,-1,COBBLESTONE:0)
Block(1,1,0,COBBLESTONE:0)
Block(1,1,1,COBBLESTONE:0)
Block(1,1,2,COBBLESTONE:0)
Block(1,1,3,COBBLESTONE:0)
Block(1,1,4,COBBLESTONE:0)
Block(1,1,5,COBBLESTONE:0)
Block(1,1,6,COBBLESTONE:0)
Block(1,1,7,COBBLESTONE:0)
Block(1,1,8,COBBLESTONE:0)
Block(1,2,-3,COBBLESTONE:0)
Block(1,2,6,COBBLESTONE:0)
Block(1,2,7,COBBLESTONE:0)
Block(1,2,8,COBBLESTONE:0)
Block(1,7,-4,SPRUCE_WOOD_STAIRS:4)
Block(1,7,-2,SPRUCE_WOOD_STAIRS:4)
Block(1,7,-1,SPRUCE_WOOD_STAIRS:4)
Block(1,7,0,SPRUCE_WOOD_STAIRS:4)
Block(1,7,1,SPRUCE_WOOD_STAIRS:4)
Block(1,7,2,SPRUCE_WOOD_STAIRS:4)
Block(1,7,3,SPRUCE_WOOD_STAIRS:4)
Block(1,7,4,SPRUCE_WOOD_STAIRS:4)
Block(1,7,6,SPRUCE_WOOD_STAIRS:4)
Block(1,8,-4,SPRUCE_WOOD_STAIRS:1)
Block(1,8,6,SPRUCE_WOOD_STAIRS:1)
Block(1,9,-4,SPRUCE_WOOD_STAIRS:5)
Block(1,9,6,SPRUCE_WOOD_STAIRS:5)
Block(2,0,-3,COBBLESTONE:0)
Block(2,0,-2,COBBLESTONE:0)
Block(2,0,-1,COBBLESTONE:0)
Block(2,0,0,COBBLESTONE:0)
Block(2,0,1,COBBLESTONE:0)
Block(2,0,2,COBBLESTONE:0)
Block(2,0,3,COBBLESTONE:0)
Block(2,0,4,COBBLESTONE:0)
Block(2,0,5,COBBLESTONE:0)
Block(2,1,-3,COBBLESTONE:0)
Block(2,1,-2,COBBLESTONE:0)
Block(2,1,4,COBBLESTONE:0)
Block(2,1,5,COBBLESTONE:0)
Block(2,2,-3,COBBLESTONE:0)
Block(2,2,5,COBBLESTONE:0)
Block(2,6,-4,SPRUCE_WOOD_STAIRS:4)
Block(2,6,-2,SPRUCE_WOOD_STAIRS:4)
Block(2,6,-1,SPRUCE_WOOD_STAIRS:4)
Block(2,6,0,SPRUCE_WOOD_STAIRS:4)
Block(2,6,1,SPRUCE_WOOD_STAIRS:4)
Block(2,6,2,SPRUCE_WOOD_STAIRS:4)
Block(2,6,3,SPRUCE_WOOD_STAIRS:4)
Block(2,6,4,SPRUCE_WOOD_STAIRS:4)
Block(2,6,6,SPRUCE_WOOD_STAIRS:4)
Block(2,7,-4,SPRUCE_WOOD_STAIRS:1)
Block(2,7,-1,SPRUCE_WOOD_STAIRS:1)
Block(2,7,6,SPRUCE_WOOD_STAIRS:1)
Block(3,0,-3,COBBLESTONE:0)
Block(3,0,-2,COBBLESTONE:0)
Block(3,0,-1,COBBLESTONE:0)
Block(3,0,0,COBBLESTONE:0)
Block(3,0,1,COBBLESTONE:0)
Block(3,0,2,COBBLESTONE:0)
Block(3,0,3,COBBLESTONE:0)
Block(3,0,4,COBBLESTONE:0)
Block(3,0,5,COBBLESTONE:0)
Block(3,1,-3,COBBLESTONE:0)
Block(3,1,-2,COBBLESTONE:0)
Block(3,1,4,COBBLESTONE:0)
Block(3,1,5,COBBLESTONE:0)
Block(3,2,-3,COBBLESTONE:0)
Block(3,2,5,COBBLESTONE:0)
Block(3,5,-4,SPRUCE_WOOD_STAIRS:4)
Block(3,5,-2,SPRUCE_WOOD_STAIRS:4)
Block(3,5,-1,SPRUCE_WOOD_STAIRS:4)
Block(3,5,0,SPRUCE_WOOD_STAIRS:4)
Block(3,5,1,SPRUCE_WOOD_STAIRS:4)
Block(3,5,2,SPRUCE_WOOD_STAIRS:4)
Block(3,5,3,SPRUCE_WOOD_STAIRS:4)
Block(3,5,4,SPRUCE_WOOD_STAIRS:4)
Block(3,5,6,SPRUCE_WOOD_STAIRS:4)
Block(3,6,-4,SPRUCE_WOOD_STAIRS:1)
Block(3,6,2,SPRUCE_WOOD_STAIRS:1)
Block(3,6,4,SPRUCE_WOOD_STAIRS:1)
Block(3,6,6,SPRUCE_WOOD_STAIRS:1)
Block(4,0,-3,COBBLESTONE:0)
Block(4,0,-2,COBBLESTONE:0)
Block(4,0,-1,COBBLESTONE:0)
Block(4,0,0,COBBLESTONE:0)
Block(4,0,1,COBBLESTONE:0)
Block(4,0,2,COBBLESTONE:0)
Block(4,0,3,COBBLESTONE:0)
Block(4,0,4,COBBLESTONE:0)
Block(4,0,5,COBBLESTONE:0)
Block(4,1,-3,COBBLESTONE:0)
Block(4,1,-2,COBBLESTONE:0)
Block(4,1,4,COBBLESTONE:0)
Block(4,1,5,COBBLESTONE:0)
Block(4,2,-3,COBBLESTONE:0)
Block(4,2,5,COBBLESTONE:0)
Block(4,4,-4,SPRUCE_WOOD_STAIRS:4)
Block(4,4,-2,SPRUCE_WOOD_STAIRS:4)
Block(4,4,-1,SPRUCE_WOOD_STAIRS:4)
Block(4,4,0,SPRUCE_WOOD_STAIRS:4)
Block(4,4,1,SPRUCE_WOOD_STAIRS:4)
Block(4,4,3,SPRUCE_WOOD_STAIRS:4)
Block(4,4,4,SPRUCE_WOOD_STAIRS:4)
Block(4,4,6,SPRUCE_WOOD_STAIRS:4)
Block(4,5,-4,SPRUCE_WOOD_STAIRS:1)
Block(4,5,1,SPRUCE_WOOD_STAIRS:1)
Block(4,5,2,SPRUCE_WOOD_STAIRS:1)
Block(4,5,6,SPRUCE_WOOD_STAIRS:1)
Block(5,0,-3,COBBLESTONE:0)
Block(5,0,-2,COBBLESTONE:0)
Block(5,0,-1,COBBLESTONE:0)
Block(5,0,0,COBBLESTONE:0)
Block(5,0,1,COBBLESTONE:0)
Block(5,0,2,COBBLESTONE:0)
Block(5,0,3,COBBLESTONE:0)
Block(5,0,4,COBBLESTONE:0)
Block(5,0,5,COBBLESTONE:0)
Block(5,1,-3,COBBLESTONE:0)
Block(5,1,-2,COBBLESTONE:0)
Block(5,1,-1,COBBLESTONE:0)
Block(5,1,0,COBBLESTONE:0)
Block(5,1,1,COBBLESTONE:0)
Block(5,1,2,COBBLESTONE:0)
Block(5,1,3,COBBLESTONE:0)
Block(5,1,4,COBBLESTONE:0)
Block(5,1,5,COBBLESTONE:0)
Block(5,2,-3,COBBLESTONE:0)
Block(5,2,5,COBBLESTONE:0)
Block(5,3,-4,SPRUCE_WOOD_STAIRS:4)
Block(5,3,-2,SPRUCE_WOOD_STAIRS:4)
Block(5,3,-1,SPRUCE_WOOD_STAIRS:4)
Block(5,3,0,SPRUCE_WOOD_STAIRS:4)
Block(5,3,1,SPRUCE_WOOD_STAIRS:4)
Block(5,3,2,SPRUCE_WOOD_STAIRS:4)
Block(5,3,3,SPRUCE_WOOD_STAIRS:4)
Block(5,3,4,SPRUCE_WOOD_STAIRS:4)
Block(5,3,6,SPRUCE_WOOD_STAIRS:4)
Block(5,4,-4,SPRUCE_WOOD_STAIRS:1)
Block(5,4,1,SPRUCE_WOOD_STAIRS:2)
Block(5,4,3,SPRUCE_WOOD_STAIRS:3)
Block(5,4,6,SPRUCE_WOOD_STAIRS:1)
Block(6,0,-3,COBBLESTONE:0)
Block(6,0,-2,COBBLESTONE:0)
Block(6,0,-1,COBBLESTONE:0)
Block(6,0,0,COBBLESTONE:0)
Block(6,0,1,COBBLESTONE:0)
Block(6,0,2,COBBLESTONE:0)
Block(6,0,3,COBBLESTONE:0)
Block(6,0,4,COBBLESTONE:0)
Block(6,0,5,COBBLESTONE:0)
Block(6,1,-3,COBBLESTONE:0)
Block(6,1,-2,COBBLESTONE:0)
Block(6,1,-1,COBBLESTONE:0)
Block(6,1,0,COBBLESTONE:0)
Block(6,1,1,COBBLESTONE:0)
Block(6,1,2,COBBLESTONE:0)
Block(6,1,3,COBBLESTONE:0)
Block(6,1,4,COBBLESTONE:0)
Block(6,1,5,COBBLESTONE:0)
Block(6,2,-3,COBBLESTONE:0)
Block(6,2,-2,COBBLESTONE:0)
Block(6,2,-1,COBBLESTONE:0)
Block(6,2,0,COBBLESTONE:0)
Block(6,2,1,COBBLESTONE:0)
Block(6,2,2,COBBLESTONE:0)
Block(6,2,3,COBBLESTONE:0)
Block(6,2,4,COBBLESTONE:0)
Block(6,2,5,COBBLESTONE:0)
Block(6,3,-4,SPRUCE_WOOD_STAIRS:1)
Block(6,3,-2,SPRUCE_WOOD_STAIRS:1)
Block(6,3,-1,SPRUCE_WOOD_STAIRS:1)
Block(6,3,1,SPRUCE_WOOD_STAIRS:1)
Block(6,3,2,SPRUCE_WOOD_STAIRS:1)
Block(6,3,3,SPRUCE_WOOD_STAIRS:1)
Block(6,3,6,SPRUCE_WOOD_STAIRS:1)

Block(-5,4,0,WOOD_STEP:9)
Block(-5,5,0,WOOD_STEP:1)
Block(-1,8,-1,WOOD_STEP:1)
Block(-1,8,2,WOOD_STEP:1)
Block(-1,8,4,WOOD_STEP:1)
Block(-1,8,5,WOOD_STEP:1)
Block(0,9,-4,WOOD_STEP:1)
Block(0,9,0,WOOD_STEP:1)
Block(0,9,2,WOOD_STEP:1)
Block(0,9,6,WOOD_STEP:1)
Block(1,8,-3,WOOD_STEP:1)
Block(1,8,-1,WOOD_STEP:1)
Block(1,8,0,WOOD_STEP:1)
Block(1,8,1,WOOD_STEP:1)
Block(1,8,4,WOOD_STEP:1)
Block(1,8,5,WOOD_STEP:1)
Block(5,4,2,WOOD_STEP:9)
Block(5,5,2,WOOD_STEP:1)

Entity(1,2,3,minecraft:villager,1)