
#######################################################################
# +-----------------------------------------------------------------+ #
# |                            BO4 object                           | #
# +-----------------------------------------------------------------+ #
#######################################################################

Author: NLBlackEagle

Description: No description given

SettingsMode: WriteDisable


#######################################################################
# +-----------------------------------------------------------------+ #
# |                          Main settings                          | #
# +-----------------------------------------------------------------+ #
#######################################################################

Frequency: 0

SpawnHeight: highestBlock

UseCenterForHighestBlock: true

##############################
# Height Limits for the BO4. #
##############################

MinHeight: 0

MaxHeight: 255

InheritBO3: 

InheritBO3Rotation: NORTH

OverrideChildSettings: true

OverrideParentHeight: false

CanOverride: false

BranchFrequency: 0

BranchFrequencyGroup: 

MustBeBelowOther: false

MustBeInside: 

CannotBeInside: 

ReplacesBO3: 

MustBeInsideWorldBorders: false

CanSpawnOnWater: true

SpawnOnWaterOnly: false

SpawnUnderWater: false

SpawnAtWaterLevel: false

HeightOffset: 0

RemoveAir: true

ReplaceAbove: 

ReplaceBelow: 

ReplaceWithBiomeBlocks: true

ReplaceWithSurfaceBlock: GRASS

ReplaceWithGroundBlock: DIRT

ReplaceWithStoneBlock: STONE

SmoothRadius: 0

SmoothHeightOffset: 0

SmoothStartTop: false

SmoothStartWood: false

SmoothingSurfaceBlock: 

SmoothingGroundBlock: 

BO3Group: 

IsSpawnPoint: false

DoReplaceBlocks: true


#######################################################################
# +-----------------------------------------------------------------+ #
# |                              Blocks                             | #
# +-----------------------------------------------------------------+ #
#######################################################################

Block(-8,-7,-4,LOG:12)
Block(-8,-6,-5,LOG:12)
Block(-8,-6,-4,LOG:12)
Block(-8,-6,-3,LEAVES:4)
Block(-8,-6,-2,LEAVES:4)
Block(-8,-5,-4,LOG:13)
Block(-8,-4,-4,LOG:13)
Block(-8,-4,-3,LOG:13)
Block(-8,-3,-7,LOG:13)
Block(-8,-3,-6,LOG:13)
Block(-8,-3,-5,LOG:13)
Block(-8,-2,-7,LOG:13)
Block(-8,33,-2,LEAVES:4)
Block(-8,33,-1,LEAVES:4)
Block(-8,33,6,LEAVES:4)
Block(-8,33,7,LEAVES:4)
Block(-8,33,8,LEAVES:4)
Block(-8,34,-4,LEAVES:4)
Block(-8,34,-2,LEAVES:4)
Block(-8,34,-1,LEAVES:4)
Block(-8,34,0,LEAVES:4)
Block(-8,34,4,LEAVES:4)
Block(-8,34,6,LEAVES:4)
Block(-8,34,8,LEAVES:4)
Block(-8,35,-5,LEAVES:4)
Block(-8,35,-4,LEAVES:4)
Block(-8,35,-3,LEAVES:4)
Block(-8,35,-2,LEAVES:4)
Block(-8,35,-1,LEAVES:4)
Block(-8,35,0,LEAVES:4)
Block(-8,35,1,LEAVES:4)
Block(-8,35,2,LEAVES:4)
Block(-8,35,5,LEAVES:4)
Block(-8,35,6,LEAVES:4)
Block(-8,35,7,LEAVES:4)
Block(-8,35,8,LEAVES:4)
Block(-8,36,-5,LEAVES:4)
Block(-8,36,-4,LEAVES:4)
Block(-8,36,-3,LEAVES:4)
Block(-8,36,-2,LEAVES:4)
Block(-8,36,-1,LEAVES:4)
Block(-8,36,0,LEAVES:4)
Block(-8,36,1,LEAVES:4)
Block(-8,36,2,LEAVES:4)
Block(-8,36,3,LEAVES:4)
Block(-8,36,4,LEAVES:4)
Block(-8,37,-5,LEAVES:4)
Block(-8,37,-4,LEAVES:4)
Block(-8,37,-3,LEAVES:4)
Block(-8,37,-2,LEAVES:4)
Block(-8,37,-1,LEAVES:4)
Block(-8,37,0,LEAVES:4)
Block(-8,37,1,LEAVES:4)
Block(-8,37,2,LEAVES:4)
Block(-8,37,3,LEAVES:4)
Block(-8,37,4,LEAVES:4)
Block(-8,37,5,LEAVES:4)
Block(-8,38,-7,LEAVES:4)
Block(-8,38,-6,LEAVES:4)
Block(-8,38,-5,LEAVES:4)
Block(-8,38,-4,LEAVES:4)
Block(-8,38,-3,LEAVES:4)
Block(-8,38,-2,LEAVES:4)
Block(-8,38,-1,LEAVES:4)
Block(-8,38,0,LEAVES:4)
Block(-8,38,1,LEAVES:4)
Block(-8,38,2,LEAVES:4)
Block(-8,38,3,LEAVES:4)
Block(-8,38,4,LEAVES:4)
Block(-8,38,5,LEAVES:4)
Block(-8,38,6,LEAVES:4)
Block(-8,39,-7,LEAVES:4)
Block(-8,39,-5,LEAVES:4)
Block(-8,39,-4,LEAVES:4)
Block(-8,39,-3,LEAVES:4)
Block(-8,39,-1,LEAVES:4)
Block(-8,39,1,LEAVES:4)
Block(-8,39,3,LEAVES:4)
Block(-8,39,4,LEAVES:4)
Block(-8,39,5,LEAVES:4)
Block(-8,39,6,LEAVES:4)
Block(-8,40,-7,LEAVES:4)
Block(-8,40,-6,LEAVES:4)
Block(-8,40,-5,LEAVES:4)
Block(-8,40,-4,LEAVES:4)
Block(-8,40,3,LEAVES:4)
Block(-8,40,5,LEAVES:4)
Block(-8,41,-7,LEAVES:4)
Block(-8,41,-6,LEAVES:4)
Block(-8,41,-5,LEAVES:4)
Block(-8,41,-4,LEAVES:4)
Block(-8,41,0,LEAVES:4)
Block(-8,41,3,LEAVES:4)
Block(-8,41,4,LEAVES:4)
Block(-8,41,5,LEAVES:4)
Block(-8,41,6,LEAVES:4)
Block(-8,41,7,LEAVES:4)
Block(-8,42,-6,LEAVES:4)
Block(-8,42,-5,LEAVES:4)
Block(-8,42,-4,LEAVES:4)
Block(-8,42,-3,LEAVES:4)
Block(-8,42,3,LEAVES:4)
Block(-8,42,4,LEAVES:4)
Block(-8,42,5,LEAVES:4)
Block(-8,42,7,LEAVES:4)
Block(-8,42,8,LEAVES:4)
Block(-8,43,-7,LEAVES:4)
Block(-8,43,-6,LEAVES:4)
Block(-8,43,-5,LEAVES:4)
Block(-8,43,-4,LEAVES:4)
Block(-8,43,-3,LEAVES:4)
Block(-8,43,-2,LEAVES:4)
Block(-8,43,-1,LEAVES:4)
Block(-8,43,2,LEAVES:4)
Block(-8,43,3,LEAVES:4)
Block(-8,43,4,LEAVES:4)
Block(-8,43,5,LEAVES:4)
Block(-8,43,6,LEAVES:4)
Block(-8,43,7,LEAVES:4)
Block(-8,43,8,LEAVES:4)
Block(-8,44,-7,LEAVES:4)
Block(-8,44,-6,LEAVES:4)
Block(-8,44,-5,LEAVES:4)
Block(-8,44,-4,LEAVES:4)
Block(-8,44,-3,LEAVES:4)
Block(-8,44,-2,LEAVES:4)
Block(-8,44,-1,LEAVES:4)
Block(-8,44,1,LEAVES:4)
Block(-8,44,2,LEAVES:4)
Block(-8,44,3,LEAVES:4)
Block(-8,44,5,LEAVES:4)
Block(-8,44,7,LEAVES:4)
Block(-8,44,8,LEAVES:4)
Block(-8,45,-7,LEAVES:3)
Block(-8,45,-6,LEAVES:3)
Block(-8,45,-5,LEAVES:3)
Block(-8,45,-4,LEAVES:3)
Block(-8,45,-3,LEAVES:3)
Block(-8,45,-2,LEAVES:3)
Block(-8,45,-1,LEAVES:4)
Block(-8,45,0,LEAVES:4)
Block(-8,45,1,LEAVES:3)
Block(-8,45,2,LEAVES:3)
Block(-8,45,3,LEAVES:3)
Block(-8,45,4,LEAVES:3)
Block(-8,45,5,LEAVES:3)
Block(-8,45,6,LEAVES:4)
Block(-8,45,7,LEAVES:3)
Block(-8,45,8,LEAVES:3)
Block(-8,46,-6,LEAVES:3)
Block(-8,46,-5,LEAVES:3)
Block(-8,46,-4,LEAVES:3)
Block(-8,46,-3,LEAVES:3)
Block(-8,46,-2,LEAVES:3)
Block(-8,46,-1,LEAVES:3)
Block(-8,46,0,LEAVES:3)
Block(-8,46,1,LEAVES:3)
Block(-8,46,2,LEAVES:3)
Block(-8,46,3,LEAVES:3)
Block(-8,46,4,LEAVES:3)
Block(-8,46,5,LEAVES:3)
Block(-8,46,6,LEAVES:3)
Block(-8,46,7,LEAVES:3)
Block(-8,46,8,LEAVES:3)
Block(-8,47,-7,LEAVES:3)
Block(-8,47,-6,LEAVES:3)
Block(-8,47,-5,LEAVES:3)
Block(-8,47,-4,LEAVES:3)
Block(-8,47,-3,LEAVES:3)
Block(-8,47,-2,LEAVES:3)
Block(-8,47,-1,LEAVES:3)
Block(-8,47,0,LEAVES:3)
Block(-8,47,1,LEAVES:3)
Block(-8,47,2,LEAVES:3)
Block(-8,47,3,LEAVES:3)
Block(-8,47,4,LEAVES:3)
Block(-8,47,5,LEAVES:3)
Block(-8,47,6,LEAVES:3)
Block(-8,47,7,LEAVES:3)
Block(-8,47,8,LEAVES:3)
Block(-8,48,-7,LEAVES:3)
Block(-8,48,-6,LEAVES:3)
Block(-8,48,-5,LEAVES:3)
Block(-8,48,-4,LEAVES:3)
Block(-8,48,-3,LEAVES:3)
Block(-8,48,-2,LEAVES:3)
Block(-8,48,-1,LEAVES:3)
Block(-8,48,0,LEAVES:3)
Block(-8,48,1,LEAVES:3)
Block(-8,48,2,LEAVES:3)
Block(-8,48,3,LEAVES:3)
Block(-8,48,4,LEAVES:3)
Block(-8,48,5,LEAVES:3)
Block(-8,48,6,LEAVES:3)
Block(-8,48,7,LEAVES:3)
Block(-8,48,8,LEAVES:3)
Block(-8,49,-7,LEAVES:3)
Block(-8,49,-5,LEAVES:3)
Block(-8,49,-4,LEAVES:3)
Block(-8,49,-3,LEAVES:3)
Block(-8,49,-2,LEAVES:3)
Block(-8,49,-1,LEAVES:3)
Block(-8,49,0,LEAVES:3)
Block(-8,49,1,LEAVES:3)
Block(-8,49,2,LEAVES:3)
Block(-8,49,3,LEAVES:3)
Block(-8,49,4,LEAVES:3)
Block(-8,49,5,LEAVES:3)
Block(-8,49,6,LEAVES:3)
Block(-8,49,7,LEAVES:3)
Block(-8,49,8,LEAVES:3)
Block(-8,50,-4,LEAVES:3)
Block(-8,50,-3,LEAVES:3)
Block(-8,50,-2,LEAVES:3)
Block(-8,50,-1,LEAVES:3)
Block(-8,50,0,LEAVES:3)
Block(-8,50,1,LEAVES:3)
Block(-8,50,2,LEAVES:3)
Block(-8,50,3,LEAVES:3)
Block(-8,50,4,LEAVES:3)
Block(-8,50,5,LEAVES:3)
Block(-8,51,-3,LEAVES:3)
Block(-8,51,-2,LEAVES:3)
Block(-8,51,-1,LEAVES:3)
Block(-8,51,0,LEAVES:3)
Block(-8,51,1,LEAVES:3)
Block(-8,51,2,LEAVES:3)
Block(-8,51,3,LEAVES:3)
Block(-8,51,5,LEAVES:3)
Block(-7,-7,-5,LOG:12)
Block(-7,-7,-4,LOG:12)
Block(-7,-7,-3,LOG:13)
Block(-7,-7,-2,LOG:13)
Block(-7,-6,-6,LOG:12)
Block(-7,-6,-5,LOG:12)
Block(-7,-6,-4,LOG:13)
Block(-7,-6,-3,LOG:13)
Block(-7,-6,-2,LEAVES:4)
Block(-7,-6,-1,LOG:13)
Block(-7,-5,-7,LOG:12)
Block(-7,-5,-6,LOG:12)
Block(-7,-5,-5,LOG:13)
Block(-7,-5,-4,LOG:13)
Block(-7,-5,-3,LOG:13)
Block(-7,-5,-2,LEAVES:4)
Block(-7,-4,-7,LOG:12)
Block(-7,-4,-6,LOG:13)
Block(-7,-4,-5,LOG:13)
Block(-7,-4,-4,LOG:13)
Block(-7,-4,-3,LOG:13)
Block(-7,-4,-2,CONCRETE:15)
Block(-7,-3,-7,LOG:13)
Block(-7,-3,-6,LOG:13)
Block(-7,-3,-5,LOG:13)
Block(-7,-3,-4,CONCRETE:15)
Block(-7,-3,-3,CONCRETE:15)
Block(-7,-2,-7,LOG:13)
Block(-7,-2,-6,LOG:13)
Block(-7,-2,-5,LOG:13)
Block(-7,-1,-7,LOG:13)
Block(-7,34,-1,LEAVES:4)
Block(-7,34,0,LEAVES:4)
Block(-7,35,-4,LEAVES:4)
Block(-7,35,-3,LEAVES:4)
Block(-7,35,0,LEAVES:4)
Block(-7,35,7,LEAVES:4)
Block(-7,36,-4,LEAVES:4)
Block(-7,36,-3,LEAVES:4)
Block(-7,36,-1,LEAVES:4)
Block(-7,36,1,LEAVES:4)
Block(-7,36,7,LEAVES:4)
Block(-7,37,-5,LEAVES:4)
Block(-7,37,-4,LEAVES:4)
Block(-7,37,-3,LEAVES:4)
Block(-7,37,-1,LEAVES:4)
Block(-7,37,0,LEAVES:4)
Block(-7,37,1,LEAVES:4)
Block(-7,37,2,LEAVES:4)
Block(-7,38,-6,LEAVES:4)
Block(-7,38,-5,LEAVES:4)
Block(-7,38,-4,LEAVES:4)
Block(-7,38,-3,LEAVES:4)
Block(-7,38,-2,LEAVES:4)
Block(-7,38,-1,LEAVES:4)
Block(-7,38,0,LEAVES:4)
Block(-7,38,1,LEAVES:4)
Block(-7,38,2,LEAVES:4)
Block(-7,38,3,LEAVES:4)
Block(-7,38,4,LEAVES:4)
Block(-7,38,5,LEAVES:4)
Block(-7,39,-7,LEAVES:4)
Block(-7,39,-6,LEAVES:4)
Block(-7,39,-5,LEAVES:4)
Block(-7,39,-4,LEAVES:4)
Block(-7,39,-3,LEAVES:4)
Block(-7,39,-1,LEAVES:4)
Block(-7,39,0,LEAVES:4)
Block(-7,39,1,LEAVES:4)
Block(-7,39,3,LEAVES:4)
Block(-7,39,4,LEAVES:4)
Block(-7,39,5,LEAVES:4)
Block(-7,40,-7,LEAVES:4)
Block(-7,40,-6,LEAVES:4)
Block(-7,40,-5,LEAVES:4)
Block(-7,40,-4,LEAVES:4)
Block(-7,40,1,LEAVES:4)
Block(-7,40,2,LEAVES:4)
Block(-7,40,3,LEAVES:4)
Block(-7,40,4,LEAVES:4)
Block(-7,40,5,LEAVES:4)
Block(-7,40,6,LEAVES:4)
Block(-7,40,7,LEAVES:4)
Block(-7,41,-6,LEAVES:4)
Block(-7,41,-5,LEAVES:4)
Block(-7,41,0,LEAVES:4)
Block(-7,41,1,LEAVES:4)
Block(-7,41,2,LEAVES:4)
Block(-7,41,4,LEAVES:4)
Block(-7,41,5,LEAVES:4)
Block(-7,41,6,LEAVES:4)
Block(-7,41,7,LEAVES:4)
Block(-7,41,8,LEAVES:4)
Block(-7,42,-6,LEAVES:4)
Block(-7,42,-5,LEAVES:4)
Block(-7,42,4,LEAVES:4)
Block(-7,42,5,LEAVES:4)
Block(-7,42,6,LEAVES:4)
Block(-7,42,7,LEAVES:4)
Block(-7,42,8,LEAVES:4)
Block(-7,43,-7,LEAVES:4)
Block(-7,43,-6,LEAVES:4)
Block(-7,43,-5,LEAVES:4)
Block(-7,43,-4,LEAVES:4)
Block(-7,43,-3,LEAVES:4)
Block(-7,43,2,LEAVES:4)
Block(-7,43,3,LEAVES:4)
Block(-7,43,5,LEAVES:4)
Block(-7,43,6,LEAVES:4)
Block(-7,43,7,LEAVES:4)
Block(-7,43,8,LEAVES:4)
Block(-7,44,-7,LEAVES:4)
Block(-7,44,-6,LEAVES:4)
Block(-7,44,-5,LEAVES:4)
Block(-7,44,-4,LEAVES:4)
Block(-7,44,-3,LEAVES:4)
Block(-7,44,-2,LEAVES:4)
Block(-7,44,-1,LEAVES:4)
Block(-7,44,3,LEAVES:4)
Block(-7,44,5,LEAVES:4)
Block(-7,44,6,LEAVES:4)
Block(-7,44,7,LEAVES:4)
Block(-7,44,8,LEAVES:3)
Block(-7,45,-7,LEAVES:4)
Block(-7,45,-6,LEAVES:4)
Block(-7,45,-5,LEAVES:3)
Block(-7,45,-4,LEAVES:3)
Block(-7,45,-3,LEAVES:3)
Block(-7,45,-2,LEAVES:4)
Block(-7,45,-1,LEAVES:4)
Block(-7,45,0,LEAVES:4)
Block(-7,45,1,LEAVES:3)
Block(-7,45,2,LEAVES:3)
Block(-7,45,5,LEAVES:3)
Block(-7,45,6,LEAVES:3)
Block(-7,45,7,LEAVES:3)
Block(-7,45,8,LEAVES:3)
Block(-7,46,-7,LEAVES:3)
Block(-7,46,-6,LEAVES:3)
Block(-7,46,-5,LEAVES:3)
Block(-7,46,-4,LEAVES:3)
Block(-7,46,-3,LEAVES:3)
Block(-7,46,-2,LEAVES:3)
Block(-7,46,-1,LEAVES:3)
Block(-7,46,0,LEAVES:3)
Block(-7,46,1,LEAVES:3)
Block(-7,46,2,LEAVES:3)
Block(-7,46,3,LEAVES:3)
Block(-7,46,4,LEAVES:3)
Block(-7,46,5,LEAVES:3)
Block(-7,46,6,LEAVES:3)
Block(-7,46,7,LEAVES:3)
Block(-7,46,8,LEAVES:3)
Block(-7,47,-7,LEAVES:3)
Block(-7,47,-6,LEAVES:3)
Block(-7,47,-5,LEAVES:3)
Block(-7,47,-4,LEAVES:3)
Block(-7,47,-3,LEAVES:3)
Block(-7,47,-2,LEAVES:3)
Block(-7,47,-1,LEAVES:3)
Block(-7,47,0,LEAVES:3)
Block(-7,47,1,LEAVES:3)
Block(-7,47,2,LEAVES:3)
Block(-7,47,3,LEAVES:3)
Block(-7,47,4,LEAVES:3)
Block(-7,47,5,LEAVES:3)
Block(-7,47,6,LEAVES:3)
Block(-7,47,7,LEAVES:3)
Block(-7,47,8,LEAVES:3)
Block(-7,48,-7,LEAVES:3)
Block(-7,48,-6,LEAVES:3)
Block(-7,48,-5,LEAVES:3)
Block(-7,48,-4,LEAVES:3)
Block(-7,48,-3,LEAVES:3)
Block(-7,48,-2,LEAVES:3)
Block(-7,48,-1,LEAVES:3)
Block(-7,48,0,LEAVES:3)
Block(-7,48,1,LEAVES:3)
Block(-7,48,2,LEAVES:3)
Block(-7,48,3,LEAVES:3)
Block(-7,48,4,LEAVES:3)
Block(-7,48,5,LEAVES:3)
Block(-7,48,6,LEAVES:3)
Block(-7,48,7,LEAVES:3)
Block(-7,48,8,LEAVES:3)
Block(-7,49,-7,LEAVES:3)
Block(-7,49,-6,LEAVES:3)
Block(-7,49,-5,LEAVES:3)
Block(-7,49,-4,LEAVES:3)
Block(-7,49,-3,LEAVES:3)
Block(-7,49,-2,LEAVES:3)
Block(-7,49,-1,LEAVES:3)
Block(-7,49,0,LEAVES:3)
Block(-7,49,1,LEAVES:3)
Block(-7,49,2,LEAVES:3)
Block(-7,49,3,LEAVES:3)
Block(-7,49,4,LEAVES:3)
Block(-7,49,5,LEAVES:3)
Block(-7,49,6,LEAVES:3)
Block(-7,49,7,LEAVES:3)
Block(-7,49,8,LEAVES:3)
Block(-7,50,-6,LEAVES:3)
Block(-7,50,-5,LEAVES:3)
Block(-7,50,-4,LEAVES:3)
Block(-7,50,-3,LEAVES:3)
Block(-7,50,-2,LEAVES:3)
Block(-7,50,-1,LEAVES:3)
Block(-7,50,1,LEAVES:3)
Block(-7,50,2,LEAVES:3)
Block(-7,50,3,LEAVES:3)
Block(-7,50,4,LEAVES:3)
Block(-7,50,5,LEAVES:3)
Block(-7,50,6,LEAVES:3)
Block(-7,50,7,LEAVES:3)
Block(-7,50,8,LEAVES:3)
Block(-7,51,-1,LEAVES:3)
Block(-7,51,1,LEAVES:3)
Block(-7,51,2,LEAVES:3)
Block(-7,51,4,LEAVES:3)
Block(-7,51,5,LEAVES:3)
Block(-7,52,5,LEAVES:3)
Block(-7,53,5,LEAVES:3)
Block(-7,53,6,LEAVES:3)
Block(-6,-11,1,LOG:13)
Block(-6,-11,2,LOG:13)
Block(-6,-10,0,LOG:13)
Block(-6,-10,1,LOG:13)
Block(-6,-10,2,LOG:13)
Block(-6,-10,3,LOG:13)
Block(-6,-9,-1,LOG:13)
Block(-6,-9,0,LOG:13)
Block(-6,-9,1,LOG:13)
Block(-6,-9,2,LOG:13)
Block(-6,-8,-2,LOG:13)
Block(-6,-8,-1,LOG:13)
Block(-6,-8,0,CONCRETE:15)
Block(-6,-7,-7,LOG:12)
Block(-6,-7,-6,LOG:12)
Block(-6,-7,-5,LOG:12)
Block(-6,-7,-4,LOG:12)
Block(-6,-7,-3,LOG:13)
Block(-6,-7,-2,LOG:13)
Block(-6,-7,-1,CONCRETE:15)
Block(-6,-6,-7,LOG:12)
Block(-6,-6,-6,LOG:12)
Block(-6,-6,-5,LOG:12)
Block(-6,-6,-4,LOG:13)
Block(-6,-6,-3,LOG:13)
Block(-6,-6,-2,LOG:13)
Block(-6,-6,-1,CONCRETE:15)
Block(-6,-5,-7,LOG:12)
Block(-6,-5,-6,LOG:12)
Block(-6,-5,-5,LOG:13)
Block(-6,-5,-4,LOG:13)
Block(-6,-5,-3,LOG:13)
Block(-6,-5,-2,CONCRETE:15)
Block(-6,-5,-1,CONCRETE:15)
Block(-6,-4,-7,LOG:12)
Block(-6,-4,-6,LOG:13)
Block(-6,-4,-5,LOG:13)
Block(-6,-4,-4,LOG:13)
Block(-6,-4,-3,LEAVES:4)
Block(-6,-4,-2,LEAVES:4)
Block(-6,-3,-7,LOG:13)
Block(-6,-3,-6,LOG:13)
Block(-6,-3,-5,LEAVES:4)
Block(-6,-3,-4,LOG:13)
Block(-6,-3,-3,LOG:13)
Block(-6,-2,-7,CONCRETE:15)
Block(-6,-2,-6,LOG:13)
Block(-6,-2,-5,CONCRETE:15)
Block(-6,-1,-7,CONCRETE:15)
Block(-6,35,7,LEAVES:4)
Block(-6,37,1,LEAVES:4)
Block(-6,37,2,LEAVES:4)
Block(-6,38,-6,LEAVES:4)
Block(-6,38,-5,LEAVES:4)
Block(-6,38,-4,LEAVES:4)
Block(-6,38,-1,LEAVES:4)
Block(-6,38,0,LEAVES:4)
Block(-6,38,2,LEAVES:4)
Block(-6,38,8,LEAVES:4)
Block(-6,39,-7,LEAVES:4)
Block(-6,39,-6,LEAVES:4)
Block(-6,39,-5,LEAVES:4)
Block(-6,39,-4,LEAVES:4)
Block(-6,39,2,LEAVES:4)
Block(-6,39,8,LEAVES:4)
Block(-6,40,-6,LEAVES:4)
Block(-6,40,-5,LEAVES:4)
Block(-6,40,-4,LEAVES:4)
Block(-6,40,2,LEAVES:4)
Block(-6,40,3,LEAVES:4)
Block(-6,40,4,LEAVES:4)
Block(-6,40,6,LEAVES:4)
Block(-6,40,7,LEAVES:4)
Block(-6,40,8,LEAVES:4)
Block(-6,41,-7,LEAVES:4)
Block(-6,41,-6,LEAVES:4)
Block(-6,41,-5,LEAVES:4)
Block(-6,41,-4,LEAVES:4)
Block(-6,41,0,LEAVES:4)
Block(-6,41,1,LEAVES:4)
Block(-6,41,2,LEAVES:4)
Block(-6,41,3,LEAVES:4)
Block(-6,41,5,LEAVES:4)
Block(-6,41,6,LEAVES:4)
Block(-6,41,7,LEAVES:4)
Block(-6,41,8,LEAVES:4)
Block(-6,42,-6,LEAVES:4)
Block(-6,42,-5,LEAVES:4)
Block(-6,42,-4,LEAVES:4)
Block(-6,42,1,LEAVES:4)
Block(-6,42,2,LEAVES:4)
Block(-6,42,3,LEAVES:4)
Block(-6,42,4,LEAVES:4)
Block(-6,42,5,LEAVES:4)
Block(-6,42,6,LEAVES:4)
Block(-6,42,7,LEAVES:4)
Block(-6,42,8,LEAVES:4)
Block(-6,43,-7,LEAVES:4)
Block(-6,43,-6,LEAVES:4)
Block(-6,43,-5,LEAVES:4)
Block(-6,43,-4,LEAVES:4)
Block(-6,43,-3,LEAVES:4)
Block(-6,43,2,LEAVES:4)
Block(-6,43,3,LEAVES:4)
Block(-6,43,5,LEAVES:4)
Block(-6,43,6,LEAVES:4)
Block(-6,43,7,LEAVES:4)
Block(-6,43,8,LEAVES:4)
Block(-6,44,-7,LEAVES:4)
Block(-6,44,-6,LEAVES:4)
Block(-6,44,-5,LEAVES:4)
Block(-6,44,-4,LEAVES:4)
Block(-6,44,-3,LEAVES:4)
Block(-6,44,-2,LEAVES:4)
Block(-6,44,3,LEAVES:4)
Block(-6,44,4,LEAVES:4)
Block(-6,44,5,LEAVES:4)
Block(-6,44,6,LEAVES:4)
Block(-6,44,7,LEAVES:3)
Block(-6,44,8,LEAVES:3)
Block(-6,45,-7,LEAVES:4)
Block(-6,45,-6,LEAVES:4)
Block(-6,45,-5,LEAVES:4)
Block(-6,45,-4,LEAVES:4)
Block(-6,45,-3,LEAVES:4)
Block(-6,45,-2,LEAVES:4)
Block(-6,45,0,LEAVES:4)
Block(-6,45,2,LEAVES:3)
Block(-6,45,3,LEAVES:3)
Block(-6,45,4,LEAVES:3)
Block(-6,45,5,LEAVES:3)
Block(-6,45,6,LEAVES:3)
Block(-6,45,7,LEAVES:3)
Block(-6,45,8,LEAVES:3)
Block(-6,46,-7,LEAVES:4)
Block(-6,46,-6,LEAVES:3)
Block(-6,46,-5,LEAVES:3)
Block(-6,46,-4,LEAVES:3)
Block(-6,46,-3,LEAVES:3)
Block(-6,46,-2,LEAVES:3)
Block(-6,46,-1,LEAVES:3)
Block(-6,46,0,LEAVES:3)
Block(-6,46,1,LEAVES:3)
Block(-6,46,2,LEAVES:3)
Block(-6,46,3,LEAVES:3)
Block(-6,46,4,LEAVES:3)
Block(-6,46,5,LEAVES:3)
Block(-6,46,6,LEAVES:3)
Block(-6,46,7,LEAVES:3)
Block(-6,46,8,LEAVES:3)
Block(-6,47,-7,LEAVES:3)
Block(-6,47,-6,LEAVES:3)
Block(-6,47,-5,LEAVES:3)
Block(-6,47,-4,LEAVES:3)
Block(-6,47,-3,LEAVES:3)
Block(-6,47,-2,LEAVES:3)
Block(-6,47,-1,LEAVES:3)
Block(-6,47,0,LEAVES:3)
Block(-6,47,1,LEAVES:3)
Block(-6,47,2,LEAVES:3)
Block(-6,47,3,LEAVES:3)
Block(-6,47,4,LEAVES:3)
Block(-6,47,5,LEAVES:3)
Block(-6,47,6,LEAVES:3)
Block(-6,47,7,LEAVES:3)
Block(-6,47,8,LEAVES:3)
Block(-6,48,-7,LEAVES:3)
Block(-6,48,-6,LEAVES:3)
Block(-6,48,-5,LEAVES:3)
Block(-6,48,-4,LEAVES:3)
Block(-6,48,-3,LEAVES:3)
Block(-6,48,-2,LEAVES:3)
Block(-6,48,-1,LEAVES:3)
Block(-6,48,0,LEAVES:3)
Block(-6,48,1,LEAVES:3)
Block(-6,48,2,LEAVES:3)
Block(-6,48,3,LEAVES:3)
Block(-6,48,4,LEAVES:3)
Block(-6,48,5,LEAVES:3)
Block(-6,48,6,LEAVES:3)
Block(-6,48,7,LEAVES:3)
Block(-6,48,8,LEAVES:3)
Block(-6,49,-7,LEAVES:3)
Block(-6,49,-6,LEAVES:3)
Block(-6,49,-5,LEAVES:3)
Block(-6,49,-4,LEAVES:3)
Block(-6,49,-3,LEAVES:3)
Block(-6,49,-2,LEAVES:3)
Block(-6,49,-1,LEAVES:3)
Block(-6,49,1,LEAVES:3)
Block(-6,49,2,LEAVES:3)
Block(-6,49,3,LEAVES:3)
Block(-6,49,4,LEAVES:3)
Block(-6,49,5,LEAVES:3)
Block(-6,49,6,LEAVES:3)
Block(-6,49,7,LEAVES:3)
Block(-6,49,8,LEAVES:3)
Block(-6,50,-5,LEAVES:3)
Block(-6,50,-4,LEAVES:3)
Block(-6,50,-3,LEAVES:3)
Block(-6,50,-2,LEAVES:3)
Block(-6,50,-1,LEAVES:3)
Block(-6,50,1,LEAVES:3)
Block(-6,50,2,LEAVES:3)
Block(-6,50,3,LEAVES:3)
Block(-6,50,4,LEAVES:3)
Block(-6,50,5,LEAVES:3)
Block(-6,50,6,LEAVES:3)
Block(-6,50,7,LEAVES:3)
Block(-6,50,8,LEAVES:3)
Block(-6,51,2,LEAVES:3)
Block(-6,51,5,LEAVES:3)
Block(-6,51,7,LEAVES:3)
Block(-6,51,8,LEAVES:3)
Block(-6,52,5,LEAVES:3)
Block(-6,52,6,LEAVES:3)
Block(-6,52,7,LEAVES:3)
Block(-5,-12,1,LOG:12)
Block(-5,-11,0,LOG:13)
Block(-5,-11,1,LOG:13)
Block(-5,-11,2,LOG:13)
Block(-5,-11,3,LOG:13)
Block(-5,-10,-1,LOG:13)
Block(-5,-10,0,LOG:13)
Block(-5,-10,1,LOG:13)
Block(-5,-10,2,LOG:13)
Block(-5,-10,3,LOG:13)
Block(-5,-9,-2,LOG:12)
Block(-5,-9,-1,LOG:13)
Block(-5,-9,0,LOG:13)
Block(-5,-9,1,LOG:13)
Block(-5,-9,2,LOG:13)
Block(-5,-9,3,LOG:13)
Block(-5,-8,-7,LOG:12)
Block(-5,-8,-3,LOG:12)
Block(-5,-8,-2,LOG:12)
Block(-5,-8,-1,LOG:13)
Block(-5,-8,0,LOG:13)
Block(-5,-8,1,CONCRETE:15)
Block(-5,-7,-7,LOG:12)
Block(-5,-7,-5,LOG:12)
Block(-5,-7,-4,LOG:12)
Block(-5,-7,-3,LOG:12)
Block(-5,-7,-2,LOG:13)
Block(-5,-7,-1,LOG:13)
Block(-5,-7,0,LOG:13)
Block(-5,-6,-7,LOG:12)
Block(-5,-6,-6,LOG:12)
Block(-5,-6,-5,LOG:12)
Block(-5,-6,-4,LOG:13)
Block(-5,-6,-3,LOG:13)
Block(-5,-6,-2,LOG:13)
Block(-5,-6,-1,LOG:13)
Block(-5,-5,-7,LOG:12)
Block(-5,-5,-6,LOG:12)
Block(-5,-5,-5,LOG:13)
Block(-5,-5,-4,LOG:13)
Block(-5,-5,-3,LOG:13)
Block(-5,-5,-2,LOG:13)
Block(-5,-4,-7,LEAVES:4)
Block(-5,-4,-6,LEAVES:4)
Block(-5,-4,-5,LEAVES:4)
Block(-5,-4,-4,LEAVES:4)
Block(-5,-4,-3,LEAVES:4)
Block(-5,-4,-2,LEAVES:4)
Block(-5,-3,-7,LEAVES:4)
Block(-5,-3,-6,LEAVES:4)
Block(-5,-3,-5,LEAVES:4)
Block(-5,-3,-4,LEAVES:4)
Block(-5,-3,-3,LEAVES:4)
Block(-5,-2,-7,LEAVES:4)
Block(-5,-2,-6,LOG:13)
Block(-5,33,-7,LOG:12)
Block(-5,34,-6,LOG:12)
Block(-5,34,-5,LOG:12)
Block(-5,35,-6,LOG:12)
Block(-5,35,-5,LOG:12)
Block(-5,35,-4,LOG:12)
Block(-5,36,-5,LOG:12)
Block(-5,36,-4,LOG:12)
Block(-5,37,2,LEAVES:4)
Block(-5,38,-6,LEAVES:4)
Block(-5,38,1,LEAVES:4)
Block(-5,38,7,LEAVES:4)
Block(-5,38,8,LEAVES:4)
Block(-5,39,-7,LEAVES:4)
Block(-5,39,-6,LEAVES:4)
Block(-5,39,-5,LEAVES:4)
Block(-5,39,1,LEAVES:4)
Block(-5,39,2,LEAVES:4)
Block(-5,39,3,LEAVES:4)
Block(-5,39,7,LEAVES:4)
Block(-5,39,8,LEAVES:4)
Block(-5,40,0,LEAVES:4)
Block(-5,40,1,LEAVES:4)
Block(-5,40,2,LEAVES:4)
Block(-5,40,3,LEAVES:4)
Block(-5,40,4,LEAVES:4)
Block(-5,40,6,LEAVES:4)
Block(-5,40,7,LEAVES:4)
Block(-5,40,8,LEAVES:4)
Block(-5,41,-6,LEAVES:4)
Block(-5,41,-5,LEAVES:4)
Block(-5,41,-4,LEAVES:4)
Block(-5,41,1,LEAVES:4)
Block(-5,41,2,LEAVES:4)
Block(-5,41,3,LEAVES:4)
Block(-5,41,5,LEAVES:4)
Block(-5,41,6,LEAVES:4)
Block(-5,41,7,LEAVES:4)
Block(-5,41,8,LEAVES:4)
Block(-5,42,-6,LEAVES:4)
Block(-5,42,-5,LEAVES:4)
Block(-5,42,-4,LEAVES:4)
Block(-5,42,0,LEAVES:4)
Block(-5,42,2,LEAVES:4)
Block(-5,42,3,LEAVES:4)
Block(-5,42,4,LEAVES:4)
Block(-5,42,5,LEAVES:4)
Block(-5,42,6,LEAVES:4)
Block(-5,42,7,LEAVES:4)
Block(-5,42,8,LEAVES:4)
Block(-5,43,-7,LEAVES:4)
Block(-5,43,-6,LEAVES:4)
Block(-5,43,-5,LEAVES:4)
Block(-5,43,-4,LEAVES:4)
Block(-5,43,0,LEAVES:4)
Block(-5,43,2,LEAVES:4)
Block(-5,43,3,LEAVES:4)
Block(-5,43,4,LEAVES:4)
Block(-5,43,5,LEAVES:4)
Block(-5,43,6,LEAVES:4)
Block(-5,43,7,LEAVES:3)
Block(-5,43,8,LEAVES:3)
Block(-5,44,-7,LEAVES:4)
Block(-5,44,-6,LEAVES:4)
Block(-5,44,-5,LEAVES:4)
Block(-5,44,-4,LEAVES:4)
Block(-5,44,-3,LEAVES:4)
Block(-5,44,3,LEAVES:4)
Block(-5,44,4,LEAVES:4)
Block(-5,44,6,LEAVES:3)
Block(-5,44,7,LEAVES:3)
Block(-5,44,8,LEAVES:3)
Block(-5,45,-7,LEAVES:4)
Block(-5,45,-6,LEAVES:4)
Block(-5,45,-5,LEAVES:4)
Block(-5,45,-4,LEAVES:4)
Block(-5,45,-3,LEAVES:4)
Block(-5,45,-2,LEAVES:4)
Block(-5,45,2,LEAVES:3)
Block(-5,45,3,LEAVES:3)
Block(-5,45,4,LEAVES:3)
Block(-5,45,5,LEAVES:3)
Block(-5,45,6,LEAVES:3)
Block(-5,45,7,LEAVES:3)
Block(-5,45,8,LEAVES:3)
Block(-5,46,-7,LEAVES:4)
Block(-5,46,-6,LEAVES:4)
Block(-5,46,-5,LEAVES:4)
Block(-5,46,-4,LEAVES:4)
Block(-5,46,-3,LEAVES:4)
Block(-5,46,-2,LEAVES:3)
Block(-5,46,-1,LEAVES:3)
Block(-5,46,1,LEAVES:3)
Block(-5,46,2,LEAVES:3)
Block(-5,46,3,LEAVES:3)
Block(-5,46,4,LEAVES:3)
Block(-5,46,5,LEAVES:3)
Block(-5,46,6,LEAVES:3)
Block(-5,46,7,LEAVES:3)
Block(-5,46,8,LEAVES:3)
Block(-5,47,-7,LEAVES:4)
Block(-5,47,-6,LEAVES:3)
Block(-5,47,-5,LEAVES:3)
Block(-5,47,-4,LEAVES:3)
Block(-5,47,-3,LEAVES:3)
Block(-5,47,-2,LEAVES:3)
Block(-5,47,-1,LEAVES:3)
Block(-5,47,2,LEAVES:3)
Block(-5,47,3,LEAVES:3)
Block(-5,47,4,LEAVES:3)
Block(-5,47,5,LEAVES:3)
Block(-5,47,6,LEAVES:3)
Block(-5,47,7,LEAVES:3)
Block(-5,47,8,LEAVES:3)
Block(-5,48,-7,LEAVES:3)
Block(-5,48,-6,LEAVES:3)
Block(-5,48,-5,LEAVES:3)
Block(-5,48,-4,LEAVES:3)
Block(-5,48,-3,LEAVES:3)
Block(-5,48,-2,LEAVES:3)
Block(-5,48,-1,LEAVES:3)
Block(-5,48,2,LEAVES:3)
Block(-5,48,3,LEAVES:3)
Block(-5,48,4,LEAVES:3)
Block(-5,48,5,LEAVES:3)
Block(-5,48,6,LEAVES:3)
Block(-5,48,7,LEAVES:3)
Block(-5,48,8,LEAVES:3)
Block(-5,49,-7,LEAVES:3)
Block(-5,49,-6,LEAVES:3)
Block(-5,49,-5,LEAVES:3)
Block(-5,49,-4,LEAVES:3)
Block(-5,49,-3,LEAVES:3)
Block(-5,49,-2,LEAVES:3)
Block(-5,49,-1,LEAVES:3)
Block(-5,49,0,LEAVES:3)
Block(-5,49,1,LEAVES:3)
Block(-5,49,2,LEAVES:3)
Block(-5,49,3,LEAVES:3)
Block(-5,49,4,LEAVES:3)
Block(-5,49,5,LEAVES:3)
Block(-5,49,6,LEAVES:3)
Block(-5,49,7,LEAVES:3)
Block(-5,49,8,LEAVES:3)
Block(-5,50,-7,LEAVES:3)
Block(-5,50,-6,LEAVES:3)
Block(-5,50,-5,LEAVES:3)
Block(-5,50,-4,LEAVES:3)
Block(-5,50,-3,LEAVES:3)
Block(-5,50,-2,LEAVES:3)
Block(-5,50,1,LEAVES:3)
Block(-5,50,2,LEAVES:3)
Block(-5,50,3,LEAVES:3)
Block(-5,50,4,LEAVES:3)
Block(-5,50,5,LEAVES:3)
Block(-5,50,6,LEAVES:3)
Block(-5,50,7,LEAVES:3)
Block(-5,50,8,LEAVES:3)
Block(-5,51,-3,LEAVES:3)
Block(-5,51,2,LEAVES:3)
Block(-5,51,3,LEAVES:3)
Block(-5,51,4,LEAVES:3)
Block(-5,51,6,LEAVES:3)
Block(-5,51,7,LEAVES:3)
Block(-5,51,8,LEAVES:3)
Block(-5,52,4,LEAVES:3)
Block(-5,52,5,LEAVES:3)
Block(-5,52,6,LEAVES:3)
Block(-5,52,7,LEAVES:3)
Block(-5,53,7,LEAVES:3)
Block(-5,54,7,LEAVES:3)
Block(-4,-15,3,LOG:13)
Block(-4,-14,2,LOG:13)
Block(-4,-14,3,LOG:13)
Block(-4,-14,4,LOG:13)
Block(-4,-13,1,LOG:13)
Block(-4,-13,2,LOG:13)
Block(-4,-13,3,LOG:13)
Block(-4,-12,0,LOG:12)
Block(-4,-12,1,LOG:13)
Block(-4,-12,2,LOG:13)
Block(-4,-11,0,LOG:12)
Block(-4,-11,1,LOG:13)
Block(-4,-11,2,LOG:13)
Block(-4,-10,0,LOG:13)
Block(-4,-10,1,LOG:13)
Block(-4,-10,2,LOG:13)
Block(-4,-10,3,CONCRETE:15)
Block(-4,-9,-1,LOG:12)
Block(-4,-9,0,LOG:13)
Block(-4,-9,1,LOG:13)
Block(-4,-9,2,CONCRETE:15)
Block(-4,-8,-2,LOG:12)
Block(-4,-8,-1,LOG:12)
Block(-4,-8,0,LOG:13)
Block(-4,-7,-7,LOG:12)
Block(-4,-7,-4,LOG:12)
Block(-4,-7,-3,LOG:12)
Block(-4,-7,-2,LOG:12)
Block(-4,-7,-1,LOG:12)
Block(-4,-6,-5,LOG:12)
Block(-4,-6,-4,LOG:12)
Block(-4,-6,-3,LOG:12)
Block(-4,-6,-2,LOG:12)
Block(-4,-5,-7,LOG:12)
Block(-4,-5,-4,LEAVES:4)
Block(-4,-4,-6,LOG:12)
Block(-4,-4,-5,LEAVES:4)
Block(-4,-4,-4,LEAVES:4)
Block(-4,-4,-3,LOG:13)
Block(-4,-4,-2,LOG:13)
Block(-4,-3,-7,LEAVES:4)
Block(-4,-3,-6,LEAVES:4)
Block(-4,-3,-5,LEAVES:4)
Block(-4,-3,-4,LEAVES:4)
Block(-4,-3,-3,LEAVES:4)
Block(-4,-2,-7,LEAVES:4)
Block(-4,-2,-3,LEAVES:4)
Block(-4,18,-7,LEAVES:4)
Block(-4,32,-7,LOG:12)
Block(-4,32,-6,LOG:12)
Block(-4,33,-7,LOG:12)
Block(-4,33,-6,LOG:12)
Block(-4,34,-7,LOG:12)
Block(-4,34,-6,LOG:12)
Block(-4,34,-5,LOG:12)
Block(-4,35,-7,LOG:12)
Block(-4,35,-6,LOG:12)
Block(-4,35,-5,LOG:12)
Block(-4,35,-4,LOG:12)
Block(-4,35,-3,LOG:12)
Block(-4,36,-6,LOG:12)
Block(-4,36,-5,LOG:12)
Block(-4,36,-4,LOG:12)
Block(-4,36,-3,LOG:12)
Block(-4,36,-2,LOG:12)
Block(-4,36,-1,LOG:12)
Block(-4,37,-7,LEAVES:4)
Block(-4,37,-1,LOG:12)
Block(-4,37,0,LOG:12)
Block(-4,37,3,LEAVES:4)
Block(-4,38,2,LEAVES:4)
Block(-4,38,3,LEAVES:4)
Block(-4,38,7,LEAVES:4)
Block(-4,38,8,LEAVES:4)
Block(-4,39,-7,LEAVES:4)
Block(-4,39,1,LEAVES:4)
Block(-4,39,3,LEAVES:4)
Block(-4,39,6,LEAVES:4)
Block(-4,39,7,LEAVES:4)
Block(-4,39,8,LEAVES:4)
Block(-4,40,1,LEAVES:4)
Block(-4,40,2,LEAVES:4)
Block(-4,40,3,LEAVES:4)
Block(-4,40,4,LEAVES:4)
Block(-4,40,5,LEAVES:4)
Block(-4,40,6,LEAVES:4)
Block(-4,40,7,LEAVES:4)
Block(-4,40,8,LEAVES:4)
Block(-4,41,-6,LEAVES:4)
Block(-4,41,-5,LEAVES:4)
Block(-4,41,0,LEAVES:4)
Block(-4,41,1,LEAVES:4)
Block(-4,41,2,LEAVES:4)
Block(-4,41,3,LEAVES:4)
Block(-4,41,4,LEAVES:4)
Block(-4,41,5,LEAVES:4)
Block(-4,41,6,LEAVES:4)
Block(-4,41,7,LEAVES:4)
Block(-4,41,8,LEAVES:4)
Block(-4,42,-6,LEAVES:4)
Block(-4,42,-5,LEAVES:4)
Block(-4,42,-1,LEAVES:4)
Block(-4,42,0,LEAVES:4)
Block(-4,42,1,LEAVES:4)
Block(-4,42,2,LEAVES:4)
Block(-4,42,3,LEAVES:4)
Block(-4,42,4,LEAVES:4)
Block(-4,42,5,LEAVES:4)
Block(-4,42,6,LEAVES:4)
Block(-4,42,7,LEAVES:4)
Block(-4,42,8,LEAVES:3)
Block(-4,43,-7,LEAVES:4)
Block(-4,43,-6,LEAVES:4)
Block(-4,43,-5,LEAVES:4)
Block(-4,43,-4,LEAVES:4)
Block(-4,43,0,LEAVES:4)
Block(-4,43,1,LEAVES:4)
Block(-4,43,4,LEAVES:4)
Block(-4,43,5,LEAVES:4)
Block(-4,43,6,LEAVES:3)
Block(-4,43,7,LEAVES:3)
Block(-4,43,8,LEAVES:3)
Block(-4,44,-7,LEAVES:4)
Block(-4,44,-6,LEAVES:4)
Block(-4,44,-5,LEAVES:4)
Block(-4,44,-4,LEAVES:4)
Block(-4,44,-3,LEAVES:4)
Block(-4,44,1,LEAVES:4)
Block(-4,44,4,LEAVES:4)
Block(-4,44,6,LEAVES:3)
Block(-4,44,7,LEAVES:3)
Block(-4,44,8,LEAVES:3)
Block(-4,45,-6,LEAVES:4)
Block(-4,45,-5,LEAVES:4)
Block(-4,45,-4,LEAVES:4)
Block(-4,45,-3,LEAVES:4)
Block(-4,45,-2,LEAVES:4)
Block(-4,45,1,LEAVES:4)
Block(-4,45,4,LEAVES:4)
Block(-4,45,5,LEAVES:3)
Block(-4,45,6,LEAVES:3)
Block(-4,45,7,LEAVES:3)
Block(-4,45,8,LEAVES:3)
Block(-4,46,-7,LEAVES:4)
Block(-4,46,-6,LEAVES:4)
Block(-4,46,-5,LEAVES:4)
Block(-4,46,-4,LEAVES:4)
Block(-4,46,-3,LEAVES:4)
Block(-4,46,-2,LEAVES:4)
Block(-4,46,-1,LEAVES:4)
Block(-4,46,6,LEAVES:3)
Block(-4,46,7,LEAVES:3)
Block(-4,46,8,LEAVES:3)
Block(-4,47,-7,LEAVES:4)
Block(-4,47,-6,LEAVES:4)
Block(-4,47,-5,LEAVES:4)
Block(-4,47,-4,LEAVES:4)
Block(-4,47,-3,LEAVES:3)
Block(-4,47,-2,LEAVES:3)
Block(-4,47,2,LEAVES:3)
Block(-4,47,3,LEAVES:3)
Block(-4,47,4,LEAVES:3)
Block(-4,47,5,LEAVES:3)
Block(-4,47,6,LEAVES:3)
Block(-4,47,7,LEAVES:3)
Block(-4,47,8,LEAVES:3)
Block(-4,48,-7,LEAVES:4)
Block(-4,48,-6,LEAVES:4)
Block(-4,48,-5,LEAVES:3)
Block(-4,48,-4,LEAVES:3)
Block(-4,48,-3,LEAVES:3)
Block(-4,48,-2,LEAVES:3)
Block(-4,48,2,LEAVES:3)
Block(-4,48,3,LEAVES:3)
Block(-4,48,4,LEAVES:3)
Block(-4,48,6,LEAVES:3)
Block(-4,48,7,LEAVES:3)
Block(-4,48,8,LEAVES:3)
Block(-4,49,-7,LEAVES:4)
Block(-4,49,-6,LEAVES:3)
Block(-4,49,-5,LEAVES:3)
Block(-4,49,-4,LEAVES:3)
Block(-4,49,-3,LEAVES:3)
Block(-4,49,-2,LEAVES:3)
Block(-4,49,0,LEAVES:3)
Block(-4,49,1,LEAVES:3)
Block(-4,49,2,LEAVES:3)
Block(-4,49,3,LEAVES:3)
Block(-4,49,4,LEAVES:3)
Block(-4,49,7,LEAVES:3)
Block(-4,49,8,LEAVES:3)
Block(-4,50,-7,LEAVES:4)
Block(-4,50,-6,LEAVES:3)
Block(-4,50,-5,LEAVES:3)
Block(-4,50,-4,LEAVES:3)
Block(-4,50,-3,LEAVES:3)
Block(-4,50,-2,LEAVES:3)
Block(-4,50,2,LEAVES:3)
Block(-4,50,3,LEAVES:3)
Block(-4,50,4,LEAVES:3)
Block(-4,51,-7,LEAVES:4)
Block(-4,51,-5,LEAVES:3)
Block(-4,51,-4,LEAVES:3)
Block(-4,51,-3,LEAVES:3)
Block(-4,51,1,LEAVES:3)
Block(-4,51,2,LEAVES:3)
Block(-4,51,3,LEAVES:3)
Block(-4,51,4,LEAVES:3)
Block(-4,51,7,LEAVES:3)
Block(-4,52,3,LEAVES:3)
Block(-4,52,4,LEAVES:3)
Block(-4,52,6,LEAVES:3)
Block(-3,-16,3,LOG:13)
Block(-3,-15,2,LOG:13)
Block(-3,-15,3,LOG:13)
Block(-3,-15,4,LOG:13)
Block(-3,-14,1,LOG:12)
Block(-3,-14,2,LOG:13)
Block(-3,-14,3,LOG:13)
Block(-3,-14,4,LOG:13)
Block(-3,-13,0,LOG:12)
Block(-3,-13,1,LOG:13)
Block(-3,-13,2,LOG:13)
Block(-3,-13,3,LOG:13)
Block(-3,-13,4,LOG:13)
Block(-3,-12,0,LOG:12)
Block(-3,-12,1,LOG:13)
Block(-3,-12,2,LOG:13)
Block(-3,-12,3,CONCRETE:15)
Block(-3,-11,0,LOG:12)
Block(-3,-11,1,LOG:13)
Block(-3,-11,2,LOG:13)
Block(-3,-10,1,LOG:12)
Block(-3,-5,-4,LOG:12)
Block(-3,-3,-7,LEAVES:4)
Block(-3,18,-7,LEAVES:4)
Block(-3,20,3,LEAVES:4)
Block(-3,31,-7,LOG:12)
Block(-3,32,-7,LOG:12)
Block(-3,32,-6,LOG:12)
Block(-3,33,-7,LOG:12)
Block(-3,33,-6,LOG:12)
Block(-3,33,-5,LOG:12)
Block(-3,34,-7,LOG:12)
Block(-3,34,-6,LOG:12)
Block(-3,34,-5,LOG:12)
Block(-3,34,-4,LOG:12)
Block(-3,35,-7,LOG:12)
Block(-3,35,-6,LOG:12)
Block(-3,35,-5,LOG:12)
Block(-3,35,-4,LOG:12)
Block(-3,35,-3,LOG:12)
Block(-3,35,-2,LOG:12)
Block(-3,35,-1,LOG:12)
Block(-3,36,-5,LOG:12)
Block(-3,36,-4,LOG:12)
Block(-3,36,-3,LOG:12)
Block(-3,36,-2,LOG:12)
Block(-3,36,-1,LOG:12)
Block(-3,36,0,LOG:12)
Block(-3,37,-7,LEAVES:4)
Block(-3,37,-4,LOG:12)
Block(-3,37,-3,LOG:12)
Block(-3,37,-2,LOG:12)
Block(-3,37,-1,LOG:12)
Block(-3,37,0,LOG:12)
Block(-3,37,1,LOG:12)
Block(-3,38,-1,LOG:12)
Block(-3,38,0,LOG:12)
Block(-3,38,1,LEAVES:4)
Block(-3,39,-7,LEAVES:4)
Block(-3,39,0,LEAVES:4)
Block(-3,39,1,LEAVES:4)
Block(-3,39,2,LEAVES:4)
Block(-3,39,3,LEAVES:4)
Block(-3,39,4,LEAVES:4)
Block(-3,39,6,LEAVES:4)
Block(-3,39,7,LEAVES:4)
Block(-3,39,8,LEAVES:4)
Block(-3,40,-7,LEAVES:4)
Block(-3,40,-1,LEAVES:4)
Block(-3,40,0,LEAVES:4)
Block(-3,40,1,LEAVES:4)
Block(-3,40,2,LEAVES:4)
Block(-3,40,3,LEAVES:4)
Block(-3,40,4,LEAVES:4)
Block(-3,40,5,LEAVES:4)
Block(-3,40,6,LEAVES:4)
Block(-3,40,7,LEAVES:4)
Block(-3,40,8,LEAVES:4)
Block(-3,41,-7,LEAVES:4)
Block(-3,41,-6,LEAVES:4)
Block(-3,41,0,LEAVES:4)
Block(-3,41,1,LEAVES:4)
Block(-3,41,2,LEAVES:4)
Block(-3,41,3,LEAVES:4)
Block(-3,41,4,LEAVES:4)
Block(-3,41,5,LEAVES:4)
Block(-3,41,6,LEAVES:4)
Block(-3,41,7,LEAVES:4)
Block(-3,41,8,LEAVES:4)
Block(-3,42,-6,LEAVES:4)
Block(-3,42,1,LEAVES:4)
Block(-3,42,2,LEAVES:4)
Block(-3,42,3,LEAVES:4)
Block(-3,42,4,LEAVES:4)
Block(-3,42,5,LEAVES:4)
Block(-3,42,6,LEAVES:4)
Block(-3,42,7,LEAVES:3)
Block(-3,42,8,LEAVES:3)
Block(-3,43,-7,LEAVES:4)
Block(-3,43,-6,LEAVES:4)
Block(-3,43,1,LEAVES:4)
Block(-3,43,2,LEAVES:4)
Block(-3,43,3,LEAVES:4)
Block(-3,43,5,LEAVES:4)
Block(-3,43,6,LEAVES:3)
Block(-3,43,7,LEAVES:3)
Block(-3,43,8,LEAVES:3)
Block(-3,44,-7,LEAVES:4)
Block(-3,44,-6,LEAVES:4)
Block(-3,44,-5,LEAVES:4)
Block(-3,44,4,LEAVES:4)
Block(-3,44,5,LEAVES:3)
Block(-3,44,6,LEAVES:3)
Block(-3,44,7,LEAVES:3)
Block(-3,44,8,LEAVES:3)
Block(-3,45,-4,LEAVES:4)
Block(-3,45,-2,LEAVES:4)
Block(-3,45,5,LEAVES:3)
Block(-3,45,6,LEAVES:3)
Block(-3,45,7,LEAVES:3)
Block(-3,45,8,LEAVES:3)
Block(-3,46,-7,LEAVES:4)
Block(-3,46,-6,LEAVES:4)
Block(-3,46,-5,LEAVES:4)
Block(-3,46,-4,LEAVES:4)
Block(-3,46,-3,LEAVES:4)
Block(-3,46,-2,LEAVES:4)
Block(-3,46,-1,LEAVES:4)
Block(-3,46,0,LEAVES:4)
Block(-3,46,2,LEAVES:4)
Block(-3,46,6,LEAVES:3)
Block(-3,46,7,LEAVES:3)
Block(-3,46,8,LEAVES:3)
Block(-3,47,-7,LEAVES:4)
Block(-3,47,-6,LEAVES:4)
Block(-3,47,-5,LEAVES:4)
Block(-3,47,-4,LEAVES:4)
Block(-3,47,-3,LEAVES:4)
Block(-3,47,-2,LEAVES:4)
Block(-3,47,2,LEAVES:3)
Block(-3,47,3,LEAVES:3)
Block(-3,47,6,LEAVES:3)
Block(-3,47,7,LEAVES:3)
Block(-3,47,8,LEAVES:3)
Block(-3,48,-7,LEAVES:4)
Block(-3,48,-6,LEAVES:4)
Block(-3,48,-5,LEAVES:4)
Block(-3,48,-4,LEAVES:4)
Block(-3,48,-3,LEAVES:3)
Block(-3,48,-2,LEAVES:3)
Block(-3,48,0,LEAVES:3)
Block(-3,48,2,LEAVES:3)
Block(-3,48,3,LEAVES:3)
Block(-3,48,4,LEAVES:3)
Block(-3,48,8,LEAVES:3)
Block(-3,49,-7,LEAVES:4)
Block(-3,49,-6,LEAVES:4)
Block(-3,49,-5,LEAVES:4)
Block(-3,49,-4,LEAVES:3)
Block(-3,49,-3,LEAVES:3)
Block(-3,49,-2,LEAVES:3)
Block(-3,49,0,LEAVES:3)
Block(-3,49,1,LEAVES:3)
Block(-3,49,2,LEAVES:3)
Block(-3,49,3,LEAVES:3)
Block(-3,49,4,LEAVES:3)
Block(-3,50,-7,LEAVES:4)
Block(-3,50,-6,LEAVES:4)
Block(-3,50,-5,LEAVES:4)
Block(-3,50,-4,LEAVES:3)
Block(-3,50,-3,LEAVES:3)
Block(-3,50,-2,LEAVES:3)
Block(-3,50,2,LEAVES:3)
Block(-3,50,3,LEAVES:3)
Block(-3,51,-4,LEAVES:3)
Block(-3,51,-3,LEAVES:3)
Block(-3,51,1,LEAVES:3)
Block(-3,51,2,LEAVES:3)
Block(-3,51,3,LEAVES:3)
Block(-2,-16,2,LOG:12)
Block(-2,-16,3,LOG:13)
Block(-2,-16,4,LOG:13)
Block(-2,-15,2,LOG:13)
Block(-2,-15,3,LOG:13)
Block(-2,-15,4,LOG:13)
Block(-2,-14,2,LOG:13)
Block(-2,-14,3,LOG:13)
Block(-2,-14,4,LOG:13)
Block(-2,-13,1,LOG:13)
Block(-2,-13,2,LOG:13)
Block(-2,-13,3,LOG:13)
Block(-2,-12,0,LOG:12)
Block(-2,-12,1,LOG:13)
Block(-2,-12,2,LOG:13)
Block(-2,-11,1,LOG:13)
Block(-2,17,-7,LEAVES:4)
Block(-2,18,-7,LEAVES:4)
Block(-2,18,4,LEAVES:4)
Block(-2,19,-7,LEAVES:4)
Block(-2,19,3,LEAVES:4)
Block(-2,19,4,LEAVES:4)
Block(-2,20,-7,LEAVES:4)
Block(-2,20,-5,LEAVES:4)
Block(-2,20,3,LEAVES:4)
Block(-2,20,4,LEAVES:4)
Block(-2,21,3,LEAVES:4)
Block(-2,31,-7,LOG:12)
Block(-2,32,-7,LOG:12)
Block(-2,32,-6,LOG:12)
Block(-2,33,-7,LOG:12)
Block(-2,33,-6,LOG:12)
Block(-2,34,-7,LOG:12)
Block(-2,34,-6,LOG:12)
Block(-2,34,-5,LOG:12)
Block(-2,35,-6,LOG:12)
Block(-2,35,-5,LOG:12)
Block(-2,35,-4,LOG:12)
Block(-2,35,-2,LOG:12)
Block(-2,36,-4,LOG:12)
Block(-2,36,-3,LOG:12)
Block(-2,36,-2,LOG:12)
Block(-2,36,-1,LOG:12)
Block(-2,36,0,LOG:12)
Block(-2,36,1,LOG:12)
Block(-2,37,-7,LEAVES:4)
Block(-2,37,-2,LOG:12)
Block(-2,37,-1,LOG:12)
Block(-2,37,0,LOG:12)
Block(-2,37,1,LOG:12)
Block(-2,37,2,LOG:12)
Block(-2,38,-7,LEAVES:4)
Block(-2,38,-1,LEAVES:4)
Block(-2,38,0,LEAVES:4)
Block(-2,38,1,LOG:12)
Block(-2,38,2,LOG:12)
Block(-2,39,-7,LEAVES:4)
Block(-2,39,-3,LEAVES:4)
Block(-2,39,-2,LEAVES:4)
Block(-2,39,-1,LEAVES:4)
Block(-2,39,0,LEAVES:4)
Block(-2,39,5,LEAVES:4)
Block(-2,39,6,LEAVES:4)
Block(-2,39,7,LEAVES:4)
Block(-2,40,-7,LEAVES:4)
Block(-2,40,-6,LEAVES:4)
Block(-2,40,-5,LEAVES:4)
Block(-2,40,-1,LEAVES:4)
Block(-2,40,0,LEAVES:4)
Block(-2,40,1,LEAVES:4)
Block(-2,40,2,LEAVES:4)
Block(-2,40,3,LEAVES:4)
Block(-2,40,4,LEAVES:4)
Block(-2,40,5,LEAVES:4)
Block(-2,40,6,LEAVES:4)
Block(-2,40,7,LEAVES:4)
Block(-2,41,-7,LEAVES:4)
Block(-2,41,-6,LEAVES:4)
Block(-2,41,-5,LEAVES:4)
Block(-2,41,-1,LEAVES:4)
Block(-2,41,0,LEAVES:4)
Block(-2,41,1,LEAVES:4)
Block(-2,41,2,LEAVES:4)
Block(-2,41,3,LEAVES:4)
Block(-2,41,4,LEAVES:4)
Block(-2,41,5,LEAVES:4)
Block(-2,41,6,LEAVES:4)
Block(-2,41,7,LEAVES:4)
Block(-2,41,8,LEAVES:4)
Block(-2,42,-7,LEAVES:4)
Block(-2,42,-6,LEAVES:4)
Block(-2,42,-5,LEAVES:4)
Block(-2,42,-1,LEAVES:4)
Block(-2,42,0,LEAVES:4)
Block(-2,42,1,LEAVES:4)
Block(-2,42,2,LEAVES:4)
Block(-2,42,3,LEAVES:4)
Block(-2,42,4,LEAVES:4)
Block(-2,42,6,LEAVES:4)
Block(-2,42,7,LEAVES:3)
Block(-2,42,8,LEAVES:3)
Block(-2,43,-7,LEAVES:4)
Block(-2,43,-6,LEAVES:4)
Block(-2,43,1,LEAVES:4)
Block(-2,43,2,LEAVES:4)
Block(-2,43,3,LEAVES:4)
Block(-2,43,4,LEAVES:4)
Block(-2,43,6,LEAVES:3)
Block(-2,43,7,LEAVES:3)
Block(-2,43,8,LEAVES:3)
Block(-2,44,-7,LEAVES:4)
Block(-2,44,-6,LEAVES:4)
Block(-2,44,0,LEAVES:4)
Block(-2,44,1,LEAVES:4)
Block(-2,44,3,LEAVES:4)
Block(-2,44,4,LEAVES:4)
Block(-2,44,6,LEAVES:3)
Block(-2,44,7,LEAVES:3)
Block(-2,44,8,LEAVES:3)
Block(-2,45,-6,LEAVES:4)
Block(-2,45,-2,LEAVES:4)
Block(-2,45,1,LEAVES:4)
Block(-2,45,3,LEAVES:4)
Block(-2,45,4,LEAVES:3)
Block(-2,45,5,LEAVES:3)
Block(-2,45,6,LEAVES:3)
Block(-2,45,7,LEAVES:3)
Block(-2,45,8,LEAVES:3)
Block(-2,46,-7,LEAVES:4)
Block(-2,46,-6,LEAVES:4)
Block(-2,46,-5,LEAVES:4)
Block(-2,46,-4,LEAVES:4)
Block(-2,46,-3,LEAVES:4)
Block(-2,46,-1,LEAVES:4)
Block(-2,46,2,LEAVES:4)
Block(-2,46,3,LEAVES:4)
Block(-2,46,6,LEAVES:3)
Block(-2,46,7,LEAVES:3)
Block(-2,46,8,LEAVES:3)
Block(-2,47,-7,LEAVES:4)
Block(-2,47,-6,LEAVES:4)
Block(-2,47,-5,LEAVES:4)
Block(-2,47,-4,LEAVES:4)
Block(-2,47,-3,LEAVES:4)
Block(-2,47,-2,LEAVES:4)
Block(-2,47,-1,LEAVES:4)
Block(-2,47,1,LEAVES:4)
Block(-2,47,2,LEAVES:4)
Block(-2,47,3,LEAVES:4)
Block(-2,47,6,LEAVES:3)
Block(-2,47,7,LEAVES:3)
Block(-2,47,8,LEAVES:3)
Block(-2,48,-7,LEAVES:4)
Block(-2,48,-6,LEAVES:4)
Block(-2,48,-5,LEAVES:4)
Block(-2,48,-4,LEAVES:4)
Block(-2,48,-3,LEAVES:4)
Block(-2,48,-2,LEAVES:4)
Block(-2,48,-1,LEAVES:4)
Block(-2,48,0,LEAVES:4)
Block(-2,48,1,LEAVES:4)
Block(-2,48,2,LEAVES:3)
Block(-2,48,3,LEAVES:3)
Block(-2,48,4,LEAVES:3)
Block(-2,48,7,LEAVES:3)
Block(-2,48,8,LEAVES:3)
Block(-2,49,-7,LEAVES:4)
Block(-2,49,-6,LEAVES:4)
Block(-2,49,-5,LEAVES:4)
Block(-2,49,-4,LEAVES:4)
Block(-2,49,-3,LEAVES:4)
Block(-2,49,-2,LEAVES:3)
Block(-2,49,0,LEAVES:3)
Block(-2,49,2,LEAVES:3)
Block(-2,49,3,LEAVES:3)
Block(-2,49,4,LEAVES:3)
Block(-2,50,-6,LEAVES:4)
Block(-2,50,-5,LEAVES:4)
Block(-2,50,-4,LEAVES:4)
Block(-2,50,-3,LEAVES:3)
Block(-2,51,-5,LEAVES:4)
Block(-2,51,-4,LEAVES:4)
Block(-2,51,-3,LEAVES:3)
Block(-2,52,-2,LEAVES:3)
Block(-1,-16,3,LOG:13)
Block(-1,-15,2,LOG:13)
Block(-1,-15,3,LOG:13)
Block(-1,-15,4,LOG:13)
Block(-1,-14,3,LOG:13)
Block(-1,18,-7,LEAVES:4)
Block(-1,18,3,LEAVES:4)
Block(-1,18,4,LEAVES:4)
Block(-1,19,-7,LEAVES:4)
Block(-1,19,-6,LEAVES:4)
Block(-1,19,-5,LEAVES:4)
Block(-1,19,3,LEAVES:4)
Block(-1,19,4,LEAVES:4)
Block(-1,19,5,LEAVES:4)
Block(-1,20,-7,LEAVES:4)
Block(-1,20,-6,LEAVES:4)
Block(-1,20,-5,LEAVES:4)
Block(-1,20,-4,LEAVES:4)
Block(-1,20,-3,LEAVES:4)
Block(-1,20,-2,LEAVES:4)
Block(-1,20,3,LEAVES:4)
Block(-1,20,4,LEAVES:4)
Block(-1,21,3,LEAVES:4)
Block(-1,34,-6,LOG:12)
Block(-1,36,-7,LEAVES:3)
Block(-1,36,-2,LOG:12)
Block(-1,37,-7,LEAVES:3)
Block(-1,37,0,LEAVES:4)
Block(-1,37,1,LOG:12)
Block(-1,38,-7,LEAVES:3)
Block(-1,38,0,LEAVES:4)
Block(-1,39,-7,LEAVES:3)
Block(-1,39,-6,LEAVES:4)
Block(-1,39,-5,LEAVES:4)
Block(-1,39,-4,LEAVES:4)
Block(-1,39,-1,LEAVES:4)
Block(-1,39,0,LEAVES:4)
Block(-1,39,1,LEAVES:4)
Block(-1,39,2,LEAVES:4)
Block(-1,39,3,LEAVES:4)
Block(-1,39,4,LEAVES:4)
Block(-1,40,-7,LEAVES:4)
Block(-1,40,-6,LEAVES:4)
Block(-1,40,-5,LEAVES:4)
Block(-1,40,-4,LEAVES:4)
Block(-1,40,-3,LEAVES:4)
Block(-1,40,-2,LEAVES:4)
Block(-1,40,-1,LEAVES:4)
Block(-1,40,0,LEAVES:4)
Block(-1,40,1,LEAVES:4)
Block(-1,40,2,LEAVES:4)
Block(-1,40,3,LEAVES:4)
Block(-1,40,4,LEAVES:4)
Block(-1,40,5,LEAVES:4)
Block(-1,40,6,LEAVES:4)
Block(-1,41,-7,LEAVES:4)
Block(-1,41,-6,LEAVES:4)
Block(-1,41,-5,LEAVES:4)
Block(-1,41,-3,LEAVES:4)
Block(-1,41,-1,LEAVES:4)
Block(-1,41,0,LEAVES:4)
Block(-1,41,1,LEAVES:4)
Block(-1,41,2,LEAVES:4)
Block(-1,41,3,LEAVES:4)
Block(-1,41,4,LEAVES:4)
Block(-1,41,5,LEAVES:4)
Block(-1,41,6,LEAVES:4)
Block(-1,41,7,LEAVES:4)
Block(-1,42,-7,LEAVES:4)
Block(-1,42,-6,LEAVES:4)
Block(-1,42,-5,LEAVES:4)
Block(-1,42,0,LEAVES:4)
Block(-1,42,1,LEAVES:4)
Block(-1,42,2,LEAVES:4)
Block(-1,42,3,LEAVES:4)
Block(-1,42,4,LEAVES:4)
Block(-1,42,5,LEAVES:4)
Block(-1,42,7,LEAVES:3)
Block(-1,42,8,LEAVES:3)
Block(-1,43,-7,LEAVES:4)
Block(-1,43,-6,LEAVES:4)
Block(-1,43,-5,LEAVES:4)
Block(-1,43,-3,LEAVES:4)
Block(-1,43,-2,LEAVES:4)
Block(-1,43,-1,LEAVES:4)
Block(-1,43,0,LEAVES:4)
Block(-1,43,1,LEAVES:4)
Block(-1,43,2,LEAVES:4)
Block(-1,43,3,LEAVES:4)
Block(-1,43,4,LEAVES:4)
Block(-1,43,7,LEAVES:3)
Block(-1,43,8,LEAVES:3)
Block(-1,44,-7,LEAVES:4)
Block(-1,44,-6,LEAVES:4)
Block(-1,44,-5,LEAVES:4)
Block(-1,44,-2,LEAVES:4)
Block(-1,44,-1,LEAVES:4)
Block(-1,44,0,LEAVES:4)
Block(-1,44,1,LEAVES:4)
Block(-1,44,2,LEAVES:4)
Block(-1,44,3,LEAVES:4)
Block(-1,44,4,LEAVES:4)
Block(-1,44,5,LEAVES:3)
Block(-1,44,8,LEAVES:3)
Block(-1,45,-7,LEAVES:4)
Block(-1,45,-6,LEAVES:4)
Block(-1,45,-5,LEAVES:4)
Block(-1,45,-4,LEAVES:4)
Block(-1,45,-3,LEAVES:4)
Block(-1,45,-2,LEAVES:4)
Block(-1,45,-1,LEAVES:4)
Block(-1,45,0,LEAVES:4)
Block(-1,45,1,LEAVES:4)
Block(-1,45,2,LEAVES:4)
Block(-1,45,3,LEAVES:4)
Block(-1,46,-7,LEAVES:4)
Block(-1,46,-6,LEAVES:4)
Block(-1,46,-5,LEAVES:4)
Block(-1,46,-4,LEAVES:4)
Block(-1,46,-3,LEAVES:4)
Block(-1,46,-2,LEAVES:4)
Block(-1,46,-1,LEAVES:4)
Block(-1,46,0,LEAVES:4)
Block(-1,46,1,LEAVES:4)
Block(-1,46,2,LEAVES:4)
Block(-1,46,3,LEAVES:4)
Block(-1,47,-7,LEAVES:4)
Block(-1,47,-6,LEAVES:4)
Block(-1,47,-5,LEAVES:4)
Block(-1,47,-4,LEAVES:4)
Block(-1,47,-3,LEAVES:4)
Block(-1,47,-2,LEAVES:4)
Block(-1,47,-1,LEAVES:4)
Block(-1,47,0,LEAVES:4)
Block(-1,47,1,LEAVES:4)
Block(-1,47,2,LEAVES:4)
Block(-1,48,-7,LEAVES:4)
Block(-1,48,-6,LEAVES:4)
Block(-1,48,-5,LEAVES:4)
Block(-1,48,-4,LEAVES:4)
Block(-1,48,-3,LEAVES:4)
Block(-1,48,-2,LEAVES:4)
Block(-1,48,-1,LEAVES:4)
Block(-1,48,0,LEAVES:4)
Block(-1,48,1,LEAVES:4)
Block(-1,49,-7,LEAVES:4)
Block(-1,49,-6,LEAVES:4)
Block(-1,49,-5,LEAVES:4)
Block(-1,49,-4,LEAVES:4)
Block(-1,49,-3,LEAVES:4)
Block(-1,49,-2,LEAVES:4)
Block(-1,49,-1,LEAVES:4)
Block(-1,49,1,LEAVES:4)
Block(-1,49,2,LEAVES:4)
Block(-1,49,3,LEAVES:4)
Block(-1,50,-7,LEAVES:4)
Block(-1,50,-6,LEAVES:4)
Block(-1,50,-5,LEAVES:4)
Block(-1,50,-4,LEAVES:4)
Block(-1,50,-3,LEAVES:4)
Block(-1,50,-1,LEAVES:4)
Block(-1,50,1,LEAVES:4)
Block(-1,50,3,LEAVES:4)
Block(-1,50,4,LEAVES:4)
Block(-1,51,-7,LEAVES:4)
Block(-1,51,-6,LEAVES:4)
Block(-1,51,-4,LEAVES:4)
Block(-1,51,-3,LEAVES:4)
Block(-1,51,-2,LEAVES:4)
Block(-1,52,-7,LEAVES:4)
Block(-1,52,-6,LEAVES:4)
Block(-1,52,-3,LEAVES:4)
Block(-1,52,-2,LEAVES:4)
Block(-1,53,-7,LEAVES:4)
Block(-1,53,-6,LEAVES:4)
Block(-1,54,-7,LEAVES:4)
Block(-1,54,-6,LEAVES:4)
Block(-1,55,-7,LEAVES:4)
Block(-1,55,-6,LEAVES:4)
Block(0,16,-5,LEAVES:4)
Block(0,17,-5,LEAVES:4)
Block(0,17,-4,LEAVES:4)
Block(0,17,-3,LEAVES:4)
Block(0,17,1,LEAVES:4)
Block(0,18,-6,LEAVES:4)
Block(0,18,-5,LEAVES:4)
Block(0,18,-4,LEAVES:4)
Block(0,18,-3,LEAVES:4)
Block(0,18,-2,LEAVES:4)
Block(0,18,0,LEAVES:4)
Block(0,18,1,LEAVES:4)
Block(0,18,2,LEAVES:4)
Block(0,18,3,LEAVES:4)
Block(0,18,4,LEAVES:4)
Block(0,18,5,LEAVES:4)
Block(0,19,-7,LEAVES:4)
Block(0,19,-6,LEAVES:4)
Block(0,19,-5,LEAVES:4)
Block(0,19,-4,LEAVES:4)
Block(0,19,-2,LEAVES:4)
Block(0,19,1,LEAVES:4)
Block(0,19,2,LEAVES:4)
Block(0,19,3,LEAVES:4)
Block(0,19,4,LEAVES:4)
Block(0,19,5,LEAVES:4)
Block(0,20,-7,LEAVES:4)
Block(0,20,-6,LEAVES:4)
Block(0,20,-5,LEAVES:4)
Block(0,20,-3,LEAVES:4)
Block(0,20,-2,LEAVES:4)
Block(0,20,-1,LEAVES:4)
Block(0,20,1,LEAVES:4)
Block(0,20,2,LEAVES:4)
Block(0,20,3,LEAVES:4)
Block(0,20,4,LEAVES:4)
Block(0,20,5,LEAVES:4)
Block(0,21,-7,LEAVES:4)
Block(0,21,-6,LEAVES:4)
Block(0,21,-1,LEAVES:4)
Block(0,21,0,LEAVES:4)
Block(0,21,1,LEAVES:4)
Block(0,21,2,LEAVES:4)
Block(0,21,5,LEAVES:4)
Block(0,22,-7,LEAVES:4)
Block(0,22,-1,LEAVES:4)
Block(0,22,0,LEAVES:4)
Block(0,22,1,LEAVES:4)
Block(0,24,-7,LEAVES:4)
Block(0,24,-2,LEAVES:4)
Block(0,37,-2,LEAVES:4)
Block(0,37,0,LEAVES:4)
Block(0,38,-7,LEAVES:3)
Block(0,38,-2,LEAVES:4)
Block(0,38,-1,LEAVES:4)
Block(0,38,0,LEAVES:4)
Block(0,39,-7,LEAVES:3)
Block(0,39,-6,LEAVES:3)
Block(0,39,-5,LEAVES:4)
Block(0,39,-4,LEAVES:4)
Block(0,39,-3,LEAVES:4)
Block(0,39,-2,LEAVES:4)
Block(0,39,-1,LEAVES:4)
Block(0,39,0,LEAVES:4)
Block(0,39,1,LEAVES:4)
Block(0,39,2,LEAVES:4)
Block(0,40,-7,LEAVES:3)
Block(0,40,-6,LEAVES:4)
Block(0,40,-5,LEAVES:4)
Block(0,40,-4,LEAVES:4)
Block(0,40,-3,LEAVES:4)
Block(0,40,-2,LEAVES:4)
Block(0,40,-1,LEAVES:4)
Block(0,40,0,LEAVES:4)
Block(0,40,2,LEAVES:4)
Block(0,40,3,LEAVES:4)
Block(0,40,4,LEAVES:4)
Block(0,40,5,LEAVES:4)
Block(0,41,-7,LEAVES:4)
Block(0,41,-6,LEAVES:4)
Block(0,41,-5,LEAVES:4)
Block(0,41,-4,LEAVES:4)
Block(0,41,-1,LEAVES:4)
Block(0,41,0,LEAVES:4)
Block(0,41,1,LEAVES:4)
Block(0,41,2,LEAVES:4)
Block(0,41,3,LEAVES:4)
Block(0,41,4,LEAVES:4)
Block(0,41,5,LEAVES:4)
Block(0,42,-7,LEAVES:4)
Block(0,42,-6,LEAVES:4)
Block(0,42,-5,LEAVES:4)
Block(0,42,-4,LEAVES:4)
Block(0,42,-1,LEAVES:4)
Block(0,42,0,LEAVES:4)
Block(0,42,1,LEAVES:4)
Block(0,42,2,LEAVES:4)
Block(0,42,3,LEAVES:4)
Block(0,42,4,LEAVES:4)
Block(0,42,5,LEAVES:4)
Block(0,43,-7,LEAVES:4)
Block(0,43,-6,LEAVES:4)
Block(0,43,-5,LEAVES:4)
Block(0,43,0,LEAVES:4)
Block(0,43,1,LEAVES:4)
Block(0,43,2,LEAVES:4)
Block(0,43,3,LEAVES:4)
Block(0,43,4,LEAVES:4)
Block(0,43,5,LEAVES:4)
Block(0,44,-7,LEAVES:4)
Block(0,44,-6,LEAVES:4)
Block(0,44,-5,LEAVES:4)
Block(0,44,-2,LEAVES:4)
Block(0,44,-1,LEAVES:4)
Block(0,44,0,LEAVES:4)
Block(0,44,1,LEAVES:4)
Block(0,44,2,LEAVES:4)
Block(0,44,3,LEAVES:4)
Block(0,44,4,LEAVES:4)
Block(0,44,5,LEAVES:3)
Block(0,45,-7,LEAVES:4)
Block(0,45,-6,LEAVES:4)
Block(0,45,-4,LEAVES:4)
Block(0,45,-2,LEAVES:4)
Block(0,45,-1,LEAVES:4)
Block(0,45,0,LEAVES:4)
Block(0,45,1,LEAVES:4)
Block(0,45,2,LEAVES:4)
Block(0,45,3,LEAVES:4)
Block(0,45,4,LEAVES:4)
Block(0,45,5,LEAVES:3)
Block(0,46,-7,LEAVES:4)
Block(0,46,-6,LEAVES:4)
Block(0,46,-5,LEAVES:4)
Block(0,46,-4,LEAVES:4)
Block(0,46,-3,LEAVES:4)
Block(0,46,-1,LEAVES:4)
Block(0,46,0,LEAVES:4)
Block(0,46,1,LEAVES:4)
Block(0,46,2,LEAVES:4)
Block(0,46,3,LEAVES:4)
Block(0,46,4,LEAVES:3)
Block(0,46,5,LEAVES:3)
Block(0,47,-7,LEAVES:4)
Block(0,47,-6,LEAVES:4)
Block(0,47,-5,LEAVES:4)
Block(0,47,-4,LEAVES:4)
Block(0,47,-3,LEAVES:4)
Block(0,47,-1,LEAVES:4)
Block(0,47,0,LEAVES:4)
Block(0,47,1,LEAVES:4)
Block(0,47,2,LEAVES:4)
Block(0,47,3,LEAVES:4)
Block(0,48,-7,LEAVES:4)
Block(0,48,-6,LEAVES:4)
Block(0,48,-5,LEAVES:4)
Block(0,48,-4,LEAVES:4)
Block(0,48,-3,LEAVES:4)
Block(0,48,-2,LEAVES:4)
Block(0,48,-1,LEAVES:4)
Block(0,48,0,LEAVES:4)
Block(0,48,1,LEAVES:4)
Block(0,48,2,LEAVES:4)
Block(0,48,3,LEAVES:4)
Block(0,49,-7,LEAVES:4)
Block(0,49,-6,LEAVES:4)
Block(0,49,-5,LEAVES:4)
Block(0,49,-4,LEAVES:4)
Block(0,49,-3,LEAVES:4)
Block(0,49,-2,LEAVES:4)
Block(0,49,-1,LEAVES:4)
Block(0,50,-7,LEAVES:4)
Block(0,50,-4,LEAVES:4)
Block(0,50,-3,LEAVES:4)
Block(0,50,-2,LEAVES:4)
Block(0,51,-7,LEAVES:4)
Block(0,51,-6,LEAVES:4)
Block(0,51,-5,LEAVES:4)
Block(0,51,-4,LEAVES:4)
Block(0,51,-3,LEAVES:4)
Block(0,51,-2,LEAVES:4)
Block(0,51,-1,LEAVES:4)
Block(0,52,-7,LEAVES:4)
Block(0,52,-6,LEAVES:4)
Block(0,52,-3,LEAVES:4)
Block(0,52,-2,LEAVES:4)
Block(0,53,-7,LEAVES:4)
Block(0,53,-6,LEAVES:4)
Block(0,54,-7,LEAVES:4)
Block(0,54,-6,LEAVES:4)
Block(1,-12,-7,LOG:12)
Block(1,16,-4,LEAVES:4)
Block(1,16,1,LEAVES:4)
Block(1,17,-6,LEAVES:4)
Block(1,17,-4,LEAVES:4)
Block(1,17,-3,LEAVES:4)
Block(1,17,-2,LEAVES:4)
Block(1,17,-1,LEAVES:4)
Block(1,17,0,LEAVES:4)
Block(1,17,1,LEAVES:4)
Block(1,17,2,LEAVES:4)
Block(1,17,3,LEAVES:4)
Block(1,18,-7,LEAVES:4)
Block(1,18,-6,LEAVES:4)
Block(1,18,-5,LEAVES:4)
Block(1,18,-4,LEAVES:4)
Block(1,18,-3,LEAVES:4)
Block(1,18,-2,LEAVES:4)
Block(1,18,-1,LEAVES:4)
Block(1,18,0,LEAVES:4)
Block(1,18,1,LEAVES:4)
Block(1,18,2,LEAVES:4)
Block(1,18,3,LEAVES:4)
Block(1,18,4,LEAVES:4)
Block(1,18,5,LEAVES:4)
Block(1,18,6,LEAVES:4)
Block(1,19,-7,LEAVES:4)
Block(1,19,-6,LEAVES:4)
Block(1,19,-5,LEAVES:4)
Block(1,19,-4,LEAVES:4)
Block(1,19,-3,LEAVES:4)
Block(1,19,-2,LEAVES:4)
Block(1,19,-1,LEAVES:4)
Block(1,19,0,LEAVES:4)
Block(1,19,1,LEAVES:4)
Block(1,19,2,LEAVES:4)
Block(1,19,3,LEAVES:4)
Block(1,19,4,LEAVES:4)
Block(1,19,5,LEAVES:4)
Block(1,20,-7,LEAVES:4)
Block(1,20,-6,LEAVES:4)
Block(1,20,-5,LEAVES:4)
Block(1,20,-4,LEAVES:4)
Block(1,20,-3,LEAVES:4)
Block(1,20,-2,LEAVES:4)
Block(1,20,-1,LEAVES:4)
Block(1,20,0,LEAVES:4)
Block(1,20,1,LEAVES:4)
Block(1,20,2,LEAVES:4)
Block(1,20,3,LEAVES:4)
Block(1,20,4,LEAVES:4)
Block(1,20,5,LEAVES:4)
Block(1,21,-7,LEAVES:4)
Block(1,21,-6,LEAVES:4)
Block(1,21,-4,LEAVES:4)
Block(1,21,-3,LEAVES:4)
Block(1,21,-2,LEAVES:4)
Block(1,21,-1,LEAVES:4)
Block(1,21,0,LEAVES:4)
Block(1,21,1,LEAVES:4)
Block(1,21,2,LEAVES:4)
Block(1,21,3,LEAVES:4)
Block(1,21,4,LEAVES:4)
Block(1,22,-7,LEAVES:4)
Block(1,22,-6,LEAVES:4)
Block(1,22,-5,LEAVES:4)
Block(1,22,-4,LEAVES:4)
Block(1,22,-3,LEAVES:4)
Block(1,22,-2,LEAVES:4)
Block(1,22,-1,LEAVES:4)
Block(1,22,0,LEAVES:4)
Block(1,22,1,LEAVES:4)
Block(1,23,-5,LEAVES:4)
Block(1,23,-4,LEAVES:4)
Block(1,23,-3,LEAVES:4)
Block(1,23,-1,LEAVES:4)
Block(1,23,1,LEAVES:4)
Block(1,24,-7,LEAVES:4)
Block(1,24,-6,LEAVES:4)
Block(1,24,-2,LEAVES:4)
Block(1,24,-1,LEAVES:4)
Block(1,24,0,LEAVES:4)
Block(1,37,-7,LEAVES:3)
Block(1,37,1,LEAVES:4)
Block(1,38,-7,LEAVES:3)
Block(1,38,-6,LEAVES:3)
Block(1,38,-3,LEAVES:4)
Block(1,38,0,LEAVES:4)
Block(1,38,1,LEAVES:4)
Block(1,39,-7,LEAVES:3)
Block(1,39,-6,LEAVES:3)
Block(1,39,-5,LEAVES:4)
Block(1,39,-4,LEAVES:4)
Block(1,39,-3,LEAVES:4)
Block(1,39,-2,LEAVES:4)
Block(1,39,-1,LEAVES:4)
Block(1,39,0,LEAVES:4)
Block(1,39,1,LEAVES:4)
Block(1,39,2,LEAVES:4)
Block(1,40,-7,LEAVES:3)
Block(1,40,-6,LEAVES:3)
Block(1,40,-5,LEAVES:4)
Block(1,40,-4,LEAVES:4)
Block(1,40,-3,LEAVES:4)
Block(1,40,-2,LEAVES:4)
Block(1,40,-1,LEAVES:4)
Block(1,40,0,LEAVES:4)
Block(1,40,1,LEAVES:4)
Block(1,40,2,LEAVES:4)
Block(1,40,4,LEAVES:4)
Block(1,40,5,LEAVES:4)
Block(1,41,-7,LEAVES:3)
Block(1,41,-6,LEAVES:4)
Block(1,41,-5,LEAVES:4)
Block(1,41,-4,LEAVES:4)
Block(1,41,-3,LEAVES:4)
Block(1,41,-2,LEAVES:4)
Block(1,41,-1,LEAVES:4)
Block(1,41,0,LEAVES:4)
Block(1,41,1,LEAVES:4)
Block(1,41,2,LEAVES:4)
Block(1,41,3,LEAVES:4)
Block(1,41,4,LEAVES:4)
Block(1,41,5,LEAVES:4)
Block(1,42,-7,LEAVES:4)
Block(1,42,-6,LEAVES:4)
Block(1,42,-5,LEAVES:4)
Block(1,42,-4,LEAVES:4)
Block(1,42,-3,LEAVES:4)
Block(1,42,-2,LEAVES:4)
Block(1,42,-1,LEAVES:4)
Block(1,42,0,LEAVES:4)
Block(1,42,1,LEAVES:4)
Block(1,42,2,LEAVES:4)
Block(1,42,3,LEAVES:4)
Block(1,42,4,LEAVES:4)
Block(1,42,5,LEAVES:4)
Block(1,43,-7,LEAVES:4)
Block(1,43,-6,LEAVES:4)
Block(1,43,-5,LEAVES:4)
Block(1,43,-4,LEAVES:4)
Block(1,43,-3,LEAVES:4)
Block(1,43,-2,LEAVES:4)
Block(1,43,-1,LEAVES:4)
Block(1,43,0,LEAVES:4)
Block(1,43,1,LEAVES:4)
Block(1,43,2,LEAVES:4)
Block(1,43,3,LEAVES:4)
Block(1,43,4,LEAVES:4)
Block(1,43,5,LEAVES:4)
Block(1,43,6,LEAVES:4)
Block(1,44,-7,LEAVES:4)
Block(1,44,-6,LEAVES:4)
Block(1,44,-5,LEAVES:4)
Block(1,44,-4,LEAVES:4)
Block(1,44,-2,LEAVES:4)
Block(1,44,-1,LEAVES:4)
Block(1,44,0,LEAVES:4)
Block(1,44,1,LEAVES:4)
Block(1,44,2,LEAVES:4)
Block(1,44,3,LEAVES:4)
Block(1,44,4,LEAVES:4)
Block(1,44,5,LEAVES:4)
Block(1,45,-7,LEAVES:4)
Block(1,45,-6,LEAVES:4)
Block(1,45,-5,LEAVES:4)
Block(1,45,-4,LEAVES:4)
Block(1,45,-3,LEAVES:4)
Block(1,45,-2,LEAVES:4)
Block(1,45,-1,LEAVES:4)
Block(1,45,0,LEAVES:4)
Block(1,45,1,LEAVES:4)
Block(1,45,2,LEAVES:4)
Block(1,45,3,LEAVES:4)
Block(1,45,4,LEAVES:4)
Block(1,45,5,LEAVES:3)
Block(1,46,-7,LEAVES:4)
Block(1,46,-6,LEAVES:4)
Block(1,46,-5,LEAVES:4)
Block(1,46,-4,LEAVES:4)
Block(1,46,-3,LEAVES:4)
Block(1,46,-2,LEAVES:4)
Block(1,46,-1,LEAVES:4)
Block(1,46,0,LEAVES:4)
Block(1,46,1,LEAVES:4)
Block(1,46,2,LEAVES:4)
Block(1,46,3,LEAVES:4)
Block(1,46,4,LEAVES:4)
Block(1,46,5,LEAVES:3)
Block(1,47,-7,LEAVES:4)
Block(1,47,-6,LEAVES:4)
Block(1,47,-5,LEAVES:4)
Block(1,47,-4,LEAVES:4)
Block(1,47,-3,LEAVES:4)
Block(1,47,-2,LEAVES:4)
Block(1,47,-1,LEAVES:4)
Block(1,47,0,LEAVES:4)
Block(1,47,1,LEAVES:4)
Block(1,47,2,LEAVES:4)
Block(1,48,-7,LEAVES:4)
Block(1,48,-6,LEAVES:4)
Block(1,48,-5,LEAVES:4)
Block(1,48,-4,LEAVES:4)
Block(1,48,-3,LEAVES:4)
Block(1,48,-2,LEAVES:4)
Block(1,48,-1,LEAVES:4)
Block(1,48,0,LEAVES:4)
Block(1,48,1,LEAVES:4)
Block(1,48,2,LEAVES:4)
Block(1,49,-5,LEAVES:4)
Block(1,49,-4,LEAVES:4)
Block(1,49,-3,LEAVES:4)
Block(1,49,-2,LEAVES:4)
Block(1,49,-1,LEAVES:4)
Block(1,49,0,LEAVES:4)
Block(1,49,1,LEAVES:4)
Block(1,50,-7,LEAVES:4)
Block(1,50,-6,LEAVES:4)
Block(1,50,-5,LEAVES:4)
Block(1,50,-4,LEAVES:4)
Block(1,50,-3,LEAVES:4)
Block(1,50,-2,LEAVES:4)
Block(1,50,-1,LEAVES:4)
Block(1,51,-7,LEAVES:4)
Block(1,51,-6,LEAVES:4)
Block(1,51,-5,LEAVES:4)
Block(1,51,-4,LEAVES:4)
Block(1,51,-3,LEAVES:4)
Block(1,51,-2,LEAVES:4)
Block(1,51,-1,LEAVES:4)
Block(1,51,0,LEAVES:4)
Block(1,52,-7,LEAVES:4)
Block(1,52,-6,LEAVES:4)
Block(1,52,-5,LEAVES:4)
Block(1,52,-4,LEAVES:4)
Block(1,52,-3,LEAVES:4)
Block(1,52,-2,LEAVES:4)
Block(1,52,-1,LEAVES:4)
Block(1,53,-7,LEAVES:4)
Block(1,53,-6,LEAVES:4)
Block(1,55,-7,LEAVES:4)
Block(2,-13,-7,LOG:12)
Block(2,-12,-7,LOG:12)
Block(2,-11,-7,LOG:12)
Block(2,16,-5,LEAVES:4)
Block(2,16,1,LEAVES:4)
Block(2,16,2,LEAVES:4)
Block(2,16,3,LEAVES:4)
Block(2,17,-7,LEAVES:4)
Block(2,17,-6,LEAVES:4)
Block(2,17,-5,LEAVES:4)
Block(2,17,-4,LEAVES:4)
Block(2,17,-3,LEAVES:4)
Block(2,17,-2,LEAVES:4)
Block(2,17,-1,LEAVES:4)
Block(2,17,0,LEAVES:4)
Block(2,17,1,LEAVES:4)
Block(2,17,2,LEAVES:4)
Block(2,17,3,LEAVES:4)
Block(2,17,4,LEAVES:4)
Block(2,18,-7,LEAVES:4)
Block(2,18,-6,LEAVES:4)
Block(2,18,-5,LEAVES:4)
Block(2,18,-4,LEAVES:4)
Block(2,18,-3,LEAVES:4)
Block(2,18,-2,LEAVES:4)
Block(2,18,-1,LEAVES:4)
Block(2,18,0,LEAVES:4)
Block(2,18,1,LEAVES:4)
Block(2,18,2,LEAVES:4)
Block(2,18,3,LEAVES:4)
Block(2,18,4,LEAVES:4)
Block(2,18,5,LEAVES:4)
Block(2,18,6,LEAVES:4)
Block(2,19,-7,LEAVES:4)
Block(2,19,-6,LEAVES:4)
Block(2,19,-5,LEAVES:4)
Block(2,19,-4,LEAVES:4)
Block(2,19,-3,LEAVES:4)
Block(2,19,-2,LEAVES:4)
Block(2,19,-1,LEAVES:4)
Block(2,19,0,LEAVES:4)
Block(2,19,1,LEAVES:4)
Block(2,19,2,LEAVES:4)
Block(2,19,3,LEAVES:4)
Block(2,19,4,LEAVES:4)
Block(2,19,5,LEAVES:4)
Block(2,19,6,LEAVES:4)
Block(2,20,-7,LEAVES:4)
Block(2,20,-6,LEAVES:4)
Block(2,20,-5,LEAVES:4)
Block(2,20,-4,LEAVES:4)
Block(2,20,-3,LEAVES:4)
Block(2,20,-2,LEAVES:4)
Block(2,20,-1,LEAVES:4)
Block(2,20,0,LEAVES:4)
Block(2,20,1,LEAVES:4)
Block(2,20,2,LEAVES:4)
Block(2,20,3,LEAVES:4)
Block(2,20,4,LEAVES:4)
Block(2,20,5,LEAVES:4)
Block(2,21,-7,LEAVES:4)
Block(2,21,-6,LEAVES:4)
Block(2,21,-5,LEAVES:4)
Block(2,21,-4,LEAVES:4)
Block(2,21,-3,LEAVES:4)
Block(2,21,-2,LEAVES:4)
Block(2,21,-1,LEAVES:4)
Block(2,21,0,LEAVES:4)
Block(2,21,1,LEAVES:4)
Block(2,21,2,LEAVES:4)
Block(2,21,3,LEAVES:4)
Block(2,21,4,LEAVES:4)
Block(2,21,5,LEAVES:4)
Block(2,22,-7,LEAVES:4)
Block(2,22,-6,LEAVES:4)
Block(2,22,-5,LEAVES:4)
Block(2,22,-4,LEAVES:4)
Block(2,22,-3,LEAVES:4)
Block(2,22,-2,LEAVES:4)
Block(2,22,-1,LEAVES:4)
Block(2,22,0,LEAVES:4)
Block(2,22,1,LEAVES:4)
Block(2,22,2,LEAVES:4)
Block(2,22,3,LEAVES:4)
Block(2,23,-7,LEAVES:4)
Block(2,23,-6,LEAVES:4)
Block(2,23,-5,LEAVES:4)
Block(2,23,-4,LEAVES:4)
Block(2,23,-3,LEAVES:4)
Block(2,23,3,LEAVES:4)
Block(2,24,-7,LEAVES:4)
Block(2,24,-6,LEAVES:4)
Block(2,37,-7,LEAVES:3)
Block(2,38,-7,LEAVES:3)
Block(2,38,-6,LEAVES:3)
Block(2,38,-4,LEAVES:4)
Block(2,38,-3,LEAVES:4)
Block(2,38,-1,LEAVES:4)
Block(2,39,-7,LEAVES:3)
Block(2,39,-6,LEAVES:3)
Block(2,39,-5,LEAVES:3)
Block(2,39,-4,LEAVES:4)
Block(2,39,-3,LEAVES:4)
Block(2,39,-2,LEAVES:4)
Block(2,39,-1,LEAVES:4)
Block(2,40,-7,LEAVES:3)
Block(2,40,-6,LEAVES:3)
Block(2,40,-5,LEAVES:4)
Block(2,40,-4,LEAVES:4)
Block(2,40,-3,LEAVES:4)
Block(2,40,-2,LEAVES:4)
Block(2,40,-1,LEAVES:4)
Block(2,40,0,LEAVES:4)
Block(2,40,1,LEAVES:4)
Block(2,41,-7,LEAVES:3)
Block(2,41,-6,LEAVES:4)
Block(2,41,-5,LEAVES:4)
Block(2,41,-4,LEAVES:4)
Block(2,41,-3,LEAVES:4)
Block(2,41,-2,LEAVES:4)
Block(2,41,-1,LEAVES:4)
Block(2,41,0,LEAVES:4)
Block(2,42,-7,LEAVES:4)
Block(2,42,-6,LEAVES:4)
Block(2,42,-5,LEAVES:4)
Block(2,42,-4,LEAVES:4)
Block(2,42,-3,LEAVES:4)
Block(2,42,-2,LEAVES:4)
Block(2,42,-1,LEAVES:4)
Block(2,42,0,LEAVES:4)
Block(2,42,1,LEAVES:4)
Block(2,42,2,LEAVES:4)
Block(2,42,3,LEAVES:4)
Block(2,42,4,LEAVES:4)
Block(2,42,5,LEAVES:4)
Block(2,43,-7,LEAVES:4)
Block(2,43,-6,LEAVES:4)
Block(2,43,-5,LEAVES:4)
Block(2,43,-4,LEAVES:4)
Block(2,43,-3,LEAVES:4)
Block(2,43,-2,LEAVES:4)
Block(2,43,-1,LEAVES:4)
Block(2,43,1,LEAVES:4)
Block(2,43,2,LEAVES:4)
Block(2,43,3,LEAVES:4)
Block(2,43,4,LEAVES:4)
Block(2,43,5,LEAVES:4)
Block(2,44,-7,LEAVES:4)
Block(2,44,-6,LEAVES:4)
Block(2,44,-5,LEAVES:4)
Block(2,44,-4,LEAVES:4)
Block(2,44,-3,LEAVES:4)
Block(2,44,-2,LEAVES:4)
Block(2,44,-1,LEAVES:4)
Block(2,44,0,LEAVES:4)
Block(2,44,1,LEAVES:4)
Block(2,44,2,LEAVES:4)
Block(2,44,3,LEAVES:4)
Block(2,44,4,LEAVES:4)
Block(2,45,-7,LEAVES:4)
Block(2,45,-6,LEAVES:4)
Block(2,45,-5,LEAVES:4)
Block(2,45,-4,LEAVES:4)
Block(2,45,-3,LEAVES:4)
Block(2,45,-2,LEAVES:4)
Block(2,45,-1,LEAVES:4)
Block(2,45,0,LEAVES:4)
Block(2,45,1,LEAVES:4)
Block(2,45,2,LEAVES:4)
Block(2,45,3,LEAVES:4)
Block(2,45,4,LEAVES:4)
Block(2,46,-7,LEAVES:4)
Block(2,46,-6,LEAVES:4)
Block(2,46,-5,LEAVES:4)
Block(2,46,-4,LEAVES:4)
Block(2,46,-3,LEAVES:4)
Block(2,46,-2,LEAVES:4)
Block(2,46,-1,LEAVES:4)
Block(2,46,1,LEAVES:4)
Block(2,46,2,LEAVES:4)
Block(2,46,3,LEAVES:4)
Block(2,47,-7,LEAVES:4)
Block(2,47,-6,LEAVES:4)
Block(2,47,-5,LEAVES:4)
Block(2,47,-4,LEAVES:4)
Block(2,47,-3,LEAVES:4)
Block(2,47,-2,LEAVES:4)
Block(2,47,-1,LEAVES:4)
Block(2,47,1,LEAVES:4)
Block(2,47,2,LEAVES:4)
Block(2,48,-4,LEAVES:4)
Block(2,48,-3,LEAVES:4)
Block(2,48,-2,LEAVES:4)
Block(2,48,-1,LEAVES:4)
Block(2,48,0,LEAVES:4)
Block(2,49,-6,LEAVES:4)
Block(2,49,-3,LEAVES:4)
Block(2,49,-2,LEAVES:4)
Block(2,49,-1,LEAVES:4)
Block(2,49,0,LEAVES:4)
Block(2,49,1,LEAVES:4)
Block(2,49,2,LEAVES:4)
Block(2,50,-7,LEAVES:4)
Block(2,50,-6,LEAVES:4)
Block(2,50,-5,LEAVES:4)
Block(2,50,-4,LEAVES:4)
Block(2,50,-3,LEAVES:4)
Block(2,50,-2,LEAVES:4)
Block(2,50,-1,LEAVES:4)
Block(2,50,0,LEAVES:4)
Block(2,51,-7,LEAVES:4)
Block(2,51,-6,LEAVES:4)
Block(2,51,-5,LEAVES:4)
Block(2,51,-4,LEAVES:4)
Block(2,51,-3,LEAVES:4)
Block(2,51,-2,LEAVES:4)
Block(2,51,-1,LEAVES:4)
Block(2,51,0,LEAVES:4)
Block(2,52,-7,LEAVES:4)
Block(2,52,-6,LEAVES:4)
Block(2,52,-5,LEAVES:4)
Block(2,52,-4,LEAVES:4)
Block(2,52,-3,LEAVES:4)
Block(2,52,-2,LEAVES:4)
Block(2,52,-1,LEAVES:4)
Block(2,52,0,LEAVES:4)
Block(2,53,-7,LEAVES:4)
Block(2,53,-6,LEAVES:4)
Block(2,53,-5,LEAVES:4)
Block(2,53,-4,LEAVES:4)
Block(2,53,-3,LEAVES:4)
Block(2,53,-2,LEAVES:4)
Block(2,54,-7,LEAVES:4)
Block(2,54,-6,LEAVES:4)
Block(2,55,-7,LEAVES:4)
Block(3,-12,-7,LOG:12)
Block(3,16,1,LEAVES:4)
Block(3,16,2,LEAVES:4)
Block(3,17,-7,LEAVES:4)
Block(3,17,-6,LEAVES:4)
Block(3,17,-5,LEAVES:4)
Block(3,17,-4,LEAVES:4)
Block(3,17,-3,LEAVES:4)
Block(3,17,-2,LEAVES:4)
Block(3,17,-1,LEAVES:4)
Block(3,17,0,LEAVES:4)
Block(3,17,1,LEAVES:4)
Block(3,17,2,LEAVES:4)
Block(3,17,3,LEAVES:4)
Block(3,18,-7,LEAVES:4)
Block(3,18,-6,LEAVES:4)
Block(3,18,-5,LEAVES:4)
Block(3,18,-4,LEAVES:4)
Block(3,18,-3,LEAVES:4)
Block(3,18,-2,LEAVES:4)
Block(3,18,-1,LEAVES:4)
Block(3,18,0,LEAVES:4)
Block(3,18,1,LEAVES:4)
Block(3,18,2,LEAVES:4)
Block(3,18,3,LEAVES:4)
Block(3,18,4,LEAVES:4)
Block(3,19,-7,LEAVES:4)
Block(3,19,-6,LEAVES:4)
Block(3,19,-5,LEAVES:4)
Block(3,19,-4,LEAVES:4)
Block(3,19,-3,LEAVES:4)
Block(3,19,-2,LEAVES:4)
Block(3,19,-1,LEAVES:4)
Block(3,19,0,LEAVES:4)
Block(3,19,1,LEAVES:4)
Block(3,19,2,LEAVES:4)
Block(3,19,3,LEAVES:4)
Block(3,19,4,LEAVES:4)
Block(3,19,5,LEAVES:4)
Block(3,20,-7,LEAVES:4)
Block(3,20,-6,LEAVES:4)
Block(3,20,-5,LEAVES:4)
Block(3,20,-4,LEAVES:4)
Block(3,20,-3,LEAVES:4)
Block(3,20,-2,LEAVES:4)
Block(3,20,-1,LEAVES:4)
Block(3,20,0,LEAVES:4)
Block(3,20,1,LEAVES:4)
Block(3,20,2,LEAVES:4)
Block(3,20,3,LEAVES:4)
Block(3,20,4,LEAVES:4)
Block(3,20,5,LEAVES:4)
Block(3,21,-7,LEAVES:4)
Block(3,21,-6,LEAVES:4)
Block(3,21,-5,LEAVES:4)
Block(3,21,-4,LEAVES:4)
Block(3,21,-3,LEAVES:4)
Block(3,21,-2,LEAVES:4)
Block(3,21,-1,LEAVES:4)
Block(3,21,0,LEAVES:4)
Block(3,21,1,LEAVES:4)
Block(3,21,2,LEAVES:4)
Block(3,21,4,LEAVES:4)
Block(3,22,-7,LEAVES:4)
Block(3,22,-6,LEAVES:4)
Block(3,22,-5,LEAVES:4)
Block(3,22,-4,LEAVES:4)
Block(3,22,-3,LEAVES:4)
Block(3,22,-2,LEAVES:4)
Block(3,22,-1,LEAVES:4)
Block(3,22,0,LEAVES:4)
Block(3,22,1,LEAVES:4)
Block(3,22,2,LEAVES:4)
Block(3,22,3,LEAVES:4)
Block(3,23,-7,LEAVES:4)
Block(3,23,-6,LEAVES:4)
Block(3,23,-5,LEAVES:4)
Block(3,23,-4,LEAVES:4)
Block(3,23,-3,LEAVES:4)
Block(3,23,-2,LEAVES:4)
Block(3,23,-1,LEAVES:4)
Block(3,24,-7,LEAVES:4)
Block(3,24,-6,LEAVES:4)
Block(3,38,-7,LEAVES:3)
Block(3,38,-2,LEAVES:4)
Block(3,38,-1,LEAVES:4)
Block(3,39,-6,LEAVES:3)
Block(3,39,-5,LEAVES:3)
Block(3,39,-4,LEAVES:4)
Block(3,39,-2,LEAVES:4)
Block(3,39,-1,LEAVES:4)
Block(3,40,-7,LEAVES:3)
Block(3,40,-6,LEAVES:3)
Block(3,40,-5,LEAVES:4)
Block(3,40,-4,LEAVES:4)
Block(3,40,-3,LEAVES:4)
Block(3,40,-2,LEAVES:4)
Block(3,40,-1,LEAVES:4)
Block(3,40,0,LEAVES:4)
Block(3,41,-7,LEAVES:3)
Block(3,41,-6,LEAVES:4)
Block(3,41,-5,LEAVES:4)
Block(3,41,-4,LEAVES:4)
Block(3,41,-3,LEAVES:4)
Block(3,41,-2,LEAVES:4)
Block(3,41,-1,LEAVES:4)
Block(3,41,0,LEAVES:4)
Block(3,41,1,LEAVES:4)
Block(3,41,3,LEAVES:4)
Block(3,41,5,LEAVES:4)
Block(3,42,-7,LEAVES:4)
Block(3,42,-6,LEAVES:4)
Block(3,42,-5,LEAVES:4)
Block(3,42,-4,LEAVES:4)
Block(3,42,-3,LEAVES:4)
Block(3,42,-2,LEAVES:4)
Block(3,42,-1,LEAVES:4)
Block(3,42,0,LEAVES:4)
Block(3,42,3,LEAVES:4)
Block(3,42,5,LEAVES:4)
Block(3,43,-7,LEAVES:4)
Block(3,43,-6,LEAVES:4)
Block(3,43,-5,LEAVES:4)
Block(3,43,-4,LEAVES:4)
Block(3,43,-3,LEAVES:4)
Block(3,43,-2,LEAVES:4)
Block(3,43,-1,LEAVES:4)
Block(3,43,0,LEAVES:4)
Block(3,43,1,LEAVES:4)
Block(3,43,2,LEAVES:4)
Block(3,43,3,LEAVES:4)
Block(3,43,4,LEAVES:4)
Block(3,44,-7,LEAVES:4)
Block(3,44,-6,LEAVES:4)
Block(3,44,-5,LEAVES:4)
Block(3,44,-4,LEAVES:4)
Block(3,44,-3,LEAVES:4)
Block(3,44,-2,LEAVES:4)
Block(3,44,-1,LEAVES:4)
Block(3,44,0,LEAVES:4)
Block(3,44,1,LEAVES:4)
Block(3,44,2,LEAVES:4)
Block(3,44,3,LEAVES:4)
Block(3,44,4,LEAVES:4)
Block(3,45,-7,LEAVES:4)
Block(3,45,-6,LEAVES:4)
Block(3,45,-5,LEAVES:4)
Block(3,45,-4,LEAVES:4)
Block(3,45,-3,LEAVES:4)
Block(3,45,-2,LEAVES:4)
Block(3,45,-1,LEAVES:4)
Block(3,45,1,LEAVES:4)
Block(3,45,2,LEAVES:4)
Block(3,45,3,LEAVES:4)
Block(3,46,-7,LEAVES:4)
Block(3,46,-6,LEAVES:4)
Block(3,46,-5,LEAVES:4)
Block(3,46,-4,LEAVES:4)
Block(3,46,-3,LEAVES:4)
Block(3,46,-2,LEAVES:4)
Block(3,46,-1,LEAVES:4)
Block(3,47,-7,LEAVES:4)
Block(3,47,-6,LEAVES:4)
Block(3,47,-5,LEAVES:4)
Block(3,47,-4,LEAVES:4)
Block(3,47,-3,LEAVES:4)
Block(3,47,-2,LEAVES:4)
Block(3,48,-7,LEAVES:4)
Block(3,48,-6,LEAVES:4)
Block(3,48,-5,LEAVES:4)
Block(3,48,-4,LEAVES:4)
Block(3,48,-3,LEAVES:4)
Block(3,48,-2,LEAVES:4)
Block(3,49,-7,LEAVES:4)
Block(3,49,-6,LEAVES:4)
Block(3,49,-5,LEAVES:4)
Block(3,49,-3,LEAVES:4)
Block(3,49,-2,LEAVES:4)
Block(3,49,-1,LEAVES:4)
Block(3,50,-7,LEAVES:4)
Block(3,50,-6,LEAVES:4)
Block(3,50,-5,LEAVES:4)
Block(3,50,-4,LEAVES:4)
Block(3,50,-3,LEAVES:4)
Block(3,50,-2,LEAVES:4)
Block(3,50,-1,LEAVES:4)
Block(3,51,-7,LEAVES:4)
Block(3,51,-6,LEAVES:4)
Block(3,51,-5,LEAVES:4)
Block(3,51,-4,LEAVES:4)
Block(3,51,-3,LEAVES:4)
Block(3,51,-2,LEAVES:4)
Block(3,51,-1,LEAVES:4)
Block(3,51,0,LEAVES:4)
Block(3,52,-7,LEAVES:4)
Block(3,52,-6,LEAVES:4)
Block(3,52,-5,LEAVES:4)
Block(3,52,-4,LEAVES:4)
Block(3,52,-3,LEAVES:4)
Block(3,52,-2,LEAVES:4)
Block(3,52,-1,LEAVES:4)
Block(3,52,0,LEAVES:4)
Block(3,53,-7,LEAVES:4)
Block(3,53,-6,LEAVES:4)
Block(3,53,-5,LEAVES:4)
Block(3,53,-4,LEAVES:4)
Block(3,53,-3,LEAVES:4)
Block(3,54,-6,LEAVES:4)
Block(3,54,-5,LEAVES:4)
Block(4,16,-6,LEAVES:4)
Block(4,16,-5,LEAVES:4)
Block(4,16,-4,LEAVES:4)
Block(4,16,-3,LEAVES:4)
Block(4,17,-7,LEAVES:4)
Block(4,17,-6,LEAVES:4)
Block(4,17,-5,LEAVES:4)
Block(4,17,-4,LEAVES:4)
Block(4,17,-3,LEAVES:4)
Block(4,17,-2,LEAVES:4)
Block(4,17,1,LEAVES:4)
Block(4,17,2,LEAVES:4)
Block(4,18,-7,LEAVES:4)
Block(4,18,-6,LEAVES:4)
Block(4,18,-5,LEAVES:4)
Block(4,18,-4,LEAVES:4)
Block(4,18,-3,LEAVES:4)
Block(4,18,-2,LEAVES:4)
Block(4,18,-1,LEAVES:4)
Block(4,18,0,LEAVES:4)
Block(4,18,1,LEAVES:4)
Block(4,18,2,LEAVES:4)
Block(4,18,3,LEAVES:4)
Block(4,19,-7,LEAVES:4)
Block(4,19,-6,LEAVES:4)
Block(4,19,-5,LEAVES:4)
Block(4,19,-4,LEAVES:4)
Block(4,19,-3,LEAVES:4)
Block(4,19,-2,LEAVES:4)
Block(4,19,-1,LEAVES:4)
Block(4,19,0,LEAVES:4)
Block(4,19,1,LEAVES:4)
Block(4,19,2,LEAVES:4)
Block(4,19,3,LEAVES:4)
Block(4,20,-7,LEAVES:4)
Block(4,20,-6,LEAVES:4)
Block(4,20,-5,LEAVES:4)
Block(4,20,-4,LEAVES:4)
Block(4,20,-3,LEAVES:4)
Block(4,20,-2,LEAVES:4)
Block(4,20,-1,LEAVES:4)
Block(4,20,0,LEAVES:4)
Block(4,20,1,LEAVES:4)
Block(4,20,2,LEAVES:4)
Block(4,21,-7,LEAVES:4)
Block(4,21,-6,LEAVES:4)
Block(4,21,-5,LEAVES:4)
Block(4,21,-4,LEAVES:4)
Block(4,21,-3,LEAVES:4)
Block(4,21,-2,LEAVES:4)
Block(4,21,-1,LEAVES:4)
Block(4,21,0,LEAVES:4)
Block(4,21,1,LEAVES:4)
Block(4,22,-7,LEAVES:4)
Block(4,22,-6,LEAVES:4)
Block(4,22,-5,LEAVES:4)
Block(4,22,-4,LEAVES:4)
Block(4,22,-3,LEAVES:4)
Block(4,22,-2,LEAVES:4)
Block(4,22,-1,LEAVES:4)
Block(4,22,1,LEAVES:4)
Block(4,22,3,LEAVES:4)
Block(4,23,-7,LEAVES:4)
Block(4,23,-6,LEAVES:4)
Block(4,23,-5,LEAVES:4)
Block(4,23,-4,LEAVES:4)
Block(4,23,-3,LEAVES:4)
Block(4,23,-2,LEAVES:4)
Block(4,23,-1,LEAVES:4)
Block(4,24,-7,LEAVES:4)
Block(4,38,-6,LEAVES:3)
Block(4,38,-3,LEAVES:3)
Block(4,38,-2,LEAVES:4)
Block(4,39,-6,LEAVES:3)
Block(4,39,-5,LEAVES:3)
Block(4,39,-4,LEAVES:3)
Block(4,39,-3,LEAVES:3)
Block(4,39,-2,LEAVES:4)
Block(4,39,-1,LEAVES:4)
Block(4,40,-6,LEAVES:3)
Block(4,40,-5,LEAVES:3)
Block(4,40,-4,LEAVES:3)
Block(4,40,-3,LEAVES:4)
Block(4,40,-2,LEAVES:4)
Block(4,40,-1,LEAVES:4)
Block(4,40,0,LEAVES:4)
Block(4,41,-7,LEAVES:3)
Block(4,41,-6,LEAVES:3)
Block(4,41,-5,LEAVES:4)
Block(4,41,-4,LEAVES:4)
Block(4,41,-3,LEAVES:4)
Block(4,41,-2,LEAVES:4)
Block(4,41,-1,LEAVES:4)
Block(4,42,-7,LEAVES:3)
Block(4,42,-6,LEAVES:4)
Block(4,42,-5,LEAVES:4)
Block(4,42,-4,LEAVES:4)
Block(4,42,-3,LEAVES:4)
Block(4,42,-2,LEAVES:4)
Block(4,42,-1,LEAVES:4)
Block(4,43,-7,LEAVES:4)
Block(4,43,-6,LEAVES:4)
Block(4,43,-5,LEAVES:4)
Block(4,43,-4,LEAVES:4)
Block(4,43,-3,LEAVES:4)
Block(4,43,-2,LEAVES:4)
Block(4,43,-1,LEAVES:4)
Block(4,44,-7,LEAVES:4)
Block(4,44,-6,LEAVES:4)
Block(4,44,-5,LEAVES:4)
Block(4,44,-4,LEAVES:4)
Block(4,44,-3,LEAVES:4)
Block(4,45,-7,LEAVES:4)
Block(4,45,-6,LEAVES:4)
Block(4,45,-5,LEAVES:4)
Block(4,45,-4,LEAVES:4)
Block(4,45,-3,LEAVES:4)
Block(4,45,-2,LEAVES:4)
Block(4,46,-7,LEAVES:4)
Block(4,46,-6,LEAVES:4)
Block(4,46,-5,LEAVES:4)
Block(4,46,-4,LEAVES:4)
Block(4,46,-3,LEAVES:4)
Block(4,46,-2,LEAVES:4)
Block(4,47,-7,LEAVES:4)
Block(4,47,-6,LEAVES:4)
Block(4,47,-5,LEAVES:4)
Block(4,47,-4,LEAVES:4)
Block(4,47,-3,LEAVES:4)
Block(4,48,-7,LEAVES:4)
Block(4,48,-6,LEAVES:4)
Block(4,48,-5,LEAVES:4)
Block(4,49,-7,LEAVES:4)
Block(4,49,-6,LEAVES:4)
Block(4,49,-3,LEAVES:4)
Block(4,49,-2,LEAVES:4)
Block(4,49,-1,LEAVES:4)
Block(4,50,-7,LEAVES:4)
Block(4,50,-6,LEAVES:4)
Block(4,50,-5,LEAVES:4)
Block(4,50,-4,LEAVES:4)
Block(4,50,-3,LEAVES:4)
Block(4,50,-2,LEAVES:4)
Block(4,50,-1,LEAVES:4)
Block(4,51,-7,LEAVES:4)
Block(4,51,-6,LEAVES:4)
Block(4,51,-5,LEAVES:4)
Block(4,51,-2,LEAVES:4)
Block(4,51,-1,LEAVES:4)
Block(4,52,-7,LEAVES:4)
Block(4,52,-6,LEAVES:4)
Block(4,52,-5,LEAVES:4)
Block(4,52,-4,LEAVES:4)
Block(4,52,-1,LEAVES:4)
Block(4,53,-7,LEAVES:4)
Block(4,53,-6,LEAVES:4)
Block(4,53,-5,LEAVES:4)
Block(4,53,-4,LEAVES:4)
Block(4,53,-3,LEAVES:4)
Block(4,54,-6,LEAVES:4)
Block(4,54,-5,LEAVES:4)
Block(4,54,-4,LEAVES:4)
Block(5,14,-4,LEAVES:4)
Block(5,15,-4,LEAVES:4)
Block(5,15,-3,LEAVES:4)
Block(5,15,-2,LEAVES:4)
Block(5,16,-5,LEAVES:4)
Block(5,16,-4,LEAVES:4)
Block(5,16,-3,LEAVES:4)
Block(5,16,-2,LEAVES:4)
Block(5,17,-6,LEAVES:4)
Block(5,17,-5,LEAVES:4)
Block(5,17,-4,LEAVES:4)
Block(5,17,-3,LEAVES:4)
Block(5,17,-2,LEAVES:4)
Block(5,18,-7,LEAVES:4)
Block(5,18,-6,LEAVES:4)
Block(5,18,-5,LEAVES:4)
Block(5,18,-4,LEAVES:4)
Block(5,18,-3,LEAVES:4)
Block(5,18,-2,LEAVES:4)
Block(5,18,-1,LEAVES:4)
Block(5,19,-7,LEAVES:4)
Block(5,19,-6,LEAVES:4)
Block(5,19,-5,LEAVES:4)
Block(5,19,-4,LEAVES:4)
Block(5,19,-3,LEAVES:4)
Block(5,19,-2,LEAVES:4)
Block(5,19,-1,LEAVES:4)
Block(5,20,-7,LEAVES:4)
Block(5,20,-6,LEAVES:4)
Block(5,20,-5,LEAVES:4)
Block(5,20,-4,LEAVES:4)
Block(5,20,-3,LEAVES:4)
Block(5,20,-2,LEAVES:4)
Block(5,20,-1,LEAVES:4)
Block(5,20,0,LEAVES:4)
Block(5,21,-7,LEAVES:4)
Block(5,21,-6,LEAVES:4)
Block(5,21,-5,LEAVES:4)
Block(5,21,-4,LEAVES:4)
Block(5,21,-3,LEAVES:4)
Block(5,21,-2,LEAVES:4)
Block(5,21,-1,LEAVES:4)
Block(5,21,0,LEAVES:4)
Block(5,22,-7,LEAVES:4)
Block(5,22,-6,LEAVES:4)
Block(5,22,-5,LEAVES:4)
Block(5,22,-4,LEAVES:4)
Block(5,22,-3,LEAVES:4)
Block(5,22,-2,LEAVES:4)
Block(5,22,-1,LEAVES:4)
Block(5,23,-7,LEAVES:4)
Block(5,23,-6,LEAVES:4)
Block(5,23,-5,LEAVES:4)
Block(5,23,-4,LEAVES:4)
Block(5,23,-3,LEAVES:4)
Block(5,23,-2,LEAVES:4)
Block(5,23,-1,LEAVES:4)
Block(5,24,-7,LEAVES:4)
Block(5,38,-7,LEAVES:3)
Block(5,38,-6,LEAVES:3)
Block(5,38,-5,LEAVES:3)
Block(5,38,-2,LEAVES:3)
Block(5,39,-7,LEAVES:3)
Block(5,39,-6,LEAVES:3)
Block(5,39,-5,LEAVES:3)
Block(5,39,-4,LEAVES:3)
Block(5,39,-3,LEAVES:3)
Block(5,39,-2,LEAVES:3)
Block(5,39,-1,LEAVES:4)
Block(5,40,-6,LEAVES:3)
Block(5,40,-5,LEAVES:3)
Block(5,40,-4,LEAVES:3)
Block(5,40,-3,LEAVES:3)
Block(5,40,-2,LEAVES:3)
Block(5,40,-1,LEAVES:4)
Block(5,40,0,LEAVES:4)
Block(5,41,-7,LEAVES:3)
Block(5,41,-6,LEAVES:3)
Block(5,41,-5,LEAVES:3)
Block(5,41,-4,LEAVES:3)
Block(5,41,-3,LEAVES:3)
Block(5,41,-2,LEAVES:3)
Block(5,41,-1,LEAVES:4)
Block(5,42,-7,LEAVES:3)
Block(5,42,-6,LEAVES:4)
Block(5,42,-5,LEAVES:3)
Block(5,42,-4,LEAVES:3)
Block(5,42,-3,LEAVES:3)
Block(5,42,-2,LEAVES:4)
Block(5,42,-1,LEAVES:4)
Block(5,42,0,LEAVES:4)
Block(5,43,-7,LEAVES:4)
Block(5,43,-6,LEAVES:4)
Block(5,43,-5,LEAVES:4)
Block(5,43,-4,LEAVES:4)
Block(5,43,-3,LEAVES:4)
Block(5,43,-2,LEAVES:4)
Block(5,43,-1,LEAVES:4)
Block(5,44,-7,LEAVES:4)
Block(5,44,-6,LEAVES:4)
Block(5,44,-5,LEAVES:4)
Block(5,44,-4,LEAVES:4)
Block(5,44,-3,LEAVES:4)
Block(5,44,-2,LEAVES:4)
Block(5,45,-7,LEAVES:4)
Block(5,45,-6,LEAVES:4)
Block(5,45,-5,LEAVES:4)
Block(5,45,-4,LEAVES:4)
Block(5,45,-3,LEAVES:4)
Block(5,46,-7,LEAVES:4)
Block(5,46,-6,LEAVES:4)
Block(5,46,-5,LEAVES:4)
Block(5,46,-4,LEAVES:4)
Block(5,46,-3,LEAVES:4)
Block(5,47,-7,LEAVES:4)
Block(5,47,-6,LEAVES:4)
Block(5,47,-5,LEAVES:4)
Block(5,47,-4,LEAVES:4)
Block(5,47,-3,LEAVES:4)
Block(5,48,-7,LEAVES:4)
Block(5,48,-6,LEAVES:4)
Block(5,48,-5,LEAVES:4)
Block(5,49,-7,LEAVES:4)
Block(5,49,-6,LEAVES:4)
Block(5,51,-6,LEAVES:4)
Block(5,52,-7,LEAVES:4)
Block(5,52,-6,LEAVES:4)
Block(5,52,-5,LEAVES:4)
Block(5,53,-7,LEAVES:4)
Block(5,53,-6,LEAVES:4)
Block(5,53,-5,LEAVES:4)
Block(5,53,-4,LEAVES:4)
Block(5,54,-7,LEAVES:4)
Block(5,54,-6,LEAVES:4)
Block(5,54,-5,LEAVES:4)
Block(6,15,-3,LEAVES:4)
Block(6,15,-2,LEAVES:4)
Block(6,16,-6,LEAVES:4)
Block(6,16,-5,LEAVES:4)
Block(6,16,-4,LEAVES:4)
Block(6,16,-3,LEAVES:4)
Block(6,16,-2,LEAVES:4)
Block(6,17,-7,LEAVES:4)
Block(6,17,-6,LEAVES:4)
Block(6,17,-5,LEAVES:4)
Block(6,17,-4,LEAVES:4)
Block(6,17,-3,LEAVES:4)
Block(6,17,-2,LEAVES:4)
Block(6,17,-1,LEAVES:4)
Block(6,18,-7,LEAVES:4)
Block(6,18,-6,LEAVES:4)
Block(6,18,-5,LEAVES:4)
Block(6,18,-4,LEAVES:4)
Block(6,18,-3,LEAVES:4)
Block(6,18,-2,LEAVES:4)
Block(6,18,-1,LEAVES:4)
Block(6,18,0,LEAVES:4)
Block(6,19,-7,LEAVES:4)
Block(6,19,-6,LEAVES:4)
Block(6,19,-5,LEAVES:4)
Block(6,19,-4,LEAVES:4)
Block(6,19,-3,LEAVES:4)
Block(6,19,-2,LEAVES:4)
Block(6,19,-1,LEAVES:4)
Block(6,19,0,LEAVES:4)
Block(6,20,-7,LEAVES:4)
Block(6,20,-6,LEAVES:4)
Block(6,20,-5,LEAVES:4)
Block(6,20,-4,LEAVES:4)
Block(6,20,-3,LEAVES:4)
Block(6,20,-2,LEAVES:4)
Block(6,20,-1,LEAVES:4)
Block(6,20,0,LEAVES:4)
Block(6,21,-7,LEAVES:4)
Block(6,21,-6,LEAVES:4)
Block(6,21,-5,LEAVES:4)
Block(6,21,-4,LEAVES:4)
Block(6,21,-3,LEAVES:4)
Block(6,21,-2,LEAVES:4)
Block(6,21,-1,LEAVES:4)
Block(6,21,0,LEAVES:4)
Block(6,22,-7,LEAVES:4)
Block(6,22,-6,LEAVES:4)
Block(6,22,-5,LEAVES:4)
Block(6,22,-4,LEAVES:4)
Block(6,22,-3,LEAVES:4)
Block(6,22,-2,LEAVES:4)
Block(6,22,-1,LEAVES:4)
Block(6,23,-7,LEAVES:4)
Block(6,23,-6,LEAVES:4)
Block(6,23,-5,LEAVES:4)
Block(6,24,-7,LEAVES:4)
Block(6,37,-6,LEAVES:3)
Block(6,37,-5,LEAVES:3)
Block(6,38,-6,LEAVES:3)
Block(6,38,-5,LEAVES:3)
Block(6,38,-4,LEAVES:3)
Block(6,39,-7,LEAVES:3)
Block(6,39,-6,LEAVES:3)
Block(6,39,-5,LEAVES:3)
Block(6,39,-4,LEAVES:3)
Block(6,39,-3,LEAVES:3)
Block(6,39,-2,LEAVES:3)
Block(6,40,-7,LEAVES:3)
Block(6,40,-6,LEAVES:3)
Block(6,40,-5,LEAVES:3)
Block(6,40,-4,LEAVES:3)
Block(6,40,-3,LEAVES:3)
Block(6,40,-2,LEAVES:3)
Block(6,41,-7,LEAVES:3)
Block(6,41,-6,LEAVES:3)
Block(6,41,-5,LEAVES:3)
Block(6,41,-4,LEAVES:3)
Block(6,41,-3,LEAVES:3)
Block(6,41,-2,LEAVES:3)
Block(6,41,-1,LEAVES:3)
Block(6,41,0,LEAVES:4)
Block(6,42,-7,LEAVES:3)
Block(6,42,-6,LEAVES:3)
Block(6,42,-5,LEAVES:3)
Block(6,42,-4,LEAVES:3)
Block(6,42,-3,LEAVES:3)
Block(6,42,-2,LEAVES:3)
Block(6,42,-1,LEAVES:3)
Block(6,43,-7,LEAVES:3)
Block(6,43,-6,LEAVES:3)
Block(6,43,-5,LEAVES:3)
Block(6,43,-4,LEAVES:3)
Block(6,43,-3,LEAVES:3)
Block(6,43,-2,LEAVES:3)
Block(6,43,-1,LEAVES:4)
Block(6,44,-7,LEAVES:3)
Block(6,44,-6,LEAVES:3)
Block(6,44,-5,LEAVES:4)
Block(6,44,-3,LEAVES:4)
Block(6,45,-7,LEAVES:4)
Block(6,45,-6,LEAVES:4)
Block(6,45,-5,LEAVES:4)
Block(6,45,-4,LEAVES:4)
Block(6,45,-3,LEAVES:4)
Block(6,46,-7,LEAVES:4)
Block(6,46,-6,LEAVES:4)
Block(6,46,-5,LEAVES:4)
Block(6,46,-4,LEAVES:4)
Block(6,46,-3,LEAVES:4)
Block(6,47,-7,LEAVES:4)
Block(6,47,-6,LEAVES:4)
Block(6,47,-5,LEAVES:4)
Block(6,47,-4,LEAVES:4)
Block(6,48,-7,LEAVES:4)
Block(6,48,-6,LEAVES:4)
Block(6,48,-5,LEAVES:4)
Block(6,49,-7,LEAVES:4)
Block(6,49,-6,LEAVES:4)
Block(6,51,-7,LEAVES:3)
Block(6,51,-6,LEAVES:4)
Block(6,52,-7,LEAVES:3)
Block(6,52,-6,LEAVES:4)
Block(6,52,-5,LEAVES:4)
Block(6,53,-7,LEAVES:3)
Block(6,53,-6,LEAVES:4)
Block(6,53,-5,LEAVES:4)
Block(6,53,-4,LEAVES:4)
Block(6,54,-6,LEAVES:4)
Block(6,54,-5,LEAVES:4)
Block(7,16,-7,LEAVES:4)
Block(7,16,-6,LEAVES:4)
Block(7,16,-3,LEAVES:4)
Block(7,16,-2,LEAVES:4)
Block(7,17,-7,LEAVES:4)
Block(7,17,-6,LEAVES:4)
Block(7,17,-5,LEAVES:4)
Block(7,17,-4,LEAVES:4)
Block(7,17,-3,LEAVES:4)
Block(7,17,-2,LEAVES:4)
Block(7,17,-1,LEAVES:4)
Block(7,18,-7,LEAVES:4)
Block(7,18,-6,LEAVES:4)
Block(7,18,-5,LEAVES:4)
Block(7,18,-4,LEAVES:4)
Block(7,18,-3,LEAVES:4)
Block(7,18,-2,LEAVES:4)
Block(7,18,-1,LEAVES:4)
Block(7,18,0,LEAVES:4)
Block(7,19,-7,LEAVES:4)
Block(7,19,-6,LEAVES:4)
Block(7,19,-5,LEAVES:4)
Block(7,19,-4,LEAVES:4)
Block(7,19,-3,LEAVES:4)
Block(7,19,-2,LEAVES:4)
Block(7,19,-1,LEAVES:4)
Block(7,19,0,LEAVES:4)
Block(7,20,-7,LEAVES:4)
Block(7,20,-6,LEAVES:4)
Block(7,20,-5,LEAVES:4)
Block(7,20,-4,LEAVES:4)
Block(7,20,-3,LEAVES:4)
Block(7,20,-2,LEAVES:4)
Block(7,20,-1,LEAVES:4)
Block(7,20,0,LEAVES:4)
Block(7,21,-7,LEAVES:4)
Block(7,21,-6,LEAVES:4)
Block(7,21,-5,LEAVES:4)
Block(7,21,-4,LEAVES:4)
Block(7,21,-3,LEAVES:4)
Block(7,21,-2,LEAVES:4)
Block(7,21,-1,LEAVES:4)
Block(7,21,0,LEAVES:4)
Block(7,22,-7,LEAVES:4)
Block(7,22,-6,LEAVES:4)
Block(7,22,-5,LEAVES:4)
Block(7,22,-4,LEAVES:4)
Block(7,22,-3,LEAVES:4)
Block(7,22,-2,LEAVES:4)
Block(7,22,-1,LEAVES:4)
Block(7,23,-7,LEAVES:4)
Block(7,23,-6,LEAVES:4)
Block(7,23,-2,LEAVES:4)
Block(7,23,-1,LEAVES:4)
Block(7,24,-1,LEAVES:4)
Block(7,37,-6,LEAVES:3)
Block(7,37,-5,LEAVES:3)
Block(7,38,-6,LEAVES:3)
Block(7,38,-5,LEAVES:3)
Block(7,38,-4,LEAVES:3)
Block(7,39,-6,LEAVES:3)
Block(7,39,-5,LEAVES:3)
Block(7,39,-4,LEAVES:3)
Block(7,39,-3,LEAVES:3)
Block(7,39,-2,LEAVES:3)
Block(7,40,-7,LEAVES:3)
Block(7,40,-6,LEAVES:3)
Block(7,40,-5,LEAVES:3)
Block(7,40,-4,LEAVES:3)
Block(7,40,-3,LEAVES:3)
Block(7,40,-2,LEAVES:3)
Block(7,41,-7,LEAVES:3)
Block(7,41,-6,LEAVES:3)
Block(7,41,-5,LEAVES:3)
Block(7,41,-4,LEAVES:3)
Block(7,41,-3,LEAVES:3)
Block(7,41,-2,LEAVES:3)
Block(7,41,-1,LEAVES:3)
Block(7,41,0,LEAVES:3)
Block(7,42,-7,LEAVES:3)
Block(7,42,-6,LEAVES:3)
Block(7,42,-5,LEAVES:3)
Block(7,42,-4,LEAVES:3)
Block(7,42,-3,LEAVES:3)
Block(7,42,-2,LEAVES:3)
Block(7,42,0,LEAVES:3)
Block(7,43,-7,LEAVES:3)
Block(7,43,-6,LEAVES:3)
Block(7,43,-5,LEAVES:3)
Block(7,43,-4,LEAVES:3)
Block(7,43,-3,LEAVES:3)
Block(7,43,-2,LEAVES:3)
Block(7,44,-7,LEAVES:3)
Block(7,44,-6,LEAVES:3)
Block(7,44,-5,LEAVES:3)
Block(7,44,-4,LEAVES:3)
Block(7,44,-3,LEAVES:3)
Block(7,44,-2,LEAVES:3)
Block(7,45,-7,LEAVES:3)
Block(7,45,-6,LEAVES:3)
Block(7,45,-5,LEAVES:3)
Block(7,45,-4,LEAVES:4)
Block(7,45,-3,LEAVES:4)
Block(7,46,-7,LEAVES:4)
Block(7,46,-6,LEAVES:4)
Block(7,46,-5,LEAVES:4)
Block(7,46,-4,LEAVES:4)
Block(7,47,-7,LEAVES:4)
Block(7,47,-6,LEAVES:4)
Block(7,47,-5,LEAVES:4)
Block(7,48,-7,LEAVES:4)
Block(7,48,-6,LEAVES:4)
Block(7,49,-7,LEAVES:3)
Block(7,49,-6,LEAVES:4)
Block(7,50,-7,LEAVES:3)
Block(7,51,-7,LEAVES:3)
Block(7,52,-7,LEAVES:3)
Block(7,52,-6,LEAVES:3)
Block(7,52,-5,LEAVES:4)
Block(7,53,-7,LEAVES:3)
Block(7,53,-6,LEAVES:3)
Block(7,53,-5,LEAVES:4)
Block(7,54,-7,LEAVES:3)
Block(7,54,-6,LEAVES:3)
Block(7,54,-5,LEAVES:4)

#######################################################################
# +-----------------------------------------------------------------+ #
# |                             Branches                            | #
# +-----------------------------------------------------------------+ #
#######################################################################

Branch(0,0,16,true,CorruptedHugeOakC3R4,NORTH,100.0,0)

#######################################################################
# +-----------------------------------------------------------------+ #
# |                             Entities                            | #
# +-----------------------------------------------------------------+ #
#######################################################################


#######################################################################
# +-----------------------------------------------------------------+ #
# |                            Particles                            | #
# +-----------------------------------------------------------------+ #
#######################################################################


#######################################################################
# +-----------------------------------------------------------------+ #
# |                             Spawners                            | #
# +-----------------------------------------------------------------+ #
#######################################################################


#######################################################################
# +-----------------------------------------------------------------+ #
# |                             ModData                             | #
# +-----------------------------------------------------------------+ #
#######################################################################

