
#######################################################################
# +-----------------------------------------------------------------+ #
# |                            BO4 object                           | #
# +-----------------------------------------------------------------+ #
#######################################################################

Author: NLBlackEagle

Description: No description given

SettingsMode: WriteDisable


#######################################################################
# +-----------------------------------------------------------------+ #
# |                          Main settings                          | #
# +-----------------------------------------------------------------+ #
#######################################################################

Frequency: 0

SpawnHeight: highestBlock

UseCenterForHighestBlock: true

##############################
# Height Limits for the BO4. #
##############################

MinHeight: 0

MaxHeight: 255

InheritBO3: 

InheritBO3Rotation: NORTH

OverrideChildSettings: true

OverrideParentHeight: false

CanOverride: false

BranchFrequency: 0

BranchFrequencyGroup: 

MustBeBelowOther: false

MustBeInside: 

CannotBeInside: 

ReplacesBO3: 

MustBeInsideWorldBorders: false

CanSpawnOnWater: true

SpawnOnWaterOnly: false

SpawnUnderWater: false

SpawnAtWaterLevel: false

HeightOffset: 0

RemoveAir: true

ReplaceAbove: 

ReplaceBelow: 

ReplaceWithBiomeBlocks: true

ReplaceWithSurfaceBlock: GRASS

ReplaceWithGroundBlock: DIRT

ReplaceWithStoneBlock: STONE

SmoothRadius: 0

SmoothHeightOffset: 0

SmoothStartTop: false

SmoothStartWood: false

SmoothingSurfaceBlock: 

SmoothingGroundBlock: 

BO3Group: 

IsSpawnPoint: false

DoReplaceBlocks: true


#######################################################################
# +-----------------------------------------------------------------+ #
# |                              Blocks                             | #
# +-----------------------------------------------------------------+ #
#######################################################################

Block(-8,37,7,LEAVES:3)
Block(-8,37,8,LEAVES:3)
Block(-8,38,6,LEAVES:3)
Block(-8,38,7,LEAVES:3)
Block(-8,38,8,LEAVES:3)
Block(-8,39,6,LEAVES:3)
Block(-8,39,7,LEAVES:3)
Block(-8,39,8,LEAVES:3)
Block(-8,40,5,LEAVES:4)
Block(-8,40,6,LEAVES:4)
Block(-8,40,7,LEAVES:4)
Block(-8,40,8,LEAVES:3)
Block(-8,41,5,LEAVES:3)
Block(-8,41,6,LEAVES:3)
Block(-8,41,7,LEAVES:3)
Block(-8,41,8,LEAVES:3)
Block(-8,42,5,LEAVES:3)
Block(-8,42,6,LEAVES:3)
Block(-8,42,8,LEAVES:3)
Block(-8,43,4,LEAVES:3)
Block(-8,43,5,LEAVES:3)
Block(-8,43,6,LEAVES:3)
Block(-8,43,7,LEAVES:3)
Block(-8,43,8,LEAVES:3)
Block(-7,37,6,LEAVES:3)
Block(-7,37,7,LEAVES:3)
Block(-7,37,8,LEAVES:3)
Block(-7,38,5,LEAVES:3)
Block(-7,38,6,LEAVES:3)
Block(-7,38,7,LEAVES:3)
Block(-7,38,8,LEAVES:3)
Block(-7,39,6,LEAVES:3)
Block(-7,39,7,LEAVES:3)
Block(-7,39,8,LEAVES:3)
Block(-7,40,4,LEAVES:3)
Block(-7,40,5,LEAVES:3)
Block(-7,40,6,LEAVES:3)
Block(-7,40,7,LEAVES:3)
Block(-7,40,8,LEAVES:3)
Block(-7,41,4,LEAVES:3)
Block(-7,41,5,LEAVES:3)
Block(-7,41,6,LEAVES:3)
Block(-7,41,7,LEAVES:3)
Block(-7,41,8,LEAVES:3)
Block(-7,42,6,LEAVES:3)
Block(-7,42,7,LEAVES:3)
Block(-7,43,6,LEAVES:3)
Block(-7,43,7,LEAVES:3)
Block(-7,43,8,LEAVES:3)
Block(-7,44,7,LEAVES:3)
Block(-7,45,6,LEAVES:3)
Block(-7,45,7,LEAVES:3)
Block(-7,46,7,LEAVES:3)
Block(-6,37,7,LEAVES:3)
Block(-6,37,8,LEAVES:3)
Block(-6,38,5,LEAVES:3)
Block(-6,38,6,LEAVES:3)
Block(-6,38,7,LEAVES:3)
Block(-6,38,8,LEAVES:3)
Block(-6,39,5,LEAVES:3)
Block(-6,39,6,LEAVES:3)
Block(-6,39,7,LEAVES:3)
Block(-6,39,8,LEAVES:3)
Block(-6,40,4,LEAVES:3)
Block(-6,40,6,LEAVES:3)
Block(-6,40,7,LEAVES:3)
Block(-6,40,8,LEAVES:3)
Block(-6,41,4,LEAVES:3)
Block(-6,41,5,LEAVES:3)
Block(-6,41,6,LEAVES:3)
Block(-6,41,7,LEAVES:3)
Block(-6,41,8,LEAVES:3)
Block(-6,42,4,LEAVES:3)
Block(-6,42,5,LEAVES:3)
Block(-6,42,6,LEAVES:3)
Block(-6,42,7,LEAVES:3)
Block(-6,42,8,LEAVES:3)
Block(-6,43,4,LEAVES:3)
Block(-6,43,5,LEAVES:3)
Block(-6,43,6,LEAVES:3)
Block(-6,43,7,LEAVES:3)
Block(-6,43,8,LEAVES:3)
Block(-6,44,2,LEAVES:3)
Block(-6,44,3,LEAVES:3)
Block(-6,44,4,LEAVES:3)
Block(-6,44,5,LEAVES:3)
Block(-6,44,6,LEAVES:3)
Block(-6,44,7,LEAVES:3)
Block(-6,45,5,LEAVES:3)
Block(-6,45,6,LEAVES:3)
Block(-6,45,7,LEAVES:3)
Block(-6,46,7,LEAVES:3)
Block(-6,46,8,LEAVES:3)
Block(-5,36,7,LEAVES:3)
Block(-5,36,8,LEAVES:3)
Block(-5,37,7,LEAVES:3)
Block(-5,37,8,LEAVES:3)
Block(-5,38,6,LEAVES:3)
Block(-5,38,7,LEAVES:3)
Block(-5,38,8,LEAVES:3)
Block(-5,39,6,LEAVES:3)
Block(-5,39,7,LEAVES:3)
Block(-5,39,8,LEAVES:3)
Block(-5,40,6,LEAVES:3)
Block(-5,40,7,LEAVES:3)
Block(-5,40,8,LEAVES:3)
Block(-5,41,4,LEAVES:3)
Block(-5,41,5,LEAVES:3)
Block(-5,41,6,LEAVES:3)
Block(-5,41,7,LEAVES:3)
Block(-5,41,8,LEAVES:3)
Block(-5,42,3,LEAVES:3)
Block(-5,42,4,LEAVES:3)
Block(-5,42,5,LEAVES:3)
Block(-5,42,6,LEAVES:3)
Block(-5,42,7,LEAVES:3)
Block(-5,42,8,LEAVES:3)
Block(-5,43,2,LEAVES:3)
Block(-5,43,3,LEAVES:3)
Block(-5,43,4,LEAVES:3)
Block(-5,43,5,LEAVES:3)
Block(-5,43,6,LEAVES:3)
Block(-5,43,7,LEAVES:3)
Block(-5,43,8,LEAVES:3)
Block(-5,44,2,LEAVES:3)
Block(-5,44,3,LEAVES:3)
Block(-5,44,4,LEAVES:3)
Block(-5,44,5,LEAVES:3)
Block(-5,44,6,LEAVES:3)
Block(-5,44,7,LEAVES:3)
Block(-5,44,8,LEAVES:3)
Block(-5,45,3,LEAVES:3)
Block(-5,45,4,LEAVES:3)
Block(-5,45,5,LEAVES:3)
Block(-5,45,6,LEAVES:3)
Block(-5,45,7,LEAVES:3)
Block(-5,45,8,LEAVES:3)
Block(-5,46,1,LEAVES:3)
Block(-5,46,2,LEAVES:3)
Block(-5,46,3,LEAVES:3)
Block(-5,46,4,LEAVES:3)
Block(-5,46,5,LEAVES:3)
Block(-5,46,6,LEAVES:3)
Block(-5,46,7,LEAVES:3)
Block(-5,46,8,LEAVES:3)
Block(-5,47,3,LEAVES:3)
Block(-5,47,4,LEAVES:3)
Block(-5,47,6,LEAVES:3)
Block(-5,47,7,LEAVES:3)
Block(-5,47,8,LEAVES:3)
Block(-5,48,3,LEAVES:3)
Block(-5,48,4,LEAVES:3)
Block(-4,35,7,LEAVES:3)
Block(-4,36,-6,LEAVES:4)
Block(-4,36,5,LEAVES:3)
Block(-4,36,6,LEAVES:3)
Block(-4,36,7,LEAVES:3)
Block(-4,36,8,LEAVES:3)
Block(-4,37,-7,LEAVES:4)
Block(-4,37,-6,LEAVES:4)
Block(-4,37,-5,LEAVES:4)
Block(-4,37,5,LEAVES:3)
Block(-4,37,7,LEAVES:3)
Block(-4,37,8,LEAVES:3)
Block(-4,38,-5,LEAVES:4)
Block(-4,38,5,LEAVES:3)
Block(-4,38,6,LEAVES:3)
Block(-4,38,7,LEAVES:3)
Block(-4,38,8,LEAVES:3)
Block(-4,39,3,LEAVES:3)
Block(-4,39,4,LEAVES:3)
Block(-4,39,5,LEAVES:3)
Block(-4,39,6,LEAVES:3)
Block(-4,39,7,LEAVES:3)
Block(-4,39,8,LEAVES:3)
Block(-4,40,3,LEAVES:3)
Block(-4,40,4,LEAVES:3)
Block(-4,40,5,LEAVES:3)
Block(-4,40,6,LEAVES:3)
Block(-4,40,7,LEAVES:3)
Block(-4,40,8,LEAVES:3)
Block(-4,41,2,LEAVES:3)
Block(-4,41,3,LEAVES:3)
Block(-4,41,4,LEAVES:3)
Block(-4,41,5,LEAVES:3)
Block(-4,41,6,LEAVES:3)
Block(-4,41,7,LEAVES:3)
Block(-4,41,8,LEAVES:3)
Block(-4,42,1,LEAVES:3)
Block(-4,42,2,LEAVES:3)
Block(-4,42,3,LEAVES:3)
Block(-4,42,4,LEAVES:3)
Block(-4,42,5,LEAVES:3)
Block(-4,42,6,LEAVES:3)
Block(-4,42,7,LEAVES:3)
Block(-4,42,8,LEAVES:3)
Block(-4,43,0,LEAVES:4)
Block(-4,43,1,LEAVES:3)
Block(-4,43,2,LEAVES:3)
Block(-4,43,3,LEAVES:3)
Block(-4,43,4,LEAVES:3)
Block(-4,43,5,LEAVES:3)
Block(-4,43,6,LEAVES:3)
Block(-4,43,7,LEAVES:3)
Block(-4,43,8,LEAVES:3)
Block(-4,44,0,LEAVES:4)
Block(-4,44,1,LEAVES:3)
Block(-4,44,2,LEAVES:3)
Block(-4,44,3,LEAVES:3)
Block(-4,44,4,LEAVES:3)
Block(-4,44,5,LEAVES:3)
Block(-4,44,6,LEAVES:3)
Block(-4,44,7,LEAVES:3)
Block(-4,44,8,LEAVES:3)
Block(-4,45,1,LEAVES:3)
Block(-4,45,2,LEAVES:3)
Block(-4,45,3,LEAVES:3)
Block(-4,45,4,LEAVES:3)
Block(-4,45,5,LEAVES:3)
Block(-4,45,6,LEAVES:3)
Block(-4,45,7,LEAVES:3)
Block(-4,45,8,LEAVES:3)
Block(-4,46,1,LEAVES:3)
Block(-4,46,2,LEAVES:3)
Block(-4,46,3,LEAVES:3)
Block(-4,46,4,LEAVES:3)
Block(-4,46,5,LEAVES:3)
Block(-4,46,6,LEAVES:3)
Block(-4,46,7,LEAVES:3)
Block(-4,46,8,LEAVES:3)
Block(-4,47,2,LEAVES:3)
Block(-4,47,3,LEAVES:3)
Block(-4,47,4,LEAVES:3)
Block(-4,47,5,LEAVES:3)
Block(-4,47,6,LEAVES:3)
Block(-4,47,7,LEAVES:3)
Block(-4,47,8,LEAVES:3)
Block(-4,48,3,LEAVES:3)
Block(-4,48,4,LEAVES:3)
Block(-4,48,5,LEAVES:3)
Block(-3,34,8,LEAVES:3)
Block(-3,35,6,LEAVES:3)
Block(-3,35,7,LEAVES:3)
Block(-3,35,8,LEAVES:3)
Block(-3,36,-7,LEAVES:4)
Block(-3,36,-6,LEAVES:4)
Block(-3,36,7,LEAVES:3)
Block(-3,36,8,LEAVES:3)
Block(-3,37,-7,LEAVES:4)
Block(-3,37,-6,LEAVES:4)
Block(-3,37,7,LEAVES:3)
Block(-3,37,8,LEAVES:3)
Block(-3,38,3,LEAVES:3)
Block(-3,38,4,LEAVES:3)
Block(-3,38,5,LEAVES:3)
Block(-3,38,6,LEAVES:3)
Block(-3,38,7,LEAVES:3)
Block(-3,38,8,LEAVES:3)
Block(-3,39,3,LEAVES:3)
Block(-3,39,4,LEAVES:3)
Block(-3,39,5,LEAVES:3)
Block(-3,39,6,LEAVES:3)
Block(-3,39,7,LEAVES:3)
Block(-3,39,8,LEAVES:3)
Block(-3,40,2,LEAVES:3)
Block(-3,40,3,LEAVES:3)
Block(-3,40,4,LEAVES:3)
Block(-3,40,5,LEAVES:3)
Block(-3,40,6,LEAVES:3)
Block(-3,40,7,LEAVES:3)
Block(-3,40,8,LEAVES:3)
Block(-3,41,2,LEAVES:3)
Block(-3,41,3,LEAVES:3)
Block(-3,41,4,LEAVES:3)
Block(-3,41,5,LEAVES:3)
Block(-3,41,6,LEAVES:3)
Block(-3,41,7,LEAVES:3)
Block(-3,41,8,LEAVES:3)
Block(-3,42,1,LEAVES:3)
Block(-3,42,2,LEAVES:3)
Block(-3,42,3,LEAVES:3)
Block(-3,42,4,LEAVES:3)
Block(-3,42,5,LEAVES:3)
Block(-3,42,6,LEAVES:3)
Block(-3,42,7,LEAVES:3)
Block(-3,42,8,LEAVES:3)
Block(-3,43,0,LEAVES:4)
Block(-3,43,1,LEAVES:3)
Block(-3,43,2,LEAVES:3)
Block(-3,43,3,LEAVES:3)
Block(-3,43,4,LEAVES:3)
Block(-3,43,5,LEAVES:3)
Block(-3,43,6,LEAVES:3)
Block(-3,43,7,LEAVES:3)
Block(-3,43,8,LEAVES:3)
Block(-3,44,1,LEAVES:3)
Block(-3,44,2,LEAVES:3)
Block(-3,44,3,LEAVES:3)
Block(-3,44,4,LEAVES:3)
Block(-3,44,5,LEAVES:3)
Block(-3,44,6,LEAVES:3)
Block(-3,44,7,LEAVES:3)
Block(-3,44,8,LEAVES:3)
Block(-3,45,1,LEAVES:3)
Block(-3,45,2,LEAVES:3)
Block(-3,45,3,LEAVES:3)
Block(-3,45,4,LEAVES:3)
Block(-3,45,5,LEAVES:3)
Block(-3,45,6,LEAVES:3)
Block(-3,45,7,LEAVES:3)
Block(-3,45,8,LEAVES:3)
Block(-3,46,2,LEAVES:3)
Block(-3,46,3,LEAVES:3)
Block(-3,46,4,LEAVES:3)
Block(-3,46,5,LEAVES:3)
Block(-3,46,6,LEAVES:3)
Block(-3,46,7,LEAVES:3)
Block(-3,46,8,LEAVES:3)
Block(-3,47,2,LEAVES:3)
Block(-3,47,3,LEAVES:3)
Block(-3,47,4,LEAVES:3)
Block(-3,47,5,LEAVES:3)
Block(-3,47,6,LEAVES:3)
Block(-3,47,7,LEAVES:3)
Block(-3,47,8,LEAVES:3)
Block(-3,48,3,LEAVES:3)
Block(-3,48,4,LEAVES:3)
Block(-3,48,5,LEAVES:3)
Block(-2,35,-7,LEAVES:4)
Block(-2,35,6,LEAVES:3)
Block(-2,36,-7,LEAVES:4)
Block(-2,36,-6,LEAVES:4)
Block(-2,36,-5,LEAVES:4)
Block(-2,36,5,LEAVES:3)
Block(-2,36,6,LEAVES:3)
Block(-2,36,8,LEAVES:3)
Block(-2,37,-7,LEAVES:4)
Block(-2,37,-6,LEAVES:4)
Block(-2,37,-5,LEAVES:4)
Block(-2,37,6,LEAVES:3)
Block(-2,37,7,LEAVES:3)
Block(-2,37,8,LEAVES:3)
Block(-2,38,-5,LEAVES:4)
Block(-2,38,3,LEAVES:3)
Block(-2,38,4,LEAVES:3)
Block(-2,38,5,LEAVES:3)
Block(-2,38,6,LEAVES:3)
Block(-2,38,7,LEAVES:3)
Block(-2,38,8,LEAVES:3)
Block(-2,39,0,LEAVES:3)
Block(-2,39,3,LEAVES:3)
Block(-2,39,4,LEAVES:3)
Block(-2,39,5,LEAVES:3)
Block(-2,39,6,LEAVES:3)
Block(-2,39,7,LEAVES:3)
Block(-2,39,8,LEAVES:3)
Block(-2,40,0,LEAVES:3)
Block(-2,40,1,LEAVES:3)
Block(-2,40,2,LEAVES:3)
Block(-2,40,3,LEAVES:3)
Block(-2,40,4,LEAVES:3)
Block(-2,40,5,LEAVES:3)
Block(-2,40,6,LEAVES:3)
Block(-2,40,7,LEAVES:3)
Block(-2,40,8,LEAVES:3)
Block(-2,41,0,LEAVES:3)
Block(-2,41,1,LEAVES:3)
Block(-2,41,2,LEAVES:3)
Block(-2,41,3,LEAVES:3)
Block(-2,41,4,LEAVES:3)
Block(-2,41,5,LEAVES:3)
Block(-2,41,6,LEAVES:3)
Block(-2,41,7,LEAVES:3)
Block(-2,41,8,LEAVES:3)
Block(-2,42,-3,LEAVES:4)
Block(-2,42,-2,LEAVES:4)
Block(-2,42,0,LEAVES:3)
Block(-2,42,1,LEAVES:3)
Block(-2,42,2,LEAVES:3)
Block(-2,42,3,LEAVES:3)
Block(-2,42,4,LEAVES:3)
Block(-2,42,5,LEAVES:3)
Block(-2,42,6,LEAVES:3)
Block(-2,42,7,LEAVES:3)
Block(-2,42,8,LEAVES:3)
Block(-2,43,-3,LEAVES:4)
Block(-2,43,-1,LEAVES:4)
Block(-2,43,0,LEAVES:4)
Block(-2,43,1,LEAVES:3)
Block(-2,43,2,LEAVES:3)
Block(-2,43,3,LEAVES:3)
Block(-2,43,4,LEAVES:3)
Block(-2,43,5,LEAVES:3)
Block(-2,43,6,LEAVES:3)
Block(-2,43,7,LEAVES:3)
Block(-2,43,8,LEAVES:3)
Block(-2,44,0,LEAVES:4)
Block(-2,44,1,LEAVES:4)
Block(-2,44,2,LEAVES:3)
Block(-2,44,3,LEAVES:3)
Block(-2,44,4,LEAVES:3)
Block(-2,44,5,LEAVES:3)
Block(-2,44,6,LEAVES:3)
Block(-2,44,7,LEAVES:3)
Block(-2,44,8,LEAVES:3)
Block(-2,45,1,LEAVES:4)
Block(-2,45,2,LEAVES:3)
Block(-2,45,3,LEAVES:3)
Block(-2,45,4,LEAVES:3)
Block(-2,45,5,LEAVES:3)
Block(-2,45,6,LEAVES:3)
Block(-2,45,7,LEAVES:3)
Block(-2,45,8,LEAVES:3)
Block(-2,46,2,LEAVES:3)
Block(-2,46,3,LEAVES:3)
Block(-2,46,4,LEAVES:3)
Block(-2,46,5,LEAVES:3)
Block(-2,46,6,LEAVES:3)
Block(-2,46,7,LEAVES:3)
Block(-2,46,8,LEAVES:3)
Block(-2,47,2,LEAVES:3)
Block(-2,47,3,LEAVES:3)
Block(-2,47,4,LEAVES:3)
Block(-2,47,5,LEAVES:3)
Block(-2,47,6,LEAVES:3)
Block(-2,47,7,LEAVES:3)
Block(-2,47,8,LEAVES:3)
Block(-2,48,3,LEAVES:3)
Block(-2,48,4,LEAVES:3)
Block(-2,48,5,LEAVES:3)
Block(-2,48,6,LEAVES:3)
Block(-2,49,5,LEAVES:3)
Block(-2,51,0,LEAVES:3)
Block(-2,51,1,LEAVES:3)
Block(-2,52,-1,LEAVES:3)
Block(-2,52,0,LEAVES:3)
Block(-1,32,-6,LEAVES:4)
Block(-1,32,-5,LEAVES:4)
Block(-1,33,-7,LEAVES:4)
Block(-1,33,-6,LEAVES:4)
Block(-1,33,-5,LEAVES:4)
Block(-1,34,-7,LEAVES:4)
Block(-1,34,-6,LEAVES:4)
Block(-1,34,-5,LEAVES:4)
Block(-1,35,-7,LEAVES:4)
Block(-1,35,-6,LEAVES:4)
Block(-1,35,5,LEAVES:3)
Block(-1,35,6,LEAVES:3)
Block(-1,35,7,LEAVES:3)
Block(-1,35,8,LEAVES:3)
Block(-1,36,-7,LEAVES:4)
Block(-1,36,-6,LEAVES:4)
Block(-1,36,-5,LEAVES:4)
Block(-1,36,5,LEAVES:3)
Block(-1,36,6,LEAVES:3)
Block(-1,36,7,LEAVES:3)
Block(-1,37,-7,LEAVES:4)
Block(-1,37,-6,LEAVES:4)
Block(-1,37,-5,LEAVES:4)
Block(-1,37,5,LEAVES:3)
Block(-1,37,6,LEAVES:3)
Block(-1,37,7,LEAVES:3)
Block(-1,37,8,LEAVES:3)
Block(-1,38,-7,LEAVES:4)
Block(-1,38,-2,LEAVES:3)
Block(-1,38,-1,LEAVES:3)
Block(-1,38,0,LEAVES:3)
Block(-1,38,4,LEAVES:3)
Block(-1,38,5,LEAVES:3)
Block(-1,38,6,LEAVES:3)
Block(-1,38,7,LEAVES:3)
Block(-1,38,8,LEAVES:3)
Block(-1,39,-7,LEAVES:4)
Block(-1,39,-2,LEAVES:3)
Block(-1,39,-1,LEAVES:3)
Block(-1,39,0,LEAVES:3)
Block(-1,39,1,LEAVES:3)
Block(-1,39,4,LEAVES:3)
Block(-1,39,5,LEAVES:3)
Block(-1,39,6,LEAVES:3)
Block(-1,39,7,LEAVES:3)
Block(-1,39,8,LEAVES:3)
Block(-1,40,-7,LEAVES:4)
Block(-1,40,-2,LEAVES:3)
Block(-1,40,-1,LEAVES:3)
Block(-1,40,0,LEAVES:3)
Block(-1,40,1,LEAVES:3)
Block(-1,40,2,LEAVES:3)
Block(-1,40,3,LEAVES:3)
Block(-1,40,4,LEAVES:3)
Block(-1,40,5,LEAVES:3)
Block(-1,40,6,LEAVES:3)
Block(-1,40,7,LEAVES:3)
Block(-1,40,8,LEAVES:3)
Block(-1,41,-4,LEAVES:4)
Block(-1,41,-1,LEAVES:3)
Block(-1,41,0,LEAVES:3)
Block(-1,41,1,LEAVES:3)
Block(-1,41,2,LEAVES:3)
Block(-1,41,3,LEAVES:3)
Block(-1,41,4,LEAVES:3)
Block(-1,41,5,LEAVES:3)
Block(-1,41,6,LEAVES:3)
Block(-1,41,7,LEAVES:3)
Block(-1,41,8,LEAVES:3)
Block(-1,42,-5,LEAVES:4)
Block(-1,42,-4,LEAVES:4)
Block(-1,42,-3,LEAVES:4)
Block(-1,42,-2,LEAVES:4)
Block(-1,42,-1,LEAVES:4)
Block(-1,42,0,LEAVES:3)
Block(-1,42,1,LEAVES:3)
Block(-1,42,2,LEAVES:3)
Block(-1,42,3,LEAVES:3)
Block(-1,42,4,LEAVES:3)
Block(-1,42,5,LEAVES:3)
Block(-1,42,6,LEAVES:3)
Block(-1,42,7,LEAVES:3)
Block(-1,42,8,LEAVES:3)
Block(-1,43,-3,LEAVES:4)
Block(-1,43,-2,LEAVES:4)
Block(-1,43,-1,LEAVES:4)
Block(-1,43,1,LEAVES:3)
Block(-1,43,2,LEAVES:3)
Block(-1,43,3,LEAVES:3)
Block(-1,43,4,LEAVES:3)
Block(-1,43,5,LEAVES:3)
Block(-1,43,6,LEAVES:3)
Block(-1,43,7,LEAVES:3)
Block(-1,43,8,LEAVES:3)
Block(-1,44,-2,LEAVES:4)
Block(-1,44,-1,LEAVES:4)
Block(-1,44,0,LEAVES:4)
Block(-1,44,1,LEAVES:4)
Block(-1,44,2,LEAVES:4)
Block(-1,44,3,LEAVES:3)
Block(-1,44,4,LEAVES:3)
Block(-1,44,5,LEAVES:3)
Block(-1,44,6,LEAVES:3)
Block(-1,44,7,LEAVES:3)
Block(-1,44,8,LEAVES:3)
Block(-1,45,0,LEAVES:4)
Block(-1,45,1,LEAVES:4)
Block(-1,45,2,LEAVES:4)
Block(-1,45,3,LEAVES:3)
Block(-1,45,4,LEAVES:3)
Block(-1,45,5,LEAVES:3)
Block(-1,45,6,LEAVES:3)
Block(-1,45,7,LEAVES:3)
Block(-1,45,8,LEAVES:3)
Block(-1,46,1,LEAVES:3)
Block(-1,46,2,LEAVES:3)
Block(-1,46,3,LEAVES:3)
Block(-1,46,4,LEAVES:3)
Block(-1,46,5,LEAVES:3)
Block(-1,46,6,LEAVES:3)
Block(-1,46,7,LEAVES:3)
Block(-1,46,8,LEAVES:3)
Block(-1,47,-2,LEAVES:3)
Block(-1,47,2,LEAVES:3)
Block(-1,47,3,LEAVES:3)
Block(-1,47,4,LEAVES:3)
Block(-1,47,5,LEAVES:3)
Block(-1,47,6,LEAVES:3)
Block(-1,47,7,LEAVES:3)
Block(-1,48,3,LEAVES:3)
Block(-1,48,4,LEAVES:3)
Block(-1,48,5,LEAVES:3)
Block(-1,48,6,LEAVES:3)
Block(-1,48,7,LEAVES:3)
Block(-1,49,3,LEAVES:3)
Block(-1,49,4,LEAVES:3)
Block(-1,49,5,LEAVES:3)
Block(-1,49,6,LEAVES:3)
Block(-1,49,7,LEAVES:4)
Block(-1,49,8,LEAVES:4)
Block(-1,50,5,LEAVES:3)
Block(-1,51,0,LEAVES:3)
Block(-1,52,-1,LEAVES:3)
Block(-1,52,2,LEAVES:3)
Block(-1,53,2,LEAVES:3)
Block(0,31,-6,LEAVES:4)
Block(0,31,-5,LEAVES:4)
Block(0,32,-7,LEAVES:4)
Block(0,32,-6,LEAVES:4)
Block(0,32,-5,LEAVES:4)
Block(0,33,-7,LEAVES:4)
Block(0,33,-6,LEAVES:4)
Block(0,33,-5,LEAVES:4)
Block(0,34,-7,LEAVES:4)
Block(0,34,-6,LEAVES:4)
Block(0,34,-5,LEAVES:4)
Block(0,34,-4,LEAVES:4)
Block(0,35,-7,LEAVES:4)
Block(0,35,-6,LEAVES:4)
Block(0,35,-5,LEAVES:4)
Block(0,35,8,LEAVES:3)
Block(0,36,-7,LEAVES:4)
Block(0,36,-6,LEAVES:4)
Block(0,36,-5,LEAVES:4)
Block(0,36,7,LEAVES:3)
Block(0,36,8,LEAVES:3)
Block(0,37,-7,LEAVES:4)
Block(0,37,-6,LEAVES:4)
Block(0,37,-5,LEAVES:4)
Block(0,37,6,LEAVES:3)
Block(0,37,7,LEAVES:3)
Block(0,37,8,LEAVES:3)
Block(0,38,-7,LEAVES:4)
Block(0,38,-6,LEAVES:4)
Block(0,38,-2,LEAVES:3)
Block(0,38,-1,LEAVES:3)
Block(0,38,0,LEAVES:3)
Block(0,38,5,LEAVES:3)
Block(0,38,6,LEAVES:3)
Block(0,38,7,LEAVES:3)
Block(0,39,-7,LEAVES:4)
Block(0,39,-6,LEAVES:4)
Block(0,39,-5,LEAVES:4)
Block(0,39,-2,LEAVES:3)
Block(0,39,-1,LEAVES:3)
Block(0,39,0,LEAVES:3)
Block(0,39,1,LEAVES:3)
Block(0,39,4,LEAVES:3)
Block(0,39,5,LEAVES:3)
Block(0,39,6,LEAVES:3)
Block(0,39,7,LEAVES:3)
Block(0,39,8,LEAVES:3)
Block(0,40,-7,LEAVES:4)
Block(0,40,-3,LEAVES:4)
Block(0,40,-2,LEAVES:4)
Block(0,40,-1,LEAVES:3)
Block(0,40,0,LEAVES:3)
Block(0,40,1,LEAVES:3)
Block(0,40,2,LEAVES:3)
Block(0,40,4,LEAVES:3)
Block(0,40,5,LEAVES:3)
Block(0,40,6,LEAVES:3)
Block(0,40,7,LEAVES:3)
Block(0,40,8,LEAVES:3)
Block(0,41,-7,LEAVES:4)
Block(0,41,-3,LEAVES:4)
Block(0,41,-2,LEAVES:4)
Block(0,41,-1,LEAVES:3)
Block(0,41,0,LEAVES:3)
Block(0,41,1,LEAVES:3)
Block(0,41,2,LEAVES:3)
Block(0,41,3,LEAVES:3)
Block(0,41,5,LEAVES:3)
Block(0,41,6,LEAVES:3)
Block(0,41,7,LEAVES:3)
Block(0,41,8,LEAVES:3)
Block(0,42,-3,LEAVES:4)
Block(0,42,-2,LEAVES:4)
Block(0,42,-1,LEAVES:4)
Block(0,42,0,LEAVES:3)
Block(0,42,1,LEAVES:3)
Block(0,42,2,LEAVES:3)
Block(0,42,3,LEAVES:3)
Block(0,42,4,LEAVES:3)
Block(0,42,5,LEAVES:3)
Block(0,42,6,LEAVES:3)
Block(0,42,7,LEAVES:3)
Block(0,42,8,LEAVES:3)
Block(0,43,-2,LEAVES:4)
Block(0,43,-1,LEAVES:4)
Block(0,43,1,LEAVES:4)
Block(0,43,2,LEAVES:3)
Block(0,43,3,LEAVES:3)
Block(0,43,4,LEAVES:3)
Block(0,43,5,LEAVES:3)
Block(0,43,6,LEAVES:3)
Block(0,43,7,LEAVES:3)
Block(0,43,8,LEAVES:3)
Block(0,44,1,LEAVES:4)
Block(0,44,2,LEAVES:4)
Block(0,44,3,LEAVES:4)
Block(0,44,4,LEAVES:3)
Block(0,44,5,LEAVES:3)
Block(0,44,6,LEAVES:3)
Block(0,44,7,LEAVES:3)
Block(0,44,8,LEAVES:3)
Block(0,45,-1,LEAVES:4)
Block(0,45,0,LEAVES:4)
Block(0,45,2,LEAVES:4)
Block(0,45,3,LEAVES:4)
Block(0,45,4,LEAVES:3)
Block(0,45,5,LEAVES:3)
Block(0,45,6,LEAVES:3)
Block(0,45,7,LEAVES:3)
Block(0,45,8,LEAVES:3)
Block(0,46,-3,LEAVES:4)
Block(0,46,-1,LEAVES:4)
Block(0,46,2,LEAVES:3)
Block(0,46,3,LEAVES:4)
Block(0,46,4,LEAVES:3)
Block(0,46,5,LEAVES:3)
Block(0,46,6,LEAVES:3)
Block(0,46,7,LEAVES:3)
Block(0,46,8,LEAVES:3)
Block(0,47,-4,LEAVES:4)
Block(0,47,-3,LEAVES:3)
Block(0,47,-2,LEAVES:3)
Block(0,47,-1,LEAVES:3)
Block(0,47,2,LEAVES:3)
Block(0,47,3,LEAVES:3)
Block(0,47,4,LEAVES:3)
Block(0,47,5,LEAVES:3)
Block(0,47,6,LEAVES:3)
Block(0,47,7,LEAVES:3)
Block(0,47,8,LEAVES:4)
Block(0,48,-3,LEAVES:3)
Block(0,48,2,LEAVES:3)
Block(0,48,3,LEAVES:3)
Block(0,48,4,LEAVES:3)
Block(0,48,5,LEAVES:3)
Block(0,48,6,LEAVES:4)
Block(0,48,7,LEAVES:4)
Block(0,48,8,LEAVES:4)
Block(0,49,2,LEAVES:3)
Block(0,49,3,LEAVES:3)
Block(0,49,4,LEAVES:3)
Block(0,49,5,LEAVES:3)
Block(0,49,6,LEAVES:4)
Block(0,49,7,LEAVES:4)
Block(0,49,8,LEAVES:4)
Block(0,50,2,LEAVES:3)
Block(0,50,3,LEAVES:3)
Block(0,50,4,LEAVES:3)
Block(0,50,5,LEAVES:3)
Block(0,50,6,LEAVES:3)
Block(0,50,7,LEAVES:4)
Block(0,50,8,LEAVES:4)
Block(0,51,0,LEAVES:3)
Block(0,51,1,LEAVES:3)
Block(0,51,2,LEAVES:3)
Block(0,51,3,LEAVES:3)
Block(0,51,4,LEAVES:3)
Block(0,52,-1,LEAVES:3)
Block(0,52,0,LEAVES:3)
Block(0,52,1,LEAVES:3)
Block(0,52,2,LEAVES:3)
Block(0,52,3,LEAVES:3)
Block(0,52,4,LEAVES:3)
Block(0,53,0,LEAVES:3)
Block(0,53,2,LEAVES:3)
Block(1,31,-7,LEAVES:4)
Block(1,31,-6,LEAVES:4)
Block(1,31,-5,LEAVES:4)
Block(1,32,-7,LEAVES:4)
Block(1,32,-6,LEAVES:4)
Block(1,32,-5,LEAVES:4)
Block(1,33,-7,LEAVES:4)
Block(1,33,-6,LEAVES:4)
Block(1,33,-5,LEAVES:4)
Block(1,33,-4,LEAVES:4)
Block(1,34,-7,LEAVES:4)
Block(1,34,-6,LEAVES:4)
Block(1,34,-5,LEAVES:4)
Block(1,34,-4,LEAVES:4)
Block(1,35,-7,LEAVES:4)
Block(1,35,-6,LEAVES:4)
Block(1,35,-5,LEAVES:4)
Block(1,36,-7,LEAVES:4)
Block(1,36,-6,LEAVES:4)
Block(1,36,-5,LEAVES:4)
Block(1,37,-7,LEAVES:4)
Block(1,37,-6,LEAVES:4)
Block(1,37,-5,LEAVES:4)
Block(1,38,-7,LEAVES:4)
Block(1,38,-6,LEAVES:4)
Block(1,38,-2,LEAVES:4)
Block(1,38,-1,LEAVES:3)
Block(1,38,0,LEAVES:3)
Block(1,38,1,LEAVES:3)
Block(1,38,7,LEAVES:3)
Block(1,38,8,LEAVES:3)
Block(1,39,-7,LEAVES:4)
Block(1,39,-6,LEAVES:4)
Block(1,39,-5,LEAVES:4)
Block(1,39,-2,LEAVES:4)
Block(1,39,-1,LEAVES:3)
Block(1,39,0,LEAVES:3)
Block(1,39,1,LEAVES:3)
Block(1,39,2,LEAVES:3)
Block(1,39,4,LEAVES:3)
Block(1,39,5,LEAVES:3)
Block(1,39,6,LEAVES:3)
Block(1,39,7,LEAVES:3)
Block(1,39,8,LEAVES:3)
Block(1,40,-6,LEAVES:4)
Block(1,40,-2,LEAVES:4)
Block(1,40,-1,LEAVES:3)
Block(1,40,0,LEAVES:3)
Block(1,40,1,LEAVES:3)
Block(1,40,2,LEAVES:3)
Block(1,40,3,LEAVES:3)
Block(1,40,5,LEAVES:3)
Block(1,40,6,LEAVES:3)
Block(1,40,7,LEAVES:3)
Block(1,40,8,LEAVES:3)
Block(1,41,-1,LEAVES:4)
Block(1,41,0,LEAVES:3)
Block(1,41,1,LEAVES:3)
Block(1,41,2,LEAVES:3)
Block(1,41,3,LEAVES:3)
Block(1,41,4,LEAVES:3)
Block(1,41,5,LEAVES:3)
Block(1,41,6,LEAVES:3)
Block(1,41,7,LEAVES:3)
Block(1,41,8,LEAVES:3)
Block(1,42,-4,LEAVES:4)
Block(1,42,-3,LEAVES:4)
Block(1,42,-2,LEAVES:4)
Block(1,42,-1,LEAVES:4)
Block(1,42,0,LEAVES:4)
Block(1,42,1,LEAVES:3)
Block(1,42,2,LEAVES:3)
Block(1,42,3,LEAVES:3)
Block(1,42,4,LEAVES:3)
Block(1,42,5,LEAVES:3)
Block(1,42,6,LEAVES:3)
Block(1,42,7,LEAVES:3)
Block(1,42,8,LEAVES:3)
Block(1,43,-1,LEAVES:4)
Block(1,43,1,LEAVES:4)
Block(1,43,2,LEAVES:3)
Block(1,43,3,LEAVES:3)
Block(1,43,4,LEAVES:3)
Block(1,43,5,LEAVES:3)
Block(1,43,6,LEAVES:3)
Block(1,43,7,LEAVES:3)
Block(1,43,8,LEAVES:3)
Block(1,44,-4,LEAVES:4)
Block(1,44,-3,LEAVES:4)
Block(1,44,0,LEAVES:4)
Block(1,44,2,LEAVES:4)
Block(1,44,3,LEAVES:3)
Block(1,44,4,LEAVES:3)
Block(1,44,5,LEAVES:3)
Block(1,44,6,LEAVES:3)
Block(1,44,7,LEAVES:3)
Block(1,44,8,LEAVES:4)
Block(1,45,-4,LEAVES:4)
Block(1,45,-3,LEAVES:4)
Block(1,45,0,LEAVES:4)
Block(1,45,2,LEAVES:4)
Block(1,45,3,LEAVES:4)
Block(1,45,4,LEAVES:4)
Block(1,45,5,LEAVES:4)
Block(1,45,6,LEAVES:4)
Block(1,45,7,LEAVES:4)
Block(1,45,8,LEAVES:4)
Block(1,46,-3,LEAVES:3)
Block(1,46,2,LEAVES:4)
Block(1,46,3,LEAVES:4)
Block(1,46,4,LEAVES:4)
Block(1,46,5,LEAVES:4)
Block(1,46,6,LEAVES:4)
Block(1,46,7,LEAVES:4)
Block(1,46,8,LEAVES:4)
Block(1,47,-4,LEAVES:3)
Block(1,47,-3,LEAVES:3)
Block(1,47,-2,LEAVES:3)
Block(1,47,2,LEAVES:3)
Block(1,47,3,LEAVES:3)
Block(1,47,4,LEAVES:4)
Block(1,47,5,LEAVES:4)
Block(1,47,6,LEAVES:4)
Block(1,47,7,LEAVES:4)
Block(1,47,8,LEAVES:4)
Block(1,48,-2,LEAVES:3)
Block(1,48,2,LEAVES:3)
Block(1,48,3,LEAVES:3)
Block(1,48,4,LEAVES:3)
Block(1,48,5,LEAVES:4)
Block(1,48,6,LEAVES:4)
Block(1,48,7,LEAVES:4)
Block(1,48,8,LEAVES:4)
Block(1,49,0,LEAVES:3)
Block(1,49,1,LEAVES:3)
Block(1,49,2,LEAVES:3)
Block(1,49,3,LEAVES:3)
Block(1,49,4,LEAVES:3)
Block(1,49,5,LEAVES:3)
Block(1,49,6,LEAVES:4)
Block(1,49,7,LEAVES:4)
Block(1,49,8,LEAVES:4)
Block(1,50,-1,LEAVES:3)
Block(1,50,0,LEAVES:3)
Block(1,50,1,LEAVES:3)
Block(1,50,2,LEAVES:3)
Block(1,50,3,LEAVES:3)
Block(1,50,4,LEAVES:3)
Block(1,50,5,LEAVES:3)
Block(1,50,6,LEAVES:4)
Block(1,50,7,LEAVES:4)
Block(1,50,8,LEAVES:4)
Block(1,51,0,LEAVES:3)
Block(1,51,1,LEAVES:3)
Block(1,51,2,LEAVES:3)
Block(1,51,3,LEAVES:3)
Block(1,51,4,LEAVES:3)
Block(1,51,5,LEAVES:3)
Block(1,51,8,LEAVES:4)
Block(1,52,-1,LEAVES:3)
Block(1,52,0,LEAVES:3)
Block(1,52,1,LEAVES:3)
Block(1,52,2,LEAVES:3)
Block(1,52,3,LEAVES:3)
Block(1,52,4,LEAVES:3)
Block(1,53,1,LEAVES:3)
Block(1,53,3,LEAVES:3)
Block(1,53,4,LEAVES:3)
Block(1,54,1,LEAVES:3)
Block(2,31,-7,LEAVES:4)
Block(2,31,-6,LEAVES:4)
Block(2,31,-5,LEAVES:4)
Block(2,32,-7,LEAVES:4)
Block(2,32,-6,LEAVES:4)
Block(2,32,-5,LEAVES:4)
Block(2,33,-7,LEAVES:4)
Block(2,33,-6,LEAVES:4)
Block(2,33,-5,LEAVES:4)
Block(2,33,-4,LEAVES:4)
Block(2,34,-7,LEAVES:4)
Block(2,34,-6,LEAVES:4)
Block(2,34,-5,LEAVES:4)
Block(2,34,-4,LEAVES:4)
Block(2,35,-7,LEAVES:4)
Block(2,35,-6,LEAVES:4)
Block(2,35,-5,LEAVES:4)
Block(2,35,-4,LEAVES:4)
Block(2,36,-7,LEAVES:4)
Block(2,36,-6,LEAVES:4)
Block(2,36,-5,LEAVES:4)
Block(2,36,-4,LEAVES:4)
Block(2,37,-7,LEAVES:4)
Block(2,37,-6,LEAVES:4)
Block(2,37,-5,LEAVES:4)
Block(2,38,-7,LEAVES:4)
Block(2,38,-6,LEAVES:4)
Block(2,38,-2,LEAVES:4)
Block(2,38,-1,LEAVES:4)
Block(2,38,0,LEAVES:3)
Block(2,38,1,LEAVES:3)
Block(2,39,-7,LEAVES:4)
Block(2,39,-6,LEAVES:4)
Block(2,39,-2,LEAVES:4)
Block(2,39,-1,LEAVES:4)
Block(2,39,0,LEAVES:3)
Block(2,39,1,LEAVES:3)
Block(2,39,2,LEAVES:3)
Block(2,39,3,LEAVES:3)
Block(2,39,4,LEAVES:3)
Block(2,39,5,LEAVES:3)
Block(2,39,6,LEAVES:3)
Block(2,39,7,LEAVES:3)
Block(2,39,8,LEAVES:3)
Block(2,40,-6,LEAVES:4)
Block(2,40,-2,LEAVES:4)
Block(2,40,-1,LEAVES:4)
Block(2,40,0,LEAVES:3)
Block(2,40,1,LEAVES:3)
Block(2,40,2,LEAVES:3)
Block(2,40,3,LEAVES:3)
Block(2,40,4,LEAVES:3)
Block(2,40,5,LEAVES:3)
Block(2,40,6,LEAVES:3)
Block(2,40,7,LEAVES:3)
Block(2,40,8,LEAVES:3)
Block(2,41,-1,LEAVES:4)
Block(2,41,0,LEAVES:3)
Block(2,41,1,LEAVES:3)
Block(2,41,2,LEAVES:3)
Block(2,41,3,LEAVES:3)
Block(2,41,4,LEAVES:3)
Block(2,41,5,LEAVES:3)
Block(2,41,6,LEAVES:3)
Block(2,41,7,LEAVES:3)
Block(2,41,8,LEAVES:3)
Block(2,42,-1,LEAVES:4)
Block(2,42,0,LEAVES:4)
Block(2,42,1,LEAVES:3)
Block(2,42,2,LEAVES:3)
Block(2,42,3,LEAVES:3)
Block(2,42,4,LEAVES:3)
Block(2,42,5,LEAVES:3)
Block(2,42,6,LEAVES:3)
Block(2,42,7,LEAVES:3)
Block(2,42,8,LEAVES:3)
Block(2,43,-1,LEAVES:4)
Block(2,43,0,LEAVES:4)
Block(2,43,1,LEAVES:4)
Block(2,43,2,LEAVES:3)
Block(2,43,3,LEAVES:3)
Block(2,43,4,LEAVES:3)
Block(2,43,5,LEAVES:3)
Block(2,43,6,LEAVES:3)
Block(2,43,7,LEAVES:3)
Block(2,43,8,LEAVES:3)
Block(2,44,0,LEAVES:4)
Block(2,44,1,LEAVES:4)
Block(2,44,2,LEAVES:4)
Block(2,44,3,LEAVES:3)
Block(2,44,4,LEAVES:3)
Block(2,44,5,LEAVES:3)
Block(2,44,6,LEAVES:3)
Block(2,44,7,LEAVES:3)
Block(2,44,8,LEAVES:4)
Block(2,45,-1,LEAVES:3)
Block(2,45,1,LEAVES:4)
Block(2,45,2,LEAVES:4)
Block(2,45,3,LEAVES:4)
Block(2,45,4,LEAVES:4)
Block(2,45,5,LEAVES:4)
Block(2,45,6,LEAVES:4)
Block(2,45,7,LEAVES:4)
Block(2,45,8,LEAVES:4)
Block(2,46,-5,LEAVES:3)
Block(2,46,-3,LEAVES:3)
Block(2,46,-2,LEAVES:3)
Block(2,46,-1,LEAVES:3)
Block(2,46,0,LEAVES:3)
Block(2,46,1,LEAVES:4)
Block(2,46,2,LEAVES:4)
Block(2,46,3,LEAVES:4)
Block(2,46,4,LEAVES:4)
Block(2,46,5,LEAVES:4)
Block(2,46,6,LEAVES:4)
Block(2,46,7,LEAVES:4)
Block(2,46,8,LEAVES:4)
Block(2,47,-6,LEAVES:3)
Block(2,47,-5,LEAVES:3)
Block(2,47,-4,LEAVES:3)
Block(2,47,-3,LEAVES:3)
Block(2,47,-2,LEAVES:3)
Block(2,47,-1,LEAVES:3)
Block(2,47,2,LEAVES:4)
Block(2,47,3,LEAVES:4)
Block(2,47,4,LEAVES:4)
Block(2,47,5,LEAVES:4)
Block(2,47,6,LEAVES:4)
Block(2,47,7,LEAVES:4)
Block(2,47,8,LEAVES:4)
Block(2,48,-6,LEAVES:3)
Block(2,48,-5,LEAVES:3)
Block(2,48,-4,LEAVES:3)
Block(2,48,-3,LEAVES:3)
Block(2,48,-2,LEAVES:3)
Block(2,48,2,LEAVES:3)
Block(2,48,3,LEAVES:3)
Block(2,48,4,LEAVES:4)
Block(2,48,5,LEAVES:4)
Block(2,48,6,LEAVES:4)
Block(2,48,7,LEAVES:4)
Block(2,48,8,LEAVES:4)
Block(2,49,-3,LEAVES:3)
Block(2,49,0,LEAVES:3)
Block(2,49,1,LEAVES:3)
Block(2,49,2,LEAVES:3)
Block(2,49,3,LEAVES:3)
Block(2,49,4,LEAVES:3)
Block(2,49,5,LEAVES:4)
Block(2,49,6,LEAVES:4)
Block(2,49,7,LEAVES:4)
Block(2,49,8,LEAVES:4)
Block(2,50,-1,LEAVES:3)
Block(2,50,0,LEAVES:3)
Block(2,50,1,LEAVES:3)
Block(2,50,2,LEAVES:3)
Block(2,50,3,LEAVES:3)
Block(2,50,4,LEAVES:3)
Block(2,50,5,LEAVES:4)
Block(2,50,6,LEAVES:4)
Block(2,50,7,LEAVES:4)
Block(2,50,8,LEAVES:4)
Block(2,51,-3,LEAVES:3)
Block(2,51,-2,LEAVES:3)
Block(2,51,-1,LEAVES:3)
Block(2,51,0,LEAVES:3)
Block(2,51,1,LEAVES:3)
Block(2,51,2,LEAVES:3)
Block(2,51,3,LEAVES:3)
Block(2,51,4,LEAVES:3)
Block(2,51,5,LEAVES:4)
Block(2,51,6,LEAVES:4)
Block(2,51,7,LEAVES:4)
Block(2,51,8,LEAVES:4)
Block(2,52,-4,LEAVES:3)
Block(2,52,-3,LEAVES:3)
Block(2,52,-2,LEAVES:3)
Block(2,52,-1,LEAVES:3)
Block(2,52,0,LEAVES:3)
Block(2,52,1,LEAVES:3)
Block(2,52,2,LEAVES:3)
Block(2,52,3,LEAVES:3)
Block(2,52,4,LEAVES:3)
Block(2,52,5,LEAVES:4)
Block(2,53,-4,LEAVES:3)
Block(2,53,-3,LEAVES:3)
Block(2,53,-2,LEAVES:3)
Block(2,53,-1,LEAVES:3)
Block(2,53,1,LEAVES:3)
Block(2,53,2,LEAVES:3)
Block(2,53,3,LEAVES:3)
Block(2,53,4,LEAVES:3)
Block(2,54,-3,LEAVES:3)
Block(2,54,1,LEAVES:3)
Block(2,55,0,LEAVES:3)
Block(2,55,1,LEAVES:3)
Block(3,31,-7,LEAVES:4)
Block(3,31,-6,LEAVES:4)
Block(3,32,-7,LEAVES:4)
Block(3,32,-6,LEAVES:4)
Block(3,32,-5,LEAVES:4)
Block(3,33,-7,LEAVES:4)
Block(3,33,-6,LEAVES:4)
Block(3,33,-5,LEAVES:4)
Block(3,33,-4,LEAVES:4)
Block(3,34,-7,LEAVES:4)
Block(3,34,-6,LEAVES:4)
Block(3,34,-5,LEAVES:4)
Block(3,34,-4,LEAVES:4)
Block(3,35,-7,LEAVES:4)
Block(3,35,-6,LEAVES:4)
Block(3,35,-5,LEAVES:4)
Block(3,35,-4,LEAVES:4)
Block(3,35,-3,LEAVES:4)
Block(3,36,-7,LEAVES:4)
Block(3,36,-6,LEAVES:4)
Block(3,36,-5,LEAVES:4)
Block(3,36,-4,LEAVES:4)
Block(3,36,-3,LEAVES:4)
Block(3,37,-7,LEAVES:4)
Block(3,37,-6,LEAVES:4)
Block(3,37,-5,LEAVES:4)
Block(3,37,-4,LEAVES:4)
Block(3,37,-3,LEAVES:4)
Block(3,37,8,LEAVES:3)
Block(3,38,-7,LEAVES:4)
Block(3,38,-6,LEAVES:4)
Block(3,38,-5,LEAVES:4)
Block(3,38,-4,LEAVES:4)
Block(3,38,-1,LEAVES:4)
Block(3,38,0,LEAVES:3)
Block(3,38,1,LEAVES:3)
Block(3,38,2,LEAVES:3)
Block(3,38,3,LEAVES:3)
Block(3,38,4,LEAVES:3)
Block(3,38,8,LEAVES:3)
Block(3,39,-6,LEAVES:4)
Block(3,39,-5,LEAVES:4)
Block(3,39,-1,LEAVES:4)
Block(3,39,0,LEAVES:3)
Block(3,39,1,LEAVES:3)
Block(3,39,2,LEAVES:3)
Block(3,39,3,LEAVES:3)
Block(3,39,4,LEAVES:3)
Block(3,39,5,LEAVES:3)
Block(3,39,6,LEAVES:3)
Block(3,40,-5,LEAVES:4)
Block(3,40,-1,LEAVES:4)
Block(3,40,0,LEAVES:3)
Block(3,40,1,LEAVES:3)
Block(3,40,2,LEAVES:3)
Block(3,40,3,LEAVES:3)
Block(3,40,4,LEAVES:3)
Block(3,40,5,LEAVES:3)
Block(3,40,6,LEAVES:3)
Block(3,40,7,LEAVES:3)
Block(3,40,8,LEAVES:3)
Block(3,41,-3,LEAVES:4)
Block(3,41,-2,LEAVES:4)
Block(3,41,-1,LEAVES:4)
Block(3,41,0,LEAVES:3)
Block(3,41,1,LEAVES:3)
Block(3,41,2,LEAVES:3)
Block(3,41,3,LEAVES:3)
Block(3,41,4,LEAVES:3)
Block(3,41,5,LEAVES:3)
Block(3,41,6,LEAVES:3)
Block(3,41,7,LEAVES:3)
Block(3,41,8,LEAVES:3)
Block(3,42,-6,LEAVES:4)
Block(3,42,-5,LEAVES:4)
Block(3,42,-4,LEAVES:4)
Block(3,42,-3,LEAVES:4)
Block(3,42,-2,LEAVES:4)
Block(3,42,-1,LEAVES:4)
Block(3,42,0,LEAVES:4)
Block(3,42,1,LEAVES:3)
Block(3,42,2,LEAVES:3)
Block(3,42,3,LEAVES:3)
Block(3,42,4,LEAVES:3)
Block(3,42,5,LEAVES:3)
Block(3,42,6,LEAVES:3)
Block(3,42,7,LEAVES:3)
Block(3,42,8,LEAVES:3)
Block(3,43,-4,LEAVES:4)
Block(3,43,-1,LEAVES:4)
Block(3,43,0,LEAVES:4)
Block(3,43,1,LEAVES:4)
Block(3,43,2,LEAVES:3)
Block(3,43,3,LEAVES:3)
Block(3,43,4,LEAVES:3)
Block(3,43,5,LEAVES:3)
Block(3,43,6,LEAVES:3)
Block(3,43,8,LEAVES:3)
Block(3,44,-4,LEAVES:3)
Block(3,44,-1,LEAVES:3)
Block(3,44,0,LEAVES:4)
Block(3,44,1,LEAVES:4)
Block(3,44,2,LEAVES:4)
Block(3,44,3,LEAVES:3)
Block(3,44,4,LEAVES:3)
Block(3,44,5,LEAVES:3)
Block(3,44,6,LEAVES:3)
Block(3,44,7,LEAVES:3)
Block(3,44,8,LEAVES:4)
Block(3,45,2,LEAVES:4)
Block(3,45,3,LEAVES:4)
Block(3,45,4,LEAVES:4)
Block(3,45,5,LEAVES:4)
Block(3,45,6,LEAVES:4)
Block(3,45,7,LEAVES:4)
Block(3,45,8,LEAVES:4)
Block(3,46,-4,LEAVES:3)
Block(3,46,1,LEAVES:3)
Block(3,46,2,LEAVES:4)
Block(3,46,3,LEAVES:4)
Block(3,46,4,LEAVES:4)
Block(3,46,5,LEAVES:4)
Block(3,46,6,LEAVES:4)
Block(3,46,7,LEAVES:4)
Block(3,46,8,LEAVES:4)
Block(3,47,-5,LEAVES:3)
Block(3,47,-4,LEAVES:3)
Block(3,47,-3,LEAVES:3)
Block(3,47,-2,LEAVES:3)
Block(3,47,-1,LEAVES:3)
Block(3,47,0,LEAVES:3)
Block(3,47,2,LEAVES:4)
Block(3,47,3,LEAVES:4)
Block(3,47,4,LEAVES:4)
Block(3,47,5,LEAVES:4)
Block(3,47,6,LEAVES:4)
Block(3,47,7,LEAVES:4)
Block(3,47,8,LEAVES:4)
Block(3,48,-5,LEAVES:3)
Block(3,48,0,LEAVES:3)
Block(3,48,1,LEAVES:3)
Block(3,48,2,LEAVES:4)
Block(3,48,3,LEAVES:4)
Block(3,48,4,LEAVES:4)
Block(3,48,5,LEAVES:4)
Block(3,48,6,LEAVES:4)
Block(3,48,7,LEAVES:4)
Block(3,48,8,LEAVES:4)
Block(3,49,-3,LEAVES:3)
Block(3,49,0,LEAVES:3)
Block(3,49,1,LEAVES:3)
Block(3,49,2,LEAVES:3)
Block(3,49,3,LEAVES:4)
Block(3,49,4,LEAVES:4)
Block(3,49,5,LEAVES:4)
Block(3,49,6,LEAVES:4)
Block(3,49,7,LEAVES:4)
Block(3,49,8,LEAVES:4)
Block(3,50,-4,LEAVES:3)
Block(3,50,-3,LEAVES:3)
Block(3,50,-2,LEAVES:3)
Block(3,50,-1,LEAVES:3)
Block(3,50,0,LEAVES:3)
Block(3,50,1,LEAVES:3)
Block(3,50,2,LEAVES:3)
Block(3,50,3,LEAVES:3)
Block(3,50,4,LEAVES:4)
Block(3,50,5,LEAVES:4)
Block(3,50,6,LEAVES:4)
Block(3,50,7,LEAVES:4)
Block(3,50,8,LEAVES:4)
Block(3,51,-5,LEAVES:3)
Block(3,51,-4,LEAVES:3)
Block(3,51,-3,LEAVES:3)
Block(3,51,-2,LEAVES:3)
Block(3,51,-1,LEAVES:3)
Block(3,51,0,LEAVES:3)
Block(3,51,1,LEAVES:3)
Block(3,51,2,LEAVES:3)
Block(3,51,3,LEAVES:3)
Block(3,51,4,LEAVES:4)
Block(3,51,5,LEAVES:4)
Block(3,51,6,LEAVES:4)
Block(3,51,7,LEAVES:4)
Block(3,51,8,LEAVES:4)
Block(3,52,-3,LEAVES:3)
Block(3,52,-2,LEAVES:3)
Block(3,52,-1,LEAVES:3)
Block(3,52,0,LEAVES:3)
Block(3,52,1,LEAVES:3)
Block(3,52,2,LEAVES:3)
Block(3,52,3,LEAVES:3)
Block(3,52,4,LEAVES:4)
Block(3,52,5,LEAVES:4)
Block(3,53,-5,LEAVES:3)
Block(3,53,-4,LEAVES:3)
Block(3,53,-3,LEAVES:3)
Block(3,53,-2,LEAVES:3)
Block(3,53,-1,LEAVES:3)
Block(3,53,0,LEAVES:3)
Block(3,53,2,LEAVES:3)
Block(3,53,3,LEAVES:3)
Block(3,53,4,LEAVES:4)
Block(3,54,-5,LEAVES:3)
Block(3,54,-3,LEAVES:3)
Block(3,54,1,LEAVES:3)
Block(3,54,2,LEAVES:3)
Block(3,55,1,LEAVES:3)
Block(4,32,-6,LEAVES:4)
Block(4,33,-6,LEAVES:4)
Block(4,34,-7,LEAVES:4)
Block(4,34,-6,LEAVES:4)
Block(4,34,-5,LEAVES:4)
Block(4,34,-4,LEAVES:4)
Block(4,35,-7,LEAVES:4)
Block(4,35,-6,LEAVES:4)
Block(4,35,-5,LEAVES:4)
Block(4,35,-4,LEAVES:4)
Block(4,35,-3,LEAVES:4)
Block(4,36,-7,LEAVES:4)
Block(4,36,-6,LEAVES:4)
Block(4,36,-5,LEAVES:4)
Block(4,36,-4,LEAVES:4)
Block(4,36,-3,LEAVES:4)
Block(4,37,-7,LEAVES:4)
Block(4,37,-6,LEAVES:4)
Block(4,37,-5,LEAVES:4)
Block(4,37,-4,LEAVES:4)
Block(4,37,-3,LEAVES:4)
Block(4,37,8,LEAVES:3)
Block(4,38,-7,LEAVES:4)
Block(4,38,-6,LEAVES:4)
Block(4,38,-5,LEAVES:4)
Block(4,38,-4,LEAVES:4)
Block(4,38,-3,LEAVES:4)
Block(4,38,-2,LEAVES:4)
Block(4,38,-1,LEAVES:4)
Block(4,38,0,LEAVES:3)
Block(4,38,1,LEAVES:3)
Block(4,38,8,LEAVES:3)
Block(4,39,-7,LEAVES:4)
Block(4,39,-6,LEAVES:4)
Block(4,39,-5,LEAVES:4)
Block(4,39,-4,LEAVES:4)
Block(4,39,-3,LEAVES:4)
Block(4,39,-2,LEAVES:4)
Block(4,39,-1,LEAVES:4)
Block(4,39,0,LEAVES:3)
Block(4,39,1,LEAVES:3)
Block(4,39,2,LEAVES:3)
Block(4,39,3,LEAVES:3)
Block(4,39,4,LEAVES:3)
Block(4,39,5,LEAVES:3)
Block(4,39,6,LEAVES:3)
Block(4,39,7,LEAVES:3)
Block(4,40,-4,LEAVES:4)
Block(4,40,-3,LEAVES:4)
Block(4,40,-2,LEAVES:4)
Block(4,40,-1,LEAVES:4)
Block(4,40,0,LEAVES:3)
Block(4,40,1,LEAVES:3)
Block(4,40,2,LEAVES:3)
Block(4,40,3,LEAVES:3)
Block(4,40,4,LEAVES:3)
Block(4,40,5,LEAVES:3)
Block(4,40,6,LEAVES:3)
Block(4,40,7,LEAVES:3)
Block(4,40,8,LEAVES:3)
Block(4,41,-4,LEAVES:4)
Block(4,41,-3,LEAVES:4)
Block(4,41,-2,LEAVES:4)
Block(4,41,-1,LEAVES:4)
Block(4,41,0,LEAVES:4)
Block(4,41,1,LEAVES:3)
Block(4,41,2,LEAVES:3)
Block(4,41,3,LEAVES:3)
Block(4,41,4,LEAVES:3)
Block(4,41,5,LEAVES:3)
Block(4,41,6,LEAVES:3)
Block(4,41,7,LEAVES:3)
Block(4,41,8,LEAVES:3)
Block(4,42,-4,LEAVES:4)
Block(4,42,-2,LEAVES:4)
Block(4,42,-1,LEAVES:4)
Block(4,42,0,LEAVES:4)
Block(4,42,1,LEAVES:3)
Block(4,42,2,LEAVES:3)
Block(4,42,3,LEAVES:3)
Block(4,42,4,LEAVES:3)
Block(4,42,5,LEAVES:3)
Block(4,42,6,LEAVES:3)
Block(4,42,7,LEAVES:3)
Block(4,42,8,LEAVES:3)
Block(4,43,-5,LEAVES:4)
Block(4,43,-4,LEAVES:3)
Block(4,43,-3,LEAVES:3)
Block(4,43,-2,LEAVES:3)
Block(4,43,-1,LEAVES:4)
Block(4,43,0,LEAVES:4)
Block(4,43,1,LEAVES:4)
Block(4,43,2,LEAVES:3)
Block(4,43,3,LEAVES:3)
Block(4,43,4,LEAVES:3)
Block(4,43,5,LEAVES:3)
Block(4,43,6,LEAVES:3)
Block(4,43,7,LEAVES:3)
Block(4,43,8,LEAVES:3)
Block(4,44,-5,LEAVES:3)
Block(4,44,-4,LEAVES:3)
Block(4,44,-3,LEAVES:3)
Block(4,44,-2,LEAVES:3)
Block(4,44,-1,LEAVES:3)
Block(4,44,0,LEAVES:3)
Block(4,44,1,LEAVES:4)
Block(4,44,2,LEAVES:4)
Block(4,44,3,LEAVES:4)
Block(4,44,4,LEAVES:3)
Block(4,44,5,LEAVES:3)
Block(4,44,6,LEAVES:3)
Block(4,44,7,LEAVES:4)
Block(4,44,8,LEAVES:4)
Block(4,45,0,LEAVES:3)
Block(4,45,1,LEAVES:3)
Block(4,45,2,LEAVES:4)
Block(4,45,3,LEAVES:4)
Block(4,45,4,LEAVES:4)
Block(4,45,5,LEAVES:4)
Block(4,45,6,LEAVES:4)
Block(4,45,7,LEAVES:4)
Block(4,45,8,LEAVES:4)
Block(4,46,0,LEAVES:3)
Block(4,46,1,LEAVES:3)
Block(4,46,2,LEAVES:4)
Block(4,46,3,LEAVES:4)
Block(4,46,4,LEAVES:4)
Block(4,46,5,LEAVES:4)
Block(4,46,6,LEAVES:4)
Block(4,46,7,LEAVES:4)
Block(4,46,8,LEAVES:4)
Block(4,47,-5,LEAVES:3)
Block(4,47,-4,LEAVES:3)
Block(4,47,-3,LEAVES:3)
Block(4,47,-2,LEAVES:3)
Block(4,47,-1,LEAVES:3)
Block(4,47,0,LEAVES:3)
Block(4,47,1,LEAVES:3)
Block(4,47,2,LEAVES:3)
Block(4,47,3,LEAVES:4)
Block(4,47,4,LEAVES:4)
Block(4,47,5,LEAVES:4)
Block(4,47,6,LEAVES:4)
Block(4,47,7,LEAVES:4)
Block(4,47,8,LEAVES:4)
Block(4,48,-5,LEAVES:3)
Block(4,48,-4,LEAVES:3)
Block(4,48,-3,LEAVES:3)
Block(4,48,-1,LEAVES:3)
Block(4,48,0,LEAVES:3)
Block(4,48,1,LEAVES:3)
Block(4,48,2,LEAVES:3)
Block(4,48,3,LEAVES:4)
Block(4,48,4,LEAVES:4)
Block(4,48,5,LEAVES:4)
Block(4,48,6,LEAVES:4)
Block(4,48,7,LEAVES:4)
Block(4,48,8,LEAVES:4)
Block(4,49,-1,LEAVES:3)
Block(4,49,0,LEAVES:3)
Block(4,49,1,LEAVES:3)
Block(4,49,2,LEAVES:3)
Block(4,49,3,LEAVES:4)
Block(4,49,4,LEAVES:4)
Block(4,49,5,LEAVES:4)
Block(4,49,6,LEAVES:4)
Block(4,49,7,LEAVES:4)
Block(4,49,8,LEAVES:4)
Block(4,50,-3,LEAVES:3)
Block(4,50,-2,LEAVES:3)
Block(4,50,-1,LEAVES:3)
Block(4,50,0,LEAVES:3)
Block(4,50,1,LEAVES:3)
Block(4,50,2,LEAVES:3)
Block(4,50,3,LEAVES:4)
Block(4,50,4,LEAVES:4)
Block(4,50,5,LEAVES:4)
Block(4,50,6,LEAVES:4)
Block(4,50,7,LEAVES:4)
Block(4,50,8,LEAVES:4)
Block(4,51,-2,LEAVES:3)
Block(4,51,-1,LEAVES:3)
Block(4,51,1,LEAVES:3)
Block(4,51,2,LEAVES:3)
Block(4,51,3,LEAVES:4)
Block(4,51,4,LEAVES:4)
Block(4,51,5,LEAVES:4)
Block(4,51,6,LEAVES:4)
Block(4,51,7,LEAVES:4)
Block(4,51,8,LEAVES:4)
Block(4,52,1,LEAVES:3)
Block(4,52,2,LEAVES:3)
Block(4,52,3,LEAVES:4)
Block(4,52,4,LEAVES:4)
Block(4,52,5,LEAVES:4)
Block(4,53,-3,LEAVES:3)
Block(4,53,-2,LEAVES:3)
Block(4,53,-1,LEAVES:3)
Block(4,53,0,LEAVES:3)
Block(4,53,1,LEAVES:3)
Block(4,53,2,LEAVES:3)
Block(4,53,3,LEAVES:4)
Block(4,53,4,LEAVES:4)
Block(4,54,-3,LEAVES:3)
Block(4,54,1,LEAVES:3)
Block(4,55,-3,LEAVES:3)
Block(4,55,2,LEAVES:4)
Block(5,34,-7,LEAVES:4)
Block(5,34,-6,LEAVES:4)
Block(5,34,-5,LEAVES:4)
Block(5,35,-7,LEAVES:4)
Block(5,35,-6,LEAVES:4)
Block(5,35,-5,LEAVES:4)
Block(5,35,-4,LEAVES:4)
Block(5,35,-3,LEAVES:4)
Block(5,36,-7,LEAVES:4)
Block(5,36,-6,LEAVES:4)
Block(5,36,-5,LEAVES:4)
Block(5,36,-4,LEAVES:4)
Block(5,36,-3,LEAVES:4)
Block(5,36,-2,LEAVES:4)
Block(5,36,8,LOG:12)
Block(5,37,-7,LEAVES:4)
Block(5,37,-6,LEAVES:4)
Block(5,37,-5,LEAVES:4)
Block(5,37,-4,LEAVES:4)
Block(5,37,-3,LEAVES:4)
Block(5,37,8,LEAVES:3)
Block(5,38,-7,LEAVES:4)
Block(5,38,-6,LEAVES:4)
Block(5,38,-5,LEAVES:4)
Block(5,38,-4,LEAVES:4)
Block(5,38,-3,LEAVES:4)
Block(5,38,-2,LEAVES:4)
Block(5,38,-1,LEAVES:4)
Block(5,38,0,LEAVES:4)
Block(5,38,1,LEAVES:3)
Block(5,38,5,LEAVES:3)
Block(5,38,6,LEAVES:3)
Block(5,38,7,LEAVES:3)
Block(5,38,8,LEAVES:3)
Block(5,39,-7,LEAVES:4)
Block(5,39,-6,LEAVES:4)
Block(5,39,-5,LEAVES:4)
Block(5,39,-4,LEAVES:4)
Block(5,39,-3,LEAVES:4)
Block(5,39,-2,LEAVES:4)
Block(5,39,-1,LEAVES:4)
Block(5,39,0,LEAVES:4)
Block(5,39,1,LEAVES:3)
Block(5,39,2,LEAVES:3)
Block(5,39,3,LEAVES:3)
Block(5,39,4,LEAVES:3)
Block(5,39,5,LEAVES:3)
Block(5,39,6,LEAVES:3)
Block(5,39,7,LEAVES:3)
Block(5,40,-6,LEAVES:4)
Block(5,40,-5,LEAVES:4)
Block(5,40,-4,LEAVES:4)
Block(5,40,-3,LEAVES:4)
Block(5,40,-2,LEAVES:4)
Block(5,40,-1,LEAVES:4)
Block(5,40,0,LEAVES:4)
Block(5,40,1,LEAVES:3)
Block(5,40,2,LEAVES:3)
Block(5,40,3,LEAVES:3)
Block(5,40,4,LEAVES:3)
Block(5,40,5,LEAVES:3)
Block(5,40,6,LEAVES:3)
Block(5,40,7,LEAVES:3)
Block(5,40,8,LEAVES:3)
Block(5,41,-5,LEAVES:4)
Block(5,41,-4,LEAVES:4)
Block(5,41,-3,LEAVES:4)
Block(5,41,-2,LEAVES:4)
Block(5,41,-1,LEAVES:4)
Block(5,41,0,LEAVES:4)
Block(5,41,1,LEAVES:3)
Block(5,41,2,LEAVES:3)
Block(5,41,3,LEAVES:3)
Block(5,41,4,LEAVES:3)
Block(5,41,5,LEAVES:3)
Block(5,41,6,LEAVES:3)
Block(5,41,7,LEAVES:3)
Block(5,41,8,LEAVES:3)
Block(5,42,-6,LEAVES:4)
Block(5,42,-5,LEAVES:4)
Block(5,42,-4,LEAVES:4)
Block(5,42,-3,LEAVES:4)
Block(5,42,-2,LEAVES:4)
Block(5,42,-1,LEAVES:4)
Block(5,42,0,LEAVES:4)
Block(5,42,1,LEAVES:4)
Block(5,42,2,LEAVES:3)
Block(5,42,3,LEAVES:3)
Block(5,42,4,LEAVES:3)
Block(5,42,5,LEAVES:3)
Block(5,42,6,LEAVES:3)
Block(5,42,7,LEAVES:3)
Block(5,42,8,LEAVES:3)
Block(5,43,-6,LEAVES:4)
Block(5,43,-5,LEAVES:3)
Block(5,43,-4,LEAVES:3)
Block(5,43,-3,LEAVES:3)
Block(5,43,-2,LEAVES:3)
Block(5,43,-1,LEAVES:3)
Block(5,43,0,LEAVES:4)
Block(5,43,1,LEAVES:4)
Block(5,43,2,LEAVES:4)
Block(5,43,3,LEAVES:3)
Block(5,43,6,LEAVES:3)
Block(5,43,7,LEAVES:3)
Block(5,43,8,LEAVES:4)
Block(5,44,-5,LEAVES:3)
Block(5,44,-4,LEAVES:3)
Block(5,44,-3,LEAVES:3)
Block(5,44,-2,LEAVES:3)
Block(5,44,-1,LEAVES:3)
Block(5,44,0,LEAVES:3)
Block(5,44,1,LEAVES:4)
Block(5,44,2,LEAVES:4)
Block(5,44,3,LEAVES:4)
Block(5,44,5,LEAVES:4)
Block(5,44,6,LEAVES:4)
Block(5,44,7,LEAVES:4)
Block(5,44,8,LEAVES:4)
Block(5,45,-4,LEAVES:3)
Block(5,45,-3,LEAVES:3)
Block(5,45,-2,LEAVES:3)
Block(5,45,-1,LEAVES:3)
Block(5,45,0,LEAVES:3)
Block(5,45,1,LEAVES:3)
Block(5,45,2,LEAVES:4)
Block(5,45,3,LEAVES:4)
Block(5,45,4,LEAVES:4)
Block(5,45,5,LEAVES:4)
Block(5,45,6,LEAVES:4)
Block(5,45,7,LEAVES:4)
Block(5,45,8,LEAVES:4)
Block(5,46,-4,LEAVES:3)
Block(5,46,-3,LEAVES:3)
Block(5,46,-2,LEAVES:3)
Block(5,46,-1,LEAVES:3)
Block(5,46,0,LEAVES:3)
Block(5,46,1,LEAVES:3)
Block(5,46,2,LEAVES:3)
Block(5,46,3,LEAVES:4)
Block(5,46,4,LEAVES:4)
Block(5,46,5,LEAVES:4)
Block(5,46,6,LEAVES:4)
Block(5,46,7,LEAVES:4)
Block(5,46,8,LEAVES:4)
Block(5,47,-5,LEAVES:3)
Block(5,47,-4,LEAVES:3)
Block(5,47,-3,LEAVES:3)
Block(5,47,-2,LEAVES:3)
Block(5,47,-1,LEAVES:3)
Block(5,47,0,LEAVES:3)
Block(5,47,1,LEAVES:3)
Block(5,47,2,LEAVES:3)
Block(5,47,3,LEAVES:4)
Block(5,47,4,LEAVES:4)
Block(5,47,5,LEAVES:4)
Block(5,47,6,LEAVES:4)
Block(5,47,7,LEAVES:4)
Block(5,47,8,LEAVES:4)
Block(5,48,-5,LEAVES:3)
Block(5,48,-1,LEAVES:3)
Block(5,48,0,LEAVES:3)
Block(5,48,1,LEAVES:3)
Block(5,48,2,LEAVES:3)
Block(5,48,3,LEAVES:4)
Block(5,48,4,LEAVES:4)
Block(5,48,5,LEAVES:4)
Block(5,48,6,LEAVES:4)
Block(5,48,7,LEAVES:4)
Block(5,48,8,LEAVES:4)
Block(5,49,-1,LEAVES:3)
Block(5,49,0,LEAVES:3)
Block(5,49,1,LEAVES:3)
Block(5,49,2,LEAVES:3)
Block(5,49,3,LEAVES:4)
Block(5,49,4,LEAVES:4)
Block(5,49,5,LEAVES:4)
Block(5,49,6,LEAVES:4)
Block(5,49,7,LEAVES:4)
Block(5,49,8,LEAVES:4)
Block(5,50,-2,LEAVES:3)
Block(5,50,-1,LEAVES:3)
Block(5,50,0,LEAVES:3)
Block(5,50,1,LEAVES:3)
Block(5,50,2,LEAVES:3)
Block(5,50,3,LEAVES:4)
Block(5,50,4,LEAVES:4)
Block(5,50,5,LEAVES:4)
Block(5,50,6,LEAVES:4)
Block(5,50,7,LEAVES:4)
Block(5,50,8,LEAVES:4)
Block(5,51,1,LEAVES:3)
Block(5,51,2,LEAVES:4)
Block(5,51,3,LEAVES:4)
Block(5,51,4,LEAVES:4)
Block(5,51,5,LEAVES:4)
Block(5,51,6,LEAVES:4)
Block(5,51,7,LEAVES:4)
Block(5,51,8,LEAVES:4)
Block(5,52,1,LEAVES:3)
Block(5,52,2,LEAVES:4)
Block(5,52,3,LEAVES:4)
Block(5,52,4,LEAVES:4)
Block(5,52,5,LEAVES:4)
Block(5,52,6,LEAVES:4)
Block(5,53,-1,LEAVES:3)
Block(5,53,1,LEAVES:3)
Block(5,53,2,LEAVES:4)
Block(5,53,3,LEAVES:4)
Block(5,53,4,LEAVES:4)
Block(5,53,5,LEAVES:4)
Block(5,54,-4,LEAVES:3)
Block(5,54,-3,LEAVES:3)
Block(5,54,-2,LEAVES:3)
Block(5,54,1,LEAVES:4)
Block(5,54,2,LEAVES:4)
Block(5,54,3,LEAVES:4)
Block(5,55,2,LEAVES:4)
Block(6,32,-7,LEAVES:4)
Block(6,32,-3,LEAVES:4)
Block(6,33,-7,LEAVES:4)
Block(6,33,-3,LEAVES:4)
Block(6,33,-2,LEAVES:4)
Block(6,34,-7,LEAVES:4)
Block(6,34,-6,LEAVES:4)
Block(6,34,-5,LEAVES:4)
Block(6,34,-3,LEAVES:4)
Block(6,34,-2,LEAVES:4)
Block(6,35,-7,LEAVES:4)
Block(6,35,-6,LEAVES:4)
Block(6,35,-5,LEAVES:4)
Block(6,35,-4,LEAVES:4)
Block(6,35,-3,LEAVES:4)
Block(6,35,-2,LEAVES:4)
Block(6,35,-1,LEAVES:4)
Block(6,36,-7,LEAVES:4)
Block(6,36,-6,LEAVES:4)
Block(6,36,-5,LEAVES:4)
Block(6,36,-4,LEAVES:4)
Block(6,36,-3,LEAVES:4)
Block(6,36,-2,LEAVES:4)
Block(6,36,-1,LEAVES:4)
Block(6,36,8,LEAVES:4)
Block(6,37,-7,LEAVES:4)
Block(6,37,-6,LEAVES:4)
Block(6,37,-5,LEAVES:4)
Block(6,37,-4,LEAVES:4)
Block(6,37,1,LEAVES:4)
Block(6,37,5,LEAVES:3)
Block(6,37,7,LEAVES:3)
Block(6,37,8,LEAVES:3)
Block(6,38,-7,LEAVES:4)
Block(6,38,-6,LEAVES:4)
Block(6,38,-5,LEAVES:4)
Block(6,38,-4,LEAVES:4)
Block(6,38,4,LEAVES:3)
Block(6,38,5,LEAVES:3)
Block(6,38,6,LEAVES:3)
Block(6,38,7,LEAVES:3)
Block(6,38,8,LEAVES:3)
Block(6,39,-7,LEAVES:4)
Block(6,39,-5,LEAVES:4)
Block(6,39,-3,LEAVES:4)
Block(6,39,-2,LEAVES:4)
Block(6,39,-1,LEAVES:4)
Block(6,39,0,LEAVES:4)
Block(6,39,1,LEAVES:4)
Block(6,39,2,LEAVES:3)
Block(6,39,3,LEAVES:3)
Block(6,39,4,LEAVES:3)
Block(6,39,5,LEAVES:3)
Block(6,39,6,LEAVES:3)
Block(6,39,7,LEAVES:3)
Block(6,39,8,LEAVES:3)
Block(6,40,-7,LEAVES:4)
Block(6,40,-4,LEAVES:4)
Block(6,40,-3,LEAVES:4)
Block(6,40,-2,LEAVES:4)
Block(6,40,-1,LEAVES:4)
Block(6,40,0,LEAVES:4)
Block(6,40,1,LEAVES:4)
Block(6,40,2,LEAVES:3)
Block(6,40,3,LEAVES:3)
Block(6,40,4,LEAVES:3)
Block(6,40,5,LEAVES:3)
Block(6,40,6,LEAVES:3)
Block(6,40,7,LEAVES:3)
Block(6,40,8,LEAVES:3)
Block(6,41,-7,LEAVES:4)
Block(6,41,-6,LEAVES:4)
Block(6,41,-5,LEAVES:4)
Block(6,41,-4,LEAVES:4)
Block(6,41,-3,LEAVES:4)
Block(6,41,-2,LEAVES:4)
Block(6,41,-1,LEAVES:4)
Block(6,41,0,LEAVES:4)
Block(6,41,1,LEAVES:4)
Block(6,41,2,LEAVES:3)
Block(6,41,3,LEAVES:3)
Block(6,41,4,LEAVES:3)
Block(6,41,5,LEAVES:3)
Block(6,41,6,LEAVES:3)
Block(6,41,7,LEAVES:3)
Block(6,41,8,LEAVES:3)
Block(6,42,-5,LEAVES:4)
Block(6,42,-4,LEAVES:4)
Block(6,42,-3,LEAVES:4)
Block(6,42,-2,LEAVES:4)
Block(6,42,-1,LEAVES:4)
Block(6,42,0,LEAVES:4)
Block(6,42,1,LEAVES:4)
Block(6,42,2,LEAVES:4)
Block(6,42,4,LEAVES:3)
Block(6,42,5,LEAVES:3)
Block(6,42,6,LEAVES:3)
Block(6,42,7,LEAVES:3)
Block(6,43,-6,LEAVES:4)
Block(6,43,-5,LEAVES:3)
Block(6,43,-4,LEAVES:3)
Block(6,43,-3,LEAVES:3)
Block(6,43,-2,LEAVES:3)
Block(6,43,-1,LEAVES:3)
Block(6,43,0,LEAVES:4)
Block(6,43,1,LEAVES:4)
Block(6,43,2,LEAVES:4)
Block(6,43,5,LEAVES:4)
Block(6,43,6,LEAVES:4)
Block(6,43,7,LEAVES:4)
Block(6,43,8,LEAVES:4)
Block(6,44,-7,LEAVES:4)
Block(6,44,-6,LEAVES:3)
Block(6,44,-5,LEAVES:3)
Block(6,44,-4,LEAVES:3)
Block(6,44,-3,LEAVES:3)
Block(6,44,-2,LEAVES:3)
Block(6,44,-1,LEAVES:3)
Block(6,44,0,LEAVES:3)
Block(6,44,1,LEAVES:3)
Block(6,44,2,LEAVES:4)
Block(6,44,5,LEAVES:4)
Block(6,44,6,LEAVES:4)
Block(6,44,7,LEAVES:4)
Block(6,44,8,LEAVES:4)
Block(6,45,-4,LEAVES:3)
Block(6,45,-3,LEAVES:3)
Block(6,45,-2,LEAVES:3)
Block(6,45,0,LEAVES:3)
Block(6,45,1,LEAVES:3)
Block(6,45,2,LEAVES:3)
Block(6,45,3,LEAVES:4)
Block(6,45,4,LEAVES:4)
Block(6,45,5,LEAVES:4)
Block(6,45,6,LEAVES:4)
Block(6,45,7,LEAVES:4)
Block(6,45,8,LEAVES:4)
Block(6,46,-2,LEAVES:3)
Block(6,46,-1,LEAVES:3)
Block(6,46,0,LEAVES:3)
Block(6,46,1,LEAVES:3)
Block(6,46,2,LEAVES:3)
Block(6,46,3,LEAVES:4)
Block(6,46,4,LEAVES:4)
Block(6,46,5,LEAVES:4)
Block(6,46,6,LEAVES:4)
Block(6,46,7,LEAVES:4)
Block(6,46,8,LEAVES:4)
Block(6,47,-4,LEAVES:3)
Block(6,47,-3,LEAVES:3)
Block(6,47,-2,LEAVES:3)
Block(6,47,-1,LEAVES:3)
Block(6,47,0,LEAVES:3)
Block(6,47,1,LEAVES:3)
Block(6,47,2,LEAVES:3)
Block(6,47,3,LEAVES:3)
Block(6,47,4,LEAVES:4)
Block(6,47,5,LEAVES:4)
Block(6,47,6,LEAVES:4)
Block(6,47,7,LEAVES:4)
Block(6,47,8,LEAVES:4)
Block(6,48,-4,LEAVES:3)
Block(6,48,-3,LEAVES:3)
Block(6,48,-2,LEAVES:3)
Block(6,48,-1,LEAVES:3)
Block(6,48,0,LEAVES:3)
Block(6,48,1,LEAVES:3)
Block(6,48,2,LEAVES:3)
Block(6,48,3,LEAVES:3)
Block(6,48,4,LEAVES:4)
Block(6,48,5,LEAVES:4)
Block(6,48,6,LEAVES:4)
Block(6,48,7,LEAVES:4)
Block(6,48,8,LEAVES:4)
Block(6,49,1,LEAVES:3)
Block(6,49,2,LEAVES:3)
Block(6,49,3,LEAVES:3)
Block(6,49,4,LEAVES:4)
Block(6,49,5,LEAVES:4)
Block(6,49,6,LEAVES:4)
Block(6,49,7,LEAVES:4)
Block(6,49,8,LEAVES:4)
Block(6,50,1,LEAVES:3)
Block(6,50,2,LEAVES:3)
Block(6,50,3,LEAVES:4)
Block(6,50,4,LEAVES:4)
Block(6,50,5,LEAVES:4)
Block(6,50,6,LEAVES:4)
Block(6,50,7,LEAVES:4)
Block(6,50,8,LEAVES:4)
Block(6,51,1,LEAVES:3)
Block(6,51,2,LEAVES:3)
Block(6,51,3,LEAVES:4)
Block(6,51,4,LEAVES:4)
Block(6,51,5,LEAVES:4)
Block(6,51,6,LEAVES:4)
Block(6,51,7,LEAVES:4)
Block(6,52,1,LEAVES:3)
Block(6,52,2,LEAVES:4)
Block(6,52,3,LEAVES:4)
Block(6,52,4,LEAVES:4)
Block(6,53,2,LEAVES:4)
Block(6,53,3,LEAVES:4)
Block(7,32,-3,LEAVES:4)
Block(7,33,-7,LEAVES:4)
Block(7,33,-5,LEAVES:4)
Block(7,33,-3,LEAVES:4)
Block(7,33,-2,LEAVES:4)
Block(7,33,-1,LEAVES:4)
Block(7,34,-7,LEAVES:4)
Block(7,34,-6,LEAVES:4)
Block(7,34,-5,LEAVES:4)
Block(7,34,-4,LEAVES:4)
Block(7,34,-3,LEAVES:4)
Block(7,34,-2,LEAVES:4)
Block(7,34,-1,LEAVES:4)
Block(7,34,8,LEAVES:4)
Block(7,35,-7,LEAVES:4)
Block(7,35,-6,LEAVES:4)
Block(7,35,-5,LEAVES:4)
Block(7,35,-4,LEAVES:4)
Block(7,35,-3,LEAVES:4)
Block(7,35,-2,LEAVES:4)
Block(7,35,8,LEAVES:4)
Block(7,36,-7,LEAVES:4)
Block(7,36,-6,LEAVES:4)
Block(7,36,-5,LEAVES:4)
Block(7,36,-4,LEAVES:4)
Block(7,36,-3,LEAVES:4)
Block(7,36,5,LEAVES:4)
Block(7,36,7,LEAVES:4)
Block(7,36,8,LEAVES:4)
Block(7,37,-7,LEAVES:4)
Block(7,37,-6,LEAVES:4)
Block(7,37,-5,LEAVES:4)
Block(7,37,-3,LEAVES:4)
Block(7,37,0,LEAVES:4)
Block(7,37,1,LEAVES:4)
Block(7,37,5,LEAVES:3)
Block(7,37,8,LOG:12)
Block(7,38,-7,LEAVES:4)
Block(7,38,-6,LEAVES:4)
Block(7,38,-5,LEAVES:4)
Block(7,38,-4,LEAVES:4)
Block(7,38,0,LEAVES:4)
Block(7,38,6,LEAVES:3)
Block(7,38,7,LEAVES:3)
Block(7,38,8,LEAVES:4)
Block(7,39,-7,LEAVES:4)
Block(7,39,-6,LEAVES:4)
Block(7,39,-5,LEAVES:4)
Block(7,39,-4,LEAVES:4)
Block(7,39,-3,LEAVES:4)
Block(7,39,-2,LEAVES:4)
Block(7,39,-1,LEAVES:4)
Block(7,39,0,LEAVES:4)
Block(7,39,1,LEAVES:4)
Block(7,39,2,LEAVES:4)
Block(7,39,5,LEAVES:3)
Block(7,39,6,LEAVES:3)
Block(7,39,7,LEAVES:3)
Block(7,39,8,LEAVES:4)
Block(7,40,-7,LEAVES:4)
Block(7,40,-4,LEAVES:4)
Block(7,40,-3,LEAVES:4)
Block(7,40,-2,LEAVES:4)
Block(7,40,-1,LEAVES:4)
Block(7,40,0,LEAVES:4)
Block(7,40,1,LEAVES:4)
Block(7,40,2,LEAVES:4)
Block(7,40,3,LEAVES:3)
Block(7,40,5,LEAVES:3)
Block(7,40,6,LEAVES:3)
Block(7,40,7,LEAVES:3)
Block(7,40,8,LEAVES:4)
Block(7,41,-5,LEAVES:4)
Block(7,41,-4,LEAVES:4)
Block(7,41,-3,LEAVES:4)
Block(7,41,-2,LEAVES:4)
Block(7,41,-1,LEAVES:4)
Block(7,41,0,LEAVES:4)
Block(7,41,1,LEAVES:4)
Block(7,41,2,LEAVES:4)
Block(7,41,3,LEAVES:4)
Block(7,41,4,LEAVES:3)
Block(7,41,5,LEAVES:3)
Block(7,41,6,LEAVES:3)
Block(7,41,7,LEAVES:4)
Block(7,41,8,LEAVES:4)
Block(7,42,-6,LEAVES:4)
Block(7,42,-5,LEAVES:4)
Block(7,42,-4,LEAVES:4)
Block(7,42,-3,LEAVES:4)
Block(7,42,-2,LEAVES:4)
Block(7,42,-1,LEAVES:4)
Block(7,42,0,LEAVES:4)
Block(7,42,1,LEAVES:4)
Block(7,42,2,LEAVES:4)
Block(7,42,3,LEAVES:4)
Block(7,42,4,LEAVES:4)
Block(7,42,5,LEAVES:4)
Block(7,42,7,LEAVES:4)
Block(7,42,8,LEAVES:4)
Block(7,43,-6,LEAVES:4)
Block(7,43,-5,LEAVES:3)
Block(7,43,-4,LEAVES:3)
Block(7,43,-3,LEAVES:3)
Block(7,43,-2,LEAVES:3)
Block(7,43,-1,LEAVES:3)
Block(7,43,0,LEAVES:3)
Block(7,43,1,LEAVES:4)
Block(7,43,2,LEAVES:4)
Block(7,43,4,LEAVES:4)
Block(7,43,5,LEAVES:4)
Block(7,43,6,LEAVES:4)
Block(7,43,7,LEAVES:4)
Block(7,43,8,LEAVES:4)
Block(7,44,-5,LEAVES:3)
Block(7,44,-4,LEAVES:3)
Block(7,44,-3,LEAVES:3)
Block(7,44,-2,LEAVES:3)
Block(7,44,-1,LEAVES:3)
Block(7,44,0,LEAVES:3)
Block(7,44,2,LEAVES:4)
Block(7,44,3,LEAVES:4)
Block(7,44,5,LEAVES:4)
Block(7,44,6,LEAVES:4)
Block(7,44,7,LEAVES:4)
Block(7,44,8,LEAVES:4)
Block(7,45,-5,LEAVES:3)
Block(7,45,-4,LEAVES:3)
Block(7,45,-3,LEAVES:3)
Block(7,45,-2,LEAVES:3)
Block(7,45,-1,LEAVES:3)
Block(7,45,0,LEAVES:3)
Block(7,45,1,LEAVES:3)
Block(7,45,2,LEAVES:3)
Block(7,45,3,LEAVES:4)
Block(7,45,4,LEAVES:4)
Block(7,45,5,LEAVES:4)
Block(7,45,6,LEAVES:4)
Block(7,45,7,LEAVES:4)
Block(7,45,8,LEAVES:4)
Block(7,46,-4,LEAVES:3)
Block(7,46,-3,LEAVES:3)
Block(7,46,-2,LEAVES:3)
Block(7,46,-1,LEAVES:3)
Block(7,46,0,LEAVES:3)
Block(7,46,1,LEAVES:3)
Block(7,46,2,LEAVES:3)
Block(7,46,3,LEAVES:3)
Block(7,46,4,LEAVES:4)
Block(7,46,5,LEAVES:4)
Block(7,46,6,LEAVES:4)
Block(7,46,7,LEAVES:4)
Block(7,46,8,LEAVES:4)
Block(7,47,-4,LEAVES:3)
Block(7,47,-3,LEAVES:3)
Block(7,47,-2,LEAVES:3)
Block(7,47,-1,LEAVES:3)
Block(7,47,1,LEAVES:3)
Block(7,47,2,LEAVES:3)
Block(7,47,3,LEAVES:3)
Block(7,47,4,LEAVES:4)
Block(7,47,5,LEAVES:4)
Block(7,47,6,LEAVES:4)
Block(7,47,7,LEAVES:4)
Block(7,47,8,LEAVES:4)
Block(7,48,-4,LEAVES:3)
Block(7,48,-3,LEAVES:3)
Block(7,48,-2,LEAVES:3)
Block(7,48,-1,LEAVES:3)
Block(7,48,2,LEAVES:3)
Block(7,48,3,LEAVES:3)
Block(7,48,4,LEAVES:4)
Block(7,48,5,LEAVES:4)
Block(7,48,6,LEAVES:4)
Block(7,48,7,LEAVES:4)
Block(7,48,8,LEAVES:4)
Block(7,49,-4,LEAVES:3)
Block(7,49,-2,LEAVES:3)
Block(7,49,2,LEAVES:3)
Block(7,49,3,LEAVES:3)
Block(7,49,4,LEAVES:4)
Block(7,49,5,LEAVES:4)
Block(7,49,6,LEAVES:4)
Block(7,49,7,LEAVES:4)
Block(7,49,8,LEAVES:4)
Block(7,50,1,LEAVES:3)
Block(7,50,2,LEAVES:3)
Block(7,50,3,LEAVES:3)
Block(7,50,4,LEAVES:4)
Block(7,50,5,LEAVES:4)
Block(7,50,6,LEAVES:4)
Block(7,50,7,LEAVES:4)
Block(7,51,1,LEAVES:3)
Block(7,51,2,LEAVES:3)
Block(7,51,3,LEAVES:4)
Block(7,51,4,LEAVES:4)
Block(7,51,5,LEAVES:4)
Block(7,52,1,LEAVES:3)

#######################################################################
# +-----------------------------------------------------------------+ #
# |                             Branches                            | #
# +-----------------------------------------------------------------+ #
#######################################################################

Branch(0,0,16,true,CorruptedHugeOakC1R3,NORTH,100.0,0)

#######################################################################
# +-----------------------------------------------------------------+ #
# |                             Entities                            | #
# +-----------------------------------------------------------------+ #
#######################################################################


#######################################################################
# +-----------------------------------------------------------------+ #
# |                            Particles                            | #
# +-----------------------------------------------------------------+ #
#######################################################################


#######################################################################
# +-----------------------------------------------------------------+ #
# |                             Spawners                            | #
# +-----------------------------------------------------------------+ #
#######################################################################


#######################################################################
# +-----------------------------------------------------------------+ #
# |                             ModData                             | #
# +-----------------------------------------------------------------+ #
#######################################################################

