
#######################################################################
# +-----------------------------------------------------------------+ #
# |                            BO4 object                           | #
# +-----------------------------------------------------------------+ #
#######################################################################

Author: NLBlackEagle

Description: No description given

SettingsMode: WriteDisable


#######################################################################
# +-----------------------------------------------------------------+ #
# |                          Main settings                          | #
# +-----------------------------------------------------------------+ #
#######################################################################

Frequency: 0

SpawnHeight: highestBlock

UseCenterForHighestBlock: true

##############################
# Height Limits for the BO4. #
##############################

MinHeight: 0

MaxHeight: 255

InheritBO3: 

InheritBO3Rotation: NORTH

OverrideChildSettings: true

OverrideParentHeight: false

CanOverride: true

BranchFrequency: 0

BranchFrequencyGroup: 

MustBeBelowOther: false

MustBeInside: 

CannotBeInside: 

ReplacesBO3: 

MustBeInsideWorldBorders: false

CanSpawnOnWater: true

SpawnOnWaterOnly: false

SpawnUnderWater: false

SpawnAtWaterLevel: false

HeightOffset: 0

RemoveAir: true

ReplaceAbove: 

ReplaceBelow: 

ReplaceWithBiomeBlocks: true

ReplaceWithSurfaceBlock: GRASS

ReplaceWithGroundBlock: DIRT

ReplaceWithStoneBlock: STONE

SmoothRadius: 0

SmoothHeightOffset: 0

SmoothStartTop: false

SmoothStartWood: false

SmoothingSurfaceBlock: 

SmoothingGroundBlock: 

BO3Group: 

IsSpawnPoint: false

DoReplaceBlocks: true


#######################################################################
# +-----------------------------------------------------------------+ #
# |                              Blocks                             | #
# +-----------------------------------------------------------------+ #
#######################################################################

Block(-1,61,-7,ICE:0)
Block(-1,62,-7,ICE:0)
Block(0,58,-5,PACKED_ICE:0)
Block(0,59,-7,ICE:0)
Block(0,59,-6,ICE:0)
Block(0,59,-5,PACKED_ICE:0)
Block(0,60,-7,ICE:0)
Block(0,60,-6,ICE:0)
Block(0,61,-7,ICE:0)
Block(0,61,-6,ICE:0)
Block(0,62,-7,ICE:0)
Block(0,62,-6,ICE:0)
Block(0,63,-7,ICE:0)
Block(0,63,-6,ICE:0)
Block(0,64,-7,ICE:0)
Block(0,64,-6,ICE:0)
Block(0,65,-7,ICE:0)
Block(0,65,-6,PACKED_ICE:0)
Block(0,66,-7,PACKED_ICE:0)
Block(0,66,-6,PACKED_ICE:0)
Block(0,67,-7,PACKED_ICE:0)
Block(0,67,-6,PACKED_ICE:0)
Block(0,68,-7,PACKED_ICE:0)
Block(1,55,-3,PACKED_ICE:0)
Block(1,56,-4,ICE:0)
Block(1,56,-3,PACKED_ICE:0)
Block(1,57,-6,ICE:0)
Block(1,57,-5,ICE:0)
Block(1,57,-4,ICE:0)
Block(1,57,-3,PACKED_ICE:0)
Block(1,58,-7,ICE:0)
Block(1,58,-6,ICE:0)
Block(1,58,-5,ICE:0)
Block(1,58,-4,ICE:0)
Block(1,59,-7,ICE:0)
Block(1,59,-6,ICE:0)
Block(1,59,-5,ICE:0)
Block(1,59,-4,PACKED_ICE:0)
Block(1,60,-7,ICE:0)
Block(1,60,-6,ICE:0)
Block(1,60,-5,ICE:0)
Block(1,60,-4,PACKED_ICE:0)
Block(1,61,-7,ICE:0)
Block(1,61,-6,ICE:0)
Block(1,61,-5,ICE:0)
Block(1,61,-4,ICE:0)
Block(1,62,-7,ICE:0)
Block(1,62,-6,ICE:0)
Block(1,62,-5,ICE:0)
Block(1,62,-4,ICE:0)
Block(1,63,-7,ICE:0)
Block(1,63,-6,ICE:0)
Block(1,63,-5,ICE:0)
Block(1,63,-4,ICE:0)
Block(1,64,-7,ICE:0)
Block(1,64,-6,ICE:0)
Block(1,64,-5,ICE:0)
Block(1,64,-4,ICE:0)
Block(1,65,-7,ICE:0)
Block(1,65,-6,ICE:0)
Block(1,65,-5,ICE:0)
Block(1,65,-4,PACKED_ICE:0)
Block(1,66,-7,ICE:0)
Block(1,66,-6,ICE:0)
Block(1,66,-5,PACKED_ICE:0)
Block(1,67,-7,PACKED_ICE:0)
Block(1,67,-6,PACKED_ICE:0)
Block(2,53,-2,ICE:0)
Block(2,53,-1,ICE:0)
Block(2,54,-3,ICE:0)
Block(2,54,-2,ICE:0)
Block(2,54,-1,PACKED_ICE:0)
Block(2,55,-4,ICE:0)
Block(2,55,-3,ICE:0)
Block(2,55,-2,PACKED_ICE:0)
Block(2,56,-6,ICE:0)
Block(2,56,-5,ICE:0)
Block(2,56,-4,ICE:0)
Block(2,56,-3,ICE:0)
Block(2,56,-2,PACKED_ICE:0)
Block(2,57,-7,ICE:0)
Block(2,57,-6,ICE:0)
Block(2,57,-5,ICE:0)
Block(2,57,-4,ICE:0)
Block(2,57,-3,ICE:0)
Block(2,57,-2,PACKED_ICE:0)
Block(2,58,-7,ICE:0)
Block(2,58,-6,ICE:0)
Block(2,58,-5,ICE:0)
Block(2,58,-4,ICE:0)
Block(2,58,-3,ICE:0)
Block(2,58,-2,PACKED_ICE:0)
Block(2,59,-7,ICE:0)
Block(2,59,-6,ICE:0)
Block(2,59,-5,ICE:0)
Block(2,59,-4,ICE:0)
Block(2,59,-3,ICE:0)
Block(2,59,-2,ICE:0)
Block(2,60,-7,ICE:0)
Block(2,60,-6,ICE:0)
Block(2,60,-5,ICE:0)
Block(2,60,-4,ICE:0)
Block(2,60,-3,ICE:0)
Block(2,60,-2,ICE:0)
Block(2,61,-7,ICE:0)
Block(2,61,-6,ICE:0)
Block(2,61,-5,ICE:0)
Block(2,61,-4,ICE:0)
Block(2,61,-3,ICE:0)
Block(2,61,-2,ICE:0)
Block(2,62,-7,ICE:0)
Block(2,62,-6,ICE:0)
Block(2,62,-5,ICE:0)
Block(2,62,-4,ICE:0)
Block(2,62,-3,ICE:0)
Block(2,62,-2,ICE:0)
Block(2,63,-7,ICE:0)
Block(2,63,-6,ICE:0)
Block(2,63,-5,ICE:0)
Block(2,63,-4,ICE:0)
Block(2,63,-3,ICE:0)
Block(2,63,-2,ICE:0)
Block(2,64,-7,ICE:0)
Block(2,64,-6,ICE:0)
Block(2,64,-5,ICE:0)
Block(2,64,-4,ICE:0)
Block(2,64,-3,ICE:0)
Block(2,65,-7,ICE:0)
Block(2,65,-6,ICE:0)
Block(2,65,-5,ICE:0)
Block(2,65,-4,ICE:0)
Block(2,65,-3,ICE:0)
Block(2,66,-7,ICE:0)
Block(2,66,-6,ICE:0)
Block(2,66,-5,ICE:0)
Block(2,67,-7,ICE:0)
Block(3,50,1,ICE:0)
Block(3,51,-1,ICE:0)
Block(3,51,0,ICE:0)
Block(3,51,1,ICE:0)
Block(3,52,-2,ICE:0)
Block(3,52,-1,ICE:0)
Block(3,52,0,ICE:0)
Block(3,52,1,PACKED_ICE:0)
Block(3,53,-3,ICE:0)
Block(3,53,-2,ICE:0)
Block(3,53,-1,ICE:0)
Block(3,53,0,ICE:0)
Block(3,54,-5,ICE:0)
Block(3,54,-4,ICE:0)
Block(3,54,-3,ICE:0)
Block(3,54,-2,ICE:0)
Block(3,54,-1,ICE:0)
Block(3,54,0,PACKED_ICE:0)
Block(3,55,-6,ICE:0)
Block(3,55,-5,ICE:0)
Block(3,55,-4,ICE:0)
Block(3,55,-3,ICE:0)
Block(3,55,-2,ICE:0)
Block(3,55,-1,PACKED_ICE:0)
Block(3,55,0,PACKED_ICE:0)
Block(3,56,-7,ICE:0)
Block(3,56,-6,ICE:0)
Block(3,56,-5,ICE:0)
Block(3,56,-4,ICE:0)
Block(3,56,-3,ICE:0)
Block(3,56,-2,ICE:0)
Block(3,56,-1,PACKED_ICE:0)
Block(3,56,0,ICE:0)
Block(3,57,-7,ICE:0)
Block(3,57,-6,ICE:0)
Block(3,57,-5,ICE:0)
Block(3,57,-4,ICE:0)
Block(3,57,-3,ICE:0)
Block(3,57,-2,ICE:0)
Block(3,57,-1,ICE:0)
Block(3,57,0,ICE:0)
Block(3,58,-7,ICE:0)
Block(3,58,-6,ICE:0)
Block(3,58,-5,ICE:0)
Block(3,58,-4,ICE:0)
Block(3,58,-3,ICE:0)
Block(3,58,-2,ICE:0)
Block(3,58,-1,ICE:0)
Block(3,58,0,ICE:0)
Block(3,59,-7,ICE:0)
Block(3,59,-6,ICE:0)
Block(3,59,-5,ICE:0)
Block(3,59,-4,ICE:0)
Block(3,59,-3,ICE:0)
Block(3,59,-2,ICE:0)
Block(3,59,-1,ICE:0)
Block(3,59,0,ICE:0)
Block(3,60,-7,ICE:0)
Block(3,60,-6,ICE:0)
Block(3,60,-5,ICE:0)
Block(3,60,-4,ICE:0)
Block(3,60,-3,ICE:0)
Block(3,60,-2,ICE:0)
Block(3,60,-1,ICE:0)
Block(3,60,0,ICE:0)
Block(3,61,-7,ICE:0)
Block(3,61,-6,ICE:0)
Block(3,61,-5,ICE:0)
Block(3,61,-4,ICE:0)
Block(3,61,-3,ICE:0)
Block(3,61,-2,ICE:0)
Block(3,61,-1,ICE:0)
Block(3,62,-7,ICE:0)
Block(3,62,-6,ICE:0)
Block(3,62,-5,ICE:0)
Block(3,62,-4,ICE:0)
Block(3,62,-3,ICE:0)
Block(3,62,-2,ICE:0)
Block(3,62,-1,ICE:0)
Block(3,63,-7,ICE:0)
Block(3,63,-6,ICE:0)
Block(3,63,-5,ICE:0)
Block(3,63,-4,ICE:0)
Block(3,63,-3,ICE:0)
Block(3,63,-2,ICE:0)
Block(3,63,-1,ICE:0)
Block(3,64,-7,ICE:0)
Block(3,64,-6,ICE:0)
Block(3,64,-5,ICE:0)
Block(3,64,-4,ICE:0)
Block(3,64,-3,ICE:0)
Block(3,65,-7,ICE:0)
Block(3,65,-6,ICE:0)
Block(3,65,-5,ICE:0)
Block(3,65,-4,ICE:0)
Block(3,66,-7,ICE:0)
Block(3,66,-6,ICE:0)
Block(3,67,-7,ICE:0)
Block(4,47,3,ICE:0)
Block(4,48,2,ICE:0)
Block(4,48,3,ICE:0)
Block(4,49,0,ICE:0)
Block(4,49,1,ICE:0)
Block(4,49,2,ICE:0)
Block(4,49,3,ICE:0)
Block(4,50,-1,ICE:0)
Block(4,50,0,ICE:0)
Block(4,50,1,ICE:0)
Block(4,50,2,ICE:0)
Block(4,50,3,ICE:0)
Block(4,51,-2,ICE:0)
Block(4,51,-1,ICE:0)
Block(4,51,0,ICE:0)
Block(4,51,1,ICE:0)
Block(4,51,2,ICE:0)
Block(4,52,-3,ICE:0)
Block(4,52,-2,ICE:0)
Block(4,52,-1,ICE:0)
Block(4,52,0,ICE:0)
Block(4,52,1,ICE:0)
Block(4,52,2,ICE:0)
Block(4,53,-4,ICE:0)
Block(4,53,-3,ICE:0)
Block(4,53,-2,ICE:0)
Block(4,53,-1,ICE:0)
Block(4,53,0,ICE:0)
Block(4,53,1,PACKED_ICE:0)
Block(4,53,2,PACKED_ICE:0)
Block(4,54,-5,ICE:0)
Block(4,54,-4,ICE:0)
Block(4,54,-3,ICE:0)
Block(4,54,-2,ICE:0)
Block(4,54,-1,ICE:0)
Block(4,54,0,ICE:0)
Block(4,54,1,PACKED_ICE:0)
Block(4,54,2,ICE:0)
Block(4,55,-6,ICE:0)
Block(4,55,-5,ICE:0)
Block(4,55,-4,ICE:0)
Block(4,55,-3,ICE:0)
Block(4,55,-2,ICE:0)
Block(4,55,-1,ICE:0)
Block(4,55,0,PACKED_ICE:0)
Block(4,55,1,ICE:0)
Block(4,55,2,ICE:0)
Block(4,56,-7,ICE:0)
Block(4,56,-6,ICE:0)
Block(4,56,-5,ICE:0)
Block(4,56,-4,ICE:0)
Block(4,56,-3,ICE:0)
Block(4,56,-2,ICE:0)
Block(4,56,-1,ICE:0)
Block(4,56,0,ICE:0)
Block(4,56,1,ICE:0)
Block(4,56,2,ICE:0)
Block(4,57,-7,ICE:0)
Block(4,57,-6,ICE:0)
Block(4,57,-5,ICE:0)
Block(4,57,-4,ICE:0)
Block(4,57,-3,ICE:0)
Block(4,57,-2,ICE:0)
Block(4,57,-1,ICE:0)
Block(4,57,0,ICE:0)
Block(4,57,1,ICE:0)
Block(4,57,2,ICE:0)
Block(4,58,-7,ICE:0)
Block(4,58,-6,ICE:0)
Block(4,58,-5,ICE:0)
Block(4,58,-4,ICE:0)
Block(4,58,-3,ICE:0)
Block(4,58,-2,ICE:0)
Block(4,58,-1,ICE:0)
Block(4,58,0,ICE:0)
Block(4,58,1,ICE:0)
Block(4,58,2,ICE:0)
Block(4,59,-7,ICE:0)
Block(4,59,-6,ICE:0)
Block(4,59,-5,ICE:0)
Block(4,59,-4,ICE:0)
Block(4,59,-3,ICE:0)
Block(4,59,-2,ICE:0)
Block(4,59,-1,ICE:0)
Block(4,59,0,ICE:0)
Block(4,59,1,ICE:0)
Block(4,60,-7,ICE:0)
Block(4,60,-6,ICE:0)
Block(4,60,-5,ICE:0)
Block(4,60,-4,ICE:0)
Block(4,60,-3,ICE:0)
Block(4,60,-2,ICE:0)
Block(4,60,-1,ICE:0)
Block(4,60,0,ICE:0)
Block(4,60,1,ICE:0)
Block(4,61,-7,ICE:0)
Block(4,61,-6,ICE:0)
Block(4,61,-5,ICE:0)
Block(4,61,-4,ICE:0)
Block(4,61,-3,ICE:0)
Block(4,61,-2,ICE:0)
Block(4,61,-1,ICE:0)
Block(4,61,0,ICE:0)
Block(4,61,1,ICE:0)
Block(4,62,-7,ICE:0)
Block(4,62,-6,ICE:0)
Block(4,62,-5,ICE:0)
Block(4,62,-4,ICE:0)
Block(4,62,-3,ICE:0)
Block(4,62,-2,ICE:0)
Block(4,62,-1,ICE:0)
Block(4,62,0,ICE:0)
Block(4,63,-7,ICE:0)
Block(4,63,-6,ICE:0)
Block(4,63,-5,ICE:0)
Block(4,63,-4,ICE:0)
Block(4,63,-3,ICE:0)
Block(4,63,-2,ICE:0)
Block(4,64,-7,ICE:0)
Block(4,64,-6,ICE:0)
Block(4,64,-5,ICE:0)
Block(4,64,-4,ICE:0)
Block(4,64,-3,ICE:0)
Block(4,65,-7,ICE:0)
Block(4,65,-6,ICE:0)
Block(4,65,-5,ICE:0)
Block(4,66,-7,ICE:0)
Block(4,66,-6,ICE:0)
Block(5,45,4,ICE:0)
Block(5,45,5,ICE:0)
Block(5,46,3,ICE:0)
Block(5,46,4,ICE:0)
Block(5,46,5,ICE:0)
Block(5,47,2,ICE:0)
Block(5,47,3,ICE:0)
Block(5,47,4,ICE:0)
Block(5,47,5,ICE:0)
Block(5,48,0,ICE:0)
Block(5,48,1,ICE:0)
Block(5,48,2,ICE:0)
Block(5,48,3,ICE:0)
Block(5,48,4,ICE:0)
Block(5,49,-1,ICE:0)
Block(5,49,0,ICE:0)
Block(5,49,1,ICE:0)
Block(5,49,2,ICE:0)
Block(5,49,3,ICE:0)
Block(5,49,4,ICE:0)
Block(5,50,-2,ICE:0)
Block(5,50,-1,ICE:0)
Block(5,50,0,ICE:0)
Block(5,50,1,ICE:0)
Block(5,50,2,ICE:0)
Block(5,50,3,ICE:0)
Block(5,50,4,ICE:0)
Block(5,51,-3,ICE:0)
Block(5,51,-2,ICE:0)
Block(5,51,-1,ICE:0)
Block(5,51,0,ICE:0)
Block(5,51,1,ICE:0)
Block(5,51,2,ICE:0)
Block(5,51,3,ICE:0)
Block(5,51,4,ICE:0)
Block(5,52,-4,ICE:0)
Block(5,52,-3,ICE:0)
Block(5,52,-2,ICE:0)
Block(5,52,-1,ICE:0)
Block(5,52,0,ICE:0)
Block(5,52,1,ICE:0)
Block(5,52,2,ICE:0)
Block(5,52,3,ICE:0)
Block(5,52,4,PACKED_ICE:0)
Block(5,53,-5,ICE:0)
Block(5,53,-4,ICE:0)
Block(5,53,-3,ICE:0)
Block(5,53,-2,ICE:0)
Block(5,53,-1,ICE:0)
Block(5,53,0,ICE:0)
Block(5,53,1,ICE:0)
Block(5,53,2,PACKED_ICE:0)
Block(5,53,3,ICE:0)
Block(5,53,4,ICE:0)
Block(5,54,-6,ICE:0)
Block(5,54,-5,ICE:0)
Block(5,54,-4,ICE:0)
Block(5,54,-3,ICE:0)
Block(5,54,-2,ICE:0)
Block(5,54,-1,ICE:0)
Block(5,54,0,ICE:0)
Block(5,54,1,ICE:0)
Block(5,54,2,ICE:0)
Block(5,54,3,ICE:0)
Block(5,54,4,ICE:0)
Block(5,55,-6,ICE:0)
Block(5,55,-5,ICE:0)
Block(5,55,-4,ICE:0)
Block(5,55,-3,ICE:0)
Block(5,55,-2,ICE:0)
Block(5,55,-1,ICE:0)
Block(5,55,0,ICE:0)
Block(5,55,1,ICE:0)
Block(5,55,2,ICE:0)
Block(5,55,3,ICE:0)
Block(5,55,4,ICE:0)
Block(5,56,-7,ICE:0)
Block(5,56,-6,ICE:0)
Block(5,56,-5,ICE:0)
Block(5,56,-4,ICE:0)
Block(5,56,-3,ICE:0)
Block(5,56,-2,ICE:0)
Block(5,56,-1,ICE:0)
Block(5,56,0,ICE:0)
Block(5,56,1,ICE:0)
Block(5,56,2,ICE:0)
Block(5,56,3,ICE:0)
Block(5,56,4,ICE:0)
Block(5,57,-7,ICE:0)
Block(5,57,-6,ICE:0)
Block(5,57,-5,ICE:0)
Block(5,57,-4,ICE:0)
Block(5,57,-3,ICE:0)
Block(5,57,-2,ICE:0)
Block(5,57,-1,ICE:0)
Block(5,57,0,ICE:0)
Block(5,57,1,ICE:0)
Block(5,57,2,ICE:0)
Block(5,57,3,ICE:0)
Block(5,58,-7,ICE:0)
Block(5,58,-6,ICE:0)
Block(5,58,-5,ICE:0)
Block(5,58,-4,ICE:0)
Block(5,58,-3,ICE:0)
Block(5,58,-2,ICE:0)
Block(5,58,-1,ICE:0)
Block(5,58,0,ICE:0)
Block(5,58,1,ICE:0)
Block(5,58,2,ICE:0)
Block(5,58,3,ICE:0)
Block(5,59,-7,ICE:0)
Block(5,59,-6,ICE:0)
Block(5,59,-5,ICE:0)
Block(5,59,-4,ICE:0)
Block(5,59,-3,ICE:0)
Block(5,59,-2,ICE:0)
Block(5,59,-1,ICE:0)
Block(5,59,0,ICE:0)
Block(5,59,1,ICE:0)
Block(5,59,2,ICE:0)
Block(5,59,3,ICE:0)
Block(5,60,-7,ICE:0)
Block(5,60,-6,ICE:0)
Block(5,60,-5,ICE:0)
Block(5,60,-4,ICE:0)
Block(5,60,-3,ICE:0)
Block(5,60,-2,ICE:0)
Block(5,60,-1,ICE:0)
Block(5,60,0,ICE:0)
Block(5,60,1,ICE:0)
Block(5,60,2,ICE:0)
Block(5,60,3,ICE:0)
Block(5,61,-7,ICE:0)
Block(5,61,-6,ICE:0)
Block(5,61,-5,ICE:0)
Block(5,61,-4,ICE:0)
Block(5,61,-3,ICE:0)
Block(5,61,-2,ICE:0)
Block(5,61,-1,ICE:0)
Block(5,61,0,ICE:0)
Block(5,61,1,ICE:0)
Block(5,62,-7,ICE:0)
Block(5,62,-6,ICE:0)
Block(5,62,-5,ICE:0)
Block(5,62,-4,ICE:0)
Block(5,62,-3,ICE:0)
Block(5,62,-2,ICE:0)
Block(5,62,-1,ICE:0)
Block(5,63,-7,ICE:0)
Block(5,63,-6,ICE:0)
Block(5,63,-5,ICE:0)
Block(5,63,-4,ICE:0)
Block(5,63,-3,ICE:0)
Block(5,63,-2,ICE:0)
Block(5,64,-7,ICE:0)
Block(5,64,-6,ICE:0)
Block(5,64,-5,ICE:0)
Block(5,64,-4,ICE:0)
Block(5,65,-7,ICE:0)
Block(5,65,-6,ICE:0)
Block(6,42,7,ICE:0)
Block(6,43,5,ICE:0)
Block(6,43,6,ICE:0)
Block(6,43,7,ICE:0)
Block(6,44,4,ICE:0)
Block(6,44,5,ICE:0)
Block(6,44,6,ICE:0)
Block(6,44,7,ICE:0)
Block(6,45,3,ICE:0)
Block(6,45,4,ICE:0)
Block(6,45,5,ICE:0)
Block(6,45,6,ICE:0)
Block(6,45,7,ICE:0)
Block(6,46,1,ICE:0)
Block(6,46,2,ICE:0)
Block(6,46,3,ICE:0)
Block(6,46,4,ICE:0)
Block(6,46,5,ICE:0)
Block(6,46,6,ICE:0)
Block(6,47,0,ICE:0)
Block(6,47,1,ICE:0)
Block(6,47,2,ICE:0)
Block(6,47,3,ICE:0)
Block(6,47,4,ICE:0)
Block(6,47,5,ICE:0)
Block(6,47,6,ICE:0)
Block(6,48,-1,ICE:0)
Block(6,48,0,ICE:0)
Block(6,48,1,ICE:0)
Block(6,48,2,ICE:0)
Block(6,48,3,ICE:0)
Block(6,48,4,ICE:0)
Block(6,48,5,ICE:0)
Block(6,48,6,ICE:0)
Block(6,49,-2,ICE:0)
Block(6,49,-1,ICE:0)
Block(6,49,0,ICE:0)
Block(6,49,1,ICE:0)
Block(6,49,2,ICE:0)
Block(6,49,3,ICE:0)
Block(6,49,4,ICE:0)
Block(6,49,5,ICE:0)
Block(6,49,6,ICE:0)
Block(6,50,-3,ICE:0)
Block(6,50,-2,ICE:0)
Block(6,50,-1,ICE:0)
Block(6,50,0,ICE:0)
Block(6,50,1,ICE:0)
Block(6,50,2,ICE:0)
Block(6,50,3,ICE:0)
Block(6,50,4,ICE:0)
Block(6,50,5,ICE:0)
Block(6,50,6,PACKED_ICE:0)
Block(6,51,-4,ICE:0)
Block(6,51,-3,ICE:0)
Block(6,51,-2,ICE:0)
Block(6,51,-1,ICE:0)
Block(6,51,0,ICE:0)
Block(6,51,1,ICE:0)
Block(6,51,2,ICE:0)
Block(6,51,3,ICE:0)
Block(6,51,4,ICE:0)
Block(6,51,5,PACKED_ICE:0)
Block(6,51,6,ICE:0)
Block(6,52,-4,ICE:0)
Block(6,52,-3,ICE:0)
Block(6,52,-2,ICE:0)
Block(6,52,-1,ICE:0)
Block(6,52,0,ICE:0)
Block(6,52,1,ICE:0)
Block(6,52,2,ICE:0)
Block(6,52,3,ICE:0)
Block(6,52,4,PACKED_ICE:0)
Block(6,52,5,ICE:0)
Block(6,52,6,ICE:0)
Block(6,53,-5,ICE:0)
Block(6,53,-4,ICE:0)
Block(6,53,-3,ICE:0)
Block(6,53,-2,ICE:0)
Block(6,53,-1,ICE:0)
Block(6,53,0,ICE:0)
Block(6,53,1,ICE:0)
Block(6,53,2,ICE:0)
Block(6,53,3,ICE:0)
Block(6,53,4,ICE:0)
Block(6,53,5,ICE:0)
Block(6,53,6,ICE:0)
Block(6,54,-6,ICE:0)
Block(6,54,-5,ICE:0)
Block(6,54,-4,ICE:0)
Block(6,54,-3,ICE:0)
Block(6,54,-2,ICE:0)
Block(6,54,-1,ICE:0)
Block(6,54,0,ICE:0)
Block(6,54,1,ICE:0)
Block(6,54,2,ICE:0)
Block(6,54,3,ICE:0)
Block(6,54,4,ICE:0)
Block(6,54,5,ICE:0)
Block(6,55,-7,ICE:0)
Block(6,55,-6,ICE:0)
Block(6,55,-5,ICE:0)
Block(6,55,-4,ICE:0)
Block(6,55,-3,ICE:0)
Block(6,55,-2,ICE:0)
Block(6,55,-1,ICE:0)
Block(6,55,0,ICE:0)
Block(6,55,1,ICE:0)
Block(6,55,2,ICE:0)
Block(6,55,3,ICE:0)
Block(6,55,4,ICE:0)
Block(6,55,5,ICE:0)
Block(6,56,-7,ICE:0)
Block(6,56,-6,ICE:0)
Block(6,56,-5,ICE:0)
Block(6,56,-4,ICE:0)
Block(6,56,-3,ICE:0)
Block(6,56,-2,ICE:0)
Block(6,56,-1,ICE:0)
Block(6,56,0,ICE:0)
Block(6,56,1,ICE:0)
Block(6,56,2,ICE:0)
Block(6,56,3,ICE:0)
Block(6,56,4,ICE:0)
Block(6,56,5,ICE:0)
Block(6,57,-7,ICE:0)
Block(6,57,-6,ICE:0)
Block(6,57,-5,ICE:0)
Block(6,57,-4,ICE:0)
Block(6,57,-3,ICE:0)
Block(6,57,-2,ICE:0)
Block(6,57,-1,ICE:0)
Block(6,57,0,ICE:0)
Block(6,57,1,ICE:0)
Block(6,57,2,ICE:0)
Block(6,57,3,ICE:0)
Block(6,57,4,ICE:0)
Block(6,57,5,ICE:0)
Block(6,58,-7,ICE:0)
Block(6,58,-6,ICE:0)
Block(6,58,-5,ICE:0)
Block(6,58,-4,ICE:0)
Block(6,58,-3,ICE:0)
Block(6,58,-2,ICE:0)
Block(6,58,-1,ICE:0)
Block(6,58,0,ICE:0)
Block(6,58,1,ICE:0)
Block(6,58,2,ICE:0)
Block(6,58,3,ICE:0)
Block(6,58,4,ICE:0)
Block(6,58,5,ICE:0)
Block(6,59,-7,ICE:0)
Block(6,59,-6,ICE:0)
Block(6,59,-5,ICE:0)
Block(6,59,-4,ICE:0)
Block(6,59,-3,ICE:0)
Block(6,59,-2,ICE:0)
Block(6,59,-1,ICE:0)
Block(6,59,0,ICE:0)
Block(6,59,1,ICE:0)
Block(6,59,2,ICE:0)
Block(6,59,3,ICE:0)
Block(6,60,-7,ICE:0)
Block(6,60,-6,ICE:0)
Block(6,60,-5,ICE:0)
Block(6,60,-4,ICE:0)
Block(6,60,-3,ICE:0)
Block(6,60,-2,ICE:0)
Block(6,60,-1,ICE:0)
Block(6,60,0,ICE:0)
Block(6,60,1,ICE:0)
Block(6,60,2,ICE:0)
Block(6,61,-7,ICE:0)
Block(6,61,-6,ICE:0)
Block(6,61,-5,ICE:0)
Block(6,61,-4,ICE:0)
Block(6,61,-3,ICE:0)
Block(6,61,-2,ICE:0)
Block(6,61,-1,ICE:0)
Block(6,61,0,ICE:0)
Block(6,62,-7,ICE:0)
Block(6,62,-6,ICE:0)
Block(6,62,-5,ICE:0)
Block(6,62,-4,ICE:0)
Block(6,62,-3,ICE:0)
Block(6,62,-2,ICE:0)
Block(6,62,-1,ICE:0)
Block(6,63,-7,ICE:0)
Block(6,63,-6,ICE:0)
Block(6,63,-5,ICE:0)
Block(6,63,-4,ICE:0)
Block(6,63,-3,ICE:0)
Block(6,64,-7,ICE:0)
Block(6,64,-6,ICE:0)
Block(7,40,8,ICE:0)
Block(7,41,6,ICE:0)
Block(7,41,7,ICE:0)
Block(7,41,8,ICE:0)
Block(7,42,5,ICE:0)
Block(7,42,6,ICE:0)
Block(7,42,7,ICE:0)
Block(7,42,8,ICE:0)
Block(7,43,4,ICE:0)
Block(7,43,5,ICE:0)
Block(7,43,6,ICE:0)
Block(7,43,7,ICE:0)
Block(7,43,8,ICE:0)
Block(7,44,3,ICE:0)
Block(7,44,4,ICE:0)
Block(7,44,5,ICE:0)
Block(7,44,6,ICE:0)
Block(7,44,7,ICE:0)
Block(7,44,8,ICE:0)
Block(7,45,1,ICE:0)
Block(7,45,2,ICE:0)
Block(7,45,3,ICE:0)
Block(7,45,4,ICE:0)
Block(7,45,5,ICE:0)
Block(7,45,6,ICE:0)
Block(7,45,7,ICE:0)
Block(7,45,8,ICE:0)
Block(7,46,0,ICE:0)
Block(7,46,1,ICE:0)
Block(7,46,2,ICE:0)
Block(7,46,3,ICE:0)
Block(7,46,4,ICE:0)
Block(7,46,5,ICE:0)
Block(7,46,6,ICE:0)
Block(7,46,7,ICE:0)
Block(7,46,8,ICE:0)
Block(7,47,-1,ICE:0)
Block(7,47,0,ICE:0)
Block(7,47,1,ICE:0)
Block(7,47,2,ICE:0)
Block(7,47,3,ICE:0)
Block(7,47,4,ICE:0)
Block(7,47,5,ICE:0)
Block(7,47,6,ICE:0)
Block(7,47,7,ICE:0)
Block(7,47,8,PACKED_ICE:0)
Block(7,48,-1,ICE:0)
Block(7,48,0,ICE:0)
Block(7,48,1,ICE:0)
Block(7,48,2,ICE:0)
Block(7,48,3,ICE:0)
Block(7,48,4,ICE:0)
Block(7,48,5,ICE:0)
Block(7,48,6,ICE:0)
Block(7,48,7,PACKED_ICE:0)
Block(7,48,8,PACKED_ICE:0)
Block(7,49,-2,ICE:0)
Block(7,49,-1,ICE:0)
Block(7,49,0,ICE:0)
Block(7,49,1,ICE:0)
Block(7,49,2,ICE:0)
Block(7,49,3,ICE:0)
Block(7,49,4,ICE:0)
Block(7,49,5,ICE:0)
Block(7,49,6,ICE:0)
Block(7,49,7,PACKED_ICE:0)
Block(7,49,8,ICE:0)
Block(7,50,-3,ICE:0)
Block(7,50,-2,ICE:0)
Block(7,50,-1,ICE:0)
Block(7,50,0,ICE:0)
Block(7,50,1,ICE:0)
Block(7,50,2,ICE:0)
Block(7,50,3,ICE:0)
Block(7,50,4,ICE:0)
Block(7,50,5,ICE:0)
Block(7,50,6,PACKED_ICE:0)
Block(7,50,7,ICE:0)
Block(7,50,8,ICE:0)
Block(7,51,-4,ICE:0)
Block(7,51,-3,ICE:0)
Block(7,51,-2,ICE:0)
Block(7,51,-1,ICE:0)
Block(7,51,0,ICE:0)
Block(7,51,1,ICE:0)
Block(7,51,2,ICE:0)
Block(7,51,3,ICE:0)
Block(7,51,4,ICE:0)
Block(7,51,5,ICE:0)
Block(7,51,6,ICE:0)
Block(7,51,7,ICE:0)
Block(7,51,8,ICE:0)
Block(7,52,-5,ICE:0)
Block(7,52,-4,ICE:0)
Block(7,52,-3,ICE:0)
Block(7,52,-2,ICE:0)
Block(7,52,-1,ICE:0)
Block(7,52,0,ICE:0)
Block(7,52,1,ICE:0)
Block(7,52,2,ICE:0)
Block(7,52,3,ICE:0)
Block(7,52,4,ICE:0)
Block(7,52,5,ICE:0)
Block(7,52,6,ICE:0)
Block(7,52,7,ICE:0)
Block(7,53,-6,ICE:0)
Block(7,53,-5,ICE:0)
Block(7,53,-4,ICE:0)
Block(7,53,-3,ICE:0)
Block(7,53,-2,ICE:0)
Block(7,53,-1,ICE:0)
Block(7,53,0,ICE:0)
Block(7,53,1,ICE:0)
Block(7,53,2,ICE:0)
Block(7,53,3,ICE:0)
Block(7,53,4,ICE:0)
Block(7,53,5,ICE:0)
Block(7,53,6,ICE:0)
Block(7,53,7,ICE:0)
Block(7,54,-6,ICE:0)
Block(7,54,-5,ICE:0)
Block(7,54,-4,ICE:0)
Block(7,54,-3,ICE:0)
Block(7,54,-2,ICE:0)
Block(7,54,-1,ICE:0)
Block(7,54,0,ICE:0)
Block(7,54,1,ICE:0)
Block(7,54,2,ICE:0)
Block(7,54,3,ICE:0)
Block(7,54,4,ICE:0)
Block(7,54,5,ICE:0)
Block(7,54,6,ICE:0)
Block(7,54,7,ICE:0)
Block(7,55,-7,ICE:0)
Block(7,55,-6,ICE:0)
Block(7,55,-5,ICE:0)
Block(7,55,-4,ICE:0)
Block(7,55,-3,ICE:0)
Block(7,55,-2,ICE:0)
Block(7,55,-1,ICE:0)
Block(7,55,0,ICE:0)
Block(7,55,1,ICE:0)
Block(7,55,2,ICE:0)
Block(7,55,3,ICE:0)
Block(7,55,4,ICE:0)
Block(7,55,5,ICE:0)
Block(7,55,6,ICE:0)
Block(7,55,7,ICE:0)
Block(7,56,-7,ICE:0)
Block(7,56,-6,ICE:0)
Block(7,56,-5,ICE:0)
Block(7,56,-4,ICE:0)
Block(7,56,-3,ICE:0)
Block(7,56,-2,ICE:0)
Block(7,56,-1,ICE:0)
Block(7,56,0,ICE:0)
Block(7,56,1,ICE:0)
Block(7,56,2,ICE:0)
Block(7,56,3,ICE:0)
Block(7,56,4,ICE:0)
Block(7,56,5,ICE:0)
Block(7,56,6,ICE:0)
Block(7,56,7,ICE:0)
Block(7,57,-7,ICE:0)
Block(7,57,-6,ICE:0)
Block(7,57,-5,ICE:0)
Block(7,57,-4,ICE:0)
Block(7,57,-3,ICE:0)
Block(7,57,-2,ICE:0)
Block(7,57,-1,ICE:0)
Block(7,57,0,ICE:0)
Block(7,57,1,ICE:0)
Block(7,57,2,ICE:0)
Block(7,57,3,ICE:0)
Block(7,57,4,ICE:0)
Block(7,57,5,ICE:0)
Block(7,57,6,ICE:0)
Block(7,58,-7,ICE:0)
Block(7,58,-6,ICE:0)
Block(7,58,-5,ICE:0)
Block(7,58,-4,ICE:0)
Block(7,58,-3,ICE:0)
Block(7,58,-2,ICE:0)
Block(7,58,-1,ICE:0)
Block(7,58,0,ICE:0)
Block(7,58,1,ICE:0)
Block(7,58,2,ICE:0)
Block(7,58,3,ICE:0)
Block(7,58,4,ICE:0)
Block(7,59,-7,ICE:0)
Block(7,59,-6,ICE:0)
Block(7,59,-5,ICE:0)
Block(7,59,-4,ICE:0)
Block(7,59,-3,ICE:0)
Block(7,59,-2,ICE:0)
Block(7,59,-1,ICE:0)
Block(7,59,0,ICE:0)
Block(7,59,1,ICE:0)
Block(7,59,2,ICE:0)
Block(7,59,3,ICE:0)
Block(7,60,-7,ICE:0)
Block(7,60,-6,ICE:0)
Block(7,60,-5,ICE:0)
Block(7,60,-4,ICE:0)
Block(7,60,-3,ICE:0)
Block(7,60,-2,ICE:0)
Block(7,60,-1,ICE:0)
Block(7,60,0,ICE:0)
Block(7,60,1,ICE:0)
Block(7,61,-7,ICE:0)
Block(7,61,-6,ICE:0)
Block(7,61,-5,ICE:0)
Block(7,61,-4,ICE:0)
Block(7,61,-3,ICE:0)
Block(7,61,-2,ICE:0)
Block(7,61,-1,ICE:0)
Block(7,62,-7,ICE:0)
Block(7,62,-6,ICE:0)
Block(7,62,-5,ICE:0)
Block(7,62,-4,ICE:0)
Block(7,62,-3,ICE:0)
Block(7,62,-2,ICE:0)
Block(7,63,-7,ICE:0)
Block(7,63,-6,ICE:0)

#######################################################################
# +-----------------------------------------------------------------+ #
# |                             Branches                            | #
# +-----------------------------------------------------------------+ #
#######################################################################


#######################################################################
# +-----------------------------------------------------------------+ #
# |                             Entities                            | #
# +-----------------------------------------------------------------+ #
#######################################################################


#######################################################################
# +-----------------------------------------------------------------+ #
# |                            Particles                            | #
# +-----------------------------------------------------------------+ #
#######################################################################


#######################################################################
# +-----------------------------------------------------------------+ #
# |                             Spawners                            | #
# +-----------------------------------------------------------------+ #
#######################################################################


#######################################################################
# +-----------------------------------------------------------------+ #
# |                             ModData                             | #
# +-----------------------------------------------------------------+ #
#######################################################################

