
#######################################################################
# +-----------------------------------------------------------------+ #
# |                            BO4 object                           | #
# +-----------------------------------------------------------------+ #
#######################################################################

Author: NLBlackEagle

Description: No description given

SettingsMode: WriteDisable


#######################################################################
# +-----------------------------------------------------------------+ #
# |                          Main settings                          | #
# +-----------------------------------------------------------------+ #
#######################################################################

Frequency: 0

SpawnHeight: highestBlock

UseCenterForHighestBlock: true

##############################
# Height Limits for the BO4. #
##############################

MinHeight: 0

MaxHeight: 255

InheritBO3: 

InheritBO3Rotation: NORTH

OverrideChildSettings: true

OverrideParentHeight: false

CanOverride: true

BranchFrequency: 0

BranchFrequencyGroup: 

MustBeBelowOther: false

MustBeInside: 

CannotBeInside: 

ReplacesBO3: 

MustBeInsideWorldBorders: false

CanSpawnOnWater: true

SpawnOnWaterOnly: false

SpawnUnderWater: false

SpawnAtWaterLevel: false

HeightOffset: 0

RemoveAir: true

ReplaceAbove: 

ReplaceBelow: 

ReplaceWithBiomeBlocks: true

ReplaceWithSurfaceBlock: GRASS

ReplaceWithGroundBlock: DIRT

ReplaceWithStoneBlock: STONE

SmoothRadius: 0

SmoothHeightOffset: 0

SmoothStartTop: false

SmoothStartWood: false

SmoothingSurfaceBlock: 

SmoothingGroundBlock: 

BO3Group: 

IsSpawnPoint: false

DoReplaceBlocks: true


#######################################################################
# +-----------------------------------------------------------------+ #
# |                              Blocks                             | #
# +-----------------------------------------------------------------+ #
#######################################################################

Block(-8,25,8,STAINED_CLAY:3)
Block(-8,26,8,STAINED_CLAY:3)
Block(-8,27,8,STAINED_CLAY:3)
Block(-8,28,7,STAINED_CLAY:3)
Block(-8,28,8,STAINED_CLAY:3)
Block(-8,29,7,STAINED_CLAY:3)
Block(-8,29,8,STAINED_CLAY:3)
Block(-8,30,6,STAINED_CLAY:3)
Block(-8,30,7,STAINED_CLAY:3)
Block(-8,30,8,STAINED_CLAY:3)
Block(-8,31,6,STAINED_CLAY:3)
Block(-8,31,7,STAINED_CLAY:3)
Block(-8,31,8,STAINED_CLAY:3)
Block(-8,32,6,OBSIDIAN:0)
Block(-8,32,7,STAINED_CLAY:3)
Block(-8,32,8,STAINED_CLAY:3)
Block(-8,33,5,OBSIDIAN:0)
Block(-8,33,6,OBSIDIAN:0)
Block(-8,33,7,STAINED_CLAY:3)
Block(-8,33,8,STAINED_CLAY:3)
Block(-8,34,5,OBSIDIAN:0)
Block(-8,34,6,OBSIDIAN:0)
Block(-8,34,7,STAINED_CLAY:3)
Block(-8,34,8,STAINED_CLAY:3)
Block(-8,35,4,OBSIDIAN:0)
Block(-8,35,5,OBSIDIAN:0)
Block(-8,35,6,OBSIDIAN:0)
Block(-8,35,7,OBSIDIAN:0)
Block(-8,35,8,STAINED_CLAY:3)
Block(-8,36,4,OBSIDIAN:0)
Block(-8,36,5,OBSIDIAN:0)
Block(-8,36,6,OBSIDIAN:0)
Block(-8,36,7,OBSIDIAN:0)
Block(-8,36,8,STAINED_CLAY:3)
Block(-8,37,4,OBSIDIAN:0)
Block(-8,37,5,OBSIDIAN:0)
Block(-8,37,6,OBSIDIAN:0)
Block(-8,37,7,OBSIDIAN:0)
Block(-8,37,8,STAINED_CLAY:3)
Block(-8,38,3,OBSIDIAN:0)
Block(-8,38,4,OBSIDIAN:0)
Block(-8,38,5,OBSIDIAN:0)
Block(-8,38,6,OBSIDIAN:0)
Block(-8,38,7,STAINED_CLAY:3)
Block(-8,38,8,STAINED_CLAY:3)
Block(-8,39,3,OBSIDIAN:0)
Block(-8,39,4,OBSIDIAN:0)
Block(-8,39,5,OBSIDIAN:0)
Block(-8,39,6,OBSIDIAN:0)
Block(-8,39,7,STAINED_CLAY:3)
Block(-8,39,8,STAINED_CLAY:3)
Block(-8,40,2,OBSIDIAN:0)
Block(-8,40,3,OBSIDIAN:0)
Block(-8,40,4,OBSIDIAN:0)
Block(-8,40,5,OBSIDIAN:0)
Block(-8,40,6,OBSIDIAN:0)
Block(-8,40,7,STAINED_CLAY:3)
Block(-8,40,8,STAINED_CLAY:3)
Block(-8,41,2,OBSIDIAN:0)
Block(-8,41,3,OBSIDIAN:0)
Block(-8,41,4,OBSIDIAN:0)
Block(-8,41,5,OBSIDIAN:0)
Block(-8,41,6,STAINED_CLAY:3)
Block(-8,41,7,STAINED_CLAY:3)
Block(-8,41,8,STAINED_CLAY:3)
Block(-8,42,1,OBSIDIAN:0)
Block(-8,42,2,OBSIDIAN:0)
Block(-8,42,3,OBSIDIAN:0)
Block(-8,42,4,OBSIDIAN:0)
Block(-8,42,5,STAINED_CLAY:3)
Block(-8,42,6,STAINED_CLAY:3)
Block(-8,42,7,STAINED_CLAY:3)
Block(-8,42,8,STAINED_CLAY:3)
Block(-8,43,1,OBSIDIAN:0)
Block(-8,43,2,OBSIDIAN:0)
Block(-8,43,3,OBSIDIAN:0)
Block(-8,43,4,STAINED_CLAY:3)
Block(-8,43,5,STAINED_CLAY:3)
Block(-8,43,6,STAINED_CLAY:3)
Block(-8,43,7,STAINED_CLAY:3)
Block(-8,43,8,STAINED_CLAY:3)
Block(-8,44,1,OBSIDIAN:0)
Block(-8,44,2,OBSIDIAN:0)
Block(-8,44,3,OBSIDIAN:0)
Block(-8,44,4,STAINED_CLAY:3)
Block(-8,44,5,STAINED_CLAY:3)
Block(-8,44,6,STAINED_CLAY:3)
Block(-8,44,7,OBSIDIAN:0)
Block(-8,44,8,OBSIDIAN:0)
Block(-8,45,0,OBSIDIAN:0)
Block(-8,45,1,OBSIDIAN:0)
Block(-8,45,2,OBSIDIAN:0)
Block(-8,45,3,OBSIDIAN:0)
Block(-8,45,4,STAINED_CLAY:3)
Block(-8,45,5,STAINED_CLAY:3)
Block(-8,45,6,OBSIDIAN:0)
Block(-8,45,7,OBSIDIAN:0)
Block(-8,45,8,OBSIDIAN:0)
Block(-8,46,0,STAINED_CLAY:3)
Block(-8,46,1,STAINED_CLAY:3)
Block(-8,46,2,STAINED_CLAY:3)
Block(-8,46,3,STAINED_CLAY:3)
Block(-8,46,4,OBSIDIAN:0)
Block(-8,46,5,OBSIDIAN:0)
Block(-8,46,6,OBSIDIAN:0)
Block(-8,46,7,OBSIDIAN:0)
Block(-8,46,8,OBSIDIAN:0)
Block(-8,47,-1,STAINED_CLAY:3)
Block(-8,47,0,STAINED_CLAY:3)
Block(-8,47,1,STAINED_CLAY:3)
Block(-8,47,2,STAINED_CLAY:3)
Block(-8,47,3,STAINED_CLAY:3)
Block(-8,47,4,OBSIDIAN:0)
Block(-8,47,5,OBSIDIAN:0)
Block(-8,47,6,OBSIDIAN:0)
Block(-8,47,7,OBSIDIAN:0)
Block(-8,47,8,OBSIDIAN:0)
Block(-8,48,-1,STAINED_CLAY:3)
Block(-8,48,0,STAINED_CLAY:3)
Block(-8,48,1,STAINED_CLAY:3)
Block(-8,48,2,STAINED_CLAY:3)
Block(-8,48,3,OBSIDIAN:0)
Block(-8,48,4,OBSIDIAN:0)
Block(-8,48,5,OBSIDIAN:0)
Block(-8,48,6,OBSIDIAN:0)
Block(-8,48,7,OBSIDIAN:0)
Block(-8,48,8,OBSIDIAN:0)
Block(-8,49,-1,STAINED_CLAY:3)
Block(-8,49,0,STAINED_CLAY:3)
Block(-8,49,1,STAINED_CLAY:3)
Block(-8,49,2,OBSIDIAN:0)
Block(-8,49,3,OBSIDIAN:0)
Block(-8,49,4,OBSIDIAN:0)
Block(-8,49,5,OBSIDIAN:0)
Block(-8,49,6,OBSIDIAN:0)
Block(-8,49,7,OBSIDIAN:0)
Block(-8,49,8,OBSIDIAN:0)
Block(-8,50,-2,STAINED_CLAY:3)
Block(-8,50,-1,STAINED_CLAY:3)
Block(-8,50,0,STAINED_CLAY:3)
Block(-8,50,1,STAINED_CLAY:3)
Block(-8,50,2,OBSIDIAN:0)
Block(-8,50,3,OBSIDIAN:0)
Block(-8,50,4,OBSIDIAN:0)
Block(-8,50,5,OBSIDIAN:0)
Block(-8,50,6,OBSIDIAN:0)
Block(-8,50,7,OBSIDIAN:0)
Block(-8,50,8,OBSIDIAN:0)
Block(-8,51,-2,STAINED_CLAY:3)
Block(-8,51,-1,STAINED_CLAY:3)
Block(-8,51,0,STAINED_CLAY:3)
Block(-8,51,1,OBSIDIAN:0)
Block(-8,51,2,OBSIDIAN:0)
Block(-8,51,3,OBSIDIAN:0)
Block(-8,51,4,OBSIDIAN:0)
Block(-8,51,5,OBSIDIAN:0)
Block(-8,51,6,OBSIDIAN:0)
Block(-8,51,7,OBSIDIAN:0)
Block(-8,52,-3,STAINED_CLAY:3)
Block(-8,52,-2,STAINED_CLAY:3)
Block(-8,52,-1,STAINED_CLAY:3)
Block(-8,52,0,OBSIDIAN:0)
Block(-8,52,1,OBSIDIAN:0)
Block(-8,52,2,OBSIDIAN:0)
Block(-8,52,3,OBSIDIAN:0)
Block(-8,52,4,OBSIDIAN:0)
Block(-8,52,5,OBSIDIAN:0)
Block(-8,52,6,OBSIDIAN:0)
Block(-8,53,-3,STAINED_CLAY:3)
Block(-8,53,-2,STAINED_CLAY:3)
Block(-8,53,-1,STAINED_CLAY:3)
Block(-8,53,0,OBSIDIAN:0)
Block(-8,53,1,OBSIDIAN:0)
Block(-8,53,2,OBSIDIAN:0)
Block(-8,53,3,OBSIDIAN:0)
Block(-8,53,4,OBSIDIAN:0)
Block(-8,53,5,OBSIDIAN:0)
Block(-8,54,-3,STAINED_CLAY:3)
Block(-8,54,-2,STAINED_CLAY:3)
Block(-8,54,-1,STAINED_CLAY:3)
Block(-8,54,0,OBSIDIAN:0)
Block(-8,54,1,OBSIDIAN:0)
Block(-8,54,2,OBSIDIAN:0)
Block(-8,54,3,OBSIDIAN:0)
Block(-8,54,4,OBSIDIAN:0)
Block(-8,55,-4,STAINED_CLAY:3)
Block(-8,55,-3,STAINED_CLAY:3)
Block(-8,55,-2,STAINED_CLAY:3)
Block(-8,55,-1,OBSIDIAN:0)
Block(-8,55,0,OBSIDIAN:0)
Block(-8,55,1,OBSIDIAN:0)
Block(-8,55,2,OBSIDIAN:0)
Block(-8,55,3,OBSIDIAN:0)
Block(-8,56,-4,STAINED_CLAY:3)
Block(-8,56,-3,STAINED_CLAY:3)
Block(-8,56,-2,OBSIDIAN:0)
Block(-8,56,-1,OBSIDIAN:0)
Block(-8,56,0,OBSIDIAN:0)
Block(-8,56,1,OBSIDIAN:0)
Block(-8,56,2,OBSIDIAN:0)
Block(-8,57,-5,STAINED_CLAY:3)
Block(-8,57,-4,STAINED_CLAY:3)
Block(-8,57,-3,OBSIDIAN:0)
Block(-8,57,-2,OBSIDIAN:0)
Block(-8,57,-1,OBSIDIAN:0)
Block(-8,57,0,OBSIDIAN:0)
Block(-8,57,1,OBSIDIAN:0)
Block(-8,58,-5,STAINED_CLAY:3)
Block(-8,58,-4,STAINED_CLAY:3)
Block(-8,58,-3,OBSIDIAN:0)
Block(-8,58,-2,OBSIDIAN:0)
Block(-8,58,-1,OBSIDIAN:0)
Block(-8,58,0,OBSIDIAN:0)
Block(-8,59,-5,STAINED_CLAY:3)
Block(-8,59,-4,OBSIDIAN:0)
Block(-8,59,-3,OBSIDIAN:0)
Block(-8,59,-2,OBSIDIAN:0)
Block(-8,59,-1,OBSIDIAN:0)
Block(-8,60,-6,STAINED_CLAY:3)
Block(-8,60,-5,STAINED_CLAY:3)
Block(-8,60,-4,OBSIDIAN:0)
Block(-8,60,-3,OBSIDIAN:0)
Block(-8,60,-2,OBSIDIAN:0)
Block(-8,61,-6,STAINED_CLAY:3)
Block(-8,61,-5,OBSIDIAN:0)
Block(-8,61,-4,OBSIDIAN:0)
Block(-8,61,-3,OBSIDIAN:0)
Block(-8,62,-7,STAINED_CLAY:3)
Block(-8,62,-6,STAINED_CLAY:3)
Block(-8,62,-5,OBSIDIAN:0)
Block(-8,62,-4,OBSIDIAN:0)
Block(-8,63,-7,OBSIDIAN:0)
Block(-8,63,-6,OBSIDIAN:0)
Block(-8,63,-5,OBSIDIAN:0)
Block(-8,64,-7,OBSIDIAN:0)
Block(-8,64,-6,OBSIDIAN:0)
Block(-8,65,-7,OBSIDIAN:0)
Block(-7,25,8,OBSIDIAN:0)
Block(-7,26,8,OBSIDIAN:0)
Block(-7,27,8,OBSIDIAN:0)
Block(-7,28,7,STAINED_CLAY:3)
Block(-7,28,8,STAINED_CLAY:3)
Block(-7,29,7,OBSIDIAN:0)
Block(-7,29,8,STAINED_CLAY:3)
Block(-7,30,6,OBSIDIAN:0)
Block(-7,30,7,OBSIDIAN:0)
Block(-7,30,8,STAINED_CLAY:3)
Block(-7,31,6,OBSIDIAN:0)
Block(-7,31,7,OBSIDIAN:0)
Block(-7,31,8,STAINED_CLAY:3)
Block(-7,32,6,OBSIDIAN:0)
Block(-7,32,7,OBSIDIAN:0)
Block(-7,32,8,STAINED_CLAY:3)
Block(-7,33,5,OBSIDIAN:0)
Block(-7,33,6,OBSIDIAN:0)
Block(-7,33,7,OBSIDIAN:0)
Block(-7,33,8,STAINED_CLAY:3)
Block(-7,34,5,OBSIDIAN:0)
Block(-7,34,6,OBSIDIAN:0)
Block(-7,34,7,OBSIDIAN:0)
Block(-7,34,8,STAINED_CLAY:3)
Block(-7,35,4,OBSIDIAN:0)
Block(-7,35,5,OBSIDIAN:0)
Block(-7,35,6,OBSIDIAN:0)
Block(-7,35,7,OBSIDIAN:0)
Block(-7,35,8,STAINED_CLAY:3)
Block(-7,36,4,OBSIDIAN:0)
Block(-7,36,5,OBSIDIAN:0)
Block(-7,36,6,OBSIDIAN:0)
Block(-7,36,7,OBSIDIAN:0)
Block(-7,36,8,STAINED_CLAY:3)
Block(-7,37,3,OBSIDIAN:0)
Block(-7,37,4,OBSIDIAN:0)
Block(-7,37,5,OBSIDIAN:0)
Block(-7,37,6,OBSIDIAN:0)
Block(-7,37,7,OBSIDIAN:0)
Block(-7,37,8,STAINED_CLAY:3)
Block(-7,38,3,OBSIDIAN:0)
Block(-7,38,4,OBSIDIAN:0)
Block(-7,38,5,OBSIDIAN:0)
Block(-7,38,6,OBSIDIAN:0)
Block(-7,38,7,STAINED_CLAY:3)
Block(-7,38,8,STAINED_CLAY:3)
Block(-7,39,3,OBSIDIAN:0)
Block(-7,39,4,OBSIDIAN:0)
Block(-7,39,5,OBSIDIAN:0)
Block(-7,39,6,OBSIDIAN:0)
Block(-7,39,7,STAINED_CLAY:3)
Block(-7,39,8,STAINED_CLAY:3)
Block(-7,40,2,OBSIDIAN:0)
Block(-7,40,3,OBSIDIAN:0)
Block(-7,40,4,OBSIDIAN:0)
Block(-7,40,5,OBSIDIAN:0)
Block(-7,40,6,OBSIDIAN:0)
Block(-7,40,7,STAINED_CLAY:3)
Block(-7,40,8,STAINED_CLAY:3)
Block(-7,41,2,OBSIDIAN:0)
Block(-7,41,3,OBSIDIAN:0)
Block(-7,41,4,OBSIDIAN:0)
Block(-7,41,5,OBSIDIAN:0)
Block(-7,41,6,STAINED_CLAY:3)
Block(-7,41,7,STAINED_CLAY:3)
Block(-7,41,8,STAINED_CLAY:3)
Block(-7,42,1,OBSIDIAN:0)
Block(-7,42,2,OBSIDIAN:0)
Block(-7,42,3,OBSIDIAN:0)
Block(-7,42,4,OBSIDIAN:0)
Block(-7,42,5,STAINED_CLAY:3)
Block(-7,42,6,STAINED_CLAY:3)
Block(-7,42,7,STAINED_CLAY:3)
Block(-7,42,8,STAINED_CLAY:3)
Block(-7,43,1,OBSIDIAN:0)
Block(-7,43,2,OBSIDIAN:0)
Block(-7,43,3,STAINED_CLAY:3)
Block(-7,43,4,STAINED_CLAY:3)
Block(-7,43,5,STAINED_CLAY:3)
Block(-7,43,6,STAINED_CLAY:3)
Block(-7,43,7,STAINED_CLAY:3)
Block(-7,43,8,STAINED_CLAY:3)
Block(-7,44,1,OBSIDIAN:0)
Block(-7,44,2,OBSIDIAN:0)
Block(-7,44,3,STAINED_CLAY:3)
Block(-7,44,4,STAINED_CLAY:3)
Block(-7,44,5,STAINED_CLAY:3)
Block(-7,44,6,STAINED_CLAY:3)
Block(-7,44,7,OBSIDIAN:0)
Block(-7,44,8,OBSIDIAN:0)
Block(-7,45,0,STAINED_CLAY:3)
Block(-7,45,1,STAINED_CLAY:3)
Block(-7,45,2,STAINED_CLAY:3)
Block(-7,45,3,STAINED_CLAY:3)
Block(-7,45,4,STAINED_CLAY:3)
Block(-7,45,5,OBSIDIAN:0)
Block(-7,45,6,OBSIDIAN:0)
Block(-7,45,7,OBSIDIAN:0)
Block(-7,45,8,OBSIDIAN:0)
Block(-7,46,0,STAINED_CLAY:3)
Block(-7,46,1,STAINED_CLAY:3)
Block(-7,46,2,STAINED_CLAY:3)
Block(-7,46,3,STAINED_CLAY:3)
Block(-7,46,4,OBSIDIAN:0)
Block(-7,46,5,OBSIDIAN:0)
Block(-7,46,6,OBSIDIAN:0)
Block(-7,46,7,OBSIDIAN:0)
Block(-7,46,8,OBSIDIAN:0)
Block(-7,47,-1,STAINED_CLAY:3)
Block(-7,47,0,STAINED_CLAY:3)
Block(-7,47,1,STAINED_CLAY:3)
Block(-7,47,2,STAINED_CLAY:3)
Block(-7,47,3,OBSIDIAN:0)
Block(-7,47,4,OBSIDIAN:0)
Block(-7,47,5,OBSIDIAN:0)
Block(-7,47,6,OBSIDIAN:0)
Block(-7,47,7,OBSIDIAN:0)
Block(-7,47,8,OBSIDIAN:0)
Block(-7,48,-1,STAINED_CLAY:3)
Block(-7,48,0,STAINED_CLAY:3)
Block(-7,48,1,STAINED_CLAY:3)
Block(-7,48,2,STAINED_CLAY:3)
Block(-7,48,3,OBSIDIAN:0)
Block(-7,48,4,OBSIDIAN:0)
Block(-7,48,5,OBSIDIAN:0)
Block(-7,48,6,OBSIDIAN:0)
Block(-7,48,7,OBSIDIAN:0)
Block(-7,48,8,OBSIDIAN:0)
Block(-7,49,-1,STAINED_CLAY:3)
Block(-7,49,0,STAINED_CLAY:3)
Block(-7,49,1,STAINED_CLAY:3)
Block(-7,49,2,OBSIDIAN:0)
Block(-7,49,3,OBSIDIAN:0)
Block(-7,49,4,OBSIDIAN:0)
Block(-7,49,5,OBSIDIAN:0)
Block(-7,49,6,OBSIDIAN:0)
Block(-7,49,7,OBSIDIAN:0)
Block(-7,50,-2,STAINED_CLAY:3)
Block(-7,50,-1,STAINED_CLAY:3)
Block(-7,50,0,STAINED_CLAY:3)
Block(-7,50,1,STAINED_CLAY:3)
Block(-7,50,2,OBSIDIAN:0)
Block(-7,50,3,OBSIDIAN:0)
Block(-7,50,4,OBSIDIAN:0)
Block(-7,50,5,OBSIDIAN:0)
Block(-7,50,6,OBSIDIAN:0)
Block(-7,51,-2,STAINED_CLAY:3)
Block(-7,51,-1,STAINED_CLAY:3)
Block(-7,51,0,STAINED_CLAY:3)
Block(-7,51,1,OBSIDIAN:0)
Block(-7,51,2,OBSIDIAN:0)
Block(-7,51,3,OBSIDIAN:0)
Block(-7,51,4,OBSIDIAN:0)
Block(-7,51,5,OBSIDIAN:0)
Block(-7,52,-3,STAINED_CLAY:3)
Block(-7,52,-2,STAINED_CLAY:3)
Block(-7,52,-1,STAINED_CLAY:3)
Block(-7,52,0,OBSIDIAN:0)
Block(-7,52,1,OBSIDIAN:0)
Block(-7,52,2,OBSIDIAN:0)
Block(-7,52,3,OBSIDIAN:0)
Block(-7,52,4,OBSIDIAN:0)
Block(-7,53,-3,STAINED_CLAY:3)
Block(-7,53,-2,STAINED_CLAY:3)
Block(-7,53,-1,STAINED_CLAY:3)
Block(-7,53,0,OBSIDIAN:0)
Block(-7,53,1,OBSIDIAN:0)
Block(-7,53,2,OBSIDIAN:0)
Block(-7,53,3,OBSIDIAN:0)
Block(-7,54,-3,STAINED_CLAY:3)
Block(-7,54,-2,STAINED_CLAY:3)
Block(-7,54,-1,STAINED_CLAY:3)
Block(-7,54,0,OBSIDIAN:0)
Block(-7,54,1,OBSIDIAN:0)
Block(-7,54,2,OBSIDIAN:0)
Block(-7,55,-4,STAINED_CLAY:3)
Block(-7,55,-3,STAINED_CLAY:3)
Block(-7,55,-2,STAINED_CLAY:3)
Block(-7,55,-1,OBSIDIAN:0)
Block(-7,55,0,OBSIDIAN:0)
Block(-7,55,1,OBSIDIAN:0)
Block(-7,56,-4,STAINED_CLAY:3)
Block(-7,56,-3,STAINED_CLAY:3)
Block(-7,56,-2,OBSIDIAN:0)
Block(-7,56,-1,OBSIDIAN:0)
Block(-7,56,0,OBSIDIAN:0)
Block(-7,57,-5,STAINED_CLAY:3)
Block(-7,57,-4,STAINED_CLAY:3)
Block(-7,57,-3,OBSIDIAN:0)
Block(-7,57,-2,OBSIDIAN:0)
Block(-7,57,-1,OBSIDIAN:0)
Block(-7,58,-5,STAINED_CLAY:3)
Block(-7,58,-4,STAINED_CLAY:3)
Block(-7,58,-3,OBSIDIAN:0)
Block(-7,58,-2,OBSIDIAN:0)
Block(-7,59,-5,STAINED_CLAY:3)
Block(-7,59,-4,STAINED_CLAY:3)
Block(-7,59,-3,OBSIDIAN:0)
Block(-7,60,-6,STAINED_CLAY:3)
Block(-7,60,-5,STAINED_CLAY:3)
Block(-7,60,-4,OBSIDIAN:0)
Block(-7,61,-6,STAINED_CLAY:3)
Block(-7,61,-5,STAINED_CLAY:3)
Block(-7,62,-7,STAINED_CLAY:3)
Block(-7,62,-6,STAINED_CLAY:3)
Block(-7,63,-7,STAINED_CLAY:3)
Block(-6,25,8,OBSIDIAN:0)
Block(-6,26,8,OBSIDIAN:0)
Block(-6,27,7,OBSIDIAN:0)
Block(-6,27,8,OBSIDIAN:0)
Block(-6,28,7,OBSIDIAN:0)
Block(-6,28,8,OBSIDIAN:0)
Block(-6,29,7,OBSIDIAN:0)
Block(-6,29,8,OBSIDIAN:0)
Block(-6,30,6,OBSIDIAN:0)
Block(-6,30,7,OBSIDIAN:0)
Block(-6,30,8,OBSIDIAN:0)
Block(-6,31,6,OBSIDIAN:0)
Block(-6,31,7,OBSIDIAN:0)
Block(-6,31,8,OBSIDIAN:0)
Block(-6,32,5,OBSIDIAN:0)
Block(-6,32,6,OBSIDIAN:0)
Block(-6,32,7,OBSIDIAN:0)
Block(-6,32,8,OBSIDIAN:0)
Block(-6,33,5,OBSIDIAN:0)
Block(-6,33,6,OBSIDIAN:0)
Block(-6,33,7,OBSIDIAN:0)
Block(-6,33,8,OBSIDIAN:0)
Block(-6,34,5,OBSIDIAN:0)
Block(-6,34,6,OBSIDIAN:0)
Block(-6,34,7,OBSIDIAN:0)
Block(-6,34,8,OBSIDIAN:0)
Block(-6,35,4,OBSIDIAN:0)
Block(-6,35,5,OBSIDIAN:0)
Block(-6,35,6,OBSIDIAN:0)
Block(-6,35,7,OBSIDIAN:0)
Block(-6,35,8,STAINED_CLAY:3)
Block(-6,36,4,OBSIDIAN:0)
Block(-6,36,5,OBSIDIAN:0)
Block(-6,36,6,OBSIDIAN:0)
Block(-6,36,7,OBSIDIAN:0)
Block(-6,36,8,STAINED_CLAY:3)
Block(-6,37,3,OBSIDIAN:0)
Block(-6,37,4,OBSIDIAN:0)
Block(-6,37,5,OBSIDIAN:0)
Block(-6,37,6,OBSIDIAN:0)
Block(-6,37,7,OBSIDIAN:0)
Block(-6,37,8,STAINED_CLAY:3)
Block(-6,38,3,OBSIDIAN:0)
Block(-6,38,4,OBSIDIAN:0)
Block(-6,38,5,OBSIDIAN:0)
Block(-6,38,6,OBSIDIAN:0)
Block(-6,38,7,STAINED_CLAY:3)
Block(-6,38,8,STAINED_CLAY:3)
Block(-6,39,3,OBSIDIAN:0)
Block(-6,39,4,OBSIDIAN:0)
Block(-6,39,5,OBSIDIAN:0)
Block(-6,39,6,STAINED_CLAY:3)
Block(-6,39,7,STAINED_CLAY:3)
Block(-6,39,8,STAINED_CLAY:3)
Block(-6,40,2,OBSIDIAN:0)
Block(-6,40,3,OBSIDIAN:0)
Block(-6,40,4,OBSIDIAN:0)
Block(-6,40,5,OBSIDIAN:0)
Block(-6,40,6,STAINED_CLAY:3)
Block(-6,40,7,STAINED_CLAY:3)
Block(-6,40,8,STAINED_CLAY:3)
Block(-6,41,2,OBSIDIAN:0)
Block(-6,41,3,OBSIDIAN:0)
Block(-6,41,4,OBSIDIAN:0)
Block(-6,41,5,OBSIDIAN:0)
Block(-6,41,6,STAINED_CLAY:3)
Block(-6,41,7,STAINED_CLAY:3)
Block(-6,41,8,STAINED_CLAY:3)
Block(-6,42,1,STAINED_CLAY:3)
Block(-6,42,2,STAINED_CLAY:3)
Block(-6,42,3,STAINED_CLAY:3)
Block(-6,42,4,STAINED_CLAY:3)
Block(-6,42,5,STAINED_CLAY:3)
Block(-6,42,6,STAINED_CLAY:3)
Block(-6,42,7,STAINED_CLAY:3)
Block(-6,42,8,STAINED_CLAY:3)
Block(-6,43,1,STAINED_CLAY:3)
Block(-6,43,2,STAINED_CLAY:3)
Block(-6,43,3,STAINED_CLAY:3)
Block(-6,43,4,STAINED_CLAY:3)
Block(-6,43,5,STAINED_CLAY:3)
Block(-6,43,6,STAINED_CLAY:3)
Block(-6,43,7,STAINED_CLAY:3)
Block(-6,43,8,STAINED_CLAY:3)
Block(-6,44,1,STAINED_CLAY:3)
Block(-6,44,2,STAINED_CLAY:3)
Block(-6,44,3,STAINED_CLAY:3)
Block(-6,44,4,STAINED_CLAY:3)
Block(-6,44,5,STAINED_CLAY:3)
Block(-6,44,6,STAINED_CLAY:3)
Block(-6,44,7,OBSIDIAN:0)
Block(-6,44,8,OBSIDIAN:0)
Block(-6,45,0,STAINED_CLAY:3)
Block(-6,45,1,STAINED_CLAY:3)
Block(-6,45,2,STAINED_CLAY:3)
Block(-6,45,3,STAINED_CLAY:3)
Block(-6,45,4,STAINED_CLAY:3)
Block(-6,45,5,OBSIDIAN:0)
Block(-6,45,6,OBSIDIAN:0)
Block(-6,45,7,OBSIDIAN:0)
Block(-6,45,8,OBSIDIAN:0)
Block(-6,46,0,STAINED_CLAY:3)
Block(-6,46,1,STAINED_CLAY:3)
Block(-6,46,2,STAINED_CLAY:3)
Block(-6,46,3,STAINED_CLAY:3)
Block(-6,46,4,OBSIDIAN:0)
Block(-6,46,5,OBSIDIAN:0)
Block(-6,46,6,OBSIDIAN:0)
Block(-6,46,7,OBSIDIAN:0)
Block(-6,46,8,OBSIDIAN:0)
Block(-6,47,-1,STAINED_CLAY:3)
Block(-6,47,0,STAINED_CLAY:3)
Block(-6,47,1,STAINED_CLAY:3)
Block(-6,47,2,STAINED_CLAY:3)
Block(-6,47,3,OBSIDIAN:0)
Block(-6,47,4,OBSIDIAN:0)
Block(-6,47,5,OBSIDIAN:0)
Block(-6,47,6,OBSIDIAN:0)
Block(-6,47,7,OBSIDIAN:0)
Block(-6,48,-1,STAINED_CLAY:3)
Block(-6,48,0,STAINED_CLAY:3)
Block(-6,48,1,STAINED_CLAY:3)
Block(-6,48,2,STAINED_CLAY:3)
Block(-6,48,3,OBSIDIAN:0)
Block(-6,48,4,OBSIDIAN:0)
Block(-6,48,5,OBSIDIAN:0)
Block(-6,48,6,OBSIDIAN:0)
Block(-6,49,-1,STAINED_CLAY:3)
Block(-6,49,0,STAINED_CLAY:3)
Block(-6,49,1,STAINED_CLAY:3)
Block(-6,49,2,OBSIDIAN:0)
Block(-6,49,3,OBSIDIAN:0)
Block(-6,49,4,OBSIDIAN:0)
Block(-6,49,5,OBSIDIAN:0)
Block(-6,50,-2,STAINED_CLAY:3)
Block(-6,50,-1,STAINED_CLAY:3)
Block(-6,50,0,STAINED_CLAY:3)
Block(-6,50,1,STAINED_CLAY:3)
Block(-6,50,2,OBSIDIAN:0)
Block(-6,50,3,OBSIDIAN:0)
Block(-6,50,4,OBSIDIAN:0)
Block(-6,51,-2,STAINED_CLAY:3)
Block(-6,51,-1,STAINED_CLAY:3)
Block(-6,51,0,STAINED_CLAY:3)
Block(-6,51,1,OBSIDIAN:0)
Block(-6,51,2,OBSIDIAN:0)
Block(-6,51,3,OBSIDIAN:0)
Block(-6,52,-3,STAINED_CLAY:3)
Block(-6,52,-2,STAINED_CLAY:3)
Block(-6,52,-1,STAINED_CLAY:3)
Block(-6,52,0,OBSIDIAN:0)
Block(-6,52,1,OBSIDIAN:0)
Block(-6,52,2,OBSIDIAN:0)
Block(-6,53,-3,STAINED_CLAY:3)
Block(-6,53,-2,STAINED_CLAY:3)
Block(-6,53,-1,STAINED_CLAY:3)
Block(-6,53,0,OBSIDIAN:0)
Block(-6,53,1,OBSIDIAN:0)
Block(-6,54,-3,STAINED_CLAY:3)
Block(-6,54,-2,STAINED_CLAY:3)
Block(-6,54,-1,STAINED_CLAY:3)
Block(-6,54,0,OBSIDIAN:0)
Block(-6,55,-4,STAINED_CLAY:3)
Block(-6,55,-3,STAINED_CLAY:3)
Block(-6,55,-2,STAINED_CLAY:3)
Block(-6,55,-1,STAINED_CLAY:3)
Block(-6,56,-4,STAINED_CLAY:3)
Block(-6,56,-3,STAINED_CLAY:3)
Block(-6,56,-2,OBSIDIAN:0)
Block(-6,57,-5,STAINED_CLAY:3)
Block(-6,57,-4,STAINED_CLAY:3)
Block(-6,57,-3,STAINED_CLAY:3)
Block(-6,58,-5,STAINED_CLAY:3)
Block(-6,58,-4,STAINED_CLAY:3)
Block(-6,59,-5,STAINED_CLAY:3)
Block(-6,60,-6,STAINED_CLAY:3)
Block(-5,25,8,OBSIDIAN:0)
Block(-5,26,8,OBSIDIAN:0)
Block(-5,27,7,OBSIDIAN:0)
Block(-5,27,8,OBSIDIAN:0)
Block(-5,28,7,OBSIDIAN:0)
Block(-5,28,8,OBSIDIAN:0)
Block(-5,29,7,OBSIDIAN:0)
Block(-5,29,8,OBSIDIAN:0)
Block(-5,30,6,OBSIDIAN:0)
Block(-5,30,7,OBSIDIAN:0)
Block(-5,30,8,OBSIDIAN:0)
Block(-5,31,6,OBSIDIAN:0)
Block(-5,31,7,OBSIDIAN:0)
Block(-5,31,8,OBSIDIAN:0)
Block(-5,32,5,OBSIDIAN:0)
Block(-5,32,6,OBSIDIAN:0)
Block(-5,32,7,OBSIDIAN:0)
Block(-5,32,8,OBSIDIAN:0)
Block(-5,33,5,OBSIDIAN:0)
Block(-5,33,6,OBSIDIAN:0)
Block(-5,33,7,OBSIDIAN:0)
Block(-5,33,8,OBSIDIAN:0)
Block(-5,34,5,OBSIDIAN:0)
Block(-5,34,6,OBSIDIAN:0)
Block(-5,34,7,OBSIDIAN:0)
Block(-5,34,8,OBSIDIAN:0)
Block(-5,35,4,OBSIDIAN:0)
Block(-5,35,5,OBSIDIAN:0)
Block(-5,35,6,OBSIDIAN:0)
Block(-5,35,7,OBSIDIAN:0)
Block(-5,35,8,STAINED_CLAY:3)
Block(-5,36,4,OBSIDIAN:0)
Block(-5,36,5,OBSIDIAN:0)
Block(-5,36,6,OBSIDIAN:0)
Block(-5,36,7,STAINED_CLAY:3)
Block(-5,36,8,STAINED_CLAY:3)
Block(-5,37,3,OBSIDIAN:0)
Block(-5,37,4,OBSIDIAN:0)
Block(-5,37,5,OBSIDIAN:0)
Block(-5,37,6,OBSIDIAN:0)
Block(-5,37,7,STAINED_CLAY:3)
Block(-5,37,8,STAINED_CLAY:3)
Block(-5,38,3,OBSIDIAN:0)
Block(-5,38,4,OBSIDIAN:0)
Block(-5,38,5,OBSIDIAN:0)
Block(-5,38,6,OBSIDIAN:0)
Block(-5,38,7,STAINED_CLAY:3)
Block(-5,38,8,STAINED_CLAY:3)
Block(-5,39,3,OBSIDIAN:0)
Block(-5,39,4,OBSIDIAN:0)
Block(-5,39,5,STAINED_CLAY:3)
Block(-5,39,6,STAINED_CLAY:3)
Block(-5,39,7,STAINED_CLAY:3)
Block(-5,39,8,STAINED_CLAY:3)
Block(-5,40,2,OBSIDIAN:0)
Block(-5,40,3,OBSIDIAN:0)
Block(-5,40,4,OBSIDIAN:0)
Block(-5,40,5,STAINED_CLAY:3)
Block(-5,40,6,STAINED_CLAY:3)
Block(-5,40,7,STAINED_CLAY:3)
Block(-5,40,8,STAINED_CLAY:3)
Block(-5,41,2,STAINED_CLAY:3)
Block(-5,41,3,STAINED_CLAY:3)
Block(-5,41,4,STAINED_CLAY:3)
Block(-5,41,5,STAINED_CLAY:3)
Block(-5,41,6,STAINED_CLAY:3)
Block(-5,41,7,STAINED_CLAY:3)
Block(-5,41,8,STAINED_CLAY:3)
Block(-5,42,1,STAINED_CLAY:3)
Block(-5,42,2,STAINED_CLAY:3)
Block(-5,42,3,STAINED_CLAY:3)
Block(-5,42,4,STAINED_CLAY:3)
Block(-5,42,5,STAINED_CLAY:3)
Block(-5,42,6,STAINED_CLAY:3)
Block(-5,42,7,STAINED_CLAY:3)
Block(-5,42,8,STAINED_CLAY:3)
Block(-5,43,1,STAINED_CLAY:3)
Block(-5,43,2,STAINED_CLAY:3)
Block(-5,43,3,STAINED_CLAY:3)
Block(-5,43,4,STAINED_CLAY:3)
Block(-5,43,5,STAINED_CLAY:3)
Block(-5,43,6,STAINED_CLAY:3)
Block(-5,43,7,STAINED_CLAY:3)
Block(-5,43,8,STAINED_CLAY:3)
Block(-5,44,1,STAINED_CLAY:3)
Block(-5,44,2,STAINED_CLAY:3)
Block(-5,44,3,STAINED_CLAY:3)
Block(-5,44,4,STAINED_CLAY:3)
Block(-5,44,5,STAINED_CLAY:3)
Block(-5,44,6,STAINED_CLAY:3)
Block(-5,44,7,STAINED_CLAY:3)
Block(-5,44,8,STAINED_CLAY:3)
Block(-5,45,0,STAINED_CLAY:3)
Block(-5,45,1,STAINED_CLAY:3)
Block(-5,45,2,STAINED_CLAY:3)
Block(-5,45,3,STAINED_CLAY:3)
Block(-5,45,4,STAINED_CLAY:3)
Block(-5,45,5,OBSIDIAN:0)
Block(-5,45,6,OBSIDIAN:0)
Block(-5,45,7,OBSIDIAN:0)
Block(-5,46,0,STAINED_CLAY:3)
Block(-5,46,1,STAINED_CLAY:3)
Block(-5,46,2,STAINED_CLAY:3)
Block(-5,46,3,STAINED_CLAY:3)
Block(-5,46,4,OBSIDIAN:0)
Block(-5,46,5,OBSIDIAN:0)
Block(-5,46,6,OBSIDIAN:0)
Block(-5,47,-1,STAINED_CLAY:3)
Block(-5,47,0,STAINED_CLAY:3)
Block(-5,47,1,STAINED_CLAY:3)
Block(-5,47,2,STAINED_CLAY:3)
Block(-5,47,3,OBSIDIAN:0)
Block(-5,47,4,OBSIDIAN:0)
Block(-5,47,5,OBSIDIAN:0)
Block(-5,48,-1,STAINED_CLAY:3)
Block(-5,48,0,STAINED_CLAY:3)
Block(-5,48,1,STAINED_CLAY:3)
Block(-5,48,2,STAINED_CLAY:3)
Block(-5,48,3,OBSIDIAN:0)
Block(-5,48,4,OBSIDIAN:0)
Block(-5,49,-1,STAINED_CLAY:3)
Block(-5,49,0,STAINED_CLAY:3)
Block(-5,49,1,STAINED_CLAY:3)
Block(-5,49,2,STAINED_CLAY:3)
Block(-5,49,3,OBSIDIAN:0)
Block(-5,50,-2,STAINED_CLAY:3)
Block(-5,50,-1,STAINED_CLAY:3)
Block(-5,50,0,STAINED_CLAY:3)
Block(-5,50,1,STAINED_CLAY:3)
Block(-5,50,2,STAINED_CLAY:3)
Block(-5,51,-2,STAINED_CLAY:3)
Block(-5,51,-1,STAINED_CLAY:3)
Block(-5,51,0,STAINED_CLAY:3)
Block(-5,51,1,OBSIDIAN:0)
Block(-5,52,-3,STAINED_CLAY:3)
Block(-5,52,-2,STAINED_CLAY:3)
Block(-5,52,-1,STAINED_CLAY:3)
Block(-5,52,0,STAINED_CLAY:3)
Block(-5,53,-3,STAINED_CLAY:3)
Block(-5,53,-2,STAINED_CLAY:3)
Block(-5,53,-1,STAINED_CLAY:3)
Block(-5,54,-4,STAINED_CLAY:3)
Block(-5,54,-3,STAINED_CLAY:3)
Block(-5,54,-2,STAINED_CLAY:3)
Block(-5,55,-4,STAINED_CLAY:3)
Block(-5,55,-3,STAINED_CLAY:3)
Block(-5,56,-4,STAINED_CLAY:3)
Block(-5,57,-5,STAINED_CLAY:3)
Block(-4,25,8,OBSIDIAN:0)
Block(-4,26,8,OBSIDIAN:0)
Block(-4,27,7,OBSIDIAN:0)
Block(-4,27,8,OBSIDIAN:0)
Block(-4,28,7,OBSIDIAN:0)
Block(-4,28,8,OBSIDIAN:0)
Block(-4,29,7,OBSIDIAN:0)
Block(-4,29,8,OBSIDIAN:0)
Block(-4,30,6,OBSIDIAN:0)
Block(-4,30,7,OBSIDIAN:0)
Block(-4,30,8,OBSIDIAN:0)
Block(-4,31,6,OBSIDIAN:0)
Block(-4,31,7,OBSIDIAN:0)
Block(-4,31,8,OBSIDIAN:0)
Block(-4,32,5,OBSIDIAN:0)
Block(-4,32,6,OBSIDIAN:0)
Block(-4,32,7,OBSIDIAN:0)
Block(-4,32,8,OBSIDIAN:0)
Block(-4,33,5,OBSIDIAN:0)
Block(-4,33,6,OBSIDIAN:0)
Block(-4,33,7,OBSIDIAN:0)
Block(-4,33,8,OBSIDIAN:0)
Block(-4,34,5,OBSIDIAN:0)
Block(-4,34,6,OBSIDIAN:0)
Block(-4,34,7,OBSIDIAN:0)
Block(-4,34,8,OBSIDIAN:0)
Block(-4,35,4,OBSIDIAN:0)
Block(-4,35,5,OBSIDIAN:0)
Block(-4,35,6,OBSIDIAN:0)
Block(-4,35,7,OBSIDIAN:0)
Block(-4,35,8,STAINED_CLAY:3)
Block(-4,36,4,OBSIDIAN:0)
Block(-4,36,5,OBSIDIAN:0)
Block(-4,36,6,OBSIDIAN:0)
Block(-4,36,7,STAINED_CLAY:3)
Block(-4,36,8,STAINED_CLAY:3)
Block(-4,37,3,OBSIDIAN:0)
Block(-4,37,4,OBSIDIAN:0)
Block(-4,37,5,OBSIDIAN:0)
Block(-4,37,6,STAINED_CLAY:3)
Block(-4,37,7,STAINED_CLAY:3)
Block(-4,37,8,STAINED_CLAY:3)
Block(-4,38,3,STAINED_CLAY:3)
Block(-4,38,4,STAINED_CLAY:3)
Block(-4,38,5,STAINED_CLAY:3)
Block(-4,38,6,STAINED_CLAY:3)
Block(-4,38,7,STAINED_CLAY:3)
Block(-4,38,8,STAINED_CLAY:3)
Block(-4,39,3,STAINED_CLAY:3)
Block(-4,39,4,STAINED_CLAY:3)
Block(-4,39,5,STAINED_CLAY:3)
Block(-4,39,6,STAINED_CLAY:3)
Block(-4,39,7,STAINED_CLAY:3)
Block(-4,39,8,STAINED_CLAY:3)
Block(-4,40,2,STAINED_CLAY:3)
Block(-4,40,3,STAINED_CLAY:3)
Block(-4,40,4,STAINED_CLAY:3)
Block(-4,40,5,STAINED_CLAY:3)
Block(-4,40,6,STAINED_CLAY:3)
Block(-4,40,7,STAINED_CLAY:3)
Block(-4,40,8,STAINED_CLAY:3)
Block(-4,41,2,STAINED_CLAY:3)
Block(-4,41,3,STAINED_CLAY:3)
Block(-4,41,4,STAINED_CLAY:3)
Block(-4,41,5,STAINED_CLAY:3)
Block(-4,41,6,STAINED_CLAY:3)
Block(-4,41,7,STAINED_CLAY:3)
Block(-4,41,8,STAINED_CLAY:3)
Block(-4,42,1,STAINED_CLAY:3)
Block(-4,42,2,STAINED_CLAY:3)
Block(-4,42,3,STAINED_CLAY:3)
Block(-4,42,4,STAINED_CLAY:3)
Block(-4,42,5,STAINED_CLAY:3)
Block(-4,42,6,STAINED_CLAY:3)
Block(-4,42,7,STAINED_CLAY:3)
Block(-4,42,8,STAINED_CLAY:3)
Block(-4,43,1,STAINED_CLAY:3)
Block(-4,43,2,STAINED_CLAY:3)
Block(-4,43,3,STAINED_CLAY:3)
Block(-4,43,4,STAINED_CLAY:3)
Block(-4,43,5,STAINED_CLAY:3)
Block(-4,43,6,STAINED_CLAY:3)
Block(-4,43,7,STAINED_CLAY:3)
Block(-4,44,0,STAINED_CLAY:3)
Block(-4,44,1,STAINED_CLAY:3)
Block(-4,44,2,STAINED_CLAY:3)
Block(-4,44,3,STAINED_CLAY:3)
Block(-4,44,4,STAINED_CLAY:3)
Block(-4,44,5,STAINED_CLAY:3)
Block(-4,44,6,STAINED_CLAY:3)
Block(-4,45,0,STAINED_CLAY:3)
Block(-4,45,1,STAINED_CLAY:3)
Block(-4,45,2,STAINED_CLAY:3)
Block(-4,45,3,STAINED_CLAY:3)
Block(-4,45,4,STAINED_CLAY:3)
Block(-4,45,5,STAINED_CLAY:3)
Block(-4,46,0,STAINED_CLAY:3)
Block(-4,46,1,STAINED_CLAY:3)
Block(-4,46,2,STAINED_CLAY:3)
Block(-4,46,3,STAINED_CLAY:3)
Block(-4,46,4,OBSIDIAN:0)
Block(-4,47,-1,STAINED_CLAY:3)
Block(-4,47,0,STAINED_CLAY:3)
Block(-4,47,1,STAINED_CLAY:3)
Block(-4,47,2,STAINED_CLAY:3)
Block(-4,47,3,STAINED_CLAY:3)
Block(-4,48,-1,STAINED_CLAY:3)
Block(-4,48,0,STAINED_CLAY:3)
Block(-4,48,1,STAINED_CLAY:3)
Block(-4,48,2,STAINED_CLAY:3)
Block(-4,49,-2,STAINED_CLAY:3)
Block(-4,49,-1,STAINED_CLAY:3)
Block(-4,49,0,STAINED_CLAY:3)
Block(-4,49,1,STAINED_CLAY:3)
Block(-4,50,-2,STAINED_CLAY:3)
Block(-4,50,-1,STAINED_CLAY:3)
Block(-4,50,0,STAINED_CLAY:3)
Block(-4,51,-2,STAINED_CLAY:3)
Block(-4,51,-1,STAINED_CLAY:3)
Block(-4,52,-3,STAINED_CLAY:3)
Block(-4,52,-2,STAINED_CLAY:3)
Block(-4,53,-3,STAINED_CLAY:3)
Block(-4,54,-4,STAINED_CLAY:3)
Block(-3,25,8,OBSIDIAN:0)
Block(-3,26,8,OBSIDIAN:0)
Block(-3,27,7,OBSIDIAN:0)
Block(-3,27,8,OBSIDIAN:0)
Block(-3,28,7,OBSIDIAN:0)
Block(-3,28,8,OBSIDIAN:0)
Block(-3,29,7,OBSIDIAN:0)
Block(-3,29,8,OBSIDIAN:0)
Block(-3,30,6,OBSIDIAN:0)
Block(-3,30,7,OBSIDIAN:0)
Block(-3,30,8,OBSIDIAN:0)
Block(-3,31,6,OBSIDIAN:0)
Block(-3,31,7,OBSIDIAN:0)
Block(-3,31,8,OBSIDIAN:0)
Block(-3,32,5,OBSIDIAN:0)
Block(-3,32,6,OBSIDIAN:0)
Block(-3,32,7,OBSIDIAN:0)
Block(-3,32,8,OBSIDIAN:0)
Block(-3,33,5,OBSIDIAN:0)
Block(-3,33,6,OBSIDIAN:0)
Block(-3,33,7,OBSIDIAN:0)
Block(-3,33,8,STAINED_CLAY:3)
Block(-3,34,5,OBSIDIAN:0)
Block(-3,34,6,OBSIDIAN:0)
Block(-3,34,7,OBSIDIAN:0)
Block(-3,34,8,STAINED_CLAY:3)
Block(-3,35,4,OBSIDIAN:0)
Block(-3,35,5,OBSIDIAN:0)
Block(-3,35,6,OBSIDIAN:0)
Block(-3,35,7,OBSIDIAN:0)
Block(-3,35,8,STAINED_CLAY:3)
Block(-3,36,4,STAINED_CLAY:3)
Block(-3,36,5,STAINED_CLAY:3)
Block(-3,36,6,STAINED_CLAY:3)
Block(-3,36,7,STAINED_CLAY:3)
Block(-3,36,8,STAINED_CLAY:3)
Block(-3,37,3,STAINED_CLAY:3)
Block(-3,37,4,STAINED_CLAY:3)
Block(-3,37,5,STAINED_CLAY:3)
Block(-3,37,6,STAINED_CLAY:3)
Block(-3,37,7,STAINED_CLAY:3)
Block(-3,37,8,STAINED_CLAY:3)
Block(-3,38,3,STAINED_CLAY:3)
Block(-3,38,4,STAINED_CLAY:3)
Block(-3,38,5,STAINED_CLAY:3)
Block(-3,38,6,STAINED_CLAY:3)
Block(-3,38,7,STAINED_CLAY:3)
Block(-3,38,8,STAINED_CLAY:3)
Block(-3,39,2,STAINED_CLAY:3)
Block(-3,39,3,STAINED_CLAY:3)
Block(-3,39,4,STAINED_CLAY:3)
Block(-3,39,5,STAINED_CLAY:3)
Block(-3,39,6,STAINED_CLAY:3)
Block(-3,39,7,STAINED_CLAY:3)
Block(-3,39,8,STAINED_CLAY:3)
Block(-3,40,2,STAINED_CLAY:3)
Block(-3,40,3,STAINED_CLAY:3)
Block(-3,40,4,STAINED_CLAY:3)
Block(-3,40,5,STAINED_CLAY:3)
Block(-3,40,6,STAINED_CLAY:3)
Block(-3,40,7,STAINED_CLAY:3)
Block(-3,40,8,STAINED_CLAY:3)
Block(-3,41,2,STAINED_CLAY:3)
Block(-3,41,3,STAINED_CLAY:3)
Block(-3,41,4,STAINED_CLAY:3)
Block(-3,41,5,STAINED_CLAY:3)
Block(-3,41,6,STAINED_CLAY:3)
Block(-3,41,7,STAINED_CLAY:3)
Block(-3,42,1,STAINED_CLAY:3)
Block(-3,42,2,STAINED_CLAY:3)
Block(-3,42,3,STAINED_CLAY:3)
Block(-3,42,4,STAINED_CLAY:3)
Block(-3,42,5,STAINED_CLAY:3)
Block(-3,42,6,STAINED_CLAY:3)
Block(-3,43,1,STAINED_CLAY:3)
Block(-3,43,2,STAINED_CLAY:3)
Block(-3,43,3,STAINED_CLAY:3)
Block(-3,43,4,STAINED_CLAY:3)
Block(-3,43,5,STAINED_CLAY:3)
Block(-3,44,0,STAINED_CLAY:3)
Block(-3,44,1,STAINED_CLAY:3)
Block(-3,44,2,STAINED_CLAY:3)
Block(-3,44,3,STAINED_CLAY:3)
Block(-3,44,4,STAINED_CLAY:3)
Block(-3,45,0,STAINED_CLAY:3)
Block(-3,45,1,STAINED_CLAY:3)
Block(-3,45,2,STAINED_CLAY:3)
Block(-3,45,3,STAINED_CLAY:3)
Block(-3,46,0,STAINED_CLAY:3)
Block(-3,46,1,STAINED_CLAY:3)
Block(-3,46,2,STAINED_CLAY:3)
Block(-3,47,-1,STAINED_CLAY:3)
Block(-3,47,0,STAINED_CLAY:3)
Block(-3,47,1,STAINED_CLAY:3)
Block(-3,48,-1,STAINED_CLAY:3)
Block(-3,48,0,STAINED_CLAY:3)
Block(-3,49,-2,STAINED_CLAY:3)
Block(-3,49,-1,STAINED_CLAY:3)
Block(-3,50,-2,STAINED_CLAY:3)
Block(-2,25,8,OBSIDIAN:0)
Block(-2,26,8,OBSIDIAN:0)
Block(-2,27,7,OBSIDIAN:0)
Block(-2,27,8,OBSIDIAN:0)
Block(-2,28,7,OBSIDIAN:0)
Block(-2,28,8,OBSIDIAN:0)
Block(-2,29,6,OBSIDIAN:0)
Block(-2,29,7,OBSIDIAN:0)
Block(-2,29,8,OBSIDIAN:0)
Block(-2,30,6,OBSIDIAN:0)
Block(-2,30,7,OBSIDIAN:0)
Block(-2,30,8,OBSIDIAN:0)
Block(-2,31,6,OBSIDIAN:0)
Block(-2,31,7,OBSIDIAN:0)
Block(-2,31,8,OBSIDIAN:0)
Block(-2,32,5,OBSIDIAN:0)
Block(-2,32,6,OBSIDIAN:0)
Block(-2,32,7,OBSIDIAN:0)
Block(-2,32,8,OBSIDIAN:0)
Block(-2,33,5,OBSIDIAN:0)
Block(-2,33,6,OBSIDIAN:0)
Block(-2,33,7,STAINED_CLAY:3)
Block(-2,33,8,STAINED_CLAY:3)
Block(-2,34,4,OBSIDIAN:0)
Block(-2,34,5,OBSIDIAN:0)
Block(-2,34,6,OBSIDIAN:0)
Block(-2,34,7,STAINED_CLAY:3)
Block(-2,34,8,STAINED_CLAY:3)
Block(-2,35,4,STAINED_CLAY:3)
Block(-2,35,5,STAINED_CLAY:3)
Block(-2,35,6,STAINED_CLAY:3)
Block(-2,35,7,STAINED_CLAY:3)
Block(-2,35,8,STAINED_CLAY:3)
Block(-2,36,4,STAINED_CLAY:3)
Block(-2,36,5,STAINED_CLAY:3)
Block(-2,36,6,STAINED_CLAY:3)
Block(-2,36,7,STAINED_CLAY:3)
Block(-2,36,8,STAINED_CLAY:3)
Block(-2,37,3,STAINED_CLAY:3)
Block(-2,37,4,STAINED_CLAY:3)
Block(-2,37,5,STAINED_CLAY:3)
Block(-2,37,6,STAINED_CLAY:3)
Block(-2,37,7,STAINED_CLAY:3)
Block(-2,37,8,STAINED_CLAY:3)
Block(-2,38,3,STAINED_CLAY:3)
Block(-2,38,4,STAINED_CLAY:3)
Block(-2,38,5,STAINED_CLAY:3)
Block(-2,38,6,STAINED_CLAY:3)
Block(-2,38,7,STAINED_CLAY:3)
Block(-2,38,8,STAINED_CLAY:3)
Block(-2,39,2,STAINED_CLAY:3)
Block(-2,39,3,STAINED_CLAY:3)
Block(-2,39,4,STAINED_CLAY:3)
Block(-2,39,5,STAINED_CLAY:3)
Block(-2,39,6,STAINED_CLAY:3)
Block(-2,39,7,STAINED_CLAY:3)
Block(-2,40,2,STAINED_CLAY:3)
Block(-2,40,3,STAINED_CLAY:3)
Block(-2,40,4,STAINED_CLAY:3)
Block(-2,40,5,STAINED_CLAY:3)
Block(-2,40,6,STAINED_CLAY:3)
Block(-2,41,2,STAINED_CLAY:3)
Block(-2,41,3,STAINED_CLAY:3)
Block(-2,41,4,STAINED_CLAY:3)
Block(-2,41,5,STAINED_CLAY:3)
Block(-2,42,1,STAINED_CLAY:3)
Block(-2,42,2,STAINED_CLAY:3)
Block(-2,42,3,STAINED_CLAY:3)
Block(-2,42,4,STAINED_CLAY:3)
Block(-2,43,1,STAINED_CLAY:3)
Block(-2,43,2,STAINED_CLAY:3)
Block(-2,43,3,STAINED_CLAY:3)
Block(-2,44,0,STAINED_CLAY:3)
Block(-2,44,1,STAINED_CLAY:3)
Block(-2,44,2,STAINED_CLAY:3)
Block(-2,44,3,STAINED_CLAY:3)
Block(-2,45,0,STAINED_CLAY:3)
Block(-2,45,1,STAINED_CLAY:3)
Block(-2,45,2,STAINED_CLAY:3)
Block(-2,46,0,STAINED_CLAY:3)
Block(-2,46,1,STAINED_CLAY:3)
Block(-2,47,-1,STAINED_CLAY:3)
Block(-2,47,0,STAINED_CLAY:3)
Block(-2,48,-1,STAINED_CLAY:3)
Block(-2,49,-2,STAINED_CLAY:3)
Block(-1,24,8,OBSIDIAN:0)
Block(-1,25,8,OBSIDIAN:0)
Block(-1,26,8,OBSIDIAN:0)
Block(-1,27,7,OBSIDIAN:0)
Block(-1,27,8,OBSIDIAN:0)
Block(-1,28,7,OBSIDIAN:0)
Block(-1,28,8,OBSIDIAN:0)
Block(-1,29,6,OBSIDIAN:0)
Block(-1,29,7,OBSIDIAN:0)
Block(-1,29,8,OBSIDIAN:0)
Block(-1,30,6,OBSIDIAN:0)
Block(-1,30,7,OBSIDIAN:0)
Block(-1,30,8,OBSIDIAN:0)
Block(-1,31,6,OBSIDIAN:0)
Block(-1,31,7,OBSIDIAN:0)
Block(-1,31,8,STAINED_CLAY:3)
Block(-1,32,5,STAINED_CLAY:3)
Block(-1,32,6,STAINED_CLAY:3)
Block(-1,32,7,STAINED_CLAY:3)
Block(-1,32,8,STAINED_CLAY:3)
Block(-1,33,5,STAINED_CLAY:3)
Block(-1,33,6,STAINED_CLAY:3)
Block(-1,33,7,STAINED_CLAY:3)
Block(-1,33,8,STAINED_CLAY:3)
Block(-1,34,4,STAINED_CLAY:3)
Block(-1,34,5,STAINED_CLAY:3)
Block(-1,34,6,STAINED_CLAY:3)
Block(-1,34,7,STAINED_CLAY:3)
Block(-1,34,8,STAINED_CLAY:3)
Block(-1,35,4,STAINED_CLAY:3)
Block(-1,35,5,STAINED_CLAY:3)
Block(-1,35,6,STAINED_CLAY:3)
Block(-1,35,7,STAINED_CLAY:3)
Block(-1,35,8,STAINED_CLAY:3)
Block(-1,36,4,STAINED_CLAY:3)
Block(-1,36,5,STAINED_CLAY:3)
Block(-1,36,6,STAINED_CLAY:3)
Block(-1,36,7,STAINED_CLAY:3)
Block(-1,36,8,STAINED_CLAY:3)
Block(-1,37,3,STAINED_CLAY:3)
Block(-1,37,4,STAINED_CLAY:3)
Block(-1,37,5,STAINED_CLAY:3)
Block(-1,37,6,STAINED_CLAY:3)
Block(-1,37,7,STAINED_CLAY:3)
Block(-1,37,8,STAINED_CLAY:3)
Block(-1,38,3,STAINED_CLAY:3)
Block(-1,38,4,STAINED_CLAY:3)
Block(-1,38,5,STAINED_CLAY:3)
Block(-1,38,6,STAINED_CLAY:3)
Block(-1,38,7,STAINED_CLAY:3)
Block(-1,39,2,STAINED_CLAY:3)
Block(-1,39,3,STAINED_CLAY:3)
Block(-1,39,4,STAINED_CLAY:3)
Block(-1,39,5,STAINED_CLAY:3)
Block(-1,39,6,STAINED_CLAY:3)
Block(-1,40,2,STAINED_CLAY:3)
Block(-1,40,3,STAINED_CLAY:3)
Block(-1,40,4,STAINED_CLAY:3)
Block(-1,40,5,STAINED_CLAY:3)
Block(-1,41,2,STAINED_CLAY:3)
Block(-1,41,3,STAINED_CLAY:3)
Block(-1,41,4,STAINED_CLAY:3)
Block(-1,42,1,STAINED_CLAY:3)
Block(-1,42,2,STAINED_CLAY:3)
Block(-1,42,3,STAINED_CLAY:3)
Block(-1,43,1,STAINED_CLAY:3)
Block(-1,43,2,STAINED_CLAY:3)
Block(-1,44,0,STAINED_CLAY:3)
Block(-1,44,1,STAINED_CLAY:3)
Block(-1,45,0,STAINED_CLAY:3)
Block(0,24,8,OBSIDIAN:0)
Block(0,25,8,OBSIDIAN:0)
Block(0,26,8,OBSIDIAN:0)
Block(0,27,7,OBSIDIAN:0)
Block(0,27,8,OBSIDIAN:0)
Block(0,28,7,OBSIDIAN:0)
Block(0,28,8,OBSIDIAN:0)
Block(0,29,6,OBSIDIAN:0)
Block(0,29,7,OBSIDIAN:0)
Block(0,29,8,OBSIDIAN:0)
Block(0,30,6,STAINED_CLAY:3)
Block(0,30,7,STAINED_CLAY:3)
Block(0,30,8,STAINED_CLAY:3)
Block(0,31,6,STAINED_CLAY:3)
Block(0,31,7,STAINED_CLAY:3)
Block(0,31,8,STAINED_CLAY:3)
Block(0,32,5,STAINED_CLAY:3)
Block(0,32,6,STAINED_CLAY:3)
Block(0,32,7,STAINED_CLAY:3)
Block(0,32,8,STAINED_CLAY:3)
Block(0,33,5,STAINED_CLAY:3)
Block(0,33,6,STAINED_CLAY:3)
Block(0,33,7,STAINED_CLAY:3)
Block(0,33,8,STAINED_CLAY:3)
Block(0,34,4,STAINED_CLAY:3)
Block(0,34,5,STAINED_CLAY:3)
Block(0,34,6,STAINED_CLAY:3)
Block(0,34,7,STAINED_CLAY:3)
Block(0,34,8,STAINED_CLAY:3)
Block(0,35,4,STAINED_CLAY:3)
Block(0,35,5,STAINED_CLAY:3)
Block(0,35,6,STAINED_CLAY:3)
Block(0,35,7,STAINED_CLAY:3)
Block(0,35,8,STAINED_CLAY:3)
Block(0,36,4,STAINED_CLAY:3)
Block(0,36,5,STAINED_CLAY:3)
Block(0,36,6,STAINED_CLAY:3)
Block(0,36,7,STAINED_CLAY:3)
Block(0,37,3,STAINED_CLAY:3)
Block(0,37,4,STAINED_CLAY:3)
Block(0,37,5,STAINED_CLAY:3)
Block(0,37,6,STAINED_CLAY:3)
Block(0,38,3,STAINED_CLAY:3)
Block(0,38,4,STAINED_CLAY:3)
Block(0,38,5,STAINED_CLAY:3)
Block(0,39,2,STAINED_CLAY:3)
Block(0,39,3,STAINED_CLAY:3)
Block(0,39,4,STAINED_CLAY:3)
Block(0,40,2,STAINED_CLAY:3)
Block(0,40,3,STAINED_CLAY:3)
Block(0,41,2,STAINED_CLAY:3)
Block(0,42,1,STAINED_CLAY:3)
Block(1,24,8,OBSIDIAN:0)
Block(1,25,8,OBSIDIAN:0)
Block(1,26,8,OBSIDIAN:0)
Block(1,27,7,OBSIDIAN:0)
Block(1,27,8,OBSIDIAN:0)
Block(1,28,7,OBSIDIAN:0)
Block(1,28,8,OBSIDIAN:0)
Block(1,29,6,STAINED_CLAY:3)
Block(1,29,7,STAINED_CLAY:3)
Block(1,29,8,STAINED_CLAY:3)
Block(1,30,6,STAINED_CLAY:3)
Block(1,30,7,STAINED_CLAY:3)
Block(1,30,8,STAINED_CLAY:3)
Block(1,31,6,STAINED_CLAY:3)
Block(1,31,7,STAINED_CLAY:3)
Block(1,31,8,STAINED_CLAY:3)
Block(1,32,5,STAINED_CLAY:3)
Block(1,32,6,STAINED_CLAY:3)
Block(1,32,7,STAINED_CLAY:3)
Block(1,32,8,STAINED_CLAY:3)
Block(1,33,5,STAINED_CLAY:3)
Block(1,33,6,STAINED_CLAY:3)
Block(1,33,7,STAINED_CLAY:3)
Block(1,33,8,STAINED_CLAY:3)
Block(1,34,4,STAINED_CLAY:3)
Block(1,34,5,STAINED_CLAY:3)
Block(1,34,6,STAINED_CLAY:3)
Block(1,34,7,STAINED_CLAY:3)
Block(1,35,4,STAINED_CLAY:3)
Block(1,35,5,STAINED_CLAY:3)
Block(1,35,6,STAINED_CLAY:3)
Block(1,36,4,STAINED_CLAY:3)
Block(1,36,5,STAINED_CLAY:3)
Block(1,37,3,STAINED_CLAY:3)
Block(1,37,4,STAINED_CLAY:3)
Block(1,38,3,STAINED_CLAY:3)
Block(1,39,2,STAINED_CLAY:3)
Block(2,24,8,OBSIDIAN:0)
Block(2,25,8,OBSIDIAN:0)
Block(2,26,8,STAINED_CLAY:3)
Block(2,27,7,STAINED_CLAY:3)
Block(2,27,8,STAINED_CLAY:3)
Block(2,28,7,STAINED_CLAY:3)
Block(2,28,8,STAINED_CLAY:3)
Block(2,29,6,STAINED_CLAY:3)
Block(2,29,7,STAINED_CLAY:3)
Block(2,29,8,STAINED_CLAY:3)
Block(2,30,6,STAINED_CLAY:3)
Block(2,30,7,STAINED_CLAY:3)
Block(2,30,8,STAINED_CLAY:3)
Block(2,31,5,STAINED_CLAY:3)
Block(2,31,6,STAINED_CLAY:3)
Block(2,31,7,STAINED_CLAY:3)
Block(2,31,8,STAINED_CLAY:3)
Block(2,32,5,STAINED_CLAY:3)
Block(2,32,6,STAINED_CLAY:3)
Block(2,32,7,STAINED_CLAY:3)
Block(2,33,5,STAINED_CLAY:3)
Block(2,33,6,STAINED_CLAY:3)
Block(2,34,4,STAINED_CLAY:3)
Block(2,34,5,STAINED_CLAY:3)
Block(2,35,4,STAINED_CLAY:3)
Block(2,36,3,STAINED_CLAY:3)
Block(3,24,8,STAINED_CLAY:3)
Block(3,25,8,STAINED_CLAY:3)
Block(3,26,7,STAINED_CLAY:3)
Block(3,26,8,STAINED_CLAY:3)
Block(3,27,7,STAINED_CLAY:3)
Block(3,27,8,STAINED_CLAY:3)
Block(3,28,7,STAINED_CLAY:3)
Block(3,28,8,STAINED_CLAY:3)
Block(3,29,6,STAINED_CLAY:3)
Block(3,29,7,STAINED_CLAY:3)
Block(3,29,8,STAINED_CLAY:3)
Block(3,30,6,STAINED_CLAY:3)
Block(3,30,7,STAINED_CLAY:3)
Block(3,31,5,STAINED_CLAY:3)
Block(3,31,6,STAINED_CLAY:3)
Block(3,32,5,STAINED_CLAY:3)
Block(4,24,8,STAINED_CLAY:3)
Block(4,25,8,STAINED_CLAY:3)
Block(4,26,7,STAINED_CLAY:3)
Block(4,26,8,STAINED_CLAY:3)
Block(4,27,7,STAINED_CLAY:3)
Block(4,27,8,STAINED_CLAY:3)
Block(4,28,7,STAINED_CLAY:3)
Block(4,29,6,STAINED_CLAY:3)
Block(5,24,8,STAINED_CLAY:3)
Block(5,25,8,STAINED_CLAY:3)
Block(5,26,7,STAINED_CLAY:3)
Block(6,24,8,STAINED_CLAY:3)

#######################################################################
# +-----------------------------------------------------------------+ #
# |                             Branches                            | #
# +-----------------------------------------------------------------+ #
#######################################################################

Branch(0,0,16,true,OBSIDIANSpike_Huge_16C1R2,NORTH,100.0,0)

#######################################################################
# +-----------------------------------------------------------------+ #
# |                             Entities                            | #
# +-----------------------------------------------------------------+ #
#######################################################################


#######################################################################
# +-----------------------------------------------------------------+ #
# |                            Particles                            | #
# +-----------------------------------------------------------------+ #
#######################################################################


#######################################################################
# +-----------------------------------------------------------------+ #
# |                             Spawners                            | #
# +-----------------------------------------------------------------+ #
#######################################################################


#######################################################################
# +-----------------------------------------------------------------+ #
# |                             ModData                             | #
# +-----------------------------------------------------------------+ #
#######################################################################

