
#######################################################################
# +-----------------------------------------------------------------+ #
# |                            BO4 object                           | #
# +-----------------------------------------------------------------+ #
#######################################################################

Author: NLBlackEagle

Description: No description given

SettingsMode: WriteDisable


#######################################################################
# +-----------------------------------------------------------------+ #
# |                          Main settings                          | #
# +-----------------------------------------------------------------+ #
#######################################################################

Frequency: 0

SpawnHeight: highestBlock

UseCenterForHighestBlock: true

##############################
# Height Limits for the BO4. #
##############################

MinHeight: 0

MaxHeight: 255

InheritBO3: 

InheritBO3Rotation: NORTH

OverrideChildSettings: true

OverrideParentHeight: false

CanOverride: true

BranchFrequency: 0

BranchFrequencyGroup: 

MustBeBelowOther: false

MustBeInside: 

CannotBeInside: 

ReplacesBO3: 

MustBeInsideWorldBorders: false

CanSpawnOnWater: true

SpawnOnWaterOnly: false

SpawnUnderWater: false

SpawnAtWaterLevel: false

HeightOffset: 0

RemoveAir: true

ReplaceAbove: 

ReplaceBelow: 

ReplaceWithBiomeBlocks: true

ReplaceWithSurfaceBlock: GRASS

ReplaceWithGroundBlock: DIRT

ReplaceWithStoneBlock: STONE

SmoothRadius: 0

SmoothHeightOffset: 0

SmoothStartTop: false

SmoothStartWood: false

SmoothingSurfaceBlock: 

SmoothingGroundBlock: 

BO3Group: 

IsSpawnPoint: false

DoReplaceBlocks: true


#######################################################################
# +-----------------------------------------------------------------+ #
# |                              Blocks                             | #
# +-----------------------------------------------------------------+ #
#######################################################################

Block(3,0,7,DIRT:1)
Block(3,0,8,DIRT:1)
Block(3,1,8,DIRT:1)
Block(3,2,8,DIRT:1)
Block(3,3,8,DIRT:1)
Block(3,4,8,STAINED_CLAY:0)
Block(3,5,8,STAINED_CLAY:0)
Block(3,6,8,STAINED_CLAY:0)
Block(3,7,8,STAINED_CLAY:0)
Block(3,8,8,STAINED_CLAY:0)
Block(3,9,8,STAINED_CLAY:0)
Block(3,10,8,STAINED_CLAY:0)
Block(3,11,8,STAINED_CLAY:0)
Block(3,12,8,STAINED_CLAY:0)
Block(3,13,8,STAINED_CLAY:0)
Block(3,14,8,STAINED_CLAY:0)
Block(3,15,8,STAINED_CLAY:0)
Block(3,16,8,DIRT:1)
Block(3,17,8,DIRT:1)
Block(3,18,8,DIRT:1)
Block(3,19,8,DIRT:1)
Block(3,20,8,DIRT:1)
Block(3,21,8,DIRT:1)
Block(3,22,8,DIRT:1)
Block(3,23,8,DIRT:1)
Block(3,24,8,DIRT:1)
Block(3,25,8,DIRT:1)
Block(3,26,8,DIRT:1)
Block(3,27,8,DIRT:1)
Block(3,28,8,DIRT:1)
Block(3,29,8,DIRT:1)
Block(4,0,8,DIRT:1)
Block(4,1,8,DIRT:1)
Block(4,2,8,DIRT:1)
Block(4,3,8,DIRT:1)
Block(4,4,8,DIRT:1)
Block(4,5,7,DIRT:1)
Block(4,5,8,DIRT:1)
Block(4,6,7,STAINED_CLAY:0)
Block(4,6,8,STAINED_CLAY:0)
Block(4,7,7,STAINED_CLAY:0)
Block(4,7,8,STAINED_CLAY:0)
Block(4,8,7,STAINED_CLAY:0)
Block(4,8,8,STAINED_CLAY:0)
Block(4,9,7,STAINED_CLAY:0)
Block(4,9,8,STAINED_CLAY:0)
Block(4,10,7,STAINED_CLAY:0)
Block(4,10,8,STAINED_CLAY:0)
Block(4,11,7,STAINED_CLAY:0)
Block(4,11,8,STAINED_CLAY:0)
Block(4,12,7,STAINED_CLAY:0)
Block(4,12,8,STAINED_CLAY:0)
Block(4,13,7,STAINED_CLAY:0)
Block(4,13,8,STAINED_CLAY:0)
Block(4,14,7,STAINED_CLAY:0)
Block(4,14,8,STAINED_CLAY:0)
Block(4,15,7,STAINED_CLAY:0)
Block(4,15,8,STAINED_CLAY:0)
Block(4,16,7,STAINED_CLAY:0)
Block(4,16,8,STAINED_CLAY:0)
Block(4,17,7,STAINED_CLAY:0)
Block(4,17,8,STAINED_CLAY:0)
Block(4,18,7,STAINED_CLAY:0)
Block(4,18,8,STAINED_CLAY:0)
Block(4,19,7,DIRT:1)
Block(4,19,8,DIRT:1)
Block(4,20,7,DIRT:1)
Block(4,20,8,DIRT:1)
Block(4,21,7,DIRT:1)
Block(4,21,8,DIRT:1)
Block(4,22,7,DIRT:1)
Block(4,22,8,DIRT:1)
Block(4,23,7,DIRT:1)
Block(4,23,8,DIRT:1)
Block(4,24,7,DIRT:1)
Block(4,24,8,DIRT:1)
Block(4,25,7,DIRT:1)
Block(4,25,8,DIRT:1)
Block(4,26,7,DIRT:1)
Block(4,26,8,DIRT:1)
Block(4,27,7,DIRT:1)
Block(4,27,8,DIRT:1)
Block(4,28,7,DIRT:1)
Block(4,28,8,DIRT:1)
Block(4,29,7,DIRT:1)
Block(4,29,8,DIRT:1)
Block(4,30,7,DIRT:1)
Block(4,30,8,STAINED_CLAY:0)
Block(4,31,7,STAINED_CLAY:0)
Block(4,31,8,STAINED_CLAY:0)
Block(4,32,7,STAINED_CLAY:0)
Block(4,32,8,STAINED_CLAY:0)
Block(4,33,7,STAINED_CLAY:0)
Block(4,33,8,STAINED_CLAY:0)
Block(4,34,7,STAINED_CLAY:0)
Block(4,34,8,STAINED_CLAY:0)
Block(4,35,7,STAINED_CLAY:0)
Block(4,35,8,STAINED_CLAY:0)
Block(4,36,8,STAINED_CLAY:0)
Block(4,37,8,STAINED_CLAY:0)
Block(4,38,8,STAINED_CLAY:0)
Block(4,39,8,DIRT:1)
Block(4,40,8,DIRT:1)
Block(4,41,8,DIRT:1)
Block(4,42,8,DIRT:1)
Block(4,43,8,DIRT:1)
Block(4,44,8,DIRT:1)
Block(4,45,8,DIRT:1)
Block(4,46,8,DIRT:1)
Block(4,47,8,DIRT:1)
Block(4,48,8,DIRT:1)
Block(4,49,8,DIRT:1)
Block(4,50,8,DIRT:1)
Block(5,4,8,DIRT:1)
Block(5,5,8,DIRT:1)
Block(5,6,8,STAINED_CLAY:0)
Block(5,7,8,STAINED_CLAY:0)
Block(5,8,8,STAINED_CLAY:0)
Block(5,9,7,STAINED_CLAY:0)
Block(5,9,8,STAINED_CLAY:0)
Block(5,10,7,STAINED_CLAY:0)
Block(5,10,8,STAINED_CLAY:0)
Block(5,11,7,STAINED_CLAY:0)
Block(5,11,8,STAINED_CLAY:0)
Block(5,12,7,STAINED_CLAY:0)
Block(5,12,8,STAINED_CLAY:0)
Block(5,13,6,STAINED_CLAY:0)
Block(5,13,7,STAINED_CLAY:0)
Block(5,13,8,STAINED_CLAY:0)
Block(5,14,6,STAINED_CLAY:0)
Block(5,14,7,STAINED_CLAY:0)
Block(5,14,8,STAINED_CLAY:0)
Block(5,15,6,STAINED_CLAY:0)
Block(5,15,7,STAINED_CLAY:0)
Block(5,15,8,STAINED_CLAY:0)
Block(5,16,6,STAINED_CLAY:0)
Block(5,16,7,STAINED_CLAY:0)
Block(5,16,8,STAINED_CLAY:0)
Block(5,17,6,STAINED_CLAY:0)
Block(5,17,7,STAINED_CLAY:0)
Block(5,17,8,STAINED_CLAY:0)
Block(5,18,6,STAINED_CLAY:0)
Block(5,18,7,STAINED_CLAY:0)
Block(5,18,8,STAINED_CLAY:0)
Block(5,19,6,STAINED_CLAY:0)
Block(5,19,7,STAINED_CLAY:0)
Block(5,19,8,STAINED_CLAY:0)
Block(5,20,6,DIRT:1)
Block(5,20,7,DIRT:1)
Block(5,20,8,DIRT:1)
Block(5,21,6,DIRT:1)
Block(5,21,7,DIRT:1)
Block(5,21,8,DIRT:1)
Block(5,22,6,DIRT:1)
Block(5,22,7,DIRT:1)
Block(5,22,8,DIRT:1)
Block(5,23,6,DIRT:1)
Block(5,23,7,DIRT:1)
Block(5,23,8,DIRT:1)
Block(5,24,6,DIRT:1)
Block(5,24,7,DIRT:1)
Block(5,24,8,DIRT:1)
Block(5,25,6,DIRT:1)
Block(5,25,7,DIRT:1)
Block(5,25,8,DIRT:1)
Block(5,26,6,DIRT:1)
Block(5,26,7,DIRT:1)
Block(5,26,8,DIRT:1)
Block(5,27,6,DIRT:1)
Block(5,27,7,DIRT:1)
Block(5,27,8,DIRT:1)
Block(5,28,6,DIRT:1)
Block(5,28,7,DIRT:1)
Block(5,28,8,DIRT:1)
Block(5,29,6,DIRT:1)
Block(5,29,7,DIRT:1)
Block(5,29,8,DIRT:1)
Block(5,30,6,DIRT:1)
Block(5,30,7,DIRT:1)
Block(5,30,8,DIRT:1)
Block(5,31,6,DIRT:1)
Block(5,31,7,STAINED_CLAY:0)
Block(5,31,8,STAINED_CLAY:0)
Block(5,32,6,DIRT:1)
Block(5,32,7,STAINED_CLAY:0)
Block(5,32,8,STAINED_CLAY:0)
Block(5,33,6,STAINED_CLAY:0)
Block(5,33,7,STAINED_CLAY:0)
Block(5,33,8,STAINED_CLAY:0)
Block(5,34,6,STAINED_CLAY:0)
Block(5,34,7,STAINED_CLAY:0)
Block(5,34,8,STAINED_CLAY:0)
Block(5,35,6,STAINED_CLAY:0)
Block(5,35,7,STAINED_CLAY:0)
Block(5,35,8,STAINED_CLAY:0)
Block(5,36,6,STAINED_CLAY:0)
Block(5,36,7,STAINED_CLAY:0)
Block(5,36,8,STAINED_CLAY:0)
Block(5,37,6,STAINED_CLAY:0)
Block(5,37,7,STAINED_CLAY:0)
Block(5,37,8,STAINED_CLAY:0)
Block(5,38,6,STAINED_CLAY:0)
Block(5,38,7,STAINED_CLAY:0)
Block(5,38,8,STAINED_CLAY:0)
Block(5,39,6,STAINED_CLAY:0)
Block(5,39,7,STAINED_CLAY:0)
Block(5,39,8,DIRT:1)
Block(5,40,6,DIRT:1)
Block(5,40,7,DIRT:1)
Block(5,40,8,DIRT:1)
Block(5,41,6,DIRT:1)
Block(5,41,7,DIRT:1)
Block(5,41,8,DIRT:1)
Block(5,42,7,DIRT:1)
Block(5,42,8,DIRT:1)
Block(5,43,7,DIRT:1)
Block(5,43,8,DIRT:1)
Block(5,44,7,DIRT:1)
Block(5,44,8,DIRT:1)
Block(5,45,7,DIRT:1)
Block(5,45,8,DIRT:1)
Block(5,46,7,DIRT:1)
Block(5,46,8,DIRT:1)
Block(5,47,7,DIRT:1)
Block(5,47,8,DIRT:1)
Block(5,48,7,DIRT:1)
Block(5,48,8,DIRT:1)
Block(5,49,7,DIRT:1)
Block(5,49,8,DIRT:1)
Block(5,50,7,DIRT:1)
Block(5,50,8,DIRT:1)
Block(5,51,7,DIRT:1)
Block(5,51,8,DIRT:1)
Block(5,52,7,DIRT:1)
Block(5,52,8,DIRT:1)
Block(5,53,7,DIRT:1)
Block(5,53,8,DIRT:1)
Block(5,54,7,DIRT:1)
Block(5,54,8,DIRT:1)
Block(5,55,7,DIRT:1)
Block(5,55,8,DIRT:1)
Block(6,8,8,STAINED_CLAY:0)
Block(6,9,8,STAINED_CLAY:0)
Block(6,10,8,STAINED_CLAY:0)
Block(6,11,8,STAINED_CLAY:0)
Block(6,12,8,STAINED_CLAY:0)
Block(6,13,7,STAINED_CLAY:0)
Block(6,13,8,STAINED_CLAY:0)
Block(6,14,7,STAINED_CLAY:0)
Block(6,14,8,STAINED_CLAY:0)
Block(6,15,7,STAINED_CLAY:0)
Block(6,15,8,STAINED_CLAY:0)
Block(6,16,7,STAINED_CLAY:0)
Block(6,16,8,STAINED_CLAY:0)
Block(6,17,6,STAINED_CLAY:0)
Block(6,17,7,STAINED_CLAY:0)
Block(6,17,8,STAINED_CLAY:0)
Block(6,18,6,STAINED_CLAY:0)
Block(6,18,7,STAINED_CLAY:0)
Block(6,18,8,STAINED_CLAY:0)
Block(6,19,6,STAINED_CLAY:0)
Block(6,19,7,STAINED_CLAY:0)
Block(6,19,8,STAINED_CLAY:0)
Block(6,20,6,STAINED_CLAY:0)
Block(6,20,7,STAINED_CLAY:0)
Block(6,20,8,STAINED_CLAY:0)
Block(6,21,6,DIRT:1)
Block(6,21,7,STAINED_CLAY:0)
Block(6,21,8,STAINED_CLAY:0)
Block(6,22,5,DIRT:1)
Block(6,22,6,DIRT:1)
Block(6,22,7,DIRT:1)
Block(6,22,8,DIRT:1)
Block(6,23,5,DIRT:1)
Block(6,23,6,DIRT:1)
Block(6,23,7,DIRT:1)
Block(6,23,8,DIRT:1)
Block(6,24,5,DIRT:1)
Block(6,24,6,DIRT:1)
Block(6,24,7,DIRT:1)
Block(6,24,8,DIRT:1)
Block(6,25,5,DIRT:1)
Block(6,25,6,DIRT:1)
Block(6,25,7,DIRT:1)
Block(6,25,8,DIRT:1)
Block(6,26,5,DIRT:1)
Block(6,26,6,DIRT:1)
Block(6,26,7,DIRT:1)
Block(6,26,8,DIRT:1)
Block(6,27,5,DIRT:1)
Block(6,27,6,DIRT:1)
Block(6,27,7,DIRT:1)
Block(6,27,8,DIRT:1)
Block(6,28,5,DIRT:1)
Block(6,28,6,DIRT:1)
Block(6,28,7,DIRT:1)
Block(6,28,8,DIRT:1)
Block(6,29,5,DIRT:1)
Block(6,29,6,DIRT:1)
Block(6,29,7,DIRT:1)
Block(6,29,8,DIRT:1)
Block(6,30,5,DIRT:1)
Block(6,30,6,DIRT:1)
Block(6,30,7,DIRT:1)
Block(6,30,8,DIRT:1)
Block(6,31,5,DIRT:1)
Block(6,31,6,DIRT:1)
Block(6,31,7,DIRT:1)
Block(6,31,8,DIRT:1)
Block(6,32,5,DIRT:1)
Block(6,32,6,DIRT:1)
Block(6,32,7,DIRT:1)
Block(6,32,8,STAINED_CLAY:0)
Block(6,33,5,STAINED_CLAY:0)
Block(6,33,6,STAINED_CLAY:0)
Block(6,33,7,STAINED_CLAY:0)
Block(6,33,8,STAINED_CLAY:0)
Block(6,34,5,STAINED_CLAY:0)
Block(6,34,6,STAINED_CLAY:0)
Block(6,34,7,STAINED_CLAY:0)
Block(6,34,8,STAINED_CLAY:0)
Block(6,35,5,STAINED_CLAY:0)
Block(6,35,6,STAINED_CLAY:0)
Block(6,35,7,STAINED_CLAY:0)
Block(6,35,8,STAINED_CLAY:0)
Block(6,36,5,STAINED_CLAY:0)
Block(6,36,6,STAINED_CLAY:0)
Block(6,36,7,STAINED_CLAY:0)
Block(6,36,8,STAINED_CLAY:0)
Block(6,37,5,STAINED_CLAY:0)
Block(6,37,6,STAINED_CLAY:0)
Block(6,37,7,STAINED_CLAY:0)
Block(6,37,8,STAINED_CLAY:0)
Block(6,38,5,STAINED_CLAY:0)
Block(6,38,6,STAINED_CLAY:0)
Block(6,38,7,STAINED_CLAY:0)
Block(6,38,8,STAINED_CLAY:0)
Block(6,39,5,STAINED_CLAY:0)
Block(6,39,6,STAINED_CLAY:0)
Block(6,39,7,STAINED_CLAY:0)
Block(6,39,8,DIRT:1)
Block(6,40,5,DIRT:1)
Block(6,40,6,DIRT:1)
Block(6,40,7,DIRT:1)
Block(6,40,8,DIRT:1)
Block(6,41,5,DIRT:1)
Block(6,41,6,DIRT:1)
Block(6,41,7,DIRT:1)
Block(6,41,8,DIRT:1)
Block(6,42,5,DIRT:1)
Block(6,42,6,DIRT:1)
Block(6,42,7,DIRT:1)
Block(6,42,8,DIRT:1)
Block(6,43,5,DIRT:1)
Block(6,43,6,DIRT:1)
Block(6,43,7,DIRT:1)
Block(6,43,8,DIRT:1)
Block(6,44,5,DIRT:1)
Block(6,44,6,DIRT:1)
Block(6,44,7,DIRT:1)
Block(6,44,8,DIRT:1)
Block(6,45,5,DIRT:1)
Block(6,45,6,DIRT:1)
Block(6,45,7,DIRT:1)
Block(6,45,8,DIRT:1)
Block(6,46,5,DIRT:1)
Block(6,46,6,DIRT:1)
Block(6,46,7,DIRT:1)
Block(6,46,8,DIRT:1)
Block(6,47,5,DIRT:1)
Block(6,47,6,DIRT:1)
Block(6,47,7,DIRT:1)
Block(6,47,8,DIRT:1)
Block(6,48,6,DIRT:1)
Block(6,48,7,DIRT:1)
Block(6,48,8,DIRT:1)
Block(6,49,6,DIRT:1)
Block(6,49,7,DIRT:1)
Block(6,49,8,DIRT:1)
Block(6,50,6,DIRT:1)
Block(6,50,7,DIRT:1)
Block(6,50,8,DIRT:1)
Block(6,51,6,DIRT:1)
Block(6,51,7,DIRT:1)
Block(6,51,8,DIRT:1)
Block(6,52,6,DIRT:1)
Block(6,52,7,DIRT:1)
Block(6,52,8,DIRT:1)
Block(6,53,6,DIRT:1)
Block(6,53,7,DIRT:1)
Block(6,53,8,DIRT:1)
Block(6,54,6,DIRT:1)
Block(6,54,7,DIRT:1)
Block(6,54,8,DIRT:1)
Block(6,55,6,DIRT:1)
Block(6,55,7,DIRT:1)
Block(6,55,8,DIRT:1)
Block(6,56,6,DIRT:1)
Block(6,56,7,DIRT:1)
Block(6,56,8,DIRT:1)
Block(6,57,6,DIRT:1)
Block(6,57,7,DIRT:1)
Block(6,57,8,DIRT:1)
Block(6,58,6,DIRT:1)
Block(6,58,7,DIRT:1)
Block(6,58,8,DIRT:1)
Block(6,59,6,DIRT:1)
Block(6,59,7,DIRT:1)
Block(6,59,8,DIRT:1)
Block(7,12,8,STAINED_CLAY:0)
Block(7,13,8,STAINED_CLAY:0)
Block(7,14,8,STAINED_CLAY:0)
Block(7,15,8,STAINED_CLAY:0)
Block(7,16,8,STAINED_CLAY:0)
Block(7,17,7,STAINED_CLAY:0)
Block(7,17,8,STAINED_CLAY:0)
Block(7,18,7,STAINED_CLAY:0)
Block(7,18,8,STAINED_CLAY:0)
Block(7,19,7,STAINED_CLAY:0)
Block(7,19,8,STAINED_CLAY:0)
Block(7,20,7,STAINED_CLAY:0)
Block(7,20,8,STAINED_CLAY:0)
Block(7,21,7,STAINED_CLAY:0)
Block(7,21,8,STAINED_CLAY:0)
Block(7,22,6,STAINED_CLAY:0)
Block(7,22,7,STAINED_CLAY:0)
Block(7,22,8,STAINED_CLAY:0)
Block(7,23,6,DIRT:1)
Block(7,23,7,DIRT:1)
Block(7,23,8,STAINED_CLAY:0)
Block(7,24,6,DIRT:1)
Block(7,24,7,DIRT:1)
Block(7,24,8,STAINED_CLAY:0)
Block(7,25,6,DIRT:1)
Block(7,25,7,DIRT:1)
Block(7,25,8,DIRT:1)
Block(7,26,5,DIRT:1)
Block(7,26,6,DIRT:1)
Block(7,26,7,DIRT:1)
Block(7,26,8,DIRT:1)
Block(7,27,5,DIRT:1)
Block(7,27,6,DIRT:1)
Block(7,27,7,DIRT:1)
Block(7,27,8,DIRT:1)
Block(7,28,5,DIRT:1)
Block(7,28,6,DIRT:1)
Block(7,28,7,DIRT:1)
Block(7,28,8,DIRT:1)
Block(7,29,5,DIRT:1)
Block(7,29,6,DIRT:1)
Block(7,29,7,DIRT:1)
Block(7,29,8,DIRT:1)
Block(7,30,5,DIRT:1)
Block(7,30,6,DIRT:1)
Block(7,30,7,DIRT:1)
Block(7,30,8,DIRT:1)
Block(7,31,4,DIRT:1)
Block(7,31,5,DIRT:1)
Block(7,31,6,DIRT:1)
Block(7,31,7,DIRT:1)
Block(7,31,8,DIRT:1)
Block(7,32,4,DIRT:1)
Block(7,32,5,DIRT:1)
Block(7,32,6,DIRT:1)
Block(7,32,7,DIRT:1)
Block(7,32,8,DIRT:1)
Block(7,33,4,DIRT:1)
Block(7,33,5,DIRT:1)
Block(7,33,6,DIRT:1)
Block(7,33,7,DIRT:1)
Block(7,33,8,DIRT:1)
Block(7,34,4,STAINED_CLAY:0)
Block(7,34,5,STAINED_CLAY:0)
Block(7,34,6,STAINED_CLAY:0)
Block(7,34,7,STAINED_CLAY:0)
Block(7,34,8,STAINED_CLAY:0)
Block(7,35,4,STAINED_CLAY:0)
Block(7,35,5,STAINED_CLAY:0)
Block(7,35,6,STAINED_CLAY:0)
Block(7,35,7,STAINED_CLAY:0)
Block(7,35,8,STAINED_CLAY:0)
Block(7,36,4,STAINED_CLAY:0)
Block(7,36,5,STAINED_CLAY:0)
Block(7,36,6,STAINED_CLAY:0)
Block(7,36,7,STAINED_CLAY:0)
Block(7,36,8,STAINED_CLAY:0)
Block(7,37,4,STAINED_CLAY:0)
Block(7,37,5,STAINED_CLAY:0)
Block(7,37,6,STAINED_CLAY:0)
Block(7,37,7,STAINED_CLAY:0)
Block(7,37,8,STAINED_CLAY:0)
Block(7,38,4,STAINED_CLAY:0)
Block(7,38,5,STAINED_CLAY:0)
Block(7,38,6,STAINED_CLAY:0)
Block(7,38,7,STAINED_CLAY:0)
Block(7,38,8,STAINED_CLAY:0)
Block(7,39,4,STAINED_CLAY:0)
Block(7,39,5,STAINED_CLAY:0)
Block(7,39,6,STAINED_CLAY:0)
Block(7,39,7,STAINED_CLAY:0)
Block(7,39,8,DIRT:1)
Block(7,40,4,DIRT:1)
Block(7,40,5,DIRT:1)
Block(7,40,6,DIRT:1)
Block(7,40,7,DIRT:1)
Block(7,40,8,DIRT:1)
Block(7,41,4,DIRT:1)
Block(7,41,5,DIRT:1)
Block(7,41,6,DIRT:1)
Block(7,41,7,DIRT:1)
Block(7,41,8,DIRT:1)
Block(7,42,4,DIRT:1)
Block(7,42,5,DIRT:1)
Block(7,42,6,DIRT:1)
Block(7,42,7,DIRT:1)
Block(7,42,8,DIRT:1)
Block(7,43,4,DIRT:1)
Block(7,43,5,DIRT:1)
Block(7,43,6,DIRT:1)
Block(7,43,7,DIRT:1)
Block(7,43,8,DIRT:1)
Block(7,44,4,DIRT:1)
Block(7,44,5,DIRT:1)
Block(7,44,6,DIRT:1)
Block(7,44,7,DIRT:1)
Block(7,44,8,DIRT:1)
Block(7,45,4,DIRT:1)
Block(7,45,5,DIRT:1)
Block(7,45,6,DIRT:1)
Block(7,45,7,DIRT:1)
Block(7,45,8,DIRT:1)
Block(7,46,4,DIRT:1)
Block(7,46,5,DIRT:1)
Block(7,46,6,DIRT:1)
Block(7,46,7,DIRT:1)
Block(7,46,8,DIRT:1)
Block(7,47,4,DIRT:1)
Block(7,47,5,DIRT:1)
Block(7,47,6,DIRT:1)
Block(7,47,7,DIRT:1)
Block(7,47,8,DIRT:1)
Block(7,48,4,DIRT:1)
Block(7,48,5,DIRT:1)
Block(7,48,6,DIRT:1)
Block(7,48,7,DIRT:1)
Block(7,48,8,DIRT:1)
Block(7,49,4,DIRT:1)
Block(7,49,5,DIRT:1)
Block(7,49,6,DIRT:1)
Block(7,49,7,DIRT:1)
Block(7,49,8,DIRT:1)
Block(7,50,4,DIRT:1)
Block(7,50,5,DIRT:1)
Block(7,50,6,DIRT:1)
Block(7,50,7,DIRT:1)
Block(7,50,8,DIRT:1)
Block(7,51,4,DIRT:1)
Block(7,51,5,DIRT:1)
Block(7,51,6,DIRT:1)
Block(7,51,7,DIRT:1)
Block(7,51,8,DIRT:1)
Block(7,52,4,DIRT:1)
Block(7,52,5,DIRT:1)
Block(7,52,6,DIRT:1)
Block(7,52,7,DIRT:1)
Block(7,52,8,DIRT:1)
Block(7,53,4,DIRT:1)
Block(7,53,5,DIRT:1)
Block(7,53,6,DIRT:1)
Block(7,53,7,DIRT:1)
Block(7,53,8,DIRT:1)
Block(7,54,5,DIRT:1)
Block(7,54,6,DIRT:1)
Block(7,54,7,DIRT:1)
Block(7,54,8,DIRT:1)
Block(7,55,5,DIRT:1)
Block(7,55,6,DIRT:1)
Block(7,55,7,DIRT:1)
Block(7,55,8,DIRT:1)
Block(7,56,5,DIRT:1)
Block(7,56,6,DIRT:1)
Block(7,56,7,DIRT:1)
Block(7,56,8,DIRT:1)
Block(7,57,5,DIRT:1)
Block(7,57,6,DIRT:1)
Block(7,57,7,DIRT:1)
Block(7,57,8,DIRT:1)
Block(7,58,5,DIRT:1)
Block(7,58,6,DIRT:1)
Block(7,58,7,DIRT:1)
Block(7,58,8,DIRT:1)
Block(7,59,5,DIRT:1)
Block(7,59,6,DIRT:1)
Block(7,59,7,DIRT:1)
Block(7,59,8,DIRT:1)
Block(7,60,5,DIRT:1)
Block(7,60,6,DIRT:1)
Block(7,60,7,DIRT:1)
Block(7,60,8,DIRT:1)
Block(7,61,5,DIRT:1)
Block(7,61,6,DIRT:1)
Block(7,61,7,DIRT:1)
Block(7,61,8,DIRT:1)
Block(7,62,5,DIRT:1)
Block(7,62,6,DIRT:1)
Block(7,62,7,DIRT:1)
Block(7,62,8,DIRT:1)
Block(7,63,5,DIRT:1)
Block(7,63,6,DIRT:1)
Block(7,63,7,DIRT:1)
Block(7,63,8,DIRT:1)
Block(7,64,5,DIRT:1)
Block(7,64,6,DIRT:1)
Block(7,64,7,DIRT:1)
Block(7,64,8,DIRT:1)

#######################################################################
# +-----------------------------------------------------------------+ #
# |                             Branches                            | #
# +-----------------------------------------------------------------+ #
#######################################################################

Branch(16,0,0,true,MudSpike_Huge_09C1R0,NORTH,100.0,0)

#######################################################################
# +-----------------------------------------------------------------+ #
# |                             Entities                            | #
# +-----------------------------------------------------------------+ #
#######################################################################


#######################################################################
# +-----------------------------------------------------------------+ #
# |                            Particles                            | #
# +-----------------------------------------------------------------+ #
#######################################################################


#######################################################################
# +-----------------------------------------------------------------+ #
# |                             Spawners                            | #
# +-----------------------------------------------------------------+ #
#######################################################################


#######################################################################
# +-----------------------------------------------------------------+ #
# |                             ModData                             | #
# +-----------------------------------------------------------------+ #
#######################################################################

