#######################################################################
# +-----------------------------------------------------------------+ #
# |                            BO3 object                           | #
# +-----------------------------------------------------------------+ #
#######################################################################

Author: Bo3 BulkEdit

Description: Converted Schematic - Modified by Bo3BulkEdit

Version: 3

SettingsMode: WriteDisable

#######################################################################
# +-----------------------------------------------------------------+ #
# |                          Main settings                          | #
# +-----------------------------------------------------------------+ #
#######################################################################



Frequency: 0


SpawnHeight: randomY





##############################
# Height Limits for the BO3. #
##############################

MinHeight: 0
MaxHeight: 256

#######################################################################
# +-----------------------------------------------------------------+ #
# |                      Source block settings                      | #
# +-----------------------------------------------------------------+ #
#######################################################################

CanOverride: true
MaxPercentageOutsideSourceBlock: 100
OutsideSourceBlock: placeAnyway

#######################################################################
# +-----------------------------------------------------------------+ #
# |                               OTG+                              | #
# +-----------------------------------------------------------------+ #
#######################################################################

#######################################################################
# +-----------------------------------------------------------------+ #
# |                              Blocks                             | #
# +-----------------------------------------------------------------+ #
#######################################################################

B(0,750,0,AIR)
B(15,750,15,AIR)
B(1,-4,1,betternether:quartz_stained_glass:15)
B(2,-4,1,betternether:quartz_stained_glass:15)
B(1,-4,2,betternether:quartz_stained_glass:15)
B(2,-4,2,betternether:quartz_stained_glass:15)
B(0,-3,0,betternether:quartz_stained_glass:15)
B(1,-3,0,betternether:quartz_stained_glass:15)
B(2,-3,0,betternether:quartz_stained_glass:15)
B(0,-3,1,betternether:quartz_stained_glass:15)
B(1,-3,1,betternether:quartz_stained_glass:15)
B(2,-3,1,betternether:quartz_stained_glass:15)
B(0,-3,2,betternether:quartz_stained_glass:15)
B(1,-3,2,betternether:quartz_stained_glass:15)
B(2,-3,2,betternether:quartz_stained_glass:15)
B(0,-2,0,betternether:quartz_stained_glass:15)
B(1,-2,0,betternether:quartz_stained_glass:15)
B(2,-2,0,betternether:quartz_stained_glass:15)
B(0,-2,1,betternether:quartz_stained_glass:15)
B(1,-2,1,betternether:quartz_stained_glass:15)
B(2,-2,1,betternether:quartz_stained_glass:15)
B(0,-2,2,betternether:quartz_stained_glass:15)
B(1,-2,2,betternether:quartz_stained_glass:15)
B(1,-1,0,betternether:quartz_stained_glass:15)
B(2,-1,0,betternether:quartz_stained_glass:15)
B(0,-1,1,betternether:quartz_stained_glass:15)
B(1,-1,1,betternether:quartz_stained_glass:15)
B(0,-1,2,betternether:quartz_stained_glass:15)
B(0,0,0,betternether:quartz_stained_glass:15)
B(1,0,0,betternether:quartz_stained_glass:15)
B(0,0,1,betternether:quartz_stained_glass:15)
B(0,1,0,betternether:quartz_stained_glass:15)
B(1,1,0,betternether:quartz_stained_glass:15)

