#######################################################################
# +-----------------------------------------------------------------+ #
# |                            BO3 object                           | #
# +-----------------------------------------------------------------+ #
#######################################################################

Author: Bo3 BulkEdit

Description: Converted Schematic - Modified by Bo3BulkEdit

Version: 3

SettingsMode: WriteDisable

#######################################################################
# +-----------------------------------------------------------------+ #
# |                          Main settings                          | #
# +-----------------------------------------------------------------+ #
#######################################################################

IsOTGPlus: true
Tree: false
Frequency: 1
Rarity: 100.0
RotateRandomly: false
SpawnHeight: randomY
MaxBranchDepth: 10
ExcludedBiomes: All

##############################
# Height Limits for the BO3. #
##############################

MinHeight: 0
MaxHeight: 255

#######################################################################
# +-----------------------------------------------------------------+ #
# |                      Source block settings                      | #
# +-----------------------------------------------------------------+ #
#######################################################################

CanOverride: true
MaxPercentageOutsideSourceBlock: 100
OutsideSourceBlock: placeAnyway

#######################################################################
# +-----------------------------------------------------------------+ #
# |                               OTG+                              | #
# +-----------------------------------------------------------------+ #
#######################################################################

BO3Group: CeilingCrystals:0

#######################################################################
# +-----------------------------------------------------------------+ #
# |                              Blocks                             | #
# +-----------------------------------------------------------------+ #
#######################################################################

B(0,750,0,AIR)
B(15,750,15,AIR)
B(13,-20,9,betternether:quartz_stained_glass:15)
B(12,-20,10,betternether:quartz_stained_glass:15)
B(13,-20,10,betternether:quartz_stained_glass:15)
B(12,-20,11,betternether:quartz_stained_glass:15)
B(13,-20,11,betternether:quartz_stained_glass:15)
B(13,-20,12,betternether:quartz_stained_glass:15)
B(13,-19,5,betternether:quartz_stained_glass:15)
B(12,-19,6,betternether:quartz_stained_glass:15)
B(13,-19,6,betternether:quartz_stained_glass:15)
B(10,-19,7,betternether:quartz_stained_glass:15)
B(11,-19,7,betternether:quartz_stained_glass:15)
B(12,-19,7,betternether:quartz_stained_glass:15)
B(13,-19,7,betternether:quartz_stained_glass:15)
B(10,-19,8,betternether:quartz_stained_glass:15)
B(11,-19,8,betternether:quartz_stained_glass:15)
B(12,-19,8,betternether:quartz_stained_glass:15)
B(13,-19,8,betternether:quartz_stained_glass:15)
B(10,-19,9,betternether:quartz_stained_glass:15)
B(11,-19,9,betternether:quartz_stained_glass:15)
B(12,-19,9,betternether:quartz_stained_glass:15)
B(13,-19,9,betternether:quartz_stained_glass:15)
B(14,-19,9,betternether:quartz_stained_glass:15)
B(11,-19,10,betternether:quartz_stained_glass:15)
B(12,-19,10,betternether:quartz_stained_glass:15)
B(13,-19,10,betternether:quartz_stained_glass:15)
B(14,-19,10,betternether:quartz_stained_glass:15)
B(11,-19,11,betternether:quartz_stained_glass:15)
B(12,-19,11,betternether:quartz_stained_glass:15)
B(13,-19,11,betternether:quartz_stained_glass:15)
B(14,-19,11,betternether:quartz_stained_glass:15)
B(13,-19,12,betternether:quartz_stained_glass:15)
B(9,-18,4,betternether:quartz_stained_glass:15)
B(11,-18,4,betternether:quartz_stained_glass:15)
B(12,-18,4,betternether:quartz_stained_glass:15)
B(13,-18,4,betternether:quartz_stained_glass:15)
B(9,-18,5,betternether:quartz_stained_glass:15)
B(10,-18,5,betternether:quartz_stained_glass:15)
B(11,-18,5,betternether:quartz_stained_glass:15)
B(12,-18,5,betternether:quartz_stained_glass:15)
B(13,-18,5,betternether:quartz_stained_glass:15)
B(9,-18,6,betternether:quartz_stained_glass:15)
B(10,-18,6,betternether:quartz_stained_glass:15)
B(11,-18,6,betternether:quartz_stained_glass:15)
B(12,-18,6,betternether:quartz_stained_glass:15)
B(13,-18,6,betternether:quartz_stained_glass:15)
B(9,-18,7,betternether:quartz_stained_glass:15)
B(10,-18,7,betternether:quartz_stained_glass:15)
RB(11,-18,7,srparasites:parasitestain:1,80,quark:crystal:1,30,srparasites:parasiterubbledense:1,100)
B(12,-18,7,betternether:quartz_stained_glass:15)
B(13,-18,7,betternether:quartz_stained_glass:15)
B(14,-18,7,betternether:quartz_stained_glass:15)
B(9,-18,8,betternether:quartz_stained_glass:15)
B(10,-18,8,betternether:quartz_stained_glass:15)
B(11,-18,8,betternether:quartz_stained_glass:15)
RB(12,-18,8,srparasites:parasitestain:1,80,quark:crystal:1,30,srparasites:parasiterubbledense:1,100)
B(13,-18,8,betternether:quartz_stained_glass:15)
B(14,-18,8,betternether:quartz_stained_glass:15)
B(10,-18,9,betternether:quartz_stained_glass:15)
B(14,-18,9,betternether:quartz_stained_glass:15)
B(10,-18,10,betternether:quartz_stained_glass:15)
B(11,-18,10,betternether:quartz_stained_glass:15)
B(12,-18,10,betternether:quartz_stained_glass:15)
B(13,-18,10,betternether:quartz_stained_glass:15)
B(14,-18,10,betternether:quartz_stained_glass:15)
B(11,-18,11,betternether:quartz_stained_glass:15)
B(12,-18,11,betternether:quartz_stained_glass:15)
B(13,-18,11,betternether:quartz_stained_glass:15)
B(12,-17,1,betternether:quartz_stained_glass:15)
B(9,-17,2,betternether:quartz_stained_glass:15)
B(11,-17,2,betternether:quartz_stained_glass:15)
B(12,-17,2,betternether:quartz_stained_glass:15)
B(8,-17,3,betternether:quartz_stained_glass:15)
B(9,-17,3,betternether:quartz_stained_glass:15)
B(10,-17,3,betternether:quartz_stained_glass:15)
B(11,-17,3,betternether:quartz_stained_glass:15)
B(12,-17,3,betternether:quartz_stained_glass:15)
B(8,-17,4,betternether:quartz_stained_glass:15)
B(9,-17,4,betternether:quartz_stained_glass:15)
B(10,-17,4,betternether:quartz_stained_glass:15)
B(11,-17,4,betternether:quartz_stained_glass:15)
B(12,-17,4,betternether:quartz_stained_glass:15)
B(13,-17,4,betternether:quartz_stained_glass:15)
B(9,-17,5,betternether:quartz_stained_glass:15)
RB(10,-17,5,srparasites:parasitestain:1,80,quark:crystal:1,30,srparasites:parasiterubbledense:1,100)
RB(11,-17,5,srparasites:parasitestain:1,80,quark:crystal:1,30,srparasites:parasiterubbledense:1,100)
B(12,-17,5,betternether:quartz_stained_glass:15)
B(13,-17,5,betternether:quartz_stained_glass:15)
B(9,-17,6,betternether:quartz_stained_glass:15)
B(10,-17,6,betternether:quartz_stained_glass:15)
RB(11,-17,6,srparasites:parasitestain:1,80,quark:crystal:1,30,srparasites:parasiterubbledense:1,100)
B(12,-17,6,betternether:quartz_stained_glass:15)
B(13,-17,6,betternether:quartz_stained_glass:15)
B(9,-17,7,betternether:quartz_stained_glass:15)
B(10,-17,7,betternether:quartz_stained_glass:15)
RB(11,-17,7,srparasites:parasitestain:1,80,quark:crystal:1,30,srparasites:parasiterubbledense:1,100)
RB(12,-17,7,srparasites:parasitestain:1,80,quark:crystal:1,30,srparasites:parasiterubbledense:1,100)
B(13,-17,7,betternether:quartz_stained_glass:15)
B(14,-17,7,betternether:quartz_stained_glass:15)
B(9,-17,8,betternether:quartz_stained_glass:15)
B(10,-17,8,betternether:quartz_stained_glass:15)
RB(11,-17,8,srparasites:parasitestain:1,80,quark:crystal:1,30,srparasites:parasiterubbledense:1,100)
RB(12,-17,8,srparasites:parasitestain:1,80,quark:crystal:1,30,srparasites:parasiterubbledense:1,100)
B(13,-17,8,betternether:quartz_stained_glass:15)
B(14,-17,8,betternether:quartz_stained_glass:15)
B(9,-17,9,betternether:quartz_stained_glass:15)
B(10,-17,9,betternether:quartz_stained_glass:15)
B(11,-17,9,betternether:quartz_stained_glass:15)
B(12,-17,9,betternether:quartz_stained_glass:15)
B(13,-17,9,betternether:quartz_stained_glass:15)
B(14,-17,9,betternether:quartz_stained_glass:15)
B(11,-17,10,betternether:quartz_stained_glass:15)
B(12,-17,10,betternether:quartz_stained_glass:15)
B(13,-17,10,betternether:quartz_stained_glass:15)
B(14,-17,10,betternether:quartz_stained_glass:15)
B(8,-16,0,betternether:quartz_stained_glass:15)
B(9,-16,0,betternether:quartz_stained_glass:15)
B(10,-16,0,betternether:quartz_stained_glass:15)
B(11,-16,0,betternether:quartz_stained_glass:15)
B(12,-16,0,betternether:quartz_stained_glass:15)
B(8,-16,1,betternether:quartz_stained_glass:15)
B(9,-16,1,betternether:quartz_stained_glass:15)
B(10,-16,1,betternether:quartz_stained_glass:15)
B(11,-16,1,betternether:quartz_stained_glass:15)
B(12,-16,1,betternether:quartz_stained_glass:15)
B(8,-16,2,betternether:quartz_stained_glass:15)
B(9,-16,2,betternether:quartz_stained_glass:15)
B(10,-16,2,betternether:quartz_stained_glass:15)
B(11,-16,2,betternether:quartz_stained_glass:15)
B(12,-16,2,betternether:quartz_stained_glass:15)
B(8,-16,3,betternether:quartz_stained_glass:15)
B(9,-16,3,betternether:quartz_stained_glass:15)
RB(10,-16,3,srparasites:parasitestain:1,80,quark:crystal:1,30,srparasites:parasiterubbledense:1,100)
B(11,-16,3,betternether:quartz_stained_glass:15)
B(12,-16,3,betternether:quartz_stained_glass:15)
B(8,-16,4,betternether:quartz_stained_glass:15)
B(9,-16,4,betternether:quartz_stained_glass:15)
B(10,-16,4,betternether:quartz_stained_glass:15)
RB(11,-16,4,srparasites:parasitestain:1,80,quark:crystal:1,30,srparasites:parasiterubbledense:1,100)
B(12,-16,4,betternether:quartz_stained_glass:15)
B(13,-16,4,betternether:quartz_stained_glass:15)
B(9,-16,5,betternether:quartz_stained_glass:15)
B(10,-16,5,betternether:quartz_stained_glass:15)
RB(11,-16,5,srparasites:parasitestain:1,80,quark:crystal:1,30,srparasites:parasiterubbledense:1,100)
B(12,-16,5,betternether:quartz_stained_glass:15)
B(13,-16,5,betternether:quartz_stained_glass:15)
B(9,-16,6,betternether:quartz_stained_glass:15)
B(10,-16,6,betternether:quartz_stained_glass:15)
RB(11,-16,6,srparasites:parasitestain:1,80,quark:crystal:1,30,srparasites:parasiterubbledense:1,100)
B(12,-16,6,betternether:quartz_stained_glass:15)
B(13,-16,6,betternether:quartz_stained_glass:15)
B(9,-16,7,betternether:quartz_stained_glass:15)
B(10,-16,7,betternether:quartz_stained_glass:15)
RB(11,-16,7,srparasites:parasitestain:1,80,quark:crystal:1,30,srparasites:parasiterubbledense:1,100)
B(12,-16,7,betternether:quartz_stained_glass:15)
B(13,-16,7,betternether:quartz_stained_glass:15)
B(14,-16,7,betternether:quartz_stained_glass:15)
B(9,-16,8,betternether:quartz_stained_glass:15)
B(10,-16,8,betternether:quartz_stained_glass:15)
B(11,-16,8,betternether:quartz_stained_glass:15)
B(12,-16,8,betternether:quartz_stained_glass:15)
B(13,-16,8,betternether:quartz_stained_glass:15)
B(14,-16,8,betternether:quartz_stained_glass:15)
B(10,-16,9,betternether:quartz_stained_glass:15)
B(11,-16,9,betternether:quartz_stained_glass:15)
B(12,-16,9,betternether:quartz_stained_glass:15)
B(13,-16,9,betternether:quartz_stained_glass:15)
B(14,-16,9,betternether:quartz_stained_glass:15)
B(7,-15,0,betternether:quartz_stained_glass:15)
B(8,-15,0,betternether:quartz_stained_glass:15)
B(9,-15,0,betternether:quartz_stained_glass:15)
B(10,-15,0,betternether:quartz_stained_glass:15)
B(11,-15,0,betternether:quartz_stained_glass:15)
B(12,-15,0,betternether:quartz_stained_glass:15)
B(8,-15,1,betternether:quartz_stained_glass:15)
B(9,-15,1,betternether:quartz_stained_glass:15)
RB(10,-15,1,srparasites:parasitestain:1,80,quark:crystal:1,30,srparasites:parasiterubbledense:1,100)
B(11,-15,1,betternether:quartz_stained_glass:15)
B(12,-15,1,betternether:quartz_stained_glass:15)
B(8,-15,2,betternether:quartz_stained_glass:15)
B(9,-15,2,betternether:quartz_stained_glass:15)
RB(10,-15,2,srparasites:parasitestain:1,80,quark:crystal:1,30,srparasites:parasiterubbledense:1,100)
B(11,-15,2,betternether:quartz_stained_glass:15)
B(12,-15,2,betternether:quartz_stained_glass:15)
B(8,-15,3,betternether:quartz_stained_glass:15)
B(9,-15,3,betternether:quartz_stained_glass:15)
RB(10,-15,3,srparasites:parasitestain:1,80,quark:crystal:1,30,srparasites:parasiterubbledense:1,100)
RB(11,-15,3,srparasites:parasitestain:1,80,quark:crystal:1,30,srparasites:parasiterubbledense:1,100)
B(12,-15,3,betternether:quartz_stained_glass:15)
B(8,-15,4,betternether:quartz_stained_glass:15)
B(9,-15,4,betternether:quartz_stained_glass:15)
B(10,-15,4,betternether:quartz_stained_glass:15)
B(11,-15,4,betternether:quartz_stained_glass:15)
B(12,-15,4,betternether:quartz_stained_glass:15)
B(13,-15,4,betternether:quartz_stained_glass:15)
B(9,-15,5,betternether:quartz_stained_glass:15)
B(10,-15,5,betternether:quartz_stained_glass:15)
B(11,-15,5,betternether:quartz_stained_glass:15)
B(12,-15,5,betternether:quartz_stained_glass:15)
B(13,-15,5,betternether:quartz_stained_glass:15)
B(9,-15,6,betternether:quartz_stained_glass:15)
B(10,-15,6,betternether:quartz_stained_glass:15)
B(11,-15,6,betternether:quartz_stained_glass:15)
B(12,-15,6,betternether:quartz_stained_glass:15)
B(13,-15,6,betternether:quartz_stained_glass:15)
B(9,-15,7,betternether:quartz_stained_glass:15)
B(10,-15,7,betternether:quartz_stained_glass:15)
B(11,-15,7,betternether:quartz_stained_glass:15)
B(12,-15,7,betternether:quartz_stained_glass:15)
B(13,-15,7,betternether:quartz_stained_glass:15)
B(14,-15,7,betternether:quartz_stained_glass:15)
B(9,-15,8,betternether:quartz_stained_glass:15)
B(10,-15,8,betternether:quartz_stained_glass:15)
B(11,-15,8,betternether:quartz_stained_glass:15)
B(12,-15,8,betternether:quartz_stained_glass:15)
B(13,-15,8,betternether:quartz_stained_glass:15)
B(14,-15,8,betternether:quartz_stained_glass:15)
B(10,-15,9,betternether:quartz_stained_glass:15)
B(11,-15,9,betternether:quartz_stained_glass:15)
B(7,-14,0,betternether:quartz_stained_glass:15)
B(8,-14,0,betternether:quartz_stained_glass:15)
RB(9,-14,0,srparasites:parasitestain:1,80,quark:crystal:1,30,srparasites:parasiterubbledense:1,100)
RB(10,-14,0,srparasites:parasitestain:1,80,quark:crystal:1,30,srparasites:parasiterubbledense:1,100)
B(11,-14,0,betternether:quartz_stained_glass:15)
B(12,-14,0,betternether:quartz_stained_glass:15)
B(8,-14,1,betternether:quartz_stained_glass:15)
B(9,-14,1,betternether:quartz_stained_glass:15)
B(10,-14,1,betternether:quartz_stained_glass:15)
B(11,-14,1,betternether:quartz_stained_glass:15)
B(12,-14,1,betternether:quartz_stained_glass:15)
B(8,-14,2,betternether:quartz_stained_glass:15)
B(9,-14,2,betternether:quartz_stained_glass:15)
B(10,-14,2,betternether:quartz_stained_glass:15)
B(11,-14,2,betternether:quartz_stained_glass:15)
B(12,-14,2,betternether:quartz_stained_glass:15)
B(8,-14,3,betternether:quartz_stained_glass:15)
B(9,-14,3,betternether:quartz_stained_glass:15)
RB(10,-14,3,srparasites:parasitestain:1,80,quark:crystal:1,30,srparasites:parasiterubbledense:1,100)
B(11,-14,3,betternether:quartz_stained_glass:15)
B(12,-14,3,betternether:quartz_stained_glass:15)
B(8,-14,4,betternether:quartz_stained_glass:15)
B(9,-14,4,betternether:quartz_stained_glass:15)
B(10,-14,4,betternether:quartz_stained_glass:15)
B(11,-14,4,betternether:quartz_stained_glass:15)
B(12,-14,4,betternether:quartz_stained_glass:15)
B(13,-14,4,betternether:quartz_stained_glass:15)
B(9,-14,5,betternether:quartz_stained_glass:15)
B(10,-14,5,betternether:quartz_stained_glass:15)
B(11,-14,5,betternether:quartz_stained_glass:15)
B(12,-14,5,betternether:quartz_stained_glass:15)
B(13,-14,5,betternether:quartz_stained_glass:15)
B(9,-14,6,betternether:quartz_stained_glass:15)
B(10,-14,6,betternether:quartz_stained_glass:15)
B(11,-14,6,betternether:quartz_stained_glass:15)
B(12,-14,6,betternether:quartz_stained_glass:15)
B(13,-14,6,betternether:quartz_stained_glass:15)
B(9,-14,7,betternether:quartz_stained_glass:15)
B(10,-14,7,betternether:quartz_stained_glass:15)
B(11,-14,7,betternether:quartz_stained_glass:15)
B(7,-13,0,betternether:quartz_stained_glass:15)
B(8,-13,0,betternether:quartz_stained_glass:15)
RB(9,-13,0,srparasites:parasitestain:1,80,quark:crystal:1,30,srparasites:parasiterubbledense:1,100)
RB(10,-13,0,srparasites:parasitestain:1,80,quark:crystal:1,30,srparasites:parasiterubbledense:1,100)
B(11,-13,0,betternether:quartz_stained_glass:15)
B(12,-13,0,betternether:quartz_stained_glass:15)
B(8,-13,1,betternether:quartz_stained_glass:15)
B(9,-13,1,betternether:quartz_stained_glass:15)
B(10,-13,1,betternether:quartz_stained_glass:15)
B(11,-13,1,betternether:quartz_stained_glass:15)
B(12,-13,1,betternether:quartz_stained_glass:15)
B(8,-13,2,betternether:quartz_stained_glass:15)
B(9,-13,2,betternether:quartz_stained_glass:15)
B(10,-13,2,betternether:quartz_stained_glass:15)
B(11,-13,2,betternether:quartz_stained_glass:15)
B(12,-13,2,betternether:quartz_stained_glass:15)
B(8,-13,3,betternether:quartz_stained_glass:15)
B(9,-13,3,betternether:quartz_stained_glass:15)
B(10,-13,3,betternether:quartz_stained_glass:15)
B(11,-13,3,betternether:quartz_stained_glass:15)
B(12,-13,3,betternether:quartz_stained_glass:15)
B(8,-13,4,betternether:quartz_stained_glass:15)
B(9,-13,4,betternether:quartz_stained_glass:15)
B(10,-13,4,betternether:quartz_stained_glass:15)
B(11,-13,4,betternether:quartz_stained_glass:15)
B(12,-13,4,betternether:quartz_stained_glass:15)
B(13,-13,4,betternether:quartz_stained_glass:15)
B(9,-13,5,betternether:quartz_stained_glass:15)
B(10,-13,5,betternether:quartz_stained_glass:15)
B(7,-12,0,betternether:quartz_stained_glass:15)
B(8,-12,0,betternether:quartz_stained_glass:15)
B(9,-12,0,betternether:quartz_stained_glass:15)
B(10,-12,0,betternether:quartz_stained_glass:15)
B(11,-12,0,betternether:quartz_stained_glass:15)
B(12,-12,0,betternether:quartz_stained_glass:15)
B(8,-12,1,betternether:quartz_stained_glass:15)
B(9,-12,1,betternether:quartz_stained_glass:15)
B(10,-12,1,betternether:quartz_stained_glass:15)
B(11,-12,1,betternether:quartz_stained_glass:15)
B(12,-12,1,betternether:quartz_stained_glass:15)
B(8,-12,2,betternether:quartz_stained_glass:15)
B(9,-12,2,betternether:quartz_stained_glass:15)
B(10,-12,2,betternether:quartz_stained_glass:15)
B(11,-12,2,betternether:quartz_stained_glass:15)
B(12,-12,2,betternether:quartz_stained_glass:15)
B(8,-12,3,betternether:quartz_stained_glass:15)
B(9,-12,3,betternether:quartz_stained_glass:15)
B(10,-12,3,betternether:quartz_stained_glass:15)
B(7,-11,0,betternether:quartz_stained_glass:15)
B(8,-11,0,betternether:quartz_stained_glass:15)
B(9,-11,0,betternether:quartz_stained_glass:15)
B(10,-11,0,betternether:quartz_stained_glass:15)
B(11,-11,0,betternether:quartz_stained_glass:15)
B(12,-11,0,betternether:quartz_stained_glass:15)
B(8,-11,1,betternether:quartz_stained_glass:15)
B(9,-11,1,betternether:quartz_stained_glass:15)

