
#######################################################################
# +-----------------------------------------------------------------+ #
# |                            BO4 object                           | #
# +-----------------------------------------------------------------+ #
#######################################################################

Author: NLBlackEagle

Description: No description given

SettingsMode: WriteWithoutComments


#######################################################################
# +-----------------------------------------------------------------+ #
# |                          Main settings                          | #
# +-----------------------------------------------------------------+ #
#######################################################################

FixedRotation: 

Frequency: 0

SpawnHeight: highestBlock

UseCenterForHighestBlock: true

##############################
# Height Limits for the BO4. #
##############################

MinHeight: 0

MaxHeight: 255

InheritBO3: 

InheritBO3Rotation: NORTH

OverrideChildSettings: true

OverrideParentHeight: false

CanOverride: true

BranchFrequency: 0

BranchFrequencyGroup: 

MustBeBelowOther: false

MustBeInside: 

CannotBeInside: 

ReplacesBO3: 

MustBeInsideWorldBorders: false

CanSpawnOnWater: true

SpawnOnWaterOnly: false

SpawnUnderWater: false

SpawnAtWaterLevel: false

HeightOffset: 0

RemoveAir: false

ReplaceAbove: 

ReplaceBelow: 

ReplaceWithBiomeBlocks: false

ReplaceWithSurfaceBlock: GRASS

ReplaceWithGroundBlock: DIRT

ReplaceWithStoneBlock: STONE

SmoothRadius: 0

SmoothHeightOffset: 0

SmoothStartTop: false

SmoothStartWood: false

SmoothingSurfaceBlock: 

SmoothingGroundBlock: 

BO3Group: 

IsSpawnPoint: false

DoReplaceBlocks: true


#######################################################################
# +-----------------------------------------------------------------+ #
# |                              Blocks                             | #
# +-----------------------------------------------------------------+ #
#######################################################################

Block(-8,0,-5,quark:slate:1)
Block(-8,0,-4,quark:slate:1)
Block(-8,0,-3,quark:slate:1)
Block(-8,0,-2,quark:slate:1)
Block(-8,0,7,quark:slate:1)
Block(-8,0,8,quark:slate:1)
Block(-8,1,-5,quark:slate:1)
Block(-8,1,-4,quark:slate:1)
Block(-8,1,-3,quark:slate:1)
Block(-8,1,-2,quark:slate:1)
Block(-8,1,7,quark:slate:1)
Block(-8,1,8,quark:slate:1)
Block(-8,2,-7,quark:slate:1)
Block(-8,2,-6,quark:slate:1)
Block(-8,2,-5,quark:slate:1)
Block(-8,2,-4,quark:slate:1)
Block(-8,2,-3,quark:slate:1)
Block(-8,2,-2,quark:slate:1)
Block(-8,2,-1,quark:slate:1)
Block(-8,2,0,quark:slate:1)
Block(-8,2,1,quark:slate:1)
Block(-8,2,2,quark:slate:1)
Block(-8,2,3,quark:slate:1)
Block(-8,2,4,quark:slate:1)
Block(-8,2,5,quark:slate:1)
Block(-8,2,6,quark:slate:1)
Block(-8,2,7,quark:slate:1)
Block(-8,2,8,quark:slate:1)
Block(-8,3,-7,quark:slate:1)
Block(-8,3,-6,quark:slate:1)
Block(-8,3,-5,quark:slate:1)
Block(-8,3,-4,quark:slate:1)
Block(-8,3,-3,quark:slate:1)
Block(-8,3,-2,quark:slate:1)
Block(-8,3,-1,quark:slate:1)
Block(-8,3,0,quark:slate:1)
Block(-8,3,1,quark:slate:1)
Block(-8,3,2,quark:slate:1)
Block(-8,3,3,quark:slate:1)
Block(-8,3,4,quark:slate:1)
Block(-8,3,5,quark:slate:1)
Block(-8,3,6,quark:slate:1)
Block(-8,3,7,quark:slate:1)
Block(-8,3,8,quark:slate:1)
Block(-8,4,-7,quark:slate:1)
Block(-8,4,-6,quark:slate:1)
Block(-8,4,-5,quark:slate:1)
Block(-8,4,-4,quark:slate:1)
Block(-8,4,-3,quark:slate:1)
Block(-8,4,-2,quark:slate:1)
Block(-8,4,-1,quark:slate:1)
Block(-8,4,0,quark:slate:1)
Block(-8,4,1,quark:slate:1)
Block(-8,4,2,quark:slate:1)
Block(-8,4,3,quark:slate:1)
Block(-8,4,4,quark:slate:1)
Block(-8,4,5,quark:slate:1)
Block(-8,4,6,quark:slate:1)
Block(-8,4,7,quark:slate:1)
Block(-8,4,8,quark:slate:1)
Block(-8,5,-7,quark:slate:1)
Block(-8,5,-6,quark:slate:1)
Block(-8,5,-5,quark:slate:1)
Block(-8,5,-4,quark:slate:1)
Block(-8,5,-3,quark:slate:1)
Block(-8,5,-2,quark:slate:1)
Block(-8,5,-1,quark:slate:1)
Block(-8,5,0,quark:slate:1)
Block(-8,5,1,quark:slate:1)
Block(-8,5,2,quark:slate:1)
Block(-8,5,3,quark:slate:1)
Block(-8,5,4,quark:slate:1)
Block(-8,5,5,quark:slate:1)
Block(-8,5,6,quark:slate:1)
Block(-8,5,7,quark:slate:1)
Block(-8,5,8,quark:slate:1)
Block(-8,6,-7,quark:slate:1)
Block(-8,6,-6,quark:slate:1)
Block(-8,6,-5,quark:slate:1)
Block(-8,6,-4,quark:slate:1)
Block(-8,6,-3,quark:slate:1)
Block(-8,6,-2,quark:slate:1)
Block(-8,6,-1,quark:slate:1)
Block(-8,6,0,quark:slate:1)
Block(-8,6,1,quark:slate:1)
Block(-8,6,2,quark:slate:1)
Block(-8,6,3,quark:slate:1)
Block(-8,6,4,quark:slate:1)
Block(-8,6,5,quark:slate:1)
Block(-8,6,6,quark:slate:1)
Block(-8,6,7,quark:slate:1)
Block(-8,6,8,quark:slate:1)
Block(-8,7,-7,quark:slate:1)
Block(-8,7,-6,quark:slate:1)
Block(-8,7,-5,quark:slate:1)
Block(-8,7,-4,quark:slate:1)
Block(-8,7,-3,quark:slate:1)
Block(-8,7,-2,quark:slate:1)
Block(-8,7,-1,quark:slate:1)
Block(-8,7,0,quark:slate:1)
Block(-8,7,1,quark:slate:1)
Block(-8,7,2,quark:slate:1)
Block(-8,7,3,quark:slate:1)
Block(-8,7,4,quark:slate:1)
Block(-8,7,5,quark:slate:1)
Block(-8,7,6,quark:slate:1)
Block(-8,7,7,quark:slate:1)
Block(-8,7,8,quark:slate:1)
Block(-8,8,-7,quark:slate:1)
Block(-8,8,-6,quark:slate:1)
Block(-8,8,-5,quark:slate:1)
Block(-8,8,-4,quark:slate:1)
Block(-8,8,-3,quark:slate:1)
Block(-8,8,-2,quark:slate:1)
Block(-8,8,-1,quark:slate:1)
Block(-8,8,0,quark:slate:1)
Block(-8,8,1,quark:slate:1)
Block(-8,8,2,quark:slate:1)
Block(-8,8,3,quark:slate:1)
Block(-8,8,4,quark:slate:1)
Block(-8,8,5,quark:slate:1)
Block(-8,8,6,quark:slate:1)
Block(-8,8,7,quark:slate:1)
Block(-8,8,8,quark:slate:1)
Block(-8,9,-7,quark:slate:1)
Block(-8,9,-6,quark:slate:1)
Block(-8,9,-5,quark:slate:1)
Block(-8,9,-4,quark:slate:1)
Block(-8,9,-3,quark:slate:1)
Block(-8,9,-2,quark:slate:1)
Block(-8,9,-1,quark:slate:1)
Block(-8,9,0,quark:slate:1)
Block(-8,9,1,quark:slate:1)
Block(-8,9,2,quark:slate:1)
Block(-8,9,3,quark:slate:1)
Block(-8,9,4,quark:slate:1)
Block(-8,9,5,quark:slate:1)
Block(-8,9,6,quark:slate:1)
Block(-8,9,7,quark:slate:1)
Block(-8,9,8,quark:slate:1)
Block(-8,10,-7,quark:slate:1)
Block(-8,10,-6,quark:slate:1)
Block(-8,10,-5,quark:slate:1)
Block(-8,10,-4,quark:slate:1)
Block(-8,10,-3,quark:slate:1)
Block(-8,10,-2,quark:slate:1)
Block(-8,10,-1,quark:slate:1)
Block(-8,10,0,quark:slate:1)
Block(-8,10,1,quark:slate:1)
Block(-8,10,2,quark:slate:1)
Block(-8,10,3,quark:slate:1)
Block(-8,10,4,quark:slate:1)
Block(-8,10,5,quark:slate:1)
Block(-8,10,6,quark:slate:1)
Block(-8,10,7,quark:slate:1)
Block(-8,10,8,quark:slate:1)
Block(-8,11,-7,biomesoplenty:wood_slab_1:14)
Block(-8,11,-6,biomesoplenty:wood_slab_1:14)
Block(-8,11,-5,biomesoplenty:wood_slab_1:14)
Block(-8,11,-4,biomesoplenty:wood_slab_1:14)
Block(-8,11,-3,biomesoplenty:wood_slab_1:14)
Block(-8,11,-2,biomesoplenty:wood_slab_1:14)
Block(-8,11,-1,biomesoplenty:wood_slab_1:14)
Block(-8,11,0,biomesoplenty:wood_slab_1:14)
Block(-8,11,1,biomesoplenty:wood_slab_1:14)
Block(-8,11,2,biomesoplenty:wood_slab_1:14)
Block(-8,11,3,biomesoplenty:wood_slab_1:14)
Block(-8,11,4,biomesoplenty:wood_slab_1:14)
Block(-8,11,5,biomesoplenty:wood_slab_1:14)
Block(-8,11,6,biomesoplenty:wood_slab_1:14)
Block(-8,11,7,biomesoplenty:wood_slab_1:14)
Block(-8,11,8,biomesoplenty:wood_slab_1:14)
Block(-8,12,-3,AIR:0)
Block(-8,12,-2,AIR:0)
Block(-8,12,-1,AIR:0)
Block(-8,12,0,inspirations:path)
Block(-8,12,1,AIR:0)
Block(-8,12,2,CARPET:15)
Block(-8,12,3,CARPET:15)
Block(-8,12,4,AIR:0)
Block(-8,12,5,inspirations:path)
Block(-8,12,6,inspirations:path)
Block(-8,12,7,AIR:0)
Block(-8,12,8,AIR:0)
Block(-8,13,-7,AIR:0)
Block(-8,13,-6,AIR:0)
Block(-8,13,-5,AIR:0)
Block(-8,13,-4,AIR:0)
Block(-8,13,-3,AIR:0)
Block(-8,13,-2,AIR:0)
Block(-8,13,-1,AIR:0)
Block(-8,13,0,AIR:0)
Block(-8,13,1,AIR:0)
Block(-8,13,2,AIR:0)
Block(-8,13,3,AIR:0)
Block(-8,13,4,AIR:0)
Block(-8,13,5,AIR:0)
Block(-8,13,6,AIR:0)
Block(-8,13,7,AIR:0)
Block(-8,13,8,AIR:0)
Block(-8,14,-7,AIR:0)
Block(-8,14,-6,AIR:0)
Block(-8,14,-5,AIR:0)
Block(-8,14,-4,AIR:0)
Block(-8,14,-3,AIR:0)
Block(-8,14,-2,AIR:0)
Block(-8,14,-1,AIR:0)
Block(-8,14,0,AIR:0)
Block(-8,14,1,AIR:0)
Block(-8,14,2,AIR:0)
Block(-8,14,3,AIR:0)
Block(-8,14,4,AIR:0)
Block(-8,14,5,AIR:0)
Block(-8,14,6,AIR:0)
Block(-8,14,7,AIR:0)
Block(-8,14,8,AIR:0)
Block(-8,15,-7,AIR:0)
Block(-8,15,-5,AIR:0)
Block(-8,15,-3,AIR:0)
Block(-8,15,-2,AIR:0)
Block(-8,15,-1,AIR:0)
Block(-8,15,0,AIR:0)
Block(-8,15,1,AIR:0)
Block(-8,15,2,AIR:0)
Block(-8,15,3,AIR:0)
Block(-8,15,4,AIR:0)
Block(-8,15,5,AIR:0)
Block(-8,15,6,AIR:0)
Block(-8,15,8,AIR:0)
Block(-8,16,-7,biomesoplenty:wood_slab_1:14)
Block(-8,16,-6,biomesoplenty:wood_slab_1:14)
Block(-8,16,-5,biomesoplenty:wood_slab_1:14)
Block(-8,16,-4,biomesoplenty:wood_slab_1:14)
Block(-8,16,-3,biomesoplenty:wood_slab_1:14)
Block(-8,16,-2,biomesoplenty:wood_slab_1:14)
Block(-8,16,-1,biomesoplenty:wood_slab_1:14)
Block(-8,16,0,quark:grate)
Block(-8,16,1,quark:grate)
Block(-8,16,2,quark:grate)
Block(-8,16,3,biomesoplenty:wood_slab_1:14)
Block(-8,16,4,biomesoplenty:wood_slab_1:14)
Block(-8,16,5,biomesoplenty:wood_slab_1:14)
Block(-8,16,6,biomesoplenty:wood_slab_1:14)
Block(-8,16,7,biomesoplenty:wood_slab_1:14)
Block(-8,16,8,biomesoplenty:wood_slab_1:14)
Block(-8,17,-7,quark:iron_plate:1)
Block(-8,17,-6,quark:iron_plate:1)
Block(-8,17,-5,quark:iron_plate:1)
Block(-8,17,-4,quark:iron_plate:1)
Block(-8,17,-3,quark:iron_plate:1)
Block(-8,17,-2,quark:iron_plate:1)
Block(-8,17,-1,quark:basalt:1)
Block(-8,17,0,quark:basalt:1)
Block(-8,17,1,quark:basalt:1)
Block(-8,17,2,quark:basalt:1)
Block(-8,17,3,quark:basalt:1)
Block(-8,17,4,quark:iron_plate:1)
Block(-8,17,5,quark:iron_plate:1)
Block(-8,17,6,quark:iron_plate:1)
Block(-8,17,7,quark:iron_plate:1)
Block(-8,17,8,quark:iron_plate:1)
Block(-8,18,-7,AIR:0)
Block(-8,18,-6,STEP:0)
Block(-8,18,-5,AIR:0)
Block(-8,18,-4,AIR:0)
Block(-8,18,-3,AIR:0)
Block(-8,18,-2,quark:slate:1)
Block(-8,18,-1,CARPET:15)
Block(-8,18,0,CARPET:15)
Block(-8,18,1,CARPET:15)
Block(-8,18,2,CARPET:15)
Block(-8,18,3,CARPET:15)
Block(-8,18,4,CARPET:15)
Block(-8,18,5,CARPET:15)
Block(-8,18,6,CARPET:15)
Block(-8,19,-7,AIR:0)
Block(-8,19,-6,AIR:0)
Block(-8,19,-5,AIR:0)
Block(-8,19,-4,AIR:0)
Block(-8,19,-2,quark:slate:1)
Block(-8,19,-1,AIR:0)
Block(-8,19,0,AIR:0)
Block(-8,19,1,AIR:0)
Block(-8,19,2,AIR:0)
Block(-8,19,3,AIR:0)
Block(-8,19,4,AIR:0)
Block(-8,19,5,AIR:0)
Block(-8,19,6,AIR:0)
Block(-8,19,8,AIR:0)
Block(-8,20,-7,AIR:0)
Block(-8,20,-6,AIR:0)
Block(-8,20,-5,AIR:0)
Block(-8,20,-4,quark:iron_plate_slab:8)
Block(-8,20,-3,quark:iron_plate_slab:8)
Block(-8,20,-2,quark:slate:1)
Block(-8,20,-1,AIR:0)
Block(-8,20,0,AIR:0)
Block(-8,20,1,AIR:0)
Block(-8,20,2,AIR:0)
Block(-8,20,3,AIR:0)
Block(-8,20,4,AIR:0)
Block(-8,20,5,AIR:0)
Block(-8,20,6,AIR:0)
Block(-8,20,7,AIR:0)
Block(-8,20,8,AIR:0)
Block(-8,21,-7,AIR:0)
Block(-8,21,-6,AIR:0)
Block(-8,21,-5,AIR:0)
Block(-8,21,-4,rustic:iron_lattice:0)
Block(-8,21,-3,AIR:0)
Block(-8,21,-2,OBSERVER:4)
Block(-8,21,-1,AIR:0)
Block(-8,21,0,AIR:0)
Block(-8,21,1,AIR:0)
Block(-8,21,2,AIR:0)
Block(-8,21,3,AIR:0)
Block(-8,21,4,AIR:0)
Block(-8,21,5,AIR:0)
Block(-8,21,6,AIR:0)
Block(-8,21,7,OBSERVER:5)
Block(-8,21,8,AIR:0)
Block(-8,22,-7,AIR:0)
Block(-8,22,-6,AIR:0)
Block(-8,22,-5,AIR:0)
Block(-8,22,-4,rustic:iron_lattice:0)
Block(-8,22,-3,AIR:0)
Block(-8,22,-2,OBSERVER:0)
Block(-8,22,-1,AIR:0)
Block(-8,22,0,AIR:0)
Block(-8,22,1,AIR:0)
Block(-8,22,2,AIR:0)
Block(-8,22,3,AIR:0)
Block(-8,22,4,AIR:0)
Block(-8,22,5,AIR:0)
Block(-8,22,6,AIR:0)
Block(-8,22,7,OBSERVER:0)
Block(-8,22,8,AIR:0)
Block(-8,23,-7,quark:iron_plate)
Block(-8,23,-6,quark:iron_plate)
Block(-8,23,-5,quark:iron_plate)
Block(-8,23,-4,quark:iron_plate)
Block(-8,23,-3,quark:iron_plate)
Block(-8,23,-2,PISTON_STICKY_BASE:1)
Block(-8,23,-1,quark:iron_plate)
Block(-8,23,0,quark:iron_plate)
Block(-8,23,1,quark:iron_plate)
Block(-8,23,2,quark:iron_plate)
Block(-8,23,3,quark:iron_plate)
Block(-8,23,4,quark:iron_plate)
Block(-8,23,5,quark:iron_plate)
Block(-8,23,6,quark:iron_plate)
Block(-8,23,7,PISTON_STICKY_BASE:1)
Block(-8,23,8,quark:iron_plate)
Block(-8,24,-7,quark:iron_plate)
Block(-8,24,-6,PRISMARINE:2)
Block(-8,24,-5,PRISMARINE:2)
Block(-8,24,-4,PRISMARINE:2)
Block(-8,24,-3,PRISMARINE:2)
Block(-8,24,-2,AIR:0)
Block(-8,24,-1,CONCRETE:7)
RandomBlock(-8,24,0,CHEST:4,../../../../Chests/Loot/moderncity_junk_loot.nbt,20,CHEST:4../../../../Chests/Loot/moderncity_rare_loot.nbt,10,CHEST:4,../../../../Chests/RLCraft/Ruins/industrial.nbt,20,CHEST:4,../../../../Chests/RLCraft/Ruins/consumables.nbt,20,CHEST:4,../../../../Chests/Loot/stronghold_corridor.nbt,20,CHEST:4,../../../../Chests/Loot/stronghold_crossing.nbt,20,CHEST:4,../../../../Chests/Loot/desert_pyramid.nbt,30,CHEST:4,../../../../Chests/Loot/simple_dungeon.nbt,100)
Block(-8,24,1,CONCRETE:7)
Block(-8,24,2,CONCRETE:7)
Block(-8,24,3,CONCRETE:7)
Block(-8,24,4,CONCRETE:7)
Block(-8,24,5,contenttweaker:bone_pile)
Block(-8,24,6,CONCRETE:7)
Block(-8,24,7,AIR:0)
Block(-8,24,8,PRISMARINE:2)
Block(-8,25,-3,STAINED_GLASS:8)
Block(-8,25,-2,quark:iron_plate)
Block(-8,25,-1,STAINED_GLASS:8)
Block(-8,25,0,AIR:0)
Block(-8,25,1,CONCRETE:7)
Block(-8,25,2,CONCRETE:7)
Block(-8,25,3,CONCRETE:7)
Block(-8,25,4,CONCRETE:7)
Block(-8,25,5,AIR:0)
Block(-8,25,6,AIR:0)
Block(-8,25,7,quark:iron_plate)
Block(-8,25,8,STAINED_GLASS:8)
Block(-8,26,-3,quark:iron_plate)
Block(-8,26,-2,quark:slate:1)
Block(-8,26,-1,quark:slate:1)
Block(-8,26,0,quark:slate:1)
Block(-8,26,1,quark:slate:1)
Block(-8,26,2,quark:slate:1)
Block(-8,26,3,quark:slate:1)
Block(-8,26,4,quark:slate:1)
Block(-8,26,5,quark:slate:1)
Block(-8,26,6,quark:slate:1)
Block(-8,26,7,quark:slate:1)
Block(-8,26,8,quark:iron_plate)
Block(-7,0,-5,quark:slate:1)
Block(-7,0,-4,quark:slate:1)
Block(-7,0,-3,quark:slate:1)
Block(-7,0,-2,quark:slate:1)
Block(-7,0,7,quark:slate:1)
Block(-7,0,8,quark:slate:1)
Block(-7,1,-5,quark:slate:1)
Block(-7,1,-4,quark:slate:1)
Block(-7,1,-3,quark:slate:1)
Block(-7,1,-2,quark:slate:1)
Block(-7,1,7,quark:slate:1)
Block(-7,1,8,quark:slate:1)
Block(-7,2,-7,quark:slate:1)
Block(-7,2,-6,quark:slate:1)
Block(-7,2,-5,quark:slate:1)
Block(-7,2,-4,quark:slate:1)
Block(-7,2,-3,quark:slate:1)
Block(-7,2,-2,quark:slate:1)
Block(-7,2,-1,quark:slate:1)
Block(-7,2,0,quark:slate:1)
Block(-7,2,1,quark:slate:1)
Block(-7,2,2,quark:slate:1)
Block(-7,2,3,quark:slate:1)
Block(-7,2,4,quark:slate:1)
Block(-7,2,5,quark:slate:1)
Block(-7,2,6,quark:slate:1)
Block(-7,2,7,quark:slate:1)
Block(-7,2,8,quark:slate:1)
Block(-7,3,-7,quark:slate:1)
Block(-7,3,-6,quark:slate:1)
Block(-7,3,-5,quark:slate:1)
Block(-7,3,-4,quark:slate:1)
Block(-7,3,-3,quark:slate:1)
Block(-7,3,-2,quark:slate:1)
Block(-7,3,-1,quark:slate:1)
Block(-7,3,0,quark:slate:1)
Block(-7,3,1,quark:slate:1)
Block(-7,3,2,quark:slate:1)
Block(-7,3,3,quark:slate:1)
Block(-7,3,4,quark:slate:1)
Block(-7,3,5,quark:slate:1)
Block(-7,3,6,quark:slate:1)
Block(-7,3,7,quark:slate:1)
Block(-7,3,8,quark:slate:1)
Block(-7,4,-7,quark:slate:1)
Block(-7,4,-6,quark:slate:1)
Block(-7,4,-5,quark:slate:1)
Block(-7,4,-4,quark:slate:1)
Block(-7,4,-3,quark:slate:1)
Block(-7,4,-2,quark:slate:1)
Block(-7,4,-1,quark:slate:1)
Block(-7,4,0,quark:slate:1)
Block(-7,4,1,quark:slate:1)
Block(-7,4,2,quark:slate:1)
Block(-7,4,3,quark:slate:1)
Block(-7,4,4,quark:slate:1)
Block(-7,4,5,quark:slate:1)
Block(-7,4,6,quark:slate:1)
Block(-7,4,7,quark:slate:1)
Block(-7,4,8,quark:slate:1)
Block(-7,5,-7,quark:slate:1)
Block(-7,5,-6,quark:slate:1)
Block(-7,5,-5,quark:slate:1)
Block(-7,5,-4,quark:slate:1)
Block(-7,5,-3,quark:slate:1)
Block(-7,5,-2,quark:slate:1)
Block(-7,5,-1,quark:slate:1)
Block(-7,5,0,quark:slate:1)
Block(-7,5,1,quark:slate:1)
Block(-7,5,2,quark:slate:1)
Block(-7,5,3,quark:slate:1)
Block(-7,5,4,quark:slate:1)
Block(-7,5,5,quark:slate:1)
Block(-7,5,6,quark:slate:1)
Block(-7,5,7,quark:slate:1)
Block(-7,5,8,quark:slate:1)
Block(-7,6,-7,quark:slate:1)
Block(-7,6,-6,quark:slate:1)
Block(-7,6,-5,quark:slate:1)
Block(-7,6,-4,quark:slate:1)
Block(-7,6,-3,quark:slate:1)
Block(-7,6,-2,quark:slate:1)
Block(-7,6,-1,quark:slate:1)
Block(-7,6,0,quark:slate:1)
Block(-7,6,1,quark:slate:1)
Block(-7,6,2,quark:slate:1)
Block(-7,6,3,quark:slate:1)
Block(-7,6,4,quark:slate:1)
Block(-7,6,5,quark:slate:1)
Block(-7,6,6,quark:slate:1)
Block(-7,6,7,quark:slate:1)
Block(-7,6,8,quark:slate:1)
Block(-7,7,-7,quark:slate:1)
Block(-7,7,-6,quark:slate:1)
Block(-7,7,-5,quark:slate:1)
Block(-7,7,-4,quark:slate:1)
Block(-7,7,-3,quark:slate:1)
Block(-7,7,-2,quark:slate:1)
Block(-7,7,-1,quark:slate:1)
Block(-7,7,0,quark:slate:1)
Block(-7,7,1,quark:slate:1)
Block(-7,7,2,quark:slate:1)
Block(-7,7,3,quark:slate:1)
Block(-7,7,4,quark:slate:1)
Block(-7,7,5,quark:slate:1)
Block(-7,7,6,quark:slate:1)
Block(-7,7,7,quark:slate:1)
Block(-7,7,8,quark:slate:1)
Block(-7,8,-7,quark:slate:1)
Block(-7,8,-6,quark:slate:1)
Block(-7,8,-5,quark:slate:1)
Block(-7,8,-4,quark:slate:1)
Block(-7,8,-3,quark:slate:1)
Block(-7,8,-2,quark:slate:1)
Block(-7,8,-1,quark:slate:1)
Block(-7,8,0,quark:slate:1)
Block(-7,8,1,quark:slate:1)
Block(-7,8,2,quark:slate:1)
Block(-7,8,3,quark:slate:1)
Block(-7,8,4,quark:slate:1)
Block(-7,8,5,quark:slate:1)
Block(-7,8,6,quark:slate:1)
Block(-7,8,7,quark:slate:1)
Block(-7,8,8,quark:slate:1)
Block(-7,9,-7,quark:slate:1)
Block(-7,9,-6,quark:slate:1)
Block(-7,9,-5,quark:slate:1)
Block(-7,9,-4,quark:slate:1)
Block(-7,9,-3,quark:slate:1)
Block(-7,9,-2,quark:slate:1)
Block(-7,9,-1,quark:slate:1)
Block(-7,9,0,quark:slate:1)
Block(-7,9,1,quark:slate:1)
Block(-7,9,2,quark:slate:1)
Block(-7,9,3,quark:slate:1)
Block(-7,9,4,quark:slate:1)
Block(-7,9,5,quark:slate:1)
Block(-7,9,6,quark:slate:1)
Block(-7,9,7,quark:slate:1)
Block(-7,9,8,quark:slate:1)
Block(-7,10,-7,quark:slate:1)
Block(-7,10,-6,quark:slate:1)
Block(-7,10,-5,quark:slate:1)
Block(-7,10,-4,quark:slate:1)
Block(-7,10,-3,quark:slate:1)
Block(-7,10,-2,quark:slate:1)
Block(-7,10,-1,quark:slate:1)
Block(-7,10,0,quark:slate:1)
Block(-7,10,1,quark:slate:1)
Block(-7,10,2,quark:slate:1)
Block(-7,10,3,quark:slate:1)
Block(-7,10,4,quark:slate:1)
Block(-7,10,5,quark:slate:1)
Block(-7,10,6,quark:slate:1)
Block(-7,10,7,quark:slate:1)
Block(-7,10,8,quark:slate:1)
Block(-7,11,-7,biomesoplenty:wood_slab_1:14)
Block(-7,11,-6,biomesoplenty:wood_slab_1:14)
Block(-7,11,-5,biomesoplenty:wood_slab_1:14)
Block(-7,11,-4,biomesoplenty:wood_slab_1:14)
Block(-7,11,-3,biomesoplenty:wood_slab_1:14)
Block(-7,11,-2,biomesoplenty:wood_slab_1:14)
Block(-7,11,-1,biomesoplenty:wood_slab_1:14)
Block(-7,11,0,biomesoplenty:wood_slab_1:14)
Block(-7,11,1,biomesoplenty:wood_slab_1:14)
Block(-7,11,2,biomesoplenty:wood_slab_1:14)
Block(-7,11,3,biomesoplenty:wood_slab_1:14)
Block(-7,11,4,biomesoplenty:wood_slab_1:14)
Block(-7,11,5,biomesoplenty:wood_slab_1:14)
Block(-7,11,6,biomesoplenty:wood_slab_1:14)
Block(-7,11,7,biomesoplenty:wood_slab_1:14)
Block(-7,11,8,biomesoplenty:wood_slab_1:14)
Block(-7,12,-7,CARPET:15)
Block(-7,12,-6,CARPET:15)
Block(-7,12,-5,CARPET:15)
Block(-7,12,-4,CARPET:15)
Block(-7,12,-3,CARPET:15)
Block(-7,12,-2,CARPET:15)
Block(-7,12,-1,CARPET:15)
Block(-7,12,0,CARPET:15)
Block(-7,12,1,CARPET:15)
Block(-7,12,2,CARPET:15)
Block(-7,12,3,CARPET:15)
Block(-7,12,4,CARPET:15)
Block(-7,12,5,CARPET:15)
Block(-7,12,6,CARPET:15)
Block(-7,12,7,CARPET:15)
Block(-7,12,8,CARPET:15)
Block(-7,13,-7,AIR:0)
Block(-7,13,-6,AIR:0)
Block(-7,13,-5,AIR:0)
Block(-7,13,-4,AIR:0)
Block(-7,13,-3,AIR:0)
Block(-7,13,-2,AIR:0)
Block(-7,13,-1,AIR:0)
Block(-7,13,0,AIR:0)
Block(-7,13,1,AIR:0)
Block(-7,13,2,AIR:0)
Block(-7,13,3,AIR:0)
Block(-7,13,4,AIR:0)
Block(-7,13,5,AIR:0)
Block(-7,13,6,AIR:0)
Block(-7,13,7,AIR:0)
Block(-7,13,8,AIR:0)
Block(-7,14,-7,AIR:0)
Block(-7,14,-6,AIR:0)
Block(-7,14,-5,AIR:0)
Block(-7,14,-4,AIR:0)
Block(-7,14,-3,AIR:0)
Block(-7,14,-2,AIR:0)
Block(-7,14,-1,AIR:0)
Block(-7,14,0,AIR:0)
Block(-7,14,1,AIR:0)
Block(-7,14,2,AIR:0)
Block(-7,14,3,AIR:0)
Block(-7,14,4,AIR:0)
Block(-7,14,5,AIR:0)
Block(-7,14,6,AIR:0)
Block(-7,14,7,AIR:0)
Block(-7,14,8,AIR:0)
Block(-7,15,-7,AIR:0)
Block(-7,15,-6,AIR:0)
Block(-7,15,-5,AIR:0)
Block(-7,15,-4,AIR:0)
Block(-7,15,-3,AIR:0)
Block(-7,15,-2,AIR:0)
Block(-7,15,-1,AIR:0)
Block(-7,15,0,AIR:0)
Block(-7,15,1,AIR:0)
Block(-7,15,2,AIR:0)
Block(-7,15,3,AIR:0)
Block(-7,15,4,AIR:0)
Block(-7,15,5,AIR:0)
Block(-7,15,6,AIR:0)
Block(-7,15,7,AIR:0)
Block(-7,15,8,AIR:0)
Block(-7,16,-7,quark:grate)
Block(-7,16,-6,quark:grate)
Block(-7,16,-5,quark:grate)
Block(-7,16,-4,quark:grate)
Block(-7,16,-3,quark:grate)
Block(-7,16,-2,quark:grate)
Block(-7,16,-1,biomesoplenty:wood_slab_1:14)
Block(-7,16,0,quark:grate)
Block(-7,16,1,quark:paper_lantern)
Block(-7,16,2,quark:grate)
Block(-7,16,3,biomesoplenty:wood_slab_1:14)
Block(-7,16,4,biomesoplenty:wood_slab_1:14)
Block(-7,16,5,quark:grate)
Block(-7,16,6,quark:grate)
Block(-7,16,7,quark:grate)
Block(-7,16,8,quark:grate)
Block(-7,17,-7,quark:basalt:1)
Block(-7,17,-6,quark:basalt:1)
Block(-7,17,-5,quark:basalt:1)
Block(-7,17,-4,quark:basalt:1)
Block(-7,17,-3,quark:basalt:1)
Block(-7,17,-2,quark:basalt:1)
Block(-7,17,-1,quark:basalt:1)
Block(-7,17,0,quark:basalt:1)
Block(-7,17,1,quark:basalt:1)
Block(-7,17,2,quark:basalt:1)
Block(-7,17,3,quark:basalt:1)
Block(-7,17,4,quark:basalt:1)
Block(-7,17,5,quark:basalt:1)
Block(-7,17,6,quark:basalt:1)
Block(-7,17,7,quark:basalt:1)
Block(-7,17,8,quark:basalt:1)
Block(-7,18,-7,AIR:0)
Block(-7,18,-6,STEP:0)
Block(-7,18,-5,AIR:0)
Block(-7,18,-4,AIR:0)
Block(-7,18,-3,AIR:0)
Block(-7,18,-2,quark:slate:1)
Block(-7,18,-1,quark:slate:1)
Block(-7,18,0,quark:slate:1)
Block(-7,18,1,quark:slate:1)
Block(-7,18,2,quark:slate:1)
Block(-7,18,3,quark:slate:1)
Block(-7,18,4,AIR:0)
Block(-7,18,5,AIR:0)
Block(-7,18,6,quark:slate:1)
Block(-7,18,7,quark:slate:1)
Block(-7,18,8,quark:slate:1)
Block(-7,19,-7,AIR:0)
Block(-7,19,-6,AIR:0)
Block(-7,19,-5,AIR:0)
Block(-7,19,-4,AIR:0)
Block(-7,19,-3,AIR:0)
Block(-7,19,-2,quark:slate:1)
Block(-7,19,-1,quark:slate:1)
Block(-7,19,0,quark:slate:1)
Block(-7,19,1,quark:slate:1)
Block(-7,19,2,quark:slate:1)
Block(-7,19,3,quark:slate:1)
Block(-7,19,4,AIR:0)
Block(-7,19,5,AIR:0)
Block(-7,19,6,quark:slate:1)
Block(-7,19,7,quark:slate:1)
Block(-7,19,8,quark:slate:1)
Block(-7,20,-7,AIR:0)
Block(-7,20,-6,AIR:0)
Block(-7,20,-5,AIR:0)
Block(-7,20,-4,quark:grate)
Block(-7,20,-3,quark:grate)
Block(-7,20,-2,quark:slate:1)
Block(-7,20,-1,quark:slate:1)
Block(-7,20,0,quark:slate:1)
Block(-7,20,1,quark:slate:1)
Block(-7,20,2,quark:slate:1)
Block(-7,20,3,quark:slate:1)
Block(-7,20,4,quark:slate:1)
Block(-7,20,5,quark:slate:1)
Block(-7,20,6,quark:slate:1)
Block(-7,20,7,quark:slate:1)
Block(-7,20,8,quark:slate:1)
Block(-7,21,-7,AIR:0)
Block(-7,21,-6,AIR:0)
Block(-7,21,-5,AIR:0)
Block(-7,21,-4,IRON_FENCE:0)
Block(-7,21,-3,AIR:0)
Block(-7,21,-2,quark:slate:1)
Block(-7,21,-1,quark:slate:1)
Block(-7,21,0,quark:slate:1)
Block(-7,21,1,quark:slate:1)
Block(-7,21,2,quark:slate:1)
Block(-7,21,3,OBSERVER:1)
Block(-7,21,4,OBSERVER:2)
Block(-7,21,5,OBSERVER:2)
Block(-7,21,6,OBSERVER:2)
Block(-7,21,7,OBSERVER:2)
Block(-7,21,8,quark:slate:1)
Block(-7,22,-7,AIR:0)
Block(-7,22,-6,AIR:0)
Block(-7,22,-5,AIR:0)
Block(-7,22,-4,AIR:0)
Block(-7,22,-3,AIR:0)
Block(-7,22,-2,quark:slate:1)
Block(-7,22,-1,quark:slate:1)
Block(-7,22,0,quark:slate:1)
Block(-7,22,1,quark:slate:1)
Block(-7,22,2,quark:slate:1)
Block(-7,22,3,OBSERVER:1)
Block(-7,22,4,quark:slate:1)
Block(-7,22,5,quark:slate:1)
Block(-7,22,6,quark:slate:1)
Block(-7,22,7,quark:slate:1)
Block(-7,22,8,quark:slate:1)
Block(-7,23,-7,quark:iron_plate)
Block(-7,23,-6,quark:prismarine_dark_slab:8)
Block(-7,23,-5,quark:prismarine_dark_slab:8)
Block(-7,23,-4,quark:prismarine_dark_slab:8)
Block(-7,23,-3,quark:prismarine_dark_slab:8)
Block(-7,23,-2,quark:prismarine_dark_slab_double)
Block(-7,23,-1,quark:iron_plate)
Block(-7,23,0,quark:prismarine_dark_slab_double)
Block(-7,23,1,quark:prismarine_dark_slab_double)
Block(-7,23,2,quark:prismarine_dark_slab_double)
Block(-7,23,3,OBSERVER:1)
Block(-7,23,4,quark:prismarine_dark_slab_double)
Block(-7,23,5,quark:prismarine_dark_slab_double)
Block(-7,23,6,quark:iron_plate)
Block(-7,23,7,quark:prismarine_dark_slab_double)
Block(-7,23,8,quark:prismarine_dark_slab_double)
Block(-7,24,-7,quark:iron_plate)
Block(-7,24,-6,PRISMARINE:2)
Block(-7,24,-5,PRISMARINE:2)
Block(-7,24,-4,PRISMARINE:2)
Block(-7,24,-3,quark:prismarine_dark_slab_double)
Block(-7,24,-2,quark:prismarine_dark_slab_double)
Block(-7,24,-1,quark:iron_plate)
Block(-7,24,0,CONCRETE:7)
Block(-7,24,1,CONCRETE:7)
Block(-7,24,2,CONCRETE:7)
Block(-7,24,3,OBSERVER:1)
Block(-7,24,4,PRISMARINE:2)
Block(-7,24,5,CONCRETE:7)
Block(-7,24,6,quark:iron_plate)
Block(-7,24,7,PRISMARINE:2)
Block(-7,24,8,PRISMARINE:2)
Block(-7,25,-6,PRISMARINE:2)
Block(-7,25,-5,PRISMARINE:2)
Block(-7,25,-4,PRISMARINE:2)
Block(-7,25,-3,PRISMARINE:2)
Block(-7,25,-2,PRISMARINE:2)
Block(-7,25,-1,CONCRETE:7)
Block(-7,25,0,CONCRETE:7)
Block(-7,25,1,CONCRETE:7)
Block(-7,25,2,CONCRETE:7)
Block(-7,25,3,REDSTONE_WIRE:0)
Block(-7,25,4,REDSTONE_WIRE:0)
Block(-7,25,5,CONCRETE:7)
Block(-7,25,6,CONCRETE:7)
Block(-7,25,7,PRISMARINE:2)
Block(-7,25,8,PRISMARINE:2)
Block(-7,26,-5,PRISMARINE:2)
Block(-7,26,-4,PRISMARINE:2)
Block(-7,26,-3,quark:iron_plate)
Block(-7,26,-2,quark:slate:1)
Block(-7,26,-1,quark:slate:1)
Block(-7,26,0,quark:slate:1)
Block(-7,26,1,quark:slate:1)
Block(-7,26,2,quark:slate:1)
Block(-7,26,3,quark:slate:1)
Block(-7,26,4,quark:slate:1)
Block(-7,26,5,quark:slate:1)
Block(-7,26,6,quark:slate:1)
Block(-7,26,7,quark:slate:1)
Block(-7,26,8,quark:iron_plate)
Block(-7,27,-4,PRISMARINE:2)
Block(-7,27,-3,PRISMARINE:2)
Block(-7,27,-2,PRISMARINE:2)
Block(-7,27,-1,PRISMARINE:2)
Block(-7,27,0,PRISMARINE:2)
Block(-7,27,1,PRISMARINE:2)
Block(-7,27,2,PRISMARINE:2)
Block(-7,27,3,PRISMARINE:2)
Block(-7,27,4,PRISMARINE:2)
Block(-7,27,5,PRISMARINE:2)
Block(-7,27,6,PRISMARINE:2)
Block(-7,27,7,PRISMARINE:2)
Block(-7,27,8,PRISMARINE:2)
Block(-6,0,-5,quark:slate:1)
Block(-6,0,-4,quark:slate:1)
Block(-6,0,-3,quark:slate:1)
Block(-6,0,-2,quark:slate:1)
Block(-6,0,7,quark:slate:1)
Block(-6,0,8,quark:slate:1)
Block(-6,1,-5,quark:slate:1)
Block(-6,1,-4,quark:slate:1)
Block(-6,1,-3,quark:slate:1)
Block(-6,1,-2,quark:slate:1)
Block(-6,1,7,quark:slate:1)
Block(-6,1,8,quark:slate:1)
Block(-6,2,-7,quark:slate:1)
Block(-6,2,-6,quark:slate:1)
Block(-6,2,-5,quark:slate:1)
Block(-6,2,-4,quark:slate:1)
Block(-6,2,-3,quark:slate:1)
Block(-6,2,-2,quark:slate:1)
Block(-6,2,-1,quark:slate:1)
Block(-6,2,0,quark:slate:1)
Block(-6,2,1,quark:slate:1)
Block(-6,2,2,quark:slate:1)
Block(-6,2,3,quark:slate:1)
Block(-6,2,4,quark:slate:1)
Block(-6,2,5,quark:slate:1)
Block(-6,2,6,quark:slate:1)
Block(-6,2,7,quark:slate:1)
Block(-6,2,8,quark:slate:1)
Block(-6,3,-7,quark:slate:1)
Block(-6,3,-6,quark:slate:1)
Block(-6,3,-5,quark:slate:1)
Block(-6,3,-4,quark:slate:1)
Block(-6,3,-3,quark:slate:1)
Block(-6,3,-2,quark:slate:1)
Block(-6,3,-1,quark:slate:1)
Block(-6,3,0,quark:slate:1)
Block(-6,3,1,quark:slate:1)
Block(-6,3,2,quark:slate:1)
Block(-6,3,3,quark:slate:1)
Block(-6,3,4,quark:slate:1)
Block(-6,3,5,quark:slate:1)
Block(-6,3,6,quark:slate:1)
Block(-6,3,7,quark:slate:1)
Block(-6,3,8,quark:slate:1)
Block(-6,4,-7,quark:slate:1)
Block(-6,4,-6,quark:slate:1)
Block(-6,4,-5,quark:slate:1)
Block(-6,4,-4,quark:slate:1)
Block(-6,4,-3,quark:slate:1)
Block(-6,4,-2,quark:slate:1)
Block(-6,4,-1,quark:slate:1)
Block(-6,4,0,quark:slate:1)
Block(-6,4,1,quark:slate:1)
Block(-6,4,2,quark:slate:1)
Block(-6,4,3,quark:slate:1)
Block(-6,4,4,quark:slate:1)
Block(-6,4,5,quark:slate:1)
Block(-6,4,6,quark:slate:1)
Block(-6,4,7,quark:slate:1)
Block(-6,4,8,quark:slate:1)
Block(-6,5,-7,quark:slate:1)
Block(-6,5,-6,quark:slate:1)
Block(-6,5,-5,quark:slate:1)
Block(-6,5,-4,quark:slate:1)
Block(-6,5,-3,quark:slate:1)
Block(-6,5,-2,quark:slate:1)
Block(-6,5,-1,quark:slate:1)
Block(-6,5,0,quark:slate:1)
Block(-6,5,1,quark:slate:1)
Block(-6,5,2,quark:slate:1)
Block(-6,5,3,quark:slate:1)
Block(-6,5,4,quark:slate:1)
Block(-6,5,5,quark:slate:1)
Block(-6,5,6,quark:slate:1)
Block(-6,5,7,quark:slate:1)
Block(-6,5,8,quark:slate:1)
Block(-6,6,-7,quark:slate:1)
Block(-6,6,-6,quark:slate:1)
Block(-6,6,-5,quark:slate:1)
Block(-6,6,-4,quark:slate:1)
Block(-6,6,-3,quark:slate:1)
Block(-6,6,-2,quark:slate:1)
Block(-6,6,-1,quark:slate:1)
Block(-6,6,0,quark:slate:1)
Block(-6,6,1,quark:slate:1)
Block(-6,6,2,quark:slate:1)
Block(-6,6,3,quark:slate:1)
Block(-6,6,4,quark:slate:1)
Block(-6,6,5,quark:slate:1)
Block(-6,6,6,quark:slate:1)
Block(-6,6,7,quark:slate:1)
Block(-6,6,8,quark:slate:1)
Block(-6,7,-7,quark:slate:1)
Block(-6,7,-6,quark:slate:1)
Block(-6,7,-5,quark:slate:1)
Block(-6,7,-4,quark:slate:1)
Block(-6,7,-3,quark:slate:1)
Block(-6,7,-2,quark:slate:1)
Block(-6,7,-1,quark:slate:1)
Block(-6,7,0,quark:slate:1)
Block(-6,7,1,quark:slate:1)
Block(-6,7,2,quark:slate:1)
Block(-6,7,3,quark:slate:1)
Block(-6,7,4,quark:slate:1)
Block(-6,7,5,quark:slate:1)
Block(-6,7,6,quark:slate:1)
Block(-6,7,7,quark:slate:1)
Block(-6,7,8,quark:slate:1)
Block(-6,8,-7,quark:slate:1)
Block(-6,8,-6,quark:slate:1)
Block(-6,8,-5,quark:slate:1)
Block(-6,8,-4,quark:slate:1)
Block(-6,8,-3,quark:slate:1)
Block(-6,8,-2,quark:slate:1)
Block(-6,8,-1,quark:slate:1)
Block(-6,8,0,quark:slate:1)
Block(-6,8,1,quark:slate:1)
Block(-6,8,2,quark:slate:1)
Block(-6,8,3,quark:slate:1)
Block(-6,8,4,quark:slate:1)
Block(-6,8,5,quark:slate:1)
Block(-6,8,6,quark:slate:1)
Block(-6,8,7,quark:slate:1)
Block(-6,8,8,quark:slate:1)
Block(-6,9,-7,quark:slate:1)
Block(-6,9,-6,quark:slate:1)
Block(-6,9,-5,quark:slate:1)
Block(-6,9,-4,quark:slate:1)
Block(-6,9,-3,quark:slate:1)
Block(-6,9,-2,quark:slate:1)
Block(-6,9,-1,quark:slate:1)
Block(-6,9,0,quark:slate:1)
Block(-6,9,1,quark:slate:1)
Block(-6,9,2,quark:slate:1)
Block(-6,9,3,quark:slate:1)
Block(-6,9,4,quark:slate:1)
Block(-6,9,5,quark:slate:1)
Block(-6,9,6,quark:slate:1)
Block(-6,9,7,quark:slate:1)
Block(-6,9,8,quark:slate:1)
Block(-6,10,-7,quark:slate:1)
Block(-6,10,-6,quark:slate:1)
Block(-6,10,-5,quark:slate:1)
Block(-6,10,-4,quark:slate:1)
Block(-6,10,-3,quark:slate:1)
Block(-6,10,-2,quark:slate:1)
Block(-6,10,-1,quark:slate:1)
Block(-6,10,0,quark:slate:1)
Block(-6,10,1,quark:slate:1)
Block(-6,10,2,quark:slate:1)
Block(-6,10,3,quark:slate:1)
Block(-6,10,4,quark:slate:1)
Block(-6,10,5,quark:slate:1)
Block(-6,10,6,quark:slate:1)
Block(-6,10,7,quark:slate:1)
Block(-6,10,8,quark:slate:1)
Block(-6,11,-7,biomesoplenty:wood_slab_1:14)
Block(-6,11,-6,biomesoplenty:wood_slab_1:14)
Block(-6,11,-5,biomesoplenty:wood_slab_1:14)
Block(-6,11,-4,biomesoplenty:wood_slab_1:14)
Block(-6,11,-3,biomesoplenty:wood_slab_1:14)
Block(-6,11,-2,biomesoplenty:wood_slab_1:14)
Block(-6,11,-1,biomesoplenty:wood_slab_1:14)
Block(-6,11,0,biomesoplenty:wood_slab_1:14)
Block(-6,11,1,biomesoplenty:wood_slab_1:14)
Block(-6,11,2,quark:iron_plate)
Block(-6,11,3,quark:iron_plate)
Block(-6,11,4,biomesoplenty:wood_slab_1:14)
Block(-6,11,5,biomesoplenty:wood_slab_1:14)
Block(-6,11,6,biomesoplenty:wood_slab_1:14)
Block(-6,11,7,biomesoplenty:wood_slab_1:14)
Block(-6,11,8,biomesoplenty:wood_slab_1:14)
Block(-6,12,-7,quark:dark_oak_trapdoor:6)
Block(-6,12,-6,quark:dark_oak_trapdoor:6)
Block(-6,12,-5,inspirations:path)
Block(-6,12,-4,CARPET:15)
Block(-6,12,-3,AIR:0)
Block(-6,12,-2,AIR:0)
Block(-6,12,-1,AIR:0)
Block(-6,12,0,AIR:0)
Block(-6,12,1,rustic:iron_lattice:0)
Block(-6,12,2,quark:iron_plate_stairs:0)
Block(-6,12,3,quark:iron_plate_stairs:0)
Block(-6,12,4,rustic:iron_lattice:0)
Block(-6,12,5,AIR:0)
Block(-6,13,-7,AIR:0)
Block(-6,13,-6,AIR:0)
Block(-6,13,-5,AIR:0)
Block(-6,13,-4,AIR:0)
Block(-6,13,-3,AIR:0)
Block(-6,13,-2,AIR:0)
Block(-6,13,-1,AIR:0)
Block(-6,13,0,AIR:0)
Block(-6,13,1,rustic:iron_lattice:0)
Block(-6,13,2,AIR:0)
Block(-6,13,3,AIR:0)
Block(-6,13,4,rustic:iron_lattice:0)
Block(-6,13,5,AIR:0)
Block(-6,13,6,AIR:0)
Block(-6,13,7,AIR:0)
Block(-6,13,8,AIR:0)
Block(-6,14,-7,AIR:0)
Block(-6,14,-6,AIR:0)
Block(-6,14,-5,AIR:0)
Block(-6,14,-4,AIR:0)
Block(-6,14,-3,AIR:0)
Block(-6,14,-2,AIR:0)
Block(-6,14,-1,AIR:0)
Block(-6,14,0,AIR:0)
Block(-6,14,1,AIR:0)
Block(-6,14,2,AIR:0)
Block(-6,14,3,AIR:0)
Block(-6,14,4,AIR:0)
Block(-6,14,5,AIR:0)
Block(-6,14,6,AIR:0)
Block(-6,14,7,AIR:0)
Block(-6,14,8,AIR:0)
Block(-6,15,-7,AIR:0)
Block(-6,15,-6,AIR:0)
Block(-6,15,-5,AIR:0)
Block(-6,15,-4,AIR:0)
Block(-6,15,-3,AIR:0)
Block(-6,15,-2,AIR:0)
Block(-6,15,-1,AIR:0)
Block(-6,15,0,AIR:0)
Block(-6,15,1,AIR:0)
Block(-6,15,2,AIR:0)
Block(-6,15,3,AIR:0)
Block(-6,15,4,AIR:0)
Block(-6,15,5,AIR:0)
Block(-6,15,6,AIR:0)
Block(-6,15,7,AIR:0)
Block(-6,15,8,AIR:0)
Block(-6,16,-7,quark:grate)
Block(-6,16,-6,quark:grate)
Block(-6,16,-5,quark:grate)
Block(-6,16,-4,quark:grate)
Block(-6,16,-3,quark:grate)
Block(-6,16,-2,quark:grate)
Block(-6,16,-1,biomesoplenty:wood_slab_1:14)
Block(-6,16,0,quark:grate)
Block(-6,16,1,quark:grate)
Block(-6,16,2,quark:grate)
Block(-6,16,3,biomesoplenty:wood_slab_1:14)
Block(-6,16,4,biomesoplenty:wood_slab_1:14)
Block(-6,16,5,quark:grate)
Block(-6,16,6,quark:grate)
Block(-6,16,7,quark:grate)
Block(-6,16,8,quark:grate)
Block(-6,17,-7,quark:basalt:1)
Block(-6,17,-6,quark:basalt:1)
Block(-6,17,-5,quark:basalt:1)
Block(-6,17,-4,quark:basalt:1)
Block(-6,17,-3,quark:basalt:1)
Block(-6,17,-2,quark:basalt:1)
Block(-6,17,-1,quark:basalt:1)
Block(-6,17,0,quark:basalt:1)
Block(-6,17,1,quark:basalt:1)
Block(-6,17,2,quark:basalt:1)
Block(-6,17,3,quark:basalt:1)
Block(-6,17,4,quark:basalt:1)
Block(-6,17,5,quark:basalt:1)
Block(-6,17,6,quark:basalt:1)
Block(-6,17,7,quark:basalt:1)
Block(-6,17,8,quark:basalt:1)
Block(-6,18,-7,AIR:0)
Block(-6,18,-6,STEP:0)
Block(-6,18,-5,AIR:0)
Block(-6,18,-4,AIR:0)
Block(-6,18,-3,AIR:0)
Block(-6,18,-2,AIR:0)
Block(-6,18,-1,AIR:0)
Block(-6,18,0,AIR:0)
Block(-6,18,1,AIR:0)
Block(-6,18,2,AIR:0)
Block(-6,18,3,AIR:0)
Block(-6,18,4,AIR:0)
Block(-6,18,5,AIR:0)
Block(-6,18,6,AIR:0)
Block(-6,18,7,AIR:0)
Block(-6,18,8,AIR:0)
Block(-6,19,-7,AIR:0)
Block(-6,19,-6,AIR:0)
Block(-6,19,-5,AIR:0)
Block(-6,19,-4,AIR:0)
Block(-6,19,-3,AIR:0)
Block(-6,19,-2,AIR:0)
Block(-6,19,-1,AIR:0)
Block(-6,19,0,AIR:0)
Block(-6,19,1,AIR:0)
Block(-6,19,2,AIR:0)
Block(-6,19,3,AIR:0)
Block(-6,19,4,AIR:0)
Block(-6,19,5,AIR:0)
Block(-6,19,6,AIR:0)
Block(-6,19,7,AIR:0)
Block(-6,19,8,AIR:0)
Block(-6,20,-7,AIR:0)
Block(-6,20,-6,AIR:0)
Block(-6,20,-5,AIR:0)
Block(-6,20,-4,quark:grate)
Block(-6,20,-3,quark:grate)
Block(-6,20,-2,quark:grate)
Block(-6,20,-1,quark:iron_plate_slab:8)
Block(-6,20,0,quark:grate)
Block(-6,20,1,quark:grate)
Block(-6,20,2,quark:grate)
Block(-6,20,3,quark:grate)
Block(-6,20,4,quark:grate)
Block(-6,20,5,quark:grate)
Block(-6,20,6,quark:iron_plate_slab:8)
Block(-6,20,7,quark:grate)
Block(-6,20,8,quark:grate)
Block(-6,21,-7,AIR:0)
Block(-6,21,-6,AIR:0)
Block(-6,21,-5,AIR:0)
Block(-6,21,-4,IRON_FENCE:0)
Block(-6,21,-3,AIR:0)
Block(-6,21,-2,AIR:0)
Block(-6,21,-1,AIR:0)
Block(-6,21,0,AIR:0)
Block(-6,21,1,AIR:0)
Block(-6,21,2,AIR:0)
Block(-6,21,3,AIR:0)
Block(-6,21,4,AIR:0)
Block(-6,21,5,AIR:0)
Block(-6,21,6,AIR:0)
Block(-6,21,7,AIR:0)
Block(-6,21,8,AIR:0)
Block(-6,22,-7,AIR:0)
Block(-6,22,-6,AIR:0)
Block(-6,22,-5,AIR:0)
Block(-6,22,-4,AIR:0)
Block(-6,22,-3,AIR:0)
Block(-6,22,-2,AIR:0)
Block(-6,22,-1,AIR:0)
Block(-6,22,0,AIR:0)
Block(-6,22,1,AIR:0)
Block(-6,22,2,AIR:0)
Block(-6,22,3,AIR:0)
Block(-6,22,4,AIR:0)
Block(-6,22,5,AIR:0)
Block(-6,22,6,AIR:0)
Block(-6,22,7,AIR:0)
Block(-6,22,8,AIR:0)
Block(-6,23,-7,quark:iron_plate)
Block(-6,23,-6,quark:prismarine_dark_slab:8)
Block(-6,23,-5,quark:prismarine_dark_slab:8)
Block(-6,23,-4,quark:prismarine_dark_slab:8)
Block(-6,23,-3,quark:prismarine_dark_slab:8)
Block(-6,23,-2,quark:prismarine_dark_slab:8)
Block(-6,23,-1,quark:iron_plate)
Block(-6,23,0,quark:prismarine_dark_slab:8)
Block(-6,23,1,quark:prismarine_dark_slab:8)
Block(-6,23,2,quark:prismarine_dark_slab:8)
Block(-6,23,3,quark:prismarine_dark_slab:8)
Block(-6,23,4,quark:prismarine_dark_slab:8)
Block(-6,23,5,quark:prismarine_dark_slab:8)
Block(-6,23,6,quark:iron_plate)
Block(-6,23,7,quark:prismarine_dark_slab:8)
Block(-6,23,8,quark:prismarine_dark_slab:8)
Block(-6,24,-7,quark:iron_plate)
Block(-6,24,-6,PRISMARINE:2)
Block(-6,24,-5,PRISMARINE:2)
Block(-6,24,-4,PRISMARINE:2)
Block(-6,24,-3,PRISMARINE:2)
Block(-6,24,-2,PRISMARINE:2)
Block(-6,24,-1,quark:iron_plate)
Block(-6,24,0,PRISMARINE:2)
Block(-6,24,1,PRISMARINE:2)
Block(-6,24,2,PRISMARINE:2)
Block(-6,24,3,PRISMARINE:2)
Block(-6,24,4,PRISMARINE:2)
Block(-6,24,5,PRISMARINE:2)
Block(-6,24,6,quark:iron_plate)
Block(-6,24,7,PRISMARINE:2)
Block(-6,24,8,PRISMARINE:2)
Block(-6,25,-3,PRISMARINE:2)
Block(-6,25,-2,PRISMARINE:2)
Block(-6,25,-1,quark:iron_plate)
Block(-6,25,0,PRISMARINE:2)
Block(-6,25,1,PRISMARINE:2)
Block(-6,25,2,PRISMARINE:2)
Block(-6,25,3,PRISMARINE:2)
Block(-6,25,4,PRISMARINE:2)
Block(-6,25,5,PRISMARINE:2)
Block(-6,25,6,quark:iron_plate)
Block(-6,25,7,PRISMARINE:2)
Block(-6,25,8,PRISMARINE:2)
Block(-6,26,-3,quark:iron_plate)
Block(-6,26,-2,quark:iron_plate)
Block(-6,26,-1,quark:iron_plate)
Block(-6,26,0,quark:iron_plate)
Block(-6,26,1,quark:iron_plate)
Block(-6,26,2,quark:iron_plate)
Block(-6,26,3,quark:iron_plate)
Block(-6,26,4,quark:iron_plate)
Block(-6,26,5,quark:iron_plate)
Block(-6,26,6,quark:iron_plate)
Block(-6,26,7,quark:iron_plate)
Block(-6,26,8,quark:iron_plate)
Block(-5,2,-7,quark:slate:1)
Block(-5,2,-6,quark:slate:1)
Block(-5,2,-5,quark:slate:1)
Block(-5,2,-4,quark:slate:1)
Block(-5,2,-3,quark:slate:1)
Block(-5,2,-2,quark:slate:1)
Block(-5,2,-1,quark:slate:1)
Block(-5,2,0,quark:slate:1)
Block(-5,2,1,quark:slate:1)
Block(-5,2,2,quark:slate:1)
Block(-5,2,3,quark:slate:1)
Block(-5,2,4,quark:slate:1)
Block(-5,2,5,quark:slate:1)
Block(-5,2,6,quark:slate:1)
Block(-5,2,7,quark:slate:1)
Block(-5,2,8,quark:slate:1)
Block(-5,3,-7,quark:slate:1)
Block(-5,3,-6,quark:slate:1)
Block(-5,3,-5,quark:slate:1)
Block(-5,3,-4,quark:slate:1)
Block(-5,3,-3,quark:slate:1)
Block(-5,3,-2,quark:slate:1)
Block(-5,3,-1,quark:slate:1)
Block(-5,3,0,quark:slate:1)
Block(-5,3,1,quark:slate:1)
Block(-5,3,2,quark:slate:1)
Block(-5,3,3,quark:slate:1)
Block(-5,3,4,quark:slate:1)
Block(-5,3,5,quark:slate:1)
Block(-5,3,6,quark:slate:1)
Block(-5,3,7,quark:slate:1)
Block(-5,3,8,quark:slate:1)
Block(-5,4,-7,quark:slate:1)
Block(-5,4,-6,quark:slate:1)
Block(-5,4,-5,quark:slate:1)
Block(-5,4,-4,quark:slate:1)
Block(-5,4,-3,quark:slate:1)
Block(-5,4,-2,quark:slate:1)
Block(-5,4,-1,quark:slate:1)
Block(-5,4,0,quark:slate:1)
Block(-5,4,1,quark:slate:1)
Block(-5,4,2,quark:slate:1)
Block(-5,4,3,quark:slate:1)
Block(-5,4,4,quark:slate:1)
Block(-5,4,5,quark:slate:1)
Block(-5,4,6,quark:slate:1)
Block(-5,4,7,quark:slate:1)
Block(-5,4,8,quark:slate:1)
Block(-5,5,-7,quark:slate:1)
Block(-5,5,-6,quark:slate:1)
Block(-5,5,-5,quark:slate:1)
Block(-5,5,-4,quark:slate:1)
Block(-5,5,-3,quark:slate:1)
Block(-5,5,-2,quark:slate:1)
Block(-5,5,-1,quark:slate:1)
Block(-5,5,0,quark:slate:1)
Block(-5,5,1,quark:slate:1)
Block(-5,5,2,quark:slate:1)
Block(-5,5,3,quark:slate:1)
Block(-5,5,4,quark:slate:1)
Block(-5,5,5,quark:slate:1)
Block(-5,5,6,quark:slate:1)
Block(-5,5,7,quark:slate:1)
Block(-5,5,8,quark:slate:1)
Block(-5,6,-7,quark:slate:1)
Block(-5,6,-6,quark:slate:1)
Block(-5,6,-5,quark:slate:1)
Block(-5,6,-4,quark:slate:1)
Block(-5,6,-3,quark:slate:1)
Block(-5,6,-2,quark:slate:1)
Block(-5,6,-1,quark:slate:1)
Block(-5,6,0,quark:slate:1)
Block(-5,6,1,quark:slate:1)
Block(-5,6,2,quark:slate:1)
Block(-5,6,3,quark:slate:1)
Block(-5,6,4,quark:slate:1)
Block(-5,6,5,quark:slate:1)
Block(-5,6,6,quark:slate:1)
Block(-5,6,7,quark:slate:1)
Block(-5,6,8,quark:slate:1)
Block(-5,7,-7,quark:slate:1)
Block(-5,7,-6,quark:slate:1)
Block(-5,7,-5,quark:slate:1)
Block(-5,7,-4,quark:slate:1)
Block(-5,7,-3,quark:slate:1)
Block(-5,7,-2,quark:slate:1)
Block(-5,7,-1,quark:slate:1)
Block(-5,7,0,quark:slate:1)
Block(-5,7,1,quark:slate:1)
Block(-5,7,2,quark:slate:1)
Block(-5,7,3,quark:slate:1)
Block(-5,7,4,quark:slate:1)
Block(-5,7,5,quark:slate:1)
Block(-5,7,6,quark:slate:1)
Block(-5,7,7,quark:slate:1)
Block(-5,7,8,quark:slate:1)
Block(-5,8,-7,quark:slate:1)
Block(-5,8,-6,quark:slate:1)
Block(-5,8,-5,quark:slate:1)
Block(-5,8,-4,quark:slate:1)
Block(-5,8,-3,quark:slate:1)
Block(-5,8,-2,quark:slate:1)
Block(-5,8,-1,quark:slate:1)
Block(-5,8,0,quark:slate:1)
Block(-5,8,1,quark:slate:1)
Block(-5,8,2,quark:slate:1)
Block(-5,8,3,quark:slate:1)
Block(-5,8,4,quark:slate:1)
Block(-5,8,5,quark:slate:1)
Block(-5,8,6,quark:slate:1)
Block(-5,8,7,quark:slate:1)
Block(-5,8,8,quark:slate:1)
Block(-5,9,-7,quark:slate:1)
Block(-5,9,-6,quark:slate:1)
Block(-5,9,-5,quark:slate:1)
Block(-5,9,-4,quark:slate:1)
Block(-5,9,-3,quark:slate:1)
Block(-5,9,-2,quark:slate:1)
Block(-5,9,-1,quark:slate:1)
Block(-5,9,0,quark:slate:1)
Block(-5,9,1,quark:slate:1)
Block(-5,9,2,quark:slate:1)
Block(-5,9,3,quark:slate:1)
Block(-5,9,4,quark:slate:1)
Block(-5,9,5,quark:slate:1)
Block(-5,9,6,quark:slate:1)
Block(-5,9,7,quark:slate:1)
Block(-5,9,8,quark:slate:1)
Block(-5,10,-7,quark:slate:1)
Block(-5,10,-6,quark:slate:1)
Block(-5,10,-5,quark:slate:1)
Block(-5,10,-4,quark:slate:1)
Block(-5,10,-3,quark:slate:1)
Block(-5,10,-2,quark:slate:1)
Block(-5,10,-1,quark:slate:1)
Block(-5,10,0,quark:slate:1)
Block(-5,10,1,quark:slate:1)
Block(-5,10,2,quark:slate:1)
Block(-5,10,3,quark:slate:1)
Block(-5,10,4,quark:slate:1)
Block(-5,10,5,quark:slate:1)
Block(-5,10,6,quark:slate:1)
Block(-5,10,7,quark:slate:1)
Block(-5,10,8,quark:slate:1)
Block(-5,11,-7,biomesoplenty:wood_slab_1:14)
Block(-5,11,-6,biomesoplenty:wood_slab_1:14)
Block(-5,11,-5,biomesoplenty:wood_slab_1:14)
Block(-5,11,-4,biomesoplenty:wood_slab_1:14)
Block(-5,11,-3,biomesoplenty:wood_slab_1:14)
Block(-5,11,-2,biomesoplenty:wood_slab_1:14)
Block(-5,11,-1,biomesoplenty:wood_slab_1:14)
Block(-5,11,0,biomesoplenty:wood_slab_1:14)
Block(-5,11,1,biomesoplenty:wood_slab_1:14)
Block(-5,11,2,quark:iron_plate)
Block(-5,11,3,quark:iron_plate)
Block(-5,11,4,biomesoplenty:wood_slab_1:14)
Block(-5,11,5,biomesoplenty:wood_slab_1:14)
Block(-5,11,6,biomesoplenty:wood_slab_1:14)
Block(-5,11,7,biomesoplenty:wood_slab_1:14)
Block(-5,11,8,biomesoplenty:wood_slab_1:14)
Block(-5,12,-7,DIRT:2)
Block(-5,12,-6,DIRT:2)
Block(-5,12,-5,quark:dark_oak_trapdoor:5)
Block(-5,12,-4,CARPET:15)
Block(-5,12,-3,contenttweaker:bone_pile)
Block(-5,12,-2,AIR:0)
Block(-5,12,-1,AIR:0)
Block(-5,12,0,AIR:0)
Block(-5,12,1,AIR:0)
Block(-5,12,2,quark:iron_plate)
Block(-5,12,3,quark:iron_plate)
Block(-5,12,4,AIR:0)
Block(-5,12,5,inspirations:path)
Block(-5,13,-7,biomesoplenty:leaves_1:5)
Block(-5,13,-6,biomesoplenty:leaves_1:5)
Block(-5,13,-5,AIR:0)
Block(-5,13,-4,AIR:0)
Block(-5,13,-3,AIR:0)
Block(-5,13,-2,AIR:0)
Block(-5,13,-1,AIR:0)
Block(-5,13,0,AIR:0)
Block(-5,13,1,rustic:iron_lattice:0)
Block(-5,13,2,AIR:0)
Block(-5,13,3,AIR:0)
Block(-5,13,4,rustic:iron_lattice:0)
Block(-5,13,5,AIR:0)
Block(-5,13,6,IRON_PLATE:0)
Block(-5,13,7,IRON_PLATE:0)
Block(-5,13,8,IRON_PLATE:0)
Block(-5,14,-7,AIR:0)
Block(-5,14,-6,biomesoplenty:leaves_1:5)
Block(-5,14,-5,AIR:0)
Block(-5,14,-4,AIR:0)
Block(-5,14,-3,quark:paper_lantern)
Block(-5,14,-2,AIR:0)
Block(-5,14,-1,AIR:0)
Block(-5,14,0,AIR:0)
Block(-5,14,1,AIR:0)
Block(-5,14,2,AIR:0)
Block(-5,14,3,AIR:0)
Block(-5,14,4,AIR:0)
Block(-5,14,5,AIR:0)
Block(-5,14,6,AIR:0)
Block(-5,14,7,AIR:0)
Block(-5,14,8,quark:paper_lantern)
Block(-5,15,-7,AIR:0)
Block(-5,15,-6,biomesoplenty:leaves_1:5)
Block(-5,15,-5,AIR:0)
Block(-5,15,-4,AIR:0)
Block(-5,15,-3,rustic:iron_lattice:0)
Block(-5,15,-2,AIR:0)
Block(-5,15,-1,AIR:0)
Block(-5,15,0,AIR:0)
Block(-5,15,1,AIR:0)
Block(-5,15,2,AIR:0)
Block(-5,15,3,AIR:0)
Block(-5,15,4,AIR:0)
Block(-5,15,5,AIR:0)
Block(-5,15,6,AIR:0)
Block(-5,15,7,AIR:0)
Block(-5,15,8,rustic:iron_lattice:0)
Block(-5,16,-7,biomesoplenty:wood_slab_1:14)
Block(-5,16,-6,biomesoplenty:wood_slab_1:14)
Block(-5,16,-5,biomesoplenty:wood_slab_1:14)
Block(-5,16,-4,biomesoplenty:wood_slab_1:14)
Block(-5,16,-3,biomesoplenty:wood_slab_1:14)
Block(-5,16,-2,biomesoplenty:wood_slab_1:14)
Block(-5,16,-1,biomesoplenty:wood_slab_1:14)
Block(-5,16,0,biomesoplenty:wood_slab_1:14)
Block(-5,16,1,biomesoplenty:wood_slab_1:14)
Block(-5,16,2,biomesoplenty:wood_slab_1:14)
Block(-5,16,3,biomesoplenty:wood_slab_1:14)
Block(-5,16,4,biomesoplenty:wood_slab_1:14)
Block(-5,16,5,biomesoplenty:wood_slab_1:14)
Block(-5,16,6,biomesoplenty:wood_slab_1:14)
Block(-5,16,7,biomesoplenty:wood_slab_1:14)
Block(-5,16,8,biomesoplenty:wood_slab_1:14)
Block(-5,17,-7,quark:iron_plate:1)
Block(-5,17,-6,quark:iron_plate:1)
Block(-5,17,-5,quark:iron_plate:1)
Block(-5,17,-4,quark:iron_plate:1)
Block(-5,17,-3,quark:iron_plate:1)
Block(-5,17,-2,quark:iron_plate:1)
Block(-5,17,-1,quark:iron_plate:1)
Block(-5,17,0,quark:iron_plate:1)
Block(-5,17,1,quark:iron_plate:1)
Block(-5,17,2,quark:iron_plate:1)
Block(-5,17,3,quark:iron_plate:1)
Block(-5,17,4,quark:iron_plate:1)
Block(-5,17,5,quark:iron_plate:1)
Block(-5,17,6,quark:iron_plate:1)
Block(-5,17,7,quark:iron_plate:1)
Block(-5,17,8,quark:iron_plate:1)
Block(-5,18,-7,inspirations:path)
Block(-5,18,-6,STEP:0)
Block(-5,18,-5,AIR:0)
Block(-5,18,-4,AIR:0)
Block(-5,18,-3,AIR:0)
Block(-5,18,-2,AIR:0)
Block(-5,18,-1,AIR:0)
Block(-5,18,0,AIR:0)
Block(-5,18,1,AIR:0)
Block(-5,18,2,AIR:0)
Block(-5,18,3,AIR:0)
Block(-5,18,4,AIR:0)
Block(-5,18,5,AIR:0)
Block(-5,18,6,AIR:0)
Block(-5,18,7,AIR:0)
Block(-5,18,8,AIR:0)
Block(-5,19,-7,AIR:0)
Block(-5,19,-6,AIR:0)
Block(-5,19,-5,AIR:0)
Block(-5,19,-4,AIR:0)
Block(-5,19,-3,AIR:0)
Block(-5,19,-2,AIR:0)
Block(-5,19,-1,AIR:0)
Block(-5,19,0,AIR:0)
Block(-5,19,1,AIR:0)
Block(-5,19,2,AIR:0)
Block(-5,19,3,AIR:0)
Block(-5,19,4,AIR:0)
Block(-5,19,5,AIR:0)
Block(-5,19,6,AIR:0)
Block(-5,19,7,AIR:0)
Block(-5,19,8,AIR:0)
Block(-5,20,-7,AIR:0)
Block(-5,20,-6,AIR:0)
Block(-5,20,-5,AIR:0)
Block(-5,20,-4,quark:grate)
Block(-5,20,-3,quark:grate)
Block(-5,20,-2,quark:grate)
Block(-5,20,-1,quark:iron_plate_slab:8)
Block(-5,20,0,quark:grate)
Block(-5,20,1,quark:grate)
Block(-5,20,2,quark:grate)
Block(-5,20,3,quark:grate)
Block(-5,20,4,quark:grate)
Block(-5,20,5,quark:grate)
Block(-5,20,6,quark:iron_plate_slab:8)
Block(-5,20,7,quark:grate)
Block(-5,20,8,quark:grate)
Block(-5,21,-7,AIR:0)
Block(-5,21,-6,AIR:0)
Block(-5,21,-5,AIR:0)
Block(-5,21,-4,IRON_FENCE:0)
Block(-5,21,-3,IRON_FENCE:0)
Block(-5,21,-2,IRON_FENCE:0)
Block(-5,21,-1,rustic:iron_lattice:0)
Block(-5,21,0,IRON_FENCE:0)
Block(-5,21,1,IRON_FENCE:0)
Block(-5,21,2,IRON_FENCE:0)
Block(-5,21,3,IRON_FENCE:0)
Block(-5,21,4,IRON_FENCE:0)
Block(-5,21,5,IRON_FENCE:0)
Block(-5,21,6,rustic:iron_lattice:0)
Block(-5,21,7,IRON_FENCE:0)
Block(-5,21,8,IRON_FENCE:0)
Block(-5,22,-7,AIR:0)
Block(-5,22,-6,AIR:0)
Block(-5,22,-5,AIR:0)
Block(-5,22,-4,AIR:0)
Block(-5,22,-3,AIR:0)
Block(-5,22,-2,AIR:0)
Block(-5,22,-1,rustic:iron_lattice:0)
Block(-5,22,0,AIR:0)
Block(-5,22,1,AIR:0)
Block(-5,22,2,AIR:0)
Block(-5,22,3,AIR:0)
Block(-5,22,4,AIR:0)
Block(-5,22,5,AIR:0)
Block(-5,22,6,rustic:iron_lattice:0)
Block(-5,22,7,AIR:0)
Block(-5,22,8,AIR:0)
Block(-5,23,-7,quark:iron_plate)
Block(-5,23,-6,quark:prismarine_dark_slab:8)
Block(-5,23,-5,quark:prismarine_dark_slab:8)
Block(-5,23,-4,quark:prismarine_dark_slab:8)
Block(-5,23,-3,quark:prismarine_dark_slab:8)
Block(-5,23,-2,quark:prismarine_dark_slab:8)
Block(-5,23,-1,quark:iron_plate)
Block(-5,23,0,quark:prismarine_dark_slab:8)
Block(-5,23,1,quark:prismarine_dark_slab:8)
Block(-5,23,2,quark:prismarine_dark_slab:8)
Block(-5,23,3,quark:prismarine_dark_slab:8)
Block(-5,23,4,quark:prismarine_dark_slab:8)
Block(-5,23,5,quark:prismarine_dark_slab:8)
Block(-5,23,6,quark:iron_plate)
Block(-5,23,7,quark:prismarine_dark_slab:8)
Block(-5,23,8,quark:prismarine_dark_slab:8)
Block(-5,24,-7,quark:iron_plate)
Block(-5,24,-6,PRISMARINE:2)
Block(-5,24,-5,PRISMARINE:2)
Block(-5,24,-4,PRISMARINE:2)
Block(-5,24,-3,PRISMARINE:2)
Block(-5,24,-2,PRISMARINE:2)
Block(-5,24,-1,quark:iron_plate)
Block(-5,24,0,PRISMARINE:2)
Block(-5,24,1,PRISMARINE:2)
Block(-5,24,2,PRISMARINE:2)
Block(-5,24,3,PRISMARINE:2)
Block(-5,24,4,PRISMARINE:2)
Block(-5,24,5,PRISMARINE:2)
Block(-5,24,6,quark:iron_plate)
Block(-5,24,7,PRISMARINE:2)
Block(-5,24,8,PRISMARINE:2)
Block(-5,25,1,PRISMARINE:2)
Block(-5,25,4,PRISMARINE:2)
Block(-4,2,-7,quark:slate:1)
Block(-4,2,-6,quark:slate:1)
Block(-4,2,-5,quark:slate:1)
Block(-4,2,-4,quark:slate:1)
Block(-4,2,-3,quark:slate:1)
Block(-4,2,-2,quark:slate:1)
Block(-4,2,-1,quark:slate:1)
Block(-4,2,0,quark:slate:1)
Block(-4,2,1,quark:slate:1)
Block(-4,2,2,quark:slate:1)
Block(-4,2,3,quark:slate:1)
Block(-4,2,4,quark:slate:1)
Block(-4,2,5,quark:slate:1)
Block(-4,2,6,quark:slate:1)
Block(-4,2,7,quark:slate:1)
Block(-4,2,8,quark:slate:1)
Block(-4,3,-7,quark:slate:1)
Block(-4,3,-6,quark:slate:1)
Block(-4,3,-5,quark:slate:1)
Block(-4,3,-4,quark:slate:1)
Block(-4,3,-3,quark:slate:1)
Block(-4,3,-2,quark:slate:1)
Block(-4,3,-1,quark:slate:1)
Block(-4,3,0,quark:slate:1)
Block(-4,3,1,quark:slate:1)
Block(-4,3,2,quark:slate:1)
Block(-4,3,3,quark:slate:1)
Block(-4,3,4,quark:slate:1)
Block(-4,3,5,quark:slate:1)
Block(-4,3,6,quark:slate:1)
Block(-4,3,7,quark:slate:1)
Block(-4,3,8,quark:slate:1)
Block(-4,4,-7,quark:slate:1)
Block(-4,4,-6,quark:slate:1)
Block(-4,4,-5,quark:slate:1)
Block(-4,4,-4,quark:slate:1)
Block(-4,4,-3,quark:slate:1)
Block(-4,4,-2,quark:slate:1)
Block(-4,4,-1,quark:slate:1)
Block(-4,4,0,quark:slate:1)
Block(-4,4,1,quark:slate:1)
Block(-4,4,2,quark:slate:1)
Block(-4,4,3,quark:slate:1)
Block(-4,4,4,quark:slate:1)
Block(-4,4,5,quark:slate:1)
Block(-4,4,6,quark:slate:1)
Block(-4,4,7,quark:slate:1)
Block(-4,4,8,quark:slate:1)
Block(-4,5,-7,quark:slate:1)
Block(-4,5,-6,quark:slate:1)
Block(-4,5,-5,quark:slate:1)
Block(-4,5,-4,quark:slate:1)
Block(-4,5,-3,quark:slate:1)
Block(-4,5,-2,quark:slate:1)
Block(-4,5,-1,quark:slate:1)
Block(-4,5,0,quark:slate:1)
Block(-4,5,1,quark:slate:1)
Block(-4,5,2,quark:slate:1)
Block(-4,5,3,quark:slate:1)
Block(-4,5,4,quark:slate:1)
Block(-4,5,5,quark:slate:1)
Block(-4,5,6,quark:slate:1)
Block(-4,5,7,quark:slate:1)
Block(-4,5,8,quark:slate:1)
Block(-4,6,-7,quark:slate:1)
Block(-4,6,-6,quark:slate:1)
Block(-4,6,-5,quark:slate:1)
Block(-4,6,-4,quark:slate:1)
Block(-4,6,-3,quark:slate:1)
Block(-4,6,-2,quark:slate:1)
Block(-4,6,-1,quark:slate:1)
Block(-4,6,0,quark:slate:1)
Block(-4,6,1,quark:slate:1)
Block(-4,6,2,quark:slate:1)
Block(-4,6,3,quark:slate:1)
Block(-4,6,4,quark:slate:1)
Block(-4,6,5,quark:slate:1)
Block(-4,6,6,quark:slate:1)
Block(-4,6,7,quark:slate:1)
Block(-4,6,8,quark:slate:1)
Block(-4,7,-7,quark:slate:1)
Block(-4,7,-6,quark:slate:1)
Block(-4,7,-5,quark:slate:1)
Block(-4,7,-4,quark:slate:1)
Block(-4,7,-3,quark:slate:1)
Block(-4,7,-2,quark:slate:1)
Block(-4,7,-1,quark:slate:1)
Block(-4,7,0,quark:slate:1)
Block(-4,7,1,quark:slate:1)
Block(-4,7,2,quark:slate:1)
Block(-4,7,3,quark:slate:1)
Block(-4,7,4,quark:slate:1)
Block(-4,7,5,quark:slate:1)
Block(-4,7,6,quark:slate:1)
Block(-4,7,7,quark:slate:1)
Block(-4,7,8,quark:slate:1)
Block(-4,8,-7,quark:slate:1)
Block(-4,8,-6,quark:slate:1)
Block(-4,8,-5,quark:slate:1)
Block(-4,8,-4,quark:slate:1)
Block(-4,8,-3,quark:slate:1)
Block(-4,8,-2,quark:slate:1)
Block(-4,8,-1,quark:slate:1)
Block(-4,8,0,quark:slate:1)
Block(-4,8,1,quark:slate:1)
Block(-4,8,2,quark:slate:1)
Block(-4,8,3,quark:slate:1)
Block(-4,8,4,quark:slate:1)
Block(-4,8,5,quark:slate:1)
Block(-4,8,6,quark:slate:1)
Block(-4,8,7,quark:slate:1)
Block(-4,8,8,quark:slate:1)
Block(-4,9,-7,quark:slate:1)
Block(-4,9,-6,quark:slate:1)
Block(-4,9,-5,quark:slate:1)
Block(-4,9,-4,quark:slate:1)
Block(-4,9,-3,quark:slate:1)
Block(-4,9,-2,quark:slate:1)
Block(-4,9,-1,quark:slate:1)
Block(-4,9,0,quark:slate:1)
Block(-4,9,1,quark:slate:1)
Block(-4,9,2,quark:slate:1)
Block(-4,9,3,quark:slate:1)
Block(-4,9,4,quark:slate:1)
Block(-4,9,5,quark:slate:1)
Block(-4,9,6,quark:slate:1)
Block(-4,9,7,quark:slate:1)
Block(-4,9,8,quark:slate:1)
Block(-4,10,-7,quark:slate:1)
Block(-4,10,-6,quark:slate:1)
Block(-4,10,-5,quark:slate:1)
Block(-4,10,-4,quark:slate:1)
Block(-4,10,-3,quark:slate:1)
Block(-4,10,-2,quark:slate:1)
Block(-4,10,-1,quark:slate:1)
Block(-4,10,0,quark:slate:1)
Block(-4,10,1,quark:slate:1)
Block(-4,10,2,quark:slate:1)
Block(-4,10,3,quark:slate:1)
Block(-4,10,4,quark:slate:1)
Block(-4,10,5,quark:slate:1)
Block(-4,10,6,quark:slate:1)
Block(-4,10,7,quark:slate:1)
Block(-4,10,8,quark:slate:1)
Block(-4,11,-7,quark:iron_plate)
Block(-4,11,-6,quark:iron_plate)
Block(-4,11,-5,quark:iron_plate)
Block(-4,11,-4,biomesoplenty:wood_slab_1:14)
Block(-4,11,-3,quark:iron_plate)
Block(-4,11,-2,quark:iron_plate)
Block(-4,11,-1,quark:iron_plate)
Block(-4,11,0,AIR:0)
Block(-4,11,1,AIR:0)
Block(-4,11,2,AIR:0)
Block(-4,11,3,AIR:0)
Block(-4,11,4,AIR:0)
Block(-4,11,5,AIR:0)
Block(-4,11,6,quark:iron_plate)
Block(-4,11,7,quark:iron_plate)
Block(-4,11,8,quark:iron_plate)
Block(-4,12,-7,quark:iron_plate)
Block(-4,12,-6,quark:iron_plate)
Block(-4,12,-5,quark:iron_plate)
Block(-4,12,-4,DARK_OAK_DOOR:2)
Block(-4,12,-3,quark:iron_plate)
Block(-4,12,-2,quark:iron_plate)
Block(-4,12,-1,quark:iron_plate)
Block(-4,12,0,AIR:0)
Block(-4,12,1,AIR:0)
Block(-4,12,2,quark:iron_plate_slab:8)
Block(-4,12,3,quark:iron_plate_slab:8)
Block(-4,12,4,AIR:0)
Block(-4,12,5,AIR:0)
Block(-4,12,6,quark:iron_plate)
Block(-4,12,7,quark:iron_plate)
Block(-4,12,8,quark:iron_plate)
Block(-4,13,-7,quark:slate:1)
Block(-4,13,-6,quark:slate:1)
Block(-4,13,-5,quark:slate:1)
Block(-4,13,-4,DARK_OAK_DOOR:8)
Block(-4,13,-3,quark:slate:1)
Block(-4,13,-2,quark:slate:1)
Block(-4,13,-1,quark:slate:1)
Block(-4,13,0,AIR:0)
Block(-4,13,1,rustic:iron_lattice:0)
Block(-4,13,2,AIR:0)
Block(-4,13,3,AIR:0)
Block(-4,13,4,rustic:iron_lattice:0)
Block(-4,13,5,AIR:0)
Block(-4,13,6,quark:slate:1)
Block(-4,13,7,quark:slate:1)
Block(-4,13,8,quark:slate:1)
Block(-4,14,-7,quark:slate:1)
Block(-4,14,-6,quark:slate:1)
Block(-4,14,-5,quark:slate:1)
Block(-4,14,-4,inspirations:carpeted_trapdoor_gray:14)
Block(-4,14,-3,quark:slate:1)
Block(-4,14,-2,quark:slate:1)
Block(-4,14,-1,quark:slate:1)
Block(-4,14,0,AIR:0)
Block(-4,14,1,AIR:0)
Block(-4,14,2,AIR:0)
Block(-4,14,3,AIR:0)
Block(-4,14,4,AIR:0)
Block(-4,14,5,AIR:0)
Block(-4,14,6,quark:slate:1)
Block(-4,14,7,quark:slate:1)
Block(-4,14,8,quark:slate:1)
Block(-4,15,-7,quark:slate:1)
Block(-4,15,-6,quark:slate:1)
Block(-4,15,-5,quark:slate:1)
Block(-4,15,-4,quark:slate:1)
Block(-4,15,-3,quark:slate:1)
Block(-4,15,-2,quark:slate:1)
Block(-4,15,-1,quark:slate:1)
Block(-4,15,0,AIR:0)
Block(-4,15,1,AIR:0)
Block(-4,15,2,AIR:0)
Block(-4,15,3,AIR:0)
Block(-4,15,4,AIR:0)
Block(-4,15,5,AIR:0)
Block(-4,15,6,quark:slate:1)
Block(-4,15,7,quark:slate:1)
Block(-4,15,8,quark:slate:1)
Block(-4,16,-7,quark:slate:1)
Block(-4,16,-6,quark:slate:1)
Block(-4,16,-5,quark:slate:1)
Block(-4,16,-4,quark:slate:1)
Block(-4,16,-3,quark:slate:1)
Block(-4,16,-2,quark:slate:1)
Block(-4,16,-1,quark:slate:1)
Block(-4,16,0,biomesoplenty:wood_slab_1:14)
Block(-4,16,1,biomesoplenty:wood_slab_1:14)
Block(-4,16,2,biomesoplenty:wood_slab_1:14)
Block(-4,16,3,biomesoplenty:wood_slab_1:14)
Block(-4,16,4,biomesoplenty:wood_slab_1:14)
Block(-4,16,5,biomesoplenty:wood_slab_1:14)
Block(-4,16,6,quark:slate:1)
Block(-4,16,7,quark:slate:1)
Block(-4,16,8,quark:slate:1)
Block(-4,17,-7,CONCRETE:7)
Block(-4,17,-6,CONCRETE:7)
Block(-4,17,-5,CONCRETE:7)
Block(-4,17,-4,CONCRETE:7)
Block(-4,17,-3,CONCRETE:7)
Block(-4,17,-2,CONCRETE:7)
Block(-4,17,-1,CONCRETE:7)
Block(-4,17,0,CONCRETE:7)
Block(-4,17,1,CONCRETE:7)
Block(-4,17,2,CONCRETE:7)
Block(-4,17,3,CONCRETE:7)
Block(-4,17,4,CONCRETE:7)
Block(-4,17,5,CONCRETE:7)
Block(-4,17,6,CONCRETE:7)
Block(-4,17,7,CONCRETE:7)
Block(-4,17,8,CONCRETE:7)
Block(-4,18,-7,inspirations:path)
Block(-4,18,-6,quark:polished_stone)
Block(-4,18,-5,AIR:0)
Block(-4,18,-4,AIR:0)
Block(-4,18,-3,AIR:0)
Block(-4,18,-2,AIR:0)
Block(-4,18,-1,AIR:0)
Block(-4,18,0,inspirations:path)
Block(-4,18,1,AIR:0)
Block(-4,18,2,AIR:0)
Block(-4,18,3,AIR:0)
Block(-4,18,4,inspirations:path)
Block(-4,18,5,inspirations:path)
Block(-4,18,6,AIR:0)
Block(-4,18,7,AIR:0)
Block(-4,18,8,AIR:0)
Block(-4,19,-7,AIR:0)
Block(-4,19,-6,inspirations:redstone_barrel)
Block(-4,19,-5,AIR:0)
Block(-4,19,-4,AIR:0)
Block(-4,19,-3,AIR:0)
Block(-4,19,-2,AIR:0)
Block(-4,19,-1,AIR:0)
Block(-4,19,0,AIR:0)
Block(-4,19,1,AIR:0)
Block(-4,19,2,AIR:0)
Block(-4,19,3,AIR:0)
Block(-4,19,4,AIR:0)
Block(-4,19,5,AIR:0)
Block(-4,19,6,AIR:0)
Block(-4,19,7,AIR:0)
Block(-4,19,8,AIR:0)
Block(-4,20,-7,AIR:0)
Block(-4,20,-6,inspirations:redstone_barrel)
Block(-4,20,-5,AIR:0)
Block(-4,20,-4,AIR:0)
Block(-4,20,-3,AIR:0)
Block(-4,20,-2,AIR:0)
Block(-4,20,-1,AIR:0)
Block(-4,20,0,AIR:0)
Block(-4,20,1,AIR:0)
Block(-4,20,2,AIR:0)
Block(-4,20,3,AIR:0)
Block(-4,20,4,AIR:0)
Block(-4,20,6,AIR:0)
Block(-4,20,7,AIR:0)
Block(-4,20,8,AIR:0)
Block(-4,21,-7,AIR:0)
Block(-4,21,-6,inspirations:redstone_barrel)
Block(-4,21,-5,AIR:0)
Block(-4,21,-4,AIR:0)
Block(-4,21,-3,AIR:0)
Block(-4,21,-2,AIR:0)
Block(-4,21,-1,AIR:0)
Block(-4,21,0,AIR:0)
Block(-4,21,1,AIR:0)
Block(-4,21,2,AIR:0)
Block(-4,21,3,AIR:0)
Block(-4,21,4,AIR:0)
Block(-4,21,5,AIR:0)
Block(-4,21,6,AIR:0)
Block(-4,21,7,AIR:0)
Block(-4,21,8,AIR:0)
Block(-4,22,-7,AIR:0)
Block(-4,22,-6,STEP:0)
Block(-4,22,-5,STEP:0)
Block(-4,22,-4,STEP:0)
Block(-4,22,-3,STEP:0)
Block(-4,22,-2,STEP:0)
Block(-4,22,-1,STEP:0)
Block(-4,22,0,STEP:0)
Block(-4,22,1,STEP:0)
Block(-4,22,2,STEP:0)
Block(-4,22,3,STEP:0)
Block(-4,22,4,STEP:0)
Block(-4,22,5,STEP:0)
Block(-4,22,6,STEP:0)
Block(-4,22,7,STEP:0)
Block(-4,22,8,STEP:0)
Block(-4,23,-7,quark:iron_plate)
Block(-4,23,-6,quark:iron_plate)
Block(-4,23,-5,quark:iron_plate)
Block(-4,23,-4,quark:iron_plate)
Block(-4,23,-3,quark:iron_plate)
Block(-4,23,-2,quark:iron_plate)
Block(-4,23,-1,quark:iron_plate)
Block(-4,23,0,quark:iron_plate)
Block(-4,23,1,quark:iron_plate)
Block(-4,23,2,quark:iron_plate)
Block(-4,23,3,quark:iron_plate)
Block(-4,23,4,quark:iron_plate)
Block(-4,23,5,quark:iron_plate)
Block(-4,23,6,quark:iron_plate)
Block(-4,23,7,quark:iron_plate)
Block(-4,23,8,quark:iron_plate)
Block(-4,24,-7,quark:iron_plate)
Block(-4,24,-6,quark:iron_plate)
Block(-4,24,-5,quark:iron_plate)
Block(-4,24,-4,quark:iron_plate)
Block(-4,24,-3,quark:iron_plate)
Block(-4,24,-2,quark:iron_plate)
Block(-4,24,-1,quark:iron_plate)
Block(-4,24,0,quark:iron_plate)
Block(-4,24,1,PRISMARINE:2)
Block(-4,24,2,quark:iron_plate)
Block(-4,24,3,quark:iron_plate)
Block(-4,24,4,PRISMARINE:2)
Block(-4,24,5,quark:iron_plate)
Block(-4,24,6,quark:iron_plate)
Block(-4,24,7,quark:iron_plate)
Block(-4,24,8,quark:iron_plate)
Block(-4,25,1,PRISMARINE:2)
Block(-4,25,4,PRISMARINE:2)
Block(-3,2,-7,quark:slate:1)
Block(-3,2,-6,quark:slate:1)
Block(-3,2,-5,quark:slate:1)
Block(-3,2,-4,quark:slate:1)
Block(-3,2,-3,quark:slate:1)
Block(-3,2,-2,quark:slate:1)
Block(-3,2,-1,quark:slate:1)
Block(-3,2,0,quark:slate:1)
Block(-3,2,1,quark:slate:1)
Block(-3,2,2,quark:slate:1)
Block(-3,2,3,quark:slate:1)
Block(-3,2,4,quark:slate:1)
Block(-3,2,5,quark:slate:1)
Block(-3,2,6,quark:slate:1)
Block(-3,2,7,quark:slate:1)
Block(-3,2,8,quark:slate:1)
Block(-3,3,-7,quark:slate:1)
Block(-3,3,-6,quark:slate:1)
Block(-3,3,-5,quark:slate:1)
Block(-3,3,-4,quark:slate:1)
Block(-3,3,-3,quark:slate:1)
Block(-3,3,-2,quark:slate:1)
Block(-3,3,-1,quark:slate:1)
Block(-3,3,0,quark:slate:1)
Block(-3,3,1,quark:slate:1)
Block(-3,3,2,quark:slate:1)
Block(-3,3,3,quark:slate:1)
Block(-3,3,4,quark:slate:1)
Block(-3,3,5,quark:slate:1)
Block(-3,3,6,quark:slate:1)
Block(-3,3,7,quark:slate:1)
Block(-3,3,8,quark:slate:1)
Block(-3,4,-7,quark:slate:1)
Block(-3,4,-6,quark:slate:1)
Block(-3,4,-5,quark:slate:1)
Block(-3,4,-4,quark:slate:1)
Block(-3,4,-3,quark:slate:1)
Block(-3,4,-2,quark:slate:1)
Block(-3,4,-1,quark:slate:1)
Block(-3,4,0,quark:slate:1)
Block(-3,4,1,quark:slate:1)
Block(-3,4,2,quark:slate:1)
Block(-3,4,3,quark:slate:1)
Block(-3,4,4,quark:slate:1)
Block(-3,4,5,quark:slate:1)
Block(-3,4,6,quark:slate:1)
Block(-3,4,7,quark:slate:1)
Block(-3,4,8,quark:slate:1)
Block(-3,5,-7,quark:slate:1)
Block(-3,5,-6,quark:slate:1)
Block(-3,5,-5,quark:slate:1)
Block(-3,5,-4,quark:slate:1)
Block(-3,5,-3,quark:slate:1)
Block(-3,5,-2,quark:slate:1)
Block(-3,5,-1,quark:slate:1)
Block(-3,5,0,quark:slate:1)
Block(-3,5,1,quark:slate:1)
Block(-3,5,2,quark:slate:1)
Block(-3,5,3,quark:slate:1)
Block(-3,5,4,quark:slate:1)
Block(-3,5,5,quark:slate:1)
Block(-3,5,6,quark:slate:1)
Block(-3,5,7,quark:slate:1)
Block(-3,5,8,quark:slate:1)
Block(-3,6,-7,quark:slate:1)
Block(-3,6,-6,quark:slate:1)
Block(-3,6,-5,quark:slate:1)
Block(-3,6,-4,quark:slate:1)
Block(-3,6,-3,quark:slate:1)
Block(-3,6,-2,quark:slate:1)
Block(-3,6,-1,quark:slate:1)
Block(-3,6,0,quark:slate:1)
Block(-3,6,1,quark:slate:1)
Block(-3,6,2,quark:slate:1)
Block(-3,6,3,quark:slate:1)
Block(-3,6,4,quark:slate:1)
Block(-3,6,5,quark:slate:1)
Block(-3,6,6,quark:slate:1)
Block(-3,6,7,quark:slate:1)
Block(-3,6,8,quark:slate:1)
Block(-3,7,-7,quark:slate:1)
Block(-3,7,-6,quark:slate:1)
Block(-3,7,-5,quark:slate:1)
Block(-3,7,-4,quark:slate:1)
Block(-3,7,-3,quark:slate:1)
Block(-3,7,-2,quark:slate:1)
Block(-3,7,-1,quark:slate:1)
Block(-3,7,0,quark:slate:1)
Block(-3,7,1,quark:slate:1)
Block(-3,7,2,quark:slate:1)
Block(-3,7,3,quark:slate:1)
Block(-3,7,4,quark:slate:1)
Block(-3,7,5,quark:slate:1)
Block(-3,7,6,quark:slate:1)
Block(-3,7,7,quark:slate:1)
Block(-3,7,8,quark:slate:1)
Block(-3,8,-7,quark:slate:1)
Block(-3,8,-6,quark:slate:1)
Block(-3,8,-5,quark:slate:1)
Block(-3,8,-4,quark:slate:1)
Block(-3,8,-3,quark:slate:1)
Block(-3,8,-2,quark:slate:1)
Block(-3,8,-1,quark:slate:1)
Block(-3,8,0,quark:slate:1)
Block(-3,8,1,quark:slate:1)
Block(-3,8,2,quark:slate:1)
Block(-3,8,3,quark:slate:1)
Block(-3,8,4,quark:slate:1)
Block(-3,8,5,quark:slate:1)
Block(-3,8,6,quark:slate:1)
Block(-3,8,7,quark:slate:1)
Block(-3,8,8,quark:slate:1)
Block(-3,9,-7,quark:slate:1)
Block(-3,9,-6,quark:slate:1)
Block(-3,9,-5,quark:slate:1)
Block(-3,9,-4,quark:slate:1)
Block(-3,9,-3,quark:slate:1)
Block(-3,9,-2,quark:slate:1)
Block(-3,9,-1,quark:slate:1)
Block(-3,9,0,quark:slate:1)
Block(-3,9,1,quark:slate:1)
Block(-3,9,2,quark:slate:1)
Block(-3,9,3,quark:slate:1)
Block(-3,9,4,quark:slate:1)
Block(-3,9,5,quark:slate:1)
Block(-3,9,6,quark:slate:1)
Block(-3,9,7,quark:slate:1)
Block(-3,9,8,quark:slate:1)
Block(-3,10,-7,quark:slate:1)
Block(-3,10,-6,quark:slate:1)
Block(-3,10,-5,quark:slate:1)
Block(-3,10,-4,quark:slate:1)
Block(-3,10,-3,quark:slate:1)
Block(-3,10,-2,quark:slate:1)
Block(-3,10,-1,quark:slate:1)
Block(-3,10,0,quark:slate:1)
Block(-3,10,1,quark:slate:1)
Block(-3,10,2,quark:slate:1)
Block(-3,10,3,quark:slate:1)
Block(-3,10,4,quark:slate:1)
Block(-3,10,5,quark:slate:1)
Block(-3,10,6,quark:slate:1)
Block(-3,10,7,quark:slate:1)
Block(-3,10,8,quark:slate:1)
Block(-3,11,-7,biomesoplenty:wood_slab_1:14)
Block(-3,11,-6,biomesoplenty:wood_slab_1:14)
Block(-3,11,-5,biomesoplenty:wood_slab_1:14)
Block(-3,11,-4,biomesoplenty:wood_slab_1:14)
Block(-3,11,-3,biomesoplenty:wood_slab_1:14)
Block(-3,11,-2,biomesoplenty:wood_slab_1:14)
Block(-3,11,-1,biomesoplenty:wood_slab_1:14)
Block(-3,11,0,CONCRETE:7)
Block(-3,11,1,quark:iron_plate)
Block(-3,11,2,AIR:0)
Block(-3,11,3,AIR:0)
Block(-3,11,4,quark:iron_plate)
Block(-3,11,5,CONCRETE:7)
Block(-3,11,6,biomesoplenty:wood_slab_1:14)
Block(-3,11,7,biomesoplenty:wood_slab_1:14)
Block(-3,11,8,biomesoplenty:wood_slab_1:14)
Block(-3,12,-7,quark:iron_plate)
Block(-3,12,-6,BED_BLOCK:9)
Block(-3,12,-5,CARPET:15)
Block(-3,12,-4,AIR:0)
Block(-3,12,-3,CARPET:15)
Block(-3,12,-2,BED_BLOCK:9)
Block(-3,12,-1,quark:iron_plate)
Block(-3,12,0,CONCRETE:7)
Block(-3,12,1,quark:iron_plate)
Block(-3,12,2,quark:iron_plate_slab:8)
Block(-3,12,3,quark:iron_plate_slab:8)
Block(-3,12,4,quark:iron_plate)
Block(-3,12,5,CONCRETE:7)
Block(-3,12,6,quark:iron_plate)
Block(-3,12,8,AIR:0)
Block(-3,13,-7,quark:slate:1)
Block(-3,13,-6,BED_BLOCK:9)
Block(-3,13,-5,quark:grate)
Block(-3,13,-4,quark:grate)
Block(-3,13,-3,quark:grate)
Block(-3,13,-2,BED_BLOCK:9)
Block(-3,13,-1,quark:slate:1)
Block(-3,13,0,CONCRETE:7)
Block(-3,13,1,quark:iron_plate)
Block(-3,13,2,AIR:0)
Block(-3,13,3,AIR:0)
Block(-3,13,4,quark:iron_plate)
Block(-3,13,5,CONCRETE:7)
Block(-3,13,6,quark:slate:1)
Block(-3,13,7,WOOD_PLATE:0)
Block(-3,13,8,AIR:0)
Block(-3,14,-7,quark:slate:1)
Block(-3,14,-6,BED_BLOCK:9)
Block(-3,14,-5,rustic:iron_lattice:0)
RandomBlock(-3,14,-4,CHEST:5,../../../../Chests/Loot/moderncity_junk_loot.nbt,20,CHEST:5../../../../Chests/Loot/moderncity_rare_loot.nbt,10,CHEST:5,../../../../Chests/RLCraft/Ruins/industrial.nbt,20,CHEST:5,../../../../Chests/RLCraft/Ruins/consumables.nbt,20,CHEST:5,../../../../Chests/Loot/stronghold_corridor.nbt,20,CHEST:5,../../../../Chests/Loot/stronghold_crossing.nbt,20,CHEST:5,../../../../Chests/Loot/desert_pyramid.nbt,30,CHEST:5,../../../../Chests/Loot/simple_dungeon.nbt,100)
Block(-3,14,-3,rustic:iron_lattice:0)
Block(-3,14,-2,BED_BLOCK:9)
Block(-3,14,-1,quark:slate:1)
Block(-3,14,0,CONCRETE:7)
Block(-3,14,1,quark:iron_plate)
Block(-3,14,2,AIR:0)
Block(-3,14,3,AIR:0)
Block(-3,14,4,quark:iron_plate)
Block(-3,14,5,CONCRETE:7)
Block(-3,14,6,quark:slate:1)
Block(-3,14,7,AIR:0)
Block(-3,14,8,AIR:0)
Block(-3,15,-7,quark:slate:1)
Block(-3,15,-6,BED_BLOCK:9)
Block(-3,15,-5,rustic:iron_lattice:0)
Block(-3,15,-4,AIR:0)
Block(-3,15,-3,rustic:iron_lattice:0)
Block(-3,15,-2,BED_BLOCK:9)
Block(-3,15,-1,quark:slate:1)
Block(-3,15,0,CONCRETE:7)
Block(-3,15,1,quark:iron_plate)
Block(-3,15,2,AIR:0)
Block(-3,15,3,AIR:0)
Block(-3,15,4,quark:iron_plate)
Block(-3,15,5,CONCRETE:7)
Block(-3,15,6,quark:slate:1)
Block(-3,15,7,AIR:0)
Block(-3,15,8,AIR:0)
Block(-3,16,-7,quark:slate:1)
Block(-3,16,-6,quark:blaze_lantern)
Block(-3,16,-5,SANDSTONE_STAIRS:5)
Block(-3,16,-4,SANDSTONE_STAIRS:5)
Block(-3,16,-3,SANDSTONE_STAIRS:5)
Block(-3,16,-2,quark:blaze_lantern)
Block(-3,16,-1,quark:slate:1)
Block(-3,16,0,CONCRETE:7)
Block(-3,16,1,quark:iron_plate)
Block(-3,16,2,biomesoplenty:wood_slab_1:14)
Block(-3,16,3,biomesoplenty:wood_slab_1:14)
Block(-3,16,4,quark:iron_plate)
Block(-3,16,5,CONCRETE:7)
Block(-3,16,6,quark:slate:1)
Block(-3,16,7,AIR:0)
Block(-3,16,8,AIR:0)
Block(-3,17,-7,CONCRETE:7)
Block(-3,17,-6,quark:iron_plate:1)
Block(-3,17,-5,quark:iron_plate:1)
Block(-3,17,-4,quark:iron_plate:1)
Block(-3,17,-3,quark:iron_plate:1)
Block(-3,17,-2,quark:iron_plate:1)
Block(-3,17,-1,CONCRETE:7)
Block(-3,17,0,CONCRETE:7)
Block(-3,17,1,CONCRETE:7)
Block(-3,17,2,CONCRETE:7)
Block(-3,17,3,CONCRETE:7)
Block(-3,17,4,CONCRETE:7)
Block(-3,17,5,CONCRETE:7)
Block(-3,17,6,CONCRETE:7)
Block(-3,17,7,quark:iron_plate:1)
Block(-3,17,8,quark:iron_plate:1)
Block(-3,18,-7,inspirations:path)
Block(-3,18,-6,STEP:0)
Block(-3,18,-5,AIR:0)
Block(-3,18,-4,AIR:0)
Block(-3,18,-3,AIR:0)
Block(-3,18,-2,BROWN_MUSHROOM:0)
Block(-3,18,-1,inspirations:path)
Block(-3,18,0,CONCRETE:7)
Block(-3,18,1,CONCRETE:7)
Block(-3,18,2,CONCRETE:7)
Block(-3,18,3,CONCRETE:7)
Block(-3,18,4,CONCRETE:7)
Block(-3,18,5,CONCRETE:7)
Block(-3,18,6,BROWN_MUSHROOM:0)
Block(-3,18,7,AIR:0)
Block(-3,18,8,AIR:0)
Block(-3,19,-7,AIR:0)
Block(-3,19,-6,AIR:0)
Block(-3,19,-5,AIR:0)
Block(-3,19,-4,AIR:0)
Block(-3,19,-3,AIR:0)
Block(-3,19,-2,AIR:0)
Block(-3,19,-1,AIR:0)
Block(-3,19,0,CONCRETE:7)
Block(-3,19,1,CONCRETE:7)
Block(-3,19,2,quark:dark_oak_trapdoor:6)
Block(-3,19,3,quark:dark_oak_trapdoor:6)
Block(-3,19,4,CONCRETE:7)
Block(-3,19,5,CONCRETE:7)
Block(-3,19,6,AIR:0)
Block(-3,19,7,AIR:0)
Block(-3,19,8,AIR:0)
Block(-3,20,-7,AIR:0)
Block(-3,20,-6,AIR:0)
Block(-3,20,-5,AIR:0)
Block(-3,20,-4,AIR:0)
Block(-3,20,-3,AIR:0)
Block(-3,20,-2,AIR:0)
Block(-3,20,-1,AIR:0)
Block(-3,20,0,CONCRETE:7)
Block(-3,20,1,CONCRETE:7)
Block(-3,20,2,CONCRETE:7)
Block(-3,20,3,CONCRETE:7)
Block(-3,20,4,CONCRETE:7)
Block(-3,20,5,CONCRETE:7)
Block(-3,20,6,AIR:0)
Block(-3,20,7,AIR:0)
Block(-3,20,8,AIR:0)
Block(-3,21,-7,AIR:0)
Block(-3,21,-6,AIR:0)
Block(-3,21,-5,AIR:0)
Block(-3,21,-4,AIR:0)
Block(-3,21,-3,AIR:0)
Block(-3,21,-2,AIR:0)
Block(-3,21,-1,AIR:0)
Block(-3,21,0,CONCRETE:7)
Block(-3,21,1,CONCRETE:7)
Block(-3,21,2,CONCRETE:7)
Block(-3,21,3,CONCRETE:7)
Block(-3,21,4,CONCRETE:7)
Block(-3,21,5,CONCRETE:7)
Block(-3,21,6,AIR:0)
Block(-3,21,7,AIR:0)
Block(-3,21,8,AIR:0)
Block(-3,22,-7,quark:stone_slate_bricks_stairs:4)
Block(-3,22,-6,quark:stone_slate_bricks_stairs:4)
Block(-3,22,-5,quark:stone_slate_bricks_stairs:4)
Block(-3,22,-4,quark:stone_slate_bricks_stairs:4)
Block(-3,22,-3,quark:stone_slate_bricks_stairs:4)
Block(-3,22,-2,quark:stone_slate_bricks_stairs:4)
Block(-3,22,-1,quark:stone_slate_bricks_stairs:4)
Block(-3,22,0,CONCRETE:7)
Block(-3,22,1,CONCRETE:7)
Block(-3,22,2,CONCRETE:7)
Block(-3,22,3,CONCRETE:7)
Block(-3,22,4,CONCRETE:7)
Block(-3,22,5,CONCRETE:7)
Block(-3,22,6,quark:stone_slate_bricks_stairs:4)
Block(-3,22,7,quark:stone_slate_bricks_stairs:4)
Block(-3,22,8,quark:stone_slate_bricks_stairs:4)
Block(-3,23,-7,quark:slate:1)
Block(-3,23,-6,quark:slate:1)
Block(-3,23,-5,quark:slate:1)
Block(-3,23,-4,quark:slate:1)
Block(-3,23,-3,quark:slate:1)
Block(-3,23,-2,quark:slate:1)
Block(-3,23,-1,quark:slate:1)
Block(-3,23,0,CONCRETE:7)
Block(-3,23,1,CONCRETE:7)
Block(-3,23,2,CONCRETE:7)
Block(-3,23,3,CONCRETE:7)
Block(-3,23,4,CONCRETE:7)
Block(-3,23,5,CONCRETE:7)
Block(-3,23,6,quark:slate:1)
Block(-3,23,7,quark:slate:1)
Block(-3,23,8,quark:slate:1)
Block(-3,24,0,quark:slate:1)
Block(-3,24,1,CONCRETE:7)
Block(-3,24,2,quark:slate:1)
Block(-3,24,3,quark:slate:1)
Block(-3,24,4,CONCRETE:7)
Block(-3,24,5,quark:slate:1)
Block(-3,25,1,PRISMARINE:2)
Block(-3,25,4,PRISMARINE:2)
Block(-2,2,-7,quark:slate:1)
Block(-2,2,-6,quark:slate:1)
Block(-2,2,-5,quark:slate:1)
Block(-2,2,-4,quark:slate:1)
Block(-2,2,-3,quark:slate:1)
Block(-2,2,-2,quark:slate:1)
Block(-2,2,-1,quark:slate:1)
Block(-2,2,0,quark:slate:1)
Block(-2,2,1,quark:slate:1)
Block(-2,2,2,quark:slate:1)
Block(-2,2,3,quark:slate:1)
Block(-2,2,4,quark:slate:1)
Block(-2,2,5,quark:slate:1)
Block(-2,2,6,quark:slate:1)
Block(-2,2,7,quark:slate:1)
Block(-2,2,8,quark:slate:1)
Block(-2,3,-7,quark:slate:1)
Block(-2,3,-6,quark:slate:1)
Block(-2,3,-5,quark:slate:1)
Block(-2,3,-4,quark:slate:1)
Block(-2,3,-3,quark:slate:1)
Block(-2,3,-2,quark:slate:1)
Block(-2,3,-1,quark:slate:1)
Block(-2,3,0,quark:slate:1)
Block(-2,3,1,quark:slate:1)
Block(-2,3,2,quark:slate:1)
Block(-2,3,3,quark:slate:1)
Block(-2,3,4,quark:slate:1)
Block(-2,3,5,quark:slate:1)
Block(-2,3,6,quark:slate:1)
Block(-2,3,7,quark:slate:1)
Block(-2,3,8,quark:slate:1)
Block(-2,4,-7,quark:slate:1)
Block(-2,4,-6,quark:slate:1)
Block(-2,4,-5,quark:slate:1)
Block(-2,4,-4,quark:slate:1)
Block(-2,4,-3,quark:slate:1)
Block(-2,4,-2,quark:slate:1)
Block(-2,4,-1,quark:slate:1)
Block(-2,4,0,quark:slate:1)
Block(-2,4,1,quark:slate:1)
Block(-2,4,2,quark:slate:1)
Block(-2,4,3,quark:slate:1)
Block(-2,4,4,quark:slate:1)
Block(-2,4,5,quark:slate:1)
Block(-2,4,6,quark:slate:1)
Block(-2,4,7,quark:slate:1)
Block(-2,4,8,quark:slate:1)
Block(-2,5,-7,quark:slate:1)
Block(-2,5,-6,quark:slate:1)
Block(-2,5,-5,quark:slate:1)
Block(-2,5,-4,quark:slate:1)
Block(-2,5,-3,quark:slate:1)
Block(-2,5,-2,quark:slate:1)
Block(-2,5,-1,quark:slate:1)
Block(-2,5,0,quark:slate:1)
Block(-2,5,1,quark:slate:1)
Block(-2,5,2,quark:slate:1)
Block(-2,5,3,quark:slate:1)
Block(-2,5,4,quark:slate:1)
Block(-2,5,5,quark:slate:1)
Block(-2,5,6,quark:slate:1)
Block(-2,5,7,quark:slate:1)
Block(-2,5,8,quark:slate:1)
Block(-2,6,-7,quark:slate:1)
Block(-2,6,-6,quark:slate:1)
Block(-2,6,-5,quark:slate:1)
Block(-2,6,-4,quark:slate:1)
Block(-2,6,-3,quark:slate:1)
Block(-2,6,-2,quark:slate:1)
Block(-2,6,-1,quark:slate:1)
Block(-2,6,0,quark:slate:1)
Block(-2,6,1,quark:slate:1)
Block(-2,6,2,quark:slate:1)
Block(-2,6,3,quark:slate:1)
Block(-2,6,4,quark:slate:1)
Block(-2,6,5,quark:slate:1)
Block(-2,6,6,quark:slate:1)
Block(-2,6,7,quark:slate:1)
Block(-2,6,8,quark:slate:1)
Block(-2,7,-7,quark:slate:1)
Block(-2,7,-6,quark:slate:1)
Block(-2,7,-5,quark:slate:1)
Block(-2,7,-4,quark:slate:1)
Block(-2,7,-3,quark:slate:1)
Block(-2,7,-2,quark:slate:1)
Block(-2,7,-1,quark:slate:1)
Block(-2,7,0,quark:slate:1)
Block(-2,7,1,quark:slate:1)
Block(-2,7,2,quark:slate:1)
Block(-2,7,3,quark:slate:1)
Block(-2,7,4,quark:slate:1)
Block(-2,7,5,quark:slate:1)
Block(-2,7,6,quark:slate:1)
Block(-2,7,7,quark:slate:1)
Block(-2,7,8,quark:slate:1)
Block(-2,8,-7,quark:slate:1)
Block(-2,8,-6,quark:slate:1)
Block(-2,8,-5,quark:slate:1)
Block(-2,8,-4,quark:slate:1)
Block(-2,8,-3,quark:slate:1)
Block(-2,8,-2,quark:slate:1)
Block(-2,8,-1,quark:slate:1)
Block(-2,8,0,quark:slate:1)
Block(-2,8,1,quark:slate:1)
Block(-2,8,2,quark:slate:1)
Block(-2,8,3,quark:slate:1)
Block(-2,8,4,quark:slate:1)
Block(-2,8,5,quark:slate:1)
Block(-2,8,6,quark:slate:1)
Block(-2,8,7,quark:slate:1)
Block(-2,8,8,quark:slate:1)
Block(-2,9,-7,quark:slate:1)
Block(-2,9,-6,quark:slate:1)
Block(-2,9,-5,quark:slate:1)
Block(-2,9,-4,quark:slate:1)
Block(-2,9,-3,quark:slate:1)
Block(-2,9,-2,quark:slate:1)
Block(-2,9,-1,quark:slate:1)
Block(-2,9,0,quark:slate:1)
Block(-2,9,1,quark:slate:1)
Block(-2,9,2,quark:slate:1)
Block(-2,9,3,quark:slate:1)
Block(-2,9,4,quark:slate:1)
Block(-2,9,5,quark:slate:1)
Block(-2,9,6,quark:slate:1)
Block(-2,9,7,quark:slate:1)
Block(-2,9,8,quark:slate:1)
Block(-2,10,-7,quark:slate:1)
Block(-2,10,-6,quark:slate:1)
Block(-2,10,-5,quark:slate:1)
Block(-2,10,-4,quark:slate:1)
Block(-2,10,-3,quark:slate:1)
Block(-2,10,-2,quark:slate:1)
Block(-2,10,-1,quark:slate:1)
Block(-2,10,0,quark:slate:1)
Block(-2,10,1,quark:slate:1)
Block(-2,10,2,quark:slate:1)
Block(-2,10,3,quark:slate:1)
Block(-2,10,4,quark:slate:1)
Block(-2,10,5,quark:slate:1)
Block(-2,10,6,quark:slate:1)
Block(-2,10,7,quark:slate:1)
Block(-2,10,8,quark:slate:1)
Block(-2,11,-7,biomesoplenty:wood_slab_1:14)
Block(-2,11,-6,biomesoplenty:wood_slab_1:14)
Block(-2,11,-5,biomesoplenty:wood_slab_1:14)
Block(-2,11,-4,biomesoplenty:wood_slab_1:14)
Block(-2,11,-3,biomesoplenty:wood_slab_1:14)
Block(-2,11,-2,biomesoplenty:wood_slab_1:14)
Block(-2,11,-1,biomesoplenty:wood_slab_1:14)
Block(-2,11,0,REDSTONE_WIRE:0)
Block(-2,11,1,OBSERVER:2)
Block(-2,11,2,OBSERVER:2)
Block(-2,11,3,OBSERVER:2)
Block(-2,11,4,OBSERVER:2)
Block(-2,11,5,REDSTONE_WIRE:0)
Block(-2,11,6,biomesoplenty:wood_slab_1:14)
Block(-2,11,7,biomesoplenty:wood_slab_1:14)
Block(-2,11,8,biomesoplenty:wood_slab_1:14)
Block(-2,12,-7,quark:iron_plate)
Block(-2,12,-6,BED_BLOCK:1)
Block(-2,12,-5,CARPET:15)
Block(-2,12,-4,CARPET:15)
Block(-2,12,-3,CARPET:15)
Block(-2,12,-2,BED_BLOCK:1)
Block(-2,12,-1,quark:iron_plate)
Block(-2,12,0,AIR:0)
Block(-2,12,1,quark:iron_plate)
Block(-2,12,2,quark:iron_plate)
Block(-2,12,3,quark:iron_plate)
Block(-2,12,4,quark:iron_plate)
Block(-2,12,5,AIR:0)
Block(-2,12,6,quark:iron_plate)
Block(-2,12,7,FURNACE:3)
Block(-2,12,8,AIR:0)
Block(-2,13,-7,quark:slate:1)
Block(-2,13,-6,BED_BLOCK:1)
Block(-2,13,-5,quark:grate)
Block(-2,13,-4,quark:grate)
Block(-2,13,-3,quark:grate)
Block(-2,13,-2,BED_BLOCK:1)
Block(-2,13,-1,quark:slate:1)
Block(-2,13,0,PISTON_STICKY_BASE:3)
Block(-2,13,1,quark:iron_plate)
Block(-2,13,2,AIR:0)
Block(-2,13,3,AIR:0)
Block(-2,13,4,quark:iron_plate)
Block(-2,13,5,PISTON_STICKY_BASE:2)
Block(-2,13,6,quark:slate:1)
Block(-2,13,7,IRON_TRAPDOOR:1)
Block(-2,13,8,AIR:0)
Block(-2,14,-7,quark:slate:1)
Block(-2,14,-6,BED_BLOCK:1)
Block(-2,14,-5,CARPET:15)
Block(-2,14,-4,CARPET:15)
Block(-2,14,-3,CARPET:15)
Block(-2,14,-2,BED_BLOCK:1)
Block(-2,14,-1,quark:slate:1)
Block(-2,14,0,PISTON_STICKY_BASE:3)
Block(-2,14,1,quark:iron_plate)
Block(-2,14,2,AIR:0)
Block(-2,14,3,AIR:0)
Block(-2,14,4,quark:iron_plate)
Block(-2,14,5,PISTON_STICKY_BASE:2)
Block(-2,14,6,quark:slate:1)
Block(-2,14,7,quark:iron_plate_stairs:0)
Block(-2,14,8,AIR:0)
Block(-2,15,-7,quark:slate:1)
Block(-2,15,-6,BED_BLOCK:1)
Block(-2,15,-5,AIR:0)
Block(-2,15,-4,AIR:0)
Block(-2,15,-3,AIR:0)
Block(-2,15,-2,BED_BLOCK:1)
Block(-2,15,-1,quark:slate:1)
Block(-2,15,0,PISTON_STICKY_BASE:3)
Block(-2,15,1,quark:iron_plate)
Block(-2,15,2,AIR:0)
Block(-2,15,3,AIR:0)
Block(-2,15,4,quark:iron_plate)
Block(-2,15,5,PISTON_STICKY_BASE:2)
Block(-2,15,6,quark:slate:1)
Block(-2,15,7,AIR:0)
Block(-2,15,8,AIR:0)
Block(-2,16,-7,quark:slate:1)
Block(-2,16,-6,SANDSTONE_STAIRS:7)
Block(-2,16,-5,AIR:0)
Block(-2,16,-4,AIR:0)
Block(-2,16,-3,AIR:0)
Block(-2,16,-2,SANDSTONE_STAIRS:6)
Block(-2,16,-1,quark:slate:1)
Block(-2,16,0,STEP:8)
Block(-2,16,1,quark:iron_plate)
Block(-2,16,2,quark:iron_plate)
Block(-2,16,3,quark:iron_plate)
Block(-2,16,4,quark:iron_plate)
Block(-2,16,5,STEP:8)
Block(-2,16,6,quark:slate:1)
Block(-2,16,7,AIR:0)
Block(-2,16,8,AIR:0)
Block(-2,17,-7,CONCRETE:7)
Block(-2,17,-6,quark:iron_plate:1)
Block(-2,17,-5,quark:framed_glass)
Block(-2,17,-4,quark:framed_glass)
Block(-2,17,-3,quark:framed_glass)
Block(-2,17,-2,quark:iron_plate:1)
Block(-2,17,-1,CONCRETE:7)
Block(-2,17,0,CONCRETE:7)
Block(-2,17,1,CONCRETE:7)
Block(-2,17,2,DISPENSER:1)
Block(-2,17,3,DISPENSER:1)
Block(-2,17,4,CONCRETE:7)
Block(-2,17,5,CONCRETE:7)
Block(-2,17,6,CONCRETE:7)
Block(-2,17,7,quark:iron_plate:1)
Block(-2,17,8,quark:framed_glass)
Block(-2,18,-7,inspirations:path)
Block(-2,18,-6,STEP:0)
Block(-2,18,-5,AIR:0)
Block(-2,18,-4,AIR:0)
Block(-2,18,-3,AIR:0)
Block(-2,18,-2,AIR:0)
Block(-2,18,-1,inspirations:path)
Block(-2,18,0,CONCRETE:7)
Block(-2,18,1,CONCRETE:7)
Block(-2,18,2,quark:grate)
Block(-2,18,3,quark:grate)
Block(-2,18,4,CONCRETE:7)
Block(-2,18,5,CONCRETE:7)
Block(-2,18,6,BROWN_MUSHROOM:0)
Block(-2,18,7,BROWN_MUSHROOM:0)
Block(-2,18,8,AIR:0)
Block(-2,19,-7,AIR:0)
Block(-2,19,-6,AIR:0)
Block(-2,19,-5,AIR:0)
Block(-2,19,-4,AIR:0)
Block(-2,19,-3,AIR:0)
Block(-2,19,-2,AIR:0)
Block(-2,19,-1,AIR:0)
Block(-2,19,0,CONCRETE:7)
Block(-2,19,1,QUARTZ_STAIRS:3)
Block(-2,19,2,SPONGE:1)
Block(-2,19,3,SPONGE:1)
Block(-2,19,4,QUARTZ_STAIRS:2)
Block(-2,19,5,CONCRETE:7)
Block(-2,19,6,AIR:0)
Block(-2,19,7,AIR:0)
Block(-2,19,8,AIR:0)
Block(-2,20,-7,AIR:0)
Block(-2,20,-6,AIR:0)
Block(-2,20,-5,AIR:0)
Block(-2,20,-4,AIR:0)
Block(-2,20,-3,AIR:0)
Block(-2,20,-2,AIR:0)
Block(-2,20,-1,AIR:0)
Block(-2,20,0,CONCRETE:7)
Block(-2,20,1,HOPPER:3)
Block(-2,20,2,inspirations:redstone_barrel)
Block(-2,20,3,inspirations:redstone_barrel)
Block(-2,20,4,HOPPER:2)
Block(-2,20,5,CONCRETE:7)
Block(-2,20,6,AIR:0)
Block(-2,20,7,AIR:0)
Block(-2,20,8,AIR:0)
Block(-2,21,-7,quark:stone_slate_bricks_stairs:4)
Block(-2,21,-6,quark:stone_slate_bricks_stairs:4)
Block(-2,21,-5,quark:stone_slate_bricks_stairs:4)
Block(-2,21,-4,quark:stone_slate_bricks_stairs:4)
Block(-2,21,-3,quark:stone_slate_bricks_stairs:4)
Block(-2,21,-2,quark:stone_slate_bricks_stairs:4)
Block(-2,21,-1,quark:stone_slate_bricks_stairs:4)
Block(-2,21,0,CONCRETE:7)
Block(-2,21,1,DROPPER:1)
Block(-2,21,2,DROPPER:1)
Block(-2,21,3,DROPPER:1)
Block(-2,21,4,DROPPER:1)
Block(-2,21,5,CONCRETE:7)
Block(-2,21,6,quark:stone_slate_bricks_stairs:4)
Block(-2,21,7,quark:stone_slate_bricks_stairs:4)
Block(-2,21,8,quark:stone_slate_bricks_stairs:4)
Block(-2,22,-7,quark:slate:1)
Block(-2,22,-6,quark:slate:1)
Block(-2,22,-5,quark:slate:1)
Block(-2,22,-4,quark:slate:1)
Block(-2,22,-3,quark:slate:1)
Block(-2,22,-2,quark:slate:1)
Block(-2,22,-1,quark:slate:1)
Block(-2,22,0,quark:slate:1)
Block(-2,22,1,IRON_FENCE:0)
Block(-2,22,2,IRON_FENCE:0)
Block(-2,22,3,IRON_FENCE:0)
Block(-2,22,4,IRON_FENCE:0)
Block(-2,22,5,CONCRETE:7)
Block(-2,22,6,quark:slate:1)
Block(-2,22,7,quark:slate:1)
Block(-2,22,8,quark:slate:1)
Block(-2,23,0,quark:slate:1)
Block(-2,23,1,rustic:iron_lattice:0)
Block(-2,23,2,rustic:iron_lattice:0)
Block(-2,23,3,rustic:iron_lattice:0)
Block(-2,23,4,rustic:iron_lattice:0)
Block(-2,23,5,quark:slate:1)
Block(-2,24,0,quark:slate:1)
Block(-2,24,1,quark:grate)
Block(-2,24,2,quark:grate)
Block(-2,24,3,quark:grate)
Block(-2,24,4,quark:grate)
Block(-2,24,5,quark:slate:1)
Block(-1,2,-7,quark:slate:1)
Block(-1,2,-6,quark:slate:1)
Block(-1,2,-5,quark:slate:1)
Block(-1,2,-4,quark:slate:1)
Block(-1,2,-3,quark:slate:1)
Block(-1,2,-2,quark:slate:1)
Block(-1,2,-1,quark:slate:1)
Block(-1,2,0,quark:slate:1)
Block(-1,2,1,quark:slate:1)
Block(-1,2,2,quark:slate:1)
Block(-1,2,3,quark:slate:1)
Block(-1,2,4,quark:slate:1)
Block(-1,2,5,quark:slate:1)
Block(-1,2,6,quark:slate:1)
Block(-1,2,7,quark:slate:1)
Block(-1,2,8,quark:slate:1)
Block(-1,3,-7,quark:slate:1)
Block(-1,3,-6,quark:slate:1)
Block(-1,3,-5,quark:slate:1)
Block(-1,3,-4,quark:slate:1)
Block(-1,3,-3,quark:slate:1)
Block(-1,3,-2,quark:slate:1)
Block(-1,3,-1,quark:slate:1)
Block(-1,3,0,quark:slate:1)
Block(-1,3,1,quark:slate:1)
Block(-1,3,2,quark:slate:1)
Block(-1,3,3,quark:slate:1)
Block(-1,3,4,quark:slate:1)
Block(-1,3,5,quark:slate:1)
Block(-1,3,6,quark:slate:1)
Block(-1,3,7,quark:slate:1)
Block(-1,3,8,quark:slate:1)
Block(-1,4,-7,quark:slate:1)
Block(-1,4,-6,quark:slate:1)
Block(-1,4,-5,quark:slate:1)
Block(-1,4,-4,quark:slate:1)
Block(-1,4,-3,quark:slate:1)
Block(-1,4,-2,quark:slate:1)
Block(-1,4,-1,quark:slate:1)
Block(-1,4,0,quark:slate:1)
Block(-1,4,1,quark:slate:1)
Block(-1,4,2,quark:slate:1)
Block(-1,4,3,quark:slate:1)
Block(-1,4,4,quark:slate:1)
Block(-1,4,5,quark:slate:1)
Block(-1,4,6,quark:slate:1)
Block(-1,4,7,quark:slate:1)
Block(-1,4,8,quark:slate:1)
Block(-1,5,-7,quark:slate:1)
Block(-1,5,-6,quark:slate:1)
Block(-1,5,-5,quark:slate:1)
Block(-1,5,-4,quark:slate:1)
Block(-1,5,-3,quark:slate:1)
Block(-1,5,-2,quark:slate:1)
Block(-1,5,-1,quark:slate:1)
Block(-1,5,0,quark:slate:1)
Block(-1,5,1,quark:slate:1)
Block(-1,5,2,quark:slate:1)
Block(-1,5,3,quark:slate:1)
Block(-1,5,4,quark:slate:1)
Block(-1,5,5,quark:slate:1)
Block(-1,5,6,quark:slate:1)
Block(-1,5,7,quark:slate:1)
Block(-1,5,8,quark:slate:1)
Block(-1,6,-7,quark:slate:1)
Block(-1,6,-6,quark:slate:1)
Block(-1,6,-5,quark:slate:1)
Block(-1,6,-4,quark:slate:1)
Block(-1,6,-3,quark:slate:1)
Block(-1,6,-2,quark:slate:1)
Block(-1,6,-1,quark:slate:1)
Block(-1,6,0,quark:slate:1)
Block(-1,6,1,quark:slate:1)
Block(-1,6,2,quark:slate:1)
Block(-1,6,3,quark:slate:1)
Block(-1,6,4,quark:slate:1)
Block(-1,6,5,quark:slate:1)
Block(-1,6,6,quark:slate:1)
Block(-1,6,7,quark:slate:1)
Block(-1,6,8,quark:slate:1)
Block(-1,7,-7,quark:slate:1)
Block(-1,7,-6,quark:slate:1)
Block(-1,7,-5,quark:slate:1)
Block(-1,7,-4,quark:slate:1)
Block(-1,7,-3,quark:slate:1)
Block(-1,7,-2,quark:slate:1)
Block(-1,7,-1,quark:slate:1)
Block(-1,7,0,quark:slate:1)
Block(-1,7,1,quark:slate:1)
Block(-1,7,2,quark:slate:1)
Block(-1,7,3,quark:slate:1)
Block(-1,7,4,quark:slate:1)
Block(-1,7,5,quark:slate:1)
Block(-1,7,6,quark:slate:1)
Block(-1,7,7,quark:slate:1)
Block(-1,7,8,quark:slate:1)
Block(-1,8,-7,quark:slate:1)
Block(-1,8,-6,quark:slate:1)
Block(-1,8,-5,quark:slate:1)
Block(-1,8,-4,quark:slate:1)
Block(-1,8,-3,quark:slate:1)
Block(-1,8,-2,quark:slate:1)
Block(-1,8,-1,quark:slate:1)
Block(-1,8,0,quark:slate:1)
Block(-1,8,1,quark:slate:1)
Block(-1,8,2,quark:slate:1)
Block(-1,8,3,quark:slate:1)
Block(-1,8,4,quark:slate:1)
Block(-1,8,5,quark:slate:1)
Block(-1,8,6,quark:slate:1)
Block(-1,8,7,quark:slate:1)
Block(-1,8,8,quark:slate:1)
Block(-1,9,-7,quark:slate:1)
Block(-1,9,-6,quark:slate:1)
Block(-1,9,-5,quark:slate:1)
Block(-1,9,-4,quark:slate:1)
Block(-1,9,-3,quark:slate:1)
Block(-1,9,-2,quark:slate:1)
Block(-1,9,-1,quark:slate:1)
Block(-1,9,0,quark:slate:1)
Block(-1,9,1,quark:slate:1)
Block(-1,9,2,quark:slate:1)
Block(-1,9,3,quark:slate:1)
Block(-1,9,4,quark:slate:1)
Block(-1,9,5,quark:slate:1)
Block(-1,9,6,quark:slate:1)
Block(-1,9,7,quark:slate:1)
Block(-1,9,8,quark:slate:1)
Block(-1,10,-7,quark:slate:1)
Block(-1,10,-6,quark:slate:1)
Block(-1,10,-5,quark:slate:1)
Block(-1,10,-4,quark:slate:1)
Block(-1,10,-3,quark:slate:1)
Block(-1,10,-2,quark:slate:1)
Block(-1,10,-1,quark:slate:1)
Block(-1,10,0,quark:slate:1)
Block(-1,10,1,quark:slate:1)
Block(-1,10,2,quark:slate:1)
Block(-1,10,3,quark:slate:1)
Block(-1,10,4,quark:slate:1)
Block(-1,10,5,quark:slate:1)
Block(-1,10,6,quark:slate:1)
Block(-1,10,7,quark:slate:1)
Block(-1,10,8,quark:slate:1)
Block(-1,11,-7,biomesoplenty:wood_slab_1:14)
Block(-1,11,-6,biomesoplenty:wood_slab_1:14)
Block(-1,11,-5,biomesoplenty:wood_slab_1:14)
Block(-1,11,-4,biomesoplenty:wood_slab_1:14)
Block(-1,11,-3,biomesoplenty:wood_slab_1:14)
Block(-1,11,-2,biomesoplenty:wood_slab_1:14)
Block(-1,11,-1,biomesoplenty:wood_slab_1:14)
Block(-1,11,0,quark:iron_plate)
Block(-1,11,1,biomesoplenty:wood_slab_1:14)
Block(-1,11,2,DISPENSER:1)
Block(-1,11,3,DISPENSER:1)
Block(-1,11,4,biomesoplenty:wood_slab_1:14)
Block(-1,11,5,quark:iron_plate)
Block(-1,11,6,biomesoplenty:wood_slab_1:14)
Block(-1,11,7,biomesoplenty:wood_slab_1:14)
Block(-1,11,8,biomesoplenty:wood_slab_1:14)
Block(-1,12,-7,quark:iron_plate)
Block(-1,12,-6,rustic:cabinet:2,../../../../Chests/RLCraft/Containers/rustic_cabinet.nbt)
Block(-1,12,-5,CARPET:15)
Block(-1,12,-4,quark:custom_bookshelf)
Block(-1,12,-3,CARPET:15)
Block(-1,12,-2,rustic:cabinet,../../../../Chests/RLCraft/Containers/rustic_cabinet.nbt)
Block(-1,12,-1,quark:iron_plate)
Block(-1,12,0,REDSTONE_WIRE:0)
Block(-1,12,1,quark:iron_plate)
Block(-1,12,2,quark:grate)
Block(-1,12,3,quark:grate)
Block(-1,12,4,quark:iron_plate)
Block(-1,12,5,REDSTONE_WIRE:0)
Block(-1,12,6,quark:iron_plate)
Block(-1,12,7,FURNACE:3)
Block(-1,12,8,AIR:0)
Block(-1,13,-7,quark:slate:1)
Block(-1,13,-6,rustic:cabinet:10,../../../../Chests/RLCraft/Containers/rustic_cabinet.nbt)
Block(-1,13,-5,quark:grate)
Block(-1,13,-4,quark:custom_bookshelf)
Block(-1,13,-3,quark:grate)
Block(-1,13,-2,rustic:cabinet:11,../../../../Chests/RLCraft/Containers/rustic_cabinet.nbt)
Block(-1,13,-1,quark:slate:1)
Block(-1,13,0,OBSERVER:0)
Block(-1,13,1,quark:slate:1)
Block(-1,13,2,AIR:0)
Block(-1,13,3,AIR:0)
Block(-1,13,4,quark:slate:1)
Block(-1,13,5,OBSERVER:0)
Block(-1,13,6,quark:slate:1)
Block(-1,13,7,IRON_TRAPDOOR:1)
Block(-1,13,8,AIR:0)
Block(-1,14,-7,quark:slate:1)
Block(-1,14,-6,rustic:cabinet:2,../../../../Chests/RLCraft/Containers/rustic_cabinet.nbt)
Block(-1,14,-5,CARPET:15)
Block(-1,14,-4,quark:custom_bookshelf)
Block(-1,14,-3,CARPET:15)
Block(-1,14,-2,rustic:cabinet,../../../../Chests/RLCraft/Containers/rustic_cabinet.nbt)
Block(-1,14,-1,quark:slate:1)
Block(-1,14,0,REDSTONE_WIRE:0)
Block(-1,14,1,quark:slate:1)
Block(-1,14,2,AIR:0)
Block(-1,14,3,AIR:0)
Block(-1,14,4,quark:slate:1)
Block(-1,14,5,REDSTONE_WIRE:0)
Block(-1,14,6,quark:slate:1)
Block(-1,14,7,quark:iron_plate_stairs)
Block(-1,14,8,AIR:0)
Block(-1,15,-7,quark:slate:1)
Block(-1,15,-6,rustic:cabinet:10,../../../../Chests/RLCraft/Containers/rustic_cabinet.nbt)
Block(-1,15,-5,AIR:0)
Block(-1,15,-3,AIR:0)
Block(-1,15,-2,rustic:cabinet:11,../../../../Chests/RLCraft/Containers/rustic_cabinet.nbt)
Block(-1,15,-1,quark:slate:1)
Block(-1,15,0,OBSERVER:0)
Block(-1,15,1,quark:slate:1)
Block(-1,15,2,AIR:0)
Block(-1,15,3,AIR:0)
Block(-1,15,4,quark:slate:1)
Block(-1,15,5,OBSERVER:0)
Block(-1,15,6,quark:slate:1)
Block(-1,15,7,quark:iron_plate_stairs:7)
Block(-1,15,8,AIR:0)
Block(-1,16,-7,quark:slate:1)
Block(-1,16,-6,quark:custom_bookshelf)
Block(-1,16,-5,AIR:0)
Block(-1,16,-4,quark:grate)
Block(-1,16,-3,AIR:0)
Block(-1,16,-2,quark:custom_bookshelf)
Block(-1,16,-1,quark:slate:1)
Block(-1,16,0,REDSTONE_WIRE:0)
Block(-1,16,1,quark:slate:1)
Block(-1,16,2,quark:grate)
Block(-1,16,3,quark:grate)
Block(-1,16,4,quark:slate:1)
Block(-1,16,5,REDSTONE_WIRE:0)
Block(-1,16,6,quark:slate:1)
Block(-1,16,7,quark:iron_plate)
Block(-1,16,8,AIR:0)
Block(-1,17,-7,CONCRETE:7)
Block(-1,17,-6,quark:iron_plate:1)
Block(-1,17,-5,quark:framed_glass)
Block(-1,17,-4,DROPPER:0)
Block(-1,17,-3,quark:framed_glass)
Block(-1,17,-2,quark:iron_plate:1)
Block(-1,17,-1,CONCRETE:7)
Block(-1,17,0,CONCRETE:7)
Block(-1,17,1,CONCRETE:7)
Block(-1,17,2,DISPENSER:1)
Block(-1,17,3,DISPENSER:1)
Block(-1,17,4,CONCRETE:7)
Block(-1,17,5,CONCRETE:7)
Block(-1,17,6,CONCRETE:7)
Block(-1,17,7,quark:iron_plate:1)
Block(-1,17,8,quark:framed_glass)
Block(-1,18,-7,STEP:0)
Block(-1,18,-6,STEP:0)
Block(-1,18,-5,STEP:0)
Block(-1,18,-4,DROPPER:1)
Block(-1,18,-3,AIR:0)
Block(-1,18,-2,inspirations:path)
Block(-1,18,-1,BROWN_MUSHROOM:0)
Block(-1,18,0,CONCRETE:7)
Block(-1,18,1,CONCRETE:7)
Block(-1,18,2,quark:grate)
Block(-1,18,3,quark:grate)
Block(-1,18,4,CONCRETE:7)
Block(-1,18,5,CONCRETE:7)
Block(-1,18,6,RED_MUSHROOM:0)
Block(-1,18,7,BROWN_MUSHROOM:0)
Block(-1,18,8,AIR:0)
Block(-1,19,-7,AIR:0)
Block(-1,19,-6,AIR:0)
Block(-1,19,-5,AIR:0)
Block(-1,19,-4,IRON_TRAPDOOR:2)
Block(-1,19,-3,AIR:0)
Block(-1,19,-2,AIR:0)
Block(-1,19,-1,CONCRETE:14)
Block(-1,19,0,CONCRETE:7)
Block(-1,19,1,QUARTZ_STAIRS:3)
Block(-1,19,2,SPONGE:1)
Block(-1,19,3,SPONGE:1)
Block(-1,19,4,QUARTZ_STAIRS:2)
Block(-1,19,5,CONCRETE:7)
Block(-1,19,6,AIR:0)
Block(-1,19,7,AIR:0)
Block(-1,19,8,AIR:0)
Block(-1,20,-7,quark:stone_slate_bricks_stairs:4)
Block(-1,20,-6,quark:stone_slate_bricks_stairs:4)
Block(-1,20,-5,quark:stone_slate_bricks_stairs:4)
Block(-1,20,-4,quark:stone_slate_bricks_stairs:4)
Block(-1,20,-3,quark:stone_slate_bricks_stairs:4)
Block(-1,20,-2,quark:stone_slate_bricks_stairs:4)
Block(-1,20,-1,CONCRETE:14)
Block(-1,20,0,CONCRETE:14)
Block(-1,20,1,HOPPER:3)
Block(-1,20,2,inspirations:redstone_barrel)
Block(-1,20,3,inspirations:redstone_barrel)
Block(-1,20,4,HOPPER:2)
Block(-1,20,5,CONCRETE:7)
Block(-1,20,6,quark:stone_slate_bricks_stairs:4)
Block(-1,20,7,quark:stone_slate_bricks_stairs:4)
Block(-1,20,8,quark:stone_slate_bricks_stairs:4)
Block(-1,21,-7,quark:slate:1)
Block(-1,21,-6,quark:slate:1)
Block(-1,21,-5,quark:slate:1)
Block(-1,21,-4,quark:slate:1)
Block(-1,21,-3,quark:slate:1)
Block(-1,21,-2,quark:slate:1)
Block(-1,21,-1,quark:slate:1)
Block(-1,21,0,CONCRETE:7)
Block(-1,21,1,DROPPER:1)
Block(-1,21,2,DROPPER:1)
Block(-1,21,3,DROPPER:1)
Block(-1,21,4,DROPPER:1)
Block(-1,21,5,CONCRETE:7)
Block(-1,21,6,quark:slate:1)
Block(-1,21,7,quark:slate:1)
Block(-1,21,8,quark:slate:1)
Block(-1,22,0,quark:slate:1)
Block(-1,22,1,IRON_FENCE:0)
Block(-1,22,2,IRON_FENCE:0)
Block(-1,22,3,IRON_FENCE:0)
Block(-1,22,4,IRON_FENCE:0)
Block(-1,22,5,quark:slate:1)
Block(-1,23,0,quark:slate:1)
Block(-1,23,1,rustic:iron_lattice:0)
Block(-1,23,2,rustic:iron_lattice:0)
Block(-1,23,3,rustic:iron_lattice:0)
Block(-1,23,4,rustic:iron_lattice:0)
Block(-1,23,5,quark:slate:1)
Block(-1,24,0,quark:slate:1)
Block(-1,24,1,quark:grate)
Block(-1,24,2,quark:grate)
Block(-1,24,3,quark:grate)
Block(-1,24,4,quark:grate)
Block(-1,24,5,quark:slate:1)
Block(0,2,-7,quark:slate:1)
Block(0,2,-6,quark:slate:1)
Block(0,2,-5,quark:slate:1)
Block(0,2,-4,quark:slate:1)
Block(0,2,-3,quark:slate:1)
Block(0,2,-2,quark:slate:1)
Block(0,2,-1,quark:slate:1)
Block(0,2,0,quark:slate:1)
Block(0,2,1,quark:slate:1)
Block(0,2,2,quark:slate:1)
Block(0,2,3,quark:slate:1)
Block(0,2,4,quark:slate:1)
Block(0,2,5,quark:slate:1)
Block(0,2,6,quark:slate:1)
Block(0,2,7,quark:slate:1)
Block(0,2,8,quark:slate:1)
Block(0,3,-7,quark:slate:1)
Block(0,3,-6,quark:slate:1)
Block(0,3,-5,quark:slate:1)
Block(0,3,-4,quark:slate:1)
Block(0,3,-3,quark:slate:1)
Block(0,3,-2,quark:slate:1)
Block(0,3,-1,quark:slate:1)
Block(0,3,0,quark:slate:1)
Block(0,3,1,quark:slate:1)
Block(0,3,2,quark:slate:1)
Block(0,3,3,quark:slate:1)
Block(0,3,4,quark:slate:1)
Block(0,3,5,quark:slate:1)
Block(0,3,6,quark:slate:1)
Block(0,3,7,quark:slate:1)
Block(0,3,8,quark:slate:1)
Block(0,4,-7,quark:slate:1)
Block(0,4,-6,quark:slate:1)
Block(0,4,-5,quark:slate:1)
Block(0,4,-4,quark:slate:1)
Block(0,4,-3,quark:slate:1)
Block(0,4,-2,quark:slate:1)
Block(0,4,-1,quark:slate:1)
Block(0,4,0,quark:slate:1)
Block(0,4,1,quark:slate:1)
Block(0,4,2,quark:slate:1)
Block(0,4,3,quark:slate:1)
Block(0,4,4,quark:slate:1)
Block(0,4,5,quark:slate:1)
Block(0,4,6,quark:slate:1)
Block(0,4,7,quark:slate:1)
Block(0,4,8,quark:slate:1)
Block(0,5,-7,quark:slate:1)
Block(0,5,-6,quark:slate:1)
Block(0,5,-5,quark:slate:1)
Block(0,5,-4,quark:slate:1)
Block(0,5,-3,quark:slate:1)
Block(0,5,-2,quark:slate:1)
Block(0,5,-1,quark:slate:1)
Block(0,5,0,quark:slate:1)
Block(0,5,1,quark:slate:1)
Block(0,5,2,quark:slate:1)
Block(0,5,3,quark:slate:1)
Block(0,5,4,quark:slate:1)
Block(0,5,5,quark:slate:1)
Block(0,5,6,quark:slate:1)
Block(0,5,7,quark:slate:1)
Block(0,5,8,quark:slate:1)
Block(0,6,-7,quark:slate:1)
Block(0,6,-6,quark:slate:1)
Block(0,6,-5,quark:slate:1)
Block(0,6,-4,quark:slate:1)
Block(0,6,-3,quark:slate:1)
Block(0,6,-2,quark:slate:1)
Block(0,6,-1,quark:slate:1)
Block(0,6,0,quark:slate:1)
Block(0,6,1,quark:slate:1)
Block(0,6,2,quark:slate:1)
Block(0,6,3,quark:slate:1)
Block(0,6,4,quark:slate:1)
Block(0,6,5,quark:slate:1)
Block(0,6,6,quark:slate:1)
Block(0,6,7,quark:slate:1)
Block(0,6,8,quark:slate:1)
Block(0,7,-7,quark:slate:1)
Block(0,7,-6,quark:slate:1)
Block(0,7,-5,quark:slate:1)
Block(0,7,-4,quark:slate:1)
Block(0,7,-3,quark:slate:1)
Block(0,7,-2,quark:slate:1)
Block(0,7,-1,quark:slate:1)
Block(0,7,0,quark:slate:1)
Block(0,7,1,quark:slate:1)
Block(0,7,2,quark:slate:1)
Block(0,7,3,quark:slate:1)
Block(0,7,4,quark:slate:1)
Block(0,7,5,quark:slate:1)
Block(0,7,6,quark:slate:1)
Block(0,7,7,quark:slate:1)
Block(0,7,8,quark:slate:1)
Block(0,8,-7,quark:slate:1)
Block(0,8,-6,quark:slate:1)
Block(0,8,-5,quark:slate:1)
Block(0,8,-4,quark:slate:1)
Block(0,8,-3,quark:slate:1)
Block(0,8,-2,quark:slate:1)
Block(0,8,-1,quark:slate:1)
Block(0,8,0,quark:slate:1)
Block(0,8,1,quark:slate:1)
Block(0,8,2,quark:slate:1)
Block(0,8,3,quark:slate:1)
Block(0,8,4,quark:slate:1)
Block(0,8,5,quark:slate:1)
Block(0,8,6,quark:slate:1)
Block(0,8,7,quark:slate:1)
Block(0,8,8,quark:slate:1)
Block(0,9,-7,quark:slate:1)
Block(0,9,-6,quark:slate:1)
Block(0,9,-5,quark:slate:1)
Block(0,9,-4,quark:slate:1)
Block(0,9,-3,quark:slate:1)
Block(0,9,-2,quark:slate:1)
Block(0,9,-1,quark:slate:1)
Block(0,9,0,quark:slate:1)
Block(0,9,1,quark:slate:1)
Block(0,9,2,quark:slate:1)
Block(0,9,3,quark:slate:1)
Block(0,9,4,quark:slate:1)
Block(0,9,5,quark:slate:1)
Block(0,9,6,quark:slate:1)
Block(0,9,7,quark:slate:1)
Block(0,9,8,quark:slate:1)
Block(0,10,-7,quark:slate:1)
Block(0,10,-6,quark:slate:1)
Block(0,10,-5,quark:slate:1)
Block(0,10,-4,quark:slate:1)
Block(0,10,-3,quark:slate:1)
Block(0,10,-2,quark:slate:1)
Block(0,10,-1,quark:slate:1)
Block(0,10,0,quark:slate:1)
Block(0,10,1,quark:slate:1)
Block(0,10,2,quark:slate:1)
Block(0,10,3,quark:slate:1)
Block(0,10,4,quark:slate:1)
Block(0,10,5,quark:slate:1)
Block(0,10,6,quark:slate:1)
Block(0,10,7,quark:slate:1)
Block(0,10,8,quark:slate:1)
Block(0,11,-7,biomesoplenty:wood_slab_1:14)
Block(0,11,-6,biomesoplenty:wood_slab_1:14)
Block(0,11,-5,biomesoplenty:wood_slab_1:14)
Block(0,11,-4,biomesoplenty:wood_slab_1:14)
Block(0,11,-3,biomesoplenty:wood_slab_1:14)
Block(0,11,-2,biomesoplenty:wood_slab_1:14)
Block(0,11,-1,biomesoplenty:wood_slab_1:14)
Block(0,11,0,REDSTONE_WIRE:0)
Block(0,11,1,REDSTONE_WIRE:0)
Block(0,11,2,DISPENSER:1)
Block(0,11,3,DISPENSER:1)
Block(0,11,4,biomesoplenty:wood_slab_1:14)
Block(0,11,5,quark:iron_plate)
Block(0,11,6,biomesoplenty:wood_slab_1:14)
Block(0,11,7,biomesoplenty:wood_slab_1:14)
Block(0,11,8,biomesoplenty:wood_slab_1:14)
Block(0,12,-7,quark:iron_plate)
Block(0,12,-6,BED_BLOCK:3)
Block(0,12,-5,CARPET:15)
Block(0,12,-4,CARPET:15)
Block(0,12,-3,CARPET:15)
Block(0,12,-2,BED_BLOCK:3)
Block(0,12,-1,quark:iron_plate)
Block(0,12,0,AIR:0)
Block(0,12,1,OBSERVER:1)
Block(0,12,2,quark:grate)
Block(0,12,3,quark:grate)
Block(0,12,4,quark:iron_plate)
Block(0,12,5,REDSTONE_WIRE:0)
Block(0,12,6,quark:iron_plate)
Block(0,12,7,FURNACE:3)
Block(0,12,8,AIR:0)
Block(0,13,-7,quark:slate:1)
Block(0,13,-6,BED_BLOCK:3)
Block(0,13,-5,quark:grate)
Block(0,13,-4,AIR:0)
Block(0,13,-3,quark:grate)
Block(0,13,-2,BED_BLOCK:3)
Block(0,13,-1,quark:slate:1)
Block(0,13,0,STEP:8)
Block(0,13,1,OBSERVER:1)
Block(0,13,2,AIR:0)
Block(0,13,3,AIR:0)
Block(0,13,4,quark:slate:1)
Block(0,13,5,STEP:8)
Block(0,13,6,quark:slate:1)
Block(0,13,7,IRON_TRAPDOOR:1)
Block(0,13,8,AIR:0)
Block(0,14,-7,quark:slate:1)
Block(0,14,-6,BED_BLOCK:3)
Block(0,14,-5,CARPET:15)
Block(0,14,-4,AIR:0)
Block(0,14,-3,CARPET:15)
Block(0,14,-2,BED_BLOCK:3)
Block(0,14,-1,quark:slate:1)
Block(0,14,0,STEP:8)
Block(0,14,1,OBSERVER:1)
Block(0,14,2,AIR:0)
Block(0,14,3,AIR:0)
Block(0,14,4,quark:slate:1)
Block(0,14,5,STEP:8)
Block(0,14,6,quark:slate:1)
Block(0,14,7,quark:iron_plate_stairs:1)
Block(0,14,8,AIR:0)
Block(0,15,-7,quark:slate:1)
Block(0,15,-6,BED_BLOCK:3)
Block(0,15,-5,AIR:0)
Block(0,15,-4,AIR:0)
Block(0,15,-3,AIR:0)
Block(0,15,-2,BED_BLOCK:3)
Block(0,15,-1,quark:slate:1)
Block(0,15,0,STEP:8)
Block(0,15,1,REDSTONE_LAMP_OFF:0)
Block(0,15,2,quark:iron_button:3)
Block(0,15,3,AIR:0)
Block(0,15,4,quark:slate:1)
Block(0,15,5,STEP:8)
Block(0,15,6,quark:slate:1)
Block(0,15,7,AIR:0)
Block(0,15,8,AIR:0)
Block(0,16,-7,quark:slate:1)
Block(0,16,-6,SANDSTONE_STAIRS:7)
Block(0,16,-5,AIR:0)
Block(0,16,-4,AIR:0)
Block(0,16,-3,AIR:0)
Block(0,16,-2,SANDSTONE_STAIRS:6)
Block(0,16,-1,quark:slate:1)
Block(0,16,0,STEP:8)
Block(0,16,1,quark:slate:1)
Block(0,16,2,quark:grate)
Block(0,16,3,quark:grate)
Block(0,16,4,quark:slate:1)
Block(0,16,5,STEP:8)
Block(0,16,6,quark:slate:1)
Block(0,16,7,AIR:0)
Block(0,16,8,AIR:0)
Block(0,17,-7,CONCRETE:7)
Block(0,17,-6,quark:iron_plate:1)
Block(0,17,-5,quark:framed_glass)
Block(0,17,-4,quark:framed_glass)
Block(0,17,-3,quark:framed_glass)
Block(0,17,-2,quark:iron_plate:1)
Block(0,17,-1,CONCRETE:11)
Block(0,17,0,CONCRETE:11)
Block(0,17,1,AIR:0)
Block(0,17,2,DISPENSER:1)
Block(0,17,3,DISPENSER:1)
Block(0,17,4,CONCRETE:7)
Block(0,17,5,CONCRETE:7)
Block(0,17,6,CONCRETE:7)
Block(0,17,7,quark:iron_plate:1)
Block(0,17,8,quark:framed_glass)
Block(0,18,-7,CONCRETE:11)
Block(0,18,-6,CONCRETE:11)
Block(0,18,-5,CONCRETE:11)
Block(0,18,-4,CONCRETE:11)
Block(0,18,-3,CONCRETE:11)
Block(0,18,-2,CONCRETE:11)
Block(0,18,-1,CONCRETE:11)
Block(0,18,0,CONCRETE:7)
Block(0,18,1,AIR:0)
Block(0,18,2,quark:grate)
Block(0,18,3,quark:grate)
Block(0,18,4,CONCRETE:7)
Block(0,18,5,CONCRETE:7)
Block(0,18,6,RED_MUSHROOM:0)
Block(0,18,7,contenttweaker:bone_pile)
Block(0,18,8,AIR:0)
Block(0,19,-7,CONCRETE:14)
Block(0,19,-6,CONCRETE:14)
Block(0,19,-5,CONCRETE:14)
Block(0,19,-4,CONCRETE:14)
Block(0,19,-3,CONCRETE:14)
Block(0,19,-2,CONCRETE:14)
Block(0,19,-1,CONCRETE:14)
Block(0,19,0,CONCRETE:7)
Block(0,19,1,QUARTZ_STAIRS:3)
Block(0,19,2,SPONGE:1)
Block(0,19,3,SPONGE:1)
Block(0,19,4,QUARTZ_STAIRS:2)
Block(0,19,5,CONCRETE:7)
Block(0,19,6,quark:stone_slate_bricks_stairs:4)
Block(0,19,7,quark:stone_slate_bricks_stairs:4)
Block(0,19,8,quark:stone_slate_bricks_stairs:4)
Block(0,20,-7,quark:slate:1)
Block(0,20,-6,quark:slate:1)
Block(0,20,-5,quark:slate:1)
Block(0,20,-4,quark:slate:1)
Block(0,20,-3,quark:slate:1)
Block(0,20,-2,quark:slate:1)
Block(0,20,-1,quark:slate:1)
Block(0,20,0,CONCRETE:7)
Block(0,20,1,HOPPER:3)
Block(0,20,2,inspirations:redstone_barrel)
Block(0,20,3,inspirations:redstone_barrel)
Block(0,20,4,HOPPER:2)
Block(0,20,5,CONCRETE:7)
Block(0,20,6,quark:slate:1)
Block(0,20,7,quark:slate:1)
Block(0,20,8,quark:slate:1)
Block(0,21,0,quark:slate:1)
Block(0,21,1,DROPPER:1)
Block(0,21,2,DROPPER:1)
Block(0,21,3,DROPPER:1)
Block(0,21,4,DROPPER:1)
Block(0,21,5,quark:slate:1)
Block(0,22,0,quark:slate:1)
Block(0,22,1,IRON_FENCE:0)
Block(0,22,2,IRON_FENCE:0)
Block(0,22,3,IRON_FENCE:0)
Block(0,22,4,IRON_FENCE:0)
Block(0,22,5,quark:slate:1)
Block(0,23,0,quark:slate:1)
Block(0,23,1,rustic:iron_lattice:0)
Block(0,23,2,rustic:iron_lattice:0)
Block(0,23,3,rustic:iron_lattice:0)
Block(0,23,4,rustic:iron_lattice:0)
Block(0,23,5,quark:slate:1)
Block(0,24,0,quark:slate:1)
Block(0,24,1,quark:grate)
Block(0,24,2,quark:grate)
Block(0,24,3,quark:grate)
Block(0,24,4,quark:grate)
Block(0,24,5,quark:slate:1)
Block(1,2,-7,quark:slate:1)
Block(1,2,-6,quark:slate:1)
Block(1,2,-5,quark:slate:1)
Block(1,2,-4,quark:slate:1)
Block(1,2,-3,quark:slate:1)
Block(1,2,-2,quark:slate:1)
Block(1,2,-1,quark:slate:1)
Block(1,2,0,quark:slate:1)
Block(1,2,1,quark:slate:1)
Block(1,2,2,quark:slate:1)
Block(1,2,3,quark:slate:1)
Block(1,2,4,quark:slate:1)
Block(1,2,5,quark:slate:1)
Block(1,2,6,quark:slate:1)
Block(1,2,7,quark:slate:1)
Block(1,2,8,quark:slate:1)
Block(1,3,-7,quark:slate:1)
Block(1,3,-6,quark:slate:1)
Block(1,3,-5,quark:slate:1)
Block(1,3,-4,quark:slate:1)
Block(1,3,-3,quark:slate:1)
Block(1,3,-2,quark:slate:1)
Block(1,3,-1,quark:slate:1)
Block(1,3,0,quark:slate:1)
Block(1,3,1,quark:slate:1)
Block(1,3,2,quark:slate:1)
Block(1,3,3,quark:slate:1)
Block(1,3,4,quark:slate:1)
Block(1,3,5,quark:slate:1)
Block(1,3,6,quark:slate:1)
Block(1,3,7,quark:slate:1)
Block(1,3,8,quark:slate:1)
Block(1,4,-7,quark:slate:1)
Block(1,4,-6,quark:slate:1)
Block(1,4,-5,quark:slate:1)
Block(1,4,-4,quark:slate:1)
Block(1,4,-3,quark:slate:1)
Block(1,4,-2,quark:slate:1)
Block(1,4,-1,quark:slate:1)
Block(1,4,0,quark:slate:1)
Block(1,4,1,quark:slate:1)
Block(1,4,2,quark:slate:1)
Block(1,4,3,quark:slate:1)
Block(1,4,4,quark:slate:1)
Block(1,4,5,quark:slate:1)
Block(1,4,6,quark:slate:1)
