
#######################################################################
# +-----------------------------------------------------------------+ #
# |                            BO3 object                           | #
# +-----------------------------------------------------------------+ #
#######################################################################

Author: NLBlackHeavenNL

Description: No description given

Version: 3

SettingsMode: WriteWithoutComments


#######################################################################
# +-----------------------------------------------------------------+ #
# |                          Main settings                          | #
# +-----------------------------------------------------------------+ #
#######################################################################

Tree: true

Frequency: 1

Rarity: 100.0

RotateRandomly: false

SpawnHeight: highestSolidBlock

SpawnHeightOffset: -1

SpawnHeightVariance: 0

##############################
# Height Limits for the BO3. #
##############################

MinHeight: 0

MaxHeight: 255

######################
# Extrusion settings #
######################

ExtrudeMode: None

ExtrudeThroughBlocks: AIR

MaxBranchDepth: 10

ExcludedBiomes: All


#######################################################################
# +-----------------------------------------------------------------+ #
# |                      Source block settings                      | #
# +-----------------------------------------------------------------+ #
#######################################################################

SourceBlocks: AIR,GRASS,DIRT,biomesoplenty:dirt

MaxPercentageOutsideSourceBlock: 0

OutsideSourceBlock: placeAnyway

DoReplaceBlocks: true

IsOTGPlus: false


#######################################################################
# +-----------------------------------------------------------------+ #
# |                              Blocks                             | #
# +-----------------------------------------------------------------+ #
#######################################################################

Block(-4,9,2,dynamictrees:leaves0:8)
Block(-4,10,1,dynamictrees:leaves0:8)
Block(-4,10,2,dynamictrees:leaves0:8)
Block(-4,10,3,dynamictrees:leaves0:8)
Block(-4,11,1,dynamictrees:leaves0:8)
Block(-4,11,2,dynamictrees:leaves0:8)
Block(-4,11,3,dynamictrees:leaves0:8)
Block(-4,12,1,dynamictrees:leaves0:8)
Block(-4,12,2,dynamictrees:leaves0:8)
Block(-4,12,3,dynamictrees:leaves0:8)
Block(-3,7,2,dynamictrees:birchbranch)
Block(-3,8,2,dynamictrees:leaves0:11)
Block(-3,9,1,dynamictrees:leaves0:8)
Block(-3,9,2,dynamictrees:leaves0:10)
Block(-3,9,3,dynamictrees:leaves0:9)
Block(-3,10,0,dynamictrees:leaves0:8)
Block(-3,10,1,dynamictrees:leaves0:9)
Block(-3,10,2,dynamictrees:leaves0:10)
Block(-3,10,3,dynamictrees:leaves0:9)
Block(-3,10,4,dynamictrees:leaves0:8)
Block(-3,11,0,dynamictrees:leaves0:8)
Block(-3,11,1,dynamictrees:leaves0:10)
Block(-3,11,2,dynamictrees:leaves0:11)
Block(-3,11,3,dynamictrees:leaves0:10)
Block(-3,11,4,dynamictrees:leaves0:8)
Block(-3,12,0,dynamictrees:leaves0:8)
Block(-3,12,1,dynamictrees:leaves0:9)
Block(-3,12,2,dynamictrees:leaves0:10)
Block(-3,12,3,dynamictrees:leaves0:9)
Block(-3,12,4,dynamictrees:leaves0:8)
Block(-3,13,1,dynamictrees:leaves0:8)
Block(-3,13,2,dynamictrees:leaves0:8)
Block(-3,13,3,dynamictrees:leaves0:8)
Block(-3,15,2,dynamictrees:leaves0:8)
Block(-3,16,1,dynamictrees:leaves0:8)
Block(-3,16,2,dynamictrees:leaves0:8)
Block(-3,16,3,dynamictrees:leaves0:8)
Block(-2,7,2,dynamictrees:birchbranch:1)
Block(-2,8,2,dynamictrees:birchbranch)
Block(-2,8,3,dynamictrees:leaves0:11)
Block(-2,8,4,dynamictrees:leaves0:8)
Block(-2,9,-1,dynamictrees:leaves0:8)
Block(-2,9,2,dynamictrees:leaves0:11)
Block(-2,9,3,dynamictrees:leaves0:10)
Block(-2,9,4,dynamictrees:leaves0:8)
Block(-2,10,0,dynamictrees:leaves0:8)
Block(-2,10,1,dynamictrees:leaves0:10)
Block(-2,10,2,dynamictrees:leaves0:11)
Block(-2,10,3,dynamictrees:leaves0:10)
Block(-2,10,4,dynamictrees:leaves0:8)
Block(-2,11,-2,dynamictrees:leaves0:8)
Block(-2,11,-1,dynamictrees:leaves0:8)
Block(-2,11,0,dynamictrees:leaves0:8)
Block(-2,11,1,dynamictrees:leaves0:11)
Block(-2,11,2,dynamictrees:birchbranch)
Block(-2,11,3,dynamictrees:leaves0:11)
Block(-2,11,4,dynamictrees:leaves0:8)
Block(-2,12,-2,dynamictrees:leaves0:8)
Block(-2,12,-1,dynamictrees:leaves0:8)
Block(-2,12,0,dynamictrees:leaves0:8)
Block(-2,12,1,dynamictrees:leaves0:10)
Block(-2,12,2,dynamictrees:leaves0:11)
Block(-2,13,1,dynamictrees:leaves0:8)
Block(-2,13,2,dynamictrees:leaves0:8)
Block(-2,14,2,dynamictrees:leaves0:8)
Block(-2,15,2,dynamictrees:leaves0:11)
Block(-2,15,3,dynamictrees:leaves0:8)
Block(-2,16,0,dynamictrees:leaves0:8)
Block(-2,16,1,dynamictrees:leaves0:8)
Block(-2,16,2,dynamictrees:leaves0:10)
Block(-2,16,3,dynamictrees:leaves0:8)
Block(-2,17,0,dynamictrees:leaves0:8)
Block(-2,17,1,dynamictrees:leaves0:8)
Block(-2,17,2,dynamictrees:leaves0:8)
Block(-2,18,0,dynamictrees:leaves0:8)
Block(-2,18,1,dynamictrees:leaves0:8)
Block(-2,18,2,dynamictrees:leaves0:8)
Block(-2,18,3,dynamictrees:leaves0:8)
Block(-2,18,4,dynamictrees:leaves0:8)
Block(-2,18,5,dynamictrees:leaves0:8)
Block(-2,19,0,dynamictrees:leaves0:8)
Block(-2,19,1,dynamictrees:leaves0:8)
Block(-2,19,2,dynamictrees:leaves0:8)
Block(-2,19,3,dynamictrees:leaves0:8)
Block(-2,19,4,dynamictrees:leaves0:8)
Block(-1,7,2,dynamictrees:birchbranch:1)
Block(-1,8,-1,dynamictrees:leaves0:8)
Block(-1,9,-1,dynamictrees:leaves0:8)
Block(-1,9,2,dynamictrees:birchbranch:1)
Block(-1,10,-1,dynamictrees:leaves0:10)
Block(-1,10,2,dynamictrees:birchbranch:1)
Block(-1,11,-3,dynamictrees:leaves0:8)
Block(-1,11,-2,dynamictrees:leaves0:10)
Block(-1,11,-1,dynamictrees:leaves0:11)
Block(-1,11,0,dynamictrees:leaves0:8)
Block(-1,11,2,dynamictrees:birchbranch:1)
Block(-1,12,-3,dynamictrees:leaves0:8)
Block(-1,12,-2,dynamictrees:leaves0:9)
Block(-1,12,-1,dynamictrees:leaves0:10)
Block(-1,12,0,dynamictrees:leaves0:8)
Block(-1,12,2,dynamictrees:leaves0:8)
Block(-1,13,-2,dynamictrees:leaves0:8)
Block(-1,13,-1,dynamictrees:leaves0:8)
Block(-1,13,4,dynamictrees:leaves0:8)
Block(-1,14,-2,dynamictrees:leaves0:8)
Block(-1,14,-1,dynamictrees:leaves0:8)
Block(-1,15,2,dynamictrees:birchbranch)
Block(-1,16,2,dynamictrees:leaves0:11)
Block(-1,17,-1,dynamictrees:leaves0:8)
Block(-1,17,0,dynamictrees:leaves0:9)
Block(-1,17,1,dynamictrees:leaves0:10)
Block(-1,17,2,dynamictrees:leaves0:9)
Block(-1,17,3,dynamictrees:leaves0:8)
Block(-1,17,4,dynamictrees:leaves0:8)
Block(-1,17,5,dynamictrees:leaves0:8)
Block(-1,17,6,dynamictrees:leaves0:8)
Block(-1,18,-1,dynamictrees:leaves0:8)
Block(-1,18,0,dynamictrees:leaves0:10)
Block(-1,18,1,dynamictrees:leaves0:11)
Block(-1,18,2,dynamictrees:leaves0:10)
Block(-1,18,3,dynamictrees:leaves0:11)
Block(-1,18,4,dynamictrees:leaves0:10)
Block(-1,18,5,dynamictrees:leaves0:9)
Block(-1,18,6,dynamictrees:leaves0:8)
Block(-1,19,-1,dynamictrees:leaves0:8)
Block(-1,19,0,dynamictrees:leaves0:9)
Block(-1,19,1,dynamictrees:leaves0:10)
Block(-1,19,2,dynamictrees:leaves0:9)
Block(-1,19,3,dynamictrees:leaves0:10)
Block(-1,19,4,dynamictrees:leaves0:9)
Block(-1,19,5,dynamictrees:leaves0:8)
Block(-1,20,0,dynamictrees:leaves0:8)
Block(-1,20,1,dynamictrees:leaves0:8)
Block(-1,20,2,dynamictrees:leaves0:8)
Block(-1,20,3,dynamictrees:leaves0:8)
Block(-1,20,4,dynamictrees:leaves0:8)
Block(0,7,-1,dynamictrees:birchbranch)
Block(0,7,2,dynamictrees:birchbranch:1)
Block(0,8,-1,dynamictrees:leaves0:11)
Block(0,9,-3,dynamictrees:leaves0:8)
Block(0,9,-1,dynamictrees:leaves0:10)
Block(0,9,2,dynamictrees:birchbranch:1)
Block(0,10,-3,dynamictrees:leaves0:10)
Block(0,10,-2,dynamictrees:leaves0:11)
Block(0,10,-1,dynamictrees:leaves0:11)
Block(0,10,4,dynamictrees:birchbranch)
Block(0,11,-3,dynamictrees:leaves0:8)
Block(0,11,-2,dynamictrees:leaves0:11)
Block(0,11,-1,dynamictrees:birchbranch)
Block(0,11,4,dynamictrees:leaves0:11)
Block(0,12,-3,dynamictrees:leaves0:8)
Block(0,12,-2,dynamictrees:leaves0:10)
Block(0,12,-1,dynamictrees:leaves0:11)
Block(0,12,2,dynamictrees:birchbranch:1)
Block(0,12,3,dynamictrees:birchbranch:1)
Block(0,12,4,dynamictrees:birchbranch)
Block(0,13,-3,dynamictrees:leaves0:8)
Block(0,13,-2,dynamictrees:leaves0:10)
Block(0,13,-1,dynamictrees:leaves0:11)
Block(0,13,1,dynamictrees:birchbranch:1)
Block(0,13,3,dynamictrees:birchbranch)
Block(0,13,4,dynamictrees:leaves0:11)
Block(0,14,-3,dynamictrees:leaves0:8)
Block(0,14,-2,dynamictrees:leaves0:9)
Block(0,14,-1,dynamictrees:leaves0:10)
Block(0,14,1,dynamictrees:birchbranch)
Block(0,14,3,dynamictrees:leaves0:11)
Block(0,15,-2,dynamictrees:leaves0:8)
Block(0,15,-1,dynamictrees:leaves0:8)
Block(0,15,1,dynamictrees:leaves0:11)
Block(0,15,2,dynamictrees:birchbranch:1)
Block(0,15,3,dynamictrees:birchbranch)
Block(0,16,1,dynamictrees:leaves0:10)
Block(0,16,3,dynamictrees:leaves0:11)
Block(0,16,4,dynamictrees:birchbranch)
Block(0,16,6,dynamictrees:leaves0:8)
Block(0,17,-1,dynamictrees:leaves0:8)
Block(0,17,0,dynamictrees:leaves0:10)
Block(0,17,1,dynamictrees:leaves0:11)
Block(0,17,2,dynamictrees:leaves0:10)
Block(0,17,3,dynamictrees:birchbranch:1)
Block(0,17,4,dynamictrees:leaves0:11)
Block(0,17,5,dynamictrees:leaves0:11)
Block(0,17,6,dynamictrees:leaves0:10)
Block(0,17,7,dynamictrees:leaves0:8)
Block(0,18,-1,dynamictrees:leaves0:8)
Block(0,18,0,dynamictrees:leaves0:11)
Block(0,18,1,dynamictrees:birchbranch)
Block(0,18,2,dynamictrees:leaves0:11)
Block(0,18,3,dynamictrees:birchbranch)
Block(0,18,4,dynamictrees:leaves0:11)
Block(0,18,5,dynamictrees:leaves0:10)
Block(0,18,6,dynamictrees:leaves0:9)
Block(0,18,7,dynamictrees:leaves0:8)
Block(0,19,-1,dynamictrees:leaves0:8)
Block(0,19,0,dynamictrees:leaves0:10)
Block(0,19,1,dynamictrees:leaves0:11)
Block(0,19,2,dynamictrees:leaves0:10)
Block(0,19,3,dynamictrees:leaves0:11)
Block(0,19,4,dynamictrees:leaves0:10)
Block(0,19,5,dynamictrees:leaves0:9)
Block(0,19,6,dynamictrees:leaves0:8)
Block(0,20,0,dynamictrees:leaves0:8)
Block(0,20,1,dynamictrees:leaves0:8)
Block(0,20,2,dynamictrees:leaves0:8)
Block(0,20,3,dynamictrees:leaves0:8)
Block(0,20,4,dynamictrees:leaves0:8)
Block(0,20,5,dynamictrees:leaves0:8)
Block(1,0,2,dynamictrees:rootydirt:0)
Block(1,1,2,dynamictrees:birchbranch:7)
Block(1,2,2,dynamictrees:birchbranch:7)
Block(1,3,2,dynamictrees:birchbranch:7)
Block(1,4,2,dynamictrees:birchbranch:7)
Block(1,5,2,dynamictrees:birchbranch:7)
Block(1,6,2,dynamictrees:birchbranch:7)
Block(1,7,-2,dynamictrees:birchbranch:1)
Block(1,7,-1,dynamictrees:birchbranch:1)
Block(1,7,0,dynamictrees:birchbranch:1)
Block(1,7,1,dynamictrees:birchbranch:1)
Block(1,7,2,dynamictrees:birchbranch:7)
Block(1,8,-1,dynamictrees:birchbranch)
Block(1,8,2,dynamictrees:birchbranch:7)
Block(1,9,-4,dynamictrees:leaves0:8)
Block(1,9,-2,dynamictrees:leaves0:11)
Block(1,9,-1,dynamictrees:leaves0:11)
Block(1,9,0,dynamictrees:birchbranch:1)
Block(1,9,1,dynamictrees:birchbranch:1)
Block(1,9,2,dynamictrees:birchbranch:7)
Block(1,9,3,dynamictrees:birchbranch:2)
Block(1,9,4,dynamictrees:birchbranch:2)
Block(1,9,5,dynamictrees:birchbranch:1)
Block(1,9,6,dynamictrees:birchbranch)
Block(1,10,-4,dynamictrees:leaves0:8)
Block(1,10,-3,dynamictrees:leaves0:11)
Block(1,10,-2,dynamictrees:birchbranch)
Block(1,10,-1,dynamictrees:birchbranch:1)
Block(1,10,0,dynamictrees:birchbranch:1)
Block(1,10,2,dynamictrees:birchbranch:6)
Block(1,10,4,dynamictrees:birchbranch:1)
Block(1,10,6,dynamictrees:leaves0:11)
Block(1,11,-3,dynamictrees:leaves0:8)
Block(1,11,-2,dynamictrees:leaves0:11)
Block(1,11,-1,dynamictrees:birchbranch:1)
Block(1,11,1,dynamictrees:birchbranch:1)
Block(1,11,2,dynamictrees:birchbranch:5)
Block(1,11,4,dynamictrees:birchbranch:1)
Block(1,11,5,dynamictrees:birchbranch)
Block(1,11,6,dynamictrees:leaves0:11)
Block(1,11,7,dynamictrees:leaves0:8)
Block(1,12,-3,dynamictrees:leaves0:8)
Block(1,12,-2,dynamictrees:leaves0:10)
Block(1,12,2,dynamictrees:birchbranch:5)
Block(1,12,5,dynamictrees:leaves0:11)
Block(1,12,6,dynamictrees:leaves0:10)
Block(1,12,7,dynamictrees:leaves0:8)
Block(1,13,-3,dynamictrees:leaves0:8)
Block(1,13,-2,dynamictrees:leaves0:11)
Block(1,13,-1,dynamictrees:birchbranch)
Block(1,13,0,dynamictrees:birchbranch:1)
Block(1,13,1,dynamictrees:birchbranch:1)
Block(1,13,2,dynamictrees:birchbranch:4)
Block(1,13,4,dynamictrees:birchbranch)
Block(1,13,5,dynamictrees:leaves0:11)
Block(1,13,6,dynamictrees:leaves0:10)
Block(1,13,7,dynamictrees:leaves0:8)
Block(1,14,-3,dynamictrees:leaves0:8)
Block(1,14,-2,dynamictrees:leaves0:10)
Block(1,14,-1,dynamictrees:leaves0:11)
Block(1,14,2,dynamictrees:birchbranch:4)
Block(1,14,3,dynamictrees:birchbranch:2)
Block(1,14,4,dynamictrees:birchbranch:2)
Block(1,14,5,dynamictrees:birchbranch)
Block(1,14,6,dynamictrees:leaves0:11)
Block(1,14,7,dynamictrees:leaves0:8)
Block(1,15,-2,dynamictrees:leaves0:8)
Block(1,15,-1,dynamictrees:leaves0:8)
Block(1,15,1,dynamictrees:birchbranch)
Block(1,15,2,dynamictrees:birchbranch:3)
Block(1,15,4,dynamictrees:birchbranch:1)
Block(1,15,5,dynamictrees:leaves0:11)
Block(1,15,6,dynamictrees:leaves0:10)
Block(1,15,7,dynamictrees:leaves0:8)
Block(1,16,-1,dynamictrees:leaves0:8)
Block(1,16,0,dynamictrees:leaves0:9)
Block(1,16,1,dynamictrees:leaves0:11)
Block(1,16,2,dynamictrees:birchbranch:2)
Block(1,16,4,dynamictrees:birchbranch:1)
Block(1,16,5,dynamictrees:birchbranch:1)
Block(1,16,6,dynamictrees:leaves0:8)
Block(1,17,-1,dynamictrees:leaves0:8)
Block(1,17,0,dynamictrees:leaves0:10)
Block(1,17,1,dynamictrees:leaves0:11)
Block(1,17,2,dynamictrees:birchbranch:2)
Block(1,17,3,dynamictrees:birchbranch:1)
Block(1,17,4,dynamictrees:leaves0:11)
Block(1,17,5,dynamictrees:birchbranch)
Block(1,17,6,dynamictrees:leaves0:11)
Block(1,17,7,dynamictrees:leaves0:8)
Block(1,18,0,dynamictrees:leaves0:8)
Block(1,18,1,dynamictrees:birchbranch:1)
Block(1,18,2,dynamictrees:birchbranch:1)
Block(1,18,3,dynamictrees:leaves0:11)
Block(1,18,4,dynamictrees:leaves0:10)
Block(1,18,5,dynamictrees:leaves0:11)
Block(1,18,6,dynamictrees:leaves0:10)
Block(1,18,7,dynamictrees:leaves0:8)
Block(1,19,0,dynamictrees:leaves0:8)
Block(1,19,1,dynamictrees:leaves0:8)
Block(1,19,2,dynamictrees:leaves0:9)
Block(1,19,3,dynamictrees:leaves0:10)
Block(1,19,4,dynamictrees:leaves0:9)
Block(1,19,5,dynamictrees:leaves0:8)
Block(1,19,6,dynamictrees:leaves0:8)
Block(1,20,2,dynamictrees:leaves0:8)
Block(1,20,3,dynamictrees:leaves0:8)
Block(1,20,4,dynamictrees:leaves0:8)
Block(2,7,-2,dynamictrees:birchbranch)
Block(2,7,-1,dynamictrees:leaves0:11)
Block(2,8,-2,dynamictrees:leaves0:11)
Block(2,8,-1,dynamictrees:leaves0:11)
Block(2,9,-3,dynamictrees:leaves0:8)
Block(2,9,-2,dynamictrees:leaves0:10)
Block(2,9,-1,dynamictrees:leaves0:10)
Block(2,10,-4,dynamictrees:leaves0:8)
Block(2,10,-3,dynamictrees:leaves0:10)
Block(2,10,-2,dynamictrees:leaves0:11)
Block(2,10,2,dynamictrees:birchbranch:3)
Block(2,10,4,dynamictrees:birchbranch)
Block(2,10,7,dynamictrees:leaves0:8)
Block(2,11,-4,dynamictrees:leaves0:8)
Block(2,11,-3,dynamictrees:leaves0:9)
Block(2,11,-2,dynamictrees:leaves0:10)
Block(2,11,1,dynamictrees:birchbranch:1)
Block(2,11,4,dynamictrees:leaves0:11)
Block(2,11,5,dynamictrees:leaves0:11)
Block(2,11,6,dynamictrees:leaves0:8)
Block(2,12,-3,dynamictrees:leaves0:8)
Block(2,12,-2,dynamictrees:leaves0:9)
Block(2,12,1,dynamictrees:birchbranch)
Block(2,12,4,dynamictrees:leaves0:10)
Block(2,12,5,dynamictrees:leaves0:10)
Block(2,12,6,dynamictrees:leaves0:9)
Block(2,12,7,dynamictrees:leaves0:8)
Block(2,13,-2,dynamictrees:leaves0:8)
Block(2,13,1,dynamictrees:leaves0:11)
Block(2,13,4,dynamictrees:leaves0:11)
Block(2,13,5,dynamictrees:leaves0:10)
Block(2,13,6,dynamictrees:leaves0:8)
Block(2,14,-3,dynamictrees:leaves0:8)
Block(2,14,-2,dynamictrees:leaves0:9)
Block(2,14,-1,dynamictrees:leaves0:10)
Block(2,14,1,dynamictrees:leaves0:10)
Block(2,14,6,dynamictrees:leaves0:8)
Block(2,15,-2,dynamictrees:leaves0:8)
Block(2,15,-1,dynamictrees:leaves0:8)
Block(2,15,0,dynamictrees:leaves0:8)
Block(2,15,1,dynamictrees:leaves0:11)
Block(2,15,6,dynamictrees:leaves0:8)
Block(2,16,-1,dynamictrees:leaves0:8)
Block(2,16,0,dynamictrees:leaves0:10)
Block(2,16,1,dynamictrees:leaves0:11)
Block(2,16,2,dynamictrees:birchbranch)
Block(2,16,3,dynamictrees:leaves0:11)
Block(2,16,4,dynamictrees:leaves0:10)
Block(2,16,5,dynamictrees:leaves0:8)
Block(2,16,6,dynamictrees:leaves0:8)
Block(2,17,-1,dynamictrees:leaves0:8)
Block(2,17,0,dynamictrees:leaves0:11)
Block(2,17,1,dynamictrees:birchbranch)
Block(2,17,2,dynamictrees:leaves0:11)
Block(2,17,3,dynamictrees:birchbranch)
Block(2,17,4,dynamictrees:leaves0:11)
Block(2,17,5,dynamictrees:leaves0:11)
Block(2,17,6,dynamictrees:leaves0:10)
Block(2,17,7,dynamictrees:leaves0:8)
Block(2,18,0,dynamictrees:leaves0:8)
Block(2,18,1,dynamictrees:birchbranch:1)
Block(2,18,2,dynamictrees:leaves0:10)
Block(2,18,3,dynamictrees:leaves0:11)
Block(2,18,4,dynamictrees:leaves0:10)
Block(2,18,5,dynamictrees:leaves0:10)
Block(2,18,6,dynamictrees:leaves0:9)
Block(2,18,7,dynamictrees:leaves0:8)
Block(2,19,2,dynamictrees:leaves0:8)
Block(2,19,3,dynamictrees:leaves0:8)
Block(2,19,4,dynamictrees:leaves0:8)
Block(2,19,5,dynamictrees:leaves0:8)
Block(2,19,6,dynamictrees:leaves0:8)
Block(3,8,-2,dynamictrees:leaves0:8)
Block(3,9,-3,dynamictrees:leaves0:8)
Block(3,9,-2,dynamictrees:leaves0:9)
Block(3,10,-3,dynamictrees:leaves0:8)
Block(3,10,-2,dynamictrees:leaves0:8)
Block(3,10,0,dynamictrees:birchbranch)
Block(3,10,1,dynamictrees:birchbranch:1)
Block(3,10,2,dynamictrees:birchbranch:3)
Block(3,10,3,dynamictrees:birchbranch)
Block(3,10,4,dynamictrees:leaves0:11)
Block(3,10,6,dynamictrees:leaves0:8)
Block(3,11,-3,dynamictrees:leaves0:8)
Block(3,11,-2,dynamictrees:leaves0:9)
Block(3,11,-1,dynamictrees:leaves0:8)
Block(3,11,0,dynamictrees:leaves0:11)
Block(3,11,2,dynamictrees:birchbranch:1)
Block(3,11,3,dynamictrees:leaves0:11)
Block(3,11,4,dynamictrees:leaves0:10)
Block(3,11,5,dynamictrees:leaves0:8)
Block(3,12,-2,dynamictrees:leaves0:8)
Block(3,12,-1,dynamictrees:leaves0:8)
Block(3,12,0,dynamictrees:leaves0:8)
Block(3,12,2,dynamictrees:birchbranch:1)
Block(3,12,3,dynamictrees:birchbranch)
Block(3,12,4,dynamictrees:leaves0:11)
Block(3,12,5,dynamictrees:leaves0:8)
Block(3,12,6,dynamictrees:leaves0:8)
Block(3,13,-1,dynamictrees:leaves0:8)
Block(3,13,2,dynamictrees:birchbranch:1)
Block(3,14,-2,dynamictrees:leaves0:8)
Block(3,14,-1,dynamictrees:leaves0:8)
Block(3,14,2,dynamictrees:birchbranch:1)
Block(3,14,5,dynamictrees:leaves0:8)
Block(3,15,0,dynamictrees:leaves0:8)
Block(3,15,1,dynamictrees:leaves0:10)
Block(3,15,2,dynamictrees:birchbranch:1)
Block(3,15,4,dynamictrees:leaves0:8)
Block(3,16,-1,dynamictrees:leaves0:8)
Block(3,16,0,dynamictrees:leaves0:9)
Block(3,16,1,dynamictrees:leaves0:10)
Block(3,16,2,dynamictrees:leaves0:11)
Block(3,16,3,dynamictrees:leaves0:10)
Block(3,16,4,dynamictrees:leaves0:9)
Block(3,16,5,dynamictrees:leaves0:8)
Block(3,17,-1,dynamictrees:leaves0:8)
Block(3,17,0,dynamictrees:leaves0:10)
Block(3,17,1,dynamictrees:leaves0:11)
Block(3,17,2,dynamictrees:leaves0:10)
Block(3,17,3,dynamictrees:leaves0:11)
Block(3,17,4,dynamictrees:leaves0:10)
Block(3,17,5,dynamictrees:leaves0:8)
Block(3,17,6,dynamictrees:leaves0:8)
Block(3,18,0,dynamictrees:leaves0:8)
Block(3,18,1,dynamictrees:leaves0:8)
Block(3,18,2,dynamictrees:leaves0:9)
Block(3,18,3,dynamictrees:leaves0:10)
Block(3,18,4,dynamictrees:leaves0:9)
Block(3,18,5,dynamictrees:leaves0:8)
Block(3,18,6,dynamictrees:leaves0:8)
Block(3,19,2,dynamictrees:leaves0:8)
Block(3,19,3,dynamictrees:leaves0:8)
Block(3,19,4,dynamictrees:leaves0:8)
Block(4,9,-2,dynamictrees:leaves0:8)
Block(4,9,0,dynamictrees:leaves0:8)
Block(4,9,1,dynamictrees:leaves0:9)
Block(4,10,-1,dynamictrees:leaves0:8)
Block(4,10,0,dynamictrees:leaves0:11)
Block(4,10,1,dynamictrees:leaves0:10)
Block(4,10,2,dynamictrees:birchbranch:1)
Block(4,10,3,dynamictrees:leaves0:11)
Block(4,10,4,dynamictrees:leaves0:10)
Block(4,11,-2,dynamictrees:leaves0:8)
Block(4,11,-1,dynamictrees:leaves0:8)
Block(4,11,0,dynamictrees:leaves0:10)
Block(4,11,1,dynamictrees:leaves0:9)
Block(4,11,2,dynamictrees:leaves0:8)
Block(4,11,3,dynamictrees:leaves0:10)
Block(4,11,4,dynamictrees:leaves0:9)
Block(4,11,5,dynamictrees:leaves0:8)
Block(4,12,0,dynamictrees:leaves0:8)
Block(4,12,1,dynamictrees:leaves0:8)
Block(4,12,3,dynamictrees:leaves0:11)
Block(4,12,4,dynamictrees:leaves0:8)
Block(4,13,3,dynamictrees:leaves0:8)
Block(4,14,1,dynamictrees:leaves0:8)
Block(4,14,3,dynamictrees:leaves0:8)
Block(4,15,0,dynamictrees:leaves0:8)
Block(4,15,1,dynamictrees:leaves0:11)
Block(4,15,2,dynamictrees:birchbranch)
Block(4,15,3,dynamictrees:leaves0:11)
Block(4,15,4,dynamictrees:leaves0:8)
Block(4,16,0,dynamictrees:leaves0:8)
Block(4,16,1,dynamictrees:leaves0:10)
Block(4,16,2,dynamictrees:leaves0:11)
Block(4,16,3,dynamictrees:leaves0:10)
Block(4,16,4,dynamictrees:leaves0:8)
Block(4,17,0,dynamictrees:leaves0:8)
Block(4,17,1,dynamictrees:leaves0:8)
Block(4,17,2,dynamictrees:leaves0:8)
Block(4,17,3,dynamictrees:leaves0:8)
Block(4,17,4,dynamictrees:leaves0:8)
Block(4,18,2,dynamictrees:leaves0:8)
Block(4,18,3,dynamictrees:leaves0:8)
Block(4,18,4,dynamictrees:leaves0:8)
Block(5,9,-1,dynamictrees:leaves0:8)
Block(5,9,0,dynamictrees:leaves0:9)
Block(5,9,1,dynamictrees:leaves0:10)
Block(5,9,2,dynamictrees:leaves0:11)
Block(5,9,3,dynamictrees:leaves0:10)
Block(5,9,4,dynamictrees:leaves0:8)
Block(5,10,-1,dynamictrees:leaves0:8)
Block(5,10,0,dynamictrees:leaves0:10)
Block(5,10,1,dynamictrees:leaves0:11)
Block(5,10,2,dynamictrees:birchbranch)
Block(5,10,3,dynamictrees:leaves0:11)
Block(5,10,4,dynamictrees:leaves0:8)
Block(5,11,-1,dynamictrees:leaves0:8)
Block(5,11,0,dynamictrees:leaves0:9)
Block(5,11,1,dynamictrees:leaves0:10)
Block(5,11,2,dynamictrees:leaves0:11)
Block(5,11,3,dynamictrees:leaves0:10)
Block(5,11,4,dynamictrees:leaves0:8)
Block(5,12,0,dynamictrees:leaves0:8)
Block(5,12,1,dynamictrees:leaves0:8)
Block(5,12,2,dynamictrees:leaves0:8)
Block(5,12,3,dynamictrees:leaves0:8)
Block(5,14,1,dynamictrees:leaves0:8)
Block(5,14,2,dynamictrees:leaves0:8)
Block(5,14,3,dynamictrees:leaves0:8)
Block(5,15,0,dynamictrees:leaves0:8)
Block(5,15,1,dynamictrees:leaves0:10)
Block(5,15,2,dynamictrees:leaves0:11)
Block(5,15,3,dynamictrees:leaves0:10)
Block(5,15,4,dynamictrees:leaves0:8)
Block(5,16,0,dynamictrees:leaves0:8)
Block(5,16,1,dynamictrees:leaves0:9)
Block(5,16,2,dynamictrees:leaves0:10)
Block(5,16,3,dynamictrees:leaves0:9)
Block(5,16,4,dynamictrees:leaves0:8)
Block(5,17,1,dynamictrees:leaves0:8)
Block(5,17,2,dynamictrees:leaves0:8)
Block(5,17,3,dynamictrees:leaves0:8)
Block(6,9,0,dynamictrees:leaves0:8)
Block(6,9,1,dynamictrees:leaves0:9)
Block(6,9,2,dynamictrees:leaves0:10)
Block(6,9,3,dynamictrees:leaves0:9)
Block(6,9,4,dynamictrees:leaves0:8)
Block(6,10,-1,dynamictrees:leaves0:8)
Block(6,10,0,dynamictrees:leaves0:9)
Block(6,10,1,dynamictrees:leaves0:10)
Block(6,10,2,dynamictrees:leaves0:11)
Block(6,10,3,dynamictrees:leaves0:10)
Block(6,10,4,dynamictrees:leaves0:8)
Block(6,11,0,dynamictrees:leaves0:8)
Block(6,11,1,dynamictrees:leaves0:9)
Block(6,11,2,dynamictrees:leaves0:10)
Block(6,11,3,dynamictrees:leaves0:9)
Block(6,11,4,dynamictrees:leaves0:8)
Block(6,12,1,dynamictrees:leaves0:8)
Block(6,12,2,dynamictrees:leaves0:8)
Block(6,12,3,dynamictrees:leaves0:8)
Block(6,15,1,dynamictrees:leaves0:8)
Block(6,15,2,dynamictrees:leaves0:8)
Block(6,15,3,dynamictrees:leaves0:8)
Block(6,16,1,dynamictrees:leaves0:8)
Block(6,16,2,dynamictrees:leaves0:8)
Block(6,16,3,dynamictrees:leaves0:8)
Block(7,9,1,dynamictrees:leaves0:8)
Block(7,9,2,dynamictrees:leaves0:8)
Block(7,9,3,dynamictrees:leaves0:8)
Block(7,10,0,dynamictrees:leaves0:8)
Block(7,10,1,dynamictrees:leaves0:8)
Block(7,10,2,dynamictrees:leaves0:8)
Block(7,10,3,dynamictrees:leaves0:8)
Block(7,11,1,dynamictrees:leaves0:8)
Block(7,11,2,dynamictrees:leaves0:8)
Block(7,11,3,dynamictrees:leaves0:8)

#######################################################################
# +-----------------------------------------------------------------+ #
# |                            BO3 checks                           | #
# +-----------------------------------------------------------------+ #
#######################################################################

BlockCheck(1,-1,2,GRASS,DIRT,biomesoplenty:grass,UNKNOWN_BLOCK)

#######################################################################
# +-----------------------------------------------------------------+ #
# |                             Branches                            | #
# +-----------------------------------------------------------------+ #
#######################################################################


#######################################################################
# +-----------------------------------------------------------------+ #
# |                             Entities                            | #
# +-----------------------------------------------------------------+ #
#######################################################################


#######################################################################
# +-----------------------------------------------------------------+ #
# |                            Particles                            | #
# +-----------------------------------------------------------------+ #
#######################################################################


#######################################################################
# +-----------------------------------------------------------------+ #
# |                             Spawners                            | #
# +-----------------------------------------------------------------+ #
#######################################################################


#######################################################################
# +-----------------------------------------------------------------+ #
# |                             ModData                             | #
# +-----------------------------------------------------------------+ #
#######################################################################

