
#######################################################################
# +-----------------------------------------------------------------+ #
# |                            BO4 object                           | #
# +-----------------------------------------------------------------+ #
#######################################################################

Author: NLBlackEagle

Description: No description given

SettingsMode: WriteWithoutComments


#######################################################################
# +-----------------------------------------------------------------+ #
# |                          Main settings                          | #
# +-----------------------------------------------------------------+ #
#######################################################################

FixedRotation: 

Frequency: 0

SpawnHeight: highestBlock

UseCenterForHighestBlock: true

##############################
# Height Limits for the BO4. #
##############################

MinHeight: 0

MaxHeight: 255

InheritBO3: 

InheritBO3Rotation: NORTH

OverrideChildSettings: true

OverrideParentHeight: false

CanOverride: true

BranchFrequency: 0

BranchFrequencyGroup: 

MustBeBelowOther: false

MustBeInside: 

CannotBeInside: 

ReplacesBO3: 

MustBeInsideWorldBorders: false

CanSpawnOnWater: true

SpawnOnWaterOnly: false

SpawnUnderWater: false

SpawnAtWaterLevel: false

HeightOffset: 0

RemoveAir: false

ReplaceAbove: 

ReplaceBelow: 

ReplaceWithBiomeBlocks: false

ReplaceWithSurfaceBlock: GRASS

ReplaceWithGroundBlock: DIRT

ReplaceWithStoneBlock: STONE

SmoothRadius: 0

SmoothHeightOffset: 0

SmoothStartTop: false

SmoothStartWood: false

SmoothingSurfaceBlock: 

SmoothingGroundBlock: 

BO3Group: 

IsSpawnPoint: false

DoReplaceBlocks: true


#######################################################################
# +-----------------------------------------------------------------+ #
# |                              Blocks                             | #
# +-----------------------------------------------------------------+ #
#######################################################################

Block(-8,14,5,quark:limestone)
Block(-8,14,6,quark:limestone)
Block(-8,14,7,quark:limestone)
Block(-8,14,8,DOUBLE_STEP:0)
Block(-8,15,1,quark:limestone)
Block(-8,15,2,quark:limestone)
Block(-8,15,3,quark:limestone)
Block(-8,15,4,quark:limestone:1)
Block(-8,16,-1,quark:limestone)
Block(-8,16,0,quark:limestone:1)
Block(-8,16,1,quark:limestone)
Block(-8,17,-3,quark:limestone:1)
Block(-8,17,-2,quark:limestone)
Block(-8,18,-5,quark:limestone:1)
Block(-8,18,-4,quark:limestone)
Block(-8,18,-3,quark:limestone)
Block(-8,19,-6,quark:limestone:1)
Block(-8,19,-5,quark:limestone:1)
Block(-8,20,-7,quark:limestone:1)
Block(-8,20,-6,quark:limestone)
Block(-8,21,-7,quark:limestone)
Block(-7,14,5,quark:limestone:1)
Block(-7,14,6,quark:limestone)
Block(-7,14,7,quark:limestone)
Block(-7,14,8,quark:limestone:1)
Block(-7,15,1,quark:limestone:1)
Block(-7,15,2,quark:limestone)
Block(-7,15,3,quark:limestone)
Block(-7,15,4,quark:limestone:1)
Block(-7,15,5,quark:limestone)
Block(-7,16,-1,quark:limestone)
Block(-7,16,0,quark:limestone)
Block(-7,16,1,quark:limestone)
Block(-7,17,-3,quark:limestone)
Block(-7,17,-2,quark:limestone:1)
Block(-7,17,-1,quark:limestone)
Block(-7,18,-5,quark:limestone)
Block(-7,18,-4,quark:limestone)
Block(-7,18,-3,quark:limestone)
Block(-7,19,-6,quark:limestone:1)
Block(-7,19,-5,quark:limestone:1)
Block(-7,20,-7,quark:limestone)
Block(-7,20,-6,quark:limestone:1)
Block(-7,21,-7,quark:limestone:1)
Block(-6,14,5,quark:limestone)
Block(-6,14,6,quark:limestone)
Block(-6,14,7,quark:limestone)
Block(-6,14,8,quark:limestone)
Block(-6,15,2,quark:limestone)
Block(-6,15,3,quark:limestone:1)
Block(-6,15,4,quark:limestone:1)
Block(-6,15,5,quark:limestone)
Block(-6,16,-1,quark:limestone)
Block(-6,16,0,quark:limestone:1)
Block(-6,16,1,quark:limestone)
Block(-6,17,-3,quark:limestone)
Block(-6,17,-2,quark:limestone)
Block(-6,17,-1,quark:limestone:1)
Block(-6,17,0,VINE:4)
Block(-6,18,-5,quark:limestone:1)
Block(-6,18,-4,quark:limestone)
Block(-6,18,-3,quark:limestone)
Block(-6,19,-6,quark:limestone)
Block(-6,19,-5,quark:limestone:1)
Block(-6,20,-6,quark:limestone)
Block(-6,21,-7,quark:limestone:1)
Block(-6,21,-6,quark:limestone:1)
Block(-5,14,6,quark:limestone)
Block(-5,14,7,quark:limestone)
Block(-5,14,8,quark:limestone)
Block(-5,15,2,quark:limestone)
Block(-5,15,3,quark:limestone)
Block(-5,15,4,quark:limestone:1)
Block(-5,15,5,quark:limestone)
Block(-5,16,-1,quark:limestone:1)
Block(-5,16,0,quark:limestone:1)
Block(-5,16,1,quark:limestone)
Block(-5,16,2,quark:limestone:1)
Block(-5,17,-3,quark:limestone)
Block(-5,17,-2,quark:limestone)
Block(-5,17,-1,quark:limestone)
Block(-5,17,0,VINE:4)
Block(-5,18,-4,quark:limestone:1)
Block(-5,18,-3,quark:limestone:1)
Block(-5,19,-5,quark:limestone)
Block(-5,19,-4,quark:limestone)
Block(-5,20,-6,quark:limestone:1)
Block(-5,21,-7,quark:limestone)
Block(-5,21,-6,quark:limestone:1)
Block(-4,14,6,quark:limestone)
Block(-4,14,7,quark:limestone)
Block(-4,14,8,quark:limestone)
Block(-4,15,2,quark:limestone:1)
Block(-4,15,3,quark:limestone)
Block(-4,15,4,quark:limestone)
Block(-4,15,5,quark:limestone:1)
Block(-4,16,0,quark:limestone)
Block(-4,16,1,quark:limestone)
Block(-4,16,2,quark:limestone)
Block(-4,17,-3,quark:limestone)
Block(-4,17,-2,quark:limestone)
Block(-4,17,-1,quark:limestone:1)
Block(-4,17,0,VINE:4)
Block(-4,18,-4,quark:limestone:1)
Block(-4,18,-3,quark:limestone)
Block(-4,19,-5,quark:limestone)
Block(-4,19,-4,quark:limestone:1)
Block(-4,20,-6,quark:limestone)
Block(-4,20,-5,quark:limestone)
Block(-4,21,-7,quark:limestone)
Block(-4,21,-6,quark:limestone)
Block(-3,14,6,quark:limestone)
Block(-3,14,7,quark:limestone:1)
Block(-3,14,8,quark:limestone)
Block(-3,15,3,quark:limestone:1)
Block(-3,15,4,quark:limestone)
Block(-3,15,5,quark:limestone)
Block(-3,16,0,quark:limestone)
Block(-3,16,1,quark:limestone)
Block(-3,16,2,quark:limestone)
Block(-3,17,-2,quark:limestone)
Block(-3,17,-1,quark:limestone:1)
Block(-3,17,0,quark:limestone)
Block(-3,18,-4,quark:limestone)
Block(-3,18,-3,quark:limestone)
Block(-3,18,-2,quark:limestone)
Block(-3,19,-5,quark:limestone)
Block(-3,19,-4,quark:limestone)
Block(-3,20,-5,quark:limestone)
Block(-2,14,7,quark:limestone:1)
Block(-2,14,8,quark:limestone)
Block(-2,15,3,quark:limestone:1)
Block(-2,15,4,quark:limestone)
Block(-2,16,0,quark:limestone:1)
Block(-2,16,1,quark:limestone)
Block(-2,16,2,quark:limestone)
Block(-2,16,3,quark:limestone)
Block(-2,17,-2,quark:limestone)
Block(-2,17,-1,quark:limestone)
Block(-2,17,0,quark:limestone)
Block(-2,18,-3,quark:limestone)
Block(-2,18,-2,quark:limestone)
Block(-2,19,-5,quark:limestone:1)
Block(-2,19,-4,quark:limestone:1)
Block(-2,20,-5,quark:limestone)
Block(-2,21,-6,quark:limestone)
Block(-1,14,8,quark:limestone:1)
Block(-1,15,4,quark:limestone)
Block(-1,15,7,quark:limestone)
Block(-1,16,1,quark:limestone)
Block(-1,16,2,quark:limestone:1)
Block(-1,16,3,quark:limestone)
Block(-1,17,-1,quark:limestone)
Block(-1,17,1,quark:limestone)
Block(-1,18,-3,quark:limestone:1)
Block(-1,19,-4,quark:limestone:1)
Block(-1,19,-3,quark:limestone)
Block(-1,20,-5,quark:limestone)
Block(-1,20,-4,quark:limestone:1)
Block(-1,21,-5,quark:limestone)
Block(0,14,8,quark:limestone)
Block(0,15,4,quark:limestone)
Block(0,15,5,quark:limestone)
Block(0,15,6,quark:limestone)
Block(0,15,7,quark:limestone)
Block(0,15,8,quark:limestone)
Block(0,16,1,quark:limestone)
Block(0,16,2,quark:limestone)
Block(0,16,3,quark:limestone)
Block(0,16,4,quark:limestone)
Block(0,17,-1,quark:limestone)
Block(0,17,1,quark:limestone)
Block(0,18,-3,quark:limestone:1)
Block(0,18,-2,quark:limestone)
Block(0,18,-1,quark:limestone)
Block(0,19,-4,quark:limestone)
Block(0,20,-5,quark:limestone:1)
Block(0,20,-4,quark:limestone)
Block(0,21,-5,quark:limestone)
Block(1,15,5,quark:limestone:1)
Block(1,15,6,quark:limestone)
Block(1,15,7,quark:limestone)
Block(1,15,8,quark:limestone)
Block(1,16,2,quark:limestone)
Block(1,16,3,quark:limestone)
Block(1,16,4,quark:limestone)
Block(1,16,5,quark:limestone)
Block(1,17,-1,quark:limestone)
Block(1,17,2,quark:limestone:1)
Block(1,18,-2,quark:limestone:1)
Block(1,19,-3,quark:limestone)
Block(1,20,-4,quark:limestone:1)
Block(1,20,-3,quark:limestone)
Block(1,21,-5,quark:limestone)
Block(1,21,-4,quark:limestone)
Block(2,15,5,quark:limestone)
Block(2,15,6,quark:limestone:1)
Block(2,15,7,quark:limestone:1)
Block(2,16,2,quark:limestone:1)
Block(2,16,3,quark:limestone:1)
Block(2,16,4,quark:limestone)
Block(2,16,5,quark:limestone)
Block(2,16,6,VINE:8)
Block(2,17,1,quark:limestone)
Block(2,17,2,quark:limestone)
Block(2,18,-1,quark:limestone)
Block(2,19,-3,quark:limestone)
Block(2,19,-2,quark:limestone)
Block(2,20,-4,quark:limestone:1)
Block(2,20,-3,quark:limestone)
Block(2,21,-4,quark:limestone)
Block(3,15,6,quark:limestone)
Block(3,15,7,quark:limestone)
Block(3,15,8,quark:limestone:1)
Block(3,16,3,quark:limestone)
Block(3,16,4,quark:limestone:1)
Block(3,16,5,quark:limestone)
Block(3,16,6,quark:limestone:1)
Block(3,16,7,VINE:12)
Block(3,17,2,quark:limestone)
Block(3,17,3,quark:limestone)
Block(3,18,0,quark:limestone)
Block(3,18,1,quark:limestone)
Block(3,19,-2,quark:limestone)
Block(3,19,-1,quark:limestone:1)
Block(3,20,-3,quark:limestone:1)
Block(3,20,-2,quark:limestone)
Block(3,21,-4,quark:limestone)
Block(3,21,-3,quark:limestone)
Block(4,15,7,quark:limestone)
Block(4,15,8,quark:limestone:1)
Block(4,16,4,quark:limestone:1)
Block(4,16,5,quark:limestone:1)
Block(4,16,6,quark:limestone:1)
Block(4,16,7,quark:limestone:1)
Block(4,16,8,VINE:4)
Block(4,17,1,quark:limestone)
Block(4,17,2,quark:limestone)
Block(4,17,3,quark:limestone)
Block(4,17,4,quark:limestone:1)
Block(4,18,0,quark:limestone)
Block(4,19,-2,quark:limestone:1)
Block(4,19,-1,quark:limestone)
Block(4,19,0,quark:limestone)
Block(4,20,-3,quark:limestone)
Block(4,20,-2,quark:limestone)
Block(4,21,-3,quark:limestone:1)
Block(5,15,8,quark:limestone)
Block(5,16,5,quark:limestone)
Block(5,16,6,quark:limestone)
Block(5,16,7,quark:limestone:1)
Block(5,16,8,quark:limestone:1)
Block(5,17,2,quark:limestone)
Block(5,17,3,quark:limestone)
Block(5,17,4,quark:limestone:1)
Block(5,17,5,quark:limestone:1)
Block(5,18,1,quark:limestone)
Block(5,18,2,quark:limestone)
Block(5,19,-1,quark:limestone)
Block(5,19,0,quark:limestone:1)
Block(5,20,-2,quark:limestone:1)
Block(5,21,-3,quark:limestone)
Block(5,21,-2,quark:limestone)
Block(6,0,-6,DOUBLE_STEP:0)
Block(6,0,-5,DOUBLE_STEP:0)
Block(6,0,-4,DOUBLE_STEP:0)
Block(6,0,-3,DOUBLE_STEP:0)
Block(6,1,-6,DOUBLE_STEP:0)
Block(6,1,-5,DOUBLE_STEP:0)
Block(6,1,-4,DOUBLE_STEP:0)
Block(6,1,-3,DOUBLE_STEP:0)
Block(6,2,-6,DOUBLE_STEP:0)
Block(6,2,-5,DOUBLE_STEP:0)
Block(6,2,-4,IRON_FENCE:0)
Block(6,2,-3,DOUBLE_STEP:0)
Block(6,3,-6,DOUBLE_STEP:0)
Block(6,3,-5,DOUBLE_STEP:0)
Block(6,3,-4,DOUBLE_STEP:0)
Block(6,3,-3,IRON_FENCE:0)
Block(6,4,-6,DOUBLE_STEP:0)
Block(6,4,-5,DOUBLE_STEP:0)
Block(6,4,-4,DOUBLE_STEP:0)
Block(6,4,-3,DOUBLE_STEP:0)
Block(6,5,-6,DOUBLE_STEP:0)
Block(6,5,-5,DOUBLE_STEP:0)
Block(6,5,-4,DOUBLE_STEP:0)
Block(6,5,-3,DOUBLE_STEP:0)
Block(6,6,-6,DOUBLE_STEP:0)
Block(6,6,-5,DOUBLE_STEP:0)
Block(6,6,-4,DOUBLE_STEP:0)
Block(6,6,-3,DOUBLE_STEP:0)
Block(6,7,-6,STEP:0)
Block(6,7,-5,STEP:0)
Block(6,7,-4,STEP:0)
Block(6,7,-3,STEP:0)
Block(6,16,4,STEP:15)
Block(6,16,5,QUARTZ_BLOCK:0)
Block(6,16,6,quark:limestone:1)
Block(6,16,7,quark:limestone:1)
Block(6,16,8,quark:limestone)
Block(6,17,3,quark:limestone)
Block(6,17,4,quark:limestone)
Block(6,17,5,quark:limestone)
Block(6,17,6,quark:limestone)
Block(6,18,1,quark:limestone:1)
Block(6,18,2,quark:limestone)
Block(6,18,3,quark:limestone)
Block(6,19,-1,quark:limestone)
Block(6,19,0,quark:limestone:1)
Block(6,19,1,quark:limestone)
Block(6,20,-1,quark:limestone)
Block(6,20,0,quark:limestone)
Block(6,21,-2,quark:limestone)
Block(6,21,-1,quark:limestone)
Block(7,0,-6,IRON_FENCE:0)
Block(7,0,-5,DOUBLE_STEP:0)
Block(7,0,-4,DOUBLE_STEP:0)
Block(7,0,-3,DOUBLE_STEP:0)
Block(7,0,-2,DOUBLE_STEP:0)
Block(7,0,-1,DOUBLE_STEP:0)
Block(7,0,0,IRON_FENCE:0)
Block(7,0,1,DOUBLE_STEP:0)
Block(7,1,-6,DOUBLE_STEP:0)
Block(7,1,-5,DOUBLE_STEP:0)
Block(7,1,-4,DOUBLE_STEP:0)
Block(7,1,-3,DOUBLE_STEP:0)
Block(7,1,-2,DOUBLE_STEP:0)
Block(7,1,-1,DOUBLE_STEP:0)
Block(7,1,0,DOUBLE_STEP:0)
Block(7,1,1,DOUBLE_STEP:0)
Block(7,2,-6,DOUBLE_STEP:0)
Block(7,2,-5,DOUBLE_STEP:0)
Block(7,2,-4,DOUBLE_STEP:0)
Block(7,2,-3,DOUBLE_STEP:0)
Block(7,2,-2,DOUBLE_STEP:0)
Block(7,2,-1,DOUBLE_STEP:0)
Block(7,2,0,DOUBLE_STEP:0)
Block(7,2,1,DOUBLE_STEP:0)
Block(7,3,-6,DOUBLE_STEP:0)
Block(7,3,-5,DOUBLE_STEP:0)
Block(7,3,-4,DOUBLE_STEP:0)
Block(7,3,-3,DOUBLE_STEP:0)
Block(7,3,-2,IRON_FENCE:0)
Block(7,3,-1,DOUBLE_STEP:0)
Block(7,3,0,IRON_FENCE:0)
Block(7,3,1,DOUBLE_STEP:0)
Block(7,4,-6,DOUBLE_STEP:0)
Block(7,4,-5,DOUBLE_STEP:0)
Block(7,4,-4,DOUBLE_STEP:0)
Block(7,4,-3,DOUBLE_STEP:0)
Block(7,4,-2,DOUBLE_STEP:0)
Block(7,4,-1,DOUBLE_STEP:0)
Block(7,4,0,DOUBLE_STEP:0)
Block(7,4,1,DOUBLE_STEP:0)
Block(7,5,-6,DOUBLE_STEP:0)
Block(7,5,-5,DOUBLE_STEP:0)
Block(7,5,-4,DOUBLE_STEP:0)
Block(7,5,-3,DOUBLE_STEP:0)
Block(7,5,-2,DOUBLE_STEP:0)
Block(7,5,-1,DOUBLE_STEP:0)
Block(7,5,0,DOUBLE_STEP:0)
Block(7,5,1,DOUBLE_STEP:0)
Block(7,6,-6,DOUBLE_STEP:0)
Block(7,6,-5,IRON_FENCE:0)
Block(7,6,-4,DOUBLE_STEP:0)
Block(7,6,-3,DOUBLE_STEP:0)
Block(7,6,-2,DOUBLE_STEP:0)
Block(7,6,-1,DOUBLE_STEP:0)
Block(7,6,0,DOUBLE_STEP:0)
Block(7,6,1,DOUBLE_STEP:0)
Block(7,7,-6,STEP:0)
Block(7,7,-5,STEP:0)
Block(7,7,-4,QUARTZ_BLOCK:0)
Block(7,7,-3,STEP:0)
Block(7,7,-2,STEP:0)
Block(7,7,-1,STEP:0)
Block(7,7,0,STEP:0)
Block(7,7,1,STEP:0)
Block(7,8,-4,QUARTZ_BLOCK:0)
Block(7,9,-4,QUARTZ_BLOCK:0)
Block(7,10,-4,QUARTZ_STAIRS:0)
Block(7,16,4,QUARTZ_BLOCK:0)
Block(7,16,5,STEP:15)
Block(7,16,7,quark:limestone)
Block(7,16,8,quark:limestone:1)
Block(7,17,4,quark:limestone)
Block(7,17,5,quark:limestone)
Block(7,17,6,quark:limestone)
Block(7,17,7,quark:limestone)
Block(7,17,8,VINE:8)
Block(7,18,2,quark:limestone:1)
Block(7,18,3,quark:limestone:1)
Block(7,18,4,quark:limestone:1)
Block(7,19,0,quark:limestone)
Block(7,19,1,quark:limestone)
Block(7,19,2,quark:limestone)
Block(7,20,-1,quark:limestone:1)
Block(7,20,0,quark:limestone:1)
Block(7,20,1,VINE:12)
Block(7,21,-1,quark:limestone:1)
Block(7,21,0,quark:limestone:1)
Block(7,21,1,VINE:4)

#######################################################################
# +-----------------------------------------------------------------+ #
# |                             Branches                            | #
# +-----------------------------------------------------------------+ #
#######################################################################

Branch(0,0,-16,true,RadioTelescopeC3R0,NORTH,100.0,0)

#######################################################################
# +-----------------------------------------------------------------+ #
# |                             Entities                            | #
# +-----------------------------------------------------------------+ #
#######################################################################


#######################################################################
# +-----------------------------------------------------------------+ #
# |                            Particles                            | #
# +-----------------------------------------------------------------+ #
#######################################################################


#######################################################################
# +-----------------------------------------------------------------+ #
# |                             Spawners                            | #
# +-----------------------------------------------------------------+ #
#######################################################################


#######################################################################
# +-----------------------------------------------------------------+ #
# |                             ModData                             | #
# +-----------------------------------------------------------------+ #
#######################################################################

