
#######################################################################
# +-----------------------------------------------------------------+ #
# |                            BO4 object                           | #
# +-----------------------------------------------------------------+ #
#######################################################################

Author: NLBlackEagle

Description: No description given

SettingsMode: WriteWithoutComments


#######################################################################
# +-----------------------------------------------------------------+ #
# |                          Main settings                          | #
# +-----------------------------------------------------------------+ #
#######################################################################

FixedRotation: 

Frequency: 0

SpawnHeight: highestBlock

UseCenterForHighestBlock: true

##############################
# Height Limits for the BO4. #
##############################

MinHeight: 0

MaxHeight: 255

InheritBO3: 

InheritBO3Rotation: NORTH

OverrideChildSettings: true

OverrideParentHeight: false

CanOverride: true

BranchFrequency: 0

BranchFrequencyGroup: 

MustBeBelowOther: false

MustBeInside: 

CannotBeInside: 

ReplacesBO3: 

MustBeInsideWorldBorders: false

CanSpawnOnWater: true

SpawnOnWaterOnly: false

SpawnUnderWater: false

SpawnAtWaterLevel: false

HeightOffset: 0

RemoveAir: false

ReplaceAbove: 

ReplaceBelow: 

ReplaceWithBiomeBlocks: false

ReplaceWithSurfaceBlock: GRASS

ReplaceWithGroundBlock: DIRT

ReplaceWithStoneBlock: STONE

SmoothRadius: 0

SmoothHeightOffset: 0

SmoothStartTop: false

SmoothStartWood: false

SmoothingSurfaceBlock: 

SmoothingGroundBlock: 

BO3Group: 

IsSpawnPoint: false

DoReplaceBlocks: true


#######################################################################
# +-----------------------------------------------------------------+ #
# |                              Blocks                             | #
# +-----------------------------------------------------------------+ #
#######################################################################

Block(-8,14,-7,DOUBLE_STEP:0)
Block(-8,14,-6,DOUBLE_STEP:0)
Block(-8,14,-5,DOUBLE_STEP:0)
Block(-8,14,-4,DOUBLE_STEP:0)
Block(-8,14,-3,quark:limestone)
Block(-8,14,-2,quark:limestone)
Block(-8,14,-1,quark:limestone)
Block(-8,14,0,quark:limestone)
Block(-8,14,1,quark:limestone)
Block(-8,14,2,quark:limestone)
Block(-8,15,2,quark:limestone:1)
Block(-8,15,3,quark:limestone)
Block(-8,15,4,quark:limestone)
Block(-8,15,5,quark:limestone)
Block(-8,15,6,quark:limestone)
Block(-8,15,7,quark:limestone:1)
Block(-8,16,7,quark:limestone)
Block(-8,16,8,quark:limestone:1)
Block(-7,13,-7,quark:limestone)
Block(-7,13,-6,quark:limestone)
Block(-7,13,-5,quark:limestone)
Block(-7,14,-6,DOUBLE_STEP:0)
Block(-7,14,-5,IRON_FENCE:0)
Block(-7,14,-4,DOUBLE_STEP:0)
Block(-7,14,-3,DOUBLE_STEP:0)
Block(-7,14,-2,DOUBLE_STEP:0)
Block(-7,14,-1,quark:limestone:1)
Block(-7,14,0,quark:limestone)
Block(-7,14,1,quark:limestone)
Block(-7,14,2,quark:limestone)
Block(-7,14,3,quark:limestone:1)
Block(-7,15,3,quark:limestone:1)
Block(-7,15,4,quark:limestone)
Block(-7,15,5,quark:limestone)
Block(-7,15,6,quark:limestone:1)
Block(-7,15,7,quark:limestone:1)
Block(-7,16,7,quark:limestone:1)
Block(-7,16,8,quark:limestone)
Block(-6,13,-7,quark:limestone:1)
Block(-6,13,-6,quark:limestone)
Block(-6,13,-5,quark:limestone:1)
Block(-6,13,-4,quark:limestone)
Block(-6,13,-3,quark:limestone:1)
Block(-6,14,-3,IRON_FENCE:0)
Block(-6,14,-2,DOUBLE_STEP:0)
Block(-6,14,-1,DOUBLE_STEP:0)
Block(-6,14,0,quark:limestone:1)
Block(-6,14,1,quark:limestone)
Block(-6,14,2,quark:limestone)
Block(-6,14,3,quark:limestone:1)
Block(-6,14,4,quark:limestone)
Block(-6,15,4,quark:limestone)
Block(-6,15,5,quark:limestone)
Block(-6,15,6,quark:limestone)
Block(-6,15,7,quark:limestone)
Block(-6,15,8,quark:limestone)
Block(-6,16,8,quark:limestone)
Block(-5,13,-7,quark:limestone:1)
Block(-5,13,-6,quark:limestone)
Block(-5,13,-5,quark:limestone)
Block(-5,13,-4,quark:limestone)
Block(-5,13,-3,quark:limestone)
Block(-5,13,-2,quark:limestone)
Block(-5,14,-2,DOUBLE_STEP:0)
Block(-5,14,-1,DOUBLE_STEP:0)
Block(-5,14,0,DOUBLE_STEP:0)
Block(-5,14,1,quark:limestone)
Block(-5,14,2,quark:limestone)
Block(-5,14,3,quark:limestone)
Block(-5,14,4,quark:limestone:1)
Block(-5,15,5,quark:limestone)
Block(-5,15,6,quark:limestone)
Block(-5,15,7,quark:limestone:1)
Block(-5,15,8,quark:limestone:1)
Block(-4,13,-7,quark:limestone:1)
Block(-4,13,-6,quark:limestone)
Block(-4,13,-5,quark:limestone)
Block(-4,13,-4,quark:limestone)
Block(-4,13,-3,quark:limestone)
Block(-4,13,-2,quark:limestone)
Block(-4,13,-1,quark:limestone:1)
Block(-4,14,-1,DOUBLE_STEP:0)
Block(-4,14,0,DOUBLE_STEP:0)
Block(-4,14,1,DOUBLE_STEP:0)
Block(-4,14,2,quark:limestone:1)
Block(-4,14,3,quark:limestone:1)
Block(-4,14,4,quark:limestone)
Block(-4,14,5,quark:limestone)
Block(-4,15,5,quark:limestone:1)
Block(-4,15,6,quark:limestone)
Block(-4,15,7,quark:limestone)
Block(-4,15,8,quark:limestone)
Block(-3,13,-7,quark:limestone)
Block(-3,13,-6,quark:limestone)
Block(-3,13,-5,quark:limestone)
Block(-3,13,-4,quark:limestone:1)
Block(-3,13,-3,quark:limestone)
Block(-3,13,-2,quark:limestone:1)
Block(-3,13,-1,quark:limestone:1)
Block(-3,13,0,quark:limestone)
Block(-3,14,0,DOUBLE_STEP:0)
Block(-3,14,1,DOUBLE_STEP:0)
Block(-3,14,2,DOUBLE_STEP:0)
Block(-3,14,3,quark:limestone)
Block(-3,14,4,quark:limestone)
Block(-3,14,5,quark:limestone)
Block(-3,14,6,quark:limestone)
Block(-3,15,6,quark:limestone)
Block(-3,15,7,quark:limestone)
Block(-3,15,8,quark:limestone:1)
Block(-2,13,-7,quark:limestone)
Block(-2,13,-6,quark:limestone)
Block(-2,13,-5,quark:limestone)
Block(-2,13,-4,quark:limestone)
Block(-2,13,-3,quark:limestone)
Block(-2,13,-2,quark:limestone)
Block(-2,13,-1,quark:limestone:1)
Block(-2,13,0,quark:limestone)
Block(-2,13,1,quark:limestone)
Block(-2,14,1,DOUBLE_STEP:0)
Block(-2,14,2,IRON_FENCE:0)
Block(-2,14,3,quark:limestone)
Block(-2,14,4,quark:limestone)
Block(-2,14,5,quark:limestone)
Block(-2,14,6,quark:limestone)
Block(-2,15,6,quark:limestone)
Block(-2,15,7,quark:limestone)
Block(-2,15,8,quark:limestone)
Block(-1,13,-7,quark:limestone:1)
Block(-1,13,-6,quark:limestone)
Block(-1,13,-5,quark:limestone)
Block(-1,13,-4,quark:limestone)
Block(-1,13,-3,quark:limestone:1)
Block(-1,13,-2,quark:limestone)
Block(-1,13,-1,quark:limestone:1)
Block(-1,13,0,quark:limestone)
Block(-1,13,1,quark:limestone)
Block(-1,14,2,DOUBLE_STEP:0)
Block(-1,14,3,DOUBLE_STEP:0)
Block(-1,14,4,quark:limestone)
Block(-1,14,5,quark:limestone)
Block(-1,14,6,quark:limestone)
Block(-1,15,8,quark:limestone)
Block(0,13,-7,quark:limestone:1)
Block(0,13,-6,quark:limestone)
Block(0,13,-5,quark:limestone)
Block(0,13,-4,quark:limestone:1)
Block(0,13,-3,quark:limestone)
Block(0,13,-2,quark:limestone)
Block(0,13,-1,quark:limestone)
Block(0,13,0,quark:limestone:1)
Block(0,13,1,quark:limestone:1)
Block(0,13,2,quark:limestone:1)
Block(0,14,-6,STEP:7)
Block(0,14,-5,STEP:7)
Block(0,14,2,DOUBLE_STEP:0)
Block(0,14,3,DOUBLE_STEP:0)
Block(0,14,4,quark:limestone)
Block(0,14,7,quark:limestone:1)
Block(0,15,7,quark:limestone)
Block(0,15,8,quark:limestone:1)
Block(1,0,-7,DOUBLE_STEP:0)
Block(1,0,-6,DOUBLE_STEP:0)
Block(1,1,-7,DOUBLE_STEP:0)
Block(1,1,-6,DOUBLE_STEP:0)
Block(1,2,-7,DOUBLE_STEP:0)
Block(1,2,-6,DOUBLE_STEP:0)
Block(1,3,-7,DOUBLE_STEP:0)
Block(1,3,-6,DOUBLE_STEP:0)
Block(1,4,-7,DOUBLE_STEP:0)
Block(1,4,-6,DOUBLE_STEP:0)
Block(1,5,-7,DOUBLE_STEP:0)
Block(1,5,-6,DOUBLE_STEP:0)
Block(1,6,-7,DOUBLE_STEP:0)
Block(1,6,-6,DOUBLE_STEP:0)
Block(1,7,-7,STEP:0)
Block(1,7,-6,STEP:0)
Block(1,12,-7,IRON_TRAPDOOR:10)
Block(1,12,-6,IRON_TRAPDOOR:10)
Block(1,13,-7,quark:limestone)
Block(1,13,-6,quark:limestone:1)
Block(1,13,-5,quark:limestone)
Block(1,13,-4,quark:limestone:1)
Block(1,13,-3,quark:limestone:1)
Block(1,13,-2,quark:limestone)
Block(1,13,-1,quark:limestone)
Block(1,13,0,quark:limestone)
Block(1,13,1,quark:limestone)
Block(1,13,2,quark:limestone)
Block(1,14,2,DOUBLE_STEP:0)
Block(1,14,3,DOUBLE_STEP:0)
Block(1,14,4,quark:limestone)
Block(1,14,5,quark:limestone)
Block(1,14,7,quark:limestone:1)
Block(1,15,8,quark:limestone)
Block(2,0,-7,DOUBLE_STEP:0)
Block(2,0,-6,DOUBLE_STEP:0)
Block(2,1,-7,DOUBLE_STEP:0)
Block(2,1,-6,DOUBLE_STEP:0)
Block(2,2,-7,DOUBLE_STEP:0)
Block(2,2,-6,DOUBLE_STEP:0)
Block(2,3,-7,DOUBLE_STEP:0)
Block(2,3,-6,IRON_FENCE:0)
Block(2,4,-7,DOUBLE_STEP:0)
Block(2,4,-6,DOUBLE_STEP:0)
Block(2,5,-7,DOUBLE_STEP:0)
Block(2,5,-6,DOUBLE_STEP:0)
Block(2,6,-7,DOUBLE_STEP:0)
Block(2,6,-6,IRON_FENCE:0)
Block(2,7,-7,QUARTZ_BLOCK:0)
Block(2,7,-6,STEP:0)
Block(2,8,-7,QUARTZ_BLOCK:0)
Block(2,9,-7,QUARTZ_BLOCK:0)
Block(2,10,-7,QUARTZ_BLOCK:0)
Block(2,11,-7,QUARTZ_BLOCK:0)
Block(2,12,-7,QUARTZ_STAIRS:7)
Block(2,12,-6,IRON_TRAPDOOR:9)
Block(2,13,-7,quark:limestone)
Block(2,13,-6,quark:limestone)
Block(2,13,-5,quark:limestone)
Block(2,13,-4,quark:limestone)
Block(2,13,-3,quark:limestone:1)
Block(2,13,-2,quark:limestone:1)
Block(2,13,-1,quark:limestone)
Block(2,13,0,quark:limestone)
Block(2,13,1,quark:limestone)
Block(2,13,2,quark:limestone)
Block(2,14,-5,STEP:7)
Block(2,14,3,DOUBLE_STEP:0)
Block(2,14,4,DOUBLE_STEP:0)
Block(2,14,5,quark:limestone:1)
Block(2,14,7,quark:limestone:1)
Block(2,15,8,quark:limestone:1)
Block(3,0,-7,DOUBLE_STEP:0)
Block(3,0,-6,DOUBLE_STEP:0)
Block(3,1,-7,DOUBLE_STEP:0)
Block(3,1,-6,DOUBLE_STEP:0)
Block(3,2,-7,DOUBLE_STEP:0)
Block(3,2,-6,DOUBLE_STEP:0)
Block(3,3,-7,DOUBLE_STEP:0)
Block(3,3,-6,DOUBLE_STEP:0)
Block(3,4,-7,DOUBLE_STEP:0)
Block(3,4,-6,DOUBLE_STEP:0)
Block(3,5,-7,IRON_FENCE:0)
Block(3,5,-6,DOUBLE_STEP:0)
Block(3,6,-7,DOUBLE_STEP:0)
Block(3,6,-6,IRON_FENCE:0)
Block(3,7,-7,QUARTZ_BLOCK:0)
Block(3,7,-6,STEP:0)
Block(3,8,-7,QUARTZ_BLOCK:0)
Block(3,10,-7,STEP:15)
Block(3,11,-7,QUARTZ_STAIRS:7)
Block(3,12,-7,QUARTZ_STAIRS:7)
Block(3,12,-6,IRON_TRAPDOOR:9)
Block(3,13,-7,DOUBLE_STEP:0)
Block(3,13,-6,DOUBLE_STEP:0)
Block(3,13,-5,DOUBLE_STEP:0)
Block(3,13,-4,DOUBLE_STEP:0)
Block(3,13,-3,DOUBLE_STEP:0)
Block(3,13,-2,DOUBLE_STEP:0)
Block(3,13,-1,DOUBLE_STEP:0)
Block(3,13,0,DOUBLE_STEP:0)
Block(3,13,1,DOUBLE_STEP:0)
Block(3,13,2,DOUBLE_STEP:0)
Block(3,14,-7,STAINED_GLASS_PANE:7)
Block(3,14,3,DOUBLE_STEP:0)
Block(3,14,4,DOUBLE_STEP:0)
Block(3,14,5,DOUBLE_STEP:0)
Block(3,14,6,DOUBLE_STEP:0)
Block(3,14,7,DOUBLE_STEP:0)
Block(3,15,-7,IRON_TRAPDOOR:2)
Block(3,15,8,DOUBLE_STEP:0)
Block(4,0,-7,DOUBLE_STEP:0)
Block(4,0,-6,DOUBLE_STEP:0)
Block(4,0,-5,DOUBLE_STEP:0)
Block(4,0,-4,DOUBLE_STEP:0)
Block(4,1,-7,DOUBLE_STEP:0)
Block(4,1,-6,DOUBLE_STEP:0)
Block(4,1,-5,DOUBLE_STEP:0)
Block(4,1,-4,DOUBLE_STEP:0)
Block(4,2,-7,DOUBLE_STEP:0)
Block(4,2,-6,DOUBLE_STEP:0)
Block(4,2,-5,DOUBLE_STEP:0)
Block(4,2,-4,IRON_FENCE:0)
Block(4,3,-7,DOUBLE_STEP:0)
Block(4,3,-6,DOUBLE_STEP:0)
Block(4,3,-5,DOUBLE_STEP:0)
Block(4,3,-4,DOUBLE_STEP:0)
Block(4,4,-7,DOUBLE_STEP:0)
Block(4,4,-6,DOUBLE_STEP:0)
Block(4,4,-5,DOUBLE_STEP:0)
Block(4,4,-4,DOUBLE_STEP:0)
Block(4,5,-7,DOUBLE_STEP:0)
Block(4,5,-6,DOUBLE_STEP:0)
Block(4,5,-5,DOUBLE_STEP:0)
Block(4,5,-4,DOUBLE_STEP:0)
Block(4,6,-7,DOUBLE_STEP:0)
Block(4,6,-6,DOUBLE_STEP:0)
Block(4,6,-5,DOUBLE_STEP:0)
Block(4,6,-4,DOUBLE_STEP:0)
Block(4,7,-7,QUARTZ_BLOCK:0)
Block(4,7,-6,STEP:0)
Block(4,7,-5,STEP:0)
Block(4,7,-4,STEP:0)
Block(4,9,-7,STEP:7)
Block(4,11,-7,QUARTZ_STAIRS:7)
Block(4,12,-6,IRON_TRAPDOOR:9)
Block(4,13,-7,DOUBLE_STEP:0)
Block(4,13,-6,DOUBLE_STEP:0)
Block(4,13,-5,DOUBLE_STEP:0)
Block(4,13,-4,DOUBLE_STEP:0)
Block(4,13,-3,DOUBLE_STEP:0)
Block(4,13,-2,DOUBLE_STEP:0)
Block(4,13,-1,DOUBLE_STEP:0)
Block(4,13,0,DOUBLE_STEP:0)
Block(4,13,1,DOUBLE_STEP:0)
Block(4,13,2,DOUBLE_STEP:0)
Block(4,13,3,IRON_FENCE:0)
Block(4,14,-7,QUARTZ_BLOCK:0)
Block(4,14,-6,QUARTZ_BLOCK:0)
Block(4,14,-5,QUARTZ_STAIRS:3)
Block(4,14,3,DOUBLE_STEP:0)
Block(4,14,4,DOUBLE_STEP:0)
Block(4,14,5,DOUBLE_STEP:0)
Block(4,14,6,IRON_FENCE:0)
Block(4,14,7,DOUBLE_STEP:0)
Block(4,15,-6,COBBLE_WALL:1)
Block(4,15,6,quark:iron_plate:1)
Block(4,15,7,quark:iron_plate:1)
Block(4,15,8,IRON_FENCE:0)
Block(4,16,-6,COBBLE_WALL:0)
Block(4,16,6,SMOOTH_STAIRS:2)
Block(4,16,7,quark:iron_plate:1)
Block(4,16,8,quark:iron_plate:1)
Block(4,17,-7,COBBLE_WALL:0)
Block(4,17,-6,COBBLE_WALL:1)
Block(4,17,7,SMOOTH_STAIRS:2)
Block(4,17,8,COBBLE_WALL:0)
Block(4,18,-7,COBBLE_WALL:1)
Block(4,19,-7,COBBLE_WALL:1)
Block(4,20,-7,COBBLE_WALL:0)
Block(5,0,-7,DOUBLE_STEP:0)
Block(5,0,-6,DOUBLE_STEP:0)
Block(5,0,-5,DOUBLE_STEP:0)
Block(5,0,-4,DOUBLE_STEP:0)
Block(5,1,-7,DOUBLE_STEP:0)
Block(5,1,-6,IRON_FENCE:0)
Block(5,1,-5,DOUBLE_STEP:0)
Block(5,1,-4,DOUBLE_STEP:0)
Block(5,2,-7,DOUBLE_STEP:0)
Block(5,2,-6,DOUBLE_STEP:0)
Block(5,2,-5,IRON_FENCE:0)
Block(5,2,-4,DOUBLE_STEP:0)
Block(5,3,-7,DOUBLE_STEP:0)
Block(5,3,-6,DOUBLE_STEP:0)
Block(5,3,-5,DOUBLE_STEP:0)
Block(5,3,-4,DOUBLE_STEP:0)
Block(5,4,-7,DOUBLE_STEP:0)
Block(5,4,-6,DOUBLE_STEP:0)
Block(5,4,-5,DOUBLE_STEP:0)
Block(5,4,-4,DOUBLE_STEP:0)
Block(5,5,-7,DOUBLE_STEP:0)
Block(5,5,-6,DOUBLE_STEP:0)
Block(5,5,-5,DOUBLE_STEP:0)
Block(5,5,-4,DOUBLE_STEP:0)
Block(5,6,-7,IRON_FENCE:0)
Block(5,6,-6,IRON_FENCE:0)
Block(5,6,-5,DOUBLE_STEP:0)
Block(5,6,-4,DOUBLE_STEP:0)
Block(5,7,-7,QUARTZ_BLOCK:0)
Block(5,7,-6,STEP:0)
Block(5,7,-5,DOUBLE_STEP:0)
Block(5,7,-4,STEP:0)
Block(5,8,-5,COBBLE_WALL:0)
Block(5,9,-5,COBBLE_WALL:0)
Block(5,10,-5,COBBLE_WALL:0)
Block(5,11,-7,QUARTZ_STAIRS:7)
Block(5,11,-5,COBBLE_WALL:0)
Block(5,12,-7,IRON_TRAPDOOR:9)
Block(5,12,-6,IRON_TRAPDOOR:9)
Block(5,12,-5,COBBLE_WALL:0)
Block(5,12,-4,COBBLE_WALL:0)
Block(5,12,-3,COBBLE_WALL:0)
Block(5,12,-2,COBBLE_WALL:0)
Block(5,12,-1,COBBLE_WALL:0)
Block(5,12,0,COBBLE_WALL:0)
Block(5,12,1,COBBLE_WALL:1)
Block(5,12,2,COBBLE_WALL:1)
Block(5,12,3,COBBLE_WALL:0)
Block(5,12,4,COBBLE_WALL:0)
Block(5,13,-7,DOUBLE_STEP:0)
Block(5,13,-6,DOUBLE_STEP:0)
Block(5,13,-5,DOUBLE_STEP:0)
Block(5,13,-4,DOUBLE_STEP:0)
Block(5,13,-3,DOUBLE_STEP:0)
Block(5,13,-2,DOUBLE_STEP:0)
Block(5,13,-1,DOUBLE_STEP:0)
Block(5,13,0,IRON_FENCE:0)
Block(5,13,1,DOUBLE_STEP:0)
Block(5,13,2,DOUBLE_STEP:0)
Block(5,13,3,DOUBLE_STEP:0)
Block(5,13,4,COBBLE_WALL:0)
Block(5,13,5,COBBLE_WALL:1)
Block(5,13,6,COBBLE_WALL:1)
Block(5,13,7,COBBLE_WALL:0)
Block(5,13,8,COBBLE_WALL:0)
Block(5,14,-7,STEP:7)
Block(5,14,-6,STEP:7)
Block(5,14,-4,STEP:7)
Block(5,14,-3,QUARTZ_STAIRS:2)
Block(5,14,-2,COBBLE_WALL:0)
Block(5,14,-1,COBBLE_WALL:0)
Block(5,14,0,COBBLE_WALL:1)
Block(5,14,1,COBBLE_WALL:0)
Block(5,14,2,COBBLE_WALL:0)
Block(5,14,3,DOUBLE_STEP:0)
Block(5,14,4,DOUBLE_STEP:0)
Block(5,14,5,DOUBLE_STEP:0)
Block(5,14,6,IRON_FENCE:0)
Block(5,14,7,IRON_FENCE:0)
Block(5,14,8,IRON_FENCE:0)
Block(5,15,2,COBBLE_WALL:0)
Block(5,15,3,COBBLE_WALL:1)
Block(5,15,4,COBBLE_WALL:1)
Block(5,15,5,COBBLE_WALL:0)
Block(5,15,6,COBBLE_WALL:1)
Block(5,15,8,DOUBLE_STEP:0)
Block(6,0,-7,DOUBLE_STEP:0)
Block(6,0,-6,DOUBLE_STEP:0)
Block(6,0,-5,DOUBLE_STEP:0)
Block(6,0,-4,DOUBLE_STEP:0)
Block(6,1,-7,DOUBLE_STEP:0)
Block(6,1,-6,DOUBLE_STEP:0)
Block(6,1,-5,DOUBLE_STEP:0)
Block(6,1,-4,DOUBLE_STEP:0)
Block(6,2,-7,DOUBLE_STEP:0)
Block(6,2,-6,DOUBLE_STEP:0)
Block(6,2,-5,DOUBLE_STEP:0)
Block(6,2,-4,DOUBLE_STEP:0)
Block(6,3,-7,DOUBLE_STEP:0)
Block(6,3,-6,DOUBLE_STEP:0)
Block(6,3,-5,DOUBLE_STEP:0)
Block(6,3,-4,IRON_FENCE:0)
Block(6,4,-7,DOUBLE_STEP:0)
Block(6,4,-6,DOUBLE_STEP:0)
Block(6,4,-5,DOUBLE_STEP:0)
Block(6,4,-4,IRON_FENCE:0)
Block(6,5,-7,DOUBLE_STEP:0)
Block(6,5,-6,DOUBLE_STEP:0)
Block(6,5,-5,DOUBLE_STEP:0)
Block(6,5,-4,DOUBLE_STEP:0)
Block(6,6,-7,DOUBLE_STEP:0)
Block(6,6,-6,IRON_FENCE:0)
Block(6,6,-5,DOUBLE_STEP:0)
Block(6,6,-4,DOUBLE_STEP:0)
Block(6,7,-7,QUARTZ_BLOCK:0)
Block(6,7,-6,STEP:0)
Block(6,7,-5,STEP:0)
Block(6,7,-4,STEP:0)
Block(6,9,-7,STEP:7)
Block(6,10,-7,STEP:7)
Block(6,11,-7,QUARTZ_STAIRS:7)
Block(6,12,-6,IRON_TRAPDOOR:9)
Block(6,13,-7,DOUBLE_STEP:0)
Block(6,13,-6,DOUBLE_STEP:0)
Block(6,13,-5,DOUBLE_STEP:0)
Block(6,13,-4,DOUBLE_STEP:0)
Block(6,13,-3,DOUBLE_STEP:0)
Block(6,13,-2,DOUBLE_STEP:0)
Block(6,13,-1,DOUBLE_STEP:0)
Block(6,13,0,DOUBLE_STEP:0)
Block(6,13,1,DOUBLE_STEP:0)
Block(6,13,2,DOUBLE_STEP:0)
Block(6,13,3,DOUBLE_STEP:0)
Block(6,14,-7,QUARTZ_BLOCK:0)
Block(6,14,-6,QUARTZ_BLOCK:0)
Block(6,14,-5,QUARTZ_STAIRS:3)
Block(6,14,3,DOUBLE_STEP:0)
Block(6,14,4,DOUBLE_STEP:0)
Block(6,14,5,DOUBLE_STEP:0)
Block(6,14,6,DOUBLE_STEP:0)
Block(6,14,7,IRON_FENCE:0)
Block(6,15,-6,COBBLE_WALL:0)
Block(6,15,6,quark:iron_plate:1)
Block(6,15,7,quark:iron_plate:1)
Block(6,15,8,DOUBLE_STEP:0)
Block(6,16,-6,COBBLE_WALL:0)
Block(6,16,6,SMOOTH_STAIRS:2)
Block(6,16,7,quark:iron_plate:1)
Block(6,16,8,quark:iron_plate:1)
Block(6,17,-7,COBBLE_WALL:1)
Block(6,17,-6,COBBLE_WALL:0)
Block(6,17,7,SMOOTH_STAIRS:2)
Block(6,17,8,COBBLE_WALL:0)
Block(6,18,-7,COBBLE_WALL:0)
Block(6,19,-7,COBBLE_WALL:0)
Block(6,20,-7,COBBLE_WALL:1)
Block(7,0,-7,DOUBLE_STEP:0)
Block(7,0,-6,IRON_FENCE:0)
Block(7,1,-7,DOUBLE_STEP:0)
Block(7,1,-6,DOUBLE_STEP:0)
Block(7,2,-7,DOUBLE_STEP:0)
Block(7,2,-6,DOUBLE_STEP:0)
Block(7,3,-7,DOUBLE_STEP:0)
Block(7,3,-6,DOUBLE_STEP:0)
Block(7,4,-7,DOUBLE_STEP:0)
Block(7,4,-6,DOUBLE_STEP:0)
Block(7,5,-7,DOUBLE_STEP:0)
Block(7,5,-6,IRON_FENCE:0)
Block(7,6,-7,DOUBLE_STEP:0)
Block(7,6,-6,DOUBLE_STEP:0)
Block(7,7,-7,QUARTZ_BLOCK:0)
Block(7,7,-6,STEP:0)
Block(7,8,-7,QUARTZ_BLOCK:0)
Block(7,11,-7,QUARTZ_STAIRS:7)
Block(7,12,-7,QUARTZ_STAIRS:7)
Block(7,12,-6,IRON_TRAPDOOR:9)
Block(7,13,-7,DOUBLE_STEP:0)
Block(7,13,-6,DOUBLE_STEP:0)
Block(7,13,-5,DOUBLE_STEP:0)
Block(7,13,-4,DOUBLE_STEP:0)
Block(7,13,-3,DOUBLE_STEP:0)
Block(7,13,-2,DOUBLE_STEP:0)
Block(7,13,-1,DOUBLE_STEP:0)
Block(7,13,0,DOUBLE_STEP:0)
Block(7,13,1,DOUBLE_STEP:0)
Block(7,13,2,DOUBLE_STEP:0)
Block(7,14,-7,STAINED_GLASS_PANE:7)
Block(7,14,3,DOUBLE_STEP:0)
Block(7,14,4,DOUBLE_STEP:0)
Block(7,14,5,DOUBLE_STEP:0)
Block(7,14,6,DOUBLE_STEP:0)
Block(7,14,7,DOUBLE_STEP:0)
Block(7,15,-7,IRON_TRAPDOOR:3)
Block(7,15,8,DOUBLE_STEP:0)

#######################################################################
# +-----------------------------------------------------------------+ #
# |                             Branches                            | #
# +-----------------------------------------------------------------+ #
#######################################################################

Branch(16,0,0,true,RadioTelescopeC3R3,NORTH,100.0,0)
Branch(-16,0,0,true,RadioTelescopeC1R3,NORTH,100.0,0)

#######################################################################
# +-----------------------------------------------------------------+ #
# |                             Entities                            | #
# +-----------------------------------------------------------------+ #
#######################################################################


#######################################################################
# +-----------------------------------------------------------------+ #
# |                            Particles                            | #
# +-----------------------------------------------------------------+ #
#######################################################################


#######################################################################
# +-----------------------------------------------------------------+ #
# |                             Spawners                            | #
# +-----------------------------------------------------------------+ #
#######################################################################


#######################################################################
# +-----------------------------------------------------------------+ #
# |                             ModData                             | #
# +-----------------------------------------------------------------+ #
#######################################################################

