
#######################################################################
# +-----------------------------------------------------------------+ #
# |                            BO4 object                           | #
# +-----------------------------------------------------------------+ #
#######################################################################

Author: NLBlackEagle

Description: No description given

SettingsMode: WriteDisable


#######################################################################
# +-----------------------------------------------------------------+ #
# |                          Main settings                          | #
# +-----------------------------------------------------------------+ #
#######################################################################

Frequency: 0

SpawnHeight: highestBlock

UseCenterForHighestBlock: true

##############################
# Height Limits for the BO4. #
##############################

MinHeight: 0

MaxHeight: 255

InheritBO3: 

InheritBO3Rotation: NORTH

OverrideChildSettings: true

OverrideParentHeight: false

CanOverride: true

BranchFrequency: 0

BranchFrequencyGroup: 

MustBeBelowOther: false

MustBeInside: 

CannotBeInside: 

ReplacesBO3: 

MustBeInsideWorldBorders: false

CanSpawnOnWater: true

SpawnOnWaterOnly: false

SpawnUnderWater: false

SpawnAtWaterLevel: false

HeightOffset: 0

RemoveAir: false

ReplaceAbove: 

ReplaceBelow: 

ReplaceWithBiomeBlocks: false

ReplaceWithSurfaceBlock: GRASS

ReplaceWithGroundBlock: DIRT

ReplaceWithStoneBlock: STONE

SmoothRadius: 0

SmoothHeightOffset: 0

SmoothStartTop: false

SmoothStartWood: false

SmoothingSurfaceBlock: 

SmoothingGroundBlock: 

BO3Group: 

IsSpawnPoint: false

DoReplaceBlocks: false


#######################################################################
# +-----------------------------------------------------------------+ #
# |                              Blocks                             | #
# +-----------------------------------------------------------------+ #
#######################################################################

Block(-8,-50,3,COBBLESTONE:0)
Block(-8,-50,4,COBBLESTONE:0)
Block(-8,-50,5,COBBLESTONE:0)
Block(-8,-50,6,STONE:5)
Block(-8,-50,7,COBBLESTONE:0)
Block(-8,-50,8,STONE:5)
Block(-8,-49,3,COBBLESTONE:0)
Block(-8,-49,4,COBBLESTONE:0)
Block(-8,-49,5,COBBLESTONE:0)
Block(-8,-49,6,STONE:5)
Block(-8,-49,7,COBBLESTONE:0)
Block(-8,-49,8,STONE:5)
Block(-8,-48,3,COBBLESTONE:0)
Block(-8,-48,4,COBBLESTONE:0)
Block(-8,-48,5,COBBLESTONE:0)
Block(-8,-48,6,STONE:5)
Block(-8,-48,7,COBBLESTONE:0)
Block(-8,-48,8,STONE:5)
Block(-8,-47,3,COBBLESTONE:0)
Block(-8,-47,4,COBBLESTONE:0)
Block(-8,-47,5,COBBLESTONE:0)
Block(-8,-47,6,STONE:5)
Block(-8,-47,7,COBBLESTONE:0)
Block(-8,-47,8,STONE:5)
Block(-8,-46,3,COBBLESTONE:0)
Block(-8,-46,4,COBBLESTONE:0)
Block(-8,-46,5,COBBLESTONE:0)
Block(-8,-46,6,STONE:5)
Block(-8,-46,7,COBBLESTONE:0)
Block(-8,-46,8,STONE:5)
Block(-8,-45,3,COBBLESTONE:0)
Block(-8,-45,4,COBBLESTONE:0)
Block(-8,-45,5,COBBLESTONE:0)
Block(-8,-45,6,STONE:5)
Block(-8,-45,7,COBBLESTONE:0)
Block(-8,-45,8,STONE:5)
Block(-8,-44,3,COBBLESTONE:0)
Block(-8,-44,4,COBBLESTONE:0)
Block(-8,-44,5,COBBLESTONE:0)
Block(-8,-44,6,STONE:5)
Block(-8,-44,7,COBBLESTONE:0)
Block(-8,-44,8,STONE:5)
Block(-8,-43,3,COBBLESTONE:0)
Block(-8,-43,4,COBBLESTONE:0)
Block(-8,-43,5,COBBLESTONE:0)
Block(-8,-43,6,STONE:5)
Block(-8,-43,7,COBBLESTONE:0)
Block(-8,-43,8,STONE:5)
Block(-8,-42,3,COBBLESTONE:0)
Block(-8,-42,4,COBBLESTONE:0)
Block(-8,-42,5,COBBLESTONE:0)
Block(-8,-42,6,STONE:5)
Block(-8,-42,7,COBBLESTONE:0)
Block(-8,-42,8,STONE:5)
Block(-8,-41,3,COBBLESTONE:0)
Block(-8,-41,4,COBBLESTONE:0)
Block(-8,-41,5,COBBLESTONE:0)
Block(-8,-41,6,STONE:5)
Block(-8,-41,7,COBBLESTONE:0)
Block(-8,-41,8,STONE:5)
Block(-8,-40,3,COBBLESTONE:0)
Block(-8,-40,4,COBBLESTONE:0)
Block(-8,-40,5,COBBLESTONE:0)
Block(-8,-40,6,STONE:5)
Block(-8,-40,7,COBBLESTONE:0)
Block(-8,-40,8,STONE:5)
Block(-8,-39,3,COBBLESTONE:0)
Block(-8,-39,4,COBBLESTONE:0)
Block(-8,-39,5,COBBLESTONE:0)
Block(-8,-39,6,STONE:5)
Block(-8,-39,7,COBBLESTONE:0)
Block(-8,-39,8,STONE:5)
Block(-8,-38,3,COBBLESTONE:0)
Block(-8,-38,4,COBBLESTONE:0)
Block(-8,-38,5,COBBLESTONE:0)
Block(-8,-38,6,STONE:5)
Block(-8,-38,7,COBBLESTONE:0)
Block(-8,-38,8,STONE:5)
Block(-8,-37,3,COBBLESTONE:0)
Block(-8,-37,4,COBBLESTONE:0)
Block(-8,-37,5,COBBLESTONE:0)
Block(-8,-37,6,STONE:5)
Block(-8,-37,7,COBBLESTONE:0)
Block(-8,-37,8,STONE:5)
Block(-8,-36,3,COBBLESTONE:0)
Block(-8,-36,4,COBBLESTONE:0)
Block(-8,-36,5,COBBLESTONE:0)
Block(-8,-36,6,STONE:5)
Block(-8,-36,7,COBBLESTONE:0)
Block(-8,-36,8,STONE:5)
Block(-8,-35,3,COBBLESTONE:0)
Block(-8,-35,4,COBBLESTONE:0)
Block(-8,-35,5,COBBLESTONE:0)
Block(-8,-35,6,STONE:5)
Block(-8,-35,7,COBBLESTONE:0)
Block(-8,-35,8,STONE:5)
Block(-8,-34,3,COBBLESTONE:0)
Block(-8,-34,4,COBBLESTONE:0)
Block(-8,-34,5,COBBLESTONE:0)
Block(-8,-34,6,STONE:5)
Block(-8,-34,7,COBBLESTONE:0)
Block(-8,-34,8,STONE:5)
Block(-8,-33,3,COBBLESTONE:0)
Block(-8,-33,4,COBBLESTONE:0)
Block(-8,-33,5,COBBLESTONE:0)
Block(-8,-33,6,STONE:5)
Block(-8,-33,7,COBBLESTONE:0)
Block(-8,-33,8,STONE:5)
Block(-8,-32,3,COBBLESTONE:0)
Block(-8,-32,4,COBBLESTONE:0)
Block(-8,-32,5,COBBLESTONE:0)
Block(-8,-32,6,STONE:5)
Block(-8,-32,7,COBBLESTONE:0)
Block(-8,-32,8,STONE:5)
Block(-8,-31,3,COBBLESTONE:0)
Block(-8,-31,4,COBBLESTONE:0)
Block(-8,-31,5,COBBLESTONE:0)
Block(-8,-31,6,STONE:5)
Block(-8,-31,7,COBBLESTONE:0)
Block(-8,-31,8,STONE:5)
Block(-8,-30,3,COBBLESTONE:0)
Block(-8,-30,4,COBBLESTONE:0)
Block(-8,-30,5,COBBLESTONE:0)
Block(-8,-30,6,STONE:5)
Block(-8,-30,7,COBBLESTONE:0)
Block(-8,-30,8,STONE:5)
Block(-8,-29,3,COBBLESTONE:0)
Block(-8,-29,4,COBBLESTONE:0)
Block(-8,-29,5,COBBLESTONE:0)
Block(-8,-29,6,STONE:5)
Block(-8,-29,7,COBBLESTONE:0)
Block(-8,-29,8,STONE:5)
Block(-8,-28,3,COBBLESTONE:0)
Block(-8,-28,4,COBBLESTONE:0)
Block(-8,-28,5,COBBLESTONE:0)
Block(-8,-28,6,STONE:5)
Block(-8,-28,7,COBBLESTONE:0)
Block(-8,-28,8,STONE:5)
Block(-8,-27,3,COBBLESTONE:0)
Block(-8,-27,4,COBBLESTONE:0)
Block(-8,-27,5,COBBLESTONE:0)
Block(-8,-27,6,STONE:5)
Block(-8,-27,7,COBBLESTONE:0)
Block(-8,-27,8,STONE:5)
Block(-8,-26,3,COBBLESTONE:0)
Block(-8,-26,4,COBBLESTONE:0)
Block(-8,-26,5,COBBLESTONE:0)
Block(-8,-26,6,STONE:5)
Block(-8,-26,7,COBBLESTONE:0)
Block(-8,-26,8,STONE:5)
Block(-8,-25,3,COBBLESTONE:0)
Block(-8,-25,4,COBBLESTONE:0)
Block(-8,-25,5,COBBLESTONE:0)
Block(-8,-25,6,STONE:5)
Block(-8,-25,7,COBBLESTONE:0)
Block(-8,-25,8,STONE:5)
Block(-8,-24,3,COBBLESTONE:0)
Block(-8,-24,4,COBBLESTONE:0)
Block(-8,-24,5,COBBLESTONE:0)
Block(-8,-24,6,STONE:5)
Block(-8,-24,7,COBBLESTONE:0)
Block(-8,-24,8,STONE:5)
Block(-8,-23,3,COBBLESTONE:0)
Block(-8,-23,4,COBBLESTONE:0)
Block(-8,-23,5,COBBLESTONE:0)
Block(-8,-23,6,STONE:5)
Block(-8,-23,7,COBBLESTONE:0)
Block(-8,-23,8,STONE:5)
Block(-8,-22,3,COBBLESTONE:0)
Block(-8,-22,4,COBBLESTONE:0)
Block(-8,-22,5,COBBLESTONE:0)
Block(-8,-22,6,STONE:5)
Block(-8,-22,7,COBBLESTONE:0)
Block(-8,-22,8,STONE:5)
Block(-8,-21,3,COBBLESTONE:0)
Block(-8,-21,4,COBBLESTONE:0)
Block(-8,-21,5,COBBLESTONE:0)
Block(-8,-21,6,STONE:5)
Block(-8,-21,7,COBBLESTONE:0)
Block(-8,-21,8,STONE:5)
Block(-8,-20,3,COBBLESTONE:0)
Block(-8,-20,4,COBBLESTONE:0)
Block(-8,-20,5,COBBLESTONE:0)
Block(-8,-20,6,STONE:5)
Block(-8,-20,7,COBBLESTONE:0)
Block(-8,-20,8,STONE:5)
Block(-8,-19,3,COBBLESTONE:0)
Block(-8,-19,4,COBBLESTONE:0)
Block(-8,-19,5,STONE:5)
Block(-8,-19,6,STONE:5)
Block(-8,-19,7,SMOOTH_BRICK:1)
Block(-8,-19,8,SMOOTH_BRICK:2)
Block(-8,-18,3,STONE:5)
Block(-8,-18,4,STONE:5)
Block(-8,-18,5,STONE:5)
Block(-8,-18,6,COBBLESTONE:0)
Block(-8,-18,7,COBBLESTONE:0)
Block(-8,-18,8,SMOOTH_BRICK:0)
Block(-8,-17,3,STONE:5)
Block(-8,-17,4,SMOOTH_BRICK:0)
Block(-8,-17,5,SMOOTH_BRICK:2)
Block(-8,-17,6,STONE:5)
Block(-8,-17,7,COBBLESTONE:0)
Block(-8,-17,8,STONE:5)
Block(-8,-16,3,STONE:5)
Block(-8,-16,4,COBBLESTONE:0)
Block(-8,-16,5,STAINED_CLAY:9)
Block(-8,-16,6,STONE:5)
Block(-8,-16,7,STONE:5)
Block(-8,-16,8,SMOOTH_BRICK:2)
Block(-8,-15,3,COBBLESTONE:0)
Block(-8,-15,4,STONE:5)
Block(-8,-15,5,COBBLESTONE:0)
Block(-8,-15,6,STONE:5)
Block(-8,-15,7,SMOOTH_BRICK:0)
Block(-8,-15,8,COBBLESTONE:0)
Block(-8,-14,3,SMOOTH_BRICK:1)
Block(-8,-14,4,COBBLESTONE:0)
Block(-8,-14,5,COBBLESTONE:0)
Block(-8,-14,6,STONE:5)
Block(-8,-14,7,SMOOTH_BRICK:2)
Block(-8,-14,8,STONE:5)
Block(-8,-13,3,SMOOTH_BRICK:0)
Block(-8,-13,4,STONE:5)
Block(-8,-13,5,STONE:5)
Block(-8,-13,6,COBBLESTONE:0)
Block(-8,-13,7,STONE:5)
Block(-8,-13,8,STONE:5)
Block(-8,-12,3,STONE:5)
Block(-8,-12,4,STONE:5)
Block(-8,-12,5,STONE:5)
Block(-8,-12,6,COBBLESTONE:0)
Block(-8,-12,7,STONE:5)
Block(-8,-12,8,COBBLESTONE:0)
Block(-8,-11,3,STAINED_CLAY:9)
Block(-8,-11,4,STONE:5)
Block(-8,-11,5,SMOOTH_BRICK:2)
Block(-8,-11,6,STONE:5)
Block(-8,-11,7,STONE:5)
Block(-8,-11,8,COBBLESTONE:0)
Block(-8,-10,3,STAINED_CLAY:9)
Block(-8,-10,4,STONE:5)
Block(-8,-10,5,STONE:5)
Block(-8,-10,6,STAINED_CLAY:9)
Block(-8,-10,7,SMOOTH_BRICK:1)
Block(-8,-10,8,STONE:5)
Block(-8,-9,3,COBBLESTONE_STAIRS:2)
Block(-8,-9,4,STONE:6)
Block(-8,-9,5,STONE:6)
Block(-8,-9,6,STONE:6)
Block(-8,-9,7,STONE:6)
Block(-8,-9,8,STONE:6)
Block(-8,-8,4,STONE:6)
Block(-8,-8,5,STONE:6)
Block(-8,-8,6,STONE:6)
Block(-8,-8,7,STONE:6)
Block(-8,-8,8,STONE:6)
Block(-8,-7,4,STONE:6)
Block(-8,-7,5,STONE:6)
Block(-8,-7,6,STONE:6)
Block(-8,-7,7,STONE:6)
Block(-8,-7,8,STONE:6)
Block(-8,-6,4,STONE:6)
Block(-8,-6,5,STONE:6)
Block(-8,-6,6,STONE:6)
Block(-8,-6,7,STONE:6)
Block(-8,-6,8,STONE:6)
Block(-8,-5,4,COBBLESTONE_STAIRS:2)
Block(-8,-5,5,COBBLESTONE:0)
Block(-8,-5,6,STONE:5)
Block(-8,-5,7,STONE:5)
Block(-8,-5,8,STONE:5)
Block(-8,-4,5,STONE:6)
Block(-8,-4,6,STONE:6)
Block(-8,-4,7,STONE:6)
Block(-8,-4,8,STONE:6)
Block(-8,-3,5,STONE:6)
Block(-8,-3,6,STONE:6)
Block(-8,-3,7,STONE:6)
Block(-8,-3,8,STONE:6)
Block(-8,-2,5,STONE:6)
Block(-8,-2,6,STONE:6)
Block(-8,-2,7,STONE:6)
Block(-8,-2,8,STONE:6)
Block(-8,-1,5,COBBLESTONE_STAIRS:2)
Block(-8,-1,6,STONE:6)
Block(-8,-1,7,STONE:6)
Block(-8,-1,8,STONE:6)
Block(-8,0,6,STONE:6)
Block(-8,0,7,STONE:6)
Block(-8,0,8,STONE:6)
Block(-8,1,6,STONE:6)
Block(-8,1,7,STONE:6)
Block(-8,1,8,STONE:6)
Block(-8,2,6,STONE:6)
Block(-8,2,7,STONE:6)
Block(-8,2,8,STONE:6)
Block(-8,3,6,STONE:6)
Block(-8,3,7,STONE:6)
Block(-8,3,8,STONE:6)
Block(-8,4,6,STONE:6)
Block(-8,4,7,STONE:6)
Block(-8,4,8,STONE:6)
Block(-8,5,6,STONE:6)
Block(-8,5,7,STONE:6)
Block(-8,5,8,STONE:6)
Block(-8,6,6,DARK_OAK_FENCE:0)
Block(-8,6,7,COBBLESTONE_STAIRS:1)
Block(-8,6,8,SMOOTH_BRICK:0)
Block(-8,7,6,AIR:0)
Block(-8,7,7,COBBLESTONE_STAIRS:6)
Block(-8,7,8,SMOOTH_BRICK:0)
Block(-8,8,6,AIR:0)
Block(-8,8,7,SMOOTH_BRICK:0)
Block(-8,8,8,SMOOTH_BRICK:0)
Block(-8,9,6,COBBLESTONE_STAIRS:6)
Block(-8,9,7,SMOOTH_BRICK:0)
Block(-8,9,8,SMOOTH_BRICK:0)
Block(-8,10,6,SMOOTH_STAIRS:1)
Block(-8,10,7,STAINED_GLASS_PANE:15)
Block(-8,10,8,COBBLESTONE_STAIRS:1)
Block(-8,11,6,AIR:0)
Block(-8,11,7,STAINED_GLASS_PANE:15)
Block(-8,11,8,AIR:0)
Block(-8,12,6,AIR:0)
Block(-8,12,7,STAINED_GLASS_PANE:15)
Block(-8,12,8,AIR:0)
Block(-8,13,6,AIR:0)
Block(-8,13,7,STEP:5)
Block(-8,13,8,STEP:13)
Block(-8,14,6,AIR:0)
Block(-8,14,7,AIR:0)
Block(-8,14,8,SMOOTH_STAIRS:6)
Block(-8,15,6,AIR:0)
Block(-8,15,7,AIR:0)
Block(-8,15,8,STEP:3)
Block(-8,16,6,AIR:0)
Block(-8,16,7,AIR:0)
Block(-8,16,8,DARK_OAK_STAIRS:6)
Block(-8,17,6,AIR:0)
Block(-8,17,7,AIR:0)
Block(-8,17,8,STEP:3)
Block(-8,18,6,AIR:0)
Block(-8,18,7,AIR:0)
Block(-8,18,8,WOOD_STEP:5)
Block(-8,19,6,AIR:0)
Block(-8,19,7,AIR:0)
Block(-8,19,8,AIR:0)
Block(-8,20,6,AIR:0)
Block(-8,20,7,AIR:0)
Block(-8,20,8,AIR:0)
Block(-8,21,6,AIR:0)
Block(-8,21,7,AIR:0)
Block(-8,21,8,AIR:0)
Block(-8,22,6,AIR:0)
Block(-8,22,7,AIR:0)
Block(-8,22,8,AIR:0)
Block(-8,23,6,AIR:0)
Block(-8,23,7,AIR:0)
Block(-8,23,8,AIR:0)
Block(-8,24,6,AIR:0)
Block(-8,24,7,AIR:0)
Block(-8,24,8,AIR:0)
Block(-8,25,6,AIR:0)
Block(-8,25,7,AIR:0)
Block(-8,25,8,AIR:0)
Block(-8,26,6,AIR:0)
Block(-8,26,7,AIR:0)
Block(-8,26,8,AIR:0)
Block(-8,27,6,AIR:0)
Block(-8,27,7,AIR:0)
Block(-8,27,8,AIR:0)
Block(-8,28,6,AIR:0)
Block(-8,28,7,AIR:0)
Block(-8,28,8,AIR:0)
Block(-8,29,6,AIR:0)
Block(-8,29,7,AIR:0)
Block(-8,29,8,AIR:0)
Block(-8,30,6,AIR:0)
Block(-8,30,7,AIR:0)
Block(-8,30,8,AIR:0)
Block(-8,31,6,AIR:0)
Block(-8,31,7,AIR:0)
Block(-8,31,8,AIR:0)
Block(-8,32,6,AIR:0)
Block(-8,32,7,AIR:0)
Block(-8,32,8,AIR:0)
Block(-8,33,6,AIR:0)
Block(-8,33,7,AIR:0)
Block(-8,33,8,AIR:0)
Block(-8,34,6,AIR:0)
Block(-8,34,7,AIR:0)
Block(-8,34,8,AIR:0)
Block(-8,35,6,AIR:0)
Block(-8,35,7,AIR:0)
Block(-8,35,8,AIR:0)
Block(-8,36,6,AIR:0)
Block(-8,36,7,AIR:0)
Block(-8,36,8,AIR:0)
Block(-8,37,6,AIR:0)
Block(-8,37,7,AIR:0)
Block(-8,37,8,AIR:0)
Block(-8,38,6,AIR:0)
Block(-8,38,7,AIR:0)
Block(-8,38,8,AIR:0)
Block(-8,39,6,AIR:0)
Block(-8,39,7,AIR:0)
Block(-8,39,8,AIR:0)
Block(-8,40,6,AIR:0)
Block(-8,40,7,AIR:0)
Block(-8,40,8,AIR:0)
Block(-8,41,6,AIR:0)
Block(-8,41,7,AIR:0)
Block(-8,41,8,AIR:0)
Block(-8,42,6,AIR:0)
Block(-8,42,7,AIR:0)
Block(-8,42,8,AIR:0)
Block(-8,43,6,AIR:0)
Block(-8,43,7,AIR:0)
Block(-8,43,8,AIR:0)
Block(-8,44,6,AIR:0)
Block(-8,44,7,AIR:0)
Block(-8,44,8,AIR:0)
Block(-8,45,6,AIR:0)
Block(-8,45,7,AIR:0)
Block(-8,45,8,AIR:0)
Block(-8,46,6,AIR:0)
Block(-8,46,7,AIR:0)
Block(-8,46,8,AIR:0)
Block(-7,-50,3,STONE:5)
Block(-7,-50,4,STONE:5)
Block(-7,-50,5,COBBLESTONE:0)
Block(-7,-50,6,STONE:5)
Block(-7,-50,7,STONE:5)
Block(-7,-50,8,COBBLESTONE:0)
Block(-7,-49,3,STONE:5)
Block(-7,-49,4,STONE:5)
Block(-7,-49,5,COBBLESTONE:0)
Block(-7,-49,6,STONE:5)
Block(-7,-49,7,STONE:5)
Block(-7,-49,8,COBBLESTONE:0)
Block(-7,-48,3,STONE:5)
Block(-7,-48,4,STONE:5)
Block(-7,-48,5,COBBLESTONE:0)
Block(-7,-48,6,STONE:5)
Block(-7,-48,7,STONE:5)
Block(-7,-48,8,COBBLESTONE:0)
Block(-7,-47,3,STONE:5)
Block(-7,-47,4,STONE:5)
Block(-7,-47,5,COBBLESTONE:0)
Block(-7,-47,6,STONE:5)
Block(-7,-47,7,STONE:5)
Block(-7,-47,8,COBBLESTONE:0)
Block(-7,-46,3,STONE:5)
Block(-7,-46,4,STONE:5)
Block(-7,-46,5,COBBLESTONE:0)
Block(-7,-46,6,STONE:5)
Block(-7,-46,7,STONE:5)
Block(-7,-46,8,COBBLESTONE:0)
Block(-7,-45,3,STONE:5)
Block(-7,-45,4,STONE:5)
Block(-7,-45,5,COBBLESTONE:0)
Block(-7,-45,6,STONE:5)
Block(-7,-45,7,STONE:5)
Block(-7,-45,8,COBBLESTONE:0)
Block(-7,-44,3,STONE:5)
Block(-7,-44,4,STONE:5)
Block(-7,-44,5,COBBLESTONE:0)
Block(-7,-44,6,STONE:5)
Block(-7,-44,7,STONE:5)
Block(-7,-44,8,COBBLESTONE:0)
Block(-7,-43,3,STONE:5)
Block(-7,-43,4,STONE:5)
Block(-7,-43,5,COBBLESTONE:0)
Block(-7,-43,6,STONE:5)
Block(-7,-43,7,STONE:5)
Block(-7,-43,8,COBBLESTONE:0)
Block(-7,-42,3,STONE:5)
Block(-7,-42,4,STONE:5)
Block(-7,-42,5,COBBLESTONE:0)
Block(-7,-42,6,STONE:5)
Block(-7,-42,7,STONE:5)
Block(-7,-42,8,COBBLESTONE:0)
Block(-7,-41,3,STONE:5)
Block(-7,-41,4,STONE:5)
Block(-7,-41,5,COBBLESTONE:0)
Block(-7,-41,6,STONE:5)
Block(-7,-41,7,STONE:5)
Block(-7,-41,8,COBBLESTONE:0)
Block(-7,-40,3,STONE:5)
Block(-7,-40,4,STONE:5)
Block(-7,-40,5,COBBLESTONE:0)
Block(-7,-40,6,STONE:5)
Block(-7,-40,7,STONE:5)
Block(-7,-40,8,COBBLESTONE:0)
Block(-7,-39,3,STONE:5)
Block(-7,-39,4,STONE:5)
Block(-7,-39,5,COBBLESTONE:0)
Block(-7,-39,6,STONE:5)
Block(-7,-39,7,STONE:5)
Block(-7,-39,8,COBBLESTONE:0)
Block(-7,-38,3,STONE:5)
Block(-7,-38,4,STONE:5)
Block(-7,-38,5,COBBLESTONE:0)
Block(-7,-38,6,STONE:5)
Block(-7,-38,7,STONE:5)
Block(-7,-38,8,COBBLESTONE:0)
Block(-7,-37,3,STONE:5)
Block(-7,-37,4,STONE:5)
Block(-7,-37,5,COBBLESTONE:0)
Block(-7,-37,6,STONE:5)
Block(-7,-37,7,STONE:5)
Block(-7,-37,8,COBBLESTONE:0)
Block(-7,-36,3,STONE:5)
Block(-7,-36,4,STONE:5)
Block(-7,-36,5,COBBLESTONE:0)
Block(-7,-36,6,STONE:5)
Block(-7,-36,7,STONE:5)
Block(-7,-36,8,COBBLESTONE:0)
Block(-7,-35,3,STONE:5)
Block(-7,-35,4,STONE:5)
Block(-7,-35,5,COBBLESTONE:0)
Block(-7,-35,6,STONE:5)
Block(-7,-35,7,STONE:5)
Block(-7,-35,8,COBBLESTONE:0)
Block(-7,-34,3,STONE:5)
Block(-7,-34,4,STONE:5)
Block(-7,-34,5,COBBLESTONE:0)
Block(-7,-34,6,STONE:5)
Block(-7,-34,7,STONE:5)
Block(-7,-34,8,COBBLESTONE:0)
Block(-7,-33,3,STONE:5)
Block(-7,-33,4,STONE:5)
Block(-7,-33,5,COBBLESTONE:0)
Block(-7,-33,6,STONE:5)
Block(-7,-33,7,STONE:5)
Block(-7,-33,8,COBBLESTONE:0)
Block(-7,-32,3,STONE:5)
Block(-7,-32,4,STONE:5)
Block(-7,-32,5,COBBLESTONE:0)
Block(-7,-32,6,STONE:5)
Block(-7,-32,7,STONE:5)
Block(-7,-32,8,COBBLESTONE:0)
Block(-7,-31,3,STONE:5)
Block(-7,-31,4,STONE:5)
Block(-7,-31,5,COBBLESTONE:0)
Block(-7,-31,6,STONE:5)
Block(-7,-31,7,STONE:5)
Block(-7,-31,8,COBBLESTONE:0)
Block(-7,-30,3,STONE:5)
Block(-7,-30,4,STONE:5)
Block(-7,-30,5,COBBLESTONE:0)
Block(-7,-30,6,STONE:5)
Block(-7,-30,7,STONE:5)
Block(-7,-30,8,COBBLESTONE:0)
Block(-7,-29,3,STONE:5)
Block(-7,-29,4,STONE:5)
Block(-7,-29,5,COBBLESTONE:0)
Block(-7,-29,6,STONE:5)
Block(-7,-29,7,STONE:5)
Block(-7,-29,8,COBBLESTONE:0)
Block(-7,-28,3,STONE:5)
Block(-7,-28,4,STONE:5)
Block(-7,-28,5,COBBLESTONE:0)
Block(-7,-28,6,STONE:5)
Block(-7,-28,7,STONE:5)
Block(-7,-28,8,COBBLESTONE:0)
Block(-7,-27,3,STONE:5)
Block(-7,-27,4,STONE:5)
Block(-7,-27,5,COBBLESTONE:0)
Block(-7,-27,6,STONE:5)
Block(-7,-27,7,STONE:5)
Block(-7,-27,8,COBBLESTONE:0)
Block(-7,-26,3,STONE:5)
Block(-7,-26,4,STONE:5)
Block(-7,-26,5,COBBLESTONE:0)
Block(-7,-26,6,STONE:5)
Block(-7,-26,7,STONE:5)
Block(-7,-26,8,COBBLESTONE:0)
Block(-7,-25,3,STONE:5)
Block(-7,-25,4,STONE:5)
Block(-7,-25,5,COBBLESTONE:0)
Block(-7,-25,6,STONE:5)
Block(-7,-25,7,STONE:5)
Block(-7,-25,8,COBBLESTONE:0)
Block(-7,-24,3,STONE:5)
Block(-7,-24,4,STONE:5)
Block(-7,-24,5,COBBLESTONE:0)
Block(-7,-24,6,STONE:5)
Block(-7,-24,7,STONE:5)
Block(-7,-24,8,COBBLESTONE:0)
Block(-7,-23,3,STONE:5)
Block(-7,-23,4,STONE:5)
Block(-7,-23,5,COBBLESTONE:0)
Block(-7,-23,6,STONE:5)
Block(-7,-23,7,STONE:5)
Block(-7,-23,8,COBBLESTONE:0)
Block(-7,-22,3,STONE:5)
Block(-7,-22,4,STONE:5)
Block(-7,-22,5,COBBLESTONE:0)
Block(-7,-22,6,STONE:5)
Block(-7,-22,7,STONE:5)
Block(-7,-22,8,COBBLESTONE:0)
Block(-7,-21,3,STONE:5)
Block(-7,-21,4,STONE:5)
Block(-7,-21,5,COBBLESTONE:0)
Block(-7,-21,6,STONE:5)
Block(-7,-21,7,STONE:5)
Block(-7,-21,8,COBBLESTONE:0)
Block(-7,-20,3,STONE:5)
Block(-7,-20,4,STONE:5)
Block(-7,-20,5,COBBLESTONE:0)
Block(-7,-20,6,STONE:5)
Block(-7,-20,7,STONE:5)
Block(-7,-20,8,COBBLESTONE:0)
Block(-7,-19,3,SMOOTH_BRICK:1)
Block(-7,-19,4,SMOOTH_BRICK:1)
Block(-7,-19,5,COBBLESTONE:0)
Block(-7,-19,6,STONE:5)
Block(-7,-19,7,COBBLESTONE:0)
Block(-7,-19,8,STONE:5)
Block(-7,-18,3,COBBLESTONE:0)
Block(-7,-18,4,COBBLESTONE:0)
Block(-7,-18,5,SMOOTH_BRICK:0)
Block(-7,-18,6,COBBLESTONE:0)
Block(-7,-18,7,SMOOTH_BRICK:1)
Block(-7,-18,8,STONE:5)
Block(-7,-17,3,COBBLESTONE:0)
Block(-7,-17,4,COBBLESTONE:0)
Block(-7,-17,5,STONE:5)
Block(-7,-17,6,STONE:5)
Block(-7,-17,7,SMOOTH_BRICK:0)
Block(-7,-17,8,COBBLESTONE:0)
Block(-7,-16,3,STONE:5)
Block(-7,-16,4,STONE:5)
Block(-7,-16,5,STONE:5)
Block(-7,-16,6,SMOOTH_BRICK:1)
Block(-7,-16,7,STONE:5)
Block(-7,-16,8,STONE:5)
Block(-7,-15,3,STONE:5)
Block(-7,-15,4,SMOOTH_BRICK:2)
Block(-7,-15,5,SMOOTH_BRICK:1)
Block(-7,-15,6,STAINED_CLAY:9)
Block(-7,-15,7,SMOOTH_BRICK:2)
Block(-7,-15,8,COBBLESTONE:0)
Block(-7,-14,3,STONE:5)
Block(-7,-14,4,STONE:5)
Block(-7,-14,5,SMOOTH_BRICK:1)
Block(-7,-14,6,STONE:5)
Block(-7,-14,7,COBBLESTONE:0)
Block(-7,-14,8,STONE:5)
Block(-7,-13,3,STONE:5)
Block(-7,-13,4,STONE:5)
Block(-7,-13,5,STONE:5)
Block(-7,-13,6,STONE:5)
Block(-7,-13,7,STONE:5)
Block(-7,-13,8,SMOOTH_BRICK:2)
Block(-7,-12,3,STONE:5)
Block(-7,-12,4,STONE:5)
Block(-7,-12,5,STONE:5)
Block(-7,-12,6,COBBLESTONE:0)
Block(-7,-12,7,COBBLESTONE:0)
Block(-7,-12,8,STAINED_CLAY:9)
Block(-7,-11,3,COBBLESTONE:0)
Block(-7,-11,4,COBBLESTONE:0)
Block(-7,-11,5,COBBLESTONE:0)
Block(-7,-11,6,STAINED_CLAY:9)
Block(-7,-11,7,COBBLESTONE:0)
Block(-7,-11,8,STONE:5)
Block(-7,-10,3,STONE:5)
Block(-7,-10,4,STONE:5)
Block(-7,-10,5,COBBLESTONE:0)
Block(-7,-10,6,SMOOTH_BRICK:2)
Block(-7,-10,7,STONE:5)
Block(-7,-10,8,COBBLESTONE:0)
Block(-7,-9,3,COBBLESTONE_STAIRS:2)
Block(-7,-9,4,STONE:6)
Block(-7,-9,5,STONE:6)
Block(-7,-9,6,STONE:6)
Block(-7,-9,7,STONE:6)
Block(-7,-9,8,STONE:6)
Block(-7,-8,4,STONE:6)
Block(-7,-8,5,STONE:6)
Block(-7,-8,6,STONE:6)
Block(-7,-8,7,STONE:6)
Block(-7,-8,8,STONE:6)
Block(-7,-7,4,STONE:6)
Block(-7,-7,5,STONE:6)
Block(-7,-7,6,STONE:6)
Block(-7,-7,7,STONE:6)
Block(-7,-7,8,STONE:6)
Block(-7,-6,4,STONE:6)
Block(-7,-6,5,STONE:6)
Block(-7,-6,6,STONE:6)
Block(-7,-6,7,STONE:6)
Block(-7,-6,8,STONE:6)
Block(-7,-5,4,COBBLESTONE_STAIRS:2)
Block(-7,-5,5,COBBLESTONE:0)
Block(-7,-5,6,STONE:5)
Block(-7,-5,7,STONE:5)
Block(-7,-5,8,STAINED_CLAY:9)
Block(-7,-4,5,STONE:6)
Block(-7,-4,6,STONE:6)
Block(-7,-4,7,STONE:6)
Block(-7,-4,8,STONE:6)
Block(-7,-3,5,STONE:6)
Block(-7,-3,6,STONE:6)
Block(-7,-3,7,STONE:6)
Block(-7,-3,8,STONE:6)
Block(-7,-2,5,STONE:6)
Block(-7,-2,6,STONE:6)
Block(-7,-2,7,STONE:6)
Block(-7,-2,8,STONE:6)
Block(-7,-1,5,COBBLESTONE_STAIRS:2)
Block(-7,-1,6,STONE:6)
Block(-7,-1,7,STONE:6)
Block(-7,-1,8,STONE:6)
Block(-7,0,6,STONE:6)
Block(-7,0,7,STONE:6)
Block(-7,0,8,STONE:6)
Block(-7,1,6,STONE:6)
Block(-7,1,7,STONE:6)
Block(-7,1,8,STONE:6)
Block(-7,2,6,STONE:6)
Block(-7,2,7,STONE:6)
Block(-7,2,8,STONE:6)
Block(-7,3,6,STONE:6)
Block(-7,3,7,STONE:6)
Block(-7,3,8,STONE:6)
Block(-7,4,6,STONE:6)
Block(-7,4,7,STONE:6)
Block(-7,4,8,STONE:6)
Block(-7,5,6,STONE:6)
Block(-7,5,7,STONE:6)
Block(-7,5,8,STONE:6)
Block(-7,6,6,DARK_OAK_FENCE:0)
Block(-7,6,7,COBBLESTONE_STAIRS:0)
Block(-7,6,8,SMOOTH_BRICK:0)
Block(-7,7,6,AIR:0)
Block(-7,7,7,COBBLESTONE_STAIRS:6)
Block(-7,7,8,SMOOTH_BRICK:0)
Block(-7,8,6,AIR:0)
Block(-7,8,7,SMOOTH_BRICK:0)
Block(-7,8,8,SMOOTH_BRICK:0)
Block(-7,9,6,COBBLESTONE_STAIRS:6)
Block(-7,9,7,SMOOTH_BRICK:0)
Block(-7,9,8,SMOOTH_BRICK:0)
Block(-7,10,6,SMOOTH_STAIRS:0)
Block(-7,10,7,STAINED_GLASS_PANE:15)
Block(-7,10,8,COBBLESTONE_STAIRS:0)
Block(-7,11,6,AIR:0)
Block(-7,11,7,STAINED_GLASS_PANE:15)
Block(-7,11,8,AIR:0)
Block(-7,12,6,AIR:0)
Block(-7,12,7,STAINED_GLASS_PANE:15)
Block(-7,12,8,AIR:0)
Block(-7,13,6,AIR:0)
Block(-7,13,7,STEP:5)
Block(-7,13,8,STEP:13)
Block(-7,14,6,AIR:0)
Block(-7,14,7,AIR:0)
Block(-7,14,8,SMOOTH_STAIRS:6)
Block(-7,15,6,AIR:0)
Block(-7,15,7,AIR:0)
Block(-7,15,8,STEP:3)
Block(-7,16,6,AIR:0)
Block(-7,16,7,AIR:0)
Block(-7,16,8,DARK_OAK_STAIRS:6)
Block(-7,17,6,AIR:0)
Block(-7,17,7,AIR:0)
Block(-7,17,8,STEP:3)
Block(-7,18,6,AIR:0)
Block(-7,18,7,AIR:0)
Block(-7,18,8,WOOD_STEP:5)
Block(-7,19,6,AIR:0)
Block(-7,19,7,AIR:0)
Block(-7,19,8,AIR:0)
Block(-7,20,6,AIR:0)
Block(-7,20,7,AIR:0)
Block(-7,20,8,AIR:0)
Block(-7,21,6,AIR:0)
Block(-7,21,7,AIR:0)
Block(-7,21,8,AIR:0)
Block(-7,22,6,AIR:0)
Block(-7,22,7,AIR:0)
Block(-7,22,8,AIR:0)
Block(-7,23,6,AIR:0)
Block(-7,23,7,AIR:0)
Block(-7,23,8,AIR:0)
Block(-7,24,6,AIR:0)
Block(-7,24,7,AIR:0)
Block(-7,24,8,AIR:0)
Block(-7,25,6,AIR:0)
Block(-7,25,7,AIR:0)
Block(-7,25,8,AIR:0)
Block(-7,26,6,AIR:0)
Block(-7,26,7,AIR:0)
Block(-7,26,8,AIR:0)
Block(-7,27,6,AIR:0)
Block(-7,27,7,AIR:0)
Block(-7,27,8,AIR:0)
Block(-7,28,6,AIR:0)
Block(-7,28,7,AIR:0)
Block(-7,28,8,AIR:0)
Block(-7,29,6,AIR:0)
Block(-7,29,7,AIR:0)
Block(-7,29,8,AIR:0)
Block(-7,30,6,AIR:0)
Block(-7,30,7,AIR:0)
Block(-7,30,8,AIR:0)
Block(-7,31,6,AIR:0)
Block(-7,31,7,AIR:0)
Block(-7,31,8,AIR:0)
Block(-7,32,6,AIR:0)
Block(-7,32,7,AIR:0)
Block(-7,32,8,AIR:0)
Block(-7,33,6,AIR:0)
Block(-7,33,7,AIR:0)
Block(-7,33,8,AIR:0)
Block(-7,34,6,AIR:0)
Block(-7,34,7,AIR:0)
Block(-7,34,8,AIR:0)
Block(-7,35,6,AIR:0)
Block(-7,35,7,AIR:0)
Block(-7,35,8,AIR:0)
Block(-7,36,6,AIR:0)
Block(-7,36,7,AIR:0)
Block(-7,36,8,AIR:0)
Block(-7,37,6,AIR:0)
Block(-7,37,7,AIR:0)
Block(-7,37,8,AIR:0)
Block(-7,38,6,AIR:0)
Block(-7,38,7,AIR:0)
Block(-7,38,8,AIR:0)
Block(-7,39,6,AIR:0)
Block(-7,39,7,AIR:0)
Block(-7,39,8,AIR:0)
Block(-7,40,6,AIR:0)
Block(-7,40,7,AIR:0)
Block(-7,40,8,AIR:0)
Block(-7,41,6,AIR:0)
Block(-7,41,7,AIR:0)
Block(-7,41,8,AIR:0)
Block(-7,42,6,AIR:0)
Block(-7,42,7,AIR:0)
Block(-7,42,8,AIR:0)
Block(-7,43,6,AIR:0)
Block(-7,43,7,AIR:0)
Block(-7,43,8,AIR:0)
Block(-7,44,6,AIR:0)
Block(-7,44,7,AIR:0)
Block(-7,44,8,AIR:0)
Block(-7,45,6,AIR:0)
Block(-7,45,7,AIR:0)
Block(-7,45,8,AIR:0)
Block(-7,46,6,AIR:0)
Block(-7,46,7,AIR:0)
Block(-7,46,8,AIR:0)
Block(-6,-50,3,LOG:0)
Block(-6,-50,4,STONE:5)
Block(-6,-50,5,SMOOTH_BRICK:2)
Block(-6,-50,6,COBBLESTONE:0)
Block(-6,-50,7,COBBLESTONE:0)
Block(-6,-50,8,COBBLESTONE:0)
Block(-6,-49,3,LOG:0)
Block(-6,-49,4,STONE:5)
Block(-6,-49,5,SMOOTH_BRICK:2)
Block(-6,-49,6,COBBLESTONE:0)
Block(-6,-49,7,COBBLESTONE:0)
Block(-6,-49,8,COBBLESTONE:0)
Block(-6,-48,3,LOG:0)
Block(-6,-48,4,STONE:5)
Block(-6,-48,5,SMOOTH_BRICK:2)
Block(-6,-48,6,COBBLESTONE:0)
Block(-6,-48,7,COBBLESTONE:0)
Block(-6,-48,8,COBBLESTONE:0)
Block(-6,-47,3,LOG:0)
Block(-6,-47,4,STONE:5)
Block(-6,-47,5,SMOOTH_BRICK:2)
Block(-6,-47,6,COBBLESTONE:0)
Block(-6,-47,7,COBBLESTONE:0)
Block(-6,-47,8,COBBLESTONE:0)
Block(-6,-46,3,LOG:0)
Block(-6,-46,4,STONE:5)
Block(-6,-46,5,SMOOTH_BRICK:2)
Block(-6,-46,6,COBBLESTONE:0)
Block(-6,-46,7,COBBLESTONE:0)
Block(-6,-46,8,COBBLESTONE:0)
Block(-6,-45,3,LOG:0)
Block(-6,-45,4,STONE:5)
Block(-6,-45,5,SMOOTH_BRICK:2)
Block(-6,-45,6,COBBLESTONE:0)
Block(-6,-45,7,COBBLESTONE:0)
Block(-6,-45,8,COBBLESTONE:0)
Block(-6,-44,3,LOG:0)
Block(-6,-44,4,STONE:5)
Block(-6,-44,5,SMOOTH_BRICK:2)
Block(-6,-44,6,COBBLESTONE:0)
Block(-6,-44,7,COBBLESTONE:0)
Block(-6,-44,8,COBBLESTONE:0)
Block(-6,-43,3,LOG:0)
Block(-6,-43,4,STONE:5)
Block(-6,-43,5,SMOOTH_BRICK:2)
Block(-6,-43,6,COBBLESTONE:0)
Block(-6,-43,7,COBBLESTONE:0)
Block(-6,-43,8,COBBLESTONE:0)
Block(-6,-42,3,LOG:0)
Block(-6,-42,4,STONE:5)
Block(-6,-42,5,SMOOTH_BRICK:2)
Block(-6,-42,6,COBBLESTONE:0)
Block(-6,-42,7,COBBLESTONE:0)
Block(-6,-42,8,COBBLESTONE:0)
Block(-6,-41,3,LOG:0)
Block(-6,-41,4,STONE:5)
Block(-6,-41,5,SMOOTH_BRICK:2)
Block(-6,-41,6,COBBLESTONE:0)
Block(-6,-41,7,COBBLESTONE:0)
Block(-6,-41,8,COBBLESTONE:0)
Block(-6,-40,3,LOG:0)
Block(-6,-40,4,STONE:5)
Block(-6,-40,5,SMOOTH_BRICK:2)
Block(-6,-40,6,COBBLESTONE:0)
Block(-6,-40,7,COBBLESTONE:0)
Block(-6,-40,8,COBBLESTONE:0)
Block(-6,-39,3,LOG:0)
Block(-6,-39,4,STONE:5)
Block(-6,-39,5,SMOOTH_BRICK:2)
Block(-6,-39,6,COBBLESTONE:0)
Block(-6,-39,7,COBBLESTONE:0)
Block(-6,-39,8,COBBLESTONE:0)
Block(-6,-38,3,LOG:0)
Block(-6,-38,4,STONE:5)
Block(-6,-38,5,SMOOTH_BRICK:2)
Block(-6,-38,6,COBBLESTONE:0)
Block(-6,-38,7,COBBLESTONE:0)
Block(-6,-38,8,COBBLESTONE:0)
Block(-6,-37,3,LOG:0)
Block(-6,-37,4,STONE:5)
Block(-6,-37,5,SMOOTH_BRICK:2)
Block(-6,-37,6,COBBLESTONE:0)
Block(-6,-37,7,COBBLESTONE:0)
Block(-6,-37,8,COBBLESTONE:0)
Block(-6,-36,3,LOG:0)
Block(-6,-36,4,STONE:5)
Block(-6,-36,5,SMOOTH_BRICK:2)
Block(-6,-36,6,COBBLESTONE:0)
Block(-6,-36,7,COBBLESTONE:0)
Block(-6,-36,8,COBBLESTONE:0)
Block(-6,-35,3,LOG:0)
Block(-6,-35,4,STONE:5)
Block(-6,-35,5,SMOOTH_BRICK:2)
Block(-6,-35,6,COBBLESTONE:0)
Block(-6,-35,7,COBBLESTONE:0)
Block(-6,-35,8,COBBLESTONE:0)
Block(-6,-34,3,LOG:0)
Block(-6,-34,4,STONE:5)
Block(-6,-34,5,SMOOTH_BRICK:2)
Block(-6,-34,6,COBBLESTONE:0)
Block(-6,-34,7,COBBLESTONE:0)
Block(-6,-34,8,COBBLESTONE:0)
Block(-6,-33,3,LOG:0)
Block(-6,-33,4,STONE:5)
Block(-6,-33,5,SMOOTH_BRICK:2)
Block(-6,-33,6,COBBLESTONE:0)
Block(-6,-33,7,COBBLESTONE:0)
Block(-6,-33,8,COBBLESTONE:0)
Block(-6,-32,3,LOG:0)
Block(-6,-32,4,STONE:5)
Block(-6,-32,5,SMOOTH_BRICK:2)
Block(-6,-32,6,COBBLESTONE:0)
Block(-6,-32,7,COBBLESTONE:0)
Block(-6,-32,8,COBBLESTONE:0)
Block(-6,-31,3,LOG:0)
Block(-6,-31,4,STONE:5)
Block(-6,-31,5,SMOOTH_BRICK:2)
Block(-6,-31,6,COBBLESTONE:0)
Block(-6,-31,7,COBBLESTONE:0)
Block(-6,-31,8,COBBLESTONE:0)
Block(-6,-30,3,LOG:0)
Block(-6,-30,4,STONE:5)
Block(-6,-30,5,SMOOTH_BRICK:2)
Block(-6,-30,6,COBBLESTONE:0)
Block(-6,-30,7,COBBLESTONE:0)
Block(-6,-30,8,COBBLESTONE:0)
Block(-6,-29,3,LOG:0)
Block(-6,-29,4,STONE:5)
Block(-6,-29,5,SMOOTH_BRICK:2)
Block(-6,-29,6,COBBLESTONE:0)
Block(-6,-29,7,COBBLESTONE:0)
Block(-6,-29,8,COBBLESTONE:0)
Block(-6,-28,3,LOG:0)
Block(-6,-28,4,STONE:5)
Block(-6,-28,5,SMOOTH_BRICK:2)
Block(-6,-28,6,COBBLESTONE:0)
Block(-6,-28,7,COBBLESTONE:0)
Block(-6,-28,8,COBBLESTONE:0)
Block(-6,-27,3,LOG:0)
Block(-6,-27,4,STONE:5)
Block(-6,-27,5,SMOOTH_BRICK:2)
Block(-6,-27,6,COBBLESTONE:0)
Block(-6,-27,7,COBBLESTONE:0)
Block(-6,-27,8,COBBLESTONE:0)
Block(-6,-26,3,LOG:0)
Block(-6,-26,4,STONE:5)
Block(-6,-26,5,SMOOTH_BRICK:2)
Block(-6,-26,6,COBBLESTONE:0)
Block(-6,-26,7,COBBLESTONE:0)
Block(-6,-26,8,COBBLESTONE:0)
Block(-6,-25,3,LOG:0)
Block(-6,-25,4,STONE:5)
Block(-6,-25,5,SMOOTH_BRICK:2)
Block(-6,-25,6,COBBLESTONE:0)
Block(-6,-25,7,COBBLESTONE:0)
Block(-6,-25,8,COBBLESTONE:0)
Block(-6,-24,3,LOG:0)
Block(-6,-24,4,STONE:5)
Block(-6,-24,5,SMOOTH_BRICK:2)
Block(-6,-24,6,COBBLESTONE:0)
Block(-6,-24,7,COBBLESTONE:0)
Block(-6,-24,8,COBBLESTONE:0)
Block(-6,-23,3,LOG:0)
Block(-6,-23,4,STONE:5)
Block(-6,-23,5,SMOOTH_BRICK:2)
Block(-6,-23,6,COBBLESTONE:0)
Block(-6,-23,7,COBBLESTONE:0)
Block(-6,-23,8,COBBLESTONE:0)
Block(-6,-22,3,LOG:0)
Block(-6,-22,4,STONE:5)
Block(-6,-22,5,SMOOTH_BRICK:2)
Block(-6,-22,6,COBBLESTONE:0)
Block(-6,-22,7,COBBLESTONE:0)
Block(-6,-22,8,COBBLESTONE:0)
Block(-6,-21,3,LOG:0)
Block(-6,-21,4,STONE:5)
Block(-6,-21,5,SMOOTH_BRICK:2)
Block(-6,-21,6,COBBLESTONE:0)
Block(-6,-21,7,COBBLESTONE:0)
Block(-6,-21,8,COBBLESTONE:0)
Block(-6,-20,3,LOG:0)
Block(-6,-20,4,STONE:5)
Block(-6,-20,5,SMOOTH_BRICK:2)
Block(-6,-20,6,COBBLESTONE:0)
Block(-6,-20,7,COBBLESTONE:0)
Block(-6,-20,8,COBBLESTONE:0)
Block(-6,-19,3,LOG:0)
Block(-6,-19,4,COBBLESTONE:0)
Block(-6,-19,5,COBBLESTONE:0)
Block(-6,-19,6,STONE:5)
Block(-6,-19,7,SMOOTH_BRICK:0)
Block(-6,-19,8,STONE:5)
Block(-6,-18,3,LOG:0)
Block(-6,-18,4,COBBLESTONE:0)
Block(-6,-18,5,SMOOTH_BRICK:2)
Block(-6,-18,6,COBBLESTONE:0)
Block(-6,-18,7,STONE:5)
Block(-6,-18,8,SMOOTH_BRICK:2)
Block(-6,-17,3,LOG:0)
Block(-6,-17,4,STONE:5)
Block(-6,-17,5,COBBLESTONE:0)
Block(-6,-17,6,SMOOTH_BRICK:2)
Block(-6,-17,7,STONE:5)
Block(-6,-17,8,COBBLESTONE:0)
Block(-6,-16,3,LOG:0)
Block(-6,-16,4,STONE:5)
Block(-6,-16,5,STONE:5)
Block(-6,-16,6,COBBLESTONE:0)
Block(-6,-16,7,COBBLESTONE:0)
Block(-6,-16,8,COBBLESTONE:0)
Block(-6,-15,3,LOG:0)
Block(-6,-15,4,COBBLESTONE:0)
Block(-6,-15,5,SMOOTH_BRICK:0)
Block(-6,-15,6,STONE:5)
Block(-6,-15,7,SMOOTH_BRICK:2)
Block(-6,-15,8,STONE:5)
Block(-6,-14,3,LOG:0)
Block(-6,-14,4,SMOOTH_BRICK:2)
Block(-6,-14,5,STONE:5)
Block(-6,-14,6,STONE:5)
Block(-6,-14,7,STONE:5)
Block(-6,-14,8,COBBLESTONE:0)
Block(-6,-13,3,LOG:0)
Block(-6,-13,4,COBBLESTONE:0)
Block(-6,-13,5,COBBLESTONE:0)
Block(-6,-13,6,COBBLESTONE:0)
Block(-6,-13,7,SMOOTH_BRICK:0)
Block(-6,-13,8,STONE:5)
Block(-6,-12,3,LOG:0)
Block(-6,-12,4,STONE:5)
Block(-6,-12,5,STONE:5)
Block(-6,-12,6,STONE:5)
Block(-6,-12,7,COBBLESTONE:0)
Block(-6,-12,8,COBBLESTONE:0)
Block(-6,-11,3,LOG:0)
Block(-6,-11,4,STONE:5)
Block(-6,-11,5,STONE:5)
Block(-6,-11,6,COBBLESTONE:0)
Block(-6,-11,7,COBBLESTONE:0)
Block(-6,-11,8,COBBLESTONE:0)
Block(-6,-10,3,LOG:0)
Block(-6,-10,4,COBBLESTONE:0)
Block(-6,-10,5,STAINED_CLAY:9)
Block(-6,-10,6,COBBLESTONE:0)
Block(-6,-10,7,SMOOTH_BRICK:0)
Block(-6,-10,8,SMOOTH_BRICK:2)
Block(-6,-9,3,SMOOTH_STAIRS:2)
Block(-6,-9,4,LOG:0)
Block(-6,-9,5,STONE:6)
Block(-6,-9,6,STONE:6)
Block(-6,-9,7,STONE:6)
Block(-6,-9,8,STONE:6)
Block(-6,-8,4,LOG:0)
Block(-6,-8,5,STONE:6)
Block(-6,-8,6,STONE:6)
Block(-6,-8,7,STONE:6)
Block(-6,-8,8,STONE:6)
Block(-6,-7,4,LOG:0)
Block(-6,-7,5,STONE:6)
Block(-6,-7,6,STONE:6)
Block(-6,-7,7,STONE:6)
Block(-6,-7,8,STONE:6)
Block(-6,-6,4,LOG:0)
Block(-6,-6,5,STONE:6)
Block(-6,-6,6,STONE:6)
Block(-6,-6,7,STONE:6)
Block(-6,-6,8,STONE:6)
Block(-6,-5,4,LOG:0)
Block(-6,-5,5,SMOOTH_BRICK:0)
Block(-6,-5,6,SMOOTH_BRICK:1)
Block(-6,-5,7,STONE:5)
Block(-6,-5,8,COBBLESTONE:0)
Block(-6,-4,4,COBBLESTONE_STAIRS:2)
Block(-6,-4,5,LOG:8)
Block(-6,-4,6,LOG:0)
Block(-6,-4,7,STONE:6)
Block(-6,-4,8,STONE:6)
Block(-6,-3,6,LOG:0)
Block(-6,-3,7,STONE:6)
Block(-6,-3,8,STONE:6)
Block(-6,-2,6,LOG:0)
Block(-6,-2,7,STONE:6)
Block(-6,-2,8,STONE:6)
Block(-6,-1,6,LOG:0)
Block(-6,-1,7,STONE:6)
Block(-6,-1,8,STONE:6)
Block(-6,0,6,LOG:0)
Block(-6,0,7,STONE:6)
Block(-6,0,8,STONE:6)
Block(-6,1,6,LOG:0)
Block(-6,1,7,STONE:6)
Block(-6,1,8,STONE:6)
Block(-6,2,6,LOG:0)
Block(-6,2,7,STONE:6)
Block(-6,2,8,STONE:6)
Block(-6,3,6,LOG:0)
Block(-6,3,7,STONE:6)
Block(-6,3,8,STONE:6)
Block(-6,4,6,LOG:0)
Block(-6,4,7,STONE:6)
Block(-6,4,8,STONE:6)
Block(-6,5,6,LOG:0)
Block(-6,5,7,STONE:6)
Block(-6,5,8,STONE:6)
Block(-6,6,6,LOG:0)
Block(-6,6,7,LOG:8)
Block(-6,6,8,LOG:0)
Block(-6,7,6,LOG:0)
Block(-6,7,7,COBBLESTONE_STAIRS:6)
Block(-6,7,8,LOG:0)
Block(-6,8,6,LOG:0)
Block(-6,8,7,STONE:6)
Block(-6,8,8,LOG:0)
Block(-6,9,6,LOG:0)
Block(-6,9,7,STONE:6)
Block(-6,9,8,LOG:0)
Block(-6,10,6,LOG:0)
Block(-6,10,7,STONE:6)
Block(-6,10,8,LOG:0)
Block(-6,11,6,STEP:3)
Block(-6,11,7,STONE:6)
Block(-6,11,8,LOG:0)
Block(-6,12,6,AIR:0)
Block(-6,12,7,STONE:6)
Block(-6,12,8,LOG:0)
Block(-6,13,6,AIR:0)
Block(-6,13,7,SMOOTH_STAIRS:2)
Block(-6,13,8,LOG:0)
Block(-6,14,6,AIR:0)
Block(-6,14,7,AIR:0)
Block(-6,14,8,LOG:0)
Block(-6,15,6,AIR:0)
Block(-6,15,7,AIR:0)
Block(-6,15,8,LOG:0)
Block(-6,16,6,AIR:0)
Block(-6,16,7,AIR:0)
Block(-6,16,8,LOG:0)
Block(-6,17,6,AIR:0)
Block(-6,17,7,AIR:0)
Block(-6,17,8,SMOOTH_STAIRS:2)
Block(-6,18,6,AIR:0)
Block(-6,18,7,AIR:0)
Block(-6,18,8,WOOD_STEP:5)
Block(-6,19,6,AIR:0)
Block(-6,19,7,AIR:0)
Block(-6,19,8,AIR:0)
Block(-6,20,6,AIR:0)
Block(-6,20,7,AIR:0)
Block(-6,20,8,AIR:0)
Block(-6,21,6,AIR:0)
Block(-6,21,7,AIR:0)
Block(-6,21,8,AIR:0)
Block(-6,22,6,AIR:0)
Block(-6,22,7,AIR:0)
Block(-6,22,8,AIR:0)
Block(-6,23,6,AIR:0)
Block(-6,23,7,AIR:0)
Block(-6,23,8,AIR:0)
Block(-6,24,6,AIR:0)
Block(-6,24,7,AIR:0)
Block(-6,24,8,AIR:0)
Block(-6,25,6,AIR:0)
Block(-6,25,7,AIR:0)
Block(-6,25,8,AIR:0)
Block(-6,26,6,AIR:0)
Block(-6,26,7,AIR:0)
Block(-6,26,8,AIR:0)
Block(-6,27,6,AIR:0)
Block(-6,27,7,AIR:0)
Block(-6,27,8,AIR:0)
Block(-6,28,6,AIR:0)
Block(-6,28,7,AIR:0)
Block(-6,28,8,AIR:0)
Block(-6,29,6,AIR:0)
Block(-6,29,7,AIR:0)
Block(-6,29,8,AIR:0)
Block(-6,30,6,AIR:0)
Block(-6,30,7,AIR:0)
Block(-6,30,8,AIR:0)
Block(-6,31,6,AIR:0)
Block(-6,31,7,AIR:0)
Block(-6,31,8,AIR:0)
Block(-6,32,6,AIR:0)
Block(-6,32,7,AIR:0)
Block(-6,32,8,AIR:0)
Block(-6,33,6,AIR:0)
Block(-6,33,7,AIR:0)
Block(-6,33,8,AIR:0)
Block(-6,34,6,AIR:0)
Block(-6,34,7,AIR:0)
Block(-6,34,8,AIR:0)
Block(-6,35,6,AIR:0)
Block(-6,35,7,AIR:0)
Block(-6,35,8,AIR:0)
Block(-6,36,6,AIR:0)
Block(-6,36,7,AIR:0)
Block(-6,36,8,AIR:0)
Block(-6,37,6,AIR:0)
Block(-6,37,7,AIR:0)
Block(-6,37,8,AIR:0)
Block(-6,38,6,AIR:0)
Block(-6,38,7,AIR:0)
Block(-6,38,8,AIR:0)
Block(-6,39,6,AIR:0)
Block(-6,39,7,AIR:0)
Block(-6,39,8,AIR:0)
Block(-6,40,6,AIR:0)
Block(-6,40,7,AIR:0)
Block(-6,40,8,AIR:0)
Block(-6,41,6,AIR:0)
Block(-6,41,7,AIR:0)
Block(-6,41,8,AIR:0)
Block(-6,42,6,AIR:0)
Block(-6,42,7,AIR:0)
Block(-6,42,8,AIR:0)
Block(-6,43,6,AIR:0)
Block(-6,43,7,AIR:0)
Block(-6,43,8,AIR:0)
Block(-6,44,6,AIR:0)
Block(-6,44,7,AIR:0)
Block(-6,44,8,AIR:0)
Block(-6,45,6,AIR:0)
Block(-6,45,7,AIR:0)
Block(-6,45,8,AIR:0)
Block(-6,46,6,AIR:0)
Block(-6,46,7,AIR:0)
Block(-6,46,8,AIR:0)
Block(-5,-50,3,COBBLESTONE:0)
Block(-5,-50,4,COBBLESTONE:0)
Block(-5,-50,5,STONE:5)
Block(-5,-50,6,STONE:5)
Block(-5,-50,7,SMOOTH_BRICK:0)
Block(-5,-50,8,SMOOTH_BRICK:1)
Block(-5,-49,3,COBBLESTONE:0)
Block(-5,-49,4,COBBLESTONE:0)
Block(-5,-49,5,STONE:5)
Block(-5,-49,6,STONE:5)
Block(-5,-49,7,SMOOTH_BRICK:0)
Block(-5,-49,8,SMOOTH_BRICK:1)
Block(-5,-48,3,COBBLESTONE:0)
Block(-5,-48,4,COBBLESTONE:0)
Block(-5,-48,5,STONE:5)
Block(-5,-48,6,STONE:5)
Block(-5,-48,7,SMOOTH_BRICK:0)
Block(-5,-48,8,SMOOTH_BRICK:1)
Block(-5,-47,3,COBBLESTONE:0)
Block(-5,-47,4,COBBLESTONE:0)
Block(-5,-47,5,STONE:5)
Block(-5,-47,6,STONE:5)
Block(-5,-47,7,SMOOTH_BRICK:0)
Block(-5,-47,8,SMOOTH_BRICK:1)
Block(-5,-46,3,COBBLESTONE:0)
Block(-5,-46,4,COBBLESTONE:0)
Block(-5,-46,5,STONE:5)
Block(-5,-46,6,STONE:5)
Block(-5,-46,7,SMOOTH_BRICK:0)
Block(-5,-46,8,SMOOTH_BRICK:1)
Block(-5,-45,3,COBBLESTONE:0)
Block(-5,-45,4,COBBLESTONE:0)
Block(-5,-45,5,STONE:5)
Block(-5,-45,6,STONE:5)
Block(-5,-45,7,SMOOTH_BRICK:0)
Block(-5,-45,8,SMOOTH_BRICK:1)
Block(-5,-44,3,COBBLESTONE:0)
Block(-5,-44,4,COBBLESTONE:0)
Block(-5,-44,5,STONE:5)
Block(-5,-44,6,STONE:5)
Block(-5,-44,7,SMOOTH_BRICK:0)
Block(-5,-44,8,SMOOTH_BRICK:1)
Block(-5,-43,3,COBBLESTONE:0)
Block(-5,-43,4,COBBLESTONE:0)
Block(-5,-43,5,STONE:5)
Block(-5,-43,6,STONE:5)
Block(-5,-43,7,SMOOTH_BRICK:0)
Block(-5,-43,8,SMOOTH_BRICK:1)
Block(-5,-42,3,COBBLESTONE:0)
Block(-5,-42,4,COBBLESTONE:0)
Block(-5,-42,5,STONE:5)
Block(-5,-42,6,STONE:5)
Block(-5,-42,7,SMOOTH_BRICK:0)
Block(-5,-42,8,SMOOTH_BRICK:1)
Block(-5,-41,3,COBBLESTONE:0)
Block(-5,-41,4,COBBLESTONE:0)
Block(-5,-41,5,STONE:5)
Block(-5,-41,6,STONE:5)
Block(-5,-41,7,SMOOTH_BRICK:0)
Block(-5,-41,8,SMOOTH_BRICK:1)
Block(-5,-40,3,COBBLESTONE:0)
Block(-5,-40,4,COBBLESTONE:0)
Block(-5,-40,5,STONE:5)
Block(-5,-40,6,STONE:5)
Block(-5,-40,7,SMOOTH_BRICK:0)
Block(-5,-40,8,SMOOTH_BRICK:1)
Block(-5,-39,3,COBBLESTONE:0)
Block(-5,-39,4,COBBLESTONE:0)
Block(-5,-39,5,STONE:5)
Block(-5,-39,6,STONE:5)
Block(-5,-39,7,SMOOTH_BRICK:0)
Block(-5,-39,8,SMOOTH_BRICK:1)
Block(-5,-38,3,COBBLESTONE:0)
Block(-5,-38,4,COBBLESTONE:0)
Block(-5,-38,5,STONE:5)
Block(-5,-38,6,STONE:5)
Block(-5,-38,7,SMOOTH_BRICK:0)
Block(-5,-38,8,SMOOTH_BRICK:1)
Block(-5,-37,3,COBBLESTONE:0)
Block(-5,-37,4,COBBLESTONE:0)
Block(-5,-37,5,STONE:5)
Block(-5,-37,6,STONE:5)
Block(-5,-37,7,SMOOTH_BRICK:0)
Block(-5,-37,8,SMOOTH_BRICK:1)
Block(-5,-36,3,COBBLESTONE:0)
Block(-5,-36,4,COBBLESTONE:0)
Block(-5,-36,5,STONE:5)
Block(-5,-36,6,STONE:5)
Block(-5,-36,7,SMOOTH_BRICK:0)
Block(-5,-36,8,SMOOTH_BRICK:1)
Block(-5,-35,3,COBBLESTONE:0)
Block(-5,-35,4,COBBLESTONE:0)
Block(-5,-35,5,STONE:5)
Block(-5,-35,6,STONE:5)
Block(-5,-35,7,SMOOTH_BRICK:0)
Block(-5,-35,8,SMOOTH_BRICK:1)
Block(-5,-34,3,COBBLESTONE:0)
Block(-5,-34,4,COBBLESTONE:0)
Block(-5,-34,5,STONE:5)
Block(-5,-34,6,STONE:5)
Block(-5,-34,7,SMOOTH_BRICK:0)
Block(-5,-34,8,SMOOTH_BRICK:1)
Block(-5,-33,3,COBBLESTONE:0)
Block(-5,-33,4,COBBLESTONE:0)
Block(-5,-33,5,STONE:5)
Block(-5,-33,6,STONE:5)
Block(-5,-33,7,SMOOTH_BRICK:0)
Block(-5,-33,8,SMOOTH_BRICK:1)
Block(-5,-32,3,COBBLESTONE:0)
Block(-5,-32,4,COBBLESTONE:0)
Block(-5,-32,5,STONE:5)
Block(-5,-32,6,STONE:5)
Block(-5,-32,7,SMOOTH_BRICK:0)
Block(-5,-32,8,SMOOTH_BRICK:1)
Block(-5,-31,3,COBBLESTONE:0)
Block(-5,-31,4,COBBLESTONE:0)
Block(-5,-31,5,STONE:5)
Block(-5,-31,6,STONE:5)
Block(-5,-31,7,SMOOTH_BRICK:0)
Block(-5,-31,8,SMOOTH_BRICK:1)
Block(-5,-30,3,COBBLESTONE:0)
Block(-5,-30,4,COBBLESTONE:0)
Block(-5,-30,5,STONE:5)
Block(-5,-30,6,STONE:5)
Block(-5,-30,7,SMOOTH_BRICK:0)
Block(-5,-30,8,SMOOTH_BRICK:1)
Block(-5,-29,3,COBBLESTONE:0)
Block(-5,-29,4,COBBLESTONE:0)
Block(-5,-29,5,STONE:5)
Block(-5,-29,6,STONE:5)
Block(-5,-29,7,SMOOTH_BRICK:0)
Block(-5,-29,8,SMOOTH_BRICK:1)
Block(-5,-28,3,COBBLESTONE:0)
Block(-5,-28,4,COBBLESTONE:0)
Block(-5,-28,5,STONE:5)
Block(-5,-28,6,STONE:5)
Block(-5,-28,7,SMOOTH_BRICK:0)
Block(-5,-28,8,SMOOTH_BRICK:1)
Block(-5,-27,3,COBBLESTONE:0)
Block(-5,-27,4,COBBLESTONE:0)
Block(-5,-27,5,STONE:5)
Block(-5,-27,6,STONE:5)
Block(-5,-27,7,SMOOTH_BRICK:0)
Block(-5,-27,8,SMOOTH_BRICK:1)
Block(-5,-26,3,COBBLESTONE:0)
Block(-5,-26,4,COBBLESTONE:0)
Block(-5,-26,5,STONE:5)
Block(-5,-26,6,STONE:5)
Block(-5,-26,7,SMOOTH_BRICK:0)
Block(-5,-26,8,SMOOTH_BRICK:1)
Block(-5,-25,3,COBBLESTONE:0)
Block(-5,-25,4,COBBLESTONE:0)
Block(-5,-25,5,STONE:5)
Block(-5,-25,6,STONE:5)
Block(-5,-25,7,SMOOTH_BRICK:0)
Block(-5,-25,8,SMOOTH_BRICK:1)
Block(-5,-24,3,COBBLESTONE:0)
Block(-5,-24,4,COBBLESTONE:0)
Block(-5,-24,5,STONE:5)
Block(-5,-24,6,STONE:5)
Block(-5,-24,7,SMOOTH_BRICK:0)
Block(-5,-24,8,SMOOTH_BRICK:1)
Block(-5,-23,3,COBBLESTONE:0)
Block(-5,-23,4,COBBLESTONE:0)
Block(-5,-23,5,STONE:5)
Block(-5,-23,6,STONE:5)
Block(-5,-23,7,SMOOTH_BRICK:0)
Block(-5,-23,8,SMOOTH_BRICK:1)
Block(-5,-22,3,COBBLESTONE:0)
Block(-5,-22,4,COBBLESTONE:0)
Block(-5,-22,5,STONE:5)
Block(-5,-22,6,STONE:5)
Block(-5,-22,7,SMOOTH_BRICK:0)
Block(-5,-22,8,SMOOTH_BRICK:1)
Block(-5,-21,3,COBBLESTONE:0)
Block(-5,-21,4,COBBLESTONE:0)
Block(-5,-21,5,STONE:5)
Block(-5,-21,6,STONE:5)
Block(-5,-21,7,SMOOTH_BRICK:0)
Block(-5,-21,8,SMOOTH_BRICK:1)
Block(-5,-20,3,COBBLESTONE:0)
Block(-5,-20,4,COBBLESTONE:0)
Block(-5,-20,5,STONE:5)
Block(-5,-20,6,STONE:5)
Block(-5,-20,7,SMOOTH_BRICK:0)
Block(-5,-20,8,SMOOTH_BRICK:1)
Block(-5,-19,3,STONE:5)
Block(-5,-19,4,STONE:5)
Block(-5,-19,5,COBBLESTONE:0)
Block(-5,-19,6,STONE:5)
Block(-5,-19,7,STONE:5)
Block(-5,-19,8,COBBLESTONE:0)
Block(-5,-18,3,SMOOTH_BRICK:2)
Block(-5,-18,4,COBBLESTONE:0)
Block(-5,-18,5,STONE:5)
Block(-5,-18,6,STONE:5)
Block(-5,-18,7,SMOOTH_BRICK:0)
Block(-5,-18,8,COBBLESTONE:0)
Block(-5,-17,3,STONE:5)
Block(-5,-17,4,COBBLESTONE:0)
Block(-5,-17,5,STONE:5)
Block(-5,-17,6,STONE:5)
Block(-5,-17,7,COBBLESTONE:0)
Block(-5,-17,8,COBBLESTONE:0)
Block(-5,-16,3,COBBLESTONE:0)
Block(-5,-16,4,COBBLESTONE:0)
Block(-5,-16,5,COBBLESTONE:0)
Block(-5,-16,6,COBBLESTONE:0)
Block(-5,-16,7,STONE:5)
Block(-5,-16,8,STONE:5)
Block(-5,-15,3,COBBLESTONE:0)
Block(-5,-15,4,COBBLESTONE:0)
Block(-5,-15,5,STONE:5)
Block(-5,-15,6,SMOOTH_BRICK:0)
Block(-5,-15,7,STONE:5)
Block(-5,-15,8,COBBLESTONE:0)
Block(-5,-14,3,STONE:5)
Block(-5,-14,4,COBBLESTONE:0)
Block(-5,-14,5,SMOOTH_BRICK:1)
Block(-5,-14,6,STONE:5)
Block(-5,-14,7,STONE:5)
Block(-5,-14,8,SMOOTH_BRICK:1)
Block(-5,-13,3,COBBLESTONE:0)
Block(-5,-13,4,COBBLESTONE:0)
Block(-5,-13,5,STONE:5)
Block(-5,-13,6,COBBLESTONE:0)
Block(-5,-13,7,COBBLESTONE:0)
Block(-5,-13,8,COBBLESTONE:0)
Block(-5,-12,3,STONE:5)
Block(-5,-12,4,STONE:5)
Block(-5,-12,5,SMOOTH_BRICK:0)
Block(-5,-12,6,STONE:5)
Block(-5,-12,7,STONE:5)
Block(-5,-12,8,COBBLESTONE:0)
Block(-5,-11,3,SMOOTH_BRICK:0)
Block(-5,-11,4,STAINED_CLAY:9)
Block(-5,-11,5,COBBLESTONE:0)
Block(-5,-11,6,COBBLESTONE:0)
Block(-5,-11,7,COBBLESTONE:0)
Block(-5,-11,8,STONE:5)
Block(-5,-10,3,COBBLESTONE:0)
Block(-5,-10,4,STONE:5)
Block(-5,-10,5,STONE:5)
Block(-5,-10,6,SMOOTH_BRICK:0)
Block(-5,-10,7,SMOOTH_BRICK:1)
Block(-5,-10,8,COBBLESTONE:0)
Block(-5,-9,3,COBBLESTONE_STAIRS:2)
Block(-5,-9,4,STONE:6)
Block(-5,-9,5,STONE:6)
Block(-5,-9,6,STONE:6)
Block(-5,-9,7,STONE:6)
Block(-5,-9,8,STONE:6)
Block(-5,-8,4,STONE:6)
Block(-5,-8,5,STONE:6)
Block(-5,-8,6,STONE:6)
Block(-5,-8,7,STONE:6)
Block(-5,-8,8,STONE:6)
Block(-5,-7,4,STONE:6)
Block(-5,-7,5,STONE:6)
Block(-5,-7,6,STONE:6)
Block(-5,-7,7,STONE:6)
Block(-5,-7,8,STONE:6)
Block(-5,-6,4,STONE:6)
Block(-5,-6,5,STONE:6)
Block(-5,-6,6,STONE:6)
Block(-5,-6,7,STONE:6)
Block(-5,-6,8,STONE:6)
Block(-5,-5,4,COBBLESTONE_STAIRS:2)
Block(-5,-5,5,STONE:5)
Block(-5,-5,6,COBBLESTONE:0)
Block(-5,-5,7,STAINED_CLAY:9)
Block(-5,-5,8,STONE:5)
Block(-5,-4,5,STONE:6)
Block(-5,-4,6,STONE:6)
Block(-5,-4,7,STONE:6)
Block(-5,-4,8,STONE:6)
Block(-5,-3,5,STONE:6)
Block(-5,-3,6,STONE:6)
Block(-5,-3,7,STONE:6)
Block(-5,-3,8,STONE:6)
Block(-5,-2,5,STONE:6)
Block(-5,-2,6,STONE:6)
Block(-5,-2,7,STONE:6)
Block(-5,-2,8,STONE:6)
Block(-5,-1,5,COBBLESTONE_STAIRS:2)
Block(-5,-1,6,STONE:6)
Block(-5,-1,7,STONE:6)
Block(-5,-1,8,STONE:6)
Block(-5,0,6,STONE:6)
Block(-5,0,7,STONE:6)
Block(-5,0,8,STONE:6)
Block(-5,1,6,STONE:6)
Block(-5,1,7,STONE:6)
Block(-5,1,8,STONE:6)
Block(-5,2,6,STONE:6)
Block(-5,2,7,STONE:6)
Block(-5,2,8,STONE:6)
Block(-5,3,6,STONE:6)
Block(-5,3,7,STONE:6)
Block(-5,3,8,STONE:6)
Block(-5,4,6,STONE:6)
Block(-5,4,7,STONE:6)
Block(-5,4,8,STONE:6)
Block(-5,5,6,STONE:6)
Block(-5,5,7,STONE:6)
Block(-5,5,8,STONE:6)
Block(-5,6,6,DARK_OAK_FENCE:0)
Block(-5,6,7,COBBLESTONE_STAIRS:1)
Block(-5,6,8,SMOOTH_BRICK:0)
Block(-5,7,6,AIR:0)
Block(-5,7,7,COBBLESTONE_STAIRS:6)
Block(-5,7,8,COBBLESTONE_STAIRS:6)
Block(-5,8,6,AIR:0)
Block(-5,8,7,SMOOTH_BRICK:0)
Block(-5,8,8,SMOOTH_BRICK:0)
Block(-5,9,6,COBBLESTONE_STAIRS:6)
Block(-5,9,7,SMOOTH_BRICK:0)
Block(-5,9,8,SMOOTH_BRICK:0)
Block(-5,10,6,SMOOTH_STAIRS:1)
Block(-5,10,7,STEP:3)
Block(-5,10,8,STEP:3)
Block(-5,11,6,AIR:0)
Block(-5,11,7,AIR:0)
Block(-5,11,8,AIR:0)
Block(-5,12,6,AIR:0)
Block(-5,12,7,AIR:0)
Block(-5,12,8,AIR:0)
Block(-5,13,6,AIR:0)
Block(-5,13,7,AIR:0)
Block(-5,13,8,AIR:0)
Block(-5,14,6,AIR:0)
Block(-5,14,7,AIR:0)
Block(-5,14,8,AIR:0)
Block(-5,15,6,AIR:0)
Block(-5,15,7,AIR:0)
Block(-5,15,8,AIR:0)
Block(-5,16,6,AIR:0)
Block(-5,16,7,AIR:0)
Block(-5,16,8,DARK_OAK_STAIRS:6)
Block(-5,17,6,AIR:0)
Block(-5,17,7,AIR:0)
Block(-5,17,8,STEP:3)
Block(-5,18,6,AIR:0)
Block(-5,18,7,AIR:0)
Block(-5,18,8,WOOD_STEP:5)
Block(-5,19,6,AIR:0)
Block(-5,19,7,AIR:0)
Block(-5,19,8,AIR:0)
Block(-5,20,6,AIR:0)
Block(-5,20,7,AIR:0)
Block(-5,20,8,AIR:0)
Block(-5,21,6,AIR:0)
Block(-5,21,7,AIR:0)
Block(-5,21,8,AIR:0)
Block(-5,22,6,AIR:0)
Block(-5,22,7,AIR:0)
Block(-5,22,8,AIR:0)
Block(-5,23,6,AIR:0)
Block(-5,23,7,AIR:0)
Block(-5,23,8,AIR:0)
Block(-5,24,6,AIR:0)
Block(-5,24,7,AIR:0)
Block(-5,24,8,AIR:0)
Block(-5,25,6,AIR:0)
Block(-5,25,7,AIR:0)
Block(-5,25,8,AIR:0)
Block(-5,26,6,AIR:0)
Block(-5,26,7,AIR:0)
Block(-5,26,8,AIR:0)
Block(-5,27,6,AIR:0)
Block(-5,27,7,AIR:0)
Block(-5,27,8,AIR:0)
Block(-5,28,6,AIR:0)
Block(-5,28,7,AIR:0)
Block(-5,28,8,AIR:0)
Block(-5,29,6,AIR:0)
Block(-5,29,7,AIR:0)
Block(-5,29,8,AIR:0)
Block(-5,30,6,AIR:0)
Block(-5,30,7,AIR:0)
Block(-5,30,8,AIR:0)
Block(-5,31,6,AIR:0)
Block(-5,31,7,AIR:0)
Block(-5,31,8,AIR:0)
Block(-5,32,6,AIR:0)
Block(-5,32,7,AIR:0)
Block(-5,32,8,AIR:0)
Block(-5,33,6,AIR:0)
Block(-5,33,7,AIR:0)
Block(-5,33,8,AIR:0)
Block(-5,34,6,AIR:0)
Block(-5,34,7,AIR:0)
Block(-5,34,8,AIR:0)
Block(-5,35,6,AIR:0)
Block(-5,35,7,AIR:0)
Block(-5,35,8,AIR:0)
Block(-5,36,6,AIR:0)
Block(-5,36,7,AIR:0)
Block(-5,36,8,AIR:0)
Block(-5,37,6,AIR:0)
Block(-5,37,7,AIR:0)
Block(-5,37,8,AIR:0)
Block(-5,38,6,AIR:0)
Block(-5,38,7,AIR:0)
Block(-5,38,8,AIR:0)
Block(-5,39,6,AIR:0)
Block(-5,39,7,AIR:0)
Block(-5,39,8,AIR:0)
Block(-5,40,6,AIR:0)
Block(-5,40,7,AIR:0)
Block(-5,40,8,AIR:0)
Block(-5,41,6,AIR:0)
Block(-5,41,7,AIR:0)
Block(-5,41,8,AIR:0)
Block(-5,42,6,AIR:0)
Block(-5,42,7,AIR:0)
Block(-5,42,8,AIR:0)
Block(-5,43,6,AIR:0)
Block(-5,43,7,AIR:0)
Block(-5,43,8,AIR:0)
Block(-5,44,6,AIR:0)
Block(-5,44,7,AIR:0)
Block(-5,44,8,AIR:0)
Block(-5,45,6,AIR:0)
Block(-5,45,7,AIR:0)
Block(-5,45,8,AIR:0)
Block(-5,46,6,AIR:0)
Block(-5,46,7,AIR:0)
Block(-5,46,8,AIR:0)
Block(-4,-50,3,STONE:5)
Block(-4,-50,4,COBBLESTONE:0)
Block(-4,-50,5,SMOOTH_BRICK:0)
Block(-4,-50,6,SMOOTH_BRICK:1)
Block(-4,-50,7,STONE:5)
Block(-4,-50,8,COBBLESTONE:0)
Block(-4,-49,3,STONE:5)
Block(-4,-49,4,COBBLESTONE:0)
Block(-4,-49,5,SMOOTH_BRICK:0)
Block(-4,-49,6,SMOOTH_BRICK:1)
Block(-4,-49,7,STONE:5)
Block(-4,-49,8,COBBLESTONE:0)
Block(-4,-48,3,STONE:5)
Block(-4,-48,4,COBBLESTONE:0)
Block(-4,-48,5,SMOOTH_BRICK:0)
Block(-4,-48,6,SMOOTH_BRICK:1)
Block(-4,-48,7,STONE:5)
Block(-4,-48,8,COBBLESTONE:0)
Block(-4,-47,3,STONE:5)
Block(-4,-47,4,COBBLESTONE:0)
Block(-4,-47,5,SMOOTH_BRICK:0)
Block(-4,-47,6,SMOOTH_BRICK:1)
Block(-4,-47,7,STONE:5)
Block(-4,-47,8,COBBLESTONE:0)
Block(-4,-46,3,STONE:5)
Block(-4,-46,4,COBBLESTONE:0)
Block(-4,-46,5,SMOOTH_BRICK:0)
Block(-4,-46,6,SMOOTH_BRICK:1)
Block(-4,-46,7,STONE:5)
Block(-4,-46,8,COBBLESTONE:0)
Block(-4,-45,3,STONE:5)
Block(-4,-45,4,COBBLESTONE:0)
Block(-4,-45,5,SMOOTH_BRICK:0)
Block(-4,-45,6,SMOOTH_BRICK:1)
Block(-4,-45,7,STONE:5)
Block(-4,-45,8,COBBLESTONE:0)
Block(-4,-44,3,STONE:5)
Block(-4,-44,4,COBBLESTONE:0)
Block(-4,-44,5,SMOOTH_BRICK:0)
Block(-4,-44,6,SMOOTH_BRICK:1)
Block(-4,-44,7,STONE:5)
Block(-4,-44,8,COBBLESTONE:0)
Block(-4,-43,3,STONE:5)
Block(-4,-43,4,COBBLESTONE:0)
Block(-4,-43,5,SMOOTH_BRICK:0)
Block(-4,-43,6,SMOOTH_BRICK:1)
Block(-4,-43,7,STONE:5)
Block(-4,-43,8,COBBLESTONE:0)
Block(-4,-42,3,STONE:5)
Block(-4,-42,4,COBBLESTONE:0)
Block(-4,-42,5,SMOOTH_BRICK:0)
Block(-4,-42,6,SMOOTH_BRICK:1)
Block(-4,-42,7,STONE:5)
Block(-4,-42,8,COBBLESTONE:0)
Block(-4,-41,3,STONE:5)
Block(-4,-41,4,COBBLESTONE:0)
Block(-4,-41,5,SMOOTH_BRICK:0)
Block(-4,-41,6,SMOOTH_BRICK:1)
Block(-4,-41,7,STONE:5)
Block(-4,-41,8,COBBLESTONE:0)
Block(-4,-40,3,STONE:5)
Block(-4,-40,4,COBBLESTONE:0)
Block(-4,-40,5,SMOOTH_BRICK:0)
Block(-4,-40,6,SMOOTH_BRICK:1)
Block(-4,-40,7,STONE:5)
Block(-4,-40,8,COBBLESTONE:0)
Block(-4,-39,3,STONE:5)
Block(-4,-39,4,COBBLESTONE:0)
Block(-4,-39,5,SMOOTH_BRICK:0)
Block(-4,-39,6,SMOOTH_BRICK:1)
Block(-4,-39,7,STONE:5)
Block(-4,-39,8,COBBLESTONE:0)
Block(-4,-38,3,STONE:5)
Block(-4,-38,4,COBBLESTONE:0)
Block(-4,-38,5,SMOOTH_BRICK:0)
Block(-4,-38,6,SMOOTH_BRICK:1)
Block(-4,-38,7,STONE:5)
Block(-4,-38,8,COBBLESTONE:0)
Block(-4,-37,3,STONE:5)
Block(-4,-37,4,COBBLESTONE:0)
Block(-4,-37,5,SMOOTH_BRICK:0)
Block(-4,-37,6,SMOOTH_BRICK:1)
Block(-4,-37,7,STONE:5)
Block(-4,-37,8,COBBLESTONE:0)
Block(-4,-36,3,STONE:5)
Block(-4,-36,4,COBBLESTONE:0)
Block(-4,-36,5,SMOOTH_BRICK:0)
Block(-4,-36,6,SMOOTH_BRICK:1)
Block(-4,-36,7,STONE:5)
Block(-4,-36,8,COBBLESTONE:0)
Block(-4,-35,3,STONE:5)
Block(-4,-35,4,COBBLESTONE:0)
Block(-4,-35,5,SMOOTH_BRICK:0)
Block(-4,-35,6,SMOOTH_BRICK:1)
Block(-4,-35,7,STONE:5)
Block(-4,-35,8,COBBLESTONE:0)
Block(-4,-34,3,STONE:5)
Block(-4,-34,4,COBBLESTONE:0)
Block(-4,-34,5,SMOOTH_BRICK:0)
Block(-4,-34,6,SMOOTH_BRICK:1)
Block(-4,-34,7,STONE:5)
Block(-4,-34,8,COBBLESTONE:0)
Block(-4,-33,3,STONE:5)
Block(-4,-33,4,COBBLESTONE:0)
Block(-4,-33,5,SMOOTH_BRICK:0)
Block(-4,-33,6,SMOOTH_BRICK:1)
Block(-4,-33,7,STONE:5)
Block(-4,-33,8,COBBLESTONE:0)
Block(-4,-32,3,STONE:5)
Block(-4,-32,4,COBBLESTONE:0)
Block(-4,-32,5,SMOOTH_BRICK:0)
Block(-4,-32,6,SMOOTH_BRICK:1)
Block(-4,-32,7,STONE:5)
Block(-4,-32,8,COBBLESTONE:0)
Block(-4,-31,3,STONE:5)
Block(-4,-31,4,COBBLESTONE:0)
Block(-4,-31,5,SMOOTH_BRICK:0)
Block(-4,-31,6,SMOOTH_BRICK:1)
Block(-4,-31,7,STONE:5)
Block(-4,-31,8,COBBLESTONE:0)
Block(-4,-30,3,STONE:5)
Block(-4,-30,4,COBBLESTONE:0)
Block(-4,-30,5,SMOOTH_BRICK:0)
Block(-4,-30,6,SMOOTH_BRICK:1)
Block(-4,-30,7,STONE:5)
Block(-4,-30,8,COBBLESTONE:0)
Block(-4,-29,3,STONE:5)
Block(-4,-29,4,COBBLESTONE:0)
Block(-4,-29,5,SMOOTH_BRICK:0)
Block(-4,-29,6,SMOOTH_BRICK:1)
Block(-4,-29,7,STONE:5)
Block(-4,-29,8,COBBLESTONE:0)
Block(-4,-28,3,STONE:5)
Block(-4,-28,4,COBBLESTONE:0)
Block(-4,-28,5,SMOOTH_BRICK:0)
Block(-4,-28,6,SMOOTH_BRICK:1)
Block(-4,-28,7,STONE:5)
Block(-4,-28,8,COBBLESTONE:0)
Block(-4,-27,3,STONE:5)
Block(-4,-27,4,COBBLESTONE:0)
Block(-4,-27,5,SMOOTH_BRICK:0)
Block(-4,-27,6,SMOOTH_BRICK:1)
Block(-4,-27,7,STONE:5)
Block(-4,-27,8,COBBLESTONE:0)
Block(-4,-26,3,STONE:5)
Block(-4,-26,4,COBBLESTONE:0)
Block(-4,-26,5,SMOOTH_BRICK:0)
Block(-4,-26,6,SMOOTH_BRICK:1)
Block(-4,-26,7,STONE:5)
Block(-4,-26,8,COBBLESTONE:0)
Block(-4,-25,3,STONE:5)
Block(-4,-25,4,COBBLESTONE:0)
Block(-4,-25,5,SMOOTH_BRICK:0)
Block(-4,-25,6,SMOOTH_BRICK:1)
Block(-4,-25,7,STONE:5)
Block(-4,-25,8,COBBLESTONE:0)
Block(-4,-24,3,STONE:5)
Block(-4,-24,4,COBBLESTONE:0)
Block(-4,-24,5,SMOOTH_BRICK:0)
Block(-4,-24,6,SMOOTH_BRICK:1)
Block(-4,-24,7,STONE:5)
Block(-4,-24,8,COBBLESTONE:0)
Block(-4,-23,3,STONE:5)
Block(-4,-23,4,COBBLESTONE:0)
Block(-4,-23,5,SMOOTH_BRICK:0)
Block(-4,-23,6,SMOOTH_BRICK:1)
Block(-4,-23,7,STONE:5)
Block(-4,-23,8,COBBLESTONE:0)
Block(-4,-22,3,STONE:5)
Block(-4,-22,4,COBBLESTONE:0)
Block(-4,-22,5,SMOOTH_BRICK:0)
Block(-4,-22,6,SMOOTH_BRICK:1)
Block(-4,-22,7,STONE:5)
Block(-4,-22,8,COBBLESTONE:0)
Block(-4,-21,3,STONE:5)
Block(-4,-21,4,COBBLESTONE:0)
Block(-4,-21,5,SMOOTH_BRICK:0)
Block(-4,-21,6,SMOOTH_BRICK:1)
Block(-4,-21,7,STONE:5)
Block(-4,-21,8,COBBLESTONE:0)
Block(-4,-20,3,STONE:5)
Block(-4,-20,4,COBBLESTONE:0)
Block(-4,-20,5,SMOOTH_BRICK:0)
Block(-4,-20,6,SMOOTH_BRICK:1)
Block(-4,-20,7,STONE:5)
Block(-4,-20,8,COBBLESTONE:0)
Block(-4,-19,3,STONE:5)
Block(-4,-19,4,COBBLESTONE:0)
Block(-4,-19,5,STONE:5)
Block(-4,-19,6,COBBLESTONE:0)
Block(-4,-19,7,SMOOTH_BRICK:2)
Block(-4,-19,8,COBBLESTONE:0)
Block(-4,-18,3,STONE:5)
Block(-4,-18,4,STONE:5)
Block(-4,-18,5,COBBLESTONE:0)
Block(-4,-18,6,SMOOTH_BRICK:1)
Block(-4,-18,7,STONE:5)
Block(-4,-18,8,STONE:5)
Block(-4,-17,3,SMOOTH_BRICK:1)
Block(-4,-17,4,COBBLESTONE:0)
Block(-4,-17,5,COBBLESTONE:0)
Block(-4,-17,6,SMOOTH_BRICK:1)
Block(-4,-17,7,STONE:5)
Block(-4,-17,8,SMOOTH_BRICK:0)
Block(-4,-16,3,COBBLESTONE:0)
Block(-4,-16,4,STONE:5)
Block(-4,-16,5,COBBLESTONE:0)
Block(-4,-16,6,COBBLESTONE:0)
Block(-4,-16,7,STONE:5)
Block(-4,-16,8,STONE:5)
Block(-4,-15,3,SMOOTH_BRICK:0)
Block(-4,-15,4,COBBLESTONE:0)
Block(-4,-15,5,COBBLESTONE:0)
Block(-4,-15,6,COBBLESTONE:0)
Block(-4,-15,7,COBBLESTONE:0)
Block(-4,-15,8,SMOOTH_BRICK:2)
Block(-4,-14,3,SMOOTH_BRICK:0)
Block(-4,-14,4,STONE:5)
Block(-4,-14,5,STONE:5)
Block(-4,-14,6,STONE:5)
Block(-4,-14,7,COBBLESTONE:0)
Block(-4,-14,8,STONE:5)
Block(-4,-13,3,COBBLESTONE:0)
Block(-4,-13,4,SMOOTH_BRICK:1)
Block(-4,-13,5,COBBLESTONE:0)
Block(-4,-13,6,COBBLESTONE:0)
Block(-4,-13,7,COBBLESTONE:0)
Block(-4,-13,8,COBBLESTONE:0)
Block(-4,-12,3,COBBLESTONE:0)
Block(-4,-12,4,STONE:5)
Block(-4,-12,5,STONE:5)
Block(-4,-12,6,COBBLESTONE:0)
Block(-4,-12,7,COBBLESTONE:0)
Block(-4,-12,8,STONE:5)
Block(-4,-11,3,COBBLESTONE:0)
Block(-4,-11,4,COBBLESTONE:0)
Block(-4,-11,5,SMOOTH_BRICK:2)
Block(-4,-11,6,STONE:5)
Block(-4,-11,7,COBBLESTONE:0)
Block(-4,-11,8,COBBLESTONE:0)
Block(-4,-10,3,STONE:5)
Block(-4,-10,4,COBBLESTONE:0)
Block(-4,-10,5,COBBLESTONE:0)
Block(-4,-10,6,SMOOTH_BRICK:1)
Block(-4,-10,7,STAINED_CLAY:9)
Block(-4,-10,8,COBBLESTONE:0)
Block(-4,-9,3,COBBLESTONE_STAIRS:2)
Block(-4,-9,4,STONE:6)
Block(-4,-9,5,STONE:6)
Block(-4,-9,6,STONE:6)
Block(-4,-9,7,STONE:6)
Block(-4,-9,8,STONE:6)
Block(-4,-8,4,STONE:6)
Block(-4,-8,5,STONE:6)
Block(-4,-8,6,STONE:6)
Block(-4,-8,7,STONE:6)
Block(-4,-8,8,STONE:6)
Block(-4,-7,4,STONE:6)
Block(-4,-7,5,STONE:6)
Block(-4,-7,6,STONE:6)
Block(-4,-7,7,STONE:6)
Block(-4,-7,8,STONE:6)
Block(-4,-6,4,STONE:6)
Block(-4,-6,5,STONE:6)
Block(-4,-6,6,STONE:6)
Block(-4,-6,7,STONE:6)
Block(-4,-6,8,STONE:6)
Block(-4,-5,4,COBBLESTONE_STAIRS:2)
Block(-4,-5,5,COBBLESTONE:0)
Block(-4,-5,6,COBBLESTONE:0)
Block(-4,-5,7,STONE:5)
Block(-4,-5,8,COBBLESTONE:0)
Block(-4,-4,5,STONE:6)
Block(-4,-4,6,STONE:6)
Block(-4,-4,7,STONE:6)
Block(-4,-4,8,STONE:6)
Block(-4,-3,5,STONE:6)
Block(-4,-3,6,STONE:6)
Block(-4,-3,7,STONE:6)
Block(-4,-3,8,STONE:6)
Block(-4,-2,5,STONE:6)
Block(-4,-2,6,STONE:6)
Block(-4,-2,7,STONE:6)
Block(-4,-2,8,STONE:6)
Block(-4,-1,5,COBBLESTONE_STAIRS:2)
Block(-4,-1,6,STONE:6)
Block(-4,-1,7,STONE:6)
Block(-4,-1,8,STONE:6)
Block(-4,0,6,STONE:6)
Block(-4,0,7,STONE:6)
Block(-4,0,8,STONE:6)
Block(-4,1,6,STONE:6)
Block(-4,1,7,STONE:6)
Block(-4,1,8,STONE:6)
Block(-4,2,6,STONE:6)
Block(-4,2,7,STONE:6)
Block(-4,2,8,STONE:6)
Block(-4,3,6,STONE:6)
Block(-4,3,7,STONE:6)
Block(-4,3,8,STONE:6)
Block(-4,4,6,STONE:6)
Block(-4,4,7,STONE:6)
Block(-4,4,8,STONE:6)
Block(-4,5,6,STONE:6)
Block(-4,5,7,STONE:6)
Block(-4,5,8,STONE:6)
Block(-4,6,6,DARK_OAK_FENCE:0)
Block(-4,6,7,COBBLESTONE_STAIRS:0)
Block(-4,6,8,SMOOTH_BRICK:0)
Block(-4,7,6,AIR:0)
Block(-4,7,7,COBBLESTONE_STAIRS:6)
Block(-4,7,8,SMOOTH_BRICK:0)
Block(-4,8,6,AIR:0)
Block(-4,8,7,SMOOTH_BRICK:0)
Block(-4,8,8,SMOOTH_BRICK:0)
Block(-4,9,6,COBBLESTONE_STAIRS:6)
Block(-4,9,7,SMOOTH_BRICK:0)
Block(-4,9,8,SMOOTH_BRICK:0)
Block(-4,10,6,SMOOTH_STAIRS:0)
Block(-4,10,7,STONE:6)
Block(-4,10,8,STEP:3)
Block(-4,11,6,AIR:0)
Block(-4,11,7,STONE:6)
Block(-4,11,8,AIR:0)
Block(-4,12,6,AIR:0)
Block(-4,12,7,STONE:6)
Block(-4,12,8,AIR:0)
Block(-4,13,6,AIR:0)
Block(-4,13,7,SMOOTH_STAIRS:2)
Block(-4,13,8,LOG:8)
Block(-4,14,6,AIR:0)
Block(-4,14,7,AIR:0)
Block(-4,14,8,LOG:0)
Block(-4,15,6,AIR:0)
Block(-4,15,7,AIR:0)
Block(-4,15,8,LOG:0)
Block(-4,16,6,AIR:0)
Block(-4,16,7,AIR:0)
Block(-4,16,8,LOG:0)
Block(-4,17,6,AIR:0)
Block(-4,17,7,AIR:0)
Block(-4,17,8,SMOOTH_STAIRS:2)
Block(-4,18,6,AIR:0)
Block(-4,18,7,AIR:0)
Block(-4,18,8,WOOD_STEP:5)
Block(-4,19,6,AIR:0)
Block(-4,19,7,AIR:0)
Block(-4,19,8,AIR:0)
Block(-4,20,6,AIR:0)
Block(-4,20,7,AIR:0)
Block(-4,20,8,AIR:0)
Block(-4,21,6,AIR:0)
Block(-4,21,7,AIR:0)
Block(-4,21,8,AIR:0)
Block(-4,22,6,AIR:0)
Block(-4,22,7,AIR:0)
Block(-4,22,8,AIR:0)
Block(-4,23,6,AIR:0)
Block(-4,23,7,AIR:0)
Block(-4,23,8,AIR:0)
Block(-4,24,6,AIR:0)
Block(-4,24,7,AIR:0)
Block(-4,24,8,AIR:0)
Block(-4,25,6,AIR:0)
Block(-4,25,7,AIR:0)
Block(-4,25,8,AIR:0)
Block(-4,26,6,AIR:0)
Block(-4,26,7,AIR:0)
Block(-4,26,8,AIR:0)
Block(-4,27,6,AIR:0)
Block(-4,27,7,AIR:0)
Block(-4,27,8,AIR:0)
Block(-4,28,6,AIR:0)
Block(-4,28,7,AIR:0)
Block(-4,28,8,AIR:0)
Block(-4,29,6,AIR:0)
Block(-4,29,7,AIR:0)
Block(-4,29,8,AIR:0)
Block(-4,30,6,AIR:0)
Block(-4,30,7,AIR:0)
Block(-4,30,8,AIR:0)
Block(-4,31,6,AIR:0)
Block(-4,31,7,AIR:0)
Block(-4,31,8,AIR:0)
Block(-4,32,6,AIR:0)
Block(-4,32,7,AIR:0)
Block(-4,32,8,AIR:0)
Block(-4,33,6,AIR:0)
Block(-4,33,7,AIR:0)
Block(-4,33,8,AIR:0)
Block(-4,34,6,AIR:0)
Block(-4,34,7,AIR:0)
Block(-4,34,8,AIR:0)
Block(-4,35,6,AIR:0)
Block(-4,35,7,AIR:0)
Block(-4,35,8,AIR:0)
Block(-4,36,6,AIR:0)
Block(-4,36,7,AIR:0)
Block(-4,36,8,AIR:0)
Block(-4,37,6,AIR:0)
Block(-4,37,7,AIR:0)
Block(-4,37,8,AIR:0)
Block(-4,38,6,AIR:0)
Block(-4,38,7,AIR:0)
Block(-4,38,8,AIR:0)
Block(-4,39,6,AIR:0)
Block(-4,39,7,AIR:0)
Block(-4,39,8,AIR:0)
Block(-4,40,6,AIR:0)
Block(-4,40,7,AIR:0)
Block(-4,40,8,AIR:0)
Block(-4,41,6,AIR:0)
Block(-4,41,7,AIR:0)
Block(-4,41,8,AIR:0)
Block(-4,42,6,AIR:0)
Block(-4,42,7,AIR:0)
Block(-4,42,8,AIR:0)
Block(-4,43,6,AIR:0)
Block(-4,43,7,AIR:0)
Block(-4,43,8,AIR:0)
Block(-4,44,6,AIR:0)
Block(-4,44,7,AIR:0)
Block(-4,44,8,AIR:0)
Block(-4,45,6,AIR:0)
Block(-4,45,7,AIR:0)
Block(-4,45,8,AIR:0)
Block(-4,46,6,AIR:0)
Block(-4,46,7,AIR:0)
Block(-4,46,8,AIR:0)
Block(-3,-50,3,LOG:0)
Block(-3,-50,4,COBBLESTONE:0)
Block(-3,-50,5,STONE:5)
Block(-3,-50,6,COBBLESTONE:0)
Block(-3,-50,7,STONE:5)
Block(-3,-50,8,STONE:5)
Block(-3,-49,3,LOG:0)
Block(-3,-49,4,COBBLESTONE:0)
Block(-3,-49,5,STONE:5)
Block(-3,-49,6,COBBLESTONE:0)
Block(-3,-49,7,STONE:5)
Block(-3,-49,8,STONE:5)
Block(-3,-48,3,LOG:0)
Block(-3,-48,4,COBBLESTONE:0)
Block(-3,-48,5,STONE:5)
Block(-3,-48,6,COBBLESTONE:0)
Block(-3,-48,7,STONE:5)
Block(-3,-48,8,STONE:5)
Block(-3,-47,3,LOG:0)
Block(-3,-47,4,COBBLESTONE:0)
Block(-3,-47,5,STONE:5)
Block(-3,-47,6,COBBLESTONE:0)
Block(-3,-47,7,STONE:5)
Block(-3,-47,8,STONE:5)
Block(-3,-46,3,LOG:0)
Block(-3,-46,4,COBBLESTONE:0)
Block(-3,-46,5,STONE:5)
Block(-3,-46,6,COBBLESTONE:0)
Block(-3,-46,7,STONE:5)
Block(-3,-46,8,STONE:5)
Block(-3,-45,3,LOG:0)
Block(-3,-45,4,COBBLESTONE:0)
Block(-3,-45,5,STONE:5)
Block(-3,-45,6,COBBLESTONE:0)
Block(-3,-45,7,STONE:5)
Block(-3,-45,8,STONE:5)
Block(-3,-44,3,LOG:0)
Block(-3,-44,4,COBBLESTONE:0)
Block(-3,-44,5,STONE:5)
Block(-3,-44,6,COBBLESTONE:0)
Block(-3,-44,7,STONE:5)
Block(-3,-44,8,STONE:5)
Block(-3,-43,3,LOG:0)
Block(-3,-43,4,COBBLESTONE:0)
Block(-3,-43,5,STONE:5)
Block(-3,-43,6,COBBLESTONE:0)
Block(-3,-43,7,STONE:5)
Block(-3,-43,8,STONE:5)
Block(-3,-42,3,LOG:0)
Block(-3,-42,4,COBBLESTONE:0)
Block(-3,-42,5,STONE:5)
Block(-3,-42,6,COBBLESTONE:0)
Block(-3,-42,7,STONE:5)
Block(-3,-42,8,STONE:5)
Block(-3,-41,3,LOG:0)
Block(-3,-41,4,COBBLESTONE:0)
Block(-3,-41,5,STONE:5)
Block(-3,-41,6,COBBLESTONE:0)
Block(-3,-41,7,STONE:5)
Block(-3,-41,8,STONE:5)
Block(-3,-40,3,LOG:0)
Block(-3,-40,4,COBBLESTONE:0)
Block(-3,-40,5,STONE:5)
Block(-3,-40,6,COBBLESTONE:0)
Block(-3,-40,7,STONE:5)
Block(-3,-40,8,STONE:5)
Block(-3,-39,3,LOG:0)
Block(-3,-39,4,COBBLESTONE:0)
Block(-3,-39,5,STONE:5)
Block(-3,-39,6,COBBLESTONE:0)
Block(-3,-39,7,STONE:5)
Block(-3,-39,8,STONE:5)
Block(-3,-38,3,LOG:0)
Block(-3,-38,4,COBBLESTONE:0)
Block(-3,-38,5,STONE:5)
Block(-3,-38,6,COBBLESTONE:0)
Block(-3,-38,7,STONE:5)
Block(-3,-38,8,STONE:5)
Block(-3,-37,3,LOG:0)
Block(-3,-37,4,COBBLESTONE:0)
Block(-3,-37,5,STONE:5)
Block(-3,-37,6,COBBLESTONE:0)
Block(-3,-37,7,STONE:5)
Block(-3,-37,8,STONE:5)
Block(-3,-36,3,LOG:0)
Block(-3,-36,4,COBBLESTONE:0)
Block(-3,-36,5,STONE:5)
Block(-3,-36,6,COBBLESTONE:0)
Block(-3,-36,7,STONE:5)
Block(-3,-36,8,STONE:5)
Block(-3,-35,3,LOG:0)
Block(-3,-35,4,COBBLESTONE:0)
Block(-3,-35,5,STONE:5)
Block(-3,-35,6,COBBLESTONE:0)
Block(-3,-35,7,STONE:5)
Block(-3,-35,8,STONE:5)
Block(-3,-34,3,LOG:0)
Block(-3,-34,4,COBBLESTONE:0)
Block(-3,-34,5,STONE:5)
Block(-3,-34,6,COBBLESTONE:0)
Block(-3,-34,7,STONE:5)
Block(-3,-34,8,STONE:5)
Block(-3,-33,3,LOG:0)
Block(-3,-33,4,COBBLESTONE:0)
Block(-3,-33,5,STONE:5)
Block(-3,-33,6,COBBLESTONE:0)
Block(-3,-33,7,STONE:5)
Block(-3,-33,8,STONE:5)
Block(-3,-32,3,LOG:0)
Block(-3,-32,4,COBBLESTONE:0)
Block(-3,-32,5,STONE:5)
Block(-3,-32,6,COBBLESTONE:0)
Block(-3,-32,7,STONE:5)
Block(-3,-32,8,STONE:5)
Block(-3,-31,3,LOG:0)
Block(-3,-31,4,COBBLESTONE:0)
Block(-3,-31,5,STONE:5)
Block(-3,-31,6,COBBLESTONE:0)
Block(-3,-31,7,STONE:5)
Block(-3,-31,8,STONE:5)
Block(-3,-30,3,LOG:0)
Block(-3,-30,4,COBBLESTONE:0)
Block(-3,-30,5,STONE:5)
Block(-3,-30,6,COBBLESTONE:0)
Block(-3,-30,7,STONE:5)
Block(-3,-30,8,STONE:5)
Block(-3,-29,3,LOG:0)
Block(-3,-29,4,COBBLESTONE:0)
Block(-3,-29,5,STONE:5)
Block(-3,-29,6,COBBLESTONE:0)
Block(-3,-29,7,STONE:5)
Block(-3,-29,8,STONE:5)
Block(-3,-28,3,LOG:0)
Block(-3,-28,4,COBBLESTONE:0)
Block(-3,-28,5,STONE:5)
Block(-3,-28,6,COBBLESTONE:0)
Block(-3,-28,7,STONE:5)
Block(-3,-28,8,STONE:5)
Block(-3,-27,3,LOG:0)
Block(-3,-27,4,COBBLESTONE:0)
Block(-3,-27,5,STONE:5)
Block(-3,-27,6,COBBLESTONE:0)
Block(-3,-27,7,STONE:5)
Block(-3,-27,8,STONE:5)
Block(-3,-26,3,LOG:0)
Block(-3,-26,4,COBBLESTONE:0)
Block(-3,-26,5,STONE:5)
Block(-3,-26,6,COBBLESTONE:0)
Block(-3,-26,7,STONE:5)
Block(-3,-26,8,STONE:5)
Block(-3,-25,3,LOG:0)
Block(-3,-25,4,COBBLESTONE:0)
Block(-3,-25,5,STONE:5)
Block(-3,-25,6,COBBLESTONE:0)
Block(-3,-25,7,STONE:5)
Block(-3,-25,8,STONE:5)
Block(-3,-24,3,LOG:0)
Block(-3,-24,4,COBBLESTONE:0)
Block(-3,-24,5,STONE:5)
Block(-3,-24,6,COBBLESTONE:0)
Block(-3,-24,7,STONE:5)
Block(-3,-24,8,STONE:5)
Block(-3,-23,3,LOG:0)
Block(-3,-23,4,COBBLESTONE:0)
Block(-3,-23,5,STONE:5)
Block(-3,-23,6,COBBLESTONE:0)
Block(-3,-23,7,STONE:5)
Block(-3,-23,8,STONE:5)
Block(-3,-22,3,LOG:0)
Block(-3,-22,4,COBBLESTONE:0)
Block(-3,-22,5,STONE:5)
Block(-3,-22,6,COBBLESTONE:0)
Block(-3,-22,7,STONE:5)
Block(-3,-22,8,STONE:5)
Block(-3,-21,3,LOG:0)
Block(-3,-21,4,COBBLESTONE:0)
Block(-3,-21,5,STONE:5)
Block(-3,-21,6,COBBLESTONE:0)
Block(-3,-21,7,STONE:5)
Block(-3,-21,8,STONE:5)
Block(-3,-20,3,LOG:0)
Block(-3,-20,4,COBBLESTONE:0)
Block(-3,-20,5,STONE:5)
Block(-3,-20,6,COBBLESTONE:0)
Block(-3,-20,7,STONE:5)
Block(-3,-20,8,STONE:5)
Block(-3,-19,3,LOG:0)
Block(-3,-19,4,STONE:5)
Block(-3,-19,5,STONE:5)
Block(-3,-19,6,STONE:5)
Block(-3,-19,7,STONE:5)
Block(-3,-19,8,STONE:5)
Block(-3,-18,3,LOG:0)
Block(-3,-18,4,STONE:5)
Block(-3,-18,5,SMOOTH_BRICK:1)
Block(-3,-18,6,COBBLESTONE:0)
Block(-3,-18,7,STONE:5)
Block(-3,-18,8,COBBLESTONE:0)
Block(-3,-17,3,LOG:0)
Block(-3,-17,4,STONE:5)
Block(-3,-17,5,STONE:5)
Block(-3,-17,6,COBBLESTONE:0)
Block(-3,-17,7,COBBLESTONE:0)
Block(-3,-17,8,STAINED_CLAY:9)
Block(-3,-16,3,LOG:0)
Block(-3,-16,4,SMOOTH_BRICK:2)
Block(-3,-16,5,STONE:5)
Block(-3,-16,6,COBBLESTONE:0)
Block(-3,-16,7,STONE:5)
Block(-3,-16,8,COBBLESTONE:0)
Block(-3,-15,3,LOG:0)
Block(-3,-15,4,STONE:5)
Block(-3,-15,5,STONE:5)
Block(-3,-15,6,SMOOTH_BRICK:0)
Block(-3,-15,7,SMOOTH_BRICK:2)
Block(-3,-15,8,SMOOTH_BRICK:2)
Block(-3,-14,3,LOG:0)
Block(-3,-14,4,COBBLESTONE:0)
Block(-3,-14,5,STONE:5)
Block(-3,-14,6,STONE:5)
Block(-3,-14,7,COBBLESTONE:0)
Block(-3,-14,8,STONE:5)
Block(-3,-13,3,LOG:0)
Block(-3,-13,4,COBBLESTONE:0)
Block(-3,-13,5,COBBLESTONE:0)
Block(-3,-13,6,COBBLESTONE:0)
Block(-3,-13,7,COBBLESTONE:0)
Block(-3,-13,8,COBBLESTONE:0)
Block(-3,-12,3,LOG:0)
Block(-3,-12,4,COBBLESTONE:0)
Block(-3,-12,5,SMOOTH_BRICK:0)
Block(-3,-12,6,SMOOTH_BRICK:0)
Block(-3,-12,7,STONE:5)
Block(-3,-12,8,COBBLESTONE:0)
Block(-3,-11,3,LOG:0)
Block(-3,-11,4,STONE:5)
Block(-3,-11,5,STONE:5)
Block(-3,-11,6,COBBLESTONE:0)
Block(-3,-11,7,STONE:5)
Block(-3,-11,8,COBBLESTONE:0)
Block(-3,-10,3,LOG:0)
Block(-3,-10,4,SMOOTH_BRICK:1)
Block(-3,-10,5,COBBLESTONE:0)
Block(-3,-10,6,STONE:5)
Block(-3,-10,7,SMOOTH_BRICK:0)
Block(-3,-10,8,COBBLESTONE:0)
Block(-3,-9,3,SMOOTH_STAIRS:2)
Block(-3,-9,4,LOG:0)
Block(-3,-9,5,STONE:6)
Block(-3,-9,6,STONE:6)
Block(-3,-9,7,STONE:6)
Block(-3,-9,8,STONE:6)
Block(-3,-8,4,LOG:0)
Block(-3,-8,5,STONE:6)
Block(-3,-8,6,STONE:6)
Block(-3,-8,7,STONE:6)
Block(-3,-8,8,STONE:6)
Block(-3,-7,4,LOG:0)
Block(-3,-7,5,STONE:6)
Block(-3,-7,6,STONE:6)
Block(-3,-7,7,STONE:6)
Block(-3,-7,8,STONE:6)
Block(-3,-6,4,LOG:0)
Block(-3,-6,5,STONE:6)
Block(-3,-6,6,STONE:6)
Block(-3,-6,7,STONE:6)
Block(-3,-6,8,STONE:6)
Block(-3,-5,4,LOG:0)
Block(-3,-5,5,COBBLESTONE:0)
Block(-3,-5,6,COBBLESTONE:0)
Block(-3,-5,7,SMOOTH_BRICK:1)
Block(-3,-5,8,SMOOTH_BRICK:2)
Block(-3,-4,4,COBBLESTONE_STAIRS:2)
Block(-3,-4,5,LOG:8)
Block(-3,-4,6,LOG:0)
Block(-3,-4,7,STONE:6)
Block(-3,-4,8,STONE:6)
Block(-3,-3,6,LOG:0)
Block(-3,-3,7,STONE:6)
Block(-3,-3,8,STONE:6)
Block(-3,-2,6,LOG:0)
Block(-3,-2,7,STONE:6)
Block(-3,-2,8,STONE:6)
Block(-3,-1,6,LOG:0)
Block(-3,-1,7,STONE:6)
Block(-3,-1,8,STONE:6)
Block(-3,0,6,LOG:0)
Block(-3,0,7,STONE:6)
Block(-3,0,8,STONE:6)
Block(-3,1,6,LOG:0)
Block(-3,1,7,STONE:6)
Block(-3,1,8,STONE:6)
Block(-3,2,6,LOG:0)
Block(-3,2,7,STONE:6)
Block(-3,2,8,STONE:6)
Block(-3,3,6,LOG:0)
Block(-3,3,7,STONE:6)
Block(-3,3,8,STONE:6)
Block(-3,4,6,LOG:0)
Block(-3,4,7,STONE:6)
Block(-3,4,8,STONE:6)
Block(-3,5,6,LOG:0)
Block(-3,5,7,STONE:6)
Block(-3,5,8,STONE:6)
Block(-3,6,6,LOG:0)
Block(-3,6,7,LOG:8)
Block(-3,6,8,LOG:8)
Block(-3,7,6,LOG:0)
Block(-3,7,7,COBBLESTONE_STAIRS:5)
Block(-3,7,8,COBBLESTONE_STAIRS:5)
Block(-3,8,6,LOG:0)
Block(-3,8,7,SMOOTH_BRICK:0)
Block(-3,8,8,SMOOTH_BRICK:0)
Block(-3,9,6,LOG:0)
Block(-3,9,7,SMOOTH_BRICK:0)
Block(-3,9,8,SMOOTH_BRICK:0)
Block(-3,10,6,LOG:0)
Block(-3,10,7,LOG:8)
Block(-3,10,8,LOG:8)
Block(-3,11,6,STEP:3)
Block(-3,11,7,AIR:0)
Block(-3,11,8,AIR:0)
Block(-3,12,6,AIR:0)
Block(-3,12,7,AIR:0)
Block(-3,12,8,AIR:0)
Block(-3,13,6,AIR:0)
Block(-3,13,7,AIR:0)
Block(-3,13,8,AIR:0)
Block(-3,14,6,AIR:0)
Block(-3,14,7,AIR:0)
Block(-3,14,8,AIR:0)
Block(-3,15,6,AIR:0)
Block(-3,15,7,AIR:0)
Block(-3,15,8,AIR:0)
Block(-3,16,6,AIR:0)
Block(-3,16,7,AIR:0)
Block(-3,16,8,DARK_OAK_STAIRS:6)
Block(-3,17,6,AIR:0)
Block(-3,17,7,AIR:0)
Block(-3,17,8,STEP:3)
Block(-3,18,6,AIR:0)
Block(-3,18,7,AIR:0)
Block(-3,18,8,WOOD_STEP:5)
Block(-3,19,6,AIR:0)
Block(-3,19,7,AIR:0)
Block(-3,19,8,AIR:0)
Block(-3,20,6,AIR:0)
Block(-3,20,7,AIR:0)
Block(-3,20,8,AIR:0)
Block(-3,21,6,AIR:0)
Block(-3,21,7,AIR:0)
Block(-3,21,8,AIR:0)
Block(-3,22,6,AIR:0)
Block(-3,22,7,AIR:0)
Block(-3,22,8,AIR:0)
Block(-3,23,6,AIR:0)
Block(-3,23,7,AIR:0)
Block(-3,23,8,AIR:0)
Block(-3,24,6,AIR:0)
Block(-3,24,7,AIR:0)
Block(-3,24,8,AIR:0)
Block(-3,25,6,AIR:0)
Block(-3,25,7,AIR:0)
Block(-3,25,8,AIR:0)
Block(-3,26,6,AIR:0)
Block(-3,26,7,AIR:0)
Block(-3,26,8,AIR:0)
Block(-3,27,6,AIR:0)
Block(-3,27,7,AIR:0)
Block(-3,27,8,AIR:0)
Block(-3,28,6,AIR:0)
Block(-3,28,7,AIR:0)
Block(-3,28,8,AIR:0)
Block(-3,29,6,AIR:0)
Block(-3,29,7,AIR:0)
Block(-3,29,8,AIR:0)
Block(-3,30,6,AIR:0)
Block(-3,30,7,AIR:0)
Block(-3,30,8,AIR:0)
Block(-3,31,6,AIR:0)
Block(-3,31,7,AIR:0)
Block(-3,31,8,AIR:0)
Block(-3,32,6,AIR:0)
Block(-3,32,7,AIR:0)
Block(-3,32,8,AIR:0)
Block(-3,33,6,AIR:0)
Block(-3,33,7,AIR:0)
Block(-3,33,8,AIR:0)
Block(-3,34,6,AIR:0)
Block(-3,34,7,AIR:0)
Block(-3,34,8,AIR:0)
Block(-3,35,6,AIR:0)
Block(-3,35,7,AIR:0)
Block(-3,35,8,AIR:0)
Block(-3,36,6,AIR:0)
Block(-3,36,7,AIR:0)
Block(-3,36,8,AIR:0)
Block(-3,37,6,AIR:0)
Block(-3,37,7,AIR:0)
Block(-3,37,8,AIR:0)
Block(-3,38,6,AIR:0)
Block(-3,38,7,AIR:0)
Block(-3,38,8,AIR:0)
Block(-3,39,6,AIR:0)
Block(-3,39,7,AIR:0)
Block(-3,39,8,AIR:0)
Block(-3,40,6,AIR:0)
Block(-3,40,7,AIR:0)
Block(-3,40,8,AIR:0)
Block(-3,41,6,AIR:0)
Block(-3,41,7,AIR:0)
Block(-3,41,8,AIR:0)
Block(-3,42,6,AIR:0)
Block(-3,42,7,AIR:0)
Block(-3,42,8,AIR:0)
Block(-3,43,6,AIR:0)
Block(-3,43,7,AIR:0)
Block(-3,43,8,AIR:0)
Block(-3,44,6,AIR:0)
Block(-3,44,7,AIR:0)
Block(-3,44,8,AIR:0)
Block(-3,45,6,AIR:0)
Block(-3,45,7,AIR:0)
Block(-3,45,8,AIR:0)
Block(-3,46,6,AIR:0)
Block(-3,46,7,AIR:0)
Block(-3,46,8,AIR:0)
Block(-2,-50,3,SMOOTH_BRICK:1)
Block(-2,-50,4,STONE:5)
Block(-2,-50,5,SMOOTH_BRICK:0)
Block(-2,-50,6,SMOOTH_BRICK:2)
Block(-2,-50,7,COBBLESTONE:0)
Block(-2,-50,8,STAINED_CLAY:9)
Block(-2,-49,3,SMOOTH_BRICK:1)
Block(-2,-49,4,STONE:5)
Block(-2,-49,5,SMOOTH_BRICK:0)
Block(-2,-49,6,SMOOTH_BRICK:2)
Block(-2,-49,7,COBBLESTONE:0)
Block(-2,-49,8,STAINED_CLAY:9)
Block(-2,-48,3,SMOOTH_BRICK:1)
Block(-2,-48,4,STONE:5)
Block(-2,-48,5,SMOOTH_BRICK:0)
Block(-2,-48,6,SMOOTH_BRICK:2)
Block(-2,-48,7,COBBLESTONE:0)
Block(-2,-48,8,STAINED_CLAY:9)
Block(-2,-47,3,SMOOTH_BRICK:1)
Block(-2,-47,4,STONE:5)
Block(-2,-47,5,SMOOTH_BRICK:0)
Block(-2,-47,6,SMOOTH_BRICK:2)
Block(-2,-47,7,COBBLESTONE:0)
Block(-2,-47,8,STAINED_CLAY:9)
Block(-2,-46,3,SMOOTH_BRICK:1)
Block(-2,-46,4,STONE:5)
Block(-2,-46,5,SMOOTH_BRICK:0)
Block(-2,-46,6,SMOOTH_BRICK:2)
Block(-2,-46,7,COBBLESTONE:0)
Block(-2,-46,8,STAINED_CLAY:9)
Block(-2,-45,3,SMOOTH_BRICK:1)
Block(-2,-45,4,STONE:5)
Block(-2,-45,5,SMOOTH_BRICK:0)
Block(-2,-45,6,SMOOTH_BRICK:2)
Block(-2,-45,7,COBBLESTONE:0)
Block(-2,-45,8,STAINED_CLAY:9)
Block(-2,-44,3,SMOOTH_BRICK:1)
Block(-2,-44,4,STONE:5)
Block(-2,-44,5,SMOOTH_BRICK:0)
Block(-2,-44,6,SMOOTH_BRICK:2)
Block(-2,-44,7,COBBLESTONE:0)
Block(-2,-44,8,STAINED_CLAY:9)
Block(-2,-43,3,SMOOTH_BRICK:1)
Block(-2,-43,4,STONE:5)
Block(-2,-43,5,SMOOTH_BRICK:0)
Block(-2,-43,6,SMOOTH_BRICK:2)
Block(-2,-43,7,COBBLESTONE:0)
Block(-2,-43,8,STAINED_CLAY:9)
Block(-2,-42,3,SMOOTH_BRICK:1)
Block(-2,-42,4,STONE:5)
Block(-2,-42,5,SMOOTH_BRICK:0)
Block(-2,-42,6,SMOOTH_BRICK:2)
Block(-2,-42,7,COBBLESTONE:0)
Block(-2,-42,8,STAINED_CLAY:9)
Block(-2,-41,3,SMOOTH_BRICK:1)
Block(-2,-41,4,STONE:5)
Block(-2,-41,5,SMOOTH_BRICK:0)
Block(-2,-41,6,SMOOTH_BRICK:2)
Block(-2,-41,7,COBBLESTONE:0)
Block(-2,-41,8,STAINED_CLAY:9)
Block(-2,-40,3,SMOOTH_BRICK:1)
Block(-2,-40,4,STONE:5)
Block(-2,-40,5,SMOOTH_BRICK:0)
Block(-2,-40,6,SMOOTH_BRICK:2)
Block(-2,-40,7,COBBLESTONE:0)
Block(-2,-40,8,STAINED_CLAY:9)
Block(-2,-39,3,SMOOTH_BRICK:1)
Block(-2,-39,4,STONE:5)
Block(-2,-39,5,SMOOTH_BRICK:0)
Block(-2,-39,6,SMOOTH_BRICK:2)
Block(-2,-39,7,COBBLESTONE:0)
Block(-2,-39,8,STAINED_CLAY:9)
Block(-2,-38,3,SMOOTH_BRICK:1)
Block(-2,-38,4,STONE:5)
Block(-2,-38,5,SMOOTH_BRICK:0)
Block(-2,-38,6,SMOOTH_BRICK:2)
Block(-2,-38,7,COBBLESTONE:0)
Block(-2,-38,8,STAINED_CLAY:9)
Block(-2,-37,3,SMOOTH_BRICK:1)
Block(-2,-37,4,STONE:5)
Block(-2,-37,5,SMOOTH_BRICK:0)
Block(-2,-37,6,SMOOTH_BRICK:2)
Block(-2,-37,7,COBBLESTONE:0)
Block(-2,-37,8,STAINED_CLAY:9)
Block(-2,-36,3,SMOOTH_BRICK:1)
Block(-2,-36,4,STONE:5)
Block(-2,-36,5,SMOOTH_BRICK:0)
Block(-2,-36,6,SMOOTH_BRICK:2)
Block(-2,-36,7,COBBLESTONE:0)
Block(-2,-36,8,STAINED_CLAY:9)
Block(-2,-35,3,SMOOTH_BRICK:1)
Block(-2,-35,4,STONE:5)
Block(-2,-35,5,SMOOTH_BRICK:0)
Block(-2,-35,6,SMOOTH_BRICK:2)
Block(-2,-35,7,COBBLESTONE:0)
Block(-2,-35,8,STAINED_CLAY:9)
Block(-2,-34,3,SMOOTH_BRICK:1)
Block(-2,-34,4,STONE:5)
Block(-2,-34,5,SMOOTH_BRICK:0)
Block(-2,-34,6,SMOOTH_BRICK:2)
Block(-2,-34,7,COBBLESTONE:0)
Block(-2,-34,8,STAINED_CLAY:9)
Block(-2,-33,3,SMOOTH_BRICK:1)
Block(-2,-33,4,STONE:5)
Block(-2,-33,5,SMOOTH_BRICK:0)
Block(-2,-33,6,SMOOTH_BRICK:2)
Block(-2,-33,7,COBBLESTONE:0)
Block(-2,-33,8,STAINED_CLAY:9)
Block(-2,-32,3,SMOOTH_BRICK:1)
Block(-2,-32,4,STONE:5)
Block(-2,-32,5,SMOOTH_BRICK:0)
Block(-2,-32,6,SMOOTH_BRICK:2)
Block(-2,-32,7,COBBLESTONE:0)
Block(-2,-32,8,STAINED_CLAY:9)
Block(-2,-31,3,SMOOTH_BRICK:1)
Block(-2,-31,4,STONE:5)
Block(-2,-31,5,SMOOTH_BRICK:0)
Block(-2,-31,6,SMOOTH_BRICK:2)
Block(-2,-31,7,COBBLESTONE:0)
Block(-2,-31,8,STAINED_CLAY:9)
Block(-2,-30,3,SMOOTH_BRICK:1)
Block(-2,-30,4,STONE:5)
Block(-2,-30,5,SMOOTH_BRICK:0)
Block(-2,-30,6,SMOOTH_BRICK:2)
Block(-2,-30,7,COBBLESTONE:0)
Block(-2,-30,8,STAINED_CLAY:9)
Block(-2,-29,3,SMOOTH_BRICK:1)
Block(-2,-29,4,STONE:5)
Block(-2,-29,5,SMOOTH_BRICK:0)
Block(-2,-29,6,SMOOTH_BRICK:2)
Block(-2,-29,7,COBBLESTONE:0)
Block(-2,-29,8,STAINED_CLAY:9)
Block(-2,-28,3,SMOOTH_BRICK:1)
Block(-2,-28,4,STONE:5)
Block(-2,-28,5,SMOOTH_BRICK:0)
Block(-2,-28,6,SMOOTH_BRICK:2)
Block(-2,-28,7,COBBLESTONE:0)
Block(-2,-28,8,STAINED_CLAY:9)
Block(-2,-27,3,SMOOTH_BRICK:1)
Block(-2,-27,4,STONE:5)
Block(-2,-27,5,SMOOTH_BRICK:0)
Block(-2,-27,6,SMOOTH_BRICK:2)
Block(-2,-27,7,COBBLESTONE:0)
Block(-2,-27,8,STAINED_CLAY:9)
Block(-2,-26,3,SMOOTH_BRICK:1)
Block(-2,-26,4,STONE:5)
Block(-2,-26,5,SMOOTH_BRICK:0)
Block(-2,-26,6,SMOOTH_BRICK:2)
Block(-2,-26,7,COBBLESTONE:0)
Block(-2,-26,8,STAINED_CLAY:9)
Block(-2,-25,3,SMOOTH_BRICK:1)
Block(-2,-25,4,STONE:5)
Block(-2,-25,5,SMOOTH_BRICK:0)
Block(-2,-25,6,SMOOTH_BRICK:2)
Block(-2,-25,7,COBBLESTONE:0)
Block(-2,-25,8,STAINED_CLAY:9)
Block(-2,-24,3,SMOOTH_BRICK:1)
Block(-2,-24,4,STONE:5)
Block(-2,-24,5,SMOOTH_BRICK:0)
Block(-2,-24,6,SMOOTH_BRICK:2)
Block(-2,-24,7,COBBLESTONE:0)
Block(-2,-24,8,STAINED_CLAY:9)
Block(-2,-23,3,SMOOTH_BRICK:1)
Block(-2,-23,4,STONE:5)
Block(-2,-23,5,SMOOTH_BRICK:0)
Block(-2,-23,6,SMOOTH_BRICK:2)
Block(-2,-23,7,COBBLESTONE:0)
Block(-2,-23,8,STAINED_CLAY:9)
Block(-2,-22,3,SMOOTH_BRICK:1)
Block(-2,-22,4,STONE:5)
Block(-2,-22,5,SMOOTH_BRICK:0)
Block(-2,-22,6,SMOOTH_BRICK:2)
Block(-2,-22,7,COBBLESTONE:0)
Block(-2,-22,8,STAINED_CLAY:9)
Block(-2,-21,3,SMOOTH_BRICK:1)
Block(-2,-21,4,STONE:5)
Block(-2,-21,5,SMOOTH_BRICK:0)
Block(-2,-21,6,SMOOTH_BRICK:2)
Block(-2,-21,7,COBBLESTONE:0)
Block(-2,-21,8,STAINED_CLAY:9)
Block(-2,-20,3,SMOOTH_BRICK:1)
Block(-2,-20,4,STONE:5)
Block(-2,-20,5,SMOOTH_BRICK:0)
Block(-2,-20,6,SMOOTH_BRICK:2)
Block(-2,-20,7,COBBLESTONE:0)
Block(-2,-20,8,STAINED_CLAY:9)
Block(-2,-19,3,STONE:5)
Block(-2,-19,4,STONE:5)
Block(-2,-19,5,COBBLESTONE:0)
Block(-2,-19,6,STONE:5)
Block(-2,-19,7,COBBLESTONE:0)
Block(-2,-19,8,SMOOTH_BRICK:1)
Block(-2,-18,3,STONE:5)
Block(-2,-18,4,COBBLESTONE:0)
Block(-2,-18,5,COBBLESTONE:0)
Block(-2,-18,6,COBBLESTONE:0)
Block(-2,-18,7,STONE:5)
Block(-2,-18,8,STONE:5)
Block(-2,-17,3,COBBLESTONE:0)
Block(-2,-17,4,STONE:5)
Block(-2,-17,5,COBBLESTONE:0)
Block(-2,-17,6,STONE:5)
Block(-2,-17,7,COBBLESTONE:0)
Block(-2,-17,8,STONE:5)
Block(-2,-16,3,COBBLESTONE:0)
Block(-2,-16,4,COBBLESTONE:0)
Block(-2,-16,5,SMOOTH_BRICK:0)
Block(-2,-16,6,SMOOTH_BRICK:1)
Block(-2,-16,7,COBBLESTONE:0)
Block(-2,-16,8,STONE:5)
Block(-2,-15,3,STONE:5)
Block(-2,-15,4,STONE:5)
Block(-2,-15,5,SMOOTH_BRICK:2)
Block(-2,-15,6,STONE:5)
Block(-2,-15,7,COBBLESTONE:0)
Block(-2,-15,8,STONE:5)
Block(-2,-14,3,SMOOTH_BRICK:1)
Block(-2,-14,4,COBBLESTONE:0)
Block(-2,-14,5,COBBLESTONE:0)
Block(-2,-14,6,STONE:5)
Block(-2,-14,7,COBBLESTONE:0)
Block(-2,-14,8,STONE:5)
Block(-2,-13,3,COBBLESTONE:0)
Block(-2,-13,4,COBBLESTONE:0)
Block(-2,-13,5,COBBLESTONE:0)
Block(-2,-13,6,COBBLESTONE:0)
Block(-2,-13,7,COBBLESTONE:0)
Block(-2,-13,8,COBBLESTONE:0)
Block(-2,-12,3,COBBLESTONE:0)
Block(-2,-12,4,SMOOTH_BRICK:0)
Block(-2,-12,5,COBBLESTONE:0)
Block(-2,-12,6,STONE:5)
Block(-2,-12,7,COBBLESTONE:0)
Block(-2,-12,8,STONE:5)
Block(-2,-11,3,SMOOTH_BRICK:2)
Block(-2,-11,4,STONE:5)
Block(-2,-11,5,COBBLESTONE:0)
Block(-2,-11,6,STONE:5)
Block(-2,-11,7,STONE:5)
Block(-2,-11,8,STONE:5)
Block(-2,-10,3,STONE:5)
Block(-2,-10,4,STONE:5)
Block(-2,-10,5,STONE:5)
Block(-2,-10,6,STONE:5)
Block(-2,-10,7,COBBLESTONE:0)
Block(-2,-10,8,STONE:5)
Block(-2,-9,3,COBBLESTONE_STAIRS:2)
Block(-2,-9,4,STONE:6)
Block(-2,-9,5,STONE:6)
Block(-2,-9,6,STONE:6)
Block(-2,-9,7,STONE:6)
Block(-2,-9,8,STONE:6)
Block(-2,-8,4,STONE:6)
Block(-2,-8,5,STONE:6)
Block(-2,-8,6,STONE:6)
Block(-2,-8,7,STONE:6)
Block(-2,-8,8,STONE:6)
Block(-2,-7,4,STONE:6)
Block(-2,-7,5,STONE:6)
Block(-2,-7,6,STONE:6)
Block(-2,-7,7,STONE:6)
Block(-2,-7,8,STONE:6)
Block(-2,-6,4,STONE:6)
Block(-2,-6,5,STONE:6)
Block(-2,-6,6,STONE:6)
Block(-2,-6,7,STONE:6)
Block(-2,-6,8,STONE:6)
Block(-2,-5,4,COBBLESTONE_STAIRS:2)
Block(-2,-5,5,STONE:5)
Block(-2,-5,6,STAINED_CLAY:9)
Block(-2,-5,7,SMOOTH_BRICK:0)
Block(-2,-5,8,SMOOTH_BRICK:0)
Block(-2,-4,5,STONE:6)
Block(-2,-4,6,STONE:6)
Block(-2,-4,7,STONE:6)
Block(-2,-4,8,STONE:6)
Block(-2,-3,5,STONE:6)
Block(-2,-3,6,STONE:6)
Block(-2,-3,7,STONE:6)
Block(-2,-3,8,STONE:6)
Block(-2,-2,5,STONE:6)
Block(-2,-2,6,STONE:6)
Block(-2,-2,7,STONE:6)
Block(-2,-2,8,STONE:6)
Block(-2,-1,5,COBBLESTONE_STAIRS:2)
Block(-2,-1,6,COBBLESTONE_STAIRS:1)
Block(-2,-1,7,STONE:6)
Block(-2,-1,8,STONE:6)
Block(-2,0,7,STONE:6)
Block(-2,0,8,STONE:6)
Block(-2,1,7,STONE:6)
Block(-2,1,8,STONE:6)
Block(-2,2,7,STONE:6)
Block(-2,2,8,STONE:6)
Block(-2,3,7,STONE:6)
Block(-2,3,8,STONE:6)
Block(-2,4,7,STONE:6)
Block(-2,4,8,STONE:6)
Block(-2,5,7,STONE:6)
Block(-2,5,8,STONE:6)
Block(-2,6,7,DARK_OAK_FENCE:0)
Block(-2,6,8,COBBLESTONE_STAIRS:1)
Block(-2,7,7,AIR:0)
Block(-2,7,8,COBBLESTONE_STAIRS:6)
Block(-2,8,7,AIR:0)
Block(-2,8,8,SMOOTH_BRICK:0)
Block(-2,9,7,COBBLESTONE_STAIRS:6)
Block(-2,9,8,SMOOTH_BRICK:0)
Block(-2,10,7,SMOOTH_STAIRS:1)
Block(-2,10,8,AIR:0)
Block(-2,11,7,AIR:0)
Block(-2,11,8,AIR:0)
Block(-2,12,7,AIR:0)
Block(-2,12,8,AIR:0)
Block(-2,13,7,AIR:0)
Block(-2,13,8,AIR:0)
Block(-2,14,7,AIR:0)
Block(-2,14,8,AIR:0)
Block(-2,15,7,AIR:0)
Block(-2,15,8,AIR:0)
Block(-2,16,7,AIR:0)
Block(-2,16,8,STEP:11)
Block(-2,17,7,AIR:0)
Block(-2,17,8,STEP:3)
Block(-2,18,7,AIR:0)
Block(-2,18,8,WOOD_STEP:5)
Block(-2,19,7,AIR:0)
Block(-2,19,8,AIR:0)
Block(-2,20,7,AIR:0)
Block(-2,20,8,AIR:0)
Block(-2,21,7,AIR:0)
Block(-2,21,8,AIR:0)
Block(-2,22,7,AIR:0)
Block(-2,22,8,AIR:0)
Block(-2,23,7,AIR:0)
Block(-2,23,8,AIR:0)
Block(-2,24,7,AIR:0)
Block(-2,24,8,AIR:0)
Block(-2,25,7,AIR:0)
Block(-2,25,8,AIR:0)
Block(-2,26,7,AIR:0)
Block(-2,26,8,AIR:0)
Block(-2,27,7,AIR:0)
Block(-2,27,8,AIR:0)
Block(-2,28,7,AIR:0)
Block(-2,28,8,AIR:0)
Block(-2,29,7,AIR:0)
Block(-2,29,8,AIR:0)
Block(-2,30,7,AIR:0)
Block(-2,30,8,AIR:0)
Block(-2,31,7,AIR:0)
Block(-2,31,8,AIR:0)
Block(-2,32,7,AIR:0)
Block(-2,32,8,AIR:0)
Block(-2,33,7,AIR:0)
Block(-2,33,8,AIR:0)
Block(-2,34,7,AIR:0)
Block(-2,34,8,AIR:0)
Block(-2,35,7,AIR:0)
Block(-2,35,8,AIR:0)
Block(-2,36,7,AIR:0)
Block(-2,36,8,AIR:0)
Block(-2,37,7,AIR:0)
Block(-2,37,8,AIR:0)
Block(-2,38,7,AIR:0)
Block(-2,38,8,AIR:0)
Block(-2,39,7,AIR:0)
Block(-2,39,8,AIR:0)
Block(-2,40,7,AIR:0)
Block(-2,40,8,AIR:0)
Block(-2,41,7,AIR:0)
Block(-2,41,8,AIR:0)
Block(-2,42,7,AIR:0)
Block(-2,42,8,AIR:0)
Block(-2,43,7,AIR:0)
Block(-2,43,8,AIR:0)
Block(-2,44,7,AIR:0)
Block(-2,44,8,AIR:0)
Block(-2,45,7,AIR:0)
Block(-2,45,8,AIR:0)
Block(-2,46,7,AIR:0)
Block(-2,46,8,AIR:0)
Block(-1,-50,3,SMOOTH_BRICK:2)
Block(-1,-50,4,STONE:5)
Block(-1,-50,5,COBBLESTONE:0)
Block(-1,-50,6,COBBLESTONE:0)
Block(-1,-50,7,STONE:5)
Block(-1,-50,8,STONE:5)
Block(-1,-49,3,SMOOTH_BRICK:2)
Block(-1,-49,4,STONE:5)
Block(-1,-49,5,COBBLESTONE:0)
Block(-1,-49,6,COBBLESTONE:0)
Block(-1,-49,7,STONE:5)
Block(-1,-49,8,STONE:5)
Block(-1,-48,3,SMOOTH_BRICK:2)
Block(-1,-48,4,STONE:5)
Block(-1,-48,5,COBBLESTONE:0)
Block(-1,-48,6,COBBLESTONE:0)
Block(-1,-48,7,STONE:5)
Block(-1,-48,8,STONE:5)
Block(-1,-47,3,SMOOTH_BRICK:2)
Block(-1,-47,4,STONE:5)
Block(-1,-47,5,COBBLESTONE:0)
Block(-1,-47,6,COBBLESTONE:0)
Block(-1,-47,7,STONE:5)
Block(-1,-47,8,STONE:5)
Block(-1,-46,3,SMOOTH_BRICK:2)
Block(-1,-46,4,STONE:5)
Block(-1,-46,5,COBBLESTONE:0)
Block(-1,-46,6,COBBLESTONE:0)
Block(-1,-46,7,STONE:5)
Block(-1,-46,8,STONE:5)
Block(-1,-45,3,SMOOTH_BRICK:2)
Block(-1,-45,4,STONE:5)
Block(-1,-45,5,COBBLESTONE:0)
Block(-1,-45,6,COBBLESTONE:0)
Block(-1,-45,7,STONE:5)
Block(-1,-45,8,STONE:5)
Block(-1,-44,3,SMOOTH_BRICK:2)
Block(-1,-44,4,STONE:5)
Block(-1,-44,5,COBBLESTONE:0)
Block(-1,-44,6,COBBLESTONE:0)
Block(-1,-44,7,STONE:5)
Block(-1,-44,8,STONE:5)
Block(-1,-43,3,SMOOTH_BRICK:2)
Block(-1,-43,4,STONE:5)
Block(-1,-43,5,COBBLESTONE:0)
Block(-1,-43,6,COBBLESTONE:0)
Block(-1,-43,7,STONE:5)
Block(-1,-43,8,STONE:5)
Block(-1,-42,3,SMOOTH_BRICK:2)
Block(-1,-42,4,STONE:5)
Block(-1,-42,5,COBBLESTONE:0)
Block(-1,-42,6,COBBLESTONE:0)
Block(-1,-42,7,STONE:5)
Block(-1,-42,8,STONE:5)
Block(-1,-41,3,SMOOTH_BRICK:2)
Block(-1,-41,4,STONE:5)
Block(-1,-41,5,COBBLESTONE:0)
Block(-1,-41,6,COBBLESTONE:0)
Block(-1,-41,7,STONE:5)
Block(-1,-41,8,STONE:5)
Block(-1,-40,3,SMOOTH_BRICK:2)
Block(-1,-40,4,STONE:5)
Block(-1,-40,5,COBBLESTONE:0)
Block(-1,-40,6,COBBLESTONE:0)
Block(-1,-40,7,STONE:5)
Block(-1,-40,8,STONE:5)
Block(-1,-39,3,SMOOTH_BRICK:2)
Block(-1,-39,4,STONE:5)
Block(-1,-39,5,COBBLESTONE:0)
Block(-1,-39,6,COBBLESTONE:0)
Block(-1,-39,7,STONE:5)
Block(-1,-39,8,STONE:5)
Block(-1,-38,3,SMOOTH_BRICK:2)
Block(-1,-38,4,STONE:5)
Block(-1,-38,5,COBBLESTONE:0)
Block(-1,-38,6,COBBLESTONE:0)
Block(-1,-38,7,STONE:5)
Block(-1,-38,8,STONE:5)
Block(-1,-37,3,SMOOTH_BRICK:2)
Block(-1,-37,4,STONE:5)
Block(-1,-37,5,COBBLESTONE:0)
Block(-1,-37,6,COBBLESTONE:0)
Block(-1,-37,7,STONE:5)
Block(-1,-37,8,STONE:5)
Block(-1,-36,3,SMOOTH_BRICK:2)
Block(-1,-36,4,STONE:5)
Block(-1,-36,5,COBBLESTONE:0)
Block(-1,-36,6,COBBLESTONE:0)
Block(-1,-36,7,STONE:5)
Block(-1,-36,8,STONE:5)
Block(-1,-35,3,SMOOTH_BRICK:2)
Block(-1,-35,4,STONE:5)
Block(-1,-35,5,COBBLESTONE:0)
Block(-1,-35,6,COBBLESTONE:0)
Block(-1,-35,7,STONE:5)
Block(-1,-35,8,STONE:5)
Block(-1,-34,3,SMOOTH_BRICK:2)
Block(-1,-34,4,STONE:5)
Block(-1,-34,5,COBBLESTONE:0)
Block(-1,-34,6,COBBLESTONE:0)
Block(-1,-34,7,STONE:5)
Block(-1,-34,8,STONE:5)
Block(-1,-33,3,SMOOTH_BRICK:2)
Block(-1,-33,4,STONE:5)
Block(-1,-33,5,COBBLESTONE:0)
Block(-1,-33,6,COBBLESTONE:0)
Block(-1,-33,7,STONE:5)
Block(-1,-33,8,STONE:5)
Block(-1,-32,3,SMOOTH_BRICK:2)
Block(-1,-32,4,STONE:5)
Block(-1,-32,5,COBBLESTONE:0)
Block(-1,-32,6,COBBLESTONE:0)
Block(-1,-32,7,STONE:5)
Block(-1,-32,8,STONE:5)
Block(-1,-31,3,SMOOTH_BRICK:2)
Block(-1,-31,4,STONE:5)
Block(-1,-31,5,COBBLESTONE:0)
Block(-1,-31,6,COBBLESTONE:0)
Block(-1,-31,7,STONE:5)
Block(-1,-31,8,STONE:5)
Block(-1,-30,3,SMOOTH_BRICK:2)
Block(-1,-30,4,STONE:5)
Block(-1,-30,5,COBBLESTONE:0)
Block(-1,-30,6,COBBLESTONE:0)
Block(-1,-30,7,STONE:5)
Block(-1,-30,8,STONE:5)
Block(-1,-29,3,SMOOTH_BRICK:2)
Block(-1,-29,4,STONE:5)
Block(-1,-29,5,COBBLESTONE:0)
Block(-1,-29,6,COBBLESTONE:0)
Block(-1,-29,7,STONE:5)
Block(-1,-29,8,STONE:5)
Block(-1,-28,3,SMOOTH_BRICK:2)
Block(-1,-28,4,STONE:5)
Block(-1,-28,5,COBBLESTONE:0)
Block(-1,-28,6,COBBLESTONE:0)
Block(-1,-28,7,STONE:5)
Block(-1,-28,8,STONE:5)
Block(-1,-27,3,SMOOTH_BRICK:2)
Block(-1,-27,4,STONE:5)
Block(-1,-27,5,COBBLESTONE:0)
Block(-1,-27,6,COBBLESTONE:0)
Block(-1,-27,7,STONE:5)
Block(-1,-27,8,STONE:5)
Block(-1,-26,3,SMOOTH_BRICK:2)
Block(-1,-26,4,STONE:5)
Block(-1,-26,5,COBBLESTONE:0)
Block(-1,-26,6,COBBLESTONE:0)
Block(-1,-26,7,STONE:5)
Block(-1,-26,8,STONE:5)
Block(-1,-25,3,SMOOTH_BRICK:2)
Block(-1,-25,4,STONE:5)
Block(-1,-25,5,COBBLESTONE:0)
Block(-1,-25,6,COBBLESTONE:0)
Block(-1,-25,7,STONE:5)
Block(-1,-25,8,STONE:5)
Block(-1,-24,3,SMOOTH_BRICK:2)
Block(-1,-24,4,STONE:5)
Block(-1,-24,5,COBBLESTONE:0)
Block(-1,-24,6,COBBLESTONE:0)
Block(-1,-24,7,STONE:5)
Block(-1,-24,8,STONE:5)
Block(-1,-23,3,SMOOTH_BRICK:2)
Block(-1,-23,4,STONE:5)
Block(-1,-23,5,COBBLESTONE:0)
Block(-1,-23,6,COBBLESTONE:0)
Block(-1,-23,7,STONE:5)
Block(-1,-23,8,STONE:5)
Block(-1,-22,3,SMOOTH_BRICK:2)
Block(-1,-22,4,STONE:5)
Block(-1,-22,5,COBBLESTONE:0)
Block(-1,-22,6,COBBLESTONE:0)
Block(-1,-22,7,STONE:5)
Block(-1,-22,8,STONE:5)
Block(-1,-21,3,SMOOTH_BRICK:2)
Block(-1,-21,4,STONE:5)
Block(-1,-21,5,COBBLESTONE:0)
Block(-1,-21,6,COBBLESTONE:0)
Block(-1,-21,7,STONE:5)
Block(-1,-21,8,STONE:5)
Block(-1,-20,3,SMOOTH_BRICK:2)
Block(-1,-20,4,STONE:5)
Block(-1,-20,5,COBBLESTONE:0)
Block(-1,-20,6,COBBLESTONE:0)
Block(-1,-20,7,STONE:5)
Block(-1,-20,8,STONE:5)
Block(-1,-19,3,STAINED_CLAY:9)
Block(-1,-19,4,COBBLESTONE:0)
Block(-1,-19,5,STONE:5)
Block(-1,-19,6,STONE:5)
Block(-1,-19,7,STONE:5)
Block(-1,-19,8,STONE:5)
Block(-1,-18,3,COBBLESTONE:0)
Block(-1,-18,4,STAINED_CLAY:9)
Block(-1,-18,5,STAINED_CLAY:9)
Block(-1,-18,6,STONE:5)
Block(-1,-18,7,COBBLESTONE:0)
Block(-1,-18,8,STONE:5)
Block(-1,-17,3,STONE:5)
Block(-1,-17,4,COBBLESTONE:0)
Block(-1,-17,5,STONE:5)
Block(-1,-17,6,STONE:5)
Block(-1,-17,7,STONE:5)
Block(-1,-17,8,STONE:5)
Block(-1,-16,3,STONE:5)
Block(-1,-16,4,STAINED_CLAY:9)
Block(-1,-16,5,STONE:5)
Block(-1,-16,6,STONE:5)
Block(-1,-16,7,STONE:5)
Block(-1,-16,8,COBBLESTONE:0)
Block(-1,-15,3,SMOOTH_BRICK:0)
Block(-1,-15,4,COBBLESTONE:0)
Block(-1,-15,5,COBBLESTONE:0)
Block(-1,-15,6,COBBLESTONE:0)
Block(-1,-15,7,STONE:5)
Block(-1,-15,8,STAINED_CLAY:9)
Block(-1,-14,3,COBBLESTONE:0)
Block(-1,-14,4,COBBLESTONE:0)
Block(-1,-14,5,STONE:5)
Block(-1,-14,6,STONE:5)
Block(-1,-14,7,STONE:5)
Block(-1,-14,8,COBBLESTONE:0)
Block(-1,-13,3,STONE:5)
Block(-1,-13,4,STONE:5)
Block(-1,-13,5,COBBLESTONE:0)
Block(-1,-13,6,STONE:5)
Block(-1,-13,7,STONE:5)
Block(-1,-13,8,STONE:5)
Block(-1,-12,3,STONE:5)
Block(-1,-12,4,STONE:5)
Block(-1,-12,5,COBBLESTONE:0)
Block(-1,-12,6,SMOOTH_BRICK:0)
Block(-1,-12,7,STONE:5)
Block(-1,-12,8,STAINED_CLAY:9)
Block(-1,-11,3,COBBLESTONE:0)
Block(-1,-11,4,SMOOTH_BRICK:0)
Block(-1,-11,5,SMOOTH_BRICK:0)
Block(-1,-11,6,STONE:5)
Block(-1,-11,7,STAINED_CLAY:9)
Block(-1,-11,8,COBBLESTONE:0)
Block(-1,-10,3,STONE:5)
Block(-1,-10,4,STONE:5)
Block(-1,-10,5,COBBLESTONE:0)
Block(-1,-10,6,STONE:5)
Block(-1,-10,7,COBBLESTONE:0)
Block(-1,-10,8,SMOOTH_BRICK:1)
Block(-1,-9,3,COBBLESTONE_STAIRS:2)
Block(-1,-9,4,LOG:0)
Block(-1,-9,5,STONE:6)
Block(-1,-9,6,LOG:0)
Block(-1,-9,7,STONE:6)
Block(-1,-9,8,STONE:6)
Block(-1,-8,4,STONE:6)
Block(-1,-8,5,STONE:6)
Block(-1,-8,6,LOG:0)
Block(-1,-8,7,STONE:6)
Block(-1,-8,8,STONE:6)
Block(-1,-7,4,STONE:6)
Block(-1,-7,5,STONE:6)
Block(-1,-7,6,LOG:0)
Block(-1,-7,7,STONE:6)
Block(-1,-7,8,STONE:6)
Block(-1,-6,4,STONE:6)
Block(-1,-6,5,STONE:6)
Block(-1,-6,6,LOG:0)
Block(-1,-6,7,STONE:6)
Block(-1,-6,8,STONE:6)
Block(-1,-5,4,COBBLESTONE_STAIRS:2)
Block(-1,-5,5,COBBLESTONE_STAIRS:1)
Block(-1,-5,6,LOG:0)
Block(-1,-5,7,STONE:5)
Block(-1,-5,8,STONE:5)
Block(-1,-4,6,STONE:6)
Block(-1,-4,7,STONE:6)
Block(-1,-4,8,STONE:6)
Block(-1,-3,6,STONE:6)
Block(-1,-3,7,STONE:6)
Block(-1,-3,8,STONE:6)
Block(-1,-2,6,STONE:6)
Block(-1,-2,7,STONE:6)
Block(-1,-2,8,STONE:6)
Block(-1,-1,6,COBBLESTONE_STAIRS:2)
Block(-1,-1,7,STONE:6)
Block(-1,-1,8,STONE:6)
Block(-1,0,7,STONE:6)
Block(-1,0,8,STONE:6)
Block(-1,1,7,STONE:6)
Block(-1,1,8,STONE:6)
Block(-1,2,7,STONE:6)
Block(-1,2,8,STONE:6)
Block(-1,3,7,STONE:6)
Block(-1,3,8,STONE:6)
Block(-1,4,7,STONE:6)
Block(-1,4,8,STONE:6)
Block(-1,5,7,STONE:6)
Block(-1,5,8,STONE:6)
Block(-1,6,7,DARK_OAK_FENCE:0)
Block(-1,6,8,COBBLESTONE_STAIRS:0)
Block(-1,7,7,AIR:0)
Block(-1,7,8,COBBLESTONE_STAIRS:6)
Block(-1,8,7,AIR:0)
Block(-1,8,8,SMOOTH_BRICK:0)
Block(-1,9,7,COBBLESTONE_STAIRS:6)
Block(-1,9,8,SMOOTH_BRICK:0)
Block(-1,10,7,SMOOTH_STAIRS:0)
Block(-1,10,8,AIR:0)
Block(-1,11,7,AIR:0)
Block(-1,11,8,AIR:0)
Block(-1,12,7,AIR:0)
Block(-1,12,8,AIR:0)
Block(-1,13,7,AIR:0)
Block(-1,13,8,AIR:0)
Block(-1,14,7,AIR:0)
Block(-1,14,8,AIR:0)
Block(-1,15,7,AIR:0)
Block(-1,15,8,AIR:0)
Block(-1,16,7,AIR:0)
Block(-1,16,8,AIR:0)
Block(-1,17,7,AIR:0)
Block(-1,17,8,AIR:0)
Block(-1,18,7,AIR:0)
Block(-1,18,8,AIR:0)
Block(-1,19,7,AIR:0)
Block(-1,19,8,AIR:0)
Block(-1,20,7,AIR:0)
Block(-1,20,8,AIR:0)
Block(-1,21,7,AIR:0)
Block(-1,21,8,AIR:0)
Block(-1,22,7,AIR:0)
Block(-1,22,8,AIR:0)
Block(-1,23,7,AIR:0)
Block(-1,23,8,AIR:0)
Block(-1,24,7,AIR:0)
Block(-1,24,8,AIR:0)
Block(-1,25,7,AIR:0)
Block(-1,25,8,AIR:0)
Block(-1,26,7,AIR:0)
Block(-1,26,8,AIR:0)
Block(-1,27,7,AIR:0)
Block(-1,27,8,AIR:0)
Block(-1,28,7,AIR:0)
Block(-1,28,8,AIR:0)
Block(-1,29,7,AIR:0)
Block(-1,29,8,AIR:0)
Block(-1,30,7,AIR:0)
Block(-1,30,8,AIR:0)
Block(-1,31,7,AIR:0)
Block(-1,31,8,AIR:0)
Block(-1,32,7,AIR:0)
Block(-1,32,8,AIR:0)
Block(-1,33,7,AIR:0)
Block(-1,33,8,AIR:0)
Block(-1,34,7,AIR:0)
Block(-1,34,8,AIR:0)
Block(-1,35,7,AIR:0)
Block(-1,35,8,AIR:0)
Block(-1,36,7,AIR:0)
Block(-1,36,8,AIR:0)
Block(-1,37,7,AIR:0)
Block(-1,37,8,AIR:0)
Block(-1,38,7,AIR:0)
Block(-1,38,8,AIR:0)
Block(-1,39,7,AIR:0)
Block(-1,39,8,AIR:0)
Block(-1,40,7,AIR:0)
Block(-1,40,8,AIR:0)
Block(-1,41,7,AIR:0)
Block(-1,41,8,AIR:0)
Block(-1,42,7,AIR:0)
Block(-1,42,8,AIR:0)
Block(-1,43,7,AIR:0)
Block(-1,43,8,AIR:0)
Block(-1,44,7,AIR:0)
Block(-1,44,8,AIR:0)
Block(-1,45,7,AIR:0)
Block(-1,45,8,AIR:0)
Block(-1,46,7,AIR:0)
Block(-1,46,8,AIR:0)
Block(0,-50,3,LOG:0)
Block(0,-50,4,STONE:5)
Block(0,-50,5,SMOOTH_BRICK:2)
Block(0,-50,6,LOG:0)
Block(0,-50,7,STONE:5)
Block(0,-50,8,STAINED_CLAY:9)
Block(0,-49,3,LOG:0)
Block(0,-49,4,STONE:5)
Block(0,-49,5,SMOOTH_BRICK:2)
Block(0,-49,6,LOG:0)
Block(0,-49,7,STONE:5)
Block(0,-49,8,STAINED_CLAY:9)
Block(0,-48,3,LOG:0)
Block(0,-48,4,STONE:5)
Block(0,-48,5,SMOOTH_BRICK:2)
Block(0,-48,6,LOG:0)
Block(0,-48,7,STONE:5)
Block(0,-48,8,STAINED_CLAY:9)
Block(0,-47,3,LOG:0)
Block(0,-47,4,STONE:5)
Block(0,-47,5,SMOOTH_BRICK:2)
Block(0,-47,6,LOG:0)
Block(0,-47,7,STONE:5)
Block(0,-47,8,STAINED_CLAY:9)
Block(0,-46,3,LOG:0)
Block(0,-46,4,STONE:5)
Block(0,-46,5,SMOOTH_BRICK:2)
Block(0,-46,6,LOG:0)
Block(0,-46,7,STONE:5)
Block(0,-46,8,STAINED_CLAY:9)
Block(0,-45,3,LOG:0)
Block(0,-45,4,STONE:5)
Block(0,-45,5,SMOOTH_BRICK:2)
Block(0,-45,6,LOG:0)
Block(0,-45,7,STONE:5)
Block(0,-45,8,STAINED_CLAY:9)
Block(0,-44,3,LOG:0)
Block(0,-44,4,STONE:5)
Block(0,-44,5,SMOOTH_BRICK:2)
Block(0,-44,6,LOG:0)
Block(0,-44,7,STONE:5)
Block(0,-44,8,STAINED_CLAY:9)
Block(0,-43,3,LOG:0)
Block(0,-43,4,STONE:5)
Block(0,-43,5,SMOOTH_BRICK:2)
Block(0,-43,6,LOG:0)
Block(0,-43,7,STONE:5)
Block(0,-43,8,STAINED_CLAY:9)
Block(0,-42,3,LOG:0)
Block(0,-42,4,STONE:5)
Block(0,-42,5,SMOOTH_BRICK:2)
Block(0,-42,6,LOG:0)
Block(0,-42,7,STONE:5)
Block(0,-42,8,STAINED_CLAY:9)
Block(0,-41,3,LOG:0)
Block(0,-41,4,STONE:5)
Block(0,-41,5,SMOOTH_BRICK:2)
Block(0,-41,6,LOG:0)
Block(0,-41,7,STONE:5)
Block(0,-41,8,STAINED_CLAY:9)
Block(0,-40,3,LOG:0)
Block(0,-40,4,STONE:5)
Block(0,-40,5,SMOOTH_BRICK:2)
Block(0,-40,6,LOG:0)
Block(0,-40,7,STONE:5)
Block(0,-40,8,STAINED_CLAY:9)
Block(0,-39,3,LOG:0)
Block(0,-39,4,STONE:5)
Block(0,-39,5,SMOOTH_BRICK:2)
Block(0,-39,6,LOG:0)
Block(0,-39,7,STONE:5)
Block(0,-39,8,STAINED_CLAY:9)
Block(0,-38,3,LOG:0)
Block(0,-38,4,STONE:5)
Block(0,-38,5,SMOOTH_BRICK:2)
Block(0,-38,6,LOG:0)
Block(0,-38,7,STONE:5)
Block(0,-38,8,STAINED_CLAY:9)
Block(0,-37,3,LOG:0)
Block(0,-37,4,STONE:5)
Block(0,-37,5,SMOOTH_BRICK:2)
Block(0,-37,6,LOG:0)
Block(0,-37,7,STONE:5)
Block(0,-37,8,STAINED_CLAY:9)
Block(0,-36,3,LOG:0)
Block(0,-36,4,STONE:5)
Block(0,-36,5,SMOOTH_BRICK:2)
Block(0,-36,6,LOG:0)
Block(0,-36,7,STONE:5)
Block(0,-36,8,STAINED_CLAY:9)
Block(0,-35,3,LOG:0)
Block(0,-35,4,STONE:5)
Block(0,-35,5,SMOOTH_BRICK:2)
Block(0,-35,6,LOG:0)
Block(0,-35,7,STONE:5)
Block(0,-35,8,STAINED_CLAY:9)
Block(0,-34,3,LOG:0)
Block(0,-34,4,STONE:5)
Block(0,-34,5,SMOOTH_BRICK:2)
Block(0,-34,6,LOG:0)
Block(0,-34,7,STONE:5)
Block(0,-34,8,STAINED_CLAY:9)
Block(0,-33,3,LOG:0)
Block(0,-33,4,STONE:5)
Block(0,-33,5,SMOOTH_BRICK:2)
Block(0,-33,6,LOG:0)
Block(0,-33,7,STONE:5)
Block(0,-33,8,STAINED_CLAY:9)
Block(0,-32,3,LOG:0)
Block(0,-32,4,STONE:5)
Block(0,-32,5,SMOOTH_BRICK:2)
Block(0,-32,6,LOG:0)
Block(0,-32,7,STONE:5)
Block(0,-32,8,STAINED_CLAY:9)
Block(0,-31,3,LOG:0)
Block(0,-31,4,STONE:5)
Block(0,-31,5,SMOOTH_BRICK:2)
Block(0,-31,6,LOG:0)
Block(0,-31,7,STONE:5)
Block(0,-31,8,STAINED_CLAY:9)
Block(0,-30,3,LOG:0)
Block(0,-30,4,STONE:5)
Block(0,-30,5,SMOOTH_BRICK:2)
Block(0,-30,6,LOG:0)
Block(0,-30,7,STONE:5)
Block(0,-30,8,STAINED_CLAY:9)
Block(0,-29,3,LOG:0)
Block(0,-29,4,STONE:5)
Block(0,-29,5,SMOOTH_BRICK:2)
Block(0,-29,6,LOG:0)
Block(0,-29,7,STONE:5)
Block(0,-29,8,STAINED_CLAY:9)
Block(0,-28,3,LOG:0)
Block(0,-28,4,STONE:5)
Block(0,-28,5,SMOOTH_BRICK:2)
Block(0,-28,6,LOG:0)
Block(0,-28,7,STONE:5)
Block(0,-28,8,STAINED_CLAY:9)
Block(0,-27,3,LOG:0)
Block(0,-27,4,STONE:5)
Block(0,-27,5,SMOOTH_BRICK:2)
Block(0,-27,6,LOG:0)
Block(0,-27,7,STONE:5)
Block(0,-27,8,STAINED_CLAY:9)
Block(0,-26,3,LOG:0)
Block(0,-26,4,STONE:5)
Block(0,-26,5,SMOOTH_BRICK:2)
Block(0,-26,6,LOG:0)
Block(0,-26,7,STONE:5)
Block(0,-26,8,STAINED_CLAY:9)
Block(0,-25,3,LOG:0)
Block(0,-25,4,STONE:5)
Block(0,-25,5,SMOOTH_BRICK:2)
Block(0,-25,6,LOG:0)
Block(0,-25,7,STONE:5)
Block(0,-25,8,STAINED_CLAY:9)
Block(0,-24,3,LOG:0)
Block(0,-24,4,STONE:5)
Block(0,-24,5,SMOOTH_BRICK:2)
Block(0,-24,6,LOG:0)
Block(0,-24,7,STONE:5)
Block(0,-24,8,STAINED_CLAY:9)
Block(0,-23,3,LOG:0)
Block(0,-23,4,STONE:5)
Block(0,-23,5,SMOOTH_BRICK:2)
Block(0,-23,6,LOG:0)
Block(0,-23,7,STONE:5)
Block(0,-23,8,STAINED_CLAY:9)
Block(0,-22,3,LOG:0)
Block(0,-22,4,STONE:5)
Block(0,-22,5,SMOOTH_BRICK:2)
Block(0,-22,6,LOG:0)
Block(0,-22,7,STONE:5)
Block(0,-22,8,STAINED_CLAY:9)
Block(0,-21,3,LOG:0)
Block(0,-21,4,STONE:5)
Block(0,-21,5,SMOOTH_BRICK:2)
Block(0,-21,6,LOG:0)
Block(0,-21,7,STONE:5)
Block(0,-21,8,STAINED_CLAY:9)
Block(0,-20,3,LOG:0)
Block(0,-20,4,STONE:5)
Block(0,-20,5,SMOOTH_BRICK:2)
Block(0,-20,6,LOG:0)
Block(0,-20,7,STONE:5)
Block(0,-20,8,STAINED_CLAY:9)
Block(0,-19,3,LOG:0)
Block(0,-19,4,STONE:5)
Block(0,-19,5,SMOOTH_BRICK:2)
Block(0,-19,6,LOG:0)
Block(0,-19,7,STONE:5)
Block(0,-19,8,SMOOTH_BRICK:1)
Block(0,-18,3,LOG:0)
Block(0,-18,4,COBBLESTONE:0)
Block(0,-18,5,STONE:5)
Block(0,-18,6,LOG:0)
Block(0,-18,7,STONE:5)
Block(0,-18,8,STONE:5)
Block(0,-17,3,LOG:0)
Block(0,-17,4,SMOOTH_BRICK:2)
Block(0,-17,5,STONE:5)
Block(0,-17,6,LOG:0)
Block(0,-17,7,STONE:5)
Block(0,-17,8,STONE:5)
Block(0,-16,3,LOG:0)
Block(0,-16,4,STONE:5)
Block(0,-16,5,COBBLESTONE:0)
Block(0,-16,6,LOG:0)
Block(0,-16,7,STONE:5)
Block(0,-16,8,STONE:5)
Block(0,-15,3,LOG:0)
Block(0,-15,4,SMOOTH_BRICK:0)
Block(0,-15,5,COBBLESTONE:0)
Block(0,-15,6,LOG:0)
Block(0,-15,7,COBBLESTONE:0)
Block(0,-15,8,STONE:5)
Block(0,-14,3,LOG:0)
Block(0,-14,4,COBBLESTONE:0)
Block(0,-14,5,COBBLESTONE:0)
Block(0,-14,6,LOG:0)
Block(0,-14,7,STONE:5)
Block(0,-14,8,COBBLESTONE:0)
Block(0,-13,3,LOG:0)
Block(0,-13,4,STAINED_CLAY:9)
Block(0,-13,5,COBBLESTONE:0)
Block(0,-13,6,LOG:0)
Block(0,-13,7,COBBLESTONE:0)
Block(0,-13,8,SMOOTH_BRICK:2)
Block(0,-12,3,LOG:0)
Block(0,-12,4,STONE:5)
Block(0,-12,5,COBBLESTONE:0)
Block(0,-12,6,LOG:0)
Block(0,-12,7,COBBLESTONE:0)
Block(0,-12,8,STONE:5)
Block(0,-11,3,LOG:0)
Block(0,-11,4,STONE:5)
Block(0,-11,5,SMOOTH_BRICK:2)
Block(0,-11,6,LOG:0)
Block(0,-11,7,SMOOTH_BRICK:0)
Block(0,-11,8,STONE:5)
Block(0,-10,3,LOG:0)
Block(0,-10,4,COBBLESTONE:0)
Block(0,-10,5,STONE:5)
Block(0,-10,6,LOG:0)
Block(0,-10,7,SMOOTH_BRICK:2)
Block(0,-10,8,STONE:5)
Block(0,-9,3,SMOOTH_STAIRS:1)
Block(0,-9,4,COBBLESTONE_STAIRS:2)
Block(0,-9,5,STONE:6)
Block(0,-9,6,STONE:6)
Block(0,-9,7,STONE:6)
Block(0,-9,8,STONE:6)
Block(0,-8,5,STONE:6)
Block(0,-8,6,STONE:6)
Block(0,-8,7,STONE:6)
Block(0,-8,8,STONE:6)
Block(0,-7,5,STONE:6)
Block(0,-7,6,STONE:6)
Block(0,-7,7,STONE:6)
Block(0,-7,8,STONE:6)
Block(0,-6,5,STONE:6)
Block(0,-6,6,STONE:6)
Block(0,-6,7,STONE:6)
Block(0,-6,8,STONE:6)
Block(0,-5,5,COBBLESTONE_STAIRS:2)
Block(0,-5,6,COBBLESTONE_STAIRS:1)
Block(0,-5,7,STONE:5)
Block(0,-5,8,STAINED_CLAY:9)
Block(0,-4,7,LOG:0)
Block(0,-4,8,STONE:6)
Block(0,-3,7,LOG:0)
Block(0,-3,8,STONE:6)
Block(0,-2,7,LOG:0)
Block(0,-2,8,STONE:6)
Block(0,-1,7,LOG:0)
Block(0,-1,8,STONE:6)
Block(0,0,7,LOG:0)
Block(0,0,8,STONE:6)
Block(0,1,7,LOG:0)
Block(0,1,8,STONE:6)
Block(0,2,7,LOG:0)
Block(0,2,8,STONE:6)
Block(0,3,7,LOG:0)
Block(0,3,8,STONE:6)
Block(0,4,7,LOG:0)
Block(0,4,8,STONE:6)
Block(0,5,7,LOG:0)
Block(0,5,8,STONE:6)
Block(0,6,7,LOG:0)
Block(0,6,8,DARK_OAK_FENCE:0)
Block(0,7,7,LOG:0)
Block(0,7,8,COBBLESTONE_STAIRS:5)
Block(0,8,7,LOG:0)
Block(0,8,8,SMOOTH_BRICK:0)
Block(0,9,7,LOG:0)
Block(0,9,8,SMOOTH_BRICK:0)
Block(0,10,6,STEP:13)
Block(0,10,7,LOG:0)
Block(0,10,8,AIR:0)
Block(0,11,6,STEP:5)
Block(0,11,7,STEP:5)
Block(0,11,8,AIR:0)
Block(0,12,7,AIR:0)
Block(0,12,8,AIR:0)
Block(0,13,7,AIR:0)
Block(0,13,8,AIR:0)
Block(0,14,7,AIR:0)
Block(0,14,8,AIR:0)
Block(0,15,7,AIR:0)
Block(0,15,8,AIR:0)
Block(0,16,7,AIR:0)
Block(0,16,8,AIR:0)
Block(0,17,7,AIR:0)
Block(0,17,8,AIR:0)
Block(0,18,7,AIR:0)
Block(0,18,8,AIR:0)
Block(0,19,7,AIR:0)
Block(0,19,8,AIR:0)
Block(0,20,7,AIR:0)
Block(0,20,8,AIR:0)
Block(0,21,7,AIR:0)
Block(0,21,8,AIR:0)
Block(0,22,7,AIR:0)
Block(0,22,8,AIR:0)
Block(0,23,7,AIR:0)
Block(0,23,8,AIR:0)
Block(0,24,7,AIR:0)
Block(0,24,8,AIR:0)
Block(0,25,7,AIR:0)
Block(0,25,8,AIR:0)
Block(0,26,7,AIR:0)
Block(0,26,8,AIR:0)
Block(0,27,7,AIR:0)
Block(0,27,8,AIR:0)
Block(0,28,7,AIR:0)
Block(0,28,8,AIR:0)
Block(0,29,7,AIR:0)
Block(0,29,8,AIR:0)
Block(0,30,7,AIR:0)
Block(0,30,8,AIR:0)
Block(0,31,7,AIR:0)
Block(0,31,8,AIR:0)
Block(0,32,7,AIR:0)
Block(0,32,8,AIR:0)
Block(0,33,7,AIR:0)
Block(0,33,8,AIR:0)
Block(0,34,7,AIR:0)
Block(0,34,8,AIR:0)
Block(0,35,7,AIR:0)
Block(0,35,8,AIR:0)
Block(0,36,7,AIR:0)
Block(0,36,8,AIR:0)
Block(0,37,7,AIR:0)
Block(0,37,8,AIR:0)
Block(0,38,7,AIR:0)
Block(0,38,8,AIR:0)
Block(0,39,7,AIR:0)
Block(0,39,8,AIR:0)
Block(0,40,7,AIR:0)
Block(0,40,8,AIR:0)
Block(0,41,7,AIR:0)
Block(0,41,8,AIR:0)
Block(0,42,7,AIR:0)
Block(0,42,8,AIR:0)
Block(0,43,7,AIR:0)
Block(0,43,8,AIR:0)
Block(0,44,7,AIR:0)
Block(0,44,8,AIR:0)
Block(0,45,7,AIR:0)
Block(0,45,8,AIR:0)
Block(0,46,7,AIR:0)
Block(0,46,8,AIR:0)
Block(1,-50,4,COBBLESTONE:0)
Block(1,-50,5,COBBLESTONE:0)
Block(1,-50,6,STONE:5)
Block(1,-50,7,STONE:5)
Block(1,-50,8,STONE:5)
Block(1,-49,4,COBBLESTONE:0)
Block(1,-49,5,COBBLESTONE:0)
Block(1,-49,6,STONE:5)
Block(1,-49,7,STONE:5)
Block(1,-49,8,STONE:5)
Block(1,-48,4,COBBLESTONE:0)
Block(1,-48,5,COBBLESTONE:0)
Block(1,-48,6,STONE:5)
Block(1,-48,7,STONE:5)
