Author: NLBlackEagle
Description: No description given
SettingsMode: WriteDisable
Frequency: 0
SpawnHeight: highestBlock
UseCenterForHighestBlock: true
MinHeight: 0
MaxHeight: 255
InheritBO3: 
InheritBO3Rotation: NORTH
OverrideChildSettings: true
OverrideParentHeight: false
CanOverride: true
BranchFrequency: 0
BranchFrequencyGroup: 
MustBeBelowOther: false
MustBeInside: 
CannotBeInside: 
ReplacesBO3: 
MustBeInsideWorldBorders: false
CanSpawnOnWater: true
SpawnOnWaterOnly: false
SpawnUnderWater: false
SpawnAtWaterLevel: false
HeightOffset: 0
RemoveAir: false
ReplaceAbove: 
ReplaceBelow: 
ReplaceWithBiomeBlocks: false
ReplaceWithSurfaceBlock: GRASS
ReplaceWithGroundBlock: DIRT
ReplaceWithStoneBlock: STONE
SmoothRadius: 0
SmoothHeightOffset: 0
SmoothStartTop: false
SmoothStartWood: false
SmoothingSurfaceBlock: 
SmoothingGroundBlock: 
BO3Group: 
IsSpawnPoint: false
DoReplaceBlocks: false
Block(4,-50,0,LOG:0)
Block(4,-50,1,COBBLESTONE:0)
Block(4,-50,2,STONE:5)
Block(4,-50,3,SMOOTH_BRICK:0)
Block(4,-50,4,LOG:0)
Block(4,-49,0,LOG:0)
Block(4,-49,1,COBBLESTONE:0)
Block(4,-49,2,STONE:5)
Block(4,-49,3,SMOOTH_BRICK:0)
Block(4,-49,4,LOG:0)
Block(4,-48,0,LOG:0)
Block(4,-48,1,COBBLESTONE:0)
Block(4,-48,2,STONE:5)
Block(4,-48,3,SMOOTH_BRICK:0)
Block(4,-48,4,LOG:0)
Block(4,-47,0,LOG:0)
Block(4,-47,1,COBBLESTONE:0)
Block(4,-47,2,STONE:5)
Block(4,-47,3,SMOOTH_BRICK:0)
Block(4,-47,4,LOG:0)
Block(4,-46,0,LOG:0)
Block(4,-46,1,COBBLESTONE:0)
Block(4,-46,2,STONE:5)
Block(4,-46,3,SMOOTH_BRICK:0)
Block(4,-46,4,LOG:0)
Block(4,-45,0,LOG:0)
Block(4,-45,1,COBBLESTONE:0)
Block(4,-45,2,STONE:5)
Block(4,-45,3,SMOOTH_BRICK:0)
Block(4,-45,4,LOG:0)
Block(4,-44,0,LOG:0)
Block(4,-44,1,COBBLESTONE:0)
Block(4,-44,2,STONE:5)
Block(4,-44,3,SMOOTH_BRICK:0)
Block(4,-44,4,LOG:0)
Block(4,-43,0,LOG:0)
Block(4,-43,1,COBBLESTONE:0)
Block(4,-43,2,STONE:5)
Block(4,-43,3,SMOOTH_BRICK:0)
Block(4,-43,4,LOG:0)
Block(4,-42,0,LOG:0)
Block(4,-42,1,COBBLESTONE:0)
Block(4,-42,2,STONE:5)
Block(4,-42,3,SMOOTH_BRICK:0)
Block(4,-42,4,LOG:0)
Block(4,-41,0,LOG:0)
Block(4,-41,1,COBBLESTONE:0)
Block(4,-41,2,STONE:5)
Block(4,-41,3,SMOOTH_BRICK:0)
Block(4,-41,4,LOG:0)
Block(4,-40,0,LOG:0)
Block(4,-40,1,COBBLESTONE:0)
Block(4,-40,2,STONE:5)
Block(4,-40,3,SMOOTH_BRICK:0)
Block(4,-40,4,LOG:0)
Block(4,-39,0,LOG:0)
Block(4,-39,1,COBBLESTONE:0)
Block(4,-39,2,STONE:5)
Block(4,-39,3,SMOOTH_BRICK:0)
Block(4,-39,4,LOG:0)
Block(4,-38,0,LOG:0)
Block(4,-38,1,COBBLESTONE:0)
Block(4,-38,2,STONE:5)
Block(4,-38,3,SMOOTH_BRICK:0)
Block(4,-38,4,LOG:0)
Block(4,-37,0,LOG:0)
Block(4,-37,1,COBBLESTONE:0)
Block(4,-37,2,STONE:5)
Block(4,-37,3,SMOOTH_BRICK:0)
Block(4,-37,4,LOG:0)
Block(4,-36,0,LOG:0)
Block(4,-36,1,COBBLESTONE:0)
Block(4,-36,2,STONE:5)
Block(4,-36,3,SMOOTH_BRICK:0)
Block(4,-36,4,LOG:0)
Block(4,-35,0,LOG:0)
Block(4,-35,1,COBBLESTONE:0)
Block(4,-35,2,STONE:5)
Block(4,-35,3,SMOOTH_BRICK:0)
Block(4,-35,4,LOG:0)
Block(4,-34,0,LOG:0)
Block(4,-34,1,COBBLESTONE:0)
Block(4,-34,2,STONE:5)
Block(4,-34,3,SMOOTH_BRICK:0)
Block(4,-34,4,LOG:0)
Block(4,-33,0,LOG:0)
Block(4,-33,1,COBBLESTONE:0)
Block(4,-33,2,STONE:5)
Block(4,-33,3,SMOOTH_BRICK:0)
Block(4,-33,4,LOG:0)
Block(4,-32,0,LOG:0)
Block(4,-32,1,COBBLESTONE:0)
Block(4,-32,2,STONE:5)
Block(4,-32,3,SMOOTH_BRICK:0)
Block(4,-32,4,LOG:0)
Block(4,-31,0,LOG:0)
Block(4,-31,1,COBBLESTONE:0)
Block(4,-31,2,STONE:5)
Block(4,-31,3,SMOOTH_BRICK:0)
Block(4,-31,4,LOG:0)
Block(4,-30,0,LOG:0)
Block(4,-30,1,COBBLESTONE:0)
Block(4,-30,2,STONE:5)
Block(4,-30,3,SMOOTH_BRICK:0)
Block(4,-30,4,LOG:0)
Block(4,-29,0,LOG:0)
Block(4,-29,1,COBBLESTONE:0)
Block(4,-29,2,STONE:5)
Block(4,-29,3,SMOOTH_BRICK:0)
Block(4,-29,4,LOG:0)
Block(4,-28,0,LOG:0)
Block(4,-28,1,COBBLESTONE:0)
Block(4,-28,2,STONE:5)
Block(4,-28,3,SMOOTH_BRICK:0)
Block(4,-28,4,LOG:0)
Block(4,-27,0,LOG:0)
Block(4,-27,1,COBBLESTONE:0)
Block(4,-27,2,STONE:5)
Block(4,-27,3,SMOOTH_BRICK:0)
Block(4,-27,4,LOG:0)
Block(4,-26,0,LOG:0)
Block(4,-26,1,COBBLESTONE:0)
Block(4,-26,2,STONE:5)
Block(4,-26,3,SMOOTH_BRICK:0)
Block(4,-26,4,LOG:0)
Block(4,-25,0,LOG:0)
Block(4,-25,1,COBBLESTONE:0)
Block(4,-25,2,STONE:5)
Block(4,-25,3,SMOOTH_BRICK:0)
Block(4,-25,4,LOG:0)
Block(4,-24,0,LOG:0)
Block(4,-24,1,COBBLESTONE:0)
Block(4,-24,2,STONE:5)
Block(4,-24,3,SMOOTH_BRICK:0)
Block(4,-24,4,LOG:0)
Block(4,-23,0,LOG:0)
Block(4,-23,1,COBBLESTONE:0)
Block(4,-23,2,STONE:5)
Block(4,-23,3,SMOOTH_BRICK:0)
Block(4,-23,4,LOG:0)
Block(4,-22,0,LOG:0)
Block(4,-22,1,COBBLESTONE:0)
Block(4,-22,2,STONE:5)
Block(4,-22,3,SMOOTH_BRICK:0)
Block(4,-22,4,LOG:0)
Block(4,-21,0,LOG:0)
Block(4,-21,1,COBBLESTONE:0)
Block(4,-21,2,STONE:5)
Block(4,-21,3,SMOOTH_BRICK:0)
Block(4,-21,4,LOG:0)
Block(4,-20,0,LOG:0)
Block(4,-20,1,COBBLESTONE:0)
Block(4,-20,2,STONE:5)
Block(4,-20,3,SMOOTH_BRICK:0)
Block(4,-20,4,LOG:0)
Block(4,-19,0,LOG:0)
Block(4,-19,1,SMOOTH_BRICK:1)
Block(4,-19,2,SMOOTH_BRICK:0)
Block(4,-19,3,STAINED_CLAY:9)
Block(4,-19,4,LOG:0)
Block(4,-18,0,LOG:0)
Block(4,-18,1,COBBLESTONE:0)
Block(4,-18,2,SMOOTH_BRICK:0)
Block(4,-18,3,SMOOTH_BRICK:0)
Block(4,-18,4,LOG:0)
Block(4,-17,0,LOG:0)
Block(4,-17,1,STONE:5)
Block(4,-17,2,STONE:5)
Block(4,-17,3,SMOOTH_BRICK:2)
Block(4,-17,4,LOG:0)
Block(4,-16,0,LOG:0)
Block(4,-16,1,COBBLESTONE:0)
Block(4,-16,2,STONE:5)
Block(4,-16,3,STONE:5)
Block(4,-16,4,LOG:0)
Block(4,-15,0,LOG:0)
Block(4,-15,1,STONE:5)
Block(4,-15,2,SMOOTH_BRICK:2)
Block(4,-15,3,STONE:5)
Block(4,-15,4,LOG:0)
Block(4,-14,0,LOG:0)
Block(4,-14,1,SMOOTH_BRICK:0)
Block(4,-14,2,COBBLESTONE:0)
Block(4,-14,3,STONE:5)
Block(4,-14,4,LOG:0)
Block(4,-13,0,LOG:0)
Block(4,-13,1,COBBLESTONE:0)
Block(4,-13,2,COBBLESTONE:0)
Block(4,-13,3,STONE:5)
Block(4,-13,4,LOG:0)
Block(4,-12,0,LOG:0)
Block(4,-12,1,STONE:5)
Block(4,-12,2,COBBLESTONE:0)
Block(4,-12,3,STONE:5)
Block(4,-12,4,LOG:0)
Block(4,-11,0,LOG:0)
Block(4,-11,1,COBBLESTONE:0)
Block(4,-11,2,STONE:5)
Block(4,-11,3,STONE:5)
Block(4,-11,4,LOG:0)
Block(4,-10,0,LOG:0)
Block(4,-10,1,COBBLESTONE:0)
Block(4,-10,2,COBBLESTONE:0)
Block(4,-10,3,SMOOTH_BRICK:1)
Block(4,-10,4,LOG:0)
Block(4,-9,0,SMOOTH_STAIRS:0)
Block(4,-9,1,COBBLESTONE_STAIRS:0)
Block(4,-9,2,COBBLESTONE_STAIRS:0)
Block(4,-9,3,COBBLESTONE_STAIRS:0)
Block(4,-9,4,SMOOTH_STAIRS:0)
Block(5,-50,-2,COBBLESTONE:0)
Block(5,-50,-1,SMOOTH_BRICK:0)
Block(5,-50,0,COBBLESTONE:0)
Block(5,-50,1,STAINED_CLAY:9)
Block(5,-50,2,SMOOTH_BRICK:2)
Block(5,-50,3,COBBLESTONE:0)
Block(5,-50,4,COBBLESTONE:0)
Block(5,-50,5,STONE:5)
Block(5,-50,6,SMOOTH_BRICK:0)
Block(5,-49,-2,COBBLESTONE:0)
Block(5,-49,-1,SMOOTH_BRICK:0)
Block(5,-49,0,COBBLESTONE:0)
Block(5,-49,1,STAINED_CLAY:9)
Block(5,-49,2,SMOOTH_BRICK:2)
Block(5,-49,3,COBBLESTONE:0)
Block(5,-49,4,COBBLESTONE:0)
Block(5,-49,5,STONE:5)
Block(5,-49,6,SMOOTH_BRICK:0)
Block(5,-48,-2,COBBLESTONE:0)
Block(5,-48,-1,SMOOTH_BRICK:0)
Block(5,-48,0,COBBLESTONE:0)
Block(5,-48,1,STAINED_CLAY:9)
Block(5,-48,2,SMOOTH_BRICK:2)
Block(5,-48,3,COBBLESTONE:0)
Block(5,-48,4,COBBLESTONE:0)
Block(5,-48,5,STONE:5)
Block(5,-48,6,SMOOTH_BRICK:0)
Block(5,-47,-2,COBBLESTONE:0)
Block(5,-47,-1,SMOOTH_BRICK:0)
Block(5,-47,0,COBBLESTONE:0)
Block(5,-47,1,STAINED_CLAY:9)
Block(5,-47,2,SMOOTH_BRICK:2)
Block(5,-47,3,COBBLESTONE:0)
Block(5,-47,4,COBBLESTONE:0)
Block(5,-47,5,STONE:5)
Block(5,-47,6,SMOOTH_BRICK:0)
Block(5,-46,-2,COBBLESTONE:0)
Block(5,-46,-1,SMOOTH_BRICK:0)
Block(5,-46,0,COBBLESTONE:0)
Block(5,-46,1,STAINED_CLAY:9)
Block(5,-46,2,SMOOTH_BRICK:2)
Block(5,-46,3,COBBLESTONE:0)
Block(5,-46,4,COBBLESTONE:0)
Block(5,-46,5,STONE:5)
Block(5,-46,6,SMOOTH_BRICK:0)
Block(5,-45,-2,COBBLESTONE:0)
Block(5,-45,-1,SMOOTH_BRICK:0)
Block(5,-45,0,COBBLESTONE:0)
Block(5,-45,1,STAINED_CLAY:9)
Block(5,-45,2,SMOOTH_BRICK:2)
Block(5,-45,3,COBBLESTONE:0)
Block(5,-45,4,COBBLESTONE:0)
Block(5,-45,5,STONE:5)
Block(5,-45,6,SMOOTH_BRICK:0)
Block(5,-44,-2,COBBLESTONE:0)
Block(5,-44,-1,SMOOTH_BRICK:0)
Block(5,-44,0,COBBLESTONE:0)
Block(5,-44,1,STAINED_CLAY:9)
Block(5,-44,2,SMOOTH_BRICK:2)
Block(5,-44,3,COBBLESTONE:0)
Block(5,-44,4,COBBLESTONE:0)
Block(5,-44,5,STONE:5)
Block(5,-44,6,SMOOTH_BRICK:0)
Block(5,-43,-2,COBBLESTONE:0)
Block(5,-43,-1,SMOOTH_BRICK:0)
Block(5,-43,0,COBBLESTONE:0)
Block(5,-43,1,STAINED_CLAY:9)
Block(5,-43,2,SMOOTH_BRICK:2)
Block(5,-43,3,COBBLESTONE:0)
Block(5,-43,4,COBBLESTONE:0)
Block(5,-43,5,STONE:5)
Block(5,-43,6,SMOOTH_BRICK:0)
Block(5,-42,-2,COBBLESTONE:0)
Block(5,-42,-1,SMOOTH_BRICK:0)
Block(5,-42,0,COBBLESTONE:0)
Block(5,-42,1,STAINED_CLAY:9)
Block(5,-42,2,SMOOTH_BRICK:2)
Block(5,-42,3,COBBLESTONE:0)
Block(5,-42,4,COBBLESTONE:0)
Block(5,-42,5,STONE:5)
Block(5,-42,6,SMOOTH_BRICK:0)
Block(5,-41,-2,COBBLESTONE:0)
Block(5,-41,-1,SMOOTH_BRICK:0)
Block(5,-41,0,COBBLESTONE:0)
Block(5,-41,1,STAINED_CLAY:9)
Block(5,-41,2,SMOOTH_BRICK:2)
Block(5,-41,3,COBBLESTONE:0)
Block(5,-41,4,COBBLESTONE:0)
Block(5,-41,5,STONE:5)
Block(5,-41,6,SMOOTH_BRICK:0)
Block(5,-40,-2,COBBLESTONE:0)
Block(5,-40,-1,SMOOTH_BRICK:0)
Block(5,-40,0,COBBLESTONE:0)
Block(5,-40,1,STAINED_CLAY:9)
Block(5,-40,2,SMOOTH_BRICK:2)
Block(5,-40,3,COBBLESTONE:0)
Block(5,-40,4,COBBLESTONE:0)
Block(5,-40,5,STONE:5)
Block(5,-40,6,SMOOTH_BRICK:0)
Block(5,-39,-2,COBBLESTONE:0)
Block(5,-39,-1,SMOOTH_BRICK:0)
Block(5,-39,0,COBBLESTONE:0)
Block(5,-39,1,STAINED_CLAY:9)
Block(5,-39,2,SMOOTH_BRICK:2)
Block(5,-39,3,COBBLESTONE:0)
Block(5,-39,4,COBBLESTONE:0)
Block(5,-39,5,STONE:5)
Block(5,-39,6,SMOOTH_BRICK:0)
Block(5,-38,-2,COBBLESTONE:0)
Block(5,-38,-1,SMOOTH_BRICK:0)
Block(5,-38,0,COBBLESTONE:0)
Block(5,-38,1,STAINED_CLAY:9)
Block(5,-38,2,SMOOTH_BRICK:2)
Block(5,-38,3,COBBLESTONE:0)
Block(5,-38,4,COBBLESTONE:0)
Block(5,-38,5,STONE:5)
Block(5,-38,6,SMOOTH_BRICK:0)
Block(5,-37,-2,COBBLESTONE:0)
Block(5,-37,-1,SMOOTH_BRICK:0)
Block(5,-37,0,COBBLESTONE:0)
Block(5,-37,1,STAINED_CLAY:9)
Block(5,-37,2,SMOOTH_BRICK:2)
Block(5,-37,3,COBBLESTONE:0)
Block(5,-37,4,COBBLESTONE:0)
Block(5,-37,5,STONE:5)
Block(5,-37,6,SMOOTH_BRICK:0)
Block(5,-36,-2,COBBLESTONE:0)
Block(5,-36,-1,SMOOTH_BRICK:0)
Block(5,-36,0,COBBLESTONE:0)
Block(5,-36,1,STAINED_CLAY:9)
Block(5,-36,2,SMOOTH_BRICK:2)
Block(5,-36,3,COBBLESTONE:0)
Block(5,-36,4,COBBLESTONE:0)
Block(5,-36,5,STONE:5)
Block(5,-36,6,SMOOTH_BRICK:0)
Block(5,-35,-2,COBBLESTONE:0)
Block(5,-35,-1,SMOOTH_BRICK:0)
Block(5,-35,0,COBBLESTONE:0)
Block(5,-35,1,STAINED_CLAY:9)
Block(5,-35,2,SMOOTH_BRICK:2)
Block(5,-35,3,COBBLESTONE:0)
Block(5,-35,4,COBBLESTONE:0)
Block(5,-35,5,STONE:5)
Block(5,-35,6,SMOOTH_BRICK:0)
Block(5,-34,-2,COBBLESTONE:0)
Block(5,-34,-1,SMOOTH_BRICK:0)
Block(5,-34,0,COBBLESTONE:0)
Block(5,-34,1,STAINED_CLAY:9)
Block(5,-34,2,SMOOTH_BRICK:2)
Block(5,-34,3,COBBLESTONE:0)
Block(5,-34,4,COBBLESTONE:0)
Block(5,-34,5,STONE:5)
Block(5,-34,6,SMOOTH_BRICK:0)
Block(5,-33,-2,COBBLESTONE:0)
Block(5,-33,-1,SMOOTH_BRICK:0)
Block(5,-33,0,COBBLESTONE:0)
Block(5,-33,1,STAINED_CLAY:9)
Block(5,-33,2,SMOOTH_BRICK:2)
Block(5,-33,3,COBBLESTONE:0)
Block(5,-33,4,COBBLESTONE:0)
Block(5,-33,5,STONE:5)
Block(5,-33,6,SMOOTH_BRICK:0)
Block(5,-32,-2,COBBLESTONE:0)
Block(5,-32,-1,SMOOTH_BRICK:0)
Block(5,-32,0,COBBLESTONE:0)
Block(5,-32,1,STAINED_CLAY:9)
Block(5,-32,2,SMOOTH_BRICK:2)
Block(5,-32,3,COBBLESTONE:0)
Block(5,-32,4,COBBLESTONE:0)
Block(5,-32,5,STONE:5)
Block(5,-32,6,SMOOTH_BRICK:0)
Block(5,-31,-2,COBBLESTONE:0)
Block(5,-31,-1,SMOOTH_BRICK:0)
Block(5,-31,0,COBBLESTONE:0)
Block(5,-31,1,STAINED_CLAY:9)
Block(5,-31,2,SMOOTH_BRICK:2)
Block(5,-31,3,COBBLESTONE:0)
Block(5,-31,4,COBBLESTONE:0)
Block(5,-31,5,STONE:5)
Block(5,-31,6,SMOOTH_BRICK:0)
Block(5,-30,-2,COBBLESTONE:0)
Block(5,-30,-1,SMOOTH_BRICK:0)
Block(5,-30,0,COBBLESTONE:0)
Block(5,-30,1,STAINED_CLAY:9)
Block(5,-30,2,SMOOTH_BRICK:2)
Block(5,-30,3,COBBLESTONE:0)
Block(5,-30,4,COBBLESTONE:0)
Block(5,-30,5,STONE:5)
Block(5,-30,6,SMOOTH_BRICK:0)
Block(5,-29,-2,COBBLESTONE:0)
Block(5,-29,-1,SMOOTH_BRICK:0)
Block(5,-29,0,COBBLESTONE:0)
Block(5,-29,1,STAINED_CLAY:9)
Block(5,-29,2,SMOOTH_BRICK:2)
Block(5,-29,3,COBBLESTONE:0)
Block(5,-29,4,COBBLESTONE:0)
Block(5,-29,5,STONE:5)
Block(5,-29,6,SMOOTH_BRICK:0)
Block(5,-28,-2,COBBLESTONE:0)
Block(5,-28,-1,SMOOTH_BRICK:0)
Block(5,-28,0,COBBLESTONE:0)
Block(5,-28,1,STAINED_CLAY:9)
Block(5,-28,2,SMOOTH_BRICK:2)
Block(5,-28,3,COBBLESTONE:0)
Block(5,-28,4,COBBLESTONE:0)
Block(5,-28,5,STONE:5)
Block(5,-28,6,SMOOTH_BRICK:0)
Block(5,-27,-2,COBBLESTONE:0)
Block(5,-27,-1,SMOOTH_BRICK:0)
Block(5,-27,0,COBBLESTONE:0)
Block(5,-27,1,STAINED_CLAY:9)
Block(5,-27,2,SMOOTH_BRICK:2)
Block(5,-27,3,COBBLESTONE:0)
Block(5,-27,4,COBBLESTONE:0)
Block(5,-27,5,STONE:5)
Block(5,-27,6,SMOOTH_BRICK:0)
Block(5,-26,-2,COBBLESTONE:0)
Block(5,-26,-1,SMOOTH_BRICK:0)
Block(5,-26,0,COBBLESTONE:0)
Block(5,-26,1,STAINED_CLAY:9)
Block(5,-26,2,SMOOTH_BRICK:2)
Block(5,-26,3,COBBLESTONE:0)
Block(5,-26,4,COBBLESTONE:0)
Block(5,-26,5,STONE:5)
Block(5,-26,6,SMOOTH_BRICK:0)
Block(5,-25,-2,COBBLESTONE:0)
Block(5,-25,-1,SMOOTH_BRICK:0)
Block(5,-25,0,COBBLESTONE:0)
Block(5,-25,1,STAINED_CLAY:9)
Block(5,-25,2,SMOOTH_BRICK:2)
Block(5,-25,3,COBBLESTONE:0)
Block(5,-25,4,COBBLESTONE:0)
Block(5,-25,5,STONE:5)
Block(5,-25,6,SMOOTH_BRICK:0)
Block(5,-24,-2,COBBLESTONE:0)
Block(5,-24,-1,SMOOTH_BRICK:0)
Block(5,-24,0,COBBLESTONE:0)
Block(5,-24,1,STAINED_CLAY:9)
Block(5,-24,2,SMOOTH_BRICK:2)
Block(5,-24,3,COBBLESTONE:0)
Block(5,-24,4,COBBLESTONE:0)
Block(5,-24,5,STONE:5)
Block(5,-24,6,SMOOTH_BRICK:0)
Block(5,-23,-2,COBBLESTONE:0)
Block(5,-23,-1,SMOOTH_BRICK:0)
Block(5,-23,0,COBBLESTONE:0)
Block(5,-23,1,STAINED_CLAY:9)
Block(5,-23,2,SMOOTH_BRICK:2)
Block(5,-23,3,COBBLESTONE:0)
Block(5,-23,4,COBBLESTONE:0)
Block(5,-23,5,STONE:5)
Block(5,-23,6,SMOOTH_BRICK:0)
Block(5,-22,-2,COBBLESTONE:0)
Block(5,-22,-1,SMOOTH_BRICK:0)
Block(5,-22,0,COBBLESTONE:0)
Block(5,-22,1,STAINED_CLAY:9)
Block(5,-22,2,SMOOTH_BRICK:2)
Block(5,-22,3,COBBLESTONE:0)
Block(5,-22,4,COBBLESTONE:0)
Block(5,-22,5,STONE:5)
Block(5,-22,6,SMOOTH_BRICK:0)
Block(5,-21,-2,COBBLESTONE:0)
Block(5,-21,-1,SMOOTH_BRICK:0)
Block(5,-21,0,COBBLESTONE:0)
Block(5,-21,1,STAINED_CLAY:9)
Block(5,-21,2,SMOOTH_BRICK:2)
Block(5,-21,3,COBBLESTONE:0)
Block(5,-21,4,COBBLESTONE:0)
Block(5,-21,5,STONE:5)
Block(5,-21,6,SMOOTH_BRICK:0)
Block(5,-20,-2,COBBLESTONE:0)
Block(5,-20,-1,SMOOTH_BRICK:0)
Block(5,-20,0,COBBLESTONE:0)
Block(5,-20,1,STAINED_CLAY:9)
Block(5,-20,2,SMOOTH_BRICK:2)
Block(5,-20,3,COBBLESTONE:0)
Block(5,-20,4,COBBLESTONE:0)
Block(5,-20,5,STONE:5)
Block(5,-20,6,SMOOTH_BRICK:0)
Block(5,-19,-2,STONE:5)
Block(5,-19,-1,SMOOTH_BRICK:2)
Block(5,-19,0,STONE:5)
Block(5,-19,1,COBBLESTONE:0)
Block(5,-19,2,STONE:5)
Block(5,-19,3,STAINED_CLAY:9)
Block(5,-19,4,COBBLESTONE:0)
Block(5,-19,5,SMOOTH_BRICK:0)
Block(5,-19,6,STAINED_CLAY:9)
Block(5,-18,-2,STAINED_CLAY:9)
Block(5,-18,-1,STAINED_CLAY:9)
Block(5,-18,0,SMOOTH_BRICK:1)
Block(5,-18,1,COBBLESTONE:0)
Block(5,-18,2,STONE:5)
Block(5,-18,3,STONE:5)
Block(5,-18,4,STONE:5)
Block(5,-18,5,SMOOTH_BRICK:0)
Block(5,-18,6,STONE:5)
Block(5,-17,-2,STONE:5)
Block(5,-17,-1,COBBLESTONE:0)
Block(5,-17,0,SMOOTH_BRICK:2)
Block(5,-17,1,COBBLESTONE:0)
Block(5,-17,2,STAINED_CLAY:9)
Block(5,-17,3,STONE:5)
Block(5,-17,4,SMOOTH_BRICK:2)
Block(5,-17,5,STONE:5)
Block(5,-17,6,STONE:5)
Block(5,-16,-2,STONE:5)
Block(5,-16,-1,STONE:5)
Block(5,-16,0,STONE:5)
Block(5,-16,1,STONE:5)
Block(5,-16,2,STONE:5)
Block(5,-16,3,SMOOTH_BRICK:1)
Block(5,-16,4,STONE:5)
Block(5,-16,5,STONE:5)
Block(5,-16,6,SMOOTH_BRICK:0)
Block(5,-15,-2,STONE:5)
Block(5,-15,-1,STONE:5)
Block(5,-15,0,STONE:5)
Block(5,-15,1,COBBLESTONE:0)
Block(5,-15,2,SMOOTH_BRICK:0)
Block(5,-15,3,SMOOTH_BRICK:2)
Block(5,-15,4,COBBLESTONE:0)
Block(5,-15,5,STONE:5)
Block(5,-15,6,COBBLESTONE:0)
Block(5,-14,-2,SMOOTH_BRICK:1)
Block(5,-14,-1,COBBLESTONE:0)
Block(5,-14,0,STONE:5)
Block(5,-14,1,COBBLESTONE:0)
Block(5,-14,2,STONE:5)
Block(5,-14,3,SMOOTH_BRICK:2)
Block(5,-14,4,SMOOTH_BRICK:0)
Block(5,-14,5,STONE:5)
Block(5,-14,6,SMOOTH_BRICK:0)
Block(5,-13,-2,COBBLESTONE:0)
Block(5,-13,-1,COBBLESTONE:0)
Block(5,-13,0,SMOOTH_BRICK:0)
Block(5,-13,1,SMOOTH_BRICK:2)
Block(5,-13,2,SMOOTH_BRICK:2)
Block(5,-13,3,STAINED_CLAY:9)
Block(5,-13,4,SMOOTH_BRICK:2)
Block(5,-13,5,SMOOTH_BRICK:2)
Block(5,-13,6,COBBLESTONE:0)
Block(5,-12,-2,STONE:5)
Block(5,-12,-1,STAINED_CLAY:9)
Block(5,-12,0,COBBLESTONE:0)
Block(5,-12,1,COBBLESTONE:0)
Block(5,-12,2,SMOOTH_BRICK:0)
Block(5,-12,3,STONE:5)
Block(5,-12,4,STONE:5)
Block(5,-12,5,COBBLESTONE:0)
Block(5,-12,6,STONE:5)
Block(5,-11,-2,COBBLESTONE:0)
Block(5,-11,-1,COBBLESTONE:0)
Block(5,-11,0,STONE:5)
Block(5,-11,1,STONE:5)
Block(5,-11,2,STONE:5)
Block(5,-11,3,STONE:5)
Block(5,-11,4,SMOOTH_BRICK:2)
Block(5,-11,5,STONE:5)
Block(5,-11,6,COBBLESTONE:0)
Block(5,-10,-2,STONE:5)
Block(5,-10,-1,STONE:5)
Block(5,-10,0,COBBLESTONE:0)
Block(5,-10,1,COBBLESTONE:0)
Block(5,-10,2,STONE:5)
Block(5,-10,3,STONE:5)
Block(5,-10,4,SMOOTH_BRICK:1)
Block(5,-10,5,SMOOTH_BRICK:2)
Block(5,-10,6,STONE:5)
Block(5,-9,-2,COBBLESTONE_STAIRS:0)
Block(5,-9,-1,COBBLESTONE_STAIRS:0)
Block(5,-9,0,COBBLESTONE_STAIRS:2)
Block(5,-9,1,LOG:0)
Block(5,-9,2,STONE:6)
Block(5,-9,3,LOG:0)
Block(5,-9,4,COBBLESTONE_STAIRS:3)
Block(5,-9,5,COBBLESTONE_STAIRS:0)
Block(5,-9,6,COBBLESTONE_STAIRS:3)
Block(5,-8,1,LOG:0)
Block(5,-8,2,STONE:6)
Block(5,-8,3,LOG:0)
Block(5,-7,1,LOG:0)
Block(5,-7,2,STONE:6)
Block(5,-7,3,LOG:0)
Block(5,-6,1,LOG:0)
Block(5,-6,2,STONE:6)
Block(5,-6,3,LOG:0)
Block(5,-5,1,LOG:0)
Block(5,-5,2,COBBLESTONE_STAIRS:0)
Block(5,-5,3,LOG:0)
Block(5,-4,1,COBBLESTONE_STAIRS:0)
Block(5,-4,3,COBBLESTONE_STAIRS:0)
Block(5,19,2,WALL_BANNER:4,origin/835-bannerC80R256.nbt)
Block(6,-50,-3,LOG:0)
Block(6,-50,-2,COBBLESTONE:0)
Block(6,-50,-1,STONE:5)
Block(6,-50,0,STONE:5)
Block(6,-50,1,STONE:5)
Block(6,-50,2,STONE:5)
Block(6,-50,3,STONE:5)
Block(6,-50,4,COBBLESTONE:0)
Block(6,-50,5,STAINED_CLAY:9)
Block(6,-50,6,STAINED_CLAY:9)
Block(6,-50,7,LOG:0)
Block(6,-49,-3,LOG:0)
Block(6,-49,-2,COBBLESTONE:0)
Block(6,-49,-1,STONE:5)
Block(6,-49,0,STONE:5)
Block(6,-49,1,STONE:5)
Block(6,-49,2,STONE:5)
Block(6,-49,3,STONE:5)
Block(6,-49,4,COBBLESTONE:0)
Block(6,-49,5,STAINED_CLAY:9)
Block(6,-49,6,STAINED_CLAY:9)
Block(6,-49,7,LOG:0)
Block(6,-48,-3,LOG:0)
Block(6,-48,-2,COBBLESTONE:0)
Block(6,-48,-1,STONE:5)
Block(6,-48,0,STONE:5)
Block(6,-48,1,STONE:5)
Block(6,-48,2,STONE:5)
Block(6,-48,3,STONE:5)
Block(6,-48,4,COBBLESTONE:0)
Block(6,-48,5,STAINED_CLAY:9)
Block(6,-48,6,STAINED_CLAY:9)
Block(6,-48,7,LOG:0)
Block(6,-47,-3,LOG:0)
Block(6,-47,-2,COBBLESTONE:0)
Block(6,-47,-1,STONE:5)
Block(6,-47,0,STONE:5)
Block(6,-47,1,STONE:5)
Block(6,-47,2,STONE:5)
Block(6,-47,3,STONE:5)
Block(6,-47,4,COBBLESTONE:0)
Block(6,-47,5,STAINED_CLAY:9)
Block(6,-47,6,STAINED_CLAY:9)
Block(6,-47,7,LOG:0)
Block(6,-46,-3,LOG:0)
Block(6,-46,-2,COBBLESTONE:0)
Block(6,-46,-1,STONE:5)
Block(6,-46,0,STONE:5)
Block(6,-46,1,STONE:5)
Block(6,-46,2,STONE:5)
Block(6,-46,3,STONE:5)
Block(6,-46,4,COBBLESTONE:0)
Block(6,-46,5,STAINED_CLAY:9)
Block(6,-46,6,STAINED_CLAY:9)
Block(6,-46,7,LOG:0)
Block(6,-45,-3,LOG:0)
Block(6,-45,-2,COBBLESTONE:0)
Block(6,-45,-1,STONE:5)
Block(6,-45,0,STONE:5)
Block(6,-45,1,STONE:5)
Block(6,-45,2,STONE:5)
Block(6,-45,3,STONE:5)
Block(6,-45,4,COBBLESTONE:0)
Block(6,-45,5,STAINED_CLAY:9)
Block(6,-45,6,STAINED_CLAY:9)
Block(6,-45,7,LOG:0)
Block(6,-44,-3,LOG:0)
Block(6,-44,-2,COBBLESTONE:0)
Block(6,-44,-1,STONE:5)
Block(6,-44,0,STONE:5)
Block(6,-44,1,STONE:5)
Block(6,-44,2,STONE:5)
Block(6,-44,3,STONE:5)
Block(6,-44,4,COBBLESTONE:0)
Block(6,-44,5,STAINED_CLAY:9)
Block(6,-44,6,STAINED_CLAY:9)
Block(6,-44,7,LOG:0)
Block(6,-43,-3,LOG:0)
Block(6,-43,-2,COBBLESTONE:0)
Block(6,-43,-1,STONE:5)
Block(6,-43,0,STONE:5)
Block(6,-43,1,STONE:5)
Block(6,-43,2,STONE:5)
Block(6,-43,3,STONE:5)
Block(6,-43,4,COBBLESTONE:0)
Block(6,-43,5,STAINED_CLAY:9)
Block(6,-43,6,STAINED_CLAY:9)
Block(6,-43,7,LOG:0)
Block(6,-42,-3,LOG:0)
Block(6,-42,-2,COBBLESTONE:0)
Block(6,-42,-1,STONE:5)
Block(6,-42,0,STONE:5)
Block(6,-42,1,STONE:5)
Block(6,-42,2,STONE:5)
Block(6,-42,3,STONE:5)
Block(6,-42,4,COBBLESTONE:0)
Block(6,-42,5,STAINED_CLAY:9)
Block(6,-42,6,STAINED_CLAY:9)
Block(6,-42,7,LOG:0)
Block(6,-41,-3,LOG:0)
Block(6,-41,-2,COBBLESTONE:0)
Block(6,-41,-1,STONE:5)
Block(6,-41,0,STONE:5)
Block(6,-41,1,STONE:5)
Block(6,-41,2,STONE:5)
Block(6,-41,3,STONE:5)
Block(6,-41,4,COBBLESTONE:0)
Block(6,-41,5,STAINED_CLAY:9)
Block(6,-41,6,STAINED_CLAY:9)
Block(6,-41,7,LOG:0)
Block(6,-40,-3,LOG:0)
Block(6,-40,-2,COBBLESTONE:0)
Block(6,-40,-1,STONE:5)
Block(6,-40,0,STONE:5)
Block(6,-40,1,STONE:5)
Block(6,-40,2,STONE:5)
Block(6,-40,3,STONE:5)
Block(6,-40,4,COBBLESTONE:0)
Block(6,-40,5,STAINED_CLAY:9)
Block(6,-40,6,STAINED_CLAY:9)
Block(6,-40,7,LOG:0)
Block(6,-39,-3,LOG:0)
Block(6,-39,-2,COBBLESTONE:0)
Block(6,-39,-1,STONE:5)
Block(6,-39,0,STONE:5)
Block(6,-39,1,STONE:5)
Block(6,-39,2,STONE:5)
Block(6,-39,3,STONE:5)
Block(6,-39,4,COBBLESTONE:0)
Block(6,-39,5,STAINED_CLAY:9)
Block(6,-39,6,STAINED_CLAY:9)
Block(6,-39,7,LOG:0)
Block(6,-38,-3,LOG:0)
Block(6,-38,-2,COBBLESTONE:0)
Block(6,-38,-1,STONE:5)
Block(6,-38,0,STONE:5)
Block(6,-38,1,STONE:5)
Block(6,-38,2,STONE:5)
Block(6,-38,3,STONE:5)
Block(6,-38,4,COBBLESTONE:0)
Block(6,-38,5,STAINED_CLAY:9)
Block(6,-38,6,STAINED_CLAY:9)
Block(6,-38,7,LOG:0)
Block(6,-37,-3,LOG:0)
Block(6,-37,-2,COBBLESTONE:0)
Block(6,-37,-1,STONE:5)
Block(6,-37,0,STONE:5)
Block(6,-37,1,STONE:5)
Block(6,-37,2,STONE:5)
Block(6,-37,3,STONE:5)
Block(6,-37,4,COBBLESTONE:0)
Block(6,-37,5,STAINED_CLAY:9)
Block(6,-37,6,STAINED_CLAY:9)
Block(6,-37,7,LOG:0)
Block(6,-36,-3,LOG:0)
Block(6,-36,-2,COBBLESTONE:0)
Block(6,-36,-1,STONE:5)
Block(6,-36,0,STONE:5)
Block(6,-36,1,STONE:5)
Block(6,-36,2,STONE:5)
Block(6,-36,3,STONE:5)
Block(6,-36,4,COBBLESTONE:0)
Block(6,-36,5,STAINED_CLAY:9)
Block(6,-36,6,STAINED_CLAY:9)
Block(6,-36,7,LOG:0)
Block(6,-35,-3,LOG:0)
Block(6,-35,-2,COBBLESTONE:0)
Block(6,-35,-1,STONE:5)
Block(6,-35,0,STONE:5)
Block(6,-35,1,STONE:5)
Block(6,-35,2,STONE:5)
Block(6,-35,3,STONE:5)
Block(6,-35,4,COBBLESTONE:0)
Block(6,-35,5,STAINED_CLAY:9)
Block(6,-35,6,STAINED_CLAY:9)
Block(6,-35,7,LOG:0)
Block(6,-34,-3,LOG:0)
Block(6,-34,-2,COBBLESTONE:0)
Block(6,-34,-1,STONE:5)
Block(6,-34,0,STONE:5)
Block(6,-34,1,STONE:5)
Block(6,-34,2,STONE:5)
Block(6,-34,3,STONE:5)
Block(6,-34,4,COBBLESTONE:0)
Block(6,-34,5,STAINED_CLAY:9)
Block(6,-34,6,STAINED_CLAY:9)
Block(6,-34,7,LOG:0)
Block(6,-33,-3,LOG:0)
Block(6,-33,-2,COBBLESTONE:0)
Block(6,-33,-1,STONE:5)
Block(6,-33,0,STONE:5)
Block(6,-33,1,STONE:5)
Block(6,-33,2,STONE:5)
Block(6,-33,3,STONE:5)
Block(6,-33,4,COBBLESTONE:0)
Block(6,-33,5,STAINED_CLAY:9)
Block(6,-33,6,STAINED_CLAY:9)
Block(6,-33,7,LOG:0)
Block(6,-32,-3,LOG:0)
Block(6,-32,-2,COBBLESTONE:0)
Block(6,-32,-1,STONE:5)
Block(6,-32,0,STONE:5)
Block(6,-32,1,STONE:5)
Block(6,-32,2,STONE:5)
Block(6,-32,3,STONE:5)
Block(6,-32,4,COBBLESTONE:0)
Block(6,-32,5,STAINED_CLAY:9)
Block(6,-32,6,STAINED_CLAY:9)
Block(6,-32,7,LOG:0)
Block(6,-31,-3,LOG:0)
Block(6,-31,-2,COBBLESTONE:0)
Block(6,-31,-1,STONE:5)
Block(6,-31,0,STONE:5)
Block(6,-31,1,STONE:5)
Block(6,-31,2,STONE:5)
Block(6,-31,3,STONE:5)
Block(6,-31,4,COBBLESTONE:0)
Block(6,-31,5,STAINED_CLAY:9)
Block(6,-31,6,STAINED_CLAY:9)
Block(6,-31,7,LOG:0)
Block(6,-30,-3,LOG:0)
Block(6,-30,-2,COBBLESTONE:0)
Block(6,-30,-1,STONE:5)
Block(6,-30,0,STONE:5)
Block(6,-30,1,STONE:5)
Block(6,-30,2,STONE:5)
Block(6,-30,3,STONE:5)
Block(6,-30,4,COBBLESTONE:0)
Block(6,-30,5,STAINED_CLAY:9)
Block(6,-30,6,STAINED_CLAY:9)
Block(6,-30,7,LOG:0)
Block(6,-29,-3,LOG:0)
Block(6,-29,-2,COBBLESTONE:0)
Block(6,-29,-1,STONE:5)
Block(6,-29,0,STONE:5)
Block(6,-29,1,STONE:5)
Block(6,-29,2,STONE:5)
Block(6,-29,3,STONE:5)
Block(6,-29,4,COBBLESTONE:0)
Block(6,-29,5,STAINED_CLAY:9)
Block(6,-29,6,STAINED_CLAY:9)
Block(6,-29,7,LOG:0)
Block(6,-28,-3,LOG:0)
Block(6,-28,-2,COBBLESTONE:0)
Block(6,-28,-1,STONE:5)
Block(6,-28,0,STONE:5)
Block(6,-28,1,STONE:5)
Block(6,-28,2,STONE:5)
Block(6,-28,3,STONE:5)
Block(6,-28,4,COBBLESTONE:0)
Block(6,-28,5,STAINED_CLAY:9)
Block(6,-28,6,STAINED_CLAY:9)
Block(6,-28,7,LOG:0)
Block(6,-27,-3,LOG:0)
Block(6,-27,-2,COBBLESTONE:0)
Block(6,-27,-1,STONE:5)
Block(6,-27,0,STONE:5)
Block(6,-27,1,STONE:5)
Block(6,-27,2,STONE:5)
Block(6,-27,3,STONE:5)
Block(6,-27,4,COBBLESTONE:0)
Block(6,-27,5,STAINED_CLAY:9)
Block(6,-27,6,STAINED_CLAY:9)
Block(6,-27,7,LOG:0)
Block(6,-26,-3,LOG:0)
Block(6,-26,-2,COBBLESTONE:0)
Block(6,-26,-1,STONE:5)
Block(6,-26,0,STONE:5)
Block(6,-26,1,STONE:5)
Block(6,-26,2,STONE:5)
Block(6,-26,3,STONE:5)
Block(6,-26,4,COBBLESTONE:0)
Block(6,-26,5,STAINED_CLAY:9)
Block(6,-26,6,STAINED_CLAY:9)
Block(6,-26,7,LOG:0)
Block(6,-25,-3,LOG:0)
Block(6,-25,-2,COBBLESTONE:0)
Block(6,-25,-1,STONE:5)
Block(6,-25,0,STONE:5)
Block(6,-25,1,STONE:5)
Block(6,-25,2,STONE:5)
Block(6,-25,3,STONE:5)
Block(6,-25,4,COBBLESTONE:0)
Block(6,-25,5,STAINED_CLAY:9)
Block(6,-25,6,STAINED_CLAY:9)
Block(6,-25,7,LOG:0)
Block(6,-24,-3,LOG:0)
Block(6,-24,-2,COBBLESTONE:0)
Block(6,-24,-1,STONE:5)
Block(6,-24,0,STONE:5)
Block(6,-24,1,STONE:5)
Block(6,-24,2,STONE:5)
Block(6,-24,3,STONE:5)
Block(6,-24,4,COBBLESTONE:0)
Block(6,-24,5,STAINED_CLAY:9)
Block(6,-24,6,STAINED_CLAY:9)
Block(6,-24,7,LOG:0)
Block(6,-23,-3,LOG:0)
Block(6,-23,-2,COBBLESTONE:0)
Block(6,-23,-1,STONE:5)
Block(6,-23,0,STONE:5)
Block(6,-23,1,STONE:5)
Block(6,-23,2,STONE:5)
Block(6,-23,3,STONE:5)
Block(6,-23,4,COBBLESTONE:0)
Block(6,-23,5,STAINED_CLAY:9)
Block(6,-23,6,STAINED_CLAY:9)
Block(6,-23,7,LOG:0)
Block(6,-22,-3,LOG:0)
Block(6,-22,-2,COBBLESTONE:0)
Block(6,-22,-1,STONE:5)
Block(6,-22,0,STONE:5)
Block(6,-22,1,STONE:5)
Block(6,-22,2,STONE:5)
Block(6,-22,3,STONE:5)
Block(6,-22,4,COBBLESTONE:0)
Block(6,-22,5,STAINED_CLAY:9)
Block(6,-22,6,STAINED_CLAY:9)
Block(6,-22,7,LOG:0)
Block(6,-21,-3,LOG:0)
Block(6,-21,-2,COBBLESTONE:0)
Block(6,-21,-1,STONE:5)
Block(6,-21,0,STONE:5)
Block(6,-21,1,STONE:5)
Block(6,-21,2,STONE:5)
Block(6,-21,3,STONE:5)
Block(6,-21,4,COBBLESTONE:0)
Block(6,-21,5,STAINED_CLAY:9)
Block(6,-21,6,STAINED_CLAY:9)
Block(6,-21,7,LOG:0)
Block(6,-20,-3,LOG:0)
Block(6,-20,-2,COBBLESTONE:0)
Block(6,-20,-1,STONE:5)
Block(6,-20,0,STONE:5)
Block(6,-20,1,STONE:5)
Block(6,-20,2,STONE:5)
Block(6,-20,3,STONE:5)
Block(6,-20,4,COBBLESTONE:0)
Block(6,-20,5,STAINED_CLAY:9)
Block(6,-20,6,STAINED_CLAY:9)
Block(6,-20,7,LOG:0)
Block(6,-19,-3,LOG:0)
Block(6,-19,-2,STONE:5)
Block(6,-19,-1,STONE:5)
Block(6,-19,0,COBBLESTONE:0)
Block(6,-19,1,STAINED_CLAY:9)
Block(6,-19,2,STONE:5)
Block(6,-19,3,SMOOTH_BRICK:2)
Block(6,-19,4,SMOOTH_BRICK:2)
Block(6,-19,5,SMOOTH_BRICK:0)
Block(6,-19,6,SMOOTH_BRICK:2)
Block(6,-19,7,LOG:0)
Block(6,-18,-3,LOG:0)
Block(6,-18,-2,STONE:5)
Block(6,-18,-1,COBBLESTONE:0)
Block(6,-18,0,COBBLESTONE:0)
Block(6,-18,1,COBBLESTONE:0)
Block(6,-18,2,STONE:5)
Block(6,-18,3,SMOOTH_BRICK:2)
Block(6,-18,4,COBBLESTONE:0)
Block(6,-18,5,SMOOTH_BRICK:0)
Block(6,-18,6,SMOOTH_BRICK:1)
Block(6,-18,7,LOG:0)
Block(6,-17,-3,LOG:0)
Block(6,-17,-2,STONE:5)
Block(6,-17,-1,STONE:5)
Block(6,-17,0,SMOOTH_BRICK:2)
Block(6,-17,1,STONE:5)
Block(6,-17,2,COBBLESTONE:0)
Block(6,-17,3,STONE:5)
Block(6,-17,4,SMOOTH_BRICK:1)
Block(6,-17,5,SMOOTH_BRICK:2)
Block(6,-17,6,STONE:5)
Block(6,-17,7,LOG:0)
Block(6,-16,-3,LOG:0)
Block(6,-16,-2,STONE:5)
Block(6,-16,-1,STONE:5)
Block(6,-16,0,COBBLESTONE:0)
Block(6,-16,1,STAINED_CLAY:9)
Block(6,-16,2,SMOOTH_BRICK:0)
Block(6,-16,3,SMOOTH_BRICK:0)
Block(6,-16,4,SMOOTH_BRICK:0)
Block(6,-16,5,COBBLESTONE:0)
Block(6,-16,6,SMOOTH_BRICK:0)
Block(6,-16,7,LOG:0)
Block(6,-15,-3,LOG:0)
Block(6,-15,-2,COBBLESTONE:0)
Block(6,-15,-1,STONE:5)
Block(6,-15,0,COBBLESTONE:0)
Block(6,-15,1,COBBLESTONE:0)
Block(6,-15,2,SMOOTH_BRICK:2)
Block(6,-15,3,SMOOTH_BRICK:0)
Block(6,-15,4,STAINED_CLAY:9)
Block(6,-15,5,SMOOTH_BRICK:0)
Block(6,-15,6,SMOOTH_BRICK:2)
Block(6,-15,7,LOG:0)
Block(6,-14,-3,LOG:0)
Block(6,-14,-2,STONE:5)
Block(6,-14,-1,COBBLESTONE:0)
Block(6,-14,0,SMOOTH_BRICK:0)
Block(6,-14,1,STONE:5)
Block(6,-14,2,STAINED_CLAY:9)
Block(6,-14,3,STONE:5)
Block(6,-14,4,STONE:5)
Block(6,-14,5,SMOOTH_BRICK:2)
Block(6,-14,6,STAINED_CLAY:9)
Block(6,-14,7,LOG:0)
Block(6,-13,-3,LOG:0)
Block(6,-13,-2,STONE:5)
Block(6,-13,-1,STAINED_CLAY:9)
Block(6,-13,0,STONE:5)
Block(6,-13,1,STAINED_CLAY:9)
Block(6,-13,2,SMOOTH_BRICK:1)
Block(6,-13,3,STONE:5)
Block(6,-13,4,SMOOTH_BRICK:0)
Block(6,-13,5,SMOOTH_BRICK:2)
Block(6,-13,6,SMOOTH_BRICK:2)
Block(6,-13,7,LOG:0)
Block(6,-12,-3,LOG:0)
Block(6,-12,-2,COBBLESTONE:0)
Block(6,-12,-1,COBBLESTONE:0)
Block(6,-12,0,COBBLESTONE:0)
Block(6,-12,1,STONE:5)
Block(6,-12,2,SMOOTH_BRICK:2)
Block(6,-12,3,SMOOTH_BRICK:0)
Block(6,-12,4,STONE:5)
Block(6,-12,5,STONE:5)
Block(6,-12,6,SMOOTH_BRICK:1)
Block(6,-12,7,LOG:0)
Block(6,-11,-3,LOG:0)
Block(6,-11,-2,COBBLESTONE:0)
Block(6,-11,-1,STONE:5)
Block(6,-11,0,COBBLESTONE:0)
Block(6,-11,1,COBBLESTONE:0)
Block(6,-11,2,STONE:5)
Block(6,-11,3,STONE:5)
Block(6,-11,4,STONE:5)
Block(6,-11,5,STONE:5)
Block(6,-11,6,STONE:5)
Block(6,-11,7,LOG:0)
Block(6,-10,-3,LOG:0)
Block(6,-10,-2,COBBLESTONE:0)
Block(6,-10,-1,COBBLESTONE:0)
Block(6,-10,0,STAINED_CLAY:9)
Block(6,-10,1,SMOOTH_BRICK:0)
Block(6,-10,2,STONE:5)
Block(6,-10,3,STONE:5)
Block(6,-10,4,STONE:5)
Block(6,-10,5,COBBLESTONE:0)
Block(6,-10,6,STONE:5)
Block(6,-10,7,LOG:0)
Block(6,-9,-3,SMOOTH_STAIRS:0)
Block(6,-9,-2,COBBLESTONE_STAIRS:2)
Block(6,-9,-1,STONE:6)
Block(6,-9,0,STONE:6)
Block(6,-9,1,STONE:6)
Block(6,-9,2,STONE:6)
Block(6,-9,3,STONE:6)
Block(6,-9,4,STONE:6)
Block(6,-9,5,STONE:6)
Block(6,-9,6,COBBLESTONE_STAIRS:0)
Block(6,-9,7,SMOOTH_STAIRS:3)
Block(6,-8,-1,STONE:6)
Block(6,-8,0,STONE:6)
Block(6,-8,1,STONE:5)
Block(6,-8,2,STONE:5)
Block(6,-8,3,SMOOTH_BRICK:2)
Block(6,-8,4,STONE:6)
Block(6,-8,5,STONE:6)
Block(6,-7,-1,STONE:6)
Block(6,-7,0,STONE:6)
Block(6,-7,1,STONE:5)
Block(6,-7,2,COBBLESTONE:0)
Block(6,-7,3,SMOOTH_BRICK:2)
Block(6,-7,4,STONE:6)
Block(6,-7,5,STONE:6)
Block(6,-6,-1,STONE:6)
Block(6,-6,0,STONE:6)
Block(6,-6,1,STONE:5)
Block(6,-6,2,STONE:5)
Block(6,-6,3,STONE:5)
Block(6,-6,4,STONE:6)
Block(6,-6,5,STONE:6)
Block(6,-5,-1,COBBLESTONE_STAIRS:0)
Block(6,-5,0,COBBLESTONE_STAIRS:0)
Block(6,-5,1,COBBLESTONE:0)
Block(6,-5,2,SMOOTH_BRICK:2)
Block(6,-5,3,STONE:5)
Block(6,-5,4,COBBLESTONE_STAIRS:0)
Block(6,-5,5,COBBLESTONE_STAIRS:0)
Block(6,-4,1,LOG:4)
Block(6,-4,2,STONE:6)
Block(6,-4,3,LOG:4)
Block(6,-3,1,LOG:0)
Block(6,-3,2,STONE:6)
Block(6,-3,3,LOG:0)
Block(6,-2,1,LOG:0)
Block(6,-2,2,STONE:6)
Block(6,-2,3,LOG:0)
Block(6,-1,1,LOG:0)
Block(6,-1,2,STONE:6)
Block(6,-1,3,LOG:0)
Block(6,0,1,LOG:0)
Block(6,0,2,COBBLESTONE_STAIRS:0)
Block(6,0,3,LOG:0)
Block(6,1,1,LOG:0)
Block(6,1,2,COBBLESTONE_STAIRS:4)
Block(6,1,3,LOG:0)
Block(6,2,1,LOG:0)
Block(6,2,2,STONE:6)
Block(6,2,3,LOG:0)
Block(6,3,1,LOG:0)
Block(6,3,2,STONE:6)
Block(6,3,3,LOG:0)
Block(6,4,1,LOG:0)
Block(6,4,2,STONE:6)
Block(6,4,3,LOG:0)
Block(6,5,1,LOG:0)
Block(6,5,2,SMOOTH_BRICK:0)
Block(6,5,3,LOG:0)
Block(6,6,1,LOG:0)
Block(6,6,2,SMOOTH_BRICK:0)
Block(6,6,3,LOG:0)
Block(6,7,1,LOG:0)
Block(6,7,2,SMOOTH_BRICK:0)
Block(6,7,3,LOG:0)
Block(6,8,1,SMOOTH_STAIRS:0)
Block(6,8,2,SMOOTH_BRICK:0)
Block(6,8,3,SMOOTH_STAIRS:0)
Block(6,9,1,AIR:0)
Block(6,9,2,SMOOTH_BRICK:0)
Block(6,9,3,AIR:0)
Block(6,10,1,AIR:0)
Block(6,10,2,SMOOTH_BRICK:0)
Block(6,10,3,AIR:0)
Block(6,11,1,AIR:0)
Block(6,11,2,SMOOTH_BRICK:0)
Block(6,11,3,AIR:0)
Block(6,12,1,AIR:0)
Block(6,12,2,SMOOTH_STAIRS:0)
Block(6,12,3,AIR:0)
Block(6,13,1,AIR:0)
Block(6,13,2,AIR:0)
Block(6,13,3,AIR:0)
Block(6,14,1,AIR:0)
Block(6,14,2,AIR:0)
Block(6,14,3,AIR:0)
Block(6,15,1,AIR:0)
Block(6,15,2,AIR:0)
Block(6,15,3,AIR:0)
Block(6,16,1,AIR:0)
Block(6,16,2,AIR:0)
Block(6,16,3,AIR:0)
Block(6,17,1,AIR:0)
Block(6,17,2,AIR:0)
Block(6,17,3,AIR:0)
Block(6,18,1,TRAP_DOOR:14)
Block(6,18,2,SMOOTH_STAIRS:4)
Block(6,18,3,TRAP_DOOR:14)
Block(6,19,1,SMOOTH_STAIRS:6)
Block(6,19,2,STONE:6)
Block(6,19,3,SMOOTH_STAIRS:7)
Block(6,20,1,STONE:6)
Block(6,20,2,STEP:0)
Block(6,20,3,STONE:6)
Block(6,21,1,AIR:0)
Block(6,21,2,AIR:0)
Block(6,21,3,AIR:0)
Block(6,22,1,AIR:0)
Block(6,22,2,AIR:0)
Block(6,22,3,AIR:0)
Block(6,23,1,AIR:0)
Block(6,23,2,AIR:0)
Block(6,23,3,AIR:0)
Block(6,24,1,AIR:0)
Block(6,24,2,AIR:0)
Block(6,24,3,AIR:0)
Block(6,25,1,AIR:0)
Block(6,25,2,AIR:0)
Block(6,25,3,AIR:0)
Block(6,26,1,AIR:0)
Block(6,26,2,AIR:0)
Block(6,26,3,AIR:0)
Block(6,27,1,AIR:0)
Block(6,27,2,AIR:0)
Block(6,27,3,AIR:0)
Block(6,28,1,AIR:0)
Block(6,28,2,AIR:0)
Block(6,28,3,AIR:0)
Block(6,29,1,AIR:0)
Block(6,29,2,AIR:0)
Block(6,29,3,AIR:0)
Block(6,30,1,AIR:0)
Block(6,30,2,AIR:0)
Block(6,30,3,AIR:0)
Block(6,31,1,AIR:0)
Block(6,31,2,AIR:0)
Block(6,31,3,AIR:0)
Block(6,32,1,AIR:0)
Block(6,32,2,AIR:0)
Block(6,32,3,AIR:0)
Block(6,33,1,AIR:0)
Block(6,33,2,AIR:0)
Block(6,33,3,AIR:0)
Block(6,34,1,AIR:0)
Block(6,34,2,AIR:0)
Block(6,34,3,AIR:0)
Block(6,35,1,AIR:0)
Block(6,35,2,AIR:0)
Block(6,35,3,AIR:0)
Block(6,36,1,AIR:0)
Block(6,36,2,AIR:0)
Block(6,36,3,AIR:0)
Block(6,37,1,AIR:0)
Block(6,37,2,AIR:0)
Block(6,37,3,AIR:0)
Block(6,38,1,AIR:0)
Block(6,38,2,AIR:0)
Block(6,38,3,AIR:0)
Block(6,39,1,AIR:0)
Block(6,39,2,AIR:0)
Block(6,39,3,AIR:0)
Block(6,40,1,AIR:0)
Block(6,40,2,AIR:0)
Block(6,40,3,AIR:0)
Block(6,41,1,AIR:0)
Block(6,41,2,AIR:0)
Block(6,41,3,AIR:0)
Block(6,42,1,AIR:0)
Block(6,42,2,AIR:0)
Block(6,42,3,AIR:0)
Block(6,43,1,AIR:0)
Block(6,43,2,AIR:0)
Block(6,43,3,AIR:0)
Block(6,44,1,AIR:0)
Block(6,44,2,AIR:0)
Block(6,44,3,AIR:0)
Block(6,45,1,AIR:0)
Block(6,45,2,AIR:0)
Block(6,45,3,AIR:0)
Block(6,46,1,AIR:0)
Block(6,46,2,AIR:0)
Block(6,46,3,AIR:0)
Block(6,47,1,AIR:0)
Block(6,47,2,AIR:0)
Block(6,47,3,AIR:0)
Block(6,48,1,AIR:0)
Block(6,48,2,AIR:0)
Block(6,48,3,AIR:0)
Block(6,49,1,AIR:0)
Block(6,49,2,AIR:0)
Block(6,49,3,AIR:0)
Block(6,50,1,AIR:0)
Block(6,50,2,AIR:0)
Block(6,50,3,AIR:0)
Block(6,51,1,AIR:0)
Block(6,51,2,AIR:0)
Block(6,51,3,AIR:0)
Block(6,52,1,AIR:0)
Block(6,52,2,AIR:0)
Block(6,52,3,AIR:0)
Block(6,53,1,AIR:0)
Block(6,53,2,AIR:0)
Block(6,53,3,AIR:0)
Block(6,54,1,AIR:0)
Block(6,54,2,AIR:0)
Block(6,54,3,AIR:0)
Block(6,55,1,AIR:0)
Block(6,55,2,AIR:0)
Block(6,55,3,AIR:0)
Block(6,56,1,AIR:0)
Block(6,56,2,AIR:0)
Block(6,56,3,AIR:0)
Block(6,57,1,AIR:0)
Block(6,57,2,AIR:0)
Block(6,57,3,AIR:0)
Block(6,58,1,AIR:0)
Block(6,58,2,AIR:0)
Block(6,58,3,AIR:0)
Block(6,59,1,AIR:0)
Block(6,59,2,AIR:0)
Block(6,59,3,AIR:0)
Block(6,60,1,AIR:0)
Block(6,60,2,AIR:0)
Block(6,60,3,AIR:0)
Block(6,61,1,AIR:0)
Block(6,61,2,AIR:0)
Block(6,61,3,AIR:0)
Block(6,62,1,AIR:0)
Block(6,62,2,AIR:0)
Block(6,62,3,AIR:0)
Block(6,63,1,AIR:0)
Block(6,63,2,AIR:0)
Block(6,63,3,AIR:0)
Block(7,-50,-4,COBBLESTONE:0)
Block(7,-50,-3,COBBLESTONE:0)
Block(7,-50,-2,SMOOTH_BRICK:1)
Block(7,-50,-1,COBBLESTONE:0)
Block(7,-50,0,SMOOTH_BRICK:2)
Block(7,-50,1,COBBLESTONE:0)
Block(7,-50,2,SMOOTH_BRICK:0)
Block(7,-50,3,STONE:5)
Block(7,-50,4,STONE:5)
Block(7,-50,5,SMOOTH_BRICK:2)
Block(7,-50,6,STONE:5)
Block(7,-50,7,STONE:5)
Block(7,-50,8,SMOOTH_BRICK:1)
Block(7,-49,-4,COBBLESTONE:0)
Block(7,-49,-3,COBBLESTONE:0)
Block(7,-49,-2,SMOOTH_BRICK:1)
Block(7,-49,-1,COBBLESTONE:0)
Block(7,-49,0,SMOOTH_BRICK:2)
Block(7,-49,1,COBBLESTONE:0)
Block(7,-49,2,SMOOTH_BRICK:0)
Block(7,-49,3,STONE:5)
Block(7,-49,4,STONE:5)
Block(7,-49,5,SMOOTH_BRICK:2)
Block(7,-49,6,STONE:5)
Block(7,-49,7,STONE:5)
Block(7,-49,8,SMOOTH_BRICK:1)
Block(7,-48,-4,COBBLESTONE:0)
Block(7,-48,-3,COBBLESTONE:0)
Block(7,-48,-2,SMOOTH_BRICK:1)
Block(7,-48,-1,COBBLESTONE:0)
Block(7,-48,0,SMOOTH_BRICK:2)
Block(7,-48,1,COBBLESTONE:0)
Block(7,-48,2,SMOOTH_BRICK:0)
Block(7,-48,3,STONE:5)
Block(7,-48,4,STONE:5)
Block(7,-48,5,SMOOTH_BRICK:2)
Block(7,-48,6,STONE:5)
Block(7,-48,7,STONE:5)
Block(7,-48,8,SMOOTH_BRICK:1)
Block(7,-47,-4,COBBLESTONE:0)
Block(7,-47,-3,COBBLESTONE:0)
Block(7,-47,-2,SMOOTH_BRICK:1)
Block(7,-47,-1,COBBLESTONE:0)
Block(7,-47,0,SMOOTH_BRICK:2)
Block(7,-47,1,COBBLESTONE:0)
Block(7,-47,2,SMOOTH_BRICK:0)
Block(7,-47,3,STONE:5)
Block(7,-47,4,STONE:5)
Block(7,-47,5,SMOOTH_BRICK:2)
Block(7,-47,6,STONE:5)
Block(7,-47,7,STONE:5)
Block(7,-47,8,SMOOTH_BRICK:1)
Block(7,-46,-4,COBBLESTONE:0)
Block(7,-46,-3,COBBLESTONE:0)
Block(7,-46,-2,SMOOTH_BRICK:1)
Block(7,-46,-1,COBBLESTONE:0)
Block(7,-46,0,SMOOTH_BRICK:2)
Block(7,-46,1,COBBLESTONE:0)
Block(7,-46,2,SMOOTH_BRICK:0)
Block(7,-46,3,STONE:5)
Block(7,-46,4,STONE:5)
Block(7,-46,5,SMOOTH_BRICK:2)
Block(7,-46,6,STONE:5)
Block(7,-46,7,STONE:5)
Block(7,-46,8,SMOOTH_BRICK:1)
Block(7,-45,-4,COBBLESTONE:0)
Block(7,-45,-3,COBBLESTONE:0)
Block(7,-45,-2,SMOOTH_BRICK:1)
Block(7,-45,-1,COBBLESTONE:0)
Block(7,-45,0,SMOOTH_BRICK:2)
Block(7,-45,1,COBBLESTONE:0)
Block(7,-45,2,SMOOTH_BRICK:0)
Block(7,-45,3,STONE:5)
Block(7,-45,4,STONE:5)
Block(7,-45,5,SMOOTH_BRICK:2)
Block(7,-45,6,STONE:5)
Block(7,-45,7,STONE:5)
Block(7,-45,8,SMOOTH_BRICK:1)
Block(7,-44,-4,COBBLESTONE:0)
Block(7,-44,-3,COBBLESTONE:0)
Block(7,-44,-2,SMOOTH_BRICK:1)
Block(7,-44,-1,COBBLESTONE:0)
Block(7,-44,0,SMOOTH_BRICK:2)
Block(7,-44,1,COBBLESTONE:0)
Block(7,-44,2,SMOOTH_BRICK:0)
Block(7,-44,3,STONE:5)
Block(7,-44,4,STONE:5)
Block(7,-44,5,SMOOTH_BRICK:2)
Block(7,-44,6,STONE:5)
Block(7,-44,7,STONE:5)
Block(7,-44,8,SMOOTH_BRICK:1)
Block(7,-43,-4,COBBLESTONE:0)
Block(7,-43,-3,COBBLESTONE:0)
Block(7,-43,-2,SMOOTH_BRICK:1)
Block(7,-43,-1,COBBLESTONE:0)
Block(7,-43,0,SMOOTH_BRICK:2)
Block(7,-43,1,COBBLESTONE:0)
Block(7,-43,2,SMOOTH_BRICK:0)
Block(7,-43,3,STONE:5)
Block(7,-43,4,STONE:5)
Block(7,-43,5,SMOOTH_BRICK:2)
Block(7,-43,6,STONE:5)
Block(7,-43,7,STONE:5)
Block(7,-43,8,SMOOTH_BRICK:1)
Block(7,-42,-4,COBBLESTONE:0)
Block(7,-42,-3,COBBLESTONE:0)
Block(7,-42,-2,SMOOTH_BRICK:1)
Block(7,-42,-1,COBBLESTONE:0)
Block(7,-42,0,SMOOTH_BRICK:2)
Block(7,-42,1,COBBLESTONE:0)
Block(7,-42,2,SMOOTH_BRICK:0)
Block(7,-42,3,STONE:5)
Block(7,-42,4,STONE:5)
Block(7,-42,5,SMOOTH_BRICK:2)
Block(7,-42,6,STONE:5)
Block(7,-42,7,STONE:5)
Block(7,-42,8,SMOOTH_BRICK:1)
Block(7,-41,-4,COBBLESTONE:0)
Block(7,-41,-3,COBBLESTONE:0)
Block(7,-41,-2,SMOOTH_BRICK:1)
Block(7,-41,-1,COBBLESTONE:0)
Block(7,-41,0,SMOOTH_BRICK:2)
Block(7,-41,1,COBBLESTONE:0)
Block(7,-41,2,SMOOTH_BRICK:0)
Block(7,-41,3,STONE:5)
Block(7,-41,4,STONE:5)
Block(7,-41,5,SMOOTH_BRICK:2)
Block(7,-41,6,STONE:5)
Block(7,-41,7,STONE:5)
Block(7,-41,8,SMOOTH_BRICK:1)
Block(7,-40,-4,COBBLESTONE:0)
Block(7,-40,-3,COBBLESTONE:0)
Block(7,-40,-2,SMOOTH_BRICK:1)
Block(7,-40,-1,COBBLESTONE:0)
Block(7,-40,0,SMOOTH_BRICK:2)
Block(7,-40,1,COBBLESTONE:0)
Block(7,-40,2,SMOOTH_BRICK:0)
Block(7,-40,3,STONE:5)
Block(7,-40,4,STONE:5)
Block(7,-40,5,SMOOTH_BRICK:2)
Block(7,-40,6,STONE:5)
Block(7,-40,7,STONE:5)
Block(7,-40,8,SMOOTH_BRICK:1)
Block(7,-39,-4,COBBLESTONE:0)
Block(7,-39,-3,COBBLESTONE:0)
Block(7,-39,-2,SMOOTH_BRICK:1)
Block(7,-39,-1,COBBLESTONE:0)
Block(7,-39,0,SMOOTH_BRICK:2)
Block(7,-39,1,COBBLESTONE:0)
Block(7,-39,2,SMOOTH_BRICK:0)
Block(7,-39,3,STONE:5)
Block(7,-39,4,STONE:5)
Block(7,-39,5,SMOOTH_BRICK:2)
Block(7,-39,6,STONE:5)
Block(7,-39,7,STONE:5)
Block(7,-39,8,SMOOTH_BRICK:1)
Block(7,-38,-4,COBBLESTONE:0)
Block(7,-38,-3,COBBLESTONE:0)
Block(7,-38,-2,SMOOTH_BRICK:1)
Block(7,-38,-1,COBBLESTONE:0)
Block(7,-38,0,SMOOTH_BRICK:2)
Block(7,-38,1,COBBLESTONE:0)
Block(7,-38,2,SMOOTH_BRICK:0)
Block(7,-38,3,STONE:5)
Block(7,-38,4,STONE:5)
Block(7,-38,5,SMOOTH_BRICK:2)
Block(7,-38,6,STONE:5)
Block(7,-38,7,STONE:5)
Block(7,-38,8,SMOOTH_BRICK:1)
Block(7,-37,-4,COBBLESTONE:0)
Block(7,-37,-3,COBBLESTONE:0)
Block(7,-37,-2,SMOOTH_BRICK:1)
Block(7,-37,-1,COBBLESTONE:0)
Block(7,-37,0,SMOOTH_BRICK:2)
Block(7,-37,1,COBBLESTONE:0)
Block(7,-37,2,SMOOTH_BRICK:0)
Block(7,-37,3,STONE:5)
Block(7,-37,4,STONE:5)
Block(7,-37,5,SMOOTH_BRICK:2)
Block(7,-37,6,STONE:5)
Block(7,-37,7,STONE:5)
Block(7,-37,8,SMOOTH_BRICK:1)
Block(7,-36,-4,COBBLESTONE:0)
Block(7,-36,-3,COBBLESTONE:0)
Block(7,-36,-2,SMOOTH_BRICK:1)
Block(7,-36,-1,COBBLESTONE:0)
Block(7,-36,0,SMOOTH_BRICK:2)
Block(7,-36,1,COBBLESTONE:0)
Block(7,-36,2,SMOOTH_BRICK:0)
Block(7,-36,3,STONE:5)
Block(7,-36,4,STONE:5)
Block(7,-36,5,SMOOTH_BRICK:2)
Block(7,-36,6,STONE:5)
Block(7,-36,7,STONE:5)
Block(7,-36,8,SMOOTH_BRICK:1)
Block(7,-35,-4,COBBLESTONE:0)
Block(7,-35,-3,COBBLESTONE:0)
Block(7,-35,-2,SMOOTH_BRICK:1)
Block(7,-35,-1,COBBLESTONE:0)
Block(7,-35,0,SMOOTH_BRICK:2)
Block(7,-35,1,COBBLESTONE:0)
Block(7,-35,2,SMOOTH_BRICK:0)
Block(7,-35,3,STONE:5)
Block(7,-35,4,STONE:5)
Block(7,-35,5,SMOOTH_BRICK:2)
Block(7,-35,6,STONE:5)
Block(7,-35,7,STONE:5)
Block(7,-35,8,SMOOTH_BRICK:1)
Block(7,-34,-4,COBBLESTONE:0)
Block(7,-34,-3,COBBLESTONE:0)
Block(7,-34,-2,SMOOTH_BRICK:1)
Block(7,-34,-1,COBBLESTONE:0)
Block(7,-34,0,SMOOTH_BRICK:2)
Block(7,-34,1,COBBLESTONE:0)
Block(7,-34,2,SMOOTH_BRICK:0)
Block(7,-34,3,STONE:5)
Block(7,-34,4,STONE:5)
Block(7,-34,5,SMOOTH_BRICK:2)
Block(7,-34,6,STONE:5)
Block(7,-34,7,STONE:5)
Block(7,-34,8,SMOOTH_BRICK:1)
Block(7,-33,-4,COBBLESTONE:0)
Block(7,-33,-3,COBBLESTONE:0)
Block(7,-33,-2,SMOOTH_BRICK:1)
Block(7,-33,-1,COBBLESTONE:0)
Block(7,-33,0,SMOOTH_BRICK:2)
Block(7,-33,1,COBBLESTONE:0)
Block(7,-33,2,SMOOTH_BRICK:0)
Block(7,-33,3,STONE:5)
Block(7,-33,4,STONE:5)
Block(7,-33,5,SMOOTH_BRICK:2)
Block(7,-33,6,STONE:5)
Block(7,-33,7,STONE:5)
Block(7,-33,8,SMOOTH_BRICK:1)
Block(7,-32,-4,COBBLESTONE:0)
Block(7,-32,-3,COBBLESTONE:0)
Block(7,-32,-2,SMOOTH_BRICK:1)
Block(7,-32,-1,COBBLESTONE:0)
Block(7,-32,0,SMOOTH_BRICK:2)
Block(7,-32,1,COBBLESTONE:0)
Block(7,-32,2,SMOOTH_BRICK:0)
Block(7,-32,3,STONE:5)
Block(7,-32,4,STONE:5)
Block(7,-32,5,SMOOTH_BRICK:2)
Block(7,-32,6,STONE:5)
Block(7,-32,7,STONE:5)
Block(7,-32,8,SMOOTH_BRICK:1)
Block(7,-31,-4,COBBLESTONE:0)
Block(7,-31,-3,COBBLESTONE:0)
Block(7,-31,-2,SMOOTH_BRICK:1)
Block(7,-31,-1,COBBLESTONE:0)
Block(7,-31,0,SMOOTH_BRICK:2)
Block(7,-31,1,COBBLESTONE:0)
Block(7,-31,2,SMOOTH_BRICK:0)
Block(7,-31,3,STONE:5)
Block(7,-31,4,STONE:5)
Block(7,-31,5,SMOOTH_BRICK:2)
Block(7,-31,6,STONE:5)
Block(7,-31,7,STONE:5)
Block(7,-31,8,SMOOTH_BRICK:1)
Block(7,-30,-4,COBBLESTONE:0)
Block(7,-30,-3,COBBLESTONE:0)
Block(7,-30,-2,SMOOTH_BRICK:1)
Block(7,-30,-1,COBBLESTONE:0)
Block(7,-30,0,SMOOTH_BRICK:2)
Block(7,-30,1,COBBLESTONE:0)
Block(7,-30,2,SMOOTH_BRICK:0)
Block(7,-30,3,STONE:5)
Block(7,-30,4,STONE:5)
Block(7,-30,5,SMOOTH_BRICK:2)
Block(7,-30,6,STONE:5)
Block(7,-30,7,STONE:5)
Block(7,-30,8,SMOOTH_BRICK:1)
Block(7,-29,-4,COBBLESTONE:0)
Block(7,-29,-3,COBBLESTONE:0)
Block(7,-29,-2,SMOOTH_BRICK:1)
Block(7,-29,-1,COBBLESTONE:0)
Block(7,-29,0,SMOOTH_BRICK:2)
Block(7,-29,1,COBBLESTONE:0)
Block(7,-29,2,SMOOTH_BRICK:0)
Block(7,-29,3,STONE:5)
Block(7,-29,4,STONE:5)
Block(7,-29,5,SMOOTH_BRICK:2)
Block(7,-29,6,STONE:5)
Block(7,-29,7,STONE:5)
Block(7,-29,8,SMOOTH_BRICK:1)
Block(7,-28,-4,COBBLESTONE:0)
Block(7,-28,-3,COBBLESTONE:0)
Block(7,-28,-2,SMOOTH_BRICK:1)
Block(7,-28,-1,COBBLESTONE:0)
Block(7,-28,0,SMOOTH_BRICK:2)
Block(7,-28,1,COBBLESTONE:0)
Block(7,-28,2,SMOOTH_BRICK:0)
Block(7,-28,3,STONE:5)
Block(7,-28,4,STONE:5)
Block(7,-28,5,SMOOTH_BRICK:2)
Block(7,-28,6,STONE:5)
Block(7,-28,7,STONE:5)
Block(7,-28,8,SMOOTH_BRICK:1)
Block(7,-27,-4,COBBLESTONE:0)
Block(7,-27,-3,COBBLESTONE:0)
Block(7,-27,-2,SMOOTH_BRICK:1)
Block(7,-27,-1,COBBLESTONE:0)
Block(7,-27,0,SMOOTH_BRICK:2)
Block(7,-27,1,COBBLESTONE:0)
Block(7,-27,2,SMOOTH_BRICK:0)
Block(7,-27,3,STONE:5)
Block(7,-27,4,STONE:5)
Block(7,-27,5,SMOOTH_BRICK:2)
Block(7,-27,6,STONE:5)
Block(7,-27,7,STONE:5)
Block(7,-27,8,SMOOTH_BRICK:1)
Block(7,-26,-4,COBBLESTONE:0)
Block(7,-26,-3,COBBLESTONE:0)
Block(7,-26,-2,SMOOTH_BRICK:1)
Block(7,-26,-1,COBBLESTONE:0)
Block(7,-26,0,SMOOTH_BRICK:2)
Block(7,-26,1,COBBLESTONE:0)
Block(7,-26,2,SMOOTH_BRICK:0)
Block(7,-26,3,STONE:5)
Block(7,-26,4,STONE:5)
Block(7,-26,5,SMOOTH_BRICK:2)
Block(7,-26,6,STONE:5)
Block(7,-26,7,STONE:5)
Block(7,-26,8,SMOOTH_BRICK:1)
Block(7,-25,-4,COBBLESTONE:0)
Block(7,-25,-3,COBBLESTONE:0)
Block(7,-25,-2,SMOOTH_BRICK:1)
Block(7,-25,-1,COBBLESTONE:0)
Block(7,-25,0,SMOOTH_BRICK:2)
Block(7,-25,1,COBBLESTONE:0)
Block(7,-25,2,SMOOTH_BRICK:0)
Block(7,-25,3,STONE:5)
Block(7,-25,4,STONE:5)
Block(7,-25,5,SMOOTH_BRICK:2)
Block(7,-25,6,STONE:5)
Block(7,-25,7,STONE:5)
Block(7,-25,8,SMOOTH_BRICK:1)
Block(7,-24,-4,COBBLESTONE:0)
Block(7,-24,-3,COBBLESTONE:0)
Block(7,-24,-2,SMOOTH_BRICK:1)
Block(7,-24,-1,COBBLESTONE:0)
Block(7,-24,0,SMOOTH_BRICK:2)
Block(7,-24,1,COBBLESTONE:0)
Block(7,-24,2,SMOOTH_BRICK:0)
Block(7,-24,3,STONE:5)
Block(7,-24,4,STONE:5)
Block(7,-24,5,SMOOTH_BRICK:2)
Block(7,-24,6,STONE:5)
Block(7,-24,7,STONE:5)
Block(7,-24,8,SMOOTH_BRICK:1)
Block(7,-23,-4,COBBLESTONE:0)
Block(7,-23,-3,COBBLESTONE:0)
Block(7,-23,-2,SMOOTH_BRICK:1)
Block(7,-23,-1,COBBLESTONE:0)
Block(7,-23,0,SMOOTH_BRICK:2)
Block(7,-23,1,COBBLESTONE:0)
Block(7,-23,2,SMOOTH_BRICK:0)
Block(7,-23,3,STONE:5)
Block(7,-23,4,STONE:5)
Block(7,-23,5,SMOOTH_BRICK:2)
Block(7,-23,6,STONE:5)
Block(7,-23,7,STONE:5)
Block(7,-23,8,SMOOTH_BRICK:1)
Block(7,-22,-4,COBBLESTONE:0)
Block(7,-22,-3,COBBLESTONE:0)
Block(7,-22,-2,SMOOTH_BRICK:1)
Block(7,-22,-1,COBBLESTONE:0)
Block(7,-22,0,SMOOTH_BRICK:2)
Block(7,-22,1,COBBLESTONE:0)
Block(7,-22,2,SMOOTH_BRICK:0)
Block(7,-22,3,STONE:5)
Block(7,-22,4,STONE:5)
Block(7,-22,5,SMOOTH_BRICK:2)
Block(7,-22,6,STONE:5)
Block(7,-22,7,STONE:5)
Block(7,-22,8,SMOOTH_BRICK:1)
Block(7,-21,-4,COBBLESTONE:0)
Block(7,-21,-3,COBBLESTONE:0)
Block(7,-21,-2,SMOOTH_BRICK:1)
Block(7,-21,-1,COBBLESTONE:0)
Block(7,-21,0,SMOOTH_BRICK:2)
Block(7,-21,1,COBBLESTONE:0)
Block(7,-21,2,SMOOTH_BRICK:0)
Block(7,-21,3,STONE:5)
Block(7,-21,4,STONE:5)
Block(7,-21,5,SMOOTH_BRICK:2)
Block(7,-21,6,STONE:5)
Block(7,-21,7,STONE:5)
Block(7,-21,8,SMOOTH_BRICK:1)
Block(7,-20,-4,COBBLESTONE:0)
Block(7,-20,-3,COBBLESTONE:0)
Block(7,-20,-2,SMOOTH_BRICK:1)
Block(7,-20,-1,COBBLESTONE:0)
Block(7,-20,0,SMOOTH_BRICK:2)
Block(7,-20,1,COBBLESTONE:0)
Block(7,-20,2,SMOOTH_BRICK:0)
Block(7,-20,3,STONE:5)
Block(7,-20,4,STONE:5)
Block(7,-20,5,SMOOTH_BRICK:2)
Block(7,-20,6,STONE:5)
Block(7,-20,7,STONE:5)
Block(7,-20,8,SMOOTH_BRICK:1)
Block(7,-19,-4,COBBLESTONE:0)
Block(7,-19,-3,STONE:5)
Block(7,-19,-2,STONE:5)
Block(7,-19,-1,STAINED_CLAY:9)
Block(7,-19,0,STONE:5)
Block(7,-19,1,COBBLESTONE:0)
Block(7,-19,2,SMOOTH_BRICK:0)
Block(7,-19,3,COBBLESTONE:0)
Block(7,-19,4,STONE:5)
Block(7,-19,5,STONE:5)
Block(7,-19,6,STONE:5)
Block(7,-19,7,STONE:5)
Block(7,-19,8,SMOOTH_BRICK:1)
Block(7,-18,-4,COBBLESTONE:0)
Block(7,-18,-3,STAINED_CLAY:9)
Block(7,-18,-2,COBBLESTONE:0)
Block(7,-18,-1,COBBLESTONE:0)
Block(7,-18,0,COBBLESTONE:0)
Block(7,-18,1,STONE:5)
Block(7,-18,2,STAINED_CLAY:9)
Block(7,-18,3,STONE:5)
Block(7,-18,4,STAINED_CLAY:9)
Block(7,-18,5,SMOOTH_BRICK:0)
Block(7,-18,6,SMOOTH_BRICK:0)
Block(7,-18,7,SMOOTH_BRICK:0)
Block(7,-18,8,SMOOTH_BRICK:2)
Block(7,-17,-4,COBBLESTONE:0)
Block(7,-17,-3,STONE:5)
Block(7,-17,-2,STONE:5)
Block(7,-17,-1,COBBLESTONE:0)
Block(7,-17,0,SMOOTH_BRICK:0)
Block(7,-17,1,SMOOTH_BRICK:0)
Block(7,-17,2,STAINED_CLAY:9)
Block(7,-17,3,STONE:5)
Block(7,-17,4,COBBLESTONE:0)
Block(7,-17,5,SMOOTH_BRICK:0)
Block(7,-17,6,SMOOTH_BRICK:2)
Block(7,-17,7,COBBLESTONE:0)
Block(7,-17,8,STONE:5)
Block(7,-16,-4,STONE:5)
Block(7,-16,-3,COBBLESTONE:0)
Block(7,-16,-2,COBBLESTONE:0)
Block(7,-16,-1,STONE:5)
Block(7,-16,0,STONE:5)
Block(7,-16,1,STONE:5)
Block(7,-16,2,COBBLESTONE:0)
Block(7,-16,3,STONE:5)
Block(7,-16,4,STONE:5)
Block(7,-16,5,STONE:5)
Block(7,-16,6,STONE:5)
Block(7,-16,7,STONE:5)
Block(7,-16,8,SMOOTH_BRICK:2)
Block(7,-15,-4,COBBLESTONE:0)
Block(7,-15,-3,COBBLESTONE:0)
Block(7,-15,-2,STONE:5)
Block(7,-15,-1,COBBLESTONE:0)
Block(7,-15,0,STAINED_CLAY:9)
Block(7,-15,1,COBBLESTONE:0)
Block(7,-15,2,STONE:5)
Block(7,-15,3,COBBLESTONE:0)
Block(7,-15,4,SMOOTH_BRICK:2)
Block(7,-15,5,STONE:5)
Block(7,-15,6,SMOOTH_BRICK:2)
Block(7,-15,7,SMOOTH_BRICK:0)
Block(7,-15,8,STONE:5)
Block(7,-14,-4,STONE:5)
Block(7,-14,-3,SMOOTH_BRICK:2)
Block(7,-14,-2,STAINED_CLAY:9)
Block(7,-14,-1,STAINED_CLAY:9)
Block(7,-14,0,SMOOTH_BRICK:1)
Block(7,-14,1,COBBLESTONE:0)
Block(7,-14,2,SMOOTH_BRICK:0)
Block(7,-14,3,STONE:5)
Block(7,-14,4,COBBLESTONE:0)
Block(7,-14,5,STAINED_CLAY:9)
Block(7,-14,6,SMOOTH_BRICK:1)
Block(7,-14,7,SMOOTH_BRICK:0)
Block(7,-14,8,STONE:5)
Block(7,-13,-4,COBBLESTONE:0)
Block(7,-13,-3,STONE:5)
Block(7,-13,-2,STONE:5)
Block(7,-13,-1,COBBLESTONE:0)
Block(7,-13,0,SMOOTH_BRICK:2)
Block(7,-13,1,SMOOTH_BRICK:2)
Block(7,-13,2,STONE:5)
Block(7,-13,3,STONE:5)
Block(7,-13,4,STONE:5)
Block(7,-13,5,STONE:5)
Block(7,-13,6,COBBLESTONE:0)
Block(7,-13,7,SMOOTH_BRICK:2)
Block(7,-13,8,SMOOTH_BRICK:2)
Block(7,-12,-4,STONE:5)
Block(7,-12,-3,STONE:5)
Block(7,-12,-2,COBBLESTONE:0)
Block(7,-12,-1,SMOOTH_BRICK:0)
Block(7,-12,0,STONE:5)
Block(7,-12,1,STONE:5)
Block(7,-12,2,COBBLESTONE:0)
Block(7,-12,3,STONE:5)
Block(7,-12,4,STONE:5)
Block(7,-12,5,SMOOTH_BRICK:2)
Block(7,-12,6,SMOOTH_BRICK:0)
Block(7,-12,7,COBBLESTONE:0)
Block(7,-12,8,STONE:5)
Block(7,-11,-4,STAINED_CLAY:9)
Block(7,-11,-3,STONE:5)
Block(7,-11,-2,STONE:5)
Block(7,-11,-1,STAINED_CLAY:9)
Block(7,-11,0,STONE:5)
Block(7,-11,1,STONE:5)
Block(7,-11,2,SMOOTH_BRICK:0)
Block(7,-11,3,STONE:5)
Block(7,-11,4,SMOOTH_BRICK:2)
Block(7,-11,5,SMOOTH_BRICK:0)
Block(7,-11,6,SMOOTH_BRICK:2)
Block(7,-11,7,COBBLESTONE:0)
Block(7,-11,8,SMOOTH_BRICK:0)
Block(7,-10,-4,SMOOTH_BRICK:1)
Block(7,-10,-3,STONE:5)
Block(7,-10,-2,COBBLESTONE:0)
Block(7,-10,-1,COBBLESTONE:0)
Block(7,-10,0,STONE:5)
Block(7,-10,1,SMOOTH_BRICK:0)
Block(7,-10,2,STONE:5)
Block(7,-10,3,STONE:5)
Block(7,-10,4,SMOOTH_BRICK:1)
Block(7,-10,5,STONE:5)
Block(7,-10,6,SMOOTH_BRICK:2)
Block(7,-10,7,COBBLESTONE:0)
Block(7,-10,8,SMOOTH_BRICK:0)
Block(7,-9,-4,COBBLESTONE_STAIRS:0)
Block(7,-9,-3,COBBLESTONE_STAIRS:2)
Block(7,-9,-2,LOG:0)
Block(7,-9,-1,STONE:6)
Block(7,-9,0,STONE:6)
Block(7,-9,1,STONE:6)
Block(7,-9,2,STONE:6)
Block(7,-9,3,STONE:6)
Block(7,-9,4,STONE:6)
Block(7,-9,5,STONE:6)
Block(7,-9,6,LOG:0)
Block(7,-9,7,COBBLESTONE_STAIRS:0)
Block(7,-9,8,COBBLESTONE_STAIRS:3)
Block(7,-8,-2,LOG:0)
Block(7,-8,-1,STONE:5)
Block(7,-8,0,COBBLESTONE:0)
Block(7,-8,1,STONE:5)
Block(7,-8,2,STONE:5)
Block(7,-8,3,SMOOTH_BRICK:0)
Block(7,-8,4,STONE:5)
Block(7,-8,5,SMOOTH_BRICK:2)
Block(7,-8,6,LOG:0)
Block(7,-7,-2,LOG:0)
Block(7,-7,-1,COBBLESTONE:0)
Block(7,-7,0,STONE:5)
Block(7,-7,1,STONE:5)
Block(7,-7,2,STONE:5)
Block(7,-7,3,SMOOTH_BRICK:2)
Block(7,-7,4,STONE:5)
Block(7,-7,5,SMOOTH_BRICK:1)
Block(7,-7,6,LOG:0)
Block(7,-6,-2,LOG:0)
Block(7,-6,-1,COBBLESTONE:0)
Block(7,-6,0,STONE:5)
Block(7,-6,1,STONE:5)
Block(7,-6,2,SMOOTH_BRICK:1)
Block(7,-6,3,SMOOTH_BRICK:2)
Block(7,-6,4,SMOOTH_BRICK:0)
Block(7,-6,5,STONE:5)
Block(7,-6,6,LOG:0)
Block(7,-5,-2,LOG:0)
Block(7,-5,-1,COBBLESTONE:0)
Block(7,-5,0,COBBLESTONE:0)
Block(7,-5,1,STONE:5)
Block(7,-5,2,COBBLESTONE:0)
Block(7,-5,3,SMOOTH_BRICK:2)
Block(7,-5,4,STONE:5)
Block(7,-5,5,COBBLESTONE:0)
Block(7,-5,6,LOG:0)
Block(7,-4,-2,LOG:0)
Block(7,-4,-1,STONE:6)
Block(7,-4,0,STONE:6)
Block(7,-4,1,STONE:6)
Block(7,-4,2,STONE:6)
Block(7,-4,3,STONE:6)
Block(7,-4,4,STONE:6)
Block(7,-4,5,STONE:6)
Block(7,-4,6,LOG:0)
Block(7,-3,-2,LOG:0)
Block(7,-3,-1,STONE:6)
Block(7,-3,0,STONE:6)
Block(7,-3,1,STONE:6)
Block(7,-3,2,STONE:6)
Block(7,-3,3,STONE:6)
Block(7,-3,4,STONE:6)
Block(7,-3,5,STONE:6)
Block(7,-3,6,LOG:0)
Block(7,-2,-2,LOG:0)
Block(7,-2,-1,STONE:6)
Block(7,-2,0,STONE:6)
Block(7,-2,1,STONE:6)
Block(7,-2,2,STONE:6)
Block(7,-2,3,STONE:6)
Block(7,-2,4,STONE:6)
Block(7,-2,5,STONE:6)
Block(7,-2,6,LOG:0)
Block(7,-1,-2,LOG:0)
Block(7,-1,-1,STONE:6)
Block(7,-1,0,STONE:6)
Block(7,-1,1,STONE:6)
Block(7,-1,2,STONE:6)
Block(7,-1,3,STONE:6)
Block(7,-1,4,STONE:6)
Block(7,-1,5,STONE:6)
Block(7,-1,6,LOG:0)
Block(7,0,-2,LOG:0)
Block(7,0,-1,STONE:6)
Block(7,0,0,STONE:6)
Block(7,0,1,AIR:0)
Block(7,0,2,AIR:0)
Block(7,0,3,AIR:0)
Block(7,0,4,STONE:6)
Block(7,0,5,STONE:6)
Block(7,0,6,LOG:0)
Block(7,1,-2,LOG:0)
Block(7,1,-1,STONE:6)
Block(7,1,0,STONE:6)
Block(7,1,1,AIR:0)
Block(7,1,2,AIR:0)
Block(7,1,3,AIR:0)
Block(7,1,4,STONE:6)
Block(7,1,5,STONE:6)
Block(7,1,6,LOG:0)
Block(7,2,-2,LOG:0)
Block(7,2,-1,STONE:6)
Block(7,2,0,STONE:6)
Block(7,2,1,AIR:0)
Block(7,2,2,AIR:0)
Block(7,2,3,AIR:0)
Block(7,2,4,STONE:6)
Block(7,2,5,STONE:6)
Block(7,2,6,LOG:0)
Block(7,3,-2,LOG:0)
Block(7,3,-1,STONE:6)
Block(7,3,0,STONE:6)
Block(7,3,1,AIR:0)
Block(7,3,2,AIR:0)
Block(7,3,3,AIR:0)
Block(7,3,4,STONE:6)
Block(7,3,5,STONE:6)
Block(7,3,6,LOG:0)
Block(7,4,-2,LOG:0)
Block(7,4,-1,STONE:6)
Block(7,4,0,STONE:6)
Block(7,4,1,AIR:0)
Block(7,4,2,AIR:0)
Block(7,4,3,AIR:0)
Block(7,4,4,STONE:6)
Block(7,4,5,STONE:6)
Block(7,4,6,LOG:0)
Block(7,5,-2,LOG:0)
Block(7,5,-1,SMOOTH_BRICK:0)
Block(7,5,0,SMOOTH_BRICK:0)
Block(7,5,1,AIR:0)
Block(7,5,2,AIR:0)
Block(7,5,3,AIR:0)
Block(7,5,4,SMOOTH_BRICK:0)
Block(7,5,5,SMOOTH_BRICK:0)
Block(7,5,6,LOG:0)
Block(7,6,-2,LOG:0)
Block(7,6,-1,SMOOTH_BRICK:0)
Block(7,6,0,SMOOTH_BRICK:0)
Block(7,6,1,AIR:0)
Block(7,6,2,AIR:0)
Block(7,6,3,AIR:0)
Block(7,6,4,SMOOTH_BRICK:0)
Block(7,6,5,SMOOTH_BRICK:0)
Block(7,6,6,LOG:0)
Block(7,7,-2,LOG:0)
Block(7,7,-1,SMOOTH_STAIRS:0)
Block(7,7,0,SMOOTH_STAIRS:0)
Block(7,7,1,LOG:4)
Block(7,7,2,WOOD_STEP:13)
Block(7,7,3,LOG:4)
Block(7,7,4,SMOOTH_STAIRS:0)
Block(7,7,5,SMOOTH_STAIRS:0)
Block(7,7,6,LOG:0)
Block(7,8,-2,STEP:0)
Block(7,8,-1,AIR:0)
Block(7,8,0,AIR:0)
Block(7,8,1,LOG:0)
Block(7,8,2,SMOOTH_BRICK:0)
Block(7,8,3,LOG:0)
Block(7,8,4,AIR:0)
Block(7,8,5,AIR:0)
Block(7,8,6,STEP:0)
Block(7,9,-2,AIR:0)
Block(7,9,-1,AIR:0)
Block(7,9,0,AIR:0)
Block(7,9,1,LOG:0)
Block(7,9,2,SMOOTH_BRICK:0)
Block(7,9,3,LOG:0)
Block(7,9,4,AIR:0)
Block(7,9,5,AIR:0)
Block(7,9,6,AIR:0)
Block(7,10,-2,AIR:0)
Block(7,10,-1,AIR:0)
Block(7,10,0,AIR:0)
Block(7,10,1,LOG:0)
Block(7,10,2,SMOOTH_BRICK:0)
Block(7,10,3,LOG:0)
Block(7,10,4,AIR:0)
Block(7,10,5,AIR:0)
Block(7,10,6,AIR:0)
Block(7,11,-2,AIR:0)
Block(7,11,-1,AIR:0)
Block(7,11,0,AIR:0)
Block(7,11,1,LOG:0)
Block(7,11,2,SMOOTH_BRICK:0)
Block(7,11,3,LOG:0)
Block(7,11,4,AIR:0)
Block(7,11,5,AIR:0)
Block(7,11,6,AIR:0)
Block(7,12,-2,AIR:0)
Block(7,12,-1,AIR:0)
Block(7,12,0,AIR:0)
Block(7,12,1,LOG:0)
Block(7,12,2,SMOOTH_BRICK:0)
Block(7,12,3,LOG:0)
Block(7,12,4,AIR:0)
Block(7,12,5,AIR:0)
Block(7,12,6,AIR:0)
Block(7,13,-2,AIR:0)
Block(7,13,-1,AIR:0)
Block(7,13,0,SMOOTH_STAIRS:4)
Block(7,13,1,LOG:0)
Block(7,13,2,SMOOTH_BRICK:0)
Block(7,13,3,LOG:0)
Block(7,13,4,SMOOTH_STAIRS:4)
Block(7,13,5,AIR:0)
Block(7,13,6,AIR:0)
Block(7,14,-2,AIR:0)
Block(7,14,-1,AIR:0)
Block(7,14,0,STEP:0)
Block(7,14,1,SMOOTH_STAIRS:0)
Block(7,14,2,SMOOTH_BRICK:0)
Block(7,14,3,SMOOTH_STAIRS:0)
Block(7,14,4,STEP:0)
Block(7,14,5,AIR:0)
Block(7,14,6,AIR:0)
Block(7,15,-2,AIR:0)
Block(7,15,-1,AIR:0)
Block(7,15,0,AIR:0)
Block(7,15,1,AIR:0)
Block(7,15,2,SMOOTH_BRICK:0)
Block(7,15,3,AIR:0)
Block(7,15,4,AIR:0)
Block(7,15,5,AIR:0)
Block(7,15,6,AIR:0)
Block(7,16,-2,AIR:0)
Block(7,16,-1,AIR:0)
Block(7,16,0,AIR:0)
Block(7,16,1,AIR:0)
Block(7,16,2,SMOOTH_BRICK:0)
Block(7,16,3,AIR:0)
Block(7,16,4,AIR:0)
Block(7,16,5,AIR:0)
Block(7,16,6,AIR:0)
Block(7,17,-2,AIR:0)
Block(7,17,-1,AIR:0)
Block(7,17,0,AIR:0)
Block(7,17,1,SMOOTH_STAIRS:4)
Block(7,17,2,SMOOTH_BRICK:0)
Block(7,17,3,SMOOTH_STAIRS:4)
Block(7,17,4,AIR:0)
Block(7,17,5,AIR:0)
Block(7,17,6,AIR:0)
Block(7,18,-2,AIR:0)
Block(7,18,-1,AIR:0)
Block(7,18,0,SMOOTH_STAIRS:6)
Block(7,18,1,LOG:4)
Block(7,18,2,SMOOTH_BRICK:0)
Block(7,18,3,LOG:4)
Block(7,18,4,SMOOTH_STAIRS:7)
Block(7,18,5,AIR:0)
Block(7,18,6,AIR:0)
Block(7,19,-2,AIR:0)
Block(7,19,-1,AIR:0)
Block(7,19,0,STONE:6)
Block(7,19,1,LOG:0)
Block(7,19,2,STEP:5)
Block(7,19,3,LOG:0)
Block(7,19,4,STONE:6)
Block(7,19,5,AIR:0)
Block(7,19,6,AIR:0)
Block(7,20,-2,AIR:0)
Block(7,20,-1,AIR:0)
Block(7,20,0,SMOOTH_BRICK:0)
Block(7,20,1,LOG:0)
Block(7,20,2,AIR:0)
Block(7,20,3,LOG:0)
Block(7,20,4,SMOOTH_BRICK:0)
Block(7,20,5,AIR:0)
Block(7,20,6,AIR:0)
Block(7,21,-2,AIR:0)
Block(7,21,-1,AIR:0)
Block(7,21,0,AIR:0)
Block(7,21,1,STEP:0)
Block(7,21,2,AIR:0)
Block(7,21,3,STEP:0)
Block(7,21,4,AIR:0)
Block(7,21,5,AIR:0)
Block(7,21,6,AIR:0)
Block(7,22,-2,AIR:0)
Block(7,22,-1,AIR:0)
Block(7,22,0,AIR:0)
Block(7,22,1,AIR:0)
Block(7,22,2,AIR:0)
Block(7,22,3,AIR:0)
Block(7,22,4,AIR:0)
Block(7,22,5,AIR:0)
Block(7,22,6,AIR:0)
Block(7,23,-2,AIR:0)
Block(7,23,-1,AIR:0)
Block(7,23,0,AIR:0)
Block(7,23,1,AIR:0)
Block(7,23,2,AIR:0)
Block(7,23,3,AIR:0)
Block(7,23,4,AIR:0)
Block(7,23,5,AIR:0)
Block(7,23,6,AIR:0)
Block(7,24,-2,AIR:0)
Block(7,24,-1,AIR:0)
Block(7,24,0,AIR:0)
Block(7,24,1,AIR:0)
Block(7,24,2,AIR:0)
Block(7,24,3,AIR:0)
Block(7,24,4,AIR:0)
Block(7,24,5,AIR:0)
Block(7,24,6,AIR:0)
Block(7,25,-2,AIR:0)
Block(7,25,-1,AIR:0)
Block(7,25,0,AIR:0)
Block(7,25,1,AIR:0)
Block(7,25,2,AIR:0)
Block(7,25,3,AIR:0)
Block(7,25,4,AIR:0)
Block(7,25,5,AIR:0)
Block(7,25,6,AIR:0)
Block(7,26,-2,AIR:0)
Block(7,26,-1,AIR:0)
Block(7,26,0,AIR:0)
Block(7,26,1,AIR:0)
Block(7,26,2,AIR:0)
Block(7,26,3,AIR:0)
Block(7,26,4,AIR:0)
Block(7,26,5,AIR:0)
Block(7,26,6,AIR:0)
Block(7,27,-2,AIR:0)
Block(7,27,-1,AIR:0)
Block(7,27,0,AIR:0)
Block(7,27,1,AIR:0)
Block(7,27,2,AIR:0)
Block(7,27,3,AIR:0)
Block(7,27,4,AIR:0)
Block(7,27,5,AIR:0)
Block(7,27,6,AIR:0)
Block(7,28,-2,AIR:0)
Block(7,28,-1,AIR:0)
Block(7,28,0,AIR:0)
Block(7,28,1,AIR:0)
Block(7,28,2,AIR:0)
Block(7,28,3,AIR:0)
Block(7,28,4,AIR:0)
Block(7,28,5,AIR:0)
Block(7,28,6,AIR:0)
Block(7,29,-2,AIR:0)
Block(7,29,-1,AIR:0)
Block(7,29,0,AIR:0)
Block(7,29,1,AIR:0)
Block(7,29,2,AIR:0)
Block(7,29,3,AIR:0)
Block(7,29,4,AIR:0)
Block(7,29,5,AIR:0)
Block(7,29,6,AIR:0)
Block(7,30,-2,AIR:0)
Block(7,30,-1,AIR:0)
Block(7,30,0,AIR:0)
Block(7,30,1,AIR:0)
Block(7,30,2,AIR:0)
Block(7,30,3,AIR:0)
Block(7,30,4,AIR:0)
Block(7,30,5,AIR:0)
Block(7,30,6,AIR:0)
Block(7,31,-2,AIR:0)
Block(7,31,-1,AIR:0)
Block(7,31,0,AIR:0)
Block(7,31,1,AIR:0)
Block(7,31,2,AIR:0)
Block(7,31,3,AIR:0)
Block(7,31,4,AIR:0)
Block(7,31,5,AIR:0)
Block(7,31,6,AIR:0)
Block(7,32,-2,AIR:0)
Block(7,32,-1,AIR:0)
Block(7,32,0,AIR:0)
Block(7,32,1,AIR:0)
Block(7,32,2,AIR:0)
Block(7,32,3,AIR:0)
Block(7,32,4,AIR:0)
Block(7,32,5,AIR:0)
Block(7,32,6,AIR:0)
Block(7,33,-2,AIR:0)
Block(7,33,-1,AIR:0)
Block(7,33,0,AIR:0)
Block(7,33,1,AIR:0)
Block(7,33,2,AIR:0)
Block(7,33,3,AIR:0)
Block(7,33,4,AIR:0)
Block(7,33,5,AIR:0)
Block(7,33,6,AIR:0)
Block(7,34,-2,AIR:0)
Block(7,34,-1,AIR:0)
Block(7,34,0,AIR:0)
Block(7,34,1,AIR:0)
Block(7,34,2,AIR:0)
Block(7,34,3,AIR:0)
Block(7,34,4,AIR:0)
Block(7,34,5,AIR:0)
Block(7,34,6,AIR:0)
Block(7,35,-2,AIR:0)
Block(7,35,-1,AIR:0)
Block(7,35,0,AIR:0)
Block(7,35,1,AIR:0)
Block(7,35,2,AIR:0)
Block(7,35,3,AIR:0)
Block(7,35,4,AIR:0)
Block(7,35,5,AIR:0)
Block(7,35,6,AIR:0)
Block(7,36,-2,AIR:0)
Block(7,36,-1,AIR:0)
Block(7,36,0,AIR:0)
Block(7,36,1,AIR:0)
Block(7,36,2,AIR:0)
Block(7,36,3,AIR:0)
Block(7,36,4,AIR:0)
Block(7,36,5,AIR:0)
Block(7,36,6,AIR:0)
Block(7,37,-2,AIR:0)
Block(7,37,-1,AIR:0)
Block(7,37,0,AIR:0)
Block(7,37,1,AIR:0)
Block(7,37,2,AIR:0)
Block(7,37,3,AIR:0)
Block(7,37,4,AIR:0)
Block(7,37,5,AIR:0)
Block(7,37,6,AIR:0)
Block(7,38,-2,AIR:0)
Block(7,38,-1,AIR:0)
Block(7,38,0,AIR:0)
Block(7,38,1,AIR:0)
Block(7,38,2,AIR:0)
Block(7,38,3,AIR:0)
Block(7,38,4,AIR:0)
Block(7,38,5,AIR:0)
Block(7,38,6,AIR:0)
Block(7,39,-2,AIR:0)
Block(7,39,-1,AIR:0)
Block(7,39,0,AIR:0)
Block(7,39,1,AIR:0)
Block(7,39,2,AIR:0)
Block(7,39,3,AIR:0)
Block(7,39,4,AIR:0)
Block(7,39,5,AIR:0)
Block(7,39,6,AIR:0)
Block(7,40,-2,AIR:0)
Block(7,40,-1,AIR:0)
Block(7,40,0,AIR:0)
Block(7,40,1,AIR:0)
Block(7,40,2,AIR:0)
Block(7,40,3,AIR:0)
Block(7,40,4,AIR:0)
Block(7,40,5,AIR:0)
Block(7,40,6,AIR:0)
Block(7,41,-2,AIR:0)
Block(7,41,-1,AIR:0)
Block(7,41,0,AIR:0)
Block(7,41,1,AIR:0)
Block(7,41,2,AIR:0)
Block(7,41,3,AIR:0)
Block(7,41,4,AIR:0)
Block(7,41,5,AIR:0)
Block(7,41,6,AIR:0)
Block(7,42,-2,AIR:0)
Block(7,42,-1,AIR:0)
Block(7,42,0,AIR:0)
Block(7,42,1,AIR:0)
Block(7,42,2,AIR:0)
Block(7,42,3,AIR:0)
Block(7,42,4,AIR:0)
Block(7,42,5,AIR:0)
Block(7,42,6,AIR:0)
Block(7,43,-2,AIR:0)
Block(7,43,-1,AIR:0)
Block(7,43,0,AIR:0)
Block(7,43,1,AIR:0)
Block(7,43,2,AIR:0)
Block(7,43,3,AIR:0)
Block(7,43,4,AIR:0)
Block(7,43,5,AIR:0)
Block(7,43,6,AIR:0)
Block(7,44,-2,AIR:0)
Block(7,44,-1,AIR:0)
Block(7,44,0,AIR:0)
Block(7,44,1,AIR:0)
Block(7,44,2,AIR:0)
Block(7,44,3,AIR:0)
Block(7,44,4,AIR:0)
Block(7,44,5,AIR:0)
Block(7,44,6,AIR:0)
Block(7,45,-2,AIR:0)
Block(7,45,-1,AIR:0)
Block(7,45,0,AIR:0)
Block(7,45,1,AIR:0)
Block(7,45,2,AIR:0)
Block(7,45,3,AIR:0)
Block(7,45,4,AIR:0)
Block(7,45,5,AIR:0)
Block(7,45,6,AIR:0)
Block(7,46,-2,AIR:0)
Block(7,46,-1,AIR:0)
Block(7,46,0,AIR:0)
Block(7,46,1,AIR:0)
Block(7,46,2,AIR:0)
Block(7,46,3,AIR:0)
Block(7,46,4,AIR:0)
Block(7,46,5,AIR:0)
Block(7,46,6,AIR:0)
Block(7,47,-2,AIR:0)
Block(7,47,-1,AIR:0)
Block(7,47,0,AIR:0)
Block(7,47,1,AIR:0)
Block(7,47,2,AIR:0)
Block(7,47,3,AIR:0)
Block(7,47,4,AIR:0)
Block(7,47,5,AIR:0)
Block(7,47,6,AIR:0)
Block(7,48,-2,AIR:0)
Block(7,48,-1,AIR:0)
Block(7,48,0,AIR:0)
Block(7,48,1,AIR:0)
Block(7,48,2,AIR:0)
Block(7,48,3,AIR:0)
Block(7,48,4,AIR:0)
Block(7,48,5,AIR:0)
Block(7,48,6,AIR:0)
Block(7,49,-2,AIR:0)
Block(7,49,-1,AIR:0)
Block(7,49,0,AIR:0)
Block(7,49,1,AIR:0)
Block(7,49,2,AIR:0)
Block(7,49,3,AIR:0)
Block(7,49,4,AIR:0)
Block(7,49,5,AIR:0)
Block(7,49,6,AIR:0)
Block(7,50,-2,AIR:0)
Block(7,50,-1,AIR:0)
Block(7,50,0,AIR:0)
Block(7,50,1,AIR:0)
Block(7,50,2,AIR:0)
Block(7,50,3,AIR:0)
Block(7,50,4,AIR:0)
Block(7,50,5,AIR:0)
Block(7,50,6,AIR:0)
Block(7,51,-2,AIR:0)
Block(7,51,-1,AIR:0)
Block(7,51,0,AIR:0)
Block(7,51,1,AIR:0)
Block(7,51,2,AIR:0)
Block(7,51,3,AIR:0)
Block(7,51,4,AIR:0)
Block(7,51,5,AIR:0)
Block(7,51,6,AIR:0)
Block(7,52,-2,AIR:0)
Block(7,52,-1,AIR:0)
Block(7,52,0,AIR:0)
Block(7,52,1,AIR:0)
Block(7,52,2,AIR:0)
Block(7,52,3,AIR:0)
Block(7,52,4,AIR:0)
Block(7,52,5,AIR:0)
Block(7,52,6,AIR:0)
Block(7,53,-2,AIR:0)
Block(7,53,-1,AIR:0)
Block(7,53,0,AIR:0)
Block(7,53,1,AIR:0)
Block(7,53,2,AIR:0)
Block(7,53,3,AIR:0)
Block(7,53,4,AIR:0)
Block(7,53,5,AIR:0)
Block(7,53,6,AIR:0)
Block(7,54,-2,AIR:0)
Block(7,54,-1,AIR:0)
Block(7,54,0,AIR:0)
Block(7,54,1,AIR:0)
Block(7,54,2,AIR:0)
Block(7,54,3,AIR:0)
Block(7,54,4,AIR:0)
Block(7,54,5,AIR:0)
Block(7,54,6,AIR:0)
Block(7,55,-2,AIR:0)
Block(7,55,-1,AIR:0)
Block(7,55,0,AIR:0)
Block(7,55,1,AIR:0)
Block(7,55,2,AIR:0)
Block(7,55,3,AIR:0)
Block(7,55,4,AIR:0)
Block(7,55,5,AIR:0)
Block(7,55,6,AIR:0)
Block(7,56,-2,AIR:0)
Block(7,56,-1,AIR:0)
Block(7,56,0,AIR:0)
Block(7,56,1,AIR:0)
Block(7,56,2,AIR:0)
Block(7,56,3,AIR:0)
Block(7,56,4,AIR:0)
Block(7,56,5,AIR:0)
Block(7,56,6,AIR:0)
Block(7,57,-2,AIR:0)
Block(7,57,-1,AIR:0)
Block(7,57,0,AIR:0)
Block(7,57,1,AIR:0)
Block(7,57,2,AIR:0)
Block(7,57,3,AIR:0)
Block(7,57,4,AIR:0)
Block(7,57,5,AIR:0)
Block(7,57,6,AIR:0)
Block(7,58,-2,AIR:0)
Block(7,58,-1,AIR:0)
Block(7,58,0,AIR:0)
Block(7,58,1,AIR:0)
Block(7,58,2,AIR:0)
Block(7,58,3,AIR:0)
Block(7,58,4,AIR:0)
Block(7,58,5,AIR:0)
Block(7,58,6,AIR:0)
Block(7,59,-2,AIR:0)
Block(7,59,-1,AIR:0)
Block(7,59,0,AIR:0)
Block(7,59,1,AIR:0)
Block(7,59,2,AIR:0)
Block(7,59,3,AIR:0)
Block(7,59,4,AIR:0)
Block(7,59,5,AIR:0)
Block(7,59,6,AIR:0)
Block(7,60,-2,AIR:0)
Block(7,60,-1,AIR:0)
Block(7,60,0,AIR:0)
Block(7,60,1,AIR:0)
Block(7,60,2,AIR:0)
Block(7,60,3,AIR:0)
Block(7,60,4,AIR:0)
Block(7,60,5,AIR:0)
Block(7,60,6,AIR:0)
Block(7,61,-2,AIR:0)
Block(7,61,-1,AIR:0)
Block(7,61,0,AIR:0)
Block(7,61,1,AIR:0)
Block(7,61,2,AIR:0)
Block(7,61,3,AIR:0)
Block(7,61,4,AIR:0)
Block(7,61,5,AIR:0)
Block(7,61,6,AIR:0)
Block(7,62,-2,AIR:0)
Block(7,62,-1,AIR:0)
Block(7,62,0,AIR:0)
Block(7,62,1,AIR:0)
Block(7,62,2,AIR:0)
Block(7,62,3,AIR:0)
Block(7,62,4,AIR:0)
Block(7,62,5,AIR:0)
Block(7,62,6,AIR:0)
Block(7,63,-2,AIR:0)
Block(7,63,-1,AIR:0)
Block(7,63,0,AIR:0)
Block(7,63,1,AIR:0)
Block(7,63,2,AIR:0)
Block(7,63,3,AIR:0)
Block(7,63,4,AIR:0)
Block(7,63,5,AIR:0)
Block(7,63,6,AIR:0)
Branch(0,0,-16,true,originC5R15,NORTH,100.0,0)
