Author: NLBlackEagle
Description: No description given
SettingsMode: WriteDisable
Frequency: 0
SpawnHeight: highestBlock
UseCenterForHighestBlock: true
MinHeight: 0
MaxHeight: 255
InheritBO3: 
InheritBO3Rotation: NORTH
OverrideChildSettings: true
OverrideParentHeight: false
CanOverride: true
BranchFrequency: 0
BranchFrequencyGroup: 
MustBeBelowOther: false
MustBeInside: 
CannotBeInside: 
ReplacesBO3: 
MustBeInsideWorldBorders: false
CanSpawnOnWater: true
SpawnOnWaterOnly: false
SpawnUnderWater: false
SpawnAtWaterLevel: false
HeightOffset: 0
RemoveAir: false
ReplaceAbove: 
ReplaceBelow: 
ReplaceWithBiomeBlocks: false
ReplaceWithSurfaceBlock: GRASS
ReplaceWithGroundBlock: DIRT
ReplaceWithStoneBlock: STONE
SmoothRadius: 0
SmoothHeightOffset: 0
SmoothStartTop: false
SmoothStartWood: false
SmoothingSurfaceBlock: 
SmoothingGroundBlock: 
BO3Group: 
IsSpawnPoint: false
DoReplaceBlocks: false
Block(-5,-50,-7,SMOOTH_BRICK:2)
Block(-5,-50,-6,STONE:5)
Block(-5,-50,-5,LOG:0)
Block(-5,-49,-7,SMOOTH_BRICK:2)
Block(-5,-49,-6,STONE:5)
Block(-5,-49,-5,LOG:0)
Block(-5,-48,-7,SMOOTH_BRICK:2)
Block(-5,-48,-6,STONE:5)
Block(-5,-48,-5,LOG:0)
Block(-5,-47,-7,SMOOTH_BRICK:2)
Block(-5,-47,-6,STONE:5)
Block(-5,-47,-5,LOG:0)
Block(-5,-46,-7,SMOOTH_BRICK:2)
Block(-5,-46,-6,STONE:5)
Block(-5,-46,-5,LOG:0)
Block(-5,-45,-7,SMOOTH_BRICK:2)
Block(-5,-45,-6,STONE:5)
Block(-5,-45,-5,LOG:0)
Block(-5,-44,-7,SMOOTH_BRICK:2)
Block(-5,-44,-6,STONE:5)
Block(-5,-44,-5,LOG:0)
Block(-5,-43,-7,SMOOTH_BRICK:2)
Block(-5,-43,-6,STONE:5)
Block(-5,-43,-5,LOG:0)
Block(-5,-42,-7,SMOOTH_BRICK:2)
Block(-5,-42,-6,STONE:5)
Block(-5,-42,-5,LOG:0)
Block(-5,-41,-7,SMOOTH_BRICK:2)
Block(-5,-41,-6,STONE:5)
Block(-5,-41,-5,LOG:0)
Block(-5,-40,-7,SMOOTH_BRICK:2)
Block(-5,-40,-6,STONE:5)
Block(-5,-40,-5,LOG:0)
Block(-5,-39,-7,SMOOTH_BRICK:2)
Block(-5,-39,-6,STONE:5)
Block(-5,-39,-5,LOG:0)
Block(-5,-38,-7,SMOOTH_BRICK:2)
Block(-5,-38,-6,STONE:5)
Block(-5,-38,-5,LOG:0)
Block(-5,-37,-7,SMOOTH_BRICK:2)
Block(-5,-37,-6,STONE:5)
Block(-5,-37,-5,LOG:0)
Block(-5,-36,-7,SMOOTH_BRICK:2)
Block(-5,-36,-6,STONE:5)
Block(-5,-36,-5,LOG:0)
Block(-5,-35,-7,SMOOTH_BRICK:2)
Block(-5,-35,-6,STONE:5)
Block(-5,-35,-5,LOG:0)
Block(-5,-34,-7,SMOOTH_BRICK:2)
Block(-5,-34,-6,STONE:5)
Block(-5,-34,-5,LOG:0)
Block(-5,-33,-7,SMOOTH_BRICK:2)
Block(-5,-33,-6,STONE:5)
Block(-5,-33,-5,LOG:0)
Block(-5,-32,-7,SMOOTH_BRICK:2)
Block(-5,-32,-6,STONE:5)
Block(-5,-32,-5,LOG:0)
Block(-5,-31,-7,SMOOTH_BRICK:2)
Block(-5,-31,-6,STONE:5)
Block(-5,-31,-5,LOG:0)
Block(-5,-30,-7,SMOOTH_BRICK:2)
Block(-5,-30,-6,STONE:5)
Block(-5,-30,-5,LOG:0)
Block(-5,-29,-7,SMOOTH_BRICK:2)
Block(-5,-29,-6,STONE:5)
Block(-5,-29,-5,LOG:0)
Block(-5,-28,-7,SMOOTH_BRICK:2)
Block(-5,-28,-6,STONE:5)
Block(-5,-28,-5,LOG:0)
Block(-5,-27,-7,SMOOTH_BRICK:2)
Block(-5,-27,-6,STONE:5)
Block(-5,-27,-5,LOG:0)
Block(-5,-26,-7,SMOOTH_BRICK:2)
Block(-5,-26,-6,STONE:5)
Block(-5,-26,-5,LOG:0)
Block(-5,-25,-7,SMOOTH_BRICK:2)
Block(-5,-25,-6,STONE:5)
Block(-5,-25,-5,LOG:0)
Block(-5,-24,-7,SMOOTH_BRICK:2)
Block(-5,-24,-6,STONE:5)
Block(-5,-24,-5,LOG:0)
Block(-5,-23,-7,SMOOTH_BRICK:2)
Block(-5,-23,-6,STONE:5)
Block(-5,-23,-5,LOG:0)
Block(-5,-22,-7,SMOOTH_BRICK:2)
Block(-5,-22,-6,STONE:5)
Block(-5,-22,-5,LOG:0)
Block(-5,-21,-7,SMOOTH_BRICK:2)
Block(-5,-21,-6,STONE:5)
Block(-5,-21,-5,LOG:0)
Block(-5,-20,-7,SMOOTH_BRICK:2)
Block(-5,-20,-6,STONE:5)
Block(-5,-20,-5,LOG:0)
Block(-5,-19,-7,STONE:5)
Block(-5,-19,-6,STONE:5)
Block(-5,-19,-5,LOG:0)
Block(-5,-18,-7,COBBLESTONE:0)
Block(-5,-18,-6,SMOOTH_BRICK:0)
Block(-5,-18,-5,LOG:0)
Block(-5,-17,-7,STONE:5)
Block(-5,-17,-6,STONE:5)
Block(-5,-17,-5,LOG:0)
Block(-5,-16,-7,SMOOTH_BRICK:0)
Block(-5,-16,-6,SMOOTH_BRICK:0)
Block(-5,-16,-5,LOG:0)
Block(-5,-15,-7,SMOOTH_BRICK:0)
Block(-5,-15,-6,COBBLESTONE:0)
Block(-5,-15,-5,LOG:0)
Block(-5,-14,-7,STAINED_CLAY:9)
Block(-5,-14,-6,STONE:5)
Block(-5,-14,-5,LOG:0)
Block(-5,-13,-7,SMOOTH_BRICK:2)
Block(-5,-13,-6,COBBLESTONE:0)
Block(-5,-13,-5,LOG:0)
Block(-5,-12,-7,SMOOTH_BRICK:2)
Block(-5,-12,-6,SMOOTH_BRICK:2)
Block(-5,-12,-5,LOG:0)
Block(-5,-11,-7,STONE:5)
Block(-5,-11,-6,SMOOTH_BRICK:0)
Block(-5,-11,-5,LOG:0)
Block(-5,-10,-7,SMOOTH_BRICK:0)
Block(-5,-10,-6,COBBLESTONE:0)
Block(-5,-10,-5,LOG:0)
Block(-5,-9,-7,COBBLESTONE_STAIRS:0)
Block(-5,-9,-6,COBBLESTONE_STAIRS:0)
Block(-5,-9,-5,SMOOTH_STAIRS:0)
Block(-4,-50,-7,SMOOTH_BRICK:1)
Block(-4,-50,-6,STONE:5)
Block(-4,-50,-5,STONE:5)
Block(-4,-50,-4,STONE:5)
Block(-4,-50,-3,STAINED_CLAY:9)
Block(-4,-49,-7,SMOOTH_BRICK:1)
Block(-4,-49,-6,STONE:5)
Block(-4,-49,-5,STONE:5)
Block(-4,-49,-4,STONE:5)
Block(-4,-49,-3,STAINED_CLAY:9)
Block(-4,-48,-7,SMOOTH_BRICK:1)
Block(-4,-48,-6,STONE:5)
Block(-4,-48,-5,STONE:5)
Block(-4,-48,-4,STONE:5)
Block(-4,-48,-3,STAINED_CLAY:9)
Block(-4,-47,-7,SMOOTH_BRICK:1)
Block(-4,-47,-6,STONE:5)
Block(-4,-47,-5,STONE:5)
Block(-4,-47,-4,STONE:5)
Block(-4,-47,-3,STAINED_CLAY:9)
Block(-4,-46,-7,SMOOTH_BRICK:1)
Block(-4,-46,-6,STONE:5)
Block(-4,-46,-5,STONE:5)
Block(-4,-46,-4,STONE:5)
Block(-4,-46,-3,STAINED_CLAY:9)
Block(-4,-45,-7,SMOOTH_BRICK:1)
Block(-4,-45,-6,STONE:5)
Block(-4,-45,-5,STONE:5)
Block(-4,-45,-4,STONE:5)
Block(-4,-45,-3,STAINED_CLAY:9)
Block(-4,-44,-7,SMOOTH_BRICK:1)
Block(-4,-44,-6,STONE:5)
Block(-4,-44,-5,STONE:5)
Block(-4,-44,-4,STONE:5)
Block(-4,-44,-3,STAINED_CLAY:9)
Block(-4,-43,-7,SMOOTH_BRICK:1)
Block(-4,-43,-6,STONE:5)
Block(-4,-43,-5,STONE:5)
Block(-4,-43,-4,STONE:5)
Block(-4,-43,-3,STAINED_CLAY:9)
Block(-4,-42,-7,SMOOTH_BRICK:1)
Block(-4,-42,-6,STONE:5)
Block(-4,-42,-5,STONE:5)
Block(-4,-42,-4,STONE:5)
Block(-4,-42,-3,STAINED_CLAY:9)
Block(-4,-41,-7,SMOOTH_BRICK:1)
Block(-4,-41,-6,STONE:5)
Block(-4,-41,-5,STONE:5)
Block(-4,-41,-4,STONE:5)
Block(-4,-41,-3,STAINED_CLAY:9)
Block(-4,-40,-7,SMOOTH_BRICK:1)
Block(-4,-40,-6,STONE:5)
Block(-4,-40,-5,STONE:5)
Block(-4,-40,-4,STONE:5)
Block(-4,-40,-3,STAINED_CLAY:9)
Block(-4,-39,-7,SMOOTH_BRICK:1)
Block(-4,-39,-6,STONE:5)
Block(-4,-39,-5,STONE:5)
Block(-4,-39,-4,STONE:5)
Block(-4,-39,-3,STAINED_CLAY:9)
Block(-4,-38,-7,SMOOTH_BRICK:1)
Block(-4,-38,-6,STONE:5)
Block(-4,-38,-5,STONE:5)
Block(-4,-38,-4,STONE:5)
Block(-4,-38,-3,STAINED_CLAY:9)
Block(-4,-37,-7,SMOOTH_BRICK:1)
Block(-4,-37,-6,STONE:5)
Block(-4,-37,-5,STONE:5)
Block(-4,-37,-4,STONE:5)
Block(-4,-37,-3,STAINED_CLAY:9)
Block(-4,-36,-7,SMOOTH_BRICK:1)
Block(-4,-36,-6,STONE:5)
Block(-4,-36,-5,STONE:5)
Block(-4,-36,-4,STONE:5)
Block(-4,-36,-3,STAINED_CLAY:9)
Block(-4,-35,-7,SMOOTH_BRICK:1)
Block(-4,-35,-6,STONE:5)
Block(-4,-35,-5,STONE:5)
Block(-4,-35,-4,STONE:5)
Block(-4,-35,-3,STAINED_CLAY:9)
Block(-4,-34,-7,SMOOTH_BRICK:1)
Block(-4,-34,-6,STONE:5)
Block(-4,-34,-5,STONE:5)
Block(-4,-34,-4,STONE:5)
Block(-4,-34,-3,STAINED_CLAY:9)
Block(-4,-33,-7,SMOOTH_BRICK:1)
Block(-4,-33,-6,STONE:5)
Block(-4,-33,-5,STONE:5)
Block(-4,-33,-4,STONE:5)
Block(-4,-33,-3,STAINED_CLAY:9)
Block(-4,-32,-7,SMOOTH_BRICK:1)
Block(-4,-32,-6,STONE:5)
Block(-4,-32,-5,STONE:5)
Block(-4,-32,-4,STONE:5)
Block(-4,-32,-3,STAINED_CLAY:9)
Block(-4,-31,-7,SMOOTH_BRICK:1)
Block(-4,-31,-6,STONE:5)
Block(-4,-31,-5,STONE:5)
Block(-4,-31,-4,STONE:5)
Block(-4,-31,-3,STAINED_CLAY:9)
Block(-4,-30,-7,SMOOTH_BRICK:1)
Block(-4,-30,-6,STONE:5)
Block(-4,-30,-5,STONE:5)
Block(-4,-30,-4,STONE:5)
Block(-4,-30,-3,STAINED_CLAY:9)
Block(-4,-29,-7,SMOOTH_BRICK:1)
Block(-4,-29,-6,STONE:5)
Block(-4,-29,-5,STONE:5)
Block(-4,-29,-4,STONE:5)
Block(-4,-29,-3,STAINED_CLAY:9)
Block(-4,-28,-7,SMOOTH_BRICK:1)
Block(-4,-28,-6,STONE:5)
Block(-4,-28,-5,STONE:5)
Block(-4,-28,-4,STONE:5)
Block(-4,-28,-3,STAINED_CLAY:9)
Block(-4,-27,-7,SMOOTH_BRICK:1)
Block(-4,-27,-6,STONE:5)
Block(-4,-27,-5,STONE:5)
Block(-4,-27,-4,STONE:5)
Block(-4,-27,-3,STAINED_CLAY:9)
Block(-4,-26,-7,SMOOTH_BRICK:1)
Block(-4,-26,-6,STONE:5)
Block(-4,-26,-5,STONE:5)
Block(-4,-26,-4,STONE:5)
Block(-4,-26,-3,STAINED_CLAY:9)
Block(-4,-25,-7,SMOOTH_BRICK:1)
Block(-4,-25,-6,STONE:5)
Block(-4,-25,-5,STONE:5)
Block(-4,-25,-4,STONE:5)
Block(-4,-25,-3,STAINED_CLAY:9)
Block(-4,-24,-7,SMOOTH_BRICK:1)
Block(-4,-24,-6,STONE:5)
Block(-4,-24,-5,STONE:5)
Block(-4,-24,-4,STONE:5)
Block(-4,-24,-3,STAINED_CLAY:9)
Block(-4,-23,-7,SMOOTH_BRICK:1)
Block(-4,-23,-6,STONE:5)
Block(-4,-23,-5,STONE:5)
Block(-4,-23,-4,STONE:5)
Block(-4,-23,-3,STAINED_CLAY:9)
Block(-4,-22,-7,SMOOTH_BRICK:1)
Block(-4,-22,-6,STONE:5)
Block(-4,-22,-5,STONE:5)
Block(-4,-22,-4,STONE:5)
Block(-4,-22,-3,STAINED_CLAY:9)
Block(-4,-21,-7,SMOOTH_BRICK:1)
Block(-4,-21,-6,STONE:5)
Block(-4,-21,-5,STONE:5)
Block(-4,-21,-4,STONE:5)
Block(-4,-21,-3,STAINED_CLAY:9)
Block(-4,-20,-7,SMOOTH_BRICK:1)
Block(-4,-20,-6,STONE:5)
Block(-4,-20,-5,STONE:5)
Block(-4,-20,-4,STONE:5)
Block(-4,-20,-3,STAINED_CLAY:9)
Block(-4,-19,-7,SMOOTH_BRICK:0)
Block(-4,-19,-6,STONE:5)
Block(-4,-19,-5,SMOOTH_BRICK:2)
Block(-4,-19,-4,SMOOTH_BRICK:0)
Block(-4,-19,-3,SMOOTH_BRICK:2)
Block(-4,-18,-7,STONE:5)
Block(-4,-18,-6,STONE:5)
Block(-4,-18,-5,STONE:5)
Block(-4,-18,-4,SMOOTH_BRICK:2)
Block(-4,-18,-3,STONE:5)
Block(-4,-17,-7,STAINED_CLAY:9)
Block(-4,-17,-6,SMOOTH_BRICK:1)
Block(-4,-17,-5,STONE:5)
Block(-4,-17,-4,SMOOTH_BRICK:2)
Block(-4,-17,-3,STAINED_CLAY:9)
Block(-4,-16,-7,COBBLESTONE:0)
Block(-4,-16,-6,SMOOTH_BRICK:2)
Block(-4,-16,-5,SMOOTH_BRICK:2)
Block(-4,-16,-4,SMOOTH_BRICK:0)
Block(-4,-16,-3,SMOOTH_BRICK:0)
Block(-4,-15,-7,STONE:5)
Block(-4,-15,-6,STONE:5)
Block(-4,-15,-5,STONE:5)
Block(-4,-15,-4,SMOOTH_BRICK:0)
Block(-4,-15,-3,STONE:5)
Block(-4,-14,-7,STONE:5)
Block(-4,-14,-6,STONE:5)
Block(-4,-14,-5,STONE:5)
Block(-4,-14,-4,SMOOTH_BRICK:0)
Block(-4,-14,-3,SMOOTH_BRICK:2)
Block(-4,-13,-7,COBBLESTONE:0)
Block(-4,-13,-6,STONE:5)
Block(-4,-13,-5,STONE:5)
Block(-4,-13,-4,STAINED_CLAY:9)
Block(-4,-13,-3,SMOOTH_BRICK:1)
Block(-4,-12,-7,STONE:5)
Block(-4,-12,-6,SMOOTH_BRICK:0)
Block(-4,-12,-5,SMOOTH_BRICK:2)
Block(-4,-12,-4,SMOOTH_BRICK:2)
Block(-4,-12,-3,SMOOTH_BRICK:1)
Block(-4,-11,-7,COBBLESTONE:0)
Block(-4,-11,-6,STONE:5)
Block(-4,-11,-5,SMOOTH_BRICK:2)
Block(-4,-11,-4,STONE:5)
Block(-4,-11,-3,COBBLESTONE:0)
Block(-4,-10,-7,STONE:5)
Block(-4,-10,-6,STONE:5)
Block(-4,-10,-5,STONE:5)
Block(-4,-10,-4,STONE:5)
Block(-4,-10,-3,SMOOTH_BRICK:1)
Block(-4,-9,-7,STONE:6)
Block(-4,-9,-6,LOG:0)
Block(-4,-9,-5,COBBLESTONE_STAIRS:3)
Block(-4,-9,-4,COBBLESTONE_STAIRS:0)
Block(-4,-9,-3,COBBLESTONE_STAIRS:3)
Block(-4,-8,-7,STONE:6)
Block(-4,-8,-6,LOG:0)
Block(-4,-7,-7,STONE:6)
Block(-4,-7,-6,LOG:0)
Block(-4,-6,-7,STONE:6)
Block(-4,-6,-6,LOG:0)
Block(-4,-5,-7,COBBLESTONE_STAIRS:0)
Block(-4,-5,-6,LOG:0)
Block(-4,-4,-6,COBBLESTONE_STAIRS:0)
Block(-3,-50,-7,SMOOTH_BRICK:0)
Block(-3,-50,-6,STAINED_CLAY:9)
Block(-3,-50,-5,COBBLESTONE:0)
Block(-3,-50,-4,COBBLESTONE:0)
Block(-3,-50,-3,SMOOTH_BRICK:0)
Block(-3,-50,-2,LOG:0)
Block(-3,-49,-7,SMOOTH_BRICK:0)
Block(-3,-49,-6,STAINED_CLAY:9)
Block(-3,-49,-5,COBBLESTONE:0)
Block(-3,-49,-4,COBBLESTONE:0)
Block(-3,-49,-3,SMOOTH_BRICK:0)
Block(-3,-49,-2,LOG:0)
Block(-3,-48,-7,SMOOTH_BRICK:0)
Block(-3,-48,-6,STAINED_CLAY:9)
Block(-3,-48,-5,COBBLESTONE:0)
Block(-3,-48,-4,COBBLESTONE:0)
Block(-3,-48,-3,SMOOTH_BRICK:0)
Block(-3,-48,-2,LOG:0)
Block(-3,-47,-7,SMOOTH_BRICK:0)
Block(-3,-47,-6,STAINED_CLAY:9)
Block(-3,-47,-5,COBBLESTONE:0)
Block(-3,-47,-4,COBBLESTONE:0)
Block(-3,-47,-3,SMOOTH_BRICK:0)
Block(-3,-47,-2,LOG:0)
Block(-3,-46,-7,SMOOTH_BRICK:0)
Block(-3,-46,-6,STAINED_CLAY:9)
Block(-3,-46,-5,COBBLESTONE:0)
Block(-3,-46,-4,COBBLESTONE:0)
Block(-3,-46,-3,SMOOTH_BRICK:0)
Block(-3,-46,-2,LOG:0)
Block(-3,-45,-7,SMOOTH_BRICK:0)
Block(-3,-45,-6,STAINED_CLAY:9)
Block(-3,-45,-5,COBBLESTONE:0)
Block(-3,-45,-4,COBBLESTONE:0)
Block(-3,-45,-3,SMOOTH_BRICK:0)
Block(-3,-45,-2,LOG:0)
Block(-3,-44,-7,SMOOTH_BRICK:0)
Block(-3,-44,-6,STAINED_CLAY:9)
Block(-3,-44,-5,COBBLESTONE:0)
Block(-3,-44,-4,COBBLESTONE:0)
Block(-3,-44,-3,SMOOTH_BRICK:0)
Block(-3,-44,-2,LOG:0)
Block(-3,-43,-7,SMOOTH_BRICK:0)
Block(-3,-43,-6,STAINED_CLAY:9)
Block(-3,-43,-5,COBBLESTONE:0)
Block(-3,-43,-4,COBBLESTONE:0)
Block(-3,-43,-3,SMOOTH_BRICK:0)
Block(-3,-43,-2,LOG:0)
Block(-3,-42,-7,SMOOTH_BRICK:0)
Block(-3,-42,-6,STAINED_CLAY:9)
Block(-3,-42,-5,COBBLESTONE:0)
Block(-3,-42,-4,COBBLESTONE:0)
Block(-3,-42,-3,SMOOTH_BRICK:0)
Block(-3,-42,-2,LOG:0)
Block(-3,-41,-7,SMOOTH_BRICK:0)
Block(-3,-41,-6,STAINED_CLAY:9)
Block(-3,-41,-5,COBBLESTONE:0)
Block(-3,-41,-4,COBBLESTONE:0)
Block(-3,-41,-3,SMOOTH_BRICK:0)
Block(-3,-41,-2,LOG:0)
Block(-3,-40,-7,SMOOTH_BRICK:0)
Block(-3,-40,-6,STAINED_CLAY:9)
Block(-3,-40,-5,COBBLESTONE:0)
Block(-3,-40,-4,COBBLESTONE:0)
Block(-3,-40,-3,SMOOTH_BRICK:0)
Block(-3,-40,-2,LOG:0)
Block(-3,-39,-7,SMOOTH_BRICK:0)
Block(-3,-39,-6,STAINED_CLAY:9)
Block(-3,-39,-5,COBBLESTONE:0)
Block(-3,-39,-4,COBBLESTONE:0)
Block(-3,-39,-3,SMOOTH_BRICK:0)
Block(-3,-39,-2,LOG:0)
Block(-3,-38,-7,SMOOTH_BRICK:0)
Block(-3,-38,-6,STAINED_CLAY:9)
Block(-3,-38,-5,COBBLESTONE:0)
Block(-3,-38,-4,COBBLESTONE:0)
Block(-3,-38,-3,SMOOTH_BRICK:0)
Block(-3,-38,-2,LOG:0)
Block(-3,-37,-7,SMOOTH_BRICK:0)
Block(-3,-37,-6,STAINED_CLAY:9)
Block(-3,-37,-5,COBBLESTONE:0)
Block(-3,-37,-4,COBBLESTONE:0)
Block(-3,-37,-3,SMOOTH_BRICK:0)
Block(-3,-37,-2,LOG:0)
Block(-3,-36,-7,SMOOTH_BRICK:0)
Block(-3,-36,-6,STAINED_CLAY:9)
Block(-3,-36,-5,COBBLESTONE:0)
Block(-3,-36,-4,COBBLESTONE:0)
Block(-3,-36,-3,SMOOTH_BRICK:0)
Block(-3,-36,-2,LOG:0)
Block(-3,-35,-7,SMOOTH_BRICK:0)
Block(-3,-35,-6,STAINED_CLAY:9)
Block(-3,-35,-5,COBBLESTONE:0)
Block(-3,-35,-4,COBBLESTONE:0)
Block(-3,-35,-3,SMOOTH_BRICK:0)
Block(-3,-35,-2,LOG:0)
Block(-3,-34,-7,SMOOTH_BRICK:0)
Block(-3,-34,-6,STAINED_CLAY:9)
Block(-3,-34,-5,COBBLESTONE:0)
Block(-3,-34,-4,COBBLESTONE:0)
Block(-3,-34,-3,SMOOTH_BRICK:0)
Block(-3,-34,-2,LOG:0)
Block(-3,-33,-7,SMOOTH_BRICK:0)
Block(-3,-33,-6,STAINED_CLAY:9)
Block(-3,-33,-5,COBBLESTONE:0)
Block(-3,-33,-4,COBBLESTONE:0)
Block(-3,-33,-3,SMOOTH_BRICK:0)
Block(-3,-33,-2,LOG:0)
Block(-3,-32,-7,SMOOTH_BRICK:0)
Block(-3,-32,-6,STAINED_CLAY:9)
Block(-3,-32,-5,COBBLESTONE:0)
Block(-3,-32,-4,COBBLESTONE:0)
Block(-3,-32,-3,SMOOTH_BRICK:0)
Block(-3,-32,-2,LOG:0)
Block(-3,-31,-7,SMOOTH_BRICK:0)
Block(-3,-31,-6,STAINED_CLAY:9)
Block(-3,-31,-5,COBBLESTONE:0)
Block(-3,-31,-4,COBBLESTONE:0)
Block(-3,-31,-3,SMOOTH_BRICK:0)
Block(-3,-31,-2,LOG:0)
Block(-3,-30,-7,SMOOTH_BRICK:0)
Block(-3,-30,-6,STAINED_CLAY:9)
Block(-3,-30,-5,COBBLESTONE:0)
Block(-3,-30,-4,COBBLESTONE:0)
Block(-3,-30,-3,SMOOTH_BRICK:0)
Block(-3,-30,-2,LOG:0)
Block(-3,-29,-7,SMOOTH_BRICK:0)
Block(-3,-29,-6,STAINED_CLAY:9)
Block(-3,-29,-5,COBBLESTONE:0)
Block(-3,-29,-4,COBBLESTONE:0)
Block(-3,-29,-3,SMOOTH_BRICK:0)
Block(-3,-29,-2,LOG:0)
Block(-3,-28,-7,SMOOTH_BRICK:0)
Block(-3,-28,-6,STAINED_CLAY:9)
Block(-3,-28,-5,COBBLESTONE:0)
Block(-3,-28,-4,COBBLESTONE:0)
Block(-3,-28,-3,SMOOTH_BRICK:0)
Block(-3,-28,-2,LOG:0)
Block(-3,-27,-7,SMOOTH_BRICK:0)
Block(-3,-27,-6,STAINED_CLAY:9)
Block(-3,-27,-5,COBBLESTONE:0)
Block(-3,-27,-4,COBBLESTONE:0)
Block(-3,-27,-3,SMOOTH_BRICK:0)
Block(-3,-27,-2,LOG:0)
Block(-3,-26,-7,SMOOTH_BRICK:0)
Block(-3,-26,-6,STAINED_CLAY:9)
Block(-3,-26,-5,COBBLESTONE:0)
Block(-3,-26,-4,COBBLESTONE:0)
Block(-3,-26,-3,SMOOTH_BRICK:0)
Block(-3,-26,-2,LOG:0)
Block(-3,-25,-7,SMOOTH_BRICK:0)
Block(-3,-25,-6,STAINED_CLAY:9)
Block(-3,-25,-5,COBBLESTONE:0)
Block(-3,-25,-4,COBBLESTONE:0)
Block(-3,-25,-3,SMOOTH_BRICK:0)
Block(-3,-25,-2,LOG:0)
Block(-3,-24,-7,SMOOTH_BRICK:0)
Block(-3,-24,-6,STAINED_CLAY:9)
Block(-3,-24,-5,COBBLESTONE:0)
Block(-3,-24,-4,COBBLESTONE:0)
Block(-3,-24,-3,SMOOTH_BRICK:0)
Block(-3,-24,-2,LOG:0)
Block(-3,-23,-7,SMOOTH_BRICK:0)
Block(-3,-23,-6,STAINED_CLAY:9)
Block(-3,-23,-5,COBBLESTONE:0)
Block(-3,-23,-4,COBBLESTONE:0)
Block(-3,-23,-3,SMOOTH_BRICK:0)
Block(-3,-23,-2,LOG:0)
Block(-3,-22,-7,SMOOTH_BRICK:0)
Block(-3,-22,-6,STAINED_CLAY:9)
Block(-3,-22,-5,COBBLESTONE:0)
Block(-3,-22,-4,COBBLESTONE:0)
Block(-3,-22,-3,SMOOTH_BRICK:0)
Block(-3,-22,-2,LOG:0)
Block(-3,-21,-7,SMOOTH_BRICK:0)
Block(-3,-21,-6,STAINED_CLAY:9)
Block(-3,-21,-5,COBBLESTONE:0)
Block(-3,-21,-4,COBBLESTONE:0)
Block(-3,-21,-3,SMOOTH_BRICK:0)
Block(-3,-21,-2,LOG:0)
Block(-3,-20,-7,SMOOTH_BRICK:0)
Block(-3,-20,-6,STAINED_CLAY:9)
Block(-3,-20,-5,COBBLESTONE:0)
Block(-3,-20,-4,COBBLESTONE:0)
Block(-3,-20,-3,SMOOTH_BRICK:0)
Block(-3,-20,-2,LOG:0)
Block(-3,-19,-7,SMOOTH_BRICK:2)
Block(-3,-19,-6,STAINED_CLAY:9)
Block(-3,-19,-5,STAINED_CLAY:9)
Block(-3,-19,-4,SMOOTH_BRICK:0)
Block(-3,-19,-3,STAINED_CLAY:9)
Block(-3,-19,-2,LOG:0)
Block(-3,-18,-7,SMOOTH_BRICK:0)
Block(-3,-18,-6,SMOOTH_BRICK:0)
Block(-3,-18,-5,STONE:5)
Block(-3,-18,-4,STAINED_CLAY:9)
Block(-3,-18,-3,COBBLESTONE:0)
Block(-3,-18,-2,LOG:0)
Block(-3,-17,-7,COBBLESTONE:0)
Block(-3,-17,-6,STONE:5)
Block(-3,-17,-5,STAINED_CLAY:9)
Block(-3,-17,-4,STONE:5)
Block(-3,-17,-3,STONE:5)
Block(-3,-17,-2,LOG:0)
Block(-3,-16,-7,STONE:5)
Block(-3,-16,-6,COBBLESTONE:0)
Block(-3,-16,-5,SMOOTH_BRICK:1)
Block(-3,-16,-4,SMOOTH_BRICK:2)
Block(-3,-16,-3,SMOOTH_BRICK:2)
Block(-3,-16,-2,LOG:0)
Block(-3,-15,-7,STONE:5)
Block(-3,-15,-6,SMOOTH_BRICK:0)
Block(-3,-15,-5,STONE:5)
Block(-3,-15,-4,SMOOTH_BRICK:1)
Block(-3,-15,-3,STONE:5)
Block(-3,-15,-2,LOG:0)
Block(-3,-14,-7,SMOOTH_BRICK:0)
Block(-3,-14,-6,SMOOTH_BRICK:0)
Block(-3,-14,-5,STONE:5)
Block(-3,-14,-4,SMOOTH_BRICK:2)
Block(-3,-14,-3,SMOOTH_BRICK:2)
Block(-3,-14,-2,LOG:0)
Block(-3,-13,-7,SMOOTH_BRICK:2)
Block(-3,-13,-6,SMOOTH_BRICK:2)
Block(-3,-13,-5,STONE:5)
Block(-3,-13,-4,SMOOTH_BRICK:1)
Block(-3,-13,-3,COBBLESTONE:0)
Block(-3,-13,-2,LOG:0)
Block(-3,-12,-7,STONE:5)
Block(-3,-12,-6,SMOOTH_BRICK:2)
Block(-3,-12,-5,SMOOTH_BRICK:2)
Block(-3,-12,-4,STONE:5)
Block(-3,-12,-3,SMOOTH_BRICK:2)
Block(-3,-12,-2,LOG:0)
Block(-3,-11,-7,STONE:5)
Block(-3,-11,-6,STONE:5)
Block(-3,-11,-5,SMOOTH_BRICK:0)
Block(-3,-11,-4,COBBLESTONE:0)
Block(-3,-11,-3,STONE:5)
Block(-3,-11,-2,LOG:0)
Block(-3,-10,-7,COBBLESTONE:0)
Block(-3,-10,-6,STONE:5)
Block(-3,-10,-5,STONE:5)
Block(-3,-10,-4,SMOOTH_BRICK:0)
Block(-3,-10,-3,STONE:5)
Block(-3,-10,-2,LOG:0)
Block(-3,-9,-7,STONE:6)
Block(-3,-9,-6,STONE:6)
Block(-3,-9,-5,STONE:6)
Block(-3,-9,-4,STONE:6)
Block(-3,-9,-3,COBBLESTONE_STAIRS:0)
Block(-3,-9,-2,SMOOTH_STAIRS:3)
Block(-3,-8,-7,SMOOTH_BRICK:2)
Block(-3,-8,-6,SMOOTH_BRICK:0)
Block(-3,-8,-5,STONE:6)
Block(-3,-8,-4,STONE:6)
Block(-3,-7,-7,STONE:5)
Block(-3,-7,-6,SMOOTH_BRICK:0)
Block(-3,-7,-5,STONE:6)
Block(-3,-7,-4,STONE:6)
Block(-3,-6,-7,STONE:5)
Block(-3,-6,-6,STONE:5)
Block(-3,-6,-5,STONE:6)
Block(-3,-6,-4,STONE:6)
Block(-3,-5,-7,SMOOTH_BRICK:1)
Block(-3,-5,-6,STONE:5)
Block(-3,-5,-5,COBBLESTONE_STAIRS:0)
Block(-3,-5,-4,COBBLESTONE_STAIRS:0)
Block(-3,-4,-7,STONE:6)
Block(-3,-4,-6,LOG:4)
Block(-3,-3,-7,STONE:6)
Block(-3,-3,-6,LOG:0)
Block(-3,-2,-7,STONE:6)
Block(-3,-2,-6,LOG:0)
Block(-3,-1,-7,STONE:6)
Block(-3,-1,-6,LOG:0)
Block(-3,0,-7,COBBLESTONE_STAIRS:0)
Block(-3,0,-6,LOG:0)
Block(-3,1,-7,COBBLESTONE_STAIRS:4)
Block(-3,1,-6,LOG:0)
Block(-3,2,-7,STONE:6)
Block(-3,2,-6,LOG:0)
Block(-3,3,-7,STONE:6)
Block(-3,3,-6,LOG:0)
Block(-3,4,-7,STONE:6)
Block(-3,4,-6,LOG:0)
Block(-3,5,-7,SMOOTH_BRICK:0)
Block(-3,5,-6,LOG:0)
Block(-3,6,-7,SMOOTH_STAIRS:4)
Block(-3,6,-6,LOG:0)
Block(-3,7,-7,SMOOTH_BRICK:0)
Block(-3,7,-6,LOG:0)
Block(-3,8,-7,AIR:0)
Block(-3,8,-6,SMOOTH_STAIRS:0)
Block(-3,9,-7,AIR:0)
Block(-3,9,-6,AIR:0)
Block(-3,10,-7,WOOD_STEP:13)
Block(-3,10,-6,WOOD_STEP:13)
Block(-3,10,-5,WOOD_STEP:13)
Block(-3,10,-4,WOOD_STEP:13)
Block(-3,11,-7,AIR:0)
Block(-3,11,-6,AIR:0)
Block(-3,12,-7,AIR:0)
Block(-3,12,-6,AIR:0)
Block(-3,13,-7,AIR:0)
Block(-3,13,-6,AIR:0)
Block(-3,14,-7,AIR:0)
Block(-3,14,-6,AIR:0)
Block(-3,15,-7,AIR:0)
Block(-3,15,-6,AIR:0)
Block(-3,16,-7,AIR:0)
Block(-3,16,-6,AIR:0)
Block(-3,17,-7,AIR:0)
Block(-3,17,-6,AIR:0)
Block(-3,18,-7,AIR:0)
Block(-3,18,-6,AIR:0)
Block(-3,19,-7,AIR:0)
Block(-3,19,-6,AIR:0)
Block(-3,20,-7,AIR:0)
Block(-3,20,-6,AIR:0)
Block(-3,21,-7,AIR:0)
Block(-3,21,-6,AIR:0)
Block(-3,22,-7,AIR:0)
Block(-3,22,-6,AIR:0)
Block(-3,23,-7,AIR:0)
Block(-3,23,-6,AIR:0)
Block(-3,24,-7,AIR:0)
Block(-3,24,-6,AIR:0)
Block(-3,25,-7,AIR:0)
Block(-3,25,-6,AIR:0)
Block(-3,26,-7,AIR:0)
Block(-3,26,-6,AIR:0)
Block(-3,27,-7,AIR:0)
Block(-3,27,-6,AIR:0)
Block(-3,28,-7,AIR:0)
Block(-3,28,-6,AIR:0)
Block(-3,29,-7,AIR:0)
Block(-3,29,-6,AIR:0)
Block(-3,30,-7,AIR:0)
Block(-3,30,-6,AIR:0)
Block(-3,31,-7,AIR:0)
Block(-3,31,-6,AIR:0)
Block(-3,32,-7,AIR:0)
Block(-3,32,-6,AIR:0)
Block(-3,33,-7,AIR:0)
Block(-3,33,-6,AIR:0)
Block(-3,34,-7,AIR:0)
Block(-3,34,-6,AIR:0)
Block(-3,35,-7,AIR:0)
Block(-3,35,-6,AIR:0)
Block(-3,36,-7,AIR:0)
Block(-3,36,-6,AIR:0)
Block(-3,37,-7,AIR:0)
Block(-3,37,-6,AIR:0)
Block(-3,38,-7,AIR:0)
Block(-3,38,-6,AIR:0)
Block(-3,39,-7,AIR:0)
Block(-3,39,-6,AIR:0)
Block(-3,40,-7,AIR:0)
Block(-3,40,-6,AIR:0)
Block(-3,41,-7,AIR:0)
Block(-3,41,-6,AIR:0)
Block(-3,42,-7,AIR:0)
Block(-3,42,-6,AIR:0)
Block(-3,43,-7,AIR:0)
Block(-3,43,-6,AIR:0)
Block(-3,44,-7,AIR:0)
Block(-3,44,-6,AIR:0)
Block(-3,45,-7,AIR:0)
Block(-3,45,-6,AIR:0)
Block(-3,46,-7,AIR:0)
Block(-3,46,-6,AIR:0)
Block(-3,47,-7,AIR:0)
Block(-3,47,-6,AIR:0)
Block(-3,48,-7,AIR:0)
Block(-3,48,-6,AIR:0)
Block(-3,49,-7,AIR:0)
Block(-3,49,-6,AIR:0)
Block(-3,50,-7,AIR:0)
Block(-3,50,-6,AIR:0)
Block(-3,51,-7,AIR:0)
Block(-3,51,-6,AIR:0)
Block(-3,52,-7,AIR:0)
Block(-3,52,-6,AIR:0)
Block(-3,53,-7,AIR:0)
Block(-3,53,-6,AIR:0)
Block(-3,54,-7,AIR:0)
Block(-3,54,-6,AIR:0)
Block(-3,55,-7,AIR:0)
Block(-3,55,-6,AIR:0)
Block(-3,56,-7,AIR:0)
Block(-3,56,-6,AIR:0)
Block(-3,57,-7,AIR:0)
Block(-3,57,-6,AIR:0)
Block(-3,58,-7,AIR:0)
Block(-3,58,-6,AIR:0)
Block(-3,59,-7,AIR:0)
Block(-3,59,-6,AIR:0)
Block(-3,60,-7,AIR:0)
Block(-3,60,-6,AIR:0)
Block(-3,61,-7,AIR:0)
Block(-3,61,-6,AIR:0)
Block(-3,62,-7,AIR:0)
Block(-3,62,-6,AIR:0)
Block(-3,63,-7,AIR:0)
Block(-3,63,-6,AIR:0)
Block(-2,-50,-7,STONE:5)
Block(-2,-50,-6,SMOOTH_BRICK:0)
Block(-2,-50,-5,STONE:5)
Block(-2,-50,-4,COBBLESTONE:0)
Block(-2,-50,-3,STONE:5)
Block(-2,-50,-2,SMOOTH_BRICK:2)
Block(-2,-50,-1,SMOOTH_BRICK:0)
Block(-2,-49,-7,STONE:5)
Block(-2,-49,-6,SMOOTH_BRICK:0)
Block(-2,-49,-5,STONE:5)
Block(-2,-49,-4,COBBLESTONE:0)
Block(-2,-49,-3,STONE:5)
Block(-2,-49,-2,SMOOTH_BRICK:2)
Block(-2,-49,-1,SMOOTH_BRICK:0)
Block(-2,-48,-7,STONE:5)
Block(-2,-48,-6,SMOOTH_BRICK:0)
Block(-2,-48,-5,STONE:5)
Block(-2,-48,-4,COBBLESTONE:0)
Block(-2,-48,-3,STONE:5)
Block(-2,-48,-2,SMOOTH_BRICK:2)
Block(-2,-48,-1,SMOOTH_BRICK:0)
Block(-2,-47,-7,STONE:5)
Block(-2,-47,-6,SMOOTH_BRICK:0)
Block(-2,-47,-5,STONE:5)
Block(-2,-47,-4,COBBLESTONE:0)
Block(-2,-47,-3,STONE:5)
Block(-2,-47,-2,SMOOTH_BRICK:2)
Block(-2,-47,-1,SMOOTH_BRICK:0)
Block(-2,-46,-7,STONE:5)
Block(-2,-46,-6,SMOOTH_BRICK:0)
Block(-2,-46,-5,STONE:5)
Block(-2,-46,-4,COBBLESTONE:0)
Block(-2,-46,-3,STONE:5)
Block(-2,-46,-2,SMOOTH_BRICK:2)
Block(-2,-46,-1,SMOOTH_BRICK:0)
Block(-2,-45,-7,STONE:5)
Block(-2,-45,-6,SMOOTH_BRICK:0)
Block(-2,-45,-5,STONE:5)
Block(-2,-45,-4,COBBLESTONE:0)
Block(-2,-45,-3,STONE:5)
Block(-2,-45,-2,SMOOTH_BRICK:2)
Block(-2,-45,-1,SMOOTH_BRICK:0)
Block(-2,-44,-7,STONE:5)
Block(-2,-44,-6,SMOOTH_BRICK:0)
Block(-2,-44,-5,STONE:5)
Block(-2,-44,-4,COBBLESTONE:0)
Block(-2,-44,-3,STONE:5)
Block(-2,-44,-2,SMOOTH_BRICK:2)
Block(-2,-44,-1,SMOOTH_BRICK:0)
Block(-2,-43,-7,STONE:5)
Block(-2,-43,-6,SMOOTH_BRICK:0)
Block(-2,-43,-5,STONE:5)
Block(-2,-43,-4,COBBLESTONE:0)
Block(-2,-43,-3,STONE:5)
Block(-2,-43,-2,SMOOTH_BRICK:2)
Block(-2,-43,-1,SMOOTH_BRICK:0)
Block(-2,-42,-7,STONE:5)
Block(-2,-42,-6,SMOOTH_BRICK:0)
Block(-2,-42,-5,STONE:5)
Block(-2,-42,-4,COBBLESTONE:0)
Block(-2,-42,-3,STONE:5)
Block(-2,-42,-2,SMOOTH_BRICK:2)
Block(-2,-42,-1,SMOOTH_BRICK:0)
Block(-2,-41,-7,STONE:5)
Block(-2,-41,-6,SMOOTH_BRICK:0)
Block(-2,-41,-5,STONE:5)
Block(-2,-41,-4,COBBLESTONE:0)
Block(-2,-41,-3,STONE:5)
Block(-2,-41,-2,SMOOTH_BRICK:2)
Block(-2,-41,-1,SMOOTH_BRICK:0)
Block(-2,-40,-7,STONE:5)
Block(-2,-40,-6,SMOOTH_BRICK:0)
Block(-2,-40,-5,STONE:5)
Block(-2,-40,-4,COBBLESTONE:0)
Block(-2,-40,-3,STONE:5)
Block(-2,-40,-2,SMOOTH_BRICK:2)
Block(-2,-40,-1,SMOOTH_BRICK:0)
Block(-2,-39,-7,STONE:5)
Block(-2,-39,-6,SMOOTH_BRICK:0)
Block(-2,-39,-5,STONE:5)
Block(-2,-39,-4,COBBLESTONE:0)
Block(-2,-39,-3,STONE:5)
Block(-2,-39,-2,SMOOTH_BRICK:2)
Block(-2,-39,-1,SMOOTH_BRICK:0)
Block(-2,-38,-7,STONE:5)
Block(-2,-38,-6,SMOOTH_BRICK:0)
Block(-2,-38,-5,STONE:5)
Block(-2,-38,-4,COBBLESTONE:0)
Block(-2,-38,-3,STONE:5)
Block(-2,-38,-2,SMOOTH_BRICK:2)
Block(-2,-38,-1,SMOOTH_BRICK:0)
Block(-2,-37,-7,STONE:5)
Block(-2,-37,-6,SMOOTH_BRICK:0)
Block(-2,-37,-5,STONE:5)
Block(-2,-37,-4,COBBLESTONE:0)
Block(-2,-37,-3,STONE:5)
Block(-2,-37,-2,SMOOTH_BRICK:2)
Block(-2,-37,-1,SMOOTH_BRICK:0)
Block(-2,-36,-7,STONE:5)
Block(-2,-36,-6,SMOOTH_BRICK:0)
Block(-2,-36,-5,STONE:5)
Block(-2,-36,-4,COBBLESTONE:0)
Block(-2,-36,-3,STONE:5)
Block(-2,-36,-2,SMOOTH_BRICK:2)
Block(-2,-36,-1,SMOOTH_BRICK:0)
Block(-2,-35,-7,STONE:5)
Block(-2,-35,-6,SMOOTH_BRICK:0)
Block(-2,-35,-5,STONE:5)
Block(-2,-35,-4,COBBLESTONE:0)
Block(-2,-35,-3,STONE:5)
Block(-2,-35,-2,SMOOTH_BRICK:2)
Block(-2,-35,-1,SMOOTH_BRICK:0)
Block(-2,-34,-7,STONE:5)
Block(-2,-34,-6,SMOOTH_BRICK:0)
Block(-2,-34,-5,STONE:5)
Block(-2,-34,-4,COBBLESTONE:0)
Block(-2,-34,-3,STONE:5)
Block(-2,-34,-2,SMOOTH_BRICK:2)
Block(-2,-34,-1,SMOOTH_BRICK:0)
Block(-2,-33,-7,STONE:5)
Block(-2,-33,-6,SMOOTH_BRICK:0)
Block(-2,-33,-5,STONE:5)
Block(-2,-33,-4,COBBLESTONE:0)
Block(-2,-33,-3,STONE:5)
Block(-2,-33,-2,SMOOTH_BRICK:2)
Block(-2,-33,-1,SMOOTH_BRICK:0)
Block(-2,-32,-7,STONE:5)
Block(-2,-32,-6,SMOOTH_BRICK:0)
Block(-2,-32,-5,STONE:5)
Block(-2,-32,-4,COBBLESTONE:0)
Block(-2,-32,-3,STONE:5)
Block(-2,-32,-2,SMOOTH_BRICK:2)
Block(-2,-32,-1,SMOOTH_BRICK:0)
Block(-2,-31,-7,STONE:5)
Block(-2,-31,-6,SMOOTH_BRICK:0)
Block(-2,-31,-5,STONE:5)
Block(-2,-31,-4,COBBLESTONE:0)
Block(-2,-31,-3,STONE:5)
Block(-2,-31,-2,SMOOTH_BRICK:2)
Block(-2,-31,-1,SMOOTH_BRICK:0)
Block(-2,-30,-7,STONE:5)
Block(-2,-30,-6,SMOOTH_BRICK:0)
Block(-2,-30,-5,STONE:5)
Block(-2,-30,-4,COBBLESTONE:0)
Block(-2,-30,-3,STONE:5)
Block(-2,-30,-2,SMOOTH_BRICK:2)
Block(-2,-30,-1,SMOOTH_BRICK:0)
Block(-2,-29,-7,STONE:5)
Block(-2,-29,-6,SMOOTH_BRICK:0)
Block(-2,-29,-5,STONE:5)
Block(-2,-29,-4,COBBLESTONE:0)
Block(-2,-29,-3,STONE:5)
Block(-2,-29,-2,SMOOTH_BRICK:2)
Block(-2,-29,-1,SMOOTH_BRICK:0)
Block(-2,-28,-7,STONE:5)
Block(-2,-28,-6,SMOOTH_BRICK:0)
Block(-2,-28,-5,STONE:5)
Block(-2,-28,-4,COBBLESTONE:0)
Block(-2,-28,-3,STONE:5)
Block(-2,-28,-2,SMOOTH_BRICK:2)
Block(-2,-28,-1,SMOOTH_BRICK:0)
Block(-2,-27,-7,STONE:5)
Block(-2,-27,-6,SMOOTH_BRICK:0)
Block(-2,-27,-5,STONE:5)
Block(-2,-27,-4,COBBLESTONE:0)
Block(-2,-27,-3,STONE:5)
Block(-2,-27,-2,SMOOTH_BRICK:2)
Block(-2,-27,-1,SMOOTH_BRICK:0)
Block(-2,-26,-7,STONE:5)
Block(-2,-26,-6,SMOOTH_BRICK:0)
Block(-2,-26,-5,STONE:5)
Block(-2,-26,-4,COBBLESTONE:0)
Block(-2,-26,-3,STONE:5)
Block(-2,-26,-2,SMOOTH_BRICK:2)
Block(-2,-26,-1,SMOOTH_BRICK:0)
Block(-2,-25,-7,STONE:5)
Block(-2,-25,-6,SMOOTH_BRICK:0)
Block(-2,-25,-5,STONE:5)
Block(-2,-25,-4,COBBLESTONE:0)
Block(-2,-25,-3,STONE:5)
Block(-2,-25,-2,SMOOTH_BRICK:2)
Block(-2,-25,-1,SMOOTH_BRICK:0)
Block(-2,-24,-7,STONE:5)
Block(-2,-24,-6,SMOOTH_BRICK:0)
Block(-2,-24,-5,STONE:5)
Block(-2,-24,-4,COBBLESTONE:0)
Block(-2,-24,-3,STONE:5)
Block(-2,-24,-2,SMOOTH_BRICK:2)
Block(-2,-24,-1,SMOOTH_BRICK:0)
Block(-2,-23,-7,STONE:5)
Block(-2,-23,-6,SMOOTH_BRICK:0)
Block(-2,-23,-5,STONE:5)
Block(-2,-23,-4,COBBLESTONE:0)
Block(-2,-23,-3,STONE:5)
Block(-2,-23,-2,SMOOTH_BRICK:2)
Block(-2,-23,-1,SMOOTH_BRICK:0)
Block(-2,-22,-7,STONE:5)
Block(-2,-22,-6,SMOOTH_BRICK:0)
Block(-2,-22,-5,STONE:5)
Block(-2,-22,-4,COBBLESTONE:0)
Block(-2,-22,-3,STONE:5)
Block(-2,-22,-2,SMOOTH_BRICK:2)
Block(-2,-22,-1,SMOOTH_BRICK:0)
Block(-2,-21,-7,STONE:5)
Block(-2,-21,-6,SMOOTH_BRICK:0)
Block(-2,-21,-5,STONE:5)
Block(-2,-21,-4,COBBLESTONE:0)
Block(-2,-21,-3,STONE:5)
Block(-2,-21,-2,SMOOTH_BRICK:2)
Block(-2,-21,-1,SMOOTH_BRICK:0)
Block(-2,-20,-7,STONE:5)
Block(-2,-20,-6,SMOOTH_BRICK:0)
Block(-2,-20,-5,STONE:5)
Block(-2,-20,-4,COBBLESTONE:0)
Block(-2,-20,-3,STONE:5)
Block(-2,-20,-2,SMOOTH_BRICK:2)
Block(-2,-20,-1,SMOOTH_BRICK:0)
Block(-2,-19,-7,STAINED_CLAY:9)
Block(-2,-19,-6,COBBLESTONE:0)
Block(-2,-19,-5,SMOOTH_BRICK:1)
Block(-2,-19,-4,STONE:5)
Block(-2,-19,-3,SMOOTH_BRICK:0)
Block(-2,-19,-2,STONE:5)
Block(-2,-19,-1,COBBLESTONE:0)
Block(-2,-18,-7,STONE:5)
Block(-2,-18,-6,STONE:5)
Block(-2,-18,-5,STONE:5)
Block(-2,-18,-4,SMOOTH_BRICK:1)
Block(-2,-18,-3,SMOOTH_BRICK:1)
Block(-2,-18,-2,SMOOTH_BRICK:0)
Block(-2,-18,-1,SMOOTH_BRICK:0)
Block(-2,-17,-7,COBBLESTONE:0)
Block(-2,-17,-6,STONE:5)
Block(-2,-17,-5,COBBLESTONE:0)
Block(-2,-17,-4,STONE:5)
Block(-2,-17,-3,COBBLESTONE:0)
Block(-2,-17,-2,STONE:5)
Block(-2,-17,-1,COBBLESTONE:0)
Block(-2,-16,-7,SMOOTH_BRICK:2)
Block(-2,-16,-6,STONE:5)
Block(-2,-16,-5,STONE:5)
Block(-2,-16,-4,SMOOTH_BRICK:2)
Block(-2,-16,-3,STONE:5)
Block(-2,-16,-2,SMOOTH_BRICK:0)
Block(-2,-16,-1,STONE:5)
Block(-2,-15,-7,SMOOTH_BRICK:0)
Block(-2,-15,-6,SMOOTH_BRICK:0)
Block(-2,-15,-5,STONE:5)
Block(-2,-15,-4,STONE:5)
Block(-2,-15,-3,SMOOTH_BRICK:1)
Block(-2,-15,-2,STAINED_CLAY:9)
Block(-2,-15,-1,STONE:5)
Block(-2,-14,-7,SMOOTH_BRICK:1)
Block(-2,-14,-6,SMOOTH_BRICK:0)
Block(-2,-14,-5,STONE:5)
Block(-2,-14,-4,SMOOTH_BRICK:2)
Block(-2,-14,-3,SMOOTH_BRICK:2)
Block(-2,-14,-2,SMOOTH_BRICK:2)
Block(-2,-14,-1,SMOOTH_BRICK:1)
Block(-2,-13,-7,SMOOTH_BRICK:0)
Block(-2,-13,-6,SMOOTH_BRICK:0)
Block(-2,-13,-5,STONE:5)
Block(-2,-13,-4,SMOOTH_BRICK:1)
Block(-2,-13,-3,STONE:5)
Block(-2,-13,-2,COBBLESTONE:0)
Block(-2,-13,-1,COBBLESTONE:0)
Block(-2,-12,-7,STONE:5)
Block(-2,-12,-6,STONE:5)
Block(-2,-12,-5,SMOOTH_BRICK:1)
Block(-2,-12,-4,SMOOTH_BRICK:0)
Block(-2,-12,-3,SMOOTH_BRICK:2)
Block(-2,-12,-2,COBBLESTONE:0)
Block(-2,-12,-1,SMOOTH_BRICK:2)
Block(-2,-11,-7,STONE:5)
Block(-2,-11,-6,SMOOTH_BRICK:0)
Block(-2,-11,-5,SMOOTH_BRICK:2)
Block(-2,-11,-4,SMOOTH_BRICK:2)
Block(-2,-11,-3,SMOOTH_BRICK:2)
Block(-2,-11,-2,SMOOTH_BRICK:2)
Block(-2,-11,-1,STAINED_CLAY:9)
Block(-2,-10,-7,STONE:5)
Block(-2,-10,-6,SMOOTH_BRICK:2)
Block(-2,-10,-5,SMOOTH_BRICK:2)
Block(-2,-10,-4,STONE:5)
Block(-2,-10,-3,SMOOTH_BRICK:0)
Block(-2,-10,-2,STONE:5)
Block(-2,-10,-1,SMOOTH_BRICK:0)
Block(-2,-9,-7,STONE:6)
Block(-2,-9,-6,STONE:6)
Block(-2,-9,-5,STONE:6)
Block(-2,-9,-4,STONE:6)
Block(-2,-9,-3,LOG:0)
Block(-2,-9,-2,COBBLESTONE_STAIRS:0)
Block(-2,-9,-1,COBBLESTONE_STAIRS:3)
Block(-2,-8,-7,SMOOTH_BRICK:2)
Block(-2,-8,-6,COBBLESTONE:0)
Block(-2,-8,-5,SMOOTH_BRICK:2)
Block(-2,-8,-4,STONE:5)
Block(-2,-8,-3,LOG:0)
Block(-2,-7,-7,STONE:5)
Block(-2,-7,-6,SMOOTH_BRICK:2)
Block(-2,-7,-5,STONE:5)
Block(-2,-7,-4,STAINED_CLAY:9)
Block(-2,-7,-3,LOG:0)
Block(-2,-6,-7,SMOOTH_BRICK:2)
Block(-2,-6,-6,SMOOTH_BRICK:1)
Block(-2,-6,-5,STONE:5)
Block(-2,-6,-4,SMOOTH_BRICK:0)
Block(-2,-6,-3,LOG:0)
Block(-2,-5,-7,SMOOTH_BRICK:0)
Block(-2,-5,-6,STONE:5)
Block(-2,-5,-5,STAINED_CLAY:9)
Block(-2,-5,-4,SMOOTH_BRICK:0)
Block(-2,-5,-3,LOG:0)
Block(-2,-4,-7,STONE:6)
Block(-2,-4,-6,STONE:6)
Block(-2,-4,-5,STONE:6)
Block(-2,-4,-4,STONE:6)
Block(-2,-4,-3,COBBLESTONE_STAIRS:0)
Block(-2,-3,-7,STONE:6)
Block(-2,-3,-6,STONE:6)
Block(-2,-3,-5,STONE:6)
Block(-2,-3,-4,STONE:6)
Block(-2,-2,-7,STONE:6)
Block(-2,-2,-6,STONE:6)
Block(-2,-2,-5,STONE:6)
Block(-2,-2,-4,STONE:6)
Block(-2,-1,-7,STONE:6)
Block(-2,-1,-6,STONE:6)
Block(-2,-1,-5,STONE:6)
Block(-2,-1,-4,STONE:6)
Block(-2,0,-7,STONE:6)
Block(-2,0,-6,STONE:6)
Block(-2,0,-5,STONE:6)
Block(-2,0,-4,STONE:6)
Block(-2,1,-7,STONE:6)
Block(-2,1,-6,STONE:6)
Block(-2,1,-5,STONE:6)
Block(-2,1,-4,STONE:6)
Block(-2,2,-7,SMOOTH_BRICK:0)
Block(-2,2,-6,SMOOTH_BRICK:0)
Block(-2,2,-5,STONE:6)
Block(-2,2,-4,STONE:6)
Block(-2,3,-7,SMOOTH_BRICK:0)
Block(-2,3,-6,SMOOTH_BRICK:0)
Block(-2,3,-5,STONE:6)
Block(-2,3,-4,STONE:6)
Block(-2,4,-7,COBBLESTONE:0)
Block(-2,4,-6,COBBLESTONE:0)
Block(-2,4,-5,STONE:6)
Block(-2,4,-4,STONE:6)
Block(-2,5,-7,COBBLESTONE:0)
Block(-2,5,-6,COBBLESTONE:0)
Block(-2,5,-5,SMOOTH_BRICK:0)
Block(-2,5,-4,SMOOTH_BRICK:0)
Block(-2,6,-7,COBBLESTONE:0)
Block(-2,6,-6,COBBLESTONE:0)
Block(-2,6,-5,SMOOTH_BRICK:0)
Block(-2,6,-4,SMOOTH_BRICK:0)
Block(-2,7,-7,LOG:8)
Block(-2,7,-6,LOG:8)
Block(-2,7,-5,SMOOTH_BRICK:0)
Block(-2,7,-4,SMOOTH_BRICK:0)
Block(-2,8,-7,STONE:6)
Block(-2,8,-6,LOG:4)
Block(-2,8,-5,COBBLESTONE:0)
Block(-2,8,-4,COBBLESTONE:0)
Block(-2,9,-7,STONE:6)
Block(-2,9,-6,LOG:0)
Block(-2,9,-5,STEP:0)
Block(-2,9,-4,STEP:0)
Block(-2,10,-7,STONE:6)
Block(-2,10,-6,LOG:0)
Block(-2,10,-5,AIR:0)
Block(-2,10,-4,AIR:0)
Block(-2,10,-3,WOOD_STEP:13)
Block(-2,11,-7,LOG:8)
Block(-2,11,-6,LOG:0)
Block(-2,11,-5,WOOD_STEP:5)
Block(-2,11,-4,WOOD_STEP:5)
Block(-2,12,-7,SMOOTH_BRICK:0)
Block(-2,12,-6,LOG:0)
Block(-2,12,-5,AIR:0)
Block(-2,12,-4,AIR:0)
Block(-2,13,-7,SMOOTH_STAIRS:0)
Block(-2,13,-6,LOG:0)
Block(-2,13,-5,AIR:0)
Block(-2,13,-4,AIR:0)
Block(-2,14,-7,SMOOTH_STAIRS:4)
Block(-2,14,-6,LOG:0)
Block(-2,14,-5,AIR:0)
Block(-2,14,-4,AIR:0)
Block(-2,15,-7,WOOD_STEP:5)
Block(-2,15,-6,LOG:0)
Block(-2,15,-5,AIR:0)
Block(-2,15,-4,AIR:0)
Block(-2,16,-7,AIR:0)
Block(-2,16,-6,LOG:0)
Block(-2,16,-5,AIR:0)
Block(-2,16,-4,AIR:0)
Block(-2,17,-7,AIR:0)
Block(-2,17,-6,LOG:0)
Block(-2,17,-5,AIR:0)
Block(-2,17,-4,AIR:0)
Block(-2,18,-7,AIR:0)
Block(-2,18,-6,LOG:0)
Block(-2,18,-5,AIR:0)
Block(-2,18,-4,AIR:0)
Block(-2,19,-7,SMOOTH_STAIRS:6)
Block(-2,19,-6,LOG:0)
Block(-2,19,-5,AIR:0)
Block(-2,19,-4,AIR:0)
Block(-2,20,-7,STONE:6)
Block(-2,20,-6,LOG:0)
Block(-2,20,-5,AIR:0)
Block(-2,20,-4,AIR:0)
Block(-2,21,-7,DARK_OAK_FENCE:0)
Block(-2,21,-6,SMOOTH_STAIRS:0)
Block(-2,21,-5,AIR:0)
Block(-2,21,-4,AIR:0)
Block(-2,22,-7,DARK_OAK_FENCE:0)
Block(-2,22,-6,AIR:0)
Block(-2,22,-5,AIR:0)
Block(-2,22,-4,AIR:0)
Block(-2,23,-7,DARK_OAK_STAIRS:0)
Block(-2,23,-6,AIR:0)
Block(-2,23,-5,AIR:0)
Block(-2,23,-4,AIR:0)
Block(-2,24,-7,AIR:0)
Block(-2,24,-6,AIR:0)
Block(-2,24,-5,AIR:0)
Block(-2,24,-4,AIR:0)
Block(-2,25,-7,AIR:0)
Block(-2,25,-6,AIR:0)
Block(-2,25,-5,AIR:0)
Block(-2,25,-4,AIR:0)
Block(-2,26,-7,AIR:0)
Block(-2,26,-6,AIR:0)
Block(-2,26,-5,AIR:0)
Block(-2,26,-4,AIR:0)
Block(-2,27,-7,AIR:0)
Block(-2,27,-6,AIR:0)
Block(-2,27,-5,AIR:0)
Block(-2,27,-4,AIR:0)
Block(-2,28,-7,AIR:0)
Block(-2,28,-6,AIR:0)
Block(-2,28,-5,AIR:0)
Block(-2,28,-4,AIR:0)
Block(-2,29,-7,AIR:0)
Block(-2,29,-6,AIR:0)
Block(-2,29,-5,AIR:0)
Block(-2,29,-4,AIR:0)
Block(-2,30,-7,AIR:0)
Block(-2,30,-6,AIR:0)
Block(-2,30,-5,AIR:0)
Block(-2,30,-4,AIR:0)
Block(-2,31,-7,AIR:0)
Block(-2,31,-6,AIR:0)
Block(-2,31,-5,AIR:0)
Block(-2,31,-4,AIR:0)
Block(-2,32,-7,AIR:0)
Block(-2,32,-6,AIR:0)
Block(-2,32,-5,AIR:0)
Block(-2,32,-4,AIR:0)
Block(-2,33,-7,AIR:0)
Block(-2,33,-6,AIR:0)
Block(-2,33,-5,AIR:0)
Block(-2,33,-4,AIR:0)
Block(-2,34,-7,AIR:0)
Block(-2,34,-6,AIR:0)
Block(-2,34,-5,AIR:0)
Block(-2,34,-4,AIR:0)
Block(-2,35,-7,AIR:0)
Block(-2,35,-6,AIR:0)
Block(-2,35,-5,AIR:0)
Block(-2,35,-4,AIR:0)
Block(-2,36,-7,AIR:0)
Block(-2,36,-6,AIR:0)
Block(-2,36,-5,AIR:0)
Block(-2,36,-4,AIR:0)
Block(-2,37,-7,AIR:0)
Block(-2,37,-6,AIR:0)
Block(-2,37,-5,AIR:0)
Block(-2,37,-4,AIR:0)
Block(-2,38,-7,AIR:0)
Block(-2,38,-6,AIR:0)
Block(-2,38,-5,AIR:0)
Block(-2,38,-4,AIR:0)
Block(-2,39,-7,AIR:0)
Block(-2,39,-6,AIR:0)
Block(-2,39,-5,AIR:0)
Block(-2,39,-4,AIR:0)
Block(-2,40,-7,AIR:0)
Block(-2,40,-6,AIR:0)
Block(-2,40,-5,AIR:0)
Block(-2,40,-4,AIR:0)
Block(-2,41,-7,AIR:0)
Block(-2,41,-6,AIR:0)
Block(-2,41,-5,AIR:0)
Block(-2,41,-4,AIR:0)
Block(-2,42,-7,AIR:0)
Block(-2,42,-6,AIR:0)
Block(-2,42,-5,AIR:0)
Block(-2,42,-4,AIR:0)
Block(-2,43,-7,AIR:0)
Block(-2,43,-6,AIR:0)
Block(-2,43,-5,AIR:0)
Block(-2,43,-4,AIR:0)
Block(-2,44,-7,AIR:0)
Block(-2,44,-6,AIR:0)
Block(-2,44,-5,AIR:0)
Block(-2,44,-4,AIR:0)
Block(-2,45,-7,AIR:0)
Block(-2,45,-6,AIR:0)
Block(-2,45,-5,AIR:0)
Block(-2,45,-4,AIR:0)
Block(-2,46,-7,AIR:0)
Block(-2,46,-6,AIR:0)
Block(-2,46,-5,AIR:0)
Block(-2,46,-4,AIR:0)
Block(-2,47,-7,AIR:0)
Block(-2,47,-6,AIR:0)
Block(-2,47,-5,AIR:0)
Block(-2,47,-4,AIR:0)
Block(-2,48,-7,AIR:0)
Block(-2,48,-6,AIR:0)
Block(-2,48,-5,WOOL:15)
Block(-2,48,-4,AIR:0)
Block(-2,49,-7,AIR:0)
Block(-2,49,-6,AIR:0)
Block(-2,49,-5,AIR:0)
Block(-2,49,-4,AIR:0)
Block(-2,50,-7,AIR:0)
Block(-2,50,-6,AIR:0)
Block(-2,50,-5,AIR:0)
Block(-2,50,-4,AIR:0)
Block(-2,51,-7,AIR:0)
Block(-2,51,-6,AIR:0)
Block(-2,51,-5,AIR:0)
Block(-2,51,-4,AIR:0)
Block(-2,52,-7,AIR:0)
Block(-2,52,-6,AIR:0)
Block(-2,52,-5,AIR:0)
Block(-2,52,-4,AIR:0)
Block(-2,53,-7,AIR:0)
Block(-2,53,-6,AIR:0)
Block(-2,53,-5,AIR:0)
Block(-2,53,-4,AIR:0)
Block(-2,54,-7,AIR:0)
Block(-2,54,-6,AIR:0)
Block(-2,54,-5,AIR:0)
Block(-2,54,-4,AIR:0)
Block(-2,55,-7,AIR:0)
Block(-2,55,-6,AIR:0)
Block(-2,55,-5,AIR:0)
Block(-2,55,-4,AIR:0)
Block(-2,56,-7,AIR:0)
Block(-2,56,-6,AIR:0)
Block(-2,56,-5,AIR:0)
Block(-2,56,-4,AIR:0)
Block(-2,57,-7,AIR:0)
Block(-2,57,-6,AIR:0)
Block(-2,57,-5,AIR:0)
Block(-2,57,-4,AIR:0)
Block(-2,58,-7,AIR:0)
Block(-2,58,-6,AIR:0)
Block(-2,58,-5,AIR:0)
Block(-2,58,-4,AIR:0)
Block(-2,59,-7,AIR:0)
Block(-2,59,-6,AIR:0)
Block(-2,59,-5,AIR:0)
Block(-2,59,-4,AIR:0)
Block(-2,60,-7,AIR:0)
Block(-2,60,-6,AIR:0)
Block(-2,60,-5,AIR:0)
Block(-2,60,-4,AIR:0)
Block(-2,61,-7,AIR:0)
Block(-2,61,-6,AIR:0)
Block(-2,61,-5,AIR:0)
Block(-2,61,-4,AIR:0)
Block(-2,62,-7,AIR:0)
Block(-2,62,-6,AIR:0)
Block(-2,62,-5,AIR:0)
Block(-2,62,-4,AIR:0)
Block(-2,63,-7,AIR:0)
Block(-2,63,-6,AIR:0)
Block(-2,63,-5,AIR:0)
Block(-2,63,-4,AIR:0)
Block(-1,-50,-7,SMOOTH_BRICK:2)
Block(-1,-50,-6,SMOOTH_BRICK:1)
Block(-1,-50,-5,SMOOTH_BRICK:0)
Block(-1,-50,-4,SMOOTH_BRICK:0)
Block(-1,-50,-3,SMOOTH_BRICK:1)
Block(-1,-50,-2,SMOOTH_BRICK:1)
Block(-1,-50,-1,STONE:5)
Block(-1,-50,0,LOG:0)
Block(-1,-49,-7,SMOOTH_BRICK:2)
Block(-1,-49,-6,SMOOTH_BRICK:1)
Block(-1,-49,-5,SMOOTH_BRICK:0)
Block(-1,-49,-4,SMOOTH_BRICK:0)
Block(-1,-49,-3,SMOOTH_BRICK:1)
Block(-1,-49,-2,SMOOTH_BRICK:1)
Block(-1,-49,-1,STONE:5)
Block(-1,-49,0,LOG:0)
Block(-1,-48,-7,SMOOTH_BRICK:2)
Block(-1,-48,-6,SMOOTH_BRICK:1)
Block(-1,-48,-5,SMOOTH_BRICK:0)
Block(-1,-48,-4,SMOOTH_BRICK:0)
Block(-1,-48,-3,SMOOTH_BRICK:1)
Block(-1,-48,-2,SMOOTH_BRICK:1)
Block(-1,-48,-1,STONE:5)
Block(-1,-48,0,LOG:0)
Block(-1,-47,-7,SMOOTH_BRICK:2)
Block(-1,-47,-6,SMOOTH_BRICK:1)
Block(-1,-47,-5,SMOOTH_BRICK:0)
Block(-1,-47,-4,SMOOTH_BRICK:0)
Block(-1,-47,-3,SMOOTH_BRICK:1)
Block(-1,-47,-2,SMOOTH_BRICK:1)
Block(-1,-47,-1,STONE:5)
Block(-1,-47,0,LOG:0)
Block(-1,-46,-7,SMOOTH_BRICK:2)
Block(-1,-46,-6,SMOOTH_BRICK:1)
Block(-1,-46,-5,SMOOTH_BRICK:0)
Block(-1,-46,-4,SMOOTH_BRICK:0)
Block(-1,-46,-3,SMOOTH_BRICK:1)
Block(-1,-46,-2,SMOOTH_BRICK:1)
Block(-1,-46,-1,STONE:5)
Block(-1,-46,0,LOG:0)
Block(-1,-45,-7,SMOOTH_BRICK:2)
Block(-1,-45,-6,SMOOTH_BRICK:1)
Block(-1,-45,-5,SMOOTH_BRICK:0)
Block(-1,-45,-4,SMOOTH_BRICK:0)
Block(-1,-45,-3,SMOOTH_BRICK:1)
Block(-1,-45,-2,SMOOTH_BRICK:1)
Block(-1,-45,-1,STONE:5)
Block(-1,-45,0,LOG:0)
Block(-1,-44,-7,SMOOTH_BRICK:2)
Block(-1,-44,-6,SMOOTH_BRICK:1)
Block(-1,-44,-5,SMOOTH_BRICK:0)
Block(-1,-44,-4,SMOOTH_BRICK:0)
Block(-1,-44,-3,SMOOTH_BRICK:1)
Block(-1,-44,-2,SMOOTH_BRICK:1)
Block(-1,-44,-1,STONE:5)
Block(-1,-44,0,LOG:0)
Block(-1,-43,-7,SMOOTH_BRICK:2)
Block(-1,-43,-6,SMOOTH_BRICK:1)
Block(-1,-43,-5,SMOOTH_BRICK:0)
Block(-1,-43,-4,SMOOTH_BRICK:0)
Block(-1,-43,-3,SMOOTH_BRICK:1)
Block(-1,-43,-2,SMOOTH_BRICK:1)
Block(-1,-43,-1,STONE:5)
Block(-1,-43,0,LOG:0)
Block(-1,-42,-7,SMOOTH_BRICK:2)
Block(-1,-42,-6,SMOOTH_BRICK:1)
Block(-1,-42,-5,SMOOTH_BRICK:0)
Block(-1,-42,-4,SMOOTH_BRICK:0)
Block(-1,-42,-3,SMOOTH_BRICK:1)
Block(-1,-42,-2,SMOOTH_BRICK:1)
Block(-1,-42,-1,STONE:5)
Block(-1,-42,0,LOG:0)
Block(-1,-41,-7,SMOOTH_BRICK:2)
Block(-1,-41,-6,SMOOTH_BRICK:1)
Block(-1,-41,-5,SMOOTH_BRICK:0)
Block(-1,-41,-4,SMOOTH_BRICK:0)
Block(-1,-41,-3,SMOOTH_BRICK:1)
Block(-1,-41,-2,SMOOTH_BRICK:1)
Block(-1,-41,-1,STONE:5)
Block(-1,-41,0,LOG:0)
Block(-1,-40,-7,SMOOTH_BRICK:2)
Block(-1,-40,-6,SMOOTH_BRICK:1)
Block(-1,-40,-5,SMOOTH_BRICK:0)
Block(-1,-40,-4,SMOOTH_BRICK:0)
Block(-1,-40,-3,SMOOTH_BRICK:1)
Block(-1,-40,-2,SMOOTH_BRICK:1)
Block(-1,-40,-1,STONE:5)
Block(-1,-40,0,LOG:0)
Block(-1,-39,-7,SMOOTH_BRICK:2)
Block(-1,-39,-6,SMOOTH_BRICK:1)
Block(-1,-39,-5,SMOOTH_BRICK:0)
Block(-1,-39,-4,SMOOTH_BRICK:0)
Block(-1,-39,-3,SMOOTH_BRICK:1)
Block(-1,-39,-2,SMOOTH_BRICK:1)
Block(-1,-39,-1,STONE:5)
Block(-1,-39,0,LOG:0)
Block(-1,-38,-7,SMOOTH_BRICK:2)
Block(-1,-38,-6,SMOOTH_BRICK:1)
Block(-1,-38,-5,SMOOTH_BRICK:0)
Block(-1,-38,-4,SMOOTH_BRICK:0)
Block(-1,-38,-3,SMOOTH_BRICK:1)
Block(-1,-38,-2,SMOOTH_BRICK:1)
Block(-1,-38,-1,STONE:5)
Block(-1,-38,0,LOG:0)
Block(-1,-37,-7,SMOOTH_BRICK:2)
Block(-1,-37,-6,SMOOTH_BRICK:1)
Block(-1,-37,-5,SMOOTH_BRICK:0)
Block(-1,-37,-4,SMOOTH_BRICK:0)
Block(-1,-37,-3,SMOOTH_BRICK:1)
Block(-1,-37,-2,SMOOTH_BRICK:1)
Block(-1,-37,-1,STONE:5)
Block(-1,-37,0,LOG:0)
Block(-1,-36,-7,SMOOTH_BRICK:2)
Block(-1,-36,-6,SMOOTH_BRICK:1)
Block(-1,-36,-5,SMOOTH_BRICK:0)
Block(-1,-36,-4,SMOOTH_BRICK:0)
Block(-1,-36,-3,SMOOTH_BRICK:1)
Block(-1,-36,-2,SMOOTH_BRICK:1)
Block(-1,-36,-1,STONE:5)
Block(-1,-36,0,LOG:0)
Block(-1,-35,-7,SMOOTH_BRICK:2)
Block(-1,-35,-6,SMOOTH_BRICK:1)
Block(-1,-35,-5,SMOOTH_BRICK:0)
Block(-1,-35,-4,SMOOTH_BRICK:0)
Block(-1,-35,-3,SMOOTH_BRICK:1)
Block(-1,-35,-2,SMOOTH_BRICK:1)
Block(-1,-35,-1,STONE:5)
Block(-1,-35,0,LOG:0)
Block(-1,-34,-7,SMOOTH_BRICK:2)
Block(-1,-34,-6,SMOOTH_BRICK:1)
Block(-1,-34,-5,SMOOTH_BRICK:0)
Block(-1,-34,-4,SMOOTH_BRICK:0)
Block(-1,-34,-3,SMOOTH_BRICK:1)
Block(-1,-34,-2,SMOOTH_BRICK:1)
Block(-1,-34,-1,STONE:5)
Block(-1,-34,0,LOG:0)
Block(-1,-33,-7,SMOOTH_BRICK:2)
Block(-1,-33,-6,SMOOTH_BRICK:1)
Block(-1,-33,-5,SMOOTH_BRICK:0)
Block(-1,-33,-4,SMOOTH_BRICK:0)
Block(-1,-33,-3,SMOOTH_BRICK:1)
Block(-1,-33,-2,SMOOTH_BRICK:1)
Block(-1,-33,-1,STONE:5)
Block(-1,-33,0,LOG:0)
Block(-1,-32,-7,SMOOTH_BRICK:2)
Block(-1,-32,-6,SMOOTH_BRICK:1)
Block(-1,-32,-5,SMOOTH_BRICK:0)
Block(-1,-32,-4,SMOOTH_BRICK:0)
Block(-1,-32,-3,SMOOTH_BRICK:1)
Block(-1,-32,-2,SMOOTH_BRICK:1)
Block(-1,-32,-1,STONE:5)
Block(-1,-32,0,LOG:0)
Block(-1,-31,-7,SMOOTH_BRICK:2)
Block(-1,-31,-6,SMOOTH_BRICK:1)
Block(-1,-31,-5,SMOOTH_BRICK:0)
Block(-1,-31,-4,SMOOTH_BRICK:0)
Block(-1,-31,-3,SMOOTH_BRICK:1)
Block(-1,-31,-2,SMOOTH_BRICK:1)
Block(-1,-31,-1,STONE:5)
Block(-1,-31,0,LOG:0)
Block(-1,-30,-7,SMOOTH_BRICK:2)
Block(-1,-30,-6,SMOOTH_BRICK:1)
Block(-1,-30,-5,SMOOTH_BRICK:0)
Block(-1,-30,-4,SMOOTH_BRICK:0)
Block(-1,-30,-3,SMOOTH_BRICK:1)
Block(-1,-30,-2,SMOOTH_BRICK:1)
Block(-1,-30,-1,STONE:5)
Block(-1,-30,0,LOG:0)
Block(-1,-29,-7,SMOOTH_BRICK:2)
Block(-1,-29,-6,SMOOTH_BRICK:1)
Block(-1,-29,-5,SMOOTH_BRICK:0)
Block(-1,-29,-4,SMOOTH_BRICK:0)
Block(-1,-29,-3,SMOOTH_BRICK:1)
Block(-1,-29,-2,SMOOTH_BRICK:1)
Block(-1,-29,-1,STONE:5)
Block(-1,-29,0,LOG:0)
Block(-1,-28,-7,SMOOTH_BRICK:2)
Block(-1,-28,-6,SMOOTH_BRICK:1)
Block(-1,-28,-5,SMOOTH_BRICK:0)
Block(-1,-28,-4,SMOOTH_BRICK:0)
Block(-1,-28,-3,SMOOTH_BRICK:1)
Block(-1,-28,-2,SMOOTH_BRICK:1)
Block(-1,-28,-1,STONE:5)
Block(-1,-28,0,LOG:0)
Block(-1,-27,-7,SMOOTH_BRICK:2)
Block(-1,-27,-6,SMOOTH_BRICK:1)
Block(-1,-27,-5,SMOOTH_BRICK:0)
Block(-1,-27,-4,SMOOTH_BRICK:0)
Block(-1,-27,-3,SMOOTH_BRICK:1)
Block(-1,-27,-2,SMOOTH_BRICK:1)
Block(-1,-27,-1,STONE:5)
Block(-1,-27,0,LOG:0)
Block(-1,-26,-7,SMOOTH_BRICK:2)
Block(-1,-26,-6,SMOOTH_BRICK:1)
Block(-1,-26,-5,SMOOTH_BRICK:0)
Block(-1,-26,-4,SMOOTH_BRICK:0)
Block(-1,-26,-3,SMOOTH_BRICK:1)
Block(-1,-26,-2,SMOOTH_BRICK:1)
Block(-1,-26,-1,STONE:5)
Block(-1,-26,0,LOG:0)
Block(-1,-25,-7,SMOOTH_BRICK:2)
Block(-1,-25,-6,SMOOTH_BRICK:1)
Block(-1,-25,-5,SMOOTH_BRICK:0)
Block(-1,-25,-4,SMOOTH_BRICK:0)
Block(-1,-25,-3,SMOOTH_BRICK:1)
Block(-1,-25,-2,SMOOTH_BRICK:1)
Block(-1,-25,-1,STONE:5)
Block(-1,-25,0,LOG:0)
Block(-1,-24,-7,SMOOTH_BRICK:2)
Block(-1,-24,-6,SMOOTH_BRICK:1)
Block(-1,-24,-5,SMOOTH_BRICK:0)
Block(-1,-24,-4,SMOOTH_BRICK:0)
Block(-1,-24,-3,SMOOTH_BRICK:1)
Block(-1,-24,-2,SMOOTH_BRICK:1)
Block(-1,-24,-1,STONE:5)
Block(-1,-24,0,LOG:0)
Block(-1,-23,-7,SMOOTH_BRICK:2)
Block(-1,-23,-6,SMOOTH_BRICK:1)
Block(-1,-23,-5,SMOOTH_BRICK:0)
Block(-1,-23,-4,SMOOTH_BRICK:0)
Block(-1,-23,-3,SMOOTH_BRICK:1)
Block(-1,-23,-2,SMOOTH_BRICK:1)
Block(-1,-23,-1,STONE:5)
Block(-1,-23,0,LOG:0)
Block(-1,-22,-7,SMOOTH_BRICK:2)
Block(-1,-22,-6,SMOOTH_BRICK:1)
Block(-1,-22,-5,SMOOTH_BRICK:0)
Block(-1,-22,-4,SMOOTH_BRICK:0)
Block(-1,-22,-3,SMOOTH_BRICK:1)
Block(-1,-22,-2,SMOOTH_BRICK:1)
Block(-1,-22,-1,STONE:5)
Block(-1,-22,0,LOG:0)
Block(-1,-21,-7,SMOOTH_BRICK:2)
Block(-1,-21,-6,SMOOTH_BRICK:1)
Block(-1,-21,-5,SMOOTH_BRICK:0)
Block(-1,-21,-4,SMOOTH_BRICK:0)
Block(-1,-21,-3,SMOOTH_BRICK:1)
Block(-1,-21,-2,SMOOTH_BRICK:1)
Block(-1,-21,-1,STONE:5)
Block(-1,-21,0,LOG:0)
Block(-1,-20,-7,SMOOTH_BRICK:2)
Block(-1,-20,-6,SMOOTH_BRICK:1)
Block(-1,-20,-5,SMOOTH_BRICK:0)
Block(-1,-20,-4,SMOOTH_BRICK:0)
Block(-1,-20,-3,SMOOTH_BRICK:1)
Block(-1,-20,-2,SMOOTH_BRICK:1)
Block(-1,-20,-1,STONE:5)
Block(-1,-20,0,LOG:0)
Block(-1,-19,-7,SMOOTH_BRICK:0)
Block(-1,-19,-6,STONE:5)
Block(-1,-19,-5,STONE:5)
Block(-1,-19,-4,SMOOTH_BRICK:2)
Block(-1,-19,-3,STONE:5)
Block(-1,-19,-2,STAINED_CLAY:9)
Block(-1,-19,-1,SMOOTH_BRICK:1)
Block(-1,-19,0,LOG:0)
Block(-1,-18,-7,SMOOTH_BRICK:0)
Block(-1,-18,-6,COBBLESTONE:0)
Block(-1,-18,-5,SMOOTH_BRICK:0)
Block(-1,-18,-4,SMOOTH_BRICK:2)
Block(-1,-18,-3,STONE:5)
Block(-1,-18,-2,COBBLESTONE:0)
Block(-1,-18,-1,STONE:5)
Block(-1,-18,0,LOG:0)
Block(-1,-17,-7,STONE:5)
Block(-1,-17,-6,STAINED_CLAY:9)
Block(-1,-17,-5,SMOOTH_BRICK:0)
Block(-1,-17,-4,SMOOTH_BRICK:2)
Block(-1,-17,-3,COBBLESTONE:0)
Block(-1,-17,-2,COBBLESTONE:0)
Block(-1,-17,-1,SMOOTH_BRICK:2)
Block(-1,-17,0,LOG:0)
Block(-1,-16,-7,SMOOTH_BRICK:1)
Block(-1,-16,-6,SMOOTH_BRICK:0)
Block(-1,-16,-5,STONE:5)
Block(-1,-16,-4,STONE:5)
Block(-1,-16,-3,SMOOTH_BRICK:1)
Block(-1,-16,-2,SMOOTH_BRICK:2)
Block(-1,-16,-1,SMOOTH_BRICK:2)
Block(-1,-16,0,LOG:0)
Block(-1,-15,-7,SMOOTH_BRICK:0)
Block(-1,-15,-6,STONE:5)
Block(-1,-15,-5,STONE:5)
Block(-1,-15,-4,COBBLESTONE:0)
Block(-1,-15,-3,STONE:5)
Block(-1,-15,-2,STONE:5)
Block(-1,-15,-1,SMOOTH_BRICK:2)
Block(-1,-15,0,LOG:0)
Block(-1,-14,-7,SMOOTH_BRICK:0)
Block(-1,-14,-6,STONE:5)
Block(-1,-14,-5,STONE:5)
Block(-1,-14,-4,SMOOTH_BRICK:0)
Block(-1,-14,-3,COBBLESTONE:0)
Block(-1,-14,-2,SMOOTH_BRICK:2)
Block(-1,-14,-1,SMOOTH_BRICK:0)
Block(-1,-14,0,LOG:0)
Block(-1,-13,-7,STONE:5)
Block(-1,-13,-6,SMOOTH_BRICK:1)
Block(-1,-13,-5,SMOOTH_BRICK:0)
Block(-1,-13,-4,COBBLESTONE:0)
Block(-1,-13,-3,COBBLESTONE:0)
Block(-1,-13,-2,STONE:5)
Block(-1,-13,-1,SMOOTH_BRICK:2)
Block(-1,-13,0,LOG:0)
Block(-1,-12,-7,SMOOTH_BRICK:0)
Block(-1,-12,-6,SMOOTH_BRICK:1)
Block(-1,-12,-5,STONE:5)
Block(-1,-12,-4,STONE:5)
Block(-1,-12,-3,STONE:5)
Block(-1,-12,-2,SMOOTH_BRICK:2)
Block(-1,-12,-1,COBBLESTONE:0)
Block(-1,-12,0,LOG:0)
Block(-1,-11,-7,STAINED_CLAY:9)
Block(-1,-11,-6,STONE:5)
Block(-1,-11,-5,SMOOTH_BRICK:1)
Block(-1,-11,-4,SMOOTH_BRICK:0)
Block(-1,-11,-3,STONE:5)
Block(-1,-11,-2,SMOOTH_BRICK:1)
Block(-1,-11,-1,STONE:5)
Block(-1,-11,0,LOG:0)
Block(-1,-10,-7,COBBLESTONE:0)
Block(-1,-10,-6,STONE:5)
Block(-1,-10,-5,STONE:5)
Block(-1,-10,-4,SMOOTH_BRICK:2)
Block(-1,-10,-3,STONE:5)
Block(-1,-10,-2,SMOOTH_BRICK:0)
Block(-1,-10,-1,STONE:5)
Block(-1,-10,0,LOG:0)
Block(-1,-9,-7,STONE:6)
Block(-1,-9,-6,STONE:6)
Block(-1,-9,-5,STONE:6)
Block(-1,-9,-4,STONE:6)
Block(-1,-9,-3,STONE:6)
Block(-1,-9,-2,STONE:6)
Block(-1,-9,-1,COBBLESTONE_STAIRS:0)
Block(-1,-9,0,SMOOTH_STAIRS:3)
Block(-1,-8,-7,STONE:5)
Block(-1,-8,-6,STONE:5)
Block(-1,-8,-5,STONE:5)
Block(-1,-8,-4,SMOOTH_BRICK:2)
Block(-1,-8,-3,STONE:5)
Block(-1,-8,-2,STONE:6)
Block(-1,-7,-7,STONE:5)
Block(-1,-7,-6,STONE:5)
Block(-1,-7,-5,STONE:5)
Block(-1,-7,-4,STONE:5)
Block(-1,-7,-3,SMOOTH_BRICK:0)
Block(-1,-7,-2,STONE:6)
Block(-1,-6,-7,SMOOTH_BRICK:0)
Block(-1,-6,-6,SMOOTH_BRICK:2)
Block(-1,-6,-5,SMOOTH_BRICK:0)
Block(-1,-6,-4,SMOOTH_BRICK:0)
Block(-1,-6,-3,COBBLESTONE:0)
Block(-1,-6,-2,STONE:6)
Block(-1,-5,-7,SMOOTH_BRICK:0)
Block(-1,-5,-6,STONE:5)
Block(-1,-5,-5,SMOOTH_BRICK:2)
Block(-1,-5,-4,SMOOTH_BRICK:0)
Block(-1,-5,-3,SMOOTH_BRICK:2)
Block(-1,-5,-2,STEP:3)
Block(-1,-4,-7,STONE:6)
Block(-1,-4,-6,STONE:6)
Block(-1,-4,-5,STONE:6)
Block(-1,-4,-4,STONE:6)
Block(-1,-4,-3,LOG:4)
Block(-1,-3,-7,STONE:6)
Block(-1,-3,-6,STONE:6)
Block(-1,-3,-5,STONE:6)
Block(-1,-3,-4,STONE:6)
Block(-1,-3,-3,LOG:0)
Block(-1,-2,-7,STONE:6)
Block(-1,-2,-6,STONE:6)
Block(-1,-2,-5,STONE:6)
Block(-1,-2,-4,STONE:6)
Block(-1,-2,-3,LOG:0)
Block(-1,-1,-7,STONE:6)
Block(-1,-1,-6,STONE:6)
Block(-1,-1,-5,STONE:6)
Block(-1,-1,-4,STONE:6)
Block(-1,-1,-3,LOG:0)
Block(-1,0,-7,STONE:6)
Block(-1,0,-6,STONE:6)
Block(-1,0,-5,STONE:6)
Block(-1,0,-4,STONE:6)
Block(-1,0,-3,LOG:0)
Block(-1,1,-7,STONE:6)
Block(-1,1,-6,STONE:6)
Block(-1,1,-5,STONE:6)
Block(-1,1,-4,STONE:6)
Block(-1,1,-3,LOG:0)
Block(-1,2,-7,SMOOTH_BRICK:0)
Block(-1,2,-6,SMOOTH_BRICK:0)
Block(-1,2,-5,SMOOTH_BRICK:0)
Block(-1,2,-4,SMOOTH_BRICK:0)
Block(-1,2,-3,LOG:0)
Block(-1,3,-7,SMOOTH_BRICK:0)
Block(-1,3,-6,SMOOTH_BRICK:0)
Block(-1,3,-5,SMOOTH_BRICK:0)
Block(-1,3,-4,SMOOTH_BRICK:0)
Block(-1,3,-3,LOG:0)
Block(-1,4,-7,COBBLESTONE:0)
Block(-1,4,-6,COBBLESTONE:0)
Block(-1,4,-5,COBBLESTONE:0)
Block(-1,4,-4,COBBLESTONE:0)
Block(-1,4,-3,LOG:0)
Block(-1,5,-7,COBBLESTONE:0)
Block(-1,5,-6,COBBLESTONE:0)
Block(-1,5,-5,COBBLESTONE:0)
Block(-1,5,-4,COBBLESTONE:0)
Block(-1,5,-3,LOG:0)
Block(-1,6,-7,COBBLESTONE:0)
Block(-1,6,-6,COBBLESTONE:0)
Block(-1,6,-5,COBBLESTONE:0)
Block(-1,6,-4,COBBLESTONE:0)
Block(-1,6,-3,LOG:0)
Block(-1,7,-7,COBBLESTONE:0)
Block(-1,7,-6,COBBLESTONE:0)
Block(-1,7,-5,COBBLESTONE:0)
Block(-1,7,-4,COBBLESTONE:0)
Block(-1,7,-3,LOG:0)
Block(-1,8,-7,STONE:6)
Block(-1,8,-6,LOG:4)
Block(-1,8,-5,WOOD_STEP:13)
Block(-1,8,-4,WOOD_STEP:13)
Block(-1,8,-3,COBBLESTONE:0)
Block(-1,9,-7,STONE:6)
Block(-1,9,-6,STONE:6)
Block(-1,9,-5,AIR:0)
Block(-1,9,-4,AIR:0)
Block(-1,9,-3,STEP:0)
Block(-1,10,-7,STONE:6)
Block(-1,10,-6,STONE:6)
Block(-1,10,-5,AIR:0)
Block(-1,10,-4,AIR:0)
Block(-1,10,-3,AIR:0)
Block(-1,10,-2,WOOD_STEP:13)
Block(-1,11,-7,WOOD_STEP:13)
Block(-1,11,-6,LOG:4)
Block(-1,11,-5,DOUBLE_STEP:5)
Block(-1,11,-4,WOOD_STEP:5)
Block(-1,11,-3,WOOD_STEP:5)
Block(-1,12,-7,SMOOTH_BRICK:0)
Block(-1,12,-6,SMOOTH_BRICK:0)
Block(-1,12,-5,SMOOTH_BRICK:0)
Block(-1,12,-4,AIR:0)
Block(-1,12,-3,AIR:0)
Block(-1,13,-7,SMOOTH_BRICK:0)
Block(-1,13,-6,COBBLESTONE:0)
Block(-1,13,-5,COBBLESTONE:0)
Block(-1,13,-4,AIR:0)
Block(-1,13,-3,AIR:0)
Block(-1,14,-7,SMOOTH_BRICK:0)
Block(-1,14,-6,SMOOTH_BRICK:0)
Block(-1,14,-5,SMOOTH_BRICK:0)
Block(-1,14,-4,AIR:0)
Block(-1,14,-3,AIR:0)
Block(-1,15,-7,COBBLESTONE_STAIRS:2)
Block(-1,15,-6,WOOD_STEP:5)
Block(-1,15,-5,SMOOTH_BRICK:0)
Block(-1,15,-4,AIR:0)
Block(-1,15,-3,AIR:0)
Block(-1,16,-7,WOOD_STEP:5)
Block(-1,16,-6,WOOD_STEP:13)
Block(-1,16,-5,SMOOTH_BRICK:0)
Block(-1,16,-4,AIR:0)
Block(-1,16,-3,AIR:0)
Block(-1,17,-7,WOOD_STEP:13)
Block(-1,17,-6,SMOOTH_BRICK:0)
Block(-1,17,-5,SMOOTH_BRICK:0)
Block(-1,17,-4,AIR:0)
Block(-1,17,-3,AIR:0)
Block(-1,18,-7,SMOOTH_BRICK:0)
Block(-1,18,-6,SMOOTH_BRICK:0)
Block(-1,18,-5,SMOOTH_BRICK:0)
Block(-1,18,-4,AIR:0)
Block(-1,18,-3,AIR:0)
Block(-1,19,-7,SMOOTH_BRICK:0)
Block(-1,19,-6,SMOOTH_BRICK:0)
Block(-1,19,-5,SMOOTH_BRICK:0)
Block(-1,19,-4,AIR:0)
Block(-1,19,-3,AIR:0)
Block(-1,20,-7,STONE:6)
Block(-1,20,-6,LOG:4)
Block(-1,20,-5,SMOOTH_STAIRS:0)
Block(-1,20,-4,AIR:0)
Block(-1,20,-3,AIR:0)
Block(-1,21,-7,SMOOTH_BRICK:0)
Block(-1,21,-6,LOG:4)
Block(-1,21,-5,AIR:0)
Block(-1,21,-4,AIR:0)
Block(-1,21,-3,AIR:0)
Block(-1,22,-7,SMOOTH_BRICK:0)
Block(-1,22,-6,COBBLE_WALL:0)
Block(-1,22,-5,AIR:0)
Block(-1,22,-4,AIR:0)
Block(-1,22,-3,AIR:0)
Block(-1,23,-7,SMOOTH_BRICK:0)
Block(-1,23,-6,COBBLE_WALL:0)
Block(-1,23,-5,AIR:0)
Block(-1,23,-4,AIR:0)
Block(-1,23,-3,AIR:0)
Block(-1,24,-7,COBBLESTONE_STAIRS:3)
Block(-1,24,-6,COBBLE_WALL:0)
Block(-1,24,-5,AIR:0)
Block(-1,24,-4,AIR:0)
Block(-1,24,-3,AIR:0)
Block(-1,25,-7,AIR:0)
Block(-1,25,-6,COBBLE_WALL:0)
Block(-1,25,-5,AIR:0)
Block(-1,25,-4,AIR:0)
Block(-1,25,-3,AIR:0)
Block(-1,26,-7,AIR:0)
Block(-1,26,-6,DARK_OAK_FENCE:0)
Block(-1,26,-5,AIR:0)
Block(-1,26,-4,AIR:0)
Block(-1,26,-3,AIR:0)
Block(-1,27,-7,AIR:0)
Block(-1,27,-6,AIR:0)
Block(-1,27,-5,AIR:0)
Block(-1,27,-4,AIR:0)
Block(-1,27,-3,AIR:0)
Block(-1,28,-7,AIR:0)
Block(-1,28,-6,AIR:0)
Block(-1,28,-5,AIR:0)
Block(-1,28,-4,AIR:0)
Block(-1,28,-3,AIR:0)
Block(-1,29,-7,AIR:0)
Block(-1,29,-6,AIR:0)
Block(-1,29,-5,AIR:0)
Block(-1,29,-4,AIR:0)
Block(-1,29,-3,AIR:0)
Block(-1,30,-7,AIR:0)
Block(-1,30,-6,AIR:0)
Block(-1,30,-5,AIR:0)
Block(-1,30,-4,AIR:0)
Block(-1,30,-3,AIR:0)
Block(-1,31,-7,AIR:0)
Block(-1,31,-6,AIR:0)
Block(-1,31,-5,AIR:0)
Block(-1,31,-4,AIR:0)
Block(-1,31,-3,AIR:0)
Block(-1,32,-7,AIR:0)
Block(-1,32,-6,AIR:0)
Block(-1,32,-5,AIR:0)
Block(-1,32,-4,AIR:0)
Block(-1,32,-3,AIR:0)
Block(-1,33,-7,AIR:0)
Block(-1,33,-6,AIR:0)
Block(-1,33,-5,AIR:0)
Block(-1,33,-4,AIR:0)
Block(-1,33,-3,AIR:0)
Block(-1,34,-7,AIR:0)
Block(-1,34,-6,AIR:0)
Block(-1,34,-5,AIR:0)
Block(-1,34,-4,AIR:0)
Block(-1,34,-3,AIR:0)
Block(-1,35,-7,AIR:0)
Block(-1,35,-6,AIR:0)
Block(-1,35,-5,AIR:0)
Block(-1,35,-4,AIR:0)
Block(-1,35,-3,AIR:0)
Block(-1,36,-7,AIR:0)
Block(-1,36,-6,AIR:0)
Block(-1,36,-5,AIR:0)
Block(-1,36,-4,AIR:0)
Block(-1,36,-3,AIR:0)
Block(-1,37,-7,AIR:0)
Block(-1,37,-6,AIR:0)
Block(-1,37,-5,AIR:0)
Block(-1,37,-4,AIR:0)
Block(-1,37,-3,AIR:0)
Block(-1,38,-7,AIR:0)
Block(-1,38,-6,AIR:0)
Block(-1,38,-5,AIR:0)
Block(-1,38,-4,AIR:0)
Block(-1,38,-3,AIR:0)
Block(-1,39,-7,WALL_BANNER:4,origin/1668-bannerC112R320.nbt)
Block(-1,39,-6,AIR:0)
Block(-1,39,-5,AIR:0)
Block(-1,39,-4,AIR:0)
Block(-1,39,-3,AIR:0)
Block(-1,40,-7,AIR:0)
Block(-1,40,-6,AIR:0)
Block(-1,40,-5,AIR:0)
Block(-1,40,-4,AIR:0)
Block(-1,40,-3,AIR:0)
Block(-1,41,-7,AIR:0)
Block(-1,41,-6,AIR:0)
Block(-1,41,-5,AIR:0)
Block(-1,41,-4,AIR:0)
Block(-1,41,-3,AIR:0)
Block(-1,42,-7,AIR:0)
Block(-1,42,-6,AIR:0)
Block(-1,42,-5,AIR:0)
Block(-1,42,-4,AIR:0)
Block(-1,42,-3,AIR:0)
Block(-1,43,-7,AIR:0)
Block(-1,43,-6,AIR:0)
Block(-1,43,-5,AIR:0)
Block(-1,43,-4,AIR:0)
Block(-1,43,-3,AIR:0)
Block(-1,44,-7,AIR:0)
Block(-1,44,-6,AIR:0)
Block(-1,44,-5,AIR:0)
Block(-1,44,-4,AIR:0)
Block(-1,44,-3,AIR:0)
Block(-1,45,-7,AIR:0)
Block(-1,45,-6,AIR:0)
Block(-1,45,-5,AIR:0)
Block(-1,45,-4,AIR:0)
Block(-1,45,-3,AIR:0)
Block(-1,46,-7,AIR:0)
Block(-1,46,-6,AIR:0)
Block(-1,46,-5,AIR:0)
Block(-1,46,-4,AIR:0)
Block(-1,46,-3,AIR:0)
Block(-1,47,-7,AIR:0)
Block(-1,47,-6,AIR:0)
Block(-1,47,-5,AIR:0)
Block(-1,47,-4,AIR:0)
Block(-1,47,-3,AIR:0)
Block(-1,48,-7,AIR:0)
Block(-1,48,-6,AIR:0)
Block(-1,48,-5,AIR:0)
Block(-1,48,-4,AIR:0)
Block(-1,48,-3,AIR:0)
Block(-1,49,-7,AIR:0)
Block(-1,49,-6,AIR:0)
Block(-1,49,-5,WOOL:14)
Block(-1,49,-4,AIR:0)
Block(-1,49,-3,AIR:0)
Block(-1,50,-7,AIR:0)
Block(-1,50,-6,AIR:0)
Block(-1,50,-5,AIR:0)
Block(-1,50,-4,AIR:0)
Block(-1,50,-3,AIR:0)
Block(-1,51,-7,AIR:0)
Block(-1,51,-6,AIR:0)
Block(-1,51,-5,AIR:0)
Block(-1,51,-4,AIR:0)
Block(-1,51,-3,AIR:0)
Block(-1,52,-7,AIR:0)
Block(-1,52,-6,AIR:0)
Block(-1,52,-5,AIR:0)
Block(-1,52,-4,AIR:0)
Block(-1,52,-3,AIR:0)
Block(-1,53,-7,AIR:0)
Block(-1,53,-6,AIR:0)
Block(-1,53,-5,AIR:0)
Block(-1,53,-4,AIR:0)
Block(-1,53,-3,AIR:0)
Block(-1,54,-7,AIR:0)
Block(-1,54,-6,AIR:0)
Block(-1,54,-5,AIR:0)
Block(-1,54,-4,AIR:0)
Block(-1,54,-3,AIR:0)
Block(-1,55,-7,AIR:0)
Block(-1,55,-6,AIR:0)
Block(-1,55,-5,AIR:0)
Block(-1,55,-4,AIR:0)
Block(-1,55,-3,AIR:0)
Block(-1,56,-7,AIR:0)
Block(-1,56,-6,AIR:0)
Block(-1,56,-5,AIR:0)
Block(-1,56,-4,AIR:0)
Block(-1,56,-3,AIR:0)
Block(-1,57,-7,AIR:0)
Block(-1,57,-6,AIR:0)
Block(-1,57,-5,AIR:0)
Block(-1,57,-4,AIR:0)
Block(-1,57,-3,AIR:0)
Block(-1,58,-7,AIR:0)
Block(-1,58,-6,AIR:0)
Block(-1,58,-5,AIR:0)
Block(-1,58,-4,AIR:0)
Block(-1,58,-3,AIR:0)
Block(-1,59,-7,AIR:0)
Block(-1,59,-6,AIR:0)
Block(-1,59,-5,AIR:0)
Block(-1,59,-4,AIR:0)
Block(-1,59,-3,AIR:0)
Block(-1,60,-7,AIR:0)
Block(-1,60,-6,AIR:0)
Block(-1,60,-5,AIR:0)
Block(-1,60,-4,AIR:0)
Block(-1,60,-3,AIR:0)
Block(-1,61,-7,AIR:0)
Block(-1,61,-6,AIR:0)
Block(-1,61,-5,AIR:0)
Block(-1,61,-4,AIR:0)
Block(-1,61,-3,AIR:0)
Block(-1,62,-7,AIR:0)
Block(-1,62,-6,AIR:0)
Block(-1,62,-5,AIR:0)
Block(-1,62,-4,AIR:0)
Block(-1,62,-3,AIR:0)
Block(-1,63,-7,AIR:0)
Block(-1,63,-6,AIR:0)
Block(-1,63,-5,AIR:0)
Block(-1,63,-4,AIR:0)
Block(-1,63,-3,AIR:0)
Block(0,-50,-7,STONE:5)
Block(0,-50,-6,STONE:5)
Block(0,-50,-5,SMOOTH_BRICK:2)
Block(0,-50,-4,STONE:5)
Block(0,-50,-3,STONE:5)
Block(0,-50,-2,SMOOTH_BRICK:1)
Block(0,-50,-1,STONE:5)
Block(0,-50,0,SMOOTH_BRICK:2)
Block(0,-50,1,SMOOTH_BRICK:0)
Block(0,-49,-7,STONE:5)
Block(0,-49,-6,STONE:5)
Block(0,-49,-5,SMOOTH_BRICK:2)
Block(0,-49,-4,STONE:5)
Block(0,-49,-3,STONE:5)
Block(0,-49,-2,SMOOTH_BRICK:1)
Block(0,-49,-1,STONE:5)
Block(0,-49,0,SMOOTH_BRICK:2)
Block(0,-49,1,SMOOTH_BRICK:0)
Block(0,-48,-7,STONE:5)
Block(0,-48,-6,STONE:5)
Block(0,-48,-5,SMOOTH_BRICK:2)
Block(0,-48,-4,STONE:5)
Block(0,-48,-3,STONE:5)
Block(0,-48,-2,SMOOTH_BRICK:1)
Block(0,-48,-1,STONE:5)
Block(0,-48,0,SMOOTH_BRICK:2)
Block(0,-48,1,SMOOTH_BRICK:0)
Block(0,-47,-7,STONE:5)
Block(0,-47,-6,STONE:5)
Block(0,-47,-5,SMOOTH_BRICK:2)
Block(0,-47,-4,STONE:5)
Block(0,-47,-3,STONE:5)
Block(0,-47,-2,SMOOTH_BRICK:1)
Block(0,-47,-1,STONE:5)
Block(0,-47,0,SMOOTH_BRICK:2)
Block(0,-47,1,SMOOTH_BRICK:0)
Block(0,-46,-7,STONE:5)
Block(0,-46,-6,STONE:5)
Block(0,-46,-5,SMOOTH_BRICK:2)
Block(0,-46,-4,STONE:5)
Block(0,-46,-3,STONE:5)
Block(0,-46,-2,SMOOTH_BRICK:1)
Block(0,-46,-1,STONE:5)
Block(0,-46,0,SMOOTH_BRICK:2)
Block(0,-46,1,SMOOTH_BRICK:0)
Block(0,-45,-7,STONE:5)
Block(0,-45,-6,STONE:5)
Block(0,-45,-5,SMOOTH_BRICK:2)
Block(0,-45,-4,STONE:5)
Block(0,-45,-3,STONE:5)
Block(0,-45,-2,SMOOTH_BRICK:1)
Block(0,-45,-1,STONE:5)
Block(0,-45,0,SMOOTH_BRICK:2)
Block(0,-45,1,SMOOTH_BRICK:0)
Block(0,-44,-7,STONE:5)
Block(0,-44,-6,STONE:5)
Block(0,-44,-5,SMOOTH_BRICK:2)
Block(0,-44,-4,STONE:5)
Block(0,-44,-3,STONE:5)
Block(0,-44,-2,SMOOTH_BRICK:1)
Block(0,-44,-1,STONE:5)
Block(0,-44,0,SMOOTH_BRICK:2)
Block(0,-44,1,SMOOTH_BRICK:0)
Block(0,-43,-7,STONE:5)
Block(0,-43,-6,STONE:5)
Block(0,-43,-5,SMOOTH_BRICK:2)
Block(0,-43,-4,STONE:5)
Block(0,-43,-3,STONE:5)
Block(0,-43,-2,SMOOTH_BRICK:1)
Block(0,-43,-1,STONE:5)
Block(0,-43,0,SMOOTH_BRICK:2)
Block(0,-43,1,SMOOTH_BRICK:0)
Block(0,-42,-7,STONE:5)
Block(0,-42,-6,STONE:5)
Block(0,-42,-5,SMOOTH_BRICK:2)
Block(0,-42,-4,STONE:5)
Block(0,-42,-3,STONE:5)
Block(0,-42,-2,SMOOTH_BRICK:1)
Block(0,-42,-1,STONE:5)
Block(0,-42,0,SMOOTH_BRICK:2)
Block(0,-42,1,SMOOTH_BRICK:0)
Block(0,-41,-7,STONE:5)
Block(0,-41,-6,STONE:5)
Block(0,-41,-5,SMOOTH_BRICK:2)
Block(0,-41,-4,STONE:5)
Block(0,-41,-3,STONE:5)
Block(0,-41,-2,SMOOTH_BRICK:1)
Block(0,-41,-1,STONE:5)
Block(0,-41,0,SMOOTH_BRICK:2)
Block(0,-41,1,SMOOTH_BRICK:0)
Block(0,-40,-7,STONE:5)
Block(0,-40,-6,STONE:5)
Block(0,-40,-5,SMOOTH_BRICK:2)
Block(0,-40,-4,STONE:5)
Block(0,-40,-3,STONE:5)
Block(0,-40,-2,SMOOTH_BRICK:1)
Block(0,-40,-1,STONE:5)
Block(0,-40,0,SMOOTH_BRICK:2)
Block(0,-40,1,SMOOTH_BRICK:0)
Block(0,-39,-7,STONE:5)
Block(0,-39,-6,STONE:5)
Block(0,-39,-5,SMOOTH_BRICK:2)
Block(0,-39,-4,STONE:5)
Block(0,-39,-3,STONE:5)
Block(0,-39,-2,SMOOTH_BRICK:1)
Block(0,-39,-1,STONE:5)
Block(0,-39,0,SMOOTH_BRICK:2)
Block(0,-39,1,SMOOTH_BRICK:0)
Block(0,-38,-7,STONE:5)
Block(0,-38,-6,STONE:5)
Block(0,-38,-5,SMOOTH_BRICK:2)
Block(0,-38,-4,STONE:5)
Block(0,-38,-3,STONE:5)
Block(0,-38,-2,SMOOTH_BRICK:1)
Block(0,-38,-1,STONE:5)
Block(0,-38,0,SMOOTH_BRICK:2)
Block(0,-38,1,SMOOTH_BRICK:0)
Block(0,-37,-7,STONE:5)
Block(0,-37,-6,STONE:5)
Block(0,-37,-5,SMOOTH_BRICK:2)
Block(0,-37,-4,STONE:5)
Block(0,-37,-3,STONE:5)
Block(0,-37,-2,SMOOTH_BRICK:1)
Block(0,-37,-1,STONE:5)
Block(0,-37,0,SMOOTH_BRICK:2)
Block(0,-37,1,SMOOTH_BRICK:0)
Block(0,-36,-7,STONE:5)
Block(0,-36,-6,STONE:5)
Block(0,-36,-5,SMOOTH_BRICK:2)
Block(0,-36,-4,STONE:5)
Block(0,-36,-3,STONE:5)
Block(0,-36,-2,SMOOTH_BRICK:1)
Block(0,-36,-1,STONE:5)
Block(0,-36,0,SMOOTH_BRICK:2)
Block(0,-36,1,SMOOTH_BRICK:0)
Block(0,-35,-7,STONE:5)
Block(0,-35,-6,STONE:5)
Block(0,-35,-5,SMOOTH_BRICK:2)
Block(0,-35,-4,STONE:5)
Block(0,-35,-3,STONE:5)
Block(0,-35,-2,SMOOTH_BRICK:1)
Block(0,-35,-1,STONE:5)
Block(0,-35,0,SMOOTH_BRICK:2)
Block(0,-35,1,SMOOTH_BRICK:0)
Block(0,-34,-7,STONE:5)
Block(0,-34,-6,STONE:5)
Block(0,-34,-5,SMOOTH_BRICK:2)
Block(0,-34,-4,STONE:5)
Block(0,-34,-3,STONE:5)
Block(0,-34,-2,SMOOTH_BRICK:1)
Block(0,-34,-1,STONE:5)
Block(0,-34,0,SMOOTH_BRICK:2)
Block(0,-34,1,SMOOTH_BRICK:0)
Block(0,-33,-7,STONE:5)
Block(0,-33,-6,STONE:5)
Block(0,-33,-5,SMOOTH_BRICK:2)
Block(0,-33,-4,STONE:5)
Block(0,-33,-3,STONE:5)
Block(0,-33,-2,SMOOTH_BRICK:1)
Block(0,-33,-1,STONE:5)
Block(0,-33,0,SMOOTH_BRICK:2)
Block(0,-33,1,SMOOTH_BRICK:0)
Block(0,-32,-7,STONE:5)
Block(0,-32,-6,STONE:5)
Block(0,-32,-5,SMOOTH_BRICK:2)
Block(0,-32,-4,STONE:5)
Block(0,-32,-3,STONE:5)
Block(0,-32,-2,SMOOTH_BRICK:1)
Block(0,-32,-1,STONE:5)
Block(0,-32,0,SMOOTH_BRICK:2)
Block(0,-32,1,SMOOTH_BRICK:0)
Block(0,-31,-7,STONE:5)
Block(0,-31,-6,STONE:5)
Block(0,-31,-5,SMOOTH_BRICK:2)
Block(0,-31,-4,STONE:5)
Block(0,-31,-3,STONE:5)
Block(0,-31,-2,SMOOTH_BRICK:1)
Block(0,-31,-1,STONE:5)
Block(0,-31,0,SMOOTH_BRICK:2)
Block(0,-31,1,SMOOTH_BRICK:0)
Block(0,-30,-7,STONE:5)
Block(0,-30,-6,STONE:5)
Block(0,-30,-5,SMOOTH_BRICK:2)
Block(0,-30,-4,STONE:5)
Block(0,-30,-3,STONE:5)
Block(0,-30,-2,SMOOTH_BRICK:1)
Block(0,-30,-1,STONE:5)
Block(0,-30,0,SMOOTH_BRICK:2)
Block(0,-30,1,SMOOTH_BRICK:0)
Block(0,-29,-7,STONE:5)
Block(0,-29,-6,STONE:5)
Block(0,-29,-5,SMOOTH_BRICK:2)
Block(0,-29,-4,STONE:5)
Block(0,-29,-3,STONE:5)
Block(0,-29,-2,SMOOTH_BRICK:1)
Block(0,-29,-1,STONE:5)
Block(0,-29,0,SMOOTH_BRICK:2)
Block(0,-29,1,SMOOTH_BRICK:0)
Block(0,-28,-7,STONE:5)
Block(0,-28,-6,STONE:5)
Block(0,-28,-5,SMOOTH_BRICK:2)
Block(0,-28,-4,STONE:5)
Block(0,-28,-3,STONE:5)
Block(0,-28,-2,SMOOTH_BRICK:1)
Block(0,-28,-1,STONE:5)
Block(0,-28,0,SMOOTH_BRICK:2)
Block(0,-28,1,SMOOTH_BRICK:0)
Block(0,-27,-7,STONE:5)
Block(0,-27,-6,STONE:5)
Block(0,-27,-5,SMOOTH_BRICK:2)
Block(0,-27,-4,STONE:5)
Block(0,-27,-3,STONE:5)
Block(0,-27,-2,SMOOTH_BRICK:1)
Block(0,-27,-1,STONE:5)
Block(0,-27,0,SMOOTH_BRICK:2)
Block(0,-27,1,SMOOTH_BRICK:0)
Block(0,-26,-7,STONE:5)
Block(0,-26,-6,STONE:5)
Block(0,-26,-5,SMOOTH_BRICK:2)
Block(0,-26,-4,STONE:5)
Block(0,-26,-3,STONE:5)
Block(0,-26,-2,SMOOTH_BRICK:1)
Block(0,-26,-1,STONE:5)
Block(0,-26,0,SMOOTH_BRICK:2)
Block(0,-26,1,SMOOTH_BRICK:0)
Block(0,-25,-7,STONE:5)
Block(0,-25,-6,STONE:5)
Block(0,-25,-5,SMOOTH_BRICK:2)
Block(0,-25,-4,STONE:5)
Block(0,-25,-3,STONE:5)
Block(0,-25,-2,SMOOTH_BRICK:1)
Block(0,-25,-1,STONE:5)
Block(0,-25,0,SMOOTH_BRICK:2)
Block(0,-25,1,SMOOTH_BRICK:0)
Block(0,-24,-7,STONE:5)
Block(0,-24,-6,STONE:5)
Block(0,-24,-5,SMOOTH_BRICK:2)
Block(0,-24,-4,STONE:5)
Block(0,-24,-3,STONE:5)
Block(0,-24,-2,SMOOTH_BRICK:1)
Block(0,-24,-1,STONE:5)
Block(0,-24,0,SMOOTH_BRICK:2)
Block(0,-24,1,SMOOTH_BRICK:0)
Block(0,-23,-7,STONE:5)
Block(0,-23,-6,STONE:5)
Block(0,-23,-5,SMOOTH_BRICK:2)
Block(0,-23,-4,STONE:5)
Block(0,-23,-3,STONE:5)
Block(0,-23,-2,SMOOTH_BRICK:1)
Block(0,-23,-1,STONE:5)
Block(0,-23,0,SMOOTH_BRICK:2)
Block(0,-23,1,SMOOTH_BRICK:0)
Block(0,-22,-7,STONE:5)
Block(0,-22,-6,STONE:5)
Block(0,-22,-5,SMOOTH_BRICK:2)
Block(0,-22,-4,STONE:5)
Block(0,-22,-3,STONE:5)
Block(0,-22,-2,SMOOTH_BRICK:1)
Block(0,-22,-1,STONE:5)
Block(0,-22,0,SMOOTH_BRICK:2)
Block(0,-22,1,SMOOTH_BRICK:0)
Block(0,-21,-7,STONE:5)
Block(0,-21,-6,STONE:5)
Block(0,-21,-5,SMOOTH_BRICK:2)
Block(0,-21,-4,STONE:5)
Block(0,-21,-3,STONE:5)
Block(0,-21,-2,SMOOTH_BRICK:1)
Block(0,-21,-1,STONE:5)
Block(0,-21,0,SMOOTH_BRICK:2)
Block(0,-21,1,SMOOTH_BRICK:0)
Block(0,-20,-7,STONE:5)
Block(0,-20,-6,STONE:5)
Block(0,-20,-5,SMOOTH_BRICK:2)
Block(0,-20,-4,STONE:5)
Block(0,-20,-3,STONE:5)
Block(0,-20,-2,SMOOTH_BRICK:1)
Block(0,-20,-1,STONE:5)
Block(0,-20,0,SMOOTH_BRICK:2)
Block(0,-20,1,SMOOTH_BRICK:0)
Block(0,-19,-7,STONE:5)
Block(0,-19,-6,COBBLESTONE:0)
Block(0,-19,-5,STONE:5)
Block(0,-19,-4,STONE:5)
Block(0,-19,-3,SMOOTH_BRICK:0)
Block(0,-19,-2,COBBLESTONE:0)
Block(0,-19,-1,SMOOTH_BRICK:1)
Block(0,-19,0,SMOOTH_BRICK:2)
Block(0,-19,1,STAINED_CLAY:9)
Block(0,-18,-7,STONE:5)
Block(0,-18,-6,COBBLESTONE:0)
Block(0,-18,-5,STONE:5)
Block(0,-18,-4,STAINED_CLAY:9)
Block(0,-18,-3,SMOOTH_BRICK:0)
Block(0,-18,-2,SMOOTH_BRICK:2)
Block(0,-18,-1,STONE:5)
Block(0,-18,0,SMOOTH_BRICK:0)
Block(0,-18,1,SMOOTH_BRICK:2)
Block(0,-17,-7,COBBLESTONE:0)
Block(0,-17,-6,STONE:5)
Block(0,-17,-5,STONE:5)
Block(0,-17,-4,SMOOTH_BRICK:2)
Block(0,-17,-3,SMOOTH_BRICK:2)
Block(0,-17,-2,SMOOTH_BRICK:0)
Block(0,-17,-1,STONE:5)
Block(0,-17,0,STAINED_CLAY:9)
Block(0,-17,1,STONE:5)
Block(0,-16,-7,STONE:5)
Block(0,-16,-6,COBBLESTONE:0)
Block(0,-16,-5,STONE:5)
Block(0,-16,-4,SMOOTH_BRICK:0)
Block(0,-16,-3,SMOOTH_BRICK:2)
Block(0,-16,-2,STONE:5)
Block(0,-16,-1,SMOOTH_BRICK:0)
Block(0,-16,0,COBBLESTONE:0)
Block(0,-16,1,SMOOTH_BRICK:0)
Block(0,-15,-7,COBBLESTONE:0)
Block(0,-15,-6,SMOOTH_BRICK:0)
Block(0,-15,-5,SMOOTH_BRICK:2)
Block(0,-15,-4,STONE:5)
Block(0,-15,-3,STONE:5)
Block(0,-15,-2,SMOOTH_BRICK:0)
Block(0,-15,-1,SMOOTH_BRICK:0)
Block(0,-15,0,SMOOTH_BRICK:1)
Block(0,-15,1,SMOOTH_BRICK:0)
Block(0,-14,-7,SMOOTH_BRICK:0)
Block(0,-14,-6,STONE:5)
Block(0,-14,-5,SMOOTH_BRICK:2)
Block(0,-14,-4,STONE:5)
Block(0,-14,-3,STAINED_CLAY:9)
Block(0,-14,-2,SMOOTH_BRICK:0)
Block(0,-14,-1,COBBLESTONE:0)
Block(0,-14,0,STONE:5)
Block(0,-14,1,COBBLESTONE:0)
Block(0,-13,-7,STONE:5)
Block(0,-13,-6,STONE:5)
Block(0,-13,-5,SMOOTH_BRICK:2)
Block(0,-13,-4,SMOOTH_BRICK:1)
Block(0,-13,-3,SMOOTH_BRICK:1)
Block(0,-13,-2,SMOOTH_BRICK:0)
Block(0,-13,-1,SMOOTH_BRICK:0)
Block(0,-13,0,SMOOTH_BRICK:2)
Block(0,-13,1,SMOOTH_BRICK:0)
Block(0,-12,-7,STONE:5)
Block(0,-12,-6,COBBLESTONE:0)
Block(0,-12,-5,STONE:5)
Block(0,-12,-4,STONE:5)
Block(0,-12,-3,SMOOTH_BRICK:0)
Block(0,-12,-2,STONE:5)
Block(0,-12,-1,STONE:5)
Block(0,-12,0,STONE:5)
Block(0,-12,1,STONE:5)
Block(0,-11,-7,SMOOTH_BRICK:2)
Block(0,-11,-6,STONE:5)
Block(0,-11,-5,SMOOTH_BRICK:2)
Block(0,-11,-4,STONE:5)
Block(0,-11,-3,STONE:5)
Block(0,-11,-2,SMOOTH_BRICK:0)
Block(0,-11,-1,SMOOTH_BRICK:0)
Block(0,-11,0,SMOOTH_BRICK:0)
Block(0,-11,1,STONE:5)
Block(0,-10,-7,SMOOTH_BRICK:0)
Block(0,-10,-6,STONE:5)
Block(0,-10,-5,STONE:5)
Block(0,-10,-4,COBBLESTONE:0)
Block(0,-10,-3,STONE:5)
Block(0,-10,-2,STONE:5)
Block(0,-10,-1,SMOOTH_BRICK:0)
Block(0,-10,0,SMOOTH_BRICK:1)
Block(0,-10,1,STONE:5)
Block(0,-9,-7,STONE:6)
Block(0,-9,-6,STONE:6)
Block(0,-9,-5,STONE:6)
Block(0,-9,-4,STONE:6)
Block(0,-9,-3,STONE:6)
Block(0,-9,-2,STONE:6)
Block(0,-9,-1,LOG:0)
Block(0,-9,0,COBBLESTONE_STAIRS:0)
Block(0,-9,1,COBBLESTONE_STAIRS:3)
Block(0,-8,-7,COBBLESTONE:0)
Block(0,-8,-6,STONE:5)
Block(0,-8,-5,COBBLESTONE:0)
Block(0,-8,-4,STONE:5)
Block(0,-8,-3,STONE:5)
Block(0,-8,-2,SMOOTH_BRICK:0)
Block(0,-8,-1,LOG:0)
Block(0,-7,-7,SMOOTH_BRICK:2)
Block(0,-7,-6,STONE:5)
Block(0,-7,-5,STONE:5)
Block(0,-7,-4,STONE:5)
Block(0,-7,-3,STONE:5)
Block(0,-7,-2,STONE:5)
Block(0,-7,-1,LOG:0)
Block(0,-6,-7,SMOOTH_BRICK:0)
Block(0,-6,-6,STONE:5)
Block(0,-6,-5,STONE:5)
Block(0,-6,-4,STONE:5)
Block(0,-6,-3,STONE:5)
Block(0,-6,-2,STONE:5)
Block(0,-6,-1,LOG:0)
Block(0,-5,-7,STONE:5)
Block(0,-5,-6,STONE:5)
Block(0,-5,-5,SMOOTH_BRICK:2)
Block(0,-5,-4,STONE:5)
Block(0,-5,-3,SMOOTH_BRICK:1)
Block(0,-5,-2,STAINED_CLAY:9)
Block(0,-5,-1,LOG:0)
Block(0,-4,-7,STONE:6)
Block(0,-4,-6,STONE:6)
Block(0,-4,-5,STONE:6)
Block(0,-4,-4,STONE:6)
Block(0,-4,-3,STONE:6)
Block(0,-4,-2,LOG:8)
Block(0,-4,-1,COBBLESTONE_STAIRS:3)
Block(0,-3,-7,STONE:6)
Block(0,-3,-6,STONE:6)
Block(0,-3,-5,STONE:6)
Block(0,-3,-4,STONE:6)
Block(0,-3,-3,STONE:6)
Block(0,-3,-2,LOG:0)
Block(0,-2,-7,STONE:6)
Block(0,-2,-6,STONE:6)
Block(0,-2,-5,STONE:6)
Block(0,-2,-4,STONE:6)
Block(0,-2,-3,STONE:6)
Block(0,-2,-2,LOG:0)
Block(0,-1,-7,STONE:6)
Block(0,-1,-6,STONE:6)
Block(0,-1,-5,STONE:6)
Block(0,-1,-4,STONE:6)
Block(0,-1,-3,STONE:6)
Block(0,-1,-2,LOG:0)
Block(0,0,-7,STONE:6)
Block(0,0,-6,STONE:6)
Block(0,0,-5,STONE:6)
Block(0,0,-4,STONE:6)
Block(0,0,-3,STONE:6)
Block(0,0,-2,LOG:0)
Block(0,1,-7,STONE:6)
Block(0,1,-6,STONE:6)
Block(0,1,-5,STONE:6)
Block(0,1,-4,STONE:6)
Block(0,1,-3,STONE:6)
Block(0,1,-2,LOG:0)
Block(0,2,-7,SMOOTH_BRICK:0)
Block(0,2,-6,SMOOTH_BRICK:0)
Block(0,2,-5,SMOOTH_BRICK:0)
Block(0,2,-4,SMOOTH_BRICK:0)
Block(0,2,-3,SMOOTH_BRICK:0)
Block(0,2,-2,LOG:0)
Block(0,3,-7,SMOOTH_BRICK:0)
Block(0,3,-6,SMOOTH_BRICK:0)
Block(0,3,-5,SMOOTH_BRICK:0)
Block(0,3,-4,SMOOTH_BRICK:0)
Block(0,3,-3,SMOOTH_BRICK:0)
Block(0,3,-2,LOG:0)
Block(0,4,-7,COBBLESTONE:0)
Block(0,4,-6,COBBLESTONE:0)
Block(0,4,-5,COBBLESTONE:0)
Block(0,4,-4,COBBLESTONE:0)
Block(0,4,-3,LOG:0)
Block(0,4,-2,LOG:0)
Block(0,5,-7,COBBLESTONE:0)
Block(0,5,-6,COBBLESTONE:0)
Block(0,5,-5,COBBLESTONE:0)
Block(0,5,-4,COBBLESTONE:0)
Block(0,5,-3,LOG:0)
Block(0,5,-2,LOG:0)
Block(0,6,-7,COBBLESTONE:0)
Block(0,6,-6,COBBLESTONE:0)
Block(0,6,-5,COBBLESTONE:0)
Block(0,6,-4,COBBLESTONE:0)
Block(0,6,-3,LOG:0)
Block(0,6,-2,LOG:0)
Block(0,7,-7,COBBLESTONE:0)
Block(0,7,-6,COBBLESTONE:0)
Block(0,7,-5,COBBLESTONE:0)
Block(0,7,-4,COBBLESTONE:0)
Block(0,7,-3,LOG:0)
Block(0,7,-2,LOG:0)
Block(0,8,-7,STONE:6)
Block(0,8,-6,LOG:4)
Block(0,8,-5,WOOD_STEP:13)
Block(0,8,-4,WOOD_STEP:13)
Block(0,8,-3,LOG:0)
Block(0,8,-2,COBBLESTONE:0)
Block(0,9,-7,STONE:6)
Block(0,9,-6,STONE:6)
Block(0,9,-5,AIR:0)
Block(0,9,-4,STONE:6)
Block(0,9,-3,LOG:0)
Block(0,9,-2,STEP:0)
Block(0,10,-7,STONE:6)
Block(0,10,-6,STONE:6)
Block(0,10,-5,AIR:0)
Block(0,10,-4,STONE:6)
Block(0,10,-3,LOG:0)
Block(0,10,-2,AIR:0)
Block(0,10,-1,WOOD_STEP:13)
Block(0,11,-7,LOG:8)
Block(0,11,-6,LOG:4)
Block(0,11,-5,LOG:8)
Block(0,11,-4,LOG:8)
Block(0,11,-3,LOG:0)
Block(0,11,-2,WOOD_STEP:5)
Block(0,12,-7,SMOOTH_BRICK:0)
Block(0,12,-6,SMOOTH_BRICK:0)
Block(0,12,-5,SMOOTH_BRICK:0)
Block(0,12,-4,SMOOTH_BRICK:0)
Block(0,12,-3,LOG:0)
Block(0,12,-2,AIR:0)
Block(0,13,-7,SMOOTH_BRICK:0)
Block(0,13,-6,SMOOTH_BRICK:0)
Block(0,13,-5,COBBLESTONE:0)
Block(0,13,-4,COBBLESTONE:0)
Block(0,13,-3,LOG:0)
Block(0,13,-2,AIR:0)
Block(0,14,-7,SMOOTH_BRICK:0)
Block(0,14,-6,SMOOTH_BRICK:0)
Block(0,14,-5,SMOOTH_BRICK:0)
Block(0,14,-4,SMOOTH_BRICK:0)
Block(0,14,-3,LOG:0)
Block(0,14,-2,AIR:0)
Block(0,15,-7,SMOOTH_BRICK:0)
Block(0,15,-6,SMOOTH_BRICK:0)
Block(0,15,-5,SMOOTH_BRICK:0)
Block(0,15,-4,WOOD_STEP:5)
Block(0,15,-3,LOG:0)
Block(0,15,-2,AIR:0)
Block(0,16,-7,SMOOTH_BRICK:0)
Block(0,16,-6,SMOOTH_BRICK:0)
Block(0,16,-5,SMOOTH_BRICK:0)
Block(0,16,-4,WOOD_STEP:13)
Block(0,16,-3,LOG:0)
Block(0,16,-2,AIR:0)
Block(0,17,-7,SMOOTH_BRICK:0)
Block(0,17,-6,SMOOTH_BRICK:0)
Block(0,17,-5,SMOOTH_BRICK:0)
Block(0,17,-4,SMOOTH_BRICK:0)
Block(0,17,-3,LOG:0)
Block(0,17,-2,AIR:0)
Block(0,18,-7,SMOOTH_BRICK:0)
Block(0,18,-6,SMOOTH_BRICK:0)
Block(0,18,-5,SMOOTH_BRICK:0)
Block(0,18,-4,SMOOTH_BRICK:0)
Block(0,18,-3,LOG:0)
Block(0,18,-2,AIR:0)
Block(0,19,-7,SMOOTH_BRICK:0)
Block(0,19,-6,SMOOTH_BRICK:0)
Block(0,19,-5,SMOOTH_BRICK:0)
Block(0,19,-4,SMOOTH_BRICK:0)
Block(0,19,-3,LOG:0)
Block(0,19,-2,AIR:0)
Block(0,20,-7,SMOOTH_BRICK:0)
Block(0,20,-6,LOG:4)
Block(0,20,-5,STONE:6)
Block(0,20,-4,STONE:6)
Block(0,20,-3,LOG:0)
Block(0,20,-2,AIR:0)
Block(0,21,-7,AIR:0)
Block(0,21,-6,LOG:0)
Block(0,21,-5,STONE:6)
Block(0,21,-4,STONE:6)
Block(0,21,-3,LOG:0)
Block(0,21,-2,AIR:0)
Block(0,22,-7,AIR:0)
Block(0,22,-6,LOG:0)
Block(0,22,-5,SMOOTH_BRICK:0)
Block(0,22,-4,SMOOTH_BRICK:0)
Block(0,22,-3,LOG:0)
Block(0,22,-2,AIR:0)
Block(0,23,-7,AIR:0)
Block(0,23,-6,LOG:0)
Block(0,23,-5,SMOOTH_BRICK:0)
Block(0,23,-4,SMOOTH_BRICK:0)
Block(0,23,-3,LOG:0)
Block(0,23,-2,AIR:0)
Block(0,24,-7,LOG:8)
Block(0,24,-6,LOG:0)
Block(0,24,-5,SMOOTH_STAIRS:0)
Block(0,24,-4,SMOOTH_STAIRS:0)
Block(0,24,-3,LOG:0)
Block(0,24,-2,AIR:0)
Block(0,25,-7,SMOOTH_BRICK:0)
Block(0,25,-6,LOG:0)
Block(0,25,-5,AIR:0)
Block(0,25,-4,AIR:0)
Block(0,25,-3,STEP:0)
Block(0,25,-2,AIR:0)
Block(0,26,-7,SMOOTH_BRICK:0)
Block(0,26,-6,LOG:0)
Block(0,26,-5,AIR:0)
Block(0,26,-4,AIR:0)
Block(0,26,-3,AIR:0)
Block(0,26,-2,AIR:0)
Block(0,27,-7,SMOOTH_BRICK:0)
Block(0,27,-6,LOG:0)
Block(0,27,-5,AIR:0)
Block(0,27,-4,AIR:0)
Block(0,27,-3,AIR:0)
Block(0,27,-2,AIR:0)
Block(0,28,-7,SMOOTH_STAIRS:0)
Block(0,28,-6,LOG:0)
Block(0,28,-5,AIR:0)
Block(0,28,-4,AIR:0)
Block(0,28,-3,AIR:0)
Block(0,28,-2,AIR:0)
Block(0,29,-7,AIR:0)
Block(0,29,-6,STEP:0)
Block(0,29,-5,AIR:0)
Block(0,29,-4,AIR:0)
Block(0,29,-3,AIR:0)
Block(0,29,-2,AIR:0)
Block(0,30,-7,AIR:0)
Block(0,30,-6,AIR:0)
Block(0,30,-5,AIR:0)
Block(0,30,-4,AIR:0)
Block(0,30,-3,AIR:0)
Block(0,30,-2,AIR:0)
Block(0,31,-7,AIR:0)
Block(0,31,-6,AIR:0)
Block(0,31,-5,AIR:0)
Block(0,31,-4,AIR:0)
Block(0,31,-3,AIR:0)
Block(0,31,-2,AIR:0)
Block(0,32,-7,AIR:0)
Block(0,32,-6,AIR:0)
Block(0,32,-5,AIR:0)
Block(0,32,-4,AIR:0)
Block(0,32,-3,AIR:0)
Block(0,32,-2,AIR:0)
Block(0,33,-7,AIR:0)
Block(0,33,-6,AIR:0)
Block(0,33,-5,AIR:0)
Block(0,33,-4,AIR:0)
Block(0,33,-3,AIR:0)
Block(0,33,-2,AIR:0)
Block(0,34,-7,AIR:0)
Block(0,34,-6,AIR:0)
Block(0,34,-5,AIR:0)
Block(0,34,-4,AIR:0)
Block(0,34,-3,AIR:0)
Block(0,34,-2,AIR:0)
Block(0,35,-7,AIR:0)
Block(0,35,-6,AIR:0)
Block(0,35,-5,AIR:0)
Block(0,35,-4,AIR:0)
Block(0,35,-3,AIR:0)
Block(0,35,-2,AIR:0)
Block(0,36,-7,AIR:0)
Block(0,36,-6,AIR:0)
Block(0,36,-5,AIR:0)
Block(0,36,-4,AIR:0)
Block(0,36,-3,AIR:0)
Block(0,36,-2,AIR:0)
Block(0,37,-7,AIR:0)
Block(0,37,-6,AIR:0)
Block(0,37,-5,AIR:0)
Block(0,37,-4,AIR:0)
Block(0,37,-3,AIR:0)
Block(0,37,-2,AIR:0)
Block(0,38,-7,SMOOTH_STAIRS:4)
Block(0,38,-6,AIR:0)
Block(0,38,-5,AIR:0)
Block(0,38,-4,AIR:0)
Block(0,38,-3,AIR:0)
Block(0,38,-2,AIR:0)
Block(0,39,-7,DOUBLE_STEP:0)
Block(0,39,-6,STEP:8)
Block(0,39,-5,AIR:0)
Block(0,39,-4,AIR:0)
Block(0,39,-3,AIR:0)
Block(0,39,-2,AIR:0)
Block(0,40,-7,AIR:0)
Block(0,40,-6,STEP:0)
Block(0,40,-5,AIR:0)
Block(0,40,-4,AIR:0)
Block(0,40,-3,AIR:0)
Block(0,40,-2,AIR:0)
Block(0,41,-7,AIR:0)
Block(0,41,-6,AIR:0)
Block(0,41,-5,AIR:0)
Block(0,41,-4,AIR:0)
Block(0,41,-3,AIR:0)
Block(0,41,-2,AIR:0)
Block(0,42,-7,AIR:0)
Block(0,42,-6,AIR:0)
Block(0,42,-5,AIR:0)
Block(0,42,-4,AIR:0)
Block(0,42,-3,AIR:0)
Block(0,42,-2,AIR:0)
Block(0,43,-7,AIR:0)
Block(0,43,-6,AIR:0)
Block(0,43,-5,AIR:0)
Block(0,43,-4,AIR:0)
Block(0,43,-3,AIR:0)
Block(0,43,-2,AIR:0)
Block(0,44,-7,AIR:0)
Block(0,44,-6,AIR:0)
Block(0,44,-5,AIR:0)
Block(0,44,-4,AIR:0)
Block(0,44,-3,AIR:0)
Block(0,44,-2,AIR:0)
Block(0,45,-7,AIR:0)
Block(0,45,-6,AIR:0)
Block(0,45,-5,AIR:0)
Block(0,45,-4,AIR:0)
Block(0,45,-3,AIR:0)
Block(0,45,-2,AIR:0)
Block(0,46,-7,AIR:0)
Block(0,46,-6,AIR:0)
Block(0,46,-5,AIR:0)
Block(0,46,-4,AIR:0)
Block(0,46,-3,AIR:0)
Block(0,46,-2,AIR:0)
Block(0,47,-7,AIR:0)
Block(0,47,-6,AIR:0)
Block(0,47,-5,AIR:0)
Block(0,47,-4,AIR:0)
Block(0,47,-3,AIR:0)
Block(0,47,-2,AIR:0)
Block(0,48,-7,AIR:0)
Block(0,48,-6,AIR:0)
Block(0,48,-5,AIR:0)
Block(0,48,-4,AIR:0)
Block(0,48,-3,AIR:0)
Block(0,48,-2,AIR:0)
Block(0,49,-7,AIR:0)
Block(0,49,-6,AIR:0)
Block(0,49,-5,AIR:0)
Block(0,49,-4,AIR:0)
Block(0,49,-3,AIR:0)
Block(0,49,-2,AIR:0)
Block(0,50,-7,AIR:0)
Block(0,50,-6,AIR:0)
Block(0,50,-5,WOOL:14)
Block(0,50,-4,AIR:0)
Block(0,50,-3,AIR:0)
Block(0,50,-2,AIR:0)
Block(0,51,-7,AIR:0)
Block(0,51,-6,AIR:0)
Block(0,51,-5,AIR:0)
Block(0,51,-4,AIR:0)
Block(0,51,-3,AIR:0)
Block(0,51,-2,AIR:0)
Block(0,52,-7,AIR:0)
Block(0,52,-6,AIR:0)
Block(0,52,-5,AIR:0)
Block(0,52,-4,AIR:0)
Block(0,52,-3,AIR:0)
Block(0,52,-2,AIR:0)
Block(0,53,-7,AIR:0)
Block(0,53,-6,AIR:0)
Block(0,53,-5,AIR:0)
Block(0,53,-4,AIR:0)
Block(0,53,-3,AIR:0)
Block(0,53,-2,AIR:0)
Block(0,54,-7,AIR:0)
Block(0,54,-6,AIR:0)
Block(0,54,-5,AIR:0)
Block(0,54,-4,AIR:0)
Block(0,54,-3,AIR:0)
Block(0,54,-2,AIR:0)
Block(0,55,-7,AIR:0)
Block(0,55,-6,AIR:0)
Block(0,55,-5,AIR:0)
Block(0,55,-4,AIR:0)
Block(0,55,-3,AIR:0)
Block(0,55,-2,AIR:0)
Block(0,56,-7,AIR:0)
Block(0,56,-6,AIR:0)
Block(0,56,-5,AIR:0)
Block(0,56,-4,AIR:0)
Block(0,56,-3,AIR:0)
Block(0,56,-2,AIR:0)
Block(0,57,-7,AIR:0)
Block(0,57,-6,AIR:0)
Block(0,57,-5,AIR:0)
Block(0,57,-4,AIR:0)
Block(0,57,-3,AIR:0)
Block(0,57,-2,AIR:0)
Block(0,58,-7,AIR:0)
Block(0,58,-6,AIR:0)
Block(0,58,-5,AIR:0)
Block(0,58,-4,AIR:0)
Block(0,58,-3,AIR:0)
Block(0,58,-2,AIR:0)
Block(0,59,-7,AIR:0)
Block(0,59,-6,AIR:0)
Block(0,59,-5,AIR:0)
Block(0,59,-4,AIR:0)
Block(0,59,-3,AIR:0)
Block(0,59,-2,AIR:0)
Block(0,60,-7,AIR:0)
Block(0,60,-6,AIR:0)
Block(0,60,-5,AIR:0)
Block(0,60,-4,AIR:0)
Block(0,60,-3,AIR:0)
Block(0,60,-2,AIR:0)
Block(0,61,-7,AIR:0)
Block(0,61,-6,AIR:0)
Block(0,61,-5,AIR:0)
Block(0,61,-4,AIR:0)
Block(0,61,-3,AIR:0)
Block(0,61,-2,AIR:0)
Block(0,62,-7,AIR:0)
Block(0,62,-6,AIR:0)
Block(0,62,-5,AIR:0)
Block(0,62,-4,AIR:0)
Block(0,62,-3,AIR:0)
Block(0,62,-2,AIR:0)
Block(0,63,-7,AIR:0)
Block(0,63,-6,AIR:0)
Block(0,63,-5,AIR:0)
Block(0,63,-4,AIR:0)
Block(0,63,-3,AIR:0)
Block(0,63,-2,AIR:0)
Block(1,-50,-7,STONE:5)
Block(1,-50,-6,SMOOTH_BRICK:2)
Block(1,-50,-5,STAINED_CLAY:9)
Block(1,-50,-4,STAINED_CLAY:9)
Block(1,-50,-3,COBBLESTONE:0)
Block(1,-50,-2,SMOOTH_BRICK:1)
Block(1,-50,-1,STONE:5)
Block(1,-50,0,STONE:5)
Block(1,-50,1,STONE:5)
Block(1,-49,-7,STONE:5)
Block(1,-49,-6,SMOOTH_BRICK:2)
Block(1,-49,-5,STAINED_CLAY:9)
Block(1,-49,-4,STAINED_CLAY:9)
Block(1,-49,-3,COBBLESTONE:0)
Block(1,-49,-2,SMOOTH_BRICK:1)
Block(1,-49,-1,STONE:5)
Block(1,-49,0,STONE:5)
Block(1,-49,1,STONE:5)
Block(1,-48,-7,STONE:5)
Block(1,-48,-6,SMOOTH_BRICK:2)
Block(1,-48,-5,STAINED_CLAY:9)
Block(1,-48,-4,STAINED_CLAY:9)
Block(1,-48,-3,COBBLESTONE:0)
Block(1,-48,-2,SMOOTH_BRICK:1)
Block(1,-48,-1,STONE:5)
Block(1,-48,0,STONE:5)
Block(1,-48,1,STONE:5)
Block(1,-47,-7,STONE:5)
Block(1,-47,-6,SMOOTH_BRICK:2)
Block(1,-47,-5,STAINED_CLAY:9)
Block(1,-47,-4,STAINED_CLAY:9)
Block(1,-47,-3,COBBLESTONE:0)
Block(1,-47,-2,SMOOTH_BRICK:1)
Block(1,-47,-1,STONE:5)
Block(1,-47,0,STONE:5)
Block(1,-47,1,STONE:5)
Block(1,-46,-7,STONE:5)
Block(1,-46,-6,SMOOTH_BRICK:2)
Block(1,-46,-5,STAINED_CLAY:9)
Block(1,-46,-4,STAINED_CLAY:9)
Block(1,-46,-3,COBBLESTONE:0)
Block(1,-46,-2,SMOOTH_BRICK:1)
Block(1,-46,-1,STONE:5)
Block(1,-46,0,STONE:5)
Block(1,-46,1,STONE:5)
Block(1,-45,-7,STONE:5)
Block(1,-45,-6,SMOOTH_BRICK:2)
Block(1,-45,-5,STAINED_CLAY:9)
Block(1,-45,-4,STAINED_CLAY:9)
Block(1,-45,-3,COBBLESTONE:0)
Block(1,-45,-2,SMOOTH_BRICK:1)
Block(1,-45,-1,STONE:5)
Block(1,-45,0,STONE:5)
Block(1,-45,1,STONE:5)
Block(1,-44,-7,STONE:5)
Block(1,-44,-6,SMOOTH_BRICK:2)
Block(1,-44,-5,STAINED_CLAY:9)
Block(1,-44,-4,STAINED_CLAY:9)
Block(1,-44,-3,COBBLESTONE:0)
Block(1,-44,-2,SMOOTH_BRICK:1)
Block(1,-44,-1,STONE:5)
Block(1,-44,0,STONE:5)
Block(1,-44,1,STONE:5)
Block(1,-43,-7,STONE:5)
Block(1,-43,-6,SMOOTH_BRICK:2)
Block(1,-43,-5,STAINED_CLAY:9)
Block(1,-43,-4,STAINED_CLAY:9)
Block(1,-43,-3,COBBLESTONE:0)
Block(1,-43,-2,SMOOTH_BRICK:1)
Block(1,-43,-1,STONE:5)
Block(1,-43,0,STONE:5)
Block(1,-43,1,STONE:5)
Block(1,-42,-7,STONE:5)
Block(1,-42,-6,SMOOTH_BRICK:2)
Block(1,-42,-5,STAINED_CLAY:9)
Block(1,-42,-4,STAINED_CLAY:9)
Block(1,-42,-3,COBBLESTONE:0)
Block(1,-42,-2,SMOOTH_BRICK:1)
Block(1,-42,-1,STONE:5)
Block(1,-42,0,STONE:5)
Block(1,-42,1,STONE:5)
Block(1,-41,-7,STONE:5)
Block(1,-41,-6,SMOOTH_BRICK:2)
Block(1,-41,-5,STAINED_CLAY:9)
Block(1,-41,-4,STAINED_CLAY:9)
Block(1,-41,-3,COBBLESTONE:0)
Block(1,-41,-2,SMOOTH_BRICK:1)
Block(1,-41,-1,STONE:5)
Block(1,-41,0,STONE:5)
Block(1,-41,1,STONE:5)
Block(1,-40,-7,STONE:5)
Block(1,-40,-6,SMOOTH_BRICK:2)
Block(1,-40,-5,STAINED_CLAY:9)
Block(1,-40,-4,STAINED_CLAY:9)
Block(1,-40,-3,COBBLESTONE:0)
Block(1,-40,-2,SMOOTH_BRICK:1)
Block(1,-40,-1,STONE:5)
Block(1,-40,0,STONE:5)
Block(1,-40,1,STONE:5)
Block(1,-39,-7,STONE:5)
Block(1,-39,-6,SMOOTH_BRICK:2)
Block(1,-39,-5,STAINED_CLAY:9)
Block(1,-39,-4,STAINED_CLAY:9)
Block(1,-39,-3,COBBLESTONE:0)
Block(1,-39,-2,SMOOTH_BRICK:1)
Block(1,-39,-1,STONE:5)
Block(1,-39,0,STONE:5)
Block(1,-39,1,STONE:5)
Block(1,-38,-7,STONE:5)
Block(1,-38,-6,SMOOTH_BRICK:2)
Block(1,-38,-5,STAINED_CLAY:9)
Block(1,-38,-4,STAINED_CLAY:9)
Block(1,-38,-3,COBBLESTONE:0)
Block(1,-38,-2,SMOOTH_BRICK:1)
Block(1,-38,-1,STONE:5)
Block(1,-38,0,STONE:5)
Block(1,-38,1,STONE:5)
Block(1,-37,-7,STONE:5)
Block(1,-37,-6,SMOOTH_BRICK:2)
Block(1,-37,-5,STAINED_CLAY:9)
Block(1,-37,-4,STAINED_CLAY:9)
Block(1,-37,-3,COBBLESTONE:0)
Block(1,-37,-2,SMOOTH_BRICK:1)
Block(1,-37,-1,STONE:5)
Block(1,-37,0,STONE:5)
Block(1,-37,1,STONE:5)
Block(1,-36,-7,STONE:5)
Block(1,-36,-6,SMOOTH_BRICK:2)
Block(1,-36,-5,STAINED_CLAY:9)
Block(1,-36,-4,STAINED_CLAY:9)
Block(1,-36,-3,COBBLESTONE:0)
Block(1,-36,-2,SMOOTH_BRICK:1)
Block(1,-36,-1,STONE:5)
Block(1,-36,0,STONE:5)
Block(1,-36,1,STONE:5)
Block(1,-35,-7,STONE:5)
Block(1,-35,-6,SMOOTH_BRICK:2)
Block(1,-35,-5,STAINED_CLAY:9)
Block(1,-35,-4,STAINED_CLAY:9)
Block(1,-35,-3,COBBLESTONE:0)
Block(1,-35,-2,SMOOTH_BRICK:1)
Block(1,-35,-1,STONE:5)
Block(1,-35,0,STONE:5)
Block(1,-35,1,STONE:5)
Block(1,-34,-7,STONE:5)
Block(1,-34,-6,SMOOTH_BRICK:2)
Block(1,-34,-5,STAINED_CLAY:9)
Block(1,-34,-4,STAINED_CLAY:9)
Block(1,-34,-3,COBBLESTONE:0)
Block(1,-34,-2,SMOOTH_BRICK:1)
Block(1,-34,-1,STONE:5)
Block(1,-34,0,STONE:5)
Block(1,-34,1,STONE:5)
Block(1,-33,-7,STONE:5)
Block(1,-33,-6,SMOOTH_BRICK:2)
Block(1,-33,-5,STAINED_CLAY:9)
Block(1,-33,-4,STAINED_CLAY:9)
Block(1,-33,-3,COBBLESTONE:0)
Block(1,-33,-2,SMOOTH_BRICK:1)
Block(1,-33,-1,STONE:5)
Block(1,-33,0,STONE:5)
Block(1,-33,1,STONE:5)
Block(1,-32,-7,STONE:5)
Block(1,-32,-6,SMOOTH_BRICK:2)
Block(1,-32,-5,STAINED_CLAY:9)
Block(1,-32,-4,STAINED_CLAY:9)
Block(1,-32,-3,COBBLESTONE:0)
Block(1,-32,-2,SMOOTH_BRICK:1)
Block(1,-32,-1,STONE:5)
Block(1,-32,0,STONE:5)
Block(1,-32,1,STONE:5)
Block(1,-31,-7,STONE:5)
Block(1,-31,-6,SMOOTH_BRICK:2)
Block(1,-31,-5,STAINED_CLAY:9)
Block(1,-31,-4,STAINED_CLAY:9)
Block(1,-31,-3,COBBLESTONE:0)
Block(1,-31,-2,SMOOTH_BRICK:1)
Block(1,-31,-1,STONE:5)
Block(1,-31,0,STONE:5)
Block(1,-31,1,STONE:5)
Block(1,-30,-7,STONE:5)
Block(1,-30,-6,SMOOTH_BRICK:2)
Block(1,-30,-5,STAINED_CLAY:9)
Block(1,-30,-4,STAINED_CLAY:9)
Block(1,-30,-3,COBBLESTONE:0)
Block(1,-30,-2,SMOOTH_BRICK:1)
Block(1,-30,-1,STONE:5)
Block(1,-30,0,STONE:5)
Block(1,-30,1,STONE:5)
Block(1,-29,-7,STONE:5)
Block(1,-29,-6,SMOOTH_BRICK:2)
Block(1,-29,-5,STAINED_CLAY:9)
Block(1,-29,-4,STAINED_CLAY:9)
Block(1,-29,-3,COBBLESTONE:0)
Block(1,-29,-2,SMOOTH_BRICK:1)
Block(1,-29,-1,STONE:5)
Block(1,-29,0,STONE:5)
Block(1,-29,1,STONE:5)
Block(1,-28,-7,STONE:5)
Block(1,-28,-6,SMOOTH_BRICK:2)
Block(1,-28,-5,STAINED_CLAY:9)
Block(1,-28,-4,STAINED_CLAY:9)
Block(1,-28,-3,COBBLESTONE:0)
Block(1,-28,-2,SMOOTH_BRICK:1)
Block(1,-28,-1,STONE:5)
Block(1,-28,0,STONE:5)
Block(1,-28,1,STONE:5)
Block(1,-27,-7,STONE:5)
Block(1,-27,-6,SMOOTH_BRICK:2)
Block(1,-27,-5,STAINED_CLAY:9)
Block(1,-27,-4,STAINED_CLAY:9)
Block(1,-27,-3,COBBLESTONE:0)
Block(1,-27,-2,SMOOTH_BRICK:1)
Block(1,-27,-1,STONE:5)
Block(1,-27,0,STONE:5)
Block(1,-27,1,STONE:5)
Block(1,-26,-7,STONE:5)
Block(1,-26,-6,SMOOTH_BRICK:2)
Block(1,-26,-5,STAINED_CLAY:9)
Block(1,-26,-4,STAINED_CLAY:9)
Block(1,-26,-3,COBBLESTONE:0)
Block(1,-26,-2,SMOOTH_BRICK:1)
Block(1,-26,-1,STONE:5)
Block(1,-26,0,STONE:5)
Block(1,-26,1,STONE:5)
Block(1,-25,-7,STONE:5)
Block(1,-25,-6,SMOOTH_BRICK:2)
Block(1,-25,-5,STAINED_CLAY:9)
Block(1,-25,-4,STAINED_CLAY:9)
Block(1,-25,-3,COBBLESTONE:0)
Block(1,-25,-2,SMOOTH_BRICK:1)
Block(1,-25,-1,STONE:5)
Block(1,-25,0,STONE:5)
Block(1,-25,1,STONE:5)
Block(1,-24,-7,STONE:5)
Block(1,-24,-6,SMOOTH_BRICK:2)
Block(1,-24,-5,STAINED_CLAY:9)
Block(1,-24,-4,STAINED_CLAY:9)
Block(1,-24,-3,COBBLESTONE:0)
Block(1,-24,-2,SMOOTH_BRICK:1)
Block(1,-24,-1,STONE:5)
Block(1,-24,0,STONE:5)
Block(1,-24,1,STONE:5)
Block(1,-23,-7,STONE:5)
Block(1,-23,-6,SMOOTH_BRICK:2)
Block(1,-23,-5,STAINED_CLAY:9)
Block(1,-23,-4,STAINED_CLAY:9)
Block(1,-23,-3,COBBLESTONE:0)
Block(1,-23,-2,SMOOTH_BRICK:1)
Block(1,-23,-1,STONE:5)
Block(1,-23,0,STONE:5)
Block(1,-23,1,STONE:5)
Block(1,-22,-7,STONE:5)
Block(1,-22,-6,SMOOTH_BRICK:2)
Block(1,-22,-5,STAINED_CLAY:9)
Block(1,-22,-4,STAINED_CLAY:9)
Block(1,-22,-3,COBBLESTONE:0)
Block(1,-22,-2,SMOOTH_BRICK:1)
Block(1,-22,-1,STONE:5)
Block(1,-22,0,STONE:5)
Block(1,-22,1,STONE:5)
Block(1,-21,-7,STONE:5)
Block(1,-21,-6,SMOOTH_BRICK:2)
Block(1,-21,-5,STAINED_CLAY:9)
Block(1,-21,-4,STAINED_CLAY:9)
Block(1,-21,-3,COBBLESTONE:0)
Block(1,-21,-2,SMOOTH_BRICK:1)
Block(1,-21,-1,STONE:5)
Block(1,-21,0,STONE:5)
Block(1,-21,1,STONE:5)
Block(1,-20,-7,STONE:5)
Block(1,-20,-6,SMOOTH_BRICK:2)
Block(1,-20,-5,STAINED_CLAY:9)
Block(1,-20,-4,STAINED_CLAY:9)
Block(1,-20,-3,COBBLESTONE:0)
Block(1,-20,-2,SMOOTH_BRICK:1)
Block(1,-20,-1,STONE:5)
Block(1,-20,0,STONE:5)
Block(1,-20,1,STONE:5)
Block(1,-19,-7,STONE:5)
Block(1,-19,-6,SMOOTH_BRICK:0)
Block(1,-19,-5,STONE:5)
Block(1,-19,-4,SMOOTH_BRICK:0)
Block(1,-19,-3,STONE:5)
Block(1,-19,-2,SMOOTH_BRICK:2)
Block(1,-19,-1,SMOOTH_BRICK:1)
Block(1,-19,0,STONE:5)
Block(1,-19,1,SMOOTH_BRICK:0)
Block(1,-18,-7,SMOOTH_BRICK:0)
Block(1,-18,-6,SMOOTH_BRICK:1)
Block(1,-18,-5,SMOOTH_BRICK:2)
Block(1,-18,-4,SMOOTH_BRICK:0)
Block(1,-18,-3,STONE:5)
Block(1,-18,-2,STONE:5)
Block(1,-18,-1,COBBLESTONE:0)
Block(1,-18,0,SMOOTH_BRICK:0)
Block(1,-18,1,SMOOTH_BRICK:2)
Block(1,-17,-7,STONE:5)
Block(1,-17,-6,SMOOTH_BRICK:0)
Block(1,-17,-5,STONE:5)
Block(1,-17,-4,STAINED_CLAY:9)
Block(1,-17,-3,SMOOTH_BRICK:2)
Block(1,-17,-2,STONE:5)
Block(1,-17,-1,STONE:5)
Block(1,-17,0,STONE:5)
Block(1,-17,1,SMOOTH_BRICK:2)
Block(1,-16,-7,SMOOTH_BRICK:1)
Block(1,-16,-6,COBBLESTONE:0)
Block(1,-16,-5,SMOOTH_BRICK:2)
Block(1,-16,-4,STONE:5)
Block(1,-16,-3,STONE:5)
Block(1,-16,-2,SMOOTH_BRICK:0)
Block(1,-16,-1,STONE:5)
Block(1,-16,0,COBBLESTONE:0)
Block(1,-16,1,COBBLESTONE:0)
Block(1,-15,-7,SMOOTH_BRICK:2)
Block(1,-15,-6,SMOOTH_BRICK:2)
Block(1,-15,-5,SMOOTH_BRICK:1)
Block(1,-15,-4,STONE:5)
Block(1,-15,-3,STAINED_CLAY:9)
Block(1,-15,-2,STONE:5)
Block(1,-15,-1,SMOOTH_BRICK:0)
Block(1,-15,0,SMOOTH_BRICK:2)
Block(1,-15,1,STONE:5)
Block(1,-14,-7,SMOOTH_BRICK:2)
Block(1,-14,-6,COBBLESTONE:0)
Block(1,-14,-5,STAINED_CLAY:9)
Block(1,-14,-4,SMOOTH_BRICK:0)
Block(1,-14,-3,SMOOTH_BRICK:2)
Block(1,-14,-2,SMOOTH_BRICK:2)
Block(1,-14,-1,STONE:5)
Block(1,-14,0,STAINED_CLAY:9)
Block(1,-14,1,STONE:5)
Block(1,-13,-7,SMOOTH_BRICK:2)
Block(1,-13,-6,SMOOTH_BRICK:2)
Block(1,-13,-5,STONE:5)
Block(1,-13,-4,SMOOTH_BRICK:0)
Block(1,-13,-3,STONE:5)
Block(1,-13,-2,SMOOTH_BRICK:2)
Block(1,-13,-1,SMOOTH_BRICK:2)
Block(1,-13,0,SMOOTH_BRICK:2)
Block(1,-13,1,STONE:5)
Block(1,-12,-7,SMOOTH_BRICK:0)
Block(1,-12,-6,SMOOTH_BRICK:2)
Block(1,-12,-5,SMOOTH_BRICK:1)
Block(1,-12,-4,STONE:5)
Block(1,-12,-3,SMOOTH_BRICK:1)
Block(1,-12,-2,STONE:5)
Block(1,-12,-1,SMOOTH_BRICK:0)
Block(1,-12,0,STONE:5)
Block(1,-12,1,SMOOTH_BRICK:0)
Block(1,-11,-7,COBBLESTONE:0)
Block(1,-11,-6,SMOOTH_BRICK:0)
Block(1,-11,-5,SMOOTH_BRICK:0)
Block(1,-11,-4,SMOOTH_BRICK:0)
Block(1,-11,-3,STONE:5)
Block(1,-11,-2,STONE:5)
Block(1,-11,-1,STONE:5)
Block(1,-11,0,STONE:5)
Block(1,-11,1,STONE:5)
Block(1,-10,-7,STONE:5)
Block(1,-10,-6,STONE:5)
Block(1,-10,-5,SMOOTH_BRICK:2)
Block(1,-10,-4,STONE:5)
Block(1,-10,-3,STONE:5)
Block(1,-10,-2,SMOOTH_BRICK:2)
Block(1,-10,-1,SMOOTH_BRICK:2)
Block(1,-10,0,STONE:5)
Block(1,-10,1,SMOOTH_BRICK:1)
Block(1,-9,-7,STONE:6)
Block(1,-9,-6,STONE:6)
Block(1,-9,-5,STONE:6)
Block(1,-9,-4,STONE:6)
Block(1,-9,-3,STONE:6)
Block(1,-9,-2,STONE:6)
Block(1,-9,-1,STONE:6)
Block(1,-9,0,STONE:6)
Block(1,-9,1,COBBLESTONE_STAIRS:3)
Block(1,-8,-7,SMOOTH_BRICK:2)
Block(1,-8,-6,SMOOTH_BRICK:2)
Block(1,-8,-5,STONE:5)
Block(1,-8,-4,SMOOTH_BRICK:0)
Block(1,-8,-3,SMOOTH_BRICK:0)
Block(1,-8,-2,SMOOTH_BRICK:0)
Block(1,-8,-1,SMOOTH_BRICK:2)
Block(1,-8,0,STONE:6)
Block(1,-7,-7,SMOOTH_BRICK:0)
Block(1,-7,-6,SMOOTH_BRICK:2)
Block(1,-7,-5,SMOOTH_BRICK:0)
Block(1,-7,-4,SMOOTH_BRICK:1)
Block(1,-7,-3,SMOOTH_BRICK:2)
Block(1,-7,-2,SMOOTH_BRICK:2)
Block(1,-7,-1,STAINED_CLAY:9)
Block(1,-7,0,STONE:6)
Block(1,-6,-7,SMOOTH_BRICK:0)
Block(1,-6,-6,SMOOTH_BRICK:0)
Block(1,-6,-5,SMOOTH_BRICK:0)
Block(1,-6,-4,STONE:5)
Block(1,-6,-3,SMOOTH_BRICK:2)
Block(1,-6,-2,STONE:5)
Block(1,-6,-1,SMOOTH_BRICK:0)
Block(1,-6,0,STONE:6)
Block(1,-5,-7,SMOOTH_BRICK:2)
Block(1,-5,-6,STONE:5)
Block(1,-5,-5,SMOOTH_BRICK:0)
Block(1,-5,-4,SMOOTH_BRICK:0)
Block(1,-5,-3,COBBLESTONE:0)
Block(1,-5,-2,SMOOTH_BRICK:2)
Block(1,-5,-1,SMOOTH_BRICK:1)
Block(1,-5,0,COBBLESTONE_STAIRS:3)
Block(1,-4,-7,STONE:6)
Block(1,-4,-6,STONE:6)
Block(1,-4,-5,STONE:6)
Block(1,-4,-4,STONE:6)
Block(1,-4,-3,STONE:6)
Block(1,-4,-2,STONE:6)
Block(1,-4,-1,STONE:6)
Block(1,-3,-7,STONE:6)
Block(1,-3,-6,STONE:6)
Block(1,-3,-5,STONE:6)
Block(1,-3,-4,STONE:6)
Block(1,-3,-3,STONE:6)
Block(1,-3,-2,STONE:6)
Block(1,-3,-1,STONE:6)
Block(1,-2,-7,STONE:6)
Block(1,-2,-6,STONE:6)
Block(1,-2,-5,STONE:6)
Block(1,-2,-4,STONE:6)
Block(1,-2,-3,STONE:6)
Block(1,-2,-2,STONE:6)
Block(1,-2,-1,STONE:6)
Block(1,-1,-7,STONE:6)
Block(1,-1,-6,STONE:6)
Block(1,-1,-5,STONE:6)
Block(1,-1,-4,STONE:6)
Block(1,-1,-3,STONE:6)
Block(1,-1,-2,STONE:6)
Block(1,-1,-1,STONE:6)
Block(1,0,-7,STONE:6)
Block(1,0,-6,STONE:6)
Block(1,0,-5,STONE:6)
Block(1,0,-4,STONE:6)
Block(1,0,-3,STONE:6)
Block(1,0,-2,STONE:6)
Block(1,0,-1,STONE:6)
Block(1,1,-7,STONE:6)
Block(1,1,-6,STONE:6)
Block(1,1,-5,STONE:6)
Block(1,1,-4,STONE:6)
Block(1,1,-3,STONE:6)
Block(1,1,-2,STONE:6)
Block(1,1,-1,STONE:6)
Block(1,2,-7,SMOOTH_BRICK:0)
Block(1,2,-6,SMOOTH_BRICK:0)
Block(1,2,-5,SMOOTH_BRICK:0)
Block(1,2,-4,SMOOTH_BRICK:0)
Block(1,2,-3,SMOOTH_BRICK:0)
Block(1,2,-2,SMOOTH_BRICK:0)
Block(1,2,-1,STONE:6)
Block(1,3,-7,SMOOTH_BRICK:0)
Block(1,3,-6,SMOOTH_BRICK:0)
Block(1,3,-5,SMOOTH_BRICK:0)
Block(1,3,-4,SMOOTH_BRICK:0)
Block(1,3,-3,SMOOTH_BRICK:0)
Block(1,3,-2,SMOOTH_BRICK:0)
Block(1,3,-1,STONE:6)
Block(1,4,-7,COBBLESTONE:0)
Block(1,4,-6,COBBLESTONE:0)
Block(1,4,-5,COBBLESTONE:0)
Block(1,4,-4,COBBLESTONE:0)
Block(1,4,-3,COBBLESTONE:0)
Block(1,4,-2,COBBLESTONE:0)
Block(1,4,-1,STONE:6)
Block(1,5,-7,COBBLESTONE:0)
Block(1,5,-6,COBBLESTONE:0)
Block(1,5,-5,COBBLESTONE:0)
Block(1,5,-4,COBBLESTONE:0)
Block(1,5,-3,COBBLESTONE:0)
Block(1,5,-2,COBBLESTONE:0)
Block(1,5,-1,SMOOTH_BRICK:0)
Block(1,6,-7,COBBLESTONE:0)
Block(1,6,-6,COBBLESTONE:0)
Block(1,6,-5,COBBLESTONE:0)
Block(1,6,-4,COBBLESTONE:0)
Block(1,6,-3,COBBLESTONE:0)
Block(1,6,-2,COBBLESTONE:0)
Block(1,6,-1,SMOOTH_BRICK:0)
Block(1,7,-7,COBBLESTONE:0)
Block(1,7,-6,COBBLESTONE:0)
Block(1,7,-5,COBBLESTONE:0)
Block(1,7,-4,COBBLESTONE:0)
Block(1,7,-3,COBBLESTONE:0)
Block(1,7,-2,COBBLESTONE:0)
Block(1,7,-1,SMOOTH_BRICK:0)
Block(1,8,-7,STONE:6)
Block(1,8,-6,LOG:4)
Block(1,8,-5,WOOD_STEP:13)
Block(1,8,-4,WOOD_STEP:13)
Block(1,8,-3,WOOD_STEP:13)
Block(1,8,-2,WOOD_STEP:13)
Block(1,8,-1,COBBLESTONE:0)
Block(1,9,-7,AIR:0)
Block(1,9,-6,AIR:0)
Block(1,9,-5,AIR:0)
Block(1,9,-4,STONE:6)
Block(1,9,-3,STONE:6)
Block(1,9,-2,AIR:0)
Block(1,9,-1,STEP:0)
Block(1,10,-7,AIR:0)
Block(1,10,-6,AIR:0)
Block(1,10,-5,AIR:0)
Block(1,10,-4,STONE:6)
Block(1,10,-3,STONE:6)
Block(1,10,-2,AIR:0)
Block(1,10,-1,AIR:0)
Block(1,10,0,WOOD_STEP:13)
Block(1,11,-7,WOOD_STEP:13)
Block(1,11,-6,LOG:4)
Block(1,11,-5,STONE:6)
Block(1,11,-4,STONE:6)
Block(1,11,-3,LOG:4)
Block(1,11,-2,WOOD_STEP:5)
Block(1,11,-1,WOOD_STEP:5)
Block(1,12,-7,SMOOTH_BRICK:0)
Block(1,12,-6,SMOOTH_BRICK:0)
Block(1,12,-5,SMOOTH_BRICK:0)
Block(1,12,-4,SMOOTH_BRICK:0)
Block(1,12,-3,SMOOTH_BRICK:0)
Block(1,12,-2,AIR:0)
Block(1,12,-1,AIR:0)
Block(1,13,-7,SMOOTH_BRICK:0)
Block(1,13,-6,SMOOTH_BRICK:0)
Block(1,13,-5,SMOOTH_BRICK:0)
Block(1,13,-4,SMOOTH_BRICK:0)
Block(1,13,-3,COBBLESTONE:0)
Block(1,13,-2,AIR:0)
Block(1,13,-1,AIR:0)
Block(1,14,-7,SMOOTH_BRICK:0)
Block(1,14,-6,SMOOTH_BRICK:0)
Block(1,14,-5,SMOOTH_BRICK:0)
Block(1,14,-4,SMOOTH_BRICK:0)
Block(1,14,-3,SMOOTH_BRICK:0)
Block(1,14,-2,AIR:0)
Block(1,14,-1,AIR:0)
Block(1,15,-7,SMOOTH_BRICK:0)
Block(1,15,-6,SMOOTH_BRICK:0)
Block(1,15,-5,AIR:0)
Block(1,15,-4,AIR:0)
Block(1,15,-3,WOOD_STEP:5)
Block(1,15,-2,AIR:0)
Block(1,15,-1,AIR:0)
Block(1,16,-7,SMOOTH_BRICK:0)
Block(1,16,-6,SMOOTH_BRICK:0)
Block(1,16,-5,AIR:0)
Block(1,16,-4,AIR:0)
Block(1,16,-3,WOOD_STEP:13)
Block(1,16,-2,AIR:0)
Block(1,16,-1,AIR:0)
Block(1,17,-7,SMOOTH_BRICK:0)
Block(1,17,-6,SMOOTH_BRICK:0)
Block(1,17,-5,WOOD_STEP:13)
Block(1,17,-4,WOOD_STEP:13)
Block(1,17,-3,SMOOTH_BRICK:0)
Block(1,17,-2,AIR:0)
Block(1,17,-1,AIR:0)
Block(1,18,-7,SMOOTH_BRICK:0)
Block(1,18,-6,SMOOTH_BRICK:0)
Block(1,18,-5,SMOOTH_BRICK:0)
Block(1,18,-4,SMOOTH_BRICK:0)
Block(1,18,-3,SMOOTH_BRICK:0)
Block(1,18,-2,AIR:0)
Block(1,18,-1,AIR:0)
Block(1,19,-7,SMOOTH_BRICK:0)
Block(1,19,-6,SMOOTH_BRICK:0)
Block(1,19,-5,SMOOTH_BRICK:0)
Block(1,19,-4,SMOOTH_BRICK:0)
Block(1,19,-3,SMOOTH_BRICK:0)
Block(1,19,-2,AIR:0)
Block(1,19,-1,AIR:0)
Block(1,20,-7,SMOOTH_BRICK:0)
Block(1,20,-6,LOG:4)
Block(1,20,-5,SMOOTH_BRICK:0)
Block(1,20,-4,SMOOTH_BRICK:0)
Block(1,20,-3,STONE:6)
Block(1,20,-2,AIR:0)
Block(1,20,-1,AIR:0)
Block(1,21,-7,AIR:0)
Block(1,21,-6,AIR:0)
Block(1,21,-5,AIR:0)
Block(1,21,-4,AIR:0)
Block(1,21,-3,STONE:6)
Block(1,21,-2,AIR:0)
Block(1,21,-1,AIR:0)
Block(1,22,-7,AIR:0)
Block(1,22,-6,AIR:0)
Block(1,22,-5,AIR:0)
Block(1,22,-4,AIR:0)
Block(1,22,-3,SMOOTH_BRICK:0)
Block(1,22,-2,AIR:0)
Block(1,22,-1,AIR:0)
Block(1,23,-7,AIR:0)
Block(1,23,-6,AIR:0)
Block(1,23,-5,AIR:0)
Block(1,23,-4,AIR:0)
Block(1,23,-3,SMOOTH_BRICK:0)
Block(1,23,-2,AIR:0)
Block(1,23,-1,AIR:0)
Block(1,24,-7,WOOD_STEP:13)
Block(1,24,-6,LOG:4)
Block(1,24,-5,WOOD_STEP:13)
Block(1,24,-4,WOOD_STEP:13)
Block(1,24,-3,SMOOTH_STAIRS:3)
Block(1,24,-2,AIR:0)
Block(1,24,-1,AIR:0)
Block(1,25,-7,SMOOTH_BRICK:0)
Block(1,25,-6,COBBLE_WALL:0)
Block(1,25,-5,COBBLE_WALL:0)
Block(1,25,-4,LOG:0)
Block(1,25,-3,AIR:0)
Block(1,25,-2,AIR:0)
Block(1,25,-1,AIR:0)
Block(1,26,-7,SMOOTH_BRICK:0)
Block(1,26,-6,COBBLE_WALL:0)
Block(1,26,-5,COBBLE_WALL:0)
Block(1,26,-4,LOG:0)
Block(1,26,-3,AIR:0)
Block(1,26,-2,AIR:0)
Block(1,26,-1,AIR:0)
Block(1,27,-7,SMOOTH_BRICK:0)
Block(1,27,-6,COBBLE_WALL:0)
Block(1,27,-5,COBBLE_WALL:0)
Block(1,27,-4,LOG:0)
Block(1,27,-3,AIR:0)
Block(1,27,-2,AIR:0)
Block(1,27,-1,AIR:0)
Block(1,28,-7,SMOOTH_BRICK:0)
Block(1,28,-6,COBBLE_WALL:0)
Block(1,28,-5,COBBLE_WALL:0)
Block(1,28,-4,LOG:0)
Block(1,28,-3,AIR:0)
Block(1,28,-2,AIR:0)
Block(1,28,-1,AIR:0)
Block(1,29,-7,SMOOTH_BRICK:0)
Block(1,29,-6,SMOOTH_BRICK:0)
Block(1,29,-5,SMOOTH_BRICK:0)
Block(1,29,-4,STEP:0)
Block(1,29,-3,AIR:0)
Block(1,29,-2,AIR:0)
Block(1,29,-1,AIR:0)
Block(1,30,-7,SMOOTH_BRICK:0)
Block(1,30,-6,SMOOTH_STAIRS:0)
Block(1,30,-5,SMOOTH_BRICK:0)
Block(1,30,-4,AIR:0)
Block(1,30,-3,AIR:0)
Block(1,30,-2,AIR:0)
Block(1,30,-1,AIR:0)
Block(1,31,-7,SMOOTH_BRICK:0)
Block(1,31,-6,SMOOTH_STAIRS:4)
Block(1,31,-5,SMOOTH_STAIRS:0)
Block(1,31,-4,AIR:0)
Block(1,31,-3,AIR:0)
Block(1,31,-2,AIR:0)
Block(1,31,-1,AIR:0)
Block(1,32,-7,SMOOTH_BRICK:0)
Block(1,32,-6,STEP:0)
Block(1,32,-5,AIR:0)
Block(1,32,-4,AIR:0)
Block(1,32,-3,AIR:0)
Block(1,32,-2,AIR:0)
Block(1,32,-1,AIR:0)
Block(1,33,-7,SMOOTH_BRICK:0)
Block(1,33,-6,AIR:0)
Block(1,33,-5,AIR:0)
Block(1,33,-4,AIR:0)
Block(1,33,-3,AIR:0)
Block(1,33,-2,AIR:0)
Block(1,33,-1,AIR:0)
Block(1,34,-7,SMOOTH_BRICK:0)
Block(1,34,-6,AIR:0)
Block(1,34,-5,AIR:0)
Block(1,34,-4,AIR:0)
Block(1,34,-3,AIR:0)
Block(1,34,-2,AIR:0)
Block(1,34,-1,AIR:0)
Block(1,35,-7,SMOOTH_BRICK:0)
Block(1,35,-6,AIR:0)
Block(1,35,-5,AIR:0)
Block(1,35,-4,AIR:0)
Block(1,35,-3,AIR:0)
Block(1,35,-2,AIR:0)
Block(1,35,-1,AIR:0)
Block(1,36,-7,SMOOTH_BRICK:0)
Block(1,36,-6,AIR:0)
Block(1,36,-5,AIR:0)
Block(1,36,-4,AIR:0)
Block(1,36,-3,AIR:0)
Block(1,36,-2,AIR:0)
Block(1,36,-1,AIR:0)
Block(1,37,-7,SMOOTH_BRICK:0)
Block(1,37,-6,SMOOTH_STAIRS:7)
Block(1,37,-5,AIR:0)
Block(1,37,-4,AIR:0)
Block(1,37,-3,AIR:0)
Block(1,37,-2,AIR:0)
Block(1,37,-1,AIR:0)
Block(1,38,-7,SMOOTH_BRICK:0)
Block(1,38,-6,DOUBLE_STEP:0)
Block(1,38,-5,DOUBLE_STEP:0)
Block(1,38,-4,AIR:0)
Block(1,38,-3,AIR:0)
Block(1,38,-2,AIR:0)
Block(1,38,-1,AIR:0)
Block(1,39,-7,STEP:0)
Block(1,39,-6,SMOOTH_BRICK:0)
Block(1,39,-5,SMOOTH_BRICK:0)
Block(1,39,-4,AIR:0)
Block(1,39,-3,AIR:0)
Block(1,39,-2,AIR:0)
Block(1,39,-1,AIR:0)
Block(1,40,-7,AIR:0)
Block(1,40,-6,COBBLE_WALL:0)
Block(1,40,-5,DOUBLE_STEP:0)
Block(1,40,-4,AIR:0)
Block(1,40,-3,AIR:0)
Block(1,40,-2,AIR:0)
Block(1,40,-1,AIR:0)
Block(1,41,-7,AIR:0)
Block(1,41,-6,COBBLE_WALL:0)
Block(1,41,-5,AIR:0)
Block(1,41,-4,AIR:0)
Block(1,41,-3,AIR:0)
Block(1,41,-2,AIR:0)
Block(1,41,-1,AIR:0)
Block(1,42,-7,AIR:0)
Block(1,42,-6,COBBLE_WALL:0)
Block(1,42,-5,AIR:0)
Block(1,42,-4,AIR:0)
Block(1,42,-3,AIR:0)
Block(1,42,-2,AIR:0)
Block(1,42,-1,AIR:0)
Block(1,43,-7,AIR:0)
Block(1,43,-6,DARK_OAK_FENCE:0)
Block(1,43,-5,AIR:0)
Block(1,43,-4,AIR:0)
Block(1,43,-3,AIR:0)
Block(1,43,-2,AIR:0)
Block(1,43,-1,AIR:0)
Block(1,44,-7,AIR:0)
Block(1,44,-6,DARK_OAK_FENCE:0)
Block(1,44,-5,AIR:0)
Block(1,44,-4,AIR:0)
Block(1,44,-3,AIR:0)
Block(1,44,-2,AIR:0)
Block(1,44,-1,AIR:0)
Block(1,45,-7,AIR:0)
Block(1,45,-6,AIR:0)
Block(1,45,-5,AIR:0)
Block(1,45,-4,AIR:0)
Block(1,45,-3,AIR:0)
Block(1,45,-2,AIR:0)
Block(1,45,-1,AIR:0)
Block(1,46,-7,AIR:0)
Block(1,46,-6,AIR:0)
Block(1,46,-5,AIR:0)
Block(1,46,-4,AIR:0)
Block(1,46,-3,AIR:0)
Block(1,46,-2,AIR:0)
Block(1,46,-1,AIR:0)
Block(1,47,-7,AIR:0)
Block(1,47,-6,AIR:0)
Block(1,47,-5,AIR:0)
Block(1,47,-4,AIR:0)
Block(1,47,-3,AIR:0)
Block(1,47,-2,AIR:0)
Block(1,47,-1,AIR:0)
Block(1,48,-7,AIR:0)
Block(1,48,-6,AIR:0)
Block(1,48,-5,AIR:0)
Block(1,48,-4,AIR:0)
Block(1,48,-3,AIR:0)
Block(1,48,-2,AIR:0)
Block(1,48,-1,AIR:0)
Block(1,49,-7,AIR:0)
Block(1,49,-6,AIR:0)
Block(1,49,-5,AIR:0)
Block(1,49,-4,AIR:0)
Block(1,49,-3,AIR:0)
Block(1,49,-2,AIR:0)
Block(1,49,-1,AIR:0)
Block(1,50,-7,AIR:0)
Block(1,50,-6,AIR:0)
Block(1,50,-5,AIR:0)
