Author: NLBlackEagle
Description: No description given
SettingsMode: WriteDisable
Frequency: 0
SpawnHeight: highestBlock
UseCenterForHighestBlock: true
MinHeight: 0
MaxHeight: 256
InheritBO3: 
InheritBO3Rotation: NORTH
OverrideChildSettings: true
OverrideParentHeight: false
CanOverride: false
BranchFrequency: 0
BranchFrequencyGroup: 
MustBeBelowOther: false
MustBeInside: 
CannotBeInside: 
ReplacesBO3: 
MustBeInsideWorldBorders: false
CanSpawnOnWater: true
SpawnOnWaterOnly: false
SpawnUnderWater: false
SpawnAtWaterLevel: false
HeightOffset: 0
RemoveAir: false
ReplaceAbove:
ReplaceBelow: 
ReplaceWithBiomeBlocks: false
ReplaceWithSurfaceBlock: GRASS
ReplaceWithGroundBlock: DIRT
ReplaceWithStoneBlock: STONE
SmoothRadius: 0
SmoothHeightOffset: 0
SmoothStartTop: false
SmoothStartWood: false
SmoothingSurfaceBlock: 
SmoothingGroundBlock: 
BO3Group: 
IsSpawnPoint: false
DoReplaceBlocks: false
RandomBlock(-8,0,-7,STONEBRICK:1,10,STONEBRICK:2,10,COBBLESTONE,10,MOSSY_COBBLESTONE,10,SMOOTH_BRICK,100)
RandomBlock(-8,0,-6,STONEBRICK:1,10,STONEBRICK:2,10,COBBLESTONE,10,MOSSY_COBBLESTONE,10,SMOOTH_BRICK,100)
RandomBlock(-8,0,-5,STONEBRICK:1,10,STONEBRICK:2,10,COBBLESTONE,10,MOSSY_COBBLESTONE,10,SMOOTH_BRICK,100)
RandomBlock(-8,0,-4,STONEBRICK:1,10,STONEBRICK:2,10,COBBLESTONE,10,MOSSY_COBBLESTONE,10,SMOOTH_BRICK,100)
RandomBlock(-8,0,-3,STONEBRICK:1,10,STONEBRICK:2,10,COBBLESTONE,10,MOSSY_COBBLESTONE,10,SMOOTH_BRICK,100)
RandomBlock(-8,0,-2,STONEBRICK:1,10,STONEBRICK:2,10,COBBLESTONE,10,MOSSY_COBBLESTONE,10,SMOOTH_BRICK,100)
RandomBlock(-8,0,-1,STONEBRICK:1,10,STONEBRICK:2,10,COBBLESTONE,10,MOSSY_COBBLESTONE,10,SMOOTH_BRICK,100)
RandomBlock(-8,0,0,STONEBRICK:1,10,STONEBRICK:2,10,COBBLESTONE,10,MOSSY_COBBLESTONE,10,SMOOTH_BRICK,100)
RandomBlock(-8,0,1,STONEBRICK:1,10,STONEBRICK:2,10,COBBLESTONE,10,MOSSY_COBBLESTONE,10,SMOOTH_BRICK,100)
RandomBlock(-8,0,2,STONEBRICK:1,10,STONEBRICK:2,10,COBBLESTONE,10,MOSSY_COBBLESTONE,10,SMOOTH_BRICK,100)
RandomBlock(-8,0,3,STONEBRICK:1,10,STONEBRICK:2,10,COBBLESTONE,10,MOSSY_COBBLESTONE,10,SMOOTH_BRICK,100)
RandomBlock(-8,0,4,STONEBRICK:1,10,STONEBRICK:2,10,COBBLESTONE,10,MOSSY_COBBLESTONE,10,SMOOTH_BRICK,100)
RandomBlock(-8,0,5,STONEBRICK:1,10,STONEBRICK:2,10,COBBLESTONE,10,MOSSY_COBBLESTONE,10,SMOOTH_BRICK,100)
RandomBlock(-8,0,6,STONEBRICK:1,10,STONEBRICK:2,10,COBBLESTONE,10,MOSSY_COBBLESTONE,10,SMOOTH_BRICK,100)
RandomBlock(-8,0,7,STONEBRICK:1,10,STONEBRICK:2,10,COBBLESTONE,10,MOSSY_COBBLESTONE,10,SMOOTH_BRICK,100)
Block(-8,0,8,OBSIDIAN:0)
Block(-8,1,-7,OBSIDIAN:0)
Block(-8,1,-6,OBSIDIAN:0)
Block(-8,1,-5,OBSIDIAN:0)
Block(-8,1,-4,OBSIDIAN:0)
Block(-8,1,-3,OBSIDIAN:0)
Block(-8,1,-2,OBSIDIAN:0)
Block(-8,1,-1,OBSIDIAN:0)
Block(-8,1,0,OBSIDIAN:0)
Block(-8,1,1,OBSIDIAN:0)
Block(-8,1,2,OBSIDIAN:0)
Block(-8,1,3,OBSIDIAN:0)
Block(-8,1,4,OBSIDIAN:0)
Block(-8,1,5,OBSIDIAN:0)
Block(-8,1,6,OBSIDIAN:0)
Block(-8,1,7,OBSIDIAN:0)
Block(-8,1,8,OBSIDIAN:0)
Block(-8,2,-7,OBSIDIAN:0)
Block(-8,2,-6,AIR:0)
Block(-8,2,-5,AIR:0)
Block(-8,2,-4,AIR:0)
Block(-8,2,-3,OBSIDIAN:0)
Block(-8,2,-2,OBSIDIAN:0)
Block(-8,2,-1,OBSIDIAN:0)
Block(-8,2,0,OBSIDIAN:0)
Block(-8,2,1,OBSIDIAN:0)
Block(-8,2,2,OBSIDIAN:0)
Block(-8,2,3,OBSIDIAN:0)
Block(-8,2,4,OBSIDIAN:0)
Block(-8,2,5,OBSIDIAN:0)
Block(-8,2,6,OBSIDIAN:0)
Block(-8,2,7,OBSIDIAN:0)
Block(-8,2,8,OBSIDIAN:0)
Block(-8,3,-7,REDSTONE_WIRE:0)
Block(-8,3,-6,OBSIDIAN:0)
Block(-8,3,-5,OBSIDIAN:0)
Block(-8,3,-4,OBSIDIAN:0)
Block(-8,3,-3,OBSIDIAN:0)
Block(-8,3,-2,OBSIDIAN:0)
Block(-8,3,-1,REDSTONE_WIRE:10)
Block(-8,3,0,OBSIDIAN:0)
Block(-8,3,1,OBSIDIAN:0)
Block(-8,3,2,OBSIDIAN:0)
Block(-8,3,3,OBSIDIAN:0)
Block(-8,3,4,OBSIDIAN:0)
Block(-8,3,5,OBSIDIAN:0)
Block(-8,3,6,OBSIDIAN:0)
Block(-8,3,7,OBSIDIAN:0)
Block(-8,3,8,OBSIDIAN:0)
Block(-8,4,-7,AIR:0)
Block(-8,4,-6,REDSTONE_WIRE:0)
Block(-8,4,-5,REDSTONE_WIRE:0)
Block(-8,4,-4,REDSTONE_WIRE:0)
Block(-8,4,-3,OBSIDIAN:0)
Block(-8,4,-2,OBSIDIAN:0)
Block(-8,4,-1,AIR:0)
Block(-8,4,0,OBSIDIAN:0)
Block(-8,4,1,OBSIDIAN:0)
Block(-8,4,2,OBSIDIAN:0)
Block(-8,4,3,OBSIDIAN:0)
Block(-8,4,4,OBSIDIAN:0)
Block(-8,4,5,OBSIDIAN:0)
Block(-8,4,6,OBSIDIAN:0)
Block(-8,4,7,OBSIDIAN:0)
Block(-8,4,8,OBSIDIAN:0)
Block(-8,5,-7,OBSIDIAN:0)
Block(-8,5,-6,OBSIDIAN:0)
Block(-8,5,-5,OBSIDIAN:0)
Block(-8,5,-4,OBSIDIAN:0)
Block(-8,5,-3,OBSIDIAN:0)
Block(-8,5,-2,OBSIDIAN:0)
Block(-8,5,-1,AIR:0)
Block(-8,5,0,OBSIDIAN:0)
Block(-8,5,1,OBSIDIAN:0)
Block(-8,5,2,OBSIDIAN:0)
Block(-8,5,3,OBSIDIAN:0)
Block(-8,5,4,OBSIDIAN:0)
Block(-8,5,5,OBSIDIAN:0)
Block(-8,5,6,OBSIDIAN:0)
Block(-8,5,7,OBSIDIAN:0)
Block(-8,5,8,OBSIDIAN:0)
RandomBlock(-8,6,-7,STONEBRICK:1,10,STONEBRICK:2,10,COBBLESTONE,10,MOSSY_COBBLESTONE,10,SMOOTH_BRICK,100)
RandomBlock(-8,6,-6,STONEBRICK:1,10,STONEBRICK:2,10,COBBLESTONE,10,MOSSY_COBBLESTONE,10,SMOOTH_BRICK,100)
RandomBlock(-8,6,-5,STONEBRICK:1,10,STONEBRICK:2,10,COBBLESTONE,10,MOSSY_COBBLESTONE,10,SMOOTH_BRICK,100)
RandomBlock(-8,6,-4,STONEBRICK:1,10,STONEBRICK:2,10,COBBLESTONE,10,MOSSY_COBBLESTONE,10,SMOOTH_BRICK,100)
RandomBlock(-8,6,-3,STONEBRICK:1,10,STONEBRICK:2,10,COBBLESTONE,10,MOSSY_COBBLESTONE,10,SMOOTH_BRICK,100)
RandomBlock(-8,6,-2,STONEBRICK:1,10,STONEBRICK:2,10,COBBLESTONE,10,MOSSY_COBBLESTONE,10,SMOOTH_BRICK,100)
RandomBlock(-8,6,-1,STONEBRICK:1,10,STONEBRICK:2,10,COBBLESTONE,10,MOSSY_COBBLESTONE,10,SMOOTH_BRICK,100)
Block(-8,6,0,OBSIDIAN:0)
Block(-8,6,1,OBSIDIAN:0)
Block(-8,6,2,OBSIDIAN:0)
Block(-8,6,3,OBSIDIAN:0)
Block(-8,6,4,OBSIDIAN:0)
Block(-8,6,5,OBSIDIAN:0)
Block(-8,6,6,OBSIDIAN:0)
Block(-8,6,7,OBSIDIAN:0)
Block(-8,6,8,OBSIDIAN:0)
Block(-8,7,-7,AIR:0)
Block(-8,7,-6,AIR:0)
Block(-8,7,-5,AIR:0)
Block(-8,7,-4,AIR:0)
RandomBlock(-8,7,-3,STONEBRICK:1,10,STONEBRICK:2,10,COBBLESTONE,10,MOSSY_COBBLESTONE,10,SMOOTH_BRICK,100)
RandomBlock(-8,7,-2,STONEBRICK:1,10,STONEBRICK:2,10,COBBLESTONE,10,MOSSY_COBBLESTONE,10,SMOOTH_BRICK,100)
RandomBlock(-8,7,-1,STONEBRICK:1,10,STONEBRICK:2,10,COBBLESTONE,10,MOSSY_COBBLESTONE,10,SMOOTH_BRICK,100)
Block(-8,7,0,OBSIDIAN:0)
Block(-8,7,1,OBSIDIAN:0)
Block(-8,7,2,OBSIDIAN:0)
Block(-8,7,3,OBSIDIAN:0)
Block(-8,7,4,OBSIDIAN:0)
Block(-8,7,5,OBSIDIAN:0)
Block(-8,7,6,OBSIDIAN:0)
Block(-8,7,7,OBSIDIAN:0)
Block(-8,7,8,OBSIDIAN:0)
Block(-8,8,-7,AIR:0)
Block(-8,8,-6,AIR:0)
Block(-8,8,-5,AIR:0)
Block(-8,8,-4,AIR:0)
RandomBlock(-8,8,-3,STONEBRICK:1,10,STONEBRICK:2,10,COBBLESTONE,10,MOSSY_COBBLESTONE,10,SMOOTH_BRICK,100)
RandomBlock(-8,8,-2,STONEBRICK:1,10,STONEBRICK:2,10,COBBLESTONE,10,MOSSY_COBBLESTONE,10,SMOOTH_BRICK,100)
RandomBlock(-8,8,-1,STONEBRICK:1,10,STONEBRICK:2,10,COBBLESTONE,10,MOSSY_COBBLESTONE,10,SMOOTH_BRICK,100)
Block(-8,8,0,OBSIDIAN:0)
Block(-8,8,1,OBSIDIAN:0)
Block(-8,8,2,OBSIDIAN:0)
Block(-8,8,3,OBSIDIAN:0)
Block(-8,8,4,OBSIDIAN:0)
Block(-8,8,5,OBSIDIAN:0)
Block(-8,8,6,OBSIDIAN:0)
Block(-8,8,7,OBSIDIAN:0)
Block(-8,8,8,OBSIDIAN:0)
Block(-8,9,-7,AIR:0)
Block(-8,9,-6,AIR:0)
Block(-8,9,-5,AIR:0)
Block(-8,9,-4,AIR:0)
RandomBlock(-8,9,-3,STONEBRICK:1,10,STONEBRICK:2,10,COBBLESTONE,10,MOSSY_COBBLESTONE,10,SMOOTH_BRICK,100)
Block(-8,9,-2,STATIONARY_LAVA:14)
RandomBlock(-8,9,-1,STONEBRICK:1,10,STONEBRICK:2,10,COBBLESTONE,10,MOSSY_COBBLESTONE,10,SMOOTH_BRICK,100)
Block(-8,9,0,OBSIDIAN:0)
Block(-8,9,1,OBSIDIAN:0)
Block(-8,9,2,OBSIDIAN:0)
Block(-8,9,3,OBSIDIAN:0)
Block(-8,9,4,OBSIDIAN:0)
Block(-8,9,5,OBSIDIAN:0)
Block(-8,9,6,OBSIDIAN:0)
Block(-8,9,7,OBSIDIAN:0)
Block(-8,9,8,OBSIDIAN:0)
Block(-8,10,-7,AIR:0)
Block(-8,10,-6,AIR:0)
Block(-8,10,-5,AIR:0)
Block(-8,10,-4,AIR:0)
RandomBlock(-8,10,-3,STONEBRICK:1,10,STONEBRICK:2,10,COBBLESTONE,10,MOSSY_COBBLESTONE,10,SMOOTH_BRICK,100)
Block(-8,10,-2,STATIONARY_LAVA:6)
RandomBlock(-8,10,-1,STONEBRICK:1,10,STONEBRICK:2,10,COBBLESTONE,10,MOSSY_COBBLESTONE,10,SMOOTH_BRICK,100)
Block(-8,10,0,OBSIDIAN:0)
Block(-8,10,1,OBSIDIAN:0)
Block(-8,10,2,OBSIDIAN:0)
Block(-8,10,3,OBSIDIAN:0)
Block(-8,10,4,OBSIDIAN:0)
Block(-8,10,5,OBSIDIAN:0)
Block(-8,10,6,OBSIDIAN:0)
Block(-8,10,7,OBSIDIAN:0)
Block(-8,10,8,OBSIDIAN:0)
Block(-8,11,-7,AIR:0)
Block(-8,11,-6,AIR:0)
Block(-8,11,-5,AIR:0)
Block(-8,11,-4,AIR:0)
RandomBlock(-8,11,-3,STONEBRICK:1,10,STONEBRICK:2,10,COBBLESTONE,10,MOSSY_COBBLESTONE,10,SMOOTH_BRICK,100)
Block(-8,11,-2,AIR:0)
RandomBlock(-8,11,-1,STONEBRICK:1,10,STONEBRICK:2,10,COBBLESTONE,10,MOSSY_COBBLESTONE,10,SMOOTH_BRICK,100)
Block(-8,11,0,OBSIDIAN:0)
Block(-8,11,1,OBSIDIAN:0)
Block(-8,11,2,OBSIDIAN:0)
Block(-8,11,3,OBSIDIAN:0)
Block(-8,11,4,OBSIDIAN:0)
Block(-8,11,5,OBSIDIAN:0)
Block(-8,11,6,OBSIDIAN:0)
Block(-8,11,7,OBSIDIAN:0)
Block(-8,11,8,OBSIDIAN:0)
Block(-8,12,-7,AIR:0)
Block(-8,12,-6,AIR:0)
Block(-8,12,-5,AIR:0)
Block(-8,12,-4,AIR:0)
Block(-8,12,-3,AIR:0)
Block(-8,12,-2,AIR:0)
RandomBlock(-8,12,-1,STONEBRICK:1,10,STONEBRICK:2,10,COBBLESTONE,10,MOSSY_COBBLESTONE,10,SMOOTH_BRICK,100)
Block(-8,12,0,OBSIDIAN:0)
Block(-8,12,1,OBSIDIAN:0)
Block(-8,12,2,OBSIDIAN:0)
Block(-8,12,3,OBSIDIAN:0)
Block(-8,12,4,OBSIDIAN:0)
Block(-8,12,5,OBSIDIAN:0)
Block(-8,12,6,OBSIDIAN:0)
Block(-8,12,7,OBSIDIAN:0)
Block(-8,12,8,OBSIDIAN:0)
Block(-8,13,-7,AIR:0)
Block(-8,13,-6,AIR:0)
Block(-8,13,-5,AIR:0)
Block(-8,13,-4,AIR:0)
Block(-8,13,-3,AIR:0)
Block(-8,13,-2,AIR:0)
RandomBlock(-8,13,-1,STONEBRICK:1,10,STONEBRICK:2,10,COBBLESTONE,10,MOSSY_COBBLESTONE,10,SMOOTH_BRICK,100)
Block(-8,13,0,OBSIDIAN:0)
Block(-8,13,1,OBSIDIAN:0)
Block(-8,13,2,OBSIDIAN:0)
Block(-8,13,3,OBSIDIAN:0)
Block(-8,13,4,OBSIDIAN:0)
Block(-8,13,5,OBSIDIAN:0)
Block(-8,13,6,OBSIDIAN:0)
Block(-8,13,7,OBSIDIAN:0)
Block(-8,13,8,OBSIDIAN:0)
Block(-8,14,-7,AIR:0)
Block(-8,14,-6,AIR:0)
Block(-8,14,-5,AIR:0)
Block(-8,14,-4,AIR:0)
Block(-8,14,-3,AIR:0)
Block(-8,14,-2,AIR:0)
RandomBlock(-8,14,-1,STONEBRICK:1,10,STONEBRICK:2,10,COBBLESTONE,10,MOSSY_COBBLESTONE,10,SMOOTH_BRICK,100)
Block(-8,14,0,OBSIDIAN:0)
Block(-8,14,1,OBSIDIAN:0)
Block(-8,14,2,OBSIDIAN:0)
Block(-8,14,3,OBSIDIAN:0)
Block(-8,14,4,OBSIDIAN:0)
Block(-8,14,5,OBSIDIAN:0)
Block(-8,14,6,OBSIDIAN:0)
Block(-8,14,7,OBSIDIAN:0)
Block(-8,14,8,OBSIDIAN:0)
Block(-8,15,-7,AIR:0)
Block(-8,15,-6,AIR:0)
Block(-8,15,-5,AIR:0)
Block(-8,15,-4,AIR:0)
Block(-8,15,-3,AIR:0)
Block(-8,15,-2,AIR:0)
RandomBlock(-8,15,-1,STONEBRICK:1,10,STONEBRICK:2,10,COBBLESTONE,10,MOSSY_COBBLESTONE,10,SMOOTH_BRICK,100)
Block(-8,15,0,OBSIDIAN:0)
Block(-8,15,1,OBSIDIAN:0)
Block(-8,15,2,OBSIDIAN:0)
Block(-8,15,3,OBSIDIAN:0)
Block(-8,15,4,OBSIDIAN:0)
Block(-8,15,5,OBSIDIAN:0)
Block(-8,15,6,OBSIDIAN:0)
Block(-8,15,7,OBSIDIAN:0)
Block(-8,15,8,OBSIDIAN:0)
Block(-8,16,-7,AIR:0)
Block(-8,16,-6,AIR:0)
Block(-8,16,-5,AIR:0)
Block(-8,16,-4,AIR:0)
Block(-8,16,-3,AIR:0)
Block(-8,16,-2,AIR:0)
RandomBlock(-8,16,-1,STONEBRICK:1,10,STONEBRICK:2,10,COBBLESTONE,10,MOSSY_COBBLESTONE,10,SMOOTH_BRICK,100)
Block(-8,16,0,OBSIDIAN:0)
Block(-8,16,1,OBSIDIAN:0)
Block(-8,16,2,OBSIDIAN:0)
Block(-8,16,3,OBSIDIAN:0)
Block(-8,16,4,OBSIDIAN:0)
Block(-8,16,5,OBSIDIAN:0)
Block(-8,16,6,OBSIDIAN:0)
Block(-8,16,7,OBSIDIAN:0)
Block(-8,16,8,OBSIDIAN:0)
Block(-8,17,-7,AIR:0)
Block(-8,17,-6,AIR:0)
Block(-8,17,-5,AIR:0)
Block(-8,17,-4,AIR:0)
RandomBlock(-8,17,-3,STONEBRICK:1,10,STONEBRICK:2,10,COBBLESTONE,10,MOSSY_COBBLESTONE,10,SMOOTH_BRICK,100)
Block(-8,17,-2,AIR:0)
RandomBlock(-8,17,-1,STONEBRICK:1,10,STONEBRICK:2,10,COBBLESTONE,10,MOSSY_COBBLESTONE,10,SMOOTH_BRICK,100)
Block(-8,17,0,OBSIDIAN:0)
Block(-8,17,1,OBSIDIAN:0)
Block(-8,17,2,OBSIDIAN:0)
Block(-8,17,3,OBSIDIAN:0)
Block(-8,17,4,OBSIDIAN:0)
Block(-8,17,5,OBSIDIAN:0)
Block(-8,17,6,OBSIDIAN:0)
Block(-8,17,7,OBSIDIAN:0)
Block(-8,17,8,OBSIDIAN:0)
RandomBlock(-8,18,-7,STONEBRICK:1,10,STONEBRICK:2,10,COBBLESTONE,10,MOSSY_COBBLESTONE,10,SMOOTH_BRICK,100)
RandomBlock(-8,18,-6,STONEBRICK:1,10,STONEBRICK:2,10,COBBLESTONE,10,MOSSY_COBBLESTONE,10,SMOOTH_BRICK,100)
RandomBlock(-8,18,-5,STONEBRICK:1,10,STONEBRICK:2,10,COBBLESTONE,10,MOSSY_COBBLESTONE,10,SMOOTH_BRICK,100)
RandomBlock(-8,18,-4,STONEBRICK:1,10,STONEBRICK:2,10,COBBLESTONE,10,MOSSY_COBBLESTONE,10,SMOOTH_BRICK,100)
RandomBlock(-8,18,-3,STONEBRICK:1,10,STONEBRICK:2,10,COBBLESTONE,10,MOSSY_COBBLESTONE,10,SMOOTH_BRICK,100)
Block(-8,18,-2,AIR:0)
RandomBlock(-8,18,-1,STONEBRICK:1,10,STONEBRICK:2,10,COBBLESTONE,10,MOSSY_COBBLESTONE,10,SMOOTH_BRICK,100)
Block(-8,18,0,OBSIDIAN:0)
Block(-8,18,1,OBSIDIAN:0)
Block(-8,18,2,OBSIDIAN:0)
Block(-8,18,3,OBSIDIAN:0)
Block(-8,18,4,OBSIDIAN:0)
Block(-8,18,5,OBSIDIAN:0)
Block(-8,18,6,OBSIDIAN:0)
Block(-8,18,7,OBSIDIAN:0)
Block(-8,18,8,OBSIDIAN:0)
Block(-8,19,-7,OBSIDIAN:0)
Block(-8,19,-6,OBSIDIAN:0)
Block(-8,19,-5,OBSIDIAN:0)
Block(-8,19,-4,OBSIDIAN:0)
RandomBlock(-8,19,-3,STONEBRICK:1,10,STONEBRICK:2,10,COBBLESTONE,10,MOSSY_COBBLESTONE,10,SMOOTH_BRICK,100)
Block(-8,19,-2,AIR:0)
RandomBlock(-8,19,-1,STONEBRICK:1,10,STONEBRICK:2,10,COBBLESTONE,10,MOSSY_COBBLESTONE,10,SMOOTH_BRICK,100)
Block(-8,19,0,OBSIDIAN:0)
Block(-8,19,1,OBSIDIAN:0)
Block(-8,19,2,OBSIDIAN:0)
Block(-8,19,3,OBSIDIAN:0)
Block(-8,19,4,OBSIDIAN:0)
Block(-8,19,5,OBSIDIAN:0)
Block(-8,19,6,OBSIDIAN:0)
Block(-8,19,7,OBSIDIAN:0)
Block(-8,19,8,OBSIDIAN:0)
Block(-8,20,-7,STATIONARY_WATER:0)
Block(-8,20,-6,STATIONARY_WATER:0)
Block(-8,20,-5,STATIONARY_WATER:0)
Block(-8,20,-4,OBSIDIAN:0)
RandomBlock(-8,20,-3,STONEBRICK:1,10,STONEBRICK:2,10,COBBLESTONE,10,MOSSY_COBBLESTONE,10,SMOOTH_BRICK,100)
Block(-8,20,-2,AIR:0)
RandomBlock(-8,20,-1,STONEBRICK:1,10,STONEBRICK:2,10,COBBLESTONE,10,MOSSY_COBBLESTONE,10,SMOOTH_BRICK,100)
Block(-8,20,0,OBSIDIAN:0)
Block(-8,20,1,OBSIDIAN:0)
Block(-8,20,2,OBSIDIAN:0)
Block(-8,20,3,OBSIDIAN:0)
Block(-8,20,4,OBSIDIAN:0)
Block(-8,20,5,OBSIDIAN:0)
Block(-8,20,6,OBSIDIAN:0)
Block(-8,20,7,OBSIDIAN:0)
Block(-8,20,8,OBSIDIAN:0)
Block(-8,21,-7,STATIONARY_WATER:0)
Block(-8,21,-6,STATIONARY_WATER:0)
Block(-8,21,-5,STATIONARY_WATER:0)
Block(-8,21,-4,OBSIDIAN:0)
RandomBlock(-8,21,-3,STONEBRICK:1,10,STONEBRICK:2,10,COBBLESTONE,10,MOSSY_COBBLESTONE,10,SMOOTH_BRICK,100)
Block(-8,21,-2,AIR:0)
RandomBlock(-8,21,-1,STONEBRICK:1,10,STONEBRICK:2,10,COBBLESTONE,10,MOSSY_COBBLESTONE,10,SMOOTH_BRICK,100)
Block(-8,21,0,OBSIDIAN:0)
Block(-8,21,1,OBSIDIAN:0)
Block(-8,21,2,OBSIDIAN:0)
Block(-8,21,3,OBSIDIAN:0)
Block(-8,21,4,OBSIDIAN:0)
Block(-8,21,5,OBSIDIAN:0)
Block(-8,21,6,OBSIDIAN:0)
Block(-8,21,7,OBSIDIAN:0)
Block(-8,21,8,OBSIDIAN:0)
Block(-8,22,-7,STATIONARY_WATER:0)
Block(-8,22,-6,STATIONARY_WATER:0)
Block(-8,22,-5,STATIONARY_WATER:0)
Block(-8,22,-4,OBSIDIAN:0)
RandomBlock(-8,22,-3,STONEBRICK:1,10,STONEBRICK:2,10,COBBLESTONE,10,MOSSY_COBBLESTONE,10,SMOOTH_BRICK,100)
Block(-8,22,-2,AIR:0)
RandomBlock(-8,22,-1,STONEBRICK:1,10,STONEBRICK:2,10,COBBLESTONE,10,MOSSY_COBBLESTONE,10,SMOOTH_BRICK,100)
Block(-8,22,0,OBSIDIAN:0)
Block(-8,22,1,OBSIDIAN:0)
Block(-8,22,2,OBSIDIAN:0)
Block(-8,22,3,OBSIDIAN:0)
Block(-8,22,4,OBSIDIAN:0)
Block(-8,22,5,OBSIDIAN:0)
Block(-8,22,6,OBSIDIAN:0)
Block(-8,22,7,OBSIDIAN:0)
Block(-8,22,8,OBSIDIAN:0)
Block(-8,23,-7,STATIONARY_WATER:0)
Block(-8,23,-6,STATIONARY_WATER:0)
Block(-8,23,-5,STATIONARY_WATER:0)
Block(-8,23,-4,OBSIDIAN:0)
RandomBlock(-8,23,-3,STONEBRICK:1,10,STONEBRICK:2,10,COBBLESTONE,10,MOSSY_COBBLESTONE,10,SMOOTH_BRICK,100)
Block(-8,23,-2,AIR:0)
RandomBlock(-8,23,-1,STONEBRICK:1,10,STONEBRICK:2,10,COBBLESTONE,10,MOSSY_COBBLESTONE,10,SMOOTH_BRICK,100)
Block(-8,23,0,OBSIDIAN:0)
Block(-8,23,1,OBSIDIAN:0)
Block(-8,23,2,OBSIDIAN:0)
Block(-8,23,3,OBSIDIAN:0)
Block(-8,23,4,OBSIDIAN:0)
Block(-8,23,5,OBSIDIAN:0)
Block(-8,23,6,OBSIDIAN:0)
Block(-8,23,7,OBSIDIAN:0)
Block(-8,23,8,OBSIDIAN:0)
RandomBlock(-8,24,-7,STONEBRICK:1,10,STONEBRICK:2,10,COBBLESTONE,10,MOSSY_COBBLESTONE,10,SMOOTH_BRICK,100)
RandomBlock(-8,24,-6,STONEBRICK:1,10,STONEBRICK:2,10,COBBLESTONE,10,MOSSY_COBBLESTONE,10,SMOOTH_BRICK,100)
RandomBlock(-8,24,-5,STONEBRICK:1,10,STONEBRICK:2,10,COBBLESTONE,10,MOSSY_COBBLESTONE,10,SMOOTH_BRICK,100)
RandomBlock(-8,24,-4,STONEBRICK:1,10,STONEBRICK:2,10,COBBLESTONE,10,MOSSY_COBBLESTONE,10,SMOOTH_BRICK,100)
RandomBlock(-8,24,-3,STONEBRICK:1,10,STONEBRICK:2,10,COBBLESTONE,10,MOSSY_COBBLESTONE,10,SMOOTH_BRICK,100)
RandomBlock(-8,24,-2,STONEBRICK:1,10,STONEBRICK:2,10,COBBLESTONE,10,MOSSY_COBBLESTONE,10,SMOOTH_BRICK,100)
RandomBlock(-8,24,-1,STONEBRICK:1,10,STONEBRICK:2,10,COBBLESTONE,10,MOSSY_COBBLESTONE,10,SMOOTH_BRICK,100)
Block(-8,24,0,OBSIDIAN:0)
Block(-8,24,1,OBSIDIAN:0)
Block(-8,24,2,OBSIDIAN:0)
Block(-8,24,3,OBSIDIAN:0)
Block(-8,24,4,OBSIDIAN:0)
Block(-8,24,5,OBSIDIAN:0)
Block(-8,24,6,OBSIDIAN:0)
Block(-8,24,7,OBSIDIAN:0)
Block(-8,24,8,OBSIDIAN:0)
Block(-8,25,-7,OBSIDIAN:0)
Block(-8,25,-6,OBSIDIAN:0)
Block(-8,25,-5,OBSIDIAN:0)
Block(-8,25,-4,OBSIDIAN:0)
Block(-8,25,-3,OBSIDIAN:0)
Block(-8,25,-2,OBSIDIAN:0)
RandomBlock(-8,25,-1,STONEBRICK:1,10,STONEBRICK:2,10,COBBLESTONE,10,MOSSY_COBBLESTONE,10,SMOOTH_BRICK,100)
Block(-8,25,0,OBSIDIAN:0)
Block(-8,25,1,OBSIDIAN:0)
Block(-8,25,2,OBSIDIAN:0)
Block(-8,25,3,OBSIDIAN:0)
Block(-8,25,4,OBSIDIAN:0)
Block(-8,25,5,OBSIDIAN:0)
Block(-8,25,6,OBSIDIAN:0)
Block(-8,25,7,OBSIDIAN:0)
Block(-8,25,8,OBSIDIAN:0)
Block(-8,26,-7,STONE_PLATE:0)
RandomBlock(-8,26,-6,STONEBRICK:1,10,STONEBRICK:2,10,COBBLESTONE,10,MOSSY_COBBLESTONE,10,SMOOTH_BRICK,100)
Block(-8,26,-5,STONE_PLATE:0)
RandomBlock(-8,26,-4,STONEBRICK:1,10,STONEBRICK:2,10,COBBLESTONE,10,MOSSY_COBBLESTONE,10,SMOOTH_BRICK,100)
Block(-8,26,-3,SMOOTH_STAIRS:1)
Block(-8,26,-2,SMOOTH_STAIRS:1)
RandomBlock(-8,26,-1,STONEBRICK:1,10,STONEBRICK:2,10,COBBLESTONE,10,MOSSY_COBBLESTONE,10,SMOOTH_BRICK,100)
Block(-8,26,0,OBSIDIAN:0)
Block(-8,26,1,OBSIDIAN:0)
Block(-8,26,2,OBSIDIAN:0)
Block(-8,26,3,OBSIDIAN:0)
Block(-8,26,4,OBSIDIAN:0)
Block(-8,26,5,OBSIDIAN:0)
Block(-8,26,6,OBSIDIAN:0)
Block(-8,26,7,OBSIDIAN:0)
Block(-8,26,8,OBSIDIAN:0)
Block(-8,27,-7,AIR:0)
RandomBlock(-8,27,-6,STONEBRICK:1,10,STONEBRICK:2,10,COBBLESTONE,10,MOSSY_COBBLESTONE,10,SMOOTH_BRICK,100)
Block(-8,27,-5,AIR:0)
RandomBlock(-8,27,-4,STONEBRICK:1,10,STONEBRICK:2,10,COBBLESTONE,10,MOSSY_COBBLESTONE,10,SMOOTH_BRICK,100)
Block(-8,27,-3,AIR:0)
Block(-8,27,-2,AIR:0)
RandomBlock(-8,27,-1,STONEBRICK:1,10,STONEBRICK:2,10,COBBLESTONE,10,MOSSY_COBBLESTONE,10,SMOOTH_BRICK,100)
Block(-8,27,0,OBSIDIAN:0)
Block(-8,27,1,OBSIDIAN:0)
Block(-8,27,2,OBSIDIAN:0)
Block(-8,27,3,OBSIDIAN:0)
Block(-8,27,4,OBSIDIAN:0)
Block(-8,27,5,OBSIDIAN:0)
Block(-8,27,6,OBSIDIAN:0)
Block(-8,27,7,OBSIDIAN:0)
Block(-8,27,8,OBSIDIAN:0)
Block(-8,28,-7,AIR:0)
RandomBlock(-8,28,-6,STONEBRICK:1,10,STONEBRICK:2,10,COBBLESTONE,10,MOSSY_COBBLESTONE,10,SMOOTH_BRICK,100)
Block(-8,28,-5,AIR:0)
RandomBlock(-8,28,-4,STONEBRICK:1,10,STONEBRICK:2,10,COBBLESTONE,10,MOSSY_COBBLESTONE,10,SMOOTH_BRICK,100)
Block(-8,28,-3,AIR:0)
Block(-8,28,-2,AIR:0)
RandomBlock(-8,28,-1,STONEBRICK:1,10,STONEBRICK:2,10,COBBLESTONE,10,MOSSY_COBBLESTONE,10,SMOOTH_BRICK,100)
Block(-8,28,0,OBSIDIAN:0)
Block(-8,28,1,OBSIDIAN:0)
Block(-8,28,2,OBSIDIAN:0)
Block(-8,28,3,OBSIDIAN:0)
Block(-8,28,4,OBSIDIAN:0)
Block(-8,28,5,OBSIDIAN:0)
Block(-8,28,6,OBSIDIAN:0)
Block(-8,28,7,OBSIDIAN:0)
Block(-8,28,8,OBSIDIAN:0)
Block(-8,29,-7,AIR:0)
RandomBlock(-8,29,-6,STONEBRICK:1,10,STONEBRICK:2,10,COBBLESTONE,10,MOSSY_COBBLESTONE,10,SMOOTH_BRICK,100)
Block(-8,29,-5,AIR:0)
RandomBlock(-8,29,-4,STONEBRICK:1,10,STONEBRICK:2,10,COBBLESTONE,10,MOSSY_COBBLESTONE,10,SMOOTH_BRICK,100)
Block(-8,29,-3,AIR:0)
Block(-8,29,-2,AIR:0)
RandomBlock(-8,29,-1,STONEBRICK:1,10,STONEBRICK:2,10,COBBLESTONE,10,MOSSY_COBBLESTONE,10,SMOOTH_BRICK,100)
Block(-8,29,0,OBSIDIAN:0)
Block(-8,29,1,OBSIDIAN:0)
Block(-8,29,2,OBSIDIAN:0)
Block(-8,29,3,OBSIDIAN:0)
Block(-8,29,4,OBSIDIAN:0)
Block(-8,29,5,OBSIDIAN:0)
Block(-8,29,6,OBSIDIAN:0)
Block(-8,29,7,OBSIDIAN:0)
Block(-8,29,8,OBSIDIAN:0)
Block(-8,30,-7,AIR:0)
RandomBlock(-8,30,-6,STONEBRICK:1,10,STONEBRICK:2,10,COBBLESTONE,10,MOSSY_COBBLESTONE,10,SMOOTH_BRICK,100)
Block(-8,30,-5,AIR:0)
RandomBlock(-8,30,-4,STONEBRICK:1,10,STONEBRICK:2,10,COBBLESTONE,10,MOSSY_COBBLESTONE,10,SMOOTH_BRICK,100)
Block(-8,30,-3,AIR:0)
Block(-8,30,-2,AIR:0)
RandomBlock(-8,30,-1,STONEBRICK:1,10,STONEBRICK:2,10,COBBLESTONE,10,MOSSY_COBBLESTONE,10,SMOOTH_BRICK,100)
Block(-8,30,0,OBSIDIAN:0)
Block(-8,30,1,OBSIDIAN:0)
Block(-8,30,2,OBSIDIAN:0)
Block(-8,30,3,OBSIDIAN:0)
Block(-8,30,4,OBSIDIAN:0)
Block(-8,30,5,OBSIDIAN:0)
Block(-8,30,6,OBSIDIAN:0)
Block(-8,30,7,OBSIDIAN:0)
Block(-8,30,8,OBSIDIAN:0)
RandomBlock(-8,31,-7,STONEBRICK:1,10,STONEBRICK:2,10,COBBLESTONE,10,MOSSY_COBBLESTONE,10,SMOOTH_BRICK,100)
Block(-8,31,-6,OBSIDIAN:0)
RandomBlock(-8,31,-5,STONEBRICK:1,10,STONEBRICK:2,10,COBBLESTONE,10,MOSSY_COBBLESTONE,10,SMOOTH_BRICK,100)
RandomBlock(-8,31,-4,STONEBRICK:1,10,STONEBRICK:2,10,COBBLESTONE,10,MOSSY_COBBLESTONE,10,SMOOTH_BRICK,100)
Block(-8,31,-3,SMOOTH_STAIRS:7)
Block(-8,31,-2,SMOOTH_STAIRS:6)
RandomBlock(-8,31,-1,STONEBRICK:1,10,STONEBRICK:2,10,COBBLESTONE,10,MOSSY_COBBLESTONE,10,SMOOTH_BRICK,100)
Block(-8,31,0,OBSIDIAN:0)
Block(-8,31,1,OBSIDIAN:0)
Block(-8,31,2,OBSIDIAN:0)
Block(-8,31,3,OBSIDIAN:0)
Block(-8,31,4,OBSIDIAN:0)
Block(-8,31,5,OBSIDIAN:0)
Block(-8,31,6,OBSIDIAN:0)
Block(-8,31,7,OBSIDIAN:0)
Block(-8,31,8,OBSIDIAN:0)
Block(-8,32,-7,OBSIDIAN:0)
Block(-8,32,-6,REDSTONE_WIRE:0)
Block(-8,32,-5,OBSIDIAN:0)
RandomBlock(-8,32,-4,STONEBRICK:1,10,STONEBRICK:2,10,COBBLESTONE,10,MOSSY_COBBLESTONE,10,SMOOTH_BRICK,100)
RandomBlock(-8,32,-3,STONEBRICK:1,10,STONEBRICK:2,10,COBBLESTONE,10,MOSSY_COBBLESTONE,10,SMOOTH_BRICK,100)
RandomBlock(-8,32,-2,STONEBRICK:1,10,STONEBRICK:2,10,COBBLESTONE,10,MOSSY_COBBLESTONE,10,SMOOTH_BRICK,100)
RandomBlock(-8,32,-1,STONEBRICK:1,10,STONEBRICK:2,10,COBBLESTONE,10,MOSSY_COBBLESTONE,10,SMOOTH_BRICK,100)
Block(-8,32,0,OBSIDIAN:0)
Block(-8,32,1,OBSIDIAN:0)
Block(-8,32,2,OBSIDIAN:0)
Block(-8,32,3,OBSIDIAN:0)
Block(-8,32,4,OBSIDIAN:0)
Block(-8,32,5,OBSIDIAN:0)
Block(-8,32,6,OBSIDIAN:0)
Block(-8,32,7,OBSIDIAN:0)
Block(-8,32,8,OBSIDIAN:0)
Block(-8,33,-7,REDSTONE_WIRE:0)
Block(-8,33,-6,AIR:0)
Block(-8,33,-5,OBSIDIAN:0)
RandomBlock(-8,33,-4,STONEBRICK:1,10,STONEBRICK:2,10,COBBLESTONE,10,MOSSY_COBBLESTONE,10,SMOOTH_BRICK,100)
RandomBlock(-8,33,-3,STONEBRICK:1,10,STONEBRICK:2,10,COBBLESTONE,10,MOSSY_COBBLESTONE,10,SMOOTH_BRICK,100)
RandomBlock(-8,33,-2,STONEBRICK:1,10,STONEBRICK:2,10,COBBLESTONE,10,MOSSY_COBBLESTONE,10,SMOOTH_BRICK,100)
RandomBlock(-8,33,-1,STONEBRICK:1,10,STONEBRICK:2,10,COBBLESTONE,10,MOSSY_COBBLESTONE,10,SMOOTH_BRICK,100)
Block(-8,33,0,OBSIDIAN:0)
Block(-8,33,1,OBSIDIAN:0)
Block(-8,33,2,OBSIDIAN:0)
Block(-8,33,3,OBSIDIAN:0)
Block(-8,33,4,OBSIDIAN:0)
Block(-8,33,5,OBSIDIAN:0)
Block(-8,33,6,OBSIDIAN:0)
Block(-8,33,7,OBSIDIAN:0)
Block(-8,33,8,OBSIDIAN:0)
Block(-8,34,-7,AIR:0)
Block(-8,34,-6,OBSIDIAN:0)
Block(-8,34,-5,OBSIDIAN:0)
RandomBlock(-8,34,-4,STONEBRICK:1,10,STONEBRICK:2,10,COBBLESTONE,10,MOSSY_COBBLESTONE,10,SMOOTH_BRICK,100)
RandomBlock(-8,34,-3,STONEBRICK:1,10,STONEBRICK:2,10,COBBLESTONE,10,MOSSY_COBBLESTONE,10,SMOOTH_BRICK,100)
RandomBlock(-8,34,-2,STONEBRICK:1,10,STONEBRICK:2,10,COBBLESTONE,10,MOSSY_COBBLESTONE,10,SMOOTH_BRICK,100)
RandomBlock(-8,34,-1,STONEBRICK:1,10,STONEBRICK:2,10,COBBLESTONE,10,MOSSY_COBBLESTONE,10,SMOOTH_BRICK,100)
Block(-8,34,0,OBSIDIAN:0)
Block(-8,34,1,OBSIDIAN:0)
Block(-8,34,2,OBSIDIAN:0)
Block(-8,34,3,OBSIDIAN:0)
Block(-8,34,4,OBSIDIAN:0)
Block(-8,34,5,OBSIDIAN:0)
Block(-8,34,6,OBSIDIAN:0)
Block(-8,34,7,OBSIDIAN:0)
Block(-8,34,8,OBSIDIAN:0)
Block(-8,35,-7,OBSIDIAN:0)
Block(-8,35,-6,OBSIDIAN:0)
Block(-8,35,-5,OBSIDIAN:0)
Block(-8,35,-4,OBSIDIAN:0)
Block(-8,35,-3,OBSIDIAN:0)
Block(-8,35,-2,OBSIDIAN:0)
Block(-8,35,-1,OBSIDIAN:0)
Block(-8,35,0,OBSIDIAN:0)
Block(-8,35,1,OBSIDIAN:0)
Block(-8,35,2,OBSIDIAN:0)
Block(-8,35,3,OBSIDIAN:0)
Block(-8,35,4,OBSIDIAN:0)
Block(-8,35,5,OBSIDIAN:0)
Block(-8,35,6,OBSIDIAN:0)
Block(-8,35,7,OBSIDIAN:0)
Block(-8,35,8,OBSIDIAN:0)
Block(-8,36,-7,OBSIDIAN:0)
Block(-8,36,-6,OBSIDIAN:0)
Block(-8,36,-5,OBSIDIAN:0)
Block(-8,36,-4,OBSIDIAN:0)
Block(-8,36,-3,OBSIDIAN:0)
Block(-8,36,-2,OBSIDIAN:0)
Block(-8,36,-1,OBSIDIAN:0)
Block(-8,36,0,OBSIDIAN:0)
Block(-8,36,1,OBSIDIAN:0)
Block(-8,36,2,OBSIDIAN:0)
Block(-8,36,3,OBSIDIAN:0)
Block(-8,36,4,OBSIDIAN:0)
Block(-8,36,5,OBSIDIAN:0)
Block(-8,36,6,OBSIDIAN:0)
Block(-8,36,7,OBSIDIAN:0)
Block(-8,36,8,OBSIDIAN:0)
Block(-8,37,-7,OBSIDIAN:0)
Block(-8,37,-6,OBSIDIAN:0)
Block(-8,37,-5,OBSIDIAN:0)
Block(-8,37,-4,OBSIDIAN:0)
Block(-8,37,-3,OBSIDIAN:0)
Block(-8,37,-2,OBSIDIAN:0)
Block(-8,37,-1,OBSIDIAN:0)
Block(-8,37,0,OBSIDIAN:0)
Block(-8,37,1,OBSIDIAN:0)
Block(-8,37,2,OBSIDIAN:0)
Block(-8,37,3,OBSIDIAN:0)
Block(-8,37,4,OBSIDIAN:0)
Block(-8,37,5,OBSIDIAN:0)
Block(-8,37,6,OBSIDIAN:0)
Block(-8,37,7,OBSIDIAN:0)
Block(-8,37,8,OBSIDIAN:0)
Block(-8,38,-7,OBSIDIAN:0)
Block(-8,38,-6,OBSIDIAN:0)
Block(-8,38,-5,OBSIDIAN:0)
Block(-8,38,-4,OBSIDIAN:0)
Block(-8,38,-3,OBSIDIAN:0)
Block(-8,38,-2,OBSIDIAN:0)
Block(-8,38,-1,OBSIDIAN:0)
Block(-8,38,0,OBSIDIAN:0)
Block(-8,38,1,OBSIDIAN:0)
Block(-8,38,2,OBSIDIAN:0)
Block(-8,38,3,OBSIDIAN:0)
Block(-8,38,4,OBSIDIAN:0)
Block(-8,38,5,OBSIDIAN:0)
Block(-8,38,6,OBSIDIAN:0)
Block(-8,38,7,OBSIDIAN:0)
Block(-8,38,8,OBSIDIAN:0)
Block(-8,39,-7,OBSIDIAN:0)
Block(-8,39,-6,OBSIDIAN:0)
Block(-8,39,-5,OBSIDIAN:0)
Block(-8,39,-4,OBSIDIAN:0)
Block(-8,39,-3,OBSIDIAN:0)
Block(-8,39,-2,OBSIDIAN:0)
Block(-8,39,-1,OBSIDIAN:0)
Block(-8,39,0,OBSIDIAN:0)
Block(-8,39,1,OBSIDIAN:0)
Block(-8,39,2,OBSIDIAN:0)
Block(-8,39,3,OBSIDIAN:0)
Block(-8,39,4,OBSIDIAN:0)
Block(-8,39,5,OBSIDIAN:0)
Block(-8,39,6,OBSIDIAN:0)
Block(-8,39,7,OBSIDIAN:0)
Block(-8,39,8,OBSIDIAN:0)
Block(-8,40,-7,OBSIDIAN:0)
Block(-8,40,-6,OBSIDIAN:0)
Block(-8,40,-5,OBSIDIAN:0)
Block(-8,40,-4,OBSIDIAN:0)
Block(-8,40,-3,OBSIDIAN:0)
Block(-8,40,-2,OBSIDIAN:0)
Block(-8,40,-1,OBSIDIAN:0)
Block(-8,40,0,OBSIDIAN:0)
Block(-8,40,1,OBSIDIAN:0)
Block(-8,40,2,OBSIDIAN:0)
Block(-8,40,3,OBSIDIAN:0)
Block(-8,40,4,OBSIDIAN:0)
Block(-8,40,5,OBSIDIAN:0)
Block(-8,40,6,OBSIDIAN:0)
Block(-8,40,7,OBSIDIAN:0)
Block(-8,40,8,OBSIDIAN:0)
Block(-8,41,-7,OBSIDIAN:0)
Block(-8,41,-6,OBSIDIAN:0)
Block(-8,41,-5,OBSIDIAN:0)
Block(-8,41,-4,OBSIDIAN:0)
Block(-8,41,-3,OBSIDIAN:0)
Block(-8,41,-2,OBSIDIAN:0)
Block(-8,41,-1,OBSIDIAN:0)
Block(-8,41,0,OBSIDIAN:0)
Block(-8,41,1,OBSIDIAN:0)
Block(-8,41,2,OBSIDIAN:0)
Block(-8,41,3,OBSIDIAN:0)
Block(-8,41,4,OBSIDIAN:0)
Block(-8,41,5,OBSIDIAN:0)
Block(-8,41,6,OBSIDIAN:0)
Block(-8,41,7,OBSIDIAN:0)
Block(-8,41,8,OBSIDIAN:0)
Block(-8,42,-7,OBSIDIAN:0)
Block(-8,42,-6,OBSIDIAN:0)
Block(-8,42,-5,OBSIDIAN:0)
Block(-8,42,-4,OBSIDIAN:0)
Block(-8,42,-3,OBSIDIAN:0)
Block(-8,42,-2,OBSIDIAN:0)
Block(-8,42,-1,OBSIDIAN:0)
Block(-8,42,0,OBSIDIAN:0)
Block(-8,42,1,OBSIDIAN:0)
Block(-8,42,2,OBSIDIAN:0)
Block(-8,42,3,OBSIDIAN:0)
Block(-8,42,4,OBSIDIAN:0)
Block(-8,42,5,OBSIDIAN:0)
Block(-8,42,6,OBSIDIAN:0)
Block(-8,42,7,OBSIDIAN:0)
Block(-8,42,8,OBSIDIAN:0)
Block(-8,43,-7,OBSIDIAN:0)
Block(-8,43,-6,OBSIDIAN:0)
Block(-8,43,-5,OBSIDIAN:0)
Block(-8,43,-4,OBSIDIAN:0)
Block(-8,43,-3,OBSIDIAN:0)
Block(-8,43,-2,OBSIDIAN:0)
Block(-8,43,-1,OBSIDIAN:0)
Block(-8,43,0,OBSIDIAN:0)
Block(-8,43,1,OBSIDIAN:0)
Block(-8,43,2,OBSIDIAN:0)
Block(-8,43,3,OBSIDIAN:0)
Block(-8,43,4,OBSIDIAN:0)
Block(-8,43,5,OBSIDIAN:0)
Block(-8,43,6,OBSIDIAN:0)
Block(-8,43,7,OBSIDIAN:0)
Block(-8,43,8,OBSIDIAN:0)
Block(-8,44,-7,OBSIDIAN:0)
Block(-8,44,-6,OBSIDIAN:0)
Block(-8,44,-5,OBSIDIAN:0)
Block(-8,44,-4,OBSIDIAN:0)
Block(-8,44,-3,OBSIDIAN:0)
Block(-8,44,-2,OBSIDIAN:0)
Block(-8,44,-1,OBSIDIAN:0)
RandomBlock(-8,44,0,STONEBRICK:1,10,STONEBRICK:2,10,COBBLESTONE,10,MOSSY_COBBLESTONE,10,SMOOTH_BRICK,100)
RandomBlock(-8,44,1,STONEBRICK:1,10,STONEBRICK:2,10,COBBLESTONE,10,MOSSY_COBBLESTONE,10,SMOOTH_BRICK,100)
RandomBlock(-8,44,2,STONEBRICK:1,10,STONEBRICK:2,10,COBBLESTONE,10,MOSSY_COBBLESTONE,10,SMOOTH_BRICK,100)
Block(-8,44,3,OBSIDIAN:0)
Block(-8,44,4,OBSIDIAN:0)
Block(-8,44,5,OBSIDIAN:0)
Block(-8,44,6,OBSIDIAN:0)
Block(-8,44,7,OBSIDIAN:0)
Block(-8,44,8,OBSIDIAN:0)
Block(-8,45,-7,OBSIDIAN:0)
Block(-8,45,-6,OBSIDIAN:0)
Block(-8,45,-5,OBSIDIAN:0)
RandomBlock(-8,45,-4,STONEBRICK:1,10,STONEBRICK:2,10,COBBLESTONE,10,MOSSY_COBBLESTONE,10,SMOOTH_BRICK,100)
RandomBlock(-8,45,-3,STONEBRICK:1,10,STONEBRICK:2,10,COBBLESTONE,10,MOSSY_COBBLESTONE,10,SMOOTH_BRICK,100)
RandomBlock(-8,45,-2,STONEBRICK:1,10,STONEBRICK:2,10,COBBLESTONE,10,MOSSY_COBBLESTONE,10,SMOOTH_BRICK,100)
RandomBlock(-8,45,-1,STONEBRICK:1,10,STONEBRICK:2,10,COBBLESTONE,10,MOSSY_COBBLESTONE,10,SMOOTH_BRICK,100)
Block(-8,45,0,AIR:0)
Block(-8,45,1,SMOOTH_STAIRS:4)
Block(-8,45,2,AIR:0)
RandomBlock(-8,45,3,STONEBRICK:1,10,STONEBRICK:2,10,COBBLESTONE,10,MOSSY_COBBLESTONE,10,SMOOTH_BRICK,100)
Block(-8,45,4,OBSIDIAN:0)
Block(-8,45,5,OBSIDIAN:0)
Block(-8,45,6,OBSIDIAN:0)
Block(-8,45,7,OBSIDIAN:0)
Block(-8,45,8,OBSIDIAN:0)
Block(-8,46,-7,OBSIDIAN:0)
Block(-8,46,-6,OBSIDIAN:0)
Block(-8,46,-5,OBSIDIAN:0)
RandomBlock(-8,46,-4,STONEBRICK:1,10,STONEBRICK:2,10,COBBLESTONE,10,MOSSY_COBBLESTONE,10,SMOOTH_BRICK,100)
Block(-8,46,-3,AIR:0)
Block(-8,46,-2,AIR:0)
RandomBlock(-8,46,-1,STONEBRICK:1,10,STONEBRICK:2,10,COBBLESTONE,10,MOSSY_COBBLESTONE,10,SMOOTH_BRICK,100)
Block(-8,46,0,AIR:0)
RandomBlock(-8,46,1,CHEST:/1,../../../Chests/Loot/desert_pyramid.nbt,30,CHEST:/1,../../../Chests/Loot/bone_only_loot.nbt,100)
Block(-8,46,2,AIR:0)
RandomBlock(-8,46,3,STONEBRICK:1,10,STONEBRICK:2,10,COBBLESTONE,10,MOSSY_COBBLESTONE,10,SMOOTH_BRICK,100)
Block(-8,46,4,OBSIDIAN:0)
Block(-8,46,5,OBSIDIAN:0)
Block(-8,46,6,OBSIDIAN:0)
Block(-8,46,7,OBSIDIAN:0)
Block(-8,46,8,OBSIDIAN:0)
Block(-8,47,-7,OBSIDIAN:0)
Block(-8,47,-6,OBSIDIAN:0)
Block(-8,47,-5,OBSIDIAN:0)
RandomBlock(-8,47,-4,STONEBRICK:1,10,STONEBRICK:2,10,COBBLESTONE,10,MOSSY_COBBLESTONE,10,SMOOTH_BRICK,100)
Block(-8,47,-3,AIR:0)
Block(-8,47,-2,AIR:0)
RandomBlock(-8,47,-1,STONEBRICK:1,10,STONEBRICK:2,10,COBBLESTONE,10,MOSSY_COBBLESTONE,10,SMOOTH_BRICK,100)
Block(-8,47,0,AIR:0)
Block(-8,47,1,AIR:0)
Block(-8,47,2,AIR:0)
RandomBlock(-8,47,3,STONEBRICK:1,10,STONEBRICK:2,10,COBBLESTONE,10,MOSSY_COBBLESTONE,10,SMOOTH_BRICK,100)
Block(-8,47,4,OBSIDIAN:0)
Block(-8,47,5,OBSIDIAN:0)
Block(-8,47,6,OBSIDIAN:0)
Block(-8,47,7,OBSIDIAN:0)
Block(-8,47,8,OBSIDIAN:0)
Block(-8,48,-7,OBSIDIAN:0)
Block(-8,48,-6,OBSIDIAN:0)
Block(-8,48,-5,OBSIDIAN:0)
RandomBlock(-8,48,-4,STONEBRICK:1,10,STONEBRICK:2,10,COBBLESTONE,10,MOSSY_COBBLESTONE,10,SMOOTH_BRICK,100)
Block(-8,48,-3,AIR:0)
Block(-8,48,-2,AIR:0)
RandomBlock(-8,48,-1,STONEBRICK:1,10,STONEBRICK:2,10,COBBLESTONE,10,MOSSY_COBBLESTONE,10,SMOOTH_BRICK,100)
RandomBlock(-8,48,0,STONEBRICK:1,10,STONEBRICK:2,10,COBBLESTONE,10,MOSSY_COBBLESTONE,10,SMOOTH_BRICK,100)
RandomBlock(-8,48,1,STONEBRICK:1,10,STONEBRICK:2,10,COBBLESTONE,10,MOSSY_COBBLESTONE,10,SMOOTH_BRICK,100)
RandomBlock(-8,48,2,STONEBRICK:1,10,STONEBRICK:2,10,COBBLESTONE,10,MOSSY_COBBLESTONE,10,SMOOTH_BRICK,100)
RandomBlock(-8,48,3,STONEBRICK:1,10,STONEBRICK:2,10,COBBLESTONE,10,MOSSY_COBBLESTONE,10,SMOOTH_BRICK,100)
Block(-8,48,4,OBSIDIAN:0)
Block(-8,48,5,OBSIDIAN:0)
Block(-8,48,6,OBSIDIAN:0)
Block(-8,48,7,OBSIDIAN:0)
Block(-8,48,8,OBSIDIAN:0)
RandomBlock(-8,49,-7,STONEBRICK:1,10,STONEBRICK:2,10,COBBLESTONE,10,MOSSY_COBBLESTONE,10,SMOOTH_BRICK,100)
RandomBlock(-8,49,-6,STONEBRICK:1,10,STONEBRICK:2,10,COBBLESTONE,10,MOSSY_COBBLESTONE,10,SMOOTH_BRICK,100)
Block(-8,49,-5,OBSIDIAN:0)
RandomBlock(-8,49,-4,STONEBRICK:1,10,STONEBRICK:2,10,COBBLESTONE,10,MOSSY_COBBLESTONE,10,SMOOTH_BRICK,100)
RandomBlock(-8,49,-3,STONEBRICK:1,10,STONEBRICK:2,10,COBBLESTONE,10,MOSSY_COBBLESTONE,10,SMOOTH_BRICK,100)
RandomBlock(-8,49,-2,STONEBRICK:1,10,STONEBRICK:2,10,COBBLESTONE,10,MOSSY_COBBLESTONE,10,SMOOTH_BRICK,100)
RandomBlock(-8,49,-1,STONEBRICK:1,10,STONEBRICK:2,10,COBBLESTONE,10,MOSSY_COBBLESTONE,10,SMOOTH_BRICK,100)
Block(-8,49,0,OBSIDIAN:0)
Block(-8,49,1,OBSIDIAN:0)
Block(-8,49,2,OBSIDIAN:0)
Block(-8,49,3,OBSIDIAN:0)
Block(-8,49,4,OBSIDIAN:0)
RandomBlock(-8,49,5,STONEBRICK:1,10,STONEBRICK:2,10,COBBLESTONE,10,MOSSY_COBBLESTONE,10,SMOOTH_BRICK,100)
RandomBlock(-8,49,6,STONEBRICK:1,10,STONEBRICK:2,10,COBBLESTONE,10,MOSSY_COBBLESTONE,10,SMOOTH_BRICK,100)
RandomBlock(-8,49,7,STONEBRICK:1,10,STONEBRICK:2,10,COBBLESTONE,10,MOSSY_COBBLESTONE,10,SMOOTH_BRICK,100)
Block(-8,49,8,OBSIDIAN:0)
Block(-8,50,-7,OBSIDIAN:0)
Block(-8,50,-6,OBSIDIAN:0)
Block(-8,50,-5,OBSIDIAN:0)
Block(-8,50,-4,OBSIDIAN:0)
Block(-8,50,-3,OBSIDIAN:0)
Block(-8,50,-2,OBSIDIAN:0)
Block(-8,50,-1,OBSIDIAN:0)
Block(-8,50,0,OBSIDIAN:0)
Block(-8,50,1,OBSIDIAN:0)
Block(-8,50,2,OBSIDIAN:0)
Block(-8,50,3,OBSIDIAN:0)
Block(-8,50,4,OBSIDIAN:0)
Block(-8,50,5,OBSIDIAN:0)
Block(-8,50,6,OBSIDIAN:0)
Block(-8,50,7,OBSIDIAN:0)
Block(-8,50,8,OBSIDIAN:0)
Block(-8,51,-7,OBSIDIAN:0)
Block(-8,51,-6,OBSIDIAN:0)
Block(-8,51,-5,OBSIDIAN:0)
Block(-8,51,-4,OBSIDIAN:0)
Block(-8,51,-3,OBSIDIAN:0)
Block(-8,51,-2,OBSIDIAN:0)
Block(-8,51,-1,OBSIDIAN:0)
Block(-8,51,0,OBSIDIAN:0)
Block(-8,51,1,OBSIDIAN:0)
Block(-8,51,2,OBSIDIAN:0)
Block(-8,51,3,OBSIDIAN:0)
Block(-8,51,4,OBSIDIAN:0)
Block(-8,51,5,OBSIDIAN:0)
Block(-8,51,6,OBSIDIAN:0)
Block(-8,51,7,OBSIDIAN:0)
Block(-8,51,8,OBSIDIAN:0)
Block(-8,52,-7,OBSIDIAN:0)
Block(-8,52,-6,OBSIDIAN:0)
Block(-8,52,-5,OBSIDIAN:0)
Block(-8,52,-4,OBSIDIAN:0)
Block(-8,52,-3,OBSIDIAN:0)
Block(-8,52,-2,OBSIDIAN:0)
Block(-8,52,-1,OBSIDIAN:0)
Block(-8,52,0,OBSIDIAN:0)
Block(-8,52,1,OBSIDIAN:0)
Block(-8,52,2,OBSIDIAN:0)
Block(-8,52,3,OBSIDIAN:0)
Block(-8,52,4,OBSIDIAN:0)
Block(-8,52,5,OBSIDIAN:0)
Block(-8,52,6,OBSIDIAN:0)
Block(-8,52,7,OBSIDIAN:0)
Block(-8,52,8,OBSIDIAN:0)
Block(-8,53,-7,OBSIDIAN:0)
Block(-8,53,-6,OBSIDIAN:0)
Block(-8,53,-5,OBSIDIAN:0)
Block(-8,53,-4,OBSIDIAN:0)
Block(-8,53,-3,OBSIDIAN:0)
Block(-8,53,-2,OBSIDIAN:0)
Block(-8,53,-1,OBSIDIAN:0)
Block(-8,53,0,OBSIDIAN:0)
Block(-8,53,1,OBSIDIAN:0)
Block(-8,53,2,OBSIDIAN:0)
Block(-8,53,3,OBSIDIAN:0)
Block(-8,53,4,OBSIDIAN:0)
Block(-8,53,5,OBSIDIAN:0)
Block(-8,53,6,OBSIDIAN:0)
Block(-8,53,7,OBSIDIAN:0)
Block(-8,53,8,OBSIDIAN:0)
Block(-8,54,-7,STONE:0)
Block(-8,54,-6,STONE:0)
Block(-8,54,-5,STONE:0)
Block(-8,54,-4,STONE:0)
Block(-8,54,-3,STONE:0)
Block(-8,54,-2,STONE:0)
Block(-8,54,-1,STONE:0)
Block(-8,54,0,STONE:0)
Block(-8,54,1,STONE:0)
Block(-8,54,2,STONE:0)
Block(-8,54,3,STONE:0)
Block(-8,54,4,STONE:0)
Block(-8,54,5,STONE:0)
Block(-8,54,6,GRASS:0)
Block(-8,54,7,GRASS:0)
Block(-8,54,8,GRASS:0)
Block(-8,55,-7,STONE:0)
Block(-8,55,-6,STONE:0)
Block(-8,55,-5,STONE:0)
Block(-8,55,-4,STONE:0)
Block(-8,55,-3,STONE:0)
Block(-8,55,-2,STONE:0)
Block(-8,55,-1,STONE:0)
Block(-8,55,0,STONE:0)
Block(-8,55,1,STONE:0)
Block(-8,55,2,STONE:0)
Block(-8,55,3,STONE:0)
Block(-8,55,4,STONE:0)
Block(-8,55,5,GRASS:0)
Block(-8,56,-7,STONE:0)
Block(-8,56,-6,STONE:0)
Block(-8,56,-5,STONE:0)
Block(-8,56,-4,STONE:0)
Block(-8,56,-3,STONE:0)
Block(-8,56,-2,STONE:0)
Block(-8,56,-1,STONE:0)
Block(-8,56,0,STONE:0)
Block(-8,56,1,STONE:0)
Block(-8,56,2,STONE:0)
Block(-8,56,3,STONE:0)
Block(-8,56,4,GRASS:0)
Block(-8,57,-7,STONE:0)
Block(-8,57,-6,STONE:0)
Block(-8,57,-5,STONE:0)
Block(-8,57,-4,STONE:0)
Block(-8,57,-3,STONE:0)
Block(-8,57,-2,STONE:0)
Block(-8,57,-1,STONE:0)
Block(-8,57,0,STONE:0)
Block(-8,57,1,STONE:0)
Block(-8,57,2,STONE:0)
Block(-8,57,3,STONE:0)
Block(-8,58,-7,STONE:0)
Block(-8,58,-6,STONE:0)
Block(-8,58,-5,STONE:0)
Block(-8,58,-4,STONE:0)
Block(-8,58,-3,STONE:0)
Block(-8,58,-2,STONE:0)
Block(-8,58,-1,STONE:0)
Block(-8,58,0,STONE:0)
Block(-8,58,1,STONE:0)
Block(-8,58,2,STONE:0)
Block(-8,58,3,GRASS:0)
Block(-8,59,-7,STONE:0)
Block(-8,59,-6,STONE:0)
Block(-8,59,-5,STONE:0)
Block(-8,59,-4,STONE:0)
Block(-8,59,-3,STONE:0)
Block(-8,59,-2,STONE:0)
Block(-8,59,-1,STONE:0)
Block(-8,59,0,STONE:0)
Block(-8,59,1,STONE:0)
Block(-8,59,2,STONE:0)
Block(-8,60,-7,STONE:0)
Block(-8,60,-6,STONE:0)
Block(-8,60,-5,STONE:0)
Block(-8,60,-4,GRASS:0)
Block(-8,60,-3,GRASS:0)
Block(-8,60,-2,GRASS:0)
Block(-8,60,-1,GRASS:0)
Block(-8,60,0,GRASS:0)
Block(-8,60,1,GRASS:0)
Block(-8,60,2,GRASS:0)
Block(-8,61,-7,STONE:0)
Block(-8,61,-6,STONE:0)
Block(-8,61,-5,GRASS:0)
Block(-8,61,-4,AIR:0)
Block(-8,61,-3,AIR:0)
Block(-8,61,-2,AIR:0)
Block(-8,62,-7,GRASS:0)
Block(-8,62,-6,GRASS:0)
Block(-8,62,-5,AIR:0)
Block(-8,62,-4,AIR:0)
Block(-8,62,-3,AIR:0)
Block(-8,62,-2,AIR:0)
RandomBlock(-7,0,-7,STONEBRICK:1,10,STONEBRICK:2,10,COBBLESTONE,10,MOSSY_COBBLESTONE,10,SMOOTH_BRICK,100)
RandomBlock(-7,0,-6,STONEBRICK:1,10,STONEBRICK:2,10,COBBLESTONE,10,MOSSY_COBBLESTONE,10,SMOOTH_BRICK,100)
RandomBlock(-7,0,-5,STONEBRICK:1,10,STONEBRICK:2,10,COBBLESTONE,10,MOSSY_COBBLESTONE,10,SMOOTH_BRICK,100)
RandomBlock(-7,0,-4,STONEBRICK:1,10,STONEBRICK:2,10,COBBLESTONE,10,MOSSY_COBBLESTONE,10,SMOOTH_BRICK,100)
RandomBlock(-7,0,-3,STONEBRICK:1,10,STONEBRICK:2,10,COBBLESTONE,10,MOSSY_COBBLESTONE,10,SMOOTH_BRICK,100)
RandomBlock(-7,0,-2,STONEBRICK:1,10,STONEBRICK:2,10,COBBLESTONE,10,MOSSY_COBBLESTONE,10,SMOOTH_BRICK,100)
RandomBlock(-7,0,-1,STONEBRICK:1,10,STONEBRICK:2,10,COBBLESTONE,10,MOSSY_COBBLESTONE,10,SMOOTH_BRICK,100)
RandomBlock(-7,0,0,STONEBRICK:1,10,STONEBRICK:2,10,COBBLESTONE,10,MOSSY_COBBLESTONE,10,SMOOTH_BRICK,100)
RandomBlock(-7,0,1,STONEBRICK:1,10,STONEBRICK:2,10,COBBLESTONE,10,MOSSY_COBBLESTONE,10,SMOOTH_BRICK,100)
RandomBlock(-7,0,2,STONEBRICK:1,10,STONEBRICK:2,10,COBBLESTONE,10,MOSSY_COBBLESTONE,10,SMOOTH_BRICK,100)
RandomBlock(-7,0,3,STONEBRICK:1,10,STONEBRICK:2,10,COBBLESTONE,10,MOSSY_COBBLESTONE,10,SMOOTH_BRICK,100)
RandomBlock(-7,0,4,STONEBRICK:1,10,STONEBRICK:2,10,COBBLESTONE,10,MOSSY_COBBLESTONE,10,SMOOTH_BRICK,100)
RandomBlock(-7,0,5,STONEBRICK:1,10,STONEBRICK:2,10,COBBLESTONE,10,MOSSY_COBBLESTONE,10,SMOOTH_BRICK,100)
RandomBlock(-7,0,6,STONEBRICK:1,10,STONEBRICK:2,10,COBBLESTONE,10,MOSSY_COBBLESTONE,10,SMOOTH_BRICK,100)
RandomBlock(-7,0,7,STONEBRICK:1,10,STONEBRICK:2,10,COBBLESTONE,10,MOSSY_COBBLESTONE,10,SMOOTH_BRICK,100)
Block(-7,0,8,OBSIDIAN:0)
Block(-7,1,-7,OBSIDIAN:0)
Block(-7,1,-6,OBSIDIAN:0)
Block(-7,1,-5,OBSIDIAN:0)
Block(-7,1,-4,OBSIDIAN:0)
Block(-7,1,-3,OBSIDIAN:0)
Block(-7,1,-2,OBSIDIAN:0)
Block(-7,1,-1,OBSIDIAN:0)
Block(-7,1,0,OBSIDIAN:0)
Block(-7,1,1,OBSIDIAN:0)
Block(-7,1,2,OBSIDIAN:0)
Block(-7,1,3,OBSIDIAN:0)
Block(-7,1,4,OBSIDIAN:0)
Block(-7,1,5,OBSIDIAN:0)
Block(-7,1,6,OBSIDIAN:0)
Block(-7,1,7,OBSIDIAN:0)
Block(-7,1,8,OBSIDIAN:0)
RandomBlock(-7,2,-7,STONEBRICK:1,10,STONEBRICK:2,10,COBBLESTONE,10,MOSSY_COBBLESTONE,10,SMOOTH_BRICK,100)
RandomBlock(-7,2,-6,STONEBRICK:1,10,STONEBRICK:2,10,COBBLESTONE,10,MOSSY_COBBLESTONE,10,SMOOTH_BRICK,100)
RandomBlock(-7,2,-5,STONEBRICK:1,10,STONEBRICK:2,10,COBBLESTONE,10,MOSSY_COBBLESTONE,10,SMOOTH_BRICK,100)
RandomBlock(-7,2,-4,STONEBRICK:1,10,STONEBRICK:2,10,COBBLESTONE,10,MOSSY_COBBLESTONE,10,SMOOTH_BRICK,100)
Block(-7,2,-3,GRAVEL:0)
Block(-7,2,-2,PISTON_BASE:2)
Block(-7,2,-1,OBSIDIAN:0)
Block(-7,2,0,OBSIDIAN:0)
Block(-7,2,1,OBSIDIAN:0)
Block(-7,2,2,OBSIDIAN:0)
Block(-7,2,3,OBSIDIAN:0)
Block(-7,2,4,OBSIDIAN:0)
Block(-7,2,5,OBSIDIAN:0)
Block(-7,2,6,OBSIDIAN:0)
Block(-7,2,7,OBSIDIAN:0)
Block(-7,2,8,OBSIDIAN:0)
Block(-7,3,-7,OBSIDIAN:0)
Block(-7,3,-6,OBSIDIAN:0)
Block(-7,3,-5,OBSIDIAN:0)
Block(-7,3,-4,OBSIDIAN:0)
Block(-7,3,-3,GRAVEL:0)
Block(-7,3,-2,OBSIDIAN:0)
Block(-7,3,-1,REDSTONE_WIRE:11)
Block(-7,3,0,OBSIDIAN:0)
Block(-7,3,1,OBSIDIAN:0)
Block(-7,3,2,OBSIDIAN:0)
Block(-7,3,3,OBSIDIAN:0)
Block(-7,3,4,OBSIDIAN:0)
Block(-7,3,5,OBSIDIAN:0)
Block(-7,3,6,OBSIDIAN:0)
Block(-7,3,7,OBSIDIAN:0)
Block(-7,3,8,OBSIDIAN:0)
Block(-7,4,-7,AIR:0)
Block(-7,4,-6,REDSTONE_COMPARATOR_OFF:7,NBT/76-comparatorC32R32.nbt)
Block(-7,4,-5,DIODE_BLOCK_OFF:12)
Block(-7,4,-4,REDSTONE_WIRE:0)
Block(-7,4,-3,GRAVEL:0)
Block(-7,4,-2,OBSIDIAN:0)
Block(-7,4,-1,AIR:0)
Block(-7,4,0,OBSIDIAN:0)
Block(-7,4,1,OBSIDIAN:0)
Block(-7,4,2,OBSIDIAN:0)
Block(-7,4,3,OBSIDIAN:0)
Block(-7,4,4,OBSIDIAN:0)
Block(-7,4,5,OBSIDIAN:0)
Block(-7,4,6,OBSIDIAN:0)
Block(-7,4,7,OBSIDIAN:0)
Block(-7,4,8,OBSIDIAN:0)
Block(-7,5,-7,OBSIDIAN:0)
Block(-7,5,-6,OBSIDIAN:0)
Block(-7,5,-5,OBSIDIAN:0)
Block(-7,5,-4,OBSIDIAN:0)
Block(-7,5,-3,GRAVEL:0)
Block(-7,5,-2,OBSIDIAN:0)
Block(-7,5,-1,AIR:0)
Block(-7,5,0,OBSIDIAN:0)
Block(-7,5,1,OBSIDIAN:0)
Block(-7,5,2,OBSIDIAN:0)
Block(-7,5,3,OBSIDIAN:0)
Block(-7,5,4,OBSIDIAN:0)
Block(-7,5,5,OBSIDIAN:0)
Block(-7,5,6,OBSIDIAN:0)
Block(-7,5,7,OBSIDIAN:0)
Block(-7,5,8,OBSIDIAN:0)
RandomBlock(-7,6,-7,STONEBRICK:1,10,STONEBRICK:2,10,COBBLESTONE,10,MOSSY_COBBLESTONE,10,SMOOTH_BRICK,100)
RandomBlock(-7,6,-6,STONEBRICK:1,10,STONEBRICK:2,10,COBBLESTONE,10,MOSSY_COBBLESTONE,10,SMOOTH_BRICK,100)
RandomBlock(-7,6,-5,STONEBRICK:1,10,STONEBRICK:2,10,COBBLESTONE,10,MOSSY_COBBLESTONE,10,SMOOTH_BRICK,100)
RandomBlock(-7,6,-4,STONEBRICK:1,10,STONEBRICK:2,10,COBBLESTONE,10,MOSSY_COBBLESTONE,10,SMOOTH_BRICK,100)
Block(-7,6,-3,GRAVEL:0)
RandomBlock(-7,6,-2,STONEBRICK:1,10,STONEBRICK:2,10,COBBLESTONE,10,MOSSY_COBBLESTONE,10,SMOOTH_BRICK,100)
RandomBlock(-7,6,-1,STONEBRICK:1,10,STONEBRICK:2,10,COBBLESTONE,10,MOSSY_COBBLESTONE,10,SMOOTH_BRICK,100)
Block(-7,6,0,OBSIDIAN:0)
Block(-7,6,1,OBSIDIAN:0)
Block(-7,6,2,OBSIDIAN:0)
Block(-7,6,3,OBSIDIAN:0)
Block(-7,6,4,OBSIDIAN:0)
Block(-7,6,5,OBSIDIAN:0)
Block(-7,6,6,OBSIDIAN:0)
Block(-7,6,7,OBSIDIAN:0)
Block(-7,6,8,OBSIDIAN:0)
Block(-7,7,-7,AIR:0)
Block(-7,7,-6,AIR:0)
Block(-7,7,-5,AIR:0)
Block(-7,7,-4,AIR:0)
RandomBlock(-7,7,-3,STONEBRICK:1,10,STONEBRICK:2,10,COBBLESTONE,10,MOSSY_COBBLESTONE,10,SMOOTH_BRICK,100)
RandomBlock(-7,7,-2,STONEBRICK:1,10,STONEBRICK:2,10,COBBLESTONE,10,MOSSY_COBBLESTONE,10,SMOOTH_BRICK,100)
RandomBlock(-7,7,-1,STONEBRICK:1,10,STONEBRICK:2,10,COBBLESTONE,10,MOSSY_COBBLESTONE,10,SMOOTH_BRICK,100)
Block(-7,7,0,OBSIDIAN:0)
Block(-7,7,1,OBSIDIAN:0)
Block(-7,7,2,OBSIDIAN:0)
Block(-7,7,3,OBSIDIAN:0)
Block(-7,7,4,OBSIDIAN:0)
Block(-7,7,5,OBSIDIAN:0)
Block(-7,7,6,OBSIDIAN:0)
Block(-7,7,7,OBSIDIAN:0)
Block(-7,7,8,OBSIDIAN:0)
Block(-7,8,-7,AIR:0)
Block(-7,8,-6,AIR:0)
Block(-7,8,-5,AIR:0)
Block(-7,8,-4,AIR:0)
RandomBlock(-7,8,-3,STONEBRICK:1,10,STONEBRICK:2,10,COBBLESTONE,10,MOSSY_COBBLESTONE,10,SMOOTH_BRICK,100)
RandomBlock(-7,8,-2,STONEBRICK:1,10,STONEBRICK:2,10,COBBLESTONE,10,MOSSY_COBBLESTONE,10,SMOOTH_BRICK,100)
RandomBlock(-7,8,-1,STONEBRICK:1,10,STONEBRICK:2,10,COBBLESTONE,10,MOSSY_COBBLESTONE,10,SMOOTH_BRICK,100)
Block(-7,8,0,OBSIDIAN:0)
Block(-7,8,1,OBSIDIAN:0)
Block(-7,8,2,OBSIDIAN:0)
Block(-7,8,3,OBSIDIAN:0)
Block(-7,8,4,OBSIDIAN:0)
Block(-7,8,5,OBSIDIAN:0)
Block(-7,8,6,OBSIDIAN:0)
Block(-7,8,7,OBSIDIAN:0)
Block(-7,8,8,OBSIDIAN:0)
Block(-7,9,-7,AIR:0)
Block(-7,9,-6,AIR:0)
Block(-7,9,-5,AIR:0)
Block(-7,9,-4,AIR:0)
RandomBlock(-7,9,-3,STONEBRICK:1,10,STONEBRICK:2,10,COBBLESTONE,10,MOSSY_COBBLESTONE,10,SMOOTH_BRICK,100)
RandomBlock(-7,9,-2,STONEBRICK:1,10,STONEBRICK:2,10,COBBLESTONE,10,MOSSY_COBBLESTONE,10,SMOOTH_BRICK,100)
RandomBlock(-7,9,-1,STONEBRICK:1,10,STONEBRICK:2,10,COBBLESTONE,10,MOSSY_COBBLESTONE,10,SMOOTH_BRICK,100)
Block(-7,9,0,OBSIDIAN:0)
Block(-7,9,1,OBSIDIAN:0)
Block(-7,9,2,OBSIDIAN:0)
Block(-7,9,3,OBSIDIAN:0)
Block(-7,9,4,OBSIDIAN:0)
Block(-7,9,5,OBSIDIAN:0)
Block(-7,9,6,OBSIDIAN:0)
Block(-7,9,7,OBSIDIAN:0)
Block(-7,9,8,OBSIDIAN:0)
Block(-7,10,-7,AIR:0)
Block(-7,10,-6,AIR:0)
Block(-7,10,-5,AIR:0)
Block(-7,10,-4,AIR:0)
RandomBlock(-7,10,-3,STONEBRICK:1,10,STONEBRICK:2,10,COBBLESTONE,10,MOSSY_COBBLESTONE,10,SMOOTH_BRICK,100)
Block(-7,10,-2,STATIONARY_LAVA:4)
RandomBlock(-7,10,-1,STONEBRICK:1,10,STONEBRICK:2,10,COBBLESTONE,10,MOSSY_COBBLESTONE,10,SMOOTH_BRICK,100)
Block(-7,10,0,OBSIDIAN:0)
Block(-7,10,1,OBSIDIAN:0)
Block(-7,10,2,OBSIDIAN:0)
Block(-7,10,3,OBSIDIAN:0)
Block(-7,10,4,OBSIDIAN:0)
Block(-7,10,5,OBSIDIAN:0)
Block(-7,10,6,OBSIDIAN:0)
Block(-7,10,7,OBSIDIAN:0)
Block(-7,10,8,OBSIDIAN:0)
Block(-7,11,-7,AIR:0)
Block(-7,11,-6,AIR:0)
Block(-7,11,-5,AIR:0)
Block(-7,11,-4,AIR:0)
RandomBlock(-7,11,-3,STONEBRICK:1,10,STONEBRICK:2,10,COBBLESTONE,10,MOSSY_COBBLESTONE,10,SMOOTH_BRICK,100)
Block(-7,11,-2,AIR:0)
RandomBlock(-7,11,-1,STONEBRICK:1,10,STONEBRICK:2,10,COBBLESTONE,10,MOSSY_COBBLESTONE,10,SMOOTH_BRICK,100)
Block(-7,11,0,OBSIDIAN:0)
Block(-7,11,1,OBSIDIAN:0)
Block(-7,11,2,OBSIDIAN:0)
Block(-7,11,3,OBSIDIAN:0)
Block(-7,11,4,OBSIDIAN:0)
Block(-7,11,5,OBSIDIAN:0)
Block(-7,11,6,OBSIDIAN:0)
Block(-7,11,7,OBSIDIAN:0)
Block(-7,11,8,OBSIDIAN:0)
Block(-7,12,-7,AIR:0)
Block(-7,12,-6,AIR:0)
Block(-7,12,-5,AIR:0)
Block(-7,12,-4,AIR:0)
Block(-7,12,-3,AIR:0)
Block(-7,12,-2,AIR:0)
RandomBlock(-7,12,-1,STONEBRICK:1,10,STONEBRICK:2,10,COBBLESTONE,10,MOSSY_COBBLESTONE,10,SMOOTH_BRICK,100)
Block(-7,12,0,OBSIDIAN:0)
Block(-7,12,1,OBSIDIAN:0)
Block(-7,12,2,OBSIDIAN:0)
Block(-7,12,3,OBSIDIAN:0)
Block(-7,12,4,OBSIDIAN:0)
Block(-7,12,5,OBSIDIAN:0)
Block(-7,12,6,OBSIDIAN:0)
Block(-7,12,7,OBSIDIAN:0)
Block(-7,12,8,OBSIDIAN:0)
Block(-7,13,-7,AIR:0)
Block(-7,13,-6,AIR:0)
Block(-7,13,-5,AIR:0)
Block(-7,13,-4,AIR:0)
Block(-7,13,-3,AIR:0)
Block(-7,13,-2,AIR:0)
RandomBlock(-7,13,-1,STONEBRICK:1,10,STONEBRICK:2,10,COBBLESTONE,10,MOSSY_COBBLESTONE,10,SMOOTH_BRICK,100)
Block(-7,13,0,OBSIDIAN:0)
Block(-7,13,1,OBSIDIAN:0)
Block(-7,13,2,OBSIDIAN:0)
Block(-7,13,3,OBSIDIAN:0)
Block(-7,13,4,OBSIDIAN:0)
Block(-7,13,5,OBSIDIAN:0)
Block(-7,13,6,OBSIDIAN:0)
Block(-7,13,7,OBSIDIAN:0)
Block(-7,13,8,OBSIDIAN:0)
Block(-7,14,-7,AIR:0)
Block(-7,14,-6,AIR:0)
Block(-7,14,-5,AIR:0)
Block(-7,14,-4,AIR:0)
Block(-7,14,-3,AIR:0)
Block(-7,14,-2,AIR:0)
RandomBlock(-7,14,-1,STONEBRICK:1,10,STONEBRICK:2,10,COBBLESTONE,10,MOSSY_COBBLESTONE,10,SMOOTH_BRICK,100)
Block(-7,14,0,OBSIDIAN:0)
Block(-7,14,1,OBSIDIAN:0)
Block(-7,14,2,OBSIDIAN:0)
Block(-7,14,3,OBSIDIAN:0)
Block(-7,14,4,OBSIDIAN:0)
Block(-7,14,5,OBSIDIAN:0)
Block(-7,14,6,OBSIDIAN:0)
Block(-7,14,7,OBSIDIAN:0)
Block(-7,14,8,OBSIDIAN:0)
Block(-7,15,-7,AIR:0)
Block(-7,15,-6,AIR:0)
Block(-7,15,-5,AIR:0)
Block(-7,15,-4,AIR:0)
Block(-7,15,-3,AIR:0)
Block(-7,15,-2,AIR:0)
RandomBlock(-7,15,-1,STONEBRICK:1,10,STONEBRICK:2,10,COBBLESTONE,10,MOSSY_COBBLESTONE,10,SMOOTH_BRICK,100)
Block(-7,15,0,OBSIDIAN:0)
Block(-7,15,1,OBSIDIAN:0)
Block(-7,15,2,OBSIDIAN:0)
Block(-7,15,3,OBSIDIAN:0)
Block(-7,15,4,OBSIDIAN:0)
Block(-7,15,5,OBSIDIAN:0)
Block(-7,15,6,OBSIDIAN:0)
Block(-7,15,7,OBSIDIAN:0)
Block(-7,15,8,OBSIDIAN:0)
Block(-7,16,-7,AIR:0)
Block(-7,16,-6,AIR:0)
Block(-7,16,-5,AIR:0)
Block(-7,16,-4,AIR:0)
Block(-7,16,-3,AIR:0)
Block(-7,16,-2,AIR:0)
RandomBlock(-7,16,-1,STONEBRICK:1,10,STONEBRICK:2,10,COBBLESTONE,10,MOSSY_COBBLESTONE,10,SMOOTH_BRICK,100)
Block(-7,16,0,OBSIDIAN:0)
Block(-7,16,1,OBSIDIAN:0)
Block(-7,16,2,OBSIDIAN:0)
Block(-7,16,3,OBSIDIAN:0)
Block(-7,16,4,OBSIDIAN:0)
Block(-7,16,5,OBSIDIAN:0)
Block(-7,16,6,OBSIDIAN:0)
Block(-7,16,7,OBSIDIAN:0)
Block(-7,16,8,OBSIDIAN:0)
Block(-7,17,-7,IRON_FENCE:0)
Block(-7,17,-6,IRON_FENCE:0)
Block(-7,17,-5,IRON_FENCE:0)
Block(-7,17,-4,IRON_FENCE:0)
RandomBlock(-7,17,-3,STONEBRICK:1,10,STONEBRICK:2,10,COBBLESTONE,10,MOSSY_COBBLESTONE,10,SMOOTH_BRICK,100)
Block(-7,17,-2,AIR:0)
RandomBlock(-7,17,-1,STONEBRICK:1,10,STONEBRICK:2,10,COBBLESTONE,10,MOSSY_COBBLESTONE,10,SMOOTH_BRICK,100)
Block(-7,17,0,OBSIDIAN:0)
Block(-7,17,1,OBSIDIAN:0)
Block(-7,17,2,OBSIDIAN:0)
Block(-7,17,3,OBSIDIAN:0)
Block(-7,17,4,OBSIDIAN:0)
Block(-7,17,5,OBSIDIAN:0)
Block(-7,17,6,OBSIDIAN:0)
Block(-7,17,7,OBSIDIAN:0)
Block(-7,17,8,OBSIDIAN:0)
Block(-7,18,-7,OBSIDIAN:0)
Block(-7,18,-6,OBSIDIAN:0)
Block(-7,18,-5,OBSIDIAN:0)
Block(-7,18,-4,OBSIDIAN:0)
Block(-7,18,-3,IRON_FENCE:0)
Block(-7,18,-2,AIR:0)
RandomBlock(-7,18,-1,STONEBRICK:1,10,STONEBRICK:2,10,COBBLESTONE,10,MOSSY_COBBLESTONE,10,SMOOTH_BRICK,100)
Block(-7,18,0,OBSIDIAN:0)
Block(-7,18,1,OBSIDIAN:0)
Block(-7,18,2,OBSIDIAN:0)
Block(-7,18,3,OBSIDIAN:0)
Block(-7,18,4,OBSIDIAN:0)
Block(-7,18,5,OBSIDIAN:0)
Block(-7,18,6,OBSIDIAN:0)
Block(-7,18,7,OBSIDIAN:0)
Block(-7,18,8,OBSIDIAN:0)
Block(-7,19,-7,STATIONARY_WATER:0)
Block(-7,19,-6,STATIONARY_WATER:0)
Block(-7,19,-5,STATIONARY_WATER:0)
Block(-7,19,-4,STATIONARY_WATER:0)
Block(-7,19,-3,IRON_FENCE:0)
Block(-7,19,-2,AIR:0)
RandomBlock(-7,19,-1,STONEBRICK:1,10,STONEBRICK:2,10,COBBLESTONE,10,MOSSY_COBBLESTONE,10,SMOOTH_BRICK,100)
Block(-7,19,0,OBSIDIAN:0)
Block(-7,19,1,OBSIDIAN:0)
Block(-7,19,2,OBSIDIAN:0)
Block(-7,19,3,OBSIDIAN:0)
Block(-7,19,4,OBSIDIAN:0)
Block(-7,19,5,OBSIDIAN:0)
Block(-7,19,6,OBSIDIAN:0)
Block(-7,19,7,OBSIDIAN:0)
Block(-7,19,8,OBSIDIAN:0)
Block(-7,20,-7,STATIONARY_WATER:0)
Block(-7,20,-6,STATIONARY_WATER:0)
Block(-7,20,-5,STATIONARY_WATER:0)
Block(-7,20,-4,STATIONARY_WATER:0)
Block(-7,20,-3,IRON_FENCE:0)
Block(-7,20,-2,AIR:0)
RandomBlock(-7,20,-1,STONEBRICK:1,10,STONEBRICK:2,10,COBBLESTONE,10,MOSSY_COBBLESTONE,10,SMOOTH_BRICK,100)
Block(-7,20,0,OBSIDIAN:0)
Block(-7,20,1,OBSIDIAN:0)
Block(-7,20,2,OBSIDIAN:0)
Block(-7,20,3,OBSIDIAN:0)
Block(-7,20,4,OBSIDIAN:0)
Block(-7,20,5,OBSIDIAN:0)
Block(-7,20,6,OBSIDIAN:0)
Block(-7,20,7,OBSIDIAN:0)
Block(-7,20,8,OBSIDIAN:0)
Block(-7,21,-7,STATIONARY_WATER:0)
Block(-7,21,-6,STATIONARY_WATER:0)
Block(-7,21,-5,STATIONARY_WATER:0)
Block(-7,21,-4,STATIONARY_WATER:0)
Block(-7,21,-3,IRON_FENCE:0)
Block(-7,21,-2,AIR:0)
RandomBlock(-7,21,-1,STONEBRICK:1,10,STONEBRICK:2,10,COBBLESTONE,10,MOSSY_COBBLESTONE,10,SMOOTH_BRICK,100)
Block(-7,21,0,OBSIDIAN:0)
Block(-7,21,1,OBSIDIAN:0)
Block(-7,21,2,OBSIDIAN:0)
Block(-7,21,3,OBSIDIAN:0)
Block(-7,21,4,OBSIDIAN:0)
Block(-7,21,5,OBSIDIAN:0)
Block(-7,21,6,OBSIDIAN:0)
Block(-7,21,7,OBSIDIAN:0)
Block(-7,21,8,OBSIDIAN:0)
Block(-7,22,-7,STATIONARY_WATER:0)
Block(-7,22,-6,STATIONARY_WATER:0)
Block(-7,22,-5,STATIONARY_WATER:0)
Block(-7,22,-4,STATIONARY_WATER:0)
Block(-7,22,-3,IRON_FENCE:0)
Block(-7,22,-2,AIR:0)
RandomBlock(-7,22,-1,STONEBRICK:1,10,STONEBRICK:2,10,COBBLESTONE,10,MOSSY_COBBLESTONE,10,SMOOTH_BRICK,100)
Block(-7,22,0,OBSIDIAN:0)
Block(-7,22,1,OBSIDIAN:0)
Block(-7,22,2,OBSIDIAN:0)
Block(-7,22,3,OBSIDIAN:0)
Block(-7,22,4,OBSIDIAN:0)
Block(-7,22,5,OBSIDIAN:0)
Block(-7,22,6,OBSIDIAN:0)
Block(-7,22,7,OBSIDIAN:0)
Block(-7,22,8,OBSIDIAN:0)
Block(-7,23,-7,STATIONARY_WATER:0)
Block(-7,23,-6,STATIONARY_WATER:0)
Block(-7,23,-5,STATIONARY_WATER:0)
Block(-7,23,-4,STATIONARY_WATER:0)
Block(-7,23,-3,IRON_FENCE:0)
Block(-7,23,-2,AIR:0)
RandomBlock(-7,23,-1,STONEBRICK:1,10,STONEBRICK:2,10,COBBLESTONE,10,MOSSY_COBBLESTONE,10,SMOOTH_BRICK,100)
Block(-7,23,0,OBSIDIAN:0)
Block(-7,23,1,OBSIDIAN:0)
Block(-7,23,2,OBSIDIAN:0)
Block(-7,23,3,OBSIDIAN:0)
Block(-7,23,4,OBSIDIAN:0)
Block(-7,23,5,OBSIDIAN:0)
Block(-7,23,6,OBSIDIAN:0)
Block(-7,23,7,OBSIDIAN:0)
Block(-7,23,8,OBSIDIAN:0)
Block(-7,24,-7,OBSIDIAN:0)
Block(-7,24,-6,OBSIDIAN:0)
Block(-7,24,-5,OBSIDIAN:0)
Block(-7,24,-4,OBSIDIAN:0)
Block(-7,24,-3,IRON_FENCE:0)
Block(-7,24,-2,AIR:0)
RandomBlock(-7,24,-1,STONEBRICK:1,10,STONEBRICK:2,10,COBBLESTONE,10,MOSSY_COBBLESTONE,10,SMOOTH_BRICK,100)
Block(-7,24,0,OBSIDIAN:0)
Block(-7,24,1,OBSIDIAN:0)
Block(-7,24,2,OBSIDIAN:0)
Block(-7,24,3,OBSIDIAN:0)
Block(-7,24,4,OBSIDIAN:0)
Block(-7,24,5,OBSIDIAN:0)
Block(-7,24,6,OBSIDIAN:0)
Block(-7,24,7,OBSIDIAN:0)
Block(-7,24,8,OBSIDIAN:0)
Block(-7,25,-7,OBSIDIAN:0)
Block(-7,25,-6,OBSIDIAN:0)
Block(-7,25,-5,OBSIDIAN:0)
Block(-7,25,-4,OBSIDIAN:0)
Block(-7,25,-3,OBSIDIAN:0)
Block(-7,25,-2,OBSIDIAN:0)
RandomBlock(-7,25,-1,STONEBRICK:1,10,STONEBRICK:2,10,COBBLESTONE,10,MOSSY_COBBLESTONE,10,SMOOTH_BRICK,100)
Block(-7,25,0,OBSIDIAN:0)
Block(-7,25,1,OBSIDIAN:0)
Block(-7,25,2,OBSIDIAN:0)
Block(-7,25,3,OBSIDIAN:0)
Block(-7,25,4,OBSIDIAN:0)
Block(-7,25,5,OBSIDIAN:0)
Block(-7,25,6,OBSIDIAN:0)
Block(-7,25,7,OBSIDIAN:0)
Block(-7,25,8,OBSIDIAN:0)
Block(-7,26,-7,STONE_PLATE:0)
Block(-7,26,-6,STONE_PLATE:0)
Block(-7,26,-5,STONE_PLATE:0)
Block(-7,26,-4,STONE_PLATE:0)
Block(-7,26,-3,STONE_PLATE:0)
Block(-7,26,-2,STONE_PLATE:0)
RandomBlock(-7,26,-1,STONEBRICK:1,10,STONEBRICK:2,10,COBBLESTONE,10,MOSSY_COBBLESTONE,10,SMOOTH_BRICK,100)
Block(-7,26,0,OBSIDIAN:0)
Block(-7,26,1,OBSIDIAN:0)
Block(-7,26,2,OBSIDIAN:0)
Block(-7,26,3,OBSIDIAN:0)
Block(-7,26,4,OBSIDIAN:0)
Block(-7,26,5,OBSIDIAN:0)
Block(-7,26,6,OBSIDIAN:0)
Block(-7,26,7,OBSIDIAN:0)
Block(-7,26,8,OBSIDIAN:0)
Block(-7,27,-7,AIR:0)
Block(-7,27,-6,AIR:0)
Block(-7,27,-5,AIR:0)
Block(-7,27,-4,AIR:0)
Block(-7,27,-3,AIR:0)
Block(-7,27,-2,AIR:0)
RandomBlock(-7,27,-1,STONEBRICK:1,10,STONEBRICK:2,10,COBBLESTONE,10,MOSSY_COBBLESTONE,10,SMOOTH_BRICK,100)
Block(-7,27,0,OBSIDIAN:0)
Block(-7,27,1,OBSIDIAN:0)
Block(-7,27,2,OBSIDIAN:0)
Block(-7,27,3,OBSIDIAN:0)
Block(-7,27,4,OBSIDIAN:0)
Block(-7,27,5,OBSIDIAN:0)
Block(-7,27,6,OBSIDIAN:0)
Block(-7,27,7,OBSIDIAN:0)
Block(-7,27,8,OBSIDIAN:0)
Block(-7,28,-7,AIR:0)
Block(-7,28,-6,AIR:0)
Block(-7,28,-5,AIR:0)
Block(-7,28,-4,AIR:0)
Block(-7,28,-3,AIR:0)
Block(-7,28,-2,AIR:0)
RandomBlock(-7,28,-1,STONEBRICK:1,10,STONEBRICK:2,10,COBBLESTONE,10,MOSSY_COBBLESTONE,10,SMOOTH_BRICK,100)
Block(-7,28,0,OBSIDIAN:0)
Block(-7,28,1,OBSIDIAN:0)
Block(-7,28,2,OBSIDIAN:0)
Block(-7,28,3,OBSIDIAN:0)
Block(-7,28,4,OBSIDIAN:0)
Block(-7,28,5,OBSIDIAN:0)
Block(-7,28,6,OBSIDIAN:0)
Block(-7,28,7,OBSIDIAN:0)
Block(-7,28,8,OBSIDIAN:0)
Block(-7,29,-7,AIR:0)
Block(-7,29,-6,AIR:0)
Block(-7,29,-5,AIR:0)
Block(-7,29,-4,AIR:0)
Block(-7,29,-3,AIR:0)
Block(-7,29,-2,AIR:0)
RandomBlock(-7,29,-1,STONEBRICK:1,10,STONEBRICK:2,10,COBBLESTONE,10,MOSSY_COBBLESTONE,10,SMOOTH_BRICK,100)
Block(-7,29,0,OBSIDIAN:0)
Block(-7,29,1,OBSIDIAN:0)
Block(-7,29,2,OBSIDIAN:0)
Block(-7,29,3,OBSIDIAN:0)
Block(-7,29,4,OBSIDIAN:0)
Block(-7,29,5,OBSIDIAN:0)
Block(-7,29,6,OBSIDIAN:0)
Block(-7,29,7,OBSIDIAN:0)
Block(-7,29,8,OBSIDIAN:0)
Block(-7,30,-7,AIR:0)
RandomBlock(-7,30,-6,STONEBRICK:1,10,STONEBRICK:2,10,COBBLESTONE,10,MOSSY_COBBLESTONE,10,SMOOTH_BRICK,100)
Block(-7,30,-5,AIR:0)
RandomBlock(-7,30,-4,STONEBRICK:1,10,STONEBRICK:2,10,COBBLESTONE,10,MOSSY_COBBLESTONE,10,SMOOTH_BRICK,100)
Block(-7,30,-3,AIR:0)
Block(-7,30,-2,AIR:0)
RandomBlock(-7,30,-1,STONEBRICK:1,10,STONEBRICK:2,10,COBBLESTONE,10,MOSSY_COBBLESTONE,10,SMOOTH_BRICK,100)
Block(-7,30,0,OBSIDIAN:0)
Block(-7,30,1,OBSIDIAN:0)
Block(-7,30,2,OBSIDIAN:0)
Block(-7,30,3,OBSIDIAN:0)
Block(-7,30,4,OBSIDIAN:0)
Block(-7,30,5,OBSIDIAN:0)
Block(-7,30,6,OBSIDIAN:0)
Block(-7,30,7,OBSIDIAN:0)
Block(-7,30,8,OBSIDIAN:0)
RandomBlock(-7,31,-7,STONEBRICK:1,10,STONEBRICK:2,10,COBBLESTONE,10,MOSSY_COBBLESTONE,10,SMOOTH_BRICK,100)
Block(-7,31,-6,OBSIDIAN:0)
RandomBlock(-7,31,-5,STONEBRICK:1,10,STONEBRICK:2,10,COBBLESTONE,10,MOSSY_COBBLESTONE,10,SMOOTH_BRICK,100)
RandomBlock(-7,31,-4,STONEBRICK:1,10,STONEBRICK:2,10,COBBLESTONE,10,MOSSY_COBBLESTONE,10,SMOOTH_BRICK,100)
Block(-7,31,-3,AIR:0)
Block(-7,31,-2,AIR:0)
RandomBlock(-7,31,-1,STONEBRICK:1,10,STONEBRICK:2,10,COBBLESTONE,10,MOSSY_COBBLESTONE,10,SMOOTH_BRICK,100)
Block(-7,31,0,OBSIDIAN:0)
Block(-7,31,1,OBSIDIAN:0)
Block(-7,31,2,OBSIDIAN:0)
Block(-7,31,3,OBSIDIAN:0)
Block(-7,31,4,OBSIDIAN:0)
Block(-7,31,5,OBSIDIAN:0)
Block(-7,31,6,OBSIDIAN:0)
Block(-7,31,7,OBSIDIAN:0)
Block(-7,31,8,OBSIDIAN:0)
Block(-7,32,-7,OBSIDIAN:0)
Block(-7,32,-6,OBSIDIAN:0)
Block(-7,32,-5,OBSIDIAN:0)
Block(-7,32,-4,OBSIDIAN:0)
Block(-7,32,-3,OBSIDIAN:0)
Block(-7,32,-2,OBSIDIAN:0)
Block(-7,32,-1,OBSIDIAN:0)
Block(-7,32,0,OBSIDIAN:0)
Block(-7,32,1,OBSIDIAN:0)
Block(-7,32,2,OBSIDIAN:0)
Block(-7,32,3,OBSIDIAN:0)
Block(-7,32,4,OBSIDIAN:0)
Block(-7,32,5,OBSIDIAN:0)
Block(-7,32,6,OBSIDIAN:0)
Block(-7,32,7,OBSIDIAN:0)
Block(-7,32,8,OBSIDIAN:0)
Block(-7,33,-7,OBSIDIAN:0)
Block(-7,33,-6,OBSIDIAN:0)
Block(-7,33,-5,OBSIDIAN:0)
Block(-7,33,-4,OBSIDIAN:0)
Block(-7,33,-3,OBSIDIAN:0)
Block(-7,33,-2,OBSIDIAN:0)
Block(-7,33,-1,OBSIDIAN:0)
Block(-7,33,0,OBSIDIAN:0)
Block(-7,33,1,OBSIDIAN:0)
Block(-7,33,2,OBSIDIAN:0)
Block(-7,33,3,OBSIDIAN:0)
Block(-7,33,4,OBSIDIAN:0)
Block(-7,33,5,OBSIDIAN:0)
Block(-7,33,6,OBSIDIAN:0)
Block(-7,33,7,OBSIDIAN:0)
Block(-7,33,8,OBSIDIAN:0)
Block(-7,34,-7,OBSIDIAN:0)
Block(-7,34,-6,OBSIDIAN:0)
Block(-7,34,-5,OBSIDIAN:0)
Block(-7,34,-4,OBSIDIAN:0)
Block(-7,34,-3,OBSIDIAN:0)
Block(-7,34,-2,OBSIDIAN:0)
Block(-7,34,-1,OBSIDIAN:0)
Block(-7,34,0,OBSIDIAN:0)
Block(-7,34,1,OBSIDIAN:0)
Block(-7,34,2,OBSIDIAN:0)
Block(-7,34,3,OBSIDIAN:0)
Block(-7,34,4,OBSIDIAN:0)
Block(-7,34,5,OBSIDIAN:0)
Block(-7,34,6,OBSIDIAN:0)
Block(-7,34,7,OBSIDIAN:0)
Block(-7,34,8,OBSIDIAN:0)
Block(-7,35,-7,OBSIDIAN:0)
Block(-7,35,-6,OBSIDIAN:0)
Block(-7,35,-5,OBSIDIAN:0)
Block(-7,35,-4,OBSIDIAN:0)
Block(-7,35,-3,OBSIDIAN:0)
Block(-7,35,-2,OBSIDIAN:0)
Block(-7,35,-1,OBSIDIAN:0)
Block(-7,35,0,OBSIDIAN:0)
Block(-7,35,1,OBSIDIAN:0)
Block(-7,35,2,OBSIDIAN:0)
Block(-7,35,3,OBSIDIAN:0)
Block(-7,35,4,OBSIDIAN:0)
Block(-7,35,5,OBSIDIAN:0)
Block(-7,35,6,OBSIDIAN:0)
Block(-7,35,7,OBSIDIAN:0)
Block(-7,35,8,OBSIDIAN:0)
Block(-7,36,-7,OBSIDIAN:0)
Block(-7,36,-6,OBSIDIAN:0)
Block(-7,36,-5,OBSIDIAN:0)
Block(-7,36,-4,OBSIDIAN:0)
Block(-7,36,-3,OBSIDIAN:0)
Block(-7,36,-2,OBSIDIAN:0)
Block(-7,36,-1,OBSIDIAN:0)
Block(-7,36,0,OBSIDIAN:0)
Block(-7,36,1,OBSIDIAN:0)
Block(-7,36,2,OBSIDIAN:0)
Block(-7,36,3,OBSIDIAN:0)
Block(-7,36,4,OBSIDIAN:0)
Block(-7,36,5,OBSIDIAN:0)
Block(-7,36,6,OBSIDIAN:0)
Block(-7,36,7,OBSIDIAN:0)
Block(-7,36,8,OBSIDIAN:0)
Block(-7,37,-7,OBSIDIAN:0)
Block(-7,37,-6,OBSIDIAN:0)
Block(-7,37,-5,OBSIDIAN:0)
Block(-7,37,-4,OBSIDIAN:0)
Block(-7,37,-3,OBSIDIAN:0)
Block(-7,37,-2,OBSIDIAN:0)
Block(-7,37,-1,OBSIDIAN:0)
Block(-7,37,0,OBSIDIAN:0)
Block(-7,37,1,OBSIDIAN:0)
Block(-7,37,2,OBSIDIAN:0)
Block(-7,37,3,OBSIDIAN:0)
Block(-7,37,4,OBSIDIAN:0)
Block(-7,37,5,OBSIDIAN:0)
Block(-7,37,6,OBSIDIAN:0)
Block(-7,37,7,OBSIDIAN:0)
Block(-7,37,8,OBSIDIAN:0)
Block(-7,38,-7,OBSIDIAN:0)
Block(-7,38,-6,OBSIDIAN:0)
Block(-7,38,-5,OBSIDIAN:0)
Block(-7,38,-4,OBSIDIAN:0)
Block(-7,38,-3,OBSIDIAN:0)
Block(-7,38,-2,OBSIDIAN:0)
Block(-7,38,-1,OBSIDIAN:0)
Block(-7,38,0,OBSIDIAN:0)
Block(-7,38,1,OBSIDIAN:0)
Block(-7,38,2,OBSIDIAN:0)
Block(-7,38,3,OBSIDIAN:0)
Block(-7,38,4,OBSIDIAN:0)
Block(-7,38,5,OBSIDIAN:0)
Block(-7,38,6,OBSIDIAN:0)
Block(-7,38,7,OBSIDIAN:0)
Block(-7,38,8,OBSIDIAN:0)
Block(-7,39,-7,OBSIDIAN:0)
Block(-7,39,-6,OBSIDIAN:0)
Block(-7,39,-5,OBSIDIAN:0)
Block(-7,39,-4,OBSIDIAN:0)
Block(-7,39,-3,OBSIDIAN:0)
Block(-7,39,-2,OBSIDIAN:0)
Block(-7,39,-1,OBSIDIAN:0)
Block(-7,39,0,OBSIDIAN:0)
Block(-7,39,1,OBSIDIAN:0)
Block(-7,39,2,OBSIDIAN:0)
Block(-7,39,3,OBSIDIAN:0)
Block(-7,39,4,OBSIDIAN:0)
Block(-7,39,5,OBSIDIAN:0)
Block(-7,39,6,OBSIDIAN:0)
Block(-7,39,7,OBSIDIAN:0)
Block(-7,39,8,OBSIDIAN:0)
Block(-7,40,-7,OBSIDIAN:0)
Block(-7,40,-6,OBSIDIAN:0)
Block(-7,40,-5,OBSIDIAN:0)
Block(-7,40,-4,OBSIDIAN:0)
Block(-7,40,-3,OBSIDIAN:0)
Block(-7,40,-2,OBSIDIAN:0)
Block(-7,40,-1,OBSIDIAN:0)
Block(-7,40,0,OBSIDIAN:0)
Block(-7,40,1,OBSIDIAN:0)
Block(-7,40,2,OBSIDIAN:0)
Block(-7,40,3,OBSIDIAN:0)
Block(-7,40,4,OBSIDIAN:0)
Block(-7,40,5,OBSIDIAN:0)
Block(-7,40,6,OBSIDIAN:0)
Block(-7,40,7,OBSIDIAN:0)
Block(-7,40,8,OBSIDIAN:0)
Block(-7,41,-7,OBSIDIAN:0)
Block(-7,41,-6,OBSIDIAN:0)
Block(-7,41,-5,OBSIDIAN:0)
Block(-7,41,-4,OBSIDIAN:0)
Block(-7,41,-3,OBSIDIAN:0)
Block(-7,41,-2,OBSIDIAN:0)
Block(-7,41,-1,OBSIDIAN:0)
Block(-7,41,0,OBSIDIAN:0)
Block(-7,41,1,OBSIDIAN:0)
Block(-7,41,2,OBSIDIAN:0)
Block(-7,41,3,OBSIDIAN:0)
Block(-7,41,4,OBSIDIAN:0)
Block(-7,41,5,OBSIDIAN:0)
Block(-7,41,6,OBSIDIAN:0)
Block(-7,41,7,OBSIDIAN:0)
Block(-7,41,8,OBSIDIAN:0)
Block(-7,42,-7,OBSIDIAN:0)
Block(-7,42,-6,OBSIDIAN:0)
Block(-7,42,-5,OBSIDIAN:0)
Block(-7,42,-4,OBSIDIAN:0)
Block(-7,42,-3,OBSIDIAN:0)
Block(-7,42,-2,OBSIDIAN:0)
Block(-7,42,-1,OBSIDIAN:0)
Block(-7,42,0,OBSIDIAN:0)
Block(-7,42,1,OBSIDIAN:0)
Block(-7,42,2,OBSIDIAN:0)
Block(-7,42,3,OBSIDIAN:0)
Block(-7,42,4,OBSIDIAN:0)
Block(-7,42,5,OBSIDIAN:0)
Block(-7,42,6,OBSIDIAN:0)
Block(-7,42,7,OBSIDIAN:0)
Block(-7,42,8,OBSIDIAN:0)
Block(-7,43,-7,OBSIDIAN:0)
Block(-7,43,-6,OBSIDIAN:0)
Block(-7,43,-5,OBSIDIAN:0)
Block(-7,43,-4,OBSIDIAN:0)
Block(-7,43,-3,OBSIDIAN:0)
Block(-7,43,-2,OBSIDIAN:0)
Block(-7,43,-1,OBSIDIAN:0)
Block(-7,43,0,OBSIDIAN:0)
Block(-7,43,1,OBSIDIAN:0)
Block(-7,43,2,OBSIDIAN:0)
Block(-7,43,3,OBSIDIAN:0)
Block(-7,43,4,OBSIDIAN:0)
Block(-7,43,5,OBSIDIAN:0)
Block(-7,43,6,OBSIDIAN:0)
Block(-7,43,7,OBSIDIAN:0)
Block(-7,43,8,OBSIDIAN:0)
Block(-7,44,-7,OBSIDIAN:0)
Block(-7,44,-6,OBSIDIAN:0)
Block(-7,44,-5,OBSIDIAN:0)
Block(-7,44,-4,OBSIDIAN:0)
Block(-7,44,-3,OBSIDIAN:0)
Block(-7,44,-2,OBSIDIAN:0)
Block(-7,44,-1,OBSIDIAN:0)
Block(-7,44,0,OBSIDIAN:0)
Block(-7,44,1,OBSIDIAN:0)
Block(-7,44,2,OBSIDIAN:0)
Block(-7,44,3,OBSIDIAN:0)
Block(-7,44,4,OBSIDIAN:0)
Block(-7,44,5,OBSIDIAN:0)
Block(-7,44,6,OBSIDIAN:0)
Block(-7,44,7,OBSIDIAN:0)
Block(-7,44,8,OBSIDIAN:0)
Block(-7,45,-7,OBSIDIAN:0)
Block(-7,45,-6,OBSIDIAN:0)
Block(-7,45,-5,OBSIDIAN:0)
Block(-7,45,-4,OBSIDIAN:0)
Block(-7,45,-3,OBSIDIAN:0)
Block(-7,45,-2,OBSIDIAN:0)
Block(-7,45,-1,OBSIDIAN:0)
Block(-7,45,0,OBSIDIAN:0)
Block(-7,45,1,OBSIDIAN:0)
Block(-7,45,2,OBSIDIAN:0)
Block(-7,45,3,OBSIDIAN:0)
Block(-7,45,4,OBSIDIAN:0)
Block(-7,45,5,OBSIDIAN:0)
Block(-7,45,6,OBSIDIAN:0)
Block(-7,45,7,OBSIDIAN:0)
Block(-7,45,8,OBSIDIAN:0)
Block(-7,46,-7,OBSIDIAN:0)
Block(-7,46,-6,OBSIDIAN:0)
Block(-7,46,-5,OBSIDIAN:0)
Block(-7,46,-4,OBSIDIAN:0)
Block(-7,46,-3,OBSIDIAN:0)
Block(-7,46,-2,OBSIDIAN:0)
Block(-7,46,-1,OBSIDIAN:0)
Block(-7,46,0,OBSIDIAN:0)
Block(-7,46,1,OBSIDIAN:0)
Block(-7,46,2,OBSIDIAN:0)
Block(-7,46,3,OBSIDIAN:0)
Block(-7,46,4,OBSIDIAN:0)
Block(-7,46,5,OBSIDIAN:0)
Block(-7,46,6,OBSIDIAN:0)
Block(-7,46,7,OBSIDIAN:0)
Block(-7,46,8,OBSIDIAN:0)
Block(-7,47,-7,OBSIDIAN:0)
Block(-7,47,-6,OBSIDIAN:0)
Block(-7,47,-5,OBSIDIAN:0)
Block(-7,47,-4,OBSIDIAN:0)
Block(-7,47,-3,OBSIDIAN:0)
Block(-7,47,-2,OBSIDIAN:0)
Block(-7,47,-1,OBSIDIAN:0)
Block(-7,47,0,OBSIDIAN:0)
Block(-7,47,1,OBSIDIAN:0)
Block(-7,47,2,OBSIDIAN:0)
Block(-7,47,3,OBSIDIAN:0)
Block(-7,47,4,OBSIDIAN:0)
Block(-7,47,5,OBSIDIAN:0)
Block(-7,47,6,OBSIDIAN:0)
Block(-7,47,7,OBSIDIAN:0)
Block(-7,47,8,OBSIDIAN:0)
Block(-7,48,-7,OBSIDIAN:0)
Block(-7,48,-6,OBSIDIAN:0)
Block(-7,48,-5,OBSIDIAN:0)
Block(-7,48,-4,OBSIDIAN:0)
Block(-7,48,-3,OBSIDIAN:0)
Block(-7,48,-2,OBSIDIAN:0)
Block(-7,48,-1,OBSIDIAN:0)
Block(-7,48,0,OBSIDIAN:0)
Block(-7,48,1,OBSIDIAN:0)
Block(-7,48,2,OBSIDIAN:0)
Block(-7,48,3,OBSIDIAN:0)
Block(-7,48,4,OBSIDIAN:0)
Block(-7,48,5,OBSIDIAN:0)
Block(-7,48,6,OBSIDIAN:0)
Block(-7,48,7,OBSIDIAN:0)
Block(-7,48,8,OBSIDIAN:0)
RandomBlock(-7,49,-7,STONEBRICK:1,10,STONEBRICK:2,10,COBBLESTONE,10,MOSSY_COBBLESTONE,10,SMOOTH_BRICK,100)
RandomBlock(-7,49,-6,STONEBRICK:1,10,STONEBRICK:2,10,COBBLESTONE,10,MOSSY_COBBLESTONE,10,SMOOTH_BRICK,100)
Block(-7,49,-5,OBSIDIAN:0)
Block(-7,49,-4,OBSIDIAN:0)
Block(-7,49,-3,OBSIDIAN:0)
Block(-7,49,-2,OBSIDIAN:0)
Block(-7,49,-1,OBSIDIAN:0)
Block(-7,49,0,OBSIDIAN:0)
Block(-7,49,1,OBSIDIAN:0)
Block(-7,49,2,OBSIDIAN:0)
Block(-7,49,3,OBSIDIAN:0)
Block(-7,49,4,OBSIDIAN:0)
RandomBlock(-7,49,5,STONEBRICK:1,10,STONEBRICK:2,10,COBBLESTONE,10,MOSSY_COBBLESTONE,10,SMOOTH_BRICK,100)
RandomBlock(-7,49,6,STONEBRICK:1,10,STONEBRICK:2,10,COBBLESTONE,10,MOSSY_COBBLESTONE,10,SMOOTH_BRICK,100)
RandomBlock(-7,49,7,STONEBRICK:1,10,STONEBRICK:2,10,COBBLESTONE,10,MOSSY_COBBLESTONE,10,SMOOTH_BRICK,100)
Block(-7,49,8,OBSIDIAN:0)
Block(-7,50,-7,OBSIDIAN:0)
Block(-7,50,-6,OBSIDIAN:0)
Block(-7,50,-5,OBSIDIAN:0)
Block(-7,50,-4,OBSIDIAN:0)
Block(-7,50,-3,OBSIDIAN:0)
Block(-7,50,-2,OBSIDIAN:0)
Block(-7,50,-1,OBSIDIAN:0)
Block(-7,50,0,OBSIDIAN:0)
Block(-7,50,1,OBSIDIAN:0)
Block(-7,50,2,OBSIDIAN:0)
Block(-7,50,3,OBSIDIAN:0)
Block(-7,50,4,OBSIDIAN:0)
Block(-7,50,5,OBSIDIAN:0)
Block(-7,50,6,OBSIDIAN:0)
Block(-7,50,7,OBSIDIAN:0)
Block(-7,50,8,OBSIDIAN:0)
Block(-7,51,-7,OBSIDIAN:0)
Block(-7,51,-6,OBSIDIAN:0)
Block(-7,51,-5,OBSIDIAN:0)
Block(-7,51,-4,OBSIDIAN:0)
Block(-7,51,-3,OBSIDIAN:0)
Block(-7,51,-2,OBSIDIAN:0)
Block(-7,51,-1,OBSIDIAN:0)
Block(-7,51,0,OBSIDIAN:0)
Block(-7,51,1,OBSIDIAN:0)
Block(-7,51,2,OBSIDIAN:0)
Block(-7,51,3,OBSIDIAN:0)
Block(-7,51,4,OBSIDIAN:0)
Block(-7,51,5,OBSIDIAN:0)
Block(-7,51,6,OBSIDIAN:0)
Block(-7,51,7,OBSIDIAN:0)
Block(-7,51,8,OBSIDIAN:0)
Block(-7,52,-7,OBSIDIAN:0)
Block(-7,52,-6,OBSIDIAN:0)
Block(-7,52,-5,OBSIDIAN:0)
Block(-7,52,-4,OBSIDIAN:0)
Block(-7,52,-3,OBSIDIAN:0)
Block(-7,52,-2,OBSIDIAN:0)
Block(-7,52,-1,OBSIDIAN:0)
Block(-7,52,0,OBSIDIAN:0)
Block(-7,52,1,OBSIDIAN:0)
Block(-7,52,2,OBSIDIAN:0)
Block(-7,52,3,OBSIDIAN:0)
Block(-7,52,4,OBSIDIAN:0)
Block(-7,52,5,OBSIDIAN:0)
Block(-7,52,6,OBSIDIAN:0)
Block(-7,52,7,OBSIDIAN:0)
Block(-7,52,8,OBSIDIAN:0)
Block(-7,53,-7,OBSIDIAN:0)
Block(-7,53,-6,OBSIDIAN:0)
Block(-7,53,-5,OBSIDIAN:0)
Block(-7,53,-4,OBSIDIAN:0)
Block(-7,53,-3,OBSIDIAN:0)
Block(-7,53,-2,OBSIDIAN:0)
Block(-7,53,-1,OBSIDIAN:0)
Block(-7,53,0,OBSIDIAN:0)
Block(-7,53,1,OBSIDIAN:0)
Block(-7,53,2,OBSIDIAN:0)
Block(-7,53,3,OBSIDIAN:0)
Block(-7,53,4,OBSIDIAN:0)
Block(-7,53,5,OBSIDIAN:0)
Block(-7,53,6,OBSIDIAN:0)
Block(-7,53,7,OBSIDIAN:0)
Block(-7,53,8,OBSIDIAN:0)
Block(-7,54,-7,STONE:0)
Block(-7,54,-6,STONE:0)
Block(-7,54,-5,STONE:0)
Block(-7,54,-4,STONE:0)
Block(-7,54,-3,STONE:0)
Block(-7,54,-2,STONE:0)
Block(-7,54,-1,STONE:0)
Block(-7,54,0,STONE:0)
Block(-7,54,1,STONE:0)
Block(-7,54,2,STONE:0)
Block(-7,54,3,STONE:0)
Block(-7,54,4,STONE:0)
Block(-7,54,5,STONE:0)
Block(-7,54,6,GRASS:0)
Block(-7,54,7,GRASS:0)
Block(-7,54,8,GRASS:0)
Block(-7,55,-7,STONE:0)
Block(-7,55,-6,STONE:0)
Block(-7,55,-5,STONE:0)
Block(-7,55,-4,STONE:0)
Block(-7,55,-3,STONE:0)
Block(-7,55,-2,STONE:0)
Block(-7,55,-1,STONE:0)
Block(-7,55,0,STONE:0)
Block(-7,55,1,STONE:0)
Block(-7,55,2,STONE:0)
Block(-7,55,3,STONE:0)
Block(-7,55,4,STONE:0)
Block(-7,55,5,GRASS:0)
Block(-7,56,-7,STONE:0)
Block(-7,56,-6,STONE:0)
Block(-7,56,-5,STONE:0)
Block(-7,56,-4,STONE:0)
Block(-7,56,-3,STONE:0)
Block(-7,56,-2,STONE:0)
Block(-7,56,-1,STONE:0)
Block(-7,56,0,STONE:0)
Block(-7,56,1,STONE:0)
Block(-7,56,2,STONE:0)
Block(-7,56,3,STONE:0)
Block(-7,56,4,GRASS:0)
Block(-7,57,-7,STONE:0)
Block(-7,57,-6,STONE:0)
Block(-7,57,-5,STONE:0)
Block(-7,57,-4,STONE:0)
Block(-7,57,-3,STONE:0)
Block(-7,57,-2,STONE:0)
Block(-7,57,-1,STONE:0)
Block(-7,57,0,STONE:0)
Block(-7,57,1,STONE:0)
Block(-7,57,2,STONE:0)
Block(-7,57,3,STONE:0)
Block(-7,58,-7,STONE:0)
Block(-7,58,-6,STONE:0)
Block(-7,58,-5,STONE:0)
Block(-7,58,-4,STONE:0)
Block(-7,58,-3,STONE:0)
Block(-7,58,-2,STONE:0)
Block(-7,58,-1,STONE:0)
Block(-7,58,0,STONE:0)
Block(-7,58,1,STONE:0)
Block(-7,58,2,STONE:0)
Block(-7,58,3,STONE:0)
Block(-7,59,-7,STONE:0)
Block(-7,59,-6,STONE:0)
Block(-7,59,-5,STONE:0)
Block(-7,59,-4,STONE:0)
Block(-7,59,-3,STONE:0)
Block(-7,59,-2,STONE:0)
Block(-7,59,-1,STONE:0)
Block(-7,59,0,STONE:0)
Block(-7,59,1,STONE:0)
Block(-7,59,2,STONE:0)
Block(-7,59,3,GRASS:0)
Block(-7,60,-7,STONE:0)
Block(-7,60,-6,STONE:0)
Block(-7,60,-5,STONE:0)
Block(-7,60,-4,GRASS:0)
Block(-7,60,-3,GRASS:0)
Block(-7,60,-2,GRASS:0)
Block(-7,60,-1,GRASS:0)
Block(-7,60,0,GRASS:0)
Block(-7,60,1,GRASS:0)
Block(-7,60,2,GRASS:0)
Block(-7,61,-7,GRASS:0)
Block(-7,61,-6,GRASS:0)
Block(-7,61,-5,GRASS:0)
RandomBlock(-6,0,-7,STONEBRICK:1,10,STONEBRICK:2,10,COBBLESTONE,10,MOSSY_COBBLESTONE,10,SMOOTH_BRICK,100)
RandomBlock(-6,0,-6,STONEBRICK:1,10,STONEBRICK:2,10,COBBLESTONE,10,MOSSY_COBBLESTONE,10,SMOOTH_BRICK,100)
RandomBlock(-6,0,-5,STONEBRICK:1,10,STONEBRICK:2,10,COBBLESTONE,10,MOSSY_COBBLESTONE,10,SMOOTH_BRICK,100)
RandomBlock(-6,0,-4,STONEBRICK:1,10,STONEBRICK:2,10,COBBLESTONE,10,MOSSY_COBBLESTONE,10,SMOOTH_BRICK,100)
RandomBlock(-6,0,-3,STONEBRICK:1,10,STONEBRICK:2,10,COBBLESTONE,10,MOSSY_COBBLESTONE,10,SMOOTH_BRICK,100)
RandomBlock(-6,0,-2,STONEBRICK:1,10,STONEBRICK:2,10,COBBLESTONE,10,MOSSY_COBBLESTONE,10,SMOOTH_BRICK,100)
RandomBlock(-6,0,-1,STONEBRICK:1,10,STONEBRICK:2,10,COBBLESTONE,10,MOSSY_COBBLESTONE,10,SMOOTH_BRICK,100)
RandomBlock(-6,0,0,STONEBRICK:1,10,STONEBRICK:2,10,COBBLESTONE,10,MOSSY_COBBLESTONE,10,SMOOTH_BRICK,100)
RandomBlock(-6,0,1,STONEBRICK:1,10,STONEBRICK:2,10,COBBLESTONE,10,MOSSY_COBBLESTONE,10,SMOOTH_BRICK,100)
RandomBlock(-6,0,2,STONEBRICK:1,10,STONEBRICK:2,10,COBBLESTONE,10,MOSSY_COBBLESTONE,10,SMOOTH_BRICK,100)
RandomBlock(-6,0,3,STONEBRICK:1,10,STONEBRICK:2,10,COBBLESTONE,10,MOSSY_COBBLESTONE,10,SMOOTH_BRICK,100)
RandomBlock(-6,0,4,STONEBRICK:1,10,STONEBRICK:2,10,COBBLESTONE,10,MOSSY_COBBLESTONE,10,SMOOTH_BRICK,100)
RandomBlock(-6,0,5,STONEBRICK:1,10,STONEBRICK:2,10,COBBLESTONE,10,MOSSY_COBBLESTONE,10,SMOOTH_BRICK,100)
RandomBlock(-6,0,6,STONEBRICK:1,10,STONEBRICK:2,10,COBBLESTONE,10,MOSSY_COBBLESTONE,10,SMOOTH_BRICK,100)
RandomBlock(-6,0,7,STONEBRICK:1,10,STONEBRICK:2,10,COBBLESTONE,10,MOSSY_COBBLESTONE,10,SMOOTH_BRICK,100)
Block(-6,0,8,OBSIDIAN:0)
Block(-6,1,-7,OBSIDIAN:0)
Block(-6,1,-6,OBSIDIAN:0)
Block(-6,1,-5,OBSIDIAN:0)
Block(-6,1,-4,OBSIDIAN:0)
Block(-6,1,-3,OBSIDIAN:0)
Block(-6,1,-2,OBSIDIAN:0)
Block(-6,1,-1,OBSIDIAN:0)
Block(-6,1,0,OBSIDIAN:0)
Block(-6,1,1,OBSIDIAN:0)
Block(-6,1,2,OBSIDIAN:0)
Block(-6,1,3,OBSIDIAN:0)
Block(-6,1,4,OBSIDIAN:0)
Block(-6,1,5,OBSIDIAN:0)
Block(-6,1,6,OBSIDIAN:0)
Block(-6,1,7,OBSIDIAN:0)
Block(-6,1,8,OBSIDIAN:0)
Block(-6,2,-7,AIR:0)
Block(-6,2,-6,AIR:0)
Block(-6,2,-5,AIR:0)
Block(-6,2,-4,AIR:0)
Block(-6,2,-3,OBSIDIAN:0)
Block(-6,2,-2,OBSIDIAN:0)
Block(-6,2,-1,OBSIDIAN:0)
Block(-6,2,0,OBSIDIAN:0)
Block(-6,2,1,OBSIDIAN:0)
Block(-6,2,2,OBSIDIAN:0)
Block(-6,2,3,OBSIDIAN:0)
Block(-6,2,4,OBSIDIAN:0)
Block(-6,2,5,OBSIDIAN:0)
Block(-6,2,6,OBSIDIAN:0)
Block(-6,2,7,OBSIDIAN:0)
Block(-6,2,8,OBSIDIAN:0)
Block(-6,3,-7,OBSIDIAN:0)
Block(-6,3,-6,OBSIDIAN:0)
Block(-6,3,-5,OBSIDIAN:0)
Block(-6,3,-4,OBSIDIAN:0)
Block(-6,3,-3,OBSIDIAN:0)
Block(-6,3,-2,OBSIDIAN:0)
Block(-6,3,-1,REDSTONE_WIRE:12)
Block(-6,3,0,OBSIDIAN:0)
Block(-6,3,1,OBSIDIAN:0)
Block(-6,3,2,OBSIDIAN:0)
Block(-6,3,3,OBSIDIAN:0)
Block(-6,3,4,OBSIDIAN:0)
Block(-6,3,5,OBSIDIAN:0)
Block(-6,3,6,OBSIDIAN:0)
Block(-6,3,7,OBSIDIAN:0)
Block(-6,3,8,OBSIDIAN:0)
Block(-6,4,-7,DIODE_BLOCK_OFF:2)
Block(-6,4,-6,REDSTONE_WIRE:0)
Block(-6,4,-5,AIR:0)
Block(-6,4,-4,AIR:0)
Block(-6,4,-3,OBSIDIAN:0)
Block(-6,4,-2,OBSIDIAN:0)
Block(-6,4,-1,AIR:0)
Block(-6,4,0,OBSIDIAN:0)
Block(-6,4,1,OBSIDIAN:0)
Block(-6,4,2,OBSIDIAN:0)
Block(-6,4,3,OBSIDIAN:0)
Block(-6,4,4,OBSIDIAN:0)
Block(-6,4,5,OBSIDIAN:0)
Block(-6,4,6,OBSIDIAN:0)
Block(-6,4,7,OBSIDIAN:0)
Block(-6,4,8,OBSIDIAN:0)
Block(-6,5,-7,PISTON_BASE:1)
Block(-6,5,-6,OBSIDIAN:0)
Block(-6,5,-5,OBSIDIAN:0)
Block(-6,5,-4,OBSIDIAN:0)
Block(-6,5,-3,OBSIDIAN:0)
Block(-6,5,-2,OBSIDIAN:0)
Block(-6,5,-1,AIR:0)
Block(-6,5,0,OBSIDIAN:0)
Block(-6,5,1,OBSIDIAN:0)
Block(-6,5,2,OBSIDIAN:0)
Block(-6,5,3,OBSIDIAN:0)
Block(-6,5,4,OBSIDIAN:0)
Block(-6,5,5,OBSIDIAN:0)
Block(-6,5,6,OBSIDIAN:0)
Block(-6,5,7,OBSIDIAN:0)
Block(-6,5,8,OBSIDIAN:0)
RandomBlock(-6,6,-7,STONEBRICK:1,10,STONEBRICK:2,10,COBBLESTONE,10,MOSSY_COBBLESTONE,10,SMOOTH_BRICK,100)
RandomBlock(-6,6,-6,STONEBRICK:1,10,STONEBRICK:2,10,COBBLESTONE,10,MOSSY_COBBLESTONE,10,SMOOTH_BRICK,100)
RandomBlock(-6,6,-5,STONEBRICK:1,10,STONEBRICK:2,10,COBBLESTONE,10,MOSSY_COBBLESTONE,10,SMOOTH_BRICK,100)
RandomBlock(-6,6,-4,STONEBRICK:1,10,STONEBRICK:2,10,COBBLESTONE,10,MOSSY_COBBLESTONE,10,SMOOTH_BRICK,100)
RandomBlock(-6,6,-3,STONEBRICK:1,10,STONEBRICK:2,10,COBBLESTONE,10,MOSSY_COBBLESTONE,10,SMOOTH_BRICK,100)
RandomBlock(-6,6,-2,STONEBRICK:1,10,STONEBRICK:2,10,COBBLESTONE,10,MOSSY_COBBLESTONE,10,SMOOTH_BRICK,100)
RandomBlock(-6,6,-1,STONEBRICK:1,10,STONEBRICK:2,10,COBBLESTONE,10,MOSSY_COBBLESTONE,10,SMOOTH_BRICK,100)
Block(-6,6,0,OBSIDIAN:0)
Block(-6,6,1,OBSIDIAN:0)
Block(-6,6,2,OBSIDIAN:0)
Block(-6,6,3,OBSIDIAN:0)
Block(-6,6,4,OBSIDIAN:0)
Block(-6,6,5,OBSIDIAN:0)
Block(-6,6,6,OBSIDIAN:0)
Block(-6,6,7,OBSIDIAN:0)
Block(-6,6,8,OBSIDIAN:0)
Block(-6,7,-7,COBBLE_WALL:0)
Block(-6,7,-6,AIR:0)
Block(-6,7,-5,AIR:0)
Block(-6,7,-4,AIR:0)
RandomBlock(-6,7,-3,STONEBRICK:1,10,STONEBRICK:2,10,COBBLESTONE,10,MOSSY_COBBLESTONE,10,SMOOTH_BRICK,100)
RandomBlock(-6,7,-2,STONEBRICK:1,10,STONEBRICK:2,10,COBBLESTONE,10,MOSSY_COBBLESTONE,10,SMOOTH_BRICK,100)
RandomBlock(-6,7,-1,STONEBRICK:1,10,STONEBRICK:2,10,COBBLESTONE,10,MOSSY_COBBLESTONE,10,SMOOTH_BRICK,100)
Block(-6,7,0,OBSIDIAN:0)
Block(-6,7,1,OBSIDIAN:0)
Block(-6,7,2,OBSIDIAN:0)
Block(-6,7,3,OBSIDIAN:0)
Block(-6,7,4,OBSIDIAN:0)
Block(-6,7,5,OBSIDIAN:0)
Block(-6,7,6,OBSIDIAN:0)
Block(-6,7,7,OBSIDIAN:0)
Block(-6,7,8,OBSIDIAN:0)
Block(-6,8,-7,TORCH:5)
Block(-6,8,-6,AIR:0)
Block(-6,8,-5,AIR:0)
Block(-6,8,-4,AIR:0)
RandomBlock(-6,8,-3,STONEBRICK:1,10,STONEBRICK:2,10,COBBLESTONE,10,MOSSY_COBBLESTONE,10,SMOOTH_BRICK,100)
RandomBlock(-6,8,-2,STONEBRICK:1,10,STONEBRICK:2,10,COBBLESTONE,10,MOSSY_COBBLESTONE,10,SMOOTH_BRICK,100)
RandomBlock(-6,8,-1,STONEBRICK:1,10,STONEBRICK:2,10,COBBLESTONE,10,MOSSY_COBBLESTONE,10,SMOOTH_BRICK,100)
Block(-6,8,0,OBSIDIAN:0)
Block(-6,8,1,OBSIDIAN:0)
Block(-6,8,2,OBSIDIAN:0)
Block(-6,8,3,OBSIDIAN:0)
Block(-6,8,4,OBSIDIAN:0)
Block(-6,8,5,OBSIDIAN:0)
Block(-6,8,6,OBSIDIAN:0)
Block(-6,8,7,OBSIDIAN:0)
Block(-6,8,8,OBSIDIAN:0)
Block(-6,9,-7,AIR:0)
Block(-6,9,-6,AIR:0)
Block(-6,9,-5,AIR:0)
Block(-6,9,-4,AIR:0)
RandomBlock(-6,9,-3,STONEBRICK:1,10,STONEBRICK:2,10,COBBLESTONE,10,MOSSY_COBBLESTONE,10,SMOOTH_BRICK,100)
RandomBlock(-6,9,-2,STONEBRICK:1,10,STONEBRICK:2,10,COBBLESTONE,10,MOSSY_COBBLESTONE,10,SMOOTH_BRICK,100)
RandomBlock(-6,9,-1,STONEBRICK:1,10,STONEBRICK:2,10,COBBLESTONE,10,MOSSY_COBBLESTONE,10,SMOOTH_BRICK,100)
Block(-6,9,0,OBSIDIAN:0)
Block(-6,9,1,OBSIDIAN:0)
Block(-6,9,2,OBSIDIAN:0)
Block(-6,9,3,OBSIDIAN:0)
Block(-6,9,4,OBSIDIAN:0)
Block(-6,9,5,OBSIDIAN:0)
Block(-6,9,6,OBSIDIAN:0)
Block(-6,9,7,OBSIDIAN:0)
Block(-6,9,8,OBSIDIAN:0)
Block(-6,10,-7,AIR:0)
Block(-6,10,-6,AIR:0)
Block(-6,10,-5,AIR:0)
Block(-6,10,-4,AIR:0)
RandomBlock(-6,10,-3,STONEBRICK:1,10,STONEBRICK:2,10,COBBLESTONE,10,MOSSY_COBBLESTONE,10,SMOOTH_BRICK,100)
Block(-6,10,-2,STATIONARY_LAVA:2)
RandomBlock(-6,10,-1,STONEBRICK:1,10,STONEBRICK:2,10,COBBLESTONE,10,MOSSY_COBBLESTONE,10,SMOOTH_BRICK,100)
Block(-6,10,0,OBSIDIAN:0)
Block(-6,10,1,OBSIDIAN:0)
Block(-6,10,2,OBSIDIAN:0)
Block(-6,10,3,OBSIDIAN:0)
Block(-6,10,4,OBSIDIAN:0)
Block(-6,10,5,OBSIDIAN:0)
Block(-6,10,6,OBSIDIAN:0)
Block(-6,10,7,OBSIDIAN:0)
Block(-6,10,8,OBSIDIAN:0)
Block(-6,11,-7,AIR:0)
Block(-6,11,-6,AIR:0)
Block(-6,11,-5,AIR:0)
Block(-6,11,-4,AIR:0)
RandomBlock(-6,11,-3,STONEBRICK:1,10,STONEBRICK:2,10,COBBLESTONE,10,MOSSY_COBBLESTONE,10,SMOOTH_BRICK,100)
Block(-6,11,-2,AIR:0)
RandomBlock(-6,11,-1,STONEBRICK:1,10,STONEBRICK:2,10,COBBLESTONE,10,MOSSY_COBBLESTONE,10,SMOOTH_BRICK,100)
Block(-6,11,0,OBSIDIAN:0)
Block(-6,11,1,OBSIDIAN:0)
Block(-6,11,2,OBSIDIAN:0)
Block(-6,11,3,OBSIDIAN:0)
Block(-6,11,4,OBSIDIAN:0)
Block(-6,11,5,OBSIDIAN:0)
Block(-6,11,6,OBSIDIAN:0)
Block(-6,11,7,OBSIDIAN:0)
Block(-6,11,8,OBSIDIAN:0)
Block(-6,12,-7,AIR:0)
Block(-6,12,-6,AIR:0)
Block(-6,12,-5,AIR:0)
Block(-6,12,-4,AIR:0)
Block(-6,12,-3,SMOOTH_STAIRS:0)
Block(-6,12,-2,AIR:0)
RandomBlock(-6,12,-1,STONEBRICK:1,10,STONEBRICK:2,10,COBBLESTONE,10,MOSSY_COBBLESTONE,10,SMOOTH_BRICK,100)
Block(-6,12,0,OBSIDIAN:0)
Block(-6,12,1,OBSIDIAN:0)
Block(-6,12,2,OBSIDIAN:0)
Block(-6,12,3,OBSIDIAN:0)
Block(-6,12,4,OBSIDIAN:0)
Block(-6,12,5,OBSIDIAN:0)
Block(-6,12,6,OBSIDIAN:0)
Block(-6,12,7,OBSIDIAN:0)
Block(-6,12,8,OBSIDIAN:0)
Block(-6,13,-7,AIR:0)
Block(-6,13,-6,AIR:0)
Block(-6,13,-5,AIR:0)
Block(-6,13,-4,AIR:0)
Block(-6,13,-3,AIR:0)
Block(-6,13,-2,AIR:0)
RandomBlock(-6,13,-1,STONEBRICK:1,10,STONEBRICK:2,10,COBBLESTONE,10,MOSSY_COBBLESTONE,10,SMOOTH_BRICK,100)
Block(-6,13,0,OBSIDIAN:0)
Block(-6,13,1,OBSIDIAN:0)
Block(-6,13,2,OBSIDIAN:0)
Block(-6,13,3,OBSIDIAN:0)
Block(-6,13,4,OBSIDIAN:0)
Block(-6,13,5,OBSIDIAN:0)
Block(-6,13,6,OBSIDIAN:0)
Block(-6,13,7,OBSIDIAN:0)
Block(-6,13,8,OBSIDIAN:0)
Block(-6,14,-7,AIR:0)
Block(-6,14,-6,AIR:0)
Block(-6,14,-5,AIR:0)
Block(-6,14,-4,AIR:0)
Block(-6,14,-3,AIR:0)
Block(-6,14,-2,AIR:0)
RandomBlock(-6,14,-1,STONEBRICK:1,10,STONEBRICK:2,10,COBBLESTONE,10,MOSSY_COBBLESTONE,10,SMOOTH_BRICK,100)
Block(-6,14,0,OBSIDIAN:0)
Block(-6,14,1,OBSIDIAN:0)
Block(-6,14,2,OBSIDIAN:0)
Block(-6,14,3,OBSIDIAN:0)
Block(-6,14,4,OBSIDIAN:0)
Block(-6,14,5,OBSIDIAN:0)
Block(-6,14,6,OBSIDIAN:0)
Block(-6,14,7,OBSIDIAN:0)
Block(-6,14,8,OBSIDIAN:0)
Block(-6,15,-7,AIR:0)
Block(-6,15,-6,AIR:0)
Block(-6,15,-5,AIR:0)
Block(-6,15,-4,AIR:0)
Block(-6,15,-3,AIR:0)
Block(-6,15,-2,AIR:0)
RandomBlock(-6,15,-1,STONEBRICK:1,10,STONEBRICK:2,10,COBBLESTONE,10,MOSSY_COBBLESTONE,10,SMOOTH_BRICK,100)
Block(-6,15,0,OBSIDIAN:0)
Block(-6,15,1,OBSIDIAN:0)
Block(-6,15,2,OBSIDIAN:0)
Block(-6,15,3,OBSIDIAN:0)
Block(-6,15,4,OBSIDIAN:0)
Block(-6,15,5,OBSIDIAN:0)
Block(-6,15,6,OBSIDIAN:0)
Block(-6,15,7,OBSIDIAN:0)
Block(-6,15,8,OBSIDIAN:0)
Block(-6,16,-7,AIR:0)
Block(-6,16,-6,SMOOTH_STAIRS:4)
Block(-6,16,-5,AIR:0)
Block(-6,16,-4,AIR:0)
Block(-6,16,-3,SMOOTH_STAIRS:4)
Block(-6,16,-2,AIR:0)
RandomBlock(-6,16,-1,STONEBRICK:1,10,STONEBRICK:2,10,COBBLESTONE,10,MOSSY_COBBLESTONE,10,SMOOTH_BRICK,100)
Block(-6,16,0,OBSIDIAN:0)
Block(-6,16,1,OBSIDIAN:0)
Block(-6,16,2,OBSIDIAN:0)
Block(-6,16,3,OBSIDIAN:0)
Block(-6,16,4,OBSIDIAN:0)
Block(-6,16,5,OBSIDIAN:0)
Block(-6,16,6,OBSIDIAN:0)
Block(-6,16,7,OBSIDIAN:0)
Block(-6,16,8,OBSIDIAN:0)
RandomBlock(-6,17,-7,STONEBRICK:1,10,STONEBRICK:2,10,COBBLESTONE,10,MOSSY_COBBLESTONE,10,SMOOTH_BRICK,100)
RandomBlock(-6,17,-6,STONEBRICK:1,10,STONEBRICK:2,10,COBBLESTONE,10,MOSSY_COBBLESTONE,10,SMOOTH_BRICK,100)
RandomBlock(-6,17,-5,STONEBRICK:1,10,STONEBRICK:2,10,COBBLESTONE,10,MOSSY_COBBLESTONE,10,SMOOTH_BRICK,100)
RandomBlock(-6,17,-4,STONEBRICK:1,10,STONEBRICK:2,10,COBBLESTONE,10,MOSSY_COBBLESTONE,10,SMOOTH_BRICK,100)
RandomBlock(-6,17,-3,STONEBRICK:1,10,STONEBRICK:2,10,COBBLESTONE,10,MOSSY_COBBLESTONE,10,SMOOTH_BRICK,100)
Block(-6,17,-2,AIR:0)
RandomBlock(-6,17,-1,STONEBRICK:1,10,STONEBRICK:2,10,COBBLESTONE,10,MOSSY_COBBLESTONE,10,SMOOTH_BRICK,100)
Block(-6,17,0,OBSIDIAN:0)
Block(-6,17,1,OBSIDIAN:0)
Block(-6,17,2,OBSIDIAN:0)
Block(-6,17,3,OBSIDIAN:0)
Block(-6,17,4,OBSIDIAN:0)
Block(-6,17,5,OBSIDIAN:0)
Block(-6,17,6,OBSIDIAN:0)
Block(-6,17,7,OBSIDIAN:0)
Block(-6,17,8,OBSIDIAN:0)
Block(-6,18,-7,OBSIDIAN:0)
Block(-6,18,-6,OBSIDIAN:0)
Block(-6,18,-5,OBSIDIAN:0)
Block(-6,18,-4,OBSIDIAN:0)
RandomBlock(-6,18,-3,STONEBRICK:1,10,STONEBRICK:2,10,COBBLESTONE,10,MOSSY_COBBLESTONE,10,SMOOTH_BRICK,100)
Block(-6,18,-2,AIR:0)
RandomBlock(-6,18,-1,STONEBRICK:1,10,STONEBRICK:2,10,COBBLESTONE,10,MOSSY_COBBLESTONE,10,SMOOTH_BRICK,100)
Block(-6,18,0,OBSIDIAN:0)
Block(-6,18,1,OBSIDIAN:0)
Block(-6,18,2,OBSIDIAN:0)
Block(-6,18,3,OBSIDIAN:0)
Block(-6,18,4,OBSIDIAN:0)
Block(-6,18,5,OBSIDIAN:0)
Block(-6,18,6,OBSIDIAN:0)
Block(-6,18,7,OBSIDIAN:0)
Block(-6,18,8,OBSIDIAN:0)
Block(-6,19,-7,STATIONARY_WATER:0)
Block(-6,19,-6,STATIONARY_WATER:0)
Block(-6,19,-5,STATIONARY_WATER:0)
Block(-6,19,-4,OBSIDIAN:0)
RandomBlock(-6,19,-3,STONEBRICK:1,10,STONEBRICK:2,10,COBBLESTONE,10,MOSSY_COBBLESTONE,10,SMOOTH_BRICK,100)
Block(-6,19,-2,AIR:0)
RandomBlock(-6,19,-1,STONEBRICK:1,10,STONEBRICK:2,10,COBBLESTONE,10,MOSSY_COBBLESTONE,10,SMOOTH_BRICK,100)
Block(-6,19,0,OBSIDIAN:0)
Block(-6,19,1,OBSIDIAN:0)
Block(-6,19,2,OBSIDIAN:0)
Block(-6,19,3,OBSIDIAN:0)
Block(-6,19,4,OBSIDIAN:0)
Block(-6,19,5,OBSIDIAN:0)
Block(-6,19,6,OBSIDIAN:0)
Block(-6,19,7,OBSIDIAN:0)
Block(-6,19,8,OBSIDIAN:0)
Block(-6,20,-7,STATIONARY_WATER:0)
Block(-6,20,-6,STATIONARY_WATER:0)
Block(-6,20,-5,STATIONARY_WATER:0)
Block(-6,20,-4,OBSIDIAN:0)
RandomBlock(-6,20,-3,STONEBRICK:1,10,STONEBRICK:2,10,COBBLESTONE,10,MOSSY_COBBLESTONE,10,SMOOTH_BRICK,100)
Block(-6,20,-2,AIR:0)
RandomBlock(-6,20,-1,STONEBRICK:1,10,STONEBRICK:2,10,COBBLESTONE,10,MOSSY_COBBLESTONE,10,SMOOTH_BRICK,100)
Block(-6,20,0,OBSIDIAN:0)
Block(-6,20,1,OBSIDIAN:0)
Block(-6,20,2,OBSIDIAN:0)
Block(-6,20,3,OBSIDIAN:0)
Block(-6,20,4,OBSIDIAN:0)
Block(-6,20,5,OBSIDIAN:0)
Block(-6,20,6,OBSIDIAN:0)
Block(-6,20,7,OBSIDIAN:0)
Block(-6,20,8,OBSIDIAN:0)
Block(-6,21,-7,STATIONARY_WATER:0)
Block(-6,21,-6,STATIONARY_WATER:0)
Block(-6,21,-5,STATIONARY_WATER:0)
Block(-6,21,-4,OBSIDIAN:0)
RandomBlock(-6,21,-3,STONEBRICK:1,10,STONEBRICK:2,10,COBBLESTONE,10,MOSSY_COBBLESTONE,10,SMOOTH_BRICK,100)
Block(-6,21,-2,AIR:0)
RandomBlock(-6,21,-1,STONEBRICK:1,10,STONEBRICK:2,10,COBBLESTONE,10,MOSSY_COBBLESTONE,10,SMOOTH_BRICK,100)
Block(-6,21,0,OBSIDIAN:0)
Block(-6,21,1,OBSIDIAN:0)
Block(-6,21,2,OBSIDIAN:0)
Block(-6,21,3,OBSIDIAN:0)
Block(-6,21,4,OBSIDIAN:0)
Block(-6,21,5,OBSIDIAN:0)
Block(-6,21,6,OBSIDIAN:0)
Block(-6,21,7,OBSIDIAN:0)
Block(-6,21,8,OBSIDIAN:0)
Block(-6,22,-7,STATIONARY_WATER:0)
Block(-6,22,-6,STATIONARY_WATER:0)
Block(-6,22,-5,STATIONARY_WATER:0)
Block(-6,22,-4,OBSIDIAN:0)
RandomBlock(-6,22,-3,STONEBRICK:1,10,STONEBRICK:2,10,COBBLESTONE,10,MOSSY_COBBLESTONE,10,SMOOTH_BRICK,100)
Block(-6,22,-2,AIR:0)
RandomBlock(-6,22,-1,STONEBRICK:1,10,STONEBRICK:2,10,COBBLESTONE,10,MOSSY_COBBLESTONE,10,SMOOTH_BRICK,100)
Block(-6,22,0,OBSIDIAN:0)
Block(-6,22,1,OBSIDIAN:0)
Block(-6,22,2,OBSIDIAN:0)
Block(-6,22,3,OBSIDIAN:0)
Block(-6,22,4,OBSIDIAN:0)
Block(-6,22,5,OBSIDIAN:0)
Block(-6,22,6,OBSIDIAN:0)
Block(-6,22,7,OBSIDIAN:0)
Block(-6,22,8,OBSIDIAN:0)
Block(-6,23,-7,STATIONARY_WATER:0)
Block(-6,23,-6,STATIONARY_WATER:0)
Block(-6,23,-5,STATIONARY_WATER:0)
Block(-6,23,-4,OBSIDIAN:0)
RandomBlock(-6,23,-3,STONEBRICK:1,10,STONEBRICK:2,10,COBBLESTONE,10,MOSSY_COBBLESTONE,10,SMOOTH_BRICK,100)
Block(-6,23,-2,AIR:0)
RandomBlock(-6,23,-1,STONEBRICK:1,10,STONEBRICK:2,10,COBBLESTONE,10,MOSSY_COBBLESTONE,10,SMOOTH_BRICK,100)
Block(-6,23,0,OBSIDIAN:0)
Block(-6,23,1,OBSIDIAN:0)
Block(-6,23,2,OBSIDIAN:0)
Block(-6,23,3,OBSIDIAN:0)
Block(-6,23,4,OBSIDIAN:0)
Block(-6,23,5,OBSIDIAN:0)
Block(-6,23,6,OBSIDIAN:0)
Block(-6,23,7,OBSIDIAN:0)
Block(-6,23,8,OBSIDIAN:0)
RandomBlock(-6,24,-7,STONEBRICK:1,10,STONEBRICK:2,10,COBBLESTONE,10,MOSSY_COBBLESTONE,10,SMOOTH_BRICK,100)
RandomBlock(-6,24,-6,STONEBRICK:1,10,STONEBRICK:2,10,COBBLESTONE,10,MOSSY_COBBLESTONE,10,SMOOTH_BRICK,100)
RandomBlock(-6,24,-5,STONEBRICK:1,10,STONEBRICK:2,10,COBBLESTONE,10,MOSSY_COBBLESTONE,10,SMOOTH_BRICK,100)
RandomBlock(-6,24,-4,STONEBRICK:1,10,STONEBRICK:2,10,COBBLESTONE,10,MOSSY_COBBLESTONE,10,SMOOTH_BRICK,100)
RandomBlock(-6,24,-3,STONEBRICK:1,10,STONEBRICK:2,10,COBBLESTONE,10,MOSSY_COBBLESTONE,10,SMOOTH_BRICK,100)
RandomBlock(-6,24,-2,STONEBRICK:1,10,STONEBRICK:2,10,COBBLESTONE,10,MOSSY_COBBLESTONE,10,SMOOTH_BRICK,100)
RandomBlock(-6,24,-1,STONEBRICK:1,10,STONEBRICK:2,10,COBBLESTONE,10,MOSSY_COBBLESTONE,10,SMOOTH_BRICK,100)
Block(-6,24,0,OBSIDIAN:0)
Block(-6,24,1,OBSIDIAN:0)
Block(-6,24,2,OBSIDIAN:0)
Block(-6,24,3,OBSIDIAN:0)
Block(-6,24,4,OBSIDIAN:0)
Block(-6,24,5,OBSIDIAN:0)
Block(-6,24,6,OBSIDIAN:0)
Block(-6,24,7,OBSIDIAN:0)
Block(-6,24,8,OBSIDIAN:0)
RandomBlock(-6,25,-7,STONEBRICK:1,10,STONEBRICK:2,10,COBBLESTONE,10,MOSSY_COBBLESTONE,10,SMOOTH_BRICK,100)
RandomBlock(-6,25,-6,STONEBRICK:1,10,STONEBRICK:2,10,COBBLESTONE,10,MOSSY_COBBLESTONE,10,SMOOTH_BRICK,100)
RandomBlock(-6,25,-5,STONEBRICK:1,10,STONEBRICK:2,10,COBBLESTONE,10,MOSSY_COBBLESTONE,10,SMOOTH_BRICK,100)
RandomBlock(-6,25,-4,STONEBRICK:1,10,STONEBRICK:2,10,COBBLESTONE,10,MOSSY_COBBLESTONE,10,SMOOTH_BRICK,100)
RandomBlock(-6,25,-3,STONEBRICK:1,10,STONEBRICK:2,10,COBBLESTONE,10,MOSSY_COBBLESTONE,10,SMOOTH_BRICK,100)
RandomBlock(-6,25,-2,STONEBRICK:1,10,STONEBRICK:2,10,COBBLESTONE,10,MOSSY_COBBLESTONE,10,SMOOTH_BRICK,100)
RandomBlock(-6,25,-1,STONEBRICK:1,10,STONEBRICK:2,10,COBBLESTONE,10,MOSSY_COBBLESTONE,10,SMOOTH_BRICK,100)
Block(-6,25,0,OBSIDIAN:0)
Block(-6,25,1,OBSIDIAN:0)
Block(-6,25,2,OBSIDIAN:0)
Block(-6,25,3,OBSIDIAN:0)
Block(-6,25,4,OBSIDIAN:0)
Block(-6,25,5,OBSIDIAN:0)
Block(-6,25,6,OBSIDIAN:0)
Block(-6,25,7,OBSIDIAN:0)
Block(-6,25,8,OBSIDIAN:0)
Block(-6,26,-7,STONE_PLATE:0)
Block(-6,26,-6,STONE_PLATE:0)
Block(-6,26,-5,STONE_PLATE:0)
Block(-6,26,-4,STONE_PLATE:0)
Block(-6,26,-3,STONE_PLATE:0)
Block(-6,26,-2,STONE_PLATE:0)
RandomBlock(-6,26,-1,STONEBRICK:1,10,STONEBRICK:2,10,COBBLESTONE,10,MOSSY_COBBLESTONE,10,SMOOTH_BRICK,100)
Block(-6,26,0,OBSIDIAN:0)
Block(-6,26,1,OBSIDIAN:0)
Block(-6,26,2,OBSIDIAN:0)
Block(-6,26,3,OBSIDIAN:0)
Block(-6,26,4,OBSIDIAN:0)
Block(-6,26,5,OBSIDIAN:0)
Block(-6,26,6,OBSIDIAN:0)
Block(-6,26,7,OBSIDIAN:0)
Block(-6,26,8,OBSIDIAN:0)
Block(-6,27,-7,AIR:0)
Block(-6,27,-6,AIR:0)
Block(-6,27,-5,AIR:0)
Block(-6,27,-4,AIR:0)
Block(-6,27,-3,AIR:0)
Block(-6,27,-2,AIR:0)
RandomBlock(-6,27,-1,STONEBRICK:1,10,STONEBRICK:2,10,COBBLESTONE,10,MOSSY_COBBLESTONE,10,SMOOTH_BRICK,100)
Block(-6,27,0,OBSIDIAN:0)
Block(-6,27,1,OBSIDIAN:0)
Block(-6,27,2,OBSIDIAN:0)
Block(-6,27,3,OBSIDIAN:0)
Block(-6,27,4,OBSIDIAN:0)
Block(-6,27,5,OBSIDIAN:0)
Block(-6,27,6,OBSIDIAN:0)
Block(-6,27,7,OBSIDIAN:0)
Block(-6,27,8,OBSIDIAN:0)
Block(-6,28,-7,AIR:0)
Block(-6,28,-6,AIR:0)
Block(-6,28,-5,AIR:0)
Block(-6,28,-4,AIR:0)
Block(-6,28,-3,AIR:0)
Block(-6,28,-2,WALL_BANNER:2,NBT/dungeon_banner.nbt)
RandomBlock(-6,28,-1,STONEBRICK:1,10,STONEBRICK:2,10,COBBLESTONE,10,MOSSY_COBBLESTONE,10,SMOOTH_BRICK,100)
Block(-6,28,0,OBSIDIAN:0)
Block(-6,28,1,OBSIDIAN:0)
Block(-6,28,2,OBSIDIAN:0)
Block(-6,28,3,OBSIDIAN:0)
Block(-6,28,4,OBSIDIAN:0)
Block(-6,28,5,OBSIDIAN:0)
Block(-6,28,6,OBSIDIAN:0)
Block(-6,28,7,OBSIDIAN:0)
Block(-6,28,8,OBSIDIAN:0)
Block(-6,29,-7,AIR:0)
Block(-6,29,-6,AIR:0)
Block(-6,29,-5,AIR:0)
Block(-6,29,-4,AIR:0)
Block(-6,29,-3,AIR:0)
Block(-6,29,-2,AIR:0)
RandomBlock(-6,29,-1,STONEBRICK:1,10,STONEBRICK:2,10,COBBLESTONE,10,MOSSY_COBBLESTONE,10,SMOOTH_BRICK,100)
Block(-6,29,0,OBSIDIAN:0)
Block(-6,29,1,OBSIDIAN:0)
Block(-6,29,2,OBSIDIAN:0)
Block(-6,29,3,OBSIDIAN:0)
Block(-6,29,4,OBSIDIAN:0)
Block(-6,29,5,OBSIDIAN:0)
Block(-6,29,6,OBSIDIAN:0)
Block(-6,29,7,OBSIDIAN:0)
Block(-6,29,8,OBSIDIAN:0)
Block(-6,30,-7,AIR:0)
RandomBlock(-6,30,-6,STONEBRICK:1,10,STONEBRICK:2,10,COBBLESTONE,10,MOSSY_COBBLESTONE,10,SMOOTH_BRICK,100)
Block(-6,30,-5,AIR:0)
RandomBlock(-6,30,-4,STONEBRICK:1,10,STONEBRICK:2,10,COBBLESTONE,10,MOSSY_COBBLESTONE,10,SMOOTH_BRICK,100)
Block(-6,30,-3,AIR:0)
Block(-6,30,-2,AIR:0)
RandomBlock(-6,30,-1,STONEBRICK:1,10,STONEBRICK:2,10,COBBLESTONE,10,MOSSY_COBBLESTONE,10,SMOOTH_BRICK,100)
Block(-6,30,0,OBSIDIAN:0)
Block(-6,30,1,OBSIDIAN:0)
Block(-6,30,2,OBSIDIAN:0)
Block(-6,30,3,OBSIDIAN:0)
Block(-6,30,4,OBSIDIAN:0)
Block(-6,30,5,OBSIDIAN:0)
Block(-6,30,6,OBSIDIAN:0)
Block(-6,30,7,OBSIDIAN:0)
Block(-6,30,8,OBSIDIAN:0)
RandomBlock(-6,31,-7,STONEBRICK:1,10,STONEBRICK:2,10,COBBLESTONE,10,MOSSY_COBBLESTONE,10,SMOOTH_BRICK,100)
Block(-6,31,-6,OBSIDIAN:0)
RandomBlock(-6,31,-5,STONEBRICK:1,10,STONEBRICK:2,10,COBBLESTONE,10,MOSSY_COBBLESTONE,10,SMOOTH_BRICK,100)
RandomBlock(-6,31,-4,STONEBRICK:1,10,STONEBRICK:2,10,COBBLESTONE,10,MOSSY_COBBLESTONE,10,SMOOTH_BRICK,100)
Block(-6,31,-3,AIR:0)
Block(-6,31,-2,AIR:0)
RandomBlock(-6,31,-1,STONEBRICK:1,10,STONEBRICK:2,10,COBBLESTONE,10,MOSSY_COBBLESTONE,10,SMOOTH_BRICK,100)
Block(-6,31,0,OBSIDIAN:0)
Block(-6,31,1,OBSIDIAN:0)
Block(-6,31,2,OBSIDIAN:0)
Block(-6,31,3,OBSIDIAN:0)
Block(-6,31,4,OBSIDIAN:0)
Block(-6,31,5,OBSIDIAN:0)
Block(-6,31,6,OBSIDIAN:0)
Block(-6,31,7,OBSIDIAN:0)
Block(-6,31,8,OBSIDIAN:0)
Block(-6,32,-7,OBSIDIAN:0)
Block(-6,32,-6,OBSIDIAN:0)
Block(-6,32,-5,OBSIDIAN:0)
Block(-6,32,-4,OBSIDIAN:0)
Block(-6,32,-3,OBSIDIAN:0)
Block(-6,32,-2,OBSIDIAN:0)
Block(-6,32,-1,OBSIDIAN:0)
Block(-6,32,0,OBSIDIAN:0)
Block(-6,32,1,OBSIDIAN:0)
Block(-6,32,2,OBSIDIAN:0)
Block(-6,32,3,OBSIDIAN:0)
Block(-6,32,4,OBSIDIAN:0)
Block(-6,32,5,OBSIDIAN:0)
Block(-6,32,6,OBSIDIAN:0)
Block(-6,32,7,OBSIDIAN:0)
Block(-6,32,8,OBSIDIAN:0)
Block(-6,33,-7,OBSIDIAN:0)
Block(-6,33,-6,OBSIDIAN:0)
Block(-6,33,-5,OBSIDIAN:0)
Block(-6,33,-4,OBSIDIAN:0)
Block(-6,33,-3,OBSIDIAN:0)
Block(-6,33,-2,OBSIDIAN:0)
Block(-6,33,-1,OBSIDIAN:0)
Block(-6,33,0,OBSIDIAN:0)
Block(-6,33,1,OBSIDIAN:0)
Block(-6,33,2,OBSIDIAN:0)
Block(-6,33,3,OBSIDIAN:0)
Block(-6,33,4,OBSIDIAN:0)
Block(-6,33,5,OBSIDIAN:0)
Block(-6,33,6,OBSIDIAN:0)
Block(-6,33,7,OBSIDIAN:0)
Block(-6,33,8,OBSIDIAN:0)
Block(-6,34,-7,OBSIDIAN:0)
Block(-6,34,-6,OBSIDIAN:0)
Block(-6,34,-5,OBSIDIAN:0)
Block(-6,34,-4,OBSIDIAN:0)
Block(-6,34,-3,OBSIDIAN:0)
Block(-6,34,-2,OBSIDIAN:0)
Block(-6,34,-1,OBSIDIAN:0)
Block(-6,34,0,OBSIDIAN:0)
Block(-6,34,1,OBSIDIAN:0)
Block(-6,34,2,OBSIDIAN:0)
Block(-6,34,3,OBSIDIAN:0)
Block(-6,34,4,OBSIDIAN:0)
Block(-6,34,5,OBSIDIAN:0)
Block(-6,34,6,OBSIDIAN:0)
Block(-6,34,7,OBSIDIAN:0)
Block(-6,34,8,OBSIDIAN:0)
Block(-6,35,-7,OBSIDIAN:0)
Block(-6,35,-6,OBSIDIAN:0)
Block(-6,35,-5,OBSIDIAN:0)
Block(-6,35,-4,OBSIDIAN:0)
Block(-6,35,-3,OBSIDIAN:0)
Block(-6,35,-2,OBSIDIAN:0)
Block(-6,35,-1,OBSIDIAN:0)
Block(-6,35,0,OBSIDIAN:0)
Block(-6,35,1,OBSIDIAN:0)
Block(-6,35,2,OBSIDIAN:0)
Block(-6,35,3,OBSIDIAN:0)
Block(-6,35,4,OBSIDIAN:0)
Block(-6,35,5,OBSIDIAN:0)
Block(-6,35,6,OBSIDIAN:0)
Block(-6,35,7,OBSIDIAN:0)
Block(-6,35,8,OBSIDIAN:0)
Block(-6,36,-7,OBSIDIAN:0)
Block(-6,36,-6,OBSIDIAN:0)
Block(-6,36,-5,OBSIDIAN:0)
Block(-6,36,-4,OBSIDIAN:0)
Block(-6,36,-3,OBSIDIAN:0)
Block(-6,36,-2,OBSIDIAN:0)
Block(-6,36,-1,OBSIDIAN:0)
Block(-6,36,0,OBSIDIAN:0)
Block(-6,36,1,OBSIDIAN:0)
Block(-6,36,2,OBSIDIAN:0)
Block(-6,36,3,OBSIDIAN:0)
Block(-6,36,4,OBSIDIAN:0)
Block(-6,36,5,OBSIDIAN:0)
Block(-6,36,6,OBSIDIAN:0)
Block(-6,36,7,OBSIDIAN:0)
Block(-6,36,8,OBSIDIAN:0)
Block(-6,37,-7,OBSIDIAN:0)
Block(-6,37,-6,OBSIDIAN:0)
Block(-6,37,-5,OBSIDIAN:0)
Block(-6,37,-4,OBSIDIAN:0)
Block(-6,37,-3,OBSIDIAN:0)
Block(-6,37,-2,OBSIDIAN:0)
Block(-6,37,-1,OBSIDIAN:0)
Block(-6,37,0,OBSIDIAN:0)
Block(-6,37,1,OBSIDIAN:0)
Block(-6,37,2,OBSIDIAN:0)
Block(-6,37,3,OBSIDIAN:0)
Block(-6,37,4,OBSIDIAN:0)
Block(-6,37,5,OBSIDIAN:0)
Block(-6,37,6,OBSIDIAN:0)
Block(-6,37,7,OBSIDIAN:0)
Block(-6,37,8,OBSIDIAN:0)
Block(-6,38,-7,OBSIDIAN:0)
Block(-6,38,-6,OBSIDIAN:0)
Block(-6,38,-5,OBSIDIAN:0)
Block(-6,38,-4,OBSIDIAN:0)
Block(-6,38,-3,OBSIDIAN:0)
Block(-6,38,-2,OBSIDIAN:0)
Block(-6,38,-1,OBSIDIAN:0)
Block(-6,38,0,OBSIDIAN:0)
Block(-6,38,1,OBSIDIAN:0)
Block(-6,38,2,OBSIDIAN:0)
Block(-6,38,3,OBSIDIAN:0)
Block(-6,38,4,OBSIDIAN:0)
Block(-6,38,5,OBSIDIAN:0)
Block(-6,38,6,OBSIDIAN:0)
Block(-6,38,7,OBSIDIAN:0)
Block(-6,38,8,OBSIDIAN:0)
Block(-6,39,-7,OBSIDIAN:0)
Block(-6,39,-6,OBSIDIAN:0)
Block(-6,39,-5,OBSIDIAN:0)
Block(-6,39,-4,OBSIDIAN:0)
Block(-6,39,-3,OBSIDIAN:0)
Block(-6,39,-2,OBSIDIAN:0)
Block(-6,39,-1,OBSIDIAN:0)
Block(-6,39,0,OBSIDIAN:0)
Block(-6,39,1,OBSIDIAN:0)
Block(-6,39,2,OBSIDIAN:0)
Block(-6,39,3,OBSIDIAN:0)
Block(-6,39,4,OBSIDIAN:0)
Block(-6,39,5,OBSIDIAN:0)
Block(-6,39,6,OBSIDIAN:0)
Block(-6,39,7,OBSIDIAN:0)
Block(-6,39,8,OBSIDIAN:0)
Block(-6,40,-7,OBSIDIAN:0)
Block(-6,40,-6,OBSIDIAN:0)
Block(-6,40,-5,OBSIDIAN:0)
Block(-6,40,-4,OBSIDIAN:0)
Block(-6,40,-3,OBSIDIAN:0)
Block(-6,40,-2,OBSIDIAN:0)
Block(-6,40,-1,OBSIDIAN:0)
Block(-6,40,0,OBSIDIAN:0)
Block(-6,40,1,OBSIDIAN:0)
Block(-6,40,2,OBSIDIAN:0)
Block(-6,40,3,OBSIDIAN:0)
Block(-6,40,4,OBSIDIAN:0)
Block(-6,40,5,OBSIDIAN:0)
Block(-6,40,6,OBSIDIAN:0)
Block(-6,40,7,OBSIDIAN:0)
Block(-6,40,8,OBSIDIAN:0)
Block(-6,41,-7,OBSIDIAN:0)
Block(-6,41,-6,OBSIDIAN:0)
Block(-6,41,-5,OBSIDIAN:0)
Block(-6,41,-4,OBSIDIAN:0)
Block(-6,41,-3,OBSIDIAN:0)
Block(-6,41,-2,OBSIDIAN:0)
Block(-6,41,-1,OBSIDIAN:0)
Block(-6,41,0,OBSIDIAN:0)
Block(-6,41,1,OBSIDIAN:0)
Block(-6,41,2,OBSIDIAN:0)
Block(-6,41,3,OBSIDIAN:0)
Block(-6,41,4,OBSIDIAN:0)
Block(-6,41,5,OBSIDIAN:0)
Block(-6,41,6,OBSIDIAN:0)
Block(-6,41,7,OBSIDIAN:0)
Block(-6,41,8,OBSIDIAN:0)
Block(-6,42,-7,OBSIDIAN:0)
Block(-6,42,-6,OBSIDIAN:0)
Block(-6,42,-5,OBSIDIAN:0)
Block(-6,42,-4,OBSIDIAN:0)
Block(-6,42,-3,OBSIDIAN:0)
Block(-6,42,-2,OBSIDIAN:0)
Block(-6,42,-1,OBSIDIAN:0)
Block(-6,42,0,OBSIDIAN:0)
Block(-6,42,1,OBSIDIAN:0)
Block(-6,42,2,OBSIDIAN:0)
Block(-6,42,3,OBSIDIAN:0)
Block(-6,42,4,OBSIDIAN:0)
Block(-6,42,5,OBSIDIAN:0)
Block(-6,42,6,OBSIDIAN:0)
Block(-6,42,7,OBSIDIAN:0)
Block(-6,42,8,OBSIDIAN:0)
Block(-6,43,-7,OBSIDIAN:0)
Block(-6,43,-6,OBSIDIAN:0)
Block(-6,43,-5,OBSIDIAN:0)
Block(-6,43,-4,OBSIDIAN:0)
Block(-6,43,-3,OBSIDIAN:0)
Block(-6,43,-2,OBSIDIAN:0)
Block(-6,43,-1,OBSIDIAN:0)
Block(-6,43,0,OBSIDIAN:0)
Block(-6,43,1,OBSIDIAN:0)
Block(-6,43,2,OBSIDIAN:0)
Block(-6,43,3,OBSIDIAN:0)
Block(-6,43,4,OBSIDIAN:0)
Block(-6,43,5,OBSIDIAN:0)
Block(-6,43,6,OBSIDIAN:0)
Block(-6,43,7,OBSIDIAN:0)
Block(-6,43,8,OBSIDIAN:0)
Block(-6,44,-7,OBSIDIAN:0)
Block(-6,44,-6,OBSIDIAN:0)
Block(-6,44,-5,OBSIDIAN:0)
Block(-6,44,-4,OBSIDIAN:0)
Block(-6,44,-3,OBSIDIAN:0)
Block(-6,44,-2,OBSIDIAN:0)
Block(-6,44,-1,OBSIDIAN:0)
Block(-6,44,0,OBSIDIAN:0)
Block(-6,44,1,OBSIDIAN:0)
Block(-6,44,2,OBSIDIAN:0)
Block(-6,44,3,OBSIDIAN:0)
Block(-6,44,4,OBSIDIAN:0)
Block(-6,44,5,OBSIDIAN:0)
Block(-6,44,6,OBSIDIAN:0)
Block(-6,44,7,OBSIDIAN:0)
Block(-6,44,8,OBSIDIAN:0)
Block(-6,45,-7,OBSIDIAN:0)
Block(-6,45,-6,OBSIDIAN:0)
Block(-6,45,-5,OBSIDIAN:0)
Block(-6,45,-4,OBSIDIAN:0)
Block(-6,45,-3,OBSIDIAN:0)
Block(-6,45,-2,OBSIDIAN:0)
Block(-6,45,-1,OBSIDIAN:0)
Block(-6,45,0,OBSIDIAN:0)
Block(-6,45,1,OBSIDIAN:0)
Block(-6,45,2,OBSIDIAN:0)
Block(-6,45,3,OBSIDIAN:0)
Block(-6,45,4,OBSIDIAN:0)
Block(-6,45,5,OBSIDIAN:0)
Block(-6,45,6,OBSIDIAN:0)
Block(-6,45,7,OBSIDIAN:0)
Block(-6,45,8,OBSIDIAN:0)
Block(-6,46,-7,OBSIDIAN:0)
Block(-6,46,-6,OBSIDIAN:0)
Block(-6,46,-5,OBSIDIAN:0)
Block(-6,46,-4,OBSIDIAN:0)
Block(-6,46,-3,OBSIDIAN:0)
Block(-6,46,-2,OBSIDIAN:0)
Block(-6,46,-1,OBSIDIAN:0)
Block(-6,46,0,OBSIDIAN:0)
Block(-6,46,1,OBSIDIAN:0)
Block(-6,46,2,OBSIDIAN:0)
Block(-6,46,3,OBSIDIAN:0)
Block(-6,46,4,OBSIDIAN:0)
Block(-6,46,5,OBSIDIAN:0)
Block(-6,46,6,OBSIDIAN:0)
Block(-6,46,7,OBSIDIAN:0)
Block(-6,46,8,OBSIDIAN:0)
Block(-6,47,-7,OBSIDIAN:0)
Block(-6,47,-6,OBSIDIAN:0)
Block(-6,47,-5,OBSIDIAN:0)
Block(-6,47,-4,OBSIDIAN:0)
Block(-6,47,-3,OBSIDIAN:0)
Block(-6,47,-2,OBSIDIAN:0)
Block(-6,47,-1,OBSIDIAN:0)
Block(-6,47,0,OBSIDIAN:0)
Block(-6,47,1,OBSIDIAN:0)
Block(-6,47,2,OBSIDIAN:0)
Block(-6,47,3,OBSIDIAN:0)
Block(-6,47,4,OBSIDIAN:0)
Block(-6,47,5,OBSIDIAN:0)
Block(-6,47,6,OBSIDIAN:0)
Block(-6,47,7,OBSIDIAN:0)
Block(-6,47,8,OBSIDIAN:0)
Block(-6,48,-7,OBSIDIAN:0)
Block(-6,48,-6,OBSIDIAN:0)
Block(-6,48,-5,OBSIDIAN:0)
Block(-6,48,-4,OBSIDIAN:0)
Block(-6,48,-3,OBSIDIAN:0)
Block(-6,48,-2,OBSIDIAN:0)
Block(-6,48,-1,OBSIDIAN:0)
Block(-6,48,0,OBSIDIAN:0)
Block(-6,48,1,OBSIDIAN:0)
Block(-6,48,2,OBSIDIAN:0)
Block(-6,48,3,OBSIDIAN:0)
Block(-6,48,4,OBSIDIAN:0)
Block(-6,48,5,OBSIDIAN:0)
Block(-6,48,6,OBSIDIAN:0)
Block(-6,48,7,OBSIDIAN:0)
Block(-6,48,8,OBSIDIAN:0)
RandomBlock(-6,49,-7,STONEBRICK:1,10,STONEBRICK:2,10,COBBLESTONE,10,MOSSY_COBBLESTONE,10,SMOOTH_BRICK,100)
RandomBlock(-6,49,-6,STONEBRICK:1,10,STONEBRICK:2,10,COBBLESTONE,10,MOSSY_COBBLESTONE,10,SMOOTH_BRICK,100)
RandomBlock(-6,49,-5,STONEBRICK:1,10,STONEBRICK:2,10,COBBLESTONE,10,MOSSY_COBBLESTONE,10,SMOOTH_BRICK,100)
RandomBlock(-6,49,-4,STONEBRICK:1,10,STONEBRICK:2,10,COBBLESTONE,10,MOSSY_COBBLESTONE,10,SMOOTH_BRICK,100)
RandomBlock(-6,49,-3,STONEBRICK:1,10,STONEBRICK:2,10,COBBLESTONE,10,MOSSY_COBBLESTONE,10,SMOOTH_BRICK,100)
RandomBlock(-6,49,-2,STONEBRICK:1,10,STONEBRICK:2,10,COBBLESTONE,10,MOSSY_COBBLESTONE,10,SMOOTH_BRICK,100)
RandomBlock(-6,49,-1,STONEBRICK:1,10,STONEBRICK:2,10,COBBLESTONE,10,MOSSY_COBBLESTONE,10,SMOOTH_BRICK,100)
RandomBlock(-6,49,0,STONEBRICK:1,10,STONEBRICK:2,10,COBBLESTONE,10,MOSSY_COBBLESTONE,10,SMOOTH_BRICK,100)
RandomBlock(-6,49,1,STONEBRICK:1,10,STONEBRICK:2,10,COBBLESTONE,10,MOSSY_COBBLESTONE,10,SMOOTH_BRICK,100)
RandomBlock(-6,49,2,STONEBRICK:1,10,STONEBRICK:2,10,COBBLESTONE,10,MOSSY_COBBLESTONE,10,SMOOTH_BRICK,100)
RandomBlock(-6,49,3,STONEBRICK:1,10,STONEBRICK:2,10,COBBLESTONE,10,MOSSY_COBBLESTONE,10,SMOOTH_BRICK,100)
RandomBlock(-6,49,4,STONEBRICK:1,10,STONEBRICK:2,10,COBBLESTONE,10,MOSSY_COBBLESTONE,10,SMOOTH_BRICK,100)
RandomBlock(-6,49,5,STONEBRICK:1,10,STONEBRICK:2,10,COBBLESTONE,10,MOSSY_COBBLESTONE,10,SMOOTH_BRICK,100)
RandomBlock(-6,49,6,STONEBRICK:1,10,STONEBRICK:2,10,COBBLESTONE,10,MOSSY_COBBLESTONE,10,SMOOTH_BRICK,100)
RandomBlock(-6,49,7,STONEBRICK:1,10,STONEBRICK:2,10,COBBLESTONE,10,MOSSY_COBBLESTONE,10,SMOOTH_BRICK,100)
Block(-6,49,8,OBSIDIAN:0)
Block(-6,50,-7,OBSIDIAN:0)
Block(-6,50,-6,OBSIDIAN:0)
Block(-6,50,-5,OBSIDIAN:0)
Block(-6,50,-4,OBSIDIAN:0)
Block(-6,50,-3,OBSIDIAN:0)
Block(-6,50,-2,OBSIDIAN:0)
Block(-6,50,-1,OBSIDIAN:0)
Block(-6,50,0,OBSIDIAN:0)
Block(-6,50,1,OBSIDIAN:0)
Block(-6,50,2,OBSIDIAN:0)
Block(-6,50,3,OBSIDIAN:0)
Block(-6,50,4,OBSIDIAN:0)
Block(-6,50,5,OBSIDIAN:0)
Block(-6,50,6,OBSIDIAN:0)
Block(-6,50,7,OBSIDIAN:0)
Block(-6,50,8,OBSIDIAN:0)
Block(-6,51,-7,OBSIDIAN:0)
Block(-6,51,-6,OBSIDIAN:0)
Block(-6,51,-5,OBSIDIAN:0)
Block(-6,51,-4,OBSIDIAN:0)
Block(-6,51,-3,OBSIDIAN:0)
Block(-6,51,-2,OBSIDIAN:0)
Block(-6,51,-1,OBSIDIAN:0)
Block(-6,51,0,OBSIDIAN:0)
Block(-6,51,1,OBSIDIAN:0)
Block(-6,51,2,OBSIDIAN:0)
Block(-6,51,3,OBSIDIAN:0)
Block(-6,51,4,OBSIDIAN:0)
Block(-6,51,5,OBSIDIAN:0)
Block(-6,51,6,OBSIDIAN:0)
Block(-6,51,7,OBSIDIAN:0)
Block(-6,51,8,OBSIDIAN:0)
Block(-6,52,-7,OBSIDIAN:0)
Block(-6,52,-6,OBSIDIAN:0)
Block(-6,52,-5,OBSIDIAN:0)
Block(-6,52,-4,OBSIDIAN:0)
Block(-6,52,-3,OBSIDIAN:0)
Block(-6,52,-2,OBSIDIAN:0)
Block(-6,52,-1,OBSIDIAN:0)
Block(-6,52,0,OBSIDIAN:0)
Block(-6,52,1,OBSIDIAN:0)
Block(-6,52,2,OBSIDIAN:0)
Block(-6,52,3,OBSIDIAN:0)
Block(-6,52,4,OBSIDIAN:0)
Block(-6,52,5,OBSIDIAN:0)
Block(-6,52,6,OBSIDIAN:0)
Block(-6,52,7,OBSIDIAN:0)
Block(-6,52,8,OBSIDIAN:0)
Block(-6,53,-7,OBSIDIAN:0)
Block(-6,53,-6,OBSIDIAN:0)
Block(-6,53,-5,OBSIDIAN:0)
Block(-6,53,-4,OBSIDIAN:0)
Block(-6,53,-3,OBSIDIAN:0)
Block(-6,53,-2,OBSIDIAN:0)
Block(-6,53,-1,OBSIDIAN:0)
Block(-6,53,0,OBSIDIAN:0)
Block(-6,53,1,OBSIDIAN:0)
Block(-6,53,2,OBSIDIAN:0)
Block(-6,53,3,OBSIDIAN:0)
Block(-6,53,4,OBSIDIAN:0)
Block(-6,53,5,OBSIDIAN:0)
Block(-6,53,6,OBSIDIAN:0)
Block(-6,53,7,OBSIDIAN:0)
Block(-6,53,8,OBSIDIAN:0)
Block(-6,54,-7,STONE:0)
Block(-6,54,-6,STONE:0)
Block(-6,54,-5,STONE:0)
Block(-6,54,-4,STONE:0)
Block(-6,54,-3,STONE:0)
Block(-6,54,-2,STONE:0)
Block(-6,54,-1,STONE:0)
Block(-6,54,0,STONE:0)
Block(-6,54,1,STONE:0)
Block(-6,54,2,STONE:0)
Block(-6,54,3,STONE:0)
Block(-6,54,4,STONE:0)
Block(-6,54,5,STONE:0)
Block(-6,54,6,STONE:0)
Block(-6,54,7,STONE:0)
Block(-6,54,8,STONE:0)
Block(-6,55,-7,STONE:0)
Block(-6,55,-6,STONE:0)
Block(-6,55,-5,STONE:0)
Block(-6,55,-4,STONE:0)
Block(-6,55,-3,STONE:0)
Block(-6,55,-2,STONE:0)
Block(-6,55,-1,STONE:0)
Block(-6,55,0,STONE:0)
Block(-6,55,1,STONE:0)
Block(-6,55,2,STONE:0)
Block(-6,55,3,STONE:0)
Block(-6,55,4,STONE:0)
Block(-6,55,5,GRASS:0)
Block(-6,55,6,GRASS:0)
Block(-6,55,7,GRASS:0)
Block(-6,55,8,GRASS:0)
Block(-6,56,-7,STONE:0)
Block(-6,56,-6,STONE:0)
Block(-6,56,-5,STONE:0)
Block(-6,56,-4,STONE:0)
Block(-6,56,-3,STONE:0)
Block(-6,56,-2,STONE:0)
Block(-6,56,-1,STONE:0)
Block(-6,56,0,STONE:0)
Block(-6,56,1,STONE:0)
Block(-6,56,2,STONE:0)
Block(-6,56,3,GRASS:0)
Block(-6,56,4,GRASS:0)
Block(-6,57,-7,STONE:0)
Block(-6,57,-6,STONE:0)
Block(-6,57,-5,STONE:0)
Block(-6,57,-4,STONE:0)
