
#######################################################################
# +-----------------------------------------------------------------+ #
# |                            BO4 object                           | #
# +-----------------------------------------------------------------+ #
#######################################################################

Author: NLBlackEagle

Description: No description given

SettingsMode: WriteDisable


#######################################################################
# +-----------------------------------------------------------------+ #
# |                          Main settings                          | #
# +-----------------------------------------------------------------+ #
#######################################################################

FixedRotation: 

Frequency: 0

SpawnHeight: highestBlock

UseCenterForHighestBlock: true

##############################
# Height Limits for the BO4. #
##############################

MinHeight: 0

MaxHeight: 255

InheritBO3: 

InheritBO3Rotation: NORTH

OverrideChildSettings: true

OverrideParentHeight: false

CanOverride: true

BranchFrequency: 0

BranchFrequencyGroup: 

MustBeBelowOther: false

MustBeInside: 

CannotBeInside: 

ReplacesBO3: 

MustBeInsideWorldBorders: false

CanSpawnOnWater: true

SpawnOnWaterOnly: false

SpawnUnderWater: false

SpawnAtWaterLevel: false

HeightOffset: 0

RemoveAir: false

ReplaceAbove: 

ReplaceBelow: 

ReplaceWithBiomeBlocks: true

ReplaceWithSurfaceBlock: GRASS

ReplaceWithGroundBlock: DIRT

ReplaceWithStoneBlock: STONE

SmoothRadius: 0

SmoothHeightOffset: 0

SmoothStartTop: false

SmoothStartWood: false

SmoothingSurfaceBlock: 

SmoothingGroundBlock: 

BO3Group: 

IsSpawnPoint: false

DoReplaceBlocks: true


#######################################################################
# +-----------------------------------------------------------------+ #
# |                              Blocks                             | #
# +-----------------------------------------------------------------+ #
#######################################################################

RandomBlock(-8,0,-7,CONCRETE:7,65,quark:iron_plate,10,quark:iron_plate:1,10,STAINED_CLAY:15,10,STAINED_CLAY:9,100)
RandomBlock(-8,0,-6,CONCRETE:7,65,quark:iron_plate,10,quark:iron_plate:1,10,STAINED_CLAY:15,10,STAINED_CLAY:9,100)
RandomBlock(-8,0,-5,CONCRETE:7,65,quark:iron_plate,10,quark:iron_plate:1,10,STAINED_CLAY:15,10,STAINED_CLAY:9,100)
RandomBlock(-8,0,-4,CONCRETE:7,65,quark:iron_plate,10,quark:iron_plate:1,10,STAINED_CLAY:15,10,STAINED_CLAY:9,100)
RandomBlock(-8,0,-3,CONCRETE:7,65,quark:iron_plate,10,quark:iron_plate:1,10,STAINED_CLAY:15,10,STAINED_CLAY:9,100)
RandomBlock(-8,0,-2,CONCRETE:7,65,quark:iron_plate,10,quark:iron_plate:1,10,STAINED_CLAY:15,10,STAINED_CLAY:9,100)
RandomBlock(-8,0,-1,CONCRETE:7,65,quark:iron_plate,10,quark:iron_plate:1,10,STAINED_CLAY:15,10,STAINED_CLAY:9,100)
RandomBlock(-8,0,0,CONCRETE:7,65,quark:iron_plate,10,quark:iron_plate:1,10,STAINED_CLAY:15,10,STAINED_CLAY:9,100)
RandomBlock(-8,0,1,CONCRETE:7,65,quark:iron_plate,10,quark:iron_plate:1,10,STAINED_CLAY:15,10,STAINED_CLAY:9,100)
RandomBlock(-8,0,2,CONCRETE:7,65,quark:iron_plate,10,quark:iron_plate:1,10,STAINED_CLAY:15,10,STAINED_CLAY:9,100)
RandomBlock(-8,0,3,CONCRETE:7,65,quark:iron_plate,10,quark:iron_plate:1,10,STAINED_CLAY:15,10,STAINED_CLAY:9,100)
RandomBlock(-8,0,4,CONCRETE:7,65,quark:iron_plate,10,quark:iron_plate:1,10,STAINED_CLAY:15,10,STAINED_CLAY:9,100)
RandomBlock(-8,0,5,CONCRETE:7,65,quark:iron_plate,10,quark:iron_plate:1,10,STAINED_CLAY:15,10,STAINED_CLAY:9,100)
RandomBlock(-8,0,6,CONCRETE:7,65,quark:iron_plate,10,quark:iron_plate:1,10,STAINED_CLAY:15,10,STAINED_CLAY:9,100)
RandomBlock(-8,0,7,CONCRETE:7,65,quark:iron_plate,10,quark:iron_plate:1,10,STAINED_CLAY:15,10,STAINED_CLAY:9,100)
RandomBlock(-8,0,8,CONCRETE:7,65,quark:iron_plate,10,quark:iron_plate:1,10,STAINED_CLAY:15,10,STAINED_CLAY:9,100)
RandomBlock(-8,1,-7,CONCRETE:7,65,quark:iron_plate,10,quark:iron_plate:1,10,STAINED_CLAY:15,10,STAINED_CLAY:9,100)
RandomBlock(-8,1,-6,CONCRETE:7,65,quark:iron_plate,10,quark:iron_plate:1,10,STAINED_CLAY:15,10,STAINED_CLAY:9,100)
RandomBlock(-8,1,-5,CONCRETE:7,65,quark:iron_plate,10,quark:iron_plate:1,10,STAINED_CLAY:15,10,STAINED_CLAY:9,100)
RandomBlock(-8,1,-4,CONCRETE:7,65,quark:iron_plate,10,quark:iron_plate:1,10,STAINED_CLAY:15,10,STAINED_CLAY:9,100)
RandomBlock(-8,1,-3,CONCRETE:7,65,quark:iron_plate,10,quark:iron_plate:1,10,STAINED_CLAY:15,10,STAINED_CLAY:9,100)
RandomBlock(-8,1,-2,CONCRETE:7,65,quark:iron_plate,10,quark:iron_plate:1,10,STAINED_CLAY:15,10,STAINED_CLAY:9,100)
RandomBlock(-8,1,-1,CONCRETE:7,65,quark:iron_plate,10,quark:iron_plate:1,10,STAINED_CLAY:15,10,STAINED_CLAY:9,100)
RandomBlock(-8,1,0,CONCRETE:7,65,quark:iron_plate,10,quark:iron_plate:1,10,STAINED_CLAY:15,10,STAINED_CLAY:9,100)
RandomBlock(-8,1,1,CONCRETE:7,65,quark:iron_plate,10,quark:iron_plate:1,10,STAINED_CLAY:15,10,STAINED_CLAY:9,100)
RandomBlock(-8,1,2,CONCRETE:7,65,quark:iron_plate,10,quark:iron_plate:1,10,STAINED_CLAY:15,10,STAINED_CLAY:9,100)
RandomBlock(-8,1,3,CONCRETE:7,65,quark:iron_plate,10,quark:iron_plate:1,10,STAINED_CLAY:15,10,STAINED_CLAY:9,100)
RandomBlock(-8,1,4,CONCRETE:7,65,quark:iron_plate,10,quark:iron_plate:1,10,STAINED_CLAY:15,10,STAINED_CLAY:9,100)
RandomBlock(-8,1,5,CONCRETE:7,65,quark:iron_plate,10,quark:iron_plate:1,10,STAINED_CLAY:15,10,STAINED_CLAY:9,100)
RandomBlock(-8,1,6,CONCRETE:7,65,quark:iron_plate,10,quark:iron_plate:1,10,STAINED_CLAY:15,10,STAINED_CLAY:9,100)
RandomBlock(-8,1,7,CONCRETE:7,65,quark:iron_plate,10,quark:iron_plate:1,10,STAINED_CLAY:15,10,STAINED_CLAY:9,100)
RandomBlock(-8,1,8,CONCRETE:7,65,quark:iron_plate,10,quark:iron_plate:1,10,STAINED_CLAY:15,10,STAINED_CLAY:9,100)
RandomBlock(-8,2,-7,CONCRETE:7,65,quark:iron_plate,10,quark:iron_plate:1,10,STAINED_CLAY:15,10,STAINED_CLAY:9,100)
RandomBlock(-8,2,-6,CONCRETE:7,65,quark:iron_plate,10,quark:iron_plate:1,10,STAINED_CLAY:15,10,STAINED_CLAY:9,100)
RandomBlock(-8,2,-5,CONCRETE:7,65,quark:iron_plate,10,quark:iron_plate:1,10,STAINED_CLAY:15,10,STAINED_CLAY:9,100)
RandomBlock(-8,2,-4,CONCRETE:7,65,quark:iron_plate,10,quark:iron_plate:1,10,STAINED_CLAY:15,10,STAINED_CLAY:9,100)
RandomBlock(-8,2,-3,CONCRETE:7,65,quark:iron_plate,10,quark:iron_plate:1,10,STAINED_CLAY:15,10,STAINED_CLAY:9,100)
RandomBlock(-8,2,-2,CONCRETE:7,65,quark:iron_plate,10,quark:iron_plate:1,10,STAINED_CLAY:15,10,STAINED_CLAY:9,100)
RandomBlock(-8,2,-1,CONCRETE:7,65,quark:iron_plate,10,quark:iron_plate:1,10,STAINED_CLAY:15,10,STAINED_CLAY:9,100)
RandomBlock(-8,2,0,CONCRETE:7,65,quark:iron_plate,10,quark:iron_plate:1,10,STAINED_CLAY:15,10,STAINED_CLAY:9,100)
RandomBlock(-8,2,1,CONCRETE:7,65,quark:iron_plate,10,quark:iron_plate:1,10,STAINED_CLAY:15,10,STAINED_CLAY:9,100)
RandomBlock(-8,2,2,CONCRETE:7,65,quark:iron_plate,10,quark:iron_plate:1,10,STAINED_CLAY:15,10,STAINED_CLAY:9,100)
RandomBlock(-8,2,3,CONCRETE:7,65,quark:iron_plate,10,quark:iron_plate:1,10,STAINED_CLAY:15,10,STAINED_CLAY:9,100)
RandomBlock(-8,2,4,CONCRETE:7,65,quark:iron_plate,10,quark:iron_plate:1,10,STAINED_CLAY:15,10,STAINED_CLAY:9,100)
RandomBlock(-8,2,5,CONCRETE:7,65,quark:iron_plate,10,quark:iron_plate:1,10,STAINED_CLAY:15,10,STAINED_CLAY:9,100)
RandomBlock(-8,2,6,CONCRETE:7,65,quark:iron_plate,10,quark:iron_plate:1,10,STAINED_CLAY:15,10,STAINED_CLAY:9,100)
RandomBlock(-8,2,7,CONCRETE:7,65,quark:iron_plate,10,quark:iron_plate:1,10,STAINED_CLAY:15,10,STAINED_CLAY:9,100)
RandomBlock(-8,2,8,CONCRETE:7,65,quark:iron_plate,10,quark:iron_plate:1,10,STAINED_CLAY:15,10,STAINED_CLAY:9,100)
RandomBlock(-8,3,-7,CONCRETE:7,65,quark:iron_plate,10,quark:iron_plate:1,10,STAINED_CLAY:15,10,STAINED_CLAY:9,100)
RandomBlock(-8,3,-6,CONCRETE:7,65,quark:iron_plate,10,quark:iron_plate:1,10,STAINED_CLAY:15,10,STAINED_CLAY:9,100)
RandomBlock(-8,3,-5,CONCRETE:7,65,quark:iron_plate,10,quark:iron_plate:1,10,STAINED_CLAY:15,10,STAINED_CLAY:9,100)
RandomBlock(-8,3,-4,CONCRETE:7,65,quark:iron_plate,10,quark:iron_plate:1,10,STAINED_CLAY:15,10,STAINED_CLAY:9,100)
RandomBlock(-8,3,-3,CONCRETE:7,65,quark:iron_plate,10,quark:iron_plate:1,10,STAINED_CLAY:15,10,STAINED_CLAY:9,100)
RandomBlock(-8,3,-2,CONCRETE:7,65,quark:iron_plate,10,quark:iron_plate:1,10,STAINED_CLAY:15,10,STAINED_CLAY:9,100)
RandomBlock(-8,3,-1,CONCRETE:7,65,quark:iron_plate,10,quark:iron_plate:1,10,STAINED_CLAY:15,10,STAINED_CLAY:9,100)
RandomBlock(-8,3,0,CONCRETE:7,65,quark:iron_plate,10,quark:iron_plate:1,10,STAINED_CLAY:15,10,STAINED_CLAY:9,100)
RandomBlock(-8,3,1,CONCRETE:7,65,quark:iron_plate,10,quark:iron_plate:1,10,STAINED_CLAY:15,10,STAINED_CLAY:9,100)
RandomBlock(-8,3,2,CONCRETE:7,65,quark:iron_plate,10,quark:iron_plate:1,10,STAINED_CLAY:15,10,STAINED_CLAY:9,100)
RandomBlock(-8,3,3,CONCRETE:7,65,quark:iron_plate,10,quark:iron_plate:1,10,STAINED_CLAY:15,10,STAINED_CLAY:9,100)
RandomBlock(-8,3,4,CONCRETE:7,65,quark:iron_plate,10,quark:iron_plate:1,10,STAINED_CLAY:15,10,STAINED_CLAY:9,100)
RandomBlock(-8,3,5,CONCRETE:7,65,quark:iron_plate,10,quark:iron_plate:1,10,STAINED_CLAY:15,10,STAINED_CLAY:9,100)
RandomBlock(-8,3,6,CONCRETE:7,65,quark:iron_plate,10,quark:iron_plate:1,10,STAINED_CLAY:15,10,STAINED_CLAY:9,100)
RandomBlock(-8,3,7,CONCRETE:7,65,quark:iron_plate,10,quark:iron_plate:1,10,STAINED_CLAY:15,10,STAINED_CLAY:9,100)
RandomBlock(-8,3,8,CONCRETE:7,65,quark:iron_plate,10,quark:iron_plate:1,10,STAINED_CLAY:15,10,STAINED_CLAY:9,100)
RandomBlock(-8,4,-7,CONCRETE:7,65,quark:iron_plate,10,quark:iron_plate:1,10,STAINED_CLAY:15,10,STAINED_CLAY:9,100)
RandomBlock(-8,4,-6,CONCRETE:7,65,quark:iron_plate,10,quark:iron_plate:1,10,STAINED_CLAY:15,10,STAINED_CLAY:9,100)
RandomBlock(-8,4,-5,CONCRETE:7,65,quark:iron_plate,10,quark:iron_plate:1,10,STAINED_CLAY:15,10,STAINED_CLAY:9,100)
RandomBlock(-8,4,-4,CONCRETE:7,65,quark:iron_plate,10,quark:iron_plate:1,10,STAINED_CLAY:15,10,STAINED_CLAY:9,100)
RandomBlock(-8,4,-3,CONCRETE:7,65,quark:iron_plate,10,quark:iron_plate:1,10,STAINED_CLAY:15,10,STAINED_CLAY:9,100)
RandomBlock(-8,4,-2,CONCRETE:7,65,quark:iron_plate,10,quark:iron_plate:1,10,STAINED_CLAY:15,10,STAINED_CLAY:9,100)
RandomBlock(-8,4,-1,CONCRETE:7,65,quark:iron_plate,10,quark:iron_plate:1,10,STAINED_CLAY:15,10,STAINED_CLAY:9,100)
RandomBlock(-8,4,0,CONCRETE:7,65,quark:iron_plate,10,quark:iron_plate:1,10,STAINED_CLAY:15,10,STAINED_CLAY:9,100)
RandomBlock(-8,4,1,CONCRETE:7,65,quark:iron_plate,10,quark:iron_plate:1,10,STAINED_CLAY:15,10,STAINED_CLAY:9,100)
RandomBlock(-8,4,2,CONCRETE:7,65,quark:iron_plate,10,quark:iron_plate:1,10,STAINED_CLAY:15,10,STAINED_CLAY:9,100)
RandomBlock(-8,4,3,CONCRETE:7,65,quark:iron_plate,10,quark:iron_plate:1,10,STAINED_CLAY:15,10,STAINED_CLAY:9,100)
RandomBlock(-8,4,4,CONCRETE:7,65,quark:iron_plate,10,quark:iron_plate:1,10,STAINED_CLAY:15,10,STAINED_CLAY:9,100)
RandomBlock(-8,4,5,CONCRETE:7,65,quark:iron_plate,10,quark:iron_plate:1,10,STAINED_CLAY:15,10,STAINED_CLAY:9,100)
RandomBlock(-8,4,6,CONCRETE:7,65,quark:iron_plate,10,quark:iron_plate:1,10,STAINED_CLAY:15,10,STAINED_CLAY:9,100)
RandomBlock(-8,4,7,CONCRETE:7,65,quark:iron_plate,10,quark:iron_plate:1,10,STAINED_CLAY:15,10,STAINED_CLAY:9,100)
RandomBlock(-8,4,8,CONCRETE:7,65,quark:iron_plate,10,quark:iron_plate:1,10,STAINED_CLAY:15,10,STAINED_CLAY:9,100)
RandomBlock(-8,5,-7,CONCRETE:7,65,quark:iron_plate,10,quark:iron_plate:1,10,STAINED_CLAY:15,10,STAINED_CLAY:9,100)
RandomBlock(-8,5,-6,CONCRETE:7,65,quark:iron_plate,10,quark:iron_plate:1,10,STAINED_CLAY:15,10,STAINED_CLAY:9,100)
RandomBlock(-8,5,-5,CONCRETE:7,65,quark:iron_plate,10,quark:iron_plate:1,10,STAINED_CLAY:15,10,STAINED_CLAY:9,100)
RandomBlock(-8,5,-4,CONCRETE:7,65,quark:iron_plate,10,quark:iron_plate:1,10,STAINED_CLAY:15,10,STAINED_CLAY:9,100)
RandomBlock(-8,5,-3,CONCRETE:7,65,quark:iron_plate,10,quark:iron_plate:1,10,STAINED_CLAY:15,10,STAINED_CLAY:9,100)
RandomBlock(-8,5,-2,CONCRETE:7,65,quark:iron_plate,10,quark:iron_plate:1,10,STAINED_CLAY:15,10,STAINED_CLAY:9,100)
RandomBlock(-8,5,-1,CONCRETE:7,65,quark:iron_plate,10,quark:iron_plate:1,10,STAINED_CLAY:15,10,STAINED_CLAY:9,100)
RandomBlock(-8,5,0,CONCRETE:7,65,quark:iron_plate,10,quark:iron_plate:1,10,STAINED_CLAY:15,10,STAINED_CLAY:9,100)
RandomBlock(-8,5,1,CONCRETE:7,65,quark:iron_plate,10,quark:iron_plate:1,10,STAINED_CLAY:15,10,STAINED_CLAY:9,100)
RandomBlock(-8,5,2,CONCRETE:7,65,quark:iron_plate,10,quark:iron_plate:1,10,STAINED_CLAY:15,10,STAINED_CLAY:9,100)
RandomBlock(-8,5,3,CONCRETE:7,65,quark:iron_plate,10,quark:iron_plate:1,10,STAINED_CLAY:15,10,STAINED_CLAY:9,100)
RandomBlock(-8,5,4,CONCRETE:7,65,quark:iron_plate,10,quark:iron_plate:1,10,STAINED_CLAY:15,10,STAINED_CLAY:9,100)
RandomBlock(-8,5,5,CONCRETE:7,65,quark:iron_plate,10,quark:iron_plate:1,10,STAINED_CLAY:15,10,STAINED_CLAY:9,100)
RandomBlock(-8,5,6,CONCRETE:7,65,quark:iron_plate,10,quark:iron_plate:1,10,STAINED_CLAY:15,10,STAINED_CLAY:9,100)
RandomBlock(-8,5,7,CONCRETE:7,65,quark:iron_plate,10,quark:iron_plate:1,10,STAINED_CLAY:15,10,STAINED_CLAY:9,100)
RandomBlock(-8,5,8,CONCRETE:7,65,quark:iron_plate,10,quark:iron_plate:1,10,STAINED_CLAY:15,10,STAINED_CLAY:9,100)
RandomBlock(-8,6,-7,CONCRETE:7,65,quark:iron_plate,10,quark:iron_plate:1,10,STAINED_CLAY:15,10,STAINED_CLAY:9,100)
RandomBlock(-8,6,-6,CONCRETE:7,65,quark:iron_plate,10,quark:iron_plate:1,10,STAINED_CLAY:15,10,STAINED_CLAY:9,100)
RandomBlock(-8,6,-5,CONCRETE:7,65,quark:iron_plate,10,quark:iron_plate:1,10,STAINED_CLAY:15,10,STAINED_CLAY:9,100)
RandomBlock(-8,6,-4,CONCRETE:7,65,quark:iron_plate,10,quark:iron_plate:1,10,STAINED_CLAY:15,10,STAINED_CLAY:9,100)
RandomBlock(-8,6,-3,CONCRETE:7,65,quark:iron_plate,10,quark:iron_plate:1,10,STAINED_CLAY:15,10,STAINED_CLAY:9,100)
RandomBlock(-8,6,-2,CONCRETE:7,65,quark:iron_plate,10,quark:iron_plate:1,10,STAINED_CLAY:15,10,STAINED_CLAY:9,100)
RandomBlock(-8,6,-1,CONCRETE:7,65,quark:iron_plate,10,quark:iron_plate:1,10,STAINED_CLAY:15,10,STAINED_CLAY:9,100)
RandomBlock(-8,6,0,CONCRETE:7,65,quark:iron_plate,10,quark:iron_plate:1,10,STAINED_CLAY:15,10,STAINED_CLAY:9,100)
RandomBlock(-8,6,1,CONCRETE:7,65,quark:iron_plate,10,quark:iron_plate:1,10,STAINED_CLAY:15,10,STAINED_CLAY:9,100)
RandomBlock(-8,6,2,CONCRETE:7,65,quark:iron_plate,10,quark:iron_plate:1,10,STAINED_CLAY:15,10,STAINED_CLAY:9,100)
RandomBlock(-8,6,3,CONCRETE:7,65,quark:iron_plate,10,quark:iron_plate:1,10,STAINED_CLAY:15,10,STAINED_CLAY:9,100)
RandomBlock(-8,6,4,CONCRETE:7,65,quark:iron_plate,10,quark:iron_plate:1,10,STAINED_CLAY:15,10,STAINED_CLAY:9,100)
RandomBlock(-8,6,5,CONCRETE:7,65,quark:iron_plate,10,quark:iron_plate:1,10,STAINED_CLAY:15,10,STAINED_CLAY:9,100)
RandomBlock(-8,6,6,CONCRETE:7,65,quark:iron_plate,10,quark:iron_plate:1,10,STAINED_CLAY:15,10,STAINED_CLAY:9,100)
RandomBlock(-8,6,7,CONCRETE:7,65,quark:iron_plate,10,quark:iron_plate:1,10,STAINED_CLAY:15,10,STAINED_CLAY:9,100)
RandomBlock(-8,6,8,CONCRETE:7,65,quark:iron_plate,10,quark:iron_plate:1,10,STAINED_CLAY:15,10,STAINED_CLAY:9,100)
RandomBlock(-8,7,-7,CONCRETE:7,65,quark:iron_plate,10,quark:iron_plate:1,10,STAINED_CLAY:15,10,STAINED_CLAY:9,100)
RandomBlock(-8,7,-6,CONCRETE:7,65,quark:iron_plate,10,quark:iron_plate:1,10,STAINED_CLAY:15,10,STAINED_CLAY:9,100)
RandomBlock(-8,7,-5,CONCRETE:7,65,quark:iron_plate,10,quark:iron_plate:1,10,STAINED_CLAY:15,10,STAINED_CLAY:9,100)
RandomBlock(-8,7,-4,CONCRETE:7,65,quark:iron_plate,10,quark:iron_plate:1,10,STAINED_CLAY:15,10,STAINED_CLAY:9,100)
RandomBlock(-8,7,-3,CONCRETE:7,65,quark:iron_plate,10,quark:iron_plate:1,10,STAINED_CLAY:15,10,STAINED_CLAY:9,100)
RandomBlock(-8,7,-2,CONCRETE:7,65,quark:iron_plate,10,quark:iron_plate:1,10,STAINED_CLAY:15,10,STAINED_CLAY:9,100)
RandomBlock(-8,7,-1,CONCRETE:7,65,quark:iron_plate,10,quark:iron_plate:1,10,STAINED_CLAY:15,10,STAINED_CLAY:9,100)
RandomBlock(-8,7,0,CONCRETE:7,65,quark:iron_plate,10,quark:iron_plate:1,10,STAINED_CLAY:15,10,STAINED_CLAY:9,100)
RandomBlock(-8,7,1,CONCRETE:7,65,quark:iron_plate,10,quark:iron_plate:1,10,STAINED_CLAY:15,10,STAINED_CLAY:9,100)
RandomBlock(-8,7,2,CONCRETE:7,65,quark:iron_plate,10,quark:iron_plate:1,10,STAINED_CLAY:15,10,STAINED_CLAY:9,100)
RandomBlock(-8,7,3,CONCRETE:7,65,quark:iron_plate,10,quark:iron_plate:1,10,STAINED_CLAY:15,10,STAINED_CLAY:9,100)
RandomBlock(-8,7,4,CONCRETE:7,65,quark:iron_plate,10,quark:iron_plate:1,10,STAINED_CLAY:15,10,STAINED_CLAY:9,100)
RandomBlock(-8,7,5,CONCRETE:7,65,quark:iron_plate,10,quark:iron_plate:1,10,STAINED_CLAY:15,10,STAINED_CLAY:9,100)
RandomBlock(-8,7,6,CONCRETE:7,65,quark:iron_plate,10,quark:iron_plate:1,10,STAINED_CLAY:15,10,STAINED_CLAY:9,100)
RandomBlock(-8,7,7,CONCRETE:7,65,quark:iron_plate,10,quark:iron_plate:1,10,STAINED_CLAY:15,10,STAINED_CLAY:9,100)
RandomBlock(-8,7,8,CONCRETE:7,65,quark:iron_plate,10,quark:iron_plate:1,10,STAINED_CLAY:15,10,STAINED_CLAY:9,100)
Block(-8,8,-7,DIRT:0)
Block(-8,8,-6,DIRT:0)
Block(-8,8,-5,DIRT:0)
Block(-8,8,-4,DIRT:0)
Block(-8,8,-3,DIRT:0)
Block(-8,8,-2,DIRT:0)
Block(-8,8,-1,DIRT:0)
Block(-8,8,0,DIRT:0)
Block(-8,8,1,DIRT:0)
Block(-8,8,2,DIRT:0)
Block(-8,8,3,DIRT:0)
Block(-8,8,4,DIRT:0)
Block(-8,8,5,DIRT:0)
Block(-8,8,6,DIRT:0)
Block(-8,8,7,DIRT:0)
RandomBlock(-8,8,8,CONCRETE:7,65,quark:iron_plate,10,quark:iron_plate:1,10,STAINED_CLAY:15,10,STAINED_CLAY:9,100)
Block(-8,9,-7,DIRT:0)
Block(-8,9,-6,DIRT:0)
Block(-8,9,-5,DIRT:0)
Block(-8,9,-4,DIRT:0)
Block(-8,9,-3,DIRT:0)
Block(-8,9,-2,DIRT:0)
Block(-8,9,-1,DIRT:0)
Block(-8,9,0,DIRT:0)
Block(-8,9,1,DIRT:0)
Block(-8,9,2,DIRT:0)
Block(-8,9,3,DIRT:0)
Block(-8,9,4,DIRT:0)
Block(-8,9,5,DIRT:0)
Block(-8,9,6,DIRT:0)
Block(-8,9,7,DIRT:0)
RandomBlock(-8,9,8,CONCRETE:7,65,quark:iron_plate,10,quark:iron_plate:1,10,STAINED_CLAY:15,10,STAINED_CLAY:9,100)
Block(-8,10,-7,STONE:0)
Block(-8,10,-6,STONE:0)
Block(-8,10,-5,SAND:0)
Block(-8,10,-4,DIRT:0)
Block(-8,10,-3,DIRT:0)
Block(-8,10,-2,DIRT:0)
Block(-8,10,-1,DIRT:0)
Block(-8,10,0,DIRT:0)
Block(-8,10,1,DIRT:0)
Block(-8,10,2,DIRT:0)
Block(-8,10,3,DIRT:0)
Block(-8,10,4,DIRT:0)
Block(-8,10,5,DIRT:0)
Block(-8,10,6,DIRT:0)
Block(-8,10,7,DIRT:0)
RandomBlock(-8,10,8,CONCRETE:7,65,quark:iron_plate,10,quark:iron_plate:1,10,STAINED_CLAY:15,10,STAINED_CLAY:9,100)
Block(-8,11,-7,DIRT:0)
Block(-8,11,-6,GRAVEL:0)
Block(-8,11,-5,GRAVEL:0)
Block(-8,11,-4,GRAVEL:0)
Block(-8,11,-3,DIRT:0)
Block(-8,11,-2,DIRT:0)
Block(-8,11,-1,DIRT:0)
Block(-8,11,0,DIRT:0)
Block(-8,11,1,DIRT:0)
Block(-8,11,2,DIRT:0)
Block(-8,11,3,DIRT:0)
Block(-8,11,4,DIRT:0)
Block(-8,11,5,DIRT:0)
Block(-8,11,6,DIRT:0)
Block(-8,11,7,DIRT:0)
RandomBlock(-8,11,8,CONCRETE:7,65,quark:iron_plate,10,quark:iron_plate:1,10,STAINED_CLAY:15,10,STAINED_CLAY:9,100)
Block(-8,12,-7,STONE:5)
Block(-8,12,-6,COBBLESTONE:0)
Block(-8,12,-5,SAND:0)
Block(-8,12,-4,DIRT:0)
Block(-8,12,-3,GRAVEL:0)
Block(-8,12,-2,STONE:3)
Block(-8,12,-1,GRAVEL:0)
Block(-8,12,0,GRAVEL:0)
Block(-8,12,1,STONE:3)
Block(-8,12,2,DIRT:0)
Block(-8,12,3,DIRT:0)
Block(-8,12,4,DIRT:0)
Block(-8,12,5,DIRT:0)
Block(-8,12,6,DIRT:0)
Block(-8,12,7,DIRT:0)
RandomBlock(-8,12,8,CONCRETE:7,65,quark:iron_plate,10,quark:iron_plate:1,10,STAINED_CLAY:15,10,STAINED_CLAY:9,100)
Block(-8,13,-7,GRAVEL:0)
Block(-8,13,-6,DIRT:0)
Block(-8,13,-5,SAND:0)
Block(-8,13,-4,GRAVEL:0)
Block(-8,13,-3,STONE:1)
Block(-8,13,-2,COBBLESTONE:0)
Block(-8,13,-1,DIRT:0)
Block(-8,13,0,DIRT:0)
Block(-8,13,1,STONE:0)
Block(-8,13,2,DIRT:0)
Block(-8,13,3,DIRT:0)
Block(-8,13,4,DIRT:0)
Block(-8,13,5,DIRT:0)
Block(-8,13,6,DIRT:0)
Block(-8,13,7,DIRT:0)
RandomBlock(-8,13,8,CONCRETE:7,65,quark:iron_plate,10,quark:iron_plate:1,10,STAINED_CLAY:15,10,STAINED_CLAY:9,100)
Block(-8,14,-3,DIRT:0)
Block(-8,14,-2,GRAVEL:0)
Block(-8,14,-1,COBBLESTONE:0)
Block(-8,14,0,GRAVEL:0)
Block(-8,14,1,STONE:1)
Block(-8,14,2,GRAVEL:0)
Block(-8,14,3,STONE:0)
Block(-8,14,4,DIRT:0)
Block(-8,14,5,DIRT:0)
Block(-8,14,6,DIRT:0)
Block(-8,14,7,DIRT:0)
RandomBlock(-8,14,8,CONCRETE:7,65,quark:iron_plate,10,quark:iron_plate:1,10,STAINED_CLAY:15,10,STAINED_CLAY:9,100)
Block(-8,15,-2,DIRT:0)
Block(-8,15,-1,DIRT:0)
Block(-8,15,0,STONE:5)
Block(-8,15,1,STONE:1)
Block(-8,15,2,STONE:0)
Block(-8,15,3,STONE:0)
Block(-8,15,4,DIRT:0)
Block(-8,15,5,DIRT:0)
Block(-8,15,6,DIRT:0)
Block(-8,15,7,DIRT:0)
RandomBlock(-8,15,8,CONCRETE:7,65,quark:iron_plate,10,quark:iron_plate:1,10,STAINED_CLAY:15,10,STAINED_CLAY:9,100)
Block(-8,16,1,COBBLESTONE:0)
Block(-8,16,2,STONE:0)
Block(-8,16,3,DIRT:0)
Block(-8,16,4,DIRT:0)
Block(-8,16,5,DIRT:0)
Block(-8,16,6,DIRT:0)
Block(-8,16,7,DIRT:0)
RandomBlock(-8,16,8,CONCRETE:7,65,quark:iron_plate,10,quark:iron_plate:1,10,STAINED_CLAY:15,10,STAINED_CLAY:9,100)
Block(-8,17,2,COBBLESTONE:0)
Block(-8,17,3,DOUBLE_STEP:0)
Block(-8,17,4,STONE:5)
Block(-8,17,5,GRAVEL:0)
Block(-8,17,6,GRASS:0)
Block(-8,17,7,DOUBLE_STEP:0)
RandomBlock(-8,17,8,CONCRETE:7,65,quark:iron_plate,10,quark:iron_plate:1,10,STAINED_CLAY:15,10,STAINED_CLAY:9,100)
Block(-8,18,3,COBBLESTONE_STAIRS:1)
RandomBlock(-7,0,-7,CONCRETE:7,65,quark:iron_plate,10,quark:iron_plate:1,10,STAINED_CLAY:15,10,STAINED_CLAY:9,100)
RandomBlock(-7,0,-6,CONCRETE:7,65,quark:iron_plate,10,quark:iron_plate:1,10,STAINED_CLAY:15,10,STAINED_CLAY:9,100)
RandomBlock(-7,0,-5,CONCRETE:7,65,quark:iron_plate,10,quark:iron_plate:1,10,STAINED_CLAY:15,10,STAINED_CLAY:9,100)
RandomBlock(-7,0,-4,CONCRETE:7,65,quark:iron_plate,10,quark:iron_plate:1,10,STAINED_CLAY:15,10,STAINED_CLAY:9,100)
RandomBlock(-7,0,-3,CONCRETE:7,65,quark:iron_plate,10,quark:iron_plate:1,10,STAINED_CLAY:15,10,STAINED_CLAY:9,100)
RandomBlock(-7,0,-2,CONCRETE:7,65,quark:iron_plate,10,quark:iron_plate:1,10,STAINED_CLAY:15,10,STAINED_CLAY:9,100)
RandomBlock(-7,0,-1,CONCRETE:7,65,quark:iron_plate,10,quark:iron_plate:1,10,STAINED_CLAY:15,10,STAINED_CLAY:9,100)
RandomBlock(-7,0,0,CONCRETE:7,65,quark:iron_plate,10,quark:iron_plate:1,10,STAINED_CLAY:15,10,STAINED_CLAY:9,100)
RandomBlock(-7,0,1,CONCRETE:7,65,quark:iron_plate,10,quark:iron_plate:1,10,STAINED_CLAY:15,10,STAINED_CLAY:9,100)
RandomBlock(-7,0,2,CONCRETE:7,65,quark:iron_plate,10,quark:iron_plate:1,10,STAINED_CLAY:15,10,STAINED_CLAY:9,100)
RandomBlock(-7,0,3,CONCRETE:7,65,quark:iron_plate,10,quark:iron_plate:1,10,STAINED_CLAY:15,10,STAINED_CLAY:9,100)
RandomBlock(-7,0,4,CONCRETE:7,65,quark:iron_plate,10,quark:iron_plate:1,10,STAINED_CLAY:15,10,STAINED_CLAY:9,100)
RandomBlock(-7,0,5,CONCRETE:7,65,quark:iron_plate,10,quark:iron_plate:1,10,STAINED_CLAY:15,10,STAINED_CLAY:9,100)
RandomBlock(-7,0,6,CONCRETE:7,65,quark:iron_plate,10,quark:iron_plate:1,10,STAINED_CLAY:15,10,STAINED_CLAY:9,100)
RandomBlock(-7,0,7,CONCRETE:7,65,quark:iron_plate,10,quark:iron_plate:1,10,STAINED_CLAY:15,10,STAINED_CLAY:9,100)
RandomBlock(-7,0,8,CONCRETE:7,65,quark:iron_plate,10,quark:iron_plate:1,10,STAINED_CLAY:15,10,STAINED_CLAY:9,100)
RandomBlock(-7,1,-7,CONCRETE:7,65,quark:iron_plate,10,quark:iron_plate:1,10,STAINED_CLAY:15,10,STAINED_CLAY:9,100)
RandomBlock(-7,1,-6,CONCRETE:7,65,quark:iron_plate,10,quark:iron_plate:1,10,STAINED_CLAY:15,10,STAINED_CLAY:9,100)
RandomBlock(-7,1,-5,CONCRETE:7,65,quark:iron_plate,10,quark:iron_plate:1,10,STAINED_CLAY:15,10,STAINED_CLAY:9,100)
RandomBlock(-7,1,-4,CONCRETE:7,65,quark:iron_plate,10,quark:iron_plate:1,10,STAINED_CLAY:15,10,STAINED_CLAY:9,100)
RandomBlock(-7,1,-3,CONCRETE:7,65,quark:iron_plate,10,quark:iron_plate:1,10,STAINED_CLAY:15,10,STAINED_CLAY:9,100)
RandomBlock(-7,1,-2,CONCRETE:7,65,quark:iron_plate,10,quark:iron_plate:1,10,STAINED_CLAY:15,10,STAINED_CLAY:9,100)
RandomBlock(-7,1,-1,CONCRETE:7,65,quark:iron_plate,10,quark:iron_plate:1,10,STAINED_CLAY:15,10,STAINED_CLAY:9,100)
RandomBlock(-7,1,0,CONCRETE:7,65,quark:iron_plate,10,quark:iron_plate:1,10,STAINED_CLAY:15,10,STAINED_CLAY:9,100)
RandomBlock(-7,1,1,CONCRETE:7,65,quark:iron_plate,10,quark:iron_plate:1,10,STAINED_CLAY:15,10,STAINED_CLAY:9,100)
RandomBlock(-7,1,2,CONCRETE:7,65,quark:iron_plate,10,quark:iron_plate:1,10,STAINED_CLAY:15,10,STAINED_CLAY:9,100)
RandomBlock(-7,1,3,CONCRETE:7,65,quark:iron_plate,10,quark:iron_plate:1,10,STAINED_CLAY:15,10,STAINED_CLAY:9,100)
RandomBlock(-7,1,4,CONCRETE:7,65,quark:iron_plate,10,quark:iron_plate:1,10,STAINED_CLAY:15,10,STAINED_CLAY:9,100)
RandomBlock(-7,1,5,CONCRETE:7,65,quark:iron_plate,10,quark:iron_plate:1,10,STAINED_CLAY:15,10,STAINED_CLAY:9,100)
RandomBlock(-7,1,6,CONCRETE:7,65,quark:iron_plate,10,quark:iron_plate:1,10,STAINED_CLAY:15,10,STAINED_CLAY:9,100)
RandomBlock(-7,1,7,CONCRETE:7,65,quark:iron_plate,10,quark:iron_plate:1,10,STAINED_CLAY:15,10,STAINED_CLAY:9,100)
RandomBlock(-7,1,8,CONCRETE:7,65,quark:iron_plate,10,quark:iron_plate:1,10,STAINED_CLAY:15,10,STAINED_CLAY:9,100)
RandomBlock(-7,2,-7,CONCRETE:7,65,quark:iron_plate,10,quark:iron_plate:1,10,STAINED_CLAY:15,10,STAINED_CLAY:9,100)
RandomBlock(-7,2,-6,CONCRETE:7,65,quark:iron_plate,10,quark:iron_plate:1,10,STAINED_CLAY:15,10,STAINED_CLAY:9,100)
RandomBlock(-7,2,-5,CONCRETE:7,65,quark:iron_plate,10,quark:iron_plate:1,10,STAINED_CLAY:15,10,STAINED_CLAY:9,100)
RandomBlock(-7,2,-4,CONCRETE:7,65,quark:iron_plate,10,quark:iron_plate:1,10,STAINED_CLAY:15,10,STAINED_CLAY:9,100)
RandomBlock(-7,2,-3,CONCRETE:7,65,quark:iron_plate,10,quark:iron_plate:1,10,STAINED_CLAY:15,10,STAINED_CLAY:9,100)
RandomBlock(-7,2,-2,CONCRETE:7,65,quark:iron_plate,10,quark:iron_plate:1,10,STAINED_CLAY:15,10,STAINED_CLAY:9,100)
RandomBlock(-7,2,-1,CONCRETE:7,65,quark:iron_plate,10,quark:iron_plate:1,10,STAINED_CLAY:15,10,STAINED_CLAY:9,100)
RandomBlock(-7,2,0,CONCRETE:7,65,quark:iron_plate,10,quark:iron_plate:1,10,STAINED_CLAY:15,10,STAINED_CLAY:9,100)
RandomBlock(-7,2,1,CONCRETE:7,65,quark:iron_plate,10,quark:iron_plate:1,10,STAINED_CLAY:15,10,STAINED_CLAY:9,100)
RandomBlock(-7,2,2,CONCRETE:7,65,quark:iron_plate,10,quark:iron_plate:1,10,STAINED_CLAY:15,10,STAINED_CLAY:9,100)
RandomBlock(-7,2,3,CONCRETE:7,65,quark:iron_plate,10,quark:iron_plate:1,10,STAINED_CLAY:15,10,STAINED_CLAY:9,100)
RandomBlock(-7,2,4,CONCRETE:7,65,quark:iron_plate,10,quark:iron_plate:1,10,STAINED_CLAY:15,10,STAINED_CLAY:9,100)
RandomBlock(-7,2,5,CONCRETE:7,65,quark:iron_plate,10,quark:iron_plate:1,10,STAINED_CLAY:15,10,STAINED_CLAY:9,100)
RandomBlock(-7,2,6,CONCRETE:7,65,quark:iron_plate,10,quark:iron_plate:1,10,STAINED_CLAY:15,10,STAINED_CLAY:9,100)
RandomBlock(-7,2,7,CONCRETE:7,65,quark:iron_plate,10,quark:iron_plate:1,10,STAINED_CLAY:15,10,STAINED_CLAY:9,100)
RandomBlock(-7,2,8,CONCRETE:7,65,quark:iron_plate,10,quark:iron_plate:1,10,STAINED_CLAY:15,10,STAINED_CLAY:9,100)
RandomBlock(-7,3,-7,CONCRETE:7,65,quark:iron_plate,10,quark:iron_plate:1,10,STAINED_CLAY:15,10,STAINED_CLAY:9,100)
RandomBlock(-7,3,-6,CONCRETE:7,65,quark:iron_plate,10,quark:iron_plate:1,10,STAINED_CLAY:15,10,STAINED_CLAY:9,100)
RandomBlock(-7,3,-5,CONCRETE:7,65,quark:iron_plate,10,quark:iron_plate:1,10,STAINED_CLAY:15,10,STAINED_CLAY:9,100)
RandomBlock(-7,3,-4,CONCRETE:7,65,quark:iron_plate,10,quark:iron_plate:1,10,STAINED_CLAY:15,10,STAINED_CLAY:9,100)
RandomBlock(-7,3,-3,CONCRETE:7,65,quark:iron_plate,10,quark:iron_plate:1,10,STAINED_CLAY:15,10,STAINED_CLAY:9,100)
RandomBlock(-7,3,-2,CONCRETE:7,65,quark:iron_plate,10,quark:iron_plate:1,10,STAINED_CLAY:15,10,STAINED_CLAY:9,100)
RandomBlock(-7,3,-1,CONCRETE:7,65,quark:iron_plate,10,quark:iron_plate:1,10,STAINED_CLAY:15,10,STAINED_CLAY:9,100)
RandomBlock(-7,3,0,CONCRETE:7,65,quark:iron_plate,10,quark:iron_plate:1,10,STAINED_CLAY:15,10,STAINED_CLAY:9,100)
RandomBlock(-7,3,1,CONCRETE:7,65,quark:iron_plate,10,quark:iron_plate:1,10,STAINED_CLAY:15,10,STAINED_CLAY:9,100)
RandomBlock(-7,3,2,CONCRETE:7,65,quark:iron_plate,10,quark:iron_plate:1,10,STAINED_CLAY:15,10,STAINED_CLAY:9,100)
RandomBlock(-7,3,3,CONCRETE:7,65,quark:iron_plate,10,quark:iron_plate:1,10,STAINED_CLAY:15,10,STAINED_CLAY:9,100)
RandomBlock(-7,3,4,CONCRETE:7,65,quark:iron_plate,10,quark:iron_plate:1,10,STAINED_CLAY:15,10,STAINED_CLAY:9,100)
RandomBlock(-7,3,5,CONCRETE:7,65,quark:iron_plate,10,quark:iron_plate:1,10,STAINED_CLAY:15,10,STAINED_CLAY:9,100)
RandomBlock(-7,3,6,CONCRETE:7,65,quark:iron_plate,10,quark:iron_plate:1,10,STAINED_CLAY:15,10,STAINED_CLAY:9,100)
RandomBlock(-7,3,7,CONCRETE:7,65,quark:iron_plate,10,quark:iron_plate:1,10,STAINED_CLAY:15,10,STAINED_CLAY:9,100)
RandomBlock(-7,3,8,CONCRETE:7,65,quark:iron_plate,10,quark:iron_plate:1,10,STAINED_CLAY:15,10,STAINED_CLAY:9,100)
RandomBlock(-7,4,-7,CONCRETE:7,65,quark:iron_plate,10,quark:iron_plate:1,10,STAINED_CLAY:15,10,STAINED_CLAY:9,100)
RandomBlock(-7,4,-6,CONCRETE:7,65,quark:iron_plate,10,quark:iron_plate:1,10,STAINED_CLAY:15,10,STAINED_CLAY:9,100)
RandomBlock(-7,4,-5,CONCRETE:7,65,quark:iron_plate,10,quark:iron_plate:1,10,STAINED_CLAY:15,10,STAINED_CLAY:9,100)
RandomBlock(-7,4,-4,CONCRETE:7,65,quark:iron_plate,10,quark:iron_plate:1,10,STAINED_CLAY:15,10,STAINED_CLAY:9,100)
RandomBlock(-7,4,-3,CONCRETE:7,65,quark:iron_plate,10,quark:iron_plate:1,10,STAINED_CLAY:15,10,STAINED_CLAY:9,100)
RandomBlock(-7,4,-2,CONCRETE:7,65,quark:iron_plate,10,quark:iron_plate:1,10,STAINED_CLAY:15,10,STAINED_CLAY:9,100)
RandomBlock(-7,4,-1,CONCRETE:7,65,quark:iron_plate,10,quark:iron_plate:1,10,STAINED_CLAY:15,10,STAINED_CLAY:9,100)
RandomBlock(-7,4,0,CONCRETE:7,65,quark:iron_plate,10,quark:iron_plate:1,10,STAINED_CLAY:15,10,STAINED_CLAY:9,100)
RandomBlock(-7,4,1,CONCRETE:7,65,quark:iron_plate,10,quark:iron_plate:1,10,STAINED_CLAY:15,10,STAINED_CLAY:9,100)
RandomBlock(-7,4,2,CONCRETE:7,65,quark:iron_plate,10,quark:iron_plate:1,10,STAINED_CLAY:15,10,STAINED_CLAY:9,100)
RandomBlock(-7,4,3,CONCRETE:7,65,quark:iron_plate,10,quark:iron_plate:1,10,STAINED_CLAY:15,10,STAINED_CLAY:9,100)
RandomBlock(-7,4,4,CONCRETE:7,65,quark:iron_plate,10,quark:iron_plate:1,10,STAINED_CLAY:15,10,STAINED_CLAY:9,100)
RandomBlock(-7,4,5,CONCRETE:7,65,quark:iron_plate,10,quark:iron_plate:1,10,STAINED_CLAY:15,10,STAINED_CLAY:9,100)
RandomBlock(-7,4,6,CONCRETE:7,65,quark:iron_plate,10,quark:iron_plate:1,10,STAINED_CLAY:15,10,STAINED_CLAY:9,100)
RandomBlock(-7,4,7,CONCRETE:7,65,quark:iron_plate,10,quark:iron_plate:1,10,STAINED_CLAY:15,10,STAINED_CLAY:9,100)
RandomBlock(-7,4,8,CONCRETE:7,65,quark:iron_plate,10,quark:iron_plate:1,10,STAINED_CLAY:15,10,STAINED_CLAY:9,100)
RandomBlock(-7,5,-7,CONCRETE:7,65,quark:iron_plate,10,quark:iron_plate:1,10,STAINED_CLAY:15,10,STAINED_CLAY:9,100)
RandomBlock(-7,5,-6,CONCRETE:7,65,quark:iron_plate,10,quark:iron_plate:1,10,STAINED_CLAY:15,10,STAINED_CLAY:9,100)
RandomBlock(-7,5,-5,CONCRETE:7,65,quark:iron_plate,10,quark:iron_plate:1,10,STAINED_CLAY:15,10,STAINED_CLAY:9,100)
RandomBlock(-7,5,-4,CONCRETE:7,65,quark:iron_plate,10,quark:iron_plate:1,10,STAINED_CLAY:15,10,STAINED_CLAY:9,100)
RandomBlock(-7,5,-3,CONCRETE:7,65,quark:iron_plate,10,quark:iron_plate:1,10,STAINED_CLAY:15,10,STAINED_CLAY:9,100)
RandomBlock(-7,5,-2,CONCRETE:7,65,quark:iron_plate,10,quark:iron_plate:1,10,STAINED_CLAY:15,10,STAINED_CLAY:9,100)
RandomBlock(-7,5,-1,CONCRETE:7,65,quark:iron_plate,10,quark:iron_plate:1,10,STAINED_CLAY:15,10,STAINED_CLAY:9,100)
RandomBlock(-7,5,0,CONCRETE:7,65,quark:iron_plate,10,quark:iron_plate:1,10,STAINED_CLAY:15,10,STAINED_CLAY:9,100)
RandomBlock(-7,5,1,CONCRETE:7,65,quark:iron_plate,10,quark:iron_plate:1,10,STAINED_CLAY:15,10,STAINED_CLAY:9,100)
RandomBlock(-7,5,2,CONCRETE:7,65,quark:iron_plate,10,quark:iron_plate:1,10,STAINED_CLAY:15,10,STAINED_CLAY:9,100)
RandomBlock(-7,5,3,CONCRETE:7,65,quark:iron_plate,10,quark:iron_plate:1,10,STAINED_CLAY:15,10,STAINED_CLAY:9,100)
RandomBlock(-7,5,4,CONCRETE:7,65,quark:iron_plate,10,quark:iron_plate:1,10,STAINED_CLAY:15,10,STAINED_CLAY:9,100)
RandomBlock(-7,5,5,CONCRETE:7,65,quark:iron_plate,10,quark:iron_plate:1,10,STAINED_CLAY:15,10,STAINED_CLAY:9,100)
RandomBlock(-7,5,6,CONCRETE:7,65,quark:iron_plate,10,quark:iron_plate:1,10,STAINED_CLAY:15,10,STAINED_CLAY:9,100)
RandomBlock(-7,5,7,CONCRETE:7,65,quark:iron_plate,10,quark:iron_plate:1,10,STAINED_CLAY:15,10,STAINED_CLAY:9,100)
RandomBlock(-7,5,8,CONCRETE:7,65,quark:iron_plate,10,quark:iron_plate:1,10,STAINED_CLAY:15,10,STAINED_CLAY:9,100)
RandomBlock(-7,6,-7,CONCRETE:7,65,quark:iron_plate,10,quark:iron_plate:1,10,STAINED_CLAY:15,10,STAINED_CLAY:9,100)
RandomBlock(-7,6,-6,CONCRETE:7,65,quark:iron_plate,10,quark:iron_plate:1,10,STAINED_CLAY:15,10,STAINED_CLAY:9,100)
RandomBlock(-7,6,-5,CONCRETE:7,65,quark:iron_plate,10,quark:iron_plate:1,10,STAINED_CLAY:15,10,STAINED_CLAY:9,100)
RandomBlock(-7,6,-4,CONCRETE:7,65,quark:iron_plate,10,quark:iron_plate:1,10,STAINED_CLAY:15,10,STAINED_CLAY:9,100)
RandomBlock(-7,6,-3,CONCRETE:7,65,quark:iron_plate,10,quark:iron_plate:1,10,STAINED_CLAY:15,10,STAINED_CLAY:9,100)
RandomBlock(-7,6,-2,CONCRETE:7,65,quark:iron_plate,10,quark:iron_plate:1,10,STAINED_CLAY:15,10,STAINED_CLAY:9,100)
RandomBlock(-7,6,-1,CONCRETE:7,65,quark:iron_plate,10,quark:iron_plate:1,10,STAINED_CLAY:15,10,STAINED_CLAY:9,100)
RandomBlock(-7,6,0,CONCRETE:7,65,quark:iron_plate,10,quark:iron_plate:1,10,STAINED_CLAY:15,10,STAINED_CLAY:9,100)
RandomBlock(-7,6,1,CONCRETE:7,65,quark:iron_plate,10,quark:iron_plate:1,10,STAINED_CLAY:15,10,STAINED_CLAY:9,100)
RandomBlock(-7,6,2,CONCRETE:7,65,quark:iron_plate,10,quark:iron_plate:1,10,STAINED_CLAY:15,10,STAINED_CLAY:9,100)
RandomBlock(-7,6,3,CONCRETE:7,65,quark:iron_plate,10,quark:iron_plate:1,10,STAINED_CLAY:15,10,STAINED_CLAY:9,100)
RandomBlock(-7,6,4,CONCRETE:7,65,quark:iron_plate,10,quark:iron_plate:1,10,STAINED_CLAY:15,10,STAINED_CLAY:9,100)
RandomBlock(-7,6,5,CONCRETE:7,65,quark:iron_plate,10,quark:iron_plate:1,10,STAINED_CLAY:15,10,STAINED_CLAY:9,100)
RandomBlock(-7,6,6,CONCRETE:7,65,quark:iron_plate,10,quark:iron_plate:1,10,STAINED_CLAY:15,10,STAINED_CLAY:9,100)
RandomBlock(-7,6,7,CONCRETE:7,65,quark:iron_plate,10,quark:iron_plate:1,10,STAINED_CLAY:15,10,STAINED_CLAY:9,100)
RandomBlock(-7,6,8,CONCRETE:7,65,quark:iron_plate,10,quark:iron_plate:1,10,STAINED_CLAY:15,10,STAINED_CLAY:9,100)
RandomBlock(-7,7,-7,CONCRETE:7,65,quark:iron_plate,10,quark:iron_plate:1,10,STAINED_CLAY:15,10,STAINED_CLAY:9,100)
RandomBlock(-7,7,-6,CONCRETE:7,65,quark:iron_plate,10,quark:iron_plate:1,10,STAINED_CLAY:15,10,STAINED_CLAY:9,100)
RandomBlock(-7,7,-5,CONCRETE:7,65,quark:iron_plate,10,quark:iron_plate:1,10,STAINED_CLAY:15,10,STAINED_CLAY:9,100)
RandomBlock(-7,7,-4,CONCRETE:7,65,quark:iron_plate,10,quark:iron_plate:1,10,STAINED_CLAY:15,10,STAINED_CLAY:9,100)
RandomBlock(-7,7,-3,CONCRETE:7,65,quark:iron_plate,10,quark:iron_plate:1,10,STAINED_CLAY:15,10,STAINED_CLAY:9,100)
RandomBlock(-7,7,-2,CONCRETE:7,65,quark:iron_plate,10,quark:iron_plate:1,10,STAINED_CLAY:15,10,STAINED_CLAY:9,100)
RandomBlock(-7,7,-1,CONCRETE:7,65,quark:iron_plate,10,quark:iron_plate:1,10,STAINED_CLAY:15,10,STAINED_CLAY:9,100)
RandomBlock(-7,7,0,CONCRETE:7,65,quark:iron_plate,10,quark:iron_plate:1,10,STAINED_CLAY:15,10,STAINED_CLAY:9,100)
RandomBlock(-7,7,1,CONCRETE:7,65,quark:iron_plate,10,quark:iron_plate:1,10,STAINED_CLAY:15,10,STAINED_CLAY:9,100)
RandomBlock(-7,7,2,CONCRETE:7,65,quark:iron_plate,10,quark:iron_plate:1,10,STAINED_CLAY:15,10,STAINED_CLAY:9,100)
RandomBlock(-7,7,3,CONCRETE:7,65,quark:iron_plate,10,quark:iron_plate:1,10,STAINED_CLAY:15,10,STAINED_CLAY:9,100)
RandomBlock(-7,7,4,CONCRETE:7,65,quark:iron_plate,10,quark:iron_plate:1,10,STAINED_CLAY:15,10,STAINED_CLAY:9,100)
RandomBlock(-7,7,5,CONCRETE:7,65,quark:iron_plate,10,quark:iron_plate:1,10,STAINED_CLAY:15,10,STAINED_CLAY:9,100)
RandomBlock(-7,7,6,CONCRETE:7,65,quark:iron_plate,10,quark:iron_plate:1,10,STAINED_CLAY:15,10,STAINED_CLAY:9,100)
RandomBlock(-7,7,7,CONCRETE:7,65,quark:iron_plate,10,quark:iron_plate:1,10,STAINED_CLAY:15,10,STAINED_CLAY:9,100)
RandomBlock(-7,7,8,CONCRETE:7,65,quark:iron_plate,10,quark:iron_plate:1,10,STAINED_CLAY:15,10,STAINED_CLAY:9,100)
Block(-7,8,-7,DIRT:0)
Block(-7,8,-6,DIRT:0)
Block(-7,8,-5,DIRT:0)
Block(-7,8,-4,DIRT:0)
Block(-7,8,-3,DIRT:0)
Block(-7,8,-2,DIRT:0)
Block(-7,8,-1,DIRT:0)
Block(-7,8,0,DIRT:0)
Block(-7,8,1,DIRT:0)
Block(-7,8,2,DIRT:0)
Block(-7,8,3,DIRT:0)
Block(-7,8,4,DIRT:0)
Block(-7,8,5,DIRT:0)
Block(-7,8,6,DIRT:0)
Block(-7,8,7,DIRT:0)
RandomBlock(-7,8,8,CONCRETE:7,65,quark:iron_plate,10,quark:iron_plate:1,10,STAINED_CLAY:15,10,STAINED_CLAY:9,100)
Block(-7,9,-7,DIRT:0)
Block(-7,9,-6,DIRT:0)
Block(-7,9,-5,DIRT:0)
Block(-7,9,-4,DIRT:0)
Block(-7,9,-3,DIRT:0)
Block(-7,9,-2,DIRT:0)
Block(-7,9,-1,DIRT:0)
Block(-7,9,0,DIRT:0)
Block(-7,9,1,DIRT:0)
Block(-7,9,2,DIRT:0)
Block(-7,9,3,DIRT:0)
Block(-7,9,4,DIRT:0)
Block(-7,9,5,DIRT:0)
Block(-7,9,6,DIRT:0)
Block(-7,9,7,DIRT:0)
RandomBlock(-7,9,8,CONCRETE:7,65,quark:iron_plate,10,quark:iron_plate:1,10,STAINED_CLAY:15,10,STAINED_CLAY:9,100)
Block(-7,10,-7,COBBLESTONE:0)
Block(-7,10,-6,STONE:0)
Block(-7,10,-5,STONE:0)
Block(-7,10,-4,DIRT:0)
Block(-7,10,-3,DIRT:0)
Block(-7,10,-2,DIRT:0)
Block(-7,10,-1,DIRT:0)
Block(-7,10,0,DIRT:0)
Block(-7,10,1,DIRT:0)
Block(-7,10,2,DIRT:0)
Block(-7,10,3,DIRT:0)
Block(-7,10,4,DIRT:0)
Block(-7,10,5,DIRT:0)
Block(-7,10,6,DIRT:0)
Block(-7,10,7,DIRT:0)
RandomBlock(-7,10,8,CONCRETE:7,65,quark:iron_plate,10,quark:iron_plate:1,10,STAINED_CLAY:15,10,STAINED_CLAY:9,100)
Block(-7,11,-7,GRAVEL:0)
Block(-7,11,-6,DIRT:0)
Block(-7,11,-5,STONE:1)
Block(-7,11,-4,SAND:0)
Block(-7,11,-3,STONE:0)
Block(-7,11,-2,DIRT:0)
Block(-7,11,-1,DIRT:0)
Block(-7,11,0,DIRT:0)
Block(-7,11,1,DIRT:0)
Block(-7,11,2,DIRT:0)
Block(-7,11,3,DIRT:0)
Block(-7,11,4,DIRT:0)
Block(-7,11,5,DIRT:0)
Block(-7,11,6,DIRT:0)
Block(-7,11,7,DIRT:0)
RandomBlock(-7,11,8,CONCRETE:7,65,quark:iron_plate,10,quark:iron_plate:1,10,STAINED_CLAY:15,10,STAINED_CLAY:9,100)
Block(-7,12,-7,DIRT:0)
Block(-7,12,-6,COBBLESTONE:0)
Block(-7,12,-5,STONE:5)
Block(-7,12,-4,STONE:0)
Block(-7,12,-3,STONE:0)
Block(-7,12,-2,STONE:0)
Block(-7,12,-1,DIRT:0)
Block(-7,12,0,STONE:5)
Block(-7,12,1,DIRT:0)
Block(-7,12,2,DIRT:0)
Block(-7,12,3,DIRT:0)
Block(-7,12,4,DIRT:0)
Block(-7,12,5,DIRT:0)
Block(-7,12,6,DIRT:0)
Block(-7,12,7,DIRT:0)
RandomBlock(-7,12,8,CONCRETE:7,65,quark:iron_plate,10,quark:iron_plate:1,10,STAINED_CLAY:15,10,STAINED_CLAY:9,100)
Block(-7,13,-7,DIRT:0)
Block(-7,13,-6,GRAVEL:0)
Block(-7,13,-5,DIRT:0)
Block(-7,13,-4,STONE:5)
Block(-7,13,-3,STONE:0)
Block(-7,13,-2,GRAVEL:0)
Block(-7,13,-1,STONE:1)
Block(-7,13,0,GRAVEL:0)
Block(-7,13,1,STONE:5)
Block(-7,13,2,STONE:5)
Block(-7,13,3,DIRT:0)
Block(-7,13,4,DIRT:0)
Block(-7,13,5,DIRT:0)
Block(-7,13,6,DIRT:0)
Block(-7,13,7,DIRT:0)
RandomBlock(-7,13,8,CONCRETE:7,65,quark:iron_plate,10,quark:iron_plate:1,10,STAINED_CLAY:15,10,STAINED_CLAY:9,100)
Block(-7,14,-7,LEAVES:7)
Block(-7,14,-4,STONE:0)
Block(-7,14,-3,COBBLESTONE:0)
Block(-7,14,-2,COBBLESTONE:0)
Block(-7,14,-1,DIRT:0)
Block(-7,14,0,DIRT:0)
Block(-7,14,1,GRAVEL:0)
Block(-7,14,2,STONE:0)
Block(-7,14,3,GRAVEL:0)
Block(-7,14,4,DIRT:0)
Block(-7,14,5,DIRT:0)
Block(-7,14,6,DIRT:0)
Block(-7,14,7,DIRT:0)
RandomBlock(-7,14,8,CONCRETE:7,65,quark:iron_plate,10,quark:iron_plate:1,10,STAINED_CLAY:15,10,STAINED_CLAY:9,100)
Block(-7,15,-2,LEAVES:7)
Block(-7,15,-1,STONE:3)
Block(-7,15,0,DIRT:0)
Block(-7,15,1,DIRT:0)
Block(-7,15,2,GRAVEL:0)
Block(-7,15,3,STONE:0)
Block(-7,15,4,STONE:0)
Block(-7,15,5,DIRT:0)
Block(-7,15,6,DIRT:0)
Block(-7,15,7,DIRT:0)
RandomBlock(-7,15,8,CONCRETE:7,65,quark:iron_plate,10,quark:iron_plate:1,10,STAINED_CLAY:15,10,STAINED_CLAY:9,100)
Block(-7,16,0,GRAVEL:0)
Block(-7,16,1,GRAVEL:0)
Block(-7,16,2,COBBLESTONE:0)
Block(-7,16,3,STONE:0)
Block(-7,16,4,DIRT:0)
Block(-7,16,5,DIRT:0)
Block(-7,16,6,DIRT:0)
Block(-7,16,7,DIRT:0)
RandomBlock(-7,16,8,CONCRETE:7,65,quark:iron_plate,10,quark:iron_plate:1,10,STAINED_CLAY:15,10,STAINED_CLAY:9,100)
Block(-7,17,2,GRAVEL:0)
Block(-7,17,3,DOUBLE_STEP:0)
Block(-7,17,4,COBBLESTONE:0)
Block(-7,17,5,GRASS:0)
Block(-7,17,6,GRASS_PATH:0)
Block(-7,17,7,DOUBLE_STEP:0)
RandomBlock(-7,17,8,CONCRETE:7,65,quark:iron_plate,10,quark:iron_plate:1,10,STAINED_CLAY:15,10,STAINED_CLAY:9,100)
Block(-7,18,3,COBBLE_WALL:1)
RandomBlock(-6,0,-7,CONCRETE:7,65,quark:iron_plate,10,quark:iron_plate:1,10,STAINED_CLAY:15,10,STAINED_CLAY:9,100)
RandomBlock(-6,0,-6,CONCRETE:7,65,quark:iron_plate,10,quark:iron_plate:1,10,STAINED_CLAY:15,10,STAINED_CLAY:9,100)
RandomBlock(-6,0,-5,CONCRETE:7,65,quark:iron_plate,10,quark:iron_plate:1,10,STAINED_CLAY:15,10,STAINED_CLAY:9,100)
RandomBlock(-6,0,-4,CONCRETE:7,65,quark:iron_plate,10,quark:iron_plate:1,10,STAINED_CLAY:15,10,STAINED_CLAY:9,100)
RandomBlock(-6,0,-3,CONCRETE:7,65,quark:iron_plate,10,quark:iron_plate:1,10,STAINED_CLAY:15,10,STAINED_CLAY:9,100)
RandomBlock(-6,0,-2,CONCRETE:7,65,quark:iron_plate,10,quark:iron_plate:1,10,STAINED_CLAY:15,10,STAINED_CLAY:9,100)
RandomBlock(-6,0,-1,CONCRETE:7,65,quark:iron_plate,10,quark:iron_plate:1,10,STAINED_CLAY:15,10,STAINED_CLAY:9,100)
RandomBlock(-6,0,0,CONCRETE:7,65,quark:iron_plate,10,quark:iron_plate:1,10,STAINED_CLAY:15,10,STAINED_CLAY:9,100)
RandomBlock(-6,0,1,CONCRETE:7,65,quark:iron_plate,10,quark:iron_plate:1,10,STAINED_CLAY:15,10,STAINED_CLAY:9,100)
RandomBlock(-6,0,2,CONCRETE:7,65,quark:iron_plate,10,quark:iron_plate:1,10,STAINED_CLAY:15,10,STAINED_CLAY:9,100)
RandomBlock(-6,0,3,CONCRETE:7,65,quark:iron_plate,10,quark:iron_plate:1,10,STAINED_CLAY:15,10,STAINED_CLAY:9,100)
RandomBlock(-6,0,4,CONCRETE:7,65,quark:iron_plate,10,quark:iron_plate:1,10,STAINED_CLAY:15,10,STAINED_CLAY:9,100)
RandomBlock(-6,0,5,CONCRETE:7,65,quark:iron_plate,10,quark:iron_plate:1,10,STAINED_CLAY:15,10,STAINED_CLAY:9,100)
RandomBlock(-6,0,6,CONCRETE:7,65,quark:iron_plate,10,quark:iron_plate:1,10,STAINED_CLAY:15,10,STAINED_CLAY:9,100)
RandomBlock(-6,0,7,CONCRETE:7,65,quark:iron_plate,10,quark:iron_plate:1,10,STAINED_CLAY:15,10,STAINED_CLAY:9,100)
RandomBlock(-6,0,8,CONCRETE:7,65,quark:iron_plate,10,quark:iron_plate:1,10,STAINED_CLAY:15,10,STAINED_CLAY:9,100)
RandomBlock(-6,1,-7,CONCRETE:7,65,quark:iron_plate,10,quark:iron_plate:1,10,STAINED_CLAY:15,10,STAINED_CLAY:9,100)
RandomBlock(-6,1,-6,CONCRETE:7,65,quark:iron_plate,10,quark:iron_plate:1,10,STAINED_CLAY:15,10,STAINED_CLAY:9,100)
RandomBlock(-6,1,-5,CONCRETE:7,65,quark:iron_plate,10,quark:iron_plate:1,10,STAINED_CLAY:15,10,STAINED_CLAY:9,100)
RandomBlock(-6,1,-4,CONCRETE:7,65,quark:iron_plate,10,quark:iron_plate:1,10,STAINED_CLAY:15,10,STAINED_CLAY:9,100)
RandomBlock(-6,1,-3,CONCRETE:7,65,quark:iron_plate,10,quark:iron_plate:1,10,STAINED_CLAY:15,10,STAINED_CLAY:9,100)
RandomBlock(-6,1,-2,CONCRETE:7,65,quark:iron_plate,10,quark:iron_plate:1,10,STAINED_CLAY:15,10,STAINED_CLAY:9,100)
RandomBlock(-6,1,-1,CONCRETE:7,65,quark:iron_plate,10,quark:iron_plate:1,10,STAINED_CLAY:15,10,STAINED_CLAY:9,100)
RandomBlock(-6,1,0,CONCRETE:7,65,quark:iron_plate,10,quark:iron_plate:1,10,STAINED_CLAY:15,10,STAINED_CLAY:9,100)
RandomBlock(-6,1,1,CONCRETE:7,65,quark:iron_plate,10,quark:iron_plate:1,10,STAINED_CLAY:15,10,STAINED_CLAY:9,100)
RandomBlock(-6,1,2,CONCRETE:7,65,quark:iron_plate,10,quark:iron_plate:1,10,STAINED_CLAY:15,10,STAINED_CLAY:9,100)
RandomBlock(-6,1,3,CONCRETE:7,65,quark:iron_plate,10,quark:iron_plate:1,10,STAINED_CLAY:15,10,STAINED_CLAY:9,100)
RandomBlock(-6,1,4,CONCRETE:7,65,quark:iron_plate,10,quark:iron_plate:1,10,STAINED_CLAY:15,10,STAINED_CLAY:9,100)
RandomBlock(-6,1,5,CONCRETE:7,65,quark:iron_plate,10,quark:iron_plate:1,10,STAINED_CLAY:15,10,STAINED_CLAY:9,100)
RandomBlock(-6,1,6,CONCRETE:7,65,quark:iron_plate,10,quark:iron_plate:1,10,STAINED_CLAY:15,10,STAINED_CLAY:9,100)
RandomBlock(-6,1,7,CONCRETE:7,65,quark:iron_plate,10,quark:iron_plate:1,10,STAINED_CLAY:15,10,STAINED_CLAY:9,100)
RandomBlock(-6,1,8,CONCRETE:7,65,quark:iron_plate,10,quark:iron_plate:1,10,STAINED_CLAY:15,10,STAINED_CLAY:9,100)
RandomBlock(-6,2,-7,CONCRETE:7,65,quark:iron_plate,10,quark:iron_plate:1,10,STAINED_CLAY:15,10,STAINED_CLAY:9,100)
RandomBlock(-6,2,-6,CONCRETE:7,65,quark:iron_plate,10,quark:iron_plate:1,10,STAINED_CLAY:15,10,STAINED_CLAY:9,100)
RandomBlock(-6,2,-5,CONCRETE:7,65,quark:iron_plate,10,quark:iron_plate:1,10,STAINED_CLAY:15,10,STAINED_CLAY:9,100)
RandomBlock(-6,2,-4,CONCRETE:7,65,quark:iron_plate,10,quark:iron_plate:1,10,STAINED_CLAY:15,10,STAINED_CLAY:9,100)
RandomBlock(-6,2,-3,CONCRETE:7,65,quark:iron_plate,10,quark:iron_plate:1,10,STAINED_CLAY:15,10,STAINED_CLAY:9,100)
RandomBlock(-6,2,-2,CONCRETE:7,65,quark:iron_plate,10,quark:iron_plate:1,10,STAINED_CLAY:15,10,STAINED_CLAY:9,100)
RandomBlock(-6,2,-1,CONCRETE:7,65,quark:iron_plate,10,quark:iron_plate:1,10,STAINED_CLAY:15,10,STAINED_CLAY:9,100)
RandomBlock(-6,2,0,CONCRETE:7,65,quark:iron_plate,10,quark:iron_plate:1,10,STAINED_CLAY:15,10,STAINED_CLAY:9,100)
RandomBlock(-6,2,1,CONCRETE:7,65,quark:iron_plate,10,quark:iron_plate:1,10,STAINED_CLAY:15,10,STAINED_CLAY:9,100)
RandomBlock(-6,2,2,CONCRETE:7,65,quark:iron_plate,10,quark:iron_plate:1,10,STAINED_CLAY:15,10,STAINED_CLAY:9,100)
RandomBlock(-6,2,3,CONCRETE:7,65,quark:iron_plate,10,quark:iron_plate:1,10,STAINED_CLAY:15,10,STAINED_CLAY:9,100)
RandomBlock(-6,2,4,CONCRETE:7,65,quark:iron_plate,10,quark:iron_plate:1,10,STAINED_CLAY:15,10,STAINED_CLAY:9,100)
RandomBlock(-6,2,5,CONCRETE:7,65,quark:iron_plate,10,quark:iron_plate:1,10,STAINED_CLAY:15,10,STAINED_CLAY:9,100)
RandomBlock(-6,2,6,CONCRETE:7,65,quark:iron_plate,10,quark:iron_plate:1,10,STAINED_CLAY:15,10,STAINED_CLAY:9,100)
RandomBlock(-6,2,7,CONCRETE:7,65,quark:iron_plate,10,quark:iron_plate:1,10,STAINED_CLAY:15,10,STAINED_CLAY:9,100)
RandomBlock(-6,2,8,CONCRETE:7,65,quark:iron_plate,10,quark:iron_plate:1,10,STAINED_CLAY:15,10,STAINED_CLAY:9,100)
RandomBlock(-6,3,-7,CONCRETE:7,65,quark:iron_plate,10,quark:iron_plate:1,10,STAINED_CLAY:15,10,STAINED_CLAY:9,100)
RandomBlock(-6,3,-6,CONCRETE:7,65,quark:iron_plate,10,quark:iron_plate:1,10,STAINED_CLAY:15,10,STAINED_CLAY:9,100)
RandomBlock(-6,3,-5,CONCRETE:7,65,quark:iron_plate,10,quark:iron_plate:1,10,STAINED_CLAY:15,10,STAINED_CLAY:9,100)
RandomBlock(-6,3,-4,CONCRETE:7,65,quark:iron_plate,10,quark:iron_plate:1,10,STAINED_CLAY:15,10,STAINED_CLAY:9,100)
RandomBlock(-6,3,-3,CONCRETE:7,65,quark:iron_plate,10,quark:iron_plate:1,10,STAINED_CLAY:15,10,STAINED_CLAY:9,100)
RandomBlock(-6,3,-2,CONCRETE:7,65,quark:iron_plate,10,quark:iron_plate:1,10,STAINED_CLAY:15,10,STAINED_CLAY:9,100)
RandomBlock(-6,3,-1,CONCRETE:7,65,quark:iron_plate,10,quark:iron_plate:1,10,STAINED_CLAY:15,10,STAINED_CLAY:9,100)
RandomBlock(-6,3,0,CONCRETE:7,65,quark:iron_plate,10,quark:iron_plate:1,10,STAINED_CLAY:15,10,STAINED_CLAY:9,100)
RandomBlock(-6,3,1,CONCRETE:7,65,quark:iron_plate,10,quark:iron_plate:1,10,STAINED_CLAY:15,10,STAINED_CLAY:9,100)
RandomBlock(-6,3,2,CONCRETE:7,65,quark:iron_plate,10,quark:iron_plate:1,10,STAINED_CLAY:15,10,STAINED_CLAY:9,100)
RandomBlock(-6,3,3,CONCRETE:7,65,quark:iron_plate,10,quark:iron_plate:1,10,STAINED_CLAY:15,10,STAINED_CLAY:9,100)
RandomBlock(-6,3,4,CONCRETE:7,65,quark:iron_plate,10,quark:iron_plate:1,10,STAINED_CLAY:15,10,STAINED_CLAY:9,100)
RandomBlock(-6,3,5,CONCRETE:7,65,quark:iron_plate,10,quark:iron_plate:1,10,STAINED_CLAY:15,10,STAINED_CLAY:9,100)
RandomBlock(-6,3,6,CONCRETE:7,65,quark:iron_plate,10,quark:iron_plate:1,10,STAINED_CLAY:15,10,STAINED_CLAY:9,100)
RandomBlock(-6,3,7,CONCRETE:7,65,quark:iron_plate,10,quark:iron_plate:1,10,STAINED_CLAY:15,10,STAINED_CLAY:9,100)
RandomBlock(-6,3,8,CONCRETE:7,65,quark:iron_plate,10,quark:iron_plate:1,10,STAINED_CLAY:15,10,STAINED_CLAY:9,100)
RandomBlock(-6,4,-7,CONCRETE:7,65,quark:iron_plate,10,quark:iron_plate:1,10,STAINED_CLAY:15,10,STAINED_CLAY:9,100)
RandomBlock(-6,4,-6,CONCRETE:7,65,quark:iron_plate,10,quark:iron_plate:1,10,STAINED_CLAY:15,10,STAINED_CLAY:9,100)
RandomBlock(-6,4,-5,CONCRETE:7,65,quark:iron_plate,10,quark:iron_plate:1,10,STAINED_CLAY:15,10,STAINED_CLAY:9,100)
RandomBlock(-6,4,-4,CONCRETE:7,65,quark:iron_plate,10,quark:iron_plate:1,10,STAINED_CLAY:15,10,STAINED_CLAY:9,100)
RandomBlock(-6,4,-3,CONCRETE:7,65,quark:iron_plate,10,quark:iron_plate:1,10,STAINED_CLAY:15,10,STAINED_CLAY:9,100)
RandomBlock(-6,4,-2,CONCRETE:7,65,quark:iron_plate,10,quark:iron_plate:1,10,STAINED_CLAY:15,10,STAINED_CLAY:9,100)
RandomBlock(-6,4,-1,CONCRETE:7,65,quark:iron_plate,10,quark:iron_plate:1,10,STAINED_CLAY:15,10,STAINED_CLAY:9,100)
RandomBlock(-6,4,0,CONCRETE:7,65,quark:iron_plate,10,quark:iron_plate:1,10,STAINED_CLAY:15,10,STAINED_CLAY:9,100)
RandomBlock(-6,4,1,CONCRETE:7,65,quark:iron_plate,10,quark:iron_plate:1,10,STAINED_CLAY:15,10,STAINED_CLAY:9,100)
RandomBlock(-6,4,2,CONCRETE:7,65,quark:iron_plate,10,quark:iron_plate:1,10,STAINED_CLAY:15,10,STAINED_CLAY:9,100)
RandomBlock(-6,4,3,CONCRETE:7,65,quark:iron_plate,10,quark:iron_plate:1,10,STAINED_CLAY:15,10,STAINED_CLAY:9,100)
RandomBlock(-6,4,4,CONCRETE:7,65,quark:iron_plate,10,quark:iron_plate:1,10,STAINED_CLAY:15,10,STAINED_CLAY:9,100)
RandomBlock(-6,4,5,CONCRETE:7,65,quark:iron_plate,10,quark:iron_plate:1,10,STAINED_CLAY:15,10,STAINED_CLAY:9,100)
RandomBlock(-6,4,6,CONCRETE:7,65,quark:iron_plate,10,quark:iron_plate:1,10,STAINED_CLAY:15,10,STAINED_CLAY:9,100)
RandomBlock(-6,4,7,CONCRETE:7,65,quark:iron_plate,10,quark:iron_plate:1,10,STAINED_CLAY:15,10,STAINED_CLAY:9,100)
RandomBlock(-6,4,8,CONCRETE:7,65,quark:iron_plate,10,quark:iron_plate:1,10,STAINED_CLAY:15,10,STAINED_CLAY:9,100)
RandomBlock(-6,5,-7,CONCRETE:7,65,quark:iron_plate,10,quark:iron_plate:1,10,STAINED_CLAY:15,10,STAINED_CLAY:9,100)
RandomBlock(-6,5,-6,CONCRETE:7,65,quark:iron_plate,10,quark:iron_plate:1,10,STAINED_CLAY:15,10,STAINED_CLAY:9,100)
RandomBlock(-6,5,-5,CONCRETE:7,65,quark:iron_plate,10,quark:iron_plate:1,10,STAINED_CLAY:15,10,STAINED_CLAY:9,100)
RandomBlock(-6,5,-4,CONCRETE:7,65,quark:iron_plate,10,quark:iron_plate:1,10,STAINED_CLAY:15,10,STAINED_CLAY:9,100)
RandomBlock(-6,5,-3,CONCRETE:7,65,quark:iron_plate,10,quark:iron_plate:1,10,STAINED_CLAY:15,10,STAINED_CLAY:9,100)
RandomBlock(-6,5,-2,CONCRETE:7,65,quark:iron_plate,10,quark:iron_plate:1,10,STAINED_CLAY:15,10,STAINED_CLAY:9,100)
RandomBlock(-6,5,-1,CONCRETE:7,65,quark:iron_plate,10,quark:iron_plate:1,10,STAINED_CLAY:15,10,STAINED_CLAY:9,100)
RandomBlock(-6,5,0,CONCRETE:7,65,quark:iron_plate,10,quark:iron_plate:1,10,STAINED_CLAY:15,10,STAINED_CLAY:9,100)
RandomBlock(-6,5,1,CONCRETE:7,65,quark:iron_plate,10,quark:iron_plate:1,10,STAINED_CLAY:15,10,STAINED_CLAY:9,100)
RandomBlock(-6,5,2,CONCRETE:7,65,quark:iron_plate,10,quark:iron_plate:1,10,STAINED_CLAY:15,10,STAINED_CLAY:9,100)
RandomBlock(-6,5,3,CONCRETE:7,65,quark:iron_plate,10,quark:iron_plate:1,10,STAINED_CLAY:15,10,STAINED_CLAY:9,100)
RandomBlock(-6,5,4,CONCRETE:7,65,quark:iron_plate,10,quark:iron_plate:1,10,STAINED_CLAY:15,10,STAINED_CLAY:9,100)
RandomBlock(-6,5,5,CONCRETE:7,65,quark:iron_plate,10,quark:iron_plate:1,10,STAINED_CLAY:15,10,STAINED_CLAY:9,100)
RandomBlock(-6,5,6,CONCRETE:7,65,quark:iron_plate,10,quark:iron_plate:1,10,STAINED_CLAY:15,10,STAINED_CLAY:9,100)
RandomBlock(-6,5,7,CONCRETE:7,65,quark:iron_plate,10,quark:iron_plate:1,10,STAINED_CLAY:15,10,STAINED_CLAY:9,100)
RandomBlock(-6,5,8,CONCRETE:7,65,quark:iron_plate,10,quark:iron_plate:1,10,STAINED_CLAY:15,10,STAINED_CLAY:9,100)
RandomBlock(-6,6,-7,CONCRETE:7,65,quark:iron_plate,10,quark:iron_plate:1,10,STAINED_CLAY:15,10,STAINED_CLAY:9,100)
RandomBlock(-6,6,-6,CONCRETE:7,65,quark:iron_plate,10,quark:iron_plate:1,10,STAINED_CLAY:15,10,STAINED_CLAY:9,100)
RandomBlock(-6,6,-5,CONCRETE:7,65,quark:iron_plate,10,quark:iron_plate:1,10,STAINED_CLAY:15,10,STAINED_CLAY:9,100)
RandomBlock(-6,6,-4,CONCRETE:7,65,quark:iron_plate,10,quark:iron_plate:1,10,STAINED_CLAY:15,10,STAINED_CLAY:9,100)
RandomBlock(-6,6,-3,CONCRETE:7,65,quark:iron_plate,10,quark:iron_plate:1,10,STAINED_CLAY:15,10,STAINED_CLAY:9,100)
RandomBlock(-6,6,-2,CONCRETE:7,65,quark:iron_plate,10,quark:iron_plate:1,10,STAINED_CLAY:15,10,STAINED_CLAY:9,100)
RandomBlock(-6,6,-1,CONCRETE:7,65,quark:iron_plate,10,quark:iron_plate:1,10,STAINED_CLAY:15,10,STAINED_CLAY:9,100)
RandomBlock(-6,6,0,CONCRETE:7,65,quark:iron_plate,10,quark:iron_plate:1,10,STAINED_CLAY:15,10,STAINED_CLAY:9,100)
RandomBlock(-6,6,1,CONCRETE:7,65,quark:iron_plate,10,quark:iron_plate:1,10,STAINED_CLAY:15,10,STAINED_CLAY:9,100)
RandomBlock(-6,6,2,CONCRETE:7,65,quark:iron_plate,10,quark:iron_plate:1,10,STAINED_CLAY:15,10,STAINED_CLAY:9,100)
RandomBlock(-6,6,3,CONCRETE:7,65,quark:iron_plate,10,quark:iron_plate:1,10,STAINED_CLAY:15,10,STAINED_CLAY:9,100)
RandomBlock(-6,6,4,CONCRETE:7,65,quark:iron_plate,10,quark:iron_plate:1,10,STAINED_CLAY:15,10,STAINED_CLAY:9,100)
RandomBlock(-6,6,5,CONCRETE:7,65,quark:iron_plate,10,quark:iron_plate:1,10,STAINED_CLAY:15,10,STAINED_CLAY:9,100)
RandomBlock(-6,6,6,CONCRETE:7,65,quark:iron_plate,10,quark:iron_plate:1,10,STAINED_CLAY:15,10,STAINED_CLAY:9,100)
RandomBlock(-6,6,7,CONCRETE:7,65,quark:iron_plate,10,quark:iron_plate:1,10,STAINED_CLAY:15,10,STAINED_CLAY:9,100)
RandomBlock(-6,6,8,CONCRETE:7,65,quark:iron_plate,10,quark:iron_plate:1,10,STAINED_CLAY:15,10,STAINED_CLAY:9,100)
RandomBlock(-6,7,-7,CONCRETE:7,65,quark:iron_plate,10,quark:iron_plate:1,10,STAINED_CLAY:15,10,STAINED_CLAY:9,100)
RandomBlock(-6,7,-6,CONCRETE:7,65,quark:iron_plate,10,quark:iron_plate:1,10,STAINED_CLAY:15,10,STAINED_CLAY:9,100)
RandomBlock(-6,7,-5,CONCRETE:7,65,quark:iron_plate,10,quark:iron_plate:1,10,STAINED_CLAY:15,10,STAINED_CLAY:9,100)
RandomBlock(-6,7,-4,CONCRETE:7,65,quark:iron_plate,10,quark:iron_plate:1,10,STAINED_CLAY:15,10,STAINED_CLAY:9,100)
RandomBlock(-6,7,-3,CONCRETE:7,65,quark:iron_plate,10,quark:iron_plate:1,10,STAINED_CLAY:15,10,STAINED_CLAY:9,100)
RandomBlock(-6,7,-2,CONCRETE:7,65,quark:iron_plate,10,quark:iron_plate:1,10,STAINED_CLAY:15,10,STAINED_CLAY:9,100)
RandomBlock(-6,7,-1,CONCRETE:7,65,quark:iron_plate,10,quark:iron_plate:1,10,STAINED_CLAY:15,10,STAINED_CLAY:9,100)
RandomBlock(-6,7,0,CONCRETE:7,65,quark:iron_plate,10,quark:iron_plate:1,10,STAINED_CLAY:15,10,STAINED_CLAY:9,100)
RandomBlock(-6,7,1,CONCRETE:7,65,quark:iron_plate,10,quark:iron_plate:1,10,STAINED_CLAY:15,10,STAINED_CLAY:9,100)
RandomBlock(-6,7,2,CONCRETE:7,65,quark:iron_plate,10,quark:iron_plate:1,10,STAINED_CLAY:15,10,STAINED_CLAY:9,100)
RandomBlock(-6,7,3,CONCRETE:7,65,quark:iron_plate,10,quark:iron_plate:1,10,STAINED_CLAY:15,10,STAINED_CLAY:9,100)
RandomBlock(-6,7,4,CONCRETE:7,65,quark:iron_plate,10,quark:iron_plate:1,10,STAINED_CLAY:15,10,STAINED_CLAY:9,100)
RandomBlock(-6,7,5,CONCRETE:7,65,quark:iron_plate,10,quark:iron_plate:1,10,STAINED_CLAY:15,10,STAINED_CLAY:9,100)
RandomBlock(-6,7,6,CONCRETE:7,65,quark:iron_plate,10,quark:iron_plate:1,10,STAINED_CLAY:15,10,STAINED_CLAY:9,100)
RandomBlock(-6,7,7,CONCRETE:7,65,quark:iron_plate,10,quark:iron_plate:1,10,STAINED_CLAY:15,10,STAINED_CLAY:9,100)
RandomBlock(-6,7,8,CONCRETE:7,65,quark:iron_plate,10,quark:iron_plate:1,10,STAINED_CLAY:15,10,STAINED_CLAY:9,100)
Block(-6,8,-7,DIRT:0)
Block(-6,8,-6,DIRT:0)
Block(-6,8,-5,DIRT:0)
Block(-6,8,-4,DIRT:0)
Block(-6,8,-3,DIRT:0)
Block(-6,8,-2,DIRT:0)
Block(-6,8,-1,DIRT:0)
Block(-6,8,0,DIRT:0)
Block(-6,8,1,DIRT:0)
Block(-6,8,2,DIRT:0)
Block(-6,8,3,DIRT:0)
Block(-6,8,4,DIRT:0)
Block(-6,8,5,DIRT:0)
Block(-6,8,6,DIRT:0)
Block(-6,8,7,DIRT:0)
RandomBlock(-6,8,8,CONCRETE:7,65,quark:iron_plate,10,quark:iron_plate:1,10,STAINED_CLAY:15,10,STAINED_CLAY:9,100)
Block(-6,9,-7,DIRT:0)
Block(-6,9,-6,DIRT:0)
Block(-6,9,-5,DIRT:0)
Block(-6,9,-4,DIRT:0)
Block(-6,9,-3,DIRT:0)
Block(-6,9,-2,DIRT:0)
Block(-6,9,-1,DIRT:0)
Block(-6,9,0,DIRT:0)
Block(-6,9,1,DIRT:0)
Block(-6,9,2,DIRT:0)
Block(-6,9,3,DIRT:0)
Block(-6,9,4,DIRT:0)
Block(-6,9,5,DIRT:0)
Block(-6,9,6,DIRT:0)
Block(-6,9,7,DIRT:0)
RandomBlock(-6,9,8,CONCRETE:7,65,quark:iron_plate,10,quark:iron_plate:1,10,STAINED_CLAY:15,10,STAINED_CLAY:9,100)
Block(-6,10,-7,SAND:0)
Block(-6,10,-6,STONE:0)
Block(-6,10,-5,GRAVEL:0)
Block(-6,10,-4,STONE:0)
Block(-6,10,-3,DIRT:0)
Block(-6,10,-2,DIRT:0)
Block(-6,10,-1,DIRT:0)
Block(-6,10,0,DIRT:0)
Block(-6,10,1,DIRT:0)
Block(-6,10,2,DIRT:0)
Block(-6,10,3,DIRT:0)
Block(-6,10,4,DIRT:0)
Block(-6,10,5,DIRT:0)
Block(-6,10,6,DIRT:0)
Block(-6,10,7,DIRT:0)
RandomBlock(-6,10,8,CONCRETE:7,65,quark:iron_plate,10,quark:iron_plate:1,10,STAINED_CLAY:15,10,STAINED_CLAY:9,100)
Block(-6,11,-7,DIRT:0)
Block(-6,11,-6,DIRT:0)
Block(-6,11,-5,STONE:3)
Block(-6,11,-4,STONE:0)
Block(-6,11,-3,STONE:5)
Block(-6,11,-2,DIRT:0)
Block(-6,11,-1,DIRT:0)
Block(-6,11,0,DIRT:0)
Block(-6,11,1,DIRT:0)
Block(-6,11,2,DIRT:0)
Block(-6,11,3,DIRT:0)
Block(-6,11,4,DIRT:0)
Block(-6,11,5,DIRT:0)
Block(-6,11,6,DIRT:0)
Block(-6,11,7,DIRT:0)
RandomBlock(-6,11,8,CONCRETE:7,65,quark:iron_plate,10,quark:iron_plate:1,10,STAINED_CLAY:15,10,STAINED_CLAY:9,100)
Block(-6,12,-7,GRAVEL:0)
Block(-6,12,-6,DIRT:0)
Block(-6,12,-5,DIRT:0)
Block(-6,12,-4,STONE:0)
Block(-6,12,-3,COBBLESTONE:0)
Block(-6,12,-2,STONE:0)
Block(-6,12,-1,STONE:0)
Block(-6,12,0,STONE:0)
Block(-6,12,1,DIRT:0)
Block(-6,12,2,DIRT:0)
Block(-6,12,3,DIRT:0)
Block(-6,12,4,DIRT:0)
Block(-6,12,5,DIRT:0)
Block(-6,12,6,DIRT:0)
Block(-6,12,7,DIRT:0)
RandomBlock(-6,12,8,CONCRETE:7,65,quark:iron_plate,10,quark:iron_plate:1,10,STAINED_CLAY:15,10,STAINED_CLAY:9,100)
Block(-6,13,-7,COBBLESTONE:0)
Block(-6,13,-6,COBBLESTONE:0)
Block(-6,13,-5,DIRT:0)
Block(-6,13,-4,STONE:1)
Block(-6,13,-3,GRAVEL:0)
Block(-6,13,-2,DIRT:0)
Block(-6,13,-1,COBBLESTONE:0)
Block(-6,13,0,COBBLESTONE:0)
Block(-6,13,1,STONE:5)
Block(-6,13,2,SAND:0)
Block(-6,13,3,DIRT:0)
Block(-6,13,4,DIRT:0)
Block(-6,13,5,DIRT:0)
Block(-6,13,6,DIRT:0)
Block(-6,13,7,DIRT:0)
RandomBlock(-6,13,8,CONCRETE:7,65,quark:iron_plate,10,quark:iron_plate:1,10,STAINED_CLAY:15,10,STAINED_CLAY:9,100)
Block(-6,14,-5,LEAVES:7)
Block(-6,14,-4,STONE:0)
Block(-6,14,-3,STONE:3)
Block(-6,14,-2,GRAVEL:0)
Block(-6,14,-1,DIRT:0)
Block(-6,14,0,GRAVEL:0)
Block(-6,14,1,COBBLESTONE:0)
Block(-6,14,2,COBBLESTONE:0)
Block(-6,14,3,GRAVEL:0)
Block(-6,14,4,DIRT:0)
Block(-6,14,5,DIRT:0)
Block(-6,14,6,DIRT:0)
Block(-6,14,7,DIRT:0)
RandomBlock(-6,14,8,CONCRETE:7,65,quark:iron_plate,10,quark:iron_plate:1,10,STAINED_CLAY:15,10,STAINED_CLAY:9,100)
Block(-6,15,-3,DIRT:0)
Block(-6,15,-2,COBBLESTONE:0)
Block(-6,15,-1,GRAVEL:0)
Block(-6,15,0,GRAVEL:0)
Block(-6,15,1,DIRT:0)
Block(-6,15,2,STONE:1)
Block(-6,15,3,DIRT:0)
Block(-6,15,4,STONE:0)
Block(-6,15,5,DIRT:0)
Block(-6,15,6,DIRT:0)
Block(-6,15,7,DIRT:0)
RandomBlock(-6,15,8,CONCRETE:7,65,quark:iron_plate,10,quark:iron_plate:1,10,STAINED_CLAY:15,10,STAINED_CLAY:9,100)
Block(-6,16,0,GRASS:0)
Block(-6,16,1,GRASS:0)
Block(-6,16,2,STONE:0)
Block(-6,16,3,DIRT:0)
Block(-6,16,4,DIRT:0)
Block(-6,16,5,DIRT:0)
Block(-6,16,6,DIRT:0)
Block(-6,16,7,DIRT:0)
RandomBlock(-6,16,8,CONCRETE:7,65,quark:iron_plate,10,quark:iron_plate:1,10,STAINED_CLAY:15,10,STAINED_CLAY:9,100)
Block(-6,17,2,SAND:0)
Block(-6,17,3,DOUBLE_STEP:0)
Block(-6,17,4,GRASS_PATH:0)
Block(-6,17,5,GRASS_PATH:0)
Block(-6,17,6,STONE:0)
Block(-6,17,7,DOUBLE_STEP:0)
RandomBlock(-6,17,8,CONCRETE:7,65,quark:iron_plate,10,quark:iron_plate:1,10,STAINED_CLAY:15,10,STAINED_CLAY:9,100)
Block(-6,18,3,STEP:0)
RandomBlock(-5,0,-7,CONCRETE:7,65,quark:iron_plate,10,quark:iron_plate:1,10,STAINED_CLAY:15,10,STAINED_CLAY:9,100)
RandomBlock(-5,0,-6,CONCRETE:7,65,quark:iron_plate,10,quark:iron_plate:1,10,STAINED_CLAY:15,10,STAINED_CLAY:9,100)
RandomBlock(-5,0,-5,CONCRETE:7,65,quark:iron_plate,10,quark:iron_plate:1,10,STAINED_CLAY:15,10,STAINED_CLAY:9,100)
RandomBlock(-5,0,-4,CONCRETE:7,65,quark:iron_plate,10,quark:iron_plate:1,10,STAINED_CLAY:15,10,STAINED_CLAY:9,100)
RandomBlock(-5,0,-3,CONCRETE:7,65,quark:iron_plate,10,quark:iron_plate:1,10,STAINED_CLAY:15,10,STAINED_CLAY:9,100)
RandomBlock(-5,0,-2,CONCRETE:7,65,quark:iron_plate,10,quark:iron_plate:1,10,STAINED_CLAY:15,10,STAINED_CLAY:9,100)
RandomBlock(-5,0,-1,CONCRETE:7,65,quark:iron_plate,10,quark:iron_plate:1,10,STAINED_CLAY:15,10,STAINED_CLAY:9,100)
RandomBlock(-5,0,0,CONCRETE:7,65,quark:iron_plate,10,quark:iron_plate:1,10,STAINED_CLAY:15,10,STAINED_CLAY:9,100)
RandomBlock(-5,0,1,CONCRETE:7,65,quark:iron_plate,10,quark:iron_plate:1,10,STAINED_CLAY:15,10,STAINED_CLAY:9,100)
RandomBlock(-5,0,2,CONCRETE:7,65,quark:iron_plate,10,quark:iron_plate:1,10,STAINED_CLAY:15,10,STAINED_CLAY:9,100)
RandomBlock(-5,0,3,CONCRETE:7,65,quark:iron_plate,10,quark:iron_plate:1,10,STAINED_CLAY:15,10,STAINED_CLAY:9,100)
RandomBlock(-5,0,4,CONCRETE:7,65,quark:iron_plate,10,quark:iron_plate:1,10,STAINED_CLAY:15,10,STAINED_CLAY:9,100)
RandomBlock(-5,0,5,CONCRETE:7,65,quark:iron_plate,10,quark:iron_plate:1,10,STAINED_CLAY:15,10,STAINED_CLAY:9,100)
RandomBlock(-5,0,6,CONCRETE:7,65,quark:iron_plate,10,quark:iron_plate:1,10,STAINED_CLAY:15,10,STAINED_CLAY:9,100)
RandomBlock(-5,0,7,CONCRETE:7,65,quark:iron_plate,10,quark:iron_plate:1,10,STAINED_CLAY:15,10,STAINED_CLAY:9,100)
RandomBlock(-5,0,8,CONCRETE:7,65,quark:iron_plate,10,quark:iron_plate:1,10,STAINED_CLAY:15,10,STAINED_CLAY:9,100)
RandomBlock(-5,1,-7,CONCRETE:7,65,quark:iron_plate,10,quark:iron_plate:1,10,STAINED_CLAY:15,10,STAINED_CLAY:9,100)
RandomBlock(-5,1,-6,CONCRETE:7,65,quark:iron_plate,10,quark:iron_plate:1,10,STAINED_CLAY:15,10,STAINED_CLAY:9,100)
RandomBlock(-5,1,-5,CONCRETE:7,65,quark:iron_plate,10,quark:iron_plate:1,10,STAINED_CLAY:15,10,STAINED_CLAY:9,100)
RandomBlock(-5,1,-4,CONCRETE:7,65,quark:iron_plate,10,quark:iron_plate:1,10,STAINED_CLAY:15,10,STAINED_CLAY:9,100)
RandomBlock(-5,1,-3,CONCRETE:7,65,quark:iron_plate,10,quark:iron_plate:1,10,STAINED_CLAY:15,10,STAINED_CLAY:9,100)
RandomBlock(-5,1,-2,CONCRETE:7,65,quark:iron_plate,10,quark:iron_plate:1,10,STAINED_CLAY:15,10,STAINED_CLAY:9,100)
RandomBlock(-5,1,-1,CONCRETE:7,65,quark:iron_plate,10,quark:iron_plate:1,10,STAINED_CLAY:15,10,STAINED_CLAY:9,100)
RandomBlock(-5,1,0,CONCRETE:7,65,quark:iron_plate,10,quark:iron_plate:1,10,STAINED_CLAY:15,10,STAINED_CLAY:9,100)
RandomBlock(-5,1,1,CONCRETE:7,65,quark:iron_plate,10,quark:iron_plate:1,10,STAINED_CLAY:15,10,STAINED_CLAY:9,100)
RandomBlock(-5,1,2,CONCRETE:7,65,quark:iron_plate,10,quark:iron_plate:1,10,STAINED_CLAY:15,10,STAINED_CLAY:9,100)
RandomBlock(-5,1,3,CONCRETE:7,65,quark:iron_plate,10,quark:iron_plate:1,10,STAINED_CLAY:15,10,STAINED_CLAY:9,100)
RandomBlock(-5,1,4,CONCRETE:7,65,quark:iron_plate,10,quark:iron_plate:1,10,STAINED_CLAY:15,10,STAINED_CLAY:9,100)
RandomBlock(-5,1,5,CONCRETE:7,65,quark:iron_plate,10,quark:iron_plate:1,10,STAINED_CLAY:15,10,STAINED_CLAY:9,100)
RandomBlock(-5,1,6,CONCRETE:7,65,quark:iron_plate,10,quark:iron_plate:1,10,STAINED_CLAY:15,10,STAINED_CLAY:9,100)
RandomBlock(-5,1,7,CONCRETE:7,65,quark:iron_plate,10,quark:iron_plate:1,10,STAINED_CLAY:15,10,STAINED_CLAY:9,100)
RandomBlock(-5,1,8,CONCRETE:7,65,quark:iron_plate,10,quark:iron_plate:1,10,STAINED_CLAY:15,10,STAINED_CLAY:9,100)
RandomBlock(-5,2,-7,CONCRETE:7,65,quark:iron_plate,10,quark:iron_plate:1,10,STAINED_CLAY:15,10,STAINED_CLAY:9,100)
RandomBlock(-5,2,-6,CONCRETE:7,65,quark:iron_plate,10,quark:iron_plate:1,10,STAINED_CLAY:15,10,STAINED_CLAY:9,100)
RandomBlock(-5,2,-5,CONCRETE:7,65,quark:iron_plate,10,quark:iron_plate:1,10,STAINED_CLAY:15,10,STAINED_CLAY:9,100)
RandomBlock(-5,2,-4,CONCRETE:7,65,quark:iron_plate,10,quark:iron_plate:1,10,STAINED_CLAY:15,10,STAINED_CLAY:9,100)
RandomBlock(-5,2,-3,CONCRETE:7,65,quark:iron_plate,10,quark:iron_plate:1,10,STAINED_CLAY:15,10,STAINED_CLAY:9,100)
RandomBlock(-5,2,-2,CONCRETE:7,65,quark:iron_plate,10,quark:iron_plate:1,10,STAINED_CLAY:15,10,STAINED_CLAY:9,100)
RandomBlock(-5,2,-1,CONCRETE:7,65,quark:iron_plate,10,quark:iron_plate:1,10,STAINED_CLAY:15,10,STAINED_CLAY:9,100)
RandomBlock(-5,2,0,CONCRETE:7,65,quark:iron_plate,10,quark:iron_plate:1,10,STAINED_CLAY:15,10,STAINED_CLAY:9,100)
RandomBlock(-5,2,1,CONCRETE:7,65,quark:iron_plate,10,quark:iron_plate:1,10,STAINED_CLAY:15,10,STAINED_CLAY:9,100)
RandomBlock(-5,2,2,CONCRETE:7,65,quark:iron_plate,10,quark:iron_plate:1,10,STAINED_CLAY:15,10,STAINED_CLAY:9,100)
RandomBlock(-5,2,3,CONCRETE:7,65,quark:iron_plate,10,quark:iron_plate:1,10,STAINED_CLAY:15,10,STAINED_CLAY:9,100)
RandomBlock(-5,2,4,CONCRETE:7,65,quark:iron_plate,10,quark:iron_plate:1,10,STAINED_CLAY:15,10,STAINED_CLAY:9,100)
RandomBlock(-5,2,5,CONCRETE:7,65,quark:iron_plate,10,quark:iron_plate:1,10,STAINED_CLAY:15,10,STAINED_CLAY:9,100)
RandomBlock(-5,2,6,CONCRETE:7,65,quark:iron_plate,10,quark:iron_plate:1,10,STAINED_CLAY:15,10,STAINED_CLAY:9,100)
RandomBlock(-5,2,7,CONCRETE:7,65,quark:iron_plate,10,quark:iron_plate:1,10,STAINED_CLAY:15,10,STAINED_CLAY:9,100)
RandomBlock(-5,2,8,CONCRETE:7,65,quark:iron_plate,10,quark:iron_plate:1,10,STAINED_CLAY:15,10,STAINED_CLAY:9,100)
RandomBlock(-5,3,-7,CONCRETE:7,65,quark:iron_plate,10,quark:iron_plate:1,10,STAINED_CLAY:15,10,STAINED_CLAY:9,100)
RandomBlock(-5,3,-6,CONCRETE:7,65,quark:iron_plate,10,quark:iron_plate:1,10,STAINED_CLAY:15,10,STAINED_CLAY:9,100)
RandomBlock(-5,3,-5,CONCRETE:7,65,quark:iron_plate,10,quark:iron_plate:1,10,STAINED_CLAY:15,10,STAINED_CLAY:9,100)
RandomBlock(-5,3,-4,CONCRETE:7,65,quark:iron_plate,10,quark:iron_plate:1,10,STAINED_CLAY:15,10,STAINED_CLAY:9,100)
RandomBlock(-5,3,-3,CONCRETE:7,65,quark:iron_plate,10,quark:iron_plate:1,10,STAINED_CLAY:15,10,STAINED_CLAY:9,100)
RandomBlock(-5,3,-2,CONCRETE:7,65,quark:iron_plate,10,quark:iron_plate:1,10,STAINED_CLAY:15,10,STAINED_CLAY:9,100)
RandomBlock(-5,3,-1,CONCRETE:7,65,quark:iron_plate,10,quark:iron_plate:1,10,STAINED_CLAY:15,10,STAINED_CLAY:9,100)
RandomBlock(-5,3,0,CONCRETE:7,65,quark:iron_plate,10,quark:iron_plate:1,10,STAINED_CLAY:15,10,STAINED_CLAY:9,100)
RandomBlock(-5,3,1,CONCRETE:7,65,quark:iron_plate,10,quark:iron_plate:1,10,STAINED_CLAY:15,10,STAINED_CLAY:9,100)
RandomBlock(-5,3,2,CONCRETE:7,65,quark:iron_plate,10,quark:iron_plate:1,10,STAINED_CLAY:15,10,STAINED_CLAY:9,100)
RandomBlock(-5,3,3,CONCRETE:7,65,quark:iron_plate,10,quark:iron_plate:1,10,STAINED_CLAY:15,10,STAINED_CLAY:9,100)
RandomBlock(-5,3,4,CONCRETE:7,65,quark:iron_plate,10,quark:iron_plate:1,10,STAINED_CLAY:15,10,STAINED_CLAY:9,100)
RandomBlock(-5,3,5,CONCRETE:7,65,quark:iron_plate,10,quark:iron_plate:1,10,STAINED_CLAY:15,10,STAINED_CLAY:9,100)
RandomBlock(-5,3,6,CONCRETE:7,65,quark:iron_plate,10,quark:iron_plate:1,10,STAINED_CLAY:15,10,STAINED_CLAY:9,100)
RandomBlock(-5,3,7,CONCRETE:7,65,quark:iron_plate,10,quark:iron_plate:1,10,STAINED_CLAY:15,10,STAINED_CLAY:9,100)
RandomBlock(-5,3,8,CONCRETE:7,65,quark:iron_plate,10,quark:iron_plate:1,10,STAINED_CLAY:15,10,STAINED_CLAY:9,100)
RandomBlock(-5,4,-7,CONCRETE:7,65,quark:iron_plate,10,quark:iron_plate:1,10,STAINED_CLAY:15,10,STAINED_CLAY:9,100)
RandomBlock(-5,4,-6,CONCRETE:7,65,quark:iron_plate,10,quark:iron_plate:1,10,STAINED_CLAY:15,10,STAINED_CLAY:9,100)
RandomBlock(-5,4,-5,CONCRETE:7,65,quark:iron_plate,10,quark:iron_plate:1,10,STAINED_CLAY:15,10,STAINED_CLAY:9,100)
RandomBlock(-5,4,-4,CONCRETE:7,65,quark:iron_plate,10,quark:iron_plate:1,10,STAINED_CLAY:15,10,STAINED_CLAY:9,100)
RandomBlock(-5,4,-3,CONCRETE:7,65,quark:iron_plate,10,quark:iron_plate:1,10,STAINED_CLAY:15,10,STAINED_CLAY:9,100)
RandomBlock(-5,4,-2,CONCRETE:7,65,quark:iron_plate,10,quark:iron_plate:1,10,STAINED_CLAY:15,10,STAINED_CLAY:9,100)
RandomBlock(-5,4,-1,CONCRETE:7,65,quark:iron_plate,10,quark:iron_plate:1,10,STAINED_CLAY:15,10,STAINED_CLAY:9,100)
RandomBlock(-5,4,0,CONCRETE:7,65,quark:iron_plate,10,quark:iron_plate:1,10,STAINED_CLAY:15,10,STAINED_CLAY:9,100)
RandomBlock(-5,4,1,CONCRETE:7,65,quark:iron_plate,10,quark:iron_plate:1,10,STAINED_CLAY:15,10,STAINED_CLAY:9,100)
RandomBlock(-5,4,2,CONCRETE:7,65,quark:iron_plate,10,quark:iron_plate:1,10,STAINED_CLAY:15,10,STAINED_CLAY:9,100)
RandomBlock(-5,4,3,CONCRETE:7,65,quark:iron_plate,10,quark:iron_plate:1,10,STAINED_CLAY:15,10,STAINED_CLAY:9,100)
RandomBlock(-5,4,4,CONCRETE:7,65,quark:iron_plate,10,quark:iron_plate:1,10,STAINED_CLAY:15,10,STAINED_CLAY:9,100)
RandomBlock(-5,4,5,CONCRETE:7,65,quark:iron_plate,10,quark:iron_plate:1,10,STAINED_CLAY:15,10,STAINED_CLAY:9,100)
RandomBlock(-5,4,6,CONCRETE:7,65,quark:iron_plate,10,quark:iron_plate:1,10,STAINED_CLAY:15,10,STAINED_CLAY:9,100)
RandomBlock(-5,4,7,CONCRETE:7,65,quark:iron_plate,10,quark:iron_plate:1,10,STAINED_CLAY:15,10,STAINED_CLAY:9,100)
RandomBlock(-5,4,8,CONCRETE:7,65,quark:iron_plate,10,quark:iron_plate:1,10,STAINED_CLAY:15,10,STAINED_CLAY:9,100)
RandomBlock(-5,5,-7,CONCRETE:7,65,quark:iron_plate,10,quark:iron_plate:1,10,STAINED_CLAY:15,10,STAINED_CLAY:9,100)
RandomBlock(-5,5,-6,CONCRETE:7,65,quark:iron_plate,10,quark:iron_plate:1,10,STAINED_CLAY:15,10,STAINED_CLAY:9,100)
RandomBlock(-5,5,-5,CONCRETE:7,65,quark:iron_plate,10,quark:iron_plate:1,10,STAINED_CLAY:15,10,STAINED_CLAY:9,100)
RandomBlock(-5,5,-4,CONCRETE:7,65,quark:iron_plate,10,quark:iron_plate:1,10,STAINED_CLAY:15,10,STAINED_CLAY:9,100)
RandomBlock(-5,5,-3,CONCRETE:7,65,quark:iron_plate,10,quark:iron_plate:1,10,STAINED_CLAY:15,10,STAINED_CLAY:9,100)
RandomBlock(-5,5,-2,CONCRETE:7,65,quark:iron_plate,10,quark:iron_plate:1,10,STAINED_CLAY:15,10,STAINED_CLAY:9,100)
RandomBlock(-5,5,-1,CONCRETE:7,65,quark:iron_plate,10,quark:iron_plate:1,10,STAINED_CLAY:15,10,STAINED_CLAY:9,100)
RandomBlock(-5,5,0,CONCRETE:7,65,quark:iron_plate,10,quark:iron_plate:1,10,STAINED_CLAY:15,10,STAINED_CLAY:9,100)
RandomBlock(-5,5,1,CONCRETE:7,65,quark:iron_plate,10,quark:iron_plate:1,10,STAINED_CLAY:15,10,STAINED_CLAY:9,100)
RandomBlock(-5,5,2,CONCRETE:7,65,quark:iron_plate,10,quark:iron_plate:1,10,STAINED_CLAY:15,10,STAINED_CLAY:9,100)
RandomBlock(-5,5,3,CONCRETE:7,65,quark:iron_plate,10,quark:iron_plate:1,10,STAINED_CLAY:15,10,STAINED_CLAY:9,100)
RandomBlock(-5,5,4,CONCRETE:7,65,quark:iron_plate,10,quark:iron_plate:1,10,STAINED_CLAY:15,10,STAINED_CLAY:9,100)
RandomBlock(-5,5,5,CONCRETE:7,65,quark:iron_plate,10,quark:iron_plate:1,10,STAINED_CLAY:15,10,STAINED_CLAY:9,100)
RandomBlock(-5,5,6,CONCRETE:7,65,quark:iron_plate,10,quark:iron_plate:1,10,STAINED_CLAY:15,10,STAINED_CLAY:9,100)
RandomBlock(-5,5,7,CONCRETE:7,65,quark:iron_plate,10,quark:iron_plate:1,10,STAINED_CLAY:15,10,STAINED_CLAY:9,100)
RandomBlock(-5,5,8,CONCRETE:7,65,quark:iron_plate,10,quark:iron_plate:1,10,STAINED_CLAY:15,10,STAINED_CLAY:9,100)
RandomBlock(-5,6,-7,CONCRETE:7,65,quark:iron_plate,10,quark:iron_plate:1,10,STAINED_CLAY:15,10,STAINED_CLAY:9,100)
RandomBlock(-5,6,-6,CONCRETE:7,65,quark:iron_plate,10,quark:iron_plate:1,10,STAINED_CLAY:15,10,STAINED_CLAY:9,100)
RandomBlock(-5,6,-5,CONCRETE:7,65,quark:iron_plate,10,quark:iron_plate:1,10,STAINED_CLAY:15,10,STAINED_CLAY:9,100)
RandomBlock(-5,6,-4,CONCRETE:7,65,quark:iron_plate,10,quark:iron_plate:1,10,STAINED_CLAY:15,10,STAINED_CLAY:9,100)
RandomBlock(-5,6,-3,CONCRETE:7,65,quark:iron_plate,10,quark:iron_plate:1,10,STAINED_CLAY:15,10,STAINED_CLAY:9,100)
RandomBlock(-5,6,-2,CONCRETE:7,65,quark:iron_plate,10,quark:iron_plate:1,10,STAINED_CLAY:15,10,STAINED_CLAY:9,100)
RandomBlock(-5,6,-1,CONCRETE:7,65,quark:iron_plate,10,quark:iron_plate:1,10,STAINED_CLAY:15,10,STAINED_CLAY:9,100)
RandomBlock(-5,6,0,CONCRETE:7,65,quark:iron_plate,10,quark:iron_plate:1,10,STAINED_CLAY:15,10,STAINED_CLAY:9,100)
RandomBlock(-5,6,1,CONCRETE:7,65,quark:iron_plate,10,quark:iron_plate:1,10,STAINED_CLAY:15,10,STAINED_CLAY:9,100)
RandomBlock(-5,6,2,CONCRETE:7,65,quark:iron_plate,10,quark:iron_plate:1,10,STAINED_CLAY:15,10,STAINED_CLAY:9,100)
RandomBlock(-5,6,3,CONCRETE:7,65,quark:iron_plate,10,quark:iron_plate:1,10,STAINED_CLAY:15,10,STAINED_CLAY:9,100)
RandomBlock(-5,6,4,CONCRETE:7,65,quark:iron_plate,10,quark:iron_plate:1,10,STAINED_CLAY:15,10,STAINED_CLAY:9,100)
RandomBlock(-5,6,5,CONCRETE:7,65,quark:iron_plate,10,quark:iron_plate:1,10,STAINED_CLAY:15,10,STAINED_CLAY:9,100)
RandomBlock(-5,6,6,CONCRETE:7,65,quark:iron_plate,10,quark:iron_plate:1,10,STAINED_CLAY:15,10,STAINED_CLAY:9,100)
RandomBlock(-5,6,7,CONCRETE:7,65,quark:iron_plate,10,quark:iron_plate:1,10,STAINED_CLAY:15,10,STAINED_CLAY:9,100)
RandomBlock(-5,6,8,CONCRETE:7,65,quark:iron_plate,10,quark:iron_plate:1,10,STAINED_CLAY:15,10,STAINED_CLAY:9,100)
RandomBlock(-5,7,-7,CONCRETE:7,65,quark:iron_plate,10,quark:iron_plate:1,10,STAINED_CLAY:15,10,STAINED_CLAY:9,100)
RandomBlock(-5,7,-6,CONCRETE:7,65,quark:iron_plate,10,quark:iron_plate:1,10,STAINED_CLAY:15,10,STAINED_CLAY:9,100)
RandomBlock(-5,7,-5,CONCRETE:7,65,quark:iron_plate,10,quark:iron_plate:1,10,STAINED_CLAY:15,10,STAINED_CLAY:9,100)
RandomBlock(-5,7,-4,CONCRETE:7,65,quark:iron_plate,10,quark:iron_plate:1,10,STAINED_CLAY:15,10,STAINED_CLAY:9,100)
RandomBlock(-5,7,-3,CONCRETE:7,65,quark:iron_plate,10,quark:iron_plate:1,10,STAINED_CLAY:15,10,STAINED_CLAY:9,100)
RandomBlock(-5,7,-2,CONCRETE:7,65,quark:iron_plate,10,quark:iron_plate:1,10,STAINED_CLAY:15,10,STAINED_CLAY:9,100)
RandomBlock(-5,7,-1,CONCRETE:7,65,quark:iron_plate,10,quark:iron_plate:1,10,STAINED_CLAY:15,10,STAINED_CLAY:9,100)
RandomBlock(-5,7,0,CONCRETE:7,65,quark:iron_plate,10,quark:iron_plate:1,10,STAINED_CLAY:15,10,STAINED_CLAY:9,100)
RandomBlock(-5,7,1,CONCRETE:7,65,quark:iron_plate,10,quark:iron_plate:1,10,STAINED_CLAY:15,10,STAINED_CLAY:9,100)
RandomBlock(-5,7,2,CONCRETE:7,65,quark:iron_plate,10,quark:iron_plate:1,10,STAINED_CLAY:15,10,STAINED_CLAY:9,100)
RandomBlock(-5,7,3,CONCRETE:7,65,quark:iron_plate,10,quark:iron_plate:1,10,STAINED_CLAY:15,10,STAINED_CLAY:9,100)
RandomBlock(-5,7,4,CONCRETE:7,65,quark:iron_plate,10,quark:iron_plate:1,10,STAINED_CLAY:15,10,STAINED_CLAY:9,100)
RandomBlock(-5,7,5,CONCRETE:7,65,quark:iron_plate,10,quark:iron_plate:1,10,STAINED_CLAY:15,10,STAINED_CLAY:9,100)
RandomBlock(-5,7,6,CONCRETE:7,65,quark:iron_plate,10,quark:iron_plate:1,10,STAINED_CLAY:15,10,STAINED_CLAY:9,100)
RandomBlock(-5,7,7,CONCRETE:7,65,quark:iron_plate,10,quark:iron_plate:1,10,STAINED_CLAY:15,10,STAINED_CLAY:9,100)
RandomBlock(-5,7,8,CONCRETE:7,65,quark:iron_plate,10,quark:iron_plate:1,10,STAINED_CLAY:15,10,STAINED_CLAY:9,100)
Block(-5,8,-7,DIRT:0)
Block(-5,8,-6,DIRT:0)
Block(-5,8,-5,DIRT:0)
Block(-5,8,-4,DIRT:0)
Block(-5,8,-3,DIRT:0)
Block(-5,8,-2,DIRT:0)
Block(-5,8,-1,DIRT:0)
Block(-5,8,0,DIRT:0)
Block(-5,8,1,DIRT:0)
Block(-5,8,2,DIRT:0)
Block(-5,8,3,DIRT:0)
Block(-5,8,4,DIRT:0)
Block(-5,8,5,DIRT:0)
Block(-5,8,6,DIRT:0)
Block(-5,8,7,DIRT:0)
RandomBlock(-5,8,8,CONCRETE:7,65,quark:iron_plate,10,quark:iron_plate:1,10,STAINED_CLAY:15,10,STAINED_CLAY:9,100)
Block(-5,9,-7,DIRT:0)
Block(-5,9,-6,DIRT:0)
Block(-5,9,-5,DIRT:0)
Block(-5,9,-4,DIRT:0)
Block(-5,9,-3,DIRT:0)
Block(-5,9,-2,DIRT:0)
Block(-5,9,-1,DIRT:0)
Block(-5,9,0,DIRT:0)
Block(-5,9,1,DIRT:0)
Block(-5,9,2,DIRT:0)
Block(-5,9,3,DIRT:0)
Block(-5,9,4,DIRT:0)
Block(-5,9,5,DIRT:0)
Block(-5,9,6,DIRT:0)
Block(-5,9,7,DIRT:0)
RandomBlock(-5,9,8,CONCRETE:7,65,quark:iron_plate,10,quark:iron_plate:1,10,STAINED_CLAY:15,10,STAINED_CLAY:9,100)
Block(-5,10,-7,DIRT:0)
Block(-5,10,-6,SAND:0)
Block(-5,10,-5,STONE:0)
Block(-5,10,-4,SAND:0)
Block(-5,10,-3,DIRT:0)
Block(-5,10,-2,DIRT:0)
Block(-5,10,-1,DIRT:0)
Block(-5,10,0,DIRT:0)
Block(-5,10,1,DIRT:0)
Block(-5,10,2,DIRT:0)
Block(-5,10,3,DIRT:0)
Block(-5,10,4,DIRT:0)
Block(-5,10,5,DIRT:0)
Block(-5,10,6,DIRT:0)
Block(-5,10,7,DIRT:0)
RandomBlock(-5,10,8,CONCRETE:7,65,quark:iron_plate,10,quark:iron_plate:1,10,STAINED_CLAY:15,10,STAINED_CLAY:9,100)
Block(-5,11,-7,COBBLESTONE:0)
Block(-5,11,-6,DIRT:0)
Block(-5,11,-5,SAND:0)
Block(-5,11,-4,STONE:5)
Block(-5,11,-3,STONE:0)
Block(-5,11,-2,DIRT:0)
Block(-5,11,-1,DIRT:0)
Block(-5,11,0,DIRT:0)
Block(-5,11,1,DIRT:0)
Block(-5,11,2,DIRT:0)
Block(-5,11,3,DIRT:0)
Block(-5,11,4,DIRT:0)
Block(-5,11,5,DIRT:0)
Block(-5,11,6,DIRT:0)
Block(-5,11,7,DIRT:0)
RandomBlock(-5,11,8,CONCRETE:7,65,quark:iron_plate,10,quark:iron_plate:1,10,STAINED_CLAY:15,10,STAINED_CLAY:9,100)
Block(-5,12,-7,GRAVEL:0)
Block(-5,12,-6,DIRT:0)
Block(-5,12,-5,COBBLESTONE:0)
Block(-5,12,-4,STONE:0)
Block(-5,12,-3,GRAVEL:0)
Block(-5,12,-2,GRAVEL:0)
Block(-5,12,-1,COBBLESTONE:0)
Block(-5,12,0,STONE:0)
Block(-5,12,1,DIRT:0)
Block(-5,12,2,DIRT:0)
Block(-5,12,3,DIRT:0)
Block(-5,12,4,DIRT:0)
Block(-5,12,5,DIRT:0)
Block(-5,12,6,DIRT:0)
Block(-5,12,7,DIRT:0)
RandomBlock(-5,12,8,CONCRETE:7,65,quark:iron_plate,10,quark:iron_plate:1,10,STAINED_CLAY:15,10,STAINED_CLAY:9,100)
Block(-5,13,-7,DIRT:0)
Block(-5,13,-6,DIRT:0)
Block(-5,13,-5,GRAVEL:0)
Block(-5,13,-4,STONE:0)
Block(-5,13,-3,SAND:0)
Block(-5,13,-2,COBBLESTONE:0)
Block(-5,13,-1,SAND:0)
Block(-5,13,0,STONE:5)
Block(-5,13,1,STONE:3)
Block(-5,13,2,STONE:5)
Block(-5,13,3,DIRT:0)
Block(-5,13,4,DIRT:0)
Block(-5,13,5,DIRT:0)
Block(-5,13,6,DIRT:0)
Block(-5,13,7,DIRT:0)
RandomBlock(-5,13,8,CONCRETE:7,65,quark:iron_plate,10,quark:iron_plate:1,10,STAINED_CLAY:15,10,STAINED_CLAY:9,100)
Block(-5,14,-4,COBBLESTONE:0)
Block(-5,14,-3,STONE:0)
Block(-5,14,-2,DIRT:0)
Block(-5,14,-1,GRAVEL:0)
Block(-5,14,0,DIRT:0)
Block(-5,14,1,STONE:0)
Block(-5,14,2,STONE:1)
Block(-5,14,3,STONE:3)
Block(-5,14,4,DIRT:0)
Block(-5,14,5,DIRT:0)
Block(-5,14,6,DIRT:0)
Block(-5,14,7,DIRT:0)
RandomBlock(-5,14,8,CONCRETE:7,65,quark:iron_plate,10,quark:iron_plate:1,10,STAINED_CLAY:15,10,STAINED_CLAY:9,100)
Block(-5,15,-3,LEAVES:7)
Block(-5,15,-2,GRAVEL:0)
Block(-5,15,-1,DIRT:0)
Block(-5,15,0,COBBLESTONE:0)
Block(-5,15,1,GRAVEL:0)
Block(-5,15,2,STONE:0)
Block(-5,15,3,DIRT:0)
Block(-5,15,4,GRAVEL:0)
Block(-5,15,5,DIRT:0)
Block(-5,15,6,DIRT:0)
Block(-5,15,7,DIRT:0)
RandomBlock(-5,15,8,CONCRETE:7,65,quark:iron_plate,10,quark:iron_plate:1,10,STAINED_CLAY:15,10,STAINED_CLAY:9,100)
Block(-5,16,0,GRASS:0)
Block(-5,16,1,DIRT:0)
Block(-5,16,2,COBBLESTONE:0)
Block(-5,16,3,DIRT:0)
Block(-5,16,4,COBBLESTONE:0)
Block(-5,16,5,DIRT:0)
Block(-5,16,6,DIRT:0)
Block(-5,16,7,DIRT:0)
RandomBlock(-5,16,8,CONCRETE:7,65,quark:iron_plate,10,quark:iron_plate:1,10,STAINED_CLAY:15,10,STAINED_CLAY:9,100)
Block(-5,17,1,STONE:5)
Block(-5,17,2,DOUBLE_STEP:0)
Block(-5,17,3,DOUBLE_STEP:0)
Block(-5,17,4,COBBLESTONE:0)
Block(-5,17,5,STONE:5)
Block(-5,17,6,GRAVEL:0)
Block(-5,17,7,DOUBLE_STEP:0)
RandomBlock(-5,17,8,CONCRETE:7,65,quark:iron_plate,10,quark:iron_plate:1,10,STAINED_CLAY:15,10,STAINED_CLAY:9,100)
Block(-5,18,2,DOUBLE_STEP:0)
Block(-5,18,3,STEP:0)
Block(-5,18,8,COBBLE_WALL:0)
RandomBlock(-4,0,-7,CONCRETE:7,65,quark:iron_plate,10,quark:iron_plate:1,10,STAINED_CLAY:15,10,STAINED_CLAY:9,100)
RandomBlock(-4,0,-6,CONCRETE:7,65,quark:iron_plate,10,quark:iron_plate:1,10,STAINED_CLAY:15,10,STAINED_CLAY:9,100)
RandomBlock(-4,0,-5,CONCRETE:7,65,quark:iron_plate,10,quark:iron_plate:1,10,STAINED_CLAY:15,10,STAINED_CLAY:9,100)
RandomBlock(-4,0,-4,CONCRETE:7,65,quark:iron_plate,10,quark:iron_plate:1,10,STAINED_CLAY:15,10,STAINED_CLAY:9,100)
RandomBlock(-4,0,-3,CONCRETE:7,65,quark:iron_plate,10,quark:iron_plate:1,10,STAINED_CLAY:15,10,STAINED_CLAY:9,100)
RandomBlock(-4,0,-2,CONCRETE:7,65,quark:iron_plate,10,quark:iron_plate:1,10,STAINED_CLAY:15,10,STAINED_CLAY:9,100)
RandomBlock(-4,0,-1,CONCRETE:7,65,quark:iron_plate,10,quark:iron_plate:1,10,STAINED_CLAY:15,10,STAINED_CLAY:9,100)
RandomBlock(-4,0,0,CONCRETE:7,65,quark:iron_plate,10,quark:iron_plate:1,10,STAINED_CLAY:15,10,STAINED_CLAY:9,100)
RandomBlock(-4,0,1,CONCRETE:7,65,quark:iron_plate,10,quark:iron_plate:1,10,STAINED_CLAY:15,10,STAINED_CLAY:9,100)
RandomBlock(-4,0,2,CONCRETE:7,65,quark:iron_plate,10,quark:iron_plate:1,10,STAINED_CLAY:15,10,STAINED_CLAY:9,100)
RandomBlock(-4,0,3,CONCRETE:7,65,quark:iron_plate,10,quark:iron_plate:1,10,STAINED_CLAY:15,10,STAINED_CLAY:9,100)
RandomBlock(-4,0,4,CONCRETE:7,65,quark:iron_plate,10,quark:iron_plate:1,10,STAINED_CLAY:15,10,STAINED_CLAY:9,100)
RandomBlock(-4,0,5,CONCRETE:7,65,quark:iron_plate,10,quark:iron_plate:1,10,STAINED_CLAY:15,10,STAINED_CLAY:9,100)
RandomBlock(-4,0,6,CONCRETE:7,65,quark:iron_plate,10,quark:iron_plate:1,10,STAINED_CLAY:15,10,STAINED_CLAY:9,100)
RandomBlock(-4,0,7,CONCRETE:7,65,quark:iron_plate,10,quark:iron_plate:1,10,STAINED_CLAY:15,10,STAINED_CLAY:9,100)
RandomBlock(-4,0,8,CONCRETE:7,65,quark:iron_plate,10,quark:iron_plate:1,10,STAINED_CLAY:15,10,STAINED_CLAY:9,100)
RandomBlock(-4,1,-7,CONCRETE:7,65,quark:iron_plate,10,quark:iron_plate:1,10,STAINED_CLAY:15,10,STAINED_CLAY:9,100)
RandomBlock(-4,1,-6,CONCRETE:7,65,quark:iron_plate,10,quark:iron_plate:1,10,STAINED_CLAY:15,10,STAINED_CLAY:9,100)
RandomBlock(-4,1,-5,CONCRETE:7,65,quark:iron_plate,10,quark:iron_plate:1,10,STAINED_CLAY:15,10,STAINED_CLAY:9,100)
RandomBlock(-4,1,-4,CONCRETE:7,65,quark:iron_plate,10,quark:iron_plate:1,10,STAINED_CLAY:15,10,STAINED_CLAY:9,100)
RandomBlock(-4,1,-3,CONCRETE:7,65,quark:iron_plate,10,quark:iron_plate:1,10,STAINED_CLAY:15,10,STAINED_CLAY:9,100)
RandomBlock(-4,1,-2,CONCRETE:7,65,quark:iron_plate,10,quark:iron_plate:1,10,STAINED_CLAY:15,10,STAINED_CLAY:9,100)
RandomBlock(-4,1,-1,CONCRETE:7,65,quark:iron_plate,10,quark:iron_plate:1,10,STAINED_CLAY:15,10,STAINED_CLAY:9,100)
RandomBlock(-4,1,0,CONCRETE:7,65,quark:iron_plate,10,quark:iron_plate:1,10,STAINED_CLAY:15,10,STAINED_CLAY:9,100)
RandomBlock(-4,1,1,CONCRETE:7,65,quark:iron_plate,10,quark:iron_plate:1,10,STAINED_CLAY:15,10,STAINED_CLAY:9,100)
RandomBlock(-4,1,2,CONCRETE:7,65,quark:iron_plate,10,quark:iron_plate:1,10,STAINED_CLAY:15,10,STAINED_CLAY:9,100)
RandomBlock(-4,1,3,CONCRETE:7,65,quark:iron_plate,10,quark:iron_plate:1,10,STAINED_CLAY:15,10,STAINED_CLAY:9,100)
RandomBlock(-4,1,4,CONCRETE:7,65,quark:iron_plate,10,quark:iron_plate:1,10,STAINED_CLAY:15,10,STAINED_CLAY:9,100)
RandomBlock(-4,1,5,CONCRETE:7,65,quark:iron_plate,10,quark:iron_plate:1,10,STAINED_CLAY:15,10,STAINED_CLAY:9,100)
RandomBlock(-4,1,6,CONCRETE:7,65,quark:iron_plate,10,quark:iron_plate:1,10,STAINED_CLAY:15,10,STAINED_CLAY:9,100)
RandomBlock(-4,1,7,CONCRETE:7,65,quark:iron_plate,10,quark:iron_plate:1,10,STAINED_CLAY:15,10,STAINED_CLAY:9,100)
RandomBlock(-4,1,8,CONCRETE:7,65,quark:iron_plate,10,quark:iron_plate:1,10,STAINED_CLAY:15,10,STAINED_CLAY:9,100)
RandomBlock(-4,2,-7,CONCRETE:7,65,quark:iron_plate,10,quark:iron_plate:1,10,STAINED_CLAY:15,10,STAINED_CLAY:9,100)
RandomBlock(-4,2,-6,CONCRETE:7,65,quark:iron_plate,10,quark:iron_plate:1,10,STAINED_CLAY:15,10,STAINED_CLAY:9,100)
RandomBlock(-4,2,-5,CONCRETE:7,65,quark:iron_plate,10,quark:iron_plate:1,10,STAINED_CLAY:15,10,STAINED_CLAY:9,100)
RandomBlock(-4,2,-4,CONCRETE:7,65,quark:iron_plate,10,quark:iron_plate:1,10,STAINED_CLAY:15,10,STAINED_CLAY:9,100)
RandomBlock(-4,2,-3,CONCRETE:7,65,quark:iron_plate,10,quark:iron_plate:1,10,STAINED_CLAY:15,10,STAINED_CLAY:9,100)
RandomBlock(-4,2,-2,CONCRETE:7,65,quark:iron_plate,10,quark:iron_plate:1,10,STAINED_CLAY:15,10,STAINED_CLAY:9,100)
RandomBlock(-4,2,-1,CONCRETE:7,65,quark:iron_plate,10,quark:iron_plate:1,10,STAINED_CLAY:15,10,STAINED_CLAY:9,100)
RandomBlock(-4,2,0,CONCRETE:7,65,quark:iron_plate,10,quark:iron_plate:1,10,STAINED_CLAY:15,10,STAINED_CLAY:9,100)
RandomBlock(-4,2,1,CONCRETE:7,65,quark:iron_plate,10,quark:iron_plate:1,10,STAINED_CLAY:15,10,STAINED_CLAY:9,100)
RandomBlock(-4,2,2,CONCRETE:7,65,quark:iron_plate,10,quark:iron_plate:1,10,STAINED_CLAY:15,10,STAINED_CLAY:9,100)
RandomBlock(-4,2,3,CONCRETE:7,65,quark:iron_plate,10,quark:iron_plate:1,10,STAINED_CLAY:15,10,STAINED_CLAY:9,100)
RandomBlock(-4,2,4,CONCRETE:7,65,quark:iron_plate,10,quark:iron_plate:1,10,STAINED_CLAY:15,10,STAINED_CLAY:9,100)
RandomBlock(-4,2,5,CONCRETE:7,65,quark:iron_plate,10,quark:iron_plate:1,10,STAINED_CLAY:15,10,STAINED_CLAY:9,100)
RandomBlock(-4,2,6,CONCRETE:7,65,quark:iron_plate,10,quark:iron_plate:1,10,STAINED_CLAY:15,10,STAINED_CLAY:9,100)
RandomBlock(-4,2,7,CONCRETE:7,65,quark:iron_plate,10,quark:iron_plate:1,10,STAINED_CLAY:15,10,STAINED_CLAY:9,100)
RandomBlock(-4,2,8,CONCRETE:7,65,quark:iron_plate,10,quark:iron_plate:1,10,STAINED_CLAY:15,10,STAINED_CLAY:9,100)
RandomBlock(-4,3,-7,CONCRETE:7,65,quark:iron_plate,10,quark:iron_plate:1,10,STAINED_CLAY:15,10,STAINED_CLAY:9,100)
RandomBlock(-4,3,-6,CONCRETE:7,65,quark:iron_plate,10,quark:iron_plate:1,10,STAINED_CLAY:15,10,STAINED_CLAY:9,100)
RandomBlock(-4,3,-5,CONCRETE:7,65,quark:iron_plate,10,quark:iron_plate:1,10,STAINED_CLAY:15,10,STAINED_CLAY:9,100)
RandomBlock(-4,3,-4,CONCRETE:7,65,quark:iron_plate,10,quark:iron_plate:1,10,STAINED_CLAY:15,10,STAINED_CLAY:9,100)
RandomBlock(-4,3,-3,CONCRETE:7,65,quark:iron_plate,10,quark:iron_plate:1,10,STAINED_CLAY:15,10,STAINED_CLAY:9,100)
RandomBlock(-4,3,-2,CONCRETE:7,65,quark:iron_plate,10,quark:iron_plate:1,10,STAINED_CLAY:15,10,STAINED_CLAY:9,100)
RandomBlock(-4,3,-1,CONCRETE:7,65,quark:iron_plate,10,quark:iron_plate:1,10,STAINED_CLAY:15,10,STAINED_CLAY:9,100)
RandomBlock(-4,3,0,CONCRETE:7,65,quark:iron_plate,10,quark:iron_plate:1,10,STAINED_CLAY:15,10,STAINED_CLAY:9,100)
RandomBlock(-4,3,1,CONCRETE:7,65,quark:iron_plate,10,quark:iron_plate:1,10,STAINED_CLAY:15,10,STAINED_CLAY:9,100)
RandomBlock(-4,3,2,CONCRETE:7,65,quark:iron_plate,10,quark:iron_plate:1,10,STAINED_CLAY:15,10,STAINED_CLAY:9,100)
RandomBlock(-4,3,3,CONCRETE:7,65,quark:iron_plate,10,quark:iron_plate:1,10,STAINED_CLAY:15,10,STAINED_CLAY:9,100)
RandomBlock(-4,3,4,CONCRETE:7,65,quark:iron_plate,10,quark:iron_plate:1,10,STAINED_CLAY:15,10,STAINED_CLAY:9,100)
RandomBlock(-4,3,5,CONCRETE:7,65,quark:iron_plate,10,quark:iron_plate:1,10,STAINED_CLAY:15,10,STAINED_CLAY:9,100)
RandomBlock(-4,3,6,CONCRETE:7,65,quark:iron_plate,10,quark:iron_plate:1,10,STAINED_CLAY:15,10,STAINED_CLAY:9,100)
RandomBlock(-4,3,7,CONCRETE:7,65,quark:iron_plate,10,quark:iron_plate:1,10,STAINED_CLAY:15,10,STAINED_CLAY:9,100)
RandomBlock(-4,3,8,CONCRETE:7,65,quark:iron_plate,10,quark:iron_plate:1,10,STAINED_CLAY:15,10,STAINED_CLAY:9,100)
RandomBlock(-4,4,-7,CONCRETE:7,65,quark:iron_plate,10,quark:iron_plate:1,10,STAINED_CLAY:15,10,STAINED_CLAY:9,100)
RandomBlock(-4,4,-6,CONCRETE:7,65,quark:iron_plate,10,quark:iron_plate:1,10,STAINED_CLAY:15,10,STAINED_CLAY:9,100)
RandomBlock(-4,4,-5,CONCRETE:7,65,quark:iron_plate,10,quark:iron_plate:1,10,STAINED_CLAY:15,10,STAINED_CLAY:9,100)
RandomBlock(-4,4,-4,CONCRETE:7,65,quark:iron_plate,10,quark:iron_plate:1,10,STAINED_CLAY:15,10,STAINED_CLAY:9,100)
RandomBlock(-4,4,-3,CONCRETE:7,65,quark:iron_plate,10,quark:iron_plate:1,10,STAINED_CLAY:15,10,STAINED_CLAY:9,100)
RandomBlock(-4,4,-2,CONCRETE:7,65,quark:iron_plate,10,quark:iron_plate:1,10,STAINED_CLAY:15,10,STAINED_CLAY:9,100)
RandomBlock(-4,4,-1,CONCRETE:7,65,quark:iron_plate,10,quark:iron_plate:1,10,STAINED_CLAY:15,10,STAINED_CLAY:9,100)
RandomBlock(-4,4,0,CONCRETE:7,65,quark:iron_plate,10,quark:iron_plate:1,10,STAINED_CLAY:15,10,STAINED_CLAY:9,100)
RandomBlock(-4,4,1,CONCRETE:7,65,quark:iron_plate,10,quark:iron_plate:1,10,STAINED_CLAY:15,10,STAINED_CLAY:9,100)
RandomBlock(-4,4,2,CONCRETE:7,65,quark:iron_plate,10,quark:iron_plate:1,10,STAINED_CLAY:15,10,STAINED_CLAY:9,100)
RandomBlock(-4,4,3,CONCRETE:7,65,quark:iron_plate,10,quark:iron_plate:1,10,STAINED_CLAY:15,10,STAINED_CLAY:9,100)
RandomBlock(-4,4,4,CONCRETE:7,65,quark:iron_plate,10,quark:iron_plate:1,10,STAINED_CLAY:15,10,STAINED_CLAY:9,100)
RandomBlock(-4,4,5,CONCRETE:7,65,quark:iron_plate,10,quark:iron_plate:1,10,STAINED_CLAY:15,10,STAINED_CLAY:9,100)
RandomBlock(-4,4,6,CONCRETE:7,65,quark:iron_plate,10,quark:iron_plate:1,10,STAINED_CLAY:15,10,STAINED_CLAY:9,100)
RandomBlock(-4,4,7,CONCRETE:7,65,quark:iron_plate,10,quark:iron_plate:1,10,STAINED_CLAY:15,10,STAINED_CLAY:9,100)
RandomBlock(-4,4,8,CONCRETE:7,65,quark:iron_plate,10,quark:iron_plate:1,10,STAINED_CLAY:15,10,STAINED_CLAY:9,100)
RandomBlock(-4,5,-7,CONCRETE:7,65,quark:iron_plate,10,quark:iron_plate:1,10,STAINED_CLAY:15,10,STAINED_CLAY:9,100)
RandomBlock(-4,5,-6,CONCRETE:7,65,quark:iron_plate,10,quark:iron_plate:1,10,STAINED_CLAY:15,10,STAINED_CLAY:9,100)
RandomBlock(-4,5,-5,CONCRETE:7,65,quark:iron_plate,10,quark:iron_plate:1,10,STAINED_CLAY:15,10,STAINED_CLAY:9,100)
RandomBlock(-4,5,-4,CONCRETE:7,65,quark:iron_plate,10,quark:iron_plate:1,10,STAINED_CLAY:15,10,STAINED_CLAY:9,100)
RandomBlock(-4,5,-3,CONCRETE:7,65,quark:iron_plate,10,quark:iron_plate:1,10,STAINED_CLAY:15,10,STAINED_CLAY:9,100)
RandomBlock(-4,5,-2,CONCRETE:7,65,quark:iron_plate,10,quark:iron_plate:1,10,STAINED_CLAY:15,10,STAINED_CLAY:9,100)
RandomBlock(-4,5,-1,CONCRETE:7,65,quark:iron_plate,10,quark:iron_plate:1,10,STAINED_CLAY:15,10,STAINED_CLAY:9,100)
RandomBlock(-4,5,0,CONCRETE:7,65,quark:iron_plate,10,quark:iron_plate:1,10,STAINED_CLAY:15,10,STAINED_CLAY:9,100)
RandomBlock(-4,5,1,CONCRETE:7,65,quark:iron_plate,10,quark:iron_plate:1,10,STAINED_CLAY:15,10,STAINED_CLAY:9,100)
RandomBlock(-4,5,2,CONCRETE:7,65,quark:iron_plate,10,quark:iron_plate:1,10,STAINED_CLAY:15,10,STAINED_CLAY:9,100)
RandomBlock(-4,5,3,CONCRETE:7,65,quark:iron_plate,10,quark:iron_plate:1,10,STAINED_CLAY:15,10,STAINED_CLAY:9,100)
RandomBlock(-4,5,4,CONCRETE:7,65,quark:iron_plate,10,quark:iron_plate:1,10,STAINED_CLAY:15,10,STAINED_CLAY:9,100)
RandomBlock(-4,5,5,CONCRETE:7,65,quark:iron_plate,10,quark:iron_plate:1,10,STAINED_CLAY:15,10,STAINED_CLAY:9,100)
RandomBlock(-4,5,6,CONCRETE:7,65,quark:iron_plate,10,quark:iron_plate:1,10,STAINED_CLAY:15,10,STAINED_CLAY:9,100)
RandomBlock(-4,5,7,CONCRETE:7,65,quark:iron_plate,10,quark:iron_plate:1,10,STAINED_CLAY:15,10,STAINED_CLAY:9,100)
RandomBlock(-4,5,8,CONCRETE:7,65,quark:iron_plate,10,quark:iron_plate:1,10,STAINED_CLAY:15,10,STAINED_CLAY:9,100)
RandomBlock(-4,6,-7,CONCRETE:7,65,quark:iron_plate,10,quark:iron_plate:1,10,STAINED_CLAY:15,10,STAINED_CLAY:9,100)
RandomBlock(-4,6,-6,CONCRETE:7,65,quark:iron_plate,10,quark:iron_plate:1,10,STAINED_CLAY:15,10,STAINED_CLAY:9,100)
RandomBlock(-4,6,-5,CONCRETE:7,65,quark:iron_plate,10,quark:iron_plate:1,10,STAINED_CLAY:15,10,STAINED_CLAY:9,100)
RandomBlock(-4,6,-4,CONCRETE:7,65,quark:iron_plate,10,quark:iron_plate:1,10,STAINED_CLAY:15,10,STAINED_CLAY:9,100)
RandomBlock(-4,6,-3,CONCRETE:7,65,quark:iron_plate,10,quark:iron_plate:1,10,STAINED_CLAY:15,10,STAINED_CLAY:9,100)
RandomBlock(-4,6,-2,CONCRETE:7,65,quark:iron_plate,10,quark:iron_plate:1,10,STAINED_CLAY:15,10,STAINED_CLAY:9,100)
RandomBlock(-4,6,-1,CONCRETE:7,65,quark:iron_plate,10,quark:iron_plate:1,10,STAINED_CLAY:15,10,STAINED_CLAY:9,100)
RandomBlock(-4,6,0,CONCRETE:7,65,quark:iron_plate,10,quark:iron_plate:1,10,STAINED_CLAY:15,10,STAINED_CLAY:9,100)
RandomBlock(-4,6,1,CONCRETE:7,65,quark:iron_plate,10,quark:iron_plate:1,10,STAINED_CLAY:15,10,STAINED_CLAY:9,100)
RandomBlock(-4,6,2,CONCRETE:7,65,quark:iron_plate,10,quark:iron_plate:1,10,STAINED_CLAY:15,10,STAINED_CLAY:9,100)
RandomBlock(-4,6,3,CONCRETE:7,65,quark:iron_plate,10,quark:iron_plate:1,10,STAINED_CLAY:15,10,STAINED_CLAY:9,100)
RandomBlock(-4,6,4,CONCRETE:7,65,quark:iron_plate,10,quark:iron_plate:1,10,STAINED_CLAY:15,10,STAINED_CLAY:9,100)
RandomBlock(-4,6,5,CONCRETE:7,65,quark:iron_plate,10,quark:iron_plate:1,10,STAINED_CLAY:15,10,STAINED_CLAY:9,100)
RandomBlock(-4,6,6,CONCRETE:7,65,quark:iron_plate,10,quark:iron_plate:1,10,STAINED_CLAY:15,10,STAINED_CLAY:9,100)
RandomBlock(-4,6,7,CONCRETE:7,65,quark:iron_plate,10,quark:iron_plate:1,10,STAINED_CLAY:15,10,STAINED_CLAY:9,100)
RandomBlock(-4,6,8,CONCRETE:7,65,quark:iron_plate,10,quark:iron_plate:1,10,STAINED_CLAY:15,10,STAINED_CLAY:9,100)
RandomBlock(-4,7,-7,CONCRETE:7,65,quark:iron_plate,10,quark:iron_plate:1,10,STAINED_CLAY:15,10,STAINED_CLAY:9,100)
RandomBlock(-4,7,-6,CONCRETE:7,65,quark:iron_plate,10,quark:iron_plate:1,10,STAINED_CLAY:15,10,STAINED_CLAY:9,100)
RandomBlock(-4,7,-5,CONCRETE:7,65,quark:iron_plate,10,quark:iron_plate:1,10,STAINED_CLAY:15,10,STAINED_CLAY:9,100)
RandomBlock(-4,7,-4,CONCRETE:7,65,quark:iron_plate,10,quark:iron_plate:1,10,STAINED_CLAY:15,10,STAINED_CLAY:9,100)
RandomBlock(-4,7,-3,CONCRETE:7,65,quark:iron_plate,10,quark:iron_plate:1,10,STAINED_CLAY:15,10,STAINED_CLAY:9,100)
RandomBlock(-4,7,-2,CONCRETE:7,65,quark:iron_plate,10,quark:iron_plate:1,10,STAINED_CLAY:15,10,STAINED_CLAY:9,100)
RandomBlock(-4,7,-1,CONCRETE:7,65,quark:iron_plate,10,quark:iron_plate:1,10,STAINED_CLAY:15,10,STAINED_CLAY:9,100)
RandomBlock(-4,7,0,CONCRETE:7,65,quark:iron_plate,10,quark:iron_plate:1,10,STAINED_CLAY:15,10,STAINED_CLAY:9,100)
RandomBlock(-4,7,1,CONCRETE:7,65,quark:iron_plate,10,quark:iron_plate:1,10,STAINED_CLAY:15,10,STAINED_CLAY:9,100)
RandomBlock(-4,7,2,CONCRETE:7,65,quark:iron_plate,10,quark:iron_plate:1,10,STAINED_CLAY:15,10,STAINED_CLAY:9,100)
RandomBlock(-4,7,3,CONCRETE:7,65,quark:iron_plate,10,quark:iron_plate:1,10,STAINED_CLAY:15,10,STAINED_CLAY:9,100)
RandomBlock(-4,7,4,CONCRETE:7,65,quark:iron_plate,10,quark:iron_plate:1,10,STAINED_CLAY:15,10,STAINED_CLAY:9,100)
RandomBlock(-4,7,5,CONCRETE:7,65,quark:iron_plate,10,quark:iron_plate:1,10,STAINED_CLAY:15,10,STAINED_CLAY:9,100)
RandomBlock(-4,7,6,CONCRETE:7,65,quark:iron_plate,10,quark:iron_plate:1,10,STAINED_CLAY:15,10,STAINED_CLAY:9,100)
RandomBlock(-4,7,7,CONCRETE:7,65,quark:iron_plate,10,quark:iron_plate:1,10,STAINED_CLAY:15,10,STAINED_CLAY:9,100)
RandomBlock(-4,7,8,CONCRETE:7,65,quark:iron_plate,10,quark:iron_plate:1,10,STAINED_CLAY:15,10,STAINED_CLAY:9,100)
Block(-4,8,-7,DIRT:0)
Block(-4,8,-6,DIRT:0)
Block(-4,8,-5,DIRT:0)
Block(-4,8,-4,DIRT:0)
Block(-4,8,-3,DIRT:0)
Block(-4,8,-2,DIRT:0)
Block(-4,8,-1,DIRT:0)
Block(-4,8,0,DIRT:0)
Block(-4,8,1,DIRT:0)
Block(-4,8,2,DIRT:0)
Block(-4,8,3,DIRT:0)
Block(-4,8,4,DIRT:0)
Block(-4,8,5,DIRT:0)
Block(-4,8,6,DIRT:0)
Block(-4,8,7,DIRT:0)
RandomBlock(-4,8,8,CONCRETE:7,65,quark:iron_plate,10,quark:iron_plate:1,10,STAINED_CLAY:15,10,STAINED_CLAY:9,100)
Block(-4,9,-7,DIRT:0)
Block(-4,9,-6,DIRT:0)
Block(-4,9,-5,DIRT:0)
Block(-4,9,-4,DIRT:0)
Block(-4,9,-3,DIRT:0)
Block(-4,9,-2,DIRT:0)
Block(-4,9,-1,DIRT:0)
Block(-4,9,0,DIRT:0)
Block(-4,9,1,DIRT:0)
Block(-4,9,2,DIRT:0)
Block(-4,9,3,DIRT:0)
Block(-4,9,4,DIRT:0)
Block(-4,9,5,DIRT:0)
Block(-4,9,6,DIRT:0)
Block(-4,9,7,DIRT:0)
RandomBlock(-4,9,8,CONCRETE:7,65,quark:iron_plate,10,quark:iron_plate:1,10,STAINED_CLAY:15,10,STAINED_CLAY:9,100)
Block(-4,10,-7,DIRT:0)
Block(-4,10,-6,STONE:0)
Block(-4,10,-5,STONE:3)
Block(-4,10,-4,DIRT:0)
Block(-4,10,-3,DIRT:0)
Block(-4,10,-2,DIRT:0)
Block(-4,10,-1,DIRT:0)
Block(-4,10,0,DIRT:0)
Block(-4,10,1,DIRT:0)
Block(-4,10,2,DIRT:0)
Block(-4,10,3,DIRT:0)
Block(-4,10,4,DIRT:0)
Block(-4,10,5,DIRT:0)
Block(-4,10,6,DIRT:0)
Block(-4,10,7,DIRT:0)
RandomBlock(-4,10,8,CONCRETE:7,65,quark:iron_plate,10,quark:iron_plate:1,10,STAINED_CLAY:15,10,STAINED_CLAY:9,100)
Block(-4,11,-7,DIRT:0)
Block(-4,11,-6,GRAVEL:0)
Block(-4,11,-5,STONE:0)
Block(-4,11,-4,STONE:0)
Block(-4,11,-3,STONE:5)
Block(-4,11,-2,DIRT:0)
Block(-4,11,-1,DIRT:0)
Block(-4,11,0,DIRT:0)
Block(-4,11,1,DIRT:0)
Block(-4,11,2,DIRT:0)
Block(-4,11,3,DIRT:0)
Block(-4,11,4,DIRT:0)
Block(-4,11,5,DIRT:0)
Block(-4,11,6,DIRT:0)
Block(-4,11,7,DIRT:0)
RandomBlock(-4,11,8,CONCRETE:7,65,quark:iron_plate,10,quark:iron_plate:1,10,STAINED_CLAY:15,10,STAINED_CLAY:9,100)
Block(-4,12,-7,GRAVEL:0)
Block(-4,12,-6,DIRT:0)
Block(-4,12,-5,STONE:5)
Block(-4,12,-4,STONE:0)
Block(-4,12,-3,STONE:0)
Block(-4,12,-2,SAND:0)
Block(-4,12,-1,STONE:0)
Block(-4,12,0,STONE:0)
Block(-4,12,1,DIRT:0)
Block(-4,12,2,DIRT:0)
Block(-4,12,3,DIRT:0)
Block(-4,12,4,DIRT:0)
Block(-4,12,5,DIRT:0)
Block(-4,12,6,DIRT:0)
Block(-4,12,7,DIRT:0)
RandomBlock(-4,12,8,CONCRETE:7,65,quark:iron_plate,10,quark:iron_plate:1,10,STAINED_CLAY:15,10,STAINED_CLAY:9,100)
Block(-4,13,-7,SAND:0)
Block(-4,13,-6,GRAVEL:0)
Block(-4,13,-5,STONE:5)
Block(-4,13,-4,STONE:0)
Block(-4,13,-3,STONE:0)
Block(-4,13,-2,STONE:0)
Block(-4,13,-1,GRAVEL:0)
Block(-4,13,0,GRAVEL:0)
Block(-4,13,1,STONE:5)
Block(-4,13,2,DIRT:0)
Block(-4,13,3,DIRT:0)
Block(-4,13,4,DIRT:0)
Block(-4,13,5,DIRT:0)
Block(-4,13,6,DIRT:0)
Block(-4,13,7,DIRT:0)
RandomBlock(-4,13,8,CONCRETE:7,65,quark:iron_plate,10,quark:iron_plate:1,10,STAINED_CLAY:15,10,STAINED_CLAY:9,100)
Block(-4,14,-7,GRAVEL:0)
Block(-4,14,-6,LEAVES:7)
Block(-4,14,-5,COBBLESTONE:0)
Block(-4,14,-4,COBBLESTONE:0)
Block(-4,14,-3,STONE:0)
Block(-4,14,-2,DIRT:0)
Block(-4,14,-1,STONE:5)
Block(-4,14,0,STONE:3)
Block(-4,14,1,STONE:0)
Block(-4,14,2,STONE:0)
Block(-4,14,3,GRAVEL:0)
Block(-4,14,4,DIRT:0)
Block(-4,14,5,DIRT:0)
Block(-4,14,6,DIRT:0)
Block(-4,14,7,DIRT:0)
RandomBlock(-4,14,8,CONCRETE:7,65,quark:iron_plate,10,quark:iron_plate:1,10,STAINED_CLAY:15,10,STAINED_CLAY:9,100)
Block(-4,15,-3,DIRT:0)
Block(-4,15,-2,DIRT:0)
Block(-4,15,-1,DIRT:0)
Block(-4,15,0,DIRT:0)
Block(-4,15,1,DIRT:0)
Block(-4,15,2,STONE:0)
Block(-4,15,3,DIRT:0)
Block(-4,15,4,DIRT:0)
Block(-4,15,5,DIRT:0)
Block(-4,15,6,DIRT:0)
Block(-4,15,7,DIRT:0)
RandomBlock(-4,15,8,CONCRETE:7,65,quark:iron_plate,10,quark:iron_plate:1,10,STAINED_CLAY:15,10,STAINED_CLAY:9,100)
Block(-4,16,-1,GRAVEL:0)
Block(-4,16,0,GRASS:0)
Block(-4,16,1,COBBLESTONE:0)
Block(-4,16,2,DIRT:0)
Block(-4,16,3,DIRT:0)
Block(-4,16,4,DIRT:0)
Block(-4,16,5,DIRT:0)
Block(-4,16,6,DIRT:0)
Block(-4,16,7,DIRT:0)
RandomBlock(-4,16,8,CONCRETE:7,65,quark:iron_plate,10,quark:iron_plate:1,10,STAINED_CLAY:15,10,STAINED_CLAY:9,100)
Block(-4,17,1,STONE:5)
Block(-4,17,2,DOUBLE_STEP:0)
Block(-4,17,3,COBBLESTONE:0)
Block(-4,17,4,GRAVEL:0)
Block(-4,17,5,STEP:3)
Block(-4,17,6,GRAVEL:0)
Block(-4,17,7,DOUBLE_STEP:0)
RandomBlock(-4,17,8,CONCRETE:7,65,quark:iron_plate,10,quark:iron_plate:1,10,STAINED_CLAY:15,10,STAINED_CLAY:9,100)
Block(-4,18,2,COBBLESTONE_STAIRS:3)
RandomBlock(-3,0,-7,CONCRETE:7,65,quark:iron_plate,10,quark:iron_plate:1,10,STAINED_CLAY:15,10,STAINED_CLAY:9,100)
RandomBlock(-3,0,-6,CONCRETE:7,65,quark:iron_plate,10,quark:iron_plate:1,10,STAINED_CLAY:15,10,STAINED_CLAY:9,100)
RandomBlock(-3,0,-5,CONCRETE:7,65,quark:iron_plate,10,quark:iron_plate:1,10,STAINED_CLAY:15,10,STAINED_CLAY:9,100)
RandomBlock(-3,0,-4,CONCRETE:7,65,quark:iron_plate,10,quark:iron_plate:1,10,STAINED_CLAY:15,10,STAINED_CLAY:9,100)
RandomBlock(-3,0,-3,CONCRETE:7,65,quark:iron_plate,10,quark:iron_plate:1,10,STAINED_CLAY:15,10,STAINED_CLAY:9,100)
RandomBlock(-3,0,-2,CONCRETE:7,65,quark:iron_plate,10,quark:iron_plate:1,10,STAINED_CLAY:15,10,STAINED_CLAY:9,100)
RandomBlock(-3,0,-1,CONCRETE:7,65,quark:iron_plate,10,quark:iron_plate:1,10,STAINED_CLAY:15,10,STAINED_CLAY:9,100)
RandomBlock(-3,0,0,CONCRETE:7,65,quark:iron_plate,10,quark:iron_plate:1,10,STAINED_CLAY:15,10,STAINED_CLAY:9,100)
RandomBlock(-3,0,1,CONCRETE:7,65,quark:iron_plate,10,quark:iron_plate:1,10,STAINED_CLAY:15,10,STAINED_CLAY:9,100)
RandomBlock(-3,0,2,CONCRETE:7,65,quark:iron_plate,10,quark:iron_plate:1,10,STAINED_CLAY:15,10,STAINED_CLAY:9,100)
RandomBlock(-3,0,3,CONCRETE:7,65,quark:iron_plate,10,quark:iron_plate:1,10,STAINED_CLAY:15,10,STAINED_CLAY:9,100)
RandomBlock(-3,0,4,CONCRETE:7,65,quark:iron_plate,10,quark:iron_plate:1,10,STAINED_CLAY:15,10,STAINED_CLAY:9,100)
RandomBlock(-3,0,5,CONCRETE:7,65,quark:iron_plate,10,quark:iron_plate:1,10,STAINED_CLAY:15,10,STAINED_CLAY:9,100)
RandomBlock(-3,0,6,CONCRETE:7,65,quark:iron_plate,10,quark:iron_plate:1,10,STAINED_CLAY:15,10,STAINED_CLAY:9,100)
RandomBlock(-3,0,7,CONCRETE:7,65,quark:iron_plate,10,quark:iron_plate:1,10,STAINED_CLAY:15,10,STAINED_CLAY:9,100)
RandomBlock(-3,0,8,CONCRETE:7,65,quark:iron_plate,10,quark:iron_plate:1,10,STAINED_CLAY:15,10,STAINED_CLAY:9,100)
RandomBlock(-3,1,-7,CONCRETE:7,65,quark:iron_plate,10,quark:iron_plate:1,10,STAINED_CLAY:15,10,STAINED_CLAY:9,100)
RandomBlock(-3,1,-6,CONCRETE:7,65,quark:iron_plate,10,quark:iron_plate:1,10,STAINED_CLAY:15,10,STAINED_CLAY:9,100)
RandomBlock(-3,1,-5,CONCRETE:7,65,quark:iron_plate,10,quark:iron_plate:1,10,STAINED_CLAY:15,10,STAINED_CLAY:9,100)
RandomBlock(-3,1,-4,CONCRETE:7,65,quark:iron_plate,10,quark:iron_plate:1,10,STAINED_CLAY:15,10,STAINED_CLAY:9,100)
RandomBlock(-3,1,-3,CONCRETE:7,65,quark:iron_plate,10,quark:iron_plate:1,10,STAINED_CLAY:15,10,STAINED_CLAY:9,100)
RandomBlock(-3,1,-2,CONCRETE:7,65,quark:iron_plate,10,quark:iron_plate:1,10,STAINED_CLAY:15,10,STAINED_CLAY:9,100)
