
#######################################################################
# +-----------------------------------------------------------------+ #
# |                            BO4 object                           | #
# +-----------------------------------------------------------------+ #
#######################################################################

Author: NLBlackEagle

Description: No description given

SettingsMode: WriteDisable


#######################################################################
# +-----------------------------------------------------------------+ #
# |                          Main settings                          | #
# +-----------------------------------------------------------------+ #
#######################################################################

FixedRotation: 

Frequency: 0

SpawnHeight: highestBlock

UseCenterForHighestBlock: true

##############################
# Height Limits for the BO4. #
##############################

MinHeight: 0

MaxHeight: 255

InheritBO3: 

InheritBO3Rotation: NORTH

OverrideChildSettings: true

OverrideParentHeight: false

CanOverride: true

BranchFrequency: 0

BranchFrequencyGroup: 

MustBeBelowOther: false

MustBeInside: 

CannotBeInside: 

ReplacesBO3: 

MustBeInsideWorldBorders: false

CanSpawnOnWater: true

SpawnOnWaterOnly: false

SpawnUnderWater: false

SpawnAtWaterLevel: false

HeightOffset: 0

RemoveAir: false

ReplaceAbove: 

ReplaceBelow: 

ReplaceWithBiomeBlocks: true

ReplaceWithSurfaceBlock: GRASS

ReplaceWithGroundBlock: DIRT

ReplaceWithStoneBlock: STONE

SmoothRadius: 0

SmoothHeightOffset: 0

SmoothStartTop: false

SmoothStartWood: false

SmoothingSurfaceBlock: 

SmoothingGroundBlock: 

BO3Group: 

IsSpawnPoint: false

DoReplaceBlocks: true


#######################################################################
# +-----------------------------------------------------------------+ #
# |                              Blocks                             | #
# +-----------------------------------------------------------------+ #
#######################################################################

RandomBlock(-8,0,-7,CONCRETE:7,65,quark:iron_plate,10,quark:iron_plate:1,10,STAINED_CLAY:15,10,STAINED_CLAY:9,100)
RandomBlock(-8,0,-6,CONCRETE:7,65,quark:iron_plate,10,quark:iron_plate:1,10,STAINED_CLAY:15,10,STAINED_CLAY:9,100)
RandomBlock(-8,0,-5,CONCRETE:7,65,quark:iron_plate,10,quark:iron_plate:1,10,STAINED_CLAY:15,10,STAINED_CLAY:9,100)
RandomBlock(-8,0,-4,CONCRETE:7,65,quark:iron_plate,10,quark:iron_plate:1,10,STAINED_CLAY:15,10,STAINED_CLAY:9,100)
RandomBlock(-8,0,-3,CONCRETE:7,65,quark:iron_plate,10,quark:iron_plate:1,10,STAINED_CLAY:15,10,STAINED_CLAY:9,100)
RandomBlock(-8,0,-2,CONCRETE:7,65,quark:iron_plate,10,quark:iron_plate:1,10,STAINED_CLAY:15,10,STAINED_CLAY:9,100)
RandomBlock(-8,0,-1,CONCRETE:7,65,quark:iron_plate,10,quark:iron_plate:1,10,STAINED_CLAY:15,10,STAINED_CLAY:9,100)
RandomBlock(-8,0,0,CONCRETE:7,65,quark:iron_plate,10,quark:iron_plate:1,10,STAINED_CLAY:15,10,STAINED_CLAY:9,100)
RandomBlock(-8,0,1,CONCRETE:7,65,quark:iron_plate,10,quark:iron_plate:1,10,STAINED_CLAY:15,10,STAINED_CLAY:9,100)
RandomBlock(-8,0,2,CONCRETE:7,65,quark:iron_plate,10,quark:iron_plate:1,10,STAINED_CLAY:15,10,STAINED_CLAY:9,100)
RandomBlock(-8,0,3,CONCRETE:7,65,quark:iron_plate,10,quark:iron_plate:1,10,STAINED_CLAY:15,10,STAINED_CLAY:9,100)
RandomBlock(-8,0,4,CONCRETE:7,65,quark:iron_plate,10,quark:iron_plate:1,10,STAINED_CLAY:15,10,STAINED_CLAY:9,100)
RandomBlock(-8,0,5,CONCRETE:7,65,quark:iron_plate,10,quark:iron_plate:1,10,STAINED_CLAY:15,10,STAINED_CLAY:9,100)
RandomBlock(-8,0,6,CONCRETE:7,65,quark:iron_plate,10,quark:iron_plate:1,10,STAINED_CLAY:15,10,STAINED_CLAY:9,100)
RandomBlock(-8,0,7,CONCRETE:7,65,quark:iron_plate,10,quark:iron_plate:1,10,STAINED_CLAY:15,10,STAINED_CLAY:9,100)
RandomBlock(-8,0,8,CONCRETE:7,65,quark:iron_plate,10,quark:iron_plate:1,10,STAINED_CLAY:15,10,STAINED_CLAY:9,100)
RandomBlock(-8,1,-7,CONCRETE:7,65,quark:iron_plate,10,quark:iron_plate:1,10,STAINED_CLAY:15,10,STAINED_CLAY:9,100)
RandomBlock(-8,1,-6,CONCRETE:7,65,quark:iron_plate,10,quark:iron_plate:1,10,STAINED_CLAY:15,10,STAINED_CLAY:9,100)
RandomBlock(-8,1,-5,CONCRETE:7,65,quark:iron_plate,10,quark:iron_plate:1,10,STAINED_CLAY:15,10,STAINED_CLAY:9,100)
RandomBlock(-8,1,-4,CONCRETE:7,65,quark:iron_plate,10,quark:iron_plate:1,10,STAINED_CLAY:15,10,STAINED_CLAY:9,100)
RandomBlock(-8,1,-3,CONCRETE:7,65,quark:iron_plate,10,quark:iron_plate:1,10,STAINED_CLAY:15,10,STAINED_CLAY:9,100)
RandomBlock(-8,1,-2,CONCRETE:7,65,quark:iron_plate,10,quark:iron_plate:1,10,STAINED_CLAY:15,10,STAINED_CLAY:9,100)
RandomBlock(-8,1,-1,CONCRETE:7,65,quark:iron_plate,10,quark:iron_plate:1,10,STAINED_CLAY:15,10,STAINED_CLAY:9,100)
RandomBlock(-8,1,0,CONCRETE:7,65,quark:iron_plate,10,quark:iron_plate:1,10,STAINED_CLAY:15,10,STAINED_CLAY:9,100)
RandomBlock(-8,1,1,CONCRETE:7,65,quark:iron_plate,10,quark:iron_plate:1,10,STAINED_CLAY:15,10,STAINED_CLAY:9,100)
RandomBlock(-8,1,2,CONCRETE:7,65,quark:iron_plate,10,quark:iron_plate:1,10,STAINED_CLAY:15,10,STAINED_CLAY:9,100)
RandomBlock(-8,1,3,CONCRETE:7,65,quark:iron_plate,10,quark:iron_plate:1,10,STAINED_CLAY:15,10,STAINED_CLAY:9,100)
RandomBlock(-8,1,4,CONCRETE:7,65,quark:iron_plate,10,quark:iron_plate:1,10,STAINED_CLAY:15,10,STAINED_CLAY:9,100)
RandomBlock(-8,1,5,CONCRETE:7,65,quark:iron_plate,10,quark:iron_plate:1,10,STAINED_CLAY:15,10,STAINED_CLAY:9,100)
RandomBlock(-8,1,6,CONCRETE:7,65,quark:iron_plate,10,quark:iron_plate:1,10,STAINED_CLAY:15,10,STAINED_CLAY:9,100)
RandomBlock(-8,1,7,CONCRETE:7,65,quark:iron_plate,10,quark:iron_plate:1,10,STAINED_CLAY:15,10,STAINED_CLAY:9,100)
RandomBlock(-8,1,8,CONCRETE:7,65,quark:iron_plate,10,quark:iron_plate:1,10,STAINED_CLAY:15,10,STAINED_CLAY:9,100)
RandomBlock(-8,2,-7,CONCRETE:7,65,quark:iron_plate,10,quark:iron_plate:1,10,STAINED_CLAY:15,10,STAINED_CLAY:9,100)
RandomBlock(-8,2,-6,CONCRETE:7,65,quark:iron_plate,10,quark:iron_plate:1,10,STAINED_CLAY:15,10,STAINED_CLAY:9,100)
RandomBlock(-8,2,-5,CONCRETE:7,65,quark:iron_plate,10,quark:iron_plate:1,10,STAINED_CLAY:15,10,STAINED_CLAY:9,100)
RandomBlock(-8,2,-4,CONCRETE:7,65,quark:iron_plate,10,quark:iron_plate:1,10,STAINED_CLAY:15,10,STAINED_CLAY:9,100)
RandomBlock(-8,2,-3,CONCRETE:7,65,quark:iron_plate,10,quark:iron_plate:1,10,STAINED_CLAY:15,10,STAINED_CLAY:9,100)
RandomBlock(-8,2,-2,CONCRETE:7,65,quark:iron_plate,10,quark:iron_plate:1,10,STAINED_CLAY:15,10,STAINED_CLAY:9,100)
RandomBlock(-8,2,-1,CONCRETE:7,65,quark:iron_plate,10,quark:iron_plate:1,10,STAINED_CLAY:15,10,STAINED_CLAY:9,100)
RandomBlock(-8,2,0,CONCRETE:7,65,quark:iron_plate,10,quark:iron_plate:1,10,STAINED_CLAY:15,10,STAINED_CLAY:9,100)
RandomBlock(-8,2,1,CONCRETE:7,65,quark:iron_plate,10,quark:iron_plate:1,10,STAINED_CLAY:15,10,STAINED_CLAY:9,100)
RandomBlock(-8,2,2,CONCRETE:7,65,quark:iron_plate,10,quark:iron_plate:1,10,STAINED_CLAY:15,10,STAINED_CLAY:9,100)
RandomBlock(-8,2,3,CONCRETE:7,65,quark:iron_plate,10,quark:iron_plate:1,10,STAINED_CLAY:15,10,STAINED_CLAY:9,100)
RandomBlock(-8,2,4,CONCRETE:7,65,quark:iron_plate,10,quark:iron_plate:1,10,STAINED_CLAY:15,10,STAINED_CLAY:9,100)
RandomBlock(-8,2,5,CONCRETE:7,65,quark:iron_plate,10,quark:iron_plate:1,10,STAINED_CLAY:15,10,STAINED_CLAY:9,100)
RandomBlock(-8,2,6,CONCRETE:7,65,quark:iron_plate,10,quark:iron_plate:1,10,STAINED_CLAY:15,10,STAINED_CLAY:9,100)
RandomBlock(-8,2,7,CONCRETE:7,65,quark:iron_plate,10,quark:iron_plate:1,10,STAINED_CLAY:15,10,STAINED_CLAY:9,100)
RandomBlock(-8,2,8,CONCRETE:7,65,quark:iron_plate,10,quark:iron_plate:1,10,STAINED_CLAY:15,10,STAINED_CLAY:9,100)
RandomBlock(-8,3,-7,CONCRETE:7,65,quark:iron_plate,10,quark:iron_plate:1,10,STAINED_CLAY:15,10,STAINED_CLAY:9,100)
RandomBlock(-8,3,-6,CONCRETE:7,65,quark:iron_plate,10,quark:iron_plate:1,10,STAINED_CLAY:15,10,STAINED_CLAY:9,100)
RandomBlock(-8,3,-5,CONCRETE:7,65,quark:iron_plate,10,quark:iron_plate:1,10,STAINED_CLAY:15,10,STAINED_CLAY:9,100)
RandomBlock(-8,3,-4,CONCRETE:7,65,quark:iron_plate,10,quark:iron_plate:1,10,STAINED_CLAY:15,10,STAINED_CLAY:9,100)
RandomBlock(-8,3,-3,CONCRETE:7,65,quark:iron_plate,10,quark:iron_plate:1,10,STAINED_CLAY:15,10,STAINED_CLAY:9,100)
RandomBlock(-8,3,-2,CONCRETE:7,65,quark:iron_plate,10,quark:iron_plate:1,10,STAINED_CLAY:15,10,STAINED_CLAY:9,100)
RandomBlock(-8,3,-1,CONCRETE:7,65,quark:iron_plate,10,quark:iron_plate:1,10,STAINED_CLAY:15,10,STAINED_CLAY:9,100)
RandomBlock(-8,3,0,CONCRETE:7,65,quark:iron_plate,10,quark:iron_plate:1,10,STAINED_CLAY:15,10,STAINED_CLAY:9,100)
RandomBlock(-8,3,1,CONCRETE:7,65,quark:iron_plate,10,quark:iron_plate:1,10,STAINED_CLAY:15,10,STAINED_CLAY:9,100)
RandomBlock(-8,3,2,CONCRETE:7,65,quark:iron_plate,10,quark:iron_plate:1,10,STAINED_CLAY:15,10,STAINED_CLAY:9,100)
RandomBlock(-8,3,3,CONCRETE:7,65,quark:iron_plate,10,quark:iron_plate:1,10,STAINED_CLAY:15,10,STAINED_CLAY:9,100)
RandomBlock(-8,3,4,CONCRETE:7,65,quark:iron_plate,10,quark:iron_plate:1,10,STAINED_CLAY:15,10,STAINED_CLAY:9,100)
RandomBlock(-8,3,5,CONCRETE:7,65,quark:iron_plate,10,quark:iron_plate:1,10,STAINED_CLAY:15,10,STAINED_CLAY:9,100)
RandomBlock(-8,3,6,CONCRETE:7,65,quark:iron_plate,10,quark:iron_plate:1,10,STAINED_CLAY:15,10,STAINED_CLAY:9,100)
RandomBlock(-8,3,7,CONCRETE:7,65,quark:iron_plate,10,quark:iron_plate:1,10,STAINED_CLAY:15,10,STAINED_CLAY:9,100)
RandomBlock(-8,3,8,CONCRETE:7,65,quark:iron_plate,10,quark:iron_plate:1,10,STAINED_CLAY:15,10,STAINED_CLAY:9,100)
RandomBlock(-8,4,-7,CONCRETE:7,65,quark:iron_plate,10,quark:iron_plate:1,10,STAINED_CLAY:15,10,STAINED_CLAY:9,100)
RandomBlock(-8,4,-6,CONCRETE:7,65,quark:iron_plate,10,quark:iron_plate:1,10,STAINED_CLAY:15,10,STAINED_CLAY:9,100)
RandomBlock(-8,4,-5,CONCRETE:7,65,quark:iron_plate,10,quark:iron_plate:1,10,STAINED_CLAY:15,10,STAINED_CLAY:9,100)
RandomBlock(-8,4,-4,CONCRETE:7,65,quark:iron_plate,10,quark:iron_plate:1,10,STAINED_CLAY:15,10,STAINED_CLAY:9,100)
RandomBlock(-8,4,-3,CONCRETE:7,65,quark:iron_plate,10,quark:iron_plate:1,10,STAINED_CLAY:15,10,STAINED_CLAY:9,100)
RandomBlock(-8,4,-2,CONCRETE:7,65,quark:iron_plate,10,quark:iron_plate:1,10,STAINED_CLAY:15,10,STAINED_CLAY:9,100)
RandomBlock(-8,4,-1,CONCRETE:7,65,quark:iron_plate,10,quark:iron_plate:1,10,STAINED_CLAY:15,10,STAINED_CLAY:9,100)
RandomBlock(-8,4,0,CONCRETE:7,65,quark:iron_plate,10,quark:iron_plate:1,10,STAINED_CLAY:15,10,STAINED_CLAY:9,100)
RandomBlock(-8,4,1,CONCRETE:7,65,quark:iron_plate,10,quark:iron_plate:1,10,STAINED_CLAY:15,10,STAINED_CLAY:9,100)
RandomBlock(-8,4,2,CONCRETE:7,65,quark:iron_plate,10,quark:iron_plate:1,10,STAINED_CLAY:15,10,STAINED_CLAY:9,100)
RandomBlock(-8,4,3,CONCRETE:7,65,quark:iron_plate,10,quark:iron_plate:1,10,STAINED_CLAY:15,10,STAINED_CLAY:9,100)
RandomBlock(-8,4,4,CONCRETE:7,65,quark:iron_plate,10,quark:iron_plate:1,10,STAINED_CLAY:15,10,STAINED_CLAY:9,100)
RandomBlock(-8,4,5,CONCRETE:7,65,quark:iron_plate,10,quark:iron_plate:1,10,STAINED_CLAY:15,10,STAINED_CLAY:9,100)
RandomBlock(-8,4,6,CONCRETE:7,65,quark:iron_plate,10,quark:iron_plate:1,10,STAINED_CLAY:15,10,STAINED_CLAY:9,100)
RandomBlock(-8,4,7,CONCRETE:7,65,quark:iron_plate,10,quark:iron_plate:1,10,STAINED_CLAY:15,10,STAINED_CLAY:9,100)
RandomBlock(-8,4,8,CONCRETE:7,65,quark:iron_plate,10,quark:iron_plate:1,10,STAINED_CLAY:15,10,STAINED_CLAY:9,100)
RandomBlock(-8,5,-7,CONCRETE:7,65,quark:iron_plate,10,quark:iron_plate:1,10,STAINED_CLAY:15,10,STAINED_CLAY:9,100)
RandomBlock(-8,5,-6,CONCRETE:7,65,quark:iron_plate,10,quark:iron_plate:1,10,STAINED_CLAY:15,10,STAINED_CLAY:9,100)
RandomBlock(-8,5,-5,CONCRETE:7,65,quark:iron_plate,10,quark:iron_plate:1,10,STAINED_CLAY:15,10,STAINED_CLAY:9,100)
RandomBlock(-8,5,-4,CONCRETE:7,65,quark:iron_plate,10,quark:iron_plate:1,10,STAINED_CLAY:15,10,STAINED_CLAY:9,100)
RandomBlock(-8,5,-3,CONCRETE:7,65,quark:iron_plate,10,quark:iron_plate:1,10,STAINED_CLAY:15,10,STAINED_CLAY:9,100)
RandomBlock(-8,5,-2,CONCRETE:7,65,quark:iron_plate,10,quark:iron_plate:1,10,STAINED_CLAY:15,10,STAINED_CLAY:9,100)
RandomBlock(-8,5,-1,CONCRETE:7,65,quark:iron_plate,10,quark:iron_plate:1,10,STAINED_CLAY:15,10,STAINED_CLAY:9,100)
RandomBlock(-8,5,0,CONCRETE:7,65,quark:iron_plate,10,quark:iron_plate:1,10,STAINED_CLAY:15,10,STAINED_CLAY:9,100)
RandomBlock(-8,5,1,CONCRETE:7,65,quark:iron_plate,10,quark:iron_plate:1,10,STAINED_CLAY:15,10,STAINED_CLAY:9,100)
RandomBlock(-8,5,2,CONCRETE:7,65,quark:iron_plate,10,quark:iron_plate:1,10,STAINED_CLAY:15,10,STAINED_CLAY:9,100)
RandomBlock(-8,5,3,CONCRETE:7,65,quark:iron_plate,10,quark:iron_plate:1,10,STAINED_CLAY:15,10,STAINED_CLAY:9,100)
RandomBlock(-8,5,4,CONCRETE:7,65,quark:iron_plate,10,quark:iron_plate:1,10,STAINED_CLAY:15,10,STAINED_CLAY:9,100)
RandomBlock(-8,5,5,CONCRETE:7,65,quark:iron_plate,10,quark:iron_plate:1,10,STAINED_CLAY:15,10,STAINED_CLAY:9,100)
RandomBlock(-8,5,6,CONCRETE:7,65,quark:iron_plate,10,quark:iron_plate:1,10,STAINED_CLAY:15,10,STAINED_CLAY:9,100)
RandomBlock(-8,5,7,CONCRETE:7,65,quark:iron_plate,10,quark:iron_plate:1,10,STAINED_CLAY:15,10,STAINED_CLAY:9,100)
RandomBlock(-8,5,8,CONCRETE:7,65,quark:iron_plate,10,quark:iron_plate:1,10,STAINED_CLAY:15,10,STAINED_CLAY:9,100)
RandomBlock(-8,6,-7,CONCRETE:7,65,quark:iron_plate,10,quark:iron_plate:1,10,STAINED_CLAY:15,10,STAINED_CLAY:9,100)
RandomBlock(-8,6,-6,CONCRETE:7,65,quark:iron_plate,10,quark:iron_plate:1,10,STAINED_CLAY:15,10,STAINED_CLAY:9,100)
RandomBlock(-8,6,-5,CONCRETE:7,65,quark:iron_plate,10,quark:iron_plate:1,10,STAINED_CLAY:15,10,STAINED_CLAY:9,100)
RandomBlock(-8,6,-4,CONCRETE:7,65,quark:iron_plate,10,quark:iron_plate:1,10,STAINED_CLAY:15,10,STAINED_CLAY:9,100)
RandomBlock(-8,6,-3,CONCRETE:7,65,quark:iron_plate,10,quark:iron_plate:1,10,STAINED_CLAY:15,10,STAINED_CLAY:9,100)
RandomBlock(-8,6,-2,CONCRETE:7,65,quark:iron_plate,10,quark:iron_plate:1,10,STAINED_CLAY:15,10,STAINED_CLAY:9,100)
RandomBlock(-8,6,-1,CONCRETE:7,65,quark:iron_plate,10,quark:iron_plate:1,10,STAINED_CLAY:15,10,STAINED_CLAY:9,100)
RandomBlock(-8,6,0,CONCRETE:7,65,quark:iron_plate,10,quark:iron_plate:1,10,STAINED_CLAY:15,10,STAINED_CLAY:9,100)
RandomBlock(-8,6,1,CONCRETE:7,65,quark:iron_plate,10,quark:iron_plate:1,10,STAINED_CLAY:15,10,STAINED_CLAY:9,100)
RandomBlock(-8,6,2,CONCRETE:7,65,quark:iron_plate,10,quark:iron_plate:1,10,STAINED_CLAY:15,10,STAINED_CLAY:9,100)
RandomBlock(-8,6,3,CONCRETE:7,65,quark:iron_plate,10,quark:iron_plate:1,10,STAINED_CLAY:15,10,STAINED_CLAY:9,100)
RandomBlock(-8,6,4,CONCRETE:7,65,quark:iron_plate,10,quark:iron_plate:1,10,STAINED_CLAY:15,10,STAINED_CLAY:9,100)
RandomBlock(-8,6,5,CONCRETE:7,65,quark:iron_plate,10,quark:iron_plate:1,10,STAINED_CLAY:15,10,STAINED_CLAY:9,100)
RandomBlock(-8,6,6,CONCRETE:7,65,quark:iron_plate,10,quark:iron_plate:1,10,STAINED_CLAY:15,10,STAINED_CLAY:9,100)
RandomBlock(-8,6,7,CONCRETE:7,65,quark:iron_plate,10,quark:iron_plate:1,10,STAINED_CLAY:15,10,STAINED_CLAY:9,100)
RandomBlock(-8,6,8,CONCRETE:7,65,quark:iron_plate,10,quark:iron_plate:1,10,STAINED_CLAY:15,10,STAINED_CLAY:9,100)
RandomBlock(-8,7,-7,CONCRETE:7,65,quark:iron_plate,10,quark:iron_plate:1,10,STAINED_CLAY:15,10,STAINED_CLAY:9,100)
RandomBlock(-8,7,-6,CONCRETE:7,65,quark:iron_plate,10,quark:iron_plate:1,10,STAINED_CLAY:15,10,STAINED_CLAY:9,100)
RandomBlock(-8,7,-5,CONCRETE:7,65,quark:iron_plate,10,quark:iron_plate:1,10,STAINED_CLAY:15,10,STAINED_CLAY:9,100)
RandomBlock(-8,7,-4,CONCRETE:7,65,quark:iron_plate,10,quark:iron_plate:1,10,STAINED_CLAY:15,10,STAINED_CLAY:9,100)
RandomBlock(-8,7,-3,CONCRETE:7,65,quark:iron_plate,10,quark:iron_plate:1,10,STAINED_CLAY:15,10,STAINED_CLAY:9,100)
RandomBlock(-8,7,-2,CONCRETE:7,65,quark:iron_plate,10,quark:iron_plate:1,10,STAINED_CLAY:15,10,STAINED_CLAY:9,100)
RandomBlock(-8,7,-1,CONCRETE:7,65,quark:iron_plate,10,quark:iron_plate:1,10,STAINED_CLAY:15,10,STAINED_CLAY:9,100)
RandomBlock(-8,7,0,CONCRETE:7,65,quark:iron_plate,10,quark:iron_plate:1,10,STAINED_CLAY:15,10,STAINED_CLAY:9,100)
RandomBlock(-8,7,1,CONCRETE:7,65,quark:iron_plate,10,quark:iron_plate:1,10,STAINED_CLAY:15,10,STAINED_CLAY:9,100)
RandomBlock(-8,7,2,CONCRETE:7,65,quark:iron_plate,10,quark:iron_plate:1,10,STAINED_CLAY:15,10,STAINED_CLAY:9,100)
RandomBlock(-8,7,3,CONCRETE:7,65,quark:iron_plate,10,quark:iron_plate:1,10,STAINED_CLAY:15,10,STAINED_CLAY:9,100)
RandomBlock(-8,7,4,CONCRETE:7,65,quark:iron_plate,10,quark:iron_plate:1,10,STAINED_CLAY:15,10,STAINED_CLAY:9,100)
RandomBlock(-8,7,5,CONCRETE:7,65,quark:iron_plate,10,quark:iron_plate:1,10,STAINED_CLAY:15,10,STAINED_CLAY:9,100)
RandomBlock(-8,7,6,CONCRETE:7,65,quark:iron_plate,10,quark:iron_plate:1,10,STAINED_CLAY:15,10,STAINED_CLAY:9,100)
RandomBlock(-8,7,7,CONCRETE:7,65,quark:iron_plate,10,quark:iron_plate:1,10,STAINED_CLAY:15,10,STAINED_CLAY:9,100)
RandomBlock(-8,7,8,CONCRETE:7,65,quark:iron_plate,10,quark:iron_plate:1,10,STAINED_CLAY:15,10,STAINED_CLAY:9,100)
RandomBlock(-8,8,-7,CONCRETE:7,65,quark:iron_plate,10,quark:iron_plate:1,10,STAINED_CLAY:15,10,STAINED_CLAY:9,100)
RandomBlock(-8,8,-6,CONCRETE:7,65,quark:iron_plate,10,quark:iron_plate:1,10,STAINED_CLAY:15,10,STAINED_CLAY:9,100)
RandomBlock(-8,8,-5,CONCRETE:7,65,quark:iron_plate,10,quark:iron_plate:1,10,STAINED_CLAY:15,10,STAINED_CLAY:9,100)
RandomBlock(-8,8,-4,CONCRETE:7,65,quark:iron_plate,10,quark:iron_plate:1,10,STAINED_CLAY:15,10,STAINED_CLAY:9,100)
RandomBlock(-8,8,-3,CONCRETE:7,65,quark:iron_plate,10,quark:iron_plate:1,10,STAINED_CLAY:15,10,STAINED_CLAY:9,100)
RandomBlock(-8,8,-2,CONCRETE:7,65,quark:iron_plate,10,quark:iron_plate:1,10,STAINED_CLAY:15,10,STAINED_CLAY:9,100)
RandomBlock(-8,8,-1,CONCRETE:7,65,quark:iron_plate,10,quark:iron_plate:1,10,STAINED_CLAY:15,10,STAINED_CLAY:9,100)
RandomBlock(-8,8,0,CONCRETE:7,65,quark:iron_plate,10,quark:iron_plate:1,10,STAINED_CLAY:15,10,STAINED_CLAY:9,100)
RandomBlock(-8,8,1,CONCRETE:7,65,quark:iron_plate,10,quark:iron_plate:1,10,STAINED_CLAY:15,10,STAINED_CLAY:9,100)
RandomBlock(-8,8,2,CONCRETE:7,65,quark:iron_plate,10,quark:iron_plate:1,10,STAINED_CLAY:15,10,STAINED_CLAY:9,100)
RandomBlock(-8,8,3,CONCRETE:7,65,quark:iron_plate,10,quark:iron_plate:1,10,STAINED_CLAY:15,10,STAINED_CLAY:9,100)
RandomBlock(-8,8,4,CONCRETE:7,65,quark:iron_plate,10,quark:iron_plate:1,10,STAINED_CLAY:15,10,STAINED_CLAY:9,100)
RandomBlock(-8,8,5,CONCRETE:7,65,quark:iron_plate,10,quark:iron_plate:1,10,STAINED_CLAY:15,10,STAINED_CLAY:9,100)
RandomBlock(-8,8,6,CONCRETE:7,65,quark:iron_plate,10,quark:iron_plate:1,10,STAINED_CLAY:15,10,STAINED_CLAY:9,100)
RandomBlock(-8,8,7,CONCRETE:7,65,quark:iron_plate,10,quark:iron_plate:1,10,STAINED_CLAY:15,10,STAINED_CLAY:9,100)
RandomBlock(-8,8,8,CONCRETE:7,65,quark:iron_plate,10,quark:iron_plate:1,10,STAINED_CLAY:15,10,STAINED_CLAY:9,100)
RandomBlock(-8,9,-7,CONCRETE:7,65,quark:iron_plate,10,quark:iron_plate:1,10,STAINED_CLAY:15,10,STAINED_CLAY:9,100)
RandomBlock(-8,9,-6,CONCRETE:7,65,quark:iron_plate,10,quark:iron_plate:1,10,STAINED_CLAY:15,10,STAINED_CLAY:9,100)
RandomBlock(-8,9,-5,CONCRETE:7,65,quark:iron_plate,10,quark:iron_plate:1,10,STAINED_CLAY:15,10,STAINED_CLAY:9,100)
RandomBlock(-8,9,-4,CONCRETE:7,65,quark:iron_plate,10,quark:iron_plate:1,10,STAINED_CLAY:15,10,STAINED_CLAY:9,100)
RandomBlock(-8,9,-3,CONCRETE:7,65,quark:iron_plate,10,quark:iron_plate:1,10,STAINED_CLAY:15,10,STAINED_CLAY:9,100)
RandomBlock(-8,9,-2,CONCRETE:7,65,quark:iron_plate,10,quark:iron_plate:1,10,STAINED_CLAY:15,10,STAINED_CLAY:9,100)
RandomBlock(-8,9,-1,CONCRETE:7,65,quark:iron_plate,10,quark:iron_plate:1,10,STAINED_CLAY:15,10,STAINED_CLAY:9,100)
RandomBlock(-8,9,0,CONCRETE:7,65,quark:iron_plate,10,quark:iron_plate:1,10,STAINED_CLAY:15,10,STAINED_CLAY:9,100)
RandomBlock(-8,9,1,CONCRETE:7,65,quark:iron_plate,10,quark:iron_plate:1,10,STAINED_CLAY:15,10,STAINED_CLAY:9,100)
RandomBlock(-8,9,2,CONCRETE:7,65,quark:iron_plate,10,quark:iron_plate:1,10,STAINED_CLAY:15,10,STAINED_CLAY:9,100)
RandomBlock(-8,9,3,CONCRETE:7,65,quark:iron_plate,10,quark:iron_plate:1,10,STAINED_CLAY:15,10,STAINED_CLAY:9,100)
RandomBlock(-8,9,4,CONCRETE:7,65,quark:iron_plate,10,quark:iron_plate:1,10,STAINED_CLAY:15,10,STAINED_CLAY:9,100)
RandomBlock(-8,9,5,CONCRETE:7,65,quark:iron_plate,10,quark:iron_plate:1,10,STAINED_CLAY:15,10,STAINED_CLAY:9,100)
RandomBlock(-8,9,6,CONCRETE:7,65,quark:iron_plate,10,quark:iron_plate:1,10,STAINED_CLAY:15,10,STAINED_CLAY:9,100)
RandomBlock(-8,9,7,CONCRETE:7,65,quark:iron_plate,10,quark:iron_plate:1,10,STAINED_CLAY:15,10,STAINED_CLAY:9,100)
RandomBlock(-8,9,8,CONCRETE:7,65,quark:iron_plate,10,quark:iron_plate:1,10,STAINED_CLAY:15,10,STAINED_CLAY:9,100)
RandomBlock(-8,10,-7,CONCRETE:7,65,quark:iron_plate,10,quark:iron_plate:1,10,STAINED_CLAY:15,10,STAINED_CLAY:9,100)
RandomBlock(-8,10,-6,CONCRETE:7,65,quark:iron_plate,10,quark:iron_plate:1,10,STAINED_CLAY:15,10,STAINED_CLAY:9,100)
RandomBlock(-8,10,-5,CONCRETE:7,65,quark:iron_plate,10,quark:iron_plate:1,10,STAINED_CLAY:15,10,STAINED_CLAY:9,100)
RandomBlock(-8,10,-4,CONCRETE:7,65,quark:iron_plate,10,quark:iron_plate:1,10,STAINED_CLAY:15,10,STAINED_CLAY:9,100)
RandomBlock(-8,10,-3,CONCRETE:7,65,quark:iron_plate,10,quark:iron_plate:1,10,STAINED_CLAY:15,10,STAINED_CLAY:9,100)
RandomBlock(-8,10,-2,CONCRETE:7,65,quark:iron_plate,10,quark:iron_plate:1,10,STAINED_CLAY:15,10,STAINED_CLAY:9,100)
RandomBlock(-8,10,-1,CONCRETE:7,65,quark:iron_plate,10,quark:iron_plate:1,10,STAINED_CLAY:15,10,STAINED_CLAY:9,100)
RandomBlock(-8,10,0,CONCRETE:7,65,quark:iron_plate,10,quark:iron_plate:1,10,STAINED_CLAY:15,10,STAINED_CLAY:9,100)
RandomBlock(-8,10,1,CONCRETE:7,65,quark:iron_plate,10,quark:iron_plate:1,10,STAINED_CLAY:15,10,STAINED_CLAY:9,100)
RandomBlock(-8,10,2,CONCRETE:7,65,quark:iron_plate,10,quark:iron_plate:1,10,STAINED_CLAY:15,10,STAINED_CLAY:9,100)
RandomBlock(-8,10,3,CONCRETE:7,65,quark:iron_plate,10,quark:iron_plate:1,10,STAINED_CLAY:15,10,STAINED_CLAY:9,100)
RandomBlock(-8,10,4,CONCRETE:7,65,quark:iron_plate,10,quark:iron_plate:1,10,STAINED_CLAY:15,10,STAINED_CLAY:9,100)
RandomBlock(-8,10,5,CONCRETE:7,65,quark:iron_plate,10,quark:iron_plate:1,10,STAINED_CLAY:15,10,STAINED_CLAY:9,100)
RandomBlock(-8,10,6,CONCRETE:7,65,quark:iron_plate,10,quark:iron_plate:1,10,STAINED_CLAY:15,10,STAINED_CLAY:9,100)
RandomBlock(-8,10,7,CONCRETE:7,65,quark:iron_plate,10,quark:iron_plate:1,10,STAINED_CLAY:15,10,STAINED_CLAY:9,100)
RandomBlock(-8,10,8,CONCRETE:7,65,quark:iron_plate,10,quark:iron_plate:1,10,STAINED_CLAY:15,10,STAINED_CLAY:9,100)
RandomBlock(-8,11,-7,CONCRETE:7,65,quark:iron_plate,10,quark:iron_plate:1,10,STAINED_CLAY:15,10,STAINED_CLAY:9,100)
RandomBlock(-8,11,-6,CONCRETE:7,65,quark:iron_plate,10,quark:iron_plate:1,10,STAINED_CLAY:15,10,STAINED_CLAY:9,100)
RandomBlock(-8,11,-5,CONCRETE:7,65,quark:iron_plate,10,quark:iron_plate:1,10,STAINED_CLAY:15,10,STAINED_CLAY:9,100)
RandomBlock(-8,11,-4,CONCRETE:7,65,quark:iron_plate,10,quark:iron_plate:1,10,STAINED_CLAY:15,10,STAINED_CLAY:9,100)
RandomBlock(-8,11,-3,CONCRETE:7,65,quark:iron_plate,10,quark:iron_plate:1,10,STAINED_CLAY:15,10,STAINED_CLAY:9,100)
RandomBlock(-8,11,-2,CONCRETE:7,65,quark:iron_plate,10,quark:iron_plate:1,10,STAINED_CLAY:15,10,STAINED_CLAY:9,100)
RandomBlock(-8,11,-1,CONCRETE:7,65,quark:iron_plate,10,quark:iron_plate:1,10,STAINED_CLAY:15,10,STAINED_CLAY:9,100)
RandomBlock(-8,11,0,CONCRETE:7,65,quark:iron_plate,10,quark:iron_plate:1,10,STAINED_CLAY:15,10,STAINED_CLAY:9,100)
RandomBlock(-8,11,1,CONCRETE:7,65,quark:iron_plate,10,quark:iron_plate:1,10,STAINED_CLAY:15,10,STAINED_CLAY:9,100)
RandomBlock(-8,11,2,CONCRETE:7,65,quark:iron_plate,10,quark:iron_plate:1,10,STAINED_CLAY:15,10,STAINED_CLAY:9,100)
RandomBlock(-8,11,3,CONCRETE:7,65,quark:iron_plate,10,quark:iron_plate:1,10,STAINED_CLAY:15,10,STAINED_CLAY:9,100)
RandomBlock(-8,11,4,CONCRETE:7,65,quark:iron_plate,10,quark:iron_plate:1,10,STAINED_CLAY:15,10,STAINED_CLAY:9,100)
RandomBlock(-8,11,5,CONCRETE:7,65,quark:iron_plate,10,quark:iron_plate:1,10,STAINED_CLAY:15,10,STAINED_CLAY:9,100)
RandomBlock(-8,11,6,CONCRETE:7,65,quark:iron_plate,10,quark:iron_plate:1,10,STAINED_CLAY:15,10,STAINED_CLAY:9,100)
RandomBlock(-8,11,7,CONCRETE:7,65,quark:iron_plate,10,quark:iron_plate:1,10,STAINED_CLAY:15,10,STAINED_CLAY:9,100)
RandomBlock(-8,11,8,CONCRETE:7,65,quark:iron_plate,10,quark:iron_plate:1,10,STAINED_CLAY:15,10,STAINED_CLAY:9,100)
RandomBlock(-8,12,-7,CONCRETE:7,65,quark:iron_plate,10,quark:iron_plate:1,10,STAINED_CLAY:15,10,STAINED_CLAY:9,100)
RandomBlock(-8,12,-6,CONCRETE:7,65,quark:iron_plate,10,quark:iron_plate:1,10,STAINED_CLAY:15,10,STAINED_CLAY:9,100)
RandomBlock(-8,12,-5,CONCRETE:7,65,quark:iron_plate,10,quark:iron_plate:1,10,STAINED_CLAY:15,10,STAINED_CLAY:9,100)
RandomBlock(-8,12,-4,CONCRETE:7,65,quark:iron_plate,10,quark:iron_plate:1,10,STAINED_CLAY:15,10,STAINED_CLAY:9,100)
RandomBlock(-8,12,-3,CONCRETE:7,65,quark:iron_plate,10,quark:iron_plate:1,10,STAINED_CLAY:15,10,STAINED_CLAY:9,100)
RandomBlock(-8,12,-2,CONCRETE:7,65,quark:iron_plate,10,quark:iron_plate:1,10,STAINED_CLAY:15,10,STAINED_CLAY:9,100)
RandomBlock(-8,12,-1,CONCRETE:7,65,quark:iron_plate,10,quark:iron_plate:1,10,STAINED_CLAY:15,10,STAINED_CLAY:9,100)
RandomBlock(-8,12,0,CONCRETE:7,65,quark:iron_plate,10,quark:iron_plate:1,10,STAINED_CLAY:15,10,STAINED_CLAY:9,100)
RandomBlock(-8,12,1,CONCRETE:7,65,quark:iron_plate,10,quark:iron_plate:1,10,STAINED_CLAY:15,10,STAINED_CLAY:9,100)
RandomBlock(-8,12,2,CONCRETE:7,65,quark:iron_plate,10,quark:iron_plate:1,10,STAINED_CLAY:15,10,STAINED_CLAY:9,100)
RandomBlock(-8,12,3,CONCRETE:7,65,quark:iron_plate,10,quark:iron_plate:1,10,STAINED_CLAY:15,10,STAINED_CLAY:9,100)
RandomBlock(-8,12,4,CONCRETE:7,65,quark:iron_plate,10,quark:iron_plate:1,10,STAINED_CLAY:15,10,STAINED_CLAY:9,100)
RandomBlock(-8,12,5,CONCRETE:7,65,quark:iron_plate,10,quark:iron_plate:1,10,STAINED_CLAY:15,10,STAINED_CLAY:9,100)
RandomBlock(-8,12,6,CONCRETE:7,65,quark:iron_plate,10,quark:iron_plate:1,10,STAINED_CLAY:15,10,STAINED_CLAY:9,100)
RandomBlock(-8,12,7,CONCRETE:7,65,quark:iron_plate,10,quark:iron_plate:1,10,STAINED_CLAY:15,10,STAINED_CLAY:9,100)
RandomBlock(-8,12,8,CONCRETE:7,65,quark:iron_plate,10,quark:iron_plate:1,10,STAINED_CLAY:15,10,STAINED_CLAY:9,100)
RandomBlock(-8,13,-7,CONCRETE:7,65,quark:iron_plate,10,quark:iron_plate:1,10,STAINED_CLAY:15,10,STAINED_CLAY:9,100)
RandomBlock(-8,13,-6,CONCRETE:7,65,quark:iron_plate,10,quark:iron_plate:1,10,STAINED_CLAY:15,10,STAINED_CLAY:9,100)
RandomBlock(-8,13,-5,CONCRETE:7,65,quark:iron_plate,10,quark:iron_plate:1,10,STAINED_CLAY:15,10,STAINED_CLAY:9,100)
RandomBlock(-8,13,-4,CONCRETE:7,65,quark:iron_plate,10,quark:iron_plate:1,10,STAINED_CLAY:15,10,STAINED_CLAY:9,100)
RandomBlock(-8,13,-3,CONCRETE:7,65,quark:iron_plate,10,quark:iron_plate:1,10,STAINED_CLAY:15,10,STAINED_CLAY:9,100)
RandomBlock(-8,13,-2,CONCRETE:7,65,quark:iron_plate,10,quark:iron_plate:1,10,STAINED_CLAY:15,10,STAINED_CLAY:9,100)
RandomBlock(-8,13,-1,CONCRETE:7,65,quark:iron_plate,10,quark:iron_plate:1,10,STAINED_CLAY:15,10,STAINED_CLAY:9,100)
RandomBlock(-8,13,0,CONCRETE:7,65,quark:iron_plate,10,quark:iron_plate:1,10,STAINED_CLAY:15,10,STAINED_CLAY:9,100)
RandomBlock(-8,13,1,CONCRETE:7,65,quark:iron_plate,10,quark:iron_plate:1,10,STAINED_CLAY:15,10,STAINED_CLAY:9,100)
RandomBlock(-8,13,2,CONCRETE:7,65,quark:iron_plate,10,quark:iron_plate:1,10,STAINED_CLAY:15,10,STAINED_CLAY:9,100)
RandomBlock(-8,13,3,CONCRETE:7,65,quark:iron_plate,10,quark:iron_plate:1,10,STAINED_CLAY:15,10,STAINED_CLAY:9,100)
RandomBlock(-8,13,4,CONCRETE:7,65,quark:iron_plate,10,quark:iron_plate:1,10,STAINED_CLAY:15,10,STAINED_CLAY:9,100)
RandomBlock(-8,13,5,CONCRETE:7,65,quark:iron_plate,10,quark:iron_plate:1,10,STAINED_CLAY:15,10,STAINED_CLAY:9,100)
RandomBlock(-8,13,6,CONCRETE:7,65,quark:iron_plate,10,quark:iron_plate:1,10,STAINED_CLAY:15,10,STAINED_CLAY:9,100)
RandomBlock(-8,13,7,CONCRETE:7,65,quark:iron_plate,10,quark:iron_plate:1,10,STAINED_CLAY:15,10,STAINED_CLAY:9,100)
RandomBlock(-8,13,8,CONCRETE:7,65,quark:iron_plate,10,quark:iron_plate:1,10,STAINED_CLAY:15,10,STAINED_CLAY:9,100)
RandomBlock(-8,14,-7,CONCRETE:7,65,quark:iron_plate,10,quark:iron_plate:1,10,STAINED_CLAY:15,10,STAINED_CLAY:9,100)
RandomBlock(-8,14,-6,CONCRETE:7,65,quark:iron_plate,10,quark:iron_plate:1,10,STAINED_CLAY:15,10,STAINED_CLAY:9,100)
RandomBlock(-8,14,-5,CONCRETE:7,65,quark:iron_plate,10,quark:iron_plate:1,10,STAINED_CLAY:15,10,STAINED_CLAY:9,100)
RandomBlock(-8,14,-4,CONCRETE:7,65,quark:iron_plate,10,quark:iron_plate:1,10,STAINED_CLAY:15,10,STAINED_CLAY:9,100)
RandomBlock(-8,14,-3,CONCRETE:7,65,quark:iron_plate,10,quark:iron_plate:1,10,STAINED_CLAY:15,10,STAINED_CLAY:9,100)
RandomBlock(-8,14,-2,CONCRETE:7,65,quark:iron_plate,10,quark:iron_plate:1,10,STAINED_CLAY:15,10,STAINED_CLAY:9,100)
RandomBlock(-8,14,-1,CONCRETE:7,65,quark:iron_plate,10,quark:iron_plate:1,10,STAINED_CLAY:15,10,STAINED_CLAY:9,100)
RandomBlock(-8,14,0,CONCRETE:7,65,quark:iron_plate,10,quark:iron_plate:1,10,STAINED_CLAY:15,10,STAINED_CLAY:9,100)
RandomBlock(-8,14,1,CONCRETE:7,65,quark:iron_plate,10,quark:iron_plate:1,10,STAINED_CLAY:15,10,STAINED_CLAY:9,100)
RandomBlock(-8,14,2,CONCRETE:7,65,quark:iron_plate,10,quark:iron_plate:1,10,STAINED_CLAY:15,10,STAINED_CLAY:9,100)
RandomBlock(-8,14,3,CONCRETE:7,65,quark:iron_plate,10,quark:iron_plate:1,10,STAINED_CLAY:15,10,STAINED_CLAY:9,100)
RandomBlock(-8,14,4,CONCRETE:7,65,quark:iron_plate,10,quark:iron_plate:1,10,STAINED_CLAY:15,10,STAINED_CLAY:9,100)
RandomBlock(-8,14,5,CONCRETE:7,65,quark:iron_plate,10,quark:iron_plate:1,10,STAINED_CLAY:15,10,STAINED_CLAY:9,100)
RandomBlock(-8,14,6,CONCRETE:7,65,quark:iron_plate,10,quark:iron_plate:1,10,STAINED_CLAY:15,10,STAINED_CLAY:9,100)
RandomBlock(-8,14,7,CONCRETE:7,65,quark:iron_plate,10,quark:iron_plate:1,10,STAINED_CLAY:15,10,STAINED_CLAY:9,100)
RandomBlock(-8,14,8,CONCRETE:7,65,quark:iron_plate,10,quark:iron_plate:1,10,STAINED_CLAY:15,10,STAINED_CLAY:9,100)
RandomBlock(-8,15,-7,CONCRETE:7,65,quark:iron_plate,10,quark:iron_plate:1,10,STAINED_CLAY:15,10,STAINED_CLAY:9,100)
RandomBlock(-8,15,-6,CONCRETE:7,65,quark:iron_plate,10,quark:iron_plate:1,10,STAINED_CLAY:15,10,STAINED_CLAY:9,100)
RandomBlock(-8,15,-5,CONCRETE:7,65,quark:iron_plate,10,quark:iron_plate:1,10,STAINED_CLAY:15,10,STAINED_CLAY:9,100)
RandomBlock(-8,15,-4,CONCRETE:7,65,quark:iron_plate,10,quark:iron_plate:1,10,STAINED_CLAY:15,10,STAINED_CLAY:9,100)
RandomBlock(-8,15,-3,CONCRETE:7,65,quark:iron_plate,10,quark:iron_plate:1,10,STAINED_CLAY:15,10,STAINED_CLAY:9,100)
RandomBlock(-8,15,-2,CONCRETE:7,65,quark:iron_plate,10,quark:iron_plate:1,10,STAINED_CLAY:15,10,STAINED_CLAY:9,100)
RandomBlock(-8,15,-1,CONCRETE:7,65,quark:iron_plate,10,quark:iron_plate:1,10,STAINED_CLAY:15,10,STAINED_CLAY:9,100)
RandomBlock(-8,15,0,CONCRETE:7,65,quark:iron_plate,10,quark:iron_plate:1,10,STAINED_CLAY:15,10,STAINED_CLAY:9,100)
RandomBlock(-8,15,1,CONCRETE:7,65,quark:iron_plate,10,quark:iron_plate:1,10,STAINED_CLAY:15,10,STAINED_CLAY:9,100)
RandomBlock(-8,15,2,CONCRETE:7,65,quark:iron_plate,10,quark:iron_plate:1,10,STAINED_CLAY:15,10,STAINED_CLAY:9,100)
RandomBlock(-8,15,3,CONCRETE:7,65,quark:iron_plate,10,quark:iron_plate:1,10,STAINED_CLAY:15,10,STAINED_CLAY:9,100)
RandomBlock(-8,15,4,CONCRETE:7,65,quark:iron_plate,10,quark:iron_plate:1,10,STAINED_CLAY:15,10,STAINED_CLAY:9,100)
RandomBlock(-8,15,5,CONCRETE:7,65,quark:iron_plate,10,quark:iron_plate:1,10,STAINED_CLAY:15,10,STAINED_CLAY:9,100)
RandomBlock(-8,15,6,CONCRETE:7,65,quark:iron_plate,10,quark:iron_plate:1,10,STAINED_CLAY:15,10,STAINED_CLAY:9,100)
RandomBlock(-8,15,7,CONCRETE:7,65,quark:iron_plate,10,quark:iron_plate:1,10,STAINED_CLAY:15,10,STAINED_CLAY:9,100)
RandomBlock(-8,15,8,CONCRETE:7,65,quark:iron_plate,10,quark:iron_plate:1,10,STAINED_CLAY:15,10,STAINED_CLAY:9,100)
RandomBlock(-8,16,-7,CONCRETE:7,65,quark:iron_plate,10,quark:iron_plate:1,10,STAINED_CLAY:15,10,STAINED_CLAY:9,100)
RandomBlock(-8,16,-6,CONCRETE:7,65,quark:iron_plate,10,quark:iron_plate:1,10,STAINED_CLAY:15,10,STAINED_CLAY:9,100)
RandomBlock(-8,16,-5,CONCRETE:7,65,quark:iron_plate,10,quark:iron_plate:1,10,STAINED_CLAY:15,10,STAINED_CLAY:9,100)
RandomBlock(-8,16,-4,CONCRETE:7,65,quark:iron_plate,10,quark:iron_plate:1,10,STAINED_CLAY:15,10,STAINED_CLAY:9,100)
RandomBlock(-8,16,-3,CONCRETE:7,65,quark:iron_plate,10,quark:iron_plate:1,10,STAINED_CLAY:15,10,STAINED_CLAY:9,100)
RandomBlock(-8,16,-2,CONCRETE:7,65,quark:iron_plate,10,quark:iron_plate:1,10,STAINED_CLAY:15,10,STAINED_CLAY:9,100)
RandomBlock(-8,16,-1,CONCRETE:7,65,quark:iron_plate,10,quark:iron_plate:1,10,STAINED_CLAY:15,10,STAINED_CLAY:9,100)
RandomBlock(-8,16,0,CONCRETE:7,65,quark:iron_plate,10,quark:iron_plate:1,10,STAINED_CLAY:15,10,STAINED_CLAY:9,100)
RandomBlock(-8,16,1,CONCRETE:7,65,quark:iron_plate,10,quark:iron_plate:1,10,STAINED_CLAY:15,10,STAINED_CLAY:9,100)
RandomBlock(-8,16,2,CONCRETE:7,65,quark:iron_plate,10,quark:iron_plate:1,10,STAINED_CLAY:15,10,STAINED_CLAY:9,100)
RandomBlock(-8,16,3,CONCRETE:7,65,quark:iron_plate,10,quark:iron_plate:1,10,STAINED_CLAY:15,10,STAINED_CLAY:9,100)
RandomBlock(-8,16,4,CONCRETE:7,65,quark:iron_plate,10,quark:iron_plate:1,10,STAINED_CLAY:15,10,STAINED_CLAY:9,100)
RandomBlock(-8,16,5,CONCRETE:7,65,quark:iron_plate,10,quark:iron_plate:1,10,STAINED_CLAY:15,10,STAINED_CLAY:9,100)
RandomBlock(-8,16,6,CONCRETE:7,65,quark:iron_plate,10,quark:iron_plate:1,10,STAINED_CLAY:15,10,STAINED_CLAY:9,100)
RandomBlock(-8,16,7,CONCRETE:7,65,quark:iron_plate,10,quark:iron_plate:1,10,STAINED_CLAY:15,10,STAINED_CLAY:9,100)
RandomBlock(-8,16,8,CONCRETE:7,65,quark:iron_plate,10,quark:iron_plate:1,10,STAINED_CLAY:15,10,STAINED_CLAY:9,100)
Block(-8,17,-7,DOUBLE_STEP:0)
RandomBlock(-8,17,-6,CONCRETE:7,65,quark:iron_plate,10,quark:iron_plate:1,10,STAINED_CLAY:15,10,STAINED_CLAY:9,100)
RandomBlock(-8,17,-5,CONCRETE:7,65,quark:iron_plate,10,quark:iron_plate:1,10,STAINED_CLAY:15,10,STAINED_CLAY:9,100)
Block(-8,17,-4,DOUBLE_STEP:0)
RandomBlock(-8,17,-3,CONCRETE:7,65,quark:iron_plate,10,quark:iron_plate:1,10,STAINED_CLAY:15,10,STAINED_CLAY:9,100)
RandomBlock(-8,17,-2,CONCRETE:7,65,quark:iron_plate,10,quark:iron_plate:1,10,STAINED_CLAY:15,10,STAINED_CLAY:9,100)
Block(-8,17,-1,DOUBLE_STEP:0)
RandomBlock(-8,17,0,CONCRETE:7,65,quark:iron_plate,10,quark:iron_plate:1,10,STAINED_CLAY:15,10,STAINED_CLAY:9,100)
RandomBlock(-8,17,1,CONCRETE:7,65,quark:iron_plate,10,quark:iron_plate:1,10,STAINED_CLAY:15,10,STAINED_CLAY:9,100)
Block(-8,17,2,DOUBLE_STEP:0)
RandomBlock(-8,17,3,CONCRETE:7,65,quark:iron_plate,10,quark:iron_plate:1,10,STAINED_CLAY:15,10,STAINED_CLAY:9,100)
RandomBlock(-8,17,4,CONCRETE:7,65,quark:iron_plate,10,quark:iron_plate:1,10,STAINED_CLAY:15,10,STAINED_CLAY:9,100)
Block(-8,17,5,DOUBLE_STEP:0)
RandomBlock(-8,17,6,CONCRETE:7,65,quark:iron_plate,10,quark:iron_plate:1,10,STAINED_CLAY:15,10,STAINED_CLAY:9,100)
RandomBlock(-8,17,7,CONCRETE:7,65,quark:iron_plate,10,quark:iron_plate:1,10,STAINED_CLAY:15,10,STAINED_CLAY:9,100)
Block(-8,17,8,DOUBLE_STEP:0)
Block(-8,18,-7,COBBLE_WALL:0)
Block(-8,18,-4,COBBLE_WALL:0)
Block(-8,18,-1,COBBLE_WALL:0)
Block(-8,18,2,COBBLE_WALL:0)
Block(-8,18,5,COBBLE_WALL:0)
Block(-8,18,8,COBBLE_WALL:0)
RandomBlock(-7,0,-7,CONCRETE:7,65,quark:iron_plate,10,quark:iron_plate:1,10,STAINED_CLAY:15,10,STAINED_CLAY:9,100)
RandomBlock(-7,0,-6,CONCRETE:7,65,quark:iron_plate,10,quark:iron_plate:1,10,STAINED_CLAY:15,10,STAINED_CLAY:9,100)
RandomBlock(-7,0,-5,CONCRETE:7,65,quark:iron_plate,10,quark:iron_plate:1,10,STAINED_CLAY:15,10,STAINED_CLAY:9,100)
RandomBlock(-7,0,-4,CONCRETE:7,65,quark:iron_plate,10,quark:iron_plate:1,10,STAINED_CLAY:15,10,STAINED_CLAY:9,100)
RandomBlock(-7,0,-3,CONCRETE:7,65,quark:iron_plate,10,quark:iron_plate:1,10,STAINED_CLAY:15,10,STAINED_CLAY:9,100)
RandomBlock(-7,0,-2,CONCRETE:7,65,quark:iron_plate,10,quark:iron_plate:1,10,STAINED_CLAY:15,10,STAINED_CLAY:9,100)
RandomBlock(-7,0,-1,CONCRETE:7,65,quark:iron_plate,10,quark:iron_plate:1,10,STAINED_CLAY:15,10,STAINED_CLAY:9,100)
RandomBlock(-7,0,0,CONCRETE:7,65,quark:iron_plate,10,quark:iron_plate:1,10,STAINED_CLAY:15,10,STAINED_CLAY:9,100)
RandomBlock(-7,0,1,CONCRETE:7,65,quark:iron_plate,10,quark:iron_plate:1,10,STAINED_CLAY:15,10,STAINED_CLAY:9,100)
RandomBlock(-7,0,2,CONCRETE:7,65,quark:iron_plate,10,quark:iron_plate:1,10,STAINED_CLAY:15,10,STAINED_CLAY:9,100)
RandomBlock(-7,0,3,CONCRETE:7,65,quark:iron_plate,10,quark:iron_plate:1,10,STAINED_CLAY:15,10,STAINED_CLAY:9,100)
RandomBlock(-7,0,4,CONCRETE:7,65,quark:iron_plate,10,quark:iron_plate:1,10,STAINED_CLAY:15,10,STAINED_CLAY:9,100)
RandomBlock(-7,0,5,CONCRETE:7,65,quark:iron_plate,10,quark:iron_plate:1,10,STAINED_CLAY:15,10,STAINED_CLAY:9,100)
RandomBlock(-7,0,6,CONCRETE:7,65,quark:iron_plate,10,quark:iron_plate:1,10,STAINED_CLAY:15,10,STAINED_CLAY:9,100)
RandomBlock(-7,0,7,CONCRETE:7,65,quark:iron_plate,10,quark:iron_plate:1,10,STAINED_CLAY:15,10,STAINED_CLAY:9,100)
RandomBlock(-7,0,8,CONCRETE:7,65,quark:iron_plate,10,quark:iron_plate:1,10,STAINED_CLAY:15,10,STAINED_CLAY:9,100)
RandomBlock(-7,1,-7,CONCRETE:7,65,quark:iron_plate,10,quark:iron_plate:1,10,STAINED_CLAY:15,10,STAINED_CLAY:9,100)
RandomBlock(-7,1,-6,CONCRETE:7,65,quark:iron_plate,10,quark:iron_plate:1,10,STAINED_CLAY:15,10,STAINED_CLAY:9,100)
RandomBlock(-7,1,-5,CONCRETE:7,65,quark:iron_plate,10,quark:iron_plate:1,10,STAINED_CLAY:15,10,STAINED_CLAY:9,100)
RandomBlock(-7,1,-4,CONCRETE:7,65,quark:iron_plate,10,quark:iron_plate:1,10,STAINED_CLAY:15,10,STAINED_CLAY:9,100)
RandomBlock(-7,1,-3,CONCRETE:7,65,quark:iron_plate,10,quark:iron_plate:1,10,STAINED_CLAY:15,10,STAINED_CLAY:9,100)
RandomBlock(-7,1,-2,CONCRETE:7,65,quark:iron_plate,10,quark:iron_plate:1,10,STAINED_CLAY:15,10,STAINED_CLAY:9,100)
RandomBlock(-7,1,-1,CONCRETE:7,65,quark:iron_plate,10,quark:iron_plate:1,10,STAINED_CLAY:15,10,STAINED_CLAY:9,100)
RandomBlock(-7,1,0,CONCRETE:7,65,quark:iron_plate,10,quark:iron_plate:1,10,STAINED_CLAY:15,10,STAINED_CLAY:9,100)
RandomBlock(-7,1,1,CONCRETE:7,65,quark:iron_plate,10,quark:iron_plate:1,10,STAINED_CLAY:15,10,STAINED_CLAY:9,100)
RandomBlock(-7,1,2,CONCRETE:7,65,quark:iron_plate,10,quark:iron_plate:1,10,STAINED_CLAY:15,10,STAINED_CLAY:9,100)
RandomBlock(-7,1,3,CONCRETE:7,65,quark:iron_plate,10,quark:iron_plate:1,10,STAINED_CLAY:15,10,STAINED_CLAY:9,100)
RandomBlock(-7,1,4,CONCRETE:7,65,quark:iron_plate,10,quark:iron_plate:1,10,STAINED_CLAY:15,10,STAINED_CLAY:9,100)
RandomBlock(-7,1,5,CONCRETE:7,65,quark:iron_plate,10,quark:iron_plate:1,10,STAINED_CLAY:15,10,STAINED_CLAY:9,100)
RandomBlock(-7,1,6,CONCRETE:7,65,quark:iron_plate,10,quark:iron_plate:1,10,STAINED_CLAY:15,10,STAINED_CLAY:9,100)
RandomBlock(-7,1,7,CONCRETE:7,65,quark:iron_plate,10,quark:iron_plate:1,10,STAINED_CLAY:15,10,STAINED_CLAY:9,100)
RandomBlock(-7,1,8,CONCRETE:7,65,quark:iron_plate,10,quark:iron_plate:1,10,STAINED_CLAY:15,10,STAINED_CLAY:9,100)
RandomBlock(-7,2,-7,CONCRETE:7,65,quark:iron_plate,10,quark:iron_plate:1,10,STAINED_CLAY:15,10,STAINED_CLAY:9,100)
RandomBlock(-7,2,-6,CONCRETE:7,65,quark:iron_plate,10,quark:iron_plate:1,10,STAINED_CLAY:15,10,STAINED_CLAY:9,100)
RandomBlock(-7,2,-5,CONCRETE:7,65,quark:iron_plate,10,quark:iron_plate:1,10,STAINED_CLAY:15,10,STAINED_CLAY:9,100)
RandomBlock(-7,2,-4,CONCRETE:7,65,quark:iron_plate,10,quark:iron_plate:1,10,STAINED_CLAY:15,10,STAINED_CLAY:9,100)
RandomBlock(-7,2,-3,CONCRETE:7,65,quark:iron_plate,10,quark:iron_plate:1,10,STAINED_CLAY:15,10,STAINED_CLAY:9,100)
RandomBlock(-7,2,-2,CONCRETE:7,65,quark:iron_plate,10,quark:iron_plate:1,10,STAINED_CLAY:15,10,STAINED_CLAY:9,100)
RandomBlock(-7,2,-1,CONCRETE:7,65,quark:iron_plate,10,quark:iron_plate:1,10,STAINED_CLAY:15,10,STAINED_CLAY:9,100)
RandomBlock(-7,2,0,CONCRETE:7,65,quark:iron_plate,10,quark:iron_plate:1,10,STAINED_CLAY:15,10,STAINED_CLAY:9,100)
RandomBlock(-7,2,1,CONCRETE:7,65,quark:iron_plate,10,quark:iron_plate:1,10,STAINED_CLAY:15,10,STAINED_CLAY:9,100)
RandomBlock(-7,2,2,CONCRETE:7,65,quark:iron_plate,10,quark:iron_plate:1,10,STAINED_CLAY:15,10,STAINED_CLAY:9,100)
RandomBlock(-7,2,3,CONCRETE:7,65,quark:iron_plate,10,quark:iron_plate:1,10,STAINED_CLAY:15,10,STAINED_CLAY:9,100)
RandomBlock(-7,2,4,CONCRETE:7,65,quark:iron_plate,10,quark:iron_plate:1,10,STAINED_CLAY:15,10,STAINED_CLAY:9,100)
RandomBlock(-7,2,5,CONCRETE:7,65,quark:iron_plate,10,quark:iron_plate:1,10,STAINED_CLAY:15,10,STAINED_CLAY:9,100)
RandomBlock(-7,2,6,CONCRETE:7,65,quark:iron_plate,10,quark:iron_plate:1,10,STAINED_CLAY:15,10,STAINED_CLAY:9,100)
RandomBlock(-7,2,7,CONCRETE:7,65,quark:iron_plate,10,quark:iron_plate:1,10,STAINED_CLAY:15,10,STAINED_CLAY:9,100)
RandomBlock(-7,2,8,CONCRETE:7,65,quark:iron_plate,10,quark:iron_plate:1,10,STAINED_CLAY:15,10,STAINED_CLAY:9,100)
RandomBlock(-7,3,-7,CONCRETE:7,65,quark:iron_plate,10,quark:iron_plate:1,10,STAINED_CLAY:15,10,STAINED_CLAY:9,100)
RandomBlock(-7,3,-6,CONCRETE:7,65,quark:iron_plate,10,quark:iron_plate:1,10,STAINED_CLAY:15,10,STAINED_CLAY:9,100)
RandomBlock(-7,3,-5,CONCRETE:7,65,quark:iron_plate,10,quark:iron_plate:1,10,STAINED_CLAY:15,10,STAINED_CLAY:9,100)
RandomBlock(-7,3,-4,CONCRETE:7,65,quark:iron_plate,10,quark:iron_plate:1,10,STAINED_CLAY:15,10,STAINED_CLAY:9,100)
RandomBlock(-7,3,-3,CONCRETE:7,65,quark:iron_plate,10,quark:iron_plate:1,10,STAINED_CLAY:15,10,STAINED_CLAY:9,100)
RandomBlock(-7,3,-2,CONCRETE:7,65,quark:iron_plate,10,quark:iron_plate:1,10,STAINED_CLAY:15,10,STAINED_CLAY:9,100)
RandomBlock(-7,3,-1,CONCRETE:7,65,quark:iron_plate,10,quark:iron_plate:1,10,STAINED_CLAY:15,10,STAINED_CLAY:9,100)
RandomBlock(-7,3,0,CONCRETE:7,65,quark:iron_plate,10,quark:iron_plate:1,10,STAINED_CLAY:15,10,STAINED_CLAY:9,100)
RandomBlock(-7,3,1,CONCRETE:7,65,quark:iron_plate,10,quark:iron_plate:1,10,STAINED_CLAY:15,10,STAINED_CLAY:9,100)
RandomBlock(-7,3,2,CONCRETE:7,65,quark:iron_plate,10,quark:iron_plate:1,10,STAINED_CLAY:15,10,STAINED_CLAY:9,100)
RandomBlock(-7,3,3,CONCRETE:7,65,quark:iron_plate,10,quark:iron_plate:1,10,STAINED_CLAY:15,10,STAINED_CLAY:9,100)
RandomBlock(-7,3,4,CONCRETE:7,65,quark:iron_plate,10,quark:iron_plate:1,10,STAINED_CLAY:15,10,STAINED_CLAY:9,100)
RandomBlock(-7,3,5,CONCRETE:7,65,quark:iron_plate,10,quark:iron_plate:1,10,STAINED_CLAY:15,10,STAINED_CLAY:9,100)
RandomBlock(-7,3,6,CONCRETE:7,65,quark:iron_plate,10,quark:iron_plate:1,10,STAINED_CLAY:15,10,STAINED_CLAY:9,100)
RandomBlock(-7,3,7,CONCRETE:7,65,quark:iron_plate,10,quark:iron_plate:1,10,STAINED_CLAY:15,10,STAINED_CLAY:9,100)
RandomBlock(-7,3,8,CONCRETE:7,65,quark:iron_plate,10,quark:iron_plate:1,10,STAINED_CLAY:15,10,STAINED_CLAY:9,100)
RandomBlock(-7,4,-7,CONCRETE:7,65,quark:iron_plate,10,quark:iron_plate:1,10,STAINED_CLAY:15,10,STAINED_CLAY:9,100)
RandomBlock(-7,4,-6,CONCRETE:7,65,quark:iron_plate,10,quark:iron_plate:1,10,STAINED_CLAY:15,10,STAINED_CLAY:9,100)
RandomBlock(-7,4,-5,CONCRETE:7,65,quark:iron_plate,10,quark:iron_plate:1,10,STAINED_CLAY:15,10,STAINED_CLAY:9,100)
RandomBlock(-7,4,-4,CONCRETE:7,65,quark:iron_plate,10,quark:iron_plate:1,10,STAINED_CLAY:15,10,STAINED_CLAY:9,100)
RandomBlock(-7,4,-3,CONCRETE:7,65,quark:iron_plate,10,quark:iron_plate:1,10,STAINED_CLAY:15,10,STAINED_CLAY:9,100)
RandomBlock(-7,4,-2,CONCRETE:7,65,quark:iron_plate,10,quark:iron_plate:1,10,STAINED_CLAY:15,10,STAINED_CLAY:9,100)
RandomBlock(-7,4,-1,CONCRETE:7,65,quark:iron_plate,10,quark:iron_plate:1,10,STAINED_CLAY:15,10,STAINED_CLAY:9,100)
RandomBlock(-7,4,0,CONCRETE:7,65,quark:iron_plate,10,quark:iron_plate:1,10,STAINED_CLAY:15,10,STAINED_CLAY:9,100)
RandomBlock(-7,4,1,CONCRETE:7,65,quark:iron_plate,10,quark:iron_plate:1,10,STAINED_CLAY:15,10,STAINED_CLAY:9,100)
RandomBlock(-7,4,2,CONCRETE:7,65,quark:iron_plate,10,quark:iron_plate:1,10,STAINED_CLAY:15,10,STAINED_CLAY:9,100)
RandomBlock(-7,4,3,CONCRETE:7,65,quark:iron_plate,10,quark:iron_plate:1,10,STAINED_CLAY:15,10,STAINED_CLAY:9,100)
RandomBlock(-7,4,4,CONCRETE:7,65,quark:iron_plate,10,quark:iron_plate:1,10,STAINED_CLAY:15,10,STAINED_CLAY:9,100)
RandomBlock(-7,4,5,CONCRETE:7,65,quark:iron_plate,10,quark:iron_plate:1,10,STAINED_CLAY:15,10,STAINED_CLAY:9,100)
RandomBlock(-7,4,6,CONCRETE:7,65,quark:iron_plate,10,quark:iron_plate:1,10,STAINED_CLAY:15,10,STAINED_CLAY:9,100)
RandomBlock(-7,4,7,CONCRETE:7,65,quark:iron_plate,10,quark:iron_plate:1,10,STAINED_CLAY:15,10,STAINED_CLAY:9,100)
RandomBlock(-7,4,8,CONCRETE:7,65,quark:iron_plate,10,quark:iron_plate:1,10,STAINED_CLAY:15,10,STAINED_CLAY:9,100)
RandomBlock(-7,5,-7,CONCRETE:7,65,quark:iron_plate,10,quark:iron_plate:1,10,STAINED_CLAY:15,10,STAINED_CLAY:9,100)
RandomBlock(-7,5,-6,CONCRETE:7,65,quark:iron_plate,10,quark:iron_plate:1,10,STAINED_CLAY:15,10,STAINED_CLAY:9,100)
RandomBlock(-7,5,-5,CONCRETE:7,65,quark:iron_plate,10,quark:iron_plate:1,10,STAINED_CLAY:15,10,STAINED_CLAY:9,100)
RandomBlock(-7,5,-4,CONCRETE:7,65,quark:iron_plate,10,quark:iron_plate:1,10,STAINED_CLAY:15,10,STAINED_CLAY:9,100)
RandomBlock(-7,5,-3,CONCRETE:7,65,quark:iron_plate,10,quark:iron_plate:1,10,STAINED_CLAY:15,10,STAINED_CLAY:9,100)
RandomBlock(-7,5,-2,CONCRETE:7,65,quark:iron_plate,10,quark:iron_plate:1,10,STAINED_CLAY:15,10,STAINED_CLAY:9,100)
RandomBlock(-7,5,-1,CONCRETE:7,65,quark:iron_plate,10,quark:iron_plate:1,10,STAINED_CLAY:15,10,STAINED_CLAY:9,100)
RandomBlock(-7,5,0,CONCRETE:7,65,quark:iron_plate,10,quark:iron_plate:1,10,STAINED_CLAY:15,10,STAINED_CLAY:9,100)
RandomBlock(-7,5,1,CONCRETE:7,65,quark:iron_plate,10,quark:iron_plate:1,10,STAINED_CLAY:15,10,STAINED_CLAY:9,100)
RandomBlock(-7,5,2,CONCRETE:7,65,quark:iron_plate,10,quark:iron_plate:1,10,STAINED_CLAY:15,10,STAINED_CLAY:9,100)
RandomBlock(-7,5,3,CONCRETE:7,65,quark:iron_plate,10,quark:iron_plate:1,10,STAINED_CLAY:15,10,STAINED_CLAY:9,100)
RandomBlock(-7,5,4,CONCRETE:7,65,quark:iron_plate,10,quark:iron_plate:1,10,STAINED_CLAY:15,10,STAINED_CLAY:9,100)
RandomBlock(-7,5,5,CONCRETE:7,65,quark:iron_plate,10,quark:iron_plate:1,10,STAINED_CLAY:15,10,STAINED_CLAY:9,100)
RandomBlock(-7,5,6,CONCRETE:7,65,quark:iron_plate,10,quark:iron_plate:1,10,STAINED_CLAY:15,10,STAINED_CLAY:9,100)
RandomBlock(-7,5,7,CONCRETE:7,65,quark:iron_plate,10,quark:iron_plate:1,10,STAINED_CLAY:15,10,STAINED_CLAY:9,100)
RandomBlock(-7,5,8,CONCRETE:7,65,quark:iron_plate,10,quark:iron_plate:1,10,STAINED_CLAY:15,10,STAINED_CLAY:9,100)
RandomBlock(-7,6,-7,CONCRETE:7,65,quark:iron_plate,10,quark:iron_plate:1,10,STAINED_CLAY:15,10,STAINED_CLAY:9,100)
RandomBlock(-7,6,-6,CONCRETE:7,65,quark:iron_plate,10,quark:iron_plate:1,10,STAINED_CLAY:15,10,STAINED_CLAY:9,100)
RandomBlock(-7,6,-5,CONCRETE:7,65,quark:iron_plate,10,quark:iron_plate:1,10,STAINED_CLAY:15,10,STAINED_CLAY:9,100)
RandomBlock(-7,6,-4,CONCRETE:7,65,quark:iron_plate,10,quark:iron_plate:1,10,STAINED_CLAY:15,10,STAINED_CLAY:9,100)
RandomBlock(-7,6,-3,CONCRETE:7,65,quark:iron_plate,10,quark:iron_plate:1,10,STAINED_CLAY:15,10,STAINED_CLAY:9,100)
RandomBlock(-7,6,-2,CONCRETE:7,65,quark:iron_plate,10,quark:iron_plate:1,10,STAINED_CLAY:15,10,STAINED_CLAY:9,100)
RandomBlock(-7,6,-1,CONCRETE:7,65,quark:iron_plate,10,quark:iron_plate:1,10,STAINED_CLAY:15,10,STAINED_CLAY:9,100)
RandomBlock(-7,6,0,CONCRETE:7,65,quark:iron_plate,10,quark:iron_plate:1,10,STAINED_CLAY:15,10,STAINED_CLAY:9,100)
RandomBlock(-7,6,1,CONCRETE:7,65,quark:iron_plate,10,quark:iron_plate:1,10,STAINED_CLAY:15,10,STAINED_CLAY:9,100)
RandomBlock(-7,6,2,CONCRETE:7,65,quark:iron_plate,10,quark:iron_plate:1,10,STAINED_CLAY:15,10,STAINED_CLAY:9,100)
RandomBlock(-7,6,3,CONCRETE:7,65,quark:iron_plate,10,quark:iron_plate:1,10,STAINED_CLAY:15,10,STAINED_CLAY:9,100)
RandomBlock(-7,6,4,CONCRETE:7,65,quark:iron_plate,10,quark:iron_plate:1,10,STAINED_CLAY:15,10,STAINED_CLAY:9,100)
RandomBlock(-7,6,5,CONCRETE:7,65,quark:iron_plate,10,quark:iron_plate:1,10,STAINED_CLAY:15,10,STAINED_CLAY:9,100)
RandomBlock(-7,6,6,CONCRETE:7,65,quark:iron_plate,10,quark:iron_plate:1,10,STAINED_CLAY:15,10,STAINED_CLAY:9,100)
RandomBlock(-7,6,7,CONCRETE:7,65,quark:iron_plate,10,quark:iron_plate:1,10,STAINED_CLAY:15,10,STAINED_CLAY:9,100)
RandomBlock(-7,6,8,CONCRETE:7,65,quark:iron_plate,10,quark:iron_plate:1,10,STAINED_CLAY:15,10,STAINED_CLAY:9,100)
RandomBlock(-7,7,-7,CONCRETE:7,65,quark:iron_plate,10,quark:iron_plate:1,10,STAINED_CLAY:15,10,STAINED_CLAY:9,100)
RandomBlock(-7,7,-6,CONCRETE:7,65,quark:iron_plate,10,quark:iron_plate:1,10,STAINED_CLAY:15,10,STAINED_CLAY:9,100)
RandomBlock(-7,7,-5,CONCRETE:7,65,quark:iron_plate,10,quark:iron_plate:1,10,STAINED_CLAY:15,10,STAINED_CLAY:9,100)
RandomBlock(-7,7,-4,CONCRETE:7,65,quark:iron_plate,10,quark:iron_plate:1,10,STAINED_CLAY:15,10,STAINED_CLAY:9,100)
RandomBlock(-7,7,-3,CONCRETE:7,65,quark:iron_plate,10,quark:iron_plate:1,10,STAINED_CLAY:15,10,STAINED_CLAY:9,100)
RandomBlock(-7,7,-2,CONCRETE:7,65,quark:iron_plate,10,quark:iron_plate:1,10,STAINED_CLAY:15,10,STAINED_CLAY:9,100)
RandomBlock(-7,7,-1,CONCRETE:7,65,quark:iron_plate,10,quark:iron_plate:1,10,STAINED_CLAY:15,10,STAINED_CLAY:9,100)
RandomBlock(-7,7,0,CONCRETE:7,65,quark:iron_plate,10,quark:iron_plate:1,10,STAINED_CLAY:15,10,STAINED_CLAY:9,100)
RandomBlock(-7,7,1,CONCRETE:7,65,quark:iron_plate,10,quark:iron_plate:1,10,STAINED_CLAY:15,10,STAINED_CLAY:9,100)
RandomBlock(-7,7,2,CONCRETE:7,65,quark:iron_plate,10,quark:iron_plate:1,10,STAINED_CLAY:15,10,STAINED_CLAY:9,100)
RandomBlock(-7,7,3,CONCRETE:7,65,quark:iron_plate,10,quark:iron_plate:1,10,STAINED_CLAY:15,10,STAINED_CLAY:9,100)
RandomBlock(-7,7,4,CONCRETE:7,65,quark:iron_plate,10,quark:iron_plate:1,10,STAINED_CLAY:15,10,STAINED_CLAY:9,100)
RandomBlock(-7,7,5,CONCRETE:7,65,quark:iron_plate,10,quark:iron_plate:1,10,STAINED_CLAY:15,10,STAINED_CLAY:9,100)
RandomBlock(-7,7,6,CONCRETE:7,65,quark:iron_plate,10,quark:iron_plate:1,10,STAINED_CLAY:15,10,STAINED_CLAY:9,100)
RandomBlock(-7,7,7,CONCRETE:7,65,quark:iron_plate,10,quark:iron_plate:1,10,STAINED_CLAY:15,10,STAINED_CLAY:9,100)
RandomBlock(-7,7,8,CONCRETE:7,65,quark:iron_plate,10,quark:iron_plate:1,10,STAINED_CLAY:15,10,STAINED_CLAY:9,100)
RandomBlock(-7,8,-7,CONCRETE:7,65,quark:iron_plate,10,quark:iron_plate:1,10,STAINED_CLAY:15,10,STAINED_CLAY:9,100)
RandomBlock(-7,8,-6,CONCRETE:8,65,quark:iron_plate,10,quark:iron_plate:1,10,STAINED_CLAY:9,15,STAINED_CLAY:7,10,CONCRETE:8,100)
RandomBlock(-7,8,-5,CONCRETE:8,65,quark:iron_plate,10,quark:iron_plate:1,10,STAINED_CLAY:9,15,STAINED_CLAY:7,10,CONCRETE:8,100)
RandomBlock(-7,8,-4,CONCRETE:8,65,quark:iron_plate,10,quark:iron_plate:1,10,STAINED_CLAY:9,15,STAINED_CLAY:7,10,CONCRETE:8,100)
RandomBlock(-7,8,-3,CONCRETE:8,65,quark:iron_plate,10,quark:iron_plate:1,10,STAINED_CLAY:9,15,STAINED_CLAY:7,10,CONCRETE:8,100)
RandomBlock(-7,8,-2,CONCRETE:8,65,quark:iron_plate,10,quark:iron_plate:1,10,STAINED_CLAY:9,15,STAINED_CLAY:7,10,CONCRETE:8,100)
RandomBlock(-7,8,-1,CONCRETE:8,65,quark:iron_plate,10,quark:iron_plate:1,10,STAINED_CLAY:9,15,STAINED_CLAY:7,10,CONCRETE:8,100)
RandomBlock(-7,8,0,CONCRETE:8,65,quark:iron_plate,10,quark:iron_plate:1,10,STAINED_CLAY:9,15,STAINED_CLAY:7,10,CONCRETE:8,100)
RandomBlock(-7,8,1,CONCRETE:8,65,quark:iron_plate,10,quark:iron_plate:1,10,STAINED_CLAY:9,15,STAINED_CLAY:7,10,CONCRETE:8,100)
RandomBlock(-7,8,2,CONCRETE:8,65,quark:iron_plate,10,quark:iron_plate:1,10,STAINED_CLAY:9,15,STAINED_CLAY:7,10,CONCRETE:8,100)
RandomBlock(-7,8,3,CONCRETE:8,65,quark:iron_plate,10,quark:iron_plate:1,10,STAINED_CLAY:9,15,STAINED_CLAY:7,10,CONCRETE:8,100)
RandomBlock(-7,8,4,CONCRETE:8,65,quark:iron_plate,10,quark:iron_plate:1,10,STAINED_CLAY:9,15,STAINED_CLAY:7,10,CONCRETE:8,100)
RandomBlock(-7,8,5,CONCRETE:8,65,quark:iron_plate,10,quark:iron_plate:1,10,STAINED_CLAY:9,15,STAINED_CLAY:7,10,CONCRETE:8,100)
RandomBlock(-7,8,6,CONCRETE:8,65,quark:iron_plate,10,quark:iron_plate:1,10,STAINED_CLAY:9,15,STAINED_CLAY:7,10,CONCRETE:8,100)
RandomBlock(-7,8,7,CONCRETE:8,65,quark:iron_plate,10,quark:iron_plate:1,10,STAINED_CLAY:9,15,STAINED_CLAY:7,10,CONCRETE:8,100)
RandomBlock(-7,8,8,CONCRETE:8,65,quark:iron_plate,10,quark:iron_plate:1,10,STAINED_CLAY:9,15,STAINED_CLAY:7,10,CONCRETE:8,100)
RandomBlock(-7,9,-7,CONCRETE:7,65,quark:iron_plate,10,quark:iron_plate:1,10,STAINED_CLAY:15,10,STAINED_CLAY:9,100)
RandomBlock(-7,9,-6,CONCRETE:8,65,quark:iron_plate,10,quark:iron_plate:1,10,STAINED_CLAY:9,15,STAINED_CLAY:7,10,CONCRETE:8,100)
RandomBlock(-7,9,-5,CONCRETE:8,65,quark:iron_plate,10,quark:iron_plate:1,10,STAINED_CLAY:9,15,STAINED_CLAY:7,10,CONCRETE:8,100)
RandomBlock(-7,9,-4,CONCRETE:8,65,quark:iron_plate,10,quark:iron_plate:1,10,STAINED_CLAY:9,15,STAINED_CLAY:7,10,CONCRETE:8,100)
RandomBlock(-7,9,-3,CONCRETE:8,65,quark:iron_plate,10,quark:iron_plate:1,10,STAINED_CLAY:9,15,STAINED_CLAY:7,10,CONCRETE:8,100)
RandomBlock(-7,9,-2,CONCRETE:8,65,quark:iron_plate,10,quark:iron_plate:1,10,STAINED_CLAY:9,15,STAINED_CLAY:7,10,CONCRETE:8,100)
RandomBlock(-7,9,-1,CONCRETE:8,65,quark:iron_plate,10,quark:iron_plate:1,10,STAINED_CLAY:9,15,STAINED_CLAY:7,10,CONCRETE:8,100)
RandomBlock(-7,9,0,CONCRETE:8,65,quark:iron_plate,10,quark:iron_plate:1,10,STAINED_CLAY:9,15,STAINED_CLAY:7,10,CONCRETE:8,100)
RandomBlock(-7,9,1,CONCRETE:8,65,quark:iron_plate,10,quark:iron_plate:1,10,STAINED_CLAY:9,15,STAINED_CLAY:7,10,CONCRETE:8,100)
RandomBlock(-7,9,2,CONCRETE:8,65,quark:iron_plate,10,quark:iron_plate:1,10,STAINED_CLAY:9,15,STAINED_CLAY:7,10,CONCRETE:8,100)
RandomBlock(-7,9,3,CONCRETE:8,65,quark:iron_plate,10,quark:iron_plate:1,10,STAINED_CLAY:9,15,STAINED_CLAY:7,10,CONCRETE:8,100)
RandomBlock(-7,9,4,CONCRETE:8,65,quark:iron_plate,10,quark:iron_plate:1,10,STAINED_CLAY:9,15,STAINED_CLAY:7,10,CONCRETE:8,100)
RandomBlock(-7,9,5,CONCRETE:8,65,quark:iron_plate,10,quark:iron_plate:1,10,STAINED_CLAY:9,15,STAINED_CLAY:7,10,CONCRETE:8,100)
RandomBlock(-7,9,6,CONCRETE:8,65,quark:iron_plate,10,quark:iron_plate:1,10,STAINED_CLAY:9,15,STAINED_CLAY:7,10,CONCRETE:8,100)
RandomBlock(-7,9,7,CONCRETE:8,65,quark:iron_plate,10,quark:iron_plate:1,10,STAINED_CLAY:9,15,STAINED_CLAY:7,10,CONCRETE:8,100)
RandomBlock(-7,9,8,CONCRETE:8,65,quark:iron_plate,10,quark:iron_plate:1,10,STAINED_CLAY:9,15,STAINED_CLAY:7,10,CONCRETE:8,100)
RandomBlock(-7,10,-7,CONCRETE:7,65,quark:iron_plate,10,quark:iron_plate:1,10,STAINED_CLAY:15,10,STAINED_CLAY:9,100)
RandomBlock(-7,10,-6,CONCRETE:8,65,quark:iron_plate,10,quark:iron_plate:1,10,STAINED_CLAY:9,15,STAINED_CLAY:7,10,CONCRETE:8,100)
RandomBlock(-7,10,-5,CONCRETE:8,65,quark:iron_plate,10,quark:iron_plate:1,10,STAINED_CLAY:9,15,STAINED_CLAY:7,10,CONCRETE:8,100)
RandomBlock(-7,10,-4,CONCRETE:8,65,quark:iron_plate,10,quark:iron_plate:1,10,STAINED_CLAY:9,15,STAINED_CLAY:7,10,CONCRETE:8,100)
RandomBlock(-7,10,-3,CONCRETE:8,65,quark:iron_plate,10,quark:iron_plate:1,10,STAINED_CLAY:9,15,STAINED_CLAY:7,10,CONCRETE:8,100)
RandomBlock(-7,10,-2,CONCRETE:8,65,quark:iron_plate,10,quark:iron_plate:1,10,STAINED_CLAY:9,15,STAINED_CLAY:7,10,CONCRETE:8,100)
RandomBlock(-7,10,-1,CONCRETE:8,65,quark:iron_plate,10,quark:iron_plate:1,10,STAINED_CLAY:9,15,STAINED_CLAY:7,10,CONCRETE:8,100)
RandomBlock(-7,10,0,CONCRETE:8,65,quark:iron_plate,10,quark:iron_plate:1,10,STAINED_CLAY:9,15,STAINED_CLAY:7,10,CONCRETE:8,100)
RandomBlock(-7,10,1,CONCRETE:8,65,quark:iron_plate,10,quark:iron_plate:1,10,STAINED_CLAY:9,15,STAINED_CLAY:7,10,CONCRETE:8,100)
RandomBlock(-7,10,2,CONCRETE:8,65,quark:iron_plate,10,quark:iron_plate:1,10,STAINED_CLAY:9,15,STAINED_CLAY:7,10,CONCRETE:8,100)
RandomBlock(-7,10,3,CONCRETE:8,65,quark:iron_plate,10,quark:iron_plate:1,10,STAINED_CLAY:9,15,STAINED_CLAY:7,10,CONCRETE:8,100)
RandomBlock(-7,10,4,CONCRETE:8,65,quark:iron_plate,10,quark:iron_plate:1,10,STAINED_CLAY:9,15,STAINED_CLAY:7,10,CONCRETE:8,100)
RandomBlock(-7,10,5,CONCRETE:8,65,quark:iron_plate,10,quark:iron_plate:1,10,STAINED_CLAY:9,15,STAINED_CLAY:7,10,CONCRETE:8,100)
RandomBlock(-7,10,6,CONCRETE:8,65,quark:iron_plate,10,quark:iron_plate:1,10,STAINED_CLAY:9,15,STAINED_CLAY:7,10,CONCRETE:8,100)
RandomBlock(-7,10,7,CONCRETE:8,65,quark:iron_plate,10,quark:iron_plate:1,10,STAINED_CLAY:9,15,STAINED_CLAY:7,10,CONCRETE:8,100)
RandomBlock(-7,10,8,CONCRETE:8,65,quark:iron_plate,10,quark:iron_plate:1,10,STAINED_CLAY:9,15,STAINED_CLAY:7,10,CONCRETE:8,100)
RandomBlock(-7,11,-7,CONCRETE:7,65,quark:iron_plate,10,quark:iron_plate:1,10,STAINED_CLAY:15,10,STAINED_CLAY:9,100)
RandomBlock(-7,11,-6,CONCRETE:8,65,quark:iron_plate,10,quark:iron_plate:1,10,STAINED_CLAY:9,15,STAINED_CLAY:7,10,CONCRETE:8,100)
RandomBlock(-7,11,-5,CONCRETE:8,65,quark:iron_plate,10,quark:iron_plate:1,10,STAINED_CLAY:9,15,STAINED_CLAY:7,10,CONCRETE:8,100)
RandomBlock(-7,11,-4,CONCRETE:8,65,quark:iron_plate,10,quark:iron_plate:1,10,STAINED_CLAY:9,15,STAINED_CLAY:7,10,CONCRETE:8,100)
RandomBlock(-7,11,-3,CONCRETE:8,65,quark:iron_plate,10,quark:iron_plate:1,10,STAINED_CLAY:9,15,STAINED_CLAY:7,10,CONCRETE:8,100)
RandomBlock(-7,11,-2,CONCRETE:8,65,quark:iron_plate,10,quark:iron_plate:1,10,STAINED_CLAY:9,15,STAINED_CLAY:7,10,CONCRETE:8,100)
RandomBlock(-7,11,-1,CONCRETE:8,65,quark:iron_plate,10,quark:iron_plate:1,10,STAINED_CLAY:9,15,STAINED_CLAY:7,10,CONCRETE:8,100)
RandomBlock(-7,11,0,CONCRETE:8,65,quark:iron_plate,10,quark:iron_plate:1,10,STAINED_CLAY:9,15,STAINED_CLAY:7,10,CONCRETE:8,100)
RandomBlock(-7,11,1,CONCRETE:8,65,quark:iron_plate,10,quark:iron_plate:1,10,STAINED_CLAY:9,15,STAINED_CLAY:7,10,CONCRETE:8,100)
RandomBlock(-7,11,2,CONCRETE:8,65,quark:iron_plate,10,quark:iron_plate:1,10,STAINED_CLAY:9,15,STAINED_CLAY:7,10,CONCRETE:8,100)
RandomBlock(-7,11,3,CONCRETE:8,65,quark:iron_plate,10,quark:iron_plate:1,10,STAINED_CLAY:9,15,STAINED_CLAY:7,10,CONCRETE:8,100)
RandomBlock(-7,11,4,CONCRETE:8,65,quark:iron_plate,10,quark:iron_plate:1,10,STAINED_CLAY:9,15,STAINED_CLAY:7,10,CONCRETE:8,100)
RandomBlock(-7,11,5,CONCRETE:8,65,quark:iron_plate,10,quark:iron_plate:1,10,STAINED_CLAY:9,15,STAINED_CLAY:7,10,CONCRETE:8,100)
RandomBlock(-7,11,6,CONCRETE:8,65,quark:iron_plate,10,quark:iron_plate:1,10,STAINED_CLAY:9,15,STAINED_CLAY:7,10,CONCRETE:8,100)
RandomBlock(-7,11,7,CONCRETE:8,65,quark:iron_plate,10,quark:iron_plate:1,10,STAINED_CLAY:9,15,STAINED_CLAY:7,10,CONCRETE:8,100)
RandomBlock(-7,11,8,CONCRETE:8,65,quark:iron_plate,10,quark:iron_plate:1,10,STAINED_CLAY:9,15,STAINED_CLAY:7,10,CONCRETE:8,100)
RandomBlock(-7,12,-7,CONCRETE:7,65,quark:iron_plate,10,quark:iron_plate:1,10,STAINED_CLAY:15,10,STAINED_CLAY:9,100)
RandomBlock(-7,12,-6,CONCRETE:8,65,quark:iron_plate,10,quark:iron_plate:1,10,STAINED_CLAY:9,15,STAINED_CLAY:7,10,CONCRETE:8,100)
RandomBlock(-7,12,-5,CONCRETE:8,65,quark:iron_plate,10,quark:iron_plate:1,10,STAINED_CLAY:9,15,STAINED_CLAY:7,10,CONCRETE:8,100)
RandomBlock(-7,12,-4,CONCRETE:8,65,quark:iron_plate,10,quark:iron_plate:1,10,STAINED_CLAY:9,15,STAINED_CLAY:7,10,CONCRETE:8,100)
RandomBlock(-7,12,-3,CONCRETE:8,65,quark:iron_plate,10,quark:iron_plate:1,10,STAINED_CLAY:9,15,STAINED_CLAY:7,10,CONCRETE:8,100)
RandomBlock(-7,12,-2,CONCRETE:8,65,quark:iron_plate,10,quark:iron_plate:1,10,STAINED_CLAY:9,15,STAINED_CLAY:7,10,CONCRETE:8,100)
RandomBlock(-7,12,-1,CONCRETE:8,65,quark:iron_plate,10,quark:iron_plate:1,10,STAINED_CLAY:9,15,STAINED_CLAY:7,10,CONCRETE:8,100)
RandomBlock(-7,12,0,CONCRETE:8,65,quark:iron_plate,10,quark:iron_plate:1,10,STAINED_CLAY:9,15,STAINED_CLAY:7,10,CONCRETE:8,100)
RandomBlock(-7,12,1,CONCRETE:8,65,quark:iron_plate,10,quark:iron_plate:1,10,STAINED_CLAY:9,15,STAINED_CLAY:7,10,CONCRETE:8,100)
RandomBlock(-7,12,2,CONCRETE:8,65,quark:iron_plate,10,quark:iron_plate:1,10,STAINED_CLAY:9,15,STAINED_CLAY:7,10,CONCRETE:8,100)
RandomBlock(-7,12,3,CONCRETE:8,65,quark:iron_plate,10,quark:iron_plate:1,10,STAINED_CLAY:9,15,STAINED_CLAY:7,10,CONCRETE:8,100)
RandomBlock(-7,12,4,CONCRETE:8,65,quark:iron_plate,10,quark:iron_plate:1,10,STAINED_CLAY:9,15,STAINED_CLAY:7,10,CONCRETE:8,100)
RandomBlock(-7,12,5,CONCRETE:8,65,quark:iron_plate,10,quark:iron_plate:1,10,STAINED_CLAY:9,15,STAINED_CLAY:7,10,CONCRETE:8,100)
RandomBlock(-7,12,6,CONCRETE:8,65,quark:iron_plate,10,quark:iron_plate:1,10,STAINED_CLAY:9,15,STAINED_CLAY:7,10,CONCRETE:8,100)
RandomBlock(-7,12,7,CONCRETE:8,65,quark:iron_plate,10,quark:iron_plate:1,10,STAINED_CLAY:9,15,STAINED_CLAY:7,10,CONCRETE:8,100)
RandomBlock(-7,12,8,CONCRETE:8,65,quark:iron_plate,10,quark:iron_plate:1,10,STAINED_CLAY:9,15,STAINED_CLAY:7,10,CONCRETE:8,100)
RandomBlock(-7,13,-7,CONCRETE:7,65,quark:iron_plate,10,quark:iron_plate:1,10,STAINED_CLAY:15,10,STAINED_CLAY:9,100)
RandomBlock(-7,13,-6,CONCRETE:8,65,quark:iron_plate,10,quark:iron_plate:1,10,STAINED_CLAY:9,15,STAINED_CLAY:7,10,CONCRETE:8,100)
RandomBlock(-7,13,-5,CONCRETE:8,65,quark:iron_plate,10,quark:iron_plate:1,10,STAINED_CLAY:9,15,STAINED_CLAY:7,10,CONCRETE:8,100)
RandomBlock(-7,13,-4,CONCRETE:8,65,quark:iron_plate,10,quark:iron_plate:1,10,STAINED_CLAY:9,15,STAINED_CLAY:7,10,CONCRETE:8,100)
RandomBlock(-7,13,-3,CONCRETE:8,65,quark:iron_plate,10,quark:iron_plate:1,10,STAINED_CLAY:9,15,STAINED_CLAY:7,10,CONCRETE:8,100)
RandomBlock(-7,13,-2,CONCRETE:8,65,quark:iron_plate,10,quark:iron_plate:1,10,STAINED_CLAY:9,15,STAINED_CLAY:7,10,CONCRETE:8,100)
RandomBlock(-7,13,-1,CONCRETE:8,65,quark:iron_plate,10,quark:iron_plate:1,10,STAINED_CLAY:9,15,STAINED_CLAY:7,10,CONCRETE:8,100)
RandomBlock(-7,13,0,CONCRETE:8,65,quark:iron_plate,10,quark:iron_plate:1,10,STAINED_CLAY:9,15,STAINED_CLAY:7,10,CONCRETE:8,100)
RandomBlock(-7,13,1,CONCRETE:8,65,quark:iron_plate,10,quark:iron_plate:1,10,STAINED_CLAY:9,15,STAINED_CLAY:7,10,CONCRETE:8,100)
RandomBlock(-7,13,2,CONCRETE:8,65,quark:iron_plate,10,quark:iron_plate:1,10,STAINED_CLAY:9,15,STAINED_CLAY:7,10,CONCRETE:8,100)
RandomBlock(-7,13,3,CONCRETE:8,65,quark:iron_plate,10,quark:iron_plate:1,10,STAINED_CLAY:9,15,STAINED_CLAY:7,10,CONCRETE:8,100)
RandomBlock(-7,13,4,CONCRETE:8,65,quark:iron_plate,10,quark:iron_plate:1,10,STAINED_CLAY:9,15,STAINED_CLAY:7,10,CONCRETE:8,100)
RandomBlock(-7,13,5,CONCRETE:8,65,quark:iron_plate,10,quark:iron_plate:1,10,STAINED_CLAY:9,15,STAINED_CLAY:7,10,CONCRETE:8,100)
RandomBlock(-7,13,6,CONCRETE:8,65,quark:iron_plate,10,quark:iron_plate:1,10,STAINED_CLAY:9,15,STAINED_CLAY:7,10,CONCRETE:8,100)
RandomBlock(-7,13,7,CONCRETE:8,65,quark:iron_plate,10,quark:iron_plate:1,10,STAINED_CLAY:9,15,STAINED_CLAY:7,10,CONCRETE:8,100)
RandomBlock(-7,13,8,CONCRETE:8,65,quark:iron_plate,10,quark:iron_plate:1,10,STAINED_CLAY:9,15,STAINED_CLAY:7,10,CONCRETE:8,100)
RandomBlock(-7,14,-7,CONCRETE:7,65,quark:iron_plate,10,quark:iron_plate:1,10,STAINED_CLAY:15,10,STAINED_CLAY:9,100)
RandomBlock(-7,14,-6,CONCRETE:8,65,quark:iron_plate,10,quark:iron_plate:1,10,STAINED_CLAY:9,15,STAINED_CLAY:7,10,CONCRETE:8,100)
RandomBlock(-7,14,-5,CONCRETE:8,65,quark:iron_plate,10,quark:iron_plate:1,10,STAINED_CLAY:9,15,STAINED_CLAY:7,10,CONCRETE:8,100)
RandomBlock(-7,14,-4,CONCRETE:8,65,quark:iron_plate,10,quark:iron_plate:1,10,STAINED_CLAY:9,15,STAINED_CLAY:7,10,CONCRETE:8,100)
RandomBlock(-7,14,-3,CONCRETE:8,65,quark:iron_plate,10,quark:iron_plate:1,10,STAINED_CLAY:9,15,STAINED_CLAY:7,10,CONCRETE:8,100)
RandomBlock(-7,14,-2,CONCRETE:8,65,quark:iron_plate,10,quark:iron_plate:1,10,STAINED_CLAY:9,15,STAINED_CLAY:7,10,CONCRETE:8,100)
RandomBlock(-7,14,-1,CONCRETE:8,65,quark:iron_plate,10,quark:iron_plate:1,10,STAINED_CLAY:9,15,STAINED_CLAY:7,10,CONCRETE:8,100)
RandomBlock(-7,14,0,CONCRETE:8,65,quark:iron_plate,10,quark:iron_plate:1,10,STAINED_CLAY:9,15,STAINED_CLAY:7,10,CONCRETE:8,100)
RandomBlock(-7,14,1,CONCRETE:8,65,quark:iron_plate,10,quark:iron_plate:1,10,STAINED_CLAY:9,15,STAINED_CLAY:7,10,CONCRETE:8,100)
RandomBlock(-7,14,2,CONCRETE:8,65,quark:iron_plate,10,quark:iron_plate:1,10,STAINED_CLAY:9,15,STAINED_CLAY:7,10,CONCRETE:8,100)
RandomBlock(-7,14,3,CONCRETE:8,65,quark:iron_plate,10,quark:iron_plate:1,10,STAINED_CLAY:9,15,STAINED_CLAY:7,10,CONCRETE:8,100)
RandomBlock(-7,14,4,CONCRETE:8,65,quark:iron_plate,10,quark:iron_plate:1,10,STAINED_CLAY:9,15,STAINED_CLAY:7,10,CONCRETE:8,100)
RandomBlock(-7,14,5,CONCRETE:8,65,quark:iron_plate,10,quark:iron_plate:1,10,STAINED_CLAY:9,15,STAINED_CLAY:7,10,CONCRETE:8,100)
RandomBlock(-7,14,6,CONCRETE:8,65,quark:iron_plate,10,quark:iron_plate:1,10,STAINED_CLAY:9,15,STAINED_CLAY:7,10,CONCRETE:8,100)
RandomBlock(-7,14,7,CONCRETE:8,65,quark:iron_plate,10,quark:iron_plate:1,10,STAINED_CLAY:9,15,STAINED_CLAY:7,10,CONCRETE:8,100)
RandomBlock(-7,14,8,CONCRETE:8,65,quark:iron_plate,10,quark:iron_plate:1,10,STAINED_CLAY:9,15,STAINED_CLAY:7,10,CONCRETE:8,100)
RandomBlock(-7,15,-7,CONCRETE:7,65,quark:iron_plate,10,quark:iron_plate:1,10,STAINED_CLAY:15,10,STAINED_CLAY:9,100)
RandomBlock(-7,15,-6,CONCRETE:8,65,quark:iron_plate,10,quark:iron_plate:1,10,STAINED_CLAY:9,15,STAINED_CLAY:7,10,CONCRETE:8,100)
RandomBlock(-7,15,-5,CONCRETE:8,65,quark:iron_plate,10,quark:iron_plate:1,10,STAINED_CLAY:9,15,STAINED_CLAY:7,10,CONCRETE:8,100)
RandomBlock(-7,15,-4,CONCRETE:8,65,quark:iron_plate,10,quark:iron_plate:1,10,STAINED_CLAY:9,15,STAINED_CLAY:7,10,CONCRETE:8,100)
RandomBlock(-7,15,-3,CONCRETE:8,65,quark:iron_plate,10,quark:iron_plate:1,10,STAINED_CLAY:9,15,STAINED_CLAY:7,10,CONCRETE:8,100)
RandomBlock(-7,15,-2,CONCRETE:8,65,quark:iron_plate,10,quark:iron_plate:1,10,STAINED_CLAY:9,15,STAINED_CLAY:7,10,CONCRETE:8,100)
RandomBlock(-7,15,-1,CONCRETE:8,65,quark:iron_plate,10,quark:iron_plate:1,10,STAINED_CLAY:9,15,STAINED_CLAY:7,10,CONCRETE:8,100)
RandomBlock(-7,15,0,CONCRETE:8,65,quark:iron_plate,10,quark:iron_plate:1,10,STAINED_CLAY:9,15,STAINED_CLAY:7,10,CONCRETE:8,100)
RandomBlock(-7,15,1,CONCRETE:8,65,quark:iron_plate,10,quark:iron_plate:1,10,STAINED_CLAY:9,15,STAINED_CLAY:7,10,CONCRETE:8,100)
RandomBlock(-7,15,2,CONCRETE:8,65,quark:iron_plate,10,quark:iron_plate:1,10,STAINED_CLAY:9,15,STAINED_CLAY:7,10,CONCRETE:8,100)
RandomBlock(-7,15,3,CONCRETE:8,65,quark:iron_plate,10,quark:iron_plate:1,10,STAINED_CLAY:9,15,STAINED_CLAY:7,10,CONCRETE:8,100)
RandomBlock(-7,15,4,CONCRETE:8,65,quark:iron_plate,10,quark:iron_plate:1,10,STAINED_CLAY:9,15,STAINED_CLAY:7,10,CONCRETE:8,100)
RandomBlock(-7,15,5,CONCRETE:8,65,quark:iron_plate,10,quark:iron_plate:1,10,STAINED_CLAY:9,15,STAINED_CLAY:7,10,CONCRETE:8,100)
RandomBlock(-7,15,6,CONCRETE:8,65,quark:iron_plate,10,quark:iron_plate:1,10,STAINED_CLAY:9,15,STAINED_CLAY:7,10,CONCRETE:8,100)
RandomBlock(-7,15,7,CONCRETE:8,65,quark:iron_plate,10,quark:iron_plate:1,10,STAINED_CLAY:9,15,STAINED_CLAY:7,10,CONCRETE:8,100)
RandomBlock(-7,15,8,CONCRETE:8,65,quark:iron_plate,10,quark:iron_plate:1,10,STAINED_CLAY:9,15,STAINED_CLAY:7,10,CONCRETE:8,100)
RandomBlock(-7,16,-7,CONCRETE:7,65,quark:iron_plate,10,quark:iron_plate:1,10,STAINED_CLAY:15,10,STAINED_CLAY:9,100)
RandomBlock(-7,16,-6,CONCRETE:8,65,quark:iron_plate,10,quark:iron_plate:1,10,STAINED_CLAY:9,15,STAINED_CLAY:7,10,CONCRETE:8,100)
RandomBlock(-7,16,-5,CONCRETE:8,65,quark:iron_plate,10,quark:iron_plate:1,10,STAINED_CLAY:9,15,STAINED_CLAY:7,10,CONCRETE:8,100)
RandomBlock(-7,16,-4,CONCRETE:8,65,quark:iron_plate,10,quark:iron_plate:1,10,STAINED_CLAY:9,15,STAINED_CLAY:7,10,CONCRETE:8,100)
RandomBlock(-7,16,-3,CONCRETE:8,65,quark:iron_plate,10,quark:iron_plate:1,10,STAINED_CLAY:9,15,STAINED_CLAY:7,10,CONCRETE:8,100)
RandomBlock(-7,16,-2,CONCRETE:8,65,quark:iron_plate,10,quark:iron_plate:1,10,STAINED_CLAY:9,15,STAINED_CLAY:7,10,CONCRETE:8,100)
RandomBlock(-7,16,-1,CONCRETE:8,65,quark:iron_plate,10,quark:iron_plate:1,10,STAINED_CLAY:9,15,STAINED_CLAY:7,10,CONCRETE:8,100)
RandomBlock(-7,16,0,CONCRETE:8,65,quark:iron_plate,10,quark:iron_plate:1,10,STAINED_CLAY:9,15,STAINED_CLAY:7,10,CONCRETE:8,100)
RandomBlock(-7,16,1,CONCRETE:8,65,quark:iron_plate,10,quark:iron_plate:1,10,STAINED_CLAY:9,15,STAINED_CLAY:7,10,CONCRETE:8,100)
RandomBlock(-7,16,2,CONCRETE:8,65,quark:iron_plate,10,quark:iron_plate:1,10,STAINED_CLAY:9,15,STAINED_CLAY:7,10,CONCRETE:8,100)
RandomBlock(-7,16,3,CONCRETE:8,65,quark:iron_plate,10,quark:iron_plate:1,10,STAINED_CLAY:9,15,STAINED_CLAY:7,10,CONCRETE:8,100)
RandomBlock(-7,16,4,CONCRETE:8,65,quark:iron_plate,10,quark:iron_plate:1,10,STAINED_CLAY:9,15,STAINED_CLAY:7,10,CONCRETE:8,100)
RandomBlock(-7,16,5,CONCRETE:8,65,quark:iron_plate,10,quark:iron_plate:1,10,STAINED_CLAY:9,15,STAINED_CLAY:7,10,CONCRETE:8,100)
RandomBlock(-7,16,6,CONCRETE:8,65,quark:iron_plate,10,quark:iron_plate:1,10,STAINED_CLAY:9,15,STAINED_CLAY:7,10,CONCRETE:8,100)
RandomBlock(-7,16,7,CONCRETE:8,65,quark:iron_plate,10,quark:iron_plate:1,10,STAINED_CLAY:9,15,STAINED_CLAY:7,10,CONCRETE:8,100)
RandomBlock(-7,16,8,CONCRETE:8,65,quark:iron_plate,10,quark:iron_plate:1,10,STAINED_CLAY:9,15,STAINED_CLAY:7,10,CONCRETE:8,100)
RandomBlock(-7,17,-7,CONCRETE:7,65,quark:iron_plate,10,quark:iron_plate:1,10,STAINED_CLAY:15,10,STAINED_CLAY:9,100)
RandomBlock(-7,17,-6,CONCRETE:7,65,quark:iron_plate,10,quark:iron_plate:1,10,STAINED_CLAY:15,10,STAINED_CLAY:9,100)
RandomBlock(-7,17,-5,CONCRETE:7,65,quark:iron_plate,10,quark:iron_plate:1,10,STAINED_CLAY:15,10,STAINED_CLAY:9,100)
RandomBlock(-7,17,-4,CONCRETE:7,65,quark:iron_plate,10,quark:iron_plate:1,10,STAINED_CLAY:15,10,STAINED_CLAY:9,100)
RandomBlock(-7,17,-3,CONCRETE:7,65,quark:iron_plate,10,quark:iron_plate:1,10,STAINED_CLAY:15,10,STAINED_CLAY:9,100)
RandomBlock(-7,17,-2,CONCRETE:7,65,quark:iron_plate,10,quark:iron_plate:1,10,STAINED_CLAY:15,10,STAINED_CLAY:9,100)
RandomBlock(-7,17,-1,CONCRETE:7,65,quark:iron_plate,10,quark:iron_plate:1,10,STAINED_CLAY:15,10,STAINED_CLAY:9,100)
RandomBlock(-7,17,0,CONCRETE:7,65,quark:iron_plate,10,quark:iron_plate:1,10,STAINED_CLAY:15,10,STAINED_CLAY:9,100)
RandomBlock(-7,17,1,CONCRETE:7,65,quark:iron_plate,10,quark:iron_plate:1,10,STAINED_CLAY:15,10,STAINED_CLAY:9,100)
RandomBlock(-7,17,2,CONCRETE:7,65,quark:iron_plate,10,quark:iron_plate:1,10,STAINED_CLAY:15,10,STAINED_CLAY:9,100)
RandomBlock(-7,17,3,CONCRETE:7,65,quark:iron_plate,10,quark:iron_plate:1,10,STAINED_CLAY:15,10,STAINED_CLAY:9,100)
RandomBlock(-7,17,4,CONCRETE:7,65,quark:iron_plate,10,quark:iron_plate:1,10,STAINED_CLAY:15,10,STAINED_CLAY:9,100)
RandomBlock(-7,17,5,CONCRETE:7,65,quark:iron_plate,10,quark:iron_plate:1,10,STAINED_CLAY:15,10,STAINED_CLAY:9,100)
RandomBlock(-7,17,6,CONCRETE:7,65,quark:iron_plate,10,quark:iron_plate:1,10,STAINED_CLAY:15,10,STAINED_CLAY:9,100)
RandomBlock(-7,17,7,CONCRETE:7,65,quark:iron_plate,10,quark:iron_plate:1,10,STAINED_CLAY:15,10,STAINED_CLAY:9,100)
RandomBlock(-7,17,8,CONCRETE:7,65,quark:iron_plate,10,quark:iron_plate:1,10,STAINED_CLAY:15,10,STAINED_CLAY:9,100)
RandomBlock(-6,0,-7,CONCRETE:7,65,quark:iron_plate,10,quark:iron_plate:1,10,STAINED_CLAY:15,10,STAINED_CLAY:9,100)
RandomBlock(-6,0,-6,CONCRETE:7,65,quark:iron_plate,10,quark:iron_plate:1,10,STAINED_CLAY:15,10,STAINED_CLAY:9,100)
RandomBlock(-6,0,-5,CONCRETE:7,65,quark:iron_plate,10,quark:iron_plate:1,10,STAINED_CLAY:15,10,STAINED_CLAY:9,100)
RandomBlock(-6,0,-4,CONCRETE:7,65,quark:iron_plate,10,quark:iron_plate:1,10,STAINED_CLAY:15,10,STAINED_CLAY:9,100)
RandomBlock(-6,0,-3,CONCRETE:7,65,quark:iron_plate,10,quark:iron_plate:1,10,STAINED_CLAY:15,10,STAINED_CLAY:9,100)
RandomBlock(-6,0,-2,CONCRETE:7,65,quark:iron_plate,10,quark:iron_plate:1,10,STAINED_CLAY:15,10,STAINED_CLAY:9,100)
RandomBlock(-6,0,-1,CONCRETE:7,65,quark:iron_plate,10,quark:iron_plate:1,10,STAINED_CLAY:15,10,STAINED_CLAY:9,100)
RandomBlock(-6,0,0,CONCRETE:7,65,quark:iron_plate,10,quark:iron_plate:1,10,STAINED_CLAY:15,10,STAINED_CLAY:9,100)
RandomBlock(-6,0,1,CONCRETE:7,65,quark:iron_plate,10,quark:iron_plate:1,10,STAINED_CLAY:15,10,STAINED_CLAY:9,100)
RandomBlock(-6,0,2,CONCRETE:7,65,quark:iron_plate,10,quark:iron_plate:1,10,STAINED_CLAY:15,10,STAINED_CLAY:9,100)
RandomBlock(-6,0,3,CONCRETE:7,65,quark:iron_plate,10,quark:iron_plate:1,10,STAINED_CLAY:15,10,STAINED_CLAY:9,100)
RandomBlock(-6,0,4,CONCRETE:7,65,quark:iron_plate,10,quark:iron_plate:1,10,STAINED_CLAY:15,10,STAINED_CLAY:9,100)
RandomBlock(-6,0,5,CONCRETE:7,65,quark:iron_plate,10,quark:iron_plate:1,10,STAINED_CLAY:15,10,STAINED_CLAY:9,100)
RandomBlock(-6,0,6,CONCRETE:7,65,quark:iron_plate,10,quark:iron_plate:1,10,STAINED_CLAY:15,10,STAINED_CLAY:9,100)
RandomBlock(-6,0,7,CONCRETE:7,65,quark:iron_plate,10,quark:iron_plate:1,10,STAINED_CLAY:15,10,STAINED_CLAY:9,100)
RandomBlock(-6,0,8,CONCRETE:7,65,quark:iron_plate,10,quark:iron_plate:1,10,STAINED_CLAY:15,10,STAINED_CLAY:9,100)
RandomBlock(-6,1,-7,CONCRETE:7,65,quark:iron_plate,10,quark:iron_plate:1,10,STAINED_CLAY:15,10,STAINED_CLAY:9,100)
RandomBlock(-6,1,-6,CONCRETE:7,65,quark:iron_plate,10,quark:iron_plate:1,10,STAINED_CLAY:15,10,STAINED_CLAY:9,100)
RandomBlock(-6,1,-5,CONCRETE:7,65,quark:iron_plate,10,quark:iron_plate:1,10,STAINED_CLAY:15,10,STAINED_CLAY:9,100)
RandomBlock(-6,1,-4,CONCRETE:7,65,quark:iron_plate,10,quark:iron_plate:1,10,STAINED_CLAY:15,10,STAINED_CLAY:9,100)
RandomBlock(-6,1,-3,CONCRETE:7,65,quark:iron_plate,10,quark:iron_plate:1,10,STAINED_CLAY:15,10,STAINED_CLAY:9,100)
RandomBlock(-6,1,-2,CONCRETE:7,65,quark:iron_plate,10,quark:iron_plate:1,10,STAINED_CLAY:15,10,STAINED_CLAY:9,100)
RandomBlock(-6,1,-1,CONCRETE:7,65,quark:iron_plate,10,quark:iron_plate:1,10,STAINED_CLAY:15,10,STAINED_CLAY:9,100)
RandomBlock(-6,1,0,CONCRETE:7,65,quark:iron_plate,10,quark:iron_plate:1,10,STAINED_CLAY:15,10,STAINED_CLAY:9,100)
RandomBlock(-6,1,1,CONCRETE:7,65,quark:iron_plate,10,quark:iron_plate:1,10,STAINED_CLAY:15,10,STAINED_CLAY:9,100)
RandomBlock(-6,1,2,CONCRETE:7,65,quark:iron_plate,10,quark:iron_plate:1,10,STAINED_CLAY:15,10,STAINED_CLAY:9,100)
RandomBlock(-6,1,3,CONCRETE:7,65,quark:iron_plate,10,quark:iron_plate:1,10,STAINED_CLAY:15,10,STAINED_CLAY:9,100)
RandomBlock(-6,1,4,CONCRETE:7,65,quark:iron_plate,10,quark:iron_plate:1,10,STAINED_CLAY:15,10,STAINED_CLAY:9,100)
RandomBlock(-6,1,5,CONCRETE:7,65,quark:iron_plate,10,quark:iron_plate:1,10,STAINED_CLAY:15,10,STAINED_CLAY:9,100)
RandomBlock(-6,1,6,CONCRETE:7,65,quark:iron_plate,10,quark:iron_plate:1,10,STAINED_CLAY:15,10,STAINED_CLAY:9,100)
RandomBlock(-6,1,7,CONCRETE:7,65,quark:iron_plate,10,quark:iron_plate:1,10,STAINED_CLAY:15,10,STAINED_CLAY:9,100)
RandomBlock(-6,1,8,CONCRETE:7,65,quark:iron_plate,10,quark:iron_plate:1,10,STAINED_CLAY:15,10,STAINED_CLAY:9,100)
RandomBlock(-6,2,-7,CONCRETE:7,65,quark:iron_plate,10,quark:iron_plate:1,10,STAINED_CLAY:15,10,STAINED_CLAY:9,100)
RandomBlock(-6,2,-6,CONCRETE:7,65,quark:iron_plate,10,quark:iron_plate:1,10,STAINED_CLAY:15,10,STAINED_CLAY:9,100)
RandomBlock(-6,2,-5,CONCRETE:7,65,quark:iron_plate,10,quark:iron_plate:1,10,STAINED_CLAY:15,10,STAINED_CLAY:9,100)
RandomBlock(-6,2,-4,CONCRETE:7,65,quark:iron_plate,10,quark:iron_plate:1,10,STAINED_CLAY:15,10,STAINED_CLAY:9,100)
RandomBlock(-6,2,-3,CONCRETE:7,65,quark:iron_plate,10,quark:iron_plate:1,10,STAINED_CLAY:15,10,STAINED_CLAY:9,100)
RandomBlock(-6,2,-2,CONCRETE:7,65,quark:iron_plate,10,quark:iron_plate:1,10,STAINED_CLAY:15,10,STAINED_CLAY:9,100)
RandomBlock(-6,2,-1,CONCRETE:7,65,quark:iron_plate,10,quark:iron_plate:1,10,STAINED_CLAY:15,10,STAINED_CLAY:9,100)
RandomBlock(-6,2,0,CONCRETE:7,65,quark:iron_plate,10,quark:iron_plate:1,10,STAINED_CLAY:15,10,STAINED_CLAY:9,100)
RandomBlock(-6,2,1,CONCRETE:7,65,quark:iron_plate,10,quark:iron_plate:1,10,STAINED_CLAY:15,10,STAINED_CLAY:9,100)
RandomBlock(-6,2,2,CONCRETE:7,65,quark:iron_plate,10,quark:iron_plate:1,10,STAINED_CLAY:15,10,STAINED_CLAY:9,100)
RandomBlock(-6,2,3,CONCRETE:7,65,quark:iron_plate,10,quark:iron_plate:1,10,STAINED_CLAY:15,10,STAINED_CLAY:9,100)
RandomBlock(-6,2,4,CONCRETE:7,65,quark:iron_plate,10,quark:iron_plate:1,10,STAINED_CLAY:15,10,STAINED_CLAY:9,100)
RandomBlock(-6,2,5,CONCRETE:7,65,quark:iron_plate,10,quark:iron_plate:1,10,STAINED_CLAY:15,10,STAINED_CLAY:9,100)
RandomBlock(-6,2,6,CONCRETE:7,65,quark:iron_plate,10,quark:iron_plate:1,10,STAINED_CLAY:15,10,STAINED_CLAY:9,100)
RandomBlock(-6,2,7,CONCRETE:7,65,quark:iron_plate,10,quark:iron_plate:1,10,STAINED_CLAY:15,10,STAINED_CLAY:9,100)
RandomBlock(-6,2,8,CONCRETE:7,65,quark:iron_plate,10,quark:iron_plate:1,10,STAINED_CLAY:15,10,STAINED_CLAY:9,100)
RandomBlock(-6,3,-7,CONCRETE:7,65,quark:iron_plate,10,quark:iron_plate:1,10,STAINED_CLAY:15,10,STAINED_CLAY:9,100)
RandomBlock(-6,3,-6,CONCRETE:7,65,quark:iron_plate,10,quark:iron_plate:1,10,STAINED_CLAY:15,10,STAINED_CLAY:9,100)
RandomBlock(-6,3,-5,CONCRETE:7,65,quark:iron_plate,10,quark:iron_plate:1,10,STAINED_CLAY:15,10,STAINED_CLAY:9,100)
RandomBlock(-6,3,-4,CONCRETE:7,65,quark:iron_plate,10,quark:iron_plate:1,10,STAINED_CLAY:15,10,STAINED_CLAY:9,100)
RandomBlock(-6,3,-3,CONCRETE:7,65,quark:iron_plate,10,quark:iron_plate:1,10,STAINED_CLAY:15,10,STAINED_CLAY:9,100)
RandomBlock(-6,3,-2,CONCRETE:7,65,quark:iron_plate,10,quark:iron_plate:1,10,STAINED_CLAY:15,10,STAINED_CLAY:9,100)
RandomBlock(-6,3,-1,CONCRETE:7,65,quark:iron_plate,10,quark:iron_plate:1,10,STAINED_CLAY:15,10,STAINED_CLAY:9,100)
RandomBlock(-6,3,0,CONCRETE:7,65,quark:iron_plate,10,quark:iron_plate:1,10,STAINED_CLAY:15,10,STAINED_CLAY:9,100)
RandomBlock(-6,3,1,CONCRETE:7,65,quark:iron_plate,10,quark:iron_plate:1,10,STAINED_CLAY:15,10,STAINED_CLAY:9,100)
RandomBlock(-6,3,2,CONCRETE:7,65,quark:iron_plate,10,quark:iron_plate:1,10,STAINED_CLAY:15,10,STAINED_CLAY:9,100)
RandomBlock(-6,3,3,CONCRETE:7,65,quark:iron_plate,10,quark:iron_plate:1,10,STAINED_CLAY:15,10,STAINED_CLAY:9,100)
RandomBlock(-6,3,4,CONCRETE:7,65,quark:iron_plate,10,quark:iron_plate:1,10,STAINED_CLAY:15,10,STAINED_CLAY:9,100)
RandomBlock(-6,3,5,CONCRETE:7,65,quark:iron_plate,10,quark:iron_plate:1,10,STAINED_CLAY:15,10,STAINED_CLAY:9,100)
RandomBlock(-6,3,6,CONCRETE:7,65,quark:iron_plate,10,quark:iron_plate:1,10,STAINED_CLAY:15,10,STAINED_CLAY:9,100)
RandomBlock(-6,3,7,CONCRETE:7,65,quark:iron_plate,10,quark:iron_plate:1,10,STAINED_CLAY:15,10,STAINED_CLAY:9,100)
RandomBlock(-6,3,8,CONCRETE:7,65,quark:iron_plate,10,quark:iron_plate:1,10,STAINED_CLAY:15,10,STAINED_CLAY:9,100)
RandomBlock(-6,4,-7,CONCRETE:7,65,quark:iron_plate,10,quark:iron_plate:1,10,STAINED_CLAY:15,10,STAINED_CLAY:9,100)
RandomBlock(-6,4,-6,CONCRETE:7,65,quark:iron_plate,10,quark:iron_plate:1,10,STAINED_CLAY:15,10,STAINED_CLAY:9,100)
RandomBlock(-6,4,-5,CONCRETE:7,65,quark:iron_plate,10,quark:iron_plate:1,10,STAINED_CLAY:15,10,STAINED_CLAY:9,100)
RandomBlock(-6,4,-4,CONCRETE:7,65,quark:iron_plate,10,quark:iron_plate:1,10,STAINED_CLAY:15,10,STAINED_CLAY:9,100)
RandomBlock(-6,4,-3,CONCRETE:7,65,quark:iron_plate,10,quark:iron_plate:1,10,STAINED_CLAY:15,10,STAINED_CLAY:9,100)
RandomBlock(-6,4,-2,CONCRETE:7,65,quark:iron_plate,10,quark:iron_plate:1,10,STAINED_CLAY:15,10,STAINED_CLAY:9,100)
RandomBlock(-6,4,-1,CONCRETE:7,65,quark:iron_plate,10,quark:iron_plate:1,10,STAINED_CLAY:15,10,STAINED_CLAY:9,100)
RandomBlock(-6,4,0,CONCRETE:7,65,quark:iron_plate,10,quark:iron_plate:1,10,STAINED_CLAY:15,10,STAINED_CLAY:9,100)
RandomBlock(-6,4,1,CONCRETE:7,65,quark:iron_plate,10,quark:iron_plate:1,10,STAINED_CLAY:15,10,STAINED_CLAY:9,100)
RandomBlock(-6,4,2,CONCRETE:7,65,quark:iron_plate,10,quark:iron_plate:1,10,STAINED_CLAY:15,10,STAINED_CLAY:9,100)
RandomBlock(-6,4,3,CONCRETE:7,65,quark:iron_plate,10,quark:iron_plate:1,10,STAINED_CLAY:15,10,STAINED_CLAY:9,100)
RandomBlock(-6,4,4,CONCRETE:7,65,quark:iron_plate,10,quark:iron_plate:1,10,STAINED_CLAY:15,10,STAINED_CLAY:9,100)
RandomBlock(-6,4,5,CONCRETE:7,65,quark:iron_plate,10,quark:iron_plate:1,10,STAINED_CLAY:15,10,STAINED_CLAY:9,100)
RandomBlock(-6,4,6,CONCRETE:7,65,quark:iron_plate,10,quark:iron_plate:1,10,STAINED_CLAY:15,10,STAINED_CLAY:9,100)
RandomBlock(-6,4,7,CONCRETE:7,65,quark:iron_plate,10,quark:iron_plate:1,10,STAINED_CLAY:15,10,STAINED_CLAY:9,100)
RandomBlock(-6,4,8,CONCRETE:7,65,quark:iron_plate,10,quark:iron_plate:1,10,STAINED_CLAY:15,10,STAINED_CLAY:9,100)
RandomBlock(-6,5,-7,CONCRETE:7,65,quark:iron_plate,10,quark:iron_plate:1,10,STAINED_CLAY:15,10,STAINED_CLAY:9,100)
RandomBlock(-6,5,-6,CONCRETE:7,65,quark:iron_plate,10,quark:iron_plate:1,10,STAINED_CLAY:15,10,STAINED_CLAY:9,100)
RandomBlock(-6,5,-5,CONCRETE:7,65,quark:iron_plate,10,quark:iron_plate:1,10,STAINED_CLAY:15,10,STAINED_CLAY:9,100)
RandomBlock(-6,5,-4,CONCRETE:7,65,quark:iron_plate,10,quark:iron_plate:1,10,STAINED_CLAY:15,10,STAINED_CLAY:9,100)
RandomBlock(-6,5,-3,CONCRETE:7,65,quark:iron_plate,10,quark:iron_plate:1,10,STAINED_CLAY:15,10,STAINED_CLAY:9,100)
RandomBlock(-6,5,-2,CONCRETE:7,65,quark:iron_plate,10,quark:iron_plate:1,10,STAINED_CLAY:15,10,STAINED_CLAY:9,100)
RandomBlock(-6,5,-1,CONCRETE:7,65,quark:iron_plate,10,quark:iron_plate:1,10,STAINED_CLAY:15,10,STAINED_CLAY:9,100)
RandomBlock(-6,5,0,CONCRETE:7,65,quark:iron_plate,10,quark:iron_plate:1,10,STAINED_CLAY:15,10,STAINED_CLAY:9,100)
RandomBlock(-6,5,1,CONCRETE:7,65,quark:iron_plate,10,quark:iron_plate:1,10,STAINED_CLAY:15,10,STAINED_CLAY:9,100)
RandomBlock(-6,5,2,CONCRETE:7,65,quark:iron_plate,10,quark:iron_plate:1,10,STAINED_CLAY:15,10,STAINED_CLAY:9,100)
RandomBlock(-6,5,3,CONCRETE:7,65,quark:iron_plate,10,quark:iron_plate:1,10,STAINED_CLAY:15,10,STAINED_CLAY:9,100)
RandomBlock(-6,5,4,CONCRETE:7,65,quark:iron_plate,10,quark:iron_plate:1,10,STAINED_CLAY:15,10,STAINED_CLAY:9,100)
RandomBlock(-6,5,5,CONCRETE:7,65,quark:iron_plate,10,quark:iron_plate:1,10,STAINED_CLAY:15,10,STAINED_CLAY:9,100)
RandomBlock(-6,5,6,CONCRETE:7,65,quark:iron_plate,10,quark:iron_plate:1,10,STAINED_CLAY:15,10,STAINED_CLAY:9,100)
RandomBlock(-6,5,7,CONCRETE:7,65,quark:iron_plate,10,quark:iron_plate:1,10,STAINED_CLAY:15,10,STAINED_CLAY:9,100)
RandomBlock(-6,5,8,CONCRETE:7,65,quark:iron_plate,10,quark:iron_plate:1,10,STAINED_CLAY:15,10,STAINED_CLAY:9,100)
RandomBlock(-6,6,-7,CONCRETE:7,65,quark:iron_plate,10,quark:iron_plate:1,10,STAINED_CLAY:15,10,STAINED_CLAY:9,100)
RandomBlock(-6,6,-6,CONCRETE:7,65,quark:iron_plate,10,quark:iron_plate:1,10,STAINED_CLAY:15,10,STAINED_CLAY:9,100)
RandomBlock(-6,6,-5,CONCRETE:7,65,quark:iron_plate,10,quark:iron_plate:1,10,STAINED_CLAY:15,10,STAINED_CLAY:9,100)
RandomBlock(-6,6,-4,CONCRETE:7,65,quark:iron_plate,10,quark:iron_plate:1,10,STAINED_CLAY:15,10,STAINED_CLAY:9,100)
RandomBlock(-6,6,-3,CONCRETE:7,65,quark:iron_plate,10,quark:iron_plate:1,10,STAINED_CLAY:15,10,STAINED_CLAY:9,100)
RandomBlock(-6,6,-2,CONCRETE:7,65,quark:iron_plate,10,quark:iron_plate:1,10,STAINED_CLAY:15,10,STAINED_CLAY:9,100)
RandomBlock(-6,6,-1,CONCRETE:7,65,quark:iron_plate,10,quark:iron_plate:1,10,STAINED_CLAY:15,10,STAINED_CLAY:9,100)
RandomBlock(-6,6,0,CONCRETE:7,65,quark:iron_plate,10,quark:iron_plate:1,10,STAINED_CLAY:15,10,STAINED_CLAY:9,100)
RandomBlock(-6,6,1,CONCRETE:7,65,quark:iron_plate,10,quark:iron_plate:1,10,STAINED_CLAY:15,10,STAINED_CLAY:9,100)
RandomBlock(-6,6,2,CONCRETE:7,65,quark:iron_plate,10,quark:iron_plate:1,10,STAINED_CLAY:15,10,STAINED_CLAY:9,100)
RandomBlock(-6,6,3,CONCRETE:7,65,quark:iron_plate,10,quark:iron_plate:1,10,STAINED_CLAY:15,10,STAINED_CLAY:9,100)
RandomBlock(-6,6,4,CONCRETE:7,65,quark:iron_plate,10,quark:iron_plate:1,10,STAINED_CLAY:15,10,STAINED_CLAY:9,100)
RandomBlock(-6,6,5,CONCRETE:7,65,quark:iron_plate,10,quark:iron_plate:1,10,STAINED_CLAY:15,10,STAINED_CLAY:9,100)
RandomBlock(-6,6,6,CONCRETE:7,65,quark:iron_plate,10,quark:iron_plate:1,10,STAINED_CLAY:15,10,STAINED_CLAY:9,100)
RandomBlock(-6,6,7,CONCRETE:7,65,quark:iron_plate,10,quark:iron_plate:1,10,STAINED_CLAY:15,10,STAINED_CLAY:9,100)
RandomBlock(-6,6,8,CONCRETE:7,65,quark:iron_plate,10,quark:iron_plate:1,10,STAINED_CLAY:15,10,STAINED_CLAY:9,100)
RandomBlock(-6,7,-7,CONCRETE:7,65,quark:iron_plate,10,quark:iron_plate:1,10,STAINED_CLAY:15,10,STAINED_CLAY:9,100)
RandomBlock(-6,7,-6,CONCRETE:7,65,quark:iron_plate,10,quark:iron_plate:1,10,STAINED_CLAY:15,10,STAINED_CLAY:9,100)
RandomBlock(-6,7,-5,CONCRETE:7,65,quark:iron_plate,10,quark:iron_plate:1,10,STAINED_CLAY:15,10,STAINED_CLAY:9,100)
RandomBlock(-6,7,-4,CONCRETE:7,65,quark:iron_plate,10,quark:iron_plate:1,10,STAINED_CLAY:15,10,STAINED_CLAY:9,100)
RandomBlock(-6,7,-3,CONCRETE:7,65,quark:iron_plate,10,quark:iron_plate:1,10,STAINED_CLAY:15,10,STAINED_CLAY:9,100)
RandomBlock(-6,7,-2,CONCRETE:7,65,quark:iron_plate,10,quark:iron_plate:1,10,STAINED_CLAY:15,10,STAINED_CLAY:9,100)
RandomBlock(-6,7,-1,CONCRETE:7,65,quark:iron_plate,10,quark:iron_plate:1,10,STAINED_CLAY:15,10,STAINED_CLAY:9,100)
RandomBlock(-6,7,0,CONCRETE:7,65,quark:iron_plate,10,quark:iron_plate:1,10,STAINED_CLAY:15,10,STAINED_CLAY:9,100)
RandomBlock(-6,7,1,CONCRETE:7,65,quark:iron_plate,10,quark:iron_plate:1,10,STAINED_CLAY:15,10,STAINED_CLAY:9,100)
RandomBlock(-6,7,2,CONCRETE:7,65,quark:iron_plate,10,quark:iron_plate:1,10,STAINED_CLAY:15,10,STAINED_CLAY:9,100)
RandomBlock(-6,7,3,CONCRETE:7,65,quark:iron_plate,10,quark:iron_plate:1,10,STAINED_CLAY:15,10,STAINED_CLAY:9,100)
RandomBlock(-6,7,4,CONCRETE:7,65,quark:iron_plate,10,quark:iron_plate:1,10,STAINED_CLAY:15,10,STAINED_CLAY:9,100)
RandomBlock(-6,7,5,CONCRETE:7,65,quark:iron_plate,10,quark:iron_plate:1,10,STAINED_CLAY:15,10,STAINED_CLAY:9,100)
RandomBlock(-6,7,6,CONCRETE:7,65,quark:iron_plate,10,quark:iron_plate:1,10,STAINED_CLAY:15,10,STAINED_CLAY:9,100)
RandomBlock(-6,7,7,CONCRETE:7,65,quark:iron_plate,10,quark:iron_plate:1,10,STAINED_CLAY:15,10,STAINED_CLAY:9,100)
RandomBlock(-6,7,8,CONCRETE:7,65,quark:iron_plate,10,quark:iron_plate:1,10,STAINED_CLAY:15,10,STAINED_CLAY:9,100)
RandomBlock(-6,8,-7,CONCRETE:7,65,quark:iron_plate,10,quark:iron_plate:1,10,STAINED_CLAY:15,10,STAINED_CLAY:9,100)
RandomBlock(-6,8,-6,CONCRETE:8,65,quark:iron_plate,10,quark:iron_plate:1,10,STAINED_CLAY:9,15,STAINED_CLAY:7,10,CONCRETE:8,100)
RandomBlock(-6,8,-5,CONCRETE:8,65,quark:iron_plate,10,quark:iron_plate:1,10,STAINED_CLAY:9,15,STAINED_CLAY:7,10,CONCRETE:8,100)
RandomBlock(-6,8,-4,CONCRETE:8,65,quark:iron_plate,10,quark:iron_plate:1,10,STAINED_CLAY:9,15,STAINED_CLAY:7,10,CONCRETE:8,100)
RandomBlock(-6,8,-3,CONCRETE:8,65,quark:iron_plate,10,quark:iron_plate:1,10,STAINED_CLAY:9,15,STAINED_CLAY:7,10,CONCRETE:8,100)
RandomBlock(-6,8,-2,CONCRETE:8,65,quark:iron_plate,10,quark:iron_plate:1,10,STAINED_CLAY:9,15,STAINED_CLAY:7,10,CONCRETE:8,100)
RandomBlock(-6,8,-1,CONCRETE:8,65,quark:iron_plate,10,quark:iron_plate:1,10,STAINED_CLAY:9,15,STAINED_CLAY:7,10,CONCRETE:8,100)
RandomBlock(-6,8,0,CONCRETE:8,65,quark:iron_plate,10,quark:iron_plate:1,10,STAINED_CLAY:9,15,STAINED_CLAY:7,10,CONCRETE:8,100)
RandomBlock(-6,8,1,CONCRETE:8,65,quark:iron_plate,10,quark:iron_plate:1,10,STAINED_CLAY:9,15,STAINED_CLAY:7,10,CONCRETE:8,100)
RandomBlock(-6,8,2,CONCRETE:8,65,quark:iron_plate,10,quark:iron_plate:1,10,STAINED_CLAY:9,15,STAINED_CLAY:7,10,CONCRETE:8,100)
RandomBlock(-6,8,3,CONCRETE:8,65,quark:iron_plate,10,quark:iron_plate:1,10,STAINED_CLAY:9,15,STAINED_CLAY:7,10,CONCRETE:8,100)
RandomBlock(-6,8,4,CONCRETE:8,65,quark:iron_plate,10,quark:iron_plate:1,10,STAINED_CLAY:9,15,STAINED_CLAY:7,10,CONCRETE:8,100)
RandomBlock(-6,8,5,CONCRETE:8,65,quark:iron_plate,10,quark:iron_plate:1,10,STAINED_CLAY:9,15,STAINED_CLAY:7,10,CONCRETE:8,100)
RandomBlock(-6,8,6,CONCRETE:8,65,quark:iron_plate,10,quark:iron_plate:1,10,STAINED_CLAY:9,15,STAINED_CLAY:7,10,CONCRETE:8,100)
RandomBlock(-6,8,7,CONCRETE:8,65,quark:iron_plate,10,quark:iron_plate:1,10,STAINED_CLAY:9,15,STAINED_CLAY:7,10,CONCRETE:8,100)
RandomBlock(-6,8,8,CONCRETE:8,65,quark:iron_plate,10,quark:iron_plate:1,10,STAINED_CLAY:9,15,STAINED_CLAY:7,10,CONCRETE:8,100)
RandomBlock(-6,9,-7,CONCRETE:7,65,quark:iron_plate,10,quark:iron_plate:1,10,STAINED_CLAY:15,10,STAINED_CLAY:9,100)
RandomBlock(-6,9,-6,CONCRETE:8,65,quark:iron_plate,10,quark:iron_plate:1,10,STAINED_CLAY:9,15,STAINED_CLAY:7,10,CONCRETE:8,100)
RandomBlock(-6,9,-5,CONCRETE:8,65,quark:iron_plate,10,quark:iron_plate:1,10,STAINED_CLAY:9,15,STAINED_CLAY:7,10,CONCRETE:8,100)
RandomBlock(-6,9,-4,CONCRETE:8,65,quark:iron_plate,10,quark:iron_plate:1,10,STAINED_CLAY:9,15,STAINED_CLAY:7,10,CONCRETE:8,100)
RandomBlock(-6,9,-3,CONCRETE:8,65,quark:iron_plate,10,quark:iron_plate:1,10,STAINED_CLAY:9,15,STAINED_CLAY:7,10,CONCRETE:8,100)
RandomBlock(-6,9,-2,CONCRETE:7,65,quark:iron_plate,10,quark:iron_plate:1,10,STAINED_CLAY:15,10,STAINED_CLAY:9,100)
RandomBlock(-6,9,-1,CONCRETE:7,65,quark:iron_plate,10,quark:iron_plate:1,10,STAINED_CLAY:15,10,STAINED_CLAY:9,100)
Block(-6,9,0,QUARTZ_BLOCK:2)
RandomBlock(-6,9,1,CONCRETE:7,65,quark:iron_plate,10,quark:iron_plate:1,10,STAINED_CLAY:15,10,STAINED_CLAY:9,100)
RandomBlock(-6,9,2,CONCRETE:7,65,quark:iron_plate,10,quark:iron_plate:1,10,STAINED_CLAY:15,10,STAINED_CLAY:9,100)
RandomBlock(-6,9,3,CONCRETE:8,65,quark:iron_plate,10,quark:iron_plate:1,10,STAINED_CLAY:9,15,STAINED_CLAY:7,10,CONCRETE:8,100)
RandomBlock(-6,9,4,CONCRETE:8,65,quark:iron_plate,10,quark:iron_plate:1,10,STAINED_CLAY:9,15,STAINED_CLAY:7,10,CONCRETE:8,100)
RandomBlock(-6,9,5,CONCRETE:8,65,quark:iron_plate,10,quark:iron_plate:1,10,STAINED_CLAY:9,15,STAINED_CLAY:7,10,CONCRETE:8,100)
RandomBlock(-6,9,6,CONCRETE:8,65,quark:iron_plate,10,quark:iron_plate:1,10,STAINED_CLAY:9,15,STAINED_CLAY:7,10,CONCRETE:8,100)
RandomBlock(-6,9,7,CONCRETE:8,65,quark:iron_plate,10,quark:iron_plate:1,10,STAINED_CLAY:9,15,STAINED_CLAY:7,10,CONCRETE:8,100)
RandomBlock(-6,9,8,CONCRETE:8,65,quark:iron_plate,10,quark:iron_plate:1,10,STAINED_CLAY:9,15,STAINED_CLAY:7,10,CONCRETE:8,100)
RandomBlock(-6,10,-7,CONCRETE:7,65,quark:iron_plate,10,quark:iron_plate:1,10,STAINED_CLAY:15,10,STAINED_CLAY:9,100)
RandomBlock(-6,10,-6,CONCRETE:8,65,quark:iron_plate,10,quark:iron_plate:1,10,STAINED_CLAY:9,15,STAINED_CLAY:7,10,CONCRETE:8,100)
RandomBlock(-6,10,-5,CONCRETE:8,65,quark:iron_plate,10,quark:iron_plate:1,10,STAINED_CLAY:9,15,STAINED_CLAY:7,10,CONCRETE:8,100)
RandomBlock(-6,10,-4,CONCRETE:8,65,quark:iron_plate,10,quark:iron_plate:1,10,STAINED_CLAY:9,15,STAINED_CLAY:7,10,CONCRETE:8,100)
RandomBlock(-6,10,-3,CONCRETE:8,65,quark:iron_plate,10,quark:iron_plate:1,10,STAINED_CLAY:9,15,STAINED_CLAY:7,10,CONCRETE:8,100)
RandomBlock(-6,10,-2,CONCRETE:7,65,quark:iron_plate,10,quark:iron_plate:1,10,STAINED_CLAY:15,10,STAINED_CLAY:9,100)
RandomBlock(-6,10,-1,CONCRETE:7,65,quark:iron_plate,10,quark:iron_plate:1,10,STAINED_CLAY:15,10,STAINED_CLAY:9,100)
Block(-6,10,0,QUARTZ_BLOCK:2)
RandomBlock(-6,10,1,CONCRETE:7,65,quark:iron_plate,10,quark:iron_plate:1,10,STAINED_CLAY:15,10,STAINED_CLAY:9,100)
RandomBlock(-6,10,2,CONCRETE:7,65,quark:iron_plate,10,quark:iron_plate:1,10,STAINED_CLAY:15,10,STAINED_CLAY:9,100)
RandomBlock(-6,10,3,CONCRETE:8,65,quark:iron_plate,10,quark:iron_plate:1,10,STAINED_CLAY:9,15,STAINED_CLAY:7,10,CONCRETE:8,100)
RandomBlock(-6,10,4,CONCRETE:8,65,quark:iron_plate,10,quark:iron_plate:1,10,STAINED_CLAY:9,15,STAINED_CLAY:7,10,CONCRETE:8,100)
RandomBlock(-6,10,5,CONCRETE:8,65,quark:iron_plate,10,quark:iron_plate:1,10,STAINED_CLAY:9,15,STAINED_CLAY:7,10,CONCRETE:8,100)
RandomBlock(-6,10,6,CONCRETE:8,65,quark:iron_plate,10,quark:iron_plate:1,10,STAINED_CLAY:9,15,STAINED_CLAY:7,10,CONCRETE:8,100)
RandomBlock(-6,10,7,CONCRETE:8,65,quark:iron_plate,10,quark:iron_plate:1,10,STAINED_CLAY:9,15,STAINED_CLAY:7,10,CONCRETE:8,100)
RandomBlock(-6,10,8,CONCRETE:8,65,quark:iron_plate,10,quark:iron_plate:1,10,STAINED_CLAY:9,15,STAINED_CLAY:7,10,CONCRETE:8,100)
RandomBlock(-6,11,-7,CONCRETE:7,65,quark:iron_plate,10,quark:iron_plate:1,10,STAINED_CLAY:15,10,STAINED_CLAY:9,100)
RandomBlock(-6,11,-6,CONCRETE:8,65,quark:iron_plate,10,quark:iron_plate:1,10,STAINED_CLAY:9,15,STAINED_CLAY:7,10,CONCRETE:8,100)
RandomBlock(-6,11,-5,CONCRETE:8,65,quark:iron_plate,10,quark:iron_plate:1,10,STAINED_CLAY:9,15,STAINED_CLAY:7,10,CONCRETE:8,100)
RandomBlock(-6,11,-4,CONCRETE:8,65,quark:iron_plate,10,quark:iron_plate:1,10,STAINED_CLAY:9,15,STAINED_CLAY:7,10,CONCRETE:8,100)
RandomBlock(-6,11,-3,CONCRETE:8,65,quark:iron_plate,10,quark:iron_plate:1,10,STAINED_CLAY:9,15,STAINED_CLAY:7,10,CONCRETE:8,100)
RandomBlock(-6,11,-2,CONCRETE:7,65,quark:iron_plate,10,quark:iron_plate:1,10,STAINED_CLAY:15,10,STAINED_CLAY:9,100)
RandomBlock(-6,11,-1,CONCRETE:7,65,quark:iron_plate,10,quark:iron_plate:1,10,STAINED_CLAY:15,10,STAINED_CLAY:9,100)
Block(-6,11,0,QUARTZ_BLOCK:2)
RandomBlock(-6,11,1,CONCRETE:7,65,quark:iron_plate,10,quark:iron_plate:1,10,STAINED_CLAY:15,10,STAINED_CLAY:9,100)
RandomBlock(-6,11,2,CONCRETE:7,65,quark:iron_plate,10,quark:iron_plate:1,10,STAINED_CLAY:15,10,STAINED_CLAY:9,100)
RandomBlock(-6,11,3,CONCRETE:8,65,quark:iron_plate,10,quark:iron_plate:1,10,STAINED_CLAY:9,15,STAINED_CLAY:7,10,CONCRETE:8,100)
RandomBlock(-6,11,4,CONCRETE:8,65,quark:iron_plate,10,quark:iron_plate:1,10,STAINED_CLAY:9,15,STAINED_CLAY:7,10,CONCRETE:8,100)
RandomBlock(-6,11,5,CONCRETE:8,65,quark:iron_plate,10,quark:iron_plate:1,10,STAINED_CLAY:9,15,STAINED_CLAY:7,10,CONCRETE:8,100)
RandomBlock(-6,11,6,CONCRETE:8,65,quark:iron_plate,10,quark:iron_plate:1,10,STAINED_CLAY:9,15,STAINED_CLAY:7,10,CONCRETE:8,100)
RandomBlock(-6,11,7,CONCRETE:8,65,quark:iron_plate,10,quark:iron_plate:1,10,STAINED_CLAY:9,15,STAINED_CLAY:7,10,CONCRETE:8,100)
RandomBlock(-6,11,8,CONCRETE:8,65,quark:iron_plate,10,quark:iron_plate:1,10,STAINED_CLAY:9,15,STAINED_CLAY:7,10,CONCRETE:8,100)
RandomBlock(-6,12,-7,CONCRETE:7,65,quark:iron_plate,10,quark:iron_plate:1,10,STAINED_CLAY:15,10,STAINED_CLAY:9,100)
RandomBlock(-6,12,-6,CONCRETE:8,65,quark:iron_plate,10,quark:iron_plate:1,10,STAINED_CLAY:9,15,STAINED_CLAY:7,10,CONCRETE:8,100)
RandomBlock(-6,12,-5,CONCRETE:8,65,quark:iron_plate,10,quark:iron_plate:1,10,STAINED_CLAY:9,15,STAINED_CLAY:7,10,CONCRETE:8,100)
RandomBlock(-6,12,-4,CONCRETE:8,65,quark:iron_plate,10,quark:iron_plate:1,10,STAINED_CLAY:9,15,STAINED_CLAY:7,10,CONCRETE:8,100)
RandomBlock(-6,12,-3,CONCRETE:8,65,quark:iron_plate,10,quark:iron_plate:1,10,STAINED_CLAY:9,15,STAINED_CLAY:7,10,CONCRETE:8,100)
RandomBlock(-6,12,-2,CONCRETE:7,65,quark:iron_plate,10,quark:iron_plate:1,10,STAINED_CLAY:15,10,STAINED_CLAY:9,100)
RandomBlock(-6,12,-1,CONCRETE:7,65,quark:iron_plate,10,quark:iron_plate:1,10,STAINED_CLAY:15,10,STAINED_CLAY:9,100)
Block(-6,12,0,QUARTZ_BLOCK:2)
RandomBlock(-6,12,1,CONCRETE:7,65,quark:iron_plate,10,quark:iron_plate:1,10,STAINED_CLAY:15,10,STAINED_CLAY:9,100)
RandomBlock(-6,12,2,CONCRETE:7,65,quark:iron_plate,10,quark:iron_plate:1,10,STAINED_CLAY:15,10,STAINED_CLAY:9,100)
RandomBlock(-6,12,3,CONCRETE:8,65,quark:iron_plate,10,quark:iron_plate:1,10,STAINED_CLAY:9,15,STAINED_CLAY:7,10,CONCRETE:8,100)
RandomBlock(-6,12,4,CONCRETE:8,65,quark:iron_plate,10,quark:iron_plate:1,10,STAINED_CLAY:9,15,STAINED_CLAY:7,10,CONCRETE:8,100)
RandomBlock(-6,12,5,CONCRETE:8,65,quark:iron_plate,10,quark:iron_plate:1,10,STAINED_CLAY:9,15,STAINED_CLAY:7,10,CONCRETE:8,100)
RandomBlock(-6,12,6,CONCRETE:8,65,quark:iron_plate,10,quark:iron_plate:1,10,STAINED_CLAY:9,15,STAINED_CLAY:7,10,CONCRETE:8,100)
RandomBlock(-6,12,7,CONCRETE:8,65,quark:iron_plate,10,quark:iron_plate:1,10,STAINED_CLAY:9,15,STAINED_CLAY:7,10,CONCRETE:8,100)
RandomBlock(-6,12,8,CONCRETE:8,65,quark:iron_plate,10,quark:iron_plate:1,10,STAINED_CLAY:9,15,STAINED_CLAY:7,10,CONCRETE:8,100)
RandomBlock(-6,13,-7,CONCRETE:7,65,quark:iron_plate,10,quark:iron_plate:1,10,STAINED_CLAY:15,10,STAINED_CLAY:9,100)
RandomBlock(-6,13,-6,CONCRETE:8,65,quark:iron_plate,10,quark:iron_plate:1,10,STAINED_CLAY:9,15,STAINED_CLAY:7,10,CONCRETE:8,100)
RandomBlock(-6,13,-5,CONCRETE:8,65,quark:iron_plate,10,quark:iron_plate:1,10,STAINED_CLAY:9,15,STAINED_CLAY:7,10,CONCRETE:8,100)
RandomBlock(-6,13,-4,CONCRETE:8,65,quark:iron_plate,10,quark:iron_plate:1,10,STAINED_CLAY:9,15,STAINED_CLAY:7,10,CONCRETE:8,100)
RandomBlock(-6,13,-3,CONCRETE:8,65,quark:iron_plate,10,quark:iron_plate:1,10,STAINED_CLAY:9,15,STAINED_CLAY:7,10,CONCRETE:8,100)
RandomBlock(-6,13,-2,CONCRETE:7,65,quark:iron_plate,10,quark:iron_plate:1,10,STAINED_CLAY:15,10,STAINED_CLAY:9,100)
RandomBlock(-6,13,-1,CONCRETE:7,65,quark:iron_plate,10,quark:iron_plate:1,10,STAINED_CLAY:15,10,STAINED_CLAY:9,100)
Block(-6,13,0,QUARTZ_BLOCK:2)
RandomBlock(-6,13,1,CONCRETE:7,65,quark:iron_plate,10,quark:iron_plate:1,10,STAINED_CLAY:15,10,STAINED_CLAY:9,100)
RandomBlock(-6,13,2,CONCRETE:7,65,quark:iron_plate,10,quark:iron_plate:1,10,STAINED_CLAY:15,10,STAINED_CLAY:9,100)
RandomBlock(-6,13,3,CONCRETE:8,65,quark:iron_plate,10,quark:iron_plate:1,10,STAINED_CLAY:9,15,STAINED_CLAY:7,10,CONCRETE:8,100)
RandomBlock(-6,13,4,CONCRETE:8,65,quark:iron_plate,10,quark:iron_plate:1,10,STAINED_CLAY:9,15,STAINED_CLAY:7,10,CONCRETE:8,100)
RandomBlock(-6,13,5,CONCRETE:8,65,quark:iron_plate,10,quark:iron_plate:1,10,STAINED_CLAY:9,15,STAINED_CLAY:7,10,CONCRETE:8,100)
RandomBlock(-6,13,6,CONCRETE:8,65,quark:iron_plate,10,quark:iron_plate:1,10,STAINED_CLAY:9,15,STAINED_CLAY:7,10,CONCRETE:8,100)
RandomBlock(-6,13,7,CONCRETE:8,65,quark:iron_plate,10,quark:iron_plate:1,10,STAINED_CLAY:9,15,STAINED_CLAY:7,10,CONCRETE:8,100)
RandomBlock(-6,13,8,CONCRETE:8,65,quark:iron_plate,10,quark:iron_plate:1,10,STAINED_CLAY:9,15,STAINED_CLAY:7,10,CONCRETE:8,100)
RandomBlock(-6,14,-7,CONCRETE:7,65,quark:iron_plate,10,quark:iron_plate:1,10,STAINED_CLAY:15,10,STAINED_CLAY:9,100)
RandomBlock(-6,14,-6,CONCRETE:8,65,quark:iron_plate,10,quark:iron_plate:1,10,STAINED_CLAY:9,15,STAINED_CLAY:7,10,CONCRETE:8,100)
RandomBlock(-6,14,-5,CONCRETE:8,65,quark:iron_plate,10,quark:iron_plate:1,10,STAINED_CLAY:9,15,STAINED_CLAY:7,10,CONCRETE:8,100)
RandomBlock(-6,14,-4,CONCRETE:8,65,quark:iron_plate,10,quark:iron_plate:1,10,STAINED_CLAY:9,15,STAINED_CLAY:7,10,CONCRETE:8,100)
RandomBlock(-6,14,-3,CONCRETE:8,65,quark:iron_plate,10,quark:iron_plate:1,10,STAINED_CLAY:9,15,STAINED_CLAY:7,10,CONCRETE:8,100)
RandomBlock(-6,14,-2,CONCRETE:7,65,quark:iron_plate,10,quark:iron_plate:1,10,STAINED_CLAY:15,10,STAINED_CLAY:9,100)
RandomBlock(-6,14,-1,CONCRETE:7,65,quark:iron_plate,10,quark:iron_plate:1,10,STAINED_CLAY:15,10,STAINED_CLAY:9,100)
Block(-6,14,0,QUARTZ_BLOCK:2)
RandomBlock(-6,14,1,CONCRETE:7,65,quark:iron_plate,10,quark:iron_plate:1,10,STAINED_CLAY:15,10,STAINED_CLAY:9,100)
RandomBlock(-6,14,2,CONCRETE:7,65,quark:iron_plate,10,quark:iron_plate:1,10,STAINED_CLAY:15,10,STAINED_CLAY:9,100)
RandomBlock(-6,14,3,CONCRETE:8,65,quark:iron_plate,10,quark:iron_plate:1,10,STAINED_CLAY:9,15,STAINED_CLAY:7,10,CONCRETE:8,100)
RandomBlock(-6,14,4,CONCRETE:8,65,quark:iron_plate,10,quark:iron_plate:1,10,STAINED_CLAY:9,15,STAINED_CLAY:7,10,CONCRETE:8,100)
RandomBlock(-6,14,5,CONCRETE:8,65,quark:iron_plate,10,quark:iron_plate:1,10,STAINED_CLAY:9,15,STAINED_CLAY:7,10,CONCRETE:8,100)
RandomBlock(-6,14,6,CONCRETE:8,65,quark:iron_plate,10,quark:iron_plate:1,10,STAINED_CLAY:9,15,STAINED_CLAY:7,10,CONCRETE:8,100)
RandomBlock(-6,14,7,CONCRETE:8,65,quark:iron_plate,10,quark:iron_plate:1,10,STAINED_CLAY:9,15,STAINED_CLAY:7,10,CONCRETE:8,100)
RandomBlock(-6,14,8,CONCRETE:8,65,quark:iron_plate,10,quark:iron_plate:1,10,STAINED_CLAY:9,15,STAINED_CLAY:7,10,CONCRETE:8,100)
RandomBlock(-6,15,-7,CONCRETE:7,65,quark:iron_plate,10,quark:iron_plate:1,10,STAINED_CLAY:15,10,STAINED_CLAY:9,100)
RandomBlock(-6,15,-6,CONCRETE:8,65,quark:iron_plate,10,quark:iron_plate:1,10,STAINED_CLAY:9,15,STAINED_CLAY:7,10,CONCRETE:8,100)
RandomBlock(-6,15,-5,CONCRETE:8,65,quark:iron_plate,10,quark:iron_plate:1,10,STAINED_CLAY:9,15,STAINED_CLAY:7,10,CONCRETE:8,100)
RandomBlock(-6,15,-4,CONCRETE:8,65,quark:iron_plate,10,quark:iron_plate:1,10,STAINED_CLAY:9,15,STAINED_CLAY:7,10,CONCRETE:8,100)
RandomBlock(-6,15,-3,CONCRETE:8,65,quark:iron_plate,10,quark:iron_plate:1,10,STAINED_CLAY:9,15,STAINED_CLAY:7,10,CONCRETE:8,100)
RandomBlock(-6,15,-2,CONCRETE:7,65,quark:iron_plate,10,quark:iron_plate:1,10,STAINED_CLAY:15,10,STAINED_CLAY:9,100)
RandomBlock(-6,15,-1,CONCRETE:7,65,quark:iron_plate,10,quark:iron_plate:1,10,STAINED_CLAY:15,10,STAINED_CLAY:9,100)
RandomBlock(-6,15,0,CONCRETE:7,65,quark:iron_plate,10,quark:iron_plate:1,10,STAINED_CLAY:15,10,STAINED_CLAY:9,100)
RandomBlock(-6,15,1,CONCRETE:7,65,quark:iron_plate,10,quark:iron_plate:1,10,STAINED_CLAY:15,10,STAINED_CLAY:9,100)
RandomBlock(-6,15,2,CONCRETE:7,65,quark:iron_plate,10,quark:iron_plate:1,10,STAINED_CLAY:15,10,STAINED_CLAY:9,100)
