
#######################################################################
# +-----------------------------------------------------------------+ #
# |                            BO4 object                           | #
# +-----------------------------------------------------------------+ #
#######################################################################

Author: NLBlackEagle

Description: No description given

SettingsMode: WriteDisable


#######################################################################
# +-----------------------------------------------------------------+ #
# |                          Main settings                          | #
# +-----------------------------------------------------------------+ #
#######################################################################

Frequency: 0

SpawnHeight: randomY

UseCenterForHighestBlock: true

##############################
# Height Limits for the BO4. #
##############################

MinHeight: 0

MaxHeight: 255

InheritBO3: 

InheritBO3Rotation: NORTH

OverrideChildSettings: true

OverrideParentHeight: false

CanOverride: false

BranchFrequency: 0

BranchFrequencyGroup: 

MustBeBelowOther: false

MustBeInside: 

CannotBeInside: 

ReplacesBO3: 

MustBeInsideWorldBorders: false

CanSpawnOnWater: true

SpawnOnWaterOnly: false

SpawnUnderWater: false

SpawnAtWaterLevel: false

HeightOffset: 0

RemoveAir: true

ReplaceAbove: 

ReplaceBelow: 

ReplaceWithBiomeBlocks: true

ReplaceWithSurfaceBlock: GRASS

ReplaceWithGroundBlock: DIRT

ReplaceWithStoneBlock: STONE

SmoothRadius: 0

SmoothHeightOffset: 0

SmoothStartTop: false

SmoothStartWood: false

SmoothingSurfaceBlock: 

SmoothingGroundBlock: 

BO3Group: 

IsSpawnPoint: false

DoReplaceBlocks: true


#######################################################################
# +-----------------------------------------------------------------+ #
# |                              Blocks                             | #
# +-----------------------------------------------------------------+ #
#######################################################################

Block(-8,0,-7,DIRT:0)
Block(-8,0,-6,DIRT:0)
Block(-8,0,-5,DIRT:0)
Block(-8,0,-4,DIRT:0)
Block(-8,0,-3,DIRT:0)
Block(-8,0,-2,DIRT:0)
Block(-8,0,-1,DIRT:0)
Block(-8,0,0,DIRT:0)
Block(-8,0,1,DIRT:0)
Block(-8,0,2,DIRT:0)
Block(-8,0,3,DIRT:0)
Block(-8,0,4,DIRT:0)
Block(-8,0,5,DIRT:0)
Block(-8,0,6,DIRT:0)
Block(-8,0,7,DIRT:0)
Block(-8,0,8,DIRT:0)
Block(-8,1,-7,DIRT:0)
Block(-8,1,-6,DIRT:0)
Block(-8,1,-5,DIRT:0)
Block(-8,1,-4,DIRT:0)
Block(-8,1,-3,DIRT:0)
Block(-8,1,-2,DIRT:0)
Block(-8,1,-1,DIRT:0)
Block(-8,1,0,DIRT:0)
Block(-8,1,1,DIRT:0)
Block(-8,1,2,DIRT:0)
Block(-8,1,3,DIRT:0)
Block(-8,1,4,DIRT:0)
Block(-8,1,5,DIRT:0)
Block(-8,1,6,DIRT:0)
Block(-8,1,7,DIRT:0)
Block(-8,1,8,DIRT:0)
Block(-8,2,-7,DIRT:0)
Block(-8,2,-6,DIRT:0)
Block(-8,2,-5,DIRT:0)
Block(-8,2,-4,DIRT:0)
Block(-8,2,-3,DIRT:0)
Block(-8,2,-2,DIRT:0)
Block(-8,2,-1,DIRT:0)
Block(-8,2,0,DIRT:0)
Block(-8,2,1,DIRT:0)
Block(-8,2,2,DIRT:0)
Block(-8,2,3,DIRT:0)
Block(-8,2,4,DIRT:0)
Block(-8,2,5,DIRT:0)
Block(-8,2,6,DIRT:0)
Block(-8,2,7,DIRT:0)
Block(-8,2,8,DIRT:0)
Block(-8,3,-7,DIRT:0)
Block(-8,3,-6,DIRT:0)
Block(-8,3,-5,DIRT:0)
Block(-8,3,-4,DIRT:0)
Block(-8,3,-3,DIRT:0)
Block(-8,3,-2,DIRT:0)
Block(-8,3,-1,DIRT:0)
Block(-8,3,0,DIRT:0)
Block(-8,3,1,DIRT:0)
Block(-8,3,2,DIRT:0)
Block(-8,3,3,DIRT:0)
Block(-8,3,4,DIRT:0)
Block(-8,3,5,DIRT:0)
Block(-8,3,6,DIRT:0)
Block(-8,3,7,DIRT:0)
Block(-8,3,8,DIRT:0)
Block(-8,4,-7,COBBLESTONE:0)
Block(-8,4,-6,COBBLESTONE:0)
Block(-8,4,-5,COBBLESTONE:0)
Block(-8,4,-4,COBBLESTONE:0)
Block(-8,4,-3,DIRT:0)
Block(-8,4,-2,DIRT:0)
Block(-8,4,-1,DIRT:0)
Block(-8,4,0,DIRT:0)
Block(-8,4,1,DIRT:0)
Block(-8,4,2,DIRT:0)
Block(-8,4,3,DIRT:0)
Block(-8,4,4,DIRT:0)
Block(-8,4,5,GRASS:0)
Block(-8,4,6,GRASS:0)
Block(-8,4,7,GRASS:0)
Block(-8,4,8,GRASS:0)
Block(-8,5,-7,IRON_FENCE:0)
Block(-8,5,-6,IRON_FENCE:0)
Block(-8,5,-5,IRON_FENCE:0)
Block(-8,5,-4,SMOOTH_STAIRS:2)
Block(-8,5,-3,DIRT:0)
Block(-8,5,-2,DIRT:0)
Block(-8,5,-1,DIRT:0)
Block(-8,5,0,DIRT:0)
Block(-8,5,1,DIRT:0)
Block(-8,5,2,GRASS:0)
Block(-8,5,3,DIRT:0)
Block(-8,5,4,GRASS:0)
Block(-8,5,5,SOIL:0)
Block(-8,5,6,SOIL:0)
Block(-8,6,-7,IRON_FENCE:0)
Block(-8,6,-6,LOG:5)
Block(-8,6,-5,IRON_FENCE:0)
Block(-8,6,-3,COBBLESTONE:0)
Block(-8,6,-2,STONE:0)
Block(-8,6,-1,COBBLESTONE_STAIRS:3)
Block(-8,6,0,HAY_BLOCK:8)
Block(-8,6,1,HAY_BLOCK:0)
Block(-8,6,3,HAY_BLOCK:0)
Block(-8,6,4,DARK_OAK_FENCE:0)
Block(-8,6,5,CROPS:7)
Block(-8,6,6,CROPS:7)
Block(-8,7,-7,IRON_FENCE:0)
Block(-8,7,-5,IRON_FENCE:0)
Block(-8,7,-3,HAY_BLOCK:0)
Block(-8,7,-2,COBBLESTONE:0)
Block(-8,7,-1,COBBLESTONE_STAIRS:7)
Block(-8,7,3,WOOD_STEP:9)
Block(-8,7,4,WOOD_STEP:1)
Block(-8,8,-7,IRON_FENCE:0)
Block(-8,8,-5,IRON_FENCE:0)
Block(-8,8,-2,COBBLESTONE:0)
Block(-8,8,-1,COBBLESTONE_STAIRS:3)
Block(-8,8,1,WOOD_STEP:9)
Block(-8,8,2,WOOD_STEP:1)
Block(-8,9,-7,IRON_FENCE:0)
Block(-8,9,-6,WOOD_STEP:13)
Block(-8,9,-5,IRON_FENCE:0)
Block(-8,9,-3,DARK_OAK_STAIRS:6)
Block(-8,9,-2,COBBLESTONE:0)
Block(-8,9,0,WOOD_STEP:1)
Block(-8,10,-7,IRON_FENCE:0)
Block(-8,10,-5,IRON_FENCE:0)
Block(-8,10,-3,HAY_BLOCK:0)
Block(-8,10,-2,WOOD:5)
Block(-8,11,-7,IRON_FENCE:0)
Block(-8,11,-5,IRON_FENCE:0)
Block(-8,11,-2,WOOD:5)
Block(-8,12,-7,IRON_FENCE:0)
Block(-8,12,-5,IRON_FENCE:0)
Block(-8,12,-4,LOG:5)
Block(-8,12,-2,WOOD:5)
Block(-8,13,-7,IRON_FENCE:0)
Block(-8,13,-5,IRON_FENCE:0)
Block(-8,13,-4,WOOD:0)
Block(-8,13,-3,WOOD:0)
Block(-8,13,-2,WOOD_DOUBLE_STEP:1)
Block(-8,13,-1,WOOD_STEP:1)
Block(-8,14,-7,IRON_FENCE:0)
Block(-8,14,-5,IRON_FENCE:0)
Block(-8,14,-4,WOOD:0)
Block(-8,14,-3,SPRUCE_WOOD_STAIRS:3)
Block(-8,15,-7,IRON_FENCE:0)
Block(-8,15,-5,IRON_FENCE:0)
Block(-8,15,-4,WOOD:5)
Block(-8,16,-7,IRON_FENCE:0)
Block(-8,16,-5,IRON_FENCE:0)
Block(-8,16,-4,WOOD:5)
Block(-8,17,-7,IRON_FENCE:0)
Block(-8,17,-5,IRON_FENCE:0)
Block(-8,17,-4,WOOD:5)
Block(-8,18,-7,IRON_FENCE:0)
Block(-8,18,-5,IRON_FENCE:0)
Block(-8,18,-4,LOG:5)
Block(-8,19,-7,IRON_FENCE:0)
Block(-8,19,-5,IRON_FENCE:0)
Block(-8,19,-4,WOOD:5)
Block(-8,20,-7,IRON_FENCE:0)
Block(-8,20,-5,IRON_FENCE:0)
Block(-8,20,-4,WOOD:5)
Block(-8,21,-7,IRON_FENCE:0)
Block(-8,21,-5,IRON_FENCE:0)
Block(-8,21,-4,WOOD:5)
Block(-8,22,-7,IRON_FENCE:0)
Block(-8,22,-5,IRON_FENCE:0)
Block(-8,22,-4,WOOD:5)
Block(-8,23,-7,IRON_FENCE:0)
Block(-8,23,-5,IRON_FENCE:0)
Block(-8,23,-4,WOOD:5)
Block(-8,24,-7,IRON_FENCE:0)
Block(-8,24,-5,IRON_FENCE:0)
Block(-8,24,-4,WOOD:5)
Block(-8,25,-7,IRON_FENCE:0)
Block(-8,25,-5,IRON_FENCE:0)
Block(-8,25,-4,WOOD:5)
Block(-8,25,-3,SPRUCE_WOOD_STAIRS:7)
Block(-8,26,-7,IRON_FENCE:0)
Block(-8,26,-6,LOG:5)
Block(-8,26,-5,IRON_FENCE:0)
Block(-8,26,-4,LOG:5)
Block(-8,26,-3,WOOD:5)
Block(-8,27,-7,IRON_FENCE:0)
Block(-8,27,-6,IRON_FENCE:0)
Block(-8,27,-5,IRON_FENCE:0)
Block(-8,27,-4,WOOD:5)
Block(-8,27,-3,WOOD:5)
Block(-8,28,-4,SPRUCE_WOOD_STAIRS:1)
Block(-8,28,-3,SPRUCE_WOOD_STAIRS:1)
Block(-8,29,-7,WOOD:1)
Block(-8,29,-6,TRAP_DOOR:10)
Block(-8,29,-5,WOOD:1)
Block(-8,30,-7,SPRUCE_WOOD_STAIRS:2)
Block(-8,30,-6,WOOD:1)
Block(-8,30,-5,SPRUCE_WOOD_STAIRS:3)
Block(-8,31,-6,WOOD_STEP:5)
Block(-7,0,-7,DIRT:0)
Block(-7,0,-6,DIRT:0)
Block(-7,0,-5,DIRT:0)
Block(-7,0,-4,DIRT:0)
Block(-7,0,-3,DIRT:0)
Block(-7,0,-2,DIRT:0)
Block(-7,0,-1,DIRT:0)
Block(-7,0,0,DIRT:0)
Block(-7,0,1,DIRT:0)
Block(-7,0,2,DIRT:0)
Block(-7,0,3,DIRT:0)
Block(-7,0,4,DIRT:0)
Block(-7,0,5,DIRT:0)
Block(-7,0,6,DIRT:0)
Block(-7,0,7,DIRT:0)
Block(-7,0,8,DIRT:0)
Block(-7,1,-7,DIRT:0)
Block(-7,1,-6,DIRT:0)
Block(-7,1,-5,DIRT:0)
Block(-7,1,-4,DIRT:0)
Block(-7,1,-3,DIRT:0)
Block(-7,1,-2,DIRT:0)
Block(-7,1,-1,DIRT:0)
Block(-7,1,0,DIRT:0)
Block(-7,1,1,DIRT:0)
Block(-7,1,2,DIRT:0)
Block(-7,1,3,DIRT:0)
Block(-7,1,4,DIRT:0)
Block(-7,1,5,DIRT:0)
Block(-7,1,6,DIRT:0)
Block(-7,1,7,DIRT:0)
Block(-7,1,8,DIRT:0)
Block(-7,2,-7,DIRT:0)
Block(-7,2,-6,DIRT:0)
Block(-7,2,-5,DIRT:0)
Block(-7,2,-4,DIRT:0)
Block(-7,2,-3,DIRT:0)
Block(-7,2,-2,DIRT:0)
Block(-7,2,-1,DIRT:0)
Block(-7,2,0,DIRT:0)
Block(-7,2,1,DIRT:0)
Block(-7,2,2,DIRT:0)
Block(-7,2,3,DIRT:0)
Block(-7,2,4,DIRT:0)
Block(-7,2,5,DIRT:0)
Block(-7,2,6,DIRT:0)
Block(-7,2,7,DIRT:0)
Block(-7,2,8,DIRT:0)
Block(-7,3,-7,DIRT:0)
Block(-7,3,-6,DIRT:0)
Block(-7,3,-5,DIRT:0)
Block(-7,3,-4,DIRT:0)
Block(-7,3,-3,DIRT:0)
Block(-7,3,-2,DIRT:0)
Block(-7,3,-1,DIRT:0)
Block(-7,3,0,DIRT:0)
Block(-7,3,1,DIRT:0)
Block(-7,3,2,DIRT:0)
Block(-7,3,3,DIRT:0)
Block(-7,3,4,DIRT:0)
Block(-7,3,5,DIRT:0)
Block(-7,3,6,DIRT:0)
Block(-7,3,7,DIRT:0)
Block(-7,3,8,DIRT:0)
Block(-7,4,-7,DIRT:0)
Block(-7,4,-6,DIRT:0)
Block(-7,4,-5,DIRT:0)
Block(-7,4,-4,DIRT:0)
Block(-7,4,-3,DIRT:0)
Block(-7,4,-2,DIRT:0)
Block(-7,4,-1,DIRT:0)
Block(-7,4,0,DIRT:0)
Block(-7,4,1,DIRT:0)
Block(-7,4,2,DIRT:0)
Block(-7,4,3,DIRT:0)
Block(-7,4,4,DIRT:0)
Block(-7,4,5,GRASS:0)
Block(-7,4,6,GRASS:0)
Block(-7,4,7,GRASS:0)
Block(-7,4,8,GRASS:0)
Block(-7,5,-7,COBBLESTONE:0)
Block(-7,5,-6,COBBLESTONE:0)
Block(-7,5,-5,COBBLESTONE:0)
Block(-7,5,-4,COBBLESTONE:0)
Block(-7,5,-3,DIRT:0)
Block(-7,5,-2,DIRT:0)
Block(-7,5,-1,DIRT:0)
Block(-7,5,0,DIRT:0)
Block(-7,5,1,GRASS:0)
Block(-7,5,2,DIRT:0)
Block(-7,5,3,GRASS:0)
Block(-7,5,4,GRASS:0)
Block(-7,5,5,SOIL:0)
Block(-7,5,6,SOIL:0)
Block(-7,6,-7,COBBLESTONE:0)
Block(-7,6,-6,LOG:5)
Block(-7,6,-5,COBBLESTONE:0)
Block(-7,6,-4,COBBLESTONE:0)
Block(-7,6,-3,COBBLESTONE:0)
Block(-7,6,-2,STONE:0)
Block(-7,6,-1,COBBLESTONE:0)
Block(-7,6,0,HAY_BLOCK:4)
Block(-7,6,2,HAY_BLOCK:0)
Block(-7,6,4,DARK_OAK_FENCE:0)
Block(-7,6,5,CROPS:7)
Block(-7,6,6,CROPS:7)
Block(-7,7,-4,HAY_BLOCK:8)
Block(-7,7,-3,HAY_BLOCK:8)
Block(-7,7,-2,LOG:1)
Block(-7,7,-1,COBBLESTONE:0)
Block(-7,7,0,HAY_BLOCK:0)
Block(-7,7,2,HAY_BLOCK:0)
Block(-7,7,3,WOOD_STEP:9)
Block(-7,7,4,WOOD_STEP:1)
Block(-7,8,-2,LOG:1)
Block(-7,8,-1,COBBLESTONE:0)
Block(-7,8,1,WOOD_STEP:9)
Block(-7,8,2,WOOD_STEP:1)
Block(-7,9,-7,WOOD_STEP:13)
Block(-7,9,-6,DARK_OAK_STAIRS:4)
Block(-7,9,-5,WOOD_STEP:13)
Block(-7,9,-4,WOOD_STEP:13)
Block(-7,9,-3,DARK_OAK_STAIRS:6)
Block(-7,9,-2,LOG:1)
Block(-7,9,-1,SMOOTH_STAIRS:3)
Block(-7,9,0,WOOD_STEP:1)
Block(-7,10,-3,HAY_BLOCK:0)
Block(-7,10,-2,LOG:1)
Block(-7,11,-2,LOG:1)
Block(-7,12,-7,LOG:9)
Block(-7,12,-6,LOG:9)
Block(-7,12,-5,LOG:9)
Block(-7,12,-4,LOG:9)
Block(-7,12,-3,LOG:9)
Block(-7,12,-2,LOG:9)
Block(-7,12,-1,LOG:9)
Block(-7,13,-7,WOOD:0)
Block(-7,13,-6,WOOD:0)
Block(-7,13,-5,WOOD:0)
Block(-7,13,-4,LOG:1)
Block(-7,13,-3,WOOD:0)
Block(-7,13,-2,WOOD_DOUBLE_STEP:1)
Block(-7,13,-1,WOOD_STEP:1)
Block(-7,14,-7,WOOD:0)
Block(-7,14,-6,WOOD:0)
Block(-7,14,-5,WOOD:0)
Block(-7,14,-4,LOG:1)
Block(-7,14,-3,SPRUCE_WOOD_STAIRS:1)
Block(-7,15,-7,WOOD:5)
Block(-7,15,-6,WOOD_STEP:1)
Block(-7,15,-5,WOOD:5)
Block(-7,15,-4,LOG:1)
Block(-7,16,-7,WOOD:5)
Block(-7,16,-6,SPRUCE_WOOD_STAIRS:5)
Block(-7,16,-5,WOOD:5)
Block(-7,16,-4,LOG:1)
Block(-7,17,-7,WOOD:5)
Block(-7,17,-6,WOOD:0)
Block(-7,17,-5,WOOD:5)
Block(-7,17,-4,LOG:1)
Block(-7,18,-7,LOG:9)
Block(-7,18,-6,LOG:9)
Block(-7,18,-5,LOG:9)
Block(-7,18,-4,LOG:1)
Block(-7,18,-3,LOG:9)
Block(-7,19,-7,WOOD:5)
Block(-7,19,-6,WOOD:0)
Block(-7,19,-5,WOOD:5)
Block(-7,19,-4,LOG:1)
Block(-7,20,-7,WOOD:5)
Block(-7,20,-6,WOOD:0)
Block(-7,20,-5,WOOD:5)
Block(-7,20,-4,LOG:1)
Block(-7,21,-7,WOOD:5)
Block(-7,21,-6,WOOD:0)
Block(-7,21,-5,WOOD:5)
Block(-7,21,-4,LOG:1)
Block(-7,22,-7,WOOD:5)
Block(-7,22,-6,WOOD:0)
Block(-7,22,-5,WOOD:5)
Block(-7,22,-4,LOG:1)
Block(-7,23,-7,WOOD:5)
Block(-7,23,-6,WOOD:0)
Block(-7,23,-5,WOOD:5)
Block(-7,23,-4,LOG:1)
Block(-7,24,-7,WOOD:5)
Block(-7,24,-6,WOOD:0)
Block(-7,24,-5,WOOD:5)
Block(-7,24,-4,LOG:1)
Block(-7,25,-7,WOOD:0)
Block(-7,25,-6,WOOD:0)
Block(-7,25,-5,WOOD:0)
Block(-7,25,-4,LOG:1)
Block(-7,25,-3,SPRUCE_WOOD_STAIRS:7)
Block(-7,26,-7,LOG:9)
Block(-7,26,-6,LOG:5)
Block(-7,26,-5,LOG:9)
Block(-7,26,-4,LOG:1)
Block(-7,26,-3,LOG:9)
Block(-7,27,-7,WOOD:0)
Block(-7,27,-6,WOOD:0)
Block(-7,27,-5,WOOD:0)
Block(-7,27,-4,WOOD:1)
Block(-7,28,-7,WOOD:0)
Block(-7,28,-6,WOOD:0)
Block(-7,28,-5,WOOD:0)
Block(-7,28,-4,SPRUCE_WOOD_STAIRS:3)
Block(-7,29,-7,WOOD:1)
Block(-7,29,-6,WOOD:0)
Block(-7,29,-5,WOOD:1)
Block(-7,30,-7,SPRUCE_WOOD_STAIRS:2)
Block(-7,30,-6,WOOD:1)
Block(-7,30,-5,SPRUCE_WOOD_STAIRS:3)
Block(-7,31,-6,WOOD_STEP:5)
Block(-6,0,-7,DIRT:0)
Block(-6,0,-6,DIRT:0)
Block(-6,0,-5,DIRT:0)
Block(-6,0,-4,DIRT:0)
Block(-6,0,-3,DIRT:0)
Block(-6,0,-2,DIRT:0)
Block(-6,0,-1,DIRT:0)
Block(-6,0,0,DIRT:0)
Block(-6,0,1,DIRT:0)
Block(-6,0,2,DIRT:0)
Block(-6,0,3,DIRT:0)
Block(-6,0,4,DIRT:0)
Block(-6,0,5,DIRT:0)
Block(-6,0,6,DIRT:0)
Block(-6,0,7,DIRT:0)
Block(-6,0,8,DIRT:0)
Block(-6,1,-7,DIRT:0)
Block(-6,1,-6,DIRT:0)
Block(-6,1,-5,DIRT:0)
Block(-6,1,-4,DIRT:0)
Block(-6,1,-3,DIRT:0)
Block(-6,1,-2,DIRT:0)
Block(-6,1,-1,DIRT:0)
Block(-6,1,0,DIRT:0)
Block(-6,1,1,DIRT:0)
Block(-6,1,2,DIRT:0)
Block(-6,1,3,DIRT:0)
Block(-6,1,4,DIRT:0)
Block(-6,1,5,DIRT:0)
Block(-6,1,6,DIRT:0)
Block(-6,1,7,DIRT:0)
Block(-6,1,8,DIRT:0)
Block(-6,2,-7,DIRT:0)
Block(-6,2,-6,DIRT:0)
Block(-6,2,-5,DIRT:0)
Block(-6,2,-4,DIRT:0)
Block(-6,2,-3,DIRT:0)
Block(-6,2,-2,DIRT:0)
Block(-6,2,-1,DIRT:0)
Block(-6,2,0,DIRT:0)
Block(-6,2,1,DIRT:0)
Block(-6,2,2,DIRT:0)
Block(-6,2,3,DIRT:0)
Block(-6,2,4,DIRT:0)
Block(-6,2,5,DIRT:0)
Block(-6,2,6,DIRT:0)
Block(-6,2,7,DIRT:0)
Block(-6,2,8,DIRT:0)
Block(-6,3,-7,DIRT:0)
Block(-6,3,-6,DIRT:0)
Block(-6,3,-5,DIRT:0)
Block(-6,3,-4,DIRT:0)
Block(-6,3,-3,DIRT:0)
Block(-6,3,-2,DIRT:0)
Block(-6,3,-1,DIRT:0)
Block(-6,3,0,DIRT:0)
Block(-6,3,1,DIRT:0)
Block(-6,3,2,DIRT:0)
Block(-6,3,3,DIRT:0)
Block(-6,3,4,DIRT:0)
Block(-6,3,5,DIRT:0)
Block(-6,3,6,DIRT:0)
Block(-6,3,7,DIRT:0)
Block(-6,3,8,GRASS:0)
Block(-6,4,-7,DIRT:0)
Block(-6,4,-6,DIRT:0)
Block(-6,4,-5,DIRT:0)
Block(-6,4,-4,DIRT:0)
Block(-6,4,-3,DIRT:0)
Block(-6,4,-2,DIRT:0)
Block(-6,4,-1,DIRT:0)
Block(-6,4,0,DIRT:0)
Block(-6,4,1,DIRT:0)
Block(-6,4,2,DIRT:0)
Block(-6,4,3,DIRT:0)
Block(-6,4,4,DIRT:0)
Block(-6,4,5,GRASS:0)
Block(-6,4,6,GRASS:0)
Block(-6,4,7,GRASS:0)
Block(-6,5,-7,DIRT:0)
Block(-6,5,-6,DIRT:0)
Block(-6,5,-5,DIRT:0)
Block(-6,5,-4,DIRT:0)
Block(-6,5,-3,DIRT:0)
Block(-6,5,-2,DIRT:0)
Block(-6,5,-1,DIRT:0)
Block(-6,5,0,GRASS:0)
Block(-6,5,1,GRASS:0)
Block(-6,5,2,DIRT:0)
Block(-6,5,3,GRASS:0)
Block(-6,5,4,DIRT:0)
Block(-6,5,5,SOIL:0)
Block(-6,6,-7,COBBLESTONE:0)
Block(-6,6,-6,LOG:5)
Block(-6,6,-5,COBBLESTONE:0)
Block(-6,6,-4,COBBLESTONE:0)
Block(-6,6,-3,STONE:0)
Block(-6,6,-2,COBBLESTONE:0)
Block(-6,6,-1,LOG:1)
Block(-6,6,2,LOG:1)
Block(-6,6,4,LOG:1)
Block(-6,6,5,CROPS:7)
Block(-6,7,-7,LADDER:2)
Block(-6,7,-6,LOG:1)
Block(-6,7,-5,HAY_BLOCK:8)
Block(-6,7,-4,HAY_BLOCK:0)
Block(-6,7,-3,COBBLESTONE:0)
Block(-6,7,-2,COBBLESTONE:0)
Block(-6,7,-1,LOG:1)
Block(-6,7,2,LOG:1)
Block(-6,7,3,WOOD_STEP:9)
Block(-6,7,4,WOOD_STEP:1)
Block(-6,8,-7,LADDER:2)
Block(-6,8,-6,LOG:1)
Block(-6,8,-4,HAY_BLOCK:8)
Block(-6,8,-3,COBBLESTONE:0)
Block(-6,8,-2,COBBLESTONE:0)
Block(-6,8,-1,LOG:1)
Block(-6,8,1,WOOD_STEP:9)
Block(-6,8,2,WOOD_STEP:1)
Block(-6,9,-7,LADDER:2)
Block(-6,9,-6,LOG:1)
Block(-6,9,-3,COBBLESTONE:0)
Block(-6,9,-2,SMOOTH_STAIRS:3)
Block(-6,9,-1,DARK_OAK_STAIRS:1)
Block(-6,9,0,WOOD_STEP:1)
Block(-6,10,-7,LADDER:2)
Block(-6,10,-6,LOG:1)
Block(-6,10,-3,WOOD:0)
Block(-6,11,-6,LOG:1)
Block(-6,11,-3,WOOD:0)
Block(-6,12,-6,LOG:1)
Block(-6,12,-4,LOG:5)
Block(-6,12,-3,WOOD:0)
Block(-6,13,-7,WOOD:0)
Block(-6,13,-6,WOOD:0)
Block(-6,13,-5,WOOD:0)
Block(-6,13,-4,WOOD:0)
Block(-6,13,-3,WOOD_DOUBLE_STEP:1)
Block(-6,13,-2,WOOD_STEP:1)
Block(-6,14,-7,SPRUCE_WOOD_STAIRS:1)
Block(-6,14,-6,SPRUCE_WOOD_STAIRS:1)
Block(-6,14,-5,SPRUCE_WOOD_STAIRS:1)
Block(-6,14,-4,SPRUCE_WOOD_STAIRS:3)
Block(-6,18,-4,LOG:5)
Block(-6,25,-7,COBBLESTONE_STAIRS:5)
Block(-6,25,-6,COBBLESTONE_STAIRS:5)
Block(-6,25,-5,COBBLESTONE_STAIRS:5)
Block(-6,25,-4,DARK_OAK_STAIRS:6)
Block(-6,25,-3,DARK_OAK_STAIRS:7)
Block(-6,26,-7,COBBLESTONE:0)
Block(-6,26,-6,LOG:5)
Block(-6,26,-5,COBBLESTONE:0)
Block(-6,26,-4,LOG:5)
Block(-6,26,-3,DARK_OAK_STAIRS:3)
Block(-6,27,-7,COBBLESTONE_STAIRS:1)
Block(-6,27,-6,COBBLESTONE_STAIRS:1)
Block(-6,27,-5,COBBLESTONE_STAIRS:1)
Block(-6,27,-4,WOOD:5)
Block(-6,28,-7,SPRUCE_WOOD_STAIRS:7)
Block(-6,28,-5,SPRUCE_WOOD_STAIRS:6)
Block(-6,28,-4,DARK_OAK_STAIRS:3)
Block(-6,29,-7,WOOD:5)
Block(-6,29,-6,DARK_OAK_STAIRS:5)
Block(-6,29,-5,WOOD:5)
Block(-6,30,-7,DARK_OAK_STAIRS:2)
Block(-6,30,-6,WOOD:1)
Block(-6,30,-5,DARK_OAK_STAIRS:3)
Block(-6,31,-6,WOOD_STEP:5)
Block(-5,0,-7,DIRT:0)
Block(-5,0,-6,DIRT:0)
Block(-5,0,-5,DIRT:0)
Block(-5,0,-4,DIRT:0)
Block(-5,0,-3,DIRT:0)
Block(-5,0,-2,DIRT:0)
Block(-5,0,-1,DIRT:0)
Block(-5,0,0,DIRT:0)
Block(-5,0,1,DIRT:0)
Block(-5,0,2,DIRT:0)
Block(-5,0,3,DIRT:0)
Block(-5,0,4,DIRT:0)
Block(-5,0,5,DIRT:0)
Block(-5,0,6,DIRT:0)
Block(-5,0,7,DIRT:0)
Block(-5,0,8,DIRT:0)
Block(-5,1,-7,DIRT:0)
Block(-5,1,-6,DIRT:0)
Block(-5,1,-5,DIRT:0)
Block(-5,1,-4,DIRT:0)
Block(-5,1,-3,DIRT:0)
Block(-5,1,-2,DIRT:0)
Block(-5,1,-1,DIRT:0)
Block(-5,1,0,DIRT:0)
Block(-5,1,1,DIRT:0)
Block(-5,1,2,DIRT:0)
Block(-5,1,3,DIRT:0)
Block(-5,1,4,DIRT:0)
Block(-5,1,5,DIRT:0)
Block(-5,1,6,DIRT:0)
Block(-5,1,7,DIRT:0)
Block(-5,1,8,DIRT:0)
Block(-5,2,-7,DIRT:0)
Block(-5,2,-6,DIRT:0)
Block(-5,2,-5,DIRT:0)
Block(-5,2,-4,DIRT:0)
Block(-5,2,-3,DIRT:0)
Block(-5,2,-2,DIRT:0)
Block(-5,2,-1,DIRT:0)
Block(-5,2,0,DIRT:0)
Block(-5,2,1,DIRT:0)
Block(-5,2,2,DIRT:0)
Block(-5,2,3,DIRT:0)
Block(-5,2,4,DIRT:0)
Block(-5,2,5,DIRT:0)
Block(-5,2,6,DIRT:0)
Block(-5,2,7,DIRT:0)
Block(-5,2,8,DIRT:0)
Block(-5,3,-7,DIRT:0)
Block(-5,3,-6,DIRT:0)
Block(-5,3,-5,DIRT:0)
Block(-5,3,-4,DIRT:0)
Block(-5,3,-3,DIRT:0)
Block(-5,3,-2,DIRT:0)
Block(-5,3,-1,DIRT:0)
Block(-5,3,0,DIRT:0)
Block(-5,3,1,DIRT:0)
Block(-5,3,2,DIRT:0)
Block(-5,3,3,DIRT:0)
Block(-5,3,4,DIRT:0)
Block(-5,3,5,DIRT:0)
Block(-5,3,6,DIRT:0)
Block(-5,3,7,GRASS:0)
Block(-5,3,8,GRASS:0)
Block(-5,4,-7,DIRT:0)
Block(-5,4,-6,DIRT:0)
Block(-5,4,-5,DIRT:0)
Block(-5,4,-4,DIRT:0)
Block(-5,4,-3,DIRT:0)
Block(-5,4,-2,DIRT:0)
Block(-5,4,-1,GRASS:0)
Block(-5,4,0,GRASS:0)
Block(-5,4,1,GRASS:0)
Block(-5,4,2,GRASS:0)
Block(-5,4,3,GRASS:0)
Block(-5,4,4,GRASS:0)
Block(-5,4,5,GRASS:0)
Block(-5,4,6,GRASS:0)
Block(-5,5,-7,DIRT:0)
Block(-5,5,-6,DIRT:0)
Block(-5,5,-5,DIRT:0)
Block(-5,5,-4,DIRT:0)
Block(-5,5,-3,DIRT:0)
Block(-5,5,-2,DIRT:0)
Block(-5,5,-1,SOIL:0)
Block(-5,5,0,SOIL:0)
Block(-5,5,1,SOIL:0)
Block(-5,5,2,SOIL:0)
Block(-5,5,3,SOIL:0)
Block(-5,5,4,SOIL:0)
Block(-5,5,5,SOIL:0)
Block(-5,6,-7,DIRT:0)
Block(-5,6,-6,DIRT:0)
Block(-5,6,-5,STONE:0)
Block(-5,6,-4,STONE:0)
Block(-5,6,-3,COBBLESTONE:0)
Block(-5,6,-2,LOG:1)
Block(-5,6,-1,CROPS:7)
Block(-5,6,0,CROPS:7)
Block(-5,6,1,CROPS:7)
Block(-5,6,2,CROPS:7)
Block(-5,6,3,CROPS:7)
Block(-5,6,4,CROPS:7)
Block(-5,6,5,CROPS:7)
Block(-5,7,-7,COBBLESTONE:0)
Block(-5,7,-6,COBBLESTONE:0)
Block(-5,7,-5,COBBLESTONE:0)
Block(-5,7,-4,LOG:1)
Block(-5,7,-3,COBBLESTONE:0)
Block(-5,7,-2,LOG:1)
Block(-5,8,-7,COBBLESTONE:0)
Block(-5,8,-6,COBBLESTONE:0)
Block(-5,8,-5,COBBLESTONE:0)
Block(-5,8,-4,LOG:1)
Block(-5,8,-3,COBBLESTONE:0)
Block(-5,8,-2,LOG:1)
Block(-5,9,-7,COBBLESTONE:0)
Block(-5,9,-6,COBBLESTONE:0)
Block(-5,9,-5,COBBLESTONE:0)
Block(-5,9,-4,LOG:1)
Block(-5,9,-3,SMOOTH_STAIRS:3)
Block(-5,9,-2,DARK_OAK_STAIRS:1)
Block(-5,10,-7,WOOD:5)
Block(-5,10,-6,WOOD:0)
Block(-5,10,-5,WOOD:5)
Block(-5,10,-4,LOG:1)
Block(-5,11,-7,WOOD:5)
Block(-5,11,-6,WOOD:0)
Block(-5,11,-5,WOOD:5)
Block(-5,11,-4,LOG:1)
Block(-5,12,-7,WOOD:5)
Block(-5,12,-6,WOOD:0)
Block(-5,12,-5,WOOD:5)
Block(-5,12,-4,LOG:5)
Block(-5,13,-7,WOOD_DOUBLE_STEP:1)
Block(-5,13,-6,WOOD_DOUBLE_STEP:1)
Block(-5,13,-5,WOOD_DOUBLE_STEP:1)
Block(-5,13,-4,WOOD_DOUBLE_STEP:1)
Block(-5,13,-3,WOOD_STEP:1)
Block(-5,26,-6,LOG:5)
Block(-4,0,-7,DIRT:0)
Block(-4,0,-6,DIRT:0)
Block(-4,0,-5,DIRT:0)
Block(-4,0,-4,DIRT:0)
Block(-4,0,-3,DIRT:0)
Block(-4,0,-2,DIRT:0)
Block(-4,0,-1,DIRT:0)
Block(-4,0,0,DIRT:0)
Block(-4,0,1,DIRT:0)
Block(-4,0,2,DIRT:0)
Block(-4,0,3,DIRT:0)
Block(-4,0,4,DIRT:0)
Block(-4,0,5,DIRT:0)
Block(-4,0,6,DIRT:0)
Block(-4,0,7,DIRT:0)
Block(-4,0,8,DIRT:0)
Block(-4,1,-7,DIRT:0)
Block(-4,1,-6,DIRT:0)
Block(-4,1,-5,DIRT:0)
Block(-4,1,-4,DIRT:0)
Block(-4,1,-3,DIRT:0)
Block(-4,1,-2,DIRT:0)
Block(-4,1,-1,DIRT:0)
Block(-4,1,0,DIRT:0)
Block(-4,1,1,DIRT:0)
Block(-4,1,2,DIRT:0)
Block(-4,1,3,DIRT:0)
Block(-4,1,4,DIRT:0)
Block(-4,1,5,DIRT:0)
Block(-4,1,6,DIRT:0)
Block(-4,1,7,DIRT:0)
Block(-4,1,8,DIRT:0)
Block(-4,2,-7,DIRT:0)
Block(-4,2,-6,DIRT:0)
Block(-4,2,-5,DIRT:0)
Block(-4,2,-4,DIRT:0)
Block(-4,2,-3,DIRT:0)
Block(-4,2,-2,DIRT:0)
Block(-4,2,-1,DIRT:0)
Block(-4,2,0,DIRT:0)
Block(-4,2,1,DIRT:0)
Block(-4,2,2,DIRT:0)
Block(-4,2,3,DIRT:0)
Block(-4,2,4,DIRT:0)
Block(-4,2,5,DIRT:0)
Block(-4,2,6,DIRT:0)
Block(-4,2,7,DIRT:0)
Block(-4,2,8,GRASS:0)
Block(-4,3,-7,DIRT:0)
Block(-4,3,-6,DIRT:0)
Block(-4,3,-5,DIRT:0)
Block(-4,3,-4,DIRT:0)
Block(-4,3,-3,DIRT:0)
Block(-4,3,-2,DIRT:0)
Block(-4,3,-1,DIRT:0)
Block(-4,3,0,DIRT:0)
Block(-4,3,1,DIRT:0)
Block(-4,3,2,DIRT:0)
Block(-4,3,3,DIRT:0)
Block(-4,3,4,DIRT:0)
Block(-4,3,5,DIRT:0)
Block(-4,3,6,GRASS:0)
Block(-4,3,7,GRASS:0)
Block(-4,4,-7,DIRT:0)
Block(-4,4,-6,DIRT:0)
Block(-4,4,-5,DIRT:0)
Block(-4,4,-4,DIRT:0)
Block(-4,4,-3,DIRT:0)
Block(-4,4,-2,DIRT:0)
Block(-4,4,-1,GRASS:0)
Block(-4,4,0,GRASS:0)
Block(-4,4,1,GRASS:0)
Block(-4,4,2,GRASS:0)
Block(-4,4,3,GRASS:0)
Block(-4,4,4,GRASS:0)
Block(-4,4,5,GRASS:0)
Block(-4,5,-7,GRASS:0)
Block(-4,5,-6,DIRT:0)
Block(-4,5,-5,GRASS:0)
Block(-4,5,-4,DIRT:0)
Block(-4,5,-3,LOG:1)
Block(-4,5,-2,SOIL:0)
Block(-4,5,-1,SOIL:0)
Block(-4,5,0,SOIL:0)
Block(-4,5,1,SOIL:0)
Block(-4,5,2,SOIL:0)
Block(-4,6,-7,COBBLESTONE_STAIRS:1)
Block(-4,6,-6,COBBLESTONE:0)
Block(-4,6,-5,COBBLESTONE_STAIRS:1)
Block(-4,6,-4,COBBLESTONE:0)
Block(-4,6,-3,LOG:1)
Block(-4,6,-2,CROPS:7)
Block(-4,6,-1,CROPS:7)
Block(-4,6,0,CROPS:7)
Block(-4,6,1,CROPS:7)
Block(-4,6,2,CROPS:7)
Block(-4,7,-7,COBBLESTONE_STAIRS:5)
Block(-4,7,-6,COBBLESTONE:0)
Block(-4,7,-5,COBBLESTONE_STAIRS:5)
Block(-4,7,-4,COBBLESTONE:0)
Block(-4,7,-3,LOG:1)
Block(-4,8,-7,COBBLESTONE_STAIRS:1)
Block(-4,8,-6,COBBLESTONE:0)
Block(-4,8,-5,COBBLESTONE_STAIRS:1)
Block(-4,8,-4,COBBLESTONE:0)
Block(-4,8,-3,LOG:1)
Block(-4,9,-6,SMOOTH_STAIRS:1)
Block(-4,9,-4,SMOOTH_STAIRS:1)
Block(-4,9,-3,DARK_OAK_STAIRS:1)
Block(-4,12,-4,LOG:5)
Block(-4,13,-7,WOOD_STEP:1)
Block(-4,13,-6,WOOD_STEP:1)
Block(-4,13,-5,WOOD_STEP:1)
Block(-4,13,-4,WOOD_STEP:1)
Block(-4,20,-2,WOOL:0)
Block(-4,20,-1,WOOL:0)
Block(-4,20,0,WOOL:0)
Block(-4,21,-4,WOOL:0)
Block(-4,21,-3,WOOL:0)
Block(-4,21,-2,FENCE:0)
Block(-4,21,-1,FENCE:0)
Block(-4,21,0,FENCE:0)
Block(-4,21,1,WOOL:0)
Block(-4,21,2,WOOL:0)
Block(-4,21,3,WOOL:0)
Block(-4,22,-5,WOOL:0)
Block(-4,22,-4,FENCE:0)
Block(-4,22,-3,FENCE:0)
Block(-4,22,-2,WOOD:5)
Block(-4,22,-1,WOOD:5)
Block(-4,22,0,WOOD:5)
Block(-4,22,1,FENCE:0)
Block(-4,22,2,FENCE:0)
Block(-4,22,3,WOOL:0)
Block(-4,22,4,WOOL:0)
Block(-4,22,5,WOOL:0)
Block(-4,23,-6,WOOL:0)
Block(-4,23,-5,FENCE:0)
Block(-4,23,-4,WOOD:5)
Block(-4,23,-3,WOOD:5)
Block(-4,23,-2,WOOD_STAIRS:3)
Block(-4,23,0,WOOD_STAIRS:2)
Block(-4,23,1,WOOD:5)
Block(-4,23,2,WOOD:5)
Block(-4,23,3,WOOD_STAIRS:3)
Block(-4,24,-6,WOOL:0)
Block(-4,24,-5,WOOD:5)
Block(-4,24,-4,WOOD_STAIRS:3)
Block(-4,25,-7,WOOD:5)
Block(-4,25,-6,FENCE:0)
Block(-4,25,-5,WOOD:5)
Block(-4,26,-7,FENCE:0)
Block(-4,26,-6,LOG:5)
Block(-4,26,-5,FENCE:0)
Block(-4,26,-4,WOOL:0)
Block(-4,26,-3,WOOL:0)
Block(-4,27,-7,WOOD:5)
Block(-4,27,-6,FENCE:0)
Block(-4,27,-5,WOOD:5)
Block(-4,27,-4,WOOD:5)
Block(-4,27,-3,FENCE:0)
Block(-4,27,-2,WOOL:0)
Block(-4,28,-7,WOOD:5)
Block(-4,28,-6,WOOL:0)
Block(-4,28,-4,WOOD_STAIRS:2)
Block(-4,28,-3,WOOD:5)
Block(-4,28,-2,FENCE:0)
Block(-4,28,-1,WOOL:0)
Block(-4,29,-7,FENCE:0)
Block(-4,29,-6,WOOL:0)
Block(-4,29,-3,WOOD:5)
Block(-4,29,-2,FENCE:0)
Block(-4,29,-1,WOOL:0)
Block(-4,30,-7,WOOL:0)
Block(-4,30,-3,WOOD_STAIRS:2)
Block(-4,30,-2,WOOD:5)
Block(-4,30,-1,FENCE:0)
Block(-4,30,0,WOOL:0)
Block(-4,31,-2,WOOD:5)
Block(-4,31,-1,FENCE:0)
Block(-4,31,0,WOOL:0)
Block(-4,32,-3,WOOD_STAIRS:6)
Block(-4,32,-2,WOOD:5)
Block(-4,32,-1,FENCE:0)
Block(-4,32,0,WOOL:0)
Block(-4,33,-3,WOOD:5)
Block(-4,33,-2,FENCE:0)
Block(-4,33,-1,WOOL:0)
Block(-4,34,-3,WOOD:5)
Block(-4,34,-2,FENCE:0)
Block(-4,34,-1,WOOL:0)
Block(-4,35,-3,WOOD_STAIRS:2)
Block(-4,35,-2,WOOL:0)
Block(-4,35,-1,WOOL:0)
Block(-4,36,-2,WOOL:0)
Block(-4,37,-2,WOOL:0)
Block(-3,0,-7,DIRT:0)
Block(-3,0,-6,DIRT:0)
Block(-3,0,-5,DIRT:0)
Block(-3,0,-4,DIRT:0)
Block(-3,0,-3,DIRT:0)
Block(-3,0,-2,DIRT:0)
Block(-3,0,-1,DIRT:0)
Block(-3,0,0,DIRT:0)
Block(-3,0,1,DIRT:0)
Block(-3,0,2,DIRT:0)
Block(-3,0,3,DIRT:0)
Block(-3,0,4,DIRT:0)
Block(-3,0,5,DIRT:0)
Block(-3,0,6,DIRT:0)
Block(-3,0,7,DIRT:0)
Block(-3,0,8,DIRT:0)
Block(-3,1,-7,DIRT:0)
Block(-3,1,-6,DIRT:0)
Block(-3,1,-5,DIRT:0)
Block(-3,1,-4,DIRT:0)
Block(-3,1,-3,DIRT:0)
Block(-3,1,-2,DIRT:0)
Block(-3,1,-1,DIRT:0)
Block(-3,1,0,DIRT:0)
Block(-3,1,1,DIRT:0)
Block(-3,1,2,DIRT:0)
Block(-3,1,3,DIRT:0)
Block(-3,1,4,DIRT:0)
Block(-3,1,5,DIRT:0)
Block(-3,1,6,DIRT:0)
Block(-3,1,7,GRASS:0)
Block(-3,1,8,GRASS:0)
Block(-3,2,-7,DIRT:0)
Block(-3,2,-6,DIRT:0)
Block(-3,2,-5,DIRT:0)
Block(-3,2,-4,DIRT:0)
Block(-3,2,-3,DIRT:0)
Block(-3,2,-2,DIRT:0)
Block(-3,2,-1,DIRT:0)
Block(-3,2,0,DIRT:0)
Block(-3,2,1,DIRT:0)
Block(-3,2,2,DIRT:0)
Block(-3,2,3,DIRT:0)
Block(-3,2,4,DIRT:0)
Block(-3,2,5,DIRT:0)
Block(-3,2,6,GRASS:0)
Block(-3,3,-7,DIRT:0)
Block(-3,3,-6,DIRT:0)
Block(-3,3,-5,DIRT:0)
Block(-3,3,-4,DIRT:0)
Block(-3,3,-3,DIRT:0)
Block(-3,3,-2,DIRT:0)
Block(-3,3,-1,DIRT:0)
Block(-3,3,0,DIRT:0)
Block(-3,3,1,DIRT:0)
Block(-3,3,2,DIRT:0)
Block(-3,3,3,GRASS:0)
Block(-3,3,4,GRASS:0)
Block(-3,3,5,GRASS:0)
Block(-3,4,-7,GRASS:0)
Block(-3,4,-6,GRASS:0)
Block(-3,4,-5,GRASS:0)
Block(-3,4,-4,GRASS:0)
Block(-3,4,-3,GRASS:0)
Block(-3,4,-2,GRASS:0)
Block(-3,4,-1,GRASS:0)
Block(-3,4,0,GRASS:0)
Block(-3,4,1,GRASS:0)
Block(-3,4,2,GRASS:0)
Block(-3,5,-7,SOIL:0)
Block(-3,5,-6,SOIL:0)
Block(-3,5,-5,SOIL:0)
Block(-3,5,-4,SOIL:0)
Block(-3,5,-3,SOIL:0)
Block(-3,5,-2,SOIL:0)
Block(-3,6,-7,CROPS:7)
Block(-3,6,-6,CROPS:7)
Block(-3,6,-5,CROPS:7)
Block(-3,6,-4,CROPS:7)
Block(-3,6,-3,CROPS:7)
Block(-3,6,-2,CROPS:7)
Block(-3,26,-6,LOG:5)
Block(-2,0,-7,DIRT:0)
Block(-2,0,-6,DIRT:0)
Block(-2,0,-5,DIRT:0)
Block(-2,0,-4,DIRT:0)
Block(-2,0,-3,DIRT:0)
Block(-2,0,-2,DIRT:0)
Block(-2,0,-1,DIRT:0)
Block(-2,0,0,DIRT:0)
Block(-2,0,1,DIRT:0)
Block(-2,0,2,DIRT:0)
Block(-2,0,3,DIRT:0)
Block(-2,0,4,DIRT:0)
Block(-2,0,5,DIRT:0)
Block(-2,0,6,DIRT:0)
Block(-2,0,7,DIRT:0)
Block(-2,0,8,GRASS:0)
Block(-2,1,-7,DIRT:0)
Block(-2,1,-6,DIRT:0)
Block(-2,1,-5,DIRT:0)
Block(-2,1,-4,DIRT:0)
Block(-2,1,-3,DIRT:0)
Block(-2,1,-2,DIRT:0)
Block(-2,1,-1,DIRT:0)
Block(-2,1,0,DIRT:0)
Block(-2,1,1,DIRT:0)
Block(-2,1,2,DIRT:0)
Block(-2,1,3,DIRT:0)
Block(-2,1,4,DIRT:0)
Block(-2,1,5,DIRT:0)
Block(-2,1,6,GRASS:0)
Block(-2,1,7,GRASS:0)
Block(-2,2,-7,DIRT:0)
Block(-2,2,-6,DIRT:0)
Block(-2,2,-5,DIRT:0)
Block(-2,2,-4,DIRT:0)
Block(-2,2,-3,DIRT:0)
Block(-2,2,-2,DIRT:0)
Block(-2,2,-1,DIRT:0)
Block(-2,2,0,DIRT:0)
Block(-2,2,1,DIRT:0)
Block(-2,2,2,DIRT:0)
Block(-2,2,3,DIRT:0)
Block(-2,2,4,GRASS:0)
Block(-2,2,5,GRASS:0)
Block(-2,3,-7,DIRT:0)
Block(-2,3,-6,DIRT:0)
Block(-2,3,-5,DIRT:0)
Block(-2,3,-4,DIRT:0)
Block(-2,3,-3,DIRT:0)
Block(-2,3,-2,DIRT:0)
Block(-2,3,-1,DIRT:0)
Block(-2,3,0,GRASS:0)
Block(-2,3,1,GRASS:0)
Block(-2,3,2,GRASS:0)
Block(-2,3,3,GRASS:0)
Block(-2,4,-7,GRASS:0)
Block(-2,4,-6,GRASS:0)
Block(-2,4,-5,GRASS:0)
Block(-2,4,-4,GRASS:0)
Block(-2,4,-3,GRASS:0)
Block(-2,4,-2,GRASS:0)
Block(-2,4,-1,GRASS:0)
Block(-1,0,-7,DIRT:0)
Block(-1,0,-6,DIRT:0)
Block(-1,0,-5,DIRT:0)
Block(-1,0,-4,DIRT:0)
Block(-1,0,-3,DIRT:0)
Block(-1,0,-2,DIRT:0)
Block(-1,0,-1,DIRT:0)
Block(-1,0,0,DIRT:0)
Block(-1,0,1,DIRT:0)
Block(-1,0,2,DIRT:0)
Block(-1,0,3,DIRT:0)
Block(-1,0,4,DIRT:0)
Block(-1,0,5,DIRT:0)
Block(-1,0,6,GRASS:0)
Block(-1,0,7,GRASS:0)
Block(-1,0,8,GRASS:0)
Block(-1,1,-7,DIRT:0)
Block(-1,1,-6,DIRT:0)
Block(-1,1,-5,DIRT:0)
Block(-1,1,-4,DIRT:0)
Block(-1,1,-3,DIRT:0)
Block(-1,1,-2,DIRT:0)
Block(-1,1,-1,DIRT:0)
Block(-1,1,0,DIRT:0)
Block(-1,1,1,DIRT:0)
Block(-1,1,2,DIRT:0)
Block(-1,1,3,DIRT:0)
Block(-1,1,4,GRASS:0)
Block(-1,1,5,GRASS:0)
Block(-1,2,-7,DIRT:0)
Block(-1,2,-6,DIRT:0)
Block(-1,2,-5,DIRT:0)
Block(-1,2,-4,DIRT:0)
Block(-1,2,-3,DIRT:0)
Block(-1,2,-2,DIRT:0)
Block(-1,2,-1,DIRT:0)
Block(-1,2,0,GRASS:0)
Block(-1,2,1,GRASS:0)
Block(-1,2,2,GRASS:0)
Block(-1,2,3,GRASS:0)
Block(-1,3,-7,DIRT:0)
Block(-1,3,-6,GRASS:0)
Block(-1,3,-5,GRASS:0)
Block(-1,3,-4,GRASS:0)
Block(-1,3,-3,GRASS:0)
Block(-1,3,-2,GRASS:0)
Block(-1,3,-1,GRASS:0)
Block(-1,4,-7,GRASS:0)

#######################################################################
# +-----------------------------------------------------------------+ #
# |                             Branches                            | #
# +-----------------------------------------------------------------+ #
#######################################################################

Branch(-16,0,0,true,WindMill_07C0R1,NORTH,100.0,0)

#######################################################################
# +-----------------------------------------------------------------+ #
# |                             Entities                            | #
# +-----------------------------------------------------------------+ #
#######################################################################


#######################################################################
# +-----------------------------------------------------------------+ #
# |                            Particles                            | #
# +-----------------------------------------------------------------+ #
#######################################################################


#######################################################################
# +-----------------------------------------------------------------+ #
# |                             Spawners                            | #
# +-----------------------------------------------------------------+ #
#######################################################################


#######################################################################
# +-----------------------------------------------------------------+ #
# |                             ModData                             | #
# +-----------------------------------------------------------------+ #
#######################################################################

