
#######################################################################
# +-----------------------------------------------------------------+ #
# |                            BO3 object                           | #
# +-----------------------------------------------------------------+ #
#######################################################################

Author: NLBlackHeavenNL

Description: No description given

Version: 3

SettingsMode: WriteWithoutComments


#######################################################################
# +-----------------------------------------------------------------+ #
# |                          Main settings                          | #
# +-----------------------------------------------------------------+ #
#######################################################################

Tree: true

Frequency: 1

Rarity: 100.0

RotateRandomly: false

SpawnHeight: highestSolidBlock

SpawnHeightOffset: -1

SpawnHeightVariance: 0

##############################
# Height Limits for the BO3. #
##############################

MinHeight: 0

MaxHeight: 255

######################
# Extrusion settings #
######################

ExtrudeMode: None

ExtrudeThroughBlocks: AIR

MaxBranchDepth: 10

ExcludedBiomes: All


#######################################################################
# +-----------------------------------------------------------------+ #
# |                      Source block settings                      | #
# +-----------------------------------------------------------------+ #
#######################################################################

SourceBlocks: AIR,GRASS,DIRT,biomesoplenty:dirt

MaxPercentageOutsideSourceBlock: 0

OutsideSourceBlock: placeAnyway

DoReplaceBlocks: true

IsOTGPlus: false


#######################################################################
# +-----------------------------------------------------------------+ #
# |                              Blocks                             | #
# +-----------------------------------------------------------------+ #
#######################################################################

Block(-3,26,-1,dynamictrees:leaves0:12)
Block(-3,26,0,dynamictrees:leaves0:12)
Block(-3,26,1,dynamictrees:leaves0:12)
Block(-3,26,2,dynamictrees:leaves0:12)
Block(-3,27,0,dynamictrees:leaves0:12)
Block(-3,27,1,dynamictrees:leaves0:12)
Block(-3,27,2,dynamictrees:leaves0:12)
Block(-2,13,4,dynamictrees:leaves0:12)
Block(-2,14,2,dynamictrees:leaves0:13)
Block(-2,14,3,dynamictrees:leaves0:12)
Block(-2,14,4,dynamictrees:leaves0:12)
Block(-2,15,2,dynamictrees:leaves0:12)
Block(-2,15,3,dynamictrees:leaves0:12)
Block(-2,15,4,dynamictrees:leaves0:12)
Block(-2,25,-1,dynamictrees:leaves0:12)
Block(-2,25,0,dynamictrees:leaves0:12)
Block(-2,25,1,dynamictrees:leaves0:12)
Block(-2,25,2,dynamictrees:leaves0:12)
Block(-2,26,-2,dynamictrees:leaves0:12)
Block(-2,26,-1,dynamictrees:leaves0:13)
Block(-2,26,0,dynamictrees:leaves0:14)
Block(-2,26,1,dynamictrees:leaves0:15)
Block(-2,26,2,dynamictrees:leaves0:14)
Block(-2,26,3,dynamictrees:leaves0:12)
Block(-2,27,-1,dynamictrees:leaves0:12)
Block(-2,27,0,dynamictrees:leaves0:13)
Block(-2,27,1,dynamictrees:leaves0:14)
Block(-2,27,2,dynamictrees:leaves0:13)
Block(-2,27,3,dynamictrees:leaves0:12)
Block(-2,28,0,dynamictrees:leaves0:12)
Block(-2,28,1,dynamictrees:leaves0:12)
Block(-2,28,2,dynamictrees:leaves0:12)
Block(-2,28,3,dynamictrees:leaves0:12)
Block(-1,13,2,dynamictrees:leaves0:13)
Block(-1,13,3,dynamictrees:leaves0:14)
Block(-1,13,4,dynamictrees:leaves0:13)
Block(-1,13,5,dynamictrees:leaves0:12)
Block(-1,14,1,dynamictrees:leaves0:15)
Block(-1,14,2,dynamictrees:leaves0:14)
Block(-1,14,3,dynamictrees:leaves0:15)
Block(-1,14,4,dynamictrees:leaves0:14)
Block(-1,14,5,dynamictrees:leaves0:12)
Block(-1,15,1,dynamictrees:leaves0:14)
Block(-1,15,2,dynamictrees:leaves0:13)
Block(-1,15,3,dynamictrees:leaves0:14)
Block(-1,15,4,dynamictrees:leaves0:13)
Block(-1,15,5,dynamictrees:leaves0:12)
Block(-1,16,0,dynamictrees:leaves0:12)
Block(-1,16,1,dynamictrees:leaves0:12)
Block(-1,16,2,dynamictrees:leaves0:12)
Block(-1,16,3,dynamictrees:leaves0:12)
Block(-1,16,4,dynamictrees:leaves0:12)
Block(-1,25,-1,dynamictrees:leaves0:12)
Block(-1,25,0,dynamictrees:leaves0:12)
Block(-1,26,-2,dynamictrees:leaves0:12)
Block(-1,26,-1,dynamictrees:leaves0:14)
Block(-1,26,0,dynamictrees:leaves0:15)
Block(-1,26,1,dynamictrees:junglebranch)
Block(-1,26,2,dynamictrees:leaves0:15)
Block(-1,26,3,dynamictrees:leaves0:13)
Block(-1,26,4,dynamictrees:leaves0:12)
Block(-1,27,-2,dynamictrees:leaves0:12)
Block(-1,27,-1,dynamictrees:leaves0:13)
Block(-1,27,0,dynamictrees:leaves0:14)
Block(-1,27,1,dynamictrees:leaves0:15)
Block(-1,27,2,dynamictrees:leaves0:15)
Block(-1,27,3,dynamictrees:leaves0:14)
Block(-1,27,4,dynamictrees:leaves0:12)
Block(-1,28,-1,dynamictrees:leaves0:12)
Block(-1,28,0,dynamictrees:leaves0:12)
Block(-1,28,1,dynamictrees:leaves0:13)
Block(-1,28,2,dynamictrees:leaves0:14)
Block(-1,28,3,dynamictrees:leaves0:13)
Block(-1,28,4,dynamictrees:leaves0:12)
Block(-1,29,1,dynamictrees:leaves0:12)
Block(-1,29,2,dynamictrees:leaves0:12)
Block(-1,29,3,dynamictrees:leaves0:12)
Block(0,0,1,dynamictrees:rootydirt:0)
Block(0,1,1,dynamictrees:junglebranch:7)
Block(0,2,1,dynamictrees:junglebranch:7)
Block(0,3,1,dynamictrees:junglebranch:7)
Block(0,4,1,dynamictrees:junglebranch:7)
Block(0,5,1,dynamictrees:junglebranch:7)
Block(0,6,1,dynamictrees:junglebranch:7)
Block(0,7,1,dynamictrees:junglebranch:6)
Block(0,8,1,dynamictrees:junglebranch:6)
Block(0,9,1,dynamictrees:junglebranch:6)
Block(0,10,1,dynamictrees:junglebranch:6)
Block(0,11,1,dynamictrees:junglebranch:5)
Block(0,12,1,dynamictrees:junglebranch:5)
Block(0,13,1,dynamictrees:junglebranch:5)
Block(0,13,3,dynamictrees:leaves0:15)
Block(0,13,4,dynamictrees:leaves0:14)
Block(0,13,5,dynamictrees:leaves0:12)
Block(0,14,1,dynamictrees:junglebranch:5)
Block(0,14,2,dynamictrees:junglebranch:1)
Block(0,14,3,dynamictrees:junglebranch)
Block(0,14,4,dynamictrees:leaves0:15)
Block(0,14,5,dynamictrees:leaves0:12)
Block(0,15,0,dynamictrees:leaves0:14)
Block(0,15,1,dynamictrees:junglebranch:4)
Block(0,15,2,dynamictrees:leaves0:12)
Block(0,15,3,dynamictrees:leaves0:15)
Block(0,15,4,dynamictrees:leaves0:14)
Block(0,15,5,dynamictrees:leaves0:12)
Block(0,16,-1,dynamictrees:leaves0:12)
Block(0,16,0,dynamictrees:leaves0:12)
Block(0,16,1,dynamictrees:junglebranch:4)
Block(0,16,2,dynamictrees:leaves0:12)
Block(0,16,3,dynamictrees:leaves0:12)
Block(0,16,4,dynamictrees:leaves0:12)
Block(0,17,0,dynamictrees:leaves0:12)
Block(0,17,1,dynamictrees:junglebranch:3)
Block(0,17,2,dynamictrees:leaves0:12)
Block(0,18,1,dynamictrees:junglebranch:3)
Block(0,19,1,dynamictrees:junglebranch:3)
Block(0,20,1,dynamictrees:junglebranch:3)
Block(0,21,1,dynamictrees:junglebranch:2)
Block(0,22,1,dynamictrees:junglebranch:2)
Block(0,23,1,dynamictrees:junglebranch:2)
Block(0,24,1,dynamictrees:junglebranch:1)
Block(0,25,-1,dynamictrees:leaves0:12)
Block(0,25,1,dynamictrees:junglebranch:1)
Block(0,25,2,dynamictrees:junglebranch)
Block(0,26,-2,dynamictrees:leaves0:12)
Block(0,26,-1,dynamictrees:leaves0:15)
Block(0,26,0,dynamictrees:junglebranch)
Block(0,26,1,dynamictrees:junglebranch:1)
Block(0,26,2,dynamictrees:leaves0:15)
Block(0,26,3,dynamictrees:leaves0:14)
Block(0,26,4,dynamictrees:leaves0:12)
Block(0,27,-2,dynamictrees:leaves0:12)
Block(0,27,-1,dynamictrees:leaves0:14)
Block(0,27,0,dynamictrees:leaves0:15)
Block(0,27,1,dynamictrees:junglebranch:1)
Block(0,27,2,dynamictrees:junglebranch)
Block(0,27,3,dynamictrees:leaves0:15)
Block(0,27,4,dynamictrees:leaves0:12)
Block(0,28,-1,dynamictrees:leaves0:12)
Block(0,28,0,dynamictrees:leaves0:13)
Block(0,28,1,dynamictrees:leaves0:14)
Block(0,28,2,dynamictrees:leaves0:15)
Block(0,28,3,dynamictrees:leaves0:14)
Block(0,28,4,dynamictrees:leaves0:12)
Block(0,29,0,dynamictrees:leaves0:12)
Block(0,29,1,dynamictrees:leaves0:12)
Block(0,29,2,dynamictrees:leaves0:12)
Block(0,29,3,dynamictrees:leaves0:12)
Block(1,13,4,dynamictrees:leaves0:13)
Block(1,13,5,dynamictrees:leaves0:12)
Block(1,14,3,dynamictrees:leaves0:15)
Block(1,14,4,dynamictrees:leaves0:14)
Block(1,14,5,dynamictrees:leaves0:12)
Block(1,15,0,dynamictrees:leaves0:14)
Block(1,15,1,dynamictrees:leaves0:15)
Block(1,15,2,dynamictrees:leaves0:14)
Block(1,15,3,dynamictrees:leaves0:14)
Block(1,15,4,dynamictrees:leaves0:13)
Block(1,15,5,dynamictrees:leaves0:12)
Block(1,16,-1,dynamictrees:leaves0:12)
Block(1,16,0,dynamictrees:leaves0:15)
Block(1,16,1,dynamictrees:junglebranch)
Block(1,16,2,dynamictrees:leaves0:15)
Block(1,16,3,dynamictrees:leaves0:12)
Block(1,16,4,dynamictrees:leaves0:12)
Block(1,17,-1,dynamictrees:leaves0:12)
Block(1,17,0,dynamictrees:leaves0:14)
Block(1,17,1,dynamictrees:leaves0:15)
Block(1,17,2,dynamictrees:leaves0:14)
Block(1,17,3,dynamictrees:leaves0:12)
Block(1,18,0,dynamictrees:leaves0:12)
Block(1,18,1,dynamictrees:leaves0:12)
Block(1,18,2,dynamictrees:leaves0:12)
Block(1,25,-1,dynamictrees:leaves0:12)
Block(1,26,-2,dynamictrees:leaves0:12)
Block(1,26,-1,dynamictrees:leaves0:14)
Block(1,26,0,dynamictrees:leaves0:15)
Block(1,26,1,dynamictrees:leaves0:15)
Block(1,26,2,dynamictrees:leaves0:14)
Block(1,26,3,dynamictrees:leaves0:13)
Block(1,26,4,dynamictrees:leaves0:12)
Block(1,27,-2,dynamictrees:leaves0:12)
Block(1,27,-1,dynamictrees:leaves0:13)
Block(1,27,0,dynamictrees:leaves0:15)
Block(1,27,1,dynamictrees:junglebranch)
Block(1,27,2,dynamictrees:leaves0:15)
Block(1,27,3,dynamictrees:leaves0:14)
Block(1,27,4,dynamictrees:leaves0:12)
Block(1,28,-1,dynamictrees:leaves0:12)
Block(1,28,0,dynamictrees:leaves0:14)
Block(1,28,1,dynamictrees:leaves0:15)
Block(1,28,2,dynamictrees:leaves0:14)
Block(1,28,3,dynamictrees:leaves0:13)
Block(1,28,4,dynamictrees:leaves0:12)
Block(1,29,0,dynamictrees:leaves0:12)
Block(1,29,1,dynamictrees:leaves0:12)
Block(1,29,2,dynamictrees:leaves0:12)
Block(1,29,3,dynamictrees:leaves0:12)
Block(2,13,4,dynamictrees:leaves0:12)
Block(2,14,3,dynamictrees:leaves0:12)
Block(2,14,4,dynamictrees:leaves0:12)
Block(2,15,0,dynamictrees:leaves0:13)
Block(2,15,1,dynamictrees:leaves0:14)
Block(2,15,2,dynamictrees:leaves0:13)
Block(2,15,3,dynamictrees:leaves0:12)
Block(2,15,4,dynamictrees:leaves0:12)
Block(2,16,-1,dynamictrees:leaves0:12)
Block(2,16,0,dynamictrees:leaves0:14)
Block(2,16,1,dynamictrees:leaves0:15)
Block(2,16,2,dynamictrees:leaves0:14)
Block(2,16,3,dynamictrees:leaves0:12)
Block(2,17,-1,dynamictrees:leaves0:12)
Block(2,17,0,dynamictrees:leaves0:13)
Block(2,17,1,dynamictrees:leaves0:14)
Block(2,17,2,dynamictrees:leaves0:13)
Block(2,17,3,dynamictrees:leaves0:12)
Block(2,18,0,dynamictrees:leaves0:12)
Block(2,18,1,dynamictrees:leaves0:12)
Block(2,18,2,dynamictrees:leaves0:12)
Block(2,26,-1,dynamictrees:leaves0:12)
Block(2,26,0,dynamictrees:leaves0:13)
Block(2,26,1,dynamictrees:leaves0:14)
Block(2,26,2,dynamictrees:leaves0:13)
Block(2,26,3,dynamictrees:leaves0:12)
Block(2,27,-1,dynamictrees:leaves0:12)
Block(2,27,0,dynamictrees:leaves0:14)
Block(2,27,1,dynamictrees:leaves0:15)
Block(2,27,2,dynamictrees:leaves0:14)
Block(2,27,3,dynamictrees:leaves0:13)
Block(2,27,4,dynamictrees:leaves0:12)
Block(2,28,-1,dynamictrees:leaves0:12)
Block(2,28,0,dynamictrees:leaves0:13)
Block(2,28,1,dynamictrees:leaves0:14)
Block(2,28,2,dynamictrees:leaves0:13)
Block(2,28,3,dynamictrees:leaves0:12)
Block(2,29,0,dynamictrees:leaves0:12)
Block(2,29,1,dynamictrees:leaves0:12)
Block(2,29,2,dynamictrees:leaves0:12)
Block(3,15,2,dynamictrees:leaves0:12)
Block(3,16,0,dynamictrees:leaves0:12)
Block(3,16,1,dynamictrees:leaves0:12)
Block(3,16,2,dynamictrees:leaves0:12)
Block(3,17,0,dynamictrees:leaves0:12)
Block(3,17,1,dynamictrees:leaves0:12)
Block(3,17,2,dynamictrees:leaves0:12)
Block(3,26,0,dynamictrees:leaves0:12)
Block(3,26,1,dynamictrees:leaves0:12)
Block(3,26,2,dynamictrees:leaves0:12)
Block(3,27,0,dynamictrees:leaves0:12)
Block(3,27,1,dynamictrees:leaves0:12)
Block(3,27,2,dynamictrees:leaves0:12)
Block(3,27,3,dynamictrees:leaves0:12)
Block(3,28,0,dynamictrees:leaves0:12)
Block(3,28,1,dynamictrees:leaves0:12)
Block(3,28,2,dynamictrees:leaves0:12)

#######################################################################
# +-----------------------------------------------------------------+ #
# |                            BO3 checks                           | #
# +-----------------------------------------------------------------+ #
#######################################################################

BlockCheck(0,-1,1,GRASS,DIRT,biomesoplenty:grass,biomesoplenty:dirt)

#######################################################################
# +-----------------------------------------------------------------+ #
# |                             Branches                            | #
# +-----------------------------------------------------------------+ #
#######################################################################


#######################################################################
# +-----------------------------------------------------------------+ #
# |                             Entities                            | #
# +-----------------------------------------------------------------+ #
#######################################################################


#######################################################################
# +-----------------------------------------------------------------+ #
# |                            Particles                            | #
# +-----------------------------------------------------------------+ #
#######################################################################


#######################################################################
# +-----------------------------------------------------------------+ #
# |                             Spawners                            | #
# +-----------------------------------------------------------------+ #
#######################################################################


#######################################################################
# +-----------------------------------------------------------------+ #
# |                             ModData                             | #
# +-----------------------------------------------------------------+ #
#######################################################################

