#######################################################################
# +-----------------------------------------------------------------+ #
# |                            BO3 object                           | #
# +-----------------------------------------------------------------+ #
#######################################################################

Author: Bo3 BulkEdit

Description: Converted Schematic - Modified by Bo3BulkEdit

Version: 3

SettingsMode: WriteDisable

#######################################################################
# +-----------------------------------------------------------------+ #
# |                          Main settings                          | #
# +-----------------------------------------------------------------+ #
#######################################################################

IsOTGPlus: true
Tree: false
Frequency: 1
Rarity: 100.0
RotateRandomly: false
SpawnHeight: randomY
MaxBranchDepth: 10
ExcludedBiomes: All

##############################
# Height Limits for the BO3. #
##############################

MinHeight: 0
MaxHeight: 255

#######################################################################
# +-----------------------------------------------------------------+ #
# |                      Source block settings                      | #
# +-----------------------------------------------------------------+ #
#######################################################################

CanOverride: true
MaxPercentageOutsideSourceBlock: 100
OutsideSourceBlock: placeAnyway

#######################################################################
# +-----------------------------------------------------------------+ #
# |                               OTG+                              | #
# +-----------------------------------------------------------------+ #
#######################################################################

BO3Group: CeilingCrystals:0

#######################################################################
# +-----------------------------------------------------------------+ #
# |                              Blocks                             | #
# +-----------------------------------------------------------------+ #
#######################################################################

B(0,750,0,AIR)
B(15,750,15,AIR)
B(0,-24,15,betternether:quartz_stained_glass:15)
B(1,-24,15,betternether:quartz_stained_glass:15)
B(2,-24,15,betternether:quartz_stained_glass:15)
B(1,-23,12,betternether:quartz_stained_glass:15)
B(0,-23,13,betternether:quartz_stained_glass:15)
B(1,-23,13,betternether:quartz_stained_glass:15)
B(2,-23,13,betternether:quartz_stained_glass:15)
B(0,-23,14,betternether:quartz_stained_glass:15)
B(1,-23,14,betternether:quartz_stained_glass:15)
B(2,-23,14,betternether:quartz_stained_glass:15)
B(0,-23,15,betternether:quartz_stained_glass:15)
B(1,-23,15,betternether:quartz_stained_glass:15)
B(2,-23,15,betternether:quartz_stained_glass:15)
B(3,-23,15,betternether:quartz_stained_glass:15)
B(0,-22,10,betternether:quartz_stained_glass:15)
B(0,-22,11,betternether:quartz_stained_glass:15)
B(1,-22,11,betternether:quartz_stained_glass:15)
B(0,-22,12,betternether:quartz_stained_glass:15)
B(1,-22,12,betternether:quartz_stained_glass:15)
B(0,-22,13,betternether:quartz_stained_glass:15)
B(1,-22,13,betternether:quartz_stained_glass:15)
B(2,-22,13,betternether:quartz_stained_glass:15)
B(2,-22,14,betternether:quartz_stained_glass:15)
B(2,-22,15,betternether:quartz_stained_glass:15)
B(0,-21,10,betternether:quartz_stained_glass:15)
B(0,-21,11,betternether:quartz_stained_glass:15)
B(1,-21,11,betternether:quartz_stained_glass:15)
B(0,-21,12,betternether:quartz_stained_glass:15)
B(1,-21,12,betternether:quartz_stained_glass:15)
B(2,-21,12,betternether:quartz_stained_glass:15)
B(0,-21,13,betternether:quartz_stained_glass:15)
B(1,-21,13,betternether:quartz_stained_glass:15)
B(2,-21,13,betternether:quartz_stained_glass:15)
B(0,-21,14,betternether:quartz_stained_glass:15)
B(1,-21,14,betternether:quartz_stained_glass:15)
B(2,-21,14,betternether:quartz_stained_glass:15)
B(0,-21,15,betternether:quartz_stained_glass:15)
B(1,-21,15,betternether:quartz_stained_glass:15)
B(0,-20,10,betternether:quartz_stained_glass:15)
B(0,-20,11,betternether:quartz_stained_glass:15)
B(1,-20,11,betternether:quartz_stained_glass:15)
B(0,-20,12,betternether:quartz_stained_glass:15)
B(1,-20,12,betternether:quartz_stained_glass:15)
B(0,-20,13,betternether:quartz_stained_glass:15)
B(1,-20,13,betternether:quartz_stained_glass:15)
B(2,-20,13,betternether:quartz_stained_glass:15)
B(0,-20,14,betternether:quartz_stained_glass:15)
B(1,-20,14,betternether:quartz_stained_glass:15)
B(0,-20,15,betternether:quartz_stained_glass:15)
B(1,-20,15,betternether:quartz_stained_glass:15)
B(0,-19,10,betternether:quartz_stained_glass:15)
B(0,-19,11,betternether:quartz_stained_glass:15)
B(1,-19,11,betternether:quartz_stained_glass:15)
B(0,-19,12,betternether:quartz_stained_glass:15)
B(1,-19,12,betternether:quartz_stained_glass:15)
B(0,-19,13,betternether:quartz_stained_glass:15)
B(1,-19,13,betternether:quartz_stained_glass:15)
B(0,-19,14,betternether:quartz_stained_glass:15)
B(0,-19,15,betternether:quartz_stained_glass:15)
B(0,-18,10,betternether:quartz_stained_glass:15)
B(0,-18,11,betternether:quartz_stained_glass:15)
B(0,-18,12,betternether:quartz_stained_glass:15)
B(1,-18,12,betternether:quartz_stained_glass:15)
B(0,-18,13,betternether:quartz_stained_glass:15)
B(0,-18,14,betternether:quartz_stained_glass:15)
B(0,-17,10,betternether:quartz_stained_glass:15)
B(0,-17,11,betternether:quartz_stained_glass:15)
B(0,-17,12,betternether:quartz_stained_glass:15)
B(0,-16,11,betternether:quartz_stained_glass:15)

