
#######################################################################
# +-----------------------------------------------------------------+ #
# |                            BO4 object                           | #
# +-----------------------------------------------------------------+ #
#######################################################################

Author: NLBlackEagle

Description: No description given

SettingsMode: WriteWithoutComments


#######################################################################
# +-----------------------------------------------------------------+ #
# |                          Main settings                          | #
# +-----------------------------------------------------------------+ #
#######################################################################

FixedRotation: 

Frequency: 0

SpawnHeight: highestBlock

UseCenterForHighestBlock: true

##############################
# Height Limits for the BO4. #
##############################

MinHeight: 0

MaxHeight: 255

InheritBO3: 

InheritBO3Rotation: NORTH

OverrideChildSettings: true

OverrideParentHeight: false

CanOverride: true

BranchFrequency: 0

BranchFrequencyGroup: 

MustBeBelowOther: false

MustBeInside: 

CannotBeInside: 

ReplacesBO3: 

MustBeInsideWorldBorders: false

CanSpawnOnWater: true

SpawnOnWaterOnly: false

SpawnUnderWater: false

SpawnAtWaterLevel: false

HeightOffset: 0

RemoveAir: false

ReplaceAbove: 

ReplaceBelow: 

ReplaceWithBiomeBlocks: false

ReplaceWithSurfaceBlock: GRASS

ReplaceWithGroundBlock: DIRT

ReplaceWithStoneBlock: STONE

SmoothRadius: 0

SmoothHeightOffset: 0

SmoothStartTop: false

SmoothStartWood: false

SmoothingSurfaceBlock: 

SmoothingGroundBlock: 

BO3Group: 

IsSpawnPoint: false

DoReplaceBlocks: true


#######################################################################
# +-----------------------------------------------------------------+ #
# |                              Blocks                             | #
# +-----------------------------------------------------------------+ #
#######################################################################

RandomBlock(-1,8,-7,rustic:iron_lattice,70,rustic:iron_lattice:0,100)
RandomBlock(-1,8,1,rustic:iron_lattice,70,rustic:iron_lattice:0,100)
RandomBlock(-1,9,-7,rustic:iron_lattice,70,rustic:iron_lattice:0,100)
RandomBlock(-1,9,1,rustic:iron_lattice,70,rustic:iron_lattice:0,100)
RandomBlock(-1,12,-7,rustic:iron_lattice,70,rustic:iron_lattice:0,100)
RandomBlock(-1,12,1,rustic:iron_lattice,70,rustic:iron_lattice:0,100)
RandomBlock(-1,13,-7,rustic:iron_lattice,70,rustic:iron_lattice:0,100)
RandomBlock(-1,13,1,rustic:iron_lattice,70,rustic:iron_lattice:0,100)
RandomBlock(0,8,-7,rustic:iron_lattice,70,rustic:iron_lattice:0,100)
Block(0,8,-5,quark:iron_plate:1)
Block(0,8,-3,quark:iron_plate:1)
Block(0,8,-1,quark:iron_plate:1)
RandomBlock(0,8,1,rustic:iron_lattice,70,rustic:iron_lattice:0,100)
Block(0,9,-7,quark:iron_plate:1)
Block(0,9,-5,quark:iron_plate:1)
Block(0,9,-3,quark:iron_plate:1)
Block(0,9,-1,quark:iron_plate:1)
Block(0,9,1,quark:iron_plate:1)
Block(0,10,-7,quark:iron_plate:1)
Block(0,10,-6,DISPENSER:0)
Block(0,10,-5,quark:iron_plate:1)
Block(0,10,-4,DISPENSER:0)
Block(0,10,-3,quark:iron_plate:1)
Block(0,10,-2,DISPENSER:0)
Block(0,10,-1,quark:iron_plate:1)
Block(0,10,0,DISPENSER:0)
Block(0,10,1,quark:iron_plate:1)
Block(0,10,2,AIR:0)
Block(0,10,3,AIR:0)
Block(0,10,4,AIR:0)
Block(0,10,5,AIR:0)
Block(0,10,6,AIR:0)
Block(0,10,7,AIR:0)
Block(0,10,8,AIR:0)
Block(0,11,-7,quark:framed_glass)
Block(0,11,-6,quark:framed_glass)
Block(0,11,-5,quark:framed_glass)
Block(0,11,-4,quark:framed_glass)
Block(0,11,-3,quark:framed_glass)
Block(0,11,-2,quark:framed_glass)
Block(0,11,-1,quark:framed_glass)
Block(0,11,0,quark:framed_glass)
Block(0,11,1,quark:framed_glass)
Block(0,12,-7,quark:iron_plate:1)
Block(0,12,-6,quark:iron_plate:1)
Block(0,12,-5,quark:iron_plate:1)
Block(0,12,-4,quark:iron_plate:1)
Block(0,12,-3,quark:iron_plate:1)
Block(0,12,-2,quark:iron_plate:1)
Block(0,12,-1,quark:iron_plate:1)
Block(0,12,0,quark:iron_plate:1)
Block(0,12,1,quark:iron_plate:1)
RandomBlock(0,13,-7,rustic:iron_lattice,70,rustic:iron_lattice:0,100)
Block(0,13,-6,AIR:0)
Block(0,13,-5,quark:iron_plate:1)
Block(0,13,-4,AIR:0)
Block(0,13,-3,quark:iron_plate:1)
Block(0,13,-2,AIR:0)
Block(0,13,-1,quark:iron_plate:1)
Block(0,13,0,AIR:0)
RandomBlock(0,13,1,rustic:iron_lattice,70,rustic:iron_lattice:0,100)
Block(1,7,-5,quark:iron_plate:1)
Block(1,7,-3,quark:iron_plate:1)
Block(1,7,-1,quark:iron_plate:1)
RandomBlock(1,8,-7,rustic:iron_lattice,70,rustic:iron_lattice:0,100)
Block(1,8,-5,quark:iron_plate:1)
Block(1,8,-3,quark:iron_plate:1)
Block(1,8,-1,quark:iron_plate:1)
RandomBlock(1,8,1,rustic:iron_lattice,70,rustic:iron_lattice:0,100)
Block(1,9,-7,quark:iron_plate:1)
Block(1,9,-6,quark:iron_plate:1)
Block(1,9,-5,quark:iron_plate:1)
Block(1,9,-4,quark:iron_plate:1)
Block(1,9,-3,MOB_SPAWNER:0,../../ruins_spawners/soldiers_multi.nbt)
Block(1,9,-2,quark:iron_plate:1)
Block(1,9,-1,quark:iron_plate:1)
Block(1,9,0,quark:iron_plate:1)
Block(1,9,1,quark:iron_plate:1)
Block(1,10,-7,quark:iron_plate:1)
Block(1,10,-6,AIR:0)
Block(1,10,-5,LEVER:9)
Block(1,10,-4,AIR:0)
Block(1,10,-3,AIR:0)
Block(1,10,-2,AIR:0)
Block(1,10,-1,LEVER:9)
Block(1,10,0,AIR:0)
Block(1,10,1,quark:iron_plate:1)
Block(1,10,2,AIR:0)
Block(1,10,3,AIR:0)
Block(1,10,4,AIR:0)
Block(1,10,5,AIR:0)
Block(1,10,6,AIR:0)
Block(1,10,7,AIR:0)
Block(1,10,8,AIR:0)
Block(1,11,-7,quark:framed_glass)
Block(1,11,-6,AIR:0)
Block(1,11,-5,AIR:0)
Block(1,11,-4,AIR:0)
Block(1,11,-3,AIR:0)
Block(1,11,-2,AIR:0)
Block(1,11,-1,AIR:0)
Block(1,11,0,AIR:0)
Block(1,11,1,quark:framed_glass)
Block(1,12,-7,quark:iron_plate:1)
Block(1,12,-6,quark:iron_plate:1)
Block(1,12,-5,quark:iron_plate:1)
Block(1,12,-4,quark:iron_plate:1)
Block(1,12,-3,quark:iron_plate:1)
Block(1,12,-2,quark:iron_plate:1)
Block(1,12,-1,quark:iron_plate:1)
Block(1,12,0,quark:iron_plate:1)
Block(1,12,1,quark:iron_plate:1)
RandomBlock(1,13,-7,rustic:iron_lattice,70,rustic:iron_lattice:0,100)
Block(1,13,-6,AIR:0)
Block(1,13,-5,quark:iron_plate:1)
Block(1,13,-4,AIR:0)
Block(1,13,-3,quark:iron_plate:1)
Block(1,13,-2,AIR:0)
Block(1,13,-1,quark:iron_plate:1)
Block(1,13,0,AIR:0)
RandomBlock(1,13,1,rustic:iron_lattice,70,rustic:iron_lattice:0,100)
RandomBlock(2,6,-7,rustic:iron_lattice,70,rustic:iron_lattice:0,100)
RandomBlock(2,7,-7,rustic:iron_lattice,70,rustic:iron_lattice:0,100)
Block(2,7,-5,quark:iron_plate:1)
Block(2,7,-3,quark:iron_plate:1)
Block(2,7,-1,quark:iron_plate:1)
RandomBlock(2,7,1,rustic:iron_lattice,70,rustic:iron_lattice:0,100)
RandomBlock(2,8,-7,rustic:iron_lattice,70,rustic:iron_lattice:0,100)
Block(2,8,-5,quark:iron_plate:1)
Block(2,8,-3,quark:iron_plate:1)
Block(2,8,-1,quark:iron_plate:1)
RandomBlock(2,8,1,rustic:iron_lattice,70,rustic:iron_lattice:0,100)
Block(2,9,-7,quark:iron_plate:1)
Block(2,9,-6,quark:iron_plate:1)
Block(2,9,-5,quark:iron_plate:1)
Block(2,9,-4,quark:iron_plate:1)
Block(2,9,-3,quark:iron_plate:1)
Block(2,9,-2,quark:iron_plate:1)
Block(2,9,-1,quark:iron_plate:1)
Block(2,9,0,quark:iron_plate:1)
Block(2,9,1,quark:iron_plate:1)
Block(2,9,2,quark:iron_plate_stairs:4)
Block(2,9,3,quark:iron_plate_stairs:4)
Block(2,9,4,quark:iron_plate_stairs:4)
Block(2,10,-7,quark:iron_plate:1)
Block(2,10,-6,AIR:0)
Block(2,10,-5,AIR:0)
Block(2,10,-4,AIR:0)
Block(2,10,-3,AIR:0)
Block(2,10,-2,AIR:0)
Block(2,10,-1,AIR:0)
Block(2,10,0,AIR:0)
Block(2,10,1,quark:iron_plate:1)
Block(2,10,2,quark:iron_plate:1)
Block(2,10,3,quark:iron_plate:1)
Block(2,10,4,quark:iron_plate:1)
Block(2,10,5,AIR:0)
Block(2,10,6,AIR:0)
Block(2,10,7,AIR:0)
Block(2,10,8,AIR:0)
Block(2,11,-7,quark:framed_glass)
Block(2,11,-6,AIR:0)
Block(2,11,-5,AIR:0)
Block(2,11,-4,AIR:0)
Block(2,11,-3,AIR:0)
Block(2,11,-2,AIR:0)
Block(2,11,-1,AIR:0)
Block(2,11,0,AIR:0)
Block(2,11,1,quark:framed_glass)
Block(2,11,2,quark:framed_glass)
Block(2,11,3,quark:framed_glass)
Block(2,11,4,quark:framed_glass)
Block(2,12,-7,quark:iron_plate:1)
Block(2,12,-6,quark:iron_plate:1)
Block(2,12,-5,quark:iron_plate:1)
Block(2,12,-4,quark:iron_plate:1)
Block(2,12,-3,quark:iron_plate:1)
Block(2,12,-2,quark:iron_plate:1)
Block(2,12,-1,quark:iron_plate:1)
Block(2,12,0,quark:iron_plate:1)
Block(2,12,1,quark:iron_plate:1)
Block(2,12,2,quark:iron_plate:1)
Block(2,12,3,quark:iron_plate:1)
Block(2,12,4,quark:iron_plate:1)
RandomBlock(2,13,-7,rustic:iron_lattice,70,rustic:iron_lattice:0,100)
Block(2,13,-6,AIR:0)
Block(2,13,-5,quark:iron_plate:1)
Block(2,13,-4,AIR:0)
Block(2,13,-3,quark:iron_plate:1)
Block(2,13,-2,AIR:0)
Block(2,13,-1,quark:iron_plate:1)
Block(2,13,0,AIR:0)
RandomBlock(2,13,1,rustic:iron_lattice,70,rustic:iron_lattice:0,100)
RandomBlock(3,5,-7,rustic:iron_lattice,70,rustic:iron_lattice:0,100)
RandomBlock(3,5,1,rustic:iron_lattice,70,rustic:iron_lattice:0,100)
RandomBlock(3,6,-7,rustic:iron_lattice,70,rustic:iron_lattice:0,100)
Block(3,6,-5,quark:iron_plate_stairs:4)
Block(3,6,-3,quark:iron_plate_stairs:4)
Block(3,6,-1,quark:iron_plate_stairs:4)
RandomBlock(3,6,1,rustic:iron_lattice,70,rustic:iron_lattice:0,100)
Block(3,7,-7,quark:iron_plate:1)
Block(3,7,-5,quark:iron_plate:1)
Block(3,7,-3,quark:iron_plate:1)
Block(3,7,-1,quark:iron_plate:1)
RandomBlock(3,7,1,rustic:iron_lattice,70,rustic:iron_lattice:0,100)
Block(3,8,-7,quark:iron_plate:1)
Block(3,8,-5,quark:iron_plate:1)
Block(3,8,-3,quark:iron_plate:1)
Block(3,8,-1,quark:iron_plate:1)
Block(3,8,1,quark:iron_plate:1)
Block(3,9,-7,quark:iron_plate:1)
Block(3,9,-6,quark:iron_plate:1)
Block(3,9,-5,quark:iron_plate:1)
Block(3,9,-4,quark:iron_plate:1)
Block(3,9,-3,quark:iron_plate:1)
Block(3,9,-2,quark:iron_plate:1)
Block(3,9,-1,quark:iron_plate:1)
Block(3,9,0,quark:iron_plate:1)
Block(3,9,1,quark:iron_plate:1)
Block(3,9,2,quark:iron_plate:1)
Block(3,9,3,quark:iron_plate:1)
Block(3,9,4,quark:iron_plate:1)
Block(3,10,-7,AIR:0)
Block(3,10,-6,AIR:0)
Block(3,10,-5,AIR:0)
Block(3,10,-4,AIR:0)
Block(3,10,-3,AIR:0)
Block(3,10,-2,AIR:0)
Block(3,10,-1,AIR:0)
Block(3,10,0,AIR:0)
Block(3,10,1,AIR:0)
Block(3,10,2,AIR:0)
Block(3,10,3,AIR:0)
Block(3,10,4,quark:iron_plate:1)
Block(3,10,5,quark:iron_plate:1)
Block(3,10,6,quark:iron_plate:1)
Block(3,10,7,quark:iron_plate:1)
Block(3,10,8,quark:iron_plate:1)
Block(3,11,-7,AIR:0)
Block(3,11,-6,AIR:0)
Block(3,11,-5,AIR:0)
Block(3,11,-4,AIR:0)
Block(3,11,-3,AIR:0)
Block(3,11,-2,AIR:0)
Block(3,11,-1,AIR:0)
Block(3,11,0,AIR:0)
Block(3,11,1,AIR:0)
Block(3,11,2,AIR:0)
Block(3,11,3,AIR:0)
Block(3,11,4,quark:framed_glass)
Block(3,12,-7,quark:iron_plate:1)
Block(3,12,-6,quark:iron_plate:1)
Block(3,12,-5,quark:iron_plate:1)
Block(3,12,-4,quark:iron_plate:1)
Block(3,12,-3,quark:iron_plate:1)
Block(3,12,-2,quark:iron_plate:1)
Block(3,12,-1,quark:iron_plate:1)
Block(3,12,0,quark:iron_plate:1)
Block(3,12,1,quark:iron_plate:1)
Block(3,12,2,quark:iron_plate:1)
Block(3,12,3,quark:iron_plate:1)
Block(3,12,4,quark:iron_plate:1)
RandomBlock(3,13,-7,rustic:iron_lattice,70,rustic:iron_lattice:0,100)
Block(3,13,-6,AIR:0)
Block(3,13,-5,quark:iron_plate:1)
Block(3,13,-4,AIR:0)
Block(3,13,-3,quark:iron_plate:1)
Block(3,13,-2,AIR:0)
Block(3,13,-1,quark:iron_plate:1)
Block(3,13,0,AIR:0)
RandomBlock(3,13,1,rustic:iron_lattice,70,rustic:iron_lattice:0,100)
Block(3,13,2,quark:iron_plate_stairs:0)
Block(3,13,4,quark:iron_plate_stairs:0)
RandomBlock(3,14,-7,rustic:iron_lattice,70,rustic:iron_lattice:0,100)
Block(3,14,-5,quark:iron_plate_stairs:0)
Block(3,14,-3,quark:iron_plate_stairs:0)
Block(3,14,-1,quark:iron_plate_stairs:0)
RandomBlock(3,14,1,rustic:iron_lattice,70,rustic:iron_lattice:0,100)
RandomBlock(3,15,-7,rustic:iron_lattice,70,rustic:iron_lattice:0,100)
RandomBlock(3,15,1,rustic:iron_lattice,70,rustic:iron_lattice:0,100)
RandomBlock(4,4,-7,rustic:iron_lattice,70,rustic:iron_lattice:0,100)
RandomBlock(4,4,1,rustic:iron_lattice,70,rustic:iron_lattice:0,100)
RandomBlock(4,5,-7,rustic:iron_lattice,70,rustic:iron_lattice:0,100)
RandomBlock(4,5,1,rustic:iron_lattice,70,rustic:iron_lattice:0,100)
Block(4,6,-7,quark:iron_plate:1)
Block(4,6,-5,quark:iron_plate:1)
Block(4,6,-3,quark:iron_plate:1)
Block(4,6,-1,quark:iron_plate:1)
Block(4,6,1,quark:iron_plate:1)
Block(4,7,-7,quark:iron_plate:1)
Block(4,7,-5,quark:iron_plate:1)
Block(4,7,-3,quark:iron_plate:1)
Block(4,7,-1,quark:iron_plate:1)
Block(4,7,1,quark:iron_plate:1)
RandomBlock(4,8,-7,IRON_FENCE,7,WOOL:15,50,LEAVES:0,50,AIR,100)
RandomBlock(4,8,-6,IRON_FENCE,7,WOOL:15,50,LEAVES:0,50,AIR,100)
RandomBlock(4,8,-5,IRON_FENCE,7,WOOL:15,50,LEAVES:0,50,AIR,100)
RandomBlock(4,8,-4,IRON_FENCE,7,WOOL:15,50,LEAVES:0,50,AIR,100)
RandomBlock(4,8,-3,IRON_FENCE,7,WOOL:15,50,LEAVES:0,50,AIR,100)
RandomBlock(4,8,-2,IRON_FENCE,7,WOOL:15,50,LEAVES:0,50,AIR,100)
RandomBlock(4,8,-1,IRON_FENCE,7,WOOL:15,50,LEAVES:0,50,AIR,100)
RandomBlock(4,8,0,IRON_FENCE,7,WOOL:15,50,LEAVES:0,50,AIR,100)
RandomBlock(4,8,1,IRON_FENCE,7,WOOL:15,50,LEAVES:0,50,AIR,100)
RandomBlock(4,8,2,IRON_FENCE,7,WOOL:15,50,LEAVES:0,50,AIR,100)
RandomBlock(4,8,3,IRON_FENCE,7,WOOL:15,50,LEAVES:0,50,AIR,100)
RandomBlock(4,8,4,IRON_FENCE,7,WOOL:15,50,LEAVES:0,50,AIR,100)
RandomBlock(4,8,5,IRON_FENCE,7,WOOL:15,50,LEAVES:0,50,AIR,100)
RandomBlock(4,8,6,IRON_FENCE,7,WOOL:15,50,LEAVES:0,50,AIR,100)
RandomBlock(4,8,7,IRON_FENCE,7,WOOL:15,50,LEAVES:0,50,AIR,100)
RandomBlock(4,8,8,IRON_FENCE,7,WOOL:15,50,LEAVES:0,50,AIR,100)
RandomBlock(4,9,-7,IRON_FENCE,7,WOOL:15,50,LEAVES:0,50,AIR,100)
RandomBlock(4,9,-6,IRON_FENCE,7,WOOL:15,50,LEAVES:0,50,AIR,100)
RandomBlock(4,9,-5,IRON_FENCE,7,WOOL:15,50,LEAVES:0,50,AIR,100)
RandomBlock(4,9,-4,IRON_FENCE,7,WOOL:15,50,LEAVES:0,50,AIR,100)
Block(4,9,-3,quark:iron_plate:1)
RandomBlock(4,9,-2,IRON_FENCE,7,WOOL:15,50,LEAVES:0,50,AIR,100)
RandomBlock(4,9,-1,IRON_FENCE,7,WOOL:15,50,LEAVES:0,50,AIR,100)
RandomBlock(4,9,0,IRON_FENCE,7,WOOL:15,50,LEAVES:0,50,AIR,100)
RandomBlock(4,9,1,IRON_FENCE,7,WOOL:15,50,LEAVES:0,50,AIR,100)
RandomBlock(4,9,2,IRON_FENCE,7,WOOL:15,50,LEAVES:0,50,AIR,100)
RandomBlock(4,9,3,IRON_FENCE,7,WOOL:15,50,LEAVES:0,50,AIR,100)
RandomBlock(4,9,4,IRON_FENCE,7,WOOL:15,50,LEAVES:0,50,AIR,100)
RandomBlock(4,9,5,IRON_FENCE,7,WOOL:15,50,LEAVES:0,50,AIR,100)
RandomBlock(4,9,6,IRON_FENCE,7,WOOL:15,50,LEAVES:0,50,AIR,100)
RandomBlock(4,9,7,IRON_FENCE,7,WOOL:15,50,LEAVES:0,50,AIR,100)
RandomBlock(4,9,8,IRON_FENCE,7,WOOL:15,50,LEAVES:0,50,AIR,100)
Block(4,10,-7,quark:iron_plate:1)
Block(4,10,-6,quark:iron_plate:1)
Block(4,10,-5,quark:iron_plate:1)
Block(4,10,-4,quark:iron_plate:1)
Block(4,10,-3,AIR:0)
Block(4,10,-2,quark:iron_plate:1)
Block(4,10,-1,quark:iron_plate:1)
Block(4,10,0,quark:iron_plate:1)
Block(4,10,1,quark:iron_plate:1)
Block(4,10,2,quark:iron_plate:1)
Block(4,10,3,quark:iron_plate:1)
Block(4,10,4,quark:iron_plate:1)
RandomBlock(4,10,5,IRON_FENCE,7,WOOL:15,50,LEAVES:0,50,AIR,100)
RandomBlock(4,10,6,IRON_FENCE,7,WOOL:15,50,LEAVES:0,50,AIR,100)
RandomBlock(4,10,7,IRON_FENCE,7,WOOL:15,50,LEAVES:0,50,AIR,100)
RandomBlock(4,10,8,IRON_FENCE,7,WOOL:15,50,LEAVES:0,50,AIR,100)
Block(4,11,-7,quark:iron_plate:1)
Block(4,11,-6,quark:iron_plate:1)
Block(4,11,-5,quark:iron_plate:1)
Block(4,11,-4,quark:iron_plate:1)
Block(4,11,-3,AIR:0)
Block(4,11,-2,quark:iron_plate:1)
Block(4,11,-1,quark:iron_plate:1)
Block(4,11,0,quark:iron_plate:1)
Block(4,11,1,quark:iron_plate:1)
Block(4,11,2,quark:iron_plate:1)
Block(4,11,3,quark:iron_plate:1)
Block(4,11,4,quark:iron_plate:1)
RandomBlock(4,11,5,IRON_FENCE,7,WOOL:15,50,LEAVES:0,50,AIR,100)
RandomBlock(4,11,6,IRON_FENCE,7,WOOL:15,50,LEAVES:0,50,AIR,100)
RandomBlock(4,11,7,IRON_FENCE,7,WOOL:15,50,LEAVES:0,50,AIR,100)
RandomBlock(4,11,8,IRON_FENCE,7,WOOL:15,50,LEAVES:0,50,AIR,100)
RandomBlock(4,12,-7,IRON_FENCE,7,WOOL:15,50,LEAVES:0,50,AIR,100)
RandomBlock(4,12,-6,IRON_FENCE,7,WOOL:15,50,LEAVES:0,50,AIR,100)
RandomBlock(4,12,-5,IRON_FENCE,7,WOOL:15,50,LEAVES:0,50,AIR,100)
Block(4,12,-4,quark:iron_plate:1)
Block(4,12,-3,quark:iron_plate:1)
Block(4,12,-2,quark:iron_plate:1)
RandomBlock(4,12,-1,IRON_FENCE,7,WOOL:15,50,LEAVES:0,50,AIR,100)
RandomBlock(4,12,0,IRON_FENCE,7,WOOL:15,50,LEAVES:0,50,AIR,100)
RandomBlock(4,12,1,IRON_FENCE,7,WOOL:15,50,LEAVES:0,50,AIR,100)
RandomBlock(4,12,2,IRON_FENCE,7,WOOL:15,50,LEAVES:0,50,AIR,100)
RandomBlock(4,12,3,IRON_FENCE,7,WOOL:15,50,LEAVES:0,50,AIR,100)
RandomBlock(4,12,4,IRON_FENCE,7,WOOL:15,50,LEAVES:0,50,AIR,100)
RandomBlock(4,12,5,IRON_FENCE,7,WOOL:15,50,LEAVES:0,50,AIR,100)
RandomBlock(4,12,6,IRON_FENCE,7,WOOL:15,50,LEAVES:0,50,AIR,100)
RandomBlock(4,12,7,IRON_FENCE,7,WOOL:15,50,LEAVES:0,50,AIR,100)
RandomBlock(4,12,8,IRON_FENCE,7,WOOL:15,50,LEAVES:0,50,AIR,100)
Block(4,13,-7,quark:iron_plate:1)
Block(4,13,-6,quark:iron_plate:1)
Block(4,13,-5,quark:iron_plate:1)
Block(4,13,-4,quark:iron_plate:1)
Block(4,13,-3,quark:iron_plate:1)
Block(4,13,-2,quark:iron_plate:1)
Block(4,13,-1,quark:iron_plate:1)
Block(4,13,0,quark:iron_plate:1)
Block(4,13,1,quark:iron_plate:1)
Block(4,13,2,quark:iron_plate:1)
Block(4,13,4,quark:iron_plate:1)
Block(4,14,-7,quark:iron_plate:1)
Block(4,14,-5,quark:iron_plate:1)
Block(4,14,-3,quark:iron_plate:1)
Block(4,14,-1,quark:iron_plate:1)
Block(4,14,1,quark:iron_plate:1)
RandomBlock(4,15,-7,rustic:iron_lattice,70,rustic:iron_lattice:0,100)
RandomBlock(4,15,1,rustic:iron_lattice,70,rustic:iron_lattice:0,100)
RandomBlock(4,16,-7,rustic:iron_lattice,70,rustic:iron_lattice:0,100)
RandomBlock(4,16,1,rustic:iron_lattice,70,rustic:iron_lattice:0,100)
RandomBlock(5,3,-7,rustic:iron_lattice,70,rustic:iron_lattice:0,100)
RandomBlock(5,3,1,rustic:iron_lattice,70,rustic:iron_lattice:0,100)
RandomBlock(5,4,-7,rustic:iron_lattice,70,rustic:iron_lattice:0,100)
RandomBlock(5,4,1,rustic:iron_lattice,70,rustic:iron_lattice:0,100)
Block(5,5,-7,quark:iron_plate:1)
Block(5,5,-5,quark:iron_plate_stairs:4)
Block(5,5,-3,quark:iron_plate_stairs:4)
Block(5,5,-1,quark:iron_plate_stairs:4)
Block(5,5,1,quark:iron_plate:1)
RandomBlock(5,6,-7,IRON_FENCE,7,WOOL:15,50,LEAVES:0,50,AIR,100)
RandomBlock(5,6,-6,IRON_FENCE,7,WOOL:15,50,LEAVES:0,50,AIR,100)
RandomBlock(5,6,-5,IRON_FENCE,7,WOOL:15,50,LEAVES:0,50,AIR,100)
RandomBlock(5,6,-4,IRON_FENCE,7,WOOL:15,50,LEAVES:0,50,AIR,100)
RandomBlock(5,6,-3,IRON_FENCE,7,WOOL:15,50,LEAVES:0,50,AIR,100)
RandomBlock(5,6,-2,IRON_FENCE,7,WOOL:15,50,LEAVES:0,50,AIR,100)
RandomBlock(5,6,-1,IRON_FENCE,7,WOOL:15,50,LEAVES:0,50,AIR,100)
RandomBlock(5,6,0,IRON_FENCE,7,WOOL:15,50,LEAVES:0,50,AIR,100)
RandomBlock(5,6,1,IRON_FENCE,7,WOOL:15,50,LEAVES:0,50,AIR,100)
RandomBlock(5,6,2,IRON_FENCE,7,WOOL:15,50,LEAVES:0,50,AIR,100)
RandomBlock(5,6,3,IRON_FENCE,7,WOOL:15,50,LEAVES:0,50,AIR,100)
RandomBlock(5,6,4,IRON_FENCE,7,WOOL:15,50,LEAVES:0,50,AIR,100)
RandomBlock(5,6,5,IRON_FENCE,7,WOOL:15,50,LEAVES:0,50,AIR,100)
RandomBlock(5,6,6,IRON_FENCE,7,WOOL:15,50,LEAVES:0,50,AIR,100)
RandomBlock(5,6,7,IRON_FENCE,7,WOOL:15,50,LEAVES:0,50,AIR,100)
RandomBlock(5,6,8,IRON_FENCE,7,WOOL:15,50,LEAVES:0,50,AIR,100)
RandomBlock(5,7,-7,IRON_FENCE,7,WOOL:15,50,LEAVES:0,50,AIR,100)
RandomBlock(5,7,-6,IRON_FENCE,7,WOOL:15,50,LEAVES:0,50,AIR,100)
RandomBlock(5,7,-5,IRON_FENCE,7,WOOL:15,50,LEAVES:0,50,AIR,100)
RandomBlock(5,7,-4,IRON_FENCE,7,WOOL:15,50,LEAVES:0,50,AIR,100)
RandomBlock(5,7,-3,IRON_FENCE,7,WOOL:15,50,LEAVES:0,50,AIR,100)
RandomBlock(5,7,-2,IRON_FENCE,7,WOOL:15,50,LEAVES:0,50,AIR,100)
RandomBlock(5,7,-1,IRON_FENCE,7,WOOL:15,50,LEAVES:0,50,AIR,100)
RandomBlock(5,7,0,IRON_FENCE,7,WOOL:15,50,LEAVES:0,50,AIR,100)
RandomBlock(5,7,1,IRON_FENCE,7,WOOL:15,50,LEAVES:0,50,AIR,100)
RandomBlock(5,7,2,IRON_FENCE,7,WOOL:15,50,LEAVES:0,50,AIR,100)
RandomBlock(5,7,3,IRON_FENCE,7,WOOL:15,50,LEAVES:0,50,AIR,100)
RandomBlock(5,7,4,IRON_FENCE,7,WOOL:15,50,LEAVES:0,50,AIR,100)
RandomBlock(5,7,5,IRON_FENCE,7,WOOL:15,50,LEAVES:0,50,AIR,100)
RandomBlock(5,7,6,IRON_FENCE,7,WOOL:15,50,LEAVES:0,50,AIR,100)
RandomBlock(5,7,7,IRON_FENCE,7,WOOL:15,50,LEAVES:0,50,AIR,100)
RandomBlock(5,7,8,IRON_FENCE,7,WOOL:15,50,LEAVES:0,50,AIR,100)
Block(5,8,-7,quark:iron_plate:1)
Block(5,8,-6,AIR:0)
Block(5,8,-5,AIR:0)
Block(5,8,-4,AIR:0)
Block(5,8,-3,AIR:0)
Block(5,8,-2,AIR:0)
Block(5,8,-1,AIR:0)
Block(5,8,0,AIR:0)
Block(5,8,1,quark:iron_plate:1)
Block(5,8,2,AIR:0)
Block(5,8,3,AIR:0)
Block(5,8,4,AIR:0)
Block(5,8,5,AIR:0)
Block(5,8,6,AIR:0)
Block(5,8,7,AIR:0)
Block(5,8,8,AIR:0)
Block(5,9,-7,quark:iron_plate:1)
Block(5,9,-6,AIR:0)
Block(5,9,-5,AIR:0)
Block(5,9,-4,AIR:0)
Block(5,9,-3,STEP:8)
Block(5,9,-2,AIR:0)
Block(5,9,-1,AIR:0)
Block(5,9,0,AIR:0)
Block(5,9,1,quark:iron_plate:1)
Block(5,9,2,AIR:0)
Block(5,9,3,AIR:0)
Block(5,9,4,AIR:0)
Block(5,9,5,AIR:0)
Block(5,9,6,AIR:0)
Block(5,9,7,AIR:0)
Block(5,9,8,AIR:0)
Block(5,10,-7,IRON_FENCE:0)
Block(5,10,-6,quark:iron_plate:1)
Block(5,10,-5,quark:iron_plate:1)
Block(5,10,-4,DOUBLE_STEP:0)
Block(5,10,-3,AIR:0)
Block(5,10,-2,DOUBLE_STEP:0)
Block(5,10,-1,quark:iron_plate:1)
Block(5,10,0,quark:iron_plate:1)
Block(5,10,1,IRON_FENCE:0)
Block(5,10,2,quark:iron_plate:1)
Block(5,10,3,quark:iron_plate:1)
Block(5,10,4,quark:iron_plate:1)
Block(5,10,5,quark:iron_plate:1)
Block(5,10,6,quark:iron_plate:1)
Block(5,10,7,quark:iron_plate:1)
Block(5,10,8,quark:iron_plate:1)
Block(5,11,-7,quark:iron_plate:1)
Block(5,11,-6,AIR:0)
Block(5,11,-5,AIR:0)
Block(5,11,-4,DOUBLE_STEP:0)
Block(5,11,-3,AIR:0)
Block(5,11,-2,DOUBLE_STEP:0)
Block(5,11,-1,AIR:0)
Block(5,11,0,AIR:0)
Block(5,11,1,quark:iron_plate:1)
Block(5,11,2,AIR:0)
Block(5,11,3,AIR:0)
Block(5,11,4,AIR:0)
Block(5,11,5,AIR:0)
Block(5,11,6,AIR:0)
Block(5,11,7,AIR:0)
Block(5,11,8,AIR:0)
Block(5,12,-7,quark:iron_plate:1)
Block(5,12,-6,AIR:0)
Block(5,12,-5,AIR:0)
Block(5,12,-4,AIR:0)
Block(5,12,-3,STEP:0)
Block(5,12,-2,AIR:0)
Block(5,12,-1,AIR:0)
Block(5,12,0,AIR:0)
Block(5,12,1,quark:iron_plate:1)
Block(5,12,2,AIR:0)
Block(5,12,3,AIR:0)
Block(5,12,4,AIR:0)
Block(5,12,5,AIR:0)
Block(5,12,6,AIR:0)
Block(5,12,7,AIR:0)
Block(5,12,8,AIR:0)
Block(5,13,-7,IRON_FENCE:0)
Block(5,13,-6,AIR:0)
Block(5,13,-5,AIR:0)
Block(5,13,-4,AIR:0)
Block(5,13,-3,AIR:0)
Block(5,13,-2,AIR:0)
Block(5,13,-1,AIR:0)
Block(5,13,0,AIR:0)
Block(5,13,1,IRON_FENCE:0)
RandomBlock(5,13,2,IRON_FENCE,7,WOOL:15,50,LEAVES:0,50,AIR,100)
RandomBlock(5,13,3,IRON_FENCE,7,WOOL:15,50,LEAVES:0,50,AIR,100)
RandomBlock(5,13,4,IRON_FENCE,7,WOOL:15,50,LEAVES:0,50,AIR,100)
RandomBlock(5,13,5,IRON_FENCE,7,WOOL:15,50,LEAVES:0,50,AIR,100)
RandomBlock(5,13,6,IRON_FENCE,7,WOOL:15,50,LEAVES:0,50,AIR,100)
RandomBlock(5,13,7,IRON_FENCE,7,WOOL:15,50,LEAVES:0,50,AIR,100)
RandomBlock(5,13,8,IRON_FENCE,7,WOOL:15,50,LEAVES:0,50,AIR,100)
RandomBlock(5,14,-7,IRON_FENCE,7,WOOL:15,50,LEAVES:0,50,AIR,100)
Block(5,14,-6,quark:iron_plate:1)
Block(5,14,-5,quark:iron_plate:1)
Block(5,14,-4,quark:iron_plate:1)
Block(5,14,-3,quark:iron_plate:1)
Block(5,14,-2,quark:iron_plate:1)
Block(5,14,-1,quark:iron_plate:1)
Block(5,14,0,quark:iron_plate:1)
RandomBlock(5,14,1,IRON_FENCE,7,WOOL:15,50,LEAVES:0,50,AIR,100)
RandomBlock(5,14,2,IRON_FENCE,7,WOOL:15,50,LEAVES:0,50,AIR,100)
RandomBlock(5,14,3,IRON_FENCE,7,WOOL:15,50,LEAVES:0,50,AIR,100)
RandomBlock(5,14,4,IRON_FENCE,7,WOOL:15,50,LEAVES:0,50,AIR,100)
RandomBlock(5,14,5,IRON_FENCE,7,WOOL:15,50,LEAVES:0,50,AIR,100)
RandomBlock(5,14,6,IRON_FENCE,7,WOOL:15,50,LEAVES:0,50,AIR,100)
RandomBlock(5,14,7,IRON_FENCE,7,WOOL:15,50,LEAVES:0,50,AIR,100)
RandomBlock(5,14,8,IRON_FENCE,7,WOOL:15,50,LEAVES:0,50,AIR,100)
Block(5,15,-7,quark:iron_plate:1)
Block(5,15,-5,quark:iron_plate_stairs:0)
Block(5,15,-3,quark:iron_plate_stairs:0)
Block(5,15,-1,quark:iron_plate_stairs:0)
Block(5,15,1,quark:iron_plate:1)
RandomBlock(5,16,-7,rustic:iron_lattice,70,rustic:iron_lattice:0,100)
RandomBlock(5,16,1,rustic:iron_lattice,70,rustic:iron_lattice:0,100)
RandomBlock(5,17,-7,rustic:iron_lattice,70,rustic:iron_lattice:0,100)
RandomBlock(5,17,1,rustic:iron_lattice,70,rustic:iron_lattice:0,100)
RandomBlock(6,2,-7,rustic:iron_lattice,70,rustic:iron_lattice:0,100)
RandomBlock(6,3,-7,rustic:iron_lattice,70,rustic:iron_lattice:0,100)
RandomBlock(6,3,1,rustic:iron_lattice,70,rustic:iron_lattice:0,100)
Block(6,4,-7,quark:iron_plate:1)
Block(6,4,1,quark:iron_plate:1)
Block(6,4,2,quark:iron_plate:1)
Block(6,4,3,quark:iron_plate:1)
Block(6,4,4,quark:iron_plate:1)
Block(6,4,5,quark:iron_plate:1)
Block(6,4,6,quark:iron_plate:1)
Block(6,4,7,quark:iron_plate:1)
Block(6,4,8,quark:iron_plate:1)
RandomBlock(6,5,-7,IRON_FENCE,7,WOOL:15,50,LEAVES:0,50,AIR,100)
RandomBlock(6,5,-6,IRON_FENCE,7,WOOL:15,50,LEAVES:0,50,AIR,100)
RandomBlock(6,5,-5,IRON_FENCE,7,WOOL:15,50,LEAVES:0,50,AIR,100)
RandomBlock(6,5,-4,IRON_FENCE,7,WOOL:15,50,LEAVES:0,50,AIR,100)
RandomBlock(6,5,-3,IRON_FENCE,7,WOOL:15,50,LEAVES:0,50,AIR,100)
RandomBlock(6,5,-2,IRON_FENCE,7,WOOL:15,50,LEAVES:0,50,AIR,100)
RandomBlock(6,5,-1,IRON_FENCE,7,WOOL:15,50,LEAVES:0,50,AIR,100)
RandomBlock(6,5,0,IRON_FENCE,7,WOOL:15,50,LEAVES:0,50,AIR,100)
RandomBlock(6,5,1,IRON_FENCE,7,WOOL:15,50,LEAVES:0,50,AIR,100)
RandomBlock(6,5,2,IRON_FENCE,7,WOOL:15,50,LEAVES:0,50,AIR,100)
RandomBlock(6,5,3,IRON_FENCE,7,WOOL:15,50,LEAVES:0,50,AIR,100)
RandomBlock(6,5,4,IRON_FENCE,7,WOOL:15,50,LEAVES:0,50,AIR,100)
RandomBlock(6,5,5,IRON_FENCE,7,WOOL:15,50,LEAVES:0,50,AIR,100)
RandomBlock(6,5,6,IRON_FENCE,7,WOOL:15,50,LEAVES:0,50,AIR,100)
RandomBlock(6,5,7,IRON_FENCE,7,WOOL:15,50,LEAVES:0,50,AIR,100)
RandomBlock(6,5,8,IRON_FENCE,7,WOOL:15,50,LEAVES:0,50,AIR,100)
Block(6,6,-7,quark:iron_plate:1)
Block(6,6,-6,AIR:0)
Block(6,6,-5,AIR:0)
Block(6,6,-4,AIR:0)
Block(6,6,-3,AIR:0)
Block(6,6,-2,AIR:0)
Block(6,6,-1,AIR:0)
Block(6,6,0,AIR:0)
Block(6,6,1,quark:iron_plate:1)
Block(6,6,2,AIR:0)
Block(6,6,3,AIR:0)
Block(6,6,4,AIR:0)
Block(6,6,5,AIR:0)
Block(6,6,6,AIR:0)
Block(6,6,7,AIR:0)
Block(6,6,8,AIR:0)
Block(6,7,-7,quark:iron_plate:1)
Block(6,7,-6,AIR:0)
Block(6,7,-5,AIR:0)
Block(6,7,-4,AIR:0)
Block(6,7,-3,AIR:0)
Block(6,7,-2,AIR:0)
Block(6,7,-1,AIR:0)
Block(6,7,0,AIR:0)
Block(6,7,1,quark:iron_plate:1)
Block(6,7,2,AIR:0)
Block(6,7,3,AIR:0)
Block(6,7,4,AIR:0)
Block(6,7,5,AIR:0)
Block(6,7,6,AIR:0)
Block(6,7,7,AIR:0)
Block(6,7,8,AIR:0)
Block(6,8,-7,AIR:0)
Block(6,8,-6,AIR:0)
Block(6,8,-5,AIR:0)
Block(6,8,-4,AIR:0)
Block(6,8,-3,AIR:0)
Block(6,8,-2,AIR:0)
Block(6,8,-1,AIR:0)
Block(6,8,0,AIR:0)
Block(6,8,1,AIR:0)
Block(6,8,2,AIR:0)
Block(6,8,3,AIR:0)
Block(6,8,4,AIR:0)
Block(6,8,5,AIR:0)
Block(6,8,6,AIR:0)
Block(6,8,7,AIR:0)
Block(6,8,8,AIR:0)
Block(6,9,-7,AIR:0)
Block(6,9,-6,AIR:0)
Block(6,9,-5,AIR:0)
Block(6,9,-4,AIR:0)
Block(6,9,-3,STEP:8)
Block(6,9,-2,AIR:0)
Block(6,9,-1,AIR:0)
Block(6,9,0,AIR:0)
Block(6,9,1,AIR:0)
Block(6,9,2,AIR:0)
Block(6,9,3,AIR:0)
Block(6,9,4,AIR:0)
Block(6,9,5,AIR:0)
Block(6,9,6,AIR:0)
Block(6,9,7,AIR:0)
Block(6,9,8,AIR:0)
Block(6,10,-7,AIR:0)
Block(6,10,-6,AIR:0)
Block(6,10,-5,AIR:0)
Block(6,10,-4,DOUBLE_STEP:0)
Block(6,10,-3,AIR:0)
Block(6,10,-2,DOUBLE_STEP:0)
Block(6,10,-1,AIR:0)
Block(6,10,0,AIR:0)
Block(6,10,1,AIR:0)
Block(6,10,2,AIR:0)
Block(6,10,3,AIR:0)
Block(6,10,4,AIR:0)
Block(6,10,5,AIR:0)
Block(6,10,6,AIR:0)
Block(6,10,7,AIR:0)
Block(6,10,8,AIR:0)
Block(6,11,-7,AIR:0)
Block(6,11,-6,AIR:0)
Block(6,11,-5,AIR:0)
Block(6,11,-4,DOUBLE_STEP:0)
Block(6,11,-3,AIR:0)
Block(6,11,-2,DOUBLE_STEP:0)
Block(6,11,-1,AIR:0)
Block(6,11,0,AIR:0)
Block(6,11,1,AIR:0)
Block(6,11,2,AIR:0)
Block(6,11,3,AIR:0)
Block(6,11,4,AIR:0)
Block(6,11,5,AIR:0)
Block(6,11,6,AIR:0)
Block(6,11,7,AIR:0)
Block(6,11,8,AIR:0)
Block(6,12,-7,AIR:0)
Block(6,12,-6,AIR:0)
Block(6,12,-5,AIR:0)
Block(6,12,-4,AIR:0)
Block(6,12,-3,STEP:0)
Block(6,12,-2,AIR:0)
Block(6,12,-1,AIR:0)
Block(6,12,0,AIR:0)
Block(6,12,1,AIR:0)
Block(6,12,2,AIR:0)
Block(6,12,3,AIR:0)
Block(6,12,4,AIR:0)
Block(6,12,5,AIR:0)
Block(6,12,6,AIR:0)
Block(6,12,7,AIR:0)
Block(6,12,8,AIR:0)
Block(6,13,-7,quark:iron_plate:1)
Block(6,13,-6,AIR:0)
Block(6,13,-5,AIR:0)
Block(6,13,-4,AIR:0)
Block(6,13,-3,AIR:0)
Block(6,13,-2,AIR:0)
Block(6,13,-1,AIR:0)
Block(6,13,0,AIR:0)
Block(6,13,1,quark:iron_plate:1)
Block(6,13,2,AIR:0)
Block(6,13,3,AIR:0)
Block(6,13,4,AIR:0)
Block(6,13,5,AIR:0)
Block(6,13,6,AIR:0)
Block(6,13,7,AIR:0)
Block(6,13,8,AIR:0)
Block(6,14,-7,quark:iron_plate:1)
Block(6,14,-6,AIR:0)
Block(6,14,-5,AIR:0)
Block(6,14,-4,AIR:0)
Block(6,14,-3,AIR:0)
Block(6,14,-2,AIR:0)
Block(6,14,-1,AIR:0)
Block(6,14,0,AIR:0)
Block(6,14,1,quark:iron_plate:1)
Block(6,14,2,AIR:0)
Block(6,14,3,AIR:0)
Block(6,14,4,AIR:0)
Block(6,14,5,AIR:0)
Block(6,14,6,AIR:0)
Block(6,14,7,AIR:0)
Block(6,14,8,AIR:0)
RandomBlock(6,15,-7,IRON_FENCE,7,WOOL:15,50,LEAVES:0,50,AIR,100)
RandomBlock(6,15,-6,IRON_FENCE,7,WOOL:15,50,LEAVES:0,50,AIR,100)
RandomBlock(6,15,-5,IRON_FENCE,7,WOOL:15,50,LEAVES:0,50,AIR,100)
RandomBlock(6,15,-4,IRON_FENCE,7,WOOL:15,50,LEAVES:0,50,AIR,100)
RandomBlock(6,15,-3,IRON_FENCE,7,WOOL:15,50,LEAVES:0,50,AIR,100)
RandomBlock(6,15,-2,IRON_FENCE,7,WOOL:15,50,LEAVES:0,50,AIR,100)
RandomBlock(6,15,-1,IRON_FENCE,7,WOOL:15,50,LEAVES:0,50,AIR,100)
RandomBlock(6,15,0,IRON_FENCE,7,WOOL:15,50,LEAVES:0,50,AIR,100)
RandomBlock(6,15,1,IRON_FENCE,7,WOOL:15,50,LEAVES:0,50,AIR,100)
RandomBlock(6,15,2,IRON_FENCE,7,WOOL:15,50,LEAVES:0,50,AIR,100)
RandomBlock(6,15,3,IRON_FENCE,7,WOOL:15,50,LEAVES:0,50,AIR,100)
RandomBlock(6,15,4,IRON_FENCE,7,WOOL:15,50,LEAVES:0,50,AIR,100)
RandomBlock(6,15,5,IRON_FENCE,7,WOOL:15,50,LEAVES:0,50,AIR,100)
RandomBlock(6,15,6,IRON_FENCE,7,WOOL:15,50,LEAVES:0,50,AIR,100)
RandomBlock(6,15,7,IRON_FENCE,7,WOOL:15,50,LEAVES:0,50,AIR,100)
RandomBlock(6,15,8,IRON_FENCE,7,WOOL:15,50,LEAVES:0,50,AIR,100)
Block(6,16,-7,quark:iron_plate:1)
Block(6,16,1,quark:iron_plate:1)
RandomBlock(6,17,-7,rustic:iron_lattice,70,rustic:iron_lattice:0,100)
RandomBlock(6,17,1,rustic:iron_lattice,70,rustic:iron_lattice:0,100)
RandomBlock(6,18,-7,rustic:iron_lattice,70,rustic:iron_lattice:0,100)
RandomBlock(6,18,1,rustic:iron_lattice,70,rustic:iron_lattice:0,100)
RandomBlock(7,1,1,rustic:iron_lattice,70,rustic:iron_lattice:0,100)
RandomBlock(7,2,-7,rustic:iron_lattice,70,rustic:iron_lattice:0,100)
RandomBlock(7,2,1,rustic:iron_lattice,70,rustic:iron_lattice:0,100)
Block(7,3,-7,quark:iron_plate:1)
Block(7,3,1,quark:iron_plate:1)
Block(7,3,2,quark:iron_plate:1)
Block(7,3,3,quark:iron_plate:1)
Block(7,3,4,quark:iron_plate:1)
Block(7,3,5,quark:iron_plate:1)
Block(7,3,6,quark:iron_plate:1)
Block(7,3,7,quark:iron_plate:1)
Block(7,3,8,quark:iron_plate:1)
RandomBlock(7,4,-7,IRON_FENCE,7,WOOL:15,50,LEAVES:0,50,AIR,100)
RandomBlock(7,4,-6,IRON_FENCE,7,WOOL:15,50,LEAVES:0,50,AIR,100)
RandomBlock(7,4,-5,IRON_FENCE,7,WOOL:15,50,LEAVES:0,50,AIR,100)
RandomBlock(7,4,-4,IRON_FENCE,7,WOOL:15,50,LEAVES:0,50,AIR,100)
RandomBlock(7,4,-3,IRON_FENCE,7,WOOL:15,50,LEAVES:0,50,AIR,100)
RandomBlock(7,4,-2,IRON_FENCE,7,WOOL:15,50,LEAVES:0,50,AIR,100)
RandomBlock(7,4,-1,IRON_FENCE,7,WOOL:15,50,LEAVES:0,50,AIR,100)
RandomBlock(7,4,0,IRON_FENCE,7,WOOL:15,50,LEAVES:0,50,AIR,100)
Block(7,4,1,quark:iron_plate:1)
Block(7,4,2,quark:iron_plate:1)
Block(7,4,3,quark:iron_plate:1)
Block(7,4,4,quark:iron_plate:1)
Block(7,4,5,quark:iron_plate:1)
Block(7,4,6,quark:iron_plate:1)
Block(7,4,7,quark:iron_plate:1)
Block(7,4,8,quark:iron_plate:1)
Block(7,5,-7,quark:iron_plate:1)
Block(7,5,-6,quark:iron_plate:1)
Block(7,5,-5,quark:iron_plate:1)
Block(7,5,-4,quark:iron_plate:1)
Block(7,5,-3,quark:iron_plate:1)
Block(7,5,-2,quark:iron_plate:1)
Block(7,5,-1,quark:iron_plate:1)
Block(7,5,0,quark:iron_plate:1)
Block(7,5,1,quark:iron_plate:1)
Block(7,5,2,quark:iron_plate:1)
Block(7,5,3,quark:iron_plate:1)
Block(7,5,4,quark:iron_plate:1)
Block(7,5,5,quark:iron_plate:1)
Block(7,5,6,quark:iron_plate:1)
Block(7,5,7,quark:iron_plate:1)
Block(7,5,8,quark:iron_plate:1)
Block(7,6,-7,AIR:0)
Block(7,6,-6,AIR:0)
Block(7,6,-5,AIR:0)
Block(7,6,-4,AIR:0)
Block(7,6,-3,AIR:0)
Block(7,6,-2,AIR:0)
Block(7,6,-1,AIR:0)
Block(7,6,0,AIR:0)
Block(7,6,1,AIR:0)
Block(7,6,2,quark:iron_plate:1)
Block(7,6,3,quark:iron_plate:1)
Block(7,6,4,quark:iron_plate:1)
Block(7,6,5,quark:iron_plate:1)
Block(7,6,6,quark:iron_plate:1)
Block(7,6,7,quark:iron_plate:1)
Block(7,6,8,quark:iron_plate:1)
Block(7,7,-7,AIR:0)
Block(7,7,-6,AIR:0)
Block(7,7,-5,AIR:0)
Block(7,7,-4,AIR:0)
Block(7,7,-3,AIR:0)
Block(7,7,-2,AIR:0)
Block(7,7,-1,AIR:0)
Block(7,7,0,AIR:0)
Block(7,7,1,AIR:0)
Block(7,7,2,AIR:0)
Block(7,7,3,AIR:0)
Block(7,7,4,AIR:0)
Block(7,7,5,AIR:0)
Block(7,7,6,AIR:0)
Block(7,7,7,AIR:0)
Block(7,7,8,AIR:0)
Block(7,8,-7,AIR:0)
Block(7,8,-6,AIR:0)
Block(7,8,-5,AIR:0)
Block(7,8,-4,AIR:0)
Block(7,8,-3,AIR:0)
Block(7,8,-2,AIR:0)
Block(7,8,-1,AIR:0)
Block(7,8,0,AIR:0)
Block(7,8,1,AIR:0)
Block(7,8,2,AIR:0)
Block(7,8,3,AIR:0)
Block(7,8,4,AIR:0)
Block(7,8,5,AIR:0)
Block(7,8,6,AIR:0)
Block(7,8,7,AIR:0)
Block(7,8,8,AIR:0)
Block(7,9,-7,AIR:0)
Block(7,9,-6,AIR:0)
Block(7,9,-5,AIR:0)
Block(7,9,-4,AIR:0)
Block(7,9,-3,STEP:8)
Block(7,9,-2,AIR:0)
Block(7,9,-1,AIR:0)
Block(7,9,0,AIR:0)
Block(7,9,1,AIR:0)
Block(7,9,2,AIR:0)
Block(7,9,3,AIR:0)
Block(7,9,4,AIR:0)
Block(7,9,5,AIR:0)
Block(7,9,6,AIR:0)
Block(7,9,7,AIR:0)
Block(7,9,8,AIR:0)
Block(7,10,-7,AIR:0)
Block(7,10,-6,AIR:0)
Block(7,10,-5,AIR:0)
Block(7,10,-4,DOUBLE_STEP:0)
Block(7,10,-3,AIR:0)
Block(7,10,-2,DOUBLE_STEP:0)
Block(7,10,-1,AIR:0)
Block(7,10,0,AIR:0)
Block(7,10,1,AIR:0)
Block(7,10,2,AIR:0)
Block(7,10,3,AIR:0)
Block(7,10,4,AIR:0)
Block(7,10,5,AIR:0)
Block(7,10,6,AIR:0)
Block(7,10,7,AIR:0)
Block(7,10,8,AIR:0)
Block(7,11,-7,AIR:0)
Block(7,11,-6,AIR:0)
Block(7,11,-5,AIR:0)
Block(7,11,-4,DOUBLE_STEP:0)
Block(7,11,-3,AIR:0)
Block(7,11,-2,DOUBLE_STEP:0)
Block(7,11,-1,AIR:0)
Block(7,11,0,AIR:0)
Block(7,11,1,AIR:0)
Block(7,11,2,AIR:0)
Block(7,11,3,AIR:0)
Block(7,11,4,AIR:0)
Block(7,11,5,AIR:0)
Block(7,11,6,AIR:0)
Block(7,11,7,AIR:0)
Block(7,11,8,AIR:0)
Block(7,12,-7,AIR:0)
Block(7,12,-6,AIR:0)
Block(7,12,-5,AIR:0)
Block(7,12,-4,AIR:0)
Block(7,12,-3,STEP:0)
Block(7,12,-2,AIR:0)
Block(7,12,-1,AIR:0)
Block(7,12,0,AIR:0)
Block(7,12,1,AIR:0)
Block(7,12,2,AIR:0)
Block(7,12,3,AIR:0)
Block(7,12,4,AIR:0)
Block(7,12,5,AIR:0)
Block(7,12,6,AIR:0)
Block(7,12,7,AIR:0)
Block(7,12,8,AIR:0)
Block(7,13,-7,AIR:0)
Block(7,13,-6,AIR:0)
Block(7,13,-5,AIR:0)
Block(7,13,-4,AIR:0)
Block(7,13,-3,AIR:0)
Block(7,13,-2,AIR:0)
Block(7,13,-1,AIR:0)
Block(7,13,0,AIR:0)
Block(7,13,1,AIR:0)
Block(7,13,2,AIR:0)
Block(7,13,3,AIR:0)
Block(7,13,4,AIR:0)
Block(7,13,5,AIR:0)
Block(7,13,6,AIR:0)
Block(7,13,7,AIR:0)
Block(7,13,8,AIR:0)
Block(7,14,-7,AIR:0)
Block(7,14,-6,AIR:0)
Block(7,14,-5,AIR:0)
Block(7,14,-4,AIR:0)
Block(7,14,-3,AIR:0)
Block(7,14,-2,AIR:0)
Block(7,14,-1,AIR:0)
Block(7,14,0,AIR:0)
Block(7,14,1,AIR:0)
Block(7,14,2,AIR:0)
Block(7,14,3,AIR:0)
Block(7,14,4,AIR:0)
Block(7,14,5,AIR:0)
Block(7,14,6,AIR:0)
Block(7,14,7,AIR:0)
Block(7,14,8,AIR:0)
Block(7,15,-7,quark:iron_plate:1)
Block(7,15,-6,AIR:0)
Block(7,15,-5,AIR:0)
Block(7,15,-4,AIR:0)
Block(7,15,-3,AIR:0)
Block(7,15,-2,AIR:0)
Block(7,15,-1,AIR:0)
Block(7,15,0,AIR:0)
Block(7,15,1,quark:iron_plate:1)
Block(7,15,2,AIR:0)
Block(7,15,3,AIR:0)
Block(7,15,4,AIR:0)
Block(7,15,5,AIR:0)
Block(7,15,6,AIR:0)
Block(7,15,7,AIR:0)
Block(7,15,8,AIR:0)
RandomBlock(7,16,-7,IRON_FENCE,7,WOOL:15,50,LEAVES:0,50,AIR,100)
RandomBlock(7,16,-6,IRON_FENCE,7,WOOL:15,50,LEAVES:0,50,AIR,100)
RandomBlock(7,16,-5,IRON_FENCE,7,WOOL:15,50,LEAVES:0,50,AIR,100)
RandomBlock(7,16,-4,IRON_FENCE,7,WOOL:15,50,LEAVES:0,50,AIR,100)
RandomBlock(7,16,-3,IRON_FENCE,7,WOOL:15,50,LEAVES:0,50,AIR,100)
RandomBlock(7,16,-2,IRON_FENCE,7,WOOL:15,50,LEAVES:0,50,AIR,100)
RandomBlock(7,16,-1,IRON_FENCE,7,WOOL:15,50,LEAVES:0,50,AIR,100)
RandomBlock(7,16,0,IRON_FENCE,7,WOOL:15,50,LEAVES:0,50,AIR,100)
RandomBlock(7,16,1,IRON_FENCE,7,WOOL:15,50,LEAVES:0,50,AIR,100)
RandomBlock(7,16,2,IRON_FENCE,7,WOOL:15,50,LEAVES:0,50,AIR,100)
RandomBlock(7,16,3,IRON_FENCE,7,WOOL:15,50,LEAVES:0,50,AIR,100)
RandomBlock(7,16,4,IRON_FENCE,7,WOOL:15,50,LEAVES:0,50,AIR,100)
RandomBlock(7,16,5,IRON_FENCE,7,WOOL:15,50,LEAVES:0,50,AIR,100)
RandomBlock(7,16,6,IRON_FENCE,7,WOOL:15,50,LEAVES:0,50,AIR,100)
RandomBlock(7,16,7,IRON_FENCE,7,WOOL:15,50,LEAVES:0,50,AIR,100)
RandomBlock(7,16,8,IRON_FENCE,7,WOOL:15,50,LEAVES:0,50,AIR,100)
Block(7,17,-7,quark:iron_plate:1)
Block(7,17,1,quark:iron_plate:1)
RandomBlock(7,18,-7,rustic:iron_lattice,70,rustic:iron_lattice:0,100)
RandomBlock(7,18,1,rustic:iron_lattice,70,rustic:iron_lattice:0,100)

#######################################################################
# +-----------------------------------------------------------------+ #
# |                             Branches                            | #
# +-----------------------------------------------------------------+ #
#######################################################################

Branch(0,0,-16,true,ZeppelinC3R1,NORTH,100.0,0)

#######################################################################
# +-----------------------------------------------------------------+ #
# |                             Entities                            | #
# +-----------------------------------------------------------------+ #
#######################################################################


#######################################################################
# +-----------------------------------------------------------------+ #
# |                            Particles                            | #
# +-----------------------------------------------------------------+ #
#######################################################################


#######################################################################
# +-----------------------------------------------------------------+ #
# |                             Spawners                            | #
# +-----------------------------------------------------------------+ #
#######################################################################


#######################################################################
# +-----------------------------------------------------------------+ #
# |                             ModData                             | #
# +-----------------------------------------------------------------+ #
#######################################################################

