
#######################################################################
# +-----------------------------------------------------------------+ #
# |                            BO3 object                           | #
# +-----------------------------------------------------------------+ #
#######################################################################

Author: NLBlackHeavenNL

Description: No description given

Version: 3

SettingsMode: WriteWithoutComments


#######################################################################
# +-----------------------------------------------------------------+ #
# |                          Main settings                          | #
# +-----------------------------------------------------------------+ #
#######################################################################

Tree: true

Frequency: 1

Rarity: 100.0

RotateRandomly: false

SpawnHeight: highestSolidBlock

SpawnHeightOffset: -1

SpawnHeightVariance: 0

##############################
# Height Limits for the BO3. #
##############################

MinHeight: 0

MaxHeight: 255

######################
# Extrusion settings #
######################

ExtrudeMode: None

ExtrudeThroughBlocks: AIR

MaxBranchDepth: 10

ExcludedBiomes: All


#######################################################################
# +-----------------------------------------------------------------+ #
# |                      Source block settings                      | #
# +-----------------------------------------------------------------+ #
#######################################################################

SourceBlocks: AIR,GRASS,DIRT,biomesoplenty:dirt

MaxPercentageOutsideSourceBlock: 0

OutsideSourceBlock: placeAnyway

DoReplaceBlocks: true

IsOTGPlus: false


#######################################################################
# +-----------------------------------------------------------------+ #
# |                              Blocks                             | #
# +-----------------------------------------------------------------+ #
#######################################################################

Block(-7,3,1,dynamictrees:leaves0:4)
Block(-6,3,0,dynamictrees:leaves0:4)
Block(-6,3,1,dynamictrees:leaves0:5)
Block(-6,3,2,dynamictrees:leaves0:4)
Block(-6,4,1,dynamictrees:leaves0:4)
Block(-6,5,1,dynamictrees:leaves0:4)
Block(-5,3,-1,dynamictrees:leaves0:4)
Block(-5,3,0,dynamictrees:leaves0:5)
Block(-5,3,1,dynamictrees:sprucebranch)
Block(-5,3,2,dynamictrees:leaves0:5)
Block(-5,3,3,dynamictrees:leaves0:4)
Block(-5,4,0,dynamictrees:leaves0:4)
Block(-5,4,1,dynamictrees:leaves0:4)
Block(-5,4,2,dynamictrees:leaves0:4)
Block(-5,5,0,dynamictrees:leaves0:4)
Block(-5,5,1,dynamictrees:leaves0:5)
Block(-5,5,2,dynamictrees:leaves0:4)
Block(-5,6,1,dynamictrees:leaves0:4)
Block(-5,7,1,dynamictrees:leaves0:4)
Block(-5,9,1,dynamictrees:leaves0:4)
Block(-5,11,1,dynamictrees:leaves0:4)
Block(-4,3,-2,dynamictrees:leaves0:4)
Block(-4,3,-1,dynamictrees:leaves0:5)
Block(-4,3,0,dynamictrees:sprucebranch)
Block(-4,3,1,dynamictrees:sprucebranch:1)
Block(-4,3,2,dynamictrees:leaves0:4)
Block(-4,3,3,dynamictrees:leaves0:5)
Block(-4,3,4,dynamictrees:leaves0:4)
Block(-4,4,-1,dynamictrees:leaves0:4)
Block(-4,4,0,dynamictrees:leaves0:4)
Block(-4,4,3,dynamictrees:leaves0:4)
Block(-4,5,-1,dynamictrees:leaves0:4)
Block(-4,5,0,dynamictrees:leaves0:5)
Block(-4,5,1,dynamictrees:sprucebranch)
Block(-4,5,2,dynamictrees:leaves0:5)
Block(-4,5,3,dynamictrees:leaves0:4)
Block(-4,6,0,dynamictrees:leaves0:4)
Block(-4,6,1,dynamictrees:leaves0:4)
Block(-4,6,2,dynamictrees:leaves0:4)
Block(-4,7,0,dynamictrees:leaves0:4)
Block(-4,7,1,dynamictrees:leaves0:5)
Block(-4,7,2,dynamictrees:leaves0:4)
Block(-4,8,1,dynamictrees:leaves0:4)
Block(-4,9,0,dynamictrees:leaves0:4)
Block(-4,9,1,dynamictrees:leaves0:5)
Block(-4,9,2,dynamictrees:leaves0:4)
Block(-4,10,1,dynamictrees:leaves0:4)
Block(-4,11,0,dynamictrees:leaves0:4)
Block(-4,11,1,dynamictrees:leaves0:5)
Block(-4,11,2,dynamictrees:leaves0:4)
Block(-4,12,1,dynamictrees:leaves0:4)
Block(-3,3,-3,dynamictrees:leaves0:4)
Block(-3,3,1,dynamictrees:sprucebranch:2)
Block(-3,3,2,dynamictrees:sprucebranch:1)
Block(-3,3,3,dynamictrees:sprucebranch)
Block(-3,3,4,dynamictrees:leaves0:5)
Block(-3,3,5,dynamictrees:leaves0:4)
Block(-3,4,3,dynamictrees:leaves0:4)
Block(-3,4,4,dynamictrees:leaves0:4)
Block(-3,5,-2,dynamictrees:leaves0:4)
Block(-3,5,-1,dynamictrees:leaves0:5)
Block(-3,5,0,dynamictrees:sprucebranch)
Block(-3,5,1,dynamictrees:sprucebranch:1)
Block(-3,5,3,dynamictrees:leaves0:4)
Block(-3,5,4,dynamictrees:leaves0:4)
Block(-3,6,-1,dynamictrees:leaves0:4)
Block(-3,6,0,dynamictrees:leaves0:4)
Block(-3,7,-1,dynamictrees:leaves0:4)
Block(-3,7,0,dynamictrees:leaves0:5)
Block(-3,7,1,dynamictrees:sprucebranch)
Block(-3,8,0,dynamictrees:leaves0:4)
Block(-3,8,1,dynamictrees:leaves0:4)
Block(-3,9,-1,dynamictrees:leaves0:4)
Block(-3,9,0,dynamictrees:leaves0:5)
Block(-3,9,1,dynamictrees:sprucebranch)
Block(-3,10,0,dynamictrees:leaves0:4)
Block(-3,10,1,dynamictrees:leaves0:4)
Block(-3,11,-1,dynamictrees:leaves0:4)
Block(-3,11,0,dynamictrees:leaves0:5)
Block(-3,11,1,dynamictrees:sprucebranch)
Block(-3,11,2,dynamictrees:leaves0:5)
Block(-3,11,3,dynamictrees:leaves0:4)
Block(-3,12,0,dynamictrees:leaves0:4)
Block(-3,12,1,dynamictrees:leaves0:4)
Block(-3,12,2,dynamictrees:leaves0:4)
Block(-3,17,1,dynamictrees:leaves0:4)
Block(-2,3,-4,dynamictrees:leaves0:4)
Block(-2,3,-3,dynamictrees:leaves0:5)
Block(-2,3,-2,dynamictrees:leaves0:4)
Block(-2,3,0,dynamictrees:sprucebranch)
Block(-2,3,1,dynamictrees:sprucebranch:2)
Block(-2,3,4,dynamictrees:leaves0:4)
Block(-2,4,-3,dynamictrees:leaves0:4)
Block(-2,5,-3,dynamictrees:leaves0:4)
Block(-2,5,-2,dynamictrees:leaves0:5)
Block(-2,5,-1,dynamictrees:sprucebranch)
Block(-2,5,1,dynamictrees:sprucebranch:1)
Block(-2,5,2,dynamictrees:sprucebranch)
Block(-2,5,3,dynamictrees:leaves0:5)
Block(-2,5,4,dynamictrees:leaves0:5)
Block(-2,5,5,dynamictrees:leaves0:4)
Block(-2,6,-2,dynamictrees:leaves0:4)
Block(-2,6,-1,dynamictrees:leaves0:4)
Block(-2,6,2,dynamictrees:leaves0:4)
Block(-2,6,3,dynamictrees:leaves0:4)
Block(-2,6,4,dynamictrees:leaves0:4)
Block(-2,7,-2,dynamictrees:leaves0:4)
Block(-2,7,-1,dynamictrees:leaves0:5)
Block(-2,7,0,dynamictrees:sprucebranch)
Block(-2,7,1,dynamictrees:sprucebranch:1)
Block(-2,7,4,dynamictrees:leaves0:4)
Block(-2,8,-1,dynamictrees:leaves0:4)
Block(-2,9,-2,dynamictrees:leaves0:4)
Block(-2,9,-1,dynamictrees:leaves0:5)
Block(-2,9,0,dynamictrees:sprucebranch)
Block(-2,9,1,dynamictrees:sprucebranch:1)
Block(-2,9,2,dynamictrees:sprucebranch)
Block(-2,9,4,dynamictrees:leaves0:4)
Block(-2,10,-1,dynamictrees:leaves0:4)
Block(-2,10,0,dynamictrees:leaves0:4)
Block(-2,10,2,dynamictrees:leaves0:4)
Block(-2,11,-1,dynamictrees:leaves0:4)
Block(-2,11,0,dynamictrees:leaves0:5)
Block(-2,11,1,dynamictrees:sprucebranch:1)
Block(-2,11,2,dynamictrees:sprucebranch)
Block(-2,11,3,dynamictrees:leaves0:5)
Block(-2,11,4,dynamictrees:leaves0:4)
Block(-2,12,0,dynamictrees:leaves0:4)
Block(-2,12,2,dynamictrees:leaves0:4)
Block(-2,12,3,dynamictrees:leaves0:4)
Block(-2,13,0,dynamictrees:leaves0:4)
Block(-2,13,2,dynamictrees:leaves0:4)
Block(-2,13,3,dynamictrees:leaves0:4)
Block(-2,15,0,dynamictrees:leaves0:4)
Block(-2,17,0,dynamictrees:leaves0:4)
Block(-2,17,1,dynamictrees:leaves0:5)
Block(-2,17,2,dynamictrees:leaves0:4)
Block(-2,18,1,dynamictrees:leaves0:4)
Block(-2,19,2,dynamictrees:leaves0:4)
Block(-2,22,1,dynamictrees:leaves0:4)
Block(-1,0,0,GRASS:0)
Block(-1,0,1,GRASS:0)
Block(-1,0,2,GRASS:0)
Block(-1,1,0,dynamictrees:trunkshell:5)
Block(-1,1,1,dynamictrees:trunkshell:6)
Block(-1,1,2,dynamictrees:trunkshell:7)
Block(-1,2,0,dynamictrees:trunkshell:5)
Block(-1,2,1,dynamictrees:trunkshell:6)
Block(-1,2,2,dynamictrees:trunkshell:7)
Block(-1,3,-5,dynamictrees:leaves0:4)
Block(-1,3,-4,dynamictrees:leaves0:5)
Block(-1,3,-3,dynamictrees:sprucebranch)
Block(-1,3,-1,dynamictrees:sprucebranch)
Block(-1,3,0,dynamictrees:trunkshell:5)
Block(-1,3,1,dynamictrees:sprucebranch:3)
Block(-1,3,2,dynamictrees:sprucebranch:1)
Block(-1,3,3,dynamictrees:sprucebranch)
Block(-1,3,5,dynamictrees:leaves0:4)
Block(-1,4,-4,dynamictrees:leaves0:4)
Block(-1,4,-3,dynamictrees:leaves0:4)
Block(-1,4,0,dynamictrees:trunkshell:5)
Block(-1,4,1,dynamictrees:trunkshell:6)
Block(-1,4,2,dynamictrees:trunkshell:7)
Block(-1,5,-4,dynamictrees:leaves0:4)
Block(-1,5,-3,dynamictrees:leaves0:5)
Block(-1,5,-2,dynamictrees:leaves0:4)
Block(-1,5,-1,dynamictrees:sprucebranch:1)
Block(-1,5,0,dynamictrees:trunkshell:5)
Block(-1,5,1,dynamictrees:sprucebranch:2)
Block(-1,5,2,dynamictrees:trunkshell:7)
Block(-1,5,3,dynamictrees:sprucebranch:1)
Block(-1,5,4,dynamictrees:sprucebranch)
Block(-1,5,5,dynamictrees:leaves0:5)
Block(-1,5,6,dynamictrees:leaves0:4)
Block(-1,6,-3,dynamictrees:leaves0:4)
Block(-1,6,0,dynamictrees:trunkshell:5)
Block(-1,6,1,dynamictrees:trunkshell:6)
Block(-1,6,2,dynamictrees:trunkshell:7)
Block(-1,6,4,dynamictrees:leaves0:4)
Block(-1,6,5,dynamictrees:leaves0:4)
Block(-1,7,-3,dynamictrees:leaves0:4)
Block(-1,7,-2,dynamictrees:leaves0:5)
Block(-1,7,-1,dynamictrees:sprucebranch)
Block(-1,7,0,dynamictrees:trunkshell:5)
Block(-1,7,1,dynamictrees:sprucebranch:1)
Block(-1,7,2,dynamictrees:trunkshell:7)
Block(-1,7,4,dynamictrees:leaves0:5)
Block(-1,7,5,dynamictrees:leaves0:4)
Block(-1,8,-2,dynamictrees:leaves0:4)
Block(-1,8,0,dynamictrees:trunkshell:5)
Block(-1,8,1,dynamictrees:trunkshell:6)
Block(-1,8,2,dynamictrees:trunkshell:7)
Block(-1,8,4,dynamictrees:leaves0:4)
Block(-1,9,-3,dynamictrees:leaves0:4)
Block(-1,9,-2,dynamictrees:leaves0:5)
Block(-1,9,-1,dynamictrees:sprucebranch)
Block(-1,9,0,dynamictrees:trunkshell:5)
Block(-1,9,1,dynamictrees:sprucebranch:1)
Block(-1,9,2,dynamictrees:leaves0:5)
Block(-1,9,3,dynamictrees:sprucebranch)
Block(-1,9,4,dynamictrees:leaves0:5)
Block(-1,9,5,dynamictrees:leaves0:4)
Block(-1,10,-2,dynamictrees:leaves0:4)
Block(-1,10,-1,dynamictrees:leaves0:4)
Block(-1,10,2,dynamictrees:leaves0:4)
Block(-1,10,3,dynamictrees:leaves0:4)
Block(-1,10,4,dynamictrees:leaves0:4)
Block(-1,11,-2,dynamictrees:leaves0:4)
Block(-1,11,-1,dynamictrees:leaves0:5)
Block(-1,11,0,dynamictrees:sprucebranch)
Block(-1,11,1,dynamictrees:sprucebranch:1)
Block(-1,11,3,dynamictrees:leaves0:4)
Block(-1,12,-1,dynamictrees:leaves0:4)
Block(-1,12,0,dynamictrees:leaves0:4)
Block(-1,13,-1,dynamictrees:leaves0:4)
Block(-1,13,0,dynamictrees:leaves0:5)
Block(-1,13,1,dynamictrees:sprucebranch)
Block(-1,13,2,dynamictrees:leaves0:5)
Block(-1,13,3,dynamictrees:leaves0:5)
Block(-1,13,4,dynamictrees:leaves0:4)
Block(-1,14,0,dynamictrees:leaves0:4)
Block(-1,14,1,dynamictrees:leaves0:4)
Block(-1,14,2,dynamictrees:leaves0:4)
Block(-1,14,3,dynamictrees:leaves0:4)
Block(-1,15,-1,dynamictrees:leaves0:4)
Block(-1,15,0,dynamictrees:leaves0:5)
Block(-1,15,1,dynamictrees:sprucebranch)
Block(-1,16,0,dynamictrees:leaves0:4)
Block(-1,16,1,dynamictrees:leaves0:4)
Block(-1,17,-1,dynamictrees:leaves0:4)
Block(-1,17,0,dynamictrees:leaves0:5)
Block(-1,17,1,dynamictrees:sprucebranch)
Block(-1,18,0,dynamictrees:leaves0:4)
Block(-1,18,1,dynamictrees:leaves0:4)
Block(-1,19,1,dynamictrees:leaves0:4)
Block(-1,19,2,dynamictrees:leaves0:5)
Block(-1,19,3,dynamictrees:leaves0:4)
Block(-1,20,2,dynamictrees:leaves0:4)
Block(-1,22,0,dynamictrees:leaves0:4)
Block(-1,22,1,dynamictrees:leaves0:5)
Block(-1,22,2,dynamictrees:leaves0:4)
Block(-1,23,1,dynamictrees:leaves0:4)
Block(0,0,0,GRASS:0)
Block(0,0,1,dynamictrees:rootydirtspecies:14,DT_Spruce_Huge_13/1-species_tile_entity.nbt)
Block(0,0,2,GRASS:0)
Block(0,1,0,dynamictrees:trunkshell)
Block(0,1,1,dynamictrees:sprucebranch:14)
Block(0,1,2,dynamictrees:trunkshell:0)
Block(0,2,0,dynamictrees:trunkshell)
Block(0,2,1,dynamictrees:sprucebranch:14)
Block(0,2,2,dynamictrees:trunkshell:0)
Block(0,3,-6,dynamictrees:leaves0:4)
Block(0,3,-5,dynamictrees:leaves0:5)
Block(0,3,-4,dynamictrees:sprucebranch)
Block(0,3,-3,dynamictrees:sprucebranch:1)
Block(0,3,-2,dynamictrees:sprucebranch:1)
Block(0,3,-1,dynamictrees:sprucebranch:2)
Block(0,3,0,dynamictrees:sprucebranch:3)
Block(0,3,1,dynamictrees:sprucebranch:13)
Block(0,3,2,dynamictrees:trunkshell:0)
Block(0,3,4,dynamictrees:sprucebranch)
Block(0,3,5,dynamictrees:leaves0:5)
Block(0,3,6,dynamictrees:leaves0:4)
Block(0,4,-5,dynamictrees:leaves0:4)
Block(0,4,-4,dynamictrees:leaves0:4)
Block(0,4,0,dynamictrees:trunkshell)
Block(0,4,1,dynamictrees:sprucebranch:11)
Block(0,4,2,dynamictrees:trunkshell:0)
Block(0,4,5,dynamictrees:leaves0:4)
Block(0,5,-5,dynamictrees:leaves0:4)
Block(0,5,-4,dynamictrees:leaves0:5)
Block(0,5,-3,dynamictrees:sprucebranch)
Block(0,5,-2,dynamictrees:sprucebranch:1)
Block(0,5,-1,dynamictrees:sprucebranch:2)
Block(0,5,0,dynamictrees:sprucebranch:3)
Block(0,5,1,dynamictrees:sprucebranch:11)
Block(0,5,2,dynamictrees:sprucebranch:1)
Block(0,5,3,dynamictrees:sprucebranch:1)
Block(0,5,5,dynamictrees:leaves0:4)
Block(0,6,-4,dynamictrees:leaves0:4)
Block(0,6,-3,dynamictrees:leaves0:4)
Block(0,6,0,dynamictrees:trunkshell)
Block(0,6,1,dynamictrees:sprucebranch:9)
Block(0,6,2,dynamictrees:trunkshell:0)
Block(0,7,-4,dynamictrees:leaves0:4)
Block(0,7,-3,dynamictrees:leaves0:5)
Block(0,7,-2,dynamictrees:sprucebranch)
Block(0,7,-1,dynamictrees:sprucebranch:1)
Block(0,7,0,dynamictrees:sprucebranch:1)
Block(0,7,1,dynamictrees:sprucebranch:9)
Block(0,7,2,dynamictrees:sprucebranch:1)
Block(0,7,3,dynamictrees:sprucebranch:1)
Block(0,7,4,dynamictrees:sprucebranch)
Block(0,8,-3,dynamictrees:leaves0:4)
Block(0,8,-2,dynamictrees:leaves0:4)
Block(0,8,0,dynamictrees:trunkshell)
Block(0,8,1,dynamictrees:sprucebranch:8)
Block(0,8,2,dynamictrees:trunkshell:0)
Block(0,8,4,dynamictrees:leaves0:4)
Block(0,9,-4,dynamictrees:leaves0:4)
Block(0,9,-3,dynamictrees:leaves0:5)
Block(0,9,-2,dynamictrees:sprucebranch)
Block(0,9,-1,dynamictrees:sprucebranch:1)
Block(0,9,0,dynamictrees:sprucebranch:1)
Block(0,9,1,dynamictrees:sprucebranch:8)
Block(0,9,2,dynamictrees:sprucebranch:1)
Block(0,9,3,dynamictrees:sprucebranch:1)
Block(0,9,4,dynamictrees:sprucebranch)
Block(0,9,5,dynamictrees:leaves0:5)
Block(0,9,6,dynamictrees:leaves0:4)
Block(0,10,-3,dynamictrees:leaves0:4)
Block(0,10,-2,dynamictrees:leaves0:4)
Block(0,10,1,dynamictrees:sprucebranch:6)
Block(0,10,4,dynamictrees:leaves0:4)
Block(0,10,5,dynamictrees:leaves0:4)
Block(0,11,-2,dynamictrees:leaves0:4)
Block(0,11,-1,dynamictrees:leaves0:5)
Block(0,11,1,dynamictrees:sprucebranch:6)
Block(0,12,-1,dynamictrees:leaves0:4)
Block(0,12,1,dynamictrees:sprucebranch:5)
Block(0,13,-1,dynamictrees:leaves0:4)
Block(0,13,0,dynamictrees:sprucebranch:1)
Block(0,13,1,dynamictrees:sprucebranch:5)
Block(0,13,2,dynamictrees:sprucebranch:1)
Block(0,13,3,dynamictrees:sprucebranch)
Block(0,13,4,dynamictrees:leaves0:5)
Block(0,13,5,dynamictrees:leaves0:4)
Block(0,14,1,dynamictrees:sprucebranch:4)
Block(0,14,3,dynamictrees:leaves0:4)
Block(0,14,4,dynamictrees:leaves0:4)
Block(0,15,0,dynamictrees:sprucebranch)
Block(0,15,1,dynamictrees:sprucebranch:4)
Block(0,15,3,dynamictrees:leaves0:4)
Block(0,16,0,dynamictrees:leaves0:4)
Block(0,16,1,dynamictrees:sprucebranch:3)
Block(0,17,-2,dynamictrees:leaves0:4)
Block(0,17,-1,dynamictrees:leaves0:5)
Block(0,17,0,dynamictrees:sprucebranch)
Block(0,17,1,dynamictrees:sprucebranch:3)
Block(0,18,-1,dynamictrees:leaves0:4)
Block(0,18,0,dynamictrees:leaves0:4)
Block(0,18,1,dynamictrees:sprucebranch:2)
Block(0,18,2,dynamictrees:leaves0:4)
Block(0,19,1,dynamictrees:sprucebranch:2)
Block(0,19,2,dynamictrees:sprucebranch)
Block(0,19,3,dynamictrees:leaves0:5)
Block(0,19,4,dynamictrees:leaves0:4)
Block(0,20,1,dynamictrees:sprucebranch:1)
Block(0,20,2,dynamictrees:leaves0:4)
Block(0,20,3,dynamictrees:leaves0:4)
Block(0,21,1,dynamictrees:sprucebranch:1)
Block(0,22,-1,dynamictrees:leaves0:4)
Block(0,22,0,dynamictrees:leaves0:5)
Block(0,22,1,dynamictrees:sprucebranch)
Block(0,22,2,dynamictrees:leaves0:5)
Block(0,22,3,dynamictrees:leaves0:4)
Block(0,23,0,dynamictrees:leaves0:4)
Block(0,23,1,dynamictrees:leaves0:7)
Block(0,23,2,dynamictrees:leaves0:4)
Block(0,24,1,dynamictrees:leaves0:6)
Block(0,25,1,dynamictrees:leaves0:4)
Block(1,0,0,GRASS:0)
Block(1,0,1,GRASS:0)
Block(1,0,2,GRASS:0)
Block(1,1,0,dynamictrees:trunkshell:3)
Block(1,1,1,dynamictrees:trunkshell:2)
Block(1,1,2,dynamictrees:trunkshell:1)
Block(1,2,0,dynamictrees:trunkshell:3)
Block(1,2,1,dynamictrees:trunkshell:2)
Block(1,2,2,dynamictrees:trunkshell:1)
Block(1,3,-5,dynamictrees:leaves0:4)
Block(1,3,-4,dynamictrees:leaves0:5)
Block(1,3,-3,dynamictrees:sprucebranch)
Block(1,3,-1,dynamictrees:sprucebranch:1)
Block(1,3,0,dynamictrees:trunkshell:3)
Block(1,3,1,dynamictrees:sprucebranch:3)
Block(1,3,2,dynamictrees:sprucebranch:1)
Block(1,3,3,dynamictrees:sprucebranch:1)
Block(1,3,4,dynamictrees:sprucebranch:1)
Block(1,3,5,dynamictrees:leaves0:4)
Block(1,4,-4,dynamictrees:leaves0:4)
Block(1,4,-3,dynamictrees:leaves0:4)
Block(1,4,0,dynamictrees:trunkshell:3)
Block(1,4,1,dynamictrees:trunkshell:2)
Block(1,4,2,dynamictrees:trunkshell:1)
Block(1,5,-4,dynamictrees:leaves0:4)
Block(1,5,-3,dynamictrees:leaves0:5)
Block(1,5,-1,dynamictrees:sprucebranch:1)
Block(1,5,0,dynamictrees:trunkshell:3)
Block(1,5,1,dynamictrees:sprucebranch:2)
Block(1,5,2,dynamictrees:leaves0:5)
Block(1,5,3,dynamictrees:sprucebranch)
Block(1,6,-3,dynamictrees:leaves0:4)
Block(1,6,0,dynamictrees:trunkshell:3)
Block(1,6,1,dynamictrees:trunkshell:2)
Block(1,6,2,dynamictrees:leaves0:4)
Block(1,7,-3,dynamictrees:leaves0:4)
Block(1,7,0,dynamictrees:trunkshell:3)
Block(1,7,1,dynamictrees:sprucebranch:1)
Block(1,7,2,dynamictrees:trunkshell:1)
Block(1,7,3,dynamictrees:sprucebranch)
Block(1,8,0,dynamictrees:trunkshell:3)
Block(1,8,1,dynamictrees:trunkshell:2)
Block(1,8,2,dynamictrees:trunkshell:1)
Block(1,9,-3,dynamictrees:leaves0:4)
Block(1,9,-1,dynamictrees:sprucebranch)
Block(1,9,0,dynamictrees:trunkshell:3)
Block(1,9,1,dynamictrees:sprucebranch:1)
Block(1,9,2,dynamictrees:trunkshell:1)
Block(1,9,3,dynamictrees:sprucebranch)
Block(1,9,4,dynamictrees:leaves0:5)
Block(1,9,5,dynamictrees:leaves0:4)
Block(1,10,-1,dynamictrees:leaves0:4)
Block(1,10,3,dynamictrees:leaves0:4)
Block(1,10,4,dynamictrees:leaves0:4)
Block(1,11,-3,dynamictrees:leaves0:4)
Block(1,11,-2,dynamictrees:leaves0:5)
Block(1,11,-1,dynamictrees:sprucebranch)
Block(1,11,0,dynamictrees:sprucebranch:1)
Block(1,11,1,dynamictrees:sprucebranch:2)
Block(1,11,2,dynamictrees:sprucebranch:1)
Block(1,11,3,dynamictrees:leaves0:4)
Block(1,12,-2,dynamictrees:leaves0:4)
Block(1,12,-1,dynamictrees:leaves0:4)
Block(1,13,-2,dynamictrees:leaves0:4)
Block(1,13,-1,dynamictrees:leaves0:5)
Block(1,13,0,dynamictrees:sprucebranch)
Block(1,13,2,dynamictrees:sprucebranch)
Block(1,13,3,dynamictrees:leaves0:5)
Block(1,13,4,dynamictrees:leaves0:4)
Block(1,14,-1,dynamictrees:leaves0:4)
Block(1,14,0,dynamictrees:leaves0:4)
Block(1,14,2,dynamictrees:leaves0:4)
Block(1,14,3,dynamictrees:leaves0:4)
Block(1,15,-1,dynamictrees:leaves0:4)
Block(1,15,0,dynamictrees:leaves0:5)
Block(1,15,1,dynamictrees:sprucebranch:1)
Block(1,15,2,dynamictrees:sprucebranch)
Block(1,15,3,dynamictrees:leaves0:5)
Block(1,15,4,dynamictrees:leaves0:4)
Block(1,16,0,dynamictrees:leaves0:4)
Block(1,16,2,dynamictrees:leaves0:4)
Block(1,16,3,dynamictrees:leaves0:4)
Block(1,17,-1,dynamictrees:leaves0:4)
Block(1,17,0,dynamictrees:leaves0:5)
Block(1,17,1,dynamictrees:sprucebranch)
Block(1,17,2,dynamictrees:leaves0:5)
Block(1,17,3,dynamictrees:leaves0:4)
Block(1,18,0,dynamictrees:leaves0:4)
Block(1,18,1,dynamictrees:leaves0:4)
Block(1,18,2,dynamictrees:leaves0:4)
Block(1,19,1,dynamictrees:leaves0:4)
Block(1,19,2,dynamictrees:leaves0:5)
Block(1,19,3,dynamictrees:leaves0:4)
Block(1,20,2,dynamictrees:leaves0:4)
Block(1,22,0,dynamictrees:leaves0:4)
Block(1,22,1,dynamictrees:leaves0:5)
Block(1,22,2,dynamictrees:leaves0:4)
Block(1,23,1,dynamictrees:leaves0:4)
Block(2,3,-4,dynamictrees:leaves0:4)
Block(2,3,-3,dynamictrees:leaves0:5)
Block(2,3,-2,dynamictrees:leaves0:5)
Block(2,3,-1,dynamictrees:sprucebranch)
Block(2,3,1,dynamictrees:sprucebranch:2)
Block(2,3,4,dynamictrees:sprucebranch)
Block(2,3,5,dynamictrees:leaves0:5)
Block(2,3,6,dynamictrees:leaves0:4)
Block(2,4,-3,dynamictrees:leaves0:4)
Block(2,4,-2,dynamictrees:leaves0:4)
Block(2,4,4,dynamictrees:leaves0:4)
Block(2,4,5,dynamictrees:leaves0:4)
Block(2,5,-3,dynamictrees:leaves0:4)
Block(2,5,-2,dynamictrees:leaves0:5)
Block(2,5,-1,dynamictrees:sprucebranch)
Block(2,5,1,dynamictrees:sprucebranch:1)
Block(2,5,2,dynamictrees:sprucebranch)
Block(2,6,-2,dynamictrees:leaves0:4)
Block(2,6,-1,dynamictrees:leaves0:4)
Block(2,7,-2,dynamictrees:leaves0:4)
Block(2,7,-1,dynamictrees:leaves0:5)
Block(2,7,0,dynamictrees:sprucebranch)
Block(2,7,1,dynamictrees:sprucebranch:1)
Block(2,7,2,dynamictrees:sprucebranch)
Block(2,7,3,dynamictrees:leaves0:5)
Block(2,7,4,dynamictrees:leaves0:4)
Block(2,8,-1,dynamictrees:leaves0:4)
Block(2,8,3,dynamictrees:leaves0:4)
Block(2,9,-2,dynamictrees:leaves0:4)
Block(2,9,-1,dynamictrees:leaves0:5)
Block(2,9,1,dynamictrees:sprucebranch:1)
Block(2,9,4,dynamictrees:leaves0:4)
Block(2,10,-1,dynamictrees:leaves0:4)
Block(2,11,-2,dynamictrees:leaves0:4)
Block(2,11,-1,dynamictrees:leaves0:5)
Block(2,11,0,dynamictrees:leaves0:4)
Block(2,11,2,dynamictrees:sprucebranch)
Block(2,11,3,dynamictrees:leaves0:5)
Block(2,11,4,dynamictrees:leaves0:4)
Block(2,12,-1,dynamictrees:leaves0:4)
Block(2,12,2,dynamictrees:leaves0:4)
Block(2,12,3,dynamictrees:leaves0:4)
Block(2,13,-1,dynamictrees:leaves0:4)
Block(2,13,2,dynamictrees:leaves0:5)
Block(2,13,3,dynamictrees:leaves0:4)
Block(2,14,2,dynamictrees:leaves0:4)
Block(2,15,-1,dynamictrees:leaves0:4)
Block(2,15,0,dynamictrees:leaves0:5)
Block(2,15,1,dynamictrees:sprucebranch)
Block(2,15,2,dynamictrees:leaves0:5)
Block(2,15,3,dynamictrees:leaves0:4)
Block(2,16,0,dynamictrees:leaves0:4)
Block(2,16,1,dynamictrees:leaves0:4)
Block(2,16,2,dynamictrees:leaves0:4)
Block(2,17,0,dynamictrees:leaves0:4)
Block(2,17,1,dynamictrees:leaves0:5)
Block(2,17,2,dynamictrees:leaves0:4)
Block(2,18,1,dynamictrees:leaves0:4)
Block(2,19,2,dynamictrees:leaves0:4)
Block(2,22,1,dynamictrees:leaves0:4)
Block(3,3,-3,dynamictrees:leaves0:4)
Block(3,3,-2,dynamictrees:leaves0:4)
Block(3,3,0,dynamictrees:sprucebranch)
Block(3,3,1,dynamictrees:sprucebranch:2)
Block(3,3,2,dynamictrees:sprucebranch:1)
Block(3,3,3,dynamictrees:sprucebranch)
Block(3,3,4,dynamictrees:leaves0:5)
Block(3,3,5,dynamictrees:leaves0:4)
Block(3,4,3,dynamictrees:leaves0:4)
Block(3,4,4,dynamictrees:leaves0:4)
Block(3,5,-2,dynamictrees:leaves0:4)
Block(3,5,-1,dynamictrees:leaves0:5)
Block(3,5,0,dynamictrees:sprucebranch)
Block(3,5,1,dynamictrees:sprucebranch:1)
Block(3,5,2,dynamictrees:leaves0:5)
Block(3,5,3,dynamictrees:leaves0:4)
Block(3,6,-1,dynamictrees:leaves0:4)
Block(3,6,0,dynamictrees:leaves0:4)
Block(3,6,2,dynamictrees:leaves0:4)
Block(3,7,-1,dynamictrees:leaves0:4)
Block(3,7,0,dynamictrees:leaves0:5)
Block(3,7,2,dynamictrees:leaves0:5)
Block(3,7,3,dynamictrees:leaves0:4)
Block(3,8,0,dynamictrees:leaves0:4)
Block(3,8,2,dynamictrees:leaves0:4)
Block(3,9,-1,dynamictrees:leaves0:4)
Block(3,9,0,dynamictrees:leaves0:5)
Block(3,9,1,dynamictrees:sprucebranch)
Block(3,10,0,dynamictrees:leaves0:4)
Block(3,10,1,dynamictrees:leaves0:4)
Block(3,11,-1,dynamictrees:leaves0:4)
Block(3,11,1,dynamictrees:leaves0:4)
Block(3,11,2,dynamictrees:leaves0:5)
Block(3,11,3,dynamictrees:leaves0:4)
Block(3,12,2,dynamictrees:leaves0:4)
Block(3,13,2,dynamictrees:leaves0:4)
Block(3,15,0,dynamictrees:leaves0:4)
Block(3,15,1,dynamictrees:leaves0:5)
Block(3,15,2,dynamictrees:leaves0:4)
Block(3,16,1,dynamictrees:leaves0:4)
Block(3,17,1,dynamictrees:leaves0:4)
Block(4,3,-1,dynamictrees:leaves0:4)
Block(4,3,1,dynamictrees:sprucebranch:1)
Block(4,3,2,dynamictrees:leaves0:4)
Block(4,3,3,dynamictrees:leaves0:5)
Block(4,3,4,dynamictrees:leaves0:4)
Block(4,4,3,dynamictrees:leaves0:4)
Block(4,5,-1,dynamictrees:leaves0:4)
Block(4,5,0,dynamictrees:leaves0:5)
Block(4,5,1,dynamictrees:sprucebranch)
Block(4,5,2,dynamictrees:leaves0:5)
Block(4,5,3,dynamictrees:leaves0:4)
Block(4,6,0,dynamictrees:leaves0:4)
Block(4,6,1,dynamictrees:leaves0:4)
Block(4,6,2,dynamictrees:leaves0:4)
Block(4,7,0,dynamictrees:leaves0:4)
Block(4,7,2,dynamictrees:leaves0:4)
Block(4,9,0,dynamictrees:leaves0:4)
Block(4,9,1,dynamictrees:leaves0:5)
Block(4,9,2,dynamictrees:leaves0:4)
Block(4,10,1,dynamictrees:leaves0:4)
Block(4,11,2,dynamictrees:leaves0:4)
Block(4,15,1,dynamictrees:leaves0:4)
Block(5,3,-1,dynamictrees:leaves0:4)
Block(5,3,0,dynamictrees:leaves0:5)
Block(5,3,1,dynamictrees:sprucebranch)
Block(5,3,2,dynamictrees:leaves0:5)
Block(5,3,3,dynamictrees:leaves0:4)
Block(5,4,0,dynamictrees:leaves0:4)
Block(5,4,1,dynamictrees:leaves0:4)
Block(5,4,2,dynamictrees:leaves0:4)
Block(5,5,0,dynamictrees:leaves0:4)
Block(5,5,1,dynamictrees:leaves0:5)
Block(5,5,2,dynamictrees:leaves0:4)
Block(5,6,1,dynamictrees:leaves0:4)
Block(5,9,1,dynamictrees:leaves0:4)
Block(6,3,0,dynamictrees:leaves0:4)
Block(6,3,1,dynamictrees:leaves0:5)
Block(6,3,2,dynamictrees:leaves0:4)
Block(6,4,1,dynamictrees:leaves0:4)
Block(6,5,1,dynamictrees:leaves0:4)
Block(7,3,1,dynamictrees:leaves0:4)

#######################################################################
# +-----------------------------------------------------------------+ #
# |                            BO3 checks                           | #
# +-----------------------------------------------------------------+ #
#######################################################################

BlockCheck(0,-1,1,GRASS,DIRT,biomesoplenty:grass,biomesoplenty:dirt)

#######################################################################
# +-----------------------------------------------------------------+ #
# |                             Branches                            | #
# +-----------------------------------------------------------------+ #
#######################################################################


#######################################################################
# +-----------------------------------------------------------------+ #
# |                             Entities                            | #
# +-----------------------------------------------------------------+ #
#######################################################################


#######################################################################
# +-----------------------------------------------------------------+ #
# |                            Particles                            | #
# +-----------------------------------------------------------------+ #
#######################################################################


#######################################################################
# +-----------------------------------------------------------------+ #
# |                             Spawners                            | #
# +-----------------------------------------------------------------+ #
#######################################################################


#######################################################################
# +-----------------------------------------------------------------+ #
# |                             ModData                             | #
# +-----------------------------------------------------------------+ #
#######################################################################

