
#######################################################################
# +-----------------------------------------------------------------+ #
# |                            BO4 object                           | #
# +-----------------------------------------------------------------+ #
#######################################################################

Author: NLBlackEagle

Description: No description given

SettingsMode: WriteDisable


#######################################################################
# +-----------------------------------------------------------------+ #
# |                          Main settings                          | #
# +-----------------------------------------------------------------+ #
#######################################################################

FixedRotation: 

Frequency: 0

SpawnHeight: highestBlock

UseCenterForHighestBlock: true

##############################
# Height Limits for the BO4. #
##############################

MinHeight: 0

MaxHeight: 255

InheritBO3: 

InheritBO3Rotation: NORTH

OverrideChildSettings: true

OverrideParentHeight: false

CanOverride: true

BranchFrequency: 0

BranchFrequencyGroup: 

MustBeBelowOther: false

MustBeInside: 

CannotBeInside: 

ReplacesBO3: 

MustBeInsideWorldBorders: false

CanSpawnOnWater: true

SpawnOnWaterOnly: false

SpawnUnderWater: false

SpawnAtWaterLevel: false

HeightOffset: 0

RemoveAir: false

ReplaceAbove: 

ReplaceBelow: 

ReplaceWithBiomeBlocks: true

ReplaceWithSurfaceBlock: GRASS

ReplaceWithGroundBlock: DIRT

ReplaceWithStoneBlock: STONE

SmoothRadius: 0

SmoothHeightOffset: 0

SmoothStartTop: false

SmoothStartWood: false

SmoothingSurfaceBlock: 

SmoothingGroundBlock: 

BO3Group: 

IsSpawnPoint: false

DoReplaceBlocks: false


#######################################################################
# +-----------------------------------------------------------------+ #
# |                              Blocks                             | #
# +-----------------------------------------------------------------+ #
#######################################################################

Block(-8,0,-3,LOG:1)
Block(-8,0,0,LOG:1)
Block(-8,0,1,LOG:1)
Block(-8,0,3,LOG:1)
Block(-8,0,7,LOG:1)
Block(-8,1,-3,LOG:1)
Block(-8,1,0,LOG:1)
Block(-8,1,1,LOG:1)
Block(-8,1,3,LOG:1)
Block(-8,1,7,LOG:1)
Block(-8,2,-6,LOG:5)
Block(-8,2,-3,LOG:1)
Block(-8,2,-2,LOG:9)
Block(-8,2,-1,LOG:9)
Block(-8,2,0,LOG:1)
Block(-8,2,1,LOG:1)
Block(-8,2,2,LOG:9)
Block(-8,2,3,LOG:1)
Block(-8,2,4,LOG:9)
Block(-8,2,5,LOG:9)
Block(-8,2,6,LOG:9)
Block(-8,2,7,LOG:1)
Block(-8,3,-3,LOG:1)
Block(-8,3,0,LOG:1)
Block(-8,3,1,LOG:1)
Block(-8,3,3,LOG:1)
Block(-8,3,7,LOG:1)
Block(-8,4,-3,LOG:1)
Block(-8,4,0,LOG:1)
Block(-8,4,1,LOG:1)
Block(-8,4,3,LOG:1)
Block(-8,4,7,LOG:1)
Block(-8,5,-6,LOG:5)
Block(-8,5,-3,LOG:1)
Block(-8,5,-2,LOG:9)
Block(-8,5,-1,LOG:9)
Block(-8,5,0,LOG:1)
Block(-8,5,1,LOG:1)
Block(-8,5,2,LOG:9)
Block(-8,5,3,LOG:1)
Block(-8,5,4,LOG:9)
Block(-8,5,5,LOG:9)
Block(-8,5,6,LOG:9)
Block(-8,5,7,LOG:1)
Block(-8,6,-3,LOG:1)
Block(-8,6,0,LOG:1)
Block(-8,6,1,LOG:1)
Block(-8,6,3,LOG:1)
Block(-8,6,7,LOG:1)
Block(-8,7,-3,LOG:1)
Block(-8,7,0,LOG:1)
Block(-8,7,1,LOG:1)
Block(-8,7,3,LOG:1)
Block(-8,7,7,LOG:1)
Block(-8,8,-6,LOG:5)
Block(-8,8,-3,LOG:1)
Block(-8,8,-2,LOG:9)
Block(-8,8,-1,LOG:9)
Block(-8,8,0,LOG:1)
Block(-8,8,1,LOG:1)
Block(-8,8,2,LOG:9)
Block(-8,8,3,LOG:1)
Block(-8,8,4,LOG:9)
Block(-8,8,5,LOG:9)
Block(-8,8,6,LOG:9)
Block(-8,8,7,LOG:1)
Block(-8,9,-3,LOG:1)
Block(-8,9,0,LOG:1)
Block(-8,9,1,LOG:1)
Block(-8,9,3,LOG:1)
Block(-8,9,7,LOG:1)
Block(-8,10,-3,LOG:1)
Block(-8,10,0,LOG:1)
Block(-8,10,1,LOG:1)
Block(-8,10,3,LOG:1)
Block(-8,10,7,LOG:1)
Block(-8,11,-6,LOG:5)
Block(-8,11,-3,LOG:1)
Block(-8,11,-2,LOG:9)
Block(-8,11,-1,LOG:9)
Block(-8,11,0,LOG:1)
Block(-8,11,1,LOG:1)
Block(-8,11,2,LOG:9)
Block(-8,11,3,LOG:1)
Block(-8,11,4,LOG:9)
Block(-8,11,5,LOG:9)
Block(-8,11,6,LOG:9)
Block(-8,11,7,LOG:1)
Block(-8,12,-3,LOG:1)
Block(-8,12,0,LOG:1)
Block(-8,12,1,LOG:1)
Block(-8,12,3,LOG:1)
Block(-8,12,7,LOG:1)
Block(-8,13,-3,LOG:1)
Block(-8,13,0,LOG:1)
Block(-8,13,1,LOG:1)
Block(-8,13,3,LOG:1)
Block(-8,13,7,LOG:1)
Block(-8,14,-6,LOG:5)
Block(-8,14,-3,LOG:1)
Block(-8,14,-2,LOG:9)
Block(-8,14,-1,LOG:9)
Block(-8,14,0,LOG:1)
Block(-8,14,1,LOG:1)
Block(-8,14,2,LOG:9)
Block(-8,14,3,LOG:1)
Block(-8,14,4,LOG:9)
Block(-8,14,5,LOG:9)
Block(-8,14,6,LOG:9)
Block(-8,14,7,LOG:1)
Block(-8,15,-3,LOG:1)
Block(-8,15,0,LOG:1)
Block(-8,15,1,LOG:1)
Block(-8,15,3,LOG:1)
Block(-8,15,7,LOG:1)
Block(-8,16,-3,LOG:1)
Block(-8,16,0,LOG:1)
Block(-8,16,1,LOG:1)
Block(-8,16,3,LOG:1)
Block(-8,16,7,LOG:1)
Block(-8,17,-6,LOG:5)
Block(-8,17,-3,LOG:1)
Block(-8,17,-2,LOG:9)
Block(-8,17,-1,LOG:9)
Block(-8,17,0,LOG:1)
Block(-8,17,1,LOG:1)
Block(-8,17,2,LOG:9)
Block(-8,17,3,LOG:1)
Block(-8,17,4,LOG:9)
Block(-8,17,5,LOG:9)
Block(-8,17,6,LOG:9)
Block(-8,17,7,LOG:1)
Block(-8,18,-3,LOG:1)
Block(-8,18,0,LOG:1)
Block(-8,18,1,LOG:1)
Block(-8,18,3,LOG:1)
Block(-8,18,7,LOG:1)
Block(-8,19,-3,LOG:1)
Block(-8,19,0,LOG:1)
Block(-8,19,1,LOG:1)
Block(-8,19,3,LOG:1)
Block(-8,19,7,LOG:1)
Block(-8,20,-6,LOG:5)
Block(-8,20,-3,LOG:1)
Block(-8,20,-2,LOG:9)
Block(-8,20,-1,LOG:9)
Block(-8,20,0,LOG:1)
Block(-8,20,1,LOG:1)
Block(-8,20,2,LOG:9)
Block(-8,20,3,LOG:1)
Block(-8,20,4,LOG:9)
Block(-8,20,5,LOG:9)
Block(-8,20,6,LOG:9)
Block(-8,20,7,LOG:1)
Block(-8,21,-3,LOG:1)
Block(-8,21,0,LOG:1)
Block(-8,21,1,LOG:1)
Block(-8,21,3,LOG:1)
Block(-8,21,7,LOG:1)
Block(-8,22,-3,LOG:1)
Block(-8,22,0,LOG:1)
Block(-8,22,1,LOG:1)
Block(-8,22,3,LOG:1)
Block(-8,22,7,LOG:1)
Block(-8,23,-6,LOG:5)
Block(-8,23,-3,LOG:1)
Block(-8,23,-2,LOG:9)
Block(-8,23,-1,LOG:9)
Block(-8,23,0,LOG:1)
Block(-8,23,1,LOG:1)
Block(-8,23,2,LOG:9)
Block(-8,23,3,LOG:1)
Block(-8,23,4,LOG:9)
Block(-8,23,5,LOG:9)
Block(-8,23,6,LOG:9)
Block(-8,23,7,LOG:1)
Block(-8,24,-3,LOG:1)
Block(-8,24,0,LOG:1)
Block(-8,24,1,LOG:1)
Block(-8,24,3,LOG:1)
Block(-8,24,7,LOG:1)
Block(-8,25,-3,LOG:1)
Block(-8,25,0,LOG:1)
Block(-8,25,1,LOG:1)
Block(-8,25,3,LOG:1)
Block(-8,25,7,LOG:1)
Block(-8,26,-6,LOG:5)
Block(-8,26,-3,LOG:1)
Block(-8,26,-2,LOG:9)
Block(-8,26,-1,LOG:9)
Block(-8,26,0,LOG:1)
Block(-8,26,1,LOG:1)
Block(-8,26,2,LOG:9)
Block(-8,26,3,LOG:1)
Block(-8,26,4,LOG:9)
Block(-8,26,5,LOG:9)
Block(-8,26,6,LOG:9)
Block(-8,26,7,LOG:1)
Block(-8,27,-3,LOG:1)
Block(-8,27,-2,WOOD_STEP:13)
Block(-8,27,0,LOG:1)
Block(-8,27,1,LOG:1)
Block(-8,27,3,LOG:1)
Block(-8,27,7,LOG:1)
Block(-8,28,-3,LOG:1)
Block(-8,28,-2,WOOD_STEP:13)
Block(-8,28,-1,DARK_OAK_FENCE_GATE:3)
Block(-8,28,0,LOG:1)
Block(-8,28,1,LOG:1)
Block(-8,28,3,LOG:1)
Block(-8,28,7,LOG:1)
Block(-8,29,-7,WOOD_STEP:9)
Block(-8,29,-6,LOG:5)
Block(-8,29,-5,WOOD_STEP:9)
Block(-8,29,-4,WOOD_STEP:9)
Block(-8,29,-3,LOG:1)
Block(-8,29,-2,LOG:9)
Block(-8,29,-1,LOG:9)
Block(-8,29,0,LOG:1)
Block(-8,29,1,LOG:1)
Block(-8,29,2,LOG:9)
Block(-8,29,3,LOG:1)
Block(-8,29,4,LOG:9)
Block(-8,29,5,LOG:9)
Block(-8,29,6,LOG:9)
Block(-8,29,7,LOG:1)
Block(-8,29,8,LOG:9)
Block(-8,30,-7,fishingmadebetter:baitbox,../NBT/Trader_Swamp/161-fishingmadebetter_baitboxC16R16.nbt)
Block(-8,30,-6,SPRUCE_WOOD_STAIRS:2)
Block(-8,30,-5,BED_BLOCK:11,../NBT/Trader_Swamp/162-bedC16R16.nbt)
Block(-8,30,-4,rustic:barrel,../../../Chests/RLCraft/Containers/rustic_barrel.nbt)
Block(-8,30,-3,LOG:1)
Block(-8,30,-2,AIR:0)
Block(-8,30,-1,AIR:0)
Block(-8,30,0,LOG:1)
Block(-8,30,1,SPRUCE_WOOD_STAIRS:4)
Block(-8,30,2,CAULDRON:3,../NBT/Trader_Swamp/164-inspirations_cauldronC16R16.nbt)
Block(-8,30,3,LOG:1)
Block(-8,30,4,variedcommodities:weapon_rack:5,../NBT/Trader_Swamp/165-variedcommodities_weapon_rackC16R16.nbt)
RandomBlock(-8,30,5,minecraft:coal_ore,10,minecraft:iron_ore,10,biomesoplenty:gem_ore:1,10,biomesoplenty:gem_ore:2,10,biomesoplenty:gem_ore:3,10,biomesoplenty:gem_ore:4,10,biomesoplenty:gem_ore:5,10,iceandfire:sapphire_ore,10,biomesoplenty:gem_ore:7,10,biomesoplenty:gem_ore:0,10,minecraft:redstone_ore,20,minecraft:gold_ore,20,minecraft:lapis_ore,20,minecraft:diamond_ore,40,minecraft:emerald_ore,40,iceandfire:sapphire_ore,40,iceandfire:silver_ore,80,scalinghealth:crystalore,100)
RandomBlock(-8,30,6,minecraft:coal_ore,10,minecraft:iron_ore,10,biomesoplenty:gem_ore:1,10,biomesoplenty:gem_ore:2,10,biomesoplenty:gem_ore:3,10,biomesoplenty:gem_ore:4,10,biomesoplenty:gem_ore:5,10,iceandfire:sapphire_ore,10,biomesoplenty:gem_ore:7,10,biomesoplenty:gem_ore:0,10,minecraft:redstone_ore,20,minecraft:gold_ore,20,minecraft:lapis_ore,20,minecraft:diamond_ore,40,minecraft:emerald_ore,40,iceandfire:sapphire_ore,40,iceandfire:silver_ore,80,scalinghealth:crystalore,100)
Block(-8,30,7,LOG:1)
Block(-8,30,8,COBBLE_WALL:0)
Block(-8,31,-7,fishingmadebetter:baitbox,../NBT/Trader_Swamp/166-fishingmadebetter_baitboxC16R16.nbt)
Block(-8,31,-6,WOOD_STEP:9)
Block(-8,31,-5,WALL_BANNER:3,../NBT/Trader_Swamp/167-bannerC16R16.nbt)
Block(-8,31,-4,AIR:0)
Block(-8,31,-3,LOG:1)
Block(-8,31,-2,AIR:0)
Block(-8,31,-1,AIR:0)
Block(-8,31,0,LOG:1)
Block(-8,31,1,FLOWER_POT:0,../NBT/Trader_Swamp/168-flower_potC16R16.nbt)
Block(-8,31,2,AIR:0)
Block(-8,31,3,LOG:1)
Block(-8,31,4,variedcommodities:weapon_rack:12)
Block(-8,31,5,AIR:0)
RandomBlock(-8,31,6,minecraft:coal_ore,10,minecraft:iron_ore,10,biomesoplenty:gem_ore:1,10,biomesoplenty:gem_ore:2,10,biomesoplenty:gem_ore:3,10,biomesoplenty:gem_ore:4,10,biomesoplenty:gem_ore:5,10,iceandfire:sapphire_ore,10,biomesoplenty:gem_ore:7,10,biomesoplenty:gem_ore:0,10,minecraft:redstone_ore,20,minecraft:gold_ore,20,minecraft:lapis_ore,20,minecraft:diamond_ore,40,minecraft:emerald_ore,40,iceandfire:sapphire_ore,40,iceandfire:silver_ore,80,scalinghealth:crystalore,100)
Block(-8,31,7,LOG:1)
Block(-8,31,8,DARK_OAK_FENCE:0)
Block(-8,32,-7,charm:iron_lantern)
Block(-8,32,-6,LOG:5)
Block(-8,32,-5,inspirations:bookshelf:0,../NBT/Trader_Swamp/170-inspirations_bookshelfC16R16.nbt)
Block(-8,32,-4,AIR:0)
Block(-8,32,-3,LOG:1)
Block(-8,32,-2,inspirations:rope)
Block(-8,32,-1,AIR:0)
Block(-8,32,0,LOG:1)
Block(-8,32,1,IRON_FENCE:0)
Block(-8,32,2,AIR:0)
Block(-8,32,3,LOG:1)
Block(-8,32,4,AIR:0)
Block(-8,32,5,AIR:0)
RandomBlock(-8,32,6,minecraft:coal_ore,10,minecraft:iron_ore,10,biomesoplenty:gem_ore:1,10,biomesoplenty:gem_ore:2,10,biomesoplenty:gem_ore:3,10,biomesoplenty:gem_ore:4,10,biomesoplenty:gem_ore:5,10,iceandfire:sapphire_ore,10,biomesoplenty:gem_ore:7,10,biomesoplenty:gem_ore:0,10,minecraft:redstone_ore,20,minecraft:gold_ore,20,minecraft:lapis_ore,20,minecraft:diamond_ore,40,minecraft:emerald_ore,40,iceandfire:sapphire_ore,40,iceandfire:silver_ore,80,scalinghealth:crystalore,100)
Block(-8,32,7,LOG:1)
Block(-8,32,8,DARK_OAK_FENCE:0)
Block(-8,33,-7,AIR:0)
Block(-8,33,-6,DARK_OAK_FENCE:0)
Block(-8,33,-5,AIR:0)
Block(-8,33,-4,charm:iron_lantern:1)
Block(-8,33,-3,LOG:1)
Block(-8,33,-2,inspirations:rope)
Block(-8,33,-1,variedcommodities:sign:5,../NBT/Trader_Swamp/171-variedcommodities_signC16R16.nbt)
Block(-8,33,0,LOG:1)
Block(-8,33,1,WOOD_STEP:9)
Block(-8,33,2,AIR:0)
Block(-8,33,3,LOG:1)
Block(-8,33,4,AIR:0)
Block(-8,33,5,charm:iron_lantern:1)
Block(-8,33,6,AIR:0)
Block(-8,33,7,LOG:1)
Block(-8,33,8,COBBLE_WALL:1)
Block(-8,34,-7,SPRUCE_WOOD_STAIRS:6)
Block(-8,34,-6,WOOD_DOUBLE_STEP:1)
Block(-8,34,-5,WOOD_DOUBLE_STEP:1)
Block(-8,34,-4,WOOD_DOUBLE_STEP:1)
Block(-8,34,-3,LOG:1)
Block(-8,34,-2,LOG:9)
Block(-8,34,-1,LOG:9)
Block(-8,34,0,LOG:1)
Block(-8,34,1,LOG:1)
Block(-8,34,2,LOG:9)
Block(-8,34,3,LOG:1)
Block(-8,34,4,LOG:9)
Block(-8,34,5,LOG:9)
Block(-8,34,6,LOG:9)
Block(-8,34,7,LOG:1)
Block(-8,34,8,LOG:9)
Block(-8,35,-7,WOOD_STEP:1)
Block(-8,35,-6,WOOD_DOUBLE_STEP:1)
Block(-8,35,-5,AIR:0)
Block(-8,35,-4,WOODEN_DOOR:1)
Block(-8,35,-3,LOG:1)
Block(-8,35,-2,WOOD:1)
Block(-8,35,-1,WOOD:1)
Block(-8,35,0,LOG:1)
Block(-8,35,1,LOG:1)
Block(-8,35,2,AIR:0)
Block(-8,35,3,LOG:1)
Block(-8,35,4,AIR:0)
Block(-8,35,5,AIR:0)
Block(-8,35,6,rustic:barrel,../../../Chests/RLCraft/Containers/rustic_barrel.nbt)
Block(-8,35,7,LOG:1)
Block(-8,35,8,COBBLE_WALL:0)
Block(-8,36,-7,WOOD_STEP:9)
Block(-8,36,-6,LOG:5)
Block(-8,36,-5,AIR:0)
Block(-8,36,-4,WOODEN_DOOR:8)
Block(-8,36,-3,LOG:1)
Block(-8,36,-2,DARK_OAK_STAIRS:3)
Block(-8,36,-1,DARK_OAK_STAIRS:2)
Block(-8,36,0,LOG:1)
Block(-8,36,1,LOG:1)
Block(-8,36,2,AIR:0)
Block(-8,36,3,LOG:1)
Block(-8,36,4,AIR:0)
Block(-8,36,5,AIR:0)
Block(-8,36,6,AIR:0)
Block(-8,36,7,LOG:1)
Block(-8,36,8,WOOD_STEP:1)
Block(-8,37,-7,WORKBENCH:0,../NBT/Trader_Swamp/175-realbench_workbenchC16R16.nbt)
Block(-8,37,-6,SPRUCE_WOOD_STAIRS:3)
Block(-8,37,-5,WOOD_STEP:1)
Block(-8,37,-4,WOOD_STEP:1)
Block(-8,37,-3,LOG:1)
Block(-8,37,-2,DARK_OAK_STAIRS:7)
Block(-8,37,-1,DARK_OAK_STAIRS:6)
Block(-8,37,0,LOG:1)
Block(-8,37,1,LOG:1)
Block(-8,37,2,variedcommodities:shelf:5,../NBT/Trader_Swamp/176-variedcommodities_shelfC16R16.nbt)
Block(-8,37,3,LOG:1)
Block(-8,37,4,charm:iron_lantern:1)
Block(-8,37,5,WOOD_STEP:9)
Block(-8,37,6,WOOD_STEP:1)
Block(-8,37,7,STONE_BUTTON:5)
Block(-8,38,-7,AIR:0)
Block(-8,38,-6,SPRUCE_WOOD_STAIRS:2)
Block(-8,38,-5,SPRUCE_WOOD_STAIRS:3)
Block(-8,38,-4,charm:iron_lantern:1)
Block(-8,38,-3,LOG:1)
Block(-8,38,-2,WOOD:1)
Block(-8,38,-1,WOOD:1)
Block(-8,38,0,LOG:1)
Block(-8,38,1,LOG:1)
Block(-8,38,2,charm:iron_lantern:1)
Block(-8,38,3,LOG:1)
Block(-8,38,4,WOOD_STEP:1)
Block(-8,39,-7,AIR:0)
Block(-8,39,-6,DARK_OAK_FENCE:0)
Block(-8,39,-5,WOOD_STEP:1)
Block(-8,39,-4,WOOD_STEP:1)
Block(-8,39,-3,LOG:1)
Block(-8,39,-2,LOG:9)
Block(-8,39,-1,LOG:9)
Block(-8,39,0,LOG:1)
Block(-8,39,1,WOOD_STEP:1)
Block(-8,39,2,WOOD_STEP:1)
Block(-8,39,3,STONE_BUTTON:5)
Block(-8,40,-7,SPRUCE_WOOD_STAIRS:3)
Block(-8,40,-6,WOOD_STEP:1)
Block(-8,40,-3,STONE_BUTTON:5)
Block(-8,40,0,STONE_BUTTON:5)
Block(-7,0,-5,LOG:1)
Block(-7,0,2,LOG:1)
Block(-7,1,-5,LOG:1)
Block(-7,1,2,LOG:1)
Block(-7,2,-6,LOG:5)
Block(-7,2,-5,LOG:1)
Block(-7,2,-4,LOG:9)
Block(-7,2,-3,LOG:5)
Block(-7,2,-2,LOG:5)
Block(-7,2,0,LOG:5)
Block(-7,2,1,LOG:9)
Block(-7,2,2,LOG:1)
Block(-7,2,3,LOG:5)
Block(-7,2,6,LOG:5)
Block(-7,3,-5,LOG:1)
Block(-7,3,2,LOG:1)
Block(-7,4,-5,LOG:1)
Block(-7,4,2,LOG:1)
Block(-7,5,-6,LOG:5)
Block(-7,5,-5,LOG:1)
Block(-7,5,-4,LOG:9)
Block(-7,5,-3,LOG:5)
Block(-7,5,-2,LOG:5)
Block(-7,5,0,LOG:5)
Block(-7,5,1,LOG:9)
Block(-7,5,2,LOG:1)
Block(-7,5,3,LOG:5)
Block(-7,5,6,LOG:5)
Block(-7,6,-5,LOG:1)
Block(-7,6,2,LOG:1)
Block(-7,7,-5,LOG:1)
Block(-7,7,2,LOG:1)
Block(-7,8,-6,LOG:5)
Block(-7,8,-5,LOG:1)
Block(-7,8,-4,LOG:9)
Block(-7,8,-3,LOG:5)
Block(-7,8,-2,LOG:5)
Block(-7,8,0,LOG:5)
Block(-7,8,1,LOG:9)
Block(-7,8,2,LOG:1)
Block(-7,8,3,LOG:5)
Block(-7,8,6,LOG:5)
Block(-7,9,-5,LOG:1)
Block(-7,9,2,LOG:1)
Block(-7,10,-5,LOG:1)
Block(-7,10,2,LOG:1)
Block(-7,11,-6,LOG:5)
Block(-7,11,-5,LOG:1)
Block(-7,11,-4,LOG:9)
Block(-7,11,-3,LOG:5)
Block(-7,11,-2,LOG:5)
Block(-7,11,0,LOG:5)
Block(-7,11,1,LOG:9)
Block(-7,11,2,LOG:1)
Block(-7,11,3,LOG:5)
Block(-7,11,6,LOG:5)
Block(-7,12,-5,LOG:1)
Block(-7,12,2,LOG:1)
Block(-7,13,-5,LOG:1)
Block(-7,13,2,LOG:1)
Block(-7,14,-6,LOG:5)
Block(-7,14,-5,LOG:1)
Block(-7,14,-4,LOG:9)
Block(-7,14,-3,LOG:5)
Block(-7,14,-2,LOG:5)
Block(-7,14,0,LOG:5)
Block(-7,14,1,LOG:9)
Block(-7,14,2,LOG:1)
Block(-7,14,3,LOG:5)
Block(-7,14,6,LOG:5)
Block(-7,15,-5,LOG:1)
Block(-7,15,2,LOG:1)
Block(-7,16,-5,LOG:1)
Block(-7,16,2,LOG:1)
Block(-7,17,-6,LOG:5)
Block(-7,17,-5,LOG:1)
Block(-7,17,-4,LOG:9)
Block(-7,17,-3,LOG:5)
Block(-7,17,-2,LOG:5)
Block(-7,17,0,LOG:5)
Block(-7,17,1,LOG:9)
Block(-7,17,2,LOG:1)
Block(-7,17,3,LOG:5)
Block(-7,17,6,LOG:5)
Block(-7,18,-5,LOG:1)
Block(-7,18,2,LOG:1)
Block(-7,19,-5,LOG:1)
Block(-7,19,2,LOG:1)
Block(-7,20,-6,LOG:5)
Block(-7,20,-5,LOG:1)
Block(-7,20,-4,LOG:9)
Block(-7,20,-3,LOG:5)
Block(-7,20,-2,LOG:5)
Block(-7,20,0,LOG:5)
Block(-7,20,1,LOG:9)
Block(-7,20,2,LOG:1)
Block(-7,20,3,LOG:5)
Block(-7,20,6,LOG:5)
Block(-7,21,-5,LOG:1)
Block(-7,21,2,LOG:1)
Block(-7,22,-5,LOG:1)
Block(-7,22,2,LOG:1)
Block(-7,23,-6,LOG:5)
Block(-7,23,-5,LOG:1)
Block(-7,23,-4,LOG:9)
Block(-7,23,-3,LOG:5)
Block(-7,23,-2,LOG:5)
Block(-7,23,0,LOG:5)
Block(-7,23,1,LOG:9)
Block(-7,23,2,LOG:1)
Block(-7,23,3,LOG:5)
Block(-7,23,6,LOG:5)
Block(-7,24,-5,LOG:1)
Block(-7,24,2,LOG:1)
Block(-7,25,-5,LOG:1)
Block(-7,25,2,LOG:1)
Block(-7,26,-6,LOG:5)
Block(-7,26,-5,LOG:1)
Block(-7,26,-4,LOG:9)
Block(-7,26,-3,LOG:5)
Block(-7,26,-2,LOG:5)
Block(-7,26,-1,WOOD_STEP:13)
Block(-7,26,0,LOG:5)
Block(-7,26,1,LOG:9)
Block(-7,26,2,LOG:1)
Block(-7,26,3,LOG:5)
Block(-7,26,6,LOG:5)
Block(-7,27,-5,LOG:1)
Block(-7,27,-2,WOOD_STEP:13)
RandomBlock(-7,27,1,minecraft:coal_ore,10,minecraft:iron_ore,10,biomesoplenty:gem_ore:1,10,biomesoplenty:gem_ore:2,10,biomesoplenty:gem_ore:3,10,biomesoplenty:gem_ore:4,10,biomesoplenty:gem_ore:5,10,iceandfire:sapphire_ore,10,biomesoplenty:gem_ore:7,10,biomesoplenty:gem_ore:0,10,minecraft:redstone_ore,20,minecraft:gold_ore,20,minecraft:lapis_ore,20,minecraft:diamond_ore,40,minecraft:emerald_ore,40,iceandfire:sapphire_ore,40,iceandfire:silver_ore,80,scalinghealth:crystalore,100)
Block(-7,27,2,LOG:1)
Block(-7,28,-5,LOG:1)
Block(-7,28,-3,WALL_BANNER:2,../NBT/Trader_Swamp/178-bannerC16R16.nbt)
Block(-7,28,-2,WOOD_STEP:13)
Block(-7,28,-1,WALL_BANNER:4,../NBT/Trader_Swamp/179-bannerC16R16.nbt)
Block(-7,28,0,WALL_BANNER:2,../NBT/Trader_Swamp/180-bannerC16R16.nbt)
RandomBlock(-7,28,1,AIR:0,30,CHEST:5,../../../Chests/Loot/junk_loot.nbt,10,CHEST:5,../../../Chests/Lore/gemtraderswamp.nbt,10,CHEST:5,../../../Chests/Loot/village_blacksmith.nbt,10,CHEST:5,../../../Chests/Loot/spawn_bonus_chest.nbt,10,CHEST:5,../../../Chests/Loot/rare_loot.nbt,5,CHEST:5,../../../Chests/Loot/gem_loot.nbt,3,CHEST:5,../../../Chests/Loot/junk_loot.nbt,50,CHEST:5,../../../Chests/Loot/gem_loot.nbt,5,CHEST:5,../../../Chests/Loot/common_loot.nbt,100)
Block(-7,28,2,LOG:1)
Block(-7,28,3,WOOD_STEP:13)
Block(-7,28,4,WALL_BANNER:3,../NBT/Trader_Swamp/182-bannerC16R16.nbt)
Block(-7,29,-7,WOOD_STEP:9)
Block(-7,29,-6,LOG:5)
Block(-7,29,-5,LOG:1)
Block(-7,29,-4,LOG:9)
Block(-7,29,-3,LOG:5)
Block(-7,29,-2,LOG:5)
Block(-7,29,-1,WOOD_STEP:9)
Block(-7,29,0,WOOD_STEP:9)
Block(-7,29,1,LOG:9)
Block(-7,29,2,LOG:1)
Block(-7,29,3,LOG:5)
Block(-7,29,4,WOOD_STEP:9)
Block(-7,29,5,WOOD_STEP:9)
Block(-7,29,6,LOG:5)
Block(-7,29,7,WOOD_STEP:9)
Block(-7,29,8,WOOD_STEP:9)
Block(-7,30,-7,MELON_BLOCK:0)
Block(-7,30,-6,SPRUCE_WOOD_STAIRS:0)
Block(-7,30,-5,LOG:1)
RandomBlock(-7,30,-4,variedcommodities:crate:1,5,charm:crate_sealed:1,../../../Chests/RLCraft/Containers/charm_villager_crate.nbt,10,charm:crate_sealed:1,../../../Chests/RLCraft/Containers/charm_villager_crate.nbt,100)
Block(-7,30,-3,SPRUCE_WOOD_STAIRS:3)
Block(-7,30,-2,AIR:0)
Block(-7,30,-1,AIR:0)
Block(-7,30,0,SPRUCE_WOOD_STAIRS:5)
Block(-7,30,1,WOOD:1)
Block(-7,30,2,LOG:1)
Block(-7,30,3,COAL_BLOCK:0)
Block(-7,30,4,AIR:0)
Block(-7,30,5,AIR:0)
Block(-7,30,6,charm:nether_gold_deposit)
Block(-7,30,7,DARK_OAK_FENCE:0)
Block(-7,30,8,DARK_OAK_FENCE:0)
Block(-7,31,-7,HAY_BLOCK:0)
Block(-7,31,-6,SPRUCE_WOOD_STAIRS:4)
Block(-7,31,-5,LOG:1)
RandomBlock(-7,31,-4,variedcommodities:crate:1,5,charm:crate_sealed:1,../../../Chests/RLCraft/Containers/charm_villager_crate.nbt,10,charm:crate_sealed:1,../../../Chests/RLCraft/Containers/charm_villager_crate.nbt,100)
Block(-7,31,-3,SPRUCE_WOOD_STAIRS:7)
Block(-7,31,-2,AIR:0)
Block(-7,31,-1,AIR:0)
Block(-7,31,0,FLOWER_POT:0,../NBT/Trader_Swamp/192-flower_potC16R16.nbt)
Block(-7,31,1,WOOD:5)
Block(-7,31,2,LOG:1)
Block(-7,31,3,iceandfire:goldpile)
Block(-7,31,4,AIR:0)
Block(-7,31,5,AIR:0)
RandomBlock(-7,31,6,minecraft:coal_ore,10,minecraft:iron_ore,10,biomesoplenty:gem_ore:1,10,biomesoplenty:gem_ore:2,10,biomesoplenty:gem_ore:3,10,biomesoplenty:gem_ore:4,10,biomesoplenty:gem_ore:5,10,iceandfire:sapphire_ore,10,biomesoplenty:gem_ore:7,10,biomesoplenty:gem_ore:0,10,minecraft:redstone_ore,20,minecraft:gold_ore,20,minecraft:lapis_ore,20,minecraft:diamond_ore,40,minecraft:emerald_ore,40,iceandfire:sapphire_ore,40,iceandfire:silver_ore,80,scalinghealth:crystalore,100)
Block(-7,31,7,AIR:0)
Block(-7,32,-7,AIR:0)
Block(-7,32,-6,LOG:5)
Block(-7,32,-5,LOG:1)
Block(-7,32,-4,inspirations:bookshelf:4,../NBT/Trader_Swamp/193-inspirations_bookshelfC16R16.nbt)
Block(-7,32,-3,LOG:5)
Block(-7,32,-2,AIR:0)
Block(-7,32,-1,AIR:0)
Block(-7,32,0,IRON_FENCE:0)
Block(-7,32,1,WOOD:5)
Block(-7,32,2,LOG:1)
Block(-7,32,3,AIR:0)
Block(-7,32,4,AIR:0)
Block(-7,32,5,AIR:0)
Block(-7,32,6,IRON_FENCE:0)
Block(-7,32,7,IRON_FENCE:0)
Block(-7,33,-7,SPRUCE_WOOD_STAIRS:4)
Block(-7,33,-6,WOOD:1)
Block(-7,33,-5,LOG:1)
Block(-7,33,-4,SPRUCE_WOOD_STAIRS:4)
Block(-7,33,-3,DARK_OAK_FENCE:0)
Block(-7,33,-2,SPRUCE_WOOD_STAIRS:4)
Block(-7,33,-1,WALL_BANNER:2,../NBT/Trader_Swamp/194-bannerC16R16.nbt)
Block(-7,33,0,WOOD_STEP:13)
Block(-7,33,1,WOOD:1)
Block(-7,33,2,LOG:1)
Block(-7,33,3,AIR:0)
Block(-7,33,4,AIR:0)
Block(-7,33,5,AIR:0)
Block(-7,33,6,WOOD_STEP:9)
Block(-7,33,7,WALL_BANNER:3,../NBT/Trader_Swamp/195-bannerC16R16.nbt)
Block(-7,34,-7,SPRUCE_WOOD_STAIRS:1)
Block(-7,34,-6,SPRUCE_WOOD_STAIRS:1)
Block(-7,34,-5,LOG:1)
Block(-7,34,-4,LOG:9)
Block(-7,34,-3,LOG:5)
Block(-7,34,-2,WOOD_DOUBLE_STEP:1)
Block(-7,34,-1,WOOD_STEP:9)
Block(-7,34,0,LOG:5)
Block(-7,34,1,LOG:9)
Block(-7,34,2,LOG:1)
Block(-7,34,3,LOG:5)
Block(-7,34,4,WOOD_STEP:9)
Block(-7,34,5,WOOD_STEP:9)
Block(-7,34,6,LOG:5)
Block(-7,34,7,WOOD_STEP:9)
Block(-7,34,8,WOOD_STEP:9)
Block(-7,35,-7,AIR:0)
Block(-7,35,-6,WOOD_STEP:1)
Block(-7,35,-5,LOG:1)
Block(-7,35,-4,WOOD:1)
Block(-7,35,-3,SPRUCE_WOOD_STAIRS:5)
RandomBlock(-7,35,-2,variedcommodities:crate:1,5,charm:crate_sealed:1,../../../Chests/RLCraft/Containers/charm_villager_crate.nbt,10,charm:crate_sealed:1,../../../Chests/RLCraft/Containers/charm_villager_crate.nbt,100)
Block(-7,35,-1,HAY_BLOCK:8)
RandomBlock(-7,35,0,variedcommodities:crate:5,5,charm:crate_sealed:5,../../../Chests/RLCraft/Containers/charm_villager_crate.nbt,10,charm:crate_sealed:5,../../../Chests/RLCraft/Containers/charm_villager_crate.nbt,100)
Block(-7,35,1,WOOD:1)
Block(-7,35,2,LOG:1)
Block(-7,35,3,AIR:0)
Block(-7,35,4,AIR:0)
Block(-7,35,5,AIR:0)
RandomBlock(-7,35,6,variedcommodities:crate:1,5,charm:crate_sealed:1,../../../Chests/RLCraft/Containers/charm_villager_crate.nbt,10,charm:crate_sealed:1,../../../Chests/RLCraft/Containers/charm_villager_crate.nbt,100)
Block(-7,35,7,DARK_OAK_FENCE:0)
Block(-7,35,8,DARK_OAK_FENCE:0)
Block(-7,36,-7,WOOD_STEP:9)
Block(-7,36,-6,LOG:5)
Block(-7,36,-5,LOG:1)
Block(-7,36,-4,DARK_OAK_STAIRS:2)
Block(-7,36,-3,FLOWER_POT:0,../NBT/Trader_Swamp/199-flower_potC16R16.nbt)
Block(-7,36,-2,AIR:0)
Block(-7,36,-1,HAY_BLOCK:8)
RandomBlock(-7,36,0,variedcommodities:barrel:5,5,charm:barrel:5,../../../Chests/RLCraft/Containers/charm_barrel.nbt,100)
Block(-7,36,1,WOOD:5)
Block(-7,36,2,LOG:1)
Block(-7,36,3,inspirations:rope)
Block(-7,36,4,AIR:0)
Block(-7,36,5,AIR:0)
Block(-7,36,6,variedcommodities:stool:5,../NBT/Trader_Swamp/201-variedcommodities_stoolC16R16.nbt)
Block(-7,36,7,SPRUCE_WOOD_STAIRS:3)
Block(-7,37,-7,quark:custom_bookshelf)
Block(-7,37,-6,SPRUCE_WOOD_STAIRS:3)
Block(-7,37,-5,LOG:1)
Block(-7,37,-4,DARK_OAK_STAIRS:6)
Block(-7,37,-3,IRON_FENCE:0)
Block(-7,37,-2,AIR:0)
Block(-7,37,-1,AIR:0)
Block(-7,37,0,AIR:0)
Block(-7,37,1,WOOD:5)
Block(-7,37,2,LOG:1)
Block(-7,37,3,inspirations:rope)
Block(-7,37,4,WOOD_STEP:9)
Block(-7,37,5,WOOD_STEP:9)
Block(-7,37,6,WOOD_STEP:1)
Block(-7,37,7,AIR:0)
Block(-7,38,-7,quark:custom_bookshelf)
Block(-7,38,-6,SPRUCE_WOOD_STAIRS:2)
Block(-7,38,-5,LOG:1)
Block(-7,38,-4,WOOD:1)
Block(-7,38,-3,WOOD_STEP:9)
Block(-7,38,-2,WALL_BANNER:3,../NBT/Trader_Swamp/209-bannerC16R16.nbt)
Block(-7,38,-1,AIR:0)
Block(-7,38,0,WOOD_STEP:9)
Block(-7,38,1,WOOD:1)
Block(-7,38,2,LOG:1)
Block(-7,38,3,WOOD_STEP:1)
Block(-7,39,-7,SPRUCE_WOOD_STAIRS:4)
Block(-7,39,-6,SPRUCE_WOOD_STAIRS:1)
Block(-7,39,-5,LOG:1)
Block(-7,39,-4,LOG:9)
Block(-7,39,-3,LOG:5)
Block(-7,39,-2,inspirations:bookshelf:12,../NBT/Trader_Swamp/210-inspirations_bookshelfC16R16.nbt)
Block(-7,39,-1,inspirations:bookshelf:12,../NBT/Trader_Swamp/211-inspirations_bookshelfC16R16.nbt)
Block(-7,39,0,LOG:5)
Block(-7,39,1,LOG:9)
Block(-7,39,2,LOG:1)
Block(-7,39,3,WOOD_STEP:1)
Block(-7,40,-7,SPRUCE_WOOD_STAIRS:3)
Block(-7,40,-6,AIR:0)
Block(-7,40,-5,STONE_BUTTON:5)
Block(-7,40,-3,WOOD_STEP:1)
Block(-7,40,-2,WOOD_STEP:1)
Block(-7,40,-1,WOOD_STEP:1)
Block(-7,40,0,WOOD_STEP:1)
Block(-7,40,2,STONE_BUTTON:5)
Block(-6,0,-6,LOG:1)
Block(-6,0,-2,LOG:1)
Block(-6,0,6,LOG:1)
Block(-6,1,-6,LOG:1)
Block(-6,1,-2,LOG:1)
Block(-6,1,6,LOG:1)
Block(-6,2,-7,LOG:9)
Block(-6,2,-6,LOG:1)
Block(-6,2,-3,LOG:5)
Block(-6,2,-2,LOG:1)
Block(-6,2,0,LOG:5)
Block(-6,2,3,LOG:1)
Block(-6,2,6,LOG:1)
Block(-6,3,-6,LOG:1)
Block(-6,3,-2,LOG:1)
Block(-6,3,6,LOG:1)
Block(-6,4,-6,LOG:1)
Block(-6,4,-2,LOG:1)
Block(-6,4,6,LOG:1)
Block(-6,5,-7,LOG:9)
Block(-6,5,-6,LOG:1)
Block(-6,5,-3,LOG:5)
Block(-6,5,-2,LOG:1)
Block(-6,5,0,LOG:5)
Block(-6,5,3,LOG:1)
Block(-6,5,6,LOG:1)
Block(-6,6,-6,LOG:1)
Block(-6,6,-2,LOG:1)
Block(-6,6,6,LOG:1)
Block(-6,7,-6,LOG:1)
Block(-6,7,-2,LOG:1)
Block(-6,7,6,LOG:1)
Block(-6,8,-7,LOG:9)
Block(-6,8,-6,LOG:1)
Block(-6,8,-3,LOG:5)
Block(-6,8,-2,LOG:1)
Block(-6,8,0,LOG:5)
Block(-6,8,3,LOG:1)
Block(-6,8,6,LOG:1)
Block(-6,9,-6,LOG:1)
Block(-6,9,-2,LOG:1)
Block(-6,9,6,LOG:1)
Block(-6,10,-6,LOG:1)
Block(-6,10,-2,LOG:1)
Block(-6,10,6,LOG:1)
Block(-6,11,-7,LOG:9)
Block(-6,11,-6,LOG:1)
Block(-6,11,-3,LOG:5)
Block(-6,11,-2,LOG:1)
Block(-6,11,0,LOG:5)
Block(-6,11,3,LOG:1)
Block(-6,11,6,LOG:1)
Block(-6,12,-6,LOG:1)
Block(-6,12,-2,LOG:1)
Block(-6,12,6,LOG:1)
Block(-6,13,-6,LOG:1)
Block(-6,13,-2,LOG:1)
Block(-6,13,6,LOG:1)
Block(-6,14,-7,LOG:9)
Block(-6,14,-6,LOG:1)
Block(-6,14,-3,LOG:5)
Block(-6,14,-2,LOG:1)
Block(-6,14,0,LOG:5)
Block(-6,14,3,LOG:1)
Block(-6,14,6,LOG:1)
Block(-6,15,-6,LOG:1)
Block(-6,15,-2,LOG:1)
Block(-6,15,6,LOG:1)
Block(-6,16,-6,LOG:1)
Block(-6,16,-2,LOG:1)
Block(-6,16,6,LOG:1)
Block(-6,17,-7,LOG:9)
Block(-6,17,-6,LOG:1)
Block(-6,17,-3,LOG:5)
Block(-6,17,-2,LOG:1)
Block(-6,17,0,LOG:5)
Block(-6,17,3,LOG:1)
Block(-6,17,6,LOG:1)
Block(-6,18,-6,LOG:1)
Block(-6,18,-2,LOG:1)
Block(-6,18,6,LOG:1)
Block(-6,19,-6,LOG:1)
Block(-6,19,-2,LOG:1)
Block(-6,19,6,LOG:1)
Block(-6,20,-7,LOG:9)
Block(-6,20,-6,LOG:1)
Block(-6,20,-3,LOG:5)
Block(-6,20,-2,LOG:1)
Block(-6,20,0,LOG:5)
Block(-6,20,3,LOG:1)
Block(-6,20,6,LOG:1)
Block(-6,21,-6,LOG:1)
Block(-6,21,-2,LOG:1)
Block(-6,21,6,LOG:1)
Block(-6,22,-6,LOG:1)
Block(-6,22,-2,LOG:1)
Block(-6,22,6,LOG:1)
Block(-6,23,-7,LOG:9)
Block(-6,23,-6,LOG:1)
Block(-6,23,-3,LOG:5)
Block(-6,23,-2,LOG:1)
Block(-6,23,0,LOG:5)
Block(-6,23,3,LOG:1)
Block(-6,23,6,LOG:1)
Block(-6,24,-6,LOG:1)
Block(-6,24,-2,LOG:1)
Block(-6,24,6,LOG:1)
Block(-6,25,-6,LOG:1)
Block(-6,25,-2,LOG:1)
Block(-6,25,6,LOG:1)
Block(-6,26,-7,LOG:9)
Block(-6,26,-6,LOG:1)
Block(-6,26,-3,LOG:5)
Block(-6,26,-2,LOG:1)
Block(-6,26,-1,WOOD_STEP:13)
Block(-6,26,0,LOG:5)
Block(-6,26,1,LOG:5)
Block(-6,26,2,WOOD_STEP:13)
Block(-6,26,3,LOG:1)
Block(-6,26,6,LOG:1)
Block(-6,27,-6,LOG:1)
Block(-6,27,-2,LOG:1)
RandomBlock(-6,27,-1,emerald_ore,50,gold_ore,35,iron_ore,100)
RandomBlock(-6,27,0,minecraft:coal_ore,10,minecraft:iron_ore,10,biomesoplenty:gem_ore:1,10,biomesoplenty:gem_ore:2,10,biomesoplenty:gem_ore:3,10,biomesoplenty:gem_ore:4,10,biomesoplenty:gem_ore:5,10,iceandfire:sapphire_ore,10,biomesoplenty:gem_ore:7,10,biomesoplenty:gem_ore:0,10,minecraft:redstone_ore,20,minecraft:gold_ore,20,minecraft:lapis_ore,20,minecraft:diamond_ore,40,minecraft:emerald_ore,40,iceandfire:sapphire_ore,40,iceandfire:silver_ore,80,scalinghealth:crystalore,100)
RandomBlock(-6,27,1,minecraft:coal_ore,10,minecraft:iron_ore,10,biomesoplenty:gem_ore:1,10,biomesoplenty:gem_ore:2,10,biomesoplenty:gem_ore:3,10,biomesoplenty:gem_ore:4,10,biomesoplenty:gem_ore:5,10,iceandfire:sapphire_ore,10,biomesoplenty:gem_ore:7,10,biomesoplenty:gem_ore:0,10,minecraft:redstone_ore,20,minecraft:gold_ore,20,minecraft:lapis_ore,20,minecraft:diamond_ore,40,minecraft:emerald_ore,40,iceandfire:sapphire_ore,40,iceandfire:silver_ore,80,scalinghealth:crystalore,100)
RandomBlock(-6,27,2,minecraft:coal_ore,10,minecraft:iron_ore,10,biomesoplenty:gem_ore:1,10,biomesoplenty:gem_ore:2,10,biomesoplenty:gem_ore:3,10,biomesoplenty:gem_ore:4,10,biomesoplenty:gem_ore:5,10,iceandfire:sapphire_ore,10,biomesoplenty:gem_ore:7,10,biomesoplenty:gem_ore:0,10,minecraft:redstone_ore,20,minecraft:gold_ore,20,minecraft:lapis_ore,20,minecraft:diamond_ore,40,minecraft:emerald_ore,40,iceandfire:sapphire_ore,40,iceandfire:silver_ore,80,scalinghealth:crystalore,100)
Block(-6,27,3,WOOD_STEP:13)
Block(-6,27,6,LOG:1)
Block(-6,28,-6,LOG:1)
Block(-6,28,-2,LOG:1)
RandomBlock(-6,28,-1,emerald_ore,50,gold_ore,35,iron_ore,100)
Block(-6,28,0,AIR:0)
Block(-6,28,1,SKULL:1,../NBT/Trader_Swamp/213-skullC16R16.nbt)
RandomBlock(-6,28,2,variedcommodities:barrel:5,5,charm:barrel:5,../../../Chests/RLCraft/Containers/charm_barrel.nbt,100)
Block(-6,28,3,WOOD_STEP:13)
Block(-6,28,4,WALL_BANNER:3,../NBT/Trader_Swamp/215-bannerC16R16.nbt)
Block(-6,28,6,LOG:1)
Block(-6,29,-7,LOG:9)
Block(-6,29,-6,LOG:1)
Block(-6,29,-5,WOOD_STEP:9)
Block(-6,29,-4,WOOD_STEP:9)
Block(-6,29,-3,LOG:5)
Block(-6,29,-2,LOG:1)
Block(-6,29,-1,WOOD_STEP:9)
Block(-6,29,0,WOOD_STEP:9)
Block(-6,29,1,LOG:5)
Block(-6,29,2,WOOD_STEP:9)
Block(-6,29,3,LOG:1)
Block(-6,29,4,WOOD_STEP:9)
Block(-6,29,5,WOOD_STEP:9)
Block(-6,29,6,LOG:1)
Block(-6,29,7,LOG:9)
Block(-6,29,8,STONE_BUTTON:3)
Block(-6,30,-7,DARK_OAK_FENCE:0)
Block(-6,30,-6,LOG:1)
Block(-6,30,-5,SPRUCE_WOOD_STAIRS:1)
Block(-6,30,-4,SPRUCE_WOOD_STAIRS:1)
Block(-6,30,-3,LOG:1)
Block(-6,30,-1,AIR:0)
Block(-6,30,0,WOOD_STEP:9)
Block(-6,30,1,CARPET:0)
Block(-6,30,2,WORKBENCH:0,../NBT/Trader_Swamp/217-realbench_workbenchC16R16.nbt)
Block(-6,30,3,STONE:6)
Block(-6,30,4,FURNACE:4,../NBT/Trader_Swamp/218-furnaceC16R16.nbt)
Block(-6,30,5,FURNACE:4,../NBT/Trader_Swamp/219-furnaceC16R16.nbt)
Block(-6,30,6,LOG:1)
Block(-6,30,7,COBBLE_WALL:1)
Block(-6,31,-7,DARK_OAK_FENCE:0)
Block(-6,31,-6,LOG:1)
Block(-6,31,-5,SPRUCE_WOOD_STAIRS:5)
Block(-6,31,-4,SPRUCE_WOOD_STAIRS:5)
Block(-6,31,-3,LOG:1)
Block(-6,31,-2,AIR:0)
Block(-6,31,-1,AIR:0)
Block(-6,31,0,AIR:0)
Block(-6,31,1,variedcommodities:shelf:5,../NBT/Trader_Swamp/220-variedcommodities_shelfC16R16.nbt)
Block(-6,31,2,variedcommodities:shelf:5,../NBT/Trader_Swamp/221-variedcommodities_shelfC16R16.nbt)
Block(-6,31,3,COBBLE_WALL:0)
Block(-6,31,4,FURNACE:4,../NBT/Trader_Swamp/222-furnaceC16R16.nbt)
Block(-6,31,5,FURNACE:4,../NBT/Trader_Swamp/223-furnaceC16R16.nbt)
Block(-6,31,6,LOG:1)
Block(-6,31,7,DARK_OAK_FENCE:0)
Block(-6,32,-7,SPRUCE_WOOD_STAIRS:4)
Block(-6,32,-6,LOG:1)
Block(-6,32,-5,WOOD:1)
Block(-6,32,-4,WOOD:1)
Block(-6,32,-3,LOG:1)
Block(-6,32,-2,SPRUCE_WOOD_STAIRS:4)
Block(-6,32,-1,AIR:0)
Block(-6,32,0,IRON_FENCE:0)
Block(-6,32,1,rustic:evaporating_basin,../NBT/Trader_Swamp/224-rustic_tileentityevaporatingbasinC16R16.nbt)
Block(-6,32,2,quark:candle:15)
Block(-6,32,3,COBBLE_WALL:0)
RandomBlock(-6,32,4,STEP:3,75,QUARK:IRON_PLATE_SLAB:3,100)
RandomBlock(-6,32,5,STEP:3,75,QUARK:IRON_PLATE_SLAB:3,100)
Block(-6,32,6,LOG:1)
Block(-6,32,7,DARK_OAK_FENCE:0)
Block(-6,33,-7,SPRUCE_WOOD_STAIRS:1)
Block(-6,33,-6,LOG:1)
Block(-6,33,-5,SPRUCE_WOOD_STAIRS:1)
Block(-6,33,-4,SPRUCE_WOOD_STAIRS:1)
Block(-6,33,-3,LOG:1)
Block(-6,33,-2,SPRUCE_WOOD_STAIRS:1)
Block(-6,33,-1,WALL_BANNER:2,../NBT/Trader_Swamp/225-bannerC16R16.nbt)
Block(-6,33,0,WOOD_STEP:13)
Block(-6,33,1,AIR:0)
Block(-6,33,2,variedcommodities:sign:5,../NBT/Trader_Swamp/226-variedcommodities_signC16R16.nbt)
Block(-6,33,3,STONE:6)
Block(-6,33,4,AIR:0)
Block(-6,33,5,AIR:0)
Block(-6,33,6,LOG:1)
Block(-6,33,7,COBBLE_WALL:1)
Block(-6,34,-7,WOOD_STEP:9)
Block(-6,34,-6,LOG:1)
Block(-6,34,-5,WOOD_STEP:9)
Block(-6,34,-4,WOOD_STEP:9)
Block(-6,34,-3,LOG:5)
Block(-6,34,-2,WOOD_STEP:9)
Block(-6,34,-1,WOOD_STEP:9)
Block(-6,34,0,LOG:5)
Block(-6,34,1,WOOD_STEP:9)
Block(-6,34,2,WOOD_DOUBLE_STEP:1)
Block(-6,34,3,LOG:1)
Block(-6,34,4,WOOD_STEP:9)
Block(-6,34,5,WOOD_STEP:9)
Block(-6,34,6,LOG:1)
Block(-6,34,7,LOG:9)
Block(-6,34,8,STONE_BUTTON:3)
Block(-6,35,-7,WOOD_STEP:1)
Block(-6,35,-6,LOG:1)
Block(-6,35,-5,WORKBENCH:0,../NBT/Trader_Swamp/227-realbench_workbenchC16R16.nbt)
Block(-6,35,-4,rustic:barrel,../../../Chests/RLCraft/Containers/rustic_barrel.nbt)
Block(-6,35,-3,FURNACE:2,../NBT/Trader_Swamp/229-furnaceC16R16.nbt)
Block(-6,35,-2,variedcommodities:stool:5,../NBT/Trader_Swamp/230-variedcommodities_stoolC16R16.nbt)
Block(-6,35,-1,HAY_BLOCK:0)
RandomBlock(-6,35,0,variedcommodities:crate:1,5,charm:crate_sealed:1,../../../Chests/RLCraft/Containers/charm_villager_crate.nbt,10,charm:crate_sealed:1,../../../Chests/RLCraft/Containers/charm_villager_crate.nbt,100)
RandomBlock(-6,35,1,variedcommodities:crate:1,5,charm:crate_sealed:1,../../../Chests/RLCraft/Containers/charm_villager_crate.nbt,10,charm:crate_sealed:1,../../../Chests/RLCraft/Containers/charm_villager_crate.nbt,100)
Block(-6,35,2,variedcommodities:weapon_rack:5,../NBT/Trader_Swamp/233-variedcommodities_weapon_rackC16R16.nbt)
Block(-6,35,3,AIR:0)
Block(-6,35,4,AIR:0)
RandomBlock(-6,35,5,variedcommodities:crate:5,5,charm:crate_sealed:5,../../../Chests/RLCraft/Containers/charm_villager_crate.nbt,10,charm:crate_sealed:5,../../../Chests/RLCraft/Containers/charm_villager_crate.nbt,100)
Block(-6,35,6,LOG:1)
Block(-6,35,7,COBBLE_WALL:0)
Block(-6,36,-7,LOG:9)
Block(-6,36,-6,LOG:1)
Block(-6,36,-5,rustic:crushing_tub,../NBT/Trader_Swamp/235-rustic_tileentitycrushingtubC16R16.nbt)
Block(-6,36,-4,AIR:0)
Block(-6,36,-3,rustic:evaporating_basin,../NBT/Trader_Swamp/236-rustic_tileentityevaporatingbasinC16R16.nbt)
Block(-6,36,-2,AIR:0)
Block(-6,36,-1,AIR:0)
Block(-6,36,0,charm:iron_lantern)
RandomBlock(-6,36,1,variedcommodities:crate:5,5,charm:crate_sealed:5,../../../Chests/RLCraft/Containers/charm_villager_crate.nbt,10,charm:crate_sealed:5,../../../Chests/RLCraft/Containers/charm_villager_crate.nbt,100)
Block(-6,36,2,variedcommodities:weapon_rack:12)
Block(-6,36,3,AIR:0)
Block(-6,36,4,AIR:0)
Block(-6,36,5,inspirations:bookshelf:4,../NBT/Trader_Swamp/238-inspirations_bookshelfC16R16.nbt)
Block(-6,36,6,LOG:1)
Block(-6,36,7,WOOD_STEP:1)
Block(-6,37,-7,SPRUCE_WOOD_STAIRS:1)
Block(-6,37,-6,LOG:1)
Block(-6,37,-5,WOOD_STEP:9)
Block(-6,37,-4,AIR:0)
Block(-6,37,-3,IRON_FENCE:0)
Block(-6,37,-2,AIR:0)
Block(-6,37,-1,AIR:0)
Block(-6,37,0,AIR:0)
Block(-6,37,1,variedcommodities:shelf:5,../NBT/Trader_Swamp/240-variedcommodities_shelfC16R16.nbt)
Block(-6,37,2,variedcommodities:shelf:5,../NBT/Trader_Swamp/241-variedcommodities_shelfC16R16.nbt)
Block(-6,37,3,AIR:0)
Block(-6,37,4,WOOD_STEP:9)
Block(-6,37,5,WOOD_STEP:1)
Block(-6,37,6,STONE_BUTTON:5)
Block(-6,37,7,AIR:0)
Block(-6,38,-7,SPRUCE_WOOD_STAIRS:0)
Block(-6,38,-6,LOG:1)
Block(-6,38,-5,charm:crate_sealed:5,../../../Chests/RLCraft/Containers/charm_villager_crate.nbt)
Block(-6,38,-4,AIR:0)
Block(-6,38,-3,WOOD_STEP:9)
Block(-6,38,-2,WALL_BANNER:3,../NBT/Trader_Swamp/243-bannerC16R16.nbt)
Block(-6,38,-1,AIR:0)
Block(-6,38,0,WOOD_STEP:9)
Block(-6,38,1,WALL_BANNER:3,../NBT/Trader_Swamp/244-bannerC16R16.nbt)
Block(-6,38,2,charm:iron_lantern)
Block(-6,38,3,WOOD:1)
Block(-6,39,-7,WOOD:1)
Block(-6,39,-6,LOG:1)
Block(-6,39,-5,AIR:0)
Block(-6,39,-4,AIR:0)
Block(-6,39,-3,LOG:5)
Block(-6,39,-2,AIR:0)
Block(-6,39,-1,AIR:0)
Block(-6,39,0,LOG:5)
Block(-6,39,1,AIR:0)
Block(-6,39,2,AIR:0)
Block(-6,39,3,LOG:1)
Block(-6,39,4,WOOD_STEP:1)
Block(-6,40,-7,SPRUCE_WOOD_STAIRS:3)
Block(-6,40,-6,STONE_BUTTON:5)
Block(-6,40,-5,WOOD_STEP:1)
Block(-6,40,-4,WOOD_STEP:1)
Block(-6,40,-3,WOOD_STEP:9)
Block(-6,40,-2,WOOD_STEP:9)
Block(-6,40,-1,WOOD_STEP:9)
Block(-6,40,0,WOOD_STEP:9)
Block(-6,40,1,WOOD_STEP:1)
Block(-6,40,2,WOOD_STEP:1)
Block(-6,40,3,STONE_BUTTON:5)
Block(-5,0,-7,LOG:1)
Block(-5,0,-1,LOG:1)
Block(-5,0,4,LOG:1)
Block(-5,0,5,LOG:1)
Block(-5,1,-7,LOG:1)
Block(-5,1,-1,LOG:1)
Block(-5,1,4,LOG:1)
Block(-5,1,5,LOG:1)
Block(-5,2,-7,LOG:1)
Block(-5,2,-3,LOG:5)
Block(-5,2,-1,LOG:1)
Block(-5,2,0,LOG:5)
Block(-5,2,3,LOG:5)
Block(-5,2,4,LOG:1)
Block(-5,2,5,LOG:1)
Block(-5,3,-7,LOG:1)
Block(-5,3,-1,LOG:1)
Block(-5,3,4,LOG:1)
Block(-5,3,5,LOG:1)
Block(-5,4,-7,LOG:1)
Block(-5,4,-1,LOG:1)
Block(-5,4,4,LOG:1)
Block(-5,4,5,LOG:1)
Block(-5,5,-7,LOG:1)
Block(-5,5,-3,LOG:5)
Block(-5,5,-1,LOG:1)
Block(-5,5,0,LOG:5)
Block(-5,5,3,LOG:5)
Block(-5,5,4,LOG:1)
Block(-5,5,5,LOG:1)
Block(-5,6,-7,LOG:1)
Block(-5,6,-1,LOG:1)
Block(-5,6,4,LOG:1)
Block(-5,6,5,LOG:1)
Block(-5,7,-7,LOG:1)
Block(-5,7,-1,LOG:1)
Block(-5,7,4,LOG:1)
Block(-5,7,5,LOG:1)
Block(-5,8,-7,LOG:1)
Block(-5,8,-3,LOG:5)
Block(-5,8,-1,LOG:1)
Block(-5,8,0,LOG:5)
Block(-5,8,3,LOG:5)
Block(-5,8,4,LOG:1)
Block(-5,8,5,LOG:1)
Block(-5,9,-7,LOG:1)
Block(-5,9,-1,LOG:1)
Block(-5,9,4,LOG:1)
Block(-5,9,5,LOG:1)
Block(-5,10,-7,LOG:1)
Block(-5,10,-1,LOG:1)
Block(-5,10,4,LOG:1)
Block(-5,10,5,LOG:1)
Block(-5,11,-7,LOG:1)
Block(-5,11,-3,LOG:5)
Block(-5,11,-1,LOG:1)
Block(-5,11,0,LOG:5)
Block(-5,11,3,LOG:5)
Block(-5,11,4,LOG:1)
Block(-5,11,5,LOG:1)
Block(-5,12,-7,LOG:1)
Block(-5,12,-1,LOG:1)
Block(-5,12,4,LOG:1)
Block(-5,12,5,LOG:1)
Block(-5,13,-7,LOG:1)
Block(-5,13,-1,LOG:1)
Block(-5,13,4,LOG:1)
Block(-5,13,5,LOG:1)
Block(-5,14,-7,LOG:1)
Block(-5,14,-3,LOG:5)
Block(-5,14,-1,LOG:1)
Block(-5,14,0,LOG:5)
Block(-5,14,3,LOG:5)
Block(-5,14,4,LOG:1)
Block(-5,14,5,LOG:1)
Block(-5,15,-7,LOG:1)
Block(-5,15,-1,LOG:1)
Block(-5,15,4,LOG:1)
Block(-5,15,5,LOG:1)
Block(-5,16,-7,LOG:1)
Block(-5,16,-1,LOG:1)
Block(-5,16,4,LOG:1)
Block(-5,16,5,LOG:1)
Block(-5,17,-7,LOG:1)
Block(-5,17,-3,LOG:5)
Block(-5,17,-1,LOG:1)
Block(-5,17,0,LOG:5)
Block(-5,17,3,LOG:5)
Block(-5,17,4,LOG:1)
Block(-5,17,5,LOG:1)
Block(-5,18,-7,LOG:1)
Block(-5,18,-1,LOG:1)
Block(-5,18,4,LOG:1)
Block(-5,18,5,LOG:1)
Block(-5,19,-7,LOG:1)
Block(-5,19,-1,LOG:1)
Block(-5,19,4,LOG:1)
Block(-5,19,5,LOG:1)
Block(-5,20,-7,LOG:1)
Block(-5,20,-3,LOG:5)
Block(-5,20,-1,LOG:1)
Block(-5,20,0,LOG:5)
Block(-5,20,3,LOG:5)
Block(-5,20,4,LOG:1)
Block(-5,20,5,LOG:1)
Block(-5,21,-7,LOG:1)
Block(-5,21,-1,LOG:1)
Block(-5,21,4,LOG:1)
Block(-5,21,5,LOG:1)
Block(-5,22,-7,LOG:1)
Block(-5,22,-1,LOG:1)
Block(-5,22,4,LOG:1)
Block(-5,22,5,LOG:1)
Block(-5,23,-7,LOG:1)
Block(-5,23,-3,LOG:5)
Block(-5,23,-1,LOG:1)
Block(-5,23,0,LOG:5)
Block(-5,23,3,LOG:5)
Block(-5,23,4,LOG:1)
Block(-5,23,5,LOG:1)
Block(-5,24,-7,LOG:1)
Block(-5,24,-1,LOG:1)
Block(-5,24,4,LOG:1)
Block(-5,24,5,LOG:1)
Block(-5,25,-7,LOG:1)
Block(-5,25,-1,LOG:1)
Block(-5,25,4,LOG:1)
Block(-5,25,5,LOG:1)
Block(-5,26,-7,LOG:1)
Block(-5,26,-3,LOG:5)
Block(-5,26,-1,LOG:1)
Block(-5,26,0,LOG:5)
Block(-5,26,1,LOG:5)
Block(-5,26,2,WOOD_STEP:13)
Block(-5,26,3,LOG:5)
Block(-5,26,4,LOG:1)
Block(-5,26,5,LOG:1)
Block(-5,27,-7,LOG:1)
Block(-5,27,-1,LOG:1)
Block(-5,27,0,GOLD_BLOCK:0)
RandomBlock(-5,27,1,minecraft:coal_ore,10,minecraft:iron_ore,10,biomesoplenty:gem_ore:1,10,biomesoplenty:gem_ore:2,10,biomesoplenty:gem_ore:3,10,biomesoplenty:gem_ore:4,10,biomesoplenty:gem_ore:5,10,iceandfire:sapphire_ore,10,biomesoplenty:gem_ore:7,10,biomesoplenty:gem_ore:0,10,minecraft:redstone_ore,20,minecraft:gold_ore,20,minecraft:lapis_ore,20,minecraft:diamond_ore,40,minecraft:emerald_ore,40,iceandfire:sapphire_ore,40,iceandfire:silver_ore,80,scalinghealth:crystalore,100)
RandomBlock(-5,27,2,emerald_ore,50,gold_ore,35,iron_ore,100)
Block(-5,27,3,WOOD_STEP:13)
Block(-5,27,4,LOG:1)
Block(-5,27,5,LOG:1)
Block(-5,28,-7,LOG:1)
Block(-5,28,-1,LOG:1)
RandomBlock(-5,28,0,AIR:0,30,CHEST:4,../../../Chests/Loot/junk_loot.nbt,10,CHEST:4,../../../Chests/Lore/gemtraderswamp.nbt,10,CHEST:4,../../../Chests/Loot/village_blacksmith.nbt,10,CHEST:4,../../../Chests/Loot/spawn_bonus_chest.nbt,10,CHEST:4,../../../Chests/Loot/rare_loot.nbt,5,CHEST:4,../../../Chests/Loot/gem_loot.nbt,3,CHEST:4,../../../Chests/Loot/junk_loot.nbt,50,CHEST:4,../../../Chests/Loot/gem_loot.nbt,5,CHEST:4,../../../Chests/Loot/common_loot.nbt,100)
Block(-5,28,1,charm:ender_pearl_block)
Block(-5,28,2,charm:nether_gold_deposit)
Block(-5,28,3,WOOD_STEP:13)
Block(-5,28,4,LOG:1)
Block(-5,28,5,LOG:1)
Block(-5,29,-7,LOG:1)
Block(-5,29,-6,WOOD_STEP:9)
Block(-5,29,-5,WOOD_STEP:9)
Block(-5,29,-4,WOOD_STEP:9)
Block(-5,29,-3,LOG:5)
Block(-5,29,-2,WOOD_STEP:9)
Block(-5,29,-1,LOG:1)
Block(-5,29,0,LOG:9)
Block(-5,29,1,LOG:5)
Block(-5,29,2,WOOD_STEP:9)
Block(-5,29,3,LOG:5)
Block(-5,29,4,LOG:1)
Block(-5,29,5,LOG:1)
Block(-5,29,6,WOOD_STEP:9)
Block(-5,29,7,WOOD_STEP:9)
Block(-5,30,-7,LOG:1)
RandomBlock(-5,30,-6,minecraft:coal_ore,10,minecraft:iron_ore,10,biomesoplenty:gem_ore:1,10,biomesoplenty:gem_ore:2,10,biomesoplenty:gem_ore:3,10,biomesoplenty:gem_ore:4,10,biomesoplenty:gem_ore:5,10,iceandfire:sapphire_ore,10,biomesoplenty:gem_ore:7,10,biomesoplenty:gem_ore:0,10,minecraft:redstone_ore,20,minecraft:gold_ore,20,minecraft:lapis_ore,20,minecraft:diamond_ore,40,minecraft:emerald_ore,40,iceandfire:sapphire_ore,40,iceandfire:silver_ore,80,scalinghealth:crystalore,100)
Block(-5,30,-5,ANVIL:10)
Block(-5,30,-4,WORKBENCH:0,../NBT/Trader_Swamp/252-realbench_workbenchC16R16.nbt)
Block(-5,30,-3,SPRUCE_WOOD_STAIRS:5)
Block(-5,30,-2,AIR:0)
Block(-5,30,-1,AIR:0)
Block(-5,30,0,WOOD_STEP:9)
Block(-5,30,1,variedcommodities:stool:5,../NBT/Trader_Swamp/253-variedcommodities_stoolC16R16.nbt)
Block(-5,30,3,rustic:liquid_barrel,../NBT/Trader_Swamp/254-rustic_tileentityliquidbarrelC16R16.nbt)
Block(-5,30,4,LOG:1)
Block(-5,30,5,LOG:1)
Block(-5,30,6,DARK_OAK_FENCE:0)
Block(-5,30,7,DARK_OAK_FENCE:0)
Block(-5,31,-7,LOG:1)
RandomBlock(-5,31,-6,minecraft:coal_ore,10,minecraft:iron_ore,10,biomesoplenty:gem_ore:1,10,biomesoplenty:gem_ore:2,10,biomesoplenty:gem_ore:3,10,biomesoplenty:gem_ore:4,10,biomesoplenty:gem_ore:5,10,iceandfire:sapphire_ore,10,biomesoplenty:gem_ore:7,10,biomesoplenty:gem_ore:0,10,minecraft:redstone_ore,20,minecraft:gold_ore,20,minecraft:lapis_ore,20,minecraft:diamond_ore,40,minecraft:emerald_ore,40,iceandfire:sapphire_ore,40,iceandfire:silver_ore,80,scalinghealth:crystalore,100)
Block(-5,31,-5,SMOOTH_BRICK:3)
Block(-5,31,-4,AIR:0)
Block(-5,31,-3,variedcommodities:sign:5,../NBT/Trader_Swamp/258-variedcommodities_signC16R16.nbt)
Block(-5,31,-2,AIR:0)
Block(-5,31,-1,AIR:0)
Block(-5,31,0,variedcommodities:book,../NBT/Trader_Swamp/259-variedcommodities_bookC16R16.nbt)
Block(-5,31,1,AIR:0)
Block(-5,31,2,AIR:0)
Block(-5,31,3,variedcommodities:shelf:5,../NBT/Trader_Swamp/260-variedcommodities_shelfC16R16.nbt)
Block(-5,31,4,LOG:1)
Block(-5,31,5,LOG:1)
Block(-5,31,6,AIR:0)
Block(-5,31,7,AIR:0)
Block(-5,32,-7,LOG:1)
Block(-5,32,-6,SPRUCE_WOOD_STAIRS:1)
Block(-5,32,-5,SPRUCE_WOOD_STAIRS:1)
Block(-5,32,-4,SPRUCE_WOOD_STAIRS:1)
Block(-5,32,-3,SPRUCE_WOOD_STAIRS:1)
Block(-5,32,-2,SPRUCE_WOOD_STAIRS:1)
Block(-5,32,-1,AIR:0)
Block(-5,32,0,IRON_FENCE:0)
Block(-5,32,1,AIR:0)
Block(-5,32,2,AIR:0)
Block(-5,32,3,charm:iron_lantern)
Block(-5,32,4,LOG:1)
Block(-5,32,5,LOG:1)
Block(-5,32,6,AIR:0)
Block(-5,32,7,AIR:0)
Block(-5,33,-7,LOG:1)
Block(-5,33,-6,AIR:0)
Block(-5,33,-5,AIR:0)
Block(-5,33,-4,AIR:0)
Block(-5,33,-3,WOOD_STEP:13)
Block(-5,33,-2,WALL_BANNER:3,../NBT/Trader_Swamp/262-bannerC16R16.nbt)
Block(-5,33,-1,WALL_BANNER:2,../NBT/Trader_Swamp/263-bannerC16R16.nbt)
Block(-5,33,0,WOOD_STEP:13)
Block(-5,33,1,AIR:0)
Block(-5,33,2,AIR:0)
Block(-5,33,3,variedcommodities:sign:5,../NBT/Trader_Swamp/264-variedcommodities_signC16R16.nbt)
Block(-5,33,4,LOG:1)
Block(-5,33,5,LOG:1)
Block(-5,33,6,AIR:0)
Block(-5,33,7,AIR:0)
Block(-5,34,-7,LOG:1)
Block(-5,34,-6,WOOD_STEP:9)
Block(-5,34,-5,WOOD_STEP:9)
Block(-5,34,-4,WOOD_STEP:9)
Block(-5,34,-3,LOG:5)
Block(-5,34,-2,WOOD_STEP:9)
Block(-5,34,-1,WOOD_STEP:9)
Block(-5,34,0,LOG:5)
Block(-5,34,1,WOOD_STEP:9)
Block(-5,34,2,WOOD_STEP:9)
Block(-5,34,3,WOOD_DOUBLE_STEP:1)
Block(-5,34,4,LOG:1)
Block(-5,34,5,LOG:1)
Block(-5,34,6,WOOD_STEP:9)
Block(-5,34,7,WOOD_STEP:9)
Block(-5,35,-7,LOG:1)
Block(-5,35,-6,PUMPKIN:2)
Block(-5,35,-4,variedcommodities:stool:1,../NBT/Trader_Swamp/265-variedcommodities_stoolC16R16.nbt)
Block(-5,35,-3,FURNACE:2,../NBT/Trader_Swamp/266-furnaceC16R16.nbt)
Block(-5,35,-2,AIR:0)
Block(-5,35,-1,AIR:0)
Block(-5,35,0,AIR:0)
Block(-5,35,2,AIR:0)
Block(-5,35,3,AIR:0)
Block(-5,35,4,LOG:1)
Block(-5,35,5,LOG:1)
Block(-5,35,6,DARK_OAK_FENCE:0)
Block(-5,35,7,DARK_OAK_FENCE:0)
Block(-5,36,-7,LOG:1)
Block(-5,36,-6,MELON_BLOCK:0)
Block(-5,36,-5,AIR:0)
Block(-5,36,-4,AIR:0)
Block(-5,36,-3,rustic:evaporating_basin,../NBT/Trader_Swamp/267-rustic_tileentityevaporatingbasinC16R16.nbt)
Block(-5,36,-2,AIR:0)
Block(-5,36,-1,AIR:0)
Block(-5,36,0,AIR:0)
Block(-5,36,1,AIR:0)
Block(-5,36,2,AIR:0)
Block(-5,36,3,AIR:0)
Block(-5,36,4,LOG:1)
Block(-5,36,5,LOG:1)
Block(-5,36,6,WOOD_STEP:1)
Block(-5,36,7,AIR:0)
Block(-5,37,-7,LOG:1)
Block(-5,37,-6,WOOD_STEP:9)
Block(-5,37,-5,variedcommodities:sign:5,../NBT/Trader_Swamp/270-variedcommodities_signC16R16.nbt)
Block(-5,37,-4,AIR:0)
Block(-5,37,-3,IRON_FENCE:0)
Block(-5,37,-2,AIR:0)
Block(-5,37,-1,AIR:0)
Block(-5,37,0,AIR:0)
Block(-5,37,1,AIR:0)
Block(-5,37,2,AIR:0)
Block(-5,37,3,variedcommodities:shelf:5,../NBT/Trader_Swamp/271-variedcommodities_shelfC16R16.nbt)
Block(-5,37,4,LOG:1)
Block(-5,37,5,STONE_BUTTON:5)
Block(-5,37,6,AIR:0)
Block(-5,37,7,AIR:0)
Block(-5,38,-7,LOG:1)
RandomBlock(-5,38,-6,AIR:0,30,CHEST:5,../../../Chests/Loot/junk_loot.nbt,10,CHEST:5,../../../Chests/Lore/gemtraderswamp.nbt,10,CHEST:5,../../../Chests/Loot/village_blacksmith.nbt,10,CHEST:5,../../../Chests/Loot/spawn_bonus_chest.nbt,10,CHEST:5,../../../Chests/Loot/rare_loot.nbt,5,CHEST:5,../../../Chests/Loot/gem_loot.nbt,3,CHEST:5,../../../Chests/Loot/junk_loot.nbt,50,CHEST:5,../../../Chests/Loot/gem_loot.nbt,5,CHEST:5,../../../Chests/Loot/common_loot.nbt,100)
Block(-5,38,-5,AIR:0)
Block(-5,38,-4,AIR:0)
Block(-5,38,-3,WOOD_STEP:9)
Block(-5,38,-2,WALL_BANNER:3,../NBT/Trader_Swamp/273-bannerC16R16.nbt)
Block(-5,38,-1,AIR:0)
Block(-5,38,0,WOOD_STEP:9)
Block(-5,38,1,WALL_BANNER:3,../NBT/Trader_Swamp/274-bannerC16R16.nbt)
Block(-5,38,2,AIR:0)
Block(-5,38,3,charm:barrel:1,../../../Chests/RLCraft/Containers/charm_barrel.nbt)
Block(-5,38,4,LOG:1)
Block(-5,39,-7,LOG:1)
Block(-5,39,-6,AIR:0)
Block(-5,39,-5,AIR:0)
Block(-5,39,-4,AIR:0)
Block(-5,39,-3,LOG:5)
Block(-5,39,-2,AIR:0)
Block(-5,39,-1,AIR:0)
Block(-5,39,0,LOG:5)
Block(-5,39,1,AIR:0)
Block(-5,39,2,AIR:0)
Block(-5,39,3,AIR:0)
Block(-5,39,4,LOG:1)
Block(-5,39,5,WOOD_STEP:1)
Block(-5,40,-7,SPRUCE_WOOD_STAIRS:3)
Block(-5,40,-6,WOOD_STEP:1)
Block(-5,40,-5,WOOD_STEP:9)
Block(-5,40,-4,WOOD_STEP:9)
Block(-5,40,-3,rustic:iron_lattice:0)
Block(-5,40,-2,AIR:0)
Block(-5,40,-1,AIR:0)
Block(-5,40,0,rustic:iron_lattice:0)
Block(-5,40,1,WOOD_STEP:9)
Block(-5,40,2,WOOD_STEP:9)
Block(-5,40,3,WOOD_STEP:1)
Block(-5,40,4,STONE_BUTTON:5)
Block(-5,41,-3,WOOD_STEP:1)
Block(-5,41,-2,WOOD_STEP:1)
Block(-5,41,-1,WOOD_STEP:1)
Block(-5,41,0,WOOD_STEP:1)
Block(-4,0,1,LOG:1)
Block(-4,0,3,LOG:1)
Block(-4,1,1,LOG:1)
Block(-4,1,3,LOG:1)
Block(-4,2,-7,LOG:5)
Block(-4,2,-3,LOG:5)
Block(-4,2,0,LOG:5)
Block(-4,2,1,LOG:1)
Block(-4,2,2,LOG:9)
Block(-4,2,3,LOG:1)
Block(-4,2,4,LOG:5)
Block(-4,3,1,LOG:1)
Block(-4,3,3,LOG:1)
Block(-4,4,1,LOG:1)
Block(-4,4,3,LOG:1)
Block(-4,5,-7,LOG:5)
Block(-4,5,-3,LOG:5)
Block(-4,5,0,LOG:5)
Block(-4,5,1,LOG:1)
Block(-4,5,2,LOG:9)
Block(-4,5,3,LOG:1)
Block(-4,5,4,LOG:5)
Block(-4,6,1,LOG:1)
Block(-4,6,3,LOG:1)
Block(-4,7,1,LOG:1)
Block(-4,7,3,LOG:1)
Block(-4,8,-7,LOG:5)
Block(-4,8,-3,LOG:5)
Block(-4,8,0,LOG:5)
Block(-4,8,1,LOG:1)
Block(-4,8,2,LOG:9)
Block(-4,8,3,LOG:1)
Block(-4,8,4,LOG:5)
Block(-4,9,1,LOG:1)
Block(-4,9,3,LOG:1)
Block(-4,10,1,LOG:1)
Block(-4,10,3,LOG:1)
Block(-4,11,-7,LOG:5)
Block(-4,11,-3,LOG:5)
Block(-4,11,0,LOG:5)
Block(-4,11,1,LOG:1)
Block(-4,11,2,LOG:9)
Block(-4,11,3,LOG:1)
Block(-4,11,4,LOG:5)
Block(-4,12,1,LOG:1)
Block(-4,12,3,LOG:1)
Block(-4,13,1,LOG:1)
Block(-4,13,3,LOG:1)
Block(-4,14,-7,LOG:5)
Block(-4,14,-3,LOG:5)
Block(-4,14,0,LOG:5)
Block(-4,14,1,LOG:1)
Block(-4,14,2,LOG:9)
Block(-4,14,3,LOG:1)
Block(-4,14,4,LOG:5)
Block(-4,15,1,LOG:1)
Block(-4,15,3,LOG:1)
Block(-4,16,1,LOG:1)
Block(-4,16,3,LOG:1)
Block(-4,17,-7,LOG:5)
Block(-4,17,-3,LOG:5)
Block(-4,17,0,LOG:5)
Block(-4,17,1,LOG:1)
Block(-4,17,2,LOG:9)
Block(-4,17,3,LOG:1)
Block(-4,17,4,LOG:5)
Block(-4,18,1,LOG:1)
Block(-4,18,3,LOG:1)
Block(-4,19,1,LOG:1)
Block(-4,19,3,LOG:1)
Block(-4,20,-7,LOG:5)
Block(-4,20,-3,LOG:5)
Block(-4,20,0,LOG:5)
Block(-4,20,1,LOG:1)
Block(-4,20,2,LOG:9)
Block(-4,20,3,LOG:1)
Block(-4,20,4,LOG:5)
Block(-4,21,1,LOG:1)
Block(-4,21,3,LOG:1)
Block(-4,22,1,LOG:1)
Block(-4,22,3,LOG:1)
Block(-4,23,-7,LOG:5)
Block(-4,23,-3,LOG:5)
Block(-4,23,0,LOG:5)
Block(-4,23,1,LOG:1)
Block(-4,23,2,LOG:9)
Block(-4,23,3,LOG:1)
Block(-4,23,4,LOG:5)
Block(-4,24,1,LOG:1)
Block(-4,24,3,LOG:1)
Block(-4,25,1,LOG:1)
Block(-4,25,3,LOG:1)
Block(-4,26,-7,LOG:5)
Block(-4,26,-3,LOG:5)
Block(-4,26,0,LOG:5)
Block(-4,26,1,LOG:1)
Block(-4,26,2,LOG:9)
Block(-4,26,3,LOG:1)
Block(-4,26,4,LOG:5)
Block(-4,27,0,WOOD_STEP:13)
Block(-4,27,1,LOG:1)
Block(-4,27,2,WOOD_STEP:13)
Block(-4,27,3,LOG:1)
Block(-4,28,-1,WALL_BANNER:2,../NBT/Trader_Swamp/277-bannerC16R16.nbt)
Block(-4,28,0,WOOD_STEP:13)
Block(-4,28,1,LOG:1)
Block(-4,28,2,WOOD_STEP:13)
Block(-4,28,3,LOG:1)
Block(-4,29,-7,LOG:5)
Block(-4,29,-6,WOOD_STEP:9)
Block(-4,29,-5,WOOD_STEP:9)
Block(-4,29,-4,WOOD_STEP:9)
Block(-4,29,-3,LOG:5)
Block(-4,29,-2,WOOD_STEP:9)
Block(-4,29,-1,WOOD_STEP:9)
Block(-4,29,0,LOG:5)
Block(-4,29,1,LOG:1)
Block(-4,29,2,LOG:9)
Block(-4,29,3,LOG:1)
Block(-4,29,4,LOG:5)
Block(-4,29,5,LOG:5)
Block(-4,29,6,WOOD_STEP:9)
Block(-4,30,-7,WOOD:1)
Block(-4,30,-5,CARPET:0)
Block(-4,30,-4,CARPET:5)
Block(-4,30,-3,SPRUCE_WOOD_STAIRS:4)
Block(-4,30,-2,AIR:0)
Block(-4,30,-1,AIR:0)
Block(-4,30,0,SPRUCE_WOOD_STAIRS:4)
Block(-4,30,1,CAULDRON:3,../NBT/Trader_Swamp/281-inspirations_cauldronC16R16.nbt)
Block(-4,30,2,CARPET:11)
Block(-4,30,3,CARPET:0)
Block(-4,30,4,WOOD:1)
Block(-4,30,5,AIR:0)
Block(-4,30,6,DARK_OAK_FENCE:0)
Block(-4,30,7,AIR:0)
Block(-4,31,-7,WOOD:5)
Block(-4,31,-6,AIR:0)
Block(-4,31,-5,AIR:0)
Block(-4,31,-4,AIR:0)
Block(-4,31,-3,AIR:0)
Block(-4,31,-1,AIR:0)
Block(-4,31,0,charm:iron_lantern)
Block(-4,31,1,AIR:0)
Block(-4,31,2,AIR:0)
#Block(-4,31,3,AIR:0)
Block(-4,31,4,WOOD:5)
Block(-4,31,5,AIR:0)
Block(-4,31,6,AIR:0)
Block(-4,31,7,AIR:0)
Block(-4,32,-7,WOOD:5)
Block(-4,32,-6,AIR:0)
Block(-4,32,-5,AIR:0)
Block(-4,32,-4,AIR:0)
Block(-4,32,-3,IRON_FENCE:0)
Block(-4,32,-2,AIR:0)
Block(-4,32,-1,AIR:0)
Block(-4,32,0,IRON_FENCE:0)
Block(-4,32,1,AIR:0)
Block(-4,32,2,AIR:0)
Block(-4,32,3,AIR:0)
Block(-4,32,4,WOOD:5)
Block(-4,32,5,AIR:0)
Block(-4,32,6,AIR:0)
Block(-4,32,7,AIR:0)
Block(-4,33,-7,WOOD:1)
Block(-4,33,-6,AIR:0)
Block(-4,33,-5,AIR:0)
Block(-4,33,-4,AIR:0)
Block(-4,33,-3,WOOD_STEP:13)
Block(-4,33,-2,WALL_BANNER:3,../NBT/Trader_Swamp/284-bannerC16R16.nbt)
Block(-4,33,-1,WALL_BANNER:2,../NBT/Trader_Swamp/285-bannerC16R16.nbt)
Block(-4,33,0,WOOD_STEP:13)
Block(-4,33,1,AIR:0)
Block(-4,33,2,AIR:0)
Block(-4,33,3,AIR:0)
Block(-4,33,4,WOOD:1)
Block(-4,33,5,AIR:0)
Block(-4,33,6,AIR:0)
Block(-4,33,7,AIR:0)
Block(-4,34,-7,LOG:5)
Block(-4,34,-6,WOOD_STEP:9)
Block(-4,34,-5,WOOD_STEP:9)
Block(-4,34,-4,WOOD_STEP:9)
Block(-4,34,-3,LOG:5)
Block(-4,34,-2,WOOD_STEP:9)
Block(-4,34,-1,WOOD_STEP:9)
Block(-4,34,0,LOG:5)
Block(-4,34,1,WOOD_STEP:9)
Block(-4,34,2,WOOD_STEP:9)
Block(-4,34,3,WOOD_STEP:9)
Block(-4,34,4,LOG:5)
Block(-4,34,5,LOG:5)
Block(-4,34,6,WOOD_STEP:9)
Block(-4,34,7,AIR:0)
Block(-4,35,-7,WOOD:1)
Block(-4,35,-6,LADDER:3)
Block(-4,35,-5,AIR:0)
Block(-4,35,-4,HAY_BLOCK:8)
Block(-4,35,-3,SPRUCE_WOOD_STAIRS:4)
Block(-4,35,-1,AIR:0)
Block(-4,35,0,AIR:0)
Block(-4,35,1,AIR:0)
Block(-4,35,2,AIR:0)
Block(-4,35,3,AIR:0)
Block(-4,35,4,WOOD:1)
Block(-4,35,5,COBBLE_WALL:0)
Block(-4,35,6,DARK_OAK_FENCE:0)
Block(-4,35,7,AIR:0)
Block(-4,36,-7,DARK_OAK_STAIRS:0)
Block(-4,36,-6,LADDER:3)
Block(-4,36,-5,AIR:0)
Block(-4,36,-4,iceandfire:goldpile)
Block(-4,36,-3,FLOWER_POT:0,../NBT/Trader_Swamp/286-flower_potC16R16.nbt)
Block(-4,36,-2,AIR:0)
Block(-4,36,-1,AIR:0)
Block(-4,36,0,AIR:0)
Block(-4,36,1,AIR:0)
Block(-4,36,2,AIR:0)
Block(-4,36,3,AIR:0)
Block(-4,36,4,DARK_OAK_STAIRS:0)
Block(-4,36,5,WOOD_STEP:1)
Block(-4,36,6,AIR:0)
Block(-4,36,7,AIR:0)
Block(-4,37,-7,DARK_OAK_STAIRS:4)
Block(-4,37,-6,AIR:0)
Block(-4,37,-5,AIR:0)
Block(-4,37,-4,AIR:0)
Block(-4,37,-3,IRON_FENCE:0)
Block(-4,37,-2,AIR:0)
Block(-4,37,-1,AIR:0)
Block(-4,37,0,AIR:0)
Block(-4,37,1,AIR:0)
Block(-4,37,2,AIR:0)
Block(-4,37,3,variedcommodities:shelf:5,../NBT/Trader_Swamp/290-variedcommodities_shelfC16R16.nbt)
Block(-4,37,4,DARK_OAK_STAIRS:4)
Block(-4,37,5,AIR:0)
Block(-4,37,6,AIR:0)
Block(-4,37,7,AIR:0)
Block(-4,38,-7,WOOD:1)
Block(-4,38,-6,AIR:0)
Block(-4,38,-5,AIR:0)
Block(-4,38,-4,AIR:0)
Block(-4,38,-3,WOOD_STEP:9)
Block(-4,38,-2,WALL_BANNER:3,../NBT/Trader_Swamp/291-bannerC16R16.nbt)
Block(-4,38,-1,AIR:0)
Block(-4,38,0,WOOD_STEP:9)
Block(-4,38,1,WALL_BANNER:3,../NBT/Trader_Swamp/292-bannerC16R16.nbt)
Block(-4,38,2,AIR:0)
Block(-4,38,3,rustic:crushing_tub,../NBT/Trader_Swamp/293-rustic_tileentitycrushingtubC16R16.nbt)
Block(-4,38,4,WOOD:1)
Block(-4,38,5,inspirations:rope)
Block(-4,39,-7,LOG:5)
Block(-4,39,-6,AIR:0)
Block(-4,39,-5,AIR:0)
Block(-4,39,-4,AIR:0)
Block(-4,39,-3,LOG:5)
Block(-4,39,-2,AIR:0)
Block(-4,39,-1,AIR:0)
Block(-4,39,0,LOG:5)
Block(-4,39,1,AIR:0)
Block(-4,39,2,AIR:0)
Block(-4,39,3,AIR:0)
Block(-4,39,4,LOG:5)
Block(-4,39,5,WOOD_STEP:1)
Block(-4,40,-6,WOOD_STEP:1)
Block(-4,40,-5,WOOD_STEP:9)
Block(-4,40,-4,charm:iron_lantern:1)
Block(-4,40,-3,rustic:iron_lattice:0)
Block(-4,40,-2,AIR:0)
Block(-4,40,-1,AIR:0)
Block(-4,40,0,rustic:iron_lattice:0)
Block(-4,40,1,charm:iron_lantern:1)
Block(-4,40,2,WOOD_STEP:9)
Block(-4,40,3,WOOD_STEP:1)
Block(-4,41,-4,WOOD_STEP:1)
Block(-4,41,-3,WOOD_STEP:1)
Block(-4,41,-2,WOOD_STEP:9)
Block(-4,41,-1,WOOD_STEP:9)
Block(-4,41,0,WOOD_STEP:1)
Block(-4,41,1,WOOD_STEP:1)
Block(-3,0,-3,LOG:1)
Block(-3,0,0,LOG:1)
Block(-3,0,5,LOG:1)
Block(-3,1,-3,LOG:1)
Block(-3,1,0,LOG:1)
Block(-3,1,5,LOG:1)
Block(-3,2,-7,LOG:9)
Block(-3,2,-6,LOG:9)
Block(-3,2,-5,LOG:9)
Block(-3,2,-4,LOG:9)
Block(-3,2,-3,LOG:1)
Block(-3,2,-2,LOG:9)
Block(-3,2,-1,LOG:9)
Block(-3,2,0,LOG:1)
Block(-3,2,1,LOG:9)
Block(-3,2,2,LOG:9)
Block(-3,2,3,LOG:9)
Block(-3,2,4,LOG:9)
Block(-3,2,5,LOG:1)
Block(-3,3,-3,LOG:1)
Block(-3,3,0,LOG:1)
Block(-3,3,5,LOG:1)
Block(-3,4,-3,LOG:1)
Block(-3,4,0,LOG:1)
Block(-3,4,5,LOG:1)
Block(-3,5,-7,LOG:9)
Block(-3,5,-6,LOG:9)
Block(-3,5,-5,LOG:9)
Block(-3,5,-4,LOG:9)
Block(-3,5,-3,LOG:1)
Block(-3,5,-2,LOG:9)
Block(-3,5,-1,LOG:9)
Block(-3,5,0,LOG:1)
Block(-3,5,1,LOG:9)
Block(-3,5,2,LOG:9)
Block(-3,5,3,LOG:9)
Block(-3,5,4,LOG:9)
Block(-3,5,5,LOG:1)
Block(-3,6,-3,LOG:1)
Block(-3,6,0,LOG:1)
Block(-3,6,5,LOG:1)
Block(-3,7,-3,LOG:1)
Block(-3,7,0,LOG:1)
Block(-3,7,5,LOG:1)
Block(-3,8,-7,LOG:9)
Block(-3,8,-6,LOG:9)
Block(-3,8,-5,LOG:9)
Block(-3,8,-4,LOG:9)
Block(-3,8,-3,LOG:1)
Block(-3,8,-2,LOG:9)
Block(-3,8,-1,LOG:9)
Block(-3,8,0,LOG:1)
Block(-3,8,1,LOG:9)
Block(-3,8,2,LOG:9)
Block(-3,8,3,LOG:9)
Block(-3,8,4,LOG:9)
Block(-3,8,5,LOG:1)
Block(-3,9,-3,LOG:1)
Block(-3,9,0,LOG:1)
Block(-3,9,5,LOG:1)
Block(-3,10,-3,LOG:1)
Block(-3,10,0,LOG:1)
Block(-3,10,5,LOG:1)
Block(-3,11,-7,LOG:9)
Block(-3,11,-6,LOG:9)
Block(-3,11,-5,LOG:9)
Block(-3,11,-4,LOG:9)
Block(-3,11,-3,LOG:1)
Block(-3,11,-2,LOG:9)
Block(-3,11,-1,LOG:9)
Block(-3,11,0,LOG:1)
Block(-3,11,1,LOG:9)
Block(-3,11,2,LOG:9)
Block(-3,11,3,LOG:9)
Block(-3,11,4,LOG:9)
Block(-3,11,5,LOG:1)
Block(-3,12,-3,LOG:1)
Block(-3,12,0,LOG:1)
Block(-3,12,5,LOG:1)
Block(-3,13,-3,LOG:1)
Block(-3,13,0,LOG:1)
Block(-3,13,5,LOG:1)
Block(-3,14,-7,LOG:9)
Block(-3,14,-6,LOG:9)
Block(-3,14,-5,LOG:9)
Block(-3,14,-4,LOG:9)
Block(-3,14,-3,LOG:1)
Block(-3,14,-2,LOG:9)
Block(-3,14,-1,LOG:9)
Block(-3,14,0,LOG:1)
Block(-3,14,1,LOG:9)
Block(-3,14,2,LOG:9)
Block(-3,14,3,LOG:9)
Block(-3,14,4,LOG:9)
Block(-3,14,5,LOG:1)
Block(-3,15,-3,LOG:1)
Block(-3,15,0,LOG:1)
Block(-3,15,5,LOG:1)
Block(-3,16,-3,LOG:1)
Block(-3,16,0,LOG:1)
Block(-3,16,5,LOG:1)
Block(-3,17,-7,LOG:9)
Block(-3,17,-6,LOG:9)
Block(-3,17,-5,LOG:9)
Block(-3,17,-4,LOG:9)
Block(-3,17,-3,LOG:1)
Block(-3,17,-2,LOG:9)
Block(-3,17,-1,LOG:9)
Block(-3,17,0,LOG:1)
Block(-3,17,1,LOG:9)
Block(-3,17,2,LOG:9)
Block(-3,17,3,LOG:9)
Block(-3,17,4,LOG:9)
Block(-3,17,5,LOG:1)
Block(-3,18,-3,LOG:1)
Block(-3,18,0,LOG:1)
Block(-3,18,5,LOG:1)
Block(-3,19,-3,LOG:1)
Block(-3,19,0,LOG:1)
Block(-3,19,5,LOG:1)
Block(-3,20,-7,LOG:9)
Block(-3,20,-6,LOG:9)
Block(-3,20,-5,LOG:9)
Block(-3,20,-4,LOG:9)
Block(-3,20,-3,LOG:1)
Block(-3,20,-2,LOG:9)
Block(-3,20,-1,LOG:9)
Block(-3,20,0,LOG:1)
Block(-3,20,1,LOG:9)
Block(-3,20,2,LOG:9)
Block(-3,20,3,LOG:9)
Block(-3,20,4,LOG:9)
Block(-3,20,5,LOG:1)
Block(-3,21,-3,LOG:1)
Block(-3,21,0,LOG:1)
Block(-3,21,5,LOG:1)
Block(-3,22,-3,LOG:1)
Block(-3,22,0,LOG:1)
Block(-3,22,5,LOG:1)
Block(-3,23,-7,LOG:9)
Block(-3,23,-6,LOG:9)
Block(-3,23,-5,LOG:9)
Block(-3,23,-4,LOG:9)
Block(-3,23,-3,LOG:1)
Block(-3,23,-2,LOG:9)
Block(-3,23,-1,LOG:9)
Block(-3,23,0,LOG:1)
Block(-3,23,1,LOG:9)
Block(-3,23,2,LOG:9)
Block(-3,23,3,LOG:9)
Block(-3,23,4,LOG:9)
Block(-3,23,5,LOG:1)
Block(-3,24,-3,LOG:1)
Block(-3,24,0,LOG:1)
Block(-3,24,5,LOG:1)
Block(-3,25,-3,LOG:1)
Block(-3,25,0,LOG:1)
Block(-3,25,5,LOG:1)
Block(-3,26,-7,LOG:9)
Block(-3,26,-6,LOG:9)
Block(-3,26,-5,LOG:9)
Block(-3,26,-4,LOG:9)
Block(-3,26,-3,LOG:1)
Block(-3,26,-2,LOG:9)
Block(-3,26,-1,LOG:9)
Block(-3,26,0,LOG:1)
Block(-3,26,1,LOG:9)
Block(-3,26,2,LOG:9)
Block(-3,26,3,LOG:9)
Block(-3,26,4,LOG:9)
Block(-3,26,5,LOG:1)
Block(-3,27,-3,LOG:1)
Block(-3,27,0,LOG:1)
Block(-3,27,5,LOG:1)
Block(-3,28,-3,LOG:1)
Block(-3,28,0,LOG:1)
Block(-3,28,2,WALL_BANNER:5,../NBT/Trader_Swamp/296-bannerC16R16.nbt)
Block(-3,28,5,LOG:1)
Block(-3,29,-7,LOG:9)
Block(-3,29,-6,LOG:9)
Block(-3,29,-5,LOG:9)
Block(-3,29,-4,LOG:9)
Block(-3,29,-3,LOG:1)
Block(-3,29,-2,LOG:9)
Block(-3,29,-1,LOG:9)
Block(-3,29,0,LOG:1)
Block(-3,29,1,LOG:9)
Block(-3,29,2,LOG:9)
Block(-3,29,3,LOG:9)
Block(-3,29,4,LOG:9)
Block(-3,29,5,LOG:1)
Block(-3,29,6,LOG:9)
Block(-3,29,7,STONE_BUTTON:3)
Block(-3,30,-7,SPRUCE_WOOD_STAIRS:7)
Block(-3,30,-6,TRAP_DOOR:9)
Block(-3,30,-5,WOOD_STEP:9)
Block(-3,30,-4,SPRUCE_WOOD_STAIRS:6)
Block(-3,30,-3,LOG:1)
Block(-3,30,-2,AIR:0)
Block(-3,30,-1,AIR:0)
Block(-3,30,0,LOG:1)
Block(-3,30,1,SPRUCE_WOOD_STAIRS:7)
Block(-3,30,2,WOOD_STEP:9)
Block(-3,30,3,TRAP_DOOR:8)
Block(-3,30,4,SPRUCE_WOOD_STAIRS:6)
Block(-3,30,5,LOG:1)
Block(-3,30,6,COBBLE_WALL:0)
Block(-3,30,7,AIR:0)
Block(-3,31,-7,FLOWER_POT:0,../NBT/Trader_Swamp/301-flower_potC16R16.nbt)
Block(-3,31,-6,AIR:0)
Block(-3,31,-5,variedcommodities:book,../NBT/Trader_Swamp/302-variedcommodities_bookC16R16.nbt)
Block(-3,31,-4,charm:iron_lantern)
Block(-3,31,-3,LOG:1)
Block(-3,31,-2,AIR:0)
Block(-3,31,-1,AIR:0)
Block(-3,31,0,LOG:1)
Block(-3,31,1,FLOWER_POT:0,../NBT/Trader_Swamp/303-flower_potC16R16.nbt)
Block(-3,31,2,AIR:0)
Block(-3,31,3,AIR:0)
Block(-3,31,4,rustic:crushing_tub,../NBT/Trader_Swamp/304-rustic_tileentitycrushingtubC16R16.nbt)
Block(-3,31,5,LOG:1)
Block(-3,31,6,DARK_OAK_FENCE:0)
Block(-3,31,7,AIR:0)
Block(-3,32,-7,IRON_FENCE:0)
Block(-3,32,-6,IRON_FENCE:0)
Block(-3,32,-5,IRON_FENCE:0)
Block(-3,32,-4,IRON_FENCE:0)
Block(-3,32,-3,LOG:1)
Block(-3,32,-2,AIR:0)
Block(-3,32,-1,AIR:0)
Block(-3,32,0,LOG:1)
Block(-3,32,1,IRON_FENCE:0)
Block(-3,32,2,IRON_FENCE:0)
Block(-3,32,3,IRON_FENCE:0)
Block(-3,32,4,IRON_FENCE:0)
Block(-3,32,5,LOG:1)
Block(-3,32,6,DARK_OAK_FENCE:0)
Block(-3,32,7,AIR:0)
Block(-3,33,-7,WOOD_STEP:13)
Block(-3,33,-6,WOOD_STEP:13)
Block(-3,33,-5,WOOD_STEP:13)
Block(-3,33,-4,WOOD_STEP:13)
Block(-3,33,-3,LOG:1)
Block(-3,33,-2,AIR:0)
Block(-3,33,-1,inspirations:rope)
Block(-3,33,0,LOG:1)
Block(-3,33,1,WOOD_STEP:13)
Block(-3,33,2,WOOD_STEP:13)
Block(-3,33,3,WOOD_STEP:13)
Block(-3,33,4,WOOD_STEP:13)
Block(-3,33,5,LOG:1)
Block(-3,33,6,COBBLE_WALL:1)
Block(-3,33,7,AIR:0)
Block(-3,34,-7,LOG:9)
Block(-3,34,-6,LOG:9)
Block(-3,34,-5,LOG:9)
Block(-3,34,-4,LOG:9)
Block(-3,34,-3,LOG:1)
Block(-3,34,-2,LOG:9)
Block(-3,34,-1,LOG:9)
Block(-3,34,0,LOG:1)
Block(-3,34,1,LOG:9)
Block(-3,34,2,LOG:9)
Block(-3,34,3,LOG:9)
Block(-3,34,4,LOG:9)
Block(-3,34,5,LOG:1)
Block(-3,34,6,LOG:9)
Block(-3,34,7,STONE_BUTTON:3)
Block(-3,35,-7,SPRUCE_WOOD_STAIRS:7)
Block(-3,35,-6,TRAP_DOOR:9)
Block(-3,35,-5,FURNACE:4,../NBT/Trader_Swamp/308-furnaceC16R16.nbt)
Block(-3,35,-4,SPRUCE_WOOD_STAIRS:6)
Block(-3,35,-3,LOG:1)
Block(-3,35,-2,AIR:0)
Block(-3,35,-1,AIR:0)
Block(-3,35,0,LOG:1)
RandomBlock(-3,35,1,variedcommodities:barrel:1,5,charm:barrel:1,../../../Chests/RLCraft/Containers/charm_barrel.nbt,100)
Block(-3,35,2,AIR:0)
Block(-3,35,3,AIR:0)
Block(-3,35,4,fishingmadebetter:baitbox,../NBT/Trader_Swamp/310-fishingmadebetter_baitboxC16R16.nbt)
Block(-3,35,5,LOG:1)
Block(-3,35,6,COBBLE_WALL:0)
Block(-3,35,7,AIR:0)
RandomBlock(-3,36,-7,AIR:0,30,CHEST:3,../../../Chests/Loot/junk_loot.nbt,10,CHEST:3,../../../Chests/Lore/gemtraderswamp.nbt,10,CHEST:3,../../../Chests/Loot/village_blacksmith.nbt,10,CHEST:3,../../../Chests/Loot/spawn_bonus_chest.nbt,10,CHEST:3,../../../Chests/Loot/rare_loot.nbt,5,CHEST:3,../../../Chests/Loot/gem_loot.nbt,3,CHEST:3,../../../Chests/Loot/junk_loot.nbt,50,CHEST:3,../../../Chests/Loot/gem_loot.nbt,5,CHEST:3,../../../Chests/Loot/common_loot.nbt,100)
Block(-3,36,-6,AIR:0)
Block(-3,36,-5,rustic:evaporating_basin,../NBT/Trader_Swamp/312-rustic_tileentityevaporatingbasinC16R16.nbt)
Block(-3,36,-4,FLOWER_POT:0,../NBT/Trader_Swamp/313-flower_potC16R16.nbt)
Block(-3,36,-3,LOG:1)
Block(-3,36,-2,AIR:0)
Block(-3,36,-1,AIR:0)
Block(-3,36,0,LOG:1)
Block(-3,36,1,AIR:0)
Block(-3,36,2,AIR:0)
Block(-3,36,3,AIR:0)
Block(-3,36,4,fishingmadebetter:baitbox,../NBT/Trader_Swamp/314-fishingmadebetter_baitboxC16R16.nbt)
Block(-3,36,5,LOG:1)
Block(-3,36,6,inspirations:rope)
Block(-3,36,7,AIR:0)
Block(-3,37,-7,IRON_FENCE:0)
Block(-3,37,-6,IRON_FENCE:0)
Block(-3,37,-5,IRON_FENCE:0)
Block(-3,37,-4,IRON_FENCE:0)
Block(-3,37,-3,LOG:1)
Block(-3,37,-2,AIR:0)
Block(-3,37,-1,AIR:0)
Block(-3,37,0,LOG:1)
Block(-3,37,1,AIR:0)
Block(-3,37,2,AIR:0)
Block(-3,37,3,inspirations:rope)
Block(-3,37,4,variedcommodities:shelf:5,../NBT/Trader_Swamp/316-variedcommodities_shelfC16R16.nbt)
Block(-3,37,5,LOG:1)
Block(-3,37,6,inspirations:rope)
Block(-3,37,7,AIR:0)
Block(-3,38,-7,WOOD_STEP:9)
Block(-3,38,-6,WOOD_STEP:9)
Block(-3,38,-5,WOOD_STEP:9)
Block(-3,38,-4,WOOD_STEP:9)
Block(-3,38,-3,LOG:1)
Block(-3,38,-2,inspirations:rope)
Block(-3,38,-1,AIR:0)
Block(-3,38,0,LOG:1)
Block(-3,38,1,inspirations:rope)
Block(-3,38,2,AIR:0)
Block(-3,38,3,inspirations:rope)
Block(-3,38,4,AIR:0)
Block(-3,38,5,LOG:1)
Block(-3,38,6,inspirations:rope)
Block(-3,39,-7,LOG:9)
Block(-3,39,-6,LOG:9)
Block(-3,39,-5,LOG:9)
Block(-3,39,-4,LOG:9)
Block(-3,39,-3,LOG:1)
Block(-3,39,-2,LOG:9)
Block(-3,39,-1,LOG:9)
Block(-3,39,0,LOG:1)
Block(-3,39,1,LOG:9)
Block(-3,39,2,LOG:9)
Block(-3,39,3,LOG:9)
Block(-3,39,4,LOG:9)
Block(-3,39,5,LOG:1)
Block(-3,39,6,WOOD_STEP:1)
Block(-3,40,-7,WOOD_STEP:1)
Block(-3,40,-6,WOOD_STEP:9)
Block(-3,40,-5,rustic:iron_lattice:0)
Block(-3,40,-4,rustic:iron_lattice:0)
Block(-3,40,-3,LOG:1)
Block(-3,40,-2,rustic:iron_lattice:0)
Block(-3,40,-1,rustic:iron_lattice:0)
Block(-3,40,0,LOG:1)
Block(-3,40,1,rustic:iron_lattice:0)
Block(-3,40,2,rustic:iron_lattice:0)
Block(-3,40,3,WOOD_STEP:9)
Block(-3,40,4,WOOD_STEP:1)
Block(-3,40,5,STONE_BUTTON:5)
Block(-3,41,-5,WOOD_STEP:1)
Block(-3,41,-4,WOOD_STEP:1)
Block(-3,41,-3,LOG:1)
Block(-3,41,-2,rustic:iron_lattice:0)
Block(-3,41,-1,rustic:iron_lattice:0)
Block(-3,41,0,LOG:1)
Block(-3,41,1,WOOD_STEP:1)
Block(-3,41,2,WOOD_STEP:1)
Block(-3,42,-3,STONE_BUTTON:5)
Block(-3,42,-2,WOOD_STEP:1)
Block(-3,42,-1,WOOD_STEP:1)
Block(-3,42,0,STONE_BUTTON:5)
Block(-2,2,-3,LOG:5)
Block(-2,2,0,LOG:5)
Block(-2,2,5,LOG:5)
Block(-2,5,-3,LOG:5)
Block(-2,5,0,LOG:5)
Block(-2,5,5,LOG:5)
Block(-2,8,-3,LOG:5)
Block(-2,8,0,LOG:5)
Block(-2,8,5,LOG:5)
Block(-2,11,-3,LOG:5)
Block(-2,11,0,LOG:5)
Block(-2,11,5,LOG:5)
Block(-2,14,-3,LOG:5)
Block(-2,14,0,LOG:5)
Block(-2,14,5,LOG:5)
Block(-2,17,-3,LOG:5)
Block(-2,17,0,LOG:5)
Block(-2,17,5,LOG:5)
Block(-2,20,-3,LOG:5)
Block(-2,20,0,LOG:5)
Block(-2,20,5,LOG:5)
Block(-2,23,-3,LOG:5)
Block(-2,23,0,LOG:5)
Block(-2,23,5,LOG:5)
Block(-2,26,-3,LOG:5)
Block(-2,26,0,LOG:5)
Block(-2,26,5,LOG:5)
Block(-2,29,-7,WOOD_STEP:9)
Block(-2,29,-6,WOOD_STEP:9)
Block(-2,29,-5,WOOD_STEP:9)
Block(-2,29,-4,WOOD_STEP:9)
Block(-2,29,-3,LOG:5)
Block(-2,29,-2,WOOD_STEP:9)
Block(-2,29,-1,WOOD_STEP:9)
Block(-2,29,0,LOG:5)
Block(-2,29,1,WOOD_STEP:9)
Block(-2,29,2,WOOD_STEP:9)
Block(-2,29,3,WOOD_STEP:9)
Block(-2,29,4,WOOD_STEP:9)
Block(-2,29,5,LOG:5)
Block(-2,29,6,WOOD_STEP:9)
Block(-2,30,-7,charm:barrel:1,../../../Chests/RLCraft/Containers/charm_barrel.nbt)
Block(-2,30,-6,AIR:0)
Block(-2,30,-5,AIR:0)
Block(-2,30,-4,AIR:0)
Block(-2,30,-3,AIR:0)
Block(-2,30,-2,AIR:0)
Block(-2,30,-1,AIR:0)
Block(-2,30,0,AIR:0)
Block(-2,30,2,AIR:0)
Block(-2,30,3,AIR:0)
Block(-2,30,4,charm:barrel:5,../../../Chests/RLCraft/Containers/charm_barrel.nbt)
Block(-2,30,5,WOOD:1)
Block(-2,30,6,DARK_OAK_FENCE:0)
Block(-2,30,7,AIR:0)
Block(-2,31,-7,AIR:0)
Block(-2,31,-6,AIR:0)
Block(-2,31,-5,AIR:0)
Block(-2,31,-4,AIR:0)
Block(-2,31,-3,AIR:0)
Block(-2,31,-2,AIR:0)
Block(-2,31,-1,AIR:0)
Block(-2,31,0,AIR:0)
Block(-2,31,2,AIR:0)
Block(-2,31,3,AIR:0)
Block(-2,31,4,charm:barrel:5,../../../Chests/RLCraft/Containers/charm_barrel.nbt)
Block(-2,31,5,SPRUCE_WOOD_STAIRS:1)
Block(-2,31,6,AIR:0)
Block(-2,31,7,AIR:0)
Block(-2,32,-7,AIR:0)
Block(-2,32,-6,AIR:0)
Block(-2,32,-5,AIR:0)
Block(-2,32,-4,AIR:0)
Block(-2,32,-3,AIR:0)
Block(-2,32,-2,AIR:0)
Block(-2,32,-1,AIR:0)
Block(-2,32,0,AIR:0)
Block(-2,32,1,AIR:0)
Block(-2,32,2,AIR:0)
Block(-2,32,3,AIR:0)
Block(-2,32,4,AIR:0)
Block(-2,32,5,SPRUCE_WOOD_STAIRS:5)
Block(-2,32,6,AIR:0)
Block(-2,32,7,AIR:0)
Block(-2,33,-7,WALL_BANNER:5,../NBT/Trader_Swamp/326-bannerC16R16.nbt)
Block(-2,33,-6,WALL_BANNER:5,../NBT/Trader_Swamp/327-bannerC16R16.nbt)
Block(-2,33,-5,WALL_BANNER:5,../NBT/Trader_Swamp/328-bannerC16R16.nbt)
Block(-2,33,-4,WALL_BANNER:5,../NBT/Trader_Swamp/329-bannerC16R16.nbt)
Block(-2,33,-3,AIR:0)
Block(-2,33,-2,AIR:0)
Block(-2,33,-1,AIR:0)
Block(-2,33,0,AIR:0)
Block(-2,33,1,WALL_BANNER:5,../NBT/Trader_Swamp/330-bannerC16R16.nbt)
Block(-2,33,2,WALL_BANNER:5,../NBT/Trader_Swamp/331-bannerC16R16.nbt)
Block(-2,33,3,WALL_BANNER:5,../NBT/Trader_Swamp/332-bannerC16R16.nbt)
Block(-2,33,4,WALL_BANNER:5,../NBT/Trader_Swamp/333-bannerC16R16.nbt)
Block(-2,33,5,WOOD:1)
Block(-2,33,6,AIR:0)
Block(-2,33,7,AIR:0)
Block(-2,34,-7,WOOD_STEP:9)
Block(-2,34,-6,WOOD_STEP:9)
Block(-2,34,-5,WOOD_STEP:9)
Block(-2,34,-4,WOOD_STEP:9)
Block(-2,34,-3,LOG:5)
Block(-2,34,-2,WOOD_STEP:9)
Block(-2,34,-1,WOOD_STEP:9)
Block(-2,34,0,LOG:5)
Block(-2,34,1,WOOD_STEP:13)
Block(-2,34,2,WOOD_STEP:9)
Block(-2,34,3,WOOD_STEP:9)
Block(-2,34,4,WOOD_STEP:9)
Block(-2,34,5,LOG:5)
Block(-2,34,6,WOOD_STEP:9)
Block(-2,34,7,AIR:0)
RandomBlock(-2,35,-7,variedcommodities:crate:5,5,charm:crate_sealed:5,../../../Chests/RLCraft/Containers/charm_villager_crate.nbt,10,charm:crate_sealed:5,../../../Chests/RLCraft/Containers/charm_villager_crate.nbt,100)
Block(-2,35,-6,AIR:0)
Block(-2,35,-5,AIR:0)
Block(-2,35,-4,AIR:0)
Block(-2,35,-3,AIR:0)
Block(-2,35,-2,AIR:0)
Block(-2,35,-1,AIR:0)
Block(-2,35,0,DARK_OAK_FENCE:0)
Block(-2,35,1,WOOD_DOUBLE_STEP:5)
Block(-2,35,2,AIR:0)
Block(-2,35,3,AIR:0)
Block(-2,35,4,fishingmadebetter:baitbox,../NBT/Trader_Swamp/335-fishingmadebetter_baitboxC16R16.nbt)
Block(-2,35,5,WOOD:1)
Block(-2,35,6,DARK_OAK_FENCE:0)
Block(-2,35,7,AIR:0)
RandomBlock(-2,36,-7,variedcommodities:crate:1,5,charm:crate_sealed:1,../../../Chests/RLCraft/Containers/charm_villager_crate.nbt,10,charm:crate_sealed:1,../../../Chests/RLCraft/Containers/charm_villager_crate.nbt,100)
Block(-2,36,-6,AIR:0)
Block(-2,36,-5,AIR:0)
Block(-2,36,-4,AIR:0)
Block(-2,36,-3,AIR:0)
Block(-2,36,-2,AIR:0)
Block(-2,36,-1,AIR:0)
Block(-2,36,0,inspirations:rope)
Block(-2,36,1,charm:iron_lantern)
Block(-2,36,2,AIR:0)
Block(-2,36,3,AIR:0)
Block(-2,36,4,AIR:0)
Block(-2,36,5,DARK_OAK_STAIRS:1)
Block(-2,36,6,AIR:0)
Block(-2,36,7,AIR:0)
Block(-2,37,-7,charm:iron_lantern)
Block(-2,37,-6,AIR:0)
Block(-2,37,-5,AIR:0)
Block(-2,37,-4,AIR:0)
Block(-2,37,-3,AIR:0)
Block(-2,37,-2,AIR:0)
Block(-2,37,-1,AIR:0)
Block(-2,37,0,inspirations:rope)
Block(-2,37,1,AIR:0)
Block(-2,37,2,AIR:0)
Block(-2,37,3,AIR:0)
Block(-2,37,4,variedcommodities:shelf:5,../NBT/Trader_Swamp/337-variedcommodities_shelfC16R16.nbt)
Block(-2,37,5,DARK_OAK_STAIRS:5)
Block(-2,37,6,AIR:0)
Block(-2,37,7,AIR:0)
Block(-2,38,-7,WALL_BANNER:5,../NBT/Trader_Swamp/338-bannerC16R16.nbt)
Block(-2,38,-6,WALL_BANNER:5,../NBT/Trader_Swamp/339-bannerC16R16.nbt)
Block(-2,38,-5,WALL_BANNER:5,../NBT/Trader_Swamp/340-bannerC16R16.nbt)
Block(-2,38,-4,WALL_BANNER:5,../NBT/Trader_Swamp/341-bannerC16R16.nbt)
Block(-2,38,-3,AIR:0)
Block(-2,38,-2,AIR:0)
Block(-2,38,-1,AIR:0)
Block(-2,38,0,inspirations:rope)
Block(-2,38,1,AIR:0)
Block(-2,38,2,AIR:0)
Block(-2,38,3,AIR:0)
Block(-2,38,4,charm:iron_lantern)
Block(-2,38,5,WOOD:1)
Block(-2,39,-7,inspirations:bookshelf:0,../NBT/Trader_Swamp/342-inspirations_bookshelfC16R16.nbt)
Block(-2,39,-6,AIR:0)
Block(-2,39,-5,AIR:0)
Block(-2,39,-4,AIR:0)
Block(-2,39,-3,LOG:5)
Block(-2,39,-2,rustic:iron_lattice:0)
Block(-2,39,-1,rustic:iron_lattice:0)
Block(-2,39,0,LOG:5)
Block(-2,39,1,AIR:0)
Block(-2,39,2,AIR:0)
Block(-2,39,3,AIR:0)
Block(-2,39,4,AIR:0)
Block(-2,39,5,LOG:5)
Block(-2,39,6,WOOD_STEP:1)
Block(-2,40,-7,WOOD_STEP:1)
Block(-2,40,-6,WOOD_STEP:9)
Block(-2,40,-5,AIR:0)
Block(-2,40,-4,AIR:0)
Block(-2,40,-3,rustic:iron_lattice:0)
Block(-2,40,-2,AIR:0)
Block(-2,40,-1,AIR:0)
Block(-2,40,0,rustic:iron_lattice:0)
Block(-2,40,1,AIR:0)
Block(-2,40,2,AIR:0)
Block(-2,40,3,WOOD_STEP:9)
Block(-2,40,4,WOOD_STEP:1)
Block(-2,41,-5,WOOD_STEP:1)
Block(-2,41,-4,WOOD_STEP:9)
Block(-2,41,-3,rustic:iron_lattice:0)
Block(-2,41,-2,AIR:0)
Block(-2,41,-1,AIR:0)
Block(-2,41,0,rustic:iron_lattice:0)
Block(-2,41,1,WOOD_STEP:9)
Block(-2,41,2,WOOD_STEP:1)
Block(-2,42,-3,WOOD_STEP:1)
Block(-2,42,-2,WOOD_STEP:1)
Block(-2,42,-1,WOOD_STEP:1)
Block(-2,42,0,WOOD_STEP:1)
Block(-1,2,-3,LOG:5)
Block(-1,2,0,LOG:5)
Block(-1,2,5,LOG:5)
Block(-1,5,-3,LOG:5)
Block(-1,5,0,LOG:5)
Block(-1,5,5,LOG:5)
Block(-1,8,-3,LOG:5)
Block(-1,8,0,LOG:5)
Block(-1,8,5,LOG:5)
Block(-1,11,-3,LOG:5)
Block(-1,11,0,LOG:5)
Block(-1,11,5,LOG:5)
Block(-1,14,-3,LOG:5)
Block(-1,14,0,LOG:5)
Block(-1,14,5,LOG:5)
Block(-1,17,-3,LOG:5)
Block(-1,17,0,LOG:5)
Block(-1,17,5,LOG:5)
Block(-1,20,-3,LOG:5)
Block(-1,20,0,LOG:5)
Block(-1,20,5,LOG:5)
Block(-1,23,-3,LOG:5)
Block(-1,23,0,LOG:5)
Block(-1,23,5,LOG:5)
Block(-1,26,-3,LOG:5)
Block(-1,26,0,LOG:5)
Block(-1,26,5,LOG:5)
Block(-1,29,-7,WOOD_STEP:9)
Block(-1,29,-6,WOOD_STEP:9)
Block(-1,29,-5,WOOD_STEP:9)
Block(-1,29,-4,WOOD_STEP:9)
Block(-1,29,-3,LOG:5)
Block(-1,29,-2,WOOD_STEP:9)
Block(-1,29,-1,WOOD_STEP:9)
Block(-1,29,0,LOG:5)
Block(-1,29,1,WOOD_STEP:9)
Block(-1,29,2,WOOD_STEP:9)
Block(-1,29,3,WOOD_STEP:9)
Block(-1,29,4,WOOD_STEP:9)
Block(-1,29,5,LOG:5)
Block(-1,29,6,WOOD_STEP:9)
RandomBlock(-1,30,-7,variedcommodities:crate:1,5,charm:crate_sealed:1,../../../Chests/RLCraft/Containers/charm_villager_crate.nbt,10,charm:crate_sealed:1,../../../Chests/RLCraft/Containers/charm_villager_crate.nbt,100)
Block(-1,30,-5,AIR:0)
Block(-1,30,-4,AIR:0)
Block(-1,30,-3,AIR:0)
Block(-1,30,-2,AIR:0)
Block(-1,30,-1,AIR:0)
Block(-1,30,0,AIR:0)
Block(-1,30,1,AIR:0)
Block(-1,30,2,AIR:0)
Block(-1,30,3,AIR:0)
Block(-1,30,4,charm:crate_sealed:1,../../../Chests/RLCraft/Containers/charm_villager_crate.nbt)
Block(-1,30,5,WOOD:1)
Block(-1,30,6,DARK_OAK_FENCE:0)
Block(-1,30,7,AIR:0)
Block(-1,31,-7,rustic:vase,../../../Chests/RLCraft/Containers/rustic_vase.nbt)
Block(-1,31,-6,AIR:0)
Block(-1,31,-5,AIR:0)
Block(-1,31,-4,AIR:0)
Block(-1,31,-3,AIR:0)
Block(-1,31,-2,AIR:0)
Block(-1,31,-1,AIR:0)
Block(-1,31,0,AIR:0)
Block(-1,31,1,AIR:0)
Block(-1,31,2,AIR:0)
Block(-1,31,3,AIR:0)
Block(-1,31,4,AIR:0)
Block(-1,31,5,SPRUCE_WOOD_STAIRS:0)
Block(-1,31,6,AIR:0)
Block(-1,31,7,AIR:0)
Block(-1,32,-7,AIR:0)
Block(-1,32,-6,AIR:0)
Block(-1,32,-5,AIR:0)
Block(-1,32,-4,AIR:0)
Block(-1,32,-3,inspirations:rope)
Block(-1,32,-2,AIR:0)
Block(-1,32,-1,AIR:0)
Block(-1,32,0,inspirations:rope)
Block(-1,32,1,AIR:0)
Block(-1,32,2,AIR:0)
Block(-1,32,3,AIR:0)
Block(-1,32,4,AIR:0)
Block(-1,32,5,SPRUCE_WOOD_STAIRS:4)
Block(-1,32,6,AIR:0)
Block(-1,32,7,AIR:0)
Block(-1,33,-7,AIR:0)
Block(-1,33,-6,AIR:0)
Block(-1,33,-5,AIR:0)
Block(-1,33,-4,AIR:0)
Block(-1,33,-3,inspirations:rope)
Block(-1,33,-2,AIR:0)
Block(-1,33,-1,AIR:0)
Block(-1,33,0,inspirations:rope)
Block(-1,33,1,WALL_BANNER:4,../NBT/Trader_Swamp/349-bannerC16R16.nbt)
Block(-1,33,2,WALL_BANNER:4,../NBT/Trader_Swamp/350-bannerC16R16.nbt)
Block(-1,33,3,WALL_BANNER:4,../NBT/Trader_Swamp/351-bannerC16R16.nbt)
Block(-1,33,4,WALL_BANNER:4,../NBT/Trader_Swamp/352-bannerC16R16.nbt)
Block(-1,33,5,WOOD:1)
Block(-1,33,6,AIR:0)
Block(-1,33,7,AIR:0)
Block(-1,34,-7,WOOD_STEP:9)
Block(-1,34,-6,WOOD_STEP:9)
Block(-1,34,-5,WOOD_STEP:9)
Block(-1,34,-4,WOOD_STEP:9)
Block(-1,34,-3,LOG:5)
Block(-1,34,-2,WOOD_STEP:9)
Block(-1,34,-1,WOOD_STEP:9)
Block(-1,34,0,LOG:5)
Block(-1,34,1,WOOD_DOUBLE_STEP:5)
Block(-1,34,2,WOOD_STEP:1)
Block(-1,34,3,WOOD_STEP:9)
Block(-1,34,4,WOOD_STEP:9)
Block(-1,34,5,LOG:5)
Block(-1,34,6,WOOD_STEP:9)
Block(-1,34,7,AIR:0)
RandomBlock(-1,35,-7,variedcommodities:crate:1,5,charm:crate_sealed:1,../../../Chests/RLCraft/Containers/charm_villager_crate.nbt,10,charm:crate_sealed:1,../../../Chests/RLCraft/Containers/charm_villager_crate.nbt,100)
Block(-1,35,-6,AIR:0)
Block(-1,35,-4,AIR:0)
Block(-1,35,-3,variedcommodities:couch_wood:5,../NBT/Trader_Swamp/354-variedcommodities_couch_woodC16R16.nbt)
Block(-1,35,-2,variedcommodities:table:5,../NBT/Trader_Swamp/355-variedcommodities_tableC16R16.nbt)
RandomBlock(-1,35,-1,variedcommodities:barrel:5,5,charm:barrel:5,../../../Chests/RLCraft/Containers/charm_barrel.nbt,100)
Block(-1,35,0,DARK_OAK_FENCE:0)
Block(-1,35,1,WOOD_STEP:5)
Block(-1,35,2,AIR:0)
Block(-1,35,3,AIR:0)
Block(-1,35,4,rustic:crushing_tub,../NBT/Trader_Swamp/357-rustic_tileentitycrushingtubC16R16.nbt)
Block(-1,35,5,WOOD:1)
Block(-1,35,6,DARK_OAK_FENCE:0)
Block(-1,35,7,AIR:0)
Block(-1,36,-7,rustic:evaporating_basin,../NBT/Trader_Swamp/358-rustic_tileentityevaporatingbasinC16R16.nbt)
Block(-1,36,-6,AIR:0)
Block(-1,36,-5,AIR:0)
Block(-1,36,-4,AIR:0)
Block(-1,36,-3,AIR:0)
Block(-1,36,-2,AIR:0)
Block(-1,36,-1,AIR:0)
Block(-1,36,0,AIR:0)
Block(-1,36,1,AIR:0)
Block(-1,36,2,AIR:0)
Block(-1,36,3,AIR:0)
Block(-1,36,4,AIR:0)
Block(-1,36,5,DARK_OAK_STAIRS:0)
Block(-1,36,6,AIR:0)
Block(-1,36,7,AIR:0)
Block(-1,37,-7,AIR:0)
Block(-1,37,-6,AIR:0)
Block(-1,37,-5,AIR:0)
Block(-1,37,-4,AIR:0)
Block(-1,37,-3,inspirations:rope)
Block(-1,37,-2,AIR:0)
Block(-1,37,-1,AIR:0)
Block(-1,37,0,AIR:0)
Block(-1,37,1,AIR:0)
Block(-1,37,2,AIR:0)
Block(-1,37,3,AIR:0)
Block(-1,37,4,variedcommodities:shelf:5,../NBT/Trader_Swamp/359-variedcommodities_shelfC16R16.nbt)
Block(-1,37,5,DARK_OAK_STAIRS:4)
Block(-1,37,6,inspirations:rope)
Block(-1,37,7,AIR:0)
Block(-1,38,-7,WALL_BANNER:4,../NBT/Trader_Swamp/360-bannerC16R16.nbt)
Block(-1,38,-6,WALL_BANNER:4,../NBT/Trader_Swamp/361-bannerC16R16.nbt)
Block(-1,38,-5,WALL_BANNER:4,../NBT/Trader_Swamp/362-bannerC16R16.nbt)
Block(-1,38,-4,WALL_BANNER:4,../NBT/Trader_Swamp/363-bannerC16R16.nbt)
Block(-1,38,-3,inspirations:rope)
Block(-1,38,-2,AIR:0)
Block(-1,38,-1,AIR:0)
Block(-1,38,0,AIR:0)
Block(-1,38,1,AIR:0)
Block(-1,38,2,AIR:0)
Block(-1,38,3,AIR:0)
RandomBlock(-1,38,4,variedcommodities:crate:3,5,charm:crate_sealed:3,../../../Chests/RLCraft/Containers/charm_villager_crate.nbt,10,charm:crate_sealed:3,../../../Chests/RLCraft/Containers/charm_villager_crate.nbt,100)
Block(-1,38,5,WOOD:1)
Block(-1,38,6,inspirations:rope)
Block(-1,39,-7,inspirations:bookshelf:0,../NBT/Trader_Swamp/365-inspirations_bookshelfC16R16.nbt)
Block(-1,39,-6,AIR:0)
Block(-1,39,-5,AIR:0)
Block(-1,39,-4,AIR:0)
Block(-1,39,-3,LOG:5)
Block(-1,39,-2,rustic:iron_lattice:0)
Block(-1,39,-1,rustic:iron_lattice:0)
Block(-1,39,0,LOG:5)
Block(-1,39,1,AIR:0)
Block(-1,39,2,AIR:0)
Block(-1,39,3,AIR:0)
Block(-1,39,4,charm:crate_sealed:1,../../../Chests/RLCraft/Containers/charm_villager_crate.nbt)
Block(-1,39,5,LOG:5)
Block(-1,39,6,WOOD_STEP:1)
Block(-1,40,-7,WOOD_STEP:1)
Block(-1,40,-6,WOOD_STEP:9)
Block(-1,40,-5,AIR:0)
Block(-1,40,-4,AIR:0)
Block(-1,40,-3,rustic:iron_lattice:0)
Block(-1,40,-2,AIR:0)
Block(-1,40,-1,AIR:0)
Block(-1,40,0,rustic:iron_lattice:0)
Block(-1,40,1,AIR:0)
Block(-1,40,2,AIR:0)
Block(-1,40,3,WOOD_STEP:9)
Block(-1,40,4,WOOD_STEP:1)
Block(-1,41,-5,WOOD_STEP:1)
Block(-1,41,-4,WOOD_STEP:9)
Block(-1,41,-3,rustic:iron_lattice:0)
Block(-1,41,-2,AIR:0)
Block(-1,41,-1,AIR:0)
Block(-1,41,0,rustic:iron_lattice:0)
Block(-1,41,1,WOOD_STEP:9)
Block(-1,41,2,WOOD_STEP:1)
Block(-1,42,-3,WOOD_STEP:1)
Block(-1,42,-2,WOOD_STEP:1)
Block(-1,42,-1,WOOD_STEP:1)
Block(-1,42,0,WOOD_STEP:1)
Block(0,0,-3,LOG:1)
Block(0,0,0,LOG:1)
Block(0,0,5,LOG:1)
Block(0,1,-3,LOG:1)
Block(0,1,0,LOG:1)
Block(0,1,5,LOG:1)
Block(0,2,-7,LOG:9)
Block(0,2,-6,LOG:9)
Block(0,2,-5,LOG:9)
Block(0,2,-4,LOG:9)
Block(0,2,-3,LOG:1)
Block(0,2,-2,LOG:9)
Block(0,2,-1,LOG:9)
Block(0,2,0,LOG:1)
Block(0,2,1,LOG:9)
Block(0,2,2,LOG:9)
Block(0,2,3,LOG:9)
Block(0,2,4,LOG:9)
Block(0,2,5,LOG:1)
Block(0,3,-3,LOG:1)
Block(0,3,0,LOG:1)
Block(0,3,5,LOG:1)
Block(0,4,-3,LOG:1)
Block(0,4,0,LOG:1)
Block(0,4,5,LOG:1)
Block(0,5,-7,LOG:9)
Block(0,5,-6,LOG:9)
Block(0,5,-5,LOG:9)
Block(0,5,-4,LOG:9)
Block(0,5,-3,LOG:1)
Block(0,5,-2,LOG:9)
Block(0,5,-1,LOG:9)
Block(0,5,0,LOG:1)
Block(0,5,1,LOG:9)
Block(0,5,2,LOG:9)
Block(0,5,3,LOG:9)
Block(0,5,4,LOG:9)
Block(0,5,5,LOG:1)
Block(0,6,-3,LOG:1)
Block(0,6,0,LOG:1)
Block(0,6,5,LOG:1)
Block(0,7,-3,LOG:1)
Block(0,7,0,LOG:1)
Block(0,7,5,LOG:1)
Block(0,8,-7,LOG:9)
Block(0,8,-6,LOG:9)
Block(0,8,-5,LOG:9)
Block(0,8,-4,LOG:9)
Block(0,8,-3,LOG:1)
Block(0,8,-2,LOG:9)
Block(0,8,-1,LOG:9)
Block(0,8,0,LOG:1)
Block(0,8,1,LOG:9)
Block(0,8,2,LOG:9)
Block(0,8,3,LOG:9)
Block(0,8,4,LOG:9)
Block(0,8,5,LOG:1)
Block(0,9,-3,LOG:1)
Block(0,9,0,LOG:1)
Block(0,9,5,LOG:1)
Block(0,10,-3,LOG:1)
Block(0,10,0,LOG:1)
Block(0,10,5,LOG:1)
Block(0,11,-7,LOG:9)
Block(0,11,-6,LOG:9)
Block(0,11,-5,LOG:9)
Block(0,11,-4,LOG:9)
Block(0,11,-3,LOG:1)
Block(0,11,-2,LOG:9)
Block(0,11,-1,LOG:9)
Block(0,11,0,LOG:1)
Block(0,11,1,LOG:9)
Block(0,11,2,LOG:9)
Block(0,11,3,LOG:9)
Block(0,11,4,LOG:9)
Block(0,11,5,LOG:1)
Block(0,12,-3,LOG:1)
Block(0,12,0,LOG:1)
Block(0,12,5,LOG:1)
Block(0,13,-3,LOG:1)
Block(0,13,0,LOG:1)
Block(0,13,5,LOG:1)
Block(0,14,-7,LOG:9)
Block(0,14,-6,LOG:9)
Block(0,14,-5,LOG:9)
Block(0,14,-4,LOG:9)
Block(0,14,-3,LOG:1)
Block(0,14,-2,LOG:9)
Block(0,14,-1,LOG:9)
Block(0,14,0,LOG:1)
Block(0,14,1,LOG:9)
Block(0,14,2,LOG:9)
Block(0,14,3,LOG:9)
Block(0,14,4,LOG:9)
Block(0,14,5,LOG:1)
Block(0,15,-3,LOG:1)
Block(0,15,0,LOG:1)
Block(0,15,5,LOG:1)
Block(0,16,-3,LOG:1)
Block(0,16,0,LOG:1)
Block(0,16,5,LOG:1)
Block(0,17,-7,LOG:9)
Block(0,17,-6,LOG:9)
Block(0,17,-5,LOG:9)
Block(0,17,-4,LOG:9)
Block(0,17,-3,LOG:1)
Block(0,17,-2,LOG:9)
Block(0,17,-1,LOG:9)
Block(0,17,0,LOG:1)
Block(0,17,1,LOG:9)
Block(0,17,2,LOG:9)
Block(0,17,3,LOG:9)
Block(0,17,4,LOG:9)
Block(0,17,5,LOG:1)
Block(0,18,-3,LOG:1)
Block(0,18,0,LOG:1)
Block(0,18,5,LOG:1)
Block(0,19,-3,LOG:1)
Block(0,19,0,LOG:1)
Block(0,19,5,LOG:1)
Block(0,20,-7,LOG:9)
Block(0,20,-6,LOG:9)
Block(0,20,-5,LOG:9)
Block(0,20,-4,LOG:9)
Block(0,20,-3,LOG:1)
Block(0,20,-2,LOG:9)
Block(0,20,-1,LOG:9)
Block(0,20,0,LOG:1)
Block(0,20,1,LOG:9)
Block(0,20,2,LOG:9)
Block(0,20,3,LOG:9)
Block(0,20,4,LOG:9)
Block(0,20,5,LOG:1)
Block(0,21,-3,LOG:1)
Block(0,21,0,LOG:1)
Block(0,21,5,LOG:1)
Block(0,22,-3,LOG:1)
Block(0,22,0,LOG:1)
Block(0,22,5,LOG:1)
Block(0,23,-7,LOG:9)
Block(0,23,-6,LOG:9)
Block(0,23,-5,LOG:9)
Block(0,23,-4,LOG:9)
Block(0,23,-3,LOG:1)
Block(0,23,-2,LOG:9)
Block(0,23,-1,LOG:9)
Block(0,23,0,LOG:1)
Block(0,23,1,LOG:9)
Block(0,23,2,LOG:9)
Block(0,23,3,LOG:9)
Block(0,23,4,LOG:9)
Block(0,23,5,LOG:1)
Block(0,24,-3,LOG:1)
Block(0,24,0,LOG:1)
Block(0,24,5,LOG:1)
Block(0,25,-3,LOG:1)
Block(0,25,0,LOG:1)
Block(0,25,5,LOG:1)
Block(0,26,-7,LOG:9)
Block(0,26,-6,LOG:9)
Block(0,26,-5,LOG:9)
Block(0,26,-4,LOG:9)
Block(0,26,-3,LOG:1)
Block(0,26,-2,LOG:9)
Block(0,26,-1,LOG:9)
Block(0,26,0,LOG:1)
Block(0,26,1,LOG:9)
Block(0,26,2,LOG:9)
Block(0,26,3,LOG:9)
Block(0,26,4,LOG:9)
Block(0,26,5,LOG:1)
Block(0,27,-3,LOG:1)
Block(0,27,0,LOG:1)
Block(0,27,5,LOG:1)
Block(0,28,-3,LOG:1)
Block(0,28,0,LOG:1)
Block(0,28,5,LOG:1)
Block(0,29,-7,LOG:9)
Block(0,29,-6,LOG:9)
Block(0,29,-5,LOG:9)
Block(0,29,-4,LOG:9)
Block(0,29,-3,LOG:1)
Block(0,29,-2,LOG:9)
Block(0,29,-1,LOG:9)
Block(0,29,0,LOG:1)
Block(0,29,1,LOG:9)
Block(0,29,2,LOG:9)
Block(0,29,3,LOG:9)
Block(0,29,4,LOG:9)
Block(0,29,5,LOG:1)
Block(0,29,6,LOG:9)
Block(0,29,7,STONE_BUTTON:3)
Block(0,30,-7,charm:barrel:1,../../../Chests/RLCraft/Containers/charm_barrel.nbt)
Block(0,30,-6,AIR:0)
Block(0,30,-5,WOOD_STEP:1)
Block(0,30,-4,WOOD_DOUBLE_STEP:5)
Block(0,30,-3,LOG:1)
Block(0,30,-2,SPRUCE_WOOD_STAIRS:7)
Block(0,30,-1,TRAP_DOOR:8)
Block(0,30,0,LOG:1)
Block(0,30,1,SPRUCE_WOOD_STAIRS:7)
Block(0,30,2,WOOD_STEP:9)
Block(0,30,3,WOOD_STEP:9)
Block(0,30,4,SPRUCE_WOOD_STAIRS:6)
Block(0,30,5,LOG:1)
Block(0,30,6,COBBLE_WALL:1)
Block(0,30,7,AIR:0)
RandomBlock(0,31,-7,variedcommodities:crate:5,5,charm:crate_sealed:5,../../../Chests/RLCraft/Containers/charm_villager_crate.nbt,10,charm:crate_sealed:5,../../../Chests/RLCraft/Containers/charm_villager_crate.nbt,100)
Block(0,31,-6,AIR:0)
Block(0,31,-5,AIR:0)
Block(0,31,-4,WOOD_STEP:5)
Block(0,31,-3,LOG:1)
Block(0,31,-2,charm:iron_lantern)
Block(0,31,-1,AIR:0)
Block(0,31,0,LOG:1)
Block(0,31,1,charm:iron_lantern)
Block(0,31,2,variedcommodities:book,../NBT/Trader_Swamp/373-variedcommodities_bookC16R16.nbt)
Block(0,31,3,AIR:0)
Block(0,31,4,FLOWER_POT:0,../NBT/Trader_Swamp/374-flower_potC16R16.nbt)
Block(0,31,5,LOG:1)
Block(0,31,6,DARK_OAK_FENCE:0)
Block(0,31,7,AIR:0)
Block(0,32,-7,charm:iron_lantern)
Block(0,32,-6,AIR:0)
Block(0,32,-5,AIR:0)
Block(0,32,-4,inspirations:rope)
Block(0,32,-3,LOG:1)
Block(0,32,-2,AIR:0)
Block(0,32,-1,AIR:0)
Block(0,32,0,LOG:1)
Block(0,32,1,IRON_FENCE:0)
Block(0,32,2,IRON_FENCE:0)
Block(0,32,3,IRON_FENCE:0)
Block(0,32,4,IRON_FENCE:0)
Block(0,32,5,LOG:1)
Block(0,32,6,DARK_OAK_FENCE:0)
Block(0,32,7,AIR:0)
Block(0,33,-7,inspirations:rope)
Block(0,33,-6,AIR:0)
Block(0,33,-5,inspirations:rope)
Block(0,33,-4,inspirations:rope)
Block(0,33,-3,LOG:1)
Block(0,33,-2,AIR:0)
Block(0,33,-1,AIR:0)
Block(0,33,0,LOG:1)
Block(0,33,1,WOOD_STEP:13)
Block(0,33,2,WOOD_STEP:13)
Block(0,33,3,WOOD_STEP:13)
Block(0,33,4,WOOD_STEP:13)
Block(0,33,5,LOG:1)
Block(0,33,6,COBBLE_WALL:0)
Block(0,33,7,AIR:0)
Block(0,34,-7,LOG:9)
Block(0,34,-6,LOG:9)
Block(0,34,-5,LOG:9)
Block(0,34,-4,LOG:9)
Block(0,34,-3,LOG:1)
Block(0,34,-2,LOG:9)
Block(0,34,-1,LOG:9)
Block(0,34,0,LOG:1)
Block(0,34,1,WOOD_DOUBLE_STEP:5)
Block(0,34,2,WOOD_STEP:1)
Block(0,34,3,WOOD_STEP:1)
Block(0,34,4,WOOD_STEP:9)
Block(0,34,5,LOG:1)
Block(0,34,6,LOG:9)
Block(0,34,7,STONE_BUTTON:3)
Block(0,35,-7,SPRUCE_WOOD_STAIRS:7)
Block(0,35,-6,TRAP_DOOR:9)
Block(0,35,-5,CAULDRON:3,../NBT/Trader_Swamp/375-inspirations_cauldronC16R16.nbt)
Block(0,35,-4,SPRUCE_WOOD_STAIRS:6)
Block(0,35,-3,LOG:1)
Block(0,35,-2,DARK_OAK_FENCE:0)
Block(0,35,-1,DARK_OAK_FENCE:0)
Block(0,35,0,LOG:1)
Block(0,35,1,charm:iron_lantern)
Block(0,35,2,AIR:0)
Block(0,35,3,AIR:0)
RandomBlock(0,35,4,variedcommodities:barrel:1,5,charm:barrel:1,../../../Chests/RLCraft/Containers/charm_barrel.nbt,100)
Block(0,35,5,LOG:1)
Block(0,35,6,COBBLE_WALL:0)
Block(0,35,7,AIR:0)
Block(0,36,-7,variedcommodities:sign:5,../NBT/Trader_Swamp/377-variedcommodities_signC16R16.nbt)
Block(0,36,-6,AIR:0)
Block(0,36,-5,AIR:0)
Block(0,36,-4,FLOWER_POT:0,../NBT/Trader_Swamp/378-flower_potC16R16.nbt)
Block(0,36,-3,LOG:1)
Block(0,36,-2,AIR:0)
Block(0,36,-1,AIR:0)
Block(0,36,0,LOG:1)
Block(0,36,1,AIR:0)
Block(0,36,2,AIR:0)
Block(0,36,3,AIR:0)
Block(0,36,4,AIR:0)
Block(0,36,5,LOG:1)
Block(0,36,6,AIR:0)
Block(0,36,7,AIR:0)
Block(0,37,-7,IRON_FENCE:0)
Block(0,37,-6,IRON_FENCE:0)
Block(0,37,-5,IRON_FENCE:0)
Block(0,37,-4,IRON_FENCE:0)
Block(0,37,-3,LOG:1)
Block(0,37,-2,inspirations:rope)
Block(0,37,-1,AIR:0)
Block(0,37,0,LOG:1)
Block(0,37,1,inspirations:rope)
Block(0,37,2,AIR:0)
Block(0,37,3,AIR:0)
Block(0,37,4,variedcommodities:shelf:5,../NBT/Trader_Swamp/379-variedcommodities_shelfC16R16.nbt)
Block(0,37,5,LOG:1)
Block(0,37,6,AIR:0)
Block(0,37,7,AIR:0)
Block(0,38,-7,WOOD_STEP:9)
Block(0,38,-6,WOOD_STEP:9)
Block(0,38,-5,WOOD_STEP:9)
Block(0,38,-4,WOOD_STEP:9)
Block(0,38,-3,LOG:1)
Block(0,38,-2,inspirations:rope)
Block(0,38,-1,inspirations:rope)
Block(0,38,0,LOG:1)
Block(0,38,1,inspirations:rope)
Block(0,38,2,AIR:0)
Block(0,38,3,inspirations:rope)
RandomBlock(0,38,4,variedcommodities:crate,5,charm:crate_sealed,../../../Chests/RLCraft/Containers/charm_villager_crate.nbt,10,charm:crate_sealed,../../../Chests/RLCraft/Containers/charm_villager_crate.nbt,100)
Block(0,38,5,LOG:1)
Block(0,39,-7,LOG:9)
Block(0,39,-6,LOG:9)
Block(0,39,-5,LOG:9)
Block(0,39,-4,LOG:9)
Block(0,39,-3,LOG:1)
Block(0,39,-2,LOG:9)
Block(0,39,-1,LOG:9)
Block(0,39,0,LOG:1)
Block(0,39,1,LOG:9)
Block(0,39,2,LOG:9)
Block(0,39,3,LOG:9)
Block(0,39,4,LOG:9)
Block(0,39,5,LOG:1)
Block(0,39,6,WOOD_STEP:1)
Block(0,40,-7,WOOD_STEP:1)
Block(0,40,-6,WOOD_STEP:9)
Block(0,40,-5,rustic:iron_lattice:0)
Block(0,40,-4,rustic:iron_lattice:0)
Block(0,40,-3,LOG:1)
Block(0,40,-2,rustic:iron_lattice:0)
Block(0,40,-1,rustic:iron_lattice:0)
Block(0,40,0,LOG:1)
Block(0,40,1,rustic:iron_lattice:0)
Block(0,40,2,rustic:iron_lattice:0)
Block(0,40,3,WOOD_STEP:9)
Block(0,40,4,WOOD_STEP:1)
Block(0,40,5,STONE_BUTTON:5)
Block(0,41,-5,WOOD_STEP:1)
Block(0,41,-4,WOOD_STEP:1)
Block(0,41,-3,LOG:1)
Block(0,41,-2,rustic:iron_lattice:0)
Block(0,41,-1,rustic:iron_lattice:0)
Block(0,41,0,LOG:1)
Block(0,41,1,WOOD_STEP:1)
Block(0,41,2,WOOD_STEP:1)
Block(0,42,-3,STONE_BUTTON:5)
Block(0,42,-2,WOOD_STEP:1)
Block(0,42,-1,WOOD_STEP:1)
Block(0,42,0,STONE_BUTTON:5)
Block(1,2,-7,LOG:5)
Block(1,2,-3,LOG:5)
Block(1,2,0,LOG:5)
Block(1,2,4,LOG:5)
Block(1,5,-7,LOG:5)
Block(1,5,-3,LOG:5)
Block(1,5,0,LOG:5)
Block(1,5,4,LOG:5)
Block(1,8,-7,LOG:5)
Block(1,8,-3,LOG:5)
Block(1,8,0,LOG:5)
Block(1,8,4,LOG:5)
Block(1,11,-7,LOG:5)
Block(1,11,-3,LOG:5)
Block(1,11,0,LOG:5)
Block(1,11,4,LOG:5)
Block(1,14,-7,LOG:5)
Block(1,14,-3,LOG:5)
Block(1,14,0,LOG:5)
Block(1,14,4,LOG:5)
Block(1,17,-7,LOG:5)
Block(1,17,-3,LOG:5)
Block(1,17,0,LOG:5)
Block(1,17,4,LOG:5)
Block(1,20,-7,LOG:5)
Block(1,20,-3,LOG:5)
Block(1,20,0,LOG:5)
Block(1,20,4,LOG:5)
Block(1,23,-7,LOG:5)
Block(1,23,-3,LOG:5)
Block(1,23,0,LOG:5)
Block(1,23,4,LOG:5)
Block(1,26,-7,LOG:5)
Block(1,26,-3,LOG:5)
Block(1,26,0,LOG:5)
Block(1,26,4,LOG:5)
Block(1,29,-7,LOG:5)
Block(1,29,-6,WOOD_STEP:9)
Block(1,29,-5,WOOD_STEP:9)
Block(1,29,-4,WOOD_STEP:9)
Block(1,29,-3,LOG:5)
Block(1,29,-2,WOOD_STEP:9)
Block(1,29,-1,WOOD_STEP:9)
Block(1,29,0,LOG:5)
Block(1,29,1,WOOD_STEP:9)
Block(1,29,2,WOOD_STEP:9)
Block(1,29,3,WOOD_STEP:9)
Block(1,29,4,LOG:5)
Block(1,29,5,WOOD_STEP:9)
Block(1,29,6,WOOD_STEP:9)
Block(1,30,-7,WOOD:1)
Block(1,30,-6,WOOD_STEP:1)
Block(1,30,-5,WOOD_STEP:1)
Block(1,30,-4,WOOD_DOUBLE_STEP:1)
Block(1,30,-3,WOOD_DOUBLE_STEP:1)
Block(1,30,-2,WOOD:5)
Block(1,30,-1,SPRUCE_DOOR:0)
Block(1,30,0,CARPET:14)
Block(1,30,1,CARPET:0)
Block(1,30,3,WORKBENCH:0,../NBT/Trader_Swamp/384-realbench_workbenchC16R16.nbt)
Block(1,30,4,WOOD:1)
Block(1,30,5,DARK_OAK_FENCE:0)
Block(1,30,6,DARK_OAK_FENCE:0)
Block(1,30,7,AIR:0)
Block(1,31,-7,WOOD:5)
Block(1,31,-6,AIR:0)
Block(1,31,-5,AIR:0)
Block(1,31,-4,AIR:0)
Block(1,31,-3,WOOD_DOUBLE_STEP:5)
Block(1,31,-2,WOOD:5)
Block(1,31,-1,SPRUCE_DOOR:8)
Block(1,31,0,AIR:0)
Block(1,31,1,AIR:0)
Block(1,31,2,AIR:0)
Block(1,31,3,LADDER:2)
Block(1,31,4,WOOD:5)
Block(1,31,5,AIR:0)
Block(1,31,6,AIR:0)
Block(1,31,7,AIR:0)
Block(1,32,-7,WOOD:5)
Block(1,32,-6,AIR:0)
Block(1,32,-5,AIR:0)
Block(1,32,-4,AIR:0)
Block(1,32,-3,WOOD_STEP:5)
Block(1,32,-2,WOOD:5)
Block(1,32,-1,WOOD:5)
Block(1,32,0,DARK_OAK_STAIRS:7)
Block(1,32,1,AIR:0)
Block(1,32,2,AIR:0)
Block(1,32,3,LADDER:2)
Block(1,32,4,WOOD:5)
Block(1,32,5,AIR:0)
Block(1,32,6,AIR:0)
Block(1,32,7,AIR:0)
Block(1,33,-7,WOOD:1)
Block(1,33,-6,AIR:0)
Block(1,33,-5,AIR:0)
Block(1,33,-4,AIR:0)
Block(1,33,-3,AIR:0)
Block(1,33,-2,charm:iron_lantern)
Block(1,33,-1,WOOD_STEP:5)
Block(1,33,0,WOOD_DOUBLE_STEP:5)
Block(1,33,1,WOOD_STEP:1)
Block(1,33,2,WOOD_STEP:9)
Block(1,33,3,AIR:0)
Block(1,33,4,WOOD:1)
Block(1,33,5,AIR:0)
Block(1,33,6,AIR:0)
Block(1,33,7,AIR:0)
Block(1,34,-7,LOG:5)
Block(1,34,-6,WOOD_STEP:9)
Block(1,34,-5,WOOD_STEP:9)
Block(1,34,-4,WOOD_STEP:9)
Block(1,34,-3,LOG:5)
Block(1,34,-2,AIR:0)
Block(1,34,-1,AIR:0)
Block(1,34,0,WOOD_STEP:5)
Block(1,34,1,AIR:0)
Block(1,34,2,AIR:0)
Block(1,34,3,WOOD_STEP:1)
Block(1,34,4,LOG:5)
Block(1,34,5,WOOD_STEP:9)
Block(1,34,6,WOOD_STEP:9)
Block(1,34,7,AIR:0)
Block(1,35,-7,WOOD:1)
Block(1,35,-6,AIR:0)
Block(1,35,-4,rustic:liquid_barrel,../NBT/Trader_Swamp/385-rustic_tileentityliquidbarrelC16R16.nbt)
Block(1,35,-3,SPRUCE_WOOD_STAIRS:5)
Block(1,35,-2,AIR:0)
Block(1,35,-1,AIR:0)
Block(1,35,0,AIR:0)
Block(1,35,1,AIR:0)
Block(1,35,2,AIR:0)
Block(1,35,3,AIR:0)
Block(1,35,4,WOOD:1)
Block(1,35,5,DARK_OAK_FENCE:0)
Block(1,35,6,DARK_OAK_FENCE:0)
Block(1,35,7,AIR:0)
Block(1,36,-7,DARK_OAK_STAIRS:1)
Block(1,36,-6,AIR:0)
Block(1,36,-5,AIR:0)
Block(1,36,-4,AIR:0)
Block(1,36,-3,BREWING_STAND:0,../NBT/Trader_Swamp/386-brewing_standC16R16.nbt)
Block(1,36,-2,AIR:0)
Block(1,36,-1,AIR:0)
Block(1,36,0,AIR:0)
Block(1,36,1,AIR:0)
Block(1,36,2,AIR:0)
Block(1,36,3,AIR:0)
Block(1,36,4,DARK_OAK_STAIRS:1)
Block(1,36,5,AIR:0)
Block(1,36,6,AIR:0)
Block(1,36,7,AIR:0)
Block(1,37,-7,DARK_OAK_STAIRS:5)
Block(1,37,-6,variedcommodities:shelf:5,../NBT/Trader_Swamp/387-variedcommodities_shelfC16R16.nbt)
Block(1,37,-5,AIR:0)
Block(1,37,-4,AIR:0)
Block(1,37,-3,IRON_FENCE:0)
Block(1,37,-2,AIR:0)
Block(1,37,-1,AIR:0)
Block(1,37,0,AIR:0)
Block(1,37,1,AIR:0)
Block(1,37,2,AIR:0)
Block(1,37,3,AIR:0)
Block(1,37,4,DARK_OAK_STAIRS:5)
Block(1,37,5,AIR:0)
Block(1,37,6,AIR:0)
Block(1,37,7,AIR:0)
Block(1,38,-7,WOOD:1)
Block(1,38,-6,rustic:brewing_barrel:0,../NBT/Trader_Swamp/388-rustic_tileentitybrewingbarrelC16R16.nbt)
Block(1,38,-5,AIR:0)
Block(1,38,-4,AIR:0)
Block(1,38,-3,WOOD_STEP:9)
Block(1,38,-2,WALL_BANNER:3,../NBT/Trader_Swamp/389-bannerC16R16.nbt)
Block(1,38,-1,AIR:0)
Block(1,38,0,AIR:0)
Block(1,38,1,AIR:0)
Block(1,38,2,AIR:0)
Block(1,38,3,AIR:0)
Block(1,38,4,WOOD:1)
Block(1,39,-7,LOG:5)
Block(1,39,-6,rustic:brewing_barrel:0,../NBT/Trader_Swamp/390-rustic_tileentitybrewingbarrelC16R16.nbt)
Block(1,39,-5,AIR:0)
Block(1,39,-4,AIR:0)
Block(1,39,-3,LOG:5)
Block(1,39,-2,AIR:0)
Block(1,39,-1,AIR:0)
Block(1,39,0,LOG:5)
Block(1,39,1,AIR:0)
Block(1,39,2,AIR:0)
Block(1,39,3,AIR:0)
Block(1,39,4,LOG:5)
Block(1,39,5,WOOD_STEP:1)
Block(1,40,-6,WOOD_STEP:1)
Block(1,40,-5,WOOD_STEP:9)
Block(1,40,-4,charm:iron_lantern:1)
Block(1,40,-3,rustic:iron_lattice:0)
Block(1,40,-2,AIR:0)
Block(1,40,-1,AIR:0)
Block(1,40,0,rustic:iron_lattice:0)
Block(1,40,1,charm:iron_lantern:1)
Block(1,40,2,WOOD_STEP:9)
Block(1,40,3,WOOD_STEP:1)
Block(1,41,-4,WOOD_STEP:1)
Block(1,41,-3,WOOD_STEP:1)
Block(1,41,-2,WOOD_STEP:9)
Block(1,41,-1,WOOD_STEP:9)
Block(1,41,0,WOOD_STEP:1)
Block(1,41,1,WOOD_STEP:1)
Block(2,0,-7,LOG:1)
Block(2,0,4,LOG:1)
Block(2,1,-7,LOG:1)
Block(2,1,4,LOG:1)
Block(2,2,-7,LOG:1)
Block(2,2,-3,LOG:5)
Block(2,2,0,LOG:5)
Block(2,2,4,LOG:1)
Block(2,3,-7,LOG:1)
Block(2,3,4,LOG:1)
Block(2,4,-7,LOG:1)
Block(2,4,4,LOG:1)
Block(2,5,-7,LOG:1)
Block(2,5,-3,LOG:5)
Block(2,5,0,LOG:5)
Block(2,5,4,LOG:1)
Block(2,6,-7,LOG:1)
Block(2,6,4,LOG:1)
Block(2,7,-7,LOG:1)
Block(2,7,4,LOG:1)
Block(2,8,-7,LOG:1)
Block(2,8,-3,LOG:5)
Block(2,8,0,LOG:5)
Block(2,8,4,LOG:1)
Block(2,9,-7,LOG:1)
Block(2,9,4,LOG:1)
Block(2,10,-7,LOG:1)
Block(2,10,4,LOG:1)
Block(2,11,-7,LOG:1)
Block(2,11,-3,LOG:5)
Block(2,11,0,LOG:5)
Block(2,11,4,LOG:1)
Block(2,12,-7,LOG:1)
Block(2,12,4,LOG:1)
Block(2,13,-7,LOG:1)
Block(2,13,4,LOG:1)
Block(2,14,-7,LOG:1)
Block(2,14,-3,LOG:5)
Block(2,14,0,LOG:5)
Block(2,14,4,LOG:1)
Block(2,15,-7,LOG:1)
Block(2,15,4,LOG:1)
Block(2,16,-7,LOG:1)
Block(2,16,4,LOG:1)
Block(2,17,-7,LOG:1)
Block(2,17,-3,LOG:5)
Block(2,17,0,LOG:5)
Block(2,17,4,LOG:1)
Block(2,18,-7,LOG:1)
Block(2,18,4,LOG:1)
Block(2,19,-7,LOG:1)
Block(2,19,4,LOG:1)
Block(2,20,-7,LOG:1)
Block(2,20,-3,LOG:5)
Block(2,20,0,LOG:5)
Block(2,20,4,LOG:1)
Block(2,21,-7,LOG:1)
Block(2,21,4,LOG:1)
Block(2,22,-7,LOG:1)
Block(2,22,4,LOG:1)
Block(2,23,-7,LOG:1)
Block(2,23,-3,LOG:5)
Block(2,23,0,LOG:5)
Block(2,23,4,LOG:1)
Block(2,24,-7,LOG:1)
Block(2,24,4,LOG:1)
Block(2,25,-7,LOG:1)
Block(2,25,4,LOG:1)
Block(2,26,-7,LOG:1)
Block(2,26,-3,LOG:5)
Block(2,26,0,LOG:5)
Block(2,26,4,LOG:1)
Block(2,27,-7,LOG:1)
Block(2,27,4,LOG:1)
Block(2,28,-7,LOG:1)
Block(2,28,4,LOG:1)
Block(2,29,-7,LOG:1)
Block(2,29,-6,WOOD_STEP:9)
Block(2,29,-5,WOOD_STEP:9)
Block(2,29,-4,WOOD_STEP:9)
Block(2,29,-3,LOG:5)
Block(2,29,-2,WOOD_STEP:9)
Block(2,29,-1,WOOD_STEP:9)
Block(2,29,0,LOG:5)
Block(2,29,1,WOOD_STEP:9)
Block(2,29,2,WOOD_STEP:9)
Block(2,29,3,WOOD_STEP:9)
Block(2,29,4,LOG:1)
Block(2,29,5,LOG:9)
Block(2,29,6,STONE_BUTTON:3)
Block(2,30,-7,LOG:1)
Block(2,30,-6,WOOD_DOUBLE_STEP:1)
Block(2,30,-5,WOOD_DOUBLE_STEP:1)
Block(2,30,-4,WOOD_DOUBLE_STEP:1)
Block(2,30,-3,WOOD_DOUBLE_STEP:1)
RandomBlock(2,30,-2,minecraft:coal_ore,10,minecraft:iron_ore,10,biomesoplenty:gem_ore:1,10,biomesoplenty:gem_ore:2,10,biomesoplenty:gem_ore:3,10,biomesoplenty:gem_ore:4,10,biomesoplenty:gem_ore:5,10,iceandfire:sapphire_ore,10,biomesoplenty:gem_ore:7,10,biomesoplenty:gem_ore:0,10,minecraft:redstone_ore,20,minecraft:gold_ore,20,minecraft:lapis_ore,20,minecraft:diamond_ore,40,minecraft:emerald_ore,40,iceandfire:sapphire_ore,40,iceandfire:silver_ore,80,scalinghealth:crystalore,100)
Block(2,30,-1,CARPET:14)
Block(2,30,0,variedcommodities:stool:5,../NBT/Trader_Swamp/392-variedcommodities_stoolC16R16.nbt)
Block(2,30,1,CARPET:14)
Block(2,30,2,CARPET:0)
Block(2,30,3,CAULDRON:3,../NBT/Trader_Swamp/393-inspirations_cauldronC16R16.nbt)
Block(2,30,4,LOG:1)
Block(2,30,5,COBBLE_WALL:0)
Block(2,30,6,AIR:0)
Block(2,30,7,AIR:0)
Block(2,31,-7,LOG:1)
Block(2,31,-6,AIR:0)
Block(2,31,-5,AIR:0)
Block(2,31,-4,AIR:0)
Block(2,31,-3,WOOD_STEP:1)
Block(2,31,-2,WOOD_STEP:9)
Block(2,31,-1,AIR:0)
Block(2,31,0,AIR:0)
Block(2,31,1,AIR:0)
Block(2,31,2,AIR:0)
Block(2,31,3,AIR:0)
Block(2,31,4,LOG:1)
Block(2,31,5,DARK_OAK_FENCE:0)
Block(2,31,6,AIR:0)
Block(2,31,7,AIR:0)
Block(2,32,-7,LOG:1)
Block(2,32,-6,AIR:0)
Block(2,32,-5,AIR:0)
Block(2,32,-4,AIR:0)
Block(2,32,-3,AIR:0)
Block(2,32,-2,AIR:0)
Block(2,32,-1,WOOD_STEP:1)
Block(2,32,0,WOOD_STEP:9)
Block(2,32,1,AIR:0)
Block(2,32,2,AIR:0)
Block(2,32,3,AIR:0)
Block(2,32,4,LOG:1)
Block(2,32,5,DARK_OAK_FENCE:0)
Block(2,32,6,AIR:0)
Block(2,32,7,AIR:0)
Block(2,33,-7,LOG:1)
Block(2,33,-6,AIR:0)
Block(2,33,-5,AIR:0)
Block(2,33,-4,AIR:0)
Block(2,33,-3,AIR:0)
Block(2,33,-2,AIR:0)
Block(2,33,-1,AIR:0)
Block(2,33,0,AIR:0)
Block(2,33,1,WOOD_STEP:1)
Block(2,33,2,WOOD_STEP:9)
Block(2,33,3,AIR:0)
Block(2,33,4,LOG:1)
Block(2,33,5,COBBLE_WALL:0)
Block(2,33,6,AIR:0)
Block(2,33,7,AIR:0)
Block(2,34,-7,LOG:1)
Block(2,34,-6,WOOD_STEP:9)
Block(2,34,-5,WOOD_STEP:9)
Block(2,34,-4,WOOD_STEP:9)
Block(2,34,-3,LOG:5)
Block(2,34,-2,AIR:0)
Block(2,34,-1,AIR:0)
Block(2,34,0,AIR:0)
Block(2,34,1,AIR:0)
Block(2,34,2,AIR:0)
Block(2,34,3,WOOD_STEP:1)
Block(2,34,4,LOG:1)
Block(2,34,5,LOG:9)
Block(2,34,6,STONE_BUTTON:3)
Block(2,34,7,AIR:0)
Block(2,35,-7,LOG:1)
Block(2,35,-6,rustic:brewing_barrel:0,../NBT/Trader_Swamp/394-rustic_tileentitybrewingbarrelC16R16.nbt)
Block(2,35,-5,AIR:0)
Block(2,35,-4,AIR:0)
Block(2,35,-3,WOOD_STEP:9)
Block(2,35,-2,AIR:0)
Block(2,35,-1,AIR:0)
Block(2,35,0,AIR:0)
Block(2,35,1,AIR:0)
Block(2,35,2,AIR:0)
Block(2,35,3,AIR:0)
Block(2,35,4,LOG:1)
Block(2,35,5,COBBLE_WALL:0)
Block(2,35,6,AIR:0)
Block(2,35,7,AIR:0)
Block(2,36,-7,LOG:1)
Block(2,36,-6,AIR:0)
Block(2,36,-5,AIR:0)
Block(2,36,-4,AIR:0)
Block(2,36,-3,FLOWER_POT:0,../NBT/Trader_Swamp/395-flower_potC16R16.nbt)
Block(2,36,-2,AIR:0)
Block(2,36,-1,AIR:0)
Block(2,36,0,inspirations:rope)
Block(2,36,1,AIR:0)
Block(2,36,2,AIR:0)
Block(2,36,3,AIR:0)
Block(2,36,4,LOG:1)
Block(2,36,5,AIR:0)
Block(2,36,6,AIR:0)
Block(2,36,7,AIR:0)
Block(2,37,-7,LOG:1)
Block(2,37,-6,variedcommodities:shelf:5,../NBT/Trader_Swamp/396-variedcommodities_shelfC16R16.nbt)
Block(2,37,-5,AIR:0)
Block(2,37,-4,AIR:0)
Block(2,37,-3,IRON_FENCE:0)
Block(2,37,-2,AIR:0)
Block(2,37,-1,AIR:0)
Block(2,37,0,inspirations:rope)
Block(2,37,1,AIR:0)
Block(2,37,2,AIR:0)
Block(2,37,3,AIR:0)
Block(2,37,4,LOG:1)
Block(2,37,5,AIR:0)
Block(2,37,6,AIR:0)
Block(2,37,7,AIR:0)
Block(2,38,-7,LOG:1)
Block(2,38,-6,rustic:brewing_barrel:0,../NBT/Trader_Swamp/397-rustic_tileentitybrewingbarrelC16R16.nbt)
Block(2,38,-5,AIR:0)
Block(2,38,-4,AIR:0)
Block(2,38,-3,WOOD_STEP:9)
Block(2,38,-2,WALL_BANNER:3,../NBT/Trader_Swamp/398-bannerC16R16.nbt)
Block(2,38,-1,AIR:0)
Block(2,38,0,inspirations:rope)
Block(2,38,1,AIR:0)
Block(2,38,2,AIR:0)
Block(2,38,3,AIR:0)
Block(2,38,4,LOG:1)
Block(2,38,5,inspirations:rope)
Block(2,39,-7,LOG:1)
Block(2,39,-6,rustic:brewing_barrel:0,../NBT/Trader_Swamp/399-rustic_tileentitybrewingbarrelC16R16.nbt)
Block(2,39,-5,AIR:0)
Block(2,39,-4,AIR:0)
Block(2,39,-3,LOG:5)
Block(2,39,-2,AIR:0)
Block(2,39,-1,AIR:0)
Block(2,39,0,LOG:5)
Block(2,39,1,AIR:0)
Block(2,39,2,AIR:0)
Block(2,39,3,AIR:0)
Block(2,39,4,LOG:1)
Block(2,39,5,WOOD_STEP:1)
