
#######################################################################
# +-----------------------------------------------------------------+ #
# |                            BO3 object                           | #
# +-----------------------------------------------------------------+ #
#######################################################################

Author: NLBlackEagle

Description: No description given

Version: 3

SettingsMode: WriteWithoutComments


#######################################################################
# +-----------------------------------------------------------------+ #
# |                          Main settings                          | #
# +-----------------------------------------------------------------+ #
#######################################################################

Tree: true

Frequency: 0

Rarity: 100.0

RotateRandomly: false

SpawnHeight: randomY

SpawnHeightOffset: 0

SpawnHeightVariance: 0

##############################
# Height Limits for the BO3. #
##############################

MinHeight: 70

MaxHeight: 255

######################
# Extrusion settings #
######################

ExtrudeMode: None

ExtrudeThroughBlocks: AIR

MaxBranchDepth: 10

ExcludedBiomes: All


#######################################################################
# +-----------------------------------------------------------------+ #
# |                      Source block settings                      | #
# +-----------------------------------------------------------------+ #
#######################################################################

SourceBlocks: CONCRETE:8

MaxPercentageOutsideSourceBlock: 100

OutsideSourceBlock: dontPlace

DoReplaceBlocks: true

IsOTGPlus: false


#######################################################################
# +-----------------------------------------------------------------+ #
# |                              Blocks                             | #
# +-----------------------------------------------------------------+ #
#######################################################################

RandomBlock(-14,14,1,CONCRETE:8,30,IRON_FENCE,30,CONCRETE:8,100)
RandomBlock(-13,9,-1,CONCRETE:8,30,IRON_FENCE,30,CONCRETE:8,100)
RandomBlock(-13,9,0,CONCRETE:8,30,IRON_FENCE,30,CONCRETE:8,100)
RandomBlock(-13,9,1,CONCRETE:8,30,IRON_FENCE,30,CONCRETE:8,100)
RandomBlock(-13,9,2,CONCRETE:8,30,IRON_FENCE,30,CONCRETE:8,100)
RandomBlock(-13,9,3,CONCRETE:8,30,IRON_FENCE,30,CONCRETE:8,100)
RandomBlock(-13,10,-2,CONCRETE:8,30,IRON_FENCE,30,CONCRETE:8,100)
RandomBlock(-13,10,-1,CONCRETE:8,30,IRON_FENCE,30,CONCRETE:8,100)
RandomBlock(-13,10,0,CONCRETE:8,30,IRON_FENCE,30,CONCRETE:8,100)
RandomBlock(-13,10,1,CONCRETE:8,30,IRON_FENCE,30,CONCRETE:8,100)
RandomBlock(-13,10,2,CONCRETE:8,30,IRON_FENCE,30,CONCRETE:8,100)
RandomBlock(-13,10,3,CONCRETE:8,30,IRON_FENCE,30,CONCRETE:8,100)
RandomBlock(-13,10,4,CONCRETE:8,30,IRON_FENCE,30,CONCRETE:8,100)
RandomBlock(-13,11,-3,CONCRETE:8,30,IRON_FENCE,30,CONCRETE:8,100)
RandomBlock(-13,11,-2,CONCRETE:8,30,IRON_FENCE,30,CONCRETE:8,100)
RandomBlock(-13,11,-1,CONCRETE:8,30,IRON_FENCE,30,CONCRETE:8,100)
RandomBlock(-13,11,0,CONCRETE:8,30,IRON_FENCE,30,CONCRETE:8,100)
RandomBlock(-13,11,1,CONCRETE:8,30,IRON_FENCE,30,CONCRETE:8,100)
RandomBlock(-13,11,2,CONCRETE:8,30,IRON_FENCE,30,CONCRETE:8,100)
RandomBlock(-13,11,3,CONCRETE:8,30,IRON_FENCE,30,CONCRETE:8,100)
RandomBlock(-13,11,4,CONCRETE:8,30,IRON_FENCE,30,CONCRETE:8,100)
RandomBlock(-13,11,5,CONCRETE:8,30,IRON_FENCE,30,CONCRETE:8,100)
RandomBlock(-13,12,-4,CONCRETE:8,30,IRON_FENCE,30,CONCRETE:8,100)
RandomBlock(-13,12,-3,CONCRETE:8,30,IRON_FENCE,30,CONCRETE:8,100)
RandomBlock(-13,12,-2,CONCRETE:8,30,IRON_FENCE,30,CONCRETE:8,100)
RandomBlock(-13,12,-1,CONCRETE:8,30,IRON_FENCE,30,CONCRETE:8,100)
RandomBlock(-13,12,0,CONCRETE:8,30,IRON_FENCE,30,CONCRETE:8,100)
RandomBlock(-13,12,1,CONCRETE:8,30,IRON_FENCE,30,CONCRETE:8,100)
RandomBlock(-13,12,2,CONCRETE:8,30,IRON_FENCE,30,CONCRETE:8,100)
RandomBlock(-13,12,3,CONCRETE:8,30,IRON_FENCE,30,CONCRETE:8,100)
RandomBlock(-13,12,4,CONCRETE:8,30,IRON_FENCE,30,CONCRETE:8,100)
RandomBlock(-13,12,5,CONCRETE:8,30,IRON_FENCE,30,CONCRETE:8,100)
RandomBlock(-13,12,6,CONCRETE:8,30,IRON_FENCE,30,CONCRETE:8,100)
RandomBlock(-13,13,-4,CONCRETE:8,30,IRON_FENCE,30,CONCRETE:8,100)
RandomBlock(-13,13,-3,CONCRETE:8,30,IRON_FENCE,30,CONCRETE:8,100)
RandomBlock(-13,13,-2,CONCRETE:8,30,IRON_FENCE,30,CONCRETE:8,100)
RandomBlock(-13,13,-1,CONCRETE:8,30,IRON_FENCE,30,CONCRETE:8,100)
RandomBlock(-13,13,0,CONCRETE:8,30,IRON_FENCE,30,CONCRETE:8,100)
RandomBlock(-13,13,1,CONCRETE:8,30,IRON_FENCE,30,CONCRETE:8,100)
RandomBlock(-13,13,2,CONCRETE:8,30,IRON_FENCE,30,CONCRETE:8,100)
RandomBlock(-13,13,3,CONCRETE:8,30,IRON_FENCE,30,CONCRETE:8,100)
RandomBlock(-13,13,4,CONCRETE:8,30,IRON_FENCE,30,CONCRETE:8,100)
RandomBlock(-13,13,5,CONCRETE:8,30,IRON_FENCE,30,CONCRETE:8,100)
RandomBlock(-13,13,6,CONCRETE:8,30,IRON_FENCE,30,CONCRETE:8,100)
RandomBlock(-13,14,-4,CONCRETE:8,30,IRON_FENCE,30,CONCRETE:8,100)
RandomBlock(-13,14,-3,CONCRETE:8,30,IRON_FENCE,30,CONCRETE:8,100)
RandomBlock(-13,14,-2,CONCRETE:8,30,IRON_FENCE,30,CONCRETE:8,100)
RandomBlock(-13,14,-1,CONCRETE:8,30,IRON_FENCE,30,CONCRETE:8,100)
RandomBlock(-13,14,0,CONCRETE:8,30,IRON_FENCE,30,CONCRETE:8,100)
RandomBlock(-13,14,1,CONCRETE:8,30,IRON_FENCE,30,CONCRETE:8,100)
RandomBlock(-13,14,2,CONCRETE:8,30,IRON_FENCE,30,CONCRETE:8,100)
RandomBlock(-13,14,3,CONCRETE:8,30,IRON_FENCE,30,CONCRETE:8,100)
RandomBlock(-13,14,4,CONCRETE:8,30,IRON_FENCE,30,CONCRETE:8,100)
RandomBlock(-13,14,5,CONCRETE:8,30,IRON_FENCE,30,CONCRETE:8,100)
RandomBlock(-13,14,6,CONCRETE:8,30,IRON_FENCE,30,CONCRETE:8,100)
RandomBlock(-13,15,-4,CONCRETE:8,30,IRON_FENCE,30,CONCRETE:8,100)
RandomBlock(-13,15,-3,CONCRETE:8,30,IRON_FENCE,30,CONCRETE:8,100)
RandomBlock(-13,15,-2,CONCRETE:8,30,IRON_FENCE,30,CONCRETE:8,100)
RandomBlock(-13,15,-1,CONCRETE:8,30,IRON_FENCE,30,CONCRETE:8,100)
RandomBlock(-13,15,0,CONCRETE:8,30,IRON_FENCE,30,CONCRETE:8,100)
RandomBlock(-13,15,1,CONCRETE:8,30,IRON_FENCE,30,CONCRETE:8,100)
RandomBlock(-13,15,2,CONCRETE:8,30,IRON_FENCE,30,CONCRETE:8,100)
RandomBlock(-13,15,3,CONCRETE:8,30,IRON_FENCE,30,CONCRETE:8,100)
RandomBlock(-13,15,4,CONCRETE:8,30,IRON_FENCE,30,CONCRETE:8,100)
RandomBlock(-13,15,5,CONCRETE:8,30,IRON_FENCE,30,CONCRETE:8,100)
RandomBlock(-13,15,6,CONCRETE:8,30,IRON_FENCE,30,CONCRETE:8,100)
RandomBlock(-13,16,-4,CONCRETE:8,30,IRON_FENCE,30,CONCRETE:8,100)
RandomBlock(-13,16,-3,CONCRETE:8,30,IRON_FENCE,30,CONCRETE:8,100)
RandomBlock(-13,16,-2,CONCRETE:8,30,IRON_FENCE,30,CONCRETE:8,100)
RandomBlock(-13,16,-1,CONCRETE:8,30,IRON_FENCE,30,CONCRETE:8,100)
RandomBlock(-13,16,0,CONCRETE:8,30,IRON_FENCE,30,CONCRETE:8,100)
RandomBlock(-13,16,1,CONCRETE:8,30,IRON_FENCE,30,CONCRETE:8,100)
RandomBlock(-13,16,2,CONCRETE:8,30,IRON_FENCE,30,CONCRETE:8,100)
RandomBlock(-13,16,3,CONCRETE:8,30,IRON_FENCE,30,CONCRETE:8,100)
RandomBlock(-13,16,4,CONCRETE:8,30,IRON_FENCE,30,CONCRETE:8,100)
RandomBlock(-13,16,5,CONCRETE:8,30,IRON_FENCE,30,CONCRETE:8,100)
RandomBlock(-13,16,6,CONCRETE:8,30,IRON_FENCE,30,CONCRETE:8,100)
RandomBlock(-13,17,-3,CONCRETE:8,30,IRON_FENCE,30,CONCRETE:8,100)
RandomBlock(-13,17,-2,CONCRETE:8,30,IRON_FENCE,30,CONCRETE:8,100)
RandomBlock(-13,17,-1,CONCRETE:8,30,IRON_FENCE,30,CONCRETE:8,100)
RandomBlock(-13,17,0,CONCRETE:8,30,IRON_FENCE,30,CONCRETE:8,100)
RandomBlock(-13,17,1,CONCRETE:8,30,IRON_FENCE,30,CONCRETE:8,100)
RandomBlock(-13,17,2,CONCRETE:8,30,IRON_FENCE,30,CONCRETE:8,100)
RandomBlock(-13,17,3,CONCRETE:8,30,IRON_FENCE,30,CONCRETE:8,100)
RandomBlock(-13,17,4,CONCRETE:8,30,IRON_FENCE,30,CONCRETE:8,100)
RandomBlock(-13,17,5,CONCRETE:8,30,IRON_FENCE,30,CONCRETE:8,100)
RandomBlock(-13,18,-2,CONCRETE:8,30,IRON_FENCE,30,CONCRETE:8,100)
RandomBlock(-13,18,-1,CONCRETE:8,30,IRON_FENCE,30,CONCRETE:8,100)
RandomBlock(-13,18,0,CONCRETE:8,30,IRON_FENCE,30,CONCRETE:8,100)
RandomBlock(-13,18,1,CONCRETE:8,30,IRON_FENCE,30,CONCRETE:8,100)
RandomBlock(-13,18,2,CONCRETE:8,30,IRON_FENCE,30,CONCRETE:8,100)
RandomBlock(-13,18,3,CONCRETE:8,30,IRON_FENCE,30,CONCRETE:8,100)
RandomBlock(-13,18,4,CONCRETE:8,30,IRON_FENCE,30,CONCRETE:8,100)
RandomBlock(-13,19,-1,CONCRETE:8,30,IRON_FENCE,30,CONCRETE:8,100)
RandomBlock(-13,19,0,CONCRETE:8,30,IRON_FENCE,30,CONCRETE:8,100)
RandomBlock(-13,19,1,CONCRETE:8,30,IRON_FENCE,30,CONCRETE:8,100)
RandomBlock(-13,19,2,CONCRETE:8,30,IRON_FENCE,30,CONCRETE:8,100)
RandomBlock(-13,19,3,CONCRETE:8,30,IRON_FENCE,30,CONCRETE:8,100)
RandomBlock(-12,7,-1,CONCRETE:8,30,IRON_FENCE,30,CONCRETE:8,100)
RandomBlock(-12,7,0,CONCRETE:8,30,IRON_FENCE,30,CONCRETE:8,100)
RandomBlock(-12,7,1,CONCRETE:8,30,IRON_FENCE,30,CONCRETE:8,100)
RandomBlock(-12,7,2,CONCRETE:8,30,IRON_FENCE,30,CONCRETE:8,100)
RandomBlock(-12,7,3,CONCRETE:8,30,IRON_FENCE,30,CONCRETE:8,100)
RandomBlock(-12,8,-3,CONCRETE:8,30,IRON_FENCE,30,CONCRETE:8,100)
RandomBlock(-12,8,-2,CONCRETE:8,30,IRON_FENCE,30,CONCRETE:8,100)
RandomBlock(-12,8,-1,CONCRETE:8,30,IRON_FENCE,30,CONCRETE:8,100)
RandomBlock(-12,8,0,CONCRETE:8,30,IRON_FENCE,30,CONCRETE:8,100)
RandomBlock(-12,8,1,CONCRETE:8,30,IRON_FENCE,30,CONCRETE:8,100)
RandomBlock(-12,8,2,CONCRETE:8,30,IRON_FENCE,30,CONCRETE:8,100)
RandomBlock(-12,8,3,CONCRETE:8,30,IRON_FENCE,30,CONCRETE:8,100)
RandomBlock(-12,8,4,CONCRETE:8,30,IRON_FENCE,30,CONCRETE:8,100)
RandomBlock(-12,8,5,CONCRETE:8,30,IRON_FENCE,30,CONCRETE:8,100)
RandomBlock(-12,9,-4,CONCRETE:8,30,IRON_FENCE,30,CONCRETE:8,100)
RandomBlock(-12,9,-3,CONCRETE:8,30,IRON_FENCE,30,CONCRETE:8,100)
RandomBlock(-12,9,-2,CONCRETE:8,30,IRON_FENCE,30,CONCRETE:8,100)
RandomBlock(-12,9,-1,CONCRETE:8,30,IRON_FENCE,30,CONCRETE:8,100)
RandomBlock(-12,9,0,CONCRETE:8,30,IRON_FENCE,30,CONCRETE:8,100)
RandomBlock(-12,9,1,CONCRETE:8,30,IRON_FENCE,30,CONCRETE:8,100)
RandomBlock(-12,9,2,CONCRETE:8,30,IRON_FENCE,30,CONCRETE:8,100)
RandomBlock(-12,9,3,CONCRETE:8,30,IRON_FENCE,30,CONCRETE:8,100)
RandomBlock(-12,9,4,CONCRETE:8,30,IRON_FENCE,30,CONCRETE:8,100)
RandomBlock(-12,9,5,CONCRETE:8,30,IRON_FENCE,30,CONCRETE:8,100)
RandomBlock(-12,9,6,CONCRETE:8,30,IRON_FENCE,30,CONCRETE:8,100)
RandomBlock(-12,10,-5,CONCRETE:8,30,IRON_FENCE,30,CONCRETE:8,100)
RandomBlock(-12,10,-4,CONCRETE:8,30,IRON_FENCE,30,CONCRETE:8,100)
RandomBlock(-12,10,-3,CONCRETE:8,30,IRON_FENCE,30,CONCRETE:8,100)
RandomBlock(-12,10,-2,CONCRETE:8,30,IRON_FENCE,30,CONCRETE:8,100)
RandomBlock(-12,10,-1,CONCRETE:8,30,IRON_FENCE,30,CONCRETE:8,100)
RandomBlock(-12,10,0,CONCRETE:8,30,IRON_FENCE,30,CONCRETE:8,100)
RandomBlock(-12,10,1,CONCRETE:8,30,IRON_FENCE,30,CONCRETE:8,100)
RandomBlock(-12,10,2,CONCRETE:8,30,IRON_FENCE,30,CONCRETE:8,100)
RandomBlock(-12,10,3,CONCRETE:8,30,IRON_FENCE,30,CONCRETE:8,100)
RandomBlock(-12,10,4,CONCRETE:8,30,IRON_FENCE,30,CONCRETE:8,100)
RandomBlock(-12,10,5,CONCRETE:8,30,IRON_FENCE,30,CONCRETE:8,100)
RandomBlock(-12,10,6,CONCRETE:8,30,IRON_FENCE,30,CONCRETE:8,100)
RandomBlock(-12,10,7,CONCRETE:8,30,IRON_FENCE,30,CONCRETE:8,100)
RandomBlock(-12,11,-5,CONCRETE:8,30,IRON_FENCE,30,CONCRETE:8,100)
RandomBlock(-12,11,-4,CONCRETE:8,30,IRON_FENCE,30,CONCRETE:8,100)
RandomBlock(-12,11,-3,CONCRETE:8,30,IRON_FENCE,30,CONCRETE:8,100)
RandomBlock(-12,11,-2,CONCRETE:8,30,IRON_FENCE,30,CONCRETE:8,100)
RandomBlock(-12,11,-1,CONCRETE:8,30,IRON_FENCE,30,CONCRETE:8,100)
RandomBlock(-12,11,0,CONCRETE:8,30,IRON_FENCE,30,CONCRETE:8,100)
RandomBlock(-12,11,1,CONCRETE:8,30,IRON_FENCE,30,CONCRETE:8,100)
RandomBlock(-12,11,2,CONCRETE:8,30,IRON_FENCE,30,CONCRETE:8,100)
RandomBlock(-12,11,3,CONCRETE:8,30,IRON_FENCE,30,CONCRETE:8,100)
RandomBlock(-12,11,4,CONCRETE:8,30,IRON_FENCE,30,CONCRETE:8,100)
RandomBlock(-12,11,5,CONCRETE:8,30,IRON_FENCE,30,CONCRETE:8,100)
RandomBlock(-12,11,6,CONCRETE:8,30,IRON_FENCE,30,CONCRETE:8,100)
RandomBlock(-12,11,7,CONCRETE:8,30,IRON_FENCE,30,CONCRETE:8,100)
RandomBlock(-12,12,-6,CONCRETE:8,30,IRON_FENCE,30,CONCRETE:8,100)
RandomBlock(-12,12,-5,CONCRETE:8,30,IRON_FENCE,30,CONCRETE:8,100)
RandomBlock(-12,12,-4,CONCRETE:8,30,IRON_FENCE,30,CONCRETE:8,100)
RandomBlock(-12,12,-3,CONCRETE:8,30,IRON_FENCE,30,CONCRETE:8,100)
RandomBlock(-12,12,-2,CONCRETE:8,30,IRON_FENCE,30,CONCRETE:8,100)
RandomBlock(-12,12,-1,CONCRETE:8,30,IRON_FENCE,30,CONCRETE:8,100)
RandomBlock(-12,12,0,CONCRETE:8,30,IRON_FENCE,30,CONCRETE:8,100)
RandomBlock(-12,12,1,CONCRETE:8,30,IRON_FENCE,30,CONCRETE:8,100)
RandomBlock(-12,12,2,CONCRETE:8,30,IRON_FENCE,30,CONCRETE:8,100)
RandomBlock(-12,12,3,CONCRETE:8,30,IRON_FENCE,30,CONCRETE:8,100)
RandomBlock(-12,12,4,CONCRETE:8,30,IRON_FENCE,30,CONCRETE:8,100)
RandomBlock(-12,12,5,CONCRETE:8,30,IRON_FENCE,30,CONCRETE:8,100)
RandomBlock(-12,12,6,CONCRETE:8,30,IRON_FENCE,30,CONCRETE:8,100)
RandomBlock(-12,12,7,CONCRETE:8,30,IRON_FENCE,30,CONCRETE:8,100)
RandomBlock(-12,12,8,CONCRETE:8,30,IRON_FENCE,30,CONCRETE:8,100)
RandomBlock(-12,13,-6,CONCRETE:8,30,IRON_FENCE,30,CONCRETE:8,100)
RandomBlock(-12,13,-5,CONCRETE:8,30,IRON_FENCE,30,CONCRETE:8,100)
RandomBlock(-12,13,-4,CONCRETE:8,30,IRON_FENCE,30,CONCRETE:8,100)
RandomBlock(-12,13,-3,CONCRETE:8,30,IRON_FENCE,30,CONCRETE:8,100)
RandomBlock(-12,13,-2,CONCRETE:8,30,IRON_FENCE,30,CONCRETE:8,100)
RandomBlock(-12,13,-1,CONCRETE:8,30,IRON_FENCE,30,CONCRETE:8,100)
RandomBlock(-12,13,0,CONCRETE:8,30,IRON_FENCE,30,CONCRETE:8,100)
RandomBlock(-12,13,1,CONCRETE:8,30,IRON_FENCE,30,CONCRETE:8,100)
RandomBlock(-12,13,2,CONCRETE:8,30,IRON_FENCE,30,CONCRETE:8,100)
RandomBlock(-12,13,3,CONCRETE:8,30,IRON_FENCE,30,CONCRETE:8,100)
RandomBlock(-12,13,4,CONCRETE:8,30,IRON_FENCE,30,CONCRETE:8,100)
RandomBlock(-12,13,5,CONCRETE:8,30,IRON_FENCE,30,CONCRETE:8,100)
RandomBlock(-12,13,6,CONCRETE:8,30,IRON_FENCE,30,CONCRETE:8,100)
RandomBlock(-12,13,7,CONCRETE:8,30,IRON_FENCE,30,CONCRETE:8,100)
RandomBlock(-12,13,8,CONCRETE:8,30,IRON_FENCE,30,CONCRETE:8,100)
RandomBlock(-12,14,-6,CONCRETE:8,30,IRON_FENCE,30,CONCRETE:8,100)
RandomBlock(-12,14,-5,CONCRETE:8,30,IRON_FENCE,30,CONCRETE:8,100)
RandomBlock(-12,14,-4,CONCRETE:8,30,IRON_FENCE,30,CONCRETE:8,100)
RandomBlock(-12,14,-3,CONCRETE:8,30,IRON_FENCE,30,CONCRETE:8,100)
RandomBlock(-12,14,-2,CONCRETE:8,30,IRON_FENCE,30,CONCRETE:8,100)
RandomBlock(-12,14,-1,CONCRETE:8,30,IRON_FENCE,30,CONCRETE:8,100)
RandomBlock(-12,14,0,CONCRETE:8,30,IRON_FENCE,30,CONCRETE:8,100)
RandomBlock(-12,14,1,CONCRETE:8,30,IRON_FENCE,30,CONCRETE:8,100)
RandomBlock(-12,14,2,CONCRETE:8,30,IRON_FENCE,30,CONCRETE:8,100)
RandomBlock(-12,14,3,CONCRETE:8,30,IRON_FENCE,30,CONCRETE:8,100)
RandomBlock(-12,14,4,CONCRETE:8,30,IRON_FENCE,30,CONCRETE:8,100)
RandomBlock(-12,14,5,CONCRETE:8,30,IRON_FENCE,30,CONCRETE:8,100)
RandomBlock(-12,14,6,CONCRETE:8,30,IRON_FENCE,30,CONCRETE:8,100)
RandomBlock(-12,14,7,CONCRETE:8,30,IRON_FENCE,30,CONCRETE:8,100)
RandomBlock(-12,14,8,CONCRETE:8,30,IRON_FENCE,30,CONCRETE:8,100)
RandomBlock(-12,15,-6,CONCRETE:8,30,IRON_FENCE,30,CONCRETE:8,100)
RandomBlock(-12,15,-5,CONCRETE:8,30,IRON_FENCE,30,CONCRETE:8,100)
RandomBlock(-12,15,-4,CONCRETE:8,30,IRON_FENCE,30,CONCRETE:8,100)
RandomBlock(-12,15,-3,CONCRETE:8,30,IRON_FENCE,30,CONCRETE:8,100)
RandomBlock(-12,15,-2,CONCRETE:8,30,IRON_FENCE,30,CONCRETE:8,100)
RandomBlock(-12,15,-1,CONCRETE:8,30,IRON_FENCE,30,CONCRETE:8,100)
RandomBlock(-12,15,0,CONCRETE:8,30,IRON_FENCE,30,CONCRETE:8,100)
RandomBlock(-12,15,1,CONCRETE:8,30,IRON_FENCE,30,CONCRETE:8,100)
RandomBlock(-12,15,2,CONCRETE:8,30,IRON_FENCE,30,CONCRETE:8,100)
RandomBlock(-12,15,3,CONCRETE:8,30,IRON_FENCE,30,CONCRETE:8,100)
RandomBlock(-12,15,4,CONCRETE:8,30,IRON_FENCE,30,CONCRETE:8,100)
RandomBlock(-12,15,5,CONCRETE:8,30,IRON_FENCE,30,CONCRETE:8,100)
RandomBlock(-12,15,6,CONCRETE:8,30,IRON_FENCE,30,CONCRETE:8,100)
RandomBlock(-12,15,7,CONCRETE:8,30,IRON_FENCE,30,CONCRETE:8,100)
RandomBlock(-12,15,8,CONCRETE:8,30,IRON_FENCE,30,CONCRETE:8,100)
RandomBlock(-12,16,-6,CONCRETE:8,30,IRON_FENCE,30,CONCRETE:8,100)
RandomBlock(-12,16,-5,CONCRETE:8,30,IRON_FENCE,30,CONCRETE:8,100)
RandomBlock(-12,16,-4,CONCRETE:8,30,IRON_FENCE,30,CONCRETE:8,100)
RandomBlock(-12,16,-3,CONCRETE:8,30,IRON_FENCE,30,CONCRETE:8,100)
RandomBlock(-12,16,-2,CONCRETE:8,30,IRON_FENCE,30,CONCRETE:8,100)
RandomBlock(-12,16,-1,CONCRETE:8,30,IRON_FENCE,30,CONCRETE:8,100)
RandomBlock(-12,16,0,CONCRETE:8,30,IRON_FENCE,30,CONCRETE:8,100)
RandomBlock(-12,16,1,CONCRETE:8,30,IRON_FENCE,30,CONCRETE:8,100)
RandomBlock(-12,16,2,CONCRETE:8,30,IRON_FENCE,30,CONCRETE:8,100)
RandomBlock(-12,16,3,CONCRETE:8,30,IRON_FENCE,30,CONCRETE:8,100)
RandomBlock(-12,16,4,CONCRETE:8,30,IRON_FENCE,30,CONCRETE:8,100)
RandomBlock(-12,16,5,CONCRETE:8,30,IRON_FENCE,30,CONCRETE:8,100)
RandomBlock(-12,16,6,CONCRETE:8,30,IRON_FENCE,30,CONCRETE:8,100)
RandomBlock(-12,16,7,CONCRETE:8,30,IRON_FENCE,30,CONCRETE:8,100)
RandomBlock(-12,16,8,CONCRETE:8,30,IRON_FENCE,30,CONCRETE:8,100)
RandomBlock(-12,17,-5,CONCRETE:8,30,IRON_FENCE,30,CONCRETE:8,100)
RandomBlock(-12,17,-4,CONCRETE:8,30,IRON_FENCE,30,CONCRETE:8,100)
RandomBlock(-12,17,-3,CONCRETE:8,30,IRON_FENCE,30,CONCRETE:8,100)
RandomBlock(-12,17,-2,CONCRETE:8,30,IRON_FENCE,30,CONCRETE:8,100)
RandomBlock(-12,17,-1,CONCRETE:8,30,IRON_FENCE,30,CONCRETE:8,100)
RandomBlock(-12,17,0,CONCRETE:8,30,IRON_FENCE,30,CONCRETE:8,100)
RandomBlock(-12,17,1,CONCRETE:8,30,IRON_FENCE,30,CONCRETE:8,100)
RandomBlock(-12,17,2,CONCRETE:8,30,IRON_FENCE,30,CONCRETE:8,100)
RandomBlock(-12,17,3,CONCRETE:8,30,IRON_FENCE,30,CONCRETE:8,100)
RandomBlock(-12,17,4,CONCRETE:8,30,IRON_FENCE,30,CONCRETE:8,100)
RandomBlock(-12,17,5,CONCRETE:8,30,IRON_FENCE,30,CONCRETE:8,100)
RandomBlock(-12,17,6,CONCRETE:8,30,IRON_FENCE,30,CONCRETE:8,100)
RandomBlock(-12,17,7,CONCRETE:8,30,IRON_FENCE,30,CONCRETE:8,100)
RandomBlock(-12,18,-5,CONCRETE:8,30,IRON_FENCE,30,CONCRETE:8,100)
RandomBlock(-12,18,-4,CONCRETE:8,30,IRON_FENCE,30,CONCRETE:8,100)
RandomBlock(-12,18,-3,CONCRETE:8,30,IRON_FENCE,30,CONCRETE:8,100)
RandomBlock(-12,18,-2,CONCRETE:8,30,IRON_FENCE,30,CONCRETE:8,100)
RandomBlock(-12,18,-1,CONCRETE:8,30,IRON_FENCE,30,CONCRETE:8,100)
RandomBlock(-12,18,0,CONCRETE:8,30,IRON_FENCE,30,CONCRETE:8,100)
RandomBlock(-12,18,1,CONCRETE:8,30,IRON_FENCE,30,CONCRETE:8,100)
RandomBlock(-12,18,2,CONCRETE:8,30,IRON_FENCE,30,CONCRETE:8,100)
RandomBlock(-12,18,3,CONCRETE:8,30,IRON_FENCE,30,CONCRETE:8,100)
RandomBlock(-12,18,4,CONCRETE:8,30,IRON_FENCE,30,CONCRETE:8,100)
RandomBlock(-12,18,5,CONCRETE:8,30,IRON_FENCE,30,CONCRETE:8,100)
RandomBlock(-12,18,6,CONCRETE:8,30,IRON_FENCE,30,CONCRETE:8,100)
RandomBlock(-12,18,7,CONCRETE:8,30,IRON_FENCE,30,CONCRETE:8,100)
RandomBlock(-12,19,-4,CONCRETE:8,30,IRON_FENCE,30,CONCRETE:8,100)
RandomBlock(-12,19,-3,CONCRETE:8,30,IRON_FENCE,30,CONCRETE:8,100)
RandomBlock(-12,19,-2,CONCRETE:8,30,IRON_FENCE,30,CONCRETE:8,100)
RandomBlock(-12,19,-1,CONCRETE:8,30,IRON_FENCE,30,CONCRETE:8,100)
RandomBlock(-12,19,0,CONCRETE:8,30,IRON_FENCE,30,CONCRETE:8,100)
RandomBlock(-12,19,1,CONCRETE:8,30,IRON_FENCE,30,CONCRETE:8,100)
RandomBlock(-12,19,2,CONCRETE:8,30,IRON_FENCE,30,CONCRETE:8,100)
RandomBlock(-12,19,3,CONCRETE:8,30,IRON_FENCE,30,CONCRETE:8,100)
RandomBlock(-12,19,4,CONCRETE:8,30,IRON_FENCE,30,CONCRETE:8,100)
RandomBlock(-12,19,5,CONCRETE:8,30,IRON_FENCE,30,CONCRETE:8,100)
RandomBlock(-12,19,6,CONCRETE:8,30,IRON_FENCE,30,CONCRETE:8,100)
RandomBlock(-12,20,-3,CONCRETE:8,30,IRON_FENCE,30,CONCRETE:8,100)
RandomBlock(-12,20,-2,CONCRETE:8,30,IRON_FENCE,30,CONCRETE:8,100)
RandomBlock(-12,20,-1,CONCRETE:8,30,IRON_FENCE,30,CONCRETE:8,100)
RandomBlock(-12,20,0,CONCRETE:8,30,IRON_FENCE,30,CONCRETE:8,100)
RandomBlock(-12,20,1,CONCRETE:8,30,IRON_FENCE,30,CONCRETE:8,100)
RandomBlock(-12,20,2,CONCRETE:8,30,IRON_FENCE,30,CONCRETE:8,100)
RandomBlock(-12,20,3,CONCRETE:8,30,IRON_FENCE,30,CONCRETE:8,100)
RandomBlock(-12,20,4,CONCRETE:8,30,IRON_FENCE,30,CONCRETE:8,100)
RandomBlock(-12,20,5,CONCRETE:8,30,IRON_FENCE,30,CONCRETE:8,100)
RandomBlock(-12,21,-1,CONCRETE:8,30,IRON_FENCE,30,CONCRETE:8,100)
RandomBlock(-12,21,0,CONCRETE:8,30,IRON_FENCE,30,CONCRETE:8,100)
RandomBlock(-12,21,1,CONCRETE:8,30,IRON_FENCE,30,CONCRETE:8,100)
RandomBlock(-12,21,2,CONCRETE:8,30,IRON_FENCE,30,CONCRETE:8,100)
RandomBlock(-12,21,3,CONCRETE:8,30,IRON_FENCE,30,CONCRETE:8,100)
RandomBlock(-11,5,1,CONCRETE:8,30,IRON_FENCE,30,CONCRETE:8,100)
RandomBlock(-11,6,-3,CONCRETE:8,30,IRON_FENCE,30,CONCRETE:8,100)
RandomBlock(-11,6,-2,CONCRETE:8,30,IRON_FENCE,30,CONCRETE:8,100)
RandomBlock(-11,6,-1,CONCRETE:8,30,IRON_FENCE,30,CONCRETE:8,100)
RandomBlock(-11,6,0,CONCRETE:8,30,IRON_FENCE,30,CONCRETE:8,100)
RandomBlock(-11,6,1,CONCRETE:8,30,IRON_FENCE,30,CONCRETE:8,100)
RandomBlock(-11,6,2,CONCRETE:8,30,IRON_FENCE,30,CONCRETE:8,100)
RandomBlock(-11,6,3,CONCRETE:8,30,IRON_FENCE,30,CONCRETE:8,100)
RandomBlock(-11,6,4,CONCRETE:8,30,IRON_FENCE,30,CONCRETE:8,100)
RandomBlock(-11,6,5,CONCRETE:8,30,IRON_FENCE,30,CONCRETE:8,100)
RandomBlock(-11,7,-4,CONCRETE:8,30,IRON_FENCE,30,CONCRETE:8,100)
RandomBlock(-11,7,-3,CONCRETE:8,30,IRON_FENCE,30,CONCRETE:8,100)
RandomBlock(-11,7,-2,CONCRETE:8,30,IRON_FENCE,30,CONCRETE:8,100)
RandomBlock(-11,7,-1,CONCRETE:8,30,IRON_FENCE,30,CONCRETE:8,100)
RandomBlock(-11,7,0,CONCRETE:8,30,IRON_FENCE,30,CONCRETE:8,100)
RandomBlock(-11,7,1,CONCRETE:8,30,IRON_FENCE,30,CONCRETE:8,100)
RandomBlock(-11,7,2,CONCRETE:8,30,IRON_FENCE,30,CONCRETE:8,100)
RandomBlock(-11,7,3,CONCRETE:8,30,IRON_FENCE,30,CONCRETE:8,100)
RandomBlock(-11,7,4,CONCRETE:8,30,IRON_FENCE,30,CONCRETE:8,100)
RandomBlock(-11,7,5,CONCRETE:8,30,IRON_FENCE,30,CONCRETE:8,100)
RandomBlock(-11,7,6,CONCRETE:8,30,IRON_FENCE,30,CONCRETE:8,100)
RandomBlock(-11,8,-5,CONCRETE:8,30,IRON_FENCE,30,CONCRETE:8,100)
RandomBlock(-11,8,-4,CONCRETE:8,30,IRON_FENCE,30,CONCRETE:8,100)
RandomBlock(-11,8,-3,CONCRETE:8,30,IRON_FENCE,30,CONCRETE:8,100)
RandomBlock(-11,8,-2,CONCRETE:8,30,IRON_FENCE,30,CONCRETE:8,100)
RandomBlock(-11,8,-1,CONCRETE:8,30,IRON_FENCE,30,CONCRETE:8,100)
RandomBlock(-11,8,0,CONCRETE:8,30,IRON_FENCE,30,CONCRETE:8,100)
RandomBlock(-11,8,1,CONCRETE:8,30,IRON_FENCE,30,CONCRETE:8,100)
RandomBlock(-11,8,2,CONCRETE:8,30,IRON_FENCE,30,CONCRETE:8,100)
RandomBlock(-11,8,3,CONCRETE:8,30,IRON_FENCE,30,CONCRETE:8,100)
RandomBlock(-11,8,4,CONCRETE:8,30,IRON_FENCE,30,CONCRETE:8,100)
RandomBlock(-11,8,5,CONCRETE:8,30,IRON_FENCE,30,CONCRETE:8,100)
RandomBlock(-11,8,6,CONCRETE:8,30,IRON_FENCE,30,CONCRETE:8,100)
RandomBlock(-11,8,7,CONCRETE:8,30,IRON_FENCE,30,CONCRETE:8,100)
RandomBlock(-11,9,-6,CONCRETE:8,30,IRON_FENCE,30,CONCRETE:8,100)
RandomBlock(-11,9,-5,CONCRETE:8,30,IRON_FENCE,30,CONCRETE:8,100)
RandomBlock(-11,9,-4,CONCRETE:8,30,IRON_FENCE,30,CONCRETE:8,100)
RandomBlock(-11,9,-3,CONCRETE:8,30,IRON_FENCE,30,CONCRETE:8,100)
RandomBlock(-11,9,-2,CONCRETE:8,30,IRON_FENCE,30,CONCRETE:8,100)
RandomBlock(-11,9,-1,CONCRETE:8,30,IRON_FENCE,30,CONCRETE:8,100)
RandomBlock(-11,9,0,CONCRETE:8,30,IRON_FENCE,30,CONCRETE:8,100)
RandomBlock(-11,9,1,CONCRETE:8,30,IRON_FENCE,30,CONCRETE:8,100)
RandomBlock(-11,9,2,CONCRETE:8,30,IRON_FENCE,30,CONCRETE:8,100)
RandomBlock(-11,9,3,CONCRETE:8,30,IRON_FENCE,30,CONCRETE:8,100)
RandomBlock(-11,9,4,CONCRETE:8,30,IRON_FENCE,30,CONCRETE:8,100)
RandomBlock(-11,9,5,CONCRETE:8,30,IRON_FENCE,30,CONCRETE:8,100)
RandomBlock(-11,9,6,CONCRETE:8,30,IRON_FENCE,30,CONCRETE:8,100)
RandomBlock(-11,9,7,CONCRETE:8,30,IRON_FENCE,30,CONCRETE:8,100)
RandomBlock(-11,9,8,CONCRETE:8,30,IRON_FENCE,30,CONCRETE:8,100)
RandomBlock(-11,10,-7,CONCRETE:8,30,IRON_FENCE,30,CONCRETE:8,100)
RandomBlock(-11,10,-6,CONCRETE:8,30,IRON_FENCE,30,CONCRETE:8,100)
RandomBlock(-11,10,-5,CONCRETE:8,30,IRON_FENCE,30,CONCRETE:8,100)
RandomBlock(-11,10,-4,CONCRETE:8,30,IRON_FENCE,30,CONCRETE:8,100)
RandomBlock(-11,10,-3,CONCRETE:8,30,IRON_FENCE,30,CONCRETE:8,100)
RandomBlock(-11,10,-2,CONCRETE:8,30,IRON_FENCE,30,CONCRETE:8,100)
RandomBlock(-11,10,-1,CONCRETE:8,30,IRON_FENCE,30,CONCRETE:8,100)
RandomBlock(-11,10,0,CONCRETE:8,30,IRON_FENCE,30,CONCRETE:8,100)
RandomBlock(-11,10,1,CONCRETE:8,30,IRON_FENCE,30,CONCRETE:8,100)
RandomBlock(-11,10,2,CONCRETE:8,30,IRON_FENCE,30,CONCRETE:8,100)
RandomBlock(-11,10,3,CONCRETE:8,30,IRON_FENCE,30,CONCRETE:8,100)
RandomBlock(-11,10,4,CONCRETE:8,30,IRON_FENCE,30,CONCRETE:8,100)
RandomBlock(-11,10,5,CONCRETE:8,30,IRON_FENCE,30,CONCRETE:8,100)
RandomBlock(-11,10,6,CONCRETE:8,30,IRON_FENCE,30,CONCRETE:8,100)
RandomBlock(-11,10,7,CONCRETE:8,30,IRON_FENCE,30,CONCRETE:8,100)
RandomBlock(-11,10,8,CONCRETE:8,30,IRON_FENCE,30,CONCRETE:8,100)
RandomBlock(-11,10,9,CONCRETE:8,30,IRON_FENCE,30,CONCRETE:8,100)
RandomBlock(-11,11,-7,CONCRETE:8,30,IRON_FENCE,30,CONCRETE:8,100)
RandomBlock(-11,11,-6,CONCRETE:8,30,IRON_FENCE,30,CONCRETE:8,100)
RandomBlock(-11,11,-5,CONCRETE:8,30,IRON_FENCE,30,CONCRETE:8,100)
RandomBlock(-11,11,-4,CONCRETE:8,30,IRON_FENCE,30,CONCRETE:8,100)
RandomBlock(-11,11,-3,CONCRETE:8,30,IRON_FENCE,30,CONCRETE:8,100)
RandomBlock(-11,11,-2,CONCRETE:8,30,IRON_FENCE,30,CONCRETE:8,100)
RandomBlock(-11,11,-1,CONCRETE:8,30,IRON_FENCE,30,CONCRETE:8,100)
RandomBlock(-11,11,0,CONCRETE:8,30,IRON_FENCE,30,CONCRETE:8,100)
RandomBlock(-11,11,1,CONCRETE:8,30,IRON_FENCE,30,CONCRETE:8,100)
RandomBlock(-11,11,2,CONCRETE:8,30,IRON_FENCE,30,CONCRETE:8,100)
RandomBlock(-11,11,3,CONCRETE:8,30,IRON_FENCE,30,CONCRETE:8,100)
RandomBlock(-11,11,4,CONCRETE:8,30,IRON_FENCE,30,CONCRETE:8,100)
RandomBlock(-11,11,5,CONCRETE:8,30,IRON_FENCE,30,CONCRETE:8,100)
RandomBlock(-11,11,6,CONCRETE:8,30,IRON_FENCE,30,CONCRETE:8,100)
RandomBlock(-11,11,7,CONCRETE:8,30,IRON_FENCE,30,CONCRETE:8,100)
RandomBlock(-11,11,8,CONCRETE:8,30,IRON_FENCE,30,CONCRETE:8,100)
RandomBlock(-11,11,9,CONCRETE:8,30,IRON_FENCE,30,CONCRETE:8,100)
RandomBlock(-11,12,-7,CONCRETE:8,30,IRON_FENCE,30,CONCRETE:8,100)
RandomBlock(-11,12,-6,CONCRETE:8,30,IRON_FENCE,30,CONCRETE:8,100)
RandomBlock(-11,12,-5,CONCRETE:8,30,IRON_FENCE,30,CONCRETE:8,100)
RandomBlock(-11,12,-4,CONCRETE:8,30,IRON_FENCE,30,CONCRETE:8,100)
RandomBlock(-11,12,-3,CONCRETE:8,30,IRON_FENCE,30,CONCRETE:8,100)
RandomBlock(-11,12,-2,CONCRETE:8,30,IRON_FENCE,30,CONCRETE:8,100)
RandomBlock(-11,12,-1,CONCRETE:8,30,IRON_FENCE,30,CONCRETE:8,100)
RandomBlock(-11,12,0,CONCRETE:8,30,IRON_FENCE,30,CONCRETE:8,100)
RandomBlock(-11,12,1,CONCRETE:8,30,IRON_FENCE,30,CONCRETE:8,100)
RandomBlock(-11,12,2,CONCRETE:8,30,IRON_FENCE,30,CONCRETE:8,100)
RandomBlock(-11,12,3,CONCRETE:8,30,IRON_FENCE,30,CONCRETE:8,100)
RandomBlock(-11,12,4,CONCRETE:8,30,IRON_FENCE,30,CONCRETE:8,100)
RandomBlock(-11,12,5,CONCRETE:8,30,IRON_FENCE,30,CONCRETE:8,100)
RandomBlock(-11,12,6,CONCRETE:8,30,IRON_FENCE,30,CONCRETE:8,100)
RandomBlock(-11,12,7,CONCRETE:8,30,IRON_FENCE,30,CONCRETE:8,100)
RandomBlock(-11,12,8,CONCRETE:8,30,IRON_FENCE,30,CONCRETE:8,100)
RandomBlock(-11,12,9,CONCRETE:8,30,IRON_FENCE,30,CONCRETE:8,100)
RandomBlock(-11,13,-7,CONCRETE:8,30,IRON_FENCE,30,CONCRETE:8,100)
RandomBlock(-11,13,-6,CONCRETE:8,30,IRON_FENCE,30,CONCRETE:8,100)
RandomBlock(-11,13,-5,CONCRETE:8,30,IRON_FENCE,30,CONCRETE:8,100)
RandomBlock(-11,13,-4,CONCRETE:8,30,IRON_FENCE,30,CONCRETE:8,100)
RandomBlock(-11,13,-3,CONCRETE:8,30,IRON_FENCE,30,CONCRETE:8,100)
RandomBlock(-11,13,-2,CONCRETE:8,30,IRON_FENCE,30,CONCRETE:8,100)
RandomBlock(-11,13,-1,CONCRETE:8,30,IRON_FENCE,30,CONCRETE:8,100)
RandomBlock(-11,13,0,CONCRETE:8,30,IRON_FENCE,30,CONCRETE:8,100)
RandomBlock(-11,13,1,CONCRETE:8,30,IRON_FENCE,30,CONCRETE:8,100)
RandomBlock(-11,13,2,CONCRETE:8,30,IRON_FENCE,30,CONCRETE:8,100)
RandomBlock(-11,13,3,CONCRETE:8,30,IRON_FENCE,30,CONCRETE:8,100)
RandomBlock(-11,13,4,CONCRETE:8,30,IRON_FENCE,30,CONCRETE:8,100)
RandomBlock(-11,13,5,CONCRETE:8,30,IRON_FENCE,30,CONCRETE:8,100)
RandomBlock(-11,13,6,CONCRETE:8,30,IRON_FENCE,30,CONCRETE:8,100)
RandomBlock(-11,13,7,CONCRETE:8,30,IRON_FENCE,30,CONCRETE:8,100)
RandomBlock(-11,13,8,CONCRETE:8,30,IRON_FENCE,30,CONCRETE:8,100)
RandomBlock(-11,13,9,CONCRETE:8,30,IRON_FENCE,30,CONCRETE:8,100)
RandomBlock(-11,14,-8,CONCRETE:8,30,IRON_FENCE,30,CONCRETE:8,100)
RandomBlock(-11,14,-7,CONCRETE:8,30,IRON_FENCE,30,CONCRETE:8,100)
RandomBlock(-11,14,-6,CONCRETE:8,30,IRON_FENCE,30,CONCRETE:8,100)
RandomBlock(-11,14,-5,CONCRETE:8,30,IRON_FENCE,30,CONCRETE:8,100)
RandomBlock(-11,14,-4,CONCRETE:8,30,IRON_FENCE,30,CONCRETE:8,100)
RandomBlock(-11,14,-3,CONCRETE:8,30,IRON_FENCE,30,CONCRETE:8,100)
RandomBlock(-11,14,-2,CONCRETE:8,30,IRON_FENCE,30,CONCRETE:8,100)
RandomBlock(-11,14,-1,CONCRETE:8,30,IRON_FENCE,30,CONCRETE:8,100)
RandomBlock(-11,14,0,CONCRETE:8,30,IRON_FENCE,30,CONCRETE:8,100)
RandomBlock(-11,14,1,CONCRETE:8,30,IRON_FENCE,30,CONCRETE:8,100)
RandomBlock(-11,14,2,CONCRETE:8,30,IRON_FENCE,30,CONCRETE:8,100)
RandomBlock(-11,14,3,CONCRETE:8,30,IRON_FENCE,30,CONCRETE:8,100)
RandomBlock(-11,14,4,CONCRETE:8,30,IRON_FENCE,30,CONCRETE:8,100)
RandomBlock(-11,14,5,CONCRETE:8,30,IRON_FENCE,30,CONCRETE:8,100)
RandomBlock(-11,14,6,CONCRETE:8,30,IRON_FENCE,30,CONCRETE:8,100)
RandomBlock(-11,14,7,CONCRETE:8,30,IRON_FENCE,30,CONCRETE:8,100)
RandomBlock(-11,14,8,CONCRETE:8,30,IRON_FENCE,30,CONCRETE:8,100)
RandomBlock(-11,14,9,CONCRETE:8,30,IRON_FENCE,30,CONCRETE:8,100)
RandomBlock(-11,14,10,CONCRETE:8,30,IRON_FENCE,30,CONCRETE:8,100)
RandomBlock(-11,15,-7,CONCRETE:8,30,IRON_FENCE,30,CONCRETE:8,100)
RandomBlock(-11,15,-6,CONCRETE:8,30,IRON_FENCE,30,CONCRETE:8,100)
RandomBlock(-11,15,-5,CONCRETE:8,30,IRON_FENCE,30,CONCRETE:8,100)
RandomBlock(-11,15,-4,CONCRETE:8,30,IRON_FENCE,30,CONCRETE:8,100)
RandomBlock(-11,15,-3,CONCRETE:8,30,IRON_FENCE,30,CONCRETE:8,100)
RandomBlock(-11,15,-2,CONCRETE:8,30,IRON_FENCE,30,CONCRETE:8,100)
RandomBlock(-11,15,-1,CONCRETE:8,30,IRON_FENCE,30,CONCRETE:8,100)
RandomBlock(-11,15,0,CONCRETE:8,30,IRON_FENCE,30,CONCRETE:8,100)
RandomBlock(-11,15,1,CONCRETE:8,30,IRON_FENCE,30,CONCRETE:8,100)
RandomBlock(-11,15,2,CONCRETE:8,30,IRON_FENCE,30,CONCRETE:8,100)
RandomBlock(-11,15,3,CONCRETE:8,30,IRON_FENCE,30,CONCRETE:8,100)
RandomBlock(-11,15,4,CONCRETE:8,30,IRON_FENCE,30,CONCRETE:8,100)
RandomBlock(-11,15,5,CONCRETE:8,30,IRON_FENCE,30,CONCRETE:8,100)
RandomBlock(-11,15,6,CONCRETE:8,30,IRON_FENCE,30,CONCRETE:8,100)
RandomBlock(-11,15,7,CONCRETE:8,30,IRON_FENCE,30,CONCRETE:8,100)
RandomBlock(-11,15,8,CONCRETE:8,30,IRON_FENCE,30,CONCRETE:8,100)
RandomBlock(-11,15,9,CONCRETE:8,30,IRON_FENCE,30,CONCRETE:8,100)
RandomBlock(-11,16,-7,CONCRETE:8,30,IRON_FENCE,30,CONCRETE:8,100)
RandomBlock(-11,16,-6,CONCRETE:8,30,IRON_FENCE,30,CONCRETE:8,100)
RandomBlock(-11,16,-5,CONCRETE:8,30,IRON_FENCE,30,CONCRETE:8,100)
RandomBlock(-11,16,-4,CONCRETE:8,30,IRON_FENCE,30,CONCRETE:8,100)
RandomBlock(-11,16,-3,CONCRETE:8,30,IRON_FENCE,30,CONCRETE:8,100)
RandomBlock(-11,16,-2,CONCRETE:8,30,IRON_FENCE,30,CONCRETE:8,100)
RandomBlock(-11,16,-1,CONCRETE:8,30,IRON_FENCE,30,CONCRETE:8,100)
RandomBlock(-11,16,0,CONCRETE:8,30,IRON_FENCE,30,CONCRETE:8,100)
RandomBlock(-11,16,1,CONCRETE:8,30,IRON_FENCE,30,CONCRETE:8,100)
RandomBlock(-11,16,2,CONCRETE:8,30,IRON_FENCE,30,CONCRETE:8,100)
RandomBlock(-11,16,3,CONCRETE:8,30,IRON_FENCE,30,CONCRETE:8,100)
RandomBlock(-11,16,4,CONCRETE:8,30,IRON_FENCE,30,CONCRETE:8,100)
RandomBlock(-11,16,5,CONCRETE:8,30,IRON_FENCE,30,CONCRETE:8,100)
RandomBlock(-11,16,6,CONCRETE:8,30,IRON_FENCE,30,CONCRETE:8,100)
RandomBlock(-11,16,7,CONCRETE:8,30,IRON_FENCE,30,CONCRETE:8,100)
RandomBlock(-11,16,8,CONCRETE:8,30,IRON_FENCE,30,CONCRETE:8,100)
RandomBlock(-11,16,9,CONCRETE:8,30,IRON_FENCE,30,CONCRETE:8,100)
RandomBlock(-11,17,-7,CONCRETE:8,30,IRON_FENCE,30,CONCRETE:8,100)
RandomBlock(-11,17,-6,CONCRETE:8,30,IRON_FENCE,30,CONCRETE:8,100)
RandomBlock(-11,17,-5,CONCRETE:8,30,IRON_FENCE,30,CONCRETE:8,100)
RandomBlock(-11,17,-4,CONCRETE:8,30,IRON_FENCE,30,CONCRETE:8,100)
RandomBlock(-11,17,-3,CONCRETE:8,30,IRON_FENCE,30,CONCRETE:8,100)
RandomBlock(-11,17,-2,CONCRETE:8,30,IRON_FENCE,30,CONCRETE:8,100)
RandomBlock(-11,17,-1,CONCRETE:8,30,IRON_FENCE,30,CONCRETE:8,100)
RandomBlock(-11,17,0,CONCRETE:8,30,IRON_FENCE,30,CONCRETE:8,100)
RandomBlock(-11,17,1,CONCRETE:8,30,IRON_FENCE,30,CONCRETE:8,100)
RandomBlock(-11,17,2,CONCRETE:8,30,IRON_FENCE,30,CONCRETE:8,100)
RandomBlock(-11,17,3,CONCRETE:8,30,IRON_FENCE,30,CONCRETE:8,100)
RandomBlock(-11,17,4,CONCRETE:8,30,IRON_FENCE,30,CONCRETE:8,100)
RandomBlock(-11,17,5,CONCRETE:8,30,IRON_FENCE,30,CONCRETE:8,100)
RandomBlock(-11,17,6,CONCRETE:8,30,IRON_FENCE,30,CONCRETE:8,100)
RandomBlock(-11,17,7,CONCRETE:8,30,IRON_FENCE,30,CONCRETE:8,100)
RandomBlock(-11,17,8,CONCRETE:8,30,IRON_FENCE,30,CONCRETE:8,100)
RandomBlock(-11,17,9,CONCRETE:8,30,IRON_FENCE,30,CONCRETE:8,100)
RandomBlock(-11,18,-7,CONCRETE:8,30,IRON_FENCE,30,CONCRETE:8,100)
RandomBlock(-11,18,-6,CONCRETE:8,30,IRON_FENCE,30,CONCRETE:8,100)
RandomBlock(-11,18,-5,CONCRETE:8,30,IRON_FENCE,30,CONCRETE:8,100)
RandomBlock(-11,18,-4,CONCRETE:8,30,IRON_FENCE,30,CONCRETE:8,100)
RandomBlock(-11,18,-3,CONCRETE:8,30,IRON_FENCE,30,CONCRETE:8,100)
RandomBlock(-11,18,-2,CONCRETE:8,30,IRON_FENCE,30,CONCRETE:8,100)
RandomBlock(-11,18,-1,CONCRETE:8,30,IRON_FENCE,30,CONCRETE:8,100)
RandomBlock(-11,18,0,CONCRETE:8,30,IRON_FENCE,30,CONCRETE:8,100)
RandomBlock(-11,18,1,CONCRETE:8,30,IRON_FENCE,30,CONCRETE:8,100)
RandomBlock(-11,18,2,CONCRETE:8,30,IRON_FENCE,30,CONCRETE:8,100)
RandomBlock(-11,18,3,CONCRETE:8,30,IRON_FENCE,30,CONCRETE:8,100)
RandomBlock(-11,18,4,CONCRETE:8,30,IRON_FENCE,30,CONCRETE:8,100)
RandomBlock(-11,18,5,CONCRETE:8,30,IRON_FENCE,30,CONCRETE:8,100)
RandomBlock(-11,18,6,CONCRETE:8,30,IRON_FENCE,30,CONCRETE:8,100)
RandomBlock(-11,18,7,CONCRETE:8,30,IRON_FENCE,30,CONCRETE:8,100)
RandomBlock(-11,18,8,CONCRETE:8,30,IRON_FENCE,30,CONCRETE:8,100)
RandomBlock(-11,18,9,CONCRETE:8,30,IRON_FENCE,30,CONCRETE:8,100)
RandomBlock(-11,19,-6,CONCRETE:8,30,IRON_FENCE,30,CONCRETE:8,100)
RandomBlock(-11,19,-5,CONCRETE:8,30,IRON_FENCE,30,CONCRETE:8,100)
RandomBlock(-11,19,-4,CONCRETE:8,30,IRON_FENCE,30,CONCRETE:8,100)
RandomBlock(-11,19,-3,CONCRETE:8,30,IRON_FENCE,30,CONCRETE:8,100)
RandomBlock(-11,19,-2,CONCRETE:8,30,IRON_FENCE,30,CONCRETE:8,100)
RandomBlock(-11,19,-1,CONCRETE:8,30,IRON_FENCE,30,CONCRETE:8,100)
RandomBlock(-11,19,0,CONCRETE:8,30,IRON_FENCE,30,CONCRETE:8,100)
RandomBlock(-11,19,1,CONCRETE:8,30,IRON_FENCE,30,CONCRETE:8,100)
RandomBlock(-11,19,2,CONCRETE:8,30,IRON_FENCE,30,CONCRETE:8,100)
RandomBlock(-11,19,3,CONCRETE:8,30,IRON_FENCE,30,CONCRETE:8,100)
RandomBlock(-11,19,4,CONCRETE:8,30,IRON_FENCE,30,CONCRETE:8,100)
RandomBlock(-11,19,5,CONCRETE:8,30,IRON_FENCE,30,CONCRETE:8,100)
RandomBlock(-11,19,6,CONCRETE:8,30,IRON_FENCE,30,CONCRETE:8,100)
RandomBlock(-11,19,7,CONCRETE:8,30,IRON_FENCE,30,CONCRETE:8,100)
RandomBlock(-11,19,8,CONCRETE:8,30,IRON_FENCE,30,CONCRETE:8,100)
RandomBlock(-11,20,-5,CONCRETE:8,30,IRON_FENCE,30,CONCRETE:8,100)
RandomBlock(-11,20,-4,CONCRETE:8,30,IRON_FENCE,30,CONCRETE:8,100)
RandomBlock(-11,20,-3,CONCRETE:8,30,IRON_FENCE,30,CONCRETE:8,100)
RandomBlock(-11,20,-2,CONCRETE:8,30,IRON_FENCE,30,CONCRETE:8,100)
RandomBlock(-11,20,-1,CONCRETE:8,30,IRON_FENCE,30,CONCRETE:8,100)
RandomBlock(-11,20,0,CONCRETE:8,30,IRON_FENCE,30,CONCRETE:8,100)
RandomBlock(-11,20,1,CONCRETE:8,30,IRON_FENCE,30,CONCRETE:8,100)
RandomBlock(-11,20,2,CONCRETE:8,30,IRON_FENCE,30,CONCRETE:8,100)
RandomBlock(-11,20,3,CONCRETE:8,30,IRON_FENCE,30,CONCRETE:8,100)
RandomBlock(-11,20,4,CONCRETE:8,30,IRON_FENCE,30,CONCRETE:8,100)
RandomBlock(-11,20,5,CONCRETE:8,30,IRON_FENCE,30,CONCRETE:8,100)
RandomBlock(-11,20,6,CONCRETE:8,30,IRON_FENCE,30,CONCRETE:8,100)
RandomBlock(-11,20,7,CONCRETE:8,30,IRON_FENCE,30,CONCRETE:8,100)
RandomBlock(-11,21,-4,CONCRETE:8,30,IRON_FENCE,30,CONCRETE:8,100)
RandomBlock(-11,21,-3,CONCRETE:8,30,IRON_FENCE,30,CONCRETE:8,100)
RandomBlock(-11,21,-2,CONCRETE:8,30,IRON_FENCE,30,CONCRETE:8,100)
RandomBlock(-11,21,-1,CONCRETE:8,30,IRON_FENCE,30,CONCRETE:8,100)
RandomBlock(-11,21,0,CONCRETE:8,30,IRON_FENCE,30,CONCRETE:8,100)
RandomBlock(-11,21,1,CONCRETE:8,30,IRON_FENCE,30,CONCRETE:8,100)
RandomBlock(-11,21,2,CONCRETE:8,30,IRON_FENCE,30,CONCRETE:8,100)
RandomBlock(-11,21,3,CONCRETE:8,30,IRON_FENCE,30,CONCRETE:8,100)
RandomBlock(-11,21,4,CONCRETE:8,30,IRON_FENCE,30,CONCRETE:8,100)
RandomBlock(-11,21,5,CONCRETE:8,30,IRON_FENCE,30,CONCRETE:8,100)
RandomBlock(-11,21,6,CONCRETE:8,30,IRON_FENCE,30,CONCRETE:8,100)
RandomBlock(-11,22,-3,CONCRETE:8,30,IRON_FENCE,30,CONCRETE:8,100)
RandomBlock(-11,22,-2,CONCRETE:8,30,IRON_FENCE,30,CONCRETE:8,100)
RandomBlock(-11,22,-1,CONCRETE:8,30,IRON_FENCE,30,CONCRETE:8,100)
RandomBlock(-11,22,0,CONCRETE:8,30,IRON_FENCE,30,CONCRETE:8,100)
RandomBlock(-11,22,1,CONCRETE:8,30,IRON_FENCE,30,CONCRETE:8,100)
RandomBlock(-11,22,2,CONCRETE:8,30,IRON_FENCE,30,CONCRETE:8,100)
RandomBlock(-11,22,3,CONCRETE:8,30,IRON_FENCE,30,CONCRETE:8,100)
RandomBlock(-11,22,4,CONCRETE:8,30,IRON_FENCE,30,CONCRETE:8,100)
RandomBlock(-11,22,5,CONCRETE:8,30,IRON_FENCE,30,CONCRETE:8,100)
RandomBlock(-11,23,1,CONCRETE:8,30,IRON_FENCE,30,CONCRETE:8,100)
RandomBlock(-10,4,-1,CONCRETE:8,30,IRON_FENCE,30,CONCRETE:8,100)
RandomBlock(-10,4,0,CONCRETE:8,30,IRON_FENCE,30,CONCRETE:8,100)
RandomBlock(-10,4,1,CONCRETE:8,30,IRON_FENCE,30,CONCRETE:8,100)
RandomBlock(-10,4,2,CONCRETE:8,30,IRON_FENCE,30,CONCRETE:8,100)
RandomBlock(-10,4,3,CONCRETE:8,30,IRON_FENCE,30,CONCRETE:8,100)
RandomBlock(-10,5,-3,CONCRETE:8,30,IRON_FENCE,30,CONCRETE:8,100)
RandomBlock(-10,5,-2,CONCRETE:8,30,IRON_FENCE,30,CONCRETE:8,100)
RandomBlock(-10,5,-1,CONCRETE:8,30,IRON_FENCE,30,CONCRETE:8,100)
RandomBlock(-10,5,0,CONCRETE:8,30,IRON_FENCE,30,CONCRETE:8,100)
RandomBlock(-10,5,1,CONCRETE:8,30,IRON_FENCE,30,CONCRETE:8,100)
RandomBlock(-10,5,2,CONCRETE:8,30,IRON_FENCE,30,CONCRETE:8,100)
RandomBlock(-10,5,3,CONCRETE:8,30,IRON_FENCE,30,CONCRETE:8,100)
RandomBlock(-10,5,4,CONCRETE:8,30,IRON_FENCE,30,CONCRETE:8,100)
RandomBlock(-10,5,5,CONCRETE:8,30,IRON_FENCE,30,CONCRETE:8,100)
RandomBlock(-10,6,-5,CONCRETE:8,30,IRON_FENCE,30,CONCRETE:8,100)
RandomBlock(-10,6,-4,CONCRETE:8,30,IRON_FENCE,30,CONCRETE:8,100)
RandomBlock(-10,6,-3,CONCRETE:8,30,IRON_FENCE,30,CONCRETE:8,100)
RandomBlock(-10,6,-2,CONCRETE:8,30,IRON_FENCE,30,CONCRETE:8,100)
RandomBlock(-10,6,-1,CONCRETE:8,30,IRON_FENCE,30,CONCRETE:8,100)
RandomBlock(-10,6,0,CONCRETE:8,30,IRON_FENCE,30,CONCRETE:8,100)
RandomBlock(-10,6,1,CONCRETE:8,30,IRON_FENCE,30,CONCRETE:8,100)
RandomBlock(-10,6,2,CONCRETE:8,30,IRON_FENCE,30,CONCRETE:8,100)
RandomBlock(-10,6,3,CONCRETE:8,30,IRON_FENCE,30,CONCRETE:8,100)
RandomBlock(-10,6,4,CONCRETE:8,30,IRON_FENCE,30,CONCRETE:8,100)
RandomBlock(-10,6,5,CONCRETE:8,30,IRON_FENCE,30,CONCRETE:8,100)
RandomBlock(-10,6,6,CONCRETE:8,30,IRON_FENCE,30,CONCRETE:8,100)
RandomBlock(-10,6,7,CONCRETE:8,30,IRON_FENCE,30,CONCRETE:8,100)
RandomBlock(-10,7,-6,CONCRETE:8,30,IRON_FENCE,30,CONCRETE:8,100)
RandomBlock(-10,7,-5,CONCRETE:8,30,IRON_FENCE,30,CONCRETE:8,100)
RandomBlock(-10,7,-4,CONCRETE:8,30,IRON_FENCE,30,CONCRETE:8,100)
RandomBlock(-10,7,-3,CONCRETE:8,30,IRON_FENCE,30,CONCRETE:8,100)
RandomBlock(-10,7,-2,CONCRETE:8,30,IRON_FENCE,30,CONCRETE:8,100)
RandomBlock(-10,7,-1,CONCRETE:8,30,IRON_FENCE,30,CONCRETE:8,100)
RandomBlock(-10,7,0,CONCRETE:8,30,IRON_FENCE,30,CONCRETE:8,100)
RandomBlock(-10,7,1,CONCRETE:8,30,IRON_FENCE,30,CONCRETE:8,100)
RandomBlock(-10,7,2,CONCRETE:8,30,IRON_FENCE,30,CONCRETE:8,100)
RandomBlock(-10,7,3,CONCRETE:8,30,IRON_FENCE,30,CONCRETE:8,100)
RandomBlock(-10,7,4,CONCRETE:8,30,IRON_FENCE,30,CONCRETE:8,100)
RandomBlock(-10,7,5,CONCRETE:8,30,IRON_FENCE,30,CONCRETE:8,100)
RandomBlock(-10,7,6,CONCRETE:8,30,IRON_FENCE,30,CONCRETE:8,100)
RandomBlock(-10,7,7,CONCRETE:8,30,IRON_FENCE,30,CONCRETE:8,100)
RandomBlock(-10,7,8,CONCRETE:8,30,IRON_FENCE,30,CONCRETE:8,100)
RandomBlock(-10,8,-7,CONCRETE:8,30,IRON_FENCE,30,CONCRETE:8,100)
RandomBlock(-10,8,-6,CONCRETE:8,30,IRON_FENCE,30,CONCRETE:8,100)
RandomBlock(-10,8,-5,CONCRETE:8,30,IRON_FENCE,30,CONCRETE:8,100)
RandomBlock(-10,8,-4,CONCRETE:8,30,IRON_FENCE,30,CONCRETE:8,100)
RandomBlock(-10,8,-3,CONCRETE:8,30,IRON_FENCE,30,CONCRETE:8,100)
RandomBlock(-10,8,-2,CONCRETE:8,30,IRON_FENCE,30,CONCRETE:8,100)
RandomBlock(-10,8,-1,CONCRETE:8,30,IRON_FENCE,30,CONCRETE:8,100)
RandomBlock(-10,8,0,CONCRETE:8,30,IRON_FENCE,30,CONCRETE:8,100)
RandomBlock(-10,8,1,CONCRETE:8,30,IRON_FENCE,30,CONCRETE:8,100)
RandomBlock(-10,8,2,CONCRETE:8,30,IRON_FENCE,30,CONCRETE:8,100)
RandomBlock(-10,8,3,CONCRETE:8,30,IRON_FENCE,30,CONCRETE:8,100)
RandomBlock(-10,8,4,CONCRETE:8,30,IRON_FENCE,30,CONCRETE:8,100)
RandomBlock(-10,8,5,CONCRETE:8,30,IRON_FENCE,30,CONCRETE:8,100)
RandomBlock(-10,8,6,CONCRETE:8,30,IRON_FENCE,30,CONCRETE:8,100)
RandomBlock(-10,8,7,CONCRETE:8,30,IRON_FENCE,30,CONCRETE:8,100)
RandomBlock(-10,8,8,CONCRETE:8,30,IRON_FENCE,30,CONCRETE:8,100)
RandomBlock(-10,8,9,CONCRETE:8,30,IRON_FENCE,30,CONCRETE:8,100)
RandomBlock(-10,9,-7,CONCRETE:8,30,IRON_FENCE,30,CONCRETE:8,100)
RandomBlock(-10,9,-6,CONCRETE:8,30,IRON_FENCE,30,CONCRETE:8,100)
RandomBlock(-10,9,-5,CONCRETE:8,30,IRON_FENCE,30,CONCRETE:8,100)
RandomBlock(-10,9,-4,CONCRETE:8,30,IRON_FENCE,30,CONCRETE:8,100)
RandomBlock(-10,9,-3,CONCRETE:8,30,IRON_FENCE,30,CONCRETE:8,100)
RandomBlock(-10,9,-2,CONCRETE:8,30,IRON_FENCE,30,CONCRETE:8,100)
RandomBlock(-10,9,-1,CONCRETE:8,30,IRON_FENCE,30,CONCRETE:8,100)
RandomBlock(-10,9,0,CONCRETE:8,30,IRON_FENCE,30,CONCRETE:8,100)
RandomBlock(-10,9,1,CONCRETE:8,30,IRON_FENCE,30,CONCRETE:8,100)
RandomBlock(-10,9,2,CONCRETE:8,30,IRON_FENCE,30,CONCRETE:8,100)
RandomBlock(-10,9,3,CONCRETE:8,30,IRON_FENCE,30,CONCRETE:8,100)
RandomBlock(-10,9,4,CONCRETE:8,30,IRON_FENCE,30,CONCRETE:8,100)
RandomBlock(-10,9,5,CONCRETE:8,30,IRON_FENCE,30,CONCRETE:8,100)
RandomBlock(-10,9,6,CONCRETE:8,30,IRON_FENCE,30,CONCRETE:8,100)
RandomBlock(-10,9,7,CONCRETE:8,30,IRON_FENCE,30,CONCRETE:8,100)
RandomBlock(-10,9,8,CONCRETE:8,30,IRON_FENCE,30,CONCRETE:8,100)
RandomBlock(-10,9,9,CONCRETE:8,30,IRON_FENCE,30,CONCRETE:8,100)
RandomBlock(-10,10,-8,CONCRETE:8,30,IRON_FENCE,30,CONCRETE:8,100)
RandomBlock(-10,10,-7,CONCRETE:8,30,IRON_FENCE,30,CONCRETE:8,100)
RandomBlock(-10,10,-6,CONCRETE:8,30,IRON_FENCE,30,CONCRETE:8,100)
RandomBlock(-10,10,-5,CONCRETE:8,30,IRON_FENCE,30,CONCRETE:8,100)
RandomBlock(-10,10,-4,CONCRETE:8,30,IRON_FENCE,30,CONCRETE:8,100)
RandomBlock(-10,10,-3,CONCRETE:8,30,IRON_FENCE,30,CONCRETE:8,100)
RandomBlock(-10,10,-2,CONCRETE:8,30,IRON_FENCE,30,CONCRETE:8,100)
RandomBlock(-10,10,-1,CONCRETE:8,30,IRON_FENCE,30,CONCRETE:8,100)
RandomBlock(-10,10,0,CONCRETE:8,30,IRON_FENCE,30,CONCRETE:8,100)
RandomBlock(-10,10,1,CONCRETE:8,30,IRON_FENCE,30,CONCRETE:8,100)
RandomBlock(-10,10,2,CONCRETE:8,30,IRON_FENCE,30,CONCRETE:8,100)
RandomBlock(-10,10,3,CONCRETE:8,30,IRON_FENCE,30,CONCRETE:8,100)
RandomBlock(-10,10,4,CONCRETE:8,30,IRON_FENCE,30,CONCRETE:8,100)
RandomBlock(-10,10,5,CONCRETE:8,30,IRON_FENCE,30,CONCRETE:8,100)
RandomBlock(-10,10,6,CONCRETE:8,30,IRON_FENCE,30,CONCRETE:8,100)
RandomBlock(-10,10,7,CONCRETE:8,30,IRON_FENCE,30,CONCRETE:8,100)
RandomBlock(-10,10,8,CONCRETE:8,30,IRON_FENCE,30,CONCRETE:8,100)
RandomBlock(-10,10,9,CONCRETE:8,30,IRON_FENCE,30,CONCRETE:8,100)
RandomBlock(-10,10,10,CONCRETE:8,30,IRON_FENCE,30,CONCRETE:8,100)
RandomBlock(-10,11,-8,CONCRETE:8,30,IRON_FENCE,30,CONCRETE:8,100)
RandomBlock(-10,11,-7,CONCRETE:8,30,IRON_FENCE,30,CONCRETE:8,100)
RandomBlock(-10,11,-6,CONCRETE:8,30,IRON_FENCE,30,CONCRETE:8,100)
RandomBlock(-10,11,-5,CONCRETE:8,30,IRON_FENCE,30,CONCRETE:8,100)
RandomBlock(-10,11,-4,CONCRETE:8,30,IRON_FENCE,30,CONCRETE:8,100)
RandomBlock(-10,11,-3,CONCRETE:8,30,IRON_FENCE,30,CONCRETE:8,100)
RandomBlock(-10,11,-2,CONCRETE:8,30,IRON_FENCE,30,CONCRETE:8,100)
RandomBlock(-10,11,-1,CONCRETE:8,30,IRON_FENCE,30,CONCRETE:8,100)
RandomBlock(-10,11,0,CONCRETE:8,30,IRON_FENCE,30,CONCRETE:8,100)
RandomBlock(-10,11,1,CONCRETE:8,30,IRON_FENCE,30,CONCRETE:8,100)
RandomBlock(-10,11,2,CONCRETE:8,30,IRON_FENCE,30,CONCRETE:8,100)
RandomBlock(-10,11,3,CONCRETE:8,30,IRON_FENCE,30,CONCRETE:8,100)
RandomBlock(-10,11,4,CONCRETE:8,30,IRON_FENCE,30,CONCRETE:8,100)
RandomBlock(-10,11,5,CONCRETE:8,30,IRON_FENCE,30,CONCRETE:8,100)
RandomBlock(-10,11,6,CONCRETE:8,30,IRON_FENCE,30,CONCRETE:8,100)
RandomBlock(-10,11,7,CONCRETE:8,30,IRON_FENCE,30,CONCRETE:8,100)
RandomBlock(-10,11,8,CONCRETE:8,30,IRON_FENCE,30,CONCRETE:8,100)
RandomBlock(-10,11,9,CONCRETE:8,30,IRON_FENCE,30,CONCRETE:8,100)
RandomBlock(-10,11,10,CONCRETE:8,30,IRON_FENCE,30,CONCRETE:8,100)
RandomBlock(-10,12,-9,CONCRETE:8,30,IRON_FENCE,30,CONCRETE:8,100)
RandomBlock(-10,12,-8,CONCRETE:8,30,IRON_FENCE,30,CONCRETE:8,100)
RandomBlock(-10,12,-7,CONCRETE:8,30,IRON_FENCE,30,CONCRETE:8,100)
RandomBlock(-10,12,-6,CONCRETE:8,30,IRON_FENCE,30,CONCRETE:8,100)
RandomBlock(-10,12,-5,CONCRETE:8,30,IRON_FENCE,30,CONCRETE:8,100)
RandomBlock(-10,12,-4,CONCRETE:8,30,IRON_FENCE,30,CONCRETE:8,100)
RandomBlock(-10,12,-3,CONCRETE:8,30,IRON_FENCE,30,CONCRETE:8,100)
RandomBlock(-10,12,-2,CONCRETE:8,30,IRON_FENCE,30,CONCRETE:8,100)
RandomBlock(-10,12,-1,CONCRETE:8,30,IRON_FENCE,30,CONCRETE:8,100)
RandomBlock(-10,12,0,CONCRETE:8,30,IRON_FENCE,30,CONCRETE:8,100)
RandomBlock(-10,12,1,CONCRETE:8,30,IRON_FENCE,30,CONCRETE:8,100)
RandomBlock(-10,12,2,CONCRETE:8,30,IRON_FENCE,30,CONCRETE:8,100)
RandomBlock(-10,12,3,CONCRETE:8,30,IRON_FENCE,30,CONCRETE:8,100)
RandomBlock(-10,12,4,CONCRETE:8,30,IRON_FENCE,30,CONCRETE:8,100)
RandomBlock(-10,12,5,CONCRETE:8,30,IRON_FENCE,30,CONCRETE:8,100)
RandomBlock(-10,12,6,CONCRETE:8,30,IRON_FENCE,30,CONCRETE:8,100)
RandomBlock(-10,12,7,CONCRETE:8,30,IRON_FENCE,30,CONCRETE:8,100)
RandomBlock(-10,12,8,CONCRETE:8,30,IRON_FENCE,30,CONCRETE:8,100)
RandomBlock(-10,12,9,CONCRETE:8,30,IRON_FENCE,30,CONCRETE:8,100)
RandomBlock(-10,12,10,CONCRETE:8,30,IRON_FENCE,30,CONCRETE:8,100)
RandomBlock(-10,12,11,CONCRETE:8,30,IRON_FENCE,30,CONCRETE:8,100)
RandomBlock(-10,13,-9,CONCRETE:8,30,IRON_FENCE,30,CONCRETE:8,100)
RandomBlock(-10,13,-8,CONCRETE:8,30,IRON_FENCE,30,CONCRETE:8,100)
RandomBlock(-10,13,-7,CONCRETE:8,30,IRON_FENCE,30,CONCRETE:8,100)
RandomBlock(-10,13,-6,CONCRETE:8,30,IRON_FENCE,30,CONCRETE:8,100)
RandomBlock(-10,13,-5,CONCRETE:8,30,IRON_FENCE,30,CONCRETE:8,100)
RandomBlock(-10,13,-4,CONCRETE:8,30,IRON_FENCE,30,CONCRETE:8,100)
RandomBlock(-10,13,-3,CONCRETE:8,30,IRON_FENCE,30,CONCRETE:8,100)
RandomBlock(-10,13,-2,CONCRETE:8,30,IRON_FENCE,30,CONCRETE:8,100)
RandomBlock(-10,13,-1,CONCRETE:8,30,IRON_FENCE,30,CONCRETE:8,100)
RandomBlock(-10,13,0,CONCRETE:8,30,IRON_FENCE,30,CONCRETE:8,100)
RandomBlock(-10,13,1,CONCRETE:8,30,IRON_FENCE,30,CONCRETE:8,100)
RandomBlock(-10,13,2,CONCRETE:8,30,IRON_FENCE,30,CONCRETE:8,100)
RandomBlock(-10,13,3,CONCRETE:8,30,IRON_FENCE,30,CONCRETE:8,100)
RandomBlock(-10,13,4,CONCRETE:8,30,IRON_FENCE,30,CONCRETE:8,100)
RandomBlock(-10,13,5,CONCRETE:8,30,IRON_FENCE,30,CONCRETE:8,100)
RandomBlock(-10,13,6,CONCRETE:8,30,IRON_FENCE,30,CONCRETE:8,100)
RandomBlock(-10,13,7,CONCRETE:8,30,IRON_FENCE,30,CONCRETE:8,100)
RandomBlock(-10,13,8,CONCRETE:8,30,IRON_FENCE,30,CONCRETE:8,100)
RandomBlock(-10,13,9,CONCRETE:8,30,IRON_FENCE,30,CONCRETE:8,100)
RandomBlock(-10,13,10,CONCRETE:8,30,IRON_FENCE,30,CONCRETE:8,100)
RandomBlock(-10,13,11,CONCRETE:8,30,IRON_FENCE,30,CONCRETE:8,100)
RandomBlock(-10,14,-9,CONCRETE:8,30,IRON_FENCE,30,CONCRETE:8,100)
RandomBlock(-10,14,-8,CONCRETE:8,30,IRON_FENCE,30,CONCRETE:8,100)
RandomBlock(-10,14,-7,CONCRETE:8,30,IRON_FENCE,30,CONCRETE:8,100)
RandomBlock(-10,14,-6,CONCRETE:8,30,IRON_FENCE,30,CONCRETE:8,100)
RandomBlock(-10,14,-5,CONCRETE:8,30,IRON_FENCE,30,CONCRETE:8,100)
RandomBlock(-10,14,-4,CONCRETE:8,30,IRON_FENCE,30,CONCRETE:8,100)
RandomBlock(-10,14,-3,CONCRETE:8,30,IRON_FENCE,30,CONCRETE:8,100)
RandomBlock(-10,14,-2,CONCRETE:8,30,IRON_FENCE,30,CONCRETE:8,100)
RandomBlock(-10,14,-1,CONCRETE:8,30,IRON_FENCE,30,CONCRETE:8,100)
RandomBlock(-10,14,0,CONCRETE:8,30,IRON_FENCE,30,CONCRETE:8,100)
RandomBlock(-10,14,1,CONCRETE:8,30,IRON_FENCE,30,CONCRETE:8,100)
RandomBlock(-10,14,2,CONCRETE:8,30,IRON_FENCE,30,CONCRETE:8,100)
RandomBlock(-10,14,3,CONCRETE:8,30,IRON_FENCE,30,CONCRETE:8,100)
RandomBlock(-10,14,4,CONCRETE:8,30,IRON_FENCE,30,CONCRETE:8,100)
RandomBlock(-10,14,5,CONCRETE:8,30,IRON_FENCE,30,CONCRETE:8,100)
RandomBlock(-10,14,6,CONCRETE:8,30,IRON_FENCE,30,CONCRETE:8,100)
RandomBlock(-10,14,7,CONCRETE:8,30,IRON_FENCE,30,CONCRETE:8,100)
RandomBlock(-10,14,8,CONCRETE:8,30,IRON_FENCE,30,CONCRETE:8,100)
RandomBlock(-10,14,9,CONCRETE:8,30,IRON_FENCE,30,CONCRETE:8,100)
RandomBlock(-10,14,10,CONCRETE:8,30,IRON_FENCE,30,CONCRETE:8,100)
RandomBlock(-10,14,11,CONCRETE:8,30,IRON_FENCE,30,CONCRETE:8,100)
RandomBlock(-10,15,-9,CONCRETE:8,30,IRON_FENCE,30,CONCRETE:8,100)
RandomBlock(-10,15,-8,CONCRETE:8,30,IRON_FENCE,30,CONCRETE:8,100)
RandomBlock(-10,15,-7,CONCRETE:8,30,IRON_FENCE,30,CONCRETE:8,100)
RandomBlock(-10,15,-6,CONCRETE:8,30,IRON_FENCE,30,CONCRETE:8,100)
RandomBlock(-10,15,-5,CONCRETE:8,30,IRON_FENCE,30,CONCRETE:8,100)
RandomBlock(-10,15,-4,CONCRETE:8,30,IRON_FENCE,30,CONCRETE:8,100)
RandomBlock(-10,15,-3,CONCRETE:8,30,IRON_FENCE,30,CONCRETE:8,100)
RandomBlock(-10,15,-2,CONCRETE:8,30,IRON_FENCE,30,CONCRETE:8,100)
RandomBlock(-10,15,-1,CONCRETE:8,30,IRON_FENCE,30,CONCRETE:8,100)
RandomBlock(-10,15,0,CONCRETE:8,30,IRON_FENCE,30,CONCRETE:8,100)
RandomBlock(-10,15,1,CONCRETE:8,30,IRON_FENCE,30,CONCRETE:8,100)
RandomBlock(-10,15,2,CONCRETE:8,30,IRON_FENCE,30,CONCRETE:8,100)
RandomBlock(-10,15,3,CONCRETE:8,30,IRON_FENCE,30,CONCRETE:8,100)
RandomBlock(-10,15,4,CONCRETE:8,30,IRON_FENCE,30,CONCRETE:8,100)
RandomBlock(-10,15,5,CONCRETE:8,30,IRON_FENCE,30,CONCRETE:8,100)
RandomBlock(-10,15,6,CONCRETE:8,30,IRON_FENCE,30,CONCRETE:8,100)
RandomBlock(-10,15,7,CONCRETE:8,30,IRON_FENCE,30,CONCRETE:8,100)
RandomBlock(-10,15,8,CONCRETE:8,30,IRON_FENCE,30,CONCRETE:8,100)
RandomBlock(-10,15,9,CONCRETE:8,30,IRON_FENCE,30,CONCRETE:8,100)
RandomBlock(-10,15,10,CONCRETE:8,30,IRON_FENCE,30,CONCRETE:8,100)
RandomBlock(-10,15,11,CONCRETE:8,30,IRON_FENCE,30,CONCRETE:8,100)
RandomBlock(-10,16,-9,CONCRETE:8,30,IRON_FENCE,30,CONCRETE:8,100)
RandomBlock(-10,16,-8,CONCRETE:8,30,IRON_FENCE,30,CONCRETE:8,100)
RandomBlock(-10,16,-7,CONCRETE:8,30,IRON_FENCE,30,CONCRETE:8,100)
RandomBlock(-10,16,-6,CONCRETE:8,30,IRON_FENCE,30,CONCRETE:8,100)
RandomBlock(-10,16,-5,CONCRETE:8,30,IRON_FENCE,30,CONCRETE:8,100)
RandomBlock(-10,16,-4,CONCRETE:8,30,IRON_FENCE,30,CONCRETE:8,100)
RandomBlock(-10,16,-3,CONCRETE:8,30,IRON_FENCE,30,CONCRETE:8,100)
RandomBlock(-10,16,-2,CONCRETE:8,30,IRON_FENCE,30,CONCRETE:8,100)
RandomBlock(-10,16,-1,CONCRETE:8,30,IRON_FENCE,30,CONCRETE:8,100)
RandomBlock(-10,16,0,CONCRETE:8,30,IRON_FENCE,30,CONCRETE:8,100)
RandomBlock(-10,16,1,CONCRETE:8,30,IRON_FENCE,30,CONCRETE:8,100)
RandomBlock(-10,16,2,CONCRETE:8,30,IRON_FENCE,30,CONCRETE:8,100)
RandomBlock(-10,16,3,CONCRETE:8,30,IRON_FENCE,30,CONCRETE:8,100)
RandomBlock(-10,16,4,CONCRETE:8,30,IRON_FENCE,30,CONCRETE:8,100)
RandomBlock(-10,16,5,CONCRETE:8,30,IRON_FENCE,30,CONCRETE:8,100)
RandomBlock(-10,16,6,CONCRETE:8,30,IRON_FENCE,30,CONCRETE:8,100)
RandomBlock(-10,16,7,CONCRETE:8,30,IRON_FENCE,30,CONCRETE:8,100)
RandomBlock(-10,16,8,CONCRETE:8,30,IRON_FENCE,30,CONCRETE:8,100)
RandomBlock(-10,16,9,CONCRETE:8,30,IRON_FENCE,30,CONCRETE:8,100)
RandomBlock(-10,16,10,CONCRETE:8,30,IRON_FENCE,30,CONCRETE:8,100)
RandomBlock(-10,16,11,CONCRETE:8,30,IRON_FENCE,30,CONCRETE:8,100)
RandomBlock(-10,17,-8,CONCRETE:8,30,IRON_FENCE,30,CONCRETE:8,100)
RandomBlock(-10,17,-7,CONCRETE:8,30,IRON_FENCE,30,CONCRETE:8,100)
RandomBlock(-10,17,-6,CONCRETE:8,30,IRON_FENCE,30,CONCRETE:8,100)
RandomBlock(-10,17,-5,CONCRETE:8,30,IRON_FENCE,30,CONCRETE:8,100)
RandomBlock(-10,17,-4,CONCRETE:8,30,IRON_FENCE,30,CONCRETE:8,100)
RandomBlock(-10,17,-3,CONCRETE:8,30,IRON_FENCE,30,CONCRETE:8,100)
RandomBlock(-10,17,-2,CONCRETE:8,30,IRON_FENCE,30,CONCRETE:8,100)
RandomBlock(-10,17,-1,CONCRETE:8,30,IRON_FENCE,30,CONCRETE:8,100)
RandomBlock(-10,17,0,CONCRETE:8,30,IRON_FENCE,30,CONCRETE:8,100)
RandomBlock(-10,17,1,CONCRETE:8,30,IRON_FENCE,30,CONCRETE:8,100)
RandomBlock(-10,17,2,CONCRETE:8,30,IRON_FENCE,30,CONCRETE:8,100)
RandomBlock(-10,17,3,CONCRETE:8,30,IRON_FENCE,30,CONCRETE:8,100)
RandomBlock(-10,17,4,CONCRETE:8,30,IRON_FENCE,30,CONCRETE:8,100)
RandomBlock(-10,17,5,CONCRETE:8,30,IRON_FENCE,30,CONCRETE:8,100)
RandomBlock(-10,17,6,CONCRETE:8,30,IRON_FENCE,30,CONCRETE:8,100)
RandomBlock(-10,17,7,CONCRETE:8,30,IRON_FENCE,30,CONCRETE:8,100)
RandomBlock(-10,17,8,CONCRETE:8,30,IRON_FENCE,30,CONCRETE:8,100)
RandomBlock(-10,17,9,CONCRETE:8,30,IRON_FENCE,30,CONCRETE:8,100)
RandomBlock(-10,17,10,CONCRETE:8,30,IRON_FENCE,30,CONCRETE:8,100)
RandomBlock(-10,18,-8,CONCRETE:8,30,IRON_FENCE,30,CONCRETE:8,100)
RandomBlock(-10,18,-7,CONCRETE:8,30,IRON_FENCE,30,CONCRETE:8,100)
RandomBlock(-10,18,-6,CONCRETE:8,30,IRON_FENCE,30,CONCRETE:8,100)
RandomBlock(-10,18,-5,CONCRETE:8,30,IRON_FENCE,30,CONCRETE:8,100)
RandomBlock(-10,18,-4,CONCRETE:8,30,IRON_FENCE,30,CONCRETE:8,100)
RandomBlock(-10,18,-3,CONCRETE:8,30,IRON_FENCE,30,CONCRETE:8,100)
RandomBlock(-10,18,-2,CONCRETE:8,30,IRON_FENCE,30,CONCRETE:8,100)
RandomBlock(-10,18,-1,CONCRETE:8,30,IRON_FENCE,30,CONCRETE:8,100)
RandomBlock(-10,18,0,CONCRETE:8,30,IRON_FENCE,30,CONCRETE:8,100)
RandomBlock(-10,18,1,CONCRETE:8,30,IRON_FENCE,30,CONCRETE:8,100)
RandomBlock(-10,18,2,CONCRETE:8,30,IRON_FENCE,30,CONCRETE:8,100)
RandomBlock(-10,18,3,CONCRETE:8,30,IRON_FENCE,30,CONCRETE:8,100)
RandomBlock(-10,18,4,CONCRETE:8,30,IRON_FENCE,30,CONCRETE:8,100)
RandomBlock(-10,18,5,CONCRETE:8,30,IRON_FENCE,30,CONCRETE:8,100)
RandomBlock(-10,18,6,CONCRETE:8,30,IRON_FENCE,30,CONCRETE:8,100)
RandomBlock(-10,18,7,CONCRETE:8,30,IRON_FENCE,30,CONCRETE:8,100)
RandomBlock(-10,18,8,CONCRETE:8,30,IRON_FENCE,30,CONCRETE:8,100)
RandomBlock(-10,18,9,CONCRETE:8,30,IRON_FENCE,30,CONCRETE:8,100)
RandomBlock(-10,18,10,CONCRETE:8,30,IRON_FENCE,30,CONCRETE:8,100)
RandomBlock(-10,19,-7,CONCRETE:8,30,IRON_FENCE,30,CONCRETE:8,100)
RandomBlock(-10,19,-6,CONCRETE:8,30,IRON_FENCE,30,CONCRETE:8,100)
RandomBlock(-10,19,-5,CONCRETE:8,30,IRON_FENCE,30,CONCRETE:8,100)
RandomBlock(-10,19,-4,CONCRETE:8,30,IRON_FENCE,30,CONCRETE:8,100)
RandomBlock(-10,19,-3,CONCRETE:8,30,IRON_FENCE,30,CONCRETE:8,100)
RandomBlock(-10,19,-2,CONCRETE:8,30,IRON_FENCE,30,CONCRETE:8,100)
RandomBlock(-10,19,-1,CONCRETE:8,30,IRON_FENCE,30,CONCRETE:8,100)
RandomBlock(-10,19,0,CONCRETE:8,30,IRON_FENCE,30,CONCRETE:8,100)
RandomBlock(-10,19,1,CONCRETE:8,30,IRON_FENCE,30,CONCRETE:8,100)
RandomBlock(-10,19,2,CONCRETE:8,30,IRON_FENCE,30,CONCRETE:8,100)
RandomBlock(-10,19,3,CONCRETE:8,30,IRON_FENCE,30,CONCRETE:8,100)
RandomBlock(-10,19,4,CONCRETE:8,30,IRON_FENCE,30,CONCRETE:8,100)
RandomBlock(-10,19,5,CONCRETE:8,30,IRON_FENCE,30,CONCRETE:8,100)
RandomBlock(-10,19,6,CONCRETE:8,30,IRON_FENCE,30,CONCRETE:8,100)
RandomBlock(-10,19,7,CONCRETE:8,30,IRON_FENCE,30,CONCRETE:8,100)
RandomBlock(-10,19,8,CONCRETE:8,30,IRON_FENCE,30,CONCRETE:8,100)
RandomBlock(-10,19,9,CONCRETE:8,30,IRON_FENCE,30,CONCRETE:8,100)
RandomBlock(-10,20,-7,CONCRETE:8,30,IRON_FENCE,30,CONCRETE:8,100)
RandomBlock(-10,20,-6,CONCRETE:8,30,IRON_FENCE,30,CONCRETE:8,100)
RandomBlock(-10,20,-5,CONCRETE:8,30,IRON_FENCE,30,CONCRETE:8,100)
RandomBlock(-10,20,-4,CONCRETE:8,30,IRON_FENCE,30,CONCRETE:8,100)
RandomBlock(-10,20,-3,CONCRETE:8,30,IRON_FENCE,30,CONCRETE:8,100)
RandomBlock(-10,20,-2,CONCRETE:8,30,IRON_FENCE,30,CONCRETE:8,100)
RandomBlock(-10,20,-1,CONCRETE:8,30,IRON_FENCE,30,CONCRETE:8,100)
RandomBlock(-10,20,0,CONCRETE:8,30,IRON_FENCE,30,CONCRETE:8,100)
RandomBlock(-10,20,1,CONCRETE:8,30,IRON_FENCE,30,CONCRETE:8,100)
RandomBlock(-10,20,2,CONCRETE:8,30,IRON_FENCE,30,CONCRETE:8,100)
RandomBlock(-10,20,3,CONCRETE:8,30,IRON_FENCE,30,CONCRETE:8,100)
RandomBlock(-10,20,4,CONCRETE:8,30,IRON_FENCE,30,CONCRETE:8,100)
RandomBlock(-10,20,5,CONCRETE:8,30,IRON_FENCE,30,CONCRETE:8,100)
RandomBlock(-10,20,6,CONCRETE:8,30,IRON_FENCE,30,CONCRETE:8,100)
RandomBlock(-10,20,7,CONCRETE:8,30,IRON_FENCE,30,CONCRETE:8,100)
RandomBlock(-10,20,8,CONCRETE:8,30,IRON_FENCE,30,CONCRETE:8,100)
RandomBlock(-10,20,9,CONCRETE:8,30,IRON_FENCE,30,CONCRETE:8,100)
RandomBlock(-10,21,-6,CONCRETE:8,30,IRON_FENCE,30,CONCRETE:8,100)
RandomBlock(-10,21,-5,CONCRETE:8,30,IRON_FENCE,30,CONCRETE:8,100)
RandomBlock(-10,21,-4,CONCRETE:8,30,IRON_FENCE,30,CONCRETE:8,100)
RandomBlock(-10,21,-3,CONCRETE:8,30,IRON_FENCE,30,CONCRETE:8,100)
RandomBlock(-10,21,-2,CONCRETE:8,30,IRON_FENCE,30,CONCRETE:8,100)
RandomBlock(-10,21,-1,CONCRETE:8,30,IRON_FENCE,30,CONCRETE:8,100)
RandomBlock(-10,21,0,CONCRETE:8,30,IRON_FENCE,30,CONCRETE:8,100)
RandomBlock(-10,21,1,CONCRETE:8,30,IRON_FENCE,30,CONCRETE:8,100)
RandomBlock(-10,21,2,CONCRETE:8,30,IRON_FENCE,30,CONCRETE:8,100)
RandomBlock(-10,21,3,CONCRETE:8,30,IRON_FENCE,30,CONCRETE:8,100)
RandomBlock(-10,21,4,CONCRETE:8,30,IRON_FENCE,30,CONCRETE:8,100)
RandomBlock(-10,21,5,CONCRETE:8,30,IRON_FENCE,30,CONCRETE:8,100)
RandomBlock(-10,21,6,CONCRETE:8,30,IRON_FENCE,30,CONCRETE:8,100)
RandomBlock(-10,21,7,CONCRETE:8,30,IRON_FENCE,30,CONCRETE:8,100)
RandomBlock(-10,21,8,CONCRETE:8,30,IRON_FENCE,30,CONCRETE:8,100)
RandomBlock(-10,22,-5,CONCRETE:8,30,IRON_FENCE,30,CONCRETE:8,100)
RandomBlock(-10,22,-4,CONCRETE:8,30,IRON_FENCE,30,CONCRETE:8,100)
RandomBlock(-10,22,-3,CONCRETE:8,30,IRON_FENCE,30,CONCRETE:8,100)
RandomBlock(-10,22,-2,CONCRETE:8,30,IRON_FENCE,30,CONCRETE:8,100)
RandomBlock(-10,22,-1,CONCRETE:8,30,IRON_FENCE,30,CONCRETE:8,100)
RandomBlock(-10,22,0,CONCRETE:8,30,IRON_FENCE,30,CONCRETE:8,100)
RandomBlock(-10,22,1,CONCRETE:8,30,IRON_FENCE,30,CONCRETE:8,100)
RandomBlock(-10,22,2,CONCRETE:8,30,IRON_FENCE,30,CONCRETE:8,100)
RandomBlock(-10,22,3,CONCRETE:8,30,IRON_FENCE,30,CONCRETE:8,100)
RandomBlock(-10,22,4,CONCRETE:8,30,IRON_FENCE,30,CONCRETE:8,100)
RandomBlock(-10,22,5,CONCRETE:8,30,IRON_FENCE,30,CONCRETE:8,100)
RandomBlock(-10,22,6,CONCRETE:8,30,IRON_FENCE,30,CONCRETE:8,100)
RandomBlock(-10,22,7,CONCRETE:8,30,IRON_FENCE,30,CONCRETE:8,100)
RandomBlock(-10,23,-3,CONCRETE:8,30,IRON_FENCE,30,CONCRETE:8,100)
RandomBlock(-10,23,-2,CONCRETE:8,30,IRON_FENCE,30,CONCRETE:8,100)
RandomBlock(-10,23,-1,CONCRETE:8,30,IRON_FENCE,30,CONCRETE:8,100)
RandomBlock(-10,23,0,CONCRETE:8,30,IRON_FENCE,30,CONCRETE:8,100)
RandomBlock(-10,23,1,CONCRETE:8,30,IRON_FENCE,30,CONCRETE:8,100)
RandomBlock(-10,23,2,CONCRETE:8,30,IRON_FENCE,30,CONCRETE:8,100)
RandomBlock(-10,23,3,CONCRETE:8,30,IRON_FENCE,30,CONCRETE:8,100)
RandomBlock(-10,23,4,CONCRETE:8,30,IRON_FENCE,30,CONCRETE:8,100)
RandomBlock(-10,23,5,CONCRETE:8,30,IRON_FENCE,30,CONCRETE:8,100)
RandomBlock(-10,24,-1,CONCRETE:8,30,IRON_FENCE,30,CONCRETE:8,100)
RandomBlock(-10,24,0,CONCRETE:8,30,IRON_FENCE,30,CONCRETE:8,100)
RandomBlock(-10,24,1,CONCRETE:8,30,IRON_FENCE,30,CONCRETE:8,100)
RandomBlock(-10,24,2,CONCRETE:8,30,IRON_FENCE,30,CONCRETE:8,100)
RandomBlock(-10,24,3,CONCRETE:8,30,IRON_FENCE,30,CONCRETE:8,100)
RandomBlock(-9,3,-1,CONCRETE:8,30,IRON_FENCE,30,CONCRETE:8,100)
RandomBlock(-9,3,0,CONCRETE:8,30,IRON_FENCE,30,CONCRETE:8,100)
RandomBlock(-9,3,1,CONCRETE:8,30,IRON_FENCE,30,CONCRETE:8,100)
RandomBlock(-9,3,2,CONCRETE:8,30,IRON_FENCE,30,CONCRETE:8,100)
RandomBlock(-9,3,3,CONCRETE:8,30,IRON_FENCE,30,CONCRETE:8,100)
RandomBlock(-9,4,-4,CONCRETE:8,30,IRON_FENCE,30,CONCRETE:8,100)
RandomBlock(-9,4,-3,CONCRETE:8,30,IRON_FENCE,30,CONCRETE:8,100)
RandomBlock(-9,4,-2,CONCRETE:8,30,IRON_FENCE,30,CONCRETE:8,100)
RandomBlock(-9,4,-1,CONCRETE:8,30,IRON_FENCE,30,CONCRETE:8,100)
RandomBlock(-9,4,0,CONCRETE:8,30,IRON_FENCE,30,CONCRETE:8,100)
RandomBlock(-9,4,1,CONCRETE:8,30,IRON_FENCE,30,CONCRETE:8,100)
RandomBlock(-9,4,2,CONCRETE:8,30,IRON_FENCE,30,CONCRETE:8,100)
RandomBlock(-9,4,3,CONCRETE:8,30,IRON_FENCE,30,CONCRETE:8,100)
RandomBlock(-9,4,4,CONCRETE:8,30,IRON_FENCE,30,CONCRETE:8,100)
RandomBlock(-9,4,5,CONCRETE:8,30,IRON_FENCE,30,CONCRETE:8,100)
RandomBlock(-9,4,6,CONCRETE:8,30,IRON_FENCE,30,CONCRETE:8,100)
RandomBlock(-9,5,-5,CONCRETE:8,30,IRON_FENCE,30,CONCRETE:8,100)
RandomBlock(-9,5,-4,CONCRETE:8,30,IRON_FENCE,30,CONCRETE:8,100)
RandomBlock(-9,5,-3,CONCRETE:8,30,IRON_FENCE,30,CONCRETE:8,100)
RandomBlock(-9,5,-2,CONCRETE:8,30,IRON_FENCE,30,CONCRETE:8,100)
RandomBlock(-9,5,-1,CONCRETE:8,30,IRON_FENCE,30,CONCRETE:8,100)
RandomBlock(-9,5,0,CONCRETE:8,30,IRON_FENCE,30,CONCRETE:8,100)
RandomBlock(-9,5,1,CONCRETE:8,30,IRON_FENCE,30,CONCRETE:8,100)
RandomBlock(-9,5,2,CONCRETE:8,30,IRON_FENCE,30,CONCRETE:8,100)
RandomBlock(-9,5,3,CONCRETE:8,30,IRON_FENCE,30,CONCRETE:8,100)
RandomBlock(-9,5,4,CONCRETE:8,30,IRON_FENCE,30,CONCRETE:8,100)
RandomBlock(-9,5,5,CONCRETE:8,30,IRON_FENCE,30,CONCRETE:8,100)
RandomBlock(-9,5,6,CONCRETE:8,30,IRON_FENCE,30,CONCRETE:8,100)
RandomBlock(-9,5,7,CONCRETE:8,30,IRON_FENCE,30,CONCRETE:8,100)
RandomBlock(-9,6,-6,CONCRETE:8,30,IRON_FENCE,30,CONCRETE:8,100)
RandomBlock(-9,6,-5,CONCRETE:8,30,IRON_FENCE,30,CONCRETE:8,100)
RandomBlock(-9,6,-4,CONCRETE:8,30,IRON_FENCE,30,CONCRETE:8,100)
RandomBlock(-9,6,-3,CONCRETE:8,30,IRON_FENCE,30,CONCRETE:8,100)
RandomBlock(-9,6,-2,CONCRETE:8,30,IRON_FENCE,30,CONCRETE:8,100)
RandomBlock(-9,6,-1,CONCRETE:8,30,IRON_FENCE,30,CONCRETE:8,100)
RandomBlock(-9,6,0,CONCRETE:8,30,IRON_FENCE,30,CONCRETE:8,100)
RandomBlock(-9,6,1,CONCRETE:8,30,IRON_FENCE,30,CONCRETE:8,100)
RandomBlock(-9,6,2,CONCRETE:8,30,IRON_FENCE,30,CONCRETE:8,100)
RandomBlock(-9,6,3,CONCRETE:8,30,IRON_FENCE,30,CONCRETE:8,100)
RandomBlock(-9,6,4,CONCRETE:8,30,IRON_FENCE,30,CONCRETE:8,100)
RandomBlock(-9,6,5,CONCRETE:8,30,IRON_FENCE,30,CONCRETE:8,100)
RandomBlock(-9,6,6,CONCRETE:8,30,IRON_FENCE,30,CONCRETE:8,100)
RandomBlock(-9,6,7,CONCRETE:8,30,IRON_FENCE,30,CONCRETE:8,100)
RandomBlock(-9,6,8,CONCRETE:8,30,IRON_FENCE,30,CONCRETE:8,100)
RandomBlock(-9,7,-7,CONCRETE:8,30,IRON_FENCE,30,CONCRETE:8,100)
RandomBlock(-9,7,-6,CONCRETE:8,30,IRON_FENCE,30,CONCRETE:8,100)
RandomBlock(-9,7,-5,CONCRETE:8,30,IRON_FENCE,30,CONCRETE:8,100)
RandomBlock(-9,7,-4,CONCRETE:8,30,IRON_FENCE,30,CONCRETE:8,100)
RandomBlock(-9,7,-3,CONCRETE:8,30,IRON_FENCE,30,CONCRETE:8,100)
RandomBlock(-9,7,-2,CONCRETE:8,30,IRON_FENCE,30,CONCRETE:8,100)
RandomBlock(-9,7,-1,CONCRETE:8,30,IRON_FENCE,30,CONCRETE:8,100)
RandomBlock(-9,7,0,CONCRETE:8,30,IRON_FENCE,30,CONCRETE:8,100)
RandomBlock(-9,7,1,CONCRETE:8,30,IRON_FENCE,30,CONCRETE:8,100)
RandomBlock(-9,7,2,CONCRETE:8,30,IRON_FENCE,30,CONCRETE:8,100)
RandomBlock(-9,7,3,CONCRETE:8,30,IRON_FENCE,30,CONCRETE:8,100)
RandomBlock(-9,7,4,CONCRETE:8,30,IRON_FENCE,30,CONCRETE:8,100)
RandomBlock(-9,7,5,CONCRETE:8,30,IRON_FENCE,30,CONCRETE:8,100)
RandomBlock(-9,7,6,CONCRETE:8,30,IRON_FENCE,30,CONCRETE:8,100)
RandomBlock(-9,7,7,CONCRETE:8,30,IRON_FENCE,30,CONCRETE:8,100)
RandomBlock(-9,7,8,CONCRETE:8,30,IRON_FENCE,30,CONCRETE:8,100)
RandomBlock(-9,7,9,CONCRETE:8,30,IRON_FENCE,30,CONCRETE:8,100)
RandomBlock(-9,8,-8,CONCRETE:8,30,IRON_FENCE,30,CONCRETE:8,100)
RandomBlock(-9,8,-7,CONCRETE:8,30,IRON_FENCE,30,CONCRETE:8,100)
RandomBlock(-9,8,-6,CONCRETE:8,30,IRON_FENCE,30,CONCRETE:8,100)
RandomBlock(-9,8,-5,CONCRETE:8,30,IRON_FENCE,30,CONCRETE:8,100)
RandomBlock(-9,8,-4,CONCRETE:8,30,IRON_FENCE,30,CONCRETE:8,100)
RandomBlock(-9,8,-3,CONCRETE:8,30,IRON_FENCE,30,CONCRETE:8,100)
RandomBlock(-9,8,-2,CONCRETE:8,30,IRON_FENCE,30,CONCRETE:8,100)
RandomBlock(-9,8,-1,CONCRETE:8,30,IRON_FENCE,30,CONCRETE:8,100)
RandomBlock(-9,8,0,CONCRETE:8,30,IRON_FENCE,30,CONCRETE:8,100)
RandomBlock(-9,8,1,CONCRETE:8,30,IRON_FENCE,30,CONCRETE:8,100)
RandomBlock(-9,8,2,CONCRETE:8,30,IRON_FENCE,30,CONCRETE:8,100)
RandomBlock(-9,8,3,CONCRETE:8,30,IRON_FENCE,30,CONCRETE:8,100)
RandomBlock(-9,8,4,CONCRETE:8,30,IRON_FENCE,30,CONCRETE:8,100)
RandomBlock(-9,8,5,CONCRETE:8,30,IRON_FENCE,30,CONCRETE:8,100)
RandomBlock(-9,8,6,CONCRETE:8,30,IRON_FENCE,30,CONCRETE:8,100)
RandomBlock(-9,8,7,CONCRETE:8,30,IRON_FENCE,30,CONCRETE:8,100)
RandomBlock(-9,8,8,CONCRETE:8,30,IRON_FENCE,30,CONCRETE:8,100)
RandomBlock(-9,8,9,CONCRETE:8,30,IRON_FENCE,30,CONCRETE:8,100)
RandomBlock(-9,8,10,CONCRETE:8,30,IRON_FENCE,30,CONCRETE:8,100)
RandomBlock(-9,9,-9,CONCRETE:8,30,IRON_FENCE,30,CONCRETE:8,100)
RandomBlock(-9,9,-8,CONCRETE:8,30,IRON_FENCE,30,CONCRETE:8,100)
RandomBlock(-9,9,-7,CONCRETE:8,30,IRON_FENCE,30,CONCRETE:8,100)
RandomBlock(-9,9,-6,CONCRETE:8,30,IRON_FENCE,30,CONCRETE:8,100)
RandomBlock(-9,9,-5,CONCRETE:8,30,IRON_FENCE,30,CONCRETE:8,100)
RandomBlock(-9,9,-4,CONCRETE:8,30,IRON_FENCE,30,CONCRETE:8,100)
RandomBlock(-9,9,-3,CONCRETE:8,30,IRON_FENCE,30,CONCRETE:8,100)
RandomBlock(-9,9,-2,CONCRETE:8,30,IRON_FENCE,30,CONCRETE:8,100)
RandomBlock(-9,9,-1,CONCRETE:8,30,IRON_FENCE,30,CONCRETE:8,100)
RandomBlock(-9,9,0,CONCRETE:8,30,IRON_FENCE,30,CONCRETE:8,100)
RandomBlock(-9,9,1,CONCRETE:8,30,IRON_FENCE,30,CONCRETE:8,100)
RandomBlock(-9,9,2,CONCRETE:8,30,IRON_FENCE,30,CONCRETE:8,100)
RandomBlock(-9,9,3,CONCRETE:8,30,IRON_FENCE,30,CONCRETE:8,100)
RandomBlock(-9,9,4,CONCRETE:8,30,IRON_FENCE,30,CONCRETE:8,100)
RandomBlock(-9,9,5,CONCRETE:8,30,IRON_FENCE,30,CONCRETE:8,100)
RandomBlock(-9,9,6,CONCRETE:8,30,IRON_FENCE,30,CONCRETE:8,100)
RandomBlock(-9,9,7,CONCRETE:8,30,IRON_FENCE,30,CONCRETE:8,100)
RandomBlock(-9,9,8,CONCRETE:8,30,IRON_FENCE,30,CONCRETE:8,100)
RandomBlock(-9,9,9,CONCRETE:8,30,IRON_FENCE,30,CONCRETE:8,100)
RandomBlock(-9,9,10,CONCRETE:8,30,IRON_FENCE,30,CONCRETE:8,100)
RandomBlock(-9,9,11,CONCRETE:8,30,IRON_FENCE,30,CONCRETE:8,100)
RandomBlock(-9,10,-9,CONCRETE:8,30,IRON_FENCE,30,CONCRETE:8,100)
RandomBlock(-9,10,-8,CONCRETE:8,30,IRON_FENCE,30,CONCRETE:8,100)
RandomBlock(-9,10,-7,CONCRETE:8,30,IRON_FENCE,30,CONCRETE:8,100)
RandomBlock(-9,10,-6,CONCRETE:8,30,IRON_FENCE,30,CONCRETE:8,100)
RandomBlock(-9,10,-5,CONCRETE:8,30,IRON_FENCE,30,CONCRETE:8,100)
RandomBlock(-9,10,-4,CONCRETE:8,30,IRON_FENCE,30,CONCRETE:8,100)
RandomBlock(-9,10,-3,CONCRETE:8,30,IRON_FENCE,30,CONCRETE:8,100)
RandomBlock(-9,10,-2,CONCRETE:8,30,IRON_FENCE,30,CONCRETE:8,100)
RandomBlock(-9,10,-1,CONCRETE:8,30,IRON_FENCE,30,CONCRETE:8,100)
RandomBlock(-9,10,0,CONCRETE:8,30,IRON_FENCE,30,CONCRETE:8,100)
RandomBlock(-9,10,1,CONCRETE:8,30,IRON_FENCE,30,CONCRETE:8,100)
RandomBlock(-9,10,2,CONCRETE:8,30,IRON_FENCE,30,CONCRETE:8,100)
RandomBlock(-9,10,3,CONCRETE:8,30,IRON_FENCE,30,CONCRETE:8,100)
RandomBlock(-9,10,4,CONCRETE:8,30,IRON_FENCE,30,CONCRETE:8,100)
RandomBlock(-9,10,5,CONCRETE:8,30,IRON_FENCE,30,CONCRETE:8,100)
RandomBlock(-9,10,6,CONCRETE:8,30,IRON_FENCE,30,CONCRETE:8,100)
RandomBlock(-9,10,7,CONCRETE:8,30,IRON_FENCE,30,CONCRETE:8,100)
RandomBlock(-9,10,8,CONCRETE:8,30,IRON_FENCE,30,CONCRETE:8,100)
RandomBlock(-9,10,9,CONCRETE:8,30,IRON_FENCE,30,CONCRETE:8,100)
RandomBlock(-9,10,10,CONCRETE:8,30,IRON_FENCE,30,CONCRETE:8,100)
RandomBlock(-9,10,11,CONCRETE:8,30,IRON_FENCE,30,CONCRETE:8,100)
RandomBlock(-9,11,-9,CONCRETE:8,30,IRON_FENCE,30,CONCRETE:8,100)
RandomBlock(-9,11,-8,CONCRETE:8,30,IRON_FENCE,30,CONCRETE:8,100)
RandomBlock(-9,11,-7,CONCRETE:8,30,IRON_FENCE,30,CONCRETE:8,100)
RandomBlock(-9,11,-6,CONCRETE:8,30,IRON_FENCE,30,CONCRETE:8,100)
RandomBlock(-9,11,-5,CONCRETE:8,30,IRON_FENCE,30,CONCRETE:8,100)
RandomBlock(-9,11,-4,CONCRETE:8,30,IRON_FENCE,30,CONCRETE:8,100)
RandomBlock(-9,11,-3,CONCRETE:8,30,IRON_FENCE,30,CONCRETE:8,100)
RandomBlock(-9,11,-2,CONCRETE:8,30,IRON_FENCE,30,CONCRETE:8,100)
RandomBlock(-9,11,-1,CONCRETE:8,30,IRON_FENCE,30,CONCRETE:8,100)
RandomBlock(-9,11,0,CONCRETE:8,30,IRON_FENCE,30,CONCRETE:8,100)
RandomBlock(-9,11,1,CONCRETE:8,30,IRON_FENCE,30,CONCRETE:8,100)
RandomBlock(-9,11,2,CONCRETE:8,30,IRON_FENCE,30,CONCRETE:8,100)
RandomBlock(-9,11,3,CONCRETE:8,30,IRON_FENCE,30,CONCRETE:8,100)
RandomBlock(-9,11,4,CONCRETE:8,30,IRON_FENCE,30,CONCRETE:8,100)
RandomBlock(-9,11,5,CONCRETE:8,30,IRON_FENCE,30,CONCRETE:8,100)
RandomBlock(-9,11,6,CONCRETE:8,30,IRON_FENCE,30,CONCRETE:8,100)
RandomBlock(-9,11,7,CONCRETE:8,30,IRON_FENCE,30,CONCRETE:8,100)
RandomBlock(-9,11,8,CONCRETE:8,30,IRON_FENCE,30,CONCRETE:8,100)
RandomBlock(-9,11,9,CONCRETE:8,30,IRON_FENCE,30,CONCRETE:8,100)
RandomBlock(-9,11,10,CONCRETE:8,30,IRON_FENCE,30,CONCRETE:8,100)
RandomBlock(-9,11,11,CONCRETE:8,30,IRON_FENCE,30,CONCRETE:8,100)
RandomBlock(-9,12,-10,CONCRETE:8,30,IRON_FENCE,30,CONCRETE:8,100)
RandomBlock(-9,12,-9,CONCRETE:8,30,IRON_FENCE,30,CONCRETE:8,100)
RandomBlock(-9,12,-8,CONCRETE:8,30,IRON_FENCE,30,CONCRETE:8,100)
RandomBlock(-9,12,-7,CONCRETE:8,30,IRON_FENCE,30,CONCRETE:8,100)
RandomBlock(-9,12,-6,CONCRETE:8,30,IRON_FENCE,30,CONCRETE:8,100)
RandomBlock(-9,12,-5,CONCRETE:8,30,IRON_FENCE,30,CONCRETE:8,100)
RandomBlock(-9,12,-4,CONCRETE:8,30,IRON_FENCE,30,CONCRETE:8,100)
RandomBlock(-9,12,-3,CONCRETE:8,30,IRON_FENCE,30,CONCRETE:8,100)
RandomBlock(-9,12,-2,CONCRETE:8,30,IRON_FENCE,30,CONCRETE:8,100)
RandomBlock(-9,12,-1,CONCRETE:8,30,IRON_FENCE,30,CONCRETE:8,100)
RandomBlock(-9,12,0,CONCRETE:8,30,IRON_FENCE,30,CONCRETE:8,100)
RandomBlock(-9,12,1,CONCRETE:8,30,IRON_FENCE,30,CONCRETE:8,100)
RandomBlock(-9,12,2,CONCRETE:8,30,IRON_FENCE,30,CONCRETE:8,100)
RandomBlock(-9,12,3,CONCRETE:8,30,IRON_FENCE,30,CONCRETE:8,100)
RandomBlock(-9,12,4,CONCRETE:8,30,IRON_FENCE,30,CONCRETE:8,100)
RandomBlock(-9,12,5,CONCRETE:8,30,IRON_FENCE,30,CONCRETE:8,100)
RandomBlock(-9,12,6,CONCRETE:8,30,IRON_FENCE,30,CONCRETE:8,100)
RandomBlock(-9,12,7,CONCRETE:8,30,IRON_FENCE,30,CONCRETE:8,100)
RandomBlock(-9,12,8,CONCRETE:8,30,IRON_FENCE,30,CONCRETE:8,100)
RandomBlock(-9,12,9,CONCRETE:8,30,IRON_FENCE,30,CONCRETE:8,100)
RandomBlock(-9,12,10,CONCRETE:8,30,IRON_FENCE,30,CONCRETE:8,100)
RandomBlock(-9,12,11,CONCRETE:8,30,IRON_FENCE,30,CONCRETE:8,100)
RandomBlock(-9,12,12,CONCRETE:8,30,IRON_FENCE,30,CONCRETE:8,100)
RandomBlock(-9,13,-10,CONCRETE:8,30,IRON_FENCE,30,CONCRETE:8,100)
RandomBlock(-9,13,-9,CONCRETE:8,30,IRON_FENCE,30,CONCRETE:8,100)
RandomBlock(-9,13,-8,CONCRETE:8,30,IRON_FENCE,30,CONCRETE:8,100)
RandomBlock(-9,13,-7,CONCRETE:8,30,IRON_FENCE,30,CONCRETE:8,100)
RandomBlock(-9,13,-6,CONCRETE:8,30,IRON_FENCE,30,CONCRETE:8,100)
RandomBlock(-9,13,-5,CONCRETE:8,30,IRON_FENCE,30,CONCRETE:8,100)
RandomBlock(-9,13,-4,CONCRETE:8,30,IRON_FENCE,30,CONCRETE:8,100)
RandomBlock(-9,13,-3,CONCRETE:8,30,IRON_FENCE,30,CONCRETE:8,100)
RandomBlock(-9,13,-2,CONCRETE:8,30,IRON_FENCE,30,CONCRETE:8,100)
RandomBlock(-9,13,-1,CONCRETE:8,30,IRON_FENCE,30,CONCRETE:8,100)
RandomBlock(-9,13,0,CONCRETE:8,30,IRON_FENCE,30,CONCRETE:8,100)
RandomBlock(-9,13,1,CONCRETE:8,30,IRON_FENCE,30,CONCRETE:8,100)
RandomBlock(-9,13,2,CONCRETE:8,30,IRON_FENCE,30,CONCRETE:8,100)
RandomBlock(-9,13,3,CONCRETE:8,30,IRON_FENCE,30,CONCRETE:8,100)
RandomBlock(-9,13,4,CONCRETE:8,30,IRON_FENCE,30,CONCRETE:8,100)
RandomBlock(-9,13,5,CONCRETE:8,30,IRON_FENCE,30,CONCRETE:8,100)
RandomBlock(-9,13,6,CONCRETE:8,30,IRON_FENCE,30,CONCRETE:8,100)
RandomBlock(-9,13,7,CONCRETE:8,30,IRON_FENCE,30,CONCRETE:8,100)
RandomBlock(-9,13,8,CONCRETE:8,30,IRON_FENCE,30,CONCRETE:8,100)
RandomBlock(-9,13,9,CONCRETE:8,30,IRON_FENCE,30,CONCRETE:8,100)
RandomBlock(-9,13,10,CONCRETE:8,30,IRON_FENCE,30,CONCRETE:8,100)
RandomBlock(-9,13,11,CONCRETE:8,30,IRON_FENCE,30,CONCRETE:8,100)
RandomBlock(-9,13,12,CONCRETE:8,30,IRON_FENCE,30,CONCRETE:8,100)
RandomBlock(-9,14,-10,CONCRETE:8,30,IRON_FENCE,30,CONCRETE:8,100)
RandomBlock(-9,14,-9,CONCRETE:8,30,IRON_FENCE,30,CONCRETE:8,100)
RandomBlock(-9,14,-8,CONCRETE:8,30,IRON_FENCE,30,CONCRETE:8,100)
RandomBlock(-9,14,-7,CONCRETE:8,30,IRON_FENCE,30,CONCRETE:8,100)
RandomBlock(-9,14,-6,CONCRETE:8,30,IRON_FENCE,30,CONCRETE:8,100)
RandomBlock(-9,14,-5,CONCRETE:8,30,IRON_FENCE,30,CONCRETE:8,100)
RandomBlock(-9,14,-4,CONCRETE:8,30,IRON_FENCE,30,CONCRETE:8,100)
RandomBlock(-9,14,-3,CONCRETE:8,30,IRON_FENCE,30,CONCRETE:8,100)
RandomBlock(-9,14,-2,CONCRETE:8,30,IRON_FENCE,30,CONCRETE:8,100)
RandomBlock(-9,14,-1,CONCRETE:8,30,IRON_FENCE,30,CONCRETE:8,100)
RandomBlock(-9,14,0,CONCRETE:8,30,IRON_FENCE,30,CONCRETE:8,100)
RandomBlock(-9,14,1,CONCRETE:8,30,IRON_FENCE,30,CONCRETE:8,100)
RandomBlock(-9,14,2,CONCRETE:8,30,IRON_FENCE,30,CONCRETE:8,100)
RandomBlock(-9,14,3,CONCRETE:8,30,IRON_FENCE,30,CONCRETE:8,100)
RandomBlock(-9,14,4,CONCRETE:8,30,IRON_FENCE,30,CONCRETE:8,100)
RandomBlock(-9,14,5,CONCRETE:8,30,IRON_FENCE,30,CONCRETE:8,100)
RandomBlock(-9,14,6,CONCRETE:8,30,IRON_FENCE,30,CONCRETE:8,100)
RandomBlock(-9,14,7,CONCRETE:8,30,IRON_FENCE,30,CONCRETE:8,100)
RandomBlock(-9,14,8,CONCRETE:8,30,IRON_FENCE,30,CONCRETE:8,100)
RandomBlock(-9,14,9,CONCRETE:8,30,IRON_FENCE,30,CONCRETE:8,100)
RandomBlock(-9,14,10,CONCRETE:8,30,IRON_FENCE,30,CONCRETE:8,100)
RandomBlock(-9,14,11,CONCRETE:8,30,IRON_FENCE,30,CONCRETE:8,100)
RandomBlock(-9,14,12,CONCRETE:8,30,IRON_FENCE,30,CONCRETE:8,100)
RandomBlock(-9,15,-10,CONCRETE:8,30,IRON_FENCE,30,CONCRETE:8,100)
RandomBlock(-9,15,-9,CONCRETE:8,30,IRON_FENCE,30,CONCRETE:8,100)
RandomBlock(-9,15,-8,CONCRETE:8,30,IRON_FENCE,30,CONCRETE:8,100)
RandomBlock(-9,15,-7,CONCRETE:8,30,IRON_FENCE,30,CONCRETE:8,100)
RandomBlock(-9,15,-6,CONCRETE:8,30,IRON_FENCE,30,CONCRETE:8,100)
RandomBlock(-9,15,-5,CONCRETE:8,30,IRON_FENCE,30,CONCRETE:8,100)
RandomBlock(-9,15,-4,CONCRETE:8,30,IRON_FENCE,30,CONCRETE:8,100)
RandomBlock(-9,15,-3,CONCRETE:8,30,IRON_FENCE,30,CONCRETE:8,100)
RandomBlock(-9,15,-2,CONCRETE:8,30,IRON_FENCE,30,CONCRETE:8,100)
RandomBlock(-9,15,-1,CONCRETE:8,30,IRON_FENCE,30,CONCRETE:8,100)
RandomBlock(-9,15,0,CONCRETE:8,30,IRON_FENCE,30,CONCRETE:8,100)
RandomBlock(-9,15,1,CONCRETE:8,30,IRON_FENCE,30,CONCRETE:8,100)
RandomBlock(-9,15,2,CONCRETE:8,30,IRON_FENCE,30,CONCRETE:8,100)
RandomBlock(-9,15,3,CONCRETE:8,30,IRON_FENCE,30,CONCRETE:8,100)
RandomBlock(-9,15,4,CONCRETE:8,30,IRON_FENCE,30,CONCRETE:8,100)
RandomBlock(-9,15,5,CONCRETE:8,30,IRON_FENCE,30,CONCRETE:8,100)
RandomBlock(-9,15,6,CONCRETE:8,30,IRON_FENCE,30,CONCRETE:8,100)
RandomBlock(-9,15,7,CONCRETE:8,30,IRON_FENCE,30,CONCRETE:8,100)
RandomBlock(-9,15,8,CONCRETE:8,30,IRON_FENCE,30,CONCRETE:8,100)
RandomBlock(-9,15,9,CONCRETE:8,30,IRON_FENCE,30,CONCRETE:8,100)
RandomBlock(-9,15,10,CONCRETE:8,30,IRON_FENCE,30,CONCRETE:8,100)
RandomBlock(-9,15,11,CONCRETE:8,30,IRON_FENCE,30,CONCRETE:8,100)
RandomBlock(-9,15,12,CONCRETE:8,30,IRON_FENCE,30,CONCRETE:8,100)
RandomBlock(-9,16,-10,CONCRETE:8,30,IRON_FENCE,30,CONCRETE:8,100)
RandomBlock(-9,16,-9,CONCRETE:8,30,IRON_FENCE,30,CONCRETE:8,100)
RandomBlock(-9,16,-8,CONCRETE:8,30,IRON_FENCE,30,CONCRETE:8,100)
RandomBlock(-9,16,-7,CONCRETE:8,30,IRON_FENCE,30,CONCRETE:8,100)
RandomBlock(-9,16,-6,CONCRETE:8,30,IRON_FENCE,30,CONCRETE:8,100)
RandomBlock(-9,16,-5,CONCRETE:8,30,IRON_FENCE,30,CONCRETE:8,100)
RandomBlock(-9,16,-4,CONCRETE:8,30,IRON_FENCE,30,CONCRETE:8,100)
RandomBlock(-9,16,-3,CONCRETE:8,30,IRON_FENCE,30,CONCRETE:8,100)
RandomBlock(-9,16,-2,CONCRETE:8,30,IRON_FENCE,30,CONCRETE:8,100)
RandomBlock(-9,16,-1,CONCRETE:8,30,IRON_FENCE,30,CONCRETE:8,100)
RandomBlock(-9,16,0,CONCRETE:8,30,IRON_FENCE,30,CONCRETE:8,100)
RandomBlock(-9,16,1,CONCRETE:8,30,IRON_FENCE,30,CONCRETE:8,100)
RandomBlock(-9,16,2,CONCRETE:8,30,IRON_FENCE,30,CONCRETE:8,100)
RandomBlock(-9,16,3,CONCRETE:8,30,IRON_FENCE,30,CONCRETE:8,100)
RandomBlock(-9,16,4,CONCRETE:8,30,IRON_FENCE,30,CONCRETE:8,100)
RandomBlock(-9,16,5,CONCRETE:8,30,IRON_FENCE,30,CONCRETE:8,100)
RandomBlock(-9,16,6,CONCRETE:8,30,IRON_FENCE,30,CONCRETE:8,100)
RandomBlock(-9,16,7,CONCRETE:8,30,IRON_FENCE,30,CONCRETE:8,100)
RandomBlock(-9,16,8,CONCRETE:8,30,IRON_FENCE,30,CONCRETE:8,100)
RandomBlock(-9,16,9,CONCRETE:8,30,IRON_FENCE,30,CONCRETE:8,100)
RandomBlock(-9,16,10,CONCRETE:8,30,IRON_FENCE,30,CONCRETE:8,100)
RandomBlock(-9,16,11,CONCRETE:8,30,IRON_FENCE,30,CONCRETE:8,100)
RandomBlock(-9,16,12,CONCRETE:8,30,IRON_FENCE,30,CONCRETE:8,100)
RandomBlock(-9,17,-9,CONCRETE:8,30,IRON_FENCE,30,CONCRETE:8,100)
RandomBlock(-9,17,-8,CONCRETE:8,30,IRON_FENCE,30,CONCRETE:8,100)
RandomBlock(-9,17,-7,CONCRETE:8,30,IRON_FENCE,30,CONCRETE:8,100)
RandomBlock(-9,17,-6,CONCRETE:8,30,IRON_FENCE,30,CONCRETE:8,100)
RandomBlock(-9,17,-5,CONCRETE:8,30,IRON_FENCE,30,CONCRETE:8,100)
RandomBlock(-9,17,-4,CONCRETE:8,30,IRON_FENCE,30,CONCRETE:8,100)
RandomBlock(-9,17,-3,CONCRETE:8,30,IRON_FENCE,30,CONCRETE:8,100)
RandomBlock(-9,17,-2,CONCRETE:8,30,IRON_FENCE,30,CONCRETE:8,100)
RandomBlock(-9,17,-1,CONCRETE:8,30,IRON_FENCE,30,CONCRETE:8,100)
RandomBlock(-9,17,0,CONCRETE:8,30,IRON_FENCE,30,CONCRETE:8,100)
RandomBlock(-9,17,1,CONCRETE:8,30,IRON_FENCE,30,CONCRETE:8,100)
RandomBlock(-9,17,2,CONCRETE:8,30,IRON_FENCE,30,CONCRETE:8,100)
RandomBlock(-9,17,3,CONCRETE:8,30,IRON_FENCE,30,CONCRETE:8,100)
RandomBlock(-9,17,4,CONCRETE:8,30,IRON_FENCE,30,CONCRETE:8,100)
RandomBlock(-9,17,5,CONCRETE:8,30,IRON_FENCE,30,CONCRETE:8,100)
RandomBlock(-9,17,6,CONCRETE:8,30,IRON_FENCE,30,CONCRETE:8,100)
RandomBlock(-9,17,7,CONCRETE:8,30,IRON_FENCE,30,CONCRETE:8,100)
RandomBlock(-9,17,8,CONCRETE:8,30,IRON_FENCE,30,CONCRETE:8,100)
RandomBlock(-9,17,9,CONCRETE:8,30,IRON_FENCE,30,CONCRETE:8,100)
RandomBlock(-9,17,10,CONCRETE:8,30,IRON_FENCE,30,CONCRETE:8,100)
RandomBlock(-9,17,11,CONCRETE:8,30,IRON_FENCE,30,CONCRETE:8,100)
RandomBlock(-9,18,-9,CONCRETE:8,30,IRON_FENCE,30,CONCRETE:8,100)
RandomBlock(-9,18,-8,CONCRETE:8,30,IRON_FENCE,30,CONCRETE:8,100)
RandomBlock(-9,18,-7,CONCRETE:8,30,IRON_FENCE,30,CONCRETE:8,100)
RandomBlock(-9,18,-6,CONCRETE:8,30,IRON_FENCE,30,CONCRETE:8,100)
RandomBlock(-9,18,-5,CONCRETE:8,30,IRON_FENCE,30,CONCRETE:8,100)
RandomBlock(-9,18,-4,CONCRETE:8,30,IRON_FENCE,30,CONCRETE:8,100)
RandomBlock(-9,18,-3,CONCRETE:8,30,IRON_FENCE,30,CONCRETE:8,100)
RandomBlock(-9,18,-2,CONCRETE:8,30,IRON_FENCE,30,CONCRETE:8,100)
RandomBlock(-9,18,-1,CONCRETE:8,30,IRON_FENCE,30,CONCRETE:8,100)
RandomBlock(-9,18,0,CONCRETE:8,30,IRON_FENCE,30,CONCRETE:8,100)
RandomBlock(-9,18,1,CONCRETE:8,30,IRON_FENCE,30,CONCRETE:8,100)
RandomBlock(-9,18,2,CONCRETE:8,30,IRON_FENCE,30,CONCRETE:8,100)
RandomBlock(-9,18,3,CONCRETE:8,30,IRON_FENCE,30,CONCRETE:8,100)
RandomBlock(-9,18,4,CONCRETE:8,30,IRON_FENCE,30,CONCRETE:8,100)
RandomBlock(-9,18,5,CONCRETE:8,30,IRON_FENCE,30,CONCRETE:8,100)
RandomBlock(-9,18,6,CONCRETE:8,30,IRON_FENCE,30,CONCRETE:8,100)
RandomBlock(-9,18,7,CONCRETE:8,30,IRON_FENCE,30,CONCRETE:8,100)
RandomBlock(-9,18,8,CONCRETE:8,30,IRON_FENCE,30,CONCRETE:8,100)
RandomBlock(-9,18,9,CONCRETE:8,30,IRON_FENCE,30,CONCRETE:8,100)
RandomBlock(-9,18,10,CONCRETE:8,30,IRON_FENCE,30,CONCRETE:8,100)
RandomBlock(-9,18,11,CONCRETE:8,30,IRON_FENCE,30,CONCRETE:8,100)
RandomBlock(-9,19,-9,CONCRETE:8,30,IRON_FENCE,30,CONCRETE:8,100)
RandomBlock(-9,19,-8,CONCRETE:8,30,IRON_FENCE,30,CONCRETE:8,100)
RandomBlock(-9,19,-7,CONCRETE:8,30,IRON_FENCE,30,CONCRETE:8,100)
RandomBlock(-9,19,-6,CONCRETE:8,30,IRON_FENCE,30,CONCRETE:8,100)
RandomBlock(-9,19,-5,CONCRETE:8,30,IRON_FENCE,30,CONCRETE:8,100)
RandomBlock(-9,19,-4,CONCRETE:8,30,IRON_FENCE,30,CONCRETE:8,100)
RandomBlock(-9,19,-3,CONCRETE:8,30,IRON_FENCE,30,CONCRETE:8,100)
RandomBlock(-9,19,-2,CONCRETE:8,30,IRON_FENCE,30,CONCRETE:8,100)
RandomBlock(-9,19,-1,CONCRETE:8,30,IRON_FENCE,30,CONCRETE:8,100)
RandomBlock(-9,19,0,CONCRETE:8,30,IRON_FENCE,30,CONCRETE:8,100)
RandomBlock(-9,19,1,CONCRETE:8,30,IRON_FENCE,30,CONCRETE:8,100)
RandomBlock(-9,19,2,CONCRETE:8,30,IRON_FENCE,30,CONCRETE:8,100)
RandomBlock(-9,19,3,CONCRETE:8,30,IRON_FENCE,30,CONCRETE:8,100)
RandomBlock(-9,19,4,CONCRETE:8,30,IRON_FENCE,30,CONCRETE:8,100)
RandomBlock(-9,19,5,CONCRETE:8,30,IRON_FENCE,30,CONCRETE:8,100)
RandomBlock(-9,19,6,CONCRETE:8,30,IRON_FENCE,30,CONCRETE:8,100)
RandomBlock(-9,19,7,CONCRETE:8,30,IRON_FENCE,30,CONCRETE:8,100)
RandomBlock(-9,19,8,CONCRETE:8,30,IRON_FENCE,30,CONCRETE:8,100)
RandomBlock(-9,19,9,CONCRETE:8,30,IRON_FENCE,30,CONCRETE:8,100)
RandomBlock(-9,19,10,CONCRETE:8,30,IRON_FENCE,30,CONCRETE:8,100)
RandomBlock(-9,19,11,CONCRETE:8,30,IRON_FENCE,30,CONCRETE:8,100)
RandomBlock(-9,20,-8,CONCRETE:8,30,IRON_FENCE,30,CONCRETE:8,100)
RandomBlock(-9,20,-7,CONCRETE:8,30,IRON_FENCE,30,CONCRETE:8,100)
RandomBlock(-9,20,-6,CONCRETE:8,30,IRON_FENCE,30,CONCRETE:8,100)
RandomBlock(-9,20,-5,CONCRETE:8,30,IRON_FENCE,30,CONCRETE:8,100)
RandomBlock(-9,20,-4,CONCRETE:8,30,IRON_FENCE,30,CONCRETE:8,100)
RandomBlock(-9,20,-3,CONCRETE:8,30,IRON_FENCE,30,CONCRETE:8,100)
RandomBlock(-9,20,-2,CONCRETE:8,30,IRON_FENCE,30,CONCRETE:8,100)
RandomBlock(-9,20,-1,CONCRETE:8,30,IRON_FENCE,30,CONCRETE:8,100)
RandomBlock(-9,20,0,CONCRETE:8,30,IRON_FENCE,30,CONCRETE:8,100)
RandomBlock(-9,20,1,CONCRETE:8,30,IRON_FENCE,30,CONCRETE:8,100)
RandomBlock(-9,20,2,CONCRETE:8,30,IRON_FENCE,30,CONCRETE:8,100)
RandomBlock(-9,20,3,CONCRETE:8,30,IRON_FENCE,30,CONCRETE:8,100)
RandomBlock(-9,20,4,CONCRETE:8,30,IRON_FENCE,30,CONCRETE:8,100)
RandomBlock(-9,20,5,CONCRETE:8,30,IRON_FENCE,30,CONCRETE:8,100)
RandomBlock(-9,20,6,CONCRETE:8,30,IRON_FENCE,30,CONCRETE:8,100)
RandomBlock(-9,20,7,CONCRETE:8,30,IRON_FENCE,30,CONCRETE:8,100)
RandomBlock(-9,20,8,CONCRETE:8,30,IRON_FENCE,30,CONCRETE:8,100)
RandomBlock(-9,20,9,CONCRETE:8,30,IRON_FENCE,30,CONCRETE:8,100)
RandomBlock(-9,20,10,CONCRETE:8,30,IRON_FENCE,30,CONCRETE:8,100)
RandomBlock(-9,21,-7,CONCRETE:8,30,IRON_FENCE,30,CONCRETE:8,100)
RandomBlock(-9,21,-6,CONCRETE:8,30,IRON_FENCE,30,CONCRETE:8,100)
RandomBlock(-9,21,-5,CONCRETE:8,30,IRON_FENCE,30,CONCRETE:8,100)
RandomBlock(-9,21,-4,CONCRETE:8,30,IRON_FENCE,30,CONCRETE:8,100)
RandomBlock(-9,21,-3,CONCRETE:8,30,IRON_FENCE,30,CONCRETE:8,100)
RandomBlock(-9,21,-2,CONCRETE:8,30,IRON_FENCE,30,CONCRETE:8,100)
RandomBlock(-9,21,-1,CONCRETE:8,30,IRON_FENCE,30,CONCRETE:8,100)
RandomBlock(-9,21,0,CONCRETE:8,30,IRON_FENCE,30,CONCRETE:8,100)
RandomBlock(-9,21,1,CONCRETE:8,30,IRON_FENCE,30,CONCRETE:8,100)
RandomBlock(-9,21,2,CONCRETE:8,30,IRON_FENCE,30,CONCRETE:8,100)
RandomBlock(-9,21,3,CONCRETE:8,30,IRON_FENCE,30,CONCRETE:8,100)
RandomBlock(-9,21,4,CONCRETE:8,30,IRON_FENCE,30,CONCRETE:8,100)
RandomBlock(-9,21,5,CONCRETE:8,30,IRON_FENCE,30,CONCRETE:8,100)
RandomBlock(-9,21,6,CONCRETE:8,30,IRON_FENCE,30,CONCRETE:8,100)
RandomBlock(-9,21,7,CONCRETE:8,30,IRON_FENCE,30,CONCRETE:8,100)
RandomBlock(-9,21,8,CONCRETE:8,30,IRON_FENCE,30,CONCRETE:8,100)
RandomBlock(-9,21,9,CONCRETE:8,30,IRON_FENCE,30,CONCRETE:8,100)
RandomBlock(-9,22,-6,CONCRETE:8,30,IRON_FENCE,30,CONCRETE:8,100)
RandomBlock(-9,22,-5,CONCRETE:8,30,IRON_FENCE,30,CONCRETE:8,100)
RandomBlock(-9,22,-4,CONCRETE:8,30,IRON_FENCE,30,CONCRETE:8,100)
RandomBlock(-9,22,-3,CONCRETE:8,30,IRON_FENCE,30,CONCRETE:8,100)
RandomBlock(-9,22,-2,CONCRETE:8,30,IRON_FENCE,30,CONCRETE:8,100)
RandomBlock(-9,22,-1,CONCRETE:8,30,IRON_FENCE,30,CONCRETE:8,100)
RandomBlock(-9,22,0,CONCRETE:8,30,IRON_FENCE,30,CONCRETE:8,100)
RandomBlock(-9,22,1,CONCRETE:8,30,IRON_FENCE,30,CONCRETE:8,100)
RandomBlock(-9,22,2,CONCRETE:8,30,IRON_FENCE,30,CONCRETE:8,100)
RandomBlock(-9,22,3,CONCRETE:8,30,IRON_FENCE,30,CONCRETE:8,100)
RandomBlock(-9,22,4,CONCRETE:8,30,IRON_FENCE,30,CONCRETE:8,100)
RandomBlock(-9,22,5,CONCRETE:8,30,IRON_FENCE,30,CONCRETE:8,100)
RandomBlock(-9,22,6,CONCRETE:8,30,IRON_FENCE,30,CONCRETE:8,100)
RandomBlock(-9,22,7,CONCRETE:8,30,IRON_FENCE,30,CONCRETE:8,100)
RandomBlock(-9,22,8,CONCRETE:8,30,IRON_FENCE,30,CONCRETE:8,100)
RandomBlock(-9,23,-5,CONCRETE:8,30,IRON_FENCE,30,CONCRETE:8,100)
RandomBlock(-9,23,-4,CONCRETE:8,30,IRON_FENCE,30,CONCRETE:8,100)
RandomBlock(-9,23,-3,CONCRETE:8,30,IRON_FENCE,30,CONCRETE:8,100)
RandomBlock(-9,23,-2,CONCRETE:8,30,IRON_FENCE,30,CONCRETE:8,100)
RandomBlock(-9,23,-1,CONCRETE:8,30,IRON_FENCE,30,CONCRETE:8,100)
RandomBlock(-9,23,0,CONCRETE:8,30,IRON_FENCE,30,CONCRETE:8,100)
RandomBlock(-9,23,1,CONCRETE:8,30,IRON_FENCE,30,CONCRETE:8,100)
RandomBlock(-9,23,2,CONCRETE:8,30,IRON_FENCE,30,CONCRETE:8,100)
RandomBlock(-9,23,3,CONCRETE:8,30,IRON_FENCE,30,CONCRETE:8,100)
RandomBlock(-9,23,4,CONCRETE:8,30,IRON_FENCE,30,CONCRETE:8,100)
RandomBlock(-9,23,5,CONCRETE:8,30,IRON_FENCE,30,CONCRETE:8,100)
RandomBlock(-9,23,6,CONCRETE:8,30,IRON_FENCE,30,CONCRETE:8,100)
RandomBlock(-9,23,7,CONCRETE:8,30,IRON_FENCE,30,CONCRETE:8,100)
RandomBlock(-9,24,-4,CONCRETE:8,30,IRON_FENCE,30,CONCRETE:8,100)
RandomBlock(-9,24,-3,CONCRETE:8,30,IRON_FENCE,30,CONCRETE:8,100)
RandomBlock(-9,24,-2,CONCRETE:8,30,IRON_FENCE,30,CONCRETE:8,100)
RandomBlock(-9,24,-1,CONCRETE:8,30,IRON_FENCE,30,CONCRETE:8,100)
RandomBlock(-9,24,0,CONCRETE:8,30,IRON_FENCE,30,CONCRETE:8,100)
RandomBlock(-9,24,1,CONCRETE:8,30,IRON_FENCE,30,CONCRETE:8,100)
RandomBlock(-9,24,2,CONCRETE:8,30,IRON_FENCE,30,CONCRETE:8,100)
RandomBlock(-9,24,3,CONCRETE:8,30,IRON_FENCE,30,CONCRETE:8,100)
RandomBlock(-9,24,4,CONCRETE:8,30,IRON_FENCE,30,CONCRETE:8,100)
RandomBlock(-9,24,5,CONCRETE:8,30,IRON_FENCE,30,CONCRETE:8,100)
RandomBlock(-9,24,6,CONCRETE:8,30,IRON_FENCE,30,CONCRETE:8,100)
RandomBlock(-9,25,-1,CONCRETE:8,30,IRON_FENCE,30,CONCRETE:8,100)
RandomBlock(-9,25,0,CONCRETE:8,30,IRON_FENCE,30,CONCRETE:8,100)
RandomBlock(-9,25,1,CONCRETE:8,30,IRON_FENCE,30,CONCRETE:8,100)
RandomBlock(-9,25,2,CONCRETE:8,30,IRON_FENCE,30,CONCRETE:8,100)
RandomBlock(-9,25,3,CONCRETE:8,30,IRON_FENCE,30,CONCRETE:8,100)
RandomBlock(-8,2,1,CONCRETE:8,30,IRON_FENCE,30,CONCRETE:8,100)
RandomBlock(-8,3,-3,CONCRETE:8,30,IRON_FENCE,30,CONCRETE:8,100)
RandomBlock(-8,3,-2,CONCRETE:8,30,IRON_FENCE,30,CONCRETE:8,100)
RandomBlock(-8,3,-1,CONCRETE:8,30,IRON_FENCE,30,CONCRETE:8,100)
RandomBlock(-8,3,0,CONCRETE:8,30,IRON_FENCE,30,CONCRETE:8,100)
RandomBlock(-8,3,1,CONCRETE:8,30,IRON_FENCE,30,CONCRETE:8,100)
RandomBlock(-8,3,2,CONCRETE:8,30,IRON_FENCE,30,CONCRETE:8,100)
RandomBlock(-8,3,3,CONCRETE:8,30,IRON_FENCE,30,CONCRETE:8,100)
RandomBlock(-8,3,4,CONCRETE:8,30,IRON_FENCE,30,CONCRETE:8,100)
RandomBlock(-8,3,5,CONCRETE:8,30,IRON_FENCE,30,CONCRETE:8,100)
RandomBlock(-8,4,-5,CONCRETE:8,30,IRON_FENCE,30,CONCRETE:8,100)
RandomBlock(-8,4,-4,CONCRETE:8,30,IRON_FENCE,30,CONCRETE:8,100)
RandomBlock(-8,4,-3,CONCRETE:8,30,IRON_FENCE,30,CONCRETE:8,100)
RandomBlock(-8,4,-2,CONCRETE:8,30,IRON_FENCE,30,CONCRETE:8,100)
RandomBlock(-8,4,-1,CONCRETE:8,30,IRON_FENCE,30,CONCRETE:8,100)
RandomBlock(-8,4,0,CONCRETE:8,30,IRON_FENCE,30,CONCRETE:8,100)
RandomBlock(-8,4,1,CONCRETE:8,30,IRON_FENCE,30,CONCRETE:8,100)
RandomBlock(-8,4,2,CONCRETE:8,30,IRON_FENCE,30,CONCRETE:8,100)
RandomBlock(-8,4,3,CONCRETE:8,30,IRON_FENCE,30,CONCRETE:8,100)
RandomBlock(-8,4,4,CONCRETE:8,30,IRON_FENCE,30,CONCRETE:8,100)
RandomBlock(-8,4,5,CONCRETE:8,30,IRON_FENCE,30,CONCRETE:8,100)
RandomBlock(-8,4,6,CONCRETE:8,30,IRON_FENCE,30,CONCRETE:8,100)
RandomBlock(-8,4,7,CONCRETE:8,30,IRON_FENCE,30,CONCRETE:8,100)
RandomBlock(-8,5,-6,CONCRETE:8,30,IRON_FENCE,30,CONCRETE:8,100)
RandomBlock(-8,5,-5,CONCRETE:8,30,IRON_FENCE,30,CONCRETE:8,100)
RandomBlock(-8,5,-4,CONCRETE:8,30,IRON_FENCE,30,CONCRETE:8,100)
RandomBlock(-8,5,-3,CONCRETE:8,30,IRON_FENCE,30,CONCRETE:8,100)
RandomBlock(-8,5,-2,CONCRETE:8,30,IRON_FENCE,30,CONCRETE:8,100)
RandomBlock(-8,5,-1,CONCRETE:8,30,IRON_FENCE,30,CONCRETE:8,100)
RandomBlock(-8,5,0,CONCRETE:8,30,IRON_FENCE,30,CONCRETE:8,100)
RandomBlock(-8,5,1,CONCRETE:8,30,IRON_FENCE,30,CONCRETE:8,100)
RandomBlock(-8,5,2,CONCRETE:8,30,IRON_FENCE,30,CONCRETE:8,100)
RandomBlock(-8,5,3,CONCRETE:8,30,IRON_FENCE,30,CONCRETE:8,100)
RandomBlock(-8,5,4,CONCRETE:8,30,IRON_FENCE,30,CONCRETE:8,100)
RandomBlock(-8,5,5,CONCRETE:8,30,IRON_FENCE,30,CONCRETE:8,100)
RandomBlock(-8,5,6,CONCRETE:8,30,IRON_FENCE,30,CONCRETE:8,100)
RandomBlock(-8,5,7,CONCRETE:8,30,IRON_FENCE,30,CONCRETE:8,100)
RandomBlock(-8,5,8,CONCRETE:8,30,IRON_FENCE,30,CONCRETE:8,100)
RandomBlock(-8,6,-7,CONCRETE:8,30,IRON_FENCE,30,CONCRETE:8,100)
RandomBlock(-8,6,-6,CONCRETE:8,30,IRON_FENCE,30,CONCRETE:8,100)
RandomBlock(-8,6,-5,CONCRETE:8,30,IRON_FENCE,30,CONCRETE:8,100)
RandomBlock(-8,6,-4,CONCRETE:8,30,IRON_FENCE,30,CONCRETE:8,100)
RandomBlock(-8,6,-3,CONCRETE:8,30,IRON_FENCE,30,CONCRETE:8,100)
RandomBlock(-8,6,-2,CONCRETE:8,30,IRON_FENCE,30,CONCRETE:8,100)
RandomBlock(-8,6,-1,CONCRETE:8,30,IRON_FENCE,30,CONCRETE:8,100)
RandomBlock(-8,6,0,CONCRETE:8,30,IRON_FENCE,30,CONCRETE:8,100)
RandomBlock(-8,6,1,CONCRETE:8,30,IRON_FENCE,30,CONCRETE:8,100)
RandomBlock(-8,6,2,CONCRETE:8,30,IRON_FENCE,30,CONCRETE:8,100)
RandomBlock(-8,6,3,CONCRETE:8,30,IRON_FENCE,30,CONCRETE:8,100)
RandomBlock(-8,6,4,CONCRETE:8,30,IRON_FENCE,30,CONCRETE:8,100)
RandomBlock(-8,6,5,CONCRETE:8,30,IRON_FENCE,30,CONCRETE:8,100)
RandomBlock(-8,6,6,CONCRETE:8,30,IRON_FENCE,30,CONCRETE:8,100)
RandomBlock(-8,6,7,CONCRETE:8,30,IRON_FENCE,30,CONCRETE:8,100)
RandomBlock(-8,6,8,CONCRETE:8,30,IRON_FENCE,30,CONCRETE:8,100)
RandomBlock(-8,6,9,CONCRETE:8,30,IRON_FENCE,30,CONCRETE:8,100)
RandomBlock(-8,7,-8,CONCRETE:8,30,IRON_FENCE,30,CONCRETE:8,100)
RandomBlock(-8,7,-7,CONCRETE:8,30,IRON_FENCE,30,CONCRETE:8,100)
RandomBlock(-8,7,-6,CONCRETE:8,30,IRON_FENCE,30,CONCRETE:8,100)
RandomBlock(-8,7,-5,CONCRETE:8,30,IRON_FENCE,30,CONCRETE:8,100)
RandomBlock(-8,7,-4,CONCRETE:8,30,IRON_FENCE,30,CONCRETE:8,100)
RandomBlock(-8,7,-3,CONCRETE:8,30,IRON_FENCE,30,CONCRETE:8,100)
RandomBlock(-8,7,-2,CONCRETE:8,30,IRON_FENCE,30,CONCRETE:8,100)
RandomBlock(-8,7,-1,CONCRETE:8,30,IRON_FENCE,30,CONCRETE:8,100)
RandomBlock(-8,7,0,CONCRETE:8,30,IRON_FENCE,30,CONCRETE:8,100)
RandomBlock(-8,7,1,CONCRETE:8,30,IRON_FENCE,30,CONCRETE:8,100)
RandomBlock(-8,7,2,CONCRETE:8,30,IRON_FENCE,30,CONCRETE:8,100)
RandomBlock(-8,7,3,CONCRETE:8,30,IRON_FENCE,30,CONCRETE:8,100)
RandomBlock(-8,7,4,CONCRETE:8,30,IRON_FENCE,30,CONCRETE:8,100)
RandomBlock(-8,7,5,CONCRETE:8,30,IRON_FENCE,30,CONCRETE:8,100)
RandomBlock(-8,7,6,CONCRETE:8,30,IRON_FENCE,30,CONCRETE:8,100)
RandomBlock(-8,7,7,CONCRETE:8,30,IRON_FENCE,30,CONCRETE:8,100)
RandomBlock(-8,7,8,CONCRETE:8,30,IRON_FENCE,30,CONCRETE:8,100)
RandomBlock(-8,7,9,CONCRETE:8,30,IRON_FENCE,30,CONCRETE:8,100)
RandomBlock(-8,7,10,CONCRETE:8,30,IRON_FENCE,30,CONCRETE:8,100)
RandomBlock(-8,8,-9,CONCRETE:8,30,IRON_FENCE,30,CONCRETE:8,100)
RandomBlock(-8,8,-8,CONCRETE:8,30,IRON_FENCE,30,CONCRETE:8,100)
RandomBlock(-8,8,-7,CONCRETE:8,30,IRON_FENCE,30,CONCRETE:8,100)
RandomBlock(-8,8,-6,CONCRETE:8,30,IRON_FENCE,30,CONCRETE:8,100)
RandomBlock(-8,8,-5,CONCRETE:8,30,IRON_FENCE,30,CONCRETE:8,100)
RandomBlock(-8,8,-4,CONCRETE:8,30,IRON_FENCE,30,CONCRETE:8,100)
RandomBlock(-8,8,-3,CONCRETE:8,30,IRON_FENCE,30,CONCRETE:8,100)
RandomBlock(-8,8,-2,CONCRETE:8,30,IRON_FENCE,30,CONCRETE:8,100)
RandomBlock(-8,8,-1,CONCRETE:8,30,IRON_FENCE,30,CONCRETE:8,100)
RandomBlock(-8,8,0,CONCRETE:8,30,IRON_FENCE,30,CONCRETE:8,100)
RandomBlock(-8,8,1,CONCRETE:8,30,IRON_FENCE,30,CONCRETE:8,100)
RandomBlock(-8,8,2,CONCRETE:8,30,IRON_FENCE,30,CONCRETE:8,100)
RandomBlock(-8,8,3,CONCRETE:8,30,IRON_FENCE,30,CONCRETE:8,100)
RandomBlock(-8,8,4,CONCRETE:8,30,IRON_FENCE,30,CONCRETE:8,100)
RandomBlock(-8,8,5,CONCRETE:8,30,IRON_FENCE,30,CONCRETE:8,100)
RandomBlock(-8,8,6,CONCRETE:8,30,IRON_FENCE,30,CONCRETE:8,100)
RandomBlock(-8,8,7,CONCRETE:8,30,IRON_FENCE,30,CONCRETE:8,100)
RandomBlock(-8,8,8,CONCRETE:8,30,IRON_FENCE,30,CONCRETE:8,100)
RandomBlock(-8,8,9,CONCRETE:8,30,IRON_FENCE,30,CONCRETE:8,100)
RandomBlock(-8,8,10,CONCRETE:8,30,IRON_FENCE,30,CONCRETE:8,100)
RandomBlock(-8,8,11,CONCRETE:8,30,IRON_FENCE,30,CONCRETE:8,100)
RandomBlock(-8,9,-9,CONCRETE:8,30,IRON_FENCE,30,CONCRETE:8,100)
RandomBlock(-8,9,-8,CONCRETE:8,30,IRON_FENCE,30,CONCRETE:8,100)
RandomBlock(-8,9,-7,CONCRETE:8,30,IRON_FENCE,30,CONCRETE:8,100)
RandomBlock(-8,9,-6,CONCRETE:8,30,IRON_FENCE,30,CONCRETE:8,100)
RandomBlock(-8,9,-5,CONCRETE:8,30,IRON_FENCE,30,CONCRETE:8,100)
RandomBlock(-8,9,-4,CONCRETE:8,30,IRON_FENCE,30,CONCRETE:8,100)
RandomBlock(-8,9,-3,CONCRETE:8,30,IRON_FENCE,30,CONCRETE:8,100)
RandomBlock(-8,9,-2,CONCRETE:8,30,IRON_FENCE,30,CONCRETE:8,100)
RandomBlock(-8,9,-1,CONCRETE:8,30,IRON_FENCE,30,CONCRETE:8,100)
RandomBlock(-8,9,0,CONCRETE:8,30,IRON_FENCE,30,CONCRETE:8,100)
RandomBlock(-8,9,1,CONCRETE:8,30,IRON_FENCE,30,CONCRETE:8,100)
RandomBlock(-8,9,2,CONCRETE:8,30,IRON_FENCE,30,CONCRETE:8,100)
RandomBlock(-8,9,3,CONCRETE:8,30,IRON_FENCE,30,CONCRETE:8,100)
RandomBlock(-8,9,4,CONCRETE:8,30,IRON_FENCE,30,CONCRETE:8,100)
RandomBlock(-8,9,5,CONCRETE:8,30,IRON_FENCE,30,CONCRETE:8,100)
RandomBlock(-8,9,6,CONCRETE:8,30,IRON_FENCE,30,CONCRETE:8,100)
RandomBlock(-8,9,7,CONCRETE:8,30,IRON_FENCE,30,CONCRETE:8,100)
RandomBlock(-8,9,8,CONCRETE:8,30,IRON_FENCE,30,CONCRETE:8,100)
RandomBlock(-8,9,9,CONCRETE:8,30,IRON_FENCE,30,CONCRETE:8,100)
RandomBlock(-8,9,10,CONCRETE:8,30,IRON_FENCE,30,CONCRETE:8,100)
RandomBlock(-8,9,11,CONCRETE:8,30,IRON_FENCE,30,CONCRETE:8,100)
RandomBlock(-8,10,-10,CONCRETE:8,30,IRON_FENCE,30,CONCRETE:8,100)
RandomBlock(-8,10,-9,CONCRETE:8,30,IRON_FENCE,30,CONCRETE:8,100)
RandomBlock(-8,10,-8,CONCRETE:8,30,IRON_FENCE,30,CONCRETE:8,100)
RandomBlock(-8,10,-7,CONCRETE:8,30,IRON_FENCE,30,CONCRETE:8,100)
RandomBlock(-8,10,-6,CONCRETE:8,30,IRON_FENCE,30,CONCRETE:8,100)
RandomBlock(-8,10,-5,CONCRETE:8,30,IRON_FENCE,30,CONCRETE:8,100)
RandomBlock(-8,10,-4,CONCRETE:8,30,IRON_FENCE,30,CONCRETE:8,100)
RandomBlock(-8,10,-3,CONCRETE:8,30,IRON_FENCE,30,CONCRETE:8,100)
RandomBlock(-8,10,-2,CONCRETE:8,30,IRON_FENCE,30,CONCRETE:8,100)
RandomBlock(-8,10,-1,CONCRETE:8,30,IRON_FENCE,30,CONCRETE:8,100)
RandomBlock(-8,10,0,CONCRETE:8,30,IRON_FENCE,30,CONCRETE:8,100)
RandomBlock(-8,10,1,CONCRETE:8,30,IRON_FENCE,30,CONCRETE:8,100)
RandomBlock(-8,10,2,CONCRETE:8,30,IRON_FENCE,30,CONCRETE:8,100)
RandomBlock(-8,10,3,CONCRETE:8,30,IRON_FENCE,30,CONCRETE:8,100)
RandomBlock(-8,10,4,CONCRETE:8,30,IRON_FENCE,30,CONCRETE:8,100)
RandomBlock(-8,10,5,CONCRETE:8,30,IRON_FENCE,30,CONCRETE:8,100)
RandomBlock(-8,10,6,CONCRETE:8,30,IRON_FENCE,30,CONCRETE:8,100)
RandomBlock(-8,10,7,CONCRETE:8,30,IRON_FENCE,30,CONCRETE:8,100)
RandomBlock(-8,10,8,CONCRETE:8,30,IRON_FENCE,30,CONCRETE:8,100)
RandomBlock(-8,10,9,CONCRETE:8,30,IRON_FENCE,30,CONCRETE:8,100)
RandomBlock(-8,10,10,CONCRETE:8,30,IRON_FENCE,30,CONCRETE:8,100)
RandomBlock(-8,10,11,CONCRETE:8,30,IRON_FENCE,30,CONCRETE:8,100)
RandomBlock(-8,10,12,CONCRETE:8,30,IRON_FENCE,30,CONCRETE:8,100)
RandomBlock(-8,11,-10,CONCRETE:8,30,IRON_FENCE,30,CONCRETE:8,100)
RandomBlock(-8,11,-9,CONCRETE:8,30,IRON_FENCE,30,CONCRETE:8,100)
RandomBlock(-8,11,-8,CONCRETE:8,30,IRON_FENCE,30,CONCRETE:8,100)
RandomBlock(-8,11,-7,CONCRETE:8,30,IRON_FENCE,30,CONCRETE:8,100)
RandomBlock(-8,11,-6,CONCRETE:8,30,IRON_FENCE,30,CONCRETE:8,100)
RandomBlock(-8,11,-5,CONCRETE:8,30,IRON_FENCE,30,CONCRETE:8,100)
RandomBlock(-8,11,-4,CONCRETE:8,30,IRON_FENCE,30,CONCRETE:8,100)
RandomBlock(-8,11,-3,CONCRETE:8,30,IRON_FENCE,30,CONCRETE:8,100)
RandomBlock(-8,11,-2,CONCRETE:8,30,IRON_FENCE,30,CONCRETE:8,100)
RandomBlock(-8,11,-1,CONCRETE:8,30,IRON_FENCE,30,CONCRETE:8,100)
RandomBlock(-8,11,0,CONCRETE:8,30,IRON_FENCE,30,CONCRETE:8,100)
RandomBlock(-8,11,1,CONCRETE:8,30,IRON_FENCE,30,CONCRETE:8,100)
RandomBlock(-8,11,2,CONCRETE:8,30,IRON_FENCE,30,CONCRETE:8,100)
RandomBlock(-8,11,3,CONCRETE:8,30,IRON_FENCE,30,CONCRETE:8,100)
RandomBlock(-8,11,4,CONCRETE:8,30,IRON_FENCE,30,CONCRETE:8,100)
RandomBlock(-8,11,5,CONCRETE:8,30,IRON_FENCE,30,CONCRETE:8,100)
RandomBlock(-8,11,6,CONCRETE:8,30,IRON_FENCE,30,CONCRETE:8,100)
RandomBlock(-8,11,7,CONCRETE:8,30,IRON_FENCE,30,CONCRETE:8,100)
RandomBlock(-8,11,8,CONCRETE:8,30,IRON_FENCE,30,CONCRETE:8,100)
RandomBlock(-8,11,9,CONCRETE:8,30,IRON_FENCE,30,CONCRETE:8,100)
RandomBlock(-8,11,10,CONCRETE:8,30,IRON_FENCE,30,CONCRETE:8,100)
RandomBlock(-8,11,11,CONCRETE:8,30,IRON_FENCE,30,CONCRETE:8,100)
RandomBlock(-8,11,12,CONCRETE:8,30,IRON_FENCE,30,CONCRETE:8,100)
RandomBlock(-8,12,-10,CONCRETE:8,30,IRON_FENCE,30,CONCRETE:8,100)
RandomBlock(-8,12,-9,CONCRETE:8,30,IRON_FENCE,30,CONCRETE:8,100)
RandomBlock(-8,12,-8,CONCRETE:8,30,IRON_FENCE,30,CONCRETE:8,100)
RandomBlock(-8,12,-7,CONCRETE:8,30,IRON_FENCE,30,CONCRETE:8,100)
RandomBlock(-8,12,-6,CONCRETE:8,30,IRON_FENCE,30,CONCRETE:8,100)
RandomBlock(-8,12,-5,CONCRETE:8,30,IRON_FENCE,30,CONCRETE:8,100)
RandomBlock(-8,12,-4,CONCRETE:8,30,IRON_FENCE,30,CONCRETE:8,100)
RandomBlock(-8,12,-3,CONCRETE:8,30,IRON_FENCE,30,CONCRETE:8,100)
RandomBlock(-8,12,-2,CONCRETE:8,30,IRON_FENCE,30,CONCRETE:8,100)
RandomBlock(-8,12,-1,CONCRETE:8,30,IRON_FENCE,30,CONCRETE:8,100)
RandomBlock(-8,12,0,CONCRETE:8,30,IRON_FENCE,30,CONCRETE:8,100)
RandomBlock(-8,12,1,CONCRETE:8,30,IRON_FENCE,30,CONCRETE:8,100)
RandomBlock(-8,12,2,CONCRETE:8,30,IRON_FENCE,30,CONCRETE:8,100)
RandomBlock(-8,12,3,CONCRETE:8,30,IRON_FENCE,30,CONCRETE:8,100)
RandomBlock(-8,12,4,CONCRETE:8,30,IRON_FENCE,30,CONCRETE:8,100)
RandomBlock(-8,12,5,CONCRETE:8,30,IRON_FENCE,30,CONCRETE:8,100)
RandomBlock(-8,12,6,CONCRETE:8,30,IRON_FENCE,30,CONCRETE:8,100)
RandomBlock(-8,12,7,CONCRETE:8,30,IRON_FENCE,30,CONCRETE:8,100)
RandomBlock(-8,12,8,CONCRETE:8,30,IRON_FENCE,30,CONCRETE:8,100)
RandomBlock(-8,12,9,CONCRETE:8,30,IRON_FENCE,30,CONCRETE:8,100)
RandomBlock(-8,12,10,CONCRETE:8,30,IRON_FENCE,30,CONCRETE:8,100)
RandomBlock(-8,12,11,CONCRETE:8,30,IRON_FENCE,30,CONCRETE:8,100)
RandomBlock(-8,12,12,CONCRETE:8,30,IRON_FENCE,30,CONCRETE:8,100)
RandomBlock(-8,13,-10,CONCRETE:8,30,IRON_FENCE,30,CONCRETE:8,100)
RandomBlock(-8,13,-9,CONCRETE:8,30,IRON_FENCE,30,CONCRETE:8,100)
RandomBlock(-8,13,-8,CONCRETE:8,30,IRON_FENCE,30,CONCRETE:8,100)
RandomBlock(-8,13,-7,CONCRETE:8,30,IRON_FENCE,30,CONCRETE:8,100)
RandomBlock(-8,13,-6,CONCRETE:8,30,IRON_FENCE,30,CONCRETE:8,100)
RandomBlock(-8,13,-5,CONCRETE:8,30,IRON_FENCE,30,CONCRETE:8,100)
RandomBlock(-8,13,-4,CONCRETE:8,30,IRON_FENCE,30,CONCRETE:8,100)
RandomBlock(-8,13,-3,CONCRETE:8,30,IRON_FENCE,30,CONCRETE:8,100)
RandomBlock(-8,13,-2,CONCRETE:8,30,IRON_FENCE,30,CONCRETE:8,100)
RandomBlock(-8,13,-1,CONCRETE:8,30,IRON_FENCE,30,CONCRETE:8,100)
RandomBlock(-8,13,0,CONCRETE:8,30,IRON_FENCE,30,CONCRETE:8,100)
RandomBlock(-8,13,1,CONCRETE:8,30,IRON_FENCE,30,CONCRETE:8,100)
RandomBlock(-8,13,2,CONCRETE:8,30,IRON_FENCE,30,CONCRETE:8,100)
RandomBlock(-8,13,3,CONCRETE:8,30,IRON_FENCE,30,CONCRETE:8,100)
RandomBlock(-8,13,4,CONCRETE:8,30,IRON_FENCE,30,CONCRETE:8,100)
RandomBlock(-8,13,5,CONCRETE:8,30,IRON_FENCE,30,CONCRETE:8,100)
RandomBlock(-8,13,6,CONCRETE:8,30,IRON_FENCE,30,CONCRETE:8,100)
RandomBlock(-8,13,7,CONCRETE:8,30,IRON_FENCE,30,CONCRETE:8,100)
RandomBlock(-8,13,8,CONCRETE:8,30,IRON_FENCE,30,CONCRETE:8,100)
RandomBlock(-8,13,9,CONCRETE:8,30,IRON_FENCE,30,CONCRETE:8,100)
RandomBlock(-8,13,10,CONCRETE:8,30,IRON_FENCE,30,CONCRETE:8,100)
RandomBlock(-8,13,11,CONCRETE:8,30,IRON_FENCE,30,CONCRETE:8,100)
RandomBlock(-8,13,12,CONCRETE:8,30,IRON_FENCE,30,CONCRETE:8,100)
RandomBlock(-8,14,-11,CONCRETE:8,30,IRON_FENCE,30,CONCRETE:8,100)
RandomBlock(-8,14,-10,CONCRETE:8,30,IRON_FENCE,30,CONCRETE:8,100)
RandomBlock(-8,14,-9,CONCRETE:8,30,IRON_FENCE,30,CONCRETE:8,100)
RandomBlock(-8,14,-8,CONCRETE:8,30,IRON_FENCE,30,CONCRETE:8,100)
RandomBlock(-8,14,-7,CONCRETE:8,30,IRON_FENCE,30,CONCRETE:8,100)
RandomBlock(-8,14,-6,CONCRETE:8,30,IRON_FENCE,30,CONCRETE:8,100)
RandomBlock(-8,14,-5,CONCRETE:8,30,IRON_FENCE,30,CONCRETE:8,100)
RandomBlock(-8,14,-4,CONCRETE:8,30,IRON_FENCE,30,CONCRETE:8,100)
RandomBlock(-8,14,-3,CONCRETE:8,30,IRON_FENCE,30,CONCRETE:8,100)
RandomBlock(-8,14,-2,CONCRETE:8,30,IRON_FENCE,30,CONCRETE:8,100)
RandomBlock(-8,14,-1,CONCRETE:8,30,IRON_FENCE,30,CONCRETE:8,100)
RandomBlock(-8,14,0,CONCRETE:8,30,IRON_FENCE,30,CONCRETE:8,100)
RandomBlock(-8,14,1,CONCRETE:8,30,IRON_FENCE,30,CONCRETE:8,100)
RandomBlock(-8,14,2,CONCRETE:8,30,IRON_FENCE,30,CONCRETE:8,100)
RandomBlock(-8,14,3,CONCRETE:8,30,IRON_FENCE,30,CONCRETE:8,100)
RandomBlock(-8,14,4,CONCRETE:8,30,IRON_FENCE,30,CONCRETE:8,100)
RandomBlock(-8,14,5,CONCRETE:8,30,IRON_FENCE,30,CONCRETE:8,100)
RandomBlock(-8,14,6,CONCRETE:8,30,IRON_FENCE,30,CONCRETE:8,100)
RandomBlock(-8,14,7,CONCRETE:8,30,IRON_FENCE,30,CONCRETE:8,100)
RandomBlock(-8,14,8,CONCRETE:8,30,IRON_FENCE,30,CONCRETE:8,100)
RandomBlock(-8,14,9,CONCRETE:8,30,IRON_FENCE,30,CONCRETE:8,100)
RandomBlock(-8,14,10,CONCRETE:8,30,IRON_FENCE,30,CONCRETE:8,100)
RandomBlock(-8,14,11,CONCRETE:8,30,IRON_FENCE,30,CONCRETE:8,100)
RandomBlock(-8,14,12,CONCRETE:8,30,IRON_FENCE,30,CONCRETE:8,100)
RandomBlock(-8,14,13,CONCRETE:8,30,IRON_FENCE,30,CONCRETE:8,100)
RandomBlock(-8,15,-10,CONCRETE:8,30,IRON_FENCE,30,CONCRETE:8,100)
RandomBlock(-8,15,-9,CONCRETE:8,30,IRON_FENCE,30,CONCRETE:8,100)
RandomBlock(-8,15,-8,CONCRETE:8,30,IRON_FENCE,30,CONCRETE:8,100)
RandomBlock(-8,15,-7,CONCRETE:8,30,IRON_FENCE,30,CONCRETE:8,100)
RandomBlock(-8,15,-6,CONCRETE:8,30,IRON_FENCE,30,CONCRETE:8,100)
RandomBlock(-8,15,-5,CONCRETE:8,30,IRON_FENCE,30,CONCRETE:8,100)
RandomBlock(-8,15,-4,CONCRETE:8,30,IRON_FENCE,30,CONCRETE:8,100)
RandomBlock(-8,15,-3,CONCRETE:8,30,IRON_FENCE,30,CONCRETE:8,100)
RandomBlock(-8,15,-2,CONCRETE:8,30,IRON_FENCE,30,CONCRETE:8,100)
RandomBlock(-8,15,-1,CONCRETE:8,30,IRON_FENCE,30,CONCRETE:8,100)
RandomBlock(-8,15,0,CONCRETE:8,30,IRON_FENCE,30,CONCRETE:8,100)
RandomBlock(-8,15,1,CONCRETE:8,30,IRON_FENCE,30,CONCRETE:8,100)
RandomBlock(-8,15,2,CONCRETE:8,30,IRON_FENCE,30,CONCRETE:8,100)
RandomBlock(-8,15,3,CONCRETE:8,30,IRON_FENCE,30,CONCRETE:8,100)
RandomBlock(-8,15,4,CONCRETE:8,30,IRON_FENCE,30,CONCRETE:8,100)
RandomBlock(-8,15,5,CONCRETE:8,30,IRON_FENCE,30,CONCRETE:8,100)
