
#######################################################################
# +-----------------------------------------------------------------+ #
# |                            BO4 object                           | #
# +-----------------------------------------------------------------+ #
#######################################################################

Author: NLBlackEagle

Description: No description given

SettingsMode: WriteDisable


#######################################################################
# +-----------------------------------------------------------------+ #
# |                          Main settings                          | #
# +-----------------------------------------------------------------+ #
#######################################################################

Frequency: 0

SpawnHeight: highestBlock

UseCenterForHighestBlock: true

##############################
# Height Limits for the BO4. #
##############################

MinHeight: 0

MaxHeight: 255

InheritBO3: 

InheritBO3Rotation: NORTH

OverrideChildSettings: true

OverrideParentHeight: false

CanOverride: false

BranchFrequency: 0

BranchFrequencyGroup: 

MustBeBelowOther: false

MustBeInside: 

CannotBeInside: 

ReplacesBO3: 

MustBeInsideWorldBorders: false

CanSpawnOnWater: true

SpawnOnWaterOnly: false

SpawnUnderWater: false

SpawnAtWaterLevel: false

HeightOffset: 0

RemoveAir: true

ReplaceAbove: 

ReplaceBelow: 

ReplaceWithBiomeBlocks: true

ReplaceWithSurfaceBlock: GRASS

ReplaceWithGroundBlock: DIRT

ReplaceWithStoneBlock: STONE

SmoothRadius: 0

SmoothHeightOffset: 0

SmoothStartTop: false

SmoothStartWood: false

SmoothingSurfaceBlock: 

SmoothingGroundBlock: 

BO3Group: 

IsSpawnPoint: false

DoReplaceBlocks: true


#######################################################################
# +-----------------------------------------------------------------+ #
# |                              Blocks                             | #
# +-----------------------------------------------------------------+ #
#######################################################################

Block(-8,-4,5,minecraft:black_glazed_terracotta:3)
Block(-8,-3,5,minecraft:black_glazed_terracotta:3)
Block(-8,-2,5,minecraft:black_glazed_terracotta:3)
Block(-8,-1,5,minecraft:black_glazed_terracotta:3)
Block(-8,0,-5,LOG:13)
Block(-8,0,-4,LOG:13)
Block(-8,0,-3,LOG:13)
Block(-8,1,-7,LOG:13)
Block(-8,1,-6,LOG_2:13)
Block(-8,1,-5,LOG:13)
Block(-8,1,-4,LOG:13)
Block(-8,1,-3,LOG:13)
Block(-8,1,-2,LOG_2:13)
Block(-8,1,-1,LOG_2:13)
Block(-8,1,0,LOG:13)
Block(-8,2,-7,LOG:13)
Block(-8,2,-6,LOG:13)
Block(-8,2,-5,LOG:13)
Block(-8,2,-4,LOG:13)
Block(-8,2,-3,LOG:13)
Block(-8,2,-2,LOG:13)
Block(-8,2,-1,LOG:13)
Block(-8,2,0,LOG:13)
Block(-8,3,-6,minecraft:black_glazed_terracotta:3)
Block(-8,3,-5,LOG:13)
Block(-8,3,-4,LOG:13)
Block(-8,3,-3,LOG:13)
Block(-8,3,-2,LOG:13)
Block(-8,3,-1,LOG:13)
Block(-8,3,0,LOG_2:13)
Block(-8,4,-6,LOG:13)
Block(-8,4,-5,minecraft:black_glazed_terracotta:3)
Block(-8,4,-4,LOG:13)
Block(-8,4,-3,LOG:13)
Block(-8,4,-2,LOG:13)
Block(-8,4,-1,LOG:13)
Block(-8,4,0,LOG:13)
Block(-8,5,-5,LOG_2:13)
Block(-8,5,-4,LOG:13)
Block(-8,5,-3,LOG:13)
Block(-8,5,-2,LOG:13)
Block(-8,5,-1,LOG_2:13)
Block(-8,5,0,LOG:13)
Block(-8,6,-5,minecraft:black_glazed_terracotta:3)
Block(-8,6,-4,LOG:13)
Block(-8,6,-3,LOG:13)
Block(-8,6,-2,LOG:13)
Block(-8,6,-1,LOG:13)
Block(-8,6,0,LOG:13)
Block(-8,7,-4,minecraft:black_glazed_terracotta:3)
Block(-8,7,-3,LOG:13)
Block(-8,7,-2,LOG:13)
Block(-8,7,-1,LOG:13)
Block(-8,7,0,LOG_2:13)
Block(-8,7,1,minecraft:black_glazed_terracotta:3)
Block(-8,8,-3,LOG_2:13)
Block(-8,8,-2,LOG:13)
Block(-8,8,-1,LOG_2:13)
Block(-8,8,0,LOG:13)
Block(-8,8,1,LOG:13)
Block(-8,9,0,LOG_2:13)
Block(-8,9,1,LOG:13)
Block(-8,9,2,minecraft:black_glazed_terracotta:3)
Block(-8,10,1,LOG:13)
Block(-8,10,2,minecraft:black_glazed_terracotta:3)
Block(-8,11,2,LOG:13)
Block(-8,11,3,minecraft:black_glazed_terracotta:3)
Block(-8,12,3,LOG:13)
Block(-8,12,4,minecraft:black_glazed_terracotta:3)
Block(-8,13,4,LOG:13)
Block(-8,14,4,LEAVES:12)
Block(-8,15,7,LEAVES:12)
Block(-8,22,7,LEAVES:12)
Block(-7,-4,-2,LOG:13)
Block(-7,-3,-2,LOG:13)
Block(-7,-2,-2,LOG:13)
Block(-7,-1,-2,LOG_2:13)
Block(-7,-1,4,LOG_2:13)
Block(-7,-1,5,minecraft:black_glazed_terracotta:3)
Block(-7,0,-7,LOG_2:13)
Block(-7,0,-6,LOG:13)
Block(-7,0,-4,LOG:13)
Block(-7,0,-3,LOG_2:13)
Block(-7,0,-2,LOG_2:13)
Block(-7,0,-1,LOG:13)
Block(-7,1,-7,LOG:13)
Block(-7,1,-6,LOG:13)
Block(-7,1,-5,LOG_2:13)
Block(-7,1,-4,LOG:13)
Block(-7,1,-3,LOG:13)
Block(-7,1,-2,LOG_2:13)
Block(-7,1,-1,LOG:13)
Block(-7,1,0,LOG_2:13)
Block(-7,1,1,LOG:13)
Block(-7,2,-7,LOG:13)
Block(-7,2,-6,LOG:13)
Block(-7,2,-5,LOG:13)
Block(-7,2,-4,LOG:13)
Block(-7,2,-3,LOG:13)
Block(-7,2,-2,LOG:13)
Block(-7,2,-1,LOG:13)
Block(-7,2,0,LOG:13)
Block(-7,3,-7,LOG:13)
Block(-7,3,-6,LOG:13)
Block(-7,3,-5,LOG:13)
Block(-7,3,-4,LOG:13)
Block(-7,3,-3,LOG_2:13)
Block(-7,3,-2,LOG:13)
Block(-7,3,-1,LOG:13)
Block(-7,3,0,LOG:13)
Block(-7,4,-6,LOG_2:13)
Block(-7,4,-5,LOG:13)
Block(-7,4,-4,LOG:13)
Block(-7,4,-3,LOG:13)
Block(-7,4,-2,LOG:13)
Block(-7,4,-1,LOG:13)
Block(-7,4,0,LOG:13)
Block(-7,5,-6,LOG:13)
Block(-7,5,-5,LOG:13)
Block(-7,5,-4,LOG_2:13)
Block(-7,5,-3,LOG_2:13)
Block(-7,5,-2,LOG:13)
Block(-7,5,-1,LOG:13)
Block(-7,6,-5,LOG:13)
Block(-7,6,-4,LOG:13)
Block(-7,6,-3,LOG_2:13)
Block(-7,6,-2,LOG:13)
Block(-7,6,-1,LOG:13)
Block(-7,6,0,minecraft:black_glazed_terracotta:3)
Block(-7,7,-5,LOG:13)
Block(-7,7,-4,LOG:13)
Block(-7,7,-3,LOG:13)
Block(-7,7,-2,LOG_2:13)
Block(-7,7,-1,minecraft:black_glazed_terracotta:3)
Block(-7,7,0,minecraft:black_glazed_terracotta:3)
Block(-7,8,-4,minecraft:black_glazed_terracotta:3)
Block(-7,8,-3,LOG_2:13)
Block(-7,8,-2,LOG:13)
Block(-7,8,-1,LEAVES:12)
Block(-7,8,0,LOG:13)
Block(-7,8,1,minecraft:black_glazed_terracotta:3)
Block(-7,9,-3,LOG:13)
Block(-7,9,-2,LOG:13)
Block(-7,9,1,LOG:13)
Block(-7,10,2,LOG:13)
Block(-7,16,6,LEAVES:12)
Block(-7,21,7,LEAVES:12)
Block(-7,21,8,LEAVES:12)
Block(-7,22,5,LEAVES:12)
Block(-7,22,8,LEAVES:12)
Block(-6,-5,4,LOG:13)
Block(-6,-4,0,LOG:13)
Block(-6,-4,4,LOG:13)
Block(-6,-3,0,LOG:13)
Block(-6,-3,4,LOG:13)
Block(-6,-2,0,LOG:13)
Block(-6,-2,4,LOG:13)
Block(-6,-1,0,LOG:13)
Block(-6,-1,4,LOG:13)
Block(-6,0,-5,LOG_2:13)
Block(-6,0,-4,LOG:13)
Block(-6,0,-3,LOG:13)
Block(-6,0,-2,LOG:13)
Block(-6,0,-1,LOG:13)
Block(-6,0,0,LOG:13)
Block(-6,0,3,LOG:13)
Block(-6,0,4,minecraft:black_glazed_terracotta:3)
Block(-6,1,-7,LOG:13)
Block(-6,1,-6,LOG:13)
Block(-6,1,-5,LOG:13)
Block(-6,1,-4,LOG:13)
Block(-6,1,-3,LOG:13)
Block(-6,1,-2,LOG:13)
Block(-6,1,-1,LOG:13)
Block(-6,1,0,LOG:13)
Block(-6,1,1,LOG:13)
Block(-6,2,-7,LOG:13)
Block(-6,2,-6,LOG:13)
Block(-6,2,-5,LOG:13)
Block(-6,2,-4,LOG:13)
Block(-6,2,-3,LOG:13)
Block(-6,2,-2,LOG:13)
Block(-6,2,-1,minecraft:black_glazed_terracotta:3)
Block(-6,2,0,LOG:13)
Block(-6,2,1,LOG:13)
Block(-6,3,-7,LOG:13)
Block(-6,3,-6,LOG:13)
Block(-6,3,-5,LOG:13)
Block(-6,3,-4,LOG:13)
Block(-6,3,-3,LOG_2:13)
Block(-6,3,-2,LOG:13)
Block(-6,3,-1,minecraft:black_glazed_terracotta:3)
Block(-6,3,0,minecraft:black_glazed_terracotta:3)
Block(-6,4,-7,LOG:13)
Block(-6,4,-6,LOG:13)
Block(-6,4,-5,LOG:13)
Block(-6,4,-4,LOG:13)
Block(-6,4,-3,LOG:13)
Block(-6,4,-2,LOG_2:13)
Block(-6,4,-1,minecraft:black_glazed_terracotta:3)
Block(-6,5,-6,LOG:13)
Block(-6,5,-5,LOG:13)
Block(-6,5,-4,LOG:13)
Block(-6,5,-3,LOG_2:13)
Block(-6,5,-2,LOG:13)
Block(-6,5,-1,minecraft:black_glazed_terracotta:3)
Block(-6,6,-6,LOG:13)
Block(-6,6,-5,LOG:13)
Block(-6,6,-4,LOG:13)
Block(-6,6,-3,LOG_2:13)
Block(-6,6,-2,LOG:13)
Block(-6,6,-1,minecraft:black_glazed_terracotta:3)
Block(-6,7,-5,LOG_2:13)
Block(-6,7,-4,LOG:13)
Block(-6,7,-3,LOG:13)
Block(-6,7,-2,LOG_2:13)
Block(-6,7,-1,LOG_2:13)
Block(-6,8,-5,LOG:13)
Block(-6,8,-4,LOG:13)
Block(-6,8,-3,LOG_2:13)
Block(-6,8,-2,LOG:13)
Block(-6,9,-4,minecraft:black_glazed_terracotta:3)
Block(-6,9,-3,LOG:13)
Block(-6,9,-2,LEAVES:12)
Block(-6,10,-3,LOG_2:13)
Block(-6,21,8,LOG:13)
Block(-6,22,6,LEAVES:12)
Block(-6,22,7,LEAVES:12)
Block(-6,22,8,LEAVES:12)
Block(-6,23,8,LEAVES:12)
Block(-5,-5,-4,LOG:13)
Block(-5,-4,-4,LOG:13)
Block(-5,-3,-4,LOG:13)
Block(-5,-2,-4,LOG:13)
Block(-5,-1,-6,LOG:13)
Block(-5,-1,-4,LOG:13)
Block(-5,0,-6,LOG:13)
Block(-5,0,-5,LOG:13)
Block(-5,0,-4,LOG_2:13)
Block(-5,0,-3,LOG_2:13)
Block(-5,0,-2,LOG:13)
Block(-5,0,1,LOG:13)
Block(-5,0,2,LOG:13)
Block(-5,0,3,minecraft:black_glazed_terracotta:3)
Block(-5,1,-7,LOG:13)
Block(-5,1,-6,LOG:13)
Block(-5,1,-5,LOG:13)
Block(-5,1,-4,LOG:13)
Block(-5,1,-3,LOG_2:13)
Block(-5,1,-2,LOG:13)
Block(-5,1,-1,LOG:13)
Block(-5,1,0,LOG:13)
Block(-5,1,1,LOG:13)
Block(-5,1,2,LOG_2:13)
Block(-5,2,-7,LOG:13)
Block(-5,2,-6,LOG_2:13)
Block(-5,2,-5,LOG_2:13)
Block(-5,2,-4,LOG:13)
Block(-5,2,-3,LOG:13)
Block(-5,2,-2,LOG:13)
Block(-5,2,0,minecraft:black_glazed_terracotta:3)
Block(-5,2,1,minecraft:black_glazed_terracotta:3)
Block(-5,2,2,minecraft:black_glazed_terracotta:3)
Block(-5,3,-7,LOG:13)
Block(-5,3,-6,LOG_2:13)
Block(-5,3,-5,LOG_2:13)
Block(-5,3,-4,LOG_2:13)
Block(-5,3,-3,LOG:13)
Block(-5,3,-2,LOG:13)
Block(-5,4,-7,LOG:13)
Block(-5,4,-6,LOG_2:13)
Block(-5,4,-5,LOG:13)
Block(-5,4,-4,LOG:13)
Block(-5,4,-3,LOG:13)
Block(-5,5,-6,LOG:13)
Block(-5,5,-5,LOG:13)
Block(-5,5,-4,LOG:13)
Block(-5,5,-3,LOG:13)
Block(-5,5,-2,LOG:13)
Block(-5,6,-6,LOG:13)
Block(-5,6,-5,LOG:13)
Block(-5,6,-4,LOG:13)
Block(-5,6,-3,LOG_2:13)
Block(-5,6,-2,LOG:13)
Block(-5,7,-6,LOG:13)
Block(-5,7,-5,LOG:13)
Block(-5,7,-4,LOG_2:13)
Block(-5,7,-3,LOG:13)
Block(-5,7,-2,LOG:13)
Block(-5,8,-5,LOG_2:13)
Block(-5,8,-4,LOG:13)
Block(-5,8,-3,LOG:13)
Block(-5,8,-2,LOG:13)
Block(-5,9,-5,LOG:13)
Block(-5,9,-4,minecraft:black_glazed_terracotta:3)
Block(-5,9,-3,LOG:13)
Block(-5,9,-2,LOG:13)
Block(-5,10,-4,minecraft:black_glazed_terracotta:3)
Block(-5,10,-3,LOG:13)
Block(-5,10,-2,LEAVES:12)
Block(-5,10,-1,LEAVES:12)
Block(-5,11,-3,LOG:13)
Block(-5,20,8,LEAVES:12)
Block(-5,21,7,LOG:13)
Block(-5,21,8,LOG:13)
Block(-5,22,5,LEAVES:12)
Block(-5,22,6,LEAVES:12)
Block(-5,22,7,LOG:13)
Block(-5,22,8,LEAVES:12)
Block(-5,23,6,LEAVES:12)
Block(-5,23,7,LEAVES:12)
Block(-5,23,8,LEAVES:12)
Block(-4,0,-7,LOG:13)
Block(-4,0,-6,LOG:13)
Block(-4,0,-5,LOG_2:13)
Block(-4,0,-4,LOG_2:13)
Block(-4,0,-3,LOG:13)
Block(-4,0,2,LOG:13)
Block(-4,0,3,LOG:13)
Block(-4,1,-7,LOG:13)
Block(-4,1,-6,LOG:13)
Block(-4,1,-5,LOG:13)
Block(-4,1,-4,LOG:13)
Block(-4,1,-3,LOG:13)
Block(-4,1,-2,LOG_2:13)
Block(-4,1,2,LOG:13)
Block(-4,1,3,minecraft:black_glazed_terracotta:3)
Block(-4,2,-7,LOG:13)
Block(-4,2,-6,LOG:13)
Block(-4,2,-5,LOG:13)
Block(-4,2,-4,LOG:13)
Block(-4,2,-3,LOG:13)
Block(-4,2,-2,LOG:13)
Block(-4,3,-7,LOG_2:13)
Block(-4,3,-6,LOG:13)
Block(-4,3,-5,LOG_2:13)
Block(-4,3,-4,LOG:13)
Block(-4,3,-3,LOG:13)
Block(-4,4,-7,minecraft:black_glazed_terracotta:3)
Block(-4,4,-6,LOG:13)
Block(-4,4,-5,LOG:13)
Block(-4,4,-4,LOG:13)
Block(-4,4,-3,LOG:13)
Block(-4,5,-7,minecraft:black_glazed_terracotta:3)
Block(-4,5,-6,LOG:13)
Block(-4,5,-5,LOG:13)
Block(-4,5,-4,LOG:13)
Block(-4,5,-3,LOG:13)
Block(-4,6,-6,minecraft:black_glazed_terracotta:3)
Block(-4,6,-5,LOG:13)
Block(-4,6,-4,LOG:13)
Block(-4,6,-3,LOG:13)
Block(-4,7,-6,minecraft:black_glazed_terracotta:3)
Block(-4,7,-5,LOG:13)
Block(-4,7,-4,LOG:13)
Block(-4,7,-3,LOG_2:13)
Block(-4,8,-6,LOG:13)
Block(-4,8,-5,LOG:13)
Block(-4,8,-4,LOG:13)
Block(-4,8,-3,LOG:13)
Block(-4,8,-2,LOG:13)
Block(-4,9,-6,LOG:13)
Block(-4,9,-5,LOG:13)
Block(-4,9,-4,LOG:13)
Block(-4,9,-3,LOG_2:13)
Block(-4,9,-2,LOG:13)
Block(-4,10,-5,minecraft:black_glazed_terracotta:3)
Block(-4,10,-4,LOG:13)
Block(-4,10,-3,LOG_2:13)
Block(-4,10,-2,LOG:13)
Block(-4,11,-5,minecraft:black_glazed_terracotta:3)
Block(-4,11,-4,LOG:13)
Block(-4,11,-3,LOG:13)
Block(-4,11,-2,LEAVES:12)
Block(-4,12,-3,LOG:13)
Block(-4,13,0,LEAVES:12)
Block(-4,19,7,LEAVES:12)
Block(-4,20,6,LEAVES:12)
Block(-4,20,7,LEAVES:12)
Block(-4,20,8,LEAVES:12)
Block(-4,21,6,LOG:13)
Block(-4,21,7,LOG:13)
Block(-4,21,8,LEAVES:12)
Block(-4,22,4,LEAVES:12)
Block(-4,22,6,LEAVES:12)
Block(-4,22,7,LEAVES:12)
Block(-4,22,8,LEAVES:12)
Block(-4,23,6,LEAVES:12)
Block(-4,23,7,LEAVES:12)
Block(-4,23,8,LEAVES:12)
Block(-3,-5,-7,LOG:13)
Block(-3,-4,-7,LOG:13)
Block(-3,-4,4,LOG:13)
Block(-3,-3,-7,LOG:13)
Block(-3,-3,4,LOG:13)
Block(-3,-2,-7,LOG:13)
Block(-3,-2,4,LOG:13)
Block(-3,-1,-7,LOG_2:13)
Block(-3,-1,4,LOG:13)
Block(-3,0,-7,LOG:13)
Block(-3,0,-5,LOG:13)
Block(-3,0,-4,LOG:13)
Block(-3,0,4,LOG_2:13)
Block(-3,1,-7,LOG_2:13)
Block(-3,1,-6,LOG:13)
Block(-3,1,-5,LOG:13)
Block(-3,1,-4,LOG_2:13)
Block(-3,1,-3,LOG:13)
Block(-3,1,-2,LOG:13)
Block(-3,1,-1,LOG:13)
Block(-3,1,4,LOG:13)
Block(-3,2,-7,LOG:13)
Block(-3,2,-6,LOG:13)
Block(-3,2,-5,LOG:13)
Block(-3,2,-4,LOG_2:13)
Block(-3,2,-3,LOG:13)
Block(-3,2,-2,LOG_2:13)
Block(-3,3,-7,LOG:13)
Block(-3,3,-6,LOG:13)
Block(-3,3,-4,LOG:13)
Block(-3,3,-3,LOG_2:13)
Block(-3,3,-2,LOG:13)
Block(-3,4,-7,LOG:13)
Block(-3,4,-4,LOG:13)
Block(-3,4,-3,minecraft:black_glazed_terracotta:3)
Block(-3,5,-4,minecraft:black_glazed_terracotta:3)
Block(-3,6,-5,LOG:13)
Block(-3,6,-4,minecraft:black_glazed_terracotta:3)
Block(-3,7,-6,minecraft:black_glazed_terracotta:3)
Block(-3,7,-5,LOG:13)
Block(-3,7,-4,minecraft:black_glazed_terracotta:3)
Block(-3,7,-3,LOG:13)
Block(-3,8,-7,minecraft:black_glazed_terracotta:3)
Block(-3,8,-6,LOG:13)
Block(-3,8,-5,LOG:13)
Block(-3,8,-4,LOG:13)
Block(-3,8,-3,LOG:13)
Block(-3,9,-7,minecraft:black_glazed_terracotta:3)
Block(-3,9,-6,LOG_2:13)
Block(-3,9,-5,LOG:13)
Block(-3,9,-4,LOG:13)
Block(-3,9,-3,LOG:13)
Block(-3,10,-7,LOG:13)
Block(-3,10,-6,LOG:13)
Block(-3,10,-5,LOG:13)
Block(-3,10,-4,LOG:13)
Block(-3,10,-3,LOG:13)
Block(-3,10,-2,LOG:13)
Block(-3,11,-6,minecraft:black_glazed_terracotta:3)
Block(-3,11,-5,LOG:13)
Block(-3,11,-4,LOG_2:13)
Block(-3,11,-3,LOG:13)
Block(-3,11,-2,LOG:13)
Block(-3,11,-1,LEAVES:12)
Block(-3,12,-5,minecraft:black_glazed_terracotta:3)
Block(-3,12,-4,LOG:13)
Block(-3,12,-3,LOG:13)
Block(-3,12,-2,LOG:13)
Block(-3,13,-4,LOG:13)
Block(-3,13,-3,LOG:13)
Block(-3,13,-2,LOG:13)
Block(-3,13,-1,LOG_2:13)
Block(-3,14,-2,LOG:13)
Block(-3,14,-1,LOG:13)
Block(-3,14,0,LEAVES:12)
Block(-3,18,2,LEAVES:12)
Block(-3,20,6,LOG_2:13)
Block(-3,20,7,LEAVES:12)
Block(-3,21,5,LEAVES:12)
Block(-3,21,6,LOG:13)
Block(-3,21,7,LEAVES:12)
Block(-3,21,8,LEAVES:12)
Block(-3,22,6,LEAVES:12)
Block(-3,22,7,LEAVES:12)
Block(-3,22,8,LEAVES:12)
Block(-3,23,7,LEAVES:12)
Block(-3,23,8,LEAVES:12)
Block(-2,-5,-1,LOG:13)
Block(-2,-4,-1,LOG:13)
Block(-2,-3,-1,LOG:13)
Block(-2,-2,-1,LOG:13)
Block(-2,-1,-1,LOG:13)
Block(-2,0,-4,LOG:13)
Block(-2,0,-1,LOG:13)
Block(-2,0,4,LOG_2:13)
Block(-2,0,5,LOG:13)
Block(-2,1,-7,LOG_2:13)
Block(-2,1,-5,LOG_2:13)
Block(-2,1,-4,LOG:13)
Block(-2,1,-3,LOG:13)
Block(-2,1,-2,LOG:13)
Block(-2,1,-1,LOG:13)
Block(-2,2,-4,LOG:13)
Block(-2,2,-3,LOG:13)
Block(-2,2,-2,LOG:13)
Block(-2,3,-3,minecraft:black_glazed_terracotta:3)
Block(-2,3,-2,minecraft:black_glazed_terracotta:3)
Block(-2,7,-5,minecraft:black_glazed_terracotta:3)
Block(-2,8,-6,LOG_2:13)
Block(-2,8,-5,minecraft:black_glazed_terracotta:3)
Block(-2,8,-4,LOG_2:13)
Block(-2,9,-7,minecraft:black_glazed_terracotta:3)
Block(-2,9,-6,minecraft:black_glazed_terracotta:3)
Block(-2,9,-5,LOG:13)
Block(-2,9,-4,LOG:13)
Block(-2,9,-3,LOG:13)
Block(-2,10,-7,LOG:13)
Block(-2,10,-6,LOG_2:13)
Block(-2,10,-5,LOG:13)
Block(-2,10,-4,LOG:13)
Block(-2,10,-3,LOG:13)
Block(-2,11,-7,LOG:13)
Block(-2,11,-6,LOG_2:13)
Block(-2,11,-5,LOG:13)
Block(-2,11,-4,LOG:13)
Block(-2,11,-3,LOG_2:13)
Block(-2,11,-2,LOG:13)
Block(-2,12,-7,LOG_2:13)
Block(-2,12,-6,minecraft:black_glazed_terracotta:3)
Block(-2,12,-5,LOG:13)
Block(-2,12,-4,LOG:13)
Block(-2,12,-3,LOG:13)
Block(-2,12,-2,LOG:13)
Block(-2,12,-1,LOG:13)
Block(-2,13,-7,LEAVES:12)
Block(-2,13,-6,minecraft:black_glazed_terracotta:3)
Block(-2,13,-5,LOG:13)
Block(-2,13,-4,LOG:13)
Block(-2,13,-3,LOG:13)
Block(-2,13,-2,LOG:13)
Block(-2,13,-1,LOG:13)
Block(-2,13,0,LEAVES:12)
Block(-2,14,-3,LOG:13)
Block(-2,14,-2,LOG:13)
Block(-2,14,-1,LOG:13)
Block(-2,14,0,LOG:13)
Block(-2,15,-1,LOG_2:13)
Block(-2,15,0,LOG:13)
Block(-2,15,1,LEAVES:12)
Block(-2,16,8,LEAVES:12)
Block(-2,17,3,LEAVES:12)
Block(-2,17,8,LEAVES:12)
Block(-2,18,2,LEAVES:12)
Block(-2,18,4,LEAVES:12)
Block(-2,18,5,LEAVES:12)
Block(-2,18,8,LEAVES:12)
Block(-2,19,5,LOG:13)
Block(-2,19,8,LEAVES:12)
Block(-2,20,4,LEAVES:12)
Block(-2,20,5,LOG_2:13)
Block(-2,20,6,LOG:13)
Block(-2,20,8,LEAVES:12)
Block(-2,21,5,LEAVES:12)
Block(-2,21,6,LEAVES:12)
Block(-2,21,8,LEAVES:12)
Block(-2,22,7,LEAVES:12)
Block(-2,22,8,LEAVES:12)
Block(-2,23,8,LEAVES:12)
Block(-1,-4,6,LOG:13)
Block(-1,-3,6,LOG:13)
Block(-1,-2,6,LOG:13)
Block(-1,-1,6,LOG:13)
Block(-1,0,-1,LOG:13)
Block(-1,0,0,LOG:13)
Block(-1,0,5,LOG:13)
Block(-1,0,6,LOG:13)
Block(-1,1,-2,LOG:13)
Block(-1,1,-1,LOG:13)
Block(-1,1,0,LOG:13)
Block(-1,2,-2,minecraft:black_glazed_terracotta:3)
Block(-1,2,-1,LOG:13)
Block(-1,3,-1,LOG:13)
Block(-1,8,-6,LOG:13)
Block(-1,9,-6,LOG:13)
Block(-1,9,-5,minecraft:black_glazed_terracotta:3)
Block(-1,9,-4,LOG_2:13)
Block(-1,10,-7,minecraft:black_glazed_terracotta:3)
Block(-1,10,-6,LOG:13)
Block(-1,10,-5,LOG_2:13)
Block(-1,10,-4,minecraft:black_glazed_terracotta:3)
Block(-1,10,-3,LOG_2:13)
Block(-1,11,-7,LOG:13)
Block(-1,11,-6,LOG:13)
Block(-1,11,-5,LOG:13)
Block(-1,11,-4,LOG:13)
Block(-1,11,-3,minecraft:black_glazed_terracotta:3)
Block(-1,11,-2,LOG:13)
Block(-1,12,-7,LOG:13)
Block(-1,12,-6,LOG:13)
Block(-1,12,-5,LOG:13)
Block(-1,12,-4,LOG:13)
Block(-1,12,-3,LOG_2:13)
Block(-1,12,-2,LOG:13)
Block(-1,12,-1,LOG:13)
Block(-1,13,-7,LOG_2:13)
Block(-1,13,-6,LOG:13)
Block(-1,13,-5,LOG:13)
Block(-1,13,-3,LOG:13)
Block(-1,13,-2,LOG:13)
Block(-1,13,-1,LOG:13)
Block(-1,13,0,LOG:13)
Block(-1,14,-6,minecraft:black_glazed_terracotta:3)
Block(-1,14,-3,LOG:13)
Block(-1,14,-2,LOG:13)
Block(-1,14,-1,LOG:13)
Block(-1,14,0,LOG:13)
Block(-1,14,1,LEAVES:12)
Block(-1,15,-2,LOG:13)
Block(-1,15,-1,LOG:13)
Block(-1,15,0,LOG:13)
Block(-1,15,1,LOG:13)
Block(-1,15,2,LEAVES:12)
Block(-1,16,-1,LOG:13)
Block(-1,16,0,LOG:13)
Block(-1,16,1,LOG:13)
Block(-1,16,2,LOG:13)
Block(-1,16,3,LEAVES:12)
Block(-1,16,6,LEAVES:12)
Block(-1,17,1,LOG:13)
Block(-1,17,2,LOG:13)
Block(-1,17,3,LOG:13)
Block(-1,17,4,LEAVES:12)
Block(-1,17,6,LEAVES:12)
Block(-1,18,2,LOG:13)
Block(-1,18,3,LOG:13)
Block(-1,18,4,LOG:13)
Block(-1,18,5,LOG:13)
Block(-1,18,6,LEAVES:12)
Block(-1,19,3,LEAVES:12)
Block(-1,19,4,LOG:13)
Block(-1,19,5,LOG:13)
Block(-1,19,6,LEAVES:12)
Block(-1,20,4,LEAVES:12)
Block(-1,20,5,LEAVES:12)
Block(-1,20,6,LEAVES:12)
Block(-1,21,4,LEAVES:12)
Block(-1,21,5,LEAVES:12)
Block(-1,21,6,LEAVES:12)
Block(-1,21,7,LEAVES:12)
Block(-1,21,8,LEAVES:12)
Block(-1,22,6,LEAVES:12)
Block(-1,22,7,LEAVES:12)
Block(-1,22,8,LEAVES:12)
Block(-1,23,7,LEAVES:12)
Block(-1,23,8,LEAVES:12)
Block(0,0,-1,LOG:13)
Block(0,0,0,minecraft:black_glazed_terracotta:3)
Block(0,0,1,LOG:13)
Block(0,1,-1,minecraft:black_glazed_terracotta:3)
Block(0,1,0,LOG:13)
Block(0,1,1,LOG_2:13)
Block(0,2,0,LOG_2:13)
Block(0,9,-6,LOG_2:13)
Block(0,10,-7,LOG_2:13)
Block(0,10,-6,LOG:13)
Block(0,10,-5,minecraft:black_glazed_terracotta:3)
Block(0,11,-7,LOG_2:13)
Block(0,11,-6,LOG:13)
Block(0,11,-5,LOG:13)
Block(0,11,-4,minecraft:black_glazed_terracotta:3)
Block(0,12,-7,LOG:13)
Block(0,12,-6,LOG:13)
Block(0,12,-5,LOG:13)
Block(0,12,-3,minecraft:black_glazed_terracotta:3)
Block(0,12,-2,minecraft:black_glazed_terracotta:3)
Block(0,13,-7,LOG:13)
Block(0,13,-6,LOG:13)
Block(0,13,-2,LOG:13)
Block(0,13,-1,minecraft:black_glazed_terracotta:3)
Block(0,14,-7,LOG:13)
Block(0,14,-2,LOG:13)
Block(0,14,-1,LOG:13)
Block(0,14,0,LOG:13)
Block(0,14,1,LOG:13)
Block(0,15,-1,LOG_2:13)
Block(0,15,0,LOG:13)
Block(0,15,1,LOG:13)
Block(0,15,2,LOG:13)
Block(0,16,0,LOG:13)
Block(0,16,1,LOG_2:13)
Block(0,16,2,LOG:13)
Block(0,16,3,LOG:13)
Block(0,16,4,LEAVES:12)
Block(0,17,0,LOG:13)
Block(0,17,1,LOG:13)
Block(0,17,2,LOG:13)
Block(0,17,3,LOG:13)
Block(0,17,4,LOG_2:13)
Block(0,17,5,LEAVES:12)
Block(0,18,1,LOG_2:13)
Block(0,18,2,LOG:13)
Block(0,18,3,LOG:13)
Block(0,18,4,LOG_2:13)
Block(0,18,5,LOG:13)
Block(0,19,2,LEAVES:12)
Block(0,19,3,LOG:13)
Block(0,19,4,LOG:13)
Block(0,19,5,LOG:13)
Block(0,19,6,LEAVES:12)
Block(0,19,8,LEAVES:12)
Block(0,20,4,LOG:13)
Block(0,20,5,LOG:13)
Block(0,20,6,LOG:13)
Block(0,20,7,LEAVES:12)
Block(0,20,8,LEAVES:12)
Block(0,21,4,LEAVES:12)
Block(0,21,5,LEAVES:12)
Block(0,21,6,LOG_2:13)
Block(0,21,7,LEAVES:12)
Block(0,21,8,LEAVES:12)
Block(0,22,4,LEAVES:12)
Block(0,22,6,LEAVES:12)
Block(0,22,7,LEAVES:12)
Block(0,22,8,LEAVES:12)
Block(0,23,8,LEAVES:12)
Block(1,0,1,LOG:13)
Block(1,1,1,LOG:13)
Block(1,11,-7,LOG:13)
Block(1,12,-7,LOG:13)
Block(1,12,-6,LOG_2:13)
Block(1,13,-7,LOG:13)
Block(1,13,-6,LEAVES:12)
Block(1,14,-7,LOG:13)
Block(1,14,-1,minecraft:black_glazed_terracotta:3)
Block(1,14,0,minecraft:black_glazed_terracotta:3)
Block(1,15,-7,LEAVES:12)
Block(1,15,0,LOG:13)
Block(1,15,1,minecraft:black_glazed_terracotta:3)
Block(1,15,2,LEAVES:12)
Block(1,16,0,LEAVES:12)
Block(1,16,1,LOG:13)
Block(1,16,2,LOG:13)
Block(1,16,3,LEAVES:12)
Block(1,17,2,minecraft:black_glazed_terracotta:3)
Block(1,17,3,minecraft:black_glazed_terracotta:3)
Block(1,17,4,LEAVES:12)
Block(1,18,2,LEAVES:12)
Block(1,18,3,LOG:13)
Block(1,18,4,LOG:13)
Block(1,18,5,LOG_2:13)
Block(1,19,3,LEAVES:12)
Block(1,19,4,LOG_2:13)
Block(1,19,5,LOG:13)
Block(1,19,6,LOG:13)
Block(1,19,7,LEAVES:12)
Block(1,20,4,LEAVES:12)
Block(1,20,5,LOG:13)
Block(1,20,6,LOG:13)
Block(1,20,7,LOG:13)
Block(1,21,4,LEAVES:12)
Block(1,21,5,LEAVES:12)
Block(1,21,6,LOG:13)
Block(1,21,7,LOG:13)
Block(1,21,8,LOG_2:13)
Block(1,22,5,LEAVES:12)
Block(1,22,6,LEAVES:12)
Block(1,22,7,LOG:13)
Block(1,22,8,LOG:13)
Block(1,23,6,LEAVES:12)
Block(1,23,7,LEAVES:12)
Block(1,23,8,LEAVES:12)
Block(1,24,7,LEAVES:12)
Block(2,-5,0,LOG:13)
Block(2,-4,0,LOG:13)
Block(2,-3,0,LOG:13)
Block(2,-2,0,LOG:13)
Block(2,-1,0,LOG_2:13)
Block(2,0,0,minecraft:black_glazed_terracotta:3)
Block(2,0,1,minecraft:black_glazed_terracotta:3)
Block(2,0,2,LOG:13)
Block(2,1,2,LOG:13)
Block(2,13,-7,LOG_2:13)
Block(2,14,-7,LEAVES:12)
Block(2,17,8,LEAVES:12)
Block(2,18,3,LEAVES:12)
Block(2,18,4,LEAVES:12)
Block(2,18,5,LEAVES:12)
Block(2,18,8,LEAVES:12)
Block(2,19,4,LEAVES:12)
Block(2,19,5,LEAVES:12)
Block(2,19,8,LEAVES:12)
Block(2,20,5,LOG:13)
Block(2,20,6,LEAVES:12)
Block(2,20,7,LEAVES:12)
Block(2,20,8,LEAVES:12)
Block(2,21,4,LEAVES:12)
Block(2,21,5,LOG:13)
Block(2,21,6,LEAVES:12)
Block(2,21,7,LOG:13)
Block(2,21,8,LOG:13)
Block(2,22,4,LEAVES:12)
Block(2,22,5,LEAVES:12)
Block(2,22,6,LEAVES:12)
Block(2,22,7,LEAVES:12)
Block(2,22,8,LOG:13)
Block(2,23,5,LEAVES:12)
Block(2,23,6,LEAVES:12)
Block(2,23,7,LEAVES:12)
Block(2,23,8,LEAVES:12)
Block(2,24,5,LEAVES:12)
Block(2,24,7,LEAVES:12)
Block(2,24,8,LEAVES:12)
Block(2,25,8,LEAVES:12)
Block(3,-3,2,LOG:13)
Block(3,-2,2,LOG:13)
Block(3,-1,-1,LOG_2:13)
Block(3,-1,0,LOG:13)
Block(3,-1,2,LOG:13)
Block(3,0,2,minecraft:black_glazed_terracotta:3)
Block(3,0,3,LOG:13)
Block(3,20,5,LEAVES:12)
Block(3,21,4,LEAVES:12)
Block(3,21,5,LOG:13)
Block(3,21,6,LOG:13)
Block(3,21,8,LEAVES:12)
Block(3,22,3,LEAVES:12)
Block(3,22,5,LEAVES:12)
Block(3,22,6,LOG:13)
Block(3,22,7,LEAVES:12)
Block(3,22,8,LEAVES:12)
Block(3,23,6,LEAVES:12)
Block(3,23,7,LEAVES:12)
Block(3,23,8,LEAVES:12)
Block(3,24,6,LEAVES:12)
Block(3,24,7,LEAVES:12)
Block(3,24,8,LEAVES:12)
Block(3,25,7,LEAVES:12)
Block(3,25,8,LEAVES:12)
Block(3,26,8,LEAVES:12)
Block(4,-1,-2,LOG:13)
Block(4,-1,-1,LOG:13)
Block(4,0,3,minecraft:black_glazed_terracotta:3)
Block(4,0,4,LOG:13)
Block(4,17,-7,LEAVES:12)
Block(4,18,-6,LEAVES:12)
Block(4,20,6,LEAVES:12)
Block(4,20,8,LEAVES:12)
Block(4,21,4,LEAVES:12)
Block(4,21,6,LEAVES:12)
Block(4,22,5,LEAVES:12)
Block(4,22,6,LOG:13)
Block(4,22,7,LEAVES:12)
Block(4,22,8,LEAVES:12)
Block(4,23,6,LEAVES:12)
Block(4,23,7,LEAVES:12)
Block(4,23,8,LEAVES:12)
Block(4,24,5,LEAVES:12)
Block(4,24,7,LEAVES:12)
Block(4,24,8,LEAVES:12)
Block(4,25,6,LEAVES:12)
Block(4,25,7,LEAVES:12)
Block(4,25,8,LEAVES:12)
Block(4,26,7,LEAVES:12)
Block(4,26,8,LEAVES:12)
Block(5,-6,-2,LOG:13)
Block(5,-5,-2,LOG:13)
Block(5,-4,-2,LOG:13)
Block(5,-4,4,LOG:13)
Block(5,-3,-2,LOG:13)
Block(5,-3,4,LOG:13)
Block(5,-2,-2,LOG_2:13)
Block(5,-2,4,LOG:13)
Block(5,-1,-2,LOG:13)
Block(5,-1,4,minecraft:black_glazed_terracotta:3)
Block(5,-1,5,LOG:13)
Block(5,0,4,minecraft:black_glazed_terracotta:3)
Block(5,15,-6,LEAVES:12)
Block(5,16,-6,LEAVES:12)
Block(5,16,7,LEAVES:12)
Block(5,17,-6,LEAVES:12)
Block(5,17,7,LEAVES:12)
Block(5,18,-7,LEAVES:12)
Block(5,18,-6,LEAVES:12)
Block(5,18,-5,LEAVES:12)
Block(5,18,-4,LEAVES:12)
Block(5,18,7,LEAVES:12)
Block(5,19,7,LEAVES:12)
Block(5,20,7,LEAVES:12)
Block(5,21,5,LEAVES:12)
Block(5,21,7,LEAVES:12)
Block(5,22,6,LOG:13)
Block(5,22,8,LEAVES:12)
Block(5,23,6,LOG:13)
Block(5,23,7,LOG:13)
Block(5,24,4,LEAVES:12)
Block(5,24,7,LEAVES:12)
Block(5,24,8,LEAVES:12)
Block(5,25,7,LEAVES:12)
Block(5,25,8,LEAVES:12)
Block(5,26,8,LEAVES:12)
Block(6,-6,6,minecraft:black_glazed_terracotta:3)
Block(6,-5,6,minecraft:black_glazed_terracotta:3)
Block(6,-4,6,minecraft:black_glazed_terracotta:3)
Block(6,-3,6,minecraft:black_glazed_terracotta:3)
Block(6,-2,-3,LOG_2:13)
Block(6,-2,-2,LOG:13)
Block(6,-2,6,minecraft:black_glazed_terracotta:3)
Block(6,-1,5,minecraft:black_glazed_terracotta:3)
Block(6,-1,6,minecraft:black_glazed_terracotta:3)
Block(6,15,-4,LEAVES:12)
Block(6,16,-7,LOG:13)
Block(6,16,-6,LOG:13)
Block(6,16,-4,LEAVES:12)
Block(6,17,-7,LEAVES:12)
Block(6,17,-6,LEAVES:12)
Block(6,17,-5,LEAVES:12)
Block(6,17,-4,LEAVES:12)
Block(6,18,-7,LEAVES:12)
Block(6,18,-6,LEAVES:12)
Block(6,18,-5,LEAVES:12)
Block(6,18,-4,LEAVES:12)
Block(6,18,-3,LEAVES:12)
Block(6,19,-7,LEAVES:12)
Block(6,21,6,LEAVES:12)
Block(6,21,8,LEAVES:12)
Block(6,22,7,LEAVES:12)
Block(6,23,5,LEAVES:12)
Block(6,23,7,LOG_2:13)
Block(6,24,6,LEAVES:12)
Block(6,24,7,LOG:13)
Block(6,24,8,LOG:13)
Block(6,25,7,LEAVES:12)
Block(6,25,8,LEAVES:12)
Block(6,26,7,LEAVES:12)
Block(6,26,8,LEAVES:12)
Block(7,-5,-3,LOG:13)
Block(7,-4,-3,LOG:13)
Block(7,-3,-3,LOG:13)
Block(7,-2,-3,LOG_2:13)
Block(7,13,-6,LEAVES:12)
Block(7,14,-6,LEAVES:12)
Block(7,15,-6,LEAVES:12)
Block(7,16,-7,LOG:13)
Block(7,16,-6,LOG:13)
Block(7,16,-3,LEAVES:12)
Block(7,17,-7,LEAVES:12)
Block(7,17,-6,LOG:13)
Block(7,17,-5,LEAVES:12)
Block(7,17,-4,LEAVES:12)
Block(7,17,-3,LEAVES:12)
Block(7,17,-2,LEAVES:12)
Block(7,18,-7,LEAVES:12)
Block(7,18,-6,LEAVES:12)
Block(7,18,-5,LEAVES:12)
Block(7,18,-4,LEAVES:12)
Block(7,18,-3,LEAVES:12)
Block(7,18,-2,LEAVES:12)
Block(7,18,8,LEAVES:12)
Block(7,19,-7,LEAVES:12)
Block(7,19,-6,LEAVES:12)
Block(7,19,-5,LEAVES:12)
Block(7,19,8,LEAVES:12)
Block(7,20,8,LEAVES:12)
Block(7,21,8,LEAVES:12)
Block(7,22,5,LEAVES:12)
Block(7,22,8,LEAVES:12)
Block(7,23,6,LEAVES:12)
Block(7,23,8,LEAVES:12)
Block(7,24,7,LEAVES:12)
Block(7,24,8,LOG_2:13)
Block(7,25,7,LEAVES:12)
Block(7,25,8,LEAVES:12)
Block(7,26,8,LEAVES:12)

#######################################################################
# +-----------------------------------------------------------------+ #
# |                             Branches                            | #
# +-----------------------------------------------------------------+ #
#######################################################################

Branch(-16,0,0,true,CherryTreeCorrupted08C0R1,NORTH,100.0,0)

#######################################################################
# +-----------------------------------------------------------------+ #
# |                             Entities                            | #
# +-----------------------------------------------------------------+ #
#######################################################################


#######################################################################
# +-----------------------------------------------------------------+ #
# |                            Particles                            | #
# +-----------------------------------------------------------------+ #
#######################################################################


#######################################################################
# +-----------------------------------------------------------------+ #
# |                             Spawners                            | #
# +-----------------------------------------------------------------+ #
#######################################################################


#######################################################################
# +-----------------------------------------------------------------+ #
# |                             ModData                             | #
# +-----------------------------------------------------------------+ #
#######################################################################

