
#######################################################################
# +-----------------------------------------------------------------+ #
# |                            BO4 object                           | #
# +-----------------------------------------------------------------+ #
#######################################################################

Author: NLBlackEagle

Description: No description given

SettingsMode: WriteDisable


#######################################################################
# +-----------------------------------------------------------------+ #
# |                          Main settings                          | #
# +-----------------------------------------------------------------+ #
#######################################################################

Frequency: 0

SpawnHeight: highestBlock

UseCenterForHighestBlock: true

##############################
# Height Limits for the BO4. #
##############################

MinHeight: 0

MaxHeight: 255

InheritBO3: 

InheritBO3Rotation: NORTH

OverrideChildSettings: true

OverrideParentHeight: false

CanOverride: false

BranchFrequency: 0

BranchFrequencyGroup: 

MustBeBelowOther: false

MustBeInside: 

CannotBeInside: 

ReplacesBO3: 

MustBeInsideWorldBorders: false

CanSpawnOnWater: true

SpawnOnWaterOnly: false

SpawnUnderWater: false

SpawnAtWaterLevel: false

HeightOffset: 0

RemoveAir: false

ReplaceAbove: 

ReplaceBelow: 

ReplaceWithBiomeBlocks: false

ReplaceWithSurfaceBlock: GRASS

ReplaceWithGroundBlock: DIRT

ReplaceWithStoneBlock: STONE

SmoothRadius: 0

SmoothHeightOffset: 0

SmoothStartTop: false

SmoothStartWood: false

SmoothingSurfaceBlock: 

SmoothingGroundBlock: 

BO3Group: 

IsSpawnPoint: false

DoReplaceBlocks: false


#######################################################################
# +-----------------------------------------------------------------+ #
# |                              Blocks                             | #
# +-----------------------------------------------------------------+ #
#######################################################################

Block(-8,0,-7,CONCRETE:7)
Block(-8,0,-6,CONCRETE:7)
Block(-8,1,-7,CONCRETE:7)
Block(-8,1,-6,CONCRETE:7)
Block(-8,2,-7,CONCRETE:7)
Block(-8,2,-6,CONCRETE:7)
Block(-8,3,-7,CONCRETE:7)
Block(-8,3,-6,CONCRETE:7)
Block(-8,4,-7,CONCRETE:7)
Block(-8,4,-6,CONCRETE:7)
Block(-8,5,-7,OBSIDIAN:0)
Block(-8,5,-6,OBSIDIAN:0)
Block(-8,6,-7,OBSIDIAN:0)
Block(-8,6,-6,OBSIDIAN:0)
Block(-8,7,-7,OBSIDIAN:0)
Block(-8,7,-6,OBSIDIAN:0)
Block(-8,8,-7,OBSIDIAN:0)
Block(-8,8,-6,OBSIDIAN:0)
Block(-8,9,-7,OBSIDIAN:0)
Block(-8,9,-6,OBSIDIAN:0)
Block(-8,10,-7,OBSIDIAN:0)
Block(-8,10,-6,OBSIDIAN:0)
Block(-8,11,-7,CONCRETE:7)
Block(-8,11,-6,CONCRETE:7)
Block(-8,12,-7,CONCRETE:7)
Block(-8,12,-6,CONCRETE:7)
Block(-8,13,-7,CONCRETE:7)
Block(-8,13,-6,CONCRETE:7)
Block(-8,14,-7,CONCRETE:7)
Block(-8,14,-6,CONCRETE:7)
Block(-8,15,-7,CONCRETE:7)
Block(-8,15,-6,CONCRETE:7)
Block(-8,16,-7,CONCRETE:7)
Block(-8,16,-6,CONCRETE:7)
Block(-8,17,-7,CONCRETE:7)
Block(-8,17,-6,CONCRETE:7)
Block(-8,18,-7,CONCRETE:7)
Block(-8,18,-6,CONCRETE:7)
Block(-8,19,-7,CONCRETE:7)
Block(-8,19,-6,CONCRETE:7)
Block(-8,20,-7,CONCRETE:7)
Block(-8,20,-6,CONCRETE:7)
Block(-8,21,-7,OBSIDIAN:0)
Block(-8,21,-6,OBSIDIAN:0)
Block(-8,22,-7,OBSIDIAN:0)
Block(-8,22,-6,OBSIDIAN:0)
Block(-8,23,-7,OBSIDIAN:0)
Block(-8,23,-6,OBSIDIAN:0)
Block(-8,24,-7,OBSIDIAN:0)
Block(-8,24,-6,OBSIDIAN:0)
Block(-8,25,-7,OBSIDIAN:0)
Block(-8,25,-6,OBSIDIAN:0)
Block(-8,26,-7,OBSIDIAN:0)
Block(-8,26,-6,OBSIDIAN:0)
Block(-8,27,-7,OBSIDIAN:0)
Block(-8,27,-6,OBSIDIAN:0)
Block(-8,28,-7,CONCRETE:7)
Block(-8,28,-6,CONCRETE:7)
Block(-8,29,-7,CONCRETE:7)
Block(-7,0,-7,CONCRETE:7)
Block(-7,0,-6,CONCRETE:7)
Block(-7,0,-4,STONE:6)
Block(-7,1,-7,CONCRETE:7)
Block(-7,1,-6,CONCRETE:7)
Block(-7,1,-4,STONE:6)
Block(-7,2,-7,CONCRETE:7)
Block(-7,2,-6,CONCRETE:7)
Block(-7,2,-4,STONE:6)
Block(-7,3,-7,CONCRETE:7)
Block(-7,3,-6,CONCRETE:7)
Block(-7,3,-4,STONE:6)
Block(-7,4,-7,CONCRETE:7)
Block(-7,4,-6,CONCRETE:7)
Block(-7,4,-4,STONE:6)
Block(-7,5,-7,OBSIDIAN:0)
Block(-7,5,-6,OBSIDIAN:0)
Block(-7,5,-4,STONE:6)
Block(-7,6,-7,OBSIDIAN:0)
Block(-7,6,-6,OBSIDIAN:0)
Block(-7,6,-4,STONE:6)
Block(-7,7,-7,OBSIDIAN:0)
Block(-7,7,-6,OBSIDIAN:0)
Block(-7,7,-4,STONE:6)
Block(-7,8,-7,OBSIDIAN:0)
Block(-7,8,-6,OBSIDIAN:0)
Block(-7,8,-4,STONE:6)
Block(-7,9,-7,OBSIDIAN:0)
Block(-7,9,-6,OBSIDIAN:0)
Block(-7,9,-4,STONE:6)
Block(-7,10,-7,OBSIDIAN:0)
Block(-7,10,-6,OBSIDIAN:0)
Block(-7,10,-4,STONE:6)
Block(-7,11,-7,OBSIDIAN:0)
Block(-7,11,-6,OBSIDIAN:0)
Block(-7,11,-4,STONE:6)
Block(-7,12,-7,CONCRETE:7)
Block(-7,12,-6,CONCRETE:7)
Block(-7,12,-4,STONE:6)
Block(-7,13,-7,CONCRETE:7)
Block(-7,13,-6,CONCRETE:7)
Block(-7,13,-4,STONE:6)
Block(-7,14,-7,CONCRETE:7)
Block(-7,14,-6,CONCRETE:7)
Block(-7,14,-4,STONE:6)
Block(-7,15,-7,CONCRETE:7)
Block(-7,15,-6,CONCRETE:7)
Block(-7,15,-4,STONE:6)
Block(-7,16,-7,CONCRETE:7)
Block(-7,16,-6,CONCRETE:7)
Block(-7,16,-4,STONE:6)
Block(-7,17,-7,CONCRETE:7)
Block(-7,17,-6,CONCRETE:7)
Block(-7,17,-4,STONE:6)
Block(-7,18,-7,CONCRETE:7)
Block(-7,18,-6,CONCRETE:7)
Block(-7,18,-4,STONE:6)
Block(-7,19,-7,CONCRETE:7)
Block(-7,19,-6,CONCRETE:7)
Block(-7,19,-4,STONE:6)
Block(-7,20,-7,CONCRETE:7)
Block(-7,20,-6,CONCRETE:7)
Block(-7,20,-4,STONE:6)
Block(-7,21,-7,CONCRETE:7)
Block(-7,21,-6,CONCRETE:7)
Block(-7,21,-4,STONE:6)
Block(-7,22,-7,OBSIDIAN:0)
Block(-7,22,-6,OBSIDIAN:0)
Block(-7,22,-4,STONE:6)
Block(-7,23,-7,OBSIDIAN:0)
Block(-7,23,-6,OBSIDIAN:0)
Block(-7,23,-4,STONE:6)
Block(-7,24,-7,OBSIDIAN:0)
Block(-7,24,-6,OBSIDIAN:0)
Block(-7,24,-4,STONE:6)
Block(-7,25,-7,OBSIDIAN:0)
Block(-7,25,-6,OBSIDIAN:0)
Block(-7,25,-4,STONE:6)
Block(-7,26,-7,OBSIDIAN:0)
Block(-7,26,-6,OBSIDIAN:0)
Block(-7,26,-4,STONE:6)
Block(-7,27,-7,OBSIDIAN:0)
Block(-7,27,-6,OBSIDIAN:0)
Block(-7,27,-4,STONE:6)
Block(-7,28,-7,OBSIDIAN:0)
Block(-7,28,-6,OBSIDIAN:0)
Block(-7,28,-4,STONE:6)
Block(-7,29,-7,STONE:6)
Block(-7,29,-4,STONE:6)
Block(-7,30,-7,STONE:6)
Block(-7,30,-4,STONE:6)
Block(-7,31,-7,STONE:6)
Block(-7,31,-4,STONE:6)
Block(-7,32,-7,STONE:6)
Block(-7,32,-4,STEP:0)
Block(-7,33,-7,STONE:6)
Block(-7,34,-7,STEP:0)
Block(-6,0,-7,CONCRETE:7)
Block(-6,0,-6,CONCRETE:7)
Block(-6,1,-7,CONCRETE:7)
Block(-6,1,-6,CONCRETE:7)
Block(-6,2,-7,CONCRETE:7)
Block(-6,2,-6,CONCRETE:7)
Block(-6,3,-7,CONCRETE:7)
Block(-6,3,-6,CONCRETE:7)
Block(-6,4,-7,CONCRETE:7)
Block(-6,4,-6,CONCRETE:7)
Block(-6,5,-7,CONCRETE:7)
Block(-6,5,-6,CONCRETE:7)
Block(-6,6,-7,OBSIDIAN:0)
Block(-6,6,-6,OBSIDIAN:0)
Block(-6,7,-7,OBSIDIAN:0)
Block(-6,7,-6,OBSIDIAN:0)
Block(-6,8,-7,OBSIDIAN:0)
Block(-6,8,-6,OBSIDIAN:0)
Block(-6,9,-7,OBSIDIAN:0)
Block(-6,9,-6,OBSIDIAN:0)
Block(-6,10,-7,OBSIDIAN:0)
Block(-6,10,-6,OBSIDIAN:0)
Block(-6,11,-7,OBSIDIAN:0)
Block(-6,11,-6,OBSIDIAN:0)
Block(-6,12,-7,CONCRETE:7)
Block(-6,12,-6,CONCRETE:7)
Block(-6,13,-7,CONCRETE:7)
Block(-6,13,-6,CONCRETE:7)
Block(-6,14,-7,CONCRETE:7)
Block(-6,14,-6,CONCRETE:7)
Block(-6,15,-7,CONCRETE:7)
Block(-6,15,-6,CONCRETE:7)
Block(-6,16,-7,CONCRETE:7)
Block(-6,16,-6,CONCRETE:7)
Block(-6,17,-7,CONCRETE:7)
Block(-6,17,-6,CONCRETE:7)
Block(-6,18,-7,CONCRETE:7)
Block(-6,18,-6,CONCRETE:7)
Block(-6,19,-7,CONCRETE:7)
Block(-6,19,-6,CONCRETE:7)
Block(-6,20,-7,CONCRETE:7)
Block(-6,20,-6,CONCRETE:7)
Block(-6,21,-7,CONCRETE:7)
Block(-6,21,-6,CONCRETE:7)
Block(-6,22,-7,CONCRETE:7)
Block(-6,22,-6,CONCRETE:7)
Block(-6,23,-7,OBSIDIAN:0)
Block(-6,23,-6,OBSIDIAN:0)
Block(-6,24,-7,OBSIDIAN:0)
Block(-6,24,-6,OBSIDIAN:0)
Block(-6,25,-7,OBSIDIAN:0)
Block(-6,25,-6,OBSIDIAN:0)
Block(-6,26,-7,OBSIDIAN:0)
Block(-6,26,-6,OBSIDIAN:0)
Block(-6,27,-7,OBSIDIAN:0)
Block(-6,27,-6,OBSIDIAN:0)
Block(-6,28,-7,OBSIDIAN:0)
Block(-6,28,-6,OBSIDIAN:0)
Block(-6,29,-7,OBSIDIAN:0)
Block(-5,0,-7,CONCRETE:7)
Block(-5,0,-6,CONCRETE:7)
Block(-5,0,-1,STONE:6)
Block(-5,1,-7,CONCRETE:7)
Block(-5,1,-6,CONCRETE:7)
Block(-5,1,-1,STONE:6)
Block(-5,2,-7,CONCRETE:7)
Block(-5,2,-6,CONCRETE:7)
Block(-5,2,-1,STONE:6)
Block(-5,3,-7,CONCRETE:7)
Block(-5,3,-6,CONCRETE:7)
Block(-5,3,-1,STONE:6)
Block(-5,4,-7,CONCRETE:7)
Block(-5,4,-6,CONCRETE:7)
Block(-5,4,-1,STONE:6)
Block(-5,5,-7,CONCRETE:7)
Block(-5,5,-6,CONCRETE:7)
Block(-5,5,-1,STONE:6)
Block(-5,6,-7,OBSIDIAN:0)
Block(-5,6,-6,OBSIDIAN:0)
Block(-5,6,-1,STONE:6)
Block(-5,7,-7,OBSIDIAN:0)
Block(-5,7,-6,OBSIDIAN:0)
Block(-5,7,-1,STONE:6)
Block(-5,8,-7,OBSIDIAN:0)
Block(-5,8,-6,OBSIDIAN:0)
Block(-5,8,-1,STONE:6)
Block(-5,9,-7,OBSIDIAN:0)
Block(-5,9,-6,OBSIDIAN:0)
Block(-5,9,-1,STONE:6)
Block(-5,10,-7,OBSIDIAN:0)
Block(-5,10,-6,OBSIDIAN:0)
Block(-5,10,-1,STONE:6)
Block(-5,11,-7,OBSIDIAN:0)
Block(-5,11,-6,OBSIDIAN:0)
Block(-5,11,-1,STONE:6)
Block(-5,12,-7,OBSIDIAN:0)
Block(-5,12,-6,OBSIDIAN:0)
Block(-5,12,-1,STONE:6)
Block(-5,13,-7,CONCRETE:7)
Block(-5,13,-6,CONCRETE:7)
Block(-5,13,-1,STONE:6)
Block(-5,14,-7,CONCRETE:7)
Block(-5,14,-6,CONCRETE:7)
Block(-5,14,-1,STONE:6)
Block(-5,15,-7,CONCRETE:7)
Block(-5,15,-6,CONCRETE:7)
Block(-5,15,-1,STONE:6)
Block(-5,16,-7,CONCRETE:7)
Block(-5,16,-6,CONCRETE:7)
Block(-5,16,-1,STONE:6)
Block(-5,17,-7,CONCRETE:7)
Block(-5,17,-6,CONCRETE:7)
Block(-5,17,-1,STONE:6)
Block(-5,18,-7,CONCRETE:7)
Block(-5,18,-6,CONCRETE:7)
Block(-5,18,-1,STONE:6)
Block(-5,19,-7,CONCRETE:7)
Block(-5,19,-6,CONCRETE:7)
Block(-5,19,-1,STONE:6)
Block(-5,20,-7,CONCRETE:7)
Block(-5,20,-6,CONCRETE:7)
Block(-5,20,-1,STONE:6)
Block(-5,21,-7,CONCRETE:7)
Block(-5,21,-6,CONCRETE:7)
Block(-5,21,-1,STONE:6)
Block(-5,22,-7,CONCRETE:7)
Block(-5,22,-6,CONCRETE:7)
Block(-5,22,-1,STONE:6)
Block(-5,23,-7,CONCRETE:7)
Block(-5,23,-6,CONCRETE:7)
Block(-5,23,-1,STONE:6)
Block(-5,24,-7,OBSIDIAN:0)
Block(-5,24,-6,OBSIDIAN:0)
Block(-5,24,-1,STONE:6)
Block(-5,25,-7,OBSIDIAN:0)
Block(-5,25,-6,OBSIDIAN:0)
Block(-5,25,-1,STONE:6)
Block(-5,26,-7,OBSIDIAN:0)
Block(-5,26,-6,OBSIDIAN:0)
Block(-5,26,-1,STONE:6)
Block(-5,27,-7,OBSIDIAN:0)
Block(-5,27,-6,OBSIDIAN:0)
Block(-5,27,-1,STONE:6)
Block(-5,28,-7,OBSIDIAN:0)
Block(-5,28,-6,OBSIDIAN:0)
Block(-5,28,-1,STONE:6)
Block(-5,29,-7,OBSIDIAN:0)
Block(-5,29,-1,STONE:6)
Block(-5,30,-1,STONE:6)
Block(-5,31,-1,STEP:0)
Block(-4,0,-7,CONCRETE:7)
Block(-4,0,-6,CONCRETE:7)
Block(-4,1,-7,CONCRETE:7)
Block(-4,1,-6,CONCRETE:7)
Block(-4,2,-7,CONCRETE:7)
Block(-4,2,-6,CONCRETE:7)
Block(-4,3,-7,CONCRETE:7)
Block(-4,3,-6,CONCRETE:7)
Block(-4,4,-7,CONCRETE:7)
Block(-4,4,-6,CONCRETE:7)
Block(-4,5,-7,CONCRETE:7)
Block(-4,5,-6,CONCRETE:7)
Block(-4,6,-7,CONCRETE:7)
Block(-4,6,-6,CONCRETE:7)
Block(-4,7,-7,OBSIDIAN:0)
Block(-4,7,-6,OBSIDIAN:0)
Block(-4,8,-7,OBSIDIAN:0)
Block(-4,8,-6,OBSIDIAN:0)
Block(-4,9,-7,OBSIDIAN:0)
Block(-4,9,-6,OBSIDIAN:0)
Block(-4,10,-7,OBSIDIAN:0)
Block(-4,10,-6,OBSIDIAN:0)
Block(-4,11,-7,OBSIDIAN:0)
Block(-4,11,-6,OBSIDIAN:0)
Block(-4,12,-7,OBSIDIAN:0)
Block(-4,12,-6,OBSIDIAN:0)
Block(-4,13,-7,CONCRETE:7)
Block(-4,13,-6,CONCRETE:7)
Block(-4,14,-7,CONCRETE:7)
Block(-4,14,-6,CONCRETE:7)
Block(-4,15,-7,CONCRETE:7)
Block(-4,15,-6,CONCRETE:7)
Block(-4,16,-7,CONCRETE:7)
Block(-4,16,-6,CONCRETE:7)
Block(-4,17,-7,CONCRETE:7)
Block(-4,17,-6,CONCRETE:7)
Block(-4,18,-7,CONCRETE:7)
Block(-4,18,-6,CONCRETE:7)
Block(-4,19,-7,CONCRETE:7)
Block(-4,19,-6,CONCRETE:7)
Block(-4,20,-7,CONCRETE:7)
Block(-4,20,-6,CONCRETE:7)
Block(-4,21,-7,CONCRETE:7)
Block(-4,21,-6,CONCRETE:7)
Block(-4,22,-7,CONCRETE:7)
Block(-4,22,-6,CONCRETE:7)
Block(-4,23,-7,CONCRETE:7)
Block(-4,23,-6,CONCRETE:7)
Block(-4,24,-7,CONCRETE:7)
Block(-4,24,-6,CONCRETE:7)
Block(-4,25,-7,OBSIDIAN:0)
Block(-4,25,-6,OBSIDIAN:0)
Block(-4,26,-7,OBSIDIAN:0)
Block(-4,26,-6,OBSIDIAN:0)
Block(-4,27,-7,OBSIDIAN:0)
Block(-4,27,-6,OBSIDIAN:0)
Block(-4,28,-7,OBSIDIAN:0)
Block(-4,28,-6,OBSIDIAN:0)
Block(-4,29,-7,OBSIDIAN:0)
Block(-3,0,-7,CONCRETE:7)
Block(-3,0,-6,CONCRETE:7)
Block(-3,0,1,STONE:6)
Block(-3,1,-7,CONCRETE:7)
Block(-3,1,-6,CONCRETE:7)
Block(-3,1,1,STONE:6)
Block(-3,2,-7,CONCRETE:7)
Block(-3,2,-6,CONCRETE:7)
Block(-3,2,1,STONE:6)
Block(-3,3,-7,CONCRETE:7)
Block(-3,3,-6,CONCRETE:7)
Block(-3,3,1,STONE:6)
Block(-3,4,-7,CONCRETE:7)
Block(-3,4,-6,CONCRETE:7)
Block(-3,4,1,STONE:6)
Block(-3,5,-7,CONCRETE:7)
Block(-3,5,-6,CONCRETE:7)
Block(-3,5,1,STONE:6)
Block(-3,6,-7,CONCRETE:7)
Block(-3,6,-6,CONCRETE:7)
Block(-3,6,1,STONE:6)
Block(-3,7,-7,CONCRETE:7)
Block(-3,7,-6,CONCRETE:7)
Block(-3,7,1,STONE:6)
Block(-3,8,-7,OBSIDIAN:0)
Block(-3,8,-6,OBSIDIAN:0)
Block(-3,8,1,STONE:6)
Block(-3,9,-7,OBSIDIAN:0)
Block(-3,9,-6,OBSIDIAN:0)
Block(-3,9,1,STONE:6)
Block(-3,10,-7,OBSIDIAN:0)
Block(-3,10,-6,OBSIDIAN:0)
Block(-3,10,1,STONE:6)
Block(-3,11,-7,OBSIDIAN:0)
Block(-3,11,-6,OBSIDIAN:0)
Block(-3,11,1,STONE:6)
Block(-3,12,-7,OBSIDIAN:0)
Block(-3,12,-6,OBSIDIAN:0)
Block(-3,12,1,STONE:6)
Block(-3,13,-7,OBSIDIAN:0)
Block(-3,13,-6,OBSIDIAN:0)
Block(-3,13,1,STONE:6)
Block(-3,14,-7,OBSIDIAN:0)
Block(-3,14,-6,OBSIDIAN:0)
Block(-3,14,1,STONE:6)
Block(-3,15,-7,CONCRETE:7)
Block(-3,15,-6,CONCRETE:7)
Block(-3,15,1,STONE:6)
Block(-3,16,-7,CONCRETE:7)
Block(-3,16,-6,CONCRETE:7)
Block(-3,16,1,STONE:6)
Block(-3,17,-7,CONCRETE:7)
Block(-3,17,-6,CONCRETE:7)
Block(-3,17,1,STONE:6)
Block(-3,18,-7,CONCRETE:7)
Block(-3,18,-6,CONCRETE:7)
Block(-3,18,1,STONE:6)
Block(-3,19,-7,CONCRETE:7)
Block(-3,19,-6,CONCRETE:7)
Block(-3,19,1,STONE:6)
Block(-3,20,-7,CONCRETE:7)
Block(-3,20,-6,CONCRETE:7)
Block(-3,20,1,STONE:6)
Block(-3,21,-7,CONCRETE:7)
Block(-3,21,-6,CONCRETE:7)
Block(-3,21,1,STONE:6)
Block(-3,22,-7,CONCRETE:7)
Block(-3,22,-6,CONCRETE:7)
Block(-3,22,1,STONE:6)
Block(-3,23,-7,CONCRETE:7)
Block(-3,23,-6,CONCRETE:7)
Block(-3,23,1,STONE:6)
Block(-3,24,-7,CONCRETE:7)
Block(-3,24,-6,CONCRETE:7)
Block(-3,24,1,STONE:6)
Block(-3,25,-7,CONCRETE:7)
Block(-3,25,-6,CONCRETE:7)
Block(-3,25,1,STONE:6)
Block(-3,26,-7,CONCRETE:7)
Block(-3,26,-6,CONCRETE:7)
Block(-3,26,1,STONE:6)
Block(-3,27,-7,OBSIDIAN:0)
Block(-3,27,-6,OBSIDIAN:0)
Block(-3,27,1,STONE:6)
Block(-3,28,-7,OBSIDIAN:0)
Block(-3,28,-6,OBSIDIAN:0)
Block(-3,28,1,STONE:6)
Block(-3,29,-7,OBSIDIAN:0)
Block(-3,29,1,STONE:6)
Block(-3,30,1,STEP:0)
Block(-2,0,-7,CONCRETE:7)
Block(-2,0,-6,CONCRETE:7)
Block(-2,1,-7,CONCRETE:7)
Block(-2,1,-6,CONCRETE:7)
Block(-2,2,-7,CONCRETE:7)
Block(-2,2,-6,CONCRETE:7)
Block(-2,3,-7,CONCRETE:7)
Block(-2,3,-6,CONCRETE:7)
Block(-2,4,-7,CONCRETE:7)
Block(-2,4,-6,CONCRETE:7)
Block(-2,5,-7,CONCRETE:7)
Block(-2,5,-6,CONCRETE:7)
Block(-2,6,-7,CONCRETE:7)
Block(-2,6,-6,CONCRETE:7)
Block(-2,7,-7,CONCRETE:7)
Block(-2,7,-6,CONCRETE:7)
Block(-2,8,-7,CONCRETE:7)
Block(-2,8,-6,CONCRETE:7)
Block(-2,9,-7,OBSIDIAN:0)
Block(-2,9,-6,OBSIDIAN:0)
Block(-2,10,-7,OBSIDIAN:0)
Block(-2,10,-6,OBSIDIAN:0)
Block(-2,11,-7,OBSIDIAN:0)
Block(-2,11,-6,OBSIDIAN:0)
Block(-2,12,-7,OBSIDIAN:0)
Block(-2,12,-6,OBSIDIAN:0)
Block(-2,13,-7,OBSIDIAN:0)
Block(-2,13,-6,OBSIDIAN:0)
Block(-2,14,-7,OBSIDIAN:0)
Block(-2,14,-6,OBSIDIAN:0)
Block(-2,15,-7,OBSIDIAN:0)
Block(-2,15,-6,OBSIDIAN:0)
Block(-2,16,-7,CONCRETE:7)
Block(-2,16,-6,CONCRETE:7)
Block(-2,17,-7,CONCRETE:7)
Block(-2,17,-6,CONCRETE:7)
Block(-2,18,-7,CONCRETE:7)
Block(-2,18,-6,CONCRETE:7)
Block(-2,19,-7,CONCRETE:7)
Block(-2,19,-6,CONCRETE:7)
Block(-2,20,-7,CONCRETE:7)
Block(-2,20,-6,CONCRETE:7)
Block(-2,21,-7,CONCRETE:7)
Block(-2,21,-6,CONCRETE:7)
Block(-2,22,-7,CONCRETE:7)
Block(-2,22,-6,CONCRETE:7)
Block(-2,23,-7,CONCRETE:7)
Block(-2,23,-6,CONCRETE:7)
Block(-2,24,-7,CONCRETE:7)
Block(-2,24,-6,CONCRETE:7)
Block(-2,25,-7,CONCRETE:7)
Block(-2,25,-6,CONCRETE:7)
Block(-2,26,-7,CONCRETE:7)
Block(-2,26,-6,CONCRETE:7)
Block(-2,27,-7,CONCRETE:7)
Block(-2,27,-6,CONCRETE:7)
Block(-2,28,-7,OBSIDIAN:0)
Block(-2,28,-6,OBSIDIAN:0)
Block(-2,29,-7,OBSIDIAN:0)
Block(-2,30,-7,SNOW:0)
Block(-1,0,-7,CONCRETE:7)
Block(-1,0,-6,OBSIDIAN:0)
Block(-1,1,-7,CONCRETE:7)
Block(-1,1,-6,CONCRETE:7)
Block(-1,2,-7,CONCRETE:7)
Block(-1,2,-6,CONCRETE:7)
Block(-1,3,-7,CONCRETE:7)
Block(-1,3,-6,CONCRETE:7)
Block(-1,4,-7,CONCRETE:7)
Block(-1,4,-6,CONCRETE:7)
Block(-1,5,-7,CONCRETE:7)
Block(-1,5,-6,CONCRETE:7)
Block(-1,6,-7,CONCRETE:7)
Block(-1,6,-6,CONCRETE:7)
Block(-1,7,-7,CONCRETE:7)
Block(-1,7,-6,CONCRETE:7)
Block(-1,8,-7,CONCRETE:7)
Block(-1,8,-6,CONCRETE:7)
Block(-1,9,-7,CONCRETE:7)
Block(-1,9,-6,CONCRETE:7)
Block(-1,10,-7,CONCRETE:7)
Block(-1,10,-6,CONCRETE:7)
Block(-1,11,-7,OBSIDIAN:0)
Block(-1,11,-6,OBSIDIAN:0)
Block(-1,12,-7,OBSIDIAN:0)
Block(-1,12,-6,OBSIDIAN:0)
Block(-1,13,-7,OBSIDIAN:0)
Block(-1,13,-6,OBSIDIAN:0)
Block(-1,14,-7,OBSIDIAN:0)
Block(-1,14,-6,OBSIDIAN:0)
Block(-1,15,-7,OBSIDIAN:0)
Block(-1,15,-6,OBSIDIAN:0)
Block(-1,16,-7,OBSIDIAN:0)
Block(-1,16,-6,OBSIDIAN:0)
Block(-1,17,-7,CONCRETE:7)
Block(-1,17,-6,CONCRETE:7)
Block(-1,18,-7,CONCRETE:7)
Block(-1,18,-6,CONCRETE:7)
Block(-1,19,-7,CONCRETE:7)
Block(-1,19,-6,CONCRETE:7)
Block(-1,20,-7,CONCRETE:7)
Block(-1,20,-6,CONCRETE:7)
Block(-1,21,-7,CONCRETE:7)
Block(-1,21,-6,CONCRETE:7)
Block(-1,22,-7,CONCRETE:7)
Block(-1,22,-6,CONCRETE:7)
Block(-1,23,-7,CONCRETE:7)
Block(-1,23,-6,CONCRETE:7)
Block(-1,24,-7,CONCRETE:7)
Block(-1,24,-6,CONCRETE:7)
Block(-1,25,-7,CONCRETE:7)
Block(-1,25,-6,CONCRETE:7)
Block(-1,26,-7,CONCRETE:7)
Block(-1,26,-6,CONCRETE:7)
Block(-1,27,-7,CONCRETE:7)
Block(-1,27,-6,CONCRETE:7)
Block(-1,28,-7,CONCRETE:7)
Block(-1,28,-6,CONCRETE:7)
Block(-1,29,-7,OBSIDIAN:0)
Block(-1,30,-7,SNOW:0)
Block(0,0,-7,OBSIDIAN:0)
Block(0,0,-6,OBSIDIAN:0)
Block(0,1,-7,CONCRETE:7)
Block(0,1,-6,OBSIDIAN:0)
Block(0,2,-7,CONCRETE:7)
Block(0,2,-6,CONCRETE:7)
Block(0,3,-7,CONCRETE:7)
Block(0,3,-6,CONCRETE:7)
Block(0,4,-7,CONCRETE:7)
Block(0,4,-6,CONCRETE:7)
Block(0,5,-7,CONCRETE:7)
Block(0,5,-6,CONCRETE:7)
Block(0,6,-7,CONCRETE:7)
Block(0,6,-6,CONCRETE:7)
Block(0,7,-7,CONCRETE:7)
Block(0,7,-6,CONCRETE:7)
Block(0,8,-7,CONCRETE:7)
Block(0,8,-6,CONCRETE:7)
Block(0,9,-7,CONCRETE:7)
Block(0,9,-6,CONCRETE:7)
Block(0,10,-7,CONCRETE:7)
Block(0,10,-6,CONCRETE:7)
Block(0,11,-7,OBSIDIAN:0)
Block(0,11,-6,OBSIDIAN:0)
Block(0,12,-7,OBSIDIAN:0)
Block(0,12,-6,OBSIDIAN:0)
Block(0,13,-7,OBSIDIAN:0)
Block(0,13,-6,OBSIDIAN:0)
Block(0,14,-7,OBSIDIAN:0)
Block(0,14,-6,OBSIDIAN:0)
Block(0,15,-7,OBSIDIAN:0)
Block(0,15,-6,OBSIDIAN:0)
Block(0,16,-7,OBSIDIAN:0)
Block(0,16,-6,OBSIDIAN:0)
Block(0,17,-7,OBSIDIAN:0)
Block(0,17,-6,OBSIDIAN:0)
Block(0,18,-7,CONCRETE:7)
Block(0,18,-6,CONCRETE:7)
Block(0,19,-7,CONCRETE:7)
Block(0,19,-6,CONCRETE:7)
Block(0,20,-7,CONCRETE:7)
Block(0,20,-6,CONCRETE:7)
Block(0,21,-7,CONCRETE:7)
Block(0,21,-6,CONCRETE:7)
Block(0,22,-7,CONCRETE:7)
Block(0,22,-6,CONCRETE:7)
Block(0,23,-7,CONCRETE:7)
Block(0,23,-6,CONCRETE:7)
Block(0,24,-7,CONCRETE:7)
Block(0,24,-6,CONCRETE:7)
Block(0,25,-7,CONCRETE:7)
Block(0,25,-6,CONCRETE:7)
Block(0,26,-7,CONCRETE:7)
Block(0,26,-6,CONCRETE:7)
Block(0,27,-7,CONCRETE:7)
Block(0,27,-6,CONCRETE:7)
Block(0,28,-7,CONCRETE:7)
Block(0,28,-6,CONCRETE:7)
Block(0,29,-7,CONCRETE:7)
Block(0,30,-7,SNOW:1)
Block(1,0,-7,OBSIDIAN:0)
Block(1,0,-6,OBSIDIAN:0)
Block(1,1,-7,OBSIDIAN:0)
Block(1,1,-6,OBSIDIAN:0)
Block(1,2,-7,CONCRETE:7)
Block(1,2,-6,CONCRETE:7)
Block(1,3,-7,CONCRETE:7)
Block(1,3,-6,CONCRETE:7)
Block(1,4,-7,CONCRETE:7)
Block(1,4,-6,CONCRETE:7)
Block(1,5,-7,CONCRETE:7)
Block(1,5,-6,CONCRETE:7)
Block(1,6,-7,CONCRETE:7)
Block(1,6,-6,CONCRETE:7)
Block(1,7,-7,CONCRETE:7)
Block(1,7,-6,CONCRETE:7)
Block(1,8,-7,CONCRETE:7)
Block(1,8,-6,CONCRETE:7)
Block(1,9,-7,CONCRETE:7)
Block(1,9,-6,CONCRETE:7)
Block(1,10,-7,CONCRETE:7)
Block(1,10,-6,CONCRETE:7)
Block(1,11,-7,CONCRETE:7)
Block(1,11,-6,CONCRETE:7)
Block(1,12,-7,OBSIDIAN:0)
Block(1,12,-6,OBSIDIAN:0)
Block(1,13,-7,OBSIDIAN:0)
Block(1,13,-6,OBSIDIAN:0)
Block(1,14,-7,OBSIDIAN:0)
Block(1,14,-6,OBSIDIAN:0)
Block(1,15,-7,OBSIDIAN:0)
Block(1,15,-6,OBSIDIAN:0)
Block(1,16,-7,OBSIDIAN:0)
Block(1,16,-6,OBSIDIAN:0)
Block(1,17,-7,OBSIDIAN:0)
Block(1,17,-6,OBSIDIAN:0)
Block(1,18,-7,OBSIDIAN:0)
Block(1,18,-6,OBSIDIAN:0)
Block(1,19,-7,CONCRETE:7)
Block(1,19,-6,CONCRETE:7)
Block(1,20,-7,CONCRETE:7)
Block(1,20,-6,CONCRETE:7)
Block(1,21,-7,CONCRETE:7)
Block(1,21,-6,CONCRETE:7)
Block(1,22,-7,CONCRETE:7)
Block(1,22,-6,CONCRETE:7)
Block(1,23,-7,CONCRETE:7)
Block(1,23,-6,CONCRETE:7)
Block(1,24,-7,CONCRETE:7)
Block(1,24,-6,CONCRETE:7)
Block(1,25,-7,CONCRETE:7)
Block(1,25,-6,CONCRETE:7)
Block(1,26,-7,CONCRETE:7)
Block(1,26,-6,CONCRETE:7)
Block(1,27,-7,CONCRETE:7)
Block(1,27,-6,CONCRETE:7)
Block(1,28,-7,CONCRETE:7)
Block(1,28,-6,CONCRETE:7)
Block(1,29,-7,CONCRETE:7)
Block(1,29,-6,SNOW:0)
Block(1,30,-7,SNOW:3)
Block(2,0,-7,OBSIDIAN:0)
Block(2,0,-6,OBSIDIAN:0)
Block(2,1,-7,OBSIDIAN:0)
Block(2,1,-6,OBSIDIAN:0)
Block(2,2,-7,OBSIDIAN:0)
Block(2,2,-6,OBSIDIAN:0)
Block(2,3,-7,CONCRETE:7)
Block(2,3,-6,CONCRETE:7)
Block(2,4,-7,CONCRETE:7)
Block(2,4,-6,CONCRETE:7)
Block(2,5,-7,CONCRETE:7)
Block(2,5,-6,CONCRETE:7)
Block(2,6,-7,CONCRETE:7)
Block(2,6,-6,CONCRETE:7)
Block(2,7,-7,CONCRETE:7)
Block(2,7,-6,CONCRETE:7)
Block(2,8,-7,CONCRETE:7)
Block(2,8,-6,CONCRETE:7)
Block(2,9,-7,CONCRETE:7)
Block(2,9,-6,CONCRETE:7)
Block(2,10,-7,CONCRETE:7)
Block(2,10,-6,CONCRETE:7)
Block(2,11,-7,CONCRETE:7)
Block(2,11,-6,CONCRETE:7)
Block(2,12,-7,CONCRETE:7)
Block(2,12,-6,CONCRETE:7)
Block(2,13,-7,OBSIDIAN:0)
Block(2,13,-6,OBSIDIAN:0)
Block(2,14,-7,OBSIDIAN:0)
Block(2,14,-6,OBSIDIAN:0)
Block(2,15,-7,OBSIDIAN:0)
Block(2,15,-6,OBSIDIAN:0)
Block(2,16,-7,OBSIDIAN:0)
Block(2,16,-6,OBSIDIAN:0)
Block(2,17,-7,OBSIDIAN:0)
Block(2,17,-6,OBSIDIAN:0)
Block(2,18,-7,OBSIDIAN:0)
Block(2,18,-6,OBSIDIAN:0)
Block(2,19,-7,OBSIDIAN:0)
Block(2,19,-6,OBSIDIAN:0)
Block(2,20,-7,CONCRETE:7)
Block(2,20,-6,CONCRETE:7)
Block(2,21,-7,CONCRETE:7)
Block(2,21,-6,CONCRETE:7)
Block(2,22,-7,CONCRETE:7)
Block(2,22,-6,CONCRETE:7)
Block(2,23,-7,CONCRETE:7)
Block(2,23,-6,CONCRETE:7)
Block(2,24,-7,CONCRETE:7)
Block(2,24,-6,CONCRETE:7)
Block(2,25,-7,CONCRETE:7)
Block(2,25,-6,CONCRETE:7)
Block(2,26,-7,CONCRETE:7)
Block(2,26,-6,CONCRETE:7)
Block(2,27,-7,CONCRETE:7)
Block(2,27,-6,CONCRETE:7)
Block(2,28,-7,CONCRETE:7)
Block(2,28,-6,CONCRETE:7)
Block(2,29,-7,CONCRETE:7)
Block(2,29,-6,SNOW:1)
Block(2,30,-7,SNOW:6)
Block(2,41,-7,PACKED_ICE:0)
Block(2,42,-7,PACKED_ICE:0)
Block(3,0,-7,OBSIDIAN:0)
Block(3,0,-6,OBSIDIAN:0)
Block(3,1,-7,OBSIDIAN:0)
Block(3,1,-6,OBSIDIAN:0)
Block(3,2,-7,OBSIDIAN:0)
Block(3,2,-6,OBSIDIAN:0)
Block(3,3,-7,CONCRETE:7)
Block(3,3,-6,CONCRETE:7)
Block(3,4,-7,CONCRETE:7)
Block(3,4,-6,CONCRETE:7)
Block(3,5,-7,CONCRETE:7)
Block(3,5,-6,CONCRETE:7)
Block(3,6,-7,CONCRETE:7)
Block(3,6,-6,CONCRETE:7)
Block(3,7,-7,CONCRETE:7)
Block(3,7,-6,CONCRETE:7)
Block(3,8,-7,CONCRETE:7)
Block(3,8,-6,CONCRETE:7)
Block(3,9,-7,CONCRETE:7)
Block(3,9,-6,CONCRETE:7)
Block(3,10,-7,CONCRETE:7)
Block(3,10,-6,CONCRETE:7)
Block(3,11,-7,CONCRETE:7)
Block(3,11,-6,CONCRETE:7)
Block(3,12,-7,CONCRETE:7)
Block(3,12,-6,CONCRETE:7)
Block(3,13,-7,CONCRETE:7)
Block(3,13,-6,CONCRETE:7)
Block(3,14,-7,OBSIDIAN:0)
Block(3,14,-6,OBSIDIAN:0)
Block(3,15,-7,OBSIDIAN:0)
Block(3,15,-6,OBSIDIAN:0)
Block(3,16,-7,OBSIDIAN:0)
Block(3,16,-6,OBSIDIAN:0)
Block(3,17,-7,OBSIDIAN:0)
Block(3,17,-6,OBSIDIAN:0)
Block(3,18,-7,OBSIDIAN:0)
Block(3,18,-6,OBSIDIAN:0)
Block(3,19,-7,OBSIDIAN:0)
Block(3,19,-6,OBSIDIAN:0)
Block(3,20,-7,CONCRETE:7)
Block(3,20,-6,CONCRETE:7)
Block(3,21,-7,CONCRETE:7)
Block(3,21,-6,CONCRETE:7)
Block(3,22,-7,CONCRETE:7)
Block(3,22,-6,CONCRETE:7)
Block(3,23,-7,CONCRETE:7)
Block(3,23,-6,CONCRETE:7)
Block(3,24,-7,CONCRETE:7)
Block(3,24,-6,CONCRETE:7)
Block(3,25,-7,CONCRETE:7)
Block(3,25,-6,CONCRETE:7)
Block(3,26,-7,CONCRETE:7)
Block(3,26,-6,CONCRETE:7)
Block(3,27,-7,CONCRETE:7)
Block(3,27,-6,CONCRETE:7)
Block(3,28,-7,CONCRETE:7)
Block(3,28,-6,CONCRETE:7)
Block(3,29,-7,CONCRETE:7)
Block(3,29,-6,SNOW:3)
Block(3,30,-7,SNOW:7)
Block(3,31,-7,SNOW:1)
Block(3,37,-6,PACKED_ICE:0)
Block(3,38,-7,PACKED_ICE:0)
Block(3,38,-6,PACKED_ICE:0)
Block(3,39,-7,PACKED_ICE:0)
Block(3,39,-6,PACKED_ICE:0)
Block(3,40,-7,PACKED_ICE:0)
Block(3,40,-6,PACKED_ICE:0)
Block(3,40,-5,PACKED_ICE:0)
Block(3,41,-7,PACKED_ICE:0)
Block(3,41,-6,PACKED_ICE:0)
Block(3,42,-7,PACKED_ICE:0)
Block(4,0,-7,OBSIDIAN:0)
Block(4,0,-6,OBSIDIAN:0)
Block(4,1,-7,OBSIDIAN:0)
Block(4,1,-6,OBSIDIAN:0)
Block(4,2,-7,OBSIDIAN:0)
Block(4,2,-6,OBSIDIAN:0)
Block(4,3,-7,OBSIDIAN:0)
Block(4,3,-6,OBSIDIAN:0)
Block(4,4,-7,CONCRETE:7)
Block(4,4,-6,CONCRETE:7)
Block(4,5,-7,CONCRETE:7)
Block(4,5,-6,CONCRETE:7)
Block(4,6,-7,CONCRETE:7)
Block(4,6,-6,CONCRETE:7)
Block(4,7,-7,CONCRETE:7)
Block(4,7,-6,CONCRETE:7)
Block(4,8,-7,CONCRETE:7)
Block(4,8,-6,CONCRETE:7)
Block(4,9,-7,CONCRETE:7)
Block(4,9,-6,CONCRETE:7)
Block(4,10,-7,CONCRETE:7)
Block(4,10,-6,CONCRETE:7)
Block(4,11,-7,CONCRETE:7)
Block(4,11,-6,CONCRETE:7)
Block(4,12,-7,CONCRETE:7)
Block(4,12,-6,CONCRETE:7)
Block(4,13,-7,CONCRETE:7)
Block(4,13,-6,CONCRETE:7)
Block(4,14,-7,OBSIDIAN:0)
Block(4,14,-6,OBSIDIAN:0)
Block(4,15,-7,OBSIDIAN:0)
Block(4,15,-6,OBSIDIAN:0)
Block(4,16,-7,OBSIDIAN:0)
Block(4,16,-6,OBSIDIAN:0)
Block(4,17,-7,OBSIDIAN:0)
Block(4,17,-6,OBSIDIAN:0)
Block(4,18,-7,OBSIDIAN:0)
Block(4,18,-6,OBSIDIAN:0)
Block(4,19,-7,OBSIDIAN:0)
Block(4,19,-6,OBSIDIAN:0)
Block(4,20,-7,CONCRETE:7)
Block(4,20,-6,CONCRETE:7)
Block(4,21,-7,CONCRETE:7)
Block(4,21,-6,CONCRETE:7)
Block(4,22,-7,CONCRETE:7)
Block(4,22,-6,CONCRETE:7)
Block(4,23,-7,CONCRETE:7)
Block(4,23,-6,CONCRETE:7)
Block(4,24,-7,CONCRETE:7)
Block(4,24,-6,CONCRETE:7)
Block(4,25,-7,CONCRETE:7)
Block(4,25,-6,CONCRETE:7)
Block(4,26,-7,CONCRETE:7)
Block(4,26,-6,CONCRETE:7)
Block(4,27,-7,CONCRETE:7)
Block(4,27,-6,CONCRETE:7)
Block(4,28,-7,CONCRETE:7)
Block(4,28,-6,CONCRETE:7)
Block(4,29,-7,CONCRETE:7)
Block(4,29,-6,SNOW:5)
Block(4,30,-7,SNOW_BLOCK:0)
Block(4,31,-7,SNOW:4)
Block(4,36,-6,PACKED_ICE:0)
Block(4,36,-5,PACKED_ICE:0)
Block(4,36,-4,PACKED_ICE:0)
Block(4,37,-7,PACKED_ICE:0)
Block(4,37,-6,PACKED_ICE:0)
Block(4,37,-5,PACKED_ICE:0)
Block(4,37,-4,PACKED_ICE:0)
Block(4,38,-7,PACKED_ICE:0)
Block(4,38,-6,PACKED_ICE:0)
Block(4,38,-5,PACKED_ICE:0)
Block(4,38,-4,PACKED_ICE:0)
Block(4,39,-7,PACKED_ICE:0)
Block(4,39,-6,PACKED_ICE:0)
Block(4,39,-5,PACKED_ICE:0)
Block(4,39,-4,PACKED_ICE:0)
Block(4,40,-7,PACKED_ICE:0)
Block(4,40,-6,PACKED_ICE:0)
Block(4,40,-5,PACKED_ICE:0)
Block(4,41,-7,PACKED_ICE:0)
Block(4,41,-6,PACKED_ICE:0)
Block(4,42,-7,PACKED_ICE:0)
Block(5,0,-7,OBSIDIAN:0)
Block(5,0,-6,OBSIDIAN:0)
Block(5,1,-7,OBSIDIAN:0)
Block(5,1,-6,OBSIDIAN:0)
Block(5,2,-7,OBSIDIAN:0)
Block(5,2,-6,OBSIDIAN:0)
Block(5,3,-7,OBSIDIAN:0)
Block(5,3,-6,OBSIDIAN:0)
Block(5,4,-7,OBSIDIAN:0)
Block(5,4,-6,OBSIDIAN:0)
Block(5,5,-7,CONCRETE:7)
Block(5,5,-6,CONCRETE:7)
Block(5,6,-7,CONCRETE:7)
Block(5,6,-6,CONCRETE:7)
Block(5,7,-7,CONCRETE:7)
Block(5,7,-6,CONCRETE:7)
Block(5,8,-7,CONCRETE:7)
Block(5,8,-6,CONCRETE:7)
Block(5,9,-7,CONCRETE:7)
Block(5,9,-6,CONCRETE:7)
Block(5,10,-7,CONCRETE:7)
Block(5,10,-6,CONCRETE:7)
Block(5,11,-7,CONCRETE:7)
Block(5,11,-6,CONCRETE:7)
Block(5,12,-7,CONCRETE:7)
Block(5,12,-6,CONCRETE:7)
Block(5,13,-7,CONCRETE:7)
Block(5,13,-6,CONCRETE:7)
Block(5,14,-7,OBSIDIAN:0)
Block(5,14,-6,OBSIDIAN:0)
Block(5,15,-7,OBSIDIAN:0)
Block(5,15,-6,OBSIDIAN:0)
Block(5,16,-7,OBSIDIAN:0)
Block(5,16,-6,OBSIDIAN:0)
Block(5,17,-7,OBSIDIAN:0)
Block(5,17,-6,OBSIDIAN:0)
Block(5,18,-7,OBSIDIAN:0)
Block(5,18,-6,OBSIDIAN:0)
Block(5,19,-7,OBSIDIAN:0)
Block(5,19,-6,OBSIDIAN:0)
Block(5,20,-7,OBSIDIAN:0)
Block(5,20,-6,OBSIDIAN:0)
Block(5,21,-7,CONCRETE:7)
Block(5,21,-6,CONCRETE:7)
Block(5,22,-7,CONCRETE:7)
Block(5,22,-6,CONCRETE:7)
Block(5,23,-7,CONCRETE:7)
Block(5,23,-6,CONCRETE:7)
Block(5,24,-7,CONCRETE:7)
Block(5,24,-6,CONCRETE:7)
Block(5,25,-7,CONCRETE:7)
Block(5,25,-6,CONCRETE:7)
Block(5,26,-7,CONCRETE:7)
Block(5,26,-6,CONCRETE:7)
Block(5,27,-7,CONCRETE:7)
Block(5,27,-6,CONCRETE:7)
Block(5,28,-7,CONCRETE:7)
Block(5,28,-6,CONCRETE:7)
Block(5,29,-7,CONCRETE:7)
Block(5,29,-6,SNOW_BLOCK:0)
Block(5,30,-7,SNOW_BLOCK:0)
Block(5,31,-7,SNOW:3)
Block(5,34,-4,PACKED_ICE:0)
Block(5,34,-3,PACKED_ICE:0)
Block(5,35,-6,PACKED_ICE:0)
Block(5,35,-5,PACKED_ICE:0)
Block(5,35,-4,PACKED_ICE:0)
Block(5,35,-3,PACKED_ICE:0)
Block(5,35,-2,PACKED_ICE:0)
Block(5,36,-7,PACKED_ICE:0)
Block(5,36,-6,PACKED_ICE:0)
Block(5,36,-5,PACKED_ICE:0)
Block(5,36,-4,PACKED_ICE:0)
Block(5,36,-3,PACKED_ICE:0)
Block(5,36,-2,PACKED_ICE:0)
Block(5,37,-7,PACKED_ICE:0)
Block(5,37,-6,PACKED_ICE:0)
Block(5,37,-5,PACKED_ICE:0)
Block(5,37,-4,PACKED_ICE:0)
Block(5,37,-3,PACKED_ICE:0)
Block(5,37,-2,PACKED_ICE:0)
Block(5,38,-7,PACKED_ICE:0)
Block(5,38,-6,PACKED_ICE:0)
Block(5,38,-5,PACKED_ICE:0)
Block(5,38,-4,PACKED_ICE:0)
Block(5,38,-3,PACKED_ICE:0)
Block(5,39,-7,PACKED_ICE:0)
Block(5,39,-6,PACKED_ICE:0)
Block(5,39,-5,PACKED_ICE:0)
Block(5,39,-4,PACKED_ICE:0)
Block(5,40,-7,PACKED_ICE:0)
Block(5,40,-6,PACKED_ICE:0)
Block(5,40,-5,PACKED_ICE:0)
Block(5,41,-7,PACKED_ICE:0)
Block(5,41,-6,PACKED_ICE:0)
Block(5,42,-7,PACKED_ICE:0)
Block(6,0,-7,OBSIDIAN:0)
Block(6,0,-6,OBSIDIAN:0)
Block(6,1,-7,OBSIDIAN:0)
Block(6,1,-6,OBSIDIAN:0)
Block(6,2,-7,OBSIDIAN:0)
Block(6,2,-6,OBSIDIAN:0)
Block(6,3,-7,OBSIDIAN:0)
Block(6,3,-6,OBSIDIAN:0)
Block(6,4,-7,OBSIDIAN:0)
Block(6,4,-6,OBSIDIAN:0)
Block(6,5,-7,OBSIDIAN:0)
Block(6,5,-6,OBSIDIAN:0)
Block(6,6,-7,CONCRETE:7)
Block(6,6,-6,CONCRETE:7)
Block(6,7,-7,CONCRETE:7)
Block(6,7,-6,CONCRETE:7)
Block(6,8,-7,CONCRETE:7)
Block(6,8,-6,CONCRETE:7)
Block(6,9,-7,CONCRETE:7)
Block(6,9,-6,CONCRETE:7)
Block(6,10,-7,CONCRETE:7)
Block(6,10,-6,CONCRETE:7)
Block(6,11,-7,CONCRETE:7)
Block(6,11,-6,CONCRETE:7)
Block(6,12,-7,CONCRETE:7)
Block(6,12,-6,CONCRETE:7)
Block(6,13,-7,CONCRETE:7)
Block(6,13,-6,CONCRETE:7)
Block(6,14,-7,CONCRETE:7)
Block(6,14,-6,CONCRETE:7)
Block(6,15,-7,OBSIDIAN:0)
Block(6,15,-6,OBSIDIAN:0)
Block(6,16,-7,OBSIDIAN:0)
Block(6,16,-6,OBSIDIAN:0)
Block(6,17,-7,OBSIDIAN:0)
Block(6,17,-6,OBSIDIAN:0)
Block(6,18,-7,OBSIDIAN:0)
Block(6,18,-6,OBSIDIAN:0)
Block(6,19,-7,OBSIDIAN:0)
Block(6,19,-6,OBSIDIAN:0)
Block(6,20,-7,OBSIDIAN:0)
Block(6,20,-6,OBSIDIAN:0)
Block(6,21,-7,CONCRETE:7)
Block(6,21,-6,CONCRETE:7)
Block(6,22,-7,CONCRETE:7)
Block(6,22,-6,CONCRETE:7)
Block(6,23,-7,CONCRETE:7)
Block(6,23,-6,CONCRETE:7)
Block(6,24,-7,CONCRETE:7)
Block(6,24,-6,CONCRETE:7)
Block(6,25,-7,CONCRETE:7)
Block(6,25,-6,CONCRETE:7)
Block(6,26,-7,CONCRETE:7)
Block(6,26,-6,CONCRETE:7)
Block(6,27,-7,CONCRETE:7)
Block(6,27,-6,CONCRETE:7)
Block(6,28,-7,CONCRETE:7)
Block(6,28,-6,CONCRETE:7)
Block(6,29,-7,CONCRETE:7)
Block(6,29,-6,SNOW_BLOCK:0)
Block(6,30,-7,SNOW_BLOCK:0)
Block(6,30,-6,SNOW:3)
Block(6,31,-7,SNOW:3)
Block(6,32,-2,PACKED_ICE:0)
Block(6,32,-1,PACKED_ICE:0)
Block(6,33,-4,PACKED_ICE:0)
Block(6,33,-3,PACKED_ICE:0)
Block(6,33,-2,PACKED_ICE:0)
Block(6,33,-1,PACKED_ICE:0)
Block(6,34,-6,PACKED_ICE:0)
Block(6,34,-5,PACKED_ICE:0)
Block(6,34,-4,PACKED_ICE:0)
Block(6,34,-3,PACKED_ICE:0)
Block(6,34,-2,PACKED_ICE:0)
Block(6,34,-1,PACKED_ICE:0)
Block(6,34,0,PACKED_ICE:0)
Block(6,35,-7,PACKED_ICE:0)
Block(6,35,-6,PACKED_ICE:0)
Block(6,35,-5,PACKED_ICE:0)
Block(6,35,-4,PACKED_ICE:0)
Block(6,35,-3,PACKED_ICE:0)
Block(6,35,-2,PACKED_ICE:0)
Block(6,35,-1,PACKED_ICE:0)
Block(6,36,-7,PACKED_ICE:0)
Block(6,36,-6,PACKED_ICE:0)
Block(6,36,-5,PACKED_ICE:0)
Block(6,36,-4,PACKED_ICE:0)
Block(6,36,-3,PACKED_ICE:0)
Block(6,36,-2,PACKED_ICE:0)
Block(6,37,-7,PACKED_ICE:0)
Block(6,37,-6,PACKED_ICE:0)
Block(6,37,-5,PACKED_ICE:0)
Block(6,37,-4,PACKED_ICE:0)
Block(6,37,-3,PACKED_ICE:0)
Block(6,37,-2,PACKED_ICE:0)
Block(6,38,-7,PACKED_ICE:0)
Block(6,38,-6,PACKED_ICE:0)
Block(6,38,-5,PACKED_ICE:0)
Block(6,38,-4,PACKED_ICE:0)
Block(6,38,-3,PACKED_ICE:0)
Block(6,39,-7,PACKED_ICE:0)
Block(6,39,-6,PACKED_ICE:0)
Block(6,39,-5,PACKED_ICE:0)
Block(6,39,-4,PACKED_ICE:0)
Block(6,40,-7,PACKED_ICE:0)
Block(6,40,-6,PACKED_ICE:0)
Block(6,40,-5,PACKED_ICE:0)
Block(6,41,-7,PACKED_ICE:0)
Block(6,41,-6,PACKED_ICE:0)
Block(6,42,-7,PACKED_ICE:0)
Block(7,0,-7,OBSIDIAN:0)
Block(7,0,-6,OBSIDIAN:0)
Block(7,1,-7,OBSIDIAN:0)
Block(7,1,-6,OBSIDIAN:0)
Block(7,2,-7,OBSIDIAN:0)
Block(7,2,-6,OBSIDIAN:0)
Block(7,3,-7,OBSIDIAN:0)
Block(7,3,-6,OBSIDIAN:0)
Block(7,4,-7,OBSIDIAN:0)
Block(7,4,-6,OBSIDIAN:0)
Block(7,5,-7,OBSIDIAN:0)
Block(7,5,-6,OBSIDIAN:0)
Block(7,6,-7,OBSIDIAN:0)
Block(7,6,-6,OBSIDIAN:0)
Block(7,7,-7,CONCRETE:7)
Block(7,7,-6,CONCRETE:7)
Block(7,8,-7,CONCRETE:7)
Block(7,8,-6,CONCRETE:7)
Block(7,9,-7,CONCRETE:7)
Block(7,9,-6,CONCRETE:7)
Block(7,10,-7,CONCRETE:7)
Block(7,10,-6,CONCRETE:7)
Block(7,11,-7,CONCRETE:7)
Block(7,11,-6,CONCRETE:7)
Block(7,12,-7,CONCRETE:7)
Block(7,12,-6,CONCRETE:7)
Block(7,13,-7,CONCRETE:7)
Block(7,13,-6,CONCRETE:7)
Block(7,14,-7,CONCRETE:7)
Block(7,14,-6,CONCRETE:7)
Block(7,15,-7,CONCRETE:7)
Block(7,15,-6,CONCRETE:7)
Block(7,16,-7,OBSIDIAN:0)
Block(7,16,-6,OBSIDIAN:0)
Block(7,17,-7,OBSIDIAN:0)
Block(7,17,-6,OBSIDIAN:0)
Block(7,18,-7,OBSIDIAN:0)
Block(7,18,-6,OBSIDIAN:0)
Block(7,19,-7,OBSIDIAN:0)
Block(7,19,-6,OBSIDIAN:0)
Block(7,20,-7,OBSIDIAN:0)
Block(7,20,-6,OBSIDIAN:0)
Block(7,21,-7,OBSIDIAN:0)
Block(7,21,-6,OBSIDIAN:0)
Block(7,22,-7,CONCRETE:7)
Block(7,22,-6,CONCRETE:7)
Block(7,23,-7,CONCRETE:7)
Block(7,23,-6,CONCRETE:7)
Block(7,24,-7,CONCRETE:7)
Block(7,24,-6,CONCRETE:7)
Block(7,25,-7,CONCRETE:7)
Block(7,25,-6,CONCRETE:7)
Block(7,26,-7,CONCRETE:7)
Block(7,26,-6,CONCRETE:7)
Block(7,27,-7,CONCRETE:7)
Block(7,27,-6,CONCRETE:7)
Block(7,28,-7,CONCRETE:7)
Block(7,28,-6,CONCRETE:7)
Block(7,29,-7,CONCRETE:7)
Block(7,29,-6,SNOW_BLOCK:0)
Block(7,30,-7,SNOW_BLOCK:0)
Block(7,30,-6,SNOW:4)
Block(7,30,-1,PACKED_ICE:0)
Block(7,30,0,PACKED_ICE:0)
Block(7,31,-7,SNOW:1)
Block(7,31,-2,PACKED_ICE:0)
Block(7,31,-1,PACKED_ICE:0)
Block(7,31,0,PACKED_ICE:0)
Block(7,31,1,PACKED_ICE:0)
Block(7,32,-4,PACKED_ICE:0)
Block(7,32,-3,PACKED_ICE:0)
Block(7,32,-2,PACKED_ICE:0)
Block(7,32,-1,PACKED_ICE:0)
Block(7,32,0,PACKED_ICE:0)
Block(7,32,1,PACKED_ICE:0)
Block(7,33,-6,PACKED_ICE:0)
Block(7,33,-5,PACKED_ICE:0)
Block(7,33,-4,PACKED_ICE:0)
Block(7,33,-3,PACKED_ICE:0)
Block(7,33,-2,PACKED_ICE:0)
Block(7,33,-1,PACKED_ICE:0)
Block(7,33,0,PACKED_ICE:0)
Block(7,33,1,PACKED_ICE:0)
Block(7,34,-7,PACKED_ICE:0)
Block(7,34,-6,PACKED_ICE:0)
Block(7,34,-5,PACKED_ICE:0)
Block(7,34,-4,PACKED_ICE:0)
Block(7,34,-3,PACKED_ICE:0)
Block(7,34,-2,PACKED_ICE:0)
Block(7,34,-1,PACKED_ICE:0)
Block(7,34,0,PACKED_ICE:0)
Block(7,35,-7,PACKED_ICE:0)
Block(7,35,-6,PACKED_ICE:0)
Block(7,35,-5,PACKED_ICE:0)
Block(7,35,-4,PACKED_ICE:0)
Block(7,35,-3,PACKED_ICE:0)
Block(7,35,-2,PACKED_ICE:0)
Block(7,35,-1,PACKED_ICE:0)
Block(7,36,-7,PACKED_ICE:0)
Block(7,36,-6,PACKED_ICE:0)
Block(7,36,-5,PACKED_ICE:0)
Block(7,36,-4,PACKED_ICE:0)
Block(7,36,-3,PACKED_ICE:0)
Block(7,36,-2,PACKED_ICE:0)
Block(7,37,-7,PACKED_ICE:0)
Block(7,37,-6,PACKED_ICE:0)
Block(7,37,-5,PACKED_ICE:0)
Block(7,37,-4,PACKED_ICE:0)
Block(7,37,-3,PACKED_ICE:0)
Block(7,37,-2,PACKED_ICE:0)
Block(7,38,-7,PACKED_ICE:0)
Block(7,38,-6,PACKED_ICE:0)
Block(7,38,-5,PACKED_ICE:0)
Block(7,38,-4,PACKED_ICE:0)
Block(7,38,-3,PACKED_ICE:0)
Block(7,39,-7,PACKED_ICE:0)
Block(7,39,-6,PACKED_ICE:0)
Block(7,39,-5,PACKED_ICE:0)
Block(7,39,-4,PACKED_ICE:0)
Block(7,40,-7,PACKED_ICE:0)
Block(7,40,-6,PACKED_ICE:0)
Block(7,40,-5,PACKED_ICE:0)
Block(7,41,-7,PACKED_ICE:0)
Block(7,41,-6,PACKED_ICE:0)
Block(7,42,-7,PACKED_ICE:0)

#######################################################################
# +-----------------------------------------------------------------+ #
# |                             Branches                            | #
# +-----------------------------------------------------------------+ #
#######################################################################

Branch(0,0,-16,true,TempleFrozenC2R2,NORTH,100.0,0)

#######################################################################
# +-----------------------------------------------------------------+ #
# |                             Entities                            | #
# +-----------------------------------------------------------------+ #
#######################################################################


#######################################################################
# +-----------------------------------------------------------------+ #
# |                            Particles                            | #
# +-----------------------------------------------------------------+ #
#######################################################################


#######################################################################
# +-----------------------------------------------------------------+ #
# |                             Spawners                            | #
# +-----------------------------------------------------------------+ #
#######################################################################


#######################################################################
# +-----------------------------------------------------------------+ #
# |                             ModData                             | #
# +-----------------------------------------------------------------+ #
#######################################################################

