
#######################################################################
# +-----------------------------------------------------------------+ #
# |                            BO4 object                           | #
# +-----------------------------------------------------------------+ #
#######################################################################

Author: NLBlackEagle

Description: No description given

SettingsMode: WriteDisable


#######################################################################
# +-----------------------------------------------------------------+ #
# |                          Main settings                          | #
# +-----------------------------------------------------------------+ #
#######################################################################

Frequency: 0

SpawnHeight: highestBlock

UseCenterForHighestBlock: true

##############################
# Height Limits for the BO4. #
##############################

MinHeight: 0

MaxHeight: 255

InheritBO3: 

InheritBO3Rotation: NORTH

OverrideChildSettings: true

OverrideParentHeight: false

CanOverride: false

BranchFrequency: 0

BranchFrequencyGroup: 

MustBeBelowOther: false

MustBeInside: 

CannotBeInside: 

ReplacesBO3: 

MustBeInsideWorldBorders: false

CanSpawnOnWater: true

SpawnOnWaterOnly: false

SpawnUnderWater: false

SpawnAtWaterLevel: false

HeightOffset: 0

RemoveAir: false

ReplaceAbove: 

ReplaceBelow: 

ReplaceWithBiomeBlocks: false

ReplaceWithSurfaceBlock: GRASS

ReplaceWithGroundBlock: DIRT

ReplaceWithStoneBlock: STONE

SmoothRadius: 0

SmoothHeightOffset: 0

SmoothStartTop: false

SmoothStartWood: false

SmoothingSurfaceBlock: 

SmoothingGroundBlock: 

BO3Group: 

IsSpawnPoint: false

DoReplaceBlocks: false


#######################################################################
# +-----------------------------------------------------------------+ #
# |                              Blocks                             | #
# +-----------------------------------------------------------------+ #
#######################################################################

Block(-8,0,-7,CONCRETE:7)
Block(-8,0,-6,CONCRETE:7)
Block(-8,0,-5,CONCRETE:7)
Block(-8,0,-4,CONCRETE:7)
Block(-8,0,-3,CONCRETE:7)
Block(-8,0,-2,CONCRETE:7)
Block(-8,0,-1,CONCRETE:7)
Block(-8,0,0,CONCRETE:7)
Block(-8,0,1,CONCRETE:7)
Block(-8,0,2,CONCRETE:7)
Block(-8,0,3,CONCRETE:7)
Block(-8,0,4,CONCRETE:7)
Block(-8,0,5,CONCRETE:7)
Block(-8,0,6,CONCRETE:7)
Block(-8,0,7,CONCRETE:7)
Block(-8,0,8,CONCRETE:7)
Block(-8,1,-7,CONCRETE:7)
Block(-8,1,-6,CONCRETE:7)
Block(-8,1,-5,CONCRETE:7)
Block(-8,1,-4,CONCRETE:7)
Block(-8,1,-3,CONCRETE:7)
Block(-8,1,-2,CONCRETE:7)
Block(-8,1,-1,CONCRETE:7)
Block(-8,1,0,CONCRETE:7)
Block(-8,1,1,CONCRETE:7)
Block(-8,1,2,CONCRETE:7)
Block(-8,1,3,CONCRETE:7)
Block(-8,1,4,CONCRETE:7)
Block(-8,1,5,CONCRETE:7)
Block(-8,1,6,CONCRETE:7)
Block(-8,1,7,CONCRETE:7)
Block(-8,1,8,CONCRETE:7)
Block(-8,2,-7,CONCRETE:7)
Block(-8,2,-6,CONCRETE:7)
Block(-8,2,-5,CONCRETE:7)
Block(-8,2,-4,CONCRETE:7)
Block(-8,2,-3,CONCRETE:7)
Block(-8,2,-2,CONCRETE:7)
Block(-8,2,-1,CONCRETE:7)
Block(-8,2,0,CONCRETE:7)
Block(-8,2,1,CONCRETE:7)
Block(-8,2,2,CONCRETE:7)
Block(-8,2,3,CONCRETE:7)
Block(-8,2,4,CONCRETE:7)
Block(-8,2,5,CONCRETE:7)
Block(-8,2,6,CONCRETE:7)
Block(-8,2,7,CONCRETE:7)
Block(-8,2,8,CONCRETE:7)
Block(-8,3,-7,CONCRETE:7)
Block(-8,3,-6,CONCRETE:7)
Block(-8,3,-5,CONCRETE:7)
Block(-8,3,-4,CONCRETE:7)
Block(-8,3,-3,CONCRETE:7)
Block(-8,3,-2,CONCRETE:7)
Block(-8,3,-1,CONCRETE:7)
Block(-8,3,0,CONCRETE:7)
Block(-8,3,1,CONCRETE:7)
Block(-8,3,2,CONCRETE:7)
Block(-8,3,3,CONCRETE:7)
Block(-8,3,4,CONCRETE:7)
Block(-8,3,5,CONCRETE:7)
Block(-8,3,6,CONCRETE:7)
Block(-8,3,7,CONCRETE:7)
Block(-8,3,8,CONCRETE:7)
Block(-8,4,-7,CONCRETE:7)
Block(-8,4,-6,CONCRETE:7)
Block(-8,4,-5,CONCRETE:7)
Block(-8,4,-4,CONCRETE:7)
Block(-8,4,-3,CONCRETE:7)
Block(-8,4,-2,CONCRETE:7)
Block(-8,4,-1,CONCRETE:7)
Block(-8,4,0,CONCRETE:7)
Block(-8,4,1,CONCRETE:7)
Block(-8,4,2,CONCRETE:7)
Block(-8,4,3,CONCRETE:7)
Block(-8,4,4,CONCRETE:7)
Block(-8,4,5,CONCRETE:7)
Block(-8,4,6,CONCRETE:7)
Block(-8,4,7,CONCRETE:7)
Block(-8,4,8,CONCRETE:7)
Block(-8,5,-7,CONCRETE:7)
Block(-8,5,-6,CONCRETE:7)
Block(-8,5,-5,CONCRETE:7)
Block(-8,5,-4,CONCRETE:7)
Block(-8,5,-3,CONCRETE:7)
Block(-8,5,-2,CONCRETE:7)
Block(-8,5,-1,CONCRETE:7)
Block(-8,5,0,CONCRETE:7)
Block(-8,5,1,CONCRETE:7)
Block(-8,5,2,CONCRETE:7)
Block(-8,5,3,CONCRETE:7)
Block(-8,5,4,CONCRETE:7)
Block(-8,5,5,CONCRETE:7)
Block(-8,5,6,CONCRETE:7)
Block(-8,5,7,CONCRETE:7)
Block(-8,5,8,CONCRETE:7)
Block(-8,6,-7,CONCRETE:7)
Block(-8,6,-6,CONCRETE:7)
Block(-8,6,-5,CONCRETE:7)
Block(-8,6,-4,CONCRETE:7)
Block(-8,6,-3,CONCRETE:7)
Block(-8,6,-2,CONCRETE:7)
Block(-8,6,-1,CONCRETE:7)
Block(-8,6,0,CONCRETE:7)
Block(-8,6,1,CONCRETE:7)
Block(-8,6,2,CONCRETE:7)
Block(-8,6,3,CONCRETE:7)
Block(-8,6,4,CONCRETE:7)
Block(-8,6,5,CONCRETE:7)
Block(-8,6,6,CONCRETE:7)
Block(-8,6,7,CONCRETE:7)
Block(-8,6,8,CONCRETE:7)
Block(-8,7,-7,CONCRETE:7)
Block(-8,7,-6,CONCRETE:7)
Block(-8,7,-5,CONCRETE:7)
Block(-8,7,-4,CONCRETE:7)
Block(-8,7,-3,CONCRETE:7)
Block(-8,7,-2,CONCRETE:7)
Block(-8,7,-1,CONCRETE:7)
Block(-8,7,0,CONCRETE:7)
Block(-8,7,1,CONCRETE:7)
Block(-8,7,2,CONCRETE:7)
Block(-8,7,3,CONCRETE:7)
Block(-8,7,4,CONCRETE:7)
Block(-8,7,5,CONCRETE:7)
Block(-8,7,6,CONCRETE:7)
Block(-8,7,7,CONCRETE:7)
Block(-8,7,8,CONCRETE:7)
Block(-8,8,-7,CONCRETE:7)
Block(-8,8,-6,CONCRETE:7)
Block(-8,8,-5,CONCRETE:7)
Block(-8,8,-4,CONCRETE:7)
Block(-8,8,-3,CONCRETE:7)
Block(-8,8,-2,CONCRETE:7)
Block(-8,8,-1,CONCRETE:7)
Block(-8,8,0,CONCRETE:7)
Block(-8,8,1,CONCRETE:7)
Block(-8,8,2,CONCRETE:7)
Block(-8,8,3,CONCRETE:7)
Block(-8,8,4,CONCRETE:7)
Block(-8,8,5,CONCRETE:7)
Block(-8,8,6,CONCRETE:7)
Block(-8,8,7,CONCRETE:7)
Block(-8,8,8,CONCRETE:7)
Block(-8,9,-7,CONCRETE:7)
Block(-8,9,-6,CONCRETE:7)
Block(-8,9,-5,CONCRETE:7)
Block(-8,9,-4,CONCRETE:7)
Block(-8,9,-3,CONCRETE:7)
Block(-8,9,-2,CONCRETE:7)
Block(-8,9,-1,CONCRETE:7)
Block(-8,9,0,CONCRETE:7)
Block(-8,9,1,CONCRETE:7)
Block(-8,9,2,CONCRETE:7)
Block(-8,9,3,CONCRETE:7)
Block(-8,9,4,CONCRETE:7)
Block(-8,9,5,CONCRETE:7)
Block(-8,9,6,CONCRETE:7)
Block(-8,9,7,CONCRETE:7)
Block(-8,9,8,CONCRETE:7)
Block(-8,10,-7,CONCRETE:7)
Block(-8,10,-6,CONCRETE:7)
Block(-8,10,-5,CONCRETE:7)
Block(-8,10,-4,CONCRETE:7)
Block(-8,10,-3,CONCRETE:7)
Block(-8,10,-2,CONCRETE:7)
Block(-8,10,-1,CONCRETE:7)
Block(-8,10,0,CONCRETE:7)
Block(-8,10,1,CONCRETE:7)
Block(-8,10,2,CONCRETE:7)
Block(-8,10,3,CONCRETE:7)
Block(-8,10,4,CONCRETE:7)
Block(-8,10,5,CONCRETE:7)
Block(-8,10,6,CONCRETE:7)
Block(-8,10,7,CONCRETE:7)
Block(-8,10,8,CONCRETE:7)
Block(-8,11,-7,CONCRETE:7)
Block(-8,11,-6,CONCRETE:7)
Block(-8,11,-5,CONCRETE:7)
Block(-8,11,-4,CONCRETE:7)
Block(-8,11,-3,CONCRETE:7)
Block(-8,11,-2,CONCRETE:7)
Block(-8,11,-1,CONCRETE:7)
Block(-8,11,0,CONCRETE:7)
Block(-8,11,1,CONCRETE:7)
Block(-8,11,2,CONCRETE:7)
Block(-8,11,3,CONCRETE:7)
Block(-8,11,4,CONCRETE:7)
Block(-8,11,5,CONCRETE:7)
Block(-8,11,6,CONCRETE:7)
Block(-8,11,7,CONCRETE:7)
Block(-8,11,8,CONCRETE:7)
Block(-8,12,-7,CONCRETE:7)
Block(-8,12,-6,CONCRETE:7)
Block(-8,12,-5,CONCRETE:7)
Block(-8,12,-4,CONCRETE:7)
Block(-8,12,-3,CONCRETE:7)
Block(-8,12,-2,CONCRETE:7)
Block(-8,12,-1,CONCRETE:7)
Block(-8,12,0,CONCRETE:7)
Block(-8,12,1,CONCRETE:7)
Block(-8,12,2,CONCRETE:7)
Block(-8,12,3,CONCRETE:7)
Block(-8,12,4,CONCRETE:7)
Block(-8,12,5,CONCRETE:7)
Block(-8,12,6,CONCRETE:7)
Block(-8,12,7,CONCRETE:7)
Block(-8,12,8,CONCRETE:7)
Block(-8,13,-7,OBSIDIAN:0)
Block(-8,13,-6,CONCRETE:7)
Block(-8,13,-5,CONCRETE:7)
Block(-8,13,-4,CONCRETE:7)
Block(-8,13,-3,CONCRETE:7)
Block(-8,13,-2,CONCRETE:7)
Block(-8,13,-1,CONCRETE:7)
Block(-8,13,0,CONCRETE:7)
Block(-8,13,1,CONCRETE:7)
Block(-8,13,2,CONCRETE:7)
Block(-8,13,3,CONCRETE:7)
Block(-8,13,4,CONCRETE:7)
Block(-8,13,5,CONCRETE:7)
Block(-8,13,6,CONCRETE:7)
Block(-8,13,7,CONCRETE:7)
Block(-8,13,8,CONCRETE:7)
Block(-8,14,-7,OBSIDIAN:0)
Block(-8,14,-6,CONCRETE:7)
Block(-8,14,-5,CONCRETE:7)
Block(-8,14,-4,CONCRETE:7)
Block(-8,14,-3,CONCRETE:7)
Block(-8,14,-2,CONCRETE:7)
Block(-8,14,-1,CONCRETE:7)
Block(-8,14,0,CONCRETE:7)
Block(-8,14,1,CONCRETE:7)
Block(-8,14,2,CONCRETE:7)
Block(-8,14,3,CONCRETE:7)
Block(-8,14,4,CONCRETE:7)
Block(-8,14,5,CONCRETE:7)
Block(-8,14,6,CONCRETE:7)
Block(-8,14,7,CONCRETE:7)
Block(-8,14,8,CONCRETE:7)
Block(-8,15,-7,OBSIDIAN:0)
Block(-8,15,-6,CONCRETE:7)
Block(-8,15,-5,CONCRETE:7)
Block(-8,15,-4,CONCRETE:7)
Block(-8,15,-3,CONCRETE:7)
Block(-8,15,-2,CONCRETE:7)
Block(-8,15,-1,CONCRETE:7)
Block(-8,15,0,CONCRETE:7)
Block(-8,15,1,CONCRETE:7)
Block(-8,15,2,CONCRETE:7)
Block(-8,15,3,CONCRETE:7)
Block(-8,15,4,CONCRETE:7)
Block(-8,15,5,CONCRETE:7)
Block(-8,15,6,CONCRETE:7)
Block(-8,15,7,CONCRETE:7)
Block(-8,15,8,CONCRETE:7)
Block(-8,16,-7,OBSIDIAN:0)
Block(-8,16,-6,CONCRETE:7)
Block(-8,16,-5,CONCRETE:7)
Block(-8,16,-4,CONCRETE:7)
Block(-8,16,-3,CONCRETE:7)
Block(-8,16,-2,CONCRETE:7)
Block(-8,16,-1,CONCRETE:7)
Block(-8,16,0,CONCRETE:7)
Block(-8,16,1,CONCRETE:7)
Block(-8,16,2,CONCRETE:7)
Block(-8,16,3,CONCRETE:7)
Block(-8,16,4,CONCRETE:7)
Block(-8,16,5,CONCRETE:7)
Block(-8,16,6,CONCRETE:7)
Block(-8,16,7,CONCRETE:7)
Block(-8,16,8,CONCRETE:7)
Block(-8,17,-7,OBSIDIAN:0)
Block(-8,17,-6,CONCRETE:7)
Block(-8,17,-5,CONCRETE:7)
Block(-8,17,-4,CONCRETE:7)
Block(-8,17,-3,CONCRETE:7)
Block(-8,17,-2,CONCRETE:7)
Block(-8,17,-1,CONCRETE:7)
Block(-8,17,0,CONCRETE:7)
Block(-8,17,1,CONCRETE:7)
Block(-8,17,2,CONCRETE:7)
Block(-8,17,3,CONCRETE:7)
Block(-8,17,4,CONCRETE:7)
Block(-8,17,5,CONCRETE:7)
Block(-8,17,6,CONCRETE:7)
Block(-8,17,7,CONCRETE:7)
Block(-8,17,8,CONCRETE:7)
Block(-8,18,-7,OBSIDIAN:0)
Block(-8,18,-6,OBSIDIAN:0)
Block(-8,18,-5,OBSIDIAN:0)
Block(-8,18,-4,CONCRETE:7)
Block(-8,18,-3,CONCRETE:7)
Block(-8,18,-2,CONCRETE:7)
Block(-8,18,-1,CONCRETE:7)
Block(-8,18,0,CONCRETE:7)
Block(-8,18,1,CONCRETE:7)
Block(-8,18,2,CONCRETE:7)
Block(-8,18,3,CONCRETE:7)
Block(-8,18,4,CONCRETE:7)
Block(-8,18,5,CONCRETE:7)
Block(-8,18,6,CONCRETE:7)
Block(-8,18,7,CONCRETE:7)
Block(-8,18,8,CONCRETE:7)
Block(-8,19,-7,OBSIDIAN:0)
Block(-8,19,-6,OBSIDIAN:0)
Block(-8,19,-5,OBSIDIAN:0)
Block(-8,19,-4,OBSIDIAN:0)
Block(-8,19,-3,CONCRETE:7)
Block(-8,19,-2,CONCRETE:7)
Block(-8,19,-1,CONCRETE:7)
Block(-8,19,0,CONCRETE:7)
Block(-8,19,1,CONCRETE:7)
Block(-8,19,2,CONCRETE:7)
Block(-8,19,3,CONCRETE:7)
Block(-8,19,4,CONCRETE:7)
Block(-8,19,5,CONCRETE:7)
Block(-8,19,6,CONCRETE:7)
Block(-8,19,7,CONCRETE:7)
Block(-8,19,8,CONCRETE:7)
Block(-8,20,-7,OBSIDIAN:0)
Block(-8,20,-6,OBSIDIAN:0)
Block(-8,20,-5,OBSIDIAN:0)
Block(-8,20,-4,OBSIDIAN:0)
Block(-8,20,-3,CONCRETE:7)
Block(-8,20,-2,CONCRETE:7)
Block(-8,20,-1,CONCRETE:7)
Block(-8,20,0,CONCRETE:7)
Block(-8,20,1,CONCRETE:7)
Block(-8,20,2,CONCRETE:7)
Block(-8,20,3,CONCRETE:7)
Block(-8,20,4,CONCRETE:7)
Block(-8,20,5,CONCRETE:7)
Block(-8,20,6,CONCRETE:7)
Block(-8,20,7,CONCRETE:7)
Block(-8,20,8,CONCRETE:7)
Block(-8,21,-7,CONCRETE:7)
Block(-8,21,-6,OBSIDIAN:0)
Block(-8,21,-5,OBSIDIAN:0)
Block(-8,21,-4,OBSIDIAN:0)
Block(-8,21,-3,OBSIDIAN:0)
Block(-8,21,-2,CONCRETE:7)
Block(-8,21,-1,CONCRETE:7)
Block(-8,21,0,CONCRETE:7)
Block(-8,21,1,CONCRETE:7)
Block(-8,21,2,CONCRETE:7)
Block(-8,21,3,CONCRETE:7)
Block(-8,21,4,CONCRETE:7)
Block(-8,21,5,CONCRETE:7)
Block(-8,21,6,CONCRETE:7)
Block(-8,21,7,CONCRETE:7)
Block(-8,21,8,CONCRETE:7)
Block(-8,22,-7,CONCRETE:7)
Block(-8,22,-6,CONCRETE:7)
Block(-8,22,-5,OBSIDIAN:0)
Block(-8,22,-4,OBSIDIAN:0)
Block(-8,22,-3,OBSIDIAN:0)
Block(-8,22,-2,CONCRETE:7)
Block(-8,22,-1,CONCRETE:7)
Block(-8,22,0,CONCRETE:7)
Block(-8,22,1,CONCRETE:7)
Block(-8,22,2,CONCRETE:7)
Block(-8,22,3,CONCRETE:7)
Block(-8,22,4,CONCRETE:7)
Block(-8,22,5,CONCRETE:7)
Block(-8,22,6,CONCRETE:7)
Block(-8,22,7,CONCRETE:7)
Block(-8,22,8,CONCRETE:7)
Block(-8,23,-7,CONCRETE:7)
Block(-8,23,-6,CONCRETE:7)
Block(-8,23,-5,OBSIDIAN:0)
Block(-8,23,-4,OBSIDIAN:0)
Block(-8,23,-3,OBSIDIAN:0)
Block(-8,23,-2,CONCRETE:7)
Block(-8,23,-1,CONCRETE:7)
Block(-8,23,0,CONCRETE:7)
Block(-8,23,1,CONCRETE:7)
Block(-8,23,2,CONCRETE:7)
Block(-8,23,3,CONCRETE:7)
Block(-8,23,4,CONCRETE:7)
Block(-8,23,5,CONCRETE:7)
Block(-8,23,6,CONCRETE:7)
Block(-8,23,7,CONCRETE:7)
Block(-8,23,8,CONCRETE:7)
Block(-8,24,-7,CONCRETE:7)
Block(-8,24,-6,CONCRETE:7)
Block(-8,24,-5,CONCRETE:7)
Block(-8,24,-4,CONCRETE:7)
Block(-8,24,-3,OBSIDIAN:0)
Block(-8,24,-2,OBSIDIAN:0)
Block(-8,24,-1,OBSIDIAN:0)
Block(-8,24,0,CONCRETE:7)
Block(-8,24,1,CONCRETE:7)
Block(-8,24,2,CONCRETE:7)
Block(-8,24,3,CONCRETE:7)
Block(-8,24,4,CONCRETE:7)
Block(-8,24,5,CONCRETE:7)
Block(-8,24,6,CONCRETE:7)
Block(-8,24,7,CONCRETE:7)
Block(-8,24,8,CONCRETE:7)
Block(-8,25,-7,CONCRETE:7)
Block(-8,25,-6,CONCRETE:7)
Block(-8,25,-5,CONCRETE:7)
Block(-8,25,-4,CONCRETE:7)
Block(-8,25,-3,OBSIDIAN:0)
Block(-8,25,-2,OBSIDIAN:0)
Block(-8,25,-1,OBSIDIAN:0)
Block(-8,25,0,CONCRETE:7)
Block(-8,25,1,CONCRETE:7)
Block(-8,25,2,CONCRETE:7)
Block(-8,25,3,CONCRETE:7)
Block(-8,25,4,CONCRETE:7)
Block(-8,25,5,CONCRETE:7)
Block(-8,25,6,CONCRETE:7)
Block(-8,25,7,CONCRETE:7)
Block(-8,25,8,CONCRETE:7)
Block(-8,26,-7,CONCRETE:7)
Block(-8,26,-6,CONCRETE:7)
Block(-8,26,-5,CONCRETE:7)
Block(-8,26,-4,CONCRETE:7)
Block(-8,26,-3,OBSIDIAN:0)
Block(-8,26,-2,OBSIDIAN:0)
Block(-8,26,-1,OBSIDIAN:0)
Block(-8,26,0,CONCRETE:7)
Block(-8,26,1,CONCRETE:7)
Block(-8,26,2,CONCRETE:7)
Block(-8,26,3,CONCRETE:7)
Block(-8,26,4,CONCRETE:7)
Block(-8,26,5,CONCRETE:7)
Block(-8,26,6,CONCRETE:7)
Block(-8,26,7,CONCRETE:7)
Block(-8,26,8,CONCRETE:7)
Block(-8,27,-7,CONCRETE:7)
Block(-8,27,-6,CONCRETE:7)
Block(-8,27,-5,CONCRETE:7)
Block(-8,27,-4,CONCRETE:7)
Block(-8,27,-3,OBSIDIAN:0)
Block(-8,27,-2,OBSIDIAN:0)
Block(-8,27,-1,OBSIDIAN:0)
Block(-8,27,0,OBSIDIAN:0)
Block(-8,27,1,OBSIDIAN:0)
Block(-8,27,2,OBSIDIAN:0)
Block(-8,27,3,CONCRETE:7)
Block(-8,27,4,CONCRETE:7)
Block(-8,27,5,CONCRETE:7)
Block(-8,27,6,CONCRETE:7)
Block(-8,27,7,CONCRETE:7)
Block(-8,27,8,CONCRETE:7)
Block(-8,28,-7,CONCRETE:7)
Block(-8,28,-6,CONCRETE:7)
Block(-8,28,-5,CONCRETE:7)
Block(-8,28,-4,CONCRETE:7)
Block(-8,28,-3,CONCRETE:7)
Block(-8,28,-2,CONCRETE:7)
Block(-8,28,-1,OBSIDIAN:0)
Block(-8,28,0,OBSIDIAN:0)
Block(-8,28,1,OBSIDIAN:0)
Block(-8,28,2,OBSIDIAN:0)
Block(-8,28,3,OBSIDIAN:0)
Block(-8,28,4,CONCRETE:7)
Block(-8,28,5,CONCRETE:7)
Block(-8,28,6,CONCRETE:7)
Block(-8,28,7,CONCRETE:7)
Block(-8,28,8,CONCRETE:7)
Block(-8,29,-7,CONCRETE:7)
Block(-8,29,-6,CONCRETE:7)
Block(-8,29,-5,CONCRETE:7)
Block(-8,29,-4,CONCRETE:7)
Block(-8,29,-3,CONCRETE:7)
Block(-8,29,-2,CONCRETE:7)
Block(-8,29,-1,OBSIDIAN:0)
Block(-8,29,0,OBSIDIAN:0)
Block(-8,29,1,OBSIDIAN:0)
Block(-8,29,2,OBSIDIAN:0)
Block(-8,29,3,OBSIDIAN:0)
Block(-8,29,4,OBSIDIAN:0)
Block(-8,29,5,OBSIDIAN:0)
Block(-8,29,6,CONCRETE:7)
Block(-8,29,7,CONCRETE:7)
Block(-8,29,8,CONCRETE:7)
Block(-8,30,-7,CONCRETE:7)
Block(-8,30,-6,CONCRETE:7)
Block(-8,30,-5,CONCRETE:7)
Block(-8,30,-4,CONCRETE:7)
Block(-8,30,-3,CONCRETE:7)
Block(-8,30,-2,CONCRETE:7)
Block(-8,30,-1,OBSIDIAN:0)
Block(-8,30,0,OBSIDIAN:0)
Block(-8,30,1,OBSIDIAN:0)
Block(-8,30,2,OBSIDIAN:0)
Block(-8,30,3,OBSIDIAN:0)
Block(-8,30,4,OBSIDIAN:0)
Block(-8,30,5,OBSIDIAN:0)
Block(-8,30,6,OBSIDIAN:0)
Block(-8,30,7,CONCRETE:7)
Block(-8,30,8,CONCRETE:7)
Block(-8,32,-7,PACKED_ICE:0)
Block(-8,33,-7,PACKED_ICE:0)
Block(-8,33,-6,PACKED_ICE:0)
Block(-8,33,-5,PACKED_ICE:0)
Block(-8,34,-7,PACKED_ICE:0)
Block(-8,34,-6,PACKED_ICE:0)
Block(-8,34,-5,PACKED_ICE:0)
Block(-8,34,-4,PACKED_ICE:0)
Block(-8,35,-7,PACKED_ICE:0)
Block(-8,35,-6,PACKED_ICE:0)
Block(-8,35,-5,PACKED_ICE:0)
Block(-8,35,-4,PACKED_ICE:0)
Block(-8,35,-3,PACKED_ICE:0)
Block(-8,35,-2,PACKED_ICE:0)
Block(-8,36,-7,PACKED_ICE:0)
Block(-8,36,-6,PACKED_ICE:0)
Block(-8,36,-5,PACKED_ICE:0)
Block(-8,36,-4,PACKED_ICE:0)
Block(-8,36,-3,PACKED_ICE:0)
Block(-8,36,-2,PACKED_ICE:0)
Block(-8,37,-7,PACKED_ICE:0)
Block(-8,37,-6,PACKED_ICE:0)
Block(-8,37,-5,PACKED_ICE:0)
Block(-8,37,-4,PACKED_ICE:0)
Block(-8,37,-3,PACKED_ICE:0)
Block(-8,37,-2,PACKED_ICE:0)
Block(-8,37,-1,PACKED_ICE:0)
Block(-8,38,-7,PACKED_ICE:0)
Block(-8,38,-6,PACKED_ICE:0)
Block(-8,38,-5,PACKED_ICE:0)
Block(-8,38,-4,PACKED_ICE:0)
Block(-8,38,-3,PACKED_ICE:0)
Block(-8,38,-2,PACKED_ICE:0)
Block(-8,38,-1,PACKED_ICE:0)
Block(-8,39,-7,PACKED_ICE:0)
Block(-8,39,-6,PACKED_ICE:0)
Block(-8,39,-5,PACKED_ICE:0)
Block(-8,39,-4,PACKED_ICE:0)
Block(-8,39,-3,PACKED_ICE:0)
Block(-8,39,-2,PACKED_ICE:0)
Block(-8,39,-1,PACKED_ICE:0)
Block(-8,40,-7,PACKED_ICE:0)
Block(-8,40,-6,PACKED_ICE:0)
Block(-8,40,-5,PACKED_ICE:0)
Block(-8,40,-4,PACKED_ICE:0)
Block(-8,40,-3,PACKED_ICE:0)
Block(-8,40,-2,PACKED_ICE:0)
Block(-8,40,-1,PACKED_ICE:0)
Block(-8,40,0,PACKED_ICE:0)
Block(-8,41,-7,PACKED_ICE:0)
Block(-8,41,-6,PACKED_ICE:0)
Block(-8,41,-5,PACKED_ICE:0)
Block(-8,41,-4,PACKED_ICE:0)
Block(-8,41,-3,PACKED_ICE:0)
Block(-8,41,-2,PACKED_ICE:0)
Block(-8,41,-1,PACKED_ICE:0)
Block(-8,41,0,PACKED_ICE:0)
Block(-8,42,-6,PACKED_ICE:0)
Block(-8,42,-5,PACKED_ICE:0)
Block(-8,42,-4,PACKED_ICE:0)
Block(-8,42,-3,PACKED_ICE:0)
Block(-8,42,-2,PACKED_ICE:0)
Block(-8,42,-1,PACKED_ICE:0)
Block(-8,42,0,PACKED_ICE:0)
Block(-7,0,-7,CONCRETE:7)
Block(-7,0,-6,CONCRETE:7)
Block(-7,0,-5,CONCRETE:7)
Block(-7,0,-4,CONCRETE:7)
Block(-7,0,-3,CONCRETE:7)
Block(-7,0,-2,CONCRETE:7)
Block(-7,0,-1,CONCRETE:7)
Block(-7,0,0,CONCRETE:7)
Block(-7,0,1,CONCRETE:7)
Block(-7,0,2,CONCRETE:7)
Block(-7,0,3,CONCRETE:7)
Block(-7,0,4,CONCRETE:7)
Block(-7,0,5,CONCRETE:7)
Block(-7,0,6,CONCRETE:7)
Block(-7,0,7,CONCRETE:7)
Block(-7,0,8,CONCRETE:7)
Block(-7,1,-7,CONCRETE:7)
Block(-7,1,-6,CONCRETE:7)
Block(-7,1,-5,CONCRETE:7)
Block(-7,1,-4,CONCRETE:7)
Block(-7,1,-3,CONCRETE:7)
Block(-7,1,-2,CONCRETE:7)
Block(-7,1,-1,CONCRETE:7)
Block(-7,1,0,CONCRETE:7)
Block(-7,1,1,CONCRETE:7)
Block(-7,1,2,CONCRETE:7)
Block(-7,1,3,CONCRETE:7)
Block(-7,1,4,CONCRETE:7)
Block(-7,1,5,CONCRETE:7)
Block(-7,1,6,CONCRETE:7)
Block(-7,1,7,CONCRETE:7)
Block(-7,1,8,CONCRETE:7)
Block(-7,2,-7,CONCRETE:7)
Block(-7,2,-6,CONCRETE:7)
Block(-7,2,-5,CONCRETE:7)
Block(-7,2,-4,CONCRETE:7)
Block(-7,2,-3,CONCRETE:7)
Block(-7,2,-2,CONCRETE:7)
Block(-7,2,-1,CONCRETE:7)
Block(-7,2,0,CONCRETE:7)
Block(-7,2,1,CONCRETE:7)
Block(-7,2,2,CONCRETE:7)
Block(-7,2,3,CONCRETE:7)
Block(-7,2,4,CONCRETE:7)
Block(-7,2,5,CONCRETE:7)
Block(-7,2,6,CONCRETE:7)
Block(-7,2,7,CONCRETE:7)
Block(-7,2,8,CONCRETE:7)
Block(-7,3,-7,CONCRETE:7)
Block(-7,3,-6,CONCRETE:7)
Block(-7,3,-5,CONCRETE:7)
Block(-7,3,-4,CONCRETE:7)
Block(-7,3,-3,CONCRETE:7)
Block(-7,3,-2,CONCRETE:7)
Block(-7,3,-1,CONCRETE:7)
Block(-7,3,0,CONCRETE:7)
Block(-7,3,1,CONCRETE:7)
Block(-7,3,2,CONCRETE:7)
Block(-7,3,3,CONCRETE:7)
Block(-7,3,4,CONCRETE:7)
Block(-7,3,5,CONCRETE:7)
Block(-7,3,6,CONCRETE:7)
Block(-7,3,7,CONCRETE:7)
Block(-7,3,8,CONCRETE:7)
Block(-7,4,-7,CONCRETE:7)
Block(-7,4,-6,CONCRETE:7)
Block(-7,4,-5,CONCRETE:7)
Block(-7,4,-4,CONCRETE:7)
Block(-7,4,-3,CONCRETE:7)
Block(-7,4,-2,CONCRETE:7)
Block(-7,4,-1,CONCRETE:7)
Block(-7,4,0,CONCRETE:7)
Block(-7,4,1,CONCRETE:7)
Block(-7,4,2,CONCRETE:7)
Block(-7,4,3,CONCRETE:7)
Block(-7,4,4,CONCRETE:7)
Block(-7,4,5,CONCRETE:7)
Block(-7,4,6,CONCRETE:7)
Block(-7,4,7,CONCRETE:7)
Block(-7,4,8,CONCRETE:7)
Block(-7,5,-7,CONCRETE:7)
Block(-7,5,-6,CONCRETE:7)
Block(-7,5,-5,CONCRETE:7)
Block(-7,5,-4,CONCRETE:7)
Block(-7,5,-3,CONCRETE:7)
Block(-7,5,-2,CONCRETE:7)
Block(-7,5,-1,CONCRETE:7)
Block(-7,5,0,CONCRETE:7)
Block(-7,5,1,CONCRETE:7)
Block(-7,5,2,CONCRETE:7)
Block(-7,5,3,CONCRETE:7)
Block(-7,5,4,CONCRETE:7)
Block(-7,5,5,CONCRETE:7)
Block(-7,5,6,CONCRETE:7)
Block(-7,5,7,CONCRETE:7)
Block(-7,5,8,CONCRETE:7)
Block(-7,6,-7,CONCRETE:7)
Block(-7,6,-6,CONCRETE:7)
Block(-7,6,-5,CONCRETE:7)
Block(-7,6,-4,CONCRETE:7)
Block(-7,6,-3,CONCRETE:7)
Block(-7,6,-2,CONCRETE:7)
Block(-7,6,-1,CONCRETE:7)
Block(-7,6,0,CONCRETE:7)
Block(-7,6,1,CONCRETE:7)
Block(-7,6,2,CONCRETE:7)
Block(-7,6,3,CONCRETE:7)
Block(-7,6,4,CONCRETE:7)
Block(-7,6,5,CONCRETE:7)
Block(-7,6,6,CONCRETE:7)
Block(-7,6,7,CONCRETE:7)
Block(-7,6,8,CONCRETE:7)
Block(-7,7,-7,CONCRETE:7)
Block(-7,7,-6,CONCRETE:7)
Block(-7,7,-5,CONCRETE:7)
Block(-7,7,-4,CONCRETE:7)
Block(-7,7,-3,CONCRETE:7)
Block(-7,7,-2,CONCRETE:7)
Block(-7,7,-1,CONCRETE:7)
Block(-7,7,0,CONCRETE:7)
Block(-7,7,1,CONCRETE:7)
Block(-7,7,2,CONCRETE:7)
Block(-7,7,3,CONCRETE:7)
Block(-7,7,4,CONCRETE:7)
Block(-7,7,5,CONCRETE:7)
Block(-7,7,6,CONCRETE:7)
Block(-7,7,7,CONCRETE:7)
Block(-7,7,8,CONCRETE:7)
Block(-7,8,-7,CONCRETE:7)
Block(-7,8,-6,CONCRETE:7)
Block(-7,8,-5,CONCRETE:7)
Block(-7,8,-4,CONCRETE:7)
Block(-7,8,-3,CONCRETE:7)
Block(-7,8,-2,CONCRETE:7)
Block(-7,8,-1,CONCRETE:7)
Block(-7,8,0,CONCRETE:7)
Block(-7,8,1,CONCRETE:7)
Block(-7,8,2,CONCRETE:7)
Block(-7,8,3,CONCRETE:7)
Block(-7,8,4,CONCRETE:7)
Block(-7,8,5,CONCRETE:7)
Block(-7,8,6,CONCRETE:7)
Block(-7,8,7,CONCRETE:7)
Block(-7,8,8,CONCRETE:7)
Block(-7,9,-7,CONCRETE:7)
Block(-7,9,-6,CONCRETE:7)
Block(-7,9,-5,CONCRETE:7)
Block(-7,9,-4,CONCRETE:7)
Block(-7,9,-3,CONCRETE:7)
Block(-7,9,-2,CONCRETE:7)
Block(-7,9,-1,CONCRETE:7)
Block(-7,9,0,CONCRETE:7)
Block(-7,9,1,CONCRETE:7)
Block(-7,9,2,CONCRETE:7)
Block(-7,9,3,CONCRETE:7)
Block(-7,9,4,CONCRETE:7)
Block(-7,9,5,CONCRETE:7)
Block(-7,9,6,CONCRETE:7)
Block(-7,9,7,CONCRETE:7)
Block(-7,9,8,CONCRETE:7)
Block(-7,10,-7,CONCRETE:7)
Block(-7,10,-6,CONCRETE:7)
Block(-7,10,-5,CONCRETE:7)
Block(-7,10,-4,CONCRETE:7)
Block(-7,10,-3,CONCRETE:7)
Block(-7,10,-2,CONCRETE:7)
Block(-7,10,-1,CONCRETE:7)
Block(-7,10,0,CONCRETE:7)
Block(-7,10,1,CONCRETE:7)
Block(-7,10,2,CONCRETE:7)
Block(-7,10,3,CONCRETE:7)
Block(-7,10,4,CONCRETE:7)
Block(-7,10,5,CONCRETE:7)
Block(-7,10,6,CONCRETE:7)
Block(-7,10,7,CONCRETE:7)
Block(-7,10,8,CONCRETE:7)
Block(-7,11,-7,CONCRETE:7)
Block(-7,11,-6,CONCRETE:7)
Block(-7,11,-5,CONCRETE:7)
Block(-7,11,-4,CONCRETE:7)
Block(-7,11,-3,CONCRETE:7)
Block(-7,11,-2,CONCRETE:7)
Block(-7,11,-1,CONCRETE:7)
Block(-7,11,0,CONCRETE:7)
Block(-7,11,1,CONCRETE:7)
Block(-7,11,2,CONCRETE:7)
Block(-7,11,3,CONCRETE:7)
Block(-7,11,4,CONCRETE:7)
Block(-7,11,5,CONCRETE:7)
Block(-7,11,6,CONCRETE:7)
Block(-7,11,7,CONCRETE:7)
Block(-7,11,8,CONCRETE:7)
Block(-7,12,-7,OBSIDIAN:0)
Block(-7,12,-6,CONCRETE:7)
Block(-7,12,-5,CONCRETE:7)
Block(-7,12,-4,CONCRETE:7)
Block(-7,12,-3,CONCRETE:7)
Block(-7,12,-2,CONCRETE:7)
Block(-7,12,-1,CONCRETE:7)
Block(-7,12,0,CONCRETE:7)
Block(-7,12,1,CONCRETE:7)
Block(-7,12,2,CONCRETE:7)
Block(-7,12,3,CONCRETE:7)
Block(-7,12,4,CONCRETE:7)
Block(-7,12,5,CONCRETE:7)
Block(-7,12,6,CONCRETE:7)
Block(-7,12,7,CONCRETE:7)
Block(-7,12,8,CONCRETE:7)
Block(-7,13,-7,OBSIDIAN:0)
Block(-7,13,-6,CONCRETE:7)
Block(-7,13,-5,CONCRETE:7)
Block(-7,13,-4,CONCRETE:7)
Block(-7,13,-3,CONCRETE:7)
Block(-7,13,-2,CONCRETE:7)
Block(-7,13,-1,CONCRETE:7)
Block(-7,13,0,CONCRETE:7)
Block(-7,13,1,CONCRETE:7)
Block(-7,13,2,CONCRETE:7)
Block(-7,13,3,CONCRETE:7)
Block(-7,13,4,CONCRETE:7)
Block(-7,13,5,CONCRETE:7)
Block(-7,13,6,CONCRETE:7)
Block(-7,13,7,CONCRETE:7)
Block(-7,13,8,CONCRETE:7)
Block(-7,14,-7,OBSIDIAN:0)
Block(-7,14,-6,CONCRETE:7)
Block(-7,14,-5,CONCRETE:7)
Block(-7,14,-4,CONCRETE:7)
Block(-7,14,-3,CONCRETE:7)
Block(-7,14,-2,CONCRETE:7)
Block(-7,14,-1,CONCRETE:7)
Block(-7,14,0,CONCRETE:7)
Block(-7,14,1,CONCRETE:7)
Block(-7,14,2,CONCRETE:7)
Block(-7,14,3,CONCRETE:7)
Block(-7,14,4,CONCRETE:7)
Block(-7,14,5,CONCRETE:7)
Block(-7,14,6,CONCRETE:7)
Block(-7,14,7,CONCRETE:7)
Block(-7,14,8,CONCRETE:7)
Block(-7,15,-7,OBSIDIAN:0)
Block(-7,15,-6,CONCRETE:7)
Block(-7,15,-5,CONCRETE:7)
Block(-7,15,-4,CONCRETE:7)
Block(-7,15,-3,CONCRETE:7)
Block(-7,15,-2,CONCRETE:7)
Block(-7,15,-1,CONCRETE:7)
Block(-7,15,0,CONCRETE:7)
Block(-7,15,1,CONCRETE:7)
Block(-7,15,2,CONCRETE:7)
Block(-7,15,3,CONCRETE:7)
Block(-7,15,4,CONCRETE:7)
Block(-7,15,5,CONCRETE:7)
Block(-7,15,6,CONCRETE:7)
Block(-7,15,7,CONCRETE:7)
Block(-7,15,8,CONCRETE:7)
Block(-7,16,-7,OBSIDIAN:0)
Block(-7,16,-6,CONCRETE:7)
Block(-7,16,-5,CONCRETE:7)
Block(-7,16,-4,CONCRETE:7)
Block(-7,16,-3,CONCRETE:7)
Block(-7,16,-2,CONCRETE:7)
Block(-7,16,-1,CONCRETE:7)
Block(-7,16,0,CONCRETE:7)
Block(-7,16,1,CONCRETE:7)
Block(-7,16,2,CONCRETE:7)
Block(-7,16,3,CONCRETE:7)
Block(-7,16,4,CONCRETE:7)
Block(-7,16,5,CONCRETE:7)
Block(-7,16,6,CONCRETE:7)
Block(-7,16,7,CONCRETE:7)
Block(-7,16,8,CONCRETE:7)
Block(-7,17,-7,OBSIDIAN:0)
Block(-7,17,-6,CONCRETE:7)
Block(-7,17,-5,CONCRETE:7)
Block(-7,17,-4,CONCRETE:7)
Block(-7,17,-3,CONCRETE:7)
Block(-7,17,-2,CONCRETE:7)
Block(-7,17,-1,CONCRETE:7)
Block(-7,17,0,CONCRETE:7)
Block(-7,17,1,CONCRETE:7)
Block(-7,17,2,CONCRETE:7)
Block(-7,17,3,CONCRETE:7)
Block(-7,17,4,CONCRETE:7)
Block(-7,17,5,CONCRETE:7)
Block(-7,17,6,CONCRETE:7)
Block(-7,17,7,CONCRETE:7)
Block(-7,17,8,CONCRETE:7)
Block(-7,18,-7,CONCRETE:7)
Block(-7,18,-6,CONCRETE:7)
Block(-7,18,-5,CONCRETE:7)
Block(-7,18,-4,CONCRETE:7)
Block(-7,18,-3,CONCRETE:7)
Block(-7,18,-2,CONCRETE:7)
Block(-7,18,-1,CONCRETE:7)
Block(-7,18,0,CONCRETE:7)
Block(-7,18,1,CONCRETE:7)
Block(-7,18,2,CONCRETE:7)
Block(-7,18,3,CONCRETE:7)
Block(-7,18,4,CONCRETE:7)
Block(-7,18,5,CONCRETE:7)
Block(-7,18,6,CONCRETE:7)
Block(-7,18,7,CONCRETE:7)
Block(-7,18,8,CONCRETE:7)
Block(-7,19,-7,CONCRETE:7)
Block(-7,19,-6,CONCRETE:7)
Block(-7,19,-5,CONCRETE:7)
Block(-7,19,-4,CONCRETE:7)
Block(-7,19,-3,CONCRETE:7)
Block(-7,19,-2,CONCRETE:7)
Block(-7,19,-1,CONCRETE:7)
Block(-7,19,0,CONCRETE:7)
Block(-7,19,1,CONCRETE:7)
Block(-7,19,2,CONCRETE:7)
Block(-7,19,3,CONCRETE:7)
Block(-7,19,4,CONCRETE:7)
Block(-7,19,5,CONCRETE:7)
Block(-7,19,6,CONCRETE:7)
Block(-7,19,7,CONCRETE:7)
Block(-7,19,8,CONCRETE:7)
Block(-7,20,-7,CONCRETE:7)
Block(-7,20,-6,CONCRETE:7)
Block(-7,20,-5,CONCRETE:7)
Block(-7,20,-4,CONCRETE:7)
Block(-7,20,-3,CONCRETE:7)
Block(-7,20,-2,CONCRETE:7)
Block(-7,20,-1,CONCRETE:7)
Block(-7,20,0,CONCRETE:7)
Block(-7,20,1,CONCRETE:7)
Block(-7,20,2,CONCRETE:7)
Block(-7,20,3,CONCRETE:7)
Block(-7,20,4,CONCRETE:7)
Block(-7,20,5,CONCRETE:7)
Block(-7,20,6,CONCRETE:7)
Block(-7,20,7,CONCRETE:7)
Block(-7,20,8,CONCRETE:7)
Block(-7,21,-7,CONCRETE:7)
Block(-7,21,-6,CONCRETE:7)
Block(-7,21,-5,CONCRETE:7)
Block(-7,21,-4,CONCRETE:7)
Block(-7,21,-3,CONCRETE:7)
Block(-7,21,-2,CONCRETE:7)
Block(-7,21,-1,CONCRETE:7)
Block(-7,21,0,CONCRETE:7)
Block(-7,21,1,CONCRETE:7)
Block(-7,21,2,CONCRETE:7)
Block(-7,21,3,CONCRETE:7)
Block(-7,21,4,CONCRETE:7)
Block(-7,21,5,CONCRETE:7)
Block(-7,21,6,CONCRETE:7)
Block(-7,21,7,CONCRETE:7)
Block(-7,21,8,CONCRETE:7)
Block(-7,22,-7,CONCRETE:7)
Block(-7,22,-6,CONCRETE:7)
Block(-7,22,-5,CONCRETE:7)
Block(-7,22,-4,CONCRETE:7)
Block(-7,22,-3,CONCRETE:7)
Block(-7,22,-2,CONCRETE:7)
Block(-7,22,-1,CONCRETE:7)
Block(-7,22,0,CONCRETE:7)
Block(-7,22,1,CONCRETE:7)
Block(-7,22,2,CONCRETE:7)
Block(-7,22,3,CONCRETE:7)
Block(-7,22,4,CONCRETE:7)
Block(-7,22,5,CONCRETE:7)
Block(-7,22,6,CONCRETE:7)
Block(-7,22,7,CONCRETE:7)
Block(-7,22,8,CONCRETE:7)
Block(-7,23,-7,CONCRETE:7)
Block(-7,23,-6,CONCRETE:7)
Block(-7,23,-5,CONCRETE:7)
Block(-7,23,-4,CONCRETE:7)
Block(-7,23,-3,CONCRETE:7)
Block(-7,23,-2,CONCRETE:7)
Block(-7,23,-1,CONCRETE:7)
Block(-7,23,0,CONCRETE:7)
Block(-7,23,1,CONCRETE:7)
Block(-7,23,2,CONCRETE:7)
Block(-7,23,3,CONCRETE:7)
Block(-7,23,4,CONCRETE:7)
Block(-7,23,5,CONCRETE:7)
Block(-7,23,6,CONCRETE:7)
Block(-7,23,7,CONCRETE:7)
Block(-7,23,8,CONCRETE:7)
Block(-7,24,-7,CONCRETE:7)
Block(-7,24,-6,CONCRETE:7)
Block(-7,24,-5,CONCRETE:7)
Block(-7,24,-4,CONCRETE:7)
Block(-7,24,-3,CONCRETE:7)
Block(-7,24,-2,CONCRETE:7)
Block(-7,24,-1,CONCRETE:7)
Block(-7,24,0,CONCRETE:7)
Block(-7,24,1,CONCRETE:7)
Block(-7,24,2,CONCRETE:7)
Block(-7,24,3,CONCRETE:7)
Block(-7,24,4,CONCRETE:7)
Block(-7,24,5,CONCRETE:7)
Block(-7,24,6,CONCRETE:7)
Block(-7,24,7,CONCRETE:7)
Block(-7,24,8,CONCRETE:7)
Block(-7,25,-7,CONCRETE:7)
Block(-7,25,-6,CONCRETE:7)
Block(-7,25,-5,CONCRETE:7)
Block(-7,25,-4,CONCRETE:7)
Block(-7,25,-3,CONCRETE:7)
Block(-7,25,-2,CONCRETE:7)
Block(-7,25,-1,CONCRETE:7)
Block(-7,25,0,CONCRETE:7)
Block(-7,25,1,CONCRETE:7)
Block(-7,25,2,CONCRETE:7)
Block(-7,25,3,CONCRETE:7)
Block(-7,25,4,CONCRETE:7)
Block(-7,25,5,CONCRETE:7)
Block(-7,25,6,CONCRETE:7)
Block(-7,25,7,CONCRETE:7)
Block(-7,25,8,CONCRETE:7)
Block(-7,26,-7,CONCRETE:7)
Block(-7,26,-6,CONCRETE:7)
Block(-7,26,-5,CONCRETE:7)
Block(-7,26,-4,CONCRETE:7)
Block(-7,26,-3,CONCRETE:7)
Block(-7,26,-2,CONCRETE:7)
Block(-7,26,-1,CONCRETE:7)
Block(-7,26,0,CONCRETE:7)
Block(-7,26,1,CONCRETE:7)
Block(-7,26,2,CONCRETE:7)
Block(-7,26,3,CONCRETE:7)
Block(-7,26,4,CONCRETE:7)
Block(-7,26,5,CONCRETE:7)
Block(-7,26,6,CONCRETE:7)
Block(-7,26,7,CONCRETE:7)
Block(-7,26,8,CONCRETE:7)
Block(-7,27,-7,CONCRETE:7)
Block(-7,27,-6,CONCRETE:7)
Block(-7,27,-5,CONCRETE:7)
Block(-7,27,-4,CONCRETE:7)
Block(-7,27,-3,CONCRETE:7)
Block(-7,27,-2,CONCRETE:7)
Block(-7,27,-1,CONCRETE:7)
Block(-7,27,0,CONCRETE:7)
Block(-7,27,1,CONCRETE:7)
Block(-7,27,2,CONCRETE:7)
Block(-7,27,3,CONCRETE:7)
Block(-7,27,4,CONCRETE:7)
Block(-7,27,5,CONCRETE:7)
Block(-7,27,6,CONCRETE:7)
Block(-7,27,7,CONCRETE:7)
Block(-7,27,8,CONCRETE:7)
Block(-7,28,-7,CONCRETE:7)
Block(-7,28,-6,CONCRETE:7)
Block(-7,28,-5,CONCRETE:7)
Block(-7,28,-4,CONCRETE:7)
Block(-7,28,-3,CONCRETE:7)
Block(-7,28,-2,CONCRETE:7)
Block(-7,28,-1,CONCRETE:7)
Block(-7,28,0,OBSIDIAN:0)
Block(-7,28,1,OBSIDIAN:0)
Block(-7,28,2,OBSIDIAN:0)
Block(-7,28,3,OBSIDIAN:0)
Block(-7,28,4,CONCRETE:7)
Block(-7,28,5,CONCRETE:7)
Block(-7,28,6,CONCRETE:7)
Block(-7,28,7,CONCRETE:7)
Block(-7,28,8,CONCRETE:7)
Block(-7,29,-7,CONCRETE:7)
Block(-7,29,-6,CONCRETE:7)
Block(-7,29,-5,CONCRETE:7)
Block(-7,29,-4,CONCRETE:7)
Block(-7,29,-3,CONCRETE:7)
Block(-7,29,-2,CONCRETE:7)
Block(-7,29,-1,CONCRETE:7)
Block(-7,29,0,OBSIDIAN:0)
Block(-7,29,1,OBSIDIAN:0)
Block(-7,29,2,OBSIDIAN:0)
Block(-7,29,3,OBSIDIAN:0)
Block(-7,29,4,OBSIDIAN:0)
Block(-7,29,5,OBSIDIAN:0)
Block(-7,29,6,CONCRETE:7)
Block(-7,29,7,CONCRETE:7)
Block(-7,29,8,CONCRETE:7)
Block(-7,30,-7,CONCRETE:7)
Block(-7,30,-6,CONCRETE:7)
Block(-7,30,-5,CONCRETE:7)
Block(-7,30,-4,CONCRETE:7)
Block(-7,30,-3,CONCRETE:7)
Block(-7,30,-2,CONCRETE:7)
Block(-7,30,-1,CONCRETE:7)
Block(-7,30,0,OBSIDIAN:0)
Block(-7,30,1,OBSIDIAN:0)
Block(-7,30,2,OBSIDIAN:0)
Block(-7,30,3,OBSIDIAN:0)
Block(-7,30,4,OBSIDIAN:0)
Block(-7,30,5,OBSIDIAN:0)
Block(-7,30,6,OBSIDIAN:0)
Block(-7,30,7,CONCRETE:7)
Block(-7,30,8,CONCRETE:7)
Block(-7,31,-7,SNOW:0)
Block(-7,31,-6,CONCRETE:7)
Block(-7,31,-5,CONCRETE:7)
Block(-7,31,-4,CONCRETE:7)
Block(-7,31,-3,CONCRETE:7)
Block(-7,31,-2,CONCRETE:7)
Block(-7,31,-1,CONCRETE:7)
Block(-7,31,0,OBSIDIAN:0)
Block(-7,31,1,OBSIDIAN:0)
Block(-7,31,2,OBSIDIAN:0)
Block(-7,31,3,OBSIDIAN:0)
Block(-7,31,4,OBSIDIAN:0)
Block(-7,31,5,OBSIDIAN:0)
Block(-7,31,6,OBSIDIAN:0)
Block(-7,31,7,OBSIDIAN:0)
Block(-7,31,8,CONCRETE:7)
Block(-7,32,-6,SNOW:2)
Block(-7,33,-7,PACKED_ICE:0)
Block(-7,34,-7,PACKED_ICE:0)
Block(-7,34,-6,PACKED_ICE:0)
Block(-7,34,-5,PACKED_ICE:0)
Block(-7,35,-7,PACKED_ICE:0)
Block(-7,35,-6,PACKED_ICE:0)
Block(-7,35,-5,PACKED_ICE:0)
Block(-7,35,-4,PACKED_ICE:0)
Block(-7,35,-3,PACKED_ICE:0)
Block(-7,36,-7,PACKED_ICE:0)
Block(-7,36,-6,PACKED_ICE:0)
Block(-7,36,-5,PACKED_ICE:0)
Block(-7,36,-4,PACKED_ICE:0)
Block(-7,36,-3,PACKED_ICE:0)
Block(-7,36,-2,PACKED_ICE:0)
Block(-7,37,-7,PACKED_ICE:0)
Block(-7,37,-6,PACKED_ICE:0)
Block(-7,37,-5,PACKED_ICE:0)
Block(-7,37,-4,PACKED_ICE:0)
Block(-7,37,-3,PACKED_ICE:0)
Block(-7,37,-2,PACKED_ICE:0)
Block(-7,37,-1,PACKED_ICE:0)
Block(-7,38,-7,PACKED_ICE:0)
Block(-7,38,-6,PACKED_ICE:0)
Block(-7,38,-5,PACKED_ICE:0)
Block(-7,38,-4,PACKED_ICE:0)
Block(-7,38,-3,PACKED_ICE:0)
Block(-7,38,-2,PACKED_ICE:0)
Block(-7,38,-1,PACKED_ICE:0)
Block(-7,39,-7,PACKED_ICE:0)
Block(-7,39,-6,PACKED_ICE:0)
Block(-7,39,-5,PACKED_ICE:0)
Block(-7,39,-4,PACKED_ICE:0)
Block(-7,39,-3,PACKED_ICE:0)
Block(-7,39,-2,PACKED_ICE:0)
Block(-7,39,-1,PACKED_ICE:0)
Block(-7,39,0,PACKED_ICE:0)
Block(-7,40,-7,PACKED_ICE:0)
Block(-7,40,-6,PACKED_ICE:0)
Block(-7,40,-5,PACKED_ICE:0)
Block(-7,40,-4,PACKED_ICE:0)
Block(-7,40,-3,PACKED_ICE:0)
Block(-7,40,-2,PACKED_ICE:0)
Block(-7,40,-1,PACKED_ICE:0)
Block(-7,40,0,PACKED_ICE:0)
Block(-7,41,-7,PACKED_ICE:0)
Block(-7,41,-6,PACKED_ICE:0)
Block(-7,41,-5,PACKED_ICE:0)
Block(-7,41,-4,PACKED_ICE:0)
Block(-7,41,-3,PACKED_ICE:0)
Block(-7,41,-2,PACKED_ICE:0)
Block(-7,41,-1,PACKED_ICE:0)
Block(-7,41,0,PACKED_ICE:0)
Block(-7,42,-6,PACKED_ICE:0)
Block(-7,42,-5,PACKED_ICE:0)
Block(-7,42,-4,PACKED_ICE:0)
Block(-7,42,-3,PACKED_ICE:0)
Block(-7,42,-2,PACKED_ICE:0)
Block(-7,42,-1,PACKED_ICE:0)
Block(-7,42,0,PACKED_ICE:0)
Block(-7,42,1,PACKED_ICE:0)
Block(-7,43,-5,PACKED_ICE:0)
Block(-7,43,-4,PACKED_ICE:0)
Block(-7,43,-3,PACKED_ICE:0)
Block(-7,43,-2,PACKED_ICE:0)
Block(-7,43,-1,PACKED_ICE:0)
Block(-7,43,0,PACKED_ICE:0)
Block(-7,43,1,PACKED_ICE:0)
Block(-6,0,-7,CONCRETE:7)
Block(-6,0,-6,CONCRETE:7)
Block(-6,0,-5,CONCRETE:7)
Block(-6,0,-4,CONCRETE:7)
Block(-6,0,-3,CONCRETE:7)
Block(-6,0,-2,CONCRETE:7)
Block(-6,0,-1,CONCRETE:7)
Block(-6,0,0,CONCRETE:7)
Block(-6,0,1,CONCRETE:7)
Block(-6,0,2,CONCRETE:7)
Block(-6,0,3,CONCRETE:7)
Block(-6,0,4,CONCRETE:7)
Block(-6,0,5,CONCRETE:7)
Block(-6,0,6,CONCRETE:7)
Block(-6,0,7,CONCRETE:7)
Block(-6,0,8,CONCRETE:7)
Block(-6,1,-7,CONCRETE:7)
Block(-6,1,-6,CONCRETE:7)
Block(-6,1,-5,STONE)
Block(-6,1,-4,STONE)
Block(-6,1,-3,OBSIDIAN:0)
Block(-6,1,-2,STONE)
Block(-6,1,-1,STONE)
Block(-6,1,0,STONE)
Block(-6,1,1,STONE)
Block(-6,1,2,STONE)
Block(-6,1,3,STONE)
Block(-6,1,4,STONE)
Block(-6,1,5,STONE)
Block(-6,1,6,OBSIDIAN:0)
Block(-6,1,7,OBSIDIAN:0)
Block(-6,1,8,STONE)
Block(-6,2,-7,CONCRETE:7)
Block(-6,2,-6,CONCRETE:7)
Block(-6,2,-5,STONE)
Block(-6,2,-4,STONE)
Block(-6,2,-3,OBSIDIAN:0)
Block(-6,2,-2,OBSIDIAN:0)
Block(-6,2,-1,OBSIDIAN:0)
Block(-6,2,0,OBSIDIAN:0)
Block(-6,2,1,STONE)
Block(-6,2,2,OBSIDIAN:0)
Block(-6,2,3,STONE)
Block(-6,2,4,STONE)
Block(-6,2,5,STONE)
Block(-6,2,6,STONE)
Block(-6,2,7,OBSIDIAN:0)
Block(-6,2,8,STONE)
Block(-6,3,-7,CONCRETE:7)
Block(-6,3,-6,CONCRETE:7)
Block(-6,3,-5,OBSIDIAN:0)
Block(-6,3,-4,STONE)
Block(-6,3,-3,STONE)
Block(-6,3,-2,STONE)
Block(-6,3,-1,STONE)
Block(-6,3,0,STONE)
Block(-6,3,1,STONE)
Block(-6,3,2,STONE)
Block(-6,3,3,STONE)
Block(-6,3,4,STONE)
Block(-6,3,5,STONE)
Block(-6,3,6,STONE)
Block(-6,3,7,OBSIDIAN:0)
Block(-6,3,8,STONE)
Block(-6,4,-7,CONCRETE:7)
Block(-6,4,-6,CONCRETE:7)
Block(-6,4,-5,OBSIDIAN:0)
Block(-6,4,-4,STONE)
Block(-6,4,-3,STONE)
Block(-6,4,-2,OBSIDIAN:0)
Block(-6,4,-1,STONE)
Block(-6,4,0,STONE)
Block(-6,4,1,OBSIDIAN:0)
Block(-6,4,2,STONE)
Block(-6,4,3,STONE)
Block(-6,4,4,STONE)
Block(-6,4,5,OBSIDIAN:0)
Block(-6,4,6,STONE)
Block(-6,4,7,STONE)
Block(-6,4,8,STONE)
Block(-6,5,-7,CONCRETE:7)
Block(-6,5,-6,CONCRETE:7)
Block(-6,5,-5,STONE)
Block(-6,5,-4,STONE)
Block(-6,5,-3,STONE)
Block(-6,5,-2,STONE)
Block(-6,5,-1,STONE)
Block(-6,5,0,STONE)
Block(-6,5,1,STONE)
Block(-6,5,2,STONE)
Block(-6,5,3,STONE)
Block(-6,5,4,STONE)
Block(-6,5,5,STONE)
Block(-6,5,6,STONE)
Block(-6,5,7,STONE)
Block(-6,5,8,STONE)
Block(-6,6,-7,CONCRETE:7)
Block(-6,6,-6,CONCRETE:7)
Block(-6,6,-5,STONE)
Block(-6,6,-4,STONE)
Block(-6,6,-3,STONE)
Block(-6,6,-2,STONE)
Block(-6,6,-1,OBSIDIAN:0)
Block(-6,6,0,STONE)
Block(-6,6,1,STONE)
Block(-6,6,2,STONE)
Block(-6,6,3,STONE)
Block(-6,6,4,OBSIDIAN:0)
Block(-6,6,5,STONE)
Block(-6,6,6,STONE)
Block(-6,6,7,STONE)
Block(-6,6,8,OBSIDIAN:0)
Block(-6,7,-7,CONCRETE:7)
Block(-6,7,-6,CONCRETE:7)
Block(-6,7,-5,STONE)
Block(-6,7,-4,STONE)
Block(-6,7,-3,STONE)
Block(-6,7,-2,OBSIDIAN:0)
Block(-6,7,-1,STONE)
Block(-6,7,0,OBSIDIAN:0)
Block(-6,7,1,OBSIDIAN:0)
Block(-6,7,2,OBSIDIAN:0)
Block(-6,7,3,STONE)
Block(-6,7,4,STONE)
Block(-6,7,5,STONE)
Block(-6,7,6,STONE)
Block(-6,7,7,STONE)
Block(-6,7,8,STONE)
Block(-6,8,-7,CONCRETE:7)
Block(-6,8,-6,CONCRETE:7)
Block(-6,8,-5,OBSIDIAN:0)
Block(-6,8,-4,OBSIDIAN:0)
Block(-6,8,-3,STONE)
Block(-6,8,-2,STONE)
Block(-6,8,-1,OBSIDIAN:0)
Block(-6,8,0,STONE)
Block(-6,8,1,STONE)
Block(-6,8,2,OBSIDIAN:0)
Block(-6,8,3,OBSIDIAN:0)
Block(-6,8,4,STONE)
Block(-6,8,5,OBSIDIAN:0)
Block(-6,8,6,STONE)
Block(-6,8,7,OBSIDIAN:0)
Block(-6,8,8,OBSIDIAN:0)
Block(-6,9,-7,CONCRETE:7)
Block(-6,9,-6,CONCRETE:7)
Block(-6,9,-5,STONE)
Block(-6,9,-4,STONE)
Block(-6,9,-3,STONE)
Block(-6,9,-2,OBSIDIAN:0)
Block(-6,9,-1,STONE)
Block(-6,9,0,STONE)
Block(-6,9,1,STONE)
Block(-6,9,2,STONE)
Block(-6,9,3,STONE)
Block(-6,9,4,OBSIDIAN:0)
Block(-6,9,5,STONE)
Block(-6,9,6,STONE)
Block(-6,9,7,OBSIDIAN:0)
Block(-6,9,8,STONE)
Block(-6,10,-7,CONCRETE:7)
Block(-6,10,-6,CONCRETE:7)
Block(-6,10,-5,STONE)
Block(-6,10,-4,OBSIDIAN:0)
Block(-6,10,-3,OBSIDIAN:0)
Block(-6,10,-2,STONE)
Block(-6,10,-1,STONE)
Block(-6,10,0,STONE)
Block(-6,10,1,STONE)
Block(-6,10,2,STONE)
Block(-6,10,3,STONE)
Block(-6,10,4,OBSIDIAN:0)
Block(-6,10,5,STONE)
Block(-6,10,6,STONE)
Block(-6,10,7,STONE)
Block(-6,10,8,STONE)
Block(-6,11,-7,OBSIDIAN:0)
Block(-6,11,-6,CONCRETE:7)
Block(-6,11,-5,OBSIDIAN:0)
Block(-6,11,-4,STONE)
Block(-6,11,-3,STONE)
Block(-6,11,-2,STONE)
Block(-6,11,-1,STONE)
Block(-6,11,0,STONE)
Block(-6,11,1,STONE)
Block(-6,11,2,STONE)
Block(-6,11,3,STONE)
Block(-6,11,4,STONE)
Block(-6,11,5,STONE)
Block(-6,11,6,STONE)
Block(-6,11,7,STONE)
Block(-6,11,8,OBSIDIAN:0)
Block(-6,12,-7,OBSIDIAN:0)
Block(-6,12,-6,CONCRETE:7)
Block(-6,12,-5,STONE)
Block(-6,12,-4,STONE)
Block(-6,12,-3,STONE)
Block(-6,12,-2,STONE)
Block(-6,12,-1,STONE)
Block(-6,12,0,STONE)
Block(-6,12,1,STONE)
Block(-6,12,2,STONE)
Block(-6,12,3,STONE)
Block(-6,12,4,STONE)
Block(-6,12,5,STONE)
Block(-6,12,6,STONE)
Block(-6,12,7,STONE)
Block(-6,12,8,OBSIDIAN:0)
Block(-6,13,-7,OBSIDIAN:0)
Block(-6,13,-6,CONCRETE:7)
Block(-6,13,-5,STONE)
Block(-6,13,-4,STONE)
Block(-6,13,-3,STONE)
Block(-6,13,-2,STONE)
Block(-6,13,-1,OBSIDIAN:0)
Block(-6,13,0,STONE)
Block(-6,13,1,STONE)
Block(-6,13,2,STONE)
Block(-6,13,3,STONE)
Block(-6,13,4,STONE)
Block(-6,13,5,STONE)
Block(-6,13,6,STONE)
Block(-6,13,7,STONE)
Block(-6,13,8,OBSIDIAN:0)
Block(-6,14,-7,OBSIDIAN:0)
Block(-6,14,-6,CONCRETE:7)
Block(-6,14,-5,OBSIDIAN:0)
Block(-6,14,-4,STONE)
Block(-6,14,-3,STONE)
Block(-6,14,-2,STONE)
Block(-6,14,-1,STONE)
Block(-6,14,0,STONE)
Block(-6,14,1,OBSIDIAN:0)
Block(-6,14,2,STONE)
Block(-6,14,3,OBSIDIAN:0)
Block(-6,14,4,STONE)
Block(-6,14,5,OBSIDIAN:0)
Block(-6,14,6,STONE)
Block(-6,14,7,STONE)
Block(-6,14,8,STONE)
Block(-6,15,-7,OBSIDIAN:0)
Block(-6,15,-6,CONCRETE:7)
Block(-6,15,-5,STONE)
Block(-6,15,-4,STONE)
Block(-6,15,-3,OBSIDIAN:0)
Block(-6,15,-2,STONE)
Block(-6,15,-1,STONE)
Block(-6,15,0,STONE)
Block(-6,15,1,STONE)
Block(-6,15,2,STONE)
Block(-6,15,3,STONE)
Block(-6,15,4,STONE)
Block(-6,15,5,STONE)
Block(-6,15,6,STONE)
Block(-6,15,7,STONE)
Block(-6,15,8,STONE)
Block(-6,16,-7,CONCRETE:7)
Block(-6,16,-6,CONCRETE:7)
Block(-6,16,-5,STONE)
Block(-6,16,-4,STONE)
Block(-6,16,-3,STONE)
Block(-6,16,-2,OBSIDIAN:0)
Block(-6,16,-1,STONE)
Block(-6,16,0,STONE)
Block(-6,16,1,STONE)
Block(-6,16,2,STONE)
Block(-6,16,3,OBSIDIAN:0)
Block(-6,16,4,STONE)
Block(-6,16,5,STONE)
Block(-6,16,6,STONE)
Block(-6,16,7,STONE)
Block(-6,16,8,STONE)
Block(-6,17,-7,CONCRETE:7)
Block(-6,17,-6,CONCRETE:7)
Block(-6,17,-5,STONE)
Block(-6,17,-4,STONE)
Block(-6,17,-3,OBSIDIAN:0)
Block(-6,17,-2,STONE)
Block(-6,17,-1,STONE)
Block(-6,17,0,STONE)
Block(-6,17,1,STONE)
Block(-6,17,2,STONE)
Block(-6,17,3,STONE)
Block(-6,17,4,STONE)
Block(-6,17,5,STONE)
Block(-6,17,6,STONE)
Block(-6,17,7,STONE)
Block(-6,17,8,STONE)
Block(-6,18,-7,CONCRETE:7)
Block(-6,18,-6,CONCRETE:7)
Block(-6,18,-5,OBSIDIAN:0)
Block(-6,18,-4,OBSIDIAN:0)
Block(-6,18,-3,STONE)
Block(-6,18,-2,STONE)
Block(-6,18,-1,OBSIDIAN:0)
Block(-6,18,0,STONE)
Block(-6,18,1,STONE)
Block(-6,18,2,OBSIDIAN:0)
Block(-6,18,3,STONE)
Block(-6,18,4,STONE)
Block(-6,18,5,STONE)
Block(-6,18,6,STONE)
Block(-6,18,7,STONE)
Block(-6,18,8,STONE)
Block(-6,19,-7,CONCRETE:7)
Block(-6,19,-6,CONCRETE:7)
Block(-6,19,-5,STONE)
Block(-6,19,-4,STONE)
Block(-6,19,-3,STONE)
Block(-6,19,-2,STONE)
Block(-6,19,-1,STONE)
Block(-6,19,0,STONE)
Block(-6,19,1,STONE)
Block(-6,19,2,STONE)
Block(-6,19,3,STONE)
Block(-6,19,4,OBSIDIAN:0)
Block(-6,19,5,STONE)
Block(-6,19,6,OBSIDIAN:0)
Block(-6,19,7,STONE)
Block(-6,19,8,STONE)
Block(-6,20,-7,CONCRETE:7)
Block(-6,20,-6,CONCRETE:7)
Block(-6,20,-5,STONE)
Block(-6,20,-4,STONE)
Block(-6,20,-3,STONE)
Block(-6,20,-2,STONE)
Block(-6,20,-1,OBSIDIAN:0)
Block(-6,20,0,STONE)
Block(-6,20,1,STONE)
Block(-6,20,2,STONE)
Block(-6,20,3,STONE)
Block(-6,20,4,OBSIDIAN:0)
Block(-6,20,5,STONE)
Block(-6,20,6,STONE)
Block(-6,20,7,STONE)
Block(-6,20,8,OBSIDIAN:0)
Block(-6,21,-7,CONCRETE:7)
Block(-6,21,-6,CONCRETE:7)
Block(-6,21,-5,OBSIDIAN:0)
Block(-6,21,-4,STONE)
Block(-6,21,-3,STONE)
Block(-6,21,-2,STONE)
Block(-6,21,-1,STONE)
Block(-6,21,0,STONE)
Block(-6,21,1,OBSIDIAN:0)
Block(-6,21,2,STONE)
Block(-6,21,3,OBSIDIAN:0)
Block(-6,21,4,STONE)
Block(-6,21,5,STONE)
Block(-6,21,6,STONE)
Block(-6,21,7,STONE)
Block(-6,21,8,STONE)
Block(-6,22,-7,CONCRETE:7)
Block(-6,22,-6,CONCRETE:7)
Block(-6,22,-5,OBSIDIAN:0)
Block(-6,22,-4,OBSIDIAN:0)
Block(-6,22,-3,STONE)
Block(-6,22,-2,STONE)
Block(-6,22,-1,STONE)
Block(-6,22,0,STONE)
Block(-6,22,1,STONE)
Block(-6,22,2,STONE)
Block(-6,22,3,OBSIDIAN:0)
Block(-6,22,4,STONE)
Block(-6,22,5,OBSIDIAN:0)
Block(-6,22,6,STONE)
Block(-6,22,7,OBSIDIAN:0)
Block(-6,22,8,STONE)
Block(-6,23,-7,CONCRETE:7)
Block(-6,23,-6,CONCRETE:7)
Block(-6,23,-5,STONE)
Block(-6,23,-4,STONE)
Block(-6,23,-3,STONE)
Block(-6,23,-2,STONE)
Block(-6,23,-1,STONE)
Block(-6,23,0,STONE)
Block(-6,23,1,STONE)
Block(-6,23,2,STONE)
Block(-6,23,3,STONE)
Block(-6,23,4,STONE)
Block(-6,23,5,STONE)
Block(-6,23,6,STONE)
Block(-6,23,7,STONE)
Block(-6,23,8,STONE)
Block(-6,24,-7,CONCRETE:7)
Block(-6,24,-6,CONCRETE:7)
Block(-6,24,-5,STONE)
Block(-6,24,-4,STONE)
Block(-6,24,-3,OBSIDIAN:0)
Block(-6,24,-2,STONE)
Block(-6,24,-1,STONE)
Block(-6,24,0,STONE)
Block(-6,24,1,STONE)
Block(-6,24,2,STONE)
Block(-6,24,3,STONE)
Block(-6,24,4,STONE)
Block(-6,24,5,STONE)
Block(-6,24,6,STONE)
Block(-6,24,7,STONE)
Block(-6,24,8,OBSIDIAN:0)
Block(-6,25,-7,CONCRETE:7)
Block(-6,25,-6,CONCRETE:7)
Block(-6,25,-5,STONE)
Block(-6,25,-4,STONE)
Block(-6,25,-3,OBSIDIAN:0)
Block(-6,25,-2,STONE)
Block(-6,25,-1,STONE)
Block(-6,25,0,STONE)
Block(-6,25,1,STONE)
Block(-6,25,2,STONE)
Block(-6,25,3,STONE)
Block(-6,25,4,STONE)
Block(-6,25,5,STONE)
Block(-6,25,6,STONE)
Block(-6,25,7,STONE)
Block(-6,25,8,STONE)
Block(-6,26,-7,CONCRETE:7)
Block(-6,26,-6,CONCRETE:7)
Block(-6,26,-5,STONE)
Block(-6,26,-4,STONE)
Block(-6,26,-3,STONE)
Block(-6,26,-2,STONE)
Block(-6,26,-1,STONE)
Block(-6,26,0,STONE)
Block(-6,26,1,STONE)
Block(-6,26,2,STONE)
Block(-6,26,3,STONE)
Block(-6,26,4,OBSIDIAN:0)
Block(-6,26,5,OBSIDIAN:0)
Block(-6,26,6,STONE)
Block(-6,26,7,STONE)
Block(-6,26,8,STONE)
Block(-6,27,-7,CONCRETE:7)
Block(-6,27,-6,CONCRETE:7)
Block(-6,27,-5,STONE)
Block(-6,27,-4,STONE)
Block(-6,27,-3,STONE)
Block(-6,27,-2,STONE)
Block(-6,27,-1,STONE)
Block(-6,27,0,OBSIDIAN:0)
Block(-6,27,1,OBSIDIAN:0)
Block(-6,27,2,STONE)
Block(-6,27,3,STONE)
Block(-6,27,4,STONE)
Block(-6,27,5,STONE)
Block(-6,27,6,STONE)
Block(-6,27,7,OBSIDIAN:0)
Block(-6,27,8,STONE)
Block(-6,28,-7,CONCRETE:7)
Block(-6,28,-6,CONCRETE:7)
Block(-6,28,-5,OBSIDIAN:0)
Block(-6,28,-4,STONE)
Block(-6,28,-3,STONE)
Block(-6,28,-2,STONE)
Block(-6,28,-1,STONE)
Block(-6,28,0,STONE)
Block(-6,28,1,STONE)
Block(-6,28,2,STONE)
Block(-6,28,3,STONE)
Block(-6,28,4,STONE)
Block(-6,28,5,STONE)
Block(-6,28,6,STONE)
Block(-6,28,7,STONE)
Block(-6,28,8,STONE)
Block(-6,29,-7,CONCRETE:7)
Block(-6,29,-6,CONCRETE:7)
Block(-6,29,-5,STONE)
Block(-6,29,-4,OBSIDIAN:0)
Block(-6,29,-3,STONE)
Block(-6,29,-2,STONE)
Block(-6,29,-1,STONE)
Block(-6,29,0,STONE)
Block(-6,29,1,STONE)
Block(-6,29,2,STONE)
Block(-6,29,3,STONE)
Block(-6,29,4,STONE)
Block(-6,29,5,STONE)
Block(-6,29,6,STONE)
Block(-6,29,7,STONE)
Block(-6,29,8,STONE)
Block(-6,30,-7,CONCRETE:7)
Block(-6,30,-6,CONCRETE:7)
Block(-6,30,-5,STONE)
Block(-6,30,-4,STONE)
Block(-6,30,-3,OBSIDIAN:0)
Block(-6,30,-2,STONE)
Block(-6,30,-1,STONE)
Block(-6,30,0,STONE)
Block(-6,30,1,STONE)
Block(-6,30,2,STONE)
Block(-6,30,3,STONE)
Block(-6,30,4,STONE)
Block(-6,30,5,OBSIDIAN:0)
Block(-6,30,6,STONE)
Block(-6,30,7,STONE)
Block(-6,30,8,STONE)
Block(-6,31,-7,SNOW:0)
Block(-6,31,-6,CONCRETE:7)
Block(-6,31,-5,STONE)
Block(-6,31,-4,STONE)
Block(-6,31,-3,STONE)
Block(-6,31,-2,OBSIDIAN:0)
Block(-6,31,-1,STONE)
Block(-6,31,0,STONE)
Block(-6,31,1,STONE)
Block(-6,31,2,OBSIDIAN:0)
Block(-6,31,3,STONE)
Block(-6,31,4,OBSIDIAN:0)
Block(-6,31,5,STONE)
Block(-6,31,6,STONE)
Block(-6,31,7,OBSIDIAN:0)
Block(-6,31,8,STONE)
Block(-6,32,-6,SNOW:5)
Block(-6,32,-5,CONCRETE:7)
Block(-6,32,-4,CONCRETE:7)
Block(-6,32,-3,CONCRETE:7)
Block(-6,32,-2,CONCRETE:7)
Block(-6,32,-1,CONCRETE:7)
Block(-6,32,0,CONCRETE:7)
Block(-6,32,1,OBSIDIAN:0)
Block(-6,32,2,OBSIDIAN:0)
Block(-6,32,3,OBSIDIAN:0)
Block(-6,32,4,OBSIDIAN:0)
Block(-6,32,5,OBSIDIAN:0)
Block(-6,32,6,OBSIDIAN:0)
Block(-6,32,7,OBSIDIAN:0)
Block(-6,32,8,OBSIDIAN:0)
Block(-6,33,-5,SNOW:5)
Block(-6,33,3,SNOW:0)
Block(-6,33,4,SNOW:1)
Block(-6,33,5,SNOW:3)
Block(-6,33,6,SNOW:5)
Block(-6,33,7,SNOW_BLOCK:0)
Block(-6,33,8,SNOW_BLOCK:0)
Block(-6,34,7,SNOW:0)
Block(-6,34,8,SNOW:0)
Block(-6,35,-7,PACKED_ICE:0)
Block(-6,35,-6,PACKED_ICE:0)
Block(-6,35,-5,PACKED_ICE:0)
Block(-6,36,-7,PACKED_ICE:0)
Block(-6,36,-6,PACKED_ICE:0)
Block(-6,36,-5,PACKED_ICE:0)
Block(-6,36,-4,PACKED_ICE:0)
Block(-6,36,-3,PACKED_ICE:0)
Block(-6,37,-7,PACKED_ICE:0)
Block(-6,37,-6,PACKED_ICE:0)
Block(-6,37,-5,PACKED_ICE:0)
Block(-6,37,-4,PACKED_ICE:0)
Block(-6,37,-3,PACKED_ICE:0)
Block(-6,37,-2,PACKED_ICE:0)
Block(-6,37,-1,PACKED_ICE:0)
Block(-6,38,-7,PACKED_ICE:0)
Block(-6,38,-6,PACKED_ICE:0)
Block(-6,38,-5,PACKED_ICE:0)
Block(-6,38,-4,PACKED_ICE:0)
Block(-6,38,-3,PACKED_ICE:0)
Block(-6,38,-2,PACKED_ICE:0)
Block(-6,38,-1,PACKED_ICE:0)
Block(-6,38,0,PACKED_ICE:0)
Block(-6,39,-7,PACKED_ICE:0)
Block(-6,39,-6,PACKED_ICE:0)
Block(-6,39,-5,PACKED_ICE:0)
Block(-6,39,-4,PACKED_ICE:0)
Block(-6,39,-3,PACKED_ICE:0)
Block(-6,39,-2,PACKED_ICE:0)
Block(-6,39,-1,PACKED_ICE:0)
Block(-6,39,0,PACKED_ICE:0)
Block(-6,40,-7,PACKED_ICE:0)
Block(-6,40,-6,PACKED_ICE:0)
Block(-6,40,-5,PACKED_ICE:0)
Block(-6,40,-4,PACKED_ICE:0)
Block(-6,40,-3,PACKED_ICE:0)
Block(-6,40,-2,PACKED_ICE:0)
Block(-6,40,-1,PACKED_ICE:0)
Block(-6,40,0,PACKED_ICE:0)
Block(-6,40,1,PACKED_ICE:0)
Block(-6,41,-7,PACKED_ICE:0)
Block(-6,41,-6,PACKED_ICE:0)
Block(-6,41,-5,PACKED_ICE:0)
Block(-6,41,-4,PACKED_ICE:0)
Block(-6,41,-3,PACKED_ICE:0)
Block(-6,41,-2,PACKED_ICE:0)
Block(-6,41,-1,PACKED_ICE:0)
Block(-6,41,0,PACKED_ICE:0)
Block(-6,41,1,PACKED_ICE:0)
Block(-6,42,-6,PACKED_ICE:0)
Block(-6,42,-5,PACKED_ICE:0)
Block(-6,42,-4,PACKED_ICE:0)
Block(-6,42,-3,PACKED_ICE:0)
Block(-6,42,-2,PACKED_ICE:0)
Block(-6,42,-1,PACKED_ICE:0)
Block(-6,42,0,PACKED_ICE:0)
Block(-6,42,1,PACKED_ICE:0)
Block(-6,43,-5,PACKED_ICE:0)
Block(-6,43,-4,PACKED_ICE:0)
Block(-6,43,-3,PACKED_ICE:0)
Block(-6,43,-2,PACKED_ICE:0)
Block(-6,43,-1,PACKED_ICE:0)
Block(-6,43,0,PACKED_ICE:0)
Block(-6,43,1,PACKED_ICE:0)
Block(-6,44,-4,PACKED_ICE:0)
Block(-6,44,-3,PACKED_ICE:0)
Block(-6,44,-2,PACKED_ICE:0)
Block(-6,44,-1,PACKED_ICE:0)
Block(-6,44,0,PACKED_ICE:0)
Block(-6,44,1,PACKED_ICE:0)
Block(-6,44,2,PACKED_ICE:0)
Block(-5,0,-7,CONCRETE:7)
Block(-5,0,-6,CONCRETE:7)
Block(-5,0,-5,CONCRETE:7)
Block(-5,0,-4,CONCRETE:7)
Block(-5,0,-3,CONCRETE:7)
Block(-5,0,-2,CONCRETE:7)
Block(-5,0,-1,CONCRETE:7)
Block(-5,0,0,CONCRETE:7)
Block(-5,0,1,CONCRETE:7)
Block(-5,0,2,CONCRETE:7)
Block(-5,0,3,CONCRETE:7)
Block(-5,0,4,CONCRETE:7)
Block(-5,0,5,CONCRETE:7)
Block(-5,0,6,CONCRETE:7)
Block(-5,0,7,CONCRETE:7)
Block(-5,0,8,CONCRETE:7)
Block(-5,1,-7,CONCRETE:7)
Block(-5,1,-6,CONCRETE:7)
Block(-5,1,-5,STONE)
Block(-5,1,-4,STONE)
Block(-5,1,-3,STONE)
Block(-5,1,-2,STONE)
Block(-5,1,-1,STONE)
Block(-5,1,0,STONE)
Block(-5,1,1,STONE)
Block(-5,1,2,OBSIDIAN:0)
Block(-5,1,3,STONE)
Block(-5,1,4,STONE)
Block(-5,1,5,STONE)
Block(-5,1,6,STONE)
Block(-5,1,7,STONE)
Block(-5,1,8,OBSIDIAN:0)
Block(-5,2,-7,CONCRETE:7)
Block(-5,2,-6,CONCRETE:7)
Block(-5,2,-5,STONE)
Block(-5,2,-4,OBSIDIAN:0)
Block(-5,2,-3,STONE)
Block(-5,2,-2,STONE)
Block(-5,2,-1,STONE)
Block(-5,2,0,STONE)
Block(-5,2,1,STONE)
Block(-5,2,2,OBSIDIAN:0)
Block(-5,2,3,STONE)
Block(-5,2,4,OBSIDIAN:0)
Block(-5,2,5,STONE)
Block(-5,2,6,OBSIDIAN:0)
Block(-5,2,7,STONE)
Block(-5,2,8,STONE)
Block(-5,3,-7,CONCRETE:7)
Block(-5,3,-6,CONCRETE:7)
Block(-5,3,-5,STONE)
Block(-5,3,-4,STONE)
Block(-5,3,-3,OBSIDIAN:0)
Block(-5,3,-2,STONE)
Block(-5,3,-1,STONE)
Block(-5,3,0,STONE)
Block(-5,3,1,OBSIDIAN:0)
Block(-5,3,2,STONE)
Block(-5,3,3,STONE)
Block(-5,3,4,STONE)
Block(-5,3,5,STONE)
Block(-5,3,6,OBSIDIAN:0)
Block(-5,3,7,STONE)
Block(-5,3,8,STONE)
Block(-5,4,-7,CONCRETE:7)
Block(-5,4,-6,CONCRETE:7)
Block(-5,4,-5,STONE)
Block(-5,4,-4,OBSIDIAN:0)
Block(-5,4,-3,STONE)
Block(-5,4,-2,STONE)
Block(-5,4,-1,OBSIDIAN:0)
Block(-5,4,0,STONE)
Block(-5,4,1,OBSIDIAN:0)
Block(-5,4,2,OBSIDIAN:0)
Block(-5,4,3,STONE)
Block(-5,4,4,STONE)
Block(-5,4,5,STONE)
Block(-5,4,6,STONE)
Block(-5,4,7,STONE)
Block(-5,4,8,STONE)
Block(-5,5,-7,CONCRETE:7)
Block(-5,5,-6,CONCRETE:7)
Block(-5,5,-5,STONE)
Block(-5,5,-4,STONE)
Block(-5,5,-3,STONE)
Block(-5,5,-2,STONE)
Block(-5,5,-1,OBSIDIAN:0)
Block(-5,5,0,STONE)
Block(-5,5,1,STONE)
Block(-5,5,2,OBSIDIAN:0)
Block(-5,5,3,STONE)
Block(-5,5,4,STONE)
Block(-5,5,5,STONE)
Block(-5,5,6,STONE)
Block(-5,5,7,STONE)
Block(-5,5,8,STONE)
Block(-5,6,-7,CONCRETE:7)
Block(-5,6,-6,CONCRETE:7)
Block(-5,6,-5,OBSIDIAN:0)
Block(-5,6,-4,STONE)
Block(-5,6,-3,OBSIDIAN:0)
Block(-5,6,-2,OBSIDIAN:0)
Block(-5,6,-1,STONE)
Block(-5,6,0,STONE)
Block(-5,6,1,STONE)
Block(-5,6,2,STONE)
Block(-5,6,3,OBSIDIAN:0)
Block(-5,6,4,OBSIDIAN:0)
Block(-5,6,5,OBSIDIAN:0)
Block(-5,6,6,STONE)
Block(-5,6,7,STONE)
Block(-5,6,8,OBSIDIAN:0)
Block(-5,7,-7,CONCRETE:7)
Block(-5,7,-6,CONCRETE:7)
Block(-5,7,-5,OBSIDIAN:0)
Block(-5,7,-4,STONE)
Block(-5,7,-3,OBSIDIAN:0)
Block(-5,7,-2,STONE)
Block(-5,7,-1,OBSIDIAN:0)
Block(-5,7,0,STONE)
Block(-5,7,1,STONE)
Block(-5,7,2,STONE)
Block(-5,7,3,STONE)
Block(-5,7,4,OBSIDIAN:0)
Block(-5,7,5,OBSIDIAN:0)
Block(-5,7,6,STONE)
Block(-5,7,7,STONE)
Block(-5,7,8,STONE)
Block(-5,8,-7,CONCRETE:7)
Block(-5,8,-6,CONCRETE:7)
Block(-5,8,-5,OBSIDIAN:0)
Block(-5,8,-4,STONE)
Block(-5,8,-3,STONE)
Block(-5,8,-2,STONE)
Block(-5,8,-1,STONE)
Block(-5,8,0,STONE)
Block(-5,8,1,STONE)
Block(-5,8,2,STONE)
Block(-5,8,3,STONE)
Block(-5,8,4,OBSIDIAN:0)
Block(-5,8,5,STONE)
Block(-5,8,6,OBSIDIAN:0)
Block(-5,8,7,STONE)
Block(-5,8,8,STONE)
Block(-5,9,-7,CONCRETE:7)
Block(-5,9,-6,CONCRETE:7)
Block(-5,9,-5,OBSIDIAN:0)
Block(-5,9,-4,STONE)
Block(-5,9,-3,OBSIDIAN:0)
Block(-5,9,-2,STONE)
Block(-5,9,-1,STONE)
Block(-5,9,0,STONE)
Block(-5,9,1,OBSIDIAN:0)
Block(-5,9,2,STONE)
Block(-5,9,3,OBSIDIAN:0)
Block(-5,9,4,OBSIDIAN:0)
Block(-5,9,5,STONE)
Block(-5,9,6,STONE)
Block(-5,9,7,STONE)
Block(-5,9,8,STONE)
Block(-5,10,-7,OBSIDIAN:0)
Block(-5,10,-6,CONCRETE:7)
Block(-5,10,-5,STONE)
Block(-5,10,-4,STONE)
Block(-5,10,-3,STONE)
Block(-5,10,-2,STONE)
Block(-5,10,-1,OBSIDIAN:0)
Block(-5,10,0,STONE)
Block(-5,10,1,STONE)
Block(-5,10,2,STONE)
Block(-5,10,3,STONE)
Block(-5,10,4,STONE)
Block(-5,10,5,STONE)
Block(-5,10,6,STONE)
Block(-5,10,7,STONE)
Block(-5,10,8,STONE)
Block(-5,11,-7,OBSIDIAN:0)
Block(-5,11,-6,CONCRETE:7)
Block(-5,11,-5,STONE)
Block(-5,11,-4,STONE)
Block(-5,11,-3,STONE)
Block(-5,11,-2,STONE)
Block(-5,11,-1,OBSIDIAN:0)
Block(-5,11,0,OBSIDIAN:0)
Block(-5,11,1,STONE)
Block(-5,11,2,STONE)
Block(-5,11,3,STONE)
Block(-5,11,4,OBSIDIAN:0)
Block(-5,11,5,STONE)
Block(-5,11,6,STONE)
Block(-5,11,7,OBSIDIAN:0)
Block(-5,11,8,STONE)
Block(-5,12,-7,OBSIDIAN:0)
Block(-5,12,-6,CONCRETE:7)
Block(-5,12,-5,STONE)
Block(-5,12,-4,STONE)
Block(-5,12,-3,STONE)
Block(-5,12,-2,OBSIDIAN:0)
Block(-5,12,-1,OBSIDIAN:0)
Block(-5,12,0,STONE)
Block(-5,12,1,STONE)
Block(-5,12,2,STONE)
Block(-5,12,3,STONE)
Block(-5,12,4,STONE)
Block(-5,12,5,OBSIDIAN:0)
Block(-5,12,6,STONE)
Block(-5,12,7,STONE)
Block(-5,12,8,STONE)
Block(-5,13,-7,OBSIDIAN:0)
Block(-5,13,-6,CONCRETE:7)
Block(-5,13,-5,OBSIDIAN:0)
Block(-5,13,-4,STONE)
Block(-5,13,-3,STONE)
Block(-5,13,-2,STONE)
Block(-5,13,-1,STONE)
Block(-5,13,0,STONE)
Block(-5,13,1,STONE)
Block(-5,13,2,STONE)
Block(-5,13,3,STONE)
Block(-5,13,4,OBSIDIAN:0)
Block(-5,13,5,STONE)
Block(-5,13,6,STONE)
Block(-5,13,7,STONE)
Block(-5,13,8,STONE)
Block(-5,14,-7,OBSIDIAN:0)
Block(-5,14,-6,CONCRETE:7)
Block(-5,14,-5,OBSIDIAN:0)
Block(-5,14,-4,STONE)
Block(-5,14,-3,STONE)
Block(-5,14,-2,STONE)
Block(-5,14,-1,STONE)
Block(-5,14,0,STONE)
Block(-5,14,1,STONE)
Block(-5,14,2,STONE)
Block(-5,14,3,STONE)
Block(-5,14,4,STONE)
Block(-5,14,5,STONE)
Block(-5,14,6,STONE)
Block(-5,14,7,OBSIDIAN:0)
Block(-5,14,8,STONE)
Block(-5,15,-7,CONCRETE:7)
Block(-5,15,-6,CONCRETE:7)
Block(-5,15,-5,STONE)
Block(-5,15,-4,STONE)
Block(-5,15,-3,STONE)
Block(-5,15,-2,STONE)
Block(-5,15,-1,OBSIDIAN:0)
Block(-5,15,0,STONE)
Block(-5,15,1,STONE)
Block(-5,15,2,OBSIDIAN:0)
Block(-5,15,3,STONE)
Block(-5,15,4,STONE)
Block(-5,15,5,STONE)
Block(-5,15,6,STONE)
Block(-5,15,7,STONE)
Block(-5,15,8,STONE)
Block(-5,16,-7,CONCRETE:7)
Block(-5,16,-6,CONCRETE:7)
Block(-5,16,-5,STONE)
Block(-5,16,-4,STONE)
Block(-5,16,-3,STONE)
Block(-5,16,-2,STONE)
Block(-5,16,-1,OBSIDIAN:0)
Block(-5,16,0,STONE)
Block(-5,16,1,OBSIDIAN:0)
Block(-5,16,2,STONE)
Block(-5,16,3,STONE)
Block(-5,16,4,STONE)
Block(-5,16,5,STONE)
Block(-5,16,6,OBSIDIAN:0)
Block(-5,16,7,STONE)
Block(-5,16,8,STONE)
Block(-5,17,-7,CONCRETE:7)
Block(-5,17,-6,CONCRETE:7)
Block(-5,17,-5,STONE)
Block(-5,17,-4,OBSIDIAN:0)
Block(-5,17,-3,STONE)
Block(-5,17,-2,STONE)
Block(-5,17,-1,STONE)
Block(-5,17,0,STONE)
Block(-5,17,1,STONE)
Block(-5,17,2,OBSIDIAN:0)
Block(-5,17,3,OBSIDIAN:0)
Block(-5,17,4,STONE)
Block(-5,17,5,STONE)
Block(-5,17,6,STONE)
Block(-5,17,7,STONE)
Block(-5,17,8,STONE)
Block(-5,18,-7,CONCRETE:7)
Block(-5,18,-6,CONCRETE:7)
Block(-5,18,-5,STONE)
Block(-5,18,-4,OBSIDIAN:0)
Block(-5,18,-3,STONE)
Block(-5,18,-2,STONE)
Block(-5,18,-1,STONE)
Block(-5,18,0,STONE)
Block(-5,18,1,STONE)
Block(-5,18,2,STONE)
Block(-5,18,3,STONE)
Block(-5,18,4,STONE)
Block(-5,18,5,STONE)
Block(-5,18,6,OBSIDIAN:0)
Block(-5,18,7,OBSIDIAN:0)
Block(-5,18,8,OBSIDIAN:0)
Block(-5,19,-7,CONCRETE:7)
Block(-5,19,-6,CONCRETE:7)
Block(-5,19,-5,STONE)
Block(-5,19,-4,STONE)
Block(-5,19,-3,STONE)
Block(-5,19,-2,STONE)
Block(-5,19,-1,STONE)
Block(-5,19,0,STONE)
Block(-5,19,1,STONE)
Block(-5,19,2,STONE)
Block(-5,19,3,STONE)
Block(-5,19,4,STONE)
Block(-5,19,5,STONE)
Block(-5,19,6,STONE)
Block(-5,19,7,STONE)
Block(-5,19,8,STONE)
Block(-5,20,-7,CONCRETE:7)
Block(-5,20,-6,CONCRETE:7)
Block(-5,20,-5,OBSIDIAN:0)
Block(-5,20,-4,STONE)
Block(-5,20,-3,STONE)
Block(-5,20,-2,STONE)
Block(-5,20,-1,STONE)
Block(-5,20,0,STONE)
Block(-5,20,1,STONE)
Block(-5,20,2,STONE)
Block(-5,20,3,STONE)
Block(-5,20,4,STONE)
Block(-5,20,5,STONE)
Block(-5,20,6,STONE)
Block(-5,20,7,STONE)
Block(-5,20,8,STONE)
Block(-5,21,-7,CONCRETE:7)
Block(-5,21,-6,CONCRETE:7)
Block(-5,21,-5,OBSIDIAN:0)
Block(-5,21,-4,STONE)
Block(-5,21,-3,STONE)
Block(-5,21,-2,STONE)
Block(-5,21,-1,STONE)
Block(-5,21,0,STONE)
Block(-5,21,1,STONE)
Block(-5,21,2,STONE)
Block(-5,21,3,STONE)
Block(-5,21,4,STONE)
Block(-5,21,5,STONE)
Block(-5,21,6,STONE)
Block(-5,21,7,STONE)
Block(-5,21,8,OBSIDIAN:0)
Block(-5,22,-7,CONCRETE:7)
Block(-5,22,-6,CONCRETE:7)
Block(-5,22,-5,STONE)
Block(-5,22,-4,STONE)
Block(-5,22,-3,STONE)
Block(-5,22,-2,STONE)
Block(-5,22,-1,OBSIDIAN:0)
Block(-5,22,0,OBSIDIAN:0)
Block(-5,22,1,STONE)
Block(-5,22,2,STONE)
Block(-5,22,3,STONE)
Block(-5,22,4,STONE)
Block(-5,22,5,STONE)
Block(-5,22,6,STONE)
Block(-5,22,7,STONE)
Block(-5,22,8,OBSIDIAN:0)
Block(-5,23,-7,CONCRETE:7)
Block(-5,23,-6,CONCRETE:7)
Block(-5,23,-5,STONE)
Block(-5,23,-4,STONE)
Block(-5,23,-3,STONE)
Block(-5,23,-2,STONE)
Block(-5,23,-1,STONE)
Block(-5,23,0,OBSIDIAN:0)
Block(-5,23,1,STONE)
Block(-5,23,2,STONE)
Block(-5,23,3,OBSIDIAN:0)
Block(-5,23,4,STONE)
Block(-5,23,5,STONE)
Block(-5,23,6,OBSIDIAN:0)
Block(-5,23,7,OBSIDIAN:0)
Block(-5,23,8,STONE)
Block(-5,24,-7,CONCRETE:7)
Block(-5,24,-6,CONCRETE:7)
Block(-5,24,-5,STONE)
Block(-5,24,-4,STONE)
Block(-5,24,-3,STONE)
Block(-5,24,-2,STONE)
Block(-5,24,-1,STONE)
Block(-5,24,0,STONE)
Block(-5,24,1,STONE)
Block(-5,24,2,STONE)
Block(-5,24,3,OBSIDIAN:0)
Block(-5,24,4,STONE)
Block(-5,24,5,STONE)
Block(-5,24,6,STONE)
Block(-5,24,7,STONE)
Block(-5,24,8,STONE)
Block(-5,25,-7,CONCRETE:7)
Block(-5,25,-6,CONCRETE:7)
Block(-5,25,-5,STONE)
Block(-5,25,-4,STONE)
Block(-5,25,-3,STONE)
Block(-5,25,-2,STONE)
Block(-5,25,-1,STONE)
Block(-5,25,0,STONE)
Block(-5,25,1,STONE)
Block(-5,25,2,STONE)
Block(-5,25,3,OBSIDIAN:0)
Block(-5,25,4,STONE)
Block(-5,25,5,OBSIDIAN:0)
Block(-5,25,6,OBSIDIAN:0)
Block(-5,25,7,STONE)
Block(-5,25,8,STONE)
Block(-5,26,-7,CONCRETE:7)
Block(-5,26,-6,CONCRETE:7)
Block(-5,26,-5,STONE)
Block(-5,26,-4,OBSIDIAN:0)
Block(-5,26,-3,STONE)
Block(-5,26,-2,STONE)
Block(-5,26,-1,STONE)
Block(-5,26,0,STONE)
Block(-5,26,1,STONE)
Block(-5,26,2,STONE)
Block(-5,26,3,STONE)
Block(-5,26,4,STONE)
Block(-5,26,5,STONE)
Block(-5,26,6,OBSIDIAN:0)
Block(-5,26,7,STONE)
Block(-5,26,8,STONE)
Block(-5,27,-7,CONCRETE:7)
Block(-5,27,-6,CONCRETE:7)
Block(-5,27,-5,OBSIDIAN:0)
Block(-5,27,-4,STONE)
Block(-5,27,-3,STONE)
Block(-5,27,-2,STONE)
Block(-5,27,-1,STONE)
Block(-5,27,0,STONE)
Block(-5,27,1,OBSIDIAN:0)
Block(-5,27,2,STONE)
Block(-5,27,3,STONE)
Block(-5,27,4,STONE)
Block(-5,27,5,STONE)
Block(-5,27,6,STONE)
Block(-5,27,7,STONE)
Block(-5,27,8,STONE)
Block(-5,28,-7,CONCRETE:7)
Block(-5,28,-6,CONCRETE:7)
Block(-5,28,-5,OBSIDIAN:0)
Block(-5,28,-4,STONE)
Block(-5,28,-3,STONE)
Block(-5,28,-2,STONE)
Block(-5,28,-1,STONE)
Block(-5,28,0,STONE)
Block(-5,28,1,STONE)
Block(-5,28,2,STONE)
Block(-5,28,3,STONE)
Block(-5,28,4,STONE)
Block(-5,28,5,STONE)
Block(-5,28,6,STONE)
Block(-5,28,7,STONE)
Block(-5,28,8,STONE)
Block(-5,29,-7,CONCRETE:7)
Block(-5,29,-6,CONCRETE:7)
Block(-5,29,-5,STONE)
Block(-5,29,-4,STONE)
Block(-5,29,-3,STONE)
Block(-5,29,-2,STONE)
Block(-5,29,-1,STONE)
Block(-5,29,0,STONE)
Block(-5,29,1,STONE)
Block(-5,29,2,STONE)
Block(-5,29,3,STONE)
Block(-5,29,4,STONE)
Block(-5,29,5,STONE)
Block(-5,29,6,OBSIDIAN:0)
Block(-5,29,7,STONE)
Block(-5,29,8,STONE)
Block(-5,30,-7,CONCRETE:7)
Block(-5,30,-6,CONCRETE:7)
Block(-5,30,-5,STONE)
Block(-5,30,-4,STONE)
Block(-5,30,-3,OBSIDIAN:0)
Block(-5,30,-2,STONE)
Block(-5,30,-1,STONE)
Block(-5,30,0,STONE)
Block(-5,30,1,STONE)
Block(-5,30,2,STONE)
Block(-5,30,3,STONE)
Block(-5,30,4,STONE)
Block(-5,30,5,OBSIDIAN:0)
Block(-5,30,6,OBSIDIAN:0)
Block(-5,30,7,OBSIDIAN:0)
Block(-5,30,8,STONE)
Block(-5,31,-7,SNOW:2)
Block(-5,31,-6,CONCRETE:7)
Block(-5,31,-5,STONE)
Block(-5,31,-4,OBSIDIAN:0)
Block(-5,31,-3,STONE)
Block(-5,31,-2,OBSIDIAN:0)
Block(-5,31,-1,STONE)
Block(-5,31,0,OBSIDIAN:0)
Block(-5,31,1,STONE)
Block(-5,31,2,STONE)
Block(-5,31,3,OBSIDIAN:0)
Block(-5,31,4,STONE)
Block(-5,31,5,STONE)
Block(-5,31,6,STONE)
Block(-5,31,7,STONE)
Block(-5,31,8,STONE)
Block(-5,32,-6,SNOW:6)
Block(-5,32,-5,CONCRETE:7)
Block(-5,32,-4,STONE)
Block(-5,32,-3,STONE)
Block(-5,32,-2,STONE)
Block(-5,32,-1,STONE)
Block(-5,32,0,OBSIDIAN:0)
Block(-5,32,1,STONE)
Block(-5,32,2,OBSIDIAN:0)
Block(-5,32,3,STONE)
Block(-5,32,4,STONE)
Block(-5,32,5,STONE)
Block(-5,32,6,OBSIDIAN:0)
Block(-5,32,7,OBSIDIAN:0)
Block(-5,32,8,STONE)
Block(-5,33,-5,SNOW_BLOCK:0)
Block(-5,33,-4,CONCRETE:7)
Block(-5,33,-3,CONCRETE:7)
Block(-5,33,-2,CONCRETE:7)
Block(-5,33,-1,CONCRETE:7)
Block(-5,33,0,CONCRETE:7)
Block(-5,33,1,CONCRETE:7)
Block(-5,33,2,CONCRETE:7)
Block(-5,33,3,OBSIDIAN:0)
Block(-5,33,4,OBSIDIAN:0)
Block(-5,33,5,OBSIDIAN:0)
Block(-5,33,6,OBSIDIAN:0)
Block(-5,33,7,OBSIDIAN:0)
Block(-5,33,8,OBSIDIAN:0)
Block(-5,34,-4,CONCRETE:7)
Block(-5,34,-3,CONCRETE:7)
Block(-5,34,2,SNOW:0)
Block(-5,34,3,SNOW:2)
Block(-5,34,4,SNOW:4)
Block(-5,34,5,SNOW:6)
Block(-5,34,6,SNOW_BLOCK:0)
Block(-5,34,7,SNOW_BLOCK:0)
Block(-5,34,8,SNOW_BLOCK:0)
Block(-5,35,-4,CONCRETE:7)
Block(-5,35,-3,CONCRETE:7)
Block(-5,35,7,SNOW:0)
Block(-5,35,8,SNOW:2)
Block(-5,36,-5,PACKED_ICE:0)
Block(-5,36,-4,PACKED_ICE:0)
Block(-5,36,-3,CONCRETE:7)
Block(-5,37,-7,PACKED_ICE:0)
Block(-5,37,-6,PACKED_ICE:0)
Block(-5,37,-5,PACKED_ICE:0)
Block(-5,37,-4,PACKED_ICE:0)
Block(-5,37,-3,PACKED_ICE:0)
Block(-5,38,-7,PACKED_ICE:0)
Block(-5,38,-6,PACKED_ICE:0)
Block(-5,38,-5,PACKED_ICE:0)
Block(-5,38,-4,PACKED_ICE:0)
Block(-5,38,-3,PACKED_ICE:0)
Block(-5,38,-2,PACKED_ICE:0)
Block(-5,38,-1,PACKED_ICE:0)
Block(-5,39,-7,PACKED_ICE:0)
Block(-5,39,-6,PACKED_ICE:0)
Block(-5,39,-5,PACKED_ICE:0)
Block(-5,39,-4,PACKED_ICE:0)
Block(-5,39,-3,PACKED_ICE:0)
Block(-5,39,-2,PACKED_ICE:0)
Block(-5,39,-1,PACKED_ICE:0)
Block(-5,39,0,PACKED_ICE:0)
Block(-5,39,1,PACKED_ICE:0)
Block(-5,40,-7,PACKED_ICE:0)
Block(-5,40,-6,PACKED_ICE:0)
Block(-5,40,-5,PACKED_ICE:0)
Block(-5,40,-4,PACKED_ICE:0)
Block(-5,40,-3,PACKED_ICE:0)
Block(-5,40,-2,PACKED_ICE:0)
Block(-5,40,-1,PACKED_ICE:0)
Block(-5,40,0,PACKED_ICE:0)
Block(-5,40,1,PACKED_ICE:0)
Block(-5,41,-6,PACKED_ICE:0)
Block(-5,41,-5,PACKED_ICE:0)
Block(-5,41,-4,PACKED_ICE:0)
Block(-5,41,-3,PACKED_ICE:0)
Block(-5,41,-2,PACKED_ICE:0)
Block(-5,41,-1,PACKED_ICE:0)
Block(-5,41,0,PACKED_ICE:0)
Block(-5,41,1,PACKED_ICE:0)
Block(-5,42,-6,PACKED_ICE:0)
Block(-5,42,-5,PACKED_ICE:0)
Block(-5,42,-4,PACKED_ICE:0)
Block(-5,42,-3,PACKED_ICE:0)
Block(-5,42,-2,PACKED_ICE:0)
Block(-5,42,-1,PACKED_ICE:0)
Block(-5,42,0,PACKED_ICE:0)
Block(-5,42,1,PACKED_ICE:0)
Block(-5,42,2,PACKED_ICE:0)
Block(-5,43,-5,PACKED_ICE:0)
Block(-5,43,-4,PACKED_ICE:0)
Block(-5,43,-3,PACKED_ICE:0)
Block(-5,43,-2,PACKED_ICE:0)
Block(-5,43,-1,PACKED_ICE:0)
Block(-5,43,0,PACKED_ICE:0)
Block(-5,43,1,PACKED_ICE:0)
Block(-5,43,2,PACKED_ICE:0)
Block(-5,44,-4,PACKED_ICE:0)
Block(-5,44,-3,PACKED_ICE:0)
Block(-5,44,-2,PACKED_ICE:0)
Block(-5,44,-1,PACKED_ICE:0)
Block(-5,44,0,PACKED_ICE:0)
Block(-5,44,1,PACKED_ICE:0)
Block(-5,44,2,PACKED_ICE:0)
Block(-5,45,-3,PACKED_ICE:0)
Block(-5,45,-2,PACKED_ICE:0)
Block(-5,45,-1,PACKED_ICE:0)
Block(-5,45,0,PACKED_ICE:0)
Block(-5,45,1,PACKED_ICE:0)
Block(-5,45,2,PACKED_ICE:0)
Block(-5,45,3,PACKED_ICE:0)
Block(-4,0,-7,CONCRETE:7)
Block(-4,0,-6,CONCRETE:7)
Block(-4,0,-5,CONCRETE:7)
Block(-4,0,-4,CONCRETE:7)
Block(-4,0,-3,CONCRETE:7)
Block(-4,0,-2,CONCRETE:7)
Block(-4,0,-1,CONCRETE:7)
Block(-4,0,0,CONCRETE:7)
Block(-4,0,1,CONCRETE:7)
Block(-4,0,2,CONCRETE:7)
Block(-4,0,3,CONCRETE:7)
Block(-4,0,4,CONCRETE:7)
Block(-4,0,5,CONCRETE:7)
Block(-4,0,6,CONCRETE:7)
Block(-4,0,7,CONCRETE:7)
Block(-4,0,8,CONCRETE:7)
Block(-4,1,-7,CONCRETE:7)
Block(-4,1,-6,CONCRETE:7)
Block(-4,1,-5,STONE)
Block(-4,1,-4,STONE)
Block(-4,1,-3,STONE)
Block(-4,1,-2,STONE)
Block(-4,1,-1,OBSIDIAN:0)
Block(-4,1,0,STONE)
Block(-4,1,1,STONE)
Block(-4,1,2,STONE)
Block(-4,1,3,STONE)
Block(-4,1,4,STONE)
Block(-4,1,5,OBSIDIAN:0)
Block(-4,1,6,STONE)
Block(-4,1,7,STONE)
Block(-4,1,8,STONE)
Block(-4,2,-7,CONCRETE:7)
Block(-4,2,-6,CONCRETE:7)
Block(-4,2,-5,STONE)
Block(-4,2,-4,STONE)
Block(-4,2,-3,OBSIDIAN:0)
Block(-4,2,-2,STONE)
Block(-4,2,-1,STONE)
Block(-4,2,0,STONE)
Block(-4,2,1,STONE)
Block(-4,2,2,STONE)
Block(-4,2,3,OBSIDIAN:0)
Block(-4,2,4,OBSIDIAN:0)
Block(-4,2,5,STONE)
Block(-4,2,6,OBSIDIAN:0)
Block(-4,2,7,OBSIDIAN:0)
Block(-4,2,8,STONE)
Block(-4,3,-7,CONCRETE:7)
Block(-4,3,-6,CONCRETE:7)
Block(-4,3,-5,STONE)
Block(-4,3,-4,OBSIDIAN:0)
Block(-4,3,-3,STONE)
Block(-4,3,-2,STONE)
Block(-4,3,-1,STONE)
Block(-4,3,0,OBSIDIAN:0)
Block(-4,3,1,STONE)
Block(-4,3,2,OBSIDIAN:0)
Block(-4,3,3,STONE)
Block(-4,3,4,STONE)
Block(-4,3,5,STONE)
Block(-4,3,6,STONE)
Block(-4,3,7,STONE)
Block(-4,3,8,STONE)
Block(-4,4,-7,CONCRETE:7)
Block(-4,4,-6,CONCRETE:7)
Block(-4,4,-5,STONE)
Block(-4,4,-4,STONE)
Block(-4,4,-3,OBSIDIAN:0)
Block(-4,4,-2,STONE)
Block(-4,4,-1,STONE)
Block(-4,4,0,STONE)
Block(-4,4,1,STONE)
Block(-4,4,2,STONE)
Block(-4,4,3,STONE)
Block(-4,4,4,STONE)
Block(-4,4,5,OBSIDIAN:0)
Block(-4,4,6,OBSIDIAN:0)
Block(-4,4,7,OBSIDIAN:0)
Block(-4,4,8,STONE)
Block(-4,5,-7,CONCRETE:7)
Block(-4,5,-6,CONCRETE:7)
Block(-4,5,-5,STONE)
Block(-4,5,-4,STONE)
Block(-4,5,-3,STONE)
Block(-4,5,-2,OBSIDIAN:0)
Block(-4,5,-1,STONE)
Block(-4,5,0,STONE)
Block(-4,5,1,STONE)
Block(-4,5,2,STONE)
Block(-4,5,3,OBSIDIAN:0)
Block(-4,5,4,OBSIDIAN:0)
Block(-4,5,5,OBSIDIAN:0)
Block(-4,5,6,OBSIDIAN:0)
Block(-4,5,7,OBSIDIAN:0)
Block(-4,5,8,STONE)
Block(-4,6,-7,CONCRETE:7)
Block(-4,6,-6,CONCRETE:7)
Block(-4,6,-5,STONE)
Block(-4,6,-4,OBSIDIAN:0)
Block(-4,6,-3,STONE)
Block(-4,6,-2,STONE)
Block(-4,6,-1,STONE)
Block(-4,6,0,STONE)
Block(-4,6,1,STONE)
Block(-4,6,2,OBSIDIAN:0)
Block(-4,6,3,OBSIDIAN:0)
Block(-4,6,4,OBSIDIAN:0)
Block(-4,6,5,OBSIDIAN:0)
Block(-4,6,6,OBSIDIAN:0)
Block(-4,6,7,OBSIDIAN:0)
Block(-4,6,8,OBSIDIAN:0)
Block(-4,7,-7,CONCRETE:7)
Block(-4,7,-6,CONCRETE:7)
Block(-4,7,-5,STONE)
Block(-4,7,-4,STONE)
Block(-4,7,-3,STONE)
Block(-4,7,-2,STONE)
Block(-4,7,-1,STONE)
Block(-4,7,0,STONE)
Block(-4,7,1,STONE)
Block(-4,7,2,STONE)
Block(-4,7,3,OBSIDIAN:0)
Block(-4,7,4,OBSIDIAN:0)
Block(-4,7,5,OBSIDIAN:0)
Block(-4,7,6,STONE)
Block(-4,7,7,STONE)
Block(-4,7,8,STONE)
Block(-4,8,-7,CONCRETE:7)
Block(-4,8,-6,CONCRETE:7)
Block(-4,8,-5,STONE)
Block(-4,8,-4,STONE)
Block(-4,8,-3,STONE)
Block(-4,8,-2,STONE)
Block(-4,8,-1,STONE)
Block(-4,8,0,STONE)
Block(-4,8,1,STONE)
Block(-4,8,2,STONE)
Block(-4,8,3,STONE)
Block(-4,8,4,STONE)
Block(-4,8,5,STONE)
Block(-4,8,6,STONE)
Block(-4,8,7,STONE)
Block(-4,8,8,STONE)
Block(-4,9,-7,CONCRETE:7)
Block(-4,9,-6,CONCRETE:7)
Block(-4,9,-5,STONE)
Block(-4,9,-4,STONE)
Block(-4,9,-3,OBSIDIAN:0)
Block(-4,9,-2,STONE)
Block(-4,9,-1,STONE)
Block(-4,9,0,STONE)
Block(-4,9,1,OBSIDIAN:0)
Block(-4,9,2,STONE)
Block(-4,9,3,STONE)
Block(-4,9,4,STONE)
Block(-4,9,5,STONE)
Block(-4,9,6,OBSIDIAN:0)
Block(-4,9,7,STONE)
Block(-4,9,8,STONE)
Block(-4,10,-7,OBSIDIAN:0)
Block(-4,10,-6,CONCRETE:7)
Block(-4,10,-5,STONE)
Block(-4,10,-4,OBSIDIAN:0)
Block(-4,10,-3,STONE)
Block(-4,10,-2,STONE)
Block(-4,10,-1,OBSIDIAN:0)
Block(-4,10,0,OBSIDIAN:0)
Block(-4,10,1,STONE)
Block(-4,10,2,STONE)
Block(-4,10,3,STONE)
Block(-4,10,4,STONE)
Block(-4,10,5,STONE)
Block(-4,10,6,STONE)
Block(-4,10,7,STONE)
Block(-4,10,8,OBSIDIAN:0)
Block(-4,11,-7,OBSIDIAN:0)
Block(-4,11,-6,CONCRETE:7)
Block(-4,11,-5,STONE)
Block(-4,11,-4,OBSIDIAN:0)
Block(-4,11,-3,STONE)
Block(-4,11,-2,STONE)
Block(-4,11,-1,STONE)
Block(-4,11,0,STONE)
Block(-4,11,1,STONE)
Block(-4,11,2,STONE)
Block(-4,11,3,STONE)
Block(-4,11,4,STONE)
Block(-4,11,5,STONE)
Block(-4,11,6,OBSIDIAN:0)
Block(-4,11,7,STONE)
Block(-4,11,8,STONE)
Block(-4,12,-7,OBSIDIAN:0)
Block(-4,12,-6,CONCRETE:7)
Block(-4,12,-5,STONE)
Block(-4,12,-4,STONE)
Block(-4,12,-3,STONE)
Block(-4,12,-2,OBSIDIAN:0)
Block(-4,12,-1,STONE)
Block(-4,12,0,STONE)
Block(-4,12,1,OBSIDIAN:0)
Block(-4,12,2,STONE)
Block(-4,12,3,OBSIDIAN:0)
Block(-4,12,4,STONE)
Block(-4,12,5,STONE)
Block(-4,12,6,STONE)
Block(-4,12,7,STONE)
Block(-4,12,8,STONE)
Block(-4,13,-7,OBSIDIAN:0)
Block(-4,13,-6,CONCRETE:7)
Block(-4,13,-5,STONE)
Block(-4,13,-4,STONE)
Block(-4,13,-3,STONE)
Block(-4,13,-2,OBSIDIAN:0)
Block(-4,13,-1,OBSIDIAN:0)
Block(-4,13,0,OBSIDIAN:0)
Block(-4,13,1,STONE)
Block(-4,13,2,STONE)
Block(-4,13,3,STONE)
Block(-4,13,4,STONE)
Block(-4,13,5,STONE)
Block(-4,13,6,OBSIDIAN:0)
Block(-4,13,7,STONE)
Block(-4,13,8,OBSIDIAN:0)
Block(-4,14,-7,CONCRETE:7)
Block(-4,14,-6,CONCRETE:7)
Block(-4,14,-5,STONE)
Block(-4,14,-4,STONE)
Block(-4,14,-3,STONE)
Block(-4,14,-2,STONE)
Block(-4,14,-1,STONE)
Block(-4,14,0,STONE)
Block(-4,14,1,STONE)
Block(-4,14,2,STONE)
Block(-4,14,3,STONE)
Block(-4,14,4,STONE)
Block(-4,14,5,STONE)
Block(-4,14,6,OBSIDIAN:0)
Block(-4,14,7,STONE)
Block(-4,14,8,STONE)
Block(-4,15,-7,CONCRETE:7)
Block(-4,15,-6,CONCRETE:7)
Block(-4,15,-5,STONE)
Block(-4,15,-4,STONE)
Block(-4,15,-3,STONE)
Block(-4,15,-2,STONE)
Block(-4,15,-1,STONE)
Block(-4,15,0,STONE)
Block(-4,15,1,STONE)
Block(-4,15,2,STONE)
Block(-4,15,3,STONE)
Block(-4,15,4,OBSIDIAN:0)
Block(-4,15,5,STONE)
Block(-4,15,6,STONE)
Block(-4,15,7,STONE)
Block(-4,15,8,OBSIDIAN:0)
Block(-4,16,-7,CONCRETE:7)
Block(-4,16,-6,CONCRETE:7)
Block(-4,16,-5,STONE)
Block(-4,16,-4,OBSIDIAN:0)
Block(-4,16,-3,STONE)
Block(-4,16,-2,STONE)
Block(-4,16,-1,STONE)
Block(-4,16,0,OBSIDIAN:0)
Block(-4,16,1,STONE)
Block(-4,16,2,STONE)
Block(-4,16,3,STONE)
Block(-4,16,4,STONE)
Block(-4,16,5,OBSIDIAN:0)
Block(-4,16,6,STONE)
Block(-4,16,7,STONE)
Block(-4,16,8,STONE)
Block(-4,17,-7,CONCRETE:7)
Block(-4,17,-6,CONCRETE:7)
Block(-4,17,-5,STONE)
Block(-4,17,-4,STONE)
Block(-4,17,-3,OBSIDIAN:0)
Block(-4,17,-2,STONE)
Block(-4,17,-1,STONE)
Block(-4,17,0,STONE)
Block(-4,17,1,STONE)
Block(-4,17,2,STONE)
Block(-4,17,3,STONE)
Block(-4,17,4,STONE)
Block(-4,17,5,STONE)
Block(-4,17,6,OBSIDIAN:0)
Block(-4,17,7,STONE)
Block(-4,17,8,STONE)
Block(-4,18,-7,CONCRETE:7)
Block(-4,18,-6,CONCRETE:7)
Block(-4,18,-5,STONE)
Block(-4,18,-4,STONE)
Block(-4,18,-3,STONE)
Block(-4,18,-2,STONE)
Block(-4,18,-1,OBSIDIAN:0)
Block(-4,18,0,STONE)
Block(-4,18,1,STONE)
Block(-4,18,2,STONE)
Block(-4,18,3,STONE)
Block(-4,18,4,OBSIDIAN:0)
Block(-4,18,5,STONE)
Block(-4,18,6,STONE)
Block(-4,18,7,OBSIDIAN:0)
Block(-4,18,8,OBSIDIAN:0)
Block(-4,19,-7,CONCRETE:7)
Block(-4,19,-6,CONCRETE:7)
Block(-4,19,-5,STONE)
Block(-4,19,-4,STONE)
Block(-4,19,-3,STONE)
Block(-4,19,-2,STONE)
Block(-4,19,-1,STONE)
Block(-4,19,0,STONE)
Block(-4,19,1,OBSIDIAN:0)
Block(-4,19,2,STONE)
Block(-4,19,3,STONE)
Block(-4,19,4,STONE)
Block(-4,19,5,STONE)
Block(-4,19,6,STONE)
Block(-4,19,7,STONE)
Block(-4,19,8,OBSIDIAN:0)
Block(-4,20,-7,CONCRETE:7)
Block(-4,20,-6,CONCRETE:7)
Block(-4,20,-5,OBSIDIAN:0)
Block(-4,20,-4,STONE)
Block(-4,20,-3,STONE)
Block(-4,20,-2,STONE)
Block(-4,20,-1,STONE)
Block(-4,20,0,STONE)
Block(-4,20,1,STONE)
Block(-4,20,2,OBSIDIAN:0)
Block(-4,20,3,STONE)
Block(-4,20,4,STONE)
Block(-4,20,5,STONE)
Block(-4,20,6,STONE)
Block(-4,20,7,OBSIDIAN:0)
Block(-4,20,8,STONE)
Block(-4,21,-7,CONCRETE:7)
Block(-4,21,-6,CONCRETE:7)
Block(-4,21,-5,STONE)
Block(-4,21,-4,STONE)
Block(-4,21,-3,STONE)
Block(-4,21,-2,STONE)
Block(-4,21,-1,OBSIDIAN:0)
Block(-4,21,0,OBSIDIAN:0)
Block(-4,21,1,STONE)
Block(-4,21,2,STONE)
Block(-4,21,3,STONE)
Block(-4,21,4,STONE)
Block(-4,21,5,STONE)
Block(-4,21,6,STONE)
Block(-4,21,7,STONE)
Block(-4,21,8,STONE)
Block(-4,22,-7,CONCRETE:7)
Block(-4,22,-6,CONCRETE:7)
Block(-4,22,-5,STONE)
Block(-4,22,-4,STONE)
Block(-4,22,-3,OBSIDIAN:0)
Block(-4,22,-2,STONE)
Block(-4,22,-1,OBSIDIAN:0)
Block(-4,22,0,STONE)
Block(-4,22,1,STONE)
Block(-4,22,2,STONE)
Block(-4,22,3,STONE)
Block(-4,22,4,STONE)
Block(-4,22,5,STONE)
Block(-4,22,6,STONE)
Block(-4,22,7,STONE)
Block(-4,22,8,STONE)
Block(-4,23,-7,CONCRETE:7)
Block(-4,23,-6,CONCRETE:7)
Block(-4,23,-5,STONE)
Block(-4,23,-4,STONE)
Block(-4,23,-3,OBSIDIAN:0)
Block(-4,23,-2,STONE)
Block(-4,23,-1,STONE)
Block(-4,23,0,STONE)
Block(-4,23,1,OBSIDIAN:0)
Block(-4,23,2,STONE)
Block(-4,23,3,STONE)
Block(-4,23,4,STONE)
Block(-4,23,5,STONE)
Block(-4,23,6,OBSIDIAN:0)
Block(-4,23,7,STONE)
Block(-4,23,8,STONE)
Block(-4,24,-7,CONCRETE:7)
Block(-4,24,-6,CONCRETE:7)
Block(-4,24,-5,OBSIDIAN:0)
Block(-4,24,-4,STONE)
Block(-4,24,-3,STONE)
Block(-4,24,-2,STONE)
Block(-4,24,-1,STONE)
Block(-4,24,0,STONE)
Block(-4,24,1,OBSIDIAN:0)
Block(-4,24,2,STONE)
Block(-4,24,3,STONE)
Block(-4,24,4,STONE)
Block(-4,24,5,STONE)
Block(-4,24,6,STONE)
Block(-4,24,7,STONE)
Block(-4,24,8,OBSIDIAN:0)
Block(-4,25,-7,CONCRETE:7)
Block(-4,25,-6,CONCRETE:7)
Block(-4,25,-5,STONE)
Block(-4,25,-4,STONE)
Block(-4,25,-3,STONE)
Block(-4,25,-2,STONE)
Block(-4,25,-1,OBSIDIAN:0)
Block(-4,25,0,STONE)
Block(-4,25,1,STONE)
Block(-4,25,2,STONE)
Block(-4,25,3,OBSIDIAN:0)
Block(-4,25,4,STONE)
Block(-4,25,5,STONE)
Block(-4,25,6,OBSIDIAN:0)
Block(-4,25,7,STONE)
Block(-4,25,8,STONE)
Block(-4,26,-7,CONCRETE:7)
Block(-4,26,-6,CONCRETE:7)
Block(-4,26,-5,STONE)
Block(-4,26,-4,OBSIDIAN:0)
Block(-4,26,-3,STONE)
Block(-4,26,-2,STONE)
Block(-4,26,-1,STONE)
Block(-4,26,0,STONE)
Block(-4,26,1,OBSIDIAN:0)
Block(-4,26,2,OBSIDIAN:0)
Block(-4,26,3,OBSIDIAN:0)
Block(-4,26,4,STONE)
Block(-4,26,5,STONE)
Block(-4,26,6,STONE)
Block(-4,26,7,STONE)
Block(-4,26,8,STONE)
Block(-4,27,-7,CONCRETE:7)
Block(-4,27,-6,CONCRETE:7)
Block(-4,27,-5,STONE)
Block(-4,27,-4,STONE)
Block(-4,27,-3,OBSIDIAN:0)
Block(-4,27,-2,STONE)
Block(-4,27,-1,OBSIDIAN:0)
Block(-4,27,0,STONE)
Block(-4,27,1,STONE)
Block(-4,27,2,STONE)
Block(-4,27,3,STONE)
Block(-4,27,4,STONE)
Block(-4,27,5,STONE)
Block(-4,27,6,STONE)
Block(-4,27,7,STONE)
Block(-4,27,8,STONE)
Block(-4,28,-7,CONCRETE:7)
Block(-4,28,-6,CONCRETE:7)
Block(-4,28,-5,STONE)
Block(-4,28,-4,STONE)
Block(-4,28,-3,OBSIDIAN:0)
Block(-4,28,-2,OBSIDIAN:0)
Block(-4,28,-1,STONE)
Block(-4,28,0,STONE)
Block(-4,28,1,STONE)
Block(-4,28,2,STONE)
Block(-4,28,3,STONE)
Block(-4,28,4,OBSIDIAN:0)
Block(-4,28,5,STONE)
Block(-4,28,6,STONE)
Block(-4,28,7,STONE)
Block(-4,28,8,STONE)
Block(-4,29,-7,CONCRETE:7)
Block(-4,29,-6,CONCRETE:7)
Block(-4,29,-5,STONE)
Block(-4,29,-4,STONE)
Block(-4,29,-3,STONE)
Block(-4,29,-2,STONE)
Block(-4,29,-1,STONE)
Block(-4,29,0,STONE)
Block(-4,29,1,STONE)
Block(-4,29,2,STONE)
Block(-4,29,3,OBSIDIAN:0)
Block(-4,29,4,STONE)
Block(-4,29,5,STONE)
Block(-4,29,6,OBSIDIAN:0)
Block(-4,29,7,STONE)
Block(-4,29,8,STONE)
Block(-4,30,-7,CONCRETE:7)
Block(-4,30,-6,CONCRETE:7)
Block(-4,30,-5,STONE)
Block(-4,30,-4,STONE)
Block(-4,30,-3,STONE)
Block(-4,30,-2,STONE)
Block(-4,30,-1,OBSIDIAN:0)
Block(-4,30,0,STONE)
Block(-4,30,1,STONE)
Block(-4,30,2,OBSIDIAN:0)
Block(-4,30,3,OBSIDIAN:0)
Block(-4,30,4,STONE)
Block(-4,30,5,STONE)
Block(-4,30,6,STONE)
Block(-4,30,7,STONE)
Block(-4,30,8,STONE)
Block(-4,31,-7,SNOW:4)
Block(-4,31,-6,CONCRETE:7)
Block(-4,31,-5,STONE)
Block(-4,31,-4,STONE)
Block(-4,31,-3,OBSIDIAN:0)
Block(-4,31,-2,OBSIDIAN:0)
Block(-4,31,-1,STONE)
Block(-4,31,0,STONE)
Block(-4,31,1,STONE)
Block(-4,31,2,STONE)
Block(-4,31,3,STONE)
Block(-4,31,4,STONE)
Block(-4,31,5,STONE)
Block(-4,31,6,STONE)
Block(-4,31,7,STONE)
Block(-4,31,8,STONE)
Block(-4,32,-6,SNOW_BLOCK:0)
Block(-4,32,-5,CONCRETE:7)
Block(-4,32,-4,STONE)
Block(-4,32,-3,STONE)
Block(-4,32,-2,STONE)
Block(-4,32,-1,STONE)
Block(-4,32,0,STONE)
Block(-4,32,1,OBSIDIAN:0)
Block(-4,32,2,STONE)
Block(-4,32,3,OBSIDIAN:0)
Block(-4,32,4,STONE)
Block(-4,32,5,STONE)
Block(-4,32,6,STONE)
Block(-4,32,7,STONE)
Block(-4,32,8,STONE)
Block(-4,33,-5,SNOW_BLOCK:0)
Block(-4,33,-4,CONCRETE:7)
Block(-4,33,-3,STONE)
Block(-4,33,-2,STONE)
Block(-4,33,-1,STONE)
Block(-4,33,0,STONE)
Block(-4,33,1,STONE)
Block(-4,33,2,STONE)
Block(-4,33,3,STONE)
Block(-4,33,4,STONE)
Block(-4,33,5,STONE)
Block(-4,33,6,STONE)
Block(-4,33,7,STONE)
Block(-4,33,8,STONE)
Block(-4,34,-4,CONCRETE:7)
Block(-4,34,-3,CONCRETE:7)
Block(-4,34,-2,CONCRETE:7)
Block(-4,34,-1,CONCRETE:7)
Block(-4,34,0,CONCRETE:7)
Block(-4,34,1,CONCRETE:7)
Block(-4,34,2,CONCRETE:7)
Block(-4,34,3,CONCRETE:7)
Block(-4,34,4,OBSIDIAN:0)
Block(-4,34,5,OBSIDIAN:0)
Block(-4,34,6,OBSIDIAN:0)
Block(-4,34,7,OBSIDIAN:0)
Block(-4,34,8,OBSIDIAN:0)
Block(-4,35,-4,CONCRETE:7)
Block(-4,35,-3,CONCRETE:7)
Block(-4,35,5,SNOW:0)
Block(-4,35,6,SNOW:2)
Block(-4,35,7,SNOW:4)
Block(-4,35,8,SNOW:6)
Block(-4,36,-4,CONCRETE:7)
Block(-4,36,-3,CONCRETE:7)
Block(-4,37,-4,STEP:0)
Block(-4,37,-3,STEP:0)
Block(-4,38,-7,PACKED_ICE:0)
Block(-4,38,-6,PACKED_ICE:0)
Block(-4,38,-5,PACKED_ICE:0)
Block(-4,38,-4,PACKED_ICE:0)
Block(-4,38,-3,PACKED_ICE:0)
Block(-4,38,-2,PACKED_ICE:0)
Block(-4,39,-7,PACKED_ICE:0)
Block(-4,39,-6,PACKED_ICE:0)
Block(-4,39,-5,PACKED_ICE:0)
Block(-4,39,-4,PACKED_ICE:0)
Block(-4,39,-3,PACKED_ICE:0)
Block(-4,39,-2,PACKED_ICE:0)
Block(-4,39,-1,PACKED_ICE:0)
Block(-4,39,0,PACKED_ICE:0)
Block(-4,40,-7,PACKED_ICE:0)
Block(-4,40,-6,PACKED_ICE:0)
Block(-4,40,-5,PACKED_ICE:0)
Block(-4,40,-4,PACKED_ICE:0)
Block(-4,40,-3,PACKED_ICE:0)
Block(-4,40,-2,PACKED_ICE:0)
Block(-4,40,-1,PACKED_ICE:0)
Block(-4,40,0,PACKED_ICE:0)
Block(-4,40,1,PACKED_ICE:0)
Block(-4,41,-6,PACKED_ICE:0)
Block(-4,41,-5,PACKED_ICE:0)
Block(-4,41,-4,PACKED_ICE:0)
Block(-4,41,-3,PACKED_ICE:0)
Block(-4,41,-2,PACKED_ICE:0)
Block(-4,41,-1,PACKED_ICE:0)
Block(-4,41,0,PACKED_ICE:0)
Block(-4,41,1,PACKED_ICE:0)
Block(-4,41,2,PACKED_ICE:0)
Block(-4,42,-5,PACKED_ICE:0)
Block(-4,42,-4,PACKED_ICE:0)
Block(-4,42,-3,PACKED_ICE:0)
Block(-4,42,-2,PACKED_ICE:0)
Block(-4,42,-1,PACKED_ICE:0)
Block(-4,42,0,PACKED_ICE:0)
Block(-4,42,1,PACKED_ICE:0)
Block(-4,42,2,PACKED_ICE:0)
Block(-4,43,-4,PACKED_ICE:0)
Block(-4,43,-3,PACKED_ICE:0)
Block(-4,43,-2,PACKED_ICE:0)
Block(-4,43,-1,PACKED_ICE:0)
Block(-4,43,0,PACKED_ICE:0)
Block(-4,43,1,PACKED_ICE:0)
Block(-4,43,2,PACKED_ICE:0)
Block(-4,44,-4,PACKED_ICE:0)
Block(-4,44,-3,PACKED_ICE:0)
Block(-4,44,-2,PACKED_ICE:0)
Block(-4,44,-1,PACKED_ICE:0)
Block(-4,44,0,PACKED_ICE:0)
Block(-4,44,1,PACKED_ICE:0)
Block(-4,44,2,PACKED_ICE:0)
Block(-4,44,3,PACKED_ICE:0)
Block(-4,45,-3,PACKED_ICE:0)
Block(-4,45,-2,PACKED_ICE:0)
Block(-4,45,-1,PACKED_ICE:0)
Block(-4,45,0,PACKED_ICE:0)
Block(-4,45,1,PACKED_ICE:0)
Block(-4,45,2,PACKED_ICE:0)
Block(-4,45,3,PACKED_ICE:0)
Block(-4,46,-2,PACKED_ICE:0)
Block(-4,46,-1,PACKED_ICE:0)
Block(-4,46,0,PACKED_ICE:0)
Block(-4,46,1,PACKED_ICE:0)
Block(-4,46,2,PACKED_ICE:0)
Block(-4,46,3,PACKED_ICE:0)
Block(-3,0,-7,CONCRETE:7)
Block(-3,0,-6,CONCRETE:7)
Block(-3,0,-5,CONCRETE:7)
Block(-3,0,-4,CONCRETE:7)
Block(-3,0,-3,CONCRETE:7)
Block(-3,0,-2,CONCRETE:7)
Block(-3,0,-1,CONCRETE:7)
Block(-3,0,0,CONCRETE:7)
Block(-3,0,1,CONCRETE:7)
Block(-3,0,2,CONCRETE:7)
Block(-3,0,3,CONCRETE:7)
Block(-3,0,4,CONCRETE:7)
Block(-3,0,5,CONCRETE:7)
Block(-3,0,6,CONCRETE:7)
Block(-3,0,7,CONCRETE:7)
Block(-3,0,8,CONCRETE:7)
Block(-3,1,-7,CONCRETE:7)
Block(-3,1,-6,CONCRETE:7)
Block(-3,1,-5,OBSIDIAN:0)
Block(-3,1,-4,STONE)
Block(-3,1,-3,STONE)
Block(-3,1,-2,STONE)
Block(-3,1,-1,STONE)
Block(-3,1,0,OBSIDIAN:0)
Block(-3,1,1,STONE)
Block(-3,1,2,STONE)
Block(-3,1,3,STONE)
Block(-3,1,4,STONE)
Block(-3,1,5,OBSIDIAN:0)
Block(-3,1,6,STONE)
Block(-3,1,7,STONE)
Block(-3,1,8,OBSIDIAN:0)
Block(-3,2,-7,CONCRETE:7)
Block(-3,2,-6,CONCRETE:7)
Block(-3,2,-5,STONE)
Block(-3,2,-4,STONE)
Block(-3,2,-3,OBSIDIAN:0)
Block(-3,2,-2,OBSIDIAN:0)
Block(-3,2,-1,STONE)
Block(-3,2,0,STONE)
Block(-3,2,1,STONE)
Block(-3,2,2,STONE)
Block(-3,2,3,STONE)
Block(-3,2,4,STONE)
Block(-3,2,5,OBSIDIAN:0)
Block(-3,2,6,OBSIDIAN:0)
Block(-3,2,7,OBSIDIAN:0)
Block(-3,2,8,STONE)
Block(-3,3,-7,CONCRETE:7)
Block(-3,3,-6,CONCRETE:7)
Block(-3,3,-5,OBSIDIAN:0)
Block(-3,3,-4,STONE)
Block(-3,3,-3,STONE)
Block(-3,3,-2,OBSIDIAN:0)
Block(-3,3,-1,STONE)
Block(-3,3,0,STONE)
Block(-3,3,1,STONE)
Block(-3,3,2,OBSIDIAN:0)
Block(-3,3,3,STONE)
Block(-3,3,4,STONE)
Block(-3,3,5,OBSIDIAN:0)
Block(-3,3,6,OBSIDIAN:0)
Block(-3,3,7,OBSIDIAN:0)
Block(-3,3,8,OBSIDIAN:0)
Block(-3,4,-7,CONCRETE:7)
Block(-3,4,-6,CONCRETE:7)
Block(-3,4,-5,STONE)
Block(-3,4,-4,OBSIDIAN:0)
Block(-3,4,-3,STONE)
Block(-3,4,-2,STONE)
Block(-3,4,-1,OBSIDIAN:0)
Block(-3,4,0,OBSIDIAN:0)
Block(-3,4,1,OBSIDIAN:0)
Block(-3,4,2,OBSIDIAN:0)
Block(-3,4,3,OBSIDIAN:0)
Block(-3,4,4,OBSIDIAN:0)
Block(-3,4,5,OBSIDIAN:0)
Block(-3,4,6,OBSIDIAN:0)
Block(-3,4,7,OBSIDIAN:0)
Block(-3,4,8,OBSIDIAN:0)
Block(-3,5,-7,CONCRETE:7)
Block(-3,5,-6,CONCRETE:7)
Block(-3,5,-5,STONE)
Block(-3,5,-4,STONE)
Block(-3,5,-3,STONE)
Block(-3,5,-2,STONE)
Block(-3,5,-1,OBSIDIAN:0)
Block(-3,5,0,OBSIDIAN:0)
Block(-3,5,1,OBSIDIAN:0)
Block(-3,5,2,OBSIDIAN:0)
Block(-3,5,3,OBSIDIAN:0)
Block(-3,5,4,OBSIDIAN:0)
Block(-3,5,5,OBSIDIAN:0)
Block(-3,5,6,OBSIDIAN:0)
Block(-3,5,7,OBSIDIAN:0)
Block(-3,5,8,OBSIDIAN:0)
Block(-3,6,-7,CONCRETE:7)
Block(-3,6,-6,CONCRETE:7)
Block(-3,6,-5,STONE)
Block(-3,6,-4,STONE)
Block(-3,6,-3,STONE)
Block(-3,6,-2,STONE)
Block(-3,6,-1,OBSIDIAN:0)
Block(-3,6,0,OBSIDIAN:0)
Block(-3,6,1,OBSIDIAN:0)
Block(-3,6,2,OBSIDIAN:0)
Block(-3,6,3,OBSIDIAN:0)
Block(-3,6,4,OBSIDIAN:0)
Block(-3,6,5,OBSIDIAN:0)
Block(-3,6,6,OBSIDIAN:0)
Block(-3,6,7,OBSIDIAN:0)
Block(-3,6,8,OBSIDIAN:0)
Block(-3,7,-7,CONCRETE:7)
Block(-3,7,-6,CONCRETE:7)
Block(-3,7,-5,STONE)
Block(-3,7,-4,OBSIDIAN:0)
Block(-3,7,-3,OBSIDIAN:0)
Block(-3,7,-2,STONE)
Block(-3,7,-1,OBSIDIAN:0)
Block(-3,7,0,OBSIDIAN:0)
Block(-3,7,1,OBSIDIAN:0)
Block(-3,7,2,OBSIDIAN:0)
Block(-3,7,3,OBSIDIAN:0)
Block(-3,7,4,OBSIDIAN:0)
Block(-3,7,5,OBSIDIAN:0)
Block(-3,7,6,OBSIDIAN:0)
Block(-3,7,7,OBSIDIAN:0)
Block(-3,7,8,STONE)
Block(-3,8,-7,CONCRETE:7)
Block(-3,8,-6,CONCRETE:7)
Block(-3,8,-5,STONE)
Block(-3,8,-4,OBSIDIAN:0)
Block(-3,8,-3,STONE)
Block(-3,8,-2,OBSIDIAN:0)
Block(-3,8,-1,STONE)
Block(-3,8,0,STONE)
Block(-3,8,1,STONE)
Block(-3,8,2,OBSIDIAN:0)
Block(-3,8,3,OBSIDIAN:0)
Block(-3,8,4,OBSIDIAN:0)
Block(-3,8,5,OBSIDIAN:0)
Block(-3,8,6,OBSIDIAN:0)
Block(-3,8,7,STONE)
Block(-3,8,8,OBSIDIAN:0)
Block(-3,9,-7,OBSIDIAN:0)
Block(-3,9,-6,CONCRETE:7)
Block(-3,9,-5,STONE)
Block(-3,9,-4,STONE)
Block(-3,9,-3,OBSIDIAN:0)
Block(-3,9,-2,STONE)
Block(-3,9,-1,STONE)
Block(-3,9,0,STONE)
Block(-3,9,1,STONE)
Block(-3,9,2,STONE)
Block(-3,9,3,STONE)
Block(-3,9,4,STONE)
Block(-3,9,5,OBSIDIAN:0)
Block(-3,9,6,OBSIDIAN:0)
Block(-3,9,7,STONE)
Block(-3,9,8,STONE)
Block(-3,10,-7,OBSIDIAN:0)
Block(-3,10,-6,CONCRETE:7)
Block(-3,10,-5,STONE)
Block(-3,10,-4,STONE)
Block(-3,10,-3,STONE)
Block(-3,10,-2,STONE)
Block(-3,10,-1,STONE)
Block(-3,10,0,STONE)
Block(-3,10,1,OBSIDIAN:0)
Block(-3,10,2,STONE)
Block(-3,10,3,STONE)
Block(-3,10,4,STONE)
Block(-3,10,5,STONE)
Block(-3,10,6,STONE)
Block(-3,10,7,STONE)
Block(-3,10,8,STONE)
Block(-3,11,-7,OBSIDIAN:0)
Block(-3,11,-6,CONCRETE:7)
Block(-3,11,-5,STONE)
Block(-3,11,-4,STONE)
Block(-3,11,-3,OBSIDIAN:0)
Block(-3,11,-2,STONE)
Block(-3,11,-1,STONE)
Block(-3,11,0,STONE)
Block(-3,11,1,STONE)
Block(-3,11,2,STONE)
Block(-3,11,3,OBSIDIAN:0)
Block(-3,11,4,STONE)
Block(-3,11,5,STONE)
Block(-3,11,6,OBSIDIAN:0)
Block(-3,11,7,STONE)
Block(-3,11,8,STONE)
Block(-3,12,-7,OBSIDIAN:0)
Block(-3,12,-6,CONCRETE:7)
Block(-3,12,-5,STONE)
Block(-3,12,-4,OBSIDIAN:0)
Block(-3,12,-3,OBSIDIAN:0)
Block(-3,12,-2,STONE)
Block(-3,12,-1,STONE)
Block(-3,12,0,STONE)
Block(-3,12,1,OBSIDIAN:0)
Block(-3,12,2,STONE)
Block(-3,12,3,STONE)
Block(-3,12,4,STONE)
Block(-3,12,5,STONE)
Block(-3,12,6,STONE)
Block(-3,12,7,STONE)
Block(-3,12,8,STONE)
Block(-3,13,-7,CONCRETE:7)
Block(-3,13,-6,CONCRETE:7)
Block(-3,13,-5,STONE)
Block(-3,13,-4,STONE)
Block(-3,13,-3,STONE)
Block(-3,13,-2,STONE)
Block(-3,13,-1,OBSIDIAN:0)
Block(-3,13,0,STONE)
Block(-3,13,1,STONE)
Block(-3,13,2,STONE)
Block(-3,13,3,STONE)
Block(-3,13,4,OBSIDIAN:0)
Block(-3,13,5,STONE)
Block(-3,13,6,STONE)
Block(-3,13,7,STONE)
Block(-3,13,8,OBSIDIAN:0)
Block(-3,14,-7,CONCRETE:7)
Block(-3,14,-6,CONCRETE:7)
Block(-3,14,-5,OBSIDIAN:0)
Block(-3,14,-4,OBSIDIAN:0)
Block(-3,14,-3,STONE)
Block(-3,14,-2,STONE)
Block(-3,14,-1,OBSIDIAN:0)
Block(-3,14,0,STONE)
Block(-3,14,1,OBSIDIAN:0)
Block(-3,14,2,STONE)
Block(-3,14,3,OBSIDIAN:0)
Block(-3,14,4,STONE)
Block(-3,14,5,STONE)
Block(-3,14,6,OBSIDIAN:0)
Block(-3,14,7,STONE)
Block(-3,14,8,STONE)
Block(-3,15,-7,CONCRETE:7)
Block(-3,15,-6,CONCRETE:7)
Block(-3,15,-5,STONE)
Block(-3,15,-4,OBSIDIAN:0)
Block(-3,15,-3,STONE)
Block(-3,15,-2,STONE)
Block(-3,15,-1,STONE)
Block(-3,15,0,STONE)
Block(-3,15,1,STONE)
Block(-3,15,2,STONE)
Block(-3,15,3,STONE)
Block(-3,15,4,STONE)
Block(-3,15,5,STONE)
Block(-3,15,6,STONE)
Block(-3,15,7,STONE)
Block(-3,15,8,STONE)
Block(-3,16,-7,CONCRETE:7)
Block(-3,16,-6,CONCRETE:7)
Block(-3,16,-5,STONE)
Block(-3,16,-4,STONE)
Block(-3,16,-3,STONE)
Block(-3,16,-2,STONE)
Block(-3,16,-1,STONE)
Block(-3,16,0,STONE)
Block(-3,16,1,STONE)
Block(-3,16,2,OBSIDIAN:0)
Block(-3,16,3,STONE)
Block(-3,16,4,STONE)
Block(-3,16,5,STONE)
Block(-3,16,6,STONE)
Block(-3,16,7,STONE)
Block(-3,16,8,STONE)
Block(-3,17,-7,CONCRETE:7)
Block(-3,17,-6,CONCRETE:7)
Block(-3,17,-5,OBSIDIAN:0)
Block(-3,17,-4,STONE)
Block(-3,17,-3,OBSIDIAN:0)
Block(-3,17,-2,OBSIDIAN:0)
Block(-3,17,-1,STONE)
Block(-3,17,0,STONE)
Block(-3,17,1,STONE)
Block(-3,17,2,STONE)
Block(-3,17,3,STONE)
Block(-3,17,4,STONE)
Block(-3,17,5,OBSIDIAN:0)
Block(-3,17,6,STONE)
Block(-3,17,7,STONE)
Block(-3,17,8,STONE)
Block(-3,18,-7,CONCRETE:7)
Block(-3,18,-6,CONCRETE:7)
Block(-3,18,-5,STONE)
Block(-3,18,-4,OBSIDIAN:0)
Block(-3,18,-3,STONE)
Block(-3,18,-2,STONE)
Block(-3,18,-1,STONE)
Block(-3,18,0,STONE)
Block(-3,18,1,STONE)
Block(-3,18,2,STONE)
Block(-3,18,3,STONE)
Block(-3,18,4,STONE)
Block(-3,18,5,OBSIDIAN:0)
Block(-3,18,6,STONE)
Block(-3,18,7,STONE)
Block(-3,18,8,STONE)
Block(-3,19,-7,CONCRETE:7)
Block(-3,19,-6,CONCRETE:7)
Block(-3,19,-5,STONE)
Block(-3,19,-4,OBSIDIAN:0)
Block(-3,19,-3,STONE)
Block(-3,19,-2,STONE)
Block(-3,19,-1,STONE)
Block(-3,19,0,STONE)
Block(-3,19,1,STONE)
Block(-3,19,2,STONE)
Block(-3,19,3,STONE)
Block(-3,19,4,STONE)
Block(-3,19,5,STONE)
Block(-3,19,6,STONE)
Block(-3,19,7,STONE)
Block(-3,19,8,STONE)
Block(-3,20,-7,CONCRETE:7)
Block(-3,20,-6,CONCRETE:7)
Block(-3,20,-5,OBSIDIAN:0)
Block(-3,20,-4,OBSIDIAN:0)
Block(-3,20,-3,STONE)
Block(-3,20,-2,STONE)
Block(-3,20,-1,STONE)
Block(-3,20,0,STONE)
Block(-3,20,1,STONE)
Block(-3,20,2,STONE)
Block(-3,20,3,STONE)
Block(-3,20,4,STONE)
Block(-3,20,5,STONE)
Block(-3,20,6,STONE)
Block(-3,20,7,STONE)
Block(-3,20,8,STONE)
Block(-3,21,-7,CONCRETE:7)
Block(-3,21,-6,CONCRETE:7)
Block(-3,21,-5,STONE)
Block(-3,21,-4,STONE)
Block(-3,21,-3,STONE)
Block(-3,21,-2,STONE)
Block(-3,21,-1,OBSIDIAN:0)
Block(-3,21,0,STONE)
Block(-3,21,1,STONE)
Block(-3,21,2,STONE)
Block(-3,21,3,STONE)
Block(-3,21,4,STONE)
Block(-3,21,5,STONE)
Block(-3,21,6,STONE)
Block(-3,21,7,STONE)
Block(-3,21,8,OBSIDIAN:0)
Block(-3,22,-7,CONCRETE:7)
Block(-3,22,-6,CONCRETE:7)
Block(-3,22,-5,STONE)
Block(-3,22,-4,STONE)
Block(-3,22,-3,STONE)
Block(-3,22,-2,OBSIDIAN:0)
Block(-3,22,-1,STONE)
Block(-3,22,0,STONE)
Block(-3,22,1,STONE)
Block(-3,22,2,STONE)
Block(-3,22,3,STONE)
Block(-3,22,4,STONE)
Block(-3,22,5,STONE)
Block(-3,22,6,OBSIDIAN:0)
Block(-3,22,7,OBSIDIAN:0)
Block(-3,22,8,STONE)
Block(-3,23,-7,CONCRETE:7)
Block(-3,23,-6,CONCRETE:7)
Block(-3,23,-5,STONE)
Block(-3,23,-4,OBSIDIAN:0)
Block(-3,23,-3,STONE)
Block(-3,23,-2,STONE)
Block(-3,23,-1,OBSIDIAN:0)
Block(-3,23,0,STONE)
Block(-3,23,1,STONE)
Block(-3,23,2,STONE)
Block(-3,23,3,STONE)
Block(-3,23,4,STONE)
Block(-3,23,5,STONE)
Block(-3,23,6,STONE)
Block(-3,23,7,STONE)
Block(-3,23,8,OBSIDIAN:0)
Block(-3,24,-7,CONCRETE:7)
Block(-3,24,-6,CONCRETE:7)
Block(-3,24,-5,STONE)
Block(-3,24,-4,STONE)
Block(-3,24,-3,STONE)
Block(-3,24,-2,STONE)
Block(-3,24,-1,STONE)
Block(-3,24,0,STONE)
Block(-3,24,1,STONE)
Block(-3,24,2,STONE)
Block(-3,24,3,STONE)
Block(-3,24,4,STONE)
Block(-3,24,5,STONE)
Block(-3,24,6,OBSIDIAN:0)
Block(-3,24,7,STONE)
Block(-3,24,8,STONE)
Block(-3,25,-7,CONCRETE:7)
Block(-3,25,-6,CONCRETE:7)
Block(-3,25,-5,OBSIDIAN:0)
Block(-3,25,-4,OBSIDIAN:0)
Block(-3,25,-3,STONE)
Block(-3,25,-2,STONE)
Block(-3,25,-1,STONE)
Block(-3,25,0,STONE)
Block(-3,25,1,STONE)
Block(-3,25,2,STONE)
Block(-3,25,3,OBSIDIAN:0)
Block(-3,25,4,STONE)
Block(-3,25,5,STONE)
Block(-3,25,6,OBSIDIAN:0)
Block(-3,25,7,STONE)
Block(-3,25,8,STONE)
Block(-3,26,-7,CONCRETE:7)
Block(-3,26,-6,CONCRETE:7)
Block(-3,26,-5,STONE)
Block(-3,26,-4,STONE)
Block(-3,26,-3,STONE)
Block(-3,26,-2,STONE)
Block(-3,26,-1,STONE)
Block(-3,26,0,STONE)
Block(-3,26,1,STONE)
Block(-3,26,2,STONE)
Block(-3,26,3,STONE)
Block(-3,26,4,STONE)
Block(-3,26,5,STONE)
Block(-3,26,6,STONE)
Block(-3,26,7,OBSIDIAN:0)
Block(-3,26,8,STONE)
Block(-3,27,-7,CONCRETE:7)
Block(-3,27,-6,CONCRETE:7)
Block(-3,27,-5,STONE)
Block(-3,27,-4,STONE)
Block(-3,27,-3,OBSIDIAN:0)
Block(-3,27,-2,STONE)
Block(-3,27,-1,STONE)
Block(-3,27,0,OBSIDIAN:0)
Block(-3,27,1,STONE)
Block(-3,27,2,STONE)
Block(-3,27,3,STONE)
Block(-3,27,4,OBSIDIAN:0)
Block(-3,27,5,STONE)
Block(-3,27,6,OBSIDIAN:0)
Block(-3,27,7,STONE)
Block(-3,27,8,STONE)
Block(-3,28,-7,CONCRETE:7)
Block(-3,28,-6,CONCRETE:7)
Block(-3,28,-5,OBSIDIAN:0)
Block(-3,28,-4,OBSIDIAN:0)
Block(-3,28,-3,STONE)
Block(-3,28,-2,OBSIDIAN:0)
Block(-3,28,-1,STONE)
Block(-3,28,0,OBSIDIAN:0)
Block(-3,28,1,STONE)
Block(-3,28,2,STONE)
Block(-3,28,3,OBSIDIAN:0)
Block(-3,28,4,STONE)
Block(-3,28,5,STONE)
Block(-3,28,6,STONE)
Block(-3,28,7,STONE)
Block(-3,28,8,STONE)
Block(-3,29,-7,CONCRETE:7)
Block(-3,29,-6,CONCRETE:7)
Block(-3,29,-5,STONE)
Block(-3,29,-4,STONE)
Block(-3,29,-3,STONE)
Block(-3,29,-2,STONE)
Block(-3,29,-1,STONE)
Block(-3,29,0,STONE)
Block(-3,29,1,STONE)
Block(-3,29,2,STONE)
Block(-3,29,3,STONE)
Block(-3,29,4,STONE)
Block(-3,29,5,STONE)
Block(-3,29,6,STONE)
Block(-3,29,7,STONE)
Block(-3,29,8,STONE)
Block(-3,30,-7,CONCRETE:7)
Block(-3,30,-6,CONCRETE:7)
Block(-3,30,-5,STONE)
Block(-3,30,-4,STONE)
Block(-3,30,-3,STONE)
Block(-3,30,-2,STONE)
Block(-3,30,-1,STONE)
Block(-3,30,0,STONE)
Block(-3,30,1,STONE)
Block(-3,30,2,STONE)
Block(-3,30,3,STONE)
Block(-3,30,4,STONE)
Block(-3,30,5,STONE)
Block(-3,30,6,STONE)
Block(-3,30,7,STONE)
Block(-3,30,8,STONE)
Block(-3,31,-7,SNOW_BLOCK:0)
Block(-3,31,-6,CONCRETE:7)
Block(-3,31,-5,OBSIDIAN:0)
Block(-3,31,-4,STONE)
Block(-3,31,-3,STONE)
Block(-3,31,-2,STONE)
Block(-3,31,-1,STONE)
Block(-3,31,0,OBSIDIAN:0)
Block(-3,31,1,STONE)
Block(-3,31,2,OBSIDIAN:0)
Block(-3,31,3,STONE)
Block(-3,31,4,STONE)
Block(-3,31,5,OBSIDIAN:0)
Block(-3,31,6,STONE)
Block(-3,31,7,STONE)
Block(-3,31,8,STONE)
Block(-3,32,-6,SNOW_BLOCK:0)
Block(-3,32,-5,CONCRETE:7)
Block(-3,32,-4,STONE)
Block(-3,32,-3,STONE)
Block(-3,32,-2,STONE)
Block(-3,32,-1,STONE)
Block(-3,32,0,STONE)
Block(-3,32,1,STONE)
Block(-3,32,2,OBSIDIAN:0)
Block(-3,32,3,STONE)
Block(-3,32,4,STONE)
Block(-3,32,5,STONE)
Block(-3,32,6,STONE)
Block(-3,32,7,OBSIDIAN:0)
Block(-3,32,8,OBSIDIAN:0)
Block(-3,33,-5,SNOW_BLOCK:0)
Block(-3,33,-4,CONCRETE:7)
Block(-3,33,-3,STONE)
Block(-3,33,-2,STONE)
Block(-3,33,-1,STONE)
Block(-3,33,0,STONE)
Block(-3,33,1,STONE)
Block(-3,33,2,OBSIDIAN:0)
Block(-3,33,3,OBSIDIAN:0)
Block(-3,33,4,STONE)
Block(-3,33,5,STONE)
Block(-3,33,6,STONE)
Block(-3,33,7,STONE)
Block(-3,33,8,STONE)
Block(-3,34,-4,SNOW_BLOCK:0)
Block(-3,34,-3,CONCRETE:7)
Block(-3,34,-2,STONE)
Block(-3,34,-1,OBSIDIAN:0)
Block(-3,34,0,STONE)
Block(-3,34,1,OBSIDIAN:0)
Block(-3,34,2,STONE)
Block(-3,34,3,STONE)
Block(-3,34,4,STONE)
Block(-3,34,5,STONE)
Block(-3,34,6,STONE)
Block(-3,34,7,STONE)
Block(-3,34,8,STONE)
Block(-3,35,-3,SNOW_BLOCK:0)
Block(-3,35,-2,CONCRETE:7)
Block(-3,35,-1,CONCRETE:7)
Block(-3,35,0,CONCRETE:7)
Block(-3,35,1,CONCRETE:7)
Block(-3,35,2,CONCRETE:7)
Block(-3,35,3,CONCRETE:7)
Block(-3,35,4,CONCRETE:7)
Block(-3,35,5,OBSIDIAN:0)
Block(-3,35,6,OBSIDIAN:0)
Block(-3,35,7,OBSIDIAN:0)
Block(-3,35,8,OBSIDIAN:0)
Block(-3,36,-3,SNOW:1)
Block(-3,36,-2,SNOW:3)
Block(-3,36,3,SNOW:0)
Block(-3,36,4,SNOW:0)
Block(-3,36,5,SNOW:1)
Block(-3,36,6,SNOW:4)
Block(-3,36,7,SNOW:6)
Block(-3,36,8,SNOW_BLOCK:0)
Block(-3,37,8,SNOW:1)
Block(-3,39,-4,PACKED_ICE:0)
Block(-3,39,-3,PACKED_ICE:0)
Block(-3,39,-2,PACKED_ICE:0)
Block(-3,40,-7,PACKED_ICE:0)
Block(-3,40,-6,PACKED_ICE:0)
Block(-3,40,-5,PACKED_ICE:0)
Block(-3,40,-4,PACKED_ICE:0)
Block(-3,40,-3,PACKED_ICE:0)
Block(-3,40,-2,PACKED_ICE:0)
Block(-3,40,-1,PACKED_ICE:0)
Block(-3,40,0,PACKED_ICE:0)
Block(-3,41,-6,PACKED_ICE:0)
Block(-3,41,-5,PACKED_ICE:0)
Block(-3,41,-4,PACKED_ICE:0)
Block(-3,41,-3,PACKED_ICE:0)
Block(-3,41,-2,PACKED_ICE:0)
Block(-3,41,-1,PACKED_ICE:0)
Block(-3,41,0,PACKED_ICE:0)
Block(-3,41,1,PACKED_ICE:0)
Block(-3,41,2,PACKED_ICE:0)
Block(-3,42,-5,PACKED_ICE:0)
Block(-3,42,-4,PACKED_ICE:0)
Block(-3,42,-3,PACKED_ICE:0)
Block(-3,42,-2,PACKED_ICE:0)
Block(-3,42,-1,PACKED_ICE:0)
Block(-3,42,0,PACKED_ICE:0)
Block(-3,42,1,PACKED_ICE:0)
Block(-3,42,2,PACKED_ICE:0)
Block(-3,42,3,PACKED_ICE:0)
Block(-3,43,-4,PACKED_ICE:0)
Block(-3,43,-3,PACKED_ICE:0)
Block(-3,43,-2,PACKED_ICE:0)
Block(-3,43,-1,PACKED_ICE:0)
Block(-3,43,0,PACKED_ICE:0)
Block(-3,43,1,PACKED_ICE:0)
Block(-3,43,2,PACKED_ICE:0)
Block(-3,43,3,PACKED_ICE:0)
Block(-3,44,-3,PACKED_ICE:0)
Block(-3,44,-2,PACKED_ICE:0)
Block(-3,44,-1,PACKED_ICE:0)
Block(-3,44,0,PACKED_ICE:0)
Block(-3,44,1,PACKED_ICE:0)
Block(-3,44,2,PACKED_ICE:0)
Block(-3,44,3,PACKED_ICE:0)
Block(-3,45,-3,PACKED_ICE:0)
Block(-3,45,-2,PACKED_ICE:0)
Block(-3,45,-1,PACKED_ICE:0)
Block(-3,45,0,PACKED_ICE:0)
Block(-3,45,1,PACKED_ICE:0)
Block(-3,45,2,PACKED_ICE:0)
Block(-3,45,3,PACKED_ICE:0)
Block(-3,45,4,PACKED_ICE:0)
Block(-3,46,-2,PACKED_ICE:0)
Block(-3,46,-1,PACKED_ICE:0)
Block(-3,46,0,PACKED_ICE:0)
Block(-3,46,1,PACKED_ICE:0)
Block(-3,46,2,PACKED_ICE:0)
Block(-3,46,3,PACKED_ICE:0)
Block(-3,46,4,PACKED_ICE:0)
Block(-3,47,-1,PACKED_ICE:0)
Block(-3,47,0,PACKED_ICE:0)
Block(-3,47,1,PACKED_ICE:0)
Block(-3,47,2,PACKED_ICE:0)
Block(-3,47,3,PACKED_ICE:0)
Block(-3,47,4,PACKED_ICE:0)
Block(-2,0,-7,CONCRETE:7)
Block(-2,0,-6,CONCRETE:7)
Block(-2,0,-5,CONCRETE:7)
Block(-2,0,-4,CONCRETE:7)
Block(-2,0,-3,CONCRETE:7)
Block(-2,0,-2,CONCRETE:7)
Block(-2,0,-1,CONCRETE:7)
Block(-2,0,0,CONCRETE:7)
Block(-2,0,1,CONCRETE:7)
Block(-2,0,2,CONCRETE:7)
Block(-2,0,3,CONCRETE:7)
Block(-2,0,4,CONCRETE:7)
Block(-2,0,5,CONCRETE:7)
Block(-2,0,6,CONCRETE:7)
Block(-2,0,7,CONCRETE:7)
Block(-2,0,8,CONCRETE:7)
Block(-2,1,-7,CONCRETE:7)
Block(-2,1,-6,CONCRETE:7)
Block(-2,1,-5,OBSIDIAN:0)
Block(-2,1,-4,STONE)
Block(-2,1,-3,STONE)
Block(-2,1,-2,STONE)
Block(-2,1,-1,OBSIDIAN:0)
Block(-2,1,0,STONE)
Block(-2,1,1,STONE)
Block(-2,1,2,STONE)
Block(-2,1,3,STONE)
Block(-2,1,4,OBSIDIAN:0)
Block(-2,1,5,STONE)
Block(-2,1,6,STONE)
Block(-2,1,7,OBSIDIAN:0)
Block(-2,1,8,STONE)
Block(-2,2,-7,CONCRETE:7)
Block(-2,2,-6,CONCRETE:7)
Block(-2,2,-5,STONE)
Block(-2,2,-4,STONE)
Block(-2,2,-3,STONE)
Block(-2,2,-2,STONE)
Block(-2,2,-1,STONE)
Block(-2,2,0,OBSIDIAN:0)
Block(-2,2,1,OBSIDIAN:0)
Block(-2,2,2,STONE)
Block(-2,2,3,STONE)
Block(-2,2,4,STONE)
Block(-2,2,5,STONE)
Block(-2,2,6,OBSIDIAN:0)
Block(-2,2,7,STONE)
Block(-2,2,8,OBSIDIAN:0)
Block(-2,3,-7,CONCRETE:7)
Block(-2,3,-6,CONCRETE:7)
Block(-2,3,-5,STONE)
Block(-2,3,-4,OBSIDIAN:0)
Block(-2,3,-3,OBSIDIAN:0)
Block(-2,3,-2,STONE)
Block(-2,3,-1,OBSIDIAN:0)
Block(-2,3,0,STONE)
Block(-2,3,1,OBSIDIAN:0)
Block(-2,3,2,OBSIDIAN:0)
Block(-2,3,3,OBSIDIAN:0)
Block(-2,3,4,OBSIDIAN:0)
Block(-2,3,5,OBSIDIAN:0)
Block(-2,3,6,OBSIDIAN:0)
Block(-2,3,7,OBSIDIAN:0)
Block(-2,3,8,OBSIDIAN:0)
Block(-2,4,-7,CONCRETE:7)
Block(-2,4,-6,CONCRETE:7)
Block(-2,4,-5,STONE)
Block(-2,4,-4,STONE)
Block(-2,4,-3,STONE)
Block(-2,4,-2,STONE)
Block(-2,4,-1,OBSIDIAN:0)
Block(-2,4,0,OBSIDIAN:0)
Block(-2,4,1,OBSIDIAN:0)
Block(-2,4,2,OBSIDIAN:0)
Block(-2,4,3,OBSIDIAN:0)
Block(-2,4,4,MAGMA:0)
Block(-2,4,5,OBSIDIAN:0)
Block(-2,4,6,MAGMA:0)
Block(-2,4,7,OBSIDIAN:0)
Block(-2,4,8,OBSIDIAN:0)
Block(-2,5,-7,CONCRETE:7)
Block(-2,5,-6,CONCRETE:7)
Block(-2,5,-5,STONE)
Block(-2,5,-4,STONE)
Block(-2,5,-3,OBSIDIAN:0)
Block(-2,5,-2,OBSIDIAN:0)
Block(-2,5,-1,OBSIDIAN:0)
Block(-2,5,0,OBSIDIAN:0)
Block(-2,5,1,MAGMA:0)
Block(-2,5,2,OBSIDIAN:0)
Block(-2,5,3,MAGMA:0)
Block(-2,5,4,OBSIDIAN:0)
Block(-2,5,5,OBSIDIAN:0)
Block(-2,5,6,MAGMA:0)
Block(-2,5,7,OBSIDIAN:0)
Block(-2,5,8,MAGMA:0)
Block(-2,6,-7,CONCRETE:7)
Block(-2,6,-6,CONCRETE:7)
Block(-2,6,-5,STONE)
Block(-2,6,-4,STONE)
Block(-2,6,-3,STONE)
Block(-2,6,-2,OBSIDIAN:0)
Block(-2,6,-1,OBSIDIAN:0)
Block(-2,6,0,OBSIDIAN:0)
Block(-2,6,1,OBSIDIAN:0)
Block(-2,6,2,OBSIDIAN:0)
Block(-2,6,3,MAGMA:0)
Block(-2,6,4,OBSIDIAN:0)
Block(-2,6,5,OBSIDIAN:0)
Block(-2,6,6,MAGMA:0)
Block(-2,6,7,OBSIDIAN:0)
Block(-2,6,8,MAGMA:0)
Block(-2,7,-7,CONCRETE:7)
Block(-2,7,-6,CONCRETE:7)
Block(-2,7,-5,STONE)
Block(-2,7,-4,STONE)
Block(-2,7,-3,STONE)
Block(-2,7,-2,OBSIDIAN:0)
Block(-2,7,-1,OBSIDIAN:0)
Block(-2,7,0,OBSIDIAN:0)
Block(-2,7,1,OBSIDIAN:0)
Block(-2,7,2,OBSIDIAN:0)
Block(-2,7,3,OBSIDIAN:0)
Block(-2,7,4,OBSIDIAN:0)
Block(-2,7,5,OBSIDIAN:0)
Block(-2,7,6,OBSIDIAN:0)
Block(-2,7,7,OBSIDIAN:0)
Block(-2,7,8,OBSIDIAN:0)
Block(-2,8,-7,OBSIDIAN:0)
Block(-2,8,-6,CONCRETE:7)
Block(-2,8,-5,STONE)
Block(-2,8,-4,OBSIDIAN:0)
Block(-2,8,-3,STONE)
Block(-2,8,-2,OBSIDIAN:0)
Block(-2,8,-1,OBSIDIAN:0)
Block(-2,8,0,OBSIDIAN:0)
Block(-2,8,1,MAGMA:0)
Block(-2,8,2,OBSIDIAN:0)
Block(-2,8,3,OBSIDIAN:0)
Block(-2,8,4,MAGMA:0)
Block(-2,8,5,OBSIDIAN:0)
Block(-2,8,6,OBSIDIAN:0)
Block(-2,8,7,OBSIDIAN:0)
Block(-2,8,8,STONE)
Block(-2,9,-7,OBSIDIAN:0)
Block(-2,9,-6,CONCRETE:7)
Block(-2,9,-5,STONE)
Block(-2,9,-4,STONE)
Block(-2,9,-3,STONE)
Block(-2,9,-2,STONE)
Block(-2,9,-1,STONE)
Block(-2,9,0,STONE)
Block(-2,9,1,STONE)
Block(-2,9,2,STONE)
Block(-2,9,3,STONE)
Block(-2,9,4,OBSIDIAN:0)
Block(-2,9,5,STONE)
Block(-2,9,6,STONE)
Block(-2,9,7,STONE)
Block(-2,9,8,STONE)
Block(-2,10,-7,OBSIDIAN:0)
Block(-2,10,-6,CONCRETE:7)
Block(-2,10,-5,OBSIDIAN:0)
Block(-2,10,-4,OBSIDIAN:0)
Block(-2,10,-3,STONE)
Block(-2,10,-2,STONE)
Block(-2,10,-1,STONE)
Block(-2,10,0,STONE)
Block(-2,10,1,OBSIDIAN:0)
Block(-2,10,2,STONE)
Block(-2,10,3,STONE)
Block(-2,10,4,OBSIDIAN:0)
Block(-2,10,5,OBSIDIAN:0)
Block(-2,10,6,STONE)
Block(-2,10,7,OBSIDIAN:0)
Block(-2,10,8,STONE)
Block(-2,11,-7,OBSIDIAN:0)
Block(-2,11,-6,CONCRETE:7)
Block(-2,11,-5,OBSIDIAN:0)
Block(-2,11,-4,STONE)
Block(-2,11,-3,STONE)
Block(-2,11,-2,STONE)
Block(-2,11,-1,OBSIDIAN:0)
Block(-2,11,0,STONE)
Block(-2,11,1,STONE)
Block(-2,11,2,STONE)
Block(-2,11,3,STONE)
Block(-2,11,4,STONE)
Block(-2,11,5,OBSIDIAN:0)
Block(-2,11,6,STONE)
Block(-2,11,7,STONE)
Block(-2,11,8,STONE)
Block(-2,12,-7,CONCRETE:7)
Block(-2,12,-6,CONCRETE:7)
Block(-2,12,-5,STONE)
Block(-2,12,-4,OBSIDIAN:0)
Block(-2,12,-3,STONE)
Block(-2,12,-2,STONE)
Block(-2,12,-1,STONE)
Block(-2,12,0,OBSIDIAN:0)
