
#######################################################################
# +-----------------------------------------------------------------+ #
# |                            BO4 object                           | #
# +-----------------------------------------------------------------+ #
#######################################################################

Author: NLBlackEagle

Description: No description given

SettingsMode: WriteDisable


#######################################################################
# +-----------------------------------------------------------------+ #
# |                          Main settings                          | #
# +-----------------------------------------------------------------+ #
#######################################################################

Frequency: 0

SpawnHeight: highestBlock

UseCenterForHighestBlock: true

##############################
# Height Limits for the BO4. #
##############################

MinHeight: 0

MaxHeight: 255

InheritBO3: 

InheritBO3Rotation: NORTH

OverrideChildSettings: true

OverrideParentHeight: false

CanOverride: true

BranchFrequency: 0

BranchFrequencyGroup: 

MustBeBelowOther: false

MustBeInside: 

CannotBeInside: 

ReplacesBO3: 

MustBeInsideWorldBorders: false

CanSpawnOnWater: true

SpawnOnWaterOnly: false

SpawnUnderWater: false

SpawnAtWaterLevel: false

HeightOffset: 0

RemoveAir: true

ReplaceAbove: 

ReplaceBelow: 

ReplaceWithBiomeBlocks: true

ReplaceWithSurfaceBlock: GRASS

ReplaceWithGroundBlock: DIRT

ReplaceWithStoneBlock: STONE

SmoothRadius: 0

SmoothHeightOffset: 0

SmoothStartTop: false

SmoothStartWood: false

SmoothingSurfaceBlock: 

SmoothingGroundBlock: 

BO3Group: 

IsSpawnPoint: false

DoReplaceBlocks: true


#######################################################################
# +-----------------------------------------------------------------+ #
# |                              Blocks                             | #
# +-----------------------------------------------------------------+ #
#######################################################################

Block(-2,26,8,SANDSTONE)
Block(-2,27,8,SANDSTONE)
Block(-2,28,8,SANDSTONE)
Block(-2,29,7,SANDSTONE)
Block(-2,29,8,SANDSTONE)
Block(-2,30,7,SANDSTONE)
Block(-2,30,8,SANDSTONE)
Block(-2,31,6,SANDSTONE)
Block(-2,31,7,SANDSTONE)
Block(-2,32,6,SANDSTONE)
Block(-2,33,5,SANDSTONE)
Block(-2,33,6,SANDSTONE)
Block(-2,34,5,SANDSTONE)
Block(-2,35,4,SANDSTONE)
Block(-1,23,8,OBSIDIAN)
Block(-1,24,8,OBSIDIAN)
Block(-1,25,8,OBSIDIAN)
Block(-1,26,7,OBSIDIAN)
Block(-1,26,8,SANDSTONE)
Block(-1,27,7,SANDSTONE)
Block(-1,27,8,SANDSTONE)
Block(-1,28,6,OBSIDIAN)
Block(-1,28,7,SANDSTONE)
Block(-1,28,8,SANDSTONE)
Block(-1,29,6,SANDSTONE)
Block(-1,29,7,SANDSTONE)
Block(-1,29,8,SANDSTONE)
Block(-1,30,5,SANDSTONE)
Block(-1,30,6,SANDSTONE)
Block(-1,30,7,SANDSTONE)
Block(-1,30,8,SANDSTONE)
Block(-1,31,5,SANDSTONE)
Block(-1,31,6,SANDSTONE)
Block(-1,31,7,SANDSTONE)
Block(-1,31,8,SANDSTONE)
Block(-1,32,4,SANDSTONE)
Block(-1,32,5,SANDSTONE)
Block(-1,32,6,SANDSTONE)
Block(-1,32,7,SANDSTONE)
Block(-1,32,8,SANDSTONE)
Block(-1,33,4,SANDSTONE)
Block(-1,33,5,SANDSTONE)
Block(-1,33,6,SANDSTONE)
Block(-1,33,7,SANDSTONE)
Block(-1,34,3,SANDSTONE)
Block(-1,34,4,SANDSTONE)
Block(-1,34,5,SANDSTONE)
Block(-1,34,6,SANDSTONE)
Block(-1,35,3,SANDSTONE)
Block(-1,35,4,SANDSTONE)
Block(-1,35,5,SANDSTONE)
Block(-1,35,6,SANDSTONE)
Block(-1,36,2,SANDSTONE)
Block(-1,36,3,SANDSTONE)
Block(-1,36,4,SANDSTONE)
Block(-1,36,5,SANDSTONE)
Block(-1,37,2,SANDSTONE)
Block(-1,37,3,SANDSTONE)
Block(-1,37,4,SANDSTONE)
Block(-1,38,1,SANDSTONE)
Block(-1,38,2,SANDSTONE)
Block(-1,38,3,SANDSTONE)
Block(-1,39,1,SANDSTONE)
Block(-1,39,2,SANDSTONE)
Block(-1,40,0,SANDSTONE)
Block(-1,40,1,SANDSTONE)
Block(-1,40,2,SANDSTONE)
Block(-1,41,0,SANDSTONE)
Block(-1,41,1,SANDSTONE)
Block(-1,42,-1,SANDSTONE)
Block(-1,42,0,SANDSTONE)
Block(-1,43,-1,SANDSTONE)
Block(-1,44,-2,SANDSTONE)
Block(-1,45,-2,SANDSTONE)
Block(0,20,8,OBSIDIAN)
Block(0,21,8,OBSIDIAN)
Block(0,22,8,OBSIDIAN)
Block(0,23,7,OBSIDIAN)
Block(0,23,8,OBSIDIAN)
Block(0,24,7,OBSIDIAN)
Block(0,24,8,OBSIDIAN)
Block(0,25,6,OBSIDIAN)
Block(0,25,7,OBSIDIAN)
Block(0,25,8,OBSIDIAN)
Block(0,26,6,OBSIDIAN)
Block(0,26,7,OBSIDIAN)
Block(0,26,8,SANDSTONE)
Block(0,27,5,OBSIDIAN)
Block(0,27,6,OBSIDIAN)
Block(0,27,7,SANDSTONE)
Block(0,27,8,SANDSTONE)
Block(0,28,5,OBSIDIAN)
Block(0,28,6,OBSIDIAN)
Block(0,28,7,SANDSTONE)
Block(0,28,8,SANDSTONE)
Block(0,29,4,OBSIDIAN)
Block(0,29,5,OBSIDIAN)
Block(0,29,6,SANDSTONE)
Block(0,29,7,SANDSTONE)
Block(0,29,8,SANDSTONE)
Block(0,30,4,OBSIDIAN)
Block(0,30,5,SANDSTONE)
Block(0,30,6,SANDSTONE)
Block(0,30,7,SANDSTONE)
Block(0,30,8,SANDSTONE)
Block(0,31,3,OBSIDIAN)
Block(0,31,4,SANDSTONE)
Block(0,31,5,SANDSTONE)
Block(0,31,6,SANDSTONE)
Block(0,31,7,SANDSTONE)
Block(0,31,8,SANDSTONE)
Block(0,32,3,OBSIDIAN)
Block(0,32,4,SANDSTONE)
Block(0,32,5,SANDSTONE)
Block(0,32,6,SANDSTONE)
Block(0,32,7,SANDSTONE)
Block(0,32,8,SANDSTONE)
Block(0,33,2,OBSIDIAN)
Block(0,33,3,OBSIDIAN)
Block(0,33,4,SANDSTONE)
Block(0,33,5,SANDSTONE)
Block(0,33,6,SANDSTONE)
Block(0,33,7,SANDSTONE)
Block(0,33,8,SANDSTONE)
Block(0,34,2,OBSIDIAN)
Block(0,34,3,SANDSTONE)
Block(0,34,4,SANDSTONE)
Block(0,34,5,SANDSTONE)
Block(0,34,6,SANDSTONE)
Block(0,34,7,SANDSTONE)
Block(0,34,8,SANDSTONE)
Block(0,35,1,OBSIDIAN)
Block(0,35,2,SANDSTONE)
Block(0,35,3,SANDSTONE)
Block(0,35,4,SANDSTONE)
Block(0,35,5,SANDSTONE)
Block(0,35,6,SANDSTONE)
Block(0,35,7,SANDSTONE)
Block(0,36,1,OBSIDIAN)
Block(0,36,2,SANDSTONE)
Block(0,36,3,SANDSTONE)
Block(0,36,4,SANDSTONE)
Block(0,36,5,SANDSTONE)
Block(0,36,6,SANDSTONE)
Block(0,37,0,OBSIDIAN)
Block(0,37,1,SANDSTONE)
Block(0,37,2,SANDSTONE)
Block(0,37,3,SANDSTONE)
Block(0,37,4,SANDSTONE)
Block(0,37,5,SANDSTONE)
Block(0,37,6,SANDSTONE)
Block(0,38,0,SANDSTONE)
Block(0,38,1,SANDSTONE)
Block(0,38,2,SANDSTONE)
Block(0,38,3,SANDSTONE)
Block(0,38,4,SANDSTONE)
Block(0,38,5,SANDSTONE)
Block(0,39,-1,SANDSTONE)
Block(0,39,0,SANDSTONE)
Block(0,39,1,SANDSTONE)
Block(0,39,2,SANDSTONE)
Block(0,39,3,SANDSTONE)
Block(0,39,4,SANDSTONE)
Block(0,40,-1,SANDSTONE)
Block(0,40,0,SANDSTONE)
Block(0,40,1,SANDSTONE)
Block(0,40,2,SANDSTONE)
Block(0,40,3,SANDSTONE)
Block(0,41,-1,SANDSTONE)
Block(0,41,0,SANDSTONE)
Block(0,41,1,SANDSTONE)
Block(0,41,2,SANDSTONE)
Block(0,42,-2,SANDSTONE)
Block(0,42,-1,SANDSTONE)
Block(0,42,0,SANDSTONE)
Block(0,42,1,SANDSTONE)
Block(0,42,2,SANDSTONE)
Block(0,43,-2,SANDSTONE)
Block(0,43,-1,SANDSTONE)
Block(0,43,0,SANDSTONE)
Block(0,43,1,SANDSTONE)
Block(0,44,-3,SANDSTONE)
Block(0,44,-2,SANDSTONE)
Block(0,44,-1,SANDSTONE)
Block(0,44,0,SANDSTONE)
Block(0,45,-3,SANDSTONE)
Block(0,45,-2,SANDSTONE)
Block(0,45,-1,SANDSTONE)
Block(0,46,-4,SANDSTONE)
Block(0,46,-3,SANDSTONE)
Block(0,46,-2,SANDSTONE)
Block(0,47,-4,SANDSTONE)
Block(0,47,-3,SANDSTONE)
Block(0,47,-2,SANDSTONE)
Block(0,48,-5,SANDSTONE)
Block(0,48,-4,SANDSTONE)
Block(0,48,-3,SANDSTONE)
Block(0,49,-5,SANDSTONE)
Block(0,49,-4,SANDSTONE)
Block(0,50,-6,SANDSTONE)
Block(0,50,-5,SANDSTONE)
Block(0,51,-6,SANDSTONE)
Block(0,52,-7,SANDSTONE)
Block(0,52,-6,SANDSTONE)
Block(0,53,-7,SANDSTONE)
Block(1,17,8,OBSIDIAN)
Block(1,18,8,OBSIDIAN)
Block(1,19,8,OBSIDIAN)
Block(1,20,7,OBSIDIAN)
Block(1,20,8,OBSIDIAN)
Block(1,21,7,OBSIDIAN)
Block(1,21,8,OBSIDIAN)
Block(1,22,6,OBSIDIAN)
Block(1,22,7,OBSIDIAN)
Block(1,22,8,OBSIDIAN)
Block(1,23,6,OBSIDIAN)
Block(1,23,7,OBSIDIAN)
Block(1,23,8,OBSIDIAN)
Block(1,24,5,OBSIDIAN)
Block(1,24,6,OBSIDIAN)
Block(1,24,7,OBSIDIAN)
Block(1,24,8,OBSIDIAN)
Block(1,25,5,OBSIDIAN)
Block(1,25,6,OBSIDIAN)
Block(1,25,7,OBSIDIAN)
Block(1,25,8,OBSIDIAN)
Block(1,26,4,OBSIDIAN)
Block(1,26,5,OBSIDIAN)
Block(1,26,6,OBSIDIAN)
Block(1,26,7,OBSIDIAN)
Block(1,26,8,SANDSTONE)
Block(1,27,4,OBSIDIAN)
Block(1,27,5,OBSIDIAN)
Block(1,27,6,OBSIDIAN)
Block(1,27,7,SANDSTONE)
Block(1,27,8,SANDSTONE)
Block(1,28,3,OBSIDIAN)
Block(1,28,4,OBSIDIAN)
Block(1,28,5,OBSIDIAN)
Block(1,28,6,OBSIDIAN)
Block(1,28,7,SANDSTONE)
Block(1,28,8,SANDSTONE)
Block(1,29,3,OBSIDIAN)
Block(1,29,4,OBSIDIAN)
Block(1,29,5,OBSIDIAN)
Block(1,29,6,SANDSTONE)
Block(1,29,7,SANDSTONE)
Block(1,29,8,SANDSTONE)
Block(1,30,2,OBSIDIAN)
Block(1,30,3,OBSIDIAN)
Block(1,30,4,OBSIDIAN)
Block(1,30,5,SANDSTONE)
Block(1,30,6,SANDSTONE)
Block(1,30,7,SANDSTONE)
Block(1,30,8,SANDSTONE)
Block(1,31,2,OBSIDIAN)
Block(1,31,3,OBSIDIAN)
Block(1,31,4,SANDSTONE)
Block(1,31,5,SANDSTONE)
Block(1,31,6,SANDSTONE)
Block(1,31,7,SANDSTONE)
Block(1,31,8,SANDSTONE)
Block(1,32,1,OBSIDIAN)
Block(1,32,2,OBSIDIAN)
Block(1,32,3,OBSIDIAN)
Block(1,32,4,SANDSTONE)
Block(1,32,5,SANDSTONE)
Block(1,32,6,SANDSTONE)
Block(1,32,7,SANDSTONE)
Block(1,32,8,SANDSTONE)
Block(1,33,1,OBSIDIAN)
Block(1,33,2,OBSIDIAN)
Block(1,33,3,OBSIDIAN)
Block(1,33,4,SANDSTONE)
Block(1,33,5,SANDSTONE)
Block(1,33,6,SANDSTONE)
Block(1,33,7,SANDSTONE)
Block(1,33,8,SANDSTONE)
Block(1,34,0,OBSIDIAN)
Block(1,34,1,OBSIDIAN)
Block(1,34,2,OBSIDIAN)
Block(1,34,3,SANDSTONE)
Block(1,34,4,SANDSTONE)
Block(1,34,5,SANDSTONE)
Block(1,34,6,SANDSTONE)
Block(1,34,7,SANDSTONE)
Block(1,34,8,SANDSTONE)
Block(1,35,0,OBSIDIAN)
Block(1,35,1,OBSIDIAN)
Block(1,35,2,SANDSTONE)
Block(1,35,3,SANDSTONE)
Block(1,35,4,SANDSTONE)
Block(1,35,5,SANDSTONE)
Block(1,35,6,SANDSTONE)
Block(1,35,7,SANDSTONE)
Block(1,35,8,SANDSTONE)
Block(1,36,-1,OBSIDIAN)
Block(1,36,0,OBSIDIAN)
Block(1,36,1,OBSIDIAN)
Block(1,36,2,SANDSTONE)
Block(1,36,3,SANDSTONE)
Block(1,36,4,SANDSTONE)
Block(1,36,5,SANDSTONE)
Block(1,36,6,SANDSTONE)
Block(1,36,7,SANDSTONE)
Block(1,36,8,SANDSTONE)
Block(1,37,-1,OBSIDIAN)
Block(1,37,0,OBSIDIAN)
Block(1,37,1,SANDSTONE)
Block(1,37,2,SANDSTONE)
Block(1,37,3,SANDSTONE)
Block(1,37,4,SANDSTONE)
Block(1,37,5,SANDSTONE)
Block(1,37,6,SANDSTONE)
Block(1,37,7,SANDSTONE)
Block(1,38,-1,OBSIDIAN)
Block(1,38,0,SANDSTONE)
Block(1,38,1,SANDSTONE)
Block(1,38,2,SANDSTONE)
Block(1,38,3,SANDSTONE)
Block(1,38,4,SANDSTONE)
Block(1,38,5,SANDSTONE)
Block(1,38,6,SANDSTONE)
Block(1,39,-2,OBSIDIAN)
Block(1,39,-1,SANDSTONE)
Block(1,39,0,SANDSTONE)
Block(1,39,1,SANDSTONE)
Block(1,39,2,SANDSTONE)
Block(1,39,3,SANDSTONE)
Block(1,39,4,SANDSTONE)
Block(1,39,5,SANDSTONE)
Block(1,39,6,SANDSTONE)
Block(1,40,-2,SANDSTONE)
Block(1,40,-1,SANDSTONE)
Block(1,40,0,SANDSTONE)
Block(1,40,1,SANDSTONE)
Block(1,40,2,SANDSTONE)
Block(1,40,3,SANDSTONE)
Block(1,40,4,SANDSTONE)
Block(1,40,5,SANDSTONE)
Block(1,41,-3,OBSIDIAN)
Block(1,41,-2,SANDSTONE)
Block(1,41,-1,SANDSTONE)
Block(1,41,0,SANDSTONE)
Block(1,41,1,SANDSTONE)
Block(1,41,2,SANDSTONE)
Block(1,41,3,SANDSTONE)
Block(1,41,4,SANDSTONE)
Block(1,42,-3,OBSIDIAN)
Block(1,42,-2,SANDSTONE)
Block(1,42,-1,SANDSTONE)
Block(1,42,0,SANDSTONE)
Block(1,42,1,SANDSTONE)
Block(1,42,2,SANDSTONE)
Block(1,42,3,SANDSTONE)
Block(1,43,-4,OBSIDIAN)
Block(1,43,-3,SANDSTONE)
Block(1,43,-2,SANDSTONE)
Block(1,43,-1,SANDSTONE)
Block(1,43,0,SANDSTONE)
Block(1,43,1,SANDSTONE)
Block(1,43,2,SANDSTONE)
Block(1,44,-4,SANDSTONE)
Block(1,44,-3,SANDSTONE)
Block(1,44,-2,SANDSTONE)
Block(1,44,-1,SANDSTONE)
Block(1,44,0,SANDSTONE)
Block(1,44,1,SANDSTONE)
Block(1,44,2,SANDSTONE)
Block(1,45,-5,SANDSTONE)
Block(1,45,-4,SANDSTONE)
Block(1,45,-3,SANDSTONE)
Block(1,45,-2,SANDSTONE)
Block(1,45,-1,SANDSTONE)
Block(1,45,0,SANDSTONE)
Block(1,45,1,SANDSTONE)
Block(1,46,-5,SANDSTONE)
Block(1,46,-4,SANDSTONE)
Block(1,46,-3,SANDSTONE)
Block(1,46,-2,SANDSTONE)
Block(1,46,-1,SANDSTONE)
Block(1,46,0,SANDSTONE)
Block(1,47,-6,OBSIDIAN)
Block(1,47,-5,SANDSTONE)
Block(1,47,-4,SANDSTONE)
Block(1,47,-3,SANDSTONE)
Block(1,47,-2,SANDSTONE)
Block(1,47,-1,SANDSTONE)
Block(1,48,-6,SANDSTONE)
Block(1,48,-5,SANDSTONE)
Block(1,48,-4,SANDSTONE)
Block(1,48,-3,SANDSTONE)
Block(1,48,-2,SANDSTONE)
Block(1,49,-7,SANDSTONE)
Block(1,49,-6,SANDSTONE)
Block(1,49,-5,SANDSTONE)
Block(1,49,-4,SANDSTONE)
Block(1,49,-3,SANDSTONE)
Block(1,49,-2,SANDSTONE)
Block(1,50,-7,SANDSTONE)
Block(1,50,-6,SANDSTONE)
Block(1,50,-5,SANDSTONE)
Block(1,50,-4,SANDSTONE)
Block(1,50,-3,SANDSTONE)
Block(1,51,-7,SANDSTONE)
Block(1,51,-6,SANDSTONE)
Block(1,51,-5,SANDSTONE)
Block(1,51,-4,SANDSTONE)
Block(1,52,-7,SANDSTONE)
Block(1,52,-6,SANDSTONE)
Block(1,52,-5,SANDSTONE)
Block(1,53,-7,SANDSTONE)
Block(1,53,-6,SANDSTONE)
Block(1,54,-7,SANDSTONE)
Block(1,54,-6,SANDSTONE)
Block(1,55,-7,SANDSTONE)
Block(2,15,8,OBSIDIAN)
Block(2,16,8,OBSIDIAN)
Block(2,17,7,OBSIDIAN)
Block(2,17,8,OBSIDIAN)
Block(2,18,7,OBSIDIAN)
Block(2,18,8,OBSIDIAN)
Block(2,19,6,OBSIDIAN)
Block(2,19,7,OBSIDIAN)
Block(2,19,8,OBSIDIAN)
Block(2,20,6,OBSIDIAN)
Block(2,20,7,OBSIDIAN)
Block(2,20,8,OBSIDIAN)
Block(2,21,5,OBSIDIAN)
Block(2,21,6,OBSIDIAN)
Block(2,21,7,OBSIDIAN)
Block(2,21,8,OBSIDIAN)
Block(2,22,5,OBSIDIAN)
Block(2,22,6,OBSIDIAN)
Block(2,22,7,OBSIDIAN)
Block(2,22,8,OBSIDIAN)
Block(2,23,4,OBSIDIAN)
Block(2,23,5,OBSIDIAN)
Block(2,23,6,OBSIDIAN)
Block(2,23,7,OBSIDIAN)
Block(2,23,8,OBSIDIAN)
Block(2,24,4,OBSIDIAN)
Block(2,24,5,OBSIDIAN)
Block(2,24,6,OBSIDIAN)
Block(2,24,7,OBSIDIAN)
Block(2,24,8,OBSIDIAN)
Block(2,25,3,OBSIDIAN)
Block(2,25,4,OBSIDIAN)
Block(2,25,5,OBSIDIAN)
Block(2,25,6,OBSIDIAN)
Block(2,25,7,OBSIDIAN)
Block(2,25,8,OBSIDIAN)
Block(2,26,3,OBSIDIAN)
Block(2,26,4,OBSIDIAN)
Block(2,26,5,OBSIDIAN)
Block(2,26,6,OBSIDIAN)
Block(2,26,7,OBSIDIAN)
Block(2,26,8,SANDSTONE)
Block(2,27,2,OBSIDIAN)
Block(2,27,3,OBSIDIAN)
Block(2,27,4,OBSIDIAN)
Block(2,27,5,OBSIDIAN)
Block(2,27,6,OBSIDIAN)
Block(2,27,7,OBSIDIAN)
Block(2,27,8,SANDSTONE)
Block(2,28,2,OBSIDIAN)
Block(2,28,3,OBSIDIAN)
Block(2,28,4,OBSIDIAN)
Block(2,28,5,OBSIDIAN)
Block(2,28,6,OBSIDIAN)
Block(2,28,7,SANDSTONE)
Block(2,28,8,SANDSTONE)
Block(2,29,1,OBSIDIAN)
Block(2,29,2,OBSIDIAN)
Block(2,29,3,OBSIDIAN)
Block(2,29,4,OBSIDIAN)
Block(2,29,5,OBSIDIAN)
Block(2,29,6,SANDSTONE)
Block(2,29,7,SANDSTONE)
Block(2,29,8,SANDSTONE)
Block(2,30,1,OBSIDIAN)
Block(2,30,2,OBSIDIAN)
Block(2,30,3,OBSIDIAN)
Block(2,30,4,OBSIDIAN)
Block(2,30,5,SANDSTONE)
Block(2,30,6,SANDSTONE)
Block(2,30,7,SANDSTONE)
Block(2,30,8,SANDSTONE)
Block(2,31,0,OBSIDIAN)
Block(2,31,1,OBSIDIAN)
Block(2,31,2,OBSIDIAN)
Block(2,31,3,OBSIDIAN)
Block(2,31,4,OBSIDIAN)
Block(2,31,5,SANDSTONE)
Block(2,31,6,SANDSTONE)
Block(2,31,7,SANDSTONE)
Block(2,31,8,SANDSTONE)
Block(2,32,0,OBSIDIAN)
Block(2,32,1,OBSIDIAN)
Block(2,32,2,OBSIDIAN)
Block(2,32,3,OBSIDIAN)
Block(2,32,4,SANDSTONE)
Block(2,32,5,SANDSTONE)
Block(2,32,6,SANDSTONE)
Block(2,32,7,SANDSTONE)
Block(2,32,8,SANDSTONE)
Block(2,33,-1,OBSIDIAN)
Block(2,33,0,OBSIDIAN)
Block(2,33,1,OBSIDIAN)
Block(2,33,2,OBSIDIAN)
Block(2,33,3,OBSIDIAN)
Block(2,33,4,SANDSTONE)
Block(2,33,5,SANDSTONE)
Block(2,33,6,SANDSTONE)
Block(2,33,7,SANDSTONE)
Block(2,33,8,SANDSTONE)
Block(2,34,-1,OBSIDIAN)
Block(2,34,0,OBSIDIAN)
Block(2,34,1,OBSIDIAN)
Block(2,34,2,OBSIDIAN)
Block(2,34,3,SANDSTONE)
Block(2,34,4,SANDSTONE)
Block(2,34,5,SANDSTONE)
Block(2,34,6,SANDSTONE)
Block(2,34,7,SANDSTONE)
Block(2,34,8,SANDSTONE)
Block(2,35,-1,OBSIDIAN)
Block(2,35,0,OBSIDIAN)
Block(2,35,1,OBSIDIAN)
Block(2,35,2,SANDSTONE)
Block(2,35,3,SANDSTONE)
Block(2,35,4,SANDSTONE)
Block(2,35,5,SANDSTONE)
Block(2,35,6,SANDSTONE)
Block(2,35,7,SANDSTONE)
Block(2,35,8,SANDSTONE)
Block(2,36,-2,OBSIDIAN)
Block(2,36,-1,OBSIDIAN)
Block(2,36,0,OBSIDIAN)
Block(2,36,1,OBSIDIAN)
Block(2,36,2,SANDSTONE)
Block(2,36,3,SANDSTONE)
Block(2,36,4,SANDSTONE)
Block(2,36,5,SANDSTONE)
Block(2,36,6,SANDSTONE)
Block(2,36,7,SANDSTONE)
Block(2,36,8,SANDSTONE)
Block(2,37,-2,OBSIDIAN)
Block(2,37,-1,OBSIDIAN)
Block(2,37,0,OBSIDIAN)
Block(2,37,1,SANDSTONE)
Block(2,37,2,SANDSTONE)
Block(2,37,3,SANDSTONE)
Block(2,37,4,SANDSTONE)
Block(2,37,5,SANDSTONE)
Block(2,37,6,SANDSTONE)
Block(2,37,7,SANDSTONE)
Block(2,37,8,SANDSTONE)
Block(2,38,-3,OBSIDIAN)
Block(2,38,-2,OBSIDIAN)
Block(2,38,-1,OBSIDIAN)
Block(2,38,0,SANDSTONE)
Block(2,38,1,SANDSTONE)
Block(2,38,2,SANDSTONE)
Block(2,38,3,SANDSTONE)
Block(2,38,4,SANDSTONE)
Block(2,38,5,SANDSTONE)
Block(2,38,6,SANDSTONE)
Block(2,38,7,SANDSTONE)
Block(2,39,-3,OBSIDIAN)
Block(2,39,-2,OBSIDIAN)
Block(2,39,-1,SANDSTONE)
Block(2,39,0,SANDSTONE)
Block(2,39,1,SANDSTONE)
Block(2,39,2,SANDSTONE)
Block(2,39,3,SANDSTONE)
Block(2,39,4,SANDSTONE)
Block(2,39,5,SANDSTONE)
Block(2,39,6,SANDSTONE)
Block(2,40,-4,OBSIDIAN)
Block(2,40,-3,OBSIDIAN)
Block(2,40,-2,SANDSTONE)
Block(2,40,-1,SANDSTONE)
Block(2,40,0,SANDSTONE)
Block(2,40,1,SANDSTONE)
Block(2,40,2,SANDSTONE)
Block(2,40,3,SANDSTONE)
Block(2,40,4,SANDSTONE)
Block(2,40,5,SANDSTONE)
Block(2,41,-4,OBSIDIAN)
Block(2,41,-3,OBSIDIAN)
Block(2,41,-2,SANDSTONE)
Block(2,41,-1,SANDSTONE)
Block(2,41,0,SANDSTONE)
Block(2,41,1,SANDSTONE)
Block(2,41,2,SANDSTONE)
Block(2,41,3,SANDSTONE)
Block(2,41,4,SANDSTONE)
Block(2,41,5,SANDSTONE)
Block(2,42,-5,OBSIDIAN)
Block(2,42,-4,OBSIDIAN)
Block(2,42,-3,OBSIDIAN)
Block(2,42,-2,SANDSTONE)
Block(2,42,-1,SANDSTONE)
Block(2,42,0,SANDSTONE)
Block(2,42,1,SANDSTONE)
Block(2,42,2,SANDSTONE)
Block(2,42,3,SANDSTONE)
Block(2,42,4,SANDSTONE)
Block(2,43,-5,OBSIDIAN)
Block(2,43,-4,OBSIDIAN)
Block(2,43,-3,SANDSTONE)
Block(2,43,-2,SANDSTONE)
Block(2,43,-1,SANDSTONE)
Block(2,43,0,SANDSTONE)
Block(2,43,1,SANDSTONE)
Block(2,43,2,SANDSTONE)
Block(2,43,3,SANDSTONE)
Block(2,44,-6,OBSIDIAN)
Block(2,44,-5,OBSIDIAN)
Block(2,44,-4,SANDSTONE)
Block(2,44,-3,SANDSTONE)
Block(2,44,-2,SANDSTONE)
Block(2,44,-1,SANDSTONE)
Block(2,44,0,SANDSTONE)
Block(2,44,1,SANDSTONE)
Block(2,44,2,SANDSTONE)
Block(2,45,-6,OBSIDIAN)
Block(2,45,-5,SANDSTONE)
Block(2,45,-4,SANDSTONE)
Block(2,45,-3,SANDSTONE)
Block(2,45,-2,SANDSTONE)
Block(2,45,-1,SANDSTONE)
Block(2,45,0,SANDSTONE)
Block(2,45,1,SANDSTONE)
Block(2,45,2,SANDSTONE)
Block(2,46,-7,OBSIDIAN)
Block(2,46,-6,OBSIDIAN)
Block(2,46,-5,SANDSTONE)
Block(2,46,-4,SANDSTONE)
Block(2,46,-3,SANDSTONE)
Block(2,46,-2,SANDSTONE)
Block(2,46,-1,SANDSTONE)
Block(2,46,0,SANDSTONE)
Block(2,46,1,SANDSTONE)
Block(2,47,-7,OBSIDIAN)
Block(2,47,-6,SANDSTONE)
Block(2,47,-5,SANDSTONE)
Block(2,47,-4,SANDSTONE)
Block(2,47,-3,SANDSTONE)
Block(2,47,-2,SANDSTONE)
Block(2,47,-1,SANDSTONE)
Block(2,47,0,SANDSTONE)
Block(2,48,-7,SANDSTONE)
Block(2,48,-6,SANDSTONE)
Block(2,48,-5,SANDSTONE)
Block(2,48,-4,SANDSTONE)
Block(2,48,-3,SANDSTONE)
Block(2,48,-2,SANDSTONE)
Block(2,48,-1,SANDSTONE)
Block(2,49,-7,SANDSTONE)
Block(2,49,-6,SANDSTONE)
Block(2,49,-5,SANDSTONE)
Block(2,49,-4,SANDSTONE)
Block(2,49,-3,SANDSTONE)
Block(2,49,-2,SANDSTONE)
Block(2,49,-1,SANDSTONE)
Block(2,50,-7,SANDSTONE)
Block(2,50,-6,SANDSTONE)
Block(2,50,-5,SANDSTONE)
Block(2,50,-4,SANDSTONE)
Block(2,50,-3,SANDSTONE)
Block(2,50,-2,SANDSTONE)
Block(2,51,-7,SANDSTONE)
Block(2,51,-6,SANDSTONE)
Block(2,51,-5,SANDSTONE)
Block(2,51,-4,SANDSTONE)
Block(2,51,-3,SANDSTONE)
Block(2,52,-7,SANDSTONE)
Block(2,52,-6,SANDSTONE)
Block(2,52,-5,SANDSTONE)
Block(2,52,-4,SANDSTONE)
Block(2,53,-7,SANDSTONE)
Block(2,53,-6,SANDSTONE)
Block(2,53,-5,SANDSTONE)
Block(2,54,-7,SANDSTONE)
Block(2,54,-6,SANDSTONE)
Block(2,54,-5,SANDSTONE)
Block(2,55,-7,SANDSTONE)
Block(2,55,-6,SANDSTONE)
Block(2,56,-7,SANDSTONE)
Block(3,12,8,OBSIDIAN)
Block(3,13,8,OBSIDIAN)
Block(3,14,7,OBSIDIAN)
Block(3,14,8,OBSIDIAN)
Block(3,15,7,OBSIDIAN)
Block(3,15,8,OBSIDIAN)
Block(3,16,6,OBSIDIAN)
Block(3,16,7,OBSIDIAN)
Block(3,16,8,OBSIDIAN)
Block(3,17,6,OBSIDIAN)
Block(3,17,7,OBSIDIAN)
Block(3,17,8,OBSIDIAN)
Block(3,18,5,OBSIDIAN)
Block(3,18,6,OBSIDIAN)
Block(3,18,7,OBSIDIAN)
Block(3,18,8,OBSIDIAN)
Block(3,19,5,OBSIDIAN)
Block(3,19,6,OBSIDIAN)
Block(3,19,7,OBSIDIAN)
Block(3,19,8,OBSIDIAN)
Block(3,20,4,OBSIDIAN)
Block(3,20,5,OBSIDIAN)
Block(3,20,6,OBSIDIAN)
Block(3,20,7,OBSIDIAN)
Block(3,20,8,OBSIDIAN)
Block(3,21,4,OBSIDIAN)
Block(3,21,5,OBSIDIAN)
Block(3,21,6,OBSIDIAN)
Block(3,21,7,OBSIDIAN)
Block(3,21,8,OBSIDIAN)
Block(3,22,3,OBSIDIAN)
Block(3,22,4,OBSIDIAN)
Block(3,22,5,OBSIDIAN)
Block(3,22,6,OBSIDIAN)
Block(3,22,7,OBSIDIAN)
Block(3,22,8,OBSIDIAN)
Block(3,23,3,OBSIDIAN)
Block(3,23,4,OBSIDIAN)
Block(3,23,5,OBSIDIAN)
Block(3,23,6,OBSIDIAN)
Block(3,23,7,OBSIDIAN)
Block(3,23,8,OBSIDIAN)
Block(3,24,2,OBSIDIAN)
Block(3,24,3,OBSIDIAN)
Block(3,24,4,OBSIDIAN)
Block(3,24,5,OBSIDIAN)
Block(3,24,6,OBSIDIAN)
Block(3,24,7,OBSIDIAN)
Block(3,24,8,OBSIDIAN)
Block(3,25,2,OBSIDIAN)
Block(3,25,3,OBSIDIAN)
Block(3,25,4,OBSIDIAN)
Block(3,25,5,OBSIDIAN)
Block(3,25,6,OBSIDIAN)
Block(3,25,7,OBSIDIAN)
Block(3,25,8,OBSIDIAN)
Block(3,26,1,OBSIDIAN)
Block(3,26,2,OBSIDIAN)
Block(3,26,3,OBSIDIAN)
Block(3,26,4,OBSIDIAN)
Block(3,26,5,OBSIDIAN)
Block(3,26,6,OBSIDIAN)
Block(3,26,7,OBSIDIAN)
Block(3,26,8,OBSIDIAN)
Block(3,27,1,OBSIDIAN)
Block(3,27,2,OBSIDIAN)
Block(3,27,3,OBSIDIAN)
Block(3,27,4,OBSIDIAN)
Block(3,27,5,OBSIDIAN)
Block(3,27,6,OBSIDIAN)
Block(3,27,7,OBSIDIAN)
Block(3,27,8,SANDSTONE)
Block(3,28,0,OBSIDIAN)
Block(3,28,1,OBSIDIAN)
Block(3,28,2,OBSIDIAN)
Block(3,28,3,OBSIDIAN)
Block(3,28,4,OBSIDIAN)
Block(3,28,5,OBSIDIAN)
Block(3,28,6,OBSIDIAN)
Block(3,28,7,OBSIDIAN)
Block(3,28,8,SANDSTONE)
Block(3,29,0,OBSIDIAN)
Block(3,29,1,OBSIDIAN)
Block(3,29,2,OBSIDIAN)
Block(3,29,3,OBSIDIAN)
Block(3,29,4,OBSIDIAN)
Block(3,29,5,OBSIDIAN)
Block(3,29,6,OBSIDIAN)
Block(3,29,7,SANDSTONE)
Block(3,29,8,SANDSTONE)
Block(3,30,-1,OBSIDIAN)
Block(3,30,0,OBSIDIAN)
Block(3,30,1,OBSIDIAN)
Block(3,30,2,OBSIDIAN)
Block(3,30,3,OBSIDIAN)
Block(3,30,4,OBSIDIAN)
Block(3,30,5,OBSIDIAN)
Block(3,30,6,SANDSTONE)
Block(3,30,7,SANDSTONE)
Block(3,30,8,SANDSTONE)
Block(3,31,-1,OBSIDIAN)
Block(3,31,0,OBSIDIAN)
Block(3,31,1,OBSIDIAN)
Block(3,31,2,OBSIDIAN)
Block(3,31,3,OBSIDIAN)
Block(3,31,4,OBSIDIAN)
Block(3,31,5,SANDSTONE)
Block(3,31,6,SANDSTONE)
Block(3,31,7,SANDSTONE)
Block(3,31,8,SANDSTONE)
Block(3,32,-1,OBSIDIAN)
Block(3,32,0,OBSIDIAN)
Block(3,32,1,OBSIDIAN)
Block(3,32,2,OBSIDIAN)
Block(3,32,3,OBSIDIAN)
Block(3,32,4,OBSIDIAN)
Block(3,32,5,SANDSTONE)
Block(3,32,6,SANDSTONE)
Block(3,32,7,SANDSTONE)
Block(3,32,8,SANDSTONE)
Block(3,33,-2,OBSIDIAN)
Block(3,33,-1,OBSIDIAN)
Block(3,33,0,OBSIDIAN)
Block(3,33,1,OBSIDIAN)
Block(3,33,2,OBSIDIAN)
Block(3,33,3,OBSIDIAN)
Block(3,33,4,SANDSTONE)
Block(3,33,5,SANDSTONE)
Block(3,33,6,SANDSTONE)
Block(3,33,7,SANDSTONE)
Block(3,33,8,SANDSTONE)
Block(3,34,-2,OBSIDIAN)
Block(3,34,-1,OBSIDIAN)
Block(3,34,0,OBSIDIAN)
Block(3,34,1,OBSIDIAN)
Block(3,34,2,OBSIDIAN)
Block(3,34,3,SANDSTONE)
Block(3,34,4,SANDSTONE)
Block(3,34,5,SANDSTONE)
Block(3,34,6,SANDSTONE)
Block(3,34,7,SANDSTONE)
Block(3,34,8,SANDSTONE)
Block(3,35,-3,OBSIDIAN)
Block(3,35,-2,OBSIDIAN)
Block(3,35,-1,OBSIDIAN)
Block(3,35,0,OBSIDIAN)
Block(3,35,1,OBSIDIAN)
Block(3,35,2,OBSIDIAN)
Block(3,35,3,SANDSTONE)
Block(3,35,4,SANDSTONE)
Block(3,35,5,SANDSTONE)
Block(3,35,6,SANDSTONE)
Block(3,35,7,SANDSTONE)
Block(3,35,8,SANDSTONE)
Block(3,36,-3,OBSIDIAN)
Block(3,36,-2,OBSIDIAN)
Block(3,36,-1,OBSIDIAN)
Block(3,36,0,OBSIDIAN)
Block(3,36,1,OBSIDIAN)
Block(3,36,2,SANDSTONE)
Block(3,36,3,SANDSTONE)
Block(3,36,4,SANDSTONE)
Block(3,36,5,SANDSTONE)
Block(3,36,6,SANDSTONE)
Block(3,36,7,SANDSTONE)
Block(3,36,8,SANDSTONE)
Block(3,37,-4,OBSIDIAN)
Block(3,37,-3,OBSIDIAN)
Block(3,37,-2,OBSIDIAN)
Block(3,37,-1,OBSIDIAN)
Block(3,37,0,OBSIDIAN)
Block(3,37,1,SANDSTONE)
Block(3,37,2,SANDSTONE)
Block(3,37,3,SANDSTONE)
Block(3,37,4,SANDSTONE)
Block(3,37,5,SANDSTONE)
Block(3,37,6,SANDSTONE)
Block(3,37,7,SANDSTONE)
Block(3,37,8,SANDSTONE)
Block(3,38,-4,OBSIDIAN)
Block(3,38,-3,OBSIDIAN)
Block(3,38,-2,OBSIDIAN)
Block(3,38,-1,OBSIDIAN)
Block(3,38,0,SANDSTONE)
Block(3,38,1,SANDSTONE)
Block(3,38,2,SANDSTONE)
Block(3,38,3,SANDSTONE)
Block(3,38,4,SANDSTONE)
Block(3,38,5,SANDSTONE)
Block(3,38,6,SANDSTONE)
Block(3,38,7,SANDSTONE)
Block(3,39,-5,OBSIDIAN)
Block(3,39,-4,OBSIDIAN)
Block(3,39,-3,OBSIDIAN)
Block(3,39,-2,OBSIDIAN)
Block(3,39,-1,SANDSTONE)
Block(3,39,0,SANDSTONE)
Block(3,39,1,SANDSTONE)
Block(3,39,2,SANDSTONE)
Block(3,39,3,SANDSTONE)
Block(3,39,4,SANDSTONE)
Block(3,39,5,SANDSTONE)
Block(3,39,6,SANDSTONE)
Block(3,40,-5,OBSIDIAN)
Block(3,40,-4,OBSIDIAN)
Block(3,40,-3,OBSIDIAN)
Block(3,40,-2,OBSIDIAN)
Block(3,40,-1,SANDSTONE)
Block(3,40,0,SANDSTONE)
Block(3,40,1,SANDSTONE)
Block(3,40,2,SANDSTONE)
Block(3,40,3,SANDSTONE)
Block(3,40,4,SANDSTONE)
Block(3,40,5,SANDSTONE)
Block(3,41,-6,OBSIDIAN)
Block(3,41,-5,OBSIDIAN)
Block(3,41,-4,OBSIDIAN)
Block(3,41,-3,OBSIDIAN)
Block(3,41,-2,SANDSTONE)
Block(3,41,-1,SANDSTONE)
Block(3,41,0,SANDSTONE)
Block(3,41,1,SANDSTONE)
Block(3,41,2,SANDSTONE)
Block(3,41,3,SANDSTONE)
Block(3,41,4,SANDSTONE)
Block(3,41,5,SANDSTONE)
Block(3,42,-6,OBSIDIAN)
Block(3,42,-5,OBSIDIAN)
Block(3,42,-4,OBSIDIAN)
Block(3,42,-3,OBSIDIAN)
Block(3,42,-2,SANDSTONE)
Block(3,42,-1,SANDSTONE)
Block(3,42,0,SANDSTONE)
Block(3,42,1,SANDSTONE)
Block(3,42,2,SANDSTONE)
Block(3,42,3,SANDSTONE)
Block(3,42,4,SANDSTONE)
Block(3,43,-7,OBSIDIAN)
Block(3,43,-6,OBSIDIAN)
Block(3,43,-5,OBSIDIAN)
Block(3,43,-4,OBSIDIAN)
Block(3,43,-3,SANDSTONE)
Block(3,43,-2,SANDSTONE)
Block(3,43,-1,SANDSTONE)
Block(3,43,0,SANDSTONE)
Block(3,43,1,SANDSTONE)
Block(3,43,2,SANDSTONE)
Block(3,43,3,SANDSTONE)
Block(3,44,-7,OBSIDIAN)
Block(3,44,-6,OBSIDIAN)
Block(3,44,-5,OBSIDIAN)
Block(3,44,-4,SANDSTONE)
Block(3,44,-3,SANDSTONE)
Block(3,44,-2,SANDSTONE)
Block(3,44,-1,SANDSTONE)
Block(3,44,0,SANDSTONE)
Block(3,44,1,SANDSTONE)
Block(3,44,2,SANDSTONE)
Block(3,45,-7,OBSIDIAN)
Block(3,45,-6,OBSIDIAN)
Block(3,45,-5,SANDSTONE)
Block(3,45,-4,SANDSTONE)
Block(3,45,-3,SANDSTONE)
Block(3,45,-2,SANDSTONE)
Block(3,45,-1,SANDSTONE)
Block(3,45,0,SANDSTONE)
Block(3,45,1,SANDSTONE)
Block(3,46,-7,OBSIDIAN)
Block(3,46,-6,OBSIDIAN)
Block(3,46,-5,SANDSTONE)
Block(3,46,-4,SANDSTONE)
Block(3,46,-3,SANDSTONE)
Block(3,46,-2,SANDSTONE)
Block(3,46,-1,SANDSTONE)
Block(3,46,0,SANDSTONE)
Block(3,46,1,SANDSTONE)
Block(3,47,-7,OBSIDIAN)
Block(3,47,-6,SANDSTONE)
Block(3,47,-5,SANDSTONE)
Block(3,47,-4,SANDSTONE)
Block(3,47,-3,SANDSTONE)
Block(3,47,-2,SANDSTONE)
Block(3,47,-1,SANDSTONE)
Block(3,47,0,SANDSTONE)
Block(3,48,-7,SANDSTONE)
Block(3,48,-6,SANDSTONE)
Block(3,48,-5,SANDSTONE)
Block(3,48,-4,SANDSTONE)
Block(3,48,-3,SANDSTONE)
Block(3,48,-2,SANDSTONE)
Block(3,48,-1,SANDSTONE)
Block(3,49,-7,SANDSTONE)
Block(3,49,-6,SANDSTONE)
Block(3,49,-5,SANDSTONE)
Block(3,49,-4,SANDSTONE)
Block(3,49,-3,SANDSTONE)
Block(3,49,-2,SANDSTONE)
Block(3,50,-7,SANDSTONE)
Block(3,50,-6,SANDSTONE)
Block(3,50,-5,SANDSTONE)
Block(3,50,-4,SANDSTONE)
Block(3,50,-3,SANDSTONE)
Block(3,50,-2,SANDSTONE)
Block(3,51,-7,SANDSTONE)
Block(3,51,-6,SANDSTONE)
Block(3,51,-5,SANDSTONE)
Block(3,51,-4,SANDSTONE)
Block(3,51,-3,SANDSTONE)
Block(3,52,-7,SANDSTONE)
Block(3,52,-6,SANDSTONE)
Block(3,52,-5,SANDSTONE)
Block(3,52,-4,SANDSTONE)
Block(3,53,-7,SANDSTONE)
Block(3,53,-6,SANDSTONE)
Block(3,53,-5,SANDSTONE)
Block(3,54,-7,SANDSTONE)
Block(3,54,-6,SANDSTONE)
Block(3,54,-5,SANDSTONE)
Block(3,55,-7,SANDSTONE)
Block(3,55,-6,SANDSTONE)
Block(3,56,-7,SANDSTONE)
Block(4,9,8,SANDSTONE)
Block(4,10,8,SANDSTONE)
Block(4,11,7,OBSIDIAN)
Block(4,11,8,OBSIDIAN)
Block(4,12,7,OBSIDIAN)
Block(4,12,8,OBSIDIAN)
Block(4,13,6,OBSIDIAN)
Block(4,13,7,OBSIDIAN)
Block(4,13,8,OBSIDIAN)
Block(4,14,6,OBSIDIAN)
Block(4,14,7,OBSIDIAN)
Block(4,14,8,OBSIDIAN)
Block(4,15,5,OBSIDIAN)
Block(4,15,6,OBSIDIAN)
Block(4,15,7,OBSIDIAN)
Block(4,15,8,OBSIDIAN)
Block(4,16,5,OBSIDIAN)
Block(4,16,6,OBSIDIAN)
Block(4,16,7,OBSIDIAN)
Block(4,16,8,OBSIDIAN)
Block(4,17,4,OBSIDIAN)
Block(4,17,5,OBSIDIAN)
Block(4,17,6,OBSIDIAN)
Block(4,17,7,OBSIDIAN)
Block(4,17,8,OBSIDIAN)
Block(4,18,4,OBSIDIAN)
Block(4,18,5,OBSIDIAN)
Block(4,18,6,OBSIDIAN)
Block(4,18,7,OBSIDIAN)
Block(4,18,8,OBSIDIAN)
Block(4,19,3,OBSIDIAN)
Block(4,19,4,OBSIDIAN)
Block(4,19,5,OBSIDIAN)
Block(4,19,6,OBSIDIAN)
Block(4,19,7,OBSIDIAN)
Block(4,19,8,OBSIDIAN)
Block(4,20,3,OBSIDIAN)
Block(4,20,4,OBSIDIAN)
Block(4,20,5,OBSIDIAN)
Block(4,20,6,OBSIDIAN)
Block(4,20,7,OBSIDIAN)
Block(4,20,8,OBSIDIAN)
Block(4,21,2,OBSIDIAN)
Block(4,21,3,OBSIDIAN)
Block(4,21,4,OBSIDIAN)
Block(4,21,5,OBSIDIAN)
Block(4,21,6,OBSIDIAN)
Block(4,21,7,OBSIDIAN)
Block(4,21,8,OBSIDIAN)
Block(4,22,2,OBSIDIAN)
Block(4,22,3,OBSIDIAN)
Block(4,22,4,OBSIDIAN)
Block(4,22,5,OBSIDIAN)
Block(4,22,6,OBSIDIAN)
Block(4,22,7,OBSIDIAN)
Block(4,22,8,OBSIDIAN)
Block(4,23,1,OBSIDIAN)
Block(4,23,2,OBSIDIAN)
Block(4,23,3,OBSIDIAN)
Block(4,23,4,OBSIDIAN)
Block(4,23,5,OBSIDIAN)
Block(4,23,6,OBSIDIAN)
Block(4,23,7,OBSIDIAN)
Block(4,23,8,OBSIDIAN)
Block(4,24,1,OBSIDIAN)
Block(4,24,2,OBSIDIAN)
Block(4,24,3,OBSIDIAN)
Block(4,24,4,OBSIDIAN)
Block(4,24,5,OBSIDIAN)
Block(4,24,6,OBSIDIAN)
Block(4,24,7,OBSIDIAN)
Block(4,24,8,OBSIDIAN)
Block(4,25,0,OBSIDIAN)
Block(4,25,1,OBSIDIAN)
Block(4,25,2,OBSIDIAN)
Block(4,25,3,OBSIDIAN)
Block(4,25,4,OBSIDIAN)
Block(4,25,5,OBSIDIAN)
Block(4,25,6,OBSIDIAN)
Block(4,25,7,OBSIDIAN)
Block(4,25,8,OBSIDIAN)
Block(4,26,0,OBSIDIAN)
Block(4,26,1,OBSIDIAN)
Block(4,26,2,OBSIDIAN)
Block(4,26,3,OBSIDIAN)
Block(4,26,4,OBSIDIAN)
Block(4,26,5,OBSIDIAN)
Block(4,26,6,OBSIDIAN)
Block(4,26,7,OBSIDIAN)
Block(4,26,8,OBSIDIAN)
Block(4,27,-1,OBSIDIAN)
Block(4,27,0,OBSIDIAN)
Block(4,27,1,OBSIDIAN)
Block(4,27,2,OBSIDIAN)
Block(4,27,3,OBSIDIAN)
Block(4,27,4,OBSIDIAN)
Block(4,27,5,OBSIDIAN)
Block(4,27,6,OBSIDIAN)
Block(4,27,7,OBSIDIAN)
Block(4,27,8,OBSIDIAN)
Block(4,28,-1,OBSIDIAN)
Block(4,28,0,OBSIDIAN)
Block(4,28,1,OBSIDIAN)
Block(4,28,2,OBSIDIAN)
Block(4,28,3,OBSIDIAN)
Block(4,28,4,OBSIDIAN)
Block(4,28,5,OBSIDIAN)
Block(4,28,6,OBSIDIAN)
Block(4,28,7,OBSIDIAN)
Block(4,28,8,SANDSTONE)
Block(4,29,-1,OBSIDIAN)
Block(4,29,0,OBSIDIAN)
Block(4,29,1,OBSIDIAN)
Block(4,29,2,OBSIDIAN)
Block(4,29,3,OBSIDIAN)
Block(4,29,4,OBSIDIAN)
Block(4,29,5,OBSIDIAN)
Block(4,29,6,OBSIDIAN)
Block(4,29,7,OBSIDIAN)
Block(4,29,8,SANDSTONE)
Block(4,30,-2,OBSIDIAN)
Block(4,30,-1,OBSIDIAN)
Block(4,30,0,OBSIDIAN)
Block(4,30,1,OBSIDIAN)
Block(4,30,2,OBSIDIAN)
Block(4,30,3,OBSIDIAN)
Block(4,30,4,OBSIDIAN)
Block(4,30,5,OBSIDIAN)
Block(4,30,6,OBSIDIAN)
Block(4,30,7,SANDSTONE)
Block(4,30,8,SANDSTONE)
Block(4,31,-2,OBSIDIAN)
Block(4,31,-1,OBSIDIAN)
Block(4,31,0,OBSIDIAN)
Block(4,31,1,OBSIDIAN)
Block(4,31,2,OBSIDIAN)
Block(4,31,3,OBSIDIAN)
Block(4,31,4,OBSIDIAN)
Block(4,31,5,OBSIDIAN)
Block(4,31,6,SANDSTONE)
Block(4,31,7,SANDSTONE)
Block(4,31,8,SANDSTONE)
Block(4,32,-3,OBSIDIAN)
Block(4,32,-2,OBSIDIAN)
Block(4,32,-1,OBSIDIAN)
Block(4,32,0,OBSIDIAN)
Block(4,32,1,OBSIDIAN)
Block(4,32,2,OBSIDIAN)
Block(4,32,3,OBSIDIAN)
Block(4,32,4,OBSIDIAN)
Block(4,32,5,OBSIDIAN)
Block(4,32,6,SANDSTONE)
Block(4,32,7,SANDSTONE)
Block(4,32,8,SANDSTONE)
Block(4,33,-3,OBSIDIAN)
Block(4,33,-2,OBSIDIAN)
Block(4,33,-1,OBSIDIAN)
Block(4,33,0,OBSIDIAN)
Block(4,33,1,OBSIDIAN)
Block(4,33,2,OBSIDIAN)
Block(4,33,3,OBSIDIAN)
Block(4,33,4,OBSIDIAN)
Block(4,33,5,SANDSTONE)
Block(4,33,6,SANDSTONE)
Block(4,33,7,SANDSTONE)
Block(4,33,8,SANDSTONE)
Block(4,34,-4,OBSIDIAN)
Block(4,34,-3,OBSIDIAN)
Block(4,34,-2,OBSIDIAN)
Block(4,34,-1,OBSIDIAN)
Block(4,34,0,OBSIDIAN)
Block(4,34,1,OBSIDIAN)
Block(4,34,2,OBSIDIAN)
Block(4,34,3,OBSIDIAN)
Block(4,34,4,SANDSTONE)
Block(4,34,5,SANDSTONE)
Block(4,34,6,SANDSTONE)
Block(4,34,7,SANDSTONE)
Block(4,34,8,SANDSTONE)
Block(4,35,-4,OBSIDIAN)
Block(4,35,-3,OBSIDIAN)
Block(4,35,-2,OBSIDIAN)
Block(4,35,-1,OBSIDIAN)
Block(4,35,0,OBSIDIAN)
Block(4,35,1,OBSIDIAN)
Block(4,35,2,OBSIDIAN)
Block(4,35,3,SANDSTONE)
Block(4,35,4,SANDSTONE)
Block(4,35,5,SANDSTONE)
Block(4,35,6,SANDSTONE)
Block(4,35,7,SANDSTONE)
Block(4,35,8,SANDSTONE)
Block(4,36,-5,OBSIDIAN)
Block(4,36,-4,OBSIDIAN)
Block(4,36,-3,OBSIDIAN)
Block(4,36,-2,OBSIDIAN)
Block(4,36,-1,OBSIDIAN)
Block(4,36,0,OBSIDIAN)
Block(4,36,1,OBSIDIAN)
Block(4,36,2,SANDSTONE)
Block(4,36,3,SANDSTONE)
Block(4,36,4,SANDSTONE)
Block(4,36,5,SANDSTONE)
Block(4,36,6,SANDSTONE)
Block(4,36,7,SANDSTONE)
Block(4,36,8,SANDSTONE)
Block(4,37,-5,OBSIDIAN)
Block(4,37,-4,OBSIDIAN)
Block(4,37,-3,OBSIDIAN)
Block(4,37,-2,OBSIDIAN)
Block(4,37,-1,OBSIDIAN)
Block(4,37,0,OBSIDIAN)
Block(4,37,1,SANDSTONE)
Block(4,37,2,SANDSTONE)
Block(4,37,3,SANDSTONE)
Block(4,37,4,SANDSTONE)
Block(4,37,5,SANDSTONE)
Block(4,37,6,SANDSTONE)
Block(4,37,7,SANDSTONE)
Block(4,37,8,SANDSTONE)
Block(4,38,-6,OBSIDIAN)
Block(4,38,-5,OBSIDIAN)
Block(4,38,-4,OBSIDIAN)
Block(4,38,-3,OBSIDIAN)
Block(4,38,-2,OBSIDIAN)
Block(4,38,-1,OBSIDIAN)
Block(4,38,0,SANDSTONE)
Block(4,38,1,SANDSTONE)
Block(4,38,2,SANDSTONE)
Block(4,38,3,SANDSTONE)
Block(4,38,4,SANDSTONE)
Block(4,38,5,SANDSTONE)
Block(4,38,6,SANDSTONE)
Block(4,38,7,SANDSTONE)
Block(4,39,-6,OBSIDIAN)
Block(4,39,-5,OBSIDIAN)
Block(4,39,-4,OBSIDIAN)
Block(4,39,-3,OBSIDIAN)
Block(4,39,-2,OBSIDIAN)
Block(4,39,-1,SANDSTONE)
Block(4,39,0,SANDSTONE)
Block(4,39,1,SANDSTONE)
Block(4,39,2,SANDSTONE)
Block(4,39,3,SANDSTONE)
Block(4,39,4,SANDSTONE)
Block(4,39,5,SANDSTONE)
Block(4,39,6,SANDSTONE)
Block(4,40,-6,OBSIDIAN)
Block(4,40,-5,OBSIDIAN)
Block(4,40,-4,OBSIDIAN)
Block(4,40,-3,OBSIDIAN)
Block(4,40,-2,OBSIDIAN)
Block(4,40,-1,SANDSTONE)
Block(4,40,0,SANDSTONE)
Block(4,40,1,SANDSTONE)
Block(4,40,2,SANDSTONE)
Block(4,40,3,SANDSTONE)
Block(4,40,4,SANDSTONE)
Block(4,40,5,SANDSTONE)
Block(4,41,-7,OBSIDIAN)
Block(4,41,-6,OBSIDIAN)
Block(4,41,-5,OBSIDIAN)
Block(4,41,-4,OBSIDIAN)
Block(4,41,-3,OBSIDIAN)
Block(4,41,-2,OBSIDIAN)
Block(4,41,-1,SANDSTONE)
Block(4,41,0,SANDSTONE)
Block(4,41,1,SANDSTONE)
Block(4,41,2,SANDSTONE)
Block(4,41,3,SANDSTONE)
Block(4,41,4,SANDSTONE)
Block(4,42,-7,OBSIDIAN)
Block(4,42,-6,OBSIDIAN)
Block(4,42,-5,OBSIDIAN)
Block(4,42,-4,OBSIDIAN)
Block(4,42,-3,OBSIDIAN)
Block(4,42,-2,OBSIDIAN)
Block(4,42,-1,SANDSTONE)
Block(4,42,0,SANDSTONE)
Block(4,42,1,SANDSTONE)
Block(4,42,2,SANDSTONE)
Block(4,42,3,SANDSTONE)
Block(4,42,4,SANDSTONE)
Block(4,43,-7,OBSIDIAN)
Block(4,43,-6,OBSIDIAN)
Block(4,43,-5,OBSIDIAN)
Block(4,43,-4,OBSIDIAN)
Block(4,43,-3,SANDSTONE)
Block(4,43,-2,SANDSTONE)
Block(4,43,-1,SANDSTONE)
Block(4,43,0,SANDSTONE)
Block(4,43,1,SANDSTONE)
Block(4,43,2,SANDSTONE)
Block(4,43,3,SANDSTONE)
Block(4,44,-7,OBSIDIAN)
Block(4,44,-6,OBSIDIAN)
Block(4,44,-5,OBSIDIAN)
Block(4,44,-4,SANDSTONE)
Block(4,44,-3,SANDSTONE)
Block(4,44,-2,SANDSTONE)
Block(4,44,-1,SANDSTONE)
Block(4,44,0,SANDSTONE)
Block(4,44,1,SANDSTONE)
Block(4,44,2,SANDSTONE)
Block(4,45,-7,OBSIDIAN)
Block(4,45,-6,OBSIDIAN)
Block(4,45,-5,OBSIDIAN)
Block(4,45,-4,SANDSTONE)
Block(4,45,-3,SANDSTONE)
Block(4,45,-2,SANDSTONE)
Block(4,45,-1,SANDSTONE)
Block(4,45,0,SANDSTONE)
Block(4,45,1,SANDSTONE)
Block(4,46,-7,OBSIDIAN)
Block(4,46,-6,OBSIDIAN)
Block(4,46,-5,SANDSTONE)
Block(4,46,-4,SANDSTONE)
Block(4,46,-3,SANDSTONE)
Block(4,46,-2,SANDSTONE)
Block(4,46,-1,SANDSTONE)
Block(4,46,0,SANDSTONE)
Block(4,46,1,SANDSTONE)
Block(4,47,-7,OBSIDIAN)
Block(4,47,-6,SANDSTONE)
Block(4,47,-5,SANDSTONE)
Block(4,47,-4,SANDSTONE)
Block(4,47,-3,SANDSTONE)
Block(4,47,-2,SANDSTONE)
Block(4,47,-1,SANDSTONE)
Block(4,47,0,SANDSTONE)
Block(4,48,-7,SANDSTONE)
Block(4,48,-6,SANDSTONE)
Block(4,48,-5,SANDSTONE)
Block(4,48,-4,SANDSTONE)
Block(4,48,-3,SANDSTONE)
Block(4,48,-2,SANDSTONE)
Block(4,48,-1,SANDSTONE)
Block(4,49,-7,SANDSTONE)
Block(4,49,-6,SANDSTONE)
Block(4,49,-5,SANDSTONE)
Block(4,49,-4,SANDSTONE)
Block(4,49,-3,SANDSTONE)
Block(4,49,-2,SANDSTONE)
Block(4,50,-7,SANDSTONE)
Block(4,50,-6,SANDSTONE)
Block(4,50,-5,SANDSTONE)
Block(4,50,-4,SANDSTONE)
Block(4,50,-3,SANDSTONE)
Block(4,51,-7,SANDSTONE)
Block(4,51,-6,SANDSTONE)
Block(4,51,-5,SANDSTONE)
Block(4,51,-4,SANDSTONE)
Block(4,51,-3,SANDSTONE)
Block(4,52,-7,SANDSTONE)
Block(4,52,-6,SANDSTONE)
Block(4,52,-5,SANDSTONE)
Block(4,52,-4,SANDSTONE)
Block(4,53,-7,SANDSTONE)
Block(4,53,-6,SANDSTONE)
Block(4,53,-5,SANDSTONE)
Block(4,54,-7,SANDSTONE)
Block(4,54,-6,SANDSTONE)
Block(4,55,-7,SANDSTONE)
Block(4,55,-6,SANDSTONE)
Block(4,56,-7,SANDSTONE)
Block(5,6,8,SANDSTONE)
Block(5,7,8,SANDSTONE)
Block(5,8,7,SANDSTONE)
Block(5,8,8,SANDSTONE)
Block(5,9,7,SANDSTONE)
Block(5,9,8,SANDSTONE)
Block(5,10,6,SANDSTONE)
Block(5,10,7,SANDSTONE)
Block(5,10,8,SANDSTONE)
Block(5,11,6,SANDSTONE)
Block(5,11,7,SANDSTONE)
Block(5,11,8,SANDSTONE)
Block(5,12,5,SANDSTONE)
Block(5,12,6,SANDSTONE)
Block(5,12,7,SANDSTONE)
Block(5,12,8,SANDSTONE)
Block(5,13,5,SANDSTONE)
Block(5,13,6,SANDSTONE)
Block(5,13,7,SANDSTONE)
Block(5,13,8,SANDSTONE)
Block(5,14,4,OBSIDIAN)
Block(5,14,5,SANDSTONE)
Block(5,14,6,SANDSTONE)
Block(5,14,7,SANDSTONE)
Block(5,14,8,OBSIDIAN)
Block(5,15,4,OBSIDIAN)
Block(5,15,5,OBSIDIAN)
Block(5,15,6,OBSIDIAN)
Block(5,15,7,OBSIDIAN)
Block(5,15,8,OBSIDIAN)
Block(5,16,3,OBSIDIAN)
Block(5,16,4,OBSIDIAN)
Block(5,16,5,OBSIDIAN)
Block(5,16,6,OBSIDIAN)
Block(5,16,7,OBSIDIAN)
Block(5,16,8,OBSIDIAN)
Block(5,17,3,OBSIDIAN)
Block(5,17,4,OBSIDIAN)
Block(5,17,5,OBSIDIAN)
Block(5,17,6,OBSIDIAN)
Block(5,17,7,OBSIDIAN)
Block(5,17,8,OBSIDIAN)
Block(5,18,2,OBSIDIAN)
Block(5,18,3,OBSIDIAN)
Block(5,18,4,OBSIDIAN)
Block(5,18,5,OBSIDIAN)
Block(5,18,6,OBSIDIAN)
Block(5,18,7,OBSIDIAN)
Block(5,18,8,OBSIDIAN)
Block(5,19,2,OBSIDIAN)
Block(5,19,3,OBSIDIAN)
Block(5,19,4,OBSIDIAN)
Block(5,19,5,OBSIDIAN)
Block(5,19,6,OBSIDIAN)
Block(5,19,7,OBSIDIAN)
Block(5,19,8,OBSIDIAN)
Block(5,20,2,OBSIDIAN)
Block(5,20,3,OBSIDIAN)
Block(5,20,4,OBSIDIAN)
Block(5,20,5,OBSIDIAN)
Block(5,20,6,OBSIDIAN)
Block(5,20,7,OBSIDIAN)
Block(5,20,8,OBSIDIAN)
Block(5,21,1,OBSIDIAN)
Block(5,21,2,OBSIDIAN)
Block(5,21,3,OBSIDIAN)
Block(5,21,4,OBSIDIAN)
Block(5,21,5,OBSIDIAN)
Block(5,21,6,OBSIDIAN)
Block(5,21,7,OBSIDIAN)
Block(5,21,8,OBSIDIAN)
Block(5,22,1,OBSIDIAN)
Block(5,22,2,OBSIDIAN)
Block(5,22,3,OBSIDIAN)
Block(5,22,4,OBSIDIAN)
Block(5,22,5,OBSIDIAN)
Block(5,22,6,OBSIDIAN)
Block(5,22,7,OBSIDIAN)
Block(5,22,8,OBSIDIAN)
Block(5,23,0,OBSIDIAN)
Block(5,23,1,OBSIDIAN)
Block(5,23,2,OBSIDIAN)
Block(5,23,3,OBSIDIAN)
Block(5,23,4,OBSIDIAN)
Block(5,23,5,OBSIDIAN)
Block(5,23,6,OBSIDIAN)
Block(5,23,7,OBSIDIAN)
Block(5,23,8,OBSIDIAN)
Block(5,24,0,OBSIDIAN)
Block(5,24,1,OBSIDIAN)
Block(5,24,2,OBSIDIAN)
Block(5,24,3,OBSIDIAN)
Block(5,24,4,OBSIDIAN)
Block(5,24,5,OBSIDIAN)
Block(5,24,6,OBSIDIAN)
Block(5,24,7,OBSIDIAN)
Block(5,24,8,OBSIDIAN)
Block(5,25,0,OBSIDIAN)
Block(5,25,1,OBSIDIAN)
Block(5,25,2,OBSIDIAN)
Block(5,25,3,OBSIDIAN)
Block(5,25,4,OBSIDIAN)
Block(5,25,5,OBSIDIAN)
Block(5,25,6,OBSIDIAN)
Block(5,25,7,OBSIDIAN)
Block(5,25,8,OBSIDIAN)
Block(5,26,-1,OBSIDIAN)
Block(5,26,0,OBSIDIAN)
Block(5,26,1,OBSIDIAN)
Block(5,26,2,OBSIDIAN)
Block(5,26,3,OBSIDIAN)
Block(5,26,4,OBSIDIAN)
Block(5,26,5,OBSIDIAN)
Block(5,26,6,OBSIDIAN)
Block(5,26,7,OBSIDIAN)
Block(5,26,8,OBSIDIAN)
Block(5,27,-1,OBSIDIAN)
Block(5,27,0,OBSIDIAN)
Block(5,27,1,OBSIDIAN)
Block(5,27,2,OBSIDIAN)
Block(5,27,3,OBSIDIAN)
Block(5,27,4,OBSIDIAN)
Block(5,27,5,OBSIDIAN)
Block(5,27,6,OBSIDIAN)
Block(5,27,7,OBSIDIAN)
Block(5,27,8,SANDSTONE)
Block(5,28,-2,OBSIDIAN)
Block(5,28,-1,OBSIDIAN)
Block(5,28,0,OBSIDIAN)
Block(5,28,1,OBSIDIAN)
Block(5,28,2,OBSIDIAN)
Block(5,28,3,OBSIDIAN)
Block(5,28,4,OBSIDIAN)
Block(5,28,5,OBSIDIAN)
Block(5,28,6,OBSIDIAN)
Block(5,28,7,OBSIDIAN)
Block(5,28,8,SANDSTONE)
Block(5,29,-2,OBSIDIAN)
Block(5,29,-1,OBSIDIAN)
Block(5,29,0,OBSIDIAN)
Block(5,29,1,OBSIDIAN)
Block(5,29,2,OBSIDIAN)
Block(5,29,3,OBSIDIAN)
Block(5,29,4,OBSIDIAN)
Block(5,29,5,OBSIDIAN)
Block(5,29,6,OBSIDIAN)
Block(5,29,7,SANDSTONE)
Block(5,29,8,SANDSTONE)
Block(5,30,-2,OBSIDIAN)
Block(5,30,-1,OBSIDIAN)
Block(5,30,0,OBSIDIAN)
Block(5,30,1,OBSIDIAN)
Block(5,30,2,OBSIDIAN)
Block(5,30,3,OBSIDIAN)
Block(5,30,4,OBSIDIAN)
Block(5,30,5,OBSIDIAN)
Block(5,30,6,OBSIDIAN)
Block(5,30,7,SANDSTONE)
Block(5,30,8,SANDSTONE)
Block(5,31,-3,OBSIDIAN)
Block(5,31,-2,OBSIDIAN)
Block(5,31,-1,OBSIDIAN)
Block(5,31,0,OBSIDIAN)
Block(5,31,1,OBSIDIAN)
Block(5,31,2,OBSIDIAN)
Block(5,31,3,OBSIDIAN)
Block(5,31,4,OBSIDIAN)
Block(5,31,5,OBSIDIAN)
Block(5,31,6,OBSIDIAN)
Block(5,31,7,SANDSTONE)
Block(5,31,8,SANDSTONE)
Block(5,32,-3,OBSIDIAN)
Block(5,32,-2,OBSIDIAN)
Block(5,32,-1,OBSIDIAN)
Block(5,32,0,OBSIDIAN)
Block(5,32,1,OBSIDIAN)
Block(5,32,2,OBSIDIAN)
Block(5,32,3,OBSIDIAN)
Block(5,32,4,OBSIDIAN)
Block(5,32,5,OBSIDIAN)
Block(5,32,6,OBSIDIAN)
Block(5,32,7,SANDSTONE)
Block(5,32,8,SANDSTONE)
Block(5,33,-3,OBSIDIAN)
Block(5,33,-2,OBSIDIAN)
Block(5,33,-1,OBSIDIAN)
Block(5,33,0,OBSIDIAN)
Block(5,33,1,OBSIDIAN)
Block(5,33,2,OBSIDIAN)
Block(5,33,3,OBSIDIAN)
Block(5,33,4,OBSIDIAN)
Block(5,33,5,SANDSTONE)
Block(5,33,6,SANDSTONE)
Block(5,33,7,SANDSTONE)
Block(5,33,8,SANDSTONE)
Block(5,34,-4,OBSIDIAN)
Block(5,34,-3,OBSIDIAN)
Block(5,34,-2,OBSIDIAN)
Block(5,34,-1,OBSIDIAN)
Block(5,34,0,OBSIDIAN)
Block(5,34,1,OBSIDIAN)
Block(5,34,2,OBSIDIAN)
Block(5,34,3,OBSIDIAN)
Block(5,34,4,SANDSTONE)
Block(5,34,5,SANDSTONE)
Block(5,34,6,SANDSTONE)
Block(5,34,7,SANDSTONE)
Block(5,34,8,SANDSTONE)
Block(5,35,-4,OBSIDIAN)
Block(5,35,-3,OBSIDIAN)
Block(5,35,-2,OBSIDIAN)
Block(5,35,-1,OBSIDIAN)
Block(5,35,0,OBSIDIAN)
Block(5,35,1,OBSIDIAN)
Block(5,35,2,OBSIDIAN)
Block(5,35,3,SANDSTONE)
Block(5,35,4,SANDSTONE)
Block(5,35,5,SANDSTONE)
Block(5,35,6,SANDSTONE)
Block(5,35,7,SANDSTONE)
Block(5,35,8,SANDSTONE)
Block(5,36,-5,OBSIDIAN)
Block(5,36,-4,OBSIDIAN)
Block(5,36,-3,OBSIDIAN)
Block(5,36,-2,OBSIDIAN)
Block(5,36,-1,OBSIDIAN)
Block(5,36,0,OBSIDIAN)
Block(5,36,1,OBSIDIAN)
Block(5,36,2,SANDSTONE)
Block(5,36,3,SANDSTONE)
Block(5,36,4,SANDSTONE)
Block(5,36,5,SANDSTONE)
Block(5,36,6,SANDSTONE)
Block(5,36,7,SANDSTONE)
Block(5,36,8,SANDSTONE)
Block(5,37,-5,OBSIDIAN)
Block(5,37,-4,OBSIDIAN)
Block(5,37,-3,OBSIDIAN)
Block(5,37,-2,OBSIDIAN)
Block(5,37,-1,OBSIDIAN)
Block(5,37,0,OBSIDIAN)
Block(5,37,1,SANDSTONE)
Block(5,37,2,SANDSTONE)
Block(5,37,3,SANDSTONE)
Block(5,37,4,SANDSTONE)
Block(5,37,5,SANDSTONE)
Block(5,37,6,SANDSTONE)
Block(5,37,7,SANDSTONE)
Block(5,38,-5,OBSIDIAN)
Block(5,38,-4,OBSIDIAN)
Block(5,38,-3,OBSIDIAN)
Block(5,38,-2,OBSIDIAN)
Block(5,38,-1,OBSIDIAN)
Block(5,38,0,SANDSTONE)
Block(5,38,1,SANDSTONE)
Block(5,38,2,SANDSTONE)
Block(5,38,3,SANDSTONE)
Block(5,38,4,SANDSTONE)
Block(5,38,5,SANDSTONE)
Block(5,38,6,SANDSTONE)
Block(5,38,7,SANDSTONE)
Block(5,39,-6,OBSIDIAN)
Block(5,39,-5,OBSIDIAN)
Block(5,39,-4,OBSIDIAN)
Block(5,39,-3,OBSIDIAN)
Block(5,39,-2,OBSIDIAN)
Block(5,39,-1,SANDSTONE)
Block(5,39,0,SANDSTONE)
Block(5,39,1,SANDSTONE)
Block(5,39,2,SANDSTONE)
Block(5,39,3,SANDSTONE)
Block(5,39,4,SANDSTONE)
Block(5,39,5,SANDSTONE)
Block(5,39,6,SANDSTONE)
Block(5,40,-6,OBSIDIAN)
Block(5,40,-5,OBSIDIAN)
Block(5,40,-4,OBSIDIAN)
Block(5,40,-3,OBSIDIAN)
Block(5,40,-2,OBSIDIAN)
Block(5,40,-1,SANDSTONE)
Block(5,40,0,SANDSTONE)
Block(5,40,1,SANDSTONE)
Block(5,40,2,SANDSTONE)
Block(5,40,3,SANDSTONE)
Block(5,40,4,SANDSTONE)
Block(5,40,5,SANDSTONE)
Block(5,41,-7,OBSIDIAN)
Block(5,41,-6,OBSIDIAN)
Block(5,41,-5,OBSIDIAN)
Block(5,41,-4,OBSIDIAN)
Block(5,41,-3,OBSIDIAN)
Block(5,41,-2,OBSIDIAN)
Block(5,41,-1,SANDSTONE)
Block(5,41,0,SANDSTONE)
Block(5,41,1,SANDSTONE)
Block(5,41,2,SANDSTONE)
Block(5,41,3,SANDSTONE)
Block(5,41,4,SANDSTONE)
Block(5,42,-7,OBSIDIAN)
Block(5,42,-6,OBSIDIAN)
Block(5,42,-5,OBSIDIAN)
Block(5,42,-4,OBSIDIAN)
Block(5,42,-3,OBSIDIAN)
Block(5,42,-2,OBSIDIAN)
Block(5,42,-1,SANDSTONE)
Block(5,42,0,SANDSTONE)
Block(5,42,1,SANDSTONE)
Block(5,42,2,SANDSTONE)
Block(5,42,3,SANDSTONE)
Block(5,43,-7,OBSIDIAN)
Block(5,43,-6,OBSIDIAN)
Block(5,43,-5,OBSIDIAN)
Block(5,43,-4,OBSIDIAN)
Block(5,43,-3,OBSIDIAN)
Block(5,43,-2,SANDSTONE)
Block(5,43,-1,SANDSTONE)
Block(5,43,0,SANDSTONE)
Block(5,43,1,SANDSTONE)
Block(5,43,2,SANDSTONE)
Block(5,43,3,SANDSTONE)
Block(5,44,-7,OBSIDIAN)
Block(5,44,-6,OBSIDIAN)
Block(5,44,-5,OBSIDIAN)
Block(5,44,-4,OBSIDIAN)
Block(5,44,-3,SANDSTONE)
Block(5,44,-2,SANDSTONE)
Block(5,44,-1,SANDSTONE)
Block(5,44,0,SANDSTONE)
Block(5,44,1,SANDSTONE)
Block(5,44,2,SANDSTONE)
Block(5,45,-7,OBSIDIAN)
Block(5,45,-6,OBSIDIAN)
Block(5,45,-5,OBSIDIAN)
Block(5,45,-4,SANDSTONE)
Block(5,45,-3,SANDSTONE)
Block(5,45,-2,SANDSTONE)
Block(5,45,-1,SANDSTONE)
Block(5,45,0,SANDSTONE)
Block(5,45,1,SANDSTONE)
Block(5,46,-7,OBSIDIAN)
Block(5,46,-6,OBSIDIAN)
Block(5,46,-5,OBSIDIAN)
Block(5,46,-4,SANDSTONE)
Block(5,46,-3,SANDSTONE)
Block(5,46,-2,SANDSTONE)
Block(5,46,-1,SANDSTONE)
Block(5,46,0,SANDSTONE)
Block(5,47,-7,OBSIDIAN)
Block(5,47,-6,OBSIDIAN)
Block(5,47,-5,SANDSTONE)
Block(5,47,-4,SANDSTONE)
Block(5,47,-3,SANDSTONE)
Block(5,47,-2,SANDSTONE)
Block(5,47,-1,SANDSTONE)
Block(5,47,0,SANDSTONE)
Block(5,48,-7,SANDSTONE)
Block(5,48,-6,SANDSTONE)
Block(5,48,-5,SANDSTONE)
Block(5,48,-4,SANDSTONE)
Block(5,48,-3,SANDSTONE)
Block(5,48,-2,SANDSTONE)
Block(5,48,-1,SANDSTONE)
Block(5,49,-7,SANDSTONE)
Block(5,49,-6,SANDSTONE)
Block(5,49,-5,SANDSTONE)
Block(5,49,-4,SANDSTONE)
Block(5,49,-3,SANDSTONE)
Block(5,49,-2,SANDSTONE)
Block(5,50,-7,SANDSTONE)
Block(5,50,-6,SANDSTONE)
Block(5,50,-5,SANDSTONE)
Block(5,50,-4,SANDSTONE)
Block(5,50,-3,SANDSTONE)
Block(5,51,-7,SANDSTONE)
Block(5,51,-6,SANDSTONE)
Block(5,51,-5,SANDSTONE)
Block(5,51,-4,SANDSTONE)
Block(5,51,-3,SANDSTONE)
Block(5,52,-7,SANDSTONE)
Block(5,52,-6,SANDSTONE)
Block(5,52,-5,SANDSTONE)
Block(5,52,-4,SANDSTONE)
Block(5,53,-7,SANDSTONE)
Block(5,53,-6,SANDSTONE)
Block(5,53,-5,SANDSTONE)
Block(5,54,-7,SANDSTONE)
Block(5,54,-6,SANDSTONE)
Block(5,55,-7,SANDSTONE)
Block(5,56,-7,SANDSTONE)
Block(6,3,8,SANDSTONE)
Block(6,4,8,SANDSTONE)
Block(6,5,8,SANDSTONE)
Block(6,6,7,SANDSTONE)
Block(6,6,8,SANDSTONE)
Block(6,7,7,SANDSTONE)
Block(6,7,8,SANDSTONE)
Block(6,8,6,SANDSTONE)
Block(6,8,7,SANDSTONE)
Block(6,8,8,SANDSTONE)
Block(6,9,6,SANDSTONE)
Block(6,9,7,SANDSTONE)
Block(6,9,8,SANDSTONE)
Block(6,10,6,SANDSTONE)
Block(6,10,7,SANDSTONE)
Block(6,10,8,SANDSTONE)
Block(6,11,5,SANDSTONE)
Block(6,11,6,SANDSTONE)
Block(6,11,7,SANDSTONE)
Block(6,11,8,SANDSTONE)
Block(6,12,5,SANDSTONE)
Block(6,12,6,SANDSTONE)
Block(6,12,7,SANDSTONE)
Block(6,12,8,SANDSTONE)
Block(6,13,5,SANDSTONE)
Block(6,13,6,SANDSTONE)
Block(6,13,7,SANDSTONE)
Block(6,13,8,SANDSTONE)
Block(6,14,4,SANDSTONE)
Block(6,14,5,SANDSTONE)
Block(6,14,6,SANDSTONE)
Block(6,14,7,SANDSTONE)
Block(6,14,8,SANDSTONE)
Block(6,15,4,SANDSTONE)
Block(6,15,5,SANDSTONE)
Block(6,15,6,SANDSTONE)
Block(6,15,7,SANDSTONE)
Block(6,15,8,SANDSTONE)
Block(6,16,3,OBSIDIAN)
Block(6,16,4,SANDSTONE)
Block(6,16,5,SANDSTONE)
Block(6,16,6,SANDSTONE)
Block(6,16,7,SANDSTONE)
Block(6,16,8,SANDSTONE)
Block(6,17,3,OBSIDIAN)
Block(6,17,4,OBSIDIAN)
Block(6,17,5,SANDSTONE)
Block(6,17,6,SANDSTONE)
Block(6,17,7,SANDSTONE)
Block(6,17,8,OBSIDIAN)
Block(6,18,3,OBSIDIAN)
Block(6,18,4,OBSIDIAN)
Block(6,18,5,OBSIDIAN)
Block(6,18,6,OBSIDIAN)
Block(6,18,7,OBSIDIAN)
Block(6,18,8,OBSIDIAN)
Block(6,19,2,OBSIDIAN)
Block(6,19,3,OBSIDIAN)
Block(6,19,4,OBSIDIAN)
Block(6,19,5,OBSIDIAN)
Block(6,19,6,OBSIDIAN)
Block(6,19,7,OBSIDIAN)
Block(6,19,8,OBSIDIAN)
Block(6,20,2,OBSIDIAN)
Block(6,20,3,OBSIDIAN)
Block(6,20,4,OBSIDIAN)
Block(6,20,5,OBSIDIAN)
Block(6,20,6,OBSIDIAN)
Block(6,20,7,OBSIDIAN)
Block(6,20,8,OBSIDIAN)
Block(6,21,1,OBSIDIAN)
Block(6,21,2,OBSIDIAN)
Block(6,21,3,OBSIDIAN)
Block(6,21,4,OBSIDIAN)
Block(6,21,5,OBSIDIAN)
Block(6,21,6,OBSIDIAN)
Block(6,21,7,OBSIDIAN)
Block(6,21,8,OBSIDIAN)
Block(6,22,1,OBSIDIAN)
Block(6,22,2,OBSIDIAN)
Block(6,22,3,OBSIDIAN)
Block(6,22,4,OBSIDIAN)
Block(6,22,5,OBSIDIAN)
Block(6,22,6,OBSIDIAN)
Block(6,22,7,OBSIDIAN)
Block(6,22,8,OBSIDIAN)
Block(6,23,1,OBSIDIAN)
Block(6,23,2,OBSIDIAN)
Block(6,23,3,OBSIDIAN)
Block(6,23,4,OBSIDIAN)
Block(6,23,5,OBSIDIAN)
Block(6,23,6,OBSIDIAN)
Block(6,23,7,OBSIDIAN)
Block(6,23,8,OBSIDIAN)
Block(6,24,0,OBSIDIAN)
Block(6,24,1,OBSIDIAN)
Block(6,24,2,OBSIDIAN)
Block(6,24,3,OBSIDIAN)
Block(6,24,4,OBSIDIAN)
Block(6,24,5,OBSIDIAN)
Block(6,24,6,OBSIDIAN)
Block(6,24,7,OBSIDIAN)
Block(6,24,8,OBSIDIAN)
Block(6,25,0,OBSIDIAN)
Block(6,25,1,OBSIDIAN)
Block(6,25,2,OBSIDIAN)
Block(6,25,3,OBSIDIAN)
Block(6,25,4,OBSIDIAN)
Block(6,25,5,OBSIDIAN)
Block(6,25,6,OBSIDIAN)
Block(6,25,7,OBSIDIAN)
Block(6,25,8,OBSIDIAN)
Block(6,26,0,OBSIDIAN)
Block(6,26,1,OBSIDIAN)
Block(6,26,2,OBSIDIAN)
Block(6,26,3,OBSIDIAN)
Block(6,26,4,OBSIDIAN)
Block(6,26,5,OBSIDIAN)
Block(6,26,6,OBSIDIAN)
Block(6,26,7,OBSIDIAN)
Block(6,26,8,OBSIDIAN)
Block(6,27,-1,OBSIDIAN)
Block(6,27,0,OBSIDIAN)
Block(6,27,1,OBSIDIAN)
Block(6,27,2,OBSIDIAN)
Block(6,27,3,OBSIDIAN)
Block(6,27,4,OBSIDIAN)
Block(6,27,5,OBSIDIAN)
Block(6,27,6,OBSIDIAN)
Block(6,27,7,OBSIDIAN)
Block(6,27,8,SANDSTONE)
Block(6,28,-1,OBSIDIAN)
Block(6,28,0,OBSIDIAN)
Block(6,28,1,OBSIDIAN)
Block(6,28,2,OBSIDIAN)
Block(6,28,3,OBSIDIAN)
Block(6,28,4,OBSIDIAN)
Block(6,28,5,OBSIDIAN)
Block(6,28,6,OBSIDIAN)
Block(6,28,7,SANDSTONE)
Block(6,28,8,SANDSTONE)
Block(6,29,-2,OBSIDIAN)
Block(6,29,-1,OBSIDIAN)
Block(6,29,0,OBSIDIAN)
Block(6,29,1,OBSIDIAN)
Block(6,29,2,OBSIDIAN)
Block(6,29,3,OBSIDIAN)
Block(6,29,4,OBSIDIAN)
Block(6,29,5,OBSIDIAN)
Block(6,29,6,OBSIDIAN)
Block(6,29,7,SANDSTONE)
Block(6,29,8,SANDSTONE)
Block(6,30,-2,OBSIDIAN)
Block(6,30,-1,OBSIDIAN)
Block(6,30,0,OBSIDIAN)
Block(6,30,1,OBSIDIAN)
Block(6,30,2,OBSIDIAN)
Block(6,30,3,OBSIDIAN)
Block(6,30,4,OBSIDIAN)
Block(6,30,5,OBSIDIAN)
Block(6,30,6,OBSIDIAN)
Block(6,30,7,SANDSTONE)
Block(6,30,8,SANDSTONE)
Block(6,31,-2,OBSIDIAN)
Block(6,31,-1,OBSIDIAN)
Block(6,31,0,OBSIDIAN)
Block(6,31,1,OBSIDIAN)
Block(6,31,2,OBSIDIAN)
Block(6,31,3,OBSIDIAN)
Block(6,31,4,OBSIDIAN)
Block(6,31,5,OBSIDIAN)
Block(6,31,6,OBSIDIAN)
Block(6,31,7,SANDSTONE)
Block(6,31,8,SANDSTONE)
Block(6,32,-3,OBSIDIAN)
Block(6,32,-2,OBSIDIAN)
Block(6,32,-1,OBSIDIAN)
Block(6,32,0,OBSIDIAN)
Block(6,32,1,OBSIDIAN)
Block(6,32,2,OBSIDIAN)
Block(6,32,3,OBSIDIAN)
Block(6,32,4,OBSIDIAN)
Block(6,32,5,OBSIDIAN)
Block(6,32,6,SANDSTONE)
Block(6,32,7,SANDSTONE)
Block(6,32,8,SANDSTONE)
Block(6,33,-3,OBSIDIAN)
Block(6,33,-2,OBSIDIAN)
Block(6,33,-1,OBSIDIAN)
Block(6,33,0,OBSIDIAN)
Block(6,33,1,OBSIDIAN)
Block(6,33,2,OBSIDIAN)
Block(6,33,3,OBSIDIAN)
Block(6,33,4,SANDSTONE)
Block(6,33,5,SANDSTONE)
Block(6,33,6,SANDSTONE)
Block(6,33,7,SANDSTONE)
Block(6,33,8,SANDSTONE)
Block(6,34,-3,OBSIDIAN)
Block(6,34,-2,OBSIDIAN)
Block(6,34,-1,OBSIDIAN)
Block(6,34,0,OBSIDIAN)
Block(6,34,1,OBSIDIAN)
Block(6,34,2,OBSIDIAN)
Block(6,34,3,SANDSTONE)
Block(6,34,4,SANDSTONE)
Block(6,34,5,SANDSTONE)
Block(6,34,6,SANDSTONE)
Block(6,34,7,SANDSTONE)
Block(6,34,8,SANDSTONE)
Block(6,35,-4,OBSIDIAN)
Block(6,35,-3,OBSIDIAN)
Block(6,35,-2,OBSIDIAN)
Block(6,35,-1,OBSIDIAN)
Block(6,35,0,OBSIDIAN)
Block(6,35,1,OBSIDIAN)
Block(6,35,2,OBSIDIAN)
Block(6,35,3,SANDSTONE)
Block(6,35,4,SANDSTONE)
Block(6,35,5,SANDSTONE)
Block(6,35,6,SANDSTONE)
Block(6,35,7,SANDSTONE)
Block(6,35,8,SANDSTONE)
Block(6,36,-4,OBSIDIAN)
Block(6,36,-3,OBSIDIAN)
Block(6,36,-2,OBSIDIAN)
Block(6,36,-1,OBSIDIAN)
Block(6,36,0,OBSIDIAN)
Block(6,36,1,OBSIDIAN)
Block(6,36,2,SANDSTONE)
Block(6,36,3,SANDSTONE)
Block(6,36,4,SANDSTONE)
Block(6,36,5,SANDSTONE)
Block(6,36,6,SANDSTONE)
Block(6,36,7,SANDSTONE)
Block(6,36,8,SANDSTONE)
Block(6,37,-5,OBSIDIAN)
Block(6,37,-4,OBSIDIAN)
Block(6,37,-3,OBSIDIAN)
Block(6,37,-2,OBSIDIAN)
Block(6,37,-1,OBSIDIAN)
Block(6,37,0,OBSIDIAN)
Block(6,37,1,SANDSTONE)
Block(6,37,2,SANDSTONE)
Block(6,37,3,SANDSTONE)
Block(6,37,4,SANDSTONE)
Block(6,37,5,SANDSTONE)
Block(6,37,6,SANDSTONE)
Block(6,37,7,SANDSTONE)
Block(6,38,-5,OBSIDIAN)
Block(6,38,-4,OBSIDIAN)
Block(6,38,-3,OBSIDIAN)
Block(6,38,-2,OBSIDIAN)
Block(6,38,-1,OBSIDIAN)
Block(6,38,0,SANDSTONE)
Block(6,38,1,SANDSTONE)
Block(6,38,2,SANDSTONE)
Block(6,38,3,SANDSTONE)
Block(6,38,4,SANDSTONE)
Block(6,38,5,SANDSTONE)
Block(6,38,6,SANDSTONE)
Block(6,39,-5,OBSIDIAN)
Block(6,39,-4,OBSIDIAN)
Block(6,39,-3,OBSIDIAN)
Block(6,39,-2,OBSIDIAN)
Block(6,39,-1,SANDSTONE)
Block(6,39,0,SANDSTONE)
Block(6,39,1,SANDSTONE)
Block(6,39,2,SANDSTONE)
Block(6,39,3,SANDSTONE)
Block(6,39,4,SANDSTONE)
Block(6,39,5,SANDSTONE)
Block(6,39,6,SANDSTONE)
Block(6,40,-6,OBSIDIAN)
Block(6,40,-5,OBSIDIAN)
Block(6,40,-4,OBSIDIAN)
Block(6,40,-3,OBSIDIAN)
Block(6,40,-2,OBSIDIAN)
Block(6,40,-1,SANDSTONE)
Block(6,40,0,SANDSTONE)
Block(6,40,1,SANDSTONE)
Block(6,40,2,SANDSTONE)
Block(6,40,3,SANDSTONE)
Block(6,40,4,SANDSTONE)
Block(6,40,5,SANDSTONE)
Block(6,41,-6,OBSIDIAN)
Block(6,41,-5,OBSIDIAN)
Block(6,41,-4,OBSIDIAN)
Block(6,41,-3,OBSIDIAN)
Block(6,41,-2,OBSIDIAN)
Block(6,41,-1,SANDSTONE)
Block(6,41,0,SANDSTONE)
Block(6,41,1,SANDSTONE)
Block(6,41,2,SANDSTONE)
Block(6,41,3,SANDSTONE)
Block(6,41,4,SANDSTONE)
Block(6,42,-7,OBSIDIAN)
Block(6,42,-6,OBSIDIAN)
Block(6,42,-5,OBSIDIAN)
Block(6,42,-4,OBSIDIAN)
Block(6,42,-3,OBSIDIAN)
Block(6,42,-2,OBSIDIAN)
Block(6,42,-1,SANDSTONE)
Block(6,42,0,SANDSTONE)
Block(6,42,1,SANDSTONE)
Block(6,42,2,SANDSTONE)
Block(6,42,3,SANDSTONE)
Block(6,43,-7,OBSIDIAN)
Block(6,43,-6,OBSIDIAN)
Block(6,43,-5,OBSIDIAN)
Block(6,43,-4,OBSIDIAN)
Block(6,43,-3,OBSIDIAN)
Block(6,43,-2,OBSIDIAN)
Block(6,43,-1,SANDSTONE)
Block(6,43,0,SANDSTONE)
Block(6,43,1,SANDSTONE)
Block(6,43,2,SANDSTONE)
Block(6,43,3,SANDSTONE)
Block(6,44,-7,OBSIDIAN)
Block(6,44,-6,OBSIDIAN)
Block(6,44,-5,OBSIDIAN)
Block(6,44,-4,OBSIDIAN)
Block(6,44,-3,OBSIDIAN)
Block(6,44,-2,SANDSTONE)
Block(6,44,-1,SANDSTONE)
Block(6,44,0,SANDSTONE)
Block(6,44,1,SANDSTONE)
Block(6,44,2,SANDSTONE)
Block(6,45,-7,OBSIDIAN)
Block(6,45,-6,OBSIDIAN)
Block(6,45,-5,OBSIDIAN)
Block(6,45,-4,OBSIDIAN)
Block(6,45,-3,SANDSTONE)
Block(6,45,-2,SANDSTONE)
Block(6,45,-1,SANDSTONE)
Block(6,45,0,SANDSTONE)
Block(6,45,1,SANDSTONE)
Block(6,46,-7,OBSIDIAN)
Block(6,46,-6,OBSIDIAN)
Block(6,46,-5,OBSIDIAN)
Block(6,46,-4,OBSIDIAN)
Block(6,46,-3,SANDSTONE)
Block(6,46,-2,SANDSTONE)
Block(6,46,-1,SANDSTONE)
Block(6,46,0,SANDSTONE)
Block(6,47,-7,OBSIDIAN)
Block(6,47,-6,OBSIDIAN)
Block(6,47,-5,OBSIDIAN)
Block(6,47,-4,OBSIDIAN)
Block(6,47,-3,SANDSTONE)
Block(6,47,-2,SANDSTONE)
Block(6,47,-1,SANDSTONE)
Block(6,48,-7,OBSIDIAN)
Block(6,48,-6,SANDSTONE)
Block(6,48,-5,SANDSTONE)
Block(6,48,-4,SANDSTONE)
Block(6,48,-3,SANDSTONE)
Block(6,48,-2,SANDSTONE)
Block(6,48,-1,SANDSTONE)
Block(6,49,-7,SANDSTONE)
Block(6,49,-6,SANDSTONE)
Block(6,49,-5,SANDSTONE)
Block(6,49,-4,SANDSTONE)
Block(6,49,-3,SANDSTONE)
Block(6,49,-2,SANDSTONE)
Block(6,50,-7,SANDSTONE)
Block(6,50,-6,SANDSTONE)
Block(6,50,-5,SANDSTONE)
Block(6,50,-4,SANDSTONE)
Block(6,50,-3,SANDSTONE)
Block(6,51,-7,SANDSTONE)
Block(6,51,-6,SANDSTONE)
Block(6,51,-5,SANDSTONE)
Block(6,51,-4,SANDSTONE)
Block(6,52,-7,SANDSTONE)
Block(6,52,-6,SANDSTONE)
Block(6,52,-5,SANDSTONE)
Block(6,53,-7,SANDSTONE)
Block(6,53,-6,SANDSTONE)
Block(6,54,-7,SANDSTONE)
Block(6,54,-6,SANDSTONE)
Block(6,55,-7,SANDSTONE)
Block(7,4,8,SANDSTONE)
Block(7,5,8,SANDSTONE)
Block(7,6,8,SANDSTONE)
Block(7,7,7,SANDSTONE)
Block(7,7,8,SANDSTONE)
Block(7,8,7,SANDSTONE)
Block(7,8,8,SANDSTONE)
Block(7,9,6,SANDSTONE)
Block(7,9,7,SANDSTONE)
Block(7,9,8,SANDSTONE)
Block(7,10,6,SANDSTONE)
Block(7,10,7,SANDSTONE)
Block(7,10,8,SANDSTONE)
Block(7,11,6,SANDSTONE)
Block(7,11,7,SANDSTONE)
Block(7,11,8,SANDSTONE)
Block(7,12,5,SANDSTONE)
Block(7,12,6,SANDSTONE)
Block(7,12,7,SANDSTONE)
Block(7,12,8,SANDSTONE)
Block(7,13,5,SANDSTONE)
Block(7,13,6,SANDSTONE)
Block(7,13,7,SANDSTONE)
Block(7,13,8,SANDSTONE)
Block(7,14,4,SANDSTONE)
Block(7,14,5,SANDSTONE)
Block(7,14,6,SANDSTONE)
Block(7,14,7,SANDSTONE)
Block(7,14,8,SANDSTONE)
Block(7,15,4,SANDSTONE)
Block(7,15,5,SANDSTONE)
Block(7,15,6,SANDSTONE)
Block(7,15,7,SANDSTONE)
Block(7,15,8,SANDSTONE)
Block(7,16,4,SANDSTONE)
Block(7,16,5,SANDSTONE)
Block(7,16,6,SANDSTONE)
Block(7,16,7,SANDSTONE)
Block(7,16,8,SANDSTONE)
Block(7,17,3,SANDSTONE)
Block(7,17,4,SANDSTONE)
Block(7,17,5,SANDSTONE)
Block(7,17,6,SANDSTONE)
Block(7,17,7,SANDSTONE)
Block(7,17,8,SANDSTONE)
Block(7,18,3,OBSIDIAN)
Block(7,18,4,SANDSTONE)
Block(7,18,5,SANDSTONE)
Block(7,18,6,SANDSTONE)
Block(7,18,7,SANDSTONE)
Block(7,18,8,SANDSTONE)
Block(7,19,3,OBSIDIAN)
Block(7,19,4,OBSIDIAN)
Block(7,19,5,OBSIDIAN)
Block(7,19,6,OBSIDIAN)
Block(7,19,7,OBSIDIAN)
Block(7,19,8,OBSIDIAN)
Block(7,20,2,OBSIDIAN)
Block(7,20,3,OBSIDIAN)
Block(7,20,4,OBSIDIAN)
Block(7,20,5,OBSIDIAN)
Block(7,20,6,OBSIDIAN)
Block(7,20,7,OBSIDIAN)
Block(7,20,8,OBSIDIAN)
Block(7,21,2,OBSIDIAN)
Block(7,21,3,OBSIDIAN)
Block(7,21,4,OBSIDIAN)
Block(7,21,5,OBSIDIAN)
Block(7,21,6,OBSIDIAN)
Block(7,21,7,OBSIDIAN)
Block(7,21,8,OBSIDIAN)
Block(7,22,1,OBSIDIAN)
Block(7,22,2,OBSIDIAN)
Block(7,22,3,OBSIDIAN)
Block(7,22,4,OBSIDIAN)
Block(7,22,5,OBSIDIAN)
Block(7,22,6,OBSIDIAN)
Block(7,22,7,OBSIDIAN)
Block(7,22,8,OBSIDIAN)
Block(7,23,1,OBSIDIAN)
Block(7,23,2,OBSIDIAN)
Block(7,23,3,OBSIDIAN)
Block(7,23,4,OBSIDIAN)
Block(7,23,5,OBSIDIAN)
Block(7,23,6,OBSIDIAN)
Block(7,23,7,OBSIDIAN)
Block(7,23,8,OBSIDIAN)
Block(7,24,1,OBSIDIAN)
Block(7,24,2,OBSIDIAN)
Block(7,24,3,OBSIDIAN)
Block(7,24,4,OBSIDIAN)
Block(7,24,5,OBSIDIAN)
Block(7,24,6,OBSIDIAN)
Block(7,24,7,OBSIDIAN)
Block(7,24,8,OBSIDIAN)
Block(7,25,0,OBSIDIAN)
Block(7,25,1,OBSIDIAN)
Block(7,25,2,OBSIDIAN)
Block(7,25,3,OBSIDIAN)
Block(7,25,4,OBSIDIAN)
Block(7,25,5,OBSIDIAN)
Block(7,25,6,OBSIDIAN)
Block(7,25,7,OBSIDIAN)
Block(7,25,8,OBSIDIAN)
Block(7,26,0,OBSIDIAN)
Block(7,26,1,OBSIDIAN)
Block(7,26,2,OBSIDIAN)
Block(7,26,3,OBSIDIAN)
Block(7,26,4,OBSIDIAN)
Block(7,26,5,OBSIDIAN)
Block(7,26,6,OBSIDIAN)
Block(7,26,7,OBSIDIAN)
Block(7,26,8,OBSIDIAN)
Block(7,27,0,OBSIDIAN)
Block(7,27,1,OBSIDIAN)
Block(7,27,2,OBSIDIAN)
Block(7,27,3,OBSIDIAN)
Block(7,27,4,OBSIDIAN)
Block(7,27,5,OBSIDIAN)
Block(7,27,6,OBSIDIAN)
Block(7,27,7,OBSIDIAN)
Block(7,27,8,SANDSTONE)
Block(7,28,-1,OBSIDIAN)
Block(7,28,0,OBSIDIAN)
Block(7,28,1,OBSIDIAN)
Block(7,28,2,OBSIDIAN)
Block(7,28,3,OBSIDIAN)
Block(7,28,4,OBSIDIAN)
Block(7,28,5,OBSIDIAN)
Block(7,28,6,OBSIDIAN)
Block(7,28,7,SANDSTONE)
Block(7,28,8,SANDSTONE)
Block(7,29,-1,OBSIDIAN)
Block(7,29,0,OBSIDIAN)
Block(7,29,1,OBSIDIAN)
Block(7,29,2,OBSIDIAN)
Block(7,29,3,OBSIDIAN)
Block(7,29,4,OBSIDIAN)
Block(7,29,5,OBSIDIAN)
Block(7,29,6,SANDSTONE)
Block(7,29,7,SANDSTONE)
Block(7,29,8,SANDSTONE)
Block(7,30,-2,OBSIDIAN)
Block(7,30,-1,OBSIDIAN)
Block(7,30,0,OBSIDIAN)
Block(7,30,1,OBSIDIAN)
Block(7,30,2,OBSIDIAN)
Block(7,30,3,OBSIDIAN)
Block(7,30,4,OBSIDIAN)
Block(7,30,5,OBSIDIAN)
Block(7,30,6,SANDSTONE)
Block(7,30,7,SANDSTONE)
Block(7,30,8,SANDSTONE)
Block(7,31,-2,OBSIDIAN)
Block(7,31,-1,OBSIDIAN)
Block(7,31,0,OBSIDIAN)
Block(7,31,1,OBSIDIAN)
Block(7,31,2,OBSIDIAN)
Block(7,31,3,OBSIDIAN)
Block(7,31,4,OBSIDIAN)
Block(7,31,5,OBSIDIAN)
Block(7,31,6,SANDSTONE)
Block(7,31,7,SANDSTONE)
Block(7,31,8,SANDSTONE)
Block(7,32,-2,OBSIDIAN)
Block(7,32,-1,OBSIDIAN)
Block(7,32,0,OBSIDIAN)
Block(7,32,1,OBSIDIAN)
Block(7,32,2,OBSIDIAN)
Block(7,32,3,OBSIDIAN)
Block(7,32,4,OBSIDIAN)
Block(7,32,5,SANDSTONE)
Block(7,32,6,SANDSTONE)
Block(7,32,7,SANDSTONE)
Block(7,32,8,SANDSTONE)
Block(7,33,-3,OBSIDIAN)
Block(7,33,-2,OBSIDIAN)
Block(7,33,-1,OBSIDIAN)
Block(7,33,0,OBSIDIAN)
Block(7,33,1,OBSIDIAN)
Block(7,33,2,OBSIDIAN)
Block(7,33,3,OBSIDIAN)
Block(7,33,4,SANDSTONE)
Block(7,33,5,SANDSTONE)
Block(7,33,6,SANDSTONE)
Block(7,33,7,SANDSTONE)
Block(7,33,8,SANDSTONE)
Block(7,34,-3,OBSIDIAN)
Block(7,34,-2,OBSIDIAN)
Block(7,34,-1,OBSIDIAN)
Block(7,34,0,OBSIDIAN)
Block(7,34,1,OBSIDIAN)
Block(7,34,2,OBSIDIAN)
Block(7,34,3,SANDSTONE)
Block(7,34,4,SANDSTONE)
Block(7,34,5,SANDSTONE)
Block(7,34,6,SANDSTONE)
Block(7,34,7,SANDSTONE)
Block(7,34,8,SANDSTONE)
Block(7,35,-4,OBSIDIAN)
Block(7,35,-3,OBSIDIAN)
Block(7,35,-2,OBSIDIAN)
Block(7,35,-1,OBSIDIAN)
Block(7,35,0,OBSIDIAN)
Block(7,35,1,OBSIDIAN)
Block(7,35,2,SANDSTONE)
Block(7,35,3,SANDSTONE)
Block(7,35,4,SANDSTONE)
Block(7,35,5,SANDSTONE)
Block(7,35,6,SANDSTONE)
Block(7,35,7,SANDSTONE)
Block(7,35,8,SANDSTONE)
Block(7,36,-4,OBSIDIAN)
Block(7,36,-3,OBSIDIAN)
Block(7,36,-2,OBSIDIAN)
Block(7,36,-1,OBSIDIAN)
Block(7,36,0,OBSIDIAN)
Block(7,36,1,OBSIDIAN)
Block(7,36,2,SANDSTONE)
Block(7,36,3,SANDSTONE)
Block(7,36,4,SANDSTONE)
Block(7,36,5,SANDSTONE)
Block(7,36,6,SANDSTONE)
Block(7,36,7,SANDSTONE)
Block(7,36,8,SANDSTONE)
Block(7,37,-4,OBSIDIAN)
Block(7,37,-3,OBSIDIAN)
Block(7,37,-2,OBSIDIAN)
Block(7,37,-1,OBSIDIAN)
Block(7,37,0,OBSIDIAN)
Block(7,37,1,SANDSTONE)
Block(7,37,2,SANDSTONE)
Block(7,37,3,SANDSTONE)
Block(7,37,4,SANDSTONE)
Block(7,37,5,SANDSTONE)
Block(7,37,6,SANDSTONE)
Block(7,37,7,SANDSTONE)
Block(7,38,-5,OBSIDIAN)
Block(7,38,-4,OBSIDIAN)
Block(7,38,-3,OBSIDIAN)
Block(7,38,-2,OBSIDIAN)
Block(7,38,-1,OBSIDIAN)
Block(7,38,0,SANDSTONE)
Block(7,38,1,SANDSTONE)
Block(7,38,2,SANDSTONE)
Block(7,38,3,SANDSTONE)
Block(7,38,4,SANDSTONE)
Block(7,38,5,SANDSTONE)
Block(7,38,6,SANDSTONE)
Block(7,39,-5,OBSIDIAN)
Block(7,39,-4,OBSIDIAN)
Block(7,39,-3,OBSIDIAN)
Block(7,39,-2,OBSIDIAN)
Block(7,39,-1,OBSIDIAN)
Block(7,39,0,SANDSTONE)
Block(7,39,1,SANDSTONE)
Block(7,39,2,SANDSTONE)
Block(7,39,3,SANDSTONE)
Block(7,39,4,SANDSTONE)
Block(7,39,5,SANDSTONE)
Block(7,40,-5,OBSIDIAN)
Block(7,40,-4,OBSIDIAN)
Block(7,40,-3,OBSIDIAN)
Block(7,40,-2,OBSIDIAN)
Block(7,40,-1,SANDSTONE)
Block(7,40,0,SANDSTONE)
Block(7,40,1,SANDSTONE)
Block(7,40,2,SANDSTONE)
Block(7,40,3,SANDSTONE)
Block(7,40,4,SANDSTONE)
Block(7,40,5,SANDSTONE)
Block(7,41,-6,OBSIDIAN)
Block(7,41,-5,OBSIDIAN)
Block(7,41,-4,OBSIDIAN)
Block(7,41,-3,OBSIDIAN)
Block(7,41,-2,OBSIDIAN)
Block(7,41,-1,SANDSTONE)
Block(7,41,0,SANDSTONE)
Block(7,41,1,SANDSTONE)
Block(7,41,2,SANDSTONE)
Block(7,41,3,SANDSTONE)
Block(7,41,4,SANDSTONE)
Block(7,42,-6,OBSIDIAN)
Block(7,42,-5,OBSIDIAN)
Block(7,42,-4,OBSIDIAN)
Block(7,42,-3,OBSIDIAN)
Block(7,42,-2,OBSIDIAN)
Block(7,42,-1,SANDSTONE)
Block(7,42,0,SANDSTONE)
Block(7,42,1,SANDSTONE)
Block(7,42,2,SANDSTONE)
Block(7,42,3,SANDSTONE)
Block(7,43,-6,OBSIDIAN)
Block(7,43,-5,OBSIDIAN)
Block(7,43,-4,OBSIDIAN)
Block(7,43,-3,OBSIDIAN)
Block(7,43,-2,OBSIDIAN)
Block(7,43,-1,OBSIDIAN)
Block(7,43,0,SANDSTONE)
Block(7,43,1,SANDSTONE)
Block(7,43,2,SANDSTONE)
Block(7,44,-6,OBSIDIAN)
Block(7,44,-5,OBSIDIAN)
Block(7,44,-4,OBSIDIAN)
Block(7,44,-3,OBSIDIAN)
Block(7,44,-2,OBSIDIAN)
Block(7,44,-1,OBSIDIAN)
Block(7,44,0,SANDSTONE)
Block(7,44,1,SANDSTONE)
Block(7,44,2,SANDSTONE)
Block(7,45,-7,OBSIDIAN)
Block(7,45,-6,OBSIDIAN)
Block(7,45,-5,OBSIDIAN)
Block(7,45,-4,OBSIDIAN)
Block(7,45,-3,OBSIDIAN)
Block(7,45,-2,OBSIDIAN)
Block(7,45,-1,SANDSTONE)
Block(7,45,0,SANDSTONE)
Block(7,45,1,SANDSTONE)
Block(7,46,-7,OBSIDIAN)
Block(7,46,-6,OBSIDIAN)
Block(7,46,-5,OBSIDIAN)
Block(7,46,-4,OBSIDIAN)
Block(7,46,-3,OBSIDIAN)
Block(7,46,-2,SANDSTONE)
Block(7,46,-1,SANDSTONE)
Block(7,46,0,SANDSTONE)
Block(7,47,-7,OBSIDIAN)
Block(7,47,-6,OBSIDIAN)
Block(7,47,-5,OBSIDIAN)
Block(7,47,-4,OBSIDIAN)
Block(7,47,-3,OBSIDIAN)
Block(7,47,-2,SANDSTONE)
Block(7,47,-1,SANDSTONE)
Block(7,48,-7,OBSIDIAN)
Block(7,48,-6,OBSIDIAN)
Block(7,48,-5,OBSIDIAN)
Block(7,48,-4,OBSIDIAN)
Block(7,48,-3,OBSIDIAN)
Block(7,48,-2,SANDSTONE)
Block(7,49,-7,OBSIDIAN)
Block(7,49,-6,SANDSTONE)
Block(7,49,-5,SANDSTONE)
Block(7,49,-4,SANDSTONE)
Block(7,49,-3,SANDSTONE)
Block(7,50,-7,SANDSTONE)
Block(7,50,-6,SANDSTONE)
Block(7,50,-5,SANDSTONE)
Block(7,50,-4,SANDSTONE)
Block(7,51,-7,SANDSTONE)
Block(7,51,-6,SANDSTONE)
Block(7,51,-5,SANDSTONE)
Block(7,52,-7,SANDSTONE)
Block(7,52,-6,SANDSTONE)
Block(7,53,-7,SANDSTONE)
Block(7,53,-6,SANDSTONE)
Block(7,54,-7,SANDSTONE)

#######################################################################
# +-----------------------------------------------------------------+ #
# |                             Branches                            | #
# +-----------------------------------------------------------------+ #
#######################################################################


#######################################################################
# +-----------------------------------------------------------------+ #
# |                             Entities                            | #
# +-----------------------------------------------------------------+ #
#######################################################################


#######################################################################
# +-----------------------------------------------------------------+ #
# |                            Particles                            | #
# +-----------------------------------------------------------------+ #
#######################################################################


#######################################################################
# +-----------------------------------------------------------------+ #
# |                             Spawners                            | #
# +-----------------------------------------------------------------+ #
#######################################################################


#######################################################################
# +-----------------------------------------------------------------+ #
# |                             ModData                             | #
# +-----------------------------------------------------------------+ #
#######################################################################

