
#######################################################################
# +-----------------------------------------------------------------+ #
# |                            BO3 object                           | #
# +-----------------------------------------------------------------+ #
#######################################################################

Author: NLBlackHeavenNL

Description: No description given

Version: 3

SettingsMode: WriteWithoutComments


#######################################################################
# +-----------------------------------------------------------------+ #
# |                          Main settings                          | #
# +-----------------------------------------------------------------+ #
#######################################################################

Tree: true

Frequency: 1

Rarity: 100.0

RotateRandomly: false

SpawnHeight: highestSolidBlock

SpawnHeightOffset: -1

SpawnHeightVariance: 0

##############################
# Height Limits for the BO3. #
##############################

MinHeight: 0

MaxHeight: 255

######################
# Extrusion settings #
######################

ExtrudeMode: None

ExtrudeThroughBlocks: AIR

MaxBranchDepth: 10

ExcludedBiomes: All


#######################################################################
# +-----------------------------------------------------------------+ #
# |                      Source block settings                      | #
# +-----------------------------------------------------------------+ #
#######################################################################

SourceBlocks: AIR,GRASS,DIRT,biomesoplenty:dirt

MaxPercentageOutsideSourceBlock: 0

OutsideSourceBlock: placeAnyway

DoReplaceBlocks: true

IsOTGPlus: false


#######################################################################
# +-----------------------------------------------------------------+ #
# |                              Blocks                             | #
# +-----------------------------------------------------------------+ #
#######################################################################

Block(-4,27,-2,dynamictrees:leaves0:12)
Block(-4,27,-1,dynamictrees:leaves0:12)
Block(-4,27,0,dynamictrees:leaves0:12)
Block(-4,27,1,dynamictrees:leaves0:12)
Block(-4,27,2,dynamictrees:leaves0:12)
Block(-4,28,-1,dynamictrees:leaves0:12)
Block(-4,28,0,dynamictrees:leaves0:12)
Block(-4,28,1,dynamictrees:leaves0:12)
Block(-4,28,2,dynamictrees:leaves0:12)
Block(-4,28,3,dynamictrees:leaves0:12)
Block(-4,29,0,dynamictrees:leaves0:12)
Block(-4,29,1,dynamictrees:leaves0:12)
Block(-4,29,2,dynamictrees:leaves0:12)
Block(-4,30,1,dynamictrees:leaves0:12)
Block(-3,26,-2,dynamictrees:leaves0:12)
Block(-3,26,-1,dynamictrees:leaves0:12)
Block(-3,27,-3,dynamictrees:leaves0:12)
Block(-3,27,-2,dynamictrees:leaves0:13)
Block(-3,27,-1,dynamictrees:leaves0:14)
Block(-3,27,0,dynamictrees:leaves0:15)
Block(-3,27,1,dynamictrees:leaves0:14)
Block(-3,27,2,dynamictrees:leaves0:15)
Block(-3,27,3,dynamictrees:leaves0:12)
Block(-3,28,-2,dynamictrees:leaves0:12)
Block(-3,28,-1,dynamictrees:leaves0:13)
Block(-3,28,0,dynamictrees:leaves0:14)
Block(-3,28,1,dynamictrees:leaves0:15)
Block(-3,28,2,dynamictrees:leaves0:14)
Block(-3,28,3,dynamictrees:leaves0:13)
Block(-3,28,4,dynamictrees:leaves0:12)
Block(-3,29,-1,dynamictrees:leaves0:12)
Block(-3,29,0,dynamictrees:leaves0:13)
Block(-3,29,1,dynamictrees:leaves0:14)
Block(-3,29,2,dynamictrees:leaves0:13)
Block(-3,29,3,dynamictrees:leaves0:12)
Block(-3,30,0,dynamictrees:leaves0:12)
Block(-3,30,1,dynamictrees:leaves0:13)
Block(-3,30,2,dynamictrees:leaves0:12)
Block(-3,31,1,dynamictrees:leaves0:12)
Block(-2,26,-2,dynamictrees:leaves0:12)
Block(-2,27,-3,dynamictrees:leaves0:12)
Block(-2,27,-2,dynamictrees:leaves0:14)
Block(-2,27,-1,dynamictrees:leaves0:15)
Block(-2,27,0,dynamictrees:junglebranch)
Block(-2,27,1,dynamictrees:junglebranch:1)
Block(-2,27,2,dynamictrees:junglebranch)
Block(-2,27,4,dynamictrees:leaves0:12)
Block(-2,28,-3,dynamictrees:leaves0:12)
Block(-2,28,-2,dynamictrees:leaves0:13)
Block(-2,28,-1,dynamictrees:leaves0:14)
Block(-2,28,0,dynamictrees:leaves0:15)
Block(-2,28,1,dynamictrees:junglebranch)
Block(-2,28,2,dynamictrees:leaves0:15)
Block(-2,28,3,dynamictrees:leaves0:14)
Block(-2,28,4,dynamictrees:leaves0:13)
Block(-2,28,5,dynamictrees:leaves0:12)
Block(-2,29,-2,dynamictrees:leaves0:12)
Block(-2,29,-1,dynamictrees:leaves0:13)
Block(-2,29,0,dynamictrees:leaves0:14)
Block(-2,29,1,dynamictrees:leaves0:15)
Block(-2,29,2,dynamictrees:leaves0:14)
Block(-2,29,3,dynamictrees:leaves0:13)
Block(-2,29,4,dynamictrees:leaves0:12)
Block(-2,30,-1,dynamictrees:leaves0:12)
Block(-2,30,0,dynamictrees:leaves0:13)
Block(-2,30,1,dynamictrees:leaves0:14)
Block(-2,30,2,dynamictrees:leaves0:13)
Block(-2,30,3,dynamictrees:leaves0:12)
Block(-2,31,0,dynamictrees:leaves0:12)
Block(-2,31,1,dynamictrees:leaves0:12)
Block(-2,31,2,dynamictrees:leaves0:12)
Block(-2,31,3,dynamictrees:leaves0:12)
Block(-2,32,0,dynamictrees:leaves0:12)
Block(-2,32,1,dynamictrees:leaves0:12)
Block(-2,32,2,dynamictrees:leaves0:12)
Block(-1,0,-2,dynamictrees:jungleroot)
Block(-1,0,-1,dynamictrees:jungleroot:1)
Block(-1,0,0,GRASS:0)
Block(-1,0,1,GRASS:0)
Block(-1,0,2,GRASS:0)
Block(-1,1,0,dynamictrees:jungleroot:2)
Block(-1,1,1,dynamictrees:trunkshell:6)
Block(-1,1,2,dynamictrees:trunkshell:7)
Block(-1,2,0,dynamictrees:trunkshell:5)
Block(-1,2,1,dynamictrees:trunkshell:6)
Block(-1,2,2,dynamictrees:trunkshell:7)
Block(-1,3,0,dynamictrees:trunkshell:5)
Block(-1,3,1,dynamictrees:trunkshell:6)
Block(-1,3,2,dynamictrees:trunkshell:7)
Block(-1,4,0,dynamictrees:trunkshell:5)
Block(-1,4,1,dynamictrees:trunkshell:6)
Block(-1,4,2,dynamictrees:trunkshell:7)
Block(-1,5,0,dynamictrees:trunkshell:5)
Block(-1,5,1,dynamictrees:trunkshell:6)
Block(-1,5,2,dynamictrees:trunkshell:7)
Block(-1,6,0,dynamictrees:trunkshell:5)
Block(-1,6,1,dynamictrees:trunkshell:6)
Block(-1,6,2,dynamictrees:trunkshell:7)
Block(-1,7,0,dynamictrees:trunkshell:5)
Block(-1,7,1,dynamictrees:trunkshell:6)
Block(-1,7,2,dynamictrees:trunkshell:7)
Block(-1,8,0,dynamictrees:trunkshell:5)
Block(-1,8,1,dynamictrees:trunkshell:6)
Block(-1,8,2,dynamictrees:trunkshell:7)
Block(-1,9,0,dynamictrees:trunkshell:5)
Block(-1,9,1,dynamictrees:trunkshell:6)
Block(-1,9,2,dynamictrees:trunkshell:7)
Block(-1,10,0,dynamictrees:trunkshell:5)
Block(-1,10,1,dynamictrees:trunkshell:6)
Block(-1,10,2,dynamictrees:trunkshell:7)
Block(-1,27,-3,dynamictrees:leaves0:12)
Block(-1,27,-2,dynamictrees:leaves0:15)
Block(-1,27,-1,dynamictrees:junglebranch)
Block(-1,27,1,dynamictrees:junglebranch:1)
Block(-1,27,3,dynamictrees:junglebranch)
Block(-1,28,-3,dynamictrees:leaves0:12)
Block(-1,28,-2,dynamictrees:leaves0:14)
Block(-1,28,-1,dynamictrees:leaves0:15)
Block(-1,28,3,dynamictrees:leaves0:15)
Block(-1,28,4,dynamictrees:leaves0:14)
Block(-1,28,5,dynamictrees:leaves0:12)
Block(-1,29,-3,dynamictrees:leaves0:12)
Block(-1,29,-2,dynamictrees:leaves0:13)
Block(-1,29,-1,dynamictrees:leaves0:14)
Block(-1,29,1,dynamictrees:junglebranch)
Block(-1,29,3,dynamictrees:leaves0:14)
Block(-1,29,4,dynamictrees:leaves0:13)
Block(-1,29,5,dynamictrees:leaves0:12)
Block(-1,30,-2,dynamictrees:leaves0:12)
Block(-1,30,-1,dynamictrees:leaves0:12)
Block(-1,30,0,dynamictrees:leaves0:12)
Block(-1,30,1,dynamictrees:leaves0:15)
Block(-1,30,2,dynamictrees:leaves0:15)
Block(-1,30,3,dynamictrees:leaves0:14)
Block(-1,30,4,dynamictrees:leaves0:12)
Block(-1,31,-1,dynamictrees:leaves0:12)
Block(-1,31,0,dynamictrees:leaves0:14)
Block(-1,31,1,dynamictrees:leaves0:15)
Block(-1,31,2,dynamictrees:leaves0:14)
Block(-1,31,3,dynamictrees:leaves0:13)
Block(-1,31,4,dynamictrees:leaves0:12)
Block(-1,32,-1,dynamictrees:leaves0:12)
Block(-1,32,0,dynamictrees:leaves0:13)
Block(-1,32,1,dynamictrees:leaves0:14)
Block(-1,32,2,dynamictrees:leaves0:13)
Block(-1,32,3,dynamictrees:leaves0:12)
Block(-1,33,0,dynamictrees:leaves0:12)
Block(-1,33,1,dynamictrees:leaves0:12)
Block(-1,33,2,dynamictrees:leaves0:12)
Block(0,0,0,GRASS:0)
Block(0,0,1,dynamictrees:rootydirtspecies:0,DT_Jungle_THuge_37/1-species_tile_entity.nbt)
Block(0,0,2,GRASS:0)
Block(0,1,0,dynamictrees:jungleroot:3)
Block(0,1,1,dynamictrees:junglebranch:11)
Block(0,1,2,dynamictrees:jungleroot:3)
Block(0,2,0,dynamictrees:trunkshell)
Block(0,2,1,dynamictrees:junglebranch:10)
Block(0,2,2,dynamictrees:trunkshell:0)
Block(0,3,0,dynamictrees:trunkshell)
Block(0,3,1,dynamictrees:junglebranch:9)
Block(0,3,2,dynamictrees:trunkshell:0)
Block(0,4,0,dynamictrees:trunkshell)
Block(0,4,1,dynamictrees:junglebranch:9)
Block(0,4,2,dynamictrees:trunkshell:0)
Block(0,5,0,dynamictrees:trunkshell)
Block(0,5,1,dynamictrees:junglebranch:9)
Block(0,5,2,dynamictrees:trunkshell:0)
Block(0,6,0,dynamictrees:trunkshell)
Block(0,6,1,dynamictrees:junglebranch:9)
Block(0,6,2,dynamictrees:trunkshell:0)
Block(0,7,0,dynamictrees:trunkshell)
Block(0,7,1,dynamictrees:junglebranch:8)
Block(0,7,2,dynamictrees:trunkshell:0)
Block(0,8,0,dynamictrees:trunkshell)
Block(0,8,1,dynamictrees:junglebranch:8)
Block(0,8,2,dynamictrees:trunkshell:0)
Block(0,9,0,dynamictrees:trunkshell)
Block(0,9,1,dynamictrees:junglebranch:8)
Block(0,9,2,dynamictrees:trunkshell:0)
Block(0,10,0,dynamictrees:trunkshell)
Block(0,10,1,dynamictrees:junglebranch:8)
Block(0,10,2,dynamictrees:trunkshell:0)
Block(0,11,1,dynamictrees:junglebranch:7)
Block(0,12,1,dynamictrees:junglebranch:7)
Block(0,13,1,dynamictrees:junglebranch:7)
Block(0,14,1,dynamictrees:junglebranch:7)
Block(0,15,1,dynamictrees:junglebranch:6)
Block(0,16,1,dynamictrees:junglebranch:6)
Block(0,17,1,dynamictrees:junglebranch:6)
Block(0,18,1,dynamictrees:junglebranch:6)
Block(0,19,1,dynamictrees:junglebranch:5)
Block(0,20,1,dynamictrees:junglebranch:5)
Block(0,21,1,dynamictrees:junglebranch:5)
Block(0,22,1,dynamictrees:junglebranch:5)
Block(0,23,1,dynamictrees:junglebranch:4)
Block(0,24,1,dynamictrees:junglebranch:4)
Block(0,25,1,dynamictrees:junglebranch:4)
Block(0,26,1,dynamictrees:junglebranch:4)
Block(0,27,-3,dynamictrees:leaves0:12)
Block(0,27,-2,dynamictrees:leaves0:14)
Block(0,27,-1,dynamictrees:junglebranch:1)
Block(0,27,0,dynamictrees:junglebranch:1)
Block(0,27,1,dynamictrees:junglebranch:3)
Block(0,27,2,dynamictrees:junglebranch:1)
Block(0,27,3,dynamictrees:junglebranch:1)
Block(0,28,-3,dynamictrees:leaves0:12)
Block(0,28,-2,dynamictrees:leaves0:15)
Block(0,28,-1,dynamictrees:junglebranch)
Block(0,28,1,dynamictrees:junglebranch:1)
Block(0,28,3,dynamictrees:junglebranch)
Block(0,28,4,dynamictrees:leaves0:15)
Block(0,28,5,dynamictrees:leaves0:12)
Block(0,29,-3,dynamictrees:leaves0:12)
Block(0,29,-2,dynamictrees:leaves0:14)
Block(0,29,-1,dynamictrees:leaves0:15)
Block(0,29,1,dynamictrees:junglebranch:1)
Block(0,29,3,dynamictrees:leaves0:15)
Block(0,29,4,dynamictrees:leaves0:14)
Block(0,29,5,dynamictrees:leaves0:12)
Block(0,30,-2,dynamictrees:leaves0:12)
Block(0,30,-1,dynamictrees:leaves0:12)
Block(0,30,0,dynamictrees:leaves0:12)
Block(0,30,1,dynamictrees:junglebranch:1)
Block(0,30,2,dynamictrees:junglebranch)
Block(0,30,3,dynamictrees:leaves0:15)
Block(0,30,4,dynamictrees:leaves0:12)
Block(0,31,-1,dynamictrees:leaves0:12)
Block(0,31,0,dynamictrees:leaves0:15)
Block(0,31,1,dynamictrees:junglebranch)
Block(0,31,2,dynamictrees:leaves0:15)
Block(0,31,3,dynamictrees:leaves0:14)
Block(0,31,4,dynamictrees:leaves0:12)
Block(0,32,-1,dynamictrees:leaves0:12)
Block(0,32,0,dynamictrees:leaves0:14)
Block(0,32,1,dynamictrees:leaves0:15)
Block(0,32,2,dynamictrees:leaves0:14)
Block(0,32,3,dynamictrees:leaves0:13)
Block(0,32,4,dynamictrees:leaves0:12)
Block(0,33,0,dynamictrees:leaves0:12)
Block(0,33,1,dynamictrees:leaves0:12)
Block(0,33,2,dynamictrees:leaves0:12)
Block(0,33,3,dynamictrees:leaves0:12)
Block(1,0,0,GRASS:0)
Block(1,0,1,GRASS:0)
Block(1,0,2,GRASS:0)
Block(1,0,3,dynamictrees:jungleroot:1)
Block(1,0,4,dynamictrees:jungleroot)
Block(1,1,0,dynamictrees:trunkshell:3)
Block(1,1,1,dynamictrees:trunkshell:2)
Block(1,1,2,dynamictrees:jungleroot:2)
Block(1,2,0,dynamictrees:trunkshell:3)
Block(1,2,1,dynamictrees:trunkshell:2)
Block(1,2,2,dynamictrees:trunkshell:1)
Block(1,3,0,dynamictrees:trunkshell:3)
Block(1,3,1,dynamictrees:trunkshell:2)
Block(1,3,2,dynamictrees:trunkshell:1)
Block(1,4,0,dynamictrees:trunkshell:3)
Block(1,4,1,dynamictrees:trunkshell:2)
Block(1,4,2,dynamictrees:trunkshell:1)
Block(1,5,0,dynamictrees:trunkshell:3)
Block(1,5,1,dynamictrees:trunkshell:2)
Block(1,5,2,dynamictrees:trunkshell:1)
Block(1,6,0,dynamictrees:trunkshell:3)
Block(1,6,1,dynamictrees:trunkshell:2)
Block(1,6,2,dynamictrees:trunkshell:1)
Block(1,7,0,dynamictrees:trunkshell:3)
Block(1,7,1,dynamictrees:trunkshell:2)
Block(1,7,2,dynamictrees:trunkshell:1)
Block(1,8,0,dynamictrees:trunkshell:3)
Block(1,8,1,dynamictrees:trunkshell:2)
Block(1,8,2,dynamictrees:trunkshell:1)
Block(1,9,0,dynamictrees:trunkshell:3)
Block(1,9,1,dynamictrees:trunkshell:2)
Block(1,9,2,dynamictrees:trunkshell:1)
Block(1,10,0,dynamictrees:trunkshell:3)
Block(1,10,1,dynamictrees:trunkshell:2)
Block(1,10,2,dynamictrees:trunkshell:1)
Block(1,27,-3,dynamictrees:leaves0:12)
Block(1,27,-2,dynamictrees:leaves0:15)
Block(1,27,-1,dynamictrees:junglebranch)
Block(1,27,1,dynamictrees:junglebranch:1)
Block(1,27,3,dynamictrees:junglebranch)
Block(1,28,-3,dynamictrees:leaves0:12)
Block(1,28,-2,dynamictrees:leaves0:14)
Block(1,28,-1,dynamictrees:leaves0:15)
Block(1,28,2,dynamictrees:leaves0:12)
Block(1,28,3,dynamictrees:leaves0:15)
Block(1,28,4,dynamictrees:leaves0:14)
Block(1,28,5,dynamictrees:leaves0:12)
Block(1,29,-3,dynamictrees:leaves0:12)
Block(1,29,-2,dynamictrees:leaves0:13)
Block(1,29,-1,dynamictrees:leaves0:14)
Block(1,29,3,dynamictrees:leaves0:14)
Block(1,29,4,dynamictrees:leaves0:13)
Block(1,29,5,dynamictrees:leaves0:12)
Block(1,30,-2,dynamictrees:leaves0:12)
Block(1,30,-1,dynamictrees:leaves0:12)
Block(1,30,0,dynamictrees:leaves0:13)
Block(1,30,1,dynamictrees:leaves0:14)
Block(1,30,2,dynamictrees:leaves0:15)
Block(1,30,3,dynamictrees:leaves0:14)
Block(1,30,4,dynamictrees:leaves0:12)
Block(1,31,-1,dynamictrees:leaves0:12)
Block(1,31,0,dynamictrees:leaves0:14)
Block(1,31,1,dynamictrees:leaves0:15)
Block(1,31,2,dynamictrees:leaves0:14)
Block(1,31,3,dynamictrees:leaves0:13)
Block(1,31,4,dynamictrees:leaves0:12)
Block(1,32,-1,dynamictrees:leaves0:12)
Block(1,32,0,dynamictrees:leaves0:13)
Block(1,32,1,dynamictrees:leaves0:14)
Block(1,32,2,dynamictrees:leaves0:13)
Block(1,32,3,dynamictrees:leaves0:12)
Block(1,33,0,dynamictrees:leaves0:12)
Block(1,33,1,dynamictrees:leaves0:12)
Block(1,33,2,dynamictrees:leaves0:12)
Block(2,26,-2,dynamictrees:leaves0:12)
Block(2,26,-1,dynamictrees:leaves0:12)
Block(2,27,-3,dynamictrees:leaves0:12)
Block(2,27,-2,dynamictrees:leaves0:14)
Block(2,27,-1,dynamictrees:leaves0:15)
Block(2,27,0,dynamictrees:junglebranch)
Block(2,27,1,dynamictrees:junglebranch:1)
Block(2,28,-3,dynamictrees:leaves0:12)
Block(2,28,-2,dynamictrees:leaves0:13)
Block(2,28,-1,dynamictrees:leaves0:14)
Block(2,28,0,dynamictrees:leaves0:15)
Block(2,28,1,dynamictrees:junglebranch)
Block(2,28,3,dynamictrees:leaves0:12)
Block(2,28,4,dynamictrees:leaves0:12)
Block(2,29,-2,dynamictrees:leaves0:12)
Block(2,29,-1,dynamictrees:leaves0:13)
Block(2,29,0,dynamictrees:leaves0:14)
Block(2,29,1,dynamictrees:leaves0:15)
Block(2,29,2,dynamictrees:leaves0:12)
Block(2,29,3,dynamictrees:leaves0:12)
Block(2,29,4,dynamictrees:leaves0:12)
Block(2,30,-1,dynamictrees:leaves0:12)
Block(2,30,0,dynamictrees:leaves0:12)
Block(2,30,1,dynamictrees:leaves0:12)
Block(2,30,2,dynamictrees:leaves0:12)
Block(2,30,3,dynamictrees:leaves0:12)
Block(2,31,0,dynamictrees:leaves0:12)
Block(2,31,1,dynamictrees:leaves0:12)
Block(2,31,2,dynamictrees:leaves0:12)
Block(2,31,3,dynamictrees:leaves0:12)
Block(2,32,0,dynamictrees:leaves0:12)
Block(2,32,1,dynamictrees:leaves0:12)
Block(2,32,2,dynamictrees:leaves0:12)
Block(3,26,-2,dynamictrees:leaves0:12)
Block(3,26,-1,dynamictrees:leaves0:12)
Block(3,27,-3,dynamictrees:leaves0:12)
Block(3,27,-2,dynamictrees:leaves0:13)
Block(3,27,-1,dynamictrees:leaves0:14)
Block(3,27,0,dynamictrees:leaves0:15)
Block(3,27,1,dynamictrees:leaves0:14)
Block(3,27,2,dynamictrees:leaves0:12)
Block(3,28,-2,dynamictrees:leaves0:12)
Block(3,28,-1,dynamictrees:leaves0:13)
Block(3,28,0,dynamictrees:leaves0:14)
Block(3,28,1,dynamictrees:leaves0:15)
Block(3,28,2,dynamictrees:leaves0:12)
Block(3,29,-1,dynamictrees:leaves0:12)
Block(3,29,0,dynamictrees:leaves0:13)
Block(3,29,1,dynamictrees:leaves0:14)
Block(3,29,2,dynamictrees:leaves0:12)
Block(3,30,0,dynamictrees:leaves0:12)
Block(3,30,1,dynamictrees:leaves0:12)
Block(4,27,-2,dynamictrees:leaves0:12)
Block(4,27,-1,dynamictrees:leaves0:12)
Block(4,27,0,dynamictrees:leaves0:12)
Block(4,27,1,dynamictrees:leaves0:12)
Block(4,27,2,dynamictrees:leaves0:12)
Block(4,28,-1,dynamictrees:leaves0:12)
Block(4,28,0,dynamictrees:leaves0:12)
Block(4,28,1,dynamictrees:leaves0:12)
Block(4,29,0,dynamictrees:leaves0:12)
Block(4,29,1,dynamictrees:leaves0:12)

#######################################################################
# +-----------------------------------------------------------------+ #
# |                            BO3 checks                           | #
# +-----------------------------------------------------------------+ #
#######################################################################

BlockCheck(0,-1,1,GRASS,DIRT,biomesoplenty:grass,biomesoplenty:dirt)

#######################################################################
# +-----------------------------------------------------------------+ #
# |                             Branches                            | #
# +-----------------------------------------------------------------+ #
#######################################################################


#######################################################################
# +-----------------------------------------------------------------+ #
# |                             Entities                            | #
# +-----------------------------------------------------------------+ #
#######################################################################


#######################################################################
# +-----------------------------------------------------------------+ #
# |                            Particles                            | #
# +-----------------------------------------------------------------+ #
#######################################################################


#######################################################################
# +-----------------------------------------------------------------+ #
# |                             Spawners                            | #
# +-----------------------------------------------------------------+ #
#######################################################################


#######################################################################
# +-----------------------------------------------------------------+ #
# |                             ModData                             | #
# +-----------------------------------------------------------------+ #
#######################################################################

