
#######################################################################
# +-----------------------------------------------------------------+ #
# |                            BO3 object                           | #
# +-----------------------------------------------------------------+ #
#######################################################################

Author: NLBlackHeavenNL

Description: No description given

Version: 3

SettingsMode: WriteWithoutComments


#######################################################################
# +-----------------------------------------------------------------+ #
# |                          Main settings                          | #
# +-----------------------------------------------------------------+ #
#######################################################################

Tree: true

Frequency: 1

Rarity: 100.0

RotateRandomly: false

SpawnHeight: highestSolidBlock

SpawnHeightOffset: -1

SpawnHeightVariance: 0

##############################
# Height Limits for the BO3. #
##############################

MinHeight: 0

MaxHeight: 255

######################
# Extrusion settings #
######################

ExtrudeMode: None

ExtrudeThroughBlocks: AIR

MaxBranchDepth: 10

ExcludedBiomes: All


#######################################################################
# +-----------------------------------------------------------------+ #
# |                      Source block settings                      | #
# +-----------------------------------------------------------------+ #
#######################################################################

SourceBlocks: AIR,GRASS,DIRT,biomesoplenty:dirt

MaxPercentageOutsideSourceBlock: 0

OutsideSourceBlock: placeAnyway

DoReplaceBlocks: true

IsOTGPlus: false


#######################################################################
# +-----------------------------------------------------------------+ #
# |                              Blocks                             | #
# +-----------------------------------------------------------------+ #
#######################################################################

Block(-7,27,0,dynamictrees:leaves0:12)
Block(-7,27,2,dynamictrees:leaves0:12)
Block(-7,28,-1,dynamictrees:leaves0:12)
Block(-7,28,0,dynamictrees:leaves0:12)
Block(-7,28,1,dynamictrees:leaves0:12)
Block(-7,28,2,dynamictrees:leaves0:12)
Block(-7,28,3,dynamictrees:leaves0:12)
Block(-7,29,0,dynamictrees:leaves0:12)
Block(-7,29,1,dynamictrees:leaves0:12)
Block(-7,29,2,dynamictrees:leaves0:12)
Block(-7,30,1,dynamictrees:leaves0:12)
Block(-6,27,-1,dynamictrees:leaves0:12)
Block(-6,27,0,dynamictrees:leaves0:13)
Block(-6,27,2,dynamictrees:leaves0:13)
Block(-6,27,3,dynamictrees:leaves0:12)
Block(-6,28,-2,dynamictrees:leaves0:12)
Block(-6,28,-1,dynamictrees:leaves0:13)
Block(-6,28,0,dynamictrees:leaves0:14)
Block(-6,28,1,dynamictrees:leaves0:15)
Block(-6,28,2,dynamictrees:leaves0:14)
Block(-6,28,3,dynamictrees:leaves0:13)
Block(-6,28,4,dynamictrees:leaves0:12)
Block(-6,29,-1,dynamictrees:leaves0:12)
Block(-6,29,0,dynamictrees:leaves0:13)
Block(-6,29,1,dynamictrees:leaves0:14)
Block(-6,29,2,dynamictrees:leaves0:13)
Block(-6,29,3,dynamictrees:leaves0:12)
Block(-6,30,0,dynamictrees:leaves0:12)
Block(-6,30,1,dynamictrees:leaves0:13)
Block(-6,30,2,dynamictrees:leaves0:12)
Block(-6,31,1,dynamictrees:leaves0:12)
Block(-5,25,1,dynamictrees:junglebranch)
Block(-5,26,0,dynamictrees:leaves0:14)
Block(-5,26,1,dynamictrees:leaves0:15)
Block(-5,27,-2,dynamictrees:leaves0:12)
Block(-5,27,-1,dynamictrees:leaves0:13)
Block(-5,27,0,dynamictrees:leaves0:14)
Block(-5,27,1,dynamictrees:leaves0:15)
Block(-5,27,3,dynamictrees:leaves0:12)
Block(-5,27,4,dynamictrees:leaves0:12)
Block(-5,28,-2,dynamictrees:leaves0:12)
Block(-5,28,-1,dynamictrees:leaves0:14)
Block(-5,28,0,dynamictrees:leaves0:15)
Block(-5,28,1,dynamictrees:junglebranch)
Block(-5,28,2,dynamictrees:leaves0:15)
Block(-5,28,3,dynamictrees:leaves0:14)
Block(-5,28,4,dynamictrees:leaves0:13)
Block(-5,28,5,dynamictrees:leaves0:12)
Block(-5,29,-2,dynamictrees:leaves0:12)
Block(-5,29,-1,dynamictrees:leaves0:13)
Block(-5,29,0,dynamictrees:leaves0:14)
Block(-5,29,1,dynamictrees:leaves0:15)
Block(-5,29,2,dynamictrees:leaves0:14)
Block(-5,29,3,dynamictrees:leaves0:13)
Block(-5,29,4,dynamictrees:leaves0:12)
Block(-5,30,-1,dynamictrees:leaves0:12)
Block(-5,30,0,dynamictrees:leaves0:13)
Block(-5,30,1,dynamictrees:leaves0:14)
Block(-5,30,2,dynamictrees:leaves0:13)
Block(-5,30,3,dynamictrees:leaves0:12)
Block(-5,31,0,dynamictrees:leaves0:12)
Block(-5,31,1,dynamictrees:leaves0:12)
Block(-5,31,2,dynamictrees:leaves0:12)
Block(-4,25,0,dynamictrees:junglebranch)
Block(-4,25,1,dynamictrees:junglebranch:1)
Block(-4,26,-1,dynamictrees:leaves0:12)
Block(-4,26,0,dynamictrees:leaves0:15)
Block(-4,27,-2,dynamictrees:leaves0:12)
Block(-4,27,-1,dynamictrees:leaves0:14)
Block(-4,27,0,dynamictrees:leaves0:15)
Block(-4,27,4,dynamictrees:leaves0:12)
Block(-4,28,-2,dynamictrees:leaves0:12)
Block(-4,28,-1,dynamictrees:leaves0:15)
Block(-4,28,0,dynamictrees:junglebranch)
Block(-4,28,1,dynamictrees:junglebranch:1)
Block(-4,28,2,dynamictrees:leaves0:14)
Block(-4,28,3,dynamictrees:leaves0:15)
Block(-4,28,4,dynamictrees:leaves0:14)
Block(-4,28,5,dynamictrees:leaves0:12)
Block(-4,29,-2,dynamictrees:leaves0:12)
Block(-4,29,-1,dynamictrees:leaves0:14)
Block(-4,29,0,dynamictrees:leaves0:15)
Block(-4,29,1,dynamictrees:junglebranch)
Block(-4,29,2,dynamictrees:leaves0:15)
Block(-4,29,3,dynamictrees:leaves0:14)
Block(-4,29,4,dynamictrees:leaves0:13)
Block(-4,29,5,dynamictrees:leaves0:12)
Block(-4,30,-2,dynamictrees:leaves0:12)
Block(-4,30,-1,dynamictrees:leaves0:13)
Block(-4,30,0,dynamictrees:leaves0:14)
Block(-4,30,1,dynamictrees:leaves0:15)
Block(-4,30,2,dynamictrees:leaves0:14)
Block(-4,30,3,dynamictrees:leaves0:13)
Block(-4,30,4,dynamictrees:leaves0:12)
Block(-4,31,-1,dynamictrees:leaves0:12)
Block(-4,31,0,dynamictrees:leaves0:13)
Block(-4,31,1,dynamictrees:leaves0:12)
Block(-4,31,2,dynamictrees:leaves0:12)
Block(-4,31,3,dynamictrees:leaves0:12)
Block(-4,32,0,dynamictrees:leaves0:12)
Block(-3,25,1,dynamictrees:junglebranch:1)
Block(-3,27,4,dynamictrees:leaves0:12)
Block(-3,28,1,dynamictrees:junglebranch:2)
Block(-3,28,2,dynamictrees:junglebranch:1)
Block(-3,28,3,dynamictrees:junglebranch)
Block(-3,28,4,dynamictrees:leaves0:15)
Block(-3,28,5,dynamictrees:leaves0:12)
Block(-3,28,6,dynamictrees:leaves0:12)
Block(-3,29,-2,dynamictrees:leaves0:12)
Block(-3,29,-1,dynamictrees:leaves0:15)
Block(-3,29,0,dynamictrees:junglebranch)
Block(-3,29,1,dynamictrees:leaves0:15)
Block(-3,29,2,dynamictrees:leaves0:15)
Block(-3,29,3,dynamictrees:leaves0:15)
Block(-3,29,4,dynamictrees:leaves0:14)
Block(-3,29,5,dynamictrees:leaves0:12)
Block(-3,29,6,dynamictrees:leaves0:12)
Block(-3,29,7,dynamictrees:leaves0:12)
Block(-3,30,-3,dynamictrees:leaves0:12)
Block(-3,30,-2,dynamictrees:leaves0:13)
Block(-3,30,-1,dynamictrees:leaves0:14)
Block(-3,30,0,dynamictrees:leaves0:15)
Block(-3,30,1,dynamictrees:leaves0:14)
Block(-3,30,2,dynamictrees:leaves0:14)
Block(-3,30,3,dynamictrees:leaves0:13)
Block(-3,30,4,dynamictrees:leaves0:12)
Block(-3,30,5,dynamictrees:leaves0:12)
Block(-3,30,6,dynamictrees:leaves0:12)
Block(-3,31,-2,dynamictrees:leaves0:12)
Block(-3,31,-1,dynamictrees:leaves0:13)
Block(-3,31,0,dynamictrees:leaves0:14)
Block(-3,31,1,dynamictrees:leaves0:13)
Block(-3,31,2,dynamictrees:leaves0:13)
Block(-3,31,3,dynamictrees:leaves0:12)
Block(-3,32,-1,dynamictrees:leaves0:12)
Block(-3,32,0,dynamictrees:leaves0:13)
Block(-3,32,1,dynamictrees:leaves0:12)
Block(-3,32,2,dynamictrees:leaves0:12)
Block(-3,33,0,dynamictrees:leaves0:12)
Block(-2,0,-2,dynamictrees:jungleroot:1)
Block(-2,25,1,dynamictrees:junglebranch:2)
Block(-2,25,2,dynamictrees:junglebranch:1)
Block(-2,25,3,dynamictrees:junglebranch:1)
Block(-2,25,4,dynamictrees:junglebranch)
Block(-2,26,3,dynamictrees:leaves0:12)
Block(-2,26,4,dynamictrees:leaves0:15)
Block(-2,26,5,dynamictrees:leaves0:12)
Block(-2,27,4,dynamictrees:leaves0:12)
Block(-2,27,5,dynamictrees:leaves0:12)
Block(-2,28,1,dynamictrees:junglebranch:3)
Block(-2,28,4,dynamictrees:leaves0:13)
Block(-2,28,5,dynamictrees:leaves0:14)
Block(-2,28,6,dynamictrees:leaves0:13)
Block(-2,28,7,dynamictrees:leaves0:12)
Block(-2,29,-4,dynamictrees:leaves0:12)
Block(-2,29,-3,dynamictrees:leaves0:12)
Block(-2,29,-2,dynamictrees:leaves0:12)
Block(-2,29,0,dynamictrees:junglebranch:1)
Block(-2,29,1,dynamictrees:junglebranch:1)
Block(-2,29,2,dynamictrees:junglebranch)
Block(-2,29,3,dynamictrees:leaves0:15)
Block(-2,29,4,dynamictrees:leaves0:14)
Block(-2,29,5,dynamictrees:leaves0:15)
Block(-2,29,6,dynamictrees:leaves0:14)
Block(-2,29,7,dynamictrees:leaves0:13)
Block(-2,29,8,dynamictrees:leaves0:12)
Block(-2,30,-4,dynamictrees:leaves0:12)
Block(-2,30,-3,dynamictrees:leaves0:13)
Block(-2,30,-2,dynamictrees:leaves0:14)
Block(-2,30,-1,dynamictrees:leaves0:15)
Block(-2,30,0,dynamictrees:junglebranch)
Block(-2,30,1,dynamictrees:leaves0:15)
Block(-2,30,2,dynamictrees:leaves0:15)
Block(-2,30,3,dynamictrees:leaves0:14)
Block(-2,30,4,dynamictrees:leaves0:13)
Block(-2,30,5,dynamictrees:leaves0:14)
Block(-2,30,6,dynamictrees:leaves0:13)
Block(-2,30,7,dynamictrees:leaves0:12)
Block(-2,31,-3,dynamictrees:leaves0:12)
Block(-2,31,-2,dynamictrees:leaves0:13)
Block(-2,31,-1,dynamictrees:leaves0:14)
Block(-2,31,0,dynamictrees:leaves0:15)
Block(-2,31,1,dynamictrees:leaves0:14)
Block(-2,31,2,dynamictrees:leaves0:14)
Block(-2,31,3,dynamictrees:leaves0:13)
Block(-2,31,4,dynamictrees:leaves0:12)
Block(-2,31,5,dynamictrees:leaves0:12)
Block(-2,31,6,dynamictrees:leaves0:12)
Block(-2,32,-2,dynamictrees:leaves0:12)
Block(-2,32,-1,dynamictrees:leaves0:13)
Block(-2,32,0,dynamictrees:leaves0:14)
Block(-2,32,1,dynamictrees:leaves0:13)
Block(-2,32,2,dynamictrees:leaves0:13)
Block(-2,32,3,dynamictrees:leaves0:12)
Block(-2,33,-1,dynamictrees:leaves0:12)
Block(-2,33,0,dynamictrees:leaves0:12)
Block(-2,33,1,dynamictrees:leaves0:12)
Block(-2,33,2,dynamictrees:leaves0:12)
Block(-1,0,-2,dynamictrees:jungleroot:2)
Block(-1,0,-1,dynamictrees:jungleroot:3)
Block(-1,0,0,GRASS:0)
Block(-1,0,1,GRASS:0)
Block(-1,0,2,GRASS:0)
Block(-1,1,0,dynamictrees:jungleroot:4)
Block(-1,1,1,dynamictrees:trunkshell:6)
Block(-1,1,2,dynamictrees:trunkshell:7)
Block(-1,2,0,dynamictrees:trunkshell:5)
Block(-1,2,1,dynamictrees:trunkshell:6)
Block(-1,2,2,dynamictrees:trunkshell:7)
Block(-1,3,0,dynamictrees:trunkshell:5)
Block(-1,3,1,dynamictrees:trunkshell:6)
Block(-1,3,2,dynamictrees:trunkshell:7)
Block(-1,4,0,dynamictrees:trunkshell:5)
Block(-1,4,1,dynamictrees:trunkshell:6)
Block(-1,4,2,dynamictrees:trunkshell:7)
Block(-1,5,0,dynamictrees:trunkshell:5)
Block(-1,5,1,dynamictrees:trunkshell:6)
Block(-1,5,2,dynamictrees:trunkshell:7)
Block(-1,6,0,dynamictrees:trunkshell:5)
Block(-1,6,1,dynamictrees:trunkshell:6)
Block(-1,6,2,dynamictrees:trunkshell:7)
Block(-1,7,0,dynamictrees:trunkshell:5)
Block(-1,7,1,dynamictrees:trunkshell:6)
Block(-1,7,2,dynamictrees:trunkshell:7)
Block(-1,8,0,dynamictrees:trunkshell:5)
Block(-1,8,1,dynamictrees:trunkshell:6)
Block(-1,8,2,dynamictrees:trunkshell:7)
Block(-1,9,0,dynamictrees:trunkshell:5)
Block(-1,9,1,dynamictrees:trunkshell:6)
Block(-1,9,2,dynamictrees:trunkshell:7)
Block(-1,10,0,dynamictrees:trunkshell:5)
Block(-1,10,1,dynamictrees:trunkshell:6)
Block(-1,10,2,dynamictrees:trunkshell:7)
Block(-1,11,0,dynamictrees:trunkshell:5)
Block(-1,11,1,dynamictrees:trunkshell:6)
Block(-1,11,2,dynamictrees:trunkshell:7)
Block(-1,12,0,dynamictrees:trunkshell:5)
Block(-1,12,1,dynamictrees:trunkshell:6)
Block(-1,12,2,dynamictrees:trunkshell:7)
Block(-1,13,0,dynamictrees:trunkshell:5)
Block(-1,13,1,dynamictrees:trunkshell:6)
Block(-1,13,2,dynamictrees:trunkshell:7)
Block(-1,14,0,dynamictrees:trunkshell:5)
Block(-1,14,1,dynamictrees:trunkshell:6)
Block(-1,14,2,dynamictrees:trunkshell:7)
Block(-1,15,0,dynamictrees:trunkshell:5)
Block(-1,15,1,dynamictrees:trunkshell:6)
Block(-1,15,2,dynamictrees:trunkshell:7)
Block(-1,16,0,dynamictrees:trunkshell:5)
Block(-1,16,1,dynamictrees:trunkshell:6)
Block(-1,16,2,dynamictrees:trunkshell:7)
Block(-1,17,0,dynamictrees:trunkshell:5)
Block(-1,17,1,dynamictrees:trunkshell:6)
Block(-1,17,2,dynamictrees:trunkshell:7)
Block(-1,18,0,dynamictrees:trunkshell:5)
Block(-1,18,1,dynamictrees:trunkshell:6)
Block(-1,18,2,dynamictrees:trunkshell:7)
Block(-1,19,0,dynamictrees:trunkshell:5)
Block(-1,19,1,dynamictrees:trunkshell:6)
Block(-1,19,2,dynamictrees:trunkshell:7)
Block(-1,20,0,dynamictrees:trunkshell:5)
Block(-1,20,1,dynamictrees:trunkshell:6)
Block(-1,20,2,dynamictrees:trunkshell:7)
Block(-1,21,0,dynamictrees:trunkshell:5)
Block(-1,21,1,dynamictrees:trunkshell:6)
Block(-1,21,2,dynamictrees:trunkshell:7)
Block(-1,22,0,dynamictrees:trunkshell:5)
Block(-1,22,1,dynamictrees:trunkshell:6)
Block(-1,22,2,dynamictrees:trunkshell:7)
Block(-1,23,0,dynamictrees:trunkshell:5)
Block(-1,23,1,dynamictrees:trunkshell:6)
Block(-1,23,2,dynamictrees:trunkshell:7)
Block(-1,24,0,dynamictrees:trunkshell:5)
Block(-1,24,1,dynamictrees:trunkshell:6)
Block(-1,24,2,dynamictrees:trunkshell:7)
Block(-1,25,0,dynamictrees:trunkshell:5)
Block(-1,25,1,dynamictrees:junglebranch:2)
Block(-1,25,2,dynamictrees:trunkshell:7)
Block(-1,26,0,dynamictrees:trunkshell:5)
Block(-1,26,1,dynamictrees:trunkshell:6)
Block(-1,26,2,dynamictrees:trunkshell:7)
Block(-1,26,4,dynamictrees:leaves0:12)
Block(-1,27,0,dynamictrees:trunkshell:5)
Block(-1,27,1,dynamictrees:trunkshell:6)
Block(-1,27,2,dynamictrees:trunkshell:7)
Block(-1,28,-4,dynamictrees:leaves0:12)
Block(-1,28,0,dynamictrees:trunkshell:5)
Block(-1,28,1,dynamictrees:junglebranch:3)
Block(-1,28,2,dynamictrees:trunkshell:7)
Block(-1,28,5,dynamictrees:leaves0:15)
Block(-1,28,6,dynamictrees:leaves0:14)
Block(-1,28,7,dynamictrees:leaves0:13)
Block(-1,28,8,dynamictrees:leaves0:12)
Block(-1,29,-5,dynamictrees:leaves0:12)
Block(-1,29,-4,dynamictrees:leaves0:14)
Block(-1,29,-3,dynamictrees:leaves0:15)
Block(-1,29,-1,dynamictrees:junglebranch:1)
Block(-1,29,3,dynamictrees:junglebranch)
Block(-1,29,4,dynamictrees:leaves0:15)
Block(-1,29,5,dynamictrees:junglebranch)
Block(-1,29,6,dynamictrees:leaves0:15)
Block(-1,29,7,dynamictrees:leaves0:14)
Block(-1,29,8,dynamictrees:leaves0:12)
Block(-1,30,-5,dynamictrees:leaves0:12)
Block(-1,30,-4,dynamictrees:leaves0:13)
Block(-1,30,-3,dynamictrees:leaves0:14)
Block(-1,30,-2,dynamictrees:leaves0:15)
Block(-1,30,-1,dynamictrees:junglebranch)
Block(-1,30,0,dynamictrees:leaves0:15)
Block(-1,30,1,dynamictrees:junglebranch:1)
Block(-1,30,2,dynamictrees:junglebranch)
Block(-1,30,3,dynamictrees:leaves0:15)
Block(-1,30,4,dynamictrees:leaves0:14)
Block(-1,30,5,dynamictrees:leaves0:15)
Block(-1,30,6,dynamictrees:leaves0:14)
Block(-1,30,7,dynamictrees:leaves0:13)
Block(-1,30,8,dynamictrees:leaves0:12)
Block(-1,31,-4,dynamictrees:leaves0:12)
Block(-1,31,-3,dynamictrees:leaves0:13)
Block(-1,31,-2,dynamictrees:leaves0:14)
Block(-1,31,-1,dynamictrees:leaves0:15)
Block(-1,31,0,dynamictrees:leaves0:14)
Block(-1,31,1,dynamictrees:leaves0:13)
Block(-1,31,2,dynamictrees:leaves0:15)
Block(-1,31,3,dynamictrees:leaves0:14)
Block(-1,31,4,dynamictrees:leaves0:13)
Block(-1,31,5,dynamictrees:leaves0:12)
Block(-1,31,6,dynamictrees:leaves0:12)
Block(-1,31,7,dynamictrees:leaves0:12)
Block(-1,32,-3,dynamictrees:leaves0:12)
Block(-1,32,-2,dynamictrees:leaves0:13)
Block(-1,32,-1,dynamictrees:leaves0:14)
Block(-1,32,0,dynamictrees:leaves0:15)
Block(-1,32,1,dynamictrees:leaves0:12)
Block(-1,32,2,dynamictrees:leaves0:14)
Block(-1,32,3,dynamictrees:leaves0:13)
Block(-1,32,4,dynamictrees:leaves0:12)
Block(-1,33,-2,dynamictrees:leaves0:12)
Block(-1,33,-1,dynamictrees:leaves0:12)
Block(-1,33,0,dynamictrees:leaves0:12)
Block(-1,33,1,dynamictrees:leaves0:12)
Block(-1,33,2,dynamictrees:leaves0:12)
Block(-1,33,3,dynamictrees:leaves0:12)
Block(0,0,0,GRASS:0)
Block(0,0,1,dynamictrees:rootydirtspecies:6,DT_Jungle_THuge_06/1-species_tile_entity.nbt)
Block(0,0,2,GRASS:0)
Block(0,0,4,dynamictrees:jungleroot:1)
Block(0,1,0,dynamictrees:jungleroot:5)
Block(0,1,1,dynamictrees:junglebranch:14)
Block(0,1,2,dynamictrees:jungleroot:5)
Block(0,2,0,dynamictrees:trunkshell)
Block(0,2,1,dynamictrees:junglebranch:13)
Block(0,2,2,dynamictrees:trunkshell:0)
Block(0,3,0,dynamictrees:trunkshell)
Block(0,3,1,dynamictrees:junglebranch:12)
Block(0,3,2,dynamictrees:trunkshell:0)
Block(0,4,0,dynamictrees:trunkshell)
Block(0,4,1,dynamictrees:junglebranch:12)
Block(0,4,2,dynamictrees:trunkshell:0)
Block(0,5,0,dynamictrees:trunkshell)
Block(0,5,1,dynamictrees:junglebranch:12)
Block(0,5,2,dynamictrees:trunkshell:0)
Block(0,6,0,dynamictrees:trunkshell)
Block(0,6,1,dynamictrees:junglebranch:12)
Block(0,6,2,dynamictrees:trunkshell:0)
Block(0,7,0,dynamictrees:trunkshell)
Block(0,7,1,dynamictrees:junglebranch:12)
Block(0,7,2,dynamictrees:trunkshell:0)
Block(0,8,0,dynamictrees:trunkshell)
Block(0,8,1,dynamictrees:junglebranch:12)
Block(0,8,2,dynamictrees:trunkshell:0)
Block(0,9,0,dynamictrees:trunkshell)
Block(0,9,1,dynamictrees:junglebranch:11)
Block(0,9,2,dynamictrees:trunkshell:0)
Block(0,10,0,dynamictrees:trunkshell)
Block(0,10,1,dynamictrees:junglebranch:11)
Block(0,10,2,dynamictrees:trunkshell:0)
Block(0,11,0,dynamictrees:trunkshell)
Block(0,11,1,dynamictrees:junglebranch:11)
Block(0,11,2,dynamictrees:trunkshell:0)
Block(0,12,0,dynamictrees:trunkshell)
Block(0,12,1,dynamictrees:junglebranch:11)
Block(0,12,2,dynamictrees:trunkshell:0)
Block(0,13,0,dynamictrees:trunkshell)
Block(0,13,1,dynamictrees:junglebranch:11)
Block(0,13,2,dynamictrees:trunkshell:0)
Block(0,14,0,dynamictrees:trunkshell)
Block(0,14,1,dynamictrees:junglebranch:10)
Block(0,14,2,dynamictrees:trunkshell:0)
Block(0,15,0,dynamictrees:trunkshell)
Block(0,15,1,dynamictrees:junglebranch:10)
Block(0,15,2,dynamictrees:trunkshell:0)
Block(0,16,0,dynamictrees:trunkshell)
Block(0,16,1,dynamictrees:junglebranch:10)
Block(0,16,2,dynamictrees:trunkshell:0)
Block(0,17,0,dynamictrees:trunkshell)
Block(0,17,1,dynamictrees:junglebranch:10)
Block(0,17,2,dynamictrees:trunkshell:0)
Block(0,18,0,dynamictrees:trunkshell)
Block(0,18,1,dynamictrees:junglebranch:10)
Block(0,18,2,dynamictrees:trunkshell:0)
Block(0,19,0,dynamictrees:trunkshell)
Block(0,19,1,dynamictrees:junglebranch:10)
Block(0,19,2,dynamictrees:trunkshell:0)
Block(0,20,0,dynamictrees:trunkshell)
Block(0,20,1,dynamictrees:junglebranch:9)
Block(0,20,2,dynamictrees:trunkshell:0)
Block(0,21,0,dynamictrees:trunkshell)
Block(0,21,1,dynamictrees:junglebranch:9)
Block(0,21,2,dynamictrees:trunkshell:0)
Block(0,22,0,dynamictrees:trunkshell)
Block(0,22,1,dynamictrees:junglebranch:9)
Block(0,22,2,dynamictrees:trunkshell:0)
Block(0,23,0,dynamictrees:trunkshell)
Block(0,23,1,dynamictrees:junglebranch:9)
Block(0,23,2,dynamictrees:trunkshell:0)
Block(0,24,0,dynamictrees:trunkshell)
Block(0,24,1,dynamictrees:junglebranch:9)
Block(0,24,2,dynamictrees:trunkshell:0)
Block(0,25,0,dynamictrees:trunkshell)
Block(0,25,1,dynamictrees:junglebranch:9)
Block(0,25,2,dynamictrees:trunkshell:0)
Block(0,26,0,dynamictrees:trunkshell)
Block(0,26,1,dynamictrees:junglebranch:8)
Block(0,26,2,dynamictrees:trunkshell:0)
Block(0,27,0,dynamictrees:trunkshell)
Block(0,27,1,dynamictrees:junglebranch:8)
Block(0,27,2,dynamictrees:trunkshell:0)
Block(0,28,-1,dynamictrees:junglebranch:3)
Block(0,28,0,dynamictrees:junglebranch:3)
Block(0,28,1,dynamictrees:junglebranch:8)
Block(0,28,2,dynamictrees:trunkshell:0)
Block(0,28,6,dynamictrees:leaves0:15)
Block(0,28,7,dynamictrees:leaves0:14)
Block(0,28,8,dynamictrees:leaves0:12)
Block(0,29,-5,dynamictrees:leaves0:12)
Block(0,29,-4,dynamictrees:leaves0:15)
Block(0,29,-3,dynamictrees:junglebranch)
Block(0,29,-2,dynamictrees:junglebranch:1)
Block(0,29,-1,dynamictrees:junglebranch:2)
Block(0,29,1,dynamictrees:junglebranch:4)
Block(0,29,2,dynamictrees:junglebranch:2)
Block(0,29,3,dynamictrees:junglebranch:2)
Block(0,29,4,dynamictrees:junglebranch:1)
Block(0,29,5,dynamictrees:junglebranch:1)
Block(0,29,6,dynamictrees:junglebranch)
Block(0,29,7,dynamictrees:leaves0:15)
Block(0,29,8,dynamictrees:leaves0:12)
Block(0,30,-5,dynamictrees:leaves0:12)
Block(0,30,-4,dynamictrees:leaves0:14)
Block(0,30,-3,dynamictrees:leaves0:15)
Block(0,30,-2,dynamictrees:junglebranch)
Block(0,30,-1,dynamictrees:leaves0:15)
Block(0,30,0,dynamictrees:junglebranch)
Block(0,30,1,dynamictrees:junglebranch:3)
Block(0,30,2,dynamictrees:leaves0:15)
Block(0,30,3,dynamictrees:junglebranch)
Block(0,30,4,dynamictrees:leaves0:15)
Block(0,30,5,dynamictrees:leaves0:14)
Block(0,30,6,dynamictrees:leaves0:15)
Block(0,30,7,dynamictrees:leaves0:14)
Block(0,30,8,dynamictrees:leaves0:12)
Block(0,31,-5,dynamictrees:leaves0:12)
Block(0,31,-4,dynamictrees:leaves0:13)
Block(0,31,-3,dynamictrees:leaves0:14)
Block(0,31,-2,dynamictrees:leaves0:15)
Block(0,31,-1,dynamictrees:leaves0:14)
Block(0,31,0,dynamictrees:leaves0:15)
Block(0,31,1,dynamictrees:junglebranch:1)
Block(0,31,2,dynamictrees:junglebranch)
Block(0,31,3,dynamictrees:leaves0:15)
Block(0,31,4,dynamictrees:leaves0:14)
Block(0,31,5,dynamictrees:leaves0:13)
Block(0,31,6,dynamictrees:leaves0:12)
Block(0,31,7,dynamictrees:leaves0:12)
Block(0,32,-4,dynamictrees:leaves0:12)
Block(0,32,-3,dynamictrees:leaves0:13)
Block(0,32,-2,dynamictrees:leaves0:14)
Block(0,32,-1,dynamictrees:leaves0:15)
Block(0,32,0,dynamictrees:junglebranch)
Block(0,32,1,dynamictrees:junglebranch:1)
Block(0,32,2,dynamictrees:leaves0:15)
Block(0,32,3,dynamictrees:leaves0:14)
Block(0,32,4,dynamictrees:leaves0:13)
Block(0,32,5,dynamictrees:leaves0:12)
Block(0,33,-3,dynamictrees:leaves0:12)
Block(0,33,-2,dynamictrees:leaves0:12)
Block(0,33,-1,dynamictrees:leaves0:12)
Block(0,33,0,dynamictrees:leaves0:12)
Block(0,33,1,dynamictrees:junglebranch)
Block(0,33,2,dynamictrees:leaves0:12)
Block(0,33,3,dynamictrees:leaves0:12)
Block(0,33,4,dynamictrees:leaves0:12)
Block(0,34,1,dynamictrees:leaves0:15)
Block(1,0,0,GRASS:0)
Block(1,0,1,GRASS:0)
Block(1,0,2,GRASS:0)
Block(1,0,3,dynamictrees:jungleroot:3)
Block(1,0,4,dynamictrees:jungleroot:2)
Block(1,1,0,dynamictrees:trunkshell:3)
Block(1,1,1,dynamictrees:trunkshell:2)
Block(1,1,2,dynamictrees:jungleroot:4)
Block(1,2,0,dynamictrees:trunkshell:3)
Block(1,2,1,dynamictrees:trunkshell:2)
Block(1,2,2,dynamictrees:trunkshell:1)
Block(1,3,0,dynamictrees:trunkshell:3)
Block(1,3,1,dynamictrees:trunkshell:2)
Block(1,3,2,dynamictrees:trunkshell:1)
Block(1,4,0,dynamictrees:trunkshell:3)
Block(1,4,1,dynamictrees:trunkshell:2)
Block(1,4,2,dynamictrees:trunkshell:1)
Block(1,5,0,dynamictrees:trunkshell:3)
Block(1,5,1,dynamictrees:trunkshell:2)
Block(1,5,2,dynamictrees:trunkshell:1)
Block(1,6,0,dynamictrees:trunkshell:3)
Block(1,6,1,dynamictrees:trunkshell:2)
Block(1,6,2,dynamictrees:trunkshell:1)
Block(1,7,0,dynamictrees:trunkshell:3)
Block(1,7,1,dynamictrees:trunkshell:2)
Block(1,7,2,dynamictrees:trunkshell:1)
Block(1,8,0,dynamictrees:trunkshell:3)
Block(1,8,1,dynamictrees:trunkshell:2)
Block(1,8,2,dynamictrees:trunkshell:1)
Block(1,9,0,dynamictrees:trunkshell:3)
Block(1,9,1,dynamictrees:trunkshell:2)
Block(1,9,2,dynamictrees:trunkshell:1)
Block(1,10,0,dynamictrees:trunkshell:3)
Block(1,10,1,dynamictrees:trunkshell:2)
Block(1,10,2,dynamictrees:trunkshell:1)
Block(1,11,0,dynamictrees:trunkshell:3)
Block(1,11,1,dynamictrees:trunkshell:2)
Block(1,11,2,dynamictrees:trunkshell:1)
Block(1,12,0,dynamictrees:trunkshell:3)
Block(1,12,1,dynamictrees:trunkshell:2)
Block(1,12,2,dynamictrees:trunkshell:1)
Block(1,13,0,dynamictrees:trunkshell:3)
Block(1,13,1,dynamictrees:trunkshell:2)
Block(1,13,2,dynamictrees:trunkshell:1)
Block(1,14,0,dynamictrees:trunkshell:3)
Block(1,14,1,dynamictrees:trunkshell:2)
Block(1,14,2,dynamictrees:trunkshell:1)
Block(1,15,0,dynamictrees:trunkshell:3)
Block(1,15,1,dynamictrees:trunkshell:2)
Block(1,15,2,dynamictrees:trunkshell:1)
Block(1,16,0,dynamictrees:trunkshell:3)
Block(1,16,1,dynamictrees:trunkshell:2)
Block(1,16,2,dynamictrees:trunkshell:1)
Block(1,17,0,dynamictrees:trunkshell:3)
Block(1,17,1,dynamictrees:trunkshell:2)
Block(1,17,2,dynamictrees:trunkshell:1)
Block(1,18,0,dynamictrees:trunkshell:3)
Block(1,18,1,dynamictrees:trunkshell:2)
Block(1,18,2,dynamictrees:trunkshell:1)
Block(1,19,0,dynamictrees:trunkshell:3)
Block(1,19,1,dynamictrees:trunkshell:2)
Block(1,19,2,dynamictrees:trunkshell:1)
Block(1,20,0,dynamictrees:trunkshell:3)
Block(1,20,1,dynamictrees:trunkshell:2)
Block(1,20,2,dynamictrees:trunkshell:1)
Block(1,21,0,dynamictrees:trunkshell:3)
Block(1,21,1,dynamictrees:trunkshell:2)
Block(1,21,2,dynamictrees:trunkshell:1)
Block(1,22,0,dynamictrees:trunkshell:3)
Block(1,22,1,dynamictrees:trunkshell:2)
Block(1,22,2,dynamictrees:trunkshell:1)
Block(1,23,0,dynamictrees:trunkshell:3)
Block(1,23,1,dynamictrees:trunkshell:2)
Block(1,23,2,dynamictrees:trunkshell:1)
Block(1,24,0,dynamictrees:trunkshell:3)
Block(1,24,1,dynamictrees:trunkshell:2)
Block(1,24,2,dynamictrees:trunkshell:1)
Block(1,25,0,dynamictrees:trunkshell:3)
Block(1,25,1,dynamictrees:trunkshell:2)
Block(1,25,2,dynamictrees:trunkshell:1)
Block(1,26,0,dynamictrees:trunkshell:3)
Block(1,26,1,dynamictrees:trunkshell:2)
Block(1,26,2,dynamictrees:trunkshell:1)
Block(1,27,0,dynamictrees:trunkshell:3)
Block(1,27,1,dynamictrees:trunkshell:2)
Block(1,27,2,dynamictrees:trunkshell:1)
Block(1,28,-5,dynamictrees:leaves0:12)
Block(1,28,-4,dynamictrees:leaves0:15)
Block(1,28,-3,dynamictrees:junglebranch)
Block(1,28,-2,dynamictrees:junglebranch:1)
Block(1,28,-1,dynamictrees:junglebranch:2)
Block(1,28,0,dynamictrees:trunkshell:3)
Block(1,28,1,dynamictrees:junglebranch:3)
Block(1,28,2,dynamictrees:trunkshell:1)
Block(1,28,5,dynamictrees:leaves0:15)
Block(1,28,6,dynamictrees:leaves0:14)
Block(1,28,7,dynamictrees:leaves0:13)
Block(1,28,8,dynamictrees:leaves0:12)
Block(1,29,-5,dynamictrees:leaves0:12)
Block(1,29,-4,dynamictrees:leaves0:14)
Block(1,29,-3,dynamictrees:leaves0:15)
Block(1,29,3,dynamictrees:junglebranch)
Block(1,29,4,dynamictrees:leaves0:15)
Block(1,29,5,dynamictrees:junglebranch)
Block(1,29,6,dynamictrees:leaves0:15)
Block(1,29,7,dynamictrees:leaves0:14)
Block(1,29,8,dynamictrees:leaves0:12)
Block(1,30,-5,dynamictrees:leaves0:12)
Block(1,30,-4,dynamictrees:leaves0:13)
Block(1,30,-3,dynamictrees:leaves0:14)
Block(1,30,-2,dynamictrees:leaves0:15)
Block(1,30,-1,dynamictrees:leaves0:14)
Block(1,30,0,dynamictrees:leaves0:15)
Block(1,30,1,dynamictrees:junglebranch:1)
Block(1,30,2,dynamictrees:junglebranch:1)
Block(1,30,3,dynamictrees:leaves0:15)
Block(1,30,4,dynamictrees:leaves0:14)
Block(1,30,5,dynamictrees:leaves0:15)
Block(1,30,6,dynamictrees:leaves0:14)
Block(1,30,7,dynamictrees:leaves0:13)
Block(1,30,8,dynamictrees:leaves0:12)
Block(1,31,-4,dynamictrees:leaves0:12)
Block(1,31,-3,dynamictrees:leaves0:13)
Block(1,31,-2,dynamictrees:leaves0:14)
Block(1,31,-1,dynamictrees:leaves0:13)
Block(1,31,0,dynamictrees:leaves0:14)
Block(1,31,1,dynamictrees:leaves0:15)
Block(1,31,2,dynamictrees:leaves0:15)
Block(1,31,3,dynamictrees:leaves0:14)
Block(1,31,4,dynamictrees:leaves0:13)
Block(1,31,5,dynamictrees:leaves0:12)
Block(1,31,6,dynamictrees:leaves0:12)
Block(1,31,7,dynamictrees:leaves0:12)
Block(1,32,-3,dynamictrees:leaves0:12)
Block(1,32,-2,dynamictrees:leaves0:13)
Block(1,32,-1,dynamictrees:leaves0:14)
Block(1,32,0,dynamictrees:leaves0:15)
Block(1,32,1,dynamictrees:junglebranch)
Block(1,32,2,dynamictrees:leaves0:15)
Block(1,32,3,dynamictrees:leaves0:13)
Block(1,32,4,dynamictrees:leaves0:12)
Block(1,33,-2,dynamictrees:leaves0:12)
Block(1,33,-1,dynamictrees:leaves0:12)
Block(1,33,0,dynamictrees:leaves0:12)
Block(1,33,1,dynamictrees:leaves0:12)
Block(1,33,2,dynamictrees:leaves0:12)
Block(1,33,3,dynamictrees:leaves0:12)
Block(2,0,4,dynamictrees:jungleroot)
Block(2,27,-4,dynamictrees:leaves0:12)
Block(2,28,-5,dynamictrees:leaves0:12)
Block(2,28,-4,dynamictrees:leaves0:14)
Block(2,28,-3,dynamictrees:leaves0:15)
Block(2,28,-1,dynamictrees:junglebranch:1)
Block(2,28,1,dynamictrees:junglebranch:2)
Block(2,28,2,dynamictrees:junglebranch:1)
Block(2,28,6,dynamictrees:leaves0:13)
Block(2,28,7,dynamictrees:leaves0:12)
Block(2,29,-5,dynamictrees:leaves0:12)
Block(2,29,-4,dynamictrees:leaves0:13)
Block(2,29,-3,dynamictrees:leaves0:14)
Block(2,29,-2,dynamictrees:leaves0:13)
Block(2,29,0,dynamictrees:junglebranch:1)
Block(2,29,1,dynamictrees:junglebranch:2)
Block(2,29,4,dynamictrees:leaves0:14)
Block(2,29,5,dynamictrees:leaves0:15)
Block(2,29,6,dynamictrees:leaves0:14)
Block(2,29,7,dynamictrees:leaves0:13)
Block(2,29,8,dynamictrees:leaves0:12)
Block(2,30,-4,dynamictrees:leaves0:12)
Block(2,30,-3,dynamictrees:leaves0:13)
Block(2,30,-2,dynamictrees:leaves0:14)
Block(2,30,-1,dynamictrees:leaves0:15)
Block(2,30,0,dynamictrees:junglebranch)
Block(2,30,1,dynamictrees:leaves0:15)
Block(2,30,2,dynamictrees:junglebranch:1)
Block(2,30,3,dynamictrees:junglebranch)
Block(2,30,4,dynamictrees:leaves0:15)
Block(2,30,5,dynamictrees:leaves0:14)
Block(2,30,6,dynamictrees:leaves0:13)
Block(2,30,7,dynamictrees:leaves0:12)
Block(2,31,-3,dynamictrees:leaves0:12)
Block(2,31,-2,dynamictrees:leaves0:13)
Block(2,31,-1,dynamictrees:leaves0:14)
Block(2,31,0,dynamictrees:leaves0:15)
Block(2,31,1,dynamictrees:leaves0:14)
Block(2,31,2,dynamictrees:leaves0:14)
Block(2,31,3,dynamictrees:leaves0:15)
Block(2,31,4,dynamictrees:leaves0:14)
Block(2,31,5,dynamictrees:leaves0:13)
Block(2,31,6,dynamictrees:leaves0:12)
Block(2,32,-2,dynamictrees:leaves0:12)
Block(2,32,-1,dynamictrees:leaves0:13)
Block(2,32,0,dynamictrees:leaves0:14)
Block(2,32,1,dynamictrees:leaves0:15)
Block(2,32,2,dynamictrees:leaves0:14)
Block(2,32,3,dynamictrees:leaves0:12)
Block(2,32,4,dynamictrees:leaves0:12)
Block(2,32,5,dynamictrees:leaves0:12)
Block(2,33,-1,dynamictrees:leaves0:12)
Block(2,33,0,dynamictrees:leaves0:12)
Block(2,33,1,dynamictrees:leaves0:12)
Block(2,33,2,dynamictrees:leaves0:12)
Block(2,33,3,dynamictrees:leaves0:12)
Block(3,27,-4,dynamictrees:leaves0:12)
Block(3,27,-3,dynamictrees:leaves0:12)
Block(3,28,-5,dynamictrees:leaves0:12)
Block(3,28,-4,dynamictrees:leaves0:13)
Block(3,28,-3,dynamictrees:leaves0:14)
Block(3,28,-2,dynamictrees:leaves0:15)
Block(3,28,-1,dynamictrees:junglebranch)
Block(3,28,2,dynamictrees:junglebranch:1)
Block(3,28,3,dynamictrees:junglebranch)
Block(3,28,6,dynamictrees:leaves0:12)
Block(3,29,-4,dynamictrees:leaves0:12)
Block(3,29,-3,dynamictrees:leaves0:13)
Block(3,29,-2,dynamictrees:leaves0:14)
Block(3,29,-1,dynamictrees:leaves0:15)
Block(3,29,1,dynamictrees:junglebranch:1)
Block(3,29,3,dynamictrees:leaves0:15)
Block(3,29,4,dynamictrees:leaves0:13)
Block(3,29,5,dynamictrees:leaves0:12)
Block(3,29,6,dynamictrees:leaves0:12)
Block(3,29,7,dynamictrees:leaves0:12)
Block(3,30,-3,dynamictrees:leaves0:12)
Block(3,30,-2,dynamictrees:leaves0:13)
Block(3,30,-1,dynamictrees:leaves0:14)
Block(3,30,0,dynamictrees:leaves0:15)
Block(3,30,1,dynamictrees:junglebranch)
Block(3,30,2,dynamictrees:leaves0:15)
Block(3,30,3,dynamictrees:leaves0:15)
Block(3,30,4,dynamictrees:leaves0:14)
Block(3,30,5,dynamictrees:leaves0:13)
Block(3,30,6,dynamictrees:leaves0:12)
Block(3,31,-2,dynamictrees:leaves0:12)
Block(3,31,-1,dynamictrees:leaves0:13)
Block(3,31,0,dynamictrees:leaves0:14)
Block(3,31,1,dynamictrees:leaves0:15)
Block(3,31,2,dynamictrees:leaves0:14)
Block(3,31,3,dynamictrees:leaves0:14)
Block(3,31,4,dynamictrees:leaves0:13)
Block(3,31,5,dynamictrees:leaves0:12)
Block(3,32,-1,dynamictrees:leaves0:12)
Block(3,32,0,dynamictrees:leaves0:13)
Block(3,32,1,dynamictrees:leaves0:14)
Block(3,32,2,dynamictrees:leaves0:13)
Block(3,32,3,dynamictrees:leaves0:12)
Block(3,32,4,dynamictrees:leaves0:12)
Block(3,33,0,dynamictrees:leaves0:12)
Block(3,33,1,dynamictrees:leaves0:12)
Block(3,33,2,dynamictrees:leaves0:12)
Block(4,27,-3,dynamictrees:leaves0:12)
Block(4,27,-2,dynamictrees:leaves0:12)
Block(4,28,-4,dynamictrees:leaves0:12)
Block(4,28,-3,dynamictrees:leaves0:13)
Block(4,28,-2,dynamictrees:leaves0:14)
Block(4,28,-1,dynamictrees:leaves0:15)
Block(4,28,3,dynamictrees:leaves0:15)
Block(4,28,4,dynamictrees:leaves0:12)
Block(4,29,-3,dynamictrees:leaves0:12)
Block(4,29,-2,dynamictrees:leaves0:13)
Block(4,29,-1,dynamictrees:leaves0:14)
Block(4,29,0,dynamictrees:leaves0:13)
Block(4,29,2,dynamictrees:leaves0:13)
Block(4,29,3,dynamictrees:leaves0:14)
Block(4,29,4,dynamictrees:leaves0:12)
Block(4,30,-2,dynamictrees:leaves0:12)
Block(4,30,-1,dynamictrees:leaves0:13)
Block(4,30,0,dynamictrees:leaves0:14)
Block(4,30,1,dynamictrees:leaves0:15)
Block(4,30,2,dynamictrees:leaves0:14)
Block(4,30,3,dynamictrees:leaves0:13)
Block(4,30,4,dynamictrees:leaves0:12)
Block(4,30,5,dynamictrees:leaves0:12)
Block(4,31,-1,dynamictrees:leaves0:12)
Block(4,31,0,dynamictrees:leaves0:13)
Block(4,31,1,dynamictrees:leaves0:14)
Block(4,31,2,dynamictrees:leaves0:13)
Block(4,31,3,dynamictrees:leaves0:12)
Block(4,31,4,dynamictrees:leaves0:12)
Block(4,32,0,dynamictrees:leaves0:12)
Block(4,32,1,dynamictrees:leaves0:13)
Block(4,32,2,dynamictrees:leaves0:12)
Block(4,33,1,dynamictrees:leaves0:12)
Block(5,28,-3,dynamictrees:leaves0:12)
Block(5,28,-2,dynamictrees:leaves0:12)
Block(5,28,-1,dynamictrees:leaves0:12)
Block(5,28,3,dynamictrees:leaves0:12)
Block(5,29,-2,dynamictrees:leaves0:12)
Block(5,29,-1,dynamictrees:leaves0:12)
Block(5,29,0,dynamictrees:leaves0:12)
Block(5,29,2,dynamictrees:leaves0:12)
Block(5,29,3,dynamictrees:leaves0:12)
Block(5,30,-1,dynamictrees:leaves0:12)
Block(5,30,0,dynamictrees:leaves0:12)
Block(5,30,1,dynamictrees:leaves0:12)
Block(5,30,2,dynamictrees:leaves0:12)
Block(5,30,3,dynamictrees:leaves0:12)
Block(5,31,0,dynamictrees:leaves0:12)
Block(5,31,1,dynamictrees:leaves0:12)
Block(5,31,2,dynamictrees:leaves0:12)
Block(5,32,1,dynamictrees:leaves0:12)

#######################################################################
# +-----------------------------------------------------------------+ #
# |                            BO3 checks                           | #
# +-----------------------------------------------------------------+ #
#######################################################################

BlockCheck(0,-1,1,GRASS,DIRT,biomesoplenty:grass,biomesoplenty:dirt)

#######################################################################
# +-----------------------------------------------------------------+ #
# |                             Branches                            | #
# +-----------------------------------------------------------------+ #
#######################################################################


#######################################################################
# +-----------------------------------------------------------------+ #
# |                             Entities                            | #
# +-----------------------------------------------------------------+ #
#######################################################################


#######################################################################
# +-----------------------------------------------------------------+ #
# |                            Particles                            | #
# +-----------------------------------------------------------------+ #
#######################################################################


#######################################################################
# +-----------------------------------------------------------------+ #
# |                             Spawners                            | #
# +-----------------------------------------------------------------+ #
#######################################################################


#######################################################################
# +-----------------------------------------------------------------+ #
# |                             ModData                             | #
# +-----------------------------------------------------------------+ #
#######################################################################

