
#######################################################################
# +-----------------------------------------------------------------+ #
# |                            BO3 object                           | #
# +-----------------------------------------------------------------+ #
#######################################################################

Author: NLBlackHeavenNL

Description: No description given

Version: 3

SettingsMode: WriteWithoutComments


#######################################################################
# +-----------------------------------------------------------------+ #
# |                          Main settings                          | #
# +-----------------------------------------------------------------+ #
#######################################################################

Tree: true

Frequency: 1

Rarity: 100.0

RotateRandomly: false

SpawnHeight: highestSolidBlock

SpawnHeightOffset: -1

SpawnHeightVariance: 0

##############################
# Height Limits for the BO3. #
##############################

MinHeight: 0

MaxHeight: 255

######################
# Extrusion settings #
######################

ExtrudeMode: None

ExtrudeThroughBlocks: AIR

MaxBranchDepth: 10

ExcludedBiomes: All


#######################################################################
# +-----------------------------------------------------------------+ #
# |                      Source block settings                      | #
# +-----------------------------------------------------------------+ #
#######################################################################

SourceBlocks: AIR,GRASS,DIRT,biomesoplenty:dirt

MaxPercentageOutsideSourceBlock: 0

OutsideSourceBlock: placeAnyway

DoReplaceBlocks: true

IsOTGPlus: false


#######################################################################
# +-----------------------------------------------------------------+ #
# |                              Blocks                             | #
# +-----------------------------------------------------------------+ #
#######################################################################

Block(-7,7,0,dynamictrees:leaves0:12)
Block(-7,7,1,dynamictrees:leaves0:12)
Block(-7,7,2,dynamictrees:leaves0:12)
Block(-7,8,-1,dynamictrees:leaves0:12)
Block(-7,8,0,dynamictrees:leaves0:12)
Block(-7,8,1,dynamictrees:leaves0:12)
Block(-7,8,2,dynamictrees:leaves0:12)
Block(-7,9,0,dynamictrees:leaves0:12)
Block(-7,9,1,dynamictrees:leaves0:12)
Block(-7,9,2,dynamictrees:leaves0:12)
Block(-6,7,-1,dynamictrees:leaves0:12)
Block(-6,7,0,dynamictrees:leaves0:13)
Block(-6,7,1,dynamictrees:leaves0:14)
Block(-6,7,2,dynamictrees:leaves0:13)
Block(-6,7,3,dynamictrees:leaves0:12)
Block(-6,8,-2,dynamictrees:leaves0:12)
Block(-6,8,-1,dynamictrees:leaves0:13)
Block(-6,8,0,dynamictrees:leaves0:14)
Block(-6,8,1,dynamictrees:leaves0:15)
Block(-6,8,2,dynamictrees:leaves0:14)
Block(-6,8,3,dynamictrees:leaves0:12)
Block(-6,9,-1,dynamictrees:leaves0:12)
Block(-6,9,0,dynamictrees:leaves0:13)
Block(-6,9,1,dynamictrees:leaves0:14)
Block(-6,9,2,dynamictrees:leaves0:13)
Block(-6,9,3,dynamictrees:leaves0:12)
Block(-6,10,0,dynamictrees:leaves0:12)
Block(-6,10,1,dynamictrees:leaves0:12)
Block(-6,10,2,dynamictrees:leaves0:12)
Block(-6,30,1,dynamictrees:leaves0:12)
Block(-6,30,2,dynamictrees:leaves0:12)
Block(-6,30,3,dynamictrees:leaves0:12)
Block(-6,31,0,dynamictrees:leaves0:12)
Block(-6,31,1,dynamictrees:leaves0:12)
Block(-6,31,2,dynamictrees:leaves0:12)
Block(-6,31,3,dynamictrees:leaves0:12)
Block(-6,31,4,dynamictrees:leaves0:12)
Block(-6,32,1,dynamictrees:leaves0:12)
Block(-6,32,2,dynamictrees:leaves0:12)
Block(-6,32,3,dynamictrees:leaves0:12)
Block(-5,7,-2,dynamictrees:leaves0:12)
Block(-5,7,-1,dynamictrees:leaves0:13)
Block(-5,7,0,dynamictrees:leaves0:14)
Block(-5,7,1,dynamictrees:leaves0:15)
Block(-5,7,2,dynamictrees:leaves0:14)
Block(-5,7,3,dynamictrees:leaves0:12)
Block(-5,8,-3,dynamictrees:leaves0:12)
Block(-5,8,-2,dynamictrees:leaves0:13)
Block(-5,8,-1,dynamictrees:leaves0:14)
Block(-5,8,0,dynamictrees:leaves0:15)
Block(-5,8,1,dynamictrees:junglebranch)
Block(-5,8,2,dynamictrees:leaves0:15)
Block(-5,8,3,dynamictrees:leaves0:12)
Block(-5,9,-2,dynamictrees:leaves0:12)
Block(-5,9,-1,dynamictrees:leaves0:13)
Block(-5,9,0,dynamictrees:leaves0:14)
Block(-5,9,1,dynamictrees:leaves0:15)
Block(-5,9,2,dynamictrees:leaves0:14)
Block(-5,9,3,dynamictrees:leaves0:12)
Block(-5,10,-1,dynamictrees:leaves0:12)
Block(-5,10,0,dynamictrees:leaves0:12)
Block(-5,10,1,dynamictrees:leaves0:12)
Block(-5,10,2,dynamictrees:leaves0:12)
Block(-5,30,0,dynamictrees:leaves0:12)
Block(-5,30,1,dynamictrees:leaves0:13)
Block(-5,30,2,dynamictrees:leaves0:14)
Block(-5,30,3,dynamictrees:leaves0:13)
Block(-5,30,4,dynamictrees:leaves0:12)
Block(-5,31,-1,dynamictrees:leaves0:12)
Block(-5,31,0,dynamictrees:leaves0:13)
Block(-5,31,1,dynamictrees:leaves0:14)
Block(-5,31,2,dynamictrees:leaves0:15)
Block(-5,31,3,dynamictrees:leaves0:14)
Block(-5,31,4,dynamictrees:leaves0:13)
Block(-5,31,5,dynamictrees:leaves0:12)
Block(-5,32,0,dynamictrees:leaves0:12)
Block(-5,32,1,dynamictrees:leaves0:13)
Block(-5,32,2,dynamictrees:leaves0:14)
Block(-5,32,3,dynamictrees:leaves0:13)
Block(-5,32,4,dynamictrees:leaves0:12)
Block(-5,33,1,dynamictrees:leaves0:12)
Block(-5,33,2,dynamictrees:leaves0:12)
Block(-5,33,3,dynamictrees:leaves0:12)
Block(-4,7,-3,dynamictrees:leaves0:12)
Block(-4,7,-2,dynamictrees:leaves0:13)
Block(-4,7,-1,dynamictrees:leaves0:14)
Block(-4,7,0,dynamictrees:leaves0:15)
Block(-4,7,1,dynamictrees:leaves0:14)
Block(-4,7,2,dynamictrees:leaves0:13)
Block(-4,7,3,dynamictrees:leaves0:12)
Block(-4,7,4,dynamictrees:leaves0:12)
Block(-4,7,5,dynamictrees:leaves0:12)
Block(-4,8,-4,dynamictrees:leaves0:12)
Block(-4,8,-3,dynamictrees:leaves0:13)
Block(-4,8,-2,dynamictrees:leaves0:14)
Block(-4,8,-1,dynamictrees:leaves0:15)
Block(-4,8,0,dynamictrees:junglebranch)
Block(-4,8,1,dynamictrees:junglebranch:1)
Block(-4,8,2,dynamictrees:leaves0:12)
Block(-4,8,4,dynamictrees:leaves0:12)
Block(-4,8,5,dynamictrees:leaves0:12)
Block(-4,9,-3,dynamictrees:leaves0:12)
Block(-4,9,-2,dynamictrees:leaves0:13)
Block(-4,9,-1,dynamictrees:leaves0:14)
Block(-4,9,0,dynamictrees:leaves0:15)
Block(-4,9,1,dynamictrees:leaves0:14)
Block(-4,9,2,dynamictrees:leaves0:13)
Block(-4,9,3,dynamictrees:leaves0:12)
Block(-4,9,4,dynamictrees:leaves0:12)
Block(-4,9,5,dynamictrees:leaves0:12)
Block(-4,10,-2,dynamictrees:leaves0:12)
Block(-4,10,-1,dynamictrees:leaves0:12)
Block(-4,10,0,dynamictrees:leaves0:12)
Block(-4,10,1,dynamictrees:leaves0:12)
Block(-4,10,2,dynamictrees:leaves0:12)
Block(-4,30,-3,dynamictrees:leaves0:12)
Block(-4,30,-2,dynamictrees:leaves0:12)
Block(-4,30,-1,dynamictrees:leaves0:12)
Block(-4,30,0,dynamictrees:leaves0:13)
Block(-4,30,1,dynamictrees:leaves0:14)
Block(-4,30,2,dynamictrees:leaves0:15)
Block(-4,30,3,dynamictrees:leaves0:14)
Block(-4,30,4,dynamictrees:leaves0:13)
Block(-4,30,5,dynamictrees:leaves0:12)
Block(-4,31,-4,dynamictrees:leaves0:12)
Block(-4,31,-3,dynamictrees:leaves0:12)
Block(-4,31,-2,dynamictrees:leaves0:12)
Block(-4,31,-1,dynamictrees:leaves0:13)
Block(-4,31,0,dynamictrees:leaves0:14)
Block(-4,31,1,dynamictrees:leaves0:15)
Block(-4,31,2,dynamictrees:junglebranch)
Block(-4,31,3,dynamictrees:leaves0:15)
Block(-4,31,4,dynamictrees:leaves0:14)
Block(-4,31,5,dynamictrees:leaves0:12)
Block(-4,32,-3,dynamictrees:leaves0:12)
Block(-4,32,-2,dynamictrees:leaves0:12)
Block(-4,32,-1,dynamictrees:leaves0:12)
Block(-4,32,0,dynamictrees:leaves0:13)
Block(-4,32,1,dynamictrees:leaves0:14)
Block(-4,32,2,dynamictrees:leaves0:15)
Block(-4,32,3,dynamictrees:leaves0:14)
Block(-4,32,4,dynamictrees:leaves0:13)
Block(-4,32,5,dynamictrees:leaves0:12)
Block(-4,33,0,dynamictrees:leaves0:12)
Block(-4,33,1,dynamictrees:leaves0:12)
Block(-4,33,2,dynamictrees:leaves0:12)
Block(-4,33,3,dynamictrees:leaves0:12)
Block(-4,33,4,dynamictrees:leaves0:12)
Block(-3,7,-4,dynamictrees:leaves0:12)
Block(-3,7,-3,dynamictrees:leaves0:13)
Block(-3,7,-2,dynamictrees:leaves0:14)
Block(-3,7,-1,dynamictrees:leaves0:13)
Block(-3,7,0,dynamictrees:leaves0:14)
Block(-3,7,1,dynamictrees:leaves0:13)
Block(-3,7,2,dynamictrees:leaves0:12)
Block(-3,7,3,dynamictrees:leaves0:12)
Block(-3,7,4,dynamictrees:leaves0:14)
Block(-3,7,5,dynamictrees:leaves0:13)
Block(-3,7,6,dynamictrees:leaves0:12)
Block(-3,8,-5,dynamictrees:leaves0:12)
Block(-3,8,-4,dynamictrees:leaves0:13)
Block(-3,8,-3,dynamictrees:leaves0:14)
Block(-3,8,-2,dynamictrees:leaves0:15)
Block(-3,8,-1,dynamictrees:leaves0:14)
Block(-3,8,0,dynamictrees:leaves0:15)
Block(-3,8,1,dynamictrees:junglebranch:1)
Block(-3,8,3,dynamictrees:leaves0:12)
Block(-3,8,4,dynamictrees:leaves0:15)
Block(-3,8,5,dynamictrees:leaves0:14)
Block(-3,8,6,dynamictrees:leaves0:12)
Block(-3,9,-4,dynamictrees:leaves0:12)
Block(-3,9,-3,dynamictrees:leaves0:13)
Block(-3,9,-2,dynamictrees:leaves0:14)
Block(-3,9,-1,dynamictrees:leaves0:13)
Block(-3,9,0,dynamictrees:leaves0:14)
Block(-3,9,1,dynamictrees:leaves0:13)
Block(-3,9,2,dynamictrees:leaves0:12)
Block(-3,9,3,dynamictrees:leaves0:12)
Block(-3,9,4,dynamictrees:leaves0:14)
Block(-3,9,5,dynamictrees:leaves0:13)
Block(-3,9,6,dynamictrees:leaves0:12)
Block(-3,10,-3,dynamictrees:leaves0:12)
Block(-3,10,-2,dynamictrees:leaves0:12)
Block(-3,10,-1,dynamictrees:leaves0:12)
Block(-3,10,0,dynamictrees:leaves0:12)
Block(-3,10,1,dynamictrees:leaves0:12)
Block(-3,10,4,dynamictrees:leaves0:12)
Block(-3,10,5,dynamictrees:leaves0:12)
Block(-3,30,-4,dynamictrees:leaves0:12)
Block(-3,30,-3,dynamictrees:leaves0:13)
Block(-3,30,-2,dynamictrees:leaves0:14)
Block(-3,30,-1,dynamictrees:leaves0:13)
Block(-3,30,0,dynamictrees:leaves0:14)
Block(-3,30,1,dynamictrees:leaves0:13)
Block(-3,30,2,dynamictrees:leaves0:14)
Block(-3,30,3,dynamictrees:leaves0:15)
Block(-3,30,4,dynamictrees:leaves0:14)
Block(-3,30,5,dynamictrees:leaves0:12)
Block(-3,31,-5,dynamictrees:leaves0:12)
Block(-3,31,-4,dynamictrees:leaves0:13)
Block(-3,31,-3,dynamictrees:leaves0:14)
Block(-3,31,-2,dynamictrees:leaves0:15)
Block(-3,31,-1,dynamictrees:leaves0:14)
Block(-3,31,0,dynamictrees:leaves0:15)
Block(-3,31,1,dynamictrees:junglebranch:1)
Block(-3,31,2,dynamictrees:junglebranch:1)
Block(-3,31,3,dynamictrees:junglebranch)
Block(-3,31,4,dynamictrees:leaves0:15)
Block(-3,31,5,dynamictrees:leaves0:12)
Block(-3,32,-4,dynamictrees:leaves0:12)
Block(-3,32,-3,dynamictrees:leaves0:13)
Block(-3,32,-2,dynamictrees:leaves0:14)
Block(-3,32,-1,dynamictrees:leaves0:13)
Block(-3,32,0,dynamictrees:leaves0:14)
Block(-3,32,1,dynamictrees:leaves0:13)
Block(-3,32,2,dynamictrees:leaves0:15)
Block(-3,32,3,dynamictrees:leaves0:15)
Block(-3,32,4,dynamictrees:leaves0:14)
Block(-3,32,5,dynamictrees:leaves0:12)
Block(-3,33,-3,dynamictrees:leaves0:12)
Block(-3,33,-2,dynamictrees:leaves0:12)
Block(-3,33,-1,dynamictrees:leaves0:12)
Block(-3,33,0,dynamictrees:leaves0:12)
Block(-3,33,1,dynamictrees:leaves0:12)
Block(-3,33,2,dynamictrees:leaves0:12)
Block(-3,33,3,dynamictrees:leaves0:12)
Block(-3,33,4,dynamictrees:leaves0:12)
Block(-2,0,-2,dynamictrees:jungleroot:1)
Block(-2,7,-5,dynamictrees:leaves0:12)
Block(-2,7,-4,dynamictrees:leaves0:13)
Block(-2,7,-3,dynamictrees:leaves0:14)
Block(-2,7,-2,dynamictrees:leaves0:15)
Block(-2,7,3,dynamictrees:leaves0:12)
Block(-2,7,4,dynamictrees:leaves0:15)
Block(-2,7,5,dynamictrees:leaves0:14)
Block(-2,8,-5,dynamictrees:leaves0:12)
Block(-2,8,-4,dynamictrees:leaves0:14)
Block(-2,8,-3,dynamictrees:leaves0:15)
Block(-2,8,-2,dynamictrees:junglebranch)
Block(-2,8,1,dynamictrees:junglebranch:2)
Block(-2,8,2,dynamictrees:junglebranch:1)
Block(-2,8,3,dynamictrees:junglebranch:1)
Block(-2,8,4,dynamictrees:junglebranch)
Block(-2,8,5,dynamictrees:leaves0:15)
Block(-2,9,-5,dynamictrees:leaves0:12)
Block(-2,9,-4,dynamictrees:leaves0:13)
Block(-2,9,-3,dynamictrees:leaves0:14)
Block(-2,9,-2,dynamictrees:leaves0:15)
Block(-2,9,-1,dynamictrees:leaves0:12)
Block(-2,9,3,dynamictrees:leaves0:12)
Block(-2,9,4,dynamictrees:leaves0:15)
Block(-2,9,5,dynamictrees:leaves0:14)
Block(-2,9,6,dynamictrees:leaves0:12)
Block(-2,10,-4,dynamictrees:leaves0:12)
Block(-2,10,-3,dynamictrees:leaves0:12)
Block(-2,10,-2,dynamictrees:leaves0:12)
Block(-2,10,4,dynamictrees:leaves0:12)
Block(-2,10,5,dynamictrees:leaves0:12)
Block(-2,26,6,dynamictrees:leaves0:12)
Block(-2,27,5,dynamictrees:leaves0:12)
Block(-2,27,6,dynamictrees:leaves0:12)
Block(-2,30,-5,dynamictrees:leaves0:12)
Block(-2,30,-4,dynamictrees:leaves0:13)
Block(-2,30,-3,dynamictrees:leaves0:14)
Block(-2,30,-2,dynamictrees:leaves0:15)
Block(-2,30,-1,dynamictrees:leaves0:14)
Block(-2,30,0,dynamictrees:leaves0:15)
Block(-2,30,2,dynamictrees:leaves0:13)
Block(-2,30,3,dynamictrees:leaves0:14)
Block(-2,30,4,dynamictrees:leaves0:13)
Block(-2,30,5,dynamictrees:leaves0:12)
Block(-2,30,6,dynamictrees:leaves0:12)
Block(-2,30,7,dynamictrees:leaves0:12)
Block(-2,31,-6,dynamictrees:leaves0:12)
Block(-2,31,-5,dynamictrees:leaves0:13)
Block(-2,31,-4,dynamictrees:leaves0:14)
Block(-2,31,-3,dynamictrees:leaves0:15)
Block(-2,31,-2,dynamictrees:junglebranch)
Block(-2,31,-1,dynamictrees:leaves0:15)
Block(-2,31,0,dynamictrees:junglebranch)
Block(-2,31,1,dynamictrees:junglebranch:2)
Block(-2,31,2,dynamictrees:leaves0:15)
Block(-2,31,3,dynamictrees:leaves0:15)
Block(-2,31,4,dynamictrees:leaves0:14)
Block(-2,31,5,dynamictrees:leaves0:13)
Block(-2,31,6,dynamictrees:leaves0:12)
Block(-2,31,7,dynamictrees:leaves0:12)
Block(-2,32,-5,dynamictrees:leaves0:12)
Block(-2,32,-4,dynamictrees:leaves0:13)
Block(-2,32,-3,dynamictrees:leaves0:14)
Block(-2,32,-2,dynamictrees:leaves0:15)
Block(-2,32,-1,dynamictrees:leaves0:14)
Block(-2,32,0,dynamictrees:leaves0:15)
Block(-2,32,1,dynamictrees:junglebranch:1)
Block(-2,32,2,dynamictrees:junglebranch)
Block(-2,32,3,dynamictrees:leaves0:15)
Block(-2,32,4,dynamictrees:leaves0:13)
Block(-2,32,5,dynamictrees:leaves0:12)
Block(-2,32,6,dynamictrees:leaves0:12)
Block(-2,32,7,dynamictrees:leaves0:12)
Block(-2,33,-4,dynamictrees:leaves0:12)
Block(-2,33,-3,dynamictrees:leaves0:12)
Block(-2,33,-2,dynamictrees:leaves0:12)
Block(-2,33,-1,dynamictrees:leaves0:12)
Block(-2,33,0,dynamictrees:leaves0:12)
Block(-2,33,1,dynamictrees:junglebranch)
Block(-2,33,2,dynamictrees:leaves0:12)
Block(-2,33,3,dynamictrees:leaves0:12)
Block(-2,33,4,dynamictrees:leaves0:12)
Block(-2,34,1,dynamictrees:leaves0:15)
Block(-1,0,-2,dynamictrees:jungleroot:2)
Block(-1,0,-1,dynamictrees:jungleroot:3)
Block(-1,0,0,GRASS:0)
Block(-1,0,1,GRASS:0)
Block(-1,0,2,GRASS:0)
Block(-1,1,0,dynamictrees:jungleroot:4)
Block(-1,1,1,dynamictrees:trunkshell:6)
Block(-1,1,2,dynamictrees:trunkshell:7)
Block(-1,2,0,dynamictrees:trunkshell:5)
Block(-1,2,1,dynamictrees:trunkshell:6)
Block(-1,2,2,dynamictrees:trunkshell:7)
Block(-1,3,0,dynamictrees:trunkshell:5)
Block(-1,3,1,dynamictrees:trunkshell:6)
Block(-1,3,2,dynamictrees:trunkshell:7)
Block(-1,4,0,dynamictrees:trunkshell:5)
Block(-1,4,1,dynamictrees:trunkshell:6)
Block(-1,4,2,dynamictrees:trunkshell:7)
Block(-1,5,0,dynamictrees:trunkshell:5)
Block(-1,5,1,dynamictrees:trunkshell:6)
Block(-1,5,2,dynamictrees:trunkshell:7)
Block(-1,6,0,dynamictrees:trunkshell:5)
Block(-1,6,1,dynamictrees:trunkshell:6)
Block(-1,6,2,dynamictrees:trunkshell:7)
Block(-1,7,-5,dynamictrees:leaves0:12)
Block(-1,7,-4,dynamictrees:leaves0:14)
Block(-1,7,-3,dynamictrees:leaves0:15)
Block(-1,7,-2,dynamictrees:leaves0:14)
Block(-1,7,0,dynamictrees:trunkshell:5)
Block(-1,7,1,dynamictrees:trunkshell:6)
Block(-1,7,2,dynamictrees:trunkshell:7)
Block(-1,8,-5,dynamictrees:leaves0:12)
Block(-1,8,-4,dynamictrees:leaves0:15)
Block(-1,8,-3,dynamictrees:junglebranch)
Block(-1,8,-2,dynamictrees:junglebranch:1)
Block(-1,8,-1,dynamictrees:junglebranch:2)
Block(-1,8,0,dynamictrees:junglebranch:2)
Block(-1,8,1,dynamictrees:junglebranch:3)
Block(-1,8,2,dynamictrees:trunkshell:7)
Block(-1,9,-5,dynamictrees:leaves0:12)
Block(-1,9,-4,dynamictrees:leaves0:14)
Block(-1,9,-3,dynamictrees:leaves0:15)
Block(-1,9,-2,dynamictrees:leaves0:14)
Block(-1,9,0,dynamictrees:trunkshell:5)
Block(-1,9,1,dynamictrees:trunkshell:6)
Block(-1,9,2,dynamictrees:trunkshell:7)
Block(-1,10,-4,dynamictrees:leaves0:12)
Block(-1,10,-3,dynamictrees:leaves0:12)
Block(-1,10,0,dynamictrees:trunkshell:5)
Block(-1,10,1,dynamictrees:trunkshell:6)
Block(-1,10,2,dynamictrees:trunkshell:7)
Block(-1,10,4,dynamictrees:leaves0:12)
Block(-1,10,5,dynamictrees:leaves0:13)
Block(-1,11,0,dynamictrees:trunkshell:5)
Block(-1,11,1,dynamictrees:trunkshell:6)
Block(-1,11,2,dynamictrees:trunkshell:7)
Block(-1,12,0,dynamictrees:trunkshell:5)
Block(-1,12,1,dynamictrees:trunkshell:6)
Block(-1,12,2,dynamictrees:trunkshell:7)
Block(-1,13,0,dynamictrees:trunkshell:5)
Block(-1,13,1,dynamictrees:trunkshell:6)
Block(-1,13,2,dynamictrees:trunkshell:7)
Block(-1,14,0,dynamictrees:trunkshell:5)
Block(-1,14,1,dynamictrees:trunkshell:6)
Block(-1,14,2,dynamictrees:trunkshell:7)
Block(-1,15,0,dynamictrees:trunkshell:5)
Block(-1,15,1,dynamictrees:trunkshell:6)
Block(-1,15,2,dynamictrees:trunkshell:7)
Block(-1,16,0,dynamictrees:trunkshell:5)
Block(-1,16,1,dynamictrees:trunkshell:6)
Block(-1,16,2,dynamictrees:trunkshell:7)
Block(-1,17,2,dynamictrees:trunkshell:7)
Block(-1,18,0,dynamictrees:trunkshell:5)
Block(-1,18,1,dynamictrees:trunkshell:6)
Block(-1,18,2,dynamictrees:trunkshell:7)
Block(-1,19,0,dynamictrees:trunkshell:5)
Block(-1,19,1,dynamictrees:trunkshell:6)
Block(-1,19,2,dynamictrees:trunkshell:7)
Block(-1,20,0,dynamictrees:trunkshell:5)
Block(-1,20,1,dynamictrees:trunkshell:6)
Block(-1,20,2,dynamictrees:trunkshell:7)
Block(-1,21,0,dynamictrees:trunkshell:5)
Block(-1,21,1,dynamictrees:trunkshell:6)
Block(-1,21,2,dynamictrees:trunkshell:7)
Block(-1,22,0,dynamictrees:trunkshell:5)
Block(-1,22,1,dynamictrees:trunkshell:6)
Block(-1,22,2,dynamictrees:trunkshell:7)
Block(-1,23,0,dynamictrees:trunkshell:5)
Block(-1,23,1,dynamictrees:trunkshell:6)
Block(-1,23,2,dynamictrees:trunkshell:7)
Block(-1,24,0,dynamictrees:trunkshell:5)
Block(-1,24,1,dynamictrees:trunkshell:6)
Block(-1,24,2,dynamictrees:trunkshell:7)
Block(-1,25,0,dynamictrees:trunkshell:5)
Block(-1,25,1,dynamictrees:trunkshell:6)
Block(-1,25,2,dynamictrees:trunkshell:7)
Block(-1,26,5,dynamictrees:leaves0:12)
Block(-1,27,5,dynamictrees:leaves0:13)
Block(-1,28,5,dynamictrees:leaves0:12)
Block(-1,29,5,dynamictrees:leaves0:12)
Block(-1,30,-6,dynamictrees:leaves0:12)
Block(-1,30,-5,dynamictrees:leaves0:13)
Block(-1,30,-4,dynamictrees:leaves0:14)
Block(-1,30,-2,dynamictrees:leaves0:12)
Block(-1,30,-1,dynamictrees:leaves0:13)
Block(-1,30,2,dynamictrees:leaves0:12)
Block(-1,30,4,dynamictrees:leaves0:12)
Block(-1,30,5,dynamictrees:leaves0:13)
Block(-1,30,6,dynamictrees:leaves0:14)
Block(-1,30,7,dynamictrees:leaves0:13)
Block(-1,30,8,dynamictrees:leaves0:12)
Block(-1,31,-6,dynamictrees:leaves0:12)
Block(-1,31,-5,dynamictrees:leaves0:14)
Block(-1,31,-4,dynamictrees:leaves0:15)
Block(-1,31,-3,dynamictrees:leaves0:14)
Block(-1,31,-2,dynamictrees:junglebranch:1)
Block(-1,31,-1,dynamictrees:leaves0:14)
Block(-1,31,0,dynamictrees:leaves0:15)
Block(-1,31,1,dynamictrees:junglebranch:2)
Block(-1,31,2,dynamictrees:leaves0:15)
Block(-1,31,3,dynamictrees:junglebranch)
Block(-1,31,4,dynamictrees:leaves0:15)
Block(-1,31,5,dynamictrees:leaves0:14)
Block(-1,31,6,dynamictrees:leaves0:15)
Block(-1,31,7,dynamictrees:leaves0:14)
Block(-1,31,8,dynamictrees:leaves0:12)
Block(-1,32,-6,dynamictrees:leaves0:12)
Block(-1,32,-5,dynamictrees:leaves0:13)
Block(-1,32,-4,dynamictrees:leaves0:14)
Block(-1,32,-3,dynamictrees:leaves0:15)
Block(-1,32,-2,dynamictrees:leaves0:14)
Block(-1,32,-1,dynamictrees:junglebranch:1)
Block(-1,32,0,dynamictrees:junglebranch)
Block(-1,32,1,dynamictrees:leaves0:15)
Block(-1,32,2,dynamictrees:leaves0:15)
Block(-1,32,3,dynamictrees:leaves0:15)
Block(-1,32,4,dynamictrees:leaves0:14)
Block(-1,32,5,dynamictrees:leaves0:15)
Block(-1,32,6,dynamictrees:leaves0:14)
Block(-1,32,7,dynamictrees:leaves0:13)
Block(-1,32,8,dynamictrees:leaves0:12)
Block(-1,33,-5,dynamictrees:leaves0:12)
Block(-1,33,-4,dynamictrees:leaves0:12)
Block(-1,33,-3,dynamictrees:leaves0:14)
Block(-1,33,-2,dynamictrees:leaves0:12)
Block(-1,33,-1,dynamictrees:leaves0:12)
Block(-1,33,0,dynamictrees:leaves0:12)
Block(-1,33,1,dynamictrees:leaves0:15)
Block(-1,33,2,dynamictrees:junglebranch)
Block(-1,33,3,dynamictrees:leaves0:12)
Block(-1,33,4,dynamictrees:leaves0:12)
Block(-1,33,5,dynamictrees:leaves0:12)
Block(-1,33,6,dynamictrees:leaves0:12)
Block(-1,33,7,dynamictrees:leaves0:12)
Block(-1,34,-3,dynamictrees:leaves0:12)
Block(-1,34,0,dynamictrees:leaves0:15)
Block(-1,34,1,dynamictrees:junglebranch)
Block(0,0,0,GRASS:0)
Block(0,0,1,dynamictrees:rootydirtspecies:0,DT_Jungle_THuge_34/1-species_tile_entity.nbt)
Block(0,0,2,GRASS:0)
Block(0,0,4,dynamictrees:jungleroot:1)
Block(0,1,0,dynamictrees:jungleroot:5)
Block(0,1,1,dynamictrees:junglebranchx)
Block(0,1,2,dynamictrees:jungleroot:5)
Block(0,2,0,dynamictrees:trunkshell)
Block(0,2,1,dynamictrees:junglebranch:15)
Block(0,2,2,dynamictrees:trunkshell:0)
Block(0,3,0,dynamictrees:trunkshell)
Block(0,3,1,dynamictrees:junglebranch:14)
Block(0,3,2,dynamictrees:trunkshell:0)
Block(0,4,0,dynamictrees:trunkshell)
Block(0,4,1,dynamictrees:junglebranch:14)
Block(0,4,2,dynamictrees:trunkshell:0)
Block(0,5,0,dynamictrees:trunkshell)
Block(0,5,1,dynamictrees:junglebranch:14)
Block(0,5,2,dynamictrees:trunkshell:0)
Block(0,6,0,dynamictrees:trunkshell)
Block(0,6,1,dynamictrees:junglebranch:14)
Block(0,6,2,dynamictrees:trunkshell:0)
Block(0,7,-4,dynamictrees:leaves0:12)
Block(0,7,0,dynamictrees:trunkshell)
Block(0,7,1,dynamictrees:junglebranch:14)
Block(0,7,2,dynamictrees:trunkshell:0)
Block(0,8,-4,dynamictrees:leaves0:12)
Block(0,8,-2,dynamictrees:leaves0:12)
Block(0,8,-1,dynamictrees:junglebranch:1)
Block(0,8,0,dynamictrees:trunkshell)
Block(0,8,1,dynamictrees:junglebranch:13)
Block(0,8,2,dynamictrees:trunkshell:0)
Block(0,9,-4,dynamictrees:leaves0:12)
Block(0,9,0,dynamictrees:trunkshell)
Block(0,9,1,dynamictrees:junglebranch:13)
Block(0,9,2,dynamictrees:trunkshell:0)
Block(0,10,0,dynamictrees:trunkshell)
Block(0,10,1,dynamictrees:junglebranch:12)
Block(0,10,2,dynamictrees:trunkshell:0)
Block(0,11,0,dynamictrees:trunkshell)
Block(0,11,1,dynamictrees:junglebranch:12)
Block(0,12,0,dynamictrees:trunkshell)
Block(0,12,1,dynamictrees:junglebranch:12)
Block(0,12,2,dynamictrees:trunkshell:0)
Block(0,13,0,dynamictrees:trunkshell)
Block(0,13,1,dynamictrees:junglebranch:12)
Block(0,13,2,dynamictrees:trunkshell:0)
Block(0,14,0,dynamictrees:trunkshell)
Block(0,14,1,dynamictrees:junglebranch:12)
Block(0,14,2,dynamictrees:trunkshell:0)
Block(0,15,0,dynamictrees:trunkshell)
Block(0,15,1,dynamictrees:junglebranch:11)
Block(0,15,2,dynamictrees:trunkshell:0)
Block(0,16,0,dynamictrees:trunkshell)
Block(0,16,1,dynamictrees:junglebranch:11)
Block(0,16,2,dynamictrees:trunkshell:0)
Block(0,17,0,dynamictrees:trunkshell)
Block(0,17,1,dynamictrees:junglebranch:10)
Block(0,17,2,dynamictrees:trunkshell:0)
Block(0,18,0,dynamictrees:trunkshell)
Block(0,18,1,dynamictrees:junglebranch:10)
Block(0,18,2,dynamictrees:trunkshell:0)
Block(0,19,0,dynamictrees:trunkshell)
Block(0,19,1,dynamictrees:junglebranch:10)
Block(0,19,2,dynamictrees:trunkshell:0)
Block(0,20,1,dynamictrees:junglebranch:9)
Block(0,20,2,dynamictrees:trunkshell:0)
Block(0,21,0,dynamictrees:trunkshell)
Block(0,21,1,dynamictrees:junglebranch:9)
Block(0,21,2,dynamictrees:trunkshell:0)
Block(0,22,0,dynamictrees:trunkshell)
Block(0,22,1,dynamictrees:junglebranch:9)
Block(0,22,2,dynamictrees:trunkshell:0)
Block(0,23,0,dynamictrees:trunkshell)
Block(0,23,1,dynamictrees:junglebranch:9)
Block(0,23,2,dynamictrees:trunkshell:0)
Block(0,24,0,dynamictrees:trunkshell)
Block(0,24,1,dynamictrees:junglebranch:8)
Block(0,24,2,dynamictrees:trunkshell:0)
Block(0,25,0,dynamictrees:trunkshell)
Block(0,25,1,dynamictrees:junglebranch:8)
Block(0,25,2,dynamictrees:trunkshell:0)
Block(0,26,1,dynamictrees:junglebranch:7)
Block(0,26,2,dynamictrees:junglebranch:1)
Block(0,26,3,dynamictrees:junglebranch:1)
Block(0,26,4,dynamictrees:junglebranch:1)
Block(0,26,5,dynamictrees:junglebranch:1)
Block(0,26,6,dynamictrees:junglebranch)
Block(0,27,1,dynamictrees:junglebranch:7)
Block(0,27,4,dynamictrees:leaves0:12)
Block(0,27,5,dynamictrees:leaves0:14)
Block(0,27,6,dynamictrees:leaves0:15)
Block(0,27,7,dynamictrees:leaves0:12)
Block(0,28,1,dynamictrees:junglebranch:7)
Block(0,28,5,dynamictrees:leaves0:12)
Block(0,28,6,dynamictrees:leaves0:12)
Block(0,29,1,dynamictrees:junglebranch:7)
Block(0,29,6,dynamictrees:leaves0:12)
Block(0,30,-6,dynamictrees:leaves0:12)
Block(0,30,-5,dynamictrees:leaves0:14)
Block(0,30,-4,dynamictrees:leaves0:15)
Block(0,30,1,dynamictrees:junglebranch:7)
Block(0,30,5,dynamictrees:leaves0:12)
Block(0,30,6,dynamictrees:leaves0:15)
Block(0,30,7,dynamictrees:leaves0:14)
Block(0,30,8,dynamictrees:leaves0:12)
Block(0,31,-6,dynamictrees:leaves0:12)
Block(0,31,-5,dynamictrees:leaves0:15)
Block(0,31,-4,dynamictrees:junglebranch)
Block(0,31,-3,dynamictrees:junglebranch:1)
Block(0,31,-2,dynamictrees:junglebranch:2)
Block(0,31,-1,dynamictrees:junglebranch:3)
Block(0,31,0,dynamictrees:junglebranch:3)
Block(0,31,1,dynamictrees:junglebranch:6)
Block(0,31,2,dynamictrees:junglebranch:2)
Block(0,31,3,dynamictrees:junglebranch:2)
Block(0,31,4,dynamictrees:junglebranch:1)
Block(0,31,5,dynamictrees:junglebranch:1)
Block(0,31,6,dynamictrees:junglebranch)
Block(0,31,7,dynamictrees:leaves0:15)
Block(0,31,8,dynamictrees:leaves0:12)
Block(0,32,-6,dynamictrees:leaves0:12)
Block(0,32,-5,dynamictrees:leaves0:14)
Block(0,32,-4,dynamictrees:leaves0:15)
Block(0,32,-3,dynamictrees:junglebranch)
Block(0,32,-2,dynamictrees:leaves0:15)
Block(0,32,-1,dynamictrees:junglebranch:2)
Block(0,32,0,dynamictrees:leaves0:15)
Block(0,32,1,dynamictrees:junglebranch:2)
Block(0,32,2,dynamictrees:leaves0:15)
Block(0,32,3,dynamictrees:junglebranch)
Block(0,32,4,dynamictrees:leaves0:15)
Block(0,32,5,dynamictrees:junglebranch)
Block(0,32,6,dynamictrees:leaves0:15)
Block(0,32,7,dynamictrees:leaves0:14)
Block(0,32,8,dynamictrees:leaves0:12)
Block(0,33,-6,dynamictrees:leaves0:12)
Block(0,33,-5,dynamictrees:leaves0:13)
Block(0,33,-4,dynamictrees:leaves0:14)
Block(0,33,-3,dynamictrees:leaves0:15)
Block(0,33,-2,dynamictrees:junglebranch)
Block(0,33,-1,dynamictrees:junglebranch:1)
Block(0,33,0,dynamictrees:leaves0:14)
Block(0,33,1,dynamictrees:junglebranch:2)
Block(0,33,2,dynamictrees:junglebranch:1)
Block(0,33,3,dynamictrees:leaves0:12)
Block(0,33,4,dynamictrees:leaves0:12)
Block(0,33,5,dynamictrees:leaves0:12)
Block(0,33,6,dynamictrees:leaves0:12)
Block(0,33,7,dynamictrees:leaves0:12)
Block(0,34,-5,dynamictrees:leaves0:12)
Block(0,34,-4,dynamictrees:leaves0:12)
Block(0,34,-3,dynamictrees:leaves0:12)
Block(0,34,-2,dynamictrees:leaves0:15)
Block(0,34,-1,dynamictrees:junglebranch)
Block(0,34,0,dynamictrees:leaves0:15)
Block(0,34,1,dynamictrees:junglebranch:1)
Block(0,34,2,dynamictrees:leaves0:15)
Block(0,35,-1,dynamictrees:leaves0:15)
Block(0,35,0,dynamictrees:leaves0:14)
Block(0,35,1,dynamictrees:leaves0:12)
Block(1,0,0,GRASS:0)
Block(1,0,1,GRASS:0)
Block(1,0,2,GRASS:0)
Block(1,0,3,dynamictrees:jungleroot:3)
Block(1,0,4,dynamictrees:jungleroot:2)
Block(1,1,0,dynamictrees:trunkshell:3)
Block(1,1,1,dynamictrees:trunkshell:2)
Block(1,1,2,dynamictrees:jungleroot:4)
Block(1,2,0,dynamictrees:trunkshell:3)
Block(1,2,1,dynamictrees:trunkshell:2)
Block(1,2,2,dynamictrees:trunkshell:1)
Block(1,3,0,dynamictrees:trunkshell:3)
Block(1,3,1,dynamictrees:trunkshell:2)
Block(1,3,2,dynamictrees:trunkshell:1)
Block(1,4,0,dynamictrees:trunkshell:3)
Block(1,4,1,dynamictrees:trunkshell:2)
Block(1,4,2,dynamictrees:trunkshell:1)
Block(1,5,0,dynamictrees:trunkshell:3)
Block(1,5,1,dynamictrees:trunkshell:2)
Block(1,5,2,dynamictrees:trunkshell:1)
Block(1,6,0,dynamictrees:trunkshell:3)
Block(1,6,1,dynamictrees:trunkshell:2)
Block(1,6,2,dynamictrees:trunkshell:1)
Block(1,7,-2,dynamictrees:leaves0:12)
Block(1,7,0,dynamictrees:trunkshell:3)
Block(1,7,1,dynamictrees:trunkshell:2)
Block(1,7,2,dynamictrees:trunkshell:1)
Block(1,8,-3,dynamictrees:leaves0:12)
Block(1,8,-2,dynamictrees:leaves0:15)
Block(1,8,-1,dynamictrees:junglebranch)
Block(1,8,0,dynamictrees:trunkshell:3)
Block(1,8,1,dynamictrees:trunkshell:2)
Block(1,8,2,dynamictrees:trunkshell:1)
Block(1,9,-2,dynamictrees:leaves0:12)
Block(1,9,0,dynamictrees:trunkshell:3)
Block(1,9,1,dynamictrees:trunkshell:2)
Block(1,9,2,dynamictrees:trunkshell:1)
Block(1,10,0,dynamictrees:trunkshell:3)
Block(1,10,1,dynamictrees:trunkshell:2)
Block(1,10,2,dynamictrees:trunkshell:1)
Block(1,11,0,dynamictrees:trunkshell:3)
Block(1,11,1,dynamictrees:trunkshell:2)
Block(1,11,2,dynamictrees:trunkshell:1)
Block(1,12,0,dynamictrees:trunkshell:3)
Block(1,12,1,dynamictrees:trunkshell:2)
Block(1,12,2,dynamictrees:trunkshell:1)
Block(1,13,0,dynamictrees:trunkshell:3)
Block(1,13,1,dynamictrees:trunkshell:2)
Block(1,13,2,dynamictrees:trunkshell:1)
Block(1,14,2,dynamictrees:trunkshell:1)
Block(1,15,0,dynamictrees:trunkshell:3)
Block(1,15,1,dynamictrees:trunkshell:2)
Block(1,15,2,dynamictrees:trunkshell:1)
Block(1,16,0,dynamictrees:trunkshell:3)
Block(1,16,1,dynamictrees:trunkshell:2)
Block(1,16,2,dynamictrees:trunkshell:1)
Block(1,17,0,dynamictrees:trunkshell:3)
Block(1,17,1,dynamictrees:trunkshell:2)
Block(1,17,2,dynamictrees:trunkshell:1)
Block(1,18,0,dynamictrees:trunkshell:3)
Block(1,18,1,dynamictrees:trunkshell:2)
Block(1,18,2,dynamictrees:trunkshell:1)
Block(1,19,0,dynamictrees:trunkshell:3)
Block(1,19,1,dynamictrees:trunkshell:2)
Block(1,19,2,dynamictrees:trunkshell:1)
Block(1,20,1,dynamictrees:trunkshell:2)
Block(1,20,2,dynamictrees:trunkshell:1)
Block(1,21,0,dynamictrees:trunkshell:3)
Block(1,21,1,dynamictrees:trunkshell:2)
Block(1,21,2,dynamictrees:trunkshell:1)
Block(1,22,0,dynamictrees:trunkshell:3)
Block(1,22,1,dynamictrees:trunkshell:2)
Block(1,22,2,dynamictrees:trunkshell:1)
Block(1,23,2,dynamictrees:trunkshell:1)
Block(1,24,0,dynamictrees:trunkshell:3)
Block(1,24,1,dynamictrees:trunkshell:2)
Block(1,24,2,dynamictrees:trunkshell:1)
Block(1,25,0,dynamictrees:trunkshell:3)
Block(1,25,1,dynamictrees:trunkshell:2)
Block(1,25,2,dynamictrees:trunkshell:1)
Block(1,26,5,dynamictrees:junglebranch)
Block(1,27,5,dynamictrees:leaves0:15)
Block(1,27,6,dynamictrees:leaves0:14)
Block(1,28,5,dynamictrees:leaves0:12)
Block(1,29,5,dynamictrees:leaves0:12)
Block(1,30,-6,dynamictrees:leaves0:12)
Block(1,30,-5,dynamictrees:leaves0:13)
Block(1,30,-4,dynamictrees:leaves0:14)
Block(1,30,-3,dynamictrees:leaves0:13)
Block(1,30,-2,dynamictrees:leaves0:14)
Block(1,30,-1,dynamictrees:leaves0:15)
Block(1,30,5,dynamictrees:leaves0:13)
Block(1,30,6,dynamictrees:leaves0:14)
Block(1,30,7,dynamictrees:leaves0:13)
Block(1,30,8,dynamictrees:leaves0:12)
Block(1,31,-6,dynamictrees:leaves0:12)
Block(1,31,-5,dynamictrees:leaves0:14)
Block(1,31,-4,dynamictrees:leaves0:15)
Block(1,31,-3,dynamictrees:leaves0:14)
Block(1,31,-2,dynamictrees:leaves0:15)
Block(1,31,-1,dynamictrees:junglebranch)
Block(1,31,0,dynamictrees:leaves0:15)
Block(1,31,1,dynamictrees:junglebranch:2)
Block(1,31,2,dynamictrees:leaves0:15)
Block(1,31,3,dynamictrees:junglebranch:1)
Block(1,31,4,dynamictrees:leaves0:13)
Block(1,31,5,dynamictrees:leaves0:14)
Block(1,31,6,dynamictrees:leaves0:15)
Block(1,31,7,dynamictrees:leaves0:14)
Block(1,31,8,dynamictrees:leaves0:12)
Block(1,32,-6,dynamictrees:leaves0:12)
Block(1,32,-5,dynamictrees:leaves0:13)
Block(1,32,-4,dynamictrees:leaves0:14)
Block(1,32,-3,dynamictrees:leaves0:15)
Block(1,32,-2,dynamictrees:leaves0:14)
Block(1,32,-1,dynamictrees:leaves0:15)
Block(1,32,0,dynamictrees:leaves0:14)
Block(1,32,1,dynamictrees:leaves0:15)
Block(1,32,2,dynamictrees:junglebranch)
Block(1,32,3,dynamictrees:leaves0:15)
Block(1,32,4,dynamictrees:leaves0:14)
Block(1,32,5,dynamictrees:leaves0:15)
Block(1,32,6,dynamictrees:leaves0:14)
Block(1,32,7,dynamictrees:leaves0:13)
Block(1,32,8,dynamictrees:leaves0:12)
Block(1,33,-5,dynamictrees:leaves0:12)
Block(1,33,-4,dynamictrees:leaves0:12)
Block(1,33,-3,dynamictrees:leaves0:12)
Block(1,33,-2,dynamictrees:leaves0:12)
Block(1,33,-1,dynamictrees:junglebranch)
Block(1,33,0,dynamictrees:leaves0:15)
Block(1,33,1,dynamictrees:junglebranch)
Block(1,33,2,dynamictrees:leaves0:12)
Block(1,33,3,dynamictrees:leaves0:12)
Block(1,33,4,dynamictrees:leaves0:12)
Block(1,33,5,dynamictrees:leaves0:12)
Block(1,33,6,dynamictrees:leaves0:12)
Block(1,33,7,dynamictrees:leaves0:12)
Block(1,34,0,dynamictrees:leaves0:14)
Block(1,34,1,dynamictrees:leaves0:15)
Block(1,35,1,dynamictrees:leaves0:12)
Block(2,0,4,dynamictrees:jungleroot)
Block(2,7,-2,dynamictrees:leaves0:12)
Block(2,7,-1,dynamictrees:leaves0:12)
Block(2,8,-3,dynamictrees:leaves0:12)
Block(2,8,-2,dynamictrees:leaves0:14)
Block(2,8,-1,dynamictrees:leaves0:15)
Block(2,9,-2,dynamictrees:leaves0:12)
Block(2,9,-1,dynamictrees:leaves0:12)
Block(2,25,5,dynamictrees:leaves0:12)
Block(2,26,4,dynamictrees:leaves0:12)
Block(2,26,5,dynamictrees:leaves0:15)
Block(2,26,6,dynamictrees:leaves0:12)
Block(2,27,4,dynamictrees:leaves0:12)
Block(2,27,5,dynamictrees:leaves0:14)
Block(2,27,6,dynamictrees:leaves0:12)
Block(2,28,5,dynamictrees:leaves0:12)
Block(2,30,-5,dynamictrees:leaves0:12)
Block(2,30,-4,dynamictrees:leaves0:12)
Block(2,30,-3,dynamictrees:leaves0:12)
Block(2,30,-2,dynamictrees:leaves0:13)
Block(2,30,-1,dynamictrees:leaves0:14)
Block(2,30,0,dynamictrees:leaves0:15)
Block(2,30,1,dynamictrees:leaves0:12)
Block(2,30,2,dynamictrees:leaves0:13)
Block(2,30,3,dynamictrees:leaves0:12)
Block(2,30,4,dynamictrees:leaves0:12)
Block(2,30,5,dynamictrees:leaves0:12)
Block(2,30,6,dynamictrees:leaves0:12)
Block(2,30,7,dynamictrees:leaves0:12)
Block(2,31,-5,dynamictrees:leaves0:12)
Block(2,31,-4,dynamictrees:leaves0:12)
Block(2,31,-3,dynamictrees:leaves0:13)
Block(2,31,-2,dynamictrees:leaves0:14)
Block(2,31,-1,dynamictrees:leaves0:15)
Block(2,31,0,dynamictrees:junglebranch)
Block(2,31,1,dynamictrees:junglebranch:2)
Block(2,31,2,dynamictrees:leaves0:14)
Block(2,31,3,dynamictrees:junglebranch:1)
Block(2,31,4,dynamictrees:leaves0:12)
Block(2,31,5,dynamictrees:leaves0:12)
Block(2,31,6,dynamictrees:leaves0:12)
Block(2,31,7,dynamictrees:leaves0:12)
Block(2,32,-5,dynamictrees:leaves0:12)
Block(2,32,-4,dynamictrees:leaves0:12)
Block(2,32,-3,dynamictrees:leaves0:12)
Block(2,32,-2,dynamictrees:leaves0:13)
Block(2,32,-1,dynamictrees:leaves0:14)
Block(2,32,0,dynamictrees:leaves0:15)
Block(2,32,1,dynamictrees:junglebranch:1)
Block(2,32,2,dynamictrees:junglebranch:1)
Block(2,32,3,dynamictrees:leaves0:14)
Block(2,32,4,dynamictrees:leaves0:13)
Block(2,32,5,dynamictrees:leaves0:12)
Block(2,32,6,dynamictrees:leaves0:12)
Block(2,32,7,dynamictrees:leaves0:12)
Block(2,33,-2,dynamictrees:leaves0:12)
Block(2,33,-1,dynamictrees:leaves0:12)
Block(2,33,0,dynamictrees:leaves0:12)
Block(2,33,1,dynamictrees:leaves0:12)
Block(2,33,2,dynamictrees:leaves0:12)
Block(2,33,3,dynamictrees:leaves0:12)
Block(2,33,4,dynamictrees:leaves0:12)
Block(3,8,-2,dynamictrees:leaves0:12)
Block(3,8,-1,dynamictrees:leaves0:12)
Block(3,26,5,dynamictrees:leaves0:12)
Block(3,27,5,dynamictrees:leaves0:12)
Block(3,30,-2,dynamictrees:leaves0:12)
Block(3,30,-1,dynamictrees:leaves0:13)
Block(3,30,0,dynamictrees:leaves0:14)
Block(3,30,1,dynamictrees:leaves0:13)
Block(3,30,2,dynamictrees:leaves0:14)
Block(3,30,3,dynamictrees:leaves0:15)
Block(3,30,4,dynamictrees:leaves0:14)
Block(3,30,5,dynamictrees:leaves0:12)
Block(3,31,-3,dynamictrees:leaves0:12)
Block(3,31,-2,dynamictrees:leaves0:13)
Block(3,31,-1,dynamictrees:leaves0:14)
Block(3,31,0,dynamictrees:leaves0:15)
Block(3,31,1,dynamictrees:junglebranch:1)
Block(3,31,2,dynamictrees:leaves0:15)
Block(3,31,3,dynamictrees:junglebranch)
Block(3,31,4,dynamictrees:leaves0:15)
Block(3,31,5,dynamictrees:leaves0:12)
Block(3,32,-2,dynamictrees:leaves0:12)
Block(3,32,-1,dynamictrees:leaves0:13)
Block(3,32,0,dynamictrees:leaves0:14)
Block(3,32,1,dynamictrees:leaves0:13)
Block(3,32,2,dynamictrees:leaves0:14)
Block(3,32,3,dynamictrees:leaves0:15)
Block(3,32,4,dynamictrees:leaves0:14)
Block(3,32,5,dynamictrees:leaves0:12)
Block(3,33,-1,dynamictrees:leaves0:12)
Block(3,33,0,dynamictrees:leaves0:12)
Block(3,33,1,dynamictrees:leaves0:12)
Block(3,33,2,dynamictrees:leaves0:12)
Block(3,33,3,dynamictrees:leaves0:12)
Block(3,33,4,dynamictrees:leaves0:12)
Block(4,30,-1,dynamictrees:leaves0:12)
Block(4,30,0,dynamictrees:leaves0:13)
Block(4,30,1,dynamictrees:leaves0:12)
Block(4,30,2,dynamictrees:leaves0:13)
Block(4,30,3,dynamictrees:leaves0:14)
Block(4,30,4,dynamictrees:leaves0:13)
Block(4,30,5,dynamictrees:leaves0:12)
Block(4,31,-2,dynamictrees:leaves0:12)
Block(4,31,-1,dynamictrees:leaves0:13)
Block(4,31,0,dynamictrees:leaves0:14)
Block(4,31,1,dynamictrees:junglebranch:1)
Block(4,31,2,dynamictrees:leaves0:14)
Block(4,31,3,dynamictrees:leaves0:15)
Block(4,31,4,dynamictrees:leaves0:14)
Block(4,31,5,dynamictrees:leaves0:12)
Block(4,32,-1,dynamictrees:leaves0:12)
Block(4,32,0,dynamictrees:leaves0:13)
Block(4,32,1,dynamictrees:leaves0:12)
Block(4,32,2,dynamictrees:leaves0:13)
Block(4,32,3,dynamictrees:leaves0:14)
Block(4,32,4,dynamictrees:leaves0:13)
Block(4,32,5,dynamictrees:leaves0:12)
Block(4,33,0,dynamictrees:leaves0:12)
Block(4,33,1,dynamictrees:leaves0:12)
Block(4,33,2,dynamictrees:leaves0:12)
Block(4,33,3,dynamictrees:leaves0:12)
Block(4,33,4,dynamictrees:leaves0:12)
Block(5,30,-1,dynamictrees:leaves0:12)
Block(5,30,0,dynamictrees:leaves0:14)
Block(5,30,1,dynamictrees:leaves0:15)
Block(5,30,2,dynamictrees:leaves0:14)
Block(5,30,3,dynamictrees:leaves0:13)
Block(5,30,4,dynamictrees:leaves0:12)
Block(5,31,-1,dynamictrees:leaves0:12)
Block(5,31,0,dynamictrees:leaves0:15)
Block(5,31,1,dynamictrees:junglebranch)
Block(5,31,2,dynamictrees:leaves0:15)
Block(5,31,3,dynamictrees:leaves0:14)
Block(5,31,4,dynamictrees:leaves0:13)
Block(5,31,5,dynamictrees:leaves0:12)
Block(5,32,-1,dynamictrees:leaves0:12)
Block(5,32,0,dynamictrees:leaves0:14)
Block(5,32,1,dynamictrees:leaves0:15)
Block(5,32,2,dynamictrees:leaves0:14)
Block(5,32,3,dynamictrees:leaves0:13)
Block(5,32,4,dynamictrees:leaves0:12)
Block(5,33,0,dynamictrees:leaves0:12)
Block(5,33,1,dynamictrees:leaves0:12)
Block(5,33,2,dynamictrees:leaves0:12)
Block(5,33,3,dynamictrees:leaves0:12)
Block(6,30,-1,dynamictrees:leaves0:12)
Block(6,30,0,dynamictrees:leaves0:13)
Block(6,30,1,dynamictrees:leaves0:14)
Block(6,30,2,dynamictrees:leaves0:13)
Block(6,30,3,dynamictrees:leaves0:12)
Block(6,31,-1,dynamictrees:leaves0:12)
Block(6,31,0,dynamictrees:leaves0:14)
Block(6,31,1,dynamictrees:leaves0:15)
Block(6,31,2,dynamictrees:leaves0:14)
Block(6,31,3,dynamictrees:leaves0:13)
Block(6,31,4,dynamictrees:leaves0:12)
Block(6,32,-1,dynamictrees:leaves0:12)
Block(6,32,0,dynamictrees:leaves0:13)
Block(6,32,1,dynamictrees:leaves0:14)
Block(6,32,2,dynamictrees:leaves0:13)
Block(6,32,3,dynamictrees:leaves0:12)
Block(6,33,0,dynamictrees:leaves0:12)
Block(6,33,1,dynamictrees:leaves0:12)
Block(6,33,2,dynamictrees:leaves0:12)
Block(7,30,0,dynamictrees:leaves0:12)
Block(7,30,1,dynamictrees:leaves0:12)
Block(7,30,2,dynamictrees:leaves0:12)
Block(7,31,0,dynamictrees:leaves0:12)
Block(7,31,1,dynamictrees:leaves0:12)
Block(7,31,2,dynamictrees:leaves0:12)
Block(7,31,3,dynamictrees:leaves0:12)
Block(7,32,0,dynamictrees:leaves0:12)
Block(7,32,1,dynamictrees:leaves0:12)
Block(7,32,2,dynamictrees:leaves0:12)

#######################################################################
# +-----------------------------------------------------------------+ #
# |                            BO3 checks                           | #
# +-----------------------------------------------------------------+ #
#######################################################################

BlockCheck(0,-1,1,GRASS,DIRT,biomesoplenty:grass,biomesoplenty:dirt)

#######################################################################
# +-----------------------------------------------------------------+ #
# |                             Branches                            | #
# +-----------------------------------------------------------------+ #
#######################################################################


#######################################################################
# +-----------------------------------------------------------------+ #
# |                             Entities                            | #
# +-----------------------------------------------------------------+ #
#######################################################################


#######################################################################
# +-----------------------------------------------------------------+ #
# |                            Particles                            | #
# +-----------------------------------------------------------------+ #
#######################################################################


#######################################################################
# +-----------------------------------------------------------------+ #
# |                             Spawners                            | #
# +-----------------------------------------------------------------+ #
#######################################################################


#######################################################################
# +-----------------------------------------------------------------+ #
# |                             ModData                             | #
# +-----------------------------------------------------------------+ #
#######################################################################

