
#######################################################################
# +-----------------------------------------------------------------+ #
# |                            BO3 object                           | #
# +-----------------------------------------------------------------+ #
#######################################################################

Author: NLBlackHeavenNL

Description: No description given

Version: 3

SettingsMode: WriteWithoutComments


#######################################################################
# +-----------------------------------------------------------------+ #
# |                          Main settings                          | #
# +-----------------------------------------------------------------+ #
#######################################################################

Tree: true

Frequency: 1

Rarity: 100.0

RotateRandomly: false

SpawnHeight: highestSolidBlock

SpawnHeightOffset: -1

SpawnHeightVariance: 0

##############################
# Height Limits for the BO3. #
##############################

MinHeight: 0

MaxHeight: 255

######################
# Extrusion settings #
######################

ExtrudeMode: None

ExtrudeThroughBlocks: AIR

MaxBranchDepth: 10

ExcludedBiomes: All


#######################################################################
# +-----------------------------------------------------------------+ #
# |                      Source block settings                      | #
# +-----------------------------------------------------------------+ #
#######################################################################

SourceBlocks: AIR,GRASS,DIRT,biomesoplenty:dirt

MaxPercentageOutsideSourceBlock: 0

OutsideSourceBlock: placeAnyway

DoReplaceBlocks: true

IsOTGPlus: false


#######################################################################
# +-----------------------------------------------------------------+ #
# |                              Blocks                             | #
# +-----------------------------------------------------------------+ #
#######################################################################

Block(-7,16,0,dynamictrees:leaves0:12)
Block(-7,16,1,dynamictrees:leaves0:12)
Block(-7,16,2,dynamictrees:leaves0:12)
Block(-7,17,-1,dynamictrees:leaves0:12)
Block(-7,17,0,dynamictrees:leaves0:12)
Block(-7,17,1,dynamictrees:leaves0:12)
Block(-7,17,2,dynamictrees:leaves0:12)
Block(-7,18,0,dynamictrees:leaves0:12)
Block(-7,18,1,dynamictrees:leaves0:12)
Block(-7,18,2,dynamictrees:leaves0:12)
Block(-6,16,-1,dynamictrees:leaves0:12)
Block(-6,16,0,dynamictrees:leaves0:13)
Block(-6,16,1,dynamictrees:leaves0:14)
Block(-6,16,2,dynamictrees:leaves0:13)
Block(-6,16,3,dynamictrees:leaves0:12)
Block(-6,17,-2,dynamictrees:leaves0:12)
Block(-6,17,-1,dynamictrees:leaves0:13)
Block(-6,17,0,dynamictrees:leaves0:14)
Block(-6,17,1,dynamictrees:leaves0:15)
Block(-6,17,2,dynamictrees:leaves0:14)
Block(-6,17,3,dynamictrees:leaves0:12)
Block(-6,18,-1,dynamictrees:leaves0:12)
Block(-6,18,0,dynamictrees:leaves0:13)
Block(-6,18,1,dynamictrees:leaves0:14)
Block(-6,18,2,dynamictrees:leaves0:13)
Block(-6,18,3,dynamictrees:leaves0:12)
Block(-6,19,0,dynamictrees:leaves0:12)
Block(-6,19,1,dynamictrees:leaves0:12)
Block(-6,19,2,dynamictrees:leaves0:12)
Block(-6,30,0,dynamictrees:leaves0:12)
Block(-6,30,1,dynamictrees:leaves0:12)
Block(-6,30,2,dynamictrees:leaves0:12)
Block(-6,31,0,dynamictrees:leaves0:12)
Block(-6,31,1,dynamictrees:leaves0:12)
Block(-6,31,2,dynamictrees:leaves0:12)
Block(-6,31,3,dynamictrees:leaves0:12)
Block(-6,32,0,dynamictrees:leaves0:12)
Block(-6,32,1,dynamictrees:leaves0:12)
Block(-6,32,2,dynamictrees:leaves0:12)
Block(-5,16,-2,dynamictrees:leaves0:12)
Block(-5,16,-1,dynamictrees:leaves0:13)
Block(-5,16,0,dynamictrees:leaves0:14)
Block(-5,16,1,dynamictrees:leaves0:15)
Block(-5,16,2,dynamictrees:leaves0:14)
Block(-5,16,3,dynamictrees:leaves0:12)
Block(-5,17,-2,dynamictrees:leaves0:12)
Block(-5,17,-1,dynamictrees:leaves0:14)
Block(-5,17,0,dynamictrees:leaves0:15)
Block(-5,17,1,dynamictrees:junglebranch)
Block(-5,17,2,dynamictrees:leaves0:15)
Block(-5,17,3,dynamictrees:leaves0:12)
Block(-5,18,-2,dynamictrees:leaves0:12)
Block(-5,18,-1,dynamictrees:leaves0:13)
Block(-5,18,0,dynamictrees:leaves0:14)
Block(-5,18,1,dynamictrees:leaves0:15)
Block(-5,18,2,dynamictrees:leaves0:14)
Block(-5,18,3,dynamictrees:leaves0:12)
Block(-5,19,-1,dynamictrees:leaves0:12)
Block(-5,19,0,dynamictrees:leaves0:12)
Block(-5,19,1,dynamictrees:leaves0:12)
Block(-5,19,2,dynamictrees:leaves0:12)
Block(-5,30,-1,dynamictrees:leaves0:12)
Block(-5,30,0,dynamictrees:leaves0:13)
Block(-5,30,1,dynamictrees:leaves0:14)
Block(-5,30,2,dynamictrees:leaves0:13)
Block(-5,30,3,dynamictrees:leaves0:12)
Block(-5,31,-1,dynamictrees:leaves0:12)
Block(-5,31,0,dynamictrees:leaves0:14)
Block(-5,31,1,dynamictrees:leaves0:15)
Block(-5,31,2,dynamictrees:leaves0:14)
Block(-5,31,3,dynamictrees:leaves0:13)
Block(-5,31,4,dynamictrees:leaves0:12)
Block(-5,32,-1,dynamictrees:leaves0:12)
Block(-5,32,0,dynamictrees:leaves0:13)
Block(-5,32,1,dynamictrees:leaves0:14)
Block(-5,32,2,dynamictrees:leaves0:13)
Block(-5,32,3,dynamictrees:leaves0:12)
Block(-5,33,0,dynamictrees:leaves0:12)
Block(-5,33,1,dynamictrees:leaves0:12)
Block(-5,33,2,dynamictrees:leaves0:12)
Block(-4,16,-2,dynamictrees:leaves0:12)
Block(-4,16,-1,dynamictrees:leaves0:14)
Block(-4,16,0,dynamictrees:leaves0:15)
Block(-4,16,1,dynamictrees:leaves0:14)
Block(-4,16,2,dynamictrees:leaves0:13)
Block(-4,16,3,dynamictrees:leaves0:12)
Block(-4,16,4,dynamictrees:leaves0:12)
Block(-4,16,5,dynamictrees:leaves0:12)
Block(-4,17,-2,dynamictrees:leaves0:12)
Block(-4,17,-1,dynamictrees:leaves0:15)
Block(-4,17,0,dynamictrees:junglebranch)
Block(-4,17,1,dynamictrees:junglebranch:1)
Block(-4,17,2,dynamictrees:leaves0:12)
Block(-4,17,4,dynamictrees:leaves0:12)
Block(-4,17,5,dynamictrees:leaves0:12)
Block(-4,18,-2,dynamictrees:leaves0:12)
Block(-4,18,-1,dynamictrees:leaves0:14)
Block(-4,18,0,dynamictrees:leaves0:15)
Block(-4,18,1,dynamictrees:leaves0:14)
Block(-4,18,2,dynamictrees:leaves0:13)
Block(-4,18,3,dynamictrees:leaves0:12)
Block(-4,18,4,dynamictrees:leaves0:12)
Block(-4,18,5,dynamictrees:leaves0:12)
Block(-4,19,-1,dynamictrees:leaves0:12)
Block(-4,19,0,dynamictrees:leaves0:12)
Block(-4,19,1,dynamictrees:leaves0:12)
Block(-4,19,2,dynamictrees:leaves0:12)
Block(-4,30,-1,dynamictrees:leaves0:12)
Block(-4,30,0,dynamictrees:leaves0:14)
Block(-4,30,1,dynamictrees:leaves0:15)
Block(-4,30,2,dynamictrees:leaves0:14)
Block(-4,30,3,dynamictrees:leaves0:12)
Block(-4,30,4,dynamictrees:leaves0:12)
Block(-4,31,-2,dynamictrees:leaves0:12)
Block(-4,31,-1,dynamictrees:leaves0:12)
Block(-4,31,0,dynamictrees:leaves0:15)
Block(-4,31,1,dynamictrees:junglebranch)
Block(-4,31,2,dynamictrees:leaves0:15)
Block(-4,31,3,dynamictrees:leaves0:14)
Block(-4,31,4,dynamictrees:leaves0:13)
Block(-4,31,5,dynamictrees:leaves0:12)
Block(-4,32,-1,dynamictrees:leaves0:12)
Block(-4,32,0,dynamictrees:leaves0:14)
Block(-4,32,1,dynamictrees:leaves0:15)
Block(-4,32,2,dynamictrees:leaves0:14)
Block(-4,32,3,dynamictrees:leaves0:13)
Block(-4,32,4,dynamictrees:leaves0:12)
Block(-4,33,0,dynamictrees:leaves0:12)
Block(-4,33,1,dynamictrees:leaves0:12)
Block(-4,33,2,dynamictrees:leaves0:12)
Block(-4,33,3,dynamictrees:leaves0:12)
Block(-3,16,-2,dynamictrees:leaves0:12)
Block(-3,16,-1,dynamictrees:leaves0:13)
Block(-3,16,0,dynamictrees:leaves0:14)
Block(-3,16,2,dynamictrees:leaves0:12)
Block(-3,16,3,dynamictrees:leaves0:12)
Block(-3,16,4,dynamictrees:leaves0:14)
Block(-3,16,5,dynamictrees:leaves0:13)
Block(-3,16,6,dynamictrees:leaves0:12)
Block(-3,17,-2,dynamictrees:leaves0:12)
Block(-3,17,-1,dynamictrees:leaves0:14)
Block(-3,17,0,dynamictrees:leaves0:15)
Block(-3,17,1,dynamictrees:junglebranch:1)
Block(-3,17,3,dynamictrees:leaves0:12)
Block(-3,17,4,dynamictrees:leaves0:15)
Block(-3,17,5,dynamictrees:leaves0:14)
Block(-3,17,6,dynamictrees:leaves0:12)
Block(-3,18,-2,dynamictrees:leaves0:12)
Block(-3,18,-1,dynamictrees:leaves0:13)
Block(-3,18,0,dynamictrees:leaves0:14)
Block(-3,18,2,dynamictrees:leaves0:12)
Block(-3,18,3,dynamictrees:leaves0:12)
Block(-3,18,4,dynamictrees:leaves0:14)
Block(-3,18,5,dynamictrees:leaves0:13)
Block(-3,18,6,dynamictrees:leaves0:12)
Block(-3,19,-1,dynamictrees:leaves0:12)
Block(-3,19,0,dynamictrees:leaves0:12)
Block(-3,19,4,dynamictrees:leaves0:12)
Block(-3,19,5,dynamictrees:leaves0:12)
Block(-3,20,-5,dynamictrees:leaves0:12)
Block(-3,20,-4,dynamictrees:leaves0:12)
Block(-3,20,-3,dynamictrees:leaves0:12)
Block(-3,21,-4,dynamictrees:leaves0:12)
Block(-3,21,-3,dynamictrees:leaves0:12)
Block(-3,30,-2,dynamictrees:leaves0:12)
Block(-3,30,-1,dynamictrees:leaves0:12)
Block(-3,30,4,dynamictrees:leaves0:12)
Block(-3,31,-3,dynamictrees:leaves0:12)
Block(-3,31,-2,dynamictrees:leaves0:13)
Block(-3,31,-1,dynamictrees:leaves0:14)
Block(-3,31,0,dynamictrees:leaves0:15)
Block(-3,31,1,dynamictrees:junglebranch:1)
Block(-3,31,2,dynamictrees:leaves0:14)
Block(-3,31,3,dynamictrees:leaves0:15)
Block(-3,31,4,dynamictrees:leaves0:14)
Block(-3,31,5,dynamictrees:leaves0:12)
Block(-3,32,-2,dynamictrees:leaves0:12)
Block(-3,32,-1,dynamictrees:leaves0:13)
Block(-3,32,0,dynamictrees:leaves0:14)
Block(-3,32,1,dynamictrees:leaves0:15)
Block(-3,32,2,dynamictrees:leaves0:14)
Block(-3,32,3,dynamictrees:leaves0:14)
Block(-3,32,4,dynamictrees:leaves0:13)
Block(-3,32,5,dynamictrees:leaves0:12)
Block(-3,33,-1,dynamictrees:leaves0:12)
Block(-3,33,0,dynamictrees:leaves0:13)
Block(-3,33,1,dynamictrees:leaves0:14)
Block(-3,33,2,dynamictrees:leaves0:13)
Block(-3,33,3,dynamictrees:leaves0:13)
Block(-3,33,4,dynamictrees:leaves0:12)
Block(-3,34,0,dynamictrees:leaves0:12)
Block(-3,34,1,dynamictrees:leaves0:12)
Block(-3,34,2,dynamictrees:leaves0:12)
Block(-3,34,3,dynamictrees:leaves0:12)
Block(-2,0,-2,dynamictrees:jungleroot:1)
Block(-2,0,-1,dynamictrees:jungleroot:2)
Block(-2,0,1,GRASS:0)
Block(-2,0,3,dynamictrees:jungleroot:1)
Block(-2,0,4,dynamictrees:jungleroot)
Block(-2,1,1,dynamictrees:jungleroot:3)
Block(-2,16,3,dynamictrees:leaves0:12)
Block(-2,16,4,dynamictrees:leaves0:15)
Block(-2,16,5,dynamictrees:leaves0:14)
Block(-2,16,6,dynamictrees:leaves0:12)
Block(-2,17,0,dynamictrees:leaves0:12)
Block(-2,17,1,dynamictrees:junglebranch:2)
Block(-2,17,2,dynamictrees:junglebranch:1)
Block(-2,17,3,dynamictrees:junglebranch:1)
Block(-2,17,4,dynamictrees:junglebranch)
Block(-2,17,5,dynamictrees:leaves0:15)
Block(-2,17,6,dynamictrees:leaves0:12)
Block(-2,18,-1,dynamictrees:leaves0:12)
Block(-2,18,0,dynamictrees:leaves0:12)
Block(-2,18,3,dynamictrees:leaves0:12)
Block(-2,18,4,dynamictrees:leaves0:15)
Block(-2,18,5,dynamictrees:leaves0:14)
Block(-2,18,6,dynamictrees:leaves0:12)
Block(-2,19,-5,dynamictrees:leaves0:12)
Block(-2,19,-4,dynamictrees:leaves0:12)
Block(-2,19,-3,dynamictrees:leaves0:12)
Block(-2,19,4,dynamictrees:leaves0:12)
Block(-2,19,5,dynamictrees:leaves0:12)
Block(-2,20,-6,dynamictrees:leaves0:12)
Block(-2,20,-5,dynamictrees:leaves0:13)
Block(-2,20,-4,dynamictrees:leaves0:14)
Block(-2,20,-3,dynamictrees:leaves0:15)
Block(-2,20,-2,dynamictrees:leaves0:12)
Block(-2,21,-5,dynamictrees:leaves0:12)
Block(-2,21,-4,dynamictrees:leaves0:13)
Block(-2,21,-3,dynamictrees:leaves0:14)
Block(-2,21,-2,dynamictrees:leaves0:12)
Block(-2,22,-4,dynamictrees:leaves0:12)
Block(-2,22,-3,dynamictrees:leaves0:12)
Block(-2,25,5,dynamictrees:leaves0:12)
Block(-2,25,6,dynamictrees:leaves0:12)
Block(-2,25,7,dynamictrees:leaves0:12)
Block(-2,26,6,dynamictrees:leaves0:12)
Block(-2,26,7,dynamictrees:leaves0:12)
Block(-2,27,5,dynamictrees:leaves0:12)
Block(-2,27,6,dynamictrees:leaves0:12)
Block(-2,27,7,dynamictrees:leaves0:12)
Block(-2,30,-2,dynamictrees:leaves0:12)
Block(-2,31,-3,dynamictrees:leaves0:12)
Block(-2,31,-2,dynamictrees:leaves0:14)
Block(-2,31,-1,dynamictrees:leaves0:15)
Block(-2,31,0,dynamictrees:junglebranch)
Block(-2,31,1,dynamictrees:junglebranch:1)
Block(-2,31,2,dynamictrees:leaves0:15)
Block(-2,31,3,dynamictrees:junglebranch)
Block(-2,31,4,dynamictrees:leaves0:15)
Block(-2,31,5,dynamictrees:leaves0:12)
Block(-2,32,-3,dynamictrees:leaves0:12)
Block(-2,32,-2,dynamictrees:leaves0:13)
Block(-2,32,-1,dynamictrees:leaves0:14)
Block(-2,32,0,dynamictrees:leaves0:15)
Block(-2,32,1,dynamictrees:junglebranch)
Block(-2,32,2,dynamictrees:leaves0:15)
Block(-2,32,3,dynamictrees:leaves0:15)
Block(-2,32,4,dynamictrees:leaves0:14)
Block(-2,32,5,dynamictrees:leaves0:12)
Block(-2,33,-2,dynamictrees:leaves0:12)
Block(-2,33,-1,dynamictrees:leaves0:13)
Block(-2,33,0,dynamictrees:leaves0:14)
Block(-2,33,1,dynamictrees:leaves0:15)
Block(-2,33,2,dynamictrees:leaves0:14)
Block(-2,33,3,dynamictrees:leaves0:14)
Block(-2,33,4,dynamictrees:leaves0:13)
Block(-2,33,5,dynamictrees:leaves0:12)
Block(-2,34,-1,dynamictrees:leaves0:12)
Block(-2,34,0,dynamictrees:leaves0:13)
Block(-2,34,1,dynamictrees:leaves0:12)
Block(-2,34,2,dynamictrees:leaves0:12)
Block(-2,34,3,dynamictrees:leaves0:13)
Block(-2,34,4,dynamictrees:leaves0:12)
Block(-2,35,0,dynamictrees:leaves0:12)
Block(-2,35,3,dynamictrees:leaves0:12)
Block(-1,0,-1,GRASS:0)
Block(-1,0,0,GRASS:0)
Block(-1,0,1,GRASS:0)
Block(-1,0,2,GRASS:0)
Block(-1,0,3,GRASS:0)
Block(-1,1,-1,dynamictrees:jungleroot:3)
Block(-1,1,0,GRASS:0)
Block(-1,1,1,GRASS:0)
Block(-1,1,2,GRASS:0)
Block(-1,1,3,dynamictrees:jungleroot:2)
Block(-1,2,0,dynamictrees:trunkshell:5)
Block(-1,2,1,dynamictrees:jungleroot:5)
Block(-1,2,2,dynamictrees:trunkshell:7)
Block(-1,3,0,dynamictrees:trunkshell:5)
Block(-1,3,1,dynamictrees:trunkshell:6)
Block(-1,3,2,dynamictrees:trunkshell:7)
Block(-1,4,0,dynamictrees:trunkshell:5)
Block(-1,4,1,dynamictrees:trunkshell:6)
Block(-1,4,2,dynamictrees:trunkshell:7)
Block(-1,5,0,dynamictrees:trunkshell:5)
Block(-1,5,1,dynamictrees:trunkshell:6)
Block(-1,5,2,dynamictrees:trunkshell:7)
Block(-1,6,0,dynamictrees:trunkshell:5)
Block(-1,6,1,dynamictrees:trunkshell:6)
Block(-1,6,2,dynamictrees:trunkshell:7)
Block(-1,7,0,dynamictrees:trunkshell:5)
Block(-1,7,1,dynamictrees:trunkshell:6)
Block(-1,7,2,dynamictrees:trunkshell:7)
Block(-1,8,0,dynamictrees:trunkshell:5)
Block(-1,8,1,dynamictrees:trunkshell:6)
Block(-1,8,2,dynamictrees:trunkshell:7)
Block(-1,9,0,dynamictrees:trunkshell:5)
Block(-1,9,1,dynamictrees:trunkshell:6)
Block(-1,9,2,dynamictrees:trunkshell:7)
Block(-1,10,0,dynamictrees:trunkshell:5)
Block(-1,10,1,dynamictrees:trunkshell:6)
Block(-1,10,2,dynamictrees:trunkshell:7)
Block(-1,11,0,dynamictrees:trunkshell:5)
Block(-1,11,1,dynamictrees:trunkshell:6)
Block(-1,11,2,dynamictrees:trunkshell:7)
Block(-1,12,0,dynamictrees:trunkshell:5)
Block(-1,12,1,dynamictrees:trunkshell:6)
Block(-1,12,2,dynamictrees:trunkshell:7)
Block(-1,13,0,dynamictrees:trunkshell:5)
Block(-1,13,1,dynamictrees:trunkshell:6)
Block(-1,13,2,dynamictrees:trunkshell:7)
Block(-1,14,0,dynamictrees:trunkshell:5)
Block(-1,14,1,dynamictrees:trunkshell:6)
Block(-1,14,2,dynamictrees:trunkshell:7)
Block(-1,15,0,dynamictrees:trunkshell:5)
Block(-1,15,1,dynamictrees:trunkshell:6)
Block(-1,15,2,dynamictrees:trunkshell:7)
Block(-1,16,-1,dynamictrees:leaves0:15)
Block(-1,16,0,dynamictrees:trunkshell:5)
Block(-1,16,1,dynamictrees:trunkshell:6)
Block(-1,16,2,dynamictrees:trunkshell:7)
Block(-1,16,4,dynamictrees:leaves0:14)
Block(-1,16,5,dynamictrees:leaves0:13)
Block(-1,16,6,dynamictrees:leaves0:12)
Block(-1,17,-1,dynamictrees:junglebranch)
Block(-1,17,0,dynamictrees:junglebranch:1)
Block(-1,17,1,dynamictrees:junglebranch:3)
Block(-1,17,2,dynamictrees:trunkshell:7)
Block(-1,17,4,dynamictrees:leaves0:15)
Block(-1,17,5,dynamictrees:leaves0:14)
Block(-1,17,6,dynamictrees:leaves0:12)
Block(-1,18,-1,dynamictrees:leaves0:15)
Block(-1,18,0,dynamictrees:trunkshell:5)
Block(-1,18,1,dynamictrees:trunkshell:6)
Block(-1,18,2,dynamictrees:trunkshell:7)
Block(-1,18,4,dynamictrees:leaves0:14)
Block(-1,18,5,dynamictrees:leaves0:13)
Block(-1,18,6,dynamictrees:leaves0:12)
Block(-1,19,-5,dynamictrees:leaves0:12)
Block(-1,19,-4,dynamictrees:leaves0:12)
Block(-1,19,-1,dynamictrees:leaves0:12)
Block(-1,19,0,dynamictrees:trunkshell:5)
Block(-1,19,1,dynamictrees:trunkshell:6)
Block(-1,19,2,dynamictrees:trunkshell:7)
Block(-1,19,4,dynamictrees:leaves0:12)
Block(-1,19,5,dynamictrees:leaves0:12)
Block(-1,20,-6,dynamictrees:leaves0:12)
Block(-1,20,-5,dynamictrees:leaves0:14)
Block(-1,20,-4,dynamictrees:leaves0:15)
Block(-1,20,-3,dynamictrees:junglebranch)
Block(-1,20,0,dynamictrees:trunkshell:5)
Block(-1,20,1,dynamictrees:trunkshell:6)
Block(-1,20,2,dynamictrees:trunkshell:7)
Block(-1,21,-6,dynamictrees:leaves0:12)
Block(-1,21,-5,dynamictrees:leaves0:13)
Block(-1,21,-4,dynamictrees:leaves0:14)
Block(-1,21,-3,dynamictrees:leaves0:15)
Block(-1,21,-2,dynamictrees:leaves0:12)
Block(-1,22,-5,dynamictrees:leaves0:12)
Block(-1,22,-4,dynamictrees:leaves0:12)
Block(-1,22,-3,dynamictrees:leaves0:12)
Block(-1,22,-2,dynamictrees:leaves0:12)
Block(-1,23,-3,dynamictrees:leaves0:12)
Block(-1,23,-2,dynamictrees:leaves0:12)
Block(-1,24,-3,dynamictrees:leaves0:12)
Block(-1,24,-2,dynamictrees:leaves0:12)
Block(-1,25,4,dynamictrees:leaves0:12)
Block(-1,25,5,dynamictrees:leaves0:13)
Block(-1,25,6,dynamictrees:leaves0:14)
Block(-1,25,7,dynamictrees:leaves0:13)
Block(-1,25,8,dynamictrees:leaves0:12)
Block(-1,26,5,dynamictrees:leaves0:12)
Block(-1,26,6,dynamictrees:leaves0:15)
Block(-1,26,7,dynamictrees:leaves0:14)
Block(-1,26,8,dynamictrees:leaves0:12)
Block(-1,27,4,dynamictrees:leaves0:12)
Block(-1,27,5,dynamictrees:leaves0:13)
Block(-1,27,6,dynamictrees:leaves0:14)
Block(-1,27,7,dynamictrees:leaves0:13)
Block(-1,27,8,dynamictrees:leaves0:12)
Block(-1,28,5,dynamictrees:leaves0:12)
Block(-1,28,6,dynamictrees:leaves0:12)
Block(-1,28,7,dynamictrees:leaves0:12)
Block(-1,30,-1,dynamictrees:leaves0:15)
Block(-1,31,-3,dynamictrees:leaves0:12)
Block(-1,31,-2,dynamictrees:leaves0:15)
Block(-1,31,-1,dynamictrees:junglebranch)
Block(-1,31,1,dynamictrees:junglebranch:1)
Block(-1,31,2,dynamictrees:leaves0:12)
Block(-1,31,3,dynamictrees:junglebranch:1)
Block(-1,32,-3,dynamictrees:leaves0:12)
Block(-1,32,-2,dynamictrees:leaves0:14)
Block(-1,32,-1,dynamictrees:leaves0:15)
Block(-1,32,0,dynamictrees:leaves0:14)
Block(-1,32,1,dynamictrees:leaves0:15)
Block(-1,32,2,dynamictrees:leaves0:14)
Block(-1,32,3,dynamictrees:leaves0:14)
Block(-1,32,4,dynamictrees:leaves0:13)
Block(-1,32,5,dynamictrees:leaves0:12)
Block(-1,33,-3,dynamictrees:leaves0:12)
Block(-1,33,-2,dynamictrees:leaves0:13)
Block(-1,33,-1,dynamictrees:leaves0:14)
Block(-1,33,0,dynamictrees:leaves0:15)
Block(-1,33,1,dynamictrees:leaves0:14)
Block(-1,33,2,dynamictrees:leaves0:14)
Block(-1,33,3,dynamictrees:leaves0:15)
Block(-1,33,4,dynamictrees:leaves0:14)
Block(-1,33,5,dynamictrees:leaves0:12)
Block(-1,34,-2,dynamictrees:leaves0:12)
Block(-1,34,-1,dynamictrees:leaves0:13)
Block(-1,34,0,dynamictrees:leaves0:14)
Block(-1,34,1,dynamictrees:leaves0:13)
Block(-1,34,2,dynamictrees:leaves0:12)
Block(-1,34,3,dynamictrees:leaves0:14)
Block(-1,34,4,dynamictrees:leaves0:13)
Block(-1,34,5,dynamictrees:leaves0:12)
Block(-1,35,-1,dynamictrees:leaves0:12)
Block(-1,35,0,dynamictrees:leaves0:12)
Block(-1,35,1,dynamictrees:leaves0:12)
Block(-1,35,3,dynamictrees:leaves0:12)
Block(-1,35,4,dynamictrees:leaves0:12)
Block(0,0,-1,GRASS:0)
Block(0,0,0,GRASS:0)
Block(0,0,1,GRASS:0)
Block(0,0,2,GRASS:0)
Block(0,0,3,GRASS:0)
Block(0,1,-1,dynamictrees:jungleroot:4)
Block(0,1,0,GRASS:0)
Block(0,1,1,dynamictrees:rootydirtspecies:0,DT_Jungle_THuge_21/1-species_tile_entity.nbt)
Block(0,1,2,GRASS:0)
Block(0,1,3,GRASS:0)
Block(0,2,0,dynamictrees:jungleroot:5)
Block(0,2,1,dynamictrees:junglebranch:14)
Block(0,2,2,dynamictrees:jungleroot:4)
Block(0,2,3,dynamictrees:jungleroot:3)
Block(0,3,0,dynamictrees:trunkshell)
Block(0,3,1,dynamictrees:junglebranch:13)
Block(0,3,2,dynamictrees:trunkshell:0)
Block(0,4,0,dynamictrees:trunkshell)
Block(0,4,1,dynamictrees:junglebranch:12)
Block(0,4,2,dynamictrees:trunkshell:0)
Block(0,5,0,dynamictrees:trunkshell)
Block(0,5,1,dynamictrees:junglebranch:12)
Block(0,5,2,dynamictrees:trunkshell:0)
Block(0,6,0,dynamictrees:trunkshell)
Block(0,6,1,dynamictrees:junglebranch:12)
Block(0,6,2,dynamictrees:trunkshell:0)
Block(0,7,0,dynamictrees:trunkshell)
Block(0,7,1,dynamictrees:junglebranch:11)
Block(0,7,2,dynamictrees:trunkshell:0)
Block(0,8,0,dynamictrees:trunkshell)
Block(0,8,1,dynamictrees:junglebranch:11)
Block(0,8,2,dynamictrees:trunkshell:0)
Block(0,9,0,dynamictrees:trunkshell)
Block(0,9,1,dynamictrees:junglebranch:11)
Block(0,9,2,dynamictrees:trunkshell:0)
Block(0,10,0,dynamictrees:trunkshell)
Block(0,10,1,dynamictrees:junglebranch:11)
Block(0,10,2,dynamictrees:trunkshell:0)
Block(0,11,0,dynamictrees:trunkshell)
Block(0,11,1,dynamictrees:junglebranch:11)
Block(0,12,0,dynamictrees:trunkshell)
Block(0,12,1,dynamictrees:junglebranch:10)
Block(0,12,2,dynamictrees:trunkshell:0)
Block(0,13,0,dynamictrees:trunkshell)
Block(0,13,1,dynamictrees:junglebranch:10)
Block(0,13,2,dynamictrees:trunkshell:0)
Block(0,14,0,dynamictrees:trunkshell)
Block(0,14,1,dynamictrees:junglebranch:10)
Block(0,14,2,dynamictrees:trunkshell:0)
Block(0,15,0,dynamictrees:trunkshell)
Block(0,15,1,dynamictrees:junglebranch:9)
Block(0,15,2,dynamictrees:trunkshell:0)
Block(0,16,0,dynamictrees:trunkshell)
Block(0,16,1,dynamictrees:junglebranch:9)
Block(0,16,2,dynamictrees:trunkshell:0)
Block(0,17,0,dynamictrees:trunkshell)
Block(0,17,1,dynamictrees:junglebranch:9)
Block(0,17,2,dynamictrees:trunkshell:0)
Block(0,18,0,dynamictrees:trunkshell)
Block(0,18,1,dynamictrees:junglebranch:8)
Block(0,18,2,dynamictrees:trunkshell:0)
Block(0,19,-5,dynamictrees:leaves0:12)
Block(0,19,0,dynamictrees:trunkshell)
Block(0,19,1,dynamictrees:junglebranch:8)
Block(0,19,2,dynamictrees:trunkshell:0)
Block(0,20,-6,dynamictrees:leaves0:12)
Block(0,20,-5,dynamictrees:leaves0:15)
Block(0,20,-4,dynamictrees:junglebranch)
Block(0,20,-3,dynamictrees:junglebranch:1)
Block(0,20,-2,dynamictrees:junglebranch:1)
Block(0,20,-1,dynamictrees:junglebranch:1)
Block(0,20,0,dynamictrees:junglebranch:2)
Block(0,20,1,dynamictrees:junglebranch:8)
Block(0,20,2,dynamictrees:trunkshell:0)
Block(0,21,-6,dynamictrees:leaves0:12)
Block(0,21,-5,dynamictrees:leaves0:14)
Block(0,21,-4,dynamictrees:leaves0:15)
Block(0,21,1,dynamictrees:junglebranch:7)
Block(0,22,-5,dynamictrees:leaves0:12)
Block(0,22,-4,dynamictrees:leaves0:12)
Block(0,22,-3,dynamictrees:leaves0:13)
Block(0,22,-2,dynamictrees:leaves0:14)
Block(0,22,1,dynamictrees:junglebranch:7)
Block(0,23,-4,dynamictrees:leaves0:12)
Block(0,23,-3,dynamictrees:leaves0:14)
Block(0,23,-2,dynamictrees:leaves0:15)
Block(0,23,-1,dynamictrees:leaves0:12)
Block(0,23,1,dynamictrees:junglebranch:7)
Block(0,24,-4,dynamictrees:leaves0:12)
Block(0,24,-3,dynamictrees:leaves0:13)
Block(0,24,-2,dynamictrees:leaves0:14)
Block(0,24,-1,dynamictrees:leaves0:12)
Block(0,24,1,dynamictrees:junglebranch:6)
Block(0,25,-3,dynamictrees:leaves0:12)
Block(0,25,-2,dynamictrees:leaves0:12)
Block(0,25,1,dynamictrees:junglebranch:6)
Block(0,25,4,dynamictrees:leaves0:13)
Block(0,25,5,dynamictrees:leaves0:14)
Block(0,25,6,dynamictrees:leaves0:15)
Block(0,25,7,dynamictrees:leaves0:14)
Block(0,25,8,dynamictrees:leaves0:12)
Block(0,26,1,dynamictrees:junglebranch:6)
Block(0,26,2,dynamictrees:junglebranch:1)
Block(0,26,3,dynamictrees:junglebranch:1)
Block(0,26,4,dynamictrees:junglebranch:1)
Block(0,26,5,dynamictrees:junglebranch:1)
Block(0,26,6,dynamictrees:junglebranch)
Block(0,26,7,dynamictrees:leaves0:15)
Block(0,26,8,dynamictrees:leaves0:12)
Block(0,27,1,dynamictrees:junglebranch:5)
Block(0,27,4,dynamictrees:leaves0:13)
Block(0,27,5,dynamictrees:leaves0:14)
Block(0,27,6,dynamictrees:leaves0:15)
Block(0,27,7,dynamictrees:leaves0:14)
Block(0,27,8,dynamictrees:leaves0:12)
Block(0,28,1,dynamictrees:junglebranch:5)
Block(0,28,4,dynamictrees:leaves0:12)
Block(0,28,5,dynamictrees:leaves0:12)
Block(0,28,6,dynamictrees:leaves0:12)
Block(0,28,7,dynamictrees:leaves0:12)
Block(0,29,-1,dynamictrees:leaves0:15)
Block(0,29,0,dynamictrees:junglebranch)
Block(0,29,1,dynamictrees:junglebranch:5)
Block(0,30,-1,dynamictrees:leaves0:14)
Block(0,30,0,dynamictrees:leaves0:15)
Block(0,30,1,dynamictrees:junglebranch:5)
Block(0,31,-3,dynamictrees:leaves0:12)
Block(0,31,-2,dynamictrees:leaves0:14)
Block(0,31,-1,dynamictrees:junglebranch:1)
Block(0,31,0,dynamictrees:junglebranch:1)
Block(0,31,1,dynamictrees:junglebranch:4)
Block(0,31,2,dynamictrees:junglebranch:2)
Block(0,31,3,dynamictrees:junglebranch:2)
Block(0,31,4,dynamictrees:junglebranch:1)
Block(0,31,5,dynamictrees:leaves0:12)
Block(0,32,-3,dynamictrees:leaves0:12)
Block(0,32,-2,dynamictrees:leaves0:15)
Block(0,32,-1,dynamictrees:junglebranch)
Block(0,32,0,dynamictrees:leaves0:15)
Block(0,32,1,dynamictrees:junglebranch:1)
Block(0,32,2,dynamictrees:leaves0:14)
Block(0,32,3,dynamictrees:junglebranch:1)
Block(0,32,4,dynamictrees:leaves0:14)
Block(0,32,5,dynamictrees:leaves0:13)
Block(0,32,6,dynamictrees:leaves0:12)
Block(0,33,-3,dynamictrees:leaves0:12)
Block(0,33,-2,dynamictrees:leaves0:14)
Block(0,33,-1,dynamictrees:leaves0:15)
Block(0,33,0,dynamictrees:junglebranch)
Block(0,33,1,dynamictrees:junglebranch:1)
Block(0,33,2,dynamictrees:leaves0:15)
Block(0,33,3,dynamictrees:junglebranch)
Block(0,33,4,dynamictrees:leaves0:15)
Block(0,33,5,dynamictrees:leaves0:12)
Block(0,34,-3,dynamictrees:leaves0:12)
Block(0,34,-2,dynamictrees:leaves0:13)
Block(0,34,-1,dynamictrees:leaves0:14)
Block(0,34,0,dynamictrees:leaves0:15)
Block(0,34,1,dynamictrees:leaves0:12)
Block(0,34,2,dynamictrees:leaves0:14)
Block(0,34,3,dynamictrees:leaves0:15)
Block(0,34,4,dynamictrees:leaves0:14)
Block(0,34,5,dynamictrees:leaves0:12)
Block(0,35,-2,dynamictrees:leaves0:12)
Block(0,35,-1,dynamictrees:leaves0:12)
Block(0,35,0,dynamictrees:leaves0:12)
Block(0,35,2,dynamictrees:leaves0:12)
Block(0,35,3,dynamictrees:leaves0:12)
Block(0,35,4,dynamictrees:leaves0:12)
Block(1,0,-1,GRASS:0)
Block(1,0,0,GRASS:0)
Block(1,0,1,GRASS:0)
Block(1,0,2,GRASS:0)
Block(1,0,3,GRASS:0)
Block(1,1,0,GRASS:0)
Block(1,1,1,GRASS:0)
Block(1,1,2,GRASS:0)
Block(1,1,3,GRASS:0)
Block(1,2,0,dynamictrees:trunkshell:3)
Block(1,2,1,dynamictrees:jungleroot:5)
Block(1,2,2,dynamictrees:trunkshell:1)
Block(1,2,3,dynamictrees:jungleroot:2)
Block(1,3,0,dynamictrees:trunkshell:3)
Block(1,3,1,dynamictrees:trunkshell:2)
Block(1,3,2,dynamictrees:trunkshell:1)
Block(1,4,0,dynamictrees:trunkshell:3)
Block(1,4,1,dynamictrees:trunkshell:2)
Block(1,4,2,dynamictrees:trunkshell:1)
Block(1,5,0,dynamictrees:trunkshell:3)
Block(1,5,1,dynamictrees:trunkshell:2)
Block(1,5,2,dynamictrees:trunkshell:1)
Block(1,6,0,dynamictrees:trunkshell:3)
Block(1,6,1,dynamictrees:trunkshell:2)
Block(1,6,2,dynamictrees:trunkshell:1)
Block(1,7,0,dynamictrees:trunkshell:3)
Block(1,7,1,dynamictrees:trunkshell:2)
Block(1,7,2,dynamictrees:trunkshell:1)
Block(1,8,0,dynamictrees:trunkshell:3)
Block(1,8,1,dynamictrees:trunkshell:2)
Block(1,8,2,dynamictrees:trunkshell:1)
Block(1,9,0,dynamictrees:trunkshell:3)
Block(1,9,1,dynamictrees:trunkshell:2)
Block(1,9,2,dynamictrees:trunkshell:1)
Block(1,10,0,dynamictrees:trunkshell:3)
Block(1,10,1,dynamictrees:trunkshell:2)
Block(1,10,2,dynamictrees:trunkshell:1)
Block(1,11,0,dynamictrees:trunkshell:3)
Block(1,11,1,dynamictrees:trunkshell:2)
Block(1,11,2,dynamictrees:trunkshell:1)
Block(1,12,0,dynamictrees:trunkshell:3)
Block(1,12,1,dynamictrees:trunkshell:2)
Block(1,12,2,dynamictrees:trunkshell:1)
Block(1,13,0,dynamictrees:trunkshell:3)
Block(1,13,1,dynamictrees:trunkshell:2)
Block(1,13,2,dynamictrees:trunkshell:1)
Block(1,14,2,dynamictrees:trunkshell:1)
Block(1,15,0,dynamictrees:trunkshell:3)
Block(1,15,1,dynamictrees:trunkshell:2)
Block(1,15,2,dynamictrees:trunkshell:1)
Block(1,16,0,dynamictrees:trunkshell:3)
Block(1,16,1,dynamictrees:trunkshell:2)
Block(1,16,2,dynamictrees:trunkshell:1)
Block(1,17,0,dynamictrees:trunkshell:3)
Block(1,17,1,dynamictrees:trunkshell:2)
Block(1,17,2,dynamictrees:trunkshell:1)
Block(1,18,0,dynamictrees:trunkshell:3)
Block(1,18,1,dynamictrees:trunkshell:2)
Block(1,18,2,dynamictrees:trunkshell:1)
Block(1,19,0,dynamictrees:trunkshell:3)
Block(1,19,1,dynamictrees:trunkshell:2)
Block(1,19,2,dynamictrees:trunkshell:1)
Block(1,20,-5,dynamictrees:leaves0:12)
Block(1,20,0,dynamictrees:junglebranch)
Block(1,20,1,dynamictrees:trunkshell:2)
Block(1,20,2,dynamictrees:trunkshell:1)
Block(1,21,-5,dynamictrees:leaves0:12)
Block(1,21,-4,dynamictrees:leaves0:12)
Block(1,22,-4,dynamictrees:leaves0:12)
Block(1,22,-3,dynamictrees:leaves0:14)
Block(1,22,-2,dynamictrees:leaves0:15)
Block(1,22,-1,dynamictrees:leaves0:12)
Block(1,23,-4,dynamictrees:leaves0:12)
Block(1,23,-3,dynamictrees:leaves0:15)
Block(1,23,-2,dynamictrees:junglebranch)
Block(1,23,-1,dynamictrees:junglebranch:1)
Block(1,23,0,dynamictrees:junglebranch:2)
Block(1,23,1,dynamictrees:junglebranch:2)
Block(1,24,-4,dynamictrees:leaves0:12)
Block(1,24,-3,dynamictrees:leaves0:14)
Block(1,24,-2,dynamictrees:leaves0:15)
Block(1,24,-1,dynamictrees:leaves0:12)
Block(1,25,-3,dynamictrees:leaves0:12)
Block(1,25,-2,dynamictrees:leaves0:12)
Block(1,25,3,dynamictrees:leaves0:12)
Block(1,25,4,dynamictrees:leaves0:14)
Block(1,25,5,dynamictrees:leaves0:15)
Block(1,25,6,dynamictrees:leaves0:14)
Block(1,25,7,dynamictrees:leaves0:13)
Block(1,25,8,dynamictrees:leaves0:12)
Block(1,26,3,dynamictrees:leaves0:12)
Block(1,26,4,dynamictrees:leaves0:15)
Block(1,26,5,dynamictrees:junglebranch)
Block(1,26,6,dynamictrees:leaves0:15)
Block(1,26,7,dynamictrees:leaves0:14)
Block(1,26,8,dynamictrees:leaves0:12)
Block(1,27,3,dynamictrees:leaves0:12)
Block(1,27,4,dynamictrees:leaves0:14)
Block(1,27,5,dynamictrees:leaves0:15)
Block(1,27,6,dynamictrees:leaves0:14)
Block(1,27,7,dynamictrees:leaves0:13)
Block(1,27,8,dynamictrees:leaves0:12)
Block(1,28,4,dynamictrees:leaves0:12)
Block(1,28,5,dynamictrees:leaves0:12)
Block(1,28,6,dynamictrees:leaves0:12)
Block(1,28,7,dynamictrees:leaves0:12)
Block(1,29,-1,dynamictrees:leaves0:12)
Block(1,30,-1,dynamictrees:leaves0:13)
Block(1,31,-3,dynamictrees:leaves0:12)
Block(1,31,-2,dynamictrees:leaves0:13)
Block(1,31,-1,dynamictrees:leaves0:14)
Block(1,31,1,dynamictrees:junglebranch:2)
Block(1,31,4,dynamictrees:junglebranch)
Block(1,31,5,dynamictrees:leaves0:15)
Block(1,31,6,dynamictrees:leaves0:12)
Block(1,32,-3,dynamictrees:leaves0:12)
Block(1,32,-2,dynamictrees:leaves0:14)
Block(1,32,-1,dynamictrees:leaves0:15)
Block(1,32,0,dynamictrees:leaves0:14)
Block(1,32,1,dynamictrees:leaves0:15)
Block(1,32,2,dynamictrees:leaves0:15)
Block(1,32,3,dynamictrees:junglebranch)
Block(1,32,4,dynamictrees:leaves0:15)
Block(1,32,5,dynamictrees:leaves0:14)
Block(1,32,6,dynamictrees:leaves0:12)
Block(1,33,-3,dynamictrees:leaves0:12)
Block(1,33,-2,dynamictrees:leaves0:13)
Block(1,33,-1,dynamictrees:leaves0:14)
Block(1,33,0,dynamictrees:leaves0:15)
Block(1,33,1,dynamictrees:leaves0:14)
Block(1,33,2,dynamictrees:leaves0:14)
Block(1,33,3,dynamictrees:leaves0:15)
Block(1,33,4,dynamictrees:leaves0:14)
Block(1,33,5,dynamictrees:leaves0:13)
Block(1,33,6,dynamictrees:leaves0:12)
Block(1,34,-2,dynamictrees:leaves0:12)
Block(1,34,-1,dynamictrees:leaves0:13)
Block(1,34,0,dynamictrees:leaves0:14)
Block(1,34,1,dynamictrees:leaves0:13)
Block(1,34,2,dynamictrees:leaves0:13)
Block(1,34,3,dynamictrees:leaves0:14)
Block(1,34,4,dynamictrees:leaves0:13)
Block(1,34,5,dynamictrees:leaves0:12)
Block(1,35,-1,dynamictrees:leaves0:12)
Block(1,35,0,dynamictrees:leaves0:12)
Block(1,35,1,dynamictrees:leaves0:12)
Block(1,35,2,dynamictrees:leaves0:12)
Block(1,35,3,dynamictrees:leaves0:12)
Block(1,35,4,dynamictrees:leaves0:12)
Block(2,0,-1,dynamictrees:jungleroot:1)
Block(2,0,0,GRASS:0)
Block(2,0,1,GRASS:0)
Block(2,1,0,dynamictrees:jungleroot:2)
Block(2,1,1,GRASS:0)
Block(2,2,1,dynamictrees:jungleroot:4)
Block(2,22,-4,dynamictrees:leaves0:12)
Block(2,22,-3,dynamictrees:leaves0:13)
Block(2,22,-2,dynamictrees:leaves0:14)
Block(2,22,-1,dynamictrees:leaves0:12)
Block(2,23,-4,dynamictrees:leaves0:12)
Block(2,23,-3,dynamictrees:leaves0:14)
Block(2,23,-2,dynamictrees:leaves0:15)
Block(2,23,-1,dynamictrees:junglebranch:1)
Block(2,23,0,dynamictrees:leaves0:12)
Block(2,23,1,dynamictrees:junglebranch:1)
Block(2,24,-4,dynamictrees:leaves0:12)
Block(2,24,-3,dynamictrees:leaves0:13)
Block(2,24,-2,dynamictrees:leaves0:14)
Block(2,24,-1,dynamictrees:leaves0:12)
Block(2,24,0,dynamictrees:leaves0:12)
Block(2,25,-3,dynamictrees:leaves0:12)
Block(2,25,-2,dynamictrees:leaves0:12)
Block(2,25,3,dynamictrees:leaves0:12)
Block(2,25,4,dynamictrees:leaves0:13)
Block(2,25,5,dynamictrees:leaves0:14)
Block(2,25,6,dynamictrees:leaves0:13)
Block(2,25,7,dynamictrees:leaves0:12)
Block(2,26,3,dynamictrees:leaves0:12)
Block(2,26,4,dynamictrees:leaves0:14)
Block(2,26,5,dynamictrees:leaves0:15)
Block(2,26,6,dynamictrees:leaves0:14)
Block(2,26,7,dynamictrees:leaves0:13)
Block(2,26,8,dynamictrees:leaves0:12)
Block(2,27,3,dynamictrees:leaves0:12)
Block(2,27,4,dynamictrees:leaves0:13)
Block(2,27,5,dynamictrees:leaves0:14)
Block(2,27,6,dynamictrees:leaves0:13)
Block(2,27,7,dynamictrees:leaves0:12)
Block(2,28,4,dynamictrees:leaves0:12)
Block(2,28,5,dynamictrees:leaves0:12)
Block(2,28,6,dynamictrees:leaves0:12)
Block(2,30,5,dynamictrees:leaves0:12)
Block(2,31,-2,dynamictrees:leaves0:12)
Block(2,31,-1,dynamictrees:leaves0:15)
Block(2,31,0,dynamictrees:junglebranch)
Block(2,31,1,dynamictrees:junglebranch:2)
Block(2,31,2,dynamictrees:junglebranch)
Block(2,31,3,dynamictrees:leaves0:15)
Block(2,31,4,dynamictrees:leaves0:15)
Block(2,31,5,dynamictrees:leaves0:14)
Block(2,31,6,dynamictrees:leaves0:12)
Block(2,32,-3,dynamictrees:leaves0:12)
Block(2,32,-2,dynamictrees:leaves0:13)
Block(2,32,-1,dynamictrees:leaves0:14)
Block(2,32,0,dynamictrees:leaves0:15)
Block(2,32,1,dynamictrees:junglebranch)
Block(2,32,2,dynamictrees:leaves0:15)
Block(2,32,3,dynamictrees:leaves0:15)
Block(2,32,4,dynamictrees:leaves0:14)
Block(2,32,5,dynamictrees:leaves0:13)
Block(2,32,6,dynamictrees:leaves0:12)
Block(2,33,-2,dynamictrees:leaves0:12)
Block(2,33,-1,dynamictrees:leaves0:13)
Block(2,33,0,dynamictrees:leaves0:14)
Block(2,33,1,dynamictrees:leaves0:15)
Block(2,33,2,dynamictrees:leaves0:14)
Block(2,33,3,dynamictrees:leaves0:14)
Block(2,33,4,dynamictrees:leaves0:13)
Block(2,33,5,dynamictrees:leaves0:12)
Block(2,34,-1,dynamictrees:leaves0:12)
Block(2,34,0,dynamictrees:leaves0:13)
Block(2,34,1,dynamictrees:leaves0:12)
Block(2,34,2,dynamictrees:leaves0:12)
Block(2,34,3,dynamictrees:leaves0:13)
Block(2,34,4,dynamictrees:leaves0:12)
Block(2,35,0,dynamictrees:leaves0:12)
Block(2,35,3,dynamictrees:leaves0:12)
Block(3,0,-1,dynamictrees:jungleroot)
Block(3,22,-3,dynamictrees:leaves0:12)
Block(3,22,-2,dynamictrees:leaves0:14)
Block(3,22,-1,dynamictrees:leaves0:15)
Block(3,22,2,dynamictrees:leaves0:14)
Block(3,22,3,dynamictrees:leaves0:13)
Block(3,22,4,dynamictrees:leaves0:12)
Block(3,23,-3,dynamictrees:leaves0:12)
Block(3,23,-2,dynamictrees:leaves0:15)
Block(3,23,-1,dynamictrees:junglebranch)
Block(3,23,0,dynamictrees:leaves0:15)
Block(3,23,1,dynamictrees:junglebranch:1)
Block(3,23,2,dynamictrees:leaves0:15)
Block(3,23,3,dynamictrees:leaves0:14)
Block(3,24,-3,dynamictrees:leaves0:12)
Block(3,24,-2,dynamictrees:leaves0:14)
Block(3,24,-1,dynamictrees:leaves0:15)
Block(3,24,0,dynamictrees:leaves0:14)
Block(3,24,1,dynamictrees:leaves0:13)
Block(3,24,2,dynamictrees:leaves0:14)
Block(3,24,3,dynamictrees:leaves0:13)
Block(3,24,4,dynamictrees:leaves0:12)
Block(3,25,-2,dynamictrees:leaves0:12)
Block(3,25,-1,dynamictrees:leaves0:12)
Block(3,25,0,dynamictrees:leaves0:12)
Block(3,25,1,dynamictrees:leaves0:12)
Block(3,25,2,dynamictrees:leaves0:12)
Block(3,25,3,dynamictrees:leaves0:12)
Block(3,25,4,dynamictrees:leaves0:12)
Block(3,25,5,dynamictrees:leaves0:12)
Block(3,25,6,dynamictrees:leaves0:12)
Block(3,26,4,dynamictrees:leaves0:12)
Block(3,26,5,dynamictrees:leaves0:12)
Block(3,26,6,dynamictrees:leaves0:12)
Block(3,26,7,dynamictrees:leaves0:12)
Block(3,27,4,dynamictrees:leaves0:12)
Block(3,27,5,dynamictrees:leaves0:12)
Block(3,27,6,dynamictrees:leaves0:12)
Block(3,30,-1,dynamictrees:leaves0:12)
Block(3,31,-2,dynamictrees:leaves0:12)
Block(3,31,-1,dynamictrees:leaves0:14)
Block(3,31,0,dynamictrees:leaves0:15)
Block(3,31,1,dynamictrees:junglebranch:1)
Block(3,31,2,dynamictrees:leaves0:15)
Block(3,31,3,dynamictrees:leaves0:14)
Block(3,31,4,dynamictrees:leaves0:12)
Block(3,31,5,dynamictrees:leaves0:12)
Block(3,32,-2,dynamictrees:leaves0:12)
Block(3,32,-1,dynamictrees:leaves0:13)
Block(3,32,0,dynamictrees:leaves0:14)
Block(3,32,1,dynamictrees:leaves0:15)
Block(3,32,2,dynamictrees:leaves0:14)
Block(3,32,3,dynamictrees:leaves0:13)
Block(3,32,4,dynamictrees:leaves0:12)
Block(3,32,5,dynamictrees:leaves0:12)
Block(3,33,-1,dynamictrees:leaves0:12)
Block(3,33,0,dynamictrees:leaves0:13)
Block(3,33,1,dynamictrees:leaves0:14)
Block(3,33,2,dynamictrees:leaves0:13)
Block(3,33,3,dynamictrees:leaves0:12)
Block(3,33,4,dynamictrees:leaves0:12)
Block(3,34,0,dynamictrees:leaves0:12)
Block(3,34,1,dynamictrees:leaves0:12)
Block(3,34,2,dynamictrees:leaves0:12)
Block(3,34,3,dynamictrees:leaves0:12)
Block(4,22,-3,dynamictrees:leaves0:12)
Block(4,22,-2,dynamictrees:leaves0:13)
Block(4,22,-1,dynamictrees:leaves0:14)
Block(4,22,0,dynamictrees:leaves0:13)
Block(4,22,1,dynamictrees:leaves0:14)
Block(4,22,2,dynamictrees:leaves0:15)
Block(4,22,3,dynamictrees:leaves0:14)
Block(4,22,4,dynamictrees:leaves0:12)
Block(4,23,-3,dynamictrees:leaves0:12)
Block(4,23,-2,dynamictrees:leaves0:14)
Block(4,23,-1,dynamictrees:leaves0:15)
Block(4,23,0,dynamictrees:leaves0:14)
Block(4,23,1,dynamictrees:junglebranch:1)
Block(4,23,2,dynamictrees:junglebranch)
Block(4,23,3,dynamictrees:leaves0:15)
Block(4,23,4,dynamictrees:leaves0:12)
Block(4,24,-3,dynamictrees:leaves0:12)
Block(4,24,-2,dynamictrees:leaves0:13)
Block(4,24,-1,dynamictrees:leaves0:14)
Block(4,24,0,dynamictrees:leaves0:13)
Block(4,24,1,dynamictrees:leaves0:14)
Block(4,24,2,dynamictrees:leaves0:15)
Block(4,24,3,dynamictrees:leaves0:14)
Block(4,24,4,dynamictrees:leaves0:12)
Block(4,25,-2,dynamictrees:leaves0:12)
Block(4,25,-1,dynamictrees:leaves0:12)
Block(4,25,0,dynamictrees:leaves0:12)
Block(4,25,1,dynamictrees:leaves0:12)
Block(4,25,2,dynamictrees:leaves0:12)
Block(4,25,3,dynamictrees:leaves0:12)
Block(4,30,-1,dynamictrees:leaves0:12)
Block(4,30,0,dynamictrees:leaves0:14)
Block(4,30,1,dynamictrees:leaves0:15)
Block(4,30,2,dynamictrees:leaves0:14)
Block(4,30,3,dynamictrees:leaves0:12)
Block(4,31,-1,dynamictrees:leaves0:12)
Block(4,31,0,dynamictrees:leaves0:15)
Block(4,31,1,dynamictrees:junglebranch)
Block(4,31,2,dynamictrees:leaves0:15)
Block(4,31,3,dynamictrees:leaves0:12)
Block(4,32,-1,dynamictrees:leaves0:12)
Block(4,32,0,dynamictrees:leaves0:14)
Block(4,32,1,dynamictrees:leaves0:15)
Block(4,32,2,dynamictrees:leaves0:14)
Block(4,32,3,dynamictrees:leaves0:12)
Block(4,33,0,dynamictrees:leaves0:12)
Block(4,33,1,dynamictrees:leaves0:12)
Block(4,33,2,dynamictrees:leaves0:12)
Block(5,22,-2,dynamictrees:leaves0:12)
Block(5,22,-1,dynamictrees:leaves0:13)
Block(5,22,0,dynamictrees:leaves0:14)
Block(5,22,1,dynamictrees:leaves0:15)
Block(5,22,2,dynamictrees:leaves0:14)
Block(5,22,3,dynamictrees:leaves0:13)
Block(5,22,4,dynamictrees:leaves0:12)
Block(5,23,-3,dynamictrees:leaves0:12)
Block(5,23,-2,dynamictrees:leaves0:13)
Block(5,23,-1,dynamictrees:leaves0:14)
Block(5,23,0,dynamictrees:leaves0:15)
Block(5,23,1,dynamictrees:junglebranch)
Block(5,23,2,dynamictrees:leaves0:15)
Block(5,23,3,dynamictrees:leaves0:14)
Block(5,23,4,dynamictrees:leaves0:12)
Block(5,24,-2,dynamictrees:leaves0:12)
Block(5,24,-1,dynamictrees:leaves0:13)
Block(5,24,0,dynamictrees:leaves0:14)
Block(5,24,1,dynamictrees:leaves0:15)
Block(5,24,2,dynamictrees:leaves0:14)
Block(5,24,3,dynamictrees:leaves0:13)
Block(5,24,4,dynamictrees:leaves0:12)
Block(5,25,-1,dynamictrees:leaves0:12)
Block(5,25,0,dynamictrees:leaves0:12)
Block(5,25,1,dynamictrees:leaves0:12)
Block(5,25,2,dynamictrees:leaves0:12)
Block(5,25,3,dynamictrees:leaves0:12)
Block(5,30,-1,dynamictrees:leaves0:12)
Block(5,30,0,dynamictrees:leaves0:13)
Block(5,30,1,dynamictrees:leaves0:14)
Block(5,30,2,dynamictrees:leaves0:13)
Block(5,30,3,dynamictrees:leaves0:12)
Block(5,31,-1,dynamictrees:leaves0:12)
Block(5,31,0,dynamictrees:leaves0:14)
Block(5,31,1,dynamictrees:leaves0:15)
Block(5,31,2,dynamictrees:leaves0:14)
Block(5,31,3,dynamictrees:leaves0:12)
Block(5,32,-1,dynamictrees:leaves0:12)
Block(5,32,0,dynamictrees:leaves0:13)
Block(5,32,1,dynamictrees:leaves0:14)
Block(5,32,2,dynamictrees:leaves0:13)
Block(5,32,3,dynamictrees:leaves0:12)
Block(5,33,0,dynamictrees:leaves0:12)
Block(5,33,1,dynamictrees:leaves0:12)
Block(5,33,2,dynamictrees:leaves0:12)
Block(6,22,-1,dynamictrees:leaves0:12)
Block(6,22,0,dynamictrees:leaves0:13)
Block(6,22,1,dynamictrees:leaves0:14)
Block(6,22,2,dynamictrees:leaves0:13)
Block(6,22,3,dynamictrees:leaves0:12)
Block(6,23,-2,dynamictrees:leaves0:12)
Block(6,23,-1,dynamictrees:leaves0:13)
Block(6,23,0,dynamictrees:leaves0:14)
Block(6,23,1,dynamictrees:leaves0:15)
Block(6,23,2,dynamictrees:leaves0:14)
Block(6,23,3,dynamictrees:leaves0:13)
Block(6,23,4,dynamictrees:leaves0:12)
Block(6,24,-1,dynamictrees:leaves0:12)
Block(6,24,0,dynamictrees:leaves0:13)
Block(6,24,1,dynamictrees:leaves0:14)
Block(6,24,2,dynamictrees:leaves0:13)
Block(6,24,3,dynamictrees:leaves0:12)
Block(6,25,0,dynamictrees:leaves0:12)
Block(6,25,1,dynamictrees:leaves0:12)
Block(6,25,2,dynamictrees:leaves0:12)
Block(6,30,0,dynamictrees:leaves0:12)
Block(6,30,1,dynamictrees:leaves0:12)
Block(6,30,2,dynamictrees:leaves0:12)
Block(6,31,0,dynamictrees:leaves0:12)
Block(6,31,1,dynamictrees:leaves0:12)
Block(6,31,2,dynamictrees:leaves0:12)
Block(6,32,0,dynamictrees:leaves0:12)
Block(6,32,1,dynamictrees:leaves0:12)
Block(6,32,2,dynamictrees:leaves0:12)
Block(7,22,0,dynamictrees:leaves0:12)
Block(7,22,1,dynamictrees:leaves0:12)
Block(7,22,2,dynamictrees:leaves0:12)
Block(7,23,-1,dynamictrees:leaves0:12)
Block(7,23,0,dynamictrees:leaves0:12)
Block(7,23,1,dynamictrees:leaves0:12)
Block(7,23,2,dynamictrees:leaves0:12)
Block(7,23,3,dynamictrees:leaves0:12)
Block(7,24,0,dynamictrees:leaves0:12)
Block(7,24,1,dynamictrees:leaves0:12)
Block(7,24,2,dynamictrees:leaves0:12)

#######################################################################
# +-----------------------------------------------------------------+ #
# |                            BO3 checks                           | #
# +-----------------------------------------------------------------+ #
#######################################################################

BlockCheck(0,-1,1,GRASS,DIRT,biomesoplenty:grass,biomesoplenty:dirt)

#######################################################################
# +-----------------------------------------------------------------+ #
# |                             Branches                            | #
# +-----------------------------------------------------------------+ #
#######################################################################


#######################################################################
# +-----------------------------------------------------------------+ #
# |                             Entities                            | #
# +-----------------------------------------------------------------+ #
#######################################################################


#######################################################################
# +-----------------------------------------------------------------+ #
# |                            Particles                            | #
# +-----------------------------------------------------------------+ #
#######################################################################


#######################################################################
# +-----------------------------------------------------------------+ #
# |                             Spawners                            | #
# +-----------------------------------------------------------------+ #
#######################################################################


#######################################################################
# +-----------------------------------------------------------------+ #
# |                             ModData                             | #
# +-----------------------------------------------------------------+ #
#######################################################################

