
#######################################################################
# +-----------------------------------------------------------------+ #
# |                            BO3 object                           | #
# +-----------------------------------------------------------------+ #
#######################################################################

Author: NLBlackEagle

Description: No description given

Version: 3

SettingsMode: WriteDisable


#######################################################################
# +-----------------------------------------------------------------+ #
# |                          Main settings                          | #
# +-----------------------------------------------------------------+ #
#######################################################################

Tree: true

Frequency: 0

Rarity: 100.0

RotateRandomly: true

SpawnHeight: highestSolidBlock

SpawnHeightOffset: -4

SpawnHeightVariance: 0

##############################
# Height Limits for the BO3. #
##############################

MinHeight: 0

MaxHeight: 255

######################
# Extrusion settings #
######################

ExtrudeMode: None

ExtrudeThroughBlocks: AIR

MaxBranchDepth: 10

ExcludedBiomes: All


#######################################################################
# +-----------------------------------------------------------------+ #
# |                      Source block settings                      | #
# +-----------------------------------------------------------------+ #
#######################################################################

SourceBlocks: AIR

MaxPercentageOutsideSourceBlock: 100

OutsideSourceBlock: placeAnyway

DoReplaceBlocks: true

IsOTGPlus: false


#######################################################################
# +-----------------------------------------------------------------+ #
# |                              Blocks                             | #
# +-----------------------------------------------------------------+ #
#######################################################################

Block(-6,0,-7,PACKED_ICE:0)
Block(-6,0,-6,PACKED_ICE:0)
Block(-6,0,-5,PACKED_ICE:0)
Block(-6,0,-4,PACKED_ICE:0)
Block(-6,0,-3,PACKED_ICE:0)
Block(-6,0,-2,PACKED_ICE:0)
Block(-6,0,-1,PACKED_ICE:0)
Block(-6,0,0,PACKED_ICE:0)
Block(-6,0,1,PACKED_ICE:0)
Block(-6,0,2,PACKED_ICE:0)
Block(-6,0,3,PACKED_ICE:0)
Block(-6,0,4,PACKED_ICE:0)
Block(-6,0,5,PACKED_ICE:0)
Block(-6,1,-7,PACKED_ICE:0)
Block(-6,1,-6,PACKED_ICE:0)
Block(-6,1,-5,PACKED_ICE:0)
Block(-6,1,-4,PACKED_ICE:0)
Block(-6,1,-3,PACKED_ICE:0)
Block(-6,1,-2,PACKED_ICE:0)
Block(-6,1,-1,ICE:0)
Block(-6,1,0,ICE:0)
Block(-6,1,1,ICE:0)
Block(-6,1,2,PACKED_ICE:0)
Block(-6,1,3,PACKED_ICE:0)
Block(-6,1,4,PACKED_ICE:0)
Block(-6,1,5,PACKED_ICE:0)
Block(-6,2,-7,PACKED_ICE:0)
Block(-6,2,-6,PACKED_ICE:0)
Block(-6,2,-5,PACKED_ICE:0)
Block(-6,2,-4,PACKED_ICE:0)
Block(-6,2,-3,PACKED_ICE:0)
Block(-6,2,-2,PACKED_ICE:0)
Block(-6,2,-1,ICE:0)
Block(-6,2,0,ICE:0)
Block(-6,2,1,ICE:0)
Block(-6,2,2,PACKED_ICE:0)
Block(-6,2,3,PACKED_ICE:0)
Block(-6,2,4,PACKED_ICE:0)
Block(-6,2,5,PACKED_ICE:0)
Block(-5,0,-7,PACKED_ICE:0)
Block(-5,0,-6,PACKED_ICE:0)
Block(-5,0,-5,PACKED_ICE:0)
Block(-5,0,-4,PACKED_ICE:0)
Block(-5,0,-3,PACKED_ICE:0)
Block(-5,0,-2,PACKED_ICE:0)
Block(-5,0,-1,PACKED_ICE:0)
Block(-5,0,0,PACKED_ICE:0)
Block(-5,0,1,PACKED_ICE:0)
Block(-5,0,2,PACKED_ICE:0)
Block(-5,0,3,PACKED_ICE:0)
Block(-5,0,4,PACKED_ICE:0)
Block(-5,0,5,PACKED_ICE:0)
Block(-5,0,6,PACKED_ICE:0)
Block(-5,1,-7,PACKED_ICE:0)
Block(-5,1,-6,PACKED_ICE:0)
Block(-5,1,-5,PACKED_ICE:0)
Block(-5,1,-4,PACKED_ICE:0)
Block(-5,1,-3,PACKED_ICE:0)
Block(-5,1,-2,PACKED_ICE:0)
Block(-5,1,-1,PACKED_ICE:0)
Block(-5,1,0,ICE:0)
Block(-5,1,1,PACKED_ICE:0)
Block(-5,1,2,PACKED_ICE:0)
Block(-5,1,3,PACKED_ICE:0)
Block(-5,1,4,PACKED_ICE:0)
Block(-5,1,5,PACKED_ICE:0)
Block(-5,1,6,PACKED_ICE:0)
Block(-5,2,-7,PACKED_ICE:0)
Block(-5,2,-6,PACKED_ICE:0)
Block(-5,2,-5,PACKED_ICE:0)
Block(-5,2,-4,PACKED_ICE:0)
Block(-5,2,-3,PACKED_ICE:0)
Block(-5,2,-2,ICE:0)
Block(-5,2,-1,ICE:0)
Block(-5,2,0,ICE:0)
Block(-5,2,1,ICE:0)
Block(-5,2,2,PACKED_ICE:0)
Block(-5,2,3,PACKED_ICE:0)
Block(-5,2,4,PACKED_ICE:0)
Block(-5,2,5,PACKED_ICE:0)
Block(-5,2,6,PACKED_ICE:0)
Block(-5,3,-7,PACKED_ICE:0)
Block(-5,3,-6,PACKED_ICE:0)
Block(-5,3,-5,PACKED_ICE:0)
Block(-5,3,-4,PACKED_ICE:0)
Block(-5,3,-3,ICE:0)
Block(-5,3,-2,ICE:0)
Block(-5,3,-1,ICE:0)
Block(-5,3,0,ICE:0)
Block(-5,3,1,PACKED_ICE:0)
Block(-5,3,2,PACKED_ICE:0)
Block(-5,3,3,PACKED_ICE:0)
Block(-5,3,4,PACKED_ICE:0)
Block(-4,0,-7,PACKED_ICE:0)
Block(-4,0,-6,PACKED_ICE:0)
Block(-4,0,-5,PACKED_ICE:0)
Block(-4,0,-4,PACKED_ICE:0)
Block(-4,0,-3,PACKED_ICE:0)
Block(-4,0,-2,PACKED_ICE:0)
Block(-4,0,-1,PACKED_ICE:0)
Block(-4,0,0,PACKED_ICE:0)
Block(-4,0,1,PACKED_ICE:0)
Block(-4,0,2,PACKED_ICE:0)
Block(-4,0,3,PACKED_ICE:0)
Block(-4,0,4,PACKED_ICE:0)
Block(-4,0,5,PACKED_ICE:0)
Block(-4,0,6,ICE:0)
Block(-4,0,7,ICE:0)
Block(-4,1,-7,PACKED_ICE:0)
Block(-4,1,-6,PACKED_ICE:0)
Block(-4,1,-5,PACKED_ICE:0)
Block(-4,1,-4,PACKED_ICE:0)
Block(-4,1,-3,PACKED_ICE:0)
Block(-4,1,-2,PACKED_ICE:0)
Block(-4,1,-1,PACKED_ICE:0)
Block(-4,1,0,PACKED_ICE:0)
Block(-4,1,1,PACKED_ICE:0)
Block(-4,1,2,PACKED_ICE:0)
Block(-4,1,3,PACKED_ICE:0)
Block(-4,1,4,PACKED_ICE:0)
Block(-4,1,5,PACKED_ICE:0)
Block(-4,1,6,PACKED_ICE:0)
Block(-4,1,7,ICE:0)
Block(-4,2,-7,PACKED_ICE:0)
Block(-4,2,-6,PACKED_ICE:0)
Block(-4,2,-5,PACKED_ICE:0)
Block(-4,2,-4,PACKED_ICE:0)
Block(-4,2,-3,PACKED_ICE:0)
Block(-4,2,-2,PACKED_ICE:0)
Block(-4,2,-1,ICE:0)
Block(-4,2,0,PACKED_ICE:0)
Block(-4,2,1,PACKED_ICE:0)
Block(-4,2,2,PACKED_ICE:0)
Block(-4,2,3,PACKED_ICE:0)
Block(-4,2,4,PACKED_ICE:0)
Block(-4,2,5,PACKED_ICE:0)
Block(-4,2,6,ICE:0)
Block(-4,2,7,ICE:0)
Block(-4,3,-7,PACKED_ICE:0)
Block(-4,3,-6,PACKED_ICE:0)
Block(-4,3,-5,PACKED_ICE:0)
Block(-4,3,-4,ICE:0)
Block(-4,3,-3,ICE:0)
Block(-4,3,-2,ICE:0)
Block(-4,3,-1,ICE:0)
Block(-4,3,0,ICE:0)
Block(-4,3,1,PACKED_ICE:0)
Block(-4,3,2,PACKED_ICE:0)
Block(-4,3,3,PACKED_ICE:0)
Block(-4,3,4,PACKED_ICE:0)
Block(-4,3,5,PACKED_ICE:0)
Block(-4,4,-7,PACKED_ICE:0)
Block(-4,4,-6,PACKED_ICE:0)
Block(-4,4,-5,PACKED_ICE:0)
Block(-4,4,-4,ICE:0)
Block(-4,4,-3,ICE:0)
Block(-4,4,-2,ICE:0)
Block(-4,4,-1,ICE:0)
Block(-4,4,0,PACKED_ICE:0)
Block(-4,4,1,PACKED_ICE:0)
Block(-4,4,2,PACKED_ICE:0)
Block(-4,4,3,PACKED_ICE:0)
Block(-3,0,-8,ICE:0)
Block(-3,0,-7,PACKED_ICE:0)
Block(-3,0,-6,PACKED_ICE:0)
Block(-3,0,-5,PACKED_ICE:0)
Block(-3,0,-4,PACKED_ICE:0)
Block(-3,0,-3,PACKED_ICE:0)
Block(-3,0,-2,PACKED_ICE:0)
Block(-3,0,-1,PACKED_ICE:0)
Block(-3,0,0,PACKED_ICE:0)
Block(-3,0,1,PACKED_ICE:0)
Block(-3,0,2,PACKED_ICE:0)
Block(-3,0,3,PACKED_ICE:0)
Block(-3,0,4,PACKED_ICE:0)
Block(-3,0,5,PACKED_ICE:0)
Block(-3,0,6,ICE:0)
Block(-3,0,7,ICE:0)
Block(-3,1,-8,ICE:0)
Block(-3,1,-7,ICE:0)
Block(-3,1,-6,PACKED_ICE:0)
Block(-3,1,-5,PACKED_ICE:0)
Block(-3,1,-4,PACKED_ICE:0)
Block(-3,1,-3,PACKED_ICE:0)
Block(-3,1,-2,PACKED_ICE:0)
Block(-3,1,-1,PACKED_ICE:0)
Block(-3,1,0,PACKED_ICE:0)
Block(-3,1,1,PACKED_ICE:0)
Block(-3,1,2,PACKED_ICE:0)
Block(-3,1,3,PACKED_ICE:0)
Block(-3,1,4,PACKED_ICE:0)
Block(-3,1,5,PACKED_ICE:0)
Block(-3,1,6,ICE:0)
Block(-3,1,7,ICE:0)
Block(-3,2,-8,ICE:0)
Block(-3,2,-7,ICE:0)
Block(-3,2,-6,PACKED_ICE:0)
Block(-3,2,-5,PACKED_ICE:0)
Block(-3,2,-4,PACKED_ICE:0)
Block(-3,2,-3,PACKED_ICE:0)
Block(-3,2,-2,PACKED_ICE:0)
Block(-3,2,-1,PACKED_ICE:0)
Block(-3,2,0,PACKED_ICE:0)
Block(-3,2,1,PACKED_ICE:0)
Block(-3,2,2,PACKED_ICE:0)
Block(-3,2,3,PACKED_ICE:0)
Block(-3,2,4,PACKED_ICE:0)
Block(-3,2,5,PACKED_ICE:0)
Block(-3,2,6,ICE:0)
Block(-3,2,7,ICE:0)
Block(-3,3,-8,ICE:0)
Block(-3,3,-7,PACKED_ICE:0)
Block(-3,3,-6,PACKED_ICE:0)
Block(-3,3,-5,PACKED_ICE:0)
Block(-3,3,-4,PACKED_ICE:0)
Block(-3,3,-3,ICE:0)
Block(-3,3,-2,PACKED_ICE:0)
Block(-3,3,-1,PACKED_ICE:0)
Block(-3,3,0,PACKED_ICE:0)
Block(-3,3,1,PACKED_ICE:0)
Block(-3,3,2,PACKED_ICE:0)
Block(-3,3,3,PACKED_ICE:0)
Block(-3,3,4,PACKED_ICE:0)
Block(-3,3,5,ICE:0)
Block(-3,3,6,ICE:0)
Block(-3,4,-8,PACKED_ICE:0)
Block(-3,4,-7,PACKED_ICE:0)
Block(-3,4,-6,PACKED_ICE:0)
Block(-3,4,-5,ICE:0)
Block(-3,4,-4,ICE:0)
Block(-3,4,-3,ICE:0)
Block(-3,4,-2,ICE:0)
Block(-3,4,-1,PACKED_ICE:0)
Block(-3,4,0,PACKED_ICE:0)
Block(-3,4,1,PACKED_ICE:0)
Block(-3,4,2,PACKED_ICE:0)
Block(-3,4,3,PACKED_ICE:0)
Block(-3,4,4,PACKED_ICE:0)
Block(-3,5,-8,ICE:0)
Block(-3,5,-7,PACKED_ICE:0)
Block(-3,5,-6,ICE:0)
Block(-3,5,-5,ICE:0)
Block(-3,5,-4,ICE:0)
Block(-3,5,-3,ICE:0)
Block(-3,5,-2,PACKED_ICE:0)
Block(-3,5,-1,PACKED_ICE:0)
Block(-3,5,0,PACKED_ICE:0)
Block(-3,5,1,PACKED_ICE:0)
Block(-3,5,2,PACKED_ICE:0)
Block(-3,5,3,PACKED_ICE:0)
Block(-2,0,-8,ICE:0)
Block(-2,0,-7,ICE:0)
Block(-2,0,-6,PACKED_ICE:0)
Block(-2,0,-5,PACKED_ICE:0)
Block(-2,0,-4,PACKED_ICE:0)
Block(-2,0,-3,PACKED_ICE:0)
Block(-2,0,-2,PACKED_ICE:0)
Block(-2,0,-1,PACKED_ICE:0)
Block(-2,0,0,PACKED_ICE:0)
Block(-2,0,1,PACKED_ICE:0)
Block(-2,0,2,PACKED_ICE:0)
Block(-2,0,3,PACKED_ICE:0)
Block(-2,0,4,PACKED_ICE:0)
Block(-2,0,5,PACKED_ICE:0)
Block(-2,0,6,ICE:0)
Block(-2,0,7,ICE:0)
Block(-2,0,8,ICE:0)
Block(-2,0,9,PACKED_ICE:0)
Block(-2,1,-8,ICE:0)
Block(-2,1,-7,ICE:0)
Block(-2,1,-6,PACKED_ICE:0)
Block(-2,1,-5,PACKED_ICE:0)
Block(-2,1,-4,PACKED_ICE:0)
Block(-2,1,-3,PACKED_ICE:0)
Block(-2,1,-2,PACKED_ICE:0)
Block(-2,1,-1,PACKED_ICE:0)
Block(-2,1,0,PACKED_ICE:0)
Block(-2,1,1,PACKED_ICE:0)
Block(-2,1,2,PACKED_ICE:0)
Block(-2,1,3,PACKED_ICE:0)
Block(-2,1,4,PACKED_ICE:0)
Block(-2,1,5,PACKED_ICE:0)
Block(-2,1,6,PACKED_ICE:0)
Block(-2,1,7,ICE:0)
Block(-2,1,8,PACKED_ICE:0)
Block(-2,1,9,PACKED_ICE:0)
Block(-2,2,-8,ICE:0)
Block(-2,2,-7,ICE:0)
Block(-2,2,-6,PACKED_ICE:0)
Block(-2,2,-5,PACKED_ICE:0)
Block(-2,2,-4,PACKED_ICE:0)
Block(-2,2,-3,PACKED_ICE:0)
Block(-2,2,-2,PACKED_ICE:0)
Block(-2,2,-1,PACKED_ICE:0)
Block(-2,2,0,PACKED_ICE:0)
Block(-2,2,1,PACKED_ICE:0)
Block(-2,2,2,PACKED_ICE:0)
Block(-2,2,3,PACKED_ICE:0)
Block(-2,2,4,PACKED_ICE:0)
Block(-2,2,5,ICE:0)
Block(-2,2,6,ICE:0)
Block(-2,2,7,ICE:0)
Block(-2,2,8,ICE:0)
Block(-2,2,9,PACKED_ICE:0)
Block(-2,3,-8,ICE:0)
Block(-2,3,-7,ICE:0)
Block(-2,3,-6,PACKED_ICE:0)
Block(-2,3,-5,PACKED_ICE:0)
Block(-2,3,-4,PACKED_ICE:0)
Block(-2,3,-3,PACKED_ICE:0)
Block(-2,3,-2,PACKED_ICE:0)
Block(-2,3,-1,PACKED_ICE:0)
Block(-2,3,0,PACKED_ICE:0)
Block(-2,3,1,PACKED_ICE:0)
Block(-2,3,2,PACKED_ICE:0)
Block(-2,3,3,PACKED_ICE:0)
Block(-2,3,4,PACKED_ICE:0)
Block(-2,3,5,ICE:0)
Block(-2,3,6,ICE:0)
Block(-2,3,7,ICE:0)
Block(-2,4,-8,ICE:0)
Block(-2,4,-7,ICE:0)
Block(-2,4,-6,PACKED_ICE:0)
Block(-2,4,-5,PACKED_ICE:0)
Block(-2,4,-4,ICE:0)
Block(-2,4,-3,PACKED_ICE:0)
Block(-2,4,-2,PACKED_ICE:0)
Block(-2,4,-1,PACKED_ICE:0)
Block(-2,4,0,PACKED_ICE:0)
Block(-2,4,1,PACKED_ICE:0)
Block(-2,4,2,PACKED_ICE:0)
Block(-2,4,3,PACKED_ICE:0)
Block(-2,4,4,ICE:0)
Block(-2,4,5,ICE:0)
Block(-2,5,-8,ICE:0)
Block(-2,5,-7,ICE:0)
Block(-2,5,-6,ICE:0)
Block(-2,5,-5,ICE:0)
Block(-2,5,-4,ICE:0)
Block(-2,5,-3,ICE:0)
Block(-2,5,-2,PACKED_ICE:0)
Block(-2,5,-1,PACKED_ICE:0)
Block(-2,5,0,PACKED_ICE:0)
Block(-2,5,1,PACKED_ICE:0)
Block(-2,5,2,PACKED_ICE:0)
Block(-2,5,3,PACKED_ICE:0)
Block(-2,5,4,ICE:0)
Block(-2,6,-8,ICE:0)
Block(-2,6,-7,ICE:0)
Block(-2,6,-6,ICE:0)
Block(-2,6,-5,ICE:0)
Block(-2,6,-4,ICE:0)
Block(-2,6,-3,PACKED_ICE:0)
Block(-2,6,-2,PACKED_ICE:0)
Block(-2,6,-1,PACKED_ICE:0)
Block(-2,6,0,PACKED_ICE:0)
Block(-2,6,1,PACKED_ICE:0)
Block(-2,6,2,PACKED_ICE:0)
Block(-1,0,-9,ICE:0)
Block(-1,0,-8,ICE:0)
Block(-1,0,-7,PACKED_ICE:0)
Block(-1,0,-6,PACKED_ICE:0)
Block(-1,0,-5,PACKED_ICE:0)
Block(-1,0,-4,PACKED_ICE:0)
Block(-1,0,-3,PACKED_ICE:0)
Block(-1,0,-2,PACKED_ICE:0)
Block(-1,0,-1,PACKED_ICE:0)
Block(-1,0,0,PACKED_ICE:0)
Block(-1,0,1,PACKED_ICE:0)
Block(-1,0,2,PACKED_ICE:0)
Block(-1,0,3,PACKED_ICE:0)
Block(-1,0,4,PACKED_ICE:0)
Block(-1,0,5,PACKED_ICE:0)
Block(-1,0,6,PACKED_ICE:0)
Block(-1,1,-9,ICE:0)
Block(-1,1,-8,ICE:0)
Block(-1,1,-7,ICE:0)
Block(-1,1,-6,PACKED_ICE:0)
Block(-1,1,-5,PACKED_ICE:0)
Block(-1,1,-4,PACKED_ICE:0)
Block(-1,1,-3,PACKED_ICE:0)
Block(-1,1,-2,PACKED_ICE:0)
Block(-1,1,-1,PACKED_ICE:0)
Block(-1,1,0,PACKED_ICE:0)
Block(-1,1,1,PACKED_ICE:0)
Block(-1,1,2,PACKED_ICE:0)
Block(-1,1,3,PACKED_ICE:0)
Block(-1,1,4,PACKED_ICE:0)
Block(-1,1,5,PACKED_ICE:0)
Block(-1,1,6,PACKED_ICE:0)
Block(-1,2,-9,ICE:0)
Block(-1,2,-8,ICE:0)
Block(-1,2,-7,ICE:0)
Block(-1,2,-6,PACKED_ICE:0)
Block(-1,2,-5,PACKED_ICE:0)
Block(-1,2,-4,PACKED_ICE:0)
Block(-1,2,-3,PACKED_ICE:0)
Block(-1,2,-2,PACKED_ICE:0)
Block(-1,2,-1,PACKED_ICE:0)
Block(-1,2,0,PACKED_ICE:0)
Block(-1,2,1,PACKED_ICE:0)
Block(-1,2,2,PACKED_ICE:0)
Block(-1,2,3,PACKED_ICE:0)
Block(-1,2,4,PACKED_ICE:0)
Block(-1,2,5,PACKED_ICE:0)
Block(-1,2,6,ICE:0)
Block(-1,3,-8,ICE:0)
Block(-1,3,-7,ICE:0)
Block(-1,3,-6,PACKED_ICE:0)
Block(-1,3,-5,PACKED_ICE:0)
Block(-1,3,-4,PACKED_ICE:0)
Block(-1,3,-3,PACKED_ICE:0)
Block(-1,3,-2,PACKED_ICE:0)
Block(-1,3,-1,PACKED_ICE:0)
Block(-1,3,0,PACKED_ICE:0)
Block(-1,3,1,PACKED_ICE:0)
Block(-1,3,2,PACKED_ICE:0)
Block(-1,3,3,PACKED_ICE:0)
Block(-1,3,4,ICE:0)
Block(-1,3,5,ICE:0)
Block(-1,3,6,ICE:0)
Block(-1,3,7,ICE:0)
Block(-1,4,-8,ICE:0)
Block(-1,4,-7,ICE:0)
Block(-1,4,-6,PACKED_ICE:0)
Block(-1,4,-5,PACKED_ICE:0)
Block(-1,4,-4,PACKED_ICE:0)
Block(-1,4,-3,PACKED_ICE:0)
Block(-1,4,-2,PACKED_ICE:0)
Block(-1,4,-1,PACKED_ICE:0)
Block(-1,4,0,PACKED_ICE:0)
Block(-1,4,1,PACKED_ICE:0)
Block(-1,4,2,PACKED_ICE:0)
Block(-1,4,3,PACKED_ICE:0)
Block(-1,4,4,ICE:0)
Block(-1,4,5,ICE:0)
Block(-1,4,6,ICE:0)
Block(-1,5,-8,ICE:0)
Block(-1,5,-7,ICE:0)
Block(-1,5,-6,ICE:0)
Block(-1,5,-5,PACKED_ICE:0)
Block(-1,5,-4,PACKED_ICE:0)
Block(-1,5,-3,PACKED_ICE:0)
Block(-1,5,-2,PACKED_ICE:0)
Block(-1,5,-1,PACKED_ICE:0)
Block(-1,5,0,PACKED_ICE:0)
Block(-1,5,1,PACKED_ICE:0)
Block(-1,5,2,PACKED_ICE:0)
Block(-1,5,3,PACKED_ICE:0)
Block(-1,5,4,ICE:0)
Block(-1,5,5,ICE:0)
Block(-1,6,-8,ICE:0)
Block(-1,6,-7,ICE:0)
Block(-1,6,-6,ICE:0)
Block(-1,6,-5,ICE:0)
Block(-1,6,-4,PACKED_ICE:0)
Block(-1,6,-3,PACKED_ICE:0)
Block(-1,6,-2,PACKED_ICE:0)
Block(-1,6,-1,PACKED_ICE:0)
Block(-1,6,0,PACKED_ICE:0)
Block(-1,6,1,PACKED_ICE:0)
Block(-1,6,2,PACKED_ICE:0)
Block(-1,6,3,ICE:0)
Block(-1,7,-8,ICE:0)
Block(-1,7,-7,ICE:0)
Block(-1,7,-6,ICE:0)
Block(-1,7,-5,PACKED_ICE:0)
Block(-1,7,-4,PACKED_ICE:0)
Block(-1,7,-3,PACKED_ICE:0)
Block(-1,7,-2,PACKED_ICE:0)
Block(-1,7,-1,PACKED_ICE:0)
Block(-1,7,0,PACKED_ICE:0)
Block(-1,7,1,PACKED_ICE:0)
Block(-1,7,2,ICE:0)
Block(-1,8,-8,ICE:0)
Block(-1,8,-7,ICE:0)
Block(-1,8,-6,ICE:0)
Block(-1,8,-5,PACKED_ICE:0)
Block(-1,8,-4,PACKED_ICE:0)
Block(-1,8,-3,PACKED_ICE:0)
Block(-1,8,-2,PACKED_ICE:0)
Block(-1,8,-1,PACKED_ICE:0)
Block(-1,8,0,PACKED_ICE:0)
Block(0,0,-8,ICE:0)
Block(0,0,-7,ICE:0)
Block(0,0,-6,ICE:0)
Block(0,0,-5,PACKED_ICE:0)
Block(0,0,-4,PACKED_ICE:0)
Block(0,0,-3,PACKED_ICE:0)
Block(0,0,-2,PACKED_ICE:0)
Block(0,0,-1,PACKED_ICE:0)
Block(0,0,0,PACKED_ICE:0)
Block(0,0,1,PACKED_ICE:0)
Block(0,0,2,PACKED_ICE:0)
Block(0,0,3,PACKED_ICE:0)
Block(0,0,4,PACKED_ICE:0)
Block(0,1,-8,ICE:0)
Block(0,1,-7,ICE:0)
Block(0,1,-6,ICE:0)
Block(0,1,-5,PACKED_ICE:0)
Block(0,1,-4,PACKED_ICE:0)
Block(0,1,-3,PACKED_ICE:0)
Block(0,1,-2,PACKED_ICE:0)
Block(0,1,-1,PACKED_ICE:0)
Block(0,1,0,PACKED_ICE:0)
Block(0,1,1,PACKED_ICE:0)
Block(0,1,2,PACKED_ICE:0)
Block(0,1,3,PACKED_ICE:0)
Block(0,1,4,PACKED_ICE:0)
Block(0,2,-8,ICE:0)
Block(0,2,-7,ICE:0)
Block(0,2,-6,PACKED_ICE:0)
Block(0,2,-5,PACKED_ICE:0)
Block(0,2,-4,PACKED_ICE:0)
Block(0,2,-3,PACKED_ICE:0)
Block(0,2,-2,PACKED_ICE:0)
Block(0,2,-1,PACKED_ICE:0)
Block(0,2,0,PACKED_ICE:0)
Block(0,2,1,PACKED_ICE:0)
Block(0,2,2,PACKED_ICE:0)
Block(0,2,3,PACKED_ICE:0)
Block(0,2,4,PACKED_ICE:0)
Block(0,3,-8,ICE:0)
Block(0,3,-7,PACKED_ICE:0)
Block(0,3,-6,PACKED_ICE:0)
Block(0,3,-5,PACKED_ICE:0)
Block(0,3,-4,PACKED_ICE:0)
Block(0,3,-3,PACKED_ICE:0)
Block(0,3,-2,PACKED_ICE:0)
Block(0,3,-1,PACKED_ICE:0)
Block(0,3,0,PACKED_ICE:0)
Block(0,3,1,PACKED_ICE:0)
Block(0,3,2,PACKED_ICE:0)
Block(0,3,3,PACKED_ICE:0)
Block(0,3,4,PACKED_ICE:0)
Block(0,3,5,ICE:0)
Block(0,4,-9,ICE:0)
Block(0,4,-8,ICE:0)
Block(0,4,-7,ICE:0)
Block(0,4,-6,PACKED_ICE:0)
Block(0,4,-5,PACKED_ICE:0)
Block(0,4,-4,PACKED_ICE:0)
Block(0,4,-3,PACKED_ICE:0)
Block(0,4,-2,PACKED_ICE:0)
Block(0,4,-1,PACKED_ICE:0)
Block(0,4,0,PACKED_ICE:0)
Block(0,4,1,PACKED_ICE:0)
Block(0,4,2,PACKED_ICE:0)
Block(0,4,3,PACKED_ICE:0)
Block(0,4,4,ICE:0)
Block(0,4,5,ICE:0)
Block(0,5,-9,PACKED_ICE:0)
Block(0,5,-8,ICE:0)
Block(0,5,-7,ICE:0)
Block(0,5,-6,PACKED_ICE:0)
Block(0,5,-5,PACKED_ICE:0)
Block(0,5,-4,PACKED_ICE:0)
Block(0,5,-3,PACKED_ICE:0)
Block(0,5,-2,PACKED_ICE:0)
Block(0,5,-1,PACKED_ICE:0)
Block(0,5,0,PACKED_ICE:0)
Block(0,5,1,PACKED_ICE:0)
Block(0,5,2,PACKED_ICE:0)
Block(0,5,3,ICE:0)
Block(0,5,4,ICE:0)
Block(0,5,5,ICE:0)
Block(0,5,6,ICE:0)
Block(0,6,-9,ICE:0)
Block(0,6,-8,ICE:0)
Block(0,6,-7,ICE:0)
Block(0,6,-6,ICE:0)
Block(0,6,-5,PACKED_ICE:0)
Block(0,6,-4,PACKED_ICE:0)
Block(0,6,-3,PACKED_ICE:0)
Block(0,6,-2,PACKED_ICE:0)
Block(0,6,-1,PACKED_ICE:0)
Block(0,6,0,PACKED_ICE:0)
Block(0,6,1,PACKED_ICE:0)
Block(0,6,2,ICE:0)
Block(0,6,3,ICE:0)
Block(0,6,4,ICE:0)
Block(0,7,-9,ICE:0)
Block(0,7,-8,ICE:0)
Block(0,7,-7,ICE:0)
Block(0,7,-6,PACKED_ICE:0)
Block(0,7,-5,PACKED_ICE:0)
Block(0,7,-4,PACKED_ICE:0)
Block(0,7,-3,PACKED_ICE:0)
Block(0,7,-2,PACKED_ICE:0)
Block(0,7,-1,PACKED_ICE:0)
Block(0,7,0,PACKED_ICE:0)
Block(0,7,1,PACKED_ICE:0)
Block(0,7,2,ICE:0)
Block(0,7,3,ICE:0)
Block(0,8,-9,ICE:0)
Block(0,8,-8,ICE:0)
Block(0,8,-7,ICE:0)
Block(0,8,-6,ICE:0)
Block(0,8,-5,ICE:0)
Block(0,8,-4,PACKED_ICE:0)
Block(0,8,-3,PACKED_ICE:0)
Block(0,8,-2,PACKED_ICE:0)
Block(0,8,-1,PACKED_ICE:0)
Block(0,8,0,PACKED_ICE:0)
Block(0,8,1,ICE:0)
Block(0,9,-9,ICE:0)
Block(0,9,-8,ICE:0)
Block(0,9,-7,ICE:0)
Block(0,9,-6,ICE:0)
Block(0,9,-5,ICE:0)
Block(0,9,-4,PACKED_ICE:0)
Block(0,9,-3,PACKED_ICE:0)
Block(0,9,-2,PACKED_ICE:0)
Block(0,9,-1,PACKED_ICE:0)
Block(0,9,0,PACKED_ICE:0)
Block(1,0,-7,ICE:0)
Block(1,0,-6,ICE:0)
Block(1,0,-5,PACKED_ICE:0)
Block(1,0,-4,PACKED_ICE:0)
Block(1,0,-3,PACKED_ICE:0)
Block(1,0,-2,PACKED_ICE:0)
Block(1,0,-1,PACKED_ICE:0)
Block(1,0,0,PACKED_ICE:0)
Block(1,0,1,PACKED_ICE:0)
Block(1,0,2,PACKED_ICE:0)
Block(1,1,-7,ICE:0)
Block(1,1,-6,ICE:0)
Block(1,1,-5,PACKED_ICE:0)
Block(1,1,-4,PACKED_ICE:0)
Block(1,1,-3,PACKED_ICE:0)
Block(1,1,-2,PACKED_ICE:0)
Block(1,1,-1,PACKED_ICE:0)
Block(1,1,0,PACKED_ICE:0)
Block(1,1,1,PACKED_ICE:0)
Block(1,1,2,PACKED_ICE:0)
Block(1,2,-7,ICE:0)
Block(1,2,-6,ICE:0)
Block(1,2,-5,PACKED_ICE:0)
Block(1,2,-4,PACKED_ICE:0)
Block(1,2,-3,PACKED_ICE:0)
Block(1,2,-2,PACKED_ICE:0)
Block(1,2,-1,PACKED_ICE:0)
Block(1,2,0,PACKED_ICE:0)
Block(1,2,1,PACKED_ICE:0)
Block(1,2,2,PACKED_ICE:0)
Block(1,3,-8,ICE:0)
Block(1,3,-7,ICE:0)
Block(1,3,-6,ICE:0)
Block(1,3,-5,PACKED_ICE:0)
Block(1,3,-4,PACKED_ICE:0)
Block(1,3,-3,PACKED_ICE:0)
Block(1,3,-2,PACKED_ICE:0)
Block(1,3,-1,PACKED_ICE:0)
Block(1,3,0,PACKED_ICE:0)
Block(1,3,1,PACKED_ICE:0)
Block(1,3,2,PACKED_ICE:0)
Block(1,4,-8,PACKED_ICE:0)
Block(1,4,-7,ICE:0)
Block(1,4,-6,PACKED_ICE:0)
Block(1,4,-5,PACKED_ICE:0)
Block(1,4,-4,PACKED_ICE:0)
Block(1,4,-3,PACKED_ICE:0)
Block(1,4,-2,PACKED_ICE:0)
Block(1,4,-1,PACKED_ICE:0)
Block(1,4,0,PACKED_ICE:0)
Block(1,4,1,PACKED_ICE:0)
Block(1,4,2,PACKED_ICE:0)
Block(1,4,3,PACKED_ICE:0)
Block(1,5,-9,PACKED_ICE:0)
Block(1,5,-8,PACKED_ICE:0)
Block(1,5,-7,PACKED_ICE:0)
Block(1,5,-6,PACKED_ICE:0)
Block(1,5,-5,PACKED_ICE:0)
Block(1,5,-4,PACKED_ICE:0)
Block(1,5,-3,PACKED_ICE:0)
Block(1,5,-2,PACKED_ICE:0)
Block(1,5,-1,PACKED_ICE:0)
Block(1,5,0,PACKED_ICE:0)
Block(1,5,1,PACKED_ICE:0)
Block(1,5,2,PACKED_ICE:0)
Block(1,5,3,PACKED_ICE:0)
Block(1,5,4,ICE:0)
Block(1,6,-9,PACKED_ICE:0)
Block(1,6,-8,PACKED_ICE:0)
Block(1,6,-7,PACKED_ICE:0)
Block(1,6,-6,PACKED_ICE:0)
Block(1,6,-5,PACKED_ICE:0)
Block(1,6,-4,PACKED_ICE:0)
Block(1,6,-3,PACKED_ICE:0)
Block(1,6,-2,PACKED_ICE:0)
Block(1,6,-1,PACKED_ICE:0)
Block(1,6,0,PACKED_ICE:0)
Block(1,6,1,PACKED_ICE:0)
Block(1,6,2,PACKED_ICE:0)
Block(1,6,3,ICE:0)
Block(1,6,4,ICE:0)
Block(1,7,-9,PACKED_ICE:0)
Block(1,7,-8,PACKED_ICE:0)
Block(1,7,-7,PACKED_ICE:0)
Block(1,7,-6,PACKED_ICE:0)
Block(1,7,-5,PACKED_ICE:0)
Block(1,7,-4,PACKED_ICE:0)
Block(1,7,-3,PACKED_ICE:0)
Block(1,7,-2,PACKED_ICE:0)
Block(1,7,-1,PACKED_ICE:0)
Block(1,7,0,PACKED_ICE:0)
Block(1,7,1,ICE:0)
Block(1,7,2,ICE:0)
Block(1,7,3,ICE:0)
Block(1,7,4,ICE:0)
Block(1,8,-9,PACKED_ICE:0)
Block(1,8,-8,ICE:0)
Block(1,8,-7,ICE:0)
Block(1,8,-6,ICE:0)
Block(1,8,-5,PACKED_ICE:0)
Block(1,8,-4,PACKED_ICE:0)
Block(1,8,-3,PACKED_ICE:0)
Block(1,8,-2,PACKED_ICE:0)
Block(1,8,-1,PACKED_ICE:0)
Block(1,8,0,PACKED_ICE:0)
Block(1,8,1,ICE:0)
Block(1,8,2,ICE:0)
Block(1,9,-9,ICE:0)
Block(1,9,-8,ICE:0)
Block(1,9,-7,ICE:0)
Block(1,9,-6,ICE:0)
Block(1,9,-5,ICE:0)
Block(1,9,-4,ICE:0)
Block(1,9,-3,PACKED_ICE:0)
Block(1,9,-2,PACKED_ICE:0)
Block(1,9,-1,PACKED_ICE:0)
Block(1,9,0,ICE:0)
Block(1,9,1,ICE:0)
Block(1,10,-9,PACKED_ICE:0)
Block(1,10,-8,ICE:0)
Block(1,10,-7,ICE:0)
Block(1,10,-6,ICE:0)
Block(1,10,-5,ICE:0)
Block(1,10,-4,ICE:0)
Block(1,10,-3,PACKED_ICE:0)
Block(1,10,-2,PACKED_ICE:0)
Block(1,10,-1,PACKED_ICE:0)
Block(2,0,-6,ICE:0)
Block(2,0,-5,PACKED_ICE:0)
Block(2,0,-4,PACKED_ICE:0)
Block(2,0,-3,PACKED_ICE:0)
Block(2,0,-2,PACKED_ICE:0)
Block(2,0,-1,PACKED_ICE:0)
Block(2,1,-6,ICE:0)
Block(2,1,-5,PACKED_ICE:0)
Block(2,1,-4,PACKED_ICE:0)
Block(2,1,-3,PACKED_ICE:0)
Block(2,1,-2,PACKED_ICE:0)
Block(2,1,-1,PACKED_ICE:0)
Block(2,2,-6,ICE:0)
Block(2,2,-5,PACKED_ICE:0)
Block(2,2,-4,PACKED_ICE:0)
Block(2,2,-3,PACKED_ICE:0)
Block(2,2,-2,PACKED_ICE:0)
Block(2,2,-1,PACKED_ICE:0)
Block(2,3,-7,ICE:0)
Block(2,3,-6,ICE:0)
Block(2,3,-5,PACKED_ICE:0)
Block(2,3,-4,PACKED_ICE:0)
Block(2,3,-3,PACKED_ICE:0)
Block(2,3,-2,PACKED_ICE:0)
Block(2,3,-1,PACKED_ICE:0)
Block(2,3,0,PACKED_ICE:0)
Block(2,4,-8,ICE:0)
Block(2,4,-7,ICE:0)
Block(2,4,-6,ICE:0)
Block(2,4,-5,PACKED_ICE:0)
Block(2,4,-4,PACKED_ICE:0)
Block(2,4,-3,PACKED_ICE:0)
Block(2,4,-2,PACKED_ICE:0)
Block(2,4,-1,PACKED_ICE:0)
Block(2,4,0,PACKED_ICE:0)
Block(2,4,1,PACKED_ICE:0)
Block(2,5,-8,PACKED_ICE:0)
Block(2,5,-7,PACKED_ICE:0)
Block(2,5,-6,PACKED_ICE:0)
Block(2,5,-5,PACKED_ICE:0)
Block(2,5,-4,PACKED_ICE:0)
Block(2,5,-3,PACKED_ICE:0)
Block(2,5,-2,PACKED_ICE:0)
Block(2,5,-1,PACKED_ICE:0)
Block(2,5,0,PACKED_ICE:0)
Block(2,5,1,PACKED_ICE:0)
Block(2,6,-9,PACKED_ICE:0)
Block(2,6,-8,PACKED_ICE:0)
Block(2,6,-7,PACKED_ICE:0)
Block(2,6,-6,PACKED_ICE:0)
Block(2,6,-5,PACKED_ICE:0)
Block(2,6,-4,PACKED_ICE:0)
Block(2,6,-3,PACKED_ICE:0)
Block(2,6,-2,PACKED_ICE:0)
Block(2,6,-1,PACKED_ICE:0)
Block(2,6,0,PACKED_ICE:0)
Block(2,6,1,PACKED_ICE:0)
Block(2,6,2,PACKED_ICE:0)
Block(2,7,-10,PACKED_ICE:0)
Block(2,7,-9,PACKED_ICE:0)
Block(2,7,-8,PACKED_ICE:0)
Block(2,7,-7,PACKED_ICE:0)
Block(2,7,-6,PACKED_ICE:0)
Block(2,7,-5,PACKED_ICE:0)
Block(2,7,-4,PACKED_ICE:0)
Block(2,7,-3,PACKED_ICE:0)
Block(2,7,-2,PACKED_ICE:0)
Block(2,7,-1,PACKED_ICE:0)
Block(2,7,0,PACKED_ICE:0)
Block(2,7,1,PACKED_ICE:0)
Block(2,7,2,ICE:0)
Block(2,7,3,PACKED_ICE:0)
Block(2,8,-10,PACKED_ICE:0)
Block(2,8,-9,PACKED_ICE:0)
Block(2,8,-8,PACKED_ICE:0)
Block(2,8,-7,PACKED_ICE:0)
Block(2,8,-6,PACKED_ICE:0)
Block(2,8,-5,PACKED_ICE:0)
Block(2,8,-4,PACKED_ICE:0)
Block(2,8,-3,PACKED_ICE:0)
Block(2,8,-2,PACKED_ICE:0)
Block(2,8,-1,PACKED_ICE:0)
Block(2,8,0,ICE:0)
Block(2,8,1,ICE:0)
Block(2,8,2,ICE:0)
Block(2,8,3,ICE:0)
Block(2,9,-9,PACKED_ICE:0)
Block(2,9,-8,PACKED_ICE:0)
Block(2,9,-7,PACKED_ICE:0)
Block(2,9,-6,ICE:0)
Block(2,9,-5,ICE:0)
Block(2,9,-4,PACKED_ICE:0)
Block(2,9,-3,PACKED_ICE:0)
Block(2,9,-2,PACKED_ICE:0)
Block(2,9,-1,PACKED_ICE:0)
Block(2,9,0,ICE:0)
Block(2,9,1,ICE:0)
Block(2,9,2,ICE:0)
Block(2,10,-9,PACKED_ICE:0)
Block(2,10,-8,PACKED_ICE:0)
Block(2,10,-7,ICE:0)
Block(2,10,-6,ICE:0)
Block(2,10,-5,ICE:0)
Block(2,10,-4,ICE:0)
Block(2,10,-3,PACKED_ICE:0)
Block(2,10,-2,PACKED_ICE:0)
Block(2,10,-1,ICE:0)
Block(2,10,0,ICE:0)
Block(2,11,-9,PACKED_ICE:0)
Block(2,11,-8,PACKED_ICE:0)
Block(2,11,-7,ICE:0)
Block(2,11,-6,ICE:0)
Block(2,11,-5,ICE:0)
Block(2,11,-4,ICE:0)
Block(2,11,-3,PACKED_ICE:0)
Block(2,11,-2,PACKED_ICE:0)
Block(2,11,-1,ICE:0)
Block(3,0,-5,PACKED_ICE:0)
Block(3,0,-4,PACKED_ICE:0)
Block(3,0,-3,PACKED_ICE:0)
Block(3,1,-5,PACKED_ICE:0)
Block(3,1,-4,PACKED_ICE:0)
Block(3,1,-3,PACKED_ICE:0)
Block(3,2,-5,PACKED_ICE:0)
Block(3,2,-4,PACKED_ICE:0)
Block(3,2,-3,PACKED_ICE:0)
Block(3,3,-6,ICE:0)
Block(3,3,-5,PACKED_ICE:0)
Block(3,3,-4,PACKED_ICE:0)
Block(3,3,-3,PACKED_ICE:0)
Block(3,3,-2,PACKED_ICE:0)
Block(3,4,-7,ICE:0)
Block(3,4,-6,ICE:0)
Block(3,4,-5,ICE:0)
Block(3,4,-4,PACKED_ICE:0)
Block(3,4,-3,PACKED_ICE:0)
Block(3,4,-2,PACKED_ICE:0)
Block(3,5,-7,PACKED_ICE:0)
Block(3,5,-6,ICE:0)
Block(3,5,-5,PACKED_ICE:0)
Block(3,5,-4,PACKED_ICE:0)
Block(3,5,-3,PACKED_ICE:0)
Block(3,5,-2,PACKED_ICE:0)
Block(3,5,-1,PACKED_ICE:0)
Block(3,6,-8,PACKED_ICE:0)
Block(3,6,-7,PACKED_ICE:0)
Block(3,6,-6,PACKED_ICE:0)
Block(3,6,-5,PACKED_ICE:0)
Block(3,6,-4,PACKED_ICE:0)
Block(3,6,-3,PACKED_ICE:0)
Block(3,6,-2,PACKED_ICE:0)
Block(3,6,-1,PACKED_ICE:0)
Block(3,6,0,PACKED_ICE:0)
Block(3,7,-9,PACKED_ICE:0)
Block(3,7,-8,PACKED_ICE:0)
Block(3,7,-7,PACKED_ICE:0)
Block(3,7,-6,PACKED_ICE:0)
Block(3,7,-5,PACKED_ICE:0)
Block(3,7,-4,PACKED_ICE:0)
Block(3,7,-3,PACKED_ICE:0)
Block(3,7,-2,PACKED_ICE:0)
Block(3,7,-1,PACKED_ICE:0)
Block(3,7,0,PACKED_ICE:0)
Block(3,8,-10,PACKED_ICE:0)
Block(3,8,-9,PACKED_ICE:0)
Block(3,8,-8,PACKED_ICE:0)
Block(3,8,-7,PACKED_ICE:0)
Block(3,8,-6,PACKED_ICE:0)
Block(3,8,-5,PACKED_ICE:0)
Block(3,8,-4,PACKED_ICE:0)
Block(3,8,-3,PACKED_ICE:0)
Block(3,8,-2,PACKED_ICE:0)
Block(3,8,-1,PACKED_ICE:0)
Block(3,8,0,PACKED_ICE:0)
Block(3,8,1,ICE:0)
Block(3,9,-10,PACKED_ICE:0)
Block(3,9,-9,PACKED_ICE:0)
Block(3,9,-8,PACKED_ICE:0)
Block(3,9,-7,PACKED_ICE:0)
Block(3,9,-6,PACKED_ICE:0)
Block(3,9,-5,PACKED_ICE:0)
Block(3,9,-4,PACKED_ICE:0)
Block(3,9,-3,PACKED_ICE:0)
Block(3,9,-2,PACKED_ICE:0)
Block(3,9,-1,ICE:0)
Block(3,9,0,ICE:0)
Block(3,9,1,ICE:0)
Block(3,9,2,ICE:0)
Block(3,10,-10,PACKED_ICE:0)
Block(3,10,-9,PACKED_ICE:0)
Block(3,10,-8,PACKED_ICE:0)
Block(3,10,-7,PACKED_ICE:0)
Block(3,10,-6,ICE:0)
Block(3,10,-5,ICE:0)
Block(3,10,-4,PACKED_ICE:0)
Block(3,10,-3,PACKED_ICE:0)
Block(3,10,-2,PACKED_ICE:0)
Block(3,10,-1,ICE:0)
Block(3,10,0,ICE:0)
Block(3,10,1,ICE:0)
Block(3,11,-10,PACKED_ICE:0)
Block(3,11,-9,PACKED_ICE:0)
Block(3,11,-8,PACKED_ICE:0)
Block(3,11,-7,ICE:0)
Block(3,11,-6,ICE:0)
Block(3,11,-5,ICE:0)
Block(3,11,-4,ICE:0)
Block(3,11,-3,PACKED_ICE:0)
Block(3,11,-2,PACKED_ICE:0)
Block(3,11,-1,ICE:0)
Block(3,11,0,ICE:0)
Block(3,12,-10,PACKED_ICE:0)
Block(3,12,-9,PACKED_ICE:0)
Block(3,12,-8,PACKED_ICE:0)
Block(3,12,-7,PACKED_ICE:0)
Block(3,12,-6,ICE:0)
Block(3,12,-5,ICE:0)
Block(3,12,-4,ICE:0)
Block(3,12,-3,PACKED_ICE:0)
Block(3,12,-2,ICE:0)
Block(3,13,-10,PACKED_ICE:0)
Block(3,13,-9,PACKED_ICE:0)
Block(3,13,-8,PACKED_ICE:0)
Block(3,13,-7,PACKED_ICE:0)
Block(3,13,-6,ICE:0)
Block(3,13,-5,ICE:0)
Block(3,13,-4,ICE:0)
Block(4,0,-5,PACKED_ICE:0)
Block(4,1,-5,PACKED_ICE:0)
Block(4,2,-5,PACKED_ICE:0)
Block(4,3,-5,ICE:0)
Block(4,4,-6,ICE:0)
Block(4,4,-5,ICE:0)
Block(4,4,-4,PACKED_ICE:0)
Block(4,5,-7,ICE:0)
Block(4,5,-6,ICE:0)
Block(4,5,-5,ICE:0)
Block(4,5,-4,PACKED_ICE:0)
Block(4,5,-3,PACKED_ICE:0)
Block(4,6,-7,ICE:0)
Block(4,6,-6,ICE:0)
Block(4,6,-5,ICE:0)
Block(4,6,-4,PACKED_ICE:0)
Block(4,6,-3,PACKED_ICE:0)
Block(4,7,-8,PACKED_ICE:0)
Block(4,7,-7,ICE:0)
Block(4,7,-6,ICE:0)
Block(4,7,-5,ICE:0)
Block(4,7,-4,PACKED_ICE:0)
Block(4,7,-3,PACKED_ICE:0)
Block(4,7,-2,PACKED_ICE:0)
Block(4,8,-9,PACKED_ICE:0)
Block(4,8,-8,PACKED_ICE:0)
Block(4,8,-7,PACKED_ICE:0)
Block(4,8,-6,ICE:0)
Block(4,8,-5,PACKED_ICE:0)
Block(4,8,-4,PACKED_ICE:0)
Block(4,8,-3,PACKED_ICE:0)
Block(4,8,-2,PACKED_ICE:0)
Block(4,8,-1,PACKED_ICE:0)
Block(4,9,-10,PACKED_ICE:0)
Block(4,9,-9,PACKED_ICE:0)
Block(4,9,-8,PACKED_ICE:0)
Block(4,9,-7,PACKED_ICE:0)
Block(4,9,-6,PACKED_ICE:0)
Block(4,9,-5,PACKED_ICE:0)
Block(4,9,-4,PACKED_ICE:0)
Block(4,9,-3,PACKED_ICE:0)
Block(4,9,-2,PACKED_ICE:0)
Block(4,9,-1,PACKED_ICE:0)
Block(4,10,-10,PACKED_ICE:0)
Block(4,10,-9,PACKED_ICE:0)
Block(4,10,-8,PACKED_ICE:0)
Block(4,10,-7,PACKED_ICE:0)
Block(4,10,-6,PACKED_ICE:0)
Block(4,10,-5,PACKED_ICE:0)
Block(4,10,-4,PACKED_ICE:0)
Block(4,10,-3,PACKED_ICE:0)
Block(4,10,-2,PACKED_ICE:0)
Block(4,10,-1,ICE:0)
Block(4,10,0,ICE:0)
Block(4,11,-10,PACKED_ICE:0)
Block(4,11,-9,PACKED_ICE:0)
Block(4,11,-8,PACKED_ICE:0)
Block(4,11,-7,PACKED_ICE:0)
Block(4,11,-6,PACKED_ICE:0)
Block(4,11,-5,ICE:0)
Block(4,11,-4,PACKED_ICE:0)
Block(4,11,-3,PACKED_ICE:0)
Block(4,11,-2,ICE:0)
Block(4,11,-1,ICE:0)
Block(4,11,0,ICE:0)
Block(4,11,1,ICE:0)
Block(4,12,-10,PACKED_ICE:0)
Block(4,12,-9,PACKED_ICE:0)
Block(4,12,-8,PACKED_ICE:0)
Block(4,12,-7,PACKED_ICE:0)
Block(4,12,-6,ICE:0)
Block(4,12,-5,ICE:0)
Block(4,12,-4,ICE:0)
Block(4,12,-3,PACKED_ICE:0)
Block(4,12,-2,ICE:0)
Block(4,12,-1,ICE:0)
Block(4,13,-10,PACKED_ICE:0)
Block(4,13,-9,PACKED_ICE:0)
Block(4,13,-8,PACKED_ICE:0)
Block(4,13,-7,PACKED_ICE:0)
Block(4,13,-6,ICE:0)
Block(4,13,-5,ICE:0)
Block(4,13,-4,ICE:0)
Block(4,13,-3,ICE:0)
Block(4,14,-10,PACKED_ICE:0)
Block(4,14,-9,PACKED_ICE:0)
Block(4,14,-8,PACKED_ICE:0)
Block(4,14,-7,PACKED_ICE:0)
Block(4,14,-6,ICE:0)
Block(4,14,-5,ICE:0)
Block(4,14,-4,ICE:0)
Block(5,5,-6,ICE:0)
Block(5,6,-7,ICE:0)
Block(5,6,-6,ICE:0)
Block(5,6,-5,ICE:0)
Block(5,7,-7,ICE:0)
Block(5,7,-6,ICE:0)
Block(5,7,-5,ICE:0)
Block(5,7,-4,PACKED_ICE:0)
Block(5,8,-8,PACKED_ICE:0)
Block(5,8,-7,ICE:0)
Block(5,8,-6,ICE:0)
Block(5,8,-5,ICE:0)
Block(5,8,-4,PACKED_ICE:0)
Block(5,9,-9,PACKED_ICE:0)
Block(5,9,-8,PACKED_ICE:0)
Block(5,9,-7,PACKED_ICE:0)
Block(5,9,-6,ICE:0)
Block(5,9,-5,PACKED_ICE:0)
Block(5,9,-4,PACKED_ICE:0)
Block(5,9,-3,PACKED_ICE:0)
Block(5,10,-10,PACKED_ICE:0)
Block(5,10,-9,PACKED_ICE:0)
Block(5,10,-8,PACKED_ICE:0)
Block(5,10,-7,ICE:0)
Block(5,10,-6,ICE:0)
Block(5,10,-5,ICE:0)
Block(5,10,-4,PACKED_ICE:0)
Block(5,10,-3,PACKED_ICE:0)
Block(5,10,-2,PACKED_ICE:0)
Block(5,11,-10,PACKED_ICE:0)
Block(5,11,-9,PACKED_ICE:0)
Block(5,11,-8,PACKED_ICE:0)
Block(5,11,-7,PACKED_ICE:0)
Block(5,11,-6,ICE:0)
Block(5,11,-5,ICE:0)
Block(5,11,-4,PACKED_ICE:0)
Block(5,11,-3,PACKED_ICE:0)
Block(5,11,-2,PACKED_ICE:0)
Block(5,12,-11,PACKED_ICE:0)
Block(5,12,-10,PACKED_ICE:0)
Block(5,12,-9,PACKED_ICE:0)
Block(5,12,-8,PACKED_ICE:0)
Block(5,12,-7,PACKED_ICE:0)
Block(5,12,-6,ICE:0)
Block(5,12,-5,ICE:0)
Block(5,12,-4,ICE:0)
Block(5,12,-3,PACKED_ICE:0)
Block(5,12,-2,ICE:0)
Block(5,12,-1,ICE:0)
Block(5,13,-11,PACKED_ICE:0)
Block(5,13,-10,PACKED_ICE:0)
Block(5,13,-9,PACKED_ICE:0)
Block(5,13,-8,PACKED_ICE:0)
Block(5,13,-7,PACKED_ICE:0)
Block(5,13,-6,PACKED_ICE:0)
Block(5,13,-5,ICE:0)
Block(5,13,-4,ICE:0)
Block(5,13,-3,ICE:0)
Block(5,13,-2,ICE:0)
Block(5,14,-11,PACKED_ICE:0)
Block(5,14,-10,PACKED_ICE:0)
Block(5,14,-9,PACKED_ICE:0)
Block(5,14,-8,PACKED_ICE:0)
Block(5,14,-7,PACKED_ICE:0)
Block(5,14,-6,ICE:0)
Block(5,14,-5,ICE:0)
Block(5,14,-4,ICE:0)
Block(5,14,-3,ICE:0)
Block(5,15,-11,PACKED_ICE:0)
Block(5,15,-10,PACKED_ICE:0)
Block(5,15,-9,PACKED_ICE:0)
Block(5,15,-8,PACKED_ICE:0)
Block(5,15,-7,PACKED_ICE:0)
Block(5,15,-6,PACKED_ICE:0)
Block(5,15,-5,ICE:0)
Block(6,7,-7,ICE:0)
Block(6,8,-7,ICE:0)
Block(6,8,-6,ICE:0)
Block(6,9,-8,PACKED_ICE:0)
Block(6,9,-7,ICE:0)
Block(6,9,-6,ICE:0)
Block(6,9,-5,ICE:0)
Block(6,10,-9,PACKED_ICE:0)
Block(6,10,-8,PACKED_ICE:0)
Block(6,10,-7,ICE:0)
Block(6,10,-6,ICE:0)
Block(6,10,-5,ICE:0)
Block(6,11,-9,PACKED_ICE:0)
Block(6,11,-8,PACKED_ICE:0)
Block(6,11,-7,ICE:0)
Block(6,11,-6,ICE:0)
Block(6,11,-5,ICE:0)
Block(6,11,-4,ICE:0)
Block(6,12,-10,PACKED_ICE:0)
Block(6,12,-9,PACKED_ICE:0)
Block(6,12,-8,PACKED_ICE:0)
Block(6,12,-7,PACKED_ICE:0)
Block(6,12,-6,ICE:0)
Block(6,12,-5,ICE:0)
Block(6,12,-4,ICE:0)
Block(6,12,-3,PACKED_ICE:0)
Block(6,13,-11,PACKED_ICE:0)
Block(6,13,-10,PACKED_ICE:0)
Block(6,13,-9,PACKED_ICE:0)
Block(6,13,-8,PACKED_ICE:0)
Block(6,13,-7,PACKED_ICE:0)
Block(6,13,-6,ICE:0)
Block(6,13,-5,ICE:0)
Block(6,13,-4,ICE:0)
Block(6,13,-3,ICE:0)
Block(6,14,-11,PACKED_ICE:0)
Block(6,14,-10,PACKED_ICE:0)
Block(6,14,-9,PACKED_ICE:0)
Block(6,14,-8,PACKED_ICE:0)
Block(6,14,-7,PACKED_ICE:0)
Block(6,14,-6,PACKED_ICE:0)
Block(6,14,-5,ICE:0)
Block(6,14,-4,ICE:0)
Block(6,14,-3,ICE:0)
Block(6,14,-2,ICE:0)
Block(6,15,-11,PACKED_ICE:0)
Block(6,15,-10,PACKED_ICE:0)
Block(6,15,-9,PACKED_ICE:0)
Block(6,15,-8,PACKED_ICE:0)
Block(6,15,-7,PACKED_ICE:0)
Block(6,15,-6,PACKED_ICE:0)
Block(6,15,-5,ICE:0)
Block(6,15,-4,ICE:0)
Block(6,16,-11,PACKED_ICE:0)
Block(6,16,-10,PACKED_ICE:0)
Block(6,16,-9,PACKED_ICE:0)
Block(6,16,-8,PACKED_ICE:0)
Block(6,16,-7,PACKED_ICE:0)
Block(6,16,-6,ICE:0)
Block(6,16,-5,ICE:0)
Block(7,10,-8,PACKED_ICE:0)
Block(7,10,-7,ICE:0)
Block(7,11,-9,PACKED_ICE:0)
Block(7,11,-8,PACKED_ICE:0)
Block(7,11,-7,ICE:0)
Block(7,11,-6,ICE:0)
Block(7,12,-9,PACKED_ICE:0)
Block(7,12,-8,PACKED_ICE:0)
Block(7,12,-7,ICE:0)
Block(7,12,-6,ICE:0)
Block(7,13,-10,PACKED_ICE:0)
Block(7,13,-9,PACKED_ICE:0)
Block(7,13,-8,PACKED_ICE:0)
Block(7,13,-7,PACKED_ICE:0)
Block(7,13,-6,ICE:0)
Block(7,13,-5,ICE:0)
Block(7,14,-11,PACKED_ICE:0)
Block(7,14,-10,PACKED_ICE:0)
Block(7,14,-9,PACKED_ICE:0)
Block(7,14,-8,PACKED_ICE:0)
Block(7,14,-7,PACKED_ICE:0)
Block(7,14,-6,ICE:0)
Block(7,14,-5,ICE:0)
Block(7,14,-4,ICE:0)
Block(7,15,-11,PACKED_ICE:0)
Block(7,15,-10,PACKED_ICE:0)
Block(7,15,-9,PACKED_ICE:0)
Block(7,15,-8,PACKED_ICE:0)
Block(7,15,-7,PACKED_ICE:0)
Block(7,15,-6,ICE:0)
Block(7,15,-5,ICE:0)
Block(7,15,-4,ICE:0)
Block(7,16,-11,PACKED_ICE:0)
Block(7,16,-10,PACKED_ICE:0)
Block(7,16,-9,PACKED_ICE:0)
Block(7,16,-8,PACKED_ICE:0)
Block(7,16,-7,PACKED_ICE:0)
Block(7,16,-6,ICE:0)
Block(7,16,-5,ICE:0)
Block(7,16,-4,ICE:0)
Block(7,17,-11,PACKED_ICE:0)
Block(7,17,-10,PACKED_ICE:0)
Block(7,17,-9,PACKED_ICE:0)
Block(7,17,-8,PACKED_ICE:0)
Block(7,17,-7,PACKED_ICE:0)
Block(7,17,-6,ICE:0)
Block(8,12,-9,PACKED_ICE:0)
Block(8,12,-8,PACKED_ICE:0)
Block(8,13,-9,PACKED_ICE:0)
Block(8,13,-8,PACKED_ICE:0)
Block(8,13,-7,PACKED_ICE:0)
Block(8,14,-10,PACKED_ICE:0)
Block(8,14,-9,PACKED_ICE:0)
Block(8,14,-8,PACKED_ICE:0)
Block(8,14,-7,PACKED_ICE:0)
Block(8,15,-11,PACKED_ICE:0)
Block(8,15,-10,PACKED_ICE:0)
Block(8,15,-9,PACKED_ICE:0)
Block(8,15,-8,PACKED_ICE:0)
Block(8,15,-7,PACKED_ICE:0)
Block(8,15,-6,PACKED_ICE:0)
Block(8,16,-11,PACKED_ICE:0)
Block(8,16,-10,PACKED_ICE:0)
Block(8,16,-9,PACKED_ICE:0)
Block(8,16,-8,PACKED_ICE:0)
Block(8,16,-7,PACKED_ICE:0)
Block(8,16,-6,ICE:0)
Block(8,16,-5,ICE:0)
Block(8,17,-12,PACKED_ICE:0)
Block(8,17,-11,PACKED_ICE:0)
Block(8,17,-10,PACKED_ICE:0)
Block(8,17,-9,PACKED_ICE:0)
Block(8,17,-8,PACKED_ICE:0)
Block(8,17,-7,ICE:0)
Block(8,17,-6,ICE:0)
Block(8,17,-5,ICE:0)
Block(8,18,-12,PACKED_ICE:0)
Block(8,18,-11,PACKED_ICE:0)
Block(8,18,-10,PACKED_ICE:0)
Block(8,18,-9,PACKED_ICE:0)
Block(8,18,-8,PACKED_ICE:0)
Block(8,18,-7,ICE:0)
Block(8,18,-6,ICE:0)
Block(8,19,-12,PACKED_ICE:0)
Block(8,19,-11,PACKED_ICE:0)
Block(8,19,-10,PACKED_ICE:0)
Block(8,19,-9,PACKED_ICE:0)
Block(8,19,-8,ICE:0)
Block(9,14,-9,PACKED_ICE:0)
Block(9,15,-10,PACKED_ICE:0)
Block(9,15,-9,PACKED_ICE:0)
Block(9,15,-8,PACKED_ICE:0)
Block(9,16,-11,PACKED_ICE:0)
Block(9,16,-10,PACKED_ICE:0)
Block(9,16,-9,PACKED_ICE:0)
Block(9,16,-8,PACKED_ICE:0)
Block(9,17,-11,PACKED_ICE:0)
Block(9,17,-10,PACKED_ICE:0)
Block(9,17,-9,PACKED_ICE:0)
Block(9,17,-8,PACKED_ICE:0)
Block(9,17,-7,PACKED_ICE:0)
Block(9,18,-12,PACKED_ICE:0)
Block(9,18,-11,PACKED_ICE:0)
Block(9,18,-10,PACKED_ICE:0)
Block(9,18,-9,PACKED_ICE:0)
Block(9,18,-8,PACKED_ICE:0)
Block(9,18,-7,ICE:0)
Block(9,18,-6,ICE:0)
Block(9,19,-12,PACKED_ICE:0)
Block(9,19,-11,PACKED_ICE:0)
Block(9,19,-10,PACKED_ICE:0)
Block(9,19,-9,ICE:0)
Block(9,19,-8,ICE:0)
Block(9,19,-7,ICE:0)
Block(9,20,-12,PACKED_ICE:0)
Block(9,20,-11,PACKED_ICE:0)
Block(9,20,-10,PACKED_ICE:0)
Block(9,20,-9,ICE:0)
Block(9,20,-8,ICE:0)
Block(10,16,-10,PACKED_ICE:0)
Block(10,17,-11,PACKED_ICE:0)
Block(10,17,-10,PACKED_ICE:0)
Block(10,17,-9,PACKED_ICE:0)
Block(10,18,-11,PACKED_ICE:0)
Block(10,18,-10,PACKED_ICE:0)
Block(10,18,-9,PACKED_ICE:0)
Block(10,19,-12,PACKED_ICE:0)
Block(10,19,-11,PACKED_ICE:0)
Block(10,19,-10,PACKED_ICE:0)
Block(10,19,-9,PACKED_ICE:0)
Block(10,19,-8,ICE:0)
Block(10,20,-12,PACKED_ICE:0)
Block(10,20,-11,PACKED_ICE:0)
Block(10,20,-10,ICE:0)
Block(10,20,-9,ICE:0)
Block(10,20,-8,ICE:0)
Block(10,20,-7,ICE:0)
Block(10,21,-12,PACKED_ICE:0)
Block(10,21,-11,PACKED_ICE:0)
Block(10,21,-10,ICE:0)
Block(10,21,-9,ICE:0)
Block(11,18,-11,PACKED_ICE:0)
Block(11,19,-11,PACKED_ICE:0)
Block(11,19,-10,PACKED_ICE:0)
Block(11,20,-12,PACKED_ICE:0)
Block(11,20,-11,PACKED_ICE:0)
Block(11,20,-10,PACKED_ICE:0)
Block(11,21,-13,PACKED_ICE:0)
Block(11,21,-12,PACKED_ICE:0)
Block(11,21,-11,PACKED_ICE:0)
Block(11,21,-10,ICE:0)
Block(11,21,-9,ICE:0)
Block(11,22,-13,PACKED_ICE:0)
Block(11,22,-12,PACKED_ICE:0)
Block(11,22,-11,ICE:0)
Block(11,22,-10,PACKED_ICE:0)
Block(12,21,-12,PACKED_ICE:0)
Block(12,21,-11,PACKED_ICE:0)
Block(12,22,-13,PACKED_ICE:0)
Block(12,22,-12,ICE:0)
Block(12,22,-11,ICE:0)
Block(12,23,-13,ICE:0)
Block(12,23,-12,ICE:0)
Block(12,23,-11,ICE:0)
Block(12,23,-10,ICE:0)
Block(12,24,-13,ICE:0)
Block(12,24,-12,ICE:0)
Block(13,23,-13,PACKED_ICE:0)
Block(13,23,-12,ICE:0)
Block(13,24,-13,ICE:0)
Block(13,24,-12,ICE:0)
Block(13,25,-13,ICE:0)
Block(13,25,-12,ICE:0)
Block(14,25,-13,ICE:0)
Block(14,26,-14,ICE:0)
Block(14,26,-13,ICE:0)
Block(15,27,-14,ICE:0)

#######################################################################
# +-----------------------------------------------------------------+ #
# |                            BO3 checks                           | #
# +-----------------------------------------------------------------+ #
#######################################################################

BlockCheck(0,-1,0,SNOW_BLOCK)

#######################################################################
# +-----------------------------------------------------------------+ #
# |                             Branches                            | #
# +-----------------------------------------------------------------+ #
#######################################################################


#######################################################################
# +-----------------------------------------------------------------+ #
# |                             Entities                            | #
# +-----------------------------------------------------------------+ #
#######################################################################


#######################################################################
# +-----------------------------------------------------------------+ #
# |                            Particles                            | #
# +-----------------------------------------------------------------+ #
#######################################################################


#######################################################################
# +-----------------------------------------------------------------+ #
# |                             Spawners                            | #
# +-----------------------------------------------------------------+ #
#######################################################################


#######################################################################
# +-----------------------------------------------------------------+ #
# |                             ModData                             | #
# +-----------------------------------------------------------------+ #
#######################################################################

