
#######################################################################
# +-----------------------------------------------------------------+ #
# |                            BO4 object                           | #
# +-----------------------------------------------------------------+ #
#######################################################################

Author: NLBlackEagle

Description: No description given

SettingsMode: WriteDisable


#######################################################################
# +-----------------------------------------------------------------+ #
# |                          Main settings                          | #
# +-----------------------------------------------------------------+ #
#######################################################################

Frequency: 0

SpawnHeight: highestBlock

UseCenterForHighestBlock: true

##############################
# Height Limits for the BO4. #
##############################

MinHeight: 0

MaxHeight: 255

InheritBO3: 

InheritBO3Rotation: NORTH

OverrideChildSettings: true

OverrideParentHeight: false

CanOverride: true

BranchFrequency: 0

BranchFrequencyGroup: 

MustBeBelowOther: false

MustBeInside: 

CannotBeInside: 

ReplacesBO3: 

MustBeInsideWorldBorders: false

CanSpawnOnWater: true

SpawnOnWaterOnly: false

SpawnUnderWater: false

SpawnAtWaterLevel: false

HeightOffset: 0

RemoveAir: true

ReplaceAbove: 

ReplaceBelow: 

ReplaceWithBiomeBlocks: true

ReplaceWithSurfaceBlock: GRASS

ReplaceWithGroundBlock: DIRT

ReplaceWithStoneBlock: STONE

SmoothRadius: 0

SmoothHeightOffset: 0

SmoothStartTop: false

SmoothStartWood: false

SmoothingSurfaceBlock: 

SmoothingGroundBlock: 

BO3Group: 

IsSpawnPoint: false

DoReplaceBlocks: true


#######################################################################
# +-----------------------------------------------------------------+ #
# |                              Blocks                             | #
# +-----------------------------------------------------------------+ #
#######################################################################

Block(2,70,8,STAINED_CLAY:0)
Block(2,71,8,STAINED_CLAY:0)
Block(2,72,7,STAINED_CLAY:0)
Block(2,72,8,STAINED_CLAY:0)
Block(2,73,6,STAINED_CLAY:0)
Block(2,73,7,STAINED_CLAY:0)
Block(2,73,8,STAINED_CLAY:0)
Block(2,74,6,STAINED_CLAY:0)
Block(2,74,7,STAINED_CLAY:0)
Block(2,74,8,STAINED_CLAY:0)
Block(2,75,5,STAINED_CLAY:0)
Block(2,75,6,STAINED_CLAY:0)
Block(2,75,7,STAINED_CLAY:0)
Block(2,75,8,STAINED_CLAY:0)
Block(2,76,4,STAINED_CLAY:0)
Block(2,76,5,STAINED_CLAY:0)
Block(2,76,6,STAINED_CLAY:0)
Block(2,76,7,STAINED_CLAY:0)
Block(2,76,8,STAINED_CLAY:0)
Block(2,77,4,STAINED_CLAY:0)
Block(2,77,5,STAINED_CLAY:0)
Block(2,77,6,STAINED_CLAY:0)
Block(2,78,3,STAINED_CLAY:0)
Block(2,78,4,STAINED_CLAY:0)
Block(2,78,5,STAINED_CLAY:0)
Block(2,79,3,STAINED_CLAY:0)
Block(2,79,4,STAINED_CLAY:0)
Block(2,80,3,STAINED_CLAY:0)
Block(3,71,8,STAINED_CLAY:0)
Block(3,72,7,STAINED_CLAY:0)
Block(3,72,8,STAINED_CLAY:0)
Block(3,73,7,STAINED_CLAY:0)
Block(3,73,8,STAINED_CLAY:0)
Block(3,74,6,STAINED_CLAY:0)
Block(3,74,7,STAINED_CLAY:0)
Block(3,74,8,STAINED_CLAY:0)
Block(3,75,5,STAINED_CLAY:0)
Block(3,75,6,STAINED_CLAY:0)
Block(3,75,7,STAINED_CLAY:0)
Block(3,75,8,STAINED_CLAY:0)
Block(3,76,5,STAINED_CLAY:0)
Block(3,76,6,STAINED_CLAY:0)
Block(3,76,7,STAINED_CLAY:0)
Block(3,76,8,STAINED_CLAY:0)
Block(3,77,4,STAINED_CLAY:0)
Block(3,77,5,STAINED_CLAY:0)
Block(3,77,6,STAINED_CLAY:0)
Block(3,77,7,STAINED_CLAY:0)
Block(3,77,8,STAINED_CLAY:0)
Block(3,78,3,STAINED_CLAY:0)
Block(3,78,4,STAINED_CLAY:0)
Block(3,78,5,STAINED_CLAY:0)
Block(3,78,6,STAINED_CLAY:0)
Block(3,78,7,STAINED_CLAY:0)
Block(3,79,2,STAINED_CLAY:0)
Block(3,79,3,STAINED_CLAY:0)
Block(3,79,4,STAINED_CLAY:0)
Block(3,79,5,STAINED_CLAY:0)
Block(3,79,6,STAINED_CLAY:0)
Block(3,80,2,STAINED_CLAY:0)
Block(3,80,3,STAINED_CLAY:0)
Block(3,80,4,STAINED_CLAY:0)
Block(3,80,5,STAINED_CLAY:0)
Block(3,81,1,STAINED_CLAY:0)
Block(3,81,2,STAINED_CLAY:0)
Block(3,81,3,STAINED_CLAY:0)
Block(3,81,4,STAINED_CLAY:0)
Block(3,82,0,STAINED_CLAY:0)
Block(3,82,1,STAINED_CLAY:0)
Block(3,82,2,STAINED_CLAY:0)
Block(3,82,3,STAINED_CLAY:0)
Block(3,83,0,STAINED_CLAY:0)
Block(3,83,1,STAINED_CLAY:0)
Block(3,83,2,STAINED_CLAY:0)
Block(3,84,-1,STAINED_CLAY:0)
Block(3,84,0,STAINED_CLAY:0)
Block(3,84,1,STAINED_CLAY:0)
Block(3,85,-2,DIRT:1)
Block(3,85,-1,DIRT:1)
Block(3,85,0,STAINED_CLAY:0)
Block(3,86,-2,DIRT:1)
Block(3,86,-1,DIRT:1)
Block(3,87,-3,DIRT:1)
Block(3,87,-2,DIRT:1)
Block(3,88,-3,DIRT:1)
Block(4,71,8,STAINED_CLAY:0)
Block(4,72,7,STAINED_CLAY:0)
Block(4,72,8,STAINED_CLAY:0)
Block(4,73,7,STAINED_CLAY:0)
Block(4,73,8,STAINED_CLAY:0)
Block(4,74,6,STAINED_CLAY:0)
Block(4,74,7,STAINED_CLAY:0)
Block(4,74,8,STAINED_CLAY:0)
Block(4,75,5,STAINED_CLAY:0)
Block(4,75,6,STAINED_CLAY:0)
Block(4,75,7,STAINED_CLAY:0)
Block(4,75,8,STAINED_CLAY:0)
Block(4,76,5,STAINED_CLAY:0)
Block(4,76,6,STAINED_CLAY:0)
Block(4,76,7,STAINED_CLAY:0)
Block(4,76,8,STAINED_CLAY:0)
Block(4,77,4,STAINED_CLAY:0)
Block(4,77,5,STAINED_CLAY:0)
Block(4,77,6,STAINED_CLAY:0)
Block(4,77,7,STAINED_CLAY:0)
Block(4,77,8,STAINED_CLAY:0)
Block(4,78,3,STAINED_CLAY:0)
Block(4,78,4,STAINED_CLAY:0)
Block(4,78,5,STAINED_CLAY:0)
Block(4,78,6,STAINED_CLAY:0)
Block(4,78,7,STAINED_CLAY:0)
Block(4,79,3,STAINED_CLAY:0)
Block(4,79,4,STAINED_CLAY:0)
Block(4,79,5,STAINED_CLAY:0)
Block(4,79,6,STAINED_CLAY:0)
Block(4,80,2,STAINED_CLAY:0)
Block(4,80,3,STAINED_CLAY:0)
Block(4,80,4,STAINED_CLAY:0)
Block(4,80,5,STAINED_CLAY:0)
Block(4,81,1,STAINED_CLAY:0)
Block(4,81,2,STAINED_CLAY:0)
Block(4,81,3,STAINED_CLAY:0)
Block(4,81,4,STAINED_CLAY:0)
Block(4,82,1,STAINED_CLAY:0)
Block(4,82,2,STAINED_CLAY:0)
Block(4,82,3,STAINED_CLAY:0)
Block(4,83,0,STAINED_CLAY:0)
Block(4,83,1,STAINED_CLAY:0)
Block(4,83,2,STAINED_CLAY:0)
Block(4,84,-1,STAINED_CLAY:0)
Block(4,84,0,STAINED_CLAY:0)
Block(4,84,1,STAINED_CLAY:0)
Block(4,85,-1,DIRT:1)
Block(4,85,0,STAINED_CLAY:0)
Block(4,86,-2,DIRT:1)
Block(4,86,-1,DIRT:1)
Block(4,86,0,DIRT:1)
Block(4,87,-3,DIRT:1)
Block(4,87,-2,DIRT:1)
Block(4,87,-1,DIRT:1)
Block(4,88,-3,DIRT:1)
Block(4,88,-2,DIRT:1)
Block(4,89,-4,DIRT:1)
Block(4,89,-3,DIRT:1)
Block(4,90,-5,DIRT:1)
Block(4,90,-4,DIRT:1)
Block(4,91,-5,DIRT:1)
Block(4,92,-6,DIRT:1)
Block(4,93,-7,DIRT:1)
Block(5,71,8,STAINED_CLAY:0)
Block(5,72,8,STAINED_CLAY:0)
Block(5,73,7,STAINED_CLAY:0)
Block(5,73,8,STAINED_CLAY:0)
Block(5,74,6,STAINED_CLAY:0)
Block(5,74,7,STAINED_CLAY:0)
Block(5,74,8,STAINED_CLAY:0)
Block(5,75,6,STAINED_CLAY:0)
Block(5,75,7,STAINED_CLAY:0)
Block(5,75,8,STAINED_CLAY:0)
Block(5,76,5,STAINED_CLAY:0)
Block(5,76,6,STAINED_CLAY:0)
Block(5,76,7,STAINED_CLAY:0)
Block(5,76,8,STAINED_CLAY:0)
Block(5,77,4,STAINED_CLAY:0)
Block(5,77,5,STAINED_CLAY:0)
Block(5,77,6,STAINED_CLAY:0)
Block(5,77,7,STAINED_CLAY:0)
Block(5,77,8,STAINED_CLAY:0)
Block(5,78,4,STAINED_CLAY:0)
Block(5,78,5,STAINED_CLAY:0)
Block(5,78,6,STAINED_CLAY:0)
Block(5,78,7,STAINED_CLAY:0)
Block(5,79,3,STAINED_CLAY:0)
Block(5,79,4,STAINED_CLAY:0)
Block(5,79,5,STAINED_CLAY:0)
Block(5,79,6,STAINED_CLAY:0)
Block(5,80,2,STAINED_CLAY:0)
Block(5,80,3,STAINED_CLAY:0)
Block(5,80,4,STAINED_CLAY:0)
Block(5,80,5,STAINED_CLAY:0)
Block(5,81,2,STAINED_CLAY:0)
Block(5,81,3,STAINED_CLAY:0)
Block(5,81,4,STAINED_CLAY:0)
Block(5,82,1,STAINED_CLAY:0)
Block(5,82,2,STAINED_CLAY:0)
Block(5,82,3,STAINED_CLAY:0)
Block(5,83,0,STAINED_CLAY:0)
Block(5,83,1,STAINED_CLAY:0)
Block(5,83,2,STAINED_CLAY:0)
Block(5,84,0,STAINED_CLAY:0)
Block(5,84,1,STAINED_CLAY:0)
Block(5,85,-1,DIRT:1)
Block(5,85,0,STAINED_CLAY:0)
Block(5,86,-2,DIRT:1)
Block(5,86,-1,DIRT:1)
Block(5,87,-2,DIRT:1)
Block(5,88,-3,DIRT:1)
Block(5,89,-4,DIRT:1)
Block(6,72,8,STAINED_CLAY:0)
Block(6,73,7,STAINED_CLAY:0)
Block(6,73,8,STAINED_CLAY:0)
Block(6,74,7,STAINED_CLAY:0)
Block(6,74,8,STAINED_CLAY:0)
Block(6,75,6,DIRT:1)
Block(6,75,7,DIRT:1)
Block(6,75,8,STAINED_CLAY:0)
Block(6,76,5,STAINED_CLAY:0)
Block(6,76,6,STAINED_CLAY:0)
Block(6,76,7,STAINED_CLAY:0)
Block(6,76,8,DIRT:1)
Block(6,77,5,STAINED_CLAY:0)
Block(6,77,6,STAINED_CLAY:0)
Block(6,77,7,STAINED_CLAY:0)
Block(6,78,4,STAINED_CLAY:0)
Block(6,78,5,STAINED_CLAY:0)
Block(6,78,6,STAINED_CLAY:0)
Block(6,79,4,STAINED_CLAY:0)
Block(6,79,5,STAINED_CLAY:0)
Block(6,80,3,STAINED_CLAY:0)
Block(6,80,4,STAINED_CLAY:0)
Block(6,81,2,STAINED_CLAY:0)
Block(6,81,3,STAINED_CLAY:0)
Block(6,82,2,STAINED_CLAY:0)
Block(6,83,1,STAINED_CLAY:0)
Block(6,84,0,STAINED_CLAY:0)
Block(7,73,8,STAINED_CLAY:0)
Block(7,74,7,DIRT:1)
Block(7,74,8,DIRT:1)
Block(7,75,7,DIRT:1)
Block(7,75,8,DIRT:1)
Block(7,76,6,DIRT:1)
Block(7,76,7,DIRT:1)
Block(7,77,5,STAINED_CLAY:0)
Block(7,77,6,STAINED_CLAY:0)
Block(7,78,5,STAINED_CLAY:0)

#######################################################################
# +-----------------------------------------------------------------+ #
# |                             Branches                            | #
# +-----------------------------------------------------------------+ #
#######################################################################

Branch(0,0,16,true,MudSpike_Huge_11C0R1,NORTH,100.0,0)

#######################################################################
# +-----------------------------------------------------------------+ #
# |                             Entities                            | #
# +-----------------------------------------------------------------+ #
#######################################################################


#######################################################################
# +-----------------------------------------------------------------+ #
# |                            Particles                            | #
# +-----------------------------------------------------------------+ #
#######################################################################


#######################################################################
# +-----------------------------------------------------------------+ #
# |                             Spawners                            | #
# +-----------------------------------------------------------------+ #
#######################################################################


#######################################################################
# +-----------------------------------------------------------------+ #
# |                             ModData                             | #
# +-----------------------------------------------------------------+ #
#######################################################################

