
#######################################################################
# +-----------------------------------------------------------------+ #
# |                            BO4 object                           | #
# +-----------------------------------------------------------------+ #
#######################################################################

Author: NLBlackEagle

Description: No description given

SettingsMode: WriteDisable


#######################################################################
# +-----------------------------------------------------------------+ #
# |                          Main settings                          | #
# +-----------------------------------------------------------------+ #
#######################################################################

Frequency: 0

SpawnHeight: highestBlock

UseCenterForHighestBlock: true

##############################
# Height Limits for the BO4. #
##############################

MinHeight: 0

MaxHeight: 255

InheritBO3: 

InheritBO3Rotation: NORTH

OverrideChildSettings: true

OverrideParentHeight: false

CanOverride: true

BranchFrequency: 0

BranchFrequencyGroup: 

MustBeBelowOther: false

MustBeInside: 

CannotBeInside: 

ReplacesBO3: 

MustBeInsideWorldBorders: false

CanSpawnOnWater: true

SpawnOnWaterOnly: false

SpawnUnderWater: false

SpawnAtWaterLevel: false

HeightOffset: 0

RemoveAir: false

ReplaceAbove: 

ReplaceBelow: 

ReplaceWithBiomeBlocks: true

ReplaceWithSurfaceBlock: GRASS

ReplaceWithGroundBlock: DIRT

ReplaceWithStoneBlock: STONE

SmoothRadius: 0

SmoothHeightOffset: 0

SmoothStartTop: false

SmoothStartWood: false

SmoothingSurfaceBlock: 

SmoothingGroundBlock: 

BO3Group: 

IsSpawnPoint: false

DoReplaceBlocks: false


#######################################################################
# +-----------------------------------------------------------------+ #
# |                              Blocks                             | #
# +-----------------------------------------------------------------+ #
#######################################################################

Block(-7,750,9,AIR:0)
Block(-4,0,-6,COBBLESTONE:0)
Block(-4,0,-4,COBBLESTONE:0)
Block(-4,0,7,COBBLESTONE:0)
Block(-4,0,9,COBBLESTONE:0)
Block(-4,1,-6,COBBLESTONE:0)
Block(-4,1,-4,COBBLESTONE:0)
Block(-4,1,7,COBBLESTONE:0)
Block(-4,1,9,COBBLESTONE:0)
Block(-4,2,-6,COBBLESTONE:0)
Block(-4,2,-4,COBBLESTONE:0)
Block(-4,2,7,COBBLESTONE:0)
Block(-4,2,9,COBBLESTONE:0)
Block(-4,3,-6,COBBLESTONE:0)
Block(-4,3,-4,COBBLESTONE:0)
Block(-4,3,7,COBBLESTONE:0)
Block(-4,3,9,COBBLESTONE:0)
Block(-4,4,-6,COBBLESTONE:0)
Block(-4,4,-5,COBBLESTONE_STAIRS:7)
Block(-4,4,-4,COBBLESTONE:0)
Block(-4,4,7,COBBLESTONE:0)
Block(-4,4,8,COBBLESTONE_STAIRS:6)
Block(-4,4,9,COBBLESTONE:0)
Block(-4,5,-6,COBBLESTONE:0)
Block(-4,5,-5,LOG:5)
Block(-4,5,-4,COBBLESTONE_STAIRS:7)
Block(-4,5,-3,STEP:11)
Block(-4,5,-2,STEP:11)
Block(-4,5,5,STEP:11)
Block(-4,5,6,STEP:11)
Block(-4,5,7,COBBLESTONE_STAIRS:6)
Block(-4,5,8,LOG:5)
Block(-4,5,9,COBBLESTONE:0)
Block(-4,6,-6,COBBLESTONE:0)
Block(-4,6,-5,COBBLESTONE_STAIRS:3)
Block(-4,6,-4,COBBLESTONE:0)
Block(-4,6,-2,COBBLESTONE_STAIRS:2)
Block(-4,6,-1,COBBLESTONE_STAIRS:7)
Block(-4,6,0,COBBLESTONE:0)
Block(-4,6,1,STEP:11)
Block(-4,6,2,STEP:11)
Block(-4,6,3,COBBLESTONE:0)
Block(-4,6,4,COBBLESTONE_STAIRS:6)
Block(-4,6,5,COBBLESTONE_STAIRS:3)
Block(-4,6,7,COBBLESTONE:0)
Block(-4,6,8,COBBLESTONE_STAIRS:2)
Block(-4,6,9,COBBLESTONE:0)
Block(-4,7,-6,LOG:1)
Block(-4,7,-5,COBBLESTONE_STAIRS:7)
Block(-4,7,-4,LOG:1)
Block(-4,7,-2,COBBLESTONE_STAIRS:6)
Block(-4,7,-1,LOG:1)
Block(-4,7,0,STEP:11)
Block(-4,7,1,STEP:11)
Block(-4,7,2,STEP:11)
Block(-4,7,3,STEP:11)
Block(-4,7,4,LOG:1)
Block(-4,7,5,COBBLESTONE_STAIRS:7)
Block(-4,7,7,LOG:1)
Block(-4,7,8,COBBLESTONE_STAIRS:6)
Block(-4,7,9,LOG:1)
Block(-3,5,-5,LOG:5)
Block(-3,5,8,LOG:5)
Block(-2,0,-4,COBBLESTONE:0)
Block(-2,0,7,COBBLESTONE:0)
Block(-2,1,-4,COBBLESTONE:0)
Block(-2,1,7,COBBLESTONE:0)
Block(-2,2,-4,COBBLESTONE:0)
Block(-2,2,7,COBBLESTONE:0)
Block(-2,3,-4,COBBLESTONE:0)
Block(-2,3,7,COBBLESTONE:0)
Block(-2,4,-4,COBBLESTONE:0)
Block(-2,4,7,COBBLESTONE:0)
Block(-2,5,-5,LOG:5)
Block(-2,5,-4,COBBLESTONE:0)
Block(-2,5,7,COBBLESTONE:0)
Block(-2,5,8,LOG:5)
Block(-2,6,-4,COBBLESTONE:0)
Block(-2,6,7,COBBLESTONE:0)
Block(-2,7,-4,LOG:1)
Block(-2,7,7,LOG:1)
Block(-1,0,-6,COBBLESTONE:0)
Block(-1,0,9,COBBLESTONE:0)
Block(-1,1,-6,COBBLESTONE:0)
Block(-1,1,9,COBBLESTONE:0)
Block(-1,2,-6,COBBLESTONE:0)
Block(-1,2,9,COBBLESTONE:0)
Block(-1,3,-6,COBBLESTONE:0)
Block(-1,3,9,COBBLESTONE:0)
Block(-1,4,-6,COBBLESTONE:0)
Block(-1,4,-5,COBBLESTONE_STAIRS:7)
Block(-1,4,8,COBBLESTONE_STAIRS:6)
Block(-1,4,9,COBBLESTONE:0)
Block(-1,5,-6,COBBLESTONE:0)
Block(-1,5,-5,LOG:5)
Block(-1,5,-4,COBBLESTONE_STAIRS:7)
Block(-1,5,-3,STEP:11)
Block(-1,5,-2,STEP:11)
Block(-1,5,5,STEP:11)
Block(-1,5,6,STEP:11)
Block(-1,5,7,COBBLESTONE_STAIRS:6)
Block(-1,5,8,LOG:5)
Block(-1,5,9,COBBLESTONE:0)
Block(-1,6,-6,COBBLESTONE:0)
Block(-1,6,-5,COBBLESTONE_STAIRS:3)
Block(-1,6,-2,COBBLESTONE_STAIRS:2)
Block(-1,6,-1,COBBLESTONE_STAIRS:7)
Block(-1,6,0,COBBLESTONE:0)
Block(-1,6,1,STEP:11)
Block(-1,6,2,STEP:11)
Block(-1,6,3,COBBLESTONE:0)
Block(-1,6,4,COBBLESTONE_STAIRS:6)
Block(-1,6,5,COBBLESTONE_STAIRS:3)
Block(-1,6,8,COBBLESTONE_STAIRS:2)
Block(-1,6,9,COBBLESTONE:0)
Block(-1,7,-6,LOG:1)
Block(-1,7,-5,COBBLESTONE_STAIRS:7)
Block(-1,7,-2,COBBLESTONE_STAIRS:6)
Block(-1,7,-1,LOG:1)
Block(-1,7,0,STEP:11)
Block(-1,7,1,STEP:11)
Block(-1,7,2,STEP:11)
Block(-1,7,3,STEP:11)
Block(-1,7,4,LOG:1)
Block(-1,7,5,COBBLESTONE_STAIRS:7)
Block(-1,7,8,COBBLESTONE_STAIRS:6)
Block(-1,7,9,LOG:1)
Block(0,5,-5,LOG:5)
Block(0,5,8,LOG:5)
Block(1,5,-5,LOG:5)
Block(1,5,8,LOG:5)
Block(2,0,-6,COBBLESTONE:0)
Block(2,0,9,COBBLESTONE:0)
Block(2,1,-6,COBBLESTONE:0)
Block(2,1,9,COBBLESTONE:0)
Block(2,2,-6,COBBLESTONE:0)
Block(2,2,9,COBBLESTONE:0)
Block(2,3,-6,COBBLESTONE:0)
Block(2,3,9,COBBLESTONE:0)
Block(2,4,-6,COBBLESTONE:0)
Block(2,4,-5,COBBLESTONE_STAIRS:7)
Block(2,4,8,COBBLESTONE_STAIRS:6)
Block(2,4,9,COBBLESTONE:0)
Block(2,5,-6,COBBLESTONE:0)
Block(2,5,-5,LOG:5)
Block(2,5,-4,COBBLESTONE_STAIRS:7)
Block(2,5,-3,STEP:11)
Block(2,5,-2,STEP:11)
Block(2,5,5,STEP:11)
Block(2,5,6,STEP:11)
Block(2,5,7,COBBLESTONE_STAIRS:6)
Block(2,5,8,LOG:5)
Block(2,5,9,COBBLESTONE:0)
Block(2,6,-6,COBBLESTONE:0)
Block(2,6,-5,COBBLESTONE_STAIRS:3)
Block(2,6,-2,COBBLESTONE_STAIRS:2)
Block(2,6,-1,COBBLESTONE_STAIRS:7)
Block(2,6,0,COBBLESTONE:0)
Block(2,6,1,STEP:11)
Block(2,6,2,STEP:11)
Block(2,6,3,COBBLESTONE:0)
Block(2,6,4,COBBLESTONE_STAIRS:6)
Block(2,6,5,COBBLESTONE_STAIRS:3)
Block(2,6,8,COBBLESTONE_STAIRS:2)
Block(2,6,9,COBBLESTONE:0)
Block(2,7,-6,LOG:1)
Block(2,7,-5,COBBLESTONE_STAIRS:7)
Block(2,7,-2,COBBLESTONE_STAIRS:6)
Block(2,7,-1,LOG:1)
Block(2,7,0,STEP:11)
Block(2,7,1,STEP:11)
Block(2,7,2,STEP:11)
Block(2,7,3,STEP:11)
Block(2,7,4,LOG:1)
Block(2,7,5,COBBLESTONE_STAIRS:7)
Block(2,7,8,COBBLESTONE_STAIRS:6)
Block(2,7,9,LOG:1)
Block(3,0,-4,COBBLESTONE:0)
Block(3,0,7,COBBLESTONE:0)
Block(3,1,-4,COBBLESTONE:0)
Block(3,1,7,COBBLESTONE:0)
Block(3,2,-4,COBBLESTONE:0)
Block(3,2,7,COBBLESTONE:0)
Block(3,3,-4,COBBLESTONE:0)
Block(3,3,7,COBBLESTONE:0)
Block(3,4,-4,COBBLESTONE:0)
Block(3,4,7,COBBLESTONE:0)
Block(3,5,-5,LOG:5)
Block(3,5,-4,COBBLESTONE:0)
Block(3,5,7,COBBLESTONE:0)
Block(3,5,8,LOG:5)
Block(3,6,-4,COBBLESTONE:0)
Block(3,6,7,COBBLESTONE:0)
Block(3,7,-4,LOG:1)
Block(3,7,7,LOG:1)
Block(4,5,-5,LOG:5)
Block(4,5,8,LOG:5)
Block(5,0,-6,COBBLESTONE:0)
Block(5,0,-4,COBBLESTONE:0)
Block(5,0,7,COBBLESTONE:0)
Block(5,0,9,COBBLESTONE:0)
Block(5,1,-6,COBBLESTONE:0)
Block(5,1,-4,COBBLESTONE:0)
Block(5,1,7,COBBLESTONE:0)
Block(5,1,9,COBBLESTONE:0)
Block(5,2,-6,COBBLESTONE:0)
Block(5,2,-4,COBBLESTONE:0)
Block(5,2,7,COBBLESTONE:0)
Block(5,2,9,COBBLESTONE:0)
Block(5,3,-6,COBBLESTONE:0)
Block(5,3,-4,COBBLESTONE:0)
Block(5,3,7,COBBLESTONE:0)
Block(5,3,9,COBBLESTONE:0)
Block(5,4,-6,COBBLESTONE:0)
Block(5,4,-5,COBBLESTONE_STAIRS:7)
Block(5,4,-4,COBBLESTONE:0)
Block(5,4,7,COBBLESTONE:0)
Block(5,4,8,COBBLESTONE_STAIRS:6)
Block(5,4,9,COBBLESTONE:0)
Block(5,5,-6,COBBLESTONE:0)
Block(5,5,-5,LOG:5)
Block(5,5,-4,COBBLESTONE_STAIRS:7)
Block(5,5,-3,STEP:11)
Block(5,5,-2,STEP:11)
Block(5,5,5,STEP:11)
Block(5,5,6,STEP:11)
Block(5,5,7,COBBLESTONE_STAIRS:6)
Block(5,5,8,LOG:5)
Block(5,5,9,COBBLESTONE:0)
Block(5,6,-6,COBBLESTONE:0)
Block(5,6,-5,COBBLESTONE_STAIRS:3)
Block(5,6,-4,COBBLESTONE:0)
Block(5,6,-2,COBBLESTONE_STAIRS:2)
Block(5,6,-1,COBBLESTONE_STAIRS:7)
Block(5,6,0,COBBLESTONE:0)
Block(5,6,1,STEP:11)
Block(5,6,2,STEP:11)
Block(5,6,3,COBBLESTONE:0)
Block(5,6,4,COBBLESTONE_STAIRS:6)
Block(5,6,5,COBBLESTONE_STAIRS:3)
Block(5,6,7,COBBLESTONE:0)
Block(5,6,8,COBBLESTONE_STAIRS:2)
Block(5,6,9,COBBLESTONE:0)
Block(5,7,-6,LOG:1)
Block(5,7,-5,COBBLESTONE_STAIRS:7)
Block(5,7,-4,LOG:1)
Block(5,7,-2,COBBLESTONE_STAIRS:6)
Block(5,7,-1,LOG:1)
Block(5,7,0,STEP:11)
Block(5,7,1,STEP:11)
Block(5,7,2,STEP:11)
Block(5,7,3,STEP:11)
Block(5,7,4,LOG:1)
Block(5,7,5,COBBLESTONE_STAIRS:7)
Block(5,7,7,LOG:1)
Block(5,7,8,COBBLESTONE_STAIRS:6)
Block(5,7,9,LOG:1)
Block(8,750,-6,AIR:0)

#######################################################################
# +-----------------------------------------------------------------+ #
# |                             Branches                            | #
# +-----------------------------------------------------------------+ #
#######################################################################

Branch(0,-4,0,true,Mineshaft-ExplodeLavaHorse-Foundation-Ext,NORTH,100.0,0)
Branch(0,-7,0,true,Mineshaft-ExplodeLavaHorse-Foundation-Ext,NORTH,100.0,0)
Branch(0,-10,0,false,Mineshaft-ExplodeLavaHorse-Foundation-Ext,NORTH,100.0,0)

#######################################################################
# +-----------------------------------------------------------------+ #
# |                             Entities                            | #
# +-----------------------------------------------------------------+ #
#######################################################################


#######################################################################
# +-----------------------------------------------------------------+ #
# |                            Particles                            | #
# +-----------------------------------------------------------------+ #
#######################################################################


#######################################################################
# +-----------------------------------------------------------------+ #
# |                             Spawners                            | #
# +-----------------------------------------------------------------+ #
#######################################################################


#######################################################################
# +-----------------------------------------------------------------+ #
# |                             ModData                             | #
# +-----------------------------------------------------------------+ #
#######################################################################

