
#######################################################################
# +-----------------------------------------------------------------+ #
# |                            BO4 object                           | #
# +-----------------------------------------------------------------+ #
#######################################################################

Author: NLBlackEagle

Description: No description given

SettingsMode: WriteDisable


#######################################################################
# +-----------------------------------------------------------------+ #
# |                          Main settings                          | #
# +-----------------------------------------------------------------+ #
#######################################################################

Frequency: 0

SpawnHeight: highestBlock

UseCenterForHighestBlock: true

##############################
# Height Limits for the BO4. #
##############################

MinHeight: 0

MaxHeight: 255

InheritBO3: 

InheritBO3Rotation: NORTH

OverrideChildSettings: true

OverrideParentHeight: false

CanOverride: true

BranchFrequency: 0

BranchFrequencyGroup: 

MustBeBelowOther: false

MustBeInside: 

CannotBeInside: 

ReplacesBO3: 

MustBeInsideWorldBorders: false

CanSpawnOnWater: true

SpawnOnWaterOnly: false

SpawnUnderWater: false

SpawnAtWaterLevel: false

HeightOffset: 0

RemoveAir: false

ReplaceAbove: 

ReplaceBelow: 

ReplaceWithBiomeBlocks: true

ReplaceWithSurfaceBlock: GRASS

ReplaceWithGroundBlock: DIRT

ReplaceWithStoneBlock: STONE

SmoothRadius: 0

SmoothHeightOffset: 0

SmoothStartTop: false

SmoothStartWood: false

SmoothingSurfaceBlock: 

SmoothingGroundBlock: 

BO3Group: 

IsSpawnPoint: false

DoReplaceBlocks: true


#######################################################################
# +-----------------------------------------------------------------+ #
# |                              Blocks                             | #
# +-----------------------------------------------------------------+ #
#######################################################################

Block(-7,0,0,COBBLESTONE:0)
Block(-7,0,3,COBBLESTONE:0)
Block(-7,1,0,COBBLESTONE:0)
Block(-7,1,3,COBBLESTONE:0)
Block(-7,2,0,COBBLESTONE:0)
Block(-7,2,3,COBBLESTONE:0)
Block(-7,3,0,COBBLESTONE:0)
Block(-7,3,3,COBBLESTONE:0)
Block(-7,4,0,COBBLESTONE:0)
Block(-7,4,3,COBBLESTONE:0)
Block(-7,5,0,COBBLESTONE:0)
Block(-7,5,3,COBBLESTONE:0)
Block(-7,6,0,COBBLESTONE:0)
Block(-7,6,3,COBBLESTONE:0)
Block(-7,7,0,LOG:1)
Block(-7,7,3,LOG:1)
Block(-6,4,0,COBBLESTONE_STAIRS:5)
Block(-6,4,3,COBBLESTONE_STAIRS:5)
Block(-6,5,0,LOG:9)
Block(-6,5,1,LOG:9)
Block(-6,5,2,LOG:9)
Block(-6,5,3,LOG:9)
Block(-6,6,0,COBBLESTONE_STAIRS:1)
Block(-6,6,3,COBBLESTONE_STAIRS:1)
Block(-6,7,0,COBBLESTONE_STAIRS:5)
Block(-6,7,3,COBBLESTONE_STAIRS:5)
Block(-5,5,0,COBBLESTONE_STAIRS:5)
Block(-5,5,3,COBBLESTONE_STAIRS:5)
Block(-4,5,0,STEP:11)
Block(-4,5,3,STEP:11)
Block(-3,5,0,STEP:11)
Block(-3,5,3,STEP:11)
Block(-3,6,0,COBBLESTONE_STAIRS:0)
Block(-3,6,3,COBBLESTONE_STAIRS:0)
Block(-3,7,0,COBBLESTONE_STAIRS:4)
Block(-3,7,3,COBBLESTONE_STAIRS:4)
Block(-2,0,-6,COBBLESTONE:0)
Block(-2,0,9,COBBLESTONE:0)
Block(-2,1,-6,COBBLESTONE:0)
Block(-2,1,9,COBBLESTONE:0)
Block(-2,2,-6,COBBLESTONE:0)
Block(-2,2,9,COBBLESTONE:0)
Block(-2,3,-6,COBBLESTONE:0)
Block(-2,3,9,COBBLESTONE:0)
Block(-2,4,-6,COBBLESTONE:0)
Block(-2,4,-5,COBBLESTONE_STAIRS:7)
Block(-2,4,8,COBBLESTONE_STAIRS:6)
Block(-2,4,9,COBBLESTONE:0)
Block(-2,5,-6,COBBLESTONE:0)
Block(-2,5,-5,LOG:5)
Block(-2,5,-4,COBBLESTONE_STAIRS:7)
Block(-2,5,-3,STEP:11)
Block(-2,5,-2,STEP:11)
Block(-2,5,5,STEP:11)
Block(-2,5,6,STEP:11)
Block(-2,5,7,COBBLESTONE_STAIRS:6)
Block(-2,5,8,LOG:5)
Block(-2,5,9,COBBLESTONE:0)
Block(-2,6,-6,COBBLESTONE:0)
Block(-2,6,-5,COBBLESTONE_STAIRS:3)
Block(-2,6,-2,COBBLESTONE_STAIRS:2)
Block(-2,6,-1,COBBLESTONE_STAIRS:7)
Block(-2,6,0,COBBLESTONE:0)
Block(-2,6,1,STEP:11)
Block(-2,6,2,STEP:11)
Block(-2,6,3,COBBLESTONE:0)
Block(-2,6,4,COBBLESTONE_STAIRS:6)
Block(-2,6,5,COBBLESTONE_STAIRS:3)
Block(-2,6,8,COBBLESTONE_STAIRS:2)
Block(-2,6,9,COBBLESTONE:0)
Block(-2,7,-6,LOG:1)
Block(-2,7,-5,COBBLESTONE_STAIRS:7)
Block(-2,7,-2,COBBLESTONE_STAIRS:6)
Block(-2,7,-1,LOG:1)
Block(-2,7,0,STEP:11)
Block(-2,7,1,STEP:11)
Block(-2,7,2,STEP:11)
Block(-2,7,3,STEP:11)
Block(-2,7,4,LOG:1)
Block(-2,7,5,COBBLESTONE_STAIRS:7)
Block(-2,7,8,COBBLESTONE_STAIRS:6)
Block(-2,7,9,LOG:1)
Block(-1,5,-5,LOG:5)
Block(-1,5,8,LOG:5)
Block(-1,6,0,COBBLESTONE:0)
Block(-1,6,3,COBBLESTONE:0)
Block(-1,7,0,STEP:11)
Block(-1,7,3,STEP:11)
Block(0,5,-5,LOG:5)
Block(0,5,8,LOG:5)
Block(0,6,0,STEP:11)
Block(0,6,3,STEP:11)
Block(0,7,0,STEP:11)
Block(0,7,3,STEP:11)
Block(1,5,-5,LOG:5)
Block(1,5,8,LOG:5)
Block(1,6,0,STEP:11)
Block(1,6,3,STEP:11)
Block(1,7,0,STEP:11)
Block(1,7,3,STEP:11)
Block(2,5,-5,LOG:5)
Block(2,5,8,LOG:5)
Block(2,6,0,COBBLESTONE:0)
Block(2,6,3,COBBLESTONE:0)
Block(2,7,0,STEP:11)
Block(2,7,3,STEP:11)
Block(3,0,-6,COBBLESTONE:0)
Block(3,0,9,COBBLESTONE:0)
Block(3,1,-6,COBBLESTONE:0)
Block(3,1,9,COBBLESTONE:0)
Block(3,2,-6,COBBLESTONE:0)
Block(3,2,9,COBBLESTONE:0)
Block(3,3,-6,COBBLESTONE:0)
Block(3,3,9,COBBLESTONE:0)
Block(3,4,-6,COBBLESTONE:0)
Block(3,4,-5,COBBLESTONE_STAIRS:7)
Block(3,4,8,COBBLESTONE_STAIRS:6)
Block(3,4,9,COBBLESTONE:0)
Block(3,5,-6,COBBLESTONE:0)
Block(3,5,-5,LOG:5)
Block(3,5,-4,COBBLESTONE_STAIRS:7)
Block(3,5,-3,STEP:11)
Block(3,5,-2,STEP:11)
Block(3,5,5,STEP:11)
Block(3,5,6,STEP:11)
Block(3,5,7,COBBLESTONE_STAIRS:6)
Block(3,5,8,LOG:5)
Block(3,5,9,COBBLESTONE:0)
Block(3,6,-6,COBBLESTONE:0)
Block(3,6,-5,COBBLESTONE_STAIRS:3)
Block(3,6,-2,COBBLESTONE_STAIRS:2)
Block(3,6,-1,COBBLESTONE_STAIRS:7)
Block(3,6,0,COBBLESTONE:0)
Block(3,6,1,STEP:11)
Block(3,6,2,STEP:11)
Block(3,6,3,COBBLESTONE:0)
Block(3,6,4,COBBLESTONE_STAIRS:6)
Block(3,6,5,COBBLESTONE_STAIRS:3)
Block(3,6,8,COBBLESTONE_STAIRS:2)
Block(3,6,9,COBBLESTONE:0)
Block(3,7,-6,LOG:1)
Block(3,7,-5,COBBLESTONE_STAIRS:7)
Block(3,7,-2,COBBLESTONE_STAIRS:6)
Block(3,7,-1,LOG:1)
Block(3,7,0,STEP:11)
Block(3,7,1,STEP:11)
Block(3,7,2,STEP:11)
Block(3,7,3,STEP:11)
Block(3,7,4,LOG:1)
Block(3,7,5,COBBLESTONE_STAIRS:7)
Block(3,7,8,COBBLESTONE_STAIRS:6)
Block(3,7,9,LOG:1)
Block(4,5,0,STEP:11)
Block(4,5,3,STEP:11)
Block(4,6,0,COBBLESTONE_STAIRS:1)
Block(4,6,3,COBBLESTONE_STAIRS:1)
Block(4,7,0,COBBLESTONE_STAIRS:5)
Block(4,7,3,COBBLESTONE_STAIRS:5)
Block(5,5,0,STEP:11)
Block(5,5,3,STEP:11)
Block(6,5,0,COBBLESTONE_STAIRS:4)
Block(6,5,3,COBBLESTONE_STAIRS:4)
Block(7,4,0,COBBLESTONE_STAIRS:4)
Block(7,4,3,COBBLESTONE_STAIRS:4)
Block(7,5,0,LOG:9)
Block(7,5,1,LOG:9)
Block(7,5,2,LOG:9)
Block(7,5,3,LOG:9)
Block(7,6,0,COBBLESTONE_STAIRS:0)
Block(7,6,3,COBBLESTONE_STAIRS:0)
Block(7,7,0,COBBLESTONE_STAIRS:4)
Block(7,7,3,COBBLESTONE_STAIRS:4)
Block(8,0,0,COBBLESTONE:0)
Block(8,0,3,COBBLESTONE:0)
Block(8,1,0,COBBLESTONE:0)
Block(8,1,3,COBBLESTONE:0)
Block(8,2,0,COBBLESTONE:0)
Block(8,2,3,COBBLESTONE:0)
Block(8,3,0,COBBLESTONE:0)
Block(8,3,3,COBBLESTONE:0)
Block(8,4,0,COBBLESTONE:0)
Block(8,4,3,COBBLESTONE:0)
Block(8,5,0,COBBLESTONE:0)
Block(8,5,3,COBBLESTONE:0)
Block(8,6,0,COBBLESTONE:0)
Block(8,6,3,COBBLESTONE:0)
Block(8,7,0,LOG:1)
Block(8,7,3,LOG:1)

#######################################################################
# +-----------------------------------------------------------------+ #
# |                             Branches                            | #
# +-----------------------------------------------------------------+ #
#######################################################################

Branch(0,-4,0,true,Mineshaft-Village-Guard-Foundation-Ext,NORTH,100.0,0)
Branch(0,-7,0,false,Mineshaft-Village-Guard-Foundation-Ext,NORTH,100.0,0)

#######################################################################
# +-----------------------------------------------------------------+ #
# |                             Entities                            | #
# +-----------------------------------------------------------------+ #
#######################################################################


#######################################################################
# +-----------------------------------------------------------------+ #
# |                            Particles                            | #
# +-----------------------------------------------------------------+ #
#######################################################################


#######################################################################
# +-----------------------------------------------------------------+ #
# |                             Spawners                            | #
# +-----------------------------------------------------------------+ #
#######################################################################


#######################################################################
# +-----------------------------------------------------------------+ #
# |                             ModData                             | #
# +-----------------------------------------------------------------+ #
#######################################################################

