
#######################################################################
# +-----------------------------------------------------------------+ #
# |                            BO3 object                           | #
# +-----------------------------------------------------------------+ #
#######################################################################

Author: NLBlackEagle

Description: No description given

Version: 3

SettingsMode: WriteDisable


#######################################################################
# +-----------------------------------------------------------------+ #
# |                          Main settings                          | #
# +-----------------------------------------------------------------+ #
#######################################################################

Tree: true

Frequency: 1

Rarity: 100.0

RotateRandomly: true

SpawnHeight: highestSolidBlock

SpawnHeightOffset: 0

SpawnHeightVariance: 0

##############################
# Height Limits for the BO3. #
##############################

MinHeight: 0

MaxHeight: 160

######################
# Extrusion settings #
######################

ExtrudeMode: None

ExtrudeThroughBlocks: AIR

MaxBranchDepth: 10

ExcludedBiomes: All


#######################################################################
# +-----------------------------------------------------------------+ #
# |                      Source block settings                      | #
# +-----------------------------------------------------------------+ #
#######################################################################

SourceBlocks: AIR,GRASS,DIRT,SAND

MaxPercentageOutsideSourceBlock: 0

OutsideSourceBlock: placeAnyway

IsOTGPlus: false

InheritBO3: 

InheritBO3Rotation: NORTH

OverrideChildSettings: true

OverrideParentHeight: false

CanOverride: false

BranchFrequency: 0

BranchFrequencyGroup: 

MustBeBelowOther: false

MustBeInside: 

CannotBeInside: 

ReplacesBO3: 

CanSpawnOnWater: true

SpawnOnWaterOnly: false

SpawnUnderWater: false

SpawnAtWaterLevel: false

HeightOffset: 0

RemoveAir: true

ReplaceAbove: 

ReplaceBelow: 

ReplaceWithBiomeBlocks: true

ReplaceWithGroundBlock: DIRT

ReplaceWithSurfaceBlock: GRASS

SmoothRadius: 0

SmoothHeightOffset: 0

SmoothStartTop: false

SmoothStartWood: false

SmoothingSurfaceBlock: 

SmoothingGroundBlock: 

BO3Group: 

IsSpawnPoint: false


#######################################################################
# +-----------------------------------------------------------------+ #
# |                              Blocks                             | #
# +-----------------------------------------------------------------+ #
#######################################################################

Block(-6,5,-1,biomesoplenty:leaves_2:15)
Block(-5,5,-2,biomesoplenty:leaves_2:15)
Block(-5,5,-1,biomesoplenty:log_2:14)
Block(-5,5,0,biomesoplenty:leaves_2:15)
Block(-5,6,-1,biomesoplenty:leaves_2:15)
Block(-4,4,3,biomesoplenty:leaves_2:15)
Block(-4,5,-2,biomesoplenty:leaves_2:15)
Block(-4,5,-1,biomesoplenty:log_2:14)
Block(-4,5,0,biomesoplenty:leaves_2:15)
Block(-4,6,-2,biomesoplenty:leaves_2:15)
Block(-4,6,-1,biomesoplenty:leaves_2:15)
Block(-4,8,2,biomesoplenty:leaves_2:15)
Block(-4,9,2,biomesoplenty:leaves_2:15)
Block(-4,14,0,biomesoplenty:leaves_2:15)
Block(-4,15,0,biomesoplenty:leaves_2:15)
Block(-3,4,1,biomesoplenty:leaves_2:15)
Block(-3,4,3,biomesoplenty:leaves_2:15)
Block(-3,5,-3,biomesoplenty:leaves_2:15)
Block(-3,5,2,biomesoplenty:leaves_2:15)
Block(-3,6,-2,biomesoplenty:leaves_2:15)
Block(-3,6,-1,biomesoplenty:log_2:14)
Block(-3,6,0,biomesoplenty:leaves_2:15)
Block(-3,7,-1,biomesoplenty:leaves_2:15)
Block(-3,7,0,biomesoplenty:leaves_2:15)
Block(-3,8,3,biomesoplenty:leaves_2:15)
Block(-3,9,1,biomesoplenty:leaves_2:15)
Block(-3,9,2,biomesoplenty:log_2:14)
Block(-3,9,3,biomesoplenty:leaves_2:15)
Block(-3,10,2,biomesoplenty:leaves_2:15)
Block(-3,14,2,biomesoplenty:leaves_2:15)
Block(-3,15,-1,biomesoplenty:leaves_2:15)
Block(-3,15,0,biomesoplenty:log_2:14)
Block(-3,15,1,biomesoplenty:leaves_2:15)
Block(-3,16,0,biomesoplenty:leaves_2:15)
Block(-2,5,-4,biomesoplenty:leaves_2:15)
Block(-2,5,-3,biomesoplenty:log_2:14)
Block(-2,5,-2,biomesoplenty:leaves_2:15)
Block(-2,5,1,biomesoplenty:leaves_2:15)
Block(-2,5,2,biomesoplenty:leaves_2:15)
Block(-2,6,-3,biomesoplenty:leaves_2:15)
Block(-2,6,-1,biomesoplenty:leaves_2:15)
Block(-2,7,-2,biomesoplenty:leaves_2:15)
Block(-2,7,-1,biomesoplenty:leaves_2:15)
Block(-2,7,0,biomesoplenty:log_2:14)
Block(-2,7,1,biomesoplenty:leaves_2:15)
Block(-2,8,0,biomesoplenty:leaves_2:15)
Block(-2,9,0,biomesoplenty:leaves_2:15)
Block(-2,9,1,biomesoplenty:log_2:14)
Block(-2,9,2,biomesoplenty:leaves_2:15)
Block(-2,10,1,biomesoplenty:leaves_2:15)
Block(-2,12,0,biomesoplenty:leaves_2:15)
Block(-2,12,1,biomesoplenty:leaves_2:15)
Block(-2,13,4,biomesoplenty:leaves_2:15)
Block(-2,14,3,biomesoplenty:leaves_2:15)
Block(-2,15,-1,biomesoplenty:leaves_2:15)
Block(-2,15,2,biomesoplenty:leaves_2:15)
Block(-2,15,3,biomesoplenty:leaves_2:15)
Block(-2,16,-1,biomesoplenty:leaves_2:15)
Block(-2,16,0,biomesoplenty:log_2:14)
Block(-2,17,0,biomesoplenty:leaves_2:15)
Block(-2,21,-1,biomesoplenty:leaves_2:15)
Block(-2,21,1,biomesoplenty:leaves_2:15)
Block(-1,3,6,biomesoplenty:leaves_2:15)
Block(-1,4,4,biomesoplenty:leaves_2:15)
Block(-1,4,5,biomesoplenty:leaves_2:15)
Block(-1,5,-3,biomesoplenty:leaves_2:15)
Block(-1,5,-2,biomesoplenty:log_2:14)
Block(-1,5,-1,biomesoplenty:log_2:14)
Block(-1,5,2,biomesoplenty:leaves_2:15)
Block(-1,5,3,biomesoplenty:leaves_2:15)
Block(-1,6,-2,biomesoplenty:leaves_2:15)
Block(-1,6,0,biomesoplenty:leaves_2:15)
Block(-1,6,1,biomesoplenty:leaves_2:15)
Block(-1,7,-1,biomesoplenty:leaves_2:15)
Block(-1,7,0,biomesoplenty:log_2:14)
Block(-1,7,1,biomesoplenty:leaves_2:15)
Block(-1,8,-6,biomesoplenty:leaves_2:15)
Block(-1,8,-5,biomesoplenty:leaves_2:15)
Block(-1,8,0,biomesoplenty:leaves_2:15)
Block(-1,8,2,biomesoplenty:leaves_2:15)
Block(-1,9,-5,biomesoplenty:leaves_2:15)
Block(-1,9,-4,biomesoplenty:leaves_2:15)
Block(-1,9,-3,biomesoplenty:leaves_2:15)
Block(-1,9,-1,biomesoplenty:leaves_2:15)
Block(-1,9,0,biomesoplenty:leaves_2:15)
Block(-1,9,1,biomesoplenty:log_2:14)
Block(-1,9,2,biomesoplenty:leaves_2:15)
Block(-1,10,-2,biomesoplenty:leaves_2:15)
Block(-1,10,-1,biomesoplenty:leaves_2:15)
Block(-1,10,1,biomesoplenty:leaves_2:15)
Block(-1,10,2,biomesoplenty:leaves_2:15)
Block(-1,11,1,biomesoplenty:leaves_2:15)
Block(-1,13,-1,biomesoplenty:leaves_2:15)
Block(-1,13,0,biomesoplenty:leaves_2:15)
Block(-1,14,-2,biomesoplenty:leaves_2:15)
Block(-1,14,-1,biomesoplenty:leaves_2:15)
Block(-1,15,0,biomesoplenty:leaves_2:15)
Block(-1,15,2,biomesoplenty:log_2:14)
Block(-1,15,3,biomesoplenty:leaves_2:15)
Block(-1,16,-1,biomesoplenty:leaves_2:15)
Block(-1,16,0,biomesoplenty:log_2:14)
Block(-1,16,1,biomesoplenty:leaves_2:15)
Block(-1,16,2,biomesoplenty:leaves_2:15)
Block(-1,17,0,biomesoplenty:leaves_2:15)
Block(-1,17,2,biomesoplenty:leaves_2:15)
Block(-1,18,1,biomesoplenty:leaves_2:15)
Block(-1,19,-1,biomesoplenty:leaves_2:15)
Block(-1,19,0,biomesoplenty:leaves_2:15)
Block(-1,21,-2,biomesoplenty:leaves_2:15)
Block(-1,21,-1,biomesoplenty:log_2:14)
Block(-1,21,0,biomesoplenty:leaves_2:15)
Block(-1,21,3,biomesoplenty:leaves_2:15)
Block(-1,22,0,biomesoplenty:leaves_2:15)
Block(-1,22,1,biomesoplenty:leaves_2:15)
Block(-1,22,2,biomesoplenty:leaves_2:15)
Block(-1,24,0,biomesoplenty:leaves_2:15)
Block(-1,27,0,biomesoplenty:leaves_2:15)
Block(0,0,0,biomesoplenty:log_2:14)
Block(0,1,0,biomesoplenty:log_2:14)
Block(0,2,0,biomesoplenty:log_2:14)
Block(0,3,0,biomesoplenty:log_2:14)
Block(0,4,0,biomesoplenty:log_2:14)
Block(0,4,4,biomesoplenty:log_2:14)
Block(0,4,5,biomesoplenty:log_2:14)
Block(0,4,6,biomesoplenty:leaves_2:15)
Block(0,5,-2,biomesoplenty:leaves_2:15)
Block(0,5,-1,biomesoplenty:leaves_2:15)
Block(0,5,0,biomesoplenty:log_2:14)
Block(0,5,1,biomesoplenty:leaves_2:15)
Block(0,5,2,biomesoplenty:log_2:14)
Block(0,5,3,biomesoplenty:log_2:14)
Block(0,5,4,biomesoplenty:leaves_2:15)
Block(0,5,5,biomesoplenty:leaves_2:15)
Block(0,6,0,biomesoplenty:log_2:14)
Block(0,6,1,biomesoplenty:log_2:14)
Block(0,6,2,biomesoplenty:leaves_2:15)
Block(0,6,3,biomesoplenty:leaves_2:15)
Block(0,7,-1,biomesoplenty:leaves_2:15)
Block(0,7,0,biomesoplenty:log_2:14)
Block(0,8,-5,biomesoplenty:leaves_2:15)
Block(0,8,-4,biomesoplenty:leaves_2:15)
Block(0,8,0,biomesoplenty:log_2:14)
Block(0,8,2,biomesoplenty:leaves_2:15)
Block(0,9,-5,biomesoplenty:leaves_2:15)
Block(0,9,-4,biomesoplenty:log_2:14)
Block(0,9,-3,biomesoplenty:log_2:14)
Block(0,9,0,biomesoplenty:log_2:14)
Block(0,9,1,biomesoplenty:log_2:14)
Block(0,9,2,biomesoplenty:leaves_2:15)
Block(0,9,3,biomesoplenty:leaves_2:15)
Block(0,10,-4,biomesoplenty:leaves_2:15)
Block(0,10,-3,biomesoplenty:leaves_2:15)
Block(0,10,-2,biomesoplenty:log_2:14)
Block(0,10,-1,biomesoplenty:log_2:14)
Block(0,10,0,biomesoplenty:log_2:14)
Block(0,10,1,biomesoplenty:log_2:14)
Block(0,10,2,biomesoplenty:leaves_2:15)
Block(0,11,-2,biomesoplenty:leaves_2:15)
Block(0,11,-1,biomesoplenty:leaves_2:15)
Block(0,11,0,biomesoplenty:log_2:14)
Block(0,11,1,biomesoplenty:leaves_2:15)
Block(0,12,0,biomesoplenty:log_2:14)
Block(0,13,-4,biomesoplenty:leaves_2:15)
Block(0,13,-3,biomesoplenty:leaves_2:15)
Block(0,13,0,biomesoplenty:log_2:14)
Block(0,14,-3,biomesoplenty:leaves_2:15)
Block(0,14,-2,biomesoplenty:log_2:14)
Block(0,14,-1,biomesoplenty:log_2:14)
Block(0,14,0,biomesoplenty:log_2:14)
Block(0,14,3,biomesoplenty:leaves_2:15)
Block(0,15,-2,biomesoplenty:leaves_2:15)
Block(0,15,-1,biomesoplenty:leaves_2:15)
Block(0,15,0,biomesoplenty:log_2:14)
Block(0,15,1,biomesoplenty:log_2:14)
Block(0,15,2,biomesoplenty:leaves_2:15)
Block(0,16,-1,biomesoplenty:leaves_2:15)
Block(0,16,0,biomesoplenty:log_2:14)
Block(0,16,1,biomesoplenty:leaves_2:15)
Block(0,17,-1,biomesoplenty:leaves_2:15)
Block(0,17,0,biomesoplenty:log_2:14)
Block(0,17,2,biomesoplenty:log_2:14)
Block(0,17,3,biomesoplenty:leaves_2:15)
Block(0,18,0,biomesoplenty:log_2:14)
Block(0,18,1,biomesoplenty:log_2:14)
Block(0,18,2,biomesoplenty:leaves_2:15)
Block(0,19,-2,biomesoplenty:leaves_2:15)
Block(0,19,-1,biomesoplenty:log_2:14)
Block(0,19,0,biomesoplenty:log_2:14)
Block(0,19,1,biomesoplenty:leaves_2:15)
Block(0,20,-1,biomesoplenty:leaves_2:15)
Block(0,20,0,biomesoplenty:log_2:14)
Block(0,20,1,biomesoplenty:log_2:14)
Block(0,20,2,biomesoplenty:leaves_2:15)
Block(0,21,-3,biomesoplenty:leaves_2:15)
Block(0,21,-1,biomesoplenty:leaves_2:15)
Block(0,21,0,biomesoplenty:log_2:14)
Block(0,21,1,biomesoplenty:leaves_2:15)
Block(0,21,3,biomesoplenty:log_2:14)
Block(0,21,4,biomesoplenty:leaves_2:15)
Block(0,22,-2,biomesoplenty:leaves_2:15)
Block(0,22,0,biomesoplenty:log_2:14)
Block(0,22,1,biomesoplenty:log_2:14)
Block(0,22,2,biomesoplenty:log_2:14)
Block(0,22,3,biomesoplenty:leaves_2:15)
Block(0,23,-1,biomesoplenty:leaves_2:15)
Block(0,23,0,biomesoplenty:log_2:14)
Block(0,23,1,biomesoplenty:leaves_2:15)
Block(0,23,2,biomesoplenty:leaves_2:15)
Block(0,24,0,biomesoplenty:log_2:14)
Block(0,24,1,biomesoplenty:leaves_2:15)
Block(0,25,-1,biomesoplenty:leaves_2:15)
Block(0,25,0,biomesoplenty:log_2:14)
Block(0,25,1,biomesoplenty:leaves_2:15)
Block(0,26,0,biomesoplenty:log_2:14)
Block(0,27,-1,biomesoplenty:leaves_2:15)
Block(0,27,0,biomesoplenty:leaves_2:15)
Block(0,27,1,biomesoplenty:leaves_2:15)
Block(0,28,0,biomesoplenty:leaves_2:15)
Block(0,29,0,biomesoplenty:leaves_2:15)
Block(1,4,4,biomesoplenty:leaves_2:15)
Block(1,4,5,biomesoplenty:leaves_2:15)
Block(1,5,0,biomesoplenty:log_2:14)
Block(1,5,2,biomesoplenty:leaves_2:15)
Block(1,5,3,biomesoplenty:leaves_2:15)
Block(1,6,-1,biomesoplenty:leaves_2:15)
Block(1,6,0,biomesoplenty:log_2:14)
Block(1,6,1,biomesoplenty:leaves_2:15)
Block(1,9,-4,biomesoplenty:leaves_2:15)
Block(1,9,-3,biomesoplenty:leaves_2:15)
Block(1,9,1,biomesoplenty:leaves_2:15)
Block(1,10,-2,biomesoplenty:leaves_2:15)
Block(1,10,-1,biomesoplenty:leaves_2:15)
Block(1,10,0,biomesoplenty:leaves_2:15)
Block(1,11,0,biomesoplenty:leaves_2:15)
Block(1,11,1,biomesoplenty:log_2:14)
Block(1,11,2,biomesoplenty:leaves_2:15)
Block(1,12,1,biomesoplenty:leaves_2:15)
Block(1,14,-2,biomesoplenty:leaves_2:15)
Block(1,14,-1,biomesoplenty:leaves_2:15)
Block(1,14,3,biomesoplenty:log_2:14)
Block(1,14,4,biomesoplenty:leaves_2:15)
Block(1,15,-1,biomesoplenty:leaves_2:15)
Block(1,15,0,biomesoplenty:log_2:14)
Block(1,15,1,biomesoplenty:leaves_2:15)
Block(1,15,2,biomesoplenty:log_2:14)
Block(1,15,3,biomesoplenty:leaves_2:15)
Block(1,16,0,biomesoplenty:leaves_2:15)
Block(1,16,2,biomesoplenty:leaves_2:15)
Block(1,17,2,biomesoplenty:leaves_2:15)
Block(1,18,-2,biomesoplenty:leaves_2:15)
Block(1,18,-1,biomesoplenty:log_2:14)
Block(1,18,0,biomesoplenty:leaves_2:15)
Block(1,18,1,biomesoplenty:leaves_2:15)
Block(1,19,-1,biomesoplenty:leaves_2:15)
Block(1,19,0,biomesoplenty:leaves_2:15)
Block(1,21,-1,biomesoplenty:leaves_2:15)
Block(1,21,0,biomesoplenty:log_2:14)
Block(1,21,1,biomesoplenty:leaves_2:15)
Block(1,21,3,biomesoplenty:leaves_2:15)
Block(1,22,0,biomesoplenty:leaves_2:15)
Block(1,22,1,biomesoplenty:leaves_2:15)
Block(1,22,2,biomesoplenty:leaves_2:15)
Block(1,23,0,biomesoplenty:leaves_2:15)
Block(1,25,0,biomesoplenty:leaves_2:15)
Block(1,27,0,biomesoplenty:leaves_2:15)
Block(2,4,-1,biomesoplenty:leaves_2:15)
Block(2,5,-2,biomesoplenty:leaves_2:15)
Block(2,5,0,biomesoplenty:leaves_2:15)
Block(2,5,1,biomesoplenty:leaves_2:15)
Block(2,5,2,biomesoplenty:leaves_2:15)
Block(2,6,-1,biomesoplenty:leaves_2:15)
Block(2,6,0,biomesoplenty:log_2:14)
Block(2,6,1,biomesoplenty:leaves_2:15)
Block(2,7,0,biomesoplenty:leaves_2:15)
Block(2,10,2,biomesoplenty:leaves_2:15)
Block(2,10,3,biomesoplenty:leaves_2:15)
Block(2,11,0,biomesoplenty:leaves_2:15)
Block(2,11,1,biomesoplenty:log_2:14)
Block(2,11,2,biomesoplenty:leaves_2:15)
Block(2,12,1,biomesoplenty:leaves_2:15)
Block(2,13,-3,biomesoplenty:leaves_2:15)
Block(2,14,-1,biomesoplenty:leaves_2:15)
Block(2,14,0,biomesoplenty:log_2:14)
Block(2,14,1,biomesoplenty:leaves_2:15)
Block(2,14,3,biomesoplenty:leaves_2:15)
Block(2,15,0,biomesoplenty:leaves_2:15)
Block(2,15,2,biomesoplenty:leaves_2:15)
Block(2,17,-2,biomesoplenty:leaves_2:15)
Block(2,17,-1,biomesoplenty:log_2:14)
Block(2,17,0,biomesoplenty:leaves_2:15)
Block(2,18,-1,biomesoplenty:leaves_2:15)
Block(2,21,-1,biomesoplenty:leaves_2:15)
Block(2,21,0,biomesoplenty:log_2:14)
Block(2,21,1,biomesoplenty:leaves_2:15)
Block(2,22,0,biomesoplenty:leaves_2:15)
Block(2,22,1,biomesoplenty:leaves_2:15)
Block(3,4,-3,biomesoplenty:leaves_2:15)
Block(3,4,-2,biomesoplenty:leaves_2:15)
Block(3,4,2,biomesoplenty:leaves_2:15)
Block(3,5,-3,biomesoplenty:leaves_2:15)
Block(3,5,-2,biomesoplenty:log_2:14)
Block(3,5,-1,biomesoplenty:leaves_2:15)
Block(3,5,1,biomesoplenty:leaves_2:15)
Block(3,6,-2,biomesoplenty:leaves_2:15)
Block(3,6,-1,biomesoplenty:log_2:14)
Block(3,6,0,biomesoplenty:leaves_2:15)
Block(3,7,-1,biomesoplenty:leaves_2:15)
Block(3,9,3,biomesoplenty:leaves_2:15)
Block(3,10,0,biomesoplenty:leaves_2:15)
Block(3,10,1,biomesoplenty:log_2:14)
Block(3,10,2,biomesoplenty:log_2:14)
Block(3,10,3,biomesoplenty:leaves_2:15)
Block(3,11,1,biomesoplenty:leaves_2:15)
Block(3,11,2,biomesoplenty:leaves_2:15)
Block(3,13,-1,biomesoplenty:leaves_2:15)
Block(3,14,-1,biomesoplenty:leaves_2:15)
Block(3,14,0,biomesoplenty:log_2:14)
Block(3,14,1,biomesoplenty:leaves_2:15)
Block(3,15,0,biomesoplenty:leaves_2:15)
Block(3,17,-1,biomesoplenty:leaves_2:15)
Block(3,21,0,biomesoplenty:leaves_2:15)
Block(4,4,-4,biomesoplenty:leaves_2:15)
Block(4,4,-3,biomesoplenty:log_2:14)
Block(4,4,1,biomesoplenty:leaves_2:15)
Block(4,5,-3,biomesoplenty:leaves_2:15)
Block(4,5,-2,biomesoplenty:log_2:14)
Block(4,5,-1,biomesoplenty:leaves_2:15)
Block(4,6,-2,biomesoplenty:leaves_2:15)
Block(4,6,-1,biomesoplenty:leaves_2:15)
Block(4,9,1,biomesoplenty:leaves_2:15)
Block(4,10,1,biomesoplenty:leaves_2:15)
Block(4,10,2,biomesoplenty:leaves_2:15)
Block(4,13,0,biomesoplenty:leaves_2:15)
Block(4,14,0,biomesoplenty:leaves_2:15)
Block(5,4,-3,biomesoplenty:leaves_2:15)
Block(5,4,-2,biomesoplenty:leaves_2:15)
Block(5,5,-2,biomesoplenty:leaves_2:15)

#######################################################################
# +-----------------------------------------------------------------+ #
# |                            BO3 checks                           | #
# +-----------------------------------------------------------------+ #
#######################################################################

BlockCheck(0,-1,0,GRASS,DIRT,biomesoplenty:grass)

#######################################################################
# +-----------------------------------------------------------------+ #
# |                             Branches                            | #
# +-----------------------------------------------------------------+ #
#######################################################################


#######################################################################
# +-----------------------------------------------------------------+ #
# |                             Entities                            | #
# +-----------------------------------------------------------------+ #
#######################################################################


#######################################################################
# +-----------------------------------------------------------------+ #
# |                            Particles                            | #
# +-----------------------------------------------------------------+ #
#######################################################################


#######################################################################
# +-----------------------------------------------------------------+ #
# |                             Spawners                            | #
# +-----------------------------------------------------------------+ #
#######################################################################


#######################################################################
# +-----------------------------------------------------------------+ #
# |                             ModData                             | #
# +-----------------------------------------------------------------+ #
#######################################################################

