
#######################################################################
# +-----------------------------------------------------------------+ #
# |                            BO3 object                           | #
# +-----------------------------------------------------------------+ #
#######################################################################

Author: NLBlackEagle

Description: No description given

Version: 3

SettingsMode: WriteWithoutComments


#######################################################################
# +-----------------------------------------------------------------+ #
# |                          Main settings                          | #
# +-----------------------------------------------------------------+ #
#######################################################################

Tree: false

Frequency: 20

Rarity: 100.0

RotateRandomly: false

SpawnHeight: randomY

SpawnHeightOffset: 0

SpawnHeightVariance: 0

##############################
# Height Limits for the BO3. #
##############################

MinHeight: 0

MaxHeight: 66

######################
# Extrusion settings #
######################

ExtrudeMode: None

ExtrudeThroughBlocks: AIR

MaxBranchDepth: 10

ExcludedBiomes: All


#######################################################################
# +-----------------------------------------------------------------+ #
# |                      Source block settings                      | #
# +-----------------------------------------------------------------+ #
#######################################################################

SourceBlocks: AIR,STAINED_CLAY,dynamictreesbop:leaves1

MaxPercentageOutsideSourceBlock: 0

OutsideSourceBlock: dontPlace

DoReplaceBlocks: true

IsOTGPlus: false


#######################################################################
# +-----------------------------------------------------------------+ #
# |                              Blocks                             | #
# +-----------------------------------------------------------------+ #
#######################################################################

Block(-3,4,3,dynamictreesbop:leaves1:12)
Block(-3,4,4,dynamictreesbop:leaves1:12)
Block(-3,4,5,dynamictreesbop:leaves1:12)
Block(-3,5,3,dynamictreesbop:leaves1:12)
Block(-3,5,4,dynamictreesbop:leaves1:12)
Block(-2,3,3,dynamictreesbop:leaves1:12)
Block(-2,3,4,dynamictreesbop:leaves1:12)
Block(-2,3,5,dynamictreesbop:leaves1:12)
Block(-2,4,2,dynamictreesbop:leaves1:12)
Block(-2,4,3,dynamictreesbop:leaves1:15)
Block(-2,4,4,dynamictreesbop:leaves1:14)
Block(-2,4,5,dynamictreesbop:leaves1:13)
Block(-2,4,6,dynamictreesbop:leaves1:12)
Block(-2,5,1,dynamictreesbop:leaves1:12)
Block(-2,5,2,dynamictreesbop:leaves1:12)
Block(-2,5,3,dynamictreesbop:leaves1:14)
Block(-2,5,4,dynamictreesbop:leaves1:13)
Block(-2,5,5,dynamictreesbop:leaves1:12)
Block(-2,6,1,dynamictreesbop:leaves1:12)
Block(-2,6,2,dynamictreesbop:leaves1:12)
Block(-2,6,3,dynamictreesbop:leaves1:12)
Block(-2,6,4,dynamictreesbop:leaves1:12)
Block(-1,3,2,dynamictreesbop:cherrybranch:1)
Block(-1,3,4,dynamictreesbop:leaves1:12)
Block(-1,3,5,dynamictreesbop:leaves1:13)
Block(-1,3,6,dynamictreesbop:leaves1:12)
Block(-1,3,7,dynamictreesbop:leaves1:12)
Block(-1,4,2,dynamictreesbop:cherrybranch:1)
Block(-1,4,3,dynamictreesbop:cherrybranch)
Block(-1,4,4,dynamictreesbop:leaves1:15)
Block(-1,4,5,dynamictreesbop:leaves1:14)
Block(-1,4,6,dynamictreesbop:leaves1:13)
Block(-1,4,7,dynamictreesbop:leaves1:12)
Block(-1,5,0,dynamictreesbop:leaves1:12)
Block(-1,5,1,dynamictreesbop:leaves1:14)
Block(-1,5,2,dynamictreesbop:leaves1:15)
Block(-1,5,3,dynamictreesbop:leaves1:15)
Block(-1,5,4,dynamictreesbop:leaves1:14)
Block(-1,5,5,dynamictreesbop:leaves1:13)
Block(-1,5,6,dynamictreesbop:leaves1:12)
Block(-1,6,0,dynamictreesbop:leaves1:12)
Block(-1,6,1,dynamictreesbop:leaves1:13)
Block(-1,6,2,dynamictreesbop:leaves1:14)
Block(-1,6,3,dynamictreesbop:leaves1:13)
Block(-1,6,4,dynamictreesbop:leaves1:12)
Block(-1,6,5,dynamictreesbop:leaves1:12)
Block(-1,7,0,dynamictreesbop:leaves1:12)
Block(-1,7,1,dynamictreesbop:leaves1:12)
Block(-1,7,2,dynamictreesbop:leaves1:12)
Block(-1,7,3,dynamictreesbop:leaves1:12)
Block(-1,8,1,dynamictreesbop:leaves1:12)
Block(0,2,7,dynamictreesbop:leaves1:12)
Block(0,3,1,dynamictreesbop:cherrybranch)
Block(0,3,2,dynamictreesbop:cherrybranch:2)
Block(0,3,5,dynamictreesbop:leaves1:14)
Block(0,3,6,dynamictreesbop:leaves1:15)
Block(0,3,7,dynamictreesbop:leaves1:14)
Block(0,3,8,dynamictreesbop:leaves1:12)
Block(0,4,1,dynamictreesbop:leaves1:15)
Block(0,4,4,dynamictreesbop:leaves1:14)
Block(0,4,5,dynamictreesbop:leaves1:15)
Block(0,4,6,dynamictreesbop:leaves1:14)
Block(0,4,7,dynamictreesbop:leaves1:13)
Block(0,4,8,dynamictreesbop:leaves1:12)
Block(0,5,0,dynamictreesbop:leaves1:12)
Block(0,5,1,dynamictreesbop:leaves1:15)
Block(0,5,2,dynamictreesbop:cherrybranch)
Block(0,5,3,dynamictreesbop:leaves1:15)
Block(0,5,4,dynamictreesbop:leaves1:14)
Block(0,5,5,dynamictreesbop:leaves1:14)
Block(0,5,6,dynamictreesbop:leaves1:13)
Block(0,5,7,dynamictreesbop:leaves1:12)
Block(0,6,-1,dynamictreesbop:leaves1:12)
Block(0,6,0,dynamictreesbop:leaves1:14)
Block(0,6,1,dynamictreesbop:leaves1:15)
Block(0,6,2,dynamictreesbop:leaves1:15)
Block(0,6,3,dynamictreesbop:leaves1:14)
Block(0,6,4,dynamictreesbop:leaves1:13)
Block(0,6,5,dynamictreesbop:leaves1:12)
Block(0,6,6,dynamictreesbop:leaves1:12)
Block(0,7,-1,dynamictreesbop:leaves1:12)
Block(0,7,0,dynamictreesbop:leaves1:13)
Block(0,7,1,dynamictreesbop:leaves1:14)
Block(0,7,2,dynamictreesbop:leaves1:12)
Block(0,7,3,dynamictreesbop:leaves1:12)
Block(0,7,4,dynamictreesbop:leaves1:12)
Block(0,8,0,dynamictreesbop:leaves1:12)
Block(0,8,1,dynamictreesbop:leaves1:13)
Block(0,8,2,dynamictreesbop:leaves1:12)
Block(0,9,1,dynamictreesbop:leaves1:12)
Block(1,0,2,dynamictrees:rootydirt:0)
Block(1,1,2,dynamictreesbop:cherrybranch:6)
Block(1,2,2,dynamictreesbop:cherrybranch:5)
Block(1,3,2,dynamictreesbop:cherrybranch:5)
Block(1,3,3,dynamictreesbop:cherrybranch:2)
Block(1,3,4,dynamictreesbop:cherrybranch:1)
Block(1,3,5,dynamictreesbop:cherrybranch:1)
Block(1,3,6,dynamictreesbop:cherrybranch)
Block(1,3,7,dynamictreesbop:leaves1:15)
Block(1,3,8,dynamictreesbop:leaves1:12)
Block(1,4,1,dynamictreesbop:cherrybranch)
Block(1,4,2,dynamictreesbop:cherrybranch:3)
Block(1,4,5,dynamictreesbop:cherrybranch)
Block(1,4,6,dynamictreesbop:leaves1:15)
Block(1,4,7,dynamictreesbop:leaves1:14)
Block(1,4,8,dynamictreesbop:leaves1:12)
Block(1,5,1,dynamictreesbop:leaves1:15)
Block(1,5,2,dynamictreesbop:cherrybranch:2)
Block(1,5,3,dynamictreesbop:cherrybranch)
Block(1,5,4,dynamictreesbop:leaves1:15)
Block(1,5,5,dynamictreesbop:leaves1:15)
Block(1,5,6,dynamictreesbop:leaves1:14)
Block(1,5,7,dynamictreesbop:leaves1:13)
Block(1,5,8,dynamictreesbop:leaves1:12)
Block(1,6,-1,dynamictreesbop:leaves1:12)
Block(1,6,0,dynamictreesbop:leaves1:15)
Block(1,6,1,dynamictreesbop:cherrybranch)
Block(1,6,2,dynamictreesbop:cherrybranch:2)
Block(1,6,3,dynamictreesbop:leaves1:15)
Block(1,6,4,dynamictreesbop:leaves1:14)
Block(1,6,5,dynamictreesbop:leaves1:12)
Block(1,6,6,dynamictreesbop:leaves1:12)
Block(1,6,7,dynamictreesbop:leaves1:12)
Block(1,7,-1,dynamictreesbop:leaves1:12)
Block(1,7,0,dynamictreesbop:leaves1:14)
Block(1,7,1,dynamictreesbop:leaves1:15)
Block(1,7,2,dynamictreesbop:cherrybranch:1)
Block(1,7,3,dynamictreesbop:leaves1:12)
Block(1,7,4,dynamictreesbop:leaves1:12)
Block(1,8,-1,dynamictreesbop:leaves1:12)
Block(1,8,0,dynamictreesbop:leaves1:13)
Block(1,8,1,dynamictreesbop:leaves1:14)
Block(1,8,2,dynamictreesbop:cherrybranch:1)
Block(1,8,3,dynamictreesbop:leaves1:12)
Block(1,9,0,dynamictreesbop:leaves1:12)
Block(1,9,1,dynamictreesbop:leaves1:13)
Block(1,9,2,dynamictreesbop:leaves1:12)
Block(1,9,3,dynamictreesbop:leaves1:12)
Block(1,10,1,dynamictreesbop:leaves1:12)
Block(2,2,7,dynamictreesbop:leaves1:12)
Block(2,3,3,dynamictreesbop:cherrybranch:1)
Block(2,3,5,dynamictreesbop:leaves1:14)
Block(2,3,6,dynamictreesbop:leaves1:15)
Block(2,3,7,dynamictreesbop:leaves1:14)
Block(2,3,8,dynamictreesbop:leaves1:12)
Block(2,4,2,dynamictreesbop:cherrybranch:1)
Block(2,4,5,dynamictreesbop:leaves1:15)
Block(2,4,6,dynamictreesbop:leaves1:14)
Block(2,4,7,dynamictreesbop:leaves1:13)
Block(2,4,8,dynamictreesbop:leaves1:12)
Block(2,5,5,dynamictreesbop:leaves1:14)
Block(2,5,6,dynamictreesbop:leaves1:13)
Block(2,5,7,dynamictreesbop:leaves1:12)
Block(2,6,0,dynamictreesbop:leaves1:12)
Block(2,6,4,dynamictreesbop:leaves1:12)
Block(2,6,5,dynamictreesbop:leaves1:12)
Block(2,6,6,dynamictreesbop:leaves1:12)
Block(2,7,-1,dynamictreesbop:leaves1:12)
Block(2,7,0,dynamictreesbop:leaves1:13)
Block(2,7,1,dynamictreesbop:leaves1:14)
Block(2,7,2,dynamictreesbop:leaves1:15)
Block(2,7,3,dynamictreesbop:leaves1:14)
Block(2,7,4,dynamictreesbop:leaves1:12)
Block(2,8,0,dynamictreesbop:leaves1:12)
Block(2,8,1,dynamictreesbop:leaves1:15)
Block(2,8,2,dynamictreesbop:cherrybranch)
Block(2,8,3,dynamictreesbop:leaves1:15)
Block(2,8,4,dynamictreesbop:leaves1:12)
Block(2,9,0,dynamictreesbop:leaves1:12)
Block(2,9,1,dynamictreesbop:leaves1:14)
Block(2,9,2,dynamictreesbop:leaves1:15)
Block(2,9,3,dynamictreesbop:leaves1:14)
Block(2,9,4,dynamictreesbop:leaves1:12)
Block(2,10,1,dynamictreesbop:leaves1:12)
Block(2,10,2,dynamictreesbop:leaves1:12)
Block(2,10,3,dynamictreesbop:leaves1:12)
Block(3,3,3,dynamictreesbop:cherrybranch)
Block(3,3,4,dynamictreesbop:leaves1:15)
Block(3,3,5,dynamictreesbop:leaves1:12)
Block(3,3,6,dynamictreesbop:leaves1:12)
Block(3,3,7,dynamictreesbop:leaves1:12)
Block(3,4,2,dynamictreesbop:cherrybranch)
Block(3,4,3,dynamictreesbop:leaves1:15)
Block(3,4,4,dynamictreesbop:leaves1:14)
Block(3,4,5,dynamictreesbop:leaves1:12)
Block(3,4,6,dynamictreesbop:leaves1:12)
Block(3,4,7,dynamictreesbop:leaves1:12)
Block(3,5,2,dynamictreesbop:leaves1:15)
Block(3,5,3,dynamictreesbop:leaves1:14)
Block(3,5,4,dynamictreesbop:leaves1:13)
Block(3,5,5,dynamictreesbop:leaves1:12)
Block(3,5,6,dynamictreesbop:leaves1:12)
Block(3,6,1,dynamictreesbop:leaves1:12)
Block(3,6,2,dynamictreesbop:leaves1:12)
Block(3,6,3,dynamictreesbop:leaves1:12)
Block(3,6,4,dynamictreesbop:leaves1:12)
Block(3,7,0,dynamictreesbop:leaves1:12)
Block(3,7,1,dynamictreesbop:leaves1:13)
Block(3,7,2,dynamictreesbop:leaves1:14)
Block(3,7,3,dynamictreesbop:leaves1:13)
Block(3,7,4,dynamictreesbop:leaves1:12)
Block(3,8,0,dynamictreesbop:leaves1:12)
Block(3,8,1,dynamictreesbop:leaves1:14)
Block(3,8,2,dynamictreesbop:leaves1:15)
Block(3,8,3,dynamictreesbop:leaves1:14)
Block(3,8,4,dynamictreesbop:leaves1:12)
Block(3,9,0,dynamictreesbop:leaves1:12)
Block(3,9,1,dynamictreesbop:leaves1:13)
Block(3,9,2,dynamictreesbop:leaves1:14)
Block(3,9,3,dynamictreesbop:leaves1:13)
Block(3,9,4,dynamictreesbop:leaves1:12)
Block(3,10,1,dynamictreesbop:leaves1:12)
Block(3,10,2,dynamictreesbop:leaves1:12)
Block(3,10,3,dynamictreesbop:leaves1:12)
Block(4,3,1,dynamictreesbop:leaves1:12)
Block(4,3,4,dynamictreesbop:leaves1:12)
Block(4,4,1,dynamictreesbop:leaves1:12)
Block(4,4,3,dynamictreesbop:leaves1:12)
Block(4,4,4,dynamictreesbop:leaves1:12)
Block(4,5,0,dynamictreesbop:leaves1:12)
Block(4,5,3,dynamictreesbop:leaves1:12)
Block(4,5,4,dynamictreesbop:leaves1:12)
Block(4,6,1,dynamictreesbop:leaves1:12)
Block(4,6,2,dynamictreesbop:leaves1:12)
Block(4,7,1,dynamictreesbop:leaves1:12)
Block(4,7,2,dynamictreesbop:leaves1:12)
Block(4,7,3,dynamictreesbop:leaves1:12)
Block(4,8,1,dynamictreesbop:leaves1:12)
Block(4,8,2,dynamictreesbop:leaves1:12)
Block(4,8,3,dynamictreesbop:leaves1:12)
Block(4,9,1,dynamictreesbop:leaves1:12)
Block(4,9,2,dynamictreesbop:leaves1:12)
Block(4,9,3,dynamictreesbop:leaves1:12)
Block(5,5,1,dynamictreesbop:leaves1:12)
Block(5,5,2,dynamictreesbop:leaves1:12)
Block(5,5,3,dynamictreesbop:leaves1:12)

#######################################################################
# +-----------------------------------------------------------------+ #
# |                            BO3 checks                           | #
# +-----------------------------------------------------------------+ #
#######################################################################

BlockCheck(1,0,2,STAINED_CLAY)

#######################################################################
# +-----------------------------------------------------------------+ #
# |                             Branches                            | #
# +-----------------------------------------------------------------+ #
#######################################################################


#######################################################################
# +-----------------------------------------------------------------+ #
# |                             Entities                            | #
# +-----------------------------------------------------------------+ #
#######################################################################


#######################################################################
# +-----------------------------------------------------------------+ #
# |                            Particles                            | #
# +-----------------------------------------------------------------+ #
#######################################################################


#######################################################################
# +-----------------------------------------------------------------+ #
# |                             Spawners                            | #
# +-----------------------------------------------------------------+ #
#######################################################################


#######################################################################
# +-----------------------------------------------------------------+ #
# |                             ModData                             | #
# +-----------------------------------------------------------------+ #
#######################################################################

