
#######################################################################
# +-----------------------------------------------------------------+ #
# |                            BO3 object                           | #
# +-----------------------------------------------------------------+ #
#######################################################################

Author: NLBlackHeavenNL

Description: No description given

Version: 3

SettingsMode: WriteWithoutComments


#######################################################################
# +-----------------------------------------------------------------+ #
# |                          Main settings                          | #
# +-----------------------------------------------------------------+ #
#######################################################################

Tree: true

Frequency: 1

Rarity: 100.0

RotateRandomly: false

SpawnHeight: highestSolidBlock

SpawnHeightOffset: -1

SpawnHeightVariance: 0

##############################
# Height Limits for the BO3. #
##############################

MinHeight: 0

MaxHeight: 255

######################
# Extrusion settings #
######################

ExtrudeMode: None

ExtrudeThroughBlocks: AIR

MaxBranchDepth: 10

ExcludedBiomes: All


#######################################################################
# +-----------------------------------------------------------------+ #
# |                      Source block settings                      | #
# +-----------------------------------------------------------------+ #
#######################################################################

SourceBlocks: AIR,GRASS,DIRT,biomesoplenty:dirt

MaxPercentageOutsideSourceBlock: 0

OutsideSourceBlock: placeAnyway

DoReplaceBlocks: true

IsOTGPlus: false


#######################################################################
# +-----------------------------------------------------------------+ #
# |                              Blocks                             | #
# +-----------------------------------------------------------------+ #
#######################################################################

Block(-4,7,-2,rustic:leaves0:0)
Block(-4,7,-1,rustic:leaves0:0)
Block(-4,7,0,rustic:leaves0:0)
Block(-4,7,1,rustic:leaves0:0)
Block(-4,7,2,rustic:leaves0:0)
Block(-4,7,3,rustic:leaves0:0)
Block(-4,7,4,rustic:leaves0:0)
Block(-4,8,-2,rustic:leaves0:0)
Block(-4,8,-1,rustic:leaves0:0)
Block(-4,8,0,rustic:leaves0:0)
Block(-4,8,2,rustic:leaves0:0)
Block(-4,8,3,rustic:leaves0:0)
Block(-4,8,4,rustic:leaves0:0)
Block(-4,9,-1,rustic:leaves0:0)
Block(-4,9,3,rustic:leaves0:0)
Block(-3,6,-2,rustic:leaves0:0)
Block(-3,6,-1,rustic:leaves0:0)
Block(-3,6,0,rustic:leaves0:0)
Block(-3,6,1,rustic:leaves0:0)
Block(-3,6,2,rustic:leaves0:0)
Block(-3,6,4,rustic:leaves0:0)
Block(-3,7,-3,rustic:leaves0:0)
Block(-3,7,-2,rustic:leaves0:2)
Block(-3,7,-1,rustic:leaves0)
Block(-3,7,0,rustic:leaves0:2)
Block(-3,7,1,rustic:leaves0:1)
Block(-3,7,2,rustic:leaves0:2)
Block(-3,7,3,rustic:leaves0)
Block(-3,7,4,rustic:leaves0:2)
Block(-3,7,5,rustic:leaves0:0)
Block(-3,8,-3,rustic:leaves0:0)
Block(-3,8,-2,rustic:leaves0:1)
Block(-3,8,-1,rustic:leaves0:2)
Block(-3,8,0,rustic:leaves0:1)
Block(-3,8,1,rustic:leaves0:0)
Block(-3,8,2,rustic:leaves0:1)
Block(-3,8,3,rustic:leaves0:2)
Block(-3,8,4,rustic:leaves0:1)
Block(-3,8,5,rustic:leaves0:0)
Block(-3,9,-2,rustic:leaves0:0)
Block(-3,9,-1,rustic:leaves0:1)
Block(-3,9,0,rustic:leaves0:0)
Block(-3,9,2,rustic:leaves0:0)
Block(-3,9,3,rustic:leaves0:1)
Block(-3,9,4,rustic:leaves0:0)
Block(-3,10,-1,rustic:leaves0:0)
Block(-3,10,3,rustic:leaves0:0)
Block(-2,7,-3,rustic:leaves0:0)
Block(-2,7,-2,rustic:leaves0)
Block(-2,7,-1,rustic:olivebranch)
Block(-2,7,0,rustic:leaves0)
Block(-2,7,1,rustic:leaves0:2)
Block(-2,7,2,rustic:leaves0)
Block(-2,7,3,rustic:olivebranch)
Block(-2,7,4,rustic:leaves0)
Block(-2,7,5,rustic:leaves0:0)
Block(-2,8,-3,rustic:leaves0:0)
Block(-2,8,-2,rustic:leaves0:2)
Block(-2,8,-1,rustic:leaves0)
Block(-2,8,0,rustic:leaves0:2)
Block(-2,8,1,rustic:leaves0:1)
Block(-2,8,2,rustic:leaves0:2)
Block(-2,8,3,rustic:leaves0)
Block(-2,8,4,rustic:leaves0:2)
Block(-2,8,5,rustic:leaves0:0)
Block(-2,9,-3,rustic:leaves0:0)
Block(-2,9,-2,rustic:leaves0:1)
Block(-2,9,-1,rustic:leaves0:2)
Block(-2,9,0,rustic:leaves0:1)
Block(-2,9,1,rustic:leaves0:0)
Block(-2,9,2,rustic:leaves0:1)
Block(-2,9,3,rustic:leaves0:2)
Block(-2,9,4,rustic:leaves0:1)
Block(-2,9,5,rustic:leaves0:0)
Block(-2,10,-2,rustic:leaves0:0)
Block(-2,10,-1,rustic:leaves0:1)
Block(-2,10,0,rustic:leaves0:0)
Block(-2,10,1,rustic:leaves0:0)
Block(-2,10,2,rustic:leaves0:0)
Block(-2,10,3,rustic:leaves0:0)
Block(-2,10,4,rustic:leaves0:0)
Block(-2,11,-1,rustic:leaves0:0)
Block(-1,7,-1,rustic:olivebranch:1)
Block(-1,7,3,rustic:olivebranch:1)
Block(-1,7,4,rustic:leaves0:2)
Block(-1,7,5,rustic:leaves0:0)
Block(-1,8,-3,rustic:leaves0:0)
Block(-1,8,-2,rustic:leaves0:1)
Block(-1,8,-1,rustic:leaves0:2)
Block(-1,8,0,rustic:leaves0:1)
Block(-1,8,1,rustic:leaves0:2)
Block(-1,8,2,rustic:leaves0)
Block(-1,8,3,rustic:olivebranch)
Block(-1,8,4,rustic:leaves0)
Block(-1,8,5,rustic:leaves0:0)
Block(-1,9,-3,rustic:leaves0:0)
Block(-1,9,-2,rustic:leaves0:2)
Block(-1,9,-1,rustic:leaves0)
Block(-1,9,0,rustic:leaves0:2)
Block(-1,9,1,rustic:leaves0)
Block(-1,9,2,rustic:leaves0:2)
Block(-1,9,3,rustic:leaves0)
Block(-1,9,4,rustic:leaves0:2)
Block(-1,9,5,rustic:leaves0:0)
Block(-1,10,-3,rustic:leaves0:0)
Block(-1,10,-2,rustic:leaves0:1)
Block(-1,10,-1,rustic:leaves0:2)
Block(-1,10,0,rustic:leaves0:1)
Block(-1,10,1,rustic:leaves0:2)
Block(-1,10,2,rustic:leaves0:1)
Block(-1,10,3,rustic:leaves0:0)
Block(-1,10,4,rustic:leaves0:0)
Block(-1,11,-2,rustic:leaves0:0)
Block(-1,11,-1,rustic:leaves0:0)
Block(-1,11,0,rustic:leaves0:0)
Block(-1,11,1,rustic:leaves0:0)
Block(-1,11,2,rustic:leaves0:0)
Block(0,0,1,dynamictrees:rootydirt:0)
Block(0,1,1,rustic:olivebranch:7)
Block(0,2,1,rustic:olivebranch:7)
Block(0,3,-1,rustic:olivebranch:4)
Block(0,3,0,rustic:olivebranch:4)
Block(0,3,1,rustic:olivebranch:7)
Block(0,4,-1,rustic:olivebranch:3)
Block(0,4,1,rustic:olivebranch:5)
Block(0,4,2,rustic:olivebranch:3)
Block(0,4,3,rustic:olivebranch:3)
Block(0,5,-1,rustic:olivebranch:3)
Block(0,5,3,rustic:olivebranch:2)
Block(0,6,-1,rustic:olivebranch:2)
Block(0,6,1,rustic:olivebranch:2)
Block(0,6,3,rustic:olivebranch:2)
Block(0,7,-1,rustic:olivebranch:2)
Block(0,7,1,rustic:olivebranch:1)
Block(0,7,3,rustic:olivebranch:1)
Block(0,7,4,rustic:leaves0:1)
Block(0,7,5,rustic:leaves0:0)
Block(0,8,-3,rustic:leaves0:0)
Block(0,8,-2,rustic:leaves0:2)
Block(0,8,-1,rustic:olivebranch:1)
Block(0,8,0,rustic:leaves0:2)
Block(0,8,1,rustic:olivebranch:1)
Block(0,8,2,rustic:olivebranch)
Block(0,8,3,rustic:leaves0)
Block(0,8,4,rustic:leaves0:2)
Block(0,8,5,rustic:leaves0:0)
Block(0,9,-3,rustic:leaves0:0)
Block(0,9,-2,rustic:leaves0)
Block(0,9,-1,rustic:olivebranch)
Block(0,9,0,rustic:leaves0)
Block(0,9,1,rustic:olivebranch)
Block(0,9,2,rustic:leaves0)
Block(0,9,3,rustic:leaves0:2)
Block(0,9,4,rustic:leaves0:1)
Block(0,9,5,rustic:leaves0:0)
Block(0,10,-3,rustic:leaves0:0)
Block(0,10,-2,rustic:leaves0:2)
Block(0,10,-1,rustic:leaves0)
Block(0,10,0,rustic:leaves0:2)
Block(0,10,1,rustic:leaves0)
Block(0,10,2,rustic:leaves0:2)
Block(0,10,3,rustic:leaves0:1)
Block(0,10,4,rustic:leaves0:0)
Block(0,11,-2,rustic:leaves0:0)
Block(0,11,-1,rustic:leaves0:0)
Block(0,11,0,rustic:leaves0:0)
Block(0,11,1,rustic:leaves0:0)
Block(0,11,2,rustic:leaves0:0)
Block(0,11,3,rustic:leaves0:0)
Block(1,4,1,rustic:olivebranch:3)
Block(1,5,1,rustic:olivebranch:2)
Block(1,6,1,rustic:olivebranch:2)
Block(1,6,4,rustic:leaves0:0)
Block(1,7,3,rustic:olivebranch)
Block(1,7,4,rustic:leaves0)
Block(1,7,5,rustic:leaves0:0)
Block(1,8,-3,rustic:leaves0:0)
Block(1,8,-2,rustic:leaves0)
Block(1,8,-1,rustic:olivebranch)
Block(1,8,0,rustic:leaves0)
Block(1,8,1,rustic:olivebranch)
Block(1,8,2,rustic:leaves0)
Block(1,8,3,rustic:leaves0)
Block(1,8,4,rustic:leaves0:2)
Block(1,8,5,rustic:leaves0:0)
Block(1,9,-3,rustic:leaves0:0)
Block(1,9,-2,rustic:leaves0:2)
Block(1,9,-1,rustic:leaves0)
Block(1,9,0,rustic:leaves0:2)
Block(1,9,1,rustic:leaves0)
Block(1,9,2,rustic:leaves0:2)
Block(1,9,3,rustic:leaves0:1)
Block(1,9,4,rustic:leaves0:0)
Block(1,10,-3,rustic:leaves0:0)
Block(1,10,-2,rustic:leaves0:1)
Block(1,10,-1,rustic:leaves0:2)
Block(1,10,0,rustic:leaves0:1)
Block(1,10,1,rustic:leaves0:2)
Block(1,10,2,rustic:leaves0:1)
Block(1,10,3,rustic:leaves0:0)
Block(1,11,-2,rustic:leaves0:0)
Block(1,11,-1,rustic:leaves0:0)
Block(1,11,0,rustic:leaves0:0)
Block(1,11,1,rustic:leaves0:0)
Block(1,11,2,rustic:leaves0:0)
Block(2,6,3,rustic:leaves0:0)
Block(2,6,4,rustic:leaves0:0)
Block(2,7,-2,rustic:leaves0:0)
Block(2,7,-1,rustic:leaves0:0)
Block(2,7,0,rustic:leaves0:0)
Block(2,7,2,rustic:leaves0:0)
Block(2,7,3,rustic:leaves0)
Block(2,7,4,rustic:leaves0:2)
Block(2,7,5,rustic:leaves0:0)
Block(2,8,-3,rustic:leaves0:0)
Block(2,8,-2,rustic:leaves0:2)
Block(2,8,-1,rustic:leaves0)
Block(2,8,0,rustic:leaves0:2)
Block(2,8,1,rustic:leaves0)
Block(2,8,2,rustic:leaves0:2)
Block(2,8,3,rustic:leaves0:2)
Block(2,8,4,rustic:leaves0:1)
Block(2,8,5,rustic:leaves0:0)
Block(2,9,-3,rustic:leaves0:0)
Block(2,9,-2,rustic:leaves0:1)
Block(2,9,-1,rustic:leaves0:2)
Block(2,9,0,rustic:leaves0:1)
Block(2,9,1,rustic:leaves0:2)
Block(2,9,2,rustic:leaves0:1)
Block(2,9,3,rustic:leaves0:0)
Block(2,9,4,rustic:leaves0:0)
Block(2,10,-2,rustic:leaves0:0)
Block(2,10,-1,rustic:leaves0:1)
Block(2,10,0,rustic:leaves0:0)
Block(2,10,1,rustic:leaves0:1)
Block(2,10,2,rustic:leaves0:0)
Block(2,11,-1,rustic:leaves0:0)
Block(2,11,1,rustic:leaves0:0)
Block(3,7,3,rustic:leaves0:0)
Block(3,7,4,rustic:leaves0:0)
Block(3,8,-2,rustic:leaves0:0)
Block(3,8,-1,rustic:leaves0:0)
Block(3,8,0,rustic:leaves0:0)
Block(3,8,1,rustic:leaves0:0)
Block(3,8,2,rustic:leaves0:0)
Block(3,8,3,rustic:leaves0:0)
Block(3,8,4,rustic:leaves0:0)
Block(3,9,-2,rustic:leaves0:0)
Block(3,9,-1,rustic:leaves0:0)
Block(3,9,0,rustic:leaves0:0)
Block(3,9,1,rustic:leaves0:0)
Block(3,9,2,rustic:leaves0:0)
Block(3,10,-1,rustic:leaves0:0)
Block(3,10,1,rustic:leaves0:0)

#######################################################################
# +-----------------------------------------------------------------+ #
# |                            BO3 checks                           | #
# +-----------------------------------------------------------------+ #
#######################################################################

BlockCheck(0,-1,1,GRASS,DIRT,biomesoplenty:grass,biomesoplenty:dirt)

#######################################################################
# +-----------------------------------------------------------------+ #
# |                             Branches                            | #
# +-----------------------------------------------------------------+ #
#######################################################################


#######################################################################
# +-----------------------------------------------------------------+ #
# |                             Entities                            | #
# +-----------------------------------------------------------------+ #
#######################################################################


#######################################################################
# +-----------------------------------------------------------------+ #
# |                            Particles                            | #
# +-----------------------------------------------------------------+ #
#######################################################################


#######################################################################
# +-----------------------------------------------------------------+ #
# |                             Spawners                            | #
# +-----------------------------------------------------------------+ #
#######################################################################


#######################################################################
# +-----------------------------------------------------------------+ #
# |                             ModData                             | #
# +-----------------------------------------------------------------+ #
#######################################################################

