
#######################################################################
# +-----------------------------------------------------------------+ #
# |                            BO3 object                           | #
# +-----------------------------------------------------------------+ #
#######################################################################

Author: NLBlackHeavenNL

Description: No description given

Version: 3

SettingsMode: WriteWithoutComments


#######################################################################
# +-----------------------------------------------------------------+ #
# |                          Main settings                          | #
# +-----------------------------------------------------------------+ #
#######################################################################

Tree: true

Frequency: 1

Rarity: 100.0

RotateRandomly: false

SpawnHeight: highestSolidBlock

SpawnHeightOffset: -1

SpawnHeightVariance: 0

##############################
# Height Limits for the BO3. #
##############################

MinHeight: 0

MaxHeight: 255

######################
# Extrusion settings #
######################

ExtrudeMode: None

ExtrudeThroughBlocks: AIR

MaxBranchDepth: 10

ExcludedBiomes: All


#######################################################################
# +-----------------------------------------------------------------+ #
# |                      Source block settings                      | #
# +-----------------------------------------------------------------+ #
#######################################################################

SourceBlocks: AIR,GRASS,DIRT,biomesoplenty:dirt

MaxPercentageOutsideSourceBlock: 0

OutsideSourceBlock: placeAnyway

DoReplaceBlocks: true

IsOTGPlus: false


#######################################################################
# +-----------------------------------------------------------------+ #
# |                              Blocks                             | #
# +-----------------------------------------------------------------+ #
#######################################################################

Block(-7,5,0,rustic:leaves0:0)
Block(-7,5,1,rustic:leaves0:0)
Block(-7,5,2,rustic:leaves0:0)
Block(-7,6,-1,rustic:leaves0:0)
Block(-7,6,0,rustic:leaves0:0)
Block(-7,6,1,rustic:leaves0:0)
Block(-7,6,2,rustic:leaves0:0)
Block(-7,7,0,rustic:leaves0:0)
Block(-7,7,1,rustic:leaves0:0)
Block(-7,7,2,rustic:leaves0:0)
Block(-6,5,-1,rustic:leaves0:0)
Block(-6,5,0,rustic:leaves0:1)
Block(-6,5,1,rustic:leaves0:0)
Block(-6,5,2,rustic:leaves0:0)
Block(-6,5,3,rustic:leaves0:0)
Block(-6,6,-2,rustic:leaves0:0)
Block(-6,6,-1,rustic:leaves0:1)
Block(-6,6,0,rustic:leaves0:2)
Block(-6,6,1,rustic:leaves0)
Block(-6,6,2,rustic:leaves0:2)
Block(-6,6,3,rustic:leaves0:0)
Block(-6,7,-1,rustic:leaves0:0)
Block(-6,7,0,rustic:leaves0:1)
Block(-6,7,1,rustic:leaves0:2)
Block(-6,7,2,rustic:leaves0:1)
Block(-6,7,3,rustic:leaves0:0)
Block(-6,8,0,rustic:leaves0:0)
Block(-6,8,1,rustic:leaves0:0)
Block(-6,8,2,rustic:leaves0:0)
Block(-5,5,-2,rustic:leaves0:0)
Block(-5,5,-1,rustic:leaves0:0)
Block(-5,5,0,rustic:leaves0:0)
Block(-5,5,2,rustic:leaves0:0)
Block(-5,5,3,rustic:leaves0:0)
Block(-5,6,-3,rustic:leaves0:0)
Block(-5,6,-2,rustic:leaves0:1)
Block(-5,6,-1,rustic:leaves0:2)
Block(-5,6,0,rustic:leaves0)
Block(-5,6,1,rustic:olivebranch)
Block(-5,6,2,rustic:leaves0)
Block(-5,6,3,rustic:leaves0:0)
Block(-5,7,-2,rustic:leaves0:0)
Block(-5,7,-1,rustic:leaves0:1)
Block(-5,7,0,rustic:leaves0:2)
Block(-5,7,1,rustic:leaves0)
Block(-5,7,2,rustic:leaves0:2)
Block(-5,7,3,rustic:leaves0:0)
Block(-5,8,-1,rustic:leaves0:0)
Block(-5,8,0,rustic:leaves0:0)
Block(-5,8,1,rustic:leaves0:0)
Block(-5,8,2,rustic:leaves0:0)
Block(-5,9,1,rustic:leaves0:0)
Block(-4,5,-2,rustic:leaves0:0)
Block(-4,5,-1,rustic:leaves0:0)
Block(-4,5,3,rustic:leaves0:0)
Block(-4,5,5,rustic:leaves0:0)
Block(-4,5,6,rustic:leaves0:0)
Block(-4,5,7,rustic:leaves0:0)
Block(-4,6,-3,rustic:leaves0:0)
Block(-4,6,-2,rustic:leaves0:2)
Block(-4,6,-1,rustic:leaves0)
Block(-4,6,0,rustic:leaves0:2)
Block(-4,6,1,rustic:olivebranch:1)
Block(-4,6,2,rustic:leaves0)
Block(-4,6,3,rustic:leaves0:2)
Block(-4,6,4,rustic:leaves0:0)
Block(-4,6,5,rustic:leaves0:0)
Block(-4,6,6,rustic:leaves0:0)
Block(-4,7,-3,rustic:leaves0:0)
Block(-4,7,-2,rustic:leaves0:1)
Block(-4,7,-1,rustic:leaves0:2)
Block(-4,7,0,rustic:leaves0:1)
Block(-4,7,1,rustic:leaves0)
Block(-4,7,2,rustic:leaves0:2)
Block(-4,7,3,rustic:leaves0:1)
Block(-4,7,4,rustic:leaves0:0)
Block(-4,8,-2,rustic:leaves0:0)
Block(-4,8,-1,rustic:leaves0:1)
Block(-4,8,0,rustic:leaves0:0)
Block(-4,8,1,rustic:leaves0:2)
Block(-4,8,2,rustic:leaves0:1)
Block(-4,8,3,rustic:leaves0:0)
Block(-4,9,-1,rustic:leaves0:0)
Block(-4,9,0,rustic:leaves0:0)
Block(-4,9,1,rustic:leaves0:1)
Block(-4,9,2,rustic:leaves0:0)
Block(-4,10,1,rustic:leaves0:0)
Block(-3,4,5,rustic:leaves0:0)
Block(-3,4,6,rustic:leaves0:0)
Block(-3,4,7,rustic:leaves0:0)
Block(-3,5,5,rustic:leaves0)
Block(-3,5,6,rustic:leaves0:2)
Block(-3,5,7,rustic:leaves0:1)
Block(-3,5,8,rustic:leaves0:0)
Block(-3,6,-3,rustic:leaves0:0)
Block(-3,6,-2,rustic:leaves0)
Block(-3,6,-1,rustic:olivebranch)
Block(-3,6,0,rustic:olivebranch:1)
Block(-3,6,1,rustic:olivebranch:2)
Block(-3,6,2,rustic:olivebranch)
Block(-3,6,4,rustic:leaves0:0)
Block(-3,6,5,rustic:leaves0:2)
Block(-3,6,6,rustic:leaves0:1)
Block(-3,6,7,rustic:leaves0:0)
Block(-3,7,-3,rustic:leaves0:0)
Block(-3,7,-2,rustic:leaves0:2)
Block(-3,7,-1,rustic:leaves0)
Block(-3,7,1,rustic:olivebranch)
Block(-3,7,2,rustic:leaves0)
Block(-3,7,3,rustic:leaves0:0)
Block(-3,7,5,rustic:leaves0:0)
Block(-3,7,6,rustic:leaves0:0)
Block(-3,8,-3,rustic:leaves0:0)
Block(-3,8,-2,rustic:leaves0:1)
Block(-3,8,-1,rustic:leaves0:2)
Block(-3,8,0,rustic:leaves0:0)
Block(-3,8,1,rustic:leaves0)
Block(-3,8,2,rustic:leaves0:2)
Block(-3,8,3,rustic:leaves0:0)
Block(-3,8,4,rustic:leaves0:0)
Block(-3,9,-2,rustic:leaves0:0)
Block(-3,9,-1,rustic:leaves0:1)
Block(-3,9,0,rustic:leaves0:0)
Block(-3,9,1,rustic:leaves0:2)
Block(-3,9,2,rustic:leaves0:1)
Block(-3,9,3,rustic:leaves0:0)
Block(-3,9,4,rustic:leaves0:0)
Block(-3,10,-1,rustic:leaves0:0)
Block(-3,10,0,rustic:leaves0:0)
Block(-3,10,1,rustic:leaves0:0)
Block(-3,10,2,rustic:leaves0:0)
Block(-3,10,3,rustic:leaves0:0)
Block(-3,11,0,rustic:leaves0:0)
Block(-3,11,1,rustic:leaves0:0)
Block(-3,11,2,rustic:leaves0:0)
Block(-3,12,1,rustic:leaves0:0)
Block(-2,4,6,rustic:leaves0:0)
Block(-2,4,7,rustic:leaves0:0)
Block(-2,5,5,rustic:olivebranch)
Block(-2,5,6,rustic:leaves0)
Block(-2,5,7,rustic:leaves0:2)
Block(-2,5,8,rustic:leaves0:0)
Block(-2,6,1,rustic:olivebranch:3)
Block(-2,6,5,rustic:leaves0)
Block(-2,6,6,rustic:leaves0:2)
Block(-2,6,7,rustic:leaves0:1)
Block(-2,6,8,rustic:leaves0:0)
Block(-2,7,-4,rustic:leaves0:0)
Block(-2,7,-3,rustic:leaves0:0)
Block(-2,7,-2,rustic:leaves0:1)
Block(-2,7,4,rustic:leaves0:0)
Block(-2,7,5,rustic:leaves0:0)
Block(-2,7,6,rustic:leaves0:1)
Block(-2,7,7,rustic:leaves0:0)
Block(-2,8,-4,rustic:leaves0:0)
Block(-2,8,-3,rustic:leaves0:1)
Block(-2,8,-2,rustic:leaves0:2)
Block(-2,8,-1,rustic:leaves0)
Block(-2,8,1,rustic:olivebranch)
Block(-2,8,3,rustic:leaves0)
Block(-2,8,4,rustic:leaves0:2)
Block(-2,8,5,rustic:leaves0:0)
Block(-2,8,6,rustic:leaves0:0)
Block(-2,9,-3,rustic:leaves0:0)
Block(-2,9,-2,rustic:leaves0:1)
Block(-2,9,-1,rustic:leaves0:2)
Block(-2,9,0,rustic:leaves0:1)
Block(-2,9,2,rustic:leaves0:1)
Block(-2,9,3,rustic:leaves0:2)
Block(-2,9,4,rustic:leaves0:1)
Block(-2,9,5,rustic:leaves0:0)
Block(-2,10,-2,rustic:leaves0:0)
Block(-2,10,-1,rustic:leaves0:1)
Block(-2,10,0,rustic:leaves0:2)
Block(-2,10,1,rustic:leaves0)
Block(-2,10,2,rustic:leaves0:2)
Block(-2,10,3,rustic:leaves0:1)
Block(-2,10,4,rustic:leaves0:0)
Block(-2,11,-1,rustic:leaves0:0)
Block(-2,11,0,rustic:leaves0:1)
Block(-2,11,1,rustic:leaves0:2)
Block(-2,11,2,rustic:leaves0:1)
Block(-2,11,3,rustic:leaves0:0)
Block(-2,12,0,rustic:leaves0:0)
Block(-2,12,1,rustic:leaves0:1)
Block(-2,12,2,rustic:leaves0:0)
Block(-2,13,1,rustic:leaves0:0)
Block(-1,5,4,rustic:olivebranch:1)
Block(-1,5,5,rustic:olivebranch:1)
Block(-1,5,6,rustic:olivebranch)
Block(-1,5,7,rustic:leaves0)
Block(-1,5,8,rustic:leaves0:0)
Block(-1,6,-4,rustic:leaves0:0)
Block(-1,6,1,rustic:olivebranch:3)
Block(-1,6,6,rustic:leaves0)
Block(-1,6,7,rustic:leaves0:2)
Block(-1,6,8,rustic:leaves0:0)
Block(-1,7,-5,rustic:leaves0:0)
Block(-1,7,-4,rustic:leaves0:2)
Block(-1,7,-3,rustic:leaves0)
Block(-1,7,-1,rustic:olivebranch:1)
Block(-1,7,5,rustic:leaves0:1)
Block(-1,7,6,rustic:leaves0:2)
Block(-1,7,7,rustic:leaves0:1)
Block(-1,7,8,rustic:leaves0:0)
Block(-1,8,-5,rustic:leaves0:0)
Block(-1,8,-4,rustic:leaves0:1)
Block(-1,8,-3,rustic:leaves0:2)
Block(-1,8,-2,rustic:leaves0)
Block(-1,8,-1,rustic:olivebranch)
Block(-1,8,1,rustic:olivebranch:1)
Block(-1,8,2,rustic:olivebranch:1)
Block(-1,8,3,rustic:olivebranch)
Block(-1,8,4,rustic:leaves0)
Block(-1,8,5,rustic:leaves0:0)
Block(-1,8,6,rustic:leaves0:0)
Block(-1,8,7,rustic:leaves0:0)
Block(-1,9,-4,rustic:leaves0:0)
Block(-1,9,-3,rustic:leaves0:1)
Block(-1,9,-2,rustic:leaves0:2)
Block(-1,9,-1,rustic:leaves0)
Block(-1,9,3,rustic:leaves0)
Block(-1,9,4,rustic:leaves0:2)
Block(-1,9,5,rustic:leaves0:0)
Block(-1,10,-3,rustic:leaves0:0)
Block(-1,10,-2,rustic:leaves0:1)
Block(-1,10,-1,rustic:leaves0:2)
Block(-1,10,0,rustic:leaves0)
Block(-1,10,1,rustic:olivebranch)
Block(-1,10,2,rustic:leaves0)
Block(-1,10,3,rustic:leaves0:2)
Block(-1,10,4,rustic:leaves0:1)
Block(-1,10,5,rustic:leaves0:0)
Block(-1,11,-2,rustic:leaves0:0)
Block(-1,11,-1,rustic:leaves0:1)
Block(-1,11,0,rustic:leaves0:2)
Block(-1,11,1,rustic:leaves0)
Block(-1,11,2,rustic:leaves0:2)
Block(-1,11,3,rustic:leaves0:1)
Block(-1,11,4,rustic:leaves0:0)
Block(-1,12,-1,rustic:leaves0:0)
Block(-1,12,0,rustic:leaves0:1)
Block(-1,12,1,rustic:leaves0:2)
Block(-1,12,2,rustic:leaves0:1)
Block(-1,12,3,rustic:leaves0:0)
Block(-1,13,0,rustic:leaves0:0)
Block(-1,13,1,rustic:leaves0:0)
Block(-1,13,2,rustic:leaves0:0)
Block(0,0,1,dynamictrees:rootydirt:0)
Block(0,1,1,rustic:olivebranch:7)
Block(0,2,1,rustic:olivebranch:7)
Block(0,3,-1,rustic:olivebranch:5)
Block(0,3,0,rustic:olivebranch:5)
Block(0,3,1,rustic:olivebranch:7)
Block(0,4,1,rustic:olivebranch:7)
Block(0,5,1,rustic:olivebranch:7)
Block(0,5,2,rustic:olivebranch:5)
Block(0,5,3,rustic:olivebranch:3)
Block(0,5,4,rustic:olivebranch:2)
Block(0,5,6,rustic:leaves0)
Block(0,5,7,rustic:leaves0:2)
Block(0,5,8,rustic:leaves0:0)
Block(0,6,-4,rustic:leaves0:0)
Block(0,6,1,rustic:olivebranch:6)
Block(0,6,4,rustic:olivebranch:1)
Block(0,6,5,rustic:olivebranch:1)
Block(0,6,6,rustic:olivebranch)
Block(0,6,7,rustic:leaves0)
Block(0,6,8,rustic:leaves0:0)
Block(0,7,-5,rustic:leaves0:0)
Block(0,7,-4,rustic:leaves0)
Block(0,7,-3,rustic:olivebranch)
Block(0,7,-2,rustic:olivebranch:1)
Block(0,7,-1,rustic:olivebranch:2)
Block(0,7,0,rustic:olivebranch:3)
Block(0,7,1,rustic:olivebranch:5)
Block(0,7,6,rustic:leaves0)
Block(0,7,7,rustic:leaves0:2)
Block(0,7,8,rustic:leaves0:0)
Block(0,8,-5,rustic:leaves0:0)
Block(0,8,-4,rustic:leaves0:2)
Block(0,8,-3,rustic:leaves0)
Block(0,8,-2,rustic:olivebranch)
Block(0,8,1,rustic:olivebranch:3)
Block(0,8,6,rustic:leaves0:0)
Block(0,8,7,rustic:leaves0:0)
Block(0,9,-5,rustic:leaves0:0)
Block(0,9,-4,rustic:leaves0:1)
Block(0,9,-3,rustic:leaves0:2)
Block(0,9,-2,rustic:leaves0)
Block(0,9,-1,rustic:olivebranch)
Block(0,9,0,rustic:olivebranch:1)
Block(0,9,1,rustic:olivebranch:2)
Block(0,9,2,rustic:olivebranch:1)
Block(0,9,3,rustic:olivebranch)
Block(0,9,4,rustic:leaves0)
Block(0,9,5,rustic:leaves0:0)
Block(0,10,-4,rustic:leaves0:0)
Block(0,10,-3,rustic:leaves0:1)
Block(0,10,-2,rustic:leaves0:2)
Block(0,10,-1,rustic:leaves0)
Block(0,10,0,rustic:leaves0:2)
Block(0,10,1,rustic:olivebranch:1)
Block(0,10,2,rustic:leaves0:2)
Block(0,10,3,rustic:leaves0)
Block(0,10,4,rustic:leaves0:2)
Block(0,10,5,rustic:leaves0:0)
Block(0,11,-3,rustic:leaves0:0)
Block(0,11,-2,rustic:leaves0:1)
Block(0,11,-1,rustic:leaves0:2)
Block(0,11,0,rustic:leaves0)
Block(0,11,1,rustic:olivebranch)
Block(0,11,2,rustic:leaves0)
Block(0,11,3,rustic:leaves0:2)
Block(0,11,4,rustic:leaves0:1)
Block(0,11,5,rustic:leaves0:0)
Block(0,12,-2,rustic:leaves0:0)
Block(0,12,-1,rustic:leaves0:1)
Block(0,12,0,rustic:leaves0:2)
Block(0,12,1,rustic:leaves0)
Block(0,12,2,rustic:leaves0:2)
Block(0,12,3,rustic:leaves0:1)
Block(0,12,4,rustic:leaves0:0)
Block(0,13,-1,rustic:leaves0:0)
Block(0,13,0,rustic:leaves0:0)
Block(0,13,1,rustic:leaves0:0)
Block(0,13,2,rustic:leaves0:0)
Block(0,13,3,rustic:leaves0:0)
Block(1,3,-1,rustic:olivebranch:4)
Block(1,5,2,rustic:olivebranch:3)
Block(1,5,6,rustic:leaves0:2)
Block(1,5,7,rustic:leaves0:1)
Block(1,5,8,rustic:leaves0:0)
Block(1,6,-5,rustic:leaves0:0)
Block(1,6,-4,rustic:leaves0:1)
Block(1,6,5,rustic:olivebranch)
Block(1,6,6,rustic:leaves0)
Block(1,6,7,rustic:leaves0:2)
Block(1,6,8,rustic:leaves0:0)
Block(1,7,-5,rustic:leaves0:0)
Block(1,7,-4,rustic:leaves0:2)
Block(1,7,-3,rustic:leaves0)
Block(1,7,0,rustic:olivebranch:1)
Block(1,7,5,rustic:leaves0)
Block(1,7,6,rustic:leaves0:2)
Block(1,7,7,rustic:leaves0:1)
Block(1,7,8,rustic:leaves0:0)
Block(1,8,-5,rustic:leaves0:0)
Block(1,8,-4,rustic:leaves0:1)
Block(1,8,-3,rustic:leaves0:2)
Block(1,8,-2,rustic:leaves0)
Block(1,8,1,rustic:olivebranch)
Block(1,8,4,rustic:leaves0:0)
Block(1,8,5,rustic:leaves0:0)
Block(1,8,6,rustic:leaves0:0)
Block(1,8,7,rustic:leaves0:0)
Block(1,9,-4,rustic:leaves0:0)
Block(1,9,-3,rustic:leaves0:1)
Block(1,9,-2,rustic:leaves0:2)
Block(1,9,-1,rustic:leaves0)
Block(1,9,1,rustic:leaves0)
Block(1,9,3,rustic:leaves0)
Block(1,9,4,rustic:leaves0:2)
Block(1,9,5,rustic:leaves0:0)
Block(1,10,-3,rustic:leaves0:0)
Block(1,10,-2,rustic:leaves0:1)
Block(1,10,-1,rustic:leaves0:2)
Block(1,10,0,rustic:leaves0)
Block(1,10,1,rustic:olivebranch)
Block(1,10,2,rustic:leaves0)
Block(1,10,3,rustic:leaves0:2)
Block(1,10,4,rustic:leaves0:1)
Block(1,10,5,rustic:leaves0:0)
Block(1,11,-2,rustic:leaves0:0)
Block(1,11,-1,rustic:leaves0:1)
Block(1,11,0,rustic:leaves0:2)
Block(1,11,1,rustic:leaves0)
Block(1,11,2,rustic:leaves0:2)
Block(1,11,3,rustic:leaves0:1)
Block(1,11,4,rustic:leaves0:0)
Block(1,12,-1,rustic:leaves0:0)
Block(1,12,0,rustic:leaves0:1)
Block(1,12,1,rustic:leaves0:2)
Block(1,12,2,rustic:leaves0:1)
Block(1,12,3,rustic:leaves0:0)
Block(1,13,0,rustic:leaves0:0)
Block(1,13,1,rustic:leaves0:0)
Block(1,13,2,rustic:leaves0:0)
Block(2,3,-2,rustic:olivebranch)
Block(2,3,-1,rustic:olivebranch:4)
Block(2,4,-2,rustic:leaves0)
Block(2,4,-1,rustic:olivebranch:2)
Block(2,5,-5,rustic:leaves0:0)
Block(2,5,-4,rustic:leaves0)
Block(2,5,-3,rustic:olivebranch)
Block(2,5,-2,rustic:olivebranch:1)
Block(2,5,-1,rustic:olivebranch:1)
Block(2,5,2,rustic:olivebranch:3)
Block(2,5,3,rustic:olivebranch:1)
Block(2,5,5,rustic:leaves0:0)
Block(2,5,6,rustic:leaves0:1)
Block(2,5,7,rustic:leaves0:0)
Block(2,6,-5,rustic:leaves0:0)
Block(2,6,-4,rustic:leaves0:2)
Block(2,6,-3,rustic:leaves0)
Block(2,6,-1,rustic:olivebranch)
Block(2,6,3,rustic:olivebranch:1)
Block(2,6,4,rustic:olivebranch)
Block(2,6,5,rustic:leaves0)
Block(2,6,6,rustic:leaves0:2)
Block(2,6,7,rustic:leaves0:1)
Block(2,6,8,rustic:leaves0:0)
Block(2,7,-5,rustic:leaves0:0)
Block(2,7,-4,rustic:leaves0:1)
Block(2,7,-3,rustic:leaves0:2)
Block(2,7,-2,rustic:leaves0:0)
Block(2,7,-1,rustic:leaves0)
Block(2,7,0,rustic:olivebranch:1)
Block(2,7,4,rustic:leaves0)
Block(2,7,5,rustic:leaves0:2)
Block(2,7,6,rustic:leaves0:1)
Block(2,7,7,rustic:leaves0:0)
Block(2,8,-4,rustic:leaves0:0)
Block(2,8,-3,rustic:leaves0:1)
Block(2,8,-2,rustic:leaves0:0)
Block(2,8,-1,rustic:leaves0:0)
Block(2,8,3,rustic:leaves0:0)
Block(2,8,4,rustic:leaves0:0)
Block(2,8,5,rustic:leaves0:0)
Block(2,8,6,rustic:leaves0:0)
Block(2,9,-3,rustic:leaves0:0)
Block(2,9,-2,rustic:leaves0:0)
Block(2,9,-1,rustic:leaves0:0)
Block(2,9,0,rustic:leaves0:1)
Block(2,9,2,rustic:leaves0:1)
Block(2,9,3,rustic:leaves0:0)
Block(2,9,4,rustic:leaves0:0)
Block(2,10,-2,rustic:leaves0:0)
Block(2,10,-1,rustic:leaves0:1)
Block(2,10,0,rustic:leaves0:2)
Block(2,10,1,rustic:leaves0)
Block(2,10,2,rustic:leaves0:2)
Block(2,10,3,rustic:leaves0:1)
Block(2,10,4,rustic:leaves0:0)
Block(2,11,-1,rustic:leaves0:0)
Block(2,11,0,rustic:leaves0:1)
Block(2,11,1,rustic:leaves0:2)
Block(2,11,2,rustic:leaves0:1)
Block(2,11,3,rustic:leaves0:0)
Block(2,12,0,rustic:leaves0:0)
Block(2,12,1,rustic:leaves0:1)
Block(2,12,2,rustic:leaves0:0)
Block(2,13,1,rustic:leaves0:0)
Block(3,3,-1,rustic:olivebranch:2)
Block(3,4,-5,rustic:leaves0:0)
Block(3,4,-4,rustic:leaves0:1)
Block(3,4,-3,rustic:leaves0:2)
Block(3,5,-5,rustic:leaves0:0)
Block(3,5,-4,rustic:leaves0:2)
Block(3,5,-3,rustic:leaves0)
Block(3,5,-2,rustic:leaves0)
Block(3,5,-1,rustic:olivebranch)
Block(3,5,2,rustic:olivebranch:2)
Block(3,5,4,rustic:leaves0:0)
Block(3,5,5,rustic:leaves0:0)
Block(3,5,6,rustic:leaves0:0)
Block(3,6,-5,rustic:leaves0:0)
Block(3,6,-4,rustic:leaves0:1)
Block(3,6,-3,rustic:leaves0:2)
Block(3,6,-2,rustic:leaves0:2)
Block(3,6,-1,rustic:leaves0)
Block(3,6,2,rustic:olivebranch:1)
Block(3,6,3,rustic:leaves0:2)
Block(3,6,4,rustic:leaves0)
Block(3,6,5,rustic:leaves0:2)
Block(3,6,6,rustic:leaves0:1)
Block(3,6,7,rustic:leaves0:0)
Block(3,7,-4,rustic:leaves0:0)
Block(3,7,-3,rustic:leaves0:1)
Block(3,7,-2,rustic:leaves0:0)
Block(3,7,-1,rustic:leaves0)
Block(3,7,0,rustic:olivebranch)
Block(3,7,2,rustic:olivebranch)
Block(3,7,3,rustic:leaves0)
Block(3,7,4,rustic:leaves0:2)
Block(3,7,5,rustic:leaves0:1)
Block(3,7,6,rustic:leaves0:0)
Block(3,8,-3,rustic:leaves0:0)
Block(3,8,-2,rustic:leaves0:0)
Block(3,8,-1,rustic:leaves0:2)
Block(3,8,0,rustic:leaves0)
Block(3,8,2,rustic:leaves0)
Block(3,8,3,rustic:leaves0:2)
Block(3,8,4,rustic:leaves0:1)
Block(3,8,5,rustic:leaves0:0)
Block(3,9,-1,rustic:leaves0:0)
Block(3,9,0,rustic:leaves0:0)
Block(3,9,2,rustic:leaves0:0)
Block(3,9,3,rustic:leaves0:0)
Block(3,9,4,rustic:leaves0:0)
Block(3,10,-1,rustic:leaves0:0)
Block(3,10,0,rustic:leaves0:0)
Block(3,10,1,rustic:leaves0:0)
Block(3,10,2,rustic:leaves0:0)
Block(3,10,3,rustic:leaves0:0)
Block(3,11,0,rustic:leaves0:0)
Block(3,11,1,rustic:leaves0:0)
Block(3,11,2,rustic:leaves0:0)
Block(3,12,1,rustic:leaves0:0)
Block(4,3,-5,rustic:leaves0:0)
Block(4,3,-4,rustic:leaves0)
Block(4,3,-3,rustic:olivebranch)
Block(4,3,-2,rustic:olivebranch:1)
Block(4,3,-1,rustic:olivebranch:2)
Block(4,4,-5,rustic:leaves0:0)
Block(4,4,-4,rustic:leaves0:2)
Block(4,4,-3,rustic:leaves0)
Block(4,4,-1,rustic:olivebranch)
Block(4,5,-5,rustic:leaves0:0)
Block(4,5,-4,rustic:leaves0:1)
Block(4,5,-3,rustic:leaves0:2)
Block(4,5,-2,rustic:leaves0:2)
Block(4,5,-1,rustic:leaves0)
Block(4,5,2,rustic:olivebranch:1)
Block(4,6,-4,rustic:leaves0:0)
Block(4,6,-3,rustic:leaves0:1)
Block(4,6,-2,rustic:leaves0:1)
Block(4,6,-1,rustic:leaves0:2)
Block(4,6,0,rustic:leaves0:0)
Block(4,6,1,rustic:leaves0:1)
Block(4,6,2,rustic:leaves0:2)
Block(4,6,3,rustic:leaves0:1)
Block(4,6,4,rustic:leaves0:0)
Block(4,6,5,rustic:leaves0:0)
Block(4,6,6,rustic:leaves0:0)
Block(4,7,-3,rustic:leaves0:0)
Block(4,7,-2,rustic:leaves0:0)
Block(4,7,-1,rustic:leaves0:2)
Block(4,7,0,rustic:leaves0)
Block(4,7,1,rustic:leaves0:2)
Block(4,7,2,rustic:leaves0)
Block(4,7,3,rustic:leaves0:2)
Block(4,7,4,rustic:leaves0:1)
Block(4,7,5,rustic:leaves0:0)
Block(4,8,-2,rustic:leaves0:0)
Block(4,8,-1,rustic:leaves0:1)
Block(4,8,0,rustic:leaves0:2)
Block(4,8,1,rustic:leaves0:1)
Block(4,8,2,rustic:leaves0:2)
Block(4,8,3,rustic:leaves0:1)
Block(4,8,4,rustic:leaves0:0)
Block(4,9,-1,rustic:leaves0:0)
Block(4,9,0,rustic:leaves0:0)
Block(4,9,1,rustic:leaves0:0)
Block(4,9,2,rustic:leaves0:0)
Block(4,9,3,rustic:leaves0:0)
Block(5,2,-4,rustic:leaves0:0)
Block(5,2,-3,rustic:leaves0:0)
Block(5,3,-5,rustic:leaves0:0)
Block(5,3,-4,rustic:leaves0:2)
Block(5,3,-3,rustic:leaves0)
Block(5,3,-2,rustic:leaves0:2)
Block(5,3,-1,rustic:olivebranch:1)
Block(5,4,-5,rustic:leaves0:0)
Block(5,4,-4,rustic:leaves0:1)
Block(5,4,-3,rustic:leaves0:2)
Block(5,4,-2,rustic:leaves0:1)
Block(5,5,-4,rustic:leaves0:0)
Block(5,5,-3,rustic:leaves0:1)
Block(5,5,-2,rustic:leaves0:0)
Block(5,5,-1,rustic:leaves0:0)
Block(5,5,0,rustic:leaves0:0)
Block(5,5,1,rustic:leaves0)
Block(5,5,2,rustic:olivebranch)
Block(5,5,3,rustic:leaves0)
Block(5,5,4,rustic:leaves0:0)
Block(5,6,-3,rustic:leaves0:0)
Block(5,6,-2,rustic:leaves0:0)
Block(5,6,-1,rustic:leaves0:0)
Block(5,6,0,rustic:leaves0:0)
Block(5,6,1,rustic:leaves0:2)
Block(5,6,2,rustic:leaves0)
Block(5,6,3,rustic:leaves0:2)
Block(5,6,4,rustic:leaves0:0)
Block(5,7,-1,rustic:leaves0:0)
Block(5,7,0,rustic:leaves0:0)
Block(5,7,1,rustic:leaves0:1)
Block(5,7,2,rustic:leaves0:2)
Block(5,7,3,rustic:leaves0:1)
Block(5,7,4,rustic:leaves0:0)
Block(5,8,-1,rustic:leaves0:0)
Block(5,8,0,rustic:leaves0:0)
Block(5,8,1,rustic:leaves0:0)
Block(5,8,2,rustic:leaves0:1)
Block(5,8,3,rustic:leaves0:0)
Block(5,9,2,rustic:leaves0:0)
Block(6,2,-4,rustic:leaves0:0)
Block(6,2,-3,rustic:leaves0:0)
Block(6,2,-2,rustic:leaves0:2)
Block(6,2,-1,rustic:leaves0)
Block(6,3,-5,rustic:leaves0:0)
Block(6,3,-4,rustic:leaves0:1)
Block(6,3,-3,rustic:leaves0:2)
Block(6,3,-2,rustic:leaves0)
Block(6,3,-1,rustic:olivebranch)
Block(6,3,0,rustic:leaves0)
Block(6,4,-4,rustic:leaves0:0)
Block(6,4,-3,rustic:leaves0:1)
Block(6,4,-2,rustic:leaves0:2)
Block(6,4,-1,rustic:leaves0)
Block(6,4,0,rustic:leaves0:2)
Block(6,4,1,rustic:leaves0:1)
Block(6,4,2,rustic:leaves0:0)
Block(6,4,3,rustic:leaves0:0)
Block(6,5,-3,rustic:leaves0:0)
Block(6,5,-2,rustic:leaves0:0)
Block(6,5,-1,rustic:leaves0:0)
Block(6,5,0,rustic:leaves0:1)
Block(6,5,1,rustic:leaves0:2)
Block(6,5,2,rustic:leaves0)
Block(6,5,3,rustic:leaves0:2)
Block(6,5,4,rustic:leaves0:0)
Block(6,6,0,rustic:leaves0:0)
Block(6,6,1,rustic:leaves0:1)
Block(6,6,2,rustic:leaves0:2)
Block(6,6,3,rustic:leaves0:1)
Block(6,6,4,rustic:leaves0:0)
Block(6,7,1,rustic:leaves0:0)
Block(6,7,2,rustic:leaves0:1)
Block(6,7,3,rustic:leaves0:0)
Block(6,8,2,rustic:leaves0:0)
Block(7,2,-3,rustic:leaves0:0)
Block(7,2,-2,rustic:leaves0:1)
Block(7,2,-1,rustic:leaves0:2)
Block(7,2,0,rustic:leaves0:1)
Block(7,3,-4,rustic:leaves0:0)
Block(7,3,-3,rustic:leaves0:1)
Block(7,3,-2,rustic:leaves0:2)
Block(7,3,-1,rustic:leaves0)
Block(7,3,0,rustic:leaves0:2)
Block(7,3,1,rustic:leaves0:0)
Block(7,4,-3,rustic:leaves0:0)
Block(7,4,-2,rustic:leaves0:1)
Block(7,4,-1,rustic:leaves0:2)
Block(7,4,0,rustic:leaves0:1)
Block(7,4,1,rustic:leaves0:0)
Block(7,5,-2,rustic:leaves0:0)
Block(7,5,-1,rustic:leaves0:0)
Block(7,5,0,rustic:leaves0:0)
Block(7,5,1,rustic:leaves0:0)
Block(7,5,2,rustic:leaves0:0)
Block(7,5,3,rustic:leaves0:0)
Block(7,6,1,rustic:leaves0:0)
Block(7,6,2,rustic:leaves0:0)
Block(7,6,3,rustic:leaves0:0)
Block(7,7,2,rustic:leaves0:0)
Block(8,2,-2,rustic:leaves0:0)
Block(8,2,-1,rustic:leaves0:0)
Block(8,2,0,rustic:leaves0:0)
Block(8,3,-3,rustic:leaves0:0)
Block(8,3,-2,rustic:leaves0:0)
Block(8,3,-1,rustic:leaves0:0)
Block(8,3,0,rustic:leaves0:0)
Block(8,4,-2,rustic:leaves0:0)
Block(8,4,-1,rustic:leaves0:0)
Block(8,4,0,rustic:leaves0:0)

#######################################################################
# +-----------------------------------------------------------------+ #
# |                            BO3 checks                           | #
# +-----------------------------------------------------------------+ #
#######################################################################

BlockCheck(0,-1,1,GRASS,DIRT,biomesoplenty:grass,biomesoplenty:dirt)

#######################################################################
# +-----------------------------------------------------------------+ #
# |                             Branches                            | #
# +-----------------------------------------------------------------+ #
#######################################################################


#######################################################################
# +-----------------------------------------------------------------+ #
# |                             Entities                            | #
# +-----------------------------------------------------------------+ #
#######################################################################


#######################################################################
# +-----------------------------------------------------------------+ #
# |                            Particles                            | #
# +-----------------------------------------------------------------+ #
#######################################################################


#######################################################################
# +-----------------------------------------------------------------+ #
# |                             Spawners                            | #
# +-----------------------------------------------------------------+ #
#######################################################################


#######################################################################
# +-----------------------------------------------------------------+ #
# |                             ModData                             | #
# +-----------------------------------------------------------------+ #
#######################################################################

