#######################################################################
# +-----------------------------------------------------------------+ #
# |                            BO3 object                           | #
# +-----------------------------------------------------------------+ #
#######################################################################

Author: Bo3 BulkEdit

Description: Converted Schematic - Modified by Bo3BulkEdit

Version: 3

SettingsMode: WriteDisable

#######################################################################
# +-----------------------------------------------------------------+ #
# |                          Main settings                          | #
# +-----------------------------------------------------------------+ #
#######################################################################



Frequency: 0


SpawnHeight: randomY





##############################
# Height Limits for the BO3. #
##############################

MinHeight: 0
MaxHeight: 256

#######################################################################
# +-----------------------------------------------------------------+ #
# |                      Source block settings                      | #
# +-----------------------------------------------------------------+ #
#######################################################################

CanOverride: true
MaxPercentageOutsideSourceBlock: 100
OutsideSourceBlock: placeAnyway

#######################################################################
# +-----------------------------------------------------------------+ #
# |                               OTG+                              | #
# +-----------------------------------------------------------------+ #
#######################################################################

#######################################################################
# +-----------------------------------------------------------------+ #
# |                              Blocks                             | #
# +-----------------------------------------------------------------+ #
#######################################################################

B(0,750,0,AIR)
B(15,750,15,AIR)
B(5,-5,5,betternether:quartz_stained_glass:15)
B(5,-5,6,betternether:quartz_stained_glass:15)
B(5,-4,3,betternether:quartz_stained_glass:15)
B(4,-4,4,betternether:quartz_stained_glass:15)
B(5,-4,4,betternether:quartz_stained_glass:15)
B(4,-4,5,betternether:quartz_stained_glass:15)
B(5,-4,5,betternether:quartz_stained_glass:15)
B(6,-4,5,betternether:quartz_stained_glass:15)
B(4,-4,6,betternether:quartz_stained_glass:15)
B(5,-4,6,betternether:quartz_stained_glass:15)
B(6,-4,6,betternether:quartz_stained_glass:15)
B(4,-3,1,betternether:quartz_stained_glass:15)
B(3,-3,2,betternether:quartz_stained_glass:15)
B(4,-3,2,betternether:quartz_stained_glass:15)
B(5,-3,2,betternether:quartz_stained_glass:15)
B(3,-3,3,betternether:quartz_stained_glass:15)
B(4,-3,3,betternether:quartz_stained_glass:15)
B(5,-3,3,betternether:quartz_stained_glass:15)
B(3,-3,4,betternether:quartz_stained_glass:15)
B(4,-3,4,betternether:quartz_stained_glass:15)
B(5,-3,4,betternether:quartz_stained_glass:15)
B(6,-3,4,betternether:quartz_stained_glass:15)
B(3,-3,5,betternether:quartz_stained_glass:15)
B(4,-3,5,betternether:quartz_stained_glass:15)
B(5,-3,5,betternether:quartz_stained_glass:15)
B(6,-3,5,betternether:quartz_stained_glass:15)
B(4,-3,6,betternether:quartz_stained_glass:15)
B(6,-3,6,betternether:quartz_stained_glass:15)
B(4,-2,0,betternether:quartz_stained_glass:15)
B(5,-2,0,betternether:quartz_stained_glass:15)
B(6,-2,0,betternether:quartz_stained_glass:15)
B(2,-2,1,betternether:quartz_stained_glass:15)
B(3,-2,1,betternether:quartz_stained_glass:15)
B(4,-2,1,betternether:quartz_stained_glass:15)
B(5,-2,1,betternether:quartz_stained_glass:15)
B(6,-2,1,betternether:quartz_stained_glass:15)
B(3,-2,2,betternether:quartz_stained_glass:15)
B(4,-2,2,betternether:quartz_stained_glass:15)
B(5,-2,2,betternether:quartz_stained_glass:15)
B(6,-2,2,betternether:quartz_stained_glass:15)
B(2,-2,3,betternether:quartz_stained_glass:15)
B(3,-2,3,betternether:quartz_stained_glass:15)
B(4,-2,3,betternether:quartz_stained_glass:15)
B(5,-2,3,betternether:quartz_stained_glass:15)
B(6,-2,3,betternether:quartz_stained_glass:15)
B(7,-2,3,betternether:quartz_stained_glass:15)
B(2,-2,4,betternether:quartz_stained_glass:15)
B(3,-2,4,betternether:quartz_stained_glass:15)
B(4,-2,4,betternether:quartz_stained_glass:15)
B(5,-2,4,betternether:quartz_stained_glass:15)
B(6,-2,4,betternether:quartz_stained_glass:15)
B(3,-2,5,betternether:quartz_stained_glass:15)
B(4,-2,5,betternether:quartz_stained_glass:15)
B(6,-2,5,betternether:quartz_stained_glass:15)
B(7,-2,5,betternether:quartz_stained_glass:15)
B(2,-1,0,betternether:quartz_stained_glass:15)
B(3,-1,0,betternether:quartz_stained_glass:15)
B(4,-1,0,betternether:quartz_stained_glass:15)
B(5,-1,0,betternether:quartz_stained_glass:15)
B(6,-1,0,betternether:quartz_stained_glass:15)
B(7,-1,0,betternether:quartz_stained_glass:15)
B(2,-1,1,betternether:quartz_stained_glass:15)
B(3,-1,1,betternether:quartz_stained_glass:15)
B(4,-1,1,betternether:quartz_stained_glass:15)
B(5,-1,1,betternether:quartz_stained_glass:15)
B(1,-1,2,betternether:quartz_stained_glass:15)
B(2,-1,2,betternether:quartz_stained_glass:15)
B(3,-1,2,betternether:quartz_stained_glass:15)
B(4,-1,2,betternether:quartz_stained_glass:15)
B(5,-1,2,betternether:quartz_stained_glass:15)
B(6,-1,2,betternether:quartz_stained_glass:15)
B(7,-1,2,betternether:quartz_stained_glass:15)
B(1,-1,3,betternether:quartz_stained_glass:15)
B(2,-1,3,betternether:quartz_stained_glass:15)
B(3,-1,3,betternether:quartz_stained_glass:15)
B(4,-1,3,betternether:quartz_stained_glass:15)
RB(5,-1,3,srparasites:parasitestain:1,80,quark:crystal:1,30,srparasites:parasiterubbledense:1,100)
B(6,-1,3,betternether:quartz_stained_glass:15)
B(7,-1,3,betternether:quartz_stained_glass:15)
B(2,-1,4,betternether:quartz_stained_glass:15)
B(3,-1,4,betternether:quartz_stained_glass:15)
B(4,-1,4,betternether:quartz_stained_glass:15)
B(5,-1,4,betternether:quartz_stained_glass:15)
B(7,-1,4,betternether:quartz_stained_glass:15)
B(3,-1,5,betternether:quartz_stained_glass:15)
B(4,-1,5,betternether:quartz_stained_glass:15)
B(5,-1,5,betternether:quartz_stained_glass:15)
B(6,-1,5,betternether:quartz_stained_glass:15)
B(7,-1,5,betternether:quartz_stained_glass:15)
B(1,0,0,betternether:quartz_stained_glass:15)
B(2,0,0,betternether:quartz_stained_glass:15)
B(3,0,0,betternether:quartz_stained_glass:15)
B(4,0,0,betternether:quartz_stained_glass:15)
B(5,0,0,betternether:quartz_stained_glass:15)
B(6,0,0,betternether:quartz_stained_glass:15)
B(7,0,0,betternether:quartz_stained_glass:15)
B(1,0,1,betternether:quartz_stained_glass:15)
B(2,0,1,betternether:quartz_stained_glass:15)
B(3,0,1,betternether:quartz_stained_glass:15)
RB(5,0,1,srparasites:parasitestain:1,80,quark:crystal:1,30,srparasites:parasiterubbledense:1,100)
B(6,0,1,betternether:quartz_stained_glass:15)
B(7,0,1,betternether:quartz_stained_glass:15)
B(8,0,1,betternether:quartz_stained_glass:15)
B(1,0,2,betternether:quartz_stained_glass:15)
B(2,0,2,betternether:quartz_stained_glass:15)
B(3,0,2,betternether:quartz_stained_glass:15)
RB(4,0,2,srparasites:parasitestain:1,80,quark:crystal:1,30,srparasites:parasiterubbledense:1,100)
RB(5,0,2,srparasites:parasitestain:1,80,quark:crystal:1,30,srparasites:parasiterubbledense:1,100)
B(6,0,2,betternether:quartz_stained_glass:15)
B(7,0,2,betternether:quartz_stained_glass:15)
B(1,0,3,betternether:quartz_stained_glass:15)
B(2,0,3,betternether:quartz_stained_glass:15)
B(3,0,3,betternether:quartz_stained_glass:15)
B(4,0,3,srparasites:parasiterubbledense:1)
B(5,0,3,betternether:quartz_stained_glass:15)
B(6,0,3,betternether:quartz_stained_glass:15)
B(7,0,3,betternether:quartz_stained_glass:15)
B(8,0,3,betternether:quartz_stained_glass:15)
B(1,0,4,betternether:quartz_stained_glass:15)
B(2,0,4,betternether:quartz_stained_glass:15)
B(3,0,4,betternether:quartz_stained_glass:15)
B(4,0,4,betternether:quartz_stained_glass:15)
B(5,0,4,betternether:quartz_stained_glass:15)
B(6,0,4,betternether:quartz_stained_glass:15)
B(7,0,4,betternether:quartz_stained_glass:15)
B(4,0,5,betternether:quartz_stained_glass:15)
B(5,0,5,betternether:quartz_stained_glass:15)
B(1,1,0,betternether:quartz_stained_glass:15)
B(2,1,0,betternether:quartz_stained_glass:15)
RB(3,1,0,srparasites:parasitestain:1,80,quark:crystal:1,30,srparasites:parasiterubbledense:1,100)
B(4,1,0,betternether:quartz_stained_glass:15)
RB(5,1,0,srparasites:parasitestain:1,80,quark:crystal:1,30,srparasites:parasiterubbledense:1,100)
B(6,1,0,betternether:quartz_stained_glass:15)
B(7,1,0,betternether:quartz_stained_glass:15)
B(1,1,1,betternether:quartz_stained_glass:15)
B(2,1,1,betternether:quartz_stained_glass:15)
B(3,1,1,betternether:quartz_stained_glass:15)
RB(4,1,1,srparasites:parasitestain:1,80,quark:crystal:1,30,srparasites:parasiterubbledense:1,100)
RB(5,1,1,srparasites:parasitestain:1,80,quark:crystal:1,30,srparasites:parasiterubbledense:1,100)
B(6,1,1,betternether:quartz_stained_glass:15)
B(7,1,1,betternether:quartz_stained_glass:15)
B(8,1,1,betternether:quartz_stained_glass:15)
B(1,1,2,betternether:quartz_stained_glass:15)
B(2,1,2,betternether:quartz_stained_glass:15)
B(3,1,2,srparasites:parasiterubbledense:1)
B(4,1,2,srparasites:parasiterubbledense:1)
RB(5,1,2,srparasites:parasitestain:1,80,quark:crystal:1,30,srparasites:parasiterubbledense:1,100)
B(6,1,2,betternether:quartz_stained_glass:15)
B(7,1,2,betternether:quartz_stained_glass:15)
B(2,1,3,srparasites:parasiterubbledense:1)
B(3,1,3,srparasites:parasiterubbledense:1)
B(4,1,3,srparasites:parasiterubbledense:1)
B(5,1,3,srparasites:parasiterubbledense:1)
B(6,1,3,betternether:quartz_stained_glass:15)
B(7,1,3,betternether:quartz_stained_glass:15)
B(1,1,4,betternether:quartz_stained_glass:15)
B(2,1,4,betternether:quartz_stained_glass:15)
B(3,1,4,betternether:quartz_stained_glass:15)
B(4,1,4,betternether:quartz_stained_glass:15)
B(5,1,4,betternether:quartz_stained_glass:15)
B(6,1,4,betternether:quartz_stained_glass:15)
B(1,2,0,betternether:quartz_stained_glass:15)
B(2,2,0,betternether:quartz_stained_glass:15)
RB(3,2,0,srparasites:parasitestain:1,80,quark:crystal:1,30,srparasites:parasiterubbledense:1,100)
RB(4,2,0,srparasites:parasitestain:1,80,quark:crystal:1,30,srparasites:parasiterubbledense:1,100)
RB(5,2,0,srparasites:parasitestain:1,80,quark:crystal:1,30,srparasites:parasiterubbledense:1,100)
B(6,2,0,betternether:quartz_stained_glass:15)
B(7,2,0,betternether:quartz_stained_glass:15)
B(8,2,0,betternether:quartz_stained_glass:15)
B(1,2,1,betternether:quartz_stained_glass:15)
B(2,2,1,betternether:quartz_stained_glass:15)
B(3,2,1,betternether:quartz_stained_glass:15)
RB(4,2,1,srparasites:parasitestain:1,80,quark:crystal:1,30,srparasites:parasiterubbledense:1,100)
B(5,2,1,srparasites:parasiterubbledense:1)
B(6,2,1,betternether:quartz_stained_glass:15)
B(7,2,1,betternether:quartz_stained_glass:15)
B(8,2,1,betternether:quartz_stained_glass:15)
B(1,2,2,betternether:quartz_stained_glass:15)
B(2,2,2,srparasites:parasiterubbledense:1)
B(3,2,2,srparasites:parasiterubbledense:1)
B(4,2,2,srparasites:parasiterubbledense:1)
B(5,2,2,srparasites:parasiterubbledense:1)
B(6,2,2,betternether:quartz_stained_glass:15)
B(7,2,2,betternether:quartz_stained_glass:15)
B(2,2,3,betternether:quartz_stained_glass:15)
B(3,2,3,srparasites:parasiterubbledense:1)
B(4,2,3,betternether:quartz_stained_glass:15)
B(5,2,3,betternether:quartz_stained_glass:15)
B(6,2,3,betternether:quartz_stained_glass:15)
B(1,3,0,betternether:quartz_stained_glass:15)
B(2,3,0,betternether:quartz_stained_glass:15)
RB(3,3,0,srparasites:parasitestain:1,80,quark:crystal:1,30,srparasites:parasiterubbledense:1,100)
RB(4,3,0,srparasites:parasitestain:1,80,quark:crystal:1,30,srparasites:parasiterubbledense:1,100)
RB(5,3,0,srparasites:parasitestain:1,80,quark:crystal:1,30,srparasites:parasiterubbledense:1,100)
B(6,3,0,betternether:quartz_stained_glass:15)
B(7,3,0,betternether:quartz_stained_glass:15)
B(8,3,0,betternether:quartz_stained_glass:15)
B(1,3,1,betternether:quartz_stained_glass:15)
B(2,3,1,betternether:quartz_stained_glass:15)
B(3,3,1,betternether:quartz_stained_glass:15)
B(4,3,1,betternether:quartz_stained_glass:15)
B(5,3,1,betternether:quartz_stained_glass:15)
B(6,3,1,betternether:quartz_stained_glass:15)
B(7,3,1,betternether:quartz_stained_glass:15)
B(2,3,2,betternether:quartz_stained_glass:15)
B(3,3,2,betternether:quartz_stained_glass:15)
B(4,3,2,betternether:quartz_stained_glass:15)
B(5,3,2,betternether:quartz_stained_glass:15)
B(6,3,2,betternether:quartz_stained_glass:15)
B(7,3,2,betternether:quartz_stained_glass:15)
B(3,3,3,betternether:quartz_stained_glass:15)
B(4,3,3,betternether:quartz_stained_glass:15)
B(5,3,3,betternether:quartz_stained_glass:15)
B(1,4,0,betternether:quartz_stained_glass:15)
B(2,4,0,betternether:quartz_stained_glass:15)
B(3,4,0,srparasites:parasiterubbledense:1)
RB(4,4,0,srparasites:parasitestain:1,80,quark:crystal:1,30,srparasites:parasiterubbledense:1,100)
B(5,4,0,betternether:quartz_stained_glass:15)
B(6,4,0,betternether:quartz_stained_glass:15)
B(7,4,0,betternether:quartz_stained_glass:15)
B(8,4,0,betternether:quartz_stained_glass:15)
B(1,4,1,betternether:quartz_stained_glass:15)
B(2,4,1,betternether:quartz_stained_glass:15)
B(3,4,1,srparasites:parasiterubbledense:1)
B(4,4,1,srparasites:parasiterubbledense:1)
B(5,4,1,betternether:quartz_stained_glass:15)
B(6,4,1,betternether:quartz_stained_glass:15)
B(7,4,1,betternether:quartz_stained_glass:15)
B(2,4,2,betternether:quartz_stained_glass:15)
B(4,4,2,betternether:quartz_stained_glass:15)
B(5,4,2,betternether:quartz_stained_glass:15)
B(1,5,0,betternether:quartz_stained_glass:15)
B(2,5,0,srparasites:parasiterubbledense:1)
B(3,5,0,srparasites:parasiterubbledense:1)
B(4,5,0,betternether:quartz_stained_glass:15)
B(5,5,0,srparasites:parasiterubbledense:1)
B(6,5,0,betternether:quartz_stained_glass:15)
B(7,5,0,betternether:quartz_stained_glass:15)
B(1,5,1,betternether:quartz_stained_glass:15)
B(2,5,1,betternether:quartz_stained_glass:15)
B(3,5,1,betternether:quartz_stained_glass:15)
B(4,5,1,betternether:quartz_stained_glass:15)
B(5,5,1,betternether:quartz_stained_glass:15)
B(6,5,1,betternether:quartz_stained_glass:15)
B(7,5,1,betternether:quartz_stained_glass:15)
B(5,5,2,betternether:quartz_stained_glass:15)
B(1,6,0,betternether:quartz_stained_glass:15)
B(2,6,0,betternether:quartz_stained_glass:15)
B(3,6,0,betternether:quartz_stained_glass:15)
B(4,6,0,srparasites:parasiterubbledense:1)
B(5,6,0,betternether:quartz_stained_glass:15)
B(6,6,0,betternether:quartz_stained_glass:15)
B(4,6,1,betternether:quartz_stained_glass:15)
B(1,7,0,betternether:quartz_stained_glass:15)
B(3,7,0,betternether:quartz_stained_glass:15)
B(4,7,0,betternether:quartz_stained_glass:15)
B(5,7,0,betternether:quartz_stained_glass:15)
B(4,8,0,betternether:quartz_stained_glass:15)

#######################################################################
# +-----------------------------------------------------------------+ #
# |                             Branches                            | #
# +-----------------------------------------------------------------+ #
#######################################################################

BR(0,0,-16,true,CRYST-SET-MED-BIG-02_0x0,NORTH,100,0)
