Author: NLBlackEagle
Description: No description given
SettingsMode: WriteDisable
Frequency: 0
SpawnHeight: highestBlock
UseCenterForHighestBlock: true
MinHeight: 0
MaxHeight: 255
InheritBO3: 
InheritBO3Rotation: NORTH
OverrideChildSettings: true
OverrideParentHeight: false
CanOverride: false
BranchFrequency: 0
BranchFrequencyGroup: 
MustBeBelowOther: false
MustBeInside: 
CannotBeInside: 
ReplacesBO3: 
MustBeInsideWorldBorders: false
CanSpawnOnWater: true
SpawnOnWaterOnly: true
SpawnUnderWater: false
SpawnAtWaterLevel: false
HeightOffset: 0
RemoveAir: false
ReplaceAbove: 
ReplaceBelow: 
ReplaceWithBiomeBlocks: true
ReplaceWithSurfaceBlock: GRASS
ReplaceWithGroundBlock: DIRT
ReplaceWithStoneBlock: STONE
SmoothRadius: 0
SmoothHeightOffset: 0
SmoothStartTop: false
SmoothStartWood: false
SmoothingSurfaceBlock: 
SmoothingGroundBlock: 
BO3Group: 
IsSpawnPoint: false
DoReplaceBlocks: true
Block(2,50,-1,WOOD_BUTTON:2)
Block(2,50,1,WOOD_BUTTON:2)
Block(2,50,2,WOOD_BUTTON:2)
Block(2,50,3,WOOD_BUTTON:2)
Block(2,50,5,WOOD_BUTTON:2)
Block(2,50,6,WOOD_BUTTON:2)
Block(2,50,7,WOOD_BUTTON:2)
Block(2,54,0,WOOD_STEP:8)
Block(2,54,1,SPRUCE_WOOD_STAIRS:4)
Block(2,54,2,WOOD_STEP:8)
Block(2,54,3,SPRUCE_WOOD_STAIRS:4)
Block(2,54,4,WOOD_STEP:8)
Block(2,54,5,SPRUCE_WOOD_STAIRS:4)
Block(2,54,6,WOOD_STEP:8)
Block(2,54,7,SPRUCE_WOOD_STAIRS:4)
Block(2,54,8,WOOD_STEP:8)
Block(2,55,0,SPRUCE_WOOD_STAIRS:0)
Block(2,55,4,SPRUCE_WOOD_STAIRS:0)
Block(2,55,8,SPRUCE_WOOD_STAIRS:0)
Block(3,0,-2,LOG:1)
Block(3,0,0,LOG:1)
Block(3,0,4,LOG:1)
Block(3,0,8,LOG:1)
Block(3,1,-2,LOG:1)
Block(3,1,0,LOG:1)
Block(3,1,1,LOG:9)
Block(3,1,2,LOG:9)
Block(3,1,3,LOG:9)
Block(3,1,4,LOG:1)
Block(3,1,8,LOG:1)
Block(3,2,-2,LOG:1)
Block(3,2,-1,LOG:9)
Block(3,2,0,LOG:1)
Block(3,2,4,LOG:1)
Block(3,2,5,LOG:9)
Block(3,2,6,LOG:9)
Block(3,2,7,LOG:9)
Block(3,2,8,LOG:1)
Block(3,3,-2,LOG:1)
Block(3,3,0,LOG:1)
Block(3,3,4,LOG:1)
Block(3,3,8,LOG:1)
Block(3,4,-2,LOG:1)
Block(3,4,0,LOG:1)
Block(3,4,4,LOG:1)
Block(3,4,8,LOG:1)
Block(3,5,-2,LOG:1)
Block(3,5,0,LOG:1)
Block(3,5,1,LOG:9)
Block(3,5,2,LOG:9)
Block(3,5,3,LOG:9)
Block(3,5,4,LOG:1)
Block(3,5,8,LOG:1)
Block(3,6,-2,LOG:1)
Block(3,6,-1,LOG:9)
Block(3,6,0,LOG:1)
Block(3,6,4,LOG:1)
Block(3,6,5,LOG:9)
Block(3,6,6,LOG:9)
Block(3,6,7,LOG:9)
Block(3,6,8,LOG:1)
Block(3,7,-2,LOG:1)
Block(3,7,0,LOG:1)
Block(3,7,4,LOG:1)
Block(3,7,8,LOG:1)
Block(3,8,-2,LOG:1)
Block(3,8,0,LOG:1)
Block(3,8,4,LOG:1)
Block(3,8,8,LOG:1)
Block(3,9,-2,LOG:1)
Block(3,9,0,LOG:1)
Block(3,9,1,LOG:9)
Block(3,9,2,LOG:9)
Block(3,9,3,LOG:9)
Block(3,9,4,LOG:1)
Block(3,9,8,LOG:1)
Block(3,10,-2,LOG:1)
Block(3,10,-1,LOG:9)
Block(3,10,0,LOG:1)
Block(3,10,4,LOG:1)
Block(3,10,5,LOG:9)
Block(3,10,6,LOG:9)
Block(3,10,7,LOG:9)
Block(3,10,8,LOG:1)
Block(3,11,-2,LOG:1)
Block(3,11,0,LOG:1)
Block(3,11,4,LOG:1)
Block(3,11,8,LOG:1)
Block(3,12,-2,LOG:1)
Block(3,12,0,LOG:1)
Block(3,12,4,LOG:1)
Block(3,12,8,LOG:1)
Block(3,13,-2,LOG:1)
Block(3,13,0,LOG:1)
Block(3,13,1,LOG:9)
Block(3,13,2,LOG:9)
Block(3,13,3,LOG:9)
Block(3,13,4,LOG:1)
Block(3,13,8,LOG:1)
Block(3,14,-2,LOG:1)
Block(3,14,-1,LOG:9)
Block(3,14,0,LOG:1)
Block(3,14,4,LOG:1)
Block(3,14,5,LOG:9)
Block(3,14,6,LOG:9)
Block(3,14,7,LOG:9)
Block(3,14,8,LOG:1)
Block(3,15,-2,LOG:1)
Block(3,15,0,LOG:1)
Block(3,15,4,LOG:1)
Block(3,15,8,LOG:1)
Block(3,16,-2,LOG:1)
Block(3,16,0,LOG:1)
Block(3,16,4,LOG:1)
Block(3,16,8,LOG:1)
Block(3,17,-2,LOG:1)
Block(3,17,0,LOG:1)
Block(3,17,1,LOG:9)
Block(3,17,2,LOG:9)
Block(3,17,3,LOG:9)
Block(3,17,4,LOG:1)
Block(3,17,8,LOG:1)
Block(3,18,-2,LOG:1)
Block(3,18,-1,LOG:9)
Block(3,18,0,LOG:1)
Block(3,18,4,LOG:1)
Block(3,18,5,LOG:9)
Block(3,18,6,LOG:9)
Block(3,18,7,LOG:9)
Block(3,18,8,LOG:1)
Block(3,19,-2,LOG:1)
Block(3,19,0,LOG:1)
Block(3,19,4,LOG:1)
Block(3,19,8,LOG:1)
Block(3,20,-2,LOG:1)
Block(3,20,0,LOG:1)
Block(3,20,4,LOG:1)
Block(3,20,8,LOG:1)
Block(3,21,-2,LOG:1)
Block(3,21,0,LOG:1)
Block(3,21,1,LOG:9)
Block(3,21,2,LOG:9)
Block(3,21,3,LOG:9)
Block(3,21,4,LOG:1)
Block(3,21,8,LOG:1)
Block(3,22,-2,LOG:1)
Block(3,22,-1,LOG:9)
Block(3,22,0,LOG:1)
Block(3,22,4,LOG:1)
Block(3,22,5,LOG:9)
Block(3,22,6,LOG:9)
Block(3,22,7,LOG:9)
Block(3,22,8,LOG:1)
Block(3,23,-2,LOG:1)
Block(3,23,0,LOG:1)
Block(3,23,4,LOG:1)
Block(3,23,8,LOG:1)
Block(3,24,-2,LOG:1)
Block(3,24,0,LOG:1)
Block(3,24,4,LOG:1)
Block(3,24,8,LOG:1)
Block(3,25,-2,LOG:1)
Block(3,25,0,LOG:1)
Block(3,25,1,LOG:9)
Block(3,25,2,LOG:9)
Block(3,25,3,LOG:9)
Block(3,25,4,LOG:1)
Block(3,25,8,LOG:1)
Block(3,26,-2,LOG:1)
Block(3,26,-1,LOG:9)
Block(3,26,0,LOG:1)
Block(3,26,4,LOG:1)
Block(3,26,5,LOG:9)
Block(3,26,6,LOG:9)
Block(3,26,7,LOG:9)
Block(3,26,8,LOG:1)
Block(3,27,-2,LOG:1)
Block(3,27,0,LOG:1)
Block(3,27,4,LOG:1)
Block(3,27,8,LOG:1)
Block(3,28,-2,LOG:1)
Block(3,28,0,LOG:1)
Block(3,28,4,LOG:1)
Block(3,28,8,LOG:1)
Block(3,29,-2,LOG:1)
Block(3,29,0,LOG:1)
Block(3,29,1,LOG:9)
Block(3,29,2,LOG:9)
Block(3,29,3,LOG:9)
Block(3,29,4,LOG:1)
Block(3,29,8,LOG:1)
Block(3,30,-2,LOG:1)
Block(3,30,-1,LOG:9)
Block(3,30,0,LOG:1)
Block(3,30,4,LOG:1)
Block(3,30,5,LOG:9)
Block(3,30,6,LOG:9)
Block(3,30,7,LOG:9)
Block(3,30,8,LOG:1)
Block(3,31,-2,LOG:1)
Block(3,31,0,LOG:1)
Block(3,31,4,LOG:1)
Block(3,31,8,LOG:1)
Block(3,32,-2,LOG:1)
Block(3,32,0,LOG:1)
Block(3,32,4,LOG:1)
Block(3,32,8,LOG:1)
Block(3,33,-2,LOG:1)
Block(3,33,0,LOG:1)
Block(3,33,1,LOG:9)
Block(3,33,2,LOG:9)
Block(3,33,3,LOG:9)
Block(3,33,4,LOG:1)
Block(3,33,8,LOG:1)
Block(3,34,-2,LOG:1)
Block(3,34,-1,LOG:9)
Block(3,34,0,LOG:1)
Block(3,34,4,LOG:1)
Block(3,34,5,LOG:9)
Block(3,34,6,LOG:9)
Block(3,34,7,LOG:9)
Block(3,34,8,LOG:1)
Block(3,35,-2,LOG:1)
Block(3,35,0,LOG:1)
Block(3,35,4,LOG:1)
Block(3,35,8,LOG:1)
Block(3,36,-2,LOG:1)
Block(3,36,0,LOG:1)
Block(3,36,4,LOG:1)
Block(3,36,8,LOG:1)
Block(3,37,-2,LOG:1)
Block(3,37,0,LOG:1)
Block(3,37,1,LOG:9)
Block(3,37,2,LOG:9)
Block(3,37,3,LOG:9)
Block(3,37,4,LOG:1)
Block(3,37,8,LOG:1)
Block(3,38,-2,LOG:1)
Block(3,38,-1,LOG:9)
Block(3,38,0,LOG:1)
Block(3,38,4,LOG:1)
Block(3,38,5,LOG:9)
Block(3,38,6,LOG:9)
Block(3,38,7,LOG:9)
Block(3,38,8,LOG:1)
Block(3,39,-2,LOG:1)
Block(3,39,0,LOG:1)
Block(3,39,4,LOG:1)
Block(3,39,8,LOG:1)
Block(3,40,-2,LOG:1)
Block(3,40,0,LOG:1)
Block(3,40,4,LOG:1)
Block(3,40,8,LOG:1)
Block(3,41,-2,LOG:1)
Block(3,41,0,LOG:1)
Block(3,41,1,LOG:9)
Block(3,41,2,LOG:9)
Block(3,41,3,LOG:9)
Block(3,41,4,LOG:1)
Block(3,41,8,LOG:1)
Block(3,42,-2,LOG:1)
Block(3,42,-1,LOG:9)
Block(3,42,0,LOG:1)
Block(3,42,4,LOG:1)
Block(3,42,5,LOG:9)
Block(3,42,6,LOG:9)
Block(3,42,7,LOG:9)
Block(3,42,8,LOG:1)
Block(3,43,-2,LOG:1)
Block(3,43,0,LOG:1)
Block(3,43,4,LOG:1)
Block(3,43,8,LOG:1)
Block(3,44,-2,LOG:1)
Block(3,44,0,LOG:1)
Block(3,44,4,LOG:1)
Block(3,44,8,LOG:1)
Block(3,45,-2,LOG:1)
Block(3,45,0,LOG:1)
Block(3,45,1,LOG:9)
Block(3,45,2,LOG:9)
Block(3,45,3,LOG:9)
Block(3,45,4,LOG:1)
Block(3,45,8,LOG:1)
Block(3,46,-2,LOG:1)
Block(3,46,-1,LOG:9)
Block(3,46,0,LOG:1)
Block(3,46,4,LOG:1)
Block(3,46,5,LOG:9)
Block(3,46,6,LOG:9)
Block(3,46,7,LOG:9)
Block(3,46,8,LOG:1)
Block(3,47,-2,LOG:1)
Block(3,47,0,LOG:1)
Block(3,47,4,LOG:1)
Block(3,47,8,LOG:1)
Block(3,48,-2,LOG:1)
Block(3,48,0,LOG:1)
Block(3,48,4,LOG:1)
Block(3,48,8,LOG:1)
Block(3,49,-2,LOG:1)
Block(3,49,0,LOG:1)
Block(3,49,4,LOG:1)
Block(3,49,8,LOG:1)
Block(3,50,-2,LOG:1)
Block(3,50,-1,LOG:9)
Block(3,50,0,LOG:1)
Block(3,50,1,LOG:9)
Block(3,50,2,LOG:9)
Block(3,50,3,LOG:9)
Block(3,50,4,LOG:1)
Block(3,50,5,LOG:9)
Block(3,50,6,LOG:9)
Block(3,50,7,LOG:9)
Block(3,50,8,LOG:1)
Block(3,51,-2,LOG:1)
Block(3,51,-1,SPRUCE_FENCE:0)
Block(3,51,0,LOG:1)
Block(3,51,4,LOG:1)
Block(3,51,8,LOG:1)
Block(3,52,-2,STEP:0)
Block(3,52,0,LOG:1)
Block(3,52,4,LOG:1)
Block(3,52,8,LOG:1)
Block(3,53,0,LOG:1)
Block(3,53,4,LOG:1)
Block(3,53,8,LOG:1)
Block(3,54,0,LOG:1)
Block(3,54,1,LOG:9)
Block(3,54,2,LOG:9)
Block(3,54,3,LOG:9)
Block(3,54,4,LOG:1)
Block(3,54,5,LOG:9)
Block(3,54,6,LOG:9)
Block(3,54,7,LOG:9)
Block(3,54,8,LOG:1)
Block(3,55,0,LOG:1)
Block(3,55,1,SPRUCE_FENCE:0)
Block(3,55,3,SPRUCE_FENCE:0)
Block(3,55,4,LOG:1)
Block(3,55,5,SPRUCE_FENCE:0)
Block(3,55,7,SPRUCE_FENCE:0)
Block(3,55,8,LOG:1)
Block(3,56,0,STEP:0)
Block(3,56,4,STEP:0)
Block(3,56,8,STEP:0)
Block(4,2,-2,LOG:5)
Block(4,2,0,LOG:5)
Block(4,2,4,LOG:5)
Block(4,6,-2,LOG:5)
Block(4,6,0,LOG:5)
Block(4,6,4,LOG:5)
Block(4,10,-2,LOG:5)
Block(4,10,0,LOG:5)
Block(4,10,4,LOG:5)
Block(4,14,-2,LOG:5)
Block(4,14,0,LOG:5)
Block(4,14,4,LOG:5)
Block(4,18,-2,LOG:5)
Block(4,18,0,LOG:5)
Block(4,18,4,LOG:5)
Block(4,22,-2,LOG:5)
Block(4,22,0,LOG:5)
Block(4,22,4,LOG:5)
Block(4,26,-2,LOG:5)
Block(4,26,0,LOG:5)
Block(4,26,4,LOG:5)
Block(4,30,-2,LOG:5)
Block(4,30,0,LOG:5)
Block(4,30,4,LOG:5)
Block(4,34,-2,LOG:5)
Block(4,34,0,LOG:5)
Block(4,34,4,LOG:5)
Block(4,38,-2,LOG:5)
Block(4,38,0,LOG:5)
Block(4,38,4,LOG:5)
Block(4,42,-2,LOG:5)
Block(4,42,0,LOG:5)
Block(4,42,4,LOG:5)
Block(4,46,-2,LOG:5)
Block(4,46,0,LOG:5)
Block(4,46,4,LOG:5)
Block(4,50,-3,WOOD_BUTTON:4)
Block(4,50,-2,LOG:5)
Block(4,50,-1,WOOD_STEP:8)
Block(4,50,0,LOG:5)
Block(4,50,1,WOOD_STEP:8)
Block(4,50,2,WOOD_STEP:8)
Block(4,50,3,WOOD_STEP:8)
Block(4,50,4,LOG:5)
Block(4,50,5,WOOD_STEP:8)
Block(4,50,6,WOOD_STEP:8)
Block(4,50,7,WOOD_STEP:8)
Block(4,50,8,LOG:5)
Block(4,51,-2,SPRUCE_FENCE:0)
Block(4,54,0,LOG:5)
Block(4,54,1,WOOD_STEP:8)
Block(4,54,2,WOOD_STEP:8)
Block(4,54,3,WOOD_STEP:8)
Block(4,54,4,LOG:5)
Block(4,54,5,WOOD_STEP:8)
Block(4,54,6,WOOD_STEP:8)
Block(4,54,7,WOOD_STEP:8)
Block(4,54,8,LOG:5)
Block(4,55,8,SPRUCE_FENCE:0)
Block(4,59,0,WALL_BANNER:4,../../Banners/dearoc_banner.nbt)
Block(4,59,4,WALL_BANNER:4,../../Banners/dearoc_banner.nbt)
Block(5,2,-2,LOG:5)
Block(5,2,0,LOG:5)
Block(5,2,4,LOG:5)
Block(5,6,-2,LOG:5)
Block(5,6,0,LOG:5)
Block(5,6,4,LOG:5)
Block(5,10,-2,LOG:5)
Block(5,10,0,LOG:5)
Block(5,10,4,LOG:5)
Block(5,14,-2,LOG:5)
Block(5,14,0,LOG:5)
Block(5,14,4,LOG:5)
Block(5,18,-2,LOG:5)
Block(5,18,0,LOG:5)
Block(5,18,4,LOG:5)
Block(5,22,-2,LOG:5)
Block(5,22,0,LOG:5)
Block(5,22,4,LOG:5)
Block(5,26,-2,LOG:5)
Block(5,26,0,LOG:5)
Block(5,26,4,LOG:5)
Block(5,30,-2,LOG:5)
Block(5,30,0,LOG:5)
Block(5,30,4,LOG:5)
Block(5,34,-2,LOG:5)
Block(5,34,0,LOG:5)
Block(5,34,4,LOG:5)
Block(5,38,-2,LOG:5)
Block(5,38,0,LOG:5)
Block(5,38,4,LOG:5)
Block(5,42,-2,LOG:5)
Block(5,42,0,LOG:5)
Block(5,42,4,LOG:5)
Block(5,46,-2,LOG:5)
Block(5,46,0,LOG:5)
Block(5,46,4,LOG:5)
Block(5,50,-3,WOOD_BUTTON:4)
Block(5,50,-2,LOG:5)
Block(5,50,-1,WOOD_STEP:8)
Block(5,50,0,LOG:5)
Block(5,50,1,WOOD_STEP:8)
Block(5,50,2,WOOD_STEP:8)
Block(5,50,3,WOOD_STEP:8)
Block(5,50,4,LOG:5)
Block(5,50,5,WOOD_STEP:8)
Block(5,50,6,WOOD_STEP:8)
Block(5,50,7,WOOD_STEP:8)
Block(5,50,8,LOG:5)
Block(5,51,-2,SPRUCE_FENCE:0)
Block(5,54,0,LOG:5)
Block(5,54,1,WOOD_STEP:8)
Block(5,54,2,WOOD_STEP:8)
Block(5,54,3,WOOD_STEP:8)
Block(5,54,4,LOG:5)
Block(5,54,5,WOOD_STEP:8)
Block(5,54,6,WOOD_STEP:8)
Block(5,54,7,WOOD_STEP:8)
Block(5,54,8,LOG:5)
Block(5,55,0,LOG:1)
Block(5,55,4,LOG:1)
Block(5,55,8,SPRUCE_FENCE:0)
Block(5,56,0,LOG:1)
Block(5,56,4,LOG:1)
Block(5,57,0,LOG:1)
Block(5,57,4,LOG:1)
Block(5,58,0,LOG:1)
Block(5,58,4,LOG:1)
Block(5,59,0,LOG:1)
Block(5,59,4,LOG:1)
Block(5,59,6,SPRUCE_FENCE:0)
Block(5,60,0,SMOOTH_STAIRS:0)
Block(5,60,4,SMOOTH_STAIRS:0)
Block(5,60,6,TORCH:5)
Block(6,2,-2,LOG:5)
Block(6,2,0,LOG:5)
Block(6,2,4,LOG:5)
Block(6,6,-2,LOG:5)
Block(6,6,0,LOG:5)
Block(6,6,4,LOG:5)
Block(6,10,-2,LOG:5)
Block(6,10,0,LOG:5)
Block(6,10,4,LOG:5)
Block(6,14,-2,LOG:5)
Block(6,14,0,LOG:5)
Block(6,14,4,LOG:5)
Block(6,18,-2,LOG:5)
Block(6,18,0,LOG:5)
Block(6,18,4,LOG:5)
Block(6,22,-2,LOG:5)
Block(6,22,0,LOG:5)
Block(6,22,4,LOG:5)
Block(6,26,-2,LOG:5)
Block(6,26,0,LOG:5)
Block(6,26,4,LOG:5)
Block(6,30,-2,LOG:5)
Block(6,30,0,LOG:5)
Block(6,30,4,LOG:5)
Block(6,34,-2,LOG:5)
Block(6,34,0,LOG:5)
Block(6,34,4,LOG:5)
Block(6,38,-2,LOG:5)
Block(6,38,0,LOG:5)
Block(6,38,4,LOG:5)
Block(6,42,-2,LOG:5)
Block(6,42,0,LOG:5)
Block(6,42,4,LOG:5)
Block(6,46,-2,LOG:5)
Block(6,46,0,LOG:5)
Block(6,46,4,LOG:5)
Block(6,50,-3,WOOD_BUTTON:4)
Block(6,50,-2,LOG:5)
Block(6,50,-1,WOOD_STEP:8)
Block(6,50,0,LOG:5)
Block(6,50,1,WOOD_STEP:8)
Block(6,50,2,WOOD_STEP:8)
Block(6,50,3,WOOD_STEP:8)
Block(6,50,4,LOG:5)
Block(6,50,5,WOOD_STEP:8)
Block(6,50,6,WOOD_STEP:8)
Block(6,50,7,WOOD_STEP:8)
Block(6,50,8,LOG:5)
Block(6,51,-2,SPRUCE_FENCE:0)
Block(6,51,-1,WOOD_STAIRS:0)
Block(6,51,1,WOOD_STAIRS:0)
Block(6,51,2,WOOD_STAIRS:0)
Block(6,51,3,WOOD_STAIRS:0)
Block(6,51,8,DARK_OAK_FENCE:0)
Block(6,52,8,TORCH:5)
Block(6,54,0,LOG:5)
Block(6,54,1,WOOD_STEP:8)
Block(6,54,2,WOOD_STEP:8)
Block(6,54,3,WOOD_STEP:8)
Block(6,54,4,LOG:5)
Block(6,54,5,WOOD_STEP:8)
Block(6,54,6,WOOD_STEP:8)
Block(6,54,7,WOOD_STEP:8)
Block(6,54,8,LOG:5)
Block(6,55,8,LOG:1)
Block(6,56,8,STEP:0)
Block(6,57,0,SPRUCE_WOOD_STAIRS:4)
Block(6,57,1,WOOD_STEP:9)
Block(6,57,2,WOOD_STEP:9)
Block(6,57,3,WOOD_STEP:9)
Block(6,57,4,SPRUCE_WOOD_STAIRS:4)
Block(6,57,5,WOOD_STEP:9)
Block(6,57,6,WOOD_STEP:9)
Block(6,57,7,WOOD_STEP:9)
Block(6,57,8,SPRUCE_WOOD_STAIRS:4)
Block(6,58,0,SPRUCE_FENCE:0)
Block(6,58,1,SPRUCE_FENCE:0)
Block(6,58,2,SPRUCE_FENCE:0)
Block(6,58,3,SPRUCE_FENCE:0)
Block(6,58,4,SPRUCE_FENCE:0)
Block(6,58,5,SPRUCE_FENCE:0)
Block(6,58,6,SPRUCE_FENCE:0)
Block(6,58,7,SPRUCE_FENCE:0)
Block(6,58,8,LOG:1)
Block(6,59,6,SPRUCE_FENCE:0)
Block(6,59,8,STEP:0)
Block(6,60,0,LOG:5)
Block(6,60,4,LOG:5)
Block(6,64,0,DARK_OAK_FENCE:0)
Block(6,64,4,DARK_OAK_FENCE:0)
Block(6,65,0,DARK_OAK_FENCE:0)
Block(6,65,1,DARK_OAK_FENCE:0)
Block(6,65,2,SPRUCE_WOOD_STAIRS:4)
Block(6,65,3,DARK_OAK_FENCE:0)
Block(6,65,4,DARK_OAK_FENCE:0)
Block(6,66,0,COBBLE_WALL:0)
Block(6,66,1,SPRUCE_WOOD_STAIRS:6)
Block(6,66,2,LOG:1)
Block(6,66,3,SPRUCE_WOOD_STAIRS:7)
Block(6,66,4,COBBLE_WALL:0)
Block(6,67,0,COBBLE_WALL:0)
Block(6,67,1,WOOD_STEP:0)
Block(6,67,2,SMOOTH_STAIRS:0)
Block(6,67,3,WOOD_STEP:0)
Block(6,67,4,COBBLE_WALL:0)
Block(6,68,0,COBBLE_WALL:0)
Block(6,68,1,STEP:0)
Block(6,68,2,SMOOTH_STAIRS:4)
Block(6,68,3,STEP:0)
Block(6,68,4,COBBLE_WALL:0)
Block(7,0,-2,LOG:1)
Block(7,0,0,LOG:1)
Block(7,0,4,LOG:1)
Block(7,0,8,LOG:1)
Block(7,1,-2,LOG:1)
Block(7,1,0,LOG:1)
Block(7,1,4,LOG:1)
Block(7,1,8,LOG:1)
Block(7,2,-2,LOG:1)
Block(7,2,-1,LOG:9)
Block(7,2,0,LOG:1)
Block(7,2,4,LOG:1)
Block(7,2,5,LOG:9)
Block(7,2,6,LOG:9)
Block(7,2,7,LOG:9)
Block(7,2,8,LOG:1)
Block(7,3,-2,LOG:1)
Block(7,3,0,LOG:1)
Block(7,3,4,LOG:1)
Block(7,3,8,LOG:1)
Block(7,4,-2,LOG:1)
Block(7,4,0,LOG:1)
Block(7,4,4,LOG:1)
Block(7,4,8,LOG:1)
Block(7,5,-2,LOG:1)
Block(7,5,0,LOG:1)
Block(7,5,4,LOG:1)
Block(7,5,8,LOG:1)
Block(7,6,-2,LOG:1)
Block(7,6,-1,LOG:9)
Block(7,6,0,LOG:1)
Block(7,6,4,LOG:1)
Block(7,6,5,LOG:9)
Block(7,6,6,LOG:9)
Block(7,6,7,LOG:9)
Block(7,6,8,LOG:1)
Block(7,7,-2,LOG:1)
Block(7,7,0,LOG:1)
Block(7,7,4,LOG:1)
Block(7,7,8,LOG:1)
Block(7,8,-2,LOG:1)
Block(7,8,0,LOG:1)
Block(7,8,4,LOG:1)
Block(7,8,8,LOG:1)
Block(7,9,-2,LOG:1)
Block(7,9,0,LOG:1)
Block(7,9,4,LOG:1)
Block(7,9,8,LOG:1)
Block(7,10,-2,LOG:1)
Block(7,10,-1,LOG:9)
Block(7,10,0,LOG:1)
Block(7,10,4,LOG:1)
Block(7,10,5,LOG:9)
Block(7,10,6,LOG:9)
Block(7,10,7,LOG:9)
Block(7,10,8,LOG:1)
Block(7,11,-2,LOG:1)
Block(7,11,0,LOG:1)
Block(7,11,4,LOG:1)
Block(7,11,8,LOG:1)
Block(7,12,-2,LOG:1)
Block(7,12,0,LOG:1)
Block(7,12,4,LOG:1)
Block(7,12,8,LOG:1)
Block(7,13,-2,LOG:1)
Block(7,13,0,LOG:1)
Block(7,13,4,LOG:1)
Block(7,13,8,LOG:1)
Block(7,14,-2,LOG:1)
Block(7,14,-1,LOG:9)
Block(7,14,0,LOG:1)
Block(7,14,4,LOG:1)
Block(7,14,5,LOG:9)
Block(7,14,6,LOG:9)
Block(7,14,7,LOG:9)
Block(7,14,8,LOG:1)
Block(7,15,-2,LOG:1)
Block(7,15,0,LOG:1)
Block(7,15,4,LOG:1)
Block(7,15,8,LOG:1)
Block(7,16,-2,LOG:1)
Block(7,16,0,LOG:1)
Block(7,16,4,LOG:1)
Block(7,16,8,LOG:1)
Block(7,17,-2,LOG:1)
Block(7,17,0,LOG:1)
Block(7,17,4,LOG:1)
Block(7,17,8,LOG:1)
Block(7,18,-2,LOG:1)
Block(7,18,-1,LOG:9)
Block(7,18,0,LOG:1)
Block(7,18,4,LOG:1)
Block(7,18,5,LOG:9)
Block(7,18,6,LOG:9)
Block(7,18,7,LOG:9)
Block(7,18,8,LOG:1)
Block(7,19,-2,LOG:1)
Block(7,19,0,LOG:1)
Block(7,19,4,LOG:1)
Block(7,19,8,LOG:1)
Block(7,20,-2,LOG:1)
Block(7,20,0,LOG:1)
Block(7,20,4,LOG:1)
Block(7,20,8,LOG:1)
Block(7,21,-2,LOG:1)
Block(7,21,0,LOG:1)
Block(7,21,4,LOG:1)
Block(7,21,8,LOG:1)
Block(7,22,-2,LOG:1)
Block(7,22,-1,LOG:9)
Block(7,22,0,LOG:1)
Block(7,22,4,LOG:1)
Block(7,22,5,LOG:9)
Block(7,22,6,LOG:9)
Block(7,22,7,LOG:9)
Block(7,22,8,LOG:1)
Block(7,23,-2,LOG:1)
Block(7,23,0,LOG:1)
Block(7,23,4,LOG:1)
Block(7,23,8,LOG:1)
Block(7,24,-2,LOG:1)
Block(7,24,0,LOG:1)
Block(7,24,4,LOG:1)
Block(7,24,8,LOG:1)
Block(7,25,-2,LOG:1)
Block(7,25,0,LOG:1)
Block(7,25,4,LOG:1)
Block(7,25,8,LOG:1)
Block(7,26,-2,LOG:1)
Block(7,26,-1,LOG:9)
Block(7,26,0,LOG:1)
Block(7,26,4,LOG:1)
Block(7,26,5,LOG:9)
Block(7,26,6,LOG:9)
Block(7,26,7,LOG:9)
Block(7,26,8,LOG:1)
Block(7,27,-2,LOG:1)
Block(7,27,0,LOG:1)
Block(7,27,4,LOG:1)
Block(7,27,8,LOG:1)
Block(7,28,-2,LOG:1)
Block(7,28,0,LOG:1)
Block(7,28,4,LOG:1)
Block(7,28,8,LOG:1)
Block(7,29,-2,LOG:1)
Block(7,29,0,LOG:1)
Block(7,29,4,LOG:1)
Block(7,29,8,LOG:1)
Block(7,30,-2,LOG:1)
Block(7,30,-1,LOG:9)
Block(7,30,0,LOG:1)
Block(7,30,4,LOG:1)
Block(7,30,5,LOG:9)
Block(7,30,6,LOG:9)
Block(7,30,7,LOG:9)
Block(7,30,8,LOG:1)
Block(7,31,-2,LOG:1)
Block(7,31,0,LOG:1)
Block(7,31,4,LOG:1)
Block(7,31,8,LOG:1)
Block(7,32,-2,LOG:1)
Block(7,32,0,LOG:1)
Block(7,32,4,LOG:1)
Block(7,32,8,LOG:1)
Block(7,33,-2,LOG:1)
Block(7,33,0,LOG:1)
Block(7,33,4,LOG:1)
Block(7,33,8,LOG:1)
Block(7,34,-2,LOG:1)
Block(7,34,-1,LOG:9)
Block(7,34,0,LOG:1)
Block(7,34,4,LOG:1)
Block(7,34,5,LOG:9)
Block(7,34,6,LOG:9)
Block(7,34,7,LOG:9)
Block(7,34,8,LOG:1)
Block(7,35,-2,LOG:1)
Block(7,35,0,LOG:1)
Block(7,35,4,LOG:1)
Block(7,35,8,LOG:1)
Block(7,36,-2,LOG:1)
Block(7,36,0,LOG:1)
Block(7,36,4,LOG:1)
Block(7,36,8,LOG:1)
Block(7,37,-2,LOG:1)
Block(7,37,0,LOG:1)
Block(7,37,4,LOG:1)
Block(7,37,8,LOG:1)
Block(7,38,-2,LOG:1)
Block(7,38,-1,LOG:9)
Block(7,38,0,LOG:1)
Block(7,38,4,LOG:1)
Block(7,38,5,LOG:9)
Block(7,38,6,LOG:9)
Block(7,38,7,LOG:9)
Block(7,38,8,LOG:1)
Block(7,39,-2,LOG:1)
Block(7,39,0,LOG:1)
Block(7,39,4,LOG:1)
Block(7,39,8,LOG:1)
Block(7,40,-2,LOG:1)
Block(7,40,0,LOG:1)
Block(7,40,4,LOG:1)
Block(7,40,8,LOG:1)
Block(7,41,-2,LOG:1)
Block(7,41,0,LOG:1)
Block(7,41,4,LOG:1)
Block(7,41,8,LOG:1)
Block(7,42,-2,LOG:1)
Block(7,42,-1,LOG:9)
Block(7,42,0,LOG:1)
Block(7,42,4,LOG:1)
Block(7,42,5,LOG:9)
Block(7,42,6,LOG:9)
Block(7,42,7,LOG:9)
Block(7,42,8,LOG:1)
Block(7,43,-2,LOG:1)
Block(7,43,0,LOG:1)
Block(7,43,4,LOG:1)
Block(7,43,8,LOG:1)
Block(7,44,-2,LOG:1)
Block(7,44,0,LOG:1)
Block(7,44,4,LOG:1)
Block(7,44,8,LOG:1)
Block(7,45,-2,LOG:1)
Block(7,45,0,LOG:1)
Block(7,45,4,LOG:1)
Block(7,45,8,LOG:1)
Block(7,46,-2,LOG:1)
Block(7,46,-1,LOG:9)
Block(7,46,0,LOG:1)
Block(7,46,4,LOG:1)
Block(7,46,5,LOG:9)
Block(7,46,6,LOG:9)
Block(7,46,7,LOG:9)
Block(7,46,8,LOG:1)
Block(7,47,-2,LOG:1)
Block(7,47,0,LOG:1)
Block(7,47,4,LOG:1)
Block(7,47,8,LOG:1)
Block(7,48,-2,LOG:1)
Block(7,48,0,LOG:1)
Block(7,48,4,LOG:1)
Block(7,48,8,LOG:1)
Block(7,49,-2,LOG:1)
Block(7,49,0,LOG:1)
Block(7,49,4,LOG:1)
Block(7,49,8,LOG:1)
Block(7,50,-2,LOG:1)
Block(7,50,0,LOG:1)
Block(7,50,1,WOOD_STEP:8)
Block(7,50,2,WOOD_STEP:8)
Block(7,50,3,WOOD_STEP:8)
Block(7,50,4,LOG:1)
Block(7,50,5,WOOD_STEP:8)
Block(7,50,6,WOOD_STEP:8)
Block(7,50,7,WOOD_STEP:8)
Block(7,50,8,LOG:1)
Block(7,51,-2,LOG:1)
Block(7,51,-1,LOG:9)
Block(7,51,0,LOG:1)
Block(7,51,1,LOG:9)
Block(7,51,2,LOG:9)
Block(7,51,3,LOG:9)
Block(7,51,4,LOG:1)
Block(7,51,5,LOG:9)
Block(7,51,6,LOG:9)
Block(7,51,7,LOG:9)
Block(7,51,8,LOG:1)
Block(7,52,-2,LOG:1)
Block(7,52,-1,WOOD_STAIRS:0)
Block(7,52,0,LOG:1)
Block(7,52,4,LOG:1)
Block(7,52,5,COBBLESTONE:0)
Block(7,52,6,COBBLESTONE:0)
Block(7,52,7,COBBLESTONE:0)
Block(7,52,8,LOG:1)
Block(7,53,-2,LOG:1)
Block(7,53,0,LOG:1)
Block(7,53,4,LOG:1)
Block(7,53,5,WOOD:1)
Block(7,53,6,WOOD:1)
Block(7,53,7,WOOD:1)
Block(7,53,8,LOG:1)
Block(7,54,-2,LOG:1)
Block(7,54,0,LOG:1)
Block(7,54,1,WOOD_STEP:8)
Block(7,54,2,WOOD_STEP:8)
Block(7,54,3,WOOD_STEP:8)
Block(7,54,4,LOG:1)
Block(7,54,5,LOG:9)
Block(7,54,6,LOG:9)
Block(7,54,7,LOG:9)
Block(7,54,8,LOG:1)
Block(7,55,-2,LOG:1)
Block(7,55,0,LOG:1)
Block(7,55,4,LOG:1)
Block(7,55,5,COBBLESTONE:0)
Block(7,55,6,COBBLESTONE:0)
Block(7,55,7,COBBLESTONE:0)
Block(7,55,8,LOG:1)
Block(7,56,-2,SMOOTH_STAIRS:2)
Block(7,56,-1,LOG:9)
Block(7,56,0,LOG:1)
Block(7,56,4,LOG:1)
Block(7,56,5,WOOD:1)
Block(7,56,6,DARK_OAK_FENCE:0)
Block(7,56,7,WOOD:1)
Block(7,56,8,LOG:1)
Block(7,57,-1,SPRUCE_WOOD_STAIRS:6)
Block(7,57,0,LOG:1)
Block(7,57,1,LOG:9)
Block(7,57,2,LOG:9)
Block(7,57,3,LOG:9)
Block(7,57,4,LOG:1)
Block(7,57,5,LOG:9)
Block(7,57,6,LOG:9)
Block(7,57,7,LOG:9)
Block(7,57,8,LOG:1)
Block(7,58,-1,LOG:1)
Block(7,58,0,LOG:1)
Block(7,58,1,COBBLESTONE:0)
Block(7,58,2,COBBLESTONE:0)
Block(7,58,3,COBBLESTONE:0)
Block(7,58,4,LOG:1)
Block(7,58,6,LOG:1)
Block(7,59,-1,STEP:0)
Block(7,59,0,LOG:1)
Block(7,59,1,WOOD:1)
Block(7,59,3,WOOD:1)
Block(7,59,4,LOG:1)
Block(7,59,6,LOG:1)
Block(7,60,0,LOG:1)
Block(7,60,1,LOG:9)
Block(7,60,2,LOG:9)
Block(7,60,3,LOG:9)
Block(7,60,4,LOG:1)
Block(7,60,5,LOG:9)
Block(7,60,6,SMOOTH_STAIRS:3)
Block(7,61,0,COBBLE_WALL:0)
Block(7,61,1,WOOD_STAIRS:0)
Block(7,61,2,LOG:1)
Block(7,61,3,WOOD_STAIRS:0)
Block(7,61,4,COBBLE_WALL:0)
Block(7,62,0,COBBLE_WALL:0)
Block(7,62,1,WOOD_STAIRS:4)
Block(7,62,2,LOG:1)
Block(7,62,3,WOOD_STAIRS:4)
Block(7,62,4,COBBLE_WALL:0)
Block(7,63,0,COBBLE_WALL:0)
Block(7,63,1,LOG:9)
Block(7,63,2,LOG:9)
Block(7,63,3,LOG:9)
Block(7,63,4,COBBLE_WALL:0)
Block(7,64,-1,DARK_OAK_FENCE:0)
Block(7,64,0,LOG:1)
Block(7,64,1,WOOD_DOUBLE_STEP:0)
Block(7,64,2,WOOD:1)
Block(7,64,3,WOOD_DOUBLE_STEP:0)
Block(7,64,4,LOG:1)
Block(7,64,5,DARK_OAK_FENCE:0)
Block(7,65,-1,DARK_OAK_FENCE:0)
Block(7,65,0,LOG:1)
Block(7,65,1,WOOD_DOUBLE_STEP:0)
Block(7,65,2,WOOD:1)
Block(7,65,3,WOOD_DOUBLE_STEP:0)
Block(7,65,4,LOG:1)
Block(7,65,5,DARK_OAK_FENCE:0)
Block(7,66,-1,COBBLE_WALL:0)
Block(7,66,0,LOG:1)
Block(7,66,1,LOG:9)
Block(7,66,2,LOG:9)
Block(7,66,3,LOG:9)
Block(7,66,4,LOG:1)
Block(7,66,5,COBBLE_WALL:0)
Block(7,67,-1,COBBLE_WALL:0)
Block(7,67,0,COBBLESTONE:0)
Block(7,67,1,DOUBLE_STEP:0)
Block(7,67,2,DOUBLE_STEP:0)
Block(7,67,3,DOUBLE_STEP:0)
Block(7,67,4,COBBLESTONE:0)
Block(7,67,5,COBBLE_WALL:0)
Block(7,68,-1,COBBLE_WALL:0)
Block(7,68,0,DOUBLE_STEP:0)
Block(7,68,4,DOUBLE_STEP:0)
Block(7,68,5,COBBLE_WALL:0)
Branch(16,0,0,true,HarborC1R2,NORTH,100.0,0)
