
#######################################################################
# +-----------------------------------------------------------------+ #
# |                            BO4 object                           | #
# +-----------------------------------------------------------------+ #
#######################################################################

Author: NLBlackEagle

Description: No description given

SettingsMode: WriteDisable


#######################################################################
# +-----------------------------------------------------------------+ #
# |                          Main settings                          | #
# +-----------------------------------------------------------------+ #
#######################################################################

Frequency: 0

SpawnHeight: highestBlock

UseCenterForHighestBlock: true

##############################
# Height Limits for the BO4. #
##############################

MinHeight: 0

MaxHeight: 255

InheritBO3: 

InheritBO3Rotation: NORTH

OverrideChildSettings: true

OverrideParentHeight: false

CanOverride: false

BranchFrequency: 0

BranchFrequencyGroup: 

MustBeBelowOther: false

MustBeInside: 

CannotBeInside: 

ReplacesBO3: 

MustBeInsideWorldBorders: false

CanSpawnOnWater: true

SpawnOnWaterOnly: true

SpawnUnderWater: false

SpawnAtWaterLevel: false

HeightOffset: 0

RemoveAir: false

ReplaceAbove: 

ReplaceBelow: 

ReplaceWithBiomeBlocks: true

ReplaceWithSurfaceBlock: GRASS

ReplaceWithGroundBlock: DIRT

ReplaceWithStoneBlock: STONE

SmoothRadius: 0

SmoothHeightOffset: 0

SmoothStartTop: false

SmoothStartWood: false

SmoothingSurfaceBlock: 

SmoothingGroundBlock: 

BO3Group: 

IsSpawnPoint: false

DoReplaceBlocks: true


#######################################################################
# +-----------------------------------------------------------------+ #
# |                              Blocks                             | #
# +-----------------------------------------------------------------+ #
#######################################################################

Block(-8,2,1,LOG:5)
Block(-8,3,5,LOG:5)
Block(-8,6,1,LOG:5)
Block(-8,7,5,LOG:5)
Block(-8,10,1,LOG:5)
Block(-8,11,5,LOG:5)
Block(-8,14,1,LOG:5)
Block(-8,15,5,LOG:5)
Block(-8,18,1,LOG:5)
Block(-8,19,5,LOG:5)
Block(-8,22,1,LOG:5)
Block(-8,23,5,LOG:5)
Block(-8,26,1,LOG:5)
Block(-8,27,5,LOG:5)
Block(-8,30,1,LOG:5)
Block(-8,31,5,LOG:5)
Block(-8,34,1,LOG:5)
Block(-8,35,5,LOG:5)
Block(-8,38,1,LOG:5)
Block(-8,39,5,LOG:5)
Block(-8,42,1,LOG:5)
Block(-8,43,5,LOG:5)
Block(-8,46,1,LOG:5)
Block(-8,47,5,LOG:5)
Block(-8,48,5,LOG:5)
Block(-8,50,0,WOOD_BUTTON:4)
Block(-8,50,1,LOG:5)
Block(-8,50,5,LOG:5)
Block(-8,51,1,WOOD_STEP:5)
Block(-8,51,5,WOOD_STEP:5)
Block(-8,52,0,WOOD_STEP:13)
Block(-8,52,1,WOOD_STEP:8)
Block(-8,52,2,WOOD_STEP:8)
Block(-8,52,3,WOOD_STEP:8)
Block(-8,52,4,WOOD_STEP:8)
Block(-8,52,5,WOOD_STEP:8)
Block(-8,52,6,WOOD_STEP:13)
Block(-8,53,0,STEP:0)
Block(-8,53,1,LOG:5)
Block(-8,53,2,STEP:0)
Block(-8,53,3,STEP:0)
Block(-8,53,4,STEP:0)
Block(-8,53,5,LOG:5)
Block(-8,53,6,STEP:0)
Block(-8,54,1,SPRUCE_FENCE:0)
Block(-8,54,5,SPRUCE_FENCE:0)
Block(-8,54,8,WOOD_STEP:9)
Block(-8,55,8,SPRUCE_FENCE:0)
Block(-7,2,1,LOG:5)
Block(-7,3,5,LOG:5)
Block(-7,6,1,LOG:5)
Block(-7,7,5,LOG:5)
Block(-7,10,1,LOG:5)
Block(-7,11,5,LOG:5)
Block(-7,14,1,LOG:5)
Block(-7,15,5,LOG:5)
Block(-7,18,1,LOG:5)
Block(-7,19,5,LOG:5)
Block(-7,22,1,LOG:5)
Block(-7,23,5,LOG:5)
Block(-7,26,1,LOG:5)
Block(-7,27,5,LOG:5)
Block(-7,30,1,LOG:5)
Block(-7,31,5,LOG:5)
Block(-7,34,1,LOG:5)
Block(-7,35,5,LOG:5)
Block(-7,38,1,LOG:5)
Block(-7,39,5,LOG:5)
Block(-7,42,1,LOG:5)
Block(-7,43,5,LOG:5)
Block(-7,46,1,LOG:5)
Block(-7,47,5,LOG:5)
Block(-7,48,5,LOG:5)
Block(-7,50,0,WOOD_BUTTON:4)
Block(-7,50,1,LOG:5)
Block(-7,50,5,LOG:5)
Block(-7,51,1,WOOD_STEP:5)
Block(-7,51,5,WOOD_STEP:5)
Block(-7,52,0,WOOD_STEP:13)
Block(-7,52,6,WOOD_STEP:13)
Block(-7,53,0,STEP:0)
Block(-7,53,1,LOG:5)
Block(-7,53,2,STEP:0)
Block(-7,53,3,STEP:0)
Block(-7,53,4,STEP:0)
Block(-7,53,5,LOG:5)
Block(-7,53,6,STEP:0)
Block(-7,54,1,SPRUCE_FENCE:0)
Block(-7,54,5,SPRUCE_FENCE:0)
Block(-7,54,8,WOOD_STEP:9)
Block(-7,55,8,SPRUCE_FENCE:0)
Block(-6,2,1,LOG:5)
Block(-6,3,5,LOG:5)
Block(-6,6,1,LOG:5)
Block(-6,7,5,LOG:5)
Block(-6,10,1,LOG:5)
Block(-6,11,5,LOG:5)
Block(-6,14,1,LOG:5)
Block(-6,15,5,LOG:5)
Block(-6,18,1,LOG:5)
Block(-6,19,5,LOG:5)
Block(-6,22,1,LOG:5)
Block(-6,23,5,LOG:5)
Block(-6,26,1,LOG:5)
Block(-6,27,5,LOG:5)
Block(-6,30,1,LOG:5)
Block(-6,31,5,LOG:5)
Block(-6,34,1,LOG:5)
Block(-6,35,5,LOG:5)
Block(-6,38,1,LOG:5)
Block(-6,39,5,LOG:5)
Block(-6,42,1,LOG:5)
Block(-6,43,5,LOG:5)
Block(-6,46,1,LOG:5)
Block(-6,47,5,LOG:5)
Block(-6,48,5,LOG:5)
Block(-6,50,0,WOOD_BUTTON:4)
Block(-6,50,1,LOG:5)
Block(-6,50,5,LOG:5)
Block(-6,51,1,WOOD_STEP:5)
Block(-6,51,5,WOOD_STEP:5)
Block(-6,52,0,WOOD_STEP:13)
Block(-6,52,1,WOOD_STEP:8)
Block(-6,52,2,WOOD_STEP:8)
Block(-6,52,3,WOOD_STEP:8)
Block(-6,52,4,WOOD_STEP:8)
Block(-6,52,5,WOOD_STEP:8)
Block(-6,52,6,WOOD_STEP:13)
Block(-6,53,0,STEP:0)
Block(-6,53,1,LOG:5)
Block(-6,53,2,DOUBLE_STEP:0)
Block(-6,53,3,DOUBLE_STEP:0)
Block(-6,53,4,DOUBLE_STEP:0)
Block(-6,53,5,LOG:5)
Block(-6,53,6,STEP:0)
Block(-6,54,1,SPRUCE_FENCE:0)
Block(-6,54,5,SPRUCE_FENCE:0)
Block(-6,54,8,WOOD_STEP:9)
Block(-6,55,8,SPRUCE_FENCE:0)
Block(-5,0,0,STONE:6)
Block(-5,0,1,LOG:1)
Block(-5,0,5,LOG:1)
Block(-5,0,6,STONE:6)
Block(-5,1,0,STONE:6)
Block(-5,1,1,LOG:1)
Block(-5,1,2,LOG:9)
Block(-5,1,3,LOG:9)
Block(-5,1,4,LOG:9)
Block(-5,1,5,LOG:1)
Block(-5,1,6,STONE:6)
Block(-5,2,0,STONE:6)
Block(-5,2,1,LOG:1)
Block(-5,2,5,LOG:1)
Block(-5,2,6,STONE:6)
Block(-5,3,0,STONE:6)
Block(-5,3,1,LOG:1)
Block(-5,3,5,LOG:1)
Block(-5,3,6,STONE:6)
Block(-5,4,0,STONE:6)
Block(-5,4,1,LOG:1)
Block(-5,4,5,LOG:1)
Block(-5,4,6,STONE:6)
Block(-5,5,0,STONE:6)
Block(-5,5,1,LOG:1)
Block(-5,5,2,LOG:9)
Block(-5,5,3,LOG:9)
Block(-5,5,4,LOG:9)
Block(-5,5,5,LOG:1)
Block(-5,5,6,STONE:6)
Block(-5,6,0,STONE:6)
Block(-5,6,1,LOG:1)
Block(-5,6,5,LOG:1)
Block(-5,6,6,STONE:6)
Block(-5,7,0,STONE:6)
Block(-5,7,1,LOG:1)
Block(-5,7,5,LOG:1)
Block(-5,7,6,STONE:6)
Block(-5,8,0,STONE:6)
Block(-5,8,1,LOG:1)
Block(-5,8,5,LOG:1)
Block(-5,8,6,STONE:6)
Block(-5,9,0,STONE:6)
Block(-5,9,1,LOG:1)
Block(-5,9,2,LOG:9)
Block(-5,9,3,LOG:9)
Block(-5,9,4,LOG:9)
Block(-5,9,5,LOG:1)
Block(-5,9,6,STONE:6)
Block(-5,10,0,STONE:6)
Block(-5,10,1,LOG:1)
Block(-5,10,5,LOG:1)
Block(-5,10,6,STONE:6)
Block(-5,11,0,STONE:6)
Block(-5,11,1,LOG:1)
Block(-5,11,5,LOG:1)
Block(-5,11,6,STONE:6)
Block(-5,12,0,STONE:6)
Block(-5,12,1,LOG:1)
Block(-5,12,5,LOG:1)
Block(-5,12,6,STONE:6)
Block(-5,13,0,STONE:6)
Block(-5,13,1,LOG:1)
Block(-5,13,2,LOG:9)
Block(-5,13,3,LOG:9)
Block(-5,13,4,LOG:9)
Block(-5,13,5,LOG:1)
Block(-5,13,6,STONE:6)
Block(-5,14,0,STONE:6)
Block(-5,14,1,LOG:1)
Block(-5,14,5,LOG:1)
Block(-5,14,6,STONE:6)
Block(-5,15,0,STONE:6)
Block(-5,15,1,LOG:1)
Block(-5,15,5,LOG:1)
Block(-5,15,6,STONE:6)
Block(-5,16,0,STONE:6)
Block(-5,16,1,LOG:1)
Block(-5,16,5,LOG:1)
Block(-5,16,6,STONE:6)
Block(-5,17,0,STONE:6)
Block(-5,17,1,LOG:1)
Block(-5,17,2,LOG:9)
Block(-5,17,3,LOG:9)
Block(-5,17,4,LOG:9)
Block(-5,17,5,LOG:1)
Block(-5,17,6,STONE:6)
Block(-5,18,0,STONE:6)
Block(-5,18,1,LOG:1)
Block(-5,18,5,LOG:1)
Block(-5,18,6,STONE:6)
Block(-5,19,0,STONE:6)
Block(-5,19,1,LOG:1)
Block(-5,19,5,LOG:1)
Block(-5,19,6,STONE:6)
Block(-5,20,0,STONE:6)
Block(-5,20,1,LOG:1)
Block(-5,20,5,LOG:1)
Block(-5,20,6,STONE:6)
Block(-5,21,0,STONE:6)
Block(-5,21,1,LOG:1)
Block(-5,21,2,LOG:9)
Block(-5,21,3,LOG:9)
Block(-5,21,4,LOG:9)
Block(-5,21,5,LOG:1)
Block(-5,21,6,STONE:6)
Block(-5,22,0,STONE:6)
Block(-5,22,1,LOG:1)
Block(-5,22,5,LOG:1)
Block(-5,22,6,STONE:6)
Block(-5,23,0,STONE:6)
Block(-5,23,1,LOG:1)
Block(-5,23,5,LOG:1)
Block(-5,23,6,STONE:6)
Block(-5,24,0,STONE:6)
Block(-5,24,1,LOG:1)
Block(-5,24,5,LOG:1)
Block(-5,24,6,STONE:6)
Block(-5,25,0,STONE:6)
Block(-5,25,1,LOG:1)
Block(-5,25,2,LOG:9)
Block(-5,25,3,LOG:9)
Block(-5,25,4,LOG:9)
Block(-5,25,5,LOG:1)
Block(-5,25,6,STONE:6)
Block(-5,26,0,STONE:6)
Block(-5,26,1,LOG:1)
Block(-5,26,5,LOG:1)
Block(-5,26,6,STONE:6)
Block(-5,27,0,STONE:6)
Block(-5,27,1,LOG:1)
Block(-5,27,5,LOG:1)
Block(-5,27,6,STONE:6)
Block(-5,28,0,STONE:6)
Block(-5,28,1,LOG:1)
Block(-5,28,5,LOG:1)
Block(-5,28,6,STONE:6)
Block(-5,29,0,STONE:6)
Block(-5,29,1,LOG:1)
Block(-5,29,2,LOG:9)
Block(-5,29,3,LOG:9)
Block(-5,29,4,LOG:9)
Block(-5,29,5,LOG:1)
Block(-5,29,6,STONE:6)
Block(-5,30,0,STONE:6)
Block(-5,30,1,LOG:1)
Block(-5,30,5,LOG:1)
Block(-5,30,6,STONE:6)
Block(-5,31,0,STONE:6)
Block(-5,31,1,LOG:1)
Block(-5,31,5,LOG:1)
Block(-5,31,6,STONE:6)
Block(-5,32,0,STONE:6)
Block(-5,32,1,LOG:1)
Block(-5,32,5,LOG:1)
Block(-5,32,6,STONE:6)
Block(-5,33,0,STONE:6)
Block(-5,33,1,LOG:1)
Block(-5,33,2,LOG:9)
Block(-5,33,3,LOG:9)
Block(-5,33,4,LOG:9)
Block(-5,33,5,LOG:1)
Block(-5,33,6,STONE:6)
Block(-5,34,0,STONE:6)
Block(-5,34,1,LOG:1)
Block(-5,34,5,LOG:1)
Block(-5,34,6,STONE:6)
Block(-5,35,0,STONE:6)
Block(-5,35,1,LOG:1)
Block(-5,35,5,LOG:1)
Block(-5,35,6,STONE:6)
Block(-5,36,0,STONE:6)
Block(-5,36,1,LOG:1)
Block(-5,36,5,LOG:1)
Block(-5,36,6,STONE:6)
Block(-5,37,0,STONE:6)
Block(-5,37,1,LOG:1)
Block(-5,37,2,LOG:9)
Block(-5,37,3,LOG:9)
Block(-5,37,4,LOG:9)
Block(-5,37,5,LOG:1)
Block(-5,37,6,STONE:6)
Block(-5,38,0,STONE:6)
Block(-5,38,1,LOG:1)
Block(-5,38,5,LOG:1)
Block(-5,38,6,STONE:6)
Block(-5,39,0,STONE:6)
Block(-5,39,1,LOG:1)
Block(-5,39,5,LOG:1)
Block(-5,39,6,STONE:6)
Block(-5,40,0,STONE:6)
Block(-5,40,1,LOG:1)
Block(-5,40,5,LOG:1)
Block(-5,40,6,STONE:6)
Block(-5,41,0,STONE:6)
Block(-5,41,1,LOG:1)
Block(-5,41,2,LOG:9)
Block(-5,41,3,LOG:9)
Block(-5,41,4,LOG:9)
Block(-5,41,5,LOG:1)
Block(-5,41,6,STONE:6)
Block(-5,42,0,STONE:6)
Block(-5,42,1,LOG:1)
Block(-5,42,5,LOG:1)
Block(-5,42,6,STONE:6)
Block(-5,43,0,STONE:6)
Block(-5,43,1,LOG:1)
Block(-5,43,5,LOG:1)
Block(-5,43,6,STONE:6)
Block(-5,44,0,STONE:6)
Block(-5,44,1,LOG:1)
Block(-5,44,5,LOG:1)
Block(-5,44,6,STONE:6)
Block(-5,45,0,STONE:6)
Block(-5,45,1,LOG:1)
Block(-5,45,2,LOG:9)
Block(-5,45,3,LOG:9)
Block(-5,45,4,LOG:9)
Block(-5,45,5,LOG:1)
Block(-5,45,6,STONE:6)
Block(-5,46,0,STONE:6)
Block(-5,46,1,LOG:1)
Block(-5,46,5,LOG:1)
Block(-5,46,6,STONE:6)
Block(-5,47,0,STONE:6)
Block(-5,47,1,LOG:1)
Block(-5,47,5,LOG:1)
Block(-5,47,6,STONE:6)
Block(-5,48,0,STONE:6)
Block(-5,48,1,LOG:1)
Block(-5,48,5,LOG:1)
Block(-5,48,6,STONE:6)
Block(-5,49,0,STONE:6)
Block(-5,49,1,LOG:1)
Block(-5,49,5,LOG:1)
Block(-5,49,6,STONE:6)
Block(-5,50,0,STONE:6)
Block(-5,50,1,LOG:1)
Block(-5,50,5,LOG:1)
Block(-5,50,6,STONE:6)
Block(-5,51,0,STONE:6)
Block(-5,51,1,LOG:1)
Block(-5,51,2,LOG:9)
Block(-5,51,3,LOG:9)
Block(-5,51,4,LOG:9)
Block(-5,51,5,LOG:1)
Block(-5,51,6,STONE:6)
Block(-5,52,0,SMOOTH_STAIRS:2)
Block(-5,52,1,LOG:1)
Block(-5,52,2,WOOD_STEP:5)
Block(-5,52,3,WOOD_STEP:5)
Block(-5,52,4,WOOD_STEP:5)
Block(-5,52,5,LOG:1)
Block(-5,52,6,SMOOTH_STAIRS:3)
Block(-5,53,0,SMOOTH_STAIRS:6)
Block(-5,53,1,LOG:1)
Block(-5,53,5,LOG:1)
Block(-5,53,6,SMOOTH_STAIRS:7)
Block(-5,54,0,STONE:6)
Block(-5,54,1,LOG:1)
Block(-5,54,2,STEP:0)
Block(-5,54,3,STEP:0)
Block(-5,54,4,STEP:0)
Block(-5,54,5,LOG:1)
Block(-5,54,6,STONE:6)
Block(-5,54,8,WOOD_STEP:9)
Block(-5,55,0,SMOOTH_STAIRS:2)
Block(-5,55,1,SMOOTH_STAIRS:3)
Block(-5,55,5,SMOOTH_STAIRS:2)
Block(-5,55,6,SMOOTH_STAIRS:3)
Block(-5,55,8,SPRUCE_FENCE:0)
Block(-5,56,0,STEP:0)
Block(-5,56,1,STEP:0)
Block(-5,56,5,STEP:0)
Block(-5,56,6,STEP:0)
Block(-4,3,1,LOG:5)
Block(-4,3,5,LOG:5)
Block(-4,7,1,LOG:5)
Block(-4,7,5,LOG:5)
Block(-4,11,1,LOG:5)
Block(-4,11,5,LOG:5)
Block(-4,15,1,LOG:5)
Block(-4,15,5,LOG:5)
Block(-4,19,1,LOG:5)
Block(-4,19,5,LOG:5)
Block(-4,23,1,LOG:5)
Block(-4,23,5,LOG:5)
Block(-4,27,1,LOG:5)
Block(-4,27,5,LOG:5)
Block(-4,31,1,LOG:5)
Block(-4,31,5,LOG:5)
Block(-4,35,1,LOG:5)
Block(-4,35,5,LOG:5)
Block(-4,39,1,LOG:5)
Block(-4,39,5,LOG:5)
Block(-4,43,1,LOG:5)
Block(-4,43,5,LOG:5)
Block(-4,47,1,LOG:5)
Block(-4,47,5,LOG:5)
Block(-4,48,1,LOG:5)
Block(-4,48,5,LOG:5)
Block(-4,51,0,WOOD_BUTTON:4)
Block(-4,51,1,LOG:5)
Block(-4,51,5,LOG:5)
Block(-4,52,1,WOOD_STEP:5)
Block(-4,52,5,WOOD_STEP:5)
Block(-4,53,0,WOOD_STEP:13)
Block(-4,53,1,WOOD_STEP:8)
Block(-4,53,2,WOOD_STEP:8)
Block(-4,53,3,WOOD_STEP:8)
Block(-4,53,4,WOOD_STEP:8)
Block(-4,53,5,WOOD_STEP:8)
Block(-4,53,6,WOOD_STEP:13)
Block(-4,54,0,STEP:0)
Block(-4,54,1,LOG:5)
Block(-4,54,2,STEP:0)
Block(-4,54,3,STEP:0)
Block(-4,54,4,STEP:0)
Block(-4,54,5,LOG:5)
Block(-4,54,6,STEP:0)
Block(-4,54,8,SPRUCE_WOOD_STAIRS:6)
Block(-4,55,1,SPRUCE_FENCE:0)
Block(-4,55,5,SPRUCE_FENCE:0)
Block(-4,55,8,LOG:1)
Block(-4,56,3,AIR:0)
Block(-3,3,1,LOG:5)
Block(-3,3,5,LOG:5)
Block(-3,7,1,LOG:5)
Block(-3,7,5,LOG:5)
Block(-3,11,1,LOG:5)
Block(-3,11,5,LOG:5)
Block(-3,15,1,LOG:5)
Block(-3,15,5,LOG:5)
Block(-3,19,1,LOG:5)
Block(-3,19,5,LOG:5)
Block(-3,23,1,LOG:5)
Block(-3,23,5,LOG:5)
Block(-3,27,1,LOG:5)
Block(-3,27,5,LOG:5)
Block(-3,31,1,LOG:5)
Block(-3,31,5,LOG:5)
Block(-3,35,1,LOG:5)
Block(-3,35,5,LOG:5)
Block(-3,39,1,LOG:5)
Block(-3,39,5,LOG:5)
Block(-3,43,1,LOG:5)
Block(-3,43,5,LOG:5)
Block(-3,47,1,LOG:5)
Block(-3,47,5,LOG:5)
Block(-3,48,1,LOG:5)
Block(-3,48,5,LOG:5)
Block(-3,51,0,WOOD_BUTTON:4)
Block(-3,51,1,LOG:5)
Block(-3,51,5,LOG:5)
Block(-3,52,1,WOOD_STEP:5)
Block(-3,52,5,WOOD_STEP:5)
Block(-3,53,0,WOOD_STEP:13)
Block(-3,53,6,WOOD_STEP:13)
Block(-3,54,0,STEP:0)
Block(-3,54,1,LOG:5)
Block(-3,54,2,STEP:0)
Block(-3,54,3,STEP:0)
Block(-3,54,4,STEP:0)
Block(-3,54,5,LOG:5)
Block(-3,54,6,STEP:0)
Block(-3,55,1,SPRUCE_FENCE:0)
Block(-3,55,5,SPRUCE_FENCE:0)
Block(-3,56,5,SPRUCE_FENCE:0)
Block(-3,57,4,SPRUCE_FENCE:0)
Block(-3,57,5,SPRUCE_FENCE:0)
Block(-3,58,4,TORCH:5)
Block(-2,3,1,LOG:5)
Block(-2,3,5,LOG:5)
Block(-2,7,1,LOG:5)
Block(-2,7,5,LOG:5)
Block(-2,11,1,LOG:5)
Block(-2,11,5,LOG:5)
Block(-2,15,1,LOG:5)
Block(-2,15,5,LOG:5)
Block(-2,19,1,LOG:5)
Block(-2,19,5,LOG:5)
Block(-2,23,1,LOG:5)
Block(-2,23,5,LOG:5)
Block(-2,27,1,LOG:5)
Block(-2,27,5,LOG:5)
Block(-2,31,1,LOG:5)
Block(-2,31,5,LOG:5)
Block(-2,35,1,LOG:5)
Block(-2,35,5,LOG:5)
Block(-2,39,1,LOG:5)
Block(-2,39,5,LOG:5)
Block(-2,43,1,LOG:5)
Block(-2,43,5,LOG:5)
Block(-2,47,1,LOG:5)
Block(-2,47,5,LOG:5)
Block(-2,48,1,LOG:5)
Block(-2,48,5,LOG:5)
Block(-2,51,0,WOOD_BUTTON:4)
Block(-2,51,1,LOG:5)
Block(-2,51,5,LOG:5)
Block(-2,52,1,WOOD_STEP:5)
Block(-2,52,5,WOOD_STEP:5)
Block(-2,53,0,WOOD_STEP:13)
Block(-2,53,1,WOOD_STEP:8)
Block(-2,53,2,WOOD_STEP:8)
Block(-2,53,3,WOOD_STEP:8)
Block(-2,53,4,WOOD_STEP:8)
Block(-2,53,5,WOOD_STEP:8)
Block(-2,53,6,WOOD_STEP:13)
Block(-2,53,7,WOOD_STEP:13)
Block(-2,53,8,WOOD_STEP:13)
Block(-2,54,0,STEP:0)
Block(-2,54,1,LOG:5)
Block(-2,54,2,STEP:0)
Block(-2,54,3,STEP:0)
Block(-2,54,4,STEP:0)
Block(-2,54,5,LOG:5)
Block(-2,54,6,STEP:0)
Block(-2,54,7,STEP:0)
Block(-2,54,8,STEP:0)
Block(-2,55,1,SPRUCE_FENCE:0)
Block(-2,55,5,SPRUCE_FENCE:0)
Block(-1,0,0,STONE:6)
Block(-1,0,1,LOG:1)
Block(-1,0,5,LOG:1)
Block(-1,1,0,STONE:6)
Block(-1,1,1,LOG:1)
Block(-1,1,5,LOG:1)
Block(-1,2,0,STONE:6)
Block(-1,2,1,LOG:1)
Block(-1,2,5,LOG:1)
Block(-1,3,0,STONE:6)
Block(-1,3,1,LOG:1)
Block(-1,3,5,LOG:1)
Block(-1,3,6,LOG:9)
Block(-1,3,7,LOG:9)
Block(-1,3,8,LOG:9)
Block(-1,4,0,STONE:6)
Block(-1,4,1,LOG:1)
Block(-1,4,5,LOG:1)
Block(-1,5,0,STONE:6)
Block(-1,5,1,LOG:1)
Block(-1,5,5,LOG:1)
Block(-1,6,0,STONE:6)
Block(-1,6,1,LOG:1)
Block(-1,6,5,LOG:1)
Block(-1,7,0,STONE:6)
Block(-1,7,1,LOG:1)
Block(-1,7,5,LOG:1)
Block(-1,7,6,LOG:9)
Block(-1,7,7,LOG:9)
Block(-1,7,8,LOG:9)
Block(-1,8,0,STONE:6)
Block(-1,8,1,LOG:1)
Block(-1,8,5,LOG:1)
Block(-1,9,0,STONE:6)
Block(-1,9,1,LOG:1)
Block(-1,9,5,LOG:1)
Block(-1,10,0,STONE:6)
Block(-1,10,1,LOG:1)
Block(-1,10,5,LOG:1)
Block(-1,11,0,STONE:6)
Block(-1,11,1,LOG:1)
Block(-1,11,5,LOG:1)
Block(-1,11,6,LOG:9)
Block(-1,11,7,LOG:9)
Block(-1,11,8,LOG:9)
Block(-1,12,0,STONE:6)
Block(-1,12,1,LOG:1)
Block(-1,12,5,LOG:1)
Block(-1,13,0,STONE:6)
Block(-1,13,1,LOG:1)
Block(-1,13,5,LOG:1)
Block(-1,14,0,STONE:6)
Block(-1,14,1,LOG:1)
Block(-1,14,5,LOG:1)
Block(-1,15,0,STONE:6)
Block(-1,15,1,LOG:1)
Block(-1,15,5,LOG:1)
Block(-1,15,6,LOG:9)
Block(-1,15,7,LOG:9)
Block(-1,15,8,LOG:9)
Block(-1,16,0,STONE:6)
Block(-1,16,1,LOG:1)
Block(-1,16,5,LOG:1)
Block(-1,17,0,STONE:6)
Block(-1,17,1,LOG:1)
Block(-1,17,5,LOG:1)
Block(-1,18,0,STONE:6)
Block(-1,18,1,LOG:1)
Block(-1,18,5,LOG:1)
Block(-1,19,0,STONE:6)
Block(-1,19,1,LOG:1)
Block(-1,19,5,LOG:1)
Block(-1,19,6,LOG:9)
Block(-1,19,7,LOG:9)
Block(-1,19,8,LOG:9)
Block(-1,20,0,STONE:6)
Block(-1,20,1,LOG:1)
Block(-1,20,5,LOG:1)
Block(-1,21,0,STONE:6)
Block(-1,21,1,LOG:1)
Block(-1,21,5,LOG:1)
Block(-1,22,0,STONE:6)
Block(-1,22,1,LOG:1)
Block(-1,22,5,LOG:1)
Block(-1,23,0,STONE:6)
Block(-1,23,1,LOG:1)
Block(-1,23,5,LOG:1)
Block(-1,23,6,LOG:9)
Block(-1,23,7,LOG:9)
Block(-1,23,8,LOG:9)
Block(-1,24,0,STONE:6)
Block(-1,24,1,LOG:1)
Block(-1,24,5,LOG:1)
Block(-1,25,0,STONE:6)
Block(-1,25,1,LOG:1)
Block(-1,25,5,LOG:1)
Block(-1,26,0,STONE:6)
Block(-1,26,1,LOG:1)
Block(-1,26,5,LOG:1)
Block(-1,27,0,STONE:6)
Block(-1,27,1,LOG:1)
Block(-1,27,5,LOG:1)
Block(-1,27,6,LOG:9)
Block(-1,27,7,LOG:9)
Block(-1,27,8,LOG:9)
Block(-1,28,0,STONE:6)
Block(-1,28,1,LOG:1)
Block(-1,28,5,LOG:1)
Block(-1,29,0,STONE:6)
Block(-1,29,1,LOG:1)
Block(-1,29,5,LOG:1)
Block(-1,30,0,STONE:6)
Block(-1,30,1,LOG:1)
Block(-1,30,5,LOG:1)
Block(-1,31,0,STONE:6)
Block(-1,31,1,LOG:1)
Block(-1,31,5,LOG:1)
Block(-1,31,6,LOG:9)
Block(-1,31,7,LOG:9)
Block(-1,31,8,LOG:9)
Block(-1,32,0,STONE:6)
Block(-1,32,1,LOG:1)
Block(-1,32,5,LOG:1)
Block(-1,33,0,STONE:6)
Block(-1,33,1,LOG:1)
Block(-1,33,5,LOG:1)
Block(-1,34,0,STONE:6)
Block(-1,34,1,LOG:1)
Block(-1,34,5,LOG:1)
Block(-1,35,0,STONE:6)
Block(-1,35,1,LOG:1)
Block(-1,35,5,LOG:1)
Block(-1,35,6,LOG:9)
Block(-1,35,7,LOG:9)
Block(-1,35,8,LOG:9)
Block(-1,36,0,STONE:6)
Block(-1,36,1,LOG:1)
Block(-1,36,5,LOG:1)
Block(-1,37,0,STONE:6)
Block(-1,37,1,LOG:1)
Block(-1,37,5,LOG:1)
Block(-1,38,0,STONE:6)
Block(-1,38,1,LOG:1)
Block(-1,38,5,LOG:1)
Block(-1,39,0,STONE:6)
Block(-1,39,1,LOG:1)
Block(-1,39,5,LOG:1)
Block(-1,39,6,LOG:9)
Block(-1,39,7,LOG:9)
Block(-1,39,8,LOG:9)
Block(-1,40,0,STONE:6)
Block(-1,40,1,LOG:1)
Block(-1,40,5,LOG:1)
Block(-1,41,0,STONE:6)
Block(-1,41,1,LOG:1)
Block(-1,41,5,LOG:1)
Block(-1,42,0,STONE:6)
Block(-1,42,1,LOG:1)
Block(-1,42,5,LOG:1)
Block(-1,43,0,STONE:6)
Block(-1,43,1,LOG:1)
Block(-1,43,5,LOG:1)
Block(-1,43,6,LOG:9)
Block(-1,43,7,LOG:9)
Block(-1,43,8,LOG:9)
Block(-1,44,0,STONE:6)
Block(-1,44,1,LOG:1)
Block(-1,44,5,LOG:1)
Block(-1,45,0,STONE:6)
Block(-1,45,1,LOG:1)
Block(-1,45,5,LOG:1)
Block(-1,46,0,STONE:6)
Block(-1,46,1,LOG:1)
Block(-1,46,5,LOG:1)
Block(-1,47,0,STONE:6)
Block(-1,47,1,LOG:1)
Block(-1,47,5,LOG:1)
Block(-1,47,6,LOG:9)
Block(-1,47,7,LOG:9)
Block(-1,47,8,LOG:9)
Block(-1,48,0,STONE:6)
Block(-1,48,1,LOG:1)
Block(-1,48,5,LOG:1)
Block(-1,48,6,LOG:9)
Block(-1,48,7,LOG:9)
Block(-1,48,8,LOG:9)
Block(-1,49,0,STONE:6)
Block(-1,49,1,LOG:1)
Block(-1,49,5,LOG:1)
Block(-1,50,0,STONE:6)
Block(-1,50,1,LOG:1)
Block(-1,50,5,LOG:1)
Block(-1,51,0,STONE:6)
Block(-1,51,1,LOG:1)
Block(-1,51,2,LOG:9)
Block(-1,51,3,LOG:9)
Block(-1,51,4,LOG:9)
Block(-1,51,5,LOG:1)
Block(-1,51,6,LOG:9)
Block(-1,51,7,LOG:9)
Block(-1,51,8,LOG:9)
Block(-1,52,0,SMOOTH_STAIRS:2)
Block(-1,52,1,LOG:1)
Block(-1,52,2,WOOD_STEP:5)
Block(-1,52,3,WOOD_STEP:5)
Block(-1,52,4,WOOD_STEP:5)
Block(-1,52,5,LOG:1)
Block(-1,52,6,WOOD_STEP:5)
Block(-1,52,7,WOOD_STEP:5)
Block(-1,52,8,WOOD_STEP:5)
Block(-1,53,0,SMOOTH_STAIRS:6)
Block(-1,53,1,LOG:1)
Block(-1,53,2,WOOD_STEP:8)
Block(-1,53,4,WOOD_STEP:8)
Block(-1,53,5,LOG:1)
Block(-1,53,6,WOOD_STEP:8)
Block(-1,53,8,WOOD_STEP:8)
Block(-1,54,0,STONE:6)
Block(-1,54,1,LOG:1)
Block(-1,54,2,STEP:0)
Block(-1,54,3,STEP:0)
Block(-1,54,4,STEP:0)
Block(-1,54,5,LOG:1)
Block(-1,54,6,LOG:9)
Block(-1,54,7,LOG:9)
Block(-1,54,8,LOG:9)
Block(-1,55,0,SMOOTH_STAIRS:2)
Block(-1,55,1,SMOOTH_STAIRS:3)
Block(-1,55,5,SMOOTH_BRICK:3)
Block(-1,55,6,SPRUCE_FENCE:0)
Block(-1,55,7,SPRUCE_FENCE:0)
Block(-1,55,8,SPRUCE_FENCE:0)
Block(-1,56,0,STEP:0)
Block(-1,56,1,STEP:0)
Block(-1,56,5,STEP:0)
Block(0,2,5,LOG:5)
Block(0,3,1,LOG:5)
Block(0,6,5,LOG:5)
Block(0,7,1,LOG:5)
Block(0,10,5,LOG:5)
Block(0,11,1,LOG:5)
Block(0,14,5,LOG:5)
Block(0,15,1,LOG:5)
Block(0,18,5,LOG:5)
Block(0,19,1,LOG:5)
Block(0,22,5,LOG:5)
Block(0,23,1,LOG:5)
Block(0,26,5,LOG:5)
Block(0,27,1,LOG:5)
Block(0,30,5,LOG:5)
Block(0,31,1,LOG:5)
Block(0,34,5,LOG:5)
Block(0,35,1,LOG:5)
Block(0,38,5,LOG:5)
Block(0,39,1,LOG:5)
Block(0,42,5,LOG:5)
Block(0,43,1,LOG:5)
Block(0,46,5,LOG:5)
Block(0,47,1,LOG:5)
Block(0,48,1,LOG:5)
Block(0,51,0,WOOD_BUTTON:4)
Block(0,51,1,LOG:5)
Block(0,51,5,LOG:5)
Block(0,52,1,WOOD_STEP:5)
Block(0,52,5,WOOD_STEP:5)
Block(0,53,0,WOOD_STEP:13)
Block(0,53,2,WOOD_STEP:8)
Block(0,53,4,WOOD_STEP:8)
Block(0,53,6,WOOD_STEP:8)
Block(0,53,8,WOOD_STEP:8)
Block(0,54,0,STEP:0)
Block(0,54,1,LOG:5)
Block(0,54,2,STEP:0)
Block(0,54,3,STEP:0)
Block(0,54,4,STEP:0)
Block(0,54,5,STEP:0)
Block(0,54,6,STEP:0)
Block(0,54,7,STEP:0)
Block(0,54,8,STEP:0)
Block(0,55,1,SPRUCE_FENCE:0)
Block(1,2,5,LOG:5)
Block(1,3,1,LOG:5)
Block(1,6,5,LOG:5)
Block(1,7,1,LOG:5)
Block(1,10,5,LOG:5)
Block(1,11,1,LOG:5)
Block(1,14,5,LOG:5)
Block(1,15,1,LOG:5)
Block(1,18,5,LOG:5)
Block(1,19,1,LOG:5)
Block(1,22,5,LOG:5)
Block(1,23,1,LOG:5)
Block(1,26,5,LOG:5)
Block(1,27,1,LOG:5)
Block(1,30,5,LOG:5)
Block(1,31,1,LOG:5)
Block(1,34,5,LOG:5)
Block(1,35,1,LOG:5)
Block(1,38,5,LOG:5)
Block(1,39,1,LOG:5)
Block(1,42,5,LOG:5)
Block(1,43,1,LOG:5)
Block(1,46,5,LOG:5)
Block(1,47,1,LOG:5)
Block(1,48,1,LOG:5)
Block(1,51,0,WOOD_BUTTON:4)
Block(1,51,1,LOG:5)
Block(1,51,5,LOG:5)
Block(1,52,1,WOOD_STEP:5)
Block(1,52,5,WOOD_STEP:5)
Block(1,53,0,WOOD_STEP:13)
Block(1,53,2,WOOD_STEP:8)
Block(1,53,4,WOOD_STEP:8)
Block(1,53,6,WOOD_STEP:8)
Block(1,53,8,WOOD_STEP:8)
Block(1,54,0,STEP:0)
Block(1,54,1,LOG:5)
Block(1,54,2,STEP:0)
Block(1,54,3,STEP:0)
Block(1,54,4,STEP:0)
Block(1,54,5,STEP:0)
Block(1,54,6,STEP:0)
Block(1,54,7,STEP:0)
Block(1,54,8,STEP:0)
Block(1,55,1,SPRUCE_FENCE:0)
Block(2,2,5,LOG:5)
Block(2,3,1,LOG:5)
Block(2,6,5,LOG:5)
Block(2,7,1,LOG:5)
Block(2,10,5,LOG:5)
Block(2,11,1,LOG:5)
Block(2,14,5,LOG:5)
Block(2,15,1,LOG:5)
Block(2,18,5,LOG:5)
Block(2,19,1,LOG:5)
Block(2,22,5,LOG:5)
Block(2,23,1,LOG:5)
Block(2,26,5,LOG:5)
Block(2,27,1,LOG:5)
Block(2,30,5,LOG:5)
Block(2,31,1,LOG:5)
Block(2,34,5,LOG:5)
Block(2,35,1,LOG:5)
Block(2,38,5,LOG:5)
Block(2,39,1,LOG:5)
Block(2,42,5,LOG:5)
Block(2,43,1,LOG:5)
Block(2,46,5,LOG:5)
Block(2,47,1,LOG:5)
Block(2,48,1,LOG:5)
Block(2,51,0,WOOD_BUTTON:4)
Block(2,51,1,LOG:5)
Block(2,51,5,LOG:5)
Block(2,52,1,WOOD_STEP:5)
Block(2,52,5,WOOD_STEP:5)
Block(2,53,0,WOOD_STEP:13)
Block(2,53,2,WOOD_STEP:8)
Block(2,53,4,WOOD_STEP:8)
Block(2,53,6,WOOD_STEP:8)
Block(2,53,8,WOOD_STEP:8)
Block(2,54,0,STEP:0)
Block(2,54,1,LOG:5)
Block(2,54,2,STEP:0)
Block(2,54,3,STEP:0)
Block(2,54,4,STEP:0)
Block(2,54,5,STEP:0)
Block(2,54,6,STEP:0)
Block(2,54,7,STEP:0)
Block(2,54,8,STEP:0)
Block(2,55,1,SPRUCE_FENCE:0)
Block(3,0,0,STONE:6)
Block(3,0,1,LOG:1)
Block(3,0,5,LOG:1)
Block(3,1,0,STONE:6)
Block(3,1,1,LOG:1)
Block(3,1,5,LOG:1)
Block(3,2,0,STONE:6)
Block(3,2,1,LOG:1)
Block(3,2,5,LOG:1)
Block(3,3,0,STONE:6)
Block(3,3,1,LOG:1)
Block(3,3,2,LOG:9)
Block(3,3,3,LOG:9)
Block(3,3,4,LOG:9)
Block(3,3,5,LOG:1)
Block(3,3,6,LOG:9)
Block(3,3,7,LOG:9)
Block(3,3,8,LOG:9)
Block(3,4,0,STONE:6)
Block(3,4,1,LOG:1)
Block(3,4,5,LOG:1)
Block(3,5,0,STONE:6)
Block(3,5,1,LOG:1)
Block(3,5,5,LOG:1)
Block(3,6,0,STONE:6)
Block(3,6,1,LOG:1)
Block(3,6,5,LOG:1)
Block(3,7,0,STONE:6)
Block(3,7,1,LOG:1)
Block(3,7,2,LOG:9)
Block(3,7,3,LOG:9)
Block(3,7,4,LOG:9)
Block(3,7,5,LOG:1)
Block(3,7,6,LOG:9)
Block(3,7,7,LOG:9)
Block(3,7,8,LOG:9)
Block(3,8,0,STONE:6)
Block(3,8,1,LOG:1)
Block(3,8,5,LOG:1)
Block(3,9,0,STONE:6)
Block(3,9,1,LOG:1)
Block(3,9,5,LOG:1)
Block(3,10,0,STONE:6)
Block(3,10,1,LOG:1)
Block(3,10,5,LOG:1)
Block(3,11,0,STONE:6)
Block(3,11,1,LOG:1)
Block(3,11,2,LOG:9)
Block(3,11,3,LOG:9)
Block(3,11,4,LOG:9)
Block(3,11,5,LOG:1)
Block(3,11,6,LOG:9)
Block(3,11,7,LOG:9)
Block(3,11,8,LOG:9)
Block(3,12,0,STONE:6)
Block(3,12,1,LOG:1)
Block(3,12,5,LOG:1)
Block(3,13,0,STONE:6)
Block(3,13,1,LOG:1)
Block(3,13,5,LOG:1)
Block(3,14,0,STONE:6)
Block(3,14,1,LOG:1)
Block(3,14,5,LOG:1)
Block(3,15,0,STONE:6)
Block(3,15,1,LOG:1)
Block(3,15,2,LOG:9)
Block(3,15,3,LOG:9)
Block(3,15,4,LOG:9)
Block(3,15,5,LOG:1)
Block(3,15,6,LOG:9)
Block(3,15,7,LOG:9)
Block(3,15,8,LOG:9)
Block(3,16,0,STONE:6)
Block(3,16,1,LOG:1)
Block(3,16,5,LOG:1)
Block(3,17,0,STONE:6)
Block(3,17,1,LOG:1)
Block(3,17,5,LOG:1)
Block(3,18,0,STONE:6)
Block(3,18,1,LOG:1)
Block(3,18,5,LOG:1)
Block(3,19,0,STONE:6)
Block(3,19,1,LOG:1)
Block(3,19,2,LOG:9)
Block(3,19,3,LOG:9)
Block(3,19,4,LOG:9)
Block(3,19,5,LOG:1)
Block(3,19,6,LOG:9)
Block(3,19,7,LOG:9)
Block(3,19,8,LOG:9)
Block(3,20,0,STONE:6)
Block(3,20,1,LOG:1)
Block(3,20,5,LOG:1)
Block(3,21,0,STONE:6)
Block(3,21,1,LOG:1)
Block(3,21,5,LOG:1)
Block(3,22,0,STONE:6)
Block(3,22,1,LOG:1)
Block(3,22,5,LOG:1)
Block(3,23,0,STONE:6)
Block(3,23,1,LOG:1)
Block(3,23,2,LOG:9)
Block(3,23,3,LOG:9)
Block(3,23,4,LOG:9)
Block(3,23,5,LOG:1)
Block(3,23,6,LOG:9)
Block(3,23,7,LOG:9)
Block(3,23,8,LOG:9)
Block(3,24,0,STONE:6)
Block(3,24,1,LOG:1)
Block(3,24,5,LOG:1)
Block(3,25,0,STONE:6)
Block(3,25,1,LOG:1)
Block(3,25,5,LOG:1)
Block(3,26,0,STONE:6)
Block(3,26,1,LOG:1)
Block(3,26,5,LOG:1)
Block(3,27,0,STONE:6)
Block(3,27,1,LOG:1)
Block(3,27,2,LOG:9)
Block(3,27,3,LOG:9)
Block(3,27,4,LOG:9)
Block(3,27,5,LOG:1)
Block(3,27,6,LOG:9)
Block(3,27,7,LOG:9)
Block(3,27,8,LOG:9)
Block(3,28,0,STONE:6)
Block(3,28,1,LOG:1)
Block(3,28,5,LOG:1)
Block(3,29,0,STONE:6)
Block(3,29,1,LOG:1)
Block(3,29,5,LOG:1)
Block(3,30,0,STONE:6)
Block(3,30,1,LOG:1)
Block(3,30,5,LOG:1)
Block(3,31,0,STONE:6)
Block(3,31,1,LOG:1)
Block(3,31,2,LOG:9)
Block(3,31,3,LOG:9)
Block(3,31,4,LOG:9)
Block(3,31,5,LOG:1)
Block(3,31,6,LOG:9)
Block(3,31,7,LOG:9)
Block(3,31,8,LOG:9)
Block(3,32,0,STONE:6)
Block(3,32,1,LOG:1)
Block(3,32,5,LOG:1)
Block(3,33,0,STONE:6)
Block(3,33,1,LOG:1)
Block(3,33,5,LOG:1)
Block(3,34,0,STONE:6)
Block(3,34,1,LOG:1)
Block(3,34,5,LOG:1)
Block(3,35,0,STONE:6)
Block(3,35,1,LOG:1)
Block(3,35,2,LOG:9)
Block(3,35,3,LOG:9)
Block(3,35,4,LOG:9)
Block(3,35,5,LOG:1)
Block(3,35,6,LOG:9)
Block(3,35,7,LOG:9)
Block(3,35,8,LOG:9)
Block(3,36,0,STONE:6)
Block(3,36,1,LOG:1)
Block(3,36,5,LOG:1)
Block(3,37,0,STONE:6)
Block(3,37,1,LOG:1)
Block(3,37,5,LOG:1)
Block(3,38,0,STONE:6)
Block(3,38,1,LOG:1)
Block(3,38,5,LOG:1)
Block(3,39,0,STONE:6)
Block(3,39,1,LOG:1)
Block(3,39,2,LOG:9)
Block(3,39,3,LOG:9)
Block(3,39,4,LOG:9)
Block(3,39,5,LOG:1)
Block(3,39,6,LOG:9)
Block(3,39,7,LOG:9)
Block(3,39,8,LOG:9)
Block(3,40,0,STONE:6)
Block(3,40,1,LOG:1)
Block(3,40,5,LOG:1)
Block(3,41,0,STONE:6)
Block(3,41,1,LOG:1)
Block(3,41,5,LOG:1)
Block(3,42,0,STONE:6)
Block(3,42,1,LOG:1)
Block(3,42,5,LOG:1)
Block(3,43,0,STONE:6)
Block(3,43,1,LOG:1)
Block(3,43,2,LOG:9)
Block(3,43,3,LOG:9)
Block(3,43,4,LOG:9)
Block(3,43,5,LOG:1)
Block(3,43,6,LOG:9)
Block(3,43,7,LOG:9)
Block(3,43,8,LOG:9)
Block(3,44,0,STONE:6)
Block(3,44,1,LOG:1)
Block(3,44,5,LOG:1)
Block(3,45,0,STONE:6)
Block(3,45,1,LOG:1)
Block(3,45,5,LOG:1)
Block(3,46,0,STONE:6)
Block(3,46,1,LOG:1)
Block(3,46,5,LOG:1)
Block(3,47,0,STONE:6)
Block(3,47,1,LOG:1)
Block(3,47,2,LOG:9)
Block(3,47,3,LOG:9)
Block(3,47,4,LOG:9)
Block(3,47,5,LOG:1)
Block(3,47,6,LOG:9)
Block(3,47,7,LOG:9)
Block(3,47,8,LOG:9)
Block(3,48,0,STONE:6)
Block(3,48,1,LOG:1)
Block(3,48,2,LOG:9)
Block(3,48,3,LOG:9)
Block(3,48,4,LOG:9)
Block(3,48,5,LOG:1)
Block(3,48,6,LOG:9)
Block(3,48,7,LOG:9)
Block(3,48,8,LOG:9)
Block(3,49,0,STONE:6)
Block(3,49,1,LOG:1)
Block(3,49,5,LOG:1)
Block(3,50,0,STONE:6)
Block(3,50,1,LOG:1)
Block(3,50,5,LOG:1)
Block(3,51,0,STONE:6)
Block(3,51,1,LOG:1)
Block(3,51,2,LOG:9)
Block(3,51,3,LOG:9)
Block(3,51,4,LOG:9)
Block(3,51,5,LOG:1)
Block(3,51,6,LOG:9)
Block(3,51,7,LOG:9)
Block(3,51,8,LOG:9)
Block(3,52,0,SMOOTH_STAIRS:2)
Block(3,52,1,LOG:1)
Block(3,52,2,WOOD_STEP:5)
Block(3,52,3,WOOD_STEP:5)
Block(3,52,4,WOOD_STEP:5)
Block(3,52,5,LOG:1)
Block(3,52,6,WOOD_STEP:5)
Block(3,52,7,WOOD_STEP:5)
Block(3,52,8,WOOD_STEP:5)
Block(3,53,0,SMOOTH_STAIRS:6)
Block(3,53,1,LOG:1)
Block(3,53,2,WOOD_STEP:8)
Block(3,53,4,WOOD_STEP:8)
Block(3,53,5,LOG:1)
Block(3,53,6,WOOD_STEP:8)
Block(3,53,8,WOOD_STEP:8)
Block(3,54,0,STONE:6)
Block(3,54,1,LOG:1)
Block(3,54,2,LOG:9)
Block(3,54,3,LOG:9)
Block(3,54,4,LOG:9)
Block(3,54,5,LOG:1)
Block(3,54,6,LOG:9)
Block(3,54,7,LOG:9)
Block(3,54,8,LOG:9)
Block(3,55,0,SMOOTH_STAIRS:2)
Block(3,55,1,SMOOTH_BRICK:3)
Block(3,55,2,SPRUCE_FENCE:0)
Block(3,55,3,SPRUCE_FENCE:0)
Block(3,55,4,SPRUCE_FENCE:0)
Block(3,55,5,SMOOTH_STAIRS:0)
Block(3,55,6,SPRUCE_FENCE:0)
Block(3,55,7,SPRUCE_FENCE:0)
Block(3,55,8,SPRUCE_FENCE:0)
Block(3,56,0,STEP:0)
Block(3,56,1,STEP:0)
Block(3,56,5,STEP:0)
Block(4,0,1,STONE:6)
Block(4,0,5,STONE:6)
Block(4,1,1,STONE:6)
Block(4,1,5,STONE:6)
Block(4,2,1,STONE:6)
Block(4,2,5,STONE:6)
Block(4,3,1,STONE:6)
Block(4,3,5,STONE:6)
Block(4,4,1,STONE:6)
Block(4,4,5,STONE:6)
Block(4,5,1,STONE:6)
Block(4,5,5,STONE:6)
Block(4,6,1,STONE:6)
Block(4,6,5,STONE:6)
Block(4,7,1,STONE:6)
Block(4,7,5,STONE:6)
Block(4,8,1,STONE:6)
Block(4,8,5,STONE:6)
Block(4,9,1,STONE:6)
Block(4,9,5,STONE:6)
Block(4,10,1,STONE:6)
Block(4,10,5,STONE:6)
Block(4,11,1,STONE:6)
Block(4,11,5,STONE:6)
Block(4,12,1,STONE:6)
Block(4,12,5,STONE:6)
Block(4,13,1,STONE:6)
Block(4,13,5,STONE:6)
Block(4,14,1,STONE:6)
Block(4,14,5,STONE:6)
Block(4,15,1,STONE:6)
Block(4,15,5,STONE:6)
Block(4,16,1,STONE:6)
Block(4,16,5,STONE:6)
Block(4,17,1,STONE:6)
Block(4,17,5,STONE:6)
Block(4,18,1,STONE:6)
Block(4,18,5,STONE:6)
Block(4,19,1,STONE:6)
Block(4,19,5,STONE:6)
Block(4,20,1,STONE:6)
Block(4,20,5,STONE:6)
Block(4,21,1,STONE:6)
Block(4,21,5,STONE:6)
Block(4,22,1,STONE:6)
Block(4,22,5,STONE:6)
Block(4,23,1,STONE:6)
Block(4,23,5,STONE:6)
Block(4,24,1,STONE:6)
Block(4,24,5,STONE:6)
Block(4,25,1,STONE:6)
Block(4,25,5,STONE:6)
Block(4,26,1,STONE:6)
Block(4,26,5,STONE:6)
Block(4,27,1,STONE:6)
Block(4,27,5,STONE:6)
Block(4,28,1,STONE:6)
Block(4,28,5,STONE:6)
Block(4,29,1,STONE:6)
Block(4,29,5,STONE:6)
Block(4,30,1,STONE:6)
Block(4,30,5,STONE:6)
Block(4,31,1,STONE:6)
Block(4,31,5,STONE:6)
Block(4,32,1,STONE:6)
Block(4,32,5,STONE:6)
Block(4,33,1,STONE:6)
Block(4,33,5,STONE:6)
Block(4,34,1,STONE:6)
Block(4,34,5,STONE:6)
Block(4,35,1,STONE:6)
Block(4,35,5,STONE:6)
Block(4,36,1,STONE:6)
Block(4,36,5,STONE:6)
Block(4,37,1,STONE:6)
Block(4,37,5,STONE:6)
Block(4,38,1,STONE:6)
Block(4,38,5,STONE:6)
Block(4,39,1,STONE:6)
Block(4,39,5,STONE:6)
Block(4,40,1,STONE:6)
Block(4,40,5,STONE:6)
Block(4,41,1,STONE:6)
Block(4,41,5,STONE:6)
Block(4,42,1,STONE:6)
Block(4,42,5,STONE:6)
Block(4,43,1,STONE:6)
Block(4,43,5,STONE:6)
Block(4,44,1,STONE:6)
Block(4,44,5,STONE:6)
Block(4,45,1,STONE:6)
Block(4,45,5,STONE:6)
Block(4,46,1,STONE:6)
Block(4,46,5,STONE:6)
Block(4,47,1,STONE:6)
Block(4,47,5,STONE:6)
Block(4,48,1,STONE:6)
Block(4,48,5,STONE:6)
Block(4,49,1,STONE:6)
Block(4,49,5,STONE:6)
Block(4,50,1,STONE:6)
Block(4,50,5,STONE:6)
Block(4,51,1,STONE:6)
Block(4,51,2,WOOD_BUTTON:1)
Block(4,51,3,WOOD_BUTTON:1)
Block(4,51,4,WOOD_BUTTON:1)
Block(4,51,5,STONE:6)
Block(4,51,6,WOOD_BUTTON:1)
Block(4,51,7,WOOD_BUTTON:1)
Block(4,51,8,WOOD_BUTTON:1)
Block(4,52,1,SMOOTH_STAIRS:1)
Block(4,52,5,SMOOTH_STAIRS:1)
Block(4,53,1,SMOOTH_STAIRS:5)
Block(4,53,2,WOOD_STEP:13)
Block(4,53,3,WOOD_STEP:13)
Block(4,53,4,WOOD_STEP:13)
Block(4,53,5,SMOOTH_STAIRS:5)
Block(4,53,6,WOOD_STEP:13)
Block(4,53,7,WOOD_STEP:13)
Block(4,53,8,WOOD_STEP:13)
Block(4,54,1,STONE:6)
Block(4,54,2,STEP:0)
Block(4,54,3,STEP:0)
Block(4,54,4,STEP:0)
Block(4,54,5,STONE:6)
Block(4,54,6,STEP:0)
Block(4,54,7,STEP:0)
Block(4,54,8,STEP:0)
Block(4,55,1,SMOOTH_STAIRS:1)
Block(4,55,5,SMOOTH_STAIRS:1)
Block(4,56,1,STEP:0)
Block(4,56,5,STEP:0)

#######################################################################
# +-----------------------------------------------------------------+ #
# |                             Branches                            | #
# +-----------------------------------------------------------------+ #
#######################################################################

Branch(-16,0,0,true,HarborC3R1,NORTH,100.0,0)

#######################################################################
# +-----------------------------------------------------------------+ #
# |                             Entities                            | #
# +-----------------------------------------------------------------+ #
#######################################################################

Entity(-4,56,3,minecraft:villager,1,../../Entities/RandomVillager.txt)

#######################################################################
# +-----------------------------------------------------------------+ #
# |                            Particles                            | #
# +-----------------------------------------------------------------+ #
#######################################################################


#######################################################################
# +-----------------------------------------------------------------+ #
# |                             Spawners                            | #
# +-----------------------------------------------------------------+ #
#######################################################################


#######################################################################
# +-----------------------------------------------------------------+ #
# |                             ModData                             | #
# +-----------------------------------------------------------------+ #
#######################################################################

