
#######################################################################
# +-----------------------------------------------------------------+ #
# |                            BO3 object                           | #
# +-----------------------------------------------------------------+ #
#######################################################################

Author: NLBlackEagle

Description: No description given

Version: 3

SettingsMode: WriteDisable


#######################################################################
# +-----------------------------------------------------------------+ #
# |                          Main settings                          | #
# +-----------------------------------------------------------------+ #
#######################################################################

Tree: true

Frequency: 1

Rarity: 100.0

RotateRandomly: false

SpawnHeight: highestSolidBlock

SpawnHeightOffset: -10

SpawnHeightVariance: 0

##############################
# Height Limits for the BO3. #
##############################

MinHeight: 55

MaxHeight: 70

######################
# Extrusion settings #
######################

ExtrudeMode: None

ExtrudeThroughBlocks: AIR

MaxBranchDepth: 10

ExcludedBiomes: All


#######################################################################
# +-----------------------------------------------------------------+ #
# |                      Source block settings                      | #
# +-----------------------------------------------------------------+ #
#######################################################################

SourceBlocks: AIR,STAINED_CLAY:4,STATIONARY_WATER,biomesoplenty:plant_0,LONG_GRASS,biomesoplenty:mushroom

MaxPercentageOutsideSourceBlock: 100

OutsideSourceBlock: dontPlace

DoReplaceBlocks: false

IsOTGPlus: false


#######################################################################
# +-----------------------------------------------------------------+ #
# |                              Blocks                             | #
# +-----------------------------------------------------------------+ #
#######################################################################

Block(-12,0,-3,STAINED_CLAY:4)
Block(-12,0,-2,STAINED_CLAY:4)
Block(-12,0,-1,STAINED_CLAY:4)
Block(-12,0,0,STAINED_CLAY:4)
Block(-12,0,1,STAINED_CLAY:4)
Block(-12,0,2,STAINED_CLAY:4)
Block(-12,0,3,STAINED_CLAY:4)
Block(-12,1,-3,STAINED_CLAY:4)
Block(-12,1,-2,STAINED_CLAY:4)
Block(-12,1,-1,STAINED_CLAY:4)
Block(-12,1,0,STAINED_CLAY:4)
Block(-12,1,1,STAINED_CLAY:4)
Block(-12,1,2,STAINED_CLAY:4)
Block(-12,1,3,STAINED_CLAY:4)
Block(-12,2,-3,STAINED_CLAY:4)
Block(-12,2,-2,STAINED_CLAY:4)
Block(-12,2,-1,STAINED_CLAY:4)
Block(-12,2,0,STAINED_CLAY:4)
Block(-12,2,1,STAINED_CLAY:4)
Block(-12,2,2,STAINED_CLAY:4)
Block(-12,2,3,STAINED_CLAY:4)
Block(-12,3,-3,STAINED_CLAY:4)
Block(-12,3,-2,STAINED_CLAY:4)
Block(-12,3,-1,STAINED_CLAY:4)
Block(-12,3,0,STAINED_CLAY:4)
Block(-12,3,1,STAINED_CLAY:4)
Block(-12,3,2,STAINED_CLAY:4)
Block(-12,3,3,STAINED_CLAY:4)
Block(-12,4,-3,STAINED_CLAY:4)
Block(-12,4,-2,STAINED_CLAY:4)
Block(-12,4,-1,STAINED_CLAY:4)
Block(-12,4,0,STAINED_CLAY:4)
Block(-12,4,1,STAINED_CLAY:4)
Block(-12,4,2,STAINED_CLAY:4)
Block(-12,4,3,STAINED_CLAY:4)
Block(-12,5,-3,STAINED_CLAY:4)
Block(-12,5,-2,STAINED_CLAY:4)
Block(-12,5,-1,STAINED_CLAY:4)
Block(-12,5,0,STAINED_CLAY:4)
Block(-12,5,1,STAINED_CLAY:4)
Block(-12,5,2,STAINED_CLAY:4)
Block(-12,5,3,STAINED_CLAY:4)
Block(-12,6,-3,STAINED_CLAY:4)
Block(-12,6,-2,STAINED_CLAY:4)
Block(-12,6,-1,STAINED_CLAY:4)
Block(-12,6,0,STAINED_CLAY:4)
Block(-12,6,1,STAINED_CLAY:4)
Block(-12,6,2,STAINED_CLAY:4)
Block(-12,6,3,STAINED_CLAY:4)
Block(-12,7,-3,STAINED_CLAY:4)
Block(-12,7,-2,STAINED_CLAY:4)
Block(-12,7,-1,STAINED_CLAY:4)
Block(-12,7,0,STAINED_CLAY:4)
Block(-12,7,1,STAINED_CLAY:4)
Block(-12,7,2,STAINED_CLAY:4)
Block(-12,7,3,STAINED_CLAY:4)
Block(-12,8,-3,STAINED_CLAY:4)
Block(-12,8,-2,STAINED_CLAY:4)
Block(-12,8,-1,STAINED_CLAY:4)
Block(-12,8,0,STAINED_CLAY:4)
Block(-12,8,1,STAINED_CLAY:4)
Block(-12,8,2,STAINED_CLAY:4)
Block(-12,8,3,STAINED_CLAY:4)
Block(-11,0,-5,STAINED_CLAY:4)
Block(-11,0,-4,STAINED_CLAY:4)
Block(-11,0,-3,STAINED_CLAY:4)
Block(-11,0,-2,STAINED_CLAY:4)
Block(-11,0,-1,STAINED_CLAY:4)
Block(-11,0,0,STAINED_CLAY:4)
Block(-11,0,1,STAINED_CLAY:4)
Block(-11,0,2,STAINED_CLAY:4)
Block(-11,0,3,STAINED_CLAY:4)
Block(-11,0,4,STAINED_CLAY:4)
Block(-11,0,5,STAINED_CLAY:4)
Block(-11,1,-5,STAINED_CLAY:4)
Block(-11,1,-4,STAINED_CLAY:4)
Block(-11,1,-3,STATIONARY_WATER:0)
Block(-11,1,-2,STATIONARY_WATER:0)
Block(-11,1,-1,STATIONARY_WATER:0)
Block(-11,1,0,STATIONARY_WATER:0)
Block(-11,1,1,STATIONARY_WATER:0)
Block(-11,1,2,STATIONARY_WATER:0)
Block(-11,1,3,STATIONARY_WATER:0)
Block(-11,1,4,STAINED_CLAY:4)
Block(-11,1,5,STAINED_CLAY:4)
Block(-11,2,-5,STAINED_CLAY:4)
Block(-11,2,-4,STAINED_CLAY:4)
Block(-11,2,-3,STATIONARY_WATER:0)
Block(-11,2,-2,STATIONARY_WATER:0)
Block(-11,2,-1,STATIONARY_WATER:0)
Block(-11,2,0,STATIONARY_WATER:0)
Block(-11,2,1,STATIONARY_WATER:0)
Block(-11,2,2,STATIONARY_WATER:0)
Block(-11,2,3,STATIONARY_WATER:0)
Block(-11,2,4,STAINED_CLAY:4)
Block(-11,2,5,STAINED_CLAY:4)
Block(-11,3,-5,STAINED_CLAY:4)
Block(-11,3,-4,STAINED_CLAY:4)
Block(-11,3,-3,STATIONARY_WATER:0)
Block(-11,3,-2,STATIONARY_WATER:0)
Block(-11,3,-1,STATIONARY_WATER:0)
Block(-11,3,0,STATIONARY_WATER:0)
Block(-11,3,1,STATIONARY_WATER:0)
Block(-11,3,2,STATIONARY_WATER:0)
Block(-11,3,3,STATIONARY_WATER:0)
Block(-11,3,4,STAINED_CLAY:4)
Block(-11,3,5,STAINED_CLAY:4)
Block(-11,4,-5,STAINED_CLAY:4)
Block(-11,4,-4,STAINED_CLAY:4)
Block(-11,4,-3,STATIONARY_WATER:0)
Block(-11,4,-2,STATIONARY_WATER:0)
Block(-11,4,-1,STATIONARY_WATER:0)
Block(-11,4,0,STATIONARY_WATER:0)
Block(-11,4,1,STATIONARY_WATER:0)
Block(-11,4,2,STATIONARY_WATER:0)
Block(-11,4,3,STATIONARY_WATER:0)
Block(-11,4,4,STAINED_CLAY:4)
Block(-11,4,5,STAINED_CLAY:4)
Block(-11,5,-5,STAINED_CLAY:4)
Block(-11,5,-4,STAINED_CLAY:4)
Block(-11,5,-3,STATIONARY_WATER:0)
Block(-11,5,-2,STATIONARY_WATER:0)
Block(-11,5,-1,STATIONARY_WATER:0)
Block(-11,5,0,STATIONARY_WATER:0)
Block(-11,5,1,STATIONARY_WATER:0)
Block(-11,5,2,STATIONARY_WATER:0)
Block(-11,5,3,STATIONARY_WATER:0)
Block(-11,5,4,STAINED_CLAY:4)
Block(-11,5,5,STAINED_CLAY:4)
Block(-11,6,-5,STAINED_CLAY:4)
Block(-11,6,-4,STAINED_CLAY:4)
Block(-11,6,-3,STATIONARY_WATER:0)
Block(-11,6,-2,STATIONARY_WATER:0)
Block(-11,6,-1,STATIONARY_WATER:0)
Block(-11,6,0,STATIONARY_WATER:0)
Block(-11,6,1,STATIONARY_WATER:0)
Block(-11,6,2,STATIONARY_WATER:0)
Block(-11,6,3,STATIONARY_WATER:0)
Block(-11,6,4,STAINED_CLAY:4)
Block(-11,6,5,STAINED_CLAY:4)
Block(-11,7,-5,STAINED_CLAY:4)
Block(-11,7,-4,STAINED_CLAY:4)
Block(-11,7,-3,STATIONARY_WATER:0)
Block(-11,7,-2,STATIONARY_WATER:0)
Block(-11,7,-1,STATIONARY_WATER:0)
Block(-11,7,0,STATIONARY_WATER:0)
Block(-11,7,1,STATIONARY_WATER:0)
Block(-11,7,2,STATIONARY_WATER:0)
Block(-11,7,3,STATIONARY_WATER:0)
Block(-11,7,4,STAINED_CLAY:4)
Block(-11,7,5,STAINED_CLAY:4)
Block(-11,8,-5,STAINED_CLAY:4)
Block(-11,8,-4,STAINED_CLAY:4)
Block(-11,8,-3,STATIONARY_WATER:0)
Block(-11,8,-2,STATIONARY_WATER:0)
Block(-11,8,-1,STATIONARY_WATER:0)
Block(-11,8,0,STATIONARY_WATER:0)
Block(-11,8,1,STATIONARY_WATER:0)
Block(-11,8,2,STATIONARY_WATER:0)
Block(-11,8,3,STATIONARY_WATER:0)
Block(-11,8,4,STAINED_CLAY:4)
Block(-11,8,5,STAINED_CLAY:4)
Block(-10,0,-7,STAINED_CLAY:4)
Block(-10,0,-6,STAINED_CLAY:4)
Block(-10,0,-5,STAINED_CLAY:4)
Block(-10,0,-4,STAINED_CLAY:4)
Block(-10,0,-3,STAINED_CLAY:4)
Block(-10,0,-2,STAINED_CLAY:4)
Block(-10,0,-1,STAINED_CLAY:4)
Block(-10,0,0,STAINED_CLAY:4)
Block(-10,0,1,STAINED_CLAY:4)
Block(-10,0,2,STAINED_CLAY:4)
Block(-10,0,3,STAINED_CLAY:4)
Block(-10,0,4,STAINED_CLAY:4)
Block(-10,0,5,STAINED_CLAY:4)
Block(-10,0,6,STAINED_CLAY:4)
Block(-10,0,7,STAINED_CLAY:4)
Block(-10,1,-7,STAINED_CLAY:4)
Block(-10,1,-6,STAINED_CLAY:4)
Block(-10,1,-5,STATIONARY_WATER:0)
Block(-10,1,-4,STATIONARY_WATER:0)
Block(-10,1,-3,STATIONARY_WATER:0)
Block(-10,1,-2,STATIONARY_WATER:0)
Block(-10,1,-1,STATIONARY_WATER:0)
Block(-10,1,0,STATIONARY_WATER:0)
Block(-10,1,1,STATIONARY_WATER:0)
Block(-10,1,2,STATIONARY_WATER:0)
Block(-10,1,3,STATIONARY_WATER:0)
Block(-10,1,4,STATIONARY_WATER:0)
Block(-10,1,5,STATIONARY_WATER:0)
Block(-10,1,6,STAINED_CLAY:4)
Block(-10,1,7,STAINED_CLAY:4)
Block(-10,2,-7,STAINED_CLAY:4)
Block(-10,2,-6,STAINED_CLAY:4)
Block(-10,2,-5,STATIONARY_WATER:0)
Block(-10,2,-4,STATIONARY_WATER:0)
Block(-10,2,-3,STATIONARY_WATER:0)
Block(-10,2,-2,STATIONARY_WATER:0)
Block(-10,2,-1,STATIONARY_WATER:0)
Block(-10,2,0,STATIONARY_WATER:0)
Block(-10,2,1,STATIONARY_WATER:0)
Block(-10,2,2,STATIONARY_WATER:0)
Block(-10,2,3,STATIONARY_WATER:0)
Block(-10,2,4,STATIONARY_WATER:0)
Block(-10,2,5,STATIONARY_WATER:0)
Block(-10,2,6,STAINED_CLAY:4)
Block(-10,2,7,STAINED_CLAY:4)
Block(-10,3,-7,STAINED_CLAY:4)
Block(-10,3,-6,STAINED_CLAY:4)
Block(-10,3,-5,STATIONARY_WATER:0)
Block(-10,3,-4,STATIONARY_WATER:0)
Block(-10,3,-3,STATIONARY_WATER:0)
Block(-10,3,-2,STATIONARY_WATER:0)
Block(-10,3,-1,STATIONARY_WATER:0)
Block(-10,3,0,STATIONARY_WATER:0)
Block(-10,3,1,STATIONARY_WATER:0)
Block(-10,3,2,STATIONARY_WATER:0)
Block(-10,3,3,STATIONARY_WATER:0)
Block(-10,3,4,STATIONARY_WATER:0)
Block(-10,3,5,STATIONARY_WATER:0)
Block(-10,3,6,STAINED_CLAY:4)
Block(-10,3,7,STAINED_CLAY:4)
Block(-10,4,-7,STAINED_CLAY:4)
Block(-10,4,-6,STAINED_CLAY:4)
Block(-10,4,-5,STATIONARY_WATER:0)
Block(-10,4,-4,STATIONARY_WATER:0)
Block(-10,4,-3,STATIONARY_WATER:0)
Block(-10,4,-2,STATIONARY_WATER:0)
Block(-10,4,-1,STATIONARY_WATER:0)
Block(-10,4,0,STATIONARY_WATER:0)
Block(-10,4,1,STATIONARY_WATER:0)
Block(-10,4,2,STATIONARY_WATER:0)
Block(-10,4,3,STATIONARY_WATER:0)
Block(-10,4,4,STATIONARY_WATER:0)
Block(-10,4,5,STATIONARY_WATER:0)
Block(-10,4,6,STAINED_CLAY:4)
Block(-10,4,7,STAINED_CLAY:4)
Block(-10,5,-7,STAINED_CLAY:4)
Block(-10,5,-6,STAINED_CLAY:4)
Block(-10,5,-5,STATIONARY_WATER:0)
Block(-10,5,-4,STATIONARY_WATER:0)
Block(-10,5,-3,STATIONARY_WATER:0)
Block(-10,5,-2,STATIONARY_WATER:0)
Block(-10,5,-1,STATIONARY_WATER:0)
Block(-10,5,0,STATIONARY_WATER:0)
Block(-10,5,1,STATIONARY_WATER:0)
Block(-10,5,2,STATIONARY_WATER:0)
Block(-10,5,3,STATIONARY_WATER:0)
Block(-10,5,4,STATIONARY_WATER:0)
Block(-10,5,5,STATIONARY_WATER:0)
Block(-10,5,6,STAINED_CLAY:4)
Block(-10,5,7,STAINED_CLAY:4)
Block(-10,6,-7,STAINED_CLAY:4)
Block(-10,6,-6,STAINED_CLAY:4)
Block(-10,6,-5,STATIONARY_WATER:0)
Block(-10,6,-4,STATIONARY_WATER:0)
Block(-10,6,-3,STATIONARY_WATER:0)
Block(-10,6,-2,STATIONARY_WATER:0)
Block(-10,6,-1,STATIONARY_WATER:0)
Block(-10,6,0,STATIONARY_WATER:0)
Block(-10,6,1,STATIONARY_WATER:0)
Block(-10,6,2,STATIONARY_WATER:0)
Block(-10,6,3,STATIONARY_WATER:0)
Block(-10,6,4,STATIONARY_WATER:0)
Block(-10,6,5,STATIONARY_WATER:0)
Block(-10,6,6,STAINED_CLAY:4)
Block(-10,6,7,STAINED_CLAY:4)
Block(-10,7,-7,STAINED_CLAY:4)
Block(-10,7,-6,STAINED_CLAY:4)
Block(-10,7,-5,STATIONARY_WATER:0)
Block(-10,7,-4,STATIONARY_WATER:0)
Block(-10,7,-3,STATIONARY_WATER:0)
Block(-10,7,-2,STATIONARY_WATER:0)
Block(-10,7,-1,STATIONARY_WATER:0)
Block(-10,7,0,STATIONARY_WATER:0)
Block(-10,7,1,STATIONARY_WATER:0)
Block(-10,7,2,STATIONARY_WATER:0)
Block(-10,7,3,STATIONARY_WATER:0)
Block(-10,7,4,STATIONARY_WATER:0)
Block(-10,7,5,STATIONARY_WATER:0)
Block(-10,7,6,STAINED_CLAY:4)
Block(-10,7,7,STAINED_CLAY:4)
Block(-10,8,-7,STAINED_CLAY:4)
Block(-10,8,-6,STAINED_CLAY:4)
Block(-10,8,-5,STATIONARY_WATER:0)
Block(-10,8,-4,STATIONARY_WATER:0)
Block(-10,8,-3,STATIONARY_WATER:0)
Block(-10,8,-2,STATIONARY_WATER:0)
Block(-10,8,-1,STATIONARY_WATER:0)
Block(-10,8,0,STATIONARY_WATER:0)
Block(-10,8,1,STATIONARY_WATER:0)
Block(-10,8,2,STATIONARY_WATER:0)
Block(-10,8,3,STATIONARY_WATER:0)
Block(-10,8,4,STATIONARY_WATER:0)
Block(-10,8,5,STATIONARY_WATER:0)
Block(-10,8,6,STAINED_CLAY:4)
Block(-10,8,7,STAINED_CLAY:4)
Block(-9,0,-8,STAINED_CLAY:4)
Block(-9,0,-7,STAINED_CLAY:4)
Block(-9,0,-6,STAINED_CLAY:4)
Block(-9,0,-5,STAINED_CLAY:4)
Block(-9,0,-4,STAINED_CLAY:4)
Block(-9,0,-3,STAINED_CLAY:4)
Block(-9,0,-2,STAINED_CLAY:4)
Block(-9,0,-1,STAINED_CLAY:4)
Block(-9,0,0,STAINED_CLAY:4)
Block(-9,0,1,STAINED_CLAY:4)
Block(-9,0,2,STAINED_CLAY:4)
Block(-9,0,3,STAINED_CLAY:4)
Block(-9,0,4,STAINED_CLAY:4)
Block(-9,0,5,STAINED_CLAY:4)
Block(-9,0,6,STAINED_CLAY:4)
Block(-9,0,7,STAINED_CLAY:4)
Block(-9,0,8,STAINED_CLAY:4)
Block(-9,1,-8,STAINED_CLAY:4)
Block(-9,1,-7,STATIONARY_WATER:0)
Block(-9,1,-6,STATIONARY_WATER:0)
Block(-9,1,-5,STATIONARY_WATER:0)
Block(-9,1,-4,STATIONARY_WATER:0)
Block(-9,1,-3,STATIONARY_WATER:0)
Block(-9,1,-2,STATIONARY_WATER:0)
Block(-9,1,-1,STATIONARY_WATER:0)
Block(-9,1,0,STATIONARY_WATER:0)
Block(-9,1,1,STATIONARY_WATER:0)
Block(-9,1,2,STATIONARY_WATER:0)
Block(-9,1,3,STATIONARY_WATER:0)
Block(-9,1,4,STATIONARY_WATER:0)
Block(-9,1,5,STATIONARY_WATER:0)
Block(-9,1,6,STATIONARY_WATER:0)
Block(-9,1,7,STATIONARY_WATER:0)
Block(-9,1,8,STAINED_CLAY:4)
Block(-9,2,-8,STAINED_CLAY:4)
Block(-9,2,-7,STATIONARY_WATER:0)
Block(-9,2,-6,STATIONARY_WATER:0)
Block(-9,2,-5,STATIONARY_WATER:0)
Block(-9,2,-4,STATIONARY_WATER:0)
Block(-9,2,-3,STATIONARY_WATER:0)
Block(-9,2,-2,STATIONARY_WATER:0)
Block(-9,2,-1,STATIONARY_WATER:0)
Block(-9,2,0,STATIONARY_WATER:0)
Block(-9,2,1,STATIONARY_WATER:0)
Block(-9,2,2,STATIONARY_WATER:0)
Block(-9,2,3,STATIONARY_WATER:0)
Block(-9,2,4,STATIONARY_WATER:0)
Block(-9,2,5,STATIONARY_WATER:0)
Block(-9,2,6,STATIONARY_WATER:0)
Block(-9,2,7,STATIONARY_WATER:0)
Block(-9,2,8,STAINED_CLAY:4)
Block(-9,3,-8,STAINED_CLAY:4)
Block(-9,3,-7,STATIONARY_WATER:0)
Block(-9,3,-6,STATIONARY_WATER:0)
Block(-9,3,-5,STATIONARY_WATER:0)
Block(-9,3,-4,STATIONARY_WATER:0)
Block(-9,3,-3,STATIONARY_WATER:0)
Block(-9,3,-2,STATIONARY_WATER:0)
Block(-9,3,-1,STATIONARY_WATER:0)
Block(-9,3,0,STATIONARY_WATER:0)
Block(-9,3,1,STATIONARY_WATER:0)
Block(-9,3,2,STATIONARY_WATER:0)
Block(-9,3,3,STATIONARY_WATER:0)
Block(-9,3,4,STATIONARY_WATER:0)
Block(-9,3,5,STATIONARY_WATER:0)
Block(-9,3,6,STATIONARY_WATER:0)
Block(-9,3,7,STATIONARY_WATER:0)
Block(-9,3,8,STAINED_CLAY:4)
Block(-9,4,-8,STAINED_CLAY:4)
Block(-9,4,-7,STATIONARY_WATER:0)
Block(-9,4,-6,STATIONARY_WATER:0)
Block(-9,4,-5,STATIONARY_WATER:0)
Block(-9,4,-4,STATIONARY_WATER:0)
Block(-9,4,-3,STATIONARY_WATER:0)
Block(-9,4,-2,STATIONARY_WATER:0)
Block(-9,4,-1,STATIONARY_WATER:0)
Block(-9,4,0,STATIONARY_WATER:0)
Block(-9,4,1,STATIONARY_WATER:0)
Block(-9,4,2,STATIONARY_WATER:0)
Block(-9,4,3,STATIONARY_WATER:0)
Block(-9,4,4,STATIONARY_WATER:0)
Block(-9,4,5,STATIONARY_WATER:0)
Block(-9,4,6,STATIONARY_WATER:0)
Block(-9,4,7,STATIONARY_WATER:0)
Block(-9,4,8,STAINED_CLAY:4)
Block(-9,5,-8,STAINED_CLAY:4)
Block(-9,5,-7,STATIONARY_WATER:0)
Block(-9,5,-6,STATIONARY_WATER:0)
Block(-9,5,-5,STATIONARY_WATER:0)
Block(-9,5,-4,STATIONARY_WATER:0)
Block(-9,5,-3,STATIONARY_WATER:0)
Block(-9,5,-2,STATIONARY_WATER:0)
Block(-9,5,-1,STATIONARY_WATER:0)
Block(-9,5,0,STATIONARY_WATER:0)
Block(-9,5,1,STATIONARY_WATER:0)
Block(-9,5,2,STATIONARY_WATER:0)
Block(-9,5,3,STATIONARY_WATER:0)
Block(-9,5,4,STATIONARY_WATER:0)
Block(-9,5,5,STATIONARY_WATER:0)
Block(-9,5,6,STATIONARY_WATER:0)
Block(-9,5,7,STATIONARY_WATER:0)
Block(-9,5,8,STAINED_CLAY:4)
Block(-9,6,-8,STAINED_CLAY:4)
Block(-9,6,-7,STATIONARY_WATER:0)
Block(-9,6,-6,STATIONARY_WATER:0)
Block(-9,6,-5,STATIONARY_WATER:0)
Block(-9,6,-4,STATIONARY_WATER:0)
Block(-9,6,-3,STATIONARY_WATER:0)
Block(-9,6,-2,STATIONARY_WATER:0)
Block(-9,6,-1,STATIONARY_WATER:0)
Block(-9,6,0,STATIONARY_WATER:0)
Block(-9,6,1,STATIONARY_WATER:0)
Block(-9,6,2,STATIONARY_WATER:0)
Block(-9,6,3,STATIONARY_WATER:0)
Block(-9,6,4,STATIONARY_WATER:0)
Block(-9,6,5,STATIONARY_WATER:0)
Block(-9,6,6,STATIONARY_WATER:0)
Block(-9,6,7,STATIONARY_WATER:0)
Block(-9,6,8,STAINED_CLAY:4)
Block(-9,7,-8,STAINED_CLAY:4)
Block(-9,7,-7,STATIONARY_WATER:0)
Block(-9,7,-6,STATIONARY_WATER:0)
Block(-9,7,-5,STATIONARY_WATER:0)
Block(-9,7,-4,STATIONARY_WATER:0)
Block(-9,7,-3,STATIONARY_WATER:0)
Block(-9,7,-2,STATIONARY_WATER:0)
Block(-9,7,-1,STATIONARY_WATER:0)
Block(-9,7,0,STATIONARY_WATER:0)
Block(-9,7,1,STATIONARY_WATER:0)
Block(-9,7,2,STATIONARY_WATER:0)
Block(-9,7,3,STATIONARY_WATER:0)
Block(-9,7,4,STATIONARY_WATER:0)
Block(-9,7,5,STATIONARY_WATER:0)
Block(-9,7,6,STATIONARY_WATER:0)
Block(-9,7,7,STATIONARY_WATER:0)
Block(-9,7,8,STAINED_CLAY:4)
Block(-9,8,-8,STAINED_CLAY:4)
Block(-9,8,-7,STATIONARY_WATER:0)
Block(-9,8,-6,STATIONARY_WATER:0)
Block(-9,8,-5,STATIONARY_WATER:0)
Block(-9,8,-4,STATIONARY_WATER:0)
Block(-9,8,-3,STATIONARY_WATER:0)
Block(-9,8,-2,STATIONARY_WATER:0)
Block(-9,8,-1,STATIONARY_WATER:0)
Block(-9,8,0,STATIONARY_WATER:0)
Block(-9,8,1,STATIONARY_WATER:0)
Block(-9,8,2,STATIONARY_WATER:0)
Block(-9,8,3,STATIONARY_WATER:0)
Block(-9,8,4,STATIONARY_WATER:0)
Block(-9,8,5,STATIONARY_WATER:0)
Block(-9,8,6,STATIONARY_WATER:0)
Block(-9,8,7,STATIONARY_WATER:0)
Block(-9,8,8,STAINED_CLAY:4)
Block(-8,0,-9,STAINED_CLAY:4)
Block(-8,0,-8,STAINED_CLAY:4)
Block(-8,0,-7,STAINED_CLAY:4)
Block(-8,0,-6,STAINED_CLAY:4)
Block(-8,0,-5,STAINED_CLAY:4)
Block(-8,0,-4,STAINED_CLAY:4)
Block(-8,0,-3,STAINED_CLAY:4)
Block(-8,0,-2,STAINED_CLAY:4)
Block(-8,0,-1,STAINED_CLAY:4)
Block(-8,0,0,STAINED_CLAY:4)
Block(-8,0,1,STAINED_CLAY:4)
Block(-8,0,2,STAINED_CLAY:4)
Block(-8,0,3,STAINED_CLAY:4)
Block(-8,0,4,STAINED_CLAY:4)
Block(-8,0,5,STAINED_CLAY:4)
Block(-8,0,6,STAINED_CLAY:4)
Block(-8,0,7,STAINED_CLAY:4)
Block(-8,0,8,STAINED_CLAY:4)
Block(-8,0,9,STAINED_CLAY:4)
Block(-8,1,-9,STAINED_CLAY:4)
Block(-8,1,-8,STATIONARY_WATER:0)
Block(-8,1,-7,STATIONARY_WATER:0)
Block(-8,1,-6,STATIONARY_WATER:0)
Block(-8,1,-5,STATIONARY_WATER:0)
Block(-8,1,-4,STATIONARY_WATER:0)
Block(-8,1,-3,STATIONARY_WATER:0)
Block(-8,1,-2,STATIONARY_WATER:0)
Block(-8,1,-1,STATIONARY_WATER:0)
Block(-8,1,0,STATIONARY_WATER:0)
Block(-8,1,1,STATIONARY_WATER:0)
Block(-8,1,2,STATIONARY_WATER:0)
Block(-8,1,3,STATIONARY_WATER:0)
Block(-8,1,4,STATIONARY_WATER:0)
Block(-8,1,5,STATIONARY_WATER:0)
Block(-8,1,6,STATIONARY_WATER:0)
Block(-8,1,7,STATIONARY_WATER:0)
Block(-8,1,8,STATIONARY_WATER:0)
Block(-8,1,9,STAINED_CLAY:4)
Block(-8,2,-9,STAINED_CLAY:4)
Block(-8,2,-8,STATIONARY_WATER:0)
Block(-8,2,-7,STATIONARY_WATER:0)
Block(-8,2,-6,STATIONARY_WATER:0)
Block(-8,2,-5,STATIONARY_WATER:0)
Block(-8,2,-4,STATIONARY_WATER:0)
Block(-8,2,-3,STATIONARY_WATER:0)
Block(-8,2,-2,STATIONARY_WATER:0)
Block(-8,2,-1,STATIONARY_WATER:0)
Block(-8,2,0,STATIONARY_WATER:0)
Block(-8,2,1,STATIONARY_WATER:0)
Block(-8,2,2,STATIONARY_WATER:0)
Block(-8,2,3,STATIONARY_WATER:0)
Block(-8,2,4,STATIONARY_WATER:0)
Block(-8,2,5,STATIONARY_WATER:0)
Block(-8,2,6,STATIONARY_WATER:0)
Block(-8,2,7,STATIONARY_WATER:0)
Block(-8,2,8,STATIONARY_WATER:0)
Block(-8,2,9,STAINED_CLAY:4)
Block(-8,3,-9,STAINED_CLAY:4)
Block(-8,3,-8,STATIONARY_WATER:0)
Block(-8,3,-7,STATIONARY_WATER:0)
Block(-8,3,-6,STATIONARY_WATER:0)
Block(-8,3,-5,STATIONARY_WATER:0)
Block(-8,3,-4,STATIONARY_WATER:0)
Block(-8,3,-3,STATIONARY_WATER:0)
Block(-8,3,-2,STATIONARY_WATER:0)
Block(-8,3,-1,STATIONARY_WATER:0)
Block(-8,3,0,STATIONARY_WATER:0)
Block(-8,3,1,STATIONARY_WATER:0)
Block(-8,3,2,STATIONARY_WATER:0)
Block(-8,3,3,STATIONARY_WATER:0)
Block(-8,3,4,STATIONARY_WATER:0)
Block(-8,3,5,STATIONARY_WATER:0)
Block(-8,3,6,STATIONARY_WATER:0)
Block(-8,3,7,STATIONARY_WATER:0)
Block(-8,3,8,STATIONARY_WATER:0)
Block(-8,3,9,STAINED_CLAY:4)
Block(-8,4,-9,STAINED_CLAY:4)
Block(-8,4,-8,STATIONARY_WATER:0)
Block(-8,4,-7,STATIONARY_WATER:0)
Block(-8,4,-6,STATIONARY_WATER:0)
Block(-8,4,-5,STATIONARY_WATER:0)
Block(-8,4,-4,STATIONARY_WATER:0)
Block(-8,4,-3,STATIONARY_WATER:0)
Block(-8,4,-2,STATIONARY_WATER:0)
Block(-8,4,-1,STATIONARY_WATER:0)
Block(-8,4,0,STATIONARY_WATER:0)
Block(-8,4,1,STATIONARY_WATER:0)
Block(-8,4,2,STATIONARY_WATER:0)
Block(-8,4,3,STATIONARY_WATER:0)
Block(-8,4,4,STATIONARY_WATER:0)
Block(-8,4,5,STATIONARY_WATER:0)
Block(-8,4,6,STATIONARY_WATER:0)
Block(-8,4,7,STATIONARY_WATER:0)
Block(-8,4,8,STATIONARY_WATER:0)
Block(-8,4,9,STAINED_CLAY:4)
Block(-8,5,-9,STAINED_CLAY:4)
Block(-8,5,-8,STATIONARY_WATER:0)
Block(-8,5,-7,STATIONARY_WATER:0)
Block(-8,5,-6,STATIONARY_WATER:0)
Block(-8,5,-5,STATIONARY_WATER:0)
Block(-8,5,-4,STATIONARY_WATER:0)
Block(-8,5,-3,STATIONARY_WATER:0)
Block(-8,5,-2,STATIONARY_WATER:0)
Block(-8,5,-1,STATIONARY_WATER:0)
Block(-8,5,0,STATIONARY_WATER:0)
Block(-8,5,1,STATIONARY_WATER:0)
Block(-8,5,2,STATIONARY_WATER:0)
Block(-8,5,3,STATIONARY_WATER:0)
Block(-8,5,4,STATIONARY_WATER:0)
Block(-8,5,5,STATIONARY_WATER:0)
Block(-8,5,6,STATIONARY_WATER:0)
Block(-8,5,7,STATIONARY_WATER:0)
Block(-8,5,8,STATIONARY_WATER:0)
Block(-8,5,9,STAINED_CLAY:4)
Block(-8,6,-9,STAINED_CLAY:4)
Block(-8,6,-8,STATIONARY_WATER:0)
Block(-8,6,-7,STATIONARY_WATER:0)
Block(-8,6,-6,STATIONARY_WATER:0)
Block(-8,6,-5,STATIONARY_WATER:0)
Block(-8,6,-4,STATIONARY_WATER:0)
Block(-8,6,-3,STATIONARY_WATER:0)
Block(-8,6,-2,STATIONARY_WATER:0)
Block(-8,6,-1,STATIONARY_WATER:0)
Block(-8,6,0,STATIONARY_WATER:0)
Block(-8,6,1,STATIONARY_WATER:0)
Block(-8,6,2,STATIONARY_WATER:0)
Block(-8,6,3,STATIONARY_WATER:0)
Block(-8,6,4,STATIONARY_WATER:0)
Block(-8,6,5,STATIONARY_WATER:0)
Block(-8,6,6,STATIONARY_WATER:0)
Block(-8,6,7,STATIONARY_WATER:0)
Block(-8,6,8,STATIONARY_WATER:0)
Block(-8,6,9,STAINED_CLAY:4)
Block(-8,7,-9,STAINED_CLAY:4)
Block(-8,7,-8,STATIONARY_WATER:0)
Block(-8,7,-7,STATIONARY_WATER:0)
Block(-8,7,-6,STATIONARY_WATER:0)
Block(-8,7,-5,STATIONARY_WATER:0)
Block(-8,7,-4,STATIONARY_WATER:0)
Block(-8,7,-3,STATIONARY_WATER:0)
Block(-8,7,-2,STATIONARY_WATER:0)
Block(-8,7,-1,STATIONARY_WATER:0)
Block(-8,7,0,STATIONARY_WATER:0)
Block(-8,7,1,STATIONARY_WATER:0)
Block(-8,7,2,STATIONARY_WATER:0)
Block(-8,7,3,STATIONARY_WATER:0)
Block(-8,7,4,STATIONARY_WATER:0)
Block(-8,7,5,STATIONARY_WATER:0)
Block(-8,7,6,STATIONARY_WATER:0)
Block(-8,7,7,STATIONARY_WATER:0)
Block(-8,7,8,STATIONARY_WATER:0)
Block(-8,7,9,STAINED_CLAY:4)
Block(-8,8,-9,STAINED_CLAY:4)
Block(-8,8,-8,STATIONARY_WATER:0)
Block(-8,8,-7,STATIONARY_WATER:0)
Block(-8,8,-6,STATIONARY_WATER:0)
Block(-8,8,-5,STATIONARY_WATER:0)
Block(-8,8,-4,STATIONARY_WATER:0)
Block(-8,8,-3,STATIONARY_WATER:0)
Block(-8,8,-2,STATIONARY_WATER:0)
Block(-8,8,-1,STATIONARY_WATER:0)
Block(-8,8,0,STATIONARY_WATER:0)
Block(-8,8,1,STATIONARY_WATER:0)
Block(-8,8,2,STATIONARY_WATER:0)
Block(-8,8,3,STATIONARY_WATER:0)
Block(-8,8,4,STATIONARY_WATER:0)
Block(-8,8,5,STATIONARY_WATER:0)
Block(-8,8,6,STATIONARY_WATER:0)
Block(-8,8,7,STATIONARY_WATER:0)
Block(-8,8,8,STATIONARY_WATER:0)
Block(-8,8,9,STAINED_CLAY:4)
Block(-7,0,-10,STAINED_CLAY:4)
Block(-7,0,-9,STAINED_CLAY:4)
Block(-7,0,-8,STAINED_CLAY:4)
Block(-7,0,-7,STAINED_CLAY:4)
Block(-7,0,-6,STAINED_CLAY:4)
Block(-7,0,-5,STAINED_CLAY:4)
Block(-7,0,-4,STAINED_CLAY:4)
Block(-7,0,-3,STAINED_CLAY:4)
Block(-7,0,-2,STAINED_CLAY:4)
Block(-7,0,-1,STAINED_CLAY:4)
Block(-7,0,0,STAINED_CLAY:4)
Block(-7,0,1,STAINED_CLAY:4)
Block(-7,0,2,STAINED_CLAY:4)
Block(-7,0,3,STAINED_CLAY:4)
Block(-7,0,4,STAINED_CLAY:4)
Block(-7,0,5,STAINED_CLAY:4)
Block(-7,0,6,STAINED_CLAY:4)
Block(-7,0,7,STAINED_CLAY:4)
Block(-7,0,8,STAINED_CLAY:4)
Block(-7,0,9,STAINED_CLAY:4)
Block(-7,0,10,STAINED_CLAY:4)
Block(-7,1,-10,STAINED_CLAY:4)
Block(-7,1,-9,STATIONARY_WATER:0)
Block(-7,1,-8,STATIONARY_WATER:0)
Block(-7,1,-7,STATIONARY_WATER:0)
Block(-7,1,-6,STATIONARY_WATER:0)
Block(-7,1,-5,STATIONARY_WATER:0)
Block(-7,1,-4,STATIONARY_WATER:0)
Block(-7,1,-3,STATIONARY_WATER:0)
Block(-7,1,-2,STATIONARY_WATER:0)
Block(-7,1,-1,STATIONARY_WATER:0)
Block(-7,1,0,STATIONARY_WATER:0)
Block(-7,1,1,STATIONARY_WATER:0)
Block(-7,1,2,STATIONARY_WATER:0)
Block(-7,1,3,STATIONARY_WATER:0)
Block(-7,1,4,STATIONARY_WATER:0)
Block(-7,1,5,STATIONARY_WATER:0)
Block(-7,1,6,STATIONARY_WATER:0)
Block(-7,1,7,STATIONARY_WATER:0)
Block(-7,1,8,STATIONARY_WATER:0)
Block(-7,1,9,STATIONARY_WATER:0)
Block(-7,1,10,STAINED_CLAY:4)
Block(-7,2,-10,STAINED_CLAY:4)
Block(-7,2,-9,STATIONARY_WATER:0)
Block(-7,2,-8,STATIONARY_WATER:0)
Block(-7,2,-7,STATIONARY_WATER:0)
Block(-7,2,-6,STATIONARY_WATER:0)
Block(-7,2,-5,STATIONARY_WATER:0)
Block(-7,2,-4,STATIONARY_WATER:0)
Block(-7,2,-3,STATIONARY_WATER:0)
Block(-7,2,-2,STATIONARY_WATER:0)
Block(-7,2,-1,STATIONARY_WATER:0)
Block(-7,2,0,STATIONARY_WATER:0)
Block(-7,2,1,STATIONARY_WATER:0)
Block(-7,2,2,STATIONARY_WATER:0)
Block(-7,2,3,STATIONARY_WATER:0)
Block(-7,2,4,STATIONARY_WATER:0)
Block(-7,2,5,STATIONARY_WATER:0)
Block(-7,2,6,STATIONARY_WATER:0)
Block(-7,2,7,STATIONARY_WATER:0)
Block(-7,2,8,STATIONARY_WATER:0)
Block(-7,2,9,STATIONARY_WATER:0)
Block(-7,2,10,STAINED_CLAY:4)
Block(-7,3,-10,STAINED_CLAY:4)
Block(-7,3,-9,STATIONARY_WATER:0)
Block(-7,3,-8,STATIONARY_WATER:0)
Block(-7,3,-7,STATIONARY_WATER:0)
Block(-7,3,-6,STATIONARY_WATER:0)
Block(-7,3,-5,STATIONARY_WATER:0)
Block(-7,3,-4,STATIONARY_WATER:0)
Block(-7,3,-3,STATIONARY_WATER:0)
Block(-7,3,-2,STATIONARY_WATER:0)
Block(-7,3,-1,STATIONARY_WATER:0)
Block(-7,3,0,STATIONARY_WATER:0)
Block(-7,3,1,STATIONARY_WATER:0)
Block(-7,3,2,STATIONARY_WATER:0)
Block(-7,3,3,STATIONARY_WATER:0)
Block(-7,3,4,STATIONARY_WATER:0)
Block(-7,3,5,STATIONARY_WATER:0)
Block(-7,3,6,STATIONARY_WATER:0)
Block(-7,3,7,STATIONARY_WATER:0)
Block(-7,3,8,STATIONARY_WATER:0)
Block(-7,3,9,STATIONARY_WATER:0)
Block(-7,3,10,STAINED_CLAY:4)
Block(-7,4,-10,STAINED_CLAY:4)
Block(-7,4,-9,STATIONARY_WATER:0)
Block(-7,4,-8,STATIONARY_WATER:0)
Block(-7,4,-7,STATIONARY_WATER:0)
Block(-7,4,-6,STATIONARY_WATER:0)
Block(-7,4,-5,STATIONARY_WATER:0)
Block(-7,4,-4,STATIONARY_WATER:0)
Block(-7,4,-3,STATIONARY_WATER:0)
Block(-7,4,-2,STATIONARY_WATER:0)
Block(-7,4,-1,STATIONARY_WATER:0)
Block(-7,4,0,STATIONARY_WATER:0)
Block(-7,4,1,STATIONARY_WATER:0)
Block(-7,4,2,STATIONARY_WATER:0)
Block(-7,4,3,STATIONARY_WATER:0)
Block(-7,4,4,STATIONARY_WATER:0)
Block(-7,4,5,STATIONARY_WATER:0)
Block(-7,4,6,STATIONARY_WATER:0)
Block(-7,4,7,STATIONARY_WATER:0)
Block(-7,4,8,STATIONARY_WATER:0)
Block(-7,4,9,STATIONARY_WATER:0)
Block(-7,4,10,STAINED_CLAY:4)
Block(-7,5,-10,STAINED_CLAY:4)
Block(-7,5,-9,STATIONARY_WATER:0)
Block(-7,5,-8,STATIONARY_WATER:0)
Block(-7,5,-7,STATIONARY_WATER:0)
Block(-7,5,-6,STATIONARY_WATER:0)
Block(-7,5,-5,STATIONARY_WATER:0)
Block(-7,5,-4,STATIONARY_WATER:0)
Block(-7,5,-3,STATIONARY_WATER:0)
Block(-7,5,-2,STATIONARY_WATER:0)
Block(-7,5,-1,STATIONARY_WATER:0)
Block(-7,5,0,STATIONARY_WATER:0)
Block(-7,5,1,STATIONARY_WATER:0)
Block(-7,5,2,STATIONARY_WATER:0)
Block(-7,5,3,STATIONARY_WATER:0)
Block(-7,5,4,STATIONARY_WATER:0)
Block(-7,5,5,STATIONARY_WATER:0)
Block(-7,5,6,STATIONARY_WATER:0)
Block(-7,5,7,STATIONARY_WATER:0)
Block(-7,5,8,STATIONARY_WATER:0)
Block(-7,5,9,STATIONARY_WATER:0)
Block(-7,5,10,STAINED_CLAY:4)
Block(-7,6,-10,STAINED_CLAY:4)
Block(-7,6,-9,STATIONARY_WATER:0)
Block(-7,6,-8,STATIONARY_WATER:0)
Block(-7,6,-7,STATIONARY_WATER:0)
Block(-7,6,-6,STATIONARY_WATER:0)
Block(-7,6,-5,STATIONARY_WATER:0)
Block(-7,6,-4,STATIONARY_WATER:0)
Block(-7,6,-3,STATIONARY_WATER:0)
Block(-7,6,-2,STATIONARY_WATER:0)
Block(-7,6,-1,STATIONARY_WATER:0)
Block(-7,6,0,STATIONARY_WATER:0)
Block(-7,6,1,STATIONARY_WATER:0)
Block(-7,6,2,STATIONARY_WATER:0)
Block(-7,6,3,STATIONARY_WATER:0)
Block(-7,6,4,STATIONARY_WATER:0)
Block(-7,6,5,STATIONARY_WATER:0)
Block(-7,6,6,STATIONARY_WATER:0)
Block(-7,6,7,STATIONARY_WATER:0)
Block(-7,6,8,STATIONARY_WATER:0)
Block(-7,6,9,STATIONARY_WATER:0)
Block(-7,6,10,STAINED_CLAY:4)
Block(-7,7,-10,STAINED_CLAY:4)
Block(-7,7,-9,STATIONARY_WATER:0)
Block(-7,7,-8,STATIONARY_WATER:0)
Block(-7,7,-7,STATIONARY_WATER:0)
Block(-7,7,-6,STATIONARY_WATER:0)
Block(-7,7,-5,STATIONARY_WATER:0)
Block(-7,7,-4,STATIONARY_WATER:0)
Block(-7,7,-3,STATIONARY_WATER:0)
Block(-7,7,-2,STATIONARY_WATER:0)
Block(-7,7,-1,STATIONARY_WATER:0)
Block(-7,7,0,STATIONARY_WATER:0)
Block(-7,7,1,STATIONARY_WATER:0)
Block(-7,7,2,STATIONARY_WATER:0)
Block(-7,7,3,STATIONARY_WATER:0)
Block(-7,7,4,STATIONARY_WATER:0)
Block(-7,7,5,STATIONARY_WATER:0)
Block(-7,7,6,STATIONARY_WATER:0)
Block(-7,7,7,STATIONARY_WATER:0)
Block(-7,7,8,STATIONARY_WATER:0)
Block(-7,7,9,STATIONARY_WATER:0)
Block(-7,7,10,STAINED_CLAY:4)
Block(-7,8,-10,STAINED_CLAY:4)
Block(-7,8,-9,STATIONARY_WATER:0)
Block(-7,8,-8,STATIONARY_WATER:0)
Block(-7,8,-7,STATIONARY_WATER:0)
Block(-7,8,-6,STATIONARY_WATER:0)
Block(-7,8,-5,STATIONARY_WATER:0)
Block(-7,8,-4,STATIONARY_WATER:0)
Block(-7,8,-3,STATIONARY_WATER:0)
Block(-7,8,-2,STATIONARY_WATER:0)
Block(-7,8,-1,STATIONARY_WATER:0)
Block(-7,8,0,STATIONARY_WATER:0)
Block(-7,8,1,STATIONARY_WATER:0)
Block(-7,8,2,STATIONARY_WATER:0)
Block(-7,8,3,STATIONARY_WATER:0)
Block(-7,8,4,STATIONARY_WATER:0)
Block(-7,8,5,STATIONARY_WATER:0)
Block(-7,8,6,STATIONARY_WATER:0)
Block(-7,8,7,STATIONARY_WATER:0)
Block(-7,8,8,STATIONARY_WATER:0)
Block(-7,8,9,STATIONARY_WATER:0)
Block(-7,8,10,STAINED_CLAY:4)
Block(-6,0,-10,STAINED_CLAY:4)
Block(-6,0,-9,STAINED_CLAY:4)
Block(-6,0,-8,STAINED_CLAY:4)
Block(-6,0,-7,STAINED_CLAY:4)
Block(-6,0,-6,STAINED_CLAY:4)
Block(-6,0,-5,STAINED_CLAY:4)
Block(-6,0,-4,STAINED_CLAY:4)
Block(-6,0,-3,STAINED_CLAY:4)
Block(-6,0,-2,STAINED_CLAY:4)
Block(-6,0,-1,STAINED_CLAY:4)
Block(-6,0,0,STAINED_CLAY:4)
Block(-6,0,1,STAINED_CLAY:4)
Block(-6,0,2,STAINED_CLAY:4)
Block(-6,0,3,STAINED_CLAY:4)
Block(-6,0,4,STAINED_CLAY:4)
Block(-6,0,5,STAINED_CLAY:4)
Block(-6,0,6,STAINED_CLAY:4)
Block(-6,0,7,STAINED_CLAY:4)
Block(-6,0,8,STAINED_CLAY:4)
Block(-6,0,9,STAINED_CLAY:4)
Block(-6,0,10,STAINED_CLAY:4)
Block(-6,1,-10,STAINED_CLAY:4)
Block(-6,1,-9,STATIONARY_WATER:0)
Block(-6,1,-8,STATIONARY_WATER:0)
Block(-6,1,-7,STATIONARY_WATER:0)
Block(-6,1,-6,STATIONARY_WATER:0)
Block(-6,1,-5,STATIONARY_WATER:0)
Block(-6,1,-4,STATIONARY_WATER:0)
Block(-6,1,-3,STATIONARY_WATER:0)
Block(-6,1,-2,STATIONARY_WATER:0)
Block(-6,1,-1,STATIONARY_WATER:0)
Block(-6,1,0,STATIONARY_WATER:0)
Block(-6,1,1,STATIONARY_WATER:0)
Block(-6,1,2,STATIONARY_WATER:0)
Block(-6,1,3,STATIONARY_WATER:0)
Block(-6,1,4,STATIONARY_WATER:0)
Block(-6,1,5,STATIONARY_WATER:0)
Block(-6,1,6,STATIONARY_WATER:0)
Block(-6,1,7,STATIONARY_WATER:0)
Block(-6,1,8,STATIONARY_WATER:0)
Block(-6,1,9,STATIONARY_WATER:0)
Block(-6,1,10,STAINED_CLAY:4)
Block(-6,2,-10,STAINED_CLAY:4)
Block(-6,2,-9,STATIONARY_WATER:0)
Block(-6,2,-8,STATIONARY_WATER:0)
Block(-6,2,-7,STATIONARY_WATER:0)
Block(-6,2,-6,STATIONARY_WATER:0)
Block(-6,2,-5,STATIONARY_WATER:0)
Block(-6,2,-4,STATIONARY_WATER:0)
Block(-6,2,-3,STATIONARY_WATER:0)
Block(-6,2,-2,STATIONARY_WATER:0)
Block(-6,2,-1,STATIONARY_WATER:0)
Block(-6,2,0,STATIONARY_WATER:0)
Block(-6,2,1,STATIONARY_WATER:0)
Block(-6,2,2,STATIONARY_WATER:0)
Block(-6,2,3,STATIONARY_WATER:0)
Block(-6,2,4,STATIONARY_WATER:0)
Block(-6,2,5,STATIONARY_WATER:0)
Block(-6,2,6,STATIONARY_WATER:0)
Block(-6,2,7,STATIONARY_WATER:0)
Block(-6,2,8,STATIONARY_WATER:0)
Block(-6,2,9,STATIONARY_WATER:0)
Block(-6,2,10,STAINED_CLAY:4)
Block(-6,3,-10,STAINED_CLAY:4)
Block(-6,3,-9,STATIONARY_WATER:0)
Block(-6,3,-8,STATIONARY_WATER:0)
Block(-6,3,-7,STATIONARY_WATER:0)
Block(-6,3,-6,STATIONARY_WATER:0)
Block(-6,3,-5,STATIONARY_WATER:0)
Block(-6,3,-4,STATIONARY_WATER:0)
Block(-6,3,-3,STATIONARY_WATER:0)
Block(-6,3,-2,STATIONARY_WATER:0)
Block(-6,3,-1,STATIONARY_WATER:0)
Block(-6,3,0,STATIONARY_WATER:0)
Block(-6,3,1,STATIONARY_WATER:0)
Block(-6,3,2,STATIONARY_WATER:0)
Block(-6,3,3,STATIONARY_WATER:0)
Block(-6,3,4,STATIONARY_WATER:0)
Block(-6,3,5,STATIONARY_WATER:0)
Block(-6,3,6,STATIONARY_WATER:0)
Block(-6,3,7,STATIONARY_WATER:0)
Block(-6,3,8,STATIONARY_WATER:0)
Block(-6,3,9,STATIONARY_WATER:0)
Block(-6,3,10,STAINED_CLAY:4)
Block(-6,4,-10,STAINED_CLAY:4)
Block(-6,4,-9,STATIONARY_WATER:0)
Block(-6,4,-8,STATIONARY_WATER:0)
Block(-6,4,-7,STATIONARY_WATER:0)
Block(-6,4,-6,STATIONARY_WATER:0)
Block(-6,4,-5,STATIONARY_WATER:0)
Block(-6,4,-4,STATIONARY_WATER:0)
Block(-6,4,-3,STATIONARY_WATER:0)
Block(-6,4,-2,STATIONARY_WATER:0)
Block(-6,4,-1,STATIONARY_WATER:0)
Block(-6,4,0,STATIONARY_WATER:0)
Block(-6,4,1,STATIONARY_WATER:0)
Block(-6,4,2,STATIONARY_WATER:0)
Block(-6,4,3,STATIONARY_WATER:0)
Block(-6,4,4,STATIONARY_WATER:0)
Block(-6,4,5,STATIONARY_WATER:0)
Block(-6,4,6,STATIONARY_WATER:0)
Block(-6,4,7,STATIONARY_WATER:0)
Block(-6,4,8,STATIONARY_WATER:0)
Block(-6,4,9,STATIONARY_WATER:0)
Block(-6,4,10,STAINED_CLAY:4)
Block(-6,5,-10,STAINED_CLAY:4)
Block(-6,5,-9,STATIONARY_WATER:0)
Block(-6,5,-8,STATIONARY_WATER:0)
Block(-6,5,-7,STATIONARY_WATER:0)
Block(-6,5,-6,STATIONARY_WATER:0)
Block(-6,5,-5,STATIONARY_WATER:0)
Block(-6,5,-4,STATIONARY_WATER:0)
Block(-6,5,-3,STATIONARY_WATER:0)
Block(-6,5,-2,STATIONARY_WATER:0)
Block(-6,5,-1,STATIONARY_WATER:0)
Block(-6,5,0,STATIONARY_WATER:0)
Block(-6,5,1,STATIONARY_WATER:0)
Block(-6,5,2,STATIONARY_WATER:0)
Block(-6,5,3,STATIONARY_WATER:0)
Block(-6,5,4,STATIONARY_WATER:0)
Block(-6,5,5,STATIONARY_WATER:0)
Block(-6,5,6,STATIONARY_WATER:0)
Block(-6,5,7,STATIONARY_WATER:0)
Block(-6,5,8,STATIONARY_WATER:0)
Block(-6,5,9,STATIONARY_WATER:0)
Block(-6,5,10,STAINED_CLAY:4)
Block(-6,6,-10,STAINED_CLAY:4)
Block(-6,6,-9,STATIONARY_WATER:0)
Block(-6,6,-8,STATIONARY_WATER:0)
Block(-6,6,-7,STATIONARY_WATER:0)
Block(-6,6,-6,STATIONARY_WATER:0)
Block(-6,6,-5,STATIONARY_WATER:0)
Block(-6,6,-4,STATIONARY_WATER:0)
Block(-6,6,-3,STATIONARY_WATER:0)
Block(-6,6,-2,STATIONARY_WATER:0)
Block(-6,6,-1,STATIONARY_WATER:0)
Block(-6,6,0,STATIONARY_WATER:0)
Block(-6,6,1,STATIONARY_WATER:0)
Block(-6,6,2,STATIONARY_WATER:0)
Block(-6,6,3,STATIONARY_WATER:0)
Block(-6,6,4,STATIONARY_WATER:0)
Block(-6,6,5,STATIONARY_WATER:0)
Block(-6,6,6,STATIONARY_WATER:0)
Block(-6,6,7,STATIONARY_WATER:0)
Block(-6,6,8,STATIONARY_WATER:0)
Block(-6,6,9,STATIONARY_WATER:0)
Block(-6,6,10,STAINED_CLAY:4)
Block(-6,7,-10,STAINED_CLAY:4)
Block(-6,7,-9,STATIONARY_WATER:0)
Block(-6,7,-8,STATIONARY_WATER:0)
Block(-6,7,-7,STATIONARY_WATER:0)
Block(-6,7,-6,STATIONARY_WATER:0)
Block(-6,7,-5,STATIONARY_WATER:0)
Block(-6,7,-4,STATIONARY_WATER:0)
Block(-6,7,-3,STATIONARY_WATER:0)
Block(-6,7,-2,STATIONARY_WATER:0)
Block(-6,7,-1,STATIONARY_WATER:0)
Block(-6,7,0,STATIONARY_WATER:0)
Block(-6,7,1,STATIONARY_WATER:0)
Block(-6,7,2,STATIONARY_WATER:0)
Block(-6,7,3,STATIONARY_WATER:0)
Block(-6,7,4,STATIONARY_WATER:0)
Block(-6,7,5,STATIONARY_WATER:0)
Block(-6,7,6,STATIONARY_WATER:0)
Block(-6,7,7,STATIONARY_WATER:0)
Block(-6,7,8,STATIONARY_WATER:0)
Block(-6,7,9,STATIONARY_WATER:0)
Block(-6,7,10,STAINED_CLAY:4)
Block(-6,8,-10,STAINED_CLAY:4)
Block(-6,8,-9,STATIONARY_WATER:0)
Block(-6,8,-8,STATIONARY_WATER:0)
Block(-6,8,-7,STATIONARY_WATER:0)
Block(-6,8,-6,STATIONARY_WATER:0)
Block(-6,8,-5,STATIONARY_WATER:0)
Block(-6,8,-4,STATIONARY_WATER:0)
Block(-6,8,-3,STATIONARY_WATER:0)
Block(-6,8,-2,STATIONARY_WATER:0)
Block(-6,8,-1,STATIONARY_WATER:0)
Block(-6,8,0,STATIONARY_WATER:0)
Block(-6,8,1,STATIONARY_WATER:0)
Block(-6,8,2,STATIONARY_WATER:0)
Block(-6,8,3,STATIONARY_WATER:0)
Block(-6,8,4,STATIONARY_WATER:0)
Block(-6,8,5,STATIONARY_WATER:0)
Block(-6,8,6,STATIONARY_WATER:0)
Block(-6,8,7,STATIONARY_WATER:0)
Block(-6,8,8,STATIONARY_WATER:0)
Block(-6,8,9,STATIONARY_WATER:0)
Block(-6,8,10,STAINED_CLAY:4)
Block(-5,0,-11,STAINED_CLAY:4)
Block(-5,0,-10,STAINED_CLAY:4)
Block(-5,0,-9,STAINED_CLAY:4)
Block(-5,0,-8,STAINED_CLAY:4)
Block(-5,0,-7,STAINED_CLAY:4)
Block(-5,0,-6,STAINED_CLAY:4)
Block(-5,0,-5,STAINED_CLAY:4)
Block(-5,0,-4,STAINED_CLAY:4)
Block(-5,0,-3,STAINED_CLAY:4)
Block(-5,0,-2,STAINED_CLAY:4)
Block(-5,0,-1,STAINED_CLAY:4)
Block(-5,0,0,STAINED_CLAY:4)
Block(-5,0,1,STAINED_CLAY:4)
Block(-5,0,2,STAINED_CLAY:4)
Block(-5,0,3,STAINED_CLAY:4)
Block(-5,0,4,STAINED_CLAY:4)
Block(-5,0,5,STAINED_CLAY:4)
Block(-5,0,6,STAINED_CLAY:4)
Block(-5,0,7,STAINED_CLAY:4)
Block(-5,0,8,STAINED_CLAY:4)
Block(-5,0,9,STAINED_CLAY:4)
Block(-5,0,10,STAINED_CLAY:4)
Block(-5,0,11,STAINED_CLAY:4)
Block(-5,1,-11,STAINED_CLAY:4)
Block(-5,1,-10,STATIONARY_WATER:0)
Block(-5,1,-9,STATIONARY_WATER:0)
Block(-5,1,-8,STATIONARY_WATER:0)
Block(-5,1,-7,STATIONARY_WATER:0)
Block(-5,1,-6,STATIONARY_WATER:0)
Block(-5,1,-5,STATIONARY_WATER:0)
Block(-5,1,-4,STATIONARY_WATER:0)
Block(-5,1,-3,STATIONARY_WATER:0)
Block(-5,1,-2,STATIONARY_WATER:0)
Block(-5,1,-1,STATIONARY_WATER:0)
Block(-5,1,0,STATIONARY_WATER:0)
Block(-5,1,1,STATIONARY_WATER:0)
Block(-5,1,2,STATIONARY_WATER:0)
Block(-5,1,3,STATIONARY_WATER:0)
Block(-5,1,4,STATIONARY_WATER:0)
Block(-5,1,5,STATIONARY_WATER:0)
Block(-5,1,6,STATIONARY_WATER:0)
Block(-5,1,7,STATIONARY_WATER:0)
Block(-5,1,8,STATIONARY_WATER:0)
Block(-5,1,9,STATIONARY_WATER:0)
Block(-5,1,10,STATIONARY_WATER:0)
Block(-5,1,11,STAINED_CLAY:4)
Block(-5,2,-11,STAINED_CLAY:4)
Block(-5,2,-10,STATIONARY_WATER:0)
Block(-5,2,-9,STATIONARY_WATER:0)
Block(-5,2,-8,STATIONARY_WATER:0)
Block(-5,2,-7,STATIONARY_WATER:0)
Block(-5,2,-6,STATIONARY_WATER:0)
Block(-5,2,-5,STATIONARY_WATER:0)
Block(-5,2,-4,STATIONARY_WATER:0)
Block(-5,2,-3,STATIONARY_WATER:0)
Block(-5,2,-2,STATIONARY_WATER:0)
Block(-5,2,-1,STATIONARY_WATER:0)
Block(-5,2,0,STATIONARY_WATER:0)
Block(-5,2,1,STATIONARY_WATER:0)
Block(-5,2,2,STATIONARY_WATER:0)
Block(-5,2,3,STATIONARY_WATER:0)
Block(-5,2,4,STATIONARY_WATER:0)
Block(-5,2,5,STATIONARY_WATER:0)
Block(-5,2,6,STATIONARY_WATER:0)
Block(-5,2,7,STATIONARY_WATER:0)
Block(-5,2,8,STATIONARY_WATER:0)
Block(-5,2,9,STATIONARY_WATER:0)
Block(-5,2,10,STATIONARY_WATER:0)
Block(-5,2,11,STAINED_CLAY:4)
Block(-5,3,-11,STAINED_CLAY:4)
Block(-5,3,-10,STATIONARY_WATER:0)
Block(-5,3,-9,STATIONARY_WATER:0)
Block(-5,3,-8,STATIONARY_WATER:0)
Block(-5,3,-7,STATIONARY_WATER:0)
Block(-5,3,-6,STATIONARY_WATER:0)
Block(-5,3,-5,STATIONARY_WATER:0)
Block(-5,3,-4,STATIONARY_WATER:0)
Block(-5,3,-3,STATIONARY_WATER:0)
Block(-5,3,-2,STATIONARY_WATER:0)
Block(-5,3,-1,STATIONARY_WATER:0)
Block(-5,3,0,STATIONARY_WATER:0)
Block(-5,3,1,STATIONARY_WATER:0)
Block(-5,3,2,STATIONARY_WATER:0)
Block(-5,3,3,STATIONARY_WATER:0)
Block(-5,3,4,STATIONARY_WATER:0)
Block(-5,3,5,STATIONARY_WATER:0)
Block(-5,3,6,STATIONARY_WATER:0)
Block(-5,3,7,STATIONARY_WATER:0)
Block(-5,3,8,STATIONARY_WATER:0)
Block(-5,3,9,STATIONARY_WATER:0)
Block(-5,3,10,STATIONARY_WATER:0)
Block(-5,3,11,STAINED_CLAY:4)
Block(-5,4,-11,STAINED_CLAY:4)
Block(-5,4,-10,STATIONARY_WATER:0)
Block(-5,4,-9,STATIONARY_WATER:0)
Block(-5,4,-8,STATIONARY_WATER:0)
Block(-5,4,-7,STATIONARY_WATER:0)
Block(-5,4,-6,STATIONARY_WATER:0)
Block(-5,4,-5,STATIONARY_WATER:0)
Block(-5,4,-4,STATIONARY_WATER:0)
Block(-5,4,-3,STATIONARY_WATER:0)
Block(-5,4,-2,STATIONARY_WATER:0)
Block(-5,4,-1,STATIONARY_WATER:0)
Block(-5,4,0,STATIONARY_WATER:0)
Block(-5,4,1,STATIONARY_WATER:0)
Block(-5,4,2,STATIONARY_WATER:0)
Block(-5,4,3,STATIONARY_WATER:0)
Block(-5,4,4,STATIONARY_WATER:0)
Block(-5,4,5,STATIONARY_WATER:0)
Block(-5,4,6,STATIONARY_WATER:0)
Block(-5,4,7,STATIONARY_WATER:0)
Block(-5,4,8,STATIONARY_WATER:0)
Block(-5,4,9,STATIONARY_WATER:0)
Block(-5,4,10,STATIONARY_WATER:0)
Block(-5,4,11,STAINED_CLAY:4)
Block(-5,5,-11,STAINED_CLAY:4)
Block(-5,5,-10,STATIONARY_WATER:0)
Block(-5,5,-9,STATIONARY_WATER:0)
Block(-5,5,-8,STATIONARY_WATER:0)
Block(-5,5,-7,STATIONARY_WATER:0)
Block(-5,5,-6,STATIONARY_WATER:0)
Block(-5,5,-5,STATIONARY_WATER:0)
Block(-5,5,-4,STATIONARY_WATER:0)
Block(-5,5,-3,STATIONARY_WATER:0)
Block(-5,5,-2,STATIONARY_WATER:0)
Block(-5,5,-1,STATIONARY_WATER:0)
Block(-5,5,0,STATIONARY_WATER:0)
Block(-5,5,1,STATIONARY_WATER:0)
Block(-5,5,2,STATIONARY_WATER:0)
Block(-5,5,3,STATIONARY_WATER:0)
Block(-5,5,4,STATIONARY_WATER:0)
Block(-5,5,5,STATIONARY_WATER:0)
Block(-5,5,6,STATIONARY_WATER:0)
Block(-5,5,7,STATIONARY_WATER:0)
Block(-5,5,8,STATIONARY_WATER:0)
Block(-5,5,9,STATIONARY_WATER:0)
Block(-5,5,10,STATIONARY_WATER:0)
Block(-5,5,11,STAINED_CLAY:4)
Block(-5,6,-11,STAINED_CLAY:4)
Block(-5,6,-10,STATIONARY_WATER:0)
Block(-5,6,-9,STATIONARY_WATER:0)
Block(-5,6,-8,STATIONARY_WATER:0)
Block(-5,6,-7,STATIONARY_WATER:0)
Block(-5,6,-6,STATIONARY_WATER:0)
Block(-5,6,-5,STATIONARY_WATER:0)
Block(-5,6,-4,STATIONARY_WATER:0)
Block(-5,6,-3,STATIONARY_WATER:0)
Block(-5,6,-2,STATIONARY_WATER:0)
Block(-5,6,-1,STATIONARY_WATER:0)
Block(-5,6,0,STATIONARY_WATER:0)
Block(-5,6,1,STATIONARY_WATER:0)
Block(-5,6,2,STATIONARY_WATER:0)
Block(-5,6,3,STATIONARY_WATER:0)
Block(-5,6,4,STATIONARY_WATER:0)
Block(-5,6,5,STATIONARY_WATER:0)
Block(-5,6,6,STATIONARY_WATER:0)
Block(-5,6,7,STATIONARY_WATER:0)
Block(-5,6,8,STATIONARY_WATER:0)
Block(-5,6,9,STATIONARY_WATER:0)
Block(-5,6,10,STATIONARY_WATER:0)
Block(-5,6,11,STAINED_CLAY:4)
Block(-5,7,-11,STAINED_CLAY:4)
Block(-5,7,-10,STATIONARY_WATER:0)
Block(-5,7,-9,STATIONARY_WATER:0)
Block(-5,7,-8,STATIONARY_WATER:0)
Block(-5,7,-7,STATIONARY_WATER:0)
Block(-5,7,-6,STATIONARY_WATER:0)
Block(-5,7,-5,STATIONARY_WATER:0)
Block(-5,7,-4,STATIONARY_WATER:0)
Block(-5,7,-3,STATIONARY_WATER:0)
Block(-5,7,-2,STATIONARY_WATER:0)
Block(-5,7,-1,STATIONARY_WATER:0)
Block(-5,7,0,STATIONARY_WATER:0)
Block(-5,7,1,STATIONARY_WATER:0)
Block(-5,7,2,STATIONARY_WATER:0)
Block(-5,7,3,STATIONARY_WATER:0)
Block(-5,7,4,STATIONARY_WATER:0)
Block(-5,7,5,STATIONARY_WATER:0)
Block(-5,7,6,STATIONARY_WATER:0)
Block(-5,7,7,STATIONARY_WATER:0)
Block(-5,7,8,STATIONARY_WATER:0)
Block(-5,7,9,STATIONARY_WATER:0)
Block(-5,7,10,STATIONARY_WATER:0)
Block(-5,7,11,STAINED_CLAY:4)
Block(-5,8,-11,STAINED_CLAY:4)
Block(-5,8,-10,STATIONARY_WATER:0)
Block(-5,8,-9,STATIONARY_WATER:0)
Block(-5,8,-8,STATIONARY_WATER:0)
Block(-5,8,-7,STATIONARY_WATER:0)
Block(-5,8,-6,STATIONARY_WATER:0)
Block(-5,8,-5,STATIONARY_WATER:0)
Block(-5,8,-4,STATIONARY_WATER:0)
Block(-5,8,-3,STATIONARY_WATER:0)
Block(-5,8,-2,STATIONARY_WATER:0)
Block(-5,8,-1,STATIONARY_WATER:0)
Block(-5,8,0,STATIONARY_WATER:0)
Block(-5,8,1,STATIONARY_WATER:0)
Block(-5,8,2,STATIONARY_WATER:0)
Block(-5,8,3,STATIONARY_WATER:0)
Block(-5,8,4,STATIONARY_WATER:0)
Block(-5,8,5,STATIONARY_WATER:0)
Block(-5,8,6,STATIONARY_WATER:0)
Block(-5,8,7,STATIONARY_WATER:0)
Block(-5,8,8,STATIONARY_WATER:0)
Block(-5,8,9,STATIONARY_WATER:0)
Block(-5,8,10,STATIONARY_WATER:0)
Block(-5,8,11,STAINED_CLAY:4)
Block(-4,0,-11,STAINED_CLAY:4)
Block(-4,0,-10,STAINED_CLAY:4)
Block(-4,0,-9,STAINED_CLAY:4)
Block(-4,0,-8,STAINED_CLAY:4)
Block(-4,0,-7,STAINED_CLAY:4)
Block(-4,0,-6,STAINED_CLAY:4)
Block(-4,0,-5,STAINED_CLAY:4)
Block(-4,0,-4,STAINED_CLAY:4)
Block(-4,0,-3,STAINED_CLAY:4)
Block(-4,0,-2,STAINED_CLAY:4)
Block(-4,0,-1,STAINED_CLAY:4)
Block(-4,0,0,STAINED_CLAY:4)
Block(-4,0,1,STAINED_CLAY:4)
Block(-4,0,2,STAINED_CLAY:4)
Block(-4,0,3,STAINED_CLAY:4)
Block(-4,0,4,STAINED_CLAY:4)
Block(-4,0,5,STAINED_CLAY:4)
Block(-4,0,6,STAINED_CLAY:4)
Block(-4,0,7,STAINED_CLAY:4)
Block(-4,0,8,STAINED_CLAY:4)
Block(-4,0,9,STAINED_CLAY:4)
Block(-4,0,10,STAINED_CLAY:4)
Block(-4,0,11,STAINED_CLAY:4)
Block(-4,1,-11,STAINED_CLAY:4)
Block(-4,1,-10,STATIONARY_WATER:0)
Block(-4,1,-9,STATIONARY_WATER:0)
Block(-4,1,-8,STATIONARY_WATER:0)
Block(-4,1,-7,STATIONARY_WATER:0)
Block(-4,1,-6,STATIONARY_WATER:0)
Block(-4,1,-5,STATIONARY_WATER:0)
Block(-4,1,-4,STATIONARY_WATER:0)
Block(-4,1,-3,STATIONARY_WATER:0)
Block(-4,1,-2,STATIONARY_WATER:0)
Block(-4,1,-1,STATIONARY_WATER:0)
Block(-4,1,0,STATIONARY_WATER:0)
Block(-4,1,1,STATIONARY_WATER:0)
Block(-4,1,2,STATIONARY_WATER:0)
Block(-4,1,3,STATIONARY_WATER:0)
Block(-4,1,4,STATIONARY_WATER:0)
Block(-4,1,5,STATIONARY_WATER:0)
Block(-4,1,6,STATIONARY_WATER:0)
Block(-4,1,7,STATIONARY_WATER:0)
Block(-4,1,8,STATIONARY_WATER:0)
Block(-4,1,9,STATIONARY_WATER:0)
Block(-4,1,10,STATIONARY_WATER:0)
Block(-4,1,11,STAINED_CLAY:4)
Block(-4,2,-11,STAINED_CLAY:4)
Block(-4,2,-10,STATIONARY_WATER:0)
Block(-4,2,-9,STATIONARY_WATER:0)
Block(-4,2,-8,STATIONARY_WATER:0)
Block(-4,2,-7,STATIONARY_WATER:0)
Block(-4,2,-6,STATIONARY_WATER:0)
Block(-4,2,-5,STATIONARY_WATER:0)
Block(-4,2,-4,STATIONARY_WATER:0)
Block(-4,2,-3,STATIONARY_WATER:0)
Block(-4,2,-2,STATIONARY_WATER:0)
Block(-4,2,-1,STATIONARY_WATER:0)
Block(-4,2,0,STATIONARY_WATER:0)
Block(-4,2,1,STATIONARY_WATER:0)
Block(-4,2,2,STATIONARY_WATER:0)
Block(-4,2,3,STATIONARY_WATER:0)
Block(-4,2,4,STATIONARY_WATER:0)
Block(-4,2,5,STATIONARY_WATER:0)
Block(-4,2,6,STATIONARY_WATER:0)
Block(-4,2,7,STATIONARY_WATER:0)
Block(-4,2,8,STATIONARY_WATER:0)
Block(-4,2,9,STATIONARY_WATER:0)
Block(-4,2,10,STATIONARY_WATER:0)
Block(-4,2,11,STAINED_CLAY:4)
Block(-4,3,-11,STAINED_CLAY:4)
Block(-4,3,-10,STATIONARY_WATER:0)
Block(-4,3,-9,STATIONARY_WATER:0)
Block(-4,3,-8,STATIONARY_WATER:0)
Block(-4,3,-7,STATIONARY_WATER:0)
Block(-4,3,-6,STATIONARY_WATER:0)
Block(-4,3,-5,STATIONARY_WATER:0)
Block(-4,3,-4,STATIONARY_WATER:0)
Block(-4,3,-3,STATIONARY_WATER:0)
Block(-4,3,-2,STATIONARY_WATER:0)
Block(-4,3,-1,STATIONARY_WATER:0)
Block(-4,3,0,STATIONARY_WATER:0)
Block(-4,3,1,STATIONARY_WATER:0)
Block(-4,3,2,STATIONARY_WATER:0)
Block(-4,3,3,STATIONARY_WATER:0)
Block(-4,3,4,STATIONARY_WATER:0)
Block(-4,3,5,STATIONARY_WATER:0)
Block(-4,3,6,STATIONARY_WATER:0)
Block(-4,3,7,STATIONARY_WATER:0)
Block(-4,3,8,STATIONARY_WATER:0)
Block(-4,3,9,STATIONARY_WATER:0)
Block(-4,3,10,STATIONARY_WATER:0)
Block(-4,3,11,STAINED_CLAY:4)
Block(-4,4,-11,STAINED_CLAY:4)
Block(-4,4,-10,STATIONARY_WATER:0)
Block(-4,4,-9,STATIONARY_WATER:0)
Block(-4,4,-8,STATIONARY_WATER:0)
Block(-4,4,-7,STATIONARY_WATER:0)
Block(-4,4,-6,STATIONARY_WATER:0)
Block(-4,4,-5,STATIONARY_WATER:0)
Block(-4,4,-4,STATIONARY_WATER:0)
Block(-4,4,-3,STATIONARY_WATER:0)
Block(-4,4,-2,STATIONARY_WATER:0)
Block(-4,4,-1,STATIONARY_WATER:0)
Block(-4,4,0,STATIONARY_WATER:0)
Block(-4,4,1,STATIONARY_WATER:0)
Block(-4,4,2,STATIONARY_WATER:0)
Block(-4,4,3,STATIONARY_WATER:0)
Block(-4,4,4,STATIONARY_WATER:0)
Block(-4,4,5,STATIONARY_WATER:0)
Block(-4,4,6,STATIONARY_WATER:0)
Block(-4,4,7,STATIONARY_WATER:0)
Block(-4,4,8,STATIONARY_WATER:0)
Block(-4,4,9,STATIONARY_WATER:0)
Block(-4,4,10,STATIONARY_WATER:0)
Block(-4,4,11,STAINED_CLAY:4)
Block(-4,5,-11,STAINED_CLAY:4)
Block(-4,5,-10,STATIONARY_WATER:0)
Block(-4,5,-9,STATIONARY_WATER:0)
Block(-4,5,-8,STATIONARY_WATER:0)
Block(-4,5,-7,STATIONARY_WATER:0)
Block(-4,5,-6,STATIONARY_WATER:0)
Block(-4,5,-5,STATIONARY_WATER:0)
Block(-4,5,-4,STATIONARY_WATER:0)
Block(-4,5,-3,STATIONARY_WATER:0)
Block(-4,5,-2,STATIONARY_WATER:0)
Block(-4,5,-1,STATIONARY_WATER:0)
Block(-4,5,0,STATIONARY_WATER:0)
Block(-4,5,1,STATIONARY_WATER:0)
Block(-4,5,2,STATIONARY_WATER:0)
Block(-4,5,3,STATIONARY_WATER:0)
Block(-4,5,4,STATIONARY_WATER:0)
Block(-4,5,5,STATIONARY_WATER:0)
Block(-4,5,6,STATIONARY_WATER:0)
Block(-4,5,7,STATIONARY_WATER:0)
Block(-4,5,8,STATIONARY_WATER:0)
Block(-4,5,9,STATIONARY_WATER:0)
Block(-4,5,10,STATIONARY_WATER:0)
Block(-4,5,11,STAINED_CLAY:4)
Block(-4,6,-11,STAINED_CLAY:4)
Block(-4,6,-10,STATIONARY_WATER:0)
Block(-4,6,-9,STATIONARY_WATER:0)
Block(-4,6,-8,STATIONARY_WATER:0)
Block(-4,6,-7,STATIONARY_WATER:0)
Block(-4,6,-6,STATIONARY_WATER:0)
Block(-4,6,-5,STATIONARY_WATER:0)
Block(-4,6,-4,STATIONARY_WATER:0)
Block(-4,6,-3,STATIONARY_WATER:0)
Block(-4,6,-2,STATIONARY_WATER:0)
Block(-4,6,-1,STATIONARY_WATER:0)
Block(-4,6,0,STATIONARY_WATER:0)
Block(-4,6,1,STATIONARY_WATER:0)
Block(-4,6,2,STATIONARY_WATER:0)
Block(-4,6,3,STATIONARY_WATER:0)
Block(-4,6,4,STATIONARY_WATER:0)
Block(-4,6,5,STATIONARY_WATER:0)
Block(-4,6,6,STATIONARY_WATER:0)
Block(-4,6,7,STATIONARY_WATER:0)
Block(-4,6,8,STATIONARY_WATER:0)
Block(-4,6,9,STATIONARY_WATER:0)
Block(-4,6,10,STATIONARY_WATER:0)
Block(-4,6,11,STAINED_CLAY:4)
Block(-4,7,-11,STAINED_CLAY:4)
Block(-4,7,-10,STATIONARY_WATER:0)
Block(-4,7,-9,STATIONARY_WATER:0)
Block(-4,7,-8,STATIONARY_WATER:0)
Block(-4,7,-7,STATIONARY_WATER:0)
Block(-4,7,-6,STATIONARY_WATER:0)
Block(-4,7,-5,STATIONARY_WATER:0)
Block(-4,7,-4,STATIONARY_WATER:0)
Block(-4,7,-3,STATIONARY_WATER:0)
Block(-4,7,-2,STATIONARY_WATER:0)
Block(-4,7,-1,STATIONARY_WATER:0)
Block(-4,7,0,STATIONARY_WATER:0)
Block(-4,7,1,STATIONARY_WATER:0)
Block(-4,7,2,STATIONARY_WATER:0)
Block(-4,7,3,STATIONARY_WATER:0)
Block(-4,7,4,STATIONARY_WATER:0)
Block(-4,7,5,STATIONARY_WATER:0)
Block(-4,7,6,STATIONARY_WATER:0)
Block(-4,7,7,STATIONARY_WATER:0)
Block(-4,7,8,STATIONARY_WATER:0)
Block(-4,7,9,STATIONARY_WATER:0)
Block(-4,7,10,STATIONARY_WATER:0)
Block(-4,7,11,STAINED_CLAY:4)
Block(-4,8,-11,STAINED_CLAY:4)
Block(-4,8,-10,STATIONARY_WATER:0)
Block(-4,8,-9,STATIONARY_WATER:0)
Block(-4,8,-8,STATIONARY_WATER:0)
Block(-4,8,-7,STATIONARY_WATER:0)
Block(-4,8,-6,STATIONARY_WATER:0)
Block(-4,8,-5,STATIONARY_WATER:0)
Block(-4,8,-4,STATIONARY_WATER:0)
Block(-4,8,-3,STATIONARY_WATER:0)
Block(-4,8,-2,STATIONARY_WATER:0)
Block(-4,8,-1,STATIONARY_WATER:0)
Block(-4,8,0,STATIONARY_WATER:0)
Block(-4,8,1,STATIONARY_WATER:0)
Block(-4,8,2,STATIONARY_WATER:0)
Block(-4,8,3,STATIONARY_WATER:0)
Block(-4,8,4,STATIONARY_WATER:0)
Block(-4,8,5,STATIONARY_WATER:0)
Block(-4,8,6,STATIONARY_WATER:0)
Block(-4,8,7,STATIONARY_WATER:0)
Block(-4,8,8,STATIONARY_WATER:0)
Block(-4,8,9,STATIONARY_WATER:0)
Block(-4,8,10,STATIONARY_WATER:0)
Block(-4,8,11,STAINED_CLAY:4)
Block(-3,0,-12,STAINED_CLAY:4)
Block(-3,0,-11,STAINED_CLAY:4)
Block(-3,0,-10,STAINED_CLAY:4)
Block(-3,0,-9,STAINED_CLAY:4)
Block(-3,0,-8,STAINED_CLAY:4)
Block(-3,0,-7,STAINED_CLAY:4)
Block(-3,0,-6,STAINED_CLAY:4)
Block(-3,0,-5,STAINED_CLAY:4)
Block(-3,0,-4,STAINED_CLAY:4)
Block(-3,0,-3,STAINED_CLAY:4)
Block(-3,0,-2,STAINED_CLAY:4)
Block(-3,0,-1,STAINED_CLAY:4)
Block(-3,0,0,STAINED_CLAY:4)
Block(-3,0,1,STAINED_CLAY:4)
Block(-3,0,2,STAINED_CLAY:4)
Block(-3,0,3,STAINED_CLAY:4)
Block(-3,0,4,STAINED_CLAY:4)
Block(-3,0,5,STAINED_CLAY:4)
Block(-3,0,6,STAINED_CLAY:4)
Block(-3,0,7,STAINED_CLAY:4)
Block(-3,0,8,STAINED_CLAY:4)
Block(-3,0,9,STAINED_CLAY:4)
Block(-3,0,10,STAINED_CLAY:4)
Block(-3,0,11,STAINED_CLAY:4)
Block(-3,0,12,STAINED_CLAY:4)
Block(-3,1,-12,STAINED_CLAY:4)
Block(-3,1,-11,STATIONARY_WATER:0)
Block(-3,1,-10,STATIONARY_WATER:0)
Block(-3,1,-9,STATIONARY_WATER:0)
Block(-3,1,-8,STATIONARY_WATER:0)
Block(-3,1,-7,STATIONARY_WATER:0)
Block(-3,1,-6,STATIONARY_WATER:0)
Block(-3,1,-5,STATIONARY_WATER:0)
Block(-3,1,-4,STATIONARY_WATER:0)
Block(-3,1,-3,STATIONARY_WATER:0)
Block(-3,1,-2,STATIONARY_WATER:0)
Block(-3,1,-1,STATIONARY_WATER:0)
Block(-3,1,0,STATIONARY_WATER:0)
Block(-3,1,1,STATIONARY_WATER:0)
Block(-3,1,2,STATIONARY_WATER:0)
Block(-3,1,3,STATIONARY_WATER:0)
Block(-3,1,4,STATIONARY_WATER:0)
Block(-3,1,5,STATIONARY_WATER:0)
Block(-3,1,6,STATIONARY_WATER:0)
Block(-3,1,7,STATIONARY_WATER:0)
Block(-3,1,8,STATIONARY_WATER:0)
Block(-3,1,9,STATIONARY_WATER:0)
Block(-3,1,10,STATIONARY_WATER:0)
Block(-3,1,11,STATIONARY_WATER:0)
Block(-3,1,12,STAINED_CLAY:4)
Block(-3,2,-12,STAINED_CLAY:4)
Block(-3,2,-11,STATIONARY_WATER:0)
Block(-3,2,-10,STATIONARY_WATER:0)
Block(-3,2,-9,STATIONARY_WATER:0)
Block(-3,2,-8,STATIONARY_WATER:0)
Block(-3,2,-7,STATIONARY_WATER:0)
Block(-3,2,-6,STATIONARY_WATER:0)
Block(-3,2,-5,STATIONARY_WATER:0)
Block(-3,2,-4,STATIONARY_WATER:0)
Block(-3,2,-3,STATIONARY_WATER:0)
Block(-3,2,-2,STATIONARY_WATER:0)
Block(-3,2,-1,STATIONARY_WATER:0)
Block(-3,2,0,STATIONARY_WATER:0)
Block(-3,2,1,STATIONARY_WATER:0)
Block(-3,2,2,STATIONARY_WATER:0)
Block(-3,2,3,STATIONARY_WATER:0)
Block(-3,2,4,STATIONARY_WATER:0)
Block(-3,2,5,STATIONARY_WATER:0)
Block(-3,2,6,STATIONARY_WATER:0)
Block(-3,2,7,STATIONARY_WATER:0)
Block(-3,2,8,STATIONARY_WATER:0)
Block(-3,2,9,STATIONARY_WATER:0)
Block(-3,2,10,STATIONARY_WATER:0)
Block(-3,2,11,STATIONARY_WATER:0)
Block(-3,2,12,STAINED_CLAY:4)
Block(-3,3,-12,STAINED_CLAY:4)
Block(-3,3,-11,STATIONARY_WATER:0)
Block(-3,3,-10,STATIONARY_WATER:0)
Block(-3,3,-9,STATIONARY_WATER:0)
Block(-3,3,-8,STATIONARY_WATER:0)
Block(-3,3,-7,STATIONARY_WATER:0)
Block(-3,3,-6,STATIONARY_WATER:0)
Block(-3,3,-5,STATIONARY_WATER:0)
Block(-3,3,-4,STATIONARY_WATER:0)
Block(-3,3,-3,STATIONARY_WATER:0)
Block(-3,3,-2,STATIONARY_WATER:0)
Block(-3,3,-1,STATIONARY_WATER:0)
Block(-3,3,0,STATIONARY_WATER:0)
Block(-3,3,1,STATIONARY_WATER:0)
Block(-3,3,2,STATIONARY_WATER:0)
Block(-3,3,3,STATIONARY_WATER:0)
Block(-3,3,4,STATIONARY_WATER:0)
Block(-3,3,5,STATIONARY_WATER:0)
Block(-3,3,6,STATIONARY_WATER:0)
Block(-3,3,7,STATIONARY_WATER:0)
Block(-3,3,8,STATIONARY_WATER:0)
Block(-3,3,9,STATIONARY_WATER:0)
Block(-3,3,10,STATIONARY_WATER:0)
Block(-3,3,11,STATIONARY_WATER:0)
Block(-3,3,12,STAINED_CLAY:4)
Block(-3,4,-12,STAINED_CLAY:4)
Block(-3,4,-11,STATIONARY_WATER:0)
Block(-3,4,-10,STATIONARY_WATER:0)
Block(-3,4,-9,STATIONARY_WATER:0)
Block(-3,4,-8,STATIONARY_WATER:0)
Block(-3,4,-7,STATIONARY_WATER:0)
Block(-3,4,-6,STATIONARY_WATER:0)
Block(-3,4,-5,STATIONARY_WATER:0)
Block(-3,4,-4,STATIONARY_WATER:0)
Block(-3,4,-3,STATIONARY_WATER:0)
Block(-3,4,-2,STATIONARY_WATER:0)
Block(-3,4,-1,STATIONARY_WATER:0)
Block(-3,4,0,STATIONARY_WATER:0)
Block(-3,4,1,STATIONARY_WATER:0)
Block(-3,4,2,STATIONARY_WATER:0)
Block(-3,4,3,STATIONARY_WATER:0)
Block(-3,4,4,STATIONARY_WATER:0)
Block(-3,4,5,STATIONARY_WATER:0)
Block(-3,4,6,STATIONARY_WATER:0)
Block(-3,4,7,STATIONARY_WATER:0)
Block(-3,4,8,STATIONARY_WATER:0)
Block(-3,4,9,STATIONARY_WATER:0)
Block(-3,4,10,STATIONARY_WATER:0)
Block(-3,4,11,STATIONARY_WATER:0)
Block(-3,4,12,STAINED_CLAY:4)
Block(-3,5,-12,STAINED_CLAY:4)
Block(-3,5,-11,STATIONARY_WATER:0)
Block(-3,5,-10,STATIONARY_WATER:0)
Block(-3,5,-9,STATIONARY_WATER:0)
Block(-3,5,-8,STATIONARY_WATER:0)
Block(-3,5,-7,STATIONARY_WATER:0)
Block(-3,5,-6,STATIONARY_WATER:0)
Block(-3,5,-5,STATIONARY_WATER:0)
Block(-3,5,-4,STATIONARY_WATER:0)
Block(-3,5,-3,STATIONARY_WATER:0)
Block(-3,5,-2,STATIONARY_WATER:0)
Block(-3,5,-1,STATIONARY_WATER:0)
Block(-3,5,0,STATIONARY_WATER:0)
Block(-3,5,1,STATIONARY_WATER:0)
Block(-3,5,2,STATIONARY_WATER:0)
Block(-3,5,3,STATIONARY_WATER:0)
Block(-3,5,4,STATIONARY_WATER:0)
Block(-3,5,5,STATIONARY_WATER:0)
Block(-3,5,6,STATIONARY_WATER:0)
Block(-3,5,7,STATIONARY_WATER:0)
Block(-3,5,8,STATIONARY_WATER:0)
Block(-3,5,9,STATIONARY_WATER:0)
Block(-3,5,10,STATIONARY_WATER:0)
Block(-3,5,11,STATIONARY_WATER:0)
Block(-3,5,12,STAINED_CLAY:4)
Block(-3,6,-12,STAINED_CLAY:4)
Block(-3,6,-11,STATIONARY_WATER:0)
Block(-3,6,-10,STATIONARY_WATER:0)
Block(-3,6,-9,STATIONARY_WATER:0)
Block(-3,6,-8,STATIONARY_WATER:0)
Block(-3,6,-7,STATIONARY_WATER:0)
Block(-3,6,-6,STATIONARY_WATER:0)
Block(-3,6,-5,STATIONARY_WATER:0)
Block(-3,6,-4,STATIONARY_WATER:0)
Block(-3,6,-3,STATIONARY_WATER:0)
Block(-3,6,-2,STATIONARY_WATER:0)
Block(-3,6,-1,STATIONARY_WATER:0)
Block(-3,6,0,STATIONARY_WATER:0)
Block(-3,6,1,STATIONARY_WATER:0)
Block(-3,6,2,STATIONARY_WATER:0)
Block(-3,6,3,STATIONARY_WATER:0)
Block(-3,6,4,STATIONARY_WATER:0)
Block(-3,6,5,STATIONARY_WATER:0)
Block(-3,6,6,STATIONARY_WATER:0)
Block(-3,6,7,STATIONARY_WATER:0)
Block(-3,6,8,STATIONARY_WATER:0)
Block(-3,6,9,STATIONARY_WATER:0)
Block(-3,6,10,STATIONARY_WATER:0)
Block(-3,6,11,STATIONARY_WATER:0)
Block(-3,6,12,STAINED_CLAY:4)
Block(-3,7,-12,STAINED_CLAY:4)
Block(-3,7,-11,STATIONARY_WATER:0)
Block(-3,7,-10,STATIONARY_WATER:0)
Block(-3,7,-9,STATIONARY_WATER:0)
Block(-3,7,-8,STATIONARY_WATER:0)
Block(-3,7,-7,STATIONARY_WATER:0)
Block(-3,7,-6,STATIONARY_WATER:0)
Block(-3,7,-5,STATIONARY_WATER:0)
Block(-3,7,-4,STATIONARY_WATER:0)
Block(-3,7,-3,STATIONARY_WATER:0)
Block(-3,7,-2,STATIONARY_WATER:0)
Block(-3,7,-1,STATIONARY_WATER:0)
Block(-3,7,0,STATIONARY_WATER:0)
Block(-3,7,1,STATIONARY_WATER:0)
Block(-3,7,2,STATIONARY_WATER:0)
Block(-3,7,3,STATIONARY_WATER:0)
Block(-3,7,4,STATIONARY_WATER:0)
Block(-3,7,5,STATIONARY_WATER:0)
Block(-3,7,6,STATIONARY_WATER:0)
Block(-3,7,7,STATIONARY_WATER:0)
Block(-3,7,8,STATIONARY_WATER:0)
Block(-3,7,9,STATIONARY_WATER:0)
Block(-3,7,10,STATIONARY_WATER:0)
Block(-3,7,11,STATIONARY_WATER:0)
Block(-3,7,12,STAINED_CLAY:4)
Block(-3,8,-12,STAINED_CLAY:4)
Block(-3,8,-11,STATIONARY_WATER:0)
Block(-3,8,-10,STATIONARY_WATER:0)
Block(-3,8,-9,STATIONARY_WATER:0)
Block(-3,8,-8,STATIONARY_WATER:0)
Block(-3,8,-7,STATIONARY_WATER:0)
Block(-3,8,-6,STATIONARY_WATER:0)
Block(-3,8,-5,STATIONARY_WATER:0)
Block(-3,8,-4,STATIONARY_WATER:0)
Block(-3,8,-3,STATIONARY_WATER:0)
Block(-3,8,-2,STATIONARY_WATER:0)
Block(-3,8,-1,STATIONARY_WATER:0)
Block(-3,8,0,STATIONARY_WATER:0)
Block(-3,8,1,STATIONARY_WATER:0)
Block(-3,8,2,STATIONARY_WATER:0)
Block(-3,8,3,STATIONARY_WATER:0)
Block(-3,8,4,STATIONARY_WATER:0)
Block(-3,8,5,STATIONARY_WATER:0)
Block(-3,8,6,STATIONARY_WATER:0)
Block(-3,8,7,STATIONARY_WATER:0)
Block(-3,8,8,STATIONARY_WATER:0)
Block(-3,8,9,STATIONARY_WATER:0)
Block(-3,8,10,STATIONARY_WATER:0)
Block(-3,8,11,STATIONARY_WATER:0)
Block(-3,8,12,STAINED_CLAY:4)
Block(-2,0,-12,STAINED_CLAY:4)
Block(-2,0,-11,STAINED_CLAY:4)
Block(-2,0,-10,STAINED_CLAY:4)
Block(-2,0,-9,STAINED_CLAY:4)
Block(-2,0,-8,STAINED_CLAY:4)
Block(-2,0,-7,STAINED_CLAY:4)
Block(-2,0,-6,STAINED_CLAY:4)
Block(-2,0,-5,STAINED_CLAY:4)
Block(-2,0,-4,STAINED_CLAY:4)
Block(-2,0,-3,STAINED_CLAY:4)
Block(-2,0,-2,STAINED_CLAY:4)
Block(-2,0,-1,STAINED_CLAY:4)
Block(-2,0,0,STAINED_CLAY:4)
Block(-2,0,1,STAINED_CLAY:4)
Block(-2,0,2,STAINED_CLAY:4)
Block(-2,0,3,STAINED_CLAY:4)
Block(-2,0,4,STAINED_CLAY:4)
Block(-2,0,5,STAINED_CLAY:4)
Block(-2,0,6,STAINED_CLAY:4)
Block(-2,0,7,STAINED_CLAY:4)
Block(-2,0,8,STAINED_CLAY:4)
Block(-2,0,9,STAINED_CLAY:4)
Block(-2,0,10,STAINED_CLAY:4)
Block(-2,0,11,STAINED_CLAY:4)
Block(-2,0,12,STAINED_CLAY:4)
Block(-2,1,-12,STAINED_CLAY:4)
Block(-2,1,-11,STATIONARY_WATER:0)
Block(-2,1,-10,STATIONARY_WATER:0)
Block(-2,1,-9,STATIONARY_WATER:0)
Block(-2,1,-8,STATIONARY_WATER:0)
Block(-2,1,-7,STATIONARY_WATER:0)
Block(-2,1,-6,STATIONARY_WATER:0)
Block(-2,1,-5,STATIONARY_WATER:0)
Block(-2,1,-4,STATIONARY_WATER:0)
Block(-2,1,-3,STATIONARY_WATER:0)
Block(-2,1,-2,STATIONARY_WATER:0)
Block(-2,1,-1,STATIONARY_WATER:0)
Block(-2,1,0,STATIONARY_WATER:0)
Block(-2,1,1,STATIONARY_WATER:0)
Block(-2,1,2,STATIONARY_WATER:0)
Block(-2,1,3,STATIONARY_WATER:0)
Block(-2,1,4,STATIONARY_WATER:0)
Block(-2,1,5,STATIONARY_WATER:0)
Block(-2,1,6,STATIONARY_WATER:0)
Block(-2,1,7,STATIONARY_WATER:0)
Block(-2,1,8,STATIONARY_WATER:0)
Block(-2,1,9,STATIONARY_WATER:0)
Block(-2,1,10,STATIONARY_WATER:0)
Block(-2,1,11,STATIONARY_WATER:0)
Block(-2,1,12,STAINED_CLAY:4)
Block(-2,2,-12,STAINED_CLAY:4)
Block(-2,2,-11,STATIONARY_WATER:0)
Block(-2,2,-10,STATIONARY_WATER:0)
Block(-2,2,-9,STATIONARY_WATER:0)
Block(-2,2,-8,STATIONARY_WATER:0)
Block(-2,2,-7,STATIONARY_WATER:0)
Block(-2,2,-6,STATIONARY_WATER:0)
Block(-2,2,-5,STATIONARY_WATER:0)
Block(-2,2,-4,STATIONARY_WATER:0)
Block(-2,2,-3,STATIONARY_WATER:0)
Block(-2,2,-2,STATIONARY_WATER:0)
Block(-2,2,-1,STATIONARY_WATER:0)
Block(-2,2,0,STATIONARY_WATER:0)
Block(-2,2,1,STATIONARY_WATER:0)
Block(-2,2,2,STATIONARY_WATER:0)
Block(-2,2,3,STATIONARY_WATER:0)
Block(-2,2,4,STATIONARY_WATER:0)
Block(-2,2,5,STATIONARY_WATER:0)
Block(-2,2,6,STATIONARY_WATER:0)
Block(-2,2,7,STATIONARY_WATER:0)
Block(-2,2,8,STATIONARY_WATER:0)
Block(-2,2,9,STATIONARY_WATER:0)
Block(-2,2,10,STATIONARY_WATER:0)
Block(-2,2,11,STATIONARY_WATER:0)
Block(-2,2,12,STAINED_CLAY:4)
Block(-2,3,-12,STAINED_CLAY:4)
Block(-2,3,-11,STATIONARY_WATER:0)
Block(-2,3,-10,STATIONARY_WATER:0)
Block(-2,3,-9,STATIONARY_WATER:0)
Block(-2,3,-8,STATIONARY_WATER:0)
Block(-2,3,-7,STATIONARY_WATER:0)
Block(-2,3,-6,STATIONARY_WATER:0)
Block(-2,3,-5,STATIONARY_WATER:0)
Block(-2,3,-4,STATIONARY_WATER:0)
Block(-2,3,-3,STATIONARY_WATER:0)
Block(-2,3,-2,STATIONARY_WATER:0)
Block(-2,3,-1,STATIONARY_WATER:0)
Block(-2,3,0,STATIONARY_WATER:0)
Block(-2,3,1,STATIONARY_WATER:0)
Block(-2,3,2,STATIONARY_WATER:0)
Block(-2,3,3,STATIONARY_WATER:0)
Block(-2,3,4,STATIONARY_WATER:0)
Block(-2,3,5,STATIONARY_WATER:0)
Block(-2,3,6,STATIONARY_WATER:0)
Block(-2,3,7,STATIONARY_WATER:0)
Block(-2,3,8,STATIONARY_WATER:0)
Block(-2,3,9,STATIONARY_WATER:0)
Block(-2,3,10,STATIONARY_WATER:0)
Block(-2,3,11,STATIONARY_WATER:0)
Block(-2,3,12,STAINED_CLAY:4)
Block(-2,4,-12,STAINED_CLAY:4)
Block(-2,4,-11,STATIONARY_WATER:0)
Block(-2,4,-10,STATIONARY_WATER:0)
Block(-2,4,-9,STATIONARY_WATER:0)
Block(-2,4,-8,STATIONARY_WATER:0)
Block(-2,4,-7,STATIONARY_WATER:0)
Block(-2,4,-6,STATIONARY_WATER:0)
Block(-2,4,-5,STATIONARY_WATER:0)
Block(-2,4,-4,STATIONARY_WATER:0)
Block(-2,4,-3,STATIONARY_WATER:0)
Block(-2,4,-2,STATIONARY_WATER:0)
Block(-2,4,-1,STATIONARY_WATER:0)
Block(-2,4,0,STATIONARY_WATER:0)
Block(-2,4,1,STATIONARY_WATER:0)
Block(-2,4,2,STATIONARY_WATER:0)
Block(-2,4,3,STATIONARY_WATER:0)
Block(-2,4,4,STATIONARY_WATER:0)
Block(-2,4,5,STATIONARY_WATER:0)
Block(-2,4,6,STATIONARY_WATER:0)
Block(-2,4,7,STATIONARY_WATER:0)
Block(-2,4,8,STATIONARY_WATER:0)
Block(-2,4,9,STATIONARY_WATER:0)
Block(-2,4,10,STATIONARY_WATER:0)
Block(-2,4,11,STATIONARY_WATER:0)
Block(-2,4,12,STAINED_CLAY:4)
Block(-2,5,-12,STAINED_CLAY:4)
Block(-2,5,-11,STATIONARY_WATER:0)
Block(-2,5,-10,STATIONARY_WATER:0)
Block(-2,5,-9,STATIONARY_WATER:0)
Block(-2,5,-8,STATIONARY_WATER:0)
Block(-2,5,-7,STATIONARY_WATER:0)
Block(-2,5,-6,STATIONARY_WATER:0)
Block(-2,5,-5,STATIONARY_WATER:0)
Block(-2,5,-4,STATIONARY_WATER:0)
Block(-2,5,-3,STATIONARY_WATER:0)
Block(-2,5,-2,STATIONARY_WATER:0)
Block(-2,5,-1,STATIONARY_WATER:0)
Block(-2,5,0,STATIONARY_WATER:0)
Block(-2,5,1,STATIONARY_WATER:0)
Block(-2,5,2,STATIONARY_WATER:0)
Block(-2,5,3,STATIONARY_WATER:0)
Block(-2,5,4,STATIONARY_WATER:0)
Block(-2,5,5,STATIONARY_WATER:0)
Block(-2,5,6,STATIONARY_WATER:0)
Block(-2,5,7,STATIONARY_WATER:0)
Block(-2,5,8,STATIONARY_WATER:0)
Block(-2,5,9,STATIONARY_WATER:0)
Block(-2,5,10,STATIONARY_WATER:0)
Block(-2,5,11,STATIONARY_WATER:0)
Block(-2,5,12,STAINED_CLAY:4)
Block(-2,6,-12,STAINED_CLAY:4)
Block(-2,6,-11,STATIONARY_WATER:0)
Block(-2,6,-10,STATIONARY_WATER:0)
Block(-2,6,-9,STATIONARY_WATER:0)
Block(-2,6,-8,STATIONARY_WATER:0)
Block(-2,6,-7,STATIONARY_WATER:0)
Block(-2,6,-6,STATIONARY_WATER:0)
Block(-2,6,-5,STATIONARY_WATER:0)
Block(-2,6,-4,STATIONARY_WATER:0)
Block(-2,6,-3,STATIONARY_WATER:0)
Block(-2,6,-2,STATIONARY_WATER:0)
Block(-2,6,-1,STATIONARY_WATER:0)
Block(-2,6,0,STATIONARY_WATER:0)
Block(-2,6,1,STATIONARY_WATER:0)
Block(-2,6,2,STATIONARY_WATER:0)
Block(-2,6,3,STATIONARY_WATER:0)
Block(-2,6,4,STATIONARY_WATER:0)
Block(-2,6,5,STATIONARY_WATER:0)
Block(-2,6,6,STATIONARY_WATER:0)
Block(-2,6,7,STATIONARY_WATER:0)
Block(-2,6,8,STATIONARY_WATER:0)
Block(-2,6,9,STATIONARY_WATER:0)
Block(-2,6,10,STATIONARY_WATER:0)
Block(-2,6,11,STATIONARY_WATER:0)
Block(-2,6,12,STAINED_CLAY:4)
Block(-2,7,-12,STAINED_CLAY:4)
Block(-2,7,-11,STATIONARY_WATER:0)
Block(-2,7,-10,STATIONARY_WATER:0)
Block(-2,7,-9,STATIONARY_WATER:0)
Block(-2,7,-8,STATIONARY_WATER:0)
Block(-2,7,-7,STATIONARY_WATER:0)
Block(-2,7,-6,STATIONARY_WATER:0)
Block(-2,7,-5,STATIONARY_WATER:0)
Block(-2,7,-4,STATIONARY_WATER:0)
Block(-2,7,-3,STATIONARY_WATER:0)
Block(-2,7,-2,STATIONARY_WATER:0)
Block(-2,7,-1,STATIONARY_WATER:0)
Block(-2,7,0,STATIONARY_WATER:0)
Block(-2,7,1,STATIONARY_WATER:0)
Block(-2,7,2,STATIONARY_WATER:0)
Block(-2,7,3,STATIONARY_WATER:0)
Block(-2,7,4,STATIONARY_WATER:0)
Block(-2,7,5,STATIONARY_WATER:0)
Block(-2,7,6,STATIONARY_WATER:0)
Block(-2,7,7,STATIONARY_WATER:0)
Block(-2,7,8,STATIONARY_WATER:0)
Block(-2,7,9,STATIONARY_WATER:0)
Block(-2,7,10,STATIONARY_WATER:0)
Block(-2,7,11,STATIONARY_WATER:0)
Block(-2,7,12,STAINED_CLAY:4)
Block(-2,8,-12,STAINED_CLAY:4)
Block(-2,8,-11,STATIONARY_WATER:0)
Block(-2,8,-10,STATIONARY_WATER:0)
Block(-2,8,-9,STATIONARY_WATER:0)
Block(-2,8,-8,STATIONARY_WATER:0)
Block(-2,8,-7,STATIONARY_WATER:0)
Block(-2,8,-6,STATIONARY_WATER:0)
Block(-2,8,-5,STATIONARY_WATER:0)
Block(-2,8,-4,STATIONARY_WATER:0)
Block(-2,8,-3,STATIONARY_WATER:0)
Block(-2,8,-2,STATIONARY_WATER:0)
Block(-2,8,-1,STATIONARY_WATER:0)
Block(-2,8,0,STATIONARY_WATER:0)
Block(-2,8,1,STATIONARY_WATER:0)
Block(-2,8,2,STATIONARY_WATER:0)
Block(-2,8,3,STATIONARY_WATER:0)
Block(-2,8,4,STATIONARY_WATER:0)
Block(-2,8,5,STATIONARY_WATER:0)
Block(-2,8,6,STATIONARY_WATER:0)
Block(-2,8,7,STATIONARY_WATER:0)
Block(-2,8,8,STATIONARY_WATER:0)
Block(-2,8,9,STATIONARY_WATER:0)
Block(-2,8,10,STATIONARY_WATER:0)
Block(-2,8,11,STATIONARY_WATER:0)
Block(-2,8,12,STAINED_CLAY:4)
Block(-1,0,-12,STAINED_CLAY:4)
Block(-1,0,-11,STAINED_CLAY:4)
Block(-1,0,-10,STAINED_CLAY:4)
Block(-1,0,-9,STAINED_CLAY:4)
Block(-1,0,-8,STAINED_CLAY:4)
Block(-1,0,-7,STAINED_CLAY:4)
Block(-1,0,-6,STAINED_CLAY:4)
Block(-1,0,-5,STAINED_CLAY:4)
Block(-1,0,-4,STAINED_CLAY:4)
Block(-1,0,-3,STAINED_CLAY:4)
Block(-1,0,-2,STAINED_CLAY:4)
Block(-1,0,-1,STAINED_CLAY:4)
Block(-1,0,0,STAINED_CLAY:4)
Block(-1,0,1,STAINED_CLAY:4)
Block(-1,0,2,STAINED_CLAY:4)
Block(-1,0,3,STAINED_CLAY:4)
Block(-1,0,4,STAINED_CLAY:4)
Block(-1,0,5,STAINED_CLAY:4)
Block(-1,0,6,STAINED_CLAY:4)
Block(-1,0,7,STAINED_CLAY:4)
Block(-1,0,8,STAINED_CLAY:4)
Block(-1,0,9,STAINED_CLAY:4)
Block(-1,0,10,STAINED_CLAY:4)
Block(-1,0,11,STAINED_CLAY:4)
Block(-1,0,12,STAINED_CLAY:4)
Block(-1,1,-12,STAINED_CLAY:4)
Block(-1,1,-11,STATIONARY_WATER:0)
Block(-1,1,-10,STATIONARY_WATER:0)
Block(-1,1,-9,STATIONARY_WATER:0)
Block(-1,1,-8,STATIONARY_WATER:0)
Block(-1,1,-7,STATIONARY_WATER:0)
Block(-1,1,-6,STATIONARY_WATER:0)
Block(-1,1,-5,STATIONARY_WATER:0)
Block(-1,1,-4,STATIONARY_WATER:0)
Block(-1,1,-3,STATIONARY_WATER:0)
Block(-1,1,-2,STATIONARY_WATER:0)
Block(-1,1,-1,STATIONARY_WATER:0)
Block(-1,1,0,STATIONARY_WATER:0)
Block(-1,1,1,STATIONARY_WATER:0)
Block(-1,1,2,STATIONARY_WATER:0)
Block(-1,1,3,STATIONARY_WATER:0)
Block(-1,1,4,STATIONARY_WATER:0)
Block(-1,1,5,STATIONARY_WATER:0)
Block(-1,1,6,STATIONARY_WATER:0)
Block(-1,1,7,STATIONARY_WATER:0)
Block(-1,1,8,STATIONARY_WATER:0)
Block(-1,1,9,STATIONARY_WATER:0)
Block(-1,1,10,STATIONARY_WATER:0)
Block(-1,1,11,STATIONARY_WATER:0)
Block(-1,1,12,STAINED_CLAY:4)
Block(-1,2,-12,STAINED_CLAY:4)
Block(-1,2,-11,STATIONARY_WATER:0)
Block(-1,2,-10,STATIONARY_WATER:0)
Block(-1,2,-9,STATIONARY_WATER:0)
Block(-1,2,-8,STATIONARY_WATER:0)
Block(-1,2,-7,STATIONARY_WATER:0)
Block(-1,2,-6,STATIONARY_WATER:0)
Block(-1,2,-5,STATIONARY_WATER:0)
Block(-1,2,-4,STATIONARY_WATER:0)
Block(-1,2,-3,STATIONARY_WATER:0)
Block(-1,2,-2,STATIONARY_WATER:0)
Block(-1,2,-1,STATIONARY_WATER:0)
Block(-1,2,0,STATIONARY_WATER:0)
Block(-1,2,1,STATIONARY_WATER:0)
Block(-1,2,2,STATIONARY_WATER:0)
Block(-1,2,3,STATIONARY_WATER:0)
Block(-1,2,4,STATIONARY_WATER:0)
Block(-1,2,5,STATIONARY_WATER:0)
Block(-1,2,6,STATIONARY_WATER:0)
Block(-1,2,7,STATIONARY_WATER:0)
Block(-1,2,8,STATIONARY_WATER:0)
Block(-1,2,9,STATIONARY_WATER:0)
Block(-1,2,10,STATIONARY_WATER:0)
Block(-1,2,11,STATIONARY_WATER:0)
Block(-1,2,12,STAINED_CLAY:4)
Block(-1,3,-12,STAINED_CLAY:4)
Block(-1,3,-11,STATIONARY_WATER:0)
Block(-1,3,-10,STATIONARY_WATER:0)
Block(-1,3,-9,STATIONARY_WATER:0)
Block(-1,3,-8,STATIONARY_WATER:0)
Block(-1,3,-7,STATIONARY_WATER:0)
Block(-1,3,-6,STATIONARY_WATER:0)
Block(-1,3,-5,STATIONARY_WATER:0)
Block(-1,3,-4,STATIONARY_WATER:0)
Block(-1,3,-3,STATIONARY_WATER:0)
Block(-1,3,-2,STATIONARY_WATER:0)
Block(-1,3,-1,STATIONARY_WATER:0)
Block(-1,3,0,STATIONARY_WATER:0)
Block(-1,3,1,STATIONARY_WATER:0)
Block(-1,3,2,STATIONARY_WATER:0)
Block(-1,3,3,STATIONARY_WATER:0)
Block(-1,3,4,STATIONARY_WATER:0)
Block(-1,3,5,STATIONARY_WATER:0)
Block(-1,3,6,STATIONARY_WATER:0)
Block(-1,3,7,STATIONARY_WATER:0)
Block(-1,3,8,STATIONARY_WATER:0)
Block(-1,3,9,STATIONARY_WATER:0)
Block(-1,3,10,STATIONARY_WATER:0)
Block(-1,3,11,STATIONARY_WATER:0)
Block(-1,3,12,STAINED_CLAY:4)
Block(-1,4,-12,STAINED_CLAY:4)
Block(-1,4,-11,STATIONARY_WATER:0)
Block(-1,4,-10,STATIONARY_WATER:0)
Block(-1,4,-9,STATIONARY_WATER:0)
Block(-1,4,-8,STATIONARY_WATER:0)
Block(-1,4,-7,STATIONARY_WATER:0)
Block(-1,4,-6,STATIONARY_WATER:0)
Block(-1,4,-5,STATIONARY_WATER:0)
Block(-1,4,-4,STATIONARY_WATER:0)
Block(-1,4,-3,STATIONARY_WATER:0)
Block(-1,4,-2,STATIONARY_WATER:0)
Block(-1,4,-1,STATIONARY_WATER:0)
Block(-1,4,0,STATIONARY_WATER:0)
Block(-1,4,1,STATIONARY_WATER:0)
Block(-1,4,2,STATIONARY_WATER:0)
Block(-1,4,3,STATIONARY_WATER:0)
Block(-1,4,4,STATIONARY_WATER:0)
Block(-1,4,5,STATIONARY_WATER:0)
Block(-1,4,6,STATIONARY_WATER:0)
Block(-1,4,7,STATIONARY_WATER:0)
Block(-1,4,8,STATIONARY_WATER:0)
Block(-1,4,9,STATIONARY_WATER:0)
Block(-1,4,10,STATIONARY_WATER:0)
Block(-1,4,11,STATIONARY_WATER:0)
Block(-1,4,12,STAINED_CLAY:4)
Block(-1,5,-12,STAINED_CLAY:4)
Block(-1,5,-11,STATIONARY_WATER:0)
Block(-1,5,-10,STATIONARY_WATER:0)
Block(-1,5,-9,STATIONARY_WATER:0)
Block(-1,5,-8,STATIONARY_WATER:0)
Block(-1,5,-7,STATIONARY_WATER:0)
Block(-1,5,-6,STATIONARY_WATER:0)
Block(-1,5,-5,STATIONARY_WATER:0)
Block(-1,5,-4,STATIONARY_WATER:0)
Block(-1,5,-3,STATIONARY_WATER:0)
Block(-1,5,-2,STATIONARY_WATER:0)
Block(-1,5,-1,STATIONARY_WATER:0)
Block(-1,5,0,STATIONARY_WATER:0)
Block(-1,5,1,STATIONARY_WATER:0)
Block(-1,5,2,STATIONARY_WATER:0)
Block(-1,5,3,STATIONARY_WATER:0)
Block(-1,5,4,STATIONARY_WATER:0)
Block(-1,5,5,STATIONARY_WATER:0)
Block(-1,5,6,STATIONARY_WATER:0)
Block(-1,5,7,STATIONARY_WATER:0)
Block(-1,5,8,STATIONARY_WATER:0)
Block(-1,5,9,STATIONARY_WATER:0)
Block(-1,5,10,STATIONARY_WATER:0)
Block(-1,5,11,STATIONARY_WATER:0)
Block(-1,5,12,STAINED_CLAY:4)
Block(-1,6,-12,STAINED_CLAY:4)
Block(-1,6,-11,STATIONARY_WATER:0)
Block(-1,6,-10,STATIONARY_WATER:0)
Block(-1,6,-9,STATIONARY_WATER:0)
Block(-1,6,-8,STATIONARY_WATER:0)
Block(-1,6,-7,STATIONARY_WATER:0)
Block(-1,6,-6,STATIONARY_WATER:0)
Block(-1,6,-5,STATIONARY_WATER:0)
Block(-1,6,-4,STATIONARY_WATER:0)
Block(-1,6,-3,STATIONARY_WATER:0)
Block(-1,6,-2,STATIONARY_WATER:0)
Block(-1,6,-1,STATIONARY_WATER:0)
Block(-1,6,0,STATIONARY_WATER:0)
Block(-1,6,1,STATIONARY_WATER:0)
Block(-1,6,2,STATIONARY_WATER:0)
Block(-1,6,3,STATIONARY_WATER:0)
Block(-1,6,4,STATIONARY_WATER:0)
Block(-1,6,5,STATIONARY_WATER:0)
Block(-1,6,6,STATIONARY_WATER:0)
Block(-1,6,7,STATIONARY_WATER:0)
Block(-1,6,8,STATIONARY_WATER:0)
Block(-1,6,9,STATIONARY_WATER:0)
Block(-1,6,10,STATIONARY_WATER:0)
Block(-1,6,11,STATIONARY_WATER:0)
Block(-1,6,12,STAINED_CLAY:4)
Block(-1,7,-12,STAINED_CLAY:4)
Block(-1,7,-11,STATIONARY_WATER:0)
Block(-1,7,-10,STATIONARY_WATER:0)
Block(-1,7,-9,STATIONARY_WATER:0)
Block(-1,7,-8,STATIONARY_WATER:0)
Block(-1,7,-7,STATIONARY_WATER:0)
Block(-1,7,-6,STATIONARY_WATER:0)
Block(-1,7,-5,STATIONARY_WATER:0)
Block(-1,7,-4,STATIONARY_WATER:0)
Block(-1,7,-3,STATIONARY_WATER:0)
Block(-1,7,-2,STATIONARY_WATER:0)
Block(-1,7,-1,STATIONARY_WATER:0)
Block(-1,7,0,STATIONARY_WATER:0)
Block(-1,7,1,STATIONARY_WATER:0)
Block(-1,7,2,STATIONARY_WATER:0)
Block(-1,7,3,STATIONARY_WATER:0)
Block(-1,7,4,STATIONARY_WATER:0)
Block(-1,7,5,STATIONARY_WATER:0)
Block(-1,7,6,STATIONARY_WATER:0)
Block(-1,7,7,STATIONARY_WATER:0)
Block(-1,7,8,STATIONARY_WATER:0)
Block(-1,7,9,STATIONARY_WATER:0)
Block(-1,7,10,STATIONARY_WATER:0)
Block(-1,7,11,STATIONARY_WATER:0)
Block(-1,7,12,STAINED_CLAY:4)
Block(-1,8,-12,STAINED_CLAY:4)
Block(-1,8,-11,STATIONARY_WATER:0)
Block(-1,8,-10,STATIONARY_WATER:0)
Block(-1,8,-9,STATIONARY_WATER:0)
Block(-1,8,-8,STATIONARY_WATER:0)
Block(-1,8,-7,STATIONARY_WATER:0)
Block(-1,8,-6,STATIONARY_WATER:0)
Block(-1,8,-5,STATIONARY_WATER:0)
Block(-1,8,-4,STATIONARY_WATER:0)
Block(-1,8,-3,STATIONARY_WATER:0)
Block(-1,8,-2,STATIONARY_WATER:0)
Block(-1,8,-1,STATIONARY_WATER:0)
Block(-1,8,0,STATIONARY_WATER:0)
Block(-1,8,1,STATIONARY_WATER:0)
Block(-1,8,2,STATIONARY_WATER:0)
Block(-1,8,3,STATIONARY_WATER:0)
Block(-1,8,4,STATIONARY_WATER:0)
Block(-1,8,5,STATIONARY_WATER:0)
Block(-1,8,6,STATIONARY_WATER:0)
Block(-1,8,7,STATIONARY_WATER:0)
Block(-1,8,8,STATIONARY_WATER:0)
Block(-1,8,9,STATIONARY_WATER:0)
Block(-1,8,10,STATIONARY_WATER:0)
Block(-1,8,11,STATIONARY_WATER:0)
Block(-1,8,12,STAINED_CLAY:4)
Block(0,0,-12,STAINED_CLAY:4)
Block(0,0,-11,STAINED_CLAY:4)
Block(0,0,-10,STAINED_CLAY:4)
Block(0,0,-9,STAINED_CLAY:4)
Block(0,0,-8,STAINED_CLAY:4)
Block(0,0,-7,STAINED_CLAY:4)
Block(0,0,-6,STAINED_CLAY:4)
Block(0,0,-5,STAINED_CLAY:4)
Block(0,0,-4,STAINED_CLAY:4)
Block(0,0,-3,STAINED_CLAY:4)
Block(0,0,-2,STAINED_CLAY:4)
Block(0,0,-1,STAINED_CLAY:4)
Block(0,0,0,STAINED_CLAY:4)
Block(0,0,1,STAINED_CLAY:4)
Block(0,0,2,STAINED_CLAY:4)
Block(0,0,3,STAINED_CLAY:4)
Block(0,0,4,STAINED_CLAY:4)
Block(0,0,5,STAINED_CLAY:4)
Block(0,0,6,STAINED_CLAY:4)
Block(0,0,7,STAINED_CLAY:4)
Block(0,0,8,STAINED_CLAY:4)
Block(0,0,9,STAINED_CLAY:4)
Block(0,0,10,STAINED_CLAY:4)
Block(0,0,11,STAINED_CLAY:4)
Block(0,0,12,STAINED_CLAY:4)
Block(0,1,-12,STAINED_CLAY:4)
Block(0,1,-11,STATIONARY_WATER:0)
Block(0,1,-10,STATIONARY_WATER:0)
Block(0,1,-9,STATIONARY_WATER:0)
Block(0,1,-8,STATIONARY_WATER:0)
Block(0,1,-7,STATIONARY_WATER:0)
Block(0,1,-6,STATIONARY_WATER:0)
Block(0,1,-5,STATIONARY_WATER:0)
Block(0,1,-4,STATIONARY_WATER:0)
Block(0,1,-3,STATIONARY_WATER:0)
Block(0,1,-2,STATIONARY_WATER:0)
Block(0,1,-1,STATIONARY_WATER:0)
Block(0,1,0,STATIONARY_WATER:0)
Block(0,1,1,STATIONARY_WATER:0)
Block(0,1,2,STATIONARY_WATER:0)
Block(0,1,3,STATIONARY_WATER:0)
Block(0,1,4,STATIONARY_WATER:0)
Block(0,1,5,STATIONARY_WATER:0)
Block(0,1,6,STATIONARY_WATER:0)
Block(0,1,7,STATIONARY_WATER:0)
Block(0,1,8,STATIONARY_WATER:0)
Block(0,1,9,STATIONARY_WATER:0)
Block(0,1,10,STATIONARY_WATER:0)
Block(0,1,11,STATIONARY_WATER:0)
Block(0,1,12,STAINED_CLAY:4)
Block(0,2,-12,STAINED_CLAY:4)
Block(0,2,-11,STATIONARY_WATER:0)
Block(0,2,-10,STATIONARY_WATER:0)
Block(0,2,-9,STATIONARY_WATER:0)
Block(0,2,-8,STATIONARY_WATER:0)
Block(0,2,-7,STATIONARY_WATER:0)
Block(0,2,-6,STATIONARY_WATER:0)
Block(0,2,-5,STATIONARY_WATER:0)
Block(0,2,-4,STATIONARY_WATER:0)
Block(0,2,-3,STATIONARY_WATER:0)
Block(0,2,-2,STATIONARY_WATER:0)
Block(0,2,-1,STATIONARY_WATER:0)
Block(0,2,0,STATIONARY_WATER:0)
Block(0,2,1,STATIONARY_WATER:0)
Block(0,2,2,STATIONARY_WATER:0)
Block(0,2,3,STATIONARY_WATER:0)
Block(0,2,4,STATIONARY_WATER:0)
Block(0,2,5,STATIONARY_WATER:0)
Block(0,2,6,STATIONARY_WATER:0)
Block(0,2,7,STATIONARY_WATER:0)
Block(0,2,8,STATIONARY_WATER:0)
Block(0,2,9,STATIONARY_WATER:0)
Block(0,2,10,STATIONARY_WATER:0)
Block(0,2,11,STATIONARY_WATER:0)
Block(0,2,12,STAINED_CLAY:4)
Block(0,3,-12,STAINED_CLAY:4)
Block(0,3,-11,STATIONARY_WATER:0)
Block(0,3,-10,STATIONARY_WATER:0)
Block(0,3,-9,STATIONARY_WATER:0)
Block(0,3,-8,STATIONARY_WATER:0)
Block(0,3,-7,STATIONARY_WATER:0)
Block(0,3,-6,STATIONARY_WATER:0)
Block(0,3,-5,STATIONARY_WATER:0)
Block(0,3,-4,STATIONARY_WATER:0)
Block(0,3,-3,STATIONARY_WATER:0)
Block(0,3,-2,STATIONARY_WATER:0)
Block(0,3,-1,STATIONARY_WATER:0)
Block(0,3,0,STATIONARY_WATER:0)
Block(0,3,1,STATIONARY_WATER:0)
Block(0,3,2,STATIONARY_WATER:0)
Block(0,3,3,STATIONARY_WATER:0)
Block(0,3,4,STATIONARY_WATER:0)
Block(0,3,5,STATIONARY_WATER:0)
Block(0,3,6,STATIONARY_WATER:0)
Block(0,3,7,STATIONARY_WATER:0)
Block(0,3,8,STATIONARY_WATER:0)
Block(0,3,9,STATIONARY_WATER:0)
Block(0,3,10,STATIONARY_WATER:0)
Block(0,3,11,STATIONARY_WATER:0)
Block(0,3,12,STAINED_CLAY:4)
Block(0,4,-12,STAINED_CLAY:4)
Block(0,4,-11,STATIONARY_WATER:0)
Block(0,4,-10,STATIONARY_WATER:0)
Block(0,4,-9,STATIONARY_WATER:0)
Block(0,4,-8,STATIONARY_WATER:0)
Block(0,4,-7,STATIONARY_WATER:0)
Block(0,4,-6,STATIONARY_WATER:0)
Block(0,4,-5,STATIONARY_WATER:0)
Block(0,4,-4,STATIONARY_WATER:0)
Block(0,4,-3,STATIONARY_WATER:0)
Block(0,4,-2,STATIONARY_WATER:0)
Block(0,4,-1,STATIONARY_WATER:0)
Block(0,4,0,STATIONARY_WATER:0)
Block(0,4,1,STATIONARY_WATER:0)
Block(0,4,2,STATIONARY_WATER:0)
Block(0,4,3,STATIONARY_WATER:0)
Block(0,4,4,STATIONARY_WATER:0)
Block(0,4,5,STATIONARY_WATER:0)
Block(0,4,6,STATIONARY_WATER:0)
Block(0,4,7,STATIONARY_WATER:0)
Block(0,4,8,STATIONARY_WATER:0)
Block(0,4,9,STATIONARY_WATER:0)
Block(0,4,10,STATIONARY_WATER:0)
Block(0,4,11,STATIONARY_WATER:0)
Block(0,4,12,STAINED_CLAY:4)
Block(0,5,-12,STAINED_CLAY:4)
Block(0,5,-11,STATIONARY_WATER:0)
Block(0,5,-10,STATIONARY_WATER:0)
Block(0,5,-9,STATIONARY_WATER:0)
Block(0,5,-8,STATIONARY_WATER:0)
Block(0,5,-7,STATIONARY_WATER:0)
Block(0,5,-6,STATIONARY_WATER:0)
Block(0,5,-5,STATIONARY_WATER:0)
Block(0,5,-4,STATIONARY_WATER:0)
Block(0,5,-3,STATIONARY_WATER:0)
Block(0,5,-2,STATIONARY_WATER:0)
Block(0,5,-1,STATIONARY_WATER:0)
Block(0,5,0,STATIONARY_WATER:0)
Block(0,5,1,STATIONARY_WATER:0)
Block(0,5,2,STATIONARY_WATER:0)
Block(0,5,3,STATIONARY_WATER:0)
Block(0,5,4,STATIONARY_WATER:0)
Block(0,5,5,STATIONARY_WATER:0)
Block(0,5,6,STATIONARY_WATER:0)
Block(0,5,7,STATIONARY_WATER:0)
Block(0,5,8,STATIONARY_WATER:0)
Block(0,5,9,STATIONARY_WATER:0)
Block(0,5,10,STATIONARY_WATER:0)
Block(0,5,11,STATIONARY_WATER:0)
Block(0,5,12,STAINED_CLAY:4)
Block(0,6,-12,STAINED_CLAY:4)
Block(0,6,-11,STATIONARY_WATER:0)
Block(0,6,-10,STATIONARY_WATER:0)
Block(0,6,-9,STATIONARY_WATER:0)
Block(0,6,-8,STATIONARY_WATER:0)
Block(0,6,-7,STATIONARY_WATER:0)
Block(0,6,-6,STATIONARY_WATER:0)
Block(0,6,-5,STATIONARY_WATER:0)
Block(0,6,-4,STATIONARY_WATER:0)
Block(0,6,-3,STATIONARY_WATER:0)
Block(0,6,-2,STATIONARY_WATER:0)
Block(0,6,-1,STATIONARY_WATER:0)
Block(0,6,0,STATIONARY_WATER:0)
Block(0,6,1,STATIONARY_WATER:0)
Block(0,6,2,STATIONARY_WATER:0)
Block(0,6,3,STATIONARY_WATER:0)
Block(0,6,4,STATIONARY_WATER:0)
Block(0,6,5,STATIONARY_WATER:0)
Block(0,6,6,STATIONARY_WATER:0)
Block(0,6,7,STATIONARY_WATER:0)
Block(0,6,8,STATIONARY_WATER:0)
Block(0,6,9,STATIONARY_WATER:0)
Block(0,6,10,STATIONARY_WATER:0)
Block(0,6,11,STATIONARY_WATER:0)
Block(0,6,12,STAINED_CLAY:4)
Block(0,7,-12,STAINED_CLAY:4)
Block(0,7,-11,STATIONARY_WATER:0)
Block(0,7,-10,STATIONARY_WATER:0)
Block(0,7,-9,STATIONARY_WATER:0)
Block(0,7,-8,STATIONARY_WATER:0)
Block(0,7,-7,STATIONARY_WATER:0)
Block(0,7,-6,STATIONARY_WATER:0)
Block(0,7,-5,STATIONARY_WATER:0)
Block(0,7,-4,STATIONARY_WATER:0)
Block(0,7,-3,STATIONARY_WATER:0)
Block(0,7,-2,STATIONARY_WATER:0)
Block(0,7,-1,STATIONARY_WATER:0)
Block(0,7,0,STATIONARY_WATER:0)
Block(0,7,1,STATIONARY_WATER:0)
Block(0,7,2,STATIONARY_WATER:0)
Block(0,7,3,STATIONARY_WATER:0)
Block(0,7,4,STATIONARY_WATER:0)
Block(0,7,5,STATIONARY_WATER:0)
Block(0,7,6,STATIONARY_WATER:0)
Block(0,7,7,STATIONARY_WATER:0)
Block(0,7,8,STATIONARY_WATER:0)
Block(0,7,9,STATIONARY_WATER:0)
Block(0,7,10,STATIONARY_WATER:0)
Block(0,7,11,STATIONARY_WATER:0)
Block(0,7,12,STAINED_CLAY:4)
Block(0,8,-12,STAINED_CLAY:4)
Block(0,8,-11,STATIONARY_WATER:0)
Block(0,8,-10,STATIONARY_WATER:0)
Block(0,8,-9,STATIONARY_WATER:0)
Block(0,8,-8,STATIONARY_WATER:0)
Block(0,8,-7,STATIONARY_WATER:0)
Block(0,8,-6,STATIONARY_WATER:0)
Block(0,8,-5,STATIONARY_WATER:0)
Block(0,8,-4,STATIONARY_WATER:0)
Block(0,8,-3,STATIONARY_WATER:0)
Block(0,8,-2,STATIONARY_WATER:0)
Block(0,8,-1,STATIONARY_WATER:0)
Block(0,8,0,STATIONARY_WATER:0)
Block(0,8,1,STATIONARY_WATER:0)
Block(0,8,2,STATIONARY_WATER:0)
Block(0,8,3,STATIONARY_WATER:0)
Block(0,8,4,STATIONARY_WATER:0)
Block(0,8,5,STATIONARY_WATER:0)
Block(0,8,6,STATIONARY_WATER:0)
Block(0,8,7,STATIONARY_WATER:0)
Block(0,8,8,STATIONARY_WATER:0)
Block(0,8,9,STATIONARY_WATER:0)
Block(0,8,10,STATIONARY_WATER:0)
Block(0,8,11,STATIONARY_WATER:0)
Block(0,8,12,STAINED_CLAY:4)
Block(1,0,-12,STAINED_CLAY:4)
Block(1,0,-11,STAINED_CLAY:4)
Block(1,0,-10,STAINED_CLAY:4)
Block(1,0,-9,STAINED_CLAY:4)
Block(1,0,-8,STAINED_CLAY:4)
Block(1,0,-7,STAINED_CLAY:4)
Block(1,0,-6,STAINED_CLAY:4)
Block(1,0,-5,STAINED_CLAY:4)
Block(1,0,-4,STAINED_CLAY:4)
Block(1,0,-3,STAINED_CLAY:4)
Block(1,0,-2,STAINED_CLAY:4)
Block(1,0,-1,STAINED_CLAY:4)
Block(1,0,0,STAINED_CLAY:4)
Block(1,0,1,STAINED_CLAY:4)
Block(1,0,2,STAINED_CLAY:4)
Block(1,0,3,STAINED_CLAY:4)
Block(1,0,4,STAINED_CLAY:4)
Block(1,0,5,STAINED_CLAY:4)
Block(1,0,6,STAINED_CLAY:4)
Block(1,0,7,STAINED_CLAY:4)
Block(1,0,8,STAINED_CLAY:4)
Block(1,0,9,STAINED_CLAY:4)
Block(1,0,10,STAINED_CLAY:4)
Block(1,0,11,STAINED_CLAY:4)
Block(1,0,12,STAINED_CLAY:4)
Block(1,1,-12,STAINED_CLAY:4)
Block(1,1,-11,STATIONARY_WATER:0)
Block(1,1,-10,STATIONARY_WATER:0)
Block(1,1,-9,STATIONARY_WATER:0)
Block(1,1,-8,STATIONARY_WATER:0)
Block(1,1,-7,STATIONARY_WATER:0)
Block(1,1,-6,STATIONARY_WATER:0)
Block(1,1,-5,STATIONARY_WATER:0)
Block(1,1,-4,STATIONARY_WATER:0)
Block(1,1,-3,STATIONARY_WATER:0)
Block(1,1,-2,STATIONARY_WATER:0)
Block(1,1,-1,STATIONARY_WATER:0)
Block(1,1,0,STATIONARY_WATER:0)
Block(1,1,1,STATIONARY_WATER:0)
Block(1,1,2,STATIONARY_WATER:0)
Block(1,1,3,STATIONARY_WATER:0)
Block(1,1,4,STATIONARY_WATER:0)
Block(1,1,5,STATIONARY_WATER:0)
Block(1,1,6,STATIONARY_WATER:0)
Block(1,1,7,STATIONARY_WATER:0)
Block(1,1,8,STATIONARY_WATER:0)
Block(1,1,9,STATIONARY_WATER:0)
Block(1,1,10,STATIONARY_WATER:0)
Block(1,1,11,STATIONARY_WATER:0)
Block(1,1,12,STAINED_CLAY:4)
Block(1,2,-12,STAINED_CLAY:4)
Block(1,2,-11,STATIONARY_WATER:0)
Block(1,2,-10,STATIONARY_WATER:0)
Block(1,2,-9,STATIONARY_WATER:0)
Block(1,2,-8,STATIONARY_WATER:0)
Block(1,2,-7,STATIONARY_WATER:0)
Block(1,2,-6,STATIONARY_WATER:0)
Block(1,2,-5,STATIONARY_WATER:0)
Block(1,2,-4,STATIONARY_WATER:0)
Block(1,2,-3,STATIONARY_WATER:0)
Block(1,2,-2,STATIONARY_WATER:0)
Block(1,2,-1,STATIONARY_WATER:0)
Block(1,2,0,STATIONARY_WATER:0)
Block(1,2,1,STATIONARY_WATER:0)
Block(1,2,2,STATIONARY_WATER:0)
Block(1,2,3,STATIONARY_WATER:0)
Block(1,2,4,STATIONARY_WATER:0)
Block(1,2,5,STATIONARY_WATER:0)
Block(1,2,6,STATIONARY_WATER:0)
Block(1,2,7,STATIONARY_WATER:0)
Block(1,2,8,STATIONARY_WATER:0)
Block(1,2,9,STATIONARY_WATER:0)
Block(1,2,10,STATIONARY_WATER:0)
Block(1,2,11,STATIONARY_WATER:0)
Block(1,2,12,STAINED_CLAY:4)
Block(1,3,-12,STAINED_CLAY:4)
Block(1,3,-11,STATIONARY_WATER:0)
Block(1,3,-10,STATIONARY_WATER:0)
Block(1,3,-9,STATIONARY_WATER:0)
Block(1,3,-8,STATIONARY_WATER:0)
Block(1,3,-7,STATIONARY_WATER:0)
Block(1,3,-6,STATIONARY_WATER:0)
Block(1,3,-5,STATIONARY_WATER:0)
Block(1,3,-4,STATIONARY_WATER:0)
Block(1,3,-3,STATIONARY_WATER:0)
Block(1,3,-2,STATIONARY_WATER:0)
Block(1,3,-1,STATIONARY_WATER:0)
Block(1,3,0,STATIONARY_WATER:0)
Block(1,3,1,STATIONARY_WATER:0)
Block(1,3,2,STATIONARY_WATER:0)
Block(1,3,3,STATIONARY_WATER:0)
Block(1,3,4,STATIONARY_WATER:0)
Block(1,3,5,STATIONARY_WATER:0)
Block(1,3,6,STATIONARY_WATER:0)
Block(1,3,7,STATIONARY_WATER:0)
Block(1,3,8,STATIONARY_WATER:0)
Block(1,3,9,STATIONARY_WATER:0)
Block(1,3,10,STATIONARY_WATER:0)
Block(1,3,11,STATIONARY_WATER:0)
Block(1,3,12,STAINED_CLAY:4)
Block(1,4,-12,STAINED_CLAY:4)
Block(1,4,-11,STATIONARY_WATER:0)
Block(1,4,-10,STATIONARY_WATER:0)
Block(1,4,-9,STATIONARY_WATER:0)
Block(1,4,-8,STATIONARY_WATER:0)
Block(1,4,-7,STATIONARY_WATER:0)
Block(1,4,-6,STATIONARY_WATER:0)
Block(1,4,-5,STATIONARY_WATER:0)
Block(1,4,-4,STATIONARY_WATER:0)
Block(1,4,-3,STATIONARY_WATER:0)
Block(1,4,-2,STATIONARY_WATER:0)
Block(1,4,-1,STATIONARY_WATER:0)
Block(1,4,0,STATIONARY_WATER:0)
Block(1,4,1,STATIONARY_WATER:0)
Block(1,4,2,STATIONARY_WATER:0)
Block(1,4,3,STATIONARY_WATER:0)
Block(1,4,4,STATIONARY_WATER:0)
Block(1,4,5,STATIONARY_WATER:0)
Block(1,4,6,STATIONARY_WATER:0)
Block(1,4,7,STATIONARY_WATER:0)
Block(1,4,8,STATIONARY_WATER:0)
Block(1,4,9,STATIONARY_WATER:0)
Block(1,4,10,STATIONARY_WATER:0)
Block(1,4,11,STATIONARY_WATER:0)
Block(1,4,12,STAINED_CLAY:4)
Block(1,5,-12,STAINED_CLAY:4)
Block(1,5,-11,STATIONARY_WATER:0)
Block(1,5,-10,STATIONARY_WATER:0)
Block(1,5,-9,STATIONARY_WATER:0)
Block(1,5,-8,STATIONARY_WATER:0)
Block(1,5,-7,STATIONARY_WATER:0)
Block(1,5,-6,STATIONARY_WATER:0)
Block(1,5,-5,STATIONARY_WATER:0)
Block(1,5,-4,STATIONARY_WATER:0)
Block(1,5,-3,STATIONARY_WATER:0)
Block(1,5,-2,STATIONARY_WATER:0)
Block(1,5,-1,STATIONARY_WATER:0)
Block(1,5,0,STATIONARY_WATER:0)
Block(1,5,1,STATIONARY_WATER:0)
Block(1,5,2,STATIONARY_WATER:0)
Block(1,5,3,STATIONARY_WATER:0)
Block(1,5,4,STATIONARY_WATER:0)
Block(1,5,5,STATIONARY_WATER:0)
Block(1,5,6,STATIONARY_WATER:0)
Block(1,5,7,STATIONARY_WATER:0)
Block(1,5,8,STATIONARY_WATER:0)
Block(1,5,9,STATIONARY_WATER:0)
Block(1,5,10,STATIONARY_WATER:0)
Block(1,5,11,STATIONARY_WATER:0)
Block(1,5,12,STAINED_CLAY:4)
Block(1,6,-12,STAINED_CLAY:4)
Block(1,6,-11,STATIONARY_WATER:0)
Block(1,6,-10,STATIONARY_WATER:0)
Block(1,6,-9,STATIONARY_WATER:0)
Block(1,6,-8,STATIONARY_WATER:0)
Block(1,6,-7,STATIONARY_WATER:0)
Block(1,6,-6,STATIONARY_WATER:0)
Block(1,6,-5,STATIONARY_WATER:0)
Block(1,6,-4,STATIONARY_WATER:0)
Block(1,6,-3,STATIONARY_WATER:0)
Block(1,6,-2,STATIONARY_WATER:0)
Block(1,6,-1,STATIONARY_WATER:0)
Block(1,6,0,STATIONARY_WATER:0)
Block(1,6,1,STATIONARY_WATER:0)
Block(1,6,2,STATIONARY_WATER:0)
Block(1,6,3,STATIONARY_WATER:0)
Block(1,6,4,STATIONARY_WATER:0)
Block(1,6,5,STATIONARY_WATER:0)
Block(1,6,6,STATIONARY_WATER:0)
Block(1,6,7,STATIONARY_WATER:0)
Block(1,6,8,STATIONARY_WATER:0)
Block(1,6,9,STATIONARY_WATER:0)
Block(1,6,10,STATIONARY_WATER:0)
Block(1,6,11,STATIONARY_WATER:0)
Block(1,6,12,STAINED_CLAY:4)
Block(1,7,-12,STAINED_CLAY:4)
Block(1,7,-11,STATIONARY_WATER:0)
Block(1,7,-10,STATIONARY_WATER:0)
Block(1,7,-9,STATIONARY_WATER:0)
Block(1,7,-8,STATIONARY_WATER:0)
Block(1,7,-7,STATIONARY_WATER:0)
Block(1,7,-6,STATIONARY_WATER:0)
Block(1,7,-5,STATIONARY_WATER:0)
Block(1,7,-4,STATIONARY_WATER:0)
Block(1,7,-3,STATIONARY_WATER:0)
Block(1,7,-2,STATIONARY_WATER:0)
Block(1,7,-1,STATIONARY_WATER:0)
Block(1,7,0,STATIONARY_WATER:0)
Block(1,7,1,STATIONARY_WATER:0)
Block(1,7,2,STATIONARY_WATER:0)
Block(1,7,3,STATIONARY_WATER:0)
Block(1,7,4,STATIONARY_WATER:0)
Block(1,7,5,STATIONARY_WATER:0)
Block(1,7,6,STATIONARY_WATER:0)
Block(1,7,7,STATIONARY_WATER:0)
Block(1,7,8,STATIONARY_WATER:0)
Block(1,7,9,STATIONARY_WATER:0)
Block(1,7,10,STATIONARY_WATER:0)
Block(1,7,11,STATIONARY_WATER:0)
Block(1,7,12,STAINED_CLAY:4)
Block(1,8,-12,STAINED_CLAY:4)
Block(1,8,-11,STATIONARY_WATER:0)
Block(1,8,-10,STATIONARY_WATER:0)
Block(1,8,-9,STATIONARY_WATER:0)
Block(1,8,-8,STATIONARY_WATER:0)
Block(1,8,-7,STATIONARY_WATER:0)
Block(1,8,-6,STATIONARY_WATER:0)
Block(1,8,-5,STATIONARY_WATER:0)
Block(1,8,-4,STATIONARY_WATER:0)
Block(1,8,-3,STATIONARY_WATER:0)
Block(1,8,-2,STATIONARY_WATER:0)
Block(1,8,-1,STATIONARY_WATER:0)
Block(1,8,0,STATIONARY_WATER:0)
Block(1,8,1,STATIONARY_WATER:0)
Block(1,8,2,STATIONARY_WATER:0)
Block(1,8,3,STATIONARY_WATER:0)
Block(1,8,4,STATIONARY_WATER:0)
Block(1,8,5,STATIONARY_WATER:0)
Block(1,8,6,STATIONARY_WATER:0)
Block(1,8,7,STATIONARY_WATER:0)
Block(1,8,8,STATIONARY_WATER:0)
Block(1,8,9,STATIONARY_WATER:0)
Block(1,8,10,STATIONARY_WATER:0)
Block(1,8,11,STATIONARY_WATER:0)
Block(1,8,12,STAINED_CLAY:4)
Block(2,0,-12,STAINED_CLAY:4)
Block(2,0,-11,STAINED_CLAY:4)
Block(2,0,-10,STAINED_CLAY:4)
Block(2,0,-9,STAINED_CLAY:4)
Block(2,0,-8,STAINED_CLAY:4)
Block(2,0,-7,STAINED_CLAY:4)
Block(2,0,-6,STAINED_CLAY:4)
Block(2,0,-5,STAINED_CLAY:4)
Block(2,0,-4,STAINED_CLAY:4)
Block(2,0,-3,STAINED_CLAY:4)
Block(2,0,-2,STAINED_CLAY:4)
Block(2,0,-1,STAINED_CLAY:4)
Block(2,0,0,STAINED_CLAY:4)
Block(2,0,1,STAINED_CLAY:4)
Block(2,0,2,STAINED_CLAY:4)
Block(2,0,3,STAINED_CLAY:4)
Block(2,0,4,STAINED_CLAY:4)
Block(2,0,5,STAINED_CLAY:4)
Block(2,0,6,STAINED_CLAY:4)
Block(2,0,7,STAINED_CLAY:4)
Block(2,0,8,STAINED_CLAY:4)
Block(2,0,9,STAINED_CLAY:4)
Block(2,0,10,STAINED_CLAY:4)
Block(2,0,11,STAINED_CLAY:4)
Block(2,0,12,STAINED_CLAY:4)
Block(2,1,-12,STAINED_CLAY:4)
Block(2,1,-11,STATIONARY_WATER:0)
Block(2,1,-10,STATIONARY_WATER:0)
Block(2,1,-9,STATIONARY_WATER:0)
Block(2,1,-8,STATIONARY_WATER:0)
Block(2,1,-7,STATIONARY_WATER:0)
Block(2,1,-6,STATIONARY_WATER:0)
Block(2,1,-5,STATIONARY_WATER:0)
Block(2,1,-4,STATIONARY_WATER:0)
Block(2,1,-3,STATIONARY_WATER:0)
Block(2,1,-2,STATIONARY_WATER:0)
Block(2,1,-1,STATIONARY_WATER:0)
Block(2,1,0,STATIONARY_WATER:0)
Block(2,1,1,STATIONARY_WATER:0)
Block(2,1,2,STATIONARY_WATER:0)
Block(2,1,3,STATIONARY_WATER:0)
Block(2,1,4,STATIONARY_WATER:0)
Block(2,1,5,STATIONARY_WATER:0)
Block(2,1,6,STATIONARY_WATER:0)
Block(2,1,7,STATIONARY_WATER:0)
Block(2,1,8,STATIONARY_WATER:0)
Block(2,1,9,STATIONARY_WATER:0)
Block(2,1,10,STATIONARY_WATER:0)
Block(2,1,11,STATIONARY_WATER:0)
Block(2,1,12,STAINED_CLAY:4)
Block(2,2,-12,STAINED_CLAY:4)
Block(2,2,-11,STATIONARY_WATER:0)
Block(2,2,-10,STATIONARY_WATER:0)
Block(2,2,-9,STATIONARY_WATER:0)
Block(2,2,-8,STATIONARY_WATER:0)
Block(2,2,-7,STATIONARY_WATER:0)
Block(2,2,-6,STATIONARY_WATER:0)
Block(2,2,-5,STATIONARY_WATER:0)
Block(2,2,-4,STATIONARY_WATER:0)
Block(2,2,-3,STATIONARY_WATER:0)
Block(2,2,-2,STATIONARY_WATER:0)
Block(2,2,-1,STATIONARY_WATER:0)
Block(2,2,0,STATIONARY_WATER:0)
Block(2,2,1,STATIONARY_WATER:0)
Block(2,2,2,STATIONARY_WATER:0)
Block(2,2,3,STATIONARY_WATER:0)
Block(2,2,4,STATIONARY_WATER:0)
Block(2,2,5,STATIONARY_WATER:0)
Block(2,2,6,STATIONARY_WATER:0)
Block(2,2,7,STATIONARY_WATER:0)
Block(2,2,8,STATIONARY_WATER:0)
Block(2,2,9,STATIONARY_WATER:0)
Block(2,2,10,STATIONARY_WATER:0)
Block(2,2,11,STATIONARY_WATER:0)
Block(2,2,12,STAINED_CLAY:4)
Block(2,3,-12,STAINED_CLAY:4)
Block(2,3,-11,STATIONARY_WATER:0)
Block(2,3,-10,STATIONARY_WATER:0)
Block(2,3,-9,STATIONARY_WATER:0)
Block(2,3,-8,STATIONARY_WATER:0)
Block(2,3,-7,STATIONARY_WATER:0)
Block(2,3,-6,STATIONARY_WATER:0)
Block(2,3,-5,STATIONARY_WATER:0)
Block(2,3,-4,STATIONARY_WATER:0)
Block(2,3,-3,STATIONARY_WATER:0)
Block(2,3,-2,STATIONARY_WATER:0)
Block(2,3,-1,STATIONARY_WATER:0)
Block(2,3,0,STATIONARY_WATER:0)
Block(2,3,1,STATIONARY_WATER:0)
Block(2,3,2,STATIONARY_WATER:0)
Block(2,3,3,STATIONARY_WATER:0)
Block(2,3,4,STATIONARY_WATER:0)
Block(2,3,5,STATIONARY_WATER:0)
Block(2,3,6,STATIONARY_WATER:0)
Block(2,3,7,STATIONARY_WATER:0)
Block(2,3,8,STATIONARY_WATER:0)
Block(2,3,9,STATIONARY_WATER:0)
Block(2,3,10,STATIONARY_WATER:0)
Block(2,3,11,STATIONARY_WATER:0)
Block(2,3,12,STAINED_CLAY:4)
Block(2,4,-12,STAINED_CLAY:4)
Block(2,4,-11,STATIONARY_WATER:0)
Block(2,4,-10,STATIONARY_WATER:0)
Block(2,4,-9,STATIONARY_WATER:0)
Block(2,4,-8,STATIONARY_WATER:0)
Block(2,4,-7,STATIONARY_WATER:0)
Block(2,4,-6,STATIONARY_WATER:0)
Block(2,4,-5,STATIONARY_WATER:0)
Block(2,4,-4,STATIONARY_WATER:0)
Block(2,4,-3,STATIONARY_WATER:0)
Block(2,4,-2,STATIONARY_WATER:0)
Block(2,4,-1,STATIONARY_WATER:0)
Block(2,4,0,STATIONARY_WATER:0)
Block(2,4,1,STATIONARY_WATER:0)
Block(2,4,2,STATIONARY_WATER:0)
Block(2,4,3,STATIONARY_WATER:0)
Block(2,4,4,STATIONARY_WATER:0)
Block(2,4,5,STATIONARY_WATER:0)
Block(2,4,6,STATIONARY_WATER:0)
Block(2,4,7,STATIONARY_WATER:0)
Block(2,4,8,STATIONARY_WATER:0)
Block(2,4,9,STATIONARY_WATER:0)
Block(2,4,10,STATIONARY_WATER:0)
Block(2,4,11,STATIONARY_WATER:0)
Block(2,4,12,STAINED_CLAY:4)
Block(2,5,-12,STAINED_CLAY:4)
Block(2,5,-11,STATIONARY_WATER:0)
Block(2,5,-10,STATIONARY_WATER:0)
Block(2,5,-9,STATIONARY_WATER:0)
Block(2,5,-8,STATIONARY_WATER:0)
Block(2,5,-7,STATIONARY_WATER:0)
Block(2,5,-6,STATIONARY_WATER:0)
Block(2,5,-5,STATIONARY_WATER:0)
Block(2,5,-4,STATIONARY_WATER:0)
Block(2,5,-3,STATIONARY_WATER:0)
Block(2,5,-2,STATIONARY_WATER:0)
Block(2,5,-1,STATIONARY_WATER:0)
Block(2,5,0,STATIONARY_WATER:0)
Block(2,5,1,STATIONARY_WATER:0)
Block(2,5,2,STATIONARY_WATER:0)
Block(2,5,3,STATIONARY_WATER:0)
Block(2,5,4,STATIONARY_WATER:0)
Block(2,5,5,STATIONARY_WATER:0)
Block(2,5,6,STATIONARY_WATER:0)
Block(2,5,7,STATIONARY_WATER:0)
Block(2,5,8,STATIONARY_WATER:0)
Block(2,5,9,STATIONARY_WATER:0)
Block(2,5,10,STATIONARY_WATER:0)
Block(2,5,11,STATIONARY_WATER:0)
Block(2,5,12,STAINED_CLAY:4)
Block(2,6,-12,STAINED_CLAY:4)
Block(2,6,-11,STATIONARY_WATER:0)
Block(2,6,-10,STATIONARY_WATER:0)
Block(2,6,-9,STATIONARY_WATER:0)
Block(2,6,-8,STATIONARY_WATER:0)
Block(2,6,-7,STATIONARY_WATER:0)
Block(2,6,-6,STATIONARY_WATER:0)
Block(2,6,-5,STATIONARY_WATER:0)
Block(2,6,-4,STATIONARY_WATER:0)
Block(2,6,-3,STATIONARY_WATER:0)
Block(2,6,-2,STATIONARY_WATER:0)
Block(2,6,-1,STATIONARY_WATER:0)
Block(2,6,0,STATIONARY_WATER:0)
Block(2,6,1,STATIONARY_WATER:0)
Block(2,6,2,STATIONARY_WATER:0)
Block(2,6,3,STATIONARY_WATER:0)
Block(2,6,4,STATIONARY_WATER:0)
Block(2,6,5,STATIONARY_WATER:0)
Block(2,6,6,STATIONARY_WATER:0)
Block(2,6,7,STATIONARY_WATER:0)
Block(2,6,8,STATIONARY_WATER:0)
Block(2,6,9,STATIONARY_WATER:0)
Block(2,6,10,STATIONARY_WATER:0)
Block(2,6,11,STATIONARY_WATER:0)
Block(2,6,12,STAINED_CLAY:4)
Block(2,7,-12,STAINED_CLAY:4)
Block(2,7,-11,STATIONARY_WATER:0)
Block(2,7,-10,STATIONARY_WATER:0)
Block(2,7,-9,STATIONARY_WATER:0)
Block(2,7,-8,STATIONARY_WATER:0)
Block(2,7,-7,STATIONARY_WATER:0)
Block(2,7,-6,STATIONARY_WATER:0)
Block(2,7,-5,STATIONARY_WATER:0)
Block(2,7,-4,STATIONARY_WATER:0)
Block(2,7,-3,STATIONARY_WATER:0)
Block(2,7,-2,STATIONARY_WATER:0)
Block(2,7,-1,STATIONARY_WATER:0)
Block(2,7,0,STATIONARY_WATER:0)
Block(2,7,1,STATIONARY_WATER:0)
Block(2,7,2,STATIONARY_WATER:0)
Block(2,7,3,STATIONARY_WATER:0)
Block(2,7,4,STATIONARY_WATER:0)
Block(2,7,5,STATIONARY_WATER:0)
Block(2,7,6,STATIONARY_WATER:0)
Block(2,7,7,STATIONARY_WATER:0)
Block(2,7,8,STATIONARY_WATER:0)
Block(2,7,9,STATIONARY_WATER:0)
Block(2,7,10,STATIONARY_WATER:0)
Block(2,7,11,STATIONARY_WATER:0)
Block(2,7,12,STAINED_CLAY:4)
Block(2,8,-12,STAINED_CLAY:4)
Block(2,8,-11,STATIONARY_WATER:0)
Block(2,8,-10,STATIONARY_WATER:0)
Block(2,8,-9,STATIONARY_WATER:0)
Block(2,8,-8,STATIONARY_WATER:0)
Block(2,8,-7,STATIONARY_WATER:0)
Block(2,8,-6,STATIONARY_WATER:0)
Block(2,8,-5,STATIONARY_WATER:0)
Block(2,8,-4,STATIONARY_WATER:0)
Block(2,8,-3,STATIONARY_WATER:0)
Block(2,8,-2,STATIONARY_WATER:0)
Block(2,8,-1,STATIONARY_WATER:0)
Block(2,8,0,STATIONARY_WATER:0)
Block(2,8,1,STATIONARY_WATER:0)
Block(2,8,2,STATIONARY_WATER:0)
Block(2,8,3,STATIONARY_WATER:0)
Block(2,8,4,STATIONARY_WATER:0)
Block(2,8,5,STATIONARY_WATER:0)
Block(2,8,6,STATIONARY_WATER:0)
Block(2,8,7,STATIONARY_WATER:0)
Block(2,8,8,STATIONARY_WATER:0)
Block(2,8,9,STATIONARY_WATER:0)
Block(2,8,10,STATIONARY_WATER:0)
Block(2,8,11,STATIONARY_WATER:0)
Block(2,8,12,STAINED_CLAY:4)
Block(3,0,-12,STAINED_CLAY:4)
Block(3,0,-11,STAINED_CLAY:4)
Block(3,0,-10,STAINED_CLAY:4)
Block(3,0,-9,STAINED_CLAY:4)
Block(3,0,-8,STAINED_CLAY:4)
Block(3,0,-7,STAINED_CLAY:4)
Block(3,0,-6,STAINED_CLAY:4)
Block(3,0,-5,STAINED_CLAY:4)
Block(3,0,-4,STAINED_CLAY:4)
Block(3,0,-3,STAINED_CLAY:4)
Block(3,0,-2,STAINED_CLAY:4)
Block(3,0,-1,STAINED_CLAY:4)
Block(3,0,0,STAINED_CLAY:4)
Block(3,0,1,STAINED_CLAY:4)
Block(3,0,2,STAINED_CLAY:4)
Block(3,0,3,STAINED_CLAY:4)
Block(3,0,4,STAINED_CLAY:4)
Block(3,0,5,STAINED_CLAY:4)
Block(3,0,6,STAINED_CLAY:4)
Block(3,0,7,STAINED_CLAY:4)
Block(3,0,8,STAINED_CLAY:4)
Block(3,0,9,STAINED_CLAY:4)
Block(3,0,10,STAINED_CLAY:4)
Block(3,0,11,STAINED_CLAY:4)
Block(3,0,12,STAINED_CLAY:4)
Block(3,1,-12,STAINED_CLAY:4)
Block(3,1,-11,STATIONARY_WATER:0)
Block(3,1,-10,STATIONARY_WATER:0)
Block(3,1,-9,STATIONARY_WATER:0)
Block(3,1,-8,STATIONARY_WATER:0)
Block(3,1,-7,STATIONARY_WATER:0)
Block(3,1,-6,STATIONARY_WATER:0)
Block(3,1,-5,STATIONARY_WATER:0)
Block(3,1,-4,STATIONARY_WATER:0)
Block(3,1,-3,STATIONARY_WATER:0)
Block(3,1,-2,STATIONARY_WATER:0)
Block(3,1,-1,STATIONARY_WATER:0)
Block(3,1,0,STATIONARY_WATER:0)
Block(3,1,1,STATIONARY_WATER:0)
Block(3,1,2,STATIONARY_WATER:0)
Block(3,1,3,STATIONARY_WATER:0)
Block(3,1,4,STATIONARY_WATER:0)
Block(3,1,5,STATIONARY_WATER:0)
Block(3,1,6,STATIONARY_WATER:0)
Block(3,1,7,STATIONARY_WATER:0)
Block(3,1,8,STATIONARY_WATER:0)
Block(3,1,9,STATIONARY_WATER:0)
Block(3,1,10,STATIONARY_WATER:0)
Block(3,1,11,STATIONARY_WATER:0)
Block(3,1,12,STAINED_CLAY:4)
Block(3,2,-12,STAINED_CLAY:4)
Block(3,2,-11,STATIONARY_WATER:0)
Block(3,2,-10,STATIONARY_WATER:0)
Block(3,2,-9,STATIONARY_WATER:0)
Block(3,2,-8,STATIONARY_WATER:0)
Block(3,2,-7,STATIONARY_WATER:0)
Block(3,2,-6,STATIONARY_WATER:0)
Block(3,2,-5,STATIONARY_WATER:0)
Block(3,2,-4,STATIONARY_WATER:0)
Block(3,2,-3,STATIONARY_WATER:0)
Block(3,2,-2,STATIONARY_WATER:0)
Block(3,2,-1,STATIONARY_WATER:0)
Block(3,2,0,STATIONARY_WATER:0)
Block(3,2,1,STATIONARY_WATER:0)
Block(3,2,2,STATIONARY_WATER:0)
Block(3,2,3,STATIONARY_WATER:0)
Block(3,2,4,STATIONARY_WATER:0)
Block(3,2,5,STATIONARY_WATER:0)
Block(3,2,6,STATIONARY_WATER:0)
Block(3,2,7,STATIONARY_WATER:0)
Block(3,2,8,STATIONARY_WATER:0)
Block(3,2,9,STATIONARY_WATER:0)
Block(3,2,10,STATIONARY_WATER:0)
Block(3,2,11,STATIONARY_WATER:0)
Block(3,2,12,STAINED_CLAY:4)
Block(3,3,-12,STAINED_CLAY:4)
Block(3,3,-11,STATIONARY_WATER:0)
Block(3,3,-10,STATIONARY_WATER:0)
Block(3,3,-9,STATIONARY_WATER:0)
Block(3,3,-8,STATIONARY_WATER:0)
Block(3,3,-7,STATIONARY_WATER:0)
Block(3,3,-6,STATIONARY_WATER:0)
Block(3,3,-5,STATIONARY_WATER:0)
Block(3,3,-4,STATIONARY_WATER:0)
Block(3,3,-3,STATIONARY_WATER:0)
Block(3,3,-2,STATIONARY_WATER:0)
Block(3,3,-1,STATIONARY_WATER:0)
Block(3,3,0,STATIONARY_WATER:0)
Block(3,3,1,STATIONARY_WATER:0)
Block(3,3,2,STATIONARY_WATER:0)
Block(3,3,3,STATIONARY_WATER:0)
Block(3,3,4,STATIONARY_WATER:0)
Block(3,3,5,STATIONARY_WATER:0)
Block(3,3,6,STATIONARY_WATER:0)
Block(3,3,7,STATIONARY_WATER:0)
Block(3,3,8,STATIONARY_WATER:0)
Block(3,3,9,STATIONARY_WATER:0)
Block(3,3,10,STATIONARY_WATER:0)
Block(3,3,11,STATIONARY_WATER:0)
Block(3,3,12,STAINED_CLAY:4)
Block(3,4,-12,STAINED_CLAY:4)
Block(3,4,-11,STATIONARY_WATER:0)
Block(3,4,-10,STATIONARY_WATER:0)
Block(3,4,-9,STATIONARY_WATER:0)
Block(3,4,-8,STATIONARY_WATER:0)
Block(3,4,-7,STATIONARY_WATER:0)
Block(3,4,-6,STATIONARY_WATER:0)
Block(3,4,-5,STATIONARY_WATER:0)
Block(3,4,-4,STATIONARY_WATER:0)
Block(3,4,-3,STATIONARY_WATER:0)
Block(3,4,-2,STATIONARY_WATER:0)
Block(3,4,-1,STATIONARY_WATER:0)
Block(3,4,0,STATIONARY_WATER:0)
Block(3,4,1,STATIONARY_WATER:0)
Block(3,4,2,STATIONARY_WATER:0)
Block(3,4,3,STATIONARY_WATER:0)
Block(3,4,4,STATIONARY_WATER:0)
Block(3,4,5,STATIONARY_WATER:0)
Block(3,4,6,STATIONARY_WATER:0)
Block(3,4,7,STATIONARY_WATER:0)
Block(3,4,8,STATIONARY_WATER:0)
Block(3,4,9,STATIONARY_WATER:0)
Block(3,4,10,STATIONARY_WATER:0)
Block(3,4,11,STATIONARY_WATER:0)
Block(3,4,12,STAINED_CLAY:4)
Block(3,5,-12,STAINED_CLAY:4)
Block(3,5,-11,STATIONARY_WATER:0)
Block(3,5,-10,STATIONARY_WATER:0)
Block(3,5,-9,STATIONARY_WATER:0)
Block(3,5,-8,STATIONARY_WATER:0)
Block(3,5,-7,STATIONARY_WATER:0)
Block(3,5,-6,STATIONARY_WATER:0)
Block(3,5,-5,STATIONARY_WATER:0)
Block(3,5,-4,STATIONARY_WATER:0)
Block(3,5,-3,STATIONARY_WATER:0)
Block(3,5,-2,STATIONARY_WATER:0)
Block(3,5,-1,STATIONARY_WATER:0)
Block(3,5,0,STATIONARY_WATER:0)
Block(3,5,1,STATIONARY_WATER:0)
Block(3,5,2,STATIONARY_WATER:0)
Block(3,5,3,STATIONARY_WATER:0)
Block(3,5,4,STATIONARY_WATER:0)
Block(3,5,5,STATIONARY_WATER:0)
Block(3,5,6,STATIONARY_WATER:0)
Block(3,5,7,STATIONARY_WATER:0)
Block(3,5,8,STATIONARY_WATER:0)
Block(3,5,9,STATIONARY_WATER:0)
Block(3,5,10,STATIONARY_WATER:0)
Block(3,5,11,STATIONARY_WATER:0)
