
#######################################################################
# +-----------------------------------------------------------------+ #
# |                            BO4 object                           | #
# +-----------------------------------------------------------------+ #
#######################################################################

Author: NLBlackEagle

Description: No description given

SettingsMode: WriteDisable


#######################################################################
# +-----------------------------------------------------------------+ #
# |                          Main settings                          | #
# +-----------------------------------------------------------------+ #
#######################################################################

Frequency: 0

SpawnHeight: highestBlock

UseCenterForHighestBlock: true

##############################
# Height Limits for the BO4. #
##############################

MinHeight: 0

MaxHeight: 255

InheritBO3: 

InheritBO3Rotation: NORTH

OverrideChildSettings: true

OverrideParentHeight: false

CanOverride: true

BranchFrequency: 0

BranchFrequencyGroup: 

MustBeBelowOther: false

MustBeInside: 

CannotBeInside: 

ReplacesBO3: 

MustBeInsideWorldBorders: false

CanSpawnOnWater: true

SpawnOnWaterOnly: false

SpawnUnderWater: false

SpawnAtWaterLevel: false

HeightOffset: 0

RemoveAir: false

ReplaceAbove: 

ReplaceBelow: 

ReplaceWithBiomeBlocks: true

ReplaceWithSurfaceBlock: GRASS

ReplaceWithGroundBlock: DIRT

ReplaceWithStoneBlock: STONE

SmoothRadius: 0

SmoothHeightOffset: 0

SmoothStartTop: false

SmoothStartWood: false

SmoothingSurfaceBlock: 

SmoothingGroundBlock: 

BO3Group: 

IsSpawnPoint: false

DoReplaceBlocks: false


#######################################################################
# +-----------------------------------------------------------------+ #
# |                              Blocks                             | #
# +-----------------------------------------------------------------+ #
#######################################################################

Block(-8,5,-7,STEP:11)
Block(-8,5,8,STEP:11)
Block(-8,6,-7,COBBLESTONE_STAIRS:1)
Block(-8,6,8,COBBLESTONE_STAIRS:1)
Block(-8,7,-7,COBBLESTONE_STAIRS:5)
Block(-8,7,8,COBBLESTONE_STAIRS:5)
Block(-7,5,-7,COBBLESTONE_STAIRS:4)
Block(-7,5,8,COBBLESTONE_STAIRS:4)
Block(-6,4,-7,COBBLESTONE_STAIRS:4)
Block(-6,4,8,COBBLESTONE_STAIRS:4)
Block(-6,5,-7,LOG:9)
Block(-6,5,8,LOG:9)
Block(-6,6,-7,COBBLESTONE_STAIRS:0)
Block(-6,6,8,COBBLESTONE_STAIRS:0)
Block(-6,7,-7,COBBLESTONE_STAIRS:4)
Block(-6,7,8,COBBLESTONE_STAIRS:4)
Block(-5,0,-7,COBBLESTONE:0)
Block(-5,0,2,COBBLESTONE:0)
Block(-5,0,5,COBBLESTONE:0)
Block(-5,0,8,COBBLESTONE:0)
Block(-5,1,-7,COBBLESTONE:0)
Block(-5,1,2,COBBLESTONE:0)
Block(-5,1,5,COBBLESTONE:0)
Block(-5,1,8,COBBLESTONE:0)
Block(-5,2,-7,COBBLESTONE:0)
Block(-5,2,2,COBBLESTONE:0)
Block(-5,2,5,COBBLESTONE:0)
Block(-5,2,8,COBBLESTONE:0)
Block(-5,3,-7,COBBLESTONE:0)
Block(-5,3,2,COBBLESTONE:0)
Block(-5,3,5,COBBLESTONE:0)
Block(-5,3,8,COBBLESTONE:0)
Block(-5,4,-7,COBBLESTONE:0)
Block(-5,4,-6,COBBLESTONE_STAIRS:7)
Block(-5,4,2,COBBLESTONE:0)
Block(-5,4,5,COBBLESTONE:0)
Block(-5,4,7,COBBLESTONE_STAIRS:6)
Block(-5,4,8,COBBLESTONE:0)
Block(-5,5,-7,COBBLESTONE:0)
Block(-5,5,-6,LOG:5)
Block(-5,5,-5,COBBLESTONE_STAIRS:7)
Block(-5,5,-4,STEP:11)
Block(-5,5,-3,STEP:11)
Block(-5,5,2,COBBLESTONE:0)
Block(-5,5,4,STEP:11)
Block(-5,5,5,COBBLESTONE:0)
Block(-5,5,6,COBBLESTONE_STAIRS:6)
Block(-5,5,7,LOG:5)
Block(-5,5,8,COBBLESTONE:0)
Block(-5,6,-7,COBBLESTONE:0)
Block(-5,6,-6,COBBLESTONE_STAIRS:3)
Block(-5,6,-3,COBBLESTONE_STAIRS:2)
Block(-5,6,-2,COBBLESTONE_STAIRS:7)
Block(-5,6,-1,COBBLESTONE:0)
Block(-5,6,0,STEP:11)
Block(-5,6,1,STEP:11)
Block(-5,6,2,COBBLESTONE:0)
Block(-5,6,3,COBBLESTONE_STAIRS:6)
Block(-5,6,4,COBBLESTONE_STAIRS:3)
Block(-5,6,5,COBBLESTONE:0)
Block(-5,6,7,COBBLESTONE_STAIRS:2)
Block(-5,6,8,COBBLESTONE:0)
Block(-5,7,-7,LOG:1)
Block(-5,7,-6,COBBLESTONE_STAIRS:7)
Block(-5,7,-3,COBBLESTONE_STAIRS:6)
Block(-5,7,-2,LOG:1)
Block(-5,7,-1,STEP:11)
Block(-5,7,0,STEP:11)
Block(-5,7,1,STEP:11)
Block(-5,7,2,LOG:1)
Block(-5,7,3,COBBLESTONE:0)
Block(-5,7,4,COBBLESTONE_STAIRS:7)
Block(-5,7,5,LOG:1)
Block(-5,7,7,COBBLESTONE_STAIRS:6)
Block(-5,7,8,LOG:1)
Block(-4,5,-6,LOG:5)
Block(-4,5,7,LOG:5)
Block(-3,5,-6,LOG:5)
Block(-3,5,7,LOG:5)
Block(-2,0,-7,COBBLESTONE:0)
Block(-2,0,8,COBBLESTONE:0)
Block(-2,1,-7,COBBLESTONE:0)
Block(-2,1,8,COBBLESTONE:0)
Block(-2,2,-7,COBBLESTONE:0)
Block(-2,2,8,COBBLESTONE:0)
Block(-2,3,-7,COBBLESTONE:0)
Block(-2,3,8,COBBLESTONE:0)
Block(-2,4,-7,COBBLESTONE:0)
Block(-2,4,-6,COBBLESTONE_STAIRS:7)
Block(-2,4,7,COBBLESTONE_STAIRS:6)
Block(-2,4,8,COBBLESTONE:0)
Block(-2,5,-7,COBBLESTONE:0)
Block(-2,5,-6,LOG:5)
Block(-2,5,-5,COBBLESTONE_STAIRS:7)
Block(-2,5,-4,STEP:11)
Block(-2,5,-3,STEP:11)
Block(-2,5,4,STEP:11)
Block(-2,5,5,STEP:11)
Block(-2,5,6,COBBLESTONE_STAIRS:6)
Block(-2,5,7,LOG:5)
Block(-2,5,8,COBBLESTONE:0)
Block(-2,6,-7,COBBLESTONE:0)
Block(-2,6,-6,COBBLESTONE_STAIRS:3)
Block(-2,6,-3,COBBLESTONE_STAIRS:2)
Block(-2,6,-2,COBBLESTONE_STAIRS:7)
Block(-2,6,-1,COBBLESTONE:0)
Block(-2,6,0,STEP:11)
Block(-2,6,1,STEP:11)
Block(-2,6,2,COBBLESTONE:0)
Block(-2,6,3,COBBLESTONE_STAIRS:6)
Block(-2,6,4,COBBLESTONE_STAIRS:3)
Block(-2,6,7,COBBLESTONE_STAIRS:2)
Block(-2,6,8,COBBLESTONE:0)
Block(-2,7,-7,LOG:1)
Block(-2,7,-6,COBBLESTONE_STAIRS:7)
Block(-2,7,-3,COBBLESTONE_STAIRS:6)
Block(-2,7,-2,LOG:1)
Block(-2,7,-1,STEP:11)
Block(-2,7,0,STEP:11)
Block(-2,7,1,STEP:11)
Block(-2,7,2,STEP:11)
Block(-2,7,3,LOG:1)
Block(-2,7,4,COBBLESTONE_STAIRS:7)
Block(-2,7,7,COBBLESTONE_STAIRS:6)
Block(-2,7,8,LOG:1)
Block(-1,5,-6,LOG:5)
Block(-1,5,7,LOG:5)
Block(0,5,-6,LOG:5)
Block(0,5,7,LOG:5)
Block(1,0,-7,COBBLESTONE:0)
Block(1,0,8,COBBLESTONE:0)
Block(1,1,-7,COBBLESTONE:0)
Block(1,1,8,COBBLESTONE:0)
Block(1,2,-7,COBBLESTONE:0)
Block(1,2,8,COBBLESTONE:0)
Block(1,3,-7,COBBLESTONE:0)
Block(1,3,8,COBBLESTONE:0)
Block(1,4,-7,COBBLESTONE:0)
Block(1,4,-6,COBBLESTONE_STAIRS:7)
Block(1,4,7,COBBLESTONE_STAIRS:6)
Block(1,4,8,COBBLESTONE:0)
Block(1,5,-7,COBBLESTONE:0)
Block(1,5,-6,LOG:5)
Block(1,5,-5,COBBLESTONE_STAIRS:7)
Block(1,5,-4,STEP:11)
Block(1,5,-3,STEP:11)
Block(1,5,4,STEP:11)
Block(1,5,5,STEP:11)
Block(1,5,6,COBBLESTONE_STAIRS:6)
Block(1,5,7,LOG:5)
Block(1,5,8,COBBLESTONE:0)
Block(1,6,-7,COBBLESTONE:0)
Block(1,6,-6,COBBLESTONE_STAIRS:3)
Block(1,6,-3,COBBLESTONE_STAIRS:2)
Block(1,6,-2,COBBLESTONE_STAIRS:7)
Block(1,6,-1,COBBLESTONE:0)
Block(1,6,0,STEP:11)
Block(1,6,1,STEP:11)
Block(1,6,2,COBBLESTONE:0)
Block(1,6,3,COBBLESTONE_STAIRS:6)
Block(1,6,4,COBBLESTONE_STAIRS:3)
Block(1,6,7,COBBLESTONE_STAIRS:2)
Block(1,6,8,COBBLESTONE:0)
Block(1,7,-7,LOG:1)
Block(1,7,-6,COBBLESTONE_STAIRS:7)
Block(1,7,-3,COBBLESTONE_STAIRS:6)
Block(1,7,-2,LOG:1)
Block(1,7,-1,STEP:11)
Block(1,7,0,STEP:11)
Block(1,7,1,STEP:11)
Block(1,7,2,STEP:11)
Block(1,7,3,LOG:1)
Block(1,7,4,COBBLESTONE_STAIRS:7)
Block(1,7,7,COBBLESTONE_STAIRS:6)
Block(1,7,8,LOG:1)
Block(7,750,8,AIR:0)

#######################################################################
# +-----------------------------------------------------------------+ #
# |                             Branches                            | #
# +-----------------------------------------------------------------+ #
#######################################################################


#######################################################################
# +-----------------------------------------------------------------+ #
# |                             Entities                            | #
# +-----------------------------------------------------------------+ #
#######################################################################


#######################################################################
# +-----------------------------------------------------------------+ #
# |                            Particles                            | #
# +-----------------------------------------------------------------+ #
#######################################################################


#######################################################################
# +-----------------------------------------------------------------+ #
# |                             Spawners                            | #
# +-----------------------------------------------------------------+ #
#######################################################################


#######################################################################
# +-----------------------------------------------------------------+ #
# |                             ModData                             | #
# +-----------------------------------------------------------------+ #
#######################################################################

