
#######################################################################
# +-----------------------------------------------------------------+ #
# |                            BO4 object                           | #
# +-----------------------------------------------------------------+ #
#######################################################################

Author: NLBlackEagle

Description: No description given

SettingsMode: WriteDisable


#######################################################################
# +-----------------------------------------------------------------+ #
# |                          Main settings                          | #
# +-----------------------------------------------------------------+ #
#######################################################################

Frequency: 0

SpawnHeight: highestBlock

UseCenterForHighestBlock: true

##############################
# Height Limits for the BO4. #
##############################

MinHeight: 0

MaxHeight: 255

InheritBO3: 

InheritBO3Rotation: NORTH

OverrideChildSettings: true

OverrideParentHeight: false

CanOverride: true

BranchFrequency: 0

BranchFrequencyGroup: 

MustBeBelowOther: false

MustBeInside: 

CannotBeInside: 

ReplacesBO3: 

MustBeInsideWorldBorders: false

CanSpawnOnWater: true

SpawnOnWaterOnly: false

SpawnUnderWater: false

SpawnAtWaterLevel: false

HeightOffset: 0

RemoveAir: false

ReplaceAbove: 

ReplaceBelow: 

ReplaceWithBiomeBlocks: true

ReplaceWithSurfaceBlock: GRASS

ReplaceWithGroundBlock: DIRT

ReplaceWithStoneBlock: STONE

SmoothRadius: 0

SmoothHeightOffset: 0

SmoothStartTop: false

SmoothStartWood: false

SmoothingSurfaceBlock: 

SmoothingGroundBlock: 

BO3Group: 

IsSpawnPoint: false

DoReplaceBlocks: false


#######################################################################
# +-----------------------------------------------------------------+ #
# |                              Blocks                             | #
# +-----------------------------------------------------------------+ #
#######################################################################

Block(-7,0,0,COBBLESTONE:0)
Block(-7,0,3,COBBLESTONE:0)
Block(-7,1,0,COBBLESTONE:0)
Block(-7,1,3,COBBLESTONE:0)
Block(-7,2,0,COBBLESTONE:0)
Block(-7,2,3,COBBLESTONE:0)
Block(-7,3,0,COBBLESTONE:0)
Block(-7,3,3,COBBLESTONE:0)
Block(-7,4,0,COBBLESTONE:0)
Block(-7,4,3,COBBLESTONE:0)
Block(-7,5,0,COBBLESTONE:0)
Block(-7,5,3,COBBLESTONE:0)
Block(-7,6,0,COBBLESTONE:0)
Block(-7,6,3,COBBLESTONE:0)
Block(-5,0,-4,COBBLESTONE:0)
Block(-5,0,0,COBBLESTONE:0)
Block(-5,0,3,COBBLESTONE:0)
Block(-5,0,7,COBBLESTONE:0)
Block(-5,1,-4,COBBLESTONE:0)
Block(-5,1,0,COBBLESTONE:0)
Block(-5,1,3,COBBLESTONE:0)
Block(-5,1,7,COBBLESTONE:0)
Block(-5,2,-4,COBBLESTONE:0)
Block(-5,2,0,COBBLESTONE:0)
Block(-5,2,3,COBBLESTONE:0)
Block(-5,2,7,COBBLESTONE:0)
Block(-5,3,-4,COBBLESTONE:0)
Block(-5,3,0,COBBLESTONE:0)
Block(-5,3,3,COBBLESTONE:0)
Block(-5,3,7,COBBLESTONE:0)
Block(-5,4,-4,COBBLESTONE:0)
Block(-5,4,0,COBBLESTONE:0)
Block(-5,4,3,COBBLESTONE:0)
Block(-5,4,7,COBBLESTONE:0)
Block(-5,5,-4,COBBLESTONE:0)
Block(-5,5,0,COBBLESTONE:0)
Block(-5,5,3,COBBLESTONE:0)
Block(-5,5,7,COBBLESTONE:0)
Block(-5,6,-4,COBBLESTONE:0)
Block(-5,6,0,COBBLESTONE:0)
Block(-5,6,3,COBBLESTONE:0)
Block(-5,6,7,COBBLESTONE:0)
Block(-1,0,-6,COBBLESTONE:0)
Block(-1,0,-4,COBBLESTONE:0)
Block(-1,0,7,COBBLESTONE:0)
Block(-1,0,9,COBBLESTONE:0)
Block(-1,1,-6,COBBLESTONE:0)
Block(-1,1,-4,COBBLESTONE:0)
Block(-1,1,7,COBBLESTONE:0)
Block(-1,1,9,COBBLESTONE:0)
Block(-1,2,-6,COBBLESTONE:0)
Block(-1,2,-4,COBBLESTONE:0)
Block(-1,2,7,COBBLESTONE:0)
Block(-1,2,9,COBBLESTONE:0)
Block(-1,3,-6,COBBLESTONE:0)
Block(-1,3,-4,COBBLESTONE:0)
Block(-1,3,7,COBBLESTONE:0)
Block(-1,3,9,COBBLESTONE:0)
Block(-1,4,-6,COBBLESTONE:0)
Block(-1,4,-4,COBBLESTONE:0)
Block(-1,4,7,COBBLESTONE:0)
Block(-1,4,9,COBBLESTONE:0)
Block(-1,5,-6,COBBLESTONE:0)
Block(-1,5,-4,COBBLESTONE:0)
Block(-1,5,7,COBBLESTONE:0)
Block(-1,5,9,COBBLESTONE:0)
Block(-1,6,-6,COBBLESTONE:0)
Block(-1,6,-4,COBBLESTONE:0)
Block(-1,6,7,COBBLESTONE:0)
Block(-1,6,9,COBBLESTONE:0)
Block(2,0,-6,COBBLESTONE:0)
Block(2,0,-4,COBBLESTONE:0)
Block(2,0,7,COBBLESTONE:0)
Block(2,0,9,COBBLESTONE:0)
Block(2,1,-6,COBBLESTONE:0)
Block(2,1,-4,COBBLESTONE:0)
Block(2,1,7,COBBLESTONE:0)
Block(2,1,9,COBBLESTONE:0)
Block(2,2,-6,COBBLESTONE:0)
Block(2,2,-4,COBBLESTONE:0)
Block(2,2,7,COBBLESTONE:0)
Block(2,2,9,COBBLESTONE:0)
Block(2,3,-6,COBBLESTONE:0)
Block(2,3,-4,COBBLESTONE:0)
Block(2,3,7,COBBLESTONE:0)
Block(2,3,9,COBBLESTONE:0)
Block(2,4,-6,COBBLESTONE:0)
Block(2,4,-4,COBBLESTONE:0)
Block(2,4,7,COBBLESTONE:0)
Block(2,4,9,COBBLESTONE:0)
Block(2,5,-6,COBBLESTONE:0)
Block(2,5,-4,COBBLESTONE:0)
Block(2,5,7,COBBLESTONE:0)
Block(2,5,9,COBBLESTONE:0)
Block(2,6,-6,COBBLESTONE:0)
Block(2,6,-4,COBBLESTONE:0)
Block(2,6,7,COBBLESTONE:0)
Block(2,6,9,COBBLESTONE:0)
Block(6,0,-4,COBBLESTONE:0)
Block(6,0,0,COBBLESTONE:0)
Block(6,0,3,COBBLESTONE:0)
Block(6,0,7,COBBLESTONE:0)
Block(6,1,-4,COBBLESTONE:0)
Block(6,1,0,COBBLESTONE:0)
Block(6,1,3,COBBLESTONE:0)
Block(6,1,7,COBBLESTONE:0)
Block(6,2,-4,COBBLESTONE:0)
Block(6,2,0,COBBLESTONE:0)
Block(6,2,3,COBBLESTONE:0)
Block(6,2,7,COBBLESTONE:0)
Block(6,3,-4,COBBLESTONE:0)
Block(6,3,0,COBBLESTONE:0)
Block(6,3,3,COBBLESTONE:0)
Block(6,3,7,COBBLESTONE:0)
Block(6,4,-4,COBBLESTONE:0)
Block(6,4,0,COBBLESTONE:0)
Block(6,4,3,COBBLESTONE:0)
Block(6,4,7,COBBLESTONE:0)
Block(6,5,-4,COBBLESTONE:0)
Block(6,5,0,COBBLESTONE:0)
Block(6,5,3,COBBLESTONE:0)
Block(6,5,7,COBBLESTONE:0)
Block(6,6,-4,COBBLESTONE:0)
Block(6,6,0,COBBLESTONE:0)
Block(6,6,3,COBBLESTONE:0)
Block(6,6,7,COBBLESTONE:0)
Block(8,0,0,COBBLESTONE:0)
Block(8,0,3,COBBLESTONE:0)
Block(8,1,0,COBBLESTONE:0)
Block(8,1,3,COBBLESTONE:0)
Block(8,2,0,COBBLESTONE:0)
Block(8,2,3,COBBLESTONE:0)
Block(8,3,0,COBBLESTONE:0)
Block(8,3,3,COBBLESTONE:0)
Block(8,4,0,COBBLESTONE:0)
Block(8,4,3,COBBLESTONE:0)
Block(8,5,0,COBBLESTONE:0)
Block(8,5,3,COBBLESTONE:0)
Block(8,6,0,COBBLESTONE:0)
Block(8,6,3,COBBLESTONE:0)

#######################################################################
# +-----------------------------------------------------------------+ #
# |                             Branches                            | #
# +-----------------------------------------------------------------+ #
#######################################################################


#######################################################################
# +-----------------------------------------------------------------+ #
# |                             Entities                            | #
# +-----------------------------------------------------------------+ #
#######################################################################


#######################################################################
# +-----------------------------------------------------------------+ #
# |                            Particles                            | #
# +-----------------------------------------------------------------+ #
#######################################################################


#######################################################################
# +-----------------------------------------------------------------+ #
# |                             Spawners                            | #
# +-----------------------------------------------------------------+ #
#######################################################################


#######################################################################
# +-----------------------------------------------------------------+ #
# |                             ModData                             | #
# +-----------------------------------------------------------------+ #
#######################################################################

