#######################################################################
# +-----------------------------------------------------------------+ #
# |                            BO3 object                           | #
# +-----------------------------------------------------------------+ #
#######################################################################

Author: Bo3 BulkEdit

Description: Converted Schematic - Modified by Bo3BulkEdit

Version: 3

SettingsMode: WriteDisable

#######################################################################
# +-----------------------------------------------------------------+ #
# |                          Main settings                          | #
# +-----------------------------------------------------------------+ #
#######################################################################

IsOTGPlus: true
Tree: false
Frequency: 1
Rarity: 100.0
RotateRandomly: false
SpawnHeight: randomY
MaxBranchDepth: 10
ExcludedBiomes: All

##############################
# Height Limits for the BO3. #
##############################

MinHeight: 0
MaxHeight: 255

#######################################################################
# +-----------------------------------------------------------------+ #
# |                      Source block settings                      | #
# +-----------------------------------------------------------------+ #
#######################################################################

CanOverride: true
MaxPercentageOutsideSourceBlock: 100
OutsideSourceBlock: placeAnyway

#######################################################################
# +-----------------------------------------------------------------+ #
# |                               OTG+                              | #
# +-----------------------------------------------------------------+ #
#######################################################################

BO3Group: CeilingCrystals:0

#######################################################################
# +-----------------------------------------------------------------+ #
# |                              Blocks                             | #
# +-----------------------------------------------------------------+ #
#######################################################################

B(0,750,0,AIR)
B(15,750,15,AIR)
B(9,-35,10,betternether:quartz_stained_glass:15)
B(10,-35,10,betternether:quartz_stained_glass:15)
B(10,-35,11,betternether:quartz_stained_glass:15)
B(11,-35,11,betternether:quartz_stained_glass:15)
B(10,-35,12,betternether:quartz_stained_glass:15)
B(11,-35,12,betternether:quartz_stained_glass:15)
B(9,-34,9,betternether:quartz_stained_glass:15)
B(10,-34,9,betternether:quartz_stained_glass:15)
B(11,-34,9,betternether:quartz_stained_glass:15)
B(9,-34,10,betternether:quartz_stained_glass:15)
B(10,-34,10,betternether:quartz_stained_glass:15)
B(11,-34,10,betternether:quartz_stained_glass:15)
B(9,-34,11,betternether:quartz_stained_glass:15)
B(10,-34,11,betternether:quartz_stained_glass:15)
B(11,-34,11,betternether:quartz_stained_glass:15)
B(10,-34,12,betternether:quartz_stained_glass:15)
B(11,-34,12,betternether:quartz_stained_glass:15)
B(9,-33,6,betternether:quartz_stained_glass:15)
B(10,-33,6,betternether:quartz_stained_glass:15)
B(9,-33,7,betternether:quartz_stained_glass:15)
B(10,-33,7,betternether:quartz_stained_glass:15)
B(11,-33,7,betternether:quartz_stained_glass:15)
B(8,-33,8,betternether:quartz_stained_glass:15)
RB(9,-33,8,srparasites:parasitestain:1,80,quark:crystal:1,30,srparasites:parasiterubbledense:1,100)
B(10,-33,8,betternether:quartz_stained_glass:15)
B(11,-33,8,betternether:quartz_stained_glass:15)
B(7,-33,9,betternether:quartz_stained_glass:15)
RB(8,-33,9,srparasites:parasitestain:1,80,quark:crystal:1,30,srparasites:parasiterubbledense:1,100)
RB(9,-33,9,srparasites:parasitestain:1,80,quark:crystal:1,30,srparasites:parasiterubbledense:1,100)
B(10,-33,9,betternether:quartz_stained_glass:15)
B(11,-33,9,betternether:quartz_stained_glass:15)
B(7,-33,10,betternether:quartz_stained_glass:15)
RB(8,-33,10,srparasites:parasitestain:1,80,quark:crystal:1,30,srparasites:parasiterubbledense:1,100)
B(9,-33,10,betternether:quartz_stained_glass:15)
B(10,-33,10,betternether:quartz_stained_glass:15)
B(11,-33,10,betternether:quartz_stained_glass:15)
B(12,-33,10,betternether:quartz_stained_glass:15)
B(7,-33,11,betternether:quartz_stained_glass:15)
B(8,-33,11,betternether:quartz_stained_glass:15)
B(9,-33,11,betternether:quartz_stained_glass:15)
B(10,-33,11,betternether:quartz_stained_glass:15)
B(11,-33,11,betternether:quartz_stained_glass:15)
B(12,-33,11,betternether:quartz_stained_glass:15)
B(8,-33,12,betternether:quartz_stained_glass:15)
B(9,-33,12,betternether:quartz_stained_glass:15)
B(11,-33,12,betternether:quartz_stained_glass:15)
B(10,-32,5,betternether:quartz_stained_glass:15)
B(9,-32,6,betternether:quartz_stained_glass:15)
B(10,-32,6,betternether:quartz_stained_glass:15)
B(11,-32,6,betternether:quartz_stained_glass:15)
B(7,-32,7,srparasites:parasiterubbledense:1)
B(8,-32,7,srparasites:parasiterubbledense:1)
B(9,-32,7,srparasites:parasiterubbledense:1)
B(10,-32,7,betternether:quartz_stained_glass:15)
B(11,-32,7,betternether:quartz_stained_glass:15)
B(6,-32,8,srparasites:parasiterubbledense:1)
RB(7,-32,8,srparasites:parasitestain:1,80,quark:crystal:1,30,srparasites:parasiterubbledense:1,100)
RB(8,-32,8,srparasites:parasitestain:1,80,quark:crystal:1,30,srparasites:parasiterubbledense:1,100)
RB(9,-32,8,srparasites:parasitestain:1,80,quark:crystal:1,30,srparasites:parasiterubbledense:1,100)
B(10,-32,8,betternether:quartz_stained_glass:15)
B(11,-32,8,betternether:quartz_stained_glass:15)
B(12,-32,8,betternether:quartz_stained_glass:15)
B(5,-32,9,betternether:quartz_stained_glass:15)
B(6,-32,9,betternether:quartz_stained_glass:15)
B(7,-32,9,betternether:quartz_stained_glass:15)
RB(8,-32,9,srparasites:parasitestain:1,80,quark:crystal:1,30,srparasites:parasiterubbledense:1,100)
RB(9,-32,9,srparasites:parasitestain:1,80,quark:crystal:1,30,srparasites:parasiterubbledense:1,100)
B(10,-32,9,betternether:quartz_stained_glass:15)
B(11,-32,9,betternether:quartz_stained_glass:15)
B(12,-32,9,betternether:quartz_stained_glass:15)
B(6,-32,10,betternether:quartz_stained_glass:15)
B(7,-32,10,betternether:quartz_stained_glass:15)
B(8,-32,10,betternether:quartz_stained_glass:15)
B(9,-32,10,betternether:quartz_stained_glass:15)
B(10,-32,10,betternether:quartz_stained_glass:15)
B(11,-32,10,betternether:quartz_stained_glass:15)
B(12,-32,10,betternether:quartz_stained_glass:15)
B(7,-32,11,betternether:quartz_stained_glass:15)
B(8,-32,11,betternether:quartz_stained_glass:15)
B(9,-32,11,betternether:quartz_stained_glass:15)
B(10,-32,11,betternether:quartz_stained_glass:15)
B(11,-32,11,betternether:quartz_stained_glass:15)
B(10,-31,4,betternether:quartz_stained_glass:15)
B(6,-31,5,betternether:quartz_stained_glass:15)
B(8,-31,5,betternether:quartz_stained_glass:15)
B(9,-31,5,betternether:quartz_stained_glass:15)
B(10,-31,5,srparasites:parasiterubbledense:1)
B(5,-31,6,betternether:quartz_stained_glass:15)
B(6,-31,6,srparasites:parasiterubbledense:1)
B(7,-31,6,srparasites:parasiterubbledense:1)
B(8,-31,6,srparasites:parasiterubbledense:1)
B(9,-31,6,betternether:quartz_stained_glass:15)
B(10,-31,6,betternether:quartz_stained_glass:15)
B(11,-31,6,betternether:quartz_stained_glass:15)
B(5,-31,7,betternether:quartz_stained_glass:15)
B(6,-31,7,srparasites:parasiterubbledense:1)
B(7,-31,7,srparasites:parasiterubbledense:1)
B(8,-31,7,srparasites:parasiterubbledense:1)
RB(9,-31,7,srparasites:parasitestain:1,80,quark:crystal:1,30,srparasites:parasiterubbledense:1,100)
B(10,-31,7,betternether:quartz_stained_glass:15)
B(11,-31,7,betternether:quartz_stained_glass:15)
B(6,-31,8,betternether:quartz_stained_glass:15)
B(7,-31,8,betternether:quartz_stained_glass:15)
RB(8,-31,8,srparasites:parasitestain:1,80,quark:crystal:1,30,srparasites:parasiterubbledense:1,100)
RB(9,-31,8,srparasites:parasitestain:1,80,quark:crystal:1,30,srparasites:parasiterubbledense:1,100)
B(10,-31,8,betternether:quartz_stained_glass:15)
B(11,-31,8,betternether:quartz_stained_glass:15)
B(12,-31,8,betternether:quartz_stained_glass:15)
B(5,-31,9,betternether:quartz_stained_glass:15)
B(6,-31,9,betternether:quartz_stained_glass:15)
B(7,-31,9,betternether:quartz_stained_glass:15)
RB(8,-31,9,srparasites:parasitestain:1,80,quark:crystal:1,30,srparasites:parasiterubbledense:1,100)
B(9,-31,9,betternether:quartz_stained_glass:15)
B(10,-31,9,betternether:quartz_stained_glass:15)
B(11,-31,9,betternether:quartz_stained_glass:15)
B(6,-31,10,betternether:quartz_stained_glass:15)
B(7,-31,10,betternether:quartz_stained_glass:15)
B(8,-31,10,betternether:quartz_stained_glass:15)
B(9,-31,10,betternether:quartz_stained_glass:15)
B(10,-31,10,betternether:quartz_stained_glass:15)
B(11,-31,10,betternether:quartz_stained_glass:15)
B(12,-31,10,betternether:quartz_stained_glass:15)
B(7,-31,11,betternether:quartz_stained_glass:15)
B(8,-31,11,betternether:quartz_stained_glass:15)
B(9,-31,11,betternether:quartz_stained_glass:15)
B(8,-30,4,betternether:quartz_stained_glass:15)
B(9,-30,4,betternether:quartz_stained_glass:15)
B(10,-30,4,betternether:quartz_stained_glass:15)
B(5,-30,5,betternether:quartz_stained_glass:15)
B(6,-30,5,betternether:quartz_stained_glass:15)
B(7,-30,5,betternether:quartz_stained_glass:15)
B(8,-30,5,srparasites:parasiterubbledense:1)
B(9,-30,5,srparasites:parasiterubbledense:1)
B(10,-30,5,srparasites:parasiterubbledense:1)
B(5,-30,6,betternether:quartz_stained_glass:15)
B(6,-30,6,betternether:quartz_stained_glass:15)
B(7,-30,6,srparasites:parasiterubbledense:1)
RB(8,-30,6,srparasites:parasitestain:1,80,quark:crystal:1,30,srparasites:parasiterubbledense:1,100)
B(9,-30,6,betternether:quartz_stained_glass:15)
B(10,-30,6,betternether:quartz_stained_glass:15)
B(11,-30,6,betternether:quartz_stained_glass:15)
B(12,-30,6,betternether:quartz_stained_glass:15)
B(5,-30,7,betternether:quartz_stained_glass:15)
B(6,-30,7,betternether:quartz_stained_glass:15)
B(7,-30,7,betternether:quartz_stained_glass:15)
RB(8,-30,7,srparasites:parasitestain:1,80,quark:crystal:1,30,srparasites:parasiterubbledense:1,100)
RB(9,-30,7,srparasites:parasitestain:1,80,quark:crystal:1,30,srparasites:parasiterubbledense:1,100)
B(10,-30,7,betternether:quartz_stained_glass:15)
B(11,-30,7,betternether:quartz_stained_glass:15)
B(5,-30,8,betternether:quartz_stained_glass:15)
B(6,-30,8,betternether:quartz_stained_glass:15)
B(7,-30,8,betternether:quartz_stained_glass:15)
RB(8,-30,8,srparasites:parasitestain:1,80,quark:crystal:1,30,srparasites:parasiterubbledense:1,100)
B(9,-30,8,betternether:quartz_stained_glass:15)
B(10,-30,8,betternether:quartz_stained_glass:15)
B(11,-30,8,betternether:quartz_stained_glass:15)
B(12,-30,8,betternether:quartz_stained_glass:15)
B(5,-30,9,betternether:quartz_stained_glass:15)
B(6,-30,9,betternether:quartz_stained_glass:15)
B(7,-30,9,betternether:quartz_stained_glass:15)
B(8,-30,9,betternether:quartz_stained_glass:15)
B(9,-30,9,betternether:quartz_stained_glass:15)
B(10,-30,9,betternether:quartz_stained_glass:15)
B(11,-30,9,betternether:quartz_stained_glass:15)
B(6,-30,10,betternether:quartz_stained_glass:15)
B(7,-30,10,betternether:quartz_stained_glass:15)
B(8,-30,10,betternether:quartz_stained_glass:15)
B(9,-30,10,betternether:quartz_stained_glass:15)
B(7,-30,11,betternether:quartz_stained_glass:15)
B(9,-30,11,betternether:quartz_stained_glass:15)
B(10,-29,3,betternether:quartz_stained_glass:15)
B(6,-29,4,betternether:quartz_stained_glass:15)
B(7,-29,4,betternether:quartz_stained_glass:15)
B(8,-29,4,srparasites:parasiterubbledense:1)
B(9,-29,4,srparasites:parasiterubbledense:1)
B(10,-29,4,betternether:quartz_stained_glass:15)
B(5,-29,5,betternether:quartz_stained_glass:15)
B(6,-29,5,betternether:quartz_stained_glass:15)
B(7,-29,5,srparasites:parasiterubbledense:1)
B(8,-29,5,srparasites:parasiterubbledense:1)
B(9,-29,5,srparasites:parasiterubbledense:1)
B(10,-29,5,betternether:quartz_stained_glass:15)
B(5,-29,6,betternether:quartz_stained_glass:15)
B(6,-29,6,betternether:quartz_stained_glass:15)
RB(7,-29,6,srparasites:parasitestain:1,80,quark:crystal:1,30,srparasites:parasiterubbledense:1,100)
RB(8,-29,6,srparasites:parasitestain:1,80,quark:crystal:1,30,srparasites:parasiterubbledense:1,100)
B(9,-29,6,betternether:quartz_stained_glass:15)
B(10,-29,6,betternether:quartz_stained_glass:15)
B(11,-29,6,betternether:quartz_stained_glass:15)
B(12,-29,6,betternether:quartz_stained_glass:15)
B(5,-29,7,betternether:quartz_stained_glass:15)
B(6,-29,7,betternether:quartz_stained_glass:15)
B(7,-29,7,betternether:quartz_stained_glass:15)
RB(8,-29,7,srparasites:parasitestain:1,80,quark:crystal:1,30,srparasites:parasiterubbledense:1,100)
RB(9,-29,7,srparasites:parasitestain:1,80,quark:crystal:1,30,srparasites:parasiterubbledense:1,100)
B(10,-29,7,betternether:quartz_stained_glass:15)
B(11,-29,7,betternether:quartz_stained_glass:15)
B(5,-29,8,betternether:quartz_stained_glass:15)
B(6,-29,8,betternether:quartz_stained_glass:15)
B(7,-29,8,betternether:quartz_stained_glass:15)
B(8,-29,8,betternether:quartz_stained_glass:15)
B(9,-29,8,betternether:quartz_stained_glass:15)
B(10,-29,8,betternether:quartz_stained_glass:15)
B(11,-29,8,betternether:quartz_stained_glass:15)
B(6,-29,9,betternether:quartz_stained_glass:15)
B(7,-29,9,betternether:quartz_stained_glass:15)
B(8,-29,9,betternether:quartz_stained_glass:15)
B(9,-29,9,betternether:quartz_stained_glass:15)
B(10,-29,9,betternether:quartz_stained_glass:15)
B(6,-29,10,betternether:quartz_stained_glass:15)
B(8,-29,10,betternether:quartz_stained_glass:15)
B(9,-28,2,betternether:quartz_stained_glass:15)
B(6,-28,3,betternether:quartz_stained_glass:15)
B(8,-28,3,betternether:quartz_stained_glass:15)
B(9,-28,3,betternether:quartz_stained_glass:15)
B(10,-28,3,betternether:quartz_stained_glass:15)
B(5,-28,4,betternether:quartz_stained_glass:15)
B(6,-28,4,betternether:quartz_stained_glass:15)
B(7,-28,4,betternether:quartz_stained_glass:15)
B(8,-28,4,srparasites:parasiterubbledense:1)
B(9,-28,4,srparasites:parasiterubbledense:1)
B(10,-28,4,betternether:quartz_stained_glass:15)
B(5,-28,5,betternether:quartz_stained_glass:15)
B(6,-28,5,betternether:quartz_stained_glass:15)
B(7,-28,5,betternether:quartz_stained_glass:15)
RB(8,-28,5,srparasites:parasitestain:1,80,quark:crystal:1,30,srparasites:parasiterubbledense:1,100)
B(9,-28,5,betternether:quartz_stained_glass:15)
B(10,-28,5,srparasites:parasiterubbledense:1)
B(11,-28,5,betternether:quartz_stained_glass:15)
B(5,-28,6,betternether:quartz_stained_glass:15)
B(6,-28,6,betternether:quartz_stained_glass:15)
RB(7,-28,6,srparasites:parasitestain:1,80,quark:crystal:1,30,srparasites:parasiterubbledense:1,100)
RB(8,-28,6,srparasites:parasitestain:1,80,quark:crystal:1,30,srparasites:parasiterubbledense:1,100)
B(9,-28,6,betternether:quartz_stained_glass:15)
B(10,-28,6,betternether:quartz_stained_glass:15)
B(11,-28,6,betternether:quartz_stained_glass:15)
B(12,-28,6,betternether:quartz_stained_glass:15)
B(4,-28,7,betternether:quartz_stained_glass:15)
B(5,-28,7,betternether:quartz_stained_glass:15)
B(6,-28,7,betternether:quartz_stained_glass:15)
B(7,-28,7,betternether:quartz_stained_glass:15)
RB(8,-28,7,srparasites:parasitestain:1,80,quark:crystal:1,30,srparasites:parasiterubbledense:1,100)
B(9,-28,7,betternether:quartz_stained_glass:15)
B(10,-28,7,betternether:quartz_stained_glass:15)
B(11,-28,7,betternether:quartz_stained_glass:15)
B(5,-28,8,betternether:quartz_stained_glass:15)
B(6,-28,8,betternether:quartz_stained_glass:15)
B(7,-28,8,betternether:quartz_stained_glass:15)
B(8,-28,8,betternether:quartz_stained_glass:15)
B(9,-28,8,betternether:quartz_stained_glass:15)
B(10,-28,8,betternether:quartz_stained_glass:15)
B(11,-28,8,betternether:quartz_stained_glass:15)
B(6,-28,9,betternether:quartz_stained_glass:15)
B(7,-28,9,betternether:quartz_stained_glass:15)
B(8,-28,9,betternether:quartz_stained_glass:15)
B(9,-28,9,betternether:quartz_stained_glass:15)
B(7,-27,2,betternether:quartz_stained_glass:15)
B(8,-27,2,betternether:quartz_stained_glass:15)
B(9,-27,2,srparasites:parasiterubbledense:1)
B(4,-27,3,betternether:quartz_stained_glass:15)
B(5,-27,3,betternether:quartz_stained_glass:15)
B(6,-27,3,betternether:quartz_stained_glass:15)
B(7,-27,3,betternether:quartz_stained_glass:15)
B(8,-27,3,srparasites:parasiterubbledense:1)
B(9,-27,3,srparasites:parasiterubbledense:1)
B(10,-27,3,betternether:quartz_stained_glass:15)
B(5,-27,4,betternether:quartz_stained_glass:15)
B(6,-27,4,betternether:quartz_stained_glass:15)
B(7,-27,4,betternether:quartz_stained_glass:15)
RB(8,-27,4,srparasites:parasitestain:1,80,quark:crystal:1,30,srparasites:parasiterubbledense:1,100)
B(9,-27,4,srparasites:parasiterubbledense:1)
B(10,-27,4,betternether:quartz_stained_glass:15)
B(5,-27,5,betternether:quartz_stained_glass:15)
B(6,-27,5,betternether:quartz_stained_glass:15)
RB(7,-27,5,srparasites:parasitestain:1,80,quark:crystal:1,30,srparasites:parasiterubbledense:1,100)
RB(8,-27,5,srparasites:parasitestain:1,80,quark:crystal:1,30,srparasites:parasiterubbledense:1,100)
B(9,-27,5,betternether:quartz_stained_glass:15)
B(10,-27,5,srparasites:parasiterubbledense:1)
B(11,-27,5,betternether:quartz_stained_glass:15)
B(5,-27,6,betternether:quartz_stained_glass:15)
B(6,-27,6,betternether:quartz_stained_glass:15)
RB(7,-27,6,srparasites:parasitestain:1,80,quark:crystal:1,30,srparasites:parasiterubbledense:1,100)
B(8,-27,6,betternether:quartz_stained_glass:15)
B(9,-27,6,betternether:quartz_stained_glass:15)
B(10,-27,6,srparasites:parasiterubbledense:1)
B(11,-27,6,betternether:quartz_stained_glass:15)
B(4,-27,7,betternether:quartz_stained_glass:15)
B(5,-27,7,betternether:quartz_stained_glass:15)
B(6,-27,7,betternether:quartz_stained_glass:15)
B(7,-27,7,betternether:quartz_stained_glass:15)
B(8,-27,7,betternether:quartz_stained_glass:15)
B(9,-27,7,betternether:quartz_stained_glass:15)
B(10,-27,7,srparasites:parasiterubbledense:1)
B(11,-27,7,betternether:quartz_stained_glass:15)
B(6,-27,8,betternether:quartz_stained_glass:15)
B(7,-27,8,betternether:quartz_stained_glass:15)
B(8,-27,8,betternether:quartz_stained_glass:15)
B(9,-27,8,betternether:quartz_stained_glass:15)
B(8,-27,9,betternether:quartz_stained_glass:15)
B(9,-26,1,betternether:quartz_stained_glass:15)
B(5,-26,2,betternether:quartz_stained_glass:15)
B(6,-26,2,betternether:quartz_stained_glass:15)
B(7,-26,2,betternether:quartz_stained_glass:15)
B(8,-26,2,srparasites:parasiterubbledense:1)
B(9,-26,2,srparasites:parasiterubbledense:1)
B(4,-26,3,betternether:quartz_stained_glass:15)
B(5,-26,3,betternether:quartz_stained_glass:15)
B(6,-26,3,betternether:quartz_stained_glass:15)
B(7,-26,3,betternether:quartz_stained_glass:15)
B(8,-26,3,betternether:quartz_stained_glass:15)
B(9,-26,3,srparasites:parasiterubbledense:1)
B(10,-26,3,betternether:quartz_stained_glass:15)
B(5,-26,4,betternether:quartz_stained_glass:15)
B(6,-26,4,betternether:quartz_stained_glass:15)
RB(7,-26,4,srparasites:parasitestain:1,80,quark:crystal:1,30,srparasites:parasiterubbledense:1,100)
RB(8,-26,4,srparasites:parasitestain:1,80,quark:crystal:1,30,srparasites:parasiterubbledense:1,100)
B(9,-26,4,betternether:quartz_stained_glass:15)
B(10,-26,4,betternether:quartz_stained_glass:15)
B(11,-26,4,betternether:quartz_stained_glass:15)
B(4,-26,5,betternether:quartz_stained_glass:15)
B(5,-26,5,betternether:quartz_stained_glass:15)
B(6,-26,5,betternether:quartz_stained_glass:15)
RB(7,-26,5,srparasites:parasitestain:1,80,quark:crystal:1,30,srparasites:parasiterubbledense:1,100)
RB(8,-26,5,srparasites:parasitestain:1,80,quark:crystal:1,30,srparasites:parasiterubbledense:1,100)
B(9,-26,5,betternether:quartz_stained_glass:15)
B(10,-26,5,srparasites:parasiterubbledense:1)
B(11,-26,5,betternether:quartz_stained_glass:15)
B(5,-26,6,betternether:quartz_stained_glass:15)
B(6,-26,6,betternether:quartz_stained_glass:15)
B(7,-26,6,betternether:quartz_stained_glass:15)
B(8,-26,6,betternether:quartz_stained_glass:15)
B(9,-26,6,betternether:quartz_stained_glass:15)
B(10,-26,6,betternether:quartz_stained_glass:15)
B(11,-26,6,betternether:quartz_stained_glass:15)
B(4,-26,7,betternether:quartz_stained_glass:15)
B(5,-26,7,betternether:quartz_stained_glass:15)
B(6,-26,7,betternether:quartz_stained_glass:15)
B(7,-26,7,betternether:quartz_stained_glass:15)
B(8,-26,7,betternether:quartz_stained_glass:15)
B(9,-26,7,betternether:quartz_stained_glass:15)
B(10,-26,7,betternether:quartz_stained_glass:15)
B(6,-26,8,betternether:quartz_stained_glass:15)
B(8,-26,8,betternether:quartz_stained_glass:15)
B(9,-25,0,betternether:quartz_stained_glass:15)
B(5,-25,1,betternether:quartz_stained_glass:15)
B(6,-25,1,betternether:quartz_stained_glass:15)
B(7,-25,1,betternether:quartz_stained_glass:15)
B(8,-25,1,betternether:quartz_stained_glass:15)
B(9,-25,1,betternether:quartz_stained_glass:15)
B(4,-25,2,betternether:quartz_stained_glass:15)
B(5,-25,2,betternether:quartz_stained_glass:15)
B(6,-25,2,betternether:quartz_stained_glass:15)
B(7,-25,2,betternether:quartz_stained_glass:15)
B(8,-25,2,betternether:quartz_stained_glass:15)
B(9,-25,2,betternether:quartz_stained_glass:15)
B(4,-25,3,betternether:quartz_stained_glass:15)
B(5,-25,3,betternether:quartz_stained_glass:15)
RB(6,-25,3,srparasites:parasitestain:1,80,quark:crystal:1,30,srparasites:parasiterubbledense:1,100)
B(7,-25,3,betternether:quartz_stained_glass:15)
RB(8,-25,3,srparasites:parasitestain:1,80,quark:crystal:1,30,srparasites:parasiterubbledense:1,100)
B(9,-25,3,betternether:quartz_stained_glass:15)
B(10,-25,3,betternether:quartz_stained_glass:15)
B(5,-25,4,betternether:quartz_stained_glass:15)
B(6,-25,4,betternether:quartz_stained_glass:15)
RB(7,-25,4,srparasites:parasitestain:1,80,quark:crystal:1,30,srparasites:parasiterubbledense:1,100)
RB(8,-25,4,srparasites:parasitestain:1,80,quark:crystal:1,30,srparasites:parasiterubbledense:1,100)
B(9,-25,4,betternether:quartz_stained_glass:15)
B(10,-25,4,betternether:quartz_stained_glass:15)
B(11,-25,4,betternether:quartz_stained_glass:15)
B(4,-25,5,betternether:quartz_stained_glass:15)
B(5,-25,5,betternether:quartz_stained_glass:15)
B(6,-25,5,betternether:quartz_stained_glass:15)
RB(7,-25,5,srparasites:parasitestain:1,80,quark:crystal:1,30,srparasites:parasiterubbledense:1,100)
B(8,-25,5,betternether:quartz_stained_glass:15)
B(9,-25,5,srparasites:parasiterubbledense:1)
B(10,-25,5,betternether:quartz_stained_glass:15)
B(5,-25,6,betternether:quartz_stained_glass:15)
B(6,-25,6,betternether:quartz_stained_glass:15)
B(7,-25,6,betternether:quartz_stained_glass:15)
B(8,-25,6,betternether:quartz_stained_glass:15)
B(9,-25,6,betternether:quartz_stained_glass:15)
B(11,-25,6,betternether:quartz_stained_glass:15)
B(5,-25,7,betternether:quartz_stained_glass:15)
B(6,-25,7,betternether:quartz_stained_glass:15)
B(7,-25,7,betternether:quartz_stained_glass:15)
B(8,-25,7,betternether:quartz_stained_glass:15)
B(9,-25,7,betternether:quartz_stained_glass:15)
B(7,-24,0,betternether:quartz_stained_glass:15)
B(8,-24,0,betternether:quartz_stained_glass:15)
B(9,-24,0,betternether:quartz_stained_glass:15)
B(4,-24,1,betternether:quartz_stained_glass:15)
B(5,-24,1,betternether:quartz_stained_glass:15)
B(6,-24,1,srparasites:parasiterubbledense:1)
B(7,-24,1,srparasites:parasiterubbledense:1)
B(8,-24,1,srparasites:parasiterubbledense:1)
B(9,-24,1,srparasites:parasiterubbledense:1)
B(4,-24,2,betternether:quartz_stained_glass:15)
B(5,-24,2,betternether:quartz_stained_glass:15)
B(6,-24,2,srparasites:parasiterubbledense:1)
RB(7,-24,2,srparasites:parasitestain:1,80,quark:crystal:1,30,srparasites:parasiterubbledense:1,100)
B(8,-24,2,betternether:quartz_stained_glass:15)
B(9,-24,2,betternether:quartz_stained_glass:15)
B(10,-24,2,betternether:quartz_stained_glass:15)
B(11,-24,2,betternether:quartz_stained_glass:15)
B(4,-24,3,betternether:quartz_stained_glass:15)
B(5,-24,3,betternether:quartz_stained_glass:15)
RB(6,-24,3,srparasites:parasitestain:1,80,quark:crystal:1,30,srparasites:parasiterubbledense:1,100)
RB(7,-24,3,srparasites:parasitestain:1,80,quark:crystal:1,30,srparasites:parasiterubbledense:1,100)
RB(8,-24,3,srparasites:parasitestain:1,80,quark:crystal:1,30,srparasites:parasiterubbledense:1,100)
B(9,-24,3,betternether:quartz_stained_glass:15)
B(10,-24,3,betternether:quartz_stained_glass:15)
B(4,-24,4,betternether:quartz_stained_glass:15)
B(5,-24,4,betternether:quartz_stained_glass:15)
B(6,-24,4,betternether:quartz_stained_glass:15)
RB(7,-24,4,srparasites:parasitestain:1,80,quark:crystal:1,30,srparasites:parasiterubbledense:1,100)
B(8,-24,4,srparasites:parasiterubbledense:1)
B(9,-24,4,srparasites:parasiterubbledense:1)
B(10,-24,4,betternether:quartz_stained_glass:15)
B(11,-24,4,betternether:quartz_stained_glass:15)
B(4,-24,5,betternether:quartz_stained_glass:15)
B(5,-24,5,betternether:quartz_stained_glass:15)
B(6,-24,5,betternether:quartz_stained_glass:15)
B(7,-24,5,betternether:quartz_stained_glass:15)
B(8,-24,5,srparasites:parasiterubbledense:1)
B(9,-24,5,srparasites:parasiterubbledense:1)
B(10,-24,5,betternether:quartz_stained_glass:15)
B(5,-24,6,betternether:quartz_stained_glass:15)
B(6,-24,6,betternether:quartz_stained_glass:15)
B(7,-24,6,betternether:quartz_stained_glass:15)
B(8,-24,6,betternether:quartz_stained_glass:15)
B(8,-24,7,betternether:quartz_stained_glass:15)
B(5,-23,0,betternether:quartz_stained_glass:15)
B(6,-23,0,betternether:quartz_stained_glass:15)
B(7,-23,0,srparasites:parasiterubbledense:1)
B(8,-23,0,srparasites:parasiterubbledense:1)
B(9,-23,0,betternether:quartz_stained_glass:15)
B(4,-23,1,betternether:quartz_stained_glass:15)
B(5,-23,1,betternether:quartz_stained_glass:15)
B(6,-23,1,srparasites:parasiterubbledense:1)
B(7,-23,1,srparasites:parasiterubbledense:1)
B(8,-23,1,srparasites:parasiterubbledense:1)
B(9,-23,1,betternether:quartz_stained_glass:15)
B(4,-23,2,betternether:quartz_stained_glass:15)
B(5,-23,2,betternether:quartz_stained_glass:15)
RB(6,-23,2,srparasites:parasitestain:1,80,quark:crystal:1,30,srparasites:parasiterubbledense:1,100)
RB(7,-23,2,srparasites:parasitestain:1,80,quark:crystal:1,30,srparasites:parasiterubbledense:1,100)
B(8,-23,2,betternether:quartz_stained_glass:15)
B(9,-23,2,betternether:quartz_stained_glass:15)
B(10,-23,2,betternether:quartz_stained_glass:15)
B(11,-23,2,betternether:quartz_stained_glass:15)
B(4,-23,3,betternether:quartz_stained_glass:15)
B(5,-23,3,betternether:quartz_stained_glass:15)
RB(6,-23,3,srparasites:parasitestain:1,80,quark:crystal:1,30,srparasites:parasiterubbledense:1,100)
RB(7,-23,3,srparasites:parasitestain:1,80,quark:crystal:1,30,srparasites:parasiterubbledense:1,100)
RB(8,-23,3,srparasites:parasitestain:1,80,quark:crystal:1,30,srparasites:parasiterubbledense:1,100)
B(9,-23,3,betternether:quartz_stained_glass:15)
B(10,-23,3,betternether:quartz_stained_glass:15)
B(4,-23,4,betternether:quartz_stained_glass:15)
B(5,-23,4,betternether:quartz_stained_glass:15)
B(6,-23,4,srparasites:parasiterubbledense:1)
B(7,-23,4,srparasites:parasiterubbledense:1)
B(8,-23,4,srparasites:parasiterubbledense:1)
B(9,-23,4,srparasites:parasiterubbledense:1)
B(10,-23,4,betternether:quartz_stained_glass:15)
B(5,-23,5,betternether:quartz_stained_glass:15)
B(6,-23,5,betternether:quartz_stained_glass:15)
B(7,-23,5,betternether:quartz_stained_glass:15)
B(8,-23,5,betternether:quartz_stained_glass:15)
B(9,-23,5,betternether:quartz_stained_glass:15)
B(5,-23,6,betternether:quartz_stained_glass:15)
B(7,-23,6,betternether:quartz_stained_glass:15)
B(4,-22,0,betternether:quartz_stained_glass:15)
B(5,-22,0,betternether:quartz_stained_glass:15)
B(6,-22,0,srparasites:parasiterubbledense:1)
B(7,-22,0,srparasites:parasiterubbledense:1)
B(8,-22,0,betternether:quartz_stained_glass:15)
B(9,-22,0,betternether:quartz_stained_glass:15)
B(4,-22,1,betternether:quartz_stained_glass:15)
B(5,-22,1,betternether:quartz_stained_glass:15)
RB(6,-22,1,srparasites:parasitestain:1,80,quark:crystal:1,30,srparasites:parasiterubbledense:1,100)
RB(7,-22,1,srparasites:parasitestain:1,80,quark:crystal:1,30,srparasites:parasiterubbledense:1,100)
B(8,-22,1,betternether:quartz_stained_glass:15)
B(9,-22,1,betternether:quartz_stained_glass:15)
B(10,-22,1,betternether:quartz_stained_glass:15)
B(4,-22,2,betternether:quartz_stained_glass:15)
B(5,-22,2,betternether:quartz_stained_glass:15)
RB(6,-22,2,srparasites:parasitestain:1,80,quark:crystal:1,30,srparasites:parasiterubbledense:1,100)
RB(7,-22,2,srparasites:parasitestain:1,80,quark:crystal:1,30,srparasites:parasiterubbledense:1,100)
B(8,-22,2,betternether:quartz_stained_glass:15)
B(9,-22,2,betternether:quartz_stained_glass:15)
B(10,-22,2,betternether:quartz_stained_glass:15)
B(11,-22,2,betternether:quartz_stained_glass:15)
B(3,-22,3,betternether:quartz_stained_glass:15)
B(4,-22,3,betternether:quartz_stained_glass:15)
B(5,-22,3,srparasites:parasiterubbledense:1)
B(6,-22,3,srparasites:parasiterubbledense:1)
RB(7,-22,3,srparasites:parasitestain:1,80,quark:crystal:1,30,srparasites:parasiterubbledense:1,100)
B(8,-22,3,betternether:quartz_stained_glass:15)
B(9,-22,3,betternether:quartz_stained_glass:15)
B(10,-22,3,betternether:quartz_stained_glass:15)
B(4,-22,4,betternether:quartz_stained_glass:15)
B(5,-22,4,srparasites:parasiterubbledense:1)
B(6,-22,4,srparasites:parasiterubbledense:1)
B(7,-22,4,srparasites:parasiterubbledense:1)
B(8,-22,4,betternether:quartz_stained_glass:15)
B(9,-22,4,betternether:quartz_stained_glass:15)
B(5,-22,5,betternether:quartz_stained_glass:15)
B(7,-22,5,betternether:quartz_stained_glass:15)
B(8,-22,5,betternether:quartz_stained_glass:15)
B(4,-21,0,srparasites:parasiterubbledense:1)
B(5,-21,0,srparasites:parasiterubbledense:1)
B(6,-21,0,srparasites:parasiterubbledense:1)
RB(7,-21,0,srparasites:parasitestain:1,80,quark:crystal:1,30,srparasites:parasiterubbledense:1,100)
B(8,-21,0,betternether:quartz_stained_glass:15)
B(9,-21,0,betternether:quartz_stained_glass:15)
B(4,-21,1,betternether:quartz_stained_glass:15)
B(5,-21,1,betternether:quartz_stained_glass:15)
RB(6,-21,1,srparasites:parasitestain:1,80,quark:crystal:1,30,srparasites:parasiterubbledense:1,100)
RB(7,-21,1,srparasites:parasitestain:1,80,quark:crystal:1,30,srparasites:parasiterubbledense:1,100)
B(8,-21,1,betternether:quartz_stained_glass:15)
B(9,-21,1,betternether:quartz_stained_glass:15)
B(10,-21,1,betternether:quartz_stained_glass:15)
B(4,-21,2,betternether:quartz_stained_glass:15)
B(5,-21,2,betternether:quartz_stained_glass:15)
RB(6,-21,2,srparasites:parasitestain:1,80,quark:crystal:1,30,srparasites:parasiterubbledense:1,100)
B(7,-21,2,srparasites:parasiterubbledense:1)
B(8,-21,2,betternether:quartz_stained_glass:15)
B(9,-21,2,betternether:quartz_stained_glass:15)
B(3,-21,3,betternether:quartz_stained_glass:15)
B(4,-21,3,betternether:quartz_stained_glass:15)
B(5,-21,3,srparasites:parasiterubbledense:1)
B(6,-21,3,srparasites:parasiterubbledense:1)
B(7,-21,3,srparasites:parasiterubbledense:1)
B(8,-21,3,betternether:quartz_stained_glass:15)
B(9,-21,3,betternether:quartz_stained_glass:15)
B(10,-21,3,betternether:quartz_stained_glass:15)
B(5,-21,4,srparasites:parasiterubbledense:1)
B(6,-21,4,betternether:quartz_stained_glass:15)
B(7,-21,4,betternether:quartz_stained_glass:15)
B(8,-21,4,betternether:quartz_stained_glass:15)
B(7,-21,5,betternether:quartz_stained_glass:15)
B(4,-20,0,srparasites:parasiterubbledense:1)
B(5,-20,0,betternether:quartz_stained_glass:15)
RB(6,-20,0,srparasites:parasitestain:1,80,quark:crystal:1,30,srparasites:parasiterubbledense:1,100)
RB(7,-20,0,srparasites:parasitestain:1,80,quark:crystal:1,30,srparasites:parasiterubbledense:1,100)
B(8,-20,0,betternether:quartz_stained_glass:15)
B(9,-20,0,betternether:quartz_stained_glass:15)
B(3,-20,1,betternether:quartz_stained_glass:15)
B(4,-20,1,betternether:quartz_stained_glass:15)
B(5,-20,1,betternether:quartz_stained_glass:15)
RB(6,-20,1,srparasites:parasitestain:1,80,quark:crystal:1,30,srparasites:parasiterubbledense:1,100)
RB(7,-20,1,srparasites:parasitestain:1,80,quark:crystal:1,30,srparasites:parasiterubbledense:1,100)
B(8,-20,1,betternether:quartz_stained_glass:15)
B(9,-20,1,betternether:quartz_stained_glass:15)
B(10,-20,1,betternether:quartz_stained_glass:15)
B(4,-20,2,betternether:quartz_stained_glass:15)
B(5,-20,2,srparasites:parasiterubbledense:1)
B(6,-20,2,betternether:quartz_stained_glass:15)
B(7,-20,2,betternether:quartz_stained_glass:15)
B(8,-20,2,betternether:quartz_stained_glass:15)
B(9,-20,2,betternether:quartz_stained_glass:15)
B(3,-20,3,betternether:quartz_stained_glass:15)
B(4,-20,3,betternether:quartz_stained_glass:15)
B(5,-20,3,srparasites:parasiterubbledense:1)
B(6,-20,3,betternether:quartz_stained_glass:15)
B(7,-20,3,betternether:quartz_stained_glass:15)
B(8,-20,3,betternether:quartz_stained_glass:15)
B(9,-20,3,betternether:quartz_stained_glass:15)
B(5,-20,4,betternether:quartz_stained_glass:15)
B(7,-20,4,betternether:quartz_stained_glass:15)
B(4,-19,0,srparasites:parasiterubbledense:1)
B(5,-19,0,betternether:quartz_stained_glass:15)
RB(6,-19,0,srparasites:parasitestain:1,80,quark:crystal:1,30,srparasites:parasiterubbledense:1,100)
RB(7,-19,0,srparasites:parasitestain:1,80,quark:crystal:1,30,srparasites:parasiterubbledense:1,100)
B(8,-19,0,betternether:quartz_stained_glass:15)
B(9,-19,0,betternether:quartz_stained_glass:15)
B(3,-19,1,betternether:quartz_stained_glass:15)
B(4,-19,1,srparasites:parasiterubbledense:1)
B(5,-19,1,srparasites:parasiterubbledense:1)
B(6,-19,1,betternether:quartz_stained_glass:15)
B(7,-19,1,betternether:quartz_stained_glass:15)
B(8,-19,1,betternether:quartz_stained_glass:15)
B(9,-19,1,betternether:quartz_stained_glass:15)
B(4,-19,2,betternether:quartz_stained_glass:15)
B(5,-19,2,srparasites:parasiterubbledense:1)
B(6,-19,2,srparasites:parasiterubbledense:1)
B(7,-19,2,betternether:quartz_stained_glass:15)
B(8,-19,2,betternether:quartz_stained_glass:15)
B(4,-19,3,betternether:quartz_stained_glass:15)
B(5,-19,3,betternether:quartz_stained_glass:15)
B(6,-19,3,betternether:quartz_stained_glass:15)
B(7,-19,3,betternether:quartz_stained_glass:15)
B(8,-19,3,betternether:quartz_stained_glass:15)
B(2,-18,0,betternether:quartz_stained_glass:15)
B(3,-18,0,betternether:quartz_stained_glass:15)
B(4,-18,0,betternether:quartz_stained_glass:15)
B(5,-18,0,betternether:quartz_stained_glass:15)
RB(6,-18,0,srparasites:parasitestain:1,80,quark:crystal:1,30,srparasites:parasiterubbledense:1,100)
B(7,-18,0,betternether:quartz_stained_glass:15)
B(8,-18,0,betternether:quartz_stained_glass:15)
B(9,-18,0,betternether:quartz_stained_glass:15)
B(3,-18,1,betternether:quartz_stained_glass:15)
B(4,-18,1,srparasites:parasiterubbledense:1)
B(5,-18,1,srparasites:parasiterubbledense:1)
B(6,-18,1,betternether:quartz_stained_glass:15)
B(7,-18,1,betternether:quartz_stained_glass:15)
B(8,-18,1,betternether:quartz_stained_glass:15)
B(9,-18,1,betternether:quartz_stained_glass:15)
B(4,-18,2,betternether:quartz_stained_glass:15)
B(5,-18,2,betternether:quartz_stained_glass:15)
B(6,-18,2,betternether:quartz_stained_glass:15)
B(7,-18,2,betternether:quartz_stained_glass:15)
B(7,-18,3,betternether:quartz_stained_glass:15)
B(2,-17,0,betternether:quartz_stained_glass:15)
B(3,-17,0,betternether:quartz_stained_glass:15)
B(4,-17,0,betternether:quartz_stained_glass:15)
B(5,-17,0,betternether:quartz_stained_glass:15)
B(6,-17,0,betternether:quartz_stained_glass:15)
B(7,-17,0,betternether:quartz_stained_glass:15)
B(8,-17,0,betternether:quartz_stained_glass:15)
B(9,-17,0,betternether:quartz_stained_glass:15)
B(4,-17,1,srparasites:parasiterubbledense:1)
B(5,-17,1,betternether:quartz_stained_glass:15)
B(6,-17,1,betternether:quartz_stained_glass:15)
B(7,-17,1,betternether:quartz_stained_glass:15)
B(8,-17,1,betternether:quartz_stained_glass:15)
B(4,-17,2,betternether:quartz_stained_glass:15)
B(6,-17,2,betternether:quartz_stained_glass:15)
B(2,-16,0,betternether:quartz_stained_glass:15)
B(3,-16,0,betternether:quartz_stained_glass:15)
B(4,-16,0,srparasites:parasiterubbledense:1)
B(5,-16,0,srparasites:parasiterubbledense:1)
B(6,-16,0,betternether:quartz_stained_glass:15)
B(7,-16,0,betternether:quartz_stained_glass:15)
B(8,-16,0,betternether:quartz_stained_glass:15)
B(4,-16,1,betternether:quartz_stained_glass:15)
B(6,-16,1,betternether:quartz_stained_glass:15)
B(7,-16,1,betternether:quartz_stained_glass:15)
B(4,-15,0,srparasites:parasiterubbledense:1)
B(5,-15,0,betternether:quartz_stained_glass:15)
B(6,-15,0,betternether:quartz_stained_glass:15)
B(7,-15,0,betternether:quartz_stained_glass:15)
B(4,-14,0,betternether:quartz_stained_glass:15)
B(6,-14,0,betternether:quartz_stained_glass:15)

