
#######################################################################
# +-----------------------------------------------------------------+ #
# |                            BO3 object                           | #
# +-----------------------------------------------------------------+ #
#######################################################################

Author: NLBlackHeavenNL

Description: No description given

Version: 3

SettingsMode: WriteWithoutComments


#######################################################################
# +-----------------------------------------------------------------+ #
# |                          Main settings                          | #
# +-----------------------------------------------------------------+ #
#######################################################################

Tree: true

Frequency: 1

Rarity: 100.0

RotateRandomly: false

SpawnHeight: highestSolidBlock

SpawnHeightOffset: -1

SpawnHeightVariance: 0

##############################
# Height Limits for the BO3. #
##############################

MinHeight: 0

MaxHeight: 255

######################
# Extrusion settings #
######################

ExtrudeMode: None

ExtrudeThroughBlocks: AIR

MaxBranchDepth: 10

ExcludedBiomes: All


#######################################################################
# +-----------------------------------------------------------------+ #
# |                      Source block settings                      | #
# +-----------------------------------------------------------------+ #
#######################################################################

SourceBlocks: AIR,GRASS,DIRT,biomesoplenty:dirt

MaxPercentageOutsideSourceBlock: 0

OutsideSourceBlock: placeAnyway

DoReplaceBlocks: true

IsOTGPlus: false


#######################################################################
# +-----------------------------------------------------------------+ #
# |                              Blocks                             | #
# +-----------------------------------------------------------------+ #
#######################################################################

Block(-5,7,0,dttraverse:leaves0:0)
Block(-4,7,-1,dttraverse:leaves0:0)
Block(-4,7,0,dttraverse:leaves0:1)
Block(-4,7,1,dttraverse:leaves0:0)
Block(-4,7,3,dttraverse:leaves0:0)
Block(-4,8,0,dttraverse:leaves0:0)
Block(-4,11,1,dttraverse:leaves0:0)
Block(-4,17,1,dttraverse:leaves0:0)
Block(-3,7,-2,dttraverse:leaves0:0)
Block(-3,7,-1,dttraverse:leaves0:1)
Block(-3,7,0,dttraverse:firbranch)
Block(-3,7,1,dttraverse:leaves0:1)
Block(-3,7,2,dttraverse:leaves0:0)
Block(-3,7,3,dttraverse:leaves0:1)
Block(-3,7,4,dttraverse:leaves0:0)
Block(-3,8,-1,dttraverse:leaves0:0)
Block(-3,8,0,dttraverse:leaves0:0)
Block(-3,8,1,dttraverse:leaves0:0)
Block(-3,8,3,dttraverse:leaves0:0)
Block(-3,11,-1,dttraverse:leaves0:0)
Block(-3,11,0,dttraverse:leaves0:0)
Block(-3,11,1,dttraverse:leaves0:1)
Block(-3,11,2,dttraverse:leaves0:0)
Block(-3,13,3,dttraverse:leaves0:0)
Block(-3,17,0,dttraverse:leaves0:0)
Block(-3,17,1,dttraverse:leaves0:1)
Block(-3,17,2,dttraverse:leaves0:0)
Block(-3,18,1,dttraverse:leaves0:0)
Block(-3,21,1,dttraverse:leaves0:0)
Block(-2,7,-2,dttraverse:leaves0:0)
Block(-2,7,-1,dttraverse:leaves0:1)
Block(-2,7,0,dttraverse:firbranch:1)
Block(-2,7,1,dttraverse:leaves0:0)
Block(-2,7,3,dttraverse:firbranch)
Block(-2,7,4,dttraverse:leaves0:1)
Block(-2,7,5,dttraverse:leaves0:0)
Block(-2,8,-1,dttraverse:leaves0:0)
Block(-2,8,3,dttraverse:leaves0:0)
Block(-2,8,4,dttraverse:leaves0:0)
Block(-2,11,-2,dttraverse:leaves0:0)
Block(-2,11,-1,dttraverse:leaves0:1)
Block(-2,11,0,dttraverse:leaves0:1)
Block(-2,11,1,dttraverse:firbranch)
Block(-2,11,2,dttraverse:leaves0:1)
Block(-2,11,3,dttraverse:leaves0:0)
Block(-2,12,-1,dttraverse:leaves0:0)
Block(-2,12,0,dttraverse:leaves0:0)
Block(-2,12,1,dttraverse:leaves0:0)
Block(-2,12,2,dttraverse:leaves0:0)
Block(-2,13,-2,dttraverse:leaves0:0)
Block(-2,13,3,dttraverse:leaves0:1)
Block(-2,13,4,dttraverse:leaves0:0)
Block(-2,14,3,dttraverse:leaves0:0)
Block(-2,17,-1,dttraverse:leaves0:0)
Block(-2,17,0,dttraverse:leaves0:1)
Block(-2,17,1,dttraverse:firbranch)
Block(-2,17,2,dttraverse:leaves0:1)
Block(-2,17,3,dttraverse:leaves0:0)
Block(-2,18,0,dttraverse:leaves0:0)
Block(-2,18,1,dttraverse:leaves0:0)
Block(-2,18,2,dttraverse:leaves0:0)
Block(-2,21,0,dttraverse:leaves0:0)
Block(-2,21,1,dttraverse:leaves0:1)
Block(-2,21,2,dttraverse:leaves0:0)
Block(-2,22,1,dttraverse:leaves0:0)
Block(-2,23,1,dttraverse:leaves0:0)
Block(-1,7,-3,dttraverse:leaves0:0)
Block(-1,7,-2,dttraverse:leaves0:1)
Block(-1,7,-1,dttraverse:firbranch)
Block(-1,7,0,dttraverse:firbranch:1)
Block(-1,7,1,dttraverse:firbranch:2)
Block(-1,7,3,dttraverse:firbranch:1)
Block(-1,7,4,dttraverse:firbranch)
Block(-1,7,5,dttraverse:leaves0:1)
Block(-1,7,6,dttraverse:leaves0:0)
Block(-1,8,-2,dttraverse:leaves0:0)
Block(-1,8,-1,dttraverse:leaves0:0)
Block(-1,8,3,dttraverse:leaves0:0)
Block(-1,8,4,dttraverse:leaves0:0)
Block(-1,8,5,dttraverse:leaves0:0)
Block(-1,11,-3,dttraverse:leaves0:0)
Block(-1,11,-2,dttraverse:leaves0:1)
Block(-1,11,-1,dttraverse:firbranch)
Block(-1,11,0,dttraverse:firbranch:1)
Block(-1,11,1,dttraverse:firbranch:1)
Block(-1,11,2,dttraverse:firbranch)
Block(-1,11,3,dttraverse:leaves0:1)
Block(-1,11,4,dttraverse:leaves0:0)
Block(-1,11,5,dttraverse:leaves0:0)
Block(-1,12,-2,dttraverse:leaves0:0)
Block(-1,12,-1,dttraverse:leaves0:0)
Block(-1,12,2,dttraverse:leaves0:0)
Block(-1,13,-3,dttraverse:leaves0:0)
Block(-1,13,-2,dttraverse:leaves0:1)
Block(-1,13,-1,dttraverse:leaves0:0)
Block(-1,13,3,dttraverse:firbranch)
Block(-1,13,4,dttraverse:leaves0:1)
Block(-1,13,5,dttraverse:leaves0:0)
Block(-1,14,-2,dttraverse:leaves0:0)
Block(-1,14,3,dttraverse:leaves0:0)
Block(-1,14,4,dttraverse:leaves0:0)
Block(-1,15,-2,dttraverse:leaves0:0)
Block(-1,17,0,dttraverse:leaves0:0)
Block(-1,17,1,dttraverse:firbranch:1)
Block(-1,17,2,dttraverse:firbranch)
Block(-1,17,3,dttraverse:leaves0:1)
Block(-1,17,4,dttraverse:leaves0:0)
Block(-1,18,2,dttraverse:leaves0:0)
Block(-1,18,3,dttraverse:leaves0:0)
Block(-1,19,-1,dttraverse:leaves0:0)
Block(-1,20,1,dttraverse:leaves0:0)
Block(-1,21,-1,dttraverse:leaves0:0)
Block(-1,21,0,dttraverse:leaves0:1)
Block(-1,21,1,dttraverse:firbranch)
Block(-1,21,2,dttraverse:leaves0:1)
Block(-1,21,3,dttraverse:leaves0:0)
Block(-1,22,0,dttraverse:leaves0:0)
Block(-1,22,1,dttraverse:leaves0:0)
Block(-1,22,2,dttraverse:leaves0:0)
Block(-1,23,0,dttraverse:leaves0:0)
Block(-1,23,1,dttraverse:leaves0:1)
Block(-1,23,2,dttraverse:leaves0:0)
Block(-1,24,1,dttraverse:leaves0:0)
Block(0,7,1,dttraverse:firbranch:2)
Block(0,7,3,dttraverse:firbranch:1)
Block(0,7,5,dttraverse:firbranch)
Block(0,7,6,dttraverse:leaves0:1)
Block(0,7,7,dttraverse:leaves0:0)
Block(0,8,5,dttraverse:leaves0:0)
Block(0,8,6,dttraverse:leaves0:0)
Block(0,11,-1,dttraverse:leaves0:1)
Block(0,11,0,dttraverse:leaves0:0)
Block(0,11,1,dttraverse:firbranch:2)
Block(0,11,2,dttraverse:leaves0:1)
Block(0,11,3,dttraverse:firbranch)
Block(0,11,4,dttraverse:leaves0:1)
Block(0,11,5,dttraverse:leaves0:1)
Block(0,11,6,dttraverse:leaves0:0)
Block(0,12,-2,dttraverse:leaves0:0)
Block(0,12,-1,dttraverse:leaves0:0)
Block(0,12,2,dttraverse:leaves0:0)
Block(0,12,3,dttraverse:leaves0:0)
Block(0,12,4,dttraverse:leaves0:0)
Block(0,12,5,dttraverse:leaves0:0)
Block(0,13,-4,dttraverse:leaves0:0)
Block(0,13,-3,dttraverse:leaves0:1)
Block(0,13,-2,dttraverse:firbranch)
Block(0,13,-1,dttraverse:leaves0:1)
Block(0,13,0,dttraverse:leaves0:0)
Block(0,13,3,dttraverse:firbranch:1)
Block(0,13,4,dttraverse:leaves0:0)
Block(0,13,5,dttraverse:leaves0:1)
Block(0,13,6,dttraverse:leaves0:0)
Block(0,14,-3,dttraverse:leaves0:0)
Block(0,14,-2,dttraverse:leaves0:0)
Block(0,14,-1,dttraverse:leaves0:0)
Block(0,14,3,dttraverse:leaves0:0)
Block(0,14,5,dttraverse:leaves0:0)
Block(0,15,-3,dttraverse:leaves0:0)
Block(0,15,-2,dttraverse:leaves0:1)
Block(0,15,-1,dttraverse:leaves0:0)
Block(0,16,-2,dttraverse:leaves0:0)
Block(0,17,1,dttraverse:firbranch:1)
Block(0,17,3,dttraverse:leaves0:0)
Block(0,19,-2,dttraverse:leaves0:0)
Block(0,19,-1,dttraverse:leaves0:1)
Block(0,19,0,dttraverse:leaves0:1)
Block(0,19,1,dttraverse:firbranch)
Block(0,20,-1,dttraverse:leaves0:0)
Block(0,20,1,dttraverse:leaves0:0)
Block(0,21,-1,dttraverse:leaves0:0)
Block(0,21,0,dttraverse:leaves0:1)
Block(0,21,1,dttraverse:firbranch:1)
Block(0,21,2,dttraverse:leaves0:1)
Block(0,21,3,dttraverse:leaves0:0)
Block(0,22,0,dttraverse:leaves0:0)
Block(0,22,1,dttraverse:leaves0:0)
Block(0,22,2,dttraverse:leaves0:0)
Block(0,23,-1,dttraverse:leaves0:0)
Block(0,23,0,dttraverse:leaves0:1)
Block(0,23,1,dttraverse:firbranch)
Block(0,23,2,dttraverse:leaves0:1)
Block(0,23,3,dttraverse:leaves0:0)
Block(0,24,0,dttraverse:leaves0:0)
Block(0,24,1,dttraverse:leaves0:1)
Block(0,24,2,dttraverse:leaves0:0)
Block(0,25,1,dttraverse:leaves0:0)
Block(1,0,1,dynamictrees:rootydirt:0)
Block(1,1,1,dttraverse:firbranch:7)
Block(1,2,1,dttraverse:firbranch:7)
Block(1,3,1,dttraverse:firbranch:7)
Block(1,4,1,dttraverse:firbranch:7)
Block(1,5,1,dttraverse:firbranch:7)
Block(1,6,1,dttraverse:firbranch:7)
Block(1,7,1,dttraverse:firbranch:7)
Block(1,7,2,dttraverse:firbranch:2)
Block(1,7,3,dttraverse:firbranch:2)
Block(1,7,4,dttraverse:firbranch:1)
Block(1,7,5,dttraverse:firbranch:1)
Block(1,7,6,dttraverse:firbranch)
Block(1,7,7,dttraverse:leaves0:1)
Block(1,7,8,dttraverse:leaves0:0)
Block(1,8,1,dttraverse:firbranch:7)
Block(1,8,6,dttraverse:leaves0:0)
Block(1,8,7,dttraverse:leaves0:0)
Block(1,9,1,dttraverse:firbranch:7)
Block(1,9,5,dttraverse:leaves0:1)
Block(1,9,6,dttraverse:leaves0:0)
Block(1,10,1,dttraverse:firbranch:7)
Block(1,10,5,dttraverse:leaves0:0)
Block(1,11,-1,dttraverse:leaves0:0)
Block(1,11,1,dttraverse:firbranch:7)
Block(1,11,2,dttraverse:firbranch:2)
Block(1,11,3,dttraverse:firbranch:1)
Block(1,11,4,dttraverse:firbranch:1)
Block(1,11,5,dttraverse:firbranch)
Block(1,11,6,dttraverse:leaves0:1)
Block(1,11,7,dttraverse:leaves0:0)
Block(1,12,1,dttraverse:firbranch:7)
Block(1,12,5,dttraverse:leaves0:0)
Block(1,12,6,dttraverse:leaves0:0)
Block(1,13,-5,dttraverse:leaves0:0)
Block(1,13,-4,dttraverse:leaves0:1)
Block(1,13,-3,dttraverse:firbranch)
Block(1,13,-2,dttraverse:firbranch:1)
Block(1,13,-1,dttraverse:firbranch:1)
Block(1,13,0,dttraverse:firbranch:2)
Block(1,13,1,dttraverse:firbranch:7)
Block(1,13,2,dttraverse:firbranch:3)
Block(1,13,3,dttraverse:firbranch:2)
Block(1,13,4,dttraverse:firbranch:1)
Block(1,13,5,dttraverse:firbranch)
Block(1,13,6,dttraverse:leaves0:1)
Block(1,13,7,dttraverse:leaves0:0)
Block(1,14,-4,dttraverse:leaves0:0)
Block(1,14,-3,dttraverse:leaves0:0)
Block(1,14,1,dttraverse:firbranch:7)
Block(1,14,4,dttraverse:leaves0:0)
Block(1,14,5,dttraverse:leaves0:0)
Block(1,14,6,dttraverse:leaves0:0)
Block(1,15,-4,dttraverse:leaves0:0)
Block(1,15,-3,dttraverse:leaves0:1)
Block(1,15,-2,dttraverse:firbranch)
Block(1,15,-1,dttraverse:firbranch:1)
Block(1,15,0,dttraverse:firbranch:1)
Block(1,15,1,dttraverse:firbranch:7)
Block(1,16,-3,dttraverse:leaves0:0)
Block(1,16,-2,dttraverse:leaves0:0)
Block(1,16,1,dttraverse:firbranch:6)
Block(1,17,1,dttraverse:firbranch:6)
Block(1,17,2,dttraverse:firbranch:1)
Block(1,17,3,dttraverse:firbranch:1)
Block(1,17,4,dttraverse:leaves0:0)
Block(1,18,1,dttraverse:firbranch:4)
Block(1,19,-3,dttraverse:leaves0:0)
Block(1,19,-2,dttraverse:leaves0:1)
Block(1,19,-1,dttraverse:firbranch)
Block(1,19,0,dttraverse:firbranch:1)
Block(1,19,1,dttraverse:firbranch:4)
Block(1,19,3,dttraverse:leaves0:0)
Block(1,20,-2,dttraverse:leaves0:0)
Block(1,20,-1,dttraverse:leaves0:0)
Block(1,20,1,dttraverse:firbranch:3)
Block(1,21,-2,dttraverse:leaves0:0)
Block(1,21,-1,dttraverse:leaves0:1)
Block(1,21,0,dttraverse:firbranch)
Block(1,21,1,dttraverse:firbranch:2)
Block(1,21,2,dttraverse:firbranch)
Block(1,21,3,dttraverse:leaves0:1)
Block(1,21,4,dttraverse:leaves0:0)
Block(1,22,-1,dttraverse:leaves0:0)
Block(1,22,0,dttraverse:leaves0:0)
Block(1,22,1,dttraverse:firbranch:1)
Block(1,22,2,dttraverse:leaves0:0)
Block(1,22,3,dttraverse:leaves0:0)
Block(1,23,0,dttraverse:leaves0:0)
Block(1,23,1,dttraverse:firbranch:1)
Block(1,23,2,dttraverse:leaves0:0)
Block(1,24,-1,dttraverse:leaves0:0)
Block(1,24,0,dttraverse:leaves0:1)
Block(1,24,1,dttraverse:firbranch)
Block(1,24,2,dttraverse:leaves0:1)
Block(1,24,3,dttraverse:leaves0:0)
Block(1,25,0,dttraverse:leaves0:0)
Block(1,25,1,dttraverse:leaves0)
Block(1,25,2,dttraverse:leaves0:0)
Block(1,26,1,dttraverse:leaves0:2)
Block(1,27,1,dttraverse:leaves0:0)
Block(2,7,1,dttraverse:leaves0:0)
Block(2,7,2,dttraverse:leaves0:1)
Block(2,7,3,dttraverse:firbranch)
Block(2,7,5,dttraverse:firbranch)
Block(2,7,6,dttraverse:leaves0:1)
Block(2,7,7,dttraverse:leaves0:0)
Block(2,8,2,dttraverse:leaves0:0)
Block(2,8,3,dttraverse:leaves0:0)
Block(2,8,5,dttraverse:leaves0:0)
Block(2,8,6,dttraverse:leaves0:0)
Block(2,9,0,dttraverse:leaves0:1)
Block(2,9,1,dttraverse:firbranch:3)
Block(2,9,2,dttraverse:firbranch:2)
Block(2,9,3,dttraverse:firbranch:1)
Block(2,9,4,dttraverse:firbranch:1)
Block(2,9,5,dttraverse:firbranch)
Block(2,9,6,dttraverse:leaves0:1)
Block(2,9,7,dttraverse:leaves0:0)
Block(2,10,0,dttraverse:leaves0:0)
Block(2,10,4,dttraverse:leaves0:0)
Block(2,10,5,dttraverse:leaves0:0)
Block(2,10,6,dttraverse:leaves0:0)
Block(2,11,2,dttraverse:leaves0:0)
Block(2,11,3,dttraverse:leaves0:1)
Block(2,11,4,dttraverse:firbranch)
Block(2,11,5,dttraverse:leaves0:1)
Block(2,11,6,dttraverse:leaves0:0)
Block(2,12,3,dttraverse:leaves0:0)
Block(2,12,4,dttraverse:leaves0:0)
Block(2,12,5,dttraverse:leaves0:0)
Block(2,13,-4,dttraverse:leaves0:0)
Block(2,13,-3,dttraverse:leaves0:1)
Block(2,13,-2,dttraverse:firbranch)
Block(2,13,-1,dttraverse:leaves0:1)
Block(2,13,0,dttraverse:leaves0:0)
Block(2,13,2,dttraverse:leaves0:0)
Block(2,13,3,dttraverse:firbranch:1)
Block(2,13,4,dttraverse:leaves0:0)
Block(2,13,5,dttraverse:leaves0:1)
Block(2,13,6,dttraverse:leaves0:0)
Block(2,14,-3,dttraverse:leaves0:0)
Block(2,14,-2,dttraverse:leaves0:0)
Block(2,14,-1,dttraverse:leaves0:0)
Block(2,14,5,dttraverse:leaves0:0)
Block(2,15,-3,dttraverse:leaves0:0)
Block(2,15,-2,dttraverse:leaves0:1)
Block(2,15,-1,dttraverse:firbranch)
Block(2,15,0,dttraverse:leaves0:1)
Block(2,15,1,dttraverse:firbranch:1)
Block(2,16,-2,dttraverse:leaves0:0)
Block(2,16,-1,dttraverse:leaves0:0)
Block(2,16,0,dttraverse:leaves0:0)
Block(2,17,3,dttraverse:firbranch)
Block(2,17,4,dttraverse:leaves0:1)
Block(2,17,5,dttraverse:leaves0:0)
Block(2,18,2,dttraverse:leaves0:0)
Block(2,18,3,dttraverse:leaves0:0)
Block(2,18,4,dttraverse:leaves0:0)
Block(2,19,-2,dttraverse:leaves0:0)
Block(2,19,-1,dttraverse:leaves0:1)
Block(2,19,0,dttraverse:leaves0:0)
Block(2,19,1,dttraverse:firbranch:1)
Block(2,19,2,dttraverse:firbranch)
Block(2,19,3,dttraverse:leaves0:1)
Block(2,19,4,dttraverse:leaves0:0)
Block(2,20,-1,dttraverse:leaves0:0)
Block(2,20,2,dttraverse:leaves0:0)
Block(2,20,3,dttraverse:leaves0:0)
Block(2,21,-1,dttraverse:leaves0:0)
Block(2,21,0,dttraverse:leaves0:1)
Block(2,21,1,dttraverse:firbranch)
Block(2,21,2,dttraverse:leaves0:1)
Block(2,21,3,dttraverse:leaves0:0)
Block(2,22,0,dttraverse:leaves0:0)
Block(2,22,1,dttraverse:leaves0:0)
Block(2,22,2,dttraverse:leaves0:0)
Block(2,24,0,dttraverse:leaves0:0)
Block(2,24,1,dttraverse:leaves0:1)
Block(2,24,2,dttraverse:leaves0:0)
Block(2,25,1,dttraverse:leaves0:0)
Block(3,7,2,dttraverse:leaves0:0)
Block(3,7,3,dttraverse:leaves0:1)
Block(3,7,4,dttraverse:leaves0:0)
Block(3,7,5,dttraverse:leaves0:1)
Block(3,7,6,dttraverse:leaves0:0)
Block(3,8,3,dttraverse:leaves0:0)
Block(3,8,5,dttraverse:leaves0:0)
Block(3,9,-2,dttraverse:leaves0:0)
Block(3,9,-1,dttraverse:leaves0:1)
Block(3,9,0,dttraverse:firbranch)
Block(3,9,1,dttraverse:firbranch:2)
Block(3,9,3,dttraverse:firbranch)
Block(3,9,4,dttraverse:leaves0:1)
Block(3,9,5,dttraverse:leaves0:1)
Block(3,9,6,dttraverse:leaves0:0)
Block(3,10,-1,dttraverse:leaves0:0)
Block(3,10,0,dttraverse:leaves0:0)
Block(3,10,3,dttraverse:leaves0:0)
Block(3,10,4,dttraverse:leaves0:0)
Block(3,10,5,dttraverse:leaves0:0)
Block(3,11,3,dttraverse:leaves0:0)
Block(3,11,4,dttraverse:leaves0:1)
Block(3,11,5,dttraverse:leaves0:0)
Block(3,12,3,dttraverse:leaves0:0)
Block(3,12,4,dttraverse:leaves0:0)
Block(3,13,-3,dttraverse:leaves0:0)
Block(3,13,-2,dttraverse:leaves0:1)
Block(3,13,2,dttraverse:leaves0:1)
Block(3,13,3,dttraverse:firbranch)
Block(3,13,4,dttraverse:leaves0:1)
Block(3,13,5,dttraverse:leaves0:0)
Block(3,14,-2,dttraverse:leaves0:0)
Block(3,14,2,dttraverse:leaves0:0)
Block(3,14,3,dttraverse:leaves0:0)
Block(3,14,4,dttraverse:leaves0:0)
Block(3,15,-2,dttraverse:leaves0:0)
Block(3,15,-1,dttraverse:leaves0:1)
Block(3,15,0,dttraverse:leaves0:0)
Block(3,15,1,dttraverse:firbranch:1)
Block(3,15,2,dttraverse:leaves0:0)
Block(3,16,-1,dttraverse:leaves0:0)
Block(3,17,3,dttraverse:leaves0:1)
Block(3,17,4,dttraverse:leaves0:0)
Block(3,18,3,dttraverse:leaves0:0)
Block(3,19,-1,dttraverse:leaves0:0)
Block(3,19,0,dttraverse:leaves0:1)
Block(3,19,1,dttraverse:firbranch)
Block(3,19,2,dttraverse:leaves0:1)
Block(3,19,3,dttraverse:leaves0:0)
Block(3,20,0,dttraverse:leaves0:0)
Block(3,20,1,dttraverse:leaves0:0)
Block(3,20,2,dttraverse:leaves0:0)
Block(3,21,0,dttraverse:leaves0:0)
Block(3,21,1,dttraverse:leaves0:1)
Block(3,21,2,dttraverse:leaves0:0)
Block(3,22,1,dttraverse:leaves0:0)
Block(3,24,1,dttraverse:leaves0:0)
Block(4,7,3,dttraverse:leaves0:0)
Block(4,7,5,dttraverse:leaves0:0)
Block(4,9,-1,dttraverse:leaves0:0)
Block(4,9,0,dttraverse:leaves0:1)
Block(4,9,1,dttraverse:firbranch:1)
Block(4,9,3,dttraverse:leaves0:1)
Block(4,9,4,dttraverse:leaves0:0)
Block(4,9,5,dttraverse:leaves0:0)
Block(4,10,0,dttraverse:leaves0:0)
Block(4,10,3,dttraverse:leaves0:0)
Block(4,11,4,dttraverse:leaves0:0)
Block(4,13,-2,dttraverse:leaves0:0)
Block(4,13,3,dttraverse:leaves0:1)
Block(4,13,4,dttraverse:leaves0:0)
Block(4,14,3,dttraverse:leaves0:0)
Block(4,15,-1,dttraverse:leaves0:0)
Block(4,15,0,dttraverse:leaves0:1)
Block(4,15,1,dttraverse:firbranch)
Block(4,15,2,dttraverse:leaves0:1)
Block(4,15,3,dttraverse:leaves0:0)
Block(4,16,0,dttraverse:leaves0:0)
Block(4,16,1,dttraverse:leaves0:0)
Block(4,16,2,dttraverse:leaves0:0)
Block(4,17,3,dttraverse:leaves0:0)
Block(4,19,0,dttraverse:leaves0:0)
Block(4,19,1,dttraverse:leaves0:1)
Block(4,19,2,dttraverse:leaves0:0)
Block(4,20,1,dttraverse:leaves0:0)
Block(4,21,1,dttraverse:leaves0:0)
Block(5,9,-2,dttraverse:leaves0:0)
Block(5,9,-1,dttraverse:leaves0:1)
Block(5,9,0,dttraverse:firbranch)
Block(5,9,1,dttraverse:firbranch:1)
Block(5,9,2,dttraverse:firbranch)
Block(5,9,3,dttraverse:leaves0:1)
Block(5,9,4,dttraverse:leaves0:0)
Block(5,10,-1,dttraverse:leaves0:0)
Block(5,10,0,dttraverse:leaves0:0)
Block(5,10,2,dttraverse:leaves0:0)
Block(5,10,3,dttraverse:leaves0:0)
Block(5,13,3,dttraverse:leaves0:0)
Block(5,15,0,dttraverse:leaves0:0)
Block(5,15,1,dttraverse:leaves0:1)
Block(5,15,2,dttraverse:leaves0:0)
Block(5,16,1,dttraverse:leaves0:0)
Block(5,19,1,dttraverse:leaves0:0)
Block(6,9,-1,dttraverse:leaves0:0)
Block(6,9,0,dttraverse:leaves0:1)
Block(6,9,1,dttraverse:firbranch)
Block(6,9,2,dttraverse:leaves0:1)
Block(6,9,3,dttraverse:leaves0:0)
Block(6,10,0,dttraverse:leaves0:0)
Block(6,10,1,dttraverse:leaves0:0)
Block(6,10,2,dttraverse:leaves0:0)
Block(6,15,1,dttraverse:leaves0:0)
Block(7,9,0,dttraverse:leaves0:0)
Block(7,9,1,dttraverse:leaves0:1)
Block(7,9,2,dttraverse:leaves0:0)
Block(7,10,1,dttraverse:leaves0:0)
Block(8,9,1,dttraverse:leaves0:0)

#######################################################################
# +-----------------------------------------------------------------+ #
# |                            BO3 checks                           | #
# +-----------------------------------------------------------------+ #
#######################################################################

BlockCheck(1,-1,1,GRASS,DIRT,biomesoplenty:grass,biomesoplenty:dirt)

#######################################################################
# +-----------------------------------------------------------------+ #
# |                             Branches                            | #
# +-----------------------------------------------------------------+ #
#######################################################################


#######################################################################
# +-----------------------------------------------------------------+ #
# |                             Entities                            | #
# +-----------------------------------------------------------------+ #
#######################################################################


#######################################################################
# +-----------------------------------------------------------------+ #
# |                            Particles                            | #
# +-----------------------------------------------------------------+ #
#######################################################################


#######################################################################
# +-----------------------------------------------------------------+ #
# |                             Spawners                            | #
# +-----------------------------------------------------------------+ #
#######################################################################


#######################################################################
# +-----------------------------------------------------------------+ #
# |                             ModData                             | #
# +-----------------------------------------------------------------+ #
#######################################################################

