
#######################################################################
# +-----------------------------------------------------------------+ #
# |                            BO4 object                           | #
# +-----------------------------------------------------------------+ #
#######################################################################

Author: BO3 BulkEdit (by LanToaster)

Description: This Object was Created with BO3_BulkEdit

SettingsMode: WriteDisable


#######################################################################
# +-----------------------------------------------------------------+ #
# |                          Main settings                          | #
# +-----------------------------------------------------------------+ #
#######################################################################

Frequency: 100

SpawnHeight: highestBlock

UseCenterForHighestBlock: true

##############################
# Height Limits for the BO4. #
##############################

MinHeight: 0

MaxHeight: 255

InheritBO3: 

InheritBO3Rotation: NORTH

OverrideChildSettings: true

OverrideParentHeight: true

CanOverride: true

BranchFrequency: 0

BranchFrequencyGroup: 

MustBeBelowOther: false

MustBeInside: 

CannotBeInside: 

ReplacesBO3: 

MustBeInsideWorldBorders: false

CanSpawnOnWater: false

SpawnOnWaterOnly: false

SpawnUnderWater: false

SpawnAtWaterLevel: false

HeightOffset: 1

RemoveAir: true

ReplaceAbove: 

ReplaceBelow: cobblestone

ReplaceWithBiomeBlocks: true

ReplaceWithSurfaceBlock: GRASS

ReplaceWithGroundBlock: DIRT

ReplaceWithStoneBlock: STONE

SmoothRadius: 0

SmoothHeightOffset: 0

SmoothStartTop: false

SmoothStartWood: false

SmoothingSurfaceBlock: 

SmoothingGroundBlock: 

BO3Group: 

IsSpawnPoint: false

DoReplaceBlocks: true


#######################################################################
# +-----------------------------------------------------------------+ #
# |                              Blocks                             | #
# +-----------------------------------------------------------------+ #
#######################################################################

Block(-6,-1,-7,GRASS:0)
Block(1,-1,-7,GRASS:0)
Block(2,-1,-7,GRASS:0)
Block(-7,-1,-6,LOG_2:0)
Block(-6,-1,-6,GRASS:0)
Block(-5,-1,-6,GRASS:0)
Block(-4,-1,-6,GRASS:0)
Block(-3,-1,-6,GRASS:0)
Block(-2,-1,-6,GRASS:0)
Block(-1,-1,-6,LOG_2:0)
Block(0,-1,-6,GRASS:0)
Block(1,-1,-6,GRASS:0)
Block(2,-1,-6,GRASS:0)
Block(3,-1,-6,GRASS:0)
Block(4,-1,-6,LOG_2:0)
Block(-7,-1,-5,GRASS:0)
Block(-6,-1,-5,DIRT:0)
Block(-5,-1,-5,GRASS:0)
Block(-4,-1,-5,DIRT:0)
Block(-3,-1,-5,GRASS_PATH:0)
Block(-2,-1,-5,GRASS_PATH:0)
Block(-1,-1,-5,GRASS:0)
Block(0,-1,-5,DIRT:0)
Block(1,-1,-5,GRASS_PATH:0)
Block(2,-1,-5,DIRT:0)
Block(3,-1,-5,GRASS:0)
Block(4,-1,-5,GRASS:0)
Block(-7,-1,-4,GRASS:0)
Block(-6,-1,-4,GRASS:0)
Block(-5,-1,-4,GRASS:0)
Block(-4,-1,-4,GRASS_PATH:0)
Block(-3,-1,-4,GRASS_PATH:0)
Block(-2,-1,-4,GRASS_PATH:0)
Block(-1,-1,-4,GRASS_PATH:0)
Block(0,-1,-4,GRASS_PATH:0)
Block(1,-1,-4,GRASS_PATH:0)
Block(2,-1,-4,GRASS_PATH:0)
Block(3,-1,-4,GRASS:0)
Block(4,-1,-4,GRASS:0)
Block(-7,-1,-3,GRASS:0)
Block(-6,-1,-3,DIRT:0)
Block(-5,-1,-3,GRASS_PATH:0)
Block(-4,-1,-3,GRASS_PATH:0)
Block(-3,-1,-3,GRASS_PATH:0)
Block(-2,-1,-3,GRASS_PATH:0)
Block(-1,-1,-3,GRASS_PATH:0)
Block(0,-1,-3,GRASS_PATH:0)
Block(1,-1,-3,DIRT:0)
Block(2,-1,-3,GRASS_PATH:0)
Block(3,-1,-3,CAULDRON:3)
Block(4,-1,-3,GRASS:0)
Block(-7,-1,-2,GRASS:0)
Block(-6,-1,-2,GRASS:0)
Block(-5,-1,-2,GRASS:0)
Block(-4,-1,-2,GRASS:0)
Block(-3,-1,-2,DIRT:0)
Block(-2,-1,-2,GRASS:0)
Block(-1,-1,-2,GRASS_PATH:0)
Block(0,-1,-2,GRASS:0)
Block(1,-1,-2,GRASS:0)
Block(2,-1,-2,DIRT:0)
Block(3,-1,-2,CAULDRON:3)
Block(4,-1,-2,GRASS:0)
Block(5,-1,-2,GRASS:0)
Block(-7,-1,-1,GRASS:0)
Block(-6,-1,-1,DIRT:0)
Block(-5,-1,-1,GRASS_PATH:0)
Block(-4,-1,-1,GRASS_PATH:0)
Block(-3,-1,-1,LOG_2:0)
Block(-2,-1,-1,GRASS:0)
Block(-1,-1,-1,GRASS_PATH:0)
Block(0,-1,-1,GRASS_PATH:0)
Block(1,-1,-1,LOG_2:0)
Block(2,-1,-1,GRASS:0)
Block(3,-1,-1,GRASS:0)
Block(4,-1,-1,LOG_2:0)
Block(5,-1,-1,GRASS:0)
Block(-7,-1,0,LOG_2:0)
Block(-6,-1,0,GRASS_PATH:0)
Block(-5,-1,0,GRASS_PATH:0)
Block(-4,-1,0,GRASS_PATH:0)
Block(-3,-1,0,GRASS_PATH:0)
Block(-2,-1,0,GRASS:0)
Block(-1,-1,0,GRASS_PATH:0)
Block(0,-1,0,GRASS_PATH:0)
Block(1,-1,0,GRASS:0)
Block(2,-1,0,GRASS:0)
Block(5,-1,0,GRASS:0)
Block(-7,-1,1,GRASS:0)
Block(-6,-1,1,GRASS_PATH:0)
Block(-5,-1,1,GRASS_PATH:0)
Block(-4,-1,1,GRASS_PATH:0)
Block(-3,-1,1,GRASS_PATH:0)
Block(-2,-1,1,GRASS_PATH:0)
Block(-1,-1,1,GRASS_PATH:0)
Block(0,-1,1,GRASS_PATH:0)
Block(1,-1,1,GRASS:0)
Block(-8,-1,2,GRASS:0)
Block(-7,-1,2,GRASS:0)
Block(-6,-1,2,DIRT:0)
Block(-5,-1,2,GRASS_PATH:0)
Block(-4,-1,2,GRASS_PATH:0)
Block(-3,-1,2,GRASS:0)
Block(-2,-1,2,GRASS_PATH:0)
Block(-1,-1,2,GRASS_PATH:0)
Block(0,-1,2,GRASS:0)
Block(1,-1,2,GRASS:0)
Block(-8,-1,3,GRASS:0)
Block(-7,-1,3,GRASS:0)
Block(-6,-1,3,GRASS_PATH:0)
Block(-5,-1,3,GRASS_PATH:0)
Block(-4,-1,3,GRASS:0)
Block(-3,-1,3,LOG_2:0)
Block(-2,-1,3,GRASS:0)
Block(-1,-1,3,GRASS:0)
Block(0,-1,3,GRASS:0)
Block(1,-1,3,LOG_2:0)
Block(2,-1,3,GRASS:0)
Block(-8,-1,4,GRASS:0)
Block(-7,-1,4,GRASS:0)
Block(-6,-1,4,GRASS:0)
Block(-5,-1,4,GRASS_PATH:0)
Block(-4,-1,4,DIRT:0)
Block(-3,-1,4,GRASS:0)
Block(-2,-1,4,GRASS:0)
Block(-1,-1,4,GRASS:0)
Block(0,-1,4,GRASS:0)
Block(1,-1,4,GRASS:0)
Block(2,-1,4,GRASS:0)
Block(-8,-1,5,GRASS:0)
Block(-7,-1,5,GRASS:0)
Block(-6,-1,5,DIRT:0)
Block(-5,-1,5,GRASS:0)
Block(-4,-1,5,GRASS:0)
Block(-3,-1,5,GRASS:0)
Block(-2,-1,5,GRASS:0)
Block(-1,-1,5,GRASS:0)
Block(0,-1,5,GRASS:0)
Block(-7,-1,6,LOG_2:0)
Block(-6,-1,6,GRASS:0)
Block(-5,-1,6,GRASS:0)
Block(-4,-1,6,GRASS:0)
Block(-3,-1,6,LOG_2:0)
Block(-5,-1,7,GRASS:0)
Block(-4,-1,7,GRASS:0)
Block(-7,0,-6,ACACIA_FENCE:0)
Block(-6,0,-6,ACACIA_FENCE:0)
Block(-5,0,-6,ACACIA_FENCE:0)
Block(-4,0,-6,ACACIA_FENCE:0)
Block(-3,0,-6,ACACIA_FENCE:0)
Block(-2,0,-6,ACACIA_FENCE:0)
Block(-1,0,-6,ACACIA_FENCE:0)
Block(0,0,-6,ACACIA_FENCE:0)
Block(1,0,-6,ACACIA_FENCE:0)
Block(2,0,-6,ACACIA_FENCE:0)
Block(3,0,-6,ACACIA_FENCE:0)
Block(4,0,-6,ACACIA_FENCE:0)
Block(-7,0,-5,ACACIA_FENCE:0)
Block(-6,0,-5,AIR)
Block(-4,0,-5,AIR)
Block(0,0,-5,AIR)
Block(2,0,-5,AIR)
Block(4,0,-5,ACACIA_FENCE:0)
Block(-7,0,-4,ACACIA_FENCE:0)
Block(4,0,-4,ACACIA_FENCE:0)
Block(-7,0,-3,ACACIA_FENCE:0)
Block(-6,0,-3,AIR)
Block(1,0,-3,AIR)
Block(4,0,-3,ACACIA_FENCE:0)
Block(-7,0,-2,ACACIA_FENCE:0)
Block(-3,0,-2,AIR)
Block(2,0,-2,AIR)
Block(4,0,-2,ACACIA_FENCE:0)
Block(-7,0,-1,ACACIA_FENCE:0)
Block(-6,0,-1,AIR)
Block(-3,0,-1,LOG_2:0)
Block(1,0,-1,LOG_2:0)
Block(2,0,-1,ACACIA_FENCE:0)
Block(3,0,-1,ACACIA_FENCE:0)
Block(4,0,-1,ACACIA_FENCE:0)
Block(-7,0,0,ACACIA_FENCE:0)
Block(1,0,0,ACACIA_FENCE:0)
Block(-7,0,1,ACACIA_FENCE:0)
Block(1,0,1,ACACIA_FENCE:0)
Block(-7,0,2,ACACIA_FENCE:0)
Block(-6,0,2,AIR)
Block(1,0,2,ACACIA_FENCE:0)
Block(-7,0,3,ACACIA_FENCE:0)
Block(-3,0,3,LOG_2:0)
Block(-2,0,3,ACACIA_FENCE:0)
Block(-1,0,3,ACACIA_FENCE:0)
Block(0,0,3,ACACIA_FENCE:0)
Block(1,0,3,LOG_2:0)
Block(-7,0,4,ACACIA_FENCE:0)
Block(-4,0,4,AIR)
Block(-3,0,4,ACACIA_FENCE:0)
Block(-7,0,5,ACACIA_FENCE:0)
Block(-6,0,5,AIR)
Block(-3,0,5,ACACIA_FENCE:0)
Block(-7,0,6,ACACIA_FENCE:0)
Block(-6,0,6,ACACIA_FENCE:0)
Block(-5,0,6,SPRUCE_FENCE_GATE:0)
Block(-4,0,6,ACACIA_FENCE:0)
Block(-3,0,6,ACACIA_FENCE:0)
Block(-1,1,-2,LADDER:2)
Block(-3,1,-1,LOG_2:0)
Block(1,1,-1,LOG_2:0)
Block(-3,1,3,LOG_2:0)
Block(1,1,3,LOG_2:0)
Block(-1,2,-2,LADDER:2)
Block(-3,2,-1,LOG_2:0)
Block(-2,2,-1,LOG_2:4)
Block(-1,2,-1,LOG_2:4)
Block(0,2,-1,LOG_2:4)
Block(1,2,-1,LOG_2:0)
Block(-3,2,0,LOG_2:8)
Block(-2,2,0,WOOD_STEP:12)
Block(-1,2,0,WOOD_STEP:12)
Block(0,2,0,WOOD_STEP:12)
Block(1,2,0,LOG_2:8)
Block(-3,2,1,LOG_2:8)
Block(-2,2,1,WOOD_STEP:12)
Block(-1,2,1,WOOD_STEP:12)
Block(0,2,1,WOOD_STEP:12)
Block(1,2,1,LOG_2:8)
Block(-3,2,2,LOG_2:8)
Block(-2,2,2,WOOD_STEP:12)
Block(-1,2,2,WOOD_STEP:12)
Block(0,2,2,WOOD_STEP:12)
Block(1,2,2,LOG_2:8)
Block(-3,2,3,LOG_2:0)
Block(-2,2,3,LOG_2:4)
Block(-1,2,3,LOG_2:4)
Block(0,2,3,LOG_2:4)
Block(1,2,3,LOG_2:0)
Block(-3,3,-1,LOG_2:0)
Block(-2,3,-1,ACACIA_FENCE:0)
Block(0,3,-1,ACACIA_FENCE:0)
Block(1,3,-1,LOG_2:0)
Block(-3,3,0,ACACIA_FENCE:0)
Block(-2,3,0,HAY_BLOCK:0)
Block(1,3,0,ACACIA_FENCE:0)
Block(-3,3,1,ACACIA_FENCE:0)
Block(-2,3,1,HAY_BLOCK:0)
Block(0,3,1,HAY_BLOCK:8)
Block(1,3,1,ACACIA_FENCE:0)
Block(-3,3,2,ACACIA_FENCE:0)
Block(-2,3,2,HAY_BLOCK:0)
Block(-1,3,2,HAY_BLOCK:4)
Block(0,3,2,HAY_BLOCK:0)
Block(1,3,2,ACACIA_FENCE:0)
Block(-3,3,3,LOG_2:0)
Block(-2,3,3,ACACIA_FENCE:0)
Block(-1,3,3,ACACIA_FENCE:0)
Block(0,3,3,ACACIA_FENCE:0)
Block(1,3,3,LOG_2:0)
Block(-4,4,-2,WOOD_STEP:12)
Block(-3,4,-2,WOOD_STEP:12)
Block(1,4,-2,WOOD_STEP:12)
Block(2,4,-2,WOOD_STEP:12)
Block(-4,4,-1,WOOD_STEP:12)
Block(-3,4,-1,LOG_2:0)
Block(-2,4,-1,ACACIA_FENCE:0)
Block(0,4,-1,ACACIA_FENCE:0)
Block(1,4,-1,LOG_2:0)
Block(2,4,-1,WOOD_STEP:12)
Block(-3,4,0,ACACIA_FENCE:0)
Block(-2,4,0,HAY_BLOCK:0)
Block(1,4,0,ACACIA_FENCE:0)
Block(2,4,0,WOOD_STEP:12)
Block(-3,4,1,ACACIA_FENCE:0)
Block(1,4,1,ACACIA_FENCE:0)
Block(2,4,1,WOOD_STEP:12)
Block(-3,4,2,ACACIA_FENCE:0)
Block(0,4,2,HAY_BLOCK:0)
Block(1,4,2,ACACIA_FENCE:0)
Block(-4,4,3,WOOD_STEP:12)
Block(-3,4,3,LOG_2:0)
Block(-2,4,3,ACACIA_FENCE:0)
Block(-1,4,3,ACACIA_FENCE:0)
Block(0,4,3,ACACIA_FENCE:0)
Block(1,4,3,LOG_2:0)
Block(-4,4,4,WOOD_STEP:12)
Block(-3,4,4,WOOD_STEP:12)
Block(1,4,4,WOOD_STEP:12)
Block(2,4,4,WOOD_STEP:12)
Block(-3,5,-2,WOOD_STEP:4)
Block(-2,5,-2,WOOD_DOUBLE_STEP:3)
Block(-1,5,-2,WOOD_STEP:12)
Block(0,5,-2,WOOD_DOUBLE_STEP:3)
Block(1,5,-2,WOOD_STEP:4)
Block(-4,5,-1,WOOD_STEP:0)
Block(-3,5,-1,WOOD_STEP:0)
Block(-2,5,-1,WOOD_DOUBLE_STEP:3)
Block(-1,5,-1,WOOD_DOUBLE_STEP:3)
Block(0,5,-1,WOOD_DOUBLE_STEP:3)
Block(1,5,-1,WOOD_STEP:0)
Block(-4,5,0,WOOD_STEP:4)
Block(-3,5,0,WOOD_STEP:4)
Block(-2,5,0,WOOD_DOUBLE_STEP:3)
Block(-1,5,0,WOOD_STEP:12)
Block(0,5,0,WOOD_DOUBLE_STEP:3)
Block(1,5,0,WOOD_STEP:0)
Block(2,5,0,WOOD_STEP:4)
Block(-4,5,1,WOOD_STEP:4)
Block(-3,5,1,WOOD_DOUBLE_STEP:3)
Block(-2,5,1,WOOD_DOUBLE_STEP:3)
Block(-1,5,1,WOOD_STEP:12)
Block(0,5,1,WOOD_STEP:8)
Block(1,5,1,WOOD_STEP:4)
Block(-4,5,2,WOOD_STEP:4)
Block(-3,5,2,WOOD_DOUBLE_STEP:3)
Block(-2,5,2,WOOD_DOUBLE_STEP:3)
Block(-1,5,2,WOOD_STEP:12)
Block(0,5,2,WOOD_DOUBLE_STEP:3)
Block(1,5,2,WOOD_DOUBLE_STEP:3)
Block(2,5,2,WOOD_STEP:4)
Block(-4,5,3,WOOD_STEP:0)
Block(-3,5,3,WOOD_STEP:4)
Block(-2,5,3,WOOD_DOUBLE_STEP:3)
Block(-1,5,3,WOOD_DOUBLE_STEP:3)
Block(0,5,3,WOOD_DOUBLE_STEP:3)
Block(1,5,3,WOOD_STEP:4)
Block(2,5,3,WOOD_STEP:4)
Block(-3,5,4,WOOD_STEP:4)
Block(-2,5,4,WOOD_DOUBLE_STEP:3)
Block(-1,5,4,WOOD_STEP:12)
Block(0,5,4,WOOD_DOUBLE_STEP:3)
Block(1,5,4,WOOD_STEP:4)
Block(-1,6,-2,WOOD_STEP:4)
Block(-1,6,-1,WOOD_STEP:4)
Block(0,6,-1,WOOD_STEP:4)
Block(-2,6,0,WOOD_STEP:0)
Block(-1,6,0,WOOD_STEP:4)
Block(-2,6,1,WOOD_STEP:4)
Block(-1,6,1,WOOD_STEP:4)
Block(-2,6,2,WOOD_STEP:0)
Block(-1,6,2,WOOD_STEP:4)
Block(-2,6,3,WOOD_STEP:0)
Block(-1,6,3,WOOD_STEP:4)
Block(-1,6,4,WOOD_STEP:4)

#######################################################################
# +-----------------------------------------------------------------+ #
# |                             Branches                            | #
# +-----------------------------------------------------------------+ #
#######################################################################


#######################################################################
# +-----------------------------------------------------------------+ #
# |                             Entities                            | #
# +-----------------------------------------------------------------+ #
#######################################################################

Entity(-6,0,-5,minecraft:pig,1,../../NBT/entities/pig.txt)
Entity(-6,0,-3,minecraft:pig,1,../../NBT/entities/pig.txt)
Entity(1,0,-3,minecraft:villager,1,../../NBT/entities/tribalherder.txt)
Entity(2,0,-2,minecraft:pig,1,../../NBT/entities/pig.txt)
Entity(-6,0,-1,minecraft:pig,1,../../NBT/entities/pig.txt)

#######################################################################
# +-----------------------------------------------------------------+ #
# |                            Particles                            | #
# +-----------------------------------------------------------------+ #
#######################################################################


#######################################################################
# +-----------------------------------------------------------------+ #
# |                             Spawners                            | #
# +-----------------------------------------------------------------+ #
#######################################################################


#######################################################################
# +-----------------------------------------------------------------+ #
# |                             ModData                             | #
# +-----------------------------------------------------------------+ #
#######################################################################

