
#######################################################################
# +-----------------------------------------------------------------+ #
# |                            BO4 object                           | #
# +-----------------------------------------------------------------+ #
#######################################################################

Author: BO3 BulkEdit (by LanToaster)

Description: This Object was Created with BO3_BulkEdit

SettingsMode: WriteDisable


#######################################################################
# +-----------------------------------------------------------------+ #
# |                          Main settings                          | #
# +-----------------------------------------------------------------+ #
#######################################################################

Frequency: 100

SpawnHeight: highestBlock

UseCenterForHighestBlock: true

##############################
# Height Limits for the BO4. #
##############################

MinHeight: 0

MaxHeight: 255

InheritBO3: 

InheritBO3Rotation: NORTH

OverrideChildSettings: true

OverrideParentHeight: true

CanOverride: true

BranchFrequency: 0

BranchFrequencyGroup: 

MustBeBelowOther: false

MustBeInside: 

CannotBeInside: 

ReplacesBO3: 

MustBeInsideWorldBorders: false

CanSpawnOnWater: false

SpawnOnWaterOnly: false

SpawnUnderWater: false

SpawnAtWaterLevel: false

HeightOffset: 1

RemoveAir: true

ReplaceAbove: 

ReplaceBelow: cobblestone

ReplaceWithBiomeBlocks: true

ReplaceWithSurfaceBlock: GRASS

ReplaceWithGroundBlock: DIRT

ReplaceWithStoneBlock: STONE

SmoothRadius: 0

SmoothHeightOffset: 0

SmoothStartTop: false

SmoothStartWood: false

SmoothingSurfaceBlock: 

SmoothingGroundBlock: 

BO3Group: 

IsSpawnPoint: false

DoReplaceBlocks: true


#######################################################################
# +-----------------------------------------------------------------+ #
# |                              Blocks                             | #
# +-----------------------------------------------------------------+ #
#######################################################################

Block(-3,-1,-5,GRASS)
Block(-2,-1,-5,GRASS)
Block(0,-1,-5,GRASS_PATH)
Block(1,-1,-5,GRASS_PATH)
Block(3,-1,-5,GRASS_PATH)
Block(4,-1,-5,GRASS_PATH)
Block(-5,-1,-4,GRASS_PATH)
Block(-4,-1,-4,GRASS)
Block(-3,-1,-4,GRASS)
Block(-2,-1,-4,GRASS)
Block(-1,-1,-4,GRASS)
Block(0,-1,-4,GRAVEL)
Block(1,-1,-4,COBBLESTONE)
Block(2,-1,-4,GRASS_PATH)
Block(3,-1,-4,GRASS_PATH)
Block(-5,-1,-3,COBBLESTONE)
Block(-4,-1,-3,GRASS)
Block(-3,-1,-3,GRASS)
Block(-2,-1,-3,COBBLESTONE)
Block(-1,-1,-3,COBBLESTONE)
Block(0,-1,-3,GRAVEL)
Block(1,-1,-3,GRAVEL)
Block(2,-1,-3,COBBLESTONE)
Block(3,-1,-3,COBBLESTONE)
Block(4,-1,-3,GRASS_PATH)
Block(-5,-1,-2,GRASS_PATH)
Block(-4,-1,-2,GRASS)
Block(-3,-1,-2,COBBLESTONE)
Block(-2,-1,-2,COBBLESTONE)
Block(-1,-1,-2,COBBLESTONE)
Block(0,-1,-2,GRAVEL)
Block(1,-1,-2,GRAVEL)
Block(2,-1,-2,COBBLESTONE)
Block(3,-1,-2,COBBLESTONE)
Block(4,-1,-2,GRASS_PATH)
Block(-5,-1,-1,GRASS_PATH)
Block(-4,-1,-1,GRASS)
Block(-3,-1,-1,LOG_2:0)
Block(-2,-1,-1,COBBLESTONE)
Block(-1,-1,-1,GRAVEL)
Block(0,-1,-1,LOG_2:0)
Block(1,-1,-1,GRASS)
Block(2,-1,-1,GRASS)
Block(3,-1,-1,GRASS)
Block(4,-1,-1,GRASS_PATH)
Block(-6,-1,0,GRASS_PATH)
Block(-5,-1,0,GRASS)
Block(-4,-1,0,GRASS)
Block(-3,-1,0,GRASS)
Block(-2,-1,0,GRAVEL)
Block(-1,-1,0,GRAVEL)
Block(0,-1,0,GRAVEL)
Block(1,-1,0,GRASS)
Block(2,-1,0,GRASS)
Block(3,-1,0,COBBLESTONE)
Block(4,-1,0,GRASS_PATH)
Block(-6,-1,1,GRASS_PATH)
Block(-5,-1,1,GRASS)
Block(-4,-1,1,DIRT)
Block(-3,-1,1,GRASS)
Block(-2,-1,1,GRASS)
Block(-1,-1,1,GRASS)
Block(0,-1,1,GRASS)
Block(1,-1,1,COBBLESTONE)
Block(2,-1,1,COBBLESTONE)
Block(3,-1,1,COBBLESTONE)
Block(4,-1,1,GRASS_PATH)
Block(-6,-1,2,GRASS_PATH)
Block(-5,-1,2,GRASS)
Block(-4,-1,2,COBBLESTONE)
Block(-3,-1,2,LOG_2:0)
Block(-2,-1,2,GRASS)
Block(-1,-1,2,DIRT)
Block(0,-1,2,LOG_2:0)
Block(1,-1,2,GRASS)
Block(2,-1,2,GRASS)
Block(3,-1,2,GRASS_PATH)
Block(-7,-1,3,GRASS_PATH)
Block(-6,-1,3,GRASS_PATH)
Block(-5,-1,3,COBBLESTONE)
Block(-4,-1,3,COBBLESTONE)
Block(-3,-1,3,GRASS)
Block(-2,-1,3,GRASS)
Block(-1,-1,3,COBBLESTONE)
Block(0,-1,3,GRASS)
Block(1,-1,3,GRASS)
Block(2,-1,3,GRASS)
Block(3,-1,3,GRASS_PATH)
Block(-6,-1,4,GRASS_PATH)
Block(-5,-1,4,COBBLESTONE)
Block(-4,-1,4,GRASS_PATH)
Block(-3,-1,4,GRASS)
Block(-2,-1,4,GRASS)
Block(-1,-1,4,COBBLESTONE)
Block(0,-1,4,GRASS_PATH)
Block(2,-1,4,COBBLESTONE)
Block(-2,-1,5,GRASS_PATH)
Block(-1,-1,5,GRASS_PATH)
Block(-5,0,-3,COBBLE_WALL)
Block(2,0,-3,COBBLE_WALL)
Block(2,0,-2,SPRUCE_FENCE)
Block(-3,0,-1,LOG_2:0)
Block(0,0,-1,LOG_2:0)
Block(-3,0,0,CAULDRON)
Block(-4,0,1,AIR)
Block(-3,0,2,LOG_2:0)
Block(-1,0,2,WORKBENCH)
Block(0,0,2,LOG_2:0)
Block(-5,0,4,COBBLE_WALL)
Block(2,0,4,COBBLE_WALL)
Block(-5,1,-3,SPRUCE_FENCE)
Block(2,1,-3,SPRUCE_FENCE)
Block(2,1,-2,TORCH)
Block(-3,1,-1,LOG_2:0)
Block(0,1,-1,LOG_2:0)
Block(-2,1,0,LADDER:5)
Block(-3,1,2,LOG_2:0)
Block(0,1,2,LOG_2:0)
Block(-5,1,4,SPRUCE_FENCE)
Block(2,1,4,SPRUCE_FENCE)
Block(-3,2,-4,WOOD_STEP:2)
Block(-2,2,-4,WOOD_DOUBLE_STEP:2)
Block(-1,2,-4,WOOD_STEP:10)
Block(0,2,-4,WOOD_STEP:10)
Block(1,2,-4,WOOD_STEP:10)
Block(2,2,-4,WOOD_STEP:10)
Block(3,2,-4,WOOD_STEP:10)
Block(-5,2,-3,WOOD_STEP:2)
Block(-4,2,-3,WOOD_STEP:2)
Block(-3,2,-3,WOOD_STEP:2)
Block(-2,2,-3,WOOD_STEP:10)
Block(2,2,-3,SPRUCE_FENCE)
Block(3,2,-3,WOOD_STEP:10)
Block(-5,2,-2,WOOD_STEP:2)
Block(-4,2,-2,WOOD_STEP:10)
Block(-3,2,-2,WOOD_STEP:10)
Block(-2,2,-2,WOOD_STEP:10)
Block(3,2,-2,WOOD_STEP:10)
Block(-5,2,-1,WOOD_DOUBLE_STEP:2)
Block(-4,2,-1,WOOD_STEP:10)
Block(-3,2,-1,LOG_2:0)
Block(-2,2,-1,SPRUCE_FENCE)
Block(-1,2,-1,SPRUCE_FENCE)
Block(0,2,-1,LOG_2:0)
Block(3,2,-1,WOOD_STEP:10)
Block(-5,2,0,WOOD_STEP:10)
Block(-4,2,0,WOOD_STEP:10)
Block(-3,2,0,SPRUCE_FENCE)
Block(-2,2,0,LADDER:5)
Block(0,2,0,SPRUCE_FENCE)
Block(1,2,0,WOOD_STEP:10)
Block(2,2,0,WOOD_STEP:10)
Block(3,2,0,WOOD_STEP:10)
Block(-5,2,1,WOOD_DOUBLE_STEP:2)
Block(-4,2,1,WOOD_STEP:10)
Block(-3,2,1,SPRUCE_FENCE)
Block(0,2,1,SPRUCE_FENCE)
Block(1,2,1,WOOD_STEP:10)
Block(2,2,1,WOOD_DOUBLE_STEP:2)
Block(3,2,1,WOOD_STEP:2)
Block(-5,2,2,WOOD_STEP:2)
Block(-4,2,2,WOOD_STEP:10)
Block(-3,2,2,LOG_2:0)
Block(-2,2,2,SPRUCE_FENCE)
Block(-1,2,2,SPRUCE_FENCE)
Block(0,2,2,LOG_2:0)
Block(1,2,2,WOOD_STEP:10)
Block(2,2,2,WOOD_DOUBLE_STEP:2)
Block(-5,2,3,WOOD_STEP:2)
Block(-4,2,3,WOOD_STEP:10)
Block(-3,2,3,WOOD_STEP:10)
Block(-2,2,3,WOOD_STEP:10)
Block(-1,2,3,WOOD_STEP:10)
Block(0,2,3,WOOD_STEP:10)
Block(1,2,3,WOOD_STEP:10)
Block(2,2,3,WOOD_DOUBLE_STEP:2)
Block(-5,2,4,WOOD_STEP:2)
Block(-4,2,4,WOOD_STEP:2)
Block(-3,2,4,WOOD_DOUBLE_STEP:2)
Block(-2,2,4,WOOD_DOUBLE_STEP:2)
Block(-1,2,4,WOOD_STEP:2)
Block(0,2,4,WOOD_STEP:2)
Block(1,2,4,WOOD_STEP:2)
Block(2,2,4,WOOD_STEP:2)
Block(-1,3,-3,WOOD_STEP:2)
Block(0,3,-3,WOOD_STEP:2)
Block(1,3,-3,WOOD_STEP:2)
Block(2,3,-3,WOOD_STEP:2)
Block(-1,3,-2,WOOD_STEP:2)
Block(0,3,-2,WOOD_DOUBLE_STEP:2)
Block(1,3,-2,WOOD_DOUBLE_STEP:2)
Block(2,3,-2,WOOD_STEP:2)
Block(-3,3,-1,LOG_2:0)
Block(-2,3,-1,WOOD_STEP:2)
Block(-1,3,-1,WOOD_STEP:2)
Block(0,3,-1,LOG_2:0)
Block(1,3,-1,WOOD_DOUBLE_STEP:2)
Block(2,3,-1,WOOD_STEP:2)
Block(-4,3,0,WOOD_STEP:2)
Block(-3,3,0,WOOD_STEP:2)
Block(-2,3,0,LADDER:5)
Block(0,3,0,WOOD_STEP:2)
Block(1,3,0,WOOD_STEP:2)
Block(-3,3,1,WOOD_STEP:2)
Block(0,3,1,WOOD_STEP:2)
Block(-3,3,2,LOG_2:0)
Block(-2,3,2,WOOD_STEP:2)
Block(-1,3,2,WOOD_STEP:2)
Block(0,3,2,LOG_2:0)
Block(1,3,2,WOOD_STEP:2)
Block(-2,3,3,WOOD_STEP:2)
Block(-3,4,-1,LOG_2:0)
Block(0,4,-1,LOG_2:0)
Block(-2,4,0,LADDER:5)
Block(-3,4,2,LOG_2:0)
Block(0,4,2,LOG_2:0)
Block(-3,5,-1,LOG_2:0)
Block(0,5,-1,LOG_2:0)
Block(-2,5,0,LADDER:5)
Block(-3,5,2,LOG_2:0)
Block(0,5,2,LOG_2:0)
Block(-3,6,-2,STONE_BUTTON)
Block(0,6,-2,STONE_BUTTON)
Block(-4,6,-1,STONE_BUTTON:2)
Block(-3,6,-1,LOG_2:0)
Block(-2,6,-1,SPRUCE_WOOD_STAIRS:5)
Block(-1,6,-1,SPRUCE_WOOD_STAIRS:4)
Block(0,6,-1,LOG_2:0)
Block(1,6,-1,STONE_BUTTON:1)
Block(-3,6,0,SPRUCE_WOOD_STAIRS:7)
Block(-2,6,0,LADDER:5)
Block(-1,6,0,WOOD_STEP:8)
Block(0,6,0,SPRUCE_WOOD_STAIRS:7)
Block(-3,6,1,SPRUCE_WOOD_STAIRS:6)
Block(-2,6,1,WOOD_STEP:8)
Block(-1,6,1,WOOD_STEP:8)
Block(0,6,1,SPRUCE_WOOD_STAIRS:6)
Block(-4,6,2,STONE_BUTTON:2)
Block(-3,6,2,LOG_2:0)
Block(-2,6,2,SPRUCE_WOOD_STAIRS:5)
Block(-1,6,2,SPRUCE_WOOD_STAIRS:4)
Block(0,6,2,LOG_2:0)
Block(1,6,2,STONE_BUTTON:1)
Block(-3,6,3,STONE_BUTTON:3)
Block(0,6,3,STONE_BUTTON:3)
Block(-3,7,-2,TRAP_DOOR:12)
Block(-2,7,-2,TRAP_DOOR:8)
Block(-1,7,-2,TRAP_DOOR:8)
Block(0,7,-2,TRAP_DOOR:12)
Block(-4,7,-1,TRAP_DOOR:14)
Block(-3,7,-1,COBBLE_WALL)
Block(-2,7,-1,AIR)
Block(0,7,-1,COBBLE_WALL)
Block(1,7,-1,TRAP_DOOR:15)
Block(-4,7,0,TRAP_DOOR:10)
Block(1,7,0,TRAP_DOOR:11)
Block(-4,7,1,TRAP_DOOR:10)
Block(-1,7,1,AIR)
Block(1,7,1,TRAP_DOOR:11)
Block(-4,7,2,TRAP_DOOR:14)
Block(-3,7,2,COBBLE_WALL)
Block(0,7,2,COBBLE_WALL)
Block(1,7,2,TRAP_DOOR:15)
Block(-3,7,3,TRAP_DOOR:13)
Block(-2,7,3,TRAP_DOOR:9)
Block(-1,7,3,TRAP_DOOR:9)
Block(0,7,3,TRAP_DOOR:13)
Block(-4,8,-2,SPRUCE_WOOD_STAIRS:2)
Block(-3,8,-2,SPRUCE_WOOD_STAIRS:2)
Block(-2,8,-2,SPRUCE_WOOD_STAIRS:2)
Block(-1,8,-2,SPRUCE_WOOD_STAIRS:2)
Block(0,8,-2,SPRUCE_WOOD_STAIRS:2)
Block(1,8,-2,SPRUCE_WOOD_STAIRS:2)
Block(-4,8,-1,SPRUCE_WOOD_STAIRS:0)
Block(-3,8,-1,SPRUCE_FENCE)
Block(0,8,-1,SPRUCE_FENCE)
Block(1,8,-1,SPRUCE_WOOD_STAIRS:1)
Block(-4,8,0,WOOD_STAIRS:0)
Block(1,8,0,SPRUCE_WOOD_STAIRS:1)
Block(-4,8,1,WOOD_STAIRS:0)
Block(1,8,1,SPRUCE_WOOD_STAIRS:1)
Block(-4,8,2,SPRUCE_WOOD_STAIRS:0)
Block(-3,8,2,SPRUCE_FENCE)
Block(0,8,2,SPRUCE_FENCE)
Block(1,8,2,SPRUCE_WOOD_STAIRS:1)
Block(-4,8,3,SPRUCE_WOOD_STAIRS:0)
Block(-3,8,3,WOOD_STAIRS:0)
Block(-2,8,3,WOOD_STAIRS:0)
Block(-1,8,3,WOOD_STAIRS:0)
Block(0,8,3,SPRUCE_WOOD_STAIRS:0)
Block(1,8,3,SPRUCE_WOOD_STAIRS:1)
Block(-3,9,-1,WOOD_STEP)
Block(-2,9,-1,WOOD_STEP)
Block(-1,9,-1,WOOD_STEP)
Block(0,9,-1,WOOD_STEP)
Block(-3,9,0,WOOD_STEP)
Block(-2,9,0,WOOD_DOUBLE_STEP)
Block(-1,9,0,WOOD_DOUBLE_STEP)
Block(0,9,0,WOOD_STEP)
Block(-3,9,1,WOOD_STEP)
Block(-2,9,1,WOOD_STEP)
Block(-1,9,1,WOOD_DOUBLE_STEP)
Block(0,9,1,WOOD_STEP)
Block(-3,9,2,WOOD_STEP)
Block(-2,9,2,WOOD_STEP)
Block(-1,9,2,WOOD_STEP)
Block(0,9,2,WOOD_STEP)

#######################################################################
# +-----------------------------------------------------------------+ #
# |                             Branches                            | #
# +-----------------------------------------------------------------+ #
#######################################################################


#######################################################################
# +-----------------------------------------------------------------+ #
# |                             Entities                            | #
# +-----------------------------------------------------------------+ #
#######################################################################

#Entity(-4,0,1,minecraft:villager,1,../../NBT/entities/tribalguard.txt)
#Entity(-1,7,1,minecraft:villager,1,../../NBT/entities/tribalbowman.txt)

#######################################################################
# +-----------------------------------------------------------------+ #
# |                            Particles                            | #
# +-----------------------------------------------------------------+ #
#######################################################################


#######################################################################
# +-----------------------------------------------------------------+ #
# |                             Spawners                            | #
# +-----------------------------------------------------------------+ #
#######################################################################


#######################################################################
# +-----------------------------------------------------------------+ #
# |                             ModData                             | #
# +-----------------------------------------------------------------+ #
#######################################################################

