#######################################################################
# +-----------------------------------------------------------------+ #
# |                            BO3 object                           | #
# +-----------------------------------------------------------------+ #
#######################################################################

Author: Bo3 BulkEdit

Description: Converted Schematic - Modified by Bo3BulkEdit

Version: 3

SettingsMode: WriteDisable

#######################################################################
# +-----------------------------------------------------------------+ #
# |                          Main settings                          | #
# +-----------------------------------------------------------------+ #
#######################################################################



Frequency: 0


SpawnHeight: randomY





##############################
# Height Limits for the BO3. #
##############################

MinHeight: 0
MaxHeight: 256

#######################################################################
# +-----------------------------------------------------------------+ #
# |                      Source block settings                      | #
# +-----------------------------------------------------------------+ #
#######################################################################

CanOverride: true
MaxPercentageOutsideSourceBlock: 100
OutsideSourceBlock: placeAnyway

#######################################################################
# +-----------------------------------------------------------------+ #
# |                               OTG+                              | #
# +-----------------------------------------------------------------+ #
#######################################################################

#######################################################################
# +-----------------------------------------------------------------+ #
# |                              Blocks                             | #
# +-----------------------------------------------------------------+ #
#######################################################################

B(0,750,0,AIR)
B(15,750,15,AIR)
B(15,2,7,betternether:quartz_stained_glass:15)
B(15,2,8,betternether:quartz_stained_glass:15)
B(15,2,9,betternether:quartz_stained_glass:15)
B(15,3,6,betternether:quartz_stained_glass:15)
B(14,3,7,betternether:quartz_stained_glass:15)
B(15,3,7,betternether:quartz_stained_glass:15)
B(14,3,8,betternether:quartz_stained_glass:15)
B(15,3,8,betternether:quartz_stained_glass:15)
B(15,3,9,betternether:quartz_stained_glass:15)
B(15,4,5,betternether:quartz_stained_glass:15)
B(14,4,6,betternether:quartz_stained_glass:15)
B(15,4,6,betternether:quartz_stained_glass:15)
B(14,4,7,betternether:quartz_stained_glass:15)
B(15,4,7,betternether:quartz_stained_glass:15)
B(14,4,8,betternether:quartz_stained_glass:15)
B(15,4,8,betternether:quartz_stained_glass:15)
B(15,4,9,betternether:quartz_stained_glass:15)
B(15,5,4,betternether:quartz_stained_glass:15)
B(13,5,5,betternether:quartz_stained_glass:15)
B(14,5,5,betternether:quartz_stained_glass:15)
B(15,5,5,betternether:quartz_stained_glass:15)
B(13,5,6,betternether:quartz_stained_glass:15)
B(14,5,6,betternether:quartz_stained_glass:15)
B(15,5,6,betternether:quartz_stained_glass:15)
B(14,5,7,betternether:quartz_stained_glass:15)
B(15,5,7,betternether:quartz_stained_glass:15)
B(14,5,8,betternether:quartz_stained_glass:15)
B(15,5,8,betternether:quartz_stained_glass:15)
B(15,5,9,betternether:quartz_stained_glass:15)
B(15,6,3,betternether:quartz_stained_glass:15)
B(13,6,4,betternether:quartz_stained_glass:15)
B(14,6,4,betternether:quartz_stained_glass:15)
B(15,6,4,betternether:quartz_stained_glass:15)
B(12,6,5,betternether:quartz_stained_glass:15)
B(13,6,5,betternether:quartz_stained_glass:15)
B(14,6,5,betternether:quartz_stained_glass:15)
B(15,6,5,betternether:quartz_stained_glass:15)
B(13,6,6,betternether:quartz_stained_glass:15)
B(14,6,6,betternether:quartz_stained_glass:15)
B(15,6,6,betternether:quartz_stained_glass:15)
B(14,6,7,betternether:quartz_stained_glass:15)
B(15,6,7,betternether:quartz_stained_glass:15)
B(14,6,8,betternether:quartz_stained_glass:15)
B(15,6,8,betternether:quartz_stained_glass:15)
B(15,6,9,betternether:quartz_stained_glass:15)
B(15,7,1,betternether:quartz_stained_glass:15)
B(13,7,2,betternether:quartz_stained_glass:15)
B(14,7,2,betternether:quartz_stained_glass:15)
B(15,7,2,betternether:quartz_stained_glass:15)
B(12,7,3,betternether:quartz_stained_glass:15)
B(13,7,3,betternether:quartz_stained_glass:15)
B(14,7,3,betternether:quartz_stained_glass:15)
B(15,7,3,betternether:quartz_stained_glass:15)
B(12,7,4,betternether:quartz_stained_glass:15)
B(13,7,4,betternether:quartz_stained_glass:15)
B(14,7,4,betternether:quartz_stained_glass:15)
B(15,7,4,betternether:quartz_stained_glass:15)
B(12,7,5,betternether:quartz_stained_glass:15)
B(13,7,5,betternether:quartz_stained_glass:15)
B(14,7,5,betternether:quartz_stained_glass:15)
RB(15,7,5,srparasites:parasitestain:1,80,quark:crystal:1,30,srparasites:parasiterubbledense:1,100)
B(13,7,6,betternether:quartz_stained_glass:15)
B(14,7,6,betternether:quartz_stained_glass:15)
RB(15,7,6,srparasites:parasitestain:1,80,quark:crystal:1,30,srparasites:parasiterubbledense:1,100)
B(14,7,7,betternether:quartz_stained_glass:15)
RB(15,7,7,srparasites:parasitestain:1,80,quark:crystal:1,30,srparasites:parasiterubbledense:1,100)
B(14,7,8,betternether:quartz_stained_glass:15)
B(15,7,8,betternether:quartz_stained_glass:15)
B(15,7,9,betternether:quartz_stained_glass:15)
B(13,8,1,betternether:quartz_stained_glass:15)
B(14,8,1,betternether:quartz_stained_glass:15)
B(15,8,1,betternether:quartz_stained_glass:15)
B(12,8,2,betternether:quartz_stained_glass:15)
B(13,8,2,betternether:quartz_stained_glass:15)
B(14,8,2,betternether:quartz_stained_glass:15)
B(15,8,2,betternether:quartz_stained_glass:15)
B(12,8,3,betternether:quartz_stained_glass:15)
B(13,8,3,betternether:quartz_stained_glass:15)
B(14,8,3,betternether:quartz_stained_glass:15)
B(15,8,3,betternether:quartz_stained_glass:15)
B(12,8,4,betternether:quartz_stained_glass:15)
B(13,8,4,betternether:quartz_stained_glass:15)
B(14,8,4,betternether:quartz_stained_glass:15)
RB(15,8,4,srparasites:parasitestain:1,80,quark:crystal:1,30,srparasites:parasiterubbledense:1,100)
B(12,8,5,betternether:quartz_stained_glass:15)
B(13,8,5,betternether:quartz_stained_glass:15)
B(14,8,5,betternether:quartz_stained_glass:15)
RB(15,8,5,srparasites:parasitestain:1,80,quark:crystal:1,30,srparasites:parasiterubbledense:1,100)
B(13,8,6,betternether:quartz_stained_glass:15)
RB(14,8,6,srparasites:parasitestain:1,80,quark:crystal:1,30,srparasites:parasiterubbledense:1,100)
RB(15,8,6,srparasites:parasitestain:1,80,quark:crystal:1,30,srparasites:parasiterubbledense:1,100)
B(14,8,7,betternether:quartz_stained_glass:15)
B(15,8,7,betternether:quartz_stained_glass:15)
B(14,8,8,betternether:quartz_stained_glass:15)
B(15,8,8,betternether:quartz_stained_glass:15)
B(15,8,9,betternether:quartz_stained_glass:15)
B(13,9,0,betternether:quartz_stained_glass:15)
B(14,9,0,betternether:quartz_stained_glass:15)
B(15,9,0,betternether:quartz_stained_glass:15)
B(12,9,1,betternether:quartz_stained_glass:15)
B(13,9,1,betternether:quartz_stained_glass:15)
B(14,9,1,betternether:quartz_stained_glass:15)
B(15,9,1,betternether:quartz_stained_glass:15)
B(11,9,2,betternether:quartz_stained_glass:15)
B(12,9,2,betternether:quartz_stained_glass:15)
B(13,9,2,betternether:quartz_stained_glass:15)
B(14,9,2,betternether:quartz_stained_glass:15)
B(15,9,2,betternether:quartz_stained_glass:15)
B(11,9,3,betternether:quartz_stained_glass:15)
B(12,9,3,betternether:quartz_stained_glass:15)
B(13,9,3,betternether:quartz_stained_glass:15)
B(14,9,3,betternether:quartz_stained_glass:15)
B(15,9,3,betternether:quartz_stained_glass:15)
B(12,9,4,betternether:quartz_stained_glass:15)
B(13,9,4,betternether:quartz_stained_glass:15)
B(14,9,4,betternether:quartz_stained_glass:15)
RB(15,9,4,srparasites:parasitestain:1,80,quark:crystal:1,30,srparasites:parasiterubbledense:1,100)
B(12,9,5,betternether:quartz_stained_glass:15)
B(13,9,5,betternether:quartz_stained_glass:15)
RB(14,9,5,srparasites:parasitestain:1,80,quark:crystal:1,30,srparasites:parasiterubbledense:1,100)
RB(15,9,5,srparasites:parasitestain:1,80,quark:crystal:1,30,srparasites:parasiterubbledense:1,100)
B(13,9,6,betternether:quartz_stained_glass:15)
RB(14,9,6,srparasites:parasitestain:1,80,quark:crystal:1,30,srparasites:parasiterubbledense:1,100)
B(15,9,6,betternether:quartz_stained_glass:15)
B(14,9,7,betternether:quartz_stained_glass:15)
B(15,9,7,betternether:quartz_stained_glass:15)
B(14,9,8,betternether:quartz_stained_glass:15)
B(15,9,8,betternether:quartz_stained_glass:15)
B(15,9,9,betternether:quartz_stained_glass:15)
B(11,10,0,betternether:quartz_stained_glass:15)
B(12,10,0,betternether:quartz_stained_glass:15)
B(13,10,0,betternether:quartz_stained_glass:15)
B(14,10,0,betternether:quartz_stained_glass:15)
B(15,10,0,betternether:quartz_stained_glass:15)
B(10,10,1,betternether:quartz_stained_glass:15)
B(11,10,1,betternether:quartz_stained_glass:15)
B(12,10,1,betternether:quartz_stained_glass:15)
B(13,10,1,betternether:quartz_stained_glass:15)
B(14,10,1,betternether:quartz_stained_glass:15)
B(15,10,1,betternether:quartz_stained_glass:15)
B(10,10,2,betternether:quartz_stained_glass:15)
B(11,10,2,betternether:quartz_stained_glass:15)
B(12,10,2,betternether:quartz_stained_glass:15)
B(13,10,2,betternether:quartz_stained_glass:15)
B(14,10,2,betternether:quartz_stained_glass:15)
B(15,10,2,betternether:quartz_stained_glass:15)
B(11,10,3,betternether:quartz_stained_glass:15)
B(12,10,3,betternether:quartz_stained_glass:15)
B(13,10,3,betternether:quartz_stained_glass:15)
RB(14,10,3,srparasites:parasitestain:1,80,quark:crystal:1,30,srparasites:parasiterubbledense:1,100)
RB(15,10,3,srparasites:parasitestain:1,80,quark:crystal:1,30,srparasites:parasiterubbledense:1,100)
B(12,10,4,betternether:quartz_stained_glass:15)
B(13,10,4,betternether:quartz_stained_glass:15)
RB(14,10,4,srparasites:parasitestain:1,80,quark:crystal:1,30,srparasites:parasiterubbledense:1,100)
RB(15,10,4,srparasites:parasitestain:1,80,quark:crystal:1,30,srparasites:parasiterubbledense:1,100)
B(12,10,5,betternether:quartz_stained_glass:15)
B(13,10,5,betternether:quartz_stained_glass:15)
B(14,10,5,betternether:quartz_stained_glass:15)
RB(15,10,5,srparasites:parasitestain:1,80,quark:crystal:1,30,srparasites:parasiterubbledense:1,100)
B(13,10,6,betternether:quartz_stained_glass:15)
B(14,10,6,betternether:quartz_stained_glass:15)
B(15,10,6,betternether:quartz_stained_glass:15)
B(14,10,7,betternether:quartz_stained_glass:15)
B(15,10,7,betternether:quartz_stained_glass:15)
B(14,10,8,betternether:quartz_stained_glass:15)
B(15,10,8,betternether:quartz_stained_glass:15)
B(10,11,0,betternether:quartz_stained_glass:15)
B(11,11,0,betternether:quartz_stained_glass:15)
B(12,11,0,betternether:quartz_stained_glass:15)
B(13,11,0,betternether:quartz_stained_glass:15)
B(14,11,0,betternether:quartz_stained_glass:15)
B(15,11,0,betternether:quartz_stained_glass:15)
B(10,11,1,betternether:quartz_stained_glass:15)
B(11,11,1,betternether:quartz_stained_glass:15)
B(12,11,1,betternether:quartz_stained_glass:15)
RB(13,11,1,srparasites:parasitestain:1,80,quark:crystal:1,30,srparasites:parasiterubbledense:1,100)
B(14,11,1,betternether:quartz_stained_glass:15)
B(15,11,1,betternether:quartz_stained_glass:15)
B(10,11,2,betternether:quartz_stained_glass:15)
B(11,11,2,betternether:quartz_stained_glass:15)
B(12,11,2,betternether:quartz_stained_glass:15)
B(13,11,2,betternether:quartz_stained_glass:15)
B(14,11,2,betternether:quartz_stained_glass:15)
RB(15,11,2,srparasites:parasitestain:1,80,quark:crystal:1,30,srparasites:parasiterubbledense:1,100)
B(11,11,3,betternether:quartz_stained_glass:15)
B(12,11,3,betternether:quartz_stained_glass:15)
RB(13,11,3,srparasites:parasitestain:1,80,quark:crystal:1,30,srparasites:parasiterubbledense:1,100)
RB(14,11,3,srparasites:parasitestain:1,80,quark:crystal:1,30,srparasites:parasiterubbledense:1,100)
RB(15,11,3,srparasites:parasitestain:1,80,quark:crystal:1,30,srparasites:parasiterubbledense:1,100)
B(12,11,4,betternether:quartz_stained_glass:15)
B(13,11,4,betternether:quartz_stained_glass:15)
RB(14,11,4,srparasites:parasitestain:1,80,quark:crystal:1,30,srparasites:parasiterubbledense:1,100)
RB(15,11,4,srparasites:parasitestain:1,80,quark:crystal:1,30,srparasites:parasiterubbledense:1,100)
B(12,11,5,betternether:quartz_stained_glass:15)
B(13,11,5,betternether:quartz_stained_glass:15)
B(14,11,5,betternether:quartz_stained_glass:15)
B(15,11,5,betternether:quartz_stained_glass:15)
B(13,11,6,betternether:quartz_stained_glass:15)
B(14,11,6,betternether:quartz_stained_glass:15)
B(15,11,6,betternether:quartz_stained_glass:15)
B(14,11,7,betternether:quartz_stained_glass:15)
B(15,11,7,betternether:quartz_stained_glass:15)
B(14,11,8,betternether:quartz_stained_glass:15)
B(15,11,8,betternether:quartz_stained_glass:15)
B(9,12,0,betternether:quartz_stained_glass:15)
B(10,12,0,betternether:quartz_stained_glass:15)
B(11,12,0,betternether:quartz_stained_glass:15)
RB(12,12,0,srparasites:parasitestain:1,80,quark:crystal:1,30,srparasites:parasiterubbledense:1,100)
B(13,12,0,betternether:quartz_stained_glass:15)
B(14,12,0,betternether:quartz_stained_glass:15)
B(15,12,0,betternether:quartz_stained_glass:15)
B(9,12,1,betternether:quartz_stained_glass:15)
B(10,12,1,betternether:quartz_stained_glass:15)
B(11,12,1,betternether:quartz_stained_glass:15)
B(12,12,1,betternether:quartz_stained_glass:15)
RB(13,12,1,srparasites:parasitestain:1,80,quark:crystal:1,30,srparasites:parasiterubbledense:1,100)
RB(14,12,1,srparasites:parasitestain:1,80,quark:crystal:1,30,srparasites:parasiterubbledense:1,100)
B(15,12,1,betternether:quartz_stained_glass:15)
B(10,12,2,betternether:quartz_stained_glass:15)
B(11,12,2,betternether:quartz_stained_glass:15)
RB(12,12,2,srparasites:parasitestain:1,80,quark:crystal:1,30,srparasites:parasiterubbledense:1,100)
RB(13,12,2,srparasites:parasitestain:1,80,quark:crystal:1,30,srparasites:parasiterubbledense:1,100)
RB(14,12,2,srparasites:parasitestain:1,80,quark:crystal:1,30,srparasites:parasiterubbledense:1,100)
B(15,12,2,betternether:quartz_stained_glass:15)
B(11,12,3,betternether:quartz_stained_glass:15)
B(12,12,3,betternether:quartz_stained_glass:15)
B(13,12,3,betternether:quartz_stained_glass:15)
RB(14,12,3,srparasites:parasitestain:1,80,quark:crystal:1,30,srparasites:parasiterubbledense:1,100)
B(15,12,3,betternether:quartz_stained_glass:15)
B(12,12,4,betternether:quartz_stained_glass:15)
B(13,12,4,betternether:quartz_stained_glass:15)
B(14,12,4,betternether:quartz_stained_glass:15)
B(15,12,4,betternether:quartz_stained_glass:15)
B(12,12,5,betternether:quartz_stained_glass:15)
B(13,12,5,betternether:quartz_stained_glass:15)
B(14,12,5,betternether:quartz_stained_glass:15)
B(15,12,5,betternether:quartz_stained_glass:15)
B(13,12,6,betternether:quartz_stained_glass:15)
B(14,12,6,betternether:quartz_stained_glass:15)
B(15,12,6,betternether:quartz_stained_glass:15)
B(14,12,7,betternether:quartz_stained_glass:15)
B(9,13,0,betternether:quartz_stained_glass:15)
B(10,13,0,betternether:quartz_stained_glass:15)
B(11,13,0,betternether:quartz_stained_glass:15)
RB(12,13,0,srparasites:parasitestain:1,80,quark:crystal:1,30,srparasites:parasiterubbledense:1,100)
RB(13,13,0,srparasites:parasitestain:1,80,quark:crystal:1,30,srparasites:parasiterubbledense:1,100)
B(14,13,0,betternether:quartz_stained_glass:15)
B(15,13,0,betternether:quartz_stained_glass:15)
B(9,13,1,betternether:quartz_stained_glass:15)
B(10,13,1,betternether:quartz_stained_glass:15)
B(11,13,1,betternether:quartz_stained_glass:15)
RB(12,13,1,srparasites:parasitestain:1,80,quark:crystal:1,30,srparasites:parasiterubbledense:1,100)
RB(13,13,1,srparasites:parasitestain:1,80,quark:crystal:1,30,srparasites:parasiterubbledense:1,100)
RB(14,13,1,srparasites:parasitestain:1,80,quark:crystal:1,30,srparasites:parasiterubbledense:1,100)
B(15,13,1,betternether:quartz_stained_glass:15)
B(10,13,2,betternether:quartz_stained_glass:15)
B(11,13,2,betternether:quartz_stained_glass:15)
RB(12,13,2,srparasites:parasitestain:1,80,quark:crystal:1,30,srparasites:parasiterubbledense:1,100)
B(13,13,2,betternether:quartz_stained_glass:15)
B(14,13,2,betternether:quartz_stained_glass:15)
B(15,13,2,betternether:quartz_stained_glass:15)
B(11,13,3,betternether:quartz_stained_glass:15)
B(12,13,3,betternether:quartz_stained_glass:15)
B(13,13,3,betternether:quartz_stained_glass:15)
RB(14,13,3,srparasites:parasitestain:1,80,quark:crystal:1,30,srparasites:parasiterubbledense:1,100)
B(15,13,3,betternether:quartz_stained_glass:15)
B(12,13,4,betternether:quartz_stained_glass:15)
B(13,13,4,betternether:quartz_stained_glass:15)
B(14,13,4,betternether:quartz_stained_glass:15)
B(15,13,4,betternether:quartz_stained_glass:15)
B(12,13,5,betternether:quartz_stained_glass:15)
B(13,13,5,betternether:quartz_stained_glass:15)
B(14,13,5,betternether:quartz_stained_glass:15)
B(15,13,5,betternether:quartz_stained_glass:15)
B(14,13,6,betternether:quartz_stained_glass:15)
B(9,14,0,betternether:quartz_stained_glass:15)
B(10,14,0,betternether:quartz_stained_glass:15)
RB(11,14,0,srparasites:parasitestain:1,80,quark:crystal:1,30,srparasites:parasiterubbledense:1,100)
RB(12,14,0,srparasites:parasitestain:1,80,quark:crystal:1,30,srparasites:parasiterubbledense:1,100)
B(13,14,0,betternether:quartz_stained_glass:15)
B(14,14,0,betternether:quartz_stained_glass:15)
B(15,14,0,betternether:quartz_stained_glass:15)
B(9,14,1,betternether:quartz_stained_glass:15)
B(10,14,1,betternether:quartz_stained_glass:15)
RB(11,14,1,srparasites:parasitestain:1,80,quark:crystal:1,30,srparasites:parasiterubbledense:1,100)
B(12,14,1,betternether:quartz_stained_glass:15)
RB(13,14,1,srparasites:parasitestain:1,80,quark:crystal:1,30,srparasites:parasiterubbledense:1,100)
B(14,14,1,betternether:quartz_stained_glass:15)
B(15,14,1,betternether:quartz_stained_glass:15)
B(10,14,2,betternether:quartz_stained_glass:15)
B(11,14,2,betternether:quartz_stained_glass:15)
B(12,14,2,betternether:quartz_stained_glass:15)
B(13,14,2,betternether:quartz_stained_glass:15)
B(14,14,2,betternether:quartz_stained_glass:15)
B(15,14,2,betternether:quartz_stained_glass:15)
B(11,14,3,betternether:quartz_stained_glass:15)
B(12,14,3,betternether:quartz_stained_glass:15)
B(13,14,3,betternether:quartz_stained_glass:15)
B(14,14,3,betternether:quartz_stained_glass:15)
B(15,14,3,betternether:quartz_stained_glass:15)
B(12,14,4,betternether:quartz_stained_glass:15)
B(13,14,4,betternether:quartz_stained_glass:15)
B(14,14,4,betternether:quartz_stained_glass:15)
B(15,14,4,betternether:quartz_stained_glass:15)
B(9,15,0,betternether:quartz_stained_glass:15)
RB(10,15,0,srparasites:parasitestain:1,80,quark:crystal:1,30,srparasites:parasiterubbledense:1,100)
RB(11,15,0,srparasites:parasitestain:1,80,quark:crystal:1,30,srparasites:parasiterubbledense:1,100)
RB(12,15,0,srparasites:parasitestain:1,80,quark:crystal:1,30,srparasites:parasiterubbledense:1,100)
B(13,15,0,betternether:quartz_stained_glass:15)
B(14,15,0,betternether:quartz_stained_glass:15)
B(15,15,0,betternether:quartz_stained_glass:15)
B(9,15,1,betternether:quartz_stained_glass:15)
B(10,15,1,betternether:quartz_stained_glass:15)
B(11,15,1,betternether:quartz_stained_glass:15)
B(12,15,1,betternether:quartz_stained_glass:15)
B(13,15,1,betternether:quartz_stained_glass:15)
B(14,15,1,betternether:quartz_stained_glass:15)
B(15,15,1,betternether:quartz_stained_glass:15)
B(10,15,2,betternether:quartz_stained_glass:15)
B(11,15,2,betternether:quartz_stained_glass:15)
B(12,15,2,betternether:quartz_stained_glass:15)
B(13,15,2,betternether:quartz_stained_glass:15)
B(14,15,2,betternether:quartz_stained_glass:15)
B(15,15,2,betternether:quartz_stained_glass:15)
B(11,15,3,betternether:quartz_stained_glass:15)
B(12,15,3,betternether:quartz_stained_glass:15)
B(13,15,3,betternether:quartz_stained_glass:15)
B(14,15,3,betternether:quartz_stained_glass:15)
B(15,15,3,betternether:quartz_stained_glass:15)
B(12,15,4,betternether:quartz_stained_glass:15)
B(13,15,4,betternether:quartz_stained_glass:15)
B(14,15,4,betternether:quartz_stained_glass:15)
B(9,16,0,betternether:quartz_stained_glass:15)
RB(10,16,0,srparasites:parasitestain:1,80,quark:crystal:1,30,srparasites:parasiterubbledense:1,100)
B(11,16,0,betternether:quartz_stained_glass:15)
RB(12,16,0,srparasites:parasitestain:1,80,quark:crystal:1,30,srparasites:parasiterubbledense:1,100)
B(13,16,0,betternether:quartz_stained_glass:15)
B(14,16,0,betternether:quartz_stained_glass:15)
B(15,16,0,betternether:quartz_stained_glass:15)
B(9,16,1,betternether:quartz_stained_glass:15)
B(10,16,1,betternether:quartz_stained_glass:15)
B(11,16,1,betternether:quartz_stained_glass:15)
B(12,16,1,betternether:quartz_stained_glass:15)
B(13,16,1,betternether:quartz_stained_glass:15)
B(14,16,1,betternether:quartz_stained_glass:15)
B(15,16,1,betternether:quartz_stained_glass:15)
B(10,16,2,betternether:quartz_stained_glass:15)
B(11,16,2,betternether:quartz_stained_glass:15)
B(12,16,2,betternether:quartz_stained_glass:15)
B(13,16,2,betternether:quartz_stained_glass:15)
B(14,16,2,betternether:quartz_stained_glass:15)
B(15,16,2,betternether:quartz_stained_glass:15)
B(11,16,3,betternether:quartz_stained_glass:15)
B(12,16,3,betternether:quartz_stained_glass:15)
B(13,16,3,betternether:quartz_stained_glass:15)
B(14,16,3,betternether:quartz_stained_glass:15)
B(9,17,0,betternether:quartz_stained_glass:15)
B(10,17,0,betternether:quartz_stained_glass:15)
B(11,17,0,betternether:quartz_stained_glass:15)
B(12,17,0,betternether:quartz_stained_glass:15)
B(13,17,0,betternether:quartz_stained_glass:15)
B(14,17,0,betternether:quartz_stained_glass:15)
B(9,17,1,betternether:quartz_stained_glass:15)
B(10,17,1,betternether:quartz_stained_glass:15)
B(11,17,1,betternether:quartz_stained_glass:15)
B(12,17,1,betternether:quartz_stained_glass:15)
B(13,17,1,betternether:quartz_stained_glass:15)
B(14,17,1,betternether:quartz_stained_glass:15)
B(10,17,2,betternether:quartz_stained_glass:15)
B(11,17,2,betternether:quartz_stained_glass:15)
B(12,17,2,betternether:quartz_stained_glass:15)
B(9,18,0,betternether:quartz_stained_glass:15)
B(10,18,0,betternether:quartz_stained_glass:15)
B(11,18,0,betternether:quartz_stained_glass:15)
B(12,18,0,betternether:quartz_stained_glass:15)
B(13,18,0,betternether:quartz_stained_glass:15)
B(14,18,0,betternether:quartz_stained_glass:15)
B(9,18,1,betternether:quartz_stained_glass:15)
B(10,18,1,betternether:quartz_stained_glass:15)
B(11,18,1,betternether:quartz_stained_glass:15)
B(12,18,1,betternether:quartz_stained_glass:15)
B(10,18,2,betternether:quartz_stained_glass:15)
B(11,18,2,betternether:quartz_stained_glass:15)
B(9,19,0,betternether:quartz_stained_glass:15)
B(10,19,0,betternether:quartz_stained_glass:15)
B(11,19,0,betternether:quartz_stained_glass:15)
B(9,19,1,betternether:quartz_stained_glass:15)
B(10,19,1,betternether:quartz_stained_glass:15)
B(9,20,0,betternether:quartz_stained_glass:15)
B(10,20,0,betternether:quartz_stained_glass:15)
B(9,21,0,betternether:quartz_stained_glass:15)

