
#######################################################################
# +-----------------------------------------------------------------+ #
# |                            BO4 object                           | #
# +-----------------------------------------------------------------+ #
#######################################################################

Author: BO3 BulkEdit (by LanToaster)

Description: This Object was Created with BO3_BulkEdit

SettingsMode: WriteDisable


#######################################################################
# +-----------------------------------------------------------------+ #
# |                          Main settings                          | #
# +-----------------------------------------------------------------+ #
#######################################################################

Frequency: 100

SpawnHeight: highestBlock

UseCenterForHighestBlock: true

##############################
# Height Limits for the BO4. #
##############################

MinHeight: 0

MaxHeight: 255

InheritBO3: 

InheritBO3Rotation: NORTH

OverrideChildSettings: true

OverrideParentHeight: true

CanOverride: true

BranchFrequency: 0

BranchFrequencyGroup: 

MustBeBelowOther: false

MustBeInside: 

CannotBeInside: 

ReplacesBO3: 

MustBeInsideWorldBorders: false

CanSpawnOnWater: false

SpawnOnWaterOnly: false

SpawnUnderWater: false

SpawnAtWaterLevel: false

HeightOffset: 1

RemoveAir: true

ReplaceAbove: 

ReplaceBelow: cobblestone

ReplaceWithBiomeBlocks: true

ReplaceWithSurfaceBlock: GRASS

ReplaceWithGroundBlock: DIRT

ReplaceWithStoneBlock: STONE

SmoothRadius: 0

SmoothHeightOffset: 0

SmoothStartTop: false

SmoothStartWood: false

SmoothingSurfaceBlock: 

SmoothingGroundBlock: 

BO3Group: 

IsSpawnPoint: false

DoReplaceBlocks: true


#######################################################################
# +-----------------------------------------------------------------+ #
# |                              Blocks                             | #
# +-----------------------------------------------------------------+ #
#######################################################################

Block(-3,-1,-6,GRASS:0)
Block(-2,-1,-6,GRASS:0)
Block(-1,-1,-6,GRASS:0)
Block(0,-1,-6,GRASS:0)
Block(-4,-1,-5,GRASS:0)
Block(-3,-1,-5,GRASS:0)
Block(-2,-1,-5,GRASS:0)
Block(-1,-1,-5,GRASS:0)
Block(0,-1,-5,GRASS:0)
Block(1,-1,-5,GRASS:0)
Block(-5,-1,-4,GRASS_PATH:0)
Block(-4,-1,-4,DIRT:0)
Block(-3,-1,-4,DIRT:0)
Block(-2,-1,-4,DIRT:0)
Block(-1,-1,-4,DIRT:0)
Block(0,-1,-4,DIRT:0)
Block(1,-1,-4,GRASS:0)
Block(2,-1,-4,DIRT:0)
Block(3,-1,-4,GRASS:0)
Block(-6,-1,-3,GRASS:0)
Block(-5,-1,-3,GRASS:0)
Block(-4,-1,-3,GRASS_PATH:0)
Block(-3,-1,-3,GRASS_PATH:0)
Block(-2,-1,-3,GRASS_PATH:0)
Block(-1,-1,-3,GRASS_PATH:0)
Block(0,-1,-3,GRASS:0)
Block(1,-1,-3,GRASS:0)
Block(2,-1,-3,DIRT:0)
Block(3,-1,-3,GRASS:0)
Block(4,-1,-3,DIRT:0)
Block(-6,-1,-2,GRASS:0)
Block(-5,-1,-2,GRASS:0)
Block(-4,-1,-2,GRASS:0)
Block(-3,-1,-2,GRASS_PATH:0)
Block(-2,-1,-2,GRASS:0)
Block(-1,-1,-2,GRASS:0)
Block(0,-1,-2,GRASS:0)
Block(1,-1,-2,DIRT:0)
Block(2,-1,-2,DIRT:0)
Block(3,-1,-2,DIRT:0)
Block(4,-1,-2,DIRT:0)
Block(5,-1,-2,GRASS:0)
Block(-6,-1,-1,GRASS:0)
Block(-5,-1,-1,GRASS:0)
Block(-4,-1,-1,GRASS:0)
Block(-3,-1,-1,GRASS:0)
Block(-2,-1,-1,GRASS_PATH:0)
Block(-1,-1,-1,GRASS:0)
Block(0,-1,-1,GRASS:0)
Block(1,-1,-1,GRASS_PATH:0)
Block(2,-1,-1,DIRT:0)
Block(3,-1,-1,DIRT:0)
Block(4,-1,-1,DIRT:0)
Block(5,-1,-1,GRASS:0)
Block(-6,-1,0,GRASS:0)
Block(-5,-1,0,GRASS:0)
Block(-4,-1,0,DIRT:0)
Block(-3,-1,0,DIRT:0)
Block(-2,-1,0,DIRT:0)
Block(-1,-1,0,DIRT:0)
Block(0,-1,0,GRASS_PATH:0)
Block(1,-1,0,GRASS:0)
Block(2,-1,0,DIRT:0)
Block(3,-1,0,DIRT:0)
Block(4,-1,0,DIRT:0)
Block(5,-1,0,GRASS:0)
Block(-5,-1,1,GRASS:0)
Block(-4,-1,1,GRASS:0)
Block(-3,-1,1,GRASS:0)
Block(-2,-1,1,GRASS_PATH:0)
Block(-1,-1,1,GRASS_PATH:0)
Block(0,-1,1,GRASS_PATH:0)
Block(1,-1,1,DIRT:0)
Block(2,-1,1,GRASS:0)
Block(3,-1,1,DIRT:0)
Block(4,-1,1,DIRT:0)
Block(5,-1,1,GRASS:0)
Block(-5,-1,2,GRASS:0)
Block(-4,-1,2,GRASS_PATH:0)
Block(-3,-1,2,GRASS_PATH:0)
Block(-2,-1,2,GRASS_PATH:0)
Block(-1,-1,2,GRASS_PATH:0)
Block(0,-1,2,GRASS:0)
Block(1,-1,2,GRASS:0)
Block(2,-1,2,GRASS_PATH:0)
Block(3,-1,2,DIRT:0)
Block(4,-1,2,DIRT:0)
Block(5,-1,2,GRASS:0)
Block(-5,-1,3,GRASS_PATH:0)
Block(-4,-1,3,GRASS_PATH:0)
Block(-3,-1,3,GRASS_PATH:0)
Block(-2,-1,3,GRASS:0)
Block(-1,-1,3,GRASS:0)
Block(0,-1,3,GRASS:0)
Block(1,-1,3,GRASS_PATH:0)
Block(2,-1,3,GRASS_PATH:0)
Block(3,-1,3,DIRT:0)
Block(4,-1,3,GRASS:0)
Block(-4,-1,4,GRASS_PATH:0)
Block(-3,-1,4,DIRT:0)
Block(-2,-1,4,DIRT:0)
Block(-1,-1,4,DIRT:0)
Block(0,-1,4,DIRT:0)
Block(1,-1,4,GRASS_PATH:0)
Block(2,-1,4,GRASS:0)
Block(3,-1,4,GRASS:0)
Block(-3,-1,5,GRASS:0)
Block(-2,-1,5,GRASS:0)
Block(-1,-1,5,GRASS:0)
Block(0,-1,5,GRASS:0)
Block(1,-1,5,GRASS:0)
Block(2,-1,5,GRASS:0)
Block(3,-1,5,DIRT:0)
Block(-1,-1,6,GRASS:0)
Block(1,-1,6,GRASS:0)
Block(-4,0,-4,LOG:7)
Block(-3,0,-4,LOG:7)
Block(-2,0,-4,LOG:7)
Block(-1,0,-4,LOG:7)
Block(0,0,-4,LOG:7)
Block(2,0,-4,LOG:11)
Block(1,0,-3,RAILS:2)
Block(2,0,-3,LOG:11)
Block(4,0,-3,LOG:11)
Block(-4,0,-2,JUNGLE_FENCE:0)
Block(0,0,-2,JUNGLE_FENCE:0)
Block(1,0,-2,AIR)
Block(2,0,-2,LOG:11)
Block(3,0,-2,LOG:11)
Block(4,0,-2,LOG:11)
Block(2,0,-1,LOG:11)
Block(3,0,-1,LOG:11)
Block(4,0,-1,LOG:11)
Block(-4,0,0,LOG:7)
Block(-3,0,0,LOG:7)
Block(-2,0,0,LOG:7)
Block(-1,0,0,LOG:7)
Block(2,0,0,LOG:11)
Block(3,0,0,LOG:11)
Block(4,0,0,LOG:11)
Block(1,0,1,AIR)
Block(3,0,1,LOG:11)
Block(4,0,1,LOG:11)
Block(5,0,1,RAILS:3)
Block(0,0,2,JUNGLE_FENCE:0)
Block(3,0,2,LOG:11)
Block(4,0,2,LOG:11)
Block(3,0,3,LOG:11)
Block(-3,0,4,LOG:7)
Block(-2,0,4,LOG:7)
Block(-1,0,4,LOG:7)
Block(0,0,4,LOG:7)
Block(3,0,5,AIR)
Block(-2,1,-6,WOOD_STEP:11)
Block(-2,1,-5,JUNGLE_WOOD_STAIRS:6)
Block(-3,1,-4,WOOD_STEP:11)
Block(-2,1,-4,WOOD_DOUBLE_STEP:3)
Block(-1,1,-4,WOOD_STEP:11)
Block(-3,1,-3,WOOD_STEP:11)
Block(-2,1,-3,WOOD_DOUBLE_STEP:3)
Block(-1,1,-3,WOOD_STEP:11)
Block(2,1,-3,RAILS:2)
Block(3,1,-3,LOG:11)
Block(-4,1,-2,JUNGLE_FENCE:0)
Block(-3,1,-2,JUNGLE_WOOD_STAIRS:4)
Block(-2,1,-2,WOOD_STEP:3)
Block(-1,1,-2,JUNGLE_WOOD_STAIRS:5)
Block(0,1,-2,JUNGLE_FENCE:0)
Block(3,1,-2,LOG:11)
Block(-3,1,-1,JUNGLE_WOOD_STAIRS:4)
Block(-2,1,-1,WOOD_STEP:3)
Block(-1,1,-1,JUNGLE_WOOD_STAIRS:5)
Block(3,1,-1,LOG:11)
Block(-4,1,0,JUNGLE_FENCE:0)
Block(-3,1,0,JUNGLE_WOOD_STAIRS:4)
Block(-2,1,0,WOOD_STEP:3)
Block(-1,1,0,JUNGLE_WOOD_STAIRS:5)
Block(3,1,0,LOG:11)
Block(-3,1,1,JUNGLE_WOOD_STAIRS:4)
Block(-2,1,1,WOOD_STEP:3)
Block(-1,1,1,JUNGLE_WOOD_STAIRS:5)
Block(3,1,1,LOG:11)
Block(4,1,1,RAILS:3)
Block(-3,1,2,WOOD_STEP:11)
Block(-2,1,2,WOOD_STEP:3)
Block(-1,1,2,JUNGLE_WOOD_STAIRS:5)
Block(0,1,2,JUNGLE_FENCE:0)
Block(-3,1,3,WOOD_STEP:11)
Block(-2,1,3,WOOD_DOUBLE_STEP:3)
Block(-1,1,3,WOOD_STEP:11)
Block(-3,1,4,WOOD_STEP:11)
Block(-2,1,4,WOOD_DOUBLE_STEP:3)
Block(-1,1,4,WOOD_STEP:11)
Block(-2,1,5,JUNGLE_WOOD_STAIRS:7)
Block(-2,1,6,WOOD_STEP:11)
Block(-2,2,-7,WOOD_DOUBLE_STEP:3)
Block(-2,2,-6,WOOD_STEP:3)
Block(-3,2,-5,WOOD_STEP:3)
Block(-2,2,-5,WOOD_STEP:3)
Block(-1,2,-5,WOOD_STEP:3)
Block(-3,2,-4,WOOD_STEP:3)
Block(-1,2,-4,WOOD_STEP:3)
Block(-4,2,-3,WOOD_DOUBLE_STEP:3)
Block(-3,2,-3,WOOD_STEP:3)
Block(-1,2,-3,WOOD_STEP:3)
Block(0,2,-3,WOOD_DOUBLE_STEP:3)
Block(3,2,-3,RAILS:1)
Block(-4,2,-2,WOOD_STEP:3)
Block(0,2,-2,WOOD_STEP:3)
Block(-4,2,-1,WOOD_DOUBLE_STEP:3)
Block(0,2,-1,WOOD_DOUBLE_STEP:3)
Block(-4,2,0,WOOD_STEP:3)
Block(0,2,0,WOOD_STEP:3)
Block(-4,2,1,WOOD_DOUBLE_STEP:3)
Block(0,2,1,WOOD_DOUBLE_STEP:3)
Block(3,2,1,RAILS:1)
Block(-4,2,2,WOOD_STEP:3)
Block(0,2,2,WOOD_STEP:3)
Block(-4,2,3,WOOD_DOUBLE_STEP:3)
Block(-3,2,3,WOOD_STEP:3)
Block(-1,2,3,WOOD_STEP:3)
Block(0,2,3,WOOD_DOUBLE_STEP:3)
Block(-3,2,4,WOOD_STEP:3)
Block(-1,2,4,WOOD_STEP:3)
Block(-3,2,5,WOOD_STEP:3)
Block(-2,2,5,WOOD_STEP:3)
Block(-1,2,5,WOOD_STEP:3)
Block(-2,2,6,WOOD_STEP:3)
Block(-2,2,7,WOOD_DOUBLE_STEP:3)
Block(-2,3,-7,JUNGLE_FENCE:0)
Block(-2,3,7,JUNGLE_FENCE:0)

#######################################################################
# +-----------------------------------------------------------------+ #
# |                             Branches                            | #
# +-----------------------------------------------------------------+ #
#######################################################################


#######################################################################
# +-----------------------------------------------------------------+ #
# |                             Entities                            | #
# +-----------------------------------------------------------------+ #
#######################################################################

Entity(1,0,-2,minecraft:villager,1,../../NBT/entities/tribalboatbuilder.txt)

#######################################################################
# +-----------------------------------------------------------------+ #
# |                            Particles                            | #
# +-----------------------------------------------------------------+ #
#######################################################################


#######################################################################
# +-----------------------------------------------------------------+ #
# |                             Spawners                            | #
# +-----------------------------------------------------------------+ #
#######################################################################


#######################################################################
# +-----------------------------------------------------------------+ #
# |                             ModData                             | #
# +-----------------------------------------------------------------+ #
#######################################################################

