
#######################################################################
# +-----------------------------------------------------------------+ #
# |                            BO3 object                           | #
# +-----------------------------------------------------------------+ #
#######################################################################

Author: NLBlackHeavenNL

Description: No description given

Version: 3

SettingsMode: WriteWithoutComments


#######################################################################
# +-----------------------------------------------------------------+ #
# |                          Main settings                          | #
# +-----------------------------------------------------------------+ #
#######################################################################

Tree: true

Frequency: 1

Rarity: 1.0

RotateRandomly: false

SpawnHeight: highestSolidBlock

SpawnHeightOffset: -1

SpawnHeightVariance: 0

##############################
# Height Limits for the BO3. #
##############################

MinHeight: 0

MaxHeight: 255

######################
# Extrusion settings #
######################

ExtrudeMode: None

ExtrudeThroughBlocks: AIR

MaxBranchDepth: 10

ExcludedBiomes: All


#######################################################################
# +-----------------------------------------------------------------+ #
# |                      Source block settings                      | #
# +-----------------------------------------------------------------+ #
#######################################################################

SourceBlocks: AIR,GRASS,DIRT,biomesoplenty:dirt,biomesoplenty:grass

MaxPercentageOutsideSourceBlock: 0

OutsideSourceBlock: placeAnyway

DoReplaceBlocks: true

IsOTGPlus: false


#######################################################################
# +-----------------------------------------------------------------+ #
# |                              Blocks                             | #
# +-----------------------------------------------------------------+ #
#######################################################################

Block(-1,12,0,dynamictreesbop:leaves2:7)
Block(-1,12,2,dynamictreesbop:leaves2:7)
Block(-1,13,0,dynamictreesbop:leaves2:6)
Block(-1,13,1,dynamictreesbop:leaves2:7)
Block(-1,13,2,dynamictreesbop:leaves2:6)
Block(0,0,1,dynamictrees:rootydirtspecies:0,DT_BPRedMaple_Tall_23/1-species_tile_entity.nbt)
Block(0,1,1,dynamictrees:oakbranch:7)
Block(0,2,1,dynamictrees:oakbranch:7)
Block(0,3,1,dynamictrees:oakbranch:7)
Block(0,4,1,dynamictrees:oakbranch:6)
Block(0,11,0,dynamictreesbop:leaves2:5)
Block(0,11,1,dynamictreesbop:leaves2:4)
Block(0,11,2,dynamictreesbop:leaves2:4)
Block(0,12,-1,dynamictreesbop:leaves2:5)
Block(0,12,0,dynamictreesbop:leaves2:6)
Block(0,12,1,dynamictreesbop:leaves2:7)
Block(0,12,2,dynamictreesbop:leaves2:6)
Block(0,12,3,dynamictreesbop:leaves2:4)
Block(0,13,-1,dynamictreesbop:leaves2:4)
Block(0,13,0,dynamictreesbop:leaves2:5)
Block(0,13,1,dynamictreesbop:leaves2:6)
Block(0,13,2,dynamictreesbop:leaves2:5)
Block(0,13,3,dynamictreesbop:leaves2:4)
Block(0,14,0,dynamictreesbop:leaves2:4)
Block(0,14,1,dynamictreesbop:leaves2:4)
Block(0,14,2,dynamictreesbop:leaves2:4)
Block(1,4,1,dynamictrees:oakbranch:4)
Block(1,5,1,dynamictrees:oakbranch:3)
Block(1,6,1,dynamictrees:oakbranch:3)
Block(1,7,1,dynamictrees:oakbranch:3)
Block(1,8,1,dynamictrees:oakbranch:1)
Block(1,9,1,dynamictrees:oakbranch:1)
Block(1,10,1,dynamictrees:oakbranch:1)
Block(1,10,3,dynamictreesbop:leaves2:4)
Block(1,11,-1,dynamictreesbop:leaves2:7)
Block(1,11,0,dynamictreesbop:leaves2:6)
Block(1,11,1,dynamictrees:oakbranch:1)
Block(1,11,2,dynamictreesbop:leaves2:4)
Block(1,12,-1,dynamictreesbop:leaves2:6)
Block(1,12,0,dynamictreesbop:leaves2:7)
Block(1,12,1,dynamictrees:oakbranch)
Block(1,12,2,dynamictreesbop:leaves2:7)
Block(1,12,3,dynamictreesbop:leaves2:4)
Block(1,13,-1,dynamictreesbop:leaves2:5)
Block(1,13,0,dynamictreesbop:leaves2:6)
Block(1,13,1,dynamictreesbop:leaves2:7)
Block(1,13,2,dynamictreesbop:leaves2:6)
Block(1,13,3,dynamictreesbop:leaves2:4)
Block(1,14,0,dynamictreesbop:leaves2:4)
Block(1,14,1,dynamictreesbop:leaves2:4)
Block(1,14,2,dynamictreesbop:leaves2:4)
Block(2,10,-1,dynamictreesbop:leaves2:7)
Block(2,10,1,dynamictrees:oakbranch)
Block(2,10,3,dynamictreesbop:leaves2:4)
Block(2,11,-1,dynamictreesbop:leaves2:6)
Block(2,11,0,dynamictreesbop:leaves2:5)
Block(2,11,1,dynamictreesbop:leaves2:7)
Block(2,11,2,dynamictreesbop:leaves2:4)
Block(2,12,-1,dynamictreesbop:leaves2:5)
Block(2,12,0,dynamictreesbop:leaves2:6)
Block(2,12,1,dynamictreesbop:leaves2:7)
Block(2,12,2,dynamictreesbop:leaves2:6)
Block(2,12,3,dynamictreesbop:leaves2:4)
Block(2,13,-1,dynamictreesbop:leaves2:4)
Block(2,13,0,dynamictreesbop:leaves2:5)
Block(2,13,1,dynamictreesbop:leaves2:6)
Block(2,13,2,dynamictreesbop:leaves2:5)
Block(2,13,3,dynamictreesbop:leaves2:4)
Block(2,14,0,dynamictreesbop:leaves2:4)
Block(2,14,1,dynamictreesbop:leaves2:4)
Block(2,14,2,dynamictreesbop:leaves2:4)
Block(3,9,2,dynamictreesbop:leaves2:4)
Block(3,10,-1,dynamictreesbop:leaves2:4)
Block(3,10,0,dynamictreesbop:leaves2:4)
Block(3,10,1,dynamictreesbop:leaves2:7)
Block(3,10,2,dynamictreesbop:leaves2:4)
Block(3,11,-1,dynamictreesbop:leaves2:4)
Block(3,11,0,dynamictreesbop:leaves2:4)
Block(3,11,1,dynamictreesbop:leaves2:6)
Block(3,11,2,dynamictreesbop:leaves2:4)
Block(3,12,0,dynamictreesbop:leaves2:4)
Block(3,12,1,dynamictreesbop:leaves2:4)
Block(3,12,2,dynamictreesbop:leaves2:4)
Block(3,13,0,dynamictreesbop:leaves2:4)
Block(3,13,1,dynamictreesbop:leaves2:4)
Block(3,13,2,dynamictreesbop:leaves2:4)
Block(4,10,1,dynamictreesbop:leaves2:4)
Block(4,11,1,dynamictreesbop:leaves2:4)

#######################################################################
# +-----------------------------------------------------------------+ #
# |                            BO3 checks                           | #
# +-----------------------------------------------------------------+ #
#######################################################################

BlockCheck(0,-1,1,GRASS,DIRT,biomesoplenty:grass,biomesoplenty:dirt)

#######################################################################
# +-----------------------------------------------------------------+ #
# |                             Branches                            | #
# +-----------------------------------------------------------------+ #
#######################################################################


#######################################################################
# +-----------------------------------------------------------------+ #
# |                             Entities                            | #
# +-----------------------------------------------------------------+ #
#######################################################################


#######################################################################
# +-----------------------------------------------------------------+ #
# |                            Particles                            | #
# +-----------------------------------------------------------------+ #
#######################################################################


#######################################################################
# +-----------------------------------------------------------------+ #
# |                             Spawners                            | #
# +-----------------------------------------------------------------+ #
#######################################################################


#######################################################################
# +-----------------------------------------------------------------+ #
# |                             ModData                             | #
# +-----------------------------------------------------------------+ #
#######################################################################

