Author: BO3 BulkEdit (by LanToaster)
Description: This Object was Created with BO3_BulkEdit
SettingsMode: WriteDisable
Frequency: 100
SpawnHeight: highestBlock
UseCenterForHighestBlock: true
MinHeight: 0
MaxHeight: 255
InheritBO3: 
InheritBO3Rotation: NORTH
OverrideChildSettings: true
OverrideParentHeight: false
CanOverride: true
BranchFrequency: 0
BranchFrequencyGroup: 
MustBeBelowOther: false
MustBeInside: 
CannotBeInside: 
ReplacesBO3: 
MustBeInsideWorldBorders: false
CanSpawnOnWater: false
SpawnOnWaterOnly: false
SpawnUnderWater: false
SpawnAtWaterLevel: false
HeightOffset: 0
RemoveAir: true
ReplaceAbove: 
ReplaceBelow: cobblestone
ReplaceWithBiomeBlocks: true
ReplaceWithSurfaceBlock: GRASS
ReplaceWithGroundBlock: DIRT
ReplaceWithStoneBlock: STONE
SmoothRadius: 0
SmoothHeightOffset: 0
SmoothStartTop: false
SmoothStartWood: false
SmoothingSurfaceBlock: 
SmoothingGroundBlock: 
BO3Group: 
IsSpawnPoint: false
DoReplaceBlocks: true
Block(-5,-1,-7,LOG:3)
Block(-2,-1,-7,COBBLESTONE)
Block(-1,-1,-7,LOG:3)
Block(0,-1,-7,GRAVEL)
Block(1,-1,-7,GRASS_PATH)
Block(2,-1,-7,LOG:3)
Block(3,-1,-7,COBBLESTONE)
Block(4,-1,-7,COBBLESTONE)
Block(6,-1,-7,LOG:3)
Block(-5,-1,-6,COBBLESTONE)
Block(-4,-1,-6,GRASS_PATH)
Block(-3,-1,-6,COBBLESTONE)
Block(-2,-1,-6,COBBLESTONE)
Block(-1,-1,-6,HAY_BLOCK:4)
Block(0,-1,-6,GRASS_PATH)
Block(1,-1,-6,HAY_BLOCK:8)
Block(2,-1,-6,HAY_BLOCK:4)
Block(3,-1,-6,COBBLESTONE)
Block(4,-1,-6,COBBLESTONE)
Block(5,-1,-6,COBBLESTONE)
Block(-6,-1,-5,COBBLESTONE)
Block(-5,-1,-5,COBBLESTONE)
Block(-4,-1,-5,GRAVEL)
Block(-3,-1,-5,HAY_BLOCK)
Block(-2,-1,-5,HAY_BLOCK)
Block(-1,-1,-5,HAY_BLOCK:8)
Block(0,-1,-5,GRASS_PATH)
Block(1,-1,-5,HAY_BLOCK:8)
Block(2,-1,-5,HAY_BLOCK)
Block(3,-1,-5,HAY_BLOCK:4)
Block(4,-1,-5,COBBLESTONE)
Block(5,-1,-5,GRASS_PATH)
Block(-6,-1,-4,COBBLESTONE)
Block(-5,-1,-4,COBBLESTONE)
Block(-4,-1,-4,HAY_BLOCK:8)
Block(-3,-1,-4,LOG:3)
Block(-2,-1,-4,COBBLESTONE)
Block(-1,-1,-4,GRAVEL)
Block(0,-1,-4,COBBLESTONE)
Block(1,-1,-4,COBBLESTONE)
Block(2,-1,-4,HAY_BLOCK:8)
Block(3,-1,-4,HAY_BLOCK)
Block(4,-1,-4,LOG:3)
Block(5,-1,-4,GRASS_PATH)
Block(-8,-1,-3,LOG:3)
Block(-6,-1,-3,COBBLESTONE)
Block(-5,-1,-3,LOG:3)
Block(-4,-1,-3,HAY_BLOCK)
Block(-3,-1,-3,COBBLESTONE)
Block(-2,-1,-3,minecraft:red_glazed_terracotta:3)
Block(-1,-1,-3,minecraft:black_glazed_terracotta:1)
Block(0,-1,-3,minecraft:black_glazed_terracotta:3)
Block(1,-1,-3,minecraft:black_glazed_terracotta)
Block(2,-1,-3,minecraft:black_glazed_terracotta:0)
Block(3,-1,-3,minecraft:red_glazed_terracotta:0)
Block(4,-1,-3,GRAVEL)
Block(5,-1,-3,GRASS_PATH)
Block(-6,-1,-2,GRASS_PATH)
Block(-5,-1,-2,GRAVEL)
Block(-4,-1,-2,HAY_BLOCK:4)
Block(-3,-1,-2,COBBLESTONE)
Block(-2,-1,-2,minecraft:black_glazed_terracotta:3)
Block(-1,-1,-2,COBBLESTONE)
Block(0,-1,-2,COBBLESTONE)
Block(1,-1,-2,COBBLESTONE)
Block(2,-1,-2,COBBLESTONE)
Block(3,-1,-2,minecraft:black_glazed_terracotta)
Block(4,-1,-2,GRASS_PATH)
Block(5,-1,-2,GRASS_PATH)
Block(6,-1,-2,GRASS_PATH)
Block(7,-1,-2,LOG:3)
Block(-8,-1,-1,GRASS_PATH)
Block(-7,-1,-1,GRASS_PATH)
Block(-6,-1,-1,GRASS_PATH)
Block(-5,-1,-1,GRASS_PATH)
Block(-4,-1,-1,COBBLESTONE)
Block(-3,-1,-1,COBBLESTONE)
Block(-2,-1,-1,minecraft:black_glazed_terracotta:1)
Block(-1,-1,-1,COBBLESTONE)
Block(0,-1,-1,MAGMA)
Block(1,-1,-1,MAGMA)
Block(2,-1,-1,COBBLESTONE)
Block(3,-1,-1,minecraft:black_glazed_terracotta:0)
Block(4,-1,-1,COBBLESTONE)
Block(5,-1,-1,GRASS_PATH)
Block(6,-1,-1,GRASS_PATH)
Block(-8,-1,0,GRASS_PATH)
Block(-7,-1,0,GRASS_PATH)
Block(-6,-1,0,GRASS_PATH)
Block(-5,-1,0,GRASS_PATH)
Block(-4,-1,0,HAY_BLOCK:4)
Block(-3,-1,0,COBBLESTONE)
Block(-2,-1,0,minecraft:black_glazed_terracotta)
Block(-1,-1,0,COBBLESTONE)
Block(0,-1,0,MAGMA)
Block(1,-1,0,MAGMA)
Block(2,-1,0,COBBLESTONE)
Block(3,-1,0,minecraft:black_glazed_terracotta:3)
Block(4,-1,0,HAY_BLOCK)
Block(5,-1,0,GRASS_PATH)
Block(-7,-1,1,GRASS_PATH)
Block(-5,-1,1,GRASS_PATH)
Block(-4,-1,1,HAY_BLOCK)
Block(-3,-1,1,COBBLESTONE)
Block(-2,-1,1,minecraft:black_glazed_terracotta:0)
Block(-1,-1,1,COBBLESTONE)
Block(0,-1,1,COBBLESTONE)
Block(1,-1,1,COBBLESTONE)
Block(2,-1,1,COBBLESTONE)
Block(3,-1,1,minecraft:black_glazed_terracotta:1)
Block(4,-1,1,HAY_BLOCK:4)
Block(5,-1,1,GRASS_PATH)
Block(7,-1,1,LOG:3)
Block(-8,-1,2,LOG:3)
Block(-6,-1,2,GRASS_PATH)
Block(-5,-1,2,LOG:3)
Block(-4,-1,2,HAY_BLOCK:4)
Block(-3,-1,2,HAY_BLOCK)
Block(-2,-1,2,minecraft:red_glazed_terracotta)
Block(-1,-1,2,minecraft:black_glazed_terracotta)
Block(0,-1,2,minecraft:black_glazed_terracotta:0)
Block(1,-1,2,minecraft:black_glazed_terracotta:1)
Block(2,-1,2,minecraft:black_glazed_terracotta:3)
Block(3,-1,2,minecraft:red_glazed_terracotta:1)
Block(4,-1,2,HAY_BLOCK)
Block(5,-1,2,GRASS_PATH)
Block(-6,-1,3,COBBLESTONE)
Block(-5,-1,3,COBBLESTONE)
Block(-4,-1,3,DIRT)
Block(-3,-1,3,LOG:3)
Block(-2,-1,3,HAY_BLOCK)
Block(-1,-1,3,HAY_BLOCK:4)
Block(0,-1,3,GRASS_PATH)
Block(1,-1,3,GRAVEL)
Block(2,-1,3,COBBLESTONE)
Block(3,-1,3,COBBLESTONE)
Block(4,-1,3,LOG:3)
Block(5,-1,3,GRASS_PATH)
Block(-5,-1,4,COBBLESTONE)
Block(-4,-1,4,COBBLESTONE)
Block(-3,-1,4,COBBLESTONE)
Block(-2,-1,4,GRASS_PATH)
Block(-1,-1,4,GRASS_PATH)
Block(0,-1,4,GRASS_PATH)
Block(1,-1,4,COBBLESTONE)
Block(2,-1,4,COBBLESTONE)
Block(3,-1,4,COBBLESTONE)
Block(4,-1,4,COBBLESTONE)
Block(5,-1,4,GRASS_PATH)
Block(2,-1,5,COBBLESTONE)
Block(3,-1,5,COBBLESTONE)
Block(4,-1,5,COBBLESTONE)
Block(5,-1,5,COBBLESTONE)
Block(-5,-1,6,LOG:3)
Block(-1,-1,6,LOG:3)
Block(2,-1,6,LOG:3)
Block(3,-1,6,COBBLESTONE)
Block(4,-1,6,COBBLESTONE)
Block(6,-1,6,LOG:3)
Block(-5,0,-7,LOG:3)
Block(-1,0,-7,LOG:3)
Block(2,0,-7,LOG:3)
Block(3,0,-7,COBBLESTONE)
RandomBlock(4,0,-7,FLOWER_POT,../../NBT/pots/JunglePot01.nbt,10,FLOWER_POT,../../NBT/pots/JunglePot02.nbt,10,FLOWER_POT,../../NBT/pots/JunglePot03.nbt,10,FLOWER_POT,../../NBT/pots/JunglePot04.nbt,10,FLOWER_POT,../../NBT/pots/JunglePot05.nbt,10,FLOWER_POT,../../NBT/pots/JunglePot06.nbt,10,FLOWER_POT,../../NBT/pots/JunglePot07.nbt,10,FLOWER_POT,../../NBT/pots/JunglePot08.nbt,100)
Block(6,0,-7,LOG:3)
RandomBlock(-3,0,-6,FLOWER_POT,../../NBT/pots/JunglePot01.nbt,10,FLOWER_POT,../../NBT/pots/JunglePot02.nbt,10,FLOWER_POT,../../NBT/pots/JunglePot03.nbt,10,FLOWER_POT,../../NBT/pots/JunglePot04.nbt,10,FLOWER_POT,../../NBT/pots/JunglePot05.nbt,10,FLOWER_POT,../../NBT/pots/JunglePot06.nbt,10,FLOWER_POT,../../NBT/pots/JunglePot07.nbt,10,FLOWER_POT,../../NBT/pots/JunglePot08.nbt,100)
Block(-2,0,-6,COBBLESTONE)
Block(2,0,-6,HAY_BLOCK)
Block(3,0,-6,COBBLESTONE)
Block(4,0,-6,COBBLESTONE)
Block(-5,0,-5,COBBLESTONE)
Block(-2,0,-5,AIR)
Block(1,0,-5,AIR)
RandomBlock(4,0,-5,FLOWER_POT,../../NBT/pots/JunglePot01.nbt,10,FLOWER_POT,../../NBT/pots/JunglePot02.nbt,10,FLOWER_POT,../../NBT/pots/JunglePot03.nbt,10,FLOWER_POT,../../NBT/pots/JunglePot04.nbt,10,FLOWER_POT,../../NBT/pots/JunglePot05.nbt,10,FLOWER_POT,../../NBT/pots/JunglePot06.nbt,10,FLOWER_POT,../../NBT/pots/JunglePot07.nbt,10,FLOWER_POT,../../NBT/pots/JunglePot08.nbt,100)
Block(7,0,-5,WOOD_STAIRS:2)
Block(-6,0,-4,COBBLESTONE)
Block(-5,0,-4,COBBLESTONE)
Block(-3,0,-4,LOG:3)
RandomBlock(-2,0,-4,FLOWER_POT,../../NBT/pots/JunglePot01.nbt,10,FLOWER_POT,../../NBT/pots/JunglePot02.nbt,10,FLOWER_POT,../../NBT/pots/JunglePot03.nbt,10,FLOWER_POT,../../NBT/pots/JunglePot04.nbt,10,FLOWER_POT,../../NBT/pots/JunglePot05.nbt,10,FLOWER_POT,../../NBT/pots/JunglePot06.nbt,10,FLOWER_POT,../../NBT/pots/JunglePot07.nbt,10,FLOWER_POT,../../NBT/pots/JunglePot08.nbt,100)
Block(3,0,-4,AIR)
Block(4,0,-4,LOG:3)
Block(7,0,-4,WOOD_STAIRS:7)
Block(-8,0,-3,JUNGLE_FENCE)
RandomBlock(-6,0,-3,FLOWER_POT,../../NBT/pots/JunglePot01.nbt,10,FLOWER_POT,../../NBT/pots/JunglePot02.nbt,10,FLOWER_POT,../../NBT/pots/JunglePot03.nbt,10,FLOWER_POT,../../NBT/pots/JunglePot04.nbt,10,FLOWER_POT,../../NBT/pots/JunglePot05.nbt,10,FLOWER_POT,../../NBT/pots/JunglePot06.nbt,10,FLOWER_POT,../../NBT/pots/JunglePot07.nbt,10,FLOWER_POT,../../NBT/pots/JunglePot08.nbt,100)
Block(-5,0,-3,LOG:3)
Block(-3,0,-3,JUNGLE_FENCE)
Block(4,0,-3,JUNGLE_FENCE)
Block(-3,0,-2,AIR)
Block(-1,0,-2,COBBLE_WALL)
Block(0,0,-2,STEP:3)
Block(1,0,-2,STEP:3)
Block(2,0,-2,COBBLE_WALL)
Block(7,0,-2,LOG:3)
Block(-1,0,-1,STEP:3)
Block(2,0,-1,STEP:3)
RandomBlock(4,0,-1,FLOWER_POT,../../NBT/pots/JunglePot01.nbt,10,FLOWER_POT,../../NBT/pots/JunglePot02.nbt,10,FLOWER_POT,../../NBT/pots/JunglePot03.nbt,10,FLOWER_POT,../../NBT/pots/JunglePot04.nbt,10,FLOWER_POT,../../NBT/pots/JunglePot05.nbt,10,FLOWER_POT,../../NBT/pots/JunglePot06.nbt,10,FLOWER_POT,../../NBT/pots/JunglePot07.nbt,10,FLOWER_POT,../../NBT/pots/JunglePot08.nbt,100)
Block(-1,0,0,STEP:3)
Block(2,0,0,STEP:3)
Block(4,0,0,AIR)
Block(-6,0,1,AIR)
RandomBlock(-3,0,1,FLOWER_POT,../../NBT/pots/JunglePot01.nbt,10,FLOWER_POT,../../NBT/pots/JunglePot02.nbt,10,FLOWER_POT,../../NBT/pots/JunglePot03.nbt,10,FLOWER_POT,../../NBT/pots/JunglePot04.nbt,10,FLOWER_POT,../../NBT/pots/JunglePot05.nbt,10,FLOWER_POT,../../NBT/pots/JunglePot06.nbt,10,FLOWER_POT,../../NBT/pots/JunglePot07.nbt,10,FLOWER_POT,../../NBT/pots/JunglePot08.nbt,100)
Block(-1,0,1,COBBLE_WALL)
Block(0,0,1,STEP:3)
Block(1,0,1,STEP:3)
Block(2,0,1,COBBLE_WALL)
Block(3,0,1,AIR)
Block(7,0,1,LOG:3)
Block(-8,0,2,JUNGLE_FENCE)
Block(-5,0,2,LOG:3)
Block(-3,0,2,JUNGLE_FENCE)
Block(-1,0,2,AIR)
Block(4,0,2,JUNGLE_FENCE)
Block(-5,0,3,COBBLESTONE)
Block(-4,0,3,COBBLESTONE)
Block(-3,0,3,LOG:3)
Block(3,0,3,COBBLESTONE)
Block(4,0,3,LOG:3)
Block(7,0,3,WOOD_STAIRS:6)
RandomBlock(-4,0,4,FLOWER_POT,../../NBT/pots/JunglePot01.nbt,10,FLOWER_POT,../../NBT/pots/JunglePot02.nbt,10,FLOWER_POT,../../NBT/pots/JunglePot03.nbt,10,FLOWER_POT,../../NBT/pots/JunglePot04.nbt,10,FLOWER_POT,../../NBT/pots/JunglePot05.nbt,10,FLOWER_POT,../../NBT/pots/JunglePot06.nbt,10,FLOWER_POT,../../NBT/pots/JunglePot07.nbt,10,FLOWER_POT,../../NBT/pots/JunglePot08.nbt,100)
Block(1,0,4,AIR)
Block(2,0,4,COBBLESTONE)
Block(3,0,4,COBBLESTONE)
Block(4,0,4,COBBLESTONE)
Block(7,0,4,WOOD_STAIRS:3)
RandomBlock(2,0,5,FLOWER_POT,../../NBT/pots/JunglePot01.nbt,10,FLOWER_POT,../../NBT/pots/JunglePot02.nbt,10,FLOWER_POT,../../NBT/pots/JunglePot03.nbt,10,FLOWER_POT,../../NBT/pots/JunglePot04.nbt,10,FLOWER_POT,../../NBT/pots/JunglePot05.nbt,10,FLOWER_POT,../../NBT/pots/JunglePot06.nbt,10,FLOWER_POT,../../NBT/pots/JunglePot07.nbt,10,FLOWER_POT,../../NBT/pots/JunglePot08.nbt,100)
Block(3,0,5,COBBLESTONE)
Block(-5,0,6,LOG:3)
Block(-1,0,6,LOG:3)
Block(2,0,6,LOG:3)
Block(6,0,6,LOG:3)
RandomBlock(-5,1,-8,WALL_BANNER,../../NBT/banners/JungleBanner01.nbt,8,WALL_BANNER,../../NBT/banners/JungleBanner02.nbt,8,WALL_BANNER,../../NBT/banners/JungleBanner03.nbt,8,WALL_BANNER,../../NBT/banners/JungleBanner04.nbt,8,WALL_BANNER,../../NBT/banners/JungleBanner05.nbt,8,WALL_BANNER,../../NBT/banners/JungleBanner06.nbt,8,WALL_BANNER,../../NBT/banners/JungleBanner07.nbt,8,WALL_BANNER,../../NBT/banners/JungleBanner08.nbt,8,WALL_BANNER,../../NBT/banners/JungleBanner09.nbt,8,WALL_BANNER,../../NBT/banners/JungleBanner10.nbt,8,WALL_BANNER,../../NBT/banners/JungleBanner11.nbt,8,WALL_BANNER,../../NBT/banners/JungleBanner12.nbt,8,WALL_BANNER,../../NBT/banners/JungleBanner13.nbt,8,WALL_BANNER,../../NBT/banners/JungleBanner14.nbt,8,WALL_BANNER,../../NBT/banners/JungleBanner15.nbt,8,WALL_BANNER,../../NBT/banners/JungleBanner16.nbt,8,WALL_BANNER,../../NBT/banners/JungleBanner17.nbt,8,WALL_BANNER,../../NBT/banners/JungleBanner18.nbt,8,WALL_BANNER,../../NBT/banners/JungleBanner19.nbt,8,WALL_BANNER,../../NBT/banners/JungleBanner20.nbt,100)
RandomBlock(-1,1,-8,WALL_BANNER,../../NBT/banners/JungleBanner01.nbt,8,WALL_BANNER,../../NBT/banners/JungleBanner02.nbt,8,WALL_BANNER,../../NBT/banners/JungleBanner03.nbt,8,WALL_BANNER,../../NBT/banners/JungleBanner04.nbt,8,WALL_BANNER,../../NBT/banners/JungleBanner05.nbt,8,WALL_BANNER,../../NBT/banners/JungleBanner06.nbt,8,WALL_BANNER,../../NBT/banners/JungleBanner07.nbt,8,WALL_BANNER,../../NBT/banners/JungleBanner08.nbt,8,WALL_BANNER,../../NBT/banners/JungleBanner09.nbt,8,WALL_BANNER,../../NBT/banners/JungleBanner10.nbt,8,WALL_BANNER,../../NBT/banners/JungleBanner11.nbt,8,WALL_BANNER,../../NBT/banners/JungleBanner12.nbt,8,WALL_BANNER,../../NBT/banners/JungleBanner13.nbt,8,WALL_BANNER,../../NBT/banners/JungleBanner14.nbt,8,WALL_BANNER,../../NBT/banners/JungleBanner15.nbt,8,WALL_BANNER,../../NBT/banners/JungleBanner16.nbt,8,WALL_BANNER,../../NBT/banners/JungleBanner17.nbt,8,WALL_BANNER,../../NBT/banners/JungleBanner18.nbt,8,WALL_BANNER,../../NBT/banners/JungleBanner19.nbt,8,WALL_BANNER,../../NBT/banners/JungleBanner20.nbt,100)
RandomBlock(2,1,-8,WALL_BANNER,../../NBT/banners/JungleBanner01.nbt,8,WALL_BANNER,../../NBT/banners/JungleBanner02.nbt,8,WALL_BANNER,../../NBT/banners/JungleBanner03.nbt,8,WALL_BANNER,../../NBT/banners/JungleBanner04.nbt,8,WALL_BANNER,../../NBT/banners/JungleBanner05.nbt,8,WALL_BANNER,../../NBT/banners/JungleBanner06.nbt,8,WALL_BANNER,../../NBT/banners/JungleBanner07.nbt,8,WALL_BANNER,../../NBT/banners/JungleBanner08.nbt,8,WALL_BANNER,../../NBT/banners/JungleBanner09.nbt,8,WALL_BANNER,../../NBT/banners/JungleBanner10.nbt,8,WALL_BANNER,../../NBT/banners/JungleBanner11.nbt,8,WALL_BANNER,../../NBT/banners/JungleBanner12.nbt,8,WALL_BANNER,../../NBT/banners/JungleBanner13.nbt,8,WALL_BANNER,../../NBT/banners/JungleBanner14.nbt,8,WALL_BANNER,../../NBT/banners/JungleBanner15.nbt,8,WALL_BANNER,../../NBT/banners/JungleBanner16.nbt,8,WALL_BANNER,../../NBT/banners/JungleBanner17.nbt,8,WALL_BANNER,../../NBT/banners/JungleBanner18.nbt,8,WALL_BANNER,../../NBT/banners/JungleBanner19.nbt,8,WALL_BANNER,../../NBT/banners/JungleBanner20.nbt,100)
RandomBlock(6,1,-8,WALL_BANNER,../../NBT/banners/JungleBanner01.nbt,8,WALL_BANNER,../../NBT/banners/JungleBanner02.nbt,8,WALL_BANNER,../../NBT/banners/JungleBanner03.nbt,8,WALL_BANNER,../../NBT/banners/JungleBanner04.nbt,8,WALL_BANNER,../../NBT/banners/JungleBanner05.nbt,8,WALL_BANNER,../../NBT/banners/JungleBanner06.nbt,8,WALL_BANNER,../../NBT/banners/JungleBanner07.nbt,8,WALL_BANNER,../../NBT/banners/JungleBanner08.nbt,8,WALL_BANNER,../../NBT/banners/JungleBanner09.nbt,8,WALL_BANNER,../../NBT/banners/JungleBanner10.nbt,8,WALL_BANNER,../../NBT/banners/JungleBanner11.nbt,8,WALL_BANNER,../../NBT/banners/JungleBanner12.nbt,8,WALL_BANNER,../../NBT/banners/JungleBanner13.nbt,8,WALL_BANNER,../../NBT/banners/JungleBanner14.nbt,8,WALL_BANNER,../../NBT/banners/JungleBanner15.nbt,8,WALL_BANNER,../../NBT/banners/JungleBanner16.nbt,8,WALL_BANNER,../../NBT/banners/JungleBanner17.nbt,8,WALL_BANNER,../../NBT/banners/JungleBanner18.nbt,8,WALL_BANNER,../../NBT/banners/JungleBanner19.nbt,8,WALL_BANNER,../../NBT/banners/JungleBanner20.nbt,100)
RandomBlock(-6,1,-7,WALL_BANNER:4,../../NBT/banners/JungleBanner01.nbt,8,WALL_BANNER:4,../../NBT/banners/JungleBanner02.nbt,8,WALL_BANNER:4,../../NBT/banners/JungleBanner03.nbt,8,WALL_BANNER:4,../../NBT/banners/JungleBanner04.nbt,8,WALL_BANNER:4,../../NBT/banners/JungleBanner05.nbt,8,WALL_BANNER:4,../../NBT/banners/JungleBanner06.nbt,8,WALL_BANNER:4,../../NBT/banners/JungleBanner07.nbt,8,WALL_BANNER:4,../../NBT/banners/JungleBanner08.nbt,8,WALL_BANNER:4,../../NBT/banners/JungleBanner09.nbt,8,WALL_BANNER:4,../../NBT/banners/JungleBanner10.nbt,8,WALL_BANNER:4,../../NBT/banners/JungleBanner11.nbt,8,WALL_BANNER:4,../../NBT/banners/JungleBanner12.nbt,8,WALL_BANNER:4,../../NBT/banners/JungleBanner13.nbt,8,WALL_BANNER:4,../../NBT/banners/JungleBanner14.nbt,8,WALL_BANNER:4,../../NBT/banners/JungleBanner15.nbt,8,WALL_BANNER:4,../../NBT/banners/JungleBanner16.nbt,8,WALL_BANNER:4,../../NBT/banners/JungleBanner17.nbt,8,WALL_BANNER:4,../../NBT/banners/JungleBanner18.nbt,8,WALL_BANNER:4,../../NBT/banners/JungleBanner19.nbt,8,WALL_BANNER:4,../../NBT/banners/JungleBanner20.nbt,100)
Block(-5,1,-7,LOG:3)
Block(-1,1,-7,LOG:3)
Block(2,1,-7,LOG:3)
Block(6,1,-7,LOG:3)
RandomBlock(7,1,-7,WALL_BANNER:5,../../NBT/banners/JungleBanner01.nbt,8,WALL_BANNER:5,../../NBT/banners/JungleBanner02.nbt,8,WALL_BANNER:5,../../NBT/banners/JungleBanner03.nbt,8,WALL_BANNER:5,../../NBT/banners/JungleBanner04.nbt,8,WALL_BANNER:5,../../NBT/banners/JungleBanner05.nbt,8,WALL_BANNER:5,../../NBT/banners/JungleBanner06.nbt,8,WALL_BANNER:5,../../NBT/banners/JungleBanner07.nbt,8,WALL_BANNER:5,../../NBT/banners/JungleBanner08.nbt,8,WALL_BANNER:5,../../NBT/banners/JungleBanner09.nbt,8,WALL_BANNER:5,../../NBT/banners/JungleBanner10.nbt,8,WALL_BANNER:5,../../NBT/banners/JungleBanner11.nbt,8,WALL_BANNER:5,../../NBT/banners/JungleBanner12.nbt,8,WALL_BANNER:5,../../NBT/banners/JungleBanner13.nbt,8,WALL_BANNER:5,../../NBT/banners/JungleBanner14.nbt,8,WALL_BANNER:5,../../NBT/banners/JungleBanner15.nbt,8,WALL_BANNER:5,../../NBT/banners/JungleBanner16.nbt,8,WALL_BANNER:5,../../NBT/banners/JungleBanner17.nbt,8,WALL_BANNER:5,../../NBT/banners/JungleBanner18.nbt,8,WALL_BANNER:5,../../NBT/banners/JungleBanner19.nbt,8,WALL_BANNER:5,../../NBT/banners/JungleBanner20.nbt,100)
Block(3,1,-6,COBBLESTONE)
RandomBlock(-5,1,-4,FLOWER_POT,../../NBT/pots/JunglePot01.nbt,10,FLOWER_POT,../../NBT/pots/JunglePot02.nbt,10,FLOWER_POT,../../NBT/pots/JunglePot03.nbt,10,FLOWER_POT,../../NBT/pots/JunglePot04.nbt,10,FLOWER_POT,../../NBT/pots/JunglePot05.nbt,10,FLOWER_POT,../../NBT/pots/JunglePot06.nbt,10,FLOWER_POT,../../NBT/pots/JunglePot07.nbt,10,FLOWER_POT,../../NBT/pots/JunglePot08.nbt,100)
Block(-3,1,-4,LOG:3)
Block(4,1,-4,LOG:3)
Block(7,1,-4,WOOD_STAIRS:2)
Block(-8,1,-3,JUNGLE_FENCE)
RandomBlock(-6,1,-3,WALL_BANNER:4,../../NBT/banners/JungleBanner01.nbt,8,WALL_BANNER:4,../../NBT/banners/JungleBanner02.nbt,8,WALL_BANNER:4,../../NBT/banners/JungleBanner03.nbt,8,WALL_BANNER:4,../../NBT/banners/JungleBanner04.nbt,8,WALL_BANNER:4,../../NBT/banners/JungleBanner05.nbt,8,WALL_BANNER:4,../../NBT/banners/JungleBanner06.nbt,8,WALL_BANNER:4,../../NBT/banners/JungleBanner07.nbt,8,WALL_BANNER:4,../../NBT/banners/JungleBanner08.nbt,8,WALL_BANNER:4,../../NBT/banners/JungleBanner09.nbt,8,WALL_BANNER:4,../../NBT/banners/JungleBanner10.nbt,8,WALL_BANNER:4,../../NBT/banners/JungleBanner11.nbt,8,WALL_BANNER:4,../../NBT/banners/JungleBanner12.nbt,8,WALL_BANNER:4,../../NBT/banners/JungleBanner13.nbt,8,WALL_BANNER:4,../../NBT/banners/JungleBanner14.nbt,8,WALL_BANNER:4,../../NBT/banners/JungleBanner15.nbt,8,WALL_BANNER:4,../../NBT/banners/JungleBanner16.nbt,8,WALL_BANNER:4,../../NBT/banners/JungleBanner17.nbt,8,WALL_BANNER:4,../../NBT/banners/JungleBanner18.nbt,8,WALL_BANNER:4,../../NBT/banners/JungleBanner19.nbt,8,WALL_BANNER:4,../../NBT/banners/JungleBanner20.nbt,100)
Block(-5,1,-3,LOG:3)
Block(-3,1,-3,REDSTONE_TORCH_ON)
Block(4,1,-3,REDSTONE_TORCH_ON)
Block(7,1,-3,WOOD_STAIRS:7)
Block(-1,1,-2,COBBLE_WALL)
Block(2,1,-2,COBBLE_WALL)
Block(7,1,-2,LOG:3)
Block(-1,1,1,COBBLE_WALL)
Block(2,1,1,COBBLE_WALL)
Block(7,1,1,LOG:3)
Block(-8,1,2,JUNGLE_FENCE)
RandomBlock(-6,1,2,WALL_BANNER:4,../../NBT/banners/JungleBanner01.nbt,8,WALL_BANNER:4,../../NBT/banners/JungleBanner02.nbt,8,WALL_BANNER:4,../../NBT/banners/JungleBanner03.nbt,8,WALL_BANNER:4,../../NBT/banners/JungleBanner04.nbt,8,WALL_BANNER:4,../../NBT/banners/JungleBanner05.nbt,8,WALL_BANNER:4,../../NBT/banners/JungleBanner06.nbt,8,WALL_BANNER:4,../../NBT/banners/JungleBanner07.nbt,8,WALL_BANNER:4,../../NBT/banners/JungleBanner08.nbt,8,WALL_BANNER:4,../../NBT/banners/JungleBanner09.nbt,8,WALL_BANNER:4,../../NBT/banners/JungleBanner10.nbt,8,WALL_BANNER:4,../../NBT/banners/JungleBanner11.nbt,8,WALL_BANNER:4,../../NBT/banners/JungleBanner12.nbt,8,WALL_BANNER:4,../../NBT/banners/JungleBanner13.nbt,8,WALL_BANNER:4,../../NBT/banners/JungleBanner14.nbt,8,WALL_BANNER:4,../../NBT/banners/JungleBanner15.nbt,8,WALL_BANNER:4,../../NBT/banners/JungleBanner16.nbt,8,WALL_BANNER:4,../../NBT/banners/JungleBanner17.nbt,8,WALL_BANNER:4,../../NBT/banners/JungleBanner18.nbt,8,WALL_BANNER:4,../../NBT/banners/JungleBanner19.nbt,8,WALL_BANNER:4,../../NBT/banners/JungleBanner20.nbt,100)
Block(-5,1,2,LOG:3)
Block(-3,1,2,REDSTONE_TORCH_ON)
Block(4,1,2,REDSTONE_TORCH_ON)
Block(7,1,2,WOOD_STAIRS:6)
RandomBlock(-4,1,3,FLOWER_POT,../../NBT/pots/JunglePot01.nbt,10,FLOWER_POT,../../NBT/pots/JunglePot02.nbt,10,FLOWER_POT,../../NBT/pots/JunglePot03.nbt,10,FLOWER_POT,../../NBT/pots/JunglePot04.nbt,10,FLOWER_POT,../../NBT/pots/JunglePot05.nbt,10,FLOWER_POT,../../NBT/pots/JunglePot06.nbt,10,FLOWER_POT,../../NBT/pots/JunglePot07.nbt,10,FLOWER_POT,../../NBT/pots/JunglePot08.nbt,100)
Block(-3,1,3,LOG:3)
RandomBlock(3,1,3,FLOWER_POT,../../NBT/pots/JunglePot01.nbt,10,FLOWER_POT,../../NBT/pots/JunglePot02.nbt,10,FLOWER_POT,../../NBT/pots/JunglePot03.nbt,10,FLOWER_POT,../../NBT/pots/JunglePot04.nbt,10,FLOWER_POT,../../NBT/pots/JunglePot05.nbt,10,FLOWER_POT,../../NBT/pots/JunglePot06.nbt,10,FLOWER_POT,../../NBT/pots/JunglePot07.nbt,10,FLOWER_POT,../../NBT/pots/JunglePot08.nbt,100)
Block(4,1,3,LOG:3)
Block(7,1,3,WOOD_STAIRS:3)
Block(3,1,4,COBBLESTONE)
RandomBlock(-6,1,6,WALL_BANNER:4,../../NBT/banners/JungleBanner01.nbt,8,WALL_BANNER:4,../../NBT/banners/JungleBanner02.nbt,8,WALL_BANNER:4,../../NBT/banners/JungleBanner03.nbt,8,WALL_BANNER:4,../../NBT/banners/JungleBanner04.nbt,8,WALL_BANNER:4,../../NBT/banners/JungleBanner05.nbt,8,WALL_BANNER:4,../../NBT/banners/JungleBanner06.nbt,8,WALL_BANNER:4,../../NBT/banners/JungleBanner07.nbt,8,WALL_BANNER:4,../../NBT/banners/JungleBanner08.nbt,8,WALL_BANNER:4,../../NBT/banners/JungleBanner09.nbt,8,WALL_BANNER:4,../../NBT/banners/JungleBanner10.nbt,8,WALL_BANNER:4,../../NBT/banners/JungleBanner11.nbt,8,WALL_BANNER:4,../../NBT/banners/JungleBanner12.nbt,8,WALL_BANNER:4,../../NBT/banners/JungleBanner13.nbt,8,WALL_BANNER:4,../../NBT/banners/JungleBanner14.nbt,8,WALL_BANNER:4,../../NBT/banners/JungleBanner15.nbt,8,WALL_BANNER:4,../../NBT/banners/JungleBanner16.nbt,8,WALL_BANNER:4,../../NBT/banners/JungleBanner17.nbt,8,WALL_BANNER:4,../../NBT/banners/JungleBanner18.nbt,8,WALL_BANNER:4,../../NBT/banners/JungleBanner19.nbt,8,WALL_BANNER:4,../../NBT/banners/JungleBanner20.nbt,100)
Block(-5,1,6,LOG:3)
Block(-1,1,6,LOG:3)
Block(2,1,6,LOG:3)
Block(6,1,6,LOG:3)
RandomBlock(7,1,6,WALL_BANNER:5,../../NBT/banners/JungleBanner01.nbt,8,WALL_BANNER:5,../../NBT/banners/JungleBanner02.nbt,8,WALL_BANNER:5,../../NBT/banners/JungleBanner03.nbt,8,WALL_BANNER:5,../../NBT/banners/JungleBanner04.nbt,8,WALL_BANNER:5,../../NBT/banners/JungleBanner05.nbt,8,WALL_BANNER:5,../../NBT/banners/JungleBanner06.nbt,8,WALL_BANNER:5,../../NBT/banners/JungleBanner07.nbt,8,WALL_BANNER:5,../../NBT/banners/JungleBanner08.nbt,8,WALL_BANNER:5,../../NBT/banners/JungleBanner09.nbt,8,WALL_BANNER:5,../../NBT/banners/JungleBanner10.nbt,8,WALL_BANNER:5,../../NBT/banners/JungleBanner11.nbt,8,WALL_BANNER:5,../../NBT/banners/JungleBanner12.nbt,8,WALL_BANNER:5,../../NBT/banners/JungleBanner13.nbt,8,WALL_BANNER:5,../../NBT/banners/JungleBanner14.nbt,8,WALL_BANNER:5,../../NBT/banners/JungleBanner15.nbt,8,WALL_BANNER:5,../../NBT/banners/JungleBanner16.nbt,8,WALL_BANNER:5,../../NBT/banners/JungleBanner17.nbt,8,WALL_BANNER:5,../../NBT/banners/JungleBanner18.nbt,8,WALL_BANNER:5,../../NBT/banners/JungleBanner19.nbt,8,WALL_BANNER:5,../../NBT/banners/JungleBanner20.nbt,100)
RandomBlock(-5,1,7,WALL_BANNER:3,../../NBT/banners/JungleBanner01.nbt,8,WALL_BANNER:3,../../NBT/banners/JungleBanner02.nbt,8,WALL_BANNER:3,../../NBT/banners/JungleBanner03.nbt,8,WALL_BANNER:3,../../NBT/banners/JungleBanner04.nbt,8,WALL_BANNER:3,../../NBT/banners/JungleBanner05.nbt,8,WALL_BANNER:3,../../NBT/banners/JungleBanner06.nbt,8,WALL_BANNER:3,../../NBT/banners/JungleBanner07.nbt,8,WALL_BANNER:3,../../NBT/banners/JungleBanner08.nbt,8,WALL_BANNER:3,../../NBT/banners/JungleBanner09.nbt,8,WALL_BANNER:3,../../NBT/banners/JungleBanner10.nbt,8,WALL_BANNER:3,../../NBT/banners/JungleBanner11.nbt,8,WALL_BANNER:3,../../NBT/banners/JungleBanner12.nbt,8,WALL_BANNER:3,../../NBT/banners/JungleBanner13.nbt,8,WALL_BANNER:3,../../NBT/banners/JungleBanner14.nbt,8,WALL_BANNER:3,../../NBT/banners/JungleBanner15.nbt,8,WALL_BANNER:3,../../NBT/banners/JungleBanner16.nbt,8,WALL_BANNER:3,../../NBT/banners/JungleBanner17.nbt,8,WALL_BANNER:3,../../NBT/banners/JungleBanner18.nbt,8,WALL_BANNER:3,../../NBT/banners/JungleBanner19.nbt,8,WALL_BANNER:3,../../NBT/banners/JungleBanner20.nbt,100)
RandomBlock(-1,1,7,WALL_BANNER:3,../../NBT/banners/JungleBanner01.nbt,8,WALL_BANNER:3,../../NBT/banners/JungleBanner02.nbt,8,WALL_BANNER:3,../../NBT/banners/JungleBanner03.nbt,8,WALL_BANNER:3,../../NBT/banners/JungleBanner04.nbt,8,WALL_BANNER:3,../../NBT/banners/JungleBanner05.nbt,8,WALL_BANNER:3,../../NBT/banners/JungleBanner06.nbt,8,WALL_BANNER:3,../../NBT/banners/JungleBanner07.nbt,8,WALL_BANNER:3,../../NBT/banners/JungleBanner08.nbt,8,WALL_BANNER:3,../../NBT/banners/JungleBanner09.nbt,8,WALL_BANNER:3,../../NBT/banners/JungleBanner10.nbt,8,WALL_BANNER:3,../../NBT/banners/JungleBanner11.nbt,8,WALL_BANNER:3,../../NBT/banners/JungleBanner12.nbt,8,WALL_BANNER:3,../../NBT/banners/JungleBanner13.nbt,8,WALL_BANNER:3,../../NBT/banners/JungleBanner14.nbt,8,WALL_BANNER:3,../../NBT/banners/JungleBanner15.nbt,8,WALL_BANNER:3,../../NBT/banners/JungleBanner16.nbt,8,WALL_BANNER:3,../../NBT/banners/JungleBanner17.nbt,8,WALL_BANNER:3,../../NBT/banners/JungleBanner18.nbt,8,WALL_BANNER:3,../../NBT/banners/JungleBanner19.nbt,8,WALL_BANNER:3,../../NBT/banners/JungleBanner20.nbt,100)
RandomBlock(2,1,7,WALL_BANNER:3,../../NBT/banners/JungleBanner01.nbt,8,WALL_BANNER:3,../../NBT/banners/JungleBanner02.nbt,8,WALL_BANNER:3,../../NBT/banners/JungleBanner03.nbt,8,WALL_BANNER:3,../../NBT/banners/JungleBanner04.nbt,8,WALL_BANNER:3,../../NBT/banners/JungleBanner05.nbt,8,WALL_BANNER:3,../../NBT/banners/JungleBanner06.nbt,8,WALL_BANNER:3,../../NBT/banners/JungleBanner07.nbt,8,WALL_BANNER:3,../../NBT/banners/JungleBanner08.nbt,8,WALL_BANNER:3,../../NBT/banners/JungleBanner09.nbt,8,WALL_BANNER:3,../../NBT/banners/JungleBanner10.nbt,8,WALL_BANNER:3,../../NBT/banners/JungleBanner11.nbt,8,WALL_BANNER:3,../../NBT/banners/JungleBanner12.nbt,8,WALL_BANNER:3,../../NBT/banners/JungleBanner13.nbt,8,WALL_BANNER:3,../../NBT/banners/JungleBanner14.nbt,8,WALL_BANNER:3,../../NBT/banners/JungleBanner15.nbt,8,WALL_BANNER:3,../../NBT/banners/JungleBanner16.nbt,8,WALL_BANNER:3,../../NBT/banners/JungleBanner17.nbt,8,WALL_BANNER:3,../../NBT/banners/JungleBanner18.nbt,8,WALL_BANNER:3,../../NBT/banners/JungleBanner19.nbt,8,WALL_BANNER:3,../../NBT/banners/JungleBanner20.nbt,100)
RandomBlock(6,1,7,WALL_BANNER:3,../../NBT/banners/JungleBanner01.nbt,8,WALL_BANNER:3,../../NBT/banners/JungleBanner02.nbt,8,WALL_BANNER:3,../../NBT/banners/JungleBanner03.nbt,8,WALL_BANNER:3,../../NBT/banners/JungleBanner04.nbt,8,WALL_BANNER:3,../../NBT/banners/JungleBanner05.nbt,8,WALL_BANNER:3,../../NBT/banners/JungleBanner06.nbt,8,WALL_BANNER:3,../../NBT/banners/JungleBanner07.nbt,8,WALL_BANNER:3,../../NBT/banners/JungleBanner08.nbt,8,WALL_BANNER:3,../../NBT/banners/JungleBanner09.nbt,8,WALL_BANNER:3,../../NBT/banners/JungleBanner10.nbt,8,WALL_BANNER:3,../../NBT/banners/JungleBanner11.nbt,8,WALL_BANNER:3,../../NBT/banners/JungleBanner12.nbt,8,WALL_BANNER:3,../../NBT/banners/JungleBanner13.nbt,8,WALL_BANNER:3,../../NBT/banners/JungleBanner14.nbt,8,WALL_BANNER:3,../../NBT/banners/JungleBanner15.nbt,8,WALL_BANNER:3,../../NBT/banners/JungleBanner16.nbt,8,WALL_BANNER:3,../../NBT/banners/JungleBanner17.nbt,8,WALL_BANNER:3,../../NBT/banners/JungleBanner18.nbt,8,WALL_BANNER:3,../../NBT/banners/JungleBanner19.nbt,8,WALL_BANNER:3,../../NBT/banners/JungleBanner20.nbt,100)
Block(-2,2,-8,LADDER)
Block(-1,2,-8,WOOD_STEP:8)
Block(0,2,-8,WOOD_STEP:8)
Block(1,2,-8,WOOD_STEP:8)
Block(2,2,-8,WOOD_STEP:8)
Block(3,2,-8,LADDER)
Block(-5,2,-7,LOG:3)
Block(-4,2,-7,LOG:7)
Block(-3,2,-7,LOG:7)
Block(-2,2,-7,LOG:7)
Block(-1,2,-7,LOG:3)
Block(0,2,-7,LOG:7)
Block(1,2,-7,LOG:7)
Block(2,2,-7,LOG:3)
Block(3,2,-7,LOG:7)
Block(4,2,-7,LOG:7)
Block(5,2,-7,LOG:7)
Block(6,2,-7,LOG:3)
Block(-5,2,-6,LOG:11)
RandomBlock(3,2,-6,FLOWER_POT,../../NBT/pots/JunglePot01.nbt,10,FLOWER_POT,../../NBT/pots/JunglePot02.nbt,10,FLOWER_POT,../../NBT/pots/JunglePot03.nbt,10,FLOWER_POT,../../NBT/pots/JunglePot04.nbt,10,FLOWER_POT,../../NBT/pots/JunglePot05.nbt,10,FLOWER_POT,../../NBT/pots/JunglePot06.nbt,10,FLOWER_POT,../../NBT/pots/JunglePot07.nbt,10,FLOWER_POT,../../NBT/pots/JunglePot08.nbt,100)
Block(6,2,-6,LOG:11)
Block(-5,2,-5,LOG:11)
Block(6,2,-5,LOG:11)
Block(-6,2,-4,WOOD_STEP:8)
Block(-5,2,-4,LOG:11)
Block(-3,2,-4,LOG:3)
Block(4,2,-4,LOG:3)
Block(5,2,-4,WOOD_STEP:8)
Block(6,2,-4,LOG:11)
Block(7,2,-4,LADDER:5)
Block(-8,2,-3,WOOD_STEP)
Block(-7,2,-3,WOOD_STEP:8)
Block(-6,2,-3,WOOD_STEP:8)
Block(-5,2,-3,LOG:3)
Block(5,2,-3,WOOD_STEP:8)
Block(6,2,-3,LOG:11)
Block(7,2,-3,WOOD_STAIRS:2)
Block(-8,2,-2,WOOD_STEP)
Block(-7,2,-2,WOOD_STEP:8)
Block(-6,2,-2,WOOD_STEP:8)
Block(-5,2,-2,LOG:11)
Block(-1,2,-2,JUNGLE_FENCE)
Block(2,2,-2,JUNGLE_FENCE)
Block(5,2,-2,WOOD_STEP:8)
Block(6,2,-2,LOG:11)
Block(7,2,-2,WOOD_DOUBLE_STEP)
Block(-8,2,-1,WOOD_STEP)
Block(-7,2,-1,WOOD_STEP:8)
Block(-6,2,-1,WOOD_STEP:8)
Block(-5,2,-1,LOG:11)
Block(5,2,-1,WOOD_STEP:8)
Block(6,2,-1,LOG:11)
Block(7,2,-1,WOOD_STEP:8)
Block(-8,2,0,WOOD_STEP)
Block(-7,2,0,WOOD_STEP:8)
Block(-6,2,0,WOOD_STEP:8)
Block(-5,2,0,LOG:11)
Block(5,2,0,WOOD_STEP:8)
Block(6,2,0,LOG:11)
Block(7,2,0,WOOD_STEP:8)
Block(-8,2,1,WOOD_STEP)
Block(-7,2,1,WOOD_STEP:8)
Block(-6,2,1,WOOD_STEP:8)
Block(-5,2,1,LOG:11)
Block(-1,2,1,JUNGLE_FENCE)
Block(2,2,1,JUNGLE_FENCE)
Block(5,2,1,WOOD_STEP:8)
Block(6,2,1,LOG:11)
Block(7,2,1,WOOD_DOUBLE_STEP)
Block(-8,2,2,WOOD_STEP)
Block(-7,2,2,WOOD_STEP:8)
Block(-6,2,2,WOOD_STEP:8)
Block(-5,2,2,LOG:3)
Block(5,2,2,WOOD_STEP:8)
Block(6,2,2,LOG:11)
Block(7,2,2,WOOD_STAIRS:3)
Block(-6,2,3,WOOD_STEP:8)
Block(-5,2,3,LOG:11)
Block(-3,2,3,LOG:3)
Block(4,2,3,LOG:3)
Block(5,2,3,WOOD_STEP:8)
Block(6,2,3,LOG:11)
Block(7,2,3,LADDER:5)
Block(-5,2,4,LOG:11)
Block(6,2,4,LOG:11)
Block(-5,2,5,LOG:11)
Block(6,2,5,LOG:11)
Block(-5,2,6,LOG:3)
Block(-4,2,6,LOG:7)
Block(-3,2,6,LOG:7)
Block(-2,2,6,LOG:7)
Block(-1,2,6,LOG:3)
Block(0,2,6,LOG:7)
Block(1,2,6,LOG:7)
Block(2,2,6,LOG:3)
Block(3,2,6,LOG:7)
Block(4,2,6,LOG:7)
Block(5,2,6,LOG:7)
Block(6,2,6,LOG:3)
Block(-2,2,7,LADDER:3)
Block(-1,2,7,WOOD_STEP:8)
Block(0,2,7,WOOD_STEP:8)
Block(1,2,7,WOOD_STEP:8)
Block(2,2,7,WOOD_STEP:8)
Block(3,2,7,LADDER:3)
Block(-5,3,-7,LOG:3)
Block(-3,3,-7,WOOD_STEP)
Block(-2,3,-7,WOOD_STEP)
Block(-1,3,-7,WOOD_STEP)
Block(2,3,-7,WOOD_STEP)
Block(3,3,-7,WOOD_STEP)
Block(4,3,-7,WOOD_STEP)
Block(6,3,-7,LOG:3)
Block(-4,3,-6,WOOD_STEP)
Block(-3,3,-6,WOOD_STEP)
Block(-2,3,-6,WOOD_STEP)
Block(-1,3,-6,WOOD_STEP)
Block(0,3,-6,WOOD_STEP)
Block(1,3,-6,WOOD_STEP)
Block(2,3,-6,WOOD_STEP)
Block(3,3,-6,WOOD_STEP)
Block(4,3,-6,WOOD_STEP)
Block(5,3,-6,WOOD_STEP)
Block(-5,3,-5,WOOD_STEP)
Block(-4,3,-5,WOOD_STEP)
Block(-3,3,-5,WOOD_STEP:8)
Block(-2,3,-5,WOOD_STEP:8)
Block(-1,3,-5,WOOD_STEP:8)
Block(0,3,-5,WOOD_STEP:8)
Block(1,3,-5,WOOD_STEP:8)
Block(2,3,-5,WOOD_STEP:8)
Block(3,3,-5,WOOD_STEP:8)
Block(4,3,-5,WOOD_STEP:8)
Block(5,3,-5,WOOD_STEP)
Block(6,3,-5,WOOD_STEP)
Block(-5,3,-4,WOOD_STEP)
Block(-4,3,-4,WOOD_STEP:8)
Block(-3,3,-4,LOG:3)
RandomBlock(-2,3,-4,WALL_BANNER:5,../../NBT/banners/JungleBanner01.nbt,8,WALL_BANNER:5,../../NBT/banners/JungleBanner02.nbt,8,WALL_BANNER:5,../../NBT/banners/JungleBanner03.nbt,8,WALL_BANNER:5,../../NBT/banners/JungleBanner04.nbt,8,WALL_BANNER:5,../../NBT/banners/JungleBanner05.nbt,8,WALL_BANNER:5,../../NBT/banners/JungleBanner06.nbt,8,WALL_BANNER:5,../../NBT/banners/JungleBanner07.nbt,8,WALL_BANNER:5,../../NBT/banners/JungleBanner08.nbt,8,WALL_BANNER:5,../../NBT/banners/JungleBanner09.nbt,8,WALL_BANNER:5,../../NBT/banners/JungleBanner10.nbt,8,WALL_BANNER:5,../../NBT/banners/JungleBanner11.nbt,8,WALL_BANNER:5,../../NBT/banners/JungleBanner12.nbt,8,WALL_BANNER:5,../../NBT/banners/JungleBanner13.nbt,8,WALL_BANNER:5,../../NBT/banners/JungleBanner14.nbt,8,WALL_BANNER:5,../../NBT/banners/JungleBanner15.nbt,8,WALL_BANNER:5,../../NBT/banners/JungleBanner16.nbt,8,WALL_BANNER:5,../../NBT/banners/JungleBanner17.nbt,8,WALL_BANNER:5,../../NBT/banners/JungleBanner18.nbt,8,WALL_BANNER:5,../../NBT/banners/JungleBanner19.nbt,8,WALL_BANNER:5,../../NBT/banners/JungleBanner20.nbt,100)
RandomBlock(3,3,-4,WALL_BANNER:4,../../NBT/banners/JungleBanner01.nbt,8,WALL_BANNER:4,../../NBT/banners/JungleBanner02.nbt,8,WALL_BANNER:4,../../NBT/banners/JungleBanner03.nbt,8,WALL_BANNER:4,../../NBT/banners/JungleBanner04.nbt,8,WALL_BANNER:4,../../NBT/banners/JungleBanner05.nbt,8,WALL_BANNER:4,../../NBT/banners/JungleBanner06.nbt,8,WALL_BANNER:4,../../NBT/banners/JungleBanner07.nbt,8,WALL_BANNER:4,../../NBT/banners/JungleBanner08.nbt,8,WALL_BANNER:4,../../NBT/banners/JungleBanner09.nbt,8,WALL_BANNER:4,../../NBT/banners/JungleBanner10.nbt,8,WALL_BANNER:4,../../NBT/banners/JungleBanner11.nbt,8,WALL_BANNER:4,../../NBT/banners/JungleBanner12.nbt,8,WALL_BANNER:4,../../NBT/banners/JungleBanner13.nbt,8,WALL_BANNER:4,../../NBT/banners/JungleBanner14.nbt,8,WALL_BANNER:4,../../NBT/banners/JungleBanner15.nbt,8,WALL_BANNER:4,../../NBT/banners/JungleBanner16.nbt,8,WALL_BANNER:4,../../NBT/banners/JungleBanner17.nbt,8,WALL_BANNER:4,../../NBT/banners/JungleBanner18.nbt,8,WALL_BANNER:4,../../NBT/banners/JungleBanner19.nbt,8,WALL_BANNER:4,../../NBT/banners/JungleBanner20.nbt,100)
Block(4,3,-4,LOG:3)
Block(5,3,-4,WOOD_STEP:8)
Block(6,3,-4,WOOD_STEP)
Block(-6,3,-3,WOOD_STEP)
Block(-5,3,-3,WOOD_STEP)
Block(-4,3,-3,WOOD_STEP:8)
RandomBlock(-3,3,-3,WALL_BANNER:3,../../NBT/banners/JungleBanner01.nbt,8,WALL_BANNER:3,../../NBT/banners/JungleBanner02.nbt,8,WALL_BANNER:3,../../NBT/banners/JungleBanner03.nbt,8,WALL_BANNER:3,../../NBT/banners/JungleBanner04.nbt,8,WALL_BANNER:3,../../NBT/banners/JungleBanner05.nbt,8,WALL_BANNER:3,../../NBT/banners/JungleBanner06.nbt,8,WALL_BANNER:3,../../NBT/banners/JungleBanner07.nbt,8,WALL_BANNER:3,../../NBT/banners/JungleBanner08.nbt,8,WALL_BANNER:3,../../NBT/banners/JungleBanner09.nbt,8,WALL_BANNER:3,../../NBT/banners/JungleBanner10.nbt,8,WALL_BANNER:3,../../NBT/banners/JungleBanner11.nbt,8,WALL_BANNER:3,../../NBT/banners/JungleBanner12.nbt,8,WALL_BANNER:3,../../NBT/banners/JungleBanner13.nbt,8,WALL_BANNER:3,../../NBT/banners/JungleBanner14.nbt,8,WALL_BANNER:3,../../NBT/banners/JungleBanner15.nbt,8,WALL_BANNER:3,../../NBT/banners/JungleBanner16.nbt,8,WALL_BANNER:3,../../NBT/banners/JungleBanner17.nbt,8,WALL_BANNER:3,../../NBT/banners/JungleBanner18.nbt,8,WALL_BANNER:3,../../NBT/banners/JungleBanner19.nbt,8,WALL_BANNER:3,../../NBT/banners/JungleBanner20.nbt,100)
RandomBlock(4,3,-3,WALL_BANNER:3,../../NBT/banners/JungleBanner01.nbt,8,WALL_BANNER:3,../../NBT/banners/JungleBanner02.nbt,8,WALL_BANNER:3,../../NBT/banners/JungleBanner03.nbt,8,WALL_BANNER:3,../../NBT/banners/JungleBanner04.nbt,8,WALL_BANNER:3,../../NBT/banners/JungleBanner05.nbt,8,WALL_BANNER:3,../../NBT/banners/JungleBanner06.nbt,8,WALL_BANNER:3,../../NBT/banners/JungleBanner07.nbt,8,WALL_BANNER:3,../../NBT/banners/JungleBanner08.nbt,8,WALL_BANNER:3,../../NBT/banners/JungleBanner09.nbt,8,WALL_BANNER:3,../../NBT/banners/JungleBanner10.nbt,8,WALL_BANNER:3,../../NBT/banners/JungleBanner11.nbt,8,WALL_BANNER:3,../../NBT/banners/JungleBanner12.nbt,8,WALL_BANNER:3,../../NBT/banners/JungleBanner13.nbt,8,WALL_BANNER:3,../../NBT/banners/JungleBanner14.nbt,8,WALL_BANNER:3,../../NBT/banners/JungleBanner15.nbt,8,WALL_BANNER:3,../../NBT/banners/JungleBanner16.nbt,8,WALL_BANNER:3,../../NBT/banners/JungleBanner17.nbt,8,WALL_BANNER:3,../../NBT/banners/JungleBanner18.nbt,8,WALL_BANNER:3,../../NBT/banners/JungleBanner19.nbt,8,WALL_BANNER:3,../../NBT/banners/JungleBanner20.nbt,100)
Block(5,3,-3,WOOD_STEP:8)
Block(6,3,-3,WOOD_STAIRS:1)
Block(-5,3,-2,WOOD_STEP)
Block(-4,3,-2,WOOD_STEP:8)
Block(-1,3,-2,JUNGLE_FENCE)
Block(2,3,-2,JUNGLE_FENCE)
Block(5,3,-2,WOOD_STAIRS:7)
Block(6,3,-2,WOOD_STAIRS:3)
Block(7,3,-2,JUNGLE_FENCE)
Block(-5,3,-1,WOOD_STEP)
Block(-4,3,-1,WOOD_STEP:8)
RandomBlock(5,3,-1,SKULL:1,../../../../Skulls/dungeon_skull_01.nbt,6,AIR,9,SKULL:1,../../../../Skulls/dungeon_skull_02.nbt,12,AIR,15,SKULL:1,../../../../Skulls/dungeon_skull_03.nbt,18,AIR,21,SKULL:1,../../../../Skulls/dungeon_skull_04.nbt,24,AIR,27,SKULL:1,../../../../Skulls/dungeon_skull_05.nbt,30,AIR,33,SKULL:1,../../../../Skulls/dungeon_skull_06.nbt,36,AIR,39,SKULL:1,../../../../Skulls/dungeon_skull_07.nbt,42,AIR,45,SKULL:1,../../../../Skulls/dungeon_skull_08.nbt,48,AIR,51,SKULL:1,../../../../Skulls/dungeon_skull_09.nbt,54,AIR,57,SKULL:1,../../../../Skulls/dungeon_skull_10.nbt,60,AIR,63,SKULL:1,../../../../Skulls/dungeon_skull_11.nbt,66,AIR,69,SKULL:1,../../../../Skulls/dungeon_skull_12.nbt,72,AIR,75,SKULL:1,../../../../Skulls/dungeon_skull_13.nbt,78,AIR,81,SKULL:1,../../../../Skulls/dungeon_skull_14.nbt,84,AIR,87,SKULL:1,../../../../Skulls/dungeon_skull_15.nbt,90,AIR,93,SKULL:1,../../../../Skulls/dungeon_skull_16.nbt,96,AIR,100)
Block(6,3,-1,WOOD_STEP)
Block(-6,3,0,WOOD_STEP)
Block(-5,3,0,WOOD_STEP)
Block(-4,3,0,WOOD_STEP:8)
RandomBlock(5,3,0,SKULL:1,../../../../Skulls/dungeon_skull_01.nbt,6,AIR,9,SKULL:1,../../../../Skulls/dungeon_skull_02.nbt,12,AIR,15,SKULL:1,../../../../Skulls/dungeon_skull_03.nbt,18,AIR,21,SKULL:1,../../../../Skulls/dungeon_skull_04.nbt,24,AIR,27,SKULL:1,../../../../Skulls/dungeon_skull_05.nbt,30,AIR,33,SKULL:1,../../../../Skulls/dungeon_skull_06.nbt,36,AIR,39,SKULL:1,../../../../Skulls/dungeon_skull_07.nbt,42,AIR,45,SKULL:1,../../../../Skulls/dungeon_skull_08.nbt,48,AIR,51,SKULL:1,../../../../Skulls/dungeon_skull_09.nbt,54,AIR,57,SKULL:1,../../../../Skulls/dungeon_skull_10.nbt,60,AIR,63,SKULL:1,../../../../Skulls/dungeon_skull_11.nbt,66,AIR,69,SKULL:1,../../../../Skulls/dungeon_skull_12.nbt,72,AIR,75,SKULL:1,../../../../Skulls/dungeon_skull_13.nbt,78,AIR,81,SKULL:1,../../../../Skulls/dungeon_skull_14.nbt,84,AIR,87,SKULL:1,../../../../Skulls/dungeon_skull_15.nbt,90,AIR,93,SKULL:1,../../../../Skulls/dungeon_skull_16.nbt,96,AIR,100)
Block(6,3,0,WOOD_STEP)
Block(-6,3,1,WOOD_STEP)
Block(-5,3,1,WOOD_STEP)
Block(-4,3,1,WOOD_STEP:8)
Block(-1,3,1,JUNGLE_FENCE)
Block(2,3,1,JUNGLE_FENCE)
Block(5,3,1,WOOD_STAIRS:6)
Block(6,3,1,WOOD_STAIRS:2)
Block(7,3,1,JUNGLE_FENCE)
Block(-5,3,2,WOOD_STEP)
Block(-4,3,2,WOOD_STEP:8)
RandomBlock(-3,3,2,WALL_BANNER,../../NBT/banners/JungleBanner01.nbt,8,WALL_BANNER,../../NBT/banners/JungleBanner02.nbt,8,WALL_BANNER,../../NBT/banners/JungleBanner03.nbt,8,WALL_BANNER,../../NBT/banners/JungleBanner04.nbt,8,WALL_BANNER,../../NBT/banners/JungleBanner05.nbt,8,WALL_BANNER,../../NBT/banners/JungleBanner06.nbt,8,WALL_BANNER,../../NBT/banners/JungleBanner07.nbt,8,WALL_BANNER,../../NBT/banners/JungleBanner08.nbt,8,WALL_BANNER,../../NBT/banners/JungleBanner09.nbt,8,WALL_BANNER,../../NBT/banners/JungleBanner10.nbt,8,WALL_BANNER,../../NBT/banners/JungleBanner11.nbt,8,WALL_BANNER,../../NBT/banners/JungleBanner12.nbt,8,WALL_BANNER,../../NBT/banners/JungleBanner13.nbt,8,WALL_BANNER,../../NBT/banners/JungleBanner14.nbt,8,WALL_BANNER,../../NBT/banners/JungleBanner15.nbt,8,WALL_BANNER,../../NBT/banners/JungleBanner16.nbt,8,WALL_BANNER,../../NBT/banners/JungleBanner17.nbt,8,WALL_BANNER,../../NBT/banners/JungleBanner18.nbt,8,WALL_BANNER,../../NBT/banners/JungleBanner19.nbt,8,WALL_BANNER,../../NBT/banners/JungleBanner20.nbt,100)
RandomBlock(4,3,2,WALL_BANNER,../../NBT/banners/JungleBanner01.nbt,8,WALL_BANNER,../../NBT/banners/JungleBanner02.nbt,8,WALL_BANNER,../../NBT/banners/JungleBanner03.nbt,8,WALL_BANNER,../../NBT/banners/JungleBanner04.nbt,8,WALL_BANNER,../../NBT/banners/JungleBanner05.nbt,8,WALL_BANNER,../../NBT/banners/JungleBanner06.nbt,8,WALL_BANNER,../../NBT/banners/JungleBanner07.nbt,8,WALL_BANNER,../../NBT/banners/JungleBanner08.nbt,8,WALL_BANNER,../../NBT/banners/JungleBanner09.nbt,8,WALL_BANNER,../../NBT/banners/JungleBanner10.nbt,8,WALL_BANNER,../../NBT/banners/JungleBanner11.nbt,8,WALL_BANNER,../../NBT/banners/JungleBanner12.nbt,8,WALL_BANNER,../../NBT/banners/JungleBanner13.nbt,8,WALL_BANNER,../../NBT/banners/JungleBanner14.nbt,8,WALL_BANNER,../../NBT/banners/JungleBanner15.nbt,8,WALL_BANNER,../../NBT/banners/JungleBanner16.nbt,8,WALL_BANNER,../../NBT/banners/JungleBanner17.nbt,8,WALL_BANNER,../../NBT/banners/JungleBanner18.nbt,8,WALL_BANNER,../../NBT/banners/JungleBanner19.nbt,8,WALL_BANNER,../../NBT/banners/JungleBanner20.nbt,100)
Block(5,3,2,WOOD_STEP:8)
Block(6,3,2,WOOD_STAIRS:1)
Block(-5,3,3,WOOD_STEP)
Block(-4,3,3,WOOD_STEP:8)
Block(-3,3,3,LOG:3)
RandomBlock(-2,3,3,WALL_BANNER:5,../../NBT/banners/JungleBanner01.nbt,8,WALL_BANNER:5,../../NBT/banners/JungleBanner02.nbt,8,WALL_BANNER:5,../../NBT/banners/JungleBanner03.nbt,8,WALL_BANNER:5,../../NBT/banners/JungleBanner04.nbt,8,WALL_BANNER:5,../../NBT/banners/JungleBanner05.nbt,8,WALL_BANNER:5,../../NBT/banners/JungleBanner06.nbt,8,WALL_BANNER:5,../../NBT/banners/JungleBanner07.nbt,8,WALL_BANNER:5,../../NBT/banners/JungleBanner08.nbt,8,WALL_BANNER:5,../../NBT/banners/JungleBanner09.nbt,8,WALL_BANNER:5,../../NBT/banners/JungleBanner10.nbt,8,WALL_BANNER:5,../../NBT/banners/JungleBanner11.nbt,8,WALL_BANNER:5,../../NBT/banners/JungleBanner12.nbt,8,WALL_BANNER:5,../../NBT/banners/JungleBanner13.nbt,8,WALL_BANNER:5,../../NBT/banners/JungleBanner14.nbt,8,WALL_BANNER:5,../../NBT/banners/JungleBanner15.nbt,8,WALL_BANNER:5,../../NBT/banners/JungleBanner16.nbt,8,WALL_BANNER:5,../../NBT/banners/JungleBanner17.nbt,8,WALL_BANNER:5,../../NBT/banners/JungleBanner18.nbt,8,WALL_BANNER:5,../../NBT/banners/JungleBanner19.nbt,8,WALL_BANNER:5,../../NBT/banners/JungleBanner20.nbt,100)
RandomBlock(3,3,3,WALL_BANNER:4,../../NBT/banners/JungleBanner01.nbt,8,WALL_BANNER:4,../../NBT/banners/JungleBanner02.nbt,8,WALL_BANNER:4,../../NBT/banners/JungleBanner03.nbt,8,WALL_BANNER:4,../../NBT/banners/JungleBanner04.nbt,8,WALL_BANNER:4,../../NBT/banners/JungleBanner05.nbt,8,WALL_BANNER:4,../../NBT/banners/JungleBanner06.nbt,8,WALL_BANNER:4,../../NBT/banners/JungleBanner07.nbt,8,WALL_BANNER:4,../../NBT/banners/JungleBanner08.nbt,8,WALL_BANNER:4,../../NBT/banners/JungleBanner09.nbt,8,WALL_BANNER:4,../../NBT/banners/JungleBanner10.nbt,8,WALL_BANNER:4,../../NBT/banners/JungleBanner11.nbt,8,WALL_BANNER:4,../../NBT/banners/JungleBanner12.nbt,8,WALL_BANNER:4,../../NBT/banners/JungleBanner13.nbt,8,WALL_BANNER:4,../../NBT/banners/JungleBanner14.nbt,8,WALL_BANNER:4,../../NBT/banners/JungleBanner15.nbt,8,WALL_BANNER:4,../../NBT/banners/JungleBanner16.nbt,8,WALL_BANNER:4,../../NBT/banners/JungleBanner17.nbt,8,WALL_BANNER:4,../../NBT/banners/JungleBanner18.nbt,8,WALL_BANNER:4,../../NBT/banners/JungleBanner19.nbt,8,WALL_BANNER:4,../../NBT/banners/JungleBanner20.nbt,100)
Block(4,3,3,LOG:3)
Block(5,3,3,WOOD_STEP:8)
Block(6,3,3,WOOD_STEP)
Block(-5,3,4,WOOD_STEP)
Block(-4,3,4,WOOD_STEP)
Block(-3,3,4,WOOD_STEP:8)
Block(-2,3,4,WOOD_STEP:8)
Block(-1,3,4,WOOD_STEP:8)
Block(0,3,4,WOOD_STEP:8)
Block(1,3,4,WOOD_STEP:8)
Block(2,3,4,WOOD_STEP:8)
Block(3,3,4,WOOD_STEP:8)
Block(4,3,4,WOOD_STEP:8)
Block(5,3,4,WOOD_STEP)
Block(6,3,4,WOOD_STEP)
Block(-4,3,5,WOOD_STEP)
Block(-3,3,5,WOOD_STEP)
Block(-2,3,5,WOOD_STEP)
Block(-1,3,5,WOOD_STEP)
Block(0,3,5,WOOD_STEP)
Block(1,3,5,WOOD_STEP)
Block(2,3,5,WOOD_STEP)
Block(3,3,5,WOOD_STEP)
Block(4,3,5,WOOD_STEP)
Block(5,3,5,WOOD_STEP)
Block(-5,3,6,LOG:3)
Block(-3,3,6,WOOD_STEP)
Block(-2,3,6,WOOD_STEP)
Block(-1,3,6,WOOD_STEP)
Block(2,3,6,WOOD_STEP)
Block(3,3,6,WOOD_STEP)
Block(4,3,6,WOOD_STEP)
Block(6,3,6,LOG:3)
Block(-5,4,-7,LOG:3)
Block(6,4,-7,LOG:3)
Block(-3,4,-5,JUNGLE_FENCE)
Block(4,4,-5,JUNGLE_FENCE)
Block(-4,4,-4,JUNGLE_FENCE)
Block(-3,4,-4,LOG:3)
Block(-2,4,-4,WOOD_STEP)
Block(-1,4,-4,WOOD_STEP)
Block(0,4,-4,WOOD_STEP)
Block(1,4,-4,WOOD_STEP)
Block(2,4,-4,WOOD_STEP)
Block(3,4,-4,WOOD_STEP)
Block(4,4,-4,LOG:3)
Block(5,4,-4,JUNGLE_FENCE)
Block(-3,4,-3,WOOD_STEP)
Block(4,4,-3,WOOD_STEP)
Block(-3,4,-2,WOOD_STEP)
Block(-2,4,-2,JUNGLE_FENCE)
Block(-1,4,-2,JUNGLE_FENCE)
Block(2,4,-2,JUNGLE_FENCE)
Block(3,4,-2,JUNGLE_FENCE)
Block(4,4,-2,WOOD_STEP)
Block(5,4,-2,WOOD_STAIRS:2)
Block(-3,4,-1,WOOD_STEP)
Block(4,4,-1,WOOD_STEP)
Block(5,4,-1,WOOD_STAIRS:7)
Block(-3,4,0,WOOD_STEP)
Block(4,4,0,WOOD_STEP)
Block(5,4,0,WOOD_STAIRS:6)
Block(-3,4,1,WOOD_STEP)
Block(-2,4,1,JUNGLE_FENCE)
Block(-1,4,1,JUNGLE_FENCE)
Block(2,4,1,JUNGLE_FENCE)
Block(3,4,1,JUNGLE_FENCE)
Block(4,4,1,WOOD_STEP)
Block(5,4,1,WOOD_STAIRS:3)
Block(-3,4,2,WOOD_STEP)
Block(4,4,2,WOOD_STEP)
Block(-4,4,3,JUNGLE_FENCE)
Block(-3,4,3,LOG:3)
Block(-2,4,3,WOOD_STEP)
Block(-1,4,3,WOOD_STEP)
Block(0,4,3,WOOD_STEP)
Block(1,4,3,WOOD_STEP)
Block(2,4,3,WOOD_STEP)
Block(3,4,3,WOOD_STEP)
Block(4,4,3,LOG:3)
Block(5,4,3,JUNGLE_FENCE)
Block(-3,4,4,JUNGLE_FENCE)
Block(4,4,4,JUNGLE_FENCE)
Block(-5,4,6,LOG:3)
Block(6,4,6,LOG:3)
Block(-5,5,-7,COBBLE_WALL)
Block(6,5,-7,COBBLE_WALL)
RandomBlock(-2,5,-5,WALL_BANNER,../../NBT/banners/JungleBanner01.nbt,8,WALL_BANNER,../../NBT/banners/JungleBanner02.nbt,8,WALL_BANNER,../../NBT/banners/JungleBanner03.nbt,8,WALL_BANNER,../../NBT/banners/JungleBanner04.nbt,8,WALL_BANNER,../../NBT/banners/JungleBanner05.nbt,8,WALL_BANNER,../../NBT/banners/JungleBanner06.nbt,8,WALL_BANNER,../../NBT/banners/JungleBanner07.nbt,8,WALL_BANNER,../../NBT/banners/JungleBanner08.nbt,8,WALL_BANNER,../../NBT/banners/JungleBanner09.nbt,8,WALL_BANNER,../../NBT/banners/JungleBanner10.nbt,8,WALL_BANNER,../../NBT/banners/JungleBanner11.nbt,8,WALL_BANNER,../../NBT/banners/JungleBanner12.nbt,8,WALL_BANNER,../../NBT/banners/JungleBanner13.nbt,8,WALL_BANNER,../../NBT/banners/JungleBanner14.nbt,8,WALL_BANNER,../../NBT/banners/JungleBanner15.nbt,8,WALL_BANNER,../../NBT/banners/JungleBanner16.nbt,8,WALL_BANNER,../../NBT/banners/JungleBanner17.nbt,8,WALL_BANNER,../../NBT/banners/JungleBanner18.nbt,8,WALL_BANNER,../../NBT/banners/JungleBanner19.nbt,8,WALL_BANNER,../../NBT/banners/JungleBanner20.nbt,100)
Block(-1,5,-5,LADDER)
Block(2,5,-5,LADDER)
RandomBlock(3,5,-5,WALL_BANNER,../../NBT/banners/JungleBanner01.nbt,8,WALL_BANNER,../../NBT/banners/JungleBanner02.nbt,8,WALL_BANNER,../../NBT/banners/JungleBanner03.nbt,8,WALL_BANNER,../../NBT/banners/JungleBanner04.nbt,8,WALL_BANNER,../../NBT/banners/JungleBanner05.nbt,8,WALL_BANNER,../../NBT/banners/JungleBanner06.nbt,8,WALL_BANNER,../../NBT/banners/JungleBanner07.nbt,8,WALL_BANNER,../../NBT/banners/JungleBanner08.nbt,8,WALL_BANNER,../../NBT/banners/JungleBanner09.nbt,8,WALL_BANNER,../../NBT/banners/JungleBanner10.nbt,8,WALL_BANNER,../../NBT/banners/JungleBanner11.nbt,8,WALL_BANNER,../../NBT/banners/JungleBanner12.nbt,8,WALL_BANNER,../../NBT/banners/JungleBanner13.nbt,8,WALL_BANNER,../../NBT/banners/JungleBanner14.nbt,8,WALL_BANNER,../../NBT/banners/JungleBanner15.nbt,8,WALL_BANNER,../../NBT/banners/JungleBanner16.nbt,8,WALL_BANNER,../../NBT/banners/JungleBanner17.nbt,8,WALL_BANNER,../../NBT/banners/JungleBanner18.nbt,8,WALL_BANNER,../../NBT/banners/JungleBanner19.nbt,8,WALL_BANNER,../../NBT/banners/JungleBanner20.nbt,100)
Block(-3,5,-4,LOG:3)
Block(-2,5,-4,LOG:7)
Block(-1,5,-4,LOG:7)
Block(0,5,-4,SMOOTH_BRICK:3)
Block(1,5,-4,SMOOTH_BRICK:3)
Block(2,5,-4,LOG:7)
Block(3,5,-4,LOG:7)
Block(4,5,-4,LOG:3)
RandomBlock(-4,5,-3,WALL_BANNER:4,../../NBT/banners/JungleBanner01.nbt,8,WALL_BANNER:4,../../NBT/banners/JungleBanner02.nbt,8,WALL_BANNER:4,../../NBT/banners/JungleBanner03.nbt,8,WALL_BANNER:4,../../NBT/banners/JungleBanner04.nbt,8,WALL_BANNER:4,../../NBT/banners/JungleBanner05.nbt,8,WALL_BANNER:4,../../NBT/banners/JungleBanner06.nbt,8,WALL_BANNER:4,../../NBT/banners/JungleBanner07.nbt,8,WALL_BANNER:4,../../NBT/banners/JungleBanner08.nbt,8,WALL_BANNER:4,../../NBT/banners/JungleBanner09.nbt,8,WALL_BANNER:4,../../NBT/banners/JungleBanner10.nbt,8,WALL_BANNER:4,../../NBT/banners/JungleBanner11.nbt,8,WALL_BANNER:4,../../NBT/banners/JungleBanner12.nbt,8,WALL_BANNER:4,../../NBT/banners/JungleBanner13.nbt,8,WALL_BANNER:4,../../NBT/banners/JungleBanner14.nbt,8,WALL_BANNER:4,../../NBT/banners/JungleBanner15.nbt,8,WALL_BANNER:4,../../NBT/banners/JungleBanner16.nbt,8,WALL_BANNER:4,../../NBT/banners/JungleBanner17.nbt,8,WALL_BANNER:4,../../NBT/banners/JungleBanner18.nbt,8,WALL_BANNER:4,../../NBT/banners/JungleBanner19.nbt,8,WALL_BANNER:4,../../NBT/banners/JungleBanner20.nbt,100)
Block(-3,5,-3,LOG:11)
Block(-1,5,-3,WOOD_STEP:8)
Block(0,5,-3,WOOD_STEP:8)
Block(1,5,-3,WOOD_STEP:8)
Block(2,5,-3,WOOD_STEP:8)
Block(4,5,-3,LOG:11)
RandomBlock(5,5,-3,WALL_BANNER:5,../../NBT/banners/JungleBanner01.nbt,8,WALL_BANNER:5,../../NBT/banners/JungleBanner02.nbt,8,WALL_BANNER:5,../../NBT/banners/JungleBanner03.nbt,8,WALL_BANNER:5,../../NBT/banners/JungleBanner04.nbt,8,WALL_BANNER:5,../../NBT/banners/JungleBanner05.nbt,8,WALL_BANNER:5,../../NBT/banners/JungleBanner06.nbt,8,WALL_BANNER:5,../../NBT/banners/JungleBanner07.nbt,8,WALL_BANNER:5,../../NBT/banners/JungleBanner08.nbt,8,WALL_BANNER:5,../../NBT/banners/JungleBanner09.nbt,8,WALL_BANNER:5,../../NBT/banners/JungleBanner10.nbt,8,WALL_BANNER:5,../../NBT/banners/JungleBanner11.nbt,8,WALL_BANNER:5,../../NBT/banners/JungleBanner12.nbt,8,WALL_BANNER:5,../../NBT/banners/JungleBanner13.nbt,8,WALL_BANNER:5,../../NBT/banners/JungleBanner14.nbt,8,WALL_BANNER:5,../../NBT/banners/JungleBanner15.nbt,8,WALL_BANNER:5,../../NBT/banners/JungleBanner16.nbt,8,WALL_BANNER:5,../../NBT/banners/JungleBanner17.nbt,8,WALL_BANNER:5,../../NBT/banners/JungleBanner18.nbt,8,WALL_BANNER:5,../../NBT/banners/JungleBanner19.nbt,8,WALL_BANNER:5,../../NBT/banners/JungleBanner20.nbt,100)
Block(-4,5,-2,LADDER:4)
Block(-3,5,-2,LOG:11)
Block(-2,5,-2,LOG:7)
Block(-1,5,-2,LOG:7)
Block(0,5,-2,LOG:7)
Block(1,5,-2,LOG:7)
Block(2,5,-2,LOG:7)
Block(3,5,-2,LOG:7)
Block(4,5,-2,LOG:11)
Block(5,5,-2,LADDER:5)
Block(-3,5,-1,SMOOTH_BRICK:3)
Block(-2,5,-1,WOOD_STEP:8)
Block(-1,5,-1,WOOD_STEP:8)
Block(2,5,-1,WOOD_STEP:8)
Block(3,5,-1,WOOD_STEP:8)
Block(4,5,-1,SMOOTH_BRICK:3)
Block(5,5,-1,WOOD_STAIRS:2)
Block(-3,5,0,SMOOTH_BRICK:3)
Block(-2,5,0,WOOD_STEP:8)
Block(-1,5,0,WOOD_STEP:8)
Block(2,5,0,WOOD_STEP:8)
Block(3,5,0,WOOD_STEP:8)
Block(4,5,0,SMOOTH_BRICK:3)
Block(5,5,0,WOOD_STAIRS:3)
Block(-4,5,1,LADDER:4)
Block(-3,5,1,LOG:11)
Block(-2,5,1,LOG:7)
Block(-1,5,1,LOG:7)
Block(0,5,1,LOG:7)
Block(1,5,1,LOG:7)
Block(2,5,1,LOG:7)
Block(3,5,1,LOG:7)
Block(4,5,1,LOG:11)
Block(5,5,1,LADDER:5)
RandomBlock(-4,5,2,WALL_BANNER:4,../../NBT/banners/JungleBanner01.nbt,8,WALL_BANNER:4,../../NBT/banners/JungleBanner02.nbt,8,WALL_BANNER:4,../../NBT/banners/JungleBanner03.nbt,8,WALL_BANNER:4,../../NBT/banners/JungleBanner04.nbt,8,WALL_BANNER:4,../../NBT/banners/JungleBanner05.nbt,8,WALL_BANNER:4,../../NBT/banners/JungleBanner06.nbt,8,WALL_BANNER:4,../../NBT/banners/JungleBanner07.nbt,8,WALL_BANNER:4,../../NBT/banners/JungleBanner08.nbt,8,WALL_BANNER:4,../../NBT/banners/JungleBanner09.nbt,8,WALL_BANNER:4,../../NBT/banners/JungleBanner10.nbt,8,WALL_BANNER:4,../../NBT/banners/JungleBanner11.nbt,8,WALL_BANNER:4,../../NBT/banners/JungleBanner12.nbt,8,WALL_BANNER:4,../../NBT/banners/JungleBanner13.nbt,8,WALL_BANNER:4,../../NBT/banners/JungleBanner14.nbt,8,WALL_BANNER:4,../../NBT/banners/JungleBanner15.nbt,8,WALL_BANNER:4,../../NBT/banners/JungleBanner16.nbt,8,WALL_BANNER:4,../../NBT/banners/JungleBanner17.nbt,8,WALL_BANNER:4,../../NBT/banners/JungleBanner18.nbt,8,WALL_BANNER:4,../../NBT/banners/JungleBanner19.nbt,8,WALL_BANNER:4,../../NBT/banners/JungleBanner20.nbt,100)
Block(-3,5,2,LOG:11)
Block(-1,5,2,WOOD_STEP:8)
Block(0,5,2,WOOD_STEP:8)
Block(1,5,2,WOOD_STEP:8)
Block(2,5,2,WOOD_STEP:8)
Block(4,5,2,LOG:11)
RandomBlock(5,5,2,WALL_BANNER:5,../../NBT/banners/JungleBanner01.nbt,8,WALL_BANNER:5,../../NBT/banners/JungleBanner02.nbt,8,WALL_BANNER:5,../../NBT/banners/JungleBanner03.nbt,8,WALL_BANNER:5,../../NBT/banners/JungleBanner04.nbt,8,WALL_BANNER:5,../../NBT/banners/JungleBanner05.nbt,8,WALL_BANNER:5,../../NBT/banners/JungleBanner06.nbt,8,WALL_BANNER:5,../../NBT/banners/JungleBanner07.nbt,8,WALL_BANNER:5,../../NBT/banners/JungleBanner08.nbt,8,WALL_BANNER:5,../../NBT/banners/JungleBanner09.nbt,8,WALL_BANNER:5,../../NBT/banners/JungleBanner10.nbt,8,WALL_BANNER:5,../../NBT/banners/JungleBanner11.nbt,8,WALL_BANNER:5,../../NBT/banners/JungleBanner12.nbt,8,WALL_BANNER:5,../../NBT/banners/JungleBanner13.nbt,8,WALL_BANNER:5,../../NBT/banners/JungleBanner14.nbt,8,WALL_BANNER:5,../../NBT/banners/JungleBanner15.nbt,8,WALL_BANNER:5,../../NBT/banners/JungleBanner16.nbt,8,WALL_BANNER:5,../../NBT/banners/JungleBanner17.nbt,8,WALL_BANNER:5,../../NBT/banners/JungleBanner18.nbt,8,WALL_BANNER:5,../../NBT/banners/JungleBanner19.nbt,8,WALL_BANNER:5,../../NBT/banners/JungleBanner20.nbt,100)
Block(-3,5,3,LOG:3)
Block(-2,5,3,LOG:7)
Block(-1,5,3,LOG:7)
Block(0,5,3,SMOOTH_BRICK:3)
Block(1,5,3,SMOOTH_BRICK:3)
Block(2,5,3,LOG:7)
Block(3,5,3,LOG:7)
Block(4,5,3,LOG:3)
RandomBlock(-2,5,4,WALL_BANNER:3,../../NBT/banners/JungleBanner01.nbt,8,WALL_BANNER:3,../../NBT/banners/JungleBanner02.nbt,8,WALL_BANNER:3,../../NBT/banners/JungleBanner03.nbt,8,WALL_BANNER:3,../../NBT/banners/JungleBanner04.nbt,8,WALL_BANNER:3,../../NBT/banners/JungleBanner05.nbt,8,WALL_BANNER:3,../../NBT/banners/JungleBanner06.nbt,8,WALL_BANNER:3,../../NBT/banners/JungleBanner07.nbt,8,WALL_BANNER:3,../../NBT/banners/JungleBanner08.nbt,8,WALL_BANNER:3,../../NBT/banners/JungleBanner09.nbt,8,WALL_BANNER:3,../../NBT/banners/JungleBanner10.nbt,8,WALL_BANNER:3,../../NBT/banners/JungleBanner11.nbt,8,WALL_BANNER:3,../../NBT/banners/JungleBanner12.nbt,8,WALL_BANNER:3,../../NBT/banners/JungleBanner13.nbt,8,WALL_BANNER:3,../../NBT/banners/JungleBanner14.nbt,8,WALL_BANNER:3,../../NBT/banners/JungleBanner15.nbt,8,WALL_BANNER:3,../../NBT/banners/JungleBanner16.nbt,8,WALL_BANNER:3,../../NBT/banners/JungleBanner17.nbt,8,WALL_BANNER:3,../../NBT/banners/JungleBanner18.nbt,8,WALL_BANNER:3,../../NBT/banners/JungleBanner19.nbt,8,WALL_BANNER:3,../../NBT/banners/JungleBanner20.nbt,100)
Block(-1,5,4,LADDER:3)
Block(2,5,4,LADDER:3)
RandomBlock(3,5,4,WALL_BANNER:3,../../NBT/banners/JungleBanner01.nbt,8,WALL_BANNER:3,../../NBT/banners/JungleBanner02.nbt,8,WALL_BANNER:3,../../NBT/banners/JungleBanner03.nbt,8,WALL_BANNER:3,../../NBT/banners/JungleBanner04.nbt,8,WALL_BANNER:3,../../NBT/banners/JungleBanner05.nbt,8,WALL_BANNER:3,../../NBT/banners/JungleBanner06.nbt,8,WALL_BANNER:3,../../NBT/banners/JungleBanner07.nbt,8,WALL_BANNER:3,../../NBT/banners/JungleBanner08.nbt,8,WALL_BANNER:3,../../NBT/banners/JungleBanner09.nbt,8,WALL_BANNER:3,../../NBT/banners/JungleBanner10.nbt,8,WALL_BANNER:3,../../NBT/banners/JungleBanner11.nbt,8,WALL_BANNER:3,../../NBT/banners/JungleBanner12.nbt,8,WALL_BANNER:3,../../NBT/banners/JungleBanner13.nbt,8,WALL_BANNER:3,../../NBT/banners/JungleBanner14.nbt,8,WALL_BANNER:3,../../NBT/banners/JungleBanner15.nbt,8,WALL_BANNER:3,../../NBT/banners/JungleBanner16.nbt,8,WALL_BANNER:3,../../NBT/banners/JungleBanner17.nbt,8,WALL_BANNER:3,../../NBT/banners/JungleBanner18.nbt,8,WALL_BANNER:3,../../NBT/banners/JungleBanner19.nbt,8,WALL_BANNER:3,../../NBT/banners/JungleBanner20.nbt,100)
Block(-5,5,6,COBBLE_WALL)
Block(6,5,6,COBBLE_WALL)
Block(-5,6,-7,JUNGLE_FENCE)
Block(6,6,-7,JUNGLE_FENCE)
Block(-3,6,-4,LOG:3)
Block(-1,6,-4,WOOD_STEP)
Block(0,6,-4,WOOD_STEP)
Block(1,6,-4,WOOD_STEP)
Block(2,6,-4,WOOD_STEP)
Block(4,6,-4,LOG:3)
Block(-2,6,-3,WOOD_STEP)
Block(-1,6,-3,COBBLE_WALL)
Block(2,6,-3,COBBLE_WALL)
Block(3,6,-3,WOOD_STEP)
Block(-3,6,-2,WOOD_STEP)
Block(-2,6,-2,COBBLE_WALL)
Block(-1,6,-2,LOG:3)
Block(2,6,-2,LOG:3)
Block(3,6,-2,COBBLE_WALL)
Block(4,6,-2,WOOD_STEP)
Block(-3,6,-1,WOOD_STEP)
Block(-3,6,0,WOOD_STEP)
Block(-3,6,1,WOOD_STEP)
Block(-2,6,1,COBBLE_WALL)
Block(-1,6,1,LOG:3)
Block(2,6,1,LOG:3)
Block(3,6,1,COBBLE_WALL)
Block(4,6,1,WOOD_STEP)
Block(-2,6,2,WOOD_STEP)
Block(-1,6,2,COBBLE_WALL)
Block(2,6,2,COBBLE_WALL)
Block(3,6,2,WOOD_STEP)
Block(-3,6,3,LOG:3)
Block(-1,6,3,WOOD_STEP)
Block(0,6,3,WOOD_STEP)
Block(1,6,3,WOOD_STEP)
Block(2,6,3,WOOD_STEP)
Block(4,6,3,LOG:3)
Block(-5,6,6,JUNGLE_FENCE)
Block(6,6,6,JUNGLE_FENCE)
Block(-5,7,-7,TORCH)
Block(6,7,-7,TORCH)
Block(-3,7,-4,COBBLE_WALL)
RandomBlock(-2,7,-4,WALL_BANNER,../../NBT/banners/JungleBanner01.nbt,8,WALL_BANNER,../../NBT/banners/JungleBanner02.nbt,8,WALL_BANNER,../../NBT/banners/JungleBanner03.nbt,8,WALL_BANNER,../../NBT/banners/JungleBanner04.nbt,8,WALL_BANNER,../../NBT/banners/JungleBanner05.nbt,8,WALL_BANNER,../../NBT/banners/JungleBanner06.nbt,8,WALL_BANNER,../../NBT/banners/JungleBanner07.nbt,8,WALL_BANNER,../../NBT/banners/JungleBanner08.nbt,8,WALL_BANNER,../../NBT/banners/JungleBanner09.nbt,8,WALL_BANNER,../../NBT/banners/JungleBanner10.nbt,8,WALL_BANNER,../../NBT/banners/JungleBanner11.nbt,8,WALL_BANNER,../../NBT/banners/JungleBanner12.nbt,8,WALL_BANNER,../../NBT/banners/JungleBanner13.nbt,8,WALL_BANNER,../../NBT/banners/JungleBanner14.nbt,8,WALL_BANNER,../../NBT/banners/JungleBanner15.nbt,8,WALL_BANNER,../../NBT/banners/JungleBanner16.nbt,8,WALL_BANNER,../../NBT/banners/JungleBanner17.nbt,8,WALL_BANNER,../../NBT/banners/JungleBanner18.nbt,8,WALL_BANNER,../../NBT/banners/JungleBanner19.nbt,8,WALL_BANNER,../../NBT/banners/JungleBanner20.nbt,100)
Block(-1,7,-4,WOOD_STEP:8)
Block(0,7,-4,WOOD_STEP:8)
Block(1,7,-4,WOOD_STEP:8)
Block(2,7,-4,WOOD_STEP:8)
RandomBlock(3,7,-4,WALL_BANNER,../../NBT/banners/JungleBanner01.nbt,8,WALL_BANNER,../../NBT/banners/JungleBanner02.nbt,8,WALL_BANNER,../../NBT/banners/JungleBanner03.nbt,8,WALL_BANNER,../../NBT/banners/JungleBanner04.nbt,8,WALL_BANNER,../../NBT/banners/JungleBanner05.nbt,8,WALL_BANNER,../../NBT/banners/JungleBanner06.nbt,8,WALL_BANNER,../../NBT/banners/JungleBanner07.nbt,8,WALL_BANNER,../../NBT/banners/JungleBanner08.nbt,8,WALL_BANNER,../../NBT/banners/JungleBanner09.nbt,8,WALL_BANNER,../../NBT/banners/JungleBanner10.nbt,8,WALL_BANNER,../../NBT/banners/JungleBanner11.nbt,8,WALL_BANNER,../../NBT/banners/JungleBanner12.nbt,8,WALL_BANNER,../../NBT/banners/JungleBanner13.nbt,8,WALL_BANNER,../../NBT/banners/JungleBanner14.nbt,8,WALL_BANNER,../../NBT/banners/JungleBanner15.nbt,8,WALL_BANNER,../../NBT/banners/JungleBanner16.nbt,8,WALL_BANNER,../../NBT/banners/JungleBanner17.nbt,8,WALL_BANNER,../../NBT/banners/JungleBanner18.nbt,8,WALL_BANNER,../../NBT/banners/JungleBanner19.nbt,8,WALL_BANNER,../../NBT/banners/JungleBanner20.nbt,100)
Block(4,7,-4,COBBLE_WALL)
RandomBlock(-3,7,-3,WALL_BANNER:4,../../NBT/banners/JungleBanner01.nbt,8,WALL_BANNER:4,../../NBT/banners/JungleBanner02.nbt,8,WALL_BANNER:4,../../NBT/banners/JungleBanner03.nbt,8,WALL_BANNER:4,../../NBT/banners/JungleBanner04.nbt,8,WALL_BANNER:4,../../NBT/banners/JungleBanner05.nbt,8,WALL_BANNER:4,../../NBT/banners/JungleBanner06.nbt,8,WALL_BANNER:4,../../NBT/banners/JungleBanner07.nbt,8,WALL_BANNER:4,../../NBT/banners/JungleBanner08.nbt,8,WALL_BANNER:4,../../NBT/banners/JungleBanner09.nbt,8,WALL_BANNER:4,../../NBT/banners/JungleBanner10.nbt,8,WALL_BANNER:4,../../NBT/banners/JungleBanner11.nbt,8,WALL_BANNER:4,../../NBT/banners/JungleBanner12.nbt,8,WALL_BANNER:4,../../NBT/banners/JungleBanner13.nbt,8,WALL_BANNER:4,../../NBT/banners/JungleBanner14.nbt,8,WALL_BANNER:4,../../NBT/banners/JungleBanner15.nbt,8,WALL_BANNER:4,../../NBT/banners/JungleBanner16.nbt,8,WALL_BANNER:4,../../NBT/banners/JungleBanner17.nbt,8,WALL_BANNER:4,../../NBT/banners/JungleBanner18.nbt,8,WALL_BANNER:4,../../NBT/banners/JungleBanner19.nbt,8,WALL_BANNER:4,../../NBT/banners/JungleBanner20.nbt,100)
Block(-2,7,-3,WOOD_STEP:8)
Block(-1,7,-3,COBBLE_WALL)
Block(2,7,-3,COBBLE_WALL)
Block(3,7,-3,WOOD_STEP:8)
RandomBlock(4,7,-3,WALL_BANNER:5,../../NBT/banners/JungleBanner01.nbt,8,WALL_BANNER:5,../../NBT/banners/JungleBanner02.nbt,8,WALL_BANNER:5,../../NBT/banners/JungleBanner03.nbt,8,WALL_BANNER:5,../../NBT/banners/JungleBanner04.nbt,8,WALL_BANNER:5,../../NBT/banners/JungleBanner05.nbt,8,WALL_BANNER:5,../../NBT/banners/JungleBanner06.nbt,8,WALL_BANNER:5,../../NBT/banners/JungleBanner07.nbt,8,WALL_BANNER:5,../../NBT/banners/JungleBanner08.nbt,8,WALL_BANNER:5,../../NBT/banners/JungleBanner09.nbt,8,WALL_BANNER:5,../../NBT/banners/JungleBanner10.nbt,8,WALL_BANNER:5,../../NBT/banners/JungleBanner11.nbt,8,WALL_BANNER:5,../../NBT/banners/JungleBanner12.nbt,8,WALL_BANNER:5,../../NBT/banners/JungleBanner13.nbt,8,WALL_BANNER:5,../../NBT/banners/JungleBanner14.nbt,8,WALL_BANNER:5,../../NBT/banners/JungleBanner15.nbt,8,WALL_BANNER:5,../../NBT/banners/JungleBanner16.nbt,8,WALL_BANNER:5,../../NBT/banners/JungleBanner17.nbt,8,WALL_BANNER:5,../../NBT/banners/JungleBanner18.nbt,8,WALL_BANNER:5,../../NBT/banners/JungleBanner19.nbt,8,WALL_BANNER:5,../../NBT/banners/JungleBanner20.nbt,100)
Block(-3,7,-2,WOOD_STEP:8)
Block(-2,7,-2,COBBLE_WALL)
Block(-1,7,-2,LOG:3)
Block(2,7,-2,LOG:3)
Block(3,7,-2,COBBLE_WALL)
Block(4,7,-2,WOOD_STEP:8)
Block(-3,7,-1,WOOD_STEP:8)
Block(-3,7,0,WOOD_STEP:8)
Block(-3,7,1,WOOD_STEP:8)
Block(-2,7,1,COBBLE_WALL)
Block(-1,7,1,LOG:3)
Block(2,7,1,LOG:3)
Block(3,7,1,COBBLE_WALL)
Block(4,7,1,WOOD_STEP:8)
RandomBlock(-3,7,2,WALL_BANNER:4,../../NBT/banners/JungleBanner01.nbt,8,WALL_BANNER:4,../../NBT/banners/JungleBanner02.nbt,8,WALL_BANNER:4,../../NBT/banners/JungleBanner03.nbt,8,WALL_BANNER:4,../../NBT/banners/JungleBanner04.nbt,8,WALL_BANNER:4,../../NBT/banners/JungleBanner05.nbt,8,WALL_BANNER:4,../../NBT/banners/JungleBanner06.nbt,8,WALL_BANNER:4,../../NBT/banners/JungleBanner07.nbt,8,WALL_BANNER:4,../../NBT/banners/JungleBanner08.nbt,8,WALL_BANNER:4,../../NBT/banners/JungleBanner09.nbt,8,WALL_BANNER:4,../../NBT/banners/JungleBanner10.nbt,8,WALL_BANNER:4,../../NBT/banners/JungleBanner11.nbt,8,WALL_BANNER:4,../../NBT/banners/JungleBanner12.nbt,8,WALL_BANNER:4,../../NBT/banners/JungleBanner13.nbt,8,WALL_BANNER:4,../../NBT/banners/JungleBanner14.nbt,8,WALL_BANNER:4,../../NBT/banners/JungleBanner15.nbt,8,WALL_BANNER:4,../../NBT/banners/JungleBanner16.nbt,8,WALL_BANNER:4,../../NBT/banners/JungleBanner17.nbt,8,WALL_BANNER:4,../../NBT/banners/JungleBanner18.nbt,8,WALL_BANNER:4,../../NBT/banners/JungleBanner19.nbt,8,WALL_BANNER:4,../../NBT/banners/JungleBanner20.nbt,100)
Block(-2,7,2,WOOD_STEP:8)
Block(-1,7,2,COBBLE_WALL)
Block(2,7,2,COBBLE_WALL)
Block(3,7,2,WOOD_STEP:8)
RandomBlock(4,7,2,WALL_BANNER:5,../../NBT/banners/JungleBanner01.nbt,8,WALL_BANNER:5,../../NBT/banners/JungleBanner02.nbt,8,WALL_BANNER:5,../../NBT/banners/JungleBanner03.nbt,8,WALL_BANNER:5,../../NBT/banners/JungleBanner04.nbt,8,WALL_BANNER:5,../../NBT/banners/JungleBanner05.nbt,8,WALL_BANNER:5,../../NBT/banners/JungleBanner06.nbt,8,WALL_BANNER:5,../../NBT/banners/JungleBanner07.nbt,8,WALL_BANNER:5,../../NBT/banners/JungleBanner08.nbt,8,WALL_BANNER:5,../../NBT/banners/JungleBanner09.nbt,8,WALL_BANNER:5,../../NBT/banners/JungleBanner10.nbt,8,WALL_BANNER:5,../../NBT/banners/JungleBanner11.nbt,8,WALL_BANNER:5,../../NBT/banners/JungleBanner12.nbt,8,WALL_BANNER:5,../../NBT/banners/JungleBanner13.nbt,8,WALL_BANNER:5,../../NBT/banners/JungleBanner14.nbt,8,WALL_BANNER:5,../../NBT/banners/JungleBanner15.nbt,8,WALL_BANNER:5,../../NBT/banners/JungleBanner16.nbt,8,WALL_BANNER:5,../../NBT/banners/JungleBanner17.nbt,8,WALL_BANNER:5,../../NBT/banners/JungleBanner18.nbt,8,WALL_BANNER:5,../../NBT/banners/JungleBanner19.nbt,8,WALL_BANNER:5,../../NBT/banners/JungleBanner20.nbt,100)
Block(-3,7,3,COBBLE_WALL)
RandomBlock(-2,7,3,WALL_BANNER:3,../../NBT/banners/JungleBanner01.nbt,8,WALL_BANNER:3,../../NBT/banners/JungleBanner02.nbt,8,WALL_BANNER:3,../../NBT/banners/JungleBanner03.nbt,8,WALL_BANNER:3,../../NBT/banners/JungleBanner04.nbt,8,WALL_BANNER:3,../../NBT/banners/JungleBanner05.nbt,8,WALL_BANNER:3,../../NBT/banners/JungleBanner06.nbt,8,WALL_BANNER:3,../../NBT/banners/JungleBanner07.nbt,8,WALL_BANNER:3,../../NBT/banners/JungleBanner08.nbt,8,WALL_BANNER:3,../../NBT/banners/JungleBanner09.nbt,8,WALL_BANNER:3,../../NBT/banners/JungleBanner10.nbt,8,WALL_BANNER:3,../../NBT/banners/JungleBanner11.nbt,8,WALL_BANNER:3,../../NBT/banners/JungleBanner12.nbt,8,WALL_BANNER:3,../../NBT/banners/JungleBanner13.nbt,8,WALL_BANNER:3,../../NBT/banners/JungleBanner14.nbt,8,WALL_BANNER:3,../../NBT/banners/JungleBanner15.nbt,8,WALL_BANNER:3,../../NBT/banners/JungleBanner16.nbt,8,WALL_BANNER:3,../../NBT/banners/JungleBanner17.nbt,8,WALL_BANNER:3,../../NBT/banners/JungleBanner18.nbt,8,WALL_BANNER:3,../../NBT/banners/JungleBanner19.nbt,8,WALL_BANNER:3,../../NBT/banners/JungleBanner20.nbt,100)
Block(-1,7,3,WOOD_STEP:8)
Block(0,7,3,WOOD_STEP:8)
Block(1,7,3,WOOD_STEP:8)
Block(2,7,3,WOOD_STEP:8)
RandomBlock(3,7,3,WALL_BANNER:3,../../NBT/banners/JungleBanner01.nbt,8,WALL_BANNER:3,../../NBT/banners/JungleBanner02.nbt,8,WALL_BANNER:3,../../NBT/banners/JungleBanner03.nbt,8,WALL_BANNER:3,../../NBT/banners/JungleBanner04.nbt,8,WALL_BANNER:3,../../NBT/banners/JungleBanner05.nbt,8,WALL_BANNER:3,../../NBT/banners/JungleBanner06.nbt,8,WALL_BANNER:3,../../NBT/banners/JungleBanner07.nbt,8,WALL_BANNER:3,../../NBT/banners/JungleBanner08.nbt,8,WALL_BANNER:3,../../NBT/banners/JungleBanner09.nbt,8,WALL_BANNER:3,../../NBT/banners/JungleBanner10.nbt,8,WALL_BANNER:3,../../NBT/banners/JungleBanner11.nbt,8,WALL_BANNER:3,../../NBT/banners/JungleBanner12.nbt,8,WALL_BANNER:3,../../NBT/banners/JungleBanner13.nbt,8,WALL_BANNER:3,../../NBT/banners/JungleBanner14.nbt,8,WALL_BANNER:3,../../NBT/banners/JungleBanner15.nbt,8,WALL_BANNER:3,../../NBT/banners/JungleBanner16.nbt,8,WALL_BANNER:3,../../NBT/banners/JungleBanner17.nbt,8,WALL_BANNER:3,../../NBT/banners/JungleBanner18.nbt,8,WALL_BANNER:3,../../NBT/banners/JungleBanner19.nbt,8,WALL_BANNER:3,../../NBT/banners/JungleBanner20.nbt,100)
Block(4,7,3,COBBLE_WALL)
Block(-5,7,6,TORCH)
Block(6,7,6,TORCH)
Block(-3,8,-4,JUNGLE_FENCE)
Block(4,8,-4,JUNGLE_FENCE)
Block(-1,8,-3,WOOD_STEP)
Block(0,8,-3,WOOD_STEP)
Block(1,8,-3,WOOD_STEP)
Block(2,8,-3,WOOD_STEP)
Block(-2,8,-2,WOOD_STEP)
Block(-1,8,-2,LOG:3)
Block(0,8,-2,WOOD_STEP)
Block(1,8,-2,WOOD_STEP)
Block(2,8,-2,LOG:3)
Block(3,8,-2,WOOD_STEP)
Block(-2,8,-1,WOOD_STEP)
Block(-1,8,-1,WOOD_STEP)
Block(2,8,-1,WOOD_STEP)
Block(3,8,-1,WOOD_STEP)
Block(4,8,-1,WOOD_STEP)
Block(-2,8,0,WOOD_STEP)
Block(-1,8,0,WOOD_STEP)
Block(2,8,0,WOOD_STEP)
Block(3,8,0,WOOD_STEP)
Block(4,8,0,WOOD_STEP)
Block(-2,8,1,WOOD_STEP)
Block(-1,8,1,LOG:3)
Block(0,8,1,WOOD_STEP)
Block(1,8,1,WOOD_STEP)
Block(2,8,1,LOG:3)
Block(3,8,1,WOOD_STEP)
Block(-1,8,2,WOOD_STEP)
Block(0,8,2,WOOD_STEP)
Block(1,8,2,WOOD_STEP)
Block(2,8,2,WOOD_STEP)
Block(-3,8,3,JUNGLE_FENCE)
Block(4,8,3,JUNGLE_FENCE)
Block(-3,9,-4,TORCH)
Block(4,9,-4,TORCH)
RandomBlock(0,9,-3,WALL_BANNER,../../NBT/banners/JungleBanner01.nbt,8,WALL_BANNER,../../NBT/banners/JungleBanner02.nbt,8,WALL_BANNER,../../NBT/banners/JungleBanner03.nbt,8,WALL_BANNER,../../NBT/banners/JungleBanner04.nbt,8,WALL_BANNER,../../NBT/banners/JungleBanner05.nbt,8,WALL_BANNER,../../NBT/banners/JungleBanner06.nbt,8,WALL_BANNER,../../NBT/banners/JungleBanner07.nbt,8,WALL_BANNER,../../NBT/banners/JungleBanner08.nbt,8,WALL_BANNER,../../NBT/banners/JungleBanner09.nbt,8,WALL_BANNER,../../NBT/banners/JungleBanner10.nbt,8,WALL_BANNER,../../NBT/banners/JungleBanner11.nbt,8,WALL_BANNER,../../NBT/banners/JungleBanner12.nbt,8,WALL_BANNER,../../NBT/banners/JungleBanner13.nbt,8,WALL_BANNER,../../NBT/banners/JungleBanner14.nbt,8,WALL_BANNER,../../NBT/banners/JungleBanner15.nbt,8,WALL_BANNER,../../NBT/banners/JungleBanner16.nbt,8,WALL_BANNER,../../NBT/banners/JungleBanner17.nbt,8,WALL_BANNER,../../NBT/banners/JungleBanner18.nbt,8,WALL_BANNER,../../NBT/banners/JungleBanner19.nbt,8,WALL_BANNER,../../NBT/banners/JungleBanner20.nbt,100)
RandomBlock(1,9,-3,WALL_BANNER,../../NBT/banners/JungleBanner01.nbt,8,WALL_BANNER,../../NBT/banners/JungleBanner02.nbt,8,WALL_BANNER,../../NBT/banners/JungleBanner03.nbt,8,WALL_BANNER,../../NBT/banners/JungleBanner04.nbt,8,WALL_BANNER,../../NBT/banners/JungleBanner05.nbt,8,WALL_BANNER,../../NBT/banners/JungleBanner06.nbt,8,WALL_BANNER,../../NBT/banners/JungleBanner07.nbt,8,WALL_BANNER,../../NBT/banners/JungleBanner08.nbt,8,WALL_BANNER,../../NBT/banners/JungleBanner09.nbt,8,WALL_BANNER,../../NBT/banners/JungleBanner10.nbt,8,WALL_BANNER,../../NBT/banners/JungleBanner11.nbt,8,WALL_BANNER,../../NBT/banners/JungleBanner12.nbt,8,WALL_BANNER,../../NBT/banners/JungleBanner13.nbt,8,WALL_BANNER,../../NBT/banners/JungleBanner14.nbt,8,WALL_BANNER,../../NBT/banners/JungleBanner15.nbt,8,WALL_BANNER,../../NBT/banners/JungleBanner16.nbt,8,WALL_BANNER,../../NBT/banners/JungleBanner17.nbt,8,WALL_BANNER,../../NBT/banners/JungleBanner18.nbt,8,WALL_BANNER,../../NBT/banners/JungleBanner19.nbt,8,WALL_BANNER,../../NBT/banners/JungleBanner20.nbt,100)
Block(-1,9,-2,JUNGLE_FENCE)
Block(0,9,-2,WOOD_STEP:8)
Block(1,9,-2,WOOD_STEP:8)
Block(2,9,-2,JUNGLE_FENCE)
RandomBlock(-2,9,-1,WALL_BANNER:4,../../NBT/banners/JungleBanner01.nbt,8,WALL_BANNER:4,../../NBT/banners/JungleBanner02.nbt,8,WALL_BANNER:4,../../NBT/banners/JungleBanner03.nbt,8,WALL_BANNER:4,../../NBT/banners/JungleBanner04.nbt,8,WALL_BANNER:4,../../NBT/banners/JungleBanner05.nbt,8,WALL_BANNER:4,../../NBT/banners/JungleBanner06.nbt,8,WALL_BANNER:4,../../NBT/banners/JungleBanner07.nbt,8,WALL_BANNER:4,../../NBT/banners/JungleBanner08.nbt,8,WALL_BANNER:4,../../NBT/banners/JungleBanner09.nbt,8,WALL_BANNER:4,../../NBT/banners/JungleBanner10.nbt,8,WALL_BANNER:4,../../NBT/banners/JungleBanner11.nbt,8,WALL_BANNER:4,../../NBT/banners/JungleBanner12.nbt,8,WALL_BANNER:4,../../NBT/banners/JungleBanner13.nbt,8,WALL_BANNER:4,../../NBT/banners/JungleBanner14.nbt,8,WALL_BANNER:4,../../NBT/banners/JungleBanner15.nbt,8,WALL_BANNER:4,../../NBT/banners/JungleBanner16.nbt,8,WALL_BANNER:4,../../NBT/banners/JungleBanner17.nbt,8,WALL_BANNER:4,../../NBT/banners/JungleBanner18.nbt,8,WALL_BANNER:4,../../NBT/banners/JungleBanner19.nbt,8,WALL_BANNER:4,../../NBT/banners/JungleBanner20.nbt,100)
Block(-1,9,-1,WOOD_STEP:8)
Block(2,9,-1,WOOD_STEP:8)
RandomBlock(3,9,-1,WALL_BANNER:5,../../NBT/banners/JungleBanner01.nbt,8,WALL_BANNER:5,../../NBT/banners/JungleBanner02.nbt,8,WALL_BANNER:5,../../NBT/banners/JungleBanner03.nbt,8,WALL_BANNER:5,../../NBT/banners/JungleBanner04.nbt,8,WALL_BANNER:5,../../NBT/banners/JungleBanner05.nbt,8,WALL_BANNER:5,../../NBT/banners/JungleBanner06.nbt,8,WALL_BANNER:5,../../NBT/banners/JungleBanner07.nbt,8,WALL_BANNER:5,../../NBT/banners/JungleBanner08.nbt,8,WALL_BANNER:5,../../NBT/banners/JungleBanner09.nbt,8,WALL_BANNER:5,../../NBT/banners/JungleBanner10.nbt,8,WALL_BANNER:5,../../NBT/banners/JungleBanner11.nbt,8,WALL_BANNER:5,../../NBT/banners/JungleBanner12.nbt,8,WALL_BANNER:5,../../NBT/banners/JungleBanner13.nbt,8,WALL_BANNER:5,../../NBT/banners/JungleBanner14.nbt,8,WALL_BANNER:5,../../NBT/banners/JungleBanner15.nbt,8,WALL_BANNER:5,../../NBT/banners/JungleBanner16.nbt,8,WALL_BANNER:5,../../NBT/banners/JungleBanner17.nbt,8,WALL_BANNER:5,../../NBT/banners/JungleBanner18.nbt,8,WALL_BANNER:5,../../NBT/banners/JungleBanner19.nbt,8,WALL_BANNER:5,../../NBT/banners/JungleBanner20.nbt,100)
RandomBlock(-2,9,0,WALL_BANNER:4,../../NBT/banners/JungleBanner01.nbt,8,WALL_BANNER:4,../../NBT/banners/JungleBanner02.nbt,8,WALL_BANNER:4,../../NBT/banners/JungleBanner03.nbt,8,WALL_BANNER:4,../../NBT/banners/JungleBanner04.nbt,8,WALL_BANNER:4,../../NBT/banners/JungleBanner05.nbt,8,WALL_BANNER:4,../../NBT/banners/JungleBanner06.nbt,8,WALL_BANNER:4,../../NBT/banners/JungleBanner07.nbt,8,WALL_BANNER:4,../../NBT/banners/JungleBanner08.nbt,8,WALL_BANNER:4,../../NBT/banners/JungleBanner09.nbt,8,WALL_BANNER:4,../../NBT/banners/JungleBanner10.nbt,8,WALL_BANNER:4,../../NBT/banners/JungleBanner11.nbt,8,WALL_BANNER:4,../../NBT/banners/JungleBanner12.nbt,8,WALL_BANNER:4,../../NBT/banners/JungleBanner13.nbt,8,WALL_BANNER:4,../../NBT/banners/JungleBanner14.nbt,8,WALL_BANNER:4,../../NBT/banners/JungleBanner15.nbt,8,WALL_BANNER:4,../../NBT/banners/JungleBanner16.nbt,8,WALL_BANNER:4,../../NBT/banners/JungleBanner17.nbt,8,WALL_BANNER:4,../../NBT/banners/JungleBanner18.nbt,8,WALL_BANNER:4,../../NBT/banners/JungleBanner19.nbt,8,WALL_BANNER:4,../../NBT/banners/JungleBanner20.nbt,100)
Block(-1,9,0,WOOD_STEP:8)
Block(2,9,0,WOOD_STEP:8)
RandomBlock(3,9,0,WALL_BANNER:5,../../NBT/banners/JungleBanner01.nbt,8,WALL_BANNER:5,../../NBT/banners/JungleBanner02.nbt,8,WALL_BANNER:5,../../NBT/banners/JungleBanner03.nbt,8,WALL_BANNER:5,../../NBT/banners/JungleBanner04.nbt,8,WALL_BANNER:5,../../NBT/banners/JungleBanner05.nbt,8,WALL_BANNER:5,../../NBT/banners/JungleBanner06.nbt,8,WALL_BANNER:5,../../NBT/banners/JungleBanner07.nbt,8,WALL_BANNER:5,../../NBT/banners/JungleBanner08.nbt,8,WALL_BANNER:5,../../NBT/banners/JungleBanner09.nbt,8,WALL_BANNER:5,../../NBT/banners/JungleBanner10.nbt,8,WALL_BANNER:5,../../NBT/banners/JungleBanner11.nbt,8,WALL_BANNER:5,../../NBT/banners/JungleBanner12.nbt,8,WALL_BANNER:5,../../NBT/banners/JungleBanner13.nbt,8,WALL_BANNER:5,../../NBT/banners/JungleBanner14.nbt,8,WALL_BANNER:5,../../NBT/banners/JungleBanner15.nbt,8,WALL_BANNER:5,../../NBT/banners/JungleBanner16.nbt,8,WALL_BANNER:5,../../NBT/banners/JungleBanner17.nbt,8,WALL_BANNER:5,../../NBT/banners/JungleBanner18.nbt,8,WALL_BANNER:5,../../NBT/banners/JungleBanner19.nbt,8,WALL_BANNER:5,../../NBT/banners/JungleBanner20.nbt,100)
Block(-1,9,1,JUNGLE_FENCE)
Block(0,9,1,WOOD_STEP:8)
Block(1,9,1,WOOD_STEP:8)
Block(2,9,1,JUNGLE_FENCE)
RandomBlock(0,9,2,WALL_BANNER:3,../../NBT/banners/JungleBanner01.nbt,8,WALL_BANNER:3,../../NBT/banners/JungleBanner02.nbt,8,WALL_BANNER:3,../../NBT/banners/JungleBanner03.nbt,8,WALL_BANNER:3,../../NBT/banners/JungleBanner04.nbt,8,WALL_BANNER:3,../../NBT/banners/JungleBanner05.nbt,8,WALL_BANNER:3,../../NBT/banners/JungleBanner06.nbt,8,WALL_BANNER:3,../../NBT/banners/JungleBanner07.nbt,8,WALL_BANNER:3,../../NBT/banners/JungleBanner08.nbt,8,WALL_BANNER:3,../../NBT/banners/JungleBanner09.nbt,8,WALL_BANNER:3,../../NBT/banners/JungleBanner10.nbt,8,WALL_BANNER:3,../../NBT/banners/JungleBanner11.nbt,8,WALL_BANNER:3,../../NBT/banners/JungleBanner12.nbt,8,WALL_BANNER:3,../../NBT/banners/JungleBanner13.nbt,8,WALL_BANNER:3,../../NBT/banners/JungleBanner14.nbt,8,WALL_BANNER:3,../../NBT/banners/JungleBanner15.nbt,8,WALL_BANNER:3,../../NBT/banners/JungleBanner16.nbt,8,WALL_BANNER:3,../../NBT/banners/JungleBanner17.nbt,8,WALL_BANNER:3,../../NBT/banners/JungleBanner18.nbt,8,WALL_BANNER:3,../../NBT/banners/JungleBanner19.nbt,8,WALL_BANNER:3,../../NBT/banners/JungleBanner20.nbt,100)
RandomBlock(1,9,2,WALL_BANNER:3,../../NBT/banners/JungleBanner01.nbt,8,WALL_BANNER:3,../../NBT/banners/JungleBanner02.nbt,8,WALL_BANNER:3,../../NBT/banners/JungleBanner03.nbt,8,WALL_BANNER:3,../../NBT/banners/JungleBanner04.nbt,8,WALL_BANNER:3,../../NBT/banners/JungleBanner05.nbt,8,WALL_BANNER:3,../../NBT/banners/JungleBanner06.nbt,8,WALL_BANNER:3,../../NBT/banners/JungleBanner07.nbt,8,WALL_BANNER:3,../../NBT/banners/JungleBanner08.nbt,8,WALL_BANNER:3,../../NBT/banners/JungleBanner09.nbt,8,WALL_BANNER:3,../../NBT/banners/JungleBanner10.nbt,8,WALL_BANNER:3,../../NBT/banners/JungleBanner11.nbt,8,WALL_BANNER:3,../../NBT/banners/JungleBanner12.nbt,8,WALL_BANNER:3,../../NBT/banners/JungleBanner13.nbt,8,WALL_BANNER:3,../../NBT/banners/JungleBanner14.nbt,8,WALL_BANNER:3,../../NBT/banners/JungleBanner15.nbt,8,WALL_BANNER:3,../../NBT/banners/JungleBanner16.nbt,8,WALL_BANNER:3,../../NBT/banners/JungleBanner17.nbt,8,WALL_BANNER:3,../../NBT/banners/JungleBanner18.nbt,8,WALL_BANNER:3,../../NBT/banners/JungleBanner19.nbt,8,WALL_BANNER:3,../../NBT/banners/JungleBanner20.nbt,100)
Block(-3,9,3,TORCH)
Block(4,9,3,TORCH)
Block(-1,10,-2,WOOD_STEP)
Block(2,10,-2,WOOD_STEP)
Block(0,10,-1,WOOD_STEP)
Block(1,10,-1,WOOD_STEP)
Block(0,10,0,WOOD_STEP)
Block(1,10,0,WOOD_STEP)
Block(-1,10,1,WOOD_STEP)
Block(2,10,1,WOOD_STEP)
Entity(-2,0,-5,minecraft:villager,1,../../NBT/entities/tribalkid.txt)
#Entity(4,0,0,minecraft:villager,1,../../NBT/entities/tribalguard.txt)
#Entity(-6,0,1,minecraft:villager,1,../../NBT/entities/tribalguard.txt)
#Entity(3,0,1,minecraft:villager,1,../../NBT/entities/tribalnative.txt)
#Entity(-1,0,2,minecraft:villager,1,../../NBT/entities/tribalnative.txt)
#Entity(1,0,4,minecraft:villager,1,../../NBT/entities/tribalnative.txt)
