
#######################################################################
# +-----------------------------------------------------------------+ #
# |                            BO4 object                           | #
# +-----------------------------------------------------------------+ #
#######################################################################


Author: NLBlackEagle

Description: No description given

SettingsMode: WriteDisable


#######################################################################
# +-----------------------------------------------------------------+ #
# |                          Main settings                          | #
# +-----------------------------------------------------------------+ #
#######################################################################

Frequency: 0

SpawnHeight: highestBlock

UseCenterForHighestBlock: true

##############################
# Height Limits for the BO4. #
##############################

MinHeight: 0

MaxHeight: 256

InheritBO3: 

InheritBO3Rotation: NORTH

OverrideChildSettings: true

OverrideParentHeight: false

CanOverride: true

BranchFrequency: 0

BranchFrequencyGroup: 

MustBeBelowOther: false

MustBeInside: 

CannotBeInside: 

ReplacesBO3: 

MustBeInsideWorldBorders: false

CanSpawnOnWater: true

SpawnOnWaterOnly: false

SpawnUnderWater: false

SpawnAtWaterLevel: false

HeightOffset: 0

RemoveAir: true

ReplaceAbove: 

ReplaceBelow: 

ReplaceWithBiomeBlocks: true

ReplaceWithSurfaceBlock: GRASS

ReplaceWithGroundBlock: DIRT

ReplaceWithStoneBlock: STONE

SmoothRadius: 0

SmoothHeightOffset: 0

SmoothStartTop: false

SmoothStartWood: false

SmoothingSurfaceBlock: 

SmoothingGroundBlock: 

BO3Group: 

IsSpawnPoint: false

DoReplaceBlocks: true


#######################################################################
# +-----------------------------------------------------------------+ #
# |                              Blocks                             | #
# +-----------------------------------------------------------------+ #
#######################################################################

Block(-7,0,-6,CONCRETE:15)
Block(-7,0,-4,CONCRETE:15)
RandomBlock(-7,0,-2,CONCRETE:7,70,STAINED_CLAY:12,15,STAINED_CLAY:15,5,CONCRETE:7,100)
RandomBlock(-7,0,-1,CONCRETE:7,70,STAINED_CLAY:12,15,STAINED_CLAY:15,5,CONCRETE:7,100)
RandomBlock(-7,0,0,CONCRETE:7,70,STAINED_CLAY:12,15,STAINED_CLAY:15,5,CONCRETE:7,100)
RandomBlock(-7,0,1,CONCRETE:7,70,STAINED_CLAY:12,15,STAINED_CLAY:15,5,CONCRETE:7,100)
RandomBlock(-7,0,2,CONCRETE:7,70,STAINED_CLAY:12,15,STAINED_CLAY:15,5,CONCRETE:7,100)
RandomBlock(-7,0,3,CONCRETE:7,70,STAINED_CLAY:12,15,STAINED_CLAY:15,5,CONCRETE:7,100)
Block(-7,0,5,CONCRETE:15)
Block(-7,0,7,CONCRETE:15)
Block(-7,1,-6,CONCRETE:15)
Block(-7,1,-4,CONCRETE:15)
RandomBlock(-7,1,-2,CONCRETE:7,70,STAINED_CLAY:12,15,STAINED_CLAY:15,5,CONCRETE:7,100)
RandomBlock(-7,1,-1,CONCRETE:7,70,STAINED_CLAY:12,15,STAINED_CLAY:15,5,CONCRETE:7,100)
RandomBlock(-7,1,0,CONCRETE:7,70,STAINED_CLAY:12,15,STAINED_CLAY:15,5,CONCRETE:7,100)
RandomBlock(-7,1,1,CONCRETE:7,70,STAINED_CLAY:12,15,STAINED_CLAY:15,5,CONCRETE:7,100)
RandomBlock(-7,1,2,CONCRETE:7,70,STAINED_CLAY:12,15,STAINED_CLAY:15,5,CONCRETE:7,100)
RandomBlock(-7,1,3,CONCRETE:7,70,STAINED_CLAY:12,15,STAINED_CLAY:15,5,CONCRETE:7,100)
Block(-7,1,5,CONCRETE:15)
Block(-7,1,7,CONCRETE:15)
Block(-7,2,-6,CONCRETE:15)
Block(-7,2,-4,CONCRETE:15)
RandomBlock(-7,2,-2,CONCRETE:7,70,STAINED_CLAY:12,15,STAINED_CLAY:15,5,CONCRETE:7,100)
RandomBlock(-7,2,-1,CONCRETE:7,70,STAINED_CLAY:12,15,STAINED_CLAY:15,5,CONCRETE:7,100)
RandomBlock(-7,2,0,CONCRETE:7,70,STAINED_CLAY:12,15,STAINED_CLAY:15,5,CONCRETE:7,100)
RandomBlock(-7,2,1,CONCRETE:7,70,STAINED_CLAY:12,15,STAINED_CLAY:15,5,CONCRETE:7,100)
RandomBlock(-7,2,2,CONCRETE:7,70,STAINED_CLAY:12,15,STAINED_CLAY:15,5,CONCRETE:7,100)
RandomBlock(-7,2,3,CONCRETE:7,70,STAINED_CLAY:12,15,STAINED_CLAY:15,5,CONCRETE:7,100)
Block(-7,2,5,CONCRETE:15)
Block(-7,2,7,CONCRETE:15)
Block(-7,3,-6,CONCRETE:15)
Block(-7,3,-4,CONCRETE:15)
RandomBlock(-7,3,-2,CONCRETE:7,70,STAINED_CLAY:12,15,STAINED_CLAY:15,5,CONCRETE:7,100)
RandomBlock(-7,3,-1,CONCRETE:7,70,STAINED_CLAY:12,15,STAINED_CLAY:15,5,CONCRETE:7,100)
RandomBlock(-7,3,0,CONCRETE:7,70,STAINED_CLAY:12,15,STAINED_CLAY:15,5,CONCRETE:7,100)
RandomBlock(-7,3,1,CONCRETE:7,70,STAINED_CLAY:12,15,STAINED_CLAY:15,5,CONCRETE:7,100)
RandomBlock(-7,3,2,CONCRETE:7,70,STAINED_CLAY:12,15,STAINED_CLAY:15,5,CONCRETE:7,100)
RandomBlock(-7,3,3,CONCRETE:7,70,STAINED_CLAY:12,15,STAINED_CLAY:15,5,CONCRETE:7,100)
Block(-7,3,5,CONCRETE:15)
Block(-7,3,7,CONCRETE:15)
Block(-7,4,-6,CONCRETE:15)
Block(-7,4,-4,CONCRETE:15)
RandomBlock(-7,4,-2,CONCRETE:7,70,STAINED_CLAY:12,15,STAINED_CLAY:15,5,CONCRETE:7,100)
RandomBlock(-7,4,-1,CONCRETE:7,70,STAINED_CLAY:12,15,STAINED_CLAY:15,5,CONCRETE:7,100)
RandomBlock(-7,4,0,CONCRETE:7,70,STAINED_CLAY:12,15,STAINED_CLAY:15,5,CONCRETE:7,100)
RandomBlock(-7,4,1,CONCRETE:7,70,STAINED_CLAY:12,15,STAINED_CLAY:15,5,CONCRETE:7,100)
RandomBlock(-7,4,2,CONCRETE:7,70,STAINED_CLAY:12,15,STAINED_CLAY:15,5,CONCRETE:7,100)
RandomBlock(-7,4,3,CONCRETE:7,70,STAINED_CLAY:12,15,STAINED_CLAY:15,5,CONCRETE:7,100)
Block(-7,4,5,CONCRETE:15)
Block(-7,4,7,CONCRETE:15)
Block(-7,5,-6,CONCRETE:15)
Block(-7,5,-4,CONCRETE:15)
RandomBlock(-7,5,-2,CONCRETE:7,70,STAINED_CLAY:12,15,STAINED_CLAY:15,5,CONCRETE:7,100)
RandomBlock(-7,5,-1,CONCRETE:7,70,STAINED_CLAY:12,15,STAINED_CLAY:15,5,CONCRETE:7,100)
RandomBlock(-7,5,0,CONCRETE:7,70,STAINED_CLAY:12,15,STAINED_CLAY:15,5,CONCRETE:7,100)
RandomBlock(-7,5,1,CONCRETE:7,70,STAINED_CLAY:12,15,STAINED_CLAY:15,5,CONCRETE:7,100)
RandomBlock(-7,5,2,CONCRETE:7,70,STAINED_CLAY:12,15,STAINED_CLAY:15,5,CONCRETE:7,100)
RandomBlock(-7,5,3,CONCRETE:7,70,STAINED_CLAY:12,15,STAINED_CLAY:15,5,CONCRETE:7,100)
Block(-7,5,5,CONCRETE:15)
Block(-7,5,7,CONCRETE:15)
Block(-7,6,-6,CONCRETE:15)
Block(-7,6,-4,CONCRETE:15)
RandomBlock(-7,6,-2,CONCRETE:7,70,STAINED_CLAY:12,15,STAINED_CLAY:15,5,CONCRETE:7,100)
RandomBlock(-7,6,-1,CONCRETE:7,70,STAINED_CLAY:12,15,STAINED_CLAY:15,5,CONCRETE:7,100)
RandomBlock(-7,6,0,CONCRETE:7,70,STAINED_CLAY:12,15,STAINED_CLAY:15,5,CONCRETE:7,100)
RandomBlock(-7,6,1,CONCRETE:7,70,STAINED_CLAY:12,15,STAINED_CLAY:15,5,CONCRETE:7,100)
RandomBlock(-7,6,2,CONCRETE:7,70,STAINED_CLAY:12,15,STAINED_CLAY:15,5,CONCRETE:7,100)
RandomBlock(-7,6,3,CONCRETE:7,70,STAINED_CLAY:12,15,STAINED_CLAY:15,5,CONCRETE:7,100)
Block(-7,6,5,CONCRETE:15)
Block(-7,6,7,CONCRETE:15)
Block(-7,7,-6,CONCRETE:15)
Block(-7,7,-4,CONCRETE:15)
RandomBlock(-7,7,-2,CONCRETE:7,70,STAINED_CLAY:12,15,STAINED_CLAY:15,5,CONCRETE:7,100)
RandomBlock(-7,7,-1,CONCRETE:7,70,STAINED_CLAY:12,15,STAINED_CLAY:15,5,CONCRETE:7,100)
RandomBlock(-7,7,0,CONCRETE:7,70,STAINED_CLAY:12,15,STAINED_CLAY:15,5,CONCRETE:7,100)
RandomBlock(-7,7,1,CONCRETE:7,70,STAINED_CLAY:12,15,STAINED_CLAY:15,5,CONCRETE:7,100)
RandomBlock(-7,7,2,CONCRETE:7,70,STAINED_CLAY:12,15,STAINED_CLAY:15,5,CONCRETE:7,100)
RandomBlock(-7,7,3,CONCRETE:7,70,STAINED_CLAY:12,15,STAINED_CLAY:15,5,CONCRETE:7,100)
Block(-7,7,5,CONCRETE:15)
Block(-7,7,7,CONCRETE:15)
Block(-7,8,-6,CONCRETE:15)
Block(-7,8,-4,CONCRETE:15)
RandomBlock(-7,8,-2,CONCRETE:7,70,STAINED_CLAY:12,15,STAINED_CLAY:15,5,CONCRETE:7,100)
RandomBlock(-7,8,-1,CONCRETE:7,70,STAINED_CLAY:12,15,STAINED_CLAY:15,5,CONCRETE:7,100)
RandomBlock(-7,8,0,CONCRETE:7,70,STAINED_CLAY:12,15,STAINED_CLAY:15,5,CONCRETE:7,100)
RandomBlock(-7,8,1,CONCRETE:7,70,STAINED_CLAY:12,15,STAINED_CLAY:15,5,CONCRETE:7,100)
RandomBlock(-7,8,2,CONCRETE:7,70,STAINED_CLAY:12,15,STAINED_CLAY:15,5,CONCRETE:7,100)
RandomBlock(-7,8,3,CONCRETE:7,70,STAINED_CLAY:12,15,STAINED_CLAY:15,5,CONCRETE:7,100)
Block(-7,8,5,CONCRETE:15)
Block(-7,8,7,CONCRETE:15)
Block(-7,9,-6,CONCRETE:15)
Block(-7,9,-4,CONCRETE:15)
RandomBlock(-7,9,-2,CONCRETE:7,70,STAINED_CLAY:12,15,STAINED_CLAY:15,5,CONCRETE:7,100)
RandomBlock(-7,9,-1,CONCRETE:7,70,STAINED_CLAY:12,15,STAINED_CLAY:15,5,CONCRETE:7,100)
RandomBlock(-7,9,0,CONCRETE:7,70,STAINED_CLAY:12,15,STAINED_CLAY:15,5,CONCRETE:7,100)
RandomBlock(-7,9,1,CONCRETE:7,70,STAINED_CLAY:12,15,STAINED_CLAY:15,5,CONCRETE:7,100)
RandomBlock(-7,9,2,CONCRETE:7,70,STAINED_CLAY:12,15,STAINED_CLAY:15,5,CONCRETE:7,100)
RandomBlock(-7,9,3,CONCRETE:7,70,STAINED_CLAY:12,15,STAINED_CLAY:15,5,CONCRETE:7,100)
Block(-7,9,5,CONCRETE:15)
Block(-7,9,7,CONCRETE:15)
RandomBlock(-6,0,-2,CONCRETE:7,70,STAINED_CLAY:12,15,STAINED_CLAY:15,5,CONCRETE:7,100)
RandomBlock(-6,0,-1,CONCRETE:7,70,STAINED_CLAY:12,15,STAINED_CLAY:15,5,CONCRETE:7,100)
RandomBlock(-6,0,0,CONCRETE:7,70,STAINED_CLAY:12,15,STAINED_CLAY:15,5,CONCRETE:7,100)
RandomBlock(-6,0,1,CONCRETE:7,70,STAINED_CLAY:12,15,STAINED_CLAY:15,5,CONCRETE:7,100)
RandomBlock(-6,0,2,CONCRETE:7,70,STAINED_CLAY:12,15,STAINED_CLAY:15,5,CONCRETE:7,100)
RandomBlock(-6,0,3,CONCRETE:7,70,STAINED_CLAY:12,15,STAINED_CLAY:15,5,CONCRETE:7,100)
RandomBlock(-6,1,-2,CONCRETE:7,70,STAINED_CLAY:12,15,STAINED_CLAY:15,5,CONCRETE:7,100)
RandomBlock(-6,1,-1,CONCRETE:7,70,STAINED_CLAY:12,15,STAINED_CLAY:15,5,CONCRETE:7,100)
RandomBlock(-6,1,0,CONCRETE:7,70,STAINED_CLAY:12,15,STAINED_CLAY:15,5,CONCRETE:7,100)
RandomBlock(-6,1,1,CONCRETE:7,70,STAINED_CLAY:12,15,STAINED_CLAY:15,5,CONCRETE:7,100)
RandomBlock(-6,1,2,CONCRETE:7,70,STAINED_CLAY:12,15,STAINED_CLAY:15,5,CONCRETE:7,100)
RandomBlock(-6,1,3,CONCRETE:7,70,STAINED_CLAY:12,15,STAINED_CLAY:15,5,CONCRETE:7,100)
RandomBlock(-6,2,-2,CONCRETE:7,70,STAINED_CLAY:12,15,STAINED_CLAY:15,5,CONCRETE:7,100)
RandomBlock(-6,2,-1,CONCRETE:7,70,STAINED_CLAY:12,15,STAINED_CLAY:15,5,CONCRETE:7,100)
RandomBlock(-6,2,0,CONCRETE:7,70,STAINED_CLAY:12,15,STAINED_CLAY:15,5,CONCRETE:7,100)
RandomBlock(-6,2,1,CONCRETE:7,70,STAINED_CLAY:12,15,STAINED_CLAY:15,5,CONCRETE:7,100)
RandomBlock(-6,2,2,CONCRETE:7,70,STAINED_CLAY:12,15,STAINED_CLAY:15,5,CONCRETE:7,100)
RandomBlock(-6,2,3,CONCRETE:7,70,STAINED_CLAY:12,15,STAINED_CLAY:15,5,CONCRETE:7,100)
RandomBlock(-6,3,-2,CONCRETE:7,70,STAINED_CLAY:12,15,STAINED_CLAY:15,5,CONCRETE:7,100)
RandomBlock(-6,3,-1,CONCRETE:7,70,STAINED_CLAY:12,15,STAINED_CLAY:15,5,CONCRETE:7,100)
RandomBlock(-6,3,0,CONCRETE:7,70,STAINED_CLAY:12,15,STAINED_CLAY:15,5,CONCRETE:7,100)
RandomBlock(-6,3,1,CONCRETE:7,70,STAINED_CLAY:12,15,STAINED_CLAY:15,5,CONCRETE:7,100)
RandomBlock(-6,3,2,CONCRETE:7,70,STAINED_CLAY:12,15,STAINED_CLAY:15,5,CONCRETE:7,100)
RandomBlock(-6,3,3,CONCRETE:7,70,STAINED_CLAY:12,15,STAINED_CLAY:15,5,CONCRETE:7,100)
RandomBlock(-6,4,-2,CONCRETE:7,70,STAINED_CLAY:12,15,STAINED_CLAY:15,5,CONCRETE:7,100)
RandomBlock(-6,4,-1,CONCRETE:7,70,STAINED_CLAY:12,15,STAINED_CLAY:15,5,CONCRETE:7,100)
RandomBlock(-6,4,0,CONCRETE:7,70,STAINED_CLAY:12,15,STAINED_CLAY:15,5,CONCRETE:7,100)
RandomBlock(-6,4,1,CONCRETE:7,70,STAINED_CLAY:12,15,STAINED_CLAY:15,5,CONCRETE:7,100)
RandomBlock(-6,4,2,CONCRETE:7,70,STAINED_CLAY:12,15,STAINED_CLAY:15,5,CONCRETE:7,100)
RandomBlock(-6,4,3,CONCRETE:7,70,STAINED_CLAY:12,15,STAINED_CLAY:15,5,CONCRETE:7,100)
RandomBlock(-6,5,-2,CONCRETE:7,70,STAINED_CLAY:12,15,STAINED_CLAY:15,5,CONCRETE:7,100)
RandomBlock(-6,5,-1,CONCRETE:7,70,STAINED_CLAY:12,15,STAINED_CLAY:15,5,CONCRETE:7,100)
RandomBlock(-6,5,0,CONCRETE:7,70,STAINED_CLAY:12,15,STAINED_CLAY:15,5,CONCRETE:7,100)
RandomBlock(-6,5,1,CONCRETE:7,70,STAINED_CLAY:12,15,STAINED_CLAY:15,5,CONCRETE:7,100)
RandomBlock(-6,5,2,CONCRETE:7,70,STAINED_CLAY:12,15,STAINED_CLAY:15,5,CONCRETE:7,100)
RandomBlock(-6,5,3,CONCRETE:7,70,STAINED_CLAY:12,15,STAINED_CLAY:15,5,CONCRETE:7,100)
RandomBlock(-6,6,-2,CONCRETE:7,70,STAINED_CLAY:12,15,STAINED_CLAY:15,5,CONCRETE:7,100)
RandomBlock(-6,6,-1,CONCRETE:7,70,STAINED_CLAY:12,15,STAINED_CLAY:15,5,CONCRETE:7,100)
RandomBlock(-6,6,0,CONCRETE:7,70,STAINED_CLAY:12,15,STAINED_CLAY:15,5,CONCRETE:7,100)
RandomBlock(-6,6,1,CONCRETE:7,70,STAINED_CLAY:12,15,STAINED_CLAY:15,5,CONCRETE:7,100)
RandomBlock(-6,6,2,CONCRETE:7,70,STAINED_CLAY:12,15,STAINED_CLAY:15,5,CONCRETE:7,100)
RandomBlock(-6,6,3,CONCRETE:7,70,STAINED_CLAY:12,15,STAINED_CLAY:15,5,CONCRETE:7,100)
RandomBlock(-6,7,-2,CONCRETE:7,70,STAINED_CLAY:12,15,STAINED_CLAY:15,5,CONCRETE:7,100)
RandomBlock(-6,7,-1,CONCRETE:7,70,STAINED_CLAY:12,15,STAINED_CLAY:15,5,CONCRETE:7,100)
RandomBlock(-6,7,0,CONCRETE:7,70,STAINED_CLAY:12,15,STAINED_CLAY:15,5,CONCRETE:7,100)
RandomBlock(-6,7,1,CONCRETE:7,70,STAINED_CLAY:12,15,STAINED_CLAY:15,5,CONCRETE:7,100)
RandomBlock(-6,7,2,CONCRETE:7,70,STAINED_CLAY:12,15,STAINED_CLAY:15,5,CONCRETE:7,100)
RandomBlock(-6,7,3,CONCRETE:7,70,STAINED_CLAY:12,15,STAINED_CLAY:15,5,CONCRETE:7,100)
RandomBlock(-6,8,-2,CONCRETE:7,70,STAINED_CLAY:12,15,STAINED_CLAY:15,5,CONCRETE:7,100)
RandomBlock(-6,8,-1,CONCRETE:7,70,STAINED_CLAY:12,15,STAINED_CLAY:15,5,CONCRETE:7,100)
RandomBlock(-6,8,0,CONCRETE:7,70,STAINED_CLAY:12,15,STAINED_CLAY:15,5,CONCRETE:7,100)
RandomBlock(-6,8,1,CONCRETE:7,70,STAINED_CLAY:12,15,STAINED_CLAY:15,5,CONCRETE:7,100)
RandomBlock(-6,8,2,CONCRETE:7,70,STAINED_CLAY:12,15,STAINED_CLAY:15,5,CONCRETE:7,100)
RandomBlock(-6,8,3,CONCRETE:7,70,STAINED_CLAY:12,15,STAINED_CLAY:15,5,CONCRETE:7,100)
RandomBlock(-6,9,-2,CONCRETE:7,70,STAINED_CLAY:12,15,STAINED_CLAY:15,5,CONCRETE:7,100)
RandomBlock(-6,9,-1,CONCRETE:7,70,STAINED_CLAY:12,15,STAINED_CLAY:15,5,CONCRETE:7,100)
RandomBlock(-6,9,0,CONCRETE:7,70,STAINED_CLAY:12,15,STAINED_CLAY:15,5,CONCRETE:7,100)
RandomBlock(-6,9,1,CONCRETE:7,70,STAINED_CLAY:12,15,STAINED_CLAY:15,5,CONCRETE:7,100)
RandomBlock(-6,9,2,CONCRETE:7,70,STAINED_CLAY:12,15,STAINED_CLAY:15,5,CONCRETE:7,100)
RandomBlock(-6,9,3,CONCRETE:7,70,STAINED_CLAY:12,15,STAINED_CLAY:15,5,CONCRETE:7,100)
RandomBlock(-5,0,-2,CONCRETE:7,70,STAINED_CLAY:12,15,STAINED_CLAY:15,5,CONCRETE:7,100)
Block(-5,0,-1,AIR:0)
Block(-5,0,0,AIR:0)
Block(-5,0,1,AIR:0)
Block(-5,0,2,AIR:0)
RandomBlock(-5,0,3,CONCRETE:7,70,STAINED_CLAY:12,15,STAINED_CLAY:15,5,CONCRETE:7,100)
RandomBlock(-5,1,-2,CONCRETE:7,70,STAINED_CLAY:12,15,STAINED_CLAY:15,5,CONCRETE:7,100)
Block(-5,1,-1,AIR:0)
Block(-5,1,0,AIR:0)
Block(-5,1,1,AIR:0)
Block(-5,1,2,AIR:0)
RandomBlock(-5,1,3,CONCRETE:7,70,STAINED_CLAY:12,15,STAINED_CLAY:15,5,CONCRETE:7,100)
RandomBlock(-5,2,-2,CONCRETE:7,70,STAINED_CLAY:12,15,STAINED_CLAY:15,5,CONCRETE:7,100)
Block(-5,2,-1,AIR:0)
Block(-5,2,0,AIR:0)
Block(-5,2,1,AIR:0)
Block(-5,2,2,AIR:0)
RandomBlock(-5,2,3,CONCRETE:7,70,STAINED_CLAY:12,15,STAINED_CLAY:15,5,CONCRETE:7,100)
RandomBlock(-5,3,-2,CONCRETE:7,70,STAINED_CLAY:12,15,STAINED_CLAY:15,5,CONCRETE:7,100)
Block(-5,3,-1,AIR:0)
Block(-5,3,0,AIR:0)
Block(-5,3,1,AIR:0)
Block(-5,3,2,AIR:0)
RandomBlock(-5,3,3,CONCRETE:7,70,STAINED_CLAY:12,15,STAINED_CLAY:15,5,CONCRETE:7,100)
RandomBlock(-5,4,-2,CONCRETE:7,70,STAINED_CLAY:12,15,STAINED_CLAY:15,5,CONCRETE:7,100)
Block(-5,4,-1,AIR:0)
Block(-5,4,0,AIR:0)
Block(-5,4,1,AIR:0)
Block(-5,4,2,AIR:0)
RandomBlock(-5,4,3,CONCRETE:7,70,STAINED_CLAY:12,15,STAINED_CLAY:15,5,CONCRETE:7,100)
RandomBlock(-5,5,-2,CONCRETE:7,70,STAINED_CLAY:12,15,STAINED_CLAY:15,5,CONCRETE:7,100)
Block(-5,5,-1,AIR:0)
Block(-5,5,0,AIR:0)
Block(-5,5,1,AIR:0)
Block(-5,5,2,AIR:0)
RandomBlock(-5,5,3,CONCRETE:7,70,STAINED_CLAY:12,15,STAINED_CLAY:15,5,CONCRETE:7,100)
RandomBlock(-5,6,-2,CONCRETE:7,70,STAINED_CLAY:12,15,STAINED_CLAY:15,5,CONCRETE:7,100)
Block(-5,6,-1,AIR:0)
Block(-5,6,0,AIR:0)
Block(-5,6,1,AIR:0)
Block(-5,6,2,AIR:0)
RandomBlock(-5,6,3,CONCRETE:7,70,STAINED_CLAY:12,15,STAINED_CLAY:15,5,CONCRETE:7,100)
RandomBlock(-5,7,-2,CONCRETE:7,70,STAINED_CLAY:12,15,STAINED_CLAY:15,5,CONCRETE:7,100)
Block(-5,7,-1,AIR:0)
Block(-5,7,0,AIR:0)
Block(-5,7,1,AIR:0)
Block(-5,7,2,AIR:0)
RandomBlock(-5,7,3,CONCRETE:7,70,STAINED_CLAY:12,15,STAINED_CLAY:15,5,CONCRETE:7,100)
RandomBlock(-5,8,-2,CONCRETE:7,70,STAINED_CLAY:12,15,STAINED_CLAY:15,5,CONCRETE:7,100)
Block(-5,8,-1,AIR:0)
Block(-5,8,0,AIR:0)
Block(-5,8,1,AIR:0)
Block(-5,8,2,AIR:0)
RandomBlock(-5,8,3,CONCRETE:7,70,STAINED_CLAY:12,15,STAINED_CLAY:15,5,CONCRETE:7,100)
RandomBlock(-5,9,-2,CONCRETE:7,70,STAINED_CLAY:12,15,STAINED_CLAY:15,5,CONCRETE:7,100)
Block(-5,9,-1,AIR:0)
Block(-5,9,0,AIR:0)
Block(-5,9,1,AIR:0)
Block(-5,9,2,AIR:0)
RandomBlock(-5,9,3,CONCRETE:7,70,STAINED_CLAY:12,15,STAINED_CLAY:15,5,CONCRETE:7,100)
RandomBlock(-4,0,-2,CONCRETE:7,70,STAINED_CLAY:12,15,STAINED_CLAY:15,5,CONCRETE:7,100)
Block(-4,0,-1,AIR:0)
Block(-4,0,0,AIR:0)
Block(-4,0,1,AIR:0)
Block(-4,0,2,AIR:0)
RandomBlock(-4,0,3,CONCRETE:7,70,STAINED_CLAY:12,15,STAINED_CLAY:15,5,CONCRETE:7,100)
RandomBlock(-4,1,-2,CONCRETE:7,70,STAINED_CLAY:12,15,STAINED_CLAY:15,5,CONCRETE:7,100)
Block(-4,1,-1,AIR:0)
Block(-4,1,0,AIR:0)
Block(-4,1,1,AIR:0)
Block(-4,1,2,AIR:0)
RandomBlock(-4,1,3,CONCRETE:7,70,STAINED_CLAY:12,15,STAINED_CLAY:15,5,CONCRETE:7,100)
RandomBlock(-4,2,-2,CONCRETE:7,70,STAINED_CLAY:12,15,STAINED_CLAY:15,5,CONCRETE:7,100)
Block(-4,2,-1,AIR:0)
Block(-4,2,0,AIR:0)
Block(-4,2,1,AIR:0)
Block(-4,2,2,AIR:0)
RandomBlock(-4,2,3,CONCRETE:7,70,STAINED_CLAY:12,15,STAINED_CLAY:15,5,CONCRETE:7,100)
RandomBlock(-4,3,-2,CONCRETE:7,70,STAINED_CLAY:12,15,STAINED_CLAY:15,5,CONCRETE:7,100)
Block(-4,3,-1,AIR:0)
Block(-4,3,0,AIR:0)
Block(-4,3,1,AIR:0)
Block(-4,3,2,AIR:0)
RandomBlock(-4,3,3,CONCRETE:7,70,STAINED_CLAY:12,15,STAINED_CLAY:15,5,CONCRETE:7,100)
RandomBlock(-4,4,-2,CONCRETE:7,70,STAINED_CLAY:12,15,STAINED_CLAY:15,5,CONCRETE:7,100)
Block(-4,4,-1,AIR:0)
Block(-4,4,0,AIR:0)
Block(-4,4,1,AIR:0)
Block(-4,4,2,AIR:0)
RandomBlock(-4,4,3,CONCRETE:7,70,STAINED_CLAY:12,15,STAINED_CLAY:15,5,CONCRETE:7,100)
RandomBlock(-4,5,-2,CONCRETE:7,70,STAINED_CLAY:12,15,STAINED_CLAY:15,5,CONCRETE:7,100)
Block(-4,5,-1,AIR:0)
Block(-4,5,0,AIR:0)
Block(-4,5,1,AIR:0)
Block(-4,5,2,AIR:0)
RandomBlock(-4,5,3,CONCRETE:7,70,STAINED_CLAY:12,15,STAINED_CLAY:15,5,CONCRETE:7,100)
RandomBlock(-4,6,-2,CONCRETE:7,70,STAINED_CLAY:12,15,STAINED_CLAY:15,5,CONCRETE:7,100)
Block(-4,6,-1,AIR:0)
Block(-4,6,0,AIR:0)
Block(-4,6,1,AIR:0)
Block(-4,6,2,AIR:0)
RandomBlock(-4,6,3,CONCRETE:7,70,STAINED_CLAY:12,15,STAINED_CLAY:15,5,CONCRETE:7,100)
RandomBlock(-4,7,-2,CONCRETE:7,70,STAINED_CLAY:12,15,STAINED_CLAY:15,5,CONCRETE:7,100)
Block(-4,7,-1,AIR:0)
Block(-4,7,0,AIR:0)
Block(-4,7,1,AIR:0)
Block(-4,7,2,AIR:0)
RandomBlock(-4,7,3,CONCRETE:7,70,STAINED_CLAY:12,15,STAINED_CLAY:15,5,CONCRETE:7,100)
RandomBlock(-4,8,-2,CONCRETE:7,70,STAINED_CLAY:12,15,STAINED_CLAY:15,5,CONCRETE:7,100)
Block(-4,8,-1,AIR:0)
Block(-4,8,0,AIR:0)
Block(-4,8,1,AIR:0)
Block(-4,8,2,AIR:0)
RandomBlock(-4,8,3,CONCRETE:7,70,STAINED_CLAY:12,15,STAINED_CLAY:15,5,CONCRETE:7,100)
RandomBlock(-4,9,-2,CONCRETE:7,70,STAINED_CLAY:12,15,STAINED_CLAY:15,5,CONCRETE:7,100)
Block(-4,9,-1,AIR:0)
Block(-4,9,0,AIR:0)
Block(-4,9,1,AIR:0)
Block(-4,9,2,AIR:0)
RandomBlock(-4,9,3,CONCRETE:7,70,STAINED_CLAY:12,15,STAINED_CLAY:15,5,CONCRETE:7,100)
RandomBlock(-3,0,-2,CONCRETE:7,70,STAINED_CLAY:12,15,STAINED_CLAY:15,5,CONCRETE:7,100)
Block(-3,0,-1,AIR:0)
Block(-3,0,0,COBBLE_WALL:0)
Block(-3,0,1,COBBLE_WALL:0)
Block(-3,0,2,AIR:0)
RandomBlock(-3,0,3,CONCRETE:7,70,STAINED_CLAY:12,15,STAINED_CLAY:15,5,CONCRETE:7,100)
RandomBlock(-3,1,-2,CONCRETE:7,70,STAINED_CLAY:12,15,STAINED_CLAY:15,5,CONCRETE:7,100)
Block(-3,1,-1,AIR:0)
Block(-3,1,0,COBBLE_WALL:0)
Block(-3,1,1,COBBLE_WALL:0)
Block(-3,1,2,AIR:0)
RandomBlock(-3,1,3,CONCRETE:7,70,STAINED_CLAY:12,15,STAINED_CLAY:15,5,CONCRETE:7,100)
RandomBlock(-3,2,-2,CONCRETE:7,70,STAINED_CLAY:12,15,STAINED_CLAY:15,5,CONCRETE:7,100)
Block(-3,2,-1,AIR:0)
Block(-3,2,0,COBBLE_WALL:0)
Block(-3,2,1,COBBLE_WALL:0)
Block(-3,2,2,AIR:0)
RandomBlock(-3,2,3,CONCRETE:7,70,STAINED_CLAY:12,15,STAINED_CLAY:15,5,CONCRETE:7,100)
RandomBlock(-3,3,-2,CONCRETE:7,70,STAINED_CLAY:12,15,STAINED_CLAY:15,5,CONCRETE:7,100)
Block(-3,3,-1,AIR:0)
Block(-3,3,0,COBBLE_WALL:0)
Block(-3,3,1,COBBLE_WALL:0)
Block(-3,3,2,AIR:0)
RandomBlock(-3,3,3,CONCRETE:7,70,STAINED_CLAY:12,15,STAINED_CLAY:15,5,CONCRETE:7,100)
RandomBlock(-3,4,-2,CONCRETE:7,70,STAINED_CLAY:12,15,STAINED_CLAY:15,5,CONCRETE:7,100)
Block(-3,4,-1,AIR:0)
Block(-3,4,0,COBBLE_WALL:0)
Block(-3,4,1,COBBLE_WALL:0)
Block(-3,4,2,AIR:0)
RandomBlock(-3,4,3,CONCRETE:7,70,STAINED_CLAY:12,15,STAINED_CLAY:15,5,CONCRETE:7,100)
RandomBlock(-3,5,-2,CONCRETE:7,70,STAINED_CLAY:12,15,STAINED_CLAY:15,5,CONCRETE:7,100)
Block(-3,5,-1,AIR:0)
Block(-3,5,0,COBBLE_WALL:0)
Block(-3,5,1,COBBLE_WALL:0)
Block(-3,5,2,AIR:0)
RandomBlock(-3,5,3,CONCRETE:7,70,STAINED_CLAY:12,15,STAINED_CLAY:15,5,CONCRETE:7,100)
RandomBlock(-3,6,-2,CONCRETE:7,70,STAINED_CLAY:12,15,STAINED_CLAY:15,5,CONCRETE:7,100)
Block(-3,6,-1,AIR:0)
Block(-3,6,0,COBBLE_WALL:0)
Block(-3,6,1,COBBLE_WALL:0)
Block(-3,6,2,AIR:0)
RandomBlock(-3,6,3,CONCRETE:7,70,STAINED_CLAY:12,15,STAINED_CLAY:15,5,CONCRETE:7,100)
RandomBlock(-3,7,-2,CONCRETE:7,70,STAINED_CLAY:12,15,STAINED_CLAY:15,5,CONCRETE:7,100)
Block(-3,7,-1,AIR:0)
Block(-3,7,0,COBBLE_WALL:0)
Block(-3,7,1,COBBLE_WALL:0)
Block(-3,7,2,AIR:0)
RandomBlock(-3,7,3,CONCRETE:7,70,STAINED_CLAY:12,15,STAINED_CLAY:15,5,CONCRETE:7,100)
RandomBlock(-3,8,-2,CONCRETE:7,70,STAINED_CLAY:12,15,STAINED_CLAY:15,5,CONCRETE:7,100)
Block(-3,8,-1,AIR:0)
Block(-3,8,0,COBBLE_WALL:0)
Block(-3,8,1,COBBLE_WALL:0)
Block(-3,8,2,AIR:0)
RandomBlock(-3,8,3,CONCRETE:7,70,STAINED_CLAY:12,15,STAINED_CLAY:15,5,CONCRETE:7,100)
RandomBlock(-3,9,-2,CONCRETE:7,70,STAINED_CLAY:12,15,STAINED_CLAY:15,5,CONCRETE:7,100)
Block(-3,9,-1,AIR:0)
Block(-3,9,0,COBBLE_WALL:0)
Block(-3,9,1,COBBLE_WALL:0)
Block(-3,9,2,AIR:0)
RandomBlock(-3,9,3,CONCRETE:7,70,STAINED_CLAY:12,15,STAINED_CLAY:15,5,CONCRETE:7,100)
RandomBlock(-2,0,-2,CONCRETE:7,70,STAINED_CLAY:12,15,STAINED_CLAY:15,5,CONCRETE:7,100)
Block(-2,0,-1,AIR:0)
Block(-2,0,0,AIR:0)
Block(-2,0,1,AIR:0)
Block(-2,0,2,AIR:0)
RandomBlock(-2,0,3,CONCRETE:7,70,STAINED_CLAY:12,15,STAINED_CLAY:15,5,CONCRETE:7,100)
RandomBlock(-2,1,-2,CONCRETE:7,70,STAINED_CLAY:12,15,STAINED_CLAY:15,5,CONCRETE:7,100)
Block(-2,1,-1,AIR:0)
Block(-2,1,0,AIR:0)
Block(-2,1,1,AIR:0)
Block(-2,1,2,AIR:0)
RandomBlock(-2,1,3,CONCRETE:7,70,STAINED_CLAY:12,15,STAINED_CLAY:15,5,CONCRETE:7,100)
RandomBlock(-2,2,-2,CONCRETE:7,70,STAINED_CLAY:12,15,STAINED_CLAY:15,5,CONCRETE:7,100)
Block(-2,2,-1,AIR:0)
Block(-2,2,0,AIR:0)
Block(-2,2,1,AIR:0)
Block(-2,2,2,AIR:0)
RandomBlock(-2,2,3,CONCRETE:7,70,STAINED_CLAY:12,15,STAINED_CLAY:15,5,CONCRETE:7,100)
RandomBlock(-2,3,-2,CONCRETE:7,70,STAINED_CLAY:12,15,STAINED_CLAY:15,5,CONCRETE:7,100)
Block(-2,3,-1,AIR:0)
Block(-2,3,0,AIR:0)
Block(-2,3,1,AIR:0)
Block(-2,3,2,AIR:0)
RandomBlock(-2,3,3,CONCRETE:7,70,STAINED_CLAY:12,15,STAINED_CLAY:15,5,CONCRETE:7,100)
RandomBlock(-2,4,-2,CONCRETE:7,70,STAINED_CLAY:12,15,STAINED_CLAY:15,5,CONCRETE:7,100)
Block(-2,4,-1,AIR:0)
Block(-2,4,0,AIR:0)
Block(-2,4,1,AIR:0)
Block(-2,4,2,AIR:0)
RandomBlock(-2,4,3,CONCRETE:7,70,STAINED_CLAY:12,15,STAINED_CLAY:15,5,CONCRETE:7,100)
RandomBlock(-2,5,-2,CONCRETE:7,70,STAINED_CLAY:12,15,STAINED_CLAY:15,5,CONCRETE:7,100)
Block(-2,5,-1,AIR:0)
Block(-2,5,0,AIR:0)
Block(-2,5,1,AIR:0)
Block(-2,5,2,AIR:0)
RandomBlock(-2,5,3,CONCRETE:7,70,STAINED_CLAY:12,15,STAINED_CLAY:15,5,CONCRETE:7,100)
RandomBlock(-2,6,-2,CONCRETE:7,70,STAINED_CLAY:12,15,STAINED_CLAY:15,5,CONCRETE:7,100)
Block(-2,6,-1,AIR:0)
Block(-2,6,0,AIR:0)
Block(-2,6,1,AIR:0)
Block(-2,6,2,AIR:0)
RandomBlock(-2,6,3,CONCRETE:7,70,STAINED_CLAY:12,15,STAINED_CLAY:15,5,CONCRETE:7,100)
RandomBlock(-2,7,-2,CONCRETE:7,70,STAINED_CLAY:12,15,STAINED_CLAY:15,5,CONCRETE:7,100)
Block(-2,7,-1,AIR:0)
Block(-2,7,0,AIR:0)
Block(-2,7,1,AIR:0)
Block(-2,7,2,AIR:0)
RandomBlock(-2,7,3,CONCRETE:7,70,STAINED_CLAY:12,15,STAINED_CLAY:15,5,CONCRETE:7,100)
RandomBlock(-2,8,-2,CONCRETE:7,70,STAINED_CLAY:12,15,STAINED_CLAY:15,5,CONCRETE:7,100)
Block(-2,8,-1,AIR:0)
Block(-2,8,0,AIR:0)
Block(-2,8,1,AIR:0)
Block(-2,8,2,AIR:0)
RandomBlock(-2,8,3,CONCRETE:7,70,STAINED_CLAY:12,15,STAINED_CLAY:15,5,CONCRETE:7,100)
RandomBlock(-2,9,-2,CONCRETE:7,70,STAINED_CLAY:12,15,STAINED_CLAY:15,5,CONCRETE:7,100)
Block(-2,9,-1,AIR:0)
Block(-2,9,0,AIR:0)
Block(-2,9,1,AIR:0)
Block(-2,9,2,AIR:0)
RandomBlock(-2,9,3,CONCRETE:7,70,STAINED_CLAY:12,15,STAINED_CLAY:15,5,CONCRETE:7,100)
Block(-1,0,-6,CONCRETE:15)
Block(-1,0,-4,CONCRETE:15)
RandomBlock(-1,0,-2,CONCRETE:7,70,STAINED_CLAY:12,15,STAINED_CLAY:15,5,CONCRETE:7,100)
Block(-1,0,-1,AIR:0)
Block(-1,0,0,AIR:0)
Block(-1,0,1,AIR:0)
Block(-1,0,2,AIR:0)
RandomBlock(-1,0,3,CONCRETE:7,70,STAINED_CLAY:12,15,STAINED_CLAY:15,5,CONCRETE:7,100)
Block(-1,0,5,CONCRETE:15)
Block(-1,0,7,CONCRETE:15)
Block(-1,1,-6,CONCRETE:15)
Block(-1,1,-4,CONCRETE:15)
RandomBlock(-1,1,-2,CONCRETE:7,70,STAINED_CLAY:12,15,STAINED_CLAY:15,5,CONCRETE:7,100)
Block(-1,1,-1,AIR:0)
Block(-1,1,0,AIR:0)
Block(-1,1,1,AIR:0)
Block(-1,1,2,AIR:0)
RandomBlock(-1,1,3,CONCRETE:7,70,STAINED_CLAY:12,15,STAINED_CLAY:15,5,CONCRETE:7,100)
Block(-1,1,5,CONCRETE:15)
Block(-1,1,7,CONCRETE:15)
Block(-1,2,-6,CONCRETE:15)
Block(-1,2,-4,CONCRETE:15)
RandomBlock(-1,2,-2,CONCRETE:7,70,STAINED_CLAY:12,15,STAINED_CLAY:15,5,CONCRETE:7,100)
Block(-1,2,-1,AIR:0)
Block(-1,2,0,AIR:0)
Block(-1,2,1,AIR:0)
Block(-1,2,2,AIR:0)
RandomBlock(-1,2,3,CONCRETE:7,70,STAINED_CLAY:12,15,STAINED_CLAY:15,5,CONCRETE:7,100)
Block(-1,2,5,CONCRETE:15)
Block(-1,2,7,CONCRETE:15)
Block(-1,3,-6,CONCRETE:15)
Block(-1,3,-4,CONCRETE:15)
RandomBlock(-1,3,-2,CONCRETE:7,70,STAINED_CLAY:12,15,STAINED_CLAY:15,5,CONCRETE:7,100)
Block(-1,3,-1,AIR:0)
Block(-1,3,0,AIR:0)
Block(-1,3,1,AIR:0)
Block(-1,3,2,AIR:0)
RandomBlock(-1,3,3,CONCRETE:7,70,STAINED_CLAY:12,15,STAINED_CLAY:15,5,CONCRETE:7,100)
Block(-1,3,5,CONCRETE:15)
Block(-1,3,7,CONCRETE:15)
Block(-1,4,-6,CONCRETE:15)
Block(-1,4,-4,CONCRETE:15)
RandomBlock(-1,4,-2,CONCRETE:7,70,STAINED_CLAY:12,15,STAINED_CLAY:15,5,CONCRETE:7,100)
Block(-1,4,-1,AIR:0)
Block(-1,4,0,AIR:0)
Block(-1,4,1,AIR:0)
Block(-1,4,2,AIR:0)
RandomBlock(-1,4,3,CONCRETE:7,70,STAINED_CLAY:12,15,STAINED_CLAY:15,5,CONCRETE:7,100)
Block(-1,4,5,CONCRETE:15)
Block(-1,4,7,CONCRETE:15)
Block(-1,5,-6,CONCRETE:15)
Block(-1,5,-4,CONCRETE:15)
RandomBlock(-1,5,-2,CONCRETE:7,70,STAINED_CLAY:12,15,STAINED_CLAY:15,5,CONCRETE:7,100)
Block(-1,5,-1,AIR:0)
Block(-1,5,0,AIR:0)
Block(-1,5,1,AIR:0)
Block(-1,5,2,AIR:0)
RandomBlock(-1,5,3,CONCRETE:7,70,STAINED_CLAY:12,15,STAINED_CLAY:15,5,CONCRETE:7,100)
Block(-1,5,5,CONCRETE:15)
Block(-1,5,7,CONCRETE:15)
Block(-1,6,-6,CONCRETE:15)
Block(-1,6,-4,CONCRETE:15)
RandomBlock(-1,6,-2,CONCRETE:7,70,STAINED_CLAY:12,15,STAINED_CLAY:15,5,CONCRETE:7,100)
Block(-1,6,-1,AIR:0)
Block(-1,6,0,AIR:0)
Block(-1,6,1,AIR:0)
Block(-1,6,2,AIR:0)
RandomBlock(-1,6,3,CONCRETE:7,70,STAINED_CLAY:12,15,STAINED_CLAY:15,5,CONCRETE:7,100)
Block(-1,6,5,CONCRETE:15)
Block(-1,6,7,CONCRETE:15)
Block(-1,7,-6,CONCRETE:15)
Block(-1,7,-4,CONCRETE:15)
RandomBlock(-1,7,-2,CONCRETE:7,70,STAINED_CLAY:12,15,STAINED_CLAY:15,5,CONCRETE:7,100)
Block(-1,7,-1,AIR:0)
Block(-1,7,0,AIR:0)
Block(-1,7,1,AIR:0)
Block(-1,7,2,AIR:0)
RandomBlock(-1,7,3,CONCRETE:7,70,STAINED_CLAY:12,15,STAINED_CLAY:15,5,CONCRETE:7,100)
Block(-1,7,5,CONCRETE:15)
Block(-1,7,7,CONCRETE:15)
Block(-1,8,-6,CONCRETE:15)
Block(-1,8,-4,CONCRETE:15)
RandomBlock(-1,8,-2,CONCRETE:7,70,STAINED_CLAY:12,15,STAINED_CLAY:15,5,CONCRETE:7,100)
Block(-1,8,-1,AIR:0)
Block(-1,8,0,AIR:0)
Block(-1,8,1,AIR:0)
Block(-1,8,2,AIR:0)
RandomBlock(-1,8,3,CONCRETE:7,70,STAINED_CLAY:12,15,STAINED_CLAY:15,5,CONCRETE:7,100)
Block(-1,8,5,CONCRETE:15)
Block(-1,8,7,CONCRETE:15)
Block(-1,9,-6,CONCRETE:15)
Block(-1,9,-4,CONCRETE:15)
RandomBlock(-1,9,-2,CONCRETE:7,70,STAINED_CLAY:12,15,STAINED_CLAY:15,5,CONCRETE:7,100)
Block(-1,9,-1,AIR:0)
Block(-1,9,0,AIR:0)
Block(-1,9,1,AIR:0)
Block(-1,9,2,AIR:0)
RandomBlock(-1,9,3,CONCRETE:7,70,STAINED_CLAY:12,15,STAINED_CLAY:15,5,CONCRETE:7,100)
Block(-1,9,5,CONCRETE:15)
Block(-1,9,7,CONCRETE:15)
RandomBlock(0,0,-2,CONCRETE:7,70,STAINED_CLAY:12,15,STAINED_CLAY:15,5,CONCRETE:7,100)
RandomBlock(0,0,-1,CONCRETE:7,70,STAINED_CLAY:12,15,STAINED_CLAY:15,5,CONCRETE:7,100)
RandomBlock(0,0,0,CONCRETE:7,70,STAINED_CLAY:12,15,STAINED_CLAY:15,5,CONCRETE:7,100)
RandomBlock(0,0,1,CONCRETE:7,70,STAINED_CLAY:12,15,STAINED_CLAY:15,5,CONCRETE:7,100)
RandomBlock(0,0,2,CONCRETE:7,70,STAINED_CLAY:12,15,STAINED_CLAY:15,5,CONCRETE:7,100)
RandomBlock(0,0,3,CONCRETE:7,70,STAINED_CLAY:12,15,STAINED_CLAY:15,5,CONCRETE:7,100)
RandomBlock(0,1,-2,CONCRETE:7,70,STAINED_CLAY:12,15,STAINED_CLAY:15,5,CONCRETE:7,100)
RandomBlock(0,1,-1,CONCRETE:7,70,STAINED_CLAY:12,15,STAINED_CLAY:15,5,CONCRETE:7,100)
RandomBlock(0,1,0,CONCRETE:7,70,STAINED_CLAY:12,15,STAINED_CLAY:15,5,CONCRETE:7,100)
RandomBlock(0,1,1,CONCRETE:7,70,STAINED_CLAY:12,15,STAINED_CLAY:15,5,CONCRETE:7,100)
RandomBlock(0,1,2,CONCRETE:7,70,STAINED_CLAY:12,15,STAINED_CLAY:15,5,CONCRETE:7,100)
RandomBlock(0,1,3,CONCRETE:7,70,STAINED_CLAY:12,15,STAINED_CLAY:15,5,CONCRETE:7,100)
RandomBlock(0,2,-2,CONCRETE:7,70,STAINED_CLAY:12,15,STAINED_CLAY:15,5,CONCRETE:7,100)
RandomBlock(0,2,-1,CONCRETE:7,70,STAINED_CLAY:12,15,STAINED_CLAY:15,5,CONCRETE:7,100)
RandomBlock(0,2,0,CONCRETE:7,70,STAINED_CLAY:12,15,STAINED_CLAY:15,5,CONCRETE:7,100)
RandomBlock(0,2,1,CONCRETE:7,70,STAINED_CLAY:12,15,STAINED_CLAY:15,5,CONCRETE:7,100)
RandomBlock(0,2,2,CONCRETE:7,70,STAINED_CLAY:12,15,STAINED_CLAY:15,5,CONCRETE:7,100)
RandomBlock(0,2,3,CONCRETE:7,70,STAINED_CLAY:12,15,STAINED_CLAY:15,5,CONCRETE:7,100)
RandomBlock(0,3,-2,CONCRETE:7,70,STAINED_CLAY:12,15,STAINED_CLAY:15,5,CONCRETE:7,100)
RandomBlock(0,3,-1,CONCRETE:7,70,STAINED_CLAY:12,15,STAINED_CLAY:15,5,CONCRETE:7,100)
RandomBlock(0,3,0,CONCRETE:7,70,STAINED_CLAY:12,15,STAINED_CLAY:15,5,CONCRETE:7,100)
RandomBlock(0,3,1,CONCRETE:7,70,STAINED_CLAY:12,15,STAINED_CLAY:15,5,CONCRETE:7,100)
RandomBlock(0,3,2,CONCRETE:7,70,STAINED_CLAY:12,15,STAINED_CLAY:15,5,CONCRETE:7,100)
RandomBlock(0,3,3,CONCRETE:7,70,STAINED_CLAY:12,15,STAINED_CLAY:15,5,CONCRETE:7,100)
RandomBlock(0,4,-2,CONCRETE:7,70,STAINED_CLAY:12,15,STAINED_CLAY:15,5,CONCRETE:7,100)
RandomBlock(0,4,-1,CONCRETE:7,70,STAINED_CLAY:12,15,STAINED_CLAY:15,5,CONCRETE:7,100)
RandomBlock(0,4,0,CONCRETE:7,70,STAINED_CLAY:12,15,STAINED_CLAY:15,5,CONCRETE:7,100)
RandomBlock(0,4,1,CONCRETE:7,70,STAINED_CLAY:12,15,STAINED_CLAY:15,5,CONCRETE:7,100)
RandomBlock(0,4,2,CONCRETE:7,70,STAINED_CLAY:12,15,STAINED_CLAY:15,5,CONCRETE:7,100)
RandomBlock(0,4,3,CONCRETE:7,70,STAINED_CLAY:12,15,STAINED_CLAY:15,5,CONCRETE:7,100)
RandomBlock(0,5,-2,CONCRETE:7,70,STAINED_CLAY:12,15,STAINED_CLAY:15,5,CONCRETE:7,100)
RandomBlock(0,5,-1,CONCRETE:7,70,STAINED_CLAY:12,15,STAINED_CLAY:15,5,CONCRETE:7,100)
RandomBlock(0,5,0,CONCRETE:7,70,STAINED_CLAY:12,15,STAINED_CLAY:15,5,CONCRETE:7,100)
RandomBlock(0,5,1,CONCRETE:7,70,STAINED_CLAY:12,15,STAINED_CLAY:15,5,CONCRETE:7,100)
RandomBlock(0,5,2,CONCRETE:7,70,STAINED_CLAY:12,15,STAINED_CLAY:15,5,CONCRETE:7,100)
RandomBlock(0,5,3,CONCRETE:7,70,STAINED_CLAY:12,15,STAINED_CLAY:15,5,CONCRETE:7,100)
RandomBlock(0,6,-2,CONCRETE:7,70,STAINED_CLAY:12,15,STAINED_CLAY:15,5,CONCRETE:7,100)
RandomBlock(0,6,-1,CONCRETE:7,70,STAINED_CLAY:12,15,STAINED_CLAY:15,5,CONCRETE:7,100)
RandomBlock(0,6,0,CONCRETE:7,70,STAINED_CLAY:12,15,STAINED_CLAY:15,5,CONCRETE:7,100)
RandomBlock(0,6,1,CONCRETE:7,70,STAINED_CLAY:12,15,STAINED_CLAY:15,5,CONCRETE:7,100)
RandomBlock(0,6,2,CONCRETE:7,70,STAINED_CLAY:12,15,STAINED_CLAY:15,5,CONCRETE:7,100)
RandomBlock(0,6,3,CONCRETE:7,70,STAINED_CLAY:12,15,STAINED_CLAY:15,5,CONCRETE:7,100)
RandomBlock(0,7,-2,CONCRETE:7,70,STAINED_CLAY:12,15,STAINED_CLAY:15,5,CONCRETE:7,100)
RandomBlock(0,7,-1,CONCRETE:7,70,STAINED_CLAY:12,15,STAINED_CLAY:15,5,CONCRETE:7,100)
RandomBlock(0,7,0,CONCRETE:7,70,STAINED_CLAY:12,15,STAINED_CLAY:15,5,CONCRETE:7,100)
RandomBlock(0,7,1,CONCRETE:7,70,STAINED_CLAY:12,15,STAINED_CLAY:15,5,CONCRETE:7,100)
RandomBlock(0,7,2,CONCRETE:7,70,STAINED_CLAY:12,15,STAINED_CLAY:15,5,CONCRETE:7,100)
RandomBlock(0,7,3,CONCRETE:7,70,STAINED_CLAY:12,15,STAINED_CLAY:15,5,CONCRETE:7,100)
RandomBlock(0,8,-2,CONCRETE:7,70,STAINED_CLAY:12,15,STAINED_CLAY:15,5,CONCRETE:7,100)
RandomBlock(0,8,-1,CONCRETE:7,70,STAINED_CLAY:12,15,STAINED_CLAY:15,5,CONCRETE:7,100)
RandomBlock(0,8,0,CONCRETE:7,70,STAINED_CLAY:12,15,STAINED_CLAY:15,5,CONCRETE:7,100)
RandomBlock(0,8,1,CONCRETE:7,70,STAINED_CLAY:12,15,STAINED_CLAY:15,5,CONCRETE:7,100)
RandomBlock(0,8,2,CONCRETE:7,70,STAINED_CLAY:12,15,STAINED_CLAY:15,5,CONCRETE:7,100)
RandomBlock(0,8,3,CONCRETE:7,70,STAINED_CLAY:12,15,STAINED_CLAY:15,5,CONCRETE:7,100)
RandomBlock(0,9,-2,CONCRETE:7,70,STAINED_CLAY:12,15,STAINED_CLAY:15,5,CONCRETE:7,100)
RandomBlock(0,9,-1,CONCRETE:7,70,STAINED_CLAY:12,15,STAINED_CLAY:15,5,CONCRETE:7,100)
RandomBlock(0,9,0,CONCRETE:7,70,STAINED_CLAY:12,15,STAINED_CLAY:15,5,CONCRETE:7,100)
RandomBlock(0,9,1,CONCRETE:7,70,STAINED_CLAY:12,15,STAINED_CLAY:15,5,CONCRETE:7,100)
RandomBlock(0,9,2,CONCRETE:7,70,STAINED_CLAY:12,15,STAINED_CLAY:15,5,CONCRETE:7,100)
RandomBlock(0,9,3,CONCRETE:7,70,STAINED_CLAY:12,15,STAINED_CLAY:15,5,CONCRETE:7,100)
Block(1,0,-2,CONCRETE:15)
Block(1,0,3,CONCRETE:15)
Block(1,1,-2,CONCRETE:15)
Block(1,1,3,CONCRETE:15)
Block(1,2,-2,CONCRETE:15)
Block(1,2,3,CONCRETE:15)
Block(1,3,-2,CONCRETE:15)
Block(1,3,3,CONCRETE:15)
Block(1,4,-2,CONCRETE:15)
Block(1,4,3,CONCRETE:15)
Block(1,5,-2,CONCRETE:15)
Block(1,5,3,CONCRETE:15)
Block(1,6,-2,CONCRETE:15)
Block(1,6,3,CONCRETE:15)
Block(1,7,-2,CONCRETE:15)
Block(1,7,3,CONCRETE:15)
Block(1,8,-2,CONCRETE:15)
Block(1,8,3,CONCRETE:15)
Block(1,9,-2,CONCRETE:15)
Block(1,9,3,CONCRETE:15)
Block(5,0,-6,CONCRETE:15)
Block(5,0,-4,CONCRETE:15)
Block(5,0,-2,CONCRETE:15)
Block(5,0,3,CONCRETE:15)
Block(5,0,5,CONCRETE:15)
Block(5,0,7,CONCRETE:15)
Block(5,1,-6,CONCRETE:15)
Block(5,1,-4,CONCRETE:15)
Block(5,1,-2,CONCRETE:15)
Block(5,1,3,CONCRETE:15)
Block(5,1,5,CONCRETE:15)
Block(5,1,7,CONCRETE:15)
Block(5,2,-6,CONCRETE:15)
Block(5,2,-4,CONCRETE:15)
Block(5,2,-2,CONCRETE:15)
Block(5,2,3,CONCRETE:15)
Block(5,2,5,CONCRETE:15)
Block(5,2,7,CONCRETE:15)
Block(5,3,-6,CONCRETE:15)
Block(5,3,-4,CONCRETE:15)
Block(5,3,-2,CONCRETE:15)
Block(5,3,3,CONCRETE:15)
Block(5,3,5,CONCRETE:15)
Block(5,3,7,CONCRETE:15)
Block(5,4,-6,CONCRETE:15)
Block(5,4,-4,CONCRETE:15)
Block(5,4,-2,CONCRETE:15)
Block(5,4,3,CONCRETE:15)
Block(5,4,5,CONCRETE:15)
Block(5,4,7,CONCRETE:15)
Block(5,5,-6,CONCRETE:15)
Block(5,5,-4,CONCRETE:15)
Block(5,5,-2,CONCRETE:15)
Block(5,5,3,CONCRETE:15)
Block(5,5,5,CONCRETE:15)
Block(5,5,7,CONCRETE:15)
Block(5,6,-6,CONCRETE:15)
Block(5,6,-4,CONCRETE:15)
Block(5,6,-2,CONCRETE:15)
Block(5,6,3,CONCRETE:15)
Block(5,6,5,CONCRETE:15)
Block(5,6,7,CONCRETE:15)
Block(5,7,-6,CONCRETE:15)
Block(5,7,-4,CONCRETE:15)
Block(5,7,-2,CONCRETE:15)
Block(5,7,3,CONCRETE:15)
Block(5,7,5,CONCRETE:15)
Block(5,7,7,CONCRETE:15)
Block(5,8,-6,CONCRETE:15)
Block(5,8,-4,CONCRETE:15)
Block(5,8,-2,CONCRETE:15)
Block(5,8,3,CONCRETE:15)
Block(5,8,5,CONCRETE:15)
Block(5,8,7,CONCRETE:15)
Block(5,9,-6,CONCRETE:15)
Block(5,9,-4,CONCRETE:15)
Block(5,9,-2,CONCRETE:15)
Block(5,9,3,CONCRETE:15)
Block(5,9,5,CONCRETE:15)
Block(5,9,7,CONCRETE:15)
RandomBlock(6,0,-6,CONCRETE:7,70,STAINED_CLAY:12,15,STAINED_CLAY:15,5,CONCRETE:7,100)
RandomBlock(6,0,-5,CONCRETE:7,70,STAINED_CLAY:12,15,STAINED_CLAY:15,5,CONCRETE:7,100)
RandomBlock(6,0,-4,CONCRETE:7,70,STAINED_CLAY:12,15,STAINED_CLAY:15,5,CONCRETE:7,100)
RandomBlock(6,0,-3,CONCRETE:7,70,STAINED_CLAY:12,15,STAINED_CLAY:15,5,CONCRETE:7,100)
RandomBlock(6,0,-2,CONCRETE:7,70,STAINED_CLAY:12,15,STAINED_CLAY:15,5,CONCRETE:7,100)
RandomBlock(6,0,3,CONCRETE:7,70,STAINED_CLAY:12,15,STAINED_CLAY:15,5,CONCRETE:7,100)
RandomBlock(6,0,4,CONCRETE:7,70,STAINED_CLAY:12,15,STAINED_CLAY:15,5,CONCRETE:7,100)
RandomBlock(6,0,5,CONCRETE:7,70,STAINED_CLAY:12,15,STAINED_CLAY:15,5,CONCRETE:7,100)
RandomBlock(6,0,6,CONCRETE:7,70,STAINED_CLAY:12,15,STAINED_CLAY:15,5,CONCRETE:7,100)
RandomBlock(6,0,7,CONCRETE:7,70,STAINED_CLAY:12,15,STAINED_CLAY:15,5,CONCRETE:7,100)
RandomBlock(6,1,-6,CONCRETE:7,70,STAINED_CLAY:12,15,STAINED_CLAY:15,5,CONCRETE:7,100)
RandomBlock(6,1,-5,CONCRETE:7,70,STAINED_CLAY:12,15,STAINED_CLAY:15,5,CONCRETE:7,100)
RandomBlock(6,1,-4,CONCRETE:7,70,STAINED_CLAY:12,15,STAINED_CLAY:15,5,CONCRETE:7,100)
RandomBlock(6,1,-3,CONCRETE:7,70,STAINED_CLAY:12,15,STAINED_CLAY:15,5,CONCRETE:7,100)
RandomBlock(6,1,-2,CONCRETE:7,70,STAINED_CLAY:12,15,STAINED_CLAY:15,5,CONCRETE:7,100)
RandomBlock(6,1,3,CONCRETE:7,70,STAINED_CLAY:12,15,STAINED_CLAY:15,5,CONCRETE:7,100)
RandomBlock(6,1,4,CONCRETE:7,70,STAINED_CLAY:12,15,STAINED_CLAY:15,5,CONCRETE:7,100)
RandomBlock(6,1,5,CONCRETE:7,70,STAINED_CLAY:12,15,STAINED_CLAY:15,5,CONCRETE:7,100)
RandomBlock(6,1,6,CONCRETE:7,70,STAINED_CLAY:12,15,STAINED_CLAY:15,5,CONCRETE:7,100)
RandomBlock(6,1,7,CONCRETE:7,70,STAINED_CLAY:12,15,STAINED_CLAY:15,5,CONCRETE:7,100)
RandomBlock(6,2,-6,CONCRETE:7,70,STAINED_CLAY:12,15,STAINED_CLAY:15,5,CONCRETE:7,100)
RandomBlock(6,2,-5,CONCRETE:7,70,STAINED_CLAY:12,15,STAINED_CLAY:15,5,CONCRETE:7,100)
RandomBlock(6,2,-4,CONCRETE:7,70,STAINED_CLAY:12,15,STAINED_CLAY:15,5,CONCRETE:7,100)
RandomBlock(6,2,-3,CONCRETE:7,70,STAINED_CLAY:12,15,STAINED_CLAY:15,5,CONCRETE:7,100)
RandomBlock(6,2,-2,CONCRETE:7,70,STAINED_CLAY:12,15,STAINED_CLAY:15,5,CONCRETE:7,100)
RandomBlock(6,2,3,CONCRETE:7,70,STAINED_CLAY:12,15,STAINED_CLAY:15,5,CONCRETE:7,100)
RandomBlock(6,2,4,CONCRETE:7,70,STAINED_CLAY:12,15,STAINED_CLAY:15,5,CONCRETE:7,100)
RandomBlock(6,2,5,CONCRETE:7,70,STAINED_CLAY:12,15,STAINED_CLAY:15,5,CONCRETE:7,100)
RandomBlock(6,2,6,CONCRETE:7,70,STAINED_CLAY:12,15,STAINED_CLAY:15,5,CONCRETE:7,100)
RandomBlock(6,2,7,CONCRETE:7,70,STAINED_CLAY:12,15,STAINED_CLAY:15,5,CONCRETE:7,100)
RandomBlock(6,3,-6,CONCRETE:7,70,STAINED_CLAY:12,15,STAINED_CLAY:15,5,CONCRETE:7,100)
RandomBlock(6,3,-5,CONCRETE:7,70,STAINED_CLAY:12,15,STAINED_CLAY:15,5,CONCRETE:7,100)
RandomBlock(6,3,-4,CONCRETE:7,70,STAINED_CLAY:12,15,STAINED_CLAY:15,5,CONCRETE:7,100)
RandomBlock(6,3,-3,CONCRETE:7,70,STAINED_CLAY:12,15,STAINED_CLAY:15,5,CONCRETE:7,100)
RandomBlock(6,3,-2,CONCRETE:7,70,STAINED_CLAY:12,15,STAINED_CLAY:15,5,CONCRETE:7,100)
RandomBlock(6,3,3,CONCRETE:7,70,STAINED_CLAY:12,15,STAINED_CLAY:15,5,CONCRETE:7,100)
RandomBlock(6,3,4,CONCRETE:7,70,STAINED_CLAY:12,15,STAINED_CLAY:15,5,CONCRETE:7,100)
RandomBlock(6,3,5,CONCRETE:7,70,STAINED_CLAY:12,15,STAINED_CLAY:15,5,CONCRETE:7,100)
RandomBlock(6,3,6,CONCRETE:7,70,STAINED_CLAY:12,15,STAINED_CLAY:15,5,CONCRETE:7,100)
RandomBlock(6,3,7,CONCRETE:7,70,STAINED_CLAY:12,15,STAINED_CLAY:15,5,CONCRETE:7,100)
RandomBlock(6,4,-6,CONCRETE:7,70,STAINED_CLAY:12,15,STAINED_CLAY:15,5,CONCRETE:7,100)
RandomBlock(6,4,-5,CONCRETE:7,70,STAINED_CLAY:12,15,STAINED_CLAY:15,5,CONCRETE:7,100)
RandomBlock(6,4,-4,CONCRETE:7,70,STAINED_CLAY:12,15,STAINED_CLAY:15,5,CONCRETE:7,100)
RandomBlock(6,4,-3,CONCRETE:7,70,STAINED_CLAY:12,15,STAINED_CLAY:15,5,CONCRETE:7,100)
RandomBlock(6,4,-2,CONCRETE:7,70,STAINED_CLAY:12,15,STAINED_CLAY:15,5,CONCRETE:7,100)
RandomBlock(6,4,3,CONCRETE:7,70,STAINED_CLAY:12,15,STAINED_CLAY:15,5,CONCRETE:7,100)
RandomBlock(6,4,4,CONCRETE:7,70,STAINED_CLAY:12,15,STAINED_CLAY:15,5,CONCRETE:7,100)
RandomBlock(6,4,5,CONCRETE:7,70,STAINED_CLAY:12,15,STAINED_CLAY:15,5,CONCRETE:7,100)
RandomBlock(6,4,6,CONCRETE:7,70,STAINED_CLAY:12,15,STAINED_CLAY:15,5,CONCRETE:7,100)
RandomBlock(6,4,7,CONCRETE:7,70,STAINED_CLAY:12,15,STAINED_CLAY:15,5,CONCRETE:7,100)
RandomBlock(6,5,-6,CONCRETE:7,70,STAINED_CLAY:12,15,STAINED_CLAY:15,5,CONCRETE:7,100)
RandomBlock(6,5,-5,CONCRETE:7,70,STAINED_CLAY:12,15,STAINED_CLAY:15,5,CONCRETE:7,100)
RandomBlock(6,5,-4,CONCRETE:7,70,STAINED_CLAY:12,15,STAINED_CLAY:15,5,CONCRETE:7,100)
RandomBlock(6,5,-3,CONCRETE:7,70,STAINED_CLAY:12,15,STAINED_CLAY:15,5,CONCRETE:7,100)
RandomBlock(6,5,-2,CONCRETE:7,70,STAINED_CLAY:12,15,STAINED_CLAY:15,5,CONCRETE:7,100)
RandomBlock(6,5,3,CONCRETE:7,70,STAINED_CLAY:12,15,STAINED_CLAY:15,5,CONCRETE:7,100)
RandomBlock(6,5,4,CONCRETE:7,70,STAINED_CLAY:12,15,STAINED_CLAY:15,5,CONCRETE:7,100)
RandomBlock(6,5,5,CONCRETE:7,70,STAINED_CLAY:12,15,STAINED_CLAY:15,5,CONCRETE:7,100)
RandomBlock(6,5,6,CONCRETE:7,70,STAINED_CLAY:12,15,STAINED_CLAY:15,5,CONCRETE:7,100)
RandomBlock(6,5,7,CONCRETE:7,70,STAINED_CLAY:12,15,STAINED_CLAY:15,5,CONCRETE:7,100)
RandomBlock(6,6,-6,CONCRETE:7,70,STAINED_CLAY:12,15,STAINED_CLAY:15,5,CONCRETE:7,100)
RandomBlock(6,6,-5,CONCRETE:7,70,STAINED_CLAY:12,15,STAINED_CLAY:15,5,CONCRETE:7,100)
RandomBlock(6,6,-4,CONCRETE:7,70,STAINED_CLAY:12,15,STAINED_CLAY:15,5,CONCRETE:7,100)
RandomBlock(6,6,-3,CONCRETE:7,70,STAINED_CLAY:12,15,STAINED_CLAY:15,5,CONCRETE:7,100)
RandomBlock(6,6,-2,CONCRETE:7,70,STAINED_CLAY:12,15,STAINED_CLAY:15,5,CONCRETE:7,100)
RandomBlock(6,6,3,CONCRETE:7,70,STAINED_CLAY:12,15,STAINED_CLAY:15,5,CONCRETE:7,100)
RandomBlock(6,6,4,CONCRETE:7,70,STAINED_CLAY:12,15,STAINED_CLAY:15,5,CONCRETE:7,100)
RandomBlock(6,6,5,CONCRETE:7,70,STAINED_CLAY:12,15,STAINED_CLAY:15,5,CONCRETE:7,100)
RandomBlock(6,6,6,CONCRETE:7,70,STAINED_CLAY:12,15,STAINED_CLAY:15,5,CONCRETE:7,100)
RandomBlock(6,6,7,CONCRETE:7,70,STAINED_CLAY:12,15,STAINED_CLAY:15,5,CONCRETE:7,100)
RandomBlock(6,7,-6,CONCRETE:7,70,STAINED_CLAY:12,15,STAINED_CLAY:15,5,CONCRETE:7,100)
RandomBlock(6,7,-5,CONCRETE:7,70,STAINED_CLAY:12,15,STAINED_CLAY:15,5,CONCRETE:7,100)
RandomBlock(6,7,-4,CONCRETE:7,70,STAINED_CLAY:12,15,STAINED_CLAY:15,5,CONCRETE:7,100)
RandomBlock(6,7,-3,CONCRETE:7,70,STAINED_CLAY:12,15,STAINED_CLAY:15,5,CONCRETE:7,100)
RandomBlock(6,7,-2,CONCRETE:7,70,STAINED_CLAY:12,15,STAINED_CLAY:15,5,CONCRETE:7,100)
RandomBlock(6,7,3,CONCRETE:7,70,STAINED_CLAY:12,15,STAINED_CLAY:15,5,CONCRETE:7,100)
RandomBlock(6,7,4,CONCRETE:7,70,STAINED_CLAY:12,15,STAINED_CLAY:15,5,CONCRETE:7,100)
RandomBlock(6,7,5,CONCRETE:7,70,STAINED_CLAY:12,15,STAINED_CLAY:15,5,CONCRETE:7,100)
RandomBlock(6,7,6,CONCRETE:7,70,STAINED_CLAY:12,15,STAINED_CLAY:15,5,CONCRETE:7,100)
RandomBlock(6,7,7,CONCRETE:7,70,STAINED_CLAY:12,15,STAINED_CLAY:15,5,CONCRETE:7,100)
RandomBlock(6,8,-6,CONCRETE:7,70,STAINED_CLAY:12,15,STAINED_CLAY:15,5,CONCRETE:7,100)
RandomBlock(6,8,-5,CONCRETE:7,70,STAINED_CLAY:12,15,STAINED_CLAY:15,5,CONCRETE:7,100)
RandomBlock(6,8,-4,CONCRETE:7,70,STAINED_CLAY:12,15,STAINED_CLAY:15,5,CONCRETE:7,100)
RandomBlock(6,8,-3,CONCRETE:7,70,STAINED_CLAY:12,15,STAINED_CLAY:15,5,CONCRETE:7,100)
RandomBlock(6,8,-2,CONCRETE:7,70,STAINED_CLAY:12,15,STAINED_CLAY:15,5,CONCRETE:7,100)
RandomBlock(6,8,3,CONCRETE:7,70,STAINED_CLAY:12,15,STAINED_CLAY:15,5,CONCRETE:7,100)
RandomBlock(6,8,4,CONCRETE:7,70,STAINED_CLAY:12,15,STAINED_CLAY:15,5,CONCRETE:7,100)
RandomBlock(6,8,5,CONCRETE:7,70,STAINED_CLAY:12,15,STAINED_CLAY:15,5,CONCRETE:7,100)
RandomBlock(6,8,6,CONCRETE:7,70,STAINED_CLAY:12,15,STAINED_CLAY:15,5,CONCRETE:7,100)
RandomBlock(6,8,7,CONCRETE:7,70,STAINED_CLAY:12,15,STAINED_CLAY:15,5,CONCRETE:7,100)
RandomBlock(6,9,-6,CONCRETE:7,70,STAINED_CLAY:12,15,STAINED_CLAY:15,5,CONCRETE:7,100)
RandomBlock(6,9,-5,CONCRETE:7,70,STAINED_CLAY:12,15,STAINED_CLAY:15,5,CONCRETE:7,100)
RandomBlock(6,9,-4,CONCRETE:7,70,STAINED_CLAY:12,15,STAINED_CLAY:15,5,CONCRETE:7,100)
RandomBlock(6,9,-3,CONCRETE:7,70,STAINED_CLAY:12,15,STAINED_CLAY:15,5,CONCRETE:7,100)
RandomBlock(6,9,-2,CONCRETE:7,70,STAINED_CLAY:12,15,STAINED_CLAY:15,5,CONCRETE:7,100)
RandomBlock(6,9,3,CONCRETE:7,70,STAINED_CLAY:12,15,STAINED_CLAY:15,5,CONCRETE:7,100)
RandomBlock(6,9,4,CONCRETE:7,70,STAINED_CLAY:12,15,STAINED_CLAY:15,5,CONCRETE:7,100)
RandomBlock(6,9,5,CONCRETE:7,70,STAINED_CLAY:12,15,STAINED_CLAY:15,5,CONCRETE:7,100)
RandomBlock(6,9,6,CONCRETE:7,70,STAINED_CLAY:12,15,STAINED_CLAY:15,5,CONCRETE:7,100)
RandomBlock(6,9,7,CONCRETE:7,70,STAINED_CLAY:12,15,STAINED_CLAY:15,5,CONCRETE:7,100)
RandomBlock(7,0,-6,CONCRETE:7,70,STAINED_CLAY:12,15,STAINED_CLAY:15,5,CONCRETE:7,100)
Block(7,0,-5,IRON_FENCE:0)
Block(7,0,-4,IRON_FENCE:0)
Block(7,0,-3,IRON_FENCE:0)
RandomBlock(7,0,-2,CONCRETE:7,70,STAINED_CLAY:12,15,STAINED_CLAY:15,5,CONCRETE:7,100)
RandomBlock(7,0,3,CONCRETE:7,70,STAINED_CLAY:12,15,STAINED_CLAY:15,5,CONCRETE:7,100)
Block(7,0,4,IRON_FENCE:0)
Block(7,0,5,IRON_FENCE:0)
Block(7,0,6,IRON_FENCE:0)
RandomBlock(7,0,7,CONCRETE:7,70,STAINED_CLAY:12,15,STAINED_CLAY:15,5,CONCRETE:7,100)
RandomBlock(7,1,-6,CONCRETE:7,70,STAINED_CLAY:12,15,STAINED_CLAY:15,5,CONCRETE:7,100)
Block(7,1,-5,IRON_FENCE:0)
Block(7,1,-4,IRON_FENCE:0)
Block(7,1,-3,IRON_FENCE:0)
RandomBlock(7,1,-2,CONCRETE:7,70,STAINED_CLAY:12,15,STAINED_CLAY:15,5,CONCRETE:7,100)
RandomBlock(7,1,3,CONCRETE:7,70,STAINED_CLAY:12,15,STAINED_CLAY:15,5,CONCRETE:7,100)
Block(7,1,4,IRON_FENCE:0)
Block(7,1,5,IRON_FENCE:0)
Block(7,1,6,IRON_FENCE:0)
RandomBlock(7,1,7,CONCRETE:7,70,STAINED_CLAY:12,15,STAINED_CLAY:15,5,CONCRETE:7,100)
RandomBlock(7,2,-6,CONCRETE:7,70,STAINED_CLAY:12,15,STAINED_CLAY:15,5,CONCRETE:7,100)
Block(7,2,-5,IRON_FENCE:0)
Block(7,2,-4,IRON_FENCE:0)
Block(7,2,-3,IRON_FENCE:0)
RandomBlock(7,2,-2,CONCRETE:7,70,STAINED_CLAY:12,15,STAINED_CLAY:15,5,CONCRETE:7,100)
RandomBlock(7,2,3,CONCRETE:7,70,STAINED_CLAY:12,15,STAINED_CLAY:15,5,CONCRETE:7,100)
Block(7,2,4,IRON_FENCE:0)
Block(7,2,5,IRON_FENCE:0)
Block(7,2,6,IRON_FENCE:0)
RandomBlock(7,2,7,CONCRETE:7,70,STAINED_CLAY:12,15,STAINED_CLAY:15,5,CONCRETE:7,100)
RandomBlock(7,3,-6,CONCRETE:7,70,STAINED_CLAY:12,15,STAINED_CLAY:15,5,CONCRETE:7,100)
Block(7,3,-5,IRON_FENCE:0)
Block(7,3,-4,IRON_FENCE:0)
Block(7,3,-3,IRON_FENCE:0)
RandomBlock(7,3,-2,CONCRETE:7,70,STAINED_CLAY:12,15,STAINED_CLAY:15,5,CONCRETE:7,100)
RandomBlock(7,3,3,CONCRETE:7,70,STAINED_CLAY:12,15,STAINED_CLAY:15,5,CONCRETE:7,100)
Block(7,3,4,IRON_FENCE:0)
Block(7,3,5,IRON_FENCE:0)
Block(7,3,6,IRON_FENCE:0)
RandomBlock(7,3,7,CONCRETE:7,70,STAINED_CLAY:12,15,STAINED_CLAY:15,5,CONCRETE:7,100)
RandomBlock(7,4,-6,CONCRETE:7,70,STAINED_CLAY:12,15,STAINED_CLAY:15,5,CONCRETE:7,100)
Block(7,4,-5,IRON_FENCE:0)
Block(7,4,-4,IRON_FENCE:0)
Block(7,4,-3,IRON_FENCE:0)
RandomBlock(7,4,-2,CONCRETE:7,70,STAINED_CLAY:12,15,STAINED_CLAY:15,5,CONCRETE:7,100)
RandomBlock(7,4,3,CONCRETE:7,70,STAINED_CLAY:12,15,STAINED_CLAY:15,5,CONCRETE:7,100)
Block(7,4,4,IRON_FENCE:0)
Block(7,4,5,IRON_FENCE:0)
Block(7,4,6,IRON_FENCE:0)
RandomBlock(7,4,7,CONCRETE:7,70,STAINED_CLAY:12,15,STAINED_CLAY:15,5,CONCRETE:7,100)
RandomBlock(7,5,-6,CONCRETE:7,70,STAINED_CLAY:12,15,STAINED_CLAY:15,5,CONCRETE:7,100)
Block(7,5,-5,IRON_FENCE:0)
Block(7,5,-4,IRON_FENCE:0)
Block(7,5,-3,IRON_FENCE:0)
RandomBlock(7,5,-2,CONCRETE:7,70,STAINED_CLAY:12,15,STAINED_CLAY:15,5,CONCRETE:7,100)
RandomBlock(7,5,3,CONCRETE:7,70,STAINED_CLAY:12,15,STAINED_CLAY:15,5,CONCRETE:7,100)
Block(7,5,4,IRON_FENCE:0)
Block(7,5,5,IRON_FENCE:0)
Block(7,5,6,IRON_FENCE:0)
RandomBlock(7,5,7,CONCRETE:7,70,STAINED_CLAY:12,15,STAINED_CLAY:15,5,CONCRETE:7,100)
RandomBlock(7,6,-6,CONCRETE:7,70,STAINED_CLAY:12,15,STAINED_CLAY:15,5,CONCRETE:7,100)
Block(7,6,-5,IRON_FENCE:0)
Block(7,6,-4,IRON_FENCE:0)
Block(7,6,-3,IRON_FENCE:0)
RandomBlock(7,6,-2,CONCRETE:7,70,STAINED_CLAY:12,15,STAINED_CLAY:15,5,CONCRETE:7,100)
RandomBlock(7,6,3,CONCRETE:7,70,STAINED_CLAY:12,15,STAINED_CLAY:15,5,CONCRETE:7,100)
Block(7,6,4,IRON_FENCE:0)
Block(7,6,5,IRON_FENCE:0)
Block(7,6,6,IRON_FENCE:0)
RandomBlock(7,6,7,CONCRETE:7,70,STAINED_CLAY:12,15,STAINED_CLAY:15,5,CONCRETE:7,100)
RandomBlock(7,7,-6,CONCRETE:7,70,STAINED_CLAY:12,15,STAINED_CLAY:15,5,CONCRETE:7,100)
Block(7,7,-5,IRON_FENCE:0)
Block(7,7,-4,IRON_FENCE:0)
Block(7,7,-3,IRON_FENCE:0)
RandomBlock(7,7,-2,CONCRETE:7,70,STAINED_CLAY:12,15,STAINED_CLAY:15,5,CONCRETE:7,100)
RandomBlock(7,7,3,CONCRETE:7,70,STAINED_CLAY:12,15,STAINED_CLAY:15,5,CONCRETE:7,100)
Block(7,7,4,IRON_FENCE:0)
Block(7,7,5,IRON_FENCE:0)
Block(7,7,6,IRON_FENCE:0)
RandomBlock(7,7,7,CONCRETE:7,70,STAINED_CLAY:12,15,STAINED_CLAY:15,5,CONCRETE:7,100)
RandomBlock(7,8,-6,CONCRETE:7,70,STAINED_CLAY:12,15,STAINED_CLAY:15,5,CONCRETE:7,100)
Block(7,8,-5,IRON_FENCE:0)
Block(7,8,-4,IRON_FENCE:0)
Block(7,8,-3,IRON_FENCE:0)
RandomBlock(7,8,-2,CONCRETE:7,70,STAINED_CLAY:12,15,STAINED_CLAY:15,5,CONCRETE:7,100)
RandomBlock(7,8,3,CONCRETE:7,70,STAINED_CLAY:12,15,STAINED_CLAY:15,5,CONCRETE:7,100)
Block(7,8,4,IRON_FENCE:0)
Block(7,8,5,IRON_FENCE:0)
Block(7,8,6,IRON_FENCE:0)
RandomBlock(7,8,7,CONCRETE:7,70,STAINED_CLAY:12,15,STAINED_CLAY:15,5,CONCRETE:7,100)
RandomBlock(7,9,-6,CONCRETE:7,70,STAINED_CLAY:12,15,STAINED_CLAY:15,5,CONCRETE:7,100)
Block(7,9,-5,IRON_FENCE:0)
Block(7,9,-4,IRON_FENCE:0)
Block(7,9,-3,IRON_FENCE:0)
RandomBlock(7,9,-2,CONCRETE:7,70,STAINED_CLAY:12,15,STAINED_CLAY:15,5,CONCRETE:7,100)
RandomBlock(7,9,3,CONCRETE:7,70,STAINED_CLAY:12,15,STAINED_CLAY:15,5,CONCRETE:7,100)
Block(7,9,4,IRON_FENCE:0)
Block(7,9,5,IRON_FENCE:0)
Block(7,9,6,IRON_FENCE:0)
RandomBlock(7,9,7,CONCRETE:7,70,STAINED_CLAY:12,15,STAINED_CLAY:15,5,CONCRETE:7,100)

#######################################################################
# +-----------------------------------------------------------------+ #
# |                             Branches                            | #
# +-----------------------------------------------------------------+ #
#######################################################################



Branch(0,0,16,true,DeepTunnel_EntranceHigh_SC0R2,NORTH,100.0,0)

#######################################################################
# +-----------------------------------------------------------------+ #
# |                             Entities                            | #
# +-----------------------------------------------------------------+ #
#######################################################################


#######################################################################
# +-----------------------------------------------------------------+ #
# |                            Particles                            | #
# +-----------------------------------------------------------------+ #
#######################################################################


#######################################################################
# +-----------------------------------------------------------------+ #
# |                             Spawners                            | #
# +-----------------------------------------------------------------+ #
#######################################################################


#######################################################################
# +-----------------------------------------------------------------+ #
# |                             ModData                             | #
# +-----------------------------------------------------------------+ #
#######################################################################

