#######################################################################
# +-----------------------------------------------------------------+ #
# |                            BO3 object                           | #
# +-----------------------------------------------------------------+ #
#######################################################################

Author: Bo3 BulkEdit

Description: Converted Schematic - Modified by Bo3BulkEdit

Version: 3

SettingsMode: WriteDisable

#######################################################################
# +-----------------------------------------------------------------+ #
# |                          Main settings                          | #
# +-----------------------------------------------------------------+ #
#######################################################################



Frequency: 0


SpawnHeight: randomY





##############################
# Height Limits for the BO3. #
##############################

MinHeight: 0
MaxHeight: 256

#######################################################################
# +-----------------------------------------------------------------+ #
# |                      Source block settings                      | #
# +-----------------------------------------------------------------+ #
#######################################################################

CanOverride: true
MaxPercentageOutsideSourceBlock: 100
OutsideSourceBlock: placeAnyway

#######################################################################
# +-----------------------------------------------------------------+ #
# |                               OTG+                              | #
# +-----------------------------------------------------------------+ #
#######################################################################

#######################################################################
# +-----------------------------------------------------------------+ #
# |                              Blocks                             | #
# +-----------------------------------------------------------------+ #
#######################################################################

B(0,750,0,AIR)
B(15,750,15,AIR)
B(15,2,15,betternether:quartz_stained_glass:15)
B(15,3,14,betternether:quartz_stained_glass:15)
B(14,3,15,betternether:quartz_stained_glass:15)
B(15,3,15,betternether:quartz_stained_glass:15)
B(15,4,13,betternether:quartz_stained_glass:15)
B(14,4,14,betternether:quartz_stained_glass:15)
B(15,4,14,betternether:quartz_stained_glass:15)
B(13,4,15,betternether:quartz_stained_glass:15)
B(14,4,15,betternether:quartz_stained_glass:15)
RB(15,4,15,srparasites:parasitestain:1,80,quark:crystal:1,30,srparasites:parasiterubbledense:1,100)
B(15,5,12,betternether:quartz_stained_glass:15)
B(14,5,13,betternether:quartz_stained_glass:15)
B(15,5,13,betternether:quartz_stained_glass:15)
B(13,5,14,betternether:quartz_stained_glass:15)
B(14,5,14,betternether:quartz_stained_glass:15)
RB(15,5,14,srparasites:parasitestain:1,80,quark:crystal:1,30,srparasites:parasiterubbledense:1,100)
B(12,5,15,betternether:quartz_stained_glass:15)
B(13,5,15,betternether:quartz_stained_glass:15)
RB(14,5,15,srparasites:parasitestain:1,80,quark:crystal:1,30,srparasites:parasiterubbledense:1,100)
RB(15,5,15,srparasites:parasitestain:1,80,quark:crystal:1,30,srparasites:parasiterubbledense:1,100)
B(14,6,12,betternether:quartz_stained_glass:15)
B(15,6,12,betternether:quartz_stained_glass:15)
B(13,6,13,betternether:quartz_stained_glass:15)
B(14,6,13,betternether:quartz_stained_glass:15)
B(15,6,13,betternether:quartz_stained_glass:15)
B(12,6,14,betternether:quartz_stained_glass:15)
B(13,6,14,betternether:quartz_stained_glass:15)
RB(14,6,14,srparasites:parasitestain:1,80,quark:crystal:1,30,srparasites:parasiterubbledense:1,100)
RB(15,6,14,srparasites:parasitestain:1,80,quark:crystal:1,30,srparasites:parasiterubbledense:1,100)
B(12,6,15,betternether:quartz_stained_glass:15)
B(13,6,15,betternether:quartz_stained_glass:15)
RB(14,6,15,srparasites:parasitestain:1,80,quark:crystal:1,30,srparasites:parasiterubbledense:1,100)
RB(15,6,15,srparasites:parasitestain:1,80,quark:crystal:1,30,srparasites:parasiterubbledense:1,100)
B(14,7,11,betternether:quartz_stained_glass:15)
B(13,7,12,betternether:quartz_stained_glass:15)
B(14,7,12,betternether:quartz_stained_glass:15)
B(15,7,12,betternether:quartz_stained_glass:15)
B(12,7,13,betternether:quartz_stained_glass:15)
B(13,7,13,betternether:quartz_stained_glass:15)
RB(14,7,13,srparasites:parasitestain:1,80,quark:crystal:1,30,srparasites:parasiterubbledense:1,100)
B(15,7,13,betternether:quartz_stained_glass:15)
B(11,7,14,betternether:quartz_stained_glass:15)
B(12,7,14,betternether:quartz_stained_glass:15)
RB(13,7,14,srparasites:parasitestain:1,80,quark:crystal:1,30,srparasites:parasiterubbledense:1,100)
RB(14,7,14,srparasites:parasitestain:1,80,quark:crystal:1,30,srparasites:parasiterubbledense:1,100)
RB(15,7,14,srparasites:parasitestain:1,80,quark:crystal:1,30,srparasites:parasiterubbledense:1,100)
B(12,7,15,betternether:quartz_stained_glass:15)
B(13,7,15,betternether:quartz_stained_glass:15)
RB(14,7,15,srparasites:parasitestain:1,80,quark:crystal:1,30,srparasites:parasiterubbledense:1,100)
B(15,7,15,betternether:quartz_stained_glass:15)
B(13,8,11,betternether:quartz_stained_glass:15)
B(14,8,11,betternether:quartz_stained_glass:15)
B(12,8,12,betternether:quartz_stained_glass:15)
B(13,8,12,betternether:quartz_stained_glass:15)
B(14,8,12,betternether:quartz_stained_glass:15)
B(15,8,12,betternether:quartz_stained_glass:15)
B(11,8,13,betternether:quartz_stained_glass:15)
B(12,8,13,betternether:quartz_stained_glass:15)
RB(13,8,13,srparasites:parasitestain:1,80,quark:crystal:1,30,srparasites:parasiterubbledense:1,100)
RB(14,8,13,srparasites:parasitestain:1,80,quark:crystal:1,30,srparasites:parasiterubbledense:1,100)
B(15,8,13,betternether:quartz_stained_glass:15)
B(11,8,14,betternether:quartz_stained_glass:15)
B(12,8,14,betternether:quartz_stained_glass:15)
RB(13,8,14,srparasites:parasitestain:1,80,quark:crystal:1,30,srparasites:parasiterubbledense:1,100)
RB(14,8,14,srparasites:parasitestain:1,80,quark:crystal:1,30,srparasites:parasiterubbledense:1,100)
B(15,8,14,betternether:quartz_stained_glass:15)
B(12,8,15,betternether:quartz_stained_glass:15)
B(13,8,15,betternether:quartz_stained_glass:15)
B(14,8,15,betternether:quartz_stained_glass:15)
B(15,8,15,betternether:quartz_stained_glass:15)
B(13,9,10,betternether:quartz_stained_glass:15)
B(12,9,11,betternether:quartz_stained_glass:15)
B(13,9,11,betternether:quartz_stained_glass:15)
B(14,9,11,betternether:quartz_stained_glass:15)
B(11,9,12,betternether:quartz_stained_glass:15)
B(12,9,12,betternether:quartz_stained_glass:15)
RB(13,9,12,srparasites:parasitestain:1,80,quark:crystal:1,30,srparasites:parasiterubbledense:1,100)
B(14,9,12,betternether:quartz_stained_glass:15)
B(15,9,12,betternether:quartz_stained_glass:15)
B(10,9,13,betternether:quartz_stained_glass:15)
B(11,9,13,betternether:quartz_stained_glass:15)
RB(12,9,13,srparasites:parasitestain:1,80,quark:crystal:1,30,srparasites:parasiterubbledense:1,100)
RB(13,9,13,srparasites:parasitestain:1,80,quark:crystal:1,30,srparasites:parasiterubbledense:1,100)
RB(14,9,13,srparasites:parasitestain:1,80,quark:crystal:1,30,srparasites:parasiterubbledense:1,100)
B(15,9,13,betternether:quartz_stained_glass:15)
B(11,9,14,betternether:quartz_stained_glass:15)
B(12,9,14,betternether:quartz_stained_glass:15)
RB(13,9,14,srparasites:parasitestain:1,80,quark:crystal:1,30,srparasites:parasiterubbledense:1,100)
B(14,9,14,betternether:quartz_stained_glass:15)
B(15,9,14,betternether:quartz_stained_glass:15)
B(12,9,15,betternether:quartz_stained_glass:15)
B(13,9,15,betternether:quartz_stained_glass:15)
B(14,9,15,betternether:quartz_stained_glass:15)
B(12,10,10,betternether:quartz_stained_glass:15)
B(13,10,10,betternether:quartz_stained_glass:15)
B(11,10,11,betternether:quartz_stained_glass:15)
B(12,10,11,betternether:quartz_stained_glass:15)
B(13,10,11,betternether:quartz_stained_glass:15)
B(14,10,11,betternether:quartz_stained_glass:15)
B(10,10,12,betternether:quartz_stained_glass:15)
B(11,10,12,betternether:quartz_stained_glass:15)
RB(12,10,12,srparasites:parasitestain:1,80,quark:crystal:1,30,srparasites:parasiterubbledense:1,100)
RB(13,10,12,srparasites:parasitestain:1,80,quark:crystal:1,30,srparasites:parasiterubbledense:1,100)
B(14,10,12,betternether:quartz_stained_glass:15)
B(15,10,12,betternether:quartz_stained_glass:15)
B(10,10,13,betternether:quartz_stained_glass:15)
B(11,10,13,betternether:quartz_stained_glass:15)
RB(12,10,13,srparasites:parasitestain:1,80,quark:crystal:1,30,srparasites:parasiterubbledense:1,100)
RB(13,10,13,srparasites:parasitestain:1,80,quark:crystal:1,30,srparasites:parasiterubbledense:1,100)
B(14,10,13,betternether:quartz_stained_glass:15)
B(15,10,13,betternether:quartz_stained_glass:15)
B(11,10,14,betternether:quartz_stained_glass:15)
B(12,10,14,betternether:quartz_stained_glass:15)
B(13,10,14,betternether:quartz_stained_glass:15)
B(14,10,14,betternether:quartz_stained_glass:15)
B(12,10,15,betternether:quartz_stained_glass:15)
B(13,10,15,betternether:quartz_stained_glass:15)
B(12,11,9,betternether:quartz_stained_glass:15)
B(11,11,10,betternether:quartz_stained_glass:15)
B(12,11,10,betternether:quartz_stained_glass:15)
B(13,11,10,betternether:quartz_stained_glass:15)
B(10,11,11,betternether:quartz_stained_glass:15)
B(11,11,11,betternether:quartz_stained_glass:15)
RB(12,11,11,srparasites:parasitestain:1,80,quark:crystal:1,30,srparasites:parasiterubbledense:1,100)
B(13,11,11,betternether:quartz_stained_glass:15)
B(14,11,11,betternether:quartz_stained_glass:15)
B(9,11,12,betternether:quartz_stained_glass:15)
B(10,11,12,betternether:quartz_stained_glass:15)
RB(11,11,12,srparasites:parasitestain:1,80,quark:crystal:1,30,srparasites:parasiterubbledense:1,100)
RB(12,11,12,srparasites:parasitestain:1,80,quark:crystal:1,30,srparasites:parasiterubbledense:1,100)
RB(13,11,12,srparasites:parasitestain:1,80,quark:crystal:1,30,srparasites:parasiterubbledense:1,100)
B(14,11,12,betternether:quartz_stained_glass:15)
B(15,11,12,betternether:quartz_stained_glass:15)
B(10,11,13,betternether:quartz_stained_glass:15)
B(11,11,13,betternether:quartz_stained_glass:15)
RB(12,11,13,srparasites:parasitestain:1,80,quark:crystal:1,30,srparasites:parasiterubbledense:1,100)
B(13,11,13,betternether:quartz_stained_glass:15)
B(14,11,13,betternether:quartz_stained_glass:15)
B(11,11,14,betternether:quartz_stained_glass:15)
B(12,11,14,betternether:quartz_stained_glass:15)
B(13,11,14,betternether:quartz_stained_glass:15)
B(12,11,15,betternether:quartz_stained_glass:15)
B(11,12,9,betternether:quartz_stained_glass:15)
B(12,12,9,betternether:quartz_stained_glass:15)
B(10,12,10,betternether:quartz_stained_glass:15)
B(11,12,10,betternether:quartz_stained_glass:15)
B(12,12,10,betternether:quartz_stained_glass:15)
B(13,12,10,betternether:quartz_stained_glass:15)
B(9,12,11,betternether:quartz_stained_glass:15)
B(10,12,11,betternether:quartz_stained_glass:15)
RB(11,12,11,srparasites:parasitestain:1,80,quark:crystal:1,30,srparasites:parasiterubbledense:1,100)
RB(12,12,11,srparasites:parasitestain:1,80,quark:crystal:1,30,srparasites:parasiterubbledense:1,100)
B(13,12,11,betternether:quartz_stained_glass:15)
B(14,12,11,betternether:quartz_stained_glass:15)
B(9,12,12,betternether:quartz_stained_glass:15)
B(10,12,12,betternether:quartz_stained_glass:15)
RB(11,12,12,srparasites:parasitestain:1,80,quark:crystal:1,30,srparasites:parasiterubbledense:1,100)
RB(12,12,12,srparasites:parasitestain:1,80,quark:crystal:1,30,srparasites:parasiterubbledense:1,100)
B(13,12,12,betternether:quartz_stained_glass:15)
B(14,12,12,betternether:quartz_stained_glass:15)
B(10,12,13,betternether:quartz_stained_glass:15)
B(11,12,13,betternether:quartz_stained_glass:15)
B(12,12,13,betternether:quartz_stained_glass:15)
B(13,12,13,betternether:quartz_stained_glass:15)
B(11,12,14,betternether:quartz_stained_glass:15)
B(12,12,14,betternether:quartz_stained_glass:15)
B(11,13,8,betternether:quartz_stained_glass:15)
B(10,13,9,betternether:quartz_stained_glass:15)
B(11,13,9,betternether:quartz_stained_glass:15)
B(12,13,9,betternether:quartz_stained_glass:15)
B(9,13,10,betternether:quartz_stained_glass:15)
B(10,13,10,betternether:quartz_stained_glass:15)
RB(11,13,10,srparasites:parasitestain:1,80,quark:crystal:1,30,srparasites:parasiterubbledense:1,100)
B(12,13,10,betternether:quartz_stained_glass:15)
B(13,13,10,betternether:quartz_stained_glass:15)
B(8,13,11,betternether:quartz_stained_glass:15)
B(9,13,11,betternether:quartz_stained_glass:15)
RB(10,13,11,srparasites:parasitestain:1,80,quark:crystal:1,30,srparasites:parasiterubbledense:1,100)
RB(11,13,11,srparasites:parasitestain:1,80,quark:crystal:1,30,srparasites:parasiterubbledense:1,100)
RB(12,13,11,srparasites:parasitestain:1,80,quark:crystal:1,30,srparasites:parasiterubbledense:1,100)
B(13,13,11,betternether:quartz_stained_glass:15)
B(14,13,11,betternether:quartz_stained_glass:15)
B(9,13,12,betternether:quartz_stained_glass:15)
B(10,13,12,betternether:quartz_stained_glass:15)
RB(11,13,12,srparasites:parasitestain:1,80,quark:crystal:1,30,srparasites:parasiterubbledense:1,100)
B(12,13,12,betternether:quartz_stained_glass:15)
B(13,13,12,betternether:quartz_stained_glass:15)
B(10,13,13,betternether:quartz_stained_glass:15)
B(11,13,13,betternether:quartz_stained_glass:15)
B(12,13,13,betternether:quartz_stained_glass:15)
B(11,13,14,betternether:quartz_stained_glass:15)
B(10,14,8,betternether:quartz_stained_glass:15)
B(11,14,8,betternether:quartz_stained_glass:15)
B(9,14,9,betternether:quartz_stained_glass:15)
B(10,14,9,betternether:quartz_stained_glass:15)
B(11,14,9,betternether:quartz_stained_glass:15)
B(12,14,9,betternether:quartz_stained_glass:15)
B(8,14,10,betternether:quartz_stained_glass:15)
B(9,14,10,betternether:quartz_stained_glass:15)
RB(10,14,10,srparasites:parasitestain:1,80,quark:crystal:1,30,srparasites:parasiterubbledense:1,100)
RB(11,14,10,srparasites:parasitestain:1,80,quark:crystal:1,30,srparasites:parasiterubbledense:1,100)
B(12,14,10,betternether:quartz_stained_glass:15)
B(13,14,10,betternether:quartz_stained_glass:15)
B(8,14,11,betternether:quartz_stained_glass:15)
B(9,14,11,betternether:quartz_stained_glass:15)
RB(10,14,11,srparasites:parasitestain:1,80,quark:crystal:1,30,srparasites:parasiterubbledense:1,100)
RB(11,14,11,srparasites:parasitestain:1,80,quark:crystal:1,30,srparasites:parasiterubbledense:1,100)
B(12,14,11,betternether:quartz_stained_glass:15)
B(13,14,11,betternether:quartz_stained_glass:15)
B(9,14,12,betternether:quartz_stained_glass:15)
B(10,14,12,betternether:quartz_stained_glass:15)
B(11,14,12,betternether:quartz_stained_glass:15)
B(12,14,12,betternether:quartz_stained_glass:15)
B(10,14,13,betternether:quartz_stained_glass:15)
B(11,14,13,betternether:quartz_stained_glass:15)
B(10,15,7,betternether:quartz_stained_glass:15)
B(9,15,8,betternether:quartz_stained_glass:15)
B(10,15,8,betternether:quartz_stained_glass:15)
B(11,15,8,betternether:quartz_stained_glass:15)
B(8,15,9,betternether:quartz_stained_glass:15)
B(9,15,9,betternether:quartz_stained_glass:15)
RB(10,15,9,srparasites:parasitestain:1,80,quark:crystal:1,30,srparasites:parasiterubbledense:1,100)
B(11,15,9,betternether:quartz_stained_glass:15)
B(12,15,9,betternether:quartz_stained_glass:15)
B(7,15,10,betternether:quartz_stained_glass:15)
B(8,15,10,betternether:quartz_stained_glass:15)
RB(9,15,10,srparasites:parasitestain:1,80,quark:crystal:1,30,srparasites:parasiterubbledense:1,100)
RB(10,15,10,srparasites:parasitestain:1,80,quark:crystal:1,30,srparasites:parasiterubbledense:1,100)
RB(11,15,10,srparasites:parasitestain:1,80,quark:crystal:1,30,srparasites:parasiterubbledense:1,100)
B(12,15,10,betternether:quartz_stained_glass:15)
B(13,15,10,betternether:quartz_stained_glass:15)
B(8,15,11,betternether:quartz_stained_glass:15)
B(9,15,11,betternether:quartz_stained_glass:15)
RB(10,15,11,srparasites:parasitestain:1,80,quark:crystal:1,30,srparasites:parasiterubbledense:1,100)
B(11,15,11,betternether:quartz_stained_glass:15)
B(12,15,11,betternether:quartz_stained_glass:15)
B(9,15,12,betternether:quartz_stained_glass:15)
B(10,15,12,betternether:quartz_stained_glass:15)
B(11,15,12,betternether:quartz_stained_glass:15)
B(10,15,13,betternether:quartz_stained_glass:15)
B(9,16,7,betternether:quartz_stained_glass:15)
B(10,16,7,betternether:quartz_stained_glass:15)
B(8,16,8,betternether:quartz_stained_glass:15)
B(9,16,8,betternether:quartz_stained_glass:15)
B(10,16,8,betternether:quartz_stained_glass:15)
B(11,16,8,betternether:quartz_stained_glass:15)
B(7,16,9,betternether:quartz_stained_glass:15)
B(8,16,9,betternether:quartz_stained_glass:15)
RB(9,16,9,srparasites:parasitestain:1,80,quark:crystal:1,30,srparasites:parasiterubbledense:1,100)
RB(10,16,9,srparasites:parasitestain:1,80,quark:crystal:1,30,srparasites:parasiterubbledense:1,100)
B(11,16,9,betternether:quartz_stained_glass:15)
B(12,16,9,betternether:quartz_stained_glass:15)
B(7,16,10,betternether:quartz_stained_glass:15)
B(8,16,10,betternether:quartz_stained_glass:15)
RB(9,16,10,srparasites:parasitestain:1,80,quark:crystal:1,30,srparasites:parasiterubbledense:1,100)
RB(10,16,10,srparasites:parasitestain:1,80,quark:crystal:1,30,srparasites:parasiterubbledense:1,100)
B(11,16,10,betternether:quartz_stained_glass:15)
B(12,16,10,betternether:quartz_stained_glass:15)
B(8,16,11,betternether:quartz_stained_glass:15)
B(9,16,11,betternether:quartz_stained_glass:15)
B(10,16,11,betternether:quartz_stained_glass:15)
B(11,16,11,betternether:quartz_stained_glass:15)
B(9,16,12,betternether:quartz_stained_glass:15)
B(10,16,12,betternether:quartz_stained_glass:15)
B(9,17,6,betternether:quartz_stained_glass:15)
B(8,17,7,betternether:quartz_stained_glass:15)
B(9,17,7,betternether:quartz_stained_glass:15)
B(10,17,7,betternether:quartz_stained_glass:15)
B(7,17,8,betternether:quartz_stained_glass:15)
B(8,17,8,betternether:quartz_stained_glass:15)
RB(9,17,8,srparasites:parasitestain:1,80,quark:crystal:1,30,srparasites:parasiterubbledense:1,100)
B(10,17,8,betternether:quartz_stained_glass:15)
B(11,17,8,betternether:quartz_stained_glass:15)
B(6,17,9,betternether:quartz_stained_glass:15)
B(7,17,9,betternether:quartz_stained_glass:15)
RB(8,17,9,srparasites:parasitestain:1,80,quark:crystal:1,30,srparasites:parasiterubbledense:1,100)
RB(9,17,9,srparasites:parasitestain:1,80,quark:crystal:1,30,srparasites:parasiterubbledense:1,100)
RB(10,17,9,srparasites:parasitestain:1,80,quark:crystal:1,30,srparasites:parasiterubbledense:1,100)
B(11,17,9,betternether:quartz_stained_glass:15)
B(12,17,9,betternether:quartz_stained_glass:15)
B(7,17,10,betternether:quartz_stained_glass:15)
B(8,17,10,betternether:quartz_stained_glass:15)
RB(9,17,10,srparasites:parasitestain:1,80,quark:crystal:1,30,srparasites:parasiterubbledense:1,100)
B(10,17,10,betternether:quartz_stained_glass:15)
B(11,17,10,betternether:quartz_stained_glass:15)
B(8,17,11,betternether:quartz_stained_glass:15)
B(9,17,11,betternether:quartz_stained_glass:15)
B(10,17,11,betternether:quartz_stained_glass:15)
B(9,17,12,betternether:quartz_stained_glass:15)
B(8,18,6,betternether:quartz_stained_glass:15)
B(9,18,6,betternether:quartz_stained_glass:15)
B(7,18,7,betternether:quartz_stained_glass:15)
B(8,18,7,betternether:quartz_stained_glass:15)
B(9,18,7,betternether:quartz_stained_glass:15)
B(10,18,7,betternether:quartz_stained_glass:15)
B(6,18,8,betternether:quartz_stained_glass:15)
B(7,18,8,betternether:quartz_stained_glass:15)
RB(8,18,8,srparasites:parasitestain:1,80,quark:crystal:1,30,srparasites:parasiterubbledense:1,100)
RB(9,18,8,srparasites:parasitestain:1,80,quark:crystal:1,30,srparasites:parasiterubbledense:1,100)
B(10,18,8,betternether:quartz_stained_glass:15)
B(11,18,8,betternether:quartz_stained_glass:15)
B(6,18,9,betternether:quartz_stained_glass:15)
B(7,18,9,betternether:quartz_stained_glass:15)
RB(8,18,9,srparasites:parasitestain:1,80,quark:crystal:1,30,srparasites:parasiterubbledense:1,100)
RB(9,18,9,srparasites:parasitestain:1,80,quark:crystal:1,30,srparasites:parasiterubbledense:1,100)
B(10,18,9,betternether:quartz_stained_glass:15)
B(11,18,9,betternether:quartz_stained_glass:15)
B(7,18,10,betternether:quartz_stained_glass:15)
B(8,18,10,betternether:quartz_stained_glass:15)
B(9,18,10,betternether:quartz_stained_glass:15)
B(10,18,10,betternether:quartz_stained_glass:15)
B(8,18,11,betternether:quartz_stained_glass:15)
B(9,18,11,betternether:quartz_stained_glass:15)
B(8,19,5,betternether:quartz_stained_glass:15)
B(7,19,6,betternether:quartz_stained_glass:15)
B(8,19,6,betternether:quartz_stained_glass:15)
B(9,19,6,betternether:quartz_stained_glass:15)
B(6,19,7,betternether:quartz_stained_glass:15)
B(7,19,7,betternether:quartz_stained_glass:15)
RB(8,19,7,srparasites:parasitestain:1,80,quark:crystal:1,30,srparasites:parasiterubbledense:1,100)
B(9,19,7,betternether:quartz_stained_glass:15)
B(10,19,7,betternether:quartz_stained_glass:15)
B(5,19,8,betternether:quartz_stained_glass:15)
B(6,19,8,betternether:quartz_stained_glass:15)
RB(7,19,8,srparasites:parasitestain:1,80,quark:crystal:1,30,srparasites:parasiterubbledense:1,100)
RB(8,19,8,srparasites:parasitestain:1,80,quark:crystal:1,30,srparasites:parasiterubbledense:1,100)
RB(9,19,8,srparasites:parasitestain:1,80,quark:crystal:1,30,srparasites:parasiterubbledense:1,100)
B(10,19,8,betternether:quartz_stained_glass:15)
B(11,19,8,betternether:quartz_stained_glass:15)
B(6,19,9,betternether:quartz_stained_glass:15)
B(7,19,9,betternether:quartz_stained_glass:15)
RB(8,19,9,srparasites:parasitestain:1,80,quark:crystal:1,30,srparasites:parasiterubbledense:1,100)
B(9,19,9,betternether:quartz_stained_glass:15)
B(10,19,9,betternether:quartz_stained_glass:15)
B(7,19,10,betternether:quartz_stained_glass:15)
B(8,19,10,betternether:quartz_stained_glass:15)
B(9,19,10,betternether:quartz_stained_glass:15)
B(8,19,11,betternether:quartz_stained_glass:15)
B(7,20,5,betternether:quartz_stained_glass:15)
B(8,20,5,betternether:quartz_stained_glass:15)
B(6,20,6,betternether:quartz_stained_glass:15)
B(7,20,6,betternether:quartz_stained_glass:15)
B(8,20,6,betternether:quartz_stained_glass:15)
B(9,20,6,betternether:quartz_stained_glass:15)
B(5,20,7,betternether:quartz_stained_glass:15)
B(6,20,7,betternether:quartz_stained_glass:15)
RB(7,20,7,srparasites:parasitestain:1,80,quark:crystal:1,30,srparasites:parasiterubbledense:1,100)
RB(8,20,7,srparasites:parasitestain:1,80,quark:crystal:1,30,srparasites:parasiterubbledense:1,100)
B(9,20,7,betternether:quartz_stained_glass:15)
B(10,20,7,betternether:quartz_stained_glass:15)
B(5,20,8,betternether:quartz_stained_glass:15)
B(6,20,8,betternether:quartz_stained_glass:15)
RB(7,20,8,srparasites:parasitestain:1,80,quark:crystal:1,30,srparasites:parasiterubbledense:1,100)
RB(8,20,8,srparasites:parasitestain:1,80,quark:crystal:1,30,srparasites:parasiterubbledense:1,100)
B(9,20,8,betternether:quartz_stained_glass:15)
B(10,20,8,betternether:quartz_stained_glass:15)
B(6,20,9,betternether:quartz_stained_glass:15)
B(7,20,9,betternether:quartz_stained_glass:15)
B(8,20,9,betternether:quartz_stained_glass:15)
B(9,20,9,betternether:quartz_stained_glass:15)
B(7,20,10,betternether:quartz_stained_glass:15)
B(8,20,10,betternether:quartz_stained_glass:15)
B(7,21,4,betternether:quartz_stained_glass:15)
B(6,21,5,betternether:quartz_stained_glass:15)
B(7,21,5,betternether:quartz_stained_glass:15)
B(8,21,5,betternether:quartz_stained_glass:15)
B(5,21,6,betternether:quartz_stained_glass:15)
B(6,21,6,betternether:quartz_stained_glass:15)
RB(7,21,6,srparasites:parasitestain:1,80,quark:crystal:1,30,srparasites:parasiterubbledense:1,100)
B(8,21,6,betternether:quartz_stained_glass:15)
B(9,21,6,betternether:quartz_stained_glass:15)
B(4,21,7,betternether:quartz_stained_glass:15)
B(5,21,7,betternether:quartz_stained_glass:15)
RB(6,21,7,srparasites:parasitestain:1,80,quark:crystal:1,30,srparasites:parasiterubbledense:1,100)
RB(7,21,7,srparasites:parasitestain:1,80,quark:crystal:1,30,srparasites:parasiterubbledense:1,100)
RB(8,21,7,srparasites:parasitestain:1,80,quark:crystal:1,30,srparasites:parasiterubbledense:1,100)
B(9,21,7,betternether:quartz_stained_glass:15)
B(10,21,7,betternether:quartz_stained_glass:15)
B(5,21,8,betternether:quartz_stained_glass:15)
B(6,21,8,betternether:quartz_stained_glass:15)
RB(7,21,8,srparasites:parasitestain:1,80,quark:crystal:1,30,srparasites:parasiterubbledense:1,100)
B(8,21,8,betternether:quartz_stained_glass:15)
B(9,21,8,betternether:quartz_stained_glass:15)
B(6,21,9,betternether:quartz_stained_glass:15)
B(7,21,9,betternether:quartz_stained_glass:15)
B(8,21,9,betternether:quartz_stained_glass:15)
B(7,21,10,betternether:quartz_stained_glass:15)
B(6,22,4,betternether:quartz_stained_glass:15)
B(7,22,4,betternether:quartz_stained_glass:15)
B(5,22,5,betternether:quartz_stained_glass:15)
B(6,22,5,betternether:quartz_stained_glass:15)
B(7,22,5,betternether:quartz_stained_glass:15)
B(8,22,5,betternether:quartz_stained_glass:15)
B(4,22,6,betternether:quartz_stained_glass:15)
B(5,22,6,betternether:quartz_stained_glass:15)
RB(6,22,6,srparasites:parasitestain:1,80,quark:crystal:1,30,srparasites:parasiterubbledense:1,100)
RB(7,22,6,srparasites:parasitestain:1,80,quark:crystal:1,30,srparasites:parasiterubbledense:1,100)
B(8,22,6,betternether:quartz_stained_glass:15)
B(9,22,6,betternether:quartz_stained_glass:15)
B(4,22,7,betternether:quartz_stained_glass:15)
B(5,22,7,betternether:quartz_stained_glass:15)
RB(6,22,7,srparasites:parasitestain:1,80,quark:crystal:1,30,srparasites:parasiterubbledense:1,100)
RB(7,22,7,srparasites:parasitestain:1,80,quark:crystal:1,30,srparasites:parasiterubbledense:1,100)
B(8,22,7,betternether:quartz_stained_glass:15)
B(9,22,7,betternether:quartz_stained_glass:15)
B(5,22,8,betternether:quartz_stained_glass:15)
B(6,22,8,betternether:quartz_stained_glass:15)
B(7,22,8,betternether:quartz_stained_glass:15)
B(8,22,8,betternether:quartz_stained_glass:15)
B(6,22,9,betternether:quartz_stained_glass:15)
B(7,22,9,betternether:quartz_stained_glass:15)
B(6,23,3,betternether:quartz_stained_glass:15)
B(5,23,4,betternether:quartz_stained_glass:15)
B(6,23,4,betternether:quartz_stained_glass:15)
B(7,23,4,betternether:quartz_stained_glass:15)
B(4,23,5,betternether:quartz_stained_glass:15)
B(5,23,5,betternether:quartz_stained_glass:15)
RB(6,23,5,srparasites:parasitestain:1,80,quark:crystal:1,30,srparasites:parasiterubbledense:1,100)
B(7,23,5,betternether:quartz_stained_glass:15)
B(8,23,5,betternether:quartz_stained_glass:15)
B(3,23,6,betternether:quartz_stained_glass:15)
B(4,23,6,betternether:quartz_stained_glass:15)
RB(5,23,6,srparasites:parasitestain:1,80,quark:crystal:1,30,srparasites:parasiterubbledense:1,100)
RB(6,23,6,srparasites:parasitestain:1,80,quark:crystal:1,30,srparasites:parasiterubbledense:1,100)
RB(7,23,6,srparasites:parasitestain:1,80,quark:crystal:1,30,srparasites:parasiterubbledense:1,100)
B(8,23,6,betternether:quartz_stained_glass:15)
B(9,23,6,betternether:quartz_stained_glass:15)
B(4,23,7,betternether:quartz_stained_glass:15)
B(5,23,7,betternether:quartz_stained_glass:15)
RB(6,23,7,srparasites:parasitestain:1,80,quark:crystal:1,30,srparasites:parasiterubbledense:1,100)
B(7,23,7,betternether:quartz_stained_glass:15)
B(8,23,7,betternether:quartz_stained_glass:15)
B(5,23,8,betternether:quartz_stained_glass:15)
B(6,23,8,betternether:quartz_stained_glass:15)
B(7,23,8,betternether:quartz_stained_glass:15)
B(6,23,9,betternether:quartz_stained_glass:15)
B(5,24,3,betternether:quartz_stained_glass:15)
B(6,24,3,betternether:quartz_stained_glass:15)
B(4,24,4,betternether:quartz_stained_glass:15)
B(5,24,4,betternether:quartz_stained_glass:15)
B(6,24,4,betternether:quartz_stained_glass:15)
B(7,24,4,betternether:quartz_stained_glass:15)
B(3,24,5,betternether:quartz_stained_glass:15)
B(4,24,5,betternether:quartz_stained_glass:15)
RB(5,24,5,srparasites:parasitestain:1,80,quark:crystal:1,30,srparasites:parasiterubbledense:1,100)
RB(6,24,5,srparasites:parasitestain:1,80,quark:crystal:1,30,srparasites:parasiterubbledense:1,100)
B(7,24,5,betternether:quartz_stained_glass:15)
B(8,24,5,betternether:quartz_stained_glass:15)
B(3,24,6,betternether:quartz_stained_glass:15)
B(4,24,6,betternether:quartz_stained_glass:15)
RB(5,24,6,srparasites:parasitestain:1,80,quark:crystal:1,30,srparasites:parasiterubbledense:1,100)
RB(6,24,6,srparasites:parasitestain:1,80,quark:crystal:1,30,srparasites:parasiterubbledense:1,100)
B(7,24,6,betternether:quartz_stained_glass:15)
B(8,24,6,betternether:quartz_stained_glass:15)
B(4,24,7,betternether:quartz_stained_glass:15)
B(5,24,7,betternether:quartz_stained_glass:15)
B(6,24,7,betternether:quartz_stained_glass:15)
B(7,24,7,betternether:quartz_stained_glass:15)
B(5,24,8,betternether:quartz_stained_glass:15)
B(6,24,8,betternether:quartz_stained_glass:15)
B(5,25,2,betternether:quartz_stained_glass:15)
B(4,25,3,betternether:quartz_stained_glass:15)
B(5,25,3,betternether:quartz_stained_glass:15)
B(6,25,3,betternether:quartz_stained_glass:15)
B(3,25,4,betternether:quartz_stained_glass:15)
B(4,25,4,betternether:quartz_stained_glass:15)
RB(5,25,4,srparasites:parasitestain:1,80,quark:crystal:1,30,srparasites:parasiterubbledense:1,100)
B(6,25,4,betternether:quartz_stained_glass:15)
B(7,25,4,betternether:quartz_stained_glass:15)
B(2,25,5,betternether:quartz_stained_glass:15)
B(3,25,5,betternether:quartz_stained_glass:15)
RB(4,25,5,srparasites:parasitestain:1,80,quark:crystal:1,30,srparasites:parasiterubbledense:1,100)
RB(5,25,5,srparasites:parasitestain:1,80,quark:crystal:1,30,srparasites:parasiterubbledense:1,100)
RB(6,25,5,srparasites:parasitestain:1,80,quark:crystal:1,30,srparasites:parasiterubbledense:1,100)
B(7,25,5,betternether:quartz_stained_glass:15)
B(8,25,5,betternether:quartz_stained_glass:15)
B(3,25,6,betternether:quartz_stained_glass:15)
B(4,25,6,betternether:quartz_stained_glass:15)
RB(5,25,6,srparasites:parasitestain:1,80,quark:crystal:1,30,srparasites:parasiterubbledense:1,100)
B(6,25,6,betternether:quartz_stained_glass:15)
B(7,25,6,betternether:quartz_stained_glass:15)
B(4,25,7,betternether:quartz_stained_glass:15)
B(5,25,7,betternether:quartz_stained_glass:15)
B(6,25,7,betternether:quartz_stained_glass:15)
B(5,25,8,betternether:quartz_stained_glass:15)
B(4,26,2,betternether:quartz_stained_glass:15)
B(5,26,2,betternether:quartz_stained_glass:15)
B(3,26,3,betternether:quartz_stained_glass:15)
B(4,26,3,betternether:quartz_stained_glass:15)
B(5,26,3,betternether:quartz_stained_glass:15)
B(6,26,3,betternether:quartz_stained_glass:15)
B(2,26,4,betternether:quartz_stained_glass:15)
B(3,26,4,betternether:quartz_stained_glass:15)
RB(4,26,4,srparasites:parasitestain:1,80,quark:crystal:1,30,srparasites:parasiterubbledense:1,100)
RB(5,26,4,srparasites:parasitestain:1,80,quark:crystal:1,30,srparasites:parasiterubbledense:1,100)
B(6,26,4,betternether:quartz_stained_glass:15)
B(7,26,4,betternether:quartz_stained_glass:15)
B(2,26,5,betternether:quartz_stained_glass:15)
B(3,26,5,betternether:quartz_stained_glass:15)
RB(4,26,5,srparasites:parasitestain:1,80,quark:crystal:1,30,srparasites:parasiterubbledense:1,100)
RB(5,26,5,srparasites:parasitestain:1,80,quark:crystal:1,30,srparasites:parasiterubbledense:1,100)
B(6,26,5,betternether:quartz_stained_glass:15)
B(7,26,5,betternether:quartz_stained_glass:15)
B(3,26,6,betternether:quartz_stained_glass:15)
B(4,26,6,betternether:quartz_stained_glass:15)
B(5,26,6,betternether:quartz_stained_glass:15)
B(6,26,6,betternether:quartz_stained_glass:15)
B(4,26,7,betternether:quartz_stained_glass:15)
B(5,26,7,betternether:quartz_stained_glass:15)
B(4,27,1,betternether:quartz_stained_glass:15)
B(3,27,2,betternether:quartz_stained_glass:15)
B(4,27,2,betternether:quartz_stained_glass:15)
B(5,27,2,betternether:quartz_stained_glass:15)
B(2,27,3,betternether:quartz_stained_glass:15)
B(3,27,3,betternether:quartz_stained_glass:15)
RB(4,27,3,srparasites:parasitestain:1,80,quark:crystal:1,30,srparasites:parasiterubbledense:1,100)
B(5,27,3,betternether:quartz_stained_glass:15)
B(6,27,3,betternether:quartz_stained_glass:15)
B(1,27,4,betternether:quartz_stained_glass:15)
B(2,27,4,betternether:quartz_stained_glass:15)
RB(3,27,4,srparasites:parasitestain:1,80,quark:crystal:1,30,srparasites:parasiterubbledense:1,100)
RB(4,27,4,srparasites:parasitestain:1,80,quark:crystal:1,30,srparasites:parasiterubbledense:1,100)
RB(5,27,4,srparasites:parasitestain:1,80,quark:crystal:1,30,srparasites:parasiterubbledense:1,100)
B(6,27,4,betternether:quartz_stained_glass:15)
B(7,27,4,betternether:quartz_stained_glass:15)
B(2,27,5,betternether:quartz_stained_glass:15)
B(3,27,5,betternether:quartz_stained_glass:15)
RB(4,27,5,srparasites:parasitestain:1,80,quark:crystal:1,30,srparasites:parasiterubbledense:1,100)
B(5,27,5,betternether:quartz_stained_glass:15)
B(6,27,5,betternether:quartz_stained_glass:15)
B(3,27,6,betternether:quartz_stained_glass:15)
B(4,27,6,betternether:quartz_stained_glass:15)
B(5,27,6,betternether:quartz_stained_glass:15)
B(4,27,7,betternether:quartz_stained_glass:15)
B(3,28,1,betternether:quartz_stained_glass:15)
B(4,28,1,betternether:quartz_stained_glass:15)
B(2,28,2,betternether:quartz_stained_glass:15)
B(3,28,2,betternether:quartz_stained_glass:15)
B(4,28,2,betternether:quartz_stained_glass:15)
B(5,28,2,betternether:quartz_stained_glass:15)
B(1,28,3,betternether:quartz_stained_glass:15)
B(2,28,3,betternether:quartz_stained_glass:15)
RB(3,28,3,srparasites:parasitestain:1,80,quark:crystal:1,30,srparasites:parasiterubbledense:1,100)
RB(4,28,3,srparasites:parasitestain:1,80,quark:crystal:1,30,srparasites:parasiterubbledense:1,100)
B(5,28,3,betternether:quartz_stained_glass:15)
B(6,28,3,betternether:quartz_stained_glass:15)
B(1,28,4,betternether:quartz_stained_glass:15)
B(2,28,4,betternether:quartz_stained_glass:15)
RB(3,28,4,srparasites:parasitestain:1,80,quark:crystal:1,30,srparasites:parasiterubbledense:1,100)
RB(4,28,4,srparasites:parasitestain:1,80,quark:crystal:1,30,srparasites:parasiterubbledense:1,100)
B(5,28,4,betternether:quartz_stained_glass:15)
B(6,28,4,betternether:quartz_stained_glass:15)
B(2,28,5,betternether:quartz_stained_glass:15)
B(3,28,5,betternether:quartz_stained_glass:15)
B(4,28,5,betternether:quartz_stained_glass:15)
B(5,28,5,betternether:quartz_stained_glass:15)
B(3,28,6,betternether:quartz_stained_glass:15)
B(4,28,6,betternether:quartz_stained_glass:15)
B(3,29,0,betternether:quartz_stained_glass:15)
B(2,29,1,betternether:quartz_stained_glass:15)
B(3,29,1,betternether:quartz_stained_glass:15)
B(4,29,1,betternether:quartz_stained_glass:15)
B(1,29,2,betternether:quartz_stained_glass:15)
B(2,29,2,betternether:quartz_stained_glass:15)
RB(3,29,2,srparasites:parasitestain:1,80,quark:crystal:1,30,srparasites:parasiterubbledense:1,100)
B(4,29,2,betternether:quartz_stained_glass:15)
B(5,29,2,betternether:quartz_stained_glass:15)
B(0,29,3,betternether:quartz_stained_glass:15)
B(1,29,3,betternether:quartz_stained_glass:15)
RB(2,29,3,srparasites:parasitestain:1,80,quark:crystal:1,30,srparasites:parasiterubbledense:1,100)
RB(3,29,3,srparasites:parasitestain:1,80,quark:crystal:1,30,srparasites:parasiterubbledense:1,100)
RB(4,29,3,srparasites:parasitestain:1,80,quark:crystal:1,30,srparasites:parasiterubbledense:1,100)
B(5,29,3,betternether:quartz_stained_glass:15)
B(6,29,3,betternether:quartz_stained_glass:15)
B(1,29,4,betternether:quartz_stained_glass:15)
B(2,29,4,betternether:quartz_stained_glass:15)
RB(3,29,4,srparasites:parasitestain:1,80,quark:crystal:1,30,srparasites:parasiterubbledense:1,100)
B(4,29,4,betternether:quartz_stained_glass:15)
B(5,29,4,betternether:quartz_stained_glass:15)
B(2,29,5,betternether:quartz_stained_glass:15)
B(3,29,5,betternether:quartz_stained_glass:15)
B(4,29,5,betternether:quartz_stained_glass:15)
B(3,29,6,betternether:quartz_stained_glass:15)
B(2,30,0,betternether:quartz_stained_glass:15)
B(3,30,0,betternether:quartz_stained_glass:15)
B(1,30,1,betternether:quartz_stained_glass:15)
B(2,30,1,betternether:quartz_stained_glass:15)
B(3,30,1,betternether:quartz_stained_glass:15)
B(4,30,1,betternether:quartz_stained_glass:15)
B(0,30,2,betternether:quartz_stained_glass:15)
B(1,30,2,betternether:quartz_stained_glass:15)
RB(2,30,2,srparasites:parasitestain:1,80,quark:crystal:1,30,srparasites:parasiterubbledense:1,100)
RB(3,30,2,srparasites:parasitestain:1,80,quark:crystal:1,30,srparasites:parasiterubbledense:1,100)
B(4,30,2,betternether:quartz_stained_glass:15)
B(5,30,2,betternether:quartz_stained_glass:15)
B(0,30,3,betternether:quartz_stained_glass:15)
B(1,30,3,betternether:quartz_stained_glass:15)
RB(2,30,3,srparasites:parasitestain:1,80,quark:crystal:1,30,srparasites:parasiterubbledense:1,100)
RB(3,30,3,srparasites:parasitestain:1,80,quark:crystal:1,30,srparasites:parasiterubbledense:1,100)
B(4,30,3,betternether:quartz_stained_glass:15)
B(5,30,3,betternether:quartz_stained_glass:15)
B(1,30,4,betternether:quartz_stained_glass:15)
B(2,30,4,betternether:quartz_stained_glass:15)
B(3,30,4,betternether:quartz_stained_glass:15)
B(4,30,4,betternether:quartz_stained_glass:15)
B(2,30,5,betternether:quartz_stained_glass:15)
B(3,30,5,betternether:quartz_stained_glass:15)
B(2,31,0,betternether:quartz_stained_glass:15)
B(3,31,0,betternether:quartz_stained_glass:15)
B(1,31,1,betternether:quartz_stained_glass:15)
RB(2,31,1,srparasites:parasitestain:1,80,quark:crystal:1,30,srparasites:parasiterubbledense:1,100)
B(3,31,1,betternether:quartz_stained_glass:15)
B(4,31,1,betternether:quartz_stained_glass:15)
B(0,31,2,betternether:quartz_stained_glass:15)
RB(1,31,2,srparasites:parasitestain:1,80,quark:crystal:1,30,srparasites:parasiterubbledense:1,100)
RB(2,31,2,srparasites:parasitestain:1,80,quark:crystal:1,30,srparasites:parasiterubbledense:1,100)
RB(3,31,2,srparasites:parasitestain:1,80,quark:crystal:1,30,srparasites:parasiterubbledense:1,100)
B(4,31,2,betternether:quartz_stained_glass:15)
B(5,31,2,betternether:quartz_stained_glass:15)
B(0,31,3,betternether:quartz_stained_glass:15)
B(1,31,3,betternether:quartz_stained_glass:15)
RB(2,31,3,srparasites:parasitestain:1,80,quark:crystal:1,30,srparasites:parasiterubbledense:1,100)
B(3,31,3,betternether:quartz_stained_glass:15)
B(4,31,3,betternether:quartz_stained_glass:15)
B(1,31,4,betternether:quartz_stained_glass:15)
B(2,31,4,betternether:quartz_stained_glass:15)
B(3,31,4,betternether:quartz_stained_glass:15)
B(2,31,5,betternether:quartz_stained_glass:15)
B(1,32,0,betternether:quartz_stained_glass:15)
B(2,32,0,betternether:quartz_stained_glass:15)
B(3,32,0,betternether:quartz_stained_glass:15)
B(0,32,1,betternether:quartz_stained_glass:15)
RB(1,32,1,srparasites:parasitestain:1,80,quark:crystal:1,30,srparasites:parasiterubbledense:1,100)
RB(2,32,1,srparasites:parasitestain:1,80,quark:crystal:1,30,srparasites:parasiterubbledense:1,100)
B(3,32,1,betternether:quartz_stained_glass:15)
B(4,32,1,betternether:quartz_stained_glass:15)
B(0,32,2,betternether:quartz_stained_glass:15)
RB(1,32,2,srparasites:parasitestain:1,80,quark:crystal:1,30,srparasites:parasiterubbledense:1,100)
RB(2,32,2,srparasites:parasitestain:1,80,quark:crystal:1,30,srparasites:parasiterubbledense:1,100)
B(3,32,2,betternether:quartz_stained_glass:15)
B(4,32,2,betternether:quartz_stained_glass:15)
B(0,32,3,betternether:quartz_stained_glass:15)
B(1,32,3,betternether:quartz_stained_glass:15)
B(2,32,3,betternether:quartz_stained_glass:15)
B(3,32,3,betternether:quartz_stained_glass:15)
B(1,32,4,betternether:quartz_stained_glass:15)
B(2,32,4,betternether:quartz_stained_glass:15)
B(1,33,0,betternether:quartz_stained_glass:15)
B(2,33,0,betternether:quartz_stained_glass:15)
B(0,33,1,betternether:quartz_stained_glass:15)
RB(1,33,1,srparasites:parasitestain:1,80,quark:crystal:1,30,srparasites:parasiterubbledense:1,100)
B(2,33,1,betternether:quartz_stained_glass:15)
B(3,33,1,betternether:quartz_stained_glass:15)
B(0,33,2,betternether:quartz_stained_glass:15)
B(1,33,2,betternether:quartz_stained_glass:15)
B(2,33,2,betternether:quartz_stained_glass:15)
B(3,33,2,betternether:quartz_stained_glass:15)
B(1,33,3,betternether:quartz_stained_glass:15)
B(2,33,3,betternether:quartz_stained_glass:15)
B(1,34,0,betternether:quartz_stained_glass:15)
B(0,34,1,betternether:quartz_stained_glass:15)
B(1,34,1,betternether:quartz_stained_glass:15)
B(2,34,1,betternether:quartz_stained_glass:15)
B(1,34,2,betternether:quartz_stained_glass:15)
B(2,34,2,betternether:quartz_stained_glass:15)
B(1,35,1,betternether:quartz_stained_glass:15)

