
#######################################################################
# +-----------------------------------------------------------------+ #
# |                            BO4 object                           | #
# +-----------------------------------------------------------------+ #
#######################################################################

Author: NLBlackEagle

Description: No description given

SettingsMode: WriteDisable


#######################################################################
# +-----------------------------------------------------------------+ #
# |                          Main settings                          | #
# +-----------------------------------------------------------------+ #
#######################################################################

Frequency: 0

SpawnHeight: highestBlock

UseCenterForHighestBlock: true

##############################
# Height Limits for the BO4. #
##############################

MinHeight: 0

MaxHeight: 255

InheritBO3: 

InheritBO3Rotation: NORTH

OverrideChildSettings: true

OverrideParentHeight: false

CanOverride: false

BranchFrequency: 0

BranchFrequencyGroup: 

MustBeBelowOther: false

MustBeInside: 

CannotBeInside: 

ReplacesBO3: 

MustBeInsideWorldBorders: false

CanSpawnOnWater: true

SpawnOnWaterOnly: false

SpawnUnderWater: false

SpawnAtWaterLevel: false

HeightOffset: 0

RemoveAir: true

ReplaceAbove: 

ReplaceBelow: 

ReplaceWithBiomeBlocks: true

ReplaceWithSurfaceBlock: GRASS

ReplaceWithGroundBlock: DIRT

ReplaceWithStoneBlock: STONE

SmoothRadius: 0

SmoothHeightOffset: 0

SmoothStartTop: false

SmoothStartWood: false

SmoothingSurfaceBlock: 

SmoothingGroundBlock: 

BO3Group: 

IsSpawnPoint: false

DoReplaceBlocks: true


#######################################################################
# +-----------------------------------------------------------------+ #
# |                              Blocks                             | #
# +-----------------------------------------------------------------+ #
#######################################################################

Block(-8,0,7,LOG:13)
Block(-8,1,7,LOG:13)
Block(-8,1,8,LOG:13)
Block(-8,2,8,LOG_2:13)
Block(-8,9,6,LEAVES:12)
Block(-8,9,8,LEAVES:12)
Block(-8,10,4,LEAVES:12)
Block(-8,10,5,LEAVES:12)
Block(-8,10,6,LEAVES:12)
Block(-8,10,7,LEAVES:12)
Block(-8,10,8,LEAVES:12)
Block(-8,11,4,LEAVES:12)
Block(-8,11,5,LEAVES:12)
Block(-8,11,6,LEAVES:12)
Block(-8,11,7,LEAVES:12)
Block(-8,11,8,LEAVES:12)
Block(-8,12,4,LEAVES:4)
Block(-8,12,5,LEAVES:12)
Block(-8,12,6,LEAVES:12)
Block(-8,12,7,LEAVES:12)
Block(-8,12,8,LEAVES:12)
Block(-7,1,8,LOG:13)
Block(-7,2,8,LOG:13)
Block(-7,5,7,LEAVES:12)
Block(-7,6,7,LEAVES:12)
Block(-7,7,7,LEAVES:12)
Block(-7,8,7,LEAVES:12)
Block(-7,9,7,LEAVES:12)
Block(-7,9,8,LEAVES:12)
Block(-7,10,5,LEAVES:12)
Block(-7,10,7,LEAVES:12)
Block(-7,10,8,LEAVES:12)
Block(-7,11,4,LEAVES:12)
Block(-7,11,5,LEAVES:12)
Block(-7,11,6,LEAVES:12)
Block(-7,11,7,LEAVES:12)
Block(-7,11,8,LEAVES:12)
Block(-7,12,3,LEAVES:12)
Block(-7,12,4,LEAVES:12)
Block(-7,12,5,LEAVES:12)
Block(-7,12,6,LEAVES:12)
Block(-7,12,7,LEAVES:12)
Block(-7,12,8,LEAVES:4)
Block(-7,13,5,LEAVES:12)
Block(-7,13,6,LEAVES:12)
Block(-7,13,7,LEAVES:12)
Block(-7,13,8,LEAVES:12)
Block(-6,8,8,LEAVES:12)
Block(-6,9,6,LEAVES:12)
Block(-6,9,8,LEAVES:12)
Block(-6,10,6,LEAVES:12)
Block(-6,10,7,LEAVES:12)
Block(-6,10,8,LEAVES:12)
Block(-6,11,5,LEAVES:12)
Block(-6,11,7,LEAVES:12)
Block(-6,11,8,LEAVES:12)
Block(-6,12,5,LEAVES:4)
Block(-6,12,6,LOG:13)
Block(-6,12,7,LEAVES:12)
Block(-6,12,8,LEAVES:12)
Block(-6,13,4,LEAVES:12)
Block(-6,13,5,LEAVES:4)
Block(-6,13,6,LEAVES:4)
Block(-6,13,7,LEAVES:12)
Block(-5,9,7,LEAVES:12)
Block(-5,10,8,LEAVES:12)
Block(-5,11,5,LEAVES:12)
Block(-5,12,7,LOG:13)
Block(-5,13,5,LEAVES:12)
Block(-5,13,6,LEAVES:4)
Block(-5,13,7,LEAVES:12)
Block(-5,13,8,LEAVES:12)
Block(-5,14,7,LEAVES:12)
Block(-4,8,8,LEAVES:12)
Block(-4,9,8,LEAVES:12)
Block(-4,10,8,LEAVES:12)
Block(-4,11,7,LEAVES:12)
Block(-4,11,8,LOG:13)
Block(-4,12,5,LEAVES:12)
Block(-4,12,6,LEAVES:12)
Block(-4,12,7,LEAVES:12)
Block(-4,12,8,LOG:13)
Block(-4,13,4,LEAVES:12)
Block(-4,13,5,LEAVES:12)
Block(-4,13,6,LEAVES:12)
Block(-4,13,7,LEAVES:12)
Block(-4,13,8,LEAVES:12)
Block(-4,14,5,LEAVES:12)
Block(-4,14,7,LEAVES:4)
Block(-4,14,8,LEAVES:12)
Block(-3,10,7,LEAVES:12)
Block(-3,10,8,LEAVES:12)
Block(-3,11,5,LEAVES:12)
Block(-3,11,8,LOG:13)
Block(-3,12,4,LEAVES:12)
Block(-3,12,5,LEAVES:12)
Block(-3,12,6,LEAVES:12)
Block(-3,12,8,LEAVES:12)
Block(-3,13,3,LEAVES:12)
Block(-3,13,4,LEAVES:12)
Block(-3,13,5,LEAVES:4)
Block(-3,13,6,LEAVES:12)
Block(-3,13,8,LEAVES:12)
Block(-3,14,5,LEAVES:12)
Block(-3,14,6,LEAVES:4)
Block(-3,14,7,LEAVES:12)
Block(-3,14,8,LEAVES:12)
Block(-2,9,8,LEAVES:12)
Block(-2,10,7,LEAVES:12)
Block(-2,10,8,LOG:13)
Block(-2,11,6,LEAVES:12)
Block(-2,11,7,LOG:13)
Block(-2,11,8,LOG_2:13)
Block(-2,12,4,LEAVES:12)
Block(-2,12,5,LEAVES:12)
Block(-2,12,6,LEAVES:12)
Block(-2,12,7,LOG:13)
Block(-2,13,3,LEAVES:12)
Block(-2,13,4,LEAVES:4)
Block(-2,13,5,LEAVES:12)
Block(-2,13,6,LEAVES:12)
Block(-2,13,7,LEAVES:12)
Block(-2,13,8,LEAVES:12)
Block(-2,14,5,LEAVES:12)
Block(-2,14,6,LEAVES:12)
Block(-2,14,7,LEAVES:4)
Block(-2,14,8,LEAVES:12)
Block(-1,7,7,LEAVES:12)
Block(-1,8,7,LEAVES:12)
Block(-1,9,7,LEAVES:12)
Block(-1,10,5,LEAVES:12)
Block(-1,10,6,LEAVES:12)
Block(-1,10,7,LEAVES:12)
Block(-1,10,8,LEAVES:12)
Block(-1,11,5,LEAVES:12)
Block(-1,11,6,LOG_2:13)
Block(-1,11,7,LOG:13)
Block(-1,11,8,LEAVES:12)
Block(-1,12,3,LEAVES:12)
Block(-1,12,4,LEAVES:12)
Block(-1,12,5,LOG_2:13)
Block(-1,12,6,LOG:13)
Block(-1,12,7,LOG:13)
Block(-1,13,1,LEAVES:12)
Block(-1,13,3,LEAVES:4)
Block(-1,13,4,LEAVES:12)
Block(-1,13,5,LEAVES:4)
Block(-1,13,6,LEAVES:12)
Block(-1,13,7,LEAVES:12)
Block(-1,13,8,LEAVES:12)
Block(-1,14,4,LEAVES:12)
Block(-1,14,6,LEAVES:4)
Block(-1,14,7,LEAVES:4)
Block(-1,14,8,LEAVES:12)
Block(0,11,7,LEAVES:12)
Block(0,12,4,LOG:13)
Block(0,12,5,LOG:13)
Block(0,12,6,LEAVES:12)
Block(0,12,7,LEAVES:12)
Block(0,12,8,LEAVES:12)
Block(0,13,2,LEAVES:12)
Block(0,13,3,LEAVES:4)
Block(0,13,4,LEAVES:12)
Block(0,13,5,LEAVES:12)
Block(0,13,6,LEAVES:12)
Block(0,13,7,LEAVES:12)
Block(0,13,8,LEAVES:12)
Block(0,14,4,LEAVES:12)
Block(0,14,5,LEAVES:12)
Block(0,14,6,LEAVES:12)
Block(0,14,7,LEAVES:12)
Block(1,7,8,LEAVES:12)
Block(1,8,5,LEAVES:12)
Block(1,8,8,LEAVES:12)
Block(1,9,5,LEAVES:12)
Block(1,9,8,LEAVES:12)
Block(1,10,5,LEAVES:12)
Block(1,10,8,LEAVES:12)
Block(1,11,4,LEAVES:12)
Block(1,11,5,LEAVES:12)
Block(1,11,8,LEAVES:12)
Block(1,12,3,LOG:13)
Block(1,12,6,LEAVES:12)
Block(1,12,8,LEAVES:12)
Block(1,13,1,LEAVES:12)
Block(1,13,3,LEAVES:12)
Block(1,13,4,LEAVES:12)
Block(1,13,5,LEAVES:12)
Block(1,13,7,LEAVES:12)
Block(1,13,8,LEAVES:12)
Block(1,14,2,LEAVES:12)
Block(1,14,4,LEAVES:12)
Block(1,14,5,LEAVES:12)
Block(1,14,6,LEAVES:12)
Block(2,-4,7,LOG:13)
Block(2,-3,7,LOG:13)
Block(2,-2,7,LOG:13)
Block(2,-1,7,LOG:13)
Block(2,0,7,minecraft:black_glazed_terracotta:3)
Block(2,0,8,minecraft:black_glazed_terracotta:3)
Block(2,1,8,minecraft:black_glazed_terracotta:3)
Block(2,9,7,LEAVES:12)
Block(2,10,7,LEAVES:12)
Block(2,11,6,LEAVES:12)
Block(2,11,7,LEAVES:12)
Block(2,12,2,LEAVES:12)
Block(2,12,3,LEAVES:12)
Block(2,12,5,LEAVES:12)
Block(2,12,7,LEAVES:12)
Block(2,13,0,LEAVES:12)
Block(2,13,3,LEAVES:12)
Block(2,13,5,LEAVES:12)
Block(2,13,7,LEAVES:12)
Block(2,14,4,LEAVES:12)
Block(3,0,6,minecraft:black_glazed_terracotta:3)
Block(3,0,7,minecraft:black_glazed_terracotta:3)
Block(3,11,3,LEAVES:12)
Block(3,11,5,LEAVES:12)
Block(3,12,1,LEAVES:12)
Block(3,12,3,LEAVES:12)
Block(3,12,7,LEAVES:12)
Block(3,13,2,LEAVES:12)
Block(3,13,4,LEAVES:12)
Block(3,13,6,LEAVES:12)
Block(3,14,3,LEAVES:12)
Block(3,14,5,LEAVES:12)
Block(3,15,8,LEAVES:12)
Block(4,-1,5,minecraft:black_glazed_terracotta:3)
Block(4,-1,6,LOG:13)
Block(4,0,6,minecraft:black_glazed_terracotta:3)
Block(4,7,4,LEAVES:12)
Block(4,8,4,LEAVES:12)
Block(4,9,4,LEAVES:12)
Block(4,10,4,LEAVES:12)
Block(4,11,4,LEAVES:12)
Block(4,12,2,LEAVES:12)
Block(4,12,4,LEAVES:12)
Block(4,12,6,LEAVES:12)
Block(4,12,8,LEAVES:12)
Block(4,13,3,LEAVES:12)
Block(4,13,5,LEAVES:12)
Block(4,15,8,LEAVES:12)
Block(5,-6,5,LOG:13)
Block(5,-5,5,LOG:13)
Block(5,-4,5,LOG:13)
Block(5,-3,5,LOG:13)
Block(5,-2,5,LOG:13)
Block(5,-1,5,minecraft:black_glazed_terracotta:3)
Block(5,12,3,LEAVES:12)
Block(5,12,5,LEAVES:12)
Block(5,13,3,LEAVES:4)
Block(5,13,5,LEAVES:4)
Block(5,15,8,LEAVES:12)
Block(6,12,6,LEAVES:12)
Block(6,13,2,LEAVES:12)
Block(6,15,7,LEAVES:12)
Block(7,14,8,LEAVES:12)

#######################################################################
# +-----------------------------------------------------------------+ #
# |                             Branches                            | #
# +-----------------------------------------------------------------+ #
#######################################################################

Branch(16,0,0,true,CherryTreeCorrupted09C2R0,NORTH,100.0,0)

#######################################################################
# +-----------------------------------------------------------------+ #
# |                             Entities                            | #
# +-----------------------------------------------------------------+ #
#######################################################################


#######################################################################
# +-----------------------------------------------------------------+ #
# |                            Particles                            | #
# +-----------------------------------------------------------------+ #
#######################################################################


#######################################################################
# +-----------------------------------------------------------------+ #
# |                             Spawners                            | #
# +-----------------------------------------------------------------+ #
#######################################################################


#######################################################################
# +-----------------------------------------------------------------+ #
# |                             ModData                             | #
# +-----------------------------------------------------------------+ #
#######################################################################

