
#######################################################################
# +-----------------------------------------------------------------+ #
# |                            BO4 object                           | #
# +-----------------------------------------------------------------+ #
#######################################################################

Author: NLBlackEagle

Description: No description given

SettingsMode: WriteDisable


#######################################################################
# +-----------------------------------------------------------------+ #
# |                          Main settings                          | #
# +-----------------------------------------------------------------+ #
#######################################################################

Frequency: 0

SpawnHeight: highestBlock

UseCenterForHighestBlock: true

##############################
# Height Limits for the BO4. #
##############################

MinHeight: 0

MaxHeight: 255

InheritBO3: 

InheritBO3Rotation: NORTH

OverrideChildSettings: true

OverrideParentHeight: false

CanOverride: true

BranchFrequency: 0

BranchFrequencyGroup: 

MustBeBelowOther: false

MustBeInside: 

CannotBeInside: 

ReplacesBO3: 

MustBeInsideWorldBorders: false

CanSpawnOnWater: true

SpawnOnWaterOnly: false

SpawnUnderWater: false

SpawnAtWaterLevel: false

HeightOffset: 0

RemoveAir: true

ReplaceAbove: 

ReplaceBelow: 

ReplaceWithBiomeBlocks: true

ReplaceWithSurfaceBlock: GRASS

ReplaceWithGroundBlock: DIRT

ReplaceWithStoneBlock: STONE

SmoothRadius: 0

SmoothHeightOffset: 0

SmoothStartTop: false

SmoothStartWood: false

SmoothingSurfaceBlock: 

SmoothingGroundBlock: 

BO3Group: 

IsSpawnPoint: false

DoReplaceBlocks: true


#######################################################################
# +-----------------------------------------------------------------+ #
# |                              Blocks                             | #
# +-----------------------------------------------------------------+ #
#######################################################################

Block(-5,13,8,OBSIDIAN)
Block(-5,14,7,OBSIDIAN)
Block(-5,14,8,OBSIDIAN)
Block(-5,15,7,OBSIDIAN)
Block(-5,15,8,OBSIDIAN)
Block(-5,16,6,OBSIDIAN)
Block(-5,16,7,OBSIDIAN)
Block(-5,17,5,OBSIDIAN)
Block(-5,17,6,OBSIDIAN)
Block(-5,18,4,OBSIDIAN)
Block(-5,18,5,OBSIDIAN)
Block(-5,19,3,OBSIDIAN)
Block(-5,19,4,OBSIDIAN)
Block(-5,20,2,OBSIDIAN)
Block(-5,20,3,OBSIDIAN)
Block(-5,21,1,OBSIDIAN)
Block(-5,21,2,OBSIDIAN)
Block(-5,22,0,OBSIDIAN)
Block(-5,23,-1,SANDSTONE)
Block(-5,24,-2,SANDSTONE)
Block(-5,25,-3,SANDSTONE)
Block(-5,26,-4,OBSIDIAN)
Block(-5,27,-5,OBSIDIAN)
Block(-4,13,8,OBSIDIAN)
Block(-4,14,7,OBSIDIAN)
Block(-4,14,8,OBSIDIAN)
Block(-4,15,6,OBSIDIAN)
Block(-4,15,7,OBSIDIAN)
Block(-4,15,8,OBSIDIAN)
Block(-4,16,5,OBSIDIAN)
Block(-4,16,6,OBSIDIAN)
Block(-4,16,7,OBSIDIAN)
Block(-4,16,8,OBSIDIAN)
Block(-4,17,4,OBSIDIAN)
Block(-4,17,5,OBSIDIAN)
Block(-4,17,6,OBSIDIAN)
Block(-4,17,7,OBSIDIAN)
Block(-4,17,8,OBSIDIAN)
Block(-4,18,3,OBSIDIAN)
Block(-4,18,4,OBSIDIAN)
Block(-4,18,5,OBSIDIAN)
Block(-4,18,6,OBSIDIAN)
Block(-4,18,7,OBSIDIAN)
Block(-4,18,8,OBSIDIAN)
Block(-4,19,2,SANDSTONE)
Block(-4,19,3,SANDSTONE)
Block(-4,19,4,OBSIDIAN)
Block(-4,19,5,OBSIDIAN)
Block(-4,19,6,OBSIDIAN)
Block(-4,20,1,SANDSTONE)
Block(-4,20,2,SANDSTONE)
Block(-4,20,3,SANDSTONE)
Block(-4,20,4,SANDSTONE)
Block(-4,20,5,OBSIDIAN)
Block(-4,21,0,SANDSTONE)
Block(-4,21,1,SANDSTONE)
Block(-4,21,2,SANDSTONE)
Block(-4,21,3,SANDSTONE)
Block(-4,21,4,SANDSTONE)
Block(-4,22,-1,SANDSTONE)
Block(-4,22,0,SANDSTONE)
Block(-4,22,1,SANDSTONE)
Block(-4,22,2,SANDSTONE)
Block(-4,22,3,SANDSTONE)
Block(-4,23,-1,SANDSTONE)
Block(-4,23,0,SANDSTONE)
Block(-4,23,1,SANDSTONE)
Block(-4,23,2,SANDSTONE)
Block(-4,24,-2,SANDSTONE)
Block(-4,24,-1,SANDSTONE)
Block(-4,24,0,SANDSTONE)
Block(-4,24,1,SANDSTONE)
Block(-4,25,-3,SANDSTONE)
Block(-4,25,-2,SANDSTONE)
Block(-4,25,-1,SANDSTONE)
Block(-4,25,0,SANDSTONE)
Block(-4,26,-4,SANDSTONE)
Block(-4,26,-3,SANDSTONE)
Block(-4,26,-2,SANDSTONE)
Block(-4,27,-5,SANDSTONE)
Block(-4,27,-4,SANDSTONE)
Block(-4,27,-3,SANDSTONE)
Block(-4,28,-6,SANDSTONE)
Block(-4,28,-5,SANDSTONE)
Block(-4,28,-4,SANDSTONE)
Block(-4,29,-7,SANDSTONE)
Block(-4,29,-6,SANDSTONE)
Block(-4,29,-5,SANDSTONE)
Block(-4,30,-7,SANDSTONE)
Block(-4,30,-6,SANDSTONE)
Block(-4,31,-7,SANDSTONE)
Block(-3,13,8,SANDSTONE)
Block(-3,14,7,SANDSTONE)
Block(-3,14,8,SANDSTONE)
Block(-3,15,6,SANDSTONE)
Block(-3,15,7,SANDSTONE)
Block(-3,15,8,SANDSTONE)
Block(-3,16,5,SANDSTONE)
Block(-3,16,6,SANDSTONE)
Block(-3,16,7,SANDSTONE)
Block(-3,16,8,SANDSTONE)
Block(-3,17,4,SANDSTONE)
Block(-3,17,5,SANDSTONE)
Block(-3,17,6,SANDSTONE)
Block(-3,17,7,SANDSTONE)
Block(-3,17,8,SANDSTONE)
Block(-3,18,3,SANDSTONE)
Block(-3,18,4,SANDSTONE)
Block(-3,18,5,SANDSTONE)
Block(-3,18,6,SANDSTONE)
Block(-3,18,7,SANDSTONE)
Block(-3,18,8,SANDSTONE)
Block(-3,19,2,SANDSTONE)
Block(-3,19,3,SANDSTONE)
Block(-3,19,4,SANDSTONE)
Block(-3,19,5,SANDSTONE)
Block(-3,19,6,SANDSTONE)
Block(-3,19,7,SANDSTONE)
Block(-3,19,8,OBSIDIAN)
Block(-3,20,1,SANDSTONE)
Block(-3,20,2,SANDSTONE)
Block(-3,20,3,SANDSTONE)
Block(-3,20,4,SANDSTONE)
Block(-3,20,5,SANDSTONE)
Block(-3,20,6,OBSIDIAN)
Block(-3,20,7,OBSIDIAN)
Block(-3,20,8,OBSIDIAN)
Block(-3,21,0,SANDSTONE)
Block(-3,21,1,SANDSTONE)
Block(-3,21,2,SANDSTONE)
Block(-3,21,3,SANDSTONE)
Block(-3,21,4,SANDSTONE)
Block(-3,21,5,SANDSTONE)
Block(-3,21,6,OBSIDIAN)
Block(-3,21,7,OBSIDIAN)
Block(-3,22,-1,SANDSTONE)
Block(-3,22,0,SANDSTONE)
Block(-3,22,1,SANDSTONE)
Block(-3,22,2,SANDSTONE)
Block(-3,22,3,SANDSTONE)
Block(-3,22,4,SANDSTONE)
Block(-3,22,5,SANDSTONE)
Block(-3,22,6,OBSIDIAN)
Block(-3,23,-2,SANDSTONE)
Block(-3,23,-1,SANDSTONE)
Block(-3,23,0,SANDSTONE)
Block(-3,23,1,SANDSTONE)
Block(-3,23,2,SANDSTONE)
Block(-3,23,3,SANDSTONE)
Block(-3,23,4,SANDSTONE)
Block(-3,24,-3,SANDSTONE)
Block(-3,24,-2,SANDSTONE)
Block(-3,24,-1,SANDSTONE)
Block(-3,24,0,SANDSTONE)
Block(-3,24,1,SANDSTONE)
Block(-3,24,2,SANDSTONE)
Block(-3,24,3,SANDSTONE)
Block(-3,25,-4,SANDSTONE)
Block(-3,25,-3,SANDSTONE)
Block(-3,25,-2,SANDSTONE)
Block(-3,25,-1,SANDSTONE)
Block(-3,25,0,SANDSTONE)
Block(-3,25,1,SANDSTONE)
Block(-3,25,2,SANDSTONE)
Block(-3,26,-5,SANDSTONE)
Block(-3,26,-4,SANDSTONE)
Block(-3,26,-3,SANDSTONE)
Block(-3,26,-2,SANDSTONE)
Block(-3,26,-1,SANDSTONE)
Block(-3,26,0,SANDSTONE)
Block(-3,27,-6,SANDSTONE)
Block(-3,27,-5,SANDSTONE)
Block(-3,27,-4,SANDSTONE)
Block(-3,27,-3,SANDSTONE)
Block(-3,27,-2,SANDSTONE)
Block(-3,27,-1,SANDSTONE)
Block(-3,28,-7,SANDSTONE)
Block(-3,28,-6,SANDSTONE)
Block(-3,28,-5,SANDSTONE)
Block(-3,28,-4,SANDSTONE)
Block(-3,28,-3,SANDSTONE)
Block(-3,28,-2,SANDSTONE)
Block(-3,29,-7,SANDSTONE)
Block(-3,29,-6,SANDSTONE)
Block(-3,29,-5,SANDSTONE)
Block(-3,29,-4,SANDSTONE)
Block(-3,29,-3,SANDSTONE)
Block(-3,30,-7,SANDSTONE)
Block(-3,30,-6,SANDSTONE)
Block(-3,30,-5,SANDSTONE)
Block(-3,31,-7,SANDSTONE)
Block(-3,31,-6,SANDSTONE)
Block(-3,32,-7,SANDSTONE)
Block(-2,12,8,SANDSTONE)
Block(-2,13,7,SANDSTONE)
Block(-2,13,8,SANDSTONE)
Block(-2,14,6,SANDSTONE)
Block(-2,14,7,SANDSTONE)
Block(-2,14,8,SANDSTONE)
Block(-2,15,5,SANDSTONE)
Block(-2,15,6,SANDSTONE)
Block(-2,15,7,SANDSTONE)
Block(-2,15,8,SANDSTONE)
Block(-2,16,5,SANDSTONE)
Block(-2,16,6,SANDSTONE)
Block(-2,16,7,SANDSTONE)
Block(-2,16,8,SANDSTONE)
Block(-2,17,4,SANDSTONE)
Block(-2,17,5,SANDSTONE)
Block(-2,17,6,SANDSTONE)
Block(-2,17,7,SANDSTONE)
Block(-2,17,8,SANDSTONE)
Block(-2,18,3,SANDSTONE)
Block(-2,18,4,SANDSTONE)
Block(-2,18,5,SANDSTONE)
Block(-2,18,6,SANDSTONE)
Block(-2,18,7,SANDSTONE)
Block(-2,18,8,SANDSTONE)
Block(-2,19,2,SANDSTONE)
Block(-2,19,3,SANDSTONE)
Block(-2,19,4,SANDSTONE)
Block(-2,19,5,SANDSTONE)
Block(-2,19,6,SANDSTONE)
Block(-2,19,7,SANDSTONE)
Block(-2,19,8,SANDSTONE)
Block(-2,20,1,SANDSTONE)
Block(-2,20,2,SANDSTONE)
Block(-2,20,3,SANDSTONE)
Block(-2,20,4,SANDSTONE)
Block(-2,20,5,SANDSTONE)
Block(-2,20,6,SANDSTONE)
Block(-2,20,7,SANDSTONE)
Block(-2,20,8,SANDSTONE)
Block(-2,21,0,SANDSTONE)
Block(-2,21,1,SANDSTONE)
Block(-2,21,2,SANDSTONE)
Block(-2,21,3,SANDSTONE)
Block(-2,21,4,SANDSTONE)
Block(-2,21,5,SANDSTONE)
Block(-2,21,6,SANDSTONE)
Block(-2,22,-1,SANDSTONE)
Block(-2,22,0,SANDSTONE)
Block(-2,22,1,SANDSTONE)
Block(-2,22,2,SANDSTONE)
Block(-2,22,3,SANDSTONE)
Block(-2,22,4,SANDSTONE)
Block(-2,22,5,SANDSTONE)
Block(-2,23,-2,SANDSTONE)
Block(-2,23,-1,SANDSTONE)
Block(-2,23,0,SANDSTONE)
Block(-2,23,1,SANDSTONE)
Block(-2,23,2,SANDSTONE)
Block(-2,23,3,SANDSTONE)
Block(-2,23,4,SANDSTONE)
Block(-2,24,-3,SANDSTONE)
Block(-2,24,-2,SANDSTONE)
Block(-2,24,-1,SANDSTONE)
Block(-2,24,0,SANDSTONE)
Block(-2,24,1,SANDSTONE)
Block(-2,24,2,SANDSTONE)
Block(-2,25,-4,SANDSTONE)
Block(-2,25,-3,SANDSTONE)
Block(-2,25,-2,SANDSTONE)
Block(-2,25,-1,SANDSTONE)
Block(-2,25,0,SANDSTONE)
Block(-2,25,1,SANDSTONE)
Block(-2,26,-5,SANDSTONE)
Block(-2,26,-4,SANDSTONE)
Block(-2,26,-3,SANDSTONE)
Block(-2,26,-2,SANDSTONE)
Block(-2,26,-1,SANDSTONE)
Block(-2,26,0,SANDSTONE)
Block(-2,27,-5,SANDSTONE)
Block(-2,27,-4,SANDSTONE)
Block(-2,27,-3,SANDSTONE)
Block(-2,27,-2,SANDSTONE)
Block(-2,27,-1,SANDSTONE)
Block(-2,28,-6,SANDSTONE)
Block(-2,28,-5,SANDSTONE)
Block(-2,28,-4,SANDSTONE)
Block(-2,28,-3,SANDSTONE)
Block(-2,29,-7,SANDSTONE)
Block(-2,29,-6,SANDSTONE)
Block(-2,29,-5,SANDSTONE)
Block(-2,29,-4,SANDSTONE)
Block(-2,30,-7,SANDSTONE)
Block(-2,30,-6,SANDSTONE)
Block(-2,30,-5,SANDSTONE)
Block(-2,31,-7,SANDSTONE)
Block(-1,13,8,SANDSTONE)
Block(-1,14,7,SANDSTONE)
Block(-1,14,8,SANDSTONE)
Block(-1,15,6,SANDSTONE)
Block(-1,15,7,SANDSTONE)
Block(-1,15,8,SANDSTONE)
Block(-1,16,5,SANDSTONE)
Block(-1,16,6,SANDSTONE)
Block(-1,16,7,SANDSTONE)
Block(-1,16,8,SANDSTONE)
Block(-1,17,4,SANDSTONE)
Block(-1,17,5,SANDSTONE)
Block(-1,17,6,SANDSTONE)
Block(-1,17,7,SANDSTONE)
Block(-1,17,8,SANDSTONE)
Block(-1,18,3,SANDSTONE)
Block(-1,18,4,SANDSTONE)
Block(-1,18,5,SANDSTONE)
Block(-1,18,6,SANDSTONE)
Block(-1,18,7,SANDSTONE)
Block(-1,18,8,SANDSTONE)
Block(-1,19,2,SANDSTONE)
Block(-1,19,3,SANDSTONE)
Block(-1,19,4,SANDSTONE)
Block(-1,19,5,SANDSTONE)
Block(-1,19,6,SANDSTONE)
Block(-1,19,7,SANDSTONE)
Block(-1,19,8,SANDSTONE)
Block(-1,20,1,SANDSTONE)
Block(-1,20,2,SANDSTONE)
Block(-1,20,3,SANDSTONE)
Block(-1,20,4,SANDSTONE)
Block(-1,20,5,SANDSTONE)
Block(-1,20,6,SANDSTONE)
Block(-1,20,7,SANDSTONE)
Block(-1,21,0,SANDSTONE)
Block(-1,21,1,SANDSTONE)
Block(-1,21,2,SANDSTONE)
Block(-1,21,3,SANDSTONE)
Block(-1,21,4,SANDSTONE)
Block(-1,21,5,SANDSTONE)
Block(-1,21,6,SANDSTONE)
Block(-1,22,-1,SANDSTONE)
Block(-1,22,0,SANDSTONE)
Block(-1,22,1,SANDSTONE)
Block(-1,22,2,SANDSTONE)
Block(-1,22,3,SANDSTONE)
Block(-1,22,4,SANDSTONE)
Block(-1,22,5,SANDSTONE)
Block(-1,23,-2,SANDSTONE)
Block(-1,23,-1,SANDSTONE)
Block(-1,23,0,SANDSTONE)
Block(-1,23,1,SANDSTONE)
Block(-1,23,2,SANDSTONE)
Block(-1,23,3,SANDSTONE)
Block(-1,24,-2,SANDSTONE)
Block(-1,24,-1,SANDSTONE)
Block(-1,24,0,SANDSTONE)
Block(-1,24,1,SANDSTONE)
Block(-1,24,2,SANDSTONE)
Block(-1,25,-3,SANDSTONE)
Block(-1,25,-2,SANDSTONE)
Block(-1,25,-1,SANDSTONE)
Block(-1,25,0,SANDSTONE)
Block(-1,25,1,SANDSTONE)
Block(-1,26,-4,SANDSTONE)
Block(-1,26,-3,SANDSTONE)
Block(-1,26,-2,SANDSTONE)
Block(-1,26,-1,SANDSTONE)
Block(-1,27,-5,SANDSTONE)
Block(-1,27,-4,SANDSTONE)
Block(-1,27,-3,SANDSTONE)
Block(-1,27,-2,SANDSTONE)
Block(-1,28,-6,SANDSTONE)
Block(-1,28,-5,SANDSTONE)
Block(-1,28,-4,SANDSTONE)
Block(-1,28,-3,SANDSTONE)
Block(-1,29,-7,SANDSTONE)
Block(-1,29,-6,SANDSTONE)
Block(-1,29,-5,SANDSTONE)
Block(-1,30,-7,SANDSTONE)
Block(-1,30,-6,SANDSTONE)
Block(0,13,8,SANDSTONE)
Block(0,14,7,SANDSTONE)
Block(0,14,8,SANDSTONE)
Block(0,15,6,SANDSTONE)
Block(0,15,7,SANDSTONE)
Block(0,15,8,SANDSTONE)
Block(0,16,5,SANDSTONE)
Block(0,16,6,SANDSTONE)
Block(0,16,7,SANDSTONE)
Block(0,16,8,SANDSTONE)
Block(0,17,4,SANDSTONE)
Block(0,17,5,SANDSTONE)
Block(0,17,6,SANDSTONE)
Block(0,17,7,SANDSTONE)
Block(0,17,8,SANDSTONE)
Block(0,18,3,SANDSTONE)
Block(0,18,4,SANDSTONE)
Block(0,18,5,SANDSTONE)
Block(0,18,6,SANDSTONE)
Block(0,18,7,SANDSTONE)
Block(0,18,8,SANDSTONE)
Block(0,19,2,SANDSTONE)
Block(0,19,3,SANDSTONE)
Block(0,19,4,SANDSTONE)
Block(0,19,5,SANDSTONE)
Block(0,19,6,SANDSTONE)
Block(0,19,7,SANDSTONE)
Block(0,19,8,SANDSTONE)
Block(0,20,1,SANDSTONE)
Block(0,20,2,SANDSTONE)
Block(0,20,3,SANDSTONE)
Block(0,20,4,SANDSTONE)
Block(0,20,5,SANDSTONE)
Block(0,20,6,SANDSTONE)
Block(0,20,7,SANDSTONE)
Block(0,21,1,SANDSTONE)
Block(0,21,2,SANDSTONE)
Block(0,21,3,SANDSTONE)
Block(0,21,4,SANDSTONE)
Block(0,21,5,SANDSTONE)
Block(0,22,0,SANDSTONE)
Block(0,22,1,SANDSTONE)
Block(0,22,2,SANDSTONE)
Block(0,22,3,SANDSTONE)
Block(0,22,4,SANDSTONE)
Block(0,23,-1,SANDSTONE)
Block(0,23,0,SANDSTONE)
Block(0,23,1,SANDSTONE)
Block(0,23,2,SANDSTONE)
Block(0,23,3,SANDSTONE)
Block(0,24,-2,SANDSTONE)
Block(0,24,-1,SANDSTONE)
Block(0,24,0,SANDSTONE)
Block(0,24,1,SANDSTONE)
Block(0,25,-3,SANDSTONE)
Block(0,25,-2,SANDSTONE)
Block(0,25,-1,SANDSTONE)
Block(0,25,0,SANDSTONE)
Block(0,26,-4,SANDSTONE)
Block(0,26,-3,SANDSTONE)
Block(1,13,8,SANDSTONE)
Block(1,14,7,SANDSTONE)
Block(1,14,8,SANDSTONE)
Block(1,15,6,SANDSTONE)
Block(1,15,7,SANDSTONE)
Block(1,15,8,SANDSTONE)
Block(1,16,5,SANDSTONE)
Block(1,16,6,SANDSTONE)
Block(1,16,7,SANDSTONE)
Block(1,16,8,SANDSTONE)
Block(1,17,5,SANDSTONE)
Block(1,17,6,SANDSTONE)
Block(1,17,7,SANDSTONE)
Block(1,17,8,SANDSTONE)
Block(1,18,4,SANDSTONE)
Block(1,18,5,SANDSTONE)
Block(1,18,6,SANDSTONE)
Block(1,18,7,SANDSTONE)
Block(1,18,8,SANDSTONE)
Block(1,19,3,SANDSTONE)
Block(1,19,4,SANDSTONE)
Block(1,19,5,SANDSTONE)
Block(1,19,6,SANDSTONE)
Block(1,19,7,SANDSTONE)
Block(1,20,2,SANDSTONE)
Block(1,20,3,SANDSTONE)
Block(1,20,4,SANDSTONE)
Block(1,20,5,SANDSTONE)
Block(1,20,6,SANDSTONE)
Block(1,21,1,SANDSTONE)
Block(1,21,2,SANDSTONE)
Block(1,21,3,SANDSTONE)
Block(1,22,0,SANDSTONE)
Block(2,13,8,SANDSTONE)
Block(2,14,8,SANDSTONE)
Block(2,15,7,SANDSTONE)
Block(2,15,8,SANDSTONE)
Block(2,16,6,SANDSTONE)
Block(2,16,7,SANDSTONE)
Block(2,16,8,SANDSTONE)
Block(2,17,5,SANDSTONE)
Block(2,17,6,SANDSTONE)

#######################################################################
# +-----------------------------------------------------------------+ #
# |                             Branches                            | #
# +-----------------------------------------------------------------+ #
#######################################################################

Branch(0,0,16,true,DesertSpike_Huge_06C0R2,NORTH,100.0,0)

#######################################################################
# +-----------------------------------------------------------------+ #
# |                             Entities                            | #
# +-----------------------------------------------------------------+ #
#######################################################################


#######################################################################
# +-----------------------------------------------------------------+ #
# |                            Particles                            | #
# +-----------------------------------------------------------------+ #
#######################################################################


#######################################################################
# +-----------------------------------------------------------------+ #
# |                             Spawners                            | #
# +-----------------------------------------------------------------+ #
#######################################################################


#######################################################################
# +-----------------------------------------------------------------+ #
# |                             ModData                             | #
# +-----------------------------------------------------------------+ #
#######################################################################

