
#######################################################################
# +-----------------------------------------------------------------+ #
# |                            BO4 object                           | #
# +-----------------------------------------------------------------+ #
#######################################################################

Author: NLBlackEagle

Description: No description given

SettingsMode: WriteDisable


#######################################################################
# +-----------------------------------------------------------------+ #
# |                          Main settings                          | #
# +-----------------------------------------------------------------+ #
#######################################################################

Frequency: 0

SpawnHeight: highestBlock

UseCenterForHighestBlock: true

##############################
# Height Limits for the BO4. #
##############################

MinHeight: 0

MaxHeight: 255

InheritBO3: 

InheritBO3Rotation: NORTH

OverrideChildSettings: true

OverrideParentHeight: false

CanOverride: true

BranchFrequency: 0

BranchFrequencyGroup: 

MustBeBelowOther: false

MustBeInside: 

CannotBeInside: 

ReplacesBO3: 

MustBeInsideWorldBorders: false

CanSpawnOnWater: true

SpawnOnWaterOnly: false

SpawnUnderWater: false

SpawnAtWaterLevel: false

HeightOffset: 0

RemoveAir: true

ReplaceAbove: 

ReplaceBelow: 

ReplaceWithBiomeBlocks: true

ReplaceWithSurfaceBlock: GRASS

ReplaceWithGroundBlock: DIRT

ReplaceWithStoneBlock: STONE

SmoothRadius: 0

SmoothHeightOffset: 0

SmoothStartTop: false

SmoothStartWood: false

SmoothingSurfaceBlock: 

SmoothingGroundBlock: 

BO3Group: 

IsSpawnPoint: false

DoReplaceBlocks: true


#######################################################################
# +-----------------------------------------------------------------+ #
# |                              Blocks                             | #
# +-----------------------------------------------------------------+ #
#######################################################################

Block(0,54,8,OBSIDIAN:0)
Block(1,51,8,OBSIDIAN:0)
Block(1,52,8,OBSIDIAN:0)
Block(1,53,7,OBSIDIAN:0)
Block(1,53,8,OBSIDIAN:0)
Block(1,54,7,STAINED_CLAY:3)
Block(1,54,8,OBSIDIAN:0)
Block(1,55,6,STAINED_CLAY:3)
Block(1,55,7,STAINED_CLAY:3)
Block(1,55,8,OBSIDIAN:0)
Block(1,56,6,STAINED_CLAY:3)
Block(1,56,7,STAINED_CLAY:3)
Block(1,56,8,STAINED_CLAY:3)
Block(1,57,5,STAINED_CLAY:3)
Block(1,57,6,STAINED_CLAY:3)
Block(1,57,7,STAINED_CLAY:3)
Block(1,58,5,STAINED_CLAY:3)
Block(1,58,6,STAINED_CLAY:3)
Block(1,59,5,STAINED_CLAY:3)
Block(1,59,6,STAINED_CLAY:3)
Block(1,60,4,STAINED_CLAY:3)
Block(1,60,5,STAINED_CLAY:3)
Block(1,61,4,STAINED_CLAY:3)
Block(1,62,3,STAINED_CLAY:3)
Block(1,64,2,STAINED_CLAY:3)
Block(2,48,8,STAINED_CLAY:3)
Block(2,49,8,OBSIDIAN:0)
Block(2,50,7,OBSIDIAN:0)
Block(2,50,8,OBSIDIAN:0)
Block(2,51,7,OBSIDIAN:0)
Block(2,51,8,OBSIDIAN:0)
Block(2,52,6,STAINED_CLAY:3)
Block(2,52,7,OBSIDIAN:0)
Block(2,52,8,OBSIDIAN:0)
Block(2,53,6,STAINED_CLAY:3)
Block(2,53,7,OBSIDIAN:0)
Block(2,53,8,OBSIDIAN:0)
Block(2,54,5,STAINED_CLAY:3)
Block(2,54,6,STAINED_CLAY:3)
Block(2,54,7,OBSIDIAN:0)
Block(2,54,8,OBSIDIAN:0)
Block(2,55,5,STAINED_CLAY:3)
Block(2,55,6,STAINED_CLAY:3)
Block(2,55,7,STAINED_CLAY:3)
Block(2,55,8,OBSIDIAN:0)
Block(2,56,5,STAINED_CLAY:3)
Block(2,56,6,STAINED_CLAY:3)
Block(2,56,7,STAINED_CLAY:3)
Block(2,56,8,STAINED_CLAY:3)
Block(2,57,4,STAINED_CLAY:3)
Block(2,57,5,STAINED_CLAY:3)
Block(2,57,6,STAINED_CLAY:3)
Block(2,57,7,STAINED_CLAY:3)
Block(2,57,8,STAINED_CLAY:3)
Block(2,58,4,STAINED_CLAY:3)
Block(2,58,5,STAINED_CLAY:3)
Block(2,58,6,STAINED_CLAY:3)
Block(2,58,7,STAINED_CLAY:3)
Block(2,58,8,STAINED_CLAY:3)
Block(2,59,3,STAINED_CLAY:3)
Block(2,59,4,STAINED_CLAY:3)
Block(2,59,5,STAINED_CLAY:3)
Block(2,59,6,STAINED_CLAY:3)
Block(2,59,7,STAINED_CLAY:3)
Block(2,60,3,STAINED_CLAY:3)
Block(2,60,4,STAINED_CLAY:3)
Block(2,60,5,STAINED_CLAY:3)
Block(2,60,6,STAINED_CLAY:3)
Block(2,61,2,STAINED_CLAY:3)
Block(2,61,3,STAINED_CLAY:3)
Block(2,61,4,STAINED_CLAY:3)
Block(2,61,5,STAINED_CLAY:3)
Block(2,62,2,STAINED_CLAY:3)
Block(2,62,3,STAINED_CLAY:3)
Block(2,62,4,STAINED_CLAY:3)
Block(2,62,5,STAINED_CLAY:3)
Block(2,63,1,STAINED_CLAY:3)
Block(2,63,2,STAINED_CLAY:3)
Block(2,63,3,STAINED_CLAY:3)
Block(2,63,4,STAINED_CLAY:3)
Block(2,64,1,STAINED_CLAY:3)
Block(2,64,2,STAINED_CLAY:3)
Block(2,64,3,STAINED_CLAY:3)
Block(2,65,0,STAINED_CLAY:3)
Block(2,65,1,STAINED_CLAY:3)
Block(2,65,2,STAINED_CLAY:3)
Block(2,66,0,STAINED_CLAY:3)
Block(2,66,1,STAINED_CLAY:3)
Block(2,67,-1,STAINED_CLAY:3)
Block(2,67,0,STAINED_CLAY:3)
Block(2,67,1,STAINED_CLAY:3)
Block(2,68,-1,STAINED_CLAY:3)
Block(2,68,0,STAINED_CLAY:3)
Block(2,69,-2,STAINED_CLAY:3)
Block(2,69,-1,STAINED_CLAY:3)
Block(2,70,-2,STAINED_CLAY:3)
Block(2,71,-3,STAINED_CLAY:3)
Block(2,71,-2,STAINED_CLAY:3)
Block(2,72,-3,STAINED_CLAY:3)
Block(2,73,-4,STAINED_CLAY:3)
Block(3,45,8,STAINED_CLAY:3)
Block(3,46,8,STAINED_CLAY:3)
Block(3,47,7,STAINED_CLAY:3)
Block(3,47,8,STAINED_CLAY:3)
Block(3,48,7,STAINED_CLAY:3)
Block(3,48,8,STAINED_CLAY:3)
Block(3,49,6,STAINED_CLAY:3)
Block(3,49,7,STAINED_CLAY:3)
Block(3,49,8,OBSIDIAN:0)
Block(3,50,6,STAINED_CLAY:3)
Block(3,50,7,OBSIDIAN:0)
Block(3,50,8,OBSIDIAN:0)
Block(3,51,5,STAINED_CLAY:3)
Block(3,51,6,STAINED_CLAY:3)
Block(3,51,7,OBSIDIAN:0)
Block(3,51,8,OBSIDIAN:0)
Block(3,52,5,STAINED_CLAY:3)
Block(3,52,6,STAINED_CLAY:3)
Block(3,52,7,OBSIDIAN:0)
Block(3,52,8,OBSIDIAN:0)
Block(3,53,5,STAINED_CLAY:3)
Block(3,53,6,STAINED_CLAY:3)
Block(3,53,7,OBSIDIAN:0)
Block(3,53,8,OBSIDIAN:0)
Block(3,54,4,STAINED_CLAY:3)
Block(3,54,5,STAINED_CLAY:3)
Block(3,54,6,STAINED_CLAY:3)
Block(3,54,7,OBSIDIAN:0)
Block(3,54,8,OBSIDIAN:0)
Block(3,55,4,STAINED_CLAY:3)
Block(3,55,5,STAINED_CLAY:3)
Block(3,55,6,STAINED_CLAY:3)
Block(3,55,7,STAINED_CLAY:3)
Block(3,55,8,OBSIDIAN:0)
Block(3,56,3,STAINED_CLAY:3)
Block(3,56,4,STAINED_CLAY:3)
Block(3,56,5,STAINED_CLAY:3)
Block(3,56,6,STAINED_CLAY:3)
Block(3,56,7,STAINED_CLAY:3)
Block(3,56,8,STAINED_CLAY:3)
Block(3,57,3,STAINED_CLAY:3)
Block(3,57,4,STAINED_CLAY:3)
Block(3,57,5,STAINED_CLAY:3)
Block(3,57,6,STAINED_CLAY:3)
Block(3,57,7,STAINED_CLAY:3)
Block(3,57,8,STAINED_CLAY:3)
Block(3,58,2,STAINED_CLAY:3)
Block(3,58,3,STAINED_CLAY:3)
Block(3,58,4,STAINED_CLAY:3)
Block(3,58,5,STAINED_CLAY:3)
Block(3,58,6,STAINED_CLAY:3)
Block(3,58,7,STAINED_CLAY:3)
Block(3,59,2,STAINED_CLAY:3)
Block(3,59,3,STAINED_CLAY:3)
Block(3,59,4,STAINED_CLAY:3)
Block(3,59,5,STAINED_CLAY:3)
Block(3,59,6,STAINED_CLAY:3)
Block(3,59,7,STAINED_CLAY:3)
Block(3,60,2,STAINED_CLAY:3)
Block(3,60,3,STAINED_CLAY:3)
Block(3,60,4,STAINED_CLAY:3)
Block(3,60,5,STAINED_CLAY:3)
Block(3,60,6,STAINED_CLAY:3)
Block(3,61,1,STAINED_CLAY:3)
Block(3,61,2,STAINED_CLAY:3)
Block(3,61,3,STAINED_CLAY:3)
Block(3,61,4,STAINED_CLAY:3)
Block(3,61,5,STAINED_CLAY:3)
Block(3,62,1,STAINED_CLAY:3)
Block(3,62,2,STAINED_CLAY:3)
Block(3,62,3,STAINED_CLAY:3)
Block(3,62,4,STAINED_CLAY:3)
Block(3,63,0,STAINED_CLAY:3)
Block(3,63,1,STAINED_CLAY:3)
Block(3,63,2,STAINED_CLAY:3)
Block(3,63,3,STAINED_CLAY:3)
Block(3,63,4,STAINED_CLAY:3)
Block(3,64,0,STAINED_CLAY:3)
Block(3,64,1,STAINED_CLAY:3)
Block(3,64,2,STAINED_CLAY:3)
Block(3,64,3,STAINED_CLAY:3)
Block(3,65,0,STAINED_CLAY:3)
Block(3,65,1,STAINED_CLAY:3)
Block(3,65,2,STAINED_CLAY:3)
Block(3,66,-1,STAINED_CLAY:3)
Block(3,66,0,STAINED_CLAY:3)
Block(3,66,1,STAINED_CLAY:3)
Block(3,67,-1,STAINED_CLAY:3)
Block(3,67,0,STAINED_CLAY:3)
Block(3,67,1,STAINED_CLAY:3)
Block(3,68,-1,STAINED_CLAY:3)
Block(3,68,0,STAINED_CLAY:3)
Block(3,69,-2,STAINED_CLAY:3)
Block(3,69,-1,STAINED_CLAY:3)
Block(3,70,-2,STAINED_CLAY:3)
Block(4,43,8,STAINED_CLAY:3)
Block(4,44,8,STAINED_CLAY:3)
Block(4,45,8,STAINED_CLAY:3)
Block(4,46,7,STAINED_CLAY:3)
Block(4,46,8,STAINED_CLAY:3)
Block(4,47,7,STAINED_CLAY:3)
Block(4,47,8,STAINED_CLAY:3)
Block(4,48,6,STAINED_CLAY:3)
Block(4,48,7,STAINED_CLAY:3)
Block(4,48,8,STAINED_CLAY:3)
Block(4,49,6,STAINED_CLAY:3)
Block(4,49,7,STAINED_CLAY:3)
Block(4,49,8,OBSIDIAN:0)
Block(4,50,6,STAINED_CLAY:3)
Block(4,50,7,OBSIDIAN:0)
Block(4,50,8,OBSIDIAN:0)
Block(4,51,5,STAINED_CLAY:3)
Block(4,51,6,STAINED_CLAY:3)
Block(4,51,7,OBSIDIAN:0)
Block(4,51,8,OBSIDIAN:0)
Block(4,52,5,STAINED_CLAY:3)
Block(4,52,6,STAINED_CLAY:3)
Block(4,52,7,OBSIDIAN:0)
Block(4,52,8,OBSIDIAN:0)
Block(4,53,5,STAINED_CLAY:3)
Block(4,53,6,STAINED_CLAY:3)
Block(4,53,7,OBSIDIAN:0)
Block(4,53,8,OBSIDIAN:0)
Block(4,54,4,STAINED_CLAY:3)
Block(4,54,5,STAINED_CLAY:3)
Block(4,54,6,STAINED_CLAY:3)
Block(4,54,7,OBSIDIAN:0)
Block(4,54,8,OBSIDIAN:0)
Block(4,55,4,STAINED_CLAY:3)
Block(4,55,5,STAINED_CLAY:3)
Block(4,55,6,STAINED_CLAY:3)
Block(4,55,7,STAINED_CLAY:3)
Block(4,55,8,OBSIDIAN:0)
Block(4,56,3,STAINED_CLAY:3)
Block(4,56,4,STAINED_CLAY:3)
Block(4,56,5,STAINED_CLAY:3)
Block(4,56,6,STAINED_CLAY:3)
Block(4,56,7,STAINED_CLAY:3)
Block(4,56,8,STAINED_CLAY:3)
Block(4,57,3,STAINED_CLAY:3)
Block(4,57,4,STAINED_CLAY:3)
Block(4,57,5,STAINED_CLAY:3)
Block(4,57,6,STAINED_CLAY:3)
Block(4,57,7,STAINED_CLAY:3)
Block(4,57,8,STAINED_CLAY:3)
Block(4,58,3,STAINED_CLAY:3)
Block(4,58,4,STAINED_CLAY:3)
Block(4,58,5,STAINED_CLAY:3)
Block(4,58,6,STAINED_CLAY:3)
Block(4,58,7,STAINED_CLAY:3)
Block(4,59,2,STAINED_CLAY:3)
Block(4,59,3,STAINED_CLAY:3)
Block(4,59,4,STAINED_CLAY:3)
Block(4,59,5,STAINED_CLAY:3)
Block(4,59,6,STAINED_CLAY:3)
Block(4,59,7,STAINED_CLAY:3)
Block(4,60,2,STAINED_CLAY:3)
Block(4,60,3,STAINED_CLAY:3)
Block(4,60,4,STAINED_CLAY:3)
Block(4,60,5,STAINED_CLAY:3)
Block(4,60,6,STAINED_CLAY:3)
Block(4,61,2,STAINED_CLAY:3)
Block(4,61,3,STAINED_CLAY:3)
Block(4,61,4,STAINED_CLAY:3)
Block(4,61,5,STAINED_CLAY:3)
Block(4,62,1,STAINED_CLAY:3)
Block(4,62,2,STAINED_CLAY:3)
Block(4,62,3,STAINED_CLAY:3)
Block(4,62,4,STAINED_CLAY:3)
Block(4,63,1,STAINED_CLAY:3)
Block(4,63,2,STAINED_CLAY:3)
Block(4,63,3,STAINED_CLAY:3)
Block(4,64,1,STAINED_CLAY:3)
Block(4,64,2,STAINED_CLAY:3)
Block(4,65,0,STAINED_CLAY:3)
Block(4,65,1,STAINED_CLAY:3)
Block(4,65,2,STAINED_CLAY:3)
Block(4,66,0,STAINED_CLAY:3)
Block(4,66,1,STAINED_CLAY:3)
Block(4,67,0,STAINED_CLAY:3)
Block(4,68,-1,STAINED_CLAY:3)
Block(5,44,8,STAINED_CLAY:3)
Block(5,45,8,STAINED_CLAY:3)
Block(5,46,8,STAINED_CLAY:3)
Block(5,47,7,STAINED_CLAY:3)
Block(5,47,8,STAINED_CLAY:3)
Block(5,48,7,STAINED_CLAY:3)
Block(5,48,8,STAINED_CLAY:3)
Block(5,49,6,STAINED_CLAY:3)
Block(5,49,7,STAINED_CLAY:3)
Block(5,49,8,OBSIDIAN:0)
Block(5,50,6,STAINED_CLAY:3)
Block(5,50,7,STAINED_CLAY:3)
Block(5,50,8,OBSIDIAN:0)
Block(5,51,6,STAINED_CLAY:3)
Block(5,51,7,OBSIDIAN:0)
Block(5,51,8,OBSIDIAN:0)
Block(5,52,5,STAINED_CLAY:3)
Block(5,52,6,STAINED_CLAY:3)
Block(5,52,7,OBSIDIAN:0)
Block(5,52,8,OBSIDIAN:0)
Block(5,53,5,STAINED_CLAY:3)
Block(5,53,6,STAINED_CLAY:3)
Block(5,53,7,OBSIDIAN:0)
Block(5,53,8,OBSIDIAN:0)
Block(5,54,5,STAINED_CLAY:3)
Block(5,54,6,STAINED_CLAY:3)
Block(5,54,7,STAINED_CLAY:3)
Block(5,54,8,OBSIDIAN:0)
Block(5,55,4,STAINED_CLAY:3)
Block(5,55,5,STAINED_CLAY:3)
Block(5,55,6,STAINED_CLAY:3)
Block(5,55,7,STAINED_CLAY:3)
Block(5,55,8,OBSIDIAN:0)
Block(5,56,4,STAINED_CLAY:3)
Block(5,56,5,STAINED_CLAY:3)
Block(5,56,6,STAINED_CLAY:3)
Block(5,56,7,STAINED_CLAY:3)
Block(5,56,8,STAINED_CLAY:3)
Block(5,57,4,STAINED_CLAY:3)
Block(5,57,5,STAINED_CLAY:3)
Block(5,57,6,STAINED_CLAY:3)
Block(5,57,7,STAINED_CLAY:3)
Block(5,57,8,STAINED_CLAY:3)
Block(5,58,3,STAINED_CLAY:3)
Block(5,58,4,STAINED_CLAY:3)
Block(5,58,5,STAINED_CLAY:3)
Block(5,58,6,STAINED_CLAY:3)
Block(5,58,7,STAINED_CLAY:3)
Block(5,59,3,STAINED_CLAY:3)
Block(5,59,4,STAINED_CLAY:3)
Block(5,59,5,STAINED_CLAY:3)
Block(5,59,6,STAINED_CLAY:3)
Block(5,60,3,STAINED_CLAY:3)
Block(5,60,4,STAINED_CLAY:3)
Block(5,60,5,STAINED_CLAY:3)
Block(5,61,3,STAINED_CLAY:3)
Block(5,61,4,STAINED_CLAY:3)
Block(5,62,2,STAINED_CLAY:3)
Block(5,62,3,STAINED_CLAY:3)
Block(5,63,2,STAINED_CLAY:3)
Block(5,64,2,STAINED_CLAY:3)
Block(5,65,1,STAINED_CLAY:3)
Block(6,45,8,STAINED_CLAY:3)
Block(6,46,8,STAINED_CLAY:3)
Block(6,47,8,STAINED_CLAY:3)
Block(6,48,7,STAINED_CLAY:3)
Block(6,48,8,STAINED_CLAY:3)
Block(6,49,7,STAINED_CLAY:3)
Block(6,49,8,STAINED_CLAY:3)
Block(6,50,7,STAINED_CLAY:3)
Block(6,50,8,OBSIDIAN:0)
Block(6,51,6,STAINED_CLAY:3)
Block(6,51,7,STAINED_CLAY:3)
Block(6,51,8,OBSIDIAN:0)
Block(6,52,6,STAINED_CLAY:3)
Block(6,52,7,STAINED_CLAY:3)
Block(6,52,8,OBSIDIAN:0)
Block(6,53,6,STAINED_CLAY:3)
Block(6,53,7,STAINED_CLAY:3)
Block(6,53,8,OBSIDIAN:0)
Block(6,54,6,STAINED_CLAY:3)
Block(6,54,7,STAINED_CLAY:3)
Block(6,54,8,OBSIDIAN:0)
Block(6,55,5,STAINED_CLAY:3)
Block(6,55,6,STAINED_CLAY:3)
Block(6,55,7,STAINED_CLAY:3)
Block(6,55,8,STAINED_CLAY:3)
Block(6,56,5,STAINED_CLAY:3)
Block(6,56,6,STAINED_CLAY:3)
Block(6,56,7,STAINED_CLAY:3)
Block(6,56,8,STAINED_CLAY:3)
Block(6,57,5,STAINED_CLAY:3)
Block(6,57,6,STAINED_CLAY:3)
Block(6,57,7,STAINED_CLAY:3)
Block(6,58,4,STAINED_CLAY:3)
Block(6,58,5,STAINED_CLAY:3)
Block(6,58,6,STAINED_CLAY:3)
Block(6,59,4,STAINED_CLAY:3)
Block(6,59,5,STAINED_CLAY:3)
Block(6,60,4,STAINED_CLAY:3)
Block(6,61,3,STAINED_CLAY:3)
Block(7,48,8,STAINED_CLAY:3)
Block(7,49,8,STAINED_CLAY:3)
Block(7,50,8,STAINED_CLAY:3)
Block(7,51,7,STAINED_CLAY:3)
Block(7,51,8,STAINED_CLAY:3)
Block(7,52,7,STAINED_CLAY:3)
Block(7,52,8,STAINED_CLAY:3)
Block(7,53,7,STAINED_CLAY:3)
Block(7,53,8,STAINED_CLAY:3)
Block(7,54,7,STAINED_CLAY:3)
Block(7,54,8,STAINED_CLAY:3)
Block(7,55,6,STAINED_CLAY:3)
Block(7,55,7,STAINED_CLAY:3)
Block(7,55,8,STAINED_CLAY:3)
Block(7,56,6,STAINED_CLAY:3)
Block(7,56,7,STAINED_CLAY:3)
Block(7,57,6,STAINED_CLAY:3)
Block(7,58,5,STAINED_CLAY:3)

#######################################################################
# +-----------------------------------------------------------------+ #
# |                             Branches                            | #
# +-----------------------------------------------------------------+ #
#######################################################################

Branch(16,0,0,true,OBSIDIANSpike_Huge_13C1R0,NORTH,100.0,0)

#######################################################################
# +-----------------------------------------------------------------+ #
# |                             Entities                            | #
# +-----------------------------------------------------------------+ #
#######################################################################


#######################################################################
# +-----------------------------------------------------------------+ #
# |                            Particles                            | #
# +-----------------------------------------------------------------+ #
#######################################################################


#######################################################################
# +-----------------------------------------------------------------+ #
# |                             Spawners                            | #
# +-----------------------------------------------------------------+ #
#######################################################################


#######################################################################
# +-----------------------------------------------------------------+ #
# |                             ModData                             | #
# +-----------------------------------------------------------------+ #
#######################################################################

