#######################################################################
# +-----------------------------------------------------------------+ #
# |                            BO3 object                           | #
# +-----------------------------------------------------------------+ #
#######################################################################

Author: Bo3 BulkEdit

Description: Converted Schematic - Modified by Bo3BulkEdit

Version: 3

SettingsMode: WriteDisable

#######################################################################
# +-----------------------------------------------------------------+ #
# |                          Main settings                          | #
# +-----------------------------------------------------------------+ #
#######################################################################



Frequency: 0


SpawnHeight: randomY





##############################
# Height Limits for the BO3. #
##############################

MinHeight: 0
MaxHeight: 256

#######################################################################
# +-----------------------------------------------------------------+ #
# |                      Source block settings                      | #
# +-----------------------------------------------------------------+ #
#######################################################################

CanOverride: true
MaxPercentageOutsideSourceBlock: 100
OutsideSourceBlock: placeAnyway

#######################################################################
# +-----------------------------------------------------------------+ #
# |                               OTG+                              | #
# +-----------------------------------------------------------------+ #
#######################################################################

#######################################################################
# +-----------------------------------------------------------------+ #
# |                              Blocks                             | #
# +-----------------------------------------------------------------+ #
#######################################################################

B(0,750,0,AIR)
B(15,750,15,AIR)
B(12,4,15,betternether:quartz_stained_glass:15)
B(12,5,14,betternether:quartz_stained_glass:15)
B(10,5,15,betternether:quartz_stained_glass:15)
B(11,5,15,betternether:quartz_stained_glass:15)
B(12,5,15,betternether:quartz_stained_glass:15)
B(10,6,14,betternether:quartz_stained_glass:15)
B(11,6,14,betternether:quartz_stained_glass:15)
B(12,6,14,betternether:quartz_stained_glass:15)
B(7,6,15,betternether:quartz_stained_glass:15)
B(8,6,15,betternether:quartz_stained_glass:15)
B(9,6,15,betternether:quartz_stained_glass:15)
B(10,6,15,betternether:quartz_stained_glass:15)
B(11,6,15,betternether:quartz_stained_glass:15)
B(12,6,15,betternether:quartz_stained_glass:15)
B(10,7,13,betternether:quartz_stained_glass:15)
B(11,7,13,betternether:quartz_stained_glass:15)
B(9,7,14,betternether:quartz_stained_glass:15)
B(10,7,14,betternether:quartz_stained_glass:15)
B(11,7,14,betternether:quartz_stained_glass:15)
B(12,7,14,betternether:quartz_stained_glass:15)
B(6,7,15,betternether:quartz_stained_glass:15)
B(7,7,15,betternether:quartz_stained_glass:15)
B(8,7,15,betternether:quartz_stained_glass:15)
B(9,7,15,betternether:quartz_stained_glass:15)
B(10,7,15,betternether:quartz_stained_glass:15)
B(11,7,15,betternether:quartz_stained_glass:15)
B(12,7,15,betternether:quartz_stained_glass:15)
B(9,8,13,betternether:quartz_stained_glass:15)
B(10,8,13,betternether:quartz_stained_glass:15)
B(11,8,13,betternether:quartz_stained_glass:15)
B(7,8,14,betternether:quartz_stained_glass:15)
B(8,8,14,betternether:quartz_stained_glass:15)
B(9,8,14,betternether:quartz_stained_glass:15)
B(10,8,14,betternether:quartz_stained_glass:15)
B(11,8,14,betternether:quartz_stained_glass:15)
B(12,8,14,betternether:quartz_stained_glass:15)
B(13,8,14,betternether:quartz_stained_glass:15)
B(5,8,15,betternether:quartz_stained_glass:15)
B(6,8,15,betternether:quartz_stained_glass:15)
B(7,8,15,betternether:quartz_stained_glass:15)
B(8,8,15,betternether:quartz_stained_glass:15)
B(9,8,15,betternether:quartz_stained_glass:15)
B(10,8,15,betternether:quartz_stained_glass:15)
B(11,8,15,betternether:quartz_stained_glass:15)
B(12,8,15,betternether:quartz_stained_glass:15)
B(13,8,15,betternether:quartz_stained_glass:15)
B(10,9,12,betternether:quartz_stained_glass:15)
B(11,9,12,betternether:quartz_stained_glass:15)
B(7,9,13,betternether:quartz_stained_glass:15)
B(8,9,13,betternether:quartz_stained_glass:15)
B(9,9,13,betternether:quartz_stained_glass:15)
B(10,9,13,betternether:quartz_stained_glass:15)
B(11,9,13,betternether:quartz_stained_glass:15)
B(6,9,14,betternether:quartz_stained_glass:15)
B(7,9,14,betternether:quartz_stained_glass:15)
B(8,9,14,betternether:quartz_stained_glass:15)
B(9,9,14,betternether:quartz_stained_glass:15)
B(10,9,14,betternether:quartz_stained_glass:15)
B(11,9,14,betternether:quartz_stained_glass:15)
B(12,9,14,betternether:quartz_stained_glass:15)
B(13,9,14,betternether:quartz_stained_glass:15)
B(5,9,15,betternether:quartz_stained_glass:15)
B(6,9,15,betternether:quartz_stained_glass:15)
B(7,9,15,betternether:quartz_stained_glass:15)
B(8,9,15,betternether:quartz_stained_glass:15)
B(9,9,15,betternether:quartz_stained_glass:15)
B(10,9,15,betternether:quartz_stained_glass:15)
B(11,9,15,betternether:quartz_stained_glass:15)
B(12,9,15,betternether:quartz_stained_glass:15)
B(13,9,15,betternether:quartz_stained_glass:15)
B(10,10,11,betternether:quartz_stained_glass:15)
B(7,10,12,betternether:quartz_stained_glass:15)
B(9,10,12,betternether:quartz_stained_glass:15)
B(10,10,12,betternether:quartz_stained_glass:15)
B(11,10,12,betternether:quartz_stained_glass:15)
B(6,10,13,betternether:quartz_stained_glass:15)
B(7,10,13,betternether:quartz_stained_glass:15)
B(8,10,13,betternether:quartz_stained_glass:15)
B(9,10,13,betternether:quartz_stained_glass:15)
B(10,10,13,betternether:quartz_stained_glass:15)
B(11,10,13,betternether:quartz_stained_glass:15)
B(12,10,13,betternether:quartz_stained_glass:15)
B(5,10,14,betternether:quartz_stained_glass:15)
B(6,10,14,betternether:quartz_stained_glass:15)
B(7,10,14,betternether:quartz_stained_glass:15)
B(8,10,14,betternether:quartz_stained_glass:15)
B(9,10,14,betternether:quartz_stained_glass:15)
B(10,10,14,betternether:quartz_stained_glass:15)
B(11,10,14,betternether:quartz_stained_glass:15)
B(12,10,14,betternether:quartz_stained_glass:15)
B(13,10,14,betternether:quartz_stained_glass:15)
B(5,10,15,betternether:quartz_stained_glass:15)
B(6,10,15,betternether:quartz_stained_glass:15)
B(7,10,15,betternether:quartz_stained_glass:15)
B(8,10,15,betternether:quartz_stained_glass:15)
B(9,10,15,betternether:quartz_stained_glass:15)
B(10,10,15,betternether:quartz_stained_glass:15)
B(11,10,15,betternether:quartz_stained_glass:15)
B(12,10,15,betternether:quartz_stained_glass:15)
B(13,10,15,betternether:quartz_stained_glass:15)
B(10,11,10,betternether:quartz_stained_glass:15)
B(9,11,11,betternether:quartz_stained_glass:15)
B(10,11,11,betternether:quartz_stained_glass:15)
B(6,11,12,betternether:quartz_stained_glass:15)
B(7,11,12,betternether:quartz_stained_glass:15)
B(8,11,12,betternether:quartz_stained_glass:15)
B(9,11,12,betternether:quartz_stained_glass:15)
B(10,11,12,betternether:quartz_stained_glass:15)
B(11,11,12,betternether:quartz_stained_glass:15)
B(4,11,13,betternether:quartz_stained_glass:15)
B(5,11,13,betternether:quartz_stained_glass:15)
B(6,11,13,betternether:quartz_stained_glass:15)
B(7,11,13,betternether:quartz_stained_glass:15)
B(8,11,13,betternether:quartz_stained_glass:15)
B(9,11,13,betternether:quartz_stained_glass:15)
B(10,11,13,betternether:quartz_stained_glass:15)
B(11,11,13,betternether:quartz_stained_glass:15)
B(12,11,13,betternether:quartz_stained_glass:15)
B(5,11,14,betternether:quartz_stained_glass:15)
B(6,11,14,betternether:quartz_stained_glass:15)
B(7,11,14,betternether:quartz_stained_glass:15)
B(8,11,14,betternether:quartz_stained_glass:15)
B(9,11,14,betternether:quartz_stained_glass:15)
B(10,11,14,betternether:quartz_stained_glass:15)
B(11,11,14,betternether:quartz_stained_glass:15)
B(12,11,14,betternether:quartz_stained_glass:15)
B(13,11,14,betternether:quartz_stained_glass:15)
B(5,11,15,betternether:quartz_stained_glass:15)
B(6,11,15,betternether:quartz_stained_glass:15)
B(7,11,15,betternether:quartz_stained_glass:15)
B(8,11,15,betternether:quartz_stained_glass:15)
B(9,11,15,betternether:quartz_stained_glass:15)
RB(10,11,15,srparasites:parasitestain:1,80,quark:crystal:1,30,srparasites:parasiterubbledense:1,100)
B(11,11,15,betternether:quartz_stained_glass:15)
B(12,11,15,betternether:quartz_stained_glass:15)
B(13,11,15,betternether:quartz_stained_glass:15)
B(8,12,10,betternether:quartz_stained_glass:15)
B(9,12,10,betternether:quartz_stained_glass:15)
B(10,12,10,betternether:quartz_stained_glass:15)
B(7,12,11,betternether:quartz_stained_glass:15)
B(8,12,11,betternether:quartz_stained_glass:15)
B(9,12,11,betternether:quartz_stained_glass:15)
B(10,12,11,betternether:quartz_stained_glass:15)
B(4,12,12,betternether:quartz_stained_glass:15)
B(5,12,12,betternether:quartz_stained_glass:15)
B(6,12,12,betternether:quartz_stained_glass:15)
B(7,12,12,betternether:quartz_stained_glass:15)
B(8,12,12,betternether:quartz_stained_glass:15)
B(9,12,12,betternether:quartz_stained_glass:15)
B(10,12,12,betternether:quartz_stained_glass:15)
B(11,12,12,betternether:quartz_stained_glass:15)
B(12,12,12,betternether:quartz_stained_glass:15)
B(4,12,13,betternether:quartz_stained_glass:15)
B(5,12,13,betternether:quartz_stained_glass:15)
B(6,12,13,betternether:quartz_stained_glass:15)
B(7,12,13,betternether:quartz_stained_glass:15)
B(8,12,13,betternether:quartz_stained_glass:15)
B(9,12,13,betternether:quartz_stained_glass:15)
B(10,12,13,betternether:quartz_stained_glass:15)
B(11,12,13,betternether:quartz_stained_glass:15)
B(12,12,13,betternether:quartz_stained_glass:15)
B(5,12,14,betternether:quartz_stained_glass:15)
B(6,12,14,betternether:quartz_stained_glass:15)
B(7,12,14,betternether:quartz_stained_glass:15)
B(8,12,14,betternether:quartz_stained_glass:15)
B(9,12,14,betternether:quartz_stained_glass:15)
B(10,12,14,srparasites:parasiterubbledense:1)
B(11,12,14,betternether:quartz_stained_glass:15)
B(12,12,14,betternether:quartz_stained_glass:15)
B(13,12,14,betternether:quartz_stained_glass:15)
B(4,12,15,betternether:quartz_stained_glass:15)
B(5,12,15,betternether:quartz_stained_glass:15)
B(6,12,15,betternether:quartz_stained_glass:15)
B(7,12,15,betternether:quartz_stained_glass:15)
RB(8,12,15,srparasites:parasitestain:1,80,quark:crystal:1,30,srparasites:parasiterubbledense:1,100)
RB(9,12,15,srparasites:parasitestain:1,80,quark:crystal:1,30,srparasites:parasiterubbledense:1,100)
RB(10,12,15,srparasites:parasitestain:1,80,quark:crystal:1,30,srparasites:parasiterubbledense:1,100)
B(11,12,15,srparasites:parasiterubbledense:1)
B(12,12,15,betternether:quartz_stained_glass:15)
B(13,12,15,betternether:quartz_stained_glass:15)
B(10,13,9,betternether:quartz_stained_glass:15)
B(7,13,10,betternether:quartz_stained_glass:15)
B(8,13,10,betternether:quartz_stained_glass:15)
B(9,13,10,betternether:quartz_stained_glass:15)
B(10,13,10,betternether:quartz_stained_glass:15)
B(6,13,11,betternether:quartz_stained_glass:15)
B(7,13,11,betternether:quartz_stained_glass:15)
B(8,13,11,betternether:quartz_stained_glass:15)
B(9,13,11,betternether:quartz_stained_glass:15)
B(10,13,11,betternether:quartz_stained_glass:15)
B(3,13,12,betternether:quartz_stained_glass:15)
B(4,13,12,betternether:quartz_stained_glass:15)
B(5,13,12,betternether:quartz_stained_glass:15)
B(6,13,12,betternether:quartz_stained_glass:15)
B(7,13,12,betternether:quartz_stained_glass:15)
B(8,13,12,betternether:quartz_stained_glass:15)
B(9,13,12,betternether:quartz_stained_glass:15)
B(10,13,12,betternether:quartz_stained_glass:15)
B(11,13,12,betternether:quartz_stained_glass:15)
B(12,13,12,betternether:quartz_stained_glass:15)
B(4,13,13,betternether:quartz_stained_glass:15)
B(5,13,13,betternether:quartz_stained_glass:15)
B(6,13,13,betternether:quartz_stained_glass:15)
B(7,13,13,betternether:quartz_stained_glass:15)
B(8,13,13,betternether:quartz_stained_glass:15)
B(9,13,13,betternether:quartz_stained_glass:15)
B(10,13,13,betternether:quartz_stained_glass:15)
B(11,13,13,betternether:quartz_stained_glass:15)
B(12,13,13,betternether:quartz_stained_glass:15)
B(5,13,14,betternether:quartz_stained_glass:15)
B(6,13,14,betternether:quartz_stained_glass:15)
B(7,13,14,betternether:quartz_stained_glass:15)
B(8,13,14,betternether:quartz_stained_glass:15)
RB(9,13,14,srparasites:parasitestain:1,80,quark:crystal:1,30,srparasites:parasiterubbledense:1,100)
B(10,13,14,srparasites:parasiterubbledense:1)
B(11,13,14,srparasites:parasiterubbledense:1)
B(12,13,14,betternether:quartz_stained_glass:15)
B(13,13,14,betternether:quartz_stained_glass:15)
B(4,13,15,betternether:quartz_stained_glass:15)
B(5,13,15,betternether:quartz_stained_glass:15)
B(6,13,15,betternether:quartz_stained_glass:15)
B(7,13,15,betternether:quartz_stained_glass:15)
RB(8,13,15,srparasites:parasitestain:1,80,quark:crystal:1,30,srparasites:parasiterubbledense:1,100)
RB(9,13,15,srparasites:parasitestain:1,80,quark:crystal:1,30,srparasites:parasiterubbledense:1,100)
RB(10,13,15,srparasites:parasitestain:1,80,quark:crystal:1,30,srparasites:parasiterubbledense:1,100)
B(11,13,15,srparasites:parasiterubbledense:1)
B(12,13,15,betternether:quartz_stained_glass:15)
B(13,13,15,betternether:quartz_stained_glass:15)
B(7,14,9,betternether:quartz_stained_glass:15)
B(8,14,9,betternether:quartz_stained_glass:15)
B(9,14,9,betternether:quartz_stained_glass:15)
B(10,14,9,betternether:quartz_stained_glass:15)
B(5,14,10,betternether:quartz_stained_glass:15)
B(6,14,10,betternether:quartz_stained_glass:15)
B(7,14,10,betternether:quartz_stained_glass:15)
B(8,14,10,betternether:quartz_stained_glass:15)
B(9,14,10,betternether:quartz_stained_glass:15)
B(10,14,10,betternether:quartz_stained_glass:15)
B(4,14,11,betternether:quartz_stained_glass:15)
B(5,14,11,betternether:quartz_stained_glass:15)
B(6,14,11,betternether:quartz_stained_glass:15)
B(7,14,11,betternether:quartz_stained_glass:15)
B(8,14,11,betternether:quartz_stained_glass:15)
B(9,14,11,betternether:quartz_stained_glass:15)
B(10,14,11,betternether:quartz_stained_glass:15)
B(11,14,11,betternether:quartz_stained_glass:15)
B(3,14,12,betternether:quartz_stained_glass:15)
B(4,14,12,betternether:quartz_stained_glass:15)
B(5,14,12,betternether:quartz_stained_glass:15)
B(6,14,12,betternether:quartz_stained_glass:15)
B(7,14,12,betternether:quartz_stained_glass:15)
B(8,14,12,betternether:quartz_stained_glass:15)
B(9,14,12,betternether:quartz_stained_glass:15)
B(10,14,12,betternether:quartz_stained_glass:15)
B(11,14,12,betternether:quartz_stained_glass:15)
B(12,14,12,betternether:quartz_stained_glass:15)
B(4,14,13,betternether:quartz_stained_glass:15)
B(5,14,13,betternether:quartz_stained_glass:15)
B(6,14,13,betternether:quartz_stained_glass:15)
B(7,14,13,betternether:quartz_stained_glass:15)
B(8,14,13,betternether:quartz_stained_glass:15)
B(9,14,13,srparasites:parasiterubbledense:1)
B(10,14,13,srparasites:parasiterubbledense:1)
B(11,14,13,srparasites:parasiterubbledense:1)
B(12,14,13,betternether:quartz_stained_glass:15)
B(4,14,14,betternether:quartz_stained_glass:15)
B(5,14,14,betternether:quartz_stained_glass:15)
B(6,14,14,betternether:quartz_stained_glass:15)
B(7,14,14,betternether:quartz_stained_glass:15)
RB(8,14,14,srparasites:parasitestain:1,80,quark:crystal:1,30,srparasites:parasiterubbledense:1,100)
RB(9,14,14,srparasites:parasitestain:1,80,quark:crystal:1,30,srparasites:parasiterubbledense:1,100)
B(10,14,14,srparasites:parasiterubbledense:1)
B(11,14,14,srparasites:parasiterubbledense:1)
B(12,14,14,srparasites:parasiterubbledense:1)
B(13,14,14,betternether:quartz_stained_glass:15)
B(4,14,15,betternether:quartz_stained_glass:15)
B(5,14,15,betternether:quartz_stained_glass:15)
B(6,14,15,betternether:quartz_stained_glass:15)
B(7,14,15,betternether:quartz_stained_glass:15)
RB(8,14,15,srparasites:parasitestain:1,80,quark:crystal:1,30,srparasites:parasiterubbledense:1,100)
RB(9,14,15,srparasites:parasitestain:1,80,quark:crystal:1,30,srparasites:parasiterubbledense:1,100)
B(10,14,15,betternether:quartz_stained_glass:15)
B(11,14,15,srparasites:parasiterubbledense:1)
B(12,14,15,betternether:quartz_stained_glass:15)
B(13,14,15,betternether:quartz_stained_glass:15)
B(8,15,8,betternether:quartz_stained_glass:15)
B(9,15,8,betternether:quartz_stained_glass:15)
B(5,15,9,betternether:quartz_stained_glass:15)
B(6,15,9,betternether:quartz_stained_glass:15)
B(7,15,9,betternether:quartz_stained_glass:15)
B(8,15,9,betternether:quartz_stained_glass:15)
B(9,15,9,betternether:quartz_stained_glass:15)
B(10,15,9,betternether:quartz_stained_glass:15)
B(4,15,10,betternether:quartz_stained_glass:15)
B(5,15,10,betternether:quartz_stained_glass:15)
B(6,15,10,betternether:quartz_stained_glass:15)
B(7,15,10,betternether:quartz_stained_glass:15)
B(8,15,10,betternether:quartz_stained_glass:15)
B(9,15,10,betternether:quartz_stained_glass:15)
B(10,15,10,betternether:quartz_stained_glass:15)
B(2,15,11,betternether:quartz_stained_glass:15)
B(3,15,11,betternether:quartz_stained_glass:15)
B(4,15,11,betternether:quartz_stained_glass:15)
B(5,15,11,betternether:quartz_stained_glass:15)
B(6,15,11,betternether:quartz_stained_glass:15)
B(7,15,11,betternether:quartz_stained_glass:15)
B(8,15,11,betternether:quartz_stained_glass:15)
B(9,15,11,betternether:quartz_stained_glass:15)
B(10,15,11,betternether:quartz_stained_glass:15)
B(11,15,11,betternether:quartz_stained_glass:15)
B(3,15,12,betternether:quartz_stained_glass:15)
B(4,15,12,betternether:quartz_stained_glass:15)
B(5,15,12,betternether:quartz_stained_glass:15)
B(6,15,12,betternether:quartz_stained_glass:15)
B(7,15,12,betternether:quartz_stained_glass:15)
B(8,15,12,betternether:quartz_stained_glass:15)
B(9,15,12,betternether:quartz_stained_glass:15)
B(10,15,12,srparasites:parasiterubbledense:1)
B(11,15,12,betternether:quartz_stained_glass:15)
B(12,15,12,betternether:quartz_stained_glass:15)
B(4,15,13,betternether:quartz_stained_glass:15)
B(5,15,13,betternether:quartz_stained_glass:15)
B(6,15,13,betternether:quartz_stained_glass:15)
RB(7,15,13,srparasites:parasitestain:1,80,quark:crystal:1,30,srparasites:parasiterubbledense:1,100)
RB(8,15,13,srparasites:parasitestain:1,80,quark:crystal:1,30,srparasites:parasiterubbledense:1,100)
B(9,15,13,srparasites:parasiterubbledense:1)
B(10,15,13,srparasites:parasiterubbledense:1)
B(11,15,13,betternether:quartz_stained_glass:15)
B(12,15,13,betternether:quartz_stained_glass:15)
B(4,15,14,betternether:quartz_stained_glass:15)
B(5,15,14,betternether:quartz_stained_glass:15)
B(6,15,14,betternether:quartz_stained_glass:15)
B(7,15,14,betternether:quartz_stained_glass:15)
RB(8,15,14,srparasites:parasitestain:1,80,quark:crystal:1,30,srparasites:parasiterubbledense:1,100)
RB(9,15,14,srparasites:parasitestain:1,80,quark:crystal:1,30,srparasites:parasiterubbledense:1,100)
B(10,15,14,srparasites:parasiterubbledense:1)
B(11,15,14,betternether:quartz_stained_glass:15)
B(12,15,14,betternether:quartz_stained_glass:15)
B(4,15,15,betternether:quartz_stained_glass:15)
B(5,15,15,betternether:quartz_stained_glass:15)
B(6,15,15,betternether:quartz_stained_glass:15)
B(7,15,15,betternether:quartz_stained_glass:15)
B(8,15,15,betternether:quartz_stained_glass:15)
B(9,15,15,betternether:quartz_stained_glass:15)
B(10,15,15,betternether:quartz_stained_glass:15)
B(11,15,15,srparasites:parasiterubbledense:1)
B(12,15,15,betternether:quartz_stained_glass:15)
B(8,16,7,betternether:quartz_stained_glass:15)
B(7,16,8,betternether:quartz_stained_glass:15)
B(8,16,8,betternether:quartz_stained_glass:15)
B(9,16,8,betternether:quartz_stained_glass:15)
B(4,16,9,betternether:quartz_stained_glass:15)
B(5,16,9,betternether:quartz_stained_glass:15)
B(6,16,9,betternether:quartz_stained_glass:15)
B(7,16,9,betternether:quartz_stained_glass:15)
B(8,16,9,betternether:quartz_stained_glass:15)
B(9,16,9,betternether:quartz_stained_glass:15)
B(10,16,9,betternether:quartz_stained_glass:15)
B(11,16,9,betternether:quartz_stained_glass:15)
B(3,16,10,betternether:quartz_stained_glass:15)
B(4,16,10,betternether:quartz_stained_glass:15)
B(5,16,10,betternether:quartz_stained_glass:15)
B(6,16,10,betternether:quartz_stained_glass:15)
B(7,16,10,betternether:quartz_stained_glass:15)
B(8,16,10,betternether:quartz_stained_glass:15)
B(9,16,10,betternether:quartz_stained_glass:15)
B(10,16,10,betternether:quartz_stained_glass:15)
B(2,16,11,betternether:quartz_stained_glass:15)
B(3,16,11,betternether:quartz_stained_glass:15)
B(4,16,11,betternether:quartz_stained_glass:15)
B(5,16,11,betternether:quartz_stained_glass:15)
B(6,16,11,betternether:quartz_stained_glass:15)
B(7,16,11,betternether:quartz_stained_glass:15)
B(8,16,11,betternether:quartz_stained_glass:15)
B(9,16,11,betternether:quartz_stained_glass:15)
B(10,16,11,betternether:quartz_stained_glass:15)
B(11,16,11,betternether:quartz_stained_glass:15)
B(3,16,12,betternether:quartz_stained_glass:15)
B(4,16,12,betternether:quartz_stained_glass:15)
B(5,16,12,betternether:quartz_stained_glass:15)
B(6,16,12,betternether:quartz_stained_glass:15)
RB(7,16,12,srparasites:parasitestain:1,80,quark:crystal:1,30,srparasites:parasiterubbledense:1,100)
B(8,16,12,betternether:quartz_stained_glass:15)
B(9,16,12,srparasites:parasiterubbledense:1)
B(10,16,12,srparasites:parasiterubbledense:1)
B(11,16,12,betternether:quartz_stained_glass:15)
B(12,16,12,betternether:quartz_stained_glass:15)
B(3,16,13,betternether:quartz_stained_glass:15)
B(4,16,13,betternether:quartz_stained_glass:15)
B(5,16,13,betternether:quartz_stained_glass:15)
B(6,16,13,betternether:quartz_stained_glass:15)
RB(7,16,13,srparasites:parasitestain:1,80,quark:crystal:1,30,srparasites:parasiterubbledense:1,100)
RB(8,16,13,srparasites:parasitestain:1,80,quark:crystal:1,30,srparasites:parasiterubbledense:1,100)
B(9,16,13,srparasites:parasiterubbledense:1)
B(10,16,13,srparasites:parasiterubbledense:1)
B(11,16,13,betternether:quartz_stained_glass:15)
B(12,16,13,betternether:quartz_stained_glass:15)
B(4,16,14,betternether:quartz_stained_glass:15)
B(5,16,14,betternether:quartz_stained_glass:15)
B(6,16,14,betternether:quartz_stained_glass:15)
B(7,16,14,betternether:quartz_stained_glass:15)
RB(8,16,14,srparasites:parasitestain:1,80,quark:crystal:1,30,srparasites:parasiterubbledense:1,100)
B(9,16,14,srparasites:parasiterubbledense:1)
B(10,16,14,srparasites:parasiterubbledense:1)
B(11,16,14,betternether:quartz_stained_glass:15)
B(12,16,14,betternether:quartz_stained_glass:15)
B(4,16,15,betternether:quartz_stained_glass:15)
B(5,16,15,betternether:quartz_stained_glass:15)
B(6,16,15,betternether:quartz_stained_glass:15)
B(7,16,15,betternether:quartz_stained_glass:15)
B(8,16,15,betternether:quartz_stained_glass:15)
B(9,16,15,betternether:quartz_stained_glass:15)
B(10,16,15,betternether:quartz_stained_glass:15)
B(11,16,15,betternether:quartz_stained_glass:15)
B(12,16,15,betternether:quartz_stained_glass:15)
B(7,17,7,betternether:quartz_stained_glass:15)
B(8,17,7,betternether:quartz_stained_glass:15)
B(5,17,8,betternether:quartz_stained_glass:15)
B(6,17,8,betternether:quartz_stained_glass:15)
B(7,17,8,betternether:quartz_stained_glass:15)
B(8,17,8,betternether:quartz_stained_glass:15)
B(9,17,8,betternether:quartz_stained_glass:15)
B(2,17,9,betternether:quartz_stained_glass:15)
B(3,17,9,betternether:quartz_stained_glass:15)
B(4,17,9,betternether:quartz_stained_glass:15)
B(5,17,9,betternether:quartz_stained_glass:15)
B(6,17,9,betternether:quartz_stained_glass:15)
B(7,17,9,betternether:quartz_stained_glass:15)
B(8,17,9,betternether:quartz_stained_glass:15)
B(9,17,9,betternether:quartz_stained_glass:15)
B(10,17,9,betternether:quartz_stained_glass:15)
B(11,17,9,betternether:quartz_stained_glass:15)
B(3,17,10,betternether:quartz_stained_glass:15)
B(4,17,10,betternether:quartz_stained_glass:15)
B(5,17,10,betternether:quartz_stained_glass:15)
B(6,17,10,betternether:quartz_stained_glass:15)
B(7,17,10,betternether:quartz_stained_glass:15)
B(8,17,10,betternether:quartz_stained_glass:15)
B(9,17,10,betternether:quartz_stained_glass:15)
B(10,17,10,betternether:quartz_stained_glass:15)
B(2,17,11,betternether:quartz_stained_glass:15)
B(3,17,11,betternether:quartz_stained_glass:15)
B(4,17,11,betternether:quartz_stained_glass:15)
B(5,17,11,betternether:quartz_stained_glass:15)
B(6,17,11,betternether:quartz_stained_glass:15)
B(7,17,11,betternether:quartz_stained_glass:15)
B(8,17,11,betternether:quartz_stained_glass:15)
B(9,17,11,srparasites:parasiterubbledense:1)
B(10,17,11,betternether:quartz_stained_glass:15)
B(11,17,11,betternether:quartz_stained_glass:15)
B(3,17,12,betternether:quartz_stained_glass:15)
B(4,17,12,betternether:quartz_stained_glass:15)
B(5,17,12,betternether:quartz_stained_glass:15)
RB(6,17,12,srparasites:parasitestain:1,80,quark:crystal:1,30,srparasites:parasiterubbledense:1,100)
RB(7,17,12,srparasites:parasitestain:1,80,quark:crystal:1,30,srparasites:parasiterubbledense:1,100)
RB(8,17,12,srparasites:parasitestain:1,80,quark:crystal:1,30,srparasites:parasiterubbledense:1,100)
B(9,17,12,srparasites:parasiterubbledense:1)
B(10,17,12,srparasites:parasiterubbledense:1)
B(11,17,12,betternether:quartz_stained_glass:15)
B(12,17,12,betternether:quartz_stained_glass:15)
B(3,17,13,betternether:quartz_stained_glass:15)
B(4,17,13,betternether:quartz_stained_glass:15)
B(5,17,13,betternether:quartz_stained_glass:15)
B(6,17,13,betternether:quartz_stained_glass:15)
RB(7,17,13,srparasites:parasitestain:1,80,quark:crystal:1,30,srparasites:parasiterubbledense:1,100)
RB(8,17,13,srparasites:parasitestain:1,80,quark:crystal:1,30,srparasites:parasiterubbledense:1,100)
B(9,17,13,srparasites:parasiterubbledense:1)
B(10,17,13,srparasites:parasiterubbledense:1)
B(11,17,13,betternether:quartz_stained_glass:15)
B(4,17,14,betternether:quartz_stained_glass:15)
B(5,17,14,betternether:quartz_stained_glass:15)
B(6,17,14,betternether:quartz_stained_glass:15)
B(7,17,14,betternether:quartz_stained_glass:15)
B(8,17,14,betternether:quartz_stained_glass:15)
B(9,17,14,srparasites:parasiterubbledense:1)
B(10,17,14,betternether:quartz_stained_glass:15)
B(11,17,14,betternether:quartz_stained_glass:15)
B(12,17,14,betternether:quartz_stained_glass:15)
B(4,17,15,betternether:quartz_stained_glass:15)
B(5,17,15,betternether:quartz_stained_glass:15)
B(6,17,15,betternether:quartz_stained_glass:15)
B(7,17,15,betternether:quartz_stained_glass:15)
B(8,17,15,betternether:quartz_stained_glass:15)
B(9,17,15,betternether:quartz_stained_glass:15)
B(10,17,15,betternether:quartz_stained_glass:15)
B(11,17,15,betternether:quartz_stained_glass:15)
B(8,18,6,betternether:quartz_stained_glass:15)
B(5,18,7,betternether:quartz_stained_glass:15)
B(6,18,7,betternether:quartz_stained_glass:15)
B(7,18,7,betternether:quartz_stained_glass:15)
B(8,18,7,betternether:quartz_stained_glass:15)
B(4,18,8,betternether:quartz_stained_glass:15)
B(5,18,8,betternether:quartz_stained_glass:15)
B(6,18,8,betternether:quartz_stained_glass:15)
B(7,18,8,betternether:quartz_stained_glass:15)
B(8,18,8,betternether:quartz_stained_glass:15)
B(9,18,8,betternether:quartz_stained_glass:15)
B(10,18,8,betternether:quartz_stained_glass:15)
B(2,18,9,betternether:quartz_stained_glass:15)
B(3,18,9,betternether:quartz_stained_glass:15)
B(4,18,9,betternether:quartz_stained_glass:15)
B(5,18,9,betternether:quartz_stained_glass:15)
B(6,18,9,betternether:quartz_stained_glass:15)
B(7,18,9,betternether:quartz_stained_glass:15)
B(8,18,9,betternether:quartz_stained_glass:15)
B(9,18,9,betternether:quartz_stained_glass:15)
B(10,18,9,betternether:quartz_stained_glass:15)
B(11,18,9,betternether:quartz_stained_glass:15)
B(3,18,10,betternether:quartz_stained_glass:15)
B(4,18,10,betternether:quartz_stained_glass:15)
B(5,18,10,betternether:quartz_stained_glass:15)
B(6,18,10,betternether:quartz_stained_glass:15)
B(7,18,10,betternether:quartz_stained_glass:15)
B(8,18,10,srparasites:parasiterubbledense:1)
B(9,18,10,betternether:quartz_stained_glass:15)
B(10,18,10,betternether:quartz_stained_glass:15)
B(2,18,11,betternether:quartz_stained_glass:15)
B(3,18,11,betternether:quartz_stained_glass:15)
B(4,18,11,betternether:quartz_stained_glass:15)
B(5,18,11,betternether:quartz_stained_glass:15)
B(6,18,11,betternether:quartz_stained_glass:15)
RB(7,18,11,srparasites:parasitestain:1,80,quark:crystal:1,30,srparasites:parasiterubbledense:1,100)
B(8,18,11,srparasites:parasiterubbledense:1)
B(9,18,11,srparasites:parasiterubbledense:1)
B(10,18,11,betternether:quartz_stained_glass:15)
B(11,18,11,betternether:quartz_stained_glass:15)
B(2,18,12,betternether:quartz_stained_glass:15)
B(3,18,12,betternether:quartz_stained_glass:15)
B(4,18,12,betternether:quartz_stained_glass:15)
B(5,18,12,betternether:quartz_stained_glass:15)
RB(6,18,12,srparasites:parasitestain:1,80,quark:crystal:1,30,srparasites:parasiterubbledense:1,100)
RB(7,18,12,srparasites:parasitestain:1,80,quark:crystal:1,30,srparasites:parasiterubbledense:1,100)
RB(8,18,12,srparasites:parasitestain:1,80,quark:crystal:1,30,srparasites:parasiterubbledense:1,100)
B(9,18,12,srparasites:parasiterubbledense:1)
B(10,18,12,srparasites:parasiterubbledense:1)
B(11,18,12,betternether:quartz_stained_glass:15)
B(12,18,12,betternether:quartz_stained_glass:15)
B(3,18,13,betternether:quartz_stained_glass:15)
B(4,18,13,betternether:quartz_stained_glass:15)
B(5,18,13,betternether:quartz_stained_glass:15)
B(6,18,13,betternether:quartz_stained_glass:15)
B(7,18,13,betternether:quartz_stained_glass:15)
B(8,18,13,srparasites:parasiterubbledense:1)
B(9,18,13,srparasites:parasiterubbledense:1)
B(10,18,13,betternether:quartz_stained_glass:15)
B(11,18,13,betternether:quartz_stained_glass:15)
B(4,18,14,betternether:quartz_stained_glass:15)
B(5,18,14,betternether:quartz_stained_glass:15)
B(6,18,14,betternether:quartz_stained_glass:15)
B(7,18,14,betternether:quartz_stained_glass:15)
B(8,18,14,betternether:quartz_stained_glass:15)
B(9,18,14,betternether:quartz_stained_glass:15)
B(10,18,14,betternether:quartz_stained_glass:15)
B(11,18,14,betternether:quartz_stained_glass:15)
B(4,18,15,betternether:quartz_stained_glass:15)
B(5,18,15,betternether:quartz_stained_glass:15)
B(6,18,15,betternether:quartz_stained_glass:15)
B(7,18,15,betternether:quartz_stained_glass:15)
B(8,18,15,betternether:quartz_stained_glass:15)
B(9,18,15,betternether:quartz_stained_glass:15)
B(10,18,15,betternether:quartz_stained_glass:15)
B(8,19,5,betternether:quartz_stained_glass:15)
B(5,19,6,betternether:quartz_stained_glass:15)
B(6,19,6,betternether:quartz_stained_glass:15)
B(7,19,6,betternether:quartz_stained_glass:15)
B(8,19,6,betternether:quartz_stained_glass:15)
B(4,19,7,betternether:quartz_stained_glass:15)
B(5,19,7,betternether:quartz_stained_glass:15)
B(6,19,7,betternether:quartz_stained_glass:15)
B(7,19,7,betternether:quartz_stained_glass:15)
B(8,19,7,betternether:quartz_stained_glass:15)
B(1,19,8,betternether:quartz_stained_glass:15)
B(2,19,8,betternether:quartz_stained_glass:15)
B(3,19,8,betternether:quartz_stained_glass:15)
B(4,19,8,betternether:quartz_stained_glass:15)
B(5,19,8,betternether:quartz_stained_glass:15)
B(6,19,8,betternether:quartz_stained_glass:15)
B(7,19,8,betternether:quartz_stained_glass:15)
B(8,19,8,betternether:quartz_stained_glass:15)
B(9,19,8,betternether:quartz_stained_glass:15)
B(10,19,8,betternether:quartz_stained_glass:15)
B(2,19,9,betternether:quartz_stained_glass:15)
B(3,19,9,betternether:quartz_stained_glass:15)
B(4,19,9,betternether:quartz_stained_glass:15)
B(5,19,9,betternether:quartz_stained_glass:15)
B(6,19,9,betternether:quartz_stained_glass:15)
B(7,19,9,betternether:quartz_stained_glass:15)
B(8,19,9,betternether:quartz_stained_glass:15)
B(9,19,9,betternether:quartz_stained_glass:15)
B(10,19,9,betternether:quartz_stained_glass:15)
B(11,19,9,betternether:quartz_stained_glass:15)
B(3,19,10,betternether:quartz_stained_glass:15)
B(4,19,10,betternether:quartz_stained_glass:15)
B(5,19,10,betternether:quartz_stained_glass:15)
B(6,19,10,betternether:quartz_stained_glass:15)
RB(7,19,10,srparasites:parasitestain:1,80,quark:crystal:1,30,srparasites:parasiterubbledense:1,100)
B(8,19,10,srparasites:parasiterubbledense:1)
B(9,19,10,betternether:quartz_stained_glass:15)
B(10,19,10,betternether:quartz_stained_glass:15)
B(2,19,11,betternether:quartz_stained_glass:15)
B(3,19,11,betternether:quartz_stained_glass:15)
B(4,19,11,betternether:quartz_stained_glass:15)
B(5,19,11,betternether:quartz_stained_glass:15)
RB(6,19,11,srparasites:parasitestain:1,80,quark:crystal:1,30,srparasites:parasiterubbledense:1,100)
RB(7,19,11,srparasites:parasitestain:1,80,quark:crystal:1,30,srparasites:parasiterubbledense:1,100)
B(8,19,11,srparasites:parasiterubbledense:1)
B(9,19,11,srparasites:parasiterubbledense:1)
B(10,19,11,betternether:quartz_stained_glass:15)
B(11,19,11,betternether:quartz_stained_glass:15)
B(2,19,12,betternether:quartz_stained_glass:15)
B(3,19,12,betternether:quartz_stained_glass:15)
B(4,19,12,betternether:quartz_stained_glass:15)
B(5,19,12,betternether:quartz_stained_glass:15)
RB(6,19,12,srparasites:parasitestain:1,80,quark:crystal:1,30,srparasites:parasiterubbledense:1,100)
B(7,19,12,betternether:quartz_stained_glass:15)
RB(8,19,12,srparasites:parasitestain:1,80,quark:crystal:1,30,srparasites:parasiterubbledense:1,100)
B(9,19,12,srparasites:parasiterubbledense:1)
B(10,19,12,srparasites:parasiterubbledense:1)
B(11,19,12,betternether:quartz_stained_glass:15)
B(3,19,13,betternether:quartz_stained_glass:15)
B(4,19,13,betternether:quartz_stained_glass:15)
B(5,19,13,srparasites:parasiterubbledense:1)
B(6,19,13,srparasites:parasiterubbledense:1)
B(7,19,13,srparasites:parasiterubbledense:1)
B(8,19,13,betternether:quartz_stained_glass:15)
B(9,19,13,betternether:quartz_stained_glass:15)
B(10,19,13,betternether:quartz_stained_glass:15)
B(11,19,13,betternether:quartz_stained_glass:15)
B(4,19,14,betternether:quartz_stained_glass:15)
B(5,19,14,betternether:quartz_stained_glass:15)
B(6,19,14,srparasites:parasiterubbledense:1)
B(7,19,14,betternether:quartz_stained_glass:15)
B(8,19,14,betternether:quartz_stained_glass:15)
B(9,19,14,betternether:quartz_stained_glass:15)
B(10,19,14,betternether:quartz_stained_glass:15)
B(5,19,15,betternether:quartz_stained_glass:15)
B(6,19,15,betternether:quartz_stained_glass:15)
B(7,19,15,betternether:quartz_stained_glass:15)
B(8,19,15,betternether:quartz_stained_glass:15)
B(9,19,15,betternether:quartz_stained_glass:15)
B(7,20,5,betternether:quartz_stained_glass:15)
B(8,20,5,betternether:quartz_stained_glass:15)
B(4,20,6,betternether:quartz_stained_glass:15)
B(5,20,6,betternether:quartz_stained_glass:15)
B(6,20,6,betternether:quartz_stained_glass:15)
B(7,20,6,betternether:quartz_stained_glass:15)
B(8,20,6,betternether:quartz_stained_glass:15)
B(2,20,7,betternether:quartz_stained_glass:15)
B(3,20,7,betternether:quartz_stained_glass:15)
B(4,20,7,betternether:quartz_stained_glass:15)
B(5,20,7,betternether:quartz_stained_glass:15)
B(6,20,7,betternether:quartz_stained_glass:15)
B(7,20,7,betternether:quartz_stained_glass:15)
B(8,20,7,betternether:quartz_stained_glass:15)
B(9,20,7,betternether:quartz_stained_glass:15)
B(1,20,8,betternether:quartz_stained_glass:15)
B(2,20,8,betternether:quartz_stained_glass:15)
B(3,20,8,betternether:quartz_stained_glass:15)
B(4,20,8,betternether:quartz_stained_glass:15)
B(5,20,8,betternether:quartz_stained_glass:15)
B(6,20,8,betternether:quartz_stained_glass:15)
B(7,20,8,betternether:quartz_stained_glass:15)
B(8,20,8,betternether:quartz_stained_glass:15)
B(9,20,8,betternether:quartz_stained_glass:15)
B(10,20,8,betternether:quartz_stained_glass:15)
B(2,20,9,betternether:quartz_stained_glass:15)
B(3,20,9,betternether:quartz_stained_glass:15)
B(4,20,9,betternether:quartz_stained_glass:15)
B(5,20,9,betternether:quartz_stained_glass:15)
B(6,20,9,betternether:quartz_stained_glass:15)
B(7,20,9,betternether:quartz_stained_glass:15)
B(8,20,9,betternether:quartz_stained_glass:15)
B(9,20,9,betternether:quartz_stained_glass:15)
B(10,20,9,betternether:quartz_stained_glass:15)
B(11,20,9,betternether:quartz_stained_glass:15)
B(2,20,10,betternether:quartz_stained_glass:15)
B(3,20,10,betternether:quartz_stained_glass:15)
B(4,20,10,betternether:quartz_stained_glass:15)
B(5,20,10,betternether:quartz_stained_glass:15)
RB(6,20,10,srparasites:parasitestain:1,80,quark:crystal:1,30,srparasites:parasiterubbledense:1,100)
RB(7,20,10,srparasites:parasitestain:1,80,quark:crystal:1,30,srparasites:parasiterubbledense:1,100)
B(8,20,10,betternether:quartz_stained_glass:15)
B(9,20,10,betternether:quartz_stained_glass:15)
B(10,20,10,betternether:quartz_stained_glass:15)
B(2,20,11,betternether:quartz_stained_glass:15)
B(3,20,11,betternether:quartz_stained_glass:15)
B(4,20,11,betternether:quartz_stained_glass:15)
B(5,20,11,betternether:quartz_stained_glass:15)
RB(6,20,11,srparasites:parasitestain:1,80,quark:crystal:1,30,srparasites:parasiterubbledense:1,100)
RB(7,20,11,srparasites:parasitestain:1,80,quark:crystal:1,30,srparasites:parasiterubbledense:1,100)
B(8,20,11,betternether:quartz_stained_glass:15)
B(9,20,11,betternether:quartz_stained_glass:15)
B(10,20,11,betternether:quartz_stained_glass:15)
B(11,20,11,betternether:quartz_stained_glass:15)
B(2,20,12,betternether:quartz_stained_glass:15)
B(3,20,12,betternether:quartz_stained_glass:15)
B(4,20,12,betternether:quartz_stained_glass:15)
B(5,20,12,srparasites:parasiterubbledense:1)
B(6,20,12,srparasites:parasiterubbledense:1)
B(7,20,12,srparasites:parasiterubbledense:1)
B(8,20,12,betternether:quartz_stained_glass:15)
B(9,20,12,betternether:quartz_stained_glass:15)
B(10,20,12,betternether:quartz_stained_glass:15)
B(11,20,12,betternether:quartz_stained_glass:15)
B(3,20,13,betternether:quartz_stained_glass:15)
B(4,20,13,betternether:quartz_stained_glass:15)
B(5,20,13,srparasites:parasiterubbledense:1)
B(6,20,13,srparasites:parasiterubbledense:1)
B(7,20,13,betternether:quartz_stained_glass:15)
B(8,20,13,betternether:quartz_stained_glass:15)
B(9,20,13,betternether:quartz_stained_glass:15)
B(4,20,14,betternether:quartz_stained_glass:15)
B(5,20,14,betternether:quartz_stained_glass:15)
B(6,20,14,betternether:quartz_stained_glass:15)
B(7,20,14,betternether:quartz_stained_glass:15)
B(8,20,14,betternether:quartz_stained_glass:15)
B(9,20,14,betternether:quartz_stained_glass:15)
B(5,20,15,betternether:quartz_stained_glass:15)
B(6,21,4,betternether:quartz_stained_glass:15)
B(7,21,4,betternether:quartz_stained_glass:15)
B(5,21,5,betternether:quartz_stained_glass:15)
B(6,21,5,betternether:quartz_stained_glass:15)
B(7,21,5,betternether:quartz_stained_glass:15)
B(8,21,5,betternether:quartz_stained_glass:15)
B(2,21,6,betternether:quartz_stained_glass:15)
B(3,21,6,betternether:quartz_stained_glass:15)
B(4,21,6,betternether:quartz_stained_glass:15)
B(5,21,6,betternether:quartz_stained_glass:15)
B(6,21,6,betternether:quartz_stained_glass:15)
B(7,21,6,betternether:quartz_stained_glass:15)
B(8,21,6,betternether:quartz_stained_glass:15)
B(1,21,7,betternether:quartz_stained_glass:15)
B(2,21,7,betternether:quartz_stained_glass:15)
B(3,21,7,betternether:quartz_stained_glass:15)
B(4,21,7,betternether:quartz_stained_glass:15)
B(5,21,7,betternether:quartz_stained_glass:15)
B(6,21,7,betternether:quartz_stained_glass:15)
B(7,21,7,betternether:quartz_stained_glass:15)
B(8,21,7,betternether:quartz_stained_glass:15)
B(9,21,7,betternether:quartz_stained_glass:15)
B(1,21,8,betternether:quartz_stained_glass:15)
B(2,21,8,betternether:quartz_stained_glass:15)
B(3,21,8,betternether:quartz_stained_glass:15)
B(4,21,8,betternether:quartz_stained_glass:15)
B(5,21,8,betternether:quartz_stained_glass:15)
B(6,21,8,betternether:quartz_stained_glass:15)
B(7,21,8,betternether:quartz_stained_glass:15)
B(8,21,8,betternether:quartz_stained_glass:15)
B(9,21,8,betternether:quartz_stained_glass:15)
B(10,21,8,betternether:quartz_stained_glass:15)
B(2,21,9,betternether:quartz_stained_glass:15)
B(3,21,9,betternether:quartz_stained_glass:15)
B(4,21,9,betternether:quartz_stained_glass:15)
RB(5,21,9,srparasites:parasitestain:1,80,quark:crystal:1,30,srparasites:parasiterubbledense:1,100)
RB(6,21,9,srparasites:parasitestain:1,80,quark:crystal:1,30,srparasites:parasiterubbledense:1,100)
B(7,21,9,betternether:quartz_stained_glass:15)
B(8,21,9,betternether:quartz_stained_glass:15)
B(9,21,9,betternether:quartz_stained_glass:15)
B(10,21,9,betternether:quartz_stained_glass:15)
B(11,21,9,betternether:quartz_stained_glass:15)
B(2,21,10,betternether:quartz_stained_glass:15)
B(3,21,10,betternether:quartz_stained_glass:15)
B(4,21,10,betternether:quartz_stained_glass:15)
B(5,21,10,betternether:quartz_stained_glass:15)
RB(6,21,10,srparasites:parasitestain:1,80,quark:crystal:1,30,srparasites:parasiterubbledense:1,100)
RB(7,21,10,srparasites:parasitestain:1,80,quark:crystal:1,30,srparasites:parasiterubbledense:1,100)
B(8,21,10,betternether:quartz_stained_glass:15)
B(9,21,10,betternether:quartz_stained_glass:15)
B(10,21,10,betternether:quartz_stained_glass:15)
B(2,21,11,betternether:quartz_stained_glass:15)
B(3,21,11,betternether:quartz_stained_glass:15)
B(4,21,11,betternether:quartz_stained_glass:15)
B(5,21,11,betternether:quartz_stained_glass:15)
RB(6,21,11,srparasites:parasitestain:1,80,quark:crystal:1,30,srparasites:parasiterubbledense:1,100)
B(7,21,11,betternether:quartz_stained_glass:15)
B(8,21,11,betternether:quartz_stained_glass:15)
B(9,21,11,betternether:quartz_stained_glass:15)
B(10,21,11,betternether:quartz_stained_glass:15)
B(2,21,12,betternether:quartz_stained_glass:15)
B(3,21,12,betternether:quartz_stained_glass:15)
B(4,21,12,betternether:quartz_stained_glass:15)
B(5,21,12,srparasites:parasiterubbledense:1)
B(6,21,12,srparasites:parasiterubbledense:1)
B(7,21,12,betternether:quartz_stained_glass:15)
B(8,21,12,betternether:quartz_stained_glass:15)
B(9,21,12,betternether:quartz_stained_glass:15)
B(10,21,12,betternether:quartz_stained_glass:15)
B(11,21,12,betternether:quartz_stained_glass:15)
B(3,21,13,betternether:quartz_stained_glass:15)
B(4,21,13,betternether:quartz_stained_glass:15)
B(5,21,13,srparasites:parasiterubbledense:1)
B(6,21,13,betternether:quartz_stained_glass:15)
B(7,21,13,betternether:quartz_stained_glass:15)
B(8,21,13,betternether:quartz_stained_glass:15)
B(9,21,13,betternether:quartz_stained_glass:15)
B(5,21,14,betternether:quartz_stained_glass:15)
B(6,21,14,betternether:quartz_stained_glass:15)
B(7,21,14,betternether:quartz_stained_glass:15)
B(8,21,14,betternether:quartz_stained_glass:15)
B(6,22,3,betternether:quartz_stained_glass:15)
B(5,22,4,betternether:quartz_stained_glass:15)
B(6,22,4,betternether:quartz_stained_glass:15)
B(7,22,4,betternether:quartz_stained_glass:15)
B(3,22,5,betternether:quartz_stained_glass:15)
B(4,22,5,betternether:quartz_stained_glass:15)
B(5,22,5,betternether:quartz_stained_glass:15)
B(6,22,5,betternether:quartz_stained_glass:15)
B(7,22,5,betternether:quartz_stained_glass:15)
B(8,22,5,betternether:quartz_stained_glass:15)
B(1,22,6,betternether:quartz_stained_glass:15)
B(2,22,6,betternether:quartz_stained_glass:15)
B(3,22,6,betternether:quartz_stained_glass:15)
B(4,22,6,betternether:quartz_stained_glass:15)
B(5,22,6,betternether:quartz_stained_glass:15)
B(6,22,6,betternether:quartz_stained_glass:15)
B(7,22,6,betternether:quartz_stained_glass:15)
B(8,22,6,betternether:quartz_stained_glass:15)
B(9,22,6,betternether:quartz_stained_glass:15)
B(1,22,7,betternether:quartz_stained_glass:15)
B(2,22,7,betternether:quartz_stained_glass:15)
B(3,22,7,betternether:quartz_stained_glass:15)
B(4,22,7,betternether:quartz_stained_glass:15)
B(5,22,7,betternether:quartz_stained_glass:15)
B(6,22,7,betternether:quartz_stained_glass:15)
B(7,22,7,betternether:quartz_stained_glass:15)
B(8,22,7,betternether:quartz_stained_glass:15)
B(9,22,7,betternether:quartz_stained_glass:15)
B(1,22,8,betternether:quartz_stained_glass:15)
B(2,22,8,betternether:quartz_stained_glass:15)
B(3,22,8,betternether:quartz_stained_glass:15)
B(4,22,8,betternether:quartz_stained_glass:15)
B(5,22,8,betternether:quartz_stained_glass:15)
B(6,22,8,betternether:quartz_stained_glass:15)
B(7,22,8,betternether:quartz_stained_glass:15)
B(8,22,8,betternether:quartz_stained_glass:15)
B(9,22,8,betternether:quartz_stained_glass:15)
B(10,22,8,betternether:quartz_stained_glass:15)
B(1,22,9,betternether:quartz_stained_glass:15)
B(2,22,9,betternether:quartz_stained_glass:15)
B(3,22,9,betternether:quartz_stained_glass:15)
B(4,22,9,betternether:quartz_stained_glass:15)
RB(5,22,9,srparasites:parasitestain:1,80,quark:crystal:1,30,srparasites:parasiterubbledense:1,100)
RB(6,22,9,srparasites:parasitestain:1,80,quark:crystal:1,30,srparasites:parasiterubbledense:1,100)
B(7,22,9,betternether:quartz_stained_glass:15)
B(8,22,9,betternether:quartz_stained_glass:15)
B(9,22,9,betternether:quartz_stained_glass:15)
B(10,22,9,betternether:quartz_stained_glass:15)
B(11,22,9,betternether:quartz_stained_glass:15)
B(2,22,10,betternether:quartz_stained_glass:15)
B(3,22,10,betternether:quartz_stained_glass:15)
B(4,22,10,betternether:quartz_stained_glass:15)
B(5,22,10,srparasites:parasiterubbledense:1)
RB(6,22,10,srparasites:parasitestain:1,80,quark:crystal:1,30,srparasites:parasiterubbledense:1,100)
B(7,22,10,betternether:quartz_stained_glass:15)
B(8,22,10,betternether:quartz_stained_glass:15)
B(9,22,10,betternether:quartz_stained_glass:15)
B(10,22,10,betternether:quartz_stained_glass:15)
B(2,22,11,betternether:quartz_stained_glass:15)
B(3,22,11,betternether:quartz_stained_glass:15)
B(4,22,11,betternether:quartz_stained_glass:15)
B(5,22,11,srparasites:parasiterubbledense:1)
B(6,22,11,srparasites:parasiterubbledense:1)
B(7,22,11,srparasites:parasiterubbledense:1)
B(8,22,11,betternether:quartz_stained_glass:15)
B(9,22,11,betternether:quartz_stained_glass:15)
B(10,22,11,betternether:quartz_stained_glass:15)
B(2,22,12,betternether:quartz_stained_glass:15)
B(3,22,12,betternether:quartz_stained_glass:15)
B(4,22,12,betternether:quartz_stained_glass:15)
B(5,22,12,srparasites:parasiterubbledense:1)
B(6,22,12,betternether:quartz_stained_glass:15)
B(7,22,12,betternether:quartz_stained_glass:15)
B(8,22,12,betternether:quartz_stained_glass:15)
B(9,22,12,betternether:quartz_stained_glass:15)
B(3,22,13,betternether:quartz_stained_glass:15)
B(4,22,13,betternether:quartz_stained_glass:15)
B(5,22,13,betternether:quartz_stained_glass:15)
B(6,22,13,betternether:quartz_stained_glass:15)
B(7,22,13,betternether:quartz_stained_glass:15)
B(8,22,13,betternether:quartz_stained_glass:15)
B(5,22,14,betternether:quartz_stained_glass:15)
B(5,23,3,betternether:quartz_stained_glass:15)
B(6,23,3,betternether:quartz_stained_glass:15)
B(7,23,3,betternether:quartz_stained_glass:15)
B(3,23,4,betternether:quartz_stained_glass:15)
B(4,23,4,betternether:quartz_stained_glass:15)
B(5,23,4,betternether:quartz_stained_glass:15)
B(6,23,4,betternether:quartz_stained_glass:15)
B(7,23,4,betternether:quartz_stained_glass:15)
B(0,23,5,betternether:quartz_stained_glass:15)
B(1,23,5,betternether:quartz_stained_glass:15)
B(2,23,5,betternether:quartz_stained_glass:15)
B(3,23,5,betternether:quartz_stained_glass:15)
B(4,23,5,betternether:quartz_stained_glass:15)
B(5,23,5,betternether:quartz_stained_glass:15)
B(6,23,5,betternether:quartz_stained_glass:15)
B(7,23,5,betternether:quartz_stained_glass:15)
B(8,23,5,betternether:quartz_stained_glass:15)
B(0,23,6,betternether:quartz_stained_glass:15)
B(1,23,6,betternether:quartz_stained_glass:15)
B(2,23,6,betternether:quartz_stained_glass:15)
B(3,23,6,betternether:quartz_stained_glass:15)
B(4,23,6,betternether:quartz_stained_glass:15)
B(5,23,6,betternether:quartz_stained_glass:15)
B(6,23,6,betternether:quartz_stained_glass:15)
B(7,23,6,betternether:quartz_stained_glass:15)
B(8,23,6,betternether:quartz_stained_glass:15)
B(9,23,6,betternether:quartz_stained_glass:15)
B(1,23,7,betternether:quartz_stained_glass:15)
B(2,23,7,betternether:quartz_stained_glass:15)
B(3,23,7,betternether:quartz_stained_glass:15)
B(4,23,7,betternether:quartz_stained_glass:15)
B(5,23,7,betternether:quartz_stained_glass:15)
B(6,23,7,betternether:quartz_stained_glass:15)
B(7,23,7,betternether:quartz_stained_glass:15)
B(8,23,7,betternether:quartz_stained_glass:15)
B(9,23,7,betternether:quartz_stained_glass:15)
B(1,23,8,betternether:quartz_stained_glass:15)
B(2,23,8,betternether:quartz_stained_glass:15)
B(3,23,8,betternether:quartz_stained_glass:15)
B(4,23,8,betternether:quartz_stained_glass:15)
RB(5,23,8,srparasites:parasitestain:1,80,quark:crystal:1,30,srparasites:parasiterubbledense:1,100)
RB(6,23,8,srparasites:parasitestain:1,80,quark:crystal:1,30,srparasites:parasiterubbledense:1,100)
B(7,23,8,betternether:quartz_stained_glass:15)
B(8,23,8,betternether:quartz_stained_glass:15)
B(9,23,8,betternether:quartz_stained_glass:15)
B(10,23,8,betternether:quartz_stained_glass:15)
B(1,23,9,betternether:quartz_stained_glass:15)
B(2,23,9,betternether:quartz_stained_glass:15)
B(3,23,9,betternether:quartz_stained_glass:15)
B(4,23,9,betternether:quartz_stained_glass:15)
RB(5,23,9,srparasites:parasitestain:1,80,quark:crystal:1,30,srparasites:parasiterubbledense:1,100)
RB(6,23,9,srparasites:parasitestain:1,80,quark:crystal:1,30,srparasites:parasiterubbledense:1,100)
B(7,23,9,betternether:quartz_stained_glass:15)
B(8,23,9,betternether:quartz_stained_glass:15)
B(9,23,9,betternether:quartz_stained_glass:15)
B(10,23,9,betternether:quartz_stained_glass:15)
B(2,23,10,betternether:quartz_stained_glass:15)
B(3,23,10,betternether:quartz_stained_glass:15)
B(4,23,10,betternether:quartz_stained_glass:15)
B(5,23,10,srparasites:parasiterubbledense:1)
B(6,23,10,betternether:quartz_stained_glass:15)
B(7,23,10,betternether:quartz_stained_glass:15)
B(8,23,10,betternether:quartz_stained_glass:15)
B(9,23,10,betternether:quartz_stained_glass:15)
B(10,23,10,betternether:quartz_stained_glass:15)
B(2,23,11,betternether:quartz_stained_glass:15)
B(3,23,11,betternether:quartz_stained_glass:15)
B(4,23,11,betternether:quartz_stained_glass:15)
B(5,23,11,srparasites:parasiterubbledense:1)
B(6,23,11,srparasites:parasiterubbledense:1)
B(7,23,11,betternether:quartz_stained_glass:15)
B(8,23,11,betternether:quartz_stained_glass:15)
B(9,23,11,betternether:quartz_stained_glass:15)
B(2,23,12,betternether:quartz_stained_glass:15)
B(3,23,12,betternether:quartz_stained_glass:15)
B(4,23,12,betternether:quartz_stained_glass:15)
B(5,23,12,betternether:quartz_stained_glass:15)
B(6,23,12,betternether:quartz_stained_glass:15)
B(7,23,12,betternether:quartz_stained_glass:15)
B(8,23,12,betternether:quartz_stained_glass:15)
B(9,23,12,betternether:quartz_stained_glass:15)
B(4,23,13,betternether:quartz_stained_glass:15)
B(5,23,13,betternether:quartz_stained_glass:15)
B(6,23,13,betternether:quartz_stained_glass:15)
B(6,24,2,betternether:quartz_stained_glass:15)
B(3,24,3,betternether:quartz_stained_glass:15)
B(4,24,3,betternether:quartz_stained_glass:15)
B(5,24,3,betternether:quartz_stained_glass:15)
B(6,24,3,betternether:quartz_stained_glass:15)
B(7,24,3,betternether:quartz_stained_glass:15)
B(2,24,4,betternether:quartz_stained_glass:15)
B(3,24,4,betternether:quartz_stained_glass:15)
B(4,24,4,betternether:quartz_stained_glass:15)
B(5,24,4,betternether:quartz_stained_glass:15)
B(6,24,4,betternether:quartz_stained_glass:15)
B(7,24,4,betternether:quartz_stained_glass:15)
B(8,24,4,betternether:quartz_stained_glass:15)
B(0,24,5,betternether:quartz_stained_glass:15)
B(1,24,5,betternether:quartz_stained_glass:15)
B(2,24,5,betternether:quartz_stained_glass:15)
B(3,24,5,betternether:quartz_stained_glass:15)
B(4,24,5,betternether:quartz_stained_glass:15)
B(5,24,5,betternether:quartz_stained_glass:15)
B(6,24,5,betternether:quartz_stained_glass:15)
B(7,24,5,betternether:quartz_stained_glass:15)
B(8,24,5,betternether:quartz_stained_glass:15)
B(0,24,6,betternether:quartz_stained_glass:15)
B(1,24,6,betternether:quartz_stained_glass:15)
B(2,24,6,betternether:quartz_stained_glass:15)
B(3,24,6,betternether:quartz_stained_glass:15)
B(4,24,6,betternether:quartz_stained_glass:15)
B(5,24,6,betternether:quartz_stained_glass:15)
B(6,24,6,betternether:quartz_stained_glass:15)
B(7,24,6,betternether:quartz_stained_glass:15)
B(8,24,6,betternether:quartz_stained_glass:15)
B(9,24,6,betternether:quartz_stained_glass:15)
B(1,24,7,betternether:quartz_stained_glass:15)
B(2,24,7,betternether:quartz_stained_glass:15)
B(3,24,7,betternether:quartz_stained_glass:15)
B(4,24,7,betternether:quartz_stained_glass:15)
RB(5,24,7,srparasites:parasitestain:1,80,quark:crystal:1,30,srparasites:parasiterubbledense:1,100)
B(6,24,7,betternether:quartz_stained_glass:15)
B(7,24,7,betternether:quartz_stained_glass:15)
B(8,24,7,betternether:quartz_stained_glass:15)
B(9,24,7,betternether:quartz_stained_glass:15)
B(0,24,8,betternether:quartz_stained_glass:15)
B(1,24,8,betternether:quartz_stained_glass:15)
B(2,24,8,betternether:quartz_stained_glass:15)
B(3,24,8,betternether:quartz_stained_glass:15)
B(4,24,8,betternether:quartz_stained_glass:15)
RB(5,24,8,srparasites:parasitestain:1,80,quark:crystal:1,30,srparasites:parasiterubbledense:1,100)
RB(6,24,8,srparasites:parasitestain:1,80,quark:crystal:1,30,srparasites:parasiterubbledense:1,100)
B(7,24,8,betternether:quartz_stained_glass:15)
B(8,24,8,betternether:quartz_stained_glass:15)
B(9,24,8,betternether:quartz_stained_glass:15)
B(10,24,8,betternether:quartz_stained_glass:15)
B(1,24,9,betternether:quartz_stained_glass:15)
B(2,24,9,betternether:quartz_stained_glass:15)
B(3,24,9,betternether:quartz_stained_glass:15)
B(4,24,9,betternether:quartz_stained_glass:15)
B(5,24,9,srparasites:parasiterubbledense:1)
B(6,24,9,betternether:quartz_stained_glass:15)
B(7,24,9,betternether:quartz_stained_glass:15)
B(8,24,9,betternether:quartz_stained_glass:15)
B(9,24,9,betternether:quartz_stained_glass:15)
B(10,24,9,betternether:quartz_stained_glass:15)
B(2,24,10,betternether:quartz_stained_glass:15)
B(3,24,10,betternether:quartz_stained_glass:15)
B(4,24,10,srparasites:parasiterubbledense:1)
B(5,24,10,srparasites:parasiterubbledense:1)
B(6,24,10,srparasites:parasiterubbledense:1)
B(7,24,10,betternether:quartz_stained_glass:15)
B(8,24,10,betternether:quartz_stained_glass:15)
B(9,24,10,betternether:quartz_stained_glass:15)
B(2,24,11,betternether:quartz_stained_glass:15)
B(3,24,11,betternether:quartz_stained_glass:15)
B(4,24,11,betternether:quartz_stained_glass:15)
B(5,24,11,srparasites:parasiterubbledense:1)
B(6,24,11,betternether:quartz_stained_glass:15)
B(7,24,11,betternether:quartz_stained_glass:15)
B(8,24,11,betternether:quartz_stained_glass:15)
B(2,24,12,betternether:quartz_stained_glass:15)
B(3,24,12,betternether:quartz_stained_glass:15)
B(4,24,12,betternether:quartz_stained_glass:15)
B(5,24,12,betternether:quartz_stained_glass:15)
B(6,24,12,betternether:quartz_stained_glass:15)
B(8,24,12,betternether:quartz_stained_glass:15)
B(6,25,1,betternether:quartz_stained_glass:15)
B(5,25,2,betternether:quartz_stained_glass:15)
B(6,25,2,betternether:quartz_stained_glass:15)
B(2,25,3,betternether:quartz_stained_glass:15)
B(3,25,3,betternether:quartz_stained_glass:15)
B(4,25,3,betternether:quartz_stained_glass:15)
B(5,25,3,betternether:quartz_stained_glass:15)
B(6,25,3,betternether:quartz_stained_glass:15)
B(7,25,3,betternether:quartz_stained_glass:15)
B(0,25,4,betternether:quartz_stained_glass:15)
B(1,25,4,betternether:quartz_stained_glass:15)
B(2,25,4,betternether:quartz_stained_glass:15)
B(3,25,4,betternether:quartz_stained_glass:15)
B(4,25,4,betternether:quartz_stained_glass:15)
B(5,25,4,betternether:quartz_stained_glass:15)
B(6,25,4,betternether:quartz_stained_glass:15)
B(7,25,4,betternether:quartz_stained_glass:15)
B(8,25,4,betternether:quartz_stained_glass:15)
B(0,25,5,betternether:quartz_stained_glass:15)
B(1,25,5,betternether:quartz_stained_glass:15)
B(2,25,5,betternether:quartz_stained_glass:15)
B(3,25,5,betternether:quartz_stained_glass:15)
B(4,25,5,betternether:quartz_stained_glass:15)
B(5,25,5,betternether:quartz_stained_glass:15)
B(6,25,5,betternether:quartz_stained_glass:15)
B(7,25,5,betternether:quartz_stained_glass:15)
B(8,25,5,betternether:quartz_stained_glass:15)
B(0,25,6,betternether:quartz_stained_glass:15)
B(1,25,6,betternether:quartz_stained_glass:15)
B(2,25,6,betternether:quartz_stained_glass:15)
B(3,25,6,betternether:quartz_stained_glass:15)
B(4,25,6,betternether:quartz_stained_glass:15)
RB(5,25,6,srparasites:parasitestain:1,80,quark:crystal:1,30,srparasites:parasiterubbledense:1,100)
B(6,25,6,betternether:quartz_stained_glass:15)
B(7,25,6,betternether:quartz_stained_glass:15)
B(8,25,6,betternether:quartz_stained_glass:15)
B(9,25,6,betternether:quartz_stained_glass:15)
B(1,25,7,betternether:quartz_stained_glass:15)
B(2,25,7,betternether:quartz_stained_glass:15)
B(3,25,7,betternether:quartz_stained_glass:15)
RB(4,25,7,srparasites:parasitestain:1,80,quark:crystal:1,30,srparasites:parasiterubbledense:1,100)
RB(5,25,7,srparasites:parasitestain:1,80,quark:crystal:1,30,srparasites:parasiterubbledense:1,100)
B(6,25,7,betternether:quartz_stained_glass:15)
B(7,25,7,betternether:quartz_stained_glass:15)
B(8,25,7,betternether:quartz_stained_glass:15)
B(9,25,7,betternether:quartz_stained_glass:15)
B(0,25,8,betternether:quartz_stained_glass:15)
B(1,25,8,betternether:quartz_stained_glass:15)
B(2,25,8,betternether:quartz_stained_glass:15)
B(3,25,8,betternether:quartz_stained_glass:15)
B(4,25,8,betternether:quartz_stained_glass:15)
RB(5,25,8,srparasites:parasitestain:1,80,quark:crystal:1,30,srparasites:parasiterubbledense:1,100)
RB(6,25,8,srparasites:parasitestain:1,80,quark:crystal:1,30,srparasites:parasiterubbledense:1,100)
B(7,25,8,betternether:quartz_stained_glass:15)
B(8,25,8,betternether:quartz_stained_glass:15)
B(9,25,8,betternether:quartz_stained_glass:15)
B(1,25,9,betternether:quartz_stained_glass:15)
B(2,25,9,betternether:quartz_stained_glass:15)
B(3,25,9,betternether:quartz_stained_glass:15)
B(4,25,9,srparasites:parasiterubbledense:1)
B(5,25,9,srparasites:parasiterubbledense:1)
B(6,25,9,betternether:quartz_stained_glass:15)
B(7,25,9,betternether:quartz_stained_glass:15)
B(8,25,9,betternether:quartz_stained_glass:15)
B(9,25,9,betternether:quartz_stained_glass:15)
B(10,25,9,betternether:quartz_stained_glass:15)
B(2,25,10,betternether:quartz_stained_glass:15)
B(3,25,10,betternether:quartz_stained_glass:15)
B(4,25,10,srparasites:parasiterubbledense:1)
B(5,25,10,betternether:quartz_stained_glass:15)
B(6,25,10,betternether:quartz_stained_glass:15)
B(7,25,10,betternether:quartz_stained_glass:15)
B(8,25,10,betternether:quartz_stained_glass:15)
B(2,25,11,betternether:quartz_stained_glass:15)
B(3,25,11,betternether:quartz_stained_glass:15)
B(4,25,11,betternether:quartz_stained_glass:15)
B(5,25,11,betternether:quartz_stained_glass:15)
B(6,25,11,betternether:quartz_stained_glass:15)
B(7,25,11,betternether:quartz_stained_glass:15)
B(8,25,11,betternether:quartz_stained_glass:15)
B(3,25,12,betternether:quartz_stained_glass:15)
B(5,25,12,betternether:quartz_stained_glass:15)
B(5,26,1,betternether:quartz_stained_glass:15)
B(6,26,1,betternether:quartz_stained_glass:15)
B(3,26,2,betternether:quartz_stained_glass:15)
B(4,26,2,betternether:quartz_stained_glass:15)
B(5,26,2,betternether:quartz_stained_glass:15)
B(6,26,2,betternether:quartz_stained_glass:15)
B(0,26,3,betternether:quartz_stained_glass:15)
B(1,26,3,betternether:quartz_stained_glass:15)
B(2,26,3,betternether:quartz_stained_glass:15)
B(3,26,3,betternether:quartz_stained_glass:15)
B(4,26,3,betternether:quartz_stained_glass:15)
B(5,26,3,betternether:quartz_stained_glass:15)
B(6,26,3,betternether:quartz_stained_glass:15)
B(7,26,3,betternether:quartz_stained_glass:15)
B(8,26,3,betternether:quartz_stained_glass:15)
B(0,26,4,betternether:quartz_stained_glass:15)
B(1,26,4,betternether:quartz_stained_glass:15)
B(2,26,4,betternether:quartz_stained_glass:15)
B(3,26,4,betternether:quartz_stained_glass:15)
B(4,26,4,betternether:quartz_stained_glass:15)
B(5,26,4,betternether:quartz_stained_glass:15)
B(6,26,4,betternether:quartz_stained_glass:15)
B(7,26,4,betternether:quartz_stained_glass:15)
B(8,26,4,betternether:quartz_stained_glass:15)
B(0,26,5,betternether:quartz_stained_glass:15)
B(1,26,5,betternether:quartz_stained_glass:15)
B(2,26,5,betternether:quartz_stained_glass:15)
B(3,26,5,betternether:quartz_stained_glass:15)
B(4,26,5,betternether:quartz_stained_glass:15)
B(5,26,5,betternether:quartz_stained_glass:15)
B(6,26,5,betternether:quartz_stained_glass:15)
B(7,26,5,betternether:quartz_stained_glass:15)
B(8,26,5,betternether:quartz_stained_glass:15)
B(0,26,6,betternether:quartz_stained_glass:15)
B(1,26,6,betternether:quartz_stained_glass:15)
B(2,26,6,betternether:quartz_stained_glass:15)
B(3,26,6,betternether:quartz_stained_glass:15)
RB(4,26,6,srparasites:parasitestain:1,80,quark:crystal:1,30,srparasites:parasiterubbledense:1,100)
RB(5,26,6,srparasites:parasitestain:1,80,quark:crystal:1,30,srparasites:parasiterubbledense:1,100)
B(6,26,6,betternether:quartz_stained_glass:15)
B(7,26,6,betternether:quartz_stained_glass:15)
B(8,26,6,betternether:quartz_stained_glass:15)
B(9,26,6,betternether:quartz_stained_glass:15)
B(0,26,7,betternether:quartz_stained_glass:15)
B(1,26,7,betternether:quartz_stained_glass:15)
B(2,26,7,betternether:quartz_stained_glass:15)
B(3,26,7,betternether:quartz_stained_glass:15)
RB(4,26,7,srparasites:parasitestain:1,80,quark:crystal:1,30,srparasites:parasiterubbledense:1,100)
RB(5,26,7,srparasites:parasitestain:1,80,quark:crystal:1,30,srparasites:parasiterubbledense:1,100)
B(6,26,7,betternether:quartz_stained_glass:15)
B(7,26,7,betternether:quartz_stained_glass:15)
B(8,26,7,betternether:quartz_stained_glass:15)
B(9,26,7,betternether:quartz_stained_glass:15)
B(0,26,8,betternether:quartz_stained_glass:15)
B(1,26,8,betternether:quartz_stained_glass:15)
B(2,26,8,betternether:quartz_stained_glass:15)
B(3,26,8,betternether:quartz_stained_glass:15)
B(4,26,8,betternether:quartz_stained_glass:15)
B(5,26,8,srparasites:parasiterubbledense:1)
B(6,26,8,betternether:quartz_stained_glass:15)
B(7,26,8,betternether:quartz_stained_glass:15)
B(8,26,8,betternether:quartz_stained_glass:15)
B(9,26,8,betternether:quartz_stained_glass:15)
B(1,26,9,betternether:quartz_stained_glass:15)
B(2,26,9,betternether:quartz_stained_glass:15)
B(3,26,9,srparasites:parasiterubbledense:1)
B(4,26,9,srparasites:parasiterubbledense:1)
B(5,26,9,betternether:quartz_stained_glass:15)
B(6,26,9,betternether:quartz_stained_glass:15)
B(7,26,9,betternether:quartz_stained_glass:15)
B(8,26,9,betternether:quartz_stained_glass:15)
B(9,26,9,betternether:quartz_stained_glass:15)
B(2,26,10,betternether:quartz_stained_glass:15)
B(3,26,10,betternether:quartz_stained_glass:15)
B(4,26,10,betternether:quartz_stained_glass:15)
B(5,26,10,betternether:quartz_stained_glass:15)
B(6,26,10,betternether:quartz_stained_glass:15)
B(7,26,10,betternether:quartz_stained_glass:15)
B(2,26,11,betternether:quartz_stained_glass:15)
B(3,26,11,betternether:quartz_stained_glass:15)
B(4,26,11,betternether:quartz_stained_glass:15)
B(5,26,11,betternether:quartz_stained_glass:15)
B(6,26,11,betternether:quartz_stained_glass:15)
B(5,27,1,betternether:quartz_stained_glass:15)
B(6,27,1,betternether:quartz_stained_glass:15)
B(3,27,2,betternether:quartz_stained_glass:15)
B(4,27,2,betternether:quartz_stained_glass:15)
B(5,27,2,betternether:quartz_stained_glass:15)
B(6,27,2,betternether:quartz_stained_glass:15)
B(0,27,3,betternether:quartz_stained_glass:15)
B(1,27,3,betternether:quartz_stained_glass:15)
B(2,27,3,betternether:quartz_stained_glass:15)
B(3,27,3,betternether:quartz_stained_glass:15)
B(4,27,3,betternether:quartz_stained_glass:15)
B(5,27,3,betternether:quartz_stained_glass:15)
B(6,27,3,betternether:quartz_stained_glass:15)
B(7,27,3,betternether:quartz_stained_glass:15)
B(8,27,3,betternether:quartz_stained_glass:15)
B(0,27,4,betternether:quartz_stained_glass:15)
B(1,27,4,betternether:quartz_stained_glass:15)
B(2,27,4,betternether:quartz_stained_glass:15)
B(3,27,4,betternether:quartz_stained_glass:15)
B(4,27,4,betternether:quartz_stained_glass:15)
B(5,27,4,betternether:quartz_stained_glass:15)
B(6,27,4,betternether:quartz_stained_glass:15)
B(7,27,4,betternether:quartz_stained_glass:15)
B(8,27,4,betternether:quartz_stained_glass:15)
B(0,27,5,betternether:quartz_stained_glass:15)
B(1,27,5,betternether:quartz_stained_glass:15)
B(2,27,5,betternether:quartz_stained_glass:15)
B(3,27,5,betternether:quartz_stained_glass:15)
B(4,27,5,betternether:quartz_stained_glass:15)
RB(5,27,5,srparasites:parasitestain:1,80,quark:crystal:1,30,srparasites:parasiterubbledense:1,100)
B(6,27,5,betternether:quartz_stained_glass:15)
B(7,27,5,betternether:quartz_stained_glass:15)
B(8,27,5,betternether:quartz_stained_glass:15)
B(0,27,6,betternether:quartz_stained_glass:15)
B(1,27,6,betternether:quartz_stained_glass:15)
B(2,27,6,betternether:quartz_stained_glass:15)
RB(3,27,6,srparasites:parasitestain:1,80,quark:crystal:1,30,srparasites:parasiterubbledense:1,100)
RB(4,27,6,srparasites:parasitestain:1,80,quark:crystal:1,30,srparasites:parasiterubbledense:1,100)
RB(5,27,6,srparasites:parasitestain:1,80,quark:crystal:1,30,srparasites:parasiterubbledense:1,100)
B(6,27,6,betternether:quartz_stained_glass:15)
B(7,27,6,betternether:quartz_stained_glass:15)
B(8,27,6,betternether:quartz_stained_glass:15)
B(9,27,6,betternether:quartz_stained_glass:15)
B(0,27,7,betternether:quartz_stained_glass:15)
B(1,27,7,betternether:quartz_stained_glass:15)
B(2,27,7,betternether:quartz_stained_glass:15)
B(3,27,7,betternether:quartz_stained_glass:15)
RB(4,27,7,srparasites:parasitestain:1,80,quark:crystal:1,30,srparasites:parasiterubbledense:1,100)
B(5,27,7,betternether:quartz_stained_glass:15)
B(6,27,7,betternether:quartz_stained_glass:15)
B(7,27,7,betternether:quartz_stained_glass:15)
B(8,27,7,betternether:quartz_stained_glass:15)
B(0,27,8,betternether:quartz_stained_glass:15)
B(1,27,8,betternether:quartz_stained_glass:15)
B(2,27,8,betternether:quartz_stained_glass:15)
B(3,27,8,betternether:quartz_stained_glass:15)
B(4,27,8,betternether:quartz_stained_glass:15)
B(5,27,8,srparasites:parasiterubbledense:1)
B(6,27,8,betternether:quartz_stained_glass:15)
B(7,27,8,betternether:quartz_stained_glass:15)
B(8,27,8,betternether:quartz_stained_glass:15)
B(9,27,8,betternether:quartz_stained_glass:15)
B(1,27,9,betternether:quartz_stained_glass:15)
B(2,27,9,betternether:quartz_stained_glass:15)
B(3,27,9,srparasites:parasiterubbledense:1)
B(4,27,9,betternether:quartz_stained_glass:15)
B(5,27,9,betternether:quartz_stained_glass:15)
B(6,27,9,betternether:quartz_stained_glass:15)
B(7,27,9,betternether:quartz_stained_glass:15)
B(8,27,9,betternether:quartz_stained_glass:15)
B(3,27,10,betternether:quartz_stained_glass:15)
B(4,27,10,betternether:quartz_stained_glass:15)
B(5,27,10,betternether:quartz_stained_glass:15)
B(6,27,10,betternether:quartz_stained_glass:15)
B(2,27,11,betternether:quartz_stained_glass:15)
B(3,27,11,betternether:quartz_stained_glass:15)
B(5,27,11,betternether:quartz_stained_glass:15)
B(3,28,1,betternether:quartz_stained_glass:15)
B(4,28,1,betternether:quartz_stained_glass:15)
B(5,28,1,betternether:quartz_stained_glass:15)
B(6,28,1,betternether:quartz_stained_glass:15)
B(0,28,2,betternether:quartz_stained_glass:15)
B(2,28,2,betternether:quartz_stained_glass:15)
B(3,28,2,betternether:quartz_stained_glass:15)
B(4,28,2,betternether:quartz_stained_glass:15)
B(5,28,2,betternether:quartz_stained_glass:15)
B(6,28,2,betternether:quartz_stained_glass:15)
B(0,28,3,betternether:quartz_stained_glass:15)
B(1,28,3,betternether:quartz_stained_glass:15)
B(2,28,3,betternether:quartz_stained_glass:15)
B(3,28,3,betternether:quartz_stained_glass:15)
B(4,28,3,betternether:quartz_stained_glass:15)
B(5,28,3,betternether:quartz_stained_glass:15)
B(6,28,3,betternether:quartz_stained_glass:15)
B(7,28,3,betternether:quartz_stained_glass:15)
B(0,28,4,betternether:quartz_stained_glass:15)
B(1,28,4,betternether:quartz_stained_glass:15)
B(2,28,4,betternether:quartz_stained_glass:15)
B(3,28,4,betternether:quartz_stained_glass:15)
B(4,28,4,betternether:quartz_stained_glass:15)
B(5,28,4,betternether:quartz_stained_glass:15)
B(6,28,4,betternether:quartz_stained_glass:15)
B(7,28,4,betternether:quartz_stained_glass:15)
B(0,28,5,betternether:quartz_stained_glass:15)
B(1,28,5,betternether:quartz_stained_glass:15)
B(2,28,5,betternether:quartz_stained_glass:15)
B(3,28,5,betternether:quartz_stained_glass:15)
RB(4,28,5,srparasites:parasitestain:1,80,quark:crystal:1,30,srparasites:parasiterubbledense:1,100)
RB(5,28,5,srparasites:parasitestain:1,80,quark:crystal:1,30,srparasites:parasiterubbledense:1,100)
B(6,28,5,betternether:quartz_stained_glass:15)
B(7,28,5,betternether:quartz_stained_glass:15)
B(8,28,5,betternether:quartz_stained_glass:15)
B(0,28,6,betternether:quartz_stained_glass:15)
B(1,28,6,betternether:quartz_stained_glass:15)
B(2,28,6,betternether:quartz_stained_glass:15)
RB(3,28,6,srparasites:parasitestain:1,80,quark:crystal:1,30,srparasites:parasiterubbledense:1,100)
RB(4,28,6,srparasites:parasitestain:1,80,quark:crystal:1,30,srparasites:parasiterubbledense:1,100)
B(5,28,6,betternether:quartz_stained_glass:15)
B(6,28,6,betternether:quartz_stained_glass:15)
B(7,28,6,betternether:quartz_stained_glass:15)
B(8,28,6,betternether:quartz_stained_glass:15)
B(1,28,7,betternether:quartz_stained_glass:15)
B(2,28,7,betternether:quartz_stained_glass:15)
B(3,28,7,betternether:quartz_stained_glass:15)
B(4,28,7,betternether:quartz_stained_glass:15)
B(5,28,7,betternether:quartz_stained_glass:15)
B(6,28,7,betternether:quartz_stained_glass:15)
B(7,28,7,betternether:quartz_stained_glass:15)
B(8,28,7,betternether:quartz_stained_glass:15)
B(1,28,8,betternether:quartz_stained_glass:15)
B(2,28,8,betternether:quartz_stained_glass:15)
B(3,28,8,betternether:quartz_stained_glass:15)
B(4,28,8,betternether:quartz_stained_glass:15)
B(5,28,8,betternether:quartz_stained_glass:15)
B(6,28,8,betternether:quartz_stained_glass:15)
B(7,28,8,betternether:quartz_stained_glass:15)
B(2,28,9,betternether:quartz_stained_glass:15)
B(3,28,9,betternether:quartz_stained_glass:15)
B(4,28,9,betternether:quartz_stained_glass:15)
B(5,28,9,betternether:quartz_stained_glass:15)
B(6,28,9,betternether:quartz_stained_glass:15)
B(3,28,10,betternether:quartz_stained_glass:15)
B(3,29,1,betternether:quartz_stained_glass:15)
B(4,29,1,betternether:quartz_stained_glass:15)
B(5,29,1,betternether:quartz_stained_glass:15)
B(0,29,2,betternether:quartz_stained_glass:15)
B(2,29,2,betternether:quartz_stained_glass:15)
B(3,29,2,betternether:quartz_stained_glass:15)
B(4,29,2,betternether:quartz_stained_glass:15)
B(5,29,2,betternether:quartz_stained_glass:15)
B(6,29,2,betternether:quartz_stained_glass:15)
B(0,29,3,betternether:quartz_stained_glass:15)
B(1,29,3,betternether:quartz_stained_glass:15)
B(2,29,3,betternether:quartz_stained_glass:15)
B(3,29,3,betternether:quartz_stained_glass:15)
B(4,29,3,betternether:quartz_stained_glass:15)
B(5,29,3,betternether:quartz_stained_glass:15)
B(6,29,3,betternether:quartz_stained_glass:15)
B(1,29,4,betternether:quartz_stained_glass:15)
B(2,29,4,betternether:quartz_stained_glass:15)
B(3,29,4,betternether:quartz_stained_glass:15)
B(4,29,4,betternether:quartz_stained_glass:15)
B(5,29,4,betternether:quartz_stained_glass:15)
B(6,29,4,betternether:quartz_stained_glass:15)
B(1,29,5,betternether:quartz_stained_glass:15)
B(2,29,5,betternether:quartz_stained_glass:15)
B(3,29,5,betternether:quartz_stained_glass:15)
RB(4,29,5,srparasites:parasitestain:1,80,quark:crystal:1,30,srparasites:parasiterubbledense:1,100)
B(5,29,5,betternether:quartz_stained_glass:15)
B(6,29,5,betternether:quartz_stained_glass:15)
B(7,29,5,betternether:quartz_stained_glass:15)
B(1,29,6,betternether:quartz_stained_glass:15)
B(2,29,6,betternether:quartz_stained_glass:15)
B(3,29,6,betternether:quartz_stained_glass:15)
B(4,29,6,betternether:quartz_stained_glass:15)
B(5,29,6,betternether:quartz_stained_glass:15)
B(6,29,6,betternether:quartz_stained_glass:15)
B(7,29,6,betternether:quartz_stained_glass:15)
B(8,29,6,betternether:quartz_stained_glass:15)
B(2,29,7,betternether:quartz_stained_glass:15)
B(3,29,7,betternether:quartz_stained_glass:15)
B(4,29,7,betternether:quartz_stained_glass:15)
B(5,29,7,betternether:quartz_stained_glass:15)
B(6,29,7,betternether:quartz_stained_glass:15)
B(7,29,7,betternether:quartz_stained_glass:15)
B(3,29,8,betternether:quartz_stained_glass:15)
B(4,29,8,betternether:quartz_stained_glass:15)
B(5,29,8,betternether:quartz_stained_glass:15)
B(6,29,8,betternether:quartz_stained_glass:15)
B(7,29,8,betternether:quartz_stained_glass:15)
B(3,29,9,betternether:quartz_stained_glass:15)
B(4,29,9,betternether:quartz_stained_glass:15)
B(3,30,0,betternether:quartz_stained_glass:15)
B(2,30,1,betternether:quartz_stained_glass:15)
B(3,30,1,betternether:quartz_stained_glass:15)
B(4,30,1,betternether:quartz_stained_glass:15)
B(5,30,1,betternether:quartz_stained_glass:15)
B(0,30,2,betternether:quartz_stained_glass:15)
B(1,30,2,betternether:quartz_stained_glass:15)
B(2,30,2,betternether:quartz_stained_glass:15)
B(3,30,2,betternether:quartz_stained_glass:15)
B(4,30,2,betternether:quartz_stained_glass:15)
B(5,30,2,betternether:quartz_stained_glass:15)
B(6,30,2,betternether:quartz_stained_glass:15)
B(0,30,3,betternether:quartz_stained_glass:15)
B(1,30,3,betternether:quartz_stained_glass:15)
B(2,30,3,betternether:quartz_stained_glass:15)
B(3,30,3,betternether:quartz_stained_glass:15)
B(4,30,3,betternether:quartz_stained_glass:15)
B(5,30,3,betternether:quartz_stained_glass:15)
B(6,30,3,betternether:quartz_stained_glass:15)
B(1,30,4,betternether:quartz_stained_glass:15)
B(2,30,4,betternether:quartz_stained_glass:15)
B(3,30,4,betternether:quartz_stained_glass:15)
B(4,30,4,betternether:quartz_stained_glass:15)
B(5,30,4,betternether:quartz_stained_glass:15)
B(6,30,4,betternether:quartz_stained_glass:15)
B(1,30,5,betternether:quartz_stained_glass:15)
B(2,30,5,betternether:quartz_stained_glass:15)
B(3,30,5,betternether:quartz_stained_glass:15)
B(4,30,5,betternether:quartz_stained_glass:15)
B(5,30,5,betternether:quartz_stained_glass:15)
B(6,30,5,betternether:quartz_stained_glass:15)
B(7,30,5,betternether:quartz_stained_glass:15)
B(1,30,6,betternether:quartz_stained_glass:15)
B(2,30,6,betternether:quartz_stained_glass:15)
B(3,30,6,betternether:quartz_stained_glass:15)
RB(4,30,6,srparasites:parasitestain:1,80,quark:crystal:1,30,srparasites:parasiterubbledense:1,100)
B(5,30,6,betternether:quartz_stained_glass:15)
B(6,30,6,betternether:quartz_stained_glass:15)
B(7,30,6,betternether:quartz_stained_glass:15)
B(2,30,7,betternether:quartz_stained_glass:15)
B(3,30,7,betternether:quartz_stained_glass:15)
B(4,30,7,betternether:quartz_stained_glass:15)
B(5,30,7,betternether:quartz_stained_glass:15)
B(6,30,7,betternether:quartz_stained_glass:15)
B(3,30,8,betternether:quartz_stained_glass:15)
B(4,30,8,betternether:quartz_stained_glass:15)
B(5,30,8,betternether:quartz_stained_glass:15)
B(6,30,8,betternether:quartz_stained_glass:15)
B(3,31,0,betternether:quartz_stained_glass:15)
B(2,31,1,betternether:quartz_stained_glass:15)
B(3,31,1,betternether:quartz_stained_glass:15)
B(4,31,1,betternether:quartz_stained_glass:15)
B(0,31,2,betternether:quartz_stained_glass:15)
B(1,31,2,betternether:quartz_stained_glass:15)
B(2,31,2,betternether:quartz_stained_glass:15)
B(3,31,2,betternether:quartz_stained_glass:15)
B(4,31,2,betternether:quartz_stained_glass:15)
B(5,31,2,betternether:quartz_stained_glass:15)
B(1,31,3,betternether:quartz_stained_glass:15)
B(2,31,3,betternether:quartz_stained_glass:15)
B(3,31,3,betternether:quartz_stained_glass:15)
B(4,31,3,betternether:quartz_stained_glass:15)
B(5,31,3,betternether:quartz_stained_glass:15)
B(1,31,4,betternether:quartz_stained_glass:15)
B(2,31,4,betternether:quartz_stained_glass:15)
B(3,31,4,betternether:quartz_stained_glass:15)
B(4,31,4,betternether:quartz_stained_glass:15)
B(5,31,4,betternether:quartz_stained_glass:15)
B(6,31,4,betternether:quartz_stained_glass:15)
B(1,31,5,betternether:quartz_stained_glass:15)
B(2,31,5,betternether:quartz_stained_glass:15)
B(3,31,5,betternether:quartz_stained_glass:15)
B(4,31,5,betternether:quartz_stained_glass:15)
B(5,31,5,betternether:quartz_stained_glass:15)
B(6,31,5,betternether:quartz_stained_glass:15)
B(2,31,6,betternether:quartz_stained_glass:15)
B(3,31,6,betternether:quartz_stained_glass:15)
B(4,31,6,betternether:quartz_stained_glass:15)
B(5,31,6,betternether:quartz_stained_glass:15)
B(3,31,7,betternether:quartz_stained_glass:15)
B(4,31,7,betternether:quartz_stained_glass:15)
B(5,31,7,betternether:quartz_stained_glass:15)
B(6,31,7,betternether:quartz_stained_glass:15)
B(4,31,8,betternether:quartz_stained_glass:15)
B(3,32,0,betternether:quartz_stained_glass:15)
B(2,32,1,betternether:quartz_stained_glass:15)
B(3,32,1,betternether:quartz_stained_glass:15)
B(4,32,1,betternether:quartz_stained_glass:15)
B(0,32,2,betternether:quartz_stained_glass:15)
B(1,32,2,betternether:quartz_stained_glass:15)
B(2,32,2,betternether:quartz_stained_glass:15)
B(3,32,2,betternether:quartz_stained_glass:15)
B(4,32,2,betternether:quartz_stained_glass:15)
B(5,32,2,betternether:quartz_stained_glass:15)
B(1,32,3,betternether:quartz_stained_glass:15)
B(2,32,3,betternether:quartz_stained_glass:15)
B(3,32,3,betternether:quartz_stained_glass:15)
B(4,32,3,betternether:quartz_stained_glass:15)
B(5,32,3,betternether:quartz_stained_glass:15)
B(1,32,4,betternether:quartz_stained_glass:15)
B(2,32,4,betternether:quartz_stained_glass:15)
B(3,32,4,betternether:quartz_stained_glass:15)
B(4,32,4,betternether:quartz_stained_glass:15)
B(5,32,4,betternether:quartz_stained_glass:15)
B(1,32,5,betternether:quartz_stained_glass:15)
B(2,32,5,betternether:quartz_stained_glass:15)
B(3,32,5,betternether:quartz_stained_glass:15)
B(4,32,5,betternether:quartz_stained_glass:15)
B(5,32,5,betternether:quartz_stained_glass:15)
B(3,32,6,betternether:quartz_stained_glass:15)
B(4,32,6,betternether:quartz_stained_glass:15)
B(5,32,6,betternether:quartz_stained_glass:15)
B(3,32,7,betternether:quartz_stained_glass:15)
B(4,32,7,betternether:quartz_stained_glass:15)
B(2,33,0,betternether:quartz_stained_glass:15)
B(3,33,0,betternether:quartz_stained_glass:15)
B(1,33,1,betternether:quartz_stained_glass:15)
B(2,33,1,betternether:quartz_stained_glass:15)
B(3,33,1,betternether:quartz_stained_glass:15)
B(1,33,2,betternether:quartz_stained_glass:15)
B(2,33,2,betternether:quartz_stained_glass:15)
B(3,33,2,betternether:quartz_stained_glass:15)
B(4,33,2,betternether:quartz_stained_glass:15)
B(1,33,3,betternether:quartz_stained_glass:15)
B(2,33,3,betternether:quartz_stained_glass:15)
B(3,33,3,betternether:quartz_stained_glass:15)
B(4,33,3,betternether:quartz_stained_glass:15)
B(2,33,4,betternether:quartz_stained_glass:15)
B(3,33,4,betternether:quartz_stained_glass:15)
B(4,33,4,betternether:quartz_stained_glass:15)
B(5,33,4,betternether:quartz_stained_glass:15)
B(3,33,5,betternether:quartz_stained_glass:15)
B(4,33,5,betternether:quartz_stained_glass:15)
B(5,33,5,betternether:quartz_stained_glass:15)
B(3,33,6,betternether:quartz_stained_glass:15)
B(2,34,0,betternether:quartz_stained_glass:15)
B(3,34,0,betternether:quartz_stained_glass:15)
B(1,34,1,betternether:quartz_stained_glass:15)
B(2,34,1,betternether:quartz_stained_glass:15)
B(3,34,1,betternether:quartz_stained_glass:15)
B(1,34,2,betternether:quartz_stained_glass:15)
B(2,34,2,betternether:quartz_stained_glass:15)
B(3,34,2,betternether:quartz_stained_glass:15)
B(4,34,2,betternether:quartz_stained_glass:15)
B(1,34,3,betternether:quartz_stained_glass:15)
B(2,34,3,betternether:quartz_stained_glass:15)
B(3,34,3,betternether:quartz_stained_glass:15)
B(4,34,3,betternether:quartz_stained_glass:15)
B(2,34,4,betternether:quartz_stained_glass:15)
B(3,34,4,betternether:quartz_stained_glass:15)
B(4,34,4,betternether:quartz_stained_glass:15)
B(1,35,0,betternether:quartz_stained_glass:15)
B(2,35,0,betternether:quartz_stained_glass:15)
B(1,35,1,betternether:quartz_stained_glass:15)
B(2,35,1,betternether:quartz_stained_glass:15)
B(3,35,1,betternether:quartz_stained_glass:15)
B(2,35,2,betternether:quartz_stained_glass:15)
B(3,35,2,betternether:quartz_stained_glass:15)
B(2,35,3,betternether:quartz_stained_glass:15)
B(1,36,0,betternether:quartz_stained_glass:15)
B(2,36,0,betternether:quartz_stained_glass:15)
B(1,36,1,betternether:quartz_stained_glass:15)
B(2,36,1,betternether:quartz_stained_glass:15)
B(3,36,1,betternether:quartz_stained_glass:15)
B(2,36,2,betternether:quartz_stained_glass:15)
B(3,36,2,betternether:quartz_stained_glass:15)
B(1,37,0,betternether:quartz_stained_glass:15)
B(2,37,1,betternether:quartz_stained_glass:15)

