#######################################################################
# +-----------------------------------------------------------------+ #
# |                            BO3 object                           | #
# +-----------------------------------------------------------------+ #
#######################################################################

Author: Bo3 BulkEdit

Description: Converted Schematic - Modified by Bo3BulkEdit

Version: 3

SettingsMode: WriteDisable

#######################################################################
# +-----------------------------------------------------------------+ #
# |                          Main settings                          | #
# +-----------------------------------------------------------------+ #
#######################################################################

IsOTGPlus: true
Tree: false
Frequency: 1
Rarity: 100.0
RotateRandomly: false
SpawnHeight: randomY
MaxBranchDepth: 10
ExcludedBiomes: All

##############################
# Height Limits for the BO3. #
##############################

MinHeight: 0
MaxHeight: 255

#######################################################################
# +-----------------------------------------------------------------+ #
# |                      Source block settings                      | #
# +-----------------------------------------------------------------+ #
#######################################################################

CanOverride: true
MaxPercentageOutsideSourceBlock: 100
OutsideSourceBlock: placeAnyway

#######################################################################
# +-----------------------------------------------------------------+ #
# |                               OTG+                              | #
# +-----------------------------------------------------------------+ #
#######################################################################

BO3Group: CeilingCrystals:0

#######################################################################
# +-----------------------------------------------------------------+ #
# |                              Blocks                             | #
# +-----------------------------------------------------------------+ #
#######################################################################

B(0,750,0,AIR)
B(15,750,15,AIR)
B(1,-41,7,betternether:quartz_stained_glass:15)
B(2,-41,7,betternether:quartz_stained_glass:15)
B(1,-41,8,betternether:quartz_stained_glass:15)
RB(2,-41,8,srparasites:parasitestain:1,80,quark:crystal:1,30,srparasites:parasiterubbledense:1,100)
B(3,-41,8,betternether:quartz_stained_glass:15)
B(2,-41,9,betternether:quartz_stained_glass:15)
B(3,-41,9,betternether:quartz_stained_glass:15)
B(4,-41,9,betternether:quartz_stained_glass:15)
B(4,-41,10,betternether:quartz_stained_glass:15)
B(1,-40,5,betternether:quartz_stained_glass:15)
B(0,-40,6,betternether:quartz_stained_glass:15)
B(1,-40,6,betternether:quartz_stained_glass:15)
B(2,-40,6,betternether:quartz_stained_glass:15)
B(0,-40,7,betternether:quartz_stained_glass:15)
RB(1,-40,7,srparasites:parasitestain:1,80,quark:crystal:1,30,srparasites:parasiterubbledense:1,100)
B(2,-40,7,betternether:quartz_stained_glass:15)
B(3,-40,7,betternether:quartz_stained_glass:15)
B(0,-40,8,betternether:quartz_stained_glass:15)
B(1,-40,8,betternether:quartz_stained_glass:15)
RB(2,-40,8,srparasites:parasitestain:1,80,quark:crystal:1,30,srparasites:parasiterubbledense:1,100)
B(3,-40,8,betternether:quartz_stained_glass:15)
B(1,-40,9,betternether:quartz_stained_glass:15)
B(2,-40,9,betternether:quartz_stained_glass:15)
B(3,-40,9,betternether:quartz_stained_glass:15)
B(4,-40,9,betternether:quartz_stained_glass:15)
B(2,-40,10,betternether:quartz_stained_glass:15)
B(3,-40,10,betternether:quartz_stained_glass:15)
B(1,-39,4,betternether:quartz_stained_glass:15)
B(2,-39,4,betternether:quartz_stained_glass:15)
B(0,-39,5,betternether:quartz_stained_glass:15)
B(1,-39,5,betternether:quartz_stained_glass:15)
B(2,-39,5,betternether:quartz_stained_glass:15)
B(0,-39,6,betternether:quartz_stained_glass:15)
B(1,-39,6,betternether:quartz_stained_glass:15)
B(2,-39,6,betternether:quartz_stained_glass:15)
RB(0,-39,7,srparasites:parasitestain:1,80,quark:crystal:1,30,srparasites:parasiterubbledense:1,100)
RB(1,-39,7,srparasites:parasitestain:1,80,quark:crystal:1,30,srparasites:parasiterubbledense:1,100)
B(2,-39,7,betternether:quartz_stained_glass:15)
B(3,-39,7,betternether:quartz_stained_glass:15)
RB(0,-39,8,srparasites:parasitestain:1,80,quark:crystal:1,30,srparasites:parasiterubbledense:1,100)
RB(1,-39,8,srparasites:parasitestain:1,80,quark:crystal:1,30,srparasites:parasiterubbledense:1,100)
B(2,-39,8,betternether:quartz_stained_glass:15)
B(3,-39,8,betternether:quartz_stained_glass:15)
B(4,-39,8,betternether:quartz_stained_glass:15)
B(0,-39,9,betternether:quartz_stained_glass:15)
B(1,-39,9,betternether:quartz_stained_glass:15)
B(2,-39,9,betternether:quartz_stained_glass:15)
B(3,-39,9,betternether:quartz_stained_glass:15)
B(1,-39,10,betternether:quartz_stained_glass:15)
B(2,-39,10,betternether:quartz_stained_glass:15)
B(1,-38,3,betternether:quartz_stained_glass:15)
B(0,-38,4,betternether:quartz_stained_glass:15)
B(1,-38,4,betternether:quartz_stained_glass:15)
B(2,-38,4,betternether:quartz_stained_glass:15)
B(0,-38,5,betternether:quartz_stained_glass:15)
B(1,-38,5,betternether:quartz_stained_glass:15)
B(2,-38,5,betternether:quartz_stained_glass:15)
RB(0,-38,6,srparasites:parasitestain:1,80,quark:crystal:1,30,srparasites:parasiterubbledense:1,100)
B(1,-38,6,betternether:quartz_stained_glass:15)
B(2,-38,6,betternether:quartz_stained_glass:15)
B(3,-38,6,betternether:quartz_stained_glass:15)
RB(0,-38,7,srparasites:parasitestain:1,80,quark:crystal:1,30,srparasites:parasiterubbledense:1,100)
RB(1,-38,7,srparasites:parasitestain:1,80,quark:crystal:1,30,srparasites:parasiterubbledense:1,100)
B(2,-38,7,betternether:quartz_stained_glass:15)
B(3,-38,7,betternether:quartz_stained_glass:15)
B(4,-38,7,betternether:quartz_stained_glass:15)
RB(0,-38,8,srparasites:parasitestain:1,80,quark:crystal:1,30,srparasites:parasiterubbledense:1,100)
B(1,-38,8,betternether:quartz_stained_glass:15)
B(2,-38,8,betternether:quartz_stained_glass:15)
B(3,-38,8,betternether:quartz_stained_glass:15)
B(0,-38,9,betternether:quartz_stained_glass:15)
B(1,-38,9,betternether:quartz_stained_glass:15)
B(2,-38,9,betternether:quartz_stained_glass:15)
B(1,-38,10,betternether:quartz_stained_glass:15)
B(0,-37,3,betternether:quartz_stained_glass:15)
B(1,-37,3,betternether:quartz_stained_glass:15)
B(0,-37,4,betternether:quartz_stained_glass:15)
B(1,-37,4,betternether:quartz_stained_glass:15)
B(2,-37,4,betternether:quartz_stained_glass:15)
B(0,-37,5,betternether:quartz_stained_glass:15)
B(1,-37,5,betternether:quartz_stained_glass:15)
B(2,-37,5,betternether:quartz_stained_glass:15)
B(3,-37,5,betternether:quartz_stained_glass:15)
RB(0,-37,6,srparasites:parasitestain:1,80,quark:crystal:1,30,srparasites:parasiterubbledense:1,100)
B(1,-37,6,betternether:quartz_stained_glass:15)
B(2,-37,6,betternether:quartz_stained_glass:15)
B(3,-37,6,betternether:quartz_stained_glass:15)
RB(0,-37,7,srparasites:parasitestain:1,80,quark:crystal:1,30,srparasites:parasiterubbledense:1,100)
B(1,-37,7,betternether:quartz_stained_glass:15)
B(2,-37,7,betternether:quartz_stained_glass:15)
B(3,-37,7,betternether:quartz_stained_glass:15)
B(0,-37,8,betternether:quartz_stained_glass:15)
B(1,-37,8,betternether:quartz_stained_glass:15)
B(2,-37,8,betternether:quartz_stained_glass:15)
B(0,-37,9,betternether:quartz_stained_glass:15)
B(1,-37,9,betternether:quartz_stained_glass:15)
B(2,-37,9,betternether:quartz_stained_glass:15)
B(0,-36,2,betternether:quartz_stained_glass:15)
B(0,-36,3,betternether:quartz_stained_glass:15)
B(1,-36,3,betternether:quartz_stained_glass:15)
B(0,-36,4,betternether:quartz_stained_glass:15)
B(1,-36,4,betternether:quartz_stained_glass:15)
B(2,-36,4,betternether:quartz_stained_glass:15)
B(3,-36,4,betternether:quartz_stained_glass:15)
RB(0,-36,5,srparasites:parasitestain:1,80,quark:crystal:1,30,srparasites:parasiterubbledense:1,100)
B(1,-36,5,betternether:quartz_stained_glass:15)
B(2,-36,5,betternether:quartz_stained_glass:15)
B(3,-36,5,betternether:quartz_stained_glass:15)
RB(0,-36,6,srparasites:parasitestain:1,80,quark:crystal:1,30,srparasites:parasiterubbledense:1,100)
B(1,-36,6,betternether:quartz_stained_glass:15)
B(2,-36,6,betternether:quartz_stained_glass:15)
B(3,-36,6,betternether:quartz_stained_glass:15)
B(0,-36,7,betternether:quartz_stained_glass:15)
B(1,-36,7,betternether:quartz_stained_glass:15)
B(2,-36,7,betternether:quartz_stained_glass:15)
B(0,-36,8,betternether:quartz_stained_glass:15)
B(1,-36,8,betternether:quartz_stained_glass:15)
B(2,-36,8,betternether:quartz_stained_glass:15)
B(0,-36,9,betternether:quartz_stained_glass:15)
B(1,-36,9,betternether:quartz_stained_glass:15)
B(0,-35,2,betternether:quartz_stained_glass:15)
B(0,-35,3,betternether:quartz_stained_glass:15)
B(1,-35,3,betternether:quartz_stained_glass:15)
B(2,-35,3,betternether:quartz_stained_glass:15)
B(0,-35,4,betternether:quartz_stained_glass:15)
B(1,-35,4,betternether:quartz_stained_glass:15)
B(2,-35,4,betternether:quartz_stained_glass:15)
B(3,-35,4,betternether:quartz_stained_glass:15)
RB(0,-35,5,srparasites:parasitestain:1,80,quark:crystal:1,30,srparasites:parasiterubbledense:1,100)
B(1,-35,5,betternether:quartz_stained_glass:15)
B(2,-35,5,betternether:quartz_stained_glass:15)
B(3,-35,5,betternether:quartz_stained_glass:15)
B(0,-35,6,betternether:quartz_stained_glass:15)
B(1,-35,6,betternether:quartz_stained_glass:15)
B(2,-35,6,betternether:quartz_stained_glass:15)
B(3,-35,6,betternether:quartz_stained_glass:15)
B(0,-35,7,betternether:quartz_stained_glass:15)
B(1,-35,7,betternether:quartz_stained_glass:15)
B(0,-35,8,betternether:quartz_stained_glass:15)
B(1,-35,8,betternether:quartz_stained_glass:15)
B(0,-34,2,betternether:quartz_stained_glass:15)
B(0,-34,3,betternether:quartz_stained_glass:15)
B(1,-34,3,betternether:quartz_stained_glass:15)
B(2,-34,3,betternether:quartz_stained_glass:15)
B(0,-34,4,betternether:quartz_stained_glass:15)
B(1,-34,4,betternether:quartz_stained_glass:15)
B(2,-34,4,betternether:quartz_stained_glass:15)
RB(0,-34,5,srparasites:parasitestain:1,80,quark:crystal:1,30,srparasites:parasiterubbledense:1,100)
B(1,-34,5,srparasites:parasiterubbledense:1)
B(2,-34,5,betternether:quartz_stained_glass:15)
B(3,-34,5,betternether:quartz_stained_glass:15)
B(0,-34,6,betternether:quartz_stained_glass:15)
B(1,-34,6,betternether:quartz_stained_glass:15)
B(2,-34,6,betternether:quartz_stained_glass:15)
B(0,-34,7,betternether:quartz_stained_glass:15)
B(1,-34,7,betternether:quartz_stained_glass:15)
B(0,-34,8,betternether:quartz_stained_glass:15)
B(0,-33,2,betternether:quartz_stained_glass:15)
B(1,-33,2,betternether:quartz_stained_glass:15)
B(0,-33,3,betternether:quartz_stained_glass:15)
B(1,-33,3,betternether:quartz_stained_glass:15)
B(2,-33,3,betternether:quartz_stained_glass:15)
B(0,-33,4,srparasites:parasiterubbledense:1)
B(1,-33,4,srparasites:parasiterubbledense:1)
B(2,-33,4,betternether:quartz_stained_glass:15)
B(0,-33,5,srparasites:parasiterubbledense:1)
B(1,-33,5,srparasites:parasiterubbledense:1)
B(2,-33,5,betternether:quartz_stained_glass:15)
B(0,-33,6,betternether:quartz_stained_glass:15)
B(0,-33,7,betternether:quartz_stained_glass:15)
B(0,-32,2,betternether:quartz_stained_glass:15)
B(1,-32,2,betternether:quartz_stained_glass:15)
B(0,-32,3,betternether:quartz_stained_glass:15)
B(1,-32,3,betternether:quartz_stained_glass:15)
B(0,-32,4,srparasites:parasiterubbledense:1)
B(1,-32,4,srparasites:parasiterubbledense:1)
B(2,-32,4,betternether:quartz_stained_glass:15)
B(0,-32,5,srparasites:parasiterubbledense:1)
B(1,-32,5,betternether:quartz_stained_glass:15)
B(0,-32,6,betternether:quartz_stained_glass:15)
B(0,-31,1,betternether:quartz_stained_glass:15)
B(0,-31,2,betternether:quartz_stained_glass:15)
B(1,-31,2,betternether:quartz_stained_glass:15)
B(0,-31,3,betternether:quartz_stained_glass:15)
B(1,-31,3,betternether:quartz_stained_glass:15)
B(0,-31,4,srparasites:parasiterubbledense:1)
B(1,-31,4,betternether:quartz_stained_glass:15)
B(0,-31,5,betternether:quartz_stained_glass:15)
B(0,-30,1,betternether:quartz_stained_glass:15)
B(0,-30,2,betternether:quartz_stained_glass:15)
B(0,-30,3,srparasites:parasiterubbledense:1)
B(1,-30,3,betternether:quartz_stained_glass:15)
B(0,-30,4,betternether:quartz_stained_glass:15)
B(0,-30,5,betternether:quartz_stained_glass:15)
B(0,-29,0,betternether:quartz_stained_glass:15)
B(0,-29,1,betternether:quartz_stained_glass:15)
B(0,-29,2,betternether:quartz_stained_glass:15)
B(0,-29,3,betternether:quartz_stained_glass:15)
B(0,-28,0,betternether:quartz_stained_glass:15)
B(0,-28,2,betternether:quartz_stained_glass:15)
B(0,-27,0,betternether:quartz_stained_glass:15)

