
#######################################################################
# +-----------------------------------------------------------------+ #
# |                            BO4 object                           | #
# +-----------------------------------------------------------------+ #
#######################################################################

Author: NLBlackEagle

Description: No description given

SettingsMode: WriteDisable


#######################################################################
# +-----------------------------------------------------------------+ #
# |                          Main settings                          | #
# +-----------------------------------------------------------------+ #
#######################################################################

FixedRotation: 

Frequency: 0

SpawnHeight: highestBlock

UseCenterForHighestBlock: true

##############################
# Height Limits for the BO4. #
##############################

MinHeight: 0

MaxHeight: 255

InheritBO3: 

InheritBO3Rotation: NORTH

OverrideChildSettings: true

OverrideParentHeight: false

CanOverride: true

BranchFrequency: 0

BranchFrequencyGroup: 

MustBeBelowOther: false

MustBeInside: 

CannotBeInside: 

ReplacesBO3: 

MustBeInsideWorldBorders: false

CanSpawnOnWater: true

SpawnOnWaterOnly: false

SpawnUnderWater: false

SpawnAtWaterLevel: false

HeightOffset: 0

RemoveAir: false

ReplaceAbove: 

ReplaceBelow: 

ReplaceWithBiomeBlocks: false

ReplaceWithSurfaceBlock: GRASS

ReplaceWithGroundBlock: DIRT

ReplaceWithStoneBlock: STONE

SmoothRadius: 0

SmoothHeightOffset: 0

SmoothStartTop: false

SmoothStartWood: false

SmoothingSurfaceBlock: 

SmoothingGroundBlock: 

BO3Group: 

IsSpawnPoint: false

DoReplaceBlocks: false


#######################################################################
# +-----------------------------------------------------------------+ #
# |                              Blocks                             | #
# +-----------------------------------------------------------------+ #
#######################################################################

Block(-8,0,-7,contenttweaker:reinforced_concrete)
Block(-8,0,-6,contenttweaker:reinforced_concrete)
Block(-8,1,-7,contenttweaker:reinforced_concrete)
Block(-8,1,-6,contenttweaker:reinforced_concrete)
Block(-8,2,-7,contenttweaker:reinforced_concrete)
Block(-8,2,-6,contenttweaker:reinforced_concrete)
Block(-8,3,-7,contenttweaker:reinforced_concrete)
Block(-8,3,-6,contenttweaker:reinforced_concrete)
Block(-8,4,-7,contenttweaker:reinforced_concrete)
Block(-8,4,-6,contenttweaker:reinforced_concrete)
Block(-8,5,-7,contenttweaker:reinforced_concrete)
Block(-8,5,-6,contenttweaker:reinforced_concrete)
Block(-8,6,-7,contenttweaker:reinforced_concrete)
Block(-8,6,-6,contenttweaker:reinforced_concrete)
Block(-8,7,-7,contenttweaker:reinforced_concrete)
Block(-8,7,-6,contenttweaker:reinforced_concrete)
Block(-8,8,-7,contenttweaker:reinforced_concrete)
Block(-8,8,-6,contenttweaker:reinforced_concrete)
Block(-7,0,-7,contenttweaker:reinforced_concrete)
Block(-7,0,-6,contenttweaker:reinforced_concrete)
Block(-7,1,-6,contenttweaker:reinforced_concrete)
Block(-7,2,-6,contenttweaker:reinforced_concrete)
Block(-7,3,-6,contenttweaker:reinforced_concrete)
Block(-7,4,-6,contenttweaker:reinforced_concrete)
Block(-7,5,-6,contenttweaker:reinforced_concrete)
Block(-7,6,-6,contenttweaker:reinforced_concrete)
Block(-7,7,-6,contenttweaker:reinforced_concrete)
Block(-7,8,-7,contenttweaker:reinforced_concrete)
Block(-7,8,-6,contenttweaker:reinforced_concrete)
Block(-6,0,-7,contenttweaker:reinforced_concrete)
Block(-6,0,-6,contenttweaker:reinforced_concrete)
Block(-6,0,-5,contenttweaker:reinforced_concrete)
Block(-6,0,-4,contenttweaker:reinforced_concrete)
Block(-6,0,-3,contenttweaker:reinforced_concrete)
Block(-6,0,-2,contenttweaker:reinforced_concrete)
Block(-6,1,-6,contenttweaker:reinforced_concrete)
Block(-6,1,-5,contenttweaker:reinforced_concrete)
Block(-6,1,-4,contenttweaker:reinforced_concrete)
Block(-6,1,-3,contenttweaker:reinforced_concrete)
Block(-6,1,-2,contenttweaker:reinforced_concrete)
Block(-6,2,-6,contenttweaker:reinforced_concrete)
Block(-6,2,-5,contenttweaker:reinforced_concrete)
Block(-6,2,-4,contenttweaker:reinforced_concrete)
Block(-6,2,-3,contenttweaker:reinforced_concrete)
Block(-6,2,-2,contenttweaker:reinforced_concrete)
Block(-6,3,-6,contenttweaker:reinforced_concrete)
Block(-6,3,-5,contenttweaker:reinforced_concrete)
Block(-6,3,-4,contenttweaker:reinforced_concrete)
Block(-6,3,-3,contenttweaker:reinforced_concrete)
Block(-6,3,-2,contenttweaker:reinforced_concrete)
Block(-6,4,-6,contenttweaker:reinforced_concrete)
Block(-6,4,-5,contenttweaker:reinforced_concrete)
Block(-6,4,-4,contenttweaker:reinforced_concrete)
Block(-6,4,-3,contenttweaker:reinforced_concrete)
Block(-6,4,-2,contenttweaker:reinforced_concrete)
Block(-6,5,-6,contenttweaker:reinforced_concrete)
Block(-6,5,-5,contenttweaker:reinforced_concrete)
Block(-6,5,-4,contenttweaker:reinforced_concrete)
Block(-6,5,-3,contenttweaker:reinforced_concrete)
Block(-6,5,-2,contenttweaker:reinforced_concrete)
Block(-6,6,-6,contenttweaker:reinforced_concrete)
Block(-6,7,-6,contenttweaker:reinforced_concrete)
Block(-6,8,-7,contenttweaker:reinforced_concrete)
Block(-6,8,-6,contenttweaker:reinforced_concrete)
Block(-5,0,-7,contenttweaker:reinforced_concrete)
Block(-5,0,-6,contenttweaker:reinforced_concrete)
Block(-5,0,-5,contenttweaker:reinforced_concrete)
Block(-5,0,-4,contenttweaker:reinforced_concrete)
Block(-5,0,-3,contenttweaker:reinforced_concrete)
Block(-5,0,-2,contenttweaker:reinforced_concrete)
Block(-5,1,-6,contenttweaker:reinforced_concrete)
Block(-5,1,-5,contenttweaker:reinforced_concrete)
Block(-5,1,-4,contenttweaker:reinforced_concrete)
Block(-5,1,-3,contenttweaker:reinforced_concrete)
Block(-5,1,-2,contenttweaker:reinforced_concrete)
Block(-5,2,-6,contenttweaker:reinforced_concrete)
Block(-5,2,-5,contenttweaker:reinforced_concrete)
Block(-5,2,-4,contenttweaker:reinforced_concrete)
Block(-5,2,-3,contenttweaker:reinforced_concrete)
Block(-5,2,-2,contenttweaker:reinforced_concrete)
Block(-5,3,-6,contenttweaker:reinforced_concrete)
Block(-5,3,-5,AIR:0)
Block(-5,3,-4,contenttweaker:resource_crate)
Block(-5,3,-3,contenttweaker:resource_crate)
Block(-5,3,-2,contenttweaker:reinforced_concrete)
Block(-5,4,-6,contenttweaker:reinforced_concrete)
Block(-5,4,-5,AIR:0)
Block(-5,4,-4,AIR:0)
Block(-5,4,-3,contenttweaker:resource_crate)
Block(-5,4,-2,contenttweaker:reinforced_concrete)
Block(-5,5,-6,contenttweaker:reinforced_concrete)
Block(-5,5,-5,contenttweaker:reinforced_concrete)
Block(-5,5,-4,contenttweaker:reinforced_concrete)
Block(-5,5,-3,contenttweaker:reinforced_concrete)
Block(-5,5,-2,contenttweaker:reinforced_concrete)
Block(-5,6,-6,contenttweaker:reinforced_concrete)
Block(-5,7,-6,contenttweaker:reinforced_concrete)
Block(-5,8,-7,contenttweaker:reinforced_concrete)
Block(-5,8,-6,contenttweaker:reinforced_concrete)
Block(-4,0,-7,contenttweaker:reinforced_concrete)
Block(-4,0,-6,contenttweaker:reinforced_concrete)
Block(-4,0,-5,contenttweaker:reinforced_concrete)
Block(-4,0,-4,contenttweaker:reinforced_concrete)
Block(-4,0,-3,contenttweaker:reinforced_concrete)
Block(-4,0,-2,contenttweaker:reinforced_concrete)
Block(-4,1,-6,contenttweaker:reinforced_concrete)
Block(-4,1,-5,contenttweaker:reinforced_concrete)
Block(-4,1,-4,contenttweaker:reinforced_concrete)
Block(-4,1,-3,contenttweaker:reinforced_concrete)
Block(-4,1,-2,contenttweaker:reinforced_concrete)
Block(-4,2,-6,contenttweaker:reinforced_concrete)
Block(-4,2,-5,contenttweaker:reinforced_concrete)
Block(-4,2,-4,contenttweaker:reinforced_concrete)
Block(-4,2,-3,contenttweaker:reinforced_concrete)
Block(-4,2,-2,contenttweaker:reinforced_concrete)
Block(-4,3,-6,contenttweaker:reinforced_concrete)
Block(-4,3,-5,contenttweaker:resource_crate)
Block(-4,3,-4,contenttweaker:resource_crate)
Block(-4,3,-3,contenttweaker:resource_crate)
Block(-4,3,-2,contenttweaker:reinforced_concrete)
Block(-4,4,-6,contenttweaker:reinforced_concrete)
Block(-4,4,-5,AIR:0)
Block(-4,4,-4,contenttweaker:resource_crate)
Block(-4,4,-3,contenttweaker:resource_crate)
Block(-4,4,-2,contenttweaker:reinforced_concrete)
Block(-4,5,-6,contenttweaker:reinforced_concrete)
Block(-4,5,-5,contenttweaker:reinforced_concrete)
Block(-4,5,-4,contenttweaker:reinforced_concrete)
Block(-4,5,-3,contenttweaker:reinforced_concrete)
Block(-4,5,-2,contenttweaker:reinforced_concrete)
Block(-4,6,-6,contenttweaker:reinforced_concrete)
Block(-4,7,-6,contenttweaker:reinforced_concrete)
Block(-4,8,-7,contenttweaker:reinforced_concrete)
Block(-4,8,-6,contenttweaker:reinforced_concrete)
Block(-3,0,-7,contenttweaker:reinforced_concrete)
Block(-3,0,-6,contenttweaker:reinforced_concrete)
Block(-3,0,-5,contenttweaker:reinforced_concrete)
Block(-3,0,-4,contenttweaker:reinforced_concrete)
Block(-3,0,-3,contenttweaker:reinforced_concrete)
Block(-3,0,-2,contenttweaker:reinforced_concrete)
Block(-3,1,-6,contenttweaker:reinforced_concrete)
Block(-3,1,-5,contenttweaker:reinforced_concrete)
Block(-3,1,-4,contenttweaker:reinforced_concrete)
Block(-3,1,-3,contenttweaker:reinforced_concrete)
Block(-3,1,-2,contenttweaker:reinforced_concrete)
Block(-3,2,-6,contenttweaker:reinforced_concrete)
Block(-3,2,-5,contenttweaker:reinforced_concrete)
Block(-3,2,-4,contenttweaker:reinforced_concrete)
Block(-3,2,-3,contenttweaker:reinforced_concrete)
Block(-3,2,-2,contenttweaker:reinforced_concrete)
Block(-3,3,-6,contenttweaker:reinforced_concrete)
Block(-3,3,-5,AIR:0)
Entity(-3,3,-4,minecraft:evocation_illager,1,../nbt/evoker.txt)
Block(-3,3,-4,AIR:0)
Block(-3,3,-3,contenttweaker:resource_crate)
Block(-3,3,-2,contenttweaker:reinforced_concrete)
Block(-3,4,-6,contenttweaker:reinforced_concrete)
Block(-3,4,-5,AIR:0)
Block(-3,4,-4,AIR:0)
Block(-3,4,-3,contenttweaker:resource_crate)
Block(-3,4,-2,contenttweaker:reinforced_concrete)
Block(-3,5,-6,contenttweaker:reinforced_concrete)
Block(-3,5,-5,contenttweaker:reinforced_concrete)
Block(-3,5,-4,contenttweaker:reinforced_concrete)
Block(-3,5,-3,contenttweaker:reinforced_concrete)
Block(-3,5,-2,contenttweaker:reinforced_concrete)
Block(-3,6,-6,contenttweaker:reinforced_concrete)
Block(-3,7,-6,contenttweaker:reinforced_concrete)
Block(-3,8,-7,contenttweaker:reinforced_concrete)
Block(-3,8,-6,contenttweaker:reinforced_concrete)
Block(-2,0,-7,contenttweaker:reinforced_concrete)
Block(-2,0,-6,contenttweaker:reinforced_concrete)
Block(-2,0,-5,contenttweaker:reinforced_concrete)
Block(-2,0,-4,contenttweaker:reinforced_concrete)
Block(-2,0,-3,contenttweaker:reinforced_concrete)
Block(-2,0,-2,contenttweaker:reinforced_concrete)
Block(-2,1,-6,contenttweaker:reinforced_concrete)
Block(-2,1,-5,contenttweaker:reinforced_concrete)
Block(-2,1,-4,contenttweaker:reinforced_concrete)
Block(-2,1,-3,contenttweaker:reinforced_concrete)
Block(-2,1,-2,contenttweaker:reinforced_concrete)
Block(-2,2,-6,contenttweaker:reinforced_concrete)
Block(-2,2,-5,contenttweaker:reinforced_concrete)
Block(-2,2,-4,contenttweaker:reinforced_concrete)
Block(-2,2,-3,contenttweaker:reinforced_concrete)
Block(-2,2,-2,contenttweaker:reinforced_concrete)
Block(-2,3,-6,contenttweaker:reinforced_concrete)
Block(-2,3,-5,AIR:0)
Block(-2,3,-4,AIR:0)
Block(-2,3,-3,contenttweaker:resource_crate)
Block(-2,3,-2,contenttweaker:reinforced_concrete)
Block(-2,4,-6,contenttweaker:reinforced_concrete)
Block(-2,4,-5,AIR:0)
Block(-2,4,-4,AIR:0)
Block(-2,4,-3,AIR:0)
Block(-2,4,-2,contenttweaker:reinforced_concrete)
Block(-2,5,-6,contenttweaker:reinforced_concrete)
Block(-2,5,-5,contenttweaker:reinforced_concrete)
Block(-2,5,-4,contenttweaker:reinforced_concrete)
Block(-2,5,-3,contenttweaker:reinforced_concrete)
Block(-2,5,-2,contenttweaker:reinforced_concrete)
Block(-2,6,-6,contenttweaker:reinforced_concrete)
Block(-2,7,-6,contenttweaker:reinforced_concrete)
Block(-2,8,-7,contenttweaker:reinforced_concrete)
Block(-2,8,-6,contenttweaker:reinforced_concrete)
Block(-1,0,-7,contenttweaker:reinforced_concrete)
Block(-1,0,-6,contenttweaker:reinforced_concrete)
Block(-1,0,-5,contenttweaker:reinforced_concrete)
Block(-1,0,-4,contenttweaker:reinforced_concrete)
Block(-1,0,-3,contenttweaker:reinforced_concrete)
Block(-1,0,-2,contenttweaker:reinforced_concrete)
Block(-1,1,-6,contenttweaker:reinforced_concrete)
Block(-1,1,-5,contenttweaker:reinforced_concrete)
Block(-1,1,-4,contenttweaker:reinforced_concrete)
Block(-1,1,-3,contenttweaker:reinforced_concrete)
Block(-1,1,-2,contenttweaker:reinforced_concrete)
Block(-1,2,-6,contenttweaker:reinforced_concrete)
Block(-1,2,-5,contenttweaker:reinforced_concrete)
Block(-1,2,-4,contenttweaker:reinforced_concrete)
Block(-1,2,-3,contenttweaker:reinforced_concrete)
Block(-1,2,-2,contenttweaker:reinforced_concrete)
Block(-1,3,-6,contenttweaker:reinforced_concrete)
Block(-1,3,-5,AIR:0)
Block(-1,3,-4,AIR:0)
Block(-1,3,-3,AIR:0)
Block(-1,3,-2,contenttweaker:reinforced_concrete)
Block(-1,4,-6,contenttweaker:reinforced_concrete)
Block(-1,4,-5,AIR:0)
Block(-1,4,-4,AIR:0)
Block(-1,4,-3,AIR:0)
Block(-1,4,-2,contenttweaker:reinforced_concrete)
Block(-1,5,-6,contenttweaker:reinforced_concrete)
Block(-1,5,-5,contenttweaker:reinforced_concrete)
Block(-1,5,-4,contenttweaker:reinforced_concrete)
Block(-1,5,-3,contenttweaker:reinforced_concrete)
Block(-1,5,-2,contenttweaker:reinforced_concrete)
Block(-1,6,-6,contenttweaker:reinforced_concrete)
Block(-1,7,-6,contenttweaker:reinforced_concrete)
Block(-1,8,-7,contenttweaker:reinforced_concrete)
Block(-1,8,-6,contenttweaker:reinforced_concrete)
Block(0,0,-7,contenttweaker:reinforced_concrete)
Block(0,0,-6,contenttweaker:reinforced_concrete)
Block(0,0,-5,contenttweaker:reinforced_concrete)
Block(0,0,-4,contenttweaker:reinforced_concrete)
Block(0,0,-3,contenttweaker:reinforced_concrete)
Block(0,0,-2,contenttweaker:reinforced_concrete)
Block(0,0,-1,contenttweaker:reinforced_concrete)
Block(0,0,0,contenttweaker:reinforced_concrete)
Block(0,0,1,contenttweaker:reinforced_concrete)
Block(0,1,-6,contenttweaker:reinforced_concrete)
Block(0,1,-5,contenttweaker:reinforced_concrete)
Block(0,1,-4,contenttweaker:reinforced_concrete)
Block(0,1,-3,contenttweaker:reinforced_concrete)
Block(0,1,-2,contenttweaker:reinforced_concrete)
Block(0,1,-1,contenttweaker:reinforced_concrete)
Block(0,1,0,contenttweaker:reinforced_concrete)
Block(0,1,1,contenttweaker:reinforced_concrete)
Block(0,2,-6,contenttweaker:reinforced_concrete)
Block(0,2,-5,contenttweaker:reinforced_concrete)
Block(0,2,-4,contenttweaker:reinforced_concrete)
Block(0,2,-3,contenttweaker:reinforced_concrete)
Block(0,2,-2,contenttweaker:reinforced_concrete)
Block(0,2,-1,contenttweaker:reinforced_concrete)
Block(0,2,0,contenttweaker:reinforced_concrete)
Block(0,2,1,contenttweaker:reinforced_concrete)
Block(0,3,-6,contenttweaker:reinforced_concrete)
Block(0,3,-5,AIR:0)
Block(0,3,-4,AIR:0)
Block(0,3,-3,AIR:0)
Block(0,3,-2,contenttweaker:reinforced_concrete)
Block(0,3,-1,contenttweaker:reinforced_concrete)
Block(0,3,0,contenttweaker:reinforced_concrete)
Block(0,3,1,contenttweaker:reinforced_concrete)
Block(0,4,-6,contenttweaker:reinforced_concrete)
Block(0,4,-5,AIR:0)
Block(0,4,-4,AIR:0)
Block(0,4,-3,AIR:0)
Block(0,4,-2,contenttweaker:reinforced_concrete)
Block(0,4,-1,contenttweaker:reinforced_concrete)
Block(0,4,0,contenttweaker:reinforced_concrete)
Block(0,4,1,contenttweaker:reinforced_concrete)
Block(0,5,-6,contenttweaker:reinforced_concrete)
Block(0,5,-5,contenttweaker:reinforced_concrete)
Block(0,5,-4,contenttweaker:reinforced_concrete)
Block(0,5,-3,contenttweaker:reinforced_concrete)
Block(0,5,-2,contenttweaker:reinforced_concrete)
Block(0,5,-1,contenttweaker:reinforced_concrete)
Block(0,5,0,contenttweaker:reinforced_concrete)
Block(0,5,1,contenttweaker:reinforced_concrete)
Block(0,6,-6,contenttweaker:reinforced_concrete)
Block(0,6,-5,contenttweaker:reinforced_concrete)
Block(0,6,-4,contenttweaker:reinforced_concrete)
Block(0,6,-3,contenttweaker:reinforced_concrete)
Block(0,6,-2,contenttweaker:reinforced_concrete)
Block(0,6,-1,contenttweaker:reinforced_concrete)
Block(0,6,0,contenttweaker:reinforced_concrete)
Block(0,6,1,contenttweaker:reinforced_concrete)
Block(0,7,-6,contenttweaker:reinforced_concrete)
Block(0,7,-3,contenttweaker:reinforced_concrete)
Block(0,7,-2,contenttweaker:reinforced_concrete)
Block(0,7,-1,contenttweaker:reinforced_concrete)
Block(0,7,0,contenttweaker:reinforced_concrete)
Block(0,7,1,contenttweaker:reinforced_concrete)
Block(0,8,-7,contenttweaker:reinforced_concrete)
Block(0,8,-6,contenttweaker:reinforced_concrete)
Block(0,8,-3,contenttweaker:reinforced_concrete)
Block(0,8,-2,contenttweaker:reinforced_concrete)
Block(0,8,-1,contenttweaker:reinforced_concrete)
Block(0,8,0,contenttweaker:reinforced_concrete)
Block(0,8,1,contenttweaker:reinforced_concrete)
Block(0,9,-3,contenttweaker:reinforced_concrete)
Block(0,9,-2,contenttweaker:reinforced_concrete)
Block(0,9,-1,contenttweaker:reinforced_concrete)
Block(0,9,0,contenttweaker:reinforced_concrete)
Block(0,9,1,contenttweaker:reinforced_concrete)
Block(0,10,-3,contenttweaker:reinforced_concrete)
Block(0,10,-2,contenttweaker:reinforced_concrete)
Block(0,10,-1,contenttweaker:reinforced_concrete)
Block(0,10,0,contenttweaker:reinforced_concrete)
Block(0,10,1,contenttweaker:reinforced_concrete)
Block(0,11,-3,contenttweaker:reinforced_concrete)
Block(0,11,-2,contenttweaker:reinforced_concrete)
Block(0,11,-1,contenttweaker:reinforced_concrete)
Block(0,11,0,contenttweaker:reinforced_concrete)
Block(0,11,1,contenttweaker:reinforced_concrete)
Block(0,12,-3,contenttweaker:reinforced_concrete)
Block(0,12,-2,contenttweaker:reinforced_concrete)
Block(0,12,-1,contenttweaker:reinforced_concrete)
Block(0,12,0,contenttweaker:reinforced_concrete)
Block(0,12,1,contenttweaker:reinforced_concrete)
Block(0,13,-3,contenttweaker:reinforced_concrete)
Block(0,13,-2,contenttweaker:reinforced_concrete)
Block(0,13,-1,contenttweaker:reinforced_concrete)
Block(0,13,0,contenttweaker:reinforced_concrete)
Block(0,13,1,contenttweaker:reinforced_concrete)
Block(0,14,-3,contenttweaker:reinforced_concrete)
Block(0,14,-2,contenttweaker:reinforced_concrete)
Block(0,14,-1,contenttweaker:reinforced_concrete)
Block(0,14,0,contenttweaker:reinforced_concrete)
Block(0,14,1,contenttweaker:reinforced_concrete)
Block(0,15,-3,contenttweaker:reinforced_concrete)
Block(0,15,-2,contenttweaker:reinforced_concrete)
Block(0,15,-1,contenttweaker:reinforced_concrete)
Block(0,15,0,contenttweaker:reinforced_concrete)
Block(0,15,1,contenttweaker:reinforced_concrete)
Block(0,16,-3,contenttweaker:reinforced_concrete)
Block(0,16,-2,contenttweaker:reinforced_concrete)
Block(0,16,-1,contenttweaker:reinforced_concrete)
Block(0,16,0,contenttweaker:reinforced_concrete)
Block(0,16,1,contenttweaker:reinforced_concrete)
Block(0,17,-3,contenttweaker:reinforced_concrete)
Block(0,17,-2,contenttweaker:reinforced_concrete)
Block(0,17,-1,contenttweaker:reinforced_concrete)
Block(0,17,0,contenttweaker:reinforced_concrete)
Block(0,17,1,contenttweaker:reinforced_concrete)
Block(0,18,-7,contenttweaker:reinforced_concrete)
Block(0,18,-6,contenttweaker:reinforced_concrete)
Block(0,18,-5,contenttweaker:reinforced_concrete)
Block(0,18,-4,contenttweaker:reinforced_concrete)
Block(0,18,-3,contenttweaker:reinforced_concrete)
Block(0,18,-2,contenttweaker:reinforced_concrete)
Block(0,18,-1,contenttweaker:reinforced_concrete)
Block(0,18,0,contenttweaker:reinforced_concrete)
Block(0,18,1,contenttweaker:reinforced_concrete)
Block(0,19,-7,contenttweaker:reinforced_concrete)
Block(0,19,-6,contenttweaker:reinforced_concrete)
Block(0,19,-5,contenttweaker:reinforced_concrete)
Block(0,19,-4,contenttweaker:reinforced_concrete)
Block(0,19,-3,contenttweaker:reinforced_concrete)
Block(0,19,-2,contenttweaker:reinforced_concrete)
Block(0,19,-1,contenttweaker:reinforced_concrete)
Block(0,19,0,contenttweaker:reinforced_concrete)
Block(0,19,1,contenttweaker:reinforced_concrete)
Block(0,20,-7,contenttweaker:reinforced_concrete)
Block(0,20,-6,contenttweaker:reinforced_concrete)
Block(0,20,-5,contenttweaker:reinforced_concrete)
Block(0,20,-4,contenttweaker:reinforced_concrete)
Block(0,20,-3,contenttweaker:reinforced_concrete)
Block(0,20,-2,contenttweaker:reinforced_concrete)
Block(0,20,-1,contenttweaker:reinforced_concrete)
Block(0,20,0,contenttweaker:reinforced_concrete)
Block(0,20,1,contenttweaker:reinforced_concrete)
Block(0,21,-7,contenttweaker:reinforced_concrete)
Block(0,21,-6,contenttweaker:reinforced_concrete)
Block(0,21,-5,contenttweaker:reinforced_concrete)
Block(0,21,-4,contenttweaker:reinforced_concrete)
Block(0,21,-3,contenttweaker:reinforced_concrete)
Block(0,21,-2,contenttweaker:reinforced_concrete)
Block(0,21,-1,contenttweaker:reinforced_concrete)
Block(0,21,0,contenttweaker:reinforced_concrete)
Block(0,21,1,contenttweaker:reinforced_concrete)
Block(0,22,-7,contenttweaker:reinforced_concrete)
Block(0,22,-6,contenttweaker:reinforced_concrete)
Block(0,22,-5,contenttweaker:reinforced_concrete)
Block(0,22,-4,contenttweaker:reinforced_concrete)
Block(0,22,-3,contenttweaker:reinforced_concrete)
Block(0,22,-2,contenttweaker:reinforced_concrete)
Block(0,22,-1,contenttweaker:reinforced_concrete)
Block(0,22,0,contenttweaker:reinforced_concrete)
Block(0,22,1,contenttweaker:reinforced_concrete)
Block(0,23,-3,contenttweaker:reinforced_concrete)
Block(0,23,-2,contenttweaker:reinforced_concrete)
Block(0,23,-1,contenttweaker:reinforced_concrete)
Block(0,23,0,contenttweaker:reinforced_concrete)
Block(0,23,1,contenttweaker:reinforced_concrete)
Block(0,24,-3,contenttweaker:reinforced_concrete)
Block(0,24,-2,contenttweaker:reinforced_concrete)
Block(0,24,-1,contenttweaker:reinforced_concrete)
Block(0,24,0,contenttweaker:reinforced_concrete)
Block(0,24,1,contenttweaker:reinforced_concrete)
Block(0,25,-3,contenttweaker:reinforced_concrete)
Block(0,25,-2,contenttweaker:reinforced_concrete)
Block(0,25,-1,contenttweaker:reinforced_concrete)
Block(0,25,0,contenttweaker:reinforced_concrete)
Block(0,25,1,contenttweaker:reinforced_concrete)
Block(0,26,-7,contenttweaker:reinforced_concrete)
Block(0,26,-6,contenttweaker:reinforced_concrete)
Block(0,26,-5,contenttweaker:reinforced_concrete)
Block(0,26,-4,contenttweaker:reinforced_concrete)
Block(0,26,-3,contenttweaker:reinforced_concrete)
Block(0,26,-2,contenttweaker:reinforced_concrete)
Block(0,26,-1,contenttweaker:reinforced_concrete)
Block(0,26,0,contenttweaker:reinforced_concrete)
Block(0,26,1,contenttweaker:reinforced_concrete)
Block(0,27,-7,contenttweaker:reinforced_concrete)
Block(0,27,-6,contenttweaker:reinforced_concrete)
Block(0,27,-5,contenttweaker:reinforced_concrete)
Block(0,27,-4,contenttweaker:reinforced_concrete)
Block(0,27,-3,contenttweaker:reinforced_concrete)
Block(0,27,-2,contenttweaker:reinforced_concrete)
Block(0,27,-1,contenttweaker:reinforced_concrete)
Block(0,27,0,contenttweaker:reinforced_concrete)
Block(0,27,1,contenttweaker:reinforced_concrete)
Block(0,28,-7,contenttweaker:reinforced_concrete)
Block(0,28,-6,contenttweaker:reinforced_concrete)
Block(0,28,-5,contenttweaker:reinforced_concrete)
Block(0,28,-4,contenttweaker:reinforced_concrete)
Block(0,28,-3,contenttweaker:reinforced_concrete)
Block(0,28,-2,contenttweaker:reinforced_concrete)
Block(0,28,-1,contenttweaker:reinforced_concrete)
Block(0,28,0,contenttweaker:reinforced_concrete)
Block(0,28,1,contenttweaker:reinforced_concrete)
Block(0,29,-7,contenttweaker:reinforced_concrete)
Block(0,29,-6,contenttweaker:reinforced_concrete)
Block(0,29,-5,contenttweaker:reinforced_concrete)
Block(0,29,-4,contenttweaker:reinforced_concrete)
Block(0,29,-3,contenttweaker:reinforced_concrete)
Block(0,29,-2,contenttweaker:reinforced_concrete)
Block(0,29,-1,contenttweaker:reinforced_concrete)
Block(0,29,0,contenttweaker:reinforced_concrete)
Block(0,29,1,contenttweaker:reinforced_concrete)
Block(1,0,-7,contenttweaker:reinforced_concrete)
Block(1,0,-6,contenttweaker:reinforced_concrete)
Block(1,0,-5,contenttweaker:reinforced_concrete)
Block(1,0,-4,contenttweaker:reinforced_concrete)
Block(1,0,-3,contenttweaker:reinforced_concrete)
Block(1,0,-2,contenttweaker:reinforced_concrete)
Block(1,0,-1,contenttweaker:reinforced_concrete)
Block(1,0,0,contenttweaker:reinforced_concrete)
Block(1,0,1,contenttweaker:reinforced_concrete)
Block(1,1,-6,contenttweaker:reinforced_concrete)
Block(1,1,-5,contenttweaker:reinforced_concrete)
Block(1,1,-4,contenttweaker:reinforced_concrete)
Block(1,1,-3,contenttweaker:reinforced_concrete)
Block(1,1,-2,contenttweaker:reinforced_concrete)
Block(1,1,-1,contenttweaker:reinforced_concrete)
Block(1,1,0,contenttweaker:reinforced_concrete)
Block(1,1,1,contenttweaker:reinforced_concrete)
Block(1,2,-6,contenttweaker:reinforced_concrete)
Block(1,2,-5,contenttweaker:reinforced_concrete)
Block(1,2,-4,contenttweaker:reinforced_concrete)
Block(1,2,-3,contenttweaker:reinforced_concrete)
Block(1,2,-2,contenttweaker:reinforced_concrete)
Block(1,2,-1,contenttweaker:reinforced_concrete)
Block(1,2,0,contenttweaker:reinforced_concrete)
Block(1,2,1,contenttweaker:reinforced_concrete)
Block(1,3,-6,AIR:0)
Block(1,3,-5,AIR:0)
Block(1,3,-4,AIR:0)
Block(1,3,-3,AIR:0)
Block(1,3,-2,AIR:0)
Block(1,3,-1,AIR:0)
Block(1,3,0,AIR:0)
Block(1,3,1,contenttweaker:reinforced_concrete)
Block(1,4,-6,AIR:0)
Block(1,4,-5,AIR:0)
Block(1,4,-4,AIR:0)
Block(1,4,-3,AIR:0)
Block(1,4,-2,AIR:0)
Block(1,4,-1,AIR:0)
Block(1,4,0,AIR:0)
Block(1,4,1,contenttweaker:reinforced_concrete)
Block(1,5,-6,AIR:0)
Block(1,5,-5,AIR:0)
Block(1,5,-4,AIR:0)
Block(1,5,-3,AIR:0)
Block(1,5,-2,AIR:0)
Block(1,5,-1,contentcreator:concrete_slab_reinforced:1)
Block(1,5,0,contentcreator:concrete_slab_reinforced)
Block(1,5,1,contenttweaker:reinforced_concrete)
Block(1,6,-6,contenttweaker:reinforced_concrete)
Block(1,6,-5,contenttweaker:reinforced_concrete)
Block(1,6,-4,contenttweaker:reinforced_concrete)
Block(1,6,-3,contenttweaker:reinforced_concrete)
Block(1,6,-2,contentcreator:concrete_slab_reinforced)
Block(1,6,-1,AIR:0)
Block(1,6,0,AIR:0)
Block(1,6,1,contenttweaker:reinforced_concrete)
Block(1,7,-6,contenttweaker:reinforced_concrete)
Block(1,7,-3,contenttweaker:reinforced_concrete)
Block(1,7,-2,AIR:0)
Block(1,7,-1,AIR:0)
Block(1,7,0,AIR:0)
Block(1,7,1,contenttweaker:reinforced_concrete)
Block(1,8,-7,contenttweaker:reinforced_concrete)
Block(1,8,-6,contenttweaker:reinforced_concrete)
Block(1,8,-3,contenttweaker:reinforced_concrete)
Block(1,8,-2,AIR:0)
Block(1,8,-1,AIR:0)
Block(1,8,0,AIR:0)
Block(1,8,1,contenttweaker:reinforced_concrete)
Block(1,9,-3,contenttweaker:reinforced_concrete)
Block(1,9,-2,AIR:0)
Block(1,9,-1,contentcreator:concrete_slab_reinforced:1)
Block(1,9,0,contentcreator:concrete_slab_reinforced)
Block(1,9,1,contenttweaker:reinforced_concrete)
Block(1,10,-3,contenttweaker:reinforced_concrete)
Block(1,10,-2,contentcreator:concrete_slab_reinforced)
Block(1,10,-1,AIR:0)
Block(1,10,0,AIR:0)
Block(1,10,1,contenttweaker:reinforced_concrete)
Block(1,11,-3,contenttweaker:reinforced_concrete)
Block(1,11,-2,AIR:0)
Block(1,11,-1,AIR:0)
Block(1,11,0,AIR:0)
Block(1,11,1,contenttweaker:reinforced_concrete)
Block(1,12,-3,contenttweaker:reinforced_concrete)
Block(1,12,-2,AIR:0)
Block(1,12,-1,AIR:0)
Block(1,12,0,AIR:0)
Block(1,12,1,contenttweaker:reinforced_concrete)
Block(1,13,-3,contenttweaker:reinforced_concrete)
Block(1,13,-2,AIR:0)
Block(1,13,-1,contentcreator:concrete_slab_reinforced:1)
Block(1,13,0,contentcreator:concrete_slab_reinforced)
Block(1,13,1,contenttweaker:reinforced_concrete)
Block(1,14,-3,contenttweaker:reinforced_concrete)
Block(1,14,-2,contentcreator:concrete_slab_reinforced)
Block(1,14,-1,AIR:0)
Block(1,14,0,AIR:0)
Block(1,14,1,contenttweaker:reinforced_concrete)
Block(1,15,-3,contenttweaker:reinforced_concrete)
Block(1,15,-2,AIR:0)
Block(1,15,-1,AIR:0)
Block(1,15,0,AIR:0)
Block(1,15,1,contenttweaker:reinforced_concrete)
Block(1,16,-3,contenttweaker:reinforced_concrete)
Block(1,16,-2,AIR:0)
Block(1,16,-1,AIR:0)
Block(1,16,0,AIR:0)
Block(1,16,1,contenttweaker:reinforced_concrete)
Block(1,17,-3,contenttweaker:reinforced_concrete)
Block(1,17,-2,AIR:0)
Block(1,17,-1,contentcreator:concrete_slab_reinforced:1)
Block(1,17,0,contentcreator:concrete_slab_reinforced)
Block(1,17,1,contenttweaker:reinforced_concrete)
Block(1,18,-7,contenttweaker:reinforced_concrete)
Block(1,18,-6,contenttweaker:reinforced_concrete)
Block(1,18,-5,contenttweaker:reinforced_concrete)
Block(1,18,-4,contenttweaker:reinforced_concrete)
Block(1,18,-3,contenttweaker:reinforced_concrete)
Block(1,18,-2,contentcreator:concrete_slab_reinforced)
Block(1,18,-1,AIR:0)
Block(1,18,0,AIR:0)
Block(1,18,1,contenttweaker:reinforced_concrete)
Block(1,19,-7,AIR:0)
Block(1,19,-6,AIR:0)
Block(1,19,-5,contenttweaker:reinforced_concrete)
Block(1,19,-4,AIR:0)
Block(1,19,-3,AIR:0)
Block(1,19,-2,AIR:0)
Block(1,19,-1,AIR:0)
Block(1,19,0,AIR:0)
Block(1,19,1,contenttweaker:reinforced_concrete)
Block(1,20,-7,AIR:0)
Block(1,20,-6,AIR:0)
Block(1,20,-5,contenttweaker:reinforced_concrete)
Block(1,20,-4,AIR:0)
Block(1,20,-3,AIR:0)
Block(1,20,-2,AIR:0)
Block(1,20,-1,AIR:0)
Block(1,20,0,AIR:0)
Block(1,20,1,contenttweaker:reinforced_concrete)
Block(1,21,-7,AIR:0)
Block(1,21,-6,AIR:0)
Block(1,21,-5,contenttweaker:reinforced_concrete)
Block(1,21,-4,AIR:0)
Block(1,21,-3,AIR:0)
Block(1,21,-2,AIR:0)
Block(1,21,-1,contentcreator:concrete_slab_reinforced:1)
Block(1,21,0,contentcreator:concrete_slab_reinforced)
Block(1,21,1,contenttweaker:reinforced_concrete)
Block(1,22,-7,contenttweaker:reinforced_concrete)
Block(1,22,-6,contenttweaker:reinforced_concrete)
Block(1,22,-5,contenttweaker:reinforced_concrete)
Block(1,22,-4,contenttweaker:reinforced_concrete)
Block(1,22,-3,contenttweaker:reinforced_concrete)
Block(1,22,-2,contentcreator:concrete_slab_reinforced)
Block(1,22,-1,AIR:0)
Block(1,22,0,AIR:0)
Block(1,22,1,contenttweaker:reinforced_concrete)
Block(1,23,-3,contenttweaker:reinforced_concrete)
Block(1,23,-2,AIR:0)
Block(1,23,-1,AIR:0)
Block(1,23,0,AIR:0)
Block(1,23,1,contenttweaker:reinforced_concrete)
Block(1,24,-3,contenttweaker:reinforced_concrete)
Block(1,24,-2,AIR:0)
Block(1,24,-1,AIR:0)
Block(1,24,0,AIR:0)
Block(1,24,1,contenttweaker:reinforced_concrete)
Block(1,25,-3,contenttweaker:reinforced_concrete)
Block(1,25,-2,AIR:0)
Block(1,25,-1,contentcreator:concrete_slab_reinforced:1)
Block(1,25,0,contentcreator:concrete_slab_reinforced)
Block(1,25,1,contenttweaker:reinforced_concrete)
Block(1,26,-7,contenttweaker:reinforced_concrete)
Block(1,26,-6,contenttweaker:reinforced_concrete)
Block(1,26,-5,contenttweaker:reinforced_concrete)
Block(1,26,-4,contenttweaker:reinforced_concrete)
Block(1,26,-3,contenttweaker:reinforced_concrete)
Block(1,26,-2,contentcreator:concrete_slab_reinforced)
Block(1,26,-1,AIR:0)
Block(1,26,0,AIR:0)
Block(1,26,1,contenttweaker:reinforced_concrete)
Block(1,27,-7,AIR:0)
Block(1,27,-6,AIR:0)
Block(1,27,-5,AIR:0)
Block(1,27,-4,contenttweaker:reinforced_concrete)
Block(1,27,-3,AIR:0)
Block(1,27,-2,AIR:0)
Block(1,27,-1,AIR:0)
Block(1,27,0,AIR:0)
Block(1,27,1,contenttweaker:reinforced_concrete)
Block(1,28,-7,AIR:0)
Block(1,28,-6,AIR:0)
Block(1,28,-5,AIR:0)
Block(1,28,-4,contenttweaker:reinforced_concrete)
Block(1,28,-3,quark:iron_button:3)
Block(1,28,-2,AIR:0)
Block(1,28,-1,AIR:0)
Block(1,28,0,AIR:0)
Block(1,28,1,contenttweaker:reinforced_concrete)
Block(1,29,-7,contenttweaker:reinforced_concrete)
Block(1,29,-6,contenttweaker:reinforced_concrete)
Block(1,29,-5,contenttweaker:reinforced_concrete)
Block(1,29,-4,contenttweaker:reinforced_concrete)
Block(1,29,-3,contenttweaker:reinforced_concrete)
Block(1,29,-2,contenttweaker:reinforced_concrete)
Block(1,29,-1,contenttweaker:reinforced_concrete)
Block(1,29,0,contenttweaker:reinforced_concrete)
Block(1,29,1,contenttweaker:reinforced_concrete)
Block(2,0,-7,contenttweaker:reinforced_concrete)
Block(2,0,-6,contenttweaker:reinforced_concrete)
Block(2,0,-5,contenttweaker:reinforced_concrete)
Block(2,0,-4,contenttweaker:reinforced_concrete)
Block(2,0,-3,contenttweaker:reinforced_concrete)
Block(2,0,-2,contenttweaker:reinforced_concrete)
Block(2,0,-1,contenttweaker:reinforced_concrete)
Block(2,0,0,contenttweaker:reinforced_concrete)
Block(2,0,1,contenttweaker:reinforced_concrete)
Block(2,1,-6,contenttweaker:reinforced_concrete)
Block(2,1,-5,contenttweaker:reinforced_concrete)
Block(2,1,-4,contenttweaker:reinforced_concrete)
Block(2,1,-3,contenttweaker:reinforced_concrete)
Block(2,1,-2,contenttweaker:reinforced_concrete)
Block(2,1,-1,contenttweaker:reinforced_concrete)
Block(2,1,0,contenttweaker:reinforced_concrete)
Block(2,1,1,contenttweaker:reinforced_concrete)
Block(2,2,-6,contenttweaker:reinforced_concrete)
Block(2,2,-5,contenttweaker:reinforced_concrete)
Block(2,2,-4,contenttweaker:reinforced_concrete)
Block(2,2,-3,contenttweaker:reinforced_concrete)
Block(2,2,-2,contenttweaker:reinforced_concrete)
Block(2,2,-1,contenttweaker:reinforced_concrete)
Block(2,2,0,contenttweaker:reinforced_concrete)
Block(2,2,1,contenttweaker:reinforced_concrete)
Block(2,3,-6,AIR:0)
Block(2,3,-5,AIR:0)
Block(2,3,-4,AIR:0)
Block(2,3,-3,AIR:0)
Block(2,3,-2,AIR:0)
Block(2,3,-1,contenttweaker:reinforced_concrete)
Block(2,3,0,AIR:0)
Block(2,3,1,contenttweaker:reinforced_concrete)
Block(2,4,-6,AIR:0)
Block(2,4,-5,AIR:0)
Block(2,4,-4,AIR:0)
Block(2,4,-3,AIR:0)
Block(2,4,-2,AIR:0)
Block(2,4,-1,contenttweaker:reinforced_concrete)
Block(2,4,0,contentcreator:concrete_slab_reinforced:1)
Block(2,4,1,contenttweaker:reinforced_concrete)
Block(2,5,-6,AIR:0)
Block(2,5,-5,AIR:0)
Block(2,5,-4,AIR:0)
Block(2,5,-3,AIR:0)
Block(2,5,-2,variedcommodities:lamp,TeleportReceiver/24-variedcommodities_lampC0R16.nbt)
Block(2,5,-1,contenttweaker:reinforced_concrete)
Block(2,5,0,AIR:0)
Block(2,5,1,contenttweaker:reinforced_concrete)
Block(2,6,-6,contenttweaker:reinforced_concrete)
Block(2,6,-5,contenttweaker:reinforced_concrete)
Block(2,6,-4,contenttweaker:reinforced_concrete)
Block(2,6,-3,contenttweaker:reinforced_concrete)
Block(2,6,-2,contentcreator:concrete_slab_reinforced:1)
Block(2,6,-1,contenttweaker:reinforced_concrete)
Block(2,6,0,AIR:0)
Block(2,6,1,contenttweaker:reinforced_concrete)
Block(2,7,-6,contenttweaker:reinforced_concrete)
Block(2,7,-3,contenttweaker:reinforced_concrete)
Block(2,7,-2,AIR:0)
Block(2,7,-1,contenttweaker:reinforced_concrete)
Block(2,7,0,AIR:0)
Block(2,7,1,contenttweaker:reinforced_concrete)
Block(2,8,-7,contenttweaker:reinforced_concrete)
Block(2,8,-6,contenttweaker:reinforced_concrete)
Block(2,8,-3,contenttweaker:reinforced_concrete)
Block(2,8,-2,AIR:0)
Block(2,8,-1,contenttweaker:reinforced_concrete)
Block(2,8,0,contentcreator:concrete_slab_reinforced:1)
Block(2,8,1,contenttweaker:reinforced_concrete)
Block(2,9,-3,contenttweaker:reinforced_concrete)
Block(2,9,-2,AIR:0)
Block(2,9,-1,contenttweaker:reinforced_concrete)
Block(2,9,0,AIR:0)
Block(2,9,1,contenttweaker:reinforced_concrete)
Block(2,10,-3,contenttweaker:reinforced_concrete)
Block(2,10,-2,contentcreator:concrete_slab_reinforced:1)
Block(2,10,-1,contenttweaker:reinforced_concrete)
Block(2,10,0,AIR:0)
Block(2,10,1,contenttweaker:reinforced_concrete)
Block(2,11,-3,contenttweaker:reinforced_concrete)
Block(2,11,-2,AIR:0)
Block(2,11,-1,contenttweaker:reinforced_concrete)
Block(2,11,0,AIR:0)
Block(2,11,1,contenttweaker:reinforced_concrete)
Block(2,12,-3,contenttweaker:reinforced_concrete)
Block(2,12,-2,AIR:0)
Block(2,12,-1,contenttweaker:reinforced_concrete)
Block(2,12,0,contentcreator:concrete_slab_reinforced:1)
Block(2,12,1,contenttweaker:reinforced_concrete)
Block(2,13,-3,contenttweaker:reinforced_concrete)
Block(2,13,-2,AIR:0)
Block(2,13,-1,contenttweaker:reinforced_concrete)
Block(2,13,0,AIR:0)
Block(2,13,1,contenttweaker:reinforced_concrete)
Block(2,14,-3,contenttweaker:reinforced_concrete)
Block(2,14,-2,contentcreator:concrete_slab_reinforced:1)
Block(2,14,-1,contenttweaker:reinforced_concrete)
Block(2,14,0,AIR:0)
Block(2,14,1,contenttweaker:reinforced_concrete)
Block(2,15,-3,contenttweaker:reinforced_concrete)
Block(2,15,-2,AIR:0)
Block(2,15,-1,contenttweaker:reinforced_concrete)
Block(2,15,0,AIR:0)
Block(2,15,1,contenttweaker:reinforced_concrete)
Block(2,16,-3,contenttweaker:reinforced_concrete)
Block(2,16,-2,AIR:0)
Block(2,16,-1,contenttweaker:reinforced_concrete)
Block(2,16,0,contentcreator:concrete_slab_reinforced:1)
Block(2,16,1,contenttweaker:reinforced_concrete)
Block(2,17,-3,contenttweaker:reinforced_concrete)
Block(2,17,-2,AIR:0)
Block(2,17,-1,contenttweaker:reinforced_concrete)
Block(2,17,0,AIR:0)
Block(2,17,1,contenttweaker:reinforced_concrete)
Block(2,18,-7,contenttweaker:reinforced_concrete)
Block(2,18,-6,contenttweaker:reinforced_concrete)
Block(2,18,-5,contenttweaker:reinforced_concrete)
Block(2,18,-4,contenttweaker:reinforced_concrete)
Block(2,18,-3,contenttweaker:reinforced_concrete)
Block(2,18,-2,contentcreator:concrete_slab_reinforced:1)
Block(2,18,-1,contenttweaker:reinforced_concrete)
Block(2,18,0,AIR:0)
Block(2,18,1,contenttweaker:reinforced_concrete)
Block(2,19,-7,AIR:0)
Block(2,19,-6,AIR:0)
Block(2,19,-5,biomesoplenty:ebony_door_block)
Block(2,19,-4,AIR:0)
Block(2,19,-3,AIR:0)
Block(2,19,-2,AIR:0)
Block(2,19,-1,contenttweaker:reinforced_concrete)
Block(2,19,0,AIR:0)
Block(2,19,1,contenttweaker:reinforced_concrete)
Block(2,20,-7,AIR:0)
Block(2,20,-6,AIR:0)
Block(2,20,-5,biomesoplenty:ebony_door_block:9)
Block(2,20,-4,AIR:0)
Block(2,20,-3,AIR:0)
Block(2,20,-2,AIR:0)
Block(2,20,-1,contenttweaker:reinforced_concrete)
Block(2,20,0,contentcreator:concrete_slab_reinforced:1)
Block(2,20,1,contenttweaker:reinforced_concrete)
Block(2,21,-7,AIR:0)
Block(2,21,-6,AIR:0)
Block(2,21,-5,contenttweaker:reinforced_concrete)
Block(2,21,-4,AIR:0)
Block(2,21,-3,AIR:0)
Block(2,21,-2,AIR:0)
Block(2,21,-1,contenttweaker:reinforced_concrete)
Block(2,21,0,AIR:0)
Block(2,21,1,contenttweaker:reinforced_concrete)
Block(2,22,-7,contenttweaker:reinforced_concrete)
Block(2,22,-6,contenttweaker:reinforced_concrete)
Block(2,22,-5,contenttweaker:reinforced_concrete)
Block(2,22,-4,contenttweaker:reinforced_concrete)
Block(2,22,-3,contenttweaker:reinforced_concrete)
Block(2,22,-2,contentcreator:concrete_slab_reinforced:1)
Block(2,22,-1,contenttweaker:reinforced_concrete)
Block(2,22,0,AIR:0)
Block(2,22,1,contenttweaker:reinforced_concrete)
Block(2,23,-3,contenttweaker:reinforced_concrete)
Block(2,23,-2,AIR:0)
Block(2,23,-1,contenttweaker:reinforced_concrete)
Block(2,23,0,AIR:0)
Block(2,23,1,contenttweaker:reinforced_concrete)
Block(2,24,-3,contenttweaker:reinforced_concrete)
Block(2,24,-2,AIR:0)
Block(2,24,-1,contenttweaker:reinforced_concrete)
Block(2,24,0,contentcreator:concrete_slab_reinforced:1)
Block(2,24,1,contenttweaker:reinforced_concrete)
Block(2,25,-3,contenttweaker:reinforced_concrete)
Block(2,25,-2,AIR:0)
Block(2,25,-1,contenttweaker:reinforced_concrete)
Block(2,25,0,AIR:0)
Block(2,25,1,contenttweaker:reinforced_concrete)
Block(2,26,-7,contenttweaker:reinforced_concrete)
Block(2,26,-6,contenttweaker:reinforced_concrete)
Block(2,26,-5,contenttweaker:reinforced_concrete)
Block(2,26,-4,contenttweaker:reinforced_concrete)
Block(2,26,-3,contenttweaker:reinforced_concrete)
Block(2,26,-2,contentcreator:concrete_slab_reinforced:1)
Block(2,26,-1,contenttweaker:reinforced_concrete)
Block(2,26,0,AIR:0)
Block(2,26,1,contenttweaker:reinforced_concrete)
Block(2,27,-7,AIR:0)
Block(2,27,-6,AIR:0)
Block(2,27,-5,AIR:0)
Block(2,27,-4,nuclearcraft:reactor_door:1)
Block(2,27,-3,AIR:0)
Block(2,27,-2,AIR:0)
Block(2,27,-1,contenttweaker:reinforced_concrete)
Block(2,27,0,AIR:0)
Block(2,27,1,contenttweaker:reinforced_concrete)
Block(2,28,-7,AIR:0)
Block(2,28,-6,AIR:0)
Block(2,28,-5,AIR:0)
Block(2,28,-4,nuclearcraft:reactor_door:8)
Block(2,28,-3,AIR:0)
Block(2,28,-2,AIR:0)
Block(2,28,-1,contenttweaker:reinforced_concrete)
Block(2,28,0,variedcommodities:lamp,TeleportReceiver/28-variedcommodities_lampC0R16.nbt)
Block(2,28,1,contenttweaker:reinforced_concrete)
Block(2,29,-7,contenttweaker:reinforced_concrete)
Block(2,29,-6,contenttweaker:reinforced_concrete)
Block(2,29,-5,contenttweaker:reinforced_concrete)
Block(2,29,-4,contenttweaker:reinforced_concrete)
Block(2,29,-3,contenttweaker:reinforced_concrete)
Block(2,29,-2,contenttweaker:reinforced_concrete)
Block(2,29,-1,contenttweaker:reinforced_concrete)
Block(2,29,0,contenttweaker:reinforced_concrete)
Block(2,29,1,contenttweaker:reinforced_concrete)
Block(3,0,-7,contenttweaker:reinforced_concrete)
Block(3,0,-6,contenttweaker:reinforced_concrete)
Block(3,0,-5,contenttweaker:reinforced_concrete)
Block(3,0,-4,contenttweaker:reinforced_concrete)
Block(3,0,-3,contenttweaker:reinforced_concrete)
Block(3,0,-2,contenttweaker:reinforced_concrete)
Block(3,0,-1,contenttweaker:reinforced_concrete)
Block(3,0,0,contenttweaker:reinforced_concrete)
Block(3,0,1,contenttweaker:reinforced_concrete)
Block(3,1,-6,contenttweaker:reinforced_concrete)
Block(3,1,-5,contenttweaker:reinforced_concrete)
Block(3,1,-4,contenttweaker:reinforced_concrete)
Block(3,1,-3,contenttweaker:reinforced_concrete)
Block(3,1,-2,contenttweaker:reinforced_concrete)
Block(3,1,-1,contenttweaker:reinforced_concrete)
Block(3,1,0,contenttweaker:reinforced_concrete)
Block(3,1,1,contenttweaker:reinforced_concrete)
Block(3,2,-6,contenttweaker:reinforced_concrete)
Block(3,2,-5,contenttweaker:reinforced_concrete)
Block(3,2,-4,contenttweaker:reinforced_concrete)
Block(3,2,-3,contenttweaker:reinforced_concrete)
Block(3,2,-2,contenttweaker:reinforced_concrete)
Block(3,2,-1,contenttweaker:reinforced_concrete)
Block(3,2,0,contenttweaker:reinforced_concrete)
Block(3,2,1,contenttweaker:reinforced_concrete)
Block(3,3,-6,AIR:0)
Block(3,3,-5,AIR:0)
Block(3,3,-4,AIR:0)
Block(3,3,-3,AIR:0)
Block(3,3,-2,contentcreator:concrete_slab_reinforced)
Block(3,3,-1,contentcreator:concrete_slab_reinforced:1)
Block(3,3,0,AIR:0)
Block(3,3,1,contenttweaker:reinforced_concrete)
Block(3,4,-6,AIR:0)
Block(3,4,-5,AIR:0)
Block(3,4,-4,AIR:0)
Block(3,4,-3,AIR:0)
Block(3,4,-2,AIR:0)
Block(3,4,-1,AIR:0)
Block(3,4,0,contentcreator:concrete_slab_reinforced)
Block(3,4,1,contenttweaker:reinforced_concrete)
Block(3,5,-6,AIR:0)
Block(3,5,-5,AIR:0)
Block(3,5,-4,AIR:0)
Block(3,5,-3,AIR:0)
Block(3,5,-2,AIR:0)
Block(3,5,-1,AIR:0)
Block(3,5,0,AIR:0)
Block(3,5,1,contenttweaker:reinforced_concrete)
Block(3,6,-6,contenttweaker:reinforced_concrete)
Block(3,6,-5,contenttweaker:reinforced_concrete)
Block(3,6,-4,contenttweaker:reinforced_concrete)
Block(3,6,-3,contenttweaker:reinforced_concrete)
Block(3,6,-2,AIR:0)
Block(3,6,-1,AIR:0)
Block(3,6,0,AIR:0)
Block(3,6,1,contenttweaker:reinforced_concrete)
Block(3,7,-6,contenttweaker:reinforced_concrete)
Block(3,7,-3,contenttweaker:reinforced_concrete)
Block(3,7,-2,contentcreator:concrete_slab_reinforced)
Block(3,7,-1,contentcreator:concrete_slab_reinforced:1)
Block(3,7,0,AIR:0)
Block(3,7,1,contenttweaker:reinforced_concrete)
Block(3,8,-7,contenttweaker:reinforced_concrete)
Block(3,8,-6,contenttweaker:reinforced_concrete)
Block(3,8,-3,contenttweaker:reinforced_concrete)
Block(3,8,-2,AIR:0)
Block(3,8,-1,AIR:0)
Block(3,8,0,contentcreator:concrete_slab_reinforced)
Block(3,8,1,contenttweaker:reinforced_concrete)
Block(3,9,-3,contenttweaker:reinforced_concrete)
Block(3,9,-2,AIR:0)
Block(3,9,-1,AIR:0)
Block(3,9,0,AIR:0)
Block(3,9,1,contenttweaker:reinforced_concrete)
Block(3,10,-3,contenttweaker:reinforced_concrete)
Block(3,10,-2,AIR:0)
Block(3,10,-1,AIR:0)
Block(3,10,0,AIR:0)
Block(3,10,1,contenttweaker:reinforced_concrete)
Block(3,11,-3,contenttweaker:reinforced_concrete)
Block(3,11,-2,contentcreator:concrete_slab_reinforced)
Block(3,11,-1,contentcreator:concrete_slab_reinforced:1)
Block(3,11,0,AIR:0)
Block(3,11,1,contenttweaker:reinforced_concrete)
Block(3,12,-3,contenttweaker:reinforced_concrete)
Block(3,12,-2,AIR:0)
Block(3,12,-1,AIR:0)
Block(3,12,0,contentcreator:concrete_slab_reinforced)
Block(3,12,1,contenttweaker:reinforced_concrete)
Block(3,13,-3,contenttweaker:reinforced_concrete)
Block(3,13,-2,AIR:0)
Block(3,13,-1,AIR:0)
Block(3,13,0,AIR:0)
Block(3,13,1,contenttweaker:reinforced_concrete)
Block(3,14,-3,contenttweaker:reinforced_concrete)
Block(3,14,-2,AIR:0)
Block(3,14,-1,AIR:0)
Block(3,14,0,AIR:0)
Block(3,14,1,contenttweaker:reinforced_concrete)
Block(3,15,-3,contenttweaker:reinforced_concrete)
Block(3,15,-2,contentcreator:concrete_slab_reinforced)
Block(3,15,-1,contentcreator:concrete_slab_reinforced:1)
Block(3,15,0,AIR:0)
Block(3,15,1,contenttweaker:reinforced_concrete)
Block(3,16,-3,contenttweaker:reinforced_concrete)
Block(3,16,-2,AIR:0)
Block(3,16,-1,AIR:0)
Block(3,16,0,contentcreator:concrete_slab_reinforced)
Block(3,16,1,contenttweaker:reinforced_concrete)
Block(3,17,-3,contenttweaker:reinforced_concrete)
Block(3,17,-2,AIR:0)
Block(3,17,-1,AIR:0)
Block(3,17,0,AIR:0)
Block(3,17,1,contenttweaker:reinforced_concrete)
Block(3,18,-7,contenttweaker:reinforced_concrete)
Block(3,18,-6,contenttweaker:reinforced_concrete)
Block(3,18,-5,contenttweaker:reinforced_concrete)
Block(3,18,-4,contenttweaker:reinforced_concrete)
Block(3,18,-3,contenttweaker:reinforced_concrete)
Block(3,18,-2,AIR:0)
Block(3,18,-1,AIR:0)
Block(3,18,0,AIR:0)
Block(3,18,1,contenttweaker:reinforced_concrete)
Block(3,19,-7,AIR:0)
Block(3,19,-6,AIR:0)
Block(3,19,-5,contenttweaker:reinforced_concrete)
Block(3,19,-4,AIR:0)
Block(3,19,-3,AIR:0)
Block(3,19,-2,contentcreator:concrete_slab_reinforced)
Block(3,19,-1,contentcreator:concrete_slab_reinforced:1)
Block(3,19,0,AIR:0)
Block(3,19,1,contenttweaker:reinforced_concrete)
Block(3,20,-7,AIR:0)
Block(3,20,-6,AIR:0)
Block(3,20,-5,contenttweaker:reinforced_concrete)
Block(3,20,-4,AIR:0)
Block(3,20,-3,AIR:0)
Block(3,20,-2,AIR:0)
Block(3,20,-1,AIR:0)
Block(3,20,0,contentcreator:concrete_slab_reinforced)
Block(3,20,1,contenttweaker:reinforced_concrete)
Block(3,21,-7,AIR:0)
Block(3,21,-6,AIR:0)
Block(3,21,-5,contenttweaker:reinforced_concrete)
Block(3,21,-4,AIR:0)
Block(3,21,-3,AIR:0)
Block(3,21,-2,AIR:0)
Block(3,21,-1,AIR:0)
Block(3,21,0,AIR:0)
Block(3,21,1,contenttweaker:reinforced_concrete)
Block(3,22,-7,contenttweaker:reinforced_concrete)
Block(3,22,-6,contenttweaker:reinforced_concrete)
Block(3,22,-5,contenttweaker:reinforced_concrete)
Block(3,22,-4,contenttweaker:reinforced_concrete)
Block(3,22,-3,contenttweaker:reinforced_concrete)
Block(3,22,-2,AIR:0)
Block(3,22,-1,AIR:0)
Block(3,22,0,AIR:0)
Block(3,22,1,contenttweaker:reinforced_concrete)
Block(3,23,-3,contenttweaker:reinforced_concrete)
Block(3,23,-2,contentcreator:concrete_slab_reinforced)
Block(3,23,-1,contentcreator:concrete_slab_reinforced:1)
Block(3,23,0,AIR:0)
Block(3,23,1,contenttweaker:reinforced_concrete)
Block(3,24,-3,contenttweaker:reinforced_concrete)
Block(3,24,-2,AIR:0)
Block(3,24,-1,AIR:0)
Block(3,24,0,contentcreator:concrete_slab_reinforced)
Block(3,24,1,contenttweaker:reinforced_concrete)
Block(3,25,-3,contenttweaker:reinforced_concrete)
Block(3,25,-2,AIR:0)
Block(3,25,-1,AIR:0)
Block(3,25,0,AIR:0)
Block(3,25,1,contenttweaker:reinforced_concrete)
Block(3,26,-7,contenttweaker:reinforced_concrete)
Block(3,26,-6,contenttweaker:reinforced_concrete)
Block(3,26,-5,contenttweaker:reinforced_concrete)
Block(3,26,-4,contenttweaker:reinforced_concrete)
Block(3,26,-3,contenttweaker:reinforced_concrete)
Block(3,26,-2,contentcreator:concrete_slab_reinforced:1)
Block(3,26,-1,contentcreator:concrete_slab_reinforced:1)
Block(3,26,0,AIR:0)
Block(3,26,1,contenttweaker:reinforced_concrete)
Block(3,27,-7,AIR:0)
Block(3,27,-6,AIR:0)
Block(3,27,-5,AIR:0)
Block(3,27,-4,contenttweaker:reinforced_concrete)
Block(3,27,-3,AIR:0)
Block(3,27,-2,AIR:0)
Block(3,27,-1,rustic:iron_lattice:0)
Block(3,27,0,AIR:0)
Block(3,27,1,contenttweaker:reinforced_concrete)
Block(3,28,-7,AIR:0)
Block(3,28,-6,AIR:0)
Block(3,28,-5,quark:iron_button)
Block(3,28,-4,contenttweaker:reinforced_concrete)
Block(3,28,-3,quark:iron_button:3)
Block(3,28,-2,AIR:0)
Block(3,28,-1,rustic:iron_lattice:0)
Block(3,28,0,AIR:0)
Block(3,28,1,contenttweaker:reinforced_concrete)
Block(3,29,-7,contenttweaker:reinforced_concrete)
Block(3,29,-6,contenttweaker:reinforced_concrete)
Block(3,29,-5,contenttweaker:reinforced_concrete)
Block(3,29,-4,contenttweaker:reinforced_concrete)
Block(3,29,-3,contenttweaker:reinforced_concrete)
Block(3,29,-2,contenttweaker:reinforced_concrete)
Block(3,29,-1,contenttweaker:reinforced_concrete)
Block(3,29,0,contenttweaker:reinforced_concrete)
Block(3,29,1,contenttweaker:reinforced_concrete)
Block(4,0,-7,contenttweaker:reinforced_concrete)
Block(4,0,-6,contenttweaker:reinforced_concrete)
Block(4,0,-5,contenttweaker:reinforced_concrete)
Block(4,0,-4,contenttweaker:reinforced_concrete)
Block(4,0,-3,contenttweaker:reinforced_concrete)
Block(4,0,-2,contenttweaker:reinforced_concrete)
Block(4,0,-1,contenttweaker:reinforced_concrete)
Block(4,0,0,contenttweaker:reinforced_concrete)
Block(4,0,1,contenttweaker:reinforced_concrete)
Block(4,1,-6,contenttweaker:reinforced_concrete)
Block(4,1,-5,contenttweaker:reinforced_concrete)
Block(4,1,-4,contenttweaker:reinforced_concrete)
Block(4,1,-3,contenttweaker:reinforced_concrete)
Block(4,1,-2,contenttweaker:reinforced_concrete)
Block(4,1,-1,contenttweaker:reinforced_concrete)
Block(4,1,0,contenttweaker:reinforced_concrete)
Block(4,1,1,contenttweaker:reinforced_concrete)
Block(4,2,-6,contenttweaker:reinforced_concrete)
Block(4,2,-5,contenttweaker:reinforced_concrete)
Block(4,2,-4,contenttweaker:reinforced_concrete)
Block(4,2,-3,contenttweaker:reinforced_concrete)
Block(4,2,-2,contenttweaker:reinforced_concrete)
Block(4,2,-1,contenttweaker:reinforced_concrete)
Block(4,2,0,contenttweaker:reinforced_concrete)
Block(4,2,1,contenttweaker:reinforced_concrete)
Block(4,3,-6,contenttweaker:reinforced_concrete)
Block(4,3,-5,AIR:0)
Entity(4,3,-4,minecraft:vindication_illager,1,../nbt/vindicator.txt)
Block(4,3,-4,AIR:0)
Block(4,3,-3,AIR:0)
Block(4,3,-2,contenttweaker:reinforced_concrete)
Block(4,3,-1,contenttweaker:reinforced_concrete)
Block(4,3,0,contenttweaker:reinforced_concrete)
Block(4,3,1,contenttweaker:reinforced_concrete)
Block(4,4,-6,contenttweaker:reinforced_concrete)
Block(4,4,-5,AIR:0)
Block(4,4,-4,AIR:0)
Block(4,4,-3,AIR:0)
Block(4,4,-2,contenttweaker:reinforced_concrete)
Block(4,4,-1,contenttweaker:reinforced_concrete)
Block(4,4,0,contenttweaker:reinforced_concrete)
Block(4,4,1,contenttweaker:reinforced_concrete)
Block(4,5,-6,contenttweaker:reinforced_concrete)
Block(4,5,-5,contenttweaker:reinforced_concrete)
Block(4,5,-4,contenttweaker:reinforced_concrete)
Block(4,5,-3,contenttweaker:reinforced_concrete)
Block(4,5,-2,contenttweaker:reinforced_concrete)
Block(4,5,-1,contenttweaker:reinforced_concrete)
Block(4,5,0,contenttweaker:reinforced_concrete)
Block(4,5,1,contenttweaker:reinforced_concrete)
Block(4,6,-6,contenttweaker:reinforced_concrete)
Block(4,6,-5,contenttweaker:reinforced_concrete)
Block(4,6,-4,contenttweaker:reinforced_concrete)
Block(4,6,-3,contenttweaker:reinforced_concrete)
Block(4,6,-2,contenttweaker:reinforced_concrete)
Block(4,6,-1,contenttweaker:reinforced_concrete)
Block(4,6,0,contenttweaker:reinforced_concrete)
Block(4,6,1,contenttweaker:reinforced_concrete)
Block(4,7,-6,contenttweaker:reinforced_concrete)
Block(4,7,-3,contenttweaker:reinforced_concrete)
Block(4,7,-2,contenttweaker:reinforced_concrete)
Block(4,7,-1,contenttweaker:reinforced_concrete)
Block(4,7,0,contenttweaker:reinforced_concrete)
Block(4,7,1,contenttweaker:reinforced_concrete)
Block(4,8,-7,contenttweaker:reinforced_concrete)
Block(4,8,-6,contenttweaker:reinforced_concrete)
Block(4,8,-3,contenttweaker:reinforced_concrete)
Block(4,8,-2,contenttweaker:reinforced_concrete)
Block(4,8,-1,contenttweaker:reinforced_concrete)
Block(4,8,0,contenttweaker:reinforced_concrete)
Block(4,8,1,contenttweaker:reinforced_concrete)
Block(4,9,-3,contenttweaker:reinforced_concrete)
Block(4,9,-2,contenttweaker:reinforced_concrete)
Block(4,9,-1,contenttweaker:reinforced_concrete)
Block(4,9,0,contenttweaker:reinforced_concrete)
Block(4,9,1,contenttweaker:reinforced_concrete)
Block(4,10,-3,contenttweaker:reinforced_concrete)
Block(4,10,-2,contenttweaker:reinforced_concrete)
Block(4,10,-1,contenttweaker:reinforced_concrete)
Block(4,10,0,contenttweaker:reinforced_concrete)
Block(4,10,1,contenttweaker:reinforced_concrete)
Block(4,11,-3,contenttweaker:reinforced_concrete)
Block(4,11,-2,contenttweaker:reinforced_concrete)
Block(4,11,-1,contenttweaker:reinforced_concrete)
Block(4,11,0,contenttweaker:reinforced_concrete)
Block(4,11,1,contenttweaker:reinforced_concrete)
Block(4,12,-3,contenttweaker:reinforced_concrete)
Block(4,12,-2,contenttweaker:reinforced_concrete)
Block(4,12,-1,contenttweaker:reinforced_concrete)
Block(4,12,0,contenttweaker:reinforced_concrete)
Block(4,12,1,contenttweaker:reinforced_concrete)
Block(4,13,-3,contenttweaker:reinforced_concrete)
Block(4,13,-2,contenttweaker:reinforced_concrete)
Block(4,13,-1,contenttweaker:reinforced_concrete)
Block(4,13,0,contenttweaker:reinforced_concrete)
Block(4,13,1,contenttweaker:reinforced_concrete)
Block(4,14,-3,contenttweaker:reinforced_concrete)
Block(4,14,-2,contenttweaker:reinforced_concrete)
Block(4,14,-1,contenttweaker:reinforced_concrete)
Block(4,14,0,contenttweaker:reinforced_concrete)
Block(4,14,1,contenttweaker:reinforced_concrete)
Block(4,15,-3,contenttweaker:reinforced_concrete)
Block(4,15,-2,contenttweaker:reinforced_concrete)
Block(4,15,-1,contenttweaker:reinforced_concrete)
Block(4,15,0,contenttweaker:reinforced_concrete)
Block(4,15,1,contenttweaker:reinforced_concrete)
Block(4,16,-3,contenttweaker:reinforced_concrete)
Block(4,16,-2,contenttweaker:reinforced_concrete)
Block(4,16,-1,contenttweaker:reinforced_concrete)
Block(4,16,0,contenttweaker:reinforced_concrete)
Block(4,16,1,contenttweaker:reinforced_concrete)
Block(4,17,-3,contenttweaker:reinforced_concrete)
Block(4,17,-2,contenttweaker:reinforced_concrete)
Block(4,17,-1,contenttweaker:reinforced_concrete)
Block(4,17,0,contenttweaker:reinforced_concrete)
Block(4,17,1,contenttweaker:reinforced_concrete)
Block(4,18,-7,contenttweaker:reinforced_concrete)
Block(4,18,-6,contenttweaker:reinforced_concrete)
Block(4,18,-5,contenttweaker:reinforced_concrete)
Block(4,18,-4,contenttweaker:reinforced_concrete)
Block(4,18,-3,contenttweaker:reinforced_concrete)
Block(4,18,-2,contenttweaker:reinforced_concrete)
Block(4,18,-1,contenttweaker:reinforced_concrete)
Block(4,18,0,contenttweaker:reinforced_concrete)
Block(4,18,1,contenttweaker:reinforced_concrete)
Block(4,19,-7,contenttweaker:reinforced_concrete)
Block(4,19,-6,contenttweaker:reinforced_concrete)
Block(4,19,-5,contenttweaker:reinforced_concrete)
Block(4,19,-4,contenttweaker:reinforced_concrete)
Block(4,19,-3,contenttweaker:reinforced_concrete)
Block(4,19,-2,contenttweaker:reinforced_concrete)
Block(4,19,-1,contenttweaker:reinforced_concrete)
Block(4,19,0,contenttweaker:reinforced_concrete)
Block(4,19,1,contenttweaker:reinforced_concrete)
Block(4,20,-7,contenttweaker:reinforced_concrete)
Block(4,20,-6,contenttweaker:reinforced_concrete)
Block(4,20,-5,contenttweaker:reinforced_concrete)
Block(4,20,-4,contenttweaker:reinforced_concrete)
Block(4,20,-3,contenttweaker:reinforced_concrete)
Block(4,20,-2,contenttweaker:reinforced_concrete)
Block(4,20,-1,contenttweaker:reinforced_concrete)
Block(4,20,0,contenttweaker:reinforced_concrete)
Block(4,20,1,contenttweaker:reinforced_concrete)
Block(4,21,-7,contenttweaker:reinforced_concrete)
Block(4,21,-6,contenttweaker:reinforced_concrete)
Block(4,21,-5,contenttweaker:reinforced_concrete)
Block(4,21,-4,contenttweaker:reinforced_concrete)
Block(4,21,-3,contenttweaker:reinforced_concrete)
Block(4,21,-2,contenttweaker:reinforced_concrete)
Block(4,21,-1,contenttweaker:reinforced_concrete)
Block(4,21,0,contenttweaker:reinforced_concrete)
Block(4,21,1,contenttweaker:reinforced_concrete)
Block(4,22,-7,contenttweaker:reinforced_concrete)
Block(4,22,-6,contenttweaker:reinforced_concrete)
Block(4,22,-5,contenttweaker:reinforced_concrete)
Block(4,22,-4,contenttweaker:reinforced_concrete)
Block(4,22,-3,contenttweaker:reinforced_concrete)
Block(4,22,-2,contenttweaker:reinforced_concrete)
Block(4,22,-1,contenttweaker:reinforced_concrete)
Block(4,22,0,contenttweaker:reinforced_concrete)
Block(4,22,1,contenttweaker:reinforced_concrete)
Block(4,23,-3,contenttweaker:reinforced_concrete)
Block(4,23,-2,contenttweaker:reinforced_concrete)
Block(4,23,-1,contenttweaker:reinforced_concrete)
Block(4,23,0,contenttweaker:reinforced_concrete)
Block(4,23,1,contenttweaker:reinforced_concrete)
Block(4,24,-3,contenttweaker:reinforced_concrete)
Block(4,24,-2,contenttweaker:reinforced_concrete)
Block(4,24,-1,contenttweaker:reinforced_concrete)
Block(4,24,0,contenttweaker:reinforced_concrete)
Block(4,24,1,contenttweaker:reinforced_concrete)
Block(4,25,-3,contenttweaker:reinforced_concrete)
Block(4,25,-2,contenttweaker:reinforced_concrete)
Block(4,25,-1,contenttweaker:reinforced_concrete)
Block(4,25,0,contenttweaker:reinforced_concrete)
Block(4,25,1,contenttweaker:reinforced_concrete)
Block(4,26,-7,contenttweaker:reinforced_concrete)
Block(4,26,-6,contenttweaker:reinforced_concrete)
Block(4,26,-5,contenttweaker:reinforced_concrete)
Block(4,26,-4,contenttweaker:reinforced_concrete)
Block(4,26,-3,contenttweaker:reinforced_concrete)
Block(4,26,-2,contenttweaker:reinforced_concrete)
Block(4,26,-1,contenttweaker:reinforced_concrete)
Block(4,26,0,contenttweaker:reinforced_concrete)
Block(4,26,1,contenttweaker:reinforced_concrete)
Block(4,27,-7,contenttweaker:reinforced_concrete)
Block(4,27,-6,contenttweaker:reinforced_concrete)
Block(4,27,-5,contenttweaker:reinforced_concrete)
Block(4,27,-4,contenttweaker:reinforced_concrete)
Block(4,27,-3,contenttweaker:reinforced_concrete)
Block(4,27,-2,contenttweaker:reinforced_concrete)
Block(4,27,-1,contenttweaker:reinforced_concrete)
Block(4,27,0,contenttweaker:reinforced_concrete)
Block(4,27,1,contenttweaker:reinforced_concrete)
Block(4,28,-7,contenttweaker:reinforced_concrete)
Block(4,28,-6,contenttweaker:reinforced_concrete)
Block(4,28,-5,contenttweaker:reinforced_concrete)
Block(4,28,-4,contenttweaker:reinforced_concrete)
Block(4,28,-3,contenttweaker:reinforced_concrete)
Block(4,28,-2,contenttweaker:reinforced_concrete)
Block(4,28,-1,contenttweaker:reinforced_concrete)
Block(4,28,0,contenttweaker:reinforced_concrete)
Block(4,28,1,contenttweaker:reinforced_concrete)
Block(4,29,-7,contenttweaker:reinforced_concrete)
Block(4,29,-6,contenttweaker:reinforced_concrete)
Block(4,29,-5,contenttweaker:reinforced_concrete)
Block(4,29,-4,contenttweaker:reinforced_concrete)
Block(4,29,-3,contenttweaker:reinforced_concrete)
Block(4,29,-2,contenttweaker:reinforced_concrete)
Block(4,29,-1,contenttweaker:reinforced_concrete)
Block(4,29,0,contenttweaker:reinforced_concrete)
Block(4,29,1,contenttweaker:reinforced_concrete)
Block(5,0,-7,contenttweaker:reinforced_concrete)
Block(5,0,-6,contenttweaker:reinforced_concrete)
Block(5,0,-5,contenttweaker:reinforced_concrete)
Block(5,0,-4,contenttweaker:reinforced_concrete)
Block(5,0,-3,contenttweaker:reinforced_concrete)
Block(5,0,-2,contenttweaker:reinforced_concrete)
Block(5,1,-6,contenttweaker:reinforced_concrete)
Block(5,1,-5,contenttweaker:reinforced_concrete)
Block(5,1,-4,contenttweaker:reinforced_concrete)
Block(5,1,-3,contenttweaker:reinforced_concrete)
Block(5,1,-2,contenttweaker:reinforced_concrete)
Block(5,2,-6,contenttweaker:reinforced_concrete)
Block(5,2,-5,contenttweaker:reinforced_concrete)
Block(5,2,-4,contenttweaker:reinforced_concrete)
Block(5,2,-3,contenttweaker:reinforced_concrete)
Block(5,2,-2,contenttweaker:reinforced_concrete)
Block(5,3,-6,contenttweaker:reinforced_concrete)
Block(5,3,-5,AIR:0)
Block(5,3,-4,AIR:0)
Block(5,3,-3,AIR:0)
Block(5,3,-2,contenttweaker:reinforced_concrete)
Block(5,4,-6,contenttweaker:reinforced_concrete)
Block(5,4,-5,AIR:0)
Block(5,4,-4,AIR:0)
Block(5,4,-3,AIR:0)
Block(5,4,-2,contenttweaker:reinforced_concrete)
Block(5,5,-6,contenttweaker:reinforced_concrete)
Block(5,5,-5,contenttweaker:reinforced_concrete)
Block(5,5,-4,contenttweaker:reinforced_concrete)
Block(5,5,-3,contenttweaker:reinforced_concrete)
Block(5,5,-2,contenttweaker:reinforced_concrete)
Block(5,6,-6,contenttweaker:reinforced_concrete)
Block(5,7,-6,contenttweaker:reinforced_concrete)
Block(5,8,-7,contenttweaker:reinforced_concrete)
Block(5,8,-6,contenttweaker:reinforced_concrete)
Block(6,0,-7,contenttweaker:reinforced_concrete)
Block(6,0,-6,contenttweaker:reinforced_concrete)
Block(6,0,-5,contenttweaker:reinforced_concrete)
Block(6,0,-4,contenttweaker:reinforced_concrete)
Block(6,0,-3,contenttweaker:reinforced_concrete)
Block(6,0,-2,contenttweaker:reinforced_concrete)
Block(6,1,-6,contenttweaker:reinforced_concrete)
Block(6,1,-5,contenttweaker:reinforced_concrete)
Block(6,1,-4,contenttweaker:reinforced_concrete)
Block(6,1,-3,contenttweaker:reinforced_concrete)
Block(6,1,-2,contenttweaker:reinforced_concrete)
Block(6,2,-6,contenttweaker:reinforced_concrete)
Block(6,2,-5,contenttweaker:reinforced_concrete)
Block(6,2,-4,contenttweaker:reinforced_concrete)
Block(6,2,-3,contenttweaker:reinforced_concrete)
Block(6,2,-2,contenttweaker:reinforced_concrete)
Block(6,3,-6,contenttweaker:reinforced_concrete)
Block(6,3,-5,AIR:0)
Block(6,3,-4,AIR:0)
Block(6,3,-3,contenttweaker:resource_crate)
Block(6,3,-2,contenttweaker:reinforced_concrete)
Block(6,4,-6,contenttweaker:reinforced_concrete)
Block(6,4,-5,AIR:0)
Block(6,4,-4,AIR:0)
Block(6,4,-3,contenttweaker:resource_crate)
Block(6,4,-2,contenttweaker:reinforced_concrete)
Block(6,5,-6,contenttweaker:reinforced_concrete)
Block(6,5,-5,contenttweaker:reinforced_concrete)
Block(6,5,-4,contenttweaker:reinforced_concrete)
Block(6,5,-3,contenttweaker:reinforced_concrete)
Block(6,5,-2,contenttweaker:reinforced_concrete)
Block(6,6,-6,contenttweaker:reinforced_concrete)
Block(6,7,-6,contenttweaker:reinforced_concrete)
Block(6,8,-7,contenttweaker:reinforced_concrete)
Block(6,8,-6,contenttweaker:reinforced_concrete)
Block(7,0,-7,contenttweaker:reinforced_concrete)
Block(7,0,-6,contenttweaker:reinforced_concrete)
Block(7,0,-5,contenttweaker:reinforced_concrete)
Block(7,0,-4,contenttweaker:reinforced_concrete)
Block(7,0,-3,contenttweaker:reinforced_concrete)
Block(7,0,-2,contenttweaker:reinforced_concrete)
Block(7,1,-6,contenttweaker:reinforced_concrete)
Block(7,1,-5,contenttweaker:reinforced_concrete)
Block(7,1,-4,contenttweaker:reinforced_concrete)
Block(7,1,-3,contenttweaker:reinforced_concrete)
Block(7,1,-2,contenttweaker:reinforced_concrete)
Block(7,2,-6,contenttweaker:reinforced_concrete)
Block(7,2,-5,contenttweaker:reinforced_concrete)
Block(7,2,-4,contenttweaker:reinforced_concrete)
Block(7,2,-3,contenttweaker:reinforced_concrete)
Block(7,2,-2,contenttweaker:reinforced_concrete)
Block(7,3,-6,contenttweaker:reinforced_concrete)
Block(7,3,-5,contenttweaker:resource_crate)
Entity(7,3,-4,minecraft:vindication_illager,1,../nbt/vindicator.txt)
Block(7,3,-4,AIR:0)
Block(7,3,-3,AIR:0)
Block(7,3,-2,contenttweaker:reinforced_concrete)
Block(7,4,-6,contenttweaker:reinforced_concrete)
Block(7,4,-5,AIR:0)
Block(7,4,-4,AIR:0)
Block(7,4,-3,AIR:0)
Block(7,4,-2,contenttweaker:reinforced_concrete)
Block(7,5,-6,contenttweaker:reinforced_concrete)
Block(7,5,-5,contenttweaker:reinforced_concrete)
Block(7,5,-4,contenttweaker:reinforced_concrete)
Block(7,5,-3,contenttweaker:reinforced_concrete)
Block(7,5,-2,contenttweaker:reinforced_concrete)
Block(7,6,-6,contenttweaker:reinforced_concrete)
Block(7,7,-6,contenttweaker:reinforced_concrete)
Block(7,8,-7,contenttweaker:reinforced_concrete)
Block(7,8,-6,contenttweaker:reinforced_concrete)
Block(-7,1,-7,dimstack:bedrock)
Block(-7,2,-7,dimstack:bedrock)
Block(-7,3,-7,dimstack:bedrock)
Block(-7,4,-7,dimstack:bedrock)
Block(-7,5,-7,dimstack:bedrock)
Block(-7,6,-7,dimstack:bedrock)
Block(-7,7,-7,dimstack:bedrock)
Block(-6,1,-7,dimstack:bedrock)
Block(-6,2,-7,dimstack:bedrock)
Block(-6,3,-7,dimstack:bedrock)
Block(-6,4,-7,dimstack:bedrock)
Block(-6,5,-7,dimstack:bedrock)
Block(-6,6,-7,dimstack:bedrock)
Block(-6,7,-7,dimstack:bedrock)
Block(-5,1,-7,dimstack:bedrock)
Block(-5,2,-7,dimstack:bedrock)
Block(-5,3,-7,dimstack:bedrock)
Block(-5,4,-7,dimstack:bedrock)
Block(-5,5,-7,dimstack:bedrock)
Block(-5,6,-7,dimstack:bedrock)
Block(-5,7,-7,dimstack:bedrock)
Block(-4,1,-7,dimstack:bedrock)
Block(-4,2,-7,dimstack:bedrock)
Block(-4,3,-7,dimstack:bedrock)
Block(-4,4,-7,dimstack:bedrock)
Block(-4,5,-7,dimstack:bedrock)
Block(-4,6,-7,dimstack:bedrock)
Block(-4,7,-7,dimstack:bedrock)
Block(-3,1,-7,dimstack:bedrock)
Block(-3,2,-7,dimstack:bedrock)
Block(-3,3,-7,dimstack:bedrock)
Block(-3,4,-7,dimstack:bedrock)
Block(-3,5,-7,dimstack:bedrock)
Block(-3,6,-7,dimstack:bedrock)
Block(-3,7,-7,dimstack:bedrock)
Block(-2,1,-7,dimstack:bedrock)
Block(-2,2,-7,dimstack:bedrock)
Block(-2,3,-7,dimstack:bedrock)
Block(-2,4,-7,dimstack:bedrock)
Block(-2,5,-7,dimstack:bedrock)
Block(-2,6,-7,dimstack:bedrock)
Block(-2,7,-7,dimstack:bedrock)
Block(-1,1,-7,dimstack:bedrock)
Block(-1,2,-7,dimstack:bedrock)
Block(-1,3,-7,dimstack:bedrock)
Block(-1,4,-7,dimstack:bedrock)
Block(-1,5,-7,dimstack:bedrock)
Block(-1,6,-7,dimstack:bedrock)
Block(-1,7,-7,dimstack:bedrock)
Block(0,1,-7,dimstack:bedrock)
Block(0,2,-7,dimstack:bedrock)
Block(0,3,-7,contenttweaker:reinforced_concrete)
Block(0,4,-7,contenttweaker:reinforced_concrete)
Block(0,5,-7,contenttweaker:reinforced_concrete)
Block(0,6,-7,dimstack:bedrock)
Block(0,7,-7,dimstack:bedrock)
Block(1,1,-7,dimstack:bedrock)
Block(1,2,-7,contenttweaker:reinforced_concrete)
Block(1,3,-7,AIR)
Block(1,4,-7,AIR)
Block(1,5,-7,AIR)
Block(1,6,-7,contenttweaker:reinforced_concrete)
Block(1,7,-7,dimstack:bedrock)
Block(2,1,-7,dimstack:bedrock)
Block(2,2,-7,contenttweaker:reinforced_concrete)
Block(2,3,-7,AIR)
Block(2,4,-7,AIR)
Block(2,5,-7,AIR)
Block(2,6,-7,contenttweaker:reinforced_concrete)
Block(2,7,-7,dimstack:bedrock)
Block(3,1,-7,dimstack:bedrock)
Block(3,2,-7,contenttweaker:reinforced_concrete)
Block(3,3,-7,AIR)
Block(3,4,-7,AIR)
Block(3,5,-7,AIR)
Block(3,6,-7,contenttweaker:reinforced_concrete)
Block(3,7,-7,dimstack:bedrock)
Block(4,1,-7,dimstack:bedrock)
Block(4,2,-7,dimstack:bedrock)
Block(4,3,-7,contenttweaker:reinforced_concrete)
Block(4,4,-7,contenttweaker:reinforced_concrete)
Block(4,5,-7,contenttweaker:reinforced_concrete)
Block(4,6,-7,dimstack:bedrock)
Block(4,7,-7,dimstack:bedrock)
Block(5,1,-7,dimstack:bedrock)
Block(5,2,-7,dimstack:bedrock)
Block(5,3,-7,dimstack:bedrock)
Block(5,4,-7,dimstack:bedrock)
Block(5,5,-7,dimstack:bedrock)
Block(5,6,-7,dimstack:bedrock)
Block(5,7,-7,dimstack:bedrock)
Block(6,1,-7,dimstack:bedrock)
Block(6,2,-7,dimstack:bedrock)
Block(6,3,-7,dimstack:bedrock)
Block(6,4,-7,dimstack:bedrock)
Block(6,5,-7,dimstack:bedrock)
Block(6,6,-7,dimstack:bedrock)
Block(6,7,-7,dimstack:bedrock)
Block(7,1,-7,dimstack:bedrock)
Block(7,2,-7,dimstack:bedrock)
Block(7,3,-7,dimstack:bedrock)
Block(7,4,-7,dimstack:bedrock)
Block(7,5,-7,dimstack:bedrock)
Block(7,6,-7,dimstack:bedrock)
Block(7,7,-7,dimstack:bedrock)

#######################################################################
# +-----------------------------------------------------------------+ #
# |                             Branches                            | #
# +-----------------------------------------------------------------+ #
#######################################################################


#######################################################################
# +-----------------------------------------------------------------+ #
# |                             Entities                            | #
# +-----------------------------------------------------------------+ #
#######################################################################


#######################################################################
# +-----------------------------------------------------------------+ #
# |                            Particles                            | #
# +-----------------------------------------------------------------+ #
#######################################################################


#######################################################################
# +-----------------------------------------------------------------+ #
# |                             Spawners                            | #
# +-----------------------------------------------------------------+ #
#######################################################################


#######################################################################
# +-----------------------------------------------------------------+ #
# |                             ModData                             | #
# +-----------------------------------------------------------------+ #
#######################################################################

