
#######################################################################
# +-----------------------------------------------------------------+ #
# |                            BO4 object                           | #
# +-----------------------------------------------------------------+ #
#######################################################################

Author: NLBlackEagle

Description: No description given

SettingsMode: WriteDisable


#######################################################################
# +-----------------------------------------------------------------+ #
# |                          Main settings                          | #
# +-----------------------------------------------------------------+ #
#######################################################################

Frequency: 0

SpawnHeight: highestBlock

UseCenterForHighestBlock: true

##############################
# Height Limits for the BO4. #
##############################

MinHeight: 0

MaxHeight: 255

InheritBO3: 

InheritBO3Rotation: NORTH

OverrideChildSettings: true

OverrideParentHeight: false

CanOverride: true

BranchFrequency: 0

BranchFrequencyGroup: 

MustBeBelowOther: false

MustBeInside: 

CannotBeInside: 

ReplacesBO3: 

MustBeInsideWorldBorders: false

CanSpawnOnWater: true

SpawnOnWaterOnly: false

SpawnUnderWater: false

SpawnAtWaterLevel: false

HeightOffset: 0

RemoveAir: true

ReplaceAbove: 

ReplaceBelow: 

ReplaceWithBiomeBlocks: true

ReplaceWithSurfaceBlock: GRASS

ReplaceWithGroundBlock: DIRT

ReplaceWithStoneBlock: STONE

SmoothRadius: 0

SmoothHeightOffset: 0

SmoothStartTop: false

SmoothStartWood: false

SmoothingSurfaceBlock: 

SmoothingGroundBlock: 

BO3Group: 

IsSpawnPoint: false

DoReplaceBlocks: true


#######################################################################
# +-----------------------------------------------------------------+ #
# |                              Blocks                             | #
# +-----------------------------------------------------------------+ #
#######################################################################

Block(-8,0,8,PACKED_ICE:0)
Block(-8,1,8,PACKED_ICE:0)
Block(-8,2,7,PACKED_ICE:0)
Block(-8,2,8,PACKED_ICE:0)
Block(-8,3,7,PACKED_ICE:0)
Block(-8,3,8,PACKED_ICE:0)
Block(-8,4,6,PACKED_ICE:0)
Block(-8,4,7,PACKED_ICE:0)
Block(-8,4,8,PACKED_ICE:0)
Block(-8,5,5,PACKED_ICE:0)
Block(-8,5,6,PACKED_ICE:0)
Block(-8,5,7,PACKED_ICE:0)
Block(-8,5,8,PACKED_ICE:0)
Block(-8,6,5,PACKED_ICE:0)
Block(-8,6,6,PACKED_ICE:0)
Block(-8,6,7,PACKED_ICE:0)
Block(-8,6,8,PACKED_ICE:0)
Block(-8,7,4,PACKED_ICE:0)
Block(-8,7,5,PACKED_ICE:0)
Block(-8,7,6,PACKED_ICE:0)
Block(-8,7,7,PACKED_ICE:0)
Block(-8,7,8,PACKED_ICE:0)
Block(-8,8,3,PACKED_ICE:0)
Block(-8,8,4,PACKED_ICE:0)
Block(-8,8,5,PACKED_ICE:0)
Block(-8,8,6,PACKED_ICE:0)
Block(-8,8,7,PACKED_ICE:0)
Block(-8,8,8,PACKED_ICE:0)
Block(-8,9,3,PACKED_ICE:0)
Block(-8,9,4,PACKED_ICE:0)
Block(-8,9,5,PACKED_ICE:0)
Block(-8,9,6,PACKED_ICE:0)
Block(-8,9,7,PACKED_ICE:0)
Block(-8,9,8,PACKED_ICE:0)
Block(-8,10,2,PACKED_ICE:0)
Block(-8,10,3,PACKED_ICE:0)
Block(-8,10,4,PACKED_ICE:0)
Block(-8,10,5,PACKED_ICE:0)
Block(-8,10,6,PACKED_ICE:0)
Block(-8,10,7,PACKED_ICE:0)
Block(-8,10,8,PACKED_ICE:0)
Block(-8,11,1,PACKED_ICE:0)
Block(-8,11,2,PACKED_ICE:0)
Block(-8,11,3,PACKED_ICE:0)
Block(-8,11,4,PACKED_ICE:0)
Block(-8,11,5,PACKED_ICE:0)
Block(-8,11,6,PACKED_ICE:0)
Block(-8,11,7,PACKED_ICE:0)
Block(-8,11,8,PACKED_ICE:0)
Block(-8,12,1,PACKED_ICE:0)
Block(-8,12,2,PACKED_ICE:0)
Block(-8,12,3,PACKED_ICE:0)
Block(-8,12,4,PACKED_ICE:0)
Block(-8,12,5,PACKED_ICE:0)
Block(-8,12,6,PACKED_ICE:0)
Block(-8,12,7,PACKED_ICE:0)
Block(-8,12,8,PACKED_ICE:0)
Block(-8,13,0,PACKED_ICE:0)
Block(-8,13,1,PACKED_ICE:0)
Block(-8,13,2,PACKED_ICE:0)
Block(-8,13,3,PACKED_ICE:0)
Block(-8,13,4,PACKED_ICE:0)
Block(-8,13,5,PACKED_ICE:0)
Block(-8,13,6,PACKED_ICE:0)
Block(-8,13,7,PACKED_ICE:0)
Block(-8,13,8,PACKED_ICE:0)
Block(-8,14,-1,PACKED_ICE:0)
Block(-8,14,0,PACKED_ICE:0)
Block(-8,14,1,PACKED_ICE:0)
Block(-8,14,2,PACKED_ICE:0)
Block(-8,14,3,PACKED_ICE:0)
Block(-8,14,4,PACKED_ICE:0)
Block(-8,14,5,PACKED_ICE:0)
Block(-8,14,6,PACKED_ICE:0)
Block(-8,14,7,PACKED_ICE:0)
Block(-8,14,8,PACKED_ICE:0)
Block(-8,15,-1,PACKED_ICE:0)
Block(-8,15,0,PACKED_ICE:0)
Block(-8,15,1,PACKED_ICE:0)
Block(-8,15,2,PACKED_ICE:0)
Block(-8,15,3,PACKED_ICE:0)
Block(-8,15,4,PACKED_ICE:0)
Block(-8,15,5,PACKED_ICE:0)
Block(-8,15,6,PACKED_ICE:0)
Block(-8,15,7,PACKED_ICE:0)
Block(-8,15,8,PACKED_ICE:0)
Block(-8,16,-2,PACKED_ICE:0)
Block(-8,16,-1,PACKED_ICE:0)
Block(-8,16,0,PACKED_ICE:0)
Block(-8,16,1,PACKED_ICE:0)
Block(-8,16,2,PACKED_ICE:0)
Block(-8,16,3,PACKED_ICE:0)
Block(-8,16,4,PACKED_ICE:0)
Block(-8,16,5,PACKED_ICE:0)
Block(-8,16,6,PACKED_ICE:0)
Block(-8,16,7,PACKED_ICE:0)
Block(-8,16,8,PACKED_ICE:0)
Block(-8,17,-3,PACKED_ICE:0)
Block(-8,17,-2,PACKED_ICE:0)
Block(-8,17,-1,PACKED_ICE:0)
Block(-8,17,0,PACKED_ICE:0)
Block(-8,17,1,PACKED_ICE:0)
Block(-8,17,2,PACKED_ICE:0)
Block(-8,17,3,PACKED_ICE:0)
Block(-8,17,4,PACKED_ICE:0)
Block(-8,17,5,PACKED_ICE:0)
Block(-8,17,6,PACKED_ICE:0)
Block(-8,17,7,PACKED_ICE:0)
Block(-8,17,8,PACKED_ICE:0)
Block(-8,18,-3,PACKED_ICE:0)
Block(-8,18,-2,PACKED_ICE:0)
Block(-8,18,-1,PACKED_ICE:0)
Block(-8,18,0,PACKED_ICE:0)
Block(-8,18,1,PACKED_ICE:0)
Block(-8,18,2,PACKED_ICE:0)
Block(-8,18,3,PACKED_ICE:0)
Block(-8,18,4,PACKED_ICE:0)
Block(-8,18,5,PACKED_ICE:0)
Block(-8,18,6,PACKED_ICE:0)
Block(-8,18,7,PACKED_ICE:0)
Block(-8,18,8,PACKED_ICE:0)
Block(-8,19,-4,PACKED_ICE:0)
Block(-8,19,-3,PACKED_ICE:0)
Block(-8,19,-2,PACKED_ICE:0)
Block(-8,19,-1,PACKED_ICE:0)
Block(-8,19,0,PACKED_ICE:0)
Block(-8,19,1,PACKED_ICE:0)
Block(-8,19,2,PACKED_ICE:0)
Block(-8,19,3,PACKED_ICE:0)
Block(-8,19,4,PACKED_ICE:0)
Block(-8,19,5,PACKED_ICE:0)
Block(-8,19,6,PACKED_ICE:0)
Block(-8,19,7,PACKED_ICE:0)
Block(-8,19,8,PACKED_ICE:0)
Block(-8,20,-5,PACKED_ICE:0)
Block(-8,20,-4,PACKED_ICE:0)
Block(-8,20,-3,PACKED_ICE:0)
Block(-8,20,-2,PACKED_ICE:0)
Block(-8,20,-1,PACKED_ICE:0)
Block(-8,20,0,PACKED_ICE:0)
Block(-8,20,1,PACKED_ICE:0)
Block(-8,20,2,PACKED_ICE:0)
Block(-8,20,3,PACKED_ICE:0)
Block(-8,20,4,PACKED_ICE:0)
Block(-8,20,5,PACKED_ICE:0)
Block(-8,20,6,PACKED_ICE:0)
Block(-8,20,7,PACKED_ICE:0)
Block(-8,20,8,PACKED_ICE:0)
Block(-8,21,-5,PACKED_ICE:0)
Block(-8,21,-4,PACKED_ICE:0)
Block(-8,21,-3,PACKED_ICE:0)
Block(-8,21,-2,PACKED_ICE:0)
Block(-8,21,-1,PACKED_ICE:0)
Block(-8,21,0,PACKED_ICE:0)
Block(-8,21,1,PACKED_ICE:0)
Block(-8,21,2,PACKED_ICE:0)
Block(-8,21,3,PACKED_ICE:0)
Block(-8,21,4,PACKED_ICE:0)
Block(-8,21,5,PACKED_ICE:0)
Block(-8,21,6,PACKED_ICE:0)
Block(-8,21,7,PACKED_ICE:0)
Block(-8,21,8,PACKED_ICE:0)
Block(-8,22,-6,PACKED_ICE:0)
Block(-8,22,-5,PACKED_ICE:0)
Block(-8,22,-4,PACKED_ICE:0)
Block(-8,22,-3,PACKED_ICE:0)
Block(-8,22,-2,PACKED_ICE:0)
Block(-8,22,-1,PACKED_ICE:0)
Block(-8,22,0,PACKED_ICE:0)
Block(-8,22,1,PACKED_ICE:0)
Block(-8,22,2,PACKED_ICE:0)
Block(-8,22,3,PACKED_ICE:0)
Block(-8,22,4,PACKED_ICE:0)
Block(-8,22,5,PACKED_ICE:0)
Block(-8,22,6,PACKED_ICE:0)
Block(-8,22,7,PACKED_ICE:0)
Block(-8,22,8,PACKED_ICE:0)
Block(-8,23,-7,PACKED_ICE:0)
Block(-8,23,-6,PACKED_ICE:0)
Block(-8,23,-5,PACKED_ICE:0)
Block(-8,23,-4,PACKED_ICE:0)
Block(-8,23,-3,PACKED_ICE:0)
Block(-8,23,-2,PACKED_ICE:0)
Block(-8,23,-1,PACKED_ICE:0)
Block(-8,23,0,PACKED_ICE:0)
Block(-8,23,1,PACKED_ICE:0)
Block(-8,23,2,PACKED_ICE:0)
Block(-8,23,3,PACKED_ICE:0)
Block(-8,23,4,PACKED_ICE:0)
Block(-8,23,5,PACKED_ICE:0)
Block(-8,23,6,PACKED_ICE:0)
Block(-8,23,7,PACKED_ICE:0)
Block(-8,23,8,PACKED_ICE:0)
Block(-8,24,-7,PACKED_ICE:0)
Block(-8,24,-6,PACKED_ICE:0)
Block(-8,24,-5,PACKED_ICE:0)
Block(-8,24,-4,PACKED_ICE:0)
Block(-8,24,-3,PACKED_ICE:0)
Block(-8,24,-2,PACKED_ICE:0)
Block(-8,24,-1,PACKED_ICE:0)
Block(-8,24,0,PACKED_ICE:0)
Block(-8,24,1,PACKED_ICE:0)
Block(-8,24,2,PACKED_ICE:0)
Block(-8,24,3,PACKED_ICE:0)
Block(-8,24,4,PACKED_ICE:0)
Block(-8,24,5,PACKED_ICE:0)
Block(-8,24,6,PACKED_ICE:0)
Block(-8,24,7,PACKED_ICE:0)
Block(-8,25,-7,PACKED_ICE:0)
Block(-8,25,-6,PACKED_ICE:0)
Block(-8,25,-5,PACKED_ICE:0)
Block(-8,25,-4,PACKED_ICE:0)
Block(-8,25,-3,PACKED_ICE:0)
Block(-8,25,-2,PACKED_ICE:0)
Block(-8,25,-1,PACKED_ICE:0)
Block(-8,25,0,PACKED_ICE:0)
Block(-8,25,1,PACKED_ICE:0)
Block(-8,25,2,PACKED_ICE:0)
Block(-8,25,3,PACKED_ICE:0)
Block(-8,25,4,PACKED_ICE:0)
Block(-8,25,5,PACKED_ICE:0)
Block(-8,25,6,PACKED_ICE:0)
Block(-8,25,7,PACKED_ICE:0)
Block(-8,26,-7,PACKED_ICE:0)
Block(-8,26,-6,PACKED_ICE:0)
Block(-8,26,-5,PACKED_ICE:0)
Block(-8,26,-4,PACKED_ICE:0)
Block(-8,26,-3,PACKED_ICE:0)
Block(-8,26,-2,ICE:0)
Block(-8,26,-1,ICE:0)
Block(-8,26,0,ICE:0)
Block(-8,26,1,PACKED_ICE:0)
Block(-8,26,2,PACKED_ICE:0)
Block(-8,26,3,PACKED_ICE:0)
Block(-8,26,4,PACKED_ICE:0)
Block(-8,26,5,PACKED_ICE:0)
Block(-8,26,6,PACKED_ICE:0)
Block(-8,27,-7,PACKED_ICE:0)
Block(-8,27,-6,PACKED_ICE:0)
Block(-8,27,-5,PACKED_ICE:0)
Block(-8,27,-4,PACKED_ICE:0)
Block(-8,27,-3,ICE:0)
Block(-8,27,-2,ICE:0)
Block(-8,27,-1,ICE:0)
Block(-8,27,0,ICE:0)
Block(-8,27,1,ICE:0)
Block(-8,27,2,PACKED_ICE:0)
Block(-8,27,3,ICE:0)
Block(-8,27,4,ICE:0)
Block(-8,27,5,ICE:0)
Block(-8,28,-7,PACKED_ICE:0)
Block(-8,28,-6,PACKED_ICE:0)
Block(-8,28,-5,PACKED_ICE:0)
Block(-8,28,-4,PACKED_ICE:0)
Block(-8,28,-3,ICE:0)
Block(-8,28,-2,ICE:0)
Block(-8,28,-1,ICE:0)
Block(-8,28,0,ICE:0)
Block(-8,28,1,ICE:0)
Block(-8,28,2,ICE:0)
Block(-8,28,3,ICE:0)
Block(-8,28,4,ICE:0)
Block(-8,29,-7,PACKED_ICE:0)
Block(-8,29,-6,PACKED_ICE:0)
Block(-8,29,-5,ICE:0)
Block(-8,29,-4,ICE:0)
Block(-8,29,-3,ICE:0)
Block(-8,29,-2,ICE:0)
Block(-8,29,-1,ICE:0)
Block(-8,29,0,ICE:0)
Block(-8,29,1,ICE:0)
Block(-8,29,2,ICE:0)
Block(-8,29,3,ICE:0)
Block(-8,30,-7,PACKED_ICE:0)
Block(-8,30,-6,ICE:0)
Block(-8,30,-5,ICE:0)
Block(-8,30,-4,ICE:0)
Block(-8,30,-3,ICE:0)
Block(-8,30,-2,ICE:0)
Block(-8,30,-1,ICE:0)
Block(-8,30,0,ICE:0)
Block(-8,30,1,ICE:0)
Block(-8,30,2,ICE:0)
Block(-8,31,-7,ICE:0)
Block(-8,31,-6,ICE:0)
Block(-8,31,-5,ICE:0)
Block(-8,31,-4,ICE:0)
Block(-8,31,-3,ICE:0)
Block(-8,31,-2,ICE:0)
Block(-8,31,-1,ICE:0)
Block(-8,31,0,ICE:0)
Block(-8,31,1,ICE:0)
Block(-8,32,-7,ICE:0)
Block(-8,32,-6,ICE:0)
Block(-8,32,-5,ICE:0)
Block(-8,32,-4,ICE:0)
Block(-8,32,-3,ICE:0)
Block(-8,32,-2,ICE:0)
Block(-8,32,-1,ICE:0)
Block(-8,32,0,ICE:0)
Block(-8,33,-7,ICE:0)
Block(-8,33,-6,ICE:0)
Block(-8,33,-5,ICE:0)
Block(-8,33,-4,ICE:0)
Block(-8,33,-3,ICE:0)
Block(-8,33,-2,ICE:0)
Block(-8,33,-1,ICE:0)
Block(-8,34,-7,ICE:0)
Block(-8,34,-6,ICE:0)
Block(-8,34,-5,ICE:0)
Block(-8,34,-4,ICE:0)
Block(-8,34,-3,ICE:0)
Block(-8,34,-2,ICE:0)
Block(-8,35,-7,ICE:0)
Block(-8,35,-6,ICE:0)
Block(-8,35,-5,ICE:0)
Block(-8,35,-4,ICE:0)
Block(-8,35,-3,ICE:0)
Block(-8,36,-7,ICE:0)
Block(-8,36,-6,ICE:0)
Block(-8,36,-5,ICE:0)
Block(-8,36,-4,ICE:0)
Block(-8,36,-3,ICE:0)
Block(-8,37,-7,ICE:0)
Block(-8,37,-6,ICE:0)
Block(-8,37,-5,ICE:0)
Block(-8,37,-4,ICE:0)
Block(-8,38,-7,ICE:0)
Block(-8,38,-6,ICE:0)
Block(-8,38,-5,ICE:0)
Block(-8,39,-7,ICE:0)
Block(-8,39,-6,ICE:0)
Block(-8,40,-7,ICE:0)
Block(-7,1,8,PACKED_ICE:0)
Block(-7,2,8,PACKED_ICE:0)
Block(-7,3,7,PACKED_ICE:0)
Block(-7,3,8,PACKED_ICE:0)
Block(-7,4,6,PACKED_ICE:0)
Block(-7,4,7,PACKED_ICE:0)
Block(-7,4,8,PACKED_ICE:0)
Block(-7,5,6,PACKED_ICE:0)
Block(-7,5,7,PACKED_ICE:0)
Block(-7,5,8,PACKED_ICE:0)
Block(-7,6,5,PACKED_ICE:0)
Block(-7,6,6,PACKED_ICE:0)
Block(-7,6,7,PACKED_ICE:0)
Block(-7,6,8,PACKED_ICE:0)
Block(-7,7,5,PACKED_ICE:0)
Block(-7,7,6,PACKED_ICE:0)
Block(-7,7,7,PACKED_ICE:0)
Block(-7,7,8,PACKED_ICE:0)
Block(-7,8,4,PACKED_ICE:0)
Block(-7,8,5,PACKED_ICE:0)
Block(-7,8,6,PACKED_ICE:0)
Block(-7,8,7,PACKED_ICE:0)
Block(-7,8,8,PACKED_ICE:0)
Block(-7,9,3,PACKED_ICE:0)
Block(-7,9,4,PACKED_ICE:0)
Block(-7,9,5,PACKED_ICE:0)
Block(-7,9,6,PACKED_ICE:0)
Block(-7,9,7,PACKED_ICE:0)
Block(-7,9,8,PACKED_ICE:0)
Block(-7,10,3,PACKED_ICE:0)
Block(-7,10,4,PACKED_ICE:0)
Block(-7,10,5,PACKED_ICE:0)
Block(-7,10,6,PACKED_ICE:0)
Block(-7,10,7,PACKED_ICE:0)
Block(-7,10,8,PACKED_ICE:0)
Block(-7,11,2,PACKED_ICE:0)
Block(-7,11,3,PACKED_ICE:0)
Block(-7,11,4,PACKED_ICE:0)
Block(-7,11,5,PACKED_ICE:0)
Block(-7,11,6,PACKED_ICE:0)
Block(-7,11,7,PACKED_ICE:0)
Block(-7,11,8,PACKED_ICE:0)
Block(-7,12,1,PACKED_ICE:0)
Block(-7,12,2,PACKED_ICE:0)
Block(-7,12,3,PACKED_ICE:0)
Block(-7,12,4,PACKED_ICE:0)
Block(-7,12,5,PACKED_ICE:0)
Block(-7,12,6,PACKED_ICE:0)
Block(-7,12,7,PACKED_ICE:0)
Block(-7,12,8,PACKED_ICE:0)
Block(-7,13,1,PACKED_ICE:0)
Block(-7,13,2,PACKED_ICE:0)
Block(-7,13,3,PACKED_ICE:0)
Block(-7,13,4,PACKED_ICE:0)
Block(-7,13,5,PACKED_ICE:0)
Block(-7,13,6,PACKED_ICE:0)
Block(-7,13,7,PACKED_ICE:0)
Block(-7,13,8,PACKED_ICE:0)
Block(-7,14,0,PACKED_ICE:0)
Block(-7,14,1,PACKED_ICE:0)
Block(-7,14,2,PACKED_ICE:0)
Block(-7,14,3,PACKED_ICE:0)
Block(-7,14,4,PACKED_ICE:0)
Block(-7,14,5,PACKED_ICE:0)
Block(-7,14,6,PACKED_ICE:0)
Block(-7,14,7,PACKED_ICE:0)
Block(-7,14,8,PACKED_ICE:0)
Block(-7,15,-1,PACKED_ICE:0)
Block(-7,15,0,PACKED_ICE:0)
Block(-7,15,1,PACKED_ICE:0)
Block(-7,15,2,PACKED_ICE:0)
Block(-7,15,3,PACKED_ICE:0)
Block(-7,15,4,PACKED_ICE:0)
Block(-7,15,5,PACKED_ICE:0)
Block(-7,15,6,PACKED_ICE:0)
Block(-7,15,7,PACKED_ICE:0)
Block(-7,15,8,PACKED_ICE:0)
Block(-7,16,-1,PACKED_ICE:0)
Block(-7,16,0,PACKED_ICE:0)
Block(-7,16,1,PACKED_ICE:0)
Block(-7,16,2,PACKED_ICE:0)
Block(-7,16,3,PACKED_ICE:0)
Block(-7,16,4,PACKED_ICE:0)
Block(-7,16,5,PACKED_ICE:0)
Block(-7,16,6,PACKED_ICE:0)
Block(-7,16,7,PACKED_ICE:0)
Block(-7,16,8,PACKED_ICE:0)
Block(-7,17,-2,PACKED_ICE:0)
Block(-7,17,-1,PACKED_ICE:0)
Block(-7,17,0,PACKED_ICE:0)
Block(-7,17,1,PACKED_ICE:0)
Block(-7,17,2,PACKED_ICE:0)
Block(-7,17,3,PACKED_ICE:0)
Block(-7,17,4,PACKED_ICE:0)
Block(-7,17,5,PACKED_ICE:0)
Block(-7,17,6,PACKED_ICE:0)
Block(-7,17,7,PACKED_ICE:0)
Block(-7,17,8,PACKED_ICE:0)
Block(-7,18,-3,PACKED_ICE:0)
Block(-7,18,-2,PACKED_ICE:0)
Block(-7,18,-1,PACKED_ICE:0)
Block(-7,18,0,PACKED_ICE:0)
Block(-7,18,1,PACKED_ICE:0)
Block(-7,18,2,PACKED_ICE:0)
Block(-7,18,3,PACKED_ICE:0)
Block(-7,18,4,PACKED_ICE:0)
Block(-7,18,5,ICE:0)
Block(-7,18,6,ICE:0)
Block(-7,18,7,ICE:0)
Block(-7,18,8,PACKED_ICE:0)
Block(-7,19,-3,PACKED_ICE:0)
Block(-7,19,-2,PACKED_ICE:0)
Block(-7,19,-1,PACKED_ICE:0)
Block(-7,19,0,PACKED_ICE:0)
Block(-7,19,1,PACKED_ICE:0)
Block(-7,19,2,PACKED_ICE:0)
Block(-7,19,3,PACKED_ICE:0)
Block(-7,19,4,ICE:0)
Block(-7,19,5,ICE:0)
Block(-7,19,6,ICE:0)
Block(-7,19,7,ICE:0)
Block(-7,19,8,ICE:0)
Block(-7,20,-4,PACKED_ICE:0)
Block(-7,20,-3,PACKED_ICE:0)
Block(-7,20,-2,PACKED_ICE:0)
Block(-7,20,-1,PACKED_ICE:0)
Block(-7,20,0,PACKED_ICE:0)
Block(-7,20,1,PACKED_ICE:0)
Block(-7,20,2,PACKED_ICE:0)
Block(-7,20,3,PACKED_ICE:0)
Block(-7,20,4,ICE:0)
Block(-7,20,5,ICE:0)
Block(-7,20,6,ICE:0)
Block(-7,20,7,ICE:0)
Block(-7,20,8,ICE:0)
Block(-7,21,-5,PACKED_ICE:0)
Block(-7,21,-4,PACKED_ICE:0)
Block(-7,21,-3,PACKED_ICE:0)
Block(-7,21,-2,PACKED_ICE:0)
Block(-7,21,-1,PACKED_ICE:0)
Block(-7,21,0,PACKED_ICE:0)
Block(-7,21,1,PACKED_ICE:0)
Block(-7,21,2,ICE:0)
Block(-7,21,3,ICE:0)
Block(-7,21,4,ICE:0)
Block(-7,21,5,ICE:0)
Block(-7,21,6,ICE:0)
Block(-7,21,7,ICE:0)
Block(-7,21,8,ICE:0)
Block(-7,22,-5,PACKED_ICE:0)
Block(-7,22,-4,PACKED_ICE:0)
Block(-7,22,-3,PACKED_ICE:0)
Block(-7,22,-2,PACKED_ICE:0)
Block(-7,22,-1,PACKED_ICE:0)
Block(-7,22,0,PACKED_ICE:0)
Block(-7,22,1,ICE:0)
Block(-7,22,2,ICE:0)
Block(-7,22,3,ICE:0)
Block(-7,22,4,ICE:0)
Block(-7,22,5,ICE:0)
Block(-7,22,6,ICE:0)
Block(-7,22,7,ICE:0)
Block(-7,22,8,PACKED_ICE:0)
Block(-7,23,-6,PACKED_ICE:0)
Block(-7,23,-5,PACKED_ICE:0)
Block(-7,23,-4,PACKED_ICE:0)
Block(-7,23,-3,PACKED_ICE:0)
Block(-7,23,-2,PACKED_ICE:0)
Block(-7,23,-1,PACKED_ICE:0)
Block(-7,23,0,PACKED_ICE:0)
Block(-7,23,1,ICE:0)
Block(-7,23,2,ICE:0)
Block(-7,23,3,ICE:0)
Block(-7,23,4,ICE:0)
Block(-7,23,5,ICE:0)
Block(-7,23,6,PACKED_ICE:0)
Block(-7,23,7,PACKED_ICE:0)
Block(-7,23,8,PACKED_ICE:0)
Block(-7,24,-7,PACKED_ICE:0)
Block(-7,24,-6,PACKED_ICE:0)
Block(-7,24,-5,PACKED_ICE:0)
Block(-7,24,-4,PACKED_ICE:0)
Block(-7,24,-3,PACKED_ICE:0)
Block(-7,24,-2,PACKED_ICE:0)
Block(-7,24,-1,PACKED_ICE:0)
Block(-7,24,0,PACKED_ICE:0)
Block(-7,24,1,ICE:0)
Block(-7,24,2,ICE:0)
Block(-7,24,3,ICE:0)
Block(-7,24,4,ICE:0)
Block(-7,24,5,ICE:0)
Block(-7,24,6,PACKED_ICE:0)
Block(-7,24,7,PACKED_ICE:0)
Block(-7,25,-7,PACKED_ICE:0)
Block(-7,25,-6,PACKED_ICE:0)
Block(-7,25,-5,PACKED_ICE:0)
Block(-7,25,-4,PACKED_ICE:0)
Block(-7,25,-3,ICE:0)
Block(-7,25,-2,ICE:0)
Block(-7,25,-1,ICE:0)
Block(-7,25,0,ICE:0)
Block(-7,25,1,ICE:0)
Block(-7,25,2,ICE:0)
Block(-7,25,3,ICE:0)
Block(-7,25,4,ICE:0)
Block(-7,25,5,PACKED_ICE:0)
Block(-7,25,6,PACKED_ICE:0)
Block(-7,26,-7,PACKED_ICE:0)
Block(-7,26,-6,PACKED_ICE:0)
Block(-7,26,-5,PACKED_ICE:0)
Block(-7,26,-4,ICE:0)
Block(-7,26,-3,ICE:0)
Block(-7,26,-2,ICE:0)
Block(-7,26,-1,ICE:0)
Block(-7,26,0,ICE:0)
Block(-7,26,1,ICE:0)
Block(-7,26,2,ICE:0)
Block(-7,26,3,PACKED_ICE:0)
Block(-7,26,4,PACKED_ICE:0)
Block(-7,26,5,PACKED_ICE:0)
Block(-7,27,-7,PACKED_ICE:0)
Block(-7,27,-6,PACKED_ICE:0)
Block(-7,27,-5,PACKED_ICE:0)
Block(-7,27,-4,ICE:0)
Block(-7,27,-3,ICE:0)
Block(-7,27,-2,ICE:0)
Block(-7,27,-1,ICE:0)
Block(-7,27,0,ICE:0)
Block(-7,27,1,ICE:0)
Block(-7,27,2,ICE:0)
Block(-7,27,3,PACKED_ICE:0)
Block(-7,27,4,PACKED_ICE:0)
Block(-7,27,5,PACKED_ICE:0)
Block(-7,28,-7,PACKED_ICE:0)
Block(-7,28,-6,PACKED_ICE:0)
Block(-7,28,-5,ICE:0)
Block(-7,28,-4,ICE:0)
Block(-7,28,-3,ICE:0)
Block(-7,28,-2,ICE:0)
Block(-7,28,-1,ICE:0)
Block(-7,28,0,ICE:0)
Block(-7,28,1,ICE:0)
Block(-7,28,2,ICE:0)
Block(-7,28,3,PACKED_ICE:0)
Block(-7,28,4,PACKED_ICE:0)
Block(-7,29,-7,PACKED_ICE:0)
Block(-7,29,-6,ICE:0)
Block(-7,29,-5,ICE:0)
Block(-7,29,-4,ICE:0)
Block(-7,29,-3,ICE:0)
Block(-7,29,-2,ICE:0)
Block(-7,29,-1,ICE:0)
Block(-7,29,0,ICE:0)
Block(-7,29,1,ICE:0)
Block(-7,29,2,ICE:0)
Block(-7,29,3,ICE:0)
Block(-7,30,-7,ICE:0)
Block(-7,30,-6,ICE:0)
Block(-7,30,-5,ICE:0)
Block(-7,30,-4,ICE:0)
Block(-7,30,-3,ICE:0)
Block(-7,30,-2,ICE:0)
Block(-7,30,-1,ICE:0)
Block(-7,30,0,ICE:0)
Block(-7,30,1,ICE:0)
Block(-7,30,2,ICE:0)
Block(-7,31,-7,ICE:0)
Block(-7,31,-6,ICE:0)
Block(-7,31,-5,ICE:0)
Block(-7,31,-4,ICE:0)
Block(-7,31,-3,ICE:0)
Block(-7,31,-2,ICE:0)
Block(-7,31,-1,ICE:0)
Block(-7,31,0,ICE:0)
Block(-7,31,1,ICE:0)
Block(-7,32,-7,ICE:0)
Block(-7,32,-6,ICE:0)
Block(-7,32,-5,ICE:0)
Block(-7,32,-4,ICE:0)
Block(-7,32,-3,ICE:0)
Block(-7,32,-2,ICE:0)
Block(-7,32,-1,ICE:0)
Block(-7,32,0,ICE:0)
Block(-7,33,-7,ICE:0)
Block(-7,33,-6,ICE:0)
Block(-7,33,-5,ICE:0)
Block(-7,33,-4,ICE:0)
Block(-7,33,-3,ICE:0)
Block(-7,33,-2,ICE:0)
Block(-7,33,-1,ICE:0)
Block(-7,34,-7,ICE:0)
Block(-7,34,-6,ICE:0)
Block(-7,34,-5,ICE:0)
Block(-7,34,-4,ICE:0)
Block(-7,34,-3,ICE:0)
Block(-7,34,-2,ICE:0)
Block(-7,35,-7,ICE:0)
Block(-7,35,-6,ICE:0)
Block(-7,35,-5,ICE:0)
Block(-7,35,-4,ICE:0)
Block(-7,35,-3,ICE:0)
Block(-7,36,-7,ICE:0)
Block(-7,36,-6,ICE:0)
Block(-7,36,-5,ICE:0)
Block(-7,36,-4,ICE:0)
Block(-7,37,-7,ICE:0)
Block(-7,37,-6,ICE:0)
Block(-7,37,-5,ICE:0)
Block(-7,38,-7,ICE:0)
Block(-7,38,-6,ICE:0)
Block(-7,38,-5,ICE:0)
Block(-7,39,-7,ICE:0)
Block(-7,39,-6,ICE:0)
Block(-7,40,-7,ICE:0)
Block(-6,2,8,PACKED_ICE:0)
Block(-6,3,8,PACKED_ICE:0)
Block(-6,4,7,PACKED_ICE:0)
Block(-6,4,8,PACKED_ICE:0)
Block(-6,5,6,PACKED_ICE:0)
Block(-6,5,7,PACKED_ICE:0)
Block(-6,5,8,PACKED_ICE:0)
Block(-6,6,6,PACKED_ICE:0)
Block(-6,6,7,PACKED_ICE:0)
Block(-6,6,8,PACKED_ICE:0)
Block(-6,7,5,PACKED_ICE:0)
Block(-6,7,6,PACKED_ICE:0)
Block(-6,7,7,PACKED_ICE:0)
Block(-6,7,8,PACKED_ICE:0)
Block(-6,8,4,PACKED_ICE:0)
Block(-6,8,5,PACKED_ICE:0)
Block(-6,8,6,PACKED_ICE:0)
Block(-6,8,7,PACKED_ICE:0)
Block(-6,8,8,PACKED_ICE:0)
Block(-6,9,4,PACKED_ICE:0)
Block(-6,9,5,PACKED_ICE:0)
Block(-6,9,6,PACKED_ICE:0)
Block(-6,9,7,PACKED_ICE:0)
Block(-6,9,8,PACKED_ICE:0)
Block(-6,10,3,PACKED_ICE:0)
Block(-6,10,4,PACKED_ICE:0)
Block(-6,10,5,PACKED_ICE:0)
Block(-6,10,6,PACKED_ICE:0)
Block(-6,10,7,PACKED_ICE:0)
Block(-6,10,8,PACKED_ICE:0)
Block(-6,11,3,PACKED_ICE:0)
Block(-6,11,4,PACKED_ICE:0)
Block(-6,11,5,PACKED_ICE:0)
Block(-6,11,6,PACKED_ICE:0)
Block(-6,11,7,PACKED_ICE:0)
Block(-6,11,8,PACKED_ICE:0)
Block(-6,12,2,PACKED_ICE:0)
Block(-6,12,3,PACKED_ICE:0)
Block(-6,12,4,PACKED_ICE:0)
Block(-6,12,5,PACKED_ICE:0)
Block(-6,12,6,PACKED_ICE:0)
Block(-6,12,7,PACKED_ICE:0)
Block(-6,12,8,PACKED_ICE:0)
Block(-6,13,1,PACKED_ICE:0)
Block(-6,13,2,PACKED_ICE:0)
Block(-6,13,3,PACKED_ICE:0)
Block(-6,13,4,PACKED_ICE:0)
Block(-6,13,5,PACKED_ICE:0)
Block(-6,13,6,PACKED_ICE:0)
Block(-6,13,7,PACKED_ICE:0)
Block(-6,13,8,ICE:0)
Block(-6,14,1,PACKED_ICE:0)
Block(-6,14,2,PACKED_ICE:0)
Block(-6,14,3,PACKED_ICE:0)
Block(-6,14,4,PACKED_ICE:0)
Block(-6,14,5,PACKED_ICE:0)
Block(-6,14,6,PACKED_ICE:0)
Block(-6,14,7,ICE:0)
Block(-6,14,8,ICE:0)
Block(-6,15,0,PACKED_ICE:0)
Block(-6,15,1,PACKED_ICE:0)
Block(-6,15,2,PACKED_ICE:0)
Block(-6,15,3,PACKED_ICE:0)
Block(-6,15,4,PACKED_ICE:0)
Block(-6,15,5,PACKED_ICE:0)
Block(-6,15,6,PACKED_ICE:0)
Block(-6,15,7,ICE:0)
Block(-6,15,8,ICE:0)
Block(-6,16,-1,PACKED_ICE:0)
Block(-6,16,0,PACKED_ICE:0)
Block(-6,16,1,PACKED_ICE:0)
Block(-6,16,2,PACKED_ICE:0)
Block(-6,16,3,PACKED_ICE:0)
Block(-6,16,4,PACKED_ICE:0)
Block(-6,16,5,PACKED_ICE:0)
Block(-6,16,6,PACKED_ICE:0)
Block(-6,16,7,ICE:0)
Block(-6,16,8,ICE:0)
Block(-6,17,-1,PACKED_ICE:0)
Block(-6,17,0,PACKED_ICE:0)
Block(-6,17,1,PACKED_ICE:0)
Block(-6,17,2,PACKED_ICE:0)
Block(-6,17,3,PACKED_ICE:0)
Block(-6,17,4,ICE:0)
Block(-6,17,5,ICE:0)
Block(-6,17,6,ICE:0)
Block(-6,17,7,ICE:0)
Block(-6,17,8,ICE:0)
Block(-6,18,-2,PACKED_ICE:0)
Block(-6,18,-1,PACKED_ICE:0)
Block(-6,18,0,PACKED_ICE:0)
Block(-6,18,1,PACKED_ICE:0)
Block(-6,18,2,PACKED_ICE:0)
Block(-6,18,3,ICE:0)
Block(-6,18,4,ICE:0)
Block(-6,18,5,ICE:0)
Block(-6,18,6,ICE:0)
Block(-6,18,7,ICE:0)
Block(-6,18,8,ICE:0)
Block(-6,19,-3,PACKED_ICE:0)
Block(-6,19,-2,PACKED_ICE:0)
Block(-6,19,-1,PACKED_ICE:0)
Block(-6,19,0,PACKED_ICE:0)
Block(-6,19,1,PACKED_ICE:0)
Block(-6,19,2,PACKED_ICE:0)
Block(-6,19,3,ICE:0)
Block(-6,19,4,ICE:0)
Block(-6,19,5,ICE:0)
Block(-6,19,6,ICE:0)
Block(-6,19,7,ICE:0)
Block(-6,19,8,ICE:0)
Block(-6,20,-3,PACKED_ICE:0)
Block(-6,20,-2,PACKED_ICE:0)
Block(-6,20,-1,PACKED_ICE:0)
Block(-6,20,0,PACKED_ICE:0)
Block(-6,20,1,ICE:0)
Block(-6,20,2,ICE:0)
Block(-6,20,3,ICE:0)
Block(-6,20,4,ICE:0)
Block(-6,20,5,ICE:0)
Block(-6,20,6,ICE:0)
Block(-6,20,7,ICE:0)
Block(-6,20,8,ICE:0)
Block(-6,21,-4,PACKED_ICE:0)
Block(-6,21,-3,PACKED_ICE:0)
Block(-6,21,-2,PACKED_ICE:0)
Block(-6,21,-1,PACKED_ICE:0)
Block(-6,21,0,ICE:0)
Block(-6,21,1,ICE:0)
Block(-6,21,2,ICE:0)
Block(-6,21,3,ICE:0)
Block(-6,21,4,ICE:0)
Block(-6,21,5,ICE:0)
Block(-6,21,6,ICE:0)
Block(-6,21,7,ICE:0)
Block(-6,21,8,ICE:0)
Block(-6,22,-5,PACKED_ICE:0)
Block(-6,22,-4,PACKED_ICE:0)
Block(-6,22,-3,PACKED_ICE:0)
Block(-6,22,-2,PACKED_ICE:0)
Block(-6,22,-1,PACKED_ICE:0)
Block(-6,22,0,ICE:0)
Block(-6,22,1,ICE:0)
Block(-6,22,2,ICE:0)
Block(-6,22,3,ICE:0)
Block(-6,22,4,ICE:0)
Block(-6,22,5,ICE:0)
Block(-6,22,6,ICE:0)
Block(-6,22,7,ICE:0)
Block(-6,22,8,ICE:0)
Block(-6,23,-5,PACKED_ICE:0)
Block(-6,23,-4,PACKED_ICE:0)
Block(-6,23,-3,PACKED_ICE:0)
Block(-6,23,-2,PACKED_ICE:0)
Block(-6,23,-1,PACKED_ICE:0)
Block(-6,23,0,ICE:0)
Block(-6,23,1,ICE:0)
Block(-6,23,2,ICE:0)
Block(-6,23,3,ICE:0)
Block(-6,23,4,ICE:0)
Block(-6,23,5,ICE:0)
Block(-6,23,6,ICE:0)
Block(-6,23,7,ICE:0)
Block(-6,23,8,ICE:0)
Block(-6,24,-6,PACKED_ICE:0)
Block(-6,24,-5,PACKED_ICE:0)
Block(-6,24,-4,PACKED_ICE:0)
Block(-6,24,-3,ICE:0)
Block(-6,24,-2,ICE:0)
Block(-6,24,-1,ICE:0)
Block(-6,24,0,ICE:0)
Block(-6,24,1,ICE:0)
Block(-6,24,2,ICE:0)
Block(-6,24,3,ICE:0)
Block(-6,24,4,ICE:0)
Block(-6,24,5,ICE:0)
Block(-6,24,6,ICE:0)
Block(-6,24,7,PACKED_ICE:0)
Block(-6,25,-7,PACKED_ICE:0)
Block(-6,25,-6,PACKED_ICE:0)
Block(-6,25,-5,PACKED_ICE:0)
Block(-6,25,-4,ICE:0)
Block(-6,25,-3,ICE:0)
Block(-6,25,-2,ICE:0)
Block(-6,25,-1,ICE:0)
Block(-6,25,0,ICE:0)
Block(-6,25,1,ICE:0)
Block(-6,25,2,ICE:0)
Block(-6,25,3,ICE:0)
Block(-6,25,4,ICE:0)
Block(-6,25,5,ICE:0)
Block(-6,25,6,ICE:0)
Block(-6,26,-7,PACKED_ICE:0)
Block(-6,26,-6,PACKED_ICE:0)
Block(-6,26,-5,ICE:0)
Block(-6,26,-4,ICE:0)
Block(-6,26,-3,ICE:0)
Block(-6,26,-2,ICE:0)
Block(-6,26,-1,ICE:0)
Block(-6,26,0,ICE:0)
Block(-6,26,1,ICE:0)
Block(-6,26,2,ICE:0)
Block(-6,26,3,ICE:0)
Block(-6,26,4,ICE:0)
Block(-6,26,5,ICE:0)
Block(-6,27,-7,PACKED_ICE:0)
Block(-6,27,-6,PACKED_ICE:0)
Block(-6,27,-5,ICE:0)
Block(-6,27,-4,ICE:0)
Block(-6,27,-3,ICE:0)
Block(-6,27,-2,ICE:0)
Block(-6,27,-1,ICE:0)
Block(-6,27,0,ICE:0)
Block(-6,27,1,ICE:0)
Block(-6,27,2,ICE:0)
Block(-6,27,3,ICE:0)
Block(-6,27,4,PACKED_ICE:0)
Block(-6,28,-7,PACKED_ICE:0)
Block(-6,28,-6,ICE:0)
Block(-6,28,-5,ICE:0)
Block(-6,28,-4,ICE:0)
Block(-6,28,-3,ICE:0)
Block(-6,28,-2,ICE:0)
Block(-6,28,-1,ICE:0)
Block(-6,28,0,ICE:0)
Block(-6,28,1,ICE:0)
Block(-6,28,2,ICE:0)
Block(-6,28,3,ICE:0)
Block(-6,29,-7,ICE:0)
Block(-6,29,-6,ICE:0)
Block(-6,29,-5,ICE:0)
Block(-6,29,-4,ICE:0)
Block(-6,29,-3,ICE:0)
Block(-6,29,-2,ICE:0)
Block(-6,29,-1,ICE:0)
Block(-6,29,0,ICE:0)
Block(-6,29,1,ICE:0)
Block(-6,29,2,ICE:0)
Block(-6,29,3,ICE:0)
Block(-6,30,-7,ICE:0)
Block(-6,30,-6,ICE:0)
Block(-6,30,-5,ICE:0)
Block(-6,30,-4,ICE:0)
Block(-6,30,-3,ICE:0)
Block(-6,30,-2,ICE:0)
Block(-6,30,-1,ICE:0)
Block(-6,30,0,ICE:0)
Block(-6,30,1,ICE:0)
Block(-6,30,2,ICE:0)
Block(-6,31,-7,ICE:0)
Block(-6,31,-6,ICE:0)
Block(-6,31,-5,ICE:0)
Block(-6,31,-4,ICE:0)
Block(-6,31,-3,ICE:0)
Block(-6,31,-2,ICE:0)
Block(-6,31,-1,ICE:0)
Block(-6,31,0,ICE:0)
Block(-6,31,1,ICE:0)
Block(-6,32,-7,ICE:0)
Block(-6,32,-6,ICE:0)
Block(-6,32,-5,ICE:0)
Block(-6,32,-4,ICE:0)
Block(-6,32,-3,ICE:0)
Block(-6,32,-2,ICE:0)
Block(-6,32,-1,ICE:0)
Block(-6,32,0,ICE:0)
Block(-6,33,-7,ICE:0)
Block(-6,33,-6,ICE:0)
Block(-6,33,-5,ICE:0)
Block(-6,33,-4,ICE:0)
Block(-6,33,-3,ICE:0)
Block(-6,33,-2,ICE:0)
Block(-6,33,-1,ICE:0)
Block(-6,34,-7,ICE:0)
Block(-6,34,-6,ICE:0)
Block(-6,34,-5,ICE:0)
Block(-6,34,-4,ICE:0)
Block(-6,34,-3,ICE:0)
Block(-6,34,-2,ICE:0)
Block(-6,35,-7,ICE:0)
Block(-6,35,-6,ICE:0)
Block(-6,35,-5,ICE:0)
Block(-6,35,-4,ICE:0)
Block(-6,35,-3,ICE:0)
Block(-6,36,-7,ICE:0)
Block(-6,36,-6,ICE:0)
Block(-6,36,-5,ICE:0)
Block(-6,36,-4,ICE:0)
Block(-6,37,-7,ICE:0)
Block(-6,37,-6,ICE:0)
Block(-6,37,-5,ICE:0)
Block(-6,38,-7,ICE:0)
Block(-6,38,-6,ICE:0)
Block(-6,39,-7,ICE:0)
Block(-5,3,8,PACKED_ICE:0)
Block(-5,4,8,PACKED_ICE:0)
Block(-5,5,7,PACKED_ICE:0)
Block(-5,5,8,PACKED_ICE:0)
Block(-5,6,6,PACKED_ICE:0)
Block(-5,6,7,PACKED_ICE:0)
Block(-5,6,8,PACKED_ICE:0)
Block(-5,7,6,PACKED_ICE:0)
Block(-5,7,7,PACKED_ICE:0)
Block(-5,7,8,PACKED_ICE:0)
Block(-5,8,5,PACKED_ICE:0)
Block(-5,8,6,PACKED_ICE:0)
Block(-5,8,7,PACKED_ICE:0)
Block(-5,8,8,PACKED_ICE:0)
Block(-5,9,4,PACKED_ICE:0)
Block(-5,9,5,PACKED_ICE:0)
Block(-5,9,6,PACKED_ICE:0)
Block(-5,9,7,PACKED_ICE:0)
Block(-5,9,8,PACKED_ICE:0)
Block(-5,10,4,PACKED_ICE:0)
Block(-5,10,5,PACKED_ICE:0)
Block(-5,10,6,PACKED_ICE:0)
Block(-5,10,7,PACKED_ICE:0)
Block(-5,10,8,PACKED_ICE:0)
Block(-5,11,3,PACKED_ICE:0)
Block(-5,11,4,PACKED_ICE:0)
Block(-5,11,5,PACKED_ICE:0)
Block(-5,11,6,PACKED_ICE:0)
Block(-5,11,7,PACKED_ICE:0)
Block(-5,11,8,PACKED_ICE:0)
Block(-5,12,2,PACKED_ICE:0)
Block(-5,12,3,PACKED_ICE:0)
Block(-5,12,4,PACKED_ICE:0)
Block(-5,12,5,PACKED_ICE:0)
Block(-5,12,6,PACKED_ICE:0)
Block(-5,12,7,ICE:0)
Block(-5,12,8,ICE:0)
Block(-5,13,2,PACKED_ICE:0)
Block(-5,13,3,PACKED_ICE:0)
Block(-5,13,4,PACKED_ICE:0)
Block(-5,13,5,PACKED_ICE:0)
Block(-5,13,6,ICE:0)
Block(-5,13,7,ICE:0)
Block(-5,13,8,ICE:0)
Block(-5,14,1,PACKED_ICE:0)
Block(-5,14,2,PACKED_ICE:0)
Block(-5,14,3,PACKED_ICE:0)
Block(-5,14,4,PACKED_ICE:0)
Block(-5,14,5,PACKED_ICE:0)
Block(-5,14,6,ICE:0)
Block(-5,14,7,ICE:0)
Block(-5,14,8,ICE:0)
Block(-5,15,1,PACKED_ICE:0)
Block(-5,15,2,PACKED_ICE:0)
Block(-5,15,3,PACKED_ICE:0)
Block(-5,15,4,PACKED_ICE:0)
Block(-5,15,5,PACKED_ICE:0)
Block(-5,15,6,ICE:0)
Block(-5,15,7,ICE:0)
Block(-5,15,8,ICE:0)
Block(-5,16,0,PACKED_ICE:0)
Block(-5,16,1,PACKED_ICE:0)
Block(-5,16,2,PACKED_ICE:0)
Block(-5,16,3,PACKED_ICE:0)
Block(-5,16,4,ICE:0)
Block(-5,16,5,ICE:0)
Block(-5,16,6,ICE:0)
Block(-5,16,7,ICE:0)
Block(-5,16,8,ICE:0)
Block(-5,17,-1,PACKED_ICE:0)
Block(-5,17,0,PACKED_ICE:0)
Block(-5,17,1,PACKED_ICE:0)
Block(-5,17,2,PACKED_ICE:0)
Block(-5,17,3,ICE:0)
Block(-5,17,4,ICE:0)
Block(-5,17,5,ICE:0)
Block(-5,17,6,ICE:0)
Block(-5,17,7,ICE:0)
Block(-5,17,8,ICE:0)
Block(-5,18,-1,PACKED_ICE:0)
Block(-5,18,0,PACKED_ICE:0)
Block(-5,18,1,PACKED_ICE:0)
Block(-5,18,2,ICE:0)
Block(-5,18,3,ICE:0)
Block(-5,18,4,ICE:0)
Block(-5,18,5,ICE:0)
Block(-5,18,6,ICE:0)
Block(-5,18,7,ICE:0)
Block(-5,18,8,ICE:0)
Block(-5,19,-2,PACKED_ICE:0)
Block(-5,19,-1,PACKED_ICE:0)
Block(-5,19,0,PACKED_ICE:0)
Block(-5,19,1,ICE:0)
Block(-5,19,2,ICE:0)
Block(-5,19,3,ICE:0)
Block(-5,19,4,ICE:0)
Block(-5,19,5,ICE:0)
Block(-5,19,6,ICE:0)
Block(-5,19,7,ICE:0)
Block(-5,19,8,ICE:0)
Block(-5,20,-3,PACKED_ICE:0)
Block(-5,20,-2,PACKED_ICE:0)
Block(-5,20,-1,PACKED_ICE:0)
Block(-5,20,0,ICE:0)
Block(-5,20,1,ICE:0)
Block(-5,20,2,ICE:0)
Block(-5,20,3,ICE:0)
Block(-5,20,4,ICE:0)
Block(-5,20,5,ICE:0)
Block(-5,20,6,ICE:0)
Block(-5,20,7,ICE:0)
Block(-5,20,8,ICE:0)
Block(-5,21,-3,PACKED_ICE:0)
Block(-5,21,-2,PACKED_ICE:0)
Block(-5,21,-1,ICE:0)
Block(-5,21,0,ICE:0)
Block(-5,21,1,ICE:0)
Block(-5,21,2,ICE:0)
Block(-5,21,3,ICE:0)
Block(-5,21,4,ICE:0)
Block(-5,21,5,ICE:0)
Block(-5,21,6,ICE:0)
Block(-5,21,7,ICE:0)
Block(-5,21,8,ICE:0)
Block(-5,22,-4,PACKED_ICE:0)
Block(-5,22,-3,PACKED_ICE:0)
Block(-5,22,-2,PACKED_ICE:0)
Block(-5,22,-1,ICE:0)
Block(-5,22,0,ICE:0)
Block(-5,22,1,ICE:0)
Block(-5,22,2,ICE:0)
Block(-5,22,3,ICE:0)
Block(-5,22,4,ICE:0)
Block(-5,22,5,ICE:0)
Block(-5,22,6,ICE:0)
Block(-5,22,7,ICE:0)
Block(-5,22,8,ICE:0)
Block(-5,23,-5,PACKED_ICE:0)
Block(-5,23,-4,PACKED_ICE:0)
Block(-5,23,-3,PACKED_ICE:0)
Block(-5,23,-2,ICE:0)
Block(-5,23,-1,ICE:0)
Block(-5,23,0,ICE:0)
Block(-5,23,1,ICE:0)
Block(-5,23,2,ICE:0)
Block(-5,23,3,ICE:0)
Block(-5,23,4,ICE:0)
Block(-5,23,5,ICE:0)
Block(-5,23,6,ICE:0)
Block(-5,23,7,ICE:0)
Block(-5,23,8,ICE:0)
Block(-5,24,-5,PACKED_ICE:0)
Block(-5,24,-4,ICE:0)
Block(-5,24,-3,ICE:0)
Block(-5,24,-2,ICE:0)
Block(-5,24,-1,ICE:0)
Block(-5,24,0,ICE:0)
Block(-5,24,1,ICE:0)
Block(-5,24,2,ICE:0)
Block(-5,24,3,ICE:0)
Block(-5,24,4,ICE:0)
Block(-5,24,5,ICE:0)
Block(-5,24,6,ICE:0)
Block(-5,24,7,ICE:0)
Block(-5,25,-6,PACKED_ICE:0)
Block(-5,25,-5,ICE:0)
Block(-5,25,-4,ICE:0)
Block(-5,25,-3,ICE:0)
Block(-5,25,-2,ICE:0)
Block(-5,25,-1,ICE:0)
Block(-5,25,0,ICE:0)
Block(-5,25,1,ICE:0)
Block(-5,25,2,ICE:0)
Block(-5,25,3,ICE:0)
Block(-5,25,4,ICE:0)
Block(-5,25,5,ICE:0)
Block(-5,25,6,ICE:0)
Block(-5,26,-7,PACKED_ICE:0)
Block(-5,26,-6,PACKED_ICE:0)
Block(-5,26,-5,ICE:0)
Block(-5,26,-4,ICE:0)
Block(-5,26,-3,ICE:0)
Block(-5,26,-2,ICE:0)
Block(-5,26,-1,ICE:0)
Block(-5,26,0,ICE:0)
Block(-5,26,1,ICE:0)
Block(-5,26,2,ICE:0)
Block(-5,26,3,ICE:0)
Block(-5,26,4,ICE:0)
Block(-5,26,5,ICE:0)
Block(-5,27,-7,PACKED_ICE:0)
Block(-5,27,-6,ICE:0)
Block(-5,27,-5,ICE:0)
Block(-5,27,-4,ICE:0)
Block(-5,27,-3,ICE:0)
Block(-5,27,-2,ICE:0)
Block(-5,27,-1,ICE:0)
Block(-5,27,0,ICE:0)
Block(-5,27,1,ICE:0)
Block(-5,27,2,ICE:0)
Block(-5,27,3,ICE:0)
Block(-5,28,-7,PACKED_ICE:0)
Block(-5,28,-6,ICE:0)
Block(-5,28,-5,ICE:0)
Block(-5,28,-4,ICE:0)
Block(-5,28,-3,ICE:0)
Block(-5,28,-2,ICE:0)
Block(-5,28,-1,ICE:0)
Block(-5,28,0,ICE:0)
Block(-5,28,1,ICE:0)
Block(-5,28,2,ICE:0)
Block(-5,29,-7,ICE:0)
Block(-5,29,-6,ICE:0)
Block(-5,29,-5,ICE:0)
Block(-5,29,-4,ICE:0)
Block(-5,29,-3,ICE:0)
Block(-5,29,-2,ICE:0)
Block(-5,29,-1,ICE:0)
Block(-5,29,0,ICE:0)
Block(-5,29,1,ICE:0)
Block(-5,30,-7,ICE:0)
Block(-5,30,-6,ICE:0)
Block(-5,30,-5,ICE:0)
Block(-5,30,-4,ICE:0)
Block(-5,30,-3,ICE:0)
Block(-5,30,-2,ICE:0)
Block(-5,30,-1,ICE:0)
Block(-5,30,0,ICE:0)
Block(-5,31,-7,ICE:0)
Block(-5,31,-6,ICE:0)
Block(-5,31,-5,ICE:0)
Block(-5,31,-4,ICE:0)
Block(-5,31,-3,ICE:0)
Block(-5,31,-2,ICE:0)
Block(-5,31,-1,ICE:0)
Block(-5,32,-7,ICE:0)
Block(-5,32,-6,ICE:0)
Block(-5,32,-5,ICE:0)
Block(-5,32,-4,ICE:0)
Block(-5,32,-3,ICE:0)
Block(-5,32,-2,ICE:0)
Block(-5,33,-7,ICE:0)
Block(-5,33,-6,ICE:0)
Block(-5,33,-5,ICE:0)
Block(-5,33,-4,ICE:0)
Block(-5,33,-3,ICE:0)
Block(-5,34,-7,ICE:0)
Block(-5,34,-6,ICE:0)
Block(-5,34,-5,ICE:0)
Block(-5,34,-4,ICE:0)
Block(-5,35,-7,ICE:0)
Block(-5,35,-6,ICE:0)
Block(-5,35,-5,ICE:0)
Block(-5,36,-7,ICE:0)
Block(-5,36,-6,ICE:0)
Block(-5,37,-7,ICE:0)
Block(-4,4,8,PACKED_ICE:0)
Block(-4,5,8,PACKED_ICE:0)
Block(-4,6,7,PACKED_ICE:0)
Block(-4,6,8,PACKED_ICE:0)
Block(-4,7,6,PACKED_ICE:0)
Block(-4,7,7,PACKED_ICE:0)
Block(-4,7,8,PACKED_ICE:0)
Block(-4,8,6,PACKED_ICE:0)
Block(-4,8,7,PACKED_ICE:0)
Block(-4,8,8,PACKED_ICE:0)
Block(-4,9,5,PACKED_ICE:0)
Block(-4,9,6,PACKED_ICE:0)
Block(-4,9,7,PACKED_ICE:0)
Block(-4,9,8,PACKED_ICE:0)
Block(-4,10,4,PACKED_ICE:0)
Block(-4,10,5,PACKED_ICE:0)
Block(-4,10,6,PACKED_ICE:0)
Block(-4,10,7,PACKED_ICE:0)
Block(-4,10,8,ICE:0)
Block(-4,11,4,PACKED_ICE:0)
Block(-4,11,5,PACKED_ICE:0)
Block(-4,11,6,PACKED_ICE:0)
Block(-4,11,7,ICE:0)
Block(-4,11,8,ICE:0)
Block(-4,12,3,PACKED_ICE:0)
Block(-4,12,4,PACKED_ICE:0)
Block(-4,12,5,PACKED_ICE:0)
Block(-4,12,6,ICE:0)
Block(-4,12,7,ICE:0)
Block(-4,12,8,ICE:0)
Block(-4,13,2,PACKED_ICE:0)
Block(-4,13,3,PACKED_ICE:0)
Block(-4,13,4,PACKED_ICE:0)
Block(-4,13,5,ICE:0)
Block(-4,13,6,ICE:0)
Block(-4,13,7,ICE:0)
Block(-4,13,8,ICE:0)
Block(-4,14,2,PACKED_ICE:0)
Block(-4,14,3,PACKED_ICE:0)
Block(-4,14,4,PACKED_ICE:0)
Block(-4,14,5,ICE:0)
Block(-4,14,6,ICE:0)
Block(-4,14,7,ICE:0)
Block(-4,14,8,ICE:0)
Block(-4,15,1,PACKED_ICE:0)
Block(-4,15,2,PACKED_ICE:0)
Block(-4,15,3,PACKED_ICE:0)
Block(-4,15,4,PACKED_ICE:0)
Block(-4,15,5,ICE:0)
Block(-4,15,6,ICE:0)
Block(-4,15,7,ICE:0)
Block(-4,15,8,ICE:0)
Block(-4,16,0,PACKED_ICE:0)
Block(-4,16,1,PACKED_ICE:0)
Block(-4,16,2,PACKED_ICE:0)
Block(-4,16,3,ICE:0)
Block(-4,16,4,ICE:0)
Block(-4,16,5,ICE:0)
Block(-4,16,6,ICE:0)
Block(-4,16,7,ICE:0)
Block(-4,16,8,ICE:0)
Block(-4,17,0,PACKED_ICE:0)
Block(-4,17,1,PACKED_ICE:0)
Block(-4,17,2,ICE:0)
Block(-4,17,3,ICE:0)
Block(-4,17,4,ICE:0)
Block(-4,17,5,ICE:0)
Block(-4,17,6,ICE:0)
Block(-4,17,7,ICE:0)
Block(-4,17,8,ICE:0)
Block(-4,18,-1,PACKED_ICE:0)
Block(-4,18,0,PACKED_ICE:0)
Block(-4,18,1,PACKED_ICE:0)
Block(-4,18,2,ICE:0)
Block(-4,18,3,ICE:0)
Block(-4,18,4,ICE:0)
Block(-4,18,5,ICE:0)
Block(-4,18,6,ICE:0)
Block(-4,18,7,ICE:0)
Block(-4,18,8,ICE:0)
Block(-4,19,-1,PACKED_ICE:0)
Block(-4,19,0,ICE:0)
Block(-4,19,1,ICE:0)
Block(-4,19,2,ICE:0)
Block(-4,19,3,ICE:0)
Block(-4,19,4,ICE:0)
Block(-4,19,5,ICE:0)
Block(-4,19,6,ICE:0)
Block(-4,19,7,ICE:0)
Block(-4,19,8,ICE:0)
Block(-4,20,-2,PACKED_ICE:0)
Block(-4,20,-1,ICE:0)
Block(-4,20,0,ICE:0)
Block(-4,20,1,ICE:0)
Block(-4,20,2,ICE:0)
Block(-4,20,3,ICE:0)
Block(-4,20,4,ICE:0)
Block(-4,20,5,ICE:0)
Block(-4,20,6,ICE:0)
Block(-4,20,7,ICE:0)
Block(-4,20,8,ICE:0)
Block(-4,21,-3,PACKED_ICE:0)
Block(-4,21,-2,PACKED_ICE:0)
Block(-4,21,-1,ICE:0)
Block(-4,21,0,ICE:0)
Block(-4,21,1,ICE:0)
Block(-4,21,2,ICE:0)
Block(-4,21,3,ICE:0)
Block(-4,21,4,ICE:0)
Block(-4,21,5,ICE:0)
Block(-4,21,6,ICE:0)
Block(-4,21,7,ICE:0)
Block(-4,21,8,ICE:0)
Block(-4,22,-3,PACKED_ICE:0)
Block(-4,22,-2,ICE:0)
Block(-4,22,-1,ICE:0)
Block(-4,22,0,ICE:0)
Block(-4,22,1,ICE:0)
Block(-4,22,2,ICE:0)
Block(-4,22,3,ICE:0)
Block(-4,22,4,ICE:0)
Block(-4,22,5,ICE:0)
Block(-4,22,6,ICE:0)
Block(-4,22,7,ICE:0)
Block(-4,23,-4,PACKED_ICE:0)
Block(-4,23,-3,ICE:0)
Block(-4,23,-2,ICE:0)
Block(-4,23,-1,ICE:0)
Block(-4,23,0,ICE:0)
Block(-4,23,1,ICE:0)
Block(-4,23,2,ICE:0)
Block(-4,23,3,ICE:0)
Block(-4,23,4,ICE:0)
Block(-4,23,5,ICE:0)
Block(-4,23,6,ICE:0)
Block(-4,24,-5,PACKED_ICE:0)
Block(-4,24,-4,ICE:0)
Block(-4,24,-3,ICE:0)
Block(-4,24,-2,ICE:0)
Block(-4,24,-1,ICE:0)
Block(-4,24,0,ICE:0)
Block(-4,24,1,ICE:0)
Block(-4,24,2,ICE:0)
Block(-4,24,3,ICE:0)
Block(-4,24,4,ICE:0)
Block(-4,24,5,ICE:0)
Block(-4,25,-5,ICE:0)
Block(-4,25,-4,ICE:0)
Block(-4,25,-3,ICE:0)
Block(-4,25,-2,ICE:0)
Block(-4,25,-1,ICE:0)
Block(-4,25,0,ICE:0)
Block(-4,25,1,ICE:0)
Block(-4,25,2,ICE:0)
Block(-4,25,3,ICE:0)
Block(-4,25,4,ICE:0)
Block(-4,26,-6,ICE:0)
Block(-4,26,-5,ICE:0)
Block(-4,26,-4,ICE:0)
Block(-4,26,-3,ICE:0)
Block(-4,26,-2,ICE:0)
Block(-4,26,-1,ICE:0)
Block(-4,26,0,ICE:0)
Block(-4,26,1,ICE:0)
Block(-4,26,2,ICE:0)
Block(-4,26,3,ICE:0)
Block(-4,27,-7,PACKED_ICE:0)
Block(-4,27,-6,ICE:0)
Block(-4,27,-5,ICE:0)
Block(-4,27,-4,ICE:0)
Block(-4,27,-3,ICE:0)
Block(-4,27,-2,ICE:0)
Block(-4,27,-1,ICE:0)
Block(-4,27,0,ICE:0)
Block(-4,27,1,ICE:0)
Block(-4,27,2,ICE:0)
Block(-4,28,-7,PACKED_ICE:0)
Block(-4,28,-6,ICE:0)
Block(-4,28,-5,ICE:0)
Block(-4,28,-4,ICE:0)
Block(-4,28,-3,ICE:0)
Block(-4,28,-2,ICE:0)
Block(-4,28,-1,ICE:0)
Block(-4,28,0,ICE:0)
Block(-4,28,1,ICE:0)
Block(-4,29,-7,ICE:0)
Block(-4,29,-6,ICE:0)
Block(-4,29,-5,ICE:0)
Block(-4,29,-4,ICE:0)
Block(-4,29,-3,ICE:0)
Block(-4,29,-2,ICE:0)
Block(-4,29,-1,ICE:0)
Block(-4,29,0,ICE:0)
Block(-4,30,-7,ICE:0)
Block(-4,30,-6,ICE:0)
Block(-4,30,-5,ICE:0)
Block(-4,30,-4,ICE:0)
Block(-4,30,-3,ICE:0)
Block(-4,30,-2,ICE:0)
Block(-4,30,-1,ICE:0)
Block(-4,31,-7,ICE:0)
Block(-4,31,-6,ICE:0)
Block(-4,31,-5,ICE:0)
Block(-4,31,-4,ICE:0)
Block(-4,31,-3,ICE:0)
Block(-4,31,-2,ICE:0)
Block(-4,32,-7,ICE:0)
Block(-4,32,-6,ICE:0)
Block(-4,32,-5,ICE:0)
Block(-4,32,-4,ICE:0)
Block(-4,32,-3,ICE:0)
Block(-4,33,-7,ICE:0)
Block(-4,33,-6,ICE:0)
Block(-4,33,-5,ICE:0)
Block(-4,33,-4,ICE:0)
Block(-4,34,-7,ICE:0)
Block(-4,34,-6,ICE:0)
Block(-4,34,-5,ICE:0)
Block(-4,35,-7,ICE:0)
Block(-3,5,8,PACKED_ICE:0)
Block(-3,6,8,PACKED_ICE:0)
Block(-3,7,7,PACKED_ICE:0)
Block(-3,7,8,PACKED_ICE:0)
Block(-3,8,6,PACKED_ICE:0)
Block(-3,8,7,PACKED_ICE:0)
Block(-3,8,8,PACKED_ICE:0)
Block(-3,9,6,PACKED_ICE:0)
Block(-3,9,7,PACKED_ICE:0)
Block(-3,9,8,ICE:0)
Block(-3,10,5,PACKED_ICE:0)
Block(-3,10,6,PACKED_ICE:0)
Block(-3,10,7,ICE:0)
Block(-3,10,8,ICE:0)
Block(-3,11,4,PACKED_ICE:0)
Block(-3,11,5,PACKED_ICE:0)
Block(-3,11,6,ICE:0)
Block(-3,11,7,ICE:0)
Block(-3,11,8,ICE:0)
Block(-3,12,4,PACKED_ICE:0)
Block(-3,12,5,ICE:0)
Block(-3,12,6,ICE:0)
Block(-3,12,7,ICE:0)
Block(-3,12,8,ICE:0)
Block(-3,13,3,PACKED_ICE:0)
Block(-3,13,4,PACKED_ICE:0)
Block(-3,13,5,ICE:0)
Block(-3,13,6,ICE:0)
Block(-3,13,7,ICE:0)
Block(-3,13,8,ICE:0)
Block(-3,14,2,PACKED_ICE:0)
Block(-3,14,3,PACKED_ICE:0)
Block(-3,14,4,ICE:0)
Block(-3,14,5,ICE:0)
Block(-3,14,6,ICE:0)
Block(-3,14,7,ICE:0)
Block(-3,14,8,ICE:0)
Block(-3,15,2,PACKED_ICE:0)
Block(-3,15,3,PACKED_ICE:0)
Block(-3,15,4,ICE:0)
Block(-3,15,5,ICE:0)
Block(-3,15,6,ICE:0)
Block(-3,15,7,ICE:0)
Block(-3,15,8,ICE:0)
Block(-3,16,1,PACKED_ICE:0)
Block(-3,16,2,PACKED_ICE:0)
Block(-3,16,3,ICE:0)
Block(-3,16,4,ICE:0)
Block(-3,16,5,ICE:0)
Block(-3,16,6,ICE:0)
Block(-3,16,7,ICE:0)
Block(-3,16,8,ICE:0)
Block(-3,17,0,PACKED_ICE:0)
Block(-3,17,1,PACKED_ICE:0)
Block(-3,17,2,ICE:0)
Block(-3,17,3,ICE:0)
Block(-3,17,4,ICE:0)
Block(-3,17,5,ICE:0)
Block(-3,17,6,ICE:0)
Block(-3,17,7,ICE:0)
Block(-3,17,8,ICE:0)
Block(-3,18,0,PACKED_ICE:0)
Block(-3,18,1,ICE:0)
Block(-3,18,2,ICE:0)
Block(-3,18,3,ICE:0)
Block(-3,18,4,ICE:0)
Block(-3,18,5,ICE:0)
Block(-3,18,6,ICE:0)
Block(-3,18,7,ICE:0)
Block(-3,18,8,ICE:0)
Block(-3,19,-1,PACKED_ICE:0)
Block(-3,19,0,ICE:0)
Block(-3,19,1,ICE:0)
Block(-3,19,2,ICE:0)
Block(-3,19,3,ICE:0)
Block(-3,19,4,ICE:0)
Block(-3,19,5,ICE:0)
Block(-3,19,6,ICE:0)
Block(-3,19,7,ICE:0)
Block(-3,19,8,ICE:0)
Block(-3,20,-2,PACKED_ICE:0)
Block(-3,20,-1,ICE:0)
Block(-3,20,0,ICE:0)
Block(-3,20,1,ICE:0)
Block(-3,20,2,ICE:0)
Block(-3,20,3,ICE:0)
Block(-3,20,4,ICE:0)
Block(-3,20,5,ICE:0)
Block(-3,20,6,ICE:0)
Block(-3,20,7,ICE:0)
Block(-3,20,8,ICE:0)
Block(-3,21,-2,ICE:0)
Block(-3,21,-1,ICE:0)
Block(-3,21,0,ICE:0)
Block(-3,21,1,ICE:0)
Block(-3,21,2,ICE:0)
Block(-3,21,3,ICE:0)
Block(-3,21,4,ICE:0)
Block(-3,21,5,ICE:0)
Block(-3,21,6,ICE:0)
Block(-3,22,-3,PACKED_ICE:0)
Block(-3,22,-2,ICE:0)
Block(-3,22,-1,ICE:0)
Block(-3,22,0,ICE:0)
Block(-3,22,1,ICE:0)
Block(-3,22,2,ICE:0)
Block(-3,22,3,ICE:0)
Block(-3,22,4,ICE:0)
Block(-3,22,5,ICE:0)
Block(-3,23,-3,ICE:0)
Block(-3,23,-2,ICE:0)
Block(-3,23,-1,ICE:0)
Block(-3,23,0,ICE:0)
Block(-3,23,1,ICE:0)
Block(-3,23,2,ICE:0)
Block(-3,23,3,ICE:0)
Block(-3,23,4,ICE:0)
Block(-3,24,-4,ICE:0)
Block(-3,24,-3,ICE:0)
Block(-3,24,-2,ICE:0)
Block(-3,24,-1,ICE:0)
Block(-3,24,0,ICE:0)
Block(-3,24,1,ICE:0)
Block(-3,24,2,ICE:0)
Block(-3,24,3,ICE:0)
Block(-3,25,-5,ICE:0)
Block(-3,25,-4,ICE:0)
Block(-3,25,-3,ICE:0)
Block(-3,25,-2,ICE:0)
Block(-3,25,-1,ICE:0)
Block(-3,25,0,ICE:0)
Block(-3,25,1,ICE:0)
Block(-3,25,2,ICE:0)
Block(-3,26,-5,ICE:0)
Block(-3,26,-4,ICE:0)
Block(-3,26,-3,ICE:0)
Block(-3,26,-2,ICE:0)
Block(-3,26,-1,ICE:0)
Block(-3,26,0,ICE:0)
Block(-3,26,1,ICE:0)
Block(-3,27,-6,ICE:0)
Block(-3,27,-5,ICE:0)
Block(-3,27,-4,ICE:0)
Block(-3,27,-3,ICE:0)
Block(-3,27,-2,ICE:0)
Block(-3,27,-1,ICE:0)
Block(-3,27,0,ICE:0)
Block(-3,28,-7,PACKED_ICE:0)
Block(-3,28,-6,ICE:0)
Block(-3,28,-5,ICE:0)
Block(-3,28,-4,ICE:0)
Block(-3,28,-3,ICE:0)
Block(-3,28,-2,ICE:0)
Block(-3,28,-1,ICE:0)
Block(-3,29,-7,ICE:0)
Block(-3,29,-6,ICE:0)
Block(-3,29,-5,ICE:0)
Block(-3,29,-4,ICE:0)
Block(-3,29,-3,ICE:0)
Block(-3,29,-2,ICE:0)
Block(-3,30,-7,ICE:0)
Block(-3,30,-6,ICE:0)
Block(-3,30,-5,ICE:0)
Block(-3,30,-4,ICE:0)
Block(-3,30,-3,ICE:0)
Block(-3,31,-7,ICE:0)
Block(-3,31,-6,ICE:0)
Block(-3,31,-5,ICE:0)
Block(-3,31,-4,ICE:0)
Block(-3,32,-7,ICE:0)
Block(-3,32,-6,ICE:0)
Block(-3,32,-5,ICE:0)
Block(-3,33,-7,ICE:0)
Block(-3,33,-6,ICE:0)
Block(-3,34,-7,ICE:0)
Block(-2,6,8,PACKED_ICE:0)
Block(-2,7,8,PACKED_ICE:0)
Block(-2,8,7,PACKED_ICE:0)
Block(-2,8,8,ICE:0)
Block(-2,9,6,PACKED_ICE:0)
Block(-2,9,7,ICE:0)
Block(-2,9,8,ICE:0)
Block(-2,10,6,PACKED_ICE:0)
Block(-2,10,7,ICE:0)
Block(-2,10,8,ICE:0)
Block(-2,11,5,PACKED_ICE:0)
Block(-2,11,6,ICE:0)
Block(-2,11,7,ICE:0)
Block(-2,11,8,ICE:0)
Block(-2,12,4,PACKED_ICE:0)
Block(-2,12,5,ICE:0)
Block(-2,12,6,ICE:0)
Block(-2,12,7,ICE:0)
Block(-2,12,8,ICE:0)
Block(-2,13,4,ICE:0)
Block(-2,13,5,ICE:0)
Block(-2,13,6,ICE:0)
Block(-2,13,7,ICE:0)
Block(-2,13,8,ICE:0)
Block(-2,14,3,PACKED_ICE:0)
Block(-2,14,4,ICE:0)
Block(-2,14,5,ICE:0)
Block(-2,14,6,ICE:0)
Block(-2,14,7,ICE:0)
Block(-2,14,8,ICE:0)
Block(-2,15,2,PACKED_ICE:0)
Block(-2,15,3,PACKED_ICE:0)
Block(-2,15,4,ICE:0)
Block(-2,15,5,ICE:0)
Block(-2,15,6,ICE:0)
Block(-2,15,7,ICE:0)
Block(-2,15,8,ICE:0)
Block(-2,16,2,PACKED_ICE:0)
Block(-2,16,3,ICE:0)
Block(-2,16,4,ICE:0)
Block(-2,16,5,ICE:0)
Block(-2,16,6,ICE:0)
Block(-2,16,7,ICE:0)
Block(-2,16,8,ICE:0)
Block(-2,17,1,PACKED_ICE:0)
Block(-2,17,2,ICE:0)
Block(-2,17,3,ICE:0)
Block(-2,17,4,ICE:0)
Block(-2,17,5,ICE:0)
Block(-2,17,6,ICE:0)
Block(-2,17,7,ICE:0)
Block(-2,17,8,ICE:0)
Block(-2,18,0,PACKED_ICE:0)
Block(-2,18,1,ICE:0)
Block(-2,18,2,ICE:0)
Block(-2,18,3,ICE:0)
Block(-2,18,4,ICE:0)
Block(-2,18,5,ICE:0)
Block(-2,18,6,ICE:0)
Block(-2,18,7,ICE:0)
Block(-2,18,8,ICE:0)
Block(-2,19,0,ICE:0)
Block(-2,19,1,ICE:0)
Block(-2,19,2,ICE:0)
Block(-2,19,3,ICE:0)
Block(-2,19,4,ICE:0)
Block(-2,19,5,ICE:0)
Block(-2,19,6,ICE:0)
Block(-2,19,7,ICE:0)
Block(-2,20,-1,ICE:0)
Block(-2,20,0,ICE:0)
Block(-2,20,1,ICE:0)
Block(-2,20,2,ICE:0)
Block(-2,20,3,ICE:0)
Block(-2,20,4,ICE:0)
Block(-2,20,5,ICE:0)
Block(-2,20,6,ICE:0)
Block(-2,21,-2,ICE:0)
Block(-2,21,-1,ICE:0)
Block(-2,21,0,ICE:0)
Block(-2,21,1,ICE:0)
Block(-2,21,2,ICE:0)
Block(-2,21,3,ICE:0)
Block(-2,21,4,ICE:0)
Block(-2,21,5,ICE:0)
Block(-2,22,-2,ICE:0)
Block(-2,22,-1,ICE:0)
Block(-2,22,0,ICE:0)
Block(-2,22,1,ICE:0)
Block(-2,22,2,ICE:0)
Block(-2,22,3,ICE:0)
Block(-2,22,4,ICE:0)
Block(-2,23,-3,ICE:0)
Block(-2,23,-2,ICE:0)
Block(-2,23,-1,ICE:0)
Block(-2,23,0,ICE:0)
Block(-2,23,1,ICE:0)
Block(-2,23,2,ICE:0)
Block(-2,23,3,ICE:0)
Block(-2,24,-4,ICE:0)
Block(-2,24,-3,ICE:0)
Block(-2,24,-2,ICE:0)
Block(-2,24,-1,ICE:0)
Block(-2,24,0,ICE:0)
Block(-2,24,1,ICE:0)
Block(-2,24,2,ICE:0)
Block(-2,25,-4,ICE:0)
Block(-2,25,-3,ICE:0)
Block(-2,25,-2,ICE:0)
Block(-2,25,-1,ICE:0)
Block(-2,25,0,ICE:0)
Block(-2,25,1,ICE:0)
Block(-2,26,-5,ICE:0)
Block(-2,26,-4,ICE:0)
Block(-2,26,-3,ICE:0)
Block(-2,26,-2,ICE:0)
Block(-2,26,-1,ICE:0)
Block(-2,26,0,ICE:0)
Block(-2,27,-5,ICE:0)
Block(-2,27,-4,ICE:0)
Block(-2,27,-3,ICE:0)
Block(-2,27,-2,ICE:0)
Block(-2,27,-1,ICE:0)
Block(-2,28,-6,ICE:0)
Block(-2,28,-5,ICE:0)
Block(-2,28,-4,ICE:0)
Block(-2,28,-3,ICE:0)
Block(-2,28,-2,ICE:0)
Block(-2,29,-7,ICE:0)
Block(-2,29,-6,ICE:0)
Block(-2,29,-5,ICE:0)
Block(-2,29,-4,ICE:0)
Block(-2,30,-7,ICE:0)
Block(-2,30,-6,ICE:0)
Block(-2,30,-5,ICE:0)
Block(-2,31,-7,ICE:0)
Block(-2,31,-6,ICE:0)
Block(-2,32,-7,ICE:0)
Block(-1,7,8,PACKED_ICE:0)
Block(-1,8,8,ICE:0)
Block(-1,9,7,ICE:0)
Block(-1,9,8,ICE:0)
Block(-1,10,6,ICE:0)
Block(-1,10,7,ICE:0)
Block(-1,10,8,ICE:0)
Block(-1,11,6,ICE:0)
Block(-1,11,7,ICE:0)
Block(-1,11,8,ICE:0)
Block(-1,12,5,ICE:0)
Block(-1,12,6,ICE:0)
Block(-1,12,7,ICE:0)
Block(-1,12,8,ICE:0)
Block(-1,13,4,ICE:0)
Block(-1,13,5,ICE:0)
Block(-1,13,6,ICE:0)
Block(-1,13,7,ICE:0)
Block(-1,13,8,ICE:0)
Block(-1,14,4,ICE:0)
Block(-1,14,5,ICE:0)
Block(-1,14,6,ICE:0)
Block(-1,14,7,ICE:0)
Block(-1,14,8,ICE:0)
Block(-1,15,3,PACKED_ICE:0)
Block(-1,15,4,ICE:0)
Block(-1,15,5,ICE:0)
Block(-1,15,6,ICE:0)
Block(-1,15,7,ICE:0)
Block(-1,15,8,ICE:0)
Block(-1,16,2,PACKED_ICE:0)
Block(-1,16,3,ICE:0)
Block(-1,16,4,ICE:0)
Block(-1,16,5,ICE:0)
Block(-1,16,6,ICE:0)
Block(-1,16,7,ICE:0)
Block(-1,16,8,ICE:0)
Block(-1,17,2,ICE:0)
Block(-1,17,3,ICE:0)
Block(-1,17,4,ICE:0)
Block(-1,17,5,ICE:0)
Block(-1,17,6,ICE:0)
Block(-1,17,7,ICE:0)
Block(-1,18,1,ICE:0)
Block(-1,18,2,ICE:0)
Block(-1,18,3,ICE:0)
Block(-1,18,4,ICE:0)
Block(-1,18,5,ICE:0)
Block(-1,18,6,ICE:0)
Block(-1,19,0,ICE:0)
Block(-1,19,1,ICE:0)
Block(-1,19,2,ICE:0)
Block(-1,19,3,ICE:0)
Block(-1,19,4,ICE:0)
Block(-1,19,5,ICE:0)
Block(-1,20,0,ICE:0)
Block(-1,20,1,ICE:0)
Block(-1,20,2,ICE:0)
Block(-1,20,3,ICE:0)
Block(-1,20,4,ICE:0)
Block(-1,21,-1,ICE:0)
Block(-1,21,0,ICE:0)
Block(-1,21,1,ICE:0)
Block(-1,21,2,ICE:0)
Block(-1,21,3,ICE:0)
Block(-1,22,-2,ICE:0)
Block(-1,22,-1,ICE:0)
Block(-1,22,0,ICE:0)
Block(-1,22,1,ICE:0)
Block(-1,22,2,ICE:0)
Block(-1,23,-2,ICE:0)
Block(-1,23,-1,ICE:0)
Block(-1,23,0,ICE:0)
Block(-1,23,1,ICE:0)
Block(-1,24,-3,ICE:0)
Block(-1,24,-2,ICE:0)
Block(-1,24,-1,ICE:0)
Block(-1,24,0,ICE:0)
Block(-1,25,-4,ICE:0)
Block(-1,25,-3,ICE:0)
Block(-1,25,-2,ICE:0)
Block(-1,25,-1,ICE:0)
Block(-1,26,-4,ICE:0)
Block(-1,26,-3,ICE:0)
Block(-1,26,-2,ICE:0)
Block(-1,27,-5,ICE:0)
Block(-1,27,-4,ICE:0)
Block(-1,27,-3,ICE:0)
Block(-1,28,-6,ICE:0)
Block(-1,28,-5,ICE:0)
Block(-1,28,-4,ICE:0)
Block(-1,29,-6,ICE:0)
Block(-1,29,-5,ICE:0)
Block(-1,30,-7,ICE:0)
Block(-1,30,-6,ICE:0)
Block(-1,31,-7,ICE:0)
Block(0,8,8,ICE:0)
Block(0,9,8,ICE:0)
Block(0,10,7,ICE:0)
Block(0,10,8,ICE:0)
Block(0,11,6,ICE:0)
Block(0,11,7,ICE:0)
Block(0,11,8,ICE:0)
Block(0,12,6,ICE:0)
Block(0,12,7,ICE:0)
Block(0,12,8,ICE:0)
Block(0,13,5,ICE:0)
Block(0,13,6,ICE:0)
Block(0,13,7,ICE:0)
Block(0,13,8,ICE:0)
Block(0,14,4,ICE:0)
Block(0,14,5,ICE:0)
Block(0,14,6,ICE:0)
Block(0,14,7,ICE:0)
Block(0,14,8,ICE:0)
Block(0,15,4,ICE:0)
Block(0,15,5,ICE:0)
Block(0,15,6,ICE:0)
Block(0,15,7,ICE:0)
Block(0,15,8,ICE:0)
Block(0,16,3,ICE:0)
Block(0,16,4,ICE:0)
Block(0,16,5,ICE:0)
Block(0,16,6,ICE:0)
Block(0,16,7,ICE:0)
Block(0,17,2,ICE:0)
Block(0,17,3,ICE:0)
Block(0,17,4,ICE:0)
Block(0,17,5,ICE:0)
Block(0,17,6,ICE:0)
Block(0,18,2,ICE:0)
Block(0,18,3,ICE:0)
Block(0,18,4,ICE:0)
Block(0,18,5,ICE:0)
Block(0,19,1,ICE:0)
Block(0,19,2,ICE:0)
Block(0,19,3,ICE:0)
Block(0,19,4,ICE:0)
Block(0,20,0,ICE:0)
Block(0,20,1,ICE:0)
Block(0,20,2,ICE:0)
Block(0,20,3,ICE:0)
Block(0,21,0,ICE:0)
Block(0,21,1,ICE:0)
Block(0,21,2,ICE:0)
Block(0,22,-1,ICE:0)
Block(0,22,0,ICE:0)
Block(0,22,1,ICE:0)
Block(0,23,-2,ICE:0)
Block(0,23,-1,ICE:0)
Block(0,23,0,ICE:0)
Block(0,24,-2,ICE:0)
Block(0,25,-3,ICE:0)
Block(0,26,-4,ICE:0)
Block(1,9,8,ICE:0)
Block(1,10,7,ICE:0)
Block(1,10,8,ICE:0)
Block(1,11,7,ICE:0)
Block(1,11,8,ICE:0)
Block(1,12,6,ICE:0)
Block(1,12,7,ICE:0)
Block(1,12,8,ICE:0)
Block(1,13,6,ICE:0)
Block(1,13,7,ICE:0)
Block(1,13,8,ICE:0)
Block(1,14,5,ICE:0)
Block(1,14,6,ICE:0)
Block(1,14,7,ICE:0)
Block(1,15,4,ICE:0)
Block(1,15,5,ICE:0)
Block(1,15,6,ICE:0)
Block(1,16,4,ICE:0)
Block(1,16,5,ICE:0)
Block(1,17,3,ICE:0)
Block(1,17,4,ICE:0)
Block(1,18,2,ICE:0)
Block(1,18,3,ICE:0)
Block(1,19,2,ICE:0)
Block(1,20,1,ICE:0)
Block(1,21,0,ICE:0)
Block(2,10,8,ICE:0)
Block(2,11,7,ICE:0)
Block(2,11,8,ICE:0)
Block(2,12,7,ICE:0)
Block(2,12,8,ICE:0)
Block(2,13,6,ICE:0)
Block(2,13,7,ICE:0)
Block(2,14,5,ICE:0)
Block(2,14,6,ICE:0)
Block(2,15,5,ICE:0)
Block(2,16,4,PACKED_ICE:0)

#######################################################################
# +-----------------------------------------------------------------+ #
# |                             Branches                            | #
# +-----------------------------------------------------------------+ #
#######################################################################

Branch(0,0,16,true,IceSpike_Huge_11C1R4,NORTH,100.0,0)

#######################################################################
# +-----------------------------------------------------------------+ #
# |                             Entities                            | #
# +-----------------------------------------------------------------+ #
#######################################################################


#######################################################################
# +-----------------------------------------------------------------+ #
# |                            Particles                            | #
# +-----------------------------------------------------------------+ #
#######################################################################


#######################################################################
# +-----------------------------------------------------------------+ #
# |                             Spawners                            | #
# +-----------------------------------------------------------------+ #
#######################################################################


#######################################################################
# +-----------------------------------------------------------------+ #
# |                             ModData                             | #
# +-----------------------------------------------------------------+ #
#######################################################################

