
#######################################################################
# +-----------------------------------------------------------------+ #
# |                            BO4 object                           | #
# +-----------------------------------------------------------------+ #
#######################################################################

Author: NLBlackEagle

Description: No description given

SettingsMode: WriteDisable


#######################################################################
# +-----------------------------------------------------------------+ #
# |                          Main settings                          | #
# +-----------------------------------------------------------------+ #
#######################################################################

Frequency: 0

SpawnHeight: highestBlock

UseCenterForHighestBlock: true

##############################
# Height Limits for the BO4. #
##############################

MinHeight: 0

MaxHeight: 255

InheritBO3: 

InheritBO3Rotation: NORTH

OverrideChildSettings: true

OverrideParentHeight: false

CanOverride: true

BranchFrequency: 0

BranchFrequencyGroup: 

MustBeBelowOther: false

MustBeInside: 

CannotBeInside: 

ReplacesBO3: 

MustBeInsideWorldBorders: false

CanSpawnOnWater: true

SpawnOnWaterOnly: false

SpawnUnderWater: false

SpawnAtWaterLevel: false

HeightOffset: 0

RemoveAir: true

ReplaceAbove: 

ReplaceBelow: 

ReplaceWithBiomeBlocks: true

ReplaceWithSurfaceBlock: GRASS

ReplaceWithGroundBlock: DIRT

ReplaceWithStoneBlock: STONE

SmoothRadius: 0

SmoothHeightOffset: 0

SmoothStartTop: false

SmoothStartWood: false

SmoothingSurfaceBlock: 

SmoothingGroundBlock: 

BO3Group: 

IsSpawnPoint: false

DoReplaceBlocks: true


#######################################################################
# +-----------------------------------------------------------------+ #
# |                              Blocks                             | #
# +-----------------------------------------------------------------+ #
#######################################################################

Block(-3,22,8,ICE:0)
Block(-3,23,7,ICE:0)
Block(-3,23,8,ICE:0)
Block(-3,24,7,ICE:0)
Block(-3,24,8,ICE:0)
Block(-3,25,6,ICE:0)
Block(-3,25,7,ICE:0)
Block(-3,25,8,ICE:0)
Block(-3,26,5,ICE:0)
Block(-3,26,6,ICE:0)
Block(-3,26,7,ICE:0)
Block(-3,26,8,ICE:0)
Block(-3,27,5,ICE:0)
Block(-3,27,6,ICE:0)
Block(-3,27,7,ICE:0)
Block(-3,27,8,ICE:0)
Block(-3,28,4,ICE:0)
Block(-3,28,5,ICE:0)
Block(-3,28,6,ICE:0)
Block(-3,28,7,ICE:0)
Block(-3,28,8,ICE:0)
Block(-3,29,3,ICE:0)
Block(-3,29,4,ICE:0)
Block(-3,29,5,ICE:0)
Block(-3,29,6,ICE:0)
Block(-3,29,7,ICE:0)
Block(-3,29,8,ICE:0)
Block(-3,30,3,ICE:0)
Block(-3,30,4,ICE:0)
Block(-3,30,5,ICE:0)
Block(-3,30,6,ICE:0)
Block(-3,30,7,ICE:0)
Block(-3,30,8,ICE:0)
Block(-3,31,3,ICE:0)
Block(-3,31,4,ICE:0)
Block(-3,31,5,ICE:0)
Block(-3,31,6,ICE:0)
Block(-3,31,7,ICE:0)
Block(-3,31,8,ICE:0)
Block(-3,32,3,ICE:0)
Block(-3,32,4,ICE:0)
Block(-3,32,5,ICE:0)
Block(-3,32,6,ICE:0)
Block(-3,32,7,ICE:0)
Block(-3,32,8,ICE:0)
Block(-3,33,3,ICE:0)
Block(-3,33,4,ICE:0)
Block(-3,33,5,ICE:0)
Block(-3,33,6,ICE:0)
Block(-3,33,7,ICE:0)
Block(-3,33,8,ICE:0)
Block(-3,34,3,ICE:0)
Block(-3,34,4,ICE:0)
Block(-3,34,5,ICE:0)
Block(-3,34,6,ICE:0)
Block(-3,34,7,ICE:0)
Block(-3,34,8,ICE:0)
Block(-3,35,3,ICE:0)
Block(-3,35,4,ICE:0)
Block(-3,35,5,ICE:0)
Block(-3,35,6,ICE:0)
Block(-3,35,7,ICE:0)
Block(-3,36,3,ICE:0)
Block(-3,36,4,ICE:0)
Block(-3,36,5,ICE:0)
Block(-3,36,6,ICE:0)
Block(-3,37,3,ICE:0)
Block(-3,37,4,ICE:0)
Block(-3,37,5,ICE:0)
Block(-3,38,2,ICE:0)
Block(-3,38,3,ICE:0)
Block(-3,38,4,ICE:0)
Block(-3,39,2,ICE:0)
Block(-3,39,3,ICE:0)
Block(-3,40,2,ICE:0)
Block(-2,22,8,ICE:0)
Block(-2,23,8,ICE:0)
Block(-2,24,7,ICE:0)
Block(-2,24,8,ICE:0)
Block(-2,25,6,ICE:0)
Block(-2,25,7,ICE:0)
Block(-2,25,8,ICE:0)
Block(-2,26,6,ICE:0)
Block(-2,26,7,ICE:0)
Block(-2,26,8,ICE:0)
Block(-2,27,5,ICE:0)
Block(-2,27,6,ICE:0)
Block(-2,27,7,ICE:0)
Block(-2,27,8,ICE:0)
Block(-2,28,4,ICE:0)
Block(-2,28,5,ICE:0)
Block(-2,28,6,ICE:0)
Block(-2,28,7,ICE:0)
Block(-2,28,8,ICE:0)
Block(-2,29,4,ICE:0)
Block(-2,29,5,ICE:0)
Block(-2,29,6,ICE:0)
Block(-2,29,7,ICE:0)
Block(-2,29,8,ICE:0)
Block(-2,30,3,ICE:0)
Block(-2,30,4,ICE:0)
Block(-2,30,5,ICE:0)
Block(-2,30,6,ICE:0)
Block(-2,30,7,ICE:0)
Block(-2,30,8,ICE:0)
Block(-2,31,2,ICE:0)
Block(-2,31,3,ICE:0)
Block(-2,31,4,ICE:0)
Block(-2,31,5,ICE:0)
Block(-2,31,6,ICE:0)
Block(-2,31,7,ICE:0)
Block(-2,31,8,ICE:0)
Block(-2,32,1,ICE:0)
Block(-2,32,2,ICE:0)
Block(-2,32,3,ICE:0)
Block(-2,32,4,ICE:0)
Block(-2,32,5,ICE:0)
Block(-2,32,6,ICE:0)
Block(-2,32,7,ICE:0)
Block(-2,32,8,ICE:0)
Block(-2,33,1,ICE:0)
Block(-2,33,2,ICE:0)
Block(-2,33,3,ICE:0)
Block(-2,33,4,ICE:0)
Block(-2,33,5,ICE:0)
Block(-2,33,6,ICE:0)
Block(-2,33,7,ICE:0)
Block(-2,33,8,ICE:0)
Block(-2,34,0,ICE:0)
Block(-2,34,1,ICE:0)
Block(-2,34,2,ICE:0)
Block(-2,34,3,ICE:0)
Block(-2,34,4,ICE:0)
Block(-2,34,5,ICE:0)
Block(-2,34,6,ICE:0)
Block(-2,34,7,ICE:0)
Block(-2,34,8,ICE:0)
Block(-2,35,-1,ICE:0)
Block(-2,35,0,ICE:0)
Block(-2,35,1,ICE:0)
Block(-2,35,2,ICE:0)
Block(-2,35,3,ICE:0)
Block(-2,35,4,ICE:0)
Block(-2,35,5,ICE:0)
Block(-2,35,6,ICE:0)
Block(-2,35,7,ICE:0)
Block(-2,35,8,ICE:0)
Block(-2,36,-1,ICE:0)
Block(-2,36,0,ICE:0)
Block(-2,36,1,ICE:0)
Block(-2,36,2,ICE:0)
Block(-2,36,3,ICE:0)
Block(-2,36,4,ICE:0)
Block(-2,36,5,ICE:0)
Block(-2,36,6,ICE:0)
Block(-2,36,7,ICE:0)
Block(-2,36,8,PACKED_ICE:0)
Block(-2,37,-2,ICE:0)
Block(-2,37,-1,ICE:0)
Block(-2,37,0,ICE:0)
Block(-2,37,1,ICE:0)
Block(-2,37,2,ICE:0)
Block(-2,37,3,ICE:0)
Block(-2,37,4,ICE:0)
Block(-2,37,5,ICE:0)
Block(-2,37,6,ICE:0)
Block(-2,37,7,PACKED_ICE:0)
Block(-2,37,8,PACKED_ICE:0)
Block(-2,38,-3,ICE:0)
Block(-2,38,-2,ICE:0)
Block(-2,38,-1,ICE:0)
Block(-2,38,0,ICE:0)
Block(-2,38,1,ICE:0)
Block(-2,38,2,ICE:0)
Block(-2,38,3,ICE:0)
Block(-2,38,4,ICE:0)
Block(-2,38,5,ICE:0)
Block(-2,38,6,PACKED_ICE:0)
Block(-2,38,7,PACKED_ICE:0)
Block(-2,39,-3,ICE:0)
Block(-2,39,-2,ICE:0)
Block(-2,39,-1,ICE:0)
Block(-2,39,0,ICE:0)
Block(-2,39,1,ICE:0)
Block(-2,39,2,ICE:0)
Block(-2,39,3,ICE:0)
Block(-2,39,4,ICE:0)
Block(-2,39,5,PACKED_ICE:0)
Block(-2,39,6,PACKED_ICE:0)
Block(-2,40,-3,ICE:0)
Block(-2,40,-2,ICE:0)
Block(-2,40,-1,ICE:0)
Block(-2,40,0,ICE:0)
Block(-2,40,1,ICE:0)
Block(-2,40,2,ICE:0)
Block(-2,40,3,ICE:0)
Block(-2,40,4,PACKED_ICE:0)
Block(-2,40,5,PACKED_ICE:0)
Block(-2,41,-3,ICE:0)
Block(-2,41,-2,ICE:0)
Block(-2,41,-1,ICE:0)
Block(-2,41,0,ICE:0)
Block(-2,41,1,ICE:0)
Block(-2,41,2,ICE:0)
Block(-2,41,3,PACKED_ICE:0)
Block(-2,41,4,PACKED_ICE:0)
Block(-2,42,-3,ICE:0)
Block(-2,42,-2,ICE:0)
Block(-2,42,-1,ICE:0)
Block(-2,42,0,ICE:0)
Block(-2,42,1,ICE:0)
Block(-2,42,2,ICE:0)
Block(-2,43,-3,ICE:0)
Block(-2,43,-2,ICE:0)
Block(-2,43,-1,ICE:0)
Block(-2,43,0,ICE:0)
Block(-2,43,1,ICE:0)
Block(-2,44,-4,ICE:0)
Block(-2,44,-3,ICE:0)
Block(-2,44,-2,ICE:0)
Block(-2,44,-1,ICE:0)
Block(-2,44,0,ICE:0)
Block(-2,45,-4,ICE:0)
Block(-2,45,-3,ICE:0)
Block(-2,45,-2,ICE:0)
Block(-2,45,-1,ICE:0)
Block(-2,46,-4,ICE:0)
Block(-2,46,-3,ICE:0)
Block(-2,46,-2,PACKED_ICE:0)
Block(-2,47,-4,ICE:0)
Block(-2,47,-3,ICE:0)
Block(-2,48,-4,ICE:0)
Block(-1,22,8,ICE:0)
Block(-1,23,8,ICE:0)
Block(-1,24,7,ICE:0)
Block(-1,24,8,ICE:0)
Block(-1,25,6,ICE:0)
Block(-1,25,7,ICE:0)
Block(-1,25,8,ICE:0)
Block(-1,26,6,ICE:0)
Block(-1,26,7,ICE:0)
Block(-1,26,8,ICE:0)
Block(-1,27,5,ICE:0)
Block(-1,27,6,ICE:0)
Block(-1,27,7,ICE:0)
Block(-1,27,8,ICE:0)
Block(-1,28,4,ICE:0)
Block(-1,28,5,ICE:0)
Block(-1,28,6,ICE:0)
Block(-1,28,7,ICE:0)
Block(-1,28,8,ICE:0)
Block(-1,29,4,ICE:0)
Block(-1,29,5,ICE:0)
Block(-1,29,6,ICE:0)
Block(-1,29,7,ICE:0)
Block(-1,29,8,ICE:0)
Block(-1,30,3,ICE:0)
Block(-1,30,4,ICE:0)
Block(-1,30,5,ICE:0)
Block(-1,30,6,ICE:0)
Block(-1,30,7,ICE:0)
Block(-1,30,8,ICE:0)
Block(-1,31,2,ICE:0)
Block(-1,31,3,ICE:0)
Block(-1,31,4,ICE:0)
Block(-1,31,5,ICE:0)
Block(-1,31,6,ICE:0)
Block(-1,31,7,ICE:0)
Block(-1,31,8,ICE:0)
Block(-1,32,2,ICE:0)
Block(-1,32,3,ICE:0)
Block(-1,32,4,ICE:0)
Block(-1,32,5,ICE:0)
Block(-1,32,6,ICE:0)
Block(-1,32,7,ICE:0)
Block(-1,32,8,ICE:0)
Block(-1,33,1,ICE:0)
Block(-1,33,2,ICE:0)
Block(-1,33,3,ICE:0)
Block(-1,33,4,ICE:0)
Block(-1,33,5,ICE:0)
Block(-1,33,6,ICE:0)
Block(-1,33,7,ICE:0)
Block(-1,33,8,ICE:0)
Block(-1,34,0,ICE:0)
Block(-1,34,1,ICE:0)
Block(-1,34,2,ICE:0)
Block(-1,34,3,ICE:0)
Block(-1,34,4,ICE:0)
Block(-1,34,5,ICE:0)
Block(-1,34,6,ICE:0)
Block(-1,34,7,ICE:0)
Block(-1,34,8,ICE:0)
Block(-1,35,0,ICE:0)
Block(-1,35,1,ICE:0)
Block(-1,35,2,ICE:0)
Block(-1,35,3,ICE:0)
Block(-1,35,4,ICE:0)
Block(-1,35,5,ICE:0)
Block(-1,35,6,ICE:0)
Block(-1,35,7,ICE:0)
Block(-1,35,8,ICE:0)
Block(-1,36,-1,ICE:0)
Block(-1,36,0,ICE:0)
Block(-1,36,1,ICE:0)
Block(-1,36,2,ICE:0)
Block(-1,36,3,ICE:0)
Block(-1,36,4,ICE:0)
Block(-1,36,5,ICE:0)
Block(-1,36,6,ICE:0)
Block(-1,36,7,ICE:0)
Block(-1,36,8,PACKED_ICE:0)
Block(-1,37,-2,ICE:0)
Block(-1,37,-1,ICE:0)
Block(-1,37,0,ICE:0)
Block(-1,37,1,ICE:0)
Block(-1,37,2,ICE:0)
Block(-1,37,3,ICE:0)
Block(-1,37,4,ICE:0)
Block(-1,37,5,ICE:0)
Block(-1,37,6,PACKED_ICE:0)
Block(-1,37,7,PACKED_ICE:0)
Block(-1,37,8,PACKED_ICE:0)
Block(-1,38,-2,ICE:0)
Block(-1,38,-1,ICE:0)
Block(-1,38,0,ICE:0)
Block(-1,38,1,ICE:0)
Block(-1,38,2,ICE:0)
Block(-1,38,3,ICE:0)
Block(-1,38,4,ICE:0)
Block(-1,38,5,ICE:0)
Block(-1,38,6,PACKED_ICE:0)
Block(-1,38,7,PACKED_ICE:0)
Block(-1,38,8,PACKED_ICE:0)
Block(-1,39,-3,ICE:0)
Block(-1,39,-2,ICE:0)
Block(-1,39,-1,ICE:0)
Block(-1,39,0,ICE:0)
Block(-1,39,1,ICE:0)
Block(-1,39,2,ICE:0)
Block(-1,39,3,ICE:0)
Block(-1,39,4,ICE:0)
Block(-1,39,5,PACKED_ICE:0)
Block(-1,39,6,PACKED_ICE:0)
Block(-1,39,7,PACKED_ICE:0)
Block(-1,39,8,PACKED_ICE:0)
Block(-1,40,-4,ICE:0)
Block(-1,40,-3,ICE:0)
Block(-1,40,-2,ICE:0)
Block(-1,40,-1,ICE:0)
Block(-1,40,0,ICE:0)
Block(-1,40,1,ICE:0)
Block(-1,40,2,ICE:0)
Block(-1,40,3,ICE:0)
Block(-1,40,4,PACKED_ICE:0)
Block(-1,40,5,PACKED_ICE:0)
Block(-1,40,6,PACKED_ICE:0)
Block(-1,40,7,PACKED_ICE:0)
Block(-1,40,8,PACKED_ICE:0)
Block(-1,41,-4,ICE:0)
Block(-1,41,-3,ICE:0)
Block(-1,41,-2,ICE:0)
Block(-1,41,-1,ICE:0)
Block(-1,41,0,ICE:0)
Block(-1,41,1,ICE:0)
Block(-1,41,2,ICE:0)
Block(-1,41,3,PACKED_ICE:0)
Block(-1,41,4,PACKED_ICE:0)
Block(-1,41,5,PACKED_ICE:0)
Block(-1,41,6,PACKED_ICE:0)
Block(-1,41,7,PACKED_ICE:0)
Block(-1,42,-5,ICE:0)
Block(-1,42,-4,ICE:0)
Block(-1,42,-3,ICE:0)
Block(-1,42,-2,ICE:0)
Block(-1,42,-1,ICE:0)
Block(-1,42,0,ICE:0)
Block(-1,42,1,ICE:0)
Block(-1,42,2,ICE:0)
Block(-1,42,3,PACKED_ICE:0)
Block(-1,42,4,PACKED_ICE:0)
Block(-1,42,5,PACKED_ICE:0)
Block(-1,43,-6,ICE:0)
Block(-1,43,-5,ICE:0)
Block(-1,43,-4,ICE:0)
Block(-1,43,-3,ICE:0)
Block(-1,43,-2,ICE:0)
Block(-1,43,-1,ICE:0)
Block(-1,43,0,ICE:0)
Block(-1,43,1,ICE:0)
Block(-1,43,2,PACKED_ICE:0)
Block(-1,43,3,PACKED_ICE:0)
Block(-1,43,4,PACKED_ICE:0)
Block(-1,44,-6,ICE:0)
Block(-1,44,-5,ICE:0)
Block(-1,44,-4,ICE:0)
Block(-1,44,-3,ICE:0)
Block(-1,44,-2,ICE:0)
Block(-1,44,-1,ICE:0)
Block(-1,44,0,ICE:0)
Block(-1,44,1,PACKED_ICE:0)
Block(-1,44,2,PACKED_ICE:0)
Block(-1,44,3,PACKED_ICE:0)
Block(-1,45,-7,ICE:0)
Block(-1,45,-6,ICE:0)
Block(-1,45,-5,ICE:0)
Block(-1,45,-4,ICE:0)
Block(-1,45,-3,ICE:0)
Block(-1,45,-2,ICE:0)
Block(-1,45,-1,ICE:0)
Block(-1,45,0,PACKED_ICE:0)
Block(-1,45,1,PACKED_ICE:0)
Block(-1,45,2,PACKED_ICE:0)
Block(-1,46,-7,ICE:0)
Block(-1,46,-6,ICE:0)
Block(-1,46,-5,ICE:0)
Block(-1,46,-4,ICE:0)
Block(-1,46,-3,ICE:0)
Block(-1,46,-2,PACKED_ICE:0)
Block(-1,46,-1,PACKED_ICE:0)
Block(-1,46,0,PACKED_ICE:0)
Block(-1,46,1,PACKED_ICE:0)
Block(-1,47,-7,ICE:0)
Block(-1,47,-6,ICE:0)
Block(-1,47,-5,ICE:0)
Block(-1,47,-4,ICE:0)
Block(-1,47,-3,ICE:0)
Block(-1,47,-2,PACKED_ICE:0)
Block(-1,47,-1,PACKED_ICE:0)
Block(-1,47,0,PACKED_ICE:0)
Block(-1,48,-7,ICE:0)
Block(-1,48,-6,ICE:0)
Block(-1,48,-5,ICE:0)
Block(-1,48,-4,ICE:0)
Block(-1,48,-3,ICE:0)
Block(-1,48,-2,PACKED_ICE:0)
Block(-1,48,-1,PACKED_ICE:0)
Block(-1,49,-7,ICE:0)
Block(-1,49,-6,ICE:0)
Block(-1,49,-5,ICE:0)
Block(-1,49,-4,ICE:0)
Block(-1,49,-3,PACKED_ICE:0)
Block(-1,50,-7,ICE:0)
Block(-1,50,-6,ICE:0)
Block(-1,50,-5,ICE:0)
Block(-1,50,-4,PACKED_ICE:0)
Block(-1,51,-7,ICE:0)
Block(-1,51,-6,ICE:0)
Block(-1,51,-5,PACKED_ICE:0)
Block(-1,52,-7,ICE:0)
Block(-1,52,-6,PACKED_ICE:0)
Block(-1,53,-7,ICE:0)
Block(0,23,8,ICE:0)
Block(0,24,7,PACKED_ICE:0)
Block(0,24,8,ICE:0)
Block(0,25,6,PACKED_ICE:0)
Block(0,25,7,ICE:0)
Block(0,25,8,ICE:0)
Block(0,26,6,ICE:0)
Block(0,26,7,ICE:0)
Block(0,26,8,ICE:0)
Block(0,27,5,PACKED_ICE:0)
Block(0,27,6,ICE:0)
Block(0,27,7,ICE:0)
Block(0,27,8,ICE:0)
Block(0,28,4,ICE:0)
Block(0,28,5,ICE:0)
Block(0,28,6,ICE:0)
Block(0,28,7,ICE:0)
Block(0,28,8,ICE:0)
Block(0,29,4,ICE:0)
Block(0,29,5,ICE:0)
Block(0,29,6,ICE:0)
Block(0,29,7,ICE:0)
Block(0,29,8,ICE:0)
Block(0,30,3,ICE:0)
Block(0,30,4,ICE:0)
Block(0,30,5,ICE:0)
Block(0,30,6,ICE:0)
Block(0,30,7,ICE:0)
Block(0,30,8,ICE:0)
Block(0,31,2,ICE:0)
Block(0,31,3,ICE:0)
Block(0,31,4,ICE:0)
Block(0,31,5,ICE:0)
Block(0,31,6,ICE:0)
Block(0,31,7,ICE:0)
Block(0,31,8,ICE:0)
Block(0,32,2,ICE:0)
Block(0,32,3,ICE:0)
Block(0,32,4,ICE:0)
Block(0,32,5,ICE:0)
Block(0,32,6,ICE:0)
Block(0,32,7,ICE:0)
Block(0,32,8,ICE:0)
Block(0,33,1,ICE:0)
Block(0,33,2,ICE:0)
Block(0,33,3,ICE:0)
Block(0,33,4,ICE:0)
Block(0,33,5,ICE:0)
Block(0,33,6,ICE:0)
Block(0,33,7,ICE:0)
Block(0,33,8,ICE:0)
Block(0,34,0,ICE:0)
Block(0,34,1,ICE:0)
Block(0,34,2,ICE:0)
Block(0,34,3,ICE:0)
Block(0,34,4,ICE:0)
Block(0,34,5,ICE:0)
Block(0,34,6,ICE:0)
Block(0,34,7,ICE:0)
Block(0,34,8,ICE:0)
Block(0,35,0,ICE:0)
Block(0,35,1,ICE:0)
Block(0,35,2,ICE:0)
Block(0,35,3,ICE:0)
Block(0,35,4,ICE:0)
Block(0,35,5,ICE:0)
Block(0,35,6,ICE:0)
Block(0,35,7,ICE:0)
Block(0,35,8,PACKED_ICE:0)
Block(0,36,-1,ICE:0)
Block(0,36,0,ICE:0)
Block(0,36,1,ICE:0)
Block(0,36,2,ICE:0)
Block(0,36,3,ICE:0)
Block(0,36,4,ICE:0)
Block(0,36,5,ICE:0)
Block(0,36,6,ICE:0)
Block(0,36,7,PACKED_ICE:0)
Block(0,36,8,PACKED_ICE:0)
Block(0,37,-2,ICE:0)
Block(0,37,-1,ICE:0)
Block(0,37,0,ICE:0)
Block(0,37,1,ICE:0)
Block(0,37,2,ICE:0)
Block(0,37,3,ICE:0)
Block(0,37,4,ICE:0)
Block(0,37,5,ICE:0)
Block(0,37,6,PACKED_ICE:0)
Block(0,37,7,PACKED_ICE:0)
Block(0,37,8,PACKED_ICE:0)
Block(0,38,-2,ICE:0)
Block(0,38,-1,ICE:0)
Block(0,38,0,ICE:0)
Block(0,38,1,ICE:0)
Block(0,38,2,ICE:0)
Block(0,38,3,ICE:0)
Block(0,38,4,ICE:0)
Block(0,38,5,PACKED_ICE:0)
Block(0,38,6,PACKED_ICE:0)
Block(0,38,7,PACKED_ICE:0)
Block(0,38,8,PACKED_ICE:0)
Block(0,39,-3,ICE:0)
Block(0,39,-2,ICE:0)
Block(0,39,-1,ICE:0)
Block(0,39,0,ICE:0)
Block(0,39,1,ICE:0)
Block(0,39,2,ICE:0)
Block(0,39,3,ICE:0)
Block(0,39,4,ICE:0)
Block(0,39,5,PACKED_ICE:0)
Block(0,39,6,PACKED_ICE:0)
Block(0,39,7,PACKED_ICE:0)
Block(0,39,8,PACKED_ICE:0)
Block(0,40,-4,ICE:0)
Block(0,40,-3,ICE:0)
Block(0,40,-2,ICE:0)
Block(0,40,-1,ICE:0)
Block(0,40,0,ICE:0)
Block(0,40,1,ICE:0)
Block(0,40,2,ICE:0)
Block(0,40,3,ICE:0)
Block(0,40,4,PACKED_ICE:0)
Block(0,40,5,PACKED_ICE:0)
Block(0,40,6,PACKED_ICE:0)
Block(0,40,7,PACKED_ICE:0)
Block(0,40,8,PACKED_ICE:0)
Block(0,41,-4,ICE:0)
Block(0,41,-3,ICE:0)
Block(0,41,-2,ICE:0)
Block(0,41,-1,ICE:0)
Block(0,41,0,ICE:0)
Block(0,41,1,ICE:0)
Block(0,41,2,ICE:0)
Block(0,41,3,PACKED_ICE:0)
Block(0,41,4,PACKED_ICE:0)
Block(0,41,5,PACKED_ICE:0)
Block(0,41,6,PACKED_ICE:0)
Block(0,41,7,PACKED_ICE:0)
Block(0,41,8,PACKED_ICE:0)
Block(0,42,-5,ICE:0)
Block(0,42,-4,ICE:0)
Block(0,42,-3,ICE:0)
Block(0,42,-2,ICE:0)
Block(0,42,-1,ICE:0)
Block(0,42,0,ICE:0)
Block(0,42,1,ICE:0)
Block(0,42,2,PACKED_ICE:0)
Block(0,42,3,PACKED_ICE:0)
Block(0,42,4,PACKED_ICE:0)
Block(0,42,5,PACKED_ICE:0)
Block(0,42,6,PACKED_ICE:0)
Block(0,42,7,PACKED_ICE:0)
Block(0,42,8,PACKED_ICE:0)
Block(0,43,-6,ICE:0)
Block(0,43,-5,ICE:0)
Block(0,43,-4,ICE:0)
Block(0,43,-3,ICE:0)
Block(0,43,-2,ICE:0)
Block(0,43,-1,ICE:0)
Block(0,43,0,ICE:0)
Block(0,43,1,ICE:0)
Block(0,43,2,PACKED_ICE:0)
Block(0,43,3,PACKED_ICE:0)
Block(0,43,4,PACKED_ICE:0)
Block(0,43,5,PACKED_ICE:0)
Block(0,43,6,PACKED_ICE:0)
Block(0,43,7,PACKED_ICE:0)
Block(0,44,-6,ICE:0)
Block(0,44,-5,ICE:0)
Block(0,44,-4,ICE:0)
Block(0,44,-3,ICE:0)
Block(0,44,-2,ICE:0)
Block(0,44,-1,ICE:0)
Block(0,44,0,ICE:0)
Block(0,44,1,PACKED_ICE:0)
Block(0,44,2,PACKED_ICE:0)
Block(0,44,3,PACKED_ICE:0)
Block(0,44,4,PACKED_ICE:0)
Block(0,44,5,PACKED_ICE:0)
Block(0,44,6,PACKED_ICE:0)
Block(0,45,-7,ICE:0)
Block(0,45,-6,ICE:0)
Block(0,45,-5,ICE:0)
Block(0,45,-4,ICE:0)
Block(0,45,-3,ICE:0)
Block(0,45,-2,ICE:0)
Block(0,45,-1,PACKED_ICE:0)
Block(0,45,0,PACKED_ICE:0)
Block(0,45,1,PACKED_ICE:0)
Block(0,45,2,PACKED_ICE:0)
Block(0,45,3,PACKED_ICE:0)
Block(0,45,4,PACKED_ICE:0)
Block(0,45,5,PACKED_ICE:0)
Block(0,46,-7,ICE:0)
Block(0,46,-6,ICE:0)
Block(0,46,-5,ICE:0)
Block(0,46,-4,ICE:0)
Block(0,46,-3,ICE:0)
Block(0,46,-2,PACKED_ICE:0)
Block(0,46,-1,PACKED_ICE:0)
Block(0,46,0,PACKED_ICE:0)
Block(0,46,1,PACKED_ICE:0)
Block(0,46,2,PACKED_ICE:0)
Block(0,46,3,PACKED_ICE:0)
Block(0,46,4,PACKED_ICE:0)
Block(0,47,-7,ICE:0)
Block(0,47,-6,ICE:0)
Block(0,47,-5,ICE:0)
Block(0,47,-4,ICE:0)
Block(0,47,-3,ICE:0)
Block(0,47,-2,PACKED_ICE:0)
Block(0,47,-1,PACKED_ICE:0)
Block(0,47,0,PACKED_ICE:0)
Block(0,47,1,PACKED_ICE:0)
Block(0,47,2,PACKED_ICE:0)
Block(0,47,3,PACKED_ICE:0)
Block(0,48,-7,ICE:0)
Block(0,48,-6,ICE:0)
Block(0,48,-5,ICE:0)
Block(0,48,-4,ICE:0)
Block(0,48,-3,ICE:0)
Block(0,48,-2,PACKED_ICE:0)
Block(0,48,-1,PACKED_ICE:0)
Block(0,48,0,PACKED_ICE:0)
Block(0,48,1,PACKED_ICE:0)
Block(0,48,2,PACKED_ICE:0)
Block(0,49,-7,ICE:0)
Block(0,49,-6,ICE:0)
Block(0,49,-5,ICE:0)
Block(0,49,-4,ICE:0)
Block(0,49,-3,PACKED_ICE:0)
Block(0,49,-2,PACKED_ICE:0)
Block(0,49,-1,PACKED_ICE:0)
Block(0,49,0,PACKED_ICE:0)
Block(0,50,-7,ICE:0)
Block(0,50,-6,ICE:0)
Block(0,50,-5,ICE:0)
Block(0,50,-4,PACKED_ICE:0)
Block(0,50,-3,PACKED_ICE:0)
Block(0,50,-2,PACKED_ICE:0)
Block(0,50,-1,PACKED_ICE:0)
Block(0,51,-7,ICE:0)
Block(0,51,-6,ICE:0)
Block(0,51,-5,PACKED_ICE:0)
Block(0,51,-4,PACKED_ICE:0)
Block(0,51,-3,PACKED_ICE:0)
Block(0,51,-2,PACKED_ICE:0)
Block(0,52,-7,ICE:0)
Block(0,52,-6,PACKED_ICE:0)
Block(0,52,-5,PACKED_ICE:0)
Block(0,52,-4,PACKED_ICE:0)
Block(0,52,-3,PACKED_ICE:0)
Block(0,53,-7,ICE:0)
Block(0,53,-6,PACKED_ICE:0)
Block(0,53,-5,PACKED_ICE:0)
Block(0,53,-4,PACKED_ICE:0)
Block(0,54,-7,ICE:0)
Block(0,54,-6,PACKED_ICE:0)
Block(0,54,-5,PACKED_ICE:0)
Block(0,55,-7,PACKED_ICE:0)
Block(0,55,-6,PACKED_ICE:0)
Block(1,23,8,PACKED_ICE:0)
Block(1,24,7,PACKED_ICE:0)
Block(1,24,8,PACKED_ICE:0)
Block(1,25,7,PACKED_ICE:0)
Block(1,25,8,PACKED_ICE:0)
Block(1,26,6,PACKED_ICE:0)
Block(1,26,7,PACKED_ICE:0)
Block(1,26,8,ICE:0)
Block(1,27,5,PACKED_ICE:0)
Block(1,27,6,PACKED_ICE:0)
Block(1,27,7,ICE:0)
Block(1,27,8,ICE:0)
Block(1,28,5,PACKED_ICE:0)
Block(1,28,6,PACKED_ICE:0)
Block(1,28,7,ICE:0)
Block(1,28,8,ICE:0)
Block(1,29,4,ICE:0)
Block(1,29,5,ICE:0)
Block(1,29,6,ICE:0)
Block(1,29,7,ICE:0)
Block(1,29,8,ICE:0)
Block(1,30,3,ICE:0)
Block(1,30,4,ICE:0)
Block(1,30,5,ICE:0)
Block(1,30,6,ICE:0)
Block(1,30,7,ICE:0)
Block(1,30,8,ICE:0)
Block(1,31,3,ICE:0)
Block(1,31,4,ICE:0)
Block(1,31,5,ICE:0)
Block(1,31,6,ICE:0)
Block(1,31,7,ICE:0)
Block(1,31,8,PACKED_ICE:0)
Block(1,32,2,ICE:0)
Block(1,32,3,ICE:0)
Block(1,32,4,ICE:0)
Block(1,32,5,ICE:0)
Block(1,32,6,ICE:0)
Block(1,32,7,ICE:0)
Block(1,32,8,PACKED_ICE:0)
Block(1,33,1,ICE:0)
Block(1,33,2,ICE:0)
Block(1,33,3,ICE:0)
Block(1,33,4,ICE:0)
Block(1,33,5,ICE:0)
Block(1,33,6,ICE:0)
Block(1,33,7,ICE:0)
Block(1,33,8,PACKED_ICE:0)
Block(1,34,1,ICE:0)
Block(1,34,2,ICE:0)
Block(1,34,3,ICE:0)
Block(1,34,4,ICE:0)
Block(1,34,5,ICE:0)
Block(1,34,6,ICE:0)
Block(1,34,7,ICE:0)
Block(1,34,8,PACKED_ICE:0)
Block(1,35,0,ICE:0)
Block(1,35,1,ICE:0)
Block(1,35,2,ICE:0)
Block(1,35,3,ICE:0)
Block(1,35,4,ICE:0)
Block(1,35,5,ICE:0)
Block(1,35,6,ICE:0)
Block(1,35,7,PACKED_ICE:0)
Block(1,35,8,PACKED_ICE:0)
Block(1,36,-1,ICE:0)
Block(1,36,0,ICE:0)
Block(1,36,1,ICE:0)
Block(1,36,2,ICE:0)
Block(1,36,3,ICE:0)
Block(1,36,4,ICE:0)
Block(1,36,5,PACKED_ICE:0)
Block(1,36,6,PACKED_ICE:0)
Block(1,36,7,PACKED_ICE:0)
Block(1,36,8,PACKED_ICE:0)
Block(1,37,-1,ICE:0)
Block(1,37,0,ICE:0)
Block(1,37,1,ICE:0)
Block(1,37,2,ICE:0)
Block(1,37,3,ICE:0)
Block(1,37,4,ICE:0)
Block(1,37,5,PACKED_ICE:0)
Block(1,37,6,PACKED_ICE:0)
Block(1,37,7,PACKED_ICE:0)
Block(1,37,8,PACKED_ICE:0)
Block(1,38,-2,ICE:0)
Block(1,38,-1,ICE:0)
Block(1,38,0,ICE:0)
Block(1,38,1,ICE:0)
Block(1,38,2,ICE:0)
Block(1,38,3,ICE:0)
Block(1,38,4,ICE:0)
Block(1,38,5,PACKED_ICE:0)
Block(1,38,6,PACKED_ICE:0)
Block(1,38,7,PACKED_ICE:0)
Block(1,38,8,PACKED_ICE:0)
Block(1,39,-3,ICE:0)
Block(1,39,-2,ICE:0)
Block(1,39,-1,ICE:0)
Block(1,39,0,ICE:0)
Block(1,39,1,ICE:0)
Block(1,39,2,ICE:0)
Block(1,39,3,ICE:0)
Block(1,39,4,PACKED_ICE:0)
Block(1,39,5,PACKED_ICE:0)
Block(1,39,6,PACKED_ICE:0)
Block(1,39,7,PACKED_ICE:0)
Block(1,39,8,PACKED_ICE:0)
Block(1,40,-3,ICE:0)
Block(1,40,-2,ICE:0)
Block(1,40,-1,ICE:0)
Block(1,40,0,ICE:0)
Block(1,40,1,ICE:0)
Block(1,40,2,ICE:0)
Block(1,40,3,PACKED_ICE:0)
Block(1,40,4,PACKED_ICE:0)
Block(1,40,5,PACKED_ICE:0)
Block(1,40,6,PACKED_ICE:0)
Block(1,40,7,PACKED_ICE:0)
Block(1,40,8,PACKED_ICE:0)
Block(1,41,-4,ICE:0)
Block(1,41,-3,ICE:0)
Block(1,41,-2,ICE:0)
Block(1,41,-1,ICE:0)
Block(1,41,0,ICE:0)
Block(1,41,1,ICE:0)
Block(1,41,2,PACKED_ICE:0)
Block(1,41,3,PACKED_ICE:0)
Block(1,41,4,PACKED_ICE:0)
Block(1,41,5,ICE:0)
Block(1,41,6,ICE:0)
Block(1,41,7,ICE:0)
Block(1,41,8,PACKED_ICE:0)
Block(1,42,-5,ICE:0)
Block(1,42,-4,ICE:0)
Block(1,42,-3,ICE:0)
Block(1,42,-2,ICE:0)
Block(1,42,-1,ICE:0)
Block(1,42,0,ICE:0)
Block(1,42,1,ICE:0)
Block(1,42,2,PACKED_ICE:0)
Block(1,42,3,PACKED_ICE:0)
Block(1,42,4,ICE:0)
Block(1,42,5,ICE:0)
Block(1,42,6,ICE:0)
Block(1,42,7,ICE:0)
Block(1,42,8,ICE:0)
Block(1,43,-6,ICE:0)
Block(1,43,-5,ICE:0)
Block(1,43,-4,ICE:0)
Block(1,43,-3,ICE:0)
Block(1,43,-2,ICE:0)
Block(1,43,-1,ICE:0)
Block(1,43,0,ICE:0)
Block(1,43,1,PACKED_ICE:0)
Block(1,43,2,PACKED_ICE:0)
Block(1,43,3,PACKED_ICE:0)
Block(1,43,4,ICE:0)
Block(1,43,5,ICE:0)
Block(1,43,6,ICE:0)
Block(1,43,7,ICE:0)
Block(1,44,-6,ICE:0)
Block(1,44,-5,ICE:0)
Block(1,44,-4,ICE:0)
Block(1,44,-3,ICE:0)
Block(1,44,-2,ICE:0)
Block(1,44,-1,ICE:0)
Block(1,44,0,PACKED_ICE:0)
Block(1,44,1,PACKED_ICE:0)
Block(1,44,2,PACKED_ICE:0)
Block(1,44,3,PACKED_ICE:0)
Block(1,44,4,ICE:0)
Block(1,44,5,ICE:0)
Block(1,44,6,ICE:0)
Block(1,44,7,ICE:0)
Block(1,45,-7,ICE:0)
Block(1,45,-6,ICE:0)
Block(1,45,-5,ICE:0)
Block(1,45,-4,ICE:0)
Block(1,45,-3,ICE:0)
Block(1,45,-2,PACKED_ICE:0)
Block(1,45,-1,PACKED_ICE:0)
Block(1,45,0,PACKED_ICE:0)
Block(1,45,1,PACKED_ICE:0)
Block(1,45,2,PACKED_ICE:0)
Block(1,45,3,PACKED_ICE:0)
Block(1,45,4,PACKED_ICE:0)
Block(1,45,5,ICE:0)
Block(1,45,6,ICE:0)
Block(1,46,-7,ICE:0)
Block(1,46,-6,ICE:0)
Block(1,46,-5,ICE:0)
Block(1,46,-4,ICE:0)
Block(1,46,-3,ICE:0)
Block(1,46,-2,PACKED_ICE:0)
Block(1,46,-1,PACKED_ICE:0)
Block(1,46,0,PACKED_ICE:0)
Block(1,46,1,PACKED_ICE:0)
Block(1,46,2,PACKED_ICE:0)
Block(1,46,3,PACKED_ICE:0)
Block(1,46,4,PACKED_ICE:0)
Block(1,46,5,PACKED_ICE:0)
Block(1,47,-7,ICE:0)
Block(1,47,-6,ICE:0)
Block(1,47,-5,ICE:0)
Block(1,47,-4,ICE:0)
Block(1,47,-3,ICE:0)
Block(1,47,-2,PACKED_ICE:0)
Block(1,47,-1,PACKED_ICE:0)
Block(1,47,0,PACKED_ICE:0)
Block(1,47,1,PACKED_ICE:0)
Block(1,47,2,PACKED_ICE:0)
Block(1,47,3,PACKED_ICE:0)
Block(1,47,4,PACKED_ICE:0)
Block(1,48,-7,ICE:0)
Block(1,48,-6,ICE:0)
Block(1,48,-5,ICE:0)
Block(1,48,-4,ICE:0)
Block(1,48,-3,PACKED_ICE:0)
Block(1,48,-2,PACKED_ICE:0)
Block(1,48,-1,PACKED_ICE:0)
Block(1,48,0,PACKED_ICE:0)
Block(1,48,1,PACKED_ICE:0)
Block(1,48,2,PACKED_ICE:0)
Block(1,48,3,PACKED_ICE:0)
Block(1,49,-7,ICE:0)
Block(1,49,-6,ICE:0)
Block(1,49,-5,ICE:0)
Block(1,49,-4,ICE:0)
Block(1,49,-3,PACKED_ICE:0)
Block(1,49,-2,PACKED_ICE:0)
Block(1,49,-1,PACKED_ICE:0)
Block(1,49,0,PACKED_ICE:0)
Block(1,49,1,PACKED_ICE:0)
Block(1,49,2,PACKED_ICE:0)
Block(1,50,-7,ICE:0)
Block(1,50,-6,ICE:0)
Block(1,50,-5,ICE:0)
Block(1,50,-4,PACKED_ICE:0)
Block(1,50,-3,PACKED_ICE:0)
Block(1,50,-2,PACKED_ICE:0)
Block(1,50,-1,PACKED_ICE:0)
Block(1,50,0,PACKED_ICE:0)
Block(1,50,1,PACKED_ICE:0)
Block(1,51,-7,ICE:0)
Block(1,51,-6,PACKED_ICE:0)
Block(1,51,-5,PACKED_ICE:0)
Block(1,51,-4,PACKED_ICE:0)
Block(1,51,-3,PACKED_ICE:0)
Block(1,51,-2,PACKED_ICE:0)
Block(1,51,-1,PACKED_ICE:0)
Block(1,51,0,PACKED_ICE:0)
Block(1,52,-7,ICE:0)
Block(1,52,-6,PACKED_ICE:0)
Block(1,52,-5,PACKED_ICE:0)
Block(1,52,-4,PACKED_ICE:0)
Block(1,52,-3,PACKED_ICE:0)
Block(1,52,-2,PACKED_ICE:0)
Block(1,52,-1,PACKED_ICE:0)
Block(1,53,-7,ICE:0)
Block(1,53,-6,PACKED_ICE:0)
Block(1,53,-5,PACKED_ICE:0)
Block(1,53,-4,PACKED_ICE:0)
Block(1,53,-3,PACKED_ICE:0)
Block(1,53,-2,PACKED_ICE:0)
Block(1,54,-7,ICE:0)
Block(1,54,-6,PACKED_ICE:0)
Block(1,54,-5,PACKED_ICE:0)
Block(1,54,-4,PACKED_ICE:0)
Block(1,54,-3,PACKED_ICE:0)
Block(1,55,-7,PACKED_ICE:0)
Block(1,55,-6,PACKED_ICE:0)
Block(1,55,-5,PACKED_ICE:0)
Block(1,55,-4,PACKED_ICE:0)
Block(1,56,-7,PACKED_ICE:0)
Block(1,56,-6,PACKED_ICE:0)
Block(1,56,-5,PACKED_ICE:0)
Block(1,57,-7,PACKED_ICE:0)
Block(1,57,-6,PACKED_ICE:0)
Block(1,58,-7,PACKED_ICE:0)
Block(2,23,8,PACKED_ICE:0)
Block(2,24,7,PACKED_ICE:0)
Block(2,24,8,PACKED_ICE:0)
Block(2,25,7,PACKED_ICE:0)
Block(2,25,8,PACKED_ICE:0)
Block(2,26,6,PACKED_ICE:0)
Block(2,26,7,PACKED_ICE:0)
Block(2,26,8,PACKED_ICE:0)
Block(2,27,5,PACKED_ICE:0)
Block(2,27,6,PACKED_ICE:0)
Block(2,27,7,PACKED_ICE:0)
Block(2,27,8,PACKED_ICE:0)
Block(2,28,5,PACKED_ICE:0)
Block(2,28,6,PACKED_ICE:0)
Block(2,28,7,PACKED_ICE:0)
Block(2,28,8,PACKED_ICE:0)
Block(2,29,4,PACKED_ICE:0)
Block(2,29,5,PACKED_ICE:0)
Block(2,29,6,PACKED_ICE:0)
Block(2,29,7,PACKED_ICE:0)
Block(2,29,8,PACKED_ICE:0)
Block(2,30,3,ICE:0)
Block(2,30,4,ICE:0)
Block(2,30,5,ICE:0)
Block(2,30,6,PACKED_ICE:0)
Block(2,30,7,PACKED_ICE:0)
Block(2,30,8,PACKED_ICE:0)
Block(2,31,3,ICE:0)
Block(2,31,4,ICE:0)
Block(2,31,5,ICE:0)
Block(2,31,6,ICE:0)
Block(2,31,7,PACKED_ICE:0)
Block(2,31,8,PACKED_ICE:0)
Block(2,32,2,ICE:0)
Block(2,32,3,ICE:0)
Block(2,32,4,ICE:0)
Block(2,32,5,ICE:0)
Block(2,32,6,ICE:0)
Block(2,32,7,PACKED_ICE:0)
Block(2,32,8,PACKED_ICE:0)
Block(2,33,1,ICE:0)
Block(2,33,2,ICE:0)
Block(2,33,3,ICE:0)
Block(2,33,4,ICE:0)
Block(2,33,5,ICE:0)
Block(2,33,6,ICE:0)
Block(2,33,7,PACKED_ICE:0)
Block(2,33,8,PACKED_ICE:0)
Block(2,34,1,ICE:0)
Block(2,34,2,ICE:0)
Block(2,34,3,ICE:0)
Block(2,34,4,ICE:0)
Block(2,34,5,ICE:0)
Block(2,34,6,PACKED_ICE:0)
Block(2,34,7,PACKED_ICE:0)
Block(2,34,8,PACKED_ICE:0)
Block(2,35,0,ICE:0)
Block(2,35,1,ICE:0)
Block(2,35,2,ICE:0)
Block(2,35,3,ICE:0)
Block(2,35,4,PACKED_ICE:0)
Block(2,35,5,PACKED_ICE:0)
Block(2,35,6,PACKED_ICE:0)
Block(2,35,7,PACKED_ICE:0)
Block(2,35,8,ICE:0)
Block(2,36,-1,ICE:0)
Block(2,36,0,ICE:0)
Block(2,36,1,ICE:0)
Block(2,36,2,ICE:0)
Block(2,36,3,ICE:0)
Block(2,36,4,PACKED_ICE:0)
Block(2,36,5,PACKED_ICE:0)
Block(2,36,6,PACKED_ICE:0)
Block(2,36,7,PACKED_ICE:0)
Block(2,36,8,ICE:0)
Block(2,37,-1,ICE:0)
Block(2,37,0,ICE:0)
Block(2,37,1,ICE:0)
Block(2,37,2,ICE:0)
Block(2,37,3,ICE:0)
Block(2,37,4,PACKED_ICE:0)
Block(2,37,5,PACKED_ICE:0)
Block(2,37,6,PACKED_ICE:0)
Block(2,37,7,PACKED_ICE:0)
Block(2,37,8,ICE:0)
Block(2,38,-2,ICE:0)
Block(2,38,-1,ICE:0)
Block(2,38,0,ICE:0)
Block(2,38,1,ICE:0)
Block(2,38,2,ICE:0)
Block(2,38,3,ICE:0)
Block(2,38,4,PACKED_ICE:0)
Block(2,38,5,PACKED_ICE:0)
Block(2,38,6,PACKED_ICE:0)
Block(2,38,7,PACKED_ICE:0)
Block(2,38,8,ICE:0)
Block(2,39,-3,ICE:0)
Block(2,39,-2,ICE:0)
Block(2,39,-1,ICE:0)
Block(2,39,0,ICE:0)
Block(2,39,1,ICE:0)
Block(2,39,2,ICE:0)
Block(2,39,3,PACKED_ICE:0)
Block(2,39,4,PACKED_ICE:0)
Block(2,39,5,PACKED_ICE:0)
Block(2,39,6,PACKED_ICE:0)
Block(2,39,7,PACKED_ICE:0)
Block(2,39,8,ICE:0)
Block(2,40,-3,ICE:0)
Block(2,40,-2,ICE:0)
Block(2,40,-1,ICE:0)
Block(2,40,0,ICE:0)
Block(2,40,1,PACKED_ICE:0)
Block(2,40,2,PACKED_ICE:0)
Block(2,40,3,PACKED_ICE:0)
Block(2,40,4,ICE:0)
Block(2,40,5,ICE:0)
Block(2,40,6,ICE:0)
Block(2,40,7,ICE:0)
Block(2,40,8,ICE:0)
Block(2,41,-4,ICE:0)
Block(2,41,-3,ICE:0)
Block(2,41,-2,ICE:0)
Block(2,41,-1,ICE:0)
Block(2,41,0,ICE:0)
Block(2,41,1,PACKED_ICE:0)
Block(2,41,2,PACKED_ICE:0)
Block(2,41,3,ICE:0)
Block(2,41,4,ICE:0)
Block(2,41,5,ICE:0)
Block(2,41,6,ICE:0)
Block(2,41,7,ICE:0)
Block(2,41,8,ICE:0)
Block(2,42,-5,ICE:0)
Block(2,42,-4,ICE:0)
Block(2,42,-3,ICE:0)
Block(2,42,-2,ICE:0)
Block(2,42,-1,ICE:0)
Block(2,42,0,ICE:0)
Block(2,42,1,PACKED_ICE:0)
Block(2,42,2,PACKED_ICE:0)
Block(2,42,3,ICE:0)
Block(2,42,4,ICE:0)
Block(2,42,5,ICE:0)
Block(2,42,6,ICE:0)
Block(2,42,7,ICE:0)
Block(2,42,8,ICE:0)
Block(2,43,-5,ICE:0)
Block(2,43,-4,ICE:0)
Block(2,43,-3,ICE:0)
Block(2,43,-2,ICE:0)
Block(2,43,-1,ICE:0)
Block(2,43,0,PACKED_ICE:0)
Block(2,43,1,PACKED_ICE:0)
Block(2,43,2,PACKED_ICE:0)
Block(2,43,3,ICE:0)
Block(2,43,4,ICE:0)
Block(2,43,5,ICE:0)
Block(2,43,6,ICE:0)
Block(2,43,7,ICE:0)
Block(2,44,-6,ICE:0)
Block(2,44,-5,ICE:0)
Block(2,44,-4,ICE:0)
Block(2,44,-3,PACKED_ICE:0)
Block(2,44,-2,PACKED_ICE:0)
Block(2,44,-1,PACKED_ICE:0)
Block(2,44,0,PACKED_ICE:0)
Block(2,44,1,PACKED_ICE:0)
Block(2,44,2,PACKED_ICE:0)
Block(2,44,3,ICE:0)
Block(2,44,4,ICE:0)
Block(2,44,5,ICE:0)
Block(2,44,6,ICE:0)
Block(2,45,-7,ICE:0)
Block(2,45,-6,ICE:0)
Block(2,45,-5,ICE:0)
Block(2,45,-4,ICE:0)
Block(2,45,-3,PACKED_ICE:0)
Block(2,45,-2,PACKED_ICE:0)
Block(2,45,-1,PACKED_ICE:0)
Block(2,45,0,PACKED_ICE:0)
Block(2,45,1,PACKED_ICE:0)
Block(2,45,2,ICE:0)
Block(2,45,3,ICE:0)
Block(2,45,4,ICE:0)
Block(2,45,5,ICE:0)
Block(2,46,-7,ICE:0)
Block(2,46,-6,ICE:0)
Block(2,46,-5,ICE:0)
Block(2,46,-4,ICE:0)
Block(2,46,-3,PACKED_ICE:0)
Block(2,46,-2,PACKED_ICE:0)
Block(2,46,-1,PACKED_ICE:0)
Block(2,46,0,PACKED_ICE:0)
Block(2,46,1,ICE:0)
Block(2,46,2,ICE:0)
Block(2,46,3,ICE:0)
Block(2,46,4,ICE:0)
Block(2,46,5,ICE:0)
Block(2,47,-7,ICE:0)
Block(2,47,-6,ICE:0)
Block(2,47,-5,ICE:0)
Block(2,47,-4,ICE:0)
Block(2,47,-3,PACKED_ICE:0)
Block(2,47,-2,PACKED_ICE:0)
Block(2,47,-1,PACKED_ICE:0)
Block(2,47,0,PACKED_ICE:0)
Block(2,47,1,ICE:0)
Block(2,47,2,ICE:0)
Block(2,47,3,ICE:0)
Block(2,47,4,ICE:0)
Block(2,48,-7,ICE:0)
Block(2,48,-6,ICE:0)
Block(2,48,-5,ICE:0)
Block(2,48,-4,ICE:0)
Block(2,48,-3,PACKED_ICE:0)
Block(2,48,-2,PACKED_ICE:0)
Block(2,48,-1,PACKED_ICE:0)
Block(2,48,0,PACKED_ICE:0)
Block(2,48,1,ICE:0)
Block(2,48,2,ICE:0)
Block(2,48,3,ICE:0)
Block(2,49,-7,ICE:0)
Block(2,49,-6,ICE:0)
Block(2,49,-5,ICE:0)
Block(2,49,-4,PACKED_ICE:0)
Block(2,49,-3,PACKED_ICE:0)
Block(2,49,-2,PACKED_ICE:0)
Block(2,49,-1,PACKED_ICE:0)
Block(2,49,0,PACKED_ICE:0)
Block(2,49,1,PACKED_ICE:0)
Block(2,49,2,ICE:0)
Block(2,50,-7,ICE:0)
Block(2,50,-6,ICE:0)
Block(2,50,-5,PACKED_ICE:0)
Block(2,50,-4,PACKED_ICE:0)
Block(2,50,-3,PACKED_ICE:0)
Block(2,50,-2,PACKED_ICE:0)
Block(2,50,-1,PACKED_ICE:0)
Block(2,50,0,PACKED_ICE:0)
Block(2,50,1,PACKED_ICE:0)
Block(2,51,-7,ICE:0)
Block(2,51,-6,PACKED_ICE:0)
Block(2,51,-5,PACKED_ICE:0)
Block(2,51,-4,PACKED_ICE:0)
Block(2,51,-3,PACKED_ICE:0)
Block(2,51,-2,PACKED_ICE:0)
Block(2,51,-1,PACKED_ICE:0)
Block(2,51,0,PACKED_ICE:0)
Block(2,52,-7,ICE:0)
Block(2,52,-6,PACKED_ICE:0)
Block(2,52,-5,PACKED_ICE:0)
Block(2,52,-4,PACKED_ICE:0)
Block(2,52,-3,PACKED_ICE:0)
Block(2,52,-2,PACKED_ICE:0)
Block(2,52,-1,PACKED_ICE:0)
Block(2,53,-7,ICE:0)
Block(2,53,-6,PACKED_ICE:0)
Block(2,53,-5,PACKED_ICE:0)
Block(2,53,-4,PACKED_ICE:0)
Block(2,53,-3,PACKED_ICE:0)
Block(2,53,-2,PACKED_ICE:0)
Block(2,54,-7,PACKED_ICE:0)
Block(2,54,-6,PACKED_ICE:0)
Block(2,54,-5,PACKED_ICE:0)
Block(2,54,-4,PACKED_ICE:0)
Block(2,54,-3,PACKED_ICE:0)
Block(2,55,-7,PACKED_ICE:0)
Block(2,55,-6,PACKED_ICE:0)
Block(2,55,-5,PACKED_ICE:0)
Block(2,55,-4,PACKED_ICE:0)
Block(2,56,-7,PACKED_ICE:0)
Block(2,56,-6,PACKED_ICE:0)
Block(2,56,-5,PACKED_ICE:0)
Block(2,57,-7,PACKED_ICE:0)
Block(2,57,-6,PACKED_ICE:0)
Block(2,58,-7,PACKED_ICE:0)
Block(2,58,-6,PACKED_ICE:0)
Block(2,59,-7,PACKED_ICE:0)
Block(3,23,8,PACKED_ICE:0)
Block(3,24,8,PACKED_ICE:0)
Block(3,25,7,PACKED_ICE:0)
Block(3,25,8,PACKED_ICE:0)
Block(3,26,6,PACKED_ICE:0)
Block(3,26,7,PACKED_ICE:0)
Block(3,26,8,PACKED_ICE:0)
Block(3,27,6,PACKED_ICE:0)
Block(3,27,7,PACKED_ICE:0)
Block(3,27,8,PACKED_ICE:0)
Block(3,28,5,PACKED_ICE:0)
Block(3,28,6,PACKED_ICE:0)
Block(3,28,7,PACKED_ICE:0)
Block(3,28,8,PACKED_ICE:0)
Block(3,29,4,PACKED_ICE:0)
Block(3,29,5,PACKED_ICE:0)
Block(3,29,6,PACKED_ICE:0)
Block(3,29,7,PACKED_ICE:0)
Block(3,29,8,PACKED_ICE:0)
Block(3,30,4,PACKED_ICE:0)
Block(3,30,5,PACKED_ICE:0)
Block(3,30,6,PACKED_ICE:0)
Block(3,30,7,PACKED_ICE:0)
Block(3,30,8,PACKED_ICE:0)
Block(3,31,3,PACKED_ICE:0)
Block(3,31,4,PACKED_ICE:0)
Block(3,31,5,PACKED_ICE:0)
Block(3,31,6,PACKED_ICE:0)
Block(3,31,7,PACKED_ICE:0)
Block(3,31,8,PACKED_ICE:0)
Block(3,32,2,PACKED_ICE:0)
Block(3,32,3,PACKED_ICE:0)
Block(3,32,4,PACKED_ICE:0)
Block(3,32,5,PACKED_ICE:0)
Block(3,32,6,PACKED_ICE:0)
Block(3,32,7,PACKED_ICE:0)
Block(3,32,8,PACKED_ICE:0)
Block(3,33,2,PACKED_ICE:0)
Block(3,33,3,PACKED_ICE:0)
Block(3,33,4,PACKED_ICE:0)
Block(3,33,5,PACKED_ICE:0)
Block(3,33,6,PACKED_ICE:0)
Block(3,33,7,PACKED_ICE:0)
Block(3,33,8,PACKED_ICE:0)
Block(3,34,1,ICE:0)
Block(3,34,2,PACKED_ICE:0)
Block(3,34,3,PACKED_ICE:0)
Block(3,34,4,PACKED_ICE:0)
Block(3,34,5,PACKED_ICE:0)
Block(3,34,6,PACKED_ICE:0)
Block(3,34,7,PACKED_ICE:0)
Block(3,34,8,ICE:0)
Block(3,35,0,ICE:0)
Block(3,35,1,ICE:0)
Block(3,35,2,ICE:0)
Block(3,35,3,PACKED_ICE:0)
Block(3,35,4,PACKED_ICE:0)
Block(3,35,5,PACKED_ICE:0)
Block(3,35,6,PACKED_ICE:0)
Block(3,35,7,PACKED_ICE:0)
Block(3,35,8,ICE:0)
Block(3,36,0,ICE:0)
Block(3,36,1,ICE:0)
Block(3,36,2,ICE:0)
Block(3,36,3,PACKED_ICE:0)
Block(3,36,4,PACKED_ICE:0)
Block(3,36,5,PACKED_ICE:0)
Block(3,36,6,PACKED_ICE:0)
Block(3,36,7,ICE:0)
Block(3,36,8,ICE:0)
Block(3,37,-1,ICE:0)
Block(3,37,0,ICE:0)
Block(3,37,1,ICE:0)
Block(3,37,2,ICE:0)
Block(3,37,3,PACKED_ICE:0)
Block(3,37,4,PACKED_ICE:0)
Block(3,37,5,PACKED_ICE:0)
Block(3,37,6,PACKED_ICE:0)
Block(3,37,7,ICE:0)
Block(3,37,8,ICE:0)
Block(3,38,-2,ICE:0)
Block(3,38,-1,ICE:0)
Block(3,38,0,ICE:0)
Block(3,38,1,ICE:0)
Block(3,38,2,PACKED_ICE:0)
Block(3,38,3,PACKED_ICE:0)
Block(3,38,4,PACKED_ICE:0)
Block(3,38,5,PACKED_ICE:0)
Block(3,38,6,PACKED_ICE:0)
Block(3,38,7,ICE:0)
Block(3,38,8,ICE:0)
Block(3,39,-3,ICE:0)
Block(3,39,-2,ICE:0)
Block(3,39,-1,ICE:0)
Block(3,39,0,PACKED_ICE:0)
Block(3,39,1,PACKED_ICE:0)
Block(3,39,2,PACKED_ICE:0)
Block(3,39,3,PACKED_ICE:0)
Block(3,39,4,ICE:0)
Block(3,39,5,ICE:0)
Block(3,39,6,ICE:0)
Block(3,39,7,ICE:0)
Block(3,39,8,ICE:0)
Block(3,40,-3,ICE:0)
Block(3,40,-2,ICE:0)
Block(3,40,-1,ICE:0)
Block(3,40,0,PACKED_ICE:0)
Block(3,40,1,PACKED_ICE:0)
Block(3,40,2,PACKED_ICE:0)
Block(3,40,3,ICE:0)
Block(3,40,4,ICE:0)
Block(3,40,5,ICE:0)
Block(3,40,6,ICE:0)
Block(3,40,7,ICE:0)
Block(3,40,8,ICE:0)
Block(3,41,-4,ICE:0)
Block(3,41,-3,ICE:0)
Block(3,41,-2,ICE:0)
Block(3,41,-1,ICE:0)
Block(3,41,0,PACKED_ICE:0)
Block(3,41,1,PACKED_ICE:0)
Block(3,41,2,ICE:0)
Block(3,41,3,ICE:0)
Block(3,41,4,ICE:0)
Block(3,41,5,ICE:0)
Block(3,41,6,ICE:0)
Block(3,41,7,ICE:0)
Block(3,41,8,ICE:0)
Block(3,42,-5,PACKED_ICE:0)
Block(3,42,-4,ICE:0)
Block(3,42,-3,ICE:0)
Block(3,42,-2,ICE:0)
Block(3,42,-1,PACKED_ICE:0)
Block(3,42,0,PACKED_ICE:0)
Block(3,42,1,PACKED_ICE:0)
Block(3,42,2,ICE:0)
Block(3,42,3,ICE:0)
Block(3,42,4,ICE:0)
Block(3,42,5,ICE:0)
Block(3,42,6,ICE:0)
Block(3,42,7,ICE:0)
Block(3,42,8,ICE:0)
Block(3,43,-5,PACKED_ICE:0)
Block(3,43,-4,PACKED_ICE:0)
Block(3,43,-3,PACKED_ICE:0)
Block(3,43,-2,PACKED_ICE:0)
Block(3,43,-1,PACKED_ICE:0)
Block(3,43,0,PACKED_ICE:0)
Block(3,43,1,PACKED_ICE:0)
Block(3,43,2,ICE:0)
Block(3,43,3,ICE:0)
Block(3,43,4,ICE:0)
Block(3,43,5,ICE:0)
Block(3,43,6,ICE:0)
Block(3,43,7,ICE:0)
Block(3,44,-6,ICE:0)
Block(3,44,-5,ICE:0)
Block(3,44,-4,PACKED_ICE:0)
Block(3,44,-3,PACKED_ICE:0)
Block(3,44,-2,PACKED_ICE:0)
Block(3,44,-1,PACKED_ICE:0)
Block(3,44,0,PACKED_ICE:0)
Block(3,44,1,ICE:0)
Block(3,44,2,ICE:0)
Block(3,44,3,ICE:0)
Block(3,44,4,ICE:0)
Block(3,44,5,ICE:0)
Block(3,44,6,ICE:0)
Block(3,45,-7,ICE:0)
Block(3,45,-6,ICE:0)
Block(3,45,-5,ICE:0)
Block(3,45,-4,PACKED_ICE:0)
Block(3,45,-3,PACKED_ICE:0)
Block(3,45,-2,PACKED_ICE:0)
Block(3,45,-1,PACKED_ICE:0)
Block(3,45,0,ICE:0)
Block(3,45,1,ICE:0)
Block(3,45,2,ICE:0)
Block(3,45,3,ICE:0)
Block(3,45,4,ICE:0)
Block(3,45,5,ICE:0)
Block(3,46,-7,ICE:0)
Block(3,46,-6,ICE:0)
Block(3,46,-5,ICE:0)
Block(3,46,-4,PACKED_ICE:0)
Block(3,46,-3,PACKED_ICE:0)
Block(3,46,-2,PACKED_ICE:0)
Block(3,46,-1,PACKED_ICE:0)
Block(3,46,0,ICE:0)
Block(3,46,1,ICE:0)
Block(3,46,2,ICE:0)
Block(3,46,3,ICE:0)
Block(3,46,4,ICE:0)
Block(3,47,-7,ICE:0)
Block(3,47,-6,ICE:0)
Block(3,47,-5,ICE:0)
Block(3,47,-4,PACKED_ICE:0)
Block(3,47,-3,PACKED_ICE:0)
Block(3,47,-2,PACKED_ICE:0)
Block(3,47,-1,PACKED_ICE:0)
Block(3,47,0,ICE:0)
Block(3,47,1,ICE:0)
Block(3,47,2,ICE:0)
Block(3,47,3,ICE:0)
Block(3,48,-7,ICE:0)
Block(3,48,-6,ICE:0)
Block(3,48,-5,ICE:0)
Block(3,48,-4,PACKED_ICE:0)
Block(3,48,-3,PACKED_ICE:0)
Block(3,48,-2,PACKED_ICE:0)
Block(3,48,-1,PACKED_ICE:0)
Block(3,48,0,ICE:0)
Block(3,48,1,ICE:0)
Block(3,48,2,ICE:0)
Block(3,49,-7,ICE:0)
Block(3,49,-6,ICE:0)
Block(3,49,-5,PACKED_ICE:0)
Block(3,49,-4,PACKED_ICE:0)
Block(3,49,-3,PACKED_ICE:0)
Block(3,49,-2,ICE:0)
Block(3,49,-1,ICE:0)
Block(3,49,0,ICE:0)
Block(3,49,1,ICE:0)
Block(3,49,2,ICE:0)
Block(3,50,-7,PACKED_ICE:0)
Block(3,50,-6,PACKED_ICE:0)
Block(3,50,-5,PACKED_ICE:0)
Block(3,50,-4,PACKED_ICE:0)
Block(3,50,-3,ICE:0)
Block(3,50,-2,ICE:0)
Block(3,50,-1,ICE:0)
Block(3,50,0,ICE:0)
Block(3,50,1,ICE:0)
Block(3,51,-7,PACKED_ICE:0)
Block(3,51,-6,PACKED_ICE:0)
Block(3,51,-5,PACKED_ICE:0)
Block(3,51,-4,PACKED_ICE:0)
Block(3,51,-3,ICE:0)
Block(3,51,-2,ICE:0)
Block(3,51,-1,ICE:0)
Block(3,51,0,ICE:0)
Block(3,52,-7,PACKED_ICE:0)
Block(3,52,-6,PACKED_ICE:0)
Block(3,52,-5,PACKED_ICE:0)
Block(3,52,-4,PACKED_ICE:0)
Block(3,52,-3,ICE:0)
Block(3,52,-2,ICE:0)
Block(3,52,-1,ICE:0)
Block(3,53,-7,PACKED_ICE:0)
Block(3,53,-6,ICE:0)
Block(3,53,-5,ICE:0)
Block(3,53,-4,ICE:0)
Block(3,53,-3,PACKED_ICE:0)
Block(3,53,-2,ICE:0)
Block(3,54,-7,ICE:0)
Block(3,54,-6,ICE:0)
Block(3,54,-5,ICE:0)
Block(3,54,-4,ICE:0)
Block(3,54,-3,ICE:0)
Block(3,55,-7,ICE:0)
Block(3,55,-6,ICE:0)
Block(3,55,-5,ICE:0)
Block(3,55,-4,ICE:0)
Block(3,56,-7,ICE:0)
Block(3,56,-6,ICE:0)
Block(3,56,-5,ICE:0)
Block(3,57,-7,PACKED_ICE:0)
Block(3,57,-6,ICE:0)
Block(3,58,-7,PACKED_ICE:0)
Block(4,23,8,PACKED_ICE:0)
Block(4,24,8,PACKED_ICE:0)
Block(4,25,7,PACKED_ICE:0)
Block(4,25,8,PACKED_ICE:0)
Block(4,26,6,PACKED_ICE:0)
Block(4,26,7,PACKED_ICE:0)
Block(4,26,8,PACKED_ICE:0)
Block(4,27,6,PACKED_ICE:0)
Block(4,27,7,PACKED_ICE:0)
Block(4,27,8,PACKED_ICE:0)
Block(4,28,5,PACKED_ICE:0)
Block(4,28,6,PACKED_ICE:0)
Block(4,28,7,PACKED_ICE:0)
Block(4,28,8,PACKED_ICE:0)
Block(4,29,4,PACKED_ICE:0)
Block(4,29,5,PACKED_ICE:0)
Block(4,29,6,PACKED_ICE:0)
Block(4,29,7,PACKED_ICE:0)
Block(4,29,8,PACKED_ICE:0)
Block(4,30,4,PACKED_ICE:0)
Block(4,30,5,PACKED_ICE:0)
Block(4,30,6,PACKED_ICE:0)
Block(4,30,7,PACKED_ICE:0)
Block(4,30,8,PACKED_ICE:0)
Block(4,31,3,PACKED_ICE:0)
Block(4,31,4,PACKED_ICE:0)
Block(4,31,5,PACKED_ICE:0)
Block(4,31,6,PACKED_ICE:0)
Block(4,31,7,PACKED_ICE:0)
Block(4,31,8,PACKED_ICE:0)
Block(4,32,2,PACKED_ICE:0)
Block(4,32,3,PACKED_ICE:0)
Block(4,32,4,PACKED_ICE:0)
Block(4,32,5,PACKED_ICE:0)
Block(4,32,6,PACKED_ICE:0)
Block(4,32,7,PACKED_ICE:0)
Block(4,32,8,PACKED_ICE:0)
Block(4,33,2,PACKED_ICE:0)
Block(4,33,3,PACKED_ICE:0)
Block(4,33,4,PACKED_ICE:0)
Block(4,33,5,PACKED_ICE:0)
Block(4,33,6,PACKED_ICE:0)
Block(4,33,7,PACKED_ICE:0)
Block(4,33,8,PACKED_ICE:0)
Block(4,34,1,PACKED_ICE:0)
Block(4,34,2,PACKED_ICE:0)
Block(4,34,3,PACKED_ICE:0)
Block(4,34,4,PACKED_ICE:0)
Block(4,34,5,PACKED_ICE:0)
Block(4,34,6,PACKED_ICE:0)
Block(4,34,7,PACKED_ICE:0)
Block(4,34,8,ICE:0)
Block(4,35,0,PACKED_ICE:0)
Block(4,35,1,PACKED_ICE:0)
Block(4,35,2,PACKED_ICE:0)
Block(4,35,3,PACKED_ICE:0)
Block(4,35,4,PACKED_ICE:0)
Block(4,35,5,PACKED_ICE:0)
Block(4,35,6,PACKED_ICE:0)
Block(4,35,7,ICE:0)
Block(4,35,8,ICE:0)
Block(4,36,0,PACKED_ICE:0)
Block(4,36,1,PACKED_ICE:0)
Block(4,36,2,PACKED_ICE:0)
Block(4,36,3,PACKED_ICE:0)
Block(4,36,4,PACKED_ICE:0)
Block(4,36,5,PACKED_ICE:0)
Block(4,36,6,PACKED_ICE:0)
Block(4,36,7,ICE:0)
Block(4,36,8,ICE:0)
Block(4,37,-1,PACKED_ICE:0)
Block(4,37,0,PACKED_ICE:0)
Block(4,37,1,PACKED_ICE:0)
Block(4,37,2,PACKED_ICE:0)
Block(4,37,3,PACKED_ICE:0)
Block(4,37,4,PACKED_ICE:0)
Block(4,37,5,PACKED_ICE:0)
Block(4,37,6,PACKED_ICE:0)
Block(4,37,7,ICE:0)
Block(4,37,8,ICE:0)
Block(4,38,-2,PACKED_ICE:0)
Block(4,38,-1,PACKED_ICE:0)
Block(4,38,0,PACKED_ICE:0)
Block(4,38,1,PACKED_ICE:0)
Block(4,38,2,PACKED_ICE:0)
Block(4,38,3,PACKED_ICE:0)
Block(4,38,4,PACKED_ICE:0)
Block(4,38,5,ICE:0)
Block(4,38,6,ICE:0)
Block(4,38,7,ICE:0)
Block(4,38,8,ICE:0)
Block(4,39,-2,PACKED_ICE:0)
Block(4,39,-1,PACKED_ICE:0)
Block(4,39,0,PACKED_ICE:0)
Block(4,39,1,PACKED_ICE:0)
Block(4,39,2,PACKED_ICE:0)
Block(4,39,3,ICE:0)
Block(4,39,4,ICE:0)
Block(4,39,5,ICE:0)
Block(4,39,6,ICE:0)
Block(4,39,7,ICE:0)
Block(4,39,8,ICE:0)
Block(4,40,-3,PACKED_ICE:0)
Block(4,40,-2,PACKED_ICE:0)
Block(4,40,-1,PACKED_ICE:0)
Block(4,40,0,PACKED_ICE:0)
Block(4,40,1,PACKED_ICE:0)
Block(4,40,2,ICE:0)
Block(4,40,3,ICE:0)
Block(4,40,4,ICE:0)
Block(4,40,5,ICE:0)
Block(4,40,6,ICE:0)
Block(4,40,7,ICE:0)
Block(4,40,8,ICE:0)
Block(4,41,-4,PACKED_ICE:0)
Block(4,41,-3,PACKED_ICE:0)
Block(4,41,-2,PACKED_ICE:0)
Block(4,41,-1,PACKED_ICE:0)
Block(4,41,0,PACKED_ICE:0)
Block(4,41,1,PACKED_ICE:0)
Block(4,41,2,ICE:0)
Block(4,41,3,ICE:0)
Block(4,41,4,ICE:0)
Block(4,41,5,ICE:0)
Block(4,41,6,ICE:0)
Block(4,41,7,ICE:0)
Block(4,41,8,ICE:0)
Block(4,42,-4,PACKED_ICE:0)
Block(4,42,-3,PACKED_ICE:0)
Block(4,42,-2,PACKED_ICE:0)
Block(4,42,-1,PACKED_ICE:0)
Block(4,42,0,PACKED_ICE:0)
Block(4,42,1,ICE:0)
Block(4,42,2,ICE:0)
Block(4,42,3,ICE:0)
Block(4,42,4,ICE:0)
Block(4,42,5,ICE:0)
Block(4,42,6,ICE:0)
Block(4,42,7,ICE:0)
Block(4,42,8,ICE:0)
Block(4,43,-5,PACKED_ICE:0)
Block(4,43,-4,PACKED_ICE:0)
Block(4,43,-3,PACKED_ICE:0)
Block(4,43,-2,PACKED_ICE:0)
Block(4,43,-1,PACKED_ICE:0)
Block(4,43,0,PACKED_ICE:0)
Block(4,43,1,ICE:0)
Block(4,43,2,ICE:0)
Block(4,43,3,ICE:0)
Block(4,43,4,ICE:0)
Block(4,43,5,ICE:0)
Block(4,43,6,ICE:0)
Block(4,43,7,ICE:0)
Block(4,44,-6,PACKED_ICE:0)
Block(4,44,-5,PACKED_ICE:0)
Block(4,44,-4,PACKED_ICE:0)
Block(4,44,-3,PACKED_ICE:0)
Block(4,44,-2,PACKED_ICE:0)
Block(4,44,-1,PACKED_ICE:0)
Block(4,44,0,ICE:0)
Block(4,44,1,ICE:0)
Block(4,44,2,ICE:0)
Block(4,44,3,ICE:0)
Block(4,44,4,ICE:0)
Block(4,44,5,ICE:0)
Block(4,44,6,ICE:0)
Block(4,45,-6,ICE:0)
Block(4,45,-5,PACKED_ICE:0)
Block(4,45,-4,PACKED_ICE:0)
Block(4,45,-3,PACKED_ICE:0)
Block(4,45,-2,PACKED_ICE:0)
Block(4,45,-1,ICE:0)
Block(4,45,0,ICE:0)
Block(4,45,1,ICE:0)
Block(4,45,2,ICE:0)
Block(4,45,3,ICE:0)
Block(4,45,4,ICE:0)
Block(4,45,5,ICE:0)
Block(4,46,-7,ICE:0)
Block(4,46,-6,ICE:0)
Block(4,46,-5,PACKED_ICE:0)
Block(4,46,-4,PACKED_ICE:0)
Block(4,46,-3,PACKED_ICE:0)
Block(4,46,-2,PACKED_ICE:0)
Block(4,46,-1,ICE:0)
Block(4,46,0,ICE:0)
Block(4,46,1,ICE:0)
Block(4,46,2,ICE:0)
Block(4,46,3,ICE:0)
Block(4,46,4,ICE:0)
Block(4,47,-7,ICE:0)
Block(4,47,-6,ICE:0)
Block(4,47,-5,PACKED_ICE:0)
Block(4,47,-4,PACKED_ICE:0)
Block(4,47,-3,PACKED_ICE:0)
Block(4,47,-2,PACKED_ICE:0)
Block(4,47,-1,ICE:0)
Block(4,47,0,ICE:0)
Block(4,47,1,ICE:0)
Block(4,47,2,ICE:0)
Block(4,47,3,ICE:0)
Block(4,48,-7,ICE:0)
Block(4,48,-6,PACKED_ICE:0)
Block(4,48,-5,PACKED_ICE:0)
Block(4,48,-4,PACKED_ICE:0)
Block(4,48,-3,ICE:0)
Block(4,48,-2,ICE:0)
Block(4,48,-1,ICE:0)
Block(4,48,0,ICE:0)
Block(4,48,1,ICE:0)
Block(4,48,2,ICE:0)
Block(4,49,-7,PACKED_ICE:0)
Block(4,49,-6,PACKED_ICE:0)
Block(4,49,-5,PACKED_ICE:0)
Block(4,49,-4,ICE:0)
Block(4,49,-3,ICE:0)
Block(4,49,-2,ICE:0)
Block(4,49,-1,ICE:0)
Block(4,49,0,ICE:0)
Block(4,49,1,ICE:0)
Block(4,50,-7,PACKED_ICE:0)
Block(4,50,-6,PACKED_ICE:0)
Block(4,50,-5,PACKED_ICE:0)
Block(4,50,-4,ICE:0)
Block(4,50,-3,ICE:0)
Block(4,50,-2,ICE:0)
Block(4,50,-1,ICE:0)
Block(4,50,0,ICE:0)
Block(4,51,-7,PACKED_ICE:0)
Block(4,51,-6,PACKED_ICE:0)
Block(4,51,-5,PACKED_ICE:0)
Block(4,51,-4,ICE:0)
Block(4,51,-3,ICE:0)
Block(4,51,-2,ICE:0)
Block(4,51,-1,ICE:0)
Block(4,51,0,ICE:0)
Block(4,52,-7,ICE:0)
Block(4,52,-6,ICE:0)
Block(4,52,-5,ICE:0)
Block(4,52,-4,ICE:0)
Block(4,52,-3,ICE:0)
Block(4,52,-2,ICE:0)
Block(4,52,-1,ICE:0)
Block(4,53,-7,ICE:0)
Block(4,53,-6,ICE:0)
Block(4,53,-5,ICE:0)
Block(4,53,-4,ICE:0)
Block(4,53,-3,ICE:0)
Block(4,53,-2,ICE:0)
Block(4,54,-7,ICE:0)
Block(4,54,-6,ICE:0)
Block(4,54,-5,ICE:0)
Block(4,54,-4,ICE:0)
Block(4,54,-3,ICE:0)
Block(4,55,-7,ICE:0)
Block(4,55,-6,ICE:0)
Block(4,55,-5,ICE:0)
Block(4,55,-4,ICE:0)
Block(4,56,-7,ICE:0)
Block(4,56,-6,ICE:0)
Block(4,56,-5,ICE:0)
Block(4,57,-7,ICE:0)
Block(4,57,-6,ICE:0)
Block(4,58,-7,ICE:0)
Block(5,24,8,PACKED_ICE:0)
Block(5,25,7,PACKED_ICE:0)
Block(5,25,8,PACKED_ICE:0)
Block(5,26,7,PACKED_ICE:0)
Block(5,26,8,PACKED_ICE:0)
Block(5,27,6,PACKED_ICE:0)
Block(5,27,7,PACKED_ICE:0)
Block(5,27,8,PACKED_ICE:0)
Block(5,28,5,PACKED_ICE:0)
Block(5,28,6,PACKED_ICE:0)
Block(5,28,7,PACKED_ICE:0)
Block(5,28,8,PACKED_ICE:0)
Block(5,29,5,PACKED_ICE:0)
Block(5,29,6,PACKED_ICE:0)
Block(5,29,7,PACKED_ICE:0)
Block(5,29,8,PACKED_ICE:0)
Block(5,30,4,PACKED_ICE:0)
Block(5,30,5,PACKED_ICE:0)
Block(5,30,6,PACKED_ICE:0)
Block(5,30,7,PACKED_ICE:0)
Block(5,30,8,PACKED_ICE:0)
Block(5,31,3,PACKED_ICE:0)
Block(5,31,4,PACKED_ICE:0)
Block(5,31,5,PACKED_ICE:0)
Block(5,31,6,PACKED_ICE:0)
Block(5,31,7,PACKED_ICE:0)
Block(5,31,8,PACKED_ICE:0)
Block(5,32,2,PACKED_ICE:0)
Block(5,32,3,PACKED_ICE:0)
Block(5,32,4,PACKED_ICE:0)
Block(5,32,5,PACKED_ICE:0)
Block(5,32,6,PACKED_ICE:0)
Block(5,32,7,PACKED_ICE:0)
Block(5,32,8,PACKED_ICE:0)
Block(5,33,2,PACKED_ICE:0)
Block(5,33,3,PACKED_ICE:0)
Block(5,33,4,PACKED_ICE:0)
Block(5,33,5,PACKED_ICE:0)
Block(5,33,6,PACKED_ICE:0)
Block(5,33,7,PACKED_ICE:0)
Block(5,33,8,PACKED_ICE:0)
Block(5,34,1,PACKED_ICE:0)
Block(5,34,2,PACKED_ICE:0)
Block(5,34,3,PACKED_ICE:0)
Block(5,34,4,PACKED_ICE:0)
Block(5,34,5,PACKED_ICE:0)
Block(5,34,6,PACKED_ICE:0)
Block(5,34,7,PACKED_ICE:0)
Block(5,34,8,ICE:0)
Block(5,35,0,PACKED_ICE:0)
Block(5,35,1,PACKED_ICE:0)
Block(5,35,2,PACKED_ICE:0)
Block(5,35,3,PACKED_ICE:0)
Block(5,35,4,PACKED_ICE:0)
Block(5,35,5,PACKED_ICE:0)
Block(5,35,6,PACKED_ICE:0)
Block(5,35,7,ICE:0)
Block(5,35,8,ICE:0)
Block(5,36,0,PACKED_ICE:0)
Block(5,36,1,PACKED_ICE:0)
Block(5,36,2,PACKED_ICE:0)
Block(5,36,3,PACKED_ICE:0)
Block(5,36,4,PACKED_ICE:0)
Block(5,36,5,PACKED_ICE:0)
Block(5,36,6,PACKED_ICE:0)
Block(5,36,7,ICE:0)
Block(5,36,8,ICE:0)
Block(5,37,-1,PACKED_ICE:0)
Block(5,37,0,PACKED_ICE:0)
Block(5,37,1,PACKED_ICE:0)
Block(5,37,2,PACKED_ICE:0)
Block(5,37,3,PACKED_ICE:0)
Block(5,37,4,PACKED_ICE:0)
Block(5,37,5,PACKED_ICE:0)
Block(5,37,6,PACKED_ICE:0)
Block(5,37,7,ICE:0)
Block(5,37,8,ICE:0)
Block(5,38,-2,PACKED_ICE:0)
Block(5,38,-1,PACKED_ICE:0)
Block(5,38,0,PACKED_ICE:0)
Block(5,38,1,PACKED_ICE:0)
Block(5,38,2,PACKED_ICE:0)
Block(5,38,3,PACKED_ICE:0)
Block(5,38,4,ICE:0)
Block(5,38,5,ICE:0)
Block(5,38,6,ICE:0)
Block(5,38,7,ICE:0)
Block(5,38,8,ICE:0)
Block(5,39,-2,PACKED_ICE:0)
Block(5,39,-1,PACKED_ICE:0)
Block(5,39,0,PACKED_ICE:0)
Block(5,39,1,PACKED_ICE:0)
Block(5,39,2,PACKED_ICE:0)
Block(5,39,3,ICE:0)
Block(5,39,4,ICE:0)
Block(5,39,5,ICE:0)
Block(5,39,6,ICE:0)
Block(5,39,7,ICE:0)
Block(5,39,8,ICE:0)
Block(5,40,-3,PACKED_ICE:0)
Block(5,40,-2,PACKED_ICE:0)
Block(5,40,-1,PACKED_ICE:0)
Block(5,40,0,PACKED_ICE:0)
Block(5,40,1,PACKED_ICE:0)
Block(5,40,2,ICE:0)
Block(5,40,3,ICE:0)
Block(5,40,4,ICE:0)
Block(5,40,5,ICE:0)
Block(5,40,6,ICE:0)
Block(5,40,7,ICE:0)
Block(5,40,8,ICE:0)
Block(5,41,-4,PACKED_ICE:0)
Block(5,41,-3,PACKED_ICE:0)
Block(5,41,-2,PACKED_ICE:0)
Block(5,41,-1,PACKED_ICE:0)
Block(5,41,0,PACKED_ICE:0)
Block(5,41,1,ICE:0)
Block(5,41,2,ICE:0)
Block(5,41,3,ICE:0)
Block(5,41,4,ICE:0)
Block(5,41,5,ICE:0)
Block(5,41,6,ICE:0)
Block(5,41,7,ICE:0)
Block(5,41,8,ICE:0)
Block(5,42,-4,PACKED_ICE:0)
Block(5,42,-3,PACKED_ICE:0)
Block(5,42,-2,PACKED_ICE:0)
Block(5,42,-1,PACKED_ICE:0)
Block(5,42,0,PACKED_ICE:0)
Block(5,42,1,ICE:0)
Block(5,42,2,ICE:0)
Block(5,42,3,ICE:0)
Block(5,42,4,ICE:0)
Block(5,42,5,ICE:0)
Block(5,42,6,ICE:0)
Block(5,42,7,ICE:0)
Block(5,42,8,ICE:0)
Block(5,43,-5,PACKED_ICE:0)
Block(5,43,-4,PACKED_ICE:0)
Block(5,43,-3,PACKED_ICE:0)
Block(5,43,-2,PACKED_ICE:0)
Block(5,43,-1,ICE:0)
Block(5,43,0,ICE:0)
Block(5,43,1,ICE:0)
Block(5,43,2,ICE:0)
Block(5,43,3,ICE:0)
Block(5,43,4,ICE:0)
Block(5,43,5,ICE:0)
Block(5,43,6,ICE:0)
Block(5,43,7,ICE:0)
Block(5,44,-6,PACKED_ICE:0)
Block(5,44,-5,PACKED_ICE:0)
Block(5,44,-4,PACKED_ICE:0)
Block(5,44,-3,PACKED_ICE:0)
Block(5,44,-2,ICE:0)
Block(5,44,-1,ICE:0)
Block(5,44,0,ICE:0)
Block(5,44,1,ICE:0)
Block(5,44,2,ICE:0)
Block(5,44,3,ICE:0)
Block(5,44,4,ICE:0)
Block(5,44,5,ICE:0)
Block(5,44,6,ICE:0)
Block(5,45,-6,PACKED_ICE:0)
Block(5,45,-5,PACKED_ICE:0)
Block(5,45,-4,PACKED_ICE:0)
Block(5,45,-3,PACKED_ICE:0)
Block(5,45,-2,ICE:0)
Block(5,45,-1,ICE:0)
Block(5,45,0,ICE:0)
Block(5,45,1,ICE:0)
Block(5,45,2,ICE:0)
Block(5,45,3,ICE:0)
Block(5,45,4,ICE:0)
Block(5,45,5,ICE:0)
Block(5,46,-7,PACKED_ICE:0)
Block(5,46,-6,PACKED_ICE:0)
Block(5,46,-5,PACKED_ICE:0)
Block(5,46,-4,PACKED_ICE:0)
Block(5,46,-3,PACKED_ICE:0)
Block(5,46,-2,ICE:0)
Block(5,46,-1,ICE:0)
Block(5,46,0,ICE:0)
Block(5,46,1,ICE:0)
Block(5,46,2,ICE:0)
Block(5,46,3,ICE:0)
Block(5,46,4,ICE:0)
Block(5,47,-7,PACKED_ICE:0)
Block(5,47,-6,PACKED_ICE:0)
Block(5,47,-5,PACKED_ICE:0)
Block(5,47,-4,PACKED_ICE:0)
Block(5,47,-3,ICE:0)
Block(5,47,-2,ICE:0)
Block(5,47,-1,ICE:0)
Block(5,47,0,ICE:0)
Block(5,47,1,ICE:0)
Block(5,47,2,ICE:0)
Block(5,47,3,ICE:0)
Block(5,48,-7,PACKED_ICE:0)
Block(5,48,-6,PACKED_ICE:0)
Block(5,48,-5,PACKED_ICE:0)
Block(5,48,-4,ICE:0)
Block(5,48,-3,ICE:0)
Block(5,48,-2,ICE:0)
Block(5,48,-1,ICE:0)
Block(5,48,0,ICE:0)
Block(5,48,1,ICE:0)
Block(5,48,2,ICE:0)
Block(5,49,-7,PACKED_ICE:0)
Block(5,49,-6,PACKED_ICE:0)
Block(5,49,-5,ICE:0)
Block(5,49,-4,ICE:0)
Block(5,49,-3,ICE:0)
Block(5,49,-2,ICE:0)
Block(5,49,-1,ICE:0)
Block(5,49,0,ICE:0)
Block(5,49,1,ICE:0)
Block(5,50,-7,PACKED_ICE:0)
Block(5,50,-6,PACKED_ICE:0)
Block(5,50,-5,ICE:0)
Block(5,50,-4,ICE:0)
Block(5,50,-3,ICE:0)
Block(5,50,-2,ICE:0)
Block(5,50,-1,ICE:0)
Block(5,50,0,ICE:0)
Block(5,51,-7,ICE:0)
Block(5,51,-6,ICE:0)
Block(5,51,-5,ICE:0)
Block(5,51,-4,ICE:0)
Block(5,51,-3,ICE:0)
Block(5,51,-2,ICE:0)
Block(5,51,-1,ICE:0)
Block(5,52,-7,ICE:0)
Block(5,52,-6,ICE:0)
Block(5,52,-5,ICE:0)
Block(5,52,-4,ICE:0)
Block(5,52,-3,ICE:0)
Block(5,52,-2,ICE:0)
Block(5,53,-7,ICE:0)
Block(5,53,-6,ICE:0)
Block(5,53,-5,ICE:0)
Block(5,53,-4,ICE:0)
Block(5,53,-3,ICE:0)
Block(5,53,-2,ICE:0)
Block(5,54,-7,ICE:0)
Block(5,54,-6,ICE:0)
Block(5,54,-5,ICE:0)
Block(5,54,-4,ICE:0)
Block(5,54,-3,ICE:0)
Block(5,55,-7,ICE:0)
Block(5,55,-6,ICE:0)
Block(5,55,-5,ICE:0)
Block(5,55,-4,ICE:0)
Block(5,56,-7,ICE:0)
Block(5,56,-6,ICE:0)
Block(5,56,-5,ICE:0)
Block(5,57,-7,ICE:0)
Block(5,57,-6,ICE:0)
Block(5,58,-7,ICE:0)
Block(6,24,8,PACKED_ICE:0)
Block(6,25,7,PACKED_ICE:0)
Block(6,25,8,PACKED_ICE:0)
Block(6,26,7,PACKED_ICE:0)
Block(6,26,8,PACKED_ICE:0)
Block(6,27,6,PACKED_ICE:0)
Block(6,27,7,PACKED_ICE:0)
Block(6,27,8,PACKED_ICE:0)
Block(6,28,5,PACKED_ICE:0)
Block(6,28,6,PACKED_ICE:0)
Block(6,28,7,PACKED_ICE:0)
Block(6,28,8,PACKED_ICE:0)
Block(6,29,5,PACKED_ICE:0)
Block(6,29,6,PACKED_ICE:0)
Block(6,29,7,PACKED_ICE:0)
Block(6,29,8,PACKED_ICE:0)
Block(6,30,4,PACKED_ICE:0)
Block(6,30,5,PACKED_ICE:0)
Block(6,30,6,PACKED_ICE:0)
Block(6,30,7,PACKED_ICE:0)
Block(6,30,8,PACKED_ICE:0)
Block(6,31,3,PACKED_ICE:0)
Block(6,31,4,PACKED_ICE:0)
Block(6,31,5,PACKED_ICE:0)
Block(6,31,6,PACKED_ICE:0)
Block(6,31,7,PACKED_ICE:0)
Block(6,31,8,PACKED_ICE:0)
Block(6,32,3,PACKED_ICE:0)
Block(6,32,4,PACKED_ICE:0)
Block(6,32,5,PACKED_ICE:0)
Block(6,32,6,PACKED_ICE:0)
Block(6,32,7,PACKED_ICE:0)
Block(6,32,8,PACKED_ICE:0)
Block(6,33,2,PACKED_ICE:0)
Block(6,33,3,PACKED_ICE:0)
Block(6,33,4,PACKED_ICE:0)
Block(6,33,5,PACKED_ICE:0)
Block(6,33,6,PACKED_ICE:0)
Block(6,33,7,PACKED_ICE:0)
Block(6,33,8,PACKED_ICE:0)
Block(6,34,1,PACKED_ICE:0)
Block(6,34,2,PACKED_ICE:0)
Block(6,34,3,PACKED_ICE:0)
Block(6,34,4,PACKED_ICE:0)
Block(6,34,5,PACKED_ICE:0)
Block(6,34,6,PACKED_ICE:0)
Block(6,34,7,PACKED_ICE:0)
Block(6,34,8,ICE:0)
Block(6,35,1,PACKED_ICE:0)
Block(6,35,2,PACKED_ICE:0)
Block(6,35,3,PACKED_ICE:0)
Block(6,35,4,PACKED_ICE:0)
Block(6,35,5,PACKED_ICE:0)
Block(6,35,6,PACKED_ICE:0)
Block(6,35,7,ICE:0)
Block(6,35,8,ICE:0)
Block(6,36,0,PACKED_ICE:0)
Block(6,36,1,PACKED_ICE:0)
Block(6,36,2,PACKED_ICE:0)
Block(6,36,3,PACKED_ICE:0)
Block(6,36,4,PACKED_ICE:0)
Block(6,36,5,PACKED_ICE:0)
Block(6,36,6,ICE:0)
Block(6,36,7,ICE:0)
Block(6,36,8,ICE:0)
Block(6,37,-1,PACKED_ICE:0)
Block(6,37,0,PACKED_ICE:0)
Block(6,37,1,PACKED_ICE:0)
Block(6,37,2,PACKED_ICE:0)
Block(6,37,3,PACKED_ICE:0)
Block(6,37,4,PACKED_ICE:0)
Block(6,37,5,ICE:0)
Block(6,37,6,ICE:0)
Block(6,37,7,ICE:0)
Block(6,37,8,ICE:0)
Block(6,38,-1,PACKED_ICE:0)
Block(6,38,0,PACKED_ICE:0)
Block(6,38,1,PACKED_ICE:0)
Block(6,38,2,PACKED_ICE:0)
Block(6,38,3,PACKED_ICE:0)
Block(6,38,4,ICE:0)
Block(6,38,5,ICE:0)
Block(6,38,6,ICE:0)
Block(6,38,7,ICE:0)
Block(6,38,8,ICE:0)
Block(6,39,-2,PACKED_ICE:0)
Block(6,39,-1,PACKED_ICE:0)
Block(6,39,0,PACKED_ICE:0)
Block(6,39,1,PACKED_ICE:0)
Block(6,39,2,PACKED_ICE:0)
Block(6,39,3,ICE:0)
Block(6,39,4,ICE:0)
Block(6,39,5,ICE:0)
Block(6,39,6,ICE:0)
Block(6,39,7,ICE:0)
Block(6,39,8,ICE:0)
Block(6,40,-3,PACKED_ICE:0)
Block(6,40,-2,PACKED_ICE:0)
Block(6,40,-1,PACKED_ICE:0)
Block(6,40,0,PACKED_ICE:0)
Block(6,40,1,PACKED_ICE:0)
Block(6,40,2,ICE:0)
Block(6,40,3,ICE:0)
Block(6,40,4,ICE:0)
Block(6,40,5,ICE:0)
Block(6,40,6,ICE:0)
Block(6,40,7,ICE:0)
Block(6,40,8,ICE:0)
Block(6,41,-3,PACKED_ICE:0)
Block(6,41,-2,PACKED_ICE:0)
Block(6,41,-1,PACKED_ICE:0)
Block(6,41,0,PACKED_ICE:0)
Block(6,41,1,ICE:0)
Block(6,41,2,ICE:0)
Block(6,41,3,ICE:0)
Block(6,41,4,ICE:0)
Block(6,41,5,ICE:0)
Block(6,41,6,ICE:0)
Block(6,41,7,ICE:0)
Block(6,41,8,ICE:0)
Block(6,42,-4,PACKED_ICE:0)
Block(6,42,-3,PACKED_ICE:0)
Block(6,42,-2,PACKED_ICE:0)
Block(6,42,-1,ICE:0)
Block(6,42,0,ICE:0)
Block(6,42,1,ICE:0)
Block(6,42,2,ICE:0)
Block(6,42,3,ICE:0)
Block(6,42,4,ICE:0)
Block(6,42,5,ICE:0)
Block(6,42,6,ICE:0)
Block(6,42,7,ICE:0)
Block(6,43,-5,PACKED_ICE:0)
Block(6,43,-4,PACKED_ICE:0)
Block(6,43,-3,PACKED_ICE:0)
Block(6,43,-2,ICE:0)
Block(6,43,-1,ICE:0)
Block(6,43,0,ICE:0)
Block(6,43,1,ICE:0)
Block(6,43,2,ICE:0)
Block(6,43,3,ICE:0)
Block(6,43,4,ICE:0)
Block(6,43,5,ICE:0)
Block(6,43,6,ICE:0)
Block(6,44,-5,PACKED_ICE:0)
Block(6,44,-4,PACKED_ICE:0)
Block(6,44,-3,ICE:0)
Block(6,44,-2,ICE:0)
Block(6,44,-1,ICE:0)
Block(6,44,0,ICE:0)
Block(6,44,1,ICE:0)
Block(6,44,2,ICE:0)
Block(6,44,3,ICE:0)
Block(6,44,4,ICE:0)
Block(6,44,5,ICE:0)
Block(6,44,6,ICE:0)
Block(6,45,-6,PACKED_ICE:0)
Block(6,45,-5,PACKED_ICE:0)
Block(6,45,-4,PACKED_ICE:0)
Block(6,45,-3,ICE:0)
Block(6,45,-2,ICE:0)
Block(6,45,-1,ICE:0)
Block(6,45,0,ICE:0)
Block(6,45,1,ICE:0)
Block(6,45,2,ICE:0)
Block(6,45,3,ICE:0)
Block(6,45,4,ICE:0)
Block(6,45,5,ICE:0)
Block(6,46,-7,PACKED_ICE:0)
Block(6,46,-6,PACKED_ICE:0)
Block(6,46,-5,PACKED_ICE:0)
Block(6,46,-4,PACKED_ICE:0)
Block(6,46,-3,ICE:0)
Block(6,46,-2,ICE:0)
Block(6,46,-1,ICE:0)
Block(6,46,0,ICE:0)
Block(6,46,1,ICE:0)
Block(6,46,2,ICE:0)
Block(6,46,3,ICE:0)
Block(6,46,4,ICE:0)
Block(6,47,-7,PACKED_ICE:0)
Block(6,47,-6,PACKED_ICE:0)
Block(6,47,-5,PACKED_ICE:0)
Block(6,47,-4,ICE:0)
Block(6,47,-3,ICE:0)
Block(6,47,-2,ICE:0)
Block(6,47,-1,ICE:0)
Block(6,47,0,ICE:0)
Block(6,47,1,ICE:0)
Block(6,47,2,ICE:0)
Block(6,47,3,ICE:0)
Block(6,48,-7,PACKED_ICE:0)
Block(6,48,-6,PACKED_ICE:0)
Block(6,48,-5,ICE:0)
Block(6,48,-4,ICE:0)
Block(6,48,-3,ICE:0)
Block(6,48,-2,ICE:0)
Block(6,48,-1,ICE:0)
Block(6,48,0,ICE:0)
Block(6,48,1,ICE:0)
Block(6,48,2,ICE:0)
Block(6,49,-7,PACKED_ICE:0)
Block(6,49,-6,ICE:0)
Block(6,49,-5,ICE:0)
Block(6,49,-4,ICE:0)
Block(6,49,-3,ICE:0)
Block(6,49,-2,ICE:0)
Block(6,49,-1,ICE:0)
Block(6,49,0,ICE:0)
Block(6,49,1,ICE:0)
Block(6,50,-7,PACKED_ICE:0)
Block(6,50,-6,ICE:0)
Block(6,50,-5,ICE:0)
Block(6,50,-4,ICE:0)
Block(6,50,-3,ICE:0)
Block(6,50,-2,ICE:0)
Block(6,50,-1,ICE:0)
Block(6,50,0,ICE:0)
Block(6,51,-7,ICE:0)
Block(6,51,-6,ICE:0)
Block(6,51,-5,ICE:0)
Block(6,51,-4,ICE:0)
Block(6,51,-3,ICE:0)
Block(6,51,-2,ICE:0)
Block(6,51,-1,ICE:0)
Block(6,52,-7,ICE:0)
Block(6,52,-6,ICE:0)
Block(6,52,-5,ICE:0)
Block(6,52,-4,ICE:0)
Block(6,52,-3,ICE:0)
Block(6,52,-2,ICE:0)
Block(6,53,-7,ICE:0)
Block(6,53,-6,ICE:0)
Block(6,53,-5,ICE:0)
Block(6,53,-4,ICE:0)
Block(6,53,-3,ICE:0)
Block(6,54,-7,ICE:0)
Block(6,54,-6,ICE:0)
Block(6,54,-5,ICE:0)
Block(6,54,-4,ICE:0)
Block(6,55,-7,ICE:0)
Block(6,55,-6,ICE:0)
Block(6,55,-5,ICE:0)
Block(6,55,-4,ICE:0)
Block(6,56,-7,ICE:0)
Block(6,56,-6,ICE:0)
Block(6,56,-5,ICE:0)
Block(6,57,-7,ICE:0)
Block(6,57,-6,ICE:0)
Block(6,58,-7,ICE:0)
Block(7,24,8,PACKED_ICE:0)
Block(7,25,8,PACKED_ICE:0)
Block(7,26,7,PACKED_ICE:0)
Block(7,26,8,PACKED_ICE:0)
Block(7,27,6,PACKED_ICE:0)
Block(7,27,7,PACKED_ICE:0)
Block(7,27,8,PACKED_ICE:0)
Block(7,28,6,PACKED_ICE:0)
Block(7,28,7,PACKED_ICE:0)
Block(7,28,8,PACKED_ICE:0)
Block(7,29,5,PACKED_ICE:0)
Block(7,29,6,PACKED_ICE:0)
Block(7,29,7,PACKED_ICE:0)
Block(7,29,8,PACKED_ICE:0)
Block(7,30,4,PACKED_ICE:0)
Block(7,30,5,PACKED_ICE:0)
Block(7,30,6,PACKED_ICE:0)
Block(7,30,7,PACKED_ICE:0)
Block(7,30,8,PACKED_ICE:0)
Block(7,31,4,PACKED_ICE:0)
Block(7,31,5,PACKED_ICE:0)
Block(7,31,6,PACKED_ICE:0)
Block(7,31,7,PACKED_ICE:0)
Block(7,31,8,PACKED_ICE:0)
Block(7,32,3,PACKED_ICE:0)
Block(7,32,4,PACKED_ICE:0)
Block(7,32,5,PACKED_ICE:0)
Block(7,32,6,PACKED_ICE:0)
Block(7,32,7,PACKED_ICE:0)
Block(7,32,8,PACKED_ICE:0)
Block(7,33,2,PACKED_ICE:0)
Block(7,33,3,PACKED_ICE:0)
Block(7,33,4,PACKED_ICE:0)
Block(7,33,5,PACKED_ICE:0)
Block(7,33,6,PACKED_ICE:0)
Block(7,33,7,PACKED_ICE:0)
Block(7,33,8,ICE:0)
Block(7,34,2,PACKED_ICE:0)
Block(7,34,3,PACKED_ICE:0)
Block(7,34,4,PACKED_ICE:0)
Block(7,34,5,PACKED_ICE:0)
Block(7,34,6,PACKED_ICE:0)
Block(7,34,7,PACKED_ICE:0)
Block(7,34,8,ICE:0)
Block(7,35,1,PACKED_ICE:0)
Block(7,35,2,PACKED_ICE:0)
Block(7,35,3,PACKED_ICE:0)
Block(7,35,4,PACKED_ICE:0)
Block(7,35,5,PACKED_ICE:0)
Block(7,35,6,ICE:0)
Block(7,35,7,ICE:0)
Block(7,35,8,ICE:0)
Block(7,36,0,PACKED_ICE:0)
Block(7,36,1,PACKED_ICE:0)
Block(7,36,2,PACKED_ICE:0)
Block(7,36,3,PACKED_ICE:0)
Block(7,36,4,PACKED_ICE:0)
Block(7,36,5,ICE:0)
Block(7,36,6,ICE:0)
Block(7,36,7,ICE:0)
Block(7,36,8,ICE:0)
Block(7,37,0,PACKED_ICE:0)
Block(7,37,1,PACKED_ICE:0)
Block(7,37,2,PACKED_ICE:0)
Block(7,37,3,PACKED_ICE:0)
Block(7,37,4,ICE:0)
Block(7,37,5,ICE:0)
Block(7,37,6,ICE:0)
Block(7,37,7,ICE:0)
Block(7,37,8,ICE:0)
Block(7,38,-1,PACKED_ICE:0)
Block(7,38,0,PACKED_ICE:0)
Block(7,38,1,PACKED_ICE:0)
Block(7,38,2,PACKED_ICE:0)
Block(7,38,3,PACKED_ICE:0)
Block(7,38,4,ICE:0)
Block(7,38,5,ICE:0)
Block(7,38,6,ICE:0)
Block(7,38,7,ICE:0)
Block(7,38,8,ICE:0)
Block(7,39,-2,PACKED_ICE:0)
Block(7,39,-1,PACKED_ICE:0)
Block(7,39,0,PACKED_ICE:0)
Block(7,39,1,PACKED_ICE:0)
Block(7,39,2,PACKED_ICE:0)
Block(7,39,3,ICE:0)
Block(7,39,4,ICE:0)
Block(7,39,5,ICE:0)
Block(7,39,6,ICE:0)
Block(7,39,7,ICE:0)
Block(7,39,8,ICE:0)
Block(7,40,-2,PACKED_ICE:0)
Block(7,40,-1,PACKED_ICE:0)
Block(7,40,0,PACKED_ICE:0)
Block(7,40,1,PACKED_ICE:0)
Block(7,40,2,ICE:0)
Block(7,40,3,ICE:0)
Block(7,40,4,ICE:0)
Block(7,40,5,ICE:0)
Block(7,40,6,ICE:0)
Block(7,40,7,ICE:0)
Block(7,40,8,ICE:0)
Block(7,41,-3,PACKED_ICE:0)
Block(7,41,-2,PACKED_ICE:0)
Block(7,41,-1,PACKED_ICE:0)
Block(7,41,0,ICE:0)
Block(7,41,1,ICE:0)
Block(7,41,2,ICE:0)
Block(7,41,3,ICE:0)
Block(7,41,4,ICE:0)
Block(7,41,5,ICE:0)
Block(7,41,6,ICE:0)
Block(7,41,7,ICE:0)
Block(7,41,8,ICE:0)
Block(7,42,-4,PACKED_ICE:0)
Block(7,42,-3,PACKED_ICE:0)
Block(7,42,-2,ICE:0)
Block(7,42,-1,ICE:0)
Block(7,42,0,ICE:0)
Block(7,42,1,ICE:0)
Block(7,42,2,ICE:0)
Block(7,42,3,ICE:0)
Block(7,42,4,ICE:0)
Block(7,42,5,ICE:0)
Block(7,42,6,ICE:0)
Block(7,42,7,ICE:0)
Block(7,43,-4,PACKED_ICE:0)
Block(7,43,-3,ICE:0)
Block(7,43,-2,ICE:0)
Block(7,43,-1,ICE:0)
Block(7,43,0,ICE:0)
Block(7,43,1,ICE:0)
Block(7,43,2,ICE:0)
Block(7,43,3,ICE:0)
Block(7,43,4,ICE:0)
Block(7,43,5,ICE:0)
Block(7,43,6,ICE:0)
Block(7,44,-5,PACKED_ICE:0)
Block(7,44,-4,PACKED_ICE:0)
Block(7,44,-3,ICE:0)
Block(7,44,-2,ICE:0)
Block(7,44,-1,ICE:0)
Block(7,44,0,ICE:0)
Block(7,44,1,ICE:0)
Block(7,44,2,ICE:0)
Block(7,44,3,ICE:0)
Block(7,44,4,ICE:0)
Block(7,44,5,ICE:0)
Block(7,45,-6,PACKED_ICE:0)
Block(7,45,-5,PACKED_ICE:0)
Block(7,45,-4,ICE:0)
Block(7,45,-3,ICE:0)
Block(7,45,-2,ICE:0)
Block(7,45,-1,ICE:0)
Block(7,45,0,ICE:0)
Block(7,45,1,ICE:0)
Block(7,45,2,ICE:0)
Block(7,45,3,ICE:0)
Block(7,45,4,ICE:0)
Block(7,46,-6,PACKED_ICE:0)
Block(7,46,-5,PACKED_ICE:0)
Block(7,46,-4,ICE:0)
Block(7,46,-3,ICE:0)
Block(7,46,-2,ICE:0)
Block(7,46,-1,ICE:0)
Block(7,46,0,ICE:0)
Block(7,46,1,ICE:0)
Block(7,46,2,ICE:0)
Block(7,46,3,ICE:0)
Block(7,46,4,ICE:0)
Block(7,47,-7,PACKED_ICE:0)
Block(7,47,-6,PACKED_ICE:0)
Block(7,47,-5,ICE:0)
Block(7,47,-4,ICE:0)
Block(7,47,-3,ICE:0)
Block(7,47,-2,ICE:0)
Block(7,47,-1,ICE:0)
Block(7,47,0,ICE:0)
Block(7,47,1,ICE:0)
Block(7,47,2,ICE:0)
Block(7,47,3,ICE:0)
Block(7,48,-7,PACKED_ICE:0)
Block(7,48,-6,ICE:0)
Block(7,48,-5,ICE:0)
Block(7,48,-4,ICE:0)
Block(7,48,-3,ICE:0)
Block(7,48,-2,ICE:0)
Block(7,48,-1,ICE:0)
Block(7,48,0,ICE:0)
Block(7,48,1,ICE:0)
Block(7,48,2,ICE:0)
Block(7,49,-7,PACKED_ICE:0)
Block(7,49,-6,ICE:0)
Block(7,49,-5,ICE:0)
Block(7,49,-4,ICE:0)
Block(7,49,-3,ICE:0)
Block(7,49,-2,ICE:0)
Block(7,49,-1,ICE:0)
Block(7,49,0,ICE:0)
Block(7,49,1,ICE:0)
Block(7,50,-7,ICE:0)
Block(7,50,-6,ICE:0)
Block(7,50,-5,ICE:0)
Block(7,50,-4,ICE:0)
Block(7,50,-3,ICE:0)
Block(7,50,-2,ICE:0)
Block(7,50,-1,ICE:0)
Block(7,50,0,ICE:0)
Block(7,51,-7,ICE:0)
Block(7,51,-6,ICE:0)
Block(7,51,-5,ICE:0)
Block(7,51,-4,ICE:0)
Block(7,51,-3,ICE:0)
Block(7,51,-2,ICE:0)
Block(7,51,-1,ICE:0)
Block(7,52,-7,ICE:0)
Block(7,52,-6,ICE:0)
Block(7,52,-5,ICE:0)
Block(7,52,-4,ICE:0)
Block(7,52,-3,ICE:0)
Block(7,52,-2,ICE:0)
Block(7,53,-7,ICE:0)
Block(7,53,-6,ICE:0)
Block(7,53,-5,ICE:0)
Block(7,53,-4,ICE:0)
Block(7,53,-3,ICE:0)
Block(7,54,-7,ICE:0)
Block(7,54,-6,ICE:0)
Block(7,54,-5,ICE:0)
Block(7,54,-4,ICE:0)
Block(7,55,-7,ICE:0)
Block(7,55,-6,ICE:0)
Block(7,55,-5,ICE:0)
Block(7,56,-7,ICE:0)
Block(7,56,-6,ICE:0)
Block(7,57,-7,ICE:0)
Block(7,57,-6,ICE:0)
Block(7,58,-7,ICE:0)

#######################################################################
# +-----------------------------------------------------------------+ #
# |                             Branches                            | #
# +-----------------------------------------------------------------+ #
#######################################################################


#######################################################################
# +-----------------------------------------------------------------+ #
# |                             Entities                            | #
# +-----------------------------------------------------------------+ #
#######################################################################


#######################################################################
# +-----------------------------------------------------------------+ #
# |                            Particles                            | #
# +-----------------------------------------------------------------+ #
#######################################################################


#######################################################################
# +-----------------------------------------------------------------+ #
# |                             Spawners                            | #
# +-----------------------------------------------------------------+ #
#######################################################################


#######################################################################
# +-----------------------------------------------------------------+ #
# |                             ModData                             | #
# +-----------------------------------------------------------------+ #
#######################################################################

