
#######################################################################
# +-----------------------------------------------------------------+ #
# |                            BO4 object                           | #
# +-----------------------------------------------------------------+ #
#######################################################################

Author: NLBlackEagle

Description: No description given

SettingsMode: WriteDisable


#######################################################################
# +-----------------------------------------------------------------+ #
# |                          Main settings                          | #
# +-----------------------------------------------------------------+ #
#######################################################################

Frequency: 0

SpawnHeight: highestBlock

UseCenterForHighestBlock: true

##############################
# Height Limits for the BO4. #
##############################

MinHeight: 0

MaxHeight: 255

InheritBO3: 

InheritBO3Rotation: NORTH

OverrideChildSettings: true

OverrideParentHeight: false

CanOverride: true

BranchFrequency: 0

BranchFrequencyGroup: 

MustBeBelowOther: false

MustBeInside: 

CannotBeInside: 

ReplacesBO3: 

MustBeInsideWorldBorders: false

CanSpawnOnWater: true

SpawnOnWaterOnly: false

SpawnUnderWater: false

SpawnAtWaterLevel: false

HeightOffset: 0

RemoveAir: true

ReplaceAbove: 

ReplaceBelow: 

ReplaceWithBiomeBlocks: true

ReplaceWithSurfaceBlock: GRASS

ReplaceWithGroundBlock: DIRT

ReplaceWithStoneBlock: STONE

SmoothRadius: 0

SmoothHeightOffset: 0

SmoothStartTop: false

SmoothStartWood: false

SmoothingSurfaceBlock: 

SmoothingGroundBlock: 

BO3Group: 

IsSpawnPoint: false

DoReplaceBlocks: true


#######################################################################
# +-----------------------------------------------------------------+ #
# |                              Blocks                             | #
# +-----------------------------------------------------------------+ #
#######################################################################

Block(-8,25,8,PACKED_ICE:0)
Block(-8,26,7,PACKED_ICE:0)
Block(-8,26,8,PACKED_ICE:0)
Block(-8,27,7,PACKED_ICE:0)
Block(-8,27,8,PACKED_ICE:0)
Block(-8,28,6,PACKED_ICE:0)
Block(-8,28,7,PACKED_ICE:0)
Block(-8,28,8,PACKED_ICE:0)
Block(-8,29,6,PACKED_ICE:0)
Block(-8,29,7,PACKED_ICE:0)
Block(-8,29,8,PACKED_ICE:0)
Block(-8,30,5,PACKED_ICE:0)
Block(-8,30,6,PACKED_ICE:0)
Block(-8,30,7,PACKED_ICE:0)
Block(-8,30,8,PACKED_ICE:0)
Block(-8,31,4,PACKED_ICE:0)
Block(-8,31,5,PACKED_ICE:0)
Block(-8,31,6,PACKED_ICE:0)
Block(-8,31,7,PACKED_ICE:0)
Block(-8,31,8,PACKED_ICE:0)
Block(-8,32,4,PACKED_ICE:0)
Block(-8,32,5,PACKED_ICE:0)
Block(-8,32,6,PACKED_ICE:0)
Block(-8,32,7,PACKED_ICE:0)
Block(-8,32,8,ICE:0)
Block(-8,33,3,PACKED_ICE:0)
Block(-8,33,4,PACKED_ICE:0)
Block(-8,33,5,PACKED_ICE:0)
Block(-8,33,6,PACKED_ICE:0)
Block(-8,33,7,ICE:0)
Block(-8,33,8,ICE:0)
Block(-8,34,2,PACKED_ICE:0)
Block(-8,34,3,PACKED_ICE:0)
Block(-8,34,4,PACKED_ICE:0)
Block(-8,34,5,PACKED_ICE:0)
Block(-8,34,6,PACKED_ICE:0)
Block(-8,34,7,ICE:0)
Block(-8,34,8,ICE:0)
Block(-8,35,2,PACKED_ICE:0)
Block(-8,35,3,PACKED_ICE:0)
Block(-8,35,4,PACKED_ICE:0)
Block(-8,35,5,ICE:0)
Block(-8,35,6,ICE:0)
Block(-8,35,7,ICE:0)
Block(-8,35,8,ICE:0)
Block(-8,36,1,PACKED_ICE:0)
Block(-8,36,2,PACKED_ICE:0)
Block(-8,36,3,PACKED_ICE:0)
Block(-8,36,4,ICE:0)
Block(-8,36,5,ICE:0)
Block(-8,36,6,ICE:0)
Block(-8,36,7,ICE:0)
Block(-8,36,8,ICE:0)
Block(-8,37,0,PACKED_ICE:0)
Block(-8,37,1,PACKED_ICE:0)
Block(-8,37,2,PACKED_ICE:0)
Block(-8,37,3,PACKED_ICE:0)
Block(-8,37,4,ICE:0)
Block(-8,37,5,ICE:0)
Block(-8,37,6,ICE:0)
Block(-8,37,7,ICE:0)
Block(-8,37,8,ICE:0)
Block(-8,38,0,PACKED_ICE:0)
Block(-8,38,1,PACKED_ICE:0)
Block(-8,38,2,PACKED_ICE:0)
Block(-8,38,3,ICE:0)
Block(-8,38,4,ICE:0)
Block(-8,38,5,ICE:0)
Block(-8,38,6,ICE:0)
Block(-8,38,7,ICE:0)
Block(-8,38,8,ICE:0)
Block(-8,39,-1,PACKED_ICE:0)
Block(-8,39,0,PACKED_ICE:0)
Block(-8,39,1,PACKED_ICE:0)
Block(-8,39,2,PACKED_ICE:0)
Block(-8,39,3,ICE:0)
Block(-8,39,4,ICE:0)
Block(-8,39,5,ICE:0)
Block(-8,39,6,ICE:0)
Block(-8,39,7,ICE:0)
Block(-8,39,8,ICE:0)
Block(-8,40,-2,PACKED_ICE:0)
Block(-8,40,-1,PACKED_ICE:0)
Block(-8,40,0,PACKED_ICE:0)
Block(-8,40,1,PACKED_ICE:0)
Block(-8,40,2,ICE:0)
Block(-8,40,3,ICE:0)
Block(-8,40,4,ICE:0)
Block(-8,40,5,ICE:0)
Block(-8,40,6,ICE:0)
Block(-8,40,7,ICE:0)
Block(-8,40,8,ICE:0)
Block(-8,41,-2,PACKED_ICE:0)
Block(-8,41,-1,ICE:0)
Block(-8,41,0,ICE:0)
Block(-8,41,1,ICE:0)
Block(-8,41,2,ICE:0)
Block(-8,41,3,ICE:0)
Block(-8,41,4,ICE:0)
Block(-8,41,5,ICE:0)
Block(-8,41,6,ICE:0)
Block(-8,41,7,ICE:0)
Block(-8,41,8,ICE:0)
Block(-8,42,-3,PACKED_ICE:0)
Block(-8,42,-2,ICE:0)
Block(-8,42,-1,ICE:0)
Block(-8,42,0,ICE:0)
Block(-8,42,1,ICE:0)
Block(-8,42,2,ICE:0)
Block(-8,42,3,ICE:0)
Block(-8,42,4,ICE:0)
Block(-8,42,5,ICE:0)
Block(-8,42,6,ICE:0)
Block(-8,42,7,ICE:0)
Block(-8,43,-4,PACKED_ICE:0)
Block(-8,43,-3,ICE:0)
Block(-8,43,-2,ICE:0)
Block(-8,43,-1,ICE:0)
Block(-8,43,0,ICE:0)
Block(-8,43,1,ICE:0)
Block(-8,43,2,ICE:0)
Block(-8,43,3,ICE:0)
Block(-8,43,4,ICE:0)
Block(-8,43,5,ICE:0)
Block(-8,43,6,ICE:0)
Block(-8,44,-4,ICE:0)
Block(-8,44,-3,ICE:0)
Block(-8,44,-2,ICE:0)
Block(-8,44,-1,ICE:0)
Block(-8,44,0,ICE:0)
Block(-8,44,1,ICE:0)
Block(-8,44,2,ICE:0)
Block(-8,44,3,ICE:0)
Block(-8,44,4,ICE:0)
Block(-8,44,5,ICE:0)
Block(-8,45,-5,PACKED_ICE:0)
Block(-8,45,-4,ICE:0)
Block(-8,45,-3,ICE:0)
Block(-8,45,-2,ICE:0)
Block(-8,45,-1,ICE:0)
Block(-8,45,0,ICE:0)
Block(-8,45,1,ICE:0)
Block(-8,45,2,ICE:0)
Block(-8,45,3,ICE:0)
Block(-8,45,4,ICE:0)
Block(-8,46,-6,PACKED_ICE:0)
Block(-8,46,-5,PACKED_ICE:0)
Block(-8,46,-4,ICE:0)
Block(-8,46,-3,ICE:0)
Block(-8,46,-2,ICE:0)
Block(-8,46,-1,ICE:0)
Block(-8,46,0,ICE:0)
Block(-8,46,1,ICE:0)
Block(-8,46,2,ICE:0)
Block(-8,46,3,ICE:0)
Block(-8,47,-6,PACKED_ICE:0)
Block(-8,47,-5,ICE:0)
Block(-8,47,-4,ICE:0)
Block(-8,47,-3,ICE:0)
Block(-8,47,-2,ICE:0)
Block(-8,47,-1,ICE:0)
Block(-8,47,0,ICE:0)
Block(-8,47,1,ICE:0)
Block(-8,47,2,ICE:0)
Block(-8,48,-7,PACKED_ICE:0)
Block(-8,48,-6,ICE:0)
Block(-8,48,-5,ICE:0)
Block(-8,48,-4,ICE:0)
Block(-8,48,-3,ICE:0)
Block(-8,48,-2,ICE:0)
Block(-8,48,-1,ICE:0)
Block(-8,48,0,ICE:0)
Block(-8,48,1,ICE:0)
Block(-8,48,2,ICE:0)
Block(-8,49,-7,ICE:0)
Block(-8,49,-6,ICE:0)
Block(-8,49,-5,ICE:0)
Block(-8,49,-4,ICE:0)
Block(-8,49,-3,ICE:0)
Block(-8,49,-2,ICE:0)
Block(-8,49,-1,ICE:0)
Block(-8,49,0,ICE:0)
Block(-8,49,1,ICE:0)
Block(-8,50,-7,ICE:0)
Block(-8,50,-6,ICE:0)
Block(-8,50,-5,ICE:0)
Block(-8,50,-4,ICE:0)
Block(-8,50,-3,ICE:0)
Block(-8,50,-2,ICE:0)
Block(-8,50,-1,ICE:0)
Block(-8,50,0,ICE:0)
Block(-8,51,-7,ICE:0)
Block(-8,51,-6,ICE:0)
Block(-8,51,-5,ICE:0)
Block(-8,51,-4,ICE:0)
Block(-8,51,-3,ICE:0)
Block(-8,51,-2,ICE:0)
Block(-8,51,-1,ICE:0)
Block(-8,52,-7,ICE:0)
Block(-8,52,-6,ICE:0)
Block(-8,52,-5,ICE:0)
Block(-8,52,-4,ICE:0)
Block(-8,52,-3,ICE:0)
Block(-8,52,-2,ICE:0)
Block(-8,53,-7,ICE:0)
Block(-8,53,-6,ICE:0)
Block(-8,53,-5,ICE:0)
Block(-8,53,-4,ICE:0)
Block(-8,53,-3,ICE:0)
Block(-8,54,-7,ICE:0)
Block(-8,54,-6,ICE:0)
Block(-8,54,-5,ICE:0)
Block(-8,54,-4,ICE:0)
Block(-8,55,-7,ICE:0)
Block(-8,55,-6,ICE:0)
Block(-8,55,-5,ICE:0)
Block(-8,56,-7,ICE:0)
Block(-8,56,-6,ICE:0)
Block(-8,57,-7,ICE:0)
Block(-7,26,8,PACKED_ICE:0)
Block(-7,27,7,PACKED_ICE:0)
Block(-7,27,8,PACKED_ICE:0)
Block(-7,28,7,PACKED_ICE:0)
Block(-7,28,8,PACKED_ICE:0)
Block(-7,29,6,PACKED_ICE:0)
Block(-7,29,7,PACKED_ICE:0)
Block(-7,29,8,PACKED_ICE:0)
Block(-7,30,5,PACKED_ICE:0)
Block(-7,30,6,PACKED_ICE:0)
Block(-7,30,7,PACKED_ICE:0)
Block(-7,30,8,PACKED_ICE:0)
Block(-7,31,5,PACKED_ICE:0)
Block(-7,31,6,PACKED_ICE:0)
Block(-7,31,7,PACKED_ICE:0)
Block(-7,31,8,ICE:0)
Block(-7,32,4,PACKED_ICE:0)
Block(-7,32,5,PACKED_ICE:0)
Block(-7,32,6,PACKED_ICE:0)
Block(-7,32,7,ICE:0)
Block(-7,32,8,ICE:0)
Block(-7,33,3,PACKED_ICE:0)
Block(-7,33,4,PACKED_ICE:0)
Block(-7,33,5,PACKED_ICE:0)
Block(-7,33,6,PACKED_ICE:0)
Block(-7,33,7,ICE:0)
Block(-7,33,8,ICE:0)
Block(-7,34,3,PACKED_ICE:0)
Block(-7,34,4,PACKED_ICE:0)
Block(-7,34,5,PACKED_ICE:0)
Block(-7,34,6,ICE:0)
Block(-7,34,7,ICE:0)
Block(-7,34,8,ICE:0)
Block(-7,35,2,PACKED_ICE:0)
Block(-7,35,3,PACKED_ICE:0)
Block(-7,35,4,PACKED_ICE:0)
Block(-7,35,5,ICE:0)
Block(-7,35,6,ICE:0)
Block(-7,35,7,ICE:0)
Block(-7,35,8,ICE:0)
Block(-7,36,2,PACKED_ICE:0)
Block(-7,36,3,PACKED_ICE:0)
Block(-7,36,4,ICE:0)
Block(-7,36,5,ICE:0)
Block(-7,36,6,ICE:0)
Block(-7,36,7,ICE:0)
Block(-7,36,8,ICE:0)
Block(-7,37,1,PACKED_ICE:0)
Block(-7,37,2,PACKED_ICE:0)
Block(-7,37,3,ICE:0)
Block(-7,37,4,ICE:0)
Block(-7,37,5,ICE:0)
Block(-7,37,6,ICE:0)
Block(-7,37,7,ICE:0)
Block(-7,37,8,ICE:0)
Block(-7,38,0,PACKED_ICE:0)
Block(-7,38,1,PACKED_ICE:0)
Block(-7,38,2,PACKED_ICE:0)
Block(-7,38,3,ICE:0)
Block(-7,38,4,ICE:0)
Block(-7,38,5,ICE:0)
Block(-7,38,6,ICE:0)
Block(-7,38,7,ICE:0)
Block(-7,38,8,ICE:0)
Block(-7,39,0,PACKED_ICE:0)
Block(-7,39,1,PACKED_ICE:0)
Block(-7,39,2,PACKED_ICE:0)
Block(-7,39,3,ICE:0)
Block(-7,39,4,ICE:0)
Block(-7,39,5,ICE:0)
Block(-7,39,6,ICE:0)
Block(-7,39,7,ICE:0)
Block(-7,39,8,ICE:0)
Block(-7,40,-1,PACKED_ICE:0)
Block(-7,40,0,PACKED_ICE:0)
Block(-7,40,1,PACKED_ICE:0)
Block(-7,40,2,PACKED_ICE:0)
Block(-7,40,3,ICE:0)
Block(-7,40,4,ICE:0)
Block(-7,40,5,ICE:0)
Block(-7,40,6,ICE:0)
Block(-7,40,7,ICE:0)
Block(-7,40,8,ICE:0)
Block(-7,41,-2,PACKED_ICE:0)
Block(-7,41,-1,ICE:0)
Block(-7,41,0,ICE:0)
Block(-7,41,1,ICE:0)
Block(-7,41,2,ICE:0)
Block(-7,41,3,ICE:0)
Block(-7,41,4,ICE:0)
Block(-7,41,5,ICE:0)
Block(-7,41,6,ICE:0)
Block(-7,41,7,ICE:0)
Block(-7,41,8,ICE:0)
Block(-7,42,-2,ICE:0)
Block(-7,42,-1,ICE:0)
Block(-7,42,0,ICE:0)
Block(-7,42,1,ICE:0)
Block(-7,42,2,ICE:0)
Block(-7,42,3,ICE:0)
Block(-7,42,4,ICE:0)
Block(-7,42,5,ICE:0)
Block(-7,42,6,ICE:0)
Block(-7,42,7,ICE:0)
Block(-7,43,-3,ICE:0)
Block(-7,43,-2,ICE:0)
Block(-7,43,-1,ICE:0)
Block(-7,43,0,ICE:0)
Block(-7,43,1,ICE:0)
Block(-7,43,2,ICE:0)
Block(-7,43,3,ICE:0)
Block(-7,43,4,ICE:0)
Block(-7,43,5,ICE:0)
Block(-7,43,6,ICE:0)
Block(-7,44,-4,ICE:0)
Block(-7,44,-3,ICE:0)
Block(-7,44,-2,ICE:0)
Block(-7,44,-1,ICE:0)
Block(-7,44,0,ICE:0)
Block(-7,44,1,ICE:0)
Block(-7,44,2,ICE:0)
Block(-7,44,3,ICE:0)
Block(-7,44,4,ICE:0)
Block(-7,44,5,ICE:0)
Block(-7,45,-4,ICE:0)
Block(-7,45,-3,ICE:0)
Block(-7,45,-2,ICE:0)
Block(-7,45,-1,ICE:0)
Block(-7,45,0,ICE:0)
Block(-7,45,1,ICE:0)
Block(-7,45,2,ICE:0)
Block(-7,45,3,ICE:0)
Block(-7,45,4,ICE:0)
Block(-7,46,-5,PACKED_ICE:0)
Block(-7,46,-4,ICE:0)
Block(-7,46,-3,ICE:0)
Block(-7,46,-2,ICE:0)
Block(-7,46,-1,ICE:0)
Block(-7,46,0,ICE:0)
Block(-7,46,1,ICE:0)
Block(-7,46,2,ICE:0)
Block(-7,46,3,ICE:0)
Block(-7,47,-6,PACKED_ICE:0)
Block(-7,47,-5,ICE:0)
Block(-7,47,-4,ICE:0)
Block(-7,47,-3,ICE:0)
Block(-7,47,-2,ICE:0)
Block(-7,47,-1,ICE:0)
Block(-7,47,0,ICE:0)
Block(-7,47,1,ICE:0)
Block(-7,47,2,ICE:0)
Block(-7,48,-6,ICE:0)
Block(-7,48,-5,ICE:0)
Block(-7,48,-4,ICE:0)
Block(-7,48,-3,ICE:0)
Block(-7,48,-2,ICE:0)
Block(-7,48,-1,ICE:0)
Block(-7,48,0,ICE:0)
Block(-7,48,1,ICE:0)
Block(-7,49,-7,ICE:0)
Block(-7,49,-6,ICE:0)
Block(-7,49,-5,ICE:0)
Block(-7,49,-4,ICE:0)
Block(-7,49,-3,ICE:0)
Block(-7,49,-2,ICE:0)
Block(-7,49,-1,ICE:0)
Block(-7,49,0,ICE:0)
Block(-7,50,-7,ICE:0)
Block(-7,50,-6,ICE:0)
Block(-7,50,-5,ICE:0)
Block(-7,50,-4,ICE:0)
Block(-7,50,-3,ICE:0)
Block(-7,50,-2,ICE:0)
Block(-7,50,-1,ICE:0)
Block(-7,51,-7,ICE:0)
Block(-7,51,-6,ICE:0)
Block(-7,51,-5,ICE:0)
Block(-7,51,-4,ICE:0)
Block(-7,51,-3,ICE:0)
Block(-7,51,-2,ICE:0)
Block(-7,52,-7,ICE:0)
Block(-7,52,-6,ICE:0)
Block(-7,52,-5,ICE:0)
Block(-7,52,-4,ICE:0)
Block(-7,52,-3,ICE:0)
Block(-7,53,-7,ICE:0)
Block(-7,53,-6,ICE:0)
Block(-7,53,-5,ICE:0)
Block(-7,54,-7,ICE:0)
Block(-7,54,-6,ICE:0)
Block(-7,55,-7,ICE:0)
Block(-6,27,8,PACKED_ICE:0)
Block(-6,28,7,PACKED_ICE:0)
Block(-6,28,8,PACKED_ICE:0)
Block(-6,29,7,PACKED_ICE:0)
Block(-6,29,8,PACKED_ICE:0)
Block(-6,30,6,PACKED_ICE:0)
Block(-6,30,7,PACKED_ICE:0)
Block(-6,30,8,PACKED_ICE:0)
Block(-6,31,5,PACKED_ICE:0)
Block(-6,31,6,PACKED_ICE:0)
Block(-6,31,7,PACKED_ICE:0)
Block(-6,31,8,ICE:0)
Block(-6,32,5,PACKED_ICE:0)
Block(-6,32,6,PACKED_ICE:0)
Block(-6,32,7,ICE:0)
Block(-6,32,8,ICE:0)
Block(-6,33,4,PACKED_ICE:0)
Block(-6,33,5,PACKED_ICE:0)
Block(-6,33,6,ICE:0)
Block(-6,33,7,ICE:0)
Block(-6,33,8,ICE:0)
Block(-6,34,3,PACKED_ICE:0)
Block(-6,34,4,PACKED_ICE:0)
Block(-6,34,5,PACKED_ICE:0)
Block(-6,34,6,ICE:0)
Block(-6,34,7,ICE:0)
Block(-6,34,8,ICE:0)
Block(-6,35,3,PACKED_ICE:0)
Block(-6,35,4,PACKED_ICE:0)
Block(-6,35,5,ICE:0)
Block(-6,35,6,ICE:0)
Block(-6,35,7,ICE:0)
Block(-6,35,8,ICE:0)
Block(-6,36,2,PACKED_ICE:0)
Block(-6,36,3,PACKED_ICE:0)
Block(-6,36,4,ICE:0)
Block(-6,36,5,ICE:0)
Block(-6,36,6,ICE:0)
Block(-6,36,7,ICE:0)
Block(-6,36,8,ICE:0)
Block(-6,37,1,PACKED_ICE:0)
Block(-6,37,2,PACKED_ICE:0)
Block(-6,37,3,ICE:0)
Block(-6,37,4,ICE:0)
Block(-6,37,5,ICE:0)
Block(-6,37,6,ICE:0)
Block(-6,37,7,ICE:0)
Block(-6,37,8,ICE:0)
Block(-6,38,1,PACKED_ICE:0)
Block(-6,38,2,PACKED_ICE:0)
Block(-6,38,3,ICE:0)
Block(-6,38,4,ICE:0)
Block(-6,38,5,ICE:0)
Block(-6,38,6,ICE:0)
Block(-6,38,7,ICE:0)
Block(-6,38,8,ICE:0)
Block(-6,39,0,PACKED_ICE:0)
Block(-6,39,1,PACKED_ICE:0)
Block(-6,39,2,PACKED_ICE:0)
Block(-6,39,3,ICE:0)
Block(-6,39,4,ICE:0)
Block(-6,39,5,ICE:0)
Block(-6,39,6,ICE:0)
Block(-6,39,7,ICE:0)
Block(-6,39,8,ICE:0)
Block(-6,40,0,PACKED_ICE:0)
Block(-6,40,1,PACKED_ICE:0)
Block(-6,40,2,PACKED_ICE:0)
Block(-6,40,3,ICE:0)
Block(-6,40,4,ICE:0)
Block(-6,40,5,ICE:0)
Block(-6,40,6,ICE:0)
Block(-6,40,7,ICE:0)
Block(-6,41,-1,ICE:0)
Block(-6,41,0,ICE:0)
Block(-6,41,1,ICE:0)
Block(-6,41,2,ICE:0)
Block(-6,41,3,ICE:0)
Block(-6,41,4,ICE:0)
Block(-6,41,5,ICE:0)
Block(-6,41,6,ICE:0)
Block(-6,42,-2,ICE:0)
Block(-6,42,-1,ICE:0)
Block(-6,42,0,ICE:0)
Block(-6,42,1,ICE:0)
Block(-6,42,2,ICE:0)
Block(-6,42,3,ICE:0)
Block(-6,42,4,ICE:0)
Block(-6,42,5,ICE:0)
Block(-6,43,-2,ICE:0)
Block(-6,43,-1,ICE:0)
Block(-6,43,0,ICE:0)
Block(-6,43,1,ICE:0)
Block(-6,43,2,ICE:0)
Block(-6,43,3,ICE:0)
Block(-6,43,4,ICE:0)
Block(-6,44,-3,ICE:0)
Block(-6,44,-2,ICE:0)
Block(-6,44,-1,ICE:0)
Block(-6,44,0,ICE:0)
Block(-6,44,1,ICE:0)
Block(-6,44,2,ICE:0)
Block(-6,44,3,ICE:0)
Block(-6,45,-4,ICE:0)
Block(-6,45,-3,ICE:0)
Block(-6,45,-2,ICE:0)
Block(-6,45,-1,ICE:0)
Block(-6,45,0,ICE:0)
Block(-6,45,1,ICE:0)
Block(-6,45,2,ICE:0)
Block(-6,46,-4,ICE:0)
Block(-6,46,-3,ICE:0)
Block(-6,46,-2,ICE:0)
Block(-6,46,-1,ICE:0)
Block(-6,46,0,ICE:0)
Block(-6,46,1,ICE:0)
Block(-6,47,-5,ICE:0)
Block(-6,47,-4,ICE:0)
Block(-6,47,-3,ICE:0)
Block(-6,47,-2,ICE:0)
Block(-6,47,-1,ICE:0)
Block(-6,47,0,ICE:0)
Block(-6,48,-6,ICE:0)
Block(-6,48,-5,ICE:0)
Block(-6,48,-4,ICE:0)
Block(-6,48,-3,ICE:0)
Block(-6,48,-2,ICE:0)
Block(-6,48,-1,ICE:0)
Block(-6,49,-6,ICE:0)
Block(-6,49,-5,ICE:0)
Block(-6,49,-4,ICE:0)
Block(-6,49,-3,ICE:0)
Block(-6,49,-2,ICE:0)
Block(-6,50,-7,ICE:0)
Block(-6,50,-6,ICE:0)
Block(-6,50,-5,ICE:0)
Block(-6,50,-4,ICE:0)
Block(-6,50,-3,ICE:0)
Block(-6,51,-7,ICE:0)
Block(-6,51,-6,ICE:0)
Block(-6,51,-5,ICE:0)
Block(-6,51,-4,ICE:0)
Block(-6,52,-7,ICE:0)
Block(-6,52,-6,ICE:0)
Block(-6,52,-5,ICE:0)
Block(-6,53,-7,ICE:0)
Block(-6,53,-6,ICE:0)
Block(-6,54,-7,ICE:0)
Block(-5,28,8,PACKED_ICE:0)
Block(-5,29,7,PACKED_ICE:0)
Block(-5,29,8,PACKED_ICE:0)
Block(-5,30,7,PACKED_ICE:0)
Block(-5,30,8,ICE:0)
Block(-5,31,6,PACKED_ICE:0)
Block(-5,31,7,PACKED_ICE:0)
Block(-5,31,8,ICE:0)
Block(-5,32,5,PACKED_ICE:0)
Block(-5,32,6,PACKED_ICE:0)
Block(-5,32,7,ICE:0)
Block(-5,32,8,ICE:0)
Block(-5,33,5,PACKED_ICE:0)
Block(-5,33,6,ICE:0)
Block(-5,33,7,ICE:0)
Block(-5,33,8,ICE:0)
Block(-5,34,4,PACKED_ICE:0)
Block(-5,34,5,PACKED_ICE:0)
Block(-5,34,6,ICE:0)
Block(-5,34,7,ICE:0)
Block(-5,34,8,ICE:0)
Block(-5,35,3,PACKED_ICE:0)
Block(-5,35,4,PACKED_ICE:0)
Block(-5,35,5,ICE:0)
Block(-5,35,6,ICE:0)
Block(-5,35,7,ICE:0)
Block(-5,35,8,ICE:0)
Block(-5,36,3,PACKED_ICE:0)
Block(-5,36,4,ICE:0)
Block(-5,36,5,ICE:0)
Block(-5,36,6,ICE:0)
Block(-5,36,7,ICE:0)
Block(-5,36,8,ICE:0)
Block(-5,37,2,PACKED_ICE:0)
Block(-5,37,3,ICE:0)
Block(-5,37,4,ICE:0)
Block(-5,37,5,ICE:0)
Block(-5,37,6,ICE:0)
Block(-5,37,7,ICE:0)
Block(-5,37,8,ICE:0)
Block(-5,38,1,PACKED_ICE:0)
Block(-5,38,2,PACKED_ICE:0)
Block(-5,38,3,ICE:0)
Block(-5,38,4,ICE:0)
Block(-5,38,5,ICE:0)
Block(-5,38,6,ICE:0)
Block(-5,38,7,ICE:0)
Block(-5,38,8,ICE:0)
Block(-5,39,1,PACKED_ICE:0)
Block(-5,39,2,PACKED_ICE:0)
Block(-5,39,3,ICE:0)
Block(-5,39,4,ICE:0)
Block(-5,39,5,ICE:0)
Block(-5,39,6,ICE:0)
Block(-5,39,7,ICE:0)
Block(-5,40,0,PACKED_ICE:0)
Block(-5,40,1,PACKED_ICE:0)
Block(-5,40,2,PACKED_ICE:0)
Block(-5,40,3,ICE:0)
Block(-5,40,4,ICE:0)
Block(-5,40,5,ICE:0)
Block(-5,40,6,ICE:0)
Block(-5,41,-1,PACKED_ICE:0)
Block(-5,41,0,ICE:0)
Block(-5,41,1,ICE:0)
Block(-5,41,2,ICE:0)
Block(-5,41,3,ICE:0)
Block(-5,41,4,ICE:0)
Block(-5,41,5,ICE:0)
Block(-5,42,-1,ICE:0)
Block(-5,42,0,ICE:0)
Block(-5,42,1,ICE:0)
Block(-5,42,2,ICE:0)
Block(-5,42,3,ICE:0)
Block(-5,42,4,ICE:0)
Block(-5,43,-2,ICE:0)
Block(-5,43,-1,ICE:0)
Block(-5,43,0,ICE:0)
Block(-5,43,1,ICE:0)
Block(-5,43,2,ICE:0)
Block(-5,43,3,ICE:0)
Block(-5,44,-2,ICE:0)
Block(-5,44,-1,ICE:0)
Block(-5,44,0,ICE:0)
Block(-5,44,1,ICE:0)
Block(-5,44,2,ICE:0)
Block(-5,45,-3,ICE:0)
Block(-5,45,-2,ICE:0)
Block(-5,45,-1,ICE:0)
Block(-5,45,0,ICE:0)
Block(-5,45,1,ICE:0)
Block(-5,46,-4,ICE:0)
Block(-5,46,-3,ICE:0)
Block(-5,46,-2,ICE:0)
Block(-5,46,-1,ICE:0)
Block(-5,46,0,ICE:0)
Block(-5,47,-4,ICE:0)
Block(-5,47,-3,ICE:0)
Block(-5,47,-2,ICE:0)
Block(-5,47,-1,ICE:0)
Block(-5,48,-5,ICE:0)
Block(-5,48,-4,ICE:0)
Block(-5,48,-3,ICE:0)
Block(-5,49,-6,ICE:0)
Block(-5,49,-5,ICE:0)
Block(-5,49,-4,ICE:0)
Block(-5,50,-6,ICE:0)
Block(-5,50,-5,ICE:0)
Block(-5,51,-7,ICE:0)
Block(-5,51,-6,ICE:0)
Block(-5,52,-7,ICE:0)
Block(-4,29,8,PACKED_ICE:0)
Block(-4,30,7,PACKED_ICE:0)
Block(-4,30,8,ICE:0)
Block(-4,31,7,PACKED_ICE:0)
Block(-4,31,8,ICE:0)
Block(-4,32,6,PACKED_ICE:0)
Block(-4,32,7,ICE:0)
Block(-4,32,8,ICE:0)
Block(-4,33,5,PACKED_ICE:0)
Block(-4,33,6,ICE:0)
Block(-4,33,7,ICE:0)
Block(-4,33,8,ICE:0)
Block(-4,34,5,PACKED_ICE:0)
Block(-4,34,6,ICE:0)
Block(-4,34,7,ICE:0)
Block(-4,34,8,ICE:0)
Block(-4,35,4,PACKED_ICE:0)
Block(-4,35,5,ICE:0)
Block(-4,35,6,ICE:0)
Block(-4,35,7,ICE:0)
Block(-4,35,8,ICE:0)
Block(-4,36,3,PACKED_ICE:0)
Block(-4,36,4,ICE:0)
Block(-4,36,5,ICE:0)
Block(-4,36,6,ICE:0)
Block(-4,36,7,ICE:0)
Block(-4,36,8,ICE:0)
Block(-4,37,3,PACKED_ICE:0)
Block(-4,37,4,ICE:0)
Block(-4,37,5,ICE:0)
Block(-4,37,6,ICE:0)
Block(-4,37,7,ICE:0)
Block(-4,38,2,PACKED_ICE:0)
Block(-4,38,3,ICE:0)
Block(-4,38,4,ICE:0)
Block(-4,38,5,ICE:0)
Block(-4,38,6,ICE:0)
Block(-4,39,1,PACKED_ICE:0)
Block(-4,39,2,PACKED_ICE:0)
Block(-4,39,3,ICE:0)
Block(-4,39,4,ICE:0)
Block(-4,39,5,ICE:0)
Block(-4,40,1,PACKED_ICE:0)
Block(-4,40,2,PACKED_ICE:0)
Block(-4,40,3,ICE:0)
Block(-4,40,4,ICE:0)
Block(-4,41,0,PACKED_ICE:0)
Block(-4,41,1,PACKED_ICE:0)
Block(-4,41,2,PACKED_ICE:0)
Block(-4,41,3,PACKED_ICE:0)
Block(-4,42,-1,ICE:0)
Block(-4,42,0,ICE:0)
Block(-4,42,1,ICE:0)
Block(-4,42,2,ICE:0)
Block(-4,43,-1,ICE:0)
Block(-4,43,0,ICE:0)
Block(-4,43,1,ICE:0)
Block(-4,44,-2,ICE:0)
Block(-4,44,-1,ICE:0)
Block(-4,44,0,ICE:0)
Block(-4,45,-3,ICE:0)
Block(-4,45,-2,ICE:0)
Block(-4,45,-1,ICE:0)
Block(-4,46,-3,ICE:0)
Block(-4,46,-2,ICE:0)
Block(-4,47,-4,ICE:0)
Block(-4,47,-3,ICE:0)
Block(-4,48,-4,ICE:0)
Block(-4,49,-5,ICE:0)
Block(-4,50,-6,ICE:0)
Block(-3,30,8,ICE:0)
Block(-3,31,7,PACKED_ICE:0)
Block(-3,31,8,ICE:0)
Block(-3,32,7,ICE:0)
Block(-3,32,8,ICE:0)
Block(-3,33,6,PACKED_ICE:0)
Block(-3,33,7,ICE:0)
Block(-3,33,8,ICE:0)
Block(-3,34,5,PACKED_ICE:0)
Block(-3,34,6,ICE:0)
Block(-3,34,7,ICE:0)
Block(-3,34,8,ICE:0)
Block(-3,35,5,PACKED_ICE:0)
Block(-3,35,6,ICE:0)
Block(-3,35,7,ICE:0)
Block(-3,35,8,ICE:0)
Block(-3,36,4,PACKED_ICE:0)
Block(-3,36,5,ICE:0)
Block(-3,36,6,ICE:0)
Block(-3,36,7,ICE:0)
Block(-3,37,3,PACKED_ICE:0)
Block(-3,37,4,ICE:0)
Block(-3,37,5,ICE:0)
Block(-3,37,6,ICE:0)
Block(-3,38,3,PACKED_ICE:0)
Block(-3,38,4,ICE:0)
Block(-3,38,5,ICE:0)
Block(-3,39,2,PACKED_ICE:0)
Block(-3,39,3,PACKED_ICE:0)
Block(-3,39,4,ICE:0)
Block(-3,40,1,PACKED_ICE:0)
Block(-3,40,2,PACKED_ICE:0)
Block(-3,40,3,PACKED_ICE:0)
Block(-3,41,1,PACKED_ICE:0)
Block(-3,41,2,PACKED_ICE:0)
Block(-3,42,0,PACKED_ICE:0)
Block(-3,43,-1,ICE:0)
Block(-2,31,8,ICE:0)
Block(-2,32,7,PACKED_ICE:0)
Block(-2,32,8,ICE:0)
Block(-2,33,7,ICE:0)
Block(-2,33,8,ICE:0)
Block(-2,34,6,PACKED_ICE:0)
Block(-2,34,7,ICE:0)
Block(-2,35,5,PACKED_ICE:0)
Block(-2,35,6,PACKED_ICE:0)
Block(-2,36,5,PACKED_ICE:0)
Block(-2,37,4,PACKED_ICE:0)
Block(-2,38,3,PACKED_ICE:0)
Block(-1,32,8,PACKED_ICE:0)
Block(-1,33,7,PACKED_ICE:0)

#######################################################################
# +-----------------------------------------------------------------+ #
# |                             Branches                            | #
# +-----------------------------------------------------------------+ #
#######################################################################

Branch(0,0,16,true,IceSpike_Huge_11C1R3,NORTH,100.0,0)

#######################################################################
# +-----------------------------------------------------------------+ #
# |                             Entities                            | #
# +-----------------------------------------------------------------+ #
#######################################################################


#######################################################################
# +-----------------------------------------------------------------+ #
# |                            Particles                            | #
# +-----------------------------------------------------------------+ #
#######################################################################


#######################################################################
# +-----------------------------------------------------------------+ #
# |                             Spawners                            | #
# +-----------------------------------------------------------------+ #
#######################################################################


#######################################################################
# +-----------------------------------------------------------------+ #
# |                             ModData                             | #
# +-----------------------------------------------------------------+ #
#######################################################################

