
#######################################################################
# +-----------------------------------------------------------------+ #
# |                            BO4 object                           | #
# +-----------------------------------------------------------------+ #
#######################################################################

Author: NLBlackEagle

Description: No description given

SettingsMode: WriteDisable


#######################################################################
# +-----------------------------------------------------------------+ #
# |                          Main settings                          | #
# +-----------------------------------------------------------------+ #
#######################################################################

Frequency: 0

SpawnHeight: highestBlock

UseCenterForHighestBlock: true

##############################
# Height Limits for the BO4. #
##############################

MinHeight: 0

MaxHeight: 255

InheritBO3: 

InheritBO3Rotation: NORTH

OverrideChildSettings: true

OverrideParentHeight: false

CanOverride: true

BranchFrequency: 0

BranchFrequencyGroup: 

MustBeBelowOther: false

MustBeInside: 

CannotBeInside: 

ReplacesBO3: 

MustBeInsideWorldBorders: false

CanSpawnOnWater: true

SpawnOnWaterOnly: false

SpawnUnderWater: false

SpawnAtWaterLevel: false

HeightOffset: 0

RemoveAir: true

ReplaceAbove: 

ReplaceBelow: 

ReplaceWithBiomeBlocks: true

ReplaceWithSurfaceBlock: GRASS

ReplaceWithGroundBlock: DIRT

ReplaceWithStoneBlock: STONE

SmoothRadius: 0

SmoothHeightOffset: 0

SmoothStartTop: false

SmoothStartWood: false

SmoothingSurfaceBlock: 

SmoothingGroundBlock: 

BO3Group: 

IsSpawnPoint: false

DoReplaceBlocks: true


#######################################################################
# +-----------------------------------------------------------------+ #
# |                              Blocks                             | #
# +-----------------------------------------------------------------+ #
#######################################################################

Block(-1,18,-7,SANDSTONE)
Block(-1,19,-7,SANDSTONE)
Block(-1,20,-7,SANDSTONE)
Block(-1,21,-7,SANDSTONE)
Block(-1,22,-7,SANDSTONE)
Block(-1,23,-7,SANDSTONE)
Block(0,15,-5,SANDSTONE)
Block(0,16,-6,SANDSTONE)
Block(0,16,-5,SANDSTONE)
Block(0,17,-7,SANDSTONE)
Block(0,17,-6,SANDSTONE)
Block(0,17,-5,SANDSTONE)
Block(0,18,-7,SANDSTONE)
Block(0,18,-6,SANDSTONE)
Block(0,18,-5,SANDSTONE)
Block(0,19,-7,SANDSTONE)
Block(0,19,-6,SANDSTONE)
Block(0,19,-5,SANDSTONE)
Block(0,20,-7,SANDSTONE)
Block(0,20,-6,SANDSTONE)
Block(0,20,-5,SANDSTONE)
Block(0,21,-7,SANDSTONE)
Block(0,21,-6,SANDSTONE)
Block(0,21,-5,SANDSTONE)
Block(0,22,-7,SANDSTONE)
Block(0,22,-6,SANDSTONE)
Block(0,23,-7,SANDSTONE)
Block(0,23,-6,SANDSTONE)
Block(0,24,-7,SANDSTONE)
Block(0,24,-6,OBSIDIAN)
Block(0,25,-7,SANDSTONE)
Block(0,25,-6,OBSIDIAN)
Block(0,26,-7,OBSIDIAN)
Block(0,26,-6,OBSIDIAN)
Block(0,27,-7,OBSIDIAN)
Block(0,27,-6,OBSIDIAN)
Block(0,28,-7,OBSIDIAN)
Block(0,28,-6,OBSIDIAN)
Block(0,29,-7,OBSIDIAN)
Block(0,29,-6,OBSIDIAN)
Block(0,30,-7,OBSIDIAN)
Block(0,31,-7,OBSIDIAN)
Block(0,32,-7,OBSIDIAN)
Block(0,33,-7,OBSIDIAN)
Block(0,34,-7,SANDSTONE)
Block(0,35,-7,SANDSTONE)
Block(0,36,-7,SANDSTONE)
Block(0,37,-7,SANDSTONE)
Block(1,13,-4,SANDSTONE)
Block(1,13,-3,SANDSTONE)
Block(1,14,-5,SANDSTONE)
Block(1,14,-4,SANDSTONE)
Block(1,14,-3,SANDSTONE)
Block(1,15,-6,SANDSTONE)
Block(1,15,-5,SANDSTONE)
Block(1,15,-4,SANDSTONE)
Block(1,15,-3,SANDSTONE)
Block(1,16,-7,SANDSTONE)
Block(1,16,-6,SANDSTONE)
Block(1,16,-5,SANDSTONE)
Block(1,16,-4,SANDSTONE)
Block(1,16,-3,SANDSTONE)
Block(1,17,-7,SANDSTONE)
Block(1,17,-6,SANDSTONE)
Block(1,17,-5,SANDSTONE)
Block(1,17,-4,SANDSTONE)
Block(1,17,-3,SANDSTONE)
Block(1,18,-7,SANDSTONE)
Block(1,18,-6,SANDSTONE)
Block(1,18,-5,SANDSTONE)
Block(1,18,-4,SANDSTONE)
Block(1,18,-3,SANDSTONE)
Block(1,19,-7,SANDSTONE)
Block(1,19,-6,SANDSTONE)
Block(1,19,-5,SANDSTONE)
Block(1,19,-4,SANDSTONE)
Block(1,20,-7,SANDSTONE)
Block(1,20,-6,SANDSTONE)
Block(1,20,-5,SANDSTONE)
Block(1,20,-4,SANDSTONE)
Block(1,21,-7,SANDSTONE)
Block(1,21,-6,SANDSTONE)
Block(1,21,-5,SANDSTONE)
Block(1,21,-4,OBSIDIAN)
Block(1,22,-7,SANDSTONE)
Block(1,22,-6,SANDSTONE)
Block(1,22,-5,SANDSTONE)
Block(1,22,-4,OBSIDIAN)
Block(1,23,-7,SANDSTONE)
Block(1,23,-6,SANDSTONE)
Block(1,23,-5,OBSIDIAN)
Block(1,23,-4,OBSIDIAN)
Block(1,24,-7,SANDSTONE)
Block(1,24,-6,OBSIDIAN)
Block(1,24,-5,OBSIDIAN)
Block(1,24,-4,OBSIDIAN)
Block(1,25,-7,OBSIDIAN)
Block(1,25,-6,OBSIDIAN)
Block(1,25,-5,OBSIDIAN)
Block(1,25,-4,OBSIDIAN)
Block(1,26,-7,OBSIDIAN)
Block(1,26,-6,OBSIDIAN)
Block(1,26,-5,OBSIDIAN)
Block(1,26,-4,OBSIDIAN)
Block(1,27,-7,OBSIDIAN)
Block(1,27,-6,OBSIDIAN)
Block(1,27,-5,OBSIDIAN)
Block(1,27,-4,OBSIDIAN)
Block(1,28,-7,OBSIDIAN)
Block(1,28,-6,OBSIDIAN)
Block(1,28,-5,OBSIDIAN)
Block(1,29,-7,OBSIDIAN)
Block(1,29,-6,OBSIDIAN)
Block(1,29,-5,OBSIDIAN)
Block(1,30,-7,OBSIDIAN)
Block(1,30,-6,OBSIDIAN)
Block(1,30,-5,OBSIDIAN)
Block(1,31,-7,OBSIDIAN)
Block(1,31,-6,OBSIDIAN)
Block(1,31,-5,OBSIDIAN)
Block(1,32,-7,OBSIDIAN)
Block(1,32,-6,OBSIDIAN)
Block(1,32,-5,SANDSTONE)
Block(1,33,-7,SANDSTONE)
Block(1,33,-6,SANDSTONE)
Block(1,33,-5,SANDSTONE)
Block(1,34,-7,SANDSTONE)
Block(1,34,-6,SANDSTONE)
Block(1,34,-5,SANDSTONE)
Block(1,35,-7,SANDSTONE)
Block(1,35,-6,SANDSTONE)
Block(1,35,-5,SANDSTONE)
Block(1,36,-7,SANDSTONE)
Block(1,36,-6,SANDSTONE)
Block(1,37,-7,SANDSTONE)
Block(1,37,-6,SANDSTONE)
Block(1,38,-7,SANDSTONE)
Block(1,38,-6,SANDSTONE)
Block(1,39,-7,SANDSTONE)
Block(1,39,-6,SANDSTONE)
Block(1,40,-7,SANDSTONE)
Block(1,40,-6,SANDSTONE)
Block(1,41,-7,SANDSTONE)
Block(2,10,-1,SANDSTONE)
Block(2,11,-3,SANDSTONE)
Block(2,11,-2,SANDSTONE)
Block(2,11,-1,SANDSTONE)
Block(2,12,-4,SANDSTONE)
Block(2,12,-3,SANDSTONE)
Block(2,12,-2,SANDSTONE)
Block(2,12,-1,SANDSTONE)
Block(2,13,-5,SANDSTONE)
Block(2,13,-4,SANDSTONE)
Block(2,13,-3,SANDSTONE)
Block(2,13,-2,SANDSTONE)
Block(2,13,-1,SANDSTONE)
Block(2,14,-7,SANDSTONE)
Block(2,14,-6,SANDSTONE)
Block(2,14,-5,SANDSTONE)
Block(2,14,-4,SANDSTONE)
Block(2,14,-3,SANDSTONE)
Block(2,14,-2,SANDSTONE)
Block(2,14,-1,SANDSTONE)
Block(2,15,-7,SANDSTONE)
Block(2,15,-6,SANDSTONE)
Block(2,15,-5,SANDSTONE)
Block(2,15,-4,SANDSTONE)
Block(2,15,-3,SANDSTONE)
Block(2,15,-2,SANDSTONE)
Block(2,15,-1,SANDSTONE)
Block(2,16,-7,SANDSTONE)
Block(2,16,-6,SANDSTONE)
Block(2,16,-5,SANDSTONE)
Block(2,16,-4,SANDSTONE)
Block(2,16,-3,SANDSTONE)
Block(2,16,-2,SANDSTONE)
Block(2,16,-1,SANDSTONE)
Block(2,17,-7,SANDSTONE)
Block(2,17,-6,SANDSTONE)
Block(2,17,-5,SANDSTONE)
Block(2,17,-4,SANDSTONE)
Block(2,17,-3,SANDSTONE)
Block(2,17,-2,SANDSTONE)
Block(2,18,-7,SANDSTONE)
Block(2,18,-6,SANDSTONE)
Block(2,18,-5,SANDSTONE)
Block(2,18,-4,SANDSTONE)
Block(2,18,-3,SANDSTONE)
Block(2,18,-2,SANDSTONE)
Block(2,19,-7,SANDSTONE)
Block(2,19,-6,SANDSTONE)
Block(2,19,-5,SANDSTONE)
Block(2,19,-4,OBSIDIAN)
Block(2,19,-3,OBSIDIAN)
Block(2,19,-2,OBSIDIAN)
Block(2,20,-7,SANDSTONE)
Block(2,20,-6,SANDSTONE)
Block(2,20,-5,SANDSTONE)
Block(2,20,-4,OBSIDIAN)
Block(2,20,-3,OBSIDIAN)
Block(2,20,-2,OBSIDIAN)
Block(2,21,-7,SANDSTONE)
Block(2,21,-6,SANDSTONE)
Block(2,21,-5,SANDSTONE)
Block(2,21,-4,OBSIDIAN)
Block(2,21,-3,OBSIDIAN)
Block(2,21,-2,OBSIDIAN)
Block(2,22,-7,SANDSTONE)
Block(2,22,-6,SANDSTONE)
Block(2,22,-5,OBSIDIAN)
Block(2,22,-4,OBSIDIAN)
Block(2,22,-3,OBSIDIAN)
Block(2,22,-2,OBSIDIAN)
Block(2,23,-7,SANDSTONE)
Block(2,23,-6,OBSIDIAN)
Block(2,23,-5,OBSIDIAN)
Block(2,23,-4,OBSIDIAN)
Block(2,23,-3,OBSIDIAN)
Block(2,23,-2,OBSIDIAN)
Block(2,24,-7,OBSIDIAN)
Block(2,24,-6,OBSIDIAN)
Block(2,24,-5,OBSIDIAN)
Block(2,24,-4,OBSIDIAN)
Block(2,24,-3,OBSIDIAN)
Block(2,24,-2,OBSIDIAN)
Block(2,25,-7,OBSIDIAN)
Block(2,25,-6,OBSIDIAN)
Block(2,25,-5,OBSIDIAN)
Block(2,25,-4,OBSIDIAN)
Block(2,25,-3,OBSIDIAN)
Block(2,26,-7,OBSIDIAN)
Block(2,26,-6,OBSIDIAN)
Block(2,26,-5,OBSIDIAN)
Block(2,26,-4,OBSIDIAN)
Block(2,26,-3,OBSIDIAN)
Block(2,27,-7,OBSIDIAN)
Block(2,27,-6,OBSIDIAN)
Block(2,27,-5,OBSIDIAN)
Block(2,27,-4,OBSIDIAN)
Block(2,27,-3,OBSIDIAN)
Block(2,28,-7,OBSIDIAN)
Block(2,28,-6,OBSIDIAN)
Block(2,28,-5,OBSIDIAN)
Block(2,28,-4,OBSIDIAN)
Block(2,28,-3,OBSIDIAN)
Block(2,29,-7,OBSIDIAN)
Block(2,29,-6,OBSIDIAN)
Block(2,29,-5,OBSIDIAN)
Block(2,29,-4,OBSIDIAN)
Block(2,29,-3,OBSIDIAN)
Block(2,30,-7,OBSIDIAN)
Block(2,30,-6,OBSIDIAN)
Block(2,30,-5,OBSIDIAN)
Block(2,30,-4,OBSIDIAN)
Block(2,30,-3,OBSIDIAN)
Block(2,31,-7,OBSIDIAN)
Block(2,31,-6,OBSIDIAN)
Block(2,31,-5,OBSIDIAN)
Block(2,31,-4,OBSIDIAN)
Block(2,31,-3,SANDSTONE)
Block(2,32,-7,OBSIDIAN)
Block(2,32,-6,SANDSTONE)
Block(2,32,-5,SANDSTONE)
Block(2,32,-4,SANDSTONE)
Block(2,32,-3,SANDSTONE)
Block(2,33,-7,SANDSTONE)
Block(2,33,-6,SANDSTONE)
Block(2,33,-5,SANDSTONE)
Block(2,33,-4,SANDSTONE)
Block(2,33,-3,SANDSTONE)
Block(2,34,-7,SANDSTONE)
Block(2,34,-6,SANDSTONE)
Block(2,34,-5,SANDSTONE)
Block(2,34,-4,SANDSTONE)
Block(2,35,-7,SANDSTONE)
Block(2,35,-6,SANDSTONE)
Block(2,35,-5,SANDSTONE)
Block(2,35,-4,SANDSTONE)
Block(2,36,-7,SANDSTONE)
Block(2,36,-6,SANDSTONE)
Block(2,36,-5,SANDSTONE)
Block(2,36,-4,SANDSTONE)
Block(2,37,-7,SANDSTONE)
Block(2,37,-6,SANDSTONE)
Block(2,37,-5,SANDSTONE)
Block(2,37,-4,SANDSTONE)
Block(2,38,-7,SANDSTONE)
Block(2,38,-6,SANDSTONE)
Block(2,38,-5,SANDSTONE)
Block(2,38,-4,SANDSTONE)
Block(2,39,-7,SANDSTONE)
Block(2,39,-6,SANDSTONE)
Block(2,39,-5,SANDSTONE)
Block(2,40,-7,SANDSTONE)
Block(2,40,-6,SANDSTONE)
Block(3,7,1,SANDSTONE)
Block(3,8,0,SANDSTONE)
Block(3,8,1,SANDSTONE)
Block(3,9,-1,SANDSTONE)
Block(3,9,0,SANDSTONE)
Block(3,9,1,SANDSTONE)
Block(3,10,-3,SANDSTONE)
Block(3,10,-2,SANDSTONE)
Block(3,10,-1,SANDSTONE)
Block(3,10,0,SANDSTONE)
Block(3,10,1,SANDSTONE)
Block(3,11,-4,SANDSTONE)
Block(3,11,-3,SANDSTONE)
Block(3,11,-2,SANDSTONE)
Block(3,11,-1,SANDSTONE)
Block(3,11,0,SANDSTONE)
Block(3,11,1,SANDSTONE)
Block(3,12,-5,SANDSTONE)
Block(3,12,-4,SANDSTONE)
Block(3,12,-3,SANDSTONE)
Block(3,12,-2,SANDSTONE)
Block(3,12,-1,SANDSTONE)
Block(3,12,0,SANDSTONE)
Block(3,12,1,SANDSTONE)
Block(3,13,-7,SANDSTONE)
Block(3,13,-6,SANDSTONE)
Block(3,13,-5,SANDSTONE)
Block(3,13,-4,SANDSTONE)
Block(3,13,-3,SANDSTONE)
Block(3,13,-2,SANDSTONE)
Block(3,13,-1,SANDSTONE)
Block(3,13,0,SANDSTONE)
Block(3,13,1,SANDSTONE)
Block(3,14,-7,SANDSTONE)
Block(3,14,-6,SANDSTONE)
Block(3,14,-5,SANDSTONE)
Block(3,14,-4,SANDSTONE)
Block(3,14,-3,SANDSTONE)
Block(3,14,-2,SANDSTONE)
Block(3,14,-1,SANDSTONE)
Block(3,14,0,SANDSTONE)
Block(3,15,-7,SANDSTONE)
Block(3,15,-6,SANDSTONE)
Block(3,15,-5,SANDSTONE)
Block(3,15,-4,SANDSTONE)
Block(3,15,-3,SANDSTONE)
Block(3,15,-2,SANDSTONE)
Block(3,15,-1,SANDSTONE)
Block(3,15,0,SANDSTONE)
Block(3,16,-7,SANDSTONE)
Block(3,16,-6,SANDSTONE)
Block(3,16,-5,SANDSTONE)
Block(3,16,-4,SANDSTONE)
Block(3,16,-3,SANDSTONE)
Block(3,16,-2,SANDSTONE)
Block(3,16,-1,SANDSTONE)
Block(3,16,0,SANDSTONE)
Block(3,17,-7,SANDSTONE)
Block(3,17,-6,SANDSTONE)
Block(3,17,-5,SANDSTONE)
Block(3,17,-4,SANDSTONE)
Block(3,17,-3,SANDSTONE)
Block(3,17,-2,SANDSTONE)
Block(3,17,-1,SANDSTONE)
Block(3,17,0,OBSIDIAN)
Block(3,18,-7,SANDSTONE)
Block(3,18,-6,SANDSTONE)
Block(3,18,-5,SANDSTONE)
Block(3,18,-4,SANDSTONE)
Block(3,18,-3,SANDSTONE)
Block(3,18,-2,OBSIDIAN)
Block(3,18,-1,OBSIDIAN)
Block(3,18,0,OBSIDIAN)
Block(3,19,-7,SANDSTONE)
Block(3,19,-6,SANDSTONE)
Block(3,19,-5,OBSIDIAN)
Block(3,19,-4,OBSIDIAN)
Block(3,19,-3,OBSIDIAN)
Block(3,19,-2,OBSIDIAN)
Block(3,19,-1,OBSIDIAN)
Block(3,19,0,OBSIDIAN)
Block(3,20,-7,SANDSTONE)
Block(3,20,-6,SANDSTONE)
Block(3,20,-5,OBSIDIAN)
Block(3,20,-4,OBSIDIAN)
Block(3,20,-3,OBSIDIAN)
Block(3,20,-2,OBSIDIAN)
Block(3,20,-1,OBSIDIAN)
Block(3,20,0,OBSIDIAN)
Block(3,21,-7,SANDSTONE)
Block(3,21,-6,SANDSTONE)
Block(3,21,-5,OBSIDIAN)
Block(3,21,-4,OBSIDIAN)
Block(3,21,-3,OBSIDIAN)
Block(3,21,-2,OBSIDIAN)
Block(3,21,-1,OBSIDIAN)
Block(3,21,0,OBSIDIAN)
Block(3,22,-7,SANDSTONE)
Block(3,22,-6,OBSIDIAN)
Block(3,22,-5,OBSIDIAN)
Block(3,22,-4,OBSIDIAN)
Block(3,22,-3,OBSIDIAN)
Block(3,22,-2,OBSIDIAN)
Block(3,22,-1,OBSIDIAN)
Block(3,22,0,OBSIDIAN)
Block(3,23,-7,OBSIDIAN)
Block(3,23,-6,OBSIDIAN)
Block(3,23,-5,OBSIDIAN)
Block(3,23,-4,OBSIDIAN)
Block(3,23,-3,OBSIDIAN)
Block(3,23,-2,OBSIDIAN)
Block(3,23,-1,OBSIDIAN)
Block(3,24,-7,OBSIDIAN)
Block(3,24,-6,OBSIDIAN)
Block(3,24,-5,OBSIDIAN)
Block(3,24,-4,OBSIDIAN)
Block(3,24,-3,OBSIDIAN)
Block(3,24,-2,OBSIDIAN)
Block(3,24,-1,OBSIDIAN)
Block(3,25,-7,OBSIDIAN)
Block(3,25,-6,OBSIDIAN)
Block(3,25,-5,OBSIDIAN)
Block(3,25,-4,OBSIDIAN)
Block(3,25,-3,OBSIDIAN)
Block(3,25,-2,OBSIDIAN)
Block(3,25,-1,OBSIDIAN)
Block(3,26,-7,OBSIDIAN)
Block(3,26,-6,OBSIDIAN)
Block(3,26,-5,OBSIDIAN)
Block(3,26,-4,OBSIDIAN)
Block(3,26,-3,OBSIDIAN)
Block(3,26,-2,OBSIDIAN)
Block(3,26,-1,OBSIDIAN)
Block(3,27,-7,OBSIDIAN)
Block(3,27,-6,OBSIDIAN)
Block(3,27,-5,OBSIDIAN)
Block(3,27,-4,OBSIDIAN)
Block(3,27,-3,OBSIDIAN)
Block(3,27,-2,OBSIDIAN)
Block(3,27,-1,OBSIDIAN)
Block(3,28,-7,OBSIDIAN)
Block(3,28,-6,OBSIDIAN)
Block(3,28,-5,OBSIDIAN)
Block(3,28,-4,OBSIDIAN)
Block(3,28,-3,OBSIDIAN)
Block(3,28,-2,OBSIDIAN)
Block(3,28,-1,OBSIDIAN)
Block(3,29,-7,OBSIDIAN)
Block(3,29,-6,OBSIDIAN)
Block(3,29,-5,OBSIDIAN)
Block(3,29,-4,OBSIDIAN)
Block(3,29,-3,OBSIDIAN)
Block(3,29,-2,SANDSTONE)
Block(3,29,-1,SANDSTONE)
Block(3,30,-7,OBSIDIAN)
Block(3,30,-6,OBSIDIAN)
Block(3,30,-5,OBSIDIAN)
Block(3,30,-4,OBSIDIAN)
Block(3,30,-3,SANDSTONE)
Block(3,30,-2,SANDSTONE)
Block(3,30,-1,SANDSTONE)
Block(3,31,-7,OBSIDIAN)
Block(3,31,-6,OBSIDIAN)
Block(3,31,-5,OBSIDIAN)
Block(3,31,-4,SANDSTONE)
Block(3,31,-3,SANDSTONE)
Block(3,31,-2,SANDSTONE)
Block(3,32,-7,OBSIDIAN)
Block(3,32,-6,SANDSTONE)
Block(3,32,-5,SANDSTONE)
Block(3,32,-4,SANDSTONE)
Block(3,32,-3,SANDSTONE)
Block(3,32,-2,SANDSTONE)
Block(3,33,-7,SANDSTONE)
Block(3,33,-6,SANDSTONE)
Block(3,33,-5,SANDSTONE)
Block(3,33,-4,SANDSTONE)
Block(3,33,-3,SANDSTONE)
Block(3,33,-2,SANDSTONE)
Block(3,34,-7,SANDSTONE)
Block(3,34,-6,SANDSTONE)
Block(3,34,-5,SANDSTONE)
Block(3,34,-4,SANDSTONE)
Block(3,34,-3,SANDSTONE)
Block(3,34,-2,SANDSTONE)
Block(3,35,-7,SANDSTONE)
Block(3,35,-6,SANDSTONE)
Block(3,35,-5,SANDSTONE)
Block(3,35,-4,SANDSTONE)
Block(3,35,-3,SANDSTONE)
Block(3,35,-2,SANDSTONE)
Block(3,36,-7,SANDSTONE)
Block(3,36,-6,SANDSTONE)
Block(3,36,-5,SANDSTONE)
Block(3,36,-4,SANDSTONE)
Block(3,36,-3,SANDSTONE)
Block(3,36,-2,SANDSTONE)
Block(3,37,-7,SANDSTONE)
Block(3,37,-6,SANDSTONE)
Block(3,37,-5,SANDSTONE)
Block(3,37,-4,SANDSTONE)
Block(3,37,-3,SANDSTONE)
Block(3,37,-2,SANDSTONE)
Block(3,38,-7,SANDSTONE)
Block(3,38,-6,SANDSTONE)
Block(3,38,-5,SANDSTONE)
Block(3,38,-4,SANDSTONE)
Block(3,39,-7,SANDSTONE)
Block(3,39,-6,SANDSTONE)
Block(3,40,-7,SANDSTONE)
Block(4,5,2,SANDSTONE)
Block(4,5,3,SANDSTONE)
Block(4,6,1,SANDSTONE)
Block(4,6,2,SANDSTONE)
Block(4,6,3,SANDSTONE)
Block(4,7,0,SANDSTONE)
Block(4,7,1,SANDSTONE)
Block(4,7,2,SANDSTONE)
Block(4,7,3,SANDSTONE)
Block(4,8,-2,SANDSTONE)
Block(4,8,-1,SANDSTONE)
Block(4,8,0,SANDSTONE)
Block(4,8,1,SANDSTONE)
Block(4,8,2,SANDSTONE)
Block(4,8,3,SANDSTONE)
Block(4,9,-3,SANDSTONE)
Block(4,9,-2,SANDSTONE)
Block(4,9,-1,SANDSTONE)
Block(4,9,0,SANDSTONE)
Block(4,9,1,SANDSTONE)
Block(4,9,2,SANDSTONE)
Block(4,9,3,SANDSTONE)
Block(4,10,-4,SANDSTONE)
Block(4,10,-3,SANDSTONE)
Block(4,10,-2,SANDSTONE)
Block(4,10,-1,SANDSTONE)
Block(4,10,0,SANDSTONE)
Block(4,10,1,SANDSTONE)
Block(4,10,2,SANDSTONE)
Block(4,10,3,SANDSTONE)
Block(4,11,-6,SANDSTONE)
Block(4,11,-5,SANDSTONE)
Block(4,11,-4,SANDSTONE)
Block(4,11,-3,SANDSTONE)
Block(4,11,-2,SANDSTONE)
Block(4,11,-1,SANDSTONE)
Block(4,11,0,SANDSTONE)
Block(4,11,1,SANDSTONE)
Block(4,11,2,SANDSTONE)
Block(4,11,3,SANDSTONE)
Block(4,12,-7,SANDSTONE)
Block(4,12,-6,SANDSTONE)
Block(4,12,-5,SANDSTONE)
Block(4,12,-4,SANDSTONE)
Block(4,12,-3,SANDSTONE)
Block(4,12,-2,SANDSTONE)
Block(4,12,-1,SANDSTONE)
Block(4,12,0,SANDSTONE)
Block(4,12,1,SANDSTONE)
Block(4,12,2,SANDSTONE)
Block(4,13,-7,SANDSTONE)
Block(4,13,-6,SANDSTONE)
Block(4,13,-5,SANDSTONE)
Block(4,13,-4,SANDSTONE)
Block(4,13,-3,SANDSTONE)
Block(4,13,-2,SANDSTONE)
Block(4,13,-1,SANDSTONE)
Block(4,13,0,SANDSTONE)
Block(4,13,1,SANDSTONE)
Block(4,13,2,SANDSTONE)
Block(4,14,-7,SANDSTONE)
Block(4,14,-6,SANDSTONE)
Block(4,14,-5,SANDSTONE)
Block(4,14,-4,SANDSTONE)
Block(4,14,-3,SANDSTONE)
Block(4,14,-2,SANDSTONE)
Block(4,14,-1,SANDSTONE)
Block(4,14,0,SANDSTONE)
Block(4,14,1,OBSIDIAN)
Block(4,14,2,OBSIDIAN)
Block(4,15,-7,SANDSTONE)
Block(4,15,-6,SANDSTONE)
Block(4,15,-5,SANDSTONE)
Block(4,15,-4,SANDSTONE)
Block(4,15,-3,SANDSTONE)
Block(4,15,-2,SANDSTONE)
Block(4,15,-1,SANDSTONE)
Block(4,15,0,SANDSTONE)
Block(4,15,1,OBSIDIAN)
Block(4,15,2,OBSIDIAN)
Block(4,16,-7,SANDSTONE)
Block(4,16,-6,SANDSTONE)
Block(4,16,-5,SANDSTONE)
Block(4,16,-4,SANDSTONE)
Block(4,16,-3,SANDSTONE)
Block(4,16,-2,SANDSTONE)
Block(4,16,-1,SANDSTONE)
Block(4,16,0,OBSIDIAN)
Block(4,16,1,OBSIDIAN)
Block(4,16,2,OBSIDIAN)
Block(4,17,-7,OBSIDIAN)
Block(4,17,-6,SANDSTONE)
Block(4,17,-5,SANDSTONE)
Block(4,17,-4,SANDSTONE)
Block(4,17,-3,SANDSTONE)
Block(4,17,-2,SANDSTONE)
Block(4,17,-1,OBSIDIAN)
Block(4,17,0,OBSIDIAN)
Block(4,17,1,OBSIDIAN)
Block(4,17,2,OBSIDIAN)
Block(4,18,-7,SANDSTONE)
Block(4,18,-6,OBSIDIAN)
Block(4,18,-5,OBSIDIAN)
Block(4,18,-4,OBSIDIAN)
Block(4,18,-3,OBSIDIAN)
Block(4,18,-2,OBSIDIAN)
Block(4,18,-1,OBSIDIAN)
Block(4,18,0,OBSIDIAN)
Block(4,18,1,OBSIDIAN)
Block(4,18,2,OBSIDIAN)
Block(4,19,-7,SANDSTONE)
Block(4,19,-6,OBSIDIAN)
Block(4,19,-5,OBSIDIAN)
Block(4,19,-4,OBSIDIAN)
Block(4,19,-3,OBSIDIAN)
Block(4,19,-2,OBSIDIAN)
Block(4,19,-1,OBSIDIAN)
Block(4,19,0,OBSIDIAN)
Block(4,19,1,OBSIDIAN)
Block(4,19,2,OBSIDIAN)
Block(4,20,-7,SANDSTONE)
Block(4,20,-6,OBSIDIAN)
Block(4,20,-5,OBSIDIAN)
Block(4,20,-4,OBSIDIAN)
Block(4,20,-3,OBSIDIAN)
Block(4,20,-2,OBSIDIAN)
Block(4,20,-1,OBSIDIAN)
Block(4,20,0,OBSIDIAN)
Block(4,20,1,OBSIDIAN)
Block(4,21,-7,OBSIDIAN)
Block(4,21,-6,OBSIDIAN)
Block(4,21,-5,OBSIDIAN)
Block(4,21,-4,OBSIDIAN)
Block(4,21,-3,OBSIDIAN)
Block(4,21,-2,OBSIDIAN)
Block(4,21,-1,OBSIDIAN)
Block(4,21,0,OBSIDIAN)
Block(4,21,1,OBSIDIAN)
Block(4,22,-7,OBSIDIAN)
Block(4,22,-6,OBSIDIAN)
Block(4,22,-5,OBSIDIAN)
Block(4,22,-4,OBSIDIAN)
Block(4,22,-3,OBSIDIAN)
Block(4,22,-2,OBSIDIAN)
Block(4,22,-1,OBSIDIAN)
Block(4,22,0,OBSIDIAN)
Block(4,22,1,OBSIDIAN)
Block(4,23,-7,OBSIDIAN)
Block(4,23,-6,OBSIDIAN)
Block(4,23,-5,OBSIDIAN)
Block(4,23,-4,OBSIDIAN)
Block(4,23,-3,OBSIDIAN)
Block(4,23,-2,OBSIDIAN)
Block(4,23,-1,OBSIDIAN)
Block(4,23,0,OBSIDIAN)
Block(4,23,1,OBSIDIAN)
Block(4,24,-7,OBSIDIAN)
Block(4,24,-6,OBSIDIAN)
Block(4,24,-5,OBSIDIAN)
Block(4,24,-4,OBSIDIAN)
Block(4,24,-3,OBSIDIAN)
Block(4,24,-2,OBSIDIAN)
Block(4,24,-1,OBSIDIAN)
Block(4,24,0,OBSIDIAN)
Block(4,24,1,OBSIDIAN)
Block(4,25,-7,OBSIDIAN)
Block(4,25,-6,OBSIDIAN)
Block(4,25,-5,OBSIDIAN)
Block(4,25,-4,OBSIDIAN)
Block(4,25,-3,OBSIDIAN)
Block(4,25,-2,OBSIDIAN)
Block(4,25,-1,OBSIDIAN)
Block(4,25,0,OBSIDIAN)
Block(4,25,1,OBSIDIAN)
Block(4,26,-7,OBSIDIAN)
Block(4,26,-6,OBSIDIAN)
Block(4,26,-5,OBSIDIAN)
Block(4,26,-4,OBSIDIAN)
Block(4,26,-3,OBSIDIAN)
Block(4,26,-2,OBSIDIAN)
Block(4,26,-1,OBSIDIAN)
Block(4,26,0,OBSIDIAN)
Block(4,26,1,OBSIDIAN)
Block(4,27,-7,OBSIDIAN)
Block(4,27,-6,OBSIDIAN)
Block(4,27,-5,OBSIDIAN)
Block(4,27,-4,OBSIDIAN)
Block(4,27,-3,OBSIDIAN)
Block(4,27,-2,OBSIDIAN)
Block(4,27,-1,OBSIDIAN)
Block(4,27,0,OBSIDIAN)
Block(4,27,1,OBSIDIAN)
Block(4,28,-7,OBSIDIAN)
Block(4,28,-6,OBSIDIAN)
Block(4,28,-5,OBSIDIAN)
Block(4,28,-4,OBSIDIAN)
Block(4,28,-3,OBSIDIAN)
Block(4,28,-2,OBSIDIAN)
Block(4,28,-1,SANDSTONE)
Block(4,28,0,SANDSTONE)
Block(4,28,1,SANDSTONE)
Block(4,29,-7,OBSIDIAN)
Block(4,29,-6,OBSIDIAN)
Block(4,29,-5,OBSIDIAN)
Block(4,29,-4,OBSIDIAN)
Block(4,29,-3,SANDSTONE)
Block(4,29,-2,SANDSTONE)
Block(4,29,-1,SANDSTONE)
Block(4,29,0,SANDSTONE)
Block(4,30,-7,OBSIDIAN)
Block(4,30,-6,OBSIDIAN)
Block(4,30,-5,OBSIDIAN)
Block(4,30,-4,SANDSTONE)
Block(4,30,-3,SANDSTONE)
Block(4,30,-2,SANDSTONE)
Block(4,30,-1,SANDSTONE)
Block(4,30,0,SANDSTONE)
Block(4,31,-7,OBSIDIAN)
Block(4,31,-6,OBSIDIAN)
Block(4,31,-5,OBSIDIAN)
Block(4,31,-4,SANDSTONE)
Block(4,31,-3,SANDSTONE)
Block(4,31,-2,SANDSTONE)
Block(4,31,-1,SANDSTONE)
Block(4,31,0,SANDSTONE)
Block(4,32,-7,OBSIDIAN)
Block(4,32,-6,SANDSTONE)
Block(4,32,-5,SANDSTONE)
Block(4,32,-4,SANDSTONE)
Block(4,32,-3,SANDSTONE)
Block(4,32,-2,SANDSTONE)
Block(4,32,-1,SANDSTONE)
Block(4,32,0,SANDSTONE)
Block(4,33,-7,SANDSTONE)
Block(4,33,-6,SANDSTONE)
Block(4,33,-5,SANDSTONE)
Block(4,33,-4,SANDSTONE)
Block(4,33,-3,SANDSTONE)
Block(4,33,-2,SANDSTONE)
Block(4,33,-1,SANDSTONE)
Block(4,33,0,SANDSTONE)
Block(4,34,-7,SANDSTONE)
Block(4,34,-6,SANDSTONE)
Block(4,34,-5,SANDSTONE)
Block(4,34,-4,SANDSTONE)
Block(4,34,-3,SANDSTONE)
Block(4,34,-2,SANDSTONE)
Block(4,34,-1,SANDSTONE)
Block(4,34,0,SANDSTONE)
Block(4,35,-7,SANDSTONE)
Block(4,35,-6,SANDSTONE)
Block(4,35,-5,SANDSTONE)
Block(4,35,-4,SANDSTONE)
Block(4,35,-3,SANDSTONE)
Block(4,35,-2,SANDSTONE)
Block(4,35,-1,SANDSTONE)
Block(4,35,0,SANDSTONE)
Block(4,36,-7,SANDSTONE)
Block(4,36,-6,SANDSTONE)
Block(4,36,-5,SANDSTONE)
Block(4,36,-4,SANDSTONE)
Block(4,36,-3,SANDSTONE)
Block(4,36,-2,SANDSTONE)
Block(4,36,-1,SANDSTONE)
Block(4,37,-7,SANDSTONE)
Block(4,37,-6,SANDSTONE)
Block(4,37,-5,SANDSTONE)
Block(4,37,-4,SANDSTONE)
Block(4,37,-3,SANDSTONE)
Block(4,38,-7,SANDSTONE)
Block(4,38,-6,SANDSTONE)
Block(4,38,-5,SANDSTONE)
Block(4,39,-7,SANDSTONE)
Block(4,39,-6,SANDSTONE)
Block(5,2,5,SANDSTONE)
Block(5,3,3,SANDSTONE)
Block(5,3,4,SANDSTONE)
Block(5,3,5,SANDSTONE)
Block(5,4,2,SANDSTONE)
Block(5,4,3,SANDSTONE)
Block(5,4,4,SANDSTONE)
Block(5,4,5,SANDSTONE)
Block(5,5,1,SANDSTONE)
Block(5,5,2,SANDSTONE)
Block(5,5,3,SANDSTONE)
Block(5,5,4,SANDSTONE)
Block(5,5,5,SANDSTONE)
Block(5,6,-1,SANDSTONE)
Block(5,6,0,SANDSTONE)
Block(5,6,1,SANDSTONE)
Block(5,6,2,SANDSTONE)
Block(5,6,3,SANDSTONE)
Block(5,6,4,SANDSTONE)
Block(5,6,5,SANDSTONE)
Block(5,7,-2,SANDSTONE)
Block(5,7,-1,SANDSTONE)
Block(5,7,0,SANDSTONE)
Block(5,7,1,SANDSTONE)
Block(5,7,2,SANDSTONE)
Block(5,7,3,SANDSTONE)
Block(5,7,4,SANDSTONE)
Block(5,7,5,SANDSTONE)
Block(5,8,-3,SANDSTONE)
Block(5,8,-2,SANDSTONE)
Block(5,8,-1,SANDSTONE)
Block(5,8,0,SANDSTONE)
Block(5,8,1,SANDSTONE)
Block(5,8,2,SANDSTONE)
Block(5,8,3,SANDSTONE)
Block(5,8,4,SANDSTONE)
Block(5,8,5,SANDSTONE)
Block(5,9,-4,SANDSTONE)
Block(5,9,-3,SANDSTONE)
Block(5,9,-2,SANDSTONE)
Block(5,9,-1,SANDSTONE)
Block(5,9,0,SANDSTONE)
Block(5,9,1,SANDSTONE)
Block(5,9,2,SANDSTONE)
Block(5,9,3,SANDSTONE)
Block(5,9,4,SANDSTONE)
Block(5,10,-6,SANDSTONE)
Block(5,10,-5,SANDSTONE)
Block(5,10,-4,SANDSTONE)
Block(5,10,-3,SANDSTONE)
Block(5,10,-2,SANDSTONE)
Block(5,10,-1,SANDSTONE)
Block(5,10,0,SANDSTONE)
Block(5,10,1,SANDSTONE)
Block(5,10,2,SANDSTONE)
Block(5,10,3,SANDSTONE)
Block(5,10,4,SANDSTONE)
Block(5,11,-7,SANDSTONE)
Block(5,11,-6,SANDSTONE)
Block(5,11,-5,SANDSTONE)
Block(5,11,-4,SANDSTONE)
Block(5,11,-3,SANDSTONE)
Block(5,11,-2,SANDSTONE)
Block(5,11,-1,SANDSTONE)
Block(5,11,0,SANDSTONE)
Block(5,11,1,SANDSTONE)
Block(5,11,2,SANDSTONE)
Block(5,11,3,SANDSTONE)
Block(5,11,4,SANDSTONE)
Block(5,12,-7,SANDSTONE)
Block(5,12,-6,SANDSTONE)
Block(5,12,-5,SANDSTONE)
Block(5,12,-4,SANDSTONE)
Block(5,12,-3,SANDSTONE)
Block(5,12,-2,SANDSTONE)
Block(5,12,-1,SANDSTONE)
Block(5,12,0,SANDSTONE)
Block(5,12,1,SANDSTONE)
Block(5,12,2,SANDSTONE)
Block(5,12,3,SANDSTONE)
Block(5,12,4,OBSIDIAN)
Block(5,13,-7,SANDSTONE)
Block(5,13,-6,SANDSTONE)
Block(5,13,-5,SANDSTONE)
Block(5,13,-4,SANDSTONE)
Block(5,13,-3,SANDSTONE)
Block(5,13,-2,SANDSTONE)
Block(5,13,-1,SANDSTONE)
Block(5,13,0,SANDSTONE)
Block(5,13,1,SANDSTONE)
Block(5,13,2,OBSIDIAN)
Block(5,13,3,OBSIDIAN)
Block(5,13,4,OBSIDIAN)
Block(5,14,-7,SANDSTONE)
Block(5,14,-6,SANDSTONE)
Block(5,14,-5,SANDSTONE)
Block(5,14,-4,SANDSTONE)
Block(5,14,-3,SANDSTONE)
Block(5,14,-2,SANDSTONE)
Block(5,14,-1,SANDSTONE)
Block(5,14,0,OBSIDIAN)
Block(5,14,1,OBSIDIAN)
Block(5,14,2,OBSIDIAN)
Block(5,14,3,OBSIDIAN)
Block(5,14,4,OBSIDIAN)
Block(5,15,-7,SANDSTONE)
Block(5,15,-6,SANDSTONE)
Block(5,15,-5,SANDSTONE)
Block(5,15,-4,SANDSTONE)
Block(5,15,-3,SANDSTONE)
Block(5,15,-2,SANDSTONE)
Block(5,15,-1,SANDSTONE)
Block(5,15,0,OBSIDIAN)
Block(5,15,1,OBSIDIAN)
Block(5,15,2,OBSIDIAN)
Block(5,15,3,OBSIDIAN)
Block(5,15,4,OBSIDIAN)
Block(5,16,-7,OBSIDIAN)
Block(5,16,-6,SANDSTONE)
Block(5,16,-5,SANDSTONE)
Block(5,16,-4,SANDSTONE)
Block(5,16,-3,SANDSTONE)
Block(5,16,-2,SANDSTONE)
Block(5,16,-1,OBSIDIAN)
Block(5,16,0,OBSIDIAN)
Block(5,16,1,OBSIDIAN)
Block(5,16,2,OBSIDIAN)
Block(5,16,3,OBSIDIAN)
Block(5,16,4,OBSIDIAN)
Block(5,17,-7,OBSIDIAN)
Block(5,17,-6,OBSIDIAN)
Block(5,17,-5,OBSIDIAN)
Block(5,17,-4,OBSIDIAN)
Block(5,17,-3,OBSIDIAN)
Block(5,17,-2,OBSIDIAN)
Block(5,17,-1,OBSIDIAN)
Block(5,17,0,OBSIDIAN)
Block(5,17,1,OBSIDIAN)
Block(5,17,2,OBSIDIAN)
Block(5,17,3,OBSIDIAN)
Block(5,17,4,OBSIDIAN)
Block(5,18,-7,OBSIDIAN)
Block(5,18,-6,OBSIDIAN)
Block(5,18,-5,OBSIDIAN)
Block(5,18,-4,OBSIDIAN)
Block(5,18,-3,OBSIDIAN)
Block(5,18,-2,OBSIDIAN)
Block(5,18,-1,OBSIDIAN)
Block(5,18,0,OBSIDIAN)
Block(5,18,1,OBSIDIAN)
Block(5,18,2,OBSIDIAN)
Block(5,18,3,OBSIDIAN)
Block(5,19,-7,OBSIDIAN)
Block(5,19,-6,OBSIDIAN)
Block(5,19,-5,OBSIDIAN)
Block(5,19,-4,OBSIDIAN)
Block(5,19,-3,OBSIDIAN)
Block(5,19,-2,OBSIDIAN)
Block(5,19,-1,OBSIDIAN)
Block(5,19,0,OBSIDIAN)
Block(5,19,1,OBSIDIAN)
Block(5,19,2,OBSIDIAN)
Block(5,19,3,OBSIDIAN)
Block(5,20,-7,OBSIDIAN)
Block(5,20,-6,OBSIDIAN)
Block(5,20,-5,OBSIDIAN)
Block(5,20,-4,OBSIDIAN)
Block(5,20,-3,OBSIDIAN)
Block(5,20,-2,OBSIDIAN)
Block(5,20,-1,OBSIDIAN)
Block(5,20,0,OBSIDIAN)
Block(5,20,1,OBSIDIAN)
Block(5,20,2,OBSIDIAN)
Block(5,20,3,OBSIDIAN)
Block(5,21,-7,OBSIDIAN)
Block(5,21,-6,OBSIDIAN)
Block(5,21,-5,OBSIDIAN)
Block(5,21,-4,OBSIDIAN)
Block(5,21,-3,OBSIDIAN)
Block(5,21,-2,OBSIDIAN)
Block(5,21,-1,OBSIDIAN)
Block(5,21,0,OBSIDIAN)
Block(5,21,1,OBSIDIAN)
Block(5,21,2,OBSIDIAN)
Block(5,21,3,OBSIDIAN)
Block(5,22,-7,OBSIDIAN)
Block(5,22,-6,OBSIDIAN)
Block(5,22,-5,OBSIDIAN)
Block(5,22,-4,OBSIDIAN)
Block(5,22,-3,OBSIDIAN)
Block(5,22,-2,OBSIDIAN)
Block(5,22,-1,OBSIDIAN)
Block(5,22,0,OBSIDIAN)
Block(5,22,1,OBSIDIAN)
Block(5,22,2,OBSIDIAN)
Block(5,22,3,OBSIDIAN)
Block(5,23,-7,OBSIDIAN)
Block(5,23,-6,OBSIDIAN)
Block(5,23,-5,OBSIDIAN)
Block(5,23,-4,OBSIDIAN)
Block(5,23,-3,OBSIDIAN)
Block(5,23,-2,OBSIDIAN)
Block(5,23,-1,OBSIDIAN)
Block(5,23,0,OBSIDIAN)
Block(5,23,1,OBSIDIAN)
Block(5,23,2,OBSIDIAN)
Block(5,23,3,OBSIDIAN)
Block(5,24,-7,OBSIDIAN)
Block(5,24,-6,OBSIDIAN)
Block(5,24,-5,OBSIDIAN)
Block(5,24,-4,OBSIDIAN)
Block(5,24,-3,OBSIDIAN)
Block(5,24,-2,OBSIDIAN)
Block(5,24,-1,OBSIDIAN)
Block(5,24,0,OBSIDIAN)
Block(5,24,1,OBSIDIAN)
Block(5,24,2,OBSIDIAN)
Block(5,24,3,OBSIDIAN)
Block(5,25,-7,OBSIDIAN)
Block(5,25,-6,OBSIDIAN)
Block(5,25,-5,OBSIDIAN)
Block(5,25,-4,OBSIDIAN)
Block(5,25,-3,OBSIDIAN)
Block(5,25,-2,OBSIDIAN)
Block(5,25,-1,OBSIDIAN)
Block(5,25,0,OBSIDIAN)
Block(5,25,1,OBSIDIAN)
Block(5,25,2,OBSIDIAN)
Block(5,25,3,SANDSTONE)
Block(5,26,-7,OBSIDIAN)
Block(5,26,-6,OBSIDIAN)
Block(5,26,-5,OBSIDIAN)
Block(5,26,-4,OBSIDIAN)
Block(5,26,-3,OBSIDIAN)
Block(5,26,-2,OBSIDIAN)
Block(5,26,-1,OBSIDIAN)
Block(5,26,0,OBSIDIAN)
Block(5,26,1,OBSIDIAN)
Block(5,26,2,SANDSTONE)
Block(5,27,-7,OBSIDIAN)
Block(5,27,-6,OBSIDIAN)
Block(5,27,-5,OBSIDIAN)
Block(5,27,-4,OBSIDIAN)
Block(5,27,-3,OBSIDIAN)
Block(5,27,-2,OBSIDIAN)
Block(5,27,-1,OBSIDIAN)
Block(5,27,0,OBSIDIAN)
Block(5,27,1,SANDSTONE)
Block(5,27,2,SANDSTONE)
Block(5,28,-7,OBSIDIAN)
Block(5,28,-6,OBSIDIAN)
Block(5,28,-5,OBSIDIAN)
Block(5,28,-4,OBSIDIAN)
Block(5,28,-3,OBSIDIAN)
Block(5,28,-2,SANDSTONE)
Block(5,28,-1,SANDSTONE)
Block(5,28,0,SANDSTONE)
Block(5,28,1,SANDSTONE)
Block(5,28,2,SANDSTONE)
Block(5,29,-7,OBSIDIAN)
Block(5,29,-6,OBSIDIAN)
Block(5,29,-5,OBSIDIAN)
Block(5,29,-4,OBSIDIAN)
Block(5,29,-3,SANDSTONE)
Block(5,29,-2,SANDSTONE)
Block(5,29,-1,SANDSTONE)
Block(5,29,0,SANDSTONE)
Block(5,29,1,SANDSTONE)
Block(5,29,2,SANDSTONE)
Block(5,30,-7,OBSIDIAN)
Block(5,30,-6,OBSIDIAN)
Block(5,30,-5,OBSIDIAN)
Block(5,30,-4,SANDSTONE)
Block(5,30,-3,SANDSTONE)
Block(5,30,-2,SANDSTONE)
Block(5,30,-1,SANDSTONE)
Block(5,30,0,SANDSTONE)
Block(5,30,1,SANDSTONE)
Block(5,30,2,SANDSTONE)
Block(5,31,-7,OBSIDIAN)
Block(5,31,-6,OBSIDIAN)
Block(5,31,-5,SANDSTONE)
Block(5,31,-4,SANDSTONE)
Block(5,31,-3,SANDSTONE)
Block(5,31,-2,SANDSTONE)
Block(5,31,-1,SANDSTONE)
Block(5,31,0,SANDSTONE)
Block(5,31,1,SANDSTONE)
Block(5,31,2,SANDSTONE)
Block(5,32,-7,OBSIDIAN)
Block(5,32,-6,OBSIDIAN)
Block(5,32,-5,SANDSTONE)
Block(5,32,-4,SANDSTONE)
Block(5,32,-3,SANDSTONE)
Block(5,32,-2,SANDSTONE)
Block(5,32,-1,SANDSTONE)
Block(5,32,0,SANDSTONE)
Block(5,32,1,SANDSTONE)
Block(5,32,2,SANDSTONE)
Block(5,33,-7,SANDSTONE)
Block(5,33,-6,SANDSTONE)
Block(5,33,-5,SANDSTONE)
Block(5,33,-4,SANDSTONE)
Block(5,33,-3,SANDSTONE)
Block(5,33,-2,SANDSTONE)
Block(5,33,-1,SANDSTONE)
Block(5,33,0,SANDSTONE)
Block(5,33,1,SANDSTONE)
Block(5,33,2,SANDSTONE)
Block(5,34,-7,SANDSTONE)
Block(5,34,-6,SANDSTONE)
Block(5,34,-5,SANDSTONE)
Block(5,34,-4,SANDSTONE)
Block(5,34,-3,SANDSTONE)
Block(5,34,-2,SANDSTONE)
Block(5,34,-1,SANDSTONE)
Block(5,34,0,SANDSTONE)
Block(5,34,1,SANDSTONE)
Block(5,35,-7,SANDSTONE)
Block(5,35,-6,SANDSTONE)
Block(5,35,-5,SANDSTONE)
Block(5,35,-4,SANDSTONE)
Block(5,35,-3,SANDSTONE)
Block(5,35,-2,SANDSTONE)
Block(5,35,-1,SANDSTONE)
Block(5,36,-7,SANDSTONE)
Block(5,36,-6,SANDSTONE)
Block(5,36,-5,SANDSTONE)
Block(5,36,-4,SANDSTONE)
Block(5,36,-3,SANDSTONE)
Block(5,36,-2,SANDSTONE)
Block(5,37,-7,SANDSTONE)
Block(5,37,-6,SANDSTONE)
Block(5,37,-5,SANDSTONE)
Block(5,37,-4,SANDSTONE)
Block(5,38,-7,SANDSTONE)
Block(5,38,-6,SANDSTONE)
Block(5,38,-5,SANDSTONE)
Block(5,39,-7,SANDSTONE)
Block(6,0,6,SANDSTONE)
Block(6,0,7,SANDSTONE)
Block(6,1,5,SANDSTONE)
Block(6,1,6,SANDSTONE)
Block(6,1,7,SANDSTONE)
Block(6,2,3,SANDSTONE)
Block(6,2,4,SANDSTONE)
Block(6,2,5,SANDSTONE)
Block(6,2,6,SANDSTONE)
Block(6,2,7,SANDSTONE)
Block(6,3,2,SANDSTONE)
Block(6,3,3,SANDSTONE)
Block(6,3,4,SANDSTONE)
Block(6,3,5,SANDSTONE)
Block(6,3,6,SANDSTONE)
Block(6,3,7,SANDSTONE)
Block(6,4,1,SANDSTONE)
Block(6,4,2,SANDSTONE)
Block(6,4,3,SANDSTONE)
Block(6,4,4,SANDSTONE)
Block(6,4,5,SANDSTONE)
Block(6,4,6,SANDSTONE)
Block(6,4,7,SANDSTONE)
Block(6,5,-1,SANDSTONE)
Block(6,5,0,SANDSTONE)
Block(6,5,1,SANDSTONE)
Block(6,5,2,SANDSTONE)
Block(6,5,3,SANDSTONE)
Block(6,5,4,SANDSTONE)
Block(6,5,5,SANDSTONE)
Block(6,5,6,SANDSTONE)
Block(6,5,7,SANDSTONE)
Block(6,6,-2,SANDSTONE)
Block(6,6,-1,SANDSTONE)
Block(6,6,0,SANDSTONE)
Block(6,6,1,SANDSTONE)
Block(6,6,2,SANDSTONE)
Block(6,6,3,SANDSTONE)
Block(6,6,4,SANDSTONE)
Block(6,6,5,SANDSTONE)
Block(6,6,6,SANDSTONE)
Block(6,6,7,SANDSTONE)
Block(6,7,-3,SANDSTONE)
Block(6,7,-2,SANDSTONE)
Block(6,7,-1,SANDSTONE)
Block(6,7,0,SANDSTONE)
Block(6,7,1,SANDSTONE)
Block(6,7,2,SANDSTONE)
Block(6,7,3,SANDSTONE)
Block(6,7,4,SANDSTONE)
Block(6,7,5,SANDSTONE)
Block(6,7,6,SANDSTONE)
Block(6,8,-5,OBSIDIAN)
Block(6,8,-4,SANDSTONE)
Block(6,8,-3,SANDSTONE)
Block(6,8,-2,SANDSTONE)
Block(6,8,-1,SANDSTONE)
Block(6,8,0,SANDSTONE)
Block(6,8,1,SANDSTONE)
Block(6,8,2,SANDSTONE)
Block(6,8,3,SANDSTONE)
Block(6,8,4,SANDSTONE)
Block(6,8,5,SANDSTONE)
Block(6,8,6,OBSIDIAN)
Block(6,9,-6,OBSIDIAN)
Block(6,9,-5,OBSIDIAN)
Block(6,9,-4,SANDSTONE)
Block(6,9,-3,SANDSTONE)
Block(6,9,-2,SANDSTONE)
Block(6,9,-1,SANDSTONE)
Block(6,9,0,SANDSTONE)
Block(6,9,1,SANDSTONE)
Block(6,9,2,SANDSTONE)
Block(6,9,3,SANDSTONE)
Block(6,9,4,SANDSTONE)
Block(6,9,5,OBSIDIAN)
Block(6,9,6,OBSIDIAN)
Block(6,10,-7,OBSIDIAN)
Block(6,10,-6,OBSIDIAN)
Block(6,10,-5,OBSIDIAN)
Block(6,10,-4,SANDSTONE)
Block(6,10,-3,SANDSTONE)
Block(6,10,-2,SANDSTONE)
Block(6,10,-1,SANDSTONE)
Block(6,10,0,SANDSTONE)
Block(6,10,1,SANDSTONE)
Block(6,10,2,SANDSTONE)
Block(6,10,3,SANDSTONE)
Block(6,10,4,SANDSTONE)
Block(6,10,5,OBSIDIAN)
Block(6,10,6,OBSIDIAN)
Block(6,11,-7,OBSIDIAN)
Block(6,11,-6,OBSIDIAN)
Block(6,11,-5,SANDSTONE)
Block(6,11,-4,SANDSTONE)
Block(6,11,-3,SANDSTONE)
Block(6,11,-2,SANDSTONE)
Block(6,11,-1,SANDSTONE)
Block(6,11,0,SANDSTONE)
Block(6,11,1,SANDSTONE)
Block(6,11,2,SANDSTONE)
Block(6,11,3,SANDSTONE)
Block(6,11,4,OBSIDIAN)
Block(6,11,5,OBSIDIAN)
Block(6,11,6,OBSIDIAN)
Block(6,12,-7,OBSIDIAN)
Block(6,12,-6,SANDSTONE)
Block(6,12,-5,SANDSTONE)
Block(6,12,-4,SANDSTONE)
Block(6,12,-3,SANDSTONE)
Block(6,12,-2,SANDSTONE)
Block(6,12,-1,SANDSTONE)
Block(6,12,0,SANDSTONE)
Block(6,12,1,SANDSTONE)
Block(6,12,2,SANDSTONE)
Block(6,12,3,OBSIDIAN)
Block(6,12,4,OBSIDIAN)
Block(6,12,5,OBSIDIAN)
Block(6,12,6,OBSIDIAN)
Block(6,13,-7,OBSIDIAN)
Block(6,13,-6,SANDSTONE)
Block(6,13,-5,SANDSTONE)
Block(6,13,-4,SANDSTONE)
Block(6,13,-3,SANDSTONE)
Block(6,13,-2,SANDSTONE)
Block(6,13,-1,OBSIDIAN)
Block(6,13,0,OBSIDIAN)
Block(6,13,1,OBSIDIAN)
Block(6,13,2,OBSIDIAN)
Block(6,13,3,OBSIDIAN)
Block(6,13,4,OBSIDIAN)
Block(6,13,5,OBSIDIAN)
Block(6,13,6,OBSIDIAN)
Block(6,14,-7,OBSIDIAN)
Block(6,14,-6,SANDSTONE)
Block(6,14,-5,SANDSTONE)
Block(6,14,-4,SANDSTONE)
Block(6,14,-3,SANDSTONE)
Block(6,14,-2,SANDSTONE)
Block(6,14,-1,OBSIDIAN)
Block(6,14,0,OBSIDIAN)
Block(6,14,1,OBSIDIAN)
Block(6,14,2,OBSIDIAN)
Block(6,14,3,OBSIDIAN)
Block(6,14,4,OBSIDIAN)
Block(6,14,5,OBSIDIAN)
Block(6,14,6,OBSIDIAN)
Block(6,15,-7,OBSIDIAN)
Block(6,15,-6,OBSIDIAN)
Block(6,15,-5,SANDSTONE)
Block(6,15,-4,SANDSTONE)
Block(6,15,-3,SANDSTONE)
Block(6,15,-2,OBSIDIAN)
Block(6,15,-1,OBSIDIAN)
Block(6,15,0,OBSIDIAN)
Block(6,15,1,OBSIDIAN)
Block(6,15,2,OBSIDIAN)
Block(6,15,3,OBSIDIAN)
Block(6,15,4,OBSIDIAN)
Block(6,15,5,OBSIDIAN)
Block(6,16,-7,OBSIDIAN)
Block(6,16,-6,OBSIDIAN)
Block(6,16,-5,OBSIDIAN)
Block(6,16,-4,OBSIDIAN)
Block(6,16,-3,OBSIDIAN)
Block(6,16,-2,OBSIDIAN)
Block(6,16,-1,OBSIDIAN)
Block(6,16,0,OBSIDIAN)
Block(6,16,1,OBSIDIAN)
Block(6,16,2,OBSIDIAN)
Block(6,16,3,OBSIDIAN)
Block(6,16,4,OBSIDIAN)
Block(6,16,5,OBSIDIAN)
Block(6,17,-7,OBSIDIAN)
Block(6,17,-6,OBSIDIAN)
Block(6,17,-5,OBSIDIAN)
Block(6,17,-4,OBSIDIAN)
Block(6,17,-3,OBSIDIAN)
Block(6,17,-2,OBSIDIAN)
Block(6,17,-1,OBSIDIAN)
Block(6,17,0,OBSIDIAN)
Block(6,17,1,OBSIDIAN)
Block(6,17,2,OBSIDIAN)
Block(6,17,3,OBSIDIAN)
Block(6,17,4,OBSIDIAN)
Block(6,17,5,OBSIDIAN)
Block(6,18,-7,OBSIDIAN)
Block(6,18,-6,OBSIDIAN)
Block(6,18,-5,OBSIDIAN)
Block(6,18,-4,OBSIDIAN)
Block(6,18,-3,OBSIDIAN)
Block(6,18,-2,OBSIDIAN)
Block(6,18,-1,OBSIDIAN)
Block(6,18,0,OBSIDIAN)
Block(6,18,1,OBSIDIAN)
Block(6,18,2,OBSIDIAN)
Block(6,18,3,OBSIDIAN)
Block(6,18,4,OBSIDIAN)
Block(6,18,5,OBSIDIAN)
Block(6,19,-7,OBSIDIAN)
Block(6,19,-6,OBSIDIAN)
Block(6,19,-5,OBSIDIAN)
Block(6,19,-4,OBSIDIAN)
Block(6,19,-3,OBSIDIAN)
Block(6,19,-2,OBSIDIAN)
Block(6,19,-1,OBSIDIAN)
Block(6,19,0,OBSIDIAN)
Block(6,19,1,OBSIDIAN)
Block(6,19,2,OBSIDIAN)
Block(6,19,3,OBSIDIAN)
Block(6,19,4,OBSIDIAN)
Block(6,19,5,OBSIDIAN)
Block(6,20,-7,OBSIDIAN)
Block(6,20,-6,OBSIDIAN)
Block(6,20,-5,OBSIDIAN)
Block(6,20,-4,OBSIDIAN)
Block(6,20,-3,OBSIDIAN)
Block(6,20,-2,OBSIDIAN)
Block(6,20,-1,OBSIDIAN)
Block(6,20,0,OBSIDIAN)
Block(6,20,1,OBSIDIAN)
Block(6,20,2,OBSIDIAN)
Block(6,20,3,OBSIDIAN)
Block(6,20,4,OBSIDIAN)
Block(6,20,5,OBSIDIAN)
Block(6,21,-7,OBSIDIAN)
Block(6,21,-6,OBSIDIAN)
Block(6,21,-5,OBSIDIAN)
Block(6,21,-4,OBSIDIAN)
Block(6,21,-3,OBSIDIAN)
Block(6,21,-2,OBSIDIAN)
Block(6,21,-1,OBSIDIAN)
Block(6,21,0,OBSIDIAN)
Block(6,21,1,OBSIDIAN)
Block(6,21,2,OBSIDIAN)
Block(6,21,3,OBSIDIAN)
Block(6,21,4,OBSIDIAN)
Block(6,21,5,OBSIDIAN)
Block(6,22,-7,OBSIDIAN)
Block(6,22,-6,OBSIDIAN)
Block(6,22,-5,OBSIDIAN)
Block(6,22,-4,OBSIDIAN)
Block(6,22,-3,OBSIDIAN)
Block(6,22,-2,OBSIDIAN)
Block(6,22,-1,OBSIDIAN)
Block(6,22,0,OBSIDIAN)
Block(6,22,1,OBSIDIAN)
Block(6,22,2,OBSIDIAN)
Block(6,22,3,OBSIDIAN)
Block(6,22,4,OBSIDIAN)
Block(6,22,5,OBSIDIAN)
Block(6,23,-7,OBSIDIAN)
Block(6,23,-6,OBSIDIAN)
Block(6,23,-5,OBSIDIAN)
Block(6,23,-4,OBSIDIAN)
Block(6,23,-3,OBSIDIAN)
Block(6,23,-2,OBSIDIAN)
Block(6,23,-1,OBSIDIAN)
Block(6,23,0,OBSIDIAN)
Block(6,23,1,OBSIDIAN)
Block(6,23,2,OBSIDIAN)
Block(6,23,3,OBSIDIAN)
Block(6,23,4,OBSIDIAN)
Block(6,23,5,OBSIDIAN)
Block(6,24,-7,OBSIDIAN)
Block(6,24,-6,OBSIDIAN)
Block(6,24,-5,OBSIDIAN)
Block(6,24,-4,OBSIDIAN)
Block(6,24,-3,OBSIDIAN)
Block(6,24,-2,OBSIDIAN)
Block(6,24,-1,OBSIDIAN)
Block(6,24,0,OBSIDIAN)
Block(6,24,1,OBSIDIAN)
Block(6,24,2,OBSIDIAN)
Block(6,24,3,OBSIDIAN)
Block(6,24,4,SANDSTONE)
Block(6,25,-7,OBSIDIAN)
Block(6,25,-6,OBSIDIAN)
Block(6,25,-5,OBSIDIAN)
Block(6,25,-4,OBSIDIAN)
Block(6,25,-3,OBSIDIAN)
Block(6,25,-2,OBSIDIAN)
Block(6,25,-1,OBSIDIAN)
Block(6,25,0,OBSIDIAN)
Block(6,25,1,OBSIDIAN)
Block(6,25,2,SANDSTONE)
Block(6,25,3,SANDSTONE)
Block(6,25,4,SANDSTONE)
Block(6,26,-7,OBSIDIAN)
Block(6,26,-6,OBSIDIAN)
Block(6,26,-5,OBSIDIAN)
Block(6,26,-4,OBSIDIAN)
Block(6,26,-3,OBSIDIAN)
Block(6,26,-2,OBSIDIAN)
Block(6,26,-1,OBSIDIAN)
Block(6,26,0,OBSIDIAN)
Block(6,26,1,SANDSTONE)
Block(6,26,2,SANDSTONE)
Block(6,26,3,SANDSTONE)
Block(6,26,4,SANDSTONE)
Block(6,27,-7,OBSIDIAN)
Block(6,27,-6,OBSIDIAN)
Block(6,27,-5,OBSIDIAN)
Block(6,27,-4,OBSIDIAN)
Block(6,27,-3,OBSIDIAN)
Block(6,27,-2,OBSIDIAN)
Block(6,27,-1,OBSIDIAN)
Block(6,27,0,OBSIDIAN)
Block(6,27,1,SANDSTONE)
Block(6,27,2,SANDSTONE)
Block(6,27,3,SANDSTONE)
Block(6,27,4,SANDSTONE)
Block(6,28,-7,OBSIDIAN)
Block(6,28,-6,OBSIDIAN)
Block(6,28,-5,OBSIDIAN)
Block(6,28,-4,OBSIDIAN)
Block(6,28,-3,OBSIDIAN)
Block(6,28,-2,SANDSTONE)
Block(6,28,-1,SANDSTONE)
Block(6,28,0,SANDSTONE)
Block(6,28,1,SANDSTONE)
Block(6,28,2,SANDSTONE)
Block(6,28,3,SANDSTONE)
Block(6,28,4,SANDSTONE)
Block(6,29,-7,OBSIDIAN)
Block(6,29,-6,OBSIDIAN)
Block(6,29,-5,OBSIDIAN)
Block(6,29,-4,OBSIDIAN)
Block(6,29,-3,SANDSTONE)
Block(6,29,-2,SANDSTONE)
Block(6,29,-1,SANDSTONE)
Block(6,29,0,SANDSTONE)
Block(6,29,1,SANDSTONE)
Block(6,29,2,SANDSTONE)
Block(6,29,3,SANDSTONE)
Block(6,29,4,SANDSTONE)
Block(6,30,-7,OBSIDIAN)
Block(6,30,-6,OBSIDIAN)
Block(6,30,-5,OBSIDIAN)
Block(6,30,-4,SANDSTONE)
Block(6,30,-3,SANDSTONE)
Block(6,30,-2,SANDSTONE)
Block(6,30,-1,SANDSTONE)
Block(6,30,0,SANDSTONE)
Block(6,30,1,SANDSTONE)
Block(6,30,2,SANDSTONE)
Block(6,30,3,SANDSTONE)
Block(6,30,4,SANDSTONE)
Block(6,31,-7,OBSIDIAN)
Block(6,31,-6,OBSIDIAN)
Block(6,31,-5,SANDSTONE)
Block(6,31,-4,SANDSTONE)
Block(6,31,-3,SANDSTONE)
Block(6,31,-2,SANDSTONE)
Block(6,31,-1,SANDSTONE)
Block(6,31,0,SANDSTONE)
Block(6,31,1,SANDSTONE)
Block(6,31,2,SANDSTONE)
Block(6,31,3,SANDSTONE)
Block(6,31,4,SANDSTONE)
Block(6,32,-7,OBSIDIAN)
Block(6,32,-6,OBSIDIAN)
Block(6,32,-5,SANDSTONE)
Block(6,32,-4,SANDSTONE)
Block(6,32,-3,SANDSTONE)
Block(6,32,-2,SANDSTONE)
Block(6,32,-1,SANDSTONE)
Block(6,32,0,SANDSTONE)
Block(6,32,1,SANDSTONE)
Block(6,32,2,SANDSTONE)
Block(6,32,3,SANDSTONE)
Block(6,33,-7,OBSIDIAN)
Block(6,33,-6,SANDSTONE)
Block(6,33,-5,SANDSTONE)
Block(6,33,-4,SANDSTONE)
Block(6,33,-3,SANDSTONE)
Block(6,33,-2,SANDSTONE)
Block(6,33,-1,SANDSTONE)
Block(6,33,0,SANDSTONE)
Block(6,33,1,SANDSTONE)
Block(6,33,2,SANDSTONE)
Block(6,34,-7,SANDSTONE)
Block(6,34,-6,SANDSTONE)
Block(6,34,-5,SANDSTONE)
Block(6,34,-4,SANDSTONE)
Block(6,34,-3,SANDSTONE)
Block(6,34,-2,SANDSTONE)
Block(6,34,-1,SANDSTONE)
Block(6,34,0,SANDSTONE)
Block(6,35,-7,SANDSTONE)
Block(6,35,-6,SANDSTONE)
Block(6,35,-5,SANDSTONE)
Block(6,35,-4,SANDSTONE)
Block(6,35,-3,SANDSTONE)
Block(6,35,-2,SANDSTONE)
Block(6,35,-1,SANDSTONE)
Block(6,36,-7,SANDSTONE)
Block(6,36,-6,SANDSTONE)
Block(6,36,-5,SANDSTONE)
Block(6,36,-4,SANDSTONE)
Block(6,36,-3,SANDSTONE)
Block(6,37,-7,SANDSTONE)
Block(6,37,-6,SANDSTONE)
Block(6,37,-5,SANDSTONE)
Block(6,38,-7,SANDSTONE)
Block(6,38,-6,SANDSTONE)
Block(7,0,4,SANDSTONE)
Block(7,0,5,SANDSTONE)
Block(7,0,6,SANDSTONE)
Block(7,0,7,SANDSTONE)
Block(7,0,8,SANDSTONE)
Block(7,1,3,SANDSTONE)
Block(7,1,4,SANDSTONE)
Block(7,1,5,SANDSTONE)
Block(7,1,6,SANDSTONE)
Block(7,1,7,SANDSTONE)
Block(7,1,8,SANDSTONE)
Block(7,2,2,SANDSTONE)
Block(7,2,3,SANDSTONE)
Block(7,2,4,SANDSTONE)
Block(7,2,5,SANDSTONE)
Block(7,2,6,SANDSTONE)
Block(7,2,7,SANDSTONE)
Block(7,2,8,SANDSTONE)
Block(7,3,0,SANDSTONE)
Block(7,3,1,SANDSTONE)
Block(7,3,2,SANDSTONE)
Block(7,3,3,SANDSTONE)
Block(7,3,4,SANDSTONE)
Block(7,3,5,SANDSTONE)
Block(7,3,6,SANDSTONE)
Block(7,3,7,SANDSTONE)
Block(7,3,8,SANDSTONE)
Block(7,4,-1,SANDSTONE)
Block(7,4,0,SANDSTONE)
Block(7,4,1,SANDSTONE)
Block(7,4,2,SANDSTONE)
Block(7,4,3,SANDSTONE)
Block(7,4,4,SANDSTONE)
Block(7,4,5,SANDSTONE)
Block(7,4,6,SANDSTONE)
Block(7,4,7,SANDSTONE)
Block(7,4,8,OBSIDIAN)
Block(7,5,-2,SANDSTONE)
Block(7,5,-1,SANDSTONE)
Block(7,5,0,SANDSTONE)
Block(7,5,1,SANDSTONE)
Block(7,5,2,SANDSTONE)
Block(7,5,3,SANDSTONE)
Block(7,5,4,SANDSTONE)
Block(7,5,5,SANDSTONE)
Block(7,5,6,SANDSTONE)
Block(7,5,7,SANDSTONE)
Block(7,5,8,OBSIDIAN)
Block(7,6,-4,OBSIDIAN)
Block(7,6,-3,SANDSTONE)
Block(7,6,-2,SANDSTONE)
Block(7,6,-1,SANDSTONE)
Block(7,6,0,SANDSTONE)
Block(7,6,1,SANDSTONE)
Block(7,6,2,SANDSTONE)
Block(7,6,3,SANDSTONE)
Block(7,6,4,SANDSTONE)
Block(7,6,5,SANDSTONE)
Block(7,6,6,SANDSTONE)
Block(7,6,7,OBSIDIAN)
Block(7,6,8,OBSIDIAN)
Block(7,7,-5,OBSIDIAN)
Block(7,7,-4,OBSIDIAN)
Block(7,7,-3,SANDSTONE)
Block(7,7,-2,SANDSTONE)
Block(7,7,-1,SANDSTONE)
Block(7,7,0,SANDSTONE)
Block(7,7,1,SANDSTONE)
Block(7,7,2,SANDSTONE)
Block(7,7,3,SANDSTONE)
Block(7,7,4,SANDSTONE)
Block(7,7,5,SANDSTONE)
Block(7,7,6,SANDSTONE)
Block(7,7,7,OBSIDIAN)
Block(7,7,8,OBSIDIAN)
Block(7,8,-6,OBSIDIAN)
Block(7,8,-5,OBSIDIAN)
Block(7,8,-4,OBSIDIAN)
Block(7,8,-3,SANDSTONE)
Block(7,8,-2,SANDSTONE)
Block(7,8,-1,SANDSTONE)
Block(7,8,0,SANDSTONE)
Block(7,8,1,SANDSTONE)
Block(7,8,2,SANDSTONE)
Block(7,8,3,SANDSTONE)
Block(7,8,4,SANDSTONE)
Block(7,8,5,SANDSTONE)
Block(7,8,6,OBSIDIAN)
Block(7,8,7,OBSIDIAN)
Block(7,8,8,OBSIDIAN)
Block(7,9,-7,OBSIDIAN)
Block(7,9,-6,OBSIDIAN)
Block(7,9,-5,OBSIDIAN)
Block(7,9,-4,OBSIDIAN)
Block(7,9,-3,SANDSTONE)
Block(7,9,-2,SANDSTONE)
Block(7,9,-1,SANDSTONE)
Block(7,9,0,SANDSTONE)
Block(7,9,1,SANDSTONE)
Block(7,9,2,SANDSTONE)
Block(7,9,3,SANDSTONE)
Block(7,9,4,OBSIDIAN)
Block(7,9,5,OBSIDIAN)
Block(7,9,6,OBSIDIAN)
Block(7,9,7,OBSIDIAN)
Block(7,9,8,OBSIDIAN)
Block(7,10,-7,OBSIDIAN)
Block(7,10,-6,OBSIDIAN)
Block(7,10,-5,OBSIDIAN)
Block(7,10,-4,OBSIDIAN)
Block(7,10,-3,SANDSTONE)
Block(7,10,-2,SANDSTONE)
Block(7,10,-1,SANDSTONE)
Block(7,10,0,SANDSTONE)
Block(7,10,1,SANDSTONE)
Block(7,10,2,SANDSTONE)
Block(7,10,3,SANDSTONE)
Block(7,10,4,OBSIDIAN)
Block(7,10,5,OBSIDIAN)
Block(7,10,6,OBSIDIAN)
Block(7,10,7,OBSIDIAN)
Block(7,10,8,OBSIDIAN)
Block(7,11,-7,OBSIDIAN)
Block(7,11,-6,OBSIDIAN)
Block(7,11,-5,OBSIDIAN)
Block(7,11,-4,OBSIDIAN)
Block(7,11,-3,OBSIDIAN)
Block(7,11,-2,SANDSTONE)
Block(7,11,-1,SANDSTONE)
Block(7,11,0,SANDSTONE)
Block(7,11,1,SANDSTONE)
Block(7,11,2,SANDSTONE)
Block(7,11,3,OBSIDIAN)
Block(7,11,4,OBSIDIAN)
Block(7,11,5,OBSIDIAN)
Block(7,11,6,OBSIDIAN)
Block(7,11,7,OBSIDIAN)
Block(7,11,8,OBSIDIAN)
Block(7,12,-7,OBSIDIAN)
Block(7,12,-6,OBSIDIAN)
Block(7,12,-5,OBSIDIAN)
Block(7,12,-4,OBSIDIAN)
Block(7,12,-3,OBSIDIAN)
Block(7,12,-2,OBSIDIAN)
Block(7,12,-1,OBSIDIAN)
Block(7,12,0,OBSIDIAN)
Block(7,12,1,OBSIDIAN)
Block(7,12,2,OBSIDIAN)
Block(7,12,3,OBSIDIAN)
Block(7,12,4,OBSIDIAN)
Block(7,12,5,OBSIDIAN)
Block(7,12,6,OBSIDIAN)
Block(7,12,7,OBSIDIAN)
Block(7,12,8,OBSIDIAN)
Block(7,13,-7,OBSIDIAN)
Block(7,13,-6,OBSIDIAN)
Block(7,13,-5,OBSIDIAN)
Block(7,13,-4,OBSIDIAN)
Block(7,13,-3,OBSIDIAN)
Block(7,13,-2,OBSIDIAN)
Block(7,13,-1,OBSIDIAN)
Block(7,13,0,OBSIDIAN)
Block(7,13,1,OBSIDIAN)
Block(7,13,2,OBSIDIAN)
Block(7,13,3,OBSIDIAN)
Block(7,13,4,OBSIDIAN)
Block(7,13,5,OBSIDIAN)
Block(7,13,6,OBSIDIAN)
Block(7,13,7,OBSIDIAN)
Block(7,14,-7,OBSIDIAN)
Block(7,14,-6,OBSIDIAN)
Block(7,14,-5,OBSIDIAN)
Block(7,14,-4,OBSIDIAN)
Block(7,14,-3,OBSIDIAN)
Block(7,14,-2,OBSIDIAN)
Block(7,14,-1,OBSIDIAN)
Block(7,14,0,OBSIDIAN)
Block(7,14,1,OBSIDIAN)
Block(7,14,2,OBSIDIAN)
Block(7,14,3,OBSIDIAN)
Block(7,14,4,OBSIDIAN)
Block(7,14,5,OBSIDIAN)
Block(7,14,6,OBSIDIAN)
Block(7,14,7,OBSIDIAN)
Block(7,15,-7,OBSIDIAN)
Block(7,15,-6,OBSIDIAN)
Block(7,15,-5,OBSIDIAN)
Block(7,15,-4,OBSIDIAN)
Block(7,15,-3,OBSIDIAN)
Block(7,15,-2,OBSIDIAN)
Block(7,15,-1,OBSIDIAN)
Block(7,15,0,OBSIDIAN)
Block(7,15,1,OBSIDIAN)
Block(7,15,2,OBSIDIAN)
Block(7,15,3,OBSIDIAN)
Block(7,15,4,OBSIDIAN)
Block(7,15,5,OBSIDIAN)
Block(7,15,6,OBSIDIAN)
Block(7,15,7,OBSIDIAN)
Block(7,16,-7,OBSIDIAN)
Block(7,16,-6,OBSIDIAN)
Block(7,16,-5,OBSIDIAN)
Block(7,16,-4,OBSIDIAN)
Block(7,16,-3,OBSIDIAN)
Block(7,16,-2,OBSIDIAN)
Block(7,16,-1,OBSIDIAN)
Block(7,16,0,OBSIDIAN)
Block(7,16,1,OBSIDIAN)
Block(7,16,2,OBSIDIAN)
Block(7,16,3,OBSIDIAN)
Block(7,16,4,OBSIDIAN)
Block(7,16,5,OBSIDIAN)
Block(7,16,6,OBSIDIAN)
Block(7,16,7,OBSIDIAN)
Block(7,17,-7,OBSIDIAN)
Block(7,17,-6,OBSIDIAN)
Block(7,17,-5,OBSIDIAN)
Block(7,17,-4,OBSIDIAN)
Block(7,17,-3,OBSIDIAN)
Block(7,17,-2,OBSIDIAN)
Block(7,17,-1,OBSIDIAN)
Block(7,17,0,OBSIDIAN)
Block(7,17,1,OBSIDIAN)
Block(7,17,2,OBSIDIAN)
Block(7,17,3,OBSIDIAN)
Block(7,17,4,OBSIDIAN)
Block(7,17,5,OBSIDIAN)
Block(7,17,6,OBSIDIAN)
Block(7,17,7,OBSIDIAN)
Block(7,18,-7,OBSIDIAN)
Block(7,18,-6,OBSIDIAN)
Block(7,18,-5,OBSIDIAN)
Block(7,18,-4,OBSIDIAN)
Block(7,18,-3,OBSIDIAN)
Block(7,18,-2,OBSIDIAN)
Block(7,18,-1,OBSIDIAN)
Block(7,18,0,OBSIDIAN)
Block(7,18,1,OBSIDIAN)
Block(7,18,2,OBSIDIAN)
Block(7,18,3,OBSIDIAN)
Block(7,18,4,OBSIDIAN)
Block(7,18,5,OBSIDIAN)
Block(7,18,6,OBSIDIAN)
Block(7,18,7,OBSIDIAN)
Block(7,19,-7,OBSIDIAN)
Block(7,19,-6,OBSIDIAN)
Block(7,19,-5,OBSIDIAN)
Block(7,19,-4,OBSIDIAN)
Block(7,19,-3,OBSIDIAN)
Block(7,19,-2,OBSIDIAN)
Block(7,19,-1,OBSIDIAN)
Block(7,19,0,OBSIDIAN)
Block(7,19,1,OBSIDIAN)
Block(7,19,2,OBSIDIAN)
Block(7,19,3,OBSIDIAN)
Block(7,19,4,OBSIDIAN)
Block(7,19,5,OBSIDIAN)
Block(7,19,6,OBSIDIAN)
Block(7,19,7,OBSIDIAN)
Block(7,20,-7,OBSIDIAN)
Block(7,20,-6,OBSIDIAN)
Block(7,20,-5,OBSIDIAN)
Block(7,20,-4,OBSIDIAN)
Block(7,20,-3,OBSIDIAN)
Block(7,20,-2,OBSIDIAN)
Block(7,20,-1,OBSIDIAN)
Block(7,20,0,OBSIDIAN)
Block(7,20,1,OBSIDIAN)
Block(7,20,2,OBSIDIAN)
Block(7,20,3,OBSIDIAN)
Block(7,20,4,OBSIDIAN)
Block(7,20,5,OBSIDIAN)
Block(7,20,6,OBSIDIAN)
Block(7,20,7,OBSIDIAN)
Block(7,21,-7,OBSIDIAN)
Block(7,21,-6,OBSIDIAN)
Block(7,21,-5,OBSIDIAN)
Block(7,21,-4,OBSIDIAN)
Block(7,21,-3,OBSIDIAN)
Block(7,21,-2,OBSIDIAN)
Block(7,21,-1,OBSIDIAN)
Block(7,21,0,OBSIDIAN)
Block(7,21,1,OBSIDIAN)
Block(7,21,2,OBSIDIAN)
Block(7,21,3,OBSIDIAN)
Block(7,21,4,OBSIDIAN)
Block(7,21,5,OBSIDIAN)
Block(7,21,6,OBSIDIAN)
Block(7,21,7,OBSIDIAN)
Block(7,22,-7,OBSIDIAN)
Block(7,22,-6,OBSIDIAN)
Block(7,22,-5,OBSIDIAN)
Block(7,22,-4,OBSIDIAN)
Block(7,22,-3,OBSIDIAN)
Block(7,22,-2,OBSIDIAN)
Block(7,22,-1,OBSIDIAN)
Block(7,22,0,OBSIDIAN)
Block(7,22,1,OBSIDIAN)
Block(7,22,2,OBSIDIAN)
Block(7,22,3,OBSIDIAN)
Block(7,22,4,OBSIDIAN)
Block(7,22,5,OBSIDIAN)
Block(7,22,6,OBSIDIAN)
Block(7,23,-7,OBSIDIAN)
Block(7,23,-6,OBSIDIAN)
Block(7,23,-5,OBSIDIAN)
Block(7,23,-4,OBSIDIAN)
Block(7,23,-3,OBSIDIAN)
Block(7,23,-2,OBSIDIAN)
Block(7,23,-1,OBSIDIAN)
Block(7,23,0,OBSIDIAN)
Block(7,23,1,OBSIDIAN)
Block(7,23,2,OBSIDIAN)
Block(7,23,3,OBSIDIAN)
Block(7,23,4,OBSIDIAN)
Block(7,23,5,OBSIDIAN)
Block(7,23,6,OBSIDIAN)
Block(7,24,-7,OBSIDIAN)
Block(7,24,-6,OBSIDIAN)
Block(7,24,-5,OBSIDIAN)
Block(7,24,-4,OBSIDIAN)
Block(7,24,-3,OBSIDIAN)
Block(7,24,-2,OBSIDIAN)
Block(7,24,-1,OBSIDIAN)
Block(7,24,0,OBSIDIAN)
Block(7,24,1,OBSIDIAN)
Block(7,24,2,OBSIDIAN)
Block(7,24,3,SANDSTONE)
Block(7,24,4,SANDSTONE)
Block(7,24,5,SANDSTONE)
Block(7,24,6,SANDSTONE)
Block(7,25,-7,OBSIDIAN)
Block(7,25,-6,OBSIDIAN)
Block(7,25,-5,OBSIDIAN)
Block(7,25,-4,OBSIDIAN)
Block(7,25,-3,OBSIDIAN)
Block(7,25,-2,OBSIDIAN)
Block(7,25,-1,OBSIDIAN)
Block(7,25,0,OBSIDIAN)
Block(7,25,1,OBSIDIAN)
Block(7,25,2,SANDSTONE)
Block(7,25,3,SANDSTONE)
Block(7,25,4,SANDSTONE)
Block(7,25,5,SANDSTONE)
Block(7,25,6,SANDSTONE)
Block(7,26,-7,OBSIDIAN)
Block(7,26,-6,OBSIDIAN)
Block(7,26,-5,OBSIDIAN)
Block(7,26,-4,OBSIDIAN)
Block(7,26,-3,OBSIDIAN)
Block(7,26,-2,OBSIDIAN)
Block(7,26,-1,OBSIDIAN)
Block(7,26,0,OBSIDIAN)
Block(7,26,1,SANDSTONE)
Block(7,26,2,SANDSTONE)
Block(7,26,3,SANDSTONE)
Block(7,26,4,SANDSTONE)
Block(7,26,5,SANDSTONE)
Block(7,26,6,SANDSTONE)
Block(7,27,-7,OBSIDIAN)
Block(7,27,-6,OBSIDIAN)
Block(7,27,-5,OBSIDIAN)
Block(7,27,-4,OBSIDIAN)
Block(7,27,-3,OBSIDIAN)
Block(7,27,-2,OBSIDIAN)
Block(7,27,-1,OBSIDIAN)
Block(7,27,0,SANDSTONE)
Block(7,27,1,SANDSTONE)
Block(7,27,2,SANDSTONE)
Block(7,27,3,SANDSTONE)
Block(7,27,4,SANDSTONE)
Block(7,27,5,SANDSTONE)
Block(7,27,6,SANDSTONE)
Block(7,28,-7,OBSIDIAN)
Block(7,28,-6,OBSIDIAN)
Block(7,28,-5,OBSIDIAN)
Block(7,28,-4,OBSIDIAN)
Block(7,28,-3,OBSIDIAN)
Block(7,28,-2,SANDSTONE)
Block(7,28,-1,SANDSTONE)
Block(7,28,0,SANDSTONE)
Block(7,28,1,SANDSTONE)
Block(7,28,2,SANDSTONE)
Block(7,28,3,SANDSTONE)
Block(7,28,4,SANDSTONE)
Block(7,28,5,SANDSTONE)
Block(7,28,6,SANDSTONE)
Block(7,29,-7,OBSIDIAN)
Block(7,29,-6,OBSIDIAN)
Block(7,29,-5,OBSIDIAN)
Block(7,29,-4,OBSIDIAN)
Block(7,29,-3,SANDSTONE)
Block(7,29,-2,SANDSTONE)
Block(7,29,-1,SANDSTONE)
Block(7,29,0,SANDSTONE)
Block(7,29,1,SANDSTONE)
Block(7,29,2,SANDSTONE)
Block(7,29,3,SANDSTONE)
Block(7,29,4,SANDSTONE)
Block(7,29,5,SANDSTONE)
Block(7,29,6,SANDSTONE)
Block(7,30,-7,OBSIDIAN)
Block(7,30,-6,OBSIDIAN)
Block(7,30,-5,OBSIDIAN)
Block(7,30,-4,SANDSTONE)
Block(7,30,-3,SANDSTONE)
Block(7,30,-2,SANDSTONE)
Block(7,30,-1,SANDSTONE)
Block(7,30,0,SANDSTONE)
Block(7,30,1,SANDSTONE)
Block(7,30,2,SANDSTONE)
Block(7,30,3,SANDSTONE)
Block(7,30,4,SANDSTONE)
Block(7,30,5,SANDSTONE)
Block(7,31,-7,OBSIDIAN)
Block(7,31,-6,OBSIDIAN)
Block(7,31,-5,SANDSTONE)
Block(7,31,-4,SANDSTONE)
Block(7,31,-3,SANDSTONE)
Block(7,31,-2,SANDSTONE)
Block(7,31,-1,SANDSTONE)
Block(7,31,0,SANDSTONE)
Block(7,31,1,SANDSTONE)
Block(7,31,2,SANDSTONE)
Block(7,31,3,SANDSTONE)
Block(7,31,4,SANDSTONE)
Block(7,32,-7,OBSIDIAN)
Block(7,32,-6,OBSIDIAN)
Block(7,32,-5,SANDSTONE)
Block(7,32,-4,SANDSTONE)
Block(7,32,-3,SANDSTONE)
Block(7,32,-2,SANDSTONE)
Block(7,32,-1,SANDSTONE)
Block(7,32,0,SANDSTONE)
Block(7,32,1,SANDSTONE)
Block(7,32,2,SANDSTONE)
Block(7,32,3,SANDSTONE)
Block(7,33,-7,OBSIDIAN)
Block(7,33,-6,OBSIDIAN)
Block(7,33,-5,SANDSTONE)
Block(7,33,-4,SANDSTONE)
Block(7,33,-3,SANDSTONE)
Block(7,33,-2,SANDSTONE)
Block(7,33,-1,SANDSTONE)
Block(7,33,0,SANDSTONE)
Block(7,33,1,SANDSTONE)
Block(7,34,-7,OBSIDIAN)
Block(7,34,-6,SANDSTONE)
Block(7,34,-5,SANDSTONE)
Block(7,34,-4,SANDSTONE)
Block(7,34,-3,SANDSTONE)
Block(7,34,-2,SANDSTONE)
Block(7,34,-1,SANDSTONE)
Block(7,34,0,SANDSTONE)
Block(7,35,-7,SANDSTONE)
Block(7,35,-6,SANDSTONE)
Block(7,35,-5,SANDSTONE)
Block(7,35,-4,SANDSTONE)
Block(7,35,-3,SANDSTONE)
Block(7,35,-2,SANDSTONE)
Block(7,36,-7,SANDSTONE)
Block(7,36,-6,SANDSTONE)
Block(7,36,-5,SANDSTONE)
Block(7,36,-4,SANDSTONE)
Block(7,37,-7,SANDSTONE)
Block(7,37,-6,SANDSTONE)
Block(7,37,-5,SANDSTONE)
Block(7,38,-7,SANDSTONE)

#######################################################################
# +-----------------------------------------------------------------+ #
# |                             Branches                            | #
# +-----------------------------------------------------------------+ #
#######################################################################

Branch(0,0,16,true,DesertSpike_Huge_01C1R4,NORTH,100.0,0)
Branch(0,0,-16,true,DesertSpike_Huge_01C1R2,NORTH,100.0,0)

#######################################################################
# +-----------------------------------------------------------------+ #
# |                             Entities                            | #
# +-----------------------------------------------------------------+ #
#######################################################################


#######################################################################
# +-----------------------------------------------------------------+ #
# |                            Particles                            | #
# +-----------------------------------------------------------------+ #
#######################################################################


#######################################################################
# +-----------------------------------------------------------------+ #
# |                             Spawners                            | #
# +-----------------------------------------------------------------+ #
#######################################################################


#######################################################################
# +-----------------------------------------------------------------+ #
# |                             ModData                             | #
# +-----------------------------------------------------------------+ #
#######################################################################

