
#######################################################################
# +-----------------------------------------------------------------+ #
# |                            BO3 object                           | #
# +-----------------------------------------------------------------+ #
#######################################################################

Author: NLBlackHeavenNL

Description: No description given

Version: 3

SettingsMode: WriteWithoutComments


#######################################################################
# +-----------------------------------------------------------------+ #
# |                          Main settings                          | #
# +-----------------------------------------------------------------+ #
#######################################################################

Tree: true

Frequency: 1

Rarity: 100.0

RotateRandomly: false

SpawnHeight: highestSolidBlock

SpawnHeightOffset: -1

SpawnHeightVariance: 0

##############################
# Height Limits for the BO3. #
##############################

MinHeight: 0

MaxHeight: 255

######################
# Extrusion settings #
######################

ExtrudeMode: None

ExtrudeThroughBlocks: AIR

MaxBranchDepth: 10

ExcludedBiomes: All


#######################################################################
# +-----------------------------------------------------------------+ #
# |                      Source block settings                      | #
# +-----------------------------------------------------------------+ #
#######################################################################

SourceBlocks: AIR,GRASS,DIRT,biomesoplenty:dirt,biomesoplenty:grass

MaxPercentageOutsideSourceBlock: 0

OutsideSourceBlock: placeAnyway

DoReplaceBlocks: true

IsOTGPlus: false


#######################################################################
# +-----------------------------------------------------------------+ #
# |                              Blocks                             | #
# +-----------------------------------------------------------------+ #
#######################################################################

Block(-4,7,2,dynamictreesbop:leaves1:8)
Block(-3,7,1,dynamictreesbop:leaves1:8)
Block(-3,7,2,dynamictreesbop:leaves1:9)
Block(-3,7,3,dynamictreesbop:leaves1:8)
Block(-3,7,4,dynamictreesbop:leaves1:8)
Block(-3,8,2,dynamictreesbop:leaves1:8)
Block(-3,9,2,dynamictreesbop:leaves1:8)
Block(-2,7,0,dynamictreesbop:leaves1:8)
Block(-2,7,1,dynamictreesbop:leaves1:9)
Block(-2,7,2,dynamictreesbop:firbranch)
Block(-2,7,3,dynamictreesbop:leaves1:9)
Block(-2,7,4,dynamictreesbop:leaves1:9)
Block(-2,7,5,dynamictreesbop:leaves1:8)
Block(-2,8,1,dynamictreesbop:leaves1:8)
Block(-2,8,2,dynamictreesbop:leaves1:8)
Block(-2,8,3,dynamictreesbop:leaves1:8)
Block(-2,8,4,dynamictreesbop:leaves1:8)
Block(-2,9,1,dynamictreesbop:leaves1:8)
Block(-2,9,2,dynamictreesbop:leaves1:9)
Block(-2,9,3,dynamictreesbop:leaves1:8)
Block(-2,10,2,dynamictreesbop:leaves1:8)
Block(-2,12,2,dynamictreesbop:leaves1:8)
Block(-1,7,1,dynamictreesbop:leaves1:8)
Block(-1,7,2,dynamictreesbop:firbranch:1)
Block(-1,7,3,dynamictreesbop:leaves1:9)
Block(-1,7,4,dynamictreesbop:firbranch)
Block(-1,7,5,dynamictreesbop:leaves1:9)
Block(-1,7,6,dynamictreesbop:leaves1:8)
Block(-1,8,2,dynamictreesbop:leaves1:8)
Block(-1,8,3,dynamictreesbop:leaves1:8)
Block(-1,8,4,dynamictreesbop:leaves1:8)
Block(-1,8,5,dynamictreesbop:leaves1:8)
Block(-1,9,0,dynamictreesbop:leaves1:8)
Block(-1,9,1,dynamictreesbop:leaves1:9)
Block(-1,9,2,dynamictreesbop:firbranch)
Block(-1,9,3,dynamictreesbop:leaves1:9)
Block(-1,9,4,dynamictreesbop:leaves1:8)
Block(-1,10,1,dynamictreesbop:leaves1:8)
Block(-1,10,2,dynamictreesbop:leaves1:8)
Block(-1,10,3,dynamictreesbop:leaves1:8)
Block(-1,12,1,dynamictreesbop:leaves1:8)
Block(-1,12,2,dynamictreesbop:leaves1:9)
Block(-1,12,3,dynamictreesbop:leaves1:8)
Block(-1,13,2,dynamictreesbop:leaves1:8)
Block(0,0,2,dynamictrees:rootydirt:0)
Block(0,1,2,dynamictreesbop:firbranch:6)
Block(0,2,2,dynamictreesbop:firbranch:6)
Block(0,3,2,dynamictreesbop:firbranch:5)
Block(0,4,2,dynamictreesbop:firbranch:5)
Block(0,5,2,dynamictreesbop:firbranch:5)
Block(0,6,2,dynamictreesbop:firbranch:4)
Block(0,7,0,dynamictreesbop:leaves1:8)
Block(0,7,1,dynamictreesbop:firbranch:1)
Block(0,7,2,dynamictreesbop:firbranch:4)
Block(0,7,3,dynamictreesbop:firbranch:1)
Block(0,7,4,dynamictreesbop:firbranch:1)
Block(0,7,5,dynamictreesbop:leaves1:8)
Block(0,8,1,dynamictreesbop:leaves1:8)
Block(0,8,2,dynamictreesbop:firbranch:2)
Block(0,9,-1,dynamictreesbop:leaves1:8)
Block(0,9,0,dynamictreesbop:leaves1:9)
Block(0,9,1,dynamictreesbop:firbranch)
Block(0,9,2,dynamictreesbop:firbranch:2)
Block(0,9,3,dynamictreesbop:firbranch)
Block(0,9,4,dynamictreesbop:leaves1:9)
Block(0,9,5,dynamictreesbop:leaves1:8)
Block(0,10,0,dynamictreesbop:leaves1:8)
Block(0,10,1,dynamictreesbop:leaves1:8)
Block(0,10,2,dynamictreesbop:firbranch:1)
Block(0,10,3,dynamictreesbop:leaves1:8)
Block(0,10,4,dynamictreesbop:leaves1:8)
Block(0,11,2,dynamictreesbop:firbranch:1)
Block(0,12,0,dynamictreesbop:leaves1:8)
Block(0,12,1,dynamictreesbop:leaves1:9)
Block(0,12,2,dynamictreesbop:firbranch)
Block(0,12,3,dynamictreesbop:leaves1:9)
Block(0,12,4,dynamictreesbop:leaves1:8)
Block(0,13,1,dynamictreesbop:leaves1:8)
Block(0,13,2,dynamictreesbop:leaves1:11)
Block(0,13,3,dynamictreesbop:leaves1:8)
Block(0,14,2,dynamictreesbop:leaves1:10)
Block(0,15,2,dynamictreesbop:leaves1:8)
Block(1,5,0,dynamictreesbop:leaves1:8)
Block(1,5,2,dynamictreesbop:firbranch:1)
Block(1,6,1,dynamictreesbop:leaves1:8)
Block(1,7,-1,dynamictreesbop:leaves1:8)
Block(1,7,0,dynamictreesbop:leaves1:9)
Block(1,7,1,dynamictreesbop:firbranch)
Block(1,7,3,dynamictreesbop:firbranch)
Block(1,7,4,dynamictreesbop:leaves1:9)
Block(1,7,5,dynamictreesbop:leaves1:8)
Block(1,8,0,dynamictreesbop:leaves1:8)
Block(1,8,1,dynamictreesbop:leaves1:8)
Block(1,8,2,dynamictreesbop:leaves1:8)
Block(1,8,3,dynamictreesbop:leaves1:8)
Block(1,8,4,dynamictreesbop:leaves1:8)
Block(1,9,0,dynamictreesbop:leaves1:8)
Block(1,9,1,dynamictreesbop:leaves1:9)
Block(1,9,2,dynamictreesbop:firbranch)
Block(1,9,3,dynamictreesbop:leaves1:9)
Block(1,9,4,dynamictreesbop:leaves1:8)
Block(1,10,1,dynamictreesbop:leaves1:8)
Block(1,10,2,dynamictreesbop:leaves1:8)
Block(1,10,3,dynamictreesbop:leaves1:8)
Block(1,12,1,dynamictreesbop:leaves1:8)
Block(1,12,2,dynamictreesbop:leaves1:9)
Block(1,12,3,dynamictreesbop:leaves1:8)
Block(1,13,2,dynamictreesbop:leaves1:8)
Block(2,5,-1,dynamictreesbop:leaves1:8)
Block(2,5,0,dynamictreesbop:leaves1:9)
Block(2,5,1,dynamictreesbop:firbranch)
Block(2,5,2,dynamictreesbop:firbranch:1)
Block(2,6,0,dynamictreesbop:leaves1:8)
Block(2,6,1,dynamictreesbop:leaves1:8)
Block(2,7,0,dynamictreesbop:leaves1:8)
Block(2,7,1,dynamictreesbop:leaves1:9)
Block(2,7,2,dynamictreesbop:leaves1:8)
Block(2,7,3,dynamictreesbop:leaves1:9)
Block(2,7,4,dynamictreesbop:leaves1:8)
Block(2,8,1,dynamictreesbop:leaves1:8)
Block(2,8,3,dynamictreesbop:leaves1:8)
Block(2,9,1,dynamictreesbop:leaves1:8)
Block(2,9,2,dynamictreesbop:leaves1:9)
Block(2,9,3,dynamictreesbop:leaves1:8)
Block(2,10,2,dynamictreesbop:leaves1:8)
Block(2,12,2,dynamictreesbop:leaves1:8)
Block(3,5,0,dynamictreesbop:leaves1:8)
Block(3,5,1,dynamictreesbop:leaves1:9)
Block(3,5,2,dynamictreesbop:leaves1:8)
Block(3,6,1,dynamictreesbop:leaves1:8)
Block(3,7,1,dynamictreesbop:leaves1:8)
Block(3,7,3,dynamictreesbop:leaves1:8)
Block(3,9,2,dynamictreesbop:leaves1:8)
Block(4,5,1,dynamictreesbop:leaves1:8)

#######################################################################
# +-----------------------------------------------------------------+ #
# |                            BO3 checks                           | #
# +-----------------------------------------------------------------+ #
#######################################################################

BlockCheck(0,-1,2,GRASS,DIRT,biomesoplenty:grass,biomesoplenty:dirt)

#######################################################################
# +-----------------------------------------------------------------+ #
# |                             Branches                            | #
# +-----------------------------------------------------------------+ #
#######################################################################


#######################################################################
# +-----------------------------------------------------------------+ #
# |                             Entities                            | #
# +-----------------------------------------------------------------+ #
#######################################################################


#######################################################################
# +-----------------------------------------------------------------+ #
# |                            Particles                            | #
# +-----------------------------------------------------------------+ #
#######################################################################


#######################################################################
# +-----------------------------------------------------------------+ #
# |                             Spawners                            | #
# +-----------------------------------------------------------------+ #
#######################################################################


#######################################################################
# +-----------------------------------------------------------------+ #
# |                             ModData                             | #
# +-----------------------------------------------------------------+ #
#######################################################################

