
#######################################################################
# +-----------------------------------------------------------------+ #
# |                            BO3 object                           | #
# +-----------------------------------------------------------------+ #
#######################################################################

Author: NLBlackHeavenNL

Description: No description given

Version: 3

SettingsMode: WriteWithoutComments


#######################################################################
# +-----------------------------------------------------------------+ #
# |                          Main settings                          | #
# +-----------------------------------------------------------------+ #
#######################################################################

Tree: true

Frequency: 1

Rarity: 100.0

RotateRandomly: false

SpawnHeight: highestSolidBlock

SpawnHeightOffset: -1

SpawnHeightVariance: 0

##############################
# Height Limits for the BO3. #
##############################

MinHeight: 0

MaxHeight: 255

######################
# Extrusion settings #
######################

ExtrudeMode: None

ExtrudeThroughBlocks: AIR

MaxBranchDepth: 10

ExcludedBiomes: All


#######################################################################
# +-----------------------------------------------------------------+ #
# |                      Source block settings                      | #
# +-----------------------------------------------------------------+ #
#######################################################################

SourceBlocks: AIR,GRASS,DIRT,biomesoplenty:dirt,biomesoplenty:grass

MaxPercentageOutsideSourceBlock: 0

OutsideSourceBlock: placeAnyway

DoReplaceBlocks: true

IsOTGPlus: false


#######################################################################
# +-----------------------------------------------------------------+ #
# |                              Blocks                             | #
# +-----------------------------------------------------------------+ #
#######################################################################

Block(-3,9,2,dynamictreesbop:leaves1:8)
Block(-2,9,1,dynamictreesbop:leaves1:8)
Block(-2,9,2,dynamictreesbop:leaves1:9)
Block(-2,9,3,dynamictreesbop:leaves1:8)
Block(-2,10,2,dynamictreesbop:leaves1:8)
Block(-2,13,2,dynamictreesbop:leaves1:8)
Block(-1,0,1,GRASS)
Block(-1,0,2,GRASS)
Block(-1,0,3,GRASS)
Block(-1,1,1,dynamictrees:trunkshell:5)
Block(-1,1,2,dynamictrees:trunkshell:6)
Block(-1,1,3,dynamictrees:trunkshell:7)
Block(-1,2,1,dynamictrees:trunkshell:5)
Block(-1,2,2,dynamictrees:trunkshell:6)
Block(-1,2,3,dynamictrees:trunkshell:7)
Block(-1,9,0,dynamictreesbop:leaves1:8)
Block(-1,9,1,dynamictreesbop:leaves1:9)
Block(-1,9,2,dynamictreesbop:firbranch)
Block(-1,9,3,dynamictreesbop:leaves1:9)
Block(-1,9,4,dynamictreesbop:leaves1:8)
Block(-1,10,1,dynamictreesbop:leaves1:8)
Block(-1,10,2,dynamictreesbop:leaves1:8)
Block(-1,10,3,dynamictreesbop:leaves1:8)
Block(-1,13,1,dynamictreesbop:leaves1:8)
Block(-1,13,2,dynamictreesbop:leaves1:9)
Block(-1,13,3,dynamictreesbop:leaves1:8)
Block(-1,14,2,dynamictreesbop:leaves1:8)
Block(0,0,1,GRASS)
Block(0,0,2,dynamictrees:rootydirt:0)
Block(0,0,3,GRASS)
Block(0,1,1,dynamictrees:trunkshell)
Block(0,1,2,dynamictreesbop:firbranch:9)
Block(0,1,3,dynamictrees:trunkshell:0)
Block(0,2,1,dynamictrees:trunkshell)
Block(0,2,2,dynamictreesbop:firbranch:8)
Block(0,2,3,dynamictrees:trunkshell:0)
Block(0,3,2,dynamictreesbop:firbranch:7)
Block(0,4,2,dynamictreesbop:firbranch:6)
Block(0,5,2,dynamictreesbop:firbranch:5)
Block(0,6,2,dynamictreesbop:firbranch:4)
Block(0,7,2,dynamictreesbop:firbranch:4)
Block(0,8,2,dynamictreesbop:firbranch:2)
Block(0,9,-1,dynamictreesbop:leaves1:8)
Block(0,9,0,dynamictreesbop:leaves1:9)
Block(0,9,1,dynamictreesbop:firbranch)
Block(0,9,2,dynamictreesbop:firbranch:1)
Block(0,9,3,dynamictreesbop:leaves1:8)
Block(0,10,0,dynamictreesbop:leaves1:8)
Block(0,10,1,dynamictreesbop:leaves1:8)
Block(0,10,2,dynamictreesbop:firbranch:1)
Block(0,11,2,dynamictreesbop:firbranch:1)
Block(0,12,2,dynamictreesbop:firbranch:1)
Block(0,13,0,dynamictreesbop:leaves1:8)
Block(0,13,1,dynamictreesbop:leaves1:9)
Block(0,13,2,dynamictreesbop:firbranch)
Block(0,13,3,dynamictreesbop:leaves1:9)
Block(0,13,4,dynamictreesbop:leaves1:8)
Block(0,14,1,dynamictreesbop:leaves1:8)
Block(0,14,2,dynamictreesbop:leaves1:11)
Block(0,14,3,dynamictreesbop:leaves1:8)
Block(0,15,2,dynamictreesbop:leaves1:10)
Block(0,16,2,dynamictreesbop:leaves1:8)
Block(1,0,1,GRASS)
Block(1,0,2,GRASS)
Block(1,0,3,GRASS)
Block(1,1,1,dynamictrees:trunkshell:3)
Block(1,1,2,dynamictrees:trunkshell:2)
Block(1,1,3,dynamictrees:trunkshell:1)
Block(1,2,1,dynamictrees:trunkshell:3)
Block(1,2,2,dynamictrees:trunkshell:2)
Block(1,2,3,dynamictrees:trunkshell:1)
Block(1,9,0,dynamictreesbop:leaves1:8)
Block(1,9,1,dynamictreesbop:leaves1:9)
Block(1,9,2,dynamictreesbop:leaves1:8)
Block(1,10,1,dynamictreesbop:leaves1:8)
Block(1,13,1,dynamictreesbop:leaves1:8)
Block(1,13,2,dynamictreesbop:leaves1:9)
Block(1,13,3,dynamictreesbop:leaves1:8)
Block(1,14,2,dynamictreesbop:leaves1:8)
Block(2,9,1,dynamictreesbop:leaves1:8)
Block(2,13,2,dynamictreesbop:leaves1:8)

#######################################################################
# +-----------------------------------------------------------------+ #
# |                            BO3 checks                           | #
# +-----------------------------------------------------------------+ #
#######################################################################

BlockCheck(0,-1,2,GRASS,DIRT,biomesoplenty:grass,biomesoplenty:dirt)

#######################################################################
# +-----------------------------------------------------------------+ #
# |                             Branches                            | #
# +-----------------------------------------------------------------+ #
#######################################################################


#######################################################################
# +-----------------------------------------------------------------+ #
# |                             Entities                            | #
# +-----------------------------------------------------------------+ #
#######################################################################


#######################################################################
# +-----------------------------------------------------------------+ #
# |                            Particles                            | #
# +-----------------------------------------------------------------+ #
#######################################################################


#######################################################################
# +-----------------------------------------------------------------+ #
# |                             Spawners                            | #
# +-----------------------------------------------------------------+ #
#######################################################################


#######################################################################
# +-----------------------------------------------------------------+ #
# |                             ModData                             | #
# +-----------------------------------------------------------------+ #
#######################################################################

