
#######################################################################
# +-----------------------------------------------------------------+ #
# |                            BO4 object                           | #
# +-----------------------------------------------------------------+ #
#######################################################################

Author: NLBlackEagle

Description: No description given

SettingsMode: WriteWithoutComments


#######################################################################
# +-----------------------------------------------------------------+ #
# |                          Main settings                          | #
# +-----------------------------------------------------------------+ #
#######################################################################

FixedRotation: 

Frequency: 0

SpawnHeight: highestBlock

UseCenterForHighestBlock: true

##############################
# Height Limits for the BO4. #
##############################

MinHeight: 0

MaxHeight: 255

InheritBO3: 

InheritBO3Rotation: NORTH

OverrideChildSettings: true

OverrideParentHeight: false

CanOverride: true

BranchFrequency: 0

BranchFrequencyGroup: 

MustBeBelowOther: false

MustBeInside: 

CannotBeInside: 

ReplacesBO3: 

MustBeInsideWorldBorders: false

CanSpawnOnWater: true

SpawnOnWaterOnly: false

SpawnUnderWater: false

SpawnAtWaterLevel: false

HeightOffset: 0

RemoveAir: false

ReplaceAbove: 

ReplaceBelow: 

ReplaceWithBiomeBlocks: false

ReplaceWithSurfaceBlock: GRASS

ReplaceWithGroundBlock: DIRT

ReplaceWithStoneBlock: STONE

SmoothRadius: 0

SmoothHeightOffset: 0

SmoothStartTop: false

SmoothStartWood: false

SmoothingSurfaceBlock: 

SmoothingGroundBlock: 

BO3Group: 

IsSpawnPoint: false

DoReplaceBlocks: true


#######################################################################
# +-----------------------------------------------------------------+ #
# |                              Blocks                             | #
# +-----------------------------------------------------------------+ #
#######################################################################

Block(-8,2,-7,CONCRETE:8)
Block(-8,2,-6,CONCRETE:8)
Block(-8,2,-5,CONCRETE:8)
Block(-8,2,-4,CONCRETE:8)
Block(-8,2,-3,CONCRETE:8)
Block(-8,2,-2,CONCRETE:8)
Block(-8,3,-7,rustic:iron_lattice:0)
Block(-8,3,-6,rustic:iron_lattice:0)
Block(-8,3,-5,rustic:iron_lattice:0)
Block(-8,3,-4,rustic:iron_lattice:0)
Block(-8,3,-3,rustic:iron_lattice:0)
Block(-8,3,-2,rustic:iron_lattice:0)
Block(-8,4,-7,rustic:iron_lattice:0)
Block(-8,4,-6,rustic:iron_lattice:0)
Block(-8,4,-5,rustic:iron_lattice:0)
Block(-8,4,-4,rustic:iron_lattice:0)
Block(-8,4,-3,rustic:iron_lattice:0)
Block(-8,4,-2,rustic:iron_lattice:0)
Block(-8,5,-7,rustic:iron_lattice:0)
Block(-8,5,-6,rustic:iron_lattice:0)
Block(-8,5,-5,rustic:iron_lattice:0)
Block(-8,5,-4,rustic:iron_lattice:0)
Block(-8,5,-3,rustic:iron_lattice:0)
Block(-8,5,-2,rustic:iron_lattice:0)
Block(-7,2,-7,CONCRETE:8)
Block(-7,2,-6,CONCRETE:8)
Block(-7,2,-5,CONCRETE:8)
Block(-7,2,-4,CONCRETE:8)
Block(-7,2,-3,CONCRETE:8)
Block(-7,2,-2,CONCRETE:8)
Block(-7,2,-1,CONCRETE:8)
Block(-7,3,-4,inspirations:path)
Block(-7,3,-3,inspirations:path)
Block(-7,3,-2,rustic:iron_lattice:0)
Block(-7,3,-1,rustic:iron_lattice:0)
Block(-7,4,-2,rustic:iron_lattice:0)
Block(-7,4,-1,rustic:iron_lattice:0)
Block(-7,5,-2,rustic:iron_lattice:0)
Block(-7,5,-1,rustic:iron_lattice:0)
Block(-6,2,-5,CONCRETE:8)
Block(-6,2,-4,CONCRETE:8)
Block(-6,2,-3,CONCRETE:8)
Block(-6,2,-2,CONCRETE:8)
Block(-6,2,-1,CONCRETE:8)
Block(-6,2,0,CONCRETE:8)
Block(-6,3,-3,inspirations:path)
Block(-6,3,-1,rustic:iron_lattice:0)
Block(-6,3,0,rustic:iron_lattice:0)
Block(-6,4,-1,rustic:iron_lattice:0)
Block(-6,4,0,rustic:iron_lattice:0)
Block(-6,5,-1,rustic:iron_lattice:0)
Block(-6,5,0,rustic:iron_lattice:0)
Block(-5,2,-5,CONCRETE:8)
Block(-5,2,-4,CONCRETE:8)
Block(-5,2,-3,CONCRETE:8)
Block(-5,2,-2,CONCRETE:8)
Block(-5,2,-1,CONCRETE:8)
Block(-5,2,0,CONCRETE:8)
Block(-5,2,1,CONCRETE:8)
Block(-5,3,0,rustic:iron_lattice:0)
Block(-5,3,1,rustic:iron_lattice:0)
Block(-5,4,0,rustic:iron_lattice:0)
Block(-5,4,1,rustic:iron_lattice:0)
Block(-5,5,0,rustic:iron_lattice:0)
Block(-5,5,1,rustic:iron_lattice:0)
Block(-4,0,-2,CONCRETE:11)
Block(-4,0,-1,CONCRETE:11)
Block(-4,0,0,CONCRETE:11)
Block(-4,1,-2,CONCRETE:11)
Block(-4,1,-1,CONCRETE:11)
Block(-4,1,0,CONCRETE:11)
Block(-4,2,-7,CONCRETE:8)
Block(-4,2,-6,CONCRETE:8)
Block(-4,2,-5,CONCRETE:8)
Block(-4,2,-4,CONCRETE:8)
Block(-4,2,-3,CONCRETE:8)
Block(-4,2,-2,CONCRETE:8)
Block(-4,2,-1,CONCRETE:8)
Block(-4,2,0,CONCRETE:8)
Block(-4,2,1,CONCRETE:8)
Block(-4,3,-2,inspirations:path)
Block(-4,3,-1,inspirations:path)
Block(-4,3,1,rustic:iron_lattice:0)
Block(-4,4,1,rustic:iron_lattice:0)
Block(-4,5,1,rustic:iron_lattice:0)
Block(-3,0,-2,CONCRETE:11)
Block(-3,0,-1,CONCRETE:11)
Block(-3,0,0,CONCRETE:11)
Block(-3,1,-2,CONCRETE:11)
Block(-3,1,-1,CONCRETE:11)
Block(-3,1,0,CONCRETE:11)
Block(-3,2,-5,CONCRETE:8)
Block(-3,2,-4,CONCRETE:8)
Block(-3,2,-3,CONCRETE:8)
Block(-3,2,-2,CONCRETE:8)
Block(-3,2,-1,CONCRETE:8)
Block(-3,2,0,CONCRETE:8)
Block(-3,2,1,CONCRETE:8)
Block(-3,3,-4,inspirations:path)
Block(-3,3,-3,inspirations:path)
Block(-3,3,-2,inspirations:path)
Block(-3,3,1,rustic:iron_lattice:0)
Block(-3,4,1,rustic:iron_lattice:0)
Block(-3,5,1,rustic:iron_lattice:0)
Block(-2,0,-2,CONCRETE:11)
Block(-2,0,-1,CONCRETE:11)
Block(-2,0,0,CONCRETE:11)
Block(-2,1,-2,CONCRETE:11)
Block(-2,1,-1,SEA_LANTERN:0)
Block(-2,1,0,CONCRETE:11)
Block(-2,2,-5,CONCRETE:8)
Block(-2,2,-4,CONCRETE:8)
Block(-2,2,-3,CONCRETE:8)
Block(-2,2,-2,CONCRETE:8)
Block(-2,2,-1,STAINED_GLASS:15)
Block(-2,2,0,CONCRETE:8)
Block(-2,2,1,CONCRETE:8)
Block(-2,3,-3,inspirations:path)
Block(-2,3,1,rustic:iron_lattice:0)
Block(-2,4,1,rustic:iron_lattice:0)
Block(-2,5,1,rustic:iron_lattice:0)
Block(-1,0,-2,CONCRETE:11)
Block(-1,0,-1,CONCRETE:11)
Block(-1,0,0,CONCRETE:11)
Block(-1,1,-2,CONCRETE:11)
Block(-1,1,-1,CONCRETE:11)
Block(-1,1,0,CONCRETE:11)
Block(-1,2,-7,CONCRETE:8)
Block(-1,2,-6,CONCRETE:8)
Block(-1,2,-5,CONCRETE:8)
Block(-1,2,-4,CONCRETE:8)
Block(-1,2,-3,CONCRETE:8)
Block(-1,2,-2,CONCRETE:8)
Block(-1,2,-1,CONCRETE:8)
Block(-1,2,0,CONCRETE:8)
Block(-1,2,1,CONCRETE:8)
Block(-1,3,-6,inspirations:path)
Block(-1,3,-5,inspirations:path)
Block(-1,3,1,rustic:iron_lattice:0)
Block(-1,4,1,rustic:iron_lattice:0)
Block(-1,5,1,rustic:iron_lattice:0)
Block(0,0,-7,CONCRETE:11)
Block(0,0,-6,CONCRETE:11)
Block(0,0,-5,CONCRETE:11)
Block(0,0,-2,CONCRETE:11)
Block(0,0,-1,CONCRETE:11)
Block(0,0,0,CONCRETE:11)
Block(0,1,-7,CONCRETE:11)
Block(0,1,-6,CONCRETE:11)
Block(0,1,-5,CONCRETE:11)
Block(0,1,-2,CONCRETE:11)
Block(0,1,-1,CONCRETE:11)
Block(0,1,0,CONCRETE:11)
Block(0,2,-7,CONCRETE:8)
Block(0,2,-6,CONCRETE:8)
Block(0,2,-5,CONCRETE:8)
Block(0,2,-4,CONCRETE:8)
Block(0,2,-3,CONCRETE:8)
Block(0,2,-2,CONCRETE:8)
Block(0,2,-1,CONCRETE:8)
Block(0,2,0,CONCRETE:8)
Block(0,2,1,CONCRETE:8)
Block(0,3,-7,inspirations:path)
Block(0,3,-6,inspirations:path)
Block(0,3,-5,inspirations:path)
Block(0,3,-4,variedcommodities:table:5)
Block(0,3,-3,variedcommodities:table:5)
Block(0,3,-2,variedcommodities:table:5)
Block(0,3,1,rustic:iron_lattice:0)
Block(0,4,-4,IRON_TRAPDOOR:2)
Block(0,4,-3,IRON_TRAPDOOR:2)
Block(0,4,-2,IRON_TRAPDOOR:2)
Block(0,4,1,rustic:iron_lattice:0)
Block(0,5,1,rustic:iron_lattice:0)
Block(1,0,-7,CONCRETE:11)
Block(1,0,-6,CONCRETE:11)
Block(1,0,-5,CONCRETE:11)
Block(1,0,-2,CONCRETE:11)
Block(1,0,-1,CONCRETE:11)
Block(1,0,0,CONCRETE:11)
Block(1,1,-7,CONCRETE:11)
Block(1,1,-6,CONCRETE:11)
Block(1,1,-5,CONCRETE:11)
Block(1,1,-2,CONCRETE:11)
Block(1,1,-1,CONCRETE:11)
Block(1,1,0,CONCRETE:11)
Block(1,2,-7,CONCRETE:8)
Block(1,2,-6,CONCRETE:8)
Block(1,2,-5,CONCRETE:8)
Block(1,2,-4,CONCRETE:8)
Block(1,2,-3,CONCRETE:8)
Block(1,2,-2,CONCRETE:8)
Block(1,2,-1,CONCRETE:8)
Block(1,2,0,CONCRETE:8)
Block(1,2,1,CONCRETE:8)
Block(1,3,-6,inspirations:path)
Block(1,3,-4,variedcommodities:table:5)
Block(1,3,-3,rustic:iron_lattice:0)
Block(1,3,-2,variedcommodities:table:5)
Block(1,3,1,rustic:iron_lattice:0)
Block(1,4,-4,IRON_TRAPDOOR:2)
Block(1,4,-3,rustic:iron_lattice:0)
Block(1,4,-2,IRON_TRAPDOOR:2)
Block(1,4,1,rustic:iron_lattice:0)
Block(1,5,-3,rustic:iron_lattice:0)
Block(1,5,1,rustic:iron_lattice:0)
Block(1,6,-3,rustic:iron_lattice:0)
Block(1,7,-3,rustic:iron_lattice:0)
Block(1,8,-3,rustic:iron_lattice:0)
Block(1,9,-3,rustic:iron_lattice:0)
Block(1,10,-3,rustic:iron_lattice:0)
Block(1,11,-3,rustic:iron_lattice:0)
Block(1,12,-4,WOOL:14)
Block(1,12,-3,rustic:iron_lattice:0)
Block(1,13,-4,WOOL:15)
Block(1,13,-3,rustic:iron_lattice:0)
Block(1,14,-3,rustic:iron_lantern)
Block(2,0,-7,CONCRETE:11)
Block(2,0,-6,CONCRETE:11)
Block(2,0,-5,CONCRETE:11)
Block(2,0,-2,CONCRETE:11)
Block(2,0,-1,CONCRETE:11)
Block(2,0,0,CONCRETE:11)
Block(2,1,-7,CONCRETE:11)
Block(2,1,-6,CONCRETE:11)
Block(2,1,-5,CONCRETE:11)
Block(2,1,-2,CONCRETE:11)
Block(2,1,-1,CONCRETE:11)
Block(2,1,0,CONCRETE:11)
Block(2,2,-7,CONCRETE:8)
Block(2,2,-6,CONCRETE:8)
Block(2,2,-5,CONCRETE:8)
Block(2,2,-4,CONCRETE:8)
Block(2,2,-3,CONCRETE:8)
Block(2,2,-2,CONCRETE:8)
Block(2,2,-1,CONCRETE:8)
Block(2,2,0,CONCRETE:8)
Block(2,2,1,CONCRETE:8)
Block(2,3,-4,variedcommodities:table:5)
Block(2,3,-3,variedcommodities:table:5)
Block(2,3,-2,variedcommodities:table:5)
Block(2,3,0,inspirations:path)
Block(2,3,1,rustic:iron_lattice:0)
Block(2,4,-4,IRON_TRAPDOOR:2)
Block(2,4,-3,IRON_TRAPDOOR:2)
Block(2,4,-2,IRON_TRAPDOOR:2)
Block(2,4,1,rustic:iron_lattice:0)
Block(2,5,1,rustic:iron_lattice:0)
Block(2,12,-5,WOOL:15)
Block(3,0,-7,CONCRETE:11)
Block(3,0,-6,CONCRETE:11)
Block(3,0,-5,CONCRETE:11)
Block(3,0,-2,CONCRETE:11)
Block(3,0,-1,CONCRETE:11)
Block(3,0,0,CONCRETE:11)
Block(3,1,-7,CONCRETE:11)
Block(3,1,-6,SEA_LANTERN:0)
Block(3,1,-5,CONCRETE:11)
Block(3,1,-2,CONCRETE:11)
Block(3,1,-1,SEA_LANTERN:0)
Block(3,1,0,CONCRETE:11)
Block(3,2,-7,CONCRETE:8)
Block(3,2,-6,STAINED_GLASS:15)
Block(3,2,-5,CONCRETE:8)
Block(3,2,-4,CONCRETE:8)
Block(3,2,-3,CONCRETE:8)
Block(3,2,-2,CONCRETE:8)
Block(3,2,-1,STAINED_GLASS:15)
Block(3,2,0,CONCRETE:8)
Block(3,2,1,CONCRETE:8)
Block(3,3,-2,inspirations:path)
Block(3,3,0,inspirations:path)
Block(3,3,1,rustic:iron_lattice:0)
Block(3,4,1,rustic:iron_lattice:0)
Block(3,5,1,rustic:iron_lattice:0)
Block(3,11,-6,WOOL:14)
Block(3,12,-6,WOOL:15)
Block(4,0,-7,CONCRETE:11)
Block(4,0,-6,CONCRETE:11)
Block(4,0,-5,CONCRETE:11)
Block(4,0,-2,CONCRETE:11)
Block(4,0,-1,CONCRETE:11)
Block(4,0,0,CONCRETE:11)
Block(4,1,-7,CONCRETE:11)
Block(4,1,-6,CONCRETE:11)
Block(4,1,-5,CONCRETE:11)
Block(4,1,-2,CONCRETE:11)
Block(4,1,-1,CONCRETE:11)
Block(4,1,0,CONCRETE:11)
Block(4,2,-7,CONCRETE:8)
Block(4,2,-6,CONCRETE:8)
Block(4,2,-5,CONCRETE:8)
Block(4,2,-4,CONCRETE:8)
Block(4,2,-3,CONCRETE:8)
Block(4,2,-2,CONCRETE:8)
Block(4,2,-1,CONCRETE:8)
Block(4,2,0,CONCRETE:8)
Block(4,2,1,CONCRETE:8)
Block(4,3,-3,inspirations:path)
Block(4,3,-2,inspirations:path)
Block(4,3,-1,inspirations:path)
Block(4,3,0,inspirations:path)
Block(4,3,1,rustic:iron_lattice:0)
Block(4,4,1,rustic:iron_lattice:0)
Block(4,5,1,rustic:iron_lattice:0)
Block(4,11,-7,WOOL:14)
Block(5,0,-7,CONCRETE:11)
Block(5,0,-6,CONCRETE:11)
Block(5,0,-5,CONCRETE:11)
Block(5,0,-2,CONCRETE:11)
Block(5,0,-1,CONCRETE:11)
Block(5,0,0,CONCRETE:11)
Block(5,1,-7,CONCRETE:11)
Block(5,1,-6,CONCRETE:11)
Block(5,1,-5,CONCRETE:11)
Block(5,1,-2,CONCRETE:11)
Block(5,1,-1,CONCRETE:11)
Block(5,1,0,CONCRETE:11)
Block(5,2,-7,CONCRETE:8)
Block(5,2,-6,CONCRETE:8)
Block(5,2,-5,CONCRETE:8)
Block(5,2,-4,CONCRETE:8)
Block(5,2,-3,CONCRETE:8)
Block(5,2,-2,CONCRETE:8)
Block(5,2,-1,CONCRETE:8)
Block(5,2,0,CONCRETE:8)
Block(5,2,1,CONCRETE:8)
Block(5,3,-3,inspirations:path)
Block(5,3,-2,inspirations:path)
Block(5,3,-1,inspirations:path)
Block(5,3,0,inspirations:path)
Block(5,3,1,rustic:iron_lattice:0)
Block(5,4,1,rustic:iron_lattice:0)
Block(5,5,1,rustic:iron_lattice:0)
Block(6,0,-7,CONCRETE:11)
Block(6,0,-6,CONCRETE:11)
Block(6,0,-5,CONCRETE:11)
Block(6,0,-2,CONCRETE:11)
Block(6,0,-1,CONCRETE:11)
Block(6,0,0,CONCRETE:11)
Block(6,1,-7,CONCRETE:11)
Block(6,1,-6,CONCRETE:11)
Block(6,1,-5,CONCRETE:11)
Block(6,1,-2,CONCRETE:11)
Block(6,1,-1,CONCRETE:11)
Block(6,1,0,CONCRETE:11)
Block(6,2,-7,CONCRETE:8)
Block(6,2,-6,CONCRETE:8)
Block(6,2,-5,CONCRETE:8)
Block(6,2,-4,CONCRETE:8)
Block(6,2,-3,CONCRETE:8)
Block(6,2,-2,CONCRETE:8)
Block(6,2,-1,CONCRETE:8)
Block(6,2,0,CONCRETE:8)
Block(6,2,1,CONCRETE:8)
Block(6,3,-5,CONCRETE:7)
Block(6,3,-1,CONCRETE:7)
Block(6,3,1,rustic:iron_lattice:0)
Block(6,4,-5,CONCRETE:7)
Block(6,4,-1,CONCRETE:7)
Block(6,4,1,rustic:iron_lattice:0)
Block(6,5,-5,CONCRETE:7)
Block(6,5,-1,CONCRETE:7)
Block(6,5,1,rustic:iron_lattice:0)
Block(6,6,-5,CONCRETE:7)
Block(6,6,-1,CONCRETE:7)
Block(6,7,-5,STEP:0)
Block(6,7,-1,STEP:0)
Block(7,0,-7,CONCRETE:11)
Block(7,0,-6,CONCRETE:11)
Block(7,0,-5,CONCRETE:11)
Block(7,0,-2,CONCRETE:11)
Block(7,0,-1,CONCRETE:11)
Block(7,0,0,CONCRETE:11)
Block(7,1,-7,CONCRETE:11)
Block(7,1,-6,CONCRETE:11)
Block(7,1,-5,CONCRETE:11)
Block(7,1,-2,CONCRETE:11)
Block(7,1,-1,CONCRETE:11)
Block(7,1,0,CONCRETE:11)
Block(7,2,-7,CONCRETE:8)
Block(7,2,-6,CONCRETE:8)
Block(7,2,-5,CONCRETE:8)
Block(7,2,-4,CONCRETE:8)
Block(7,2,-3,CONCRETE:8)
Block(7,2,-2,CONCRETE:8)
Block(7,2,-1,CONCRETE:8)
Block(7,2,0,CONCRETE:8)
Block(7,2,1,CONCRETE:8)
Block(7,3,-5,CONCRETE:8)
Block(7,3,-4,SPRUCE_DOOR:2)
Block(7,3,-3,CONCRETE:8)
Block(7,3,-2,CONCRETE:8)
Block(7,3,-1,CONCRETE:8)
Block(7,3,0,CONCRETE:7)
Block(7,3,1,rustic:iron_lattice:0)
Block(7,4,-5,CONCRETE:8)
Block(7,4,-4,SPRUCE_DOOR:9)
Block(7,4,-3,CONCRETE:8)
Block(7,4,-2,CONCRETE:8)
Block(7,4,-1,CONCRETE:8)
Block(7,4,0,CONCRETE:7)
Block(7,4,1,rustic:iron_lattice:0)
Block(7,5,-5,CONCRETE:8)
Block(7,5,-4,CONCRETE:8)
Block(7,5,-3,CONCRETE:8)
Block(7,5,-2,CONCRETE:8)
Block(7,5,-1,CONCRETE:8)
Block(7,5,0,CONCRETE:7)
Block(7,5,1,rustic:iron_lattice:0)
Block(7,6,-5,STEP:0)
Block(7,6,-4,STEP:0)
Block(7,6,-3,STEP:0)
Block(7,6,-2,STEP:0)
Block(7,6,-1,STEP:0)
Block(7,6,0,CONCRETE:7)
Block(7,7,0,STEP:0)

#######################################################################
# +-----------------------------------------------------------------+ #
# |                             Branches                            | #
# +-----------------------------------------------------------------+ #
#######################################################################


#######################################################################
# +-----------------------------------------------------------------+ #
# |                             Entities                            | #
# +-----------------------------------------------------------------+ #
#######################################################################


#######################################################################
# +-----------------------------------------------------------------+ #
# |                            Particles                            | #
# +-----------------------------------------------------------------+ #
#######################################################################


#######################################################################
# +-----------------------------------------------------------------+ #
# |                             Spawners                            | #
# +-----------------------------------------------------------------+ #
#######################################################################


#######################################################################
# +-----------------------------------------------------------------+ #
# |                             ModData                             | #
# +-----------------------------------------------------------------+ #
#######################################################################

