
#######################################################################
# +-----------------------------------------------------------------+ #
# |                            BO4 object                           | #
# +-----------------------------------------------------------------+ #
#######################################################################

Author: NLBlackEagle

Description: No description given

SettingsMode: WriteDisable


#######################################################################
# +-----------------------------------------------------------------+ #
# |                          Main settings                          | #
# +-----------------------------------------------------------------+ #
#######################################################################

Frequency: 0

SpawnHeight: highestBlock

UseCenterForHighestBlock: true

##############################
# Height Limits for the BO4. #
##############################

MinHeight: 0

MaxHeight: 255

InheritBO3: 

InheritBO3Rotation: NORTH

OverrideChildSettings: true

OverrideParentHeight: false

CanOverride: true

BranchFrequency: 0

BranchFrequencyGroup: 

MustBeBelowOther: false

MustBeInside: 

CannotBeInside: 

ReplacesBO3: 

MustBeInsideWorldBorders: false

CanSpawnOnWater: true

SpawnOnWaterOnly: false

SpawnUnderWater: false

SpawnAtWaterLevel: false

HeightOffset: 0

RemoveAir: true

ReplaceAbove: 

ReplaceBelow: 

ReplaceWithBiomeBlocks: true

ReplaceWithSurfaceBlock: GRASS

ReplaceWithGroundBlock: DIRT

ReplaceWithStoneBlock: STONE

SmoothRadius: 0

SmoothHeightOffset: 0

SmoothStartTop: false

SmoothStartWood: false

SmoothingSurfaceBlock: 

SmoothingGroundBlock: 

BO3Group: 

IsSpawnPoint: false

DoReplaceBlocks: true


#######################################################################
# +-----------------------------------------------------------------+ #
# |                              Blocks                             | #
# +-----------------------------------------------------------------+ #
#######################################################################

Block(-8,0,-4,OBSIDIAN)
Block(-8,0,-3,OBSIDIAN)
Block(-8,0,-2,OBSIDIAN)
Block(-8,0,-1,OBSIDIAN)
Block(-8,0,0,OBSIDIAN)
Block(-8,0,1,OBSIDIAN)
Block(-8,0,2,OBSIDIAN)
Block(-8,1,-5,OBSIDIAN)
Block(-8,1,-4,OBSIDIAN)
Block(-8,1,-3,OBSIDIAN)
Block(-8,1,-2,OBSIDIAN)
Block(-8,1,-1,OBSIDIAN)
Block(-8,1,0,OBSIDIAN)
Block(-8,1,1,OBSIDIAN)
Block(-8,2,-5,OBSIDIAN)
Block(-8,2,-4,OBSIDIAN)
Block(-8,2,-3,OBSIDIAN)
Block(-8,2,-2,OBSIDIAN)
Block(-8,2,-1,OBSIDIAN)
Block(-8,2,0,OBSIDIAN)
Block(-8,3,-6,OBSIDIAN)
Block(-8,3,-5,OBSIDIAN)
Block(-8,3,-4,OBSIDIAN)
Block(-8,3,-3,OBSIDIAN)
Block(-8,3,-2,OBSIDIAN)
Block(-8,3,-1,OBSIDIAN)
Block(-8,3,0,OBSIDIAN)
Block(-8,4,-7,OBSIDIAN)
Block(-8,4,-6,OBSIDIAN)
Block(-8,4,-5,OBSIDIAN)
Block(-8,4,-4,OBSIDIAN)
Block(-8,4,-3,OBSIDIAN)
Block(-8,4,-2,OBSIDIAN)
Block(-8,4,-1,OBSIDIAN)
Block(-8,5,-7,OBSIDIAN)
Block(-8,5,-6,OBSIDIAN)
Block(-8,5,-5,OBSIDIAN)
Block(-8,5,-4,OBSIDIAN)
Block(-8,5,-3,OBSIDIAN)
Block(-8,5,-2,OBSIDIAN)
Block(-8,6,-7,OBSIDIAN)
Block(-8,6,-6,OBSIDIAN)
Block(-8,6,-5,OBSIDIAN)
Block(-8,6,-4,OBSIDIAN)
Block(-8,6,-3,OBSIDIAN)
Block(-8,7,-7,OBSIDIAN)
Block(-8,7,-6,OBSIDIAN)
Block(-8,7,-5,OBSIDIAN)
Block(-8,7,-4,OBSIDIAN)
Block(-8,8,-7,OBSIDIAN)
Block(-8,8,-6,OBSIDIAN)
Block(-8,8,-5,OBSIDIAN)
Block(-8,9,-7,OBSIDIAN)
Block(-8,9,-6,OBSIDIAN)
Block(-8,9,-5,OBSIDIAN)
Block(-8,10,-7,OBSIDIAN)
Block(-8,10,-6,OBSIDIAN)
Block(-8,11,-7,OBSIDIAN)
Block(-7,0,-4,OBSIDIAN)
Block(-7,0,-3,OBSIDIAN)
Block(-7,0,-2,OBSIDIAN)
Block(-7,0,-1,OBSIDIAN)
Block(-7,0,0,OBSIDIAN)
Block(-7,1,-5,OBSIDIAN)
Block(-7,1,-4,OBSIDIAN)
Block(-7,1,-3,OBSIDIAN)
Block(-7,1,-2,OBSIDIAN)
Block(-7,1,-1,OBSIDIAN)
Block(-7,1,0,OBSIDIAN)
Block(-7,2,-5,OBSIDIAN)
Block(-7,2,-4,OBSIDIAN)
Block(-7,2,-3,OBSIDIAN)
Block(-7,2,-2,OBSIDIAN)
Block(-7,2,-1,OBSIDIAN)
Block(-7,3,-6,OBSIDIAN)
Block(-7,3,-5,OBSIDIAN)
Block(-7,3,-4,OBSIDIAN)
Block(-7,3,-3,OBSIDIAN)
Block(-7,3,-2,OBSIDIAN)
Block(-7,4,-7,OBSIDIAN)
Block(-7,4,-6,OBSIDIAN)
Block(-7,4,-5,OBSIDIAN)
Block(-7,4,-4,OBSIDIAN)
Block(-7,4,-3,OBSIDIAN)
Block(-7,5,-7,OBSIDIAN)
Block(-7,5,-6,OBSIDIAN)
Block(-7,5,-5,OBSIDIAN)
Block(-7,5,-4,OBSIDIAN)
Block(-7,6,-7,OBSIDIAN)
Block(-7,6,-6,OBSIDIAN)
Block(-7,6,-5,OBSIDIAN)
Block(-7,7,-7,OBSIDIAN)
Block(-7,7,-6,OBSIDIAN)
Block(-7,7,-5,OBSIDIAN)
Block(-7,8,-7,OBSIDIAN)
Block(-7,8,-6,OBSIDIAN)
Block(-7,9,-7,OBSIDIAN)
Block(-6,0,-4,OBSIDIAN)
Block(-6,0,-3,OBSIDIAN)
Block(-6,0,-2,OBSIDIAN)
Block(-6,0,-1,OBSIDIAN)
Block(-6,1,-4,OBSIDIAN)
Block(-6,1,-3,OBSIDIAN)
Block(-6,1,-2,OBSIDIAN)
Block(-6,2,-5,OBSIDIAN)
Block(-6,2,-4,OBSIDIAN)
Block(-6,2,-3,OBSIDIAN)
Block(-6,3,-6,OBSIDIAN)
Block(-6,3,-5,OBSIDIAN)
Block(-6,3,-4,OBSIDIAN)
Block(-6,4,-6,OBSIDIAN)
Block(-6,4,-5,OBSIDIAN)
Block(-6,5,-7,OBSIDIAN)
Block(-6,5,-6,OBSIDIAN)
Block(-6,5,-5,OBSIDIAN)
Block(-6,6,-7,OBSIDIAN)
Block(-6,6,-6,OBSIDIAN)
Block(-6,7,-7,OBSIDIAN)
Block(-5,0,-4,OBSIDIAN)
Block(-5,0,-3,OBSIDIAN)
Block(-5,1,-4,OBSIDIAN)
Block(-5,2,-5,OBSIDIAN)
Block(-5,3,-6,OBSIDIAN)
Block(-5,3,-5,OBSIDIAN)
Block(-5,4,-6,OBSIDIAN)
Block(-5,5,-7,OBSIDIAN)
Block(-4,0,-4,OBSIDIAN)

#######################################################################
# +-----------------------------------------------------------------+ #
# |                             Branches                            | #
# +-----------------------------------------------------------------+ #
#######################################################################

Branch(-16,0,0,true,DesertSpike_Huge_10C0R2,NORTH,100.0,0)

#######################################################################
# +-----------------------------------------------------------------+ #
# |                             Entities                            | #
# +-----------------------------------------------------------------+ #
#######################################################################


#######################################################################
# +-----------------------------------------------------------------+ #
# |                            Particles                            | #
# +-----------------------------------------------------------------+ #
#######################################################################


#######################################################################
# +-----------------------------------------------------------------+ #
# |                             Spawners                            | #
# +-----------------------------------------------------------------+ #
#######################################################################


#######################################################################
# +-----------------------------------------------------------------+ #
# |                             ModData                             | #
# +-----------------------------------------------------------------+ #
#######################################################################

