
#######################################################################
# +-----------------------------------------------------------------+ #
# |                            BO4 object                           | #
# +-----------------------------------------------------------------+ #
#######################################################################

Author: NLBlackEagle

Description: No description given

SettingsMode: WriteDisable


#######################################################################
# +-----------------------------------------------------------------+ #
# |                          Main settings                          | #
# +-----------------------------------------------------------------+ #
#######################################################################

Frequency: 0

SpawnHeight: highestBlock

UseCenterForHighestBlock: true

##############################
# Height Limits for the BO4. #
##############################

MinHeight: 0

MaxHeight: 255

InheritBO3: 

InheritBO3Rotation: NORTH

OverrideChildSettings: true

OverrideParentHeight: false

CanOverride: true

BranchFrequency: 0

BranchFrequencyGroup: 

MustBeBelowOther: false

MustBeInside: 

CannotBeInside: 

ReplacesBO3: 

MustBeInsideWorldBorders: false

CanSpawnOnWater: true

SpawnOnWaterOnly: false

SpawnUnderWater: false

SpawnAtWaterLevel: false

HeightOffset: 0

RemoveAir: true

ReplaceAbove: 

ReplaceBelow: 

ReplaceWithBiomeBlocks: true

ReplaceWithSurfaceBlock: GRASS

ReplaceWithGroundBlock: DIRT

ReplaceWithStoneBlock: STONE

SmoothRadius: 0

SmoothHeightOffset: 0

SmoothStartTop: false

SmoothStartWood: false

SmoothingSurfaceBlock: 

SmoothingGroundBlock: 

BO3Group: 

IsSpawnPoint: false

DoReplaceBlocks: true


#######################################################################
# +-----------------------------------------------------------------+ #
# |                              Blocks                             | #
# +-----------------------------------------------------------------+ #
#######################################################################

Block(-4,2,8,OBSIDIAN)
Block(-3,3,8,OBSIDIAN)
Block(-3,4,7,OBSIDIAN)
Block(-3,4,8,OBSIDIAN)
Block(-3,5,7,OBSIDIAN)
Block(-3,5,8,OBSIDIAN)
Block(-3,6,6,OBSIDIAN)
Block(-3,7,5,OBSIDIAN)
Block(-2,3,8,OBSIDIAN)
Block(-2,4,8,OBSIDIAN)
Block(-2,5,7,OBSIDIAN)
Block(-2,5,8,OBSIDIAN)
Block(-2,6,6,OBSIDIAN)
Block(-2,6,7,OBSIDIAN)
Block(-2,6,8,OBSIDIAN)
Block(-2,7,6,OBSIDIAN)
Block(-2,7,7,OBSIDIAN)
Block(-2,7,8,OBSIDIAN)
Block(-2,8,5,OBSIDIAN)
Block(-2,8,6,OBSIDIAN)
Block(-2,8,7,OBSIDIAN)
Block(-2,9,4,OBSIDIAN)
Block(-2,9,5,OBSIDIAN)
Block(-2,10,4,OBSIDIAN)
Block(-1,3,8,OBSIDIAN)
Block(-1,4,8,OBSIDIAN)
Block(-1,5,7,OBSIDIAN)
Block(-1,5,8,OBSIDIAN)
Block(-1,6,6,OBSIDIAN)
Block(-1,6,7,OBSIDIAN)
Block(-1,6,8,OBSIDIAN)
Block(-1,7,6,OBSIDIAN)
Block(-1,7,7,OBSIDIAN)
Block(-1,7,8,OBSIDIAN)
Block(-1,8,5,OBSIDIAN)
Block(-1,8,6,OBSIDIAN)
Block(-1,8,7,OBSIDIAN)
Block(-1,8,8,OBSIDIAN)
Block(-1,9,5,OBSIDIAN)
Block(-1,9,6,OBSIDIAN)
Block(-1,9,7,OBSIDIAN)
Block(-1,9,8,OBSIDIAN)
Block(-1,10,4,OBSIDIAN)
Block(-1,10,5,OBSIDIAN)
Block(-1,10,6,OBSIDIAN)
Block(-1,10,7,OBSIDIAN)
Block(-1,11,3,OBSIDIAN)
Block(-1,11,4,OBSIDIAN)
Block(-1,11,5,OBSIDIAN)
Block(-1,11,6,OBSIDIAN)
Block(-1,12,3,OBSIDIAN)
Block(-1,12,4,OBSIDIAN)
Block(-1,13,2,OBSIDIAN)
Block(-1,13,3,OBSIDIAN)
Block(-1,14,1,OBSIDIAN)
Block(0,4,8,OBSIDIAN)
Block(0,5,7,OBSIDIAN)
Block(0,5,8,OBSIDIAN)
Block(0,6,7,OBSIDIAN)
Block(0,6,8,OBSIDIAN)
Block(0,7,6,OBSIDIAN)
Block(0,7,7,OBSIDIAN)
Block(0,7,8,OBSIDIAN)
Block(0,8,5,OBSIDIAN)
Block(0,8,6,OBSIDIAN)
Block(0,8,7,OBSIDIAN)
Block(0,8,8,OBSIDIAN)
Block(0,9,5,OBSIDIAN)
Block(0,9,6,OBSIDIAN)
Block(0,9,7,OBSIDIAN)
Block(0,9,8,OBSIDIAN)
Block(0,10,4,OBSIDIAN)
Block(0,10,5,OBSIDIAN)
Block(0,10,6,OBSIDIAN)
Block(0,10,7,OBSIDIAN)
Block(0,10,8,OBSIDIAN)
Block(0,11,4,OBSIDIAN)
Block(0,11,5,OBSIDIAN)
Block(0,11,6,OBSIDIAN)
Block(0,11,7,OBSIDIAN)
Block(0,11,8,OBSIDIAN)
Block(0,12,3,OBSIDIAN)
Block(0,12,4,OBSIDIAN)
Block(0,12,5,OBSIDIAN)
Block(0,12,6,OBSIDIAN)
Block(0,12,7,OBSIDIAN)
Block(0,12,8,OBSIDIAN)
Block(0,13,2,OBSIDIAN)
Block(0,13,3,OBSIDIAN)
Block(0,13,4,OBSIDIAN)
Block(0,13,5,OBSIDIAN)
Block(0,13,6,OBSIDIAN)
Block(0,14,2,OBSIDIAN)
Block(0,14,3,OBSIDIAN)
Block(0,14,4,OBSIDIAN)
Block(0,14,5,OBSIDIAN)
Block(0,15,1,OBSIDIAN)
Block(0,15,2,OBSIDIAN)
Block(0,15,3,OBSIDIAN)
Block(0,16,0,OBSIDIAN)
Block(0,16,1,OBSIDIAN)
Block(0,16,2,OBSIDIAN)
Block(0,17,0,OBSIDIAN)
Block(0,18,-1,OBSIDIAN)
Block(1,4,8,OBSIDIAN)
Block(1,5,7,OBSIDIAN)
Block(1,5,8,OBSIDIAN)
Block(1,6,7,OBSIDIAN)
Block(1,6,8,OBSIDIAN)
Block(1,7,6,OBSIDIAN)
Block(1,7,7,OBSIDIAN)
Block(1,7,8,OBSIDIAN)
Block(1,8,6,OBSIDIAN)
Block(1,8,7,OBSIDIAN)
Block(1,8,8,OBSIDIAN)
Block(1,9,5,OBSIDIAN)
Block(1,9,6,OBSIDIAN)
Block(1,9,7,OBSIDIAN)
Block(1,9,8,OBSIDIAN)
Block(1,10,4,OBSIDIAN)
Block(1,10,5,OBSIDIAN)
Block(1,10,6,OBSIDIAN)
Block(1,10,7,OBSIDIAN)
Block(1,10,8,OBSIDIAN)
Block(1,11,4,OBSIDIAN)
Block(1,11,5,OBSIDIAN)
Block(1,11,6,OBSIDIAN)
Block(1,11,7,OBSIDIAN)
Block(1,11,8,OBSIDIAN)
Block(1,12,3,OBSIDIAN)
Block(1,12,4,OBSIDIAN)
Block(1,12,5,OBSIDIAN)
Block(1,12,6,OBSIDIAN)
Block(1,12,7,OBSIDIAN)
Block(1,12,8,OBSIDIAN)
Block(1,13,2,OBSIDIAN)
Block(1,13,3,OBSIDIAN)
Block(1,13,4,OBSIDIAN)
Block(1,13,5,OBSIDIAN)
Block(1,13,6,OBSIDIAN)
Block(1,13,7,OBSIDIAN)
Block(1,13,8,OBSIDIAN)
Block(1,14,2,OBSIDIAN)
Block(1,14,3,OBSIDIAN)
Block(1,14,4,OBSIDIAN)
Block(1,14,5,OBSIDIAN)
Block(1,14,6,OBSIDIAN)
Block(1,14,7,OBSIDIAN)
Block(1,14,8,OBSIDIAN)
Block(1,15,1,OBSIDIAN)
Block(1,15,2,OBSIDIAN)
Block(1,15,3,OBSIDIAN)
Block(1,15,4,OBSIDIAN)
Block(1,15,5,OBSIDIAN)
Block(1,15,6,OBSIDIAN)
Block(1,15,7,OBSIDIAN)
Block(1,16,1,OBSIDIAN)
Block(1,16,2,OBSIDIAN)
Block(1,16,3,OBSIDIAN)
Block(1,16,4,OBSIDIAN)
Block(1,16,5,OBSIDIAN)
Block(1,17,0,OBSIDIAN)
Block(1,17,1,OBSIDIAN)
Block(1,17,2,OBSIDIAN)
Block(1,17,3,OBSIDIAN)
Block(1,17,4,OBSIDIAN)
Block(1,18,-1,OBSIDIAN)
Block(1,18,0,OBSIDIAN)
Block(1,18,1,OBSIDIAN)
Block(1,18,2,OBSIDIAN)
Block(1,19,-1,OBSIDIAN)
Block(1,19,0,OBSIDIAN)
Block(1,19,1,OBSIDIAN)
Block(1,20,-2,OBSIDIAN)
Block(1,20,-1,OBSIDIAN)
Block(1,21,-3,OBSIDIAN)
Block(1,21,-2,OBSIDIAN)
Block(2,4,8,OBSIDIAN)
Block(2,5,8,OBSIDIAN)
Block(2,6,7,OBSIDIAN)
Block(2,6,8,OBSIDIAN)
Block(2,7,6,OBSIDIAN)
Block(2,7,7,OBSIDIAN)
Block(2,7,8,OBSIDIAN)
Block(2,8,6,OBSIDIAN)
Block(2,8,7,OBSIDIAN)
Block(2,8,8,OBSIDIAN)
Block(2,9,5,OBSIDIAN)
Block(2,9,6,OBSIDIAN)
Block(2,9,7,OBSIDIAN)
Block(2,9,8,OBSIDIAN)
Block(2,10,4,OBSIDIAN)
Block(2,10,5,OBSIDIAN)
Block(2,10,6,OBSIDIAN)
Block(2,10,7,OBSIDIAN)
Block(2,10,8,OBSIDIAN)
Block(2,11,4,OBSIDIAN)
Block(2,11,5,OBSIDIAN)
Block(2,11,6,OBSIDIAN)
Block(2,11,7,OBSIDIAN)
Block(2,11,8,OBSIDIAN)
Block(2,12,3,OBSIDIAN)
Block(2,12,4,OBSIDIAN)
Block(2,12,5,OBSIDIAN)
Block(2,12,6,OBSIDIAN)
Block(2,12,7,OBSIDIAN)
Block(2,12,8,OBSIDIAN)
Block(2,13,3,OBSIDIAN)
Block(2,13,4,OBSIDIAN)
Block(2,13,5,OBSIDIAN)
Block(2,13,6,OBSIDIAN)
Block(2,13,7,OBSIDIAN)
Block(2,13,8,OBSIDIAN)
Block(2,14,2,OBSIDIAN)
Block(2,14,3,OBSIDIAN)
Block(2,14,4,OBSIDIAN)
Block(2,14,5,OBSIDIAN)
Block(2,14,6,OBSIDIAN)
Block(2,14,7,OBSIDIAN)
Block(2,14,8,OBSIDIAN)
Block(2,15,1,OBSIDIAN)
Block(2,15,2,OBSIDIAN)
Block(2,15,3,OBSIDIAN)
Block(2,15,4,OBSIDIAN)
Block(2,15,5,OBSIDIAN)
Block(2,15,6,OBSIDIAN)
Block(2,15,7,OBSIDIAN)
Block(2,15,8,OBSIDIAN)
Block(2,16,1,OBSIDIAN)
Block(2,16,2,OBSIDIAN)
Block(2,16,3,OBSIDIAN)
Block(2,16,4,OBSIDIAN)
Block(2,16,5,OBSIDIAN)
Block(2,16,6,OBSIDIAN)
Block(2,16,7,OBSIDIAN)
Block(2,16,8,OBSIDIAN)
Block(2,17,0,OBSIDIAN)
Block(2,17,1,OBSIDIAN)
Block(2,17,2,OBSIDIAN)
Block(2,17,3,OBSIDIAN)
Block(2,17,4,OBSIDIAN)
Block(2,17,5,OBSIDIAN)
Block(2,17,6,OBSIDIAN)
Block(2,17,7,OBSIDIAN)
Block(2,18,-1,OBSIDIAN)
Block(2,18,0,OBSIDIAN)
Block(2,18,1,OBSIDIAN)
Block(2,18,2,OBSIDIAN)
Block(2,18,3,OBSIDIAN)
Block(2,18,4,OBSIDIAN)
Block(2,18,5,OBSIDIAN)
Block(2,18,6,OBSIDIAN)
Block(2,19,-1,OBSIDIAN)
Block(2,19,0,OBSIDIAN)
Block(2,19,1,OBSIDIAN)
Block(2,19,2,OBSIDIAN)
Block(2,19,3,OBSIDIAN)
Block(2,19,4,OBSIDIAN)
Block(2,20,-2,OBSIDIAN)
Block(2,20,-1,OBSIDIAN)
Block(2,20,0,OBSIDIAN)
Block(2,20,1,OBSIDIAN)
Block(2,20,2,OBSIDIAN)
Block(2,20,3,OBSIDIAN)
Block(2,21,-2,OBSIDIAN)
Block(2,21,-1,OBSIDIAN)
Block(2,21,0,OBSIDIAN)
Block(2,21,1,OBSIDIAN)
Block(2,22,-3,OBSIDIAN)
Block(2,22,-2,OBSIDIAN)
Block(2,22,-1,OBSIDIAN)
Block(2,22,0,OBSIDIAN)
Block(2,23,-4,OBSIDIAN)
Block(2,23,-3,OBSIDIAN)
Block(2,23,-2,OBSIDIAN)
Block(2,24,-4,OBSIDIAN)
Block(2,24,-3,OBSIDIAN)
Block(2,25,-5,OBSIDIAN)
Block(2,26,-6,OBSIDIAN)
Block(3,4,8,OBSIDIAN)
Block(3,5,8,OBSIDIAN)
Block(3,6,7,OBSIDIAN)
Block(3,6,8,OBSIDIAN)
Block(3,7,7,OBSIDIAN)
Block(3,7,8,OBSIDIAN)
Block(3,8,6,OBSIDIAN)
Block(3,8,7,OBSIDIAN)
Block(3,8,8,OBSIDIAN)
Block(3,9,5,OBSIDIAN)
Block(3,9,6,OBSIDIAN)
Block(3,9,7,OBSIDIAN)
Block(3,9,8,OBSIDIAN)
Block(3,10,5,OBSIDIAN)
Block(3,10,6,OBSIDIAN)
Block(3,10,7,OBSIDIAN)
Block(3,10,8,OBSIDIAN)
Block(3,11,4,OBSIDIAN)
Block(3,11,5,OBSIDIAN)
Block(3,11,6,OBSIDIAN)
Block(3,11,7,OBSIDIAN)
Block(3,11,8,OBSIDIAN)
Block(3,12,3,OBSIDIAN)
Block(3,12,4,OBSIDIAN)
Block(3,12,5,OBSIDIAN)
Block(3,12,6,OBSIDIAN)
Block(3,12,7,OBSIDIAN)
Block(3,12,8,OBSIDIAN)
Block(3,13,3,OBSIDIAN)
Block(3,13,4,OBSIDIAN)
Block(3,13,5,OBSIDIAN)
Block(3,13,6,OBSIDIAN)
Block(3,13,7,OBSIDIAN)
Block(3,13,8,OBSIDIAN)
Block(3,14,2,OBSIDIAN)
Block(3,14,3,OBSIDIAN)
Block(3,14,4,OBSIDIAN)
Block(3,14,5,OBSIDIAN)
Block(3,14,6,OBSIDIAN)
Block(3,14,7,OBSIDIAN)
Block(3,14,8,OBSIDIAN)
Block(3,15,2,OBSIDIAN)
Block(3,15,3,OBSIDIAN)
Block(3,15,4,OBSIDIAN)
Block(3,15,5,OBSIDIAN)
Block(3,15,6,OBSIDIAN)
Block(3,15,7,OBSIDIAN)
Block(3,15,8,OBSIDIAN)
Block(3,16,1,OBSIDIAN)
Block(3,16,2,OBSIDIAN)
Block(3,16,3,OBSIDIAN)
Block(3,16,4,OBSIDIAN)
Block(3,16,5,OBSIDIAN)
Block(3,16,6,OBSIDIAN)
Block(3,16,7,OBSIDIAN)
Block(3,16,8,OBSIDIAN)
Block(3,17,0,OBSIDIAN)
Block(3,17,1,OBSIDIAN)
Block(3,17,2,OBSIDIAN)
Block(3,17,3,OBSIDIAN)
Block(3,17,4,OBSIDIAN)
Block(3,17,5,OBSIDIAN)
Block(3,17,6,OBSIDIAN)
Block(3,17,7,OBSIDIAN)
Block(3,17,8,OBSIDIAN)
Block(3,18,0,OBSIDIAN)
Block(3,18,1,OBSIDIAN)
Block(3,18,2,OBSIDIAN)
Block(3,18,3,OBSIDIAN)
Block(3,18,4,OBSIDIAN)
Block(3,18,5,OBSIDIAN)
Block(3,18,6,OBSIDIAN)
Block(3,18,7,OBSIDIAN)
Block(3,18,8,OBSIDIAN)
Block(3,19,-1,OBSIDIAN)
Block(3,19,0,OBSIDIAN)
Block(3,19,1,OBSIDIAN)
Block(3,19,2,OBSIDIAN)
Block(3,19,3,OBSIDIAN)
Block(3,19,4,OBSIDIAN)
Block(3,19,5,OBSIDIAN)
Block(3,19,6,OBSIDIAN)
Block(3,19,7,OBSIDIAN)
Block(3,19,8,OBSIDIAN)
Block(3,20,-2,OBSIDIAN)
Block(3,20,-1,OBSIDIAN)
Block(3,20,0,OBSIDIAN)
Block(3,20,1,OBSIDIAN)
Block(3,20,2,OBSIDIAN)
Block(3,20,3,OBSIDIAN)
Block(3,20,4,OBSIDIAN)
Block(3,20,5,OBSIDIAN)
Block(3,20,6,OBSIDIAN)
Block(3,21,-2,OBSIDIAN)
Block(3,21,-1,OBSIDIAN)
Block(3,21,0,OBSIDIAN)
Block(3,21,1,OBSIDIAN)
Block(3,21,2,OBSIDIAN)
Block(3,21,3,OBSIDIAN)
Block(3,21,4,OBSIDIAN)
Block(3,21,5,OBSIDIAN)
Block(3,22,-3,OBSIDIAN)
Block(3,22,-2,OBSIDIAN)
Block(3,22,-1,OBSIDIAN)
Block(3,22,0,OBSIDIAN)
Block(3,22,1,OBSIDIAN)
Block(3,22,2,OBSIDIAN)
Block(3,22,3,OBSIDIAN)
Block(3,23,-3,OBSIDIAN)
Block(3,23,-2,OBSIDIAN)
Block(3,23,-1,OBSIDIAN)
Block(3,23,0,OBSIDIAN)
Block(3,23,1,OBSIDIAN)
Block(3,23,2,OBSIDIAN)
Block(3,24,-4,OBSIDIAN)
Block(3,24,-3,OBSIDIAN)
Block(3,24,-2,OBSIDIAN)
Block(3,24,-1,OBSIDIAN)
Block(3,24,0,OBSIDIAN)
Block(3,25,-5,OBSIDIAN)
Block(3,25,-4,OBSIDIAN)
Block(3,25,-3,OBSIDIAN)
Block(3,25,-2,OBSIDIAN)
Block(3,25,-1,OBSIDIAN)
Block(3,26,-5,OBSIDIAN)
Block(3,26,-4,OBSIDIAN)
Block(3,26,-3,OBSIDIAN)
Block(3,27,-6,OBSIDIAN)
Block(3,27,-5,OBSIDIAN)
Block(3,27,-4,OBSIDIAN)
Block(3,28,-7,OBSIDIAN)
Block(3,28,-6,OBSIDIAN)
Block(3,29,-7,OBSIDIAN)
Block(4,5,8,OBSIDIAN)
Block(4,6,7,OBSIDIAN)
Block(4,6,8,OBSIDIAN)
Block(4,7,7,OBSIDIAN)
Block(4,7,8,OBSIDIAN)
Block(4,8,6,OBSIDIAN)
Block(4,8,7,OBSIDIAN)
Block(4,8,8,OBSIDIAN)
Block(4,9,5,OBSIDIAN)
Block(4,9,6,OBSIDIAN)
Block(4,9,7,OBSIDIAN)
Block(4,9,8,OBSIDIAN)
Block(4,10,5,OBSIDIAN)
Block(4,10,6,OBSIDIAN)
Block(4,10,7,OBSIDIAN)
Block(4,10,8,OBSIDIAN)
Block(4,11,4,OBSIDIAN)
Block(4,11,5,OBSIDIAN)
Block(4,11,6,OBSIDIAN)
Block(4,11,7,OBSIDIAN)
Block(4,11,8,OBSIDIAN)
Block(4,12,4,OBSIDIAN)
Block(4,12,5,OBSIDIAN)
Block(4,12,6,OBSIDIAN)
Block(4,12,7,OBSIDIAN)
Block(4,12,8,OBSIDIAN)
Block(4,13,3,OBSIDIAN)
Block(4,13,4,OBSIDIAN)
Block(4,13,5,OBSIDIAN)
Block(4,13,6,OBSIDIAN)
Block(4,13,7,OBSIDIAN)
Block(4,13,8,OBSIDIAN)
Block(4,14,2,OBSIDIAN)
Block(4,14,3,OBSIDIAN)
Block(4,14,4,OBSIDIAN)
Block(4,14,5,OBSIDIAN)
Block(4,14,6,OBSIDIAN)
Block(4,14,7,OBSIDIAN)
Block(4,14,8,OBSIDIAN)
Block(4,15,2,OBSIDIAN)
Block(4,15,3,OBSIDIAN)
Block(4,15,4,OBSIDIAN)
Block(4,15,5,OBSIDIAN)
Block(4,15,6,OBSIDIAN)
Block(4,15,7,OBSIDIAN)
Block(4,15,8,OBSIDIAN)
Block(4,16,1,OBSIDIAN)
Block(4,16,2,OBSIDIAN)
Block(4,16,3,OBSIDIAN)
Block(4,16,4,OBSIDIAN)
Block(4,16,5,OBSIDIAN)
Block(4,16,6,OBSIDIAN)
Block(4,16,7,OBSIDIAN)
Block(4,16,8,OBSIDIAN)
Block(4,17,0,OBSIDIAN)
Block(4,17,1,OBSIDIAN)
Block(4,17,2,OBSIDIAN)
Block(4,17,3,OBSIDIAN)
Block(4,17,4,OBSIDIAN)
Block(4,17,5,OBSIDIAN)
Block(4,17,6,OBSIDIAN)
Block(4,17,7,OBSIDIAN)
Block(4,17,8,OBSIDIAN)
Block(4,18,0,OBSIDIAN)
Block(4,18,1,OBSIDIAN)
Block(4,18,2,OBSIDIAN)
Block(4,18,3,OBSIDIAN)
Block(4,18,4,OBSIDIAN)
Block(4,18,5,OBSIDIAN)
Block(4,18,6,OBSIDIAN)
Block(4,18,7,OBSIDIAN)
Block(4,18,8,OBSIDIAN)
Block(4,19,-1,OBSIDIAN)
Block(4,19,0,OBSIDIAN)
Block(4,19,1,OBSIDIAN)
Block(4,19,2,OBSIDIAN)
Block(4,19,3,OBSIDIAN)
Block(4,19,4,OBSIDIAN)
Block(4,19,5,OBSIDIAN)
Block(4,19,6,OBSIDIAN)
Block(4,19,7,OBSIDIAN)
Block(4,19,8,OBSIDIAN)
Block(4,20,-1,OBSIDIAN)
Block(4,20,0,OBSIDIAN)
Block(4,20,1,OBSIDIAN)
Block(4,20,2,OBSIDIAN)
Block(4,20,3,OBSIDIAN)
Block(4,20,4,OBSIDIAN)
Block(4,20,5,OBSIDIAN)
Block(4,20,6,OBSIDIAN)
Block(4,20,7,OBSIDIAN)
Block(4,20,8,OBSIDIAN)
Block(4,21,-2,OBSIDIAN)
Block(4,21,-1,OBSIDIAN)
Block(4,21,0,OBSIDIAN)
Block(4,21,1,OBSIDIAN)
Block(4,21,2,OBSIDIAN)
Block(4,21,3,OBSIDIAN)
Block(4,21,4,OBSIDIAN)
Block(4,21,5,OBSIDIAN)
Block(4,21,6,OBSIDIAN)
Block(4,21,7,OBSIDIAN)
Block(4,22,-3,OBSIDIAN)
Block(4,22,-2,OBSIDIAN)
Block(4,22,-1,OBSIDIAN)
Block(4,22,0,OBSIDIAN)
Block(4,22,1,OBSIDIAN)
Block(4,22,2,OBSIDIAN)
Block(4,22,3,OBSIDIAN)
Block(4,22,4,OBSIDIAN)
Block(4,22,5,OBSIDIAN)
Block(4,22,6,OBSIDIAN)
Block(4,23,-3,OBSIDIAN)
Block(4,23,-2,OBSIDIAN)
Block(4,23,-1,OBSIDIAN)
Block(4,23,0,OBSIDIAN)
Block(4,23,1,OBSIDIAN)
Block(4,23,2,OBSIDIAN)
Block(4,23,3,OBSIDIAN)
Block(4,23,4,OBSIDIAN)
Block(4,23,5,OBSIDIAN)
Block(4,24,-4,OBSIDIAN)
Block(4,24,-3,OBSIDIAN)
Block(4,24,-2,OBSIDIAN)
Block(4,24,-1,OBSIDIAN)
Block(4,24,0,OBSIDIAN)
Block(4,24,1,OBSIDIAN)
Block(4,24,2,OBSIDIAN)
Block(4,24,3,OBSIDIAN)
Block(4,24,4,OBSIDIAN)
Block(4,25,-5,OBSIDIAN)
Block(4,25,-4,OBSIDIAN)
Block(4,25,-3,OBSIDIAN)
Block(4,25,-2,OBSIDIAN)
Block(4,25,-1,OBSIDIAN)
Block(4,25,0,OBSIDIAN)
Block(4,25,1,OBSIDIAN)
Block(4,25,2,OBSIDIAN)
Block(4,26,-5,OBSIDIAN)
Block(4,26,-4,OBSIDIAN)
Block(4,26,-3,OBSIDIAN)
Block(4,26,-2,OBSIDIAN)
Block(4,26,-1,OBSIDIAN)
Block(4,26,0,OBSIDIAN)
Block(4,26,1,OBSIDIAN)
Block(4,27,-6,OBSIDIAN)
Block(4,27,-5,OBSIDIAN)
Block(4,27,-4,OBSIDIAN)
Block(4,27,-3,OBSIDIAN)
Block(4,27,-2,OBSIDIAN)
Block(4,27,-1,OBSIDIAN)
Block(4,28,-6,OBSIDIAN)
Block(4,28,-5,OBSIDIAN)
Block(4,28,-4,OBSIDIAN)
Block(4,28,-3,OBSIDIAN)
Block(4,28,-2,OBSIDIAN)
Block(4,29,-7,OBSIDIAN)
Block(4,29,-6,OBSIDIAN)
Block(4,29,-5,OBSIDIAN)
Block(4,29,-4,OBSIDIAN)
Block(4,30,-7,OBSIDIAN)
Block(4,30,-6,OBSIDIAN)
Block(4,30,-5,OBSIDIAN)
Block(4,31,-7,OBSIDIAN)
Block(5,5,8,OBSIDIAN)
Block(5,6,8,OBSIDIAN)
Block(5,7,7,OBSIDIAN)
Block(5,7,8,OBSIDIAN)
Block(5,8,6,OBSIDIAN)
Block(5,8,7,OBSIDIAN)
Block(5,8,8,OBSIDIAN)
Block(5,9,6,OBSIDIAN)
Block(5,9,7,OBSIDIAN)
Block(5,9,8,OBSIDIAN)
Block(5,10,5,OBSIDIAN)
Block(5,10,6,OBSIDIAN)
Block(5,10,7,OBSIDIAN)
Block(5,10,8,OBSIDIAN)
Block(5,11,4,OBSIDIAN)
Block(5,11,5,OBSIDIAN)
Block(5,11,6,OBSIDIAN)
Block(5,11,7,OBSIDIAN)
Block(5,11,8,OBSIDIAN)
Block(5,12,4,OBSIDIAN)
Block(5,12,5,OBSIDIAN)
Block(5,12,6,OBSIDIAN)
Block(5,12,7,OBSIDIAN)
Block(5,12,8,OBSIDIAN)
Block(5,13,3,OBSIDIAN)
Block(5,13,4,OBSIDIAN)
Block(5,13,5,OBSIDIAN)
Block(5,13,6,OBSIDIAN)
Block(5,13,7,OBSIDIAN)
Block(5,13,8,OBSIDIAN)
Block(5,14,3,OBSIDIAN)
Block(5,14,4,OBSIDIAN)
Block(5,14,5,OBSIDIAN)
Block(5,14,6,OBSIDIAN)
Block(5,14,7,OBSIDIAN)
Block(5,14,8,OBSIDIAN)
Block(5,15,2,OBSIDIAN)
Block(5,15,3,OBSIDIAN)
Block(5,15,4,OBSIDIAN)
Block(5,15,5,OBSIDIAN)
Block(5,15,6,OBSIDIAN)
Block(5,15,7,OBSIDIAN)
Block(5,15,8,OBSIDIAN)
Block(5,16,1,OBSIDIAN)
Block(5,16,2,OBSIDIAN)
Block(5,16,3,OBSIDIAN)
Block(5,16,4,OBSIDIAN)
Block(5,16,5,OBSIDIAN)
Block(5,16,6,OBSIDIAN)
Block(5,16,7,OBSIDIAN)
Block(5,16,8,OBSIDIAN)
Block(5,17,1,OBSIDIAN)
Block(5,17,2,OBSIDIAN)
Block(5,17,3,OBSIDIAN)
Block(5,17,4,OBSIDIAN)
Block(5,17,5,OBSIDIAN)
Block(5,17,6,OBSIDIAN)
Block(5,17,7,OBSIDIAN)
Block(5,17,8,OBSIDIAN)
Block(5,18,0,OBSIDIAN)
Block(5,18,1,OBSIDIAN)
Block(5,18,2,OBSIDIAN)
Block(5,18,3,OBSIDIAN)
Block(5,18,4,OBSIDIAN)
Block(5,18,5,OBSIDIAN)
Block(5,18,6,OBSIDIAN)
Block(5,18,7,OBSIDIAN)
Block(5,18,8,OBSIDIAN)
Block(5,19,-1,OBSIDIAN)
Block(5,19,0,OBSIDIAN)
Block(5,19,1,OBSIDIAN)
Block(5,19,2,OBSIDIAN)
Block(5,19,3,OBSIDIAN)
Block(5,19,4,OBSIDIAN)
Block(5,19,5,OBSIDIAN)
Block(5,19,6,OBSIDIAN)
Block(5,19,7,OBSIDIAN)
Block(5,20,-1,OBSIDIAN)
Block(5,20,0,OBSIDIAN)
Block(5,20,1,OBSIDIAN)
Block(5,20,2,OBSIDIAN)
Block(5,20,3,OBSIDIAN)
Block(5,20,4,OBSIDIAN)
Block(5,20,5,OBSIDIAN)
Block(5,20,6,OBSIDIAN)
Block(5,21,-2,OBSIDIAN)
Block(5,21,-1,OBSIDIAN)
Block(5,21,0,OBSIDIAN)
Block(5,21,1,OBSIDIAN)
Block(5,21,2,OBSIDIAN)
Block(5,21,3,OBSIDIAN)
Block(5,21,4,OBSIDIAN)
Block(5,21,5,OBSIDIAN)
Block(5,21,6,OBSIDIAN)
Block(5,22,-2,OBSIDIAN)
Block(5,22,-1,OBSIDIAN)
Block(5,22,0,OBSIDIAN)
Block(5,22,1,OBSIDIAN)
Block(5,22,2,OBSIDIAN)
Block(5,22,3,OBSIDIAN)
Block(5,22,4,OBSIDIAN)
Block(5,22,5,OBSIDIAN)
Block(5,23,-3,OBSIDIAN)
Block(5,23,-2,OBSIDIAN)
Block(5,23,-1,OBSIDIAN)
Block(5,23,0,OBSIDIAN)
Block(5,23,1,OBSIDIAN)
Block(5,23,2,OBSIDIAN)
Block(5,23,3,OBSIDIAN)
Block(5,23,4,OBSIDIAN)
Block(5,24,-4,OBSIDIAN)
Block(5,24,-3,OBSIDIAN)
Block(5,24,-2,OBSIDIAN)
Block(5,24,-1,OBSIDIAN)
Block(5,24,0,OBSIDIAN)
Block(5,24,1,OBSIDIAN)
Block(5,24,2,OBSIDIAN)
Block(5,24,3,OBSIDIAN)
Block(5,25,-4,OBSIDIAN)
Block(5,25,-3,OBSIDIAN)
Block(5,25,-2,OBSIDIAN)
Block(5,25,-1,OBSIDIAN)
Block(5,25,0,OBSIDIAN)
Block(5,25,1,OBSIDIAN)
Block(5,25,2,OBSIDIAN)
Block(5,26,-5,OBSIDIAN)
Block(5,26,-4,OBSIDIAN)
Block(5,26,-3,OBSIDIAN)
Block(5,26,-2,OBSIDIAN)
Block(5,26,-1,OBSIDIAN)
Block(5,26,0,OBSIDIAN)
Block(5,26,1,OBSIDIAN)
Block(5,27,-6,OBSIDIAN)
Block(5,27,-5,OBSIDIAN)
Block(5,27,-4,OBSIDIAN)
Block(5,27,-3,OBSIDIAN)
Block(5,27,-2,OBSIDIAN)
Block(5,27,-1,OBSIDIAN)
Block(5,27,0,OBSIDIAN)
Block(5,27,1,OBSIDIAN)
Block(5,28,-6,OBSIDIAN)
Block(5,28,-5,OBSIDIAN)
Block(5,28,-4,OBSIDIAN)
Block(5,28,-3,OBSIDIAN)
Block(5,28,-2,OBSIDIAN)
Block(5,28,-1,OBSIDIAN)
Block(5,28,0,OBSIDIAN)
Block(5,29,-7,OBSIDIAN)
Block(5,29,-6,OBSIDIAN)
Block(5,29,-5,OBSIDIAN)
Block(5,29,-4,OBSIDIAN)
Block(5,29,-3,OBSIDIAN)
Block(5,29,-2,OBSIDIAN)
Block(5,29,-1,OBSIDIAN)
Block(5,30,-7,OBSIDIAN)
Block(5,30,-6,OBSIDIAN)
Block(5,30,-5,OBSIDIAN)
Block(5,30,-4,OBSIDIAN)
Block(5,30,-3,OBSIDIAN)
Block(5,30,-2,OBSIDIAN)
Block(5,31,-7,OBSIDIAN)
Block(5,31,-6,OBSIDIAN)
Block(5,31,-5,OBSIDIAN)
Block(5,31,-4,OBSIDIAN)
Block(5,31,-3,OBSIDIAN)
Block(5,32,-7,OBSIDIAN)
Block(5,32,-6,OBSIDIAN)
Block(5,32,-5,OBSIDIAN)
Block(5,33,-7,OBSIDIAN)
Block(5,33,-6,OBSIDIAN)
Block(6,5,8,OBSIDIAN)
Block(6,6,8,OBSIDIAN)
Block(6,7,7,OBSIDIAN)
Block(6,7,8,OBSIDIAN)
Block(6,8,6,OBSIDIAN)
Block(6,8,7,OBSIDIAN)
Block(6,8,8,OBSIDIAN)
Block(6,9,6,OBSIDIAN)
Block(6,9,7,OBSIDIAN)
Block(6,9,8,OBSIDIAN)
Block(6,10,5,OBSIDIAN)
Block(6,10,6,OBSIDIAN)
Block(6,10,7,OBSIDIAN)
Block(6,10,8,OBSIDIAN)
Block(6,11,5,OBSIDIAN)
Block(6,11,6,OBSIDIAN)
Block(6,11,7,OBSIDIAN)
Block(6,11,8,OBSIDIAN)
Block(6,12,4,OBSIDIAN)
Block(6,12,5,OBSIDIAN)
Block(6,12,6,OBSIDIAN)
Block(6,12,7,OBSIDIAN)
Block(6,12,8,OBSIDIAN)
Block(6,13,3,OBSIDIAN)
Block(6,13,4,OBSIDIAN)
Block(6,13,5,OBSIDIAN)
Block(6,13,6,OBSIDIAN)
Block(6,13,7,OBSIDIAN)
Block(6,13,8,OBSIDIAN)
Block(6,14,3,OBSIDIAN)
Block(6,14,4,OBSIDIAN)
Block(6,14,5,OBSIDIAN)
Block(6,14,6,OBSIDIAN)
Block(6,14,7,OBSIDIAN)
Block(6,14,8,OBSIDIAN)
Block(6,15,2,OBSIDIAN)
Block(6,15,3,OBSIDIAN)
Block(6,15,4,OBSIDIAN)
Block(6,15,5,OBSIDIAN)
Block(6,15,6,OBSIDIAN)
Block(6,15,7,OBSIDIAN)
Block(6,15,8,OBSIDIAN)
Block(6,16,1,OBSIDIAN)
Block(6,16,2,OBSIDIAN)
Block(6,16,3,OBSIDIAN)
Block(6,16,4,OBSIDIAN)
Block(6,16,5,OBSIDIAN)
Block(6,16,6,OBSIDIAN)
Block(6,16,7,OBSIDIAN)
Block(6,16,8,OBSIDIAN)
Block(6,17,1,OBSIDIAN)
Block(6,17,2,OBSIDIAN)
Block(6,17,3,OBSIDIAN)
Block(6,17,4,OBSIDIAN)
Block(6,17,5,OBSIDIAN)
Block(6,17,6,OBSIDIAN)
Block(6,17,7,OBSIDIAN)
Block(6,18,0,OBSIDIAN)
Block(6,18,1,OBSIDIAN)
Block(6,18,2,OBSIDIAN)
Block(6,18,3,OBSIDIAN)
Block(6,18,4,OBSIDIAN)
Block(6,18,5,OBSIDIAN)
Block(6,18,6,OBSIDIAN)
Block(6,19,0,OBSIDIAN)
Block(6,19,1,OBSIDIAN)
Block(6,19,2,OBSIDIAN)
Block(6,19,3,OBSIDIAN)
Block(6,19,4,OBSIDIAN)
Block(6,19,5,OBSIDIAN)
Block(6,19,6,OBSIDIAN)
Block(6,20,-1,OBSIDIAN)
Block(6,20,0,OBSIDIAN)
Block(6,20,1,OBSIDIAN)
Block(6,20,2,OBSIDIAN)
Block(6,20,3,OBSIDIAN)
Block(6,20,4,OBSIDIAN)
Block(6,20,5,OBSIDIAN)
Block(6,21,-2,OBSIDIAN)
Block(6,21,-1,OBSIDIAN)
Block(6,21,0,OBSIDIAN)
Block(6,21,1,OBSIDIAN)
Block(6,21,2,OBSIDIAN)
Block(6,21,3,OBSIDIAN)
Block(6,21,4,OBSIDIAN)
Block(6,22,-2,OBSIDIAN)
Block(6,22,-1,OBSIDIAN)
Block(6,22,0,OBSIDIAN)
Block(6,22,1,OBSIDIAN)
Block(6,22,2,OBSIDIAN)
Block(6,22,3,OBSIDIAN)
Block(6,23,-3,OBSIDIAN)
Block(6,23,-2,OBSIDIAN)
Block(6,23,-1,OBSIDIAN)
Block(6,23,0,OBSIDIAN)
Block(6,23,1,OBSIDIAN)
Block(6,23,2,OBSIDIAN)
Block(6,24,-4,OBSIDIAN)
Block(6,24,-3,OBSIDIAN)
Block(6,24,-2,OBSIDIAN)
Block(6,24,-1,OBSIDIAN)
Block(6,24,0,OBSIDIAN)
Block(6,24,1,OBSIDIAN)
Block(6,25,-4,OBSIDIAN)
Block(6,25,-3,OBSIDIAN)
Block(6,25,-2,OBSIDIAN)
Block(6,25,-1,OBSIDIAN)
Block(6,25,0,OBSIDIAN)
Block(6,25,1,OBSIDIAN)
Block(6,26,-5,OBSIDIAN)
Block(6,26,-4,OBSIDIAN)
Block(6,26,-3,OBSIDIAN)
Block(6,26,-2,OBSIDIAN)
Block(6,26,-1,OBSIDIAN)
Block(6,26,0,OBSIDIAN)
Block(6,27,-5,OBSIDIAN)
Block(6,27,-4,OBSIDIAN)
Block(6,27,-3,OBSIDIAN)
Block(6,27,-2,OBSIDIAN)
Block(6,27,-1,OBSIDIAN)
Block(6,28,-6,OBSIDIAN)
Block(6,28,-5,OBSIDIAN)
Block(6,28,-4,OBSIDIAN)
Block(6,28,-3,OBSIDIAN)
Block(6,28,-2,OBSIDIAN)
Block(6,29,-7,OBSIDIAN)
Block(6,29,-6,OBSIDIAN)
Block(6,29,-5,OBSIDIAN)
Block(6,29,-4,OBSIDIAN)
Block(6,29,-3,OBSIDIAN)
Block(6,30,-7,OBSIDIAN)
Block(6,30,-6,OBSIDIAN)
Block(6,30,-5,OBSIDIAN)
Block(6,30,-4,OBSIDIAN)
Block(6,30,-3,OBSIDIAN)
Block(6,31,-7,OBSIDIAN)
Block(6,31,-6,OBSIDIAN)
Block(6,31,-5,OBSIDIAN)
Block(6,31,-4,OBSIDIAN)
Block(6,32,-7,OBSIDIAN)
Block(6,32,-6,OBSIDIAN)
Block(6,32,-5,OBSIDIAN)
Block(6,33,-7,OBSIDIAN)
Block(6,33,-6,OBSIDIAN)
Block(6,34,-7,OBSIDIAN)
Block(7,5,8,OBSIDIAN)
Block(7,6,8,OBSIDIAN)
Block(7,7,7,OBSIDIAN)
Block(7,7,8,OBSIDIAN)
Block(7,8,7,OBSIDIAN)
Block(7,8,8,OBSIDIAN)
Block(7,9,6,OBSIDIAN)
Block(7,9,7,OBSIDIAN)
Block(7,9,8,OBSIDIAN)
Block(7,10,5,OBSIDIAN)
Block(7,10,6,OBSIDIAN)
Block(7,10,7,OBSIDIAN)
Block(7,10,8,OBSIDIAN)
Block(7,11,5,OBSIDIAN)
Block(7,11,6,OBSIDIAN)
Block(7,11,7,OBSIDIAN)
Block(7,11,8,OBSIDIAN)
Block(7,12,4,OBSIDIAN)
Block(7,12,5,OBSIDIAN)
Block(7,12,6,OBSIDIAN)
Block(7,12,7,OBSIDIAN)
Block(7,12,8,OBSIDIAN)
Block(7,13,3,OBSIDIAN)
Block(7,13,4,OBSIDIAN)
Block(7,13,5,OBSIDIAN)
Block(7,13,6,OBSIDIAN)
Block(7,13,7,OBSIDIAN)
Block(7,13,8,OBSIDIAN)
Block(7,14,3,OBSIDIAN)
Block(7,14,4,OBSIDIAN)
Block(7,14,5,OBSIDIAN)
Block(7,14,6,OBSIDIAN)
Block(7,14,7,OBSIDIAN)
Block(7,14,8,OBSIDIAN)
Block(7,15,2,OBSIDIAN)
Block(7,15,3,OBSIDIAN)
Block(7,15,4,OBSIDIAN)
Block(7,15,5,OBSIDIAN)
Block(7,15,6,OBSIDIAN)
Block(7,15,7,OBSIDIAN)
Block(7,16,2,OBSIDIAN)
Block(7,16,3,OBSIDIAN)
Block(7,16,4,OBSIDIAN)
Block(7,16,5,OBSIDIAN)
Block(7,16,6,OBSIDIAN)
Block(7,17,1,OBSIDIAN)
Block(7,17,2,OBSIDIAN)
Block(7,17,3,OBSIDIAN)
Block(7,17,4,OBSIDIAN)
Block(7,17,5,OBSIDIAN)
Block(7,17,6,OBSIDIAN)
Block(7,18,0,OBSIDIAN)
Block(7,18,1,OBSIDIAN)
Block(7,18,2,OBSIDIAN)
Block(7,18,3,OBSIDIAN)
Block(7,18,4,OBSIDIAN)
Block(7,18,5,OBSIDIAN)
Block(7,19,0,OBSIDIAN)
Block(7,19,1,OBSIDIAN)
Block(7,19,2,OBSIDIAN)
Block(7,19,3,OBSIDIAN)
Block(7,19,4,OBSIDIAN)
Block(7,20,-1,OBSIDIAN)
Block(7,20,0,OBSIDIAN)
Block(7,20,1,OBSIDIAN)
Block(7,20,2,OBSIDIAN)
Block(7,20,3,OBSIDIAN)
Block(7,21,-2,OBSIDIAN)
Block(7,21,-1,OBSIDIAN)
Block(7,21,0,OBSIDIAN)
Block(7,21,1,OBSIDIAN)
Block(7,21,2,OBSIDIAN)
Block(7,22,-2,OBSIDIAN)
Block(7,22,-1,OBSIDIAN)
Block(7,22,0,OBSIDIAN)
Block(7,22,1,OBSIDIAN)
Block(7,22,2,OBSIDIAN)
Block(7,23,-3,OBSIDIAN)
Block(7,23,-2,OBSIDIAN)
Block(7,23,-1,OBSIDIAN)
Block(7,23,0,OBSIDIAN)
Block(7,23,1,OBSIDIAN)
Block(7,24,-3,OBSIDIAN)
Block(7,24,-2,OBSIDIAN)
Block(7,24,-1,OBSIDIAN)
Block(7,24,0,OBSIDIAN)
Block(7,25,-4,OBSIDIAN)
Block(7,25,-3,OBSIDIAN)
Block(7,25,-2,OBSIDIAN)
Block(7,25,-1,OBSIDIAN)
Block(7,26,-5,OBSIDIAN)
Block(7,26,-4,OBSIDIAN)
Block(7,26,-3,OBSIDIAN)
Block(7,26,-2,OBSIDIAN)
Block(7,27,-5,OBSIDIAN)
Block(7,27,-4,OBSIDIAN)
Block(7,27,-3,OBSIDIAN)
Block(7,28,-6,OBSIDIAN)
Block(7,28,-5,OBSIDIAN)
Block(7,28,-4,OBSIDIAN)
Block(7,28,-3,OBSIDIAN)
Block(7,29,-7,OBSIDIAN)
Block(7,29,-6,OBSIDIAN)
Block(7,29,-5,OBSIDIAN)
Block(7,29,-4,OBSIDIAN)
Block(7,30,-7,OBSIDIAN)
Block(7,30,-6,OBSIDIAN)
Block(7,30,-5,OBSIDIAN)
Block(7,31,-7,OBSIDIAN)
Block(7,31,-6,OBSIDIAN)
Block(7,32,-7,OBSIDIAN)

#######################################################################
# +-----------------------------------------------------------------+ #
# |                             Branches                            | #
# +-----------------------------------------------------------------+ #
#######################################################################


#######################################################################
# +-----------------------------------------------------------------+ #
# |                             Entities                            | #
# +-----------------------------------------------------------------+ #
#######################################################################


#######################################################################
# +-----------------------------------------------------------------+ #
# |                            Particles                            | #
# +-----------------------------------------------------------------+ #
#######################################################################


#######################################################################
# +-----------------------------------------------------------------+ #
# |                             Spawners                            | #
# +-----------------------------------------------------------------+ #
#######################################################################


#######################################################################
# +-----------------------------------------------------------------+ #
# |                             ModData                             | #
# +-----------------------------------------------------------------+ #
#######################################################################

