#######################################################################
# +-----------------------------------------------------------------+ #
# |                            BO3 object                           | #
# +-----------------------------------------------------------------+ #
#######################################################################

Author: Bo3 BulkEdit

Description: Converted Schematic - Modified by Bo3BulkEdit

Version: 3

SettingsMode: WriteDisable

#######################################################################
# +-----------------------------------------------------------------+ #
# |                          Main settings                          | #
# +-----------------------------------------------------------------+ #
#######################################################################

IsOTGPlus: true
Tree: false
Frequency: 1
Rarity: 100.0
RotateRandomly: false
SpawnHeight: randomY
MaxBranchDepth: 10
ExcludedBiomes: All

##############################
# Height Limits for the BO3. #
##############################

MinHeight: 0
MaxHeight: 255

#######################################################################
# +-----------------------------------------------------------------+ #
# |                      Source block settings                      | #
# +-----------------------------------------------------------------+ #
#######################################################################

CanOverride: true
MaxPercentageOutsideSourceBlock: 100
OutsideSourceBlock: placeAnyway

#######################################################################
# +-----------------------------------------------------------------+ #
# |                               OTG+                              | #
# +-----------------------------------------------------------------+ #
#######################################################################

BO3Group: CeilingCrystals:0

#######################################################################
# +-----------------------------------------------------------------+ #
# |                              Blocks                             | #
# +-----------------------------------------------------------------+ #
#######################################################################

B(0,750,0,AIR)
B(15,750,15,AIR)
B(1,-12,15,betternether:quartz_stained_glass:15)
B(2,-12,15,betternether:quartz_stained_glass:15)
B(3,-12,15,betternether:quartz_stained_glass:15)
B(0,-11,13,betternether:quartz_stained_glass:15)
B(1,-11,13,betternether:quartz_stained_glass:15)
B(0,-11,14,betternether:quartz_stained_glass:15)
B(1,-11,14,betternether:quartz_stained_glass:15)
B(2,-11,14,betternether:quartz_stained_glass:15)
B(0,-11,15,betternether:quartz_stained_glass:15)
B(1,-11,15,betternether:quartz_stained_glass:15)
B(2,-11,15,betternether:quartz_stained_glass:15)
B(3,-11,15,betternether:quartz_stained_glass:15)
B(0,-10,12,betternether:quartz_stained_glass:15)
B(0,-10,13,betternether:quartz_stained_glass:15)
B(1,-10,13,betternether:quartz_stained_glass:15)
B(0,-10,14,betternether:quartz_stained_glass:15)
B(1,-10,14,betternether:quartz_stained_glass:15)
B(2,-10,14,betternether:quartz_stained_glass:15)
B(0,-10,15,betternether:quartz_stained_glass:15)
B(1,-10,15,betternether:quartz_stained_glass:15)
B(2,-10,15,betternether:quartz_stained_glass:15)
B(3,-10,15,betternether:quartz_stained_glass:15)
B(0,-9,12,betternether:quartz_stained_glass:15)
B(0,-9,13,betternether:quartz_stained_glass:15)
B(1,-9,13,betternether:quartz_stained_glass:15)
B(0,-9,14,betternether:quartz_stained_glass:15)
B(1,-9,14,betternether:quartz_stained_glass:15)
B(2,-9,14,betternether:quartz_stained_glass:15)
B(0,-9,15,betternether:quartz_stained_glass:15)
B(1,-9,15,betternether:quartz_stained_glass:15)
B(2,-9,15,betternether:quartz_stained_glass:15)
B(3,-9,15,betternether:quartz_stained_glass:15)
B(0,-8,12,betternether:quartz_stained_glass:15)
B(0,-8,13,betternether:quartz_stained_glass:15)
B(1,-8,13,betternether:quartz_stained_glass:15)
B(0,-8,14,betternether:quartz_stained_glass:15)
B(1,-8,14,betternether:quartz_stained_glass:15)
B(2,-8,14,betternether:quartz_stained_glass:15)
RB(0,-8,15,srparasites:parasitestain:1,80,quark:crystal:1,30,srparasites:parasiterubbledense:1,100)
B(1,-8,15,betternether:quartz_stained_glass:15)
B(2,-8,15,betternether:quartz_stained_glass:15)
B(3,-8,15,betternether:quartz_stained_glass:15)
B(0,-7,12,betternether:quartz_stained_glass:15)
B(0,-7,13,betternether:quartz_stained_glass:15)
B(1,-7,13,betternether:quartz_stained_glass:15)
B(0,-7,14,betternether:quartz_stained_glass:15)
B(1,-7,14,betternether:quartz_stained_glass:15)
B(2,-7,14,betternether:quartz_stained_glass:15)
B(0,-7,15,betternether:quartz_stained_glass:15)
B(1,-7,15,betternether:quartz_stained_glass:15)
B(2,-7,15,betternether:quartz_stained_glass:15)
B(3,-7,15,betternether:quartz_stained_glass:15)
B(0,-6,12,betternether:quartz_stained_glass:15)
B(0,-6,13,betternether:quartz_stained_glass:15)
B(1,-6,13,betternether:quartz_stained_glass:15)
B(0,-6,14,betternether:quartz_stained_glass:15)
B(1,-6,14,betternether:quartz_stained_glass:15)
B(2,-6,14,betternether:quartz_stained_glass:15)
B(0,-6,15,betternether:quartz_stained_glass:15)
B(1,-6,15,betternether:quartz_stained_glass:15)
B(2,-6,15,betternether:quartz_stained_glass:15)
B(3,-6,15,betternether:quartz_stained_glass:15)
B(0,-5,12,betternether:quartz_stained_glass:15)
B(0,-5,13,betternether:quartz_stained_glass:15)
B(1,-5,13,betternether:quartz_stained_glass:15)
B(0,-5,14,betternether:quartz_stained_glass:15)
B(1,-5,14,betternether:quartz_stained_glass:15)
B(2,-5,14,betternether:quartz_stained_glass:15)
B(0,-5,15,betternether:quartz_stained_glass:15)
B(1,-5,15,betternether:quartz_stained_glass:15)
B(2,-5,15,betternether:quartz_stained_glass:15)
B(0,-4,12,betternether:quartz_stained_glass:15)
B(0,-4,13,betternether:quartz_stained_glass:15)
B(0,-4,14,betternether:quartz_stained_glass:15)

