#######################################################################
# +-----------------------------------------------------------------+ #
# |                            BO3 object                           | #
# +-----------------------------------------------------------------+ #
#######################################################################

Author: Bo3 BulkEdit

Description: Converted Schematic - Modified by Bo3BulkEdit

Version: 3

SettingsMode: WriteDisable

#######################################################################
# +-----------------------------------------------------------------+ #
# |                          Main settings                          | #
# +-----------------------------------------------------------------+ #
#######################################################################



Frequency: 0


SpawnHeight: randomY





##############################
# Height Limits for the BO3. #
##############################

MinHeight: 0
MaxHeight: 256

#######################################################################
# +-----------------------------------------------------------------+ #
# |                      Source block settings                      | #
# +-----------------------------------------------------------------+ #
#######################################################################

CanOverride: true
MaxPercentageOutsideSourceBlock: 100
OutsideSourceBlock: placeAnyway

#######################################################################
# +-----------------------------------------------------------------+ #
# |                               OTG+                              | #
# +-----------------------------------------------------------------+ #
#######################################################################

#######################################################################
# +-----------------------------------------------------------------+ #
# |                              Blocks                             | #
# +-----------------------------------------------------------------+ #
#######################################################################

B(0,750,0,AIR)
B(15,750,15,AIR)
B(6,-1,15,betternether:quartz_stained_glass:15)
B(8,-1,15,betternether:quartz_stained_glass:15)
B(9,-1,15,betternether:quartz_stained_glass:15)
B(5,0,14,betternether:quartz_stained_glass:15)
B(6,0,14,betternether:quartz_stained_glass:15)
B(7,0,14,betternether:quartz_stained_glass:15)
B(8,0,14,betternether:quartz_stained_glass:15)
B(9,0,14,betternether:quartz_stained_glass:15)
B(6,0,15,betternether:quartz_stained_glass:15)
B(7,0,15,betternether:quartz_stained_glass:15)
B(8,0,15,betternether:quartz_stained_glass:15)
B(9,0,15,betternether:quartz_stained_glass:15)
B(9,1,12,betternether:quartz_stained_glass:15)
B(5,1,13,betternether:quartz_stained_glass:15)
B(7,1,13,betternether:quartz_stained_glass:15)
B(9,1,13,betternether:quartz_stained_glass:15)
B(5,1,14,betternether:quartz_stained_glass:15)
B(6,1,14,betternether:quartz_stained_glass:15)
B(7,1,14,betternether:quartz_stained_glass:15)
B(8,1,14,betternether:quartz_stained_glass:15)
B(9,1,14,betternether:quartz_stained_glass:15)
B(4,1,15,betternether:quartz_stained_glass:15)
B(5,1,15,betternether:quartz_stained_glass:15)
B(6,1,15,betternether:quartz_stained_glass:15)
B(7,1,15,betternether:quartz_stained_glass:15)
B(8,1,15,betternether:quartz_stained_glass:15)
B(9,1,15,betternether:quartz_stained_glass:15)
B(10,1,15,betternether:quartz_stained_glass:15)
B(11,1,15,betternether:quartz_stained_glass:15)
B(7,2,12,betternether:quartz_stained_glass:15)
B(8,2,12,betternether:quartz_stained_glass:15)
B(9,2,12,betternether:quartz_stained_glass:15)
B(4,2,13,betternether:quartz_stained_glass:15)
B(5,2,13,betternether:quartz_stained_glass:15)
B(6,2,13,betternether:quartz_stained_glass:15)
B(7,2,13,betternether:quartz_stained_glass:15)
B(8,2,13,betternether:quartz_stained_glass:15)
B(9,2,13,betternether:quartz_stained_glass:15)
B(4,2,14,betternether:quartz_stained_glass:15)
B(5,2,14,betternether:quartz_stained_glass:15)
B(6,2,14,betternether:quartz_stained_glass:15)
B(7,2,14,betternether:quartz_stained_glass:15)
B(8,2,14,betternether:quartz_stained_glass:15)
B(9,2,14,betternether:quartz_stained_glass:15)
B(10,2,14,betternether:quartz_stained_glass:15)
B(4,2,15,betternether:quartz_stained_glass:15)
B(5,2,15,betternether:quartz_stained_glass:15)
B(6,2,15,betternether:quartz_stained_glass:15)
RB(7,2,15,srparasites:parasitestain:1,80,quark:crystal:1,30,srparasites:parasiterubbledense:1,100)
RB(8,2,15,srparasites:parasitestain:1,80,quark:crystal:1,30,srparasites:parasiterubbledense:1,100)
B(9,2,15,betternether:quartz_stained_glass:15)
B(10,2,15,betternether:quartz_stained_glass:15)
B(11,2,15,betternether:quartz_stained_glass:15)
B(7,3,11,betternether:quartz_stained_glass:15)
B(8,3,11,betternether:quartz_stained_glass:15)
B(5,3,12,betternether:quartz_stained_glass:15)
B(6,3,12,betternether:quartz_stained_glass:15)
B(7,3,12,betternether:quartz_stained_glass:15)
B(8,3,12,betternether:quartz_stained_glass:15)
B(9,3,12,betternether:quartz_stained_glass:15)
B(3,3,13,betternether:quartz_stained_glass:15)
B(4,3,13,betternether:quartz_stained_glass:15)
B(5,3,13,betternether:quartz_stained_glass:15)
B(6,3,13,betternether:quartz_stained_glass:15)
RB(7,3,13,srparasites:parasitestain:1,80,quark:crystal:1,30,srparasites:parasiterubbledense:1,100)
B(8,3,13,betternether:quartz_stained_glass:15)
B(9,3,13,betternether:quartz_stained_glass:15)
B(4,3,14,betternether:quartz_stained_glass:15)
B(5,3,14,betternether:quartz_stained_glass:15)
RB(6,3,14,srparasites:parasitestain:1,80,quark:crystal:1,30,srparasites:parasiterubbledense:1,100)
RB(7,3,14,srparasites:parasitestain:1,80,quark:crystal:1,30,srparasites:parasiterubbledense:1,100)
B(8,3,14,betternether:quartz_stained_glass:15)
B(9,3,14,betternether:quartz_stained_glass:15)
B(10,3,14,betternether:quartz_stained_glass:15)
B(4,3,15,betternether:quartz_stained_glass:15)
B(5,3,15,betternether:quartz_stained_glass:15)
B(6,3,15,betternether:quartz_stained_glass:15)
RB(7,3,15,srparasites:parasitestain:1,80,quark:crystal:1,30,srparasites:parasiterubbledense:1,100)
RB(8,3,15,srparasites:parasitestain:1,80,quark:crystal:1,30,srparasites:parasiterubbledense:1,100)
B(9,3,15,betternether:quartz_stained_glass:15)
B(10,3,15,betternether:quartz_stained_glass:15)
B(8,4,10,betternether:quartz_stained_glass:15)
B(5,4,11,betternether:quartz_stained_glass:15)
B(6,4,11,betternether:quartz_stained_glass:15)
B(7,4,11,betternether:quartz_stained_glass:15)
B(8,4,11,betternether:quartz_stained_glass:15)
B(3,4,12,betternether:quartz_stained_glass:15)
B(4,4,12,betternether:quartz_stained_glass:15)
B(5,4,12,betternether:quartz_stained_glass:15)
B(6,4,12,betternether:quartz_stained_glass:15)
B(7,4,12,betternether:quartz_stained_glass:15)
B(8,4,12,betternether:quartz_stained_glass:15)
B(9,4,12,betternether:quartz_stained_glass:15)
B(10,4,12,betternether:quartz_stained_glass:15)
B(3,4,13,betternether:quartz_stained_glass:15)
B(4,4,13,betternether:quartz_stained_glass:15)
B(5,4,13,betternether:quartz_stained_glass:15)
RB(6,4,13,srparasites:parasitestain:1,80,quark:crystal:1,30,srparasites:parasiterubbledense:1,100)
RB(7,4,13,srparasites:parasitestain:1,80,quark:crystal:1,30,srparasites:parasiterubbledense:1,100)
B(8,4,13,betternether:quartz_stained_glass:15)
B(9,4,13,betternether:quartz_stained_glass:15)
B(10,4,13,betternether:quartz_stained_glass:15)
B(4,4,14,betternether:quartz_stained_glass:15)
B(5,4,14,betternether:quartz_stained_glass:15)
RB(6,4,14,srparasites:parasitestain:1,80,quark:crystal:1,30,srparasites:parasiterubbledense:1,100)
RB(7,4,14,srparasites:parasitestain:1,80,quark:crystal:1,30,srparasites:parasiterubbledense:1,100)
B(8,4,14,betternether:quartz_stained_glass:15)
B(9,4,14,betternether:quartz_stained_glass:15)
B(10,4,14,betternether:quartz_stained_glass:15)
B(3,4,15,betternether:quartz_stained_glass:15)
B(4,4,15,betternether:quartz_stained_glass:15)
B(5,4,15,srparasites:parasiterubbledense:1)
B(6,4,15,srparasites:parasiterubbledense:1)
B(7,4,15,srparasites:parasiterubbledense:1)
B(8,4,15,betternether:quartz_stained_glass:15)
B(9,4,15,betternether:quartz_stained_glass:15)
B(10,4,15,betternether:quartz_stained_glass:15)
B(8,5,9,betternether:quartz_stained_glass:15)
B(7,5,10,betternether:quartz_stained_glass:15)
B(8,5,10,srparasites:parasiterubbledense:1)
B(3,5,11,betternether:quartz_stained_glass:15)
B(4,5,11,betternether:quartz_stained_glass:15)
B(5,5,11,betternether:quartz_stained_glass:15)
B(6,5,11,betternether:quartz_stained_glass:15)
B(7,5,11,srparasites:parasiterubbledense:1)
B(8,5,11,betternether:quartz_stained_glass:15)
B(3,5,12,betternether:quartz_stained_glass:15)
B(4,5,12,betternether:quartz_stained_glass:15)
B(5,5,12,betternether:quartz_stained_glass:15)
B(6,5,12,betternether:quartz_stained_glass:15)
RB(7,5,12,srparasites:parasitestain:1,80,quark:crystal:1,30,srparasites:parasiterubbledense:1,100)
B(8,5,12,srparasites:parasiterubbledense:1)
B(9,5,12,betternether:quartz_stained_glass:15)
B(10,5,12,betternether:quartz_stained_glass:15)
B(3,5,13,betternether:quartz_stained_glass:15)
B(4,5,13,betternether:quartz_stained_glass:15)
B(5,5,13,betternether:quartz_stained_glass:15)
RB(6,5,13,srparasites:parasitestain:1,80,quark:crystal:1,30,srparasites:parasiterubbledense:1,100)
RB(7,5,13,srparasites:parasitestain:1,80,quark:crystal:1,30,srparasites:parasiterubbledense:1,100)
B(8,5,13,betternether:quartz_stained_glass:15)
B(9,5,13,betternether:quartz_stained_glass:15)
B(10,5,13,betternether:quartz_stained_glass:15)
B(4,5,14,betternether:quartz_stained_glass:15)
B(5,5,14,betternether:quartz_stained_glass:15)
RB(6,5,14,srparasites:parasitestain:1,80,quark:crystal:1,30,srparasites:parasiterubbledense:1,100)
B(7,5,14,srparasites:parasiterubbledense:1)
B(8,5,14,betternether:quartz_stained_glass:15)
B(9,5,14,betternether:quartz_stained_glass:15)
B(3,5,15,betternether:quartz_stained_glass:15)
B(4,5,15,betternether:quartz_stained_glass:15)
B(5,5,15,srparasites:parasiterubbledense:1)
B(6,5,15,srparasites:parasiterubbledense:1)
B(7,5,15,srparasites:parasiterubbledense:1)
B(8,5,15,betternether:quartz_stained_glass:15)
B(9,5,15,betternether:quartz_stained_glass:15)
B(10,5,15,betternether:quartz_stained_glass:15)
B(6,6,9,betternether:quartz_stained_glass:15)
B(7,6,9,betternether:quartz_stained_glass:15)
B(8,6,9,betternether:quartz_stained_glass:15)
B(3,6,10,betternether:quartz_stained_glass:15)
B(4,6,10,betternether:quartz_stained_glass:15)
B(5,6,10,betternether:quartz_stained_glass:15)
B(6,6,10,betternether:quartz_stained_glass:15)
B(7,6,10,srparasites:parasiterubbledense:1)
B(8,6,10,srparasites:parasiterubbledense:1)
B(3,6,11,betternether:quartz_stained_glass:15)
B(4,6,11,betternether:quartz_stained_glass:15)
B(5,6,11,betternether:quartz_stained_glass:15)
B(6,6,11,betternether:quartz_stained_glass:15)
B(7,6,11,srparasites:parasiterubbledense:1)
B(8,6,11,betternether:quartz_stained_glass:15)
B(9,6,11,betternether:quartz_stained_glass:15)
B(10,6,11,betternether:quartz_stained_glass:15)
B(3,6,12,betternether:quartz_stained_glass:15)
B(4,6,12,betternether:quartz_stained_glass:15)
B(5,6,12,betternether:quartz_stained_glass:15)
RB(6,6,12,srparasites:parasitestain:1,80,quark:crystal:1,30,srparasites:parasiterubbledense:1,100)
RB(7,6,12,srparasites:parasitestain:1,80,quark:crystal:1,30,srparasites:parasiterubbledense:1,100)
B(8,6,12,srparasites:parasiterubbledense:1)
B(9,6,12,betternether:quartz_stained_glass:15)
B(10,6,12,betternether:quartz_stained_glass:15)
B(3,6,13,betternether:quartz_stained_glass:15)
B(4,6,13,betternether:quartz_stained_glass:15)
B(5,6,13,betternether:quartz_stained_glass:15)
RB(6,6,13,srparasites:parasitestain:1,80,quark:crystal:1,30,srparasites:parasiterubbledense:1,100)
B(7,6,13,betternether:quartz_stained_glass:15)
B(8,6,13,srparasites:parasiterubbledense:1)
B(9,6,13,betternether:quartz_stained_glass:15)
B(10,6,13,betternether:quartz_stained_glass:15)
B(3,6,14,betternether:quartz_stained_glass:15)
B(4,6,14,betternether:quartz_stained_glass:15)
B(5,6,14,betternether:quartz_stained_glass:15)
B(6,6,14,betternether:quartz_stained_glass:15)
B(7,6,14,betternether:quartz_stained_glass:15)
B(8,6,14,betternether:quartz_stained_glass:15)
B(9,6,14,betternether:quartz_stained_glass:15)
B(3,6,15,betternether:quartz_stained_glass:15)
B(4,6,15,betternether:quartz_stained_glass:15)
B(5,6,15,srparasites:parasiterubbledense:1)
B(6,6,15,srparasites:parasiterubbledense:1)
B(7,6,15,betternether:quartz_stained_glass:15)
B(8,6,15,betternether:quartz_stained_glass:15)
B(6,7,8,betternether:quartz_stained_glass:15)
B(8,7,8,betternether:quartz_stained_glass:15)
B(5,7,9,betternether:quartz_stained_glass:15)
B(6,7,9,betternether:quartz_stained_glass:15)
B(7,7,9,srparasites:parasiterubbledense:1)
B(8,7,9,betternether:quartz_stained_glass:15)
B(2,7,10,betternether:quartz_stained_glass:15)
B(3,7,10,betternether:quartz_stained_glass:15)
B(4,7,10,betternether:quartz_stained_glass:15)
B(5,7,10,betternether:quartz_stained_glass:15)
B(6,7,10,betternether:quartz_stained_glass:15)
B(7,7,10,betternether:quartz_stained_glass:15)
B(8,7,10,srparasites:parasiterubbledense:1)
B(3,7,11,betternether:quartz_stained_glass:15)
B(4,7,11,betternether:quartz_stained_glass:15)
RB(5,7,11,srparasites:parasitestain:1,80,quark:crystal:1,30,srparasites:parasiterubbledense:1,100)
RB(6,7,11,srparasites:parasitestain:1,80,quark:crystal:1,30,srparasites:parasiterubbledense:1,100)
B(7,7,11,srparasites:parasiterubbledense:1)
B(8,7,11,betternether:quartz_stained_glass:15)
B(9,7,11,betternether:quartz_stained_glass:15)
B(10,7,11,betternether:quartz_stained_glass:15)
B(3,7,12,betternether:quartz_stained_glass:15)
B(4,7,12,betternether:quartz_stained_glass:15)
B(5,7,12,betternether:quartz_stained_glass:15)
RB(6,7,12,srparasites:parasitestain:1,80,quark:crystal:1,30,srparasites:parasiterubbledense:1,100)
RB(7,7,12,srparasites:parasitestain:1,80,quark:crystal:1,30,srparasites:parasiterubbledense:1,100)
B(8,7,12,srparasites:parasiterubbledense:1)
B(9,7,12,betternether:quartz_stained_glass:15)
B(3,7,13,betternether:quartz_stained_glass:15)
B(4,7,13,srparasites:parasiterubbledense:1)
B(5,7,13,srparasites:parasiterubbledense:1)
B(6,7,13,betternether:quartz_stained_glass:15)
B(7,7,13,betternether:quartz_stained_glass:15)
B(8,7,13,betternether:quartz_stained_glass:15)
B(9,7,13,betternether:quartz_stained_glass:15)
B(3,7,14,betternether:quartz_stained_glass:15)
B(4,7,14,betternether:quartz_stained_glass:15)
B(5,7,14,srparasites:parasiterubbledense:1)
B(6,7,14,betternether:quartz_stained_glass:15)
B(7,7,14,betternether:quartz_stained_glass:15)
B(8,7,14,betternether:quartz_stained_glass:15)
B(4,7,15,betternether:quartz_stained_glass:15)
B(5,7,15,betternether:quartz_stained_glass:15)
B(6,7,15,betternether:quartz_stained_glass:15)
B(7,7,15,betternether:quartz_stained_glass:15)
B(8,7,15,betternether:quartz_stained_glass:15)
B(5,8,8,betternether:quartz_stained_glass:15)
B(6,8,8,srparasites:parasiterubbledense:1)
B(7,8,8,betternether:quartz_stained_glass:15)
B(8,8,8,betternether:quartz_stained_glass:15)
B(3,8,9,betternether:quartz_stained_glass:15)
B(4,8,9,betternether:quartz_stained_glass:15)
B(5,8,9,betternether:quartz_stained_glass:15)
B(6,8,9,betternether:quartz_stained_glass:15)
B(7,8,9,srparasites:parasiterubbledense:1)
B(8,8,9,betternether:quartz_stained_glass:15)
B(2,8,10,betternether:quartz_stained_glass:15)
B(3,8,10,betternether:quartz_stained_glass:15)
B(4,8,10,betternether:quartz_stained_glass:15)
B(5,8,10,betternether:quartz_stained_glass:15)
B(6,8,10,betternether:quartz_stained_glass:15)
B(7,8,10,srparasites:parasiterubbledense:1)
B(8,8,10,betternether:quartz_stained_glass:15)
B(9,8,10,betternether:quartz_stained_glass:15)
B(3,8,11,betternether:quartz_stained_glass:15)
B(4,8,11,betternether:quartz_stained_glass:15)
RB(5,8,11,srparasites:parasitestain:1,80,quark:crystal:1,30,srparasites:parasiterubbledense:1,100)
RB(6,8,11,srparasites:parasitestain:1,80,quark:crystal:1,30,srparasites:parasiterubbledense:1,100)
B(7,8,11,betternether:quartz_stained_glass:15)
B(8,8,11,betternether:quartz_stained_glass:15)
B(9,8,11,betternether:quartz_stained_glass:15)
B(10,8,11,betternether:quartz_stained_glass:15)
B(2,8,12,betternether:quartz_stained_glass:15)
B(3,8,12,betternether:quartz_stained_glass:15)
B(4,8,12,betternether:quartz_stained_glass:15)
B(5,8,12,srparasites:parasiterubbledense:1)
RB(6,8,12,srparasites:parasitestain:1,80,quark:crystal:1,30,srparasites:parasiterubbledense:1,100)
B(7,8,12,betternether:quartz_stained_glass:15)
B(8,8,12,betternether:quartz_stained_glass:15)
B(9,8,12,betternether:quartz_stained_glass:15)
B(3,8,13,betternether:quartz_stained_glass:15)
B(4,8,13,srparasites:parasiterubbledense:1)
B(5,8,13,srparasites:parasiterubbledense:1)
B(6,8,13,betternether:quartz_stained_glass:15)
B(7,8,13,betternether:quartz_stained_glass:15)
B(8,8,13,betternether:quartz_stained_glass:15)
B(9,8,13,betternether:quartz_stained_glass:15)
B(3,8,14,betternether:quartz_stained_glass:15)
B(4,8,14,betternether:quartz_stained_glass:15)
B(5,8,14,srparasites:parasiterubbledense:1)
B(6,8,14,betternether:quartz_stained_glass:15)
B(7,8,14,betternether:quartz_stained_glass:15)
B(6,9,7,betternether:quartz_stained_glass:15)
B(7,9,7,betternether:quartz_stained_glass:15)
B(3,9,8,betternether:quartz_stained_glass:15)
B(4,9,8,betternether:quartz_stained_glass:15)
B(5,9,8,betternether:quartz_stained_glass:15)
B(6,9,8,srparasites:parasiterubbledense:1)
B(7,9,8,srparasites:parasiterubbledense:1)
B(8,9,8,betternether:quartz_stained_glass:15)
B(2,9,9,betternether:quartz_stained_glass:15)
B(3,9,9,betternether:quartz_stained_glass:15)
B(4,9,9,betternether:quartz_stained_glass:15)
B(5,9,9,betternether:quartz_stained_glass:15)
RB(6,9,9,srparasites:parasitestain:1,80,quark:crystal:1,30,srparasites:parasiterubbledense:1,100)
B(7,9,9,srparasites:parasiterubbledense:1)
B(8,9,9,betternether:quartz_stained_glass:15)
B(2,9,10,betternether:quartz_stained_glass:15)
B(3,9,10,betternether:quartz_stained_glass:15)
RB(4,9,10,srparasites:parasitestain:1,80,quark:crystal:1,30,srparasites:parasiterubbledense:1,100)
RB(5,9,10,srparasites:parasitestain:1,80,quark:crystal:1,30,srparasites:parasiterubbledense:1,100)
RB(6,9,10,srparasites:parasitestain:1,80,quark:crystal:1,30,srparasites:parasiterubbledense:1,100)
B(7,9,10,betternether:quartz_stained_glass:15)
B(8,9,10,betternether:quartz_stained_glass:15)
B(9,9,10,betternether:quartz_stained_glass:15)
B(3,9,11,betternether:quartz_stained_glass:15)
B(4,9,11,betternether:quartz_stained_glass:15)
RB(5,9,11,srparasites:parasitestain:1,80,quark:crystal:1,30,srparasites:parasiterubbledense:1,100)
RB(6,9,11,srparasites:parasitestain:1,80,quark:crystal:1,30,srparasites:parasiterubbledense:1,100)
B(7,9,11,betternether:quartz_stained_glass:15)
B(8,9,11,betternether:quartz_stained_glass:15)
B(2,9,12,betternether:quartz_stained_glass:15)
B(3,9,12,betternether:quartz_stained_glass:15)
B(4,9,12,betternether:quartz_stained_glass:15)
B(5,9,12,betternether:quartz_stained_glass:15)
B(6,9,12,betternether:quartz_stained_glass:15)
B(7,9,12,betternether:quartz_stained_glass:15)
B(8,9,12,betternether:quartz_stained_glass:15)
B(9,9,12,betternether:quartz_stained_glass:15)
B(3,9,13,betternether:quartz_stained_glass:15)
B(4,9,13,srparasites:parasiterubbledense:1)
B(5,9,13,betternether:quartz_stained_glass:15)
B(6,9,13,betternether:quartz_stained_glass:15)
B(7,9,13,betternether:quartz_stained_glass:15)
B(8,9,13,betternether:quartz_stained_glass:15)
B(4,9,14,betternether:quartz_stained_glass:15)
B(5,9,14,betternether:quartz_stained_glass:15)
B(6,9,14,betternether:quartz_stained_glass:15)
B(6,10,6,betternether:quartz_stained_glass:15)
B(4,10,7,betternether:quartz_stained_glass:15)
B(5,10,7,betternether:quartz_stained_glass:15)
B(6,10,7,srparasites:parasiterubbledense:1)
B(7,10,7,betternether:quartz_stained_glass:15)
B(2,10,8,betternether:quartz_stained_glass:15)
B(3,10,8,betternether:quartz_stained_glass:15)
B(4,10,8,betternether:quartz_stained_glass:15)
B(5,10,8,betternether:quartz_stained_glass:15)
B(6,10,8,srparasites:parasiterubbledense:1)
B(7,10,8,srparasites:parasiterubbledense:1)
B(8,10,8,betternether:quartz_stained_glass:15)
B(2,10,9,betternether:quartz_stained_glass:15)
B(3,10,9,betternether:quartz_stained_glass:15)
B(4,10,9,betternether:quartz_stained_glass:15)
RB(5,10,9,srparasites:parasitestain:1,80,quark:crystal:1,30,srparasites:parasiterubbledense:1,100)
RB(6,10,9,srparasites:parasitestain:1,80,quark:crystal:1,30,srparasites:parasiterubbledense:1,100)
B(7,10,9,betternether:quartz_stained_glass:15)
B(8,10,9,betternether:quartz_stained_glass:15)
B(2,10,10,betternether:quartz_stained_glass:15)
B(3,10,10,betternether:quartz_stained_glass:15)
RB(4,10,10,srparasites:parasitestain:1,80,quark:crystal:1,30,srparasites:parasiterubbledense:1,100)
RB(5,10,10,srparasites:parasitestain:1,80,quark:crystal:1,30,srparasites:parasiterubbledense:1,100)
RB(6,10,10,srparasites:parasitestain:1,80,quark:crystal:1,30,srparasites:parasiterubbledense:1,100)
B(7,10,10,betternether:quartz_stained_glass:15)
B(8,10,10,betternether:quartz_stained_glass:15)
B(9,10,10,betternether:quartz_stained_glass:15)
B(2,10,11,betternether:quartz_stained_glass:15)
B(3,10,11,betternether:quartz_stained_glass:15)
B(4,10,11,betternether:quartz_stained_glass:15)
B(5,10,11,betternether:quartz_stained_glass:15)
B(6,10,11,betternether:quartz_stained_glass:15)
B(7,10,11,betternether:quartz_stained_glass:15)
B(8,10,11,betternether:quartz_stained_glass:15)
B(2,10,12,betternether:quartz_stained_glass:15)
B(3,10,12,srparasites:parasiterubbledense:1)
B(4,10,12,srparasites:parasiterubbledense:1)
B(5,10,12,srparasites:parasiterubbledense:1)
B(6,10,12,betternether:quartz_stained_glass:15)
B(7,10,12,betternether:quartz_stained_glass:15)
B(8,10,12,betternether:quartz_stained_glass:15)
B(3,10,13,betternether:quartz_stained_glass:15)
B(4,10,13,betternether:quartz_stained_glass:15)
B(6,10,13,betternether:quartz_stained_glass:15)
B(4,11,6,betternether:quartz_stained_glass:15)
B(5,11,6,betternether:quartz_stained_glass:15)
B(6,11,6,srparasites:parasiterubbledense:1)
B(1,11,7,betternether:quartz_stained_glass:15)
B(3,11,7,betternether:quartz_stained_glass:15)
B(4,11,7,betternether:quartz_stained_glass:15)
B(5,11,7,betternether:quartz_stained_glass:15)
B(6,11,7,srparasites:parasiterubbledense:1)
B(7,11,7,betternether:quartz_stained_glass:15)
B(2,11,8,betternether:quartz_stained_glass:15)
B(3,11,8,betternether:quartz_stained_glass:15)
B(4,11,8,betternether:quartz_stained_glass:15)
RB(5,11,8,srparasites:parasitestain:1,80,quark:crystal:1,30,srparasites:parasiterubbledense:1,100)
B(6,11,8,betternether:quartz_stained_glass:15)
B(7,11,8,srparasites:parasiterubbledense:1)
B(8,11,8,betternether:quartz_stained_glass:15)
B(2,11,9,betternether:quartz_stained_glass:15)
B(3,11,9,betternether:quartz_stained_glass:15)
RB(4,11,9,srparasites:parasitestain:1,80,quark:crystal:1,30,srparasites:parasiterubbledense:1,100)
RB(5,11,9,srparasites:parasitestain:1,80,quark:crystal:1,30,srparasites:parasiterubbledense:1,100)
RB(6,11,9,srparasites:parasitestain:1,80,quark:crystal:1,30,srparasites:parasiterubbledense:1,100)
B(7,11,9,betternether:quartz_stained_glass:15)
B(8,11,9,betternether:quartz_stained_glass:15)
B(2,11,10,betternether:quartz_stained_glass:15)
B(3,11,10,betternether:quartz_stained_glass:15)
RB(4,11,10,srparasites:parasitestain:1,80,quark:crystal:1,30,srparasites:parasiterubbledense:1,100)
RB(5,11,10,srparasites:parasitestain:1,80,quark:crystal:1,30,srparasites:parasiterubbledense:1,100)
RB(6,11,10,srparasites:parasitestain:1,80,quark:crystal:1,30,srparasites:parasiterubbledense:1,100)
B(7,11,10,betternether:quartz_stained_glass:15)
B(8,11,10,betternether:quartz_stained_glass:15)
B(2,11,11,betternether:quartz_stained_glass:15)
B(3,11,11,betternether:quartz_stained_glass:15)
B(4,11,11,srparasites:parasiterubbledense:1)
B(5,11,11,betternether:quartz_stained_glass:15)
B(6,11,11,betternether:quartz_stained_glass:15)
B(7,11,11,betternether:quartz_stained_glass:15)
B(8,11,11,betternether:quartz_stained_glass:15)
B(3,11,12,srparasites:parasiterubbledense:1)
B(4,11,12,srparasites:parasiterubbledense:1)
B(5,11,12,betternether:quartz_stained_glass:15)
B(6,11,12,betternether:quartz_stained_glass:15)
B(7,11,12,betternether:quartz_stained_glass:15)
B(3,11,13,betternether:quartz_stained_glass:15)
B(6,12,5,betternether:quartz_stained_glass:15)
B(3,12,6,betternether:quartz_stained_glass:15)
B(4,12,6,betternether:quartz_stained_glass:15)
B(5,12,6,srparasites:parasiterubbledense:1)
B(6,12,6,betternether:quartz_stained_glass:15)
B(1,12,7,betternether:quartz_stained_glass:15)
B(2,12,7,betternether:quartz_stained_glass:15)
B(3,12,7,betternether:quartz_stained_glass:15)
B(4,12,7,betternether:quartz_stained_glass:15)
B(5,12,7,betternether:quartz_stained_glass:15)
B(6,12,7,betternether:quartz_stained_glass:15)
B(7,12,7,betternether:quartz_stained_glass:15)
B(8,12,7,betternether:quartz_stained_glass:15)
B(2,12,8,betternether:quartz_stained_glass:15)
B(3,12,8,betternether:quartz_stained_glass:15)
RB(4,12,8,srparasites:parasitestain:1,80,quark:crystal:1,30,srparasites:parasiterubbledense:1,100)
RB(5,12,8,srparasites:parasitestain:1,80,quark:crystal:1,30,srparasites:parasiterubbledense:1,100)
B(6,12,8,betternether:quartz_stained_glass:15)
B(7,12,8,betternether:quartz_stained_glass:15)
B(8,12,8,betternether:quartz_stained_glass:15)
B(2,12,9,betternether:quartz_stained_glass:15)
B(3,12,9,betternether:quartz_stained_glass:15)
RB(4,12,9,srparasites:parasitestain:1,80,quark:crystal:1,30,srparasites:parasiterubbledense:1,100)
RB(5,12,9,srparasites:parasitestain:1,80,quark:crystal:1,30,srparasites:parasiterubbledense:1,100)
B(6,12,9,betternether:quartz_stained_glass:15)
B(7,12,9,betternether:quartz_stained_glass:15)
B(8,12,9,betternether:quartz_stained_glass:15)
B(2,12,10,betternether:quartz_stained_glass:15)
B(3,12,10,srparasites:parasiterubbledense:1)
B(4,12,10,srparasites:parasiterubbledense:1)
B(5,12,10,srparasites:parasiterubbledense:1)
B(6,12,10,betternether:quartz_stained_glass:15)
B(7,12,10,betternether:quartz_stained_glass:15)
B(8,12,10,betternether:quartz_stained_glass:15)
B(2,12,11,betternether:quartz_stained_glass:15)
B(3,12,11,betternether:quartz_stained_glass:15)
B(4,12,11,srparasites:parasiterubbledense:1)
B(5,12,11,betternether:quartz_stained_glass:15)
B(6,12,11,betternether:quartz_stained_glass:15)
B(3,12,12,betternether:quartz_stained_glass:15)
B(4,12,12,betternether:quartz_stained_glass:15)
B(6,12,12,betternether:quartz_stained_glass:15)
B(6,13,4,betternether:quartz_stained_glass:15)
B(2,13,5,betternether:quartz_stained_glass:15)
B(3,13,5,betternether:quartz_stained_glass:15)
B(4,13,5,betternether:quartz_stained_glass:15)
B(5,13,5,betternether:quartz_stained_glass:15)
B(6,13,5,srparasites:parasiterubbledense:1)
B(1,13,6,betternether:quartz_stained_glass:15)
B(2,13,6,betternether:quartz_stained_glass:15)
B(3,13,6,betternether:quartz_stained_glass:15)
B(4,13,6,srparasites:parasiterubbledense:1)
B(5,13,6,srparasites:parasiterubbledense:1)
B(6,13,6,betternether:quartz_stained_glass:15)
B(1,13,7,betternether:quartz_stained_glass:15)
B(2,13,7,betternether:quartz_stained_glass:15)
B(3,13,7,betternether:quartz_stained_glass:15)
RB(4,13,7,srparasites:parasitestain:1,80,quark:crystal:1,30,srparasites:parasiterubbledense:1,100)
RB(5,13,7,srparasites:parasitestain:1,80,quark:crystal:1,30,srparasites:parasiterubbledense:1,100)
B(6,13,7,betternether:quartz_stained_glass:15)
B(7,13,7,betternether:quartz_stained_glass:15)
B(8,13,7,betternether:quartz_stained_glass:15)
B(2,13,8,betternether:quartz_stained_glass:15)
B(3,13,8,betternether:quartz_stained_glass:15)
RB(4,13,8,srparasites:parasitestain:1,80,quark:crystal:1,30,srparasites:parasiterubbledense:1,100)
RB(5,13,8,srparasites:parasitestain:1,80,quark:crystal:1,30,srparasites:parasiterubbledense:1,100)
B(6,13,8,betternether:quartz_stained_glass:15)
B(7,13,8,betternether:quartz_stained_glass:15)
B(8,13,8,betternether:quartz_stained_glass:15)
B(2,13,9,betternether:quartz_stained_glass:15)
B(3,13,9,betternether:quartz_stained_glass:15)
RB(4,13,9,srparasites:parasitestain:1,80,quark:crystal:1,30,srparasites:parasiterubbledense:1,100)
B(5,13,9,srparasites:parasiterubbledense:1)
B(6,13,9,betternether:quartz_stained_glass:15)
B(7,13,9,betternether:quartz_stained_glass:15)
B(8,13,9,betternether:quartz_stained_glass:15)
B(2,13,10,betternether:quartz_stained_glass:15)
B(3,13,10,srparasites:parasiterubbledense:1)
B(4,13,10,srparasites:parasiterubbledense:1)
B(5,13,10,srparasites:parasiterubbledense:1)
B(6,13,10,betternether:quartz_stained_glass:15)
B(7,13,10,betternether:quartz_stained_glass:15)
B(3,13,11,betternether:quartz_stained_glass:15)
B(4,13,11,betternether:quartz_stained_glass:15)
B(5,13,11,betternether:quartz_stained_glass:15)
B(6,13,11,betternether:quartz_stained_glass:15)
B(4,14,4,betternether:quartz_stained_glass:15)
B(5,14,4,betternether:quartz_stained_glass:15)
B(6,14,4,betternether:quartz_stained_glass:15)
B(1,14,5,betternether:quartz_stained_glass:15)
B(2,14,5,betternether:quartz_stained_glass:15)
B(3,14,5,srparasites:parasiterubbledense:1)
B(4,14,5,srparasites:parasiterubbledense:1)
B(5,14,5,srparasites:parasiterubbledense:1)
B(6,14,5,srparasites:parasiterubbledense:1)
B(1,14,6,betternether:quartz_stained_glass:15)
B(2,14,6,betternether:quartz_stained_glass:15)
B(3,14,6,betternether:quartz_stained_glass:15)
RB(4,14,6,srparasites:parasitestain:1,80,quark:crystal:1,30,srparasites:parasiterubbledense:1,100)
B(5,14,6,srparasites:parasiterubbledense:1)
B(6,14,6,betternether:quartz_stained_glass:15)
B(7,14,6,betternether:quartz_stained_glass:15)
B(1,14,7,betternether:quartz_stained_glass:15)
B(2,14,7,betternether:quartz_stained_glass:15)
B(3,14,7,betternether:quartz_stained_glass:15)
RB(4,14,7,srparasites:parasitestain:1,80,quark:crystal:1,30,srparasites:parasiterubbledense:1,100)
RB(5,14,7,srparasites:parasitestain:1,80,quark:crystal:1,30,srparasites:parasiterubbledense:1,100)
B(6,14,7,betternether:quartz_stained_glass:15)
B(7,14,7,betternether:quartz_stained_glass:15)
B(8,14,7,betternether:quartz_stained_glass:15)
B(1,14,8,betternether:quartz_stained_glass:15)
B(2,14,8,betternether:quartz_stained_glass:15)
B(3,14,8,betternether:quartz_stained_glass:15)
RB(4,14,8,srparasites:parasitestain:1,80,quark:crystal:1,30,srparasites:parasiterubbledense:1,100)
B(5,14,8,betternether:quartz_stained_glass:15)
B(6,14,8,betternether:quartz_stained_glass:15)
B(7,14,8,betternether:quartz_stained_glass:15)
B(8,14,8,betternether:quartz_stained_glass:15)
B(2,14,9,betternether:quartz_stained_glass:15)
B(3,14,9,betternether:quartz_stained_glass:15)
B(4,14,9,betternether:quartz_stained_glass:15)
B(5,14,9,srparasites:parasiterubbledense:1)
B(6,14,9,betternether:quartz_stained_glass:15)
B(7,14,9,betternether:quartz_stained_glass:15)
B(2,14,10,betternether:quartz_stained_glass:15)
B(3,14,10,betternether:quartz_stained_glass:15)
B(4,14,10,betternether:quartz_stained_glass:15)
B(5,14,10,betternether:quartz_stained_glass:15)
B(6,14,10,betternether:quartz_stained_glass:15)
B(4,15,3,betternether:quartz_stained_glass:15)
B(5,15,3,betternether:quartz_stained_glass:15)
B(6,15,3,betternether:quartz_stained_glass:15)
B(2,15,4,betternether:quartz_stained_glass:15)
B(3,15,4,betternether:quartz_stained_glass:15)
B(4,15,4,betternether:quartz_stained_glass:15)
B(5,15,4,betternether:quartz_stained_glass:15)
B(6,15,4,betternether:quartz_stained_glass:15)
B(0,15,5,betternether:quartz_stained_glass:15)
B(1,15,5,betternether:quartz_stained_glass:15)
B(2,15,5,betternether:quartz_stained_glass:15)
B(3,15,5,betternether:quartz_stained_glass:15)
B(4,15,5,betternether:quartz_stained_glass:15)
B(5,15,5,srparasites:parasiterubbledense:1)
B(6,15,5,betternether:quartz_stained_glass:15)
B(1,15,6,betternether:quartz_stained_glass:15)
B(2,15,6,betternether:quartz_stained_glass:15)
RB(3,15,6,srparasites:parasitestain:1,80,quark:crystal:1,30,srparasites:parasiterubbledense:1,100)
RB(4,15,6,srparasites:parasitestain:1,80,quark:crystal:1,30,srparasites:parasiterubbledense:1,100)
B(5,15,6,betternether:quartz_stained_glass:15)
B(6,15,6,betternether:quartz_stained_glass:15)
B(7,15,6,betternether:quartz_stained_glass:15)
B(1,15,7,betternether:quartz_stained_glass:15)
B(2,15,7,betternether:quartz_stained_glass:15)
B(3,15,7,betternether:quartz_stained_glass:15)
RB(4,15,7,srparasites:parasitestain:1,80,quark:crystal:1,30,srparasites:parasiterubbledense:1,100)
RB(5,15,7,srparasites:parasitestain:1,80,quark:crystal:1,30,srparasites:parasiterubbledense:1,100)
B(6,15,7,betternether:quartz_stained_glass:15)
B(7,15,7,betternether:quartz_stained_glass:15)
B(1,15,8,betternether:quartz_stained_glass:15)
B(2,15,8,betternether:quartz_stained_glass:15)
B(3,15,8,betternether:quartz_stained_glass:15)
B(4,15,8,srparasites:parasiterubbledense:1)
B(5,15,8,srparasites:parasiterubbledense:1)
B(6,15,8,betternether:quartz_stained_glass:15)
B(7,15,8,betternether:quartz_stained_glass:15)
B(8,15,8,betternether:quartz_stained_glass:15)
B(2,15,9,betternether:quartz_stained_glass:15)
B(3,15,9,betternether:quartz_stained_glass:15)
B(4,15,9,srparasites:parasiterubbledense:1)
B(5,15,9,betternether:quartz_stained_glass:15)
B(6,15,9,betternether:quartz_stained_glass:15)
B(2,15,10,betternether:quartz_stained_glass:15)
B(4,15,10,betternether:quartz_stained_glass:15)
B(5,15,10,betternether:quartz_stained_glass:15)
B(6,15,10,betternether:quartz_stained_glass:15)
B(5,16,2,betternether:quartz_stained_glass:15)
B(2,16,3,betternether:quartz_stained_glass:15)
B(3,16,3,betternether:quartz_stained_glass:15)
B(4,16,3,betternether:quartz_stained_glass:15)
B(5,16,3,betternether:quartz_stained_glass:15)
B(6,16,3,betternether:quartz_stained_glass:15)
B(1,16,4,betternether:quartz_stained_glass:15)
B(2,16,4,betternether:quartz_stained_glass:15)
B(3,16,4,betternether:quartz_stained_glass:15)
B(4,16,4,betternether:quartz_stained_glass:15)
B(5,16,4,betternether:quartz_stained_glass:15)
B(6,16,4,betternether:quartz_stained_glass:15)
B(7,16,4,betternether:quartz_stained_glass:15)
B(0,16,5,betternether:quartz_stained_glass:15)
B(1,16,5,betternether:quartz_stained_glass:15)
B(2,16,5,betternether:quartz_stained_glass:15)
RB(3,16,5,srparasites:parasitestain:1,80,quark:crystal:1,30,srparasites:parasiterubbledense:1,100)
RB(4,16,5,srparasites:parasitestain:1,80,quark:crystal:1,30,srparasites:parasiterubbledense:1,100)
B(5,16,5,betternether:quartz_stained_glass:15)
B(6,16,5,betternether:quartz_stained_glass:15)
B(7,16,5,betternether:quartz_stained_glass:15)
B(1,16,6,betternether:quartz_stained_glass:15)
B(2,16,6,betternether:quartz_stained_glass:15)
RB(3,16,6,srparasites:parasitestain:1,80,quark:crystal:1,30,srparasites:parasiterubbledense:1,100)
RB(4,16,6,srparasites:parasitestain:1,80,quark:crystal:1,30,srparasites:parasiterubbledense:1,100)
B(5,16,6,betternether:quartz_stained_glass:15)
B(6,16,6,betternether:quartz_stained_glass:15)
B(7,16,6,betternether:quartz_stained_glass:15)
B(0,16,7,betternether:quartz_stained_glass:15)
B(1,16,7,betternether:quartz_stained_glass:15)
B(2,16,7,betternether:quartz_stained_glass:15)
B(3,16,7,betternether:quartz_stained_glass:15)
B(4,16,7,betternether:quartz_stained_glass:15)
B(5,16,7,srparasites:parasiterubbledense:1)
B(6,16,7,srparasites:parasiterubbledense:1)
B(7,16,7,betternether:quartz_stained_glass:15)
B(1,16,8,betternether:quartz_stained_glass:15)
B(2,16,8,betternether:quartz_stained_glass:15)
B(3,16,8,srparasites:parasiterubbledense:1)
B(4,16,8,srparasites:parasiterubbledense:1)
B(5,16,8,betternether:quartz_stained_glass:15)
B(7,16,8,betternether:quartz_stained_glass:15)
B(2,16,9,betternether:quartz_stained_glass:15)
B(3,16,9,betternether:quartz_stained_glass:15)
B(4,16,9,betternether:quartz_stained_glass:15)
B(5,16,9,betternether:quartz_stained_glass:15)
B(5,17,1,betternether:quartz_stained_glass:15)
B(4,17,2,betternether:quartz_stained_glass:15)
B(5,17,2,betternether:quartz_stained_glass:15)
B(0,17,3,betternether:quartz_stained_glass:15)
B(1,17,3,betternether:quartz_stained_glass:15)
B(2,17,3,betternether:quartz_stained_glass:15)
B(3,17,3,betternether:quartz_stained_glass:15)
B(4,17,3,betternether:quartz_stained_glass:15)
B(5,17,3,betternether:quartz_stained_glass:15)
B(6,17,3,betternether:quartz_stained_glass:15)
B(1,17,4,betternether:quartz_stained_glass:15)
B(2,17,4,betternether:quartz_stained_glass:15)
B(3,17,4,betternether:quartz_stained_glass:15)
RB(4,17,4,srparasites:parasitestain:1,80,quark:crystal:1,30,srparasites:parasiterubbledense:1,100)
B(5,17,4,betternether:quartz_stained_glass:15)
B(6,17,4,betternether:quartz_stained_glass:15)
B(7,17,4,betternether:quartz_stained_glass:15)
B(0,17,5,betternether:quartz_stained_glass:15)
B(1,17,5,betternether:quartz_stained_glass:15)
B(2,17,5,betternether:quartz_stained_glass:15)
RB(3,17,5,srparasites:parasitestain:1,80,quark:crystal:1,30,srparasites:parasiterubbledense:1,100)
RB(4,17,5,srparasites:parasitestain:1,80,quark:crystal:1,30,srparasites:parasiterubbledense:1,100)
B(5,17,5,betternether:quartz_stained_glass:15)
B(6,17,5,betternether:quartz_stained_glass:15)
B(7,17,5,betternether:quartz_stained_glass:15)
B(1,17,6,betternether:quartz_stained_glass:15)
B(2,17,6,betternether:quartz_stained_glass:15)
RB(3,17,6,srparasites:parasitestain:1,80,quark:crystal:1,30,srparasites:parasiterubbledense:1,100)
B(4,17,6,betternether:quartz_stained_glass:15)
B(5,17,6,betternether:quartz_stained_glass:15)
B(6,17,6,srparasites:parasiterubbledense:1)
B(0,17,7,betternether:quartz_stained_glass:15)
B(1,17,7,betternether:quartz_stained_glass:15)
B(2,17,7,betternether:quartz_stained_glass:15)
B(3,17,7,betternether:quartz_stained_glass:15)
B(4,17,7,srparasites:parasiterubbledense:1)
B(5,17,7,srparasites:parasiterubbledense:1)
B(6,17,7,betternether:quartz_stained_glass:15)
B(7,17,7,betternether:quartz_stained_glass:15)
B(2,17,8,betternether:quartz_stained_glass:15)
B(3,17,8,betternether:quartz_stained_glass:15)
B(4,17,8,betternether:quartz_stained_glass:15)
B(5,17,8,betternether:quartz_stained_glass:15)
B(2,17,9,betternether:quartz_stained_glass:15)
B(4,17,9,betternether:quartz_stained_glass:15)
B(3,18,1,betternether:quartz_stained_glass:15)
B(4,18,1,betternether:quartz_stained_glass:15)
B(5,18,1,betternether:quartz_stained_glass:15)
B(0,18,2,betternether:quartz_stained_glass:15)
B(2,18,2,betternether:quartz_stained_glass:15)
B(3,18,2,betternether:quartz_stained_glass:15)
B(4,18,2,betternether:quartz_stained_glass:15)
B(5,18,2,betternether:quartz_stained_glass:15)
B(0,18,3,betternether:quartz_stained_glass:15)
B(1,18,3,betternether:quartz_stained_glass:15)
B(2,18,3,betternether:quartz_stained_glass:15)
B(3,18,3,betternether:quartz_stained_glass:15)
B(4,18,3,betternether:quartz_stained_glass:15)
B(5,18,3,betternether:quartz_stained_glass:15)
B(6,18,3,betternether:quartz_stained_glass:15)
B(7,18,3,betternether:quartz_stained_glass:15)
B(1,18,4,betternether:quartz_stained_glass:15)
B(2,18,4,betternether:quartz_stained_glass:15)
RB(3,18,4,srparasites:parasitestain:1,80,quark:crystal:1,30,srparasites:parasiterubbledense:1,100)
RB(4,18,4,srparasites:parasitestain:1,80,quark:crystal:1,30,srparasites:parasiterubbledense:1,100)
B(5,18,4,betternether:quartz_stained_glass:15)
B(6,18,4,betternether:quartz_stained_glass:15)
B(7,18,4,betternether:quartz_stained_glass:15)
B(0,18,5,betternether:quartz_stained_glass:15)
B(1,18,5,betternether:quartz_stained_glass:15)
B(2,18,5,betternether:quartz_stained_glass:15)
RB(3,18,5,srparasites:parasitestain:1,80,quark:crystal:1,30,srparasites:parasiterubbledense:1,100)
RB(4,18,5,srparasites:parasitestain:1,80,quark:crystal:1,30,srparasites:parasiterubbledense:1,100)
B(5,18,5,betternether:quartz_stained_glass:15)
B(6,18,5,betternether:quartz_stained_glass:15)
B(7,18,5,betternether:quartz_stained_glass:15)
B(0,18,6,betternether:quartz_stained_glass:15)
B(1,18,6,betternether:quartz_stained_glass:15)
B(2,18,6,betternether:quartz_stained_glass:15)
B(3,18,6,betternether:quartz_stained_glass:15)
B(4,18,6,betternether:quartz_stained_glass:15)
B(5,18,6,betternether:quartz_stained_glass:15)
B(6,18,6,betternether:quartz_stained_glass:15)
B(0,18,7,betternether:quartz_stained_glass:15)
B(1,18,7,betternether:quartz_stained_glass:15)
B(2,18,7,betternether:quartz_stained_glass:15)
B(3,18,7,betternether:quartz_stained_glass:15)
B(4,18,7,betternether:quartz_stained_glass:15)
B(5,18,7,betternether:quartz_stained_glass:15)
B(2,18,8,betternether:quartz_stained_glass:15)
B(4,18,8,betternether:quartz_stained_glass:15)
B(3,19,1,betternether:quartz_stained_glass:15)
B(4,19,1,betternether:quartz_stained_glass:15)
B(5,19,1,betternether:quartz_stained_glass:15)
B(0,19,2,betternether:quartz_stained_glass:15)
B(2,19,2,betternether:quartz_stained_glass:15)
B(3,19,2,betternether:quartz_stained_glass:15)
B(4,19,2,betternether:quartz_stained_glass:15)
B(5,19,2,betternether:quartz_stained_glass:15)
B(0,19,3,betternether:quartz_stained_glass:15)
B(1,19,3,betternether:quartz_stained_glass:15)
RB(2,19,3,srparasites:parasitestain:1,80,quark:crystal:1,30,srparasites:parasiterubbledense:1,100)
RB(3,19,3,srparasites:parasitestain:1,80,quark:crystal:1,30,srparasites:parasiterubbledense:1,100)
B(4,19,3,betternether:quartz_stained_glass:15)
B(5,19,3,betternether:quartz_stained_glass:15)
B(6,19,3,betternether:quartz_stained_glass:15)
B(7,19,3,betternether:quartz_stained_glass:15)
B(1,19,4,betternether:quartz_stained_glass:15)
B(2,19,4,betternether:quartz_stained_glass:15)
RB(3,19,4,srparasites:parasitestain:1,80,quark:crystal:1,30,srparasites:parasiterubbledense:1,100)
RB(4,19,4,srparasites:parasitestain:1,80,quark:crystal:1,30,srparasites:parasiterubbledense:1,100)
B(5,19,4,betternether:quartz_stained_glass:15)
B(6,19,4,betternether:quartz_stained_glass:15)
B(0,19,5,betternether:quartz_stained_glass:15)
B(1,19,5,betternether:quartz_stained_glass:15)
B(2,19,5,betternether:quartz_stained_glass:15)
B(3,19,5,betternether:quartz_stained_glass:15)
B(4,19,5,betternether:quartz_stained_glass:15)
B(5,19,5,srparasites:parasiterubbledense:1)
B(6,19,5,betternether:quartz_stained_glass:15)
B(0,19,6,betternether:quartz_stained_glass:15)
B(1,19,6,betternether:quartz_stained_glass:15)
B(2,19,6,betternether:quartz_stained_glass:15)
B(3,19,6,betternether:quartz_stained_glass:15)
B(4,19,6,betternether:quartz_stained_glass:15)
B(5,19,6,betternether:quartz_stained_glass:15)
B(1,19,7,betternether:quartz_stained_glass:15)
B(2,19,7,betternether:quartz_stained_glass:15)
B(3,19,7,betternether:quartz_stained_glass:15)
B(4,19,7,betternether:quartz_stained_glass:15)
B(5,19,7,betternether:quartz_stained_glass:15)
B(2,20,1,betternether:quartz_stained_glass:15)
B(3,20,1,betternether:quartz_stained_glass:15)
B(4,20,1,betternether:quartz_stained_glass:15)
B(5,20,1,betternether:quartz_stained_glass:15)
B(0,20,2,betternether:quartz_stained_glass:15)
B(1,20,2,betternether:quartz_stained_glass:15)
B(2,20,2,betternether:quartz_stained_glass:15)
B(3,20,2,betternether:quartz_stained_glass:15)
B(4,20,2,betternether:quartz_stained_glass:15)
B(5,20,2,betternether:quartz_stained_glass:15)
B(0,20,3,betternether:quartz_stained_glass:15)
B(1,20,3,betternether:quartz_stained_glass:15)
RB(2,20,3,srparasites:parasitestain:1,80,quark:crystal:1,30,srparasites:parasiterubbledense:1,100)
RB(3,20,3,srparasites:parasitestain:1,80,quark:crystal:1,30,srparasites:parasiterubbledense:1,100)
B(4,20,3,srparasites:parasiterubbledense:1)
B(5,20,3,betternether:quartz_stained_glass:15)
B(6,20,3,betternether:quartz_stained_glass:15)
B(1,20,4,betternether:quartz_stained_glass:15)
B(2,20,4,betternether:quartz_stained_glass:15)
RB(3,20,4,srparasites:parasitestain:1,80,quark:crystal:1,30,srparasites:parasiterubbledense:1,100)
B(4,20,4,srparasites:parasiterubbledense:1)
B(5,20,4,srparasites:parasiterubbledense:1)
B(6,20,4,betternether:quartz_stained_glass:15)
B(0,20,5,betternether:quartz_stained_glass:15)
B(1,20,5,betternether:quartz_stained_glass:15)
B(2,20,5,betternether:quartz_stained_glass:15)
B(3,20,5,srparasites:parasiterubbledense:1)
B(4,20,5,srparasites:parasiterubbledense:1)
B(5,20,5,srparasites:parasiterubbledense:1)
B(6,20,5,betternether:quartz_stained_glass:15)
B(1,20,6,betternether:quartz_stained_glass:15)
B(2,20,6,betternether:quartz_stained_glass:15)
B(3,20,6,betternether:quartz_stained_glass:15)
B(4,20,6,betternether:quartz_stained_glass:15)
B(2,20,7,betternether:quartz_stained_glass:15)
B(2,21,1,betternether:quartz_stained_glass:15)
B(3,21,1,betternether:quartz_stained_glass:15)
B(4,21,1,betternether:quartz_stained_glass:15)
B(0,21,2,betternether:quartz_stained_glass:15)
B(1,21,2,betternether:quartz_stained_glass:15)
B(2,21,2,betternether:quartz_stained_glass:15)
B(3,21,2,betternether:quartz_stained_glass:15)
B(4,21,2,betternether:quartz_stained_glass:15)
B(5,21,2,betternether:quartz_stained_glass:15)
B(1,21,3,betternether:quartz_stained_glass:15)
B(2,21,3,betternether:quartz_stained_glass:15)
B(3,21,3,betternether:quartz_stained_glass:15)
B(4,21,3,srparasites:parasiterubbledense:1)
B(1,21,4,betternether:quartz_stained_glass:15)
B(2,21,4,betternether:quartz_stained_glass:15)
B(3,21,4,srparasites:parasiterubbledense:1)
B(4,21,4,srparasites:parasiterubbledense:1)
B(5,21,4,betternether:quartz_stained_glass:15)
B(1,21,5,betternether:quartz_stained_glass:15)
B(2,21,5,betternether:quartz_stained_glass:15)
B(3,21,5,betternether:quartz_stained_glass:15)
B(4,21,5,betternether:quartz_stained_glass:15)
B(5,21,5,betternether:quartz_stained_glass:15)
B(2,21,6,betternether:quartz_stained_glass:15)
B(3,21,6,betternether:quartz_stained_glass:15)
B(2,22,0,betternether:quartz_stained_glass:15)
B(3,22,0,betternether:quartz_stained_glass:15)
B(1,22,1,betternether:quartz_stained_glass:15)
B(2,22,1,betternether:quartz_stained_glass:15)
B(3,22,1,betternether:quartz_stained_glass:15)
B(4,22,1,betternether:quartz_stained_glass:15)
B(0,22,2,betternether:quartz_stained_glass:15)
B(1,22,2,betternether:quartz_stained_glass:15)
B(2,22,2,betternether:quartz_stained_glass:15)
B(3,22,2,betternether:quartz_stained_glass:15)
B(4,22,2,betternether:quartz_stained_glass:15)
B(5,22,2,betternether:quartz_stained_glass:15)
B(1,22,3,betternether:quartz_stained_glass:15)
B(2,22,3,betternether:quartz_stained_glass:15)
RB(3,22,3,srparasites:parasitestain:1,80,quark:crystal:1,30,srparasites:parasiterubbledense:1,100)
B(4,22,3,betternether:quartz_stained_glass:15)
B(1,22,4,betternether:quartz_stained_glass:15)
B(2,22,4,betternether:quartz_stained_glass:15)
B(3,22,4,betternether:quartz_stained_glass:15)
B(4,22,4,betternether:quartz_stained_glass:15)
B(3,22,5,betternether:quartz_stained_glass:15)
B(4,22,5,betternether:quartz_stained_glass:15)
B(2,23,0,betternether:quartz_stained_glass:15)
B(3,23,0,betternether:quartz_stained_glass:15)
B(1,23,1,betternether:quartz_stained_glass:15)
B(2,23,1,betternether:quartz_stained_glass:15)
B(3,23,1,betternether:quartz_stained_glass:15)
B(1,23,2,betternether:quartz_stained_glass:15)
B(2,23,2,betternether:quartz_stained_glass:15)
B(3,23,2,betternether:quartz_stained_glass:15)
B(4,23,2,betternether:quartz_stained_glass:15)
B(1,23,3,betternether:quartz_stained_glass:15)
B(2,23,3,betternether:quartz_stained_glass:15)
B(3,23,3,betternether:quartz_stained_glass:15)
B(3,23,4,betternether:quartz_stained_glass:15)
B(4,23,4,betternether:quartz_stained_glass:15)
B(2,24,0,betternether:quartz_stained_glass:15)
B(3,24,0,betternether:quartz_stained_glass:15)
B(1,24,1,betternether:quartz_stained_glass:15)
B(2,24,1,betternether:quartz_stained_glass:15)
B(3,24,1,betternether:quartz_stained_glass:15)
B(1,24,2,betternether:quartz_stained_glass:15)
B(2,24,2,betternether:quartz_stained_glass:15)
B(3,24,2,betternether:quartz_stained_glass:15)
B(2,24,3,betternether:quartz_stained_glass:15)
B(3,24,3,betternether:quartz_stained_glass:15)
B(1,25,0,betternether:quartz_stained_glass:15)
B(2,25,0,betternether:quartz_stained_glass:15)
B(3,25,0,betternether:quartz_stained_glass:15)
B(1,25,1,betternether:quartz_stained_glass:15)
B(2,25,1,betternether:quartz_stained_glass:15)
B(3,25,1,betternether:quartz_stained_glass:15)
B(2,25,2,betternether:quartz_stained_glass:15)
B(3,25,2,betternether:quartz_stained_glass:15)
B(1,26,0,betternether:quartz_stained_glass:15)
B(2,26,0,betternether:quartz_stained_glass:15)
B(3,26,0,betternether:quartz_stained_glass:15)
B(1,26,1,betternether:quartz_stained_glass:15)
B(1,27,0,betternether:quartz_stained_glass:15)

