
#######################################################################
# +-----------------------------------------------------------------+ #
# |                            BO3 object                           | #
# +-----------------------------------------------------------------+ #
#######################################################################

Author: NLBlackHeavenNL

Description: No description given

Version: 3

SettingsMode: WriteWithoutComments


#######################################################################
# +-----------------------------------------------------------------+ #
# |                          Main settings                          | #
# +-----------------------------------------------------------------+ #
#######################################################################

Tree: true

Frequency: 1

Rarity: 100.0

RotateRandomly: false

SpawnHeight: highestSolidBlock

SpawnHeightOffset: -1

SpawnHeightVariance: 0

##############################
# Height Limits for the BO3. #
##############################

MinHeight: 0

MaxHeight: 255

######################
# Extrusion settings #
######################

ExtrudeMode: None

ExtrudeThroughBlocks: AIR

MaxBranchDepth: 10

ExcludedBiomes: All


#######################################################################
# +-----------------------------------------------------------------+ #
# |                      Source block settings                      | #
# +-----------------------------------------------------------------+ #
#######################################################################

SourceBlocks: AIR,GRASS,DIRT,biomesoplenty:dirt

MaxPercentageOutsideSourceBlock: 0

OutsideSourceBlock: placeAnyway

DoReplaceBlocks: true

IsOTGPlus: false


#######################################################################
# +-----------------------------------------------------------------+ #
# |                              Blocks                             | #
# +-----------------------------------------------------------------+ #
#######################################################################

Block(-2,4,-3,dynamictrees:leaves0:12)
Block(-2,4,-2,dynamictrees:leaves0:12)
Block(-2,5,-3,dynamictrees:leaves0:12)
Block(-2,5,-2,dynamictrees:leaves0:12)
Block(-2,6,-3,dynamictrees:leaves0:12)
Block(-2,6,-2,dynamictrees:leaves0:12)
Block(-2,9,4,dynamictrees:leaves0:12)
Block(-2,9,5,dynamictrees:leaves0:12)
Block(-2,10,4,dynamictrees:leaves0:12)
Block(-2,10,5,dynamictrees:leaves0:12)
Block(-2,11,4,dynamictrees:leaves0:12)
Block(-2,11,5,dynamictrees:leaves0:12)
Block(-2,15,-2,dynamictrees:leaves0:12)
Block(-2,15,-1,dynamictrees:leaves0:12)
Block(-2,15,1,dynamictrees:leaves0:12)
Block(-2,16,-2,dynamictrees:leaves0:12)
Block(-2,16,-1,dynamictrees:leaves0:12)
Block(-2,16,0,dynamictrees:leaves0:12)
Block(-2,16,1,dynamictrees:leaves0:12)
Block(-2,16,2,dynamictrees:leaves0:12)
Block(-2,16,3,dynamictrees:leaves0:12)
Block(-2,16,4,dynamictrees:leaves0:12)
Block(-2,17,-1,dynamictrees:leaves0:12)
Block(-2,17,0,dynamictrees:leaves0:12)
Block(-2,17,1,dynamictrees:leaves0:12)
Block(-2,17,2,dynamictrees:leaves0:12)
Block(-2,17,3,dynamictrees:leaves0:12)
Block(-2,17,4,dynamictrees:leaves0:12)
Block(-2,18,0,dynamictrees:leaves0:12)
Block(-2,18,1,dynamictrees:leaves0:12)
Block(-2,18,2,dynamictrees:leaves0:12)
Block(-1,4,-4,dynamictrees:leaves0:12)
Block(-1,4,-3,dynamictrees:leaves0:13)
Block(-1,4,-2,dynamictrees:leaves0:14)
Block(-1,4,-1,dynamictrees:leaves0:12)
Block(-1,5,-4,dynamictrees:leaves0:12)
Block(-1,5,-3,dynamictrees:leaves0:14)
Block(-1,5,-2,dynamictrees:leaves0:15)
Block(-1,5,-1,dynamictrees:leaves0:12)
Block(-1,6,-4,dynamictrees:leaves0:12)
Block(-1,6,-3,dynamictrees:leaves0:13)
Block(-1,6,-2,dynamictrees:leaves0:14)
Block(-1,6,-1,dynamictrees:leaves0:12)
Block(-1,7,-3,dynamictrees:leaves0:12)
Block(-1,7,-2,dynamictrees:leaves0:12)
Block(-1,9,3,dynamictrees:leaves0:12)
Block(-1,9,4,dynamictrees:leaves0:14)
Block(-1,9,5,dynamictrees:leaves0:13)
Block(-1,9,6,dynamictrees:leaves0:12)
Block(-1,10,3,dynamictrees:leaves0:12)
Block(-1,10,4,dynamictrees:leaves0:15)
Block(-1,10,5,dynamictrees:leaves0:14)
Block(-1,10,6,dynamictrees:leaves0:12)
Block(-1,11,3,dynamictrees:leaves0:12)
Block(-1,11,4,dynamictrees:leaves0:14)
Block(-1,11,5,dynamictrees:leaves0:13)
Block(-1,11,6,dynamictrees:leaves0:12)
Block(-1,12,4,dynamictrees:leaves0:12)
Block(-1,12,5,dynamictrees:leaves0:12)
Block(-1,14,-2,dynamictrees:leaves0:12)
Block(-1,14,1,dynamictrees:junglebranch)
Block(-1,15,-3,dynamictrees:leaves0:12)
Block(-1,15,-2,dynamictrees:leaves0:14)
Block(-1,15,-1,dynamictrees:leaves0:15)
Block(-1,15,1,dynamictrees:leaves0:15)
Block(-1,15,3,dynamictrees:leaves0:12)
Block(-1,15,4,dynamictrees:leaves0:12)
Block(-1,16,-3,dynamictrees:leaves0:12)
Block(-1,16,-2,dynamictrees:leaves0:13)
Block(-1,16,-1,dynamictrees:leaves0:14)
Block(-1,16,0,dynamictrees:leaves0:13)
Block(-1,16,1,dynamictrees:leaves0:14)
Block(-1,16,2,dynamictrees:leaves0:14)
Block(-1,16,3,dynamictrees:leaves0:15)
Block(-1,16,4,dynamictrees:leaves0:14)
Block(-1,16,5,dynamictrees:leaves0:12)
Block(-1,17,-2,dynamictrees:leaves0:12)
Block(-1,17,-1,dynamictrees:leaves0:13)
Block(-1,17,0,dynamictrees:leaves0:14)
Block(-1,17,1,dynamictrees:leaves0:15)
Block(-1,17,2,dynamictrees:leaves0:14)
Block(-1,17,3,dynamictrees:leaves0:14)
Block(-1,17,4,dynamictrees:leaves0:13)
Block(-1,17,5,dynamictrees:leaves0:12)
Block(-1,18,-1,dynamictrees:leaves0:12)
Block(-1,18,0,dynamictrees:leaves0:13)
Block(-1,18,1,dynamictrees:leaves0:14)
Block(-1,18,2,dynamictrees:leaves0:13)
Block(-1,18,3,dynamictrees:leaves0:12)
Block(-1,18,4,dynamictrees:leaves0:12)
Block(-1,19,0,dynamictrees:leaves0:12)
Block(-1,19,1,dynamictrees:leaves0:12)
Block(-1,19,2,dynamictrees:leaves0:12)
Block(0,0,1,dynamictrees:rootydirt:0)
Block(0,1,1,dynamictrees:junglebranch:7)
Block(0,2,1,dynamictrees:junglebranch:7)
Block(0,3,1,dynamictrees:junglebranch:6)
Block(0,4,-4,dynamictrees:leaves0:12)
Block(0,4,-3,dynamictrees:leaves0:14)
Block(0,4,-2,dynamictrees:leaves0:15)
Block(0,4,-1,dynamictrees:leaves0:12)
Block(0,4,1,dynamictrees:junglebranch:6)
Block(0,5,-4,dynamictrees:leaves0:12)
Block(0,5,-3,dynamictrees:leaves0:15)
Block(0,5,-2,dynamictrees:junglebranch)
Block(0,5,-1,dynamictrees:junglebranch:1)
Block(0,5,0,dynamictrees:junglebranch:2)
Block(0,5,1,dynamictrees:junglebranch:6)
Block(0,6,-4,dynamictrees:leaves0:12)
Block(0,6,-3,dynamictrees:leaves0:14)
Block(0,6,-2,dynamictrees:leaves0:15)
Block(0,6,-1,dynamictrees:leaves0:12)
Block(0,6,1,dynamictrees:junglebranch:5)
Block(0,7,-3,dynamictrees:leaves0:12)
Block(0,7,-2,dynamictrees:leaves0:12)
Block(0,7,1,dynamictrees:junglebranch:5)
Block(0,8,1,dynamictrees:junglebranch:5)
Block(0,9,1,dynamictrees:junglebranch:5)
Block(0,9,3,dynamictrees:leaves0:12)
Block(0,9,4,dynamictrees:leaves0:15)
Block(0,9,5,dynamictrees:leaves0:14)
Block(0,9,6,dynamictrees:leaves0:12)
Block(0,10,1,dynamictrees:junglebranch:4)
Block(0,10,2,dynamictrees:junglebranch:1)
Block(0,10,3,dynamictrees:junglebranch:1)
Block(0,10,4,dynamictrees:junglebranch)
Block(0,10,5,dynamictrees:leaves0:15)
Block(0,10,6,dynamictrees:leaves0:12)
Block(0,11,1,dynamictrees:junglebranch:4)
Block(0,11,3,dynamictrees:leaves0:12)
Block(0,11,4,dynamictrees:leaves0:15)
Block(0,11,5,dynamictrees:leaves0:14)
Block(0,11,6,dynamictrees:leaves0:12)
Block(0,12,1,dynamictrees:junglebranch:4)
Block(0,12,4,dynamictrees:leaves0:12)
Block(0,12,5,dynamictrees:leaves0:12)
Block(0,13,1,dynamictrees:junglebranch:3)
Block(0,14,1,dynamictrees:junglebranch:3)
Block(0,15,-3,dynamictrees:leaves0:12)
Block(0,15,-2,dynamictrees:leaves0:15)
Block(0,15,-1,dynamictrees:junglebranch)
Block(0,15,0,dynamictrees:junglebranch:1)
Block(0,15,1,dynamictrees:junglebranch:2)
Block(0,15,2,dynamictrees:junglebranch:1)
Block(0,15,3,dynamictrees:junglebranch:1)
Block(0,15,4,dynamictrees:leaves0:12)
Block(0,16,-3,dynamictrees:leaves0:12)
Block(0,16,-2,dynamictrees:leaves0:14)
Block(0,16,-1,dynamictrees:leaves0:15)
Block(0,16,0,dynamictrees:leaves0:14)
Block(0,16,1,dynamictrees:junglebranch:1)
Block(0,16,2,dynamictrees:leaves0:15)
Block(0,16,3,dynamictrees:junglebranch)
Block(0,16,4,dynamictrees:leaves0:15)
Block(0,16,5,dynamictrees:leaves0:12)
Block(0,17,-3,dynamictrees:leaves0:12)
Block(0,17,-2,dynamictrees:leaves0:13)
Block(0,17,-1,dynamictrees:leaves0:14)
Block(0,17,0,dynamictrees:leaves0:15)
Block(0,17,1,dynamictrees:junglebranch)
Block(0,17,2,dynamictrees:leaves0:15)
Block(0,17,3,dynamictrees:leaves0:15)
Block(0,17,4,dynamictrees:leaves0:14)
Block(0,17,5,dynamictrees:leaves0:12)
Block(0,18,-2,dynamictrees:leaves0:12)
Block(0,18,-1,dynamictrees:leaves0:13)
Block(0,18,0,dynamictrees:leaves0:14)
Block(0,18,1,dynamictrees:leaves0:15)
Block(0,18,2,dynamictrees:leaves0:14)
Block(0,18,3,dynamictrees:leaves0:12)
Block(0,18,4,dynamictrees:leaves0:12)
Block(0,19,-1,dynamictrees:leaves0:12)
Block(0,19,0,dynamictrees:leaves0:12)
Block(0,19,1,dynamictrees:leaves0:12)
Block(0,19,2,dynamictrees:leaves0:12)
Block(1,4,-4,dynamictrees:leaves0:12)
Block(1,4,-3,dynamictrees:leaves0:13)
Block(1,4,-2,dynamictrees:leaves0:14)
Block(1,4,-1,dynamictrees:leaves0:13)
Block(1,4,0,dynamictrees:leaves0:12)
Block(1,4,1,dynamictrees:leaves0:12)
Block(1,5,-4,dynamictrees:leaves0:12)
Block(1,5,-3,dynamictrees:leaves0:14)
Block(1,5,-2,dynamictrees:leaves0:15)
Block(1,5,-1,dynamictrees:leaves0:14)
Block(1,5,0,dynamictrees:junglebranch:1)
Block(1,5,1,dynamictrees:leaves0:12)
Block(1,6,-4,dynamictrees:leaves0:12)
Block(1,6,-3,dynamictrees:leaves0:13)
Block(1,6,-2,dynamictrees:leaves0:14)
Block(1,6,-1,dynamictrees:leaves0:13)
Block(1,6,0,dynamictrees:leaves0:12)
Block(1,6,1,dynamictrees:leaves0:12)
Block(1,7,-3,dynamictrees:leaves0:12)
Block(1,7,-2,dynamictrees:leaves0:12)
Block(1,7,-1,dynamictrees:leaves0:12)
Block(1,9,4,dynamictrees:leaves0:14)
Block(1,9,5,dynamictrees:leaves0:13)
Block(1,9,6,dynamictrees:leaves0:12)
Block(1,10,4,dynamictrees:leaves0:15)
Block(1,10,5,dynamictrees:leaves0:14)
Block(1,10,6,dynamictrees:leaves0:12)
Block(1,11,4,dynamictrees:leaves0:14)
Block(1,11,5,dynamictrees:leaves0:13)
Block(1,11,6,dynamictrees:leaves0:12)
Block(1,12,4,dynamictrees:leaves0:12)
Block(1,12,5,dynamictrees:leaves0:12)
Block(1,14,-2,dynamictrees:leaves0:12)
Block(1,14,1,dynamictrees:junglebranch:1)
Block(1,15,-3,dynamictrees:leaves0:12)
Block(1,15,-2,dynamictrees:leaves0:14)
Block(1,15,-1,dynamictrees:leaves0:15)
Block(1,15,3,dynamictrees:leaves0:12)
Block(1,15,4,dynamictrees:leaves0:12)
Block(1,16,-3,dynamictrees:leaves0:12)
Block(1,16,-2,dynamictrees:leaves0:13)
Block(1,16,-1,dynamictrees:leaves0:14)
Block(1,16,0,dynamictrees:leaves0:13)
Block(1,16,1,dynamictrees:leaves0:12)
Block(1,16,2,dynamictrees:leaves0:14)
Block(1,16,3,dynamictrees:leaves0:15)
Block(1,16,4,dynamictrees:leaves0:14)
Block(1,16,5,dynamictrees:leaves0:12)
Block(1,17,-2,dynamictrees:leaves0:12)
Block(1,17,-1,dynamictrees:leaves0:13)
Block(1,17,0,dynamictrees:leaves0:14)
Block(1,17,1,dynamictrees:leaves0:15)
Block(1,17,2,dynamictrees:leaves0:14)
Block(1,17,3,dynamictrees:leaves0:14)
Block(1,17,4,dynamictrees:leaves0:13)
Block(1,17,5,dynamictrees:leaves0:12)
Block(1,18,-1,dynamictrees:leaves0:12)
Block(1,18,0,dynamictrees:leaves0:13)
Block(1,18,1,dynamictrees:leaves0:14)
Block(1,18,2,dynamictrees:leaves0:13)
Block(1,18,3,dynamictrees:leaves0:12)
Block(1,18,4,dynamictrees:leaves0:12)
Block(1,19,0,dynamictrees:leaves0:12)
Block(1,19,1,dynamictrees:leaves0:12)
Block(1,19,2,dynamictrees:leaves0:12)
Block(2,4,-3,dynamictrees:leaves0:12)
Block(2,4,-2,dynamictrees:leaves0:13)
Block(2,4,-1,dynamictrees:leaves0:14)
Block(2,4,0,dynamictrees:leaves0:15)
Block(2,4,1,dynamictrees:leaves0:14)
Block(2,4,2,dynamictrees:leaves0:12)
Block(2,5,-4,dynamictrees:leaves0:12)
Block(2,5,-3,dynamictrees:leaves0:13)
Block(2,5,-2,dynamictrees:leaves0:14)
Block(2,5,-1,dynamictrees:leaves0:15)
Block(2,5,0,dynamictrees:junglebranch)
Block(2,5,1,dynamictrees:leaves0:15)
Block(2,5,2,dynamictrees:leaves0:12)
Block(2,6,-3,dynamictrees:leaves0:12)
Block(2,6,-2,dynamictrees:leaves0:13)
Block(2,6,-1,dynamictrees:leaves0:14)
Block(2,6,0,dynamictrees:leaves0:15)
Block(2,6,1,dynamictrees:leaves0:14)
Block(2,6,2,dynamictrees:leaves0:12)
Block(2,7,-2,dynamictrees:leaves0:12)
Block(2,7,-1,dynamictrees:leaves0:12)
Block(2,7,0,dynamictrees:leaves0:12)
Block(2,7,1,dynamictrees:leaves0:12)
Block(2,9,4,dynamictrees:leaves0:12)
Block(2,9,5,dynamictrees:leaves0:12)
Block(2,10,4,dynamictrees:leaves0:12)
Block(2,10,5,dynamictrees:leaves0:12)
Block(2,11,4,dynamictrees:leaves0:12)
Block(2,11,5,dynamictrees:leaves0:12)
Block(2,14,-2,dynamictrees:leaves0:12)
Block(2,14,-1,dynamictrees:leaves0:15)
Block(2,14,0,dynamictrees:junglebranch)
Block(2,14,1,dynamictrees:junglebranch:1)
Block(2,14,2,dynamictrees:junglebranch)
Block(2,14,3,dynamictrees:leaves0:15)
Block(2,14,4,dynamictrees:leaves0:12)
Block(2,15,-3,dynamictrees:leaves0:12)
Block(2,15,-2,dynamictrees:leaves0:13)
Block(2,15,-1,dynamictrees:leaves0:14)
Block(2,15,0,dynamictrees:leaves0:15)
Block(2,15,1,dynamictrees:leaves0:14)
Block(2,15,2,dynamictrees:leaves0:15)
Block(2,15,3,dynamictrees:leaves0:14)
Block(2,15,4,dynamictrees:leaves0:12)
Block(2,16,-2,dynamictrees:leaves0:12)
Block(2,16,-1,dynamictrees:leaves0:13)
Block(2,16,0,dynamictrees:leaves0:12)
Block(2,16,1,dynamictrees:leaves0:12)
Block(2,16,2,dynamictrees:leaves0:12)
Block(2,16,3,dynamictrees:leaves0:12)
Block(2,16,4,dynamictrees:leaves0:12)
Block(2,17,-1,dynamictrees:leaves0:12)
Block(2,17,0,dynamictrees:leaves0:12)
Block(2,17,1,dynamictrees:leaves0:12)
Block(2,17,2,dynamictrees:leaves0:12)
Block(2,17,3,dynamictrees:leaves0:12)
Block(2,17,4,dynamictrees:leaves0:12)
Block(2,18,0,dynamictrees:leaves0:12)
Block(2,18,1,dynamictrees:leaves0:12)
Block(2,18,2,dynamictrees:leaves0:12)
Block(3,4,-2,dynamictrees:leaves0:12)
Block(3,4,-1,dynamictrees:leaves0:13)
Block(3,4,0,dynamictrees:leaves0:14)
Block(3,4,1,dynamictrees:leaves0:13)
Block(3,4,2,dynamictrees:leaves0:12)
Block(3,5,-3,dynamictrees:leaves0:12)
Block(3,5,-2,dynamictrees:leaves0:13)
Block(3,5,-1,dynamictrees:leaves0:14)
Block(3,5,0,dynamictrees:leaves0:15)
Block(3,5,1,dynamictrees:leaves0:14)
Block(3,5,2,dynamictrees:leaves0:12)
Block(3,6,-2,dynamictrees:leaves0:12)
Block(3,6,-1,dynamictrees:leaves0:13)
Block(3,6,0,dynamictrees:leaves0:14)
Block(3,6,1,dynamictrees:leaves0:13)
Block(3,6,2,dynamictrees:leaves0:12)
Block(3,7,-1,dynamictrees:leaves0:12)
Block(3,7,0,dynamictrees:leaves0:12)
Block(3,7,1,dynamictrees:leaves0:12)
Block(3,13,-2,dynamictrees:leaves0:12)
Block(3,13,-1,dynamictrees:leaves0:13)
Block(3,13,0,dynamictrees:leaves0:14)
Block(3,13,1,dynamictrees:leaves0:15)
Block(3,13,2,dynamictrees:leaves0:14)
Block(3,13,3,dynamictrees:leaves0:13)
Block(3,13,4,dynamictrees:leaves0:12)
Block(3,14,-2,dynamictrees:leaves0:12)
Block(3,14,-1,dynamictrees:leaves0:14)
Block(3,14,0,dynamictrees:leaves0:15)
Block(3,14,1,dynamictrees:junglebranch)
Block(3,14,2,dynamictrees:leaves0:15)
Block(3,14,3,dynamictrees:leaves0:14)
Block(3,14,4,dynamictrees:leaves0:12)
Block(3,15,-2,dynamictrees:leaves0:12)
Block(3,15,-1,dynamictrees:leaves0:13)
Block(3,15,0,dynamictrees:leaves0:14)
Block(3,15,1,dynamictrees:leaves0:15)
Block(3,15,2,dynamictrees:leaves0:14)
Block(3,15,3,dynamictrees:leaves0:13)
Block(3,15,4,dynamictrees:leaves0:12)
Block(3,16,-1,dynamictrees:leaves0:12)
Block(3,16,0,dynamictrees:leaves0:12)
Block(3,16,1,dynamictrees:leaves0:12)
Block(3,16,2,dynamictrees:leaves0:12)
Block(3,16,3,dynamictrees:leaves0:12)
Block(4,4,-1,dynamictrees:leaves0:12)
Block(4,4,0,dynamictrees:leaves0:12)
Block(4,4,1,dynamictrees:leaves0:12)
Block(4,5,-2,dynamictrees:leaves0:12)
Block(4,5,-1,dynamictrees:leaves0:12)
Block(4,5,0,dynamictrees:leaves0:12)
Block(4,5,1,dynamictrees:leaves0:12)
Block(4,6,-1,dynamictrees:leaves0:12)
Block(4,6,0,dynamictrees:leaves0:12)
Block(4,6,1,dynamictrees:leaves0:12)
Block(4,13,-1,dynamictrees:leaves0:12)
Block(4,13,0,dynamictrees:leaves0:13)
Block(4,13,1,dynamictrees:leaves0:14)
Block(4,13,2,dynamictrees:leaves0:13)
Block(4,13,3,dynamictrees:leaves0:12)
Block(4,14,-2,dynamictrees:leaves0:12)
Block(4,14,-1,dynamictrees:leaves0:13)
Block(4,14,0,dynamictrees:leaves0:14)
Block(4,14,1,dynamictrees:leaves0:15)
Block(4,14,2,dynamictrees:leaves0:14)
Block(4,14,3,dynamictrees:leaves0:13)
Block(4,14,4,dynamictrees:leaves0:12)
Block(4,15,-1,dynamictrees:leaves0:12)
Block(4,15,0,dynamictrees:leaves0:13)
Block(4,15,1,dynamictrees:leaves0:14)
Block(4,15,2,dynamictrees:leaves0:13)
Block(4,15,3,dynamictrees:leaves0:12)
Block(4,16,0,dynamictrees:leaves0:12)
Block(4,16,1,dynamictrees:leaves0:12)
Block(4,16,2,dynamictrees:leaves0:12)
Block(5,13,0,dynamictrees:leaves0:12)
Block(5,13,1,dynamictrees:leaves0:12)
Block(5,13,2,dynamictrees:leaves0:12)
Block(5,14,-1,dynamictrees:leaves0:12)
Block(5,14,0,dynamictrees:leaves0:12)
Block(5,14,1,dynamictrees:leaves0:12)
Block(5,14,2,dynamictrees:leaves0:12)
Block(5,14,3,dynamictrees:leaves0:12)
Block(5,15,0,dynamictrees:leaves0:12)
Block(5,15,1,dynamictrees:leaves0:12)
Block(5,15,2,dynamictrees:leaves0:12)

#######################################################################
# +-----------------------------------------------------------------+ #
# |                            BO3 checks                           | #
# +-----------------------------------------------------------------+ #
#######################################################################

BlockCheck(0,-1,1,GRASS,DIRT,biomesoplenty:grass,biomesoplenty:dirt)

#######################################################################
# +-----------------------------------------------------------------+ #
# |                             Branches                            | #
# +-----------------------------------------------------------------+ #
#######################################################################


#######################################################################
# +-----------------------------------------------------------------+ #
# |                             Entities                            | #
# +-----------------------------------------------------------------+ #
#######################################################################


#######################################################################
# +-----------------------------------------------------------------+ #
# |                            Particles                            | #
# +-----------------------------------------------------------------+ #
#######################################################################


#######################################################################
# +-----------------------------------------------------------------+ #
# |                             Spawners                            | #
# +-----------------------------------------------------------------+ #
#######################################################################


#######################################################################
# +-----------------------------------------------------------------+ #
# |                             ModData                             | #
# +-----------------------------------------------------------------+ #
#######################################################################

