#######################################################################
# +-----------------------------------------------------------------+ #
# |                            BO3 object                           | #
# +-----------------------------------------------------------------+ #
#######################################################################

Author: Bo3 BulkEdit

Description: Converted Schematic - Modified by Bo3BulkEdit

Version: 3

SettingsMode: WriteDisable

#######################################################################
# +-----------------------------------------------------------------+ #
# |                          Main settings                          | #
# +-----------------------------------------------------------------+ #
#######################################################################

IsOTGPlus: true
Tree: false
Frequency: 1
Rarity: 100.0
RotateRandomly: false
SpawnHeight: randomY
MaxBranchDepth: 10
ExcludedBiomes: All

##############################
# Height Limits for the BO3. #
##############################

MinHeight: 0
MaxHeight: 255

#######################################################################
# +-----------------------------------------------------------------+ #
# |                      Source block settings                      | #
# +-----------------------------------------------------------------+ #
#######################################################################

CanOverride: true
MaxPercentageOutsideSourceBlock: 100
OutsideSourceBlock: placeAnyway

#######################################################################
# +-----------------------------------------------------------------+ #
# |                               OTG+                              | #
# +-----------------------------------------------------------------+ #
#######################################################################

BO3Group: CeilingCrystals:0

#######################################################################
# +-----------------------------------------------------------------+ #
# |                              Blocks                             | #
# +-----------------------------------------------------------------+ #
#######################################################################

B(0,750,0,AIR)
B(15,750,15,AIR)
B(2,-31,15,betternether:quartz_stained_glass:15)
B(1,-30,14,betternether:quartz_stained_glass:15)
B(2,-30,14,betternether:quartz_stained_glass:15)
B(0,-30,15,betternether:quartz_stained_glass:15)
B(1,-30,15,betternether:quartz_stained_glass:15)
B(2,-30,15,betternether:quartz_stained_glass:15)
B(3,-30,15,betternether:quartz_stained_glass:15)
B(0,-29,13,betternether:quartz_stained_glass:15)
B(1,-29,13,betternether:quartz_stained_glass:15)
B(0,-29,14,betternether:quartz_stained_glass:15)
B(1,-29,14,betternether:quartz_stained_glass:15)
B(2,-29,14,betternether:quartz_stained_glass:15)
B(3,-29,14,betternether:quartz_stained_glass:15)
B(0,-29,15,betternether:quartz_stained_glass:15)
B(1,-29,15,betternether:quartz_stained_glass:15)
B(2,-29,15,betternether:quartz_stained_glass:15)
B(3,-29,15,betternether:quartz_stained_glass:15)
B(4,-29,15,betternether:quartz_stained_glass:15)
B(0,-28,12,betternether:quartz_stained_glass:15)
B(0,-28,13,betternether:quartz_stained_glass:15)
B(1,-28,13,betternether:quartz_stained_glass:15)
B(0,-28,14,betternether:quartz_stained_glass:15)
B(1,-28,14,betternether:quartz_stained_glass:15)
B(2,-28,14,betternether:quartz_stained_glass:15)
B(3,-28,14,betternether:quartz_stained_glass:15)
RB(0,-28,15,srparasites:parasitestain:1,80,quark:crystal:1,30,srparasites:parasiterubbledense:1,100)
B(1,-28,15,betternether:quartz_stained_glass:15)
B(2,-28,15,betternether:quartz_stained_glass:15)
B(3,-28,15,betternether:quartz_stained_glass:15)
B(0,-27,12,betternether:quartz_stained_glass:15)
B(0,-27,13,betternether:quartz_stained_glass:15)
B(1,-27,13,betternether:quartz_stained_glass:15)
B(2,-27,13,betternether:quartz_stained_glass:15)
B(0,-27,14,betternether:quartz_stained_glass:15)
B(1,-27,14,betternether:quartz_stained_glass:15)
B(2,-27,14,betternether:quartz_stained_glass:15)
B(3,-27,14,betternether:quartz_stained_glass:15)
RB(0,-27,15,srparasites:parasitestain:1,80,quark:crystal:1,30,srparasites:parasiterubbledense:1,100)
B(1,-27,15,srparasites:parasiterubbledense:1)
B(2,-27,15,srparasites:parasiterubbledense:1)
B(3,-27,15,betternether:quartz_stained_glass:15)
B(0,-26,12,betternether:quartz_stained_glass:15)
B(0,-26,13,betternether:quartz_stained_glass:15)
B(1,-26,13,betternether:quartz_stained_glass:15)
B(2,-26,13,betternether:quartz_stained_glass:15)
B(0,-26,14,betternether:quartz_stained_glass:15)
B(1,-26,14,betternether:quartz_stained_glass:15)
B(2,-26,14,betternether:quartz_stained_glass:15)
RB(0,-26,15,srparasites:parasitestain:1,80,quark:crystal:1,30,srparasites:parasiterubbledense:1,100)
B(1,-26,15,srparasites:parasiterubbledense:1)
B(2,-26,15,srparasites:parasiterubbledense:1)
B(3,-26,15,betternether:quartz_stained_glass:15)
B(0,-25,12,betternether:quartz_stained_glass:15)
B(1,-25,12,betternether:quartz_stained_glass:15)
B(0,-25,13,betternether:quartz_stained_glass:15)
B(1,-25,13,betternether:quartz_stained_glass:15)
B(2,-25,13,betternether:quartz_stained_glass:15)
B(0,-25,14,betternether:quartz_stained_glass:15)
B(1,-25,14,betternether:quartz_stained_glass:15)
B(2,-25,14,betternether:quartz_stained_glass:15)
B(0,-25,15,betternether:quartz_stained_glass:15)
B(1,-25,15,srparasites:parasiterubbledense:1)
B(2,-25,15,betternether:quartz_stained_glass:15)
B(0,-24,12,betternether:quartz_stained_glass:15)
B(1,-24,12,betternether:quartz_stained_glass:15)
B(0,-24,13,betternether:quartz_stained_glass:15)
B(1,-24,13,betternether:quartz_stained_glass:15)
B(0,-24,14,betternether:quartz_stained_glass:15)
B(1,-24,14,betternether:quartz_stained_glass:15)
B(2,-24,14,betternether:quartz_stained_glass:15)
B(0,-24,15,srparasites:parasiterubbledense:1)
B(1,-24,15,betternether:quartz_stained_glass:15)
B(0,-23,11,betternether:quartz_stained_glass:15)
B(0,-23,12,betternether:quartz_stained_glass:15)
B(1,-23,12,betternether:quartz_stained_glass:15)
B(0,-23,13,betternether:quartz_stained_glass:15)
B(1,-23,13,betternether:quartz_stained_glass:15)
B(0,-23,14,srparasites:parasiterubbledense:1)
B(1,-23,14,betternether:quartz_stained_glass:15)
B(0,-23,15,betternether:quartz_stained_glass:15)
B(0,-22,11,betternether:quartz_stained_glass:15)
B(0,-22,12,betternether:quartz_stained_glass:15)
B(0,-22,13,betternether:quartz_stained_glass:15)
B(1,-22,13,betternether:quartz_stained_glass:15)
B(0,-22,14,betternether:quartz_stained_glass:15)
B(0,-22,15,betternether:quartz_stained_glass:15)
B(0,-21,11,betternether:quartz_stained_glass:15)
B(0,-21,12,betternether:quartz_stained_glass:15)
B(0,-21,13,betternether:quartz_stained_glass:15)
B(0,-20,12,betternether:quartz_stained_glass:15)

