#######################################################################
# +-----------------------------------------------------------------+ #
# |                            BO3 object                           | #
# +-----------------------------------------------------------------+ #
#######################################################################

Author: Bo3 BulkEdit

Description: Converted Schematic - Modified by Bo3BulkEdit

Version: 3

SettingsMode: WriteDisable

#######################################################################
# +-----------------------------------------------------------------+ #
# |                          Main settings                          | #
# +-----------------------------------------------------------------+ #
#######################################################################

IsOTGPlus: true
Tree: false
Frequency: 1
Rarity: 100.0
RotateRandomly: false
SpawnHeight: randomY
MaxBranchDepth: 10
ExcludedBiomes: All

##############################
# Height Limits for the BO3. #
##############################

MinHeight: 0
MaxHeight: 255

#######################################################################
# +-----------------------------------------------------------------+ #
# |                      Source block settings                      | #
# +-----------------------------------------------------------------+ #
#######################################################################

CanOverride: true
MaxPercentageOutsideSourceBlock: 100
OutsideSourceBlock: placeAnyway

#######################################################################
# +-----------------------------------------------------------------+ #
# |                               OTG+                              | #
# +-----------------------------------------------------------------+ #
#######################################################################

BO3Group: CeilingCrystals:0

#######################################################################
# +-----------------------------------------------------------------+ #
# |                              Blocks                             | #
# +-----------------------------------------------------------------+ #
#######################################################################

B(0,750,0,AIR)
B(15,750,15,AIR)
B(14,-31,15,betternether:quartz_stained_glass:15)
B(15,-31,15,betternether:quartz_stained_glass:15)
B(15,-30,14,betternether:quartz_stained_glass:15)
B(13,-30,15,betternether:quartz_stained_glass:15)
B(14,-30,15,betternether:quartz_stained_glass:15)
B(15,-30,15,betternether:quartz_stained_glass:15)
B(14,-29,14,betternether:quartz_stained_glass:15)
B(15,-29,14,betternether:quartz_stained_glass:15)
B(12,-29,15,betternether:quartz_stained_glass:15)
B(13,-29,15,betternether:quartz_stained_glass:15)
B(14,-29,15,betternether:quartz_stained_glass:15)
B(15,-29,15,betternether:quartz_stained_glass:15)
B(14,-28,13,betternether:quartz_stained_glass:15)
B(13,-28,14,betternether:quartz_stained_glass:15)
B(14,-28,14,betternether:quartz_stained_glass:15)
B(15,-28,14,betternether:quartz_stained_glass:15)
B(11,-28,15,betternether:quartz_stained_glass:15)
B(12,-28,15,betternether:quartz_stained_glass:15)
B(13,-28,15,betternether:quartz_stained_glass:15)
B(14,-28,15,betternether:quartz_stained_glass:15)
B(15,-28,15,betternether:quartz_stained_glass:15)
B(13,-27,13,betternether:quartz_stained_glass:15)
B(14,-27,13,betternether:quartz_stained_glass:15)
B(12,-27,14,betternether:quartz_stained_glass:15)
B(13,-27,14,betternether:quartz_stained_glass:15)
B(14,-27,14,betternether:quartz_stained_glass:15)
B(15,-27,14,betternether:quartz_stained_glass:15)
B(9,-27,15,betternether:quartz_stained_glass:15)
B(10,-27,15,betternether:quartz_stained_glass:15)
B(11,-27,15,betternether:quartz_stained_glass:15)
B(12,-27,15,betternether:quartz_stained_glass:15)
B(13,-27,15,betternether:quartz_stained_glass:15)
B(14,-27,15,betternether:quartz_stained_glass:15)
B(15,-27,15,betternether:quartz_stained_glass:15)
B(13,-26,12,betternether:quartz_stained_glass:15)
B(12,-26,13,betternether:quartz_stained_glass:15)
B(13,-26,13,betternether:quartz_stained_glass:15)
B(14,-26,13,betternether:quartz_stained_glass:15)
B(11,-26,14,betternether:quartz_stained_glass:15)
B(12,-26,14,betternether:quartz_stained_glass:15)
B(13,-26,14,betternether:quartz_stained_glass:15)
B(14,-26,14,betternether:quartz_stained_glass:15)
B(15,-26,14,betternether:quartz_stained_glass:15)
B(8,-26,15,betternether:quartz_stained_glass:15)
B(9,-26,15,betternether:quartz_stained_glass:15)
B(10,-26,15,betternether:quartz_stained_glass:15)
B(11,-26,15,betternether:quartz_stained_glass:15)
B(12,-26,15,betternether:quartz_stained_glass:15)
B(13,-26,15,betternether:quartz_stained_glass:15)
B(14,-26,15,betternether:quartz_stained_glass:15)
B(15,-26,15,betternether:quartz_stained_glass:15)
B(12,-25,12,betternether:quartz_stained_glass:15)
B(13,-25,12,betternether:quartz_stained_glass:15)
B(11,-25,13,betternether:quartz_stained_glass:15)
B(12,-25,13,betternether:quartz_stained_glass:15)
B(13,-25,13,betternether:quartz_stained_glass:15)
B(14,-25,13,betternether:quartz_stained_glass:15)
B(9,-25,14,betternether:quartz_stained_glass:15)
B(10,-25,14,betternether:quartz_stained_glass:15)
B(11,-25,14,betternether:quartz_stained_glass:15)
B(12,-25,14,betternether:quartz_stained_glass:15)
B(13,-25,14,betternether:quartz_stained_glass:15)
B(14,-25,14,betternether:quartz_stained_glass:15)
B(15,-25,14,betternether:quartz_stained_glass:15)
B(8,-25,15,betternether:quartz_stained_glass:15)
B(9,-25,15,betternether:quartz_stained_glass:15)
B(10,-25,15,betternether:quartz_stained_glass:15)
RB(11,-25,15,srparasites:parasitestain:1,80,quark:crystal:1,30,srparasites:parasiterubbledense:1,100)
B(12,-25,15,betternether:quartz_stained_glass:15)
RB(13,-25,15,srparasites:parasitestain:1,80,quark:crystal:1,30,srparasites:parasiterubbledense:1,100)
B(14,-25,15,betternether:quartz_stained_glass:15)
B(15,-25,15,betternether:quartz_stained_glass:15)
B(12,-24,11,betternether:quartz_stained_glass:15)
B(11,-24,12,betternether:quartz_stained_glass:15)
B(12,-24,12,betternether:quartz_stained_glass:15)
B(13,-24,12,betternether:quartz_stained_glass:15)
B(9,-24,13,betternether:quartz_stained_glass:15)
B(10,-24,13,betternether:quartz_stained_glass:15)
B(11,-24,13,betternether:quartz_stained_glass:15)
B(12,-24,13,betternether:quartz_stained_glass:15)
B(13,-24,13,betternether:quartz_stained_glass:15)
B(14,-24,13,betternether:quartz_stained_glass:15)
B(8,-24,14,betternether:quartz_stained_glass:15)
B(9,-24,14,betternether:quartz_stained_glass:15)
B(10,-24,14,betternether:quartz_stained_glass:15)
B(11,-24,14,betternether:quartz_stained_glass:15)
B(12,-24,14,betternether:quartz_stained_glass:15)
B(13,-24,14,betternether:quartz_stained_glass:15)
B(14,-24,14,betternether:quartz_stained_glass:15)
B(15,-24,14,betternether:quartz_stained_glass:15)
B(8,-24,15,betternether:quartz_stained_glass:15)
B(9,-24,15,betternether:quartz_stained_glass:15)
B(10,-24,15,betternether:quartz_stained_glass:15)
RB(11,-24,15,srparasites:parasitestain:1,80,quark:crystal:1,30,srparasites:parasiterubbledense:1,100)
RB(12,-24,15,srparasites:parasitestain:1,80,quark:crystal:1,30,srparasites:parasiterubbledense:1,100)
RB(13,-24,15,srparasites:parasitestain:1,80,quark:crystal:1,30,srparasites:parasiterubbledense:1,100)
B(14,-24,15,betternether:quartz_stained_glass:15)
B(15,-24,15,betternether:quartz_stained_glass:15)
B(11,-23,11,betternether:quartz_stained_glass:15)
B(12,-23,11,betternether:quartz_stained_glass:15)
B(9,-23,12,betternether:quartz_stained_glass:15)
B(10,-23,12,betternether:quartz_stained_glass:15)
B(11,-23,12,betternether:quartz_stained_glass:15)
B(12,-23,12,betternether:quartz_stained_glass:15)
B(13,-23,12,betternether:quartz_stained_glass:15)
B(8,-23,13,betternether:quartz_stained_glass:15)
B(9,-23,13,betternether:quartz_stained_glass:15)
B(10,-23,13,betternether:quartz_stained_glass:15)
B(11,-23,13,betternether:quartz_stained_glass:15)
B(12,-23,13,betternether:quartz_stained_glass:15)
B(13,-23,13,betternether:quartz_stained_glass:15)
B(14,-23,13,betternether:quartz_stained_glass:15)
B(8,-23,14,betternether:quartz_stained_glass:15)
B(9,-23,14,betternether:quartz_stained_glass:15)
B(10,-23,14,betternether:quartz_stained_glass:15)
RB(11,-23,14,srparasites:parasitestain:1,80,quark:crystal:1,30,srparasites:parasiterubbledense:1,100)
B(12,-23,14,betternether:quartz_stained_glass:15)
RB(13,-23,14,srparasites:parasitestain:1,80,quark:crystal:1,30,srparasites:parasiterubbledense:1,100)
B(14,-23,14,betternether:quartz_stained_glass:15)
B(15,-23,14,betternether:quartz_stained_glass:15)
B(8,-23,15,betternether:quartz_stained_glass:15)
B(9,-23,15,betternether:quartz_stained_glass:15)
B(10,-23,15,betternether:quartz_stained_glass:15)
RB(11,-23,15,srparasites:parasitestain:1,80,quark:crystal:1,30,srparasites:parasiterubbledense:1,100)
RB(12,-23,15,srparasites:parasitestain:1,80,quark:crystal:1,30,srparasites:parasiterubbledense:1,100)
B(13,-23,15,betternether:quartz_stained_glass:15)
B(14,-23,15,betternether:quartz_stained_glass:15)
B(15,-23,15,betternether:quartz_stained_glass:15)
B(11,-22,10,betternether:quartz_stained_glass:15)
B(9,-22,11,betternether:quartz_stained_glass:15)
B(10,-22,11,betternether:quartz_stained_glass:15)
B(11,-22,11,betternether:quartz_stained_glass:15)
B(12,-22,11,betternether:quartz_stained_glass:15)
B(8,-22,12,betternether:quartz_stained_glass:15)
B(9,-22,12,betternether:quartz_stained_glass:15)
B(10,-22,12,betternether:quartz_stained_glass:15)
B(11,-22,12,betternether:quartz_stained_glass:15)
B(12,-22,12,betternether:quartz_stained_glass:15)
B(13,-22,12,betternether:quartz_stained_glass:15)
B(7,-22,13,betternether:quartz_stained_glass:15)
B(8,-22,13,betternether:quartz_stained_glass:15)
B(9,-22,13,betternether:quartz_stained_glass:15)
B(10,-22,13,betternether:quartz_stained_glass:15)
B(11,-22,13,betternether:quartz_stained_glass:15)
B(12,-22,13,betternether:quartz_stained_glass:15)
B(13,-22,13,betternether:quartz_stained_glass:15)
B(14,-22,13,betternether:quartz_stained_glass:15)
B(8,-22,14,betternether:quartz_stained_glass:15)
B(9,-22,14,betternether:quartz_stained_glass:15)
B(10,-22,14,betternether:quartz_stained_glass:15)
RB(11,-22,14,srparasites:parasitestain:1,80,quark:crystal:1,30,srparasites:parasiterubbledense:1,100)
RB(12,-22,14,srparasites:parasitestain:1,80,quark:crystal:1,30,srparasites:parasiterubbledense:1,100)
RB(13,-22,14,srparasites:parasitestain:1,80,quark:crystal:1,30,srparasites:parasiterubbledense:1,100)
B(14,-22,14,betternether:quartz_stained_glass:15)
B(15,-22,14,betternether:quartz_stained_glass:15)
B(8,-22,15,betternether:quartz_stained_glass:15)
B(9,-22,15,betternether:quartz_stained_glass:15)
RB(10,-22,15,srparasites:parasitestain:1,80,quark:crystal:1,30,srparasites:parasiterubbledense:1,100)
RB(11,-22,15,srparasites:parasitestain:1,80,quark:crystal:1,30,srparasites:parasiterubbledense:1,100)
B(12,-22,15,betternether:quartz_stained_glass:15)
B(13,-22,15,betternether:quartz_stained_glass:15)
B(14,-22,15,betternether:quartz_stained_glass:15)
B(15,-22,15,betternether:quartz_stained_glass:15)
B(10,-21,9,betternether:quartz_stained_glass:15)
B(9,-21,10,betternether:quartz_stained_glass:15)
B(10,-21,10,betternether:quartz_stained_glass:15)
B(11,-21,10,betternether:quartz_stained_glass:15)
B(8,-21,11,betternether:quartz_stained_glass:15)
B(9,-21,11,betternether:quartz_stained_glass:15)
B(10,-21,11,betternether:quartz_stained_glass:15)
B(11,-21,11,betternether:quartz_stained_glass:15)
B(12,-21,11,betternether:quartz_stained_glass:15)
B(7,-21,12,betternether:quartz_stained_glass:15)
B(8,-21,12,betternether:quartz_stained_glass:15)
B(9,-21,12,betternether:quartz_stained_glass:15)
B(10,-21,12,betternether:quartz_stained_glass:15)
B(11,-21,12,betternether:quartz_stained_glass:15)
B(12,-21,12,betternether:quartz_stained_glass:15)
B(13,-21,12,betternether:quartz_stained_glass:15)
B(7,-21,13,betternether:quartz_stained_glass:15)
B(8,-21,13,betternether:quartz_stained_glass:15)
B(9,-21,13,betternether:quartz_stained_glass:15)
RB(10,-21,13,srparasites:parasitestain:1,80,quark:crystal:1,30,srparasites:parasiterubbledense:1,100)
B(11,-21,13,betternether:quartz_stained_glass:15)
RB(12,-21,13,srparasites:parasitestain:1,80,quark:crystal:1,30,srparasites:parasiterubbledense:1,100)
B(13,-21,13,betternether:quartz_stained_glass:15)
B(14,-21,13,betternether:quartz_stained_glass:15)
B(8,-21,14,betternether:quartz_stained_glass:15)
B(9,-21,14,betternether:quartz_stained_glass:15)
B(10,-21,14,betternether:quartz_stained_glass:15)
RB(11,-21,14,srparasites:parasitestain:1,80,quark:crystal:1,30,srparasites:parasiterubbledense:1,100)
RB(12,-21,14,srparasites:parasitestain:1,80,quark:crystal:1,30,srparasites:parasiterubbledense:1,100)
B(13,-21,14,betternether:quartz_stained_glass:15)
B(14,-21,14,betternether:quartz_stained_glass:15)
B(15,-21,14,betternether:quartz_stained_glass:15)
B(8,-21,15,betternether:quartz_stained_glass:15)
B(9,-21,15,betternether:quartz_stained_glass:15)
RB(10,-21,15,srparasites:parasitestain:1,80,quark:crystal:1,30,srparasites:parasiterubbledense:1,100)
RB(11,-21,15,srparasites:parasitestain:1,80,quark:crystal:1,30,srparasites:parasiterubbledense:1,100)
B(12,-21,15,betternether:quartz_stained_glass:15)
B(13,-21,15,betternether:quartz_stained_glass:15)
B(14,-21,15,betternether:quartz_stained_glass:15)
B(15,-21,15,betternether:quartz_stained_glass:15)
B(9,-20,9,betternether:quartz_stained_glass:15)
B(10,-20,9,betternether:quartz_stained_glass:15)
B(8,-20,10,betternether:quartz_stained_glass:15)
B(9,-20,10,betternether:quartz_stained_glass:15)
B(10,-20,10,betternether:quartz_stained_glass:15)
B(11,-20,10,betternether:quartz_stained_glass:15)
B(7,-20,11,betternether:quartz_stained_glass:15)
B(8,-20,11,betternether:quartz_stained_glass:15)
B(9,-20,11,betternether:quartz_stained_glass:15)
B(10,-20,11,betternether:quartz_stained_glass:15)
B(11,-20,11,betternether:quartz_stained_glass:15)
B(12,-20,11,betternether:quartz_stained_glass:15)
B(6,-20,12,betternether:quartz_stained_glass:15)
B(7,-20,12,betternether:quartz_stained_glass:15)
B(8,-20,12,betternether:quartz_stained_glass:15)
B(9,-20,12,betternether:quartz_stained_glass:15)
B(10,-20,12,betternether:quartz_stained_glass:15)
B(11,-20,12,betternether:quartz_stained_glass:15)
B(12,-20,12,betternether:quartz_stained_glass:15)
B(13,-20,12,betternether:quartz_stained_glass:15)
B(7,-20,13,betternether:quartz_stained_glass:15)
B(8,-20,13,betternether:quartz_stained_glass:15)
B(9,-20,13,betternether:quartz_stained_glass:15)
RB(10,-20,13,srparasites:parasitestain:1,80,quark:crystal:1,30,srparasites:parasiterubbledense:1,100)
RB(11,-20,13,srparasites:parasitestain:1,80,quark:crystal:1,30,srparasites:parasiterubbledense:1,100)
RB(12,-20,13,srparasites:parasitestain:1,80,quark:crystal:1,30,srparasites:parasiterubbledense:1,100)
B(13,-20,13,betternether:quartz_stained_glass:15)
B(14,-20,13,betternether:quartz_stained_glass:15)
B(8,-20,14,betternether:quartz_stained_glass:15)
B(9,-20,14,betternether:quartz_stained_glass:15)
RB(10,-20,14,srparasites:parasitestain:1,80,quark:crystal:1,30,srparasites:parasiterubbledense:1,100)
RB(11,-20,14,srparasites:parasitestain:1,80,quark:crystal:1,30,srparasites:parasiterubbledense:1,100)
B(12,-20,14,betternether:quartz_stained_glass:15)
B(13,-20,14,betternether:quartz_stained_glass:15)
B(14,-20,14,betternether:quartz_stained_glass:15)
B(15,-20,14,betternether:quartz_stained_glass:15)
B(8,-20,15,betternether:quartz_stained_glass:15)
B(9,-20,15,betternether:quartz_stained_glass:15)
B(10,-20,15,betternether:quartz_stained_glass:15)
B(11,-20,15,betternether:quartz_stained_glass:15)
B(12,-20,15,betternether:quartz_stained_glass:15)
B(13,-20,15,betternether:quartz_stained_glass:15)
B(14,-20,15,betternether:quartz_stained_glass:15)
B(15,-20,15,betternether:quartz_stained_glass:15)
B(10,-19,8,betternether:quartz_stained_glass:15)
B(8,-19,9,betternether:quartz_stained_glass:15)
B(9,-19,9,betternether:quartz_stained_glass:15)
B(10,-19,9,betternether:quartz_stained_glass:15)
B(7,-19,10,betternether:quartz_stained_glass:15)
B(8,-19,10,betternether:quartz_stained_glass:15)
B(9,-19,10,betternether:quartz_stained_glass:15)
B(10,-19,10,betternether:quartz_stained_glass:15)
B(11,-19,10,betternether:quartz_stained_glass:15)
B(6,-19,11,betternether:quartz_stained_glass:15)
B(7,-19,11,betternether:quartz_stained_glass:15)
B(8,-19,11,betternether:quartz_stained_glass:15)
RB(9,-19,11,srparasites:parasitestain:1,80,quark:crystal:1,30,srparasites:parasiterubbledense:1,100)
B(10,-19,11,betternether:quartz_stained_glass:15)
B(11,-19,11,betternether:quartz_stained_glass:15)
B(12,-19,11,betternether:quartz_stained_glass:15)
B(6,-19,12,betternether:quartz_stained_glass:15)
B(7,-19,12,betternether:quartz_stained_glass:15)
B(8,-19,12,betternether:quartz_stained_glass:15)
B(9,-19,12,betternether:quartz_stained_glass:15)
B(10,-19,12,betternether:quartz_stained_glass:15)
RB(11,-19,12,srparasites:parasitestain:1,80,quark:crystal:1,30,srparasites:parasiterubbledense:1,100)
B(12,-19,12,betternether:quartz_stained_glass:15)
B(13,-19,12,betternether:quartz_stained_glass:15)
B(7,-19,13,betternether:quartz_stained_glass:15)
B(8,-19,13,betternether:quartz_stained_glass:15)
RB(9,-19,13,srparasites:parasitestain:1,80,quark:crystal:1,30,srparasites:parasiterubbledense:1,100)
RB(10,-19,13,srparasites:parasitestain:1,80,quark:crystal:1,30,srparasites:parasiterubbledense:1,100)
RB(11,-19,13,srparasites:parasitestain:1,80,quark:crystal:1,30,srparasites:parasiterubbledense:1,100)
B(12,-19,13,betternether:quartz_stained_glass:15)
B(13,-19,13,betternether:quartz_stained_glass:15)
B(14,-19,13,betternether:quartz_stained_glass:15)
B(8,-19,14,betternether:quartz_stained_glass:15)
B(9,-19,14,betternether:quartz_stained_glass:15)
RB(10,-19,14,srparasites:parasitestain:1,80,quark:crystal:1,30,srparasites:parasiterubbledense:1,100)
RB(11,-19,14,srparasites:parasitestain:1,80,quark:crystal:1,30,srparasites:parasiterubbledense:1,100)
B(12,-19,14,betternether:quartz_stained_glass:15)
B(13,-19,14,betternether:quartz_stained_glass:15)
B(14,-19,14,betternether:quartz_stained_glass:15)
B(8,-19,15,betternether:quartz_stained_glass:15)
B(9,-19,15,betternether:quartz_stained_glass:15)
B(10,-19,15,betternether:quartz_stained_glass:15)
B(11,-19,15,betternether:quartz_stained_glass:15)
B(12,-19,15,betternether:quartz_stained_glass:15)
B(13,-19,15,betternether:quartz_stained_glass:15)
B(10,-18,7,betternether:quartz_stained_glass:15)
B(9,-18,8,betternether:quartz_stained_glass:15)
B(10,-18,8,betternether:quartz_stained_glass:15)
B(7,-18,9,betternether:quartz_stained_glass:15)
B(8,-18,9,betternether:quartz_stained_glass:15)
B(9,-18,9,betternether:quartz_stained_glass:15)
B(10,-18,9,betternether:quartz_stained_glass:15)
B(6,-18,10,betternether:quartz_stained_glass:15)
B(7,-18,10,betternether:quartz_stained_glass:15)
B(8,-18,10,betternether:quartz_stained_glass:15)
B(9,-18,10,betternether:quartz_stained_glass:15)
B(10,-18,10,betternether:quartz_stained_glass:15)
B(11,-18,10,betternether:quartz_stained_glass:15)
B(5,-18,11,betternether:quartz_stained_glass:15)
B(6,-18,11,betternether:quartz_stained_glass:15)
B(7,-18,11,betternether:quartz_stained_glass:15)
B(8,-18,11,betternether:quartz_stained_glass:15)
RB(9,-18,11,srparasites:parasitestain:1,80,quark:crystal:1,30,srparasites:parasiterubbledense:1,100)
B(10,-18,11,betternether:quartz_stained_glass:15)
B(11,-18,11,betternether:quartz_stained_glass:15)
B(12,-18,11,betternether:quartz_stained_glass:15)
B(6,-18,12,betternether:quartz_stained_glass:15)
B(7,-18,12,betternether:quartz_stained_glass:15)
B(8,-18,12,betternether:quartz_stained_glass:15)
RB(9,-18,12,srparasites:parasitestain:1,80,quark:crystal:1,30,srparasites:parasiterubbledense:1,100)
RB(10,-18,12,srparasites:parasitestain:1,80,quark:crystal:1,30,srparasites:parasiterubbledense:1,100)
RB(11,-18,12,srparasites:parasitestain:1,80,quark:crystal:1,30,srparasites:parasiterubbledense:1,100)
B(12,-18,12,betternether:quartz_stained_glass:15)
B(13,-18,12,betternether:quartz_stained_glass:15)
B(7,-18,13,betternether:quartz_stained_glass:15)
B(8,-18,13,betternether:quartz_stained_glass:15)
RB(9,-18,13,srparasites:parasitestain:1,80,quark:crystal:1,30,srparasites:parasiterubbledense:1,100)
RB(10,-18,13,srparasites:parasitestain:1,80,quark:crystal:1,30,srparasites:parasiterubbledense:1,100)
B(11,-18,13,betternether:quartz_stained_glass:15)
B(12,-18,13,betternether:quartz_stained_glass:15)
B(13,-18,13,betternether:quartz_stained_glass:15)
B(14,-18,13,betternether:quartz_stained_glass:15)
B(8,-18,14,betternether:quartz_stained_glass:15)
B(9,-18,14,betternether:quartz_stained_glass:15)
B(10,-18,14,betternether:quartz_stained_glass:15)
B(11,-18,14,betternether:quartz_stained_glass:15)
B(12,-18,14,betternether:quartz_stained_glass:15)
B(13,-18,14,betternether:quartz_stained_glass:15)
B(14,-18,14,betternether:quartz_stained_glass:15)
B(8,-18,15,betternether:quartz_stained_glass:15)
B(9,-18,15,betternether:quartz_stained_glass:15)
B(10,-18,15,betternether:quartz_stained_glass:15)
B(11,-18,15,betternether:quartz_stained_glass:15)
B(12,-18,15,betternether:quartz_stained_glass:15)
B(9,-17,7,betternether:quartz_stained_glass:15)
B(10,-17,7,betternether:quartz_stained_glass:15)
B(8,-17,8,betternether:quartz_stained_glass:15)
B(9,-17,8,betternether:quartz_stained_glass:15)
B(10,-17,8,betternether:quartz_stained_glass:15)
B(6,-17,9,betternether:quartz_stained_glass:15)
B(7,-17,9,betternether:quartz_stained_glass:15)
B(8,-17,9,betternether:quartz_stained_glass:15)
B(9,-17,9,betternether:quartz_stained_glass:15)
B(10,-17,9,betternether:quartz_stained_glass:15)
B(5,-17,10,betternether:quartz_stained_glass:15)
B(6,-17,10,betternether:quartz_stained_glass:15)
B(7,-17,10,betternether:quartz_stained_glass:15)
RB(8,-17,10,srparasites:parasitestain:1,80,quark:crystal:1,30,srparasites:parasiterubbledense:1,100)
B(9,-17,10,betternether:quartz_stained_glass:15)
B(10,-17,10,betternether:quartz_stained_glass:15)
B(11,-17,10,betternether:quartz_stained_glass:15)
B(5,-17,11,betternether:quartz_stained_glass:15)
B(6,-17,11,betternether:quartz_stained_glass:15)
B(7,-17,11,betternether:quartz_stained_glass:15)
B(8,-17,11,betternether:quartz_stained_glass:15)
RB(9,-17,11,srparasites:parasitestain:1,80,quark:crystal:1,30,srparasites:parasiterubbledense:1,100)
RB(10,-17,11,srparasites:parasitestain:1,80,quark:crystal:1,30,srparasites:parasiterubbledense:1,100)
B(11,-17,11,betternether:quartz_stained_glass:15)
B(12,-17,11,betternether:quartz_stained_glass:15)
B(6,-17,12,betternether:quartz_stained_glass:15)
B(7,-17,12,betternether:quartz_stained_glass:15)
RB(8,-17,12,srparasites:parasitestain:1,80,quark:crystal:1,30,srparasites:parasiterubbledense:1,100)
RB(9,-17,12,srparasites:parasitestain:1,80,quark:crystal:1,30,srparasites:parasiterubbledense:1,100)
RB(10,-17,12,srparasites:parasitestain:1,80,quark:crystal:1,30,srparasites:parasiterubbledense:1,100)
B(11,-17,12,betternether:quartz_stained_glass:15)
B(12,-17,12,betternether:quartz_stained_glass:15)
B(13,-17,12,betternether:quartz_stained_glass:15)
B(7,-17,13,betternether:quartz_stained_glass:15)
B(8,-17,13,betternether:quartz_stained_glass:15)
B(9,-17,13,betternether:quartz_stained_glass:15)
RB(10,-17,13,srparasites:parasitestain:1,80,quark:crystal:1,30,srparasites:parasiterubbledense:1,100)
B(11,-17,13,betternether:quartz_stained_glass:15)
B(12,-17,13,betternether:quartz_stained_glass:15)
B(13,-17,13,betternether:quartz_stained_glass:15)
B(8,-17,14,betternether:quartz_stained_glass:15)
B(9,-17,14,betternether:quartz_stained_glass:15)
B(10,-17,14,betternether:quartz_stained_glass:15)
B(11,-17,14,betternether:quartz_stained_glass:15)
B(12,-17,14,betternether:quartz_stained_glass:15)
B(13,-17,14,betternether:quartz_stained_glass:15)
B(8,-17,15,betternether:quartz_stained_glass:15)
B(9,-17,15,betternether:quartz_stained_glass:15)
B(10,-17,15,betternether:quartz_stained_glass:15)
B(11,-17,15,betternether:quartz_stained_glass:15)
B(9,-16,6,betternether:quartz_stained_glass:15)
B(8,-16,7,betternether:quartz_stained_glass:15)
B(9,-16,7,betternether:quartz_stained_glass:15)
B(10,-16,7,betternether:quartz_stained_glass:15)
B(7,-16,8,betternether:quartz_stained_glass:15)
B(8,-16,8,betternether:quartz_stained_glass:15)
B(9,-16,8,betternether:quartz_stained_glass:15)
B(10,-16,8,betternether:quartz_stained_glass:15)
B(4,-16,9,betternether:quartz_stained_glass:15)
B(5,-16,9,betternether:quartz_stained_glass:15)
B(6,-16,9,betternether:quartz_stained_glass:15)
B(7,-16,9,betternether:quartz_stained_glass:15)
B(8,-16,9,betternether:quartz_stained_glass:15)
B(9,-16,9,betternether:quartz_stained_glass:15)
B(10,-16,9,betternether:quartz_stained_glass:15)
B(5,-16,10,betternether:quartz_stained_glass:15)
B(6,-16,10,betternether:quartz_stained_glass:15)
B(7,-16,10,betternether:quartz_stained_glass:15)
RB(8,-16,10,srparasites:parasitestain:1,80,quark:crystal:1,30,srparasites:parasiterubbledense:1,100)
RB(9,-16,10,srparasites:parasitestain:1,80,quark:crystal:1,30,srparasites:parasiterubbledense:1,100)
B(10,-16,10,betternether:quartz_stained_glass:15)
B(11,-16,10,betternether:quartz_stained_glass:15)
B(5,-16,11,betternether:quartz_stained_glass:15)
B(6,-16,11,betternether:quartz_stained_glass:15)
B(7,-16,11,betternether:quartz_stained_glass:15)
RB(8,-16,11,srparasites:parasitestain:1,80,quark:crystal:1,30,srparasites:parasiterubbledense:1,100)
RB(9,-16,11,srparasites:parasitestain:1,80,quark:crystal:1,30,srparasites:parasiterubbledense:1,100)
RB(10,-16,11,srparasites:parasitestain:1,80,quark:crystal:1,30,srparasites:parasiterubbledense:1,100)
B(11,-16,11,betternether:quartz_stained_glass:15)
B(12,-16,11,betternether:quartz_stained_glass:15)
B(6,-16,12,betternether:quartz_stained_glass:15)
B(7,-16,12,betternether:quartz_stained_glass:15)
RB(8,-16,12,srparasites:parasitestain:1,80,quark:crystal:1,30,srparasites:parasiterubbledense:1,100)
B(9,-16,12,betternether:quartz_stained_glass:15)
B(10,-16,12,betternether:quartz_stained_glass:15)
B(11,-16,12,betternether:quartz_stained_glass:15)
B(12,-16,12,betternether:quartz_stained_glass:15)
B(13,-16,12,betternether:quartz_stained_glass:15)
B(7,-16,13,betternether:quartz_stained_glass:15)
B(8,-16,13,betternether:quartz_stained_glass:15)
B(9,-16,13,betternether:quartz_stained_glass:15)
B(10,-16,13,betternether:quartz_stained_glass:15)
B(11,-16,13,betternether:quartz_stained_glass:15)
B(12,-16,13,betternether:quartz_stained_glass:15)
B(13,-16,13,betternether:quartz_stained_glass:15)
B(8,-16,14,betternether:quartz_stained_glass:15)
B(9,-16,14,betternether:quartz_stained_glass:15)
B(10,-16,14,betternether:quartz_stained_glass:15)
B(11,-16,14,betternether:quartz_stained_glass:15)
B(12,-16,14,betternether:quartz_stained_glass:15)
B(8,-16,15,betternether:quartz_stained_glass:15)
B(9,-16,15,betternether:quartz_stained_glass:15)
B(10,-16,15,betternether:quartz_stained_glass:15)
B(8,-15,6,betternether:quartz_stained_glass:15)
B(9,-15,6,betternether:quartz_stained_glass:15)
B(7,-15,7,betternether:quartz_stained_glass:15)
B(8,-15,7,betternether:quartz_stained_glass:15)
B(9,-15,7,betternether:quartz_stained_glass:15)
B(10,-15,7,betternether:quartz_stained_glass:15)
B(6,-15,8,betternether:quartz_stained_glass:15)
B(7,-15,8,betternether:quartz_stained_glass:15)
B(8,-15,8,betternether:quartz_stained_glass:15)
B(9,-15,8,betternether:quartz_stained_glass:15)
B(10,-15,8,betternether:quartz_stained_glass:15)
B(4,-15,9,betternether:quartz_stained_glass:15)
B(5,-15,9,betternether:quartz_stained_glass:15)
B(6,-15,9,betternether:quartz_stained_glass:15)
RB(7,-15,9,srparasites:parasitestain:1,80,quark:crystal:1,30,srparasites:parasiterubbledense:1,100)
B(8,-15,9,betternether:quartz_stained_glass:15)
RB(9,-15,9,srparasites:parasitestain:1,80,quark:crystal:1,30,srparasites:parasiterubbledense:1,100)
B(10,-15,9,betternether:quartz_stained_glass:15)
B(5,-15,10,betternether:quartz_stained_glass:15)
B(6,-15,10,betternether:quartz_stained_glass:15)
B(7,-15,10,betternether:quartz_stained_glass:15)
RB(8,-15,10,srparasites:parasitestain:1,80,quark:crystal:1,30,srparasites:parasiterubbledense:1,100)
RB(9,-15,10,srparasites:parasitestain:1,80,quark:crystal:1,30,srparasites:parasiterubbledense:1,100)
B(10,-15,10,betternether:quartz_stained_glass:15)
B(11,-15,10,betternether:quartz_stained_glass:15)
B(5,-15,11,betternether:quartz_stained_glass:15)
B(6,-15,11,betternether:quartz_stained_glass:15)
RB(7,-15,11,srparasites:parasitestain:1,80,quark:crystal:1,30,srparasites:parasiterubbledense:1,100)
RB(8,-15,11,srparasites:parasitestain:1,80,quark:crystal:1,30,srparasites:parasiterubbledense:1,100)
RB(9,-15,11,srparasites:parasitestain:1,80,quark:crystal:1,30,srparasites:parasiterubbledense:1,100)
B(10,-15,11,betternether:quartz_stained_glass:15)
B(11,-15,11,betternether:quartz_stained_glass:15)
B(12,-15,11,betternether:quartz_stained_glass:15)
B(6,-15,12,betternether:quartz_stained_glass:15)
B(7,-15,12,betternether:quartz_stained_glass:15)
B(8,-15,12,betternether:quartz_stained_glass:15)
B(9,-15,12,betternether:quartz_stained_glass:15)
B(10,-15,12,betternether:quartz_stained_glass:15)
B(11,-15,12,betternether:quartz_stained_glass:15)
B(12,-15,12,betternether:quartz_stained_glass:15)
B(7,-15,13,betternether:quartz_stained_glass:15)
B(8,-15,13,betternether:quartz_stained_glass:15)
B(9,-15,13,betternether:quartz_stained_glass:15)
B(10,-15,13,betternether:quartz_stained_glass:15)
B(11,-15,13,betternether:quartz_stained_glass:15)
B(12,-15,13,betternether:quartz_stained_glass:15)
B(8,-15,14,betternether:quartz_stained_glass:15)
B(9,-15,14,betternether:quartz_stained_glass:15)
B(10,-15,14,betternether:quartz_stained_glass:15)
B(11,-15,14,betternether:quartz_stained_glass:15)
B(8,-14,5,betternether:quartz_stained_glass:15)
B(7,-14,6,betternether:quartz_stained_glass:15)
B(8,-14,6,betternether:quartz_stained_glass:15)
B(9,-14,6,betternether:quartz_stained_glass:15)
B(6,-14,7,betternether:quartz_stained_glass:15)
B(7,-14,7,betternether:quartz_stained_glass:15)
B(8,-14,7,betternether:quartz_stained_glass:15)
B(9,-14,7,betternether:quartz_stained_glass:15)
B(10,-14,7,betternether:quartz_stained_glass:15)
B(4,-14,8,betternether:quartz_stained_glass:15)
B(5,-14,8,betternether:quartz_stained_glass:15)
B(6,-14,8,betternether:quartz_stained_glass:15)
B(7,-14,8,betternether:quartz_stained_glass:15)
B(8,-14,8,betternether:quartz_stained_glass:15)
B(9,-14,8,betternether:quartz_stained_glass:15)
B(10,-14,8,betternether:quartz_stained_glass:15)
B(4,-14,9,betternether:quartz_stained_glass:15)
B(5,-14,9,betternether:quartz_stained_glass:15)
B(6,-14,9,betternether:quartz_stained_glass:15)
RB(7,-14,9,srparasites:parasitestain:1,80,quark:crystal:1,30,srparasites:parasiterubbledense:1,100)
RB(8,-14,9,srparasites:parasitestain:1,80,quark:crystal:1,30,srparasites:parasiterubbledense:1,100)
RB(9,-14,9,srparasites:parasitestain:1,80,quark:crystal:1,30,srparasites:parasiterubbledense:1,100)
B(10,-14,9,betternether:quartz_stained_glass:15)
B(5,-14,10,betternether:quartz_stained_glass:15)
B(6,-14,10,betternether:quartz_stained_glass:15)
RB(7,-14,10,srparasites:parasitestain:1,80,quark:crystal:1,30,srparasites:parasiterubbledense:1,100)
RB(8,-14,10,srparasites:parasitestain:1,80,quark:crystal:1,30,srparasites:parasiterubbledense:1,100)
B(9,-14,10,betternether:quartz_stained_glass:15)
B(10,-14,10,betternether:quartz_stained_glass:15)
B(11,-14,10,betternether:quartz_stained_glass:15)
B(5,-14,11,betternether:quartz_stained_glass:15)
B(6,-14,11,betternether:quartz_stained_glass:15)
RB(7,-14,11,srparasites:parasitestain:1,80,quark:crystal:1,30,srparasites:parasiterubbledense:1,100)
B(8,-14,11,betternether:quartz_stained_glass:15)
B(9,-14,11,betternether:quartz_stained_glass:15)
B(10,-14,11,betternether:quartz_stained_glass:15)
B(11,-14,11,betternether:quartz_stained_glass:15)
B(12,-14,11,betternether:quartz_stained_glass:15)
B(6,-14,12,betternether:quartz_stained_glass:15)
B(7,-14,12,betternether:quartz_stained_glass:15)
B(8,-14,12,betternether:quartz_stained_glass:15)
B(9,-14,12,betternether:quartz_stained_glass:15)
B(10,-14,12,betternether:quartz_stained_glass:15)
B(11,-14,12,betternether:quartz_stained_glass:15)
B(12,-14,12,betternether:quartz_stained_glass:15)
B(7,-14,13,betternether:quartz_stained_glass:15)
B(8,-14,13,betternether:quartz_stained_glass:15)
B(9,-14,13,betternether:quartz_stained_glass:15)
B(10,-14,13,betternether:quartz_stained_glass:15)
B(11,-14,13,betternether:quartz_stained_glass:15)
B(8,-14,14,betternether:quartz_stained_glass:15)
B(9,-14,14,betternether:quartz_stained_glass:15)
B(10,-14,14,betternether:quartz_stained_glass:15)
B(7,-13,5,betternether:quartz_stained_glass:15)
B(8,-13,5,betternether:quartz_stained_glass:15)
B(6,-13,6,betternether:quartz_stained_glass:15)
B(7,-13,6,betternether:quartz_stained_glass:15)
B(8,-13,6,betternether:quartz_stained_glass:15)
B(9,-13,6,betternether:quartz_stained_glass:15)
B(4,-13,7,betternether:quartz_stained_glass:15)
B(5,-13,7,betternether:quartz_stained_glass:15)
B(6,-13,7,betternether:quartz_stained_glass:15)
B(7,-13,7,betternether:quartz_stained_glass:15)
B(8,-13,7,betternether:quartz_stained_glass:15)
B(9,-13,7,betternether:quartz_stained_glass:15)
B(10,-13,7,betternether:quartz_stained_glass:15)
B(4,-13,8,betternether:quartz_stained_glass:15)
B(5,-13,8,betternether:quartz_stained_glass:15)
B(6,-13,8,betternether:quartz_stained_glass:15)
RB(7,-13,8,srparasites:parasitestain:1,80,quark:crystal:1,30,srparasites:parasiterubbledense:1,100)
B(8,-13,8,betternether:quartz_stained_glass:15)
RB(9,-13,8,srparasites:parasitestain:1,80,quark:crystal:1,30,srparasites:parasiterubbledense:1,100)
B(10,-13,8,betternether:quartz_stained_glass:15)
B(4,-13,9,betternether:quartz_stained_glass:15)
B(5,-13,9,betternether:quartz_stained_glass:15)
B(6,-13,9,betternether:quartz_stained_glass:15)
RB(7,-13,9,srparasites:parasitestain:1,80,quark:crystal:1,30,srparasites:parasiterubbledense:1,100)
RB(8,-13,9,srparasites:parasitestain:1,80,quark:crystal:1,30,srparasites:parasiterubbledense:1,100)
B(9,-13,9,betternether:quartz_stained_glass:15)
B(10,-13,9,betternether:quartz_stained_glass:15)
B(5,-13,10,betternether:quartz_stained_glass:15)
RB(6,-13,10,srparasites:parasitestain:1,80,quark:crystal:1,30,srparasites:parasiterubbledense:1,100)
RB(7,-13,10,srparasites:parasitestain:1,80,quark:crystal:1,30,srparasites:parasiterubbledense:1,100)
RB(8,-13,10,srparasites:parasitestain:1,80,quark:crystal:1,30,srparasites:parasiterubbledense:1,100)
B(9,-13,10,betternether:quartz_stained_glass:15)
B(10,-13,10,betternether:quartz_stained_glass:15)
B(11,-13,10,betternether:quartz_stained_glass:15)
B(5,-13,11,betternether:quartz_stained_glass:15)
B(6,-13,11,betternether:quartz_stained_glass:15)
B(7,-13,11,betternether:quartz_stained_glass:15)
B(8,-13,11,betternether:quartz_stained_glass:15)
B(9,-13,11,betternether:quartz_stained_glass:15)
B(10,-13,11,betternether:quartz_stained_glass:15)
B(11,-13,11,betternether:quartz_stained_glass:15)
B(6,-13,12,betternether:quartz_stained_glass:15)
B(7,-13,12,betternether:quartz_stained_glass:15)
B(8,-13,12,betternether:quartz_stained_glass:15)
B(9,-13,12,betternether:quartz_stained_glass:15)
B(10,-13,12,betternether:quartz_stained_glass:15)
B(11,-13,12,betternether:quartz_stained_glass:15)
B(7,-13,13,betternether:quartz_stained_glass:15)
B(8,-13,13,betternether:quartz_stained_glass:15)
B(9,-13,13,betternether:quartz_stained_glass:15)
B(10,-13,13,betternether:quartz_stained_glass:15)
B(7,-12,4,betternether:quartz_stained_glass:15)
B(6,-12,5,betternether:quartz_stained_glass:15)
B(7,-12,5,betternether:quartz_stained_glass:15)
B(8,-12,5,betternether:quartz_stained_glass:15)
B(4,-12,6,betternether:quartz_stained_glass:15)
B(5,-12,6,betternether:quartz_stained_glass:15)
B(6,-12,6,betternether:quartz_stained_glass:15)
B(7,-12,6,betternether:quartz_stained_glass:15)
B(8,-12,6,betternether:quartz_stained_glass:15)
B(9,-12,6,betternether:quartz_stained_glass:15)
B(3,-12,7,betternether:quartz_stained_glass:15)
B(4,-12,7,betternether:quartz_stained_glass:15)
B(5,-12,7,betternether:quartz_stained_glass:15)
B(6,-12,7,betternether:quartz_stained_glass:15)
B(7,-12,7,betternether:quartz_stained_glass:15)
B(8,-12,7,betternether:quartz_stained_glass:15)
B(9,-12,7,betternether:quartz_stained_glass:15)
B(10,-12,7,betternether:quartz_stained_glass:15)
B(4,-12,8,betternether:quartz_stained_glass:15)
B(5,-12,8,betternether:quartz_stained_glass:15)
B(6,-12,8,betternether:quartz_stained_glass:15)
RB(7,-12,8,srparasites:parasitestain:1,80,quark:crystal:1,30,srparasites:parasiterubbledense:1,100)
RB(8,-12,8,srparasites:parasitestain:1,80,quark:crystal:1,30,srparasites:parasiterubbledense:1,100)
RB(9,-12,8,srparasites:parasitestain:1,80,quark:crystal:1,30,srparasites:parasiterubbledense:1,100)
B(10,-12,8,betternether:quartz_stained_glass:15)
B(4,-12,9,betternether:quartz_stained_glass:15)
B(5,-12,9,betternether:quartz_stained_glass:15)
RB(6,-12,9,srparasites:parasitestain:1,80,quark:crystal:1,30,srparasites:parasiterubbledense:1,100)
RB(7,-12,9,srparasites:parasitestain:1,80,quark:crystal:1,30,srparasites:parasiterubbledense:1,100)
B(8,-12,9,betternether:quartz_stained_glass:15)
B(9,-12,9,betternether:quartz_stained_glass:15)
B(10,-12,9,betternether:quartz_stained_glass:15)
B(5,-12,10,betternether:quartz_stained_glass:15)
RB(6,-12,10,srparasites:parasitestain:1,80,quark:crystal:1,30,srparasites:parasiterubbledense:1,100)
B(7,-12,10,betternether:quartz_stained_glass:15)
B(8,-12,10,betternether:quartz_stained_glass:15)
B(9,-12,10,betternether:quartz_stained_glass:15)
B(10,-12,10,betternether:quartz_stained_glass:15)
B(11,-12,10,betternether:quartz_stained_glass:15)
B(5,-12,11,betternether:quartz_stained_glass:15)
B(6,-12,11,betternether:quartz_stained_glass:15)
B(7,-12,11,betternether:quartz_stained_glass:15)
B(8,-12,11,betternether:quartz_stained_glass:15)
B(9,-12,11,betternether:quartz_stained_glass:15)
B(10,-12,11,betternether:quartz_stained_glass:15)
B(11,-12,11,betternether:quartz_stained_glass:15)
B(6,-12,12,betternether:quartz_stained_glass:15)
B(7,-12,12,betternether:quartz_stained_glass:15)
B(8,-12,12,betternether:quartz_stained_glass:15)
B(9,-12,12,betternether:quartz_stained_glass:15)
B(10,-12,12,betternether:quartz_stained_glass:15)
B(7,-12,13,betternether:quartz_stained_glass:15)
B(8,-12,13,betternether:quartz_stained_glass:15)
B(6,-11,4,betternether:quartz_stained_glass:15)
B(7,-11,4,betternether:quartz_stained_glass:15)
B(4,-11,5,betternether:quartz_stained_glass:15)
B(5,-11,5,betternether:quartz_stained_glass:15)
B(6,-11,5,betternether:quartz_stained_glass:15)
B(7,-11,5,betternether:quartz_stained_glass:15)
B(8,-11,5,betternether:quartz_stained_glass:15)
B(3,-11,6,betternether:quartz_stained_glass:15)
B(4,-11,6,betternether:quartz_stained_glass:15)
B(5,-11,6,betternether:quartz_stained_glass:15)
B(6,-11,6,betternether:quartz_stained_glass:15)
B(7,-11,6,betternether:quartz_stained_glass:15)
B(8,-11,6,betternether:quartz_stained_glass:15)
B(9,-11,6,betternether:quartz_stained_glass:15)
B(3,-11,7,betternether:quartz_stained_glass:15)
B(4,-11,7,betternether:quartz_stained_glass:15)
B(5,-11,7,betternether:quartz_stained_glass:15)
RB(6,-11,7,srparasites:parasitestain:1,80,quark:crystal:1,30,srparasites:parasiterubbledense:1,100)
B(7,-11,7,betternether:quartz_stained_glass:15)
RB(8,-11,7,srparasites:parasitestain:1,80,quark:crystal:1,30,srparasites:parasiterubbledense:1,100)
B(9,-11,7,betternether:quartz_stained_glass:15)
B(10,-11,7,betternether:quartz_stained_glass:15)
B(4,-11,8,betternether:quartz_stained_glass:15)
B(5,-11,8,betternether:quartz_stained_glass:15)
B(6,-11,8,betternether:quartz_stained_glass:15)
RB(7,-11,8,srparasites:parasitestain:1,80,quark:crystal:1,30,srparasites:parasiterubbledense:1,100)
RB(8,-11,8,srparasites:parasitestain:1,80,quark:crystal:1,30,srparasites:parasiterubbledense:1,100)
B(9,-11,8,betternether:quartz_stained_glass:15)
B(10,-11,8,betternether:quartz_stained_glass:15)
B(4,-11,9,betternether:quartz_stained_glass:15)
RB(5,-11,9,srparasites:parasitestain:1,80,quark:crystal:1,30,srparasites:parasiterubbledense:1,100)
RB(6,-11,9,srparasites:parasitestain:1,80,quark:crystal:1,30,srparasites:parasiterubbledense:1,100)
RB(7,-11,9,srparasites:parasitestain:1,80,quark:crystal:1,30,srparasites:parasiterubbledense:1,100)
B(8,-11,9,betternether:quartz_stained_glass:15)
B(9,-11,9,betternether:quartz_stained_glass:15)
B(10,-11,9,betternether:quartz_stained_glass:15)
B(5,-11,10,betternether:quartz_stained_glass:15)
B(6,-11,10,betternether:quartz_stained_glass:15)
B(7,-11,10,betternether:quartz_stained_glass:15)
B(8,-11,10,betternether:quartz_stained_glass:15)
B(9,-11,10,betternether:quartz_stained_glass:15)
B(10,-11,10,betternether:quartz_stained_glass:15)
B(5,-11,11,betternether:quartz_stained_glass:15)
B(6,-11,11,betternether:quartz_stained_glass:15)
B(7,-11,11,betternether:quartz_stained_glass:15)
B(8,-11,11,betternether:quartz_stained_glass:15)
B(9,-11,11,betternether:quartz_stained_glass:15)
B(10,-11,11,betternether:quartz_stained_glass:15)
B(6,-11,12,betternether:quartz_stained_glass:15)
B(7,-11,12,betternether:quartz_stained_glass:15)
B(8,-11,12,betternether:quartz_stained_glass:15)
B(6,-10,3,betternether:quartz_stained_glass:15)
B(4,-10,4,betternether:quartz_stained_glass:15)
B(5,-10,4,betternether:quartz_stained_glass:15)
B(6,-10,4,betternether:quartz_stained_glass:15)
B(7,-10,4,betternether:quartz_stained_glass:15)
B(3,-10,5,betternether:quartz_stained_glass:15)
B(4,-10,5,betternether:quartz_stained_glass:15)
B(5,-10,5,betternether:quartz_stained_glass:15)
B(6,-10,5,betternether:quartz_stained_glass:15)
B(7,-10,5,betternether:quartz_stained_glass:15)
B(8,-10,5,betternether:quartz_stained_glass:15)
B(2,-10,6,betternether:quartz_stained_glass:15)
B(3,-10,6,betternether:quartz_stained_glass:15)
B(4,-10,6,betternether:quartz_stained_glass:15)
B(5,-10,6,betternether:quartz_stained_glass:15)
B(6,-10,6,betternether:quartz_stained_glass:15)
B(7,-10,6,betternether:quartz_stained_glass:15)
B(8,-10,6,betternether:quartz_stained_glass:15)
B(9,-10,6,betternether:quartz_stained_glass:15)
B(3,-10,7,betternether:quartz_stained_glass:15)
B(4,-10,7,betternether:quartz_stained_glass:15)
B(5,-10,7,betternether:quartz_stained_glass:15)
RB(6,-10,7,srparasites:parasitestain:1,80,quark:crystal:1,30,srparasites:parasiterubbledense:1,100)
RB(7,-10,7,srparasites:parasitestain:1,80,quark:crystal:1,30,srparasites:parasiterubbledense:1,100)
RB(8,-10,7,srparasites:parasitestain:1,80,quark:crystal:1,30,srparasites:parasiterubbledense:1,100)
B(9,-10,7,betternether:quartz_stained_glass:15)
B(10,-10,7,betternether:quartz_stained_glass:15)
B(4,-10,8,betternether:quartz_stained_glass:15)
B(5,-10,8,betternether:quartz_stained_glass:15)
RB(6,-10,8,srparasites:parasitestain:1,80,quark:crystal:1,30,srparasites:parasiterubbledense:1,100)
RB(7,-10,8,srparasites:parasitestain:1,80,quark:crystal:1,30,srparasites:parasiterubbledense:1,100)
B(8,-10,8,betternether:quartz_stained_glass:15)
B(9,-10,8,betternether:quartz_stained_glass:15)
B(10,-10,8,betternether:quartz_stained_glass:15)
B(4,-10,9,betternether:quartz_stained_glass:15)
RB(5,-10,9,srparasites:parasitestain:1,80,quark:crystal:1,30,srparasites:parasiterubbledense:1,100)
B(6,-10,9,betternether:quartz_stained_glass:15)
RB(7,-10,9,srparasites:parasitestain:1,80,quark:crystal:1,30,srparasites:parasiterubbledense:1,100)
B(8,-10,9,betternether:quartz_stained_glass:15)
B(9,-10,9,betternether:quartz_stained_glass:15)
B(10,-10,9,betternether:quartz_stained_glass:15)
B(5,-10,10,betternether:quartz_stained_glass:15)
B(6,-10,10,betternether:quartz_stained_glass:15)
B(7,-10,10,betternether:quartz_stained_glass:15)
B(8,-10,10,betternether:quartz_stained_glass:15)
B(9,-10,10,betternether:quartz_stained_glass:15)
B(10,-10,10,betternether:quartz_stained_glass:15)
B(5,-10,11,betternether:quartz_stained_glass:15)
B(6,-10,11,betternether:quartz_stained_glass:15)
B(7,-10,11,betternether:quartz_stained_glass:15)
B(8,-10,11,betternether:quartz_stained_glass:15)
B(6,-10,12,betternether:quartz_stained_glass:15)
B(7,-10,12,betternether:quartz_stained_glass:15)
B(4,-9,3,betternether:quartz_stained_glass:15)
B(5,-9,3,betternether:quartz_stained_glass:15)
B(6,-9,3,betternether:quartz_stained_glass:15)
B(3,-9,4,betternether:quartz_stained_glass:15)
B(4,-9,4,betternether:quartz_stained_glass:15)
B(5,-9,4,betternether:quartz_stained_glass:15)
B(6,-9,4,betternether:quartz_stained_glass:15)
B(7,-9,4,betternether:quartz_stained_glass:15)
B(2,-9,5,betternether:quartz_stained_glass:15)
B(3,-9,5,betternether:quartz_stained_glass:15)
B(4,-9,5,betternether:quartz_stained_glass:15)
B(5,-9,5,betternether:quartz_stained_glass:15)
B(6,-9,5,betternether:quartz_stained_glass:15)
B(7,-9,5,betternether:quartz_stained_glass:15)
B(8,-9,5,betternether:quartz_stained_glass:15)
B(2,-9,6,betternether:quartz_stained_glass:15)
B(3,-9,6,betternether:quartz_stained_glass:15)
B(4,-9,6,betternether:quartz_stained_glass:15)
RB(5,-9,6,srparasites:parasitestain:1,80,quark:crystal:1,30,srparasites:parasiterubbledense:1,100)
B(6,-9,6,betternether:quartz_stained_glass:15)
RB(7,-9,6,srparasites:parasitestain:1,80,quark:crystal:1,30,srparasites:parasiterubbledense:1,100)
B(8,-9,6,betternether:quartz_stained_glass:15)
B(9,-9,6,betternether:quartz_stained_glass:15)
B(3,-9,7,betternether:quartz_stained_glass:15)
B(4,-9,7,betternether:quartz_stained_glass:15)
B(5,-9,7,betternether:quartz_stained_glass:15)
RB(6,-9,7,srparasites:parasitestain:1,80,quark:crystal:1,30,srparasites:parasiterubbledense:1,100)
RB(7,-9,7,srparasites:parasitestain:1,80,quark:crystal:1,30,srparasites:parasiterubbledense:1,100)
B(8,-9,7,betternether:quartz_stained_glass:15)
B(9,-9,7,betternether:quartz_stained_glass:15)
B(10,-9,7,betternether:quartz_stained_glass:15)
B(4,-9,8,betternether:quartz_stained_glass:15)
RB(5,-9,8,srparasites:parasitestain:1,80,quark:crystal:1,30,srparasites:parasiterubbledense:1,100)
RB(6,-9,8,srparasites:parasitestain:1,80,quark:crystal:1,30,srparasites:parasiterubbledense:1,100)
RB(7,-9,8,srparasites:parasitestain:1,80,quark:crystal:1,30,srparasites:parasiterubbledense:1,100)
B(8,-9,8,betternether:quartz_stained_glass:15)
B(9,-9,8,betternether:quartz_stained_glass:15)
B(10,-9,8,betternether:quartz_stained_glass:15)
B(4,-9,9,betternether:quartz_stained_glass:15)
B(5,-9,9,betternether:quartz_stained_glass:15)
B(6,-9,9,betternether:quartz_stained_glass:15)
B(7,-9,9,betternether:quartz_stained_glass:15)
B(8,-9,9,betternether:quartz_stained_glass:15)
B(9,-9,9,betternether:quartz_stained_glass:15)
B(5,-9,10,betternether:quartz_stained_glass:15)
B(6,-9,10,betternether:quartz_stained_glass:15)
B(7,-9,10,betternether:quartz_stained_glass:15)
B(8,-9,10,betternether:quartz_stained_glass:15)
B(5,-9,11,betternether:quartz_stained_glass:15)
B(6,-9,11,betternether:quartz_stained_glass:15)
B(7,-9,11,betternether:quartz_stained_glass:15)
B(6,-8,2,betternether:quartz_stained_glass:15)
B(3,-8,3,betternether:quartz_stained_glass:15)
B(4,-8,3,betternether:quartz_stained_glass:15)
B(5,-8,3,betternether:quartz_stained_glass:15)
B(6,-8,3,betternether:quartz_stained_glass:15)
B(2,-8,4,betternether:quartz_stained_glass:15)
B(3,-8,4,betternether:quartz_stained_glass:15)
B(4,-8,4,betternether:quartz_stained_glass:15)
B(5,-8,4,betternether:quartz_stained_glass:15)
B(6,-8,4,betternether:quartz_stained_glass:15)
B(7,-8,4,betternether:quartz_stained_glass:15)
B(1,-8,5,betternether:quartz_stained_glass:15)
B(2,-8,5,betternether:quartz_stained_glass:15)
B(3,-8,5,betternether:quartz_stained_glass:15)
B(4,-8,5,betternether:quartz_stained_glass:15)
B(5,-8,5,betternether:quartz_stained_glass:15)
B(6,-8,5,betternether:quartz_stained_glass:15)
B(7,-8,5,betternether:quartz_stained_glass:15)
B(8,-8,5,betternether:quartz_stained_glass:15)
B(2,-8,6,betternether:quartz_stained_glass:15)
B(3,-8,6,betternether:quartz_stained_glass:15)
B(4,-8,6,betternether:quartz_stained_glass:15)
RB(5,-8,6,srparasites:parasitestain:1,80,quark:crystal:1,30,srparasites:parasiterubbledense:1,100)
RB(6,-8,6,srparasites:parasitestain:1,80,quark:crystal:1,30,srparasites:parasiterubbledense:1,100)
RB(7,-8,6,srparasites:parasitestain:1,80,quark:crystal:1,30,srparasites:parasiterubbledense:1,100)
B(8,-8,6,betternether:quartz_stained_glass:15)
B(9,-8,6,betternether:quartz_stained_glass:15)
B(3,-8,7,betternether:quartz_stained_glass:15)
B(4,-8,7,betternether:quartz_stained_glass:15)
RB(5,-8,7,srparasites:parasitestain:1,80,quark:crystal:1,30,srparasites:parasiterubbledense:1,100)
RB(6,-8,7,srparasites:parasitestain:1,80,quark:crystal:1,30,srparasites:parasiterubbledense:1,100)
B(7,-8,7,betternether:quartz_stained_glass:15)
B(8,-8,7,betternether:quartz_stained_glass:15)
B(9,-8,7,betternether:quartz_stained_glass:15)
B(10,-8,7,betternether:quartz_stained_glass:15)
B(4,-8,8,betternether:quartz_stained_glass:15)
RB(5,-8,8,srparasites:parasitestain:1,80,quark:crystal:1,30,srparasites:parasiterubbledense:1,100)
B(6,-8,8,betternether:quartz_stained_glass:15)
RB(7,-8,8,srparasites:parasitestain:1,80,quark:crystal:1,30,srparasites:parasiterubbledense:1,100)
B(8,-8,8,betternether:quartz_stained_glass:15)
B(9,-8,8,betternether:quartz_stained_glass:15)
B(10,-8,8,betternether:quartz_stained_glass:15)
B(4,-8,9,betternether:quartz_stained_glass:15)
B(5,-8,9,betternether:quartz_stained_glass:15)
B(6,-8,9,betternether:quartz_stained_glass:15)
B(7,-8,9,betternether:quartz_stained_glass:15)
B(8,-8,9,betternether:quartz_stained_glass:15)
B(5,-8,10,betternether:quartz_stained_glass:15)
B(6,-8,10,betternether:quartz_stained_glass:15)
B(7,-8,10,betternether:quartz_stained_glass:15)
B(5,-8,11,betternether:quartz_stained_glass:15)
B(6,-8,11,betternether:quartz_stained_glass:15)
B(4,-7,2,betternether:quartz_stained_glass:15)
B(5,-7,2,betternether:quartz_stained_glass:15)
B(6,-7,2,betternether:quartz_stained_glass:15)
B(2,-7,3,betternether:quartz_stained_glass:15)
B(3,-7,3,betternether:quartz_stained_glass:15)
B(4,-7,3,betternether:quartz_stained_glass:15)
B(5,-7,3,betternether:quartz_stained_glass:15)
B(6,-7,3,betternether:quartz_stained_glass:15)
B(1,-7,4,betternether:quartz_stained_glass:15)
B(2,-7,4,betternether:quartz_stained_glass:15)
B(3,-7,4,betternether:quartz_stained_glass:15)
RB(4,-7,4,srparasites:parasitestain:1,80,quark:crystal:1,30,srparasites:parasiterubbledense:1,100)
B(5,-7,4,betternether:quartz_stained_glass:15)
B(6,-7,4,betternether:quartz_stained_glass:15)
B(7,-7,4,betternether:quartz_stained_glass:15)
B(1,-7,5,betternether:quartz_stained_glass:15)
B(2,-7,5,betternether:quartz_stained_glass:15)
B(3,-7,5,betternether:quartz_stained_glass:15)
B(4,-7,5,betternether:quartz_stained_glass:15)
B(5,-7,5,betternether:quartz_stained_glass:15)
RB(6,-7,5,srparasites:parasitestain:1,80,quark:crystal:1,30,srparasites:parasiterubbledense:1,100)
B(7,-7,5,betternether:quartz_stained_glass:15)
B(8,-7,5,betternether:quartz_stained_glass:15)
B(2,-7,6,betternether:quartz_stained_glass:15)
B(3,-7,6,betternether:quartz_stained_glass:15)
RB(4,-7,6,srparasites:parasitestain:1,80,quark:crystal:1,30,srparasites:parasiterubbledense:1,100)
RB(5,-7,6,srparasites:parasitestain:1,80,quark:crystal:1,30,srparasites:parasiterubbledense:1,100)
RB(6,-7,6,srparasites:parasitestain:1,80,quark:crystal:1,30,srparasites:parasiterubbledense:1,100)
B(7,-7,6,betternether:quartz_stained_glass:15)
B(8,-7,6,betternether:quartz_stained_glass:15)
B(9,-7,6,betternether:quartz_stained_glass:15)
B(3,-7,7,betternether:quartz_stained_glass:15)
B(4,-7,7,betternether:quartz_stained_glass:15)
RB(5,-7,7,srparasites:parasitestain:1,80,quark:crystal:1,30,srparasites:parasiterubbledense:1,100)
RB(6,-7,7,srparasites:parasitestain:1,80,quark:crystal:1,30,srparasites:parasiterubbledense:1,100)
B(7,-7,7,betternether:quartz_stained_glass:15)
B(8,-7,7,betternether:quartz_stained_glass:15)
B(9,-7,7,betternether:quartz_stained_glass:15)
B(4,-7,8,betternether:quartz_stained_glass:15)
B(5,-7,8,betternether:quartz_stained_glass:15)
B(6,-7,8,betternether:quartz_stained_glass:15)
B(7,-7,8,betternether:quartz_stained_glass:15)
B(8,-7,8,betternether:quartz_stained_glass:15)
B(9,-7,8,betternether:quartz_stained_glass:15)
B(4,-7,9,betternether:quartz_stained_glass:15)
B(5,-7,9,betternether:quartz_stained_glass:15)
B(6,-7,9,betternether:quartz_stained_glass:15)
B(7,-7,9,betternether:quartz_stained_glass:15)
B(5,-7,10,betternether:quartz_stained_glass:15)
B(6,-7,10,betternether:quartz_stained_glass:15)
B(5,-6,0,betternether:quartz_stained_glass:15)
B(4,-6,1,betternether:quartz_stained_glass:15)
B(5,-6,1,betternether:quartz_stained_glass:15)
B(3,-6,2,betternether:quartz_stained_glass:15)
B(4,-6,2,betternether:quartz_stained_glass:15)
B(5,-6,2,betternether:quartz_stained_glass:15)
B(6,-6,2,betternether:quartz_stained_glass:15)
B(1,-6,3,betternether:quartz_stained_glass:15)
B(2,-6,3,betternether:quartz_stained_glass:15)
B(3,-6,3,betternether:quartz_stained_glass:15)
B(4,-6,3,betternether:quartz_stained_glass:15)
B(5,-6,3,betternether:quartz_stained_glass:15)
B(6,-6,3,betternether:quartz_stained_glass:15)
B(0,-6,4,betternether:quartz_stained_glass:15)
B(1,-6,4,betternether:quartz_stained_glass:15)
B(2,-6,4,betternether:quartz_stained_glass:15)
B(3,-6,4,betternether:quartz_stained_glass:15)
RB(4,-6,4,srparasites:parasitestain:1,80,quark:crystal:1,30,srparasites:parasiterubbledense:1,100)
B(5,-6,4,betternether:quartz_stained_glass:15)
B(6,-6,4,betternether:quartz_stained_glass:15)
B(7,-6,4,betternether:quartz_stained_glass:15)
B(1,-6,5,betternether:quartz_stained_glass:15)
B(2,-6,5,betternether:quartz_stained_glass:15)
B(3,-6,5,betternether:quartz_stained_glass:15)
RB(4,-6,5,srparasites:parasitestain:1,80,quark:crystal:1,30,srparasites:parasiterubbledense:1,100)
RB(5,-6,5,srparasites:parasitestain:1,80,quark:crystal:1,30,srparasites:parasiterubbledense:1,100)
RB(6,-6,5,srparasites:parasitestain:1,80,quark:crystal:1,30,srparasites:parasiterubbledense:1,100)
B(7,-6,5,betternether:quartz_stained_glass:15)
B(8,-6,5,betternether:quartz_stained_glass:15)
B(2,-6,6,betternether:quartz_stained_glass:15)
B(3,-6,6,betternether:quartz_stained_glass:15)
RB(4,-6,6,srparasites:parasitestain:1,80,quark:crystal:1,30,srparasites:parasiterubbledense:1,100)
RB(5,-6,6,srparasites:parasitestain:1,80,quark:crystal:1,30,srparasites:parasiterubbledense:1,100)
B(6,-6,6,betternether:quartz_stained_glass:15)
B(7,-6,6,betternether:quartz_stained_glass:15)
B(8,-6,6,betternether:quartz_stained_glass:15)
B(9,-6,6,betternether:quartz_stained_glass:15)
B(3,-6,7,betternether:quartz_stained_glass:15)
B(4,-6,7,betternether:quartz_stained_glass:15)
B(5,-6,7,betternether:quartz_stained_glass:15)
RB(6,-6,7,srparasites:parasitestain:1,80,quark:crystal:1,30,srparasites:parasiterubbledense:1,100)
B(7,-6,7,betternether:quartz_stained_glass:15)
B(8,-6,7,betternether:quartz_stained_glass:15)
B(9,-6,7,betternether:quartz_stained_glass:15)
B(4,-6,8,betternether:quartz_stained_glass:15)
B(5,-6,8,betternether:quartz_stained_glass:15)
B(6,-6,8,betternether:quartz_stained_glass:15)
B(7,-6,8,betternether:quartz_stained_glass:15)
B(8,-6,8,betternether:quartz_stained_glass:15)
B(4,-6,9,betternether:quartz_stained_glass:15)
B(5,-6,9,betternether:quartz_stained_glass:15)
B(6,-6,9,betternether:quartz_stained_glass:15)
B(5,-6,10,betternether:quartz_stained_glass:15)
B(4,-5,0,betternether:quartz_stained_glass:15)
B(5,-5,0,betternether:quartz_stained_glass:15)
B(3,-5,1,betternether:quartz_stained_glass:15)
B(4,-5,1,betternether:quartz_stained_glass:15)
B(5,-5,1,betternether:quartz_stained_glass:15)
B(2,-5,2,betternether:quartz_stained_glass:15)
B(3,-5,2,betternether:quartz_stained_glass:15)
B(4,-5,2,betternether:quartz_stained_glass:15)
B(5,-5,2,betternether:quartz_stained_glass:15)
B(6,-5,2,betternether:quartz_stained_glass:15)
B(0,-5,3,betternether:quartz_stained_glass:15)
B(1,-5,3,betternether:quartz_stained_glass:15)
B(2,-5,3,betternether:quartz_stained_glass:15)
RB(3,-5,3,srparasites:parasitestain:1,80,quark:crystal:1,30,srparasites:parasiterubbledense:1,100)
B(4,-5,3,betternether:quartz_stained_glass:15)
B(5,-5,3,betternether:quartz_stained_glass:15)
B(6,-5,3,betternether:quartz_stained_glass:15)
B(0,-5,4,betternether:quartz_stained_glass:15)
B(1,-5,4,betternether:quartz_stained_glass:15)
B(2,-5,4,betternether:quartz_stained_glass:15)
B(3,-5,4,betternether:quartz_stained_glass:15)
RB(4,-5,4,srparasites:parasitestain:1,80,quark:crystal:1,30,srparasites:parasiterubbledense:1,100)
RB(5,-5,4,srparasites:parasitestain:1,80,quark:crystal:1,30,srparasites:parasiterubbledense:1,100)
B(6,-5,4,betternether:quartz_stained_glass:15)
B(7,-5,4,betternether:quartz_stained_glass:15)
B(1,-5,5,betternether:quartz_stained_glass:15)
B(2,-5,5,betternether:quartz_stained_glass:15)
RB(3,-5,5,srparasites:parasitestain:1,80,quark:crystal:1,30,srparasites:parasiterubbledense:1,100)
RB(4,-5,5,srparasites:parasitestain:1,80,quark:crystal:1,30,srparasites:parasiterubbledense:1,100)
RB(5,-5,5,srparasites:parasitestain:1,80,quark:crystal:1,30,srparasites:parasiterubbledense:1,100)
B(6,-5,5,betternether:quartz_stained_glass:15)
B(7,-5,5,betternether:quartz_stained_glass:15)
B(8,-5,5,betternether:quartz_stained_glass:15)
B(2,-5,6,betternether:quartz_stained_glass:15)
B(3,-5,6,betternether:quartz_stained_glass:15)
B(4,-5,6,betternether:quartz_stained_glass:15)
RB(5,-5,6,srparasites:parasitestain:1,80,quark:crystal:1,30,srparasites:parasiterubbledense:1,100)
B(6,-5,6,betternether:quartz_stained_glass:15)
B(7,-5,6,betternether:quartz_stained_glass:15)
B(8,-5,6,betternether:quartz_stained_glass:15)
B(3,-5,7,betternether:quartz_stained_glass:15)
B(4,-5,7,betternether:quartz_stained_glass:15)
B(5,-5,7,betternether:quartz_stained_glass:15)
B(6,-5,7,betternether:quartz_stained_glass:15)
B(7,-5,7,betternether:quartz_stained_glass:15)
B(8,-5,7,betternether:quartz_stained_glass:15)
B(4,-5,8,betternether:quartz_stained_glass:15)
B(5,-5,8,betternether:quartz_stained_glass:15)
B(6,-5,8,betternether:quartz_stained_glass:15)
B(7,-5,8,betternether:quartz_stained_glass:15)
B(5,-5,9,betternether:quartz_stained_glass:15)
B(3,-4,0,betternether:quartz_stained_glass:15)
B(4,-4,0,betternether:quartz_stained_glass:15)
B(5,-4,0,betternether:quartz_stained_glass:15)
B(2,-4,1,betternether:quartz_stained_glass:15)
B(3,-4,1,betternether:quartz_stained_glass:15)
B(4,-4,1,betternether:quartz_stained_glass:15)
B(5,-4,1,betternether:quartz_stained_glass:15)
B(1,-4,2,betternether:quartz_stained_glass:15)
B(2,-4,2,betternether:quartz_stained_glass:15)
B(3,-4,2,betternether:quartz_stained_glass:15)
B(4,-4,2,betternether:quartz_stained_glass:15)
B(5,-4,2,betternether:quartz_stained_glass:15)
B(6,-4,2,betternether:quartz_stained_glass:15)
B(0,-4,3,betternether:quartz_stained_glass:15)
B(1,-4,3,betternether:quartz_stained_glass:15)
B(2,-4,3,betternether:quartz_stained_glass:15)
RB(3,-4,3,srparasites:parasitestain:1,80,quark:crystal:1,30,srparasites:parasiterubbledense:1,100)
RB(4,-4,3,srparasites:parasitestain:1,80,quark:crystal:1,30,srparasites:parasiterubbledense:1,100)
B(5,-4,3,betternether:quartz_stained_glass:15)
B(6,-4,3,betternether:quartz_stained_glass:15)
B(0,-4,4,betternether:quartz_stained_glass:15)
B(1,-4,4,betternether:quartz_stained_glass:15)
B(2,-4,4,betternether:quartz_stained_glass:15)
RB(3,-4,4,srparasites:parasitestain:1,80,quark:crystal:1,30,srparasites:parasiterubbledense:1,100)
RB(4,-4,4,srparasites:parasitestain:1,80,quark:crystal:1,30,srparasites:parasiterubbledense:1,100)
RB(5,-4,4,srparasites:parasitestain:1,80,quark:crystal:1,30,srparasites:parasiterubbledense:1,100)
B(6,-4,4,betternether:quartz_stained_glass:15)
B(7,-4,4,betternether:quartz_stained_glass:15)
B(1,-4,5,betternether:quartz_stained_glass:15)
B(2,-4,5,betternether:quartz_stained_glass:15)
RB(3,-4,5,srparasites:parasitestain:1,80,quark:crystal:1,30,srparasites:parasiterubbledense:1,100)
B(4,-4,5,betternether:quartz_stained_glass:15)
B(5,-4,5,betternether:quartz_stained_glass:15)
B(6,-4,5,betternether:quartz_stained_glass:15)
B(7,-4,5,betternether:quartz_stained_glass:15)
B(8,-4,5,betternether:quartz_stained_glass:15)
B(2,-4,6,betternether:quartz_stained_glass:15)
B(3,-4,6,betternether:quartz_stained_glass:15)
B(4,-4,6,betternether:quartz_stained_glass:15)
RB(5,-4,6,srparasites:parasitestain:1,80,quark:crystal:1,30,srparasites:parasiterubbledense:1,100)
B(6,-4,6,betternether:quartz_stained_glass:15)
B(7,-4,6,betternether:quartz_stained_glass:15)
B(8,-4,6,betternether:quartz_stained_glass:15)
B(3,-4,7,betternether:quartz_stained_glass:15)
B(4,-4,7,betternether:quartz_stained_glass:15)
B(5,-4,7,betternether:quartz_stained_glass:15)
B(6,-4,7,betternether:quartz_stained_glass:15)
B(7,-4,7,betternether:quartz_stained_glass:15)
B(4,-4,8,betternether:quartz_stained_glass:15)
B(5,-4,8,betternether:quartz_stained_glass:15)
B(6,-4,8,betternether:quartz_stained_glass:15)
B(3,-3,0,betternether:quartz_stained_glass:15)
B(4,-3,0,betternether:quartz_stained_glass:15)
B(5,-3,0,betternether:quartz_stained_glass:15)
B(2,-3,1,betternether:quartz_stained_glass:15)
B(3,-3,1,betternether:quartz_stained_glass:15)
B(4,-3,1,betternether:quartz_stained_glass:15)
B(5,-3,1,betternether:quartz_stained_glass:15)
B(1,-3,2,betternether:quartz_stained_glass:15)
B(2,-3,2,betternether:quartz_stained_glass:15)
RB(3,-3,2,srparasites:parasitestain:1,80,quark:crystal:1,30,srparasites:parasiterubbledense:1,100)
B(4,-3,2,betternether:quartz_stained_glass:15)
B(5,-3,2,betternether:quartz_stained_glass:15)
B(6,-3,2,betternether:quartz_stained_glass:15)
B(0,-3,3,betternether:quartz_stained_glass:15)
B(1,-3,3,betternether:quartz_stained_glass:15)
B(2,-3,3,betternether:quartz_stained_glass:15)
RB(3,-3,3,srparasites:parasitestain:1,80,quark:crystal:1,30,srparasites:parasiterubbledense:1,100)
RB(4,-3,3,srparasites:parasitestain:1,80,quark:crystal:1,30,srparasites:parasiterubbledense:1,100)
B(5,-3,3,betternether:quartz_stained_glass:15)
B(6,-3,3,betternether:quartz_stained_glass:15)
B(0,-3,4,betternether:quartz_stained_glass:15)
B(1,-3,4,betternether:quartz_stained_glass:15)
RB(2,-3,4,srparasites:parasitestain:1,80,quark:crystal:1,30,srparasites:parasiterubbledense:1,100)
RB(3,-3,4,srparasites:parasitestain:1,80,quark:crystal:1,30,srparasites:parasiterubbledense:1,100)
RB(4,-3,4,srparasites:parasitestain:1,80,quark:crystal:1,30,srparasites:parasiterubbledense:1,100)
B(5,-3,4,betternether:quartz_stained_glass:15)
B(6,-3,4,betternether:quartz_stained_glass:15)
B(7,-3,4,betternether:quartz_stained_glass:15)
B(1,-3,5,betternether:quartz_stained_glass:15)
B(2,-3,5,betternether:quartz_stained_glass:15)
B(3,-3,5,betternether:quartz_stained_glass:15)
B(4,-3,5,betternether:quartz_stained_glass:15)
B(5,-3,5,betternether:quartz_stained_glass:15)
B(6,-3,5,betternether:quartz_stained_glass:15)
B(7,-3,5,betternether:quartz_stained_glass:15)
B(2,-3,6,betternether:quartz_stained_glass:15)
B(3,-3,6,betternether:quartz_stained_glass:15)
B(4,-3,6,betternether:quartz_stained_glass:15)
B(5,-3,6,betternether:quartz_stained_glass:15)
B(6,-3,6,betternether:quartz_stained_glass:15)
B(7,-3,6,betternether:quartz_stained_glass:15)
B(3,-3,7,betternether:quartz_stained_glass:15)
B(4,-3,7,betternether:quartz_stained_glass:15)
B(5,-3,7,betternether:quartz_stained_glass:15)
B(6,-3,7,betternether:quartz_stained_glass:15)
B(5,-3,8,betternether:quartz_stained_glass:15)
B(3,-2,0,betternether:quartz_stained_glass:15)
B(4,-2,0,betternether:quartz_stained_glass:15)
B(5,-2,0,betternether:quartz_stained_glass:15)
B(2,-2,1,betternether:quartz_stained_glass:15)
B(3,-2,1,betternether:quartz_stained_glass:15)
B(4,-2,1,betternether:quartz_stained_glass:15)
B(5,-2,1,betternether:quartz_stained_glass:15)
B(1,-2,2,betternether:quartz_stained_glass:15)
B(2,-2,2,betternether:quartz_stained_glass:15)
B(3,-2,2,betternether:quartz_stained_glass:15)
RB(4,-2,2,srparasites:parasitestain:1,80,quark:crystal:1,30,srparasites:parasiterubbledense:1,100)
B(5,-2,2,betternether:quartz_stained_glass:15)
B(6,-2,2,betternether:quartz_stained_glass:15)
B(0,-2,3,betternether:quartz_stained_glass:15)
B(1,-2,3,betternether:quartz_stained_glass:15)
RB(2,-2,3,srparasites:parasitestain:1,80,quark:crystal:1,30,srparasites:parasiterubbledense:1,100)
RB(3,-2,3,srparasites:parasitestain:1,80,quark:crystal:1,30,srparasites:parasiterubbledense:1,100)
B(4,-2,3,betternether:quartz_stained_glass:15)
B(5,-2,3,betternether:quartz_stained_glass:15)
B(6,-2,3,betternether:quartz_stained_glass:15)
B(0,-2,4,betternether:quartz_stained_glass:15)
B(1,-2,4,betternether:quartz_stained_glass:15)
RB(2,-2,4,srparasites:parasitestain:1,80,quark:crystal:1,30,srparasites:parasiterubbledense:1,100)
B(3,-2,4,betternether:quartz_stained_glass:15)
RB(4,-2,4,srparasites:parasitestain:1,80,quark:crystal:1,30,srparasites:parasiterubbledense:1,100)
B(5,-2,4,betternether:quartz_stained_glass:15)
B(6,-2,4,betternether:quartz_stained_glass:15)
B(7,-2,4,betternether:quartz_stained_glass:15)
B(1,-2,5,betternether:quartz_stained_glass:15)
B(2,-2,5,betternether:quartz_stained_glass:15)
B(3,-2,5,betternether:quartz_stained_glass:15)
B(4,-2,5,betternether:quartz_stained_glass:15)
B(5,-2,5,betternether:quartz_stained_glass:15)
B(6,-2,5,betternether:quartz_stained_glass:15)
B(7,-2,5,betternether:quartz_stained_glass:15)
B(2,-2,6,betternether:quartz_stained_glass:15)
B(3,-2,6,betternether:quartz_stained_glass:15)
B(4,-2,6,betternether:quartz_stained_glass:15)
B(5,-2,6,betternether:quartz_stained_glass:15)
B(6,-2,6,betternether:quartz_stained_glass:15)
B(3,-2,7,betternether:quartz_stained_glass:15)
B(4,-2,7,betternether:quartz_stained_glass:15)
B(5,-2,7,betternether:quartz_stained_glass:15)
B(2,-1,0,betternether:quartz_stained_glass:15)
B(3,-1,0,betternether:quartz_stained_glass:15)
B(4,-1,0,betternether:quartz_stained_glass:15)
B(1,-1,1,betternether:quartz_stained_glass:15)
B(2,-1,1,betternether:quartz_stained_glass:15)
B(3,-1,1,betternether:quartz_stained_glass:15)
B(4,-1,1,betternether:quartz_stained_glass:15)
B(1,-1,2,betternether:quartz_stained_glass:15)
B(2,-1,2,betternether:quartz_stained_glass:15)
RB(3,-1,2,srparasites:parasitestain:1,80,quark:crystal:1,30,srparasites:parasiterubbledense:1,100)
B(4,-1,2,betternether:quartz_stained_glass:15)
B(5,-1,2,betternether:quartz_stained_glass:15)
B(0,-1,3,betternether:quartz_stained_glass:15)
B(1,-1,3,betternether:quartz_stained_glass:15)
B(2,-1,3,betternether:quartz_stained_glass:15)
B(3,-1,3,betternether:quartz_stained_glass:15)
B(4,-1,3,betternether:quartz_stained_glass:15)
B(5,-1,3,betternether:quartz_stained_glass:15)
B(6,-1,3,betternether:quartz_stained_glass:15)
B(1,-1,4,betternether:quartz_stained_glass:15)
B(2,-1,4,betternether:quartz_stained_glass:15)
B(3,-1,4,betternether:quartz_stained_glass:15)
B(4,-1,4,betternether:quartz_stained_glass:15)
B(5,-1,4,betternether:quartz_stained_glass:15)
B(6,-1,4,betternether:quartz_stained_glass:15)
B(2,-1,5,betternether:quartz_stained_glass:15)
B(3,-1,5,betternether:quartz_stained_glass:15)
B(4,-1,5,betternether:quartz_stained_glass:15)
B(5,-1,5,betternether:quartz_stained_glass:15)
B(6,-1,5,betternether:quartz_stained_glass:15)
B(2,-1,6,betternether:quartz_stained_glass:15)
B(3,-1,6,betternether:quartz_stained_glass:15)
B(4,-1,6,betternether:quartz_stained_glass:15)
B(5,-1,6,betternether:quartz_stained_glass:15)
B(2,0,0,betternether:quartz_stained_glass:15)
B(3,0,0,betternether:quartz_stained_glass:15)
B(4,0,0,betternether:quartz_stained_glass:15)
B(1,0,1,betternether:quartz_stained_glass:15)
B(2,0,1,betternether:quartz_stained_glass:15)
B(3,0,1,betternether:quartz_stained_glass:15)
B(4,0,1,betternether:quartz_stained_glass:15)
B(1,0,2,betternether:quartz_stained_glass:15)
B(2,0,2,betternether:quartz_stained_glass:15)
B(4,0,2,betternether:quartz_stained_glass:15)
B(5,0,2,betternether:quartz_stained_glass:15)
B(0,0,3,betternether:quartz_stained_glass:15)
B(1,0,3,betternether:quartz_stained_glass:15)
B(2,0,3,betternether:quartz_stained_glass:15)
B(3,0,3,betternether:quartz_stained_glass:15)
B(4,0,3,betternether:quartz_stained_glass:15)
B(5,0,3,betternether:quartz_stained_glass:15)
B(1,0,4,betternether:quartz_stained_glass:15)
B(2,0,4,betternether:quartz_stained_glass:15)
B(3,0,4,betternether:quartz_stained_glass:15)
B(4,0,4,betternether:quartz_stained_glass:15)
B(5,0,4,betternether:quartz_stained_glass:15)
B(6,0,4,betternether:quartz_stained_glass:15)
B(2,0,5,betternether:quartz_stained_glass:15)
B(3,0,5,betternether:quartz_stained_glass:15)
B(4,0,5,betternether:quartz_stained_glass:15)
B(5,0,5,betternether:quartz_stained_glass:15)
B(3,0,6,betternether:quartz_stained_glass:15)
B(1,1,0,betternether:quartz_stained_glass:15)
B(2,1,0,betternether:quartz_stained_glass:15)
B(3,1,0,betternether:quartz_stained_glass:15)
B(1,1,1,betternether:quartz_stained_glass:15)
B(2,1,1,betternether:quartz_stained_glass:15)
B(3,1,1,betternether:quartz_stained_glass:15)
B(4,1,1,betternether:quartz_stained_glass:15)
B(1,1,2,betternether:quartz_stained_glass:15)
B(2,1,2,betternether:quartz_stained_glass:15)
B(3,1,2,betternether:quartz_stained_glass:15)
B(4,1,2,betternether:quartz_stained_glass:15)
B(1,1,3,betternether:quartz_stained_glass:15)
B(2,1,3,betternether:quartz_stained_glass:15)
B(3,1,3,betternether:quartz_stained_glass:15)
B(4,1,3,betternether:quartz_stained_glass:15)
B(2,1,4,betternether:quartz_stained_glass:15)
B(3,1,4,betternether:quartz_stained_glass:15)
B(1,2,0,betternether:quartz_stained_glass:15)
B(2,2,0,betternether:quartz_stained_glass:15)
B(3,2,0,betternether:quartz_stained_glass:15)
B(1,2,1,betternether:quartz_stained_glass:15)
B(2,2,1,betternether:quartz_stained_glass:15)
B(3,2,1,betternether:quartz_stained_glass:15)
B(4,2,1,betternether:quartz_stained_glass:15)
B(1,2,2,betternether:quartz_stained_glass:15)
B(2,2,2,betternether:quartz_stained_glass:15)
B(3,2,2,betternether:quartz_stained_glass:15)
B(4,2,2,betternether:quartz_stained_glass:15)
B(1,2,3,betternether:quartz_stained_glass:15)
B(2,2,3,betternether:quartz_stained_glass:15)
B(1,3,0,betternether:quartz_stained_glass:15)
B(2,3,0,betternether:quartz_stained_glass:15)
B(1,3,1,betternether:quartz_stained_glass:15)
B(2,3,1,betternether:quartz_stained_glass:15)
B(3,3,1,betternether:quartz_stained_glass:15)
B(2,3,2,betternether:quartz_stained_glass:15)
B(3,3,2,betternether:quartz_stained_glass:15)
B(1,4,0,betternether:quartz_stained_glass:15)
B(2,4,1,betternether:quartz_stained_glass:15)
B(1,5,0,betternether:quartz_stained_glass:15)

#######################################################################
# +-----------------------------------------------------------------+ #
# |                             Branches                            | #
# +-----------------------------------------------------------------+ #
#######################################################################

BR(0,0,16,true,CEILING_CRYST-SET-MED-BIG-16_0x1,NORTH,100,0)
