#######################################################################
# +-----------------------------------------------------------------+ #
# |                            BO3 object                           | #
# +-----------------------------------------------------------------+ #
#######################################################################

Author: Bo3 BulkEdit

Description: Converted Schematic - Modified by Bo3BulkEdit

Version: 3

SettingsMode: WriteDisable

#######################################################################
# +-----------------------------------------------------------------+ #
# |                          Main settings                          | #
# +-----------------------------------------------------------------+ #
#######################################################################



Frequency: 0


SpawnHeight: randomY





##############################
# Height Limits for the BO3. #
##############################

MinHeight: 0
MaxHeight: 256

#######################################################################
# +-----------------------------------------------------------------+ #
# |                      Source block settings                      | #
# +-----------------------------------------------------------------+ #
#######################################################################

CanOverride: true
MaxPercentageOutsideSourceBlock: 100
OutsideSourceBlock: placeAnyway

#######################################################################
# +-----------------------------------------------------------------+ #
# |                               OTG+                              | #
# +-----------------------------------------------------------------+ #
#######################################################################

#######################################################################
# +-----------------------------------------------------------------+ #
# |                              Blocks                             | #
# +-----------------------------------------------------------------+ #
#######################################################################

B(0,750,0,AIR)
B(15,750,15,AIR)
B(1,1,7,betternether:quartz_stained_glass:15)
B(2,1,7,betternether:quartz_stained_glass:15)
B(1,1,8,betternether:quartz_stained_glass:15)
RB(2,1,8,srparasites:parasitestain:1,80,quark:crystal:1,30,srparasites:parasiterubbledense:1,100)
B(3,1,8,betternether:quartz_stained_glass:15)
B(2,1,9,betternether:quartz_stained_glass:15)
B(3,1,9,betternether:quartz_stained_glass:15)
B(4,1,9,betternether:quartz_stained_glass:15)
B(4,1,10,betternether:quartz_stained_glass:15)
B(1,2,5,betternether:quartz_stained_glass:15)
B(0,2,6,betternether:quartz_stained_glass:15)
B(1,2,6,betternether:quartz_stained_glass:15)
B(2,2,6,betternether:quartz_stained_glass:15)
B(0,2,7,betternether:quartz_stained_glass:15)
RB(1,2,7,srparasites:parasitestain:1,80,quark:crystal:1,30,srparasites:parasiterubbledense:1,100)
B(2,2,7,betternether:quartz_stained_glass:15)
B(3,2,7,betternether:quartz_stained_glass:15)
B(0,2,8,betternether:quartz_stained_glass:15)
B(1,2,8,betternether:quartz_stained_glass:15)
RB(2,2,8,srparasites:parasitestain:1,80,quark:crystal:1,30,srparasites:parasiterubbledense:1,100)
B(3,2,8,betternether:quartz_stained_glass:15)
B(1,2,9,betternether:quartz_stained_glass:15)
B(2,2,9,betternether:quartz_stained_glass:15)
B(3,2,9,betternether:quartz_stained_glass:15)
B(4,2,9,betternether:quartz_stained_glass:15)
B(2,2,10,betternether:quartz_stained_glass:15)
B(3,2,10,betternether:quartz_stained_glass:15)
B(1,3,4,betternether:quartz_stained_glass:15)
B(2,3,4,betternether:quartz_stained_glass:15)
B(0,3,5,betternether:quartz_stained_glass:15)
B(1,3,5,betternether:quartz_stained_glass:15)
B(2,3,5,betternether:quartz_stained_glass:15)
B(0,3,6,betternether:quartz_stained_glass:15)
B(1,3,6,betternether:quartz_stained_glass:15)
B(2,3,6,betternether:quartz_stained_glass:15)
RB(0,3,7,srparasites:parasitestain:1,80,quark:crystal:1,30,srparasites:parasiterubbledense:1,100)
RB(1,3,7,srparasites:parasitestain:1,80,quark:crystal:1,30,srparasites:parasiterubbledense:1,100)
B(2,3,7,betternether:quartz_stained_glass:15)
B(3,3,7,betternether:quartz_stained_glass:15)
RB(0,3,8,srparasites:parasitestain:1,80,quark:crystal:1,30,srparasites:parasiterubbledense:1,100)
RB(1,3,8,srparasites:parasitestain:1,80,quark:crystal:1,30,srparasites:parasiterubbledense:1,100)
B(2,3,8,betternether:quartz_stained_glass:15)
B(3,3,8,betternether:quartz_stained_glass:15)
B(4,3,8,betternether:quartz_stained_glass:15)
B(0,3,9,betternether:quartz_stained_glass:15)
B(1,3,9,betternether:quartz_stained_glass:15)
B(2,3,9,betternether:quartz_stained_glass:15)
B(3,3,9,betternether:quartz_stained_glass:15)
B(1,3,10,betternether:quartz_stained_glass:15)
B(2,3,10,betternether:quartz_stained_glass:15)
B(1,4,3,betternether:quartz_stained_glass:15)
B(0,4,4,betternether:quartz_stained_glass:15)
B(1,4,4,betternether:quartz_stained_glass:15)
B(2,4,4,betternether:quartz_stained_glass:15)
B(0,4,5,betternether:quartz_stained_glass:15)
B(1,4,5,betternether:quartz_stained_glass:15)
B(2,4,5,betternether:quartz_stained_glass:15)
RB(0,4,6,srparasites:parasitestain:1,80,quark:crystal:1,30,srparasites:parasiterubbledense:1,100)
B(1,4,6,betternether:quartz_stained_glass:15)
B(2,4,6,betternether:quartz_stained_glass:15)
B(3,4,6,betternether:quartz_stained_glass:15)
RB(0,4,7,srparasites:parasitestain:1,80,quark:crystal:1,30,srparasites:parasiterubbledense:1,100)
RB(1,4,7,srparasites:parasitestain:1,80,quark:crystal:1,30,srparasites:parasiterubbledense:1,100)
B(2,4,7,betternether:quartz_stained_glass:15)
B(3,4,7,betternether:quartz_stained_glass:15)
B(4,4,7,betternether:quartz_stained_glass:15)
RB(0,4,8,srparasites:parasitestain:1,80,quark:crystal:1,30,srparasites:parasiterubbledense:1,100)
B(1,4,8,betternether:quartz_stained_glass:15)
B(2,4,8,betternether:quartz_stained_glass:15)
B(3,4,8,betternether:quartz_stained_glass:15)
B(0,4,9,betternether:quartz_stained_glass:15)
B(1,4,9,betternether:quartz_stained_glass:15)
B(2,4,9,betternether:quartz_stained_glass:15)
B(1,4,10,betternether:quartz_stained_glass:15)
B(0,5,3,betternether:quartz_stained_glass:15)
B(1,5,3,betternether:quartz_stained_glass:15)
B(0,5,4,betternether:quartz_stained_glass:15)
B(1,5,4,betternether:quartz_stained_glass:15)
B(2,5,4,betternether:quartz_stained_glass:15)
B(0,5,5,betternether:quartz_stained_glass:15)
B(1,5,5,betternether:quartz_stained_glass:15)
B(2,5,5,betternether:quartz_stained_glass:15)
B(3,5,5,betternether:quartz_stained_glass:15)
RB(0,5,6,srparasites:parasitestain:1,80,quark:crystal:1,30,srparasites:parasiterubbledense:1,100)
B(1,5,6,betternether:quartz_stained_glass:15)
B(2,5,6,betternether:quartz_stained_glass:15)
B(3,5,6,betternether:quartz_stained_glass:15)
RB(0,5,7,srparasites:parasitestain:1,80,quark:crystal:1,30,srparasites:parasiterubbledense:1,100)
B(1,5,7,betternether:quartz_stained_glass:15)
B(2,5,7,betternether:quartz_stained_glass:15)
B(3,5,7,betternether:quartz_stained_glass:15)
B(0,5,8,betternether:quartz_stained_glass:15)
B(1,5,8,betternether:quartz_stained_glass:15)
B(2,5,8,betternether:quartz_stained_glass:15)
B(0,5,9,betternether:quartz_stained_glass:15)
B(1,5,9,betternether:quartz_stained_glass:15)
B(2,5,9,betternether:quartz_stained_glass:15)
B(0,6,2,betternether:quartz_stained_glass:15)
B(0,6,3,betternether:quartz_stained_glass:15)
B(1,6,3,betternether:quartz_stained_glass:15)
B(0,6,4,betternether:quartz_stained_glass:15)
B(1,6,4,betternether:quartz_stained_glass:15)
B(2,6,4,betternether:quartz_stained_glass:15)
B(3,6,4,betternether:quartz_stained_glass:15)
RB(0,6,5,srparasites:parasitestain:1,80,quark:crystal:1,30,srparasites:parasiterubbledense:1,100)
B(1,6,5,betternether:quartz_stained_glass:15)
B(2,6,5,betternether:quartz_stained_glass:15)
B(3,6,5,betternether:quartz_stained_glass:15)
RB(0,6,6,srparasites:parasitestain:1,80,quark:crystal:1,30,srparasites:parasiterubbledense:1,100)
B(1,6,6,betternether:quartz_stained_glass:15)
B(2,6,6,betternether:quartz_stained_glass:15)
B(3,6,6,betternether:quartz_stained_glass:15)
B(0,6,7,betternether:quartz_stained_glass:15)
B(1,6,7,betternether:quartz_stained_glass:15)
B(2,6,7,betternether:quartz_stained_glass:15)
B(0,6,8,betternether:quartz_stained_glass:15)
B(1,6,8,betternether:quartz_stained_glass:15)
B(2,6,8,betternether:quartz_stained_glass:15)
B(0,6,9,betternether:quartz_stained_glass:15)
B(1,6,9,betternether:quartz_stained_glass:15)
B(0,7,2,betternether:quartz_stained_glass:15)
B(0,7,3,betternether:quartz_stained_glass:15)
B(1,7,3,betternether:quartz_stained_glass:15)
B(2,7,3,betternether:quartz_stained_glass:15)
B(0,7,4,betternether:quartz_stained_glass:15)
B(1,7,4,betternether:quartz_stained_glass:15)
B(2,7,4,betternether:quartz_stained_glass:15)
B(3,7,4,betternether:quartz_stained_glass:15)
RB(0,7,5,srparasites:parasitestain:1,80,quark:crystal:1,30,srparasites:parasiterubbledense:1,100)
B(1,7,5,betternether:quartz_stained_glass:15)
B(2,7,5,betternether:quartz_stained_glass:15)
B(3,7,5,betternether:quartz_stained_glass:15)
B(0,7,6,betternether:quartz_stained_glass:15)
B(1,7,6,betternether:quartz_stained_glass:15)
B(2,7,6,betternether:quartz_stained_glass:15)
B(3,7,6,betternether:quartz_stained_glass:15)
B(0,7,7,betternether:quartz_stained_glass:15)
B(1,7,7,betternether:quartz_stained_glass:15)
B(0,7,8,betternether:quartz_stained_glass:15)
B(1,7,8,betternether:quartz_stained_glass:15)
B(0,8,2,betternether:quartz_stained_glass:15)
B(0,8,3,betternether:quartz_stained_glass:15)
B(1,8,3,betternether:quartz_stained_glass:15)
B(2,8,3,betternether:quartz_stained_glass:15)
B(0,8,4,betternether:quartz_stained_glass:15)
B(1,8,4,betternether:quartz_stained_glass:15)
B(2,8,4,betternether:quartz_stained_glass:15)
RB(0,8,5,srparasites:parasitestain:1,80,quark:crystal:1,30,srparasites:parasiterubbledense:1,100)
B(1,8,5,srparasites:parasiterubbledense:1)
B(2,8,5,betternether:quartz_stained_glass:15)
B(3,8,5,betternether:quartz_stained_glass:15)
B(0,8,6,betternether:quartz_stained_glass:15)
B(1,8,6,betternether:quartz_stained_glass:15)
B(2,8,6,betternether:quartz_stained_glass:15)
B(0,8,7,betternether:quartz_stained_glass:15)
B(1,8,7,betternether:quartz_stained_glass:15)
B(0,8,8,betternether:quartz_stained_glass:15)
B(0,9,2,betternether:quartz_stained_glass:15)
B(1,9,2,betternether:quartz_stained_glass:15)
B(0,9,3,betternether:quartz_stained_glass:15)
B(1,9,3,betternether:quartz_stained_glass:15)
B(2,9,3,betternether:quartz_stained_glass:15)
B(0,9,4,srparasites:parasiterubbledense:1)
B(1,9,4,srparasites:parasiterubbledense:1)
B(2,9,4,betternether:quartz_stained_glass:15)
B(0,9,5,srparasites:parasiterubbledense:1)
B(1,9,5,srparasites:parasiterubbledense:1)
B(2,9,5,betternether:quartz_stained_glass:15)
B(0,9,6,betternether:quartz_stained_glass:15)
B(0,9,7,betternether:quartz_stained_glass:15)
B(0,10,2,betternether:quartz_stained_glass:15)
B(1,10,2,betternether:quartz_stained_glass:15)
B(0,10,3,betternether:quartz_stained_glass:15)
B(1,10,3,betternether:quartz_stained_glass:15)
B(0,10,4,srparasites:parasiterubbledense:1)
B(1,10,4,srparasites:parasiterubbledense:1)
B(2,10,4,betternether:quartz_stained_glass:15)
B(0,10,5,srparasites:parasiterubbledense:1)
B(1,10,5,betternether:quartz_stained_glass:15)
B(0,10,6,betternether:quartz_stained_glass:15)
B(0,11,1,betternether:quartz_stained_glass:15)
B(0,11,2,betternether:quartz_stained_glass:15)
B(1,11,2,betternether:quartz_stained_glass:15)
B(0,11,3,betternether:quartz_stained_glass:15)
B(1,11,3,betternether:quartz_stained_glass:15)
B(0,11,4,srparasites:parasiterubbledense:1)
B(1,11,4,betternether:quartz_stained_glass:15)
B(0,11,5,betternether:quartz_stained_glass:15)
B(0,12,1,betternether:quartz_stained_glass:15)
B(0,12,2,betternether:quartz_stained_glass:15)
B(0,12,3,srparasites:parasiterubbledense:1)
B(1,12,3,betternether:quartz_stained_glass:15)
B(0,12,4,betternether:quartz_stained_glass:15)
B(0,12,5,betternether:quartz_stained_glass:15)
B(0,13,0,betternether:quartz_stained_glass:15)
B(0,13,1,betternether:quartz_stained_glass:15)
B(0,13,2,betternether:quartz_stained_glass:15)
B(0,13,3,betternether:quartz_stained_glass:15)
B(0,14,0,betternether:quartz_stained_glass:15)
B(0,14,2,betternether:quartz_stained_glass:15)
B(0,15,0,betternether:quartz_stained_glass:15)

