
#######################################################################
# +-----------------------------------------------------------------+ #
# |                            BO4 object                           | #
# +-----------------------------------------------------------------+ #
#######################################################################

Author: NLBlackEagle

Description: No description given

SettingsMode: WriteWithoutComments


#######################################################################
# +-----------------------------------------------------------------+ #
# |                          Main settings                          | #
# +-----------------------------------------------------------------+ #
#######################################################################

FixedRotation: 

Frequency: 0

SpawnHeight: highestBlock

UseCenterForHighestBlock: true

##############################
# Height Limits for the BO4. #
##############################

MinHeight: 0

MaxHeight: 255

InheritBO3: 

InheritBO3Rotation: NORTH

OverrideChildSettings: true

OverrideParentHeight: false

CanOverride: true

BranchFrequency: 0

BranchFrequencyGroup: 

MustBeBelowOther: false

MustBeInside: 

CannotBeInside: 

ReplacesBO3: 

MustBeInsideWorldBorders: false

CanSpawnOnWater: true

SpawnOnWaterOnly: false

SpawnUnderWater: false

SpawnAtWaterLevel: false

HeightOffset: 0

RemoveAir: true

ReplaceAbove: 

ReplaceBelow: 

ReplaceWithBiomeBlocks: true

ReplaceWithSurfaceBlock: GRASS

ReplaceWithGroundBlock: DIRT

ReplaceWithStoneBlock: STONE

SmoothRadius: 0

SmoothHeightOffset: 0

SmoothStartTop: false

SmoothStartWood: false

SmoothingSurfaceBlock: 

SmoothingGroundBlock: 

BO3Group: 

IsSpawnPoint: false

DoReplaceBlocks: true


#######################################################################
# +-----------------------------------------------------------------+ #
# |                              Blocks                             | #
# +-----------------------------------------------------------------+ #
#######################################################################

Block(-3,0,7,STONE:0)
Block(-3,0,8,STONE:0)
Block(-2,0,7,STONE:0)
Block(-2,0,8,STONE:0)
Block(-1,0,7,STONE:0)
Block(-1,0,8,STONE:0)
Block(-1,1,8,STONE:0)
Block(0,0,7,STONE:0)
Block(0,0,8,STONE:0)
Block(0,1,7,STONE:0)
Block(0,1,8,STONE:0)
Block(0,30,-4,STONE:0)
Block(0,30,-3,STONE:0)
Block(0,30,-2,STONE:0)
Block(0,31,-4,STONE:0)
Block(0,31,-3,STONE:0)
Block(0,31,-2,STONE:0)
Block(0,32,-4,STONE:0)
Block(0,32,-3,STONE:0)
Block(0,32,-2,STONE:0)
Block(1,0,7,STONE:0)
Block(1,0,8,STONE:0)
Block(1,1,7,STONE:0)
Block(1,1,8,STONE:0)
Block(1,29,-3,STONE:0)
Block(1,29,-2,STONE:0)
Block(1,29,-1,STONE:0)
Block(1,30,-4,STONE:0)
Block(1,30,-3,STONE:0)
Block(1,30,-2,STONE:0)
Block(1,30,-1,STONE:0)
Block(1,31,-4,STONE:0)
Block(1,31,-3,STONE:0)
Block(1,31,-2,STONE:0)
Block(1,31,-1,STONE:0)
Block(1,32,-5,STONE:0)
Block(1,32,-4,STONE:0)
Block(1,32,-3,STONE:0)
Block(1,32,-2,STONE:0)
Block(1,32,-1,STONE:0)
Block(1,33,-4,STONE:0)
Block(1,33,-3,STONE:0)
Block(1,33,-2,STONE:0)
Block(2,0,7,STONE:0)
Block(2,0,8,STONE:0)
Block(2,1,7,STONE:0)
Block(2,1,8,STONE:0)
Block(2,2,7,STONE:0)
Block(2,2,8,STONE:0)
Block(2,28,-3,STONE:0)
Block(2,28,-2,STONE:0)
Block(2,28,-1,STONE:0)
Block(2,28,0,STONE:0)
Block(2,29,-4,STONE:0)
Block(2,29,-3,STONE:0)
Block(2,29,-2,STONE:0)
Block(2,29,-1,STONE:0)
Block(2,29,0,STONE:0)
Block(2,30,-4,STONE:0)
Block(2,30,-3,STONE:0)
Block(2,30,-2,STONE:0)
Block(2,30,-1,STONE:0)
Block(2,30,0,STONE:0)
Block(2,31,-5,STONE:0)
Block(2,31,-4,STONE:0)
Block(2,31,-3,STONE:0)
Block(2,31,-2,STONE:0)
Block(2,31,-1,STONE:0)
Block(2,32,-5,STONE:0)
Block(2,32,-4,STONE:0)
Block(2,32,-3,STONE:0)
Block(2,32,-2,STONE:0)
Block(2,32,-1,STONE:0)
Block(2,33,-4,STONE:0)
Block(2,33,-3,STONE:0)
Block(2,33,-2,STONE:0)
Block(3,0,6,STONE:0)
Block(3,0,7,STONE:0)
Block(3,0,8,STONE:0)
Block(3,1,7,STONE:0)
Block(3,1,8,STONE:0)
Block(3,2,7,STONE:0)
Block(3,2,8,STONE:0)
Block(3,28,-3,STONE:0)
Block(3,28,-2,STONE:0)
Block(3,28,-1,STONE:0)
Block(3,28,0,STONE:0)
Block(3,28,1,STONE:0)
Block(3,29,-4,STONE:0)
Block(3,29,-3,STONE:0)
Block(3,29,-2,STONE:0)
Block(3,29,-1,STONE:0)
Block(3,29,0,STONE:0)
Block(3,29,1,STONE:0)
Block(3,30,-4,STONE:0)
Block(3,30,-3,STONE:0)
Block(3,30,-2,STONE:0)
Block(3,30,-1,STONE:0)
Block(3,30,0,STONE:0)
Block(3,30,1,STONE:0)
Block(3,31,-5,STONE:0)
Block(3,31,-4,STONE:0)
Block(3,31,-3,STONE:0)
Block(3,31,-2,STONE:0)
Block(3,31,-1,STONE:0)
Block(3,31,0,STONE:0)
Block(3,32,-5,STONE:0)
Block(3,32,-4,STONE:0)
Block(3,32,-3,STONE:0)
Block(3,32,-2,STONE:0)
Block(3,32,-1,STONE:0)
Block(3,33,-4,STONE:0)
Block(3,33,-3,STONE:0)
Block(3,33,-2,STONE:0)
Block(4,0,6,STONE:0)
Block(4,0,7,STONE:0)
Block(4,0,8,STONE:0)
Block(4,1,6,STONE:0)
Block(4,1,7,STONE:0)
Block(4,1,8,STONE:0)
Block(4,2,7,STONE:0)
Block(4,2,8,STONE:0)
Block(4,3,7,STONE:0)
Block(4,3,8,STONE:0)
Block(4,27,0,STONE:0)
Block(4,27,1,STONE:0)
Block(4,28,-2,STONE:0)
Block(4,28,-1,STONE:0)
Block(4,28,0,STONE:0)
Block(4,28,1,STONE:0)
Block(4,29,-4,STONE:0)
Block(4,29,-3,STONE:0)
Block(4,29,-2,STONE:0)
Block(4,29,-1,STONE:0)
Block(4,29,0,STONE:0)
Block(4,29,1,STONE:0)
Block(4,30,-4,STONE:0)
Block(4,30,-3,STONE:0)
Block(4,30,-2,STONE:0)
Block(4,30,-1,STONE:0)
Block(4,30,0,STONE:0)
Block(4,30,1,STONE:0)
Block(4,31,-4,STONE:0)
Block(4,31,-3,STONE:0)
Block(4,31,-2,STONE:0)
Block(4,31,-1,STONE:0)
Block(4,31,0,STONE:0)
Block(4,32,-5,STONE:0)
Block(4,32,-4,STONE:0)
Block(4,32,-3,STONE:0)
Block(4,32,-2,STONE:0)
Block(4,32,-1,STONE:0)
Block(4,33,-4,STONE:0)
Block(5,0,6,STONE:0)
Block(5,0,7,STONE:0)
Block(5,0,8,STONE:0)
Block(5,1,6,STONE:0)
Block(5,1,7,STONE:0)
Block(5,1,8,STONE:0)
Block(5,2,6,STONE:0)
Block(5,2,7,STONE:0)
Block(5,2,8,STONE:0)
Block(5,3,7,STONE:0)
Block(5,3,8,STONE:0)
Block(5,26,0,STONE:0)
Block(5,26,1,STONE:0)
Block(5,27,-2,STONE:0)
Block(5,27,-1,STONE:0)
Block(5,27,0,STONE:0)
Block(5,27,1,STONE:0)
Block(5,27,2,STONE:0)
Block(5,28,-2,STONE:0)
Block(5,28,-1,STONE:0)
Block(5,28,0,STONE:0)
Block(5,28,1,STONE:0)
Block(5,28,2,STONE:0)
Block(5,29,-5,STONE:0)
Block(5,29,-4,STONE:0)
Block(5,29,-3,STONE:0)
Block(5,29,-2,STONE:0)
Block(5,29,-1,STONE:0)
Block(5,29,0,STONE:0)
Block(5,29,1,STONE:0)
Block(5,30,-5,STONE:0)
Block(5,30,-4,STONE:0)
Block(5,30,-3,STONE:0)
Block(5,30,-2,STONE:0)
Block(5,30,-1,STONE:0)
Block(5,30,0,STONE:0)
Block(5,30,1,STONE:0)
Block(5,31,-5,STONE:0)
Block(5,31,-4,STONE:0)
Block(5,31,-3,STONE:0)
Block(5,31,-2,STONE:0)
Block(5,31,-1,STONE:0)
Block(5,31,0,STONE:0)
Block(5,32,-4,STONE:0)
Block(5,32,-3,STONE:0)
Block(5,32,-2,STONE:0)
Block(5,32,-1,STONE:0)
Block(5,33,-4,STONE:0)
Block(5,33,-3,STONE:0)
Block(6,0,6,STONE:0)
Block(6,0,7,STONE:0)
Block(6,0,8,STONE:0)
Block(6,1,6,STONE:0)
Block(6,1,7,STONE:0)
Block(6,1,8,STONE:0)
Block(6,2,6,STONE:0)
Block(6,2,7,STONE:0)
Block(6,2,8,STONE:0)
Block(6,3,7,STONE:0)
Block(6,3,8,STONE:0)
Block(6,26,-1,STONE:0)
Block(6,26,0,STONE:0)
Block(6,26,1,STONE:0)
Block(6,26,2,STONE:0)
Block(6,27,-2,STONE:0)
Block(6,27,-1,STONE:0)
Block(6,27,0,STONE:0)
Block(6,27,1,STONE:0)
Block(6,27,2,STONE:0)
Block(6,28,-3,STONE:0)
Block(6,28,-2,STONE:0)
Block(6,28,-1,STONE:0)
Block(6,28,0,STONE:0)
Block(6,28,1,STONE:0)
Block(6,28,2,STONE:0)
Block(6,29,-4,STONE:0)
Block(6,29,-3,STONE:0)
Block(6,29,-2,STONE:0)
Block(6,29,-1,STONE:0)
Block(6,29,0,STONE:0)
Block(6,29,1,STONE:0)
Block(6,29,2,STONE:0)
Block(6,30,-5,STONE:0)
Block(6,30,-4,STONE:0)
Block(6,30,-3,STONE:0)
Block(6,30,-2,STONE:0)
Block(6,30,-1,STONE:0)
Block(6,30,0,STONE:0)
Block(6,30,1,STONE:0)
Block(6,31,-5,STONE:0)
Block(6,31,-4,STONE:0)
Block(6,31,-3,STONE:0)
Block(6,31,-2,STONE:0)
Block(6,31,-1,STONE:0)
Block(6,31,0,STONE:0)
Block(6,32,-5,STONE:0)
Block(6,32,-4,STONE:0)
Block(6,32,-3,STONE:0)
Block(6,32,-2,STONE:0)
Block(6,32,-1,STONE:0)
Block(6,33,-5,STONE:0)
Block(6,33,-4,STONE:0)
Block(6,33,-3,STONE:0)
Block(6,33,-2,STONE:0)
Block(7,0,6,STONE:0)
Block(7,0,7,STONE:0)
Block(7,0,8,STONE:0)
Block(7,1,7,STONE:0)
Block(7,1,8,STONE:0)
Block(7,2,7,STONE:0)
Block(7,2,8,STONE:0)
Block(7,3,7,STONE:0)
Block(7,3,8,STONE:0)
Block(7,26,-1,STONE:0)
Block(7,26,0,STONE:0)
Block(7,26,1,STONE:0)
Block(7,26,2,STONE:0)
Block(7,27,-3,STONE:0)
Block(7,27,-2,STONE:0)
Block(7,27,-1,STONE:0)
Block(7,27,0,STONE:0)
Block(7,27,1,STONE:0)
Block(7,27,2,STONE:0)
Block(7,27,3,STONE:0)
Block(7,28,-4,STONE:0)
Block(7,28,-3,STONE:0)
Block(7,28,-2,STONE:0)
Block(7,28,-1,STONE:0)
Block(7,28,0,STONE:0)
Block(7,28,1,STONE:0)
Block(7,28,2,STONE:0)
Block(7,28,3,STONE:0)
Block(7,29,-4,STONE:0)
Block(7,29,-3,STONE:0)
Block(7,29,-2,STONE:0)
Block(7,29,-1,STONE:0)
Block(7,29,0,STONE:0)
Block(7,29,1,STONE:0)
Block(7,29,2,STONE:0)
Block(7,30,-5,STONE:0)
Block(7,30,-4,STONE:0)
Block(7,30,-3,STONE:0)
Block(7,30,-2,STONE:0)
Block(7,30,-1,STONE:0)
Block(7,30,0,STONE:0)
Block(7,30,1,STONE:0)
Block(7,31,-6,STONE:0)
Block(7,31,-5,STONE:0)
Block(7,31,-4,STONE:0)
Block(7,31,-3,STONE:0)
Block(7,31,-2,STONE:0)
Block(7,31,-1,STONE:0)
Block(7,31,0,STONE:0)
Block(7,31,1,STONE:0)
Block(7,31,2,STONE:0)
Block(7,31,3,STONE:0)
Block(7,32,-6,STONE:0)
Block(7,32,-5,STONE:0)
Block(7,32,-4,STONE:0)
Block(7,32,-3,STONE:0)
Block(7,32,-2,STONE:0)
Block(7,32,-1,STONE:0)
Block(7,32,0,STONE:0)
Block(7,32,1,STONE:0)
Block(7,32,2,STONE:0)
Block(7,32,3,STONE:0)
Block(7,33,-6,STONE:0)
Block(7,33,-5,STONE:0)
Block(7,33,-4,STONE:0)
Block(7,33,-3,STONE:0)
Block(7,33,-2,STONE:0)
Block(7,33,1,STONE:0)
Block(7,33,2,STONE:0)
Block(7,33,3,STONE:0)

#######################################################################
# +-----------------------------------------------------------------+ #
# |                             Branches                            | #
# +-----------------------------------------------------------------+ #
#######################################################################

Branch(16,0,0,true,UnderworldColumn_01C1R1,NORTH,100.0,0)

#######################################################################
# +-----------------------------------------------------------------+ #
# |                             Entities                            | #
# +-----------------------------------------------------------------+ #
#######################################################################


#######################################################################
# +-----------------------------------------------------------------+ #
# |                            Particles                            | #
# +-----------------------------------------------------------------+ #
#######################################################################


#######################################################################
# +-----------------------------------------------------------------+ #
# |                             Spawners                            | #
# +-----------------------------------------------------------------+ #
#######################################################################


#######################################################################
# +-----------------------------------------------------------------+ #
# |                             ModData                             | #
# +-----------------------------------------------------------------+ #
#######################################################################

