
#######################################################################
# +-----------------------------------------------------------------+ #
# |                            BO4 object                           | #
# +-----------------------------------------------------------------+ #
#######################################################################

Author: NLBlackEagle

Description: No description given

SettingsMode: WriteDisable


#######################################################################
# +-----------------------------------------------------------------+ #
# |                          Main settings                          | #
# +-----------------------------------------------------------------+ #
#######################################################################

Frequency: 0

SpawnHeight: highestBlock

UseCenterForHighestBlock: true

##############################
# Height Limits for the BO4. #
##############################

MinHeight: 0

MaxHeight: 255

InheritBO3: 

InheritBO3Rotation: NORTH

OverrideChildSettings: true

OverrideParentHeight: false

CanOverride: false

BranchFrequency: 0

BranchFrequencyGroup: 

MustBeBelowOther: false

MustBeInside: 

CannotBeInside: 

ReplacesBO3: 

MustBeInsideWorldBorders: false

CanSpawnOnWater: true

SpawnOnWaterOnly: false

SpawnUnderWater: false

SpawnAtWaterLevel: false

HeightOffset: 0

RemoveAir: false

ReplaceAbove: 

ReplaceBelow: 

ReplaceWithBiomeBlocks: false

ReplaceWithSurfaceBlock: 

ReplaceWithGroundBlock: 

ReplaceWithStoneBlock: 

SmoothRadius: 0

SmoothHeightOffset: 0

SmoothStartTop: false

SmoothStartWood: false

SmoothingSurfaceBlock: 

SmoothingGroundBlock: 

BO3Group: 

IsSpawnPoint: false

DoReplaceBlocks: false


#######################################################################
# +-----------------------------------------------------------------+ #
# |                              Blocks                             | #
# +-----------------------------------------------------------------+ #
#######################################################################

Block(-8,3,-7,STONE:3)
Block(-8,3,-6,STONE:3)
Block(-8,4,-7,STONE:3)
Block(-8,4,-6,STONE:3)
Block(-8,4,-5,STONE:3)
Block(-8,5,-7,STONE:3)
Block(-8,5,-6,STONE:3)
Block(-8,5,-5,STONE:3)
Block(-8,5,-4,STONE:3)
Block(-8,6,-7,STONE:3)
Block(-8,6,-6,STONE:3)
Block(-8,6,-5,STONE:3)
Block(-8,6,-4,STONE:3)
Block(-8,6,-3,STONE:3)
Block(-8,6,-2,STONE:3)
Block(-8,7,-7,STONE:3)
Block(-8,7,-6,STONE:3)
Block(-8,7,-5,STONE:3)
Block(-8,7,-4,STONE:3)
Block(-8,7,-3,STONE:3)
Block(-8,7,-2,STONE:3)
Block(-8,7,-1,STONE:3)
Block(-8,8,-7,STONE:3)
Block(-8,8,-6,STONE:3)
Block(-8,8,-5,STONE:3)
Block(-8,8,-4,STONE:3)
Block(-8,8,-3,STONE:3)
Block(-8,8,-2,STONE:3)
Block(-8,8,-1,STONE:3)
Block(-8,8,0,STONE:3)
Block(-8,9,-7,STONE:3)
Block(-8,9,-6,STONE:3)
Block(-8,9,-5,STONE:3)
Block(-8,9,-4,STONE:3)
Block(-8,9,-3,STONE:3)
Block(-8,9,-2,STONE:3)
Block(-8,9,-1,STONE:3)
Block(-8,9,0,STONE:3)
Block(-8,9,1,STONE:3)
Block(-8,9,2,STONE:3)
Block(-8,10,-7,STONE:0)
Block(-8,10,-6,STONE:3)
Block(-8,10,-5,STONE:3)
Block(-8,10,-4,STONE:3)
Block(-8,10,-3,STONE:3)
Block(-8,10,-2,STONE:3)
Block(-8,10,-1,STONE:3)
Block(-8,10,0,STONE:3)
Block(-8,10,1,STONE:3)
Block(-8,10,2,STONE:3)
Block(-8,10,3,STONE:3)
Block(-8,11,-7,STONE:0)
Block(-8,11,-6,STONE:0)
Block(-8,11,-5,STONE:3)
Block(-8,11,-4,STONE:3)
Block(-8,11,-3,STONE:3)
Block(-8,11,-2,STONE:3)
Block(-8,11,-1,STONE:3)
Block(-8,11,0,STONE:3)
Block(-8,11,1,STONE:3)
Block(-8,11,2,STONE:3)
Block(-8,11,3,STONE:3)
Block(-8,11,4,STONE:3)
Block(-8,12,-7,STONE:0)
Block(-8,12,-6,STONE:0)
Block(-8,12,-5,STONE:0)
Block(-8,12,-4,STONE:0)
Block(-8,12,-3,STONE:3)
Block(-8,12,-2,STONE:3)
Block(-8,12,-1,STONE:3)
Block(-8,12,0,STONE:3)
Block(-8,12,1,STONE:3)
Block(-8,12,2,STONE:3)
Block(-8,12,3,STONE:3)
Block(-8,12,4,STONE:3)
Block(-8,12,5,STONE:3)
Block(-8,13,-7,STONE:0)
Block(-8,13,-6,STONE:0)
Block(-8,13,-5,STONE:0)
Block(-8,13,-4,STONE:0)
Block(-8,13,-3,STONE:0)
Block(-8,13,-2,STONE:3)
Block(-8,13,-1,STONE:3)
Block(-8,13,0,STONE:3)
Block(-8,13,1,STONE:3)
Block(-8,13,2,STONE:3)
Block(-8,13,3,STONE:3)
Block(-8,13,4,STONE:3)
Block(-8,13,5,STONE:3)
Block(-8,13,6,STONE:3)
Block(-8,13,7,STONE:3)
Block(-8,14,-7,STONE:0)
Block(-8,14,-6,STONE:0)
Block(-8,14,-5,STONE:0)
Block(-8,14,-4,STONE:0)
Block(-8,14,-3,STONE:0)
Block(-8,14,-2,STONE:0)
Block(-8,14,-1,STONE:3)
Block(-8,14,0,STONE:3)
Block(-8,14,1,STONE:3)
Block(-8,14,2,STONE:3)
Block(-8,14,3,STONE:3)
Block(-8,14,4,STONE:3)
Block(-8,14,5,STONE:3)
Block(-8,14,6,STONE:3)
Block(-8,14,7,STONE:3)
Block(-8,15,-7,STONE:0)
Block(-8,15,-6,STONE:0)
Block(-8,15,-5,STONE:0)
Block(-8,15,-4,STONE:0)
Block(-8,15,-3,STONE:0)
Block(-8,15,-2,STONE:0)
Block(-8,15,-1,STONE:0)
Block(-8,15,0,STONE:3)
Block(-8,15,1,STONE:3)
Block(-8,15,2,STONE:3)
Block(-8,15,3,STONE:3)
Block(-8,15,4,STONE:3)
Block(-8,15,5,STONE:3)
Block(-8,15,6,STONE:3)
Block(-8,15,7,STONE:5)
Block(-8,15,8,STONE:5)
Block(-8,16,-7,STONE:0)
Block(-8,16,-6,STONE:0)
Block(-8,16,-5,STONE:0)
Block(-8,16,-4,STONE:0)
Block(-8,16,-3,STONE:0)
Block(-8,16,-2,STONE:0)
Block(-8,16,-1,STONE:0)
Block(-8,16,0,STONE:0)
Block(-8,16,1,STONE:0)
Block(-8,16,2,STONE:3)
Block(-8,16,3,STONE:3)
Block(-8,16,4,STONE:3)
Block(-8,16,5,STONE:5)
Block(-8,16,6,STONE:5)
Block(-8,16,7,STONE:5)
Block(-8,16,8,STONE:5)
Block(-8,17,-7,OBSIDIAN:0)
Block(-8,17,-6,OBSIDIAN:0)
Block(-8,17,-5,STONE:0)
Block(-8,17,-4,STONE:0)
Block(-8,17,-3,STONE:0)
Block(-8,17,-2,STONE:0)
Block(-8,17,-1,STONE:0)
Block(-8,17,0,STONE:0)
Block(-8,17,1,STONE:0)
Block(-8,17,2,STONE:0)
Block(-8,17,3,STONE:0)
Block(-8,17,4,STONE:0)
Block(-8,17,5,STONE:0)
Block(-8,17,6,STONE:5)
Block(-8,17,7,STONE:5)
Block(-8,17,8,STONE:5)
Block(-8,18,-7,OBSIDIAN:0)
Block(-8,18,-6,OBSIDIAN:0)
Block(-8,18,-5,GRASS:0)
Block(-8,18,-4,GRASS:0)
Block(-8,18,-3,GRASS:0)
Block(-8,18,-2,STONE:0)
Block(-8,18,-1,STONE:0)
Block(-8,18,0,STONE:0)
Block(-8,18,1,STONE:0)
Block(-8,18,2,STONE:0)
Block(-8,18,3,STONE:0)
Block(-8,18,4,STONE:0)
Block(-8,18,5,STONE:0)
Block(-8,18,6,STONE:5)
Block(-8,18,7,STONE:5)
Block(-8,18,8,STONE:5)
Block(-8,19,-7,AIR:0)
Block(-8,19,-6,AIR:0)
Block(-8,19,-5,AIR:0)
Block(-8,19,-4,AIR:0)
Block(-8,19,-3,AIR:0)
Block(-8,19,-2,GRASS:0)
Block(-8,19,-1,STONE:0)
Block(-8,19,0,STONE:0)
Block(-8,19,1,STONE:0)
Block(-8,19,2,STONE:0)
Block(-8,19,3,STONE:0)
Block(-8,19,4,STONE:0)
Block(-8,19,5,STONE:0)
Block(-8,19,6,STONE:0)
Block(-8,19,7,STONE:5)
Block(-8,19,8,STONE:5)
Block(-8,20,-7,AIR:0)
Block(-8,20,-6,AIR:0)
Block(-8,20,-5,AIR:0)
Block(-8,20,-4,AIR:0)
Block(-8,20,-3,AIR:0)
Block(-8,20,-2,AIR:0)
Block(-8,20,-1,GRASS:0)
Block(-8,20,0,STONE:0)
Block(-8,20,1,STONE:0)
Block(-8,20,2,STONE:0)
Block(-8,20,3,STONE:0)
Block(-8,20,4,STONE:0)
Block(-8,20,5,STONE:0)
Block(-8,20,6,STONE:0)
Block(-8,20,7,STONE:0)
Block(-8,20,8,STONE:0)
Block(-8,21,-7,AIR:0)
Block(-8,21,-6,AIR:0)
Block(-8,21,-5,AIR:0)
Block(-8,21,-4,AIR:0)
Block(-8,21,-3,AIR:0)
Block(-8,21,-2,AIR:0)
Block(-8,21,-1,AIR:0)
Block(-8,21,0,STONE:0)
Block(-8,21,1,STONE:0)
Block(-8,21,2,STONE:0)
Block(-8,21,3,STONE:0)
Block(-8,21,4,STONE:0)
Block(-8,21,5,STONE:0)
Block(-8,21,6,STONE:0)
Block(-8,21,7,STONE:0)
Block(-8,21,8,STONE:0)
Block(-8,22,-7,AIR:0)
Block(-8,22,-6,AIR:0)
Block(-8,22,-5,AIR:0)
Block(-8,22,-4,AIR:0)
Block(-8,22,-3,AIR:0)
Block(-8,22,-2,AIR:0)
Block(-8,22,-1,AIR:0)
Block(-8,22,0,AIR:0)
Block(-8,22,1,GRASS:0)
Block(-8,22,2,STONE:0)
Block(-8,22,3,STONE:0)
Block(-8,22,4,STONE:0)
Block(-8,22,5,STONE:0)
Block(-8,22,6,STONE:0)
Block(-8,22,7,STONE:0)
Block(-8,22,8,STONE:0)
Block(-8,23,-7,AIR:0)
Block(-8,23,-6,AIR:0)
Block(-8,23,-5,AIR:0)
Block(-8,23,-4,AIR:0)
Block(-8,23,-3,AIR:0)
Block(-8,23,-2,AIR:0)
Block(-8,23,-1,AIR:0)
Block(-8,23,0,AIR:0)
Block(-8,23,1,AIR:0)
Block(-8,23,2,AIR:0)
Block(-8,23,3,STONE:0)
Block(-8,23,4,STONE:0)
Block(-8,23,5,STONE:0)
Block(-8,23,6,STONE:0)
Block(-8,23,7,STONE:0)
Block(-8,23,8,STONE:0)
Block(-8,24,-7,AIR:0)
Block(-8,24,-6,AIR:0)
Block(-8,24,-5,AIR:0)
Block(-8,24,-4,AIR:0)
Block(-8,24,-3,AIR:0)
Block(-8,24,-2,AIR:0)
Block(-8,24,-1,AIR:0)
Block(-8,24,0,AIR:0)
Block(-8,24,1,AIR:0)
Block(-8,24,2,STONE:0)
Block(-8,24,3,STONE:0)
Block(-8,24,4,STONE:0)
Block(-8,24,5,STONE:0)
Block(-8,24,6,STONE:0)
Block(-8,24,7,STONE:0)
Block(-8,24,8,STONE:0)
Block(-8,25,-7,AIR:0)
Block(-8,25,-6,AIR:0)
Block(-8,25,-5,AIR:0)
Block(-8,25,-4,AIR:0)
Block(-8,25,-3,AIR:0)
Block(-8,25,-2,AIR:0)
Block(-8,25,-1,AIR:0)
Block(-8,25,0,AIR:0)
Block(-8,25,1,AIR:0)
Block(-8,25,2,STONE:0)
Block(-8,25,3,STONE:0)
Block(-8,25,4,STONE:0)
Block(-8,25,5,STONE:0)
Block(-8,25,6,STONE:0)
Block(-8,25,7,STONE:0)
Block(-8,25,8,STONE:0)
Block(-8,26,-7,AIR:0)
Block(-8,26,-6,AIR:0)
Block(-8,26,-5,AIR:0)
Block(-8,26,-4,AIR:0)
Block(-8,26,-3,AIR:0)
Block(-8,26,-2,AIR:0)
Block(-8,26,-1,AIR:0)
Block(-8,26,0,AIR:0)
Block(-8,26,1,STONE:0)
Block(-8,26,2,STONE:0)
Block(-8,26,3,STONE:0)
Block(-8,26,4,STONE:0)
Block(-8,26,5,STONE:0)
Block(-8,26,6,STONE:0)
Block(-8,26,7,STONE:0)
Block(-8,26,8,STONE:0)
Block(-8,27,-7,AIR:0)
Block(-8,27,-6,AIR:0)
Block(-8,27,-5,AIR:0)
Block(-8,27,-4,AIR:0)
Block(-8,27,-3,AIR:0)
Block(-8,27,-2,AIR:0)
Block(-8,27,-1,AIR:0)
Block(-8,27,0,AIR:0)
Block(-8,27,1,STONE:0)
Block(-8,27,2,STONE:0)
Block(-8,27,3,STONE:0)
Block(-8,27,4,STONE:0)
Block(-8,27,5,STONE:0)
Block(-8,27,6,STONE:0)
Block(-8,27,7,STONE:0)
Block(-8,27,8,STONE:5)
Block(-8,28,-7,AIR:0)
Block(-8,28,-6,AIR:0)
Block(-8,28,-5,AIR:0)
Block(-8,28,-4,AIR:0)
Block(-8,28,-3,AIR:0)
Block(-8,28,-2,AIR:0)
Block(-8,28,-1,AIR:0)
Block(-8,28,0,STONE:0)
Block(-8,28,1,STONE:0)
Block(-8,28,2,STONE:0)
Block(-8,28,3,STONE:0)
Block(-8,28,4,STONE:0)
Block(-8,28,5,STONE:0)
Block(-8,28,6,STONE:0)
Block(-8,28,7,STONE:5)
Block(-8,28,8,STONE:5)
Block(-8,29,-7,AIR:0)
Block(-8,29,-6,AIR:0)
Block(-8,29,-5,AIR:0)
Block(-8,29,-4,AIR:0)
Block(-8,29,-3,AIR:0)
Block(-8,29,-2,STONE:0)
Block(-8,29,-1,STONE:0)
Block(-8,29,0,STONE:0)
Block(-8,29,1,STONE:0)
Block(-8,29,2,STONE:0)
Block(-8,29,3,STONE:0)
Block(-8,29,4,STONE:0)
Block(-8,29,5,STONE:0)
Block(-8,29,6,STONE:5)
Block(-8,29,7,STONE:5)
Block(-8,29,8,STONE:5)
Block(-8,30,-7,AIR:0)
Block(-8,30,-6,AIR:0)
Block(-8,30,-5,AIR:0)
Block(-8,30,-4,STONE:0)
Block(-8,30,-3,STONE:0)
Block(-8,30,-2,STONE:0)
Block(-8,30,-1,STONE:0)
Block(-8,30,0,STONE:0)
Block(-8,30,1,STONE:0)
Block(-8,30,2,STONE:0)
Block(-8,30,3,STONE:0)
Block(-8,30,4,STONE:0)
Block(-8,30,5,STONE:0)
Block(-8,30,6,STONE:5)
Block(-8,30,7,STONE:5)
Block(-8,30,8,STONE:5)
Block(-8,31,-7,AIR:0)
Block(-8,31,-6,AIR:0)
Block(-8,31,-5,STONE:0)
Block(-8,31,-4,STONE:0)
Block(-8,31,-3,STONE:0)
Block(-8,31,-2,STONE:0)
Block(-8,31,-1,STONE:0)
Block(-8,31,0,STONE:0)
Block(-8,31,1,STONE:0)
Block(-8,31,2,STONE:0)
Block(-8,31,3,STONE:0)
Block(-8,31,4,STONE:0)
Block(-8,31,5,STONE:0)
Block(-8,31,6,STONE:5)
Block(-8,31,7,STONE:5)
Block(-8,31,8,STONE:5)
Block(-8,32,-7,AIR:0)
Block(-8,32,-6,AIR:0)
Block(-8,32,-5,STONE:0)
Block(-8,32,-4,STONE:0)
Block(-8,32,-3,STONE:0)
Block(-8,32,-2,STONE:0)
Block(-8,32,-1,STONE:0)
Block(-8,32,0,STONE:0)
Block(-8,32,1,STONE:0)
Block(-8,32,2,STONE:0)
Block(-8,32,3,STONE:5)
Block(-8,32,4,STONE:5)
Block(-8,32,5,STONE:5)
Block(-8,32,6,STONE:5)
Block(-8,32,7,STONE:5)
Block(-8,32,8,STONE:5)
Block(-8,33,-7,AIR:0)
Block(-8,33,-6,STONE:0)
Block(-8,33,-5,STONE:0)
Block(-8,33,-4,STONE:0)
Block(-8,33,-3,STONE:0)
Block(-8,33,-2,STONE:0)
Block(-8,33,-1,STONE:0)
Block(-8,33,0,STONE:0)
Block(-8,33,1,STONE:0)
Block(-8,33,2,STONE:5)
Block(-8,33,3,STONE:5)
Block(-8,33,4,STONE:5)
Block(-8,33,5,STONE:5)
Block(-8,33,6,STONE:5)
Block(-8,33,7,STONE:5)
Block(-8,33,8,STONE:5)
Block(-8,34,-7,STONE:0)
Block(-8,34,-6,STONE:0)
Block(-8,34,-5,STONE:0)
Block(-8,34,-4,STONE:0)
Block(-8,34,-3,STONE:0)
Block(-8,34,-2,STONE:0)
Block(-8,34,-1,STONE:0)
Block(-8,34,0,STONE:0)
Block(-8,34,1,STONE:5)
Block(-8,34,2,STONE:5)
Block(-8,34,3,STONE:5)
Block(-8,34,4,STONE:5)
Block(-8,34,5,STONE:5)
Block(-8,34,6,STONE:5)
Block(-8,34,7,STONE:5)
Block(-8,34,8,STONE:5)
Block(-8,35,-7,STONE:0)
Block(-8,35,-6,STONE:0)
Block(-8,35,-5,STONE:0)
Block(-8,35,-4,STONE:0)
Block(-8,35,-3,STONE:0)
Block(-8,35,-2,STONE:0)
Block(-8,35,-1,STONE:0)
Block(-8,35,0,STONE:5)
Block(-8,35,1,STONE:5)
Block(-8,35,2,STONE:5)
Block(-8,35,3,STONE:5)
Block(-8,35,4,STONE:5)
Block(-8,35,5,STONE:5)
Block(-8,35,6,STONE:5)
Block(-8,35,7,STONE:5)
Block(-8,35,8,STONE:5)
Block(-8,36,-7,STONE:0)
Block(-8,36,-6,STONE:0)
Block(-8,36,-5,STONE:0)
Block(-8,36,-4,STONE:0)
Block(-8,36,-3,STONE:0)
Block(-8,36,-2,STONE:0)
Block(-8,36,-1,STONE:0)
Block(-8,36,0,STONE:5)
Block(-8,36,1,STONE:5)
Block(-8,36,2,STONE:5)
Block(-8,36,3,STONE:5)
Block(-8,36,4,STONE:5)
Block(-8,36,5,STONE:5)
Block(-8,36,6,STONE:5)
Block(-8,36,7,STONE:5)
Block(-8,36,8,STONE:5)
Block(-8,37,-7,STONE:0)
Block(-8,37,-6,STONE:0)
Block(-8,37,-5,STONE:0)
Block(-8,37,-4,STONE:0)
Block(-8,37,-3,STONE:0)
Block(-8,37,-2,STONE:3)
Block(-8,37,-1,STONE:3)
Block(-8,37,0,STONE:3)
Block(-8,37,1,STONE:3)
Block(-8,37,2,STONE:3)
Block(-8,37,3,STONE:5)
Block(-8,37,4,STONE:5)
Block(-8,37,5,STONE:5)
Block(-8,37,6,STONE:5)
Block(-8,37,7,STONE:5)
Block(-8,37,8,STONE:5)
Block(-8,38,-7,STONE:0)
Block(-8,38,-6,STONE:3)
Block(-8,38,-5,STONE:3)
Block(-8,38,-4,STONE:3)
Block(-8,38,-3,STONE:3)
Block(-8,38,-2,STONE:3)
Block(-8,38,-1,STONE:3)
Block(-8,38,0,STONE:3)
Block(-8,38,1,OBSIDIAN:0)
Block(-8,38,2,OBSIDIAN:0)
Block(-8,38,3,OBSIDIAN:0)
Block(-8,38,4,STONE:5)
Block(-8,38,5,STONE:5)
Block(-8,38,6,STONE:5)
Block(-8,38,7,STONE:5)
Block(-8,38,8,STONE:5)
Block(-8,39,-7,STONE:3)
Block(-8,39,-6,STONE:3)
Block(-8,39,-5,STONE:3)
Block(-8,39,-4,STONE:3)
Block(-8,39,-3,STONE:3)
Block(-8,39,-2,STONE:3)
Block(-8,39,-1,STONE:3)
Block(-8,39,0,OBSIDIAN:0)
Block(-8,39,1,OBSIDIAN:0)
Block(-8,39,2,OBSIDIAN:0)
Block(-8,39,3,OBSIDIAN:0)
Block(-8,39,4,OBSIDIAN:0)
Block(-8,39,5,OBSIDIAN:0)
Block(-8,40,-7,STONE:3)
Block(-8,40,-6,STONE:3)
Block(-8,40,-5,STONE:3)
Block(-8,40,-4,STONE:3)
Block(-8,40,-3,STONE:3)
Block(-8,40,-2,STONE:3)
Block(-8,40,-1,STONE:3)
Block(-8,40,0,OBSIDIAN:0)
Block(-8,40,1,OBSIDIAN:0)
Block(-8,40,2,OBSIDIAN:0)
Block(-8,40,3,OBSIDIAN:0)
Block(-8,40,4,OBSIDIAN:0)
Block(-8,41,-7,STONE:3)
Block(-8,41,-6,STONE:3)
Block(-8,41,-5,STONE:3)
Block(-8,41,-4,STONE:3)
Block(-8,41,-3,STONE:3)
Block(-8,41,-2,STONE:3)
Block(-8,41,-1,STONE:3)
Block(-8,41,0,OBSIDIAN:0)
Block(-8,41,1,OBSIDIAN:0)
Block(-8,41,2,OBSIDIAN:0)
Block(-8,42,-7,STONE:3)
Block(-8,42,-6,STONE:3)
Block(-8,42,-5,STONE:3)
Block(-8,42,-4,STONE:3)
Block(-8,42,-3,STONE:3)
Block(-8,42,-2,STONE:3)
Block(-8,42,-1,STONE:3)
Block(-8,42,0,STONE:3)
Block(-8,43,-7,STONE:3)
Block(-8,43,-6,STONE:3)
Block(-8,43,-5,STONE:3)
Block(-8,43,-4,STONE:3)
Block(-8,43,-3,STONE:3)
Block(-8,43,-2,STONE:3)
Block(-8,44,-7,STONE:3)
Block(-8,44,-6,STONE:3)
Block(-8,44,-5,STONE:3)
Block(-8,44,-4,STONE:3)
Block(-8,44,-3,STONE:3)
Block(-8,45,-7,STONE:3)
Block(-8,45,-6,STONE:3)
Block(-8,45,-5,STONE:3)
Block(-8,47,-7,STONE:3)
Block(-8,48,-7,STONE:5)
Block(-7,3,-7,STONE:3)
Block(-7,3,-6,STONE:3)
Block(-7,4,-7,STONE:3)
Block(-7,4,-6,STONE:3)
Block(-7,4,-5,STONE:3)
Block(-7,5,-7,STONE:3)
Block(-7,5,-6,STONE:3)
Block(-7,5,-5,STONE:3)
Block(-7,5,-4,STONE:3)
Block(-7,6,-7,STONE:3)
Block(-7,6,-6,STONE:3)
Block(-7,6,-5,STONE:3)
Block(-7,6,-4,STONE:3)
Block(-7,6,-3,STONE:3)
Block(-7,7,-7,STONE:3)
Block(-7,7,-6,STONE:3)
Block(-7,7,-5,STONE:3)
Block(-7,7,-4,STONE:3)
Block(-7,7,-3,STONE:3)
Block(-7,7,-2,STONE:3)
Block(-7,7,-1,STONE:3)
Block(-7,8,-7,STONE:3)
Block(-7,8,-6,STONE:3)
Block(-7,8,-5,STONE:3)
Block(-7,8,-4,STONE:3)
Block(-7,8,-3,STONE:3)
Block(-7,8,-2,STONE:3)
Block(-7,8,-1,STONE:3)
Block(-7,8,0,STONE:3)
Block(-7,9,-7,STONE:3)
Block(-7,9,-6,STONE:3)
Block(-7,9,-5,STONE:3)
Block(-7,9,-4,STONE:3)
Block(-7,9,-3,STONE:3)
Block(-7,9,-2,STONE:3)
Block(-7,9,-1,STONE:3)
Block(-7,9,0,STONE:3)
Block(-7,9,1,STONE:3)
Block(-7,10,-7,STONE:3)
Block(-7,10,-6,STONE:3)
Block(-7,10,-5,STONE:3)
Block(-7,10,-4,STONE:3)
Block(-7,10,-3,STONE:3)
Block(-7,10,-2,STONE:3)
Block(-7,10,-1,STONE:3)
Block(-7,10,0,STONE:3)
Block(-7,10,1,STONE:3)
Block(-7,10,2,STONE:3)
Block(-7,11,-7,STONE:0)
Block(-7,11,-6,STONE:3)
Block(-7,11,-5,STONE:3)
Block(-7,11,-4,STONE:3)
Block(-7,11,-3,STONE:3)
Block(-7,11,-2,STONE:3)
Block(-7,11,-1,STONE:3)
Block(-7,11,0,STONE:3)
Block(-7,11,1,STONE:3)
Block(-7,11,2,STONE:3)
Block(-7,11,3,STONE:3)
Block(-7,11,4,STONE:3)
Block(-7,12,-7,STONE:0)
Block(-7,12,-6,STONE:0)
Block(-7,12,-5,STONE:0)
Block(-7,12,-4,STONE:3)
Block(-7,12,-3,STONE:3)
Block(-7,12,-2,STONE:3)
Block(-7,12,-1,STONE:3)
Block(-7,12,0,STONE:3)
Block(-7,12,1,STONE:3)
Block(-7,12,2,STONE:3)
Block(-7,12,3,STONE:3)
Block(-7,12,4,STONE:3)
Block(-7,12,5,STONE:3)
Block(-7,13,-7,STONE:0)
Block(-7,13,-6,STONE:0)
Block(-7,13,-5,STONE:0)
Block(-7,13,-4,STONE:0)
Block(-7,13,-3,STONE:3)
Block(-7,13,-2,STONE:3)
Block(-7,13,-1,STONE:3)
Block(-7,13,0,STONE:3)
Block(-7,13,1,STONE:3)
Block(-7,13,2,STONE:3)
Block(-7,13,3,STONE:3)
Block(-7,13,4,STONE:3)
Block(-7,13,5,STONE:3)
Block(-7,13,6,STONE:3)
Block(-7,13,7,STONE:3)
Block(-7,14,-7,STONE:0)
Block(-7,14,-6,STONE:0)
Block(-7,14,-5,STONE:0)
Block(-7,14,-4,STONE:0)
Block(-7,14,-3,STONE:0)
Block(-7,14,-2,STONE:0)
Block(-7,14,-1,STONE:3)
Block(-7,14,0,STONE:3)
Block(-7,14,1,STONE:3)
Block(-7,14,2,STONE:3)
Block(-7,14,3,STONE:3)
Block(-7,14,4,STONE:3)
Block(-7,14,5,STONE:3)
Block(-7,14,6,STONE:3)
Block(-7,14,7,STONE:3)
Block(-7,15,-7,STONE:0)
Block(-7,15,-6,STONE:0)
Block(-7,15,-5,STONE:0)
Block(-7,15,-4,STONE:0)
Block(-7,15,-3,STONE:0)
Block(-7,15,-2,STONE:0)
Block(-7,15,-1,STONE:0)
Block(-7,15,0,STONE:3)
Block(-7,15,1,STONE:3)
Block(-7,15,2,STONE:3)
Block(-7,15,3,STONE:3)
Block(-7,15,4,STONE:3)
Block(-7,15,5,STONE:3)
Block(-7,15,6,STONE:3)
Block(-7,15,7,STONE:3)
Block(-7,15,8,STONE:3)
Block(-7,16,-7,STONE:0)
Block(-7,16,-6,STONE:0)
Block(-7,16,-5,STONE:0)
Block(-7,16,-4,STONE:0)
Block(-7,16,-3,STONE:0)
Block(-7,16,-2,STONE:0)
Block(-7,16,-1,STONE:0)
Block(-7,16,0,STONE:0)
Block(-7,16,1,STONE:3)
Block(-7,16,2,STONE:3)
Block(-7,16,3,STONE:3)
Block(-7,16,4,STONE:3)
Block(-7,16,5,STONE:3)
Block(-7,16,6,STONE:3)
Block(-7,16,7,STONE:3)
Block(-7,16,8,STONE:3)
Block(-7,17,-7,OBSIDIAN:0)
Block(-7,17,-6,STONE:0)
Block(-7,17,-5,STONE:0)
Block(-7,17,-4,STONE:0)
Block(-7,17,-3,STONE:0)
Block(-7,17,-2,STONE:0)
Block(-7,17,-1,STONE:0)
Block(-7,17,0,STONE:0)
Block(-7,17,1,STONE:0)
Block(-7,17,2,STONE:0)
Block(-7,17,3,STONE:0)
Block(-7,17,4,STONE:0)
Block(-7,17,5,STONE:3)
Block(-7,17,6,STONE:3)
Block(-7,17,7,STONE:3)
Block(-7,17,8,STONE:3)
Block(-7,18,-7,OBSIDIAN:0)
Block(-7,18,-6,OBSIDIAN:0)
Block(-7,18,-5,STONE:0)
Block(-7,18,-4,STONE:0)
Block(-7,18,-3,STONE:0)
Block(-7,18,-2,STONE:0)
Block(-7,18,-1,STONE:0)
Block(-7,18,0,STONE:0)
Block(-7,18,1,STONE:0)
Block(-7,18,2,STONE:0)
Block(-7,18,3,STONE:0)
Block(-7,18,4,STONE:0)
Block(-7,18,5,STONE:0)
Block(-7,18,6,STONE:3)
Block(-7,18,7,STONE:3)
Block(-7,18,8,STONE:3)
Block(-7,19,-7,AIR:0)
Block(-7,19,-6,AIR:0)
Block(-7,19,-5,GRASS:0)
Block(-7,19,-4,GRASS:0)
Block(-7,19,-3,GRASS:0)
Block(-7,19,-2,STONE:0)
Block(-7,19,-1,STONE:0)
Block(-7,19,0,STONE:0)
Block(-7,19,1,STONE:0)
Block(-7,19,2,STONE:0)
Block(-7,19,3,STONE:0)
Block(-7,19,4,STONE:0)
Block(-7,19,5,STONE:0)
Block(-7,19,6,STONE:0)
Block(-7,19,7,STONE:0)
Block(-7,19,8,STONE:5)
Block(-7,20,-7,AIR:0)
Block(-7,20,-6,AIR:0)
Block(-7,20,-5,AIR:0)
Block(-7,20,-4,AIR:0)
Block(-7,20,-3,AIR:0)
Block(-7,20,-2,GRASS:0)
Block(-7,20,-1,GRASS:0)
Block(-7,20,0,STONE:0)
Block(-7,20,1,STONE:0)
Block(-7,20,2,STONE:0)
Block(-7,20,3,STONE:0)
Block(-7,20,4,STONE:0)
Block(-7,20,5,STONE:0)
Block(-7,20,6,STONE:0)
Block(-7,20,7,STONE:0)
Block(-7,20,8,STONE:0)
Block(-7,21,-7,AIR:0)
Block(-7,21,-6,AIR:0)
Block(-7,21,-5,AIR:0)
Block(-7,21,-4,AIR:0)
Block(-7,21,-3,AIR:0)
Block(-7,21,-2,AIR:0)
Block(-7,21,-1,AIR:0)
Block(-7,21,0,STONE:0)
Block(-7,21,1,STONE:0)
Block(-7,21,2,STONE:0)
Block(-7,21,3,STONE:0)
Block(-7,21,4,STONE:0)
Block(-7,21,5,STONE:0)
Block(-7,21,6,STONE:0)
Block(-7,21,7,STONE:0)
Block(-7,21,8,STONE:0)
Block(-7,22,-7,AIR:0)
Block(-7,22,-6,AIR:0)
Block(-7,22,-5,AIR:0)
Block(-7,22,-4,AIR:0)
Block(-7,22,-3,AIR:0)
Block(-7,22,-2,AIR:0)
Block(-7,22,-1,AIR:0)
Block(-7,22,0,AIR:0)
Block(-7,22,1,STONE:0)
Block(-7,22,2,STONE:0)
Block(-7,22,3,STONE:0)
Block(-7,22,4,STONE:0)
Block(-7,22,5,STONE:0)
Block(-7,22,6,STONE:0)
Block(-7,22,7,STONE:0)
Block(-7,22,8,STONE:0)
Block(-7,23,-7,AIR:0)
Block(-7,23,-6,AIR:0)
Block(-7,23,-5,AIR:0)
Block(-7,23,-4,AIR:0)
Block(-7,23,-3,AIR:0)
Block(-7,23,-2,AIR:0)
Block(-7,23,-1,AIR:0)
Block(-7,23,0,AIR:0)
Block(-7,23,1,AIR:0)
Block(-7,23,2,STONE:0)
Block(-7,23,3,STONE:0)
Block(-7,23,4,STONE:0)
Block(-7,23,5,STONE:0)
Block(-7,23,6,STONE:0)
Block(-7,23,7,STONE:0)
Block(-7,23,8,STONE:0)
Block(-7,24,-7,AIR:0)
Block(-7,24,-6,AIR:0)
Block(-7,24,-5,AIR:0)
Block(-7,24,-4,AIR:0)
Block(-7,24,-3,AIR:0)
Block(-7,24,-2,AIR:0)
Block(-7,24,-1,AIR:0)
Block(-7,24,0,AIR:0)
Block(-7,24,1,STONE:0)
Block(-7,24,2,STONE:0)
Block(-7,24,3,STONE:0)
Block(-7,24,4,STONE:0)
Block(-7,24,5,STONE:0)
Block(-7,24,6,STONE:0)
Block(-7,24,7,STONE:0)
Block(-7,24,8,STONE:0)
Block(-7,25,-7,AIR:0)
Block(-7,25,-6,AIR:0)
Block(-7,25,-5,AIR:0)
Block(-7,25,-4,AIR:0)
Block(-7,25,-3,AIR:0)
Block(-7,25,-2,AIR:0)
Block(-7,25,-1,AIR:0)
Block(-7,25,0,AIR:0)
Block(-7,25,1,STONE:0)
Block(-7,25,2,STONE:0)
Block(-7,25,3,STONE:0)
Block(-7,25,4,STONE:0)
Block(-7,25,5,STONE:0)
Block(-7,25,6,STONE:0)
Block(-7,25,7,STONE:0)
Block(-7,25,8,STONE:0)
Block(-7,26,-7,AIR:0)
Block(-7,26,-6,AIR:0)
Block(-7,26,-5,AIR:0)
Block(-7,26,-4,AIR:0)
Block(-7,26,-3,AIR:0)
Block(-7,26,-2,AIR:0)
Block(-7,26,-1,AIR:0)
Block(-7,26,0,STONE:0)
Block(-7,26,1,STONE:0)
Block(-7,26,2,STONE:0)
Block(-7,26,3,STONE:0)
Block(-7,26,4,STONE:0)
Block(-7,26,5,STONE:0)
Block(-7,26,6,STONE:0)
Block(-7,26,7,STONE:0)
Block(-7,26,8,STONE:0)
Block(-7,27,-7,AIR:0)
Block(-7,27,-6,AIR:0)
Block(-7,27,-5,AIR:0)
Block(-7,27,-4,AIR:0)
Block(-7,27,-3,AIR:0)
Block(-7,27,-2,AIR:0)
Block(-7,27,-1,STONE:0)
Block(-7,27,0,STONE:0)
Block(-7,27,1,STONE:0)
Block(-7,27,2,STONE:0)
Block(-7,27,3,STONE:0)
Block(-7,27,4,STONE:0)
Block(-7,27,5,STONE:0)
Block(-7,27,6,STONE:0)
Block(-7,27,7,STONE:5)
Block(-7,27,8,STONE:5)
Block(-7,28,-7,AIR:0)
Block(-7,28,-6,AIR:0)
Block(-7,28,-5,AIR:0)
Block(-7,28,-4,AIR:0)
Block(-7,28,-3,AIR:0)
Block(-7,28,-2,STONE:0)
Block(-7,28,-1,STONE:0)
Block(-7,28,0,STONE:0)
Block(-7,28,1,STONE:0)
Block(-7,28,2,STONE:0)
Block(-7,28,3,STONE:0)
Block(-7,28,4,STONE:0)
Block(-7,28,5,STONE:0)
Block(-7,28,6,STONE:5)
Block(-7,28,7,STONE:5)
Block(-7,28,8,STONE:5)
Block(-7,29,-7,AIR:0)
Block(-7,29,-6,AIR:0)
Block(-7,29,-5,AIR:0)
Block(-7,29,-4,AIR:0)
Block(-7,29,-3,STONE:0)
Block(-7,29,-2,STONE:0)
Block(-7,29,-1,STONE:0)
Block(-7,29,0,STONE:0)
Block(-7,29,1,STONE:0)
Block(-7,29,2,STONE:0)
Block(-7,29,3,STONE:0)
Block(-7,29,4,STONE:0)
Block(-7,29,5,STONE:0)
Block(-7,29,6,STONE:5)
Block(-7,29,7,STONE:5)
Block(-7,29,8,STONE:5)
Block(-7,30,-7,AIR:0)
Block(-7,30,-6,AIR:0)
Block(-7,30,-5,AIR:0)
Block(-7,30,-4,STONE:0)
Block(-7,30,-3,STONE:0)
Block(-7,30,-2,STONE:0)
Block(-7,30,-1,STONE:0)
Block(-7,30,0,STONE:0)
Block(-7,30,1,STONE:0)
Block(-7,30,2,STONE:0)
Block(-7,30,3,STONE:0)
Block(-7,30,4,STONE:0)
Block(-7,30,5,STONE:5)
Block(-7,30,6,STONE:5)
Block(-7,30,7,STONE:5)
Block(-7,30,8,STONE:5)
Block(-7,31,-7,AIR:0)
Block(-7,31,-6,AIR:0)
Block(-7,31,-5,STONE:0)
Block(-7,31,-4,STONE:0)
Block(-7,31,-3,STONE:0)
Block(-7,31,-2,STONE:0)
Block(-7,31,-1,STONE:0)
Block(-7,31,0,STONE:0)
Block(-7,31,1,STONE:0)
Block(-7,31,2,STONE:0)
Block(-7,31,3,STONE:0)
Block(-7,31,4,STONE:0)
Block(-7,31,5,STONE:5)
Block(-7,31,6,STONE:5)
Block(-7,31,7,STONE:5)
Block(-7,31,8,STONE:5)
Block(-7,32,-7,AIR:0)
Block(-7,32,-6,STONE:0)
Block(-7,32,-5,STONE:0)
Block(-7,32,-4,STONE:0)
Block(-7,32,-3,STONE:0)
Block(-7,32,-2,STONE:0)
Block(-7,32,-1,STONE:0)
Block(-7,32,0,STONE:0)
Block(-7,32,1,STONE:0)
Block(-7,32,2,STONE:0)
Block(-7,32,3,STONE:5)
Block(-7,32,4,STONE:5)
Block(-7,32,5,STONE:5)
Block(-7,32,6,STONE:5)
Block(-7,32,7,STONE:5)
Block(-7,32,8,STONE:5)
Block(-7,33,-7,STONE:0)
Block(-7,33,-6,STONE:0)
Block(-7,33,-5,STONE:0)
Block(-7,33,-4,STONE:0)
Block(-7,33,-3,STONE:0)
Block(-7,33,-2,STONE:0)
Block(-7,33,-1,STONE:0)
Block(-7,33,0,STONE:0)
Block(-7,33,1,STONE:5)
Block(-7,33,2,STONE:5)
Block(-7,33,3,STONE:5)
Block(-7,33,4,STONE:5)
Block(-7,33,5,STONE:5)
Block(-7,33,6,STONE:5)
Block(-7,33,7,STONE:5)
Block(-7,33,8,STONE:5)
Block(-7,34,-7,STONE:0)
Block(-7,34,-6,STONE:0)
Block(-7,34,-5,STONE:0)
Block(-7,34,-4,STONE:0)
Block(-7,34,-3,STONE:0)
Block(-7,34,-2,STONE:0)
Block(-7,34,-1,STONE:0)
Block(-7,34,0,STONE:5)
Block(-7,34,1,STONE:5)
Block(-7,34,2,STONE:5)
Block(-7,34,3,STONE:5)
Block(-7,34,4,STONE:5)
Block(-7,34,5,STONE:5)
Block(-7,34,6,STONE:5)
Block(-7,34,7,STONE:5)
Block(-7,34,8,STONE:5)
Block(-7,35,-7,STONE:0)
Block(-7,35,-6,STONE:0)
Block(-7,35,-5,STONE:0)
Block(-7,35,-4,STONE:0)
Block(-7,35,-3,STONE:0)
Block(-7,35,-2,STONE:0)
Block(-7,35,-1,STONE:0)
Block(-7,35,0,STONE:5)
Block(-7,35,1,STONE:5)
Block(-7,35,2,STONE:5)
Block(-7,35,3,STONE:5)
Block(-7,35,4,STONE:5)
Block(-7,35,5,STONE:5)
Block(-7,35,6,STONE:5)
Block(-7,35,7,STONE:5)
Block(-7,35,8,STONE:5)
Block(-7,36,-7,STONE:0)
Block(-7,36,-6,STONE:0)
Block(-7,36,-5,STONE:0)
Block(-7,36,-4,STONE:0)
Block(-7,36,-3,STONE:0)
Block(-7,36,-2,STONE:0)
Block(-7,36,-1,STONE:0)
Block(-7,36,0,STONE:5)
Block(-7,36,1,STONE:5)
Block(-7,36,2,STONE:5)
Block(-7,36,3,STONE:5)
Block(-7,36,4,STONE:5)
Block(-7,36,5,STONE:5)
Block(-7,37,-7,STONE:0)
Block(-7,37,-6,STONE:0)
Block(-7,37,-5,STONE:0)
Block(-7,37,-4,STONE:0)
Block(-7,37,-3,STONE:0)
Block(-7,37,-2,STONE:3)
Block(-7,37,-1,STONE:3)
Block(-7,37,0,STONE:3)
Block(-7,37,1,STONE:3)
Block(-7,37,2,STONE:3)
Block(-7,37,3,STONE:5)
Block(-7,37,4,STONE:5)
Block(-7,38,-7,STONE:0)
Block(-7,38,-6,STONE:3)
Block(-7,38,-5,STONE:3)
Block(-7,38,-4,STONE:3)
Block(-7,38,-3,STONE:3)
Block(-7,38,-2,STONE:3)
Block(-7,38,-1,STONE:3)
Block(-7,38,0,STONE:3)
Block(-7,38,1,OBSIDIAN:0)
Block(-7,38,2,OBSIDIAN:0)
Block(-7,38,3,OBSIDIAN:0)
Block(-7,38,4,STONE:5)
Block(-7,39,-7,STONE:3)
Block(-7,39,-6,STONE:3)
Block(-7,39,-5,STONE:3)
Block(-7,39,-4,STONE:3)
Block(-7,39,-3,STONE:3)
Block(-7,39,-2,STONE:3)
Block(-7,39,-1,STONE:3)
Block(-7,39,0,OBSIDIAN:0)
Block(-7,39,1,OBSIDIAN:0)
Block(-7,39,2,OBSIDIAN:0)
Block(-7,39,3,OBSIDIAN:0)
Block(-7,40,-7,STONE:3)
Block(-7,40,-6,STONE:3)
Block(-7,40,-5,STONE:3)
Block(-7,40,-4,STONE:3)
Block(-7,40,-3,STONE:3)
Block(-7,40,-2,STONE:3)
Block(-7,40,-1,OBSIDIAN:0)
Block(-7,40,0,OBSIDIAN:0)
Block(-7,40,1,OBSIDIAN:0)
Block(-7,40,2,OBSIDIAN:0)
Block(-7,41,-7,STONE:3)
Block(-7,41,-6,STONE:3)
Block(-7,41,-5,STONE:3)
Block(-7,41,-4,STONE:3)
Block(-7,41,-3,STONE:3)
Block(-7,41,-2,STONE:3)
Block(-7,41,-1,OBSIDIAN:0)
Block(-7,41,0,OBSIDIAN:0)
Block(-7,41,1,OBSIDIAN:0)
Block(-7,42,-7,STONE:3)
Block(-7,42,-6,STONE:3)
Block(-7,42,-5,STONE:3)
Block(-7,42,-4,STONE:3)
Block(-7,42,-3,STONE:3)
Block(-7,42,-2,STONE:3)
Block(-7,42,-1,OBSIDIAN:0)
Block(-7,43,-7,STONE:3)
Block(-7,43,-6,STONE:3)
Block(-7,43,-5,STONE:3)
Block(-7,43,-4,STONE:3)
Block(-7,43,-3,STONE:3)
Block(-7,43,-2,STONE:3)
Block(-7,44,-7,STONE:3)
Block(-7,44,-6,STONE:3)
Block(-7,44,-5,STONE:3)
Block(-7,45,-7,STONE:3)
Block(-7,45,-6,STONE:3)
Block(-6,3,-7,STONE:3)
Block(-6,4,-7,STONE:3)
Block(-6,4,-6,STONE:3)
Block(-6,4,-5,STONE:3)
Block(-6,5,-7,STONE:3)
Block(-6,5,-6,STONE:3)
Block(-6,5,-5,STONE:3)
Block(-6,5,-4,STONE:3)
Block(-6,6,-7,STONE:3)
Block(-6,6,-6,STONE:3)
Block(-6,6,-5,STONE:3)
Block(-6,6,-4,STONE:3)
Block(-6,7,-7,STONE:3)
Block(-6,7,-6,STONE:3)
Block(-6,7,-5,STONE:3)
Block(-6,7,-4,STONE:3)
Block(-6,7,-3,STONE:3)
Block(-6,7,-2,STONE:3)
Block(-6,7,-1,STONE:3)
Block(-6,8,-7,STONE:3)
Block(-6,8,-6,STONE:3)
Block(-6,8,-5,STONE:3)
Block(-6,8,-4,STONE:3)
Block(-6,8,-3,STONE:3)
Block(-6,8,-2,STONE:3)
Block(-6,8,-1,STONE:3)
Block(-6,8,0,STONE:3)
Block(-6,9,-7,STONE:3)
Block(-6,9,-6,STONE:3)
Block(-6,9,-5,STONE:3)
Block(-6,9,-4,STONE:3)
Block(-6,9,-3,STONE:3)
Block(-6,9,-2,STONE:3)
Block(-6,9,-1,STONE:3)
Block(-6,9,0,STONE:3)
Block(-6,9,1,STONE:3)
Block(-6,10,-7,STONE:3)
Block(-6,10,-6,STONE:3)
Block(-6,10,-5,STONE:3)
Block(-6,10,-4,STONE:3)
Block(-6,10,-3,STONE:3)
Block(-6,10,-2,STONE:3)
Block(-6,10,-1,STONE:3)
Block(-6,10,0,STONE:3)
Block(-6,10,1,STONE:3)
Block(-6,11,-7,STONE:3)
Block(-6,11,-6,STONE:3)
Block(-6,11,-5,STONE:3)
Block(-6,11,-4,STONE:3)
Block(-6,11,-3,STONE:3)
Block(-6,11,-2,STONE:3)
Block(-6,11,-1,STONE:3)
Block(-6,11,0,STONE:3)
Block(-6,11,1,STONE:3)
Block(-6,11,2,STONE:3)
Block(-6,11,3,STONE:3)
Block(-6,12,-7,STONE:0)
Block(-6,12,-6,STONE:0)
Block(-6,12,-5,STONE:3)
Block(-6,12,-4,STONE:3)
Block(-6,12,-3,STONE:3)
Block(-6,12,-2,STONE:3)
Block(-6,12,-1,STONE:3)
Block(-6,12,0,STONE:3)
Block(-6,12,1,STONE:3)
Block(-6,12,2,STONE:3)
Block(-6,12,3,STONE:3)
Block(-6,12,4,STONE:3)
Block(-6,13,-7,STONE:0)
Block(-6,13,-6,STONE:0)
Block(-6,13,-5,STONE:0)
Block(-6,13,-4,STONE:0)
Block(-6,13,-3,STONE:3)
Block(-6,13,-2,STONE:3)
Block(-6,13,-1,STONE:3)
Block(-6,13,0,STONE:3)
Block(-6,13,1,STONE:3)
Block(-6,13,2,STONE:3)
Block(-6,13,3,STONE:3)
Block(-6,13,4,STONE:3)
Block(-6,13,5,STONE:3)
Block(-6,13,6,STONE:3)
Block(-6,13,7,STONE:3)
Block(-6,14,-7,STONE:0)
Block(-6,14,-6,STONE:0)
Block(-6,14,-5,STONE:0)
Block(-6,14,-4,STONE:0)
Block(-6,14,-3,STONE:0)
Block(-6,14,-2,STONE:3)
Block(-6,14,-1,STONE:3)
Block(-6,14,0,STONE:3)
Block(-6,14,1,STONE:3)
Block(-6,14,2,STONE:3)
Block(-6,14,3,STONE:3)
Block(-6,14,4,STONE:3)
Block(-6,14,5,STONE:3)
Block(-6,14,6,STONE:3)
Block(-6,14,7,STONE:3)
Block(-6,14,8,STONE:3)
Block(-6,15,-7,STONE:0)
Block(-6,15,-6,STONE:0)
Block(-6,15,-5,STONE:0)
Block(-6,15,-4,STONE:0)
Block(-6,15,-3,STONE:0)
Block(-6,15,-2,STONE:0)
Block(-6,15,-1,STONE:0)
Block(-6,15,0,STONE:3)
Block(-6,15,1,STONE:3)
Block(-6,15,2,STONE:3)
Block(-6,15,3,STONE:3)
Block(-6,15,4,STONE:3)
Block(-6,15,5,STONE:3)
Block(-6,15,6,STONE:3)
Block(-6,15,7,STONE:3)
Block(-6,15,8,STONE:3)
Block(-6,16,-7,STONE:0)
Block(-6,16,-6,STONE:0)
Block(-6,16,-5,STONE:0)
Block(-6,16,-4,STONE:0)
Block(-6,16,-3,STONE:0)
Block(-6,16,-2,STONE:0)
Block(-6,16,-1,STONE:0)
Block(-6,16,0,STONE:0)
Block(-6,16,1,STONE:3)
Block(-6,16,2,STONE:3)
Block(-6,16,3,STONE:3)
Block(-6,16,4,STONE:3)
Block(-6,16,5,STONE:3)
Block(-6,16,6,STONE:3)
Block(-6,16,7,STONE:3)
Block(-6,16,8,STONE:3)
Block(-6,17,-7,STONE:0)
Block(-6,17,-6,STONE:0)
Block(-6,17,-5,STONE:0)
Block(-6,17,-4,STONE:0)
Block(-6,17,-3,STONE:0)
Block(-6,17,-2,STONE:0)
Block(-6,17,-1,STONE:0)
Block(-6,17,0,STONE:0)
Block(-6,17,1,STONE:0)
Block(-6,17,2,STONE:0)
Block(-6,17,3,STONE:3)
Block(-6,17,4,STONE:3)
Block(-6,17,5,STONE:3)
Block(-6,17,6,STONE:3)
Block(-6,17,7,STONE:3)
Block(-6,17,8,STONE:3)
Block(-6,18,-7,OBSIDIAN:0)
Block(-6,18,-6,STONE:0)
Block(-6,18,-5,STONE:0)
Block(-6,18,-4,STONE:0)
Block(-6,18,-3,STONE:0)
Block(-6,18,-2,STONE:0)
Block(-6,18,-1,STONE:0)
Block(-6,18,0,STONE:0)
Block(-6,18,1,STONE:0)
Block(-6,18,2,STONE:0)
Block(-6,18,3,STONE:0)
Block(-6,18,4,STONE:3)
Block(-6,18,5,STONE:3)
Block(-6,18,6,STONE:3)
Block(-6,18,7,STONE:3)
Block(-6,18,8,STONE:3)
Block(-6,19,-7,AIR:0)
Block(-6,19,-6,GRASS:0)
Block(-6,19,-5,STONE:0)
Block(-6,19,-4,STONE:0)
Block(-6,19,-3,STONE:0)
Block(-6,19,-2,STONE:0)
Block(-6,19,-1,STONE:0)
Block(-6,19,0,STONE:0)
Block(-6,19,1,STONE:0)
Block(-6,19,2,STONE:0)
Block(-6,19,3,STONE:0)
Block(-6,19,4,STONE:0)
Block(-6,19,5,STONE:3)
Block(-6,19,6,STONE:3)
Block(-6,19,7,STONE:3)
Block(-6,19,8,STONE:3)
Block(-6,20,-7,AIR:0)
Block(-6,20,-6,AIR:0)
Block(-6,20,-5,GRASS:0)
Block(-6,20,-4,GRASS:0)
Block(-6,20,-3,GRASS:0)
Block(-6,20,-2,GRASS:0)
Block(-6,20,-1,STONE:0)
Block(-6,20,0,STONE:0)
Block(-6,20,1,STONE:0)
Block(-6,20,2,STONE:0)
Block(-6,20,3,STONE:0)
Block(-6,20,4,STONE:0)
Block(-6,20,5,STONE:0)
Block(-6,20,6,STONE:0)
Block(-6,20,7,STONE:0)
Block(-6,20,8,STONE:0)
Block(-6,21,-7,AIR:0)
Block(-6,21,-6,AIR:0)
Block(-6,21,-5,AIR:0)
Block(-6,21,-4,AIR:0)
Block(-6,21,-3,AIR:0)
Block(-6,21,-2,AIR:0)
Block(-6,21,-1,GRASS:0)
Block(-6,21,0,GRASS:0)
Block(-6,21,1,STONE:0)
Block(-6,21,2,STONE:0)
Block(-6,21,3,STONE:0)
Block(-6,21,4,STONE:0)
Block(-6,21,5,STONE:0)
Block(-6,21,6,STONE:0)
Block(-6,21,7,STONE:0)
Block(-6,21,8,STONE:0)
Block(-6,22,-7,AIR:0)
Block(-6,22,-6,AIR:0)
Block(-6,22,-5,AIR:0)
Block(-6,22,-4,AIR:0)
Block(-6,22,-3,AIR:0)
Block(-6,22,-2,AIR:0)
Block(-6,22,-1,AIR:0)
Block(-6,22,0,AIR:0)
Block(-6,22,1,STONE:0)
Block(-6,22,2,STONE:0)
Block(-6,22,3,STONE:0)
Block(-6,22,4,STONE:0)
Block(-6,22,5,STONE:0)
Block(-6,22,6,STONE:0)
Block(-6,22,7,STONE:0)
Block(-6,22,8,STONE:0)
Block(-6,23,-7,AIR:0)
Block(-6,23,-6,AIR:0)
Block(-6,23,-5,AIR:0)
Block(-6,23,-4,AIR:0)
Block(-6,23,-3,AIR:0)
Block(-6,23,-2,AIR:0)
Block(-6,23,-1,AIR:0)
Block(-6,23,0,AIR:0)
Block(-6,23,1,STONE:0)
Block(-6,23,2,STONE:0)
Block(-6,23,3,STONE:0)
Block(-6,23,4,STONE:0)
Block(-6,23,5,STONE:0)
Block(-6,23,6,STONE:0)
Block(-6,23,7,STONE:0)
Block(-6,23,8,STONE:0)
Block(-6,24,-7,AIR:0)
Block(-6,24,-6,AIR:0)
Block(-6,24,-5,AIR:0)
Block(-6,24,-4,AIR:0)
Block(-6,24,-3,AIR:0)
Block(-6,24,-2,AIR:0)
Block(-6,24,-1,AIR:0)
Block(-6,24,0,AIR:0)
Block(-6,24,1,STONE:0)
Block(-6,24,2,STONE:0)
Block(-6,24,3,STONE:0)
Block(-6,24,4,STONE:0)
Block(-6,24,5,STONE:0)
Block(-6,24,6,STONE:0)
Block(-6,24,7,STONE:0)
Block(-6,24,8,STONE:0)
Block(-6,25,-7,AIR:0)
Block(-6,25,-6,AIR:0)
Block(-6,25,-5,AIR:0)
Block(-6,25,-4,AIR:0)
Block(-6,25,-3,AIR:0)
Block(-6,25,-2,AIR:0)
Block(-6,25,-1,AIR:0)
Block(-6,25,0,STONE:0)
Block(-6,25,1,STONE:0)
Block(-6,25,2,STONE:0)
Block(-6,25,3,STONE:0)
Block(-6,25,4,STONE:0)
Block(-6,25,5,STONE:0)
Block(-6,25,6,STONE:0)
Block(-6,25,7,STONE:0)
Block(-6,25,8,STONE:0)
Block(-6,26,-7,AIR:0)
Block(-6,26,-6,AIR:0)
Block(-6,26,-5,AIR:0)
Block(-6,26,-4,AIR:0)
Block(-6,26,-3,AIR:0)
Block(-6,26,-2,AIR:0)
Block(-6,26,-1,STONE:0)
Block(-6,26,0,STONE:0)
Block(-6,26,1,STONE:0)
Block(-6,26,2,STONE:0)
Block(-6,26,3,STONE:0)
Block(-6,26,4,STONE:0)
Block(-6,26,5,STONE:0)
Block(-6,26,6,STONE:0)
Block(-6,26,7,STONE:5)
Block(-6,26,8,STONE:5)
Block(-6,27,-7,AIR:0)
Block(-6,27,-6,AIR:0)
Block(-6,27,-5,AIR:0)
Block(-6,27,-4,AIR:0)
Block(-6,27,-3,AIR:0)
Block(-6,27,-2,STONE:0)
Block(-6,27,-1,STONE:0)
Block(-6,27,0,STONE:0)
Block(-6,27,1,STONE:0)
Block(-6,27,2,STONE:0)
Block(-6,27,3,STONE:0)
Block(-6,27,4,STONE:0)
Block(-6,27,5,STONE:0)
Block(-6,27,6,STONE:5)
Block(-6,27,7,STONE:5)
Block(-6,27,8,STONE:5)
Block(-6,28,-7,AIR:0)
Block(-6,28,-6,AIR:0)
Block(-6,28,-5,AIR:0)
Block(-6,28,-4,AIR:0)
Block(-6,28,-3,STONE:0)
Block(-6,28,-2,STONE:0)
Block(-6,28,-1,STONE:0)
Block(-6,28,0,STONE:0)
Block(-6,28,1,STONE:0)
Block(-6,28,2,STONE:0)
Block(-6,28,3,STONE:0)
Block(-6,28,4,STONE:0)
Block(-6,28,5,STONE:0)
Block(-6,28,6,STONE:5)
Block(-6,28,7,STONE:5)
Block(-6,28,8,STONE:5)
Block(-6,29,-7,AIR:0)
Block(-6,29,-6,AIR:0)
Block(-6,29,-5,AIR:0)
Block(-6,29,-4,AIR:0)
Block(-6,29,-3,STONE:0)
Block(-6,29,-2,STONE:0)
Block(-6,29,-1,STONE:0)
Block(-6,29,0,STONE:0)
Block(-6,29,1,STONE:0)
Block(-6,29,2,STONE:0)
Block(-6,29,3,STONE:0)
Block(-6,29,4,STONE:0)
Block(-6,29,5,STONE:5)
Block(-6,29,6,STONE:5)
Block(-6,29,7,STONE:5)
Block(-6,29,8,STONE:5)
Block(-6,30,-7,AIR:0)
Block(-6,30,-6,AIR:0)
Block(-6,30,-5,AIR:0)
Block(-6,30,-4,STONE:0)
Block(-6,30,-3,STONE:0)
Block(-6,30,-2,STONE:0)
Block(-6,30,-1,STONE:0)
Block(-6,30,0,STONE:0)
Block(-6,30,1,STONE:0)
Block(-6,30,2,STONE:0)
Block(-6,30,3,STONE:0)
Block(-6,30,4,STONE:0)
Block(-6,30,5,STONE:5)
Block(-6,30,6,STONE:5)
Block(-6,30,7,STONE:5)
Block(-6,30,8,STONE:5)
Block(-6,31,-7,AIR:0)
Block(-6,31,-6,STONE:0)
Block(-6,31,-5,STONE:0)
Block(-6,31,-4,STONE:0)
Block(-6,31,-3,STONE:0)
Block(-6,31,-2,STONE:0)
Block(-6,31,-1,STONE:0)
Block(-6,31,0,STONE:0)
Block(-6,31,1,STONE:0)
Block(-6,31,2,STONE:0)
Block(-6,31,3,STONE:0)
Block(-6,31,4,STONE:0)
Block(-6,31,5,STONE:5)
Block(-6,31,6,STONE:5)
Block(-6,31,7,STONE:5)
Block(-6,31,8,STONE:5)
Block(-6,32,-7,STONE:0)
Block(-6,32,-6,STONE:0)
Block(-6,32,-5,STONE:0)
Block(-6,32,-4,STONE:0)
Block(-6,32,-3,STONE:0)
Block(-6,32,-2,STONE:0)
Block(-6,32,-1,STONE:0)
Block(-6,32,0,STONE:0)
Block(-6,32,1,STONE:5)
Block(-6,32,2,STONE:5)
Block(-6,32,3,STONE:5)
Block(-6,32,4,STONE:5)
Block(-6,32,5,STONE:5)
Block(-6,32,6,STONE:5)
Block(-6,32,7,STONE:5)
Block(-6,32,8,STONE:5)
Block(-6,33,-7,STONE:0)
Block(-6,33,-6,STONE:0)
Block(-6,33,-5,STONE:0)
Block(-6,33,-4,STONE:0)
Block(-6,33,-3,STONE:0)
Block(-6,33,-2,STONE:0)
Block(-6,33,-1,STONE:0)
Block(-6,33,0,STONE:5)
Block(-6,33,1,STONE:5)
Block(-6,33,2,STONE:5)
Block(-6,33,3,STONE:5)
Block(-6,33,4,STONE:5)
Block(-6,33,5,STONE:5)
Block(-6,33,6,STONE:5)
Block(-6,33,7,STONE:5)
Block(-6,33,8,STONE:5)
Block(-6,34,-7,STONE:0)
Block(-6,34,-6,STONE:0)
Block(-6,34,-5,STONE:0)
Block(-6,34,-4,STONE:0)
Block(-6,34,-3,STONE:0)
Block(-6,34,-2,STONE:0)
Block(-6,34,-1,STONE:5)
Block(-6,34,0,STONE:5)
Block(-6,34,1,STONE:5)
Block(-6,34,2,STONE:5)
Block(-6,34,3,STONE:5)
Block(-6,34,4,STONE:5)
Block(-6,34,5,STONE:5)
Block(-6,34,6,STONE:5)
Block(-6,34,7,STONE:5)
Block(-6,34,8,STONE:5)
Block(-6,35,-7,STONE:0)
Block(-6,35,-6,STONE:0)
Block(-6,35,-5,STONE:0)
Block(-6,35,-4,STONE:0)
Block(-6,35,-3,STONE:0)
Block(-6,35,-2,STONE:0)
Block(-6,35,-1,STONE:5)
Block(-6,35,0,STONE:5)
Block(-6,35,1,STONE:5)
Block(-6,35,2,STONE:5)
Block(-6,35,3,STONE:5)
Block(-6,35,4,STONE:5)
Block(-6,35,5,STONE:5)
Block(-6,35,6,STONE:5)
Block(-6,35,7,STONE:5)
Block(-6,36,-7,STONE:0)
Block(-6,36,-6,STONE:0)
Block(-6,36,-5,STONE:0)
Block(-6,36,-4,STONE:0)
Block(-6,36,-3,STONE:0)
Block(-6,36,-2,STONE:0)
Block(-6,36,-1,STONE:5)
Block(-6,36,0,STONE:5)
Block(-6,36,1,STONE:5)
Block(-6,36,2,STONE:5)
Block(-6,36,3,STONE:5)
Block(-6,36,4,STONE:5)
Block(-6,37,-7,STONE:0)
Block(-6,37,-6,STONE:0)
Block(-6,37,-5,STONE:0)
Block(-6,37,-4,STONE:0)
Block(-6,37,-3,STONE:0)
Block(-6,37,-2,STONE:0)
Block(-6,37,-1,STONE:3)
Block(-6,37,0,STONE:3)
Block(-6,37,1,STONE:3)
Block(-6,37,2,STONE:5)
Block(-6,37,3,STONE:5)
Block(-6,37,4,STONE:5)
Block(-6,38,-7,STONE:0)
Block(-6,38,-6,STONE:3)
Block(-6,38,-5,STONE:3)
Block(-6,38,-4,STONE:3)
Block(-6,38,-3,STONE:3)
Block(-6,38,-2,STONE:3)
Block(-6,38,-1,STONE:3)
Block(-6,38,0,STONE:3)
Block(-6,38,1,OBSIDIAN:0)
Block(-6,38,2,OBSIDIAN:0)
Block(-6,38,3,OBSIDIAN:0)
Block(-6,39,-7,STONE:3)
Block(-6,39,-6,STONE:3)
Block(-6,39,-5,STONE:3)
Block(-6,39,-4,STONE:3)
Block(-6,39,-3,STONE:3)
Block(-6,39,-2,STONE:3)
Block(-6,39,-1,OBSIDIAN:0)
Block(-6,39,0,OBSIDIAN:0)
Block(-6,39,1,OBSIDIAN:0)
Block(-6,39,2,OBSIDIAN:0)
Block(-6,40,-7,STONE:3)
Block(-6,40,-6,STONE:3)
Block(-6,40,-5,STONE:3)
Block(-6,40,-4,STONE:3)
Block(-6,40,-3,STONE:3)
Block(-6,40,-2,OBSIDIAN:0)
Block(-6,40,-1,OBSIDIAN:0)
Block(-6,40,0,OBSIDIAN:0)
Block(-6,40,1,OBSIDIAN:0)
Block(-6,41,-7,STONE:3)
Block(-6,41,-6,STONE:3)
Block(-6,41,-5,STONE:3)
Block(-6,41,-4,STONE:3)
Block(-6,41,-3,STONE:3)
Block(-6,41,-2,OBSIDIAN:0)
Block(-6,41,-1,OBSIDIAN:0)
Block(-6,41,0,OBSIDIAN:0)
Block(-6,42,-7,STONE:3)
Block(-6,42,-6,STONE:3)
Block(-6,42,-5,STONE:3)
Block(-6,42,-4,STONE:3)
Block(-6,42,-3,STONE:3)
Block(-6,42,-2,OBSIDIAN:0)
Block(-6,42,-1,OBSIDIAN:0)
Block(-6,43,-7,STONE:3)
Block(-6,43,-6,STONE:3)
Block(-6,43,-5,STONE:3)
Block(-6,43,-4,STONE:3)
Block(-6,43,-3,STONE:3)
Block(-6,43,-2,STONE:3)
Block(-6,44,-7,STONE:3)
Block(-6,44,-6,STONE:3)
Block(-5,4,-7,STONE:3)
Block(-5,4,-6,STONE:3)
Block(-5,5,-7,STONE:3)
Block(-5,5,-6,STONE:3)
Block(-5,5,-5,STONE:3)
Block(-5,6,-7,STONE:3)
Block(-5,6,-6,STONE:3)
Block(-5,6,-5,STONE:3)
Block(-5,6,-4,STONE:3)
Block(-5,7,-7,STONE:3)
Block(-5,7,-6,STONE:3)
Block(-5,7,-5,STONE:3)
Block(-5,7,-4,STONE:3)
Block(-5,7,-3,STONE:3)
Block(-5,8,-7,STONE:3)
Block(-5,8,-6,STONE:3)
Block(-5,8,-5,STONE:3)
Block(-5,8,-4,STONE:3)
Block(-5,8,-3,STONE:3)
Block(-5,8,-2,STONE:3)
Block(-5,8,-1,STONE:3)
Block(-5,9,-7,STONE:3)
Block(-5,9,-6,STONE:3)
Block(-5,9,-5,STONE:3)
Block(-5,9,-4,STONE:3)
Block(-5,9,-3,STONE:3)
Block(-5,9,-2,STONE:3)
Block(-5,9,-1,STONE:3)
Block(-5,9,0,STONE:3)
Block(-5,10,-7,STONE:3)
Block(-5,10,-6,STONE:3)
Block(-5,10,-5,STONE:3)
Block(-5,10,-4,STONE:3)
Block(-5,10,-3,STONE:3)
Block(-5,10,-2,STONE:3)
Block(-5,10,-1,STONE:3)
Block(-5,10,0,STONE:3)
Block(-5,10,1,STONE:3)
Block(-5,11,-7,STONE:3)
Block(-5,11,-6,STONE:3)
Block(-5,11,-5,STONE:3)
Block(-5,11,-4,STONE:3)
Block(-5,11,-3,STONE:3)
Block(-5,11,-2,STONE:3)
Block(-5,11,-1,STONE:3)
Block(-5,11,0,STONE:3)
Block(-5,11,1,STONE:3)
Block(-5,11,2,STONE:3)
Block(-5,12,-7,STONE:3)
Block(-5,12,-6,STONE:3)
Block(-5,12,-5,STONE:3)
Block(-5,12,-4,STONE:3)
Block(-5,12,-3,STONE:3)
Block(-5,12,-2,STONE:3)
Block(-5,12,-1,STONE:3)
Block(-5,12,0,STONE:3)
Block(-5,12,1,STONE:3)
Block(-5,12,2,STONE:3)
Block(-5,12,3,STONE:3)
Block(-5,12,4,STONE:3)
Block(-5,13,-7,STONE:0)
Block(-5,13,-6,STONE:0)
Block(-5,13,-5,STONE:0)
Block(-5,13,-4,STONE:0)
Block(-5,13,-3,STONE:3)
Block(-5,13,-2,STONE:3)
Block(-5,13,-1,STONE:3)
Block(-5,13,0,STONE:3)
Block(-5,13,1,STONE:3)
Block(-5,13,2,STONE:3)
Block(-5,13,3,STONE:3)
Block(-5,13,4,STONE:3)
Block(-5,13,5,STONE:3)
Block(-5,13,6,STONE:3)
Block(-5,13,7,STONE:3)
Block(-5,14,-7,STONE:0)
Block(-5,14,-6,STONE:0)
Block(-5,14,-5,STONE:0)
Block(-5,14,-4,STONE:0)
Block(-5,14,-3,STONE:0)
Block(-5,14,-2,STONE:3)
Block(-5,14,-1,STONE:3)
Block(-5,14,0,STONE:3)
Block(-5,14,1,STONE:3)
Block(-5,14,2,STONE:3)
Block(-5,14,3,STONE:3)
Block(-5,14,4,STONE:3)
Block(-5,14,5,STONE:3)
Block(-5,14,6,STONE:3)
Block(-5,14,7,STONE:3)
Block(-5,14,8,STONE:3)
Block(-5,15,-7,STONE:0)
Block(-5,15,-6,STONE:0)
Block(-5,15,-5,STONE:0)
Block(-5,15,-4,STONE:0)
Block(-5,15,-3,STONE:0)
Block(-5,15,-2,STONE:0)
Block(-5,15,-1,STONE:0)
Block(-5,15,0,STONE:3)
Block(-5,15,1,STONE:3)
Block(-5,15,2,STONE:3)
Block(-5,15,3,STONE:3)
Block(-5,15,4,STONE:3)
Block(-5,15,5,STONE:3)
Block(-5,15,6,STONE:3)
Block(-5,15,7,STONE:3)
Block(-5,15,8,STONE:3)
Block(-5,16,-7,STONE:0)
Block(-5,16,-6,STONE:0)
Block(-5,16,-5,STONE:0)
Block(-5,16,-4,STONE:0)
Block(-5,16,-3,STONE:0)
Block(-5,16,-2,STONE:0)
Block(-5,16,-1,STONE:0)
Block(-5,16,0,STONE:0)
Block(-5,16,1,STONE:3)
Block(-5,16,2,STONE:3)
Block(-5,16,3,STONE:3)
Block(-5,16,4,STONE:3)
Block(-5,16,5,STONE:3)
Block(-5,16,6,STONE:3)
Block(-5,16,7,STONE:3)
Block(-5,16,8,STONE:3)
Block(-5,17,-7,STONE:0)
Block(-5,17,-6,STONE:0)
Block(-5,17,-5,STONE:0)
Block(-5,17,-4,STONE:0)
Block(-5,17,-3,STONE:0)
Block(-5,17,-2,STONE:0)
Block(-5,17,-1,STONE:0)
Block(-5,17,0,STONE:0)
Block(-5,17,1,STONE:0)
Block(-5,17,2,STONE:3)
Block(-5,17,3,STONE:3)
Block(-5,17,4,STONE:3)
Block(-5,17,5,STONE:3)
Block(-5,17,6,STONE:3)
Block(-5,17,7,STONE:3)
Block(-5,17,8,STONE:3)
Block(-5,18,-7,OBSIDIAN:0)
Block(-5,18,-6,STONE:0)
Block(-5,18,-5,STONE:0)
Block(-5,18,-4,STONE:0)
Block(-5,18,-3,STONE:0)
Block(-5,18,-2,STONE:0)
Block(-5,18,-1,STONE:0)
Block(-5,18,0,STONE:0)
Block(-5,18,1,STONE:0)
Block(-5,18,2,STONE:0)
Block(-5,18,3,STONE:3)
Block(-5,18,4,STONE:3)
Block(-5,18,5,STONE:3)
Block(-5,18,6,STONE:3)
Block(-5,18,7,STONE:3)
Block(-5,18,8,STONE:3)
Block(-5,19,-7,OBSIDIAN:0)
Block(-5,19,-6,OBSIDIAN:0)
Block(-5,19,-5,STONE:0)
Block(-5,19,-4,STONE:0)
Block(-5,19,-3,STONE:0)
Block(-5,19,-2,STONE:0)
Block(-5,19,-1,STONE:0)
Block(-5,19,0,STONE:0)
Block(-5,19,1,STONE:0)
Block(-5,19,2,STONE:0)
Block(-5,19,3,STONE:0)
Block(-5,19,4,STONE:3)
Block(-5,19,5,STONE:3)
Block(-5,19,6,STONE:3)
Block(-5,19,7,STONE:3)
Block(-5,19,8,STONE:3)
Block(-5,20,-7,AIR:0)
Block(-5,20,-6,GRASS:0)
Block(-5,20,-5,GRASS:0)
Block(-5,20,-4,STONE:0)
Block(-5,20,-3,STONE:0)
Block(-5,20,-2,STONE:0)
Block(-5,20,-1,STONE:0)
Block(-5,20,0,STONE:0)
Block(-5,20,1,STONE:0)
Block(-5,20,2,STONE:0)
Block(-5,20,3,STONE:0)
Block(-5,20,4,STONE:0)
Block(-5,20,5,STONE:3)
Block(-5,20,6,STONE:3)
Block(-5,20,7,STONE:3)
Block(-5,20,8,STONE:3)
Block(-5,21,-7,AIR:0)
Block(-5,21,-6,AIR:0)
Block(-5,21,-5,AIR:0)
Block(-5,21,-4,GRASS:0)
Block(-5,21,-3,GRASS:0)
Block(-5,21,-2,GRASS:0)
Block(-5,21,-1,GRASS:0)
Block(-5,21,0,STONE:0)
Block(-5,21,1,STONE:0)
Block(-5,21,2,STONE:0)
Block(-5,21,3,STONE:0)
Block(-5,21,4,STONE:0)
Block(-5,21,5,STONE:0)
Block(-5,21,6,STONE:0)
Block(-5,21,7,STONE:0)
Block(-5,21,8,STONE:0)
Block(-5,22,-7,AIR:0)
Block(-5,22,-6,AIR:0)
Block(-5,22,-5,AIR:0)
Block(-5,22,-4,AIR:0)
Block(-5,22,-3,AIR:0)
Block(-5,22,-2,AIR:0)
Block(-5,22,-1,AIR:0)
Block(-5,22,0,STONE:0)
Block(-5,22,1,STONE:0)
Block(-5,22,2,STONE:0)
Block(-5,22,3,STONE:0)
Block(-5,22,4,STONE:0)
Block(-5,22,5,STONE:0)
Block(-5,22,6,STONE:0)
Block(-5,22,7,STONE:0)
Block(-5,22,8,STONE:0)
Block(-5,23,-7,AIR:0)
Block(-5,23,-6,AIR:0)
Block(-5,23,-5,AIR:0)
Block(-5,23,-4,AIR:0)
Block(-5,23,-3,AIR:0)
Block(-5,23,-2,AIR:0)
Block(-5,23,-1,AIR:0)
Block(-5,23,0,AIR:0)
Block(-5,23,1,STONE:0)
Block(-5,23,2,STONE:0)
Block(-5,23,3,STONE:0)
Block(-5,23,4,STONE:0)
Block(-5,23,5,STONE:0)
Block(-5,23,6,STONE:0)
Block(-5,23,7,STONE:0)
Block(-5,23,8,STONE:0)
Block(-5,24,-7,AIR:0)
Block(-5,24,-6,AIR:0)
Block(-5,24,-5,AIR:0)
Block(-5,24,-4,AIR:0)
Block(-5,24,-3,AIR:0)
Block(-5,24,-2,AIR:0)
Block(-5,24,-1,AIR:0)
Block(-5,24,0,STONE:0)
Block(-5,24,1,STONE:0)
Block(-5,24,2,STONE:0)
Block(-5,24,3,STONE:0)
Block(-5,24,4,STONE:0)
Block(-5,24,5,STONE:0)
Block(-5,24,6,STONE:0)
Block(-5,24,7,STONE:0)
Block(-5,24,8,STONE:0)
Block(-5,25,-7,AIR:0)
Block(-5,25,-6,AIR:0)
Block(-5,25,-5,AIR:0)
Block(-5,25,-4,AIR:0)
Block(-5,25,-3,AIR:0)
Block(-5,25,-2,AIR:0)
Block(-5,25,-1,STONE:0)
Block(-5,25,0,STONE:0)
Block(-5,25,1,STONE:0)
Block(-5,25,2,STONE:0)
Block(-5,25,3,STONE:0)
Block(-5,25,4,STONE:0)
Block(-5,25,5,STONE:0)
Block(-5,25,6,STONE:0)
Block(-5,25,7,STONE:5)
Block(-5,25,8,STONE:5)
Block(-5,26,-7,AIR:0)
Block(-5,26,-6,AIR:0)
Block(-5,26,-5,AIR:0)
Block(-5,26,-4,AIR:0)
Block(-5,26,-3,AIR:0)
Block(-5,26,-2,STONE:0)
Block(-5,26,-1,STONE:0)
Block(-5,26,0,STONE:0)
Block(-5,26,1,STONE:0)
Block(-5,26,2,STONE:0)
Block(-5,26,3,STONE:0)
Block(-5,26,4,STONE:0)
Block(-5,26,5,STONE:0)
Block(-5,26,6,STONE:5)
Block(-5,26,7,STONE:5)
Block(-5,26,8,STONE:5)
Block(-5,27,-7,AIR:0)
Block(-5,27,-6,AIR:0)
Block(-5,27,-5,AIR:0)
Block(-5,27,-4,AIR:0)
Block(-5,27,-3,STONE:0)
Block(-5,27,-2,STONE:0)
Block(-5,27,-1,STONE:0)
Block(-5,27,0,STONE:0)
Block(-5,27,1,STONE:0)
Block(-5,27,2,STONE:0)
Block(-5,27,3,STONE:0)
Block(-5,27,4,STONE:0)
Block(-5,27,5,STONE:5)
Block(-5,27,6,STONE:5)
Block(-5,27,7,STONE:5)
Block(-5,27,8,STONE:5)
Block(-5,28,-7,AIR:0)
Block(-5,28,-6,AIR:0)
Block(-5,28,-5,AIR:0)
Block(-5,28,-4,AIR:0)
Block(-5,28,-3,STONE:0)
Block(-5,28,-2,STONE:0)
Block(-5,28,-1,STONE:0)
Block(-5,28,0,STONE:0)
Block(-5,28,1,STONE:0)
Block(-5,28,2,STONE:0)
Block(-5,28,3,STONE:0)
Block(-5,28,4,STONE:0)
Block(-5,28,5,STONE:5)
Block(-5,28,6,STONE:5)
Block(-5,28,7,STONE:5)
Block(-5,28,8,STONE:5)
Block(-5,29,-7,AIR:0)
Block(-5,29,-6,AIR:0)
Block(-5,29,-5,AIR:0)
Block(-5,29,-4,STONE:0)
Block(-5,29,-3,STONE:0)
Block(-5,29,-2,STONE:0)
Block(-5,29,-1,STONE:0)
Block(-5,29,0,STONE:0)
Block(-5,29,1,STONE:0)
Block(-5,29,2,STONE:0)
Block(-5,29,3,STONE:0)
Block(-5,29,4,STONE:0)
Block(-5,29,5,STONE:5)
Block(-5,29,6,STONE:5)
Block(-5,29,7,STONE:5)
Block(-5,29,8,STONE:5)
Block(-5,30,-7,AIR:0)
Block(-5,30,-6,STONE:0)
Block(-5,30,-5,STONE:0)
Block(-5,30,-4,STONE:0)
Block(-5,30,-3,STONE:0)
Block(-5,30,-2,STONE:0)
Block(-5,30,-1,STONE:0)
Block(-5,30,0,STONE:0)
Block(-5,30,1,STONE:0)
Block(-5,30,2,STONE:0)
Block(-5,30,3,STONE:0)
Block(-5,30,4,STONE:0)
Block(-5,30,5,STONE:5)
Block(-5,30,6,STONE:5)
Block(-5,30,7,STONE:5)
Block(-5,30,8,STONE:5)
Block(-5,31,-7,STONE:0)
Block(-5,31,-6,STONE:0)
Block(-5,31,-5,STONE:0)
Block(-5,31,-4,STONE:0)
Block(-5,31,-3,STONE:0)
Block(-5,31,-2,STONE:0)
Block(-5,31,-1,STONE:0)
Block(-5,31,0,STONE:0)
Block(-5,31,1,STONE:0)
Block(-5,31,2,STONE:5)
Block(-5,31,3,STONE:5)
Block(-5,31,4,STONE:5)
Block(-5,31,5,STONE:5)
Block(-5,31,6,STONE:5)
Block(-5,31,7,STONE:5)
Block(-5,31,8,STONE:5)
Block(-5,32,-7,STONE:0)
Block(-5,32,-6,STONE:0)
Block(-5,32,-5,STONE:0)
Block(-5,32,-4,STONE:0)
Block(-5,32,-3,STONE:0)
Block(-5,32,-2,STONE:0)
Block(-5,32,-1,STONE:0)
Block(-5,32,0,STONE:5)
Block(-5,32,1,STONE:5)
Block(-5,32,2,STONE:5)
Block(-5,32,3,STONE:5)
Block(-5,32,4,STONE:5)
Block(-5,32,5,STONE:5)
Block(-5,32,6,STONE:5)
Block(-5,32,7,STONE:5)
Block(-5,32,8,STONE:5)
Block(-5,33,-7,STONE:0)
Block(-5,33,-6,STONE:0)
Block(-5,33,-5,STONE:0)
Block(-5,33,-4,STONE:0)
Block(-5,33,-3,STONE:0)
Block(-5,33,-2,STONE:0)
Block(-5,33,-1,STONE:5)
Block(-5,33,0,STONE:5)
Block(-5,33,1,STONE:5)
Block(-5,33,2,STONE:5)
Block(-5,33,3,STONE:5)
Block(-5,33,4,STONE:5)
Block(-5,33,5,STONE:5)
Block(-5,33,6,STONE:5)
Block(-5,33,7,STONE:5)
Block(-5,33,8,STONE:5)
Block(-5,34,-7,STONE:0)
Block(-5,34,-6,STONE:0)
Block(-5,34,-5,STONE:0)
Block(-5,34,-4,STONE:0)
Block(-5,34,-3,STONE:0)
Block(-5,34,-2,STONE:0)
Block(-5,34,-1,STONE:5)
Block(-5,34,0,STONE:5)
Block(-5,34,1,STONE:5)
Block(-5,34,2,STONE:5)
Block(-5,34,3,STONE:5)
Block(-5,34,4,STONE:5)
Block(-5,34,5,STONE:5)
Block(-5,34,6,STONE:5)
Block(-5,34,7,STONE:5)
Block(-5,34,8,STONE:5)
Block(-5,35,-7,STONE:0)
Block(-5,35,-6,STONE:0)
Block(-5,35,-5,STONE:0)
Block(-5,35,-4,STONE:0)
Block(-5,35,-3,STONE:0)
Block(-5,35,-2,STONE:5)
Block(-5,35,-1,STONE:5)
Block(-5,35,0,STONE:5)
Block(-5,35,1,STONE:5)
Block(-5,35,2,STONE:5)
Block(-5,35,3,STONE:5)
Block(-5,35,4,STONE:5)
Block(-5,35,5,STONE:5)
Block(-5,35,6,STONE:5)
Block(-5,36,-7,STONE:0)
Block(-5,36,-6,STONE:0)
Block(-5,36,-5,STONE:0)
Block(-5,36,-4,STONE:0)
Block(-5,36,-3,STONE:0)
Block(-5,36,-2,STONE:5)
Block(-5,36,-1,STONE:5)
Block(-5,36,0,STONE:5)
Block(-5,36,1,STONE:5)
Block(-5,36,2,STONE:5)
Block(-5,36,3,STONE:5)
Block(-5,36,4,STONE:5)
Block(-5,37,-7,STONE:0)
Block(-5,37,-6,STONE:0)
Block(-5,37,-5,STONE:0)
Block(-5,37,-4,STONE:0)
Block(-5,37,-3,STONE:0)
Block(-5,37,-2,STONE:5)
Block(-5,37,-1,STONE:5)
Block(-5,37,0,STONE:5)
Block(-5,37,1,STONE:5)
Block(-5,37,2,STONE:5)
Block(-5,37,3,STONE:5)
Block(-5,38,-7,STONE:0)
Block(-5,38,-6,STONE:0)
Block(-5,38,-5,STONE:3)
Block(-5,38,-4,STONE:3)
Block(-5,38,-3,STONE:3)
Block(-5,38,-2,STONE:3)
Block(-5,38,-1,STONE:3)
Block(-5,38,0,STONE:3)
Block(-5,38,1,STONE:3)
Block(-5,38,2,STONE:3)
Block(-5,39,-7,STONE:3)
Block(-5,39,-6,STONE:3)
Block(-5,39,-5,STONE:3)
Block(-5,39,-4,STONE:3)
Block(-5,39,-3,STONE:3)
Block(-5,39,-2,STONE:3)
Block(-5,39,-1,OBSIDIAN:0)
Block(-5,39,0,OBSIDIAN:0)
Block(-5,39,1,OBSIDIAN:0)
Block(-5,39,2,OBSIDIAN:0)
Block(-5,40,-7,STONE:3)
Block(-5,40,-6,STONE:3)
Block(-5,40,-5,STONE:3)
Block(-5,40,-4,STONE:3)
Block(-5,40,-3,STONE:3)
Block(-5,40,-2,OBSIDIAN:0)
Block(-5,40,-1,OBSIDIAN:0)
Block(-5,40,0,OBSIDIAN:0)
Block(-5,40,1,OBSIDIAN:0)
Block(-5,41,-7,STONE:3)
Block(-5,41,-6,STONE:3)
Block(-5,41,-5,STONE:3)
Block(-5,41,-4,STONE:3)
Block(-5,41,-3,STONE:3)
Block(-5,41,-2,OBSIDIAN:0)
Block(-5,41,-1,OBSIDIAN:0)
Block(-5,41,0,OBSIDIAN:0)
Block(-5,42,-7,STONE:3)
Block(-5,42,-6,STONE:3)
Block(-5,42,-5,STONE:3)
Block(-5,42,-4,STONE:3)
Block(-5,42,-3,STONE:3)
Block(-5,42,-2,OBSIDIAN:0)
Block(-5,42,-1,OBSIDIAN:0)
Block(-5,43,-7,STONE:3)
Block(-5,43,-6,STONE:3)
Block(-5,43,-5,STONE:3)
Block(-5,43,-4,STONE:3)
Block(-5,43,-3,STONE:3)
Block(-5,43,-2,STONE:3)
Block(-5,44,-7,STONE:3)
Block(-4,5,-7,STONE:3)
Block(-4,5,-6,STONE:3)
Block(-4,6,-7,STONE:3)
Block(-4,6,-6,STONE:3)
Block(-4,6,-5,STONE:3)
Block(-4,7,-7,STONE:3)
Block(-4,7,-6,STONE:3)
Block(-4,7,-5,STONE:3)
Block(-4,8,-7,STONE:3)
Block(-4,8,-6,STONE:3)
Block(-4,8,-5,STONE:3)
Block(-4,8,-4,STONE:3)
Block(-4,8,-3,STONE:3)
Block(-4,9,-7,STONE:3)
Block(-4,9,-6,STONE:3)
Block(-4,9,-5,STONE:3)
Block(-4,9,-4,STONE:3)
Block(-4,9,-3,STONE:3)
Block(-4,9,-2,STONE:3)
Block(-4,9,-1,STONE:3)
Block(-4,10,-7,STONE:3)
Block(-4,10,-6,STONE:3)
Block(-4,10,-5,STONE:3)
Block(-4,10,-4,STONE:3)
Block(-4,10,-3,STONE:3)
Block(-4,10,-2,STONE:3)
Block(-4,10,-1,STONE:3)
Block(-4,10,0,STONE:3)
Block(-4,11,-7,STONE:3)
Block(-4,11,-6,STONE:3)
Block(-4,11,-5,STONE:3)
Block(-4,11,-4,STONE:3)
Block(-4,11,-3,STONE:3)
Block(-4,11,-2,STONE:3)
Block(-4,11,-1,STONE:3)
Block(-4,11,0,STONE:3)
Block(-4,11,1,STONE:3)
Block(-4,12,-7,STONE:3)
Block(-4,12,-6,STONE:3)
Block(-4,12,-5,STONE:3)
Block(-4,12,-4,STONE:3)
Block(-4,12,-3,STONE:3)
Block(-4,12,-2,STONE:3)
Block(-4,12,-1,STONE:3)
Block(-4,12,0,STONE:3)
Block(-4,12,1,STONE:3)
Block(-4,12,2,STONE:3)
Block(-4,12,3,STONE:3)
Block(-4,12,4,STONE:3)
Block(-4,13,-7,STONE:3)
Block(-4,13,-6,STONE:3)
Block(-4,13,-5,STONE:3)
Block(-4,13,-4,STONE:0)
Block(-4,13,-3,STONE:3)
Block(-4,13,-2,STONE:3)
Block(-4,13,-1,STONE:3)
Block(-4,13,0,STONE:3)
Block(-4,13,1,STONE:3)
Block(-4,13,2,STONE:3)
Block(-4,13,3,STONE:3)
Block(-4,13,4,STONE:3)
Block(-4,13,5,STONE:3)
Block(-4,13,6,STONE:3)
Block(-4,14,-7,STONE:0)
Block(-4,14,-6,STONE:0)
Block(-4,14,-5,STONE:0)
Block(-4,14,-4,STONE:0)
Block(-4,14,-3,STONE:0)
Block(-4,14,-2,STONE:3)
Block(-4,14,-1,STONE:3)
Block(-4,14,0,STONE:3)
Block(-4,14,1,STONE:3)
Block(-4,14,2,STONE:3)
Block(-4,14,3,STONE:3)
Block(-4,14,4,STONE:3)
Block(-4,14,5,STONE:3)
Block(-4,14,6,STONE:3)
Block(-4,14,7,STONE:3)
Block(-4,15,-7,STONE:0)
Block(-4,15,-6,STONE:0)
Block(-4,15,-5,STONE:0)
Block(-4,15,-4,STONE:0)
Block(-4,15,-3,STONE:0)
Block(-4,15,-2,STONE:0)
Block(-4,15,-1,STONE:0)
Block(-4,15,0,STONE:3)
Block(-4,15,1,STONE:3)
Block(-4,15,2,STONE:3)
Block(-4,15,3,STONE:3)
Block(-4,15,4,STONE:3)
Block(-4,15,5,STONE:3)
Block(-4,15,6,STONE:3)
Block(-4,15,7,STONE:3)
Block(-4,15,8,STONE:3)
Block(-4,16,-7,STONE:0)
Block(-4,16,-6,STONE:0)
Block(-4,16,-5,STONE:0)
Block(-4,16,-4,STONE:0)
Block(-4,16,-3,STONE:0)
Block(-4,16,-2,STONE:0)
Block(-4,16,-1,STONE:0)
Block(-4,16,0,STONE:0)
Block(-4,16,1,STONE:3)
Block(-4,16,2,STONE:3)
Block(-4,16,3,STONE:3)
Block(-4,16,4,STONE:3)
Block(-4,16,5,STONE:3)
Block(-4,16,6,STONE:3)
Block(-4,16,7,STONE:3)
Block(-4,16,8,STONE:3)
Block(-4,17,-7,STONE:0)
Block(-4,17,-6,STONE:0)
Block(-4,17,-5,STONE:0)
Block(-4,17,-4,STONE:0)
Block(-4,17,-3,STONE:0)
Block(-4,17,-2,STONE:0)
Block(-4,17,-1,STONE:0)
Block(-4,17,0,STONE:0)
Block(-4,17,1,STONE:0)
Block(-4,17,2,STONE:3)
Block(-4,17,3,STONE:3)
Block(-4,17,4,STONE:3)
Block(-4,17,5,STONE:3)
Block(-4,17,6,STONE:3)
Block(-4,17,7,STONE:3)
Block(-4,17,8,STONE:3)
Block(-4,18,-7,OBSIDIAN:0)
Block(-4,18,-6,OBSIDIAN:0)
Block(-4,18,-5,STONE:0)
Block(-4,18,-4,STONE:0)
Block(-4,18,-3,STONE:0)
Block(-4,18,-2,STONE:0)
Block(-4,18,-1,STONE:0)
Block(-4,18,0,STONE:0)
Block(-4,18,1,STONE:0)
Block(-4,18,2,STONE:0)
Block(-4,18,3,STONE:3)
Block(-4,18,4,STONE:3)
Block(-4,18,5,STONE:3)
Block(-4,18,6,STONE:3)
Block(-4,18,7,STONE:3)
Block(-4,18,8,STONE:3)
Block(-4,19,-7,OBSIDIAN:0)
Block(-4,19,-6,OBSIDIAN:0)
Block(-4,19,-5,STONE:0)
Block(-4,19,-4,STONE:0)
Block(-4,19,-3,STONE:0)
Block(-4,19,-2,STONE:0)
Block(-4,19,-1,STONE:0)
Block(-4,19,0,STONE:0)
Block(-4,19,1,STONE:0)
Block(-4,19,2,STONE:0)
Block(-4,19,3,STONE:3)
Block(-4,19,4,STONE:3)
Block(-4,19,5,STONE:3)
Block(-4,19,6,STONE:3)
Block(-4,19,7,STONE:3)
Block(-4,19,8,STONE:3)
Block(-4,20,-7,AIR:0)
Block(-4,20,-6,OBSIDIAN:0)
Block(-4,20,-5,STONE:0)
Block(-4,20,-4,STONE:0)
Block(-4,20,-3,STONE:0)
Block(-4,20,-2,STONE:0)
Block(-4,20,-1,STONE:0)
Block(-4,20,0,STONE:0)
Block(-4,20,1,STONE:0)
Block(-4,20,2,STONE:0)
Block(-4,20,3,STONE:0)
Block(-4,20,4,STONE:3)
Block(-4,20,5,STONE:3)
Block(-4,20,6,STONE:3)
Block(-4,20,7,STONE:3)
Block(-4,20,8,STONE:3)
Block(-4,21,-7,AIR:0)
Block(-4,21,-6,AIR:0)
Block(-4,21,-5,GRASS:0)
Block(-4,21,-4,GRASS:0)
Block(-4,21,-3,GRASS:0)
Block(-4,21,-2,GRASS:0)
Block(-4,21,-1,STONE:0)
Block(-4,21,0,STONE:0)
Block(-4,21,1,STONE:0)
Block(-4,21,2,STONE:0)
Block(-4,21,3,STONE:0)
Block(-4,21,4,STONE:0)
Block(-4,21,5,STONE:0)
Block(-4,21,6,STONE:3)
Block(-4,21,7,STONE:3)
Block(-4,21,8,STONE:3)
Block(-4,22,-7,AIR:0)
Block(-4,22,-6,AIR:0)
Block(-4,22,-5,AIR:0)
Block(-4,22,-4,AIR:0)
Block(-4,22,-3,AIR:0)
Block(-4,22,-2,AIR:0)
Block(-4,22,-1,STONE:0)
Block(-4,22,0,STONE:0)
Block(-4,22,1,STONE:0)
Block(-4,22,2,STONE:0)
Block(-4,22,3,STONE:0)
Block(-4,22,4,STONE:0)
Block(-4,22,5,STONE:0)
Block(-4,22,6,STONE:0)
Block(-4,22,7,STONE:0)
Block(-4,22,8,STONE:0)
Block(-4,23,-7,AIR:0)
Block(-4,23,-6,AIR:0)
Block(-4,23,-5,AIR:0)
Block(-4,23,-4,AIR:0)
Block(-4,23,-3,AIR:0)
Block(-4,23,-2,AIR:0)
Block(-4,23,-1,AIR:0)
Block(-4,23,0,STONE:0)
Block(-4,23,1,STONE:0)
Block(-4,23,2,STONE:0)
Block(-4,23,3,STONE:0)
Block(-4,23,4,STONE:0)
Block(-4,23,5,STONE:0)
Block(-4,23,6,STONE:0)
Block(-4,23,7,STONE:0)
Block(-4,23,8,STONE:0)
Block(-4,24,-7,AIR:0)
Block(-4,24,-6,AIR:0)
Block(-4,24,-5,AIR:0)
Block(-4,24,-4,AIR:0)
Block(-4,24,-3,AIR:0)
Block(-4,24,-2,AIR:0)
Block(-4,24,-1,STONE:0)
Block(-4,24,0,STONE:0)
Block(-4,24,1,STONE:0)
Block(-4,24,2,STONE:0)
Block(-4,24,3,STONE:0)
Block(-4,24,4,STONE:0)
Block(-4,24,5,STONE:0)
Block(-4,24,6,STONE:0)
Block(-4,24,7,STONE:0)
Block(-4,24,8,STONE:5)
Block(-4,25,-7,AIR:0)
Block(-4,25,-6,AIR:0)
Block(-4,25,-5,AIR:0)
Block(-4,25,-4,AIR:0)
Block(-4,25,-3,AIR:0)
Block(-4,25,-2,AIR:0)
Block(-4,25,-1,STONE:0)
Block(-4,25,0,STONE:0)
Block(-4,25,1,STONE:0)
Block(-4,25,2,STONE:0)
Block(-4,25,3,STONE:0)
Block(-4,25,4,STONE:0)
Block(-4,25,5,STONE:0)
Block(-4,25,6,STONE:5)
Block(-4,25,7,STONE:5)
Block(-4,25,8,STONE:5)
Block(-4,26,-7,AIR:0)
Block(-4,26,-6,AIR:0)
Block(-4,26,-5,AIR:0)
Block(-4,26,-4,AIR:0)
Block(-4,26,-3,STONE:0)
Block(-4,26,-2,STONE:0)
Block(-4,26,-1,STONE:0)
Block(-4,26,0,STONE:0)
Block(-4,26,1,STONE:0)
Block(-4,26,2,STONE:0)
Block(-4,26,3,STONE:0)
Block(-4,26,4,STONE:0)
Block(-4,26,5,STONE:5)
Block(-4,26,6,STONE:5)
Block(-4,26,7,STONE:5)
Block(-4,26,8,STONE:5)
Block(-4,27,-7,AIR:0)
Block(-4,27,-6,AIR:0)
Block(-4,27,-5,AIR:0)
Block(-4,27,-4,STONE:0)
Block(-4,27,-3,STONE:0)
Block(-4,27,-2,STONE:0)
Block(-4,27,-1,STONE:0)
Block(-4,27,0,STONE:0)
Block(-4,27,1,STONE:0)
Block(-4,27,2,STONE:0)
Block(-4,27,3,STONE:0)
Block(-4,27,4,STONE:0)
Block(-4,27,5,STONE:5)
Block(-4,27,6,STONE:5)
Block(-4,27,7,STONE:5)
Block(-4,27,8,STONE:5)
Block(-4,28,-7,AIR:0)
Block(-4,28,-6,AIR:0)
Block(-4,28,-5,AIR:0)
Block(-4,28,-4,STONE:0)
Block(-4,28,-3,STONE:0)
Block(-4,28,-2,STONE:0)
Block(-4,28,-1,STONE:0)
Block(-4,28,0,STONE:0)
Block(-4,28,1,STONE:0)
Block(-4,28,2,STONE:0)
Block(-4,28,3,STONE:0)
Block(-4,28,4,STONE:5)
Block(-4,28,5,STONE:5)
Block(-4,28,6,STONE:5)
Block(-4,28,7,STONE:5)
Block(-4,28,8,STONE:5)
Block(-4,29,-7,AIR:0)
Block(-4,29,-6,AIR:0)
Block(-4,29,-5,STONE:0)
Block(-4,29,-4,STONE:0)
Block(-4,29,-3,STONE:0)
Block(-4,29,-2,STONE:0)
Block(-4,29,-1,STONE:0)
Block(-4,29,0,STONE:0)
Block(-4,29,1,STONE:0)
Block(-4,29,2,STONE:0)
Block(-4,29,3,STONE:0)
Block(-4,29,4,STONE:5)
Block(-4,29,5,STONE:5)
Block(-4,29,6,STONE:5)
Block(-4,29,7,STONE:5)
Block(-4,29,8,STONE:5)
Block(-4,30,-7,STONE:0)
Block(-4,30,-6,STONE:0)
Block(-4,30,-5,STONE:0)
Block(-4,30,-4,STONE:0)
Block(-4,30,-3,STONE:0)
Block(-4,30,-2,STONE:0)
Block(-4,30,-1,STONE:0)
Block(-4,30,0,STONE:0)
Block(-4,30,1,STONE:0)
Block(-4,30,2,STONE:0)
Block(-4,30,3,STONE:0)
Block(-4,30,4,STONE:5)
Block(-4,30,5,STONE:5)
Block(-4,30,6,STONE:5)
Block(-4,30,7,STONE:5)
Block(-4,30,8,STONE:5)
Block(-4,31,-7,STONE:0)
Block(-4,31,-6,STONE:0)
Block(-4,31,-5,STONE:0)
Block(-4,31,-4,STONE:0)
Block(-4,31,-3,STONE:0)
Block(-4,31,-2,STONE:0)
Block(-4,31,-1,STONE:0)
Block(-4,31,0,STONE:0)
Block(-4,31,1,STONE:5)
Block(-4,31,2,STONE:5)
Block(-4,31,3,STONE:5)
Block(-4,31,4,STONE:5)
Block(-4,31,5,STONE:5)
Block(-4,31,6,STONE:5)
Block(-4,31,7,STONE:5)
Block(-4,31,8,STONE:5)
Block(-4,32,-7,STONE:0)
Block(-4,32,-6,STONE:0)
Block(-4,32,-5,STONE:0)
Block(-4,32,-4,STONE:0)
Block(-4,32,-3,STONE:0)
Block(-4,32,-2,STONE:0)
Block(-4,32,-1,STONE:0)
Block(-4,32,0,STONE:5)
Block(-4,32,1,STONE:5)
Block(-4,32,2,STONE:5)
Block(-4,32,3,STONE:5)
Block(-4,32,4,STONE:5)
Block(-4,32,5,STONE:5)
Block(-4,32,6,STONE:5)
Block(-4,32,7,STONE:5)
Block(-4,32,8,STONE:5)
Block(-4,33,-7,STONE:0)
Block(-4,33,-6,STONE:0)
Block(-4,33,-5,STONE:0)
Block(-4,33,-4,STONE:0)
Block(-4,33,-3,STONE:0)
Block(-4,33,-2,STONE:0)
Block(-4,33,-1,STONE:5)
Block(-4,33,0,STONE:5)
Block(-4,33,1,STONE:5)
Block(-4,33,2,STONE:5)
Block(-4,33,3,STONE:5)
Block(-4,33,4,STONE:5)
Block(-4,33,5,STONE:5)
Block(-4,33,6,STONE:5)
Block(-4,33,7,STONE:5)
Block(-4,33,8,STONE:5)
Block(-4,34,-7,STONE:0)
Block(-4,34,-6,STONE:0)
Block(-4,34,-5,STONE:0)
Block(-4,34,-4,STONE:0)
Block(-4,34,-3,STONE:0)
Block(-4,34,-2,STONE:5)
Block(-4,34,-1,STONE:5)
Block(-4,34,0,STONE:5)
Block(-4,34,1,STONE:5)
Block(-4,34,2,STONE:5)
Block(-4,34,3,STONE:5)
Block(-4,34,4,STONE:5)
Block(-4,34,5,STONE:5)
Block(-4,34,6,STONE:5)
Block(-4,34,7,STONE:5)
Block(-4,35,-7,STONE:0)
Block(-4,35,-6,STONE:0)
Block(-4,35,-5,STONE:0)
Block(-4,35,-4,STONE:0)
Block(-4,35,-3,STONE:0)
Block(-4,35,-2,STONE:5)
Block(-4,35,-1,STONE:5)
Block(-4,35,0,STONE:5)
Block(-4,35,1,STONE:5)
Block(-4,35,2,STONE:5)
Block(-4,35,3,STONE:5)
Block(-4,35,4,STONE:5)
Block(-4,36,-7,STONE:0)
Block(-4,36,-6,STONE:0)
Block(-4,36,-5,STONE:0)
Block(-4,36,-4,STONE:0)
Block(-4,36,-3,STONE:0)
Block(-4,36,-2,STONE:5)
Block(-4,36,-1,STONE:5)
Block(-4,36,0,STONE:5)
Block(-4,36,1,STONE:5)
Block(-4,36,2,STONE:5)
Block(-4,36,3,STONE:5)
Block(-4,37,-7,STONE:0)
Block(-4,37,-6,STONE:0)
Block(-4,37,-5,STONE:0)
Block(-4,37,-4,STONE:0)
Block(-4,37,-3,STONE:0)
Block(-4,37,-2,STONE:5)
Block(-4,37,-1,STONE:5)
Block(-4,37,0,STONE:5)
Block(-4,37,1,STONE:5)
Block(-4,37,2,STONE:5)
Block(-4,37,3,STONE:5)
Block(-4,38,-7,STONE:0)
Block(-4,38,-6,STONE:0)
Block(-4,38,-5,STONE:0)
Block(-4,38,-4,STONE:0)
Block(-4,38,-3,STONE:0)
Block(-4,38,-2,STONE:5)
Block(-4,38,-1,STONE:5)
Block(-4,38,0,STONE:5)
Block(-4,38,1,STONE:5)
Block(-4,38,2,STONE:5)
Block(-4,39,-7,STONE:0)
Block(-4,39,-6,STONE:3)
Block(-4,39,-5,STONE:3)
Block(-4,39,-4,STONE:3)
Block(-4,39,-3,STONE:3)
Block(-4,39,-2,OBSIDIAN:0)
Block(-4,39,-1,OBSIDIAN:0)
Block(-4,39,0,OBSIDIAN:0)
Block(-4,39,1,OBSIDIAN:0)
Block(-4,40,-7,STONE:3)
Block(-4,40,-6,STONE:3)
Block(-4,40,-5,STONE:3)
Block(-4,40,-4,STONE:3)
Block(-4,40,-3,OBSIDIAN:0)
Block(-4,40,-2,OBSIDIAN:0)
Block(-4,40,-1,OBSIDIAN:0)
Block(-4,40,0,OBSIDIAN:0)
Block(-4,41,-7,STONE:3)
Block(-4,41,-6,STONE:3)
Block(-4,41,-5,STONE:3)
Block(-4,41,-4,STONE:3)
Block(-4,41,-3,OBSIDIAN:0)
Block(-4,41,-2,OBSIDIAN:0)
Block(-4,41,-1,OBSIDIAN:0)
Block(-4,41,0,OBSIDIAN:0)
Block(-4,42,-7,STONE:3)
Block(-4,42,-6,STONE:3)
Block(-4,42,-5,STONE:3)
Block(-4,42,-4,STONE:3)
Block(-4,42,-3,OBSIDIAN:0)
Block(-4,42,-2,OBSIDIAN:0)
Block(-4,42,-1,OBSIDIAN:0)
Block(-4,43,-7,STONE:3)
Block(-4,43,-6,STONE:3)
Block(-4,43,-5,STONE:3)
Block(-4,43,-4,STONE:3)
Block(-4,43,-3,STONE:3)
Block(-4,44,-7,STONE:3)
Block(-3,6,-7,STONE:3)
Block(-3,7,-7,STONE:3)
Block(-3,7,-6,STONE:3)
Block(-3,8,-7,STONE:3)
Block(-3,8,-6,STONE:3)
Block(-3,8,-5,STONE:3)
Block(-3,9,-7,STONE:3)
Block(-3,9,-6,STONE:3)
Block(-3,9,-5,STONE:3)
Block(-3,9,-4,STONE:3)
Block(-3,9,-3,STONE:3)
Block(-3,10,-7,STONE:3)
Block(-3,10,-6,STONE:3)
Block(-3,10,-5,STONE:3)
Block(-3,10,-4,STONE:3)
Block(-3,10,-3,STONE:3)
Block(-3,10,-2,STONE:3)
Block(-3,10,0,STONE:3)
Block(-3,11,-7,STONE:3)
Block(-3,11,-6,STONE:3)
Block(-3,11,-5,STONE:3)
Block(-3,11,-4,STONE:3)
Block(-3,11,-3,STONE:3)
Block(-3,11,-2,STONE:3)
Block(-3,11,-1,STONE:3)
Block(-3,11,0,STONE:3)
Block(-3,12,-7,STONE:3)
Block(-3,12,-6,STONE:3)
Block(-3,12,-5,STONE:3)
Block(-3,12,-4,STONE:3)
Block(-3,12,-3,STONE:3)
Block(-3,12,-2,STONE:3)
Block(-3,12,-1,STONE:3)
Block(-3,12,0,STONE:3)
Block(-3,12,1,STONE:3)
Block(-3,12,3,STONE:3)
Block(-3,13,-7,STONE:3)
Block(-3,13,-6,STONE:3)
Block(-3,13,-5,STONE:3)
Block(-3,13,-4,STONE:3)
Block(-3,13,-3,STONE:3)
Block(-3,13,-2,STONE:3)
Block(-3,13,-1,STONE:3)
Block(-3,13,0,STONE:3)
Block(-3,13,1,STONE:3)
Block(-3,13,2,STONE:3)
Block(-3,13,3,STONE:3)
Block(-3,13,4,STONE:3)
Block(-3,13,5,STONE:3)
Block(-3,14,-7,STONE:3)
Block(-3,14,-6,STONE:3)
Block(-3,14,-5,STONE:0)
Block(-3,14,-4,STONE:3)
Block(-3,14,-3,STONE:3)
Block(-3,14,-2,STONE:3)
Block(-3,14,-1,STONE:3)
Block(-3,14,0,STONE:3)
Block(-3,14,1,STONE:3)
Block(-3,14,2,STONE:3)
Block(-3,14,3,STONE:3)
Block(-3,14,4,STONE:3)
Block(-3,14,5,STONE:3)
Block(-3,14,6,STONE:3)
Block(-3,15,-7,STONE:0)
Block(-3,15,-6,STONE:0)
Block(-3,15,-5,STONE:0)
Block(-3,15,-4,STONE:0)
Block(-3,15,-3,STONE:3)
Block(-3,15,-2,STONE:3)
Block(-3,15,-1,STONE:3)
Block(-3,15,0,STONE:3)
Block(-3,15,1,STONE:3)
Block(-3,15,2,STONE:3)
Block(-3,15,3,STONE:3)
Block(-3,15,4,STONE:3)
Block(-3,15,5,STONE:3)
Block(-3,15,6,STONE:3)
Block(-3,15,7,STONE:3)
Block(-3,16,-7,STONE:0)
Block(-3,16,-6,STONE:0)
Block(-3,16,-5,STONE:0)
Block(-3,16,-4,STONE:0)
Block(-3,16,-3,STONE:0)
Block(-3,16,-2,STONE:0)
Block(-3,16,-1,STONE:0)
Block(-3,16,0,STONE:0)
Block(-3,16,1,STONE:3)
Block(-3,16,2,STONE:3)
Block(-3,16,3,STONE:3)
Block(-3,16,4,STONE:3)
Block(-3,16,5,STONE:3)
Block(-3,16,6,STONE:3)
Block(-3,16,7,STONE:3)
Block(-3,16,8,STONE:3)
Block(-3,17,-7,STONE:0)
Block(-3,17,-6,STONE:0)
Block(-3,17,-5,STONE:0)
Block(-3,17,-4,STONE:0)
Block(-3,17,-3,STONE:0)
Block(-3,17,-2,STONE:0)
Block(-3,17,-1,STONE:0)
Block(-3,17,0,STONE:0)
Block(-3,17,1,STONE:0)
Block(-3,17,2,STONE:3)
Block(-3,17,3,STONE:3)
Block(-3,17,4,STONE:3)
Block(-3,17,5,STONE:3)
Block(-3,17,6,STONE:3)
Block(-3,17,7,STONE:3)
Block(-3,17,8,STONE:3)
Block(-3,18,-7,OBSIDIAN:0)
Block(-3,18,-6,STONE:0)
Block(-3,18,-5,STONE:0)
Block(-3,18,-4,STONE:0)
Block(-3,18,-3,STONE:0)
Block(-3,18,-2,STONE:0)
Block(-3,18,-1,STONE:0)
Block(-3,18,0,STONE:0)
Block(-3,18,1,STONE:0)
Block(-3,18,2,STONE:3)
Block(-3,18,3,STONE:3)
Block(-3,18,4,STONE:3)
Block(-3,18,5,STONE:3)
Block(-3,18,6,STONE:3)
Block(-3,18,7,STONE:3)
Block(-3,18,8,STONE:3)
Block(-3,19,-7,OBSIDIAN:0)
Block(-3,19,-6,OBSIDIAN:0)
Block(-3,19,-5,STONE:0)
Block(-3,19,-4,STONE:0)
Block(-3,19,-3,STONE:0)
Block(-3,19,-2,STONE:0)
Block(-3,19,-1,STONE:0)
Block(-3,19,0,STONE:0)
Block(-3,19,1,STONE:0)
Block(-3,19,2,STONE:0)
Block(-3,19,3,STONE:3)
Block(-3,19,4,STONE:3)
Block(-3,19,5,STONE:3)
Block(-3,19,6,STONE:3)
Block(-3,19,7,STONE:3)
Block(-3,19,8,STONE:3)
Block(-3,20,-7,OBSIDIAN:0)
Block(-3,20,-6,OBSIDIAN:0)
Block(-3,20,-5,STONE:0)
Block(-3,20,-4,STONE:0)
Block(-3,20,-3,STONE:0)
Block(-3,20,-2,STONE:0)
Block(-3,20,-1,STONE:0)
Block(-3,20,0,STONE:0)
Block(-3,20,1,STONE:0)
Block(-3,20,2,STONE:0)
Block(-3,20,3,STONE:0)
Block(-3,20,4,STONE:3)
Block(-3,20,5,STONE:3)
Block(-3,20,6,STONE:3)
Block(-3,20,7,STONE:3)
Block(-3,20,8,STONE:3)
Block(-3,21,-7,AIR:0)
Block(-3,21,-6,AIR:0)
Block(-3,21,-5,OBSIDIAN:0)
Block(-3,21,-4,GRASS:0)
Block(-3,21,-3,GRASS:0)
Block(-3,21,-2,STONE:0)
Block(-3,21,-1,STONE:0)
Block(-3,21,0,STONE:0)
Block(-3,21,1,STONE:0)
Block(-3,21,2,STONE:0)
Block(-3,21,3,STONE:0)
Block(-3,21,4,STONE:0)
Block(-3,21,5,STONE:3)
Block(-3,21,6,STONE:3)
Block(-3,21,7,STONE:3)
Block(-3,21,8,STONE:3)
Block(-3,22,-7,AIR:0)
Block(-3,22,-6,AIR:0)
Block(-3,22,-5,AIR:0)
Block(-3,22,-4,AIR:0)
Block(-3,22,-3,AIR:0)
Block(-3,22,-2,STONE:0)
Block(-3,22,-1,STONE:0)
Block(-3,22,0,STONE:0)
Block(-3,22,1,STONE:0)
Block(-3,22,2,STONE:0)
Block(-3,22,3,STONE:0)
Block(-3,22,4,STONE:0)
Block(-3,22,5,STONE:0)
Block(-3,22,6,STONE:3)
Block(-3,22,7,STONE:3)
Block(-3,22,8,STONE:3)
Block(-3,23,-7,AIR:0)
Block(-3,23,-6,AIR:0)
Block(-3,23,-5,AIR:0)
Block(-3,23,-4,AIR:0)
Block(-3,23,-3,AIR:0)
Block(-3,23,-2,STONE:0)
Block(-3,23,-1,STONE:0)
Block(-3,23,0,STONE:0)
Block(-3,23,1,STONE:0)
Block(-3,23,2,STONE:0)
Block(-3,23,3,STONE:0)
Block(-3,23,4,STONE:0)
Block(-3,23,5,STONE:0)
Block(-3,23,6,STONE:0)
Block(-3,23,7,STONE:0)
Block(-3,23,8,STONE:0)
Block(-3,24,-7,AIR:0)
Block(-3,24,-6,AIR:0)
Block(-3,24,-5,AIR:0)
Block(-3,24,-4,AIR:0)
Block(-3,24,-3,AIR:0)
Block(-3,24,-2,STONE:0)
Block(-3,24,-1,STONE:0)
Block(-3,24,0,STONE:0)
Block(-3,24,1,STONE:0)
Block(-3,24,2,STONE:0)
Block(-3,24,3,STONE:0)
Block(-3,24,4,STONE:0)
Block(-3,24,5,STONE:0)
Block(-3,24,6,STONE:0)
Block(-3,24,7,STONE:5)
Block(-3,24,8,STONE:5)
Block(-3,25,-7,AIR:0)
Block(-3,25,-6,AIR:0)
Block(-3,25,-5,AIR:0)
Block(-3,25,-4,STONE:0)
Block(-3,25,-3,STONE:0)
Block(-3,25,-2,STONE:0)
Block(-3,25,-1,STONE:0)
Block(-3,25,0,STONE:0)
Block(-3,25,1,STONE:0)
Block(-3,25,2,STONE:0)
Block(-3,25,3,STONE:0)
Block(-3,25,4,STONE:0)
Block(-3,25,5,STONE:5)
Block(-3,25,6,STONE:5)
Block(-3,25,7,STONE:5)
Block(-3,25,8,STONE:5)
Block(-3,26,-7,AIR:0)
Block(-3,26,-6,AIR:0)
Block(-3,26,-5,STONE:0)
Block(-3,26,-4,STONE:0)
Block(-3,26,-3,STONE:0)
Block(-3,26,-2,STONE:0)
Block(-3,26,-1,STONE:0)
Block(-3,26,0,STONE:0)
Block(-3,26,1,STONE:0)
Block(-3,26,2,STONE:0)
Block(-3,26,3,STONE:0)
Block(-3,26,4,STONE:5)
Block(-3,26,5,STONE:5)
Block(-3,26,6,STONE:5)
Block(-3,26,7,STONE:5)
Block(-3,26,8,STONE:5)
Block(-3,27,-7,AIR:0)
Block(-3,27,-6,AIR:0)
Block(-3,27,-5,STONE:0)
Block(-3,27,-4,STONE:0)
Block(-3,27,-3,STONE:0)
Block(-3,27,-2,STONE:0)
Block(-3,27,-1,STONE:0)
Block(-3,27,0,STONE:0)
Block(-3,27,1,STONE:0)
Block(-3,27,2,STONE:0)
Block(-3,27,3,STONE:0)
Block(-3,27,4,STONE:5)
Block(-3,27,5,STONE:5)
Block(-3,27,6,STONE:5)
Block(-3,27,7,STONE:5)
Block(-3,27,8,STONE:5)
Block(-3,28,-7,AIR:0)
Block(-3,28,-6,AIR:0)
Block(-3,28,-5,STONE:0)
Block(-3,28,-4,STONE:0)
Block(-3,28,-3,STONE:0)
Block(-3,28,-2,STONE:0)
Block(-3,28,-1,STONE:0)
Block(-3,28,0,STONE:0)
Block(-3,28,1,STONE:0)
Block(-3,28,2,STONE:0)
Block(-3,28,3,STONE:0)
Block(-3,28,4,STONE:5)
Block(-3,28,5,STONE:5)
Block(-3,28,6,STONE:5)
Block(-3,28,7,STONE:5)
Block(-3,28,8,STONE:5)
Block(-3,29,-7,AIR:0)
Block(-3,29,-6,STONE:0)
Block(-3,29,-5,STONE:0)
Block(-3,29,-4,STONE:0)
Block(-3,29,-3,STONE:0)
Block(-3,29,-2,STONE:0)
Block(-3,29,-1,STONE:0)
Block(-3,29,0,STONE:0)
Block(-3,29,1,STONE:0)
Block(-3,29,2,STONE:0)
Block(-3,29,3,STONE:0)
Block(-3,29,4,STONE:5)
Block(-3,29,5,STONE:5)
Block(-3,29,6,STONE:5)
Block(-3,29,7,STONE:5)
Block(-3,29,8,STONE:5)
Block(-3,30,-7,STONE:0)
Block(-3,30,-6,STONE:0)
Block(-3,30,-5,STONE:0)
Block(-3,30,-4,STONE:0)
Block(-3,30,-3,STONE:0)
Block(-3,30,-2,STONE:0)
Block(-3,30,-1,STONE:0)
Block(-3,30,0,STONE:5)
Block(-3,30,1,STONE:5)
Block(-3,30,2,STONE:5)
Block(-3,30,3,STONE:5)
Block(-3,30,4,STONE:5)
Block(-3,30,5,STONE:5)
Block(-3,30,6,STONE:5)
Block(-3,30,7,STONE:5)
Block(-3,30,8,STONE:5)
Block(-3,31,-7,STONE:0)
Block(-3,31,-6,STONE:0)
Block(-3,31,-5,STONE:0)
Block(-3,31,-4,STONE:0)
Block(-3,31,-3,STONE:0)
Block(-3,31,-2,STONE:0)
Block(-3,31,-1,STONE:5)
Block(-3,31,0,STONE:5)
Block(-3,31,1,STONE:5)
Block(-3,31,2,STONE:5)
Block(-3,31,3,STONE:5)
Block(-3,31,4,STONE:5)
Block(-3,31,5,STONE:5)
Block(-3,31,6,STONE:5)
Block(-3,31,7,STONE:5)
Block(-3,31,8,STONE:5)
Block(-3,32,-7,STONE:0)
Block(-3,32,-6,STONE:0)
Block(-3,32,-5,STONE:0)
Block(-3,32,-4,STONE:0)
Block(-3,32,-3,STONE:0)
Block(-3,32,-2,STONE:0)
Block(-3,32,-1,STONE:5)
Block(-3,32,0,STONE:5)
Block(-3,32,1,STONE:5)
Block(-3,32,2,STONE:5)
Block(-3,32,3,STONE:5)
Block(-3,32,4,STONE:5)
Block(-3,32,5,STONE:5)
Block(-3,32,6,STONE:5)
Block(-3,32,7,STONE:5)
Block(-3,32,8,STONE:5)
Block(-3,33,-7,STONE:0)
Block(-3,33,-6,STONE:0)
Block(-3,33,-5,STONE:0)
Block(-3,33,-4,STONE:0)
Block(-3,33,-3,STONE:0)
Block(-3,33,-2,STONE:0)
Block(-3,33,-1,STONE:5)
Block(-3,33,0,STONE:5)
Block(-3,33,1,STONE:5)
Block(-3,33,2,STONE:5)
Block(-3,33,3,STONE:5)
Block(-3,33,4,STONE:5)
Block(-3,33,5,STONE:5)
Block(-3,33,6,STONE:5)
Block(-3,33,7,STONE:5)
Block(-3,34,-7,STONE:0)
Block(-3,34,-6,STONE:0)
Block(-3,34,-5,STONE:0)
Block(-3,34,-4,STONE:0)
Block(-3,34,-3,STONE:0)
Block(-3,34,-2,STONE:5)
Block(-3,34,-1,STONE:5)
Block(-3,34,0,STONE:5)
Block(-3,34,1,STONE:5)
Block(-3,34,2,STONE:5)
Block(-3,34,3,STONE:5)
Block(-3,34,4,STONE:5)
Block(-3,34,5,STONE:5)
Block(-3,35,-7,STONE:0)
Block(-3,35,-6,STONE:0)
Block(-3,35,-5,STONE:0)
Block(-3,35,-4,STONE:0)
Block(-3,35,-3,STONE:0)
Block(-3,35,-2,STONE:5)
Block(-3,35,-1,STONE:5)
Block(-3,35,0,STONE:5)
Block(-3,35,1,STONE:5)
Block(-3,35,2,STONE:5)
Block(-3,35,3,STONE:5)
Block(-3,36,-7,STONE:0)
Block(-3,36,-6,STONE:0)
Block(-3,36,-5,STONE:0)
Block(-3,36,-4,STONE:0)
Block(-3,36,-3,STONE:0)
Block(-3,36,-2,STONE:5)
Block(-3,36,-1,STONE:5)
Block(-3,36,0,STONE:5)
Block(-3,36,1,STONE:5)
Block(-3,36,2,STONE:5)
Block(-3,36,3,STONE:5)
Block(-3,37,-7,STONE:0)
Block(-3,37,-6,STONE:0)
Block(-3,37,-5,STONE:0)
Block(-3,37,-4,STONE:0)
Block(-3,37,-3,STONE:0)
Block(-3,37,-2,STONE:5)
Block(-3,37,-1,STONE:5)
Block(-3,37,0,STONE:5)
Block(-3,37,1,STONE:5)
Block(-3,37,2,STONE:5)
Block(-3,38,-7,STONE:0)
Block(-3,38,-6,STONE:0)
Block(-3,38,-5,STONE:0)
Block(-3,38,-4,STONE:0)
Block(-3,38,-3,STONE:0)
Block(-3,38,-2,STONE:5)
Block(-3,38,-1,STONE:5)
Block(-3,38,0,STONE:5)
Block(-3,38,1,STONE:5)
Block(-3,39,-7,STONE:0)
Block(-3,39,-6,STONE:0)
Block(-3,39,-5,STONE:0)
Block(-3,39,-4,STONE:0)
Block(-3,39,-3,STONE:0)
Block(-3,39,-2,OBSIDIAN:0)
Block(-3,39,-1,OBSIDIAN:0)
Block(-3,39,0,OBSIDIAN:0)
Block(-3,40,-7,STONE:0)
Block(-3,40,-6,STONE:3)
Block(-3,40,-5,STONE:3)
Block(-3,40,-4,STONE:3)
Block(-3,40,-3,OBSIDIAN:0)
Block(-3,40,-2,OBSIDIAN:0)
Block(-3,40,-1,OBSIDIAN:0)
Block(-3,40,0,OBSIDIAN:0)
Block(-3,41,-7,STONE:3)
Block(-3,41,-6,STONE:3)
Block(-3,41,-5,STONE:3)
Block(-3,41,-4,STONE:3)
Block(-3,41,-3,OBSIDIAN:0)
Block(-3,41,-2,OBSIDIAN:0)
Block(-3,41,-1,OBSIDIAN:0)
Block(-3,42,-7,STONE:3)
Block(-3,42,-6,STONE:3)
Block(-3,42,-5,STONE:3)
Block(-3,42,-4,STONE:3)
Block(-3,42,-3,OBSIDIAN:0)
Block(-3,42,-2,OBSIDIAN:0)
Block(-3,43,-7,STONE:3)
Block(-3,43,-6,STONE:3)
Block(-3,43,-5,STONE:3)
Block(-2,8,-7,STONE:3)
Block(-2,9,-7,STONE:3)
Block(-2,9,-6,STONE:3)
Block(-2,9,-5,STONE:3)
Block(-2,10,-7,STONE:3)
Block(-2,10,-6,STONE:3)
Block(-2,10,-5,STONE:3)
Block(-2,10,-4,STONE:3)
Block(-2,10,-3,STONE:3)
Block(-2,11,-7,STONE:3)
Block(-2,11,-6,STONE:3)
Block(-2,11,-5,STONE:3)
Block(-2,11,-4,STONE:3)
Block(-2,11,-3,STONE:3)
Block(-2,11,-2,STONE:3)
Block(-2,11,-1,STONE:3)
Block(-2,11,0,STONE:3)
Block(-2,12,-7,STONE:3)
Block(-2,12,-6,STONE:3)
Block(-2,12,-5,STONE:3)
Block(-2,12,-4,STONE:3)
Block(-2,12,-3,STONE:3)
Block(-2,12,-2,STONE:3)
Block(-2,12,-1,STONE:3)
Block(-2,12,0,STONE:3)
Block(-2,12,1,STONE:3)
Block(-2,13,-7,STONE:3)
Block(-2,13,-6,STONE:3)
Block(-2,13,-5,STONE:3)
Block(-2,13,-4,STONE:3)
Block(-2,13,-3,STONE:3)
Block(-2,13,-2,STONE:3)
Block(-2,13,-1,STONE:3)
Block(-2,13,0,STONE:3)
Block(-2,13,1,STONE:3)
Block(-2,13,2,STONE:3)
Block(-2,13,3,STONE:3)
Block(-2,14,-7,STONE:3)
Block(-2,14,-6,STONE:3)
Block(-2,14,-5,STONE:3)
Block(-2,14,-4,STONE:3)
Block(-2,14,-3,STONE:3)
Block(-2,14,-2,STONE:3)
Block(-2,14,-1,STONE:3)
Block(-2,14,0,STONE:3)
Block(-2,14,1,STONE:3)
Block(-2,14,2,STONE:3)
Block(-2,14,3,STONE:3)
Block(-2,14,4,STONE:3)
Block(-2,14,5,STONE:3)
Block(-2,15,-7,STONE:0)
Block(-2,15,-6,STONE:0)
Block(-2,15,-5,STONE:0)
Block(-2,15,-4,STONE:3)
Block(-2,15,-3,STONE:3)
Block(-2,15,-2,STONE:3)
Block(-2,15,-1,STONE:3)
Block(-2,15,0,STONE:3)
Block(-2,15,1,STONE:3)
Block(-2,15,2,STONE:3)
Block(-2,15,3,STONE:3)
Block(-2,15,4,STONE:3)
Block(-2,15,5,STONE:3)
Block(-2,15,6,STONE:3)
Block(-2,16,-7,STONE:0)
Block(-2,16,-6,STONE:0)
Block(-2,16,-5,STONE:0)
Block(-2,16,-4,STONE:0)
Block(-2,16,-3,STONE:3)
Block(-2,16,-2,STONE:3)
Block(-2,16,-1,STONE:3)
Block(-2,16,0,STONE:3)
Block(-2,16,1,STONE:3)
Block(-2,16,2,STONE:3)
Block(-2,16,3,STONE:3)
Block(-2,16,4,STONE:3)
Block(-2,16,5,STONE:3)
Block(-2,16,6,STONE:3)
Block(-2,16,7,STONE:3)
Block(-2,17,-7,STONE:0)
Block(-2,17,-6,STONE:0)
Block(-2,17,-5,STONE:0)
Block(-2,17,-4,STONE:0)
Block(-2,17,-3,STONE:0)
Block(-2,17,-2,STONE:0)
Block(-2,17,-1,STONE:0)
Block(-2,17,0,STONE:0)
Block(-2,17,1,STONE:0)
Block(-2,17,2,STONE:3)
Block(-2,17,3,STONE:3)
Block(-2,17,4,STONE:3)
Block(-2,17,5,STONE:3)
Block(-2,17,6,STONE:3)
Block(-2,17,7,STONE:3)
Block(-2,17,8,STONE:3)
Block(-2,18,-7,STONE:0)
Block(-2,18,-6,STONE:0)
Block(-2,18,-5,STONE:0)
Block(-2,18,-4,STONE:0)
Block(-2,18,-3,STONE:0)
Block(-2,18,-2,STONE:0)
Block(-2,18,-1,STONE:0)
Block(-2,18,0,STONE:0)
Block(-2,18,1,STONE:0)
Block(-2,18,2,STONE:3)
Block(-2,18,3,STONE:3)
Block(-2,18,4,STONE:3)
Block(-2,18,5,STONE:3)
Block(-2,18,6,STONE:3)
Block(-2,18,7,STONE:3)
Block(-2,18,8,STONE:3)
Block(-2,19,-7,OBSIDIAN:0)
Block(-2,19,-6,STONE:0)
Block(-2,19,-5,STONE:0)
Block(-2,19,-4,STONE:0)
Block(-2,19,-3,STONE:0)
Block(-2,19,-2,STONE:0)
Block(-2,19,-1,STONE:0)
Block(-2,19,0,STONE:0)
Block(-2,19,1,STONE:0)
Block(-2,19,2,STONE:0)
Block(-2,19,3,STONE:3)
Block(-2,19,4,STONE:3)
Block(-2,19,5,STONE:3)
Block(-2,19,6,STONE:3)
Block(-2,19,7,STONE:3)
Block(-2,19,8,STONE:3)
Block(-2,20,-7,OBSIDIAN:0)
Block(-2,20,-6,OBSIDIAN:0)
Block(-2,20,-5,OBSIDIAN:0)
Block(-2,20,-4,STONE:0)
Block(-2,20,-3,STONE:0)
Block(-2,20,-2,STONE:0)
Block(-2,20,-1,STONE:0)
Block(-2,20,0,STONE:0)
Block(-2,20,1,STONE:0)
Block(-2,20,2,STONE:0)
Block(-2,20,3,STONE:0)
Block(-2,20,4,STONE:3)
Block(-2,20,5,STONE:3)
Block(-2,20,6,STONE:3)
Block(-2,20,7,STONE:3)
Block(-2,20,8,STONE:3)
Block(-2,21,-7,AIR:0)
Block(-2,21,-6,OBSIDIAN:0)
Block(-2,21,-5,OBSIDIAN:0)
Block(-2,21,-4,STONE:0)
Block(-2,21,-3,STONE:0)
Block(-2,21,-2,STONE:0)
Block(-2,21,-1,STONE:0)
Block(-2,21,0,STONE:0)
Block(-2,21,1,STONE:0)
Block(-2,21,2,STONE:0)
Block(-2,21,3,STONE:0)
Block(-2,21,4,STONE:3)
Block(-2,21,5,STONE:3)
Block(-2,21,6,STONE:3)
Block(-2,21,7,STONE:3)
Block(-2,21,8,STONE:3)
Block(-2,22,-7,AIR:0)
Block(-2,22,-6,AIR:0)
Block(-2,22,-5,AIR:0)
Block(-2,22,-4,STONE:0)
Block(-2,22,-3,STONE:0)
Block(-2,22,-2,STONE:0)
Block(-2,22,-1,STONE:0)
Block(-2,22,0,STONE:0)
Block(-2,22,1,STONE:0)
Block(-2,22,2,STONE:0)
Block(-2,22,3,STONE:0)
Block(-2,22,4,STONE:0)
Block(-2,22,5,STONE:3)
Block(-2,22,6,STONE:3)
Block(-2,22,7,STONE:3)
Block(-2,22,8,OBSIDIAN:0)
Block(-2,23,-7,AIR:0)
Block(-2,23,-6,AIR:0)
Block(-2,23,-5,AIR:0)
Block(-2,23,-4,STONE:0)
Block(-2,23,-3,STONE:0)
Block(-2,23,-2,STONE:0)
Block(-2,23,-1,STONE:0)
Block(-2,23,0,STONE:0)
Block(-2,23,1,STONE:0)
Block(-2,23,2,STONE:0)
Block(-2,23,3,STONE:0)
Block(-2,23,4,STONE:0)
Block(-2,23,5,STONE:0)
Block(-2,23,6,STONE:0)
Block(-2,23,7,STONE:3)
Block(-2,23,8,OBSIDIAN:0)
Block(-2,24,-7,AIR:0)
Block(-2,24,-6,AIR:0)
Block(-2,24,-5,AIR:0)
Block(-2,24,-4,OBSIDIAN:0)
Block(-2,24,-3,STONE:0)
Block(-2,24,-2,STONE:0)
Block(-2,24,-1,STONE:0)
Block(-2,24,0,STONE:0)
Block(-2,24,1,STONE:0)
Block(-2,24,2,STONE:0)
Block(-2,24,3,STONE:0)
Block(-2,24,4,STONE:5)
Block(-2,24,5,STONE:5)
Block(-2,24,6,STONE:5)
Block(-2,24,7,STONE:5)
Block(-2,24,8,OBSIDIAN:0)
Block(-2,25,-7,AIR:0)
Block(-2,25,-6,AIR:0)
Block(-2,25,-5,OBSIDIAN:0)
Block(-2,25,-4,STONE:0)
Block(-2,25,-3,STONE:0)
Block(-2,25,-2,STONE:0)
Block(-2,25,-1,STONE:0)
Block(-2,25,0,STONE:0)
Block(-2,25,1,STONE:0)
Block(-2,25,2,STONE:0)
Block(-2,25,3,STONE:5)
Block(-2,25,4,STONE:5)
Block(-2,25,5,STONE:5)
Block(-2,25,6,STONE:5)
Block(-2,25,7,STONE:5)
Block(-2,25,8,STONE:5)
Block(-2,26,-7,AIR:0)
Block(-2,26,-6,OBSIDIAN:0)
Block(-2,26,-5,STONE:0)
Block(-2,26,-4,STONE:0)
Block(-2,26,-3,STONE:0)
Block(-2,26,-2,STONE:0)
Block(-2,26,-1,STONE:0)
Block(-2,26,0,STONE:0)
Block(-2,26,1,STONE:0)
Block(-2,26,2,STONE:0)
Block(-2,26,3,STONE:5)
Block(-2,26,4,STONE:5)
Block(-2,26,5,STONE:5)
Block(-2,26,6,STONE:5)
Block(-2,26,7,STONE:5)
Block(-2,26,8,STONE:5)
Block(-2,27,-7,AIR:0)
Block(-2,27,-6,STONE:0)
Block(-2,27,-5,STONE:0)
Block(-2,27,-4,STONE:0)
Block(-2,27,-3,STONE:0)
Block(-2,27,-2,STONE:0)
Block(-2,27,-1,STONE:0)
Block(-2,27,0,STONE:0)
Block(-2,27,1,STONE:0)
Block(-2,27,2,STONE:0)
Block(-2,27,3,STONE:5)
Block(-2,27,4,STONE:5)
Block(-2,27,5,STONE:5)
Block(-2,27,6,STONE:5)
Block(-2,27,7,STONE:5)
Block(-2,27,8,STONE:5)
Block(-2,28,-7,AIR:0)
Block(-2,28,-6,STONE:0)
Block(-2,28,-5,STONE:0)
Block(-2,28,-4,STONE:0)
Block(-2,28,-3,STONE:0)
Block(-2,28,-2,STONE:0)
Block(-2,28,-1,STONE:0)
Block(-2,28,0,STONE:0)
Block(-2,28,1,STONE:0)
Block(-2,28,2,STONE:0)
Block(-2,28,3,STONE:5)
Block(-2,28,4,STONE:5)
Block(-2,28,5,STONE:5)
Block(-2,28,6,STONE:5)
Block(-2,28,7,STONE:5)
Block(-2,28,8,STONE:5)
Block(-2,29,-7,AIR:0)
Block(-2,29,-6,STONE:0)
Block(-2,29,-5,STONE:0)
Block(-2,29,-4,STONE:0)
Block(-2,29,-3,STONE:0)
Block(-2,29,-2,STONE:0)
Block(-2,29,-1,STONE:0)
Block(-2,29,0,STONE:5)
Block(-2,29,1,STONE:5)
Block(-2,29,2,STONE:5)
Block(-2,29,3,STONE:5)
Block(-2,29,4,STONE:5)
Block(-2,29,5,STONE:5)
Block(-2,29,6,STONE:5)
Block(-2,29,7,STONE:5)
Block(-2,29,8,STONE:5)
Block(-2,30,-7,STONE:0)
Block(-2,30,-6,STONE:0)
Block(-2,30,-5,STONE:0)
Block(-2,30,-4,STONE:0)
Block(-2,30,-3,STONE:0)
Block(-2,30,-2,STONE:0)
Block(-2,30,-1,STONE:5)
Block(-2,30,0,STONE:5)
Block(-2,30,1,STONE:5)
Block(-2,30,2,STONE:5)
Block(-2,30,3,STONE:5)
Block(-2,30,4,STONE:5)
Block(-2,30,5,STONE:5)
Block(-2,30,6,STONE:5)
Block(-2,30,7,STONE:5)
Block(-2,30,8,STONE:5)
Block(-2,31,-7,OBSIDIAN:0)
Block(-2,31,-6,STONE:0)
Block(-2,31,-5,STONE:0)
Block(-2,31,-4,STONE:0)
Block(-2,31,-3,STONE:0)
Block(-2,31,-2,STONE:5)
Block(-2,31,-1,STONE:5)
Block(-2,31,0,STONE:5)
Block(-2,31,1,STONE:5)
Block(-2,31,2,STONE:5)
Block(-2,31,3,STONE:5)
Block(-2,31,4,STONE:5)
Block(-2,31,5,STONE:5)
Block(-2,31,6,STONE:5)
Block(-2,31,7,STONE:5)
Block(-2,32,-7,STONE:0)
Block(-2,32,-6,STONE:0)
Block(-2,32,-5,STONE:0)
Block(-2,32,-4,STONE:0)
Block(-2,32,-3,STONE:0)
Block(-2,32,-2,STONE:5)
Block(-2,32,-1,STONE:5)
Block(-2,32,0,STONE:5)
Block(-2,32,1,STONE:5)
Block(-2,32,2,STONE:5)
Block(-2,32,3,STONE:5)
Block(-2,32,4,STONE:5)
Block(-2,32,5,STONE:5)
Block(-2,32,6,STONE:5)
Block(-2,33,-7,STONE:0)
Block(-2,33,-6,STONE:0)
Block(-2,33,-5,STONE:0)
Block(-2,33,-4,STONE:0)
Block(-2,33,-3,STONE:0)
Block(-2,33,-2,STONE:5)
Block(-2,33,-1,STONE:5)
Block(-2,33,0,STONE:5)
Block(-2,33,1,STONE:5)
Block(-2,33,2,STONE:5)
Block(-2,33,3,STONE:5)
Block(-2,33,4,STONE:5)
Block(-2,33,5,STONE:5)
Block(-2,34,-7,STONE:0)
Block(-2,34,-6,STONE:0)
Block(-2,34,-5,STONE:0)
Block(-2,34,-4,STONE:0)
Block(-2,34,-3,STONE:0)
Block(-2,34,-2,STONE:5)
Block(-2,34,-1,STONE:5)
Block(-2,34,0,STONE:5)
Block(-2,34,1,STONE:5)
Block(-2,34,2,STONE:5)
Block(-2,34,3,STONE:5)
Block(-2,34,4,STONE:5)
Block(-2,35,-7,STONE:0)
Block(-2,35,-6,STONE:0)
Block(-2,35,-5,STONE:0)
Block(-2,35,-4,STONE:0)
Block(-2,35,-3,STONE:0)
Block(-2,35,-2,STONE:5)
Block(-2,35,-1,STONE:5)
Block(-2,35,0,STONE:5)
Block(-2,35,1,STONE:5)
Block(-2,35,2,STONE:5)
Block(-2,35,3,STONE:5)
Block(-2,36,-7,STONE:0)
Block(-2,36,-6,STONE:0)
Block(-2,36,-5,STONE:0)
Block(-2,36,-4,STONE:0)
Block(-2,36,-3,STONE:0)
Block(-2,36,-2,STONE:5)
Block(-2,36,-1,STONE:5)
Block(-2,36,0,STONE:5)
Block(-2,36,1,STONE:5)
Block(-2,36,2,STONE:5)
Block(-2,37,-7,STONE:0)
Block(-2,37,-6,STONE:0)
Block(-2,37,-5,STONE:0)
Block(-2,37,-4,STONE:0)
Block(-2,37,-3,STONE:0)
Block(-2,37,-2,STONE:5)
Block(-2,37,-1,STONE:5)
Block(-2,37,0,STONE:5)
Block(-2,37,1,STONE:5)
Block(-2,38,-7,STONE:0)
Block(-2,38,-6,STONE:0)
Block(-2,38,-5,STONE:0)
Block(-2,38,-4,STONE:0)
Block(-2,38,-3,STONE:0)
Block(-2,38,-2,STONE:5)
Block(-2,38,-1,STONE:5)
Block(-2,38,0,STONE:5)
Block(-2,39,-7,STONE:0)
Block(-2,39,-6,STONE:0)
Block(-2,39,-5,OBSIDIAN:0)
Block(-2,39,-4,OBSIDIAN:0)
Block(-2,39,-3,OBSIDIAN:0)
Block(-2,39,-2,OBSIDIAN:0)
Block(-2,39,-1,OBSIDIAN:0)
Block(-2,40,-7,STONE:0)
Block(-2,40,-6,STONE:0)
Block(-2,40,-5,OBSIDIAN:0)
Block(-2,40,-4,OBSIDIAN:0)
Block(-2,40,-3,OBSIDIAN:0)
Block(-2,40,-2,OBSIDIAN:0)
Block(-2,40,-1,OBSIDIAN:0)
Block(-2,41,-7,STONE:0)
Block(-2,41,-6,STONE:0)
Block(-2,41,-5,OBSIDIAN:0)
Block(-2,41,-4,OBSIDIAN:0)
Block(-2,41,-3,OBSIDIAN:0)
Block(-2,41,-2,OBSIDIAN:0)
Block(-2,42,-7,STONE:0)
Block(-2,42,-6,STONE:3)
Block(-2,43,-7,STONE:0)
Block(-2,43,-6,STONE:3)
Block(-1,9,-7,STONE:3)
Block(-1,10,-7,STONE:3)
Block(-1,10,-6,STONE:3)
Block(-1,10,-5,STONE:3)
Block(-1,10,-4,STONE:3)
Block(-1,11,-7,STONE:3)
Block(-1,11,-6,STONE:3)
Block(-1,11,-5,STONE:3)
Block(-1,11,-4,STONE:3)
Block(-1,11,-3,STONE:3)
Block(-1,11,-2,STONE:3)
Block(-1,11,-1,STONE:3)
Block(-1,12,-7,STONE:3)
Block(-1,12,-6,STONE:3)
Block(-1,12,-5,STONE:3)
Block(-1,12,-4,STONE:3)
Block(-1,12,-3,STONE:3)
Block(-1,12,-2,STONE:3)
Block(-1,12,-1,STONE:3)
Block(-1,12,0,STONE:3)
Block(-1,12,1,STONE:3)
Block(-1,13,-7,STONE:3)
Block(-1,13,-6,STONE:3)
Block(-1,13,-5,STONE:3)
Block(-1,13,-4,STONE:3)
Block(-1,13,-3,STONE:3)
Block(-1,13,-2,STONE:3)
Block(-1,13,-1,STONE:3)
Block(-1,13,0,STONE:3)
Block(-1,13,1,STONE:3)
Block(-1,13,2,STONE:3)
Block(-1,14,-7,STONE:3)
Block(-1,14,-6,STONE:3)
Block(-1,14,-5,STONE:3)
Block(-1,14,-4,STONE:3)
Block(-1,14,-3,STONE:3)
Block(-1,14,-2,STONE:3)
Block(-1,14,-1,STONE:3)
Block(-1,14,0,STONE:3)
Block(-1,14,1,STONE:3)
Block(-1,14,2,STONE:3)
Block(-1,14,3,STONE:3)
Block(-1,14,4,STONE:3)
Block(-1,15,-7,STONE:0)
Block(-1,15,-6,STONE:0)
Block(-1,15,-5,STONE:3)
Block(-1,15,-4,STONE:3)
Block(-1,15,-3,STONE:3)
Block(-1,15,-2,STONE:3)
Block(-1,15,-1,STONE:3)
Block(-1,15,0,STONE:3)
Block(-1,15,1,STONE:3)
Block(-1,15,2,STONE:3)
Block(-1,15,3,STONE:3)
Block(-1,15,4,STONE:3)
Block(-1,15,5,STONE:3)
Block(-1,16,-7,STONE:0)
Block(-1,16,-6,STONE:0)
Block(-1,16,-5,STONE:0)
Block(-1,16,-4,STONE:3)
Block(-1,16,-3,STONE:3)
Block(-1,16,-2,STONE:3)
Block(-1,16,-1,STONE:3)
Block(-1,16,0,STONE:3)
Block(-1,16,1,STONE:3)
Block(-1,16,2,STONE:3)
Block(-1,16,3,STONE:3)
Block(-1,16,4,STONE:3)
Block(-1,16,5,STONE:3)
Block(-1,16,6,STONE:3)
Block(-1,17,-7,STONE:0)
Block(-1,17,-6,STONE:0)
Block(-1,17,-5,STONE:0)
Block(-1,17,-4,STONE:0)
Block(-1,17,-3,STONE:0)
Block(-1,17,-2,STONE:3)
Block(-1,17,-1,STONE:3)
Block(-1,17,0,STONE:3)
Block(-1,17,1,STONE:0)
Block(-1,17,2,STONE:3)
Block(-1,17,3,STONE:3)
Block(-1,17,4,STONE:3)
Block(-1,17,5,STONE:3)
Block(-1,17,6,STONE:3)
Block(-1,17,7,STONE:3)
Block(-1,17,8,STONE:3)
Block(-1,18,-7,STONE:0)
Block(-1,18,-6,STONE:0)
Block(-1,18,-5,STONE:0)
Block(-1,18,-4,STONE:0)
Block(-1,18,-3,STONE:0)
Block(-1,18,-2,STONE:0)
Block(-1,18,-1,STONE:0)
Block(-1,18,0,STONE:0)
Block(-1,18,1,STONE:0)
Block(-1,18,2,STONE:3)
Block(-1,18,3,STONE:3)
Block(-1,18,4,STONE:3)
Block(-1,18,5,STONE:3)
Block(-1,18,6,STONE:3)
Block(-1,18,7,STONE:3)
Block(-1,18,8,STONE:3)
Block(-1,19,-7,STONE:0)
Block(-1,19,-6,STONE:0)
Block(-1,19,-5,STONE:0)
Block(-1,19,-4,STONE:0)
Block(-1,19,-3,STONE:0)
Block(-1,19,-2,STONE:0)
Block(-1,19,-1,STONE:0)
Block(-1,19,0,STONE:0)
Block(-1,19,1,STONE:0)
Block(-1,19,2,STONE:0)
Block(-1,19,3,STONE:3)
Block(-1,19,4,STONE:3)
Block(-1,19,5,STONE:3)
Block(-1,19,6,STONE:3)
Block(-1,19,7,STONE:3)
Block(-1,19,8,STONE:3)
Block(-1,20,-7,OBSIDIAN:0)
Block(-1,20,-6,OBSIDIAN:0)
Block(-1,20,-5,OBSIDIAN:0)
Block(-1,20,-4,OBSIDIAN:0)
Block(-1,20,-3,STONE:0)
Block(-1,20,-2,STONE:0)
Block(-1,20,-1,STONE:0)
Block(-1,20,0,STONE:0)
Block(-1,20,1,STONE:0)
Block(-1,20,2,STONE:0)
Block(-1,20,3,STONE:3)
Block(-1,20,4,STONE:3)
Block(-1,20,5,STONE:3)
Block(-1,20,6,STONE:3)
Block(-1,20,7,STONE:3)
Block(-1,20,8,STONE:3)
Block(-1,21,-7,OBSIDIAN:0)
Block(-1,21,-6,OBSIDIAN:0)
Block(-1,21,-5,OBSIDIAN:0)
Block(-1,21,-4,OBSIDIAN:0)
Block(-1,21,-3,OBSIDIAN:0)
Block(-1,21,-2,STONE:0)
Block(-1,21,-1,STONE:0)
Block(-1,21,0,STONE:0)
Block(-1,21,1,STONE:0)
Block(-1,21,2,STONE:0)
Block(-1,21,3,STONE:0)
Block(-1,21,4,STONE:3)
Block(-1,21,5,STONE:3)
Block(-1,21,6,STONE:3)
Block(-1,21,7,STONE:3)
Block(-1,21,8,OBSIDIAN:0)
Block(-1,22,-7,AIR:0)
Block(-1,22,-6,AIR:0)
Block(-1,22,-5,AIR:0)
Block(-1,22,-4,OBSIDIAN:0)
Block(-1,22,-3,OBSIDIAN:0)
Block(-1,22,-2,STONE:0)
Block(-1,22,-1,STONE:0)
Block(-1,22,0,STONE:0)
Block(-1,22,1,STONE:0)
Block(-1,22,2,STONE:0)
Block(-1,22,3,STONE:0)
Block(-1,22,4,STONE:0)
Block(-1,22,5,STONE:3)
Block(-1,22,6,STONE:3)
Block(-1,22,7,STONE:3)
Block(-1,22,8,OBSIDIAN:0)
Block(-1,23,-7,AIR:0)
Block(-1,23,-6,AIR:0)
Block(-1,23,-5,AIR:0)
Block(-1,23,-4,OBSIDIAN:0)
Block(-1,23,-3,STONE:0)
Block(-1,23,-2,STONE:0)
Block(-1,23,-1,STONE:0)
Block(-1,23,0,STONE:0)
Block(-1,23,1,STONE:0)
Block(-1,23,2,STONE:0)
Block(-1,23,3,STONE:0)
Block(-1,23,4,STONE:5)
Block(-1,23,5,STONE:5)
Block(-1,23,6,STONE:3)
Block(-1,23,7,STONE:3)
Block(-1,23,8,OBSIDIAN:0)
Block(-1,24,-7,AIR:0)
Block(-1,24,-6,AIR:0)
Block(-1,24,-5,OBSIDIAN:0)
Block(-1,24,-4,OBSIDIAN:0)
Block(-1,24,-3,STONE:0)
Block(-1,24,-2,STONE:0)
Block(-1,24,-1,STONE:0)
Block(-1,24,0,STONE:0)
Block(-1,24,1,STONE:0)
Block(-1,24,2,STONE:0)
Block(-1,24,3,STONE:5)
Block(-1,24,4,STONE:5)
Block(-1,24,5,STONE:5)
Block(-1,24,6,STONE:5)
Block(-1,24,7,STONE:5)
Block(-1,24,8,OBSIDIAN:0)
Block(-1,25,-7,AIR:0)
Block(-1,25,-6,OBSIDIAN:0)
Block(-1,25,-5,OBSIDIAN:0)
Block(-1,25,-4,OBSIDIAN:0)
Block(-1,25,-3,STONE:0)
Block(-1,25,-2,STONE:0)
Block(-1,25,-1,STONE:0)
Block(-1,25,0,STONE:0)
Block(-1,25,1,STONE:0)
Block(-1,25,2,STONE:5)
Block(-1,25,3,STONE:5)
Block(-1,25,4,STONE:5)
Block(-1,25,5,STONE:5)
Block(-1,25,6,STONE:5)
Block(-1,25,7,STONE:5)
Block(-1,25,8,STONE:5)
Block(-1,26,-7,AIR:0)
Block(-1,26,-6,OBSIDIAN:0)
Block(-1,26,-5,OBSIDIAN:0)
Block(-1,26,-4,STONE:0)
Block(-1,26,-3,STONE:0)
Block(-1,26,-2,STONE:0)
Block(-1,26,-1,STONE:0)
Block(-1,26,0,STONE:0)
Block(-1,26,1,STONE:0)
Block(-1,26,2,STONE:5)
Block(-1,26,3,STONE:5)
Block(-1,26,4,STONE:5)
Block(-1,26,5,STONE:5)
Block(-1,26,6,STONE:5)
Block(-1,26,7,STONE:5)
Block(-1,26,8,STONE:5)
Block(-1,27,-7,OBSIDIAN:0)
Block(-1,27,-6,OBSIDIAN:0)
Block(-1,27,-5,STONE:0)
Block(-1,27,-4,STONE:0)
Block(-1,27,-3,STONE:0)
Block(-1,27,-2,STONE:0)
Block(-1,27,-1,STONE:0)
Block(-1,27,0,STONE:0)
Block(-1,27,1,STONE:0)
Block(-1,27,2,STONE:5)
Block(-1,27,3,STONE:5)
Block(-1,27,4,STONE:5)
Block(-1,27,5,STONE:5)
Block(-1,27,6,STONE:5)
Block(-1,27,7,STONE:5)
Block(-1,27,8,STONE:5)
Block(-1,28,-7,OBSIDIAN:0)
Block(-1,28,-6,OBSIDIAN:0)
Block(-1,28,-5,STONE:0)
Block(-1,28,-4,STONE:0)
Block(-1,28,-3,STONE:0)
Block(-1,28,-2,STONE:0)
Block(-1,28,-1,STONE:0)
Block(-1,28,0,STONE:0)
Block(-1,28,1,STONE:5)
Block(-1,28,2,STONE:5)
Block(-1,28,3,STONE:5)
Block(-1,28,4,STONE:5)
Block(-1,28,5,STONE:5)
Block(-1,28,6,STONE:5)
Block(-1,28,7,STONE:5)
Block(-1,28,8,STONE:5)
Block(-1,29,-7,OBSIDIAN:0)
Block(-1,29,-6,OBSIDIAN:0)
Block(-1,29,-5,STONE:0)
Block(-1,29,-4,STONE:0)
Block(-1,29,-3,STONE:0)
Block(-1,29,-2,STONE:0)
Block(-1,29,-1,STONE:5)
Block(-1,29,0,STONE:5)
Block(-1,29,1,STONE:5)
Block(-1,29,2,STONE:5)
Block(-1,29,3,STONE:5)
Block(-1,29,4,STONE:5)
Block(-1,29,5,STONE:5)
Block(-1,29,6,STONE:5)
Block(-1,29,7,STONE:5)
Block(-1,29,8,STONE:5)
Block(-1,30,-7,OBSIDIAN:0)
Block(-1,30,-6,STONE:0)
Block(-1,30,-5,STONE:0)
Block(-1,30,-4,STONE:0)
Block(-1,30,-3,STONE:0)
Block(-1,30,-2,STONE:5)
Block(-1,30,-1,STONE:5)
Block(-1,30,0,STONE:5)
Block(-1,30,1,STONE:5)
Block(-1,30,2,STONE:5)
Block(-1,30,3,STONE:5)
Block(-1,30,4,STONE:5)
Block(-1,30,5,STONE:5)
Block(-1,30,6,STONE:5)
Block(-1,30,7,STONE:5)
Block(-1,31,-7,OBSIDIAN:0)
Block(-1,31,-6,STONE:0)
Block(-1,31,-5,STONE:0)
Block(-1,31,-4,STONE:0)
Block(-1,31,-3,STONE:0)
Block(-1,31,-2,STONE:5)
Block(-1,31,-1,STONE:5)
Block(-1,31,0,STONE:5)
Block(-1,31,1,STONE:5)
Block(-1,31,2,STONE:5)
Block(-1,31,3,STONE:5)
Block(-1,31,4,STONE:5)
Block(-1,31,5,STONE:5)
Block(-1,31,6,STONE:5)
Block(-1,32,-7,OBSIDIAN:0)
Block(-1,32,-6,STONE:0)
Block(-1,32,-5,STONE:0)
Block(-1,32,-4,STONE:0)
Block(-1,32,-3,STONE:5)
Block(-1,32,-2,STONE:5)
Block(-1,32,-1,STONE:5)
Block(-1,32,0,STONE:5)
Block(-1,32,1,STONE:5)
Block(-1,32,2,STONE:5)
Block(-1,32,3,STONE:5)
Block(-1,32,4,STONE:5)
Block(-1,32,5,STONE:5)
Block(-1,33,-7,STONE:0)
Block(-1,33,-6,STONE:0)
Block(-1,33,-5,STONE:0)
Block(-1,33,-4,STONE:0)
Block(-1,33,-3,STONE:5)
Block(-1,33,-2,STONE:5)
Block(-1,33,-1,STONE:5)
Block(-1,33,0,STONE:5)
Block(-1,33,1,STONE:5)
Block(-1,33,2,STONE:5)
Block(-1,33,3,STONE:5)
Block(-1,33,4,STONE:5)
Block(-1,33,5,STONE:5)
Block(-1,34,-7,STONE:0)
Block(-1,34,-6,STONE:0)
Block(-1,34,-5,STONE:0)
Block(-1,34,-4,STONE:0)
Block(-1,34,-3,STONE:5)
Block(-1,34,-2,STONE:5)
Block(-1,34,-1,STONE:5)
Block(-1,34,0,STONE:5)
Block(-1,34,1,STONE:5)
Block(-1,34,2,STONE:5)
Block(-1,34,3,STONE:5)
Block(-1,34,4,STONE:5)
Block(-1,35,-7,STONE:0)
Block(-1,35,-6,STONE:0)
Block(-1,35,-5,STONE:0)
Block(-1,35,-4,STONE:0)
Block(-1,35,-3,STONE:0)
Block(-1,35,-2,STONE:5)
Block(-1,35,-1,STONE:5)
Block(-1,35,0,STONE:5)
Block(-1,35,1,STONE:5)
Block(-1,35,2,STONE:5)
Block(-1,36,-7,STONE:0)
Block(-1,36,-6,STONE:0)
Block(-1,36,-5,STONE:0)
Block(-1,36,-4,STONE:0)
Block(-1,36,-3,STONE:0)
Block(-1,36,-2,STONE:5)
Block(-1,36,-1,STONE:5)
Block(-1,36,0,STONE:5)
Block(-1,36,1,STONE:5)
Block(-1,37,-7,STONE:0)
Block(-1,37,-6,STONE:0)
Block(-1,37,-5,STONE:0)
Block(-1,37,-4,STONE:0)
Block(-1,37,-3,STONE:0)
Block(-1,37,-2,STONE:5)
Block(-1,37,-1,STONE:5)
Block(-1,37,0,STONE:5)
Block(-1,37,1,STONE:5)
Block(-1,38,-7,STONE:0)
Block(-1,38,-6,STONE:0)
Block(-1,38,-5,OBSIDIAN:0)
Block(-1,38,-4,OBSIDIAN:0)
Block(-1,38,-3,OBSIDIAN:0)
Block(-1,38,-2,STONE:0)
Block(-1,38,-1,STONE:5)
Block(-1,39,-7,STONE:0)
Block(-1,39,-6,OBSIDIAN:0)
Block(-1,39,-5,OBSIDIAN:0)
Block(-1,39,-4,OBSIDIAN:0)
Block(-1,39,-3,OBSIDIAN:0)
Block(-1,39,-2,OBSIDIAN:0)
Block(-1,39,-1,STONE:5)
Block(-1,40,-7,STONE:0)
Block(-1,40,-6,OBSIDIAN:0)
Block(-1,40,-5,OBSIDIAN:0)
Block(-1,40,-4,OBSIDIAN:0)
Block(-1,40,-3,OBSIDIAN:0)
Block(-1,40,-2,OBSIDIAN:0)
Block(-1,41,-7,STONE:0)
Block(-1,41,-6,OBSIDIAN:0)
Block(-1,41,-5,OBSIDIAN:0)
Block(-1,41,-4,OBSIDIAN:0)
Block(-1,42,-7,STONE:0)
Block(-1,42,-6,STONE:0)
Block(-1,43,-7,STONE:3)
Block(-1,44,-7,STONE:3)
Block(0,10,-7,STONE:3)
Block(0,10,-6,STONE:3)
Block(0,11,-7,STONE:3)
Block(0,11,-6,STONE:3)
Block(0,11,-5,STONE:3)
Block(0,11,-4,STONE:3)
Block(0,11,-3,STONE:3)
Block(0,12,-7,STONE:3)
Block(0,12,-6,STONE:3)
Block(0,12,-5,STONE:3)
Block(0,12,-4,STONE:3)
Block(0,12,-3,STONE:3)
Block(0,12,-2,STONE:3)
Block(0,12,-1,STONE:3)
Block(0,12,0,STONE:3)
Block(0,13,-7,STONE:3)
Block(0,13,-6,STONE:3)
Block(0,13,-5,STONE:3)
Block(0,13,-4,STONE:3)
Block(0,13,-3,STONE:3)
Block(0,13,-2,STONE:3)
Block(0,13,-1,STONE:3)
Block(0,13,0,STONE:3)
Block(0,13,1,STONE:3)
Block(0,13,2,STONE:3)
Block(0,14,-7,STONE:3)
Block(0,14,-6,STONE:3)
Block(0,14,-5,STONE:3)
Block(0,14,-4,STONE:3)
Block(0,14,-3,STONE:3)
Block(0,14,-2,STONE:3)
Block(0,14,-1,STONE:3)
Block(0,14,0,STONE:3)
Block(0,14,1,STONE:3)
Block(0,14,2,STONE:3)
Block(0,14,3,STONE:3)
Block(0,15,-7,STONE:0)
Block(0,15,-6,STONE:0)
Block(0,15,-5,STONE:3)
Block(0,15,-4,STONE:3)
Block(0,15,-3,STONE:3)
Block(0,15,-2,STONE:3)
Block(0,15,-1,STONE:3)
Block(0,15,0,STONE:3)
Block(0,15,1,STONE:3)
Block(0,15,2,STONE:3)
Block(0,15,3,STONE:3)
Block(0,15,4,STONE:3)
Block(0,16,-7,STONE:0)
Block(0,16,-6,STONE:0)
Block(0,16,-5,STONE:0)
Block(0,16,-4,STONE:3)
Block(0,16,-3,STONE:3)
Block(0,16,-2,STONE:3)
Block(0,16,-1,STONE:3)
Block(0,16,0,STONE:3)
Block(0,16,1,STONE:3)
Block(0,16,2,STONE:3)
Block(0,16,3,STONE:3)
Block(0,16,4,STONE:3)
Block(0,16,5,STONE:3)
Block(0,16,6,STONE:3)
Block(0,17,-7,STONE:0)
Block(0,17,-6,STONE:0)
Block(0,17,-5,STONE:0)
Block(0,17,-4,STONE:0)
Block(0,17,-3,STONE:3)
Block(0,17,-2,STONE:3)
Block(0,17,-1,STONE:3)
Block(0,17,0,STONE:3)
Block(0,17,1,STONE:3)
Block(0,17,2,STONE:3)
Block(0,17,3,STONE:3)
Block(0,17,4,STONE:3)
Block(0,17,5,STONE:3)
Block(0,17,6,STONE:3)
Block(0,17,7,STONE:3)
Block(0,18,-7,STONE:0)
Block(0,18,-6,STONE:0)
Block(0,18,-5,STONE:0)
Block(0,18,-4,STONE:0)
Block(0,18,-3,STONE:0)
Block(0,18,-2,STONE:0)
Block(0,18,-1,STONE:0)
Block(0,18,0,STONE:0)
Block(0,18,1,STONE:3)
Block(0,18,2,STONE:3)
Block(0,18,3,STONE:3)
Block(0,18,4,STONE:3)
Block(0,18,5,STONE:3)
Block(0,18,6,STONE:3)
Block(0,18,7,STONE:3)
Block(0,18,8,STONE:3)
Block(0,19,-7,STONE:0)
Block(0,19,-6,STONE:0)
Block(0,19,-5,STONE:0)
Block(0,19,-4,STONE:0)
Block(0,19,-3,STONE:0)
Block(0,19,-2,STONE:0)
Block(0,19,-1,STONE:0)
Block(0,19,0,STONE:0)
Block(0,19,1,STONE:0)
Block(0,19,2,STONE:3)
Block(0,19,3,STONE:3)
Block(0,19,4,STONE:3)
Block(0,19,5,STONE:3)
Block(0,19,6,STONE:3)
Block(0,19,7,STONE:3)
Block(0,19,8,STONE:3)
Block(0,20,-7,OBSIDIAN:0)
Block(0,20,-6,OBSIDIAN:0)
Block(0,20,-5,OBSIDIAN:0)
Block(0,20,-4,OBSIDIAN:0)
Block(0,20,-3,OBSIDIAN:0)
Block(0,20,-2,STONE:0)
Block(0,20,-1,STONE:0)
Block(0,20,0,STONE:0)
Block(0,20,1,STONE:0)
Block(0,20,2,STONE:0)
Block(0,20,3,STONE:3)
Block(0,20,4,STONE:3)
Block(0,20,5,STONE:3)
Block(0,20,6,STONE:3)
Block(0,20,7,STONE:3)
Block(0,20,8,OBSIDIAN:0)
Block(0,21,-7,OBSIDIAN:0)
Block(0,21,-6,OBSIDIAN:0)
Block(0,21,-5,OBSIDIAN:0)
Block(0,21,-4,OBSIDIAN:0)
Block(0,21,-3,OBSIDIAN:0)
Block(0,21,-2,STONE:0)
Block(0,21,-1,STONE:0)
Block(0,21,0,STONE:0)
Block(0,21,1,STONE:0)
Block(0,21,2,STONE:0)
Block(0,21,3,STONE:0)
Block(0,21,4,STONE:3)
Block(0,21,5,STONE:3)
Block(0,21,6,STONE:3)
Block(0,21,7,OBSIDIAN:0)
Block(0,21,8,OBSIDIAN:0)
Block(0,22,-7,AIR:0)
Block(0,22,-6,AIR:0)
Block(0,22,-5,AIR:0)
Block(0,22,-4,OBSIDIAN:0)
Block(0,22,-3,OBSIDIAN:0)
Block(0,22,-2,STONE:0)
Block(0,22,-1,STONE:0)
Block(0,22,0,STONE:0)
Block(0,22,1,STONE:0)
Block(0,22,2,STONE:0)
Block(0,22,3,STONE:0)
Block(0,22,4,STONE:5)
Block(0,22,5,STONE:3)
Block(0,22,6,STONE:3)
Block(0,22,7,OBSIDIAN:0)
Block(0,22,8,OBSIDIAN:0)
Block(0,23,-7,AIR:0)
Block(0,23,-6,AIR:0)
Block(0,23,-5,AIR:0)
Block(0,23,-4,OBSIDIAN:0)
Block(0,23,-3,OBSIDIAN:0)
Block(0,23,-2,STONE:0)
Block(0,23,-1,STONE:0)
Block(0,23,0,STONE:0)
Block(0,23,1,STONE:0)
Block(0,23,2,STONE:0)
Block(0,23,3,STONE:5)
Block(0,23,4,STONE:5)
Block(0,23,5,STONE:5)
Block(0,23,6,STONE:3)
Block(0,23,7,OBSIDIAN:0)
