
#######################################################################
# +-----------------------------------------------------------------+ #
# |                            BO4 object                           | #
# +-----------------------------------------------------------------+ #
#######################################################################

Author: NLBlackEagle

Description: No description given

SettingsMode: WriteDisable


#######################################################################
# +-----------------------------------------------------------------+ #
# |                          Main settings                          | #
# +-----------------------------------------------------------------+ #
#######################################################################

Frequency: 0

SpawnHeight: highestBlock

UseCenterForHighestBlock: true

##############################
# Height Limits for the BO4. #
##############################

MinHeight: 0

MaxHeight: 255

InheritBO3: 

InheritBO3Rotation: NORTH

OverrideChildSettings: true

OverrideParentHeight: false

CanOverride: false

BranchFrequency: 0

BranchFrequencyGroup: 

MustBeBelowOther: false

MustBeInside: 

CannotBeInside: 

ReplacesBO3: 

MustBeInsideWorldBorders: false

CanSpawnOnWater: true

SpawnOnWaterOnly: false

SpawnUnderWater: false

SpawnAtWaterLevel: false

HeightOffset: 0

RemoveAir: true

ReplaceAbove: 

ReplaceBelow: 

ReplaceWithBiomeBlocks: true

ReplaceWithSurfaceBlock: GRASS

ReplaceWithGroundBlock: DIRT

ReplaceWithStoneBlock: STONE

SmoothRadius: 0

SmoothHeightOffset: 0

SmoothStartTop: false

SmoothStartWood: false

SmoothingSurfaceBlock: 

SmoothingGroundBlock: 

BO3Group: 

IsSpawnPoint: false

DoReplaceBlocks: true


#######################################################################
# +-----------------------------------------------------------------+ #
# |                              Blocks                             | #
# +-----------------------------------------------------------------+ #
#######################################################################

Block(-8,0,-7,STONE:6)
Block(-8,0,-6,STONE:6)
Block(-8,0,-5,STONE:6)
Block(-8,0,-4,STONE:6)
Block(-8,0,-3,STONE:6)
Block(-8,0,-2,STONE:6)
Block(-8,0,-1,DIRT:0)
Block(-8,0,0,DIRT:0)
Block(-8,0,1,DIRT:0)
Block(-8,0,2,DIRT:0)
Block(-8,0,3,DIRT:0)
Block(-8,0,4,DIRT:0)
Block(-8,0,5,DIRT:0)
Block(-8,0,6,DIRT:0)
Block(-8,0,7,DIRT:0)
Block(-8,0,8,DIRT:0)
Block(-8,1,-7,STONE:6)
Block(-8,1,-6,STONE:6)
Block(-8,1,-5,STONE:6)
Block(-8,1,-4,STONE:6)
Block(-8,1,-3,STONE:6)
Block(-8,1,-2,STONE:6)
Block(-8,1,-1,DIRT:0)
Block(-8,1,0,DIRT:0)
Block(-8,1,1,DIRT:0)
Block(-8,1,2,DIRT:0)
Block(-8,1,3,DIRT:0)
Block(-8,1,4,DIRT:0)
Block(-8,1,5,DIRT:0)
Block(-8,1,6,DIRT:0)
Block(-8,1,7,DIRT:0)
Block(-8,1,8,DIRT:0)
Block(-8,2,-7,STONE:6)
Block(-8,2,-6,STONE:6)
Block(-8,2,-5,STONE:6)
Block(-8,2,-4,STONE:6)
Block(-8,2,-3,STONE:6)
Block(-8,2,-2,STONE:6)
Block(-8,2,-1,DIRT:0)
Block(-8,2,0,DIRT:0)
Block(-8,2,1,DIRT:0)
Block(-8,2,2,DIRT:0)
Block(-8,2,3,DIRT:0)
Block(-8,2,4,DIRT:0)
Block(-8,2,5,DIRT:0)
Block(-8,2,6,DIRT:0)
Block(-8,2,7,DIRT:0)
Block(-8,2,8,DIRT:0)
Block(-8,3,-7,STONE:6)
Block(-8,3,-6,STONE:6)
Block(-8,3,-5,STONE:6)
Block(-8,3,-4,STONE:6)
Block(-8,3,-3,STONE:6)
Block(-8,3,-2,STONE:6)
Block(-8,3,-1,DIRT:0)
Block(-8,3,0,DIRT:0)
Block(-8,3,1,DIRT:0)
Block(-8,3,2,DIRT:0)
Block(-8,3,3,DIRT:0)
Block(-8,3,4,DIRT:0)
Block(-8,3,5,DIRT:0)
Block(-8,3,6,DIRT:0)
Block(-8,3,7,DIRT:0)
Block(-8,3,8,DIRT:0)
Block(-8,4,-7,STONE:6)
Block(-8,4,-6,STONE:6)
Block(-8,4,-5,STONE:6)
Block(-8,4,-4,STONE:6)
Block(-8,4,-3,STONE:6)
Block(-8,4,-2,STONE:6)
Block(-8,4,-1,DIRT:0)
Block(-8,4,0,DIRT:0)
Block(-8,4,1,DIRT:0)
Block(-8,4,2,DIRT:0)
Block(-8,4,3,DIRT:0)
Block(-8,4,4,DIRT:0)
Block(-8,4,5,DIRT:0)
Block(-8,4,6,DIRT:0)
Block(-8,4,7,DIRT:0)
Block(-8,4,8,DIRT:0)
Block(-8,5,-7,STONE:6)
Block(-8,5,-6,STONE:6)
Block(-8,5,-5,STONE:6)
Block(-8,5,-4,STONE:6)
Block(-8,5,-3,STONE:6)
Block(-8,5,-2,STONE:6)
Block(-8,5,-1,DIRT:0)
Block(-8,5,0,DIRT:0)
Block(-8,5,1,DIRT:0)
Block(-8,5,2,DIRT:0)
Block(-8,5,3,DIRT:0)
Block(-8,5,4,DIRT:0)
Block(-8,5,5,DIRT:0)
Block(-8,5,6,DIRT:0)
Block(-8,5,7,DIRT:0)
Block(-8,5,8,DIRT:0)
Block(-8,6,-7,STONE:6)
Block(-8,6,-6,STONE:6)
Block(-8,6,-5,STONE:6)
Block(-8,6,-4,STONE:6)
Block(-8,6,-3,STONE:6)
Block(-8,6,-2,STONE:6)
Block(-8,6,-1,DIRT:0)
Block(-8,6,0,DIRT:0)
Block(-8,6,1,DIRT:0)
Block(-8,6,2,DIRT:0)
Block(-8,6,3,DIRT:0)
Block(-8,6,4,DIRT:0)
Block(-8,6,5,DIRT:0)
Block(-8,6,6,DIRT:0)
Block(-8,6,7,DIRT:0)
Block(-8,6,8,DIRT:0)
Block(-8,7,-7,STONE:6)
Block(-8,7,-6,STONE:6)
Block(-8,7,-5,STONE:6)
Block(-8,7,-4,STONE:6)
Block(-8,7,-3,STONE:6)
Block(-8,7,-2,STONE:6)
Block(-8,7,-1,DIRT:0)
Block(-8,7,0,DIRT:0)
Block(-8,7,1,DIRT:0)
Block(-8,7,2,DIRT:0)
Block(-8,7,3,DIRT:0)
Block(-8,7,4,DIRT:0)
Block(-8,7,5,DIRT:0)
Block(-8,7,6,DIRT:0)
Block(-8,7,7,DIRT:0)
Block(-8,7,8,DIRT:0)
Block(-8,8,-7,STONE:6)
Block(-8,8,-6,STONE:6)
Block(-8,8,-5,STONE:6)
Block(-8,8,-4,STONE:6)
Block(-8,8,-3,STONE:6)
Block(-8,8,-2,STONE:6)
Block(-8,8,-1,DIRT:0)
Block(-8,8,0,DIRT:0)
Block(-8,8,1,DIRT:0)
Block(-8,8,2,DIRT:0)
Block(-8,8,3,DIRT:0)
Block(-8,8,4,DIRT:0)
Block(-8,8,5,DIRT:0)
Block(-8,8,6,DIRT:0)
Block(-8,8,7,DIRT:0)
Block(-8,8,8,DIRT:0)
Block(-8,9,-7,STONE:6)
Block(-8,9,-6,STONE:6)
Block(-8,9,-5,STONE:6)
Block(-8,9,-4,STONE:6)
Block(-8,9,-3,STONE:6)
Block(-8,9,-2,STONE:6)
Block(-8,9,-1,DIRT:0)
Block(-8,9,0,DIRT:0)
Block(-8,9,1,DIRT:0)
Block(-8,9,2,DIRT:0)
Block(-8,9,3,DIRT:0)
Block(-8,9,4,DIRT:0)
Block(-8,9,5,DIRT:0)
Block(-8,9,6,DIRT:0)
Block(-8,9,7,DIRT:0)
Block(-8,9,8,DIRT:0)
Block(-8,10,-7,STONE:6)
Block(-8,10,-6,STONE:6)
Block(-8,10,-5,STONE:6)
Block(-8,10,-4,STONE:6)
Block(-8,10,-3,STONE:6)
Block(-8,10,-2,STONE:6)
Block(-8,10,-1,DIRT:0)
Block(-8,10,0,DIRT:0)
Block(-8,10,1,DIRT:0)
Block(-8,10,2,DIRT:0)
Block(-8,10,3,DIRT:0)
Block(-8,10,4,DIRT:0)
Block(-8,10,5,DIRT:0)
Block(-8,10,6,DIRT:0)
Block(-8,10,7,DIRT:0)
Block(-8,10,8,DIRT:0)
Block(-8,11,-7,STONE:6)
Block(-8,11,-6,STONE:6)
Block(-8,11,-5,STONE:6)
Block(-8,11,-4,STONE:6)
Block(-8,11,-3,STONE:6)
Block(-8,11,-2,STONE:6)
Block(-8,11,-1,DIRT:0)
Block(-8,11,0,DIRT:0)
Block(-8,11,1,DIRT:0)
Block(-8,11,2,DIRT:0)
Block(-8,11,3,DIRT:0)
Block(-8,11,4,STONE:6)
Block(-8,11,5,STONE:6)
Block(-8,11,6,STONE:6)
Block(-8,11,7,STONE:6)
Block(-8,11,8,DIRT:0)
Block(-8,12,-7,STONE:6)
Block(-8,12,-6,STONE:6)
Block(-8,12,-5,COBBLESTONE:0)
Block(-8,12,-4,COBBLESTONE:0)
Block(-8,12,-3,COBBLESTONE:0)
Block(-8,12,-2,COBBLESTONE:0)
Block(-8,12,-1,COBBLESTONE:0)
Block(-8,12,0,COBBLESTONE:0)
Block(-8,12,1,STONE:6)
Block(-8,12,2,STONE:6)
Block(-8,12,3,STONE:6)
Block(-8,12,7,STONE:6)
Block(-8,12,8,COBBLESTONE:0)
Block(-8,13,-7,STONE:6)
Block(-8,13,-6,STONE:6)
Block(-8,13,-5,COBBLESTONE:0)
Block(-8,13,-4,COBBLESTONE:0)
Block(-8,13,-3,COBBLESTONE:0)
Block(-8,13,-2,COBBLESTONE:0)
Block(-8,13,-1,COBBLESTONE:0)
Block(-8,13,0,COBBLESTONE:0)
Block(-8,13,1,STONE:6)
Block(-8,13,2,STONE:6)
Block(-8,13,3,STONE:6)
Block(-8,13,7,STONE:6)
Block(-8,13,8,COBBLESTONE:0)
Block(-8,14,-7,STONE:6)
Block(-8,14,-6,STONE:6)
Block(-8,14,-5,COBBLESTONE:0)
Block(-8,14,-4,COBBLESTONE:0)
Block(-8,14,-3,COBBLESTONE:0)
Block(-8,14,-2,COBBLESTONE:0)
Block(-8,14,-1,COBBLESTONE:0)
Block(-8,14,0,COBBLESTONE:0)
Block(-8,14,1,STONE:6)
Block(-8,14,2,STONE:6)
Block(-8,14,3,STONE:6)
Block(-8,14,7,STONE:6)
Block(-8,14,8,COBBLESTONE:0)
Block(-8,15,-7,STONE:6)
Block(-8,15,-6,STONE:6)
Block(-8,15,-5,COBBLESTONE:0)
Block(-8,15,-4,COBBLESTONE:0)
Block(-8,15,-3,COBBLESTONE:0)
Block(-8,15,-2,COBBLESTONE:0)
Block(-8,15,-1,COBBLESTONE:0)
Block(-8,15,0,COBBLESTONE:0)
Block(-8,15,1,STONE:6)
Block(-8,15,2,STONE:6)
Block(-8,15,3,STONE:6)
Block(-8,15,7,STONE:6)
Block(-8,15,8,COBBLESTONE:0)
Block(-8,16,-7,STONE:6)
Block(-8,16,-6,STONE:6)
Block(-8,16,-5,COBBLESTONE:0)
Block(-8,16,-4,COBBLESTONE:0)
Block(-8,16,-3,COBBLESTONE:0)
Block(-8,16,-2,COBBLESTONE:0)
Block(-8,16,-1,COBBLESTONE:0)
Block(-8,16,0,COBBLESTONE:0)
Block(-8,16,1,STONE:6)
Block(-8,16,2,STONE:6)
Block(-8,16,3,STONE:6)
Block(-8,16,7,STONE:6)
Block(-8,16,8,COBBLESTONE:0)
Block(-8,17,-7,STONE:6)
Block(-8,17,-6,STONE:6)
Block(-8,17,-5,COBBLESTONE:0)
Block(-8,17,-4,COBBLESTONE:0)
Block(-8,17,-3,COBBLESTONE:0)
Block(-8,17,-2,COBBLESTONE:0)
Block(-8,17,-1,COBBLESTONE:0)
Block(-8,17,0,COBBLESTONE:0)
Block(-8,17,1,STONE:6)
Block(-8,17,2,STONE:6)
Block(-8,17,3,STONE:6)
Block(-8,17,7,STONE:6)
Block(-8,17,8,COBBLESTONE:0)
Block(-8,18,-7,STONE:6)
Block(-8,18,-6,STONE:6)
Block(-8,18,-5,COBBLESTONE:0)
Block(-8,18,-4,COBBLESTONE:0)
Block(-8,18,-3,COBBLESTONE:0)
Block(-8,18,-2,COBBLESTONE:0)
Block(-8,18,-1,COBBLESTONE:0)
Block(-8,18,0,COBBLESTONE:0)
Block(-8,18,1,STONE:6)
Block(-8,18,2,STONE:6)
Block(-8,18,3,STONE:6)
Block(-8,18,7,STONE:6)
Block(-8,18,8,COBBLESTONE:0)
Block(-8,19,-7,STONE:6)
Block(-8,19,-6,STONE:6)
Block(-8,19,-5,COBBLESTONE:0)
Block(-8,19,-4,COBBLESTONE:0)
Block(-8,19,-3,COBBLESTONE:0)
Block(-8,19,-2,COBBLESTONE:0)
Block(-8,19,-1,COBBLESTONE:0)
Block(-8,19,0,COBBLESTONE:0)
Block(-8,19,1,STONE:6)
Block(-8,19,2,STONE:6)
Block(-8,19,3,STONE:6)
Block(-8,19,7,STONE:6)
Block(-8,19,8,COBBLESTONE:0)
Block(-8,20,-7,STONE:6)
Block(-8,20,-6,STONE:6)
Block(-8,20,-5,COBBLESTONE:0)
Block(-8,20,-4,COBBLESTONE:0)
Block(-8,20,-3,COBBLESTONE:0)
Block(-8,20,-2,COBBLESTONE:0)
Block(-8,20,-1,COBBLESTONE:0)
Block(-8,20,0,COBBLESTONE:0)
Block(-8,20,1,STONE:6)
Block(-8,20,2,STONE:6)
Block(-8,20,3,STONE:6)
Block(-8,20,7,STONE:6)
Block(-8,20,8,COBBLESTONE:0)
Block(-8,21,-7,STONE:6)
Block(-8,21,-6,STONE:6)
Block(-8,21,-5,COBBLESTONE:0)
Block(-8,21,-4,COBBLESTONE:0)
Block(-8,21,-3,COBBLESTONE:0)
Block(-8,21,-2,COBBLESTONE:0)
Block(-8,21,-1,COBBLESTONE:0)
Block(-8,21,0,COBBLESTONE:0)
Block(-8,21,1,STONE:6)
Block(-8,21,2,STONE:6)
Block(-8,21,3,STONE:6)
Block(-8,21,7,STONE:6)
Block(-8,21,8,COBBLESTONE:0)
Block(-8,22,-7,STONE:6)
Block(-8,22,-6,STONE:6)
Block(-8,22,-5,COBBLESTONE:0)
Block(-8,22,-4,COBBLESTONE:0)
Block(-8,22,-3,COBBLESTONE:0)
Block(-8,22,-2,COBBLESTONE:0)
Block(-8,22,-1,COBBLESTONE:0)
Block(-8,22,0,COBBLESTONE:0)
Block(-8,22,1,STONE:6)
Block(-8,22,2,STONE:6)
Block(-8,22,3,STONE:6)
Block(-8,22,7,STONE:6)
Block(-8,22,8,COBBLESTONE:0)
Block(-8,23,-7,STONE:6)
Block(-8,23,-6,STONE:6)
Block(-8,23,-5,COBBLESTONE:0)
Block(-8,23,-4,COBBLESTONE:0)
Block(-8,23,-3,COBBLESTONE:0)
Block(-8,23,-2,COBBLESTONE:0)
Block(-8,23,-1,COBBLESTONE:0)
Block(-8,23,0,COBBLESTONE:0)
Block(-8,23,1,STONE:6)
Block(-8,23,2,STONE:6)
Block(-8,23,3,STONE:6)
Block(-8,23,7,STONE:6)
Block(-8,23,8,COBBLESTONE:0)
Block(-8,24,-7,STONE:6)
Block(-8,24,-6,STONE:6)
Block(-8,24,-5,COBBLESTONE:0)
Block(-8,24,-4,COBBLESTONE:0)
Block(-8,24,-3,COBBLESTONE:0)
Block(-8,24,-2,COBBLESTONE:0)
Block(-8,24,-1,COBBLESTONE:0)
Block(-8,24,0,COBBLESTONE:0)
Block(-8,24,1,STONE:6)
Block(-8,24,2,STONE:6)
Block(-8,24,3,STONE:6)
Block(-8,24,7,STONE:6)
Block(-8,24,8,COBBLESTONE:0)
Block(-8,25,-7,STONE:6)
Block(-8,25,-6,STONE:6)
Block(-8,25,-5,COBBLESTONE:0)
Block(-8,25,-4,COBBLESTONE:0)
Block(-8,25,-3,COBBLESTONE:0)
Block(-8,25,-2,COBBLESTONE:0)
Block(-8,25,-1,COBBLESTONE:0)
Block(-8,25,0,COBBLESTONE:0)
Block(-8,25,1,STONE:6)
Block(-8,25,2,STONE:6)
Block(-8,25,3,STONE:6)
Block(-8,25,7,STONE:6)
Block(-8,25,8,COBBLESTONE:0)
Block(-8,26,-7,STONE:6)
Block(-8,26,-6,STONE:6)
Block(-8,26,-5,COBBLESTONE:0)
Block(-8,26,-4,COBBLESTONE:0)
Block(-8,26,-3,COBBLESTONE:0)
Block(-8,26,-2,COBBLESTONE:0)
Block(-8,26,-1,COBBLESTONE:0)
Block(-8,26,0,COBBLESTONE:0)
Block(-8,26,1,STONE:6)
Block(-8,26,2,STONE:6)
Block(-8,26,3,STONE:6)
Block(-8,26,7,STONE:6)
Block(-8,26,8,COBBLESTONE:0)
Block(-8,27,7,STONE:6)
Block(-8,27,8,COBBLESTONE:0)
Block(-8,28,7,STONE:6)
Block(-8,28,8,COBBLESTONE:0)
Block(-8,29,7,STONE:6)
Block(-8,29,8,COBBLESTONE:0)
Block(-8,30,7,STONE:6)
Block(-8,30,8,COBBLESTONE:0)
Block(-8,31,7,STONE:6)
Block(-8,31,8,COBBLESTONE:0)
Block(-8,32,7,STONE:6)
Block(-8,32,8,COBBLESTONE:0)
Block(-8,33,7,STONE:6)
Block(-8,33,8,COBBLESTONE:0)
Block(-8,34,-7,STONE:6)
Block(-8,34,3,STONE:6)
Block(-8,34,7,STONE:6)
Block(-8,34,8,COBBLESTONE:0)
Block(-8,35,-7,STONE:6)
Block(-8,35,-6,STONE:6)
Block(-8,35,-5,COBBLESTONE:0)
Block(-8,35,1,STONE:6)
Block(-8,35,2,STONE:6)
Block(-8,35,3,STONE:6)
Block(-8,35,7,STONE:6)
Block(-8,35,8,COBBLESTONE:0)
Block(-8,36,-7,STONE:6)
Block(-8,36,-6,STONE:6)
Block(-8,36,-5,COBBLESTONE:0)
Block(-8,36,-4,COBBLESTONE:0)
Block(-8,36,-3,COBBLESTONE:0)
Block(-8,36,-2,COBBLESTONE:0)
Block(-8,36,-1,COBBLESTONE:0)
Block(-8,36,0,COBBLESTONE:0)
Block(-8,36,1,STONE:6)
Block(-8,36,2,STONE:6)
Block(-8,36,3,STONE:6)
Block(-8,36,7,STONE:6)
Block(-8,36,8,COBBLESTONE:0)
Block(-8,37,-7,STONE:6)
Block(-8,37,-6,STONE:6)
Block(-8,37,-5,COBBLESTONE:0)
Block(-8,37,-4,COBBLESTONE:0)
Block(-8,37,-3,COBBLESTONE:0)
Block(-8,37,-2,COBBLESTONE:0)
Block(-8,37,-1,COBBLESTONE:0)
Block(-8,37,0,COBBLESTONE:0)
Block(-8,37,1,STONE:6)
Block(-8,37,2,STONE:6)
Block(-8,37,3,STONE:6)
Block(-8,37,7,STONE:6)
Block(-8,37,8,COBBLESTONE:0)
Block(-8,38,-7,STEP:0)
Block(-8,38,-6,STEP:0)
Block(-8,38,8,COBBLESTONE:0)
Block(-8,39,8,COBBLESTONE:0)
Block(-8,40,8,COBBLESTONE:0)
Block(-8,41,8,COBBLESTONE:0)
Block(-8,42,7,STONE:6)
Block(-8,42,8,COBBLESTONE:0)
Block(-8,43,7,COBBLE_WALL:0)
Block(-8,43,8,COBBLE_WALL:0)
Block(-8,44,7,STEP:0)
Block(-8,44,8,STEP:0)
Block(-7,0,-6,STONE:6)
Block(-7,0,-5,STONE:6)
Block(-7,0,-4,STONE:6)
Block(-7,0,-3,STONE:6)
Block(-7,0,-2,STONE:6)
Block(-7,0,-1,STONE:6)
Block(-7,0,0,STONE:6)
Block(-7,0,1,STONE:6)
Block(-7,0,2,DIRT:0)
Block(-7,0,3,DIRT:0)
Block(-7,0,4,DIRT:0)
Block(-7,0,5,DIRT:0)
Block(-7,0,6,DIRT:0)
Block(-7,0,7,DIRT:0)
Block(-7,0,8,DIRT:0)
Block(-7,1,-6,STONE:6)
Block(-7,1,-5,STONE:6)
Block(-7,1,-4,STONE:6)
Block(-7,1,-3,STONE:6)
Block(-7,1,-2,STONE:6)
Block(-7,1,-1,STONE:6)
Block(-7,1,0,STONE:6)
Block(-7,1,1,STONE:6)
Block(-7,1,2,DIRT:0)
Block(-7,1,3,DIRT:0)
Block(-7,1,4,DIRT:0)
Block(-7,1,5,DIRT:0)
Block(-7,1,6,DIRT:0)
Block(-7,1,7,DIRT:0)
Block(-7,1,8,DIRT:0)
Block(-7,2,-6,STONE:6)
Block(-7,2,-5,STONE:6)
Block(-7,2,-4,STONE:6)
Block(-7,2,-3,STONE:6)
Block(-7,2,-2,STONE:6)
Block(-7,2,-1,STONE:6)
Block(-7,2,0,STONE:6)
Block(-7,2,1,STONE:6)
Block(-7,2,2,DIRT:0)
Block(-7,2,3,DIRT:0)
Block(-7,2,4,DIRT:0)
Block(-7,2,5,DIRT:0)
Block(-7,2,6,DIRT:0)
Block(-7,2,7,DIRT:0)
Block(-7,2,8,DIRT:0)
Block(-7,3,-6,STONE:6)
Block(-7,3,-5,STONE:6)
Block(-7,3,-4,STONE:6)
Block(-7,3,-3,STONE:6)
Block(-7,3,-2,STONE:6)
Block(-7,3,-1,STONE:6)
Block(-7,3,0,STONE:6)
Block(-7,3,1,STONE:6)
Block(-7,3,2,DIRT:0)
Block(-7,3,3,DIRT:0)
Block(-7,3,4,DIRT:0)
Block(-7,3,5,DIRT:0)
Block(-7,3,6,DIRT:0)
Block(-7,3,7,DIRT:0)
Block(-7,3,8,DIRT:0)
Block(-7,4,-6,STONE:6)
Block(-7,4,-5,STONE:6)
Block(-7,4,-4,STONE:6)
Block(-7,4,-3,STONE:6)
Block(-7,4,-2,STONE:6)
Block(-7,4,-1,STONE:6)
Block(-7,4,0,STONE:6)
Block(-7,4,1,STONE:6)
Block(-7,4,2,DIRT:0)
Block(-7,4,3,DIRT:0)
Block(-7,4,4,DIRT:0)
Block(-7,4,5,DIRT:0)
Block(-7,4,6,DIRT:0)
Block(-7,4,7,DIRT:0)
Block(-7,4,8,DIRT:0)
Block(-7,5,-6,STONE:6)
Block(-7,5,-5,STONE:6)
Block(-7,5,-4,STONE:6)
Block(-7,5,-3,STONE:6)
Block(-7,5,-2,STONE:6)
Block(-7,5,-1,STONE:6)
Block(-7,5,0,STONE:6)
Block(-7,5,1,STONE:6)
Block(-7,5,2,DIRT:0)
Block(-7,5,3,DIRT:0)
Block(-7,5,4,DIRT:0)
Block(-7,5,5,DIRT:0)
Block(-7,5,6,DIRT:0)
Block(-7,5,7,DIRT:0)
Block(-7,5,8,DIRT:0)
Block(-7,6,-6,STONE:6)
Block(-7,6,-5,STONE:6)
Block(-7,6,-4,STONE:6)
Block(-7,6,-3,STONE:6)
Block(-7,6,-2,STONE:6)
Block(-7,6,-1,STONE:6)
Block(-7,6,0,STONE:6)
Block(-7,6,1,STONE:6)
Block(-7,6,2,DIRT:0)
Block(-7,6,3,DIRT:0)
Block(-7,6,4,DIRT:0)
Block(-7,6,5,DIRT:0)
Block(-7,6,6,DIRT:0)
Block(-7,6,7,DIRT:0)
Block(-7,6,8,DIRT:0)
Block(-7,7,-6,STONE:6)
Block(-7,7,-5,STONE:6)
Block(-7,7,-4,STONE:6)
Block(-7,7,-3,STONE:6)
Block(-7,7,-2,STONE:6)
Block(-7,7,-1,STONE:6)
Block(-7,7,0,STONE:6)
Block(-7,7,1,STONE:6)
Block(-7,7,2,DIRT:0)
Block(-7,7,3,DIRT:0)
Block(-7,7,4,DIRT:0)
Block(-7,7,5,DIRT:0)
Block(-7,7,6,DIRT:0)
Block(-7,7,7,DIRT:0)
Block(-7,7,8,DIRT:0)
Block(-7,8,-6,STONE:6)
Block(-7,8,-5,STONE:6)
Block(-7,8,-4,STONE:6)
Block(-7,8,-3,STONE:6)
Block(-7,8,-2,STONE:6)
Block(-7,8,-1,STONE:6)
Block(-7,8,0,STONE:6)
Block(-7,8,1,STONE:6)
Block(-7,8,2,DIRT:0)
Block(-7,8,3,DIRT:0)
Block(-7,8,4,DIRT:0)
Block(-7,8,5,DIRT:0)
Block(-7,8,6,DIRT:0)
Block(-7,8,7,DIRT:0)
Block(-7,8,8,DIRT:0)
Block(-7,9,-6,STONE:6)
Block(-7,9,-5,STONE:6)
Block(-7,9,-4,STONE:6)
Block(-7,9,-3,STONE:6)
Block(-7,9,-2,STONE:6)
Block(-7,9,-1,STONE:6)
Block(-7,9,0,STONE:6)
Block(-7,9,1,STONE:6)
Block(-7,9,2,DIRT:0)
Block(-7,9,3,DIRT:0)
Block(-7,9,4,DIRT:0)
Block(-7,9,5,DIRT:0)
Block(-7,9,6,DIRT:0)
Block(-7,9,7,DIRT:0)
Block(-7,9,8,DIRT:0)
Block(-7,10,-6,STONE:6)
Block(-7,10,-5,STONE:6)
Block(-7,10,-4,STONE:6)
Block(-7,10,-3,STONE:6)
Block(-7,10,-2,STONE:6)
Block(-7,10,-1,STONE:6)
Block(-7,10,0,STONE:6)
Block(-7,10,1,STONE:6)
Block(-7,10,2,DIRT:0)
Block(-7,10,3,DIRT:0)
Block(-7,10,4,DIRT:0)
Block(-7,10,5,DIRT:0)
Block(-7,10,6,DIRT:0)
Block(-7,10,7,DIRT:0)
Block(-7,10,8,DIRT:0)
Block(-7,11,-6,STONE:6)
Block(-7,11,-5,STONE:6)
Block(-7,11,-4,STONE:6)
Block(-7,11,-3,STONE:6)
Block(-7,11,-2,STONE:6)
Block(-7,11,-1,STONE:6)
Block(-7,11,0,STONE:6)
Block(-7,11,1,STONE:6)
Block(-7,11,2,DIRT:0)
Block(-7,11,3,DIRT:0)
Block(-7,11,4,DIRT:0)
Block(-7,11,5,DIRT:0)
Block(-7,11,6,DIRT:0)
Block(-7,11,7,STONE:6)
Block(-7,11,8,STONE:6)
Block(-7,12,-6,STONE:6)
Block(-7,12,-5,STONE:6)
Block(-7,12,-4,STONE:6)
Block(-7,12,-3,STONE:6)
Block(-7,12,-2,COBBLESTONE:0)
Block(-7,12,-1,COBBLESTONE:0)
Block(-7,12,0,COBBLESTONE:0)
Block(-7,12,1,COBBLESTONE:0)
Block(-7,12,2,COBBLESTONE:0)
Block(-7,12,3,COBBLESTONE:0)
Block(-7,12,4,STONE:6)
Block(-7,12,5,STONE:6)
Block(-7,12,6,STONE:6)
Block(-7,12,7,STONE:6)
Block(-7,12,8,COBBLESTONE:0)
Block(-7,13,-6,STONE:6)
Block(-7,13,-5,STONE:6)
Block(-7,13,-4,STONE:6)
Block(-7,13,-3,STONE:6)
Block(-7,13,-2,COBBLESTONE:0)
Block(-7,13,-1,COBBLESTONE:0)
Block(-7,13,0,COBBLESTONE:0)
Block(-7,13,1,COBBLESTONE:0)
Block(-7,13,2,COBBLESTONE:0)
Block(-7,13,3,COBBLESTONE:0)
Block(-7,13,4,STONE:6)
Block(-7,13,5,STONE:6)
Block(-7,13,6,STONE:6)
Block(-7,13,7,STONE:6)
Block(-7,13,8,COBBLESTONE:0)
Block(-7,14,-6,STONE:6)
Block(-7,14,-5,STONE:6)
Block(-7,14,-4,STONE:6)
Block(-7,14,-3,STONE:6)
Block(-7,14,-2,COBBLESTONE:0)
Block(-7,14,-1,COBBLESTONE:0)
Block(-7,14,0,COBBLESTONE:0)
Block(-7,14,1,COBBLESTONE:0)
Block(-7,14,2,COBBLESTONE:0)
Block(-7,14,3,COBBLESTONE:0)
Block(-7,14,4,STONE:6)
Block(-7,14,5,STONE:6)
Block(-7,14,6,STONE:6)
Block(-7,14,7,STONE:6)
Block(-7,14,8,COBBLESTONE:0)
Block(-7,15,-6,STONE:6)
Block(-7,15,-5,STONE:6)
Block(-7,15,-4,STONE:6)
Block(-7,15,-3,STONE:6)
Block(-7,15,-2,COBBLESTONE:0)
Block(-7,15,-1,COBBLESTONE:0)
Block(-7,15,0,COBBLESTONE:0)
Block(-7,15,1,COBBLESTONE:0)
Block(-7,15,2,COBBLESTONE:0)
Block(-7,15,3,COBBLESTONE:0)
Block(-7,15,4,STONE:6)
Block(-7,15,5,STONE:6)
Block(-7,15,6,STONE:6)
Block(-7,15,7,STONE:6)
Block(-7,15,8,COBBLESTONE:0)
Block(-7,16,-6,STONE:6)
Block(-7,16,-5,STONE:6)
Block(-7,16,-4,STONE:6)
Block(-7,16,-3,STONE:6)
Block(-7,16,-2,COBBLESTONE:0)
Block(-7,16,-1,COBBLESTONE:0)
Block(-7,16,0,COBBLESTONE:0)
Block(-7,16,1,COBBLESTONE:0)
Block(-7,16,2,COBBLESTONE:0)
Block(-7,16,3,COBBLESTONE:0)
Block(-7,16,4,STONE:6)
Block(-7,16,5,STONE:6)
Block(-7,16,6,STONE:6)
Block(-7,16,7,STONE:6)
Block(-7,16,8,COBBLESTONE:0)
Block(-7,17,-6,STONE:6)
Block(-7,17,-5,STONE:6)
Block(-7,17,-4,STONE:6)
Block(-7,17,-3,STONE:6)
Block(-7,17,-2,COBBLESTONE:0)
Block(-7,17,-1,COBBLESTONE:0)
Block(-7,17,0,COBBLESTONE:0)
Block(-7,17,1,COBBLESTONE:0)
Block(-7,17,2,COBBLESTONE:0)
Block(-7,17,3,COBBLESTONE:0)
Block(-7,17,4,STONE:6)
Block(-7,17,5,STONE:6)
Block(-7,17,6,STONE:6)
Block(-7,17,7,STONE:6)
Block(-7,17,8,COBBLESTONE:0)
Block(-7,18,-6,STONE:6)
Block(-7,18,-5,STONE:6)
Block(-7,18,-4,STONE:6)
Block(-7,18,-3,STONE:6)
Block(-7,18,-2,COBBLESTONE:0)
Block(-7,18,-1,COBBLESTONE:0)
Block(-7,18,0,COBBLESTONE:0)
Block(-7,18,1,COBBLESTONE:0)
Block(-7,18,2,COBBLESTONE:0)
Block(-7,18,3,COBBLESTONE:0)
Block(-7,18,4,STONE:6)
Block(-7,18,5,STONE:6)
Block(-7,18,6,STONE:6)
Block(-7,18,7,STONE:6)
Block(-7,18,8,COBBLESTONE:0)
Block(-7,19,-6,STONE:6)
Block(-7,19,-5,STONE:6)
Block(-7,19,-4,STONE:6)
Block(-7,19,-3,STONE:6)
Block(-7,19,-2,COBBLESTONE:0)
Block(-7,19,-1,COBBLESTONE:0)
Block(-7,19,0,COBBLESTONE:0)
Block(-7,19,1,COBBLESTONE:0)
Block(-7,19,2,COBBLESTONE:0)
Block(-7,19,3,COBBLESTONE:0)
Block(-7,19,4,STONE:6)
Block(-7,19,5,STONE:6)
Block(-7,19,6,STONE:6)
Block(-7,19,7,STONE:6)
Block(-7,19,8,COBBLESTONE:0)
Block(-7,20,-6,STONE:6)
Block(-7,20,-5,STONE:6)
Block(-7,20,-4,STONE:6)
Block(-7,20,-3,STONE:6)
Block(-7,20,-2,COBBLESTONE:0)
Block(-7,20,-1,COBBLESTONE:0)
Block(-7,20,0,COBBLESTONE:0)
Block(-7,20,1,COBBLESTONE:0)
Block(-7,20,2,COBBLESTONE:0)
Block(-7,20,3,COBBLESTONE:0)
Block(-7,20,4,STONE:6)
Block(-7,20,5,STONE:6)
Block(-7,20,6,STONE:6)
Block(-7,20,7,STONE:6)
Block(-7,20,8,COBBLESTONE:0)
Block(-7,21,-6,STONE:6)
Block(-7,21,-5,STONE:6)
Block(-7,21,-4,STONE:6)
Block(-7,21,-3,STONE:6)
Block(-7,21,-2,COBBLESTONE:0)
Block(-7,21,-1,COBBLESTONE:0)
Block(-7,21,0,COBBLESTONE:0)
Block(-7,21,1,COBBLESTONE:0)
Block(-7,21,2,COBBLESTONE:0)
Block(-7,21,3,COBBLESTONE:0)
Block(-7,21,4,STONE:6)
Block(-7,21,5,STONE:6)
Block(-7,21,6,STONE:6)
Block(-7,21,7,STONE:6)
Block(-7,21,8,COBBLESTONE:0)
Block(-7,22,-6,STONE:6)
Block(-7,22,-5,STONE:6)
Block(-7,22,-4,STONE:6)
Block(-7,22,-3,STONE:6)
Block(-7,22,-2,COBBLESTONE:0)
Block(-7,22,-1,COBBLESTONE:0)
Block(-7,22,0,COBBLESTONE:0)
Block(-7,22,1,COBBLESTONE:0)
Block(-7,22,2,COBBLESTONE:0)
Block(-7,22,3,COBBLESTONE:0)
Block(-7,22,4,STONE:6)
Block(-7,22,5,STONE:6)
Block(-7,22,6,STONE:6)
Block(-7,22,7,STONE:6)
Block(-7,22,8,COBBLESTONE:0)
Block(-7,23,-6,STONE:6)
Block(-7,23,-5,STONE:6)
Block(-7,23,-4,STONE:6)
Block(-7,23,-3,STONE:6)
Block(-7,23,-2,COBBLESTONE:0)
Block(-7,23,-1,COBBLESTONE:0)
Block(-7,23,0,COBBLESTONE:0)
Block(-7,23,1,COBBLESTONE:0)
Block(-7,23,2,COBBLESTONE:0)
Block(-7,23,3,COBBLESTONE:0)
Block(-7,23,4,STONE:6)
Block(-7,23,5,STONE:6)
Block(-7,23,6,STONE:6)
Block(-7,23,7,STONE:6)
Block(-7,23,8,COBBLESTONE:0)
Block(-7,24,-6,STONE:6)
Block(-7,24,-5,STONE:6)
Block(-7,24,-4,STONE:6)
Block(-7,24,-3,STONE:6)
Block(-7,24,-2,COBBLESTONE:0)
Block(-7,24,-1,COBBLESTONE:0)
Block(-7,24,0,COBBLESTONE:0)
Block(-7,24,1,COBBLESTONE:0)
Block(-7,24,2,COBBLESTONE:0)
Block(-7,24,3,COBBLESTONE:0)
Block(-7,24,4,STONE:6)
Block(-7,24,5,STONE:6)
Block(-7,24,6,STONE:6)
Block(-7,24,7,STONE:6)
Block(-7,24,8,COBBLESTONE:0)
Block(-7,25,-6,STONE:6)
Block(-7,25,-5,STONE:6)
Block(-7,25,-4,STONE:6)
Block(-7,25,-3,STONE:6)
Block(-7,25,-2,COBBLESTONE:0)
Block(-7,25,-1,COBBLESTONE:0)
Block(-7,25,0,COBBLESTONE:0)
Block(-7,25,1,COBBLESTONE:0)
Block(-7,25,2,COBBLESTONE:0)
Block(-7,25,3,COBBLESTONE:0)
Block(-7,25,4,STONE:6)
Block(-7,25,5,STONE:6)
Block(-7,25,6,STONE:6)
Block(-7,25,7,STONE:6)
Block(-7,25,8,COBBLESTONE:0)
Block(-7,26,-6,STONE:6)
Block(-7,26,-5,STONE:6)
Block(-7,26,-4,STONE:6)
Block(-7,26,-3,STONE:6)
Block(-7,26,-2,COBBLESTONE:0)
Block(-7,26,-1,COBBLESTONE:0)
Block(-7,26,0,COBBLESTONE:0)
Block(-7,26,1,COBBLESTONE:0)
Block(-7,26,2,COBBLESTONE:0)
Block(-7,26,3,COBBLESTONE:0)
Block(-7,26,4,STONE:6)
Block(-7,26,5,STONE:6)
Block(-7,26,6,STONE:6)
Block(-7,26,7,STONE:6)
Block(-7,26,8,COBBLESTONE:0)
Block(-7,27,6,STONE:6)
Block(-7,27,7,STONE:6)
Block(-7,27,8,COBBLESTONE:0)
Block(-7,28,6,STONE:6)
Block(-7,28,7,STONE:6)
Block(-7,28,8,COBBLESTONE:0)
Block(-7,29,6,STONE:6)
Block(-7,29,7,STONE:6)
Block(-7,29,8,COBBLESTONE:0)
Block(-7,30,6,STONE:6)
Block(-7,30,7,STONE:6)
Block(-7,30,8,COBBLESTONE:0)
Block(-7,31,5,STONE:6)
Block(-7,31,6,STONE:6)
Block(-7,31,7,STONE:6)
Block(-7,31,8,COBBLESTONE:0)
Block(-7,32,5,STONE:6)
Block(-7,32,6,STONE:6)
Block(-7,32,7,STONE:6)
Block(-7,32,8,COBBLESTONE:0)
Block(-7,33,4,STONE:6)
Block(-7,33,5,STONE:6)
Block(-7,33,6,STONE:6)
Block(-7,33,7,STONE:6)
Block(-7,33,8,COBBLESTONE:0)
Block(-7,34,2,COBBLESTONE:0)
Block(-7,34,3,COBBLESTONE:0)
Block(-7,34,4,STONE:6)
Block(-7,34,5,STONE:6)
Block(-7,34,6,STONE:6)
Block(-7,34,7,STONE:6)
Block(-7,34,8,COBBLESTONE:0)
Block(-7,35,-6,STONE:6)
Block(-7,35,0,COBBLESTONE:0)
Block(-7,35,1,COBBLESTONE:0)
Block(-7,35,2,COBBLESTONE:0)
Block(-7,35,3,COBBLESTONE:0)
Block(-7,35,4,STONE:6)
Block(-7,35,5,STONE:6)
Block(-7,35,6,STONE:6)
Block(-7,35,7,STONE:6)
Block(-7,35,8,COBBLESTONE:0)
Block(-7,36,-6,STONE:6)
Block(-7,36,-5,STONE:6)
Block(-7,36,-4,STONE:6)
Block(-7,36,-3,STONE:6)
Block(-7,36,-2,COBBLESTONE:0)
Block(-7,36,-1,COBBLESTONE:0)
Block(-7,36,0,COBBLESTONE:0)
Block(-7,36,1,COBBLESTONE:0)
Block(-7,36,2,COBBLESTONE:0)
Block(-7,36,3,COBBLESTONE:0)
Block(-7,36,4,STONE:6)
Block(-7,36,5,STONE:6)
Block(-7,36,6,STONE:6)
Block(-7,36,7,STONE:6)
Block(-7,36,8,COBBLESTONE:0)
Block(-7,37,-6,STONE:6)
Block(-7,37,-5,STONE:6)
Block(-7,37,-4,STONE:6)
Block(-7,37,-3,STONE:6)
Block(-7,37,-2,COBBLESTONE:0)
Block(-7,37,-1,COBBLESTONE:0)
Block(-7,37,0,COBBLESTONE:0)
Block(-7,37,1,COBBLESTONE:0)
Block(-7,37,2,COBBLESTONE:0)
Block(-7,37,3,COBBLESTONE:0)
Block(-7,37,4,STONE:6)
Block(-7,37,5,STONE:6)
Block(-7,37,6,STONE:6)
Block(-7,37,7,STONE:6)
Block(-7,37,8,COBBLESTONE:0)
Block(-7,38,-6,STEP:0)
Block(-7,38,-5,STEP:0)
Block(-7,38,-4,STEP:0)
Block(-7,38,-3,STEP:0)
Block(-7,38,8,COBBLESTONE:0)
Block(-7,39,7,STONE:6)
Block(-7,39,8,COBBLESTONE:0)
Block(-7,40,7,STONE:6)
Block(-7,40,8,COBBLESTONE:0)
Block(-7,41,8,COBBLESTONE:0)
Block(-7,42,7,STONE:6)
Block(-7,42,8,COBBLESTONE:0)
Block(-7,43,7,COBBLE_WALL:0)
Block(-7,43,8,COBBLE_WALL:0)
Block(-7,44,7,STEP:0)
Block(-7,44,8,STEP:0)
Block(-6,0,-3,STONE:6)
Block(-6,0,-2,STONE:6)
Block(-6,0,-1,STONE:6)
Block(-6,0,0,STONE:6)
Block(-6,0,1,STONE:6)
Block(-6,0,2,STONE:6)
Block(-6,0,3,STONE:6)
Block(-6,0,4,DIRT:0)
Block(-6,0,5,DIRT:0)
Block(-6,0,6,DIRT:0)
Block(-6,0,7,DIRT:0)
Block(-6,0,8,DIRT:0)
Block(-6,1,-3,STONE:6)
Block(-6,1,-2,STONE:6)
Block(-6,1,-1,STONE:6)
Block(-6,1,0,STONE:6)
Block(-6,1,1,STONE:6)
Block(-6,1,2,STONE:6)
Block(-6,1,3,STONE:6)
Block(-6,1,4,DIRT:0)
Block(-6,1,5,DIRT:0)
Block(-6,1,6,DIRT:0)
Block(-6,1,7,DIRT:0)
Block(-6,1,8,DIRT:0)
Block(-6,2,-3,STONE:6)
Block(-6,2,-2,STONE:6)
Block(-6,2,-1,STONE:6)
Block(-6,2,0,STONE:6)
Block(-6,2,1,STONE:6)
Block(-6,2,2,STONE:6)
Block(-6,2,3,STONE:6)
Block(-6,2,4,DIRT:0)
Block(-6,2,5,DIRT:0)
Block(-6,2,6,DIRT:0)
Block(-6,2,7,DIRT:0)
Block(-6,2,8,DIRT:0)
Block(-6,3,-3,STONE:6)
Block(-6,3,-2,STONE:6)
Block(-6,3,-1,STONE:6)
Block(-6,3,0,STONE:6)
Block(-6,3,1,STONE:6)
Block(-6,3,2,STONE:6)
Block(-6,3,3,STONE:6)
Block(-6,3,4,DIRT:0)
Block(-6,3,5,DIRT:0)
Block(-6,3,6,DIRT:0)
Block(-6,3,7,DIRT:0)
Block(-6,3,8,DIRT:0)
Block(-6,4,-3,STONE:6)
Block(-6,4,-2,STONE:6)
Block(-6,4,-1,STONE:6)
Block(-6,4,0,STONE:6)
Block(-6,4,1,STONE:6)
Block(-6,4,2,STONE:6)
Block(-6,4,3,STONE:6)
Block(-6,4,4,DIRT:0)
Block(-6,4,5,DIRT:0)
Block(-6,4,6,DIRT:0)
Block(-6,4,7,DIRT:0)
Block(-6,4,8,DIRT:0)
Block(-6,5,-3,STONE:6)
Block(-6,5,-2,STONE:6)
Block(-6,5,-1,STONE:6)
Block(-6,5,0,STONE:6)
Block(-6,5,1,STONE:6)
Block(-6,5,2,STONE:6)
Block(-6,5,3,STONE:6)
Block(-6,5,4,DIRT:0)
Block(-6,5,5,DIRT:0)
Block(-6,5,6,DIRT:0)
Block(-6,5,7,DIRT:0)
Block(-6,5,8,DIRT:0)
Block(-6,6,-3,STONE:6)
Block(-6,6,-2,STONE:6)
Block(-6,6,-1,STONE:6)
Block(-6,6,0,STONE:6)
Block(-6,6,1,STONE:6)
Block(-6,6,2,STONE:6)
Block(-6,6,3,STONE:6)
Block(-6,6,4,DIRT:0)
Block(-6,6,5,DIRT:0)
Block(-6,6,6,DIRT:0)
Block(-6,6,7,DIRT:0)
Block(-6,6,8,DIRT:0)
Block(-6,7,-3,STONE:6)
Block(-6,7,-2,STONE:6)
Block(-6,7,-1,STONE:6)
Block(-6,7,0,STONE:6)
Block(-6,7,1,STONE:6)
Block(-6,7,2,STONE:6)
Block(-6,7,3,STONE:6)
Block(-6,7,4,DIRT:0)
Block(-6,7,5,DIRT:0)
Block(-6,7,6,DIRT:0)
Block(-6,7,7,DIRT:0)
Block(-6,7,8,DIRT:0)
Block(-6,8,-3,STONE:6)
Block(-6,8,-2,STONE:6)
Block(-6,8,-1,STONE:6)
Block(-6,8,0,STONE:6)
Block(-6,8,1,STONE:6)
Block(-6,8,2,STONE:6)
Block(-6,8,3,STONE:6)
Block(-6,8,4,DIRT:0)
Block(-6,8,5,DIRT:0)
Block(-6,8,6,DIRT:0)
Block(-6,8,7,DIRT:0)
Block(-6,8,8,DIRT:0)
Block(-6,9,-3,STONE:6)
Block(-6,9,-2,STONE:6)
Block(-6,9,-1,STONE:6)
Block(-6,9,0,STONE:6)
Block(-6,9,1,STONE:6)
Block(-6,9,2,STONE:6)
Block(-6,9,3,STONE:6)
Block(-6,9,4,DIRT:0)
Block(-6,9,5,DIRT:0)
Block(-6,9,6,DIRT:0)
Block(-6,9,7,DIRT:0)
Block(-6,9,8,DIRT:0)
Block(-6,10,-3,STONE:6)
Block(-6,10,-2,STONE:6)
Block(-6,10,-1,STONE:6)
Block(-6,10,0,STONE:6)
Block(-6,10,1,STONE:6)
Block(-6,10,2,STONE:6)
Block(-6,10,3,STONE:6)
Block(-6,10,4,DIRT:0)
Block(-6,10,5,DIRT:0)
Block(-6,10,6,DIRT:0)
Block(-6,10,7,DIRT:0)
Block(-6,10,8,DIRT:0)
Block(-6,11,-3,STONE:6)
Block(-6,11,-2,STONE:6)
Block(-6,11,-1,STONE:6)
Block(-6,11,0,STONE:6)
Block(-6,11,1,STONE:6)
Block(-6,11,2,STONE:6)
Block(-6,11,3,STONE:6)
Block(-6,11,4,DIRT:0)
Block(-6,11,5,DIRT:0)
Block(-6,11,6,DIRT:0)
Block(-6,11,7,DIRT:0)
Block(-6,11,8,DIRT:0)
Block(-6,12,-3,STONE:6)
Block(-6,12,-2,STONE:6)
Block(-6,12,-1,STONE:6)
Block(-6,12,0,STONE:6)
Block(-6,12,1,COBBLESTONE:0)
Block(-6,12,2,COBBLESTONE:0)
Block(-6,12,3,COBBLESTONE:0)
Block(-6,12,4,COBBLESTONE:0)
Block(-6,12,5,COBBLESTONE:0)
Block(-6,12,6,COBBLESTONE:0)
Block(-6,12,7,STONE:6)
Block(-6,12,8,STONE:6)
Block(-6,13,-3,STONE:6)
Block(-6,13,-2,STONE:6)
Block(-6,13,-1,STONE:6)
Block(-6,13,0,STONE:6)
Block(-6,13,1,COBBLESTONE:0)
Block(-6,13,2,COBBLESTONE:0)
Block(-6,13,3,COBBLESTONE:0)
Block(-6,13,4,COBBLESTONE:0)
Block(-6,13,5,COBBLESTONE:0)
Block(-6,13,6,COBBLESTONE:0)
Block(-6,13,7,STONE:6)
Block(-6,13,8,STONE:6)
Block(-6,14,-3,STONE:6)
Block(-6,14,-2,STONE:6)
Block(-6,14,-1,STONE:6)
Block(-6,14,0,STONE:6)
Block(-6,14,1,COBBLESTONE:0)
Block(-6,14,2,COBBLESTONE:0)
Block(-6,14,3,COBBLESTONE:0)
Block(-6,14,4,COBBLESTONE:0)
Block(-6,14,5,COBBLESTONE:0)
Block(-6,14,6,COBBLESTONE:0)
Block(-6,14,7,STONE:6)
Block(-6,14,8,STONE:6)
Block(-6,15,-3,STONE:6)
Block(-6,15,-2,STONE:6)
Block(-6,15,-1,STONE:6)
Block(-6,15,0,STONE:6)
Block(-6,15,1,COBBLESTONE:0)
Block(-6,15,2,COBBLESTONE:0)
Block(-6,15,3,COBBLESTONE:0)
Block(-6,15,4,COBBLESTONE:0)
Block(-6,15,5,COBBLESTONE:0)
Block(-6,15,6,COBBLESTONE:0)
Block(-6,15,7,STONE:6)
Block(-6,15,8,STONE:6)
Block(-6,16,-3,STONE:6)
Block(-6,16,-2,STONE:6)
Block(-6,16,-1,STONE:6)
Block(-6,16,0,STONE:6)
Block(-6,16,1,COBBLESTONE:0)
Block(-6,16,2,COBBLESTONE:0)
Block(-6,16,3,COBBLESTONE:0)
Block(-6,16,4,COBBLESTONE:0)
Block(-6,16,5,COBBLESTONE:0)
Block(-6,16,6,COBBLESTONE:0)
Block(-6,16,7,STONE:6)
Block(-6,16,8,STONE:6)
Block(-6,17,-3,STONE:6)
Block(-6,17,-2,STONE:6)
Block(-6,17,-1,STONE:6)
Block(-6,17,0,STONE:6)
Block(-6,17,1,COBBLESTONE:0)
Block(-6,17,2,COBBLESTONE:0)
Block(-6,17,3,COBBLESTONE:0)
Block(-6,17,4,COBBLESTONE:0)
Block(-6,17,5,COBBLESTONE:0)
Block(-6,17,6,COBBLESTONE:0)
Block(-6,17,7,STONE:6)
Block(-6,17,8,STONE:6)
Block(-6,18,-3,STONE:6)
Block(-6,18,-2,STONE:6)
Block(-6,18,-1,STONE:6)
Block(-6,18,0,STONE:6)
Block(-6,18,1,COBBLESTONE:0)
Block(-6,18,2,COBBLESTONE:0)
Block(-6,18,3,COBBLESTONE:0)
Block(-6,18,4,COBBLESTONE:0)
Block(-6,18,5,COBBLESTONE:0)
Block(-6,18,6,COBBLESTONE:0)
Block(-6,18,7,STONE:6)
Block(-6,18,8,STONE:6)
Block(-6,19,-3,STONE:6)
Block(-6,19,-2,STONE:6)
Block(-6,19,-1,STONE:6)
Block(-6,19,0,STONE:6)
Block(-6,19,1,COBBLESTONE:0)
Block(-6,19,2,COBBLESTONE:0)
Block(-6,19,3,COBBLESTONE:0)
Block(-6,19,4,COBBLESTONE:0)
Block(-6,19,5,COBBLESTONE:0)
Block(-6,19,6,COBBLESTONE:0)
Block(-6,19,7,STONE:6)
Block(-6,19,8,STONE:6)
Block(-6,20,-3,STONE:6)
Block(-6,20,-2,STONE:6)
Block(-6,20,-1,STONE:6)
Block(-6,20,0,STONE:6)
Block(-6,20,1,COBBLESTONE:0)
Block(-6,20,2,COBBLESTONE:0)
Block(-6,20,3,COBBLESTONE:0)
Block(-6,20,4,COBBLESTONE:0)
Block(-6,20,5,COBBLESTONE:0)
Block(-6,20,6,COBBLESTONE:0)
Block(-6,20,7,STONE:6)
Block(-6,20,8,STONE:6)
Block(-6,21,-3,STONE:6)
Block(-6,21,-2,STONE:6)
Block(-6,21,-1,STONE:6)
Block(-6,21,0,STONE:6)
Block(-6,21,1,COBBLESTONE:0)
Block(-6,21,2,COBBLESTONE:0)
Block(-6,21,3,COBBLESTONE:0)
Block(-6,21,4,COBBLESTONE:0)
Block(-6,21,5,COBBLESTONE:0)
Block(-6,21,6,COBBLESTONE:0)
Block(-6,21,7,STONE:6)
Block(-6,21,8,STONE:6)
Block(-6,22,-3,STONE:6)
Block(-6,22,-2,STONE:6)
Block(-6,22,-1,STONE:6)
Block(-6,22,0,STONE:6)
Block(-6,22,1,COBBLESTONE:0)
Block(-6,22,2,COBBLESTONE:0)
Block(-6,22,3,COBBLESTONE:0)
Block(-6,22,4,COBBLESTONE:0)
Block(-6,22,5,COBBLESTONE:0)
Block(-6,22,6,COBBLESTONE:0)
Block(-6,22,7,STONE:6)
Block(-6,22,8,STONE:6)
Block(-6,23,-3,STONE:6)
Block(-6,23,-2,STONE:6)
Block(-6,23,-1,STONE:6)
Block(-6,23,0,STONE:6)
Block(-6,23,1,COBBLESTONE:0)
Block(-6,23,2,COBBLESTONE:0)
Block(-6,23,3,COBBLESTONE:0)
Block(-6,23,4,COBBLESTONE:0)
Block(-6,23,5,COBBLESTONE:0)
Block(-6,23,6,COBBLESTONE:0)
Block(-6,23,7,STONE:6)
Block(-6,23,8,STONE:6)
Block(-6,24,-3,STONE:6)
Block(-6,24,-2,STONE:6)
Block(-6,24,-1,STONE:6)
Block(-6,24,0,STONE:6)
Block(-6,24,1,COBBLESTONE:0)
Block(-6,24,2,COBBLESTONE:0)
Block(-6,24,3,COBBLESTONE:0)
Block(-6,24,4,COBBLESTONE:0)
Block(-6,24,5,COBBLESTONE:0)
Block(-6,24,6,COBBLESTONE:0)
Block(-6,24,7,STONE:6)
Block(-6,24,8,STONE:6)
Block(-6,25,-3,STONE:6)
Block(-6,25,-2,STONE:6)
Block(-6,25,-1,STONE:6)
Block(-6,25,0,STONE:6)
Block(-6,25,1,COBBLESTONE:0)
Block(-6,25,2,COBBLESTONE:0)
Block(-6,25,3,COBBLESTONE:0)
Block(-6,25,4,COBBLESTONE:0)
Block(-6,25,5,COBBLESTONE:0)
Block(-6,25,6,COBBLESTONE:0)
Block(-6,25,7,STONE:6)
Block(-6,25,8,STONE:6)
Block(-6,26,-3,STONE:6)
Block(-6,26,-2,STONE:6)
Block(-6,26,-1,STONE:6)
Block(-6,26,0,STONE:6)
Block(-6,26,1,COBBLESTONE:0)
Block(-6,26,2,COBBLESTONE:0)
Block(-6,26,3,COBBLESTONE:0)
Block(-6,26,4,COBBLESTONE:0)
Block(-6,26,5,COBBLESTONE:0)
Block(-6,26,6,COBBLESTONE:0)
Block(-6,26,7,STONE:6)
Block(-6,26,8,STONE:6)
Block(-6,27,5,COBBLESTONE:0)
Block(-6,27,6,COBBLESTONE:0)
Block(-6,27,7,STONE:6)
Block(-6,27,8,STONE:6)
Block(-6,28,5,COBBLESTONE:0)
Block(-6,28,6,COBBLESTONE:0)
Block(-6,28,7,STONE:6)
Block(-6,28,8,STONE:6)
Block(-6,29,5,COBBLESTONE:0)
Block(-6,29,6,COBBLESTONE:0)
Block(-6,29,7,STONE:6)
Block(-6,29,8,STONE:6)
Block(-6,30,5,COBBLESTONE:0)
Block(-6,30,6,COBBLESTONE:0)
Block(-6,30,7,STONE:6)
Block(-6,30,8,STONE:6)
Block(-6,31,4,COBBLESTONE:0)
Block(-6,31,5,COBBLESTONE:0)
Block(-6,31,6,COBBLESTONE:0)
Block(-6,31,7,STONE:6)
Block(-6,31,8,STONE:6)
Block(-6,32,4,COBBLESTONE:0)
Block(-6,32,5,COBBLESTONE:0)
Block(-6,32,6,COBBLESTONE:0)
Block(-6,32,7,STONE:6)
Block(-6,32,8,STONE:6)
Block(-6,33,3,COBBLESTONE:0)
Block(-6,33,4,COBBLESTONE:0)
Block(-6,33,5,COBBLESTONE:0)
Block(-6,33,6,COBBLESTONE:0)
Block(-6,33,7,STONE:6)
Block(-6,33,8,STONE:6)
Block(-6,34,1,COBBLESTONE:0)
Block(-6,34,2,COBBLESTONE:0)
Block(-6,34,3,COBBLESTONE:0)
Block(-6,34,4,COBBLESTONE:0)
Block(-6,34,5,COBBLESTONE:0)
Block(-6,34,6,COBBLESTONE:0)
Block(-6,34,7,STONE:6)
Block(-6,34,8,STONE:6)
Block(-6,35,-1,STONE:6)
Block(-6,35,0,STONE:6)
Block(-6,35,1,COBBLESTONE:0)
Block(-6,35,2,COBBLESTONE:0)
Block(-6,35,3,COBBLESTONE:0)
Block(-6,35,4,COBBLESTONE:0)
Block(-6,35,5,COBBLESTONE:0)
Block(-6,35,6,COBBLESTONE:0)
Block(-6,35,7,STONE:6)
Block(-6,35,8,STONE:6)
Block(-6,36,-3,STONE:6)
Block(-6,36,-2,STONE:6)
Block(-6,36,-1,STONE:6)
Block(-6,36,0,STONE:6)
Block(-6,36,1,COBBLESTONE:0)
Block(-6,36,2,COBBLESTONE:0)
Block(-6,36,3,COBBLESTONE:0)
Block(-6,36,4,COBBLESTONE:0)
Block(-6,36,5,COBBLESTONE:0)
Block(-6,36,6,COBBLESTONE:0)
Block(-6,36,7,STONE:6)
Block(-6,36,8,STONE:6)
Block(-6,37,-3,STONE:6)
Block(-6,37,-2,STONE:6)
Block(-6,37,-1,STONE:6)
Block(-6,37,0,STONE:6)
Block(-6,37,1,COBBLESTONE:0)
Block(-6,37,2,COBBLESTONE:0)
Block(-6,37,3,COBBLESTONE:0)
Block(-6,37,4,COBBLESTONE:0)
Block(-6,37,5,COBBLESTONE:0)
Block(-6,37,6,COBBLESTONE:0)
Block(-6,37,7,STONE:6)
Block(-6,37,8,STONE:6)
Block(-6,38,-3,STEP:0)
Block(-6,38,-2,STEP:0)
Block(-6,38,-1,STEP:0)
Block(-6,38,0,STEP:0)
Block(-6,38,7,STONE:6)
Block(-6,38,8,COBBLE_WALL:0)
Block(-6,39,7,STONE:6)
Block(-6,39,8,COBBLE_WALL:0)
Block(-6,40,7,STONE:6)
Block(-6,40,8,COBBLE_WALL:0)
Block(-6,41,7,STONE:6)
Block(-6,41,8,COBBLE_WALL:0)
Block(-6,42,7,STONE:6)
Block(-6,42,8,COBBLE_WALL:0)
Block(-6,43,7,COBBLE_WALL:0)
Block(-6,43,8,COBBLE_WALL:0)
Block(-6,44,7,STEP:0)
Block(-6,44,8,STEP:0)
Block(-5,0,0,STONE:6)
Block(-5,0,1,STONE:6)
Block(-5,0,2,STONE:6)
Block(-5,0,3,STONE:6)
Block(-5,0,4,STONE:6)
Block(-5,0,5,STONE:6)
Block(-5,0,6,STONE:6)
Block(-5,0,7,DIRT:0)
Block(-5,0,8,DIRT:0)
Block(-5,1,0,STONE:6)
Block(-5,1,1,STONE:6)
Block(-5,1,2,STONE:6)
Block(-5,1,3,STONE:6)
Block(-5,1,4,STONE:6)
Block(-5,1,5,STONE:6)
Block(-5,1,6,STONE:6)
Block(-5,1,7,DIRT:0)
Block(-5,1,8,DIRT:0)
Block(-5,2,0,STONE:6)
Block(-5,2,1,STONE:6)
Block(-5,2,2,STONE:6)
Block(-5,2,3,STONE:6)
Block(-5,2,4,STONE:6)
Block(-5,2,5,STONE:6)
Block(-5,2,6,STONE:6)
Block(-5,2,7,DIRT:0)
Block(-5,2,8,DIRT:0)
Block(-5,3,0,STONE:6)
Block(-5,3,1,STONE:6)
Block(-5,3,2,STONE:6)
Block(-5,3,3,STONE:6)
Block(-5,3,4,STONE:6)
Block(-5,3,5,STONE:6)
Block(-5,3,6,STONE:6)
Block(-5,3,7,DIRT:0)
Block(-5,3,8,DIRT:0)
Block(-5,4,0,STONE:6)
Block(-5,4,1,STONE:6)
Block(-5,4,2,STONE:6)
Block(-5,4,3,STONE:6)
Block(-5,4,4,STONE:6)
Block(-5,4,5,STONE:6)
Block(-5,4,6,STONE:6)
Block(-5,4,7,DIRT:0)
Block(-5,4,8,DIRT:0)
Block(-5,5,0,STONE:6)
Block(-5,5,1,STONE:6)
Block(-5,5,2,STONE:6)
Block(-5,5,3,STONE:6)
Block(-5,5,4,STONE:6)
Block(-5,5,5,STONE:6)
Block(-5,5,6,STONE:6)
Block(-5,5,7,DIRT:0)
Block(-5,5,8,DIRT:0)
Block(-5,6,0,STONE:6)
Block(-5,6,1,STONE:6)
Block(-5,6,2,STONE:6)
Block(-5,6,3,STONE:6)
Block(-5,6,4,STONE:6)
Block(-5,6,5,STONE:6)
Block(-5,6,6,STONE:6)
Block(-5,6,7,DIRT:0)
Block(-5,6,8,DIRT:0)
Block(-5,7,0,STONE:6)
Block(-5,7,1,STONE:6)
Block(-5,7,2,STONE:6)
Block(-5,7,3,STONE:6)
Block(-5,7,4,STONE:6)
Block(-5,7,5,STONE:6)
Block(-5,7,6,STONE:6)
Block(-5,7,7,DIRT:0)
Block(-5,7,8,DIRT:0)
Block(-5,8,0,STONE:6)
Block(-5,8,1,STONE:6)
Block(-5,8,2,STONE:6)
Block(-5,8,3,STONE:6)
Block(-5,8,4,STONE:6)
Block(-5,8,5,STONE:6)
Block(-5,8,6,STONE:6)
Block(-5,8,7,DIRT:0)
Block(-5,8,8,DIRT:0)
Block(-5,9,0,STONE:6)
Block(-5,9,1,STONE:6)
Block(-5,9,2,STONE:6)
Block(-5,9,3,STONE:6)
Block(-5,9,4,STONE:6)
Block(-5,9,5,STONE:6)
Block(-5,9,6,STONE:6)
Block(-5,9,7,DIRT:0)
Block(-5,9,8,DIRT:0)
Block(-5,10,0,STONE:6)
Block(-5,10,1,STONE:6)
Block(-5,10,2,STONE:6)
Block(-5,10,3,STONE:6)
Block(-5,10,4,STONE:6)
Block(-5,10,5,STONE:6)
Block(-5,10,6,STONE:6)
Block(-5,10,7,DIRT:0)
Block(-5,10,8,DIRT:0)
Block(-5,11,0,STONE:6)
Block(-5,11,1,STONE:6)
Block(-5,11,2,STONE:6)
Block(-5,11,3,STONE:6)
Block(-5,11,4,STONE:6)
Block(-5,11,5,STONE:6)
Block(-5,11,6,STONE:6)
Block(-5,11,7,DIRT:0)
Block(-5,11,8,DIRT:0)
Block(-5,12,0,STONE:6)
Block(-5,12,1,STONE:6)
Block(-5,12,2,STONE:6)
Block(-5,12,3,STONE:6)
Block(-5,12,4,COBBLESTONE:0)
Block(-5,12,5,COBBLESTONE:0)
Block(-5,12,6,COBBLESTONE:0)
Block(-5,12,7,COBBLESTONE:0)
Block(-5,12,8,COBBLESTONE:0)
Block(-5,13,0,STONE:6)
Block(-5,13,1,STONE:6)
Block(-5,13,2,STONE:6)
Block(-5,13,3,STONE:6)
Block(-5,13,4,COBBLESTONE:0)
Block(-5,13,5,COBBLESTONE:0)
Block(-5,13,6,COBBLESTONE:0)
Block(-5,13,7,COBBLESTONE:0)
Block(-5,13,8,COBBLESTONE:0)
Block(-5,14,0,STONE:6)
Block(-5,14,1,STONE:6)
Block(-5,14,2,STONE:6)
Block(-5,14,3,STONE:6)
Block(-5,14,4,COBBLESTONE:0)
Block(-5,14,5,COBBLESTONE:0)
Block(-5,14,6,COBBLESTONE:0)
Block(-5,14,7,COBBLESTONE:0)
Block(-5,14,8,COBBLESTONE:0)
Block(-5,15,0,STONE:6)
Block(-5,15,1,STONE:6)
Block(-5,15,2,STONE:6)
Block(-5,15,3,STONE:6)
Block(-5,15,4,COBBLESTONE:0)
Block(-5,15,5,COBBLESTONE:0)
Block(-5,15,6,COBBLESTONE:0)
Block(-5,15,7,COBBLESTONE:0)
Block(-5,15,8,COBBLESTONE:0)
Block(-5,16,0,STONE:6)
Block(-5,16,1,STONE:6)
Block(-5,16,2,STONE:6)
Block(-5,16,3,STONE:6)
Block(-5,16,4,COBBLESTONE:0)
Block(-5,16,5,COBBLESTONE:0)
Block(-5,16,6,COBBLESTONE:0)
Block(-5,16,7,COBBLESTONE:0)
Block(-5,16,8,COBBLESTONE:0)
Block(-5,17,0,STONE:6)
Block(-5,17,1,STONE:6)
Block(-5,17,2,STONE:6)
Block(-5,17,3,STONE:6)
Block(-5,17,4,COBBLESTONE:0)
Block(-5,17,5,COBBLESTONE:0)
Block(-5,17,6,COBBLESTONE:0)
Block(-5,17,7,COBBLESTONE:0)
Block(-5,17,8,COBBLESTONE:0)
Block(-5,18,0,STONE:6)
Block(-5,18,1,STONE:6)
Block(-5,18,2,STONE:6)
Block(-5,18,3,STONE:6)
Block(-5,18,4,COBBLESTONE:0)
Block(-5,18,5,COBBLESTONE:0)
Block(-5,18,6,COBBLESTONE:0)
Block(-5,18,7,COBBLESTONE:0)
Block(-5,18,8,COBBLESTONE:0)
Block(-5,19,0,STONE:6)
Block(-5,19,1,STONE:6)
Block(-5,19,2,STONE:6)
Block(-5,19,3,STONE:6)
Block(-5,19,4,COBBLESTONE:0)
Block(-5,19,5,COBBLESTONE:0)
Block(-5,19,6,COBBLESTONE:0)
Block(-5,19,7,COBBLESTONE:0)
Block(-5,19,8,COBBLESTONE:0)
Block(-5,20,0,STONE:6)
Block(-5,20,1,STONE:6)
Block(-5,20,2,STONE:6)
Block(-5,20,3,STONE:6)
Block(-5,20,4,COBBLESTONE:0)
Block(-5,20,5,COBBLESTONE:0)
Block(-5,20,6,COBBLESTONE:0)
Block(-5,20,7,COBBLESTONE:0)
Block(-5,20,8,COBBLESTONE:0)
Block(-5,21,0,STONE:6)
Block(-5,21,1,STONE:6)
Block(-5,21,2,STONE:6)
Block(-5,21,3,STONE:6)
Block(-5,21,4,COBBLESTONE:0)
Block(-5,21,5,COBBLESTONE:0)
Block(-5,21,6,COBBLESTONE:0)
Block(-5,21,7,COBBLESTONE:0)
Block(-5,21,8,COBBLESTONE:0)
Block(-5,22,0,STONE:6)
Block(-5,22,1,STONE:6)
Block(-5,22,2,STONE:6)
Block(-5,22,3,STONE:6)
Block(-5,22,4,COBBLESTONE:0)
Block(-5,22,5,COBBLESTONE:0)
Block(-5,22,6,COBBLESTONE:0)
Block(-5,22,7,COBBLESTONE:0)
Block(-5,22,8,COBBLESTONE:0)
Block(-5,23,0,STONE:6)
Block(-5,23,1,STONE:6)
Block(-5,23,2,STONE:6)
Block(-5,23,3,STONE:6)
Block(-5,23,4,COBBLESTONE:0)
Block(-5,23,5,COBBLESTONE:0)
Block(-5,23,6,COBBLESTONE:0)
Block(-5,23,7,COBBLESTONE:0)
Block(-5,23,8,COBBLESTONE:0)
Block(-5,24,0,STONE:6)
Block(-5,24,1,STONE:6)
Block(-5,24,2,STONE:6)
Block(-5,24,3,STONE:6)
Block(-5,24,4,COBBLESTONE:0)
Block(-5,24,5,COBBLESTONE:0)
Block(-5,24,6,COBBLESTONE:0)
Block(-5,24,7,COBBLESTONE:0)
Block(-5,24,8,COBBLESTONE:0)
Block(-5,25,0,STONE:6)
Block(-5,25,1,STONE:6)
Block(-5,25,2,STONE:6)
Block(-5,25,3,STONE:6)
Block(-5,25,4,COBBLESTONE:0)
Block(-5,25,5,COBBLESTONE:0)
Block(-5,25,6,COBBLESTONE:0)
Block(-5,25,7,COBBLESTONE:0)
Block(-5,25,8,COBBLESTONE:0)
Block(-5,26,0,STONE:6)
Block(-5,26,1,STONE:6)
Block(-5,26,2,STONE:6)
Block(-5,26,3,STONE:6)
Block(-5,26,4,COBBLESTONE:0)
Block(-5,26,5,COBBLESTONE:0)
Block(-5,26,6,COBBLESTONE:0)
Block(-5,26,7,COBBLESTONE:0)
Block(-5,26,8,COBBLESTONE:0)
Block(-5,27,4,COBBLESTONE:0)
Block(-5,27,5,COBBLESTONE:0)
Block(-5,27,6,COBBLESTONE:0)
Block(-5,27,7,COBBLESTONE:0)
Block(-5,27,8,COBBLESTONE:0)
Block(-5,28,4,COBBLESTONE:0)
Block(-5,28,5,COBBLESTONE:0)
Block(-5,28,6,COBBLESTONE:0)
Block(-5,28,7,COBBLESTONE:0)
Block(-5,28,8,COBBLESTONE:0)
Block(-5,29,4,COBBLESTONE:0)
Block(-5,29,5,COBBLESTONE:0)
Block(-5,29,6,COBBLESTONE:0)
Block(-5,29,7,COBBLESTONE:0)
Block(-5,29,8,COBBLESTONE:0)
Block(-5,30,4,COBBLESTONE:0)
Block(-5,30,5,COBBLESTONE:0)
Block(-5,30,6,COBBLESTONE:0)
Block(-5,30,7,COBBLESTONE:0)
Block(-5,30,8,COBBLESTONE:0)
Block(-5,31,3,STONE:6)
Block(-5,31,4,COBBLESTONE:0)
Block(-5,31,5,COBBLESTONE:0)
Block(-5,31,6,COBBLESTONE:0)
Block(-5,31,7,COBBLESTONE:0)
Block(-5,31,8,COBBLESTONE:0)
Block(-5,32,3,STONE:6)
Block(-5,32,4,COBBLESTONE:0)
Block(-5,32,5,COBBLESTONE:0)
Block(-5,32,6,COBBLESTONE:0)
Block(-5,32,7,COBBLESTONE:0)
Block(-5,32,8,COBBLESTONE:0)
Block(-5,33,2,STONE:6)
Block(-5,33,3,STONE:6)
Block(-5,33,4,COBBLESTONE:0)
Block(-5,33,5,COBBLESTONE:0)
Block(-5,33,6,COBBLESTONE:0)
Block(-5,33,7,COBBLESTONE:0)
Block(-5,33,8,COBBLESTONE:0)
Block(-5,34,0,STONE:6)
Block(-5,34,1,STONE:6)
Block(-5,34,2,STONE:6)
Block(-5,34,3,STONE:6)
Block(-5,34,4,COBBLESTONE:0)
Block(-5,34,5,COBBLESTONE:0)
Block(-5,34,6,COBBLESTONE:0)
Block(-5,34,7,COBBLESTONE:0)
Block(-5,34,8,COBBLESTONE:0)
Block(-5,35,0,STONE:6)
Block(-5,35,1,STONE:6)
Block(-5,35,2,STONE:6)
Block(-5,35,3,STONE:6)
Block(-5,35,4,COBBLESTONE:0)
Block(-5,35,5,COBBLESTONE:0)
Block(-5,35,6,COBBLESTONE:0)
Block(-5,35,7,COBBLESTONE:0)
Block(-5,35,8,COBBLESTONE:0)
Block(-5,36,0,STONE:6)
Block(-5,36,1,STONE:6)
Block(-5,36,2,STONE:6)
Block(-5,36,3,STONE:6)
Block(-5,36,4,COBBLESTONE:0)
Block(-5,36,5,COBBLESTONE:0)
Block(-5,36,6,COBBLESTONE:0)
Block(-5,36,7,COBBLESTONE:0)
Block(-5,36,8,COBBLESTONE:0)
Block(-5,37,0,STONE:6)
Block(-5,37,1,STONE:6)
Block(-5,37,2,STONE:6)
Block(-5,37,3,STONE:6)
Block(-5,37,4,COBBLESTONE:0)
Block(-5,37,5,COBBLESTONE:0)
Block(-5,37,6,COBBLESTONE:0)
Block(-5,37,7,COBBLESTONE:0)
Block(-5,37,8,COBBLESTONE:0)
Block(-5,38,0,STEP:0)
Block(-5,38,1,STEP:0)
Block(-5,38,2,STEP:0)
Block(-5,38,3,STEP:0)
Block(-4,0,3,STONE:6)
Block(-4,0,4,STONE:6)
Block(-4,0,5,STONE:6)
Block(-4,0,6,STONE:6)
Block(-4,0,7,STONE:6)
Block(-4,0,8,STONE:6)
Block(-4,1,3,STONE:6)
Block(-4,1,4,STONE:6)
Block(-4,1,5,STONE:6)
Block(-4,1,6,STONE:6)
Block(-4,1,7,STONE:6)
Block(-4,1,8,STONE:6)
Block(-4,2,3,STONE:6)
Block(-4,2,4,STONE:6)
Block(-4,2,5,STONE:6)
Block(-4,2,6,STONE:6)
Block(-4,2,7,STONE:6)
Block(-4,2,8,STONE:6)
Block(-4,3,3,STONE:6)
Block(-4,3,4,STONE:6)
Block(-4,3,5,STONE:6)
Block(-4,3,6,STONE:6)
Block(-4,3,7,STONE:6)
Block(-4,3,8,STONE:6)
Block(-4,4,3,STONE:6)
Block(-4,4,4,STONE:6)
Block(-4,4,5,STONE:6)
Block(-4,4,6,STONE:6)
Block(-4,4,7,STONE:6)
Block(-4,4,8,STONE:6)
Block(-4,5,3,STONE:6)
Block(-4,5,4,STONE:6)
Block(-4,5,5,STONE:6)
Block(-4,5,6,STONE:6)
Block(-4,5,7,STONE:6)
Block(-4,5,8,STONE:6)
Block(-4,6,3,STONE:6)
Block(-4,6,4,STONE:6)
Block(-4,6,5,STONE:6)
Block(-4,6,6,STONE:6)
Block(-4,6,7,STONE:6)
Block(-4,6,8,STONE:6)
Block(-4,7,3,STONE:6)
Block(-4,7,4,STONE:6)
Block(-4,7,5,STONE:6)
Block(-4,7,6,STONE:6)
Block(-4,7,7,STONE:6)
Block(-4,7,8,STONE:6)
Block(-4,8,3,STONE:6)
Block(-4,8,4,STONE:6)
Block(-4,8,5,STONE:6)
Block(-4,8,6,STONE:6)
Block(-4,8,7,STONE:6)
Block(-4,8,8,STONE:6)
Block(-4,9,3,STONE:6)
Block(-4,9,4,STONE:6)
Block(-4,9,5,STONE:6)
Block(-4,9,6,STONE:6)
Block(-4,9,7,STONE:6)
Block(-4,9,8,STONE:6)
Block(-4,10,3,STONE:6)
Block(-4,10,4,STONE:6)
Block(-4,10,5,STONE:6)
Block(-4,10,6,STONE:6)
Block(-4,10,7,STONE:6)
Block(-4,10,8,STONE:6)
Block(-4,11,3,STONE:6)
Block(-4,11,4,STONE:6)
Block(-4,11,5,STONE:6)
Block(-4,11,6,STONE:6)
Block(-4,11,7,STONE:6)
Block(-4,11,8,STONE:6)
Block(-4,12,3,STONE:6)
Block(-4,12,4,STONE:6)
Block(-4,12,5,STONE:6)
Block(-4,12,6,STONE:6)
Block(-4,12,7,COBBLESTONE:0)
Block(-4,12,8,COBBLESTONE:0)
Block(-4,13,3,STONE:6)
Block(-4,13,4,STONE:6)
Block(-4,13,5,STONE:6)
Block(-4,13,6,STONE:6)
Block(-4,13,7,COBBLESTONE:0)
Block(-4,13,8,COBBLESTONE:0)
Block(-4,14,3,STONE:6)
Block(-4,14,4,STONE:6)
Block(-4,14,5,STONE:6)
Block(-4,14,6,STONE:6)
Block(-4,14,7,COBBLESTONE:0)
Block(-4,14,8,COBBLESTONE:0)
Block(-4,15,3,STONE:6)
Block(-4,15,4,STONE:6)
Block(-4,15,5,STONE:6)
Block(-4,15,6,STONE:6)
Block(-4,15,7,COBBLESTONE:0)
Block(-4,15,8,COBBLESTONE:0)
Block(-4,16,3,STONE:6)
Block(-4,16,4,STONE:6)
Block(-4,16,5,STONE:6)
Block(-4,16,6,STONE:6)
Block(-4,16,7,COBBLESTONE:0)
Block(-4,16,8,COBBLESTONE:0)
Block(-4,17,3,STONE:6)
Block(-4,17,4,STONE:6)
Block(-4,17,5,STONE:6)
Block(-4,17,6,STONE:6)
Block(-4,17,7,COBBLESTONE:0)
Block(-4,17,8,COBBLESTONE:0)
Block(-4,18,3,STONE:6)
Block(-4,18,4,STONE:6)
Block(-4,18,5,STONE:6)
Block(-4,18,6,STONE:6)
Block(-4,18,7,COBBLESTONE:0)
Block(-4,18,8,COBBLESTONE:0)
Block(-4,19,3,STONE:6)
Block(-4,19,4,STONE:6)
Block(-4,19,5,STONE:6)
Block(-4,19,6,STONE:6)
Block(-4,19,7,COBBLESTONE:0)
Block(-4,19,8,COBBLESTONE:0)
Block(-4,20,3,STONE:6)
Block(-4,20,4,STONE:6)
Block(-4,20,5,STONE:6)
Block(-4,20,6,STONE:6)
Block(-4,20,7,COBBLESTONE:0)
Block(-4,20,8,COBBLESTONE:0)
Block(-4,21,3,STONE:6)
Block(-4,21,4,STONE:6)
Block(-4,21,5,STONE:6)
Block(-4,21,6,STONE:6)
Block(-4,21,7,COBBLESTONE:0)
Block(-4,21,8,COBBLESTONE:0)
Block(-4,22,3,STONE:6)
Block(-4,22,4,STONE:6)
Block(-4,22,5,STONE:6)
Block(-4,22,6,STONE:6)
Block(-4,22,7,COBBLESTONE:0)
Block(-4,22,8,COBBLESTONE:0)
Block(-4,23,3,STONE:6)
Block(-4,23,4,STONE:6)
Block(-4,23,5,STONE:6)
Block(-4,23,6,STONE:6)
Block(-4,23,7,COBBLESTONE:0)
Block(-4,23,8,COBBLESTONE:0)
Block(-4,24,3,STONE:6)
Block(-4,24,4,STONE:6)
Block(-4,24,5,STONE:6)
Block(-4,24,6,STONE:6)
Block(-4,24,7,COBBLESTONE:0)
Block(-4,24,8,COBBLESTONE:0)
Block(-4,25,3,STONE:6)
Block(-4,25,4,STONE:6)
Block(-4,25,5,STONE:6)
Block(-4,25,6,STONE:6)
Block(-4,25,7,COBBLESTONE:0)
Block(-4,25,8,COBBLESTONE:0)
Block(-4,26,3,STONE:6)
Block(-4,26,4,STONE:6)
Block(-4,26,5,STONE:6)
Block(-4,26,6,STONE:6)
Block(-4,26,7,COBBLESTONE:0)
Block(-4,26,8,COBBLESTONE:0)
Block(-4,27,3,STONE:6)
Block(-4,27,4,STONE:6)
Block(-4,27,5,STONE:6)
Block(-4,27,6,STONE:6)
Block(-4,27,7,COBBLESTONE:0)
Block(-4,27,8,COBBLESTONE:0)
Block(-4,28,3,STONE:6)
Block(-4,28,4,STONE:6)
Block(-4,28,5,STONE:6)
Block(-4,28,6,STONE:6)
Block(-4,28,7,COBBLESTONE:0)
Block(-4,28,8,COBBLESTONE:0)
Block(-4,29,3,STONE:6)
Block(-4,29,4,STONE:6)
Block(-4,29,5,STONE:6)
Block(-4,29,6,STONE:6)
Block(-4,29,7,COBBLESTONE:0)
Block(-4,29,8,COBBLESTONE:0)
Block(-4,30,3,STONE:6)
Block(-4,30,4,STONE:6)
Block(-4,30,5,STONE:6)
Block(-4,30,6,STONE:6)
Block(-4,30,7,COBBLESTONE:0)
Block(-4,30,8,COBBLESTONE:0)
Block(-4,31,3,STONE:6)
Block(-4,31,4,STONE:6)
Block(-4,31,5,STONE:6)
Block(-4,31,6,STONE:6)
Block(-4,31,7,COBBLESTONE:0)
Block(-4,31,8,COBBLESTONE:0)
Block(-4,32,3,STONE:6)
Block(-4,32,4,STONE:6)
Block(-4,32,5,STONE:6)
Block(-4,32,6,STONE:6)
Block(-4,32,7,COBBLESTONE:0)
Block(-4,32,8,COBBLESTONE:0)
Block(-4,33,3,STONE:6)
Block(-4,33,4,STONE:6)
Block(-4,33,5,STONE:6)
Block(-4,33,6,STONE:6)
Block(-4,33,7,COBBLESTONE:0)
Block(-4,33,8,COBBLESTONE:0)
Block(-4,34,3,STONE:6)
Block(-4,34,4,STONE:6)
Block(-4,34,5,STONE:6)
Block(-4,34,6,STONE:6)
Block(-4,34,7,COBBLESTONE:0)
Block(-4,34,8,COBBLESTONE:0)
Block(-4,35,3,STONE:6)
Block(-4,35,4,STONE:6)
Block(-4,35,5,STONE:6)
Block(-4,35,6,STONE:6)
Block(-4,35,7,COBBLESTONE:0)
Block(-4,35,8,COBBLESTONE:0)
Block(-4,36,3,STONE:6)
Block(-4,36,4,STONE:6)
Block(-4,36,5,STONE:6)
Block(-4,36,6,STONE:6)
Block(-4,36,7,COBBLESTONE:0)
Block(-4,36,8,COBBLESTONE:0)
Block(-4,37,3,STONE:6)
Block(-4,37,4,STONE:6)
Block(-4,37,5,STONE:6)
Block(-4,37,6,STONE:6)
Block(-4,37,7,COBBLESTONE:0)
Block(-4,37,8,COBBLESTONE:0)
Block(-4,38,3,STEP:0)
Block(-4,38,4,STEP:0)
Block(-4,38,5,STEP:0)
Block(-4,38,6,STEP:0)
Block(-3,0,6,STONE:6)
Block(-3,0,7,STONE:6)
Block(-3,0,8,STONE:6)
Block(-3,1,6,STONE:6)
Block(-3,1,7,STONE:6)
Block(-3,1,8,STONE:6)
Block(-3,2,6,STONE:6)
Block(-3,2,7,STONE:6)
Block(-3,2,8,STONE:6)
Block(-3,3,6,STONE:6)
Block(-3,3,7,STONE:6)
Block(-3,3,8,STONE:6)
Block(-3,4,6,STONE:6)
Block(-3,4,7,STONE:6)
Block(-3,4,8,STONE:6)
Block(-3,5,6,STONE:6)
Block(-3,5,7,STONE:6)
Block(-3,5,8,STONE:6)
Block(-3,6,6,STONE:6)
Block(-3,6,7,STONE:6)
Block(-3,6,8,STONE:6)
Block(-3,7,6,STONE:6)
Block(-3,7,7,STONE:6)
Block(-3,7,8,STONE:6)
Block(-3,8,6,STONE:6)
Block(-3,8,7,STONE:6)
Block(-3,8,8,STONE:6)
Block(-3,9,6,STONE:6)
Block(-3,9,7,STONE:6)
Block(-3,9,8,STONE:6)
Block(-3,10,6,STONE:6)
Block(-3,10,7,STONE:6)
Block(-3,10,8,STONE:6)
Block(-3,11,6,STONE:6)
Block(-3,11,7,STONE:6)
Block(-3,11,8,STONE:6)
Block(-3,12,6,STONE:6)
Block(-3,12,7,STONE:6)
Block(-3,12,8,STONE:6)
Block(-3,13,6,STONE:6)
Block(-3,13,7,STONE:6)
Block(-3,13,8,STONE:6)
Block(-3,14,6,STONE:6)
Block(-3,14,7,STONE:6)
Block(-3,14,8,STONE:6)
Block(-3,15,6,STONE:6)
Block(-3,15,7,STONE:6)
Block(-3,15,8,STONE:6)
Block(-3,16,6,STONE:6)
Block(-3,16,7,STONE:6)
Block(-3,16,8,STONE:6)
Block(-3,17,6,STONE:6)
Block(-3,17,7,STONE:6)
Block(-3,17,8,STONE:6)
Block(-3,18,6,STONE:6)
Block(-3,18,7,STONE:6)
Block(-3,18,8,STONE:6)
Block(-3,19,6,STONE:6)
Block(-3,19,7,STONE:6)
Block(-3,19,8,STONE:6)
Block(-3,20,6,STONE:6)
Block(-3,20,7,STONE:6)
Block(-3,20,8,STONE:6)
Block(-3,21,6,STONE:6)
Block(-3,21,7,STONE:6)
Block(-3,21,8,STONE:6)
Block(-3,22,6,STONE:6)
Block(-3,22,7,STONE:6)
Block(-3,22,8,STONE:6)
Block(-3,23,6,STONE:6)
Block(-3,23,7,STONE:6)
Block(-3,23,8,STONE:6)
Block(-3,24,6,STONE:6)
Block(-3,24,7,STONE:6)
Block(-3,24,8,STONE:6)
Block(-3,25,6,STONE:6)
Block(-3,25,7,STONE:6)
Block(-3,25,8,STONE:6)
Block(-3,26,6,STONE:6)
Block(-3,26,7,STONE:6)
Block(-3,26,8,STONE:6)
Block(-3,27,6,STONE:6)
Block(-3,27,7,STONE:6)
Block(-3,27,8,STONE:6)
Block(-3,28,6,STONE:6)
Block(-3,28,7,STONE:6)
Block(-3,28,8,STONE:6)
Block(-3,29,6,STONE:6)
Block(-3,29,7,STONE:6)
Block(-3,29,8,STONE:6)
Block(-3,30,6,STONE:6)
Block(-3,30,7,STONE:6)
Block(-3,30,8,STONE:6)
Block(-3,31,6,STONE:6)
Block(-3,31,7,STONE:6)
Block(-3,31,8,STONE:6)
Block(-3,32,6,STONE:6)
Block(-3,32,7,STONE:6)
Block(-3,32,8,STONE:6)
Block(-3,33,6,STONE:6)
Block(-3,33,7,STONE:6)
Block(-3,33,8,STONE:6)
Block(-3,34,6,STONE:6)
Block(-3,34,7,STONE:6)
Block(-3,34,8,STONE:6)
Block(-3,35,6,STONE:6)
Block(-3,35,7,STONE:6)
Block(-3,35,8,STONE:6)
Block(-3,36,6,STONE:6)
Block(-3,36,7,STONE:6)
Block(-3,36,8,STONE:6)
Block(-3,37,6,STONE:6)
Block(-3,37,7,STONE:6)
Block(-3,37,8,STONE:6)
Block(-3,38,6,STEP:0)
Block(-3,38,7,STEP:0)
Block(-3,38,8,STEP:0)

#######################################################################
# +-----------------------------------------------------------------+ #
# |                             Branches                            | #
# +-----------------------------------------------------------------+ #
#######################################################################

Branch(0,0,16,true,SpawnHexC16R8,NORTH,100.0,0)

#######################################################################
# +-----------------------------------------------------------------+ #
# |                             Entities                            | #
# +-----------------------------------------------------------------+ #
#######################################################################


#######################################################################
# +-----------------------------------------------------------------+ #
# |                            Particles                            | #
# +-----------------------------------------------------------------+ #
#######################################################################


#######################################################################
# +-----------------------------------------------------------------+ #
# |                             Spawners                            | #
# +-----------------------------------------------------------------+ #
#######################################################################


#######################################################################
# +-----------------------------------------------------------------+ #
# |                             ModData                             | #
# +-----------------------------------------------------------------+ #
#######################################################################

