
#######################################################################
# +-----------------------------------------------------------------+ #
# |                            BO4 object                           | #
# +-----------------------------------------------------------------+ #
#######################################################################

Author: NLBlackEagle

Description: No description given

SettingsMode: WriteDisable


#######################################################################
# +-----------------------------------------------------------------+ #
# |                          Main settings                          | #
# +-----------------------------------------------------------------+ #
#######################################################################

Frequency: 0

SpawnHeight: highestBlock

UseCenterForHighestBlock: true

##############################
# Height Limits for the BO4. #
##############################

MinHeight: 0

MaxHeight: 255

InheritBO3: 

InheritBO3Rotation: NORTH

OverrideChildSettings: true

OverrideParentHeight: false

CanOverride: false

BranchFrequency: 0

BranchFrequencyGroup: 

MustBeBelowOther: false

MustBeInside: 

CannotBeInside: 

ReplacesBO3: 

MustBeInsideWorldBorders: false

CanSpawnOnWater: true

SpawnOnWaterOnly: false

SpawnUnderWater: false

SpawnAtWaterLevel: false

HeightOffset: 0

RemoveAir: true

ReplaceAbove: 

ReplaceBelow: 

ReplaceWithBiomeBlocks: true

ReplaceWithSurfaceBlock: GRASS

ReplaceWithGroundBlock: DIRT

ReplaceWithStoneBlock: STONE

SmoothRadius: 0

SmoothHeightOffset: 0

SmoothStartTop: false

SmoothStartWood: false

SmoothingSurfaceBlock: 

SmoothingGroundBlock: 

BO3Group: 

IsSpawnPoint: false

DoReplaceBlocks: true


#######################################################################
# +-----------------------------------------------------------------+ #
# |                              Blocks                             | #
# +-----------------------------------------------------------------+ #
#######################################################################

Block(-2,37,0,COBBLESTONE:0)
Block(-2,37,1,STONE:6)
Block(-2,38,1,STEP:0)
Block(-1,34,1,SMOOTH_STAIRS:5)
Block(-1,35,1,SMOOTH_STAIRS:0)
Block(-1,37,-1,COBBLESTONE:0)
Block(-1,37,0,COBBLESTONE:0)
Block(-1,37,1,STONE:6)
Block(-1,38,1,STEP:0)
Block(0,35,1,STONE:6)
Block(0,36,1,COBBLE_WALL:0)
Block(0,37,-1,COBBLESTONE:0)
Block(0,37,0,COBBLESTONE:0)
Block(0,37,1,STONE:6)
Block(0,38,-3,STEP:0)
Block(0,38,1,STEP:0)
Block(1,34,1,SMOOTH_STAIRS:4)
Block(1,35,1,SMOOTH_STAIRS:1)
Block(1,37,-1,COBBLESTONE:0)
Block(1,37,0,COBBLESTONE:0)
Block(1,37,1,STONE:6)
Block(1,38,-3,STEP:0)
Block(1,38,1,STEP:0)
Block(2,33,1,SMOOTH_STAIRS:4)
Block(2,34,1,STONE:6)
Block(2,35,1,SMOOTH_STAIRS:0)
Block(2,36,1,SMOOTH_STAIRS:4)
Block(2,37,-3,STONE:6)
Block(2,37,-2,COBBLESTONE:0)
Block(2,37,-1,COBBLESTONE:0)
Block(2,37,0,COBBLESTONE:0)
Block(2,37,1,STONE:6)
Block(2,38,-3,STEP:0)
Block(2,38,1,STEP:0)
Block(3,0,-3,STONE:6)
Block(3,0,1,STONE:6)
Block(3,1,-3,STONE:6)
Block(3,1,1,STONE:6)
Block(3,2,-3,STONE:6)
Block(3,2,1,STONE:6)
Block(3,3,-3,STONE:6)
Block(3,3,1,STONE:6)
Block(3,4,-3,STONE:6)
Block(3,4,1,STONE:6)
Block(3,5,-3,STONE:6)
Block(3,5,1,STONE:6)
Block(3,6,-3,STONE:6)
Block(3,6,1,STONE:6)
Block(3,7,-3,STONE:6)
Block(3,7,1,STONE:6)
Block(3,8,-3,STONE:6)
Block(3,8,1,STONE:6)
Block(3,9,-3,STONE:6)
Block(3,9,1,STONE:6)
Block(3,10,-3,STONE:6)
Block(3,10,1,STONE:6)
Block(3,11,-3,STONE:6)
Block(3,11,1,STONE:6)
Block(3,12,-3,STONE:6)
Block(3,12,1,STONE:6)
Block(3,13,-3,STONE:6)
Block(3,13,1,STONE:6)
Block(3,14,-3,STONE:6)
Block(3,14,1,STONE:6)
Block(3,15,-3,STONE:6)
Block(3,15,1,STONE:6)
Block(3,16,-3,STONE:6)
Block(3,16,1,STONE:6)
Block(3,17,-3,STONE:6)
Block(3,17,1,STONE:6)
Block(3,18,-3,STONE:6)
Block(3,18,1,STONE:6)
Block(3,19,-3,STONE:6)
Block(3,19,1,STONE:6)
Block(3,20,-3,STONE:6)
Block(3,20,1,STONE:6)
Block(3,21,-3,STONE:6)
Block(3,21,1,STONE:6)
Block(3,22,-3,STONE:6)
Block(3,22,1,STONE:6)
Block(3,23,-3,STONE:6)
Block(3,23,1,STONE:6)
Block(3,24,-3,STONE:6)
Block(3,24,1,STONE:6)
Block(3,25,-3,STONE:6)
Block(3,25,1,STONE:6)
Block(3,26,-3,STONE:6)
Block(3,26,1,STONE:6)
Block(3,27,-3,STONE:6)
Block(3,27,1,STONE:6)
Block(3,28,-3,STONE:6)
Block(3,28,1,STONE:6)
Block(3,29,-3,STONE:6)
Block(3,29,1,STONE:6)
Block(3,30,-3,STONE:6)
Block(3,30,1,STONE:6)
Block(3,31,-3,STONE:6)
Block(3,31,1,STONE:6)
Block(3,32,-3,STONE:6)
Block(3,32,1,STONE:6)
Block(3,33,-3,STONE:6)
Block(3,33,1,STONE:6)
Block(3,34,-3,STONE:6)
Block(3,34,1,STONE:6)
Block(3,35,-3,STONE:6)
Block(3,35,1,STONE:6)
Block(3,36,-3,STONE:6)
Block(3,36,1,STONE:6)
Block(3,37,-3,STONE:6)
Block(3,37,-2,STONE:6)
Block(3,37,-1,STONE:6)
Block(3,37,0,STONE:6)
Block(3,37,1,STONE:6)
Block(3,38,-3,STEP:0)
Block(3,38,-2,STEP:0)
Block(3,38,0,STEP:0)
Block(3,38,1,STEP:0)
Block(4,0,-2,COBBLESTONE:0)
Block(4,0,-1,COBBLESTONE:0)
Block(4,0,0,COBBLESTONE:0)
Block(4,1,-2,COBBLESTONE:0)
Block(4,1,-1,COBBLESTONE:0)
Block(4,1,0,COBBLESTONE:0)
Block(4,2,-2,COBBLESTONE:0)
Block(4,2,-1,COBBLESTONE:0)
Block(4,2,0,COBBLESTONE:0)
Block(4,3,-2,COBBLESTONE:0)
Block(4,3,-1,COBBLESTONE:0)
Block(4,3,0,COBBLESTONE:0)
Block(4,4,-2,COBBLESTONE:0)
Block(4,4,-1,COBBLESTONE:0)
Block(4,4,0,COBBLESTONE:0)
Block(4,5,-2,COBBLESTONE:0)
Block(4,5,-1,COBBLESTONE:0)
Block(4,5,0,COBBLESTONE:0)
Block(4,6,-2,COBBLESTONE:0)
Block(4,6,-1,COBBLESTONE:0)
Block(4,6,0,COBBLESTONE:0)
Block(4,7,-2,COBBLESTONE:0)
Block(4,7,-1,COBBLESTONE:0)
Block(4,7,0,COBBLESTONE:0)
Block(4,8,-2,COBBLESTONE:0)
Block(4,8,-1,COBBLESTONE:0)
Block(4,8,0,COBBLESTONE:0)
Block(4,9,-2,COBBLESTONE:0)
Block(4,9,-1,COBBLESTONE:0)
Block(4,9,0,COBBLESTONE:0)
Block(4,10,-2,COBBLESTONE:0)
Block(4,10,-1,COBBLESTONE:0)
Block(4,10,0,COBBLESTONE:0)
Block(4,11,-2,COBBLESTONE:0)
Block(4,11,-1,COBBLESTONE:0)
Block(4,11,0,COBBLESTONE:0)
Block(4,12,-2,COBBLESTONE:0)
Block(4,12,-1,COBBLESTONE:0)
Block(4,12,0,COBBLESTONE:0)
Block(4,13,-2,COBBLESTONE:0)
Block(4,13,-1,COBBLESTONE:0)
Block(4,13,0,COBBLESTONE:0)
Block(4,14,-2,COBBLESTONE:0)
Block(4,14,-1,COBBLESTONE:0)
Block(4,14,0,COBBLESTONE:0)
Block(4,15,-2,COBBLESTONE:0)
Block(4,15,-1,COBBLESTONE:0)
Block(4,15,0,COBBLESTONE:0)
Block(4,16,-2,COBBLESTONE:0)
Block(4,16,-1,COBBLESTONE:0)
Block(4,16,0,COBBLESTONE:0)
Block(4,17,-2,COBBLESTONE:0)
Block(4,17,-1,COBBLESTONE:0)
Block(4,17,0,COBBLESTONE:0)
Block(4,18,-2,COBBLESTONE:0)
Block(4,18,-1,COBBLESTONE:0)
Block(4,18,0,COBBLESTONE:0)
Block(4,19,-2,COBBLESTONE:0)
Block(4,19,-1,COBBLESTONE:0)
Block(4,19,0,COBBLESTONE:0)
Block(4,20,-2,COBBLESTONE:0)
Block(4,20,-1,COBBLESTONE:0)
Block(4,20,0,COBBLESTONE:0)
Block(4,21,-2,COBBLESTONE:0)
Block(4,21,-1,COBBLESTONE:0)
Block(4,21,0,COBBLESTONE:0)
Block(4,22,-2,COBBLESTONE:0)
Block(4,22,-1,COBBLESTONE:0)
Block(4,22,0,COBBLESTONE:0)
Block(4,23,-2,COBBLESTONE:0)
Block(4,23,-1,COBBLESTONE:0)
Block(4,23,0,COBBLESTONE:0)
Block(4,24,-2,COBBLESTONE:0)
Block(4,24,-1,COBBLESTONE:0)
Block(4,24,0,COBBLESTONE:0)
Block(4,25,-2,COBBLESTONE:0)
Block(4,25,-1,COBBLESTONE:0)
Block(4,25,0,COBBLESTONE:0)
Block(4,26,-2,COBBLESTONE:0)
Block(4,26,-1,COBBLESTONE:0)
Block(4,26,0,COBBLESTONE:0)
Block(4,27,-2,COBBLESTONE:0)
Block(4,27,-1,COBBLESTONE:0)
Block(4,27,0,COBBLESTONE:0)
Block(4,28,-2,COBBLESTONE:0)
Block(4,28,-1,COBBLESTONE:0)
Block(4,28,0,COBBLESTONE:0)
Block(4,29,-2,COBBLESTONE:0)
Block(4,29,-1,COBBLESTONE:0)
Block(4,29,0,COBBLESTONE:0)
Block(4,30,-1,COBBLESTONE:0)
Block(4,30,0,COBBLESTONE:0)
Block(4,31,0,COBBLESTONE:0)
Block(4,32,0,COBBLESTONE:0)
Block(4,33,0,COBBLESTONE:0)
Block(4,34,0,COBBLESTONE:0)
Block(4,35,-2,COBBLESTONE:0)
Block(4,35,0,COBBLESTONE:0)
Block(4,36,-2,COBBLESTONE:0)
Block(4,36,-1,COBBLESTONE:0)
Block(4,37,-2,COBBLESTONE:0)
Block(4,37,-1,COBBLESTONE:0)
Block(4,37,0,COBBLESTONE:0)
Block(4,38,-2,STEP:0)
Block(4,38,0,STEP:0)
Block(5,0,-3,STONE:6)
Block(5,0,1,STONE:6)
Block(5,1,-3,STONE:6)
Block(5,1,1,STONE:6)
Block(5,2,-3,STONE:6)
Block(5,2,1,STONE:6)
Block(5,3,-3,STONE:6)
Block(5,3,1,STONE:6)
Block(5,4,-3,STONE:6)
Block(5,4,1,STONE:6)
Block(5,5,-3,STONE:6)
Block(5,5,1,STONE:6)
Block(5,6,-3,STONE:6)
Block(5,6,1,STONE:6)
Block(5,7,-3,STONE:6)
Block(5,7,1,STONE:6)
Block(5,8,-3,STONE:6)
Block(5,8,1,STONE:6)
Block(5,9,-3,STONE:6)
Block(5,9,1,STONE:6)
Block(5,10,-3,STONE:6)
Block(5,10,1,STONE:6)
Block(5,11,-3,STONE:6)
Block(5,11,1,STONE:6)
Block(5,12,-3,STONE:6)
Block(5,12,1,STONE:6)
Block(5,13,-3,STONE:6)
Block(5,13,1,STONE:6)
Block(5,14,-3,STONE:6)
Block(5,14,1,STONE:6)
Block(5,15,-3,STONE:6)
Block(5,15,1,STONE:6)
Block(5,16,-3,STONE:6)
Block(5,16,1,STONE:6)
Block(5,17,-3,STONE:6)
Block(5,17,1,STONE:6)
Block(5,18,-3,STONE:6)
Block(5,18,1,STONE:6)
Block(5,19,-3,STONE:6)
Block(5,19,1,STONE:6)
Block(5,20,-3,STONE:6)
Block(5,20,1,STONE:6)
Block(5,21,-3,STONE:6)
Block(5,21,1,STONE:6)
Block(5,22,-3,STONE:6)
Block(5,22,1,STONE:6)
Block(5,23,-3,STONE:6)
Block(5,23,1,STONE:6)
Block(5,24,-3,STONE:6)
Block(5,24,1,STONE:6)
Block(5,25,-3,STONE:6)
Block(5,25,1,STONE:6)
Block(5,26,-3,STONE:6)
Block(5,26,1,STONE:6)
Block(5,27,-3,STONE:6)
Block(5,27,1,STONE:6)
Block(5,28,-3,STONE:6)
Block(5,28,1,STONE:6)
Block(5,29,-3,STONE:6)
Block(5,29,1,STONE:6)
Block(5,30,-3,STONE:6)
Block(5,30,1,STONE:6)
Block(5,31,-3,STONE:6)
Block(5,31,1,STONE:6)
Block(5,32,-3,STONE:6)
Block(5,32,1,STONE:6)
Block(5,33,-3,STONE:6)
Block(5,33,1,STONE:6)
Block(5,34,-3,STONE:6)
Block(5,34,1,STONE:6)
Block(5,35,-3,STONE:6)
Block(5,35,1,STONE:6)
Block(5,36,-3,STONE:6)
Block(5,36,1,STONE:6)
Block(5,37,-3,STONE:6)
Block(5,37,-2,STONE:6)
Block(5,37,-1,STONE:6)
Block(5,37,0,STONE:6)
Block(5,37,1,STONE:6)
Block(5,38,-3,STEP:0)
Block(5,38,-2,STEP:0)
Block(5,38,0,STEP:0)
Block(5,38,1,STEP:0)
Block(6,33,-3,SMOOTH_STAIRS:5)
Block(6,33,1,SMOOTH_STAIRS:5)
Block(6,34,-3,STONE:6)
Block(6,34,1,STONE:6)
Block(6,35,-3,SMOOTH_STAIRS:1)
Block(6,35,1,SMOOTH_STAIRS:1)
Block(6,36,-3,SMOOTH_STAIRS:5)
Block(6,36,1,SMOOTH_STAIRS:5)
Block(6,37,-3,STONE:6)
Block(6,37,-2,COBBLESTONE:0)
Block(6,37,-1,COBBLESTONE:0)
Block(6,37,0,COBBLESTONE:0)
Block(6,37,1,STONE:6)
Block(6,38,-3,STEP:0)
Block(6,38,1,STEP:0)
Block(7,34,-3,SMOOTH_STAIRS:5)
Block(7,34,1,SMOOTH_STAIRS:5)
Block(7,35,-3,SMOOTH_STAIRS:0)
Block(7,35,1,SMOOTH_STAIRS:0)
Block(7,37,-3,STONE:6)
Block(7,37,-2,COBBLESTONE:0)
Block(7,37,-1,COBBLESTONE:0)
Block(7,37,0,COBBLESTONE:0)
Block(7,37,1,STONE:6)
Block(7,38,-3,STEP:0)
Block(7,38,1,STEP:0)

#######################################################################
# +-----------------------------------------------------------------+ #
# |                             Branches                            | #
# +-----------------------------------------------------------------+ #
#######################################################################

Branch(0,0,16,true,SpawnHexC0R10,NORTH,100.0,0)

#######################################################################
# +-----------------------------------------------------------------+ #
# |                             Entities                            | #
# +-----------------------------------------------------------------+ #
#######################################################################


#######################################################################
# +-----------------------------------------------------------------+ #
# |                            Particles                            | #
# +-----------------------------------------------------------------+ #
#######################################################################


#######################################################################
# +-----------------------------------------------------------------+ #
# |                             Spawners                            | #
# +-----------------------------------------------------------------+ #
#######################################################################


#######################################################################
# +-----------------------------------------------------------------+ #
# |                             ModData                             | #
# +-----------------------------------------------------------------+ #
#######################################################################

