
#######################################################################
# +-----------------------------------------------------------------+ #
# |                            BO4 object                           | #
# +-----------------------------------------------------------------+ #
#######################################################################

Author: NLBlackEagle

Description: No description given

SettingsMode: WriteDisable


#######################################################################
# +-----------------------------------------------------------------+ #
# |                          Main settings                          | #
# +-----------------------------------------------------------------+ #
#######################################################################

Frequency: 0

SpawnHeight: highestBlock

UseCenterForHighestBlock: true

##############################
# Height Limits for the BO4. #
##############################

MinHeight: 0

MaxHeight: 255

InheritBO3: 

InheritBO3Rotation: NORTH

OverrideChildSettings: true

OverrideParentHeight: false

CanOverride: false

BranchFrequency: 0

BranchFrequencyGroup: 

MustBeBelowOther: false

MustBeInside: 

CannotBeInside: 

ReplacesBO3: 

MustBeInsideWorldBorders: false

CanSpawnOnWater: true

SpawnOnWaterOnly: false

SpawnUnderWater: false

SpawnAtWaterLevel: false

HeightOffset: 0

RemoveAir: true

ReplaceAbove: 

ReplaceBelow: 

ReplaceWithBiomeBlocks: true

ReplaceWithSurfaceBlock: GRASS

ReplaceWithGroundBlock: DIRT

ReplaceWithStoneBlock: STONE

SmoothRadius: 0

SmoothHeightOffset: 0

SmoothStartTop: false

SmoothStartWood: false

SmoothingSurfaceBlock: 

SmoothingGroundBlock: 

BO3Group: 

IsSpawnPoint: false

DoReplaceBlocks: true


#######################################################################
# +-----------------------------------------------------------------+ #
# |                              Blocks                             | #
# +-----------------------------------------------------------------+ #
#######################################################################

Block(-8,54,4,COBBLESTONE:0)
Block(-8,54,5,COBBLESTONE:0)
Block(-8,54,6,MOSSY_COBBLESTONE:0)
Block(-8,55,7,COBBLESTONE:0)
Block(-8,55,8,COBBLESTONE:0)
Block(-7,0,8,STONE:6)
Block(-7,1,8,STONE:6)
Block(-7,2,8,STONE:6)
Block(-7,3,8,STONE:6)
Block(-7,4,8,STONE:6)
Block(-7,5,8,STONE:6)
Block(-7,6,8,STONE:6)
Block(-7,7,8,STONE:6)
Block(-7,8,8,STONE:6)
Block(-7,9,8,STONE:6)
Block(-7,10,8,STONE:6)
Block(-7,11,8,STONE:6)
Block(-7,12,8,STONE:6)
Block(-7,13,8,STONE:6)
Block(-7,14,8,STONE:6)
Block(-7,15,8,STONE:6)
Block(-7,16,8,STONE:6)
Block(-7,17,8,STONE:6)
Block(-7,18,8,STONE:6)
Block(-7,19,8,STONE:6)
Block(-7,20,8,STONE:6)
Block(-7,21,8,STONE:6)
Block(-7,22,8,STONE:6)
Block(-7,23,8,STONE:6)
Block(-7,24,8,STONE:6)
Block(-7,25,8,STONE:6)
Block(-7,26,8,STONE:6)
Block(-7,27,8,STONE:6)
Block(-7,28,8,STONE:6)
Block(-7,29,8,STONE:6)
Block(-7,30,8,STONE:6)
Block(-7,31,8,STONE:6)
Block(-7,32,8,STONE:6)
Block(-7,33,8,STONE:6)
Block(-7,34,8,STONE:6)
Block(-7,35,8,STONE:6)
Block(-7,36,8,STONE:6)
Block(-7,37,8,STONE:6)
Block(-7,38,8,STEP:0)
Block(-7,41,2,STAINED_CLAY:9)
Block(-7,52,5,STAINED_CLAY:9)
Block(-7,52,6,STAINED_CLAY:9)
Block(-7,52,7,STAINED_CLAY:9)
Block(-7,52,8,STAINED_CLAY:9)
Block(-7,53,6,COBBLESTONE:0)
Block(-7,53,7,COBBLESTONE:0)
Block(-7,53,8,COBBLESTONE:0)
Block(-7,54,7,COBBLESTONE:0)
Block(-7,54,8,STAINED_CLAY:9)
Block(-7,55,8,STAINED_CLAY:9)
Block(-6,0,8,STONE:6)
Block(-6,1,8,STONE:6)
Block(-6,2,8,STONE:6)
Block(-6,3,8,STONE:6)
Block(-6,4,8,STONE:6)
Block(-6,5,8,STONE:6)
Block(-6,6,8,STONE:6)
Block(-6,7,8,STONE:6)
Block(-6,8,8,STONE:6)
Block(-6,9,8,STONE:6)
Block(-6,10,8,STONE:6)
Block(-6,11,8,STONE:6)
Block(-6,12,8,STONE:6)
Block(-6,13,8,STONE:6)
Block(-6,14,8,STONE:6)
Block(-6,15,8,STONE:6)
Block(-6,16,8,STONE:6)
Block(-6,17,8,STONE:6)
Block(-6,18,8,STONE:6)
Block(-6,19,8,STONE:6)
Block(-6,20,8,STONE:6)
Block(-6,21,8,STONE:6)
Block(-6,22,8,STONE:6)
Block(-6,23,8,STONE:6)
Block(-6,24,8,STONE:6)
Block(-6,25,8,STONE:6)
Block(-6,26,8,STONE:6)
Block(-6,27,8,STONE:6)
Block(-6,28,8,STONE:6)
Block(-6,29,8,STONE:6)
Block(-6,30,8,STONE:6)
Block(-6,31,8,STONE:6)
Block(-6,32,8,STONE:6)
Block(-6,33,8,STONE:6)
Block(-6,34,8,STONE:6)
Block(-6,35,8,STONE:6)
Block(-6,36,8,STONE:6)
Block(-6,37,8,STONE:6)
Block(-6,38,8,STEP:0)
Block(-6,41,1,MOSSY_COBBLESTONE:0)
Block(-6,41,2,COBBLESTONE:0)
Block(-6,41,3,STAINED_CLAY:9)
Block(-6,50,7,STAINED_CLAY:9)
Block(-6,50,8,COBBLESTONE:0)
Block(-6,51,6,STAINED_CLAY:9)
Block(-6,51,7,STAINED_CLAY:9)
Block(-6,51,8,COBBLESTONE:0)
Block(-5,0,-3,STONE:6)
Block(-5,0,-1,STONE:6)
Block(-5,0,5,STONE:6)
Block(-5,0,7,STONE:6)
Block(-5,0,8,STONE:6)
Block(-5,1,-3,STONE:6)
Block(-5,1,-1,STONE:6)
Block(-5,1,5,STONE:6)
Block(-5,1,7,STONE:6)
Block(-5,1,8,STONE:6)
Block(-5,2,-3,STONE:6)
Block(-5,2,-1,STONE:6)
Block(-5,2,5,STONE:6)
Block(-5,2,7,STONE:6)
Block(-5,2,8,STONE:6)
Block(-5,3,-3,STONE:6)
Block(-5,3,-1,STONE:6)
Block(-5,3,5,STONE:6)
Block(-5,3,7,STONE:6)
Block(-5,3,8,STONE:6)
Block(-5,4,-3,STONE:6)
Block(-5,4,-1,STONE:6)
Block(-5,4,5,STONE:6)
Block(-5,4,7,STONE:6)
Block(-5,4,8,STONE:6)
Block(-5,5,-3,STONE:6)
Block(-5,5,-1,STONE:6)
Block(-5,5,5,STONE:6)
Block(-5,5,7,STONE:6)
Block(-5,5,8,STONE:6)
Block(-5,6,-3,STONE:6)
Block(-5,6,-1,STONE:6)
Block(-5,6,5,STONE:6)
Block(-5,6,7,STONE:6)
Block(-5,6,8,STONE:6)
Block(-5,7,-3,STONE:6)
Block(-5,7,-1,STONE:6)
Block(-5,7,5,STONE:6)
Block(-5,7,7,STONE:6)
Block(-5,7,8,STONE:6)
Block(-5,8,-3,STONE:6)
Block(-5,8,-1,STONE:6)
Block(-5,8,5,STONE:6)
Block(-5,8,7,STONE:6)
Block(-5,8,8,STONE:6)
Block(-5,9,-3,STONE:6)
Block(-5,9,-1,STONE:6)
Block(-5,9,5,STONE:6)
Block(-5,9,7,STONE:6)
Block(-5,9,8,STONE:6)
Block(-5,10,-3,STONE:6)
Block(-5,10,-1,STONE:6)
Block(-5,10,5,STONE:6)
Block(-5,10,7,STONE:6)
Block(-5,10,8,STONE:6)
Block(-5,11,-3,STONE:6)
Block(-5,11,-1,STONE:6)
Block(-5,11,5,STONE:6)
Block(-5,11,7,STONE:6)
Block(-5,11,8,STONE:6)
Block(-5,12,-3,STONE:6)
Block(-5,12,-1,STONE:6)
Block(-5,12,5,STONE:6)
Block(-5,12,7,STONE:6)
Block(-5,12,8,STONE:6)
Block(-5,13,-3,STONE:6)
Block(-5,13,-1,STONE:6)
Block(-5,13,5,STONE:6)
Block(-5,13,7,STONE:6)
Block(-5,13,8,STONE:6)
Block(-5,14,-3,STONE:6)
Block(-5,14,-1,STONE:6)
Block(-5,14,5,STONE:6)
Block(-5,14,7,STONE:6)
Block(-5,14,8,STONE:6)
Block(-5,15,-3,STONE:6)
Block(-5,15,-1,STONE:6)
Block(-5,15,5,STONE:6)
Block(-5,15,7,STONE:6)
Block(-5,15,8,STONE:6)
Block(-5,16,-3,STONE:6)
Block(-5,16,-1,STONE:6)
Block(-5,16,5,STONE:6)
Block(-5,16,7,STONE:6)
Block(-5,16,8,STONE:6)
Block(-5,17,-3,STONE:6)
Block(-5,17,-1,STONE:6)
Block(-5,17,5,STONE:6)
Block(-5,17,7,STONE:6)
Block(-5,17,8,STONE:6)
Block(-5,18,-3,STONE:6)
Block(-5,18,-1,STONE:6)
Block(-5,18,5,STONE:6)
Block(-5,18,7,STONE:6)
Block(-5,18,8,STONE:6)
Block(-5,19,-3,STONE:6)
Block(-5,19,-1,STONE:6)
Block(-5,19,5,STONE:6)
Block(-5,19,7,STONE:6)
Block(-5,19,8,STONE:6)
Block(-5,20,-3,STONE:6)
Block(-5,20,-1,STONE:6)
Block(-5,20,5,STONE:6)
Block(-5,20,7,STONE:6)
Block(-5,20,8,STONE:6)
Block(-5,21,-3,STONE:6)
Block(-5,21,-1,STONE:6)
Block(-5,21,5,STONE:6)
Block(-5,21,7,STONE:6)
Block(-5,21,8,STONE:6)
Block(-5,22,-3,STONE:6)
Block(-5,22,-1,STONE:6)
Block(-5,22,5,STONE:6)
Block(-5,22,7,STONE:6)
Block(-5,22,8,STONE:6)
Block(-5,23,-3,STONE:6)
Block(-5,23,-1,STONE:6)
Block(-5,23,5,STONE:6)
Block(-5,23,7,STONE:6)
Block(-5,23,8,STONE:6)
Block(-5,24,-3,STONE:6)
Block(-5,24,-1,STONE:6)
Block(-5,24,5,STONE:6)
Block(-5,24,7,STONE:6)
Block(-5,24,8,STONE:6)
Block(-5,25,-3,STONE:6)
Block(-5,25,-1,STONE:6)
Block(-5,25,5,STONE:6)
Block(-5,25,7,STONE:6)
Block(-5,25,8,STONE:6)
Block(-5,26,-3,STONE:6)
Block(-5,26,-1,STONE:6)
Block(-5,26,5,STONE:6)
Block(-5,26,7,STONE:6)
Block(-5,26,8,STONE:6)
Block(-5,27,-3,STONE:6)
Block(-5,27,-1,STONE:6)
Block(-5,27,5,STONE:6)
Block(-5,27,7,STONE:6)
Block(-5,27,8,STONE:6)
Block(-5,28,-3,STONE:6)
Block(-5,28,-1,STONE:6)
Block(-5,28,5,STONE:6)
Block(-5,28,7,STONE:6)
Block(-5,28,8,STONE:6)
Block(-5,29,-3,STONE:6)
Block(-5,29,-1,STONE:6)
Block(-5,29,5,STONE:6)
Block(-5,29,7,STONE:6)
Block(-5,29,8,STONE:6)
Block(-5,30,-3,STONE:6)
Block(-5,30,-1,STONE:6)
Block(-5,30,5,STONE:6)
Block(-5,30,7,STONE:6)
Block(-5,30,8,STONE:6)
Block(-5,31,-3,STONE:6)
Block(-5,31,-1,STONE:6)
Block(-5,31,5,STONE:6)
Block(-5,31,7,STONE:6)
Block(-5,31,8,STONE:6)
Block(-5,32,-3,STONE:6)
Block(-5,32,-1,STONE:6)
Block(-5,32,5,STONE:6)
Block(-5,32,7,STONE:6)
Block(-5,32,8,STONE:6)
Block(-5,33,-4,SMOOTH_STAIRS:6)
Block(-5,33,-3,STONE:6)
Block(-5,33,-1,STONE:6)
Block(-5,33,0,SMOOTH_STAIRS:7)
Block(-5,33,4,SMOOTH_STAIRS:6)
Block(-5,33,5,STONE:6)
Block(-5,33,7,STONE:6)
Block(-5,33,8,STONE:6)
Block(-5,34,-7,SMOOTH_STAIRS:7)
Block(-5,34,-5,SMOOTH_STAIRS:6)
Block(-5,34,-4,STONE:6)
Block(-5,34,-3,STONE:6)
Block(-5,34,-1,STONE:6)
Block(-5,34,0,STONE:6)
Block(-5,34,1,SMOOTH_STAIRS:7)
Block(-5,34,3,SMOOTH_STAIRS:6)
Block(-5,34,4,STONE:6)
Block(-5,34,5,STONE:6)
Block(-5,34,7,STONE:6)
Block(-5,34,8,STONE:6)
Block(-5,35,-7,SMOOTH_STAIRS:2)
Block(-5,35,-6,STONE:6)
Block(-5,35,-5,SMOOTH_STAIRS:3)
Block(-5,35,-4,SMOOTH_STAIRS:2)
Block(-5,35,-3,STONE:6)
Block(-5,35,-1,STONE:6)
Block(-5,35,0,SMOOTH_STAIRS:3)
Block(-5,35,1,SMOOTH_STAIRS:2)
Block(-5,35,2,STONE:6)
Block(-5,35,3,SMOOTH_STAIRS:3)
Block(-5,35,4,SMOOTH_STAIRS:2)
Block(-5,35,5,STONE:6)
Block(-5,35,7,STONE:6)
Block(-5,35,8,STONE:6)
Block(-5,36,-6,COBBLE_WALL:0)
Block(-5,36,-4,SMOOTH_STAIRS:6)
Block(-5,36,-3,STONE:6)
Block(-5,36,-1,STONE:6)
Block(-5,36,0,SMOOTH_STAIRS:7)
Block(-5,36,2,COBBLE_WALL:0)
Block(-5,36,4,SMOOTH_STAIRS:6)
Block(-5,36,5,STONE:6)
Block(-5,36,7,STONE:6)
Block(-5,36,8,STONE:6)
Block(-5,37,-7,STONE:6)
Block(-5,37,-6,STONE:6)
Block(-5,37,-5,STONE:6)
Block(-5,37,-3,STONE:6)
Block(-5,37,-1,STONE:6)
Block(-5,37,0,STONE:6)
Block(-5,37,1,STONE:6)
Block(-5,37,2,STONE:6)
Block(-5,37,3,STONE:6)
Block(-5,37,4,STONE:6)
Block(-5,37,5,STONE:6)
Block(-5,37,7,STONE:6)
Block(-5,37,8,STONE:6)
Block(-5,38,-7,STEP:0)
Block(-5,38,-6,STEP:0)
Block(-5,38,-1,STEP:0)
Block(-5,38,0,STEP:0)
Block(-5,38,3,STEP:0)
Block(-5,38,4,STEP:0)
Block(-5,38,5,STEP:0)
Block(-5,38,7,STEP:0)
Block(-5,38,8,STEP:0)
Block(-5,42,2,COBBLESTONE:0)
Block(-5,42,3,STAINED_CLAY:9)
Block(-5,43,4,COBBLESTONE:0)
Block(-5,50,8,STAINED_CLAY:9)
Block(-4,0,-2,COBBLESTONE:0)
Block(-4,0,6,COBBLESTONE:0)
Block(-4,0,8,STONE:6)
Block(-4,1,-2,COBBLESTONE:0)
Block(-4,1,6,COBBLESTONE:0)
Block(-4,1,8,STONE:6)
Block(-4,2,-2,COBBLESTONE:0)
Block(-4,2,6,COBBLESTONE:0)
Block(-4,2,8,STONE:6)
Block(-4,3,-2,COBBLESTONE:0)
Block(-4,3,6,COBBLESTONE:0)
Block(-4,3,8,STONE:6)
Block(-4,4,-2,COBBLESTONE:0)
Block(-4,4,6,COBBLESTONE:0)
Block(-4,4,8,STONE:6)
Block(-4,5,-2,COBBLESTONE:0)
Block(-4,5,6,COBBLESTONE:0)
Block(-4,5,8,STONE:6)
Block(-4,6,-2,COBBLESTONE:0)
Block(-4,6,6,COBBLESTONE:0)
Block(-4,6,8,STONE:6)
Block(-4,7,-2,COBBLESTONE:0)
Block(-4,7,6,COBBLESTONE:0)
Block(-4,7,8,STONE:6)
Block(-4,8,-2,COBBLESTONE:0)
Block(-4,8,6,COBBLESTONE:0)
Block(-4,8,8,STONE:6)
Block(-4,9,-2,COBBLESTONE:0)
Block(-4,9,6,COBBLESTONE:0)
Block(-4,9,8,STONE:6)
Block(-4,10,-2,COBBLESTONE:0)
Block(-4,10,6,COBBLESTONE:0)
Block(-4,10,8,STONE:6)
Block(-4,11,-2,COBBLESTONE:0)
Block(-4,11,6,COBBLESTONE:0)
Block(-4,11,8,STONE:6)
Block(-4,12,-2,COBBLESTONE:0)
Block(-4,12,6,COBBLESTONE:0)
Block(-4,12,8,STONE:6)
Block(-4,13,-2,COBBLESTONE:0)
Block(-4,13,6,COBBLESTONE:0)
Block(-4,13,8,STONE:6)
Block(-4,14,-2,COBBLESTONE:0)
Block(-4,14,6,COBBLESTONE:0)
Block(-4,14,8,STONE:6)
Block(-4,15,-2,COBBLESTONE:0)
Block(-4,15,6,COBBLESTONE:0)
Block(-4,15,8,STONE:6)
Block(-4,16,-2,COBBLESTONE:0)
Block(-4,16,6,COBBLESTONE:0)
Block(-4,16,8,STONE:6)
Block(-4,17,-2,COBBLESTONE:0)
Block(-4,17,6,COBBLESTONE:0)
Block(-4,17,8,STONE:6)
Block(-4,18,-2,COBBLESTONE:0)
Block(-4,18,6,COBBLESTONE:0)
Block(-4,18,8,STONE:6)
Block(-4,19,-2,COBBLESTONE:0)
Block(-4,19,6,COBBLESTONE:0)
Block(-4,19,8,STONE:6)
Block(-4,20,-2,COBBLESTONE:0)
Block(-4,20,6,COBBLESTONE:0)
Block(-4,20,8,STONE:6)
Block(-4,21,-2,COBBLESTONE:0)
Block(-4,21,6,COBBLESTONE:0)
Block(-4,21,8,STONE:6)
Block(-4,22,-2,COBBLESTONE:0)
Block(-4,22,6,COBBLESTONE:0)
Block(-4,22,8,STONE:6)
Block(-4,23,-2,COBBLESTONE:0)
Block(-4,23,6,COBBLESTONE:0)
Block(-4,23,8,STONE:6)
Block(-4,24,-2,COBBLESTONE:0)
Block(-4,24,6,COBBLESTONE:0)
Block(-4,24,8,STONE:6)
Block(-4,25,-2,COBBLESTONE:0)
Block(-4,25,6,COBBLESTONE:0)
Block(-4,25,8,STONE:6)
Block(-4,26,-2,COBBLESTONE:0)
Block(-4,26,6,COBBLESTONE:0)
Block(-4,26,8,STONE:6)
Block(-4,27,-2,COBBLESTONE:0)
Block(-4,27,6,COBBLESTONE:0)
Block(-4,27,8,STONE:6)
Block(-4,28,-2,COBBLESTONE:0)
Block(-4,28,6,COBBLESTONE:0)
Block(-4,28,8,STONE:6)
Block(-4,29,-2,COBBLESTONE:0)
Block(-4,29,6,COBBLESTONE:0)
Block(-4,29,8,STONE:6)
Block(-4,30,-2,COBBLESTONE:0)
Block(-4,30,6,COBBLESTONE:0)
Block(-4,30,8,STONE:6)
Block(-4,31,-2,COBBLESTONE:0)
Block(-4,31,6,COBBLESTONE:0)
Block(-4,31,8,STONE:6)
Block(-4,32,-2,COBBLESTONE:0)
Block(-4,32,6,COBBLESTONE:0)
Block(-4,32,8,STONE:6)
Block(-4,33,-2,COBBLESTONE:0)
Block(-4,33,6,COBBLESTONE:0)
Block(-4,33,8,STONE:6)
Block(-4,34,-2,COBBLESTONE:0)
Block(-4,34,6,COBBLESTONE:0)
Block(-4,34,8,STONE:6)
Block(-4,35,-2,COBBLESTONE:0)
Block(-4,35,6,COBBLESTONE:0)
Block(-4,35,8,STONE:6)
Block(-4,36,-2,COBBLESTONE:0)
Block(-4,36,6,COBBLESTONE:0)
Block(-4,36,8,STONE:6)
Block(-4,37,-7,COBBLESTONE:0)
Block(-4,37,-5,COBBLESTONE:0)
Block(-4,37,-4,COBBLESTONE:0)
Block(-4,37,-3,STONE:6)
Block(-4,37,-2,COBBLESTONE:0)
Block(-4,37,-1,STONE:6)
Block(-4,37,0,COBBLESTONE:0)
Block(-4,37,1,COBBLESTONE:0)
Block(-4,37,2,COBBLESTONE:0)
Block(-4,37,3,COBBLESTONE:0)
Block(-4,37,4,COBBLESTONE:0)
Block(-4,37,5,STONE:6)
Block(-4,37,6,COBBLESTONE:0)
Block(-4,37,7,STONE:6)
Block(-4,37,8,STONE:6)
Block(-4,38,-1,STEP:0)
Block(-4,38,5,STEP:0)
Block(-4,38,6,STEP:0)
Block(-4,38,7,STEP:0)
Block(-4,42,2,STAINED_CLAY:9)
Block(-4,42,3,COBBLESTONE:0)
Block(-4,43,3,COBBLESTONE:0)
Block(-4,43,4,COBBLESTONE:0)
Block(-4,44,5,COBBLESTONE:0)
Block(-4,45,6,COBBLESTONE:0)
Block(-4,46,8,STAINED_CLAY:9)
Block(-4,47,8,MOSSY_COBBLESTONE:0)
Block(-4,48,8,COBBLESTONE:0)
Block(-3,0,-2,COBBLESTONE:0)
Block(-3,0,6,COBBLESTONE:0)
Block(-3,0,7,STONE:6)
Block(-3,0,8,STONE:6)
Block(-3,1,-2,COBBLESTONE:0)
Block(-3,1,6,COBBLESTONE:0)
Block(-3,1,7,STONE:6)
Block(-3,1,8,STONE:6)
Block(-3,2,-2,COBBLESTONE:0)
Block(-3,2,6,COBBLESTONE:0)
Block(-3,2,7,STONE:6)
Block(-3,2,8,STONE:6)
Block(-3,3,-2,COBBLESTONE:0)
Block(-3,3,6,COBBLESTONE:0)
Block(-3,3,7,STONE:6)
Block(-3,3,8,STONE:6)
Block(-3,4,-2,COBBLESTONE:0)
Block(-3,4,6,COBBLESTONE:0)
Block(-3,4,7,STONE:6)
Block(-3,4,8,STONE:6)
Block(-3,5,-2,COBBLESTONE:0)
Block(-3,5,6,COBBLESTONE:0)
Block(-3,5,7,STONE:6)
Block(-3,5,8,STONE:6)
Block(-3,6,-2,COBBLESTONE:0)
Block(-3,6,6,COBBLESTONE:0)
Block(-3,6,7,STONE:6)
Block(-3,6,8,STONE:6)
Block(-3,7,-2,COBBLESTONE:0)
Block(-3,7,6,COBBLESTONE:0)
Block(-3,7,7,STONE:6)
Block(-3,7,8,STONE:6)
Block(-3,8,-2,COBBLESTONE:0)
Block(-3,8,6,COBBLESTONE:0)
Block(-3,8,7,STONE:6)
Block(-3,8,8,STONE:6)
Block(-3,9,-2,COBBLESTONE:0)
Block(-3,9,6,COBBLESTONE:0)
Block(-3,9,7,STONE:6)
Block(-3,9,8,STONE:6)
Block(-3,10,-2,COBBLESTONE:0)
Block(-3,10,6,COBBLESTONE:0)
Block(-3,10,7,STONE:6)
Block(-3,10,8,STONE:6)
Block(-3,11,-2,COBBLESTONE:0)
Block(-3,11,6,COBBLESTONE:0)
Block(-3,11,7,STONE:6)
Block(-3,11,8,STONE:6)
Block(-3,12,-2,COBBLESTONE:0)
Block(-3,12,6,COBBLESTONE:0)
Block(-3,12,7,STONE:6)
Block(-3,12,8,COBBLESTONE:0)
Block(-3,13,-2,COBBLESTONE:0)
Block(-3,13,6,COBBLESTONE:0)
Block(-3,13,7,STONE:6)
Block(-3,13,8,COBBLESTONE:0)
Block(-3,14,-2,COBBLESTONE:0)
Block(-3,14,6,COBBLESTONE:0)
Block(-3,14,7,STONE:6)
Block(-3,14,8,COBBLESTONE:0)
Block(-3,15,-2,COBBLESTONE:0)
Block(-3,15,6,COBBLESTONE:0)
Block(-3,15,7,STONE:6)
Block(-3,15,8,COBBLESTONE:0)
Block(-3,16,-2,COBBLESTONE:0)
Block(-3,16,6,COBBLESTONE:0)
Block(-3,16,7,STONE:6)
Block(-3,16,8,COBBLESTONE:0)
Block(-3,17,-2,COBBLESTONE:0)
Block(-3,17,6,COBBLESTONE:0)
Block(-3,17,7,STONE:6)
Block(-3,17,8,COBBLESTONE:0)
Block(-3,18,-2,COBBLESTONE:0)
Block(-3,18,6,COBBLESTONE:0)
Block(-3,18,7,STONE:6)
Block(-3,18,8,COBBLESTONE:0)
Block(-3,19,-2,COBBLESTONE:0)
Block(-3,19,6,COBBLESTONE:0)
Block(-3,19,7,STONE:6)
Block(-3,19,8,COBBLESTONE:0)
Block(-3,20,-2,COBBLESTONE:0)
Block(-3,20,6,COBBLESTONE:0)
Block(-3,20,7,STONE:6)
Block(-3,20,8,COBBLESTONE:0)
Block(-3,21,-2,COBBLESTONE:0)
Block(-3,21,6,COBBLESTONE:0)
Block(-3,21,7,STONE:6)
Block(-3,21,8,COBBLESTONE:0)
Block(-3,22,-2,COBBLESTONE:0)
Block(-3,22,6,COBBLESTONE:0)
Block(-3,22,7,STONE:6)
Block(-3,22,8,COBBLESTONE:0)
Block(-3,23,-2,COBBLESTONE:0)
Block(-3,23,6,COBBLESTONE:0)
Block(-3,23,7,STONE:6)
Block(-3,23,8,COBBLESTONE:0)
Block(-3,24,-2,COBBLESTONE:0)
Block(-3,24,6,COBBLESTONE:0)
Block(-3,24,7,STONE:6)
Block(-3,24,8,COBBLESTONE:0)
Block(-3,25,-2,COBBLESTONE:0)
Block(-3,25,6,COBBLESTONE:0)
Block(-3,25,7,STONE:6)
Block(-3,25,8,COBBLESTONE:0)
Block(-3,26,-2,COBBLESTONE:0)
Block(-3,26,6,COBBLESTONE:0)
Block(-3,26,7,STONE:6)
Block(-3,26,8,COBBLESTONE:0)
Block(-3,27,-2,COBBLESTONE:0)
Block(-3,27,6,COBBLESTONE:0)
Block(-3,27,7,STONE:6)
Block(-3,27,8,COBBLESTONE:0)
Block(-3,28,-2,COBBLESTONE:0)
Block(-3,28,6,COBBLESTONE:0)
Block(-3,28,7,STONE:6)
Block(-3,28,8,COBBLESTONE:0)
Block(-3,29,-2,COBBLESTONE:0)
Block(-3,29,6,COBBLESTONE:0)
Block(-3,29,7,STONE:6)
Block(-3,29,8,COBBLESTONE:0)
Block(-3,30,-2,COBBLESTONE:0)
Block(-3,30,6,COBBLESTONE:0)
Block(-3,30,7,STONE:6)
Block(-3,30,8,COBBLESTONE:0)
Block(-3,31,-2,COBBLESTONE:0)
Block(-3,31,6,COBBLESTONE:0)
Block(-3,31,7,STONE:6)
Block(-3,31,8,COBBLESTONE:0)
Block(-3,32,-2,COBBLESTONE:0)
Block(-3,32,6,COBBLESTONE:0)
Block(-3,32,7,STONE:6)
Block(-3,32,8,COBBLESTONE:0)
Block(-3,33,-2,COBBLESTONE:0)
Block(-3,33,6,COBBLESTONE:0)
Block(-3,33,7,STONE:6)
Block(-3,33,8,COBBLESTONE:0)
Block(-3,34,-2,COBBLESTONE:0)
Block(-3,34,6,COBBLESTONE:0)
Block(-3,34,7,STONE:6)
Block(-3,34,8,COBBLESTONE:0)
Block(-3,35,-2,COBBLESTONE:0)
Block(-3,35,6,COBBLESTONE:0)
Block(-3,35,7,STONE:6)
Block(-3,35,8,COBBLESTONE:0)
Block(-3,36,-2,COBBLESTONE:0)
Block(-3,36,6,COBBLESTONE:0)
Block(-3,36,7,STONE:6)
Block(-3,36,8,COBBLESTONE:0)
Block(-3,37,-4,COBBLESTONE:0)
Block(-3,37,-3,STONE:6)
Block(-3,37,-2,COBBLESTONE:0)
Block(-3,37,-1,STONE:6)
Block(-3,37,0,COBBLESTONE:0)
Block(-3,37,3,COBBLESTONE:0)
Block(-3,37,4,COBBLESTONE:0)
Block(-3,37,5,STONE:6)
Block(-3,37,6,COBBLESTONE:0)
Block(-3,37,7,STONE:6)
Block(-3,37,8,COBBLESTONE:0)
Block(-3,43,3,COBBLESTONE:0)
Block(-3,43,4,MOSSY_COBBLESTONE:0)
Block(-3,43,5,STAINED_CLAY:9)
Block(-3,44,4,STAINED_CLAY:9)
Block(-3,44,5,COBBLESTONE:0)
Block(-3,44,6,STAINED_CLAY:9)
Block(-3,45,5,COBBLESTONE:0)
Block(-3,45,6,STAINED_CLAY:9)
Block(-3,45,7,STAINED_CLAY:9)
Block(-3,46,7,COBBLESTONE:0)
Block(-3,46,8,STAINED_CLAY:9)
Block(-3,47,7,COBBLESTONE:0)
Block(-3,47,8,STAINED_CLAY:9)
Block(-3,48,8,COBBLESTONE:0)
Block(-2,0,-2,COBBLESTONE:0)
Block(-2,0,6,COBBLESTONE:0)
Block(-2,0,7,STONE:6)
Block(-2,0,8,STONE:6)
Block(-2,1,-2,COBBLESTONE:0)
Block(-2,1,6,COBBLESTONE:0)
Block(-2,1,7,STONE:6)
Block(-2,1,8,STONE:6)
Block(-2,2,-2,COBBLESTONE:0)
Block(-2,2,6,COBBLESTONE:0)
Block(-2,2,7,STONE:6)
Block(-2,2,8,STONE:6)
Block(-2,3,-2,COBBLESTONE:0)
Block(-2,3,6,COBBLESTONE:0)
Block(-2,3,7,STONE:6)
Block(-2,3,8,STONE:6)
Block(-2,4,-2,COBBLESTONE:0)
Block(-2,4,6,COBBLESTONE:0)
Block(-2,4,7,STONE:6)
Block(-2,4,8,STONE:6)
Block(-2,5,-2,COBBLESTONE:0)
Block(-2,5,6,COBBLESTONE:0)
Block(-2,5,7,STONE:6)
Block(-2,5,8,STONE:6)
Block(-2,6,-2,COBBLESTONE:0)
Block(-2,6,6,COBBLESTONE:0)
Block(-2,6,7,STONE:6)
Block(-2,6,8,STONE:6)
Block(-2,7,-2,COBBLESTONE:0)
Block(-2,7,6,COBBLESTONE:0)
Block(-2,7,7,STONE:6)
Block(-2,7,8,STONE:6)
Block(-2,8,-2,COBBLESTONE:0)
Block(-2,8,6,COBBLESTONE:0)
Block(-2,8,7,STONE:6)
Block(-2,8,8,STONE:6)
Block(-2,9,-2,COBBLESTONE:0)
Block(-2,9,6,COBBLESTONE:0)
Block(-2,9,7,STONE:6)
Block(-2,9,8,STONE:6)
Block(-2,10,-2,COBBLESTONE:0)
Block(-2,10,6,COBBLESTONE:0)
Block(-2,10,7,STONE:6)
Block(-2,10,8,STONE:6)
Block(-2,11,-2,COBBLESTONE:0)
Block(-2,11,6,COBBLESTONE:0)
Block(-2,11,7,STONE:6)
Block(-2,11,8,STONE:6)
Block(-2,12,-2,COBBLESTONE:0)
Block(-2,12,6,COBBLESTONE:0)
Block(-2,12,7,STONE:6)
Block(-2,12,8,STONE:6)
Block(-2,13,-2,COBBLESTONE:0)
Block(-2,13,6,COBBLESTONE:0)
Block(-2,13,7,STONE:6)
Block(-2,13,8,STONE:6)
Block(-2,14,-2,COBBLESTONE:0)
Block(-2,14,6,COBBLESTONE:0)
Block(-2,14,7,STONE:6)
Block(-2,14,8,STONE:6)
Block(-2,15,-2,COBBLESTONE:0)
Block(-2,15,6,COBBLESTONE:0)
Block(-2,15,7,STONE:6)
Block(-2,15,8,STONE:6)
Block(-2,16,-2,COBBLESTONE:0)
Block(-2,16,6,COBBLESTONE:0)
Block(-2,16,7,STONE:6)
Block(-2,16,8,STONE:6)
Block(-2,17,-2,COBBLESTONE:0)
Block(-2,17,6,COBBLESTONE:0)
Block(-2,17,7,STONE:6)
Block(-2,17,8,STONE:6)
Block(-2,18,-2,COBBLESTONE:0)
Block(-2,18,6,COBBLESTONE:0)
Block(-2,18,7,STONE:6)
Block(-2,18,8,STONE:6)
Block(-2,19,-2,COBBLESTONE:0)
Block(-2,19,6,COBBLESTONE:0)
Block(-2,19,7,STONE:6)
Block(-2,19,8,STONE:6)
Block(-2,20,-2,COBBLESTONE:0)
Block(-2,20,6,COBBLESTONE:0)
Block(-2,20,7,STONE:6)
Block(-2,20,8,STONE:6)
Block(-2,21,-2,COBBLESTONE:0)
Block(-2,21,6,COBBLESTONE:0)
Block(-2,21,7,STONE:6)
Block(-2,21,8,STONE:6)
Block(-2,22,-2,COBBLESTONE:0)
Block(-2,22,6,COBBLESTONE:0)
Block(-2,22,7,STONE:6)
Block(-2,22,8,STONE:6)
Block(-2,23,-2,COBBLESTONE:0)
Block(-2,23,6,COBBLESTONE:0)
Block(-2,23,7,STONE:6)
Block(-2,23,8,STONE:6)
Block(-2,24,-2,COBBLESTONE:0)
Block(-2,24,6,COBBLESTONE:0)
Block(-2,24,7,STONE:6)
Block(-2,24,8,STONE:6)
Block(-2,25,-2,COBBLESTONE:0)
Block(-2,25,6,COBBLESTONE:0)
Block(-2,25,7,STONE:6)
Block(-2,25,8,STONE:6)
Block(-2,26,-2,COBBLESTONE:0)
Block(-2,26,6,COBBLESTONE:0)
Block(-2,26,7,STONE:6)
Block(-2,26,8,STONE:6)
Block(-2,27,-2,COBBLESTONE:0)
Block(-2,27,6,COBBLESTONE:0)
Block(-2,27,7,STONE:6)
Block(-2,27,8,STONE:6)
Block(-2,28,-2,COBBLESTONE:0)
Block(-2,28,6,COBBLESTONE:0)
Block(-2,28,7,STONE:6)
Block(-2,28,8,STONE:6)
Block(-2,29,-2,COBBLESTONE:0)
Block(-2,29,6,COBBLESTONE:0)
Block(-2,29,7,STONE:6)
Block(-2,29,8,STONE:6)
Block(-2,30,-2,COBBLESTONE:0)
Block(-2,30,6,COBBLESTONE:0)
Block(-2,30,7,STONE:6)
Block(-2,30,8,STONE:6)
Block(-2,31,-2,COBBLESTONE:0)
Block(-2,31,6,COBBLESTONE:0)
Block(-2,31,7,STONE:6)
Block(-2,31,8,STONE:6)
Block(-2,32,-2,COBBLESTONE:0)
Block(-2,32,6,COBBLESTONE:0)
Block(-2,32,7,STONE:6)
Block(-2,32,8,STONE:6)
Block(-2,33,-2,COBBLESTONE:0)
Block(-2,33,6,COBBLESTONE:0)
Block(-2,33,7,STONE:6)
Block(-2,33,8,STONE:6)
Block(-2,34,-2,COBBLESTONE:0)
Block(-2,34,6,COBBLESTONE:0)
Block(-2,34,7,STONE:6)
Block(-2,34,8,STONE:6)
Block(-2,35,-2,COBBLESTONE:0)
Block(-2,35,6,COBBLESTONE:0)
Block(-2,35,7,STONE:6)
Block(-2,35,8,STONE:6)
Block(-2,36,-2,COBBLESTONE:0)
Block(-2,36,6,COBBLESTONE:0)
Block(-2,36,7,STONE:6)
Block(-2,36,8,STONE:6)
Block(-2,37,-4,COBBLESTONE:0)
Block(-2,37,-3,STONE:6)
Block(-2,37,-2,COBBLESTONE:0)
Block(-2,37,-1,STONE:6)
Block(-2,37,0,COBBLESTONE:0)
Block(-2,37,1,COBBLESTONE:0)
Block(-2,37,4,COBBLESTONE:0)
Block(-2,37,5,STONE:6)
Block(-2,37,6,COBBLESTONE:0)
Block(-2,37,7,STONE:6)
Block(-2,37,8,STONE:6)
Block(-2,38,-3,STEP:0)
Block(-2,38,-2,STEP:0)
Block(-2,38,-1,STEP:0)
Block(-2,38,5,STEP:0)
Block(-2,38,6,STEP:0)
Block(-2,38,7,STEP:0)
Block(-2,38,8,STEP:0)
Block(-2,42,2,COBBLESTONE:0)
Block(-2,42,3,COBBLESTONE:0)
Block(-2,43,3,COBBLESTONE:0)
Block(-2,43,4,STAINED_CLAY:9)
Block(-2,44,5,COBBLESTONE:0)
Block(-2,45,6,STAINED_CLAY:9)
Block(-2,46,8,COBBLESTONE:0)
Block(-2,47,8,STAINED_CLAY:9)
Block(-2,48,8,COBBLESTONE:0)
Block(-1,0,-3,STONE:6)
Block(-1,0,-1,STONE:6)
Block(-1,0,5,STONE:6)
Block(-1,0,7,STONE:6)
Block(-1,0,8,STONE:6)
Block(-1,1,-3,STONE:6)
Block(-1,1,-1,STONE:6)
Block(-1,1,5,STONE:6)
Block(-1,1,7,STONE:6)
Block(-1,1,8,STONE:6)
Block(-1,2,-3,STONE:6)
Block(-1,2,-1,STONE:6)
Block(-1,2,5,STONE:6)
Block(-1,2,7,STONE:6)
Block(-1,2,8,STONE:6)
Block(-1,3,-3,STONE:6)
Block(-1,3,-1,STONE:6)
Block(-1,3,5,STONE:6)
Block(-1,3,7,STONE:6)
Block(-1,3,8,STONE:6)
Block(-1,4,-3,STONE:6)
Block(-1,4,-1,STONE:6)
Block(-1,4,5,STONE:6)
Block(-1,4,7,STONE:6)
Block(-1,4,8,STONE:6)
Block(-1,5,-3,STONE:6)
Block(-1,5,-1,STONE:6)
Block(-1,5,5,STONE:6)
Block(-1,5,7,STONE:6)
Block(-1,5,8,STONE:6)
Block(-1,6,-3,STONE:6)
Block(-1,6,-1,STONE:6)
Block(-1,6,5,STONE:6)
Block(-1,6,7,STONE:6)
Block(-1,6,8,STONE:6)
Block(-1,7,-3,STONE:6)
Block(-1,7,-1,STONE:6)
Block(-1,7,5,STONE:6)
Block(-1,7,7,STONE:6)
Block(-1,7,8,STONE:6)
Block(-1,8,-3,STONE:6)
Block(-1,8,-1,STONE:6)
Block(-1,8,5,STONE:6)
Block(-1,8,7,STONE:6)
Block(-1,8,8,STONE:6)
Block(-1,9,-3,STONE:6)
Block(-1,9,-1,STONE:6)
Block(-1,9,5,STONE:6)
Block(-1,9,7,STONE:6)
Block(-1,9,8,STONE:6)
Block(-1,10,-3,STONE:6)
Block(-1,10,-1,STONE:6)
Block(-1,10,5,STONE:6)
Block(-1,10,7,STONE:6)
Block(-1,10,8,STONE:6)
Block(-1,11,-3,STONE:6)
Block(-1,11,-1,STONE:6)
Block(-1,11,5,STONE:6)
Block(-1,11,7,STONE:6)
Block(-1,11,8,STONE:6)
Block(-1,12,-3,STONE:6)
Block(-1,12,-1,STONE:6)
Block(-1,12,5,STONE:6)
Block(-1,12,7,STONE:6)
Block(-1,12,8,STONE:6)
Block(-1,13,-3,STONE:6)
Block(-1,13,-1,STONE:6)
Block(-1,13,5,STONE:6)
Block(-1,13,7,STONE:6)
Block(-1,13,8,STONE:6)
Block(-1,14,-3,STONE:6)
Block(-1,14,-1,STONE:6)
Block(-1,14,5,STONE:6)
Block(-1,14,7,STONE:6)
Block(-1,14,8,STONE:6)
Block(-1,15,-3,STONE:6)
Block(-1,15,-1,STONE:6)
Block(-1,15,5,STONE:6)
Block(-1,15,7,STONE:6)
Block(-1,15,8,STONE:6)
Block(-1,16,-3,STONE:6)
Block(-1,16,-1,STONE:6)
Block(-1,16,5,STONE:6)
Block(-1,16,7,STONE:6)
Block(-1,16,8,STONE:6)
Block(-1,17,-3,STONE:6)
Block(-1,17,-1,STONE:6)
Block(-1,17,5,STONE:6)
Block(-1,17,7,STONE:6)
Block(-1,17,8,STONE:6)
Block(-1,18,-3,STONE:6)
Block(-1,18,-1,STONE:6)
Block(-1,18,5,STONE:6)
Block(-1,18,7,STONE:6)
Block(-1,18,8,STONE:6)
Block(-1,19,-3,STONE:6)
Block(-1,19,-1,STONE:6)
Block(-1,19,5,STONE:6)
Block(-1,19,7,STONE:6)
Block(-1,19,8,STONE:6)
Block(-1,20,-3,STONE:6)
Block(-1,20,-1,STONE:6)
Block(-1,20,5,STONE:6)
Block(-1,20,7,STONE:6)
Block(-1,20,8,STONE:6)
Block(-1,21,-3,STONE:6)
Block(-1,21,-1,STONE:6)
Block(-1,21,5,STONE:6)
Block(-1,21,7,STONE:6)
Block(-1,21,8,STONE:6)
Block(-1,22,-3,STONE:6)
Block(-1,22,-1,STONE:6)
Block(-1,22,5,STONE:6)
Block(-1,22,7,STONE:6)
Block(-1,22,8,STONE:6)
Block(-1,23,-3,STONE:6)
Block(-1,23,-1,STONE:6)
Block(-1,23,5,STONE:6)
Block(-1,23,7,STONE:6)
Block(-1,23,8,STONE:6)
Block(-1,24,-3,STONE:6)
Block(-1,24,-1,STONE:6)
Block(-1,24,5,STONE:6)
Block(-1,24,7,STONE:6)
Block(-1,24,8,STONE:6)
Block(-1,25,-3,STONE:6)
Block(-1,25,-1,STONE:6)
Block(-1,25,5,STONE:6)
Block(-1,25,7,STONE:6)
Block(-1,25,8,STONE:6)
Block(-1,26,-3,STONE:6)
Block(-1,26,-1,STONE:6)
Block(-1,26,5,STONE:6)
Block(-1,26,7,STONE:6)
Block(-1,26,8,STONE:6)
Block(-1,27,-3,STONE:6)
Block(-1,27,-1,STONE:6)
Block(-1,27,5,STONE:6)
Block(-1,27,7,STONE:6)
Block(-1,27,8,STONE:6)
Block(-1,28,-3,STONE:6)
Block(-1,28,-1,STONE:6)
Block(-1,28,5,STONE:6)
Block(-1,28,7,STONE:6)
Block(-1,28,8,STONE:6)
Block(-1,29,-3,STONE:6)
Block(-1,29,-1,STONE:6)
Block(-1,29,5,STONE:6)
Block(-1,29,7,STONE:6)
Block(-1,29,8,STONE:6)
Block(-1,30,-3,STONE:6)
Block(-1,30,-1,STONE:6)
Block(-1,30,5,STONE:6)
Block(-1,30,7,STONE:6)
Block(-1,30,8,STONE:6)
Block(-1,31,-3,STONE:6)
Block(-1,31,-1,STONE:6)
Block(-1,31,5,STONE:6)
Block(-1,31,7,STONE:6)
Block(-1,31,8,STONE:6)
Block(-1,32,-3,STONE:6)
Block(-1,32,-1,STONE:6)
Block(-1,32,5,STONE:6)
Block(-1,32,7,STONE:6)
Block(-1,32,8,STONE:6)
Block(-1,33,-3,STONE:6)
Block(-1,33,-1,STONE:6)
Block(-1,33,0,SMOOTH_STAIRS:7)
Block(-1,33,4,SMOOTH_STAIRS:6)
Block(-1,33,5,STONE:6)
Block(-1,33,7,STONE:6)
Block(-1,33,8,STONE:6)
Block(-1,34,-3,STONE:6)
Block(-1,34,-1,STONE:6)
Block(-1,34,0,STONE:6)
Block(-1,34,1,SMOOTH_STAIRS:7)
Block(-1,34,3,SMOOTH_STAIRS:6)
Block(-1,34,4,STONE:6)
Block(-1,34,5,STONE:6)
Block(-1,34,7,STONE:6)
Block(-1,34,8,STONE:6)
Block(-1,35,-3,STONE:6)
Block(-1,35,-1,STONE:6)
Block(-1,35,0,SMOOTH_STAIRS:3)
Block(-1,35,1,SMOOTH_STAIRS:2)
Block(-1,35,2,STONE:6)
Block(-1,35,3,SMOOTH_STAIRS:3)
Block(-1,35,4,SMOOTH_STAIRS:2)
Block(-1,35,5,STONE:6)
Block(-1,35,7,STONE:6)
Block(-1,35,8,STONE:6)
Block(-1,36,-3,STONE:6)
Block(-1,36,-1,STONE:6)
Block(-1,36,0,SMOOTH_STAIRS:7)
Block(-1,36,2,COBBLE_WALL:0)
Block(-1,36,4,SMOOTH_STAIRS:6)
Block(-1,36,5,STONE:6)
Block(-1,36,7,STONE:6)
Block(-1,36,8,STONE:6)
Block(-1,37,-4,STONE:6)
Block(-1,37,-3,STONE:6)
Block(-1,37,-1,STONE:6)
Block(-1,37,0,STONE:6)
Block(-1,37,1,STONE:6)
Block(-1,37,2,STONE:6)
Block(-1,37,3,STONE:6)
Block(-1,37,4,STONE:6)
Block(-1,37,5,STONE:6)
Block(-1,37,7,STONE:6)
Block(-1,37,8,STONE:6)
Block(-1,38,-5,STEP:0)
Block(-1,38,-4,STEP:0)
Block(-1,38,-3,STEP:0)
Block(-1,38,-1,STEP:0)
Block(-1,38,0,STEP:0)
Block(-1,38,1,STEP:0)
Block(-1,38,2,STEP:0)
Block(-1,38,3,STEP:0)
Block(-1,38,4,STEP:0)
Block(-1,38,5,STEP:0)
Block(-1,38,7,STEP:0)
Block(-1,38,8,STEP:0)
Block(-1,42,2,STAINED_CLAY:9)
Block(-1,42,3,COBBLESTONE:0)
Block(-1,43,4,MOSSY_COBBLESTONE:0)
Block(-1,50,8,STAINED_CLAY:9)
Block(0,0,8,STONE:6)
Block(0,1,8,STONE:6)
Block(0,2,8,STONE:6)
Block(0,3,8,STONE:6)
Block(0,4,8,STONE:6)
Block(0,5,8,STONE:6)
Block(0,6,8,STONE:6)
Block(0,7,8,STONE:6)
Block(0,8,8,STONE:6)
Block(0,9,8,STONE:6)
Block(0,10,8,STONE:6)
Block(0,11,8,STONE:6)
Block(0,12,8,STONE:6)
Block(0,13,8,STONE:6)
Block(0,14,8,STONE:6)
Block(0,15,8,STONE:6)
Block(0,16,8,STONE:6)
Block(0,17,8,STONE:6)
Block(0,18,8,STONE:6)
Block(0,19,8,STONE:6)
Block(0,20,8,STONE:6)
Block(0,21,8,STONE:6)
Block(0,22,8,STONE:6)
Block(0,23,8,STONE:6)
Block(0,24,8,STONE:6)
Block(0,25,8,STONE:6)
Block(0,26,8,STONE:6)
Block(0,27,8,STONE:6)
Block(0,28,8,STONE:6)
Block(0,29,8,STONE:6)
Block(0,30,8,STONE:6)
Block(0,31,8,STONE:6)
Block(0,32,8,STONE:6)
Block(0,33,8,STONE:6)
Block(0,34,8,STONE:6)
Block(0,35,8,STONE:6)
Block(0,36,8,STONE:6)
Block(0,37,8,STONE:6)
Block(0,38,8,STEP:0)
Block(0,41,1,STAINED_CLAY:9)
Block(0,41,2,MOSSY_COBBLESTONE:0)
Block(0,41,3,STAINED_CLAY:9)
Block(0,50,7,COBBLESTONE:0)
Block(0,50,8,COBBLESTONE:0)
Block(0,51,6,STAINED_CLAY:9)
Block(0,51,7,COBBLESTONE:0)
Block(0,51,8,STAINED_CLAY:9)
Block(1,0,8,STONE:6)
Block(1,1,8,STONE:6)
Block(1,2,8,STONE:6)
Block(1,3,8,STONE:6)
Block(1,4,8,STONE:6)
Block(1,5,8,STONE:6)
Block(1,6,8,STONE:6)
Block(1,7,8,STONE:6)
Block(1,8,8,STONE:6)
Block(1,9,8,STONE:6)
Block(1,10,8,STONE:6)
Block(1,11,8,STONE:6)
Block(1,12,8,STONE:6)
Block(1,13,8,STONE:6)
Block(1,14,8,STONE:6)
Block(1,15,8,STONE:6)
Block(1,16,8,STONE:6)
Block(1,17,8,STONE:6)
Block(1,18,8,STONE:6)
Block(1,19,8,STONE:6)
Block(1,20,8,STONE:6)
Block(1,21,8,STONE:6)
Block(1,22,8,STONE:6)
Block(1,23,8,STONE:6)
Block(1,24,8,STONE:6)
Block(1,25,8,STONE:6)
Block(1,26,8,STONE:6)
Block(1,27,8,STONE:6)
Block(1,28,8,STONE:6)
Block(1,29,8,STONE:6)
Block(1,30,8,STONE:6)
Block(1,31,8,STONE:6)
Block(1,32,8,STONE:6)
Block(1,33,8,STONE:6)
Block(1,34,8,STONE:6)
Block(1,35,8,STONE:6)
Block(1,36,8,STONE:6)
Block(1,37,8,STONE:6)
Block(1,38,8,STEP:0)
Block(1,41,2,STAINED_CLAY:9)
Block(1,52,5,MOSSY_COBBLESTONE:0)
Block(1,52,6,STAINED_CLAY:9)
Block(1,52,7,MOSSY_COBBLESTONE:0)
Block(1,52,8,COBBLESTONE:0)
Block(1,53,6,STAINED_CLAY:9)
Block(1,53,7,COBBLESTONE:0)
Block(1,53,8,COBBLESTONE:0)
Block(1,54,7,COBBLESTONE:0)
Block(1,54,8,MOSSY_COBBLESTONE:0)
Block(1,55,8,COBBLESTONE:0)
Block(2,54,4,COBBLESTONE:0)
Block(2,54,5,STAINED_CLAY:9)
Block(2,54,6,STAINED_CLAY:9)
Block(2,55,7,STAINED_CLAY:9)
Block(2,55,8,COBBLESTONE:0)
Block(3,55,6,COBBLESTONE:0)

#######################################################################
# +-----------------------------------------------------------------+ #
# |                             Branches                            | #
# +-----------------------------------------------------------------+ #
#######################################################################

Branch(-16,0,0,true,SpawnHexC8R1,NORTH,100.0,0)

#######################################################################
# +-----------------------------------------------------------------+ #
# |                             Entities                            | #
# +-----------------------------------------------------------------+ #
#######################################################################


#######################################################################
# +-----------------------------------------------------------------+ #
# |                            Particles                            | #
# +-----------------------------------------------------------------+ #
#######################################################################


#######################################################################
# +-----------------------------------------------------------------+ #
# |                             Spawners                            | #
# +-----------------------------------------------------------------+ #
#######################################################################


#######################################################################
# +-----------------------------------------------------------------+ #
# |                             ModData                             | #
# +-----------------------------------------------------------------+ #
#######################################################################

