
#######################################################################
# +-----------------------------------------------------------------+ #
# |                            BO4 object                           | #
# +-----------------------------------------------------------------+ #
#######################################################################

Author: NLBlackEagle

Description: No description given

SettingsMode: WriteDisable


#######################################################################
# +-----------------------------------------------------------------+ #
# |                          Main settings                          | #
# +-----------------------------------------------------------------+ #
#######################################################################

Frequency: 0

SpawnHeight: highestBlock

UseCenterForHighestBlock: true

##############################
# Height Limits for the BO4. #
##############################

MinHeight: 0

MaxHeight: 255

InheritBO3: 

InheritBO3Rotation: NORTH

OverrideChildSettings: true

OverrideParentHeight: false

CanOverride: false

BranchFrequency: 0

BranchFrequencyGroup: 

MustBeBelowOther: false

MustBeInside: 

CannotBeInside: 

ReplacesBO3: 

MustBeInsideWorldBorders: false

CanSpawnOnWater: true

SpawnOnWaterOnly: false

SpawnUnderWater: false

SpawnAtWaterLevel: false

HeightOffset: 0

RemoveAir: true

ReplaceAbove: 

ReplaceBelow: 

ReplaceWithBiomeBlocks: true

ReplaceWithSurfaceBlock: GRASS

ReplaceWithGroundBlock: DIRT

ReplaceWithStoneBlock: STONE

SmoothRadius: 0

SmoothHeightOffset: 0

SmoothStartTop: false

SmoothStartWood: false

SmoothingSurfaceBlock: 

SmoothingGroundBlock: 

BO3Group: 

IsSpawnPoint: false

DoReplaceBlocks: true


#######################################################################
# +-----------------------------------------------------------------+ #
# |                              Blocks                             | #
# +-----------------------------------------------------------------+ #
#######################################################################

Block(-5,0,-7,STONE:6)
Block(-5,0,-1,STONE:6)
Block(-5,0,1,STONE:6)
Block(-5,1,-7,STONE:6)
Block(-5,1,-1,STONE:6)
Block(-5,1,1,STONE:6)
Block(-5,2,-7,STONE:6)
Block(-5,2,-1,STONE:6)
Block(-5,2,1,STONE:6)
Block(-5,3,-7,STONE:6)
Block(-5,3,-1,STONE:6)
Block(-5,3,1,STONE:6)
Block(-5,4,-7,STONE:6)
Block(-5,4,-1,STONE:6)
Block(-5,4,1,STONE:6)
Block(-5,5,-7,STONE:6)
Block(-5,5,-1,STONE:6)
Block(-5,5,1,STONE:6)
Block(-5,6,-7,STONE:6)
Block(-5,6,-1,STONE:6)
Block(-5,6,1,STONE:6)
Block(-5,7,-7,STONE:6)
Block(-5,7,-1,STONE:6)
Block(-5,7,1,STONE:6)
Block(-5,8,-7,STONE:6)
Block(-5,8,-1,STONE:6)
Block(-5,8,1,STONE:6)
Block(-5,9,-7,STONE:6)
Block(-5,9,-1,STONE:6)
Block(-5,9,1,STONE:6)
Block(-5,10,-7,STONE:6)
Block(-5,10,-1,STONE:6)
Block(-5,10,1,STONE:6)
Block(-5,11,-7,STONE:6)
Block(-5,11,-1,STONE:6)
Block(-5,11,1,STONE:6)
Block(-5,12,-7,STONE:6)
Block(-5,12,-1,STONE:6)
Block(-5,12,1,STONE:6)
Block(-5,13,-7,STONE:6)
Block(-5,13,-1,STONE:6)
Block(-5,13,1,STONE:6)
Block(-5,14,-7,STONE:6)
Block(-5,14,-1,STONE:6)
Block(-5,14,1,STONE:6)
Block(-5,15,-7,STONE:6)
Block(-5,15,-1,STONE:6)
Block(-5,15,1,STONE:6)
Block(-5,16,-7,STONE:6)
Block(-5,16,-1,STONE:6)
Block(-5,16,1,STONE:6)
Block(-5,17,-7,STONE:6)
Block(-5,17,-1,STONE:6)
Block(-5,17,1,STONE:6)
Block(-5,18,-7,STONE:6)
Block(-5,18,-1,STONE:6)
Block(-5,18,1,STONE:6)
Block(-5,19,-7,STONE:6)
Block(-5,19,-1,STONE:6)
Block(-5,19,1,STONE:6)
Block(-5,20,-7,STONE:6)
Block(-5,20,-1,STONE:6)
Block(-5,20,1,STONE:6)
Block(-5,21,-7,STONE:6)
Block(-5,21,-1,STONE:6)
Block(-5,21,1,STONE:6)
Block(-5,22,-7,STONE:6)
Block(-5,22,-1,STONE:6)
Block(-5,22,1,STONE:6)
Block(-5,23,-7,STONE:6)
Block(-5,23,-1,STONE:6)
Block(-5,23,1,STONE:6)
Block(-5,24,-7,STONE:6)
Block(-5,24,-1,STONE:6)
Block(-5,24,1,STONE:6)
Block(-5,25,-7,STONE:6)
Block(-5,25,-1,STONE:6)
Block(-5,25,1,STONE:6)
Block(-5,26,-7,STONE:6)
Block(-5,26,-1,STONE:6)
Block(-5,26,1,STONE:6)
Block(-5,27,-7,STONE:6)
Block(-5,27,-1,STONE:6)
Block(-5,27,1,STONE:6)
Block(-5,28,-7,STONE:6)
Block(-5,28,-1,STONE:6)
Block(-5,28,1,STONE:6)
Block(-5,29,-7,STONE:6)
Block(-5,29,-1,STONE:6)
Block(-5,29,1,STONE:6)
Block(-5,30,-7,STONE:6)
Block(-5,30,-1,STONE:6)
Block(-5,30,1,STONE:6)
Block(-5,31,-7,STONE:6)
Block(-5,31,-1,STONE:6)
Block(-5,31,1,STONE:6)
Block(-5,32,-7,STONE:6)
Block(-5,32,-1,STONE:6)
Block(-5,32,1,STONE:6)
Block(-5,33,-7,STONE:6)
Block(-5,33,-6,SMOOTH_STAIRS:7)
Block(-5,33,-2,SMOOTH_STAIRS:6)
Block(-5,33,-1,STONE:6)
Block(-5,34,-6,STONE:6)
Block(-5,34,-5,SMOOTH_STAIRS:7)
Block(-5,34,-3,SMOOTH_STAIRS:6)
Block(-5,34,-2,STONE:6)
Block(-5,34,-1,STONE:6)
Block(-5,35,-5,SMOOTH_STAIRS:2)
Block(-5,35,-4,STONE:6)
Block(-5,35,-3,SMOOTH_STAIRS:3)
Block(-4,0,0,COBBLESTONE:0)
Block(-4,1,0,COBBLESTONE:0)
Block(-4,2,0,COBBLESTONE:0)
Block(-4,3,0,COBBLESTONE:0)
Block(-4,4,0,COBBLESTONE:0)
Block(-4,5,0,COBBLESTONE:0)
Block(-4,6,0,COBBLESTONE:0)
Block(-4,7,0,COBBLESTONE:0)
Block(-4,8,0,COBBLESTONE:0)
Block(-4,9,0,COBBLESTONE:0)
Block(-4,10,0,COBBLESTONE:0)
Block(-4,11,0,COBBLESTONE:0)
Block(-4,12,0,COBBLESTONE:0)
Block(-4,13,0,COBBLESTONE:0)
Block(-4,14,0,COBBLESTONE:0)
Block(-4,15,0,COBBLESTONE:0)
Block(-4,16,0,COBBLESTONE:0)
Block(-4,17,0,COBBLESTONE:0)
Block(-4,18,0,COBBLESTONE:0)
Block(-4,19,0,COBBLESTONE:0)
Block(-4,20,0,COBBLESTONE:0)
Block(-4,21,0,COBBLESTONE:0)
Block(-4,22,0,COBBLESTONE:0)
Block(-4,23,0,COBBLESTONE:0)
Block(-4,24,0,COBBLESTONE:0)
Block(-4,25,0,COBBLESTONE:0)
Block(-4,26,0,COBBLESTONE:0)
Block(-4,27,0,COBBLESTONE:0)
Block(-4,28,0,COBBLESTONE:0)
Block(-4,29,0,COBBLESTONE:0)
Block(-4,30,0,COBBLESTONE:0)
Block(-4,31,0,COBBLESTONE:0)
Block(-4,32,0,COBBLESTONE:0)
Block(-4,33,0,COBBLESTONE:0)
Block(-4,34,0,COBBLESTONE:0)
Block(-4,35,0,COBBLESTONE:0)
Block(-3,0,0,COBBLESTONE:0)
Block(-3,1,0,COBBLESTONE:0)
Block(-3,2,0,COBBLESTONE:0)
Block(-3,3,0,COBBLESTONE:0)
Block(-3,4,0,COBBLESTONE:0)
Block(-3,5,0,COBBLESTONE:0)
Block(-3,6,0,COBBLESTONE:0)
Block(-3,7,0,COBBLESTONE:0)
Block(-3,8,0,COBBLESTONE:0)
Block(-3,9,0,COBBLESTONE:0)
Block(-3,10,0,COBBLESTONE:0)
Block(-3,11,0,COBBLESTONE:0)
Block(-3,12,0,COBBLESTONE:0)
Block(-3,13,0,COBBLESTONE:0)
Block(-3,14,0,COBBLESTONE:0)
Block(-3,15,0,COBBLESTONE:0)
Block(-3,16,0,COBBLESTONE:0)
Block(-3,17,0,COBBLESTONE:0)
Block(-3,18,0,COBBLESTONE:0)
Block(-3,19,0,COBBLESTONE:0)
Block(-3,20,0,COBBLESTONE:0)
Block(-3,21,0,COBBLESTONE:0)
Block(-3,22,0,COBBLESTONE:0)
Block(-3,23,0,COBBLESTONE:0)
Block(-3,24,0,COBBLESTONE:0)
Block(-3,25,0,COBBLESTONE:0)
Block(-3,26,0,COBBLESTONE:0)
Block(-3,27,0,COBBLESTONE:0)
Block(-3,28,0,COBBLESTONE:0)
Block(-3,29,0,COBBLESTONE:0)
Block(-3,30,0,COBBLESTONE:0)
Block(-3,31,0,COBBLESTONE:0)
Block(-3,32,0,COBBLESTONE:0)
Block(-3,33,0,COBBLESTONE:0)
Block(-3,34,0,COBBLESTONE:0)
Block(-3,35,0,COBBLESTONE:0)
Block(-3,36,0,COBBLESTONE:0)
Block(-3,37,0,COBBLESTONE:0)
Block(-3,37,1,STONE:6)
Block(-2,0,0,COBBLESTONE:0)
Block(-2,1,0,COBBLESTONE:0)
Block(-2,2,0,COBBLESTONE:0)
Block(-2,3,0,COBBLESTONE:0)
Block(-2,4,0,COBBLESTONE:0)
Block(-2,5,0,COBBLESTONE:0)
Block(-2,6,0,COBBLESTONE:0)
Block(-2,7,0,COBBLESTONE:0)
Block(-2,8,0,COBBLESTONE:0)
Block(-2,9,0,COBBLESTONE:0)
Block(-2,10,0,COBBLESTONE:0)
Block(-2,11,0,COBBLESTONE:0)
Block(-2,12,0,COBBLESTONE:0)
Block(-2,13,0,COBBLESTONE:0)
Block(-2,14,0,COBBLESTONE:0)
Block(-2,15,0,COBBLESTONE:0)
Block(-2,16,0,COBBLESTONE:0)
Block(-2,17,0,COBBLESTONE:0)
Block(-2,18,0,COBBLESTONE:0)
Block(-2,19,0,COBBLESTONE:0)
Block(-2,20,0,COBBLESTONE:0)
Block(-2,21,0,COBBLESTONE:0)
Block(-2,22,0,COBBLESTONE:0)
Block(-2,23,0,COBBLESTONE:0)
Block(-2,24,0,COBBLESTONE:0)
Block(-2,25,0,COBBLESTONE:0)
Block(-2,26,0,COBBLESTONE:0)
Block(-2,27,0,COBBLESTONE:0)
Block(-2,28,0,COBBLESTONE:0)
Block(-2,29,0,COBBLESTONE:0)
Block(-2,30,0,COBBLESTONE:0)
Block(-2,31,0,COBBLESTONE:0)
Block(-2,32,0,COBBLESTONE:0)
Block(-2,33,0,COBBLESTONE:0)
Block(-2,34,0,COBBLESTONE:0)
Block(-2,35,0,COBBLESTONE:0)
Block(-2,36,0,COBBLESTONE:0)
Block(-2,37,-7,STONE:6)
Block(-2,37,-6,COBBLESTONE:0)
Block(-2,37,-3,COBBLESTONE:0)
Block(-2,37,-2,COBBLESTONE:0)
Block(-2,37,-1,STONE:6)
Block(-2,37,0,COBBLESTONE:0)
Block(-2,37,1,STONE:6)
Block(-2,38,-1,STEP:0)
Block(-2,38,0,STEP:0)
Block(-2,38,1,STEP:0)
Block(-1,0,-7,STONE:6)
Block(-1,0,-1,STONE:6)
Block(-1,0,1,STONE:6)
Block(-1,1,-7,STONE:6)
Block(-1,1,-1,STONE:6)
Block(-1,1,1,STONE:6)
Block(-1,2,-7,STONE:6)
Block(-1,2,-1,STONE:6)
Block(-1,2,1,STONE:6)
Block(-1,3,-7,STONE:6)
Block(-1,3,-1,STONE:6)
Block(-1,3,1,STONE:6)
Block(-1,4,-7,STONE:6)
Block(-1,4,-1,STONE:6)
Block(-1,4,1,STONE:6)
Block(-1,5,-7,STONE:6)
Block(-1,5,-1,STONE:6)
Block(-1,5,1,STONE:6)
Block(-1,6,-7,STONE:6)
Block(-1,6,-1,STONE:6)
Block(-1,6,1,STONE:6)
Block(-1,7,-7,STONE:6)
Block(-1,7,-1,STONE:6)
Block(-1,7,1,STONE:6)
Block(-1,8,-7,STONE:6)
Block(-1,8,-1,STONE:6)
Block(-1,8,1,STONE:6)
Block(-1,9,-7,STONE:6)
Block(-1,9,-1,STONE:6)
Block(-1,9,1,STONE:6)
Block(-1,10,-7,STONE:6)
Block(-1,10,-1,STONE:6)
Block(-1,10,1,STONE:6)
Block(-1,11,-7,STONE:6)
Block(-1,11,-1,STONE:6)
Block(-1,11,1,STONE:6)
Block(-1,12,-7,STONE:6)
Block(-1,12,-1,STONE:6)
Block(-1,12,1,STONE:6)
Block(-1,13,-7,STONE:6)
Block(-1,13,-1,STONE:6)
Block(-1,13,1,STONE:6)
Block(-1,14,-7,STONE:6)
Block(-1,14,-1,STONE:6)
Block(-1,14,1,STONE:6)
Block(-1,15,-7,STONE:6)
Block(-1,15,-1,STONE:6)
Block(-1,15,1,STONE:6)
Block(-1,16,-7,STONE:6)
Block(-1,16,-1,STONE:6)
Block(-1,16,1,STONE:6)
Block(-1,17,-7,STONE:6)
Block(-1,17,-1,STONE:6)
Block(-1,17,1,STONE:6)
Block(-1,18,-7,STONE:6)
Block(-1,18,-1,STONE:6)
Block(-1,18,1,STONE:6)
Block(-1,19,-7,STONE:6)
Block(-1,19,-1,STONE:6)
Block(-1,19,1,STONE:6)
Block(-1,20,-7,STONE:6)
Block(-1,20,-1,STONE:6)
Block(-1,20,1,STONE:6)
Block(-1,21,-7,STONE:6)
Block(-1,21,-1,STONE:6)
Block(-1,21,1,STONE:6)
Block(-1,22,-7,STONE:6)
Block(-1,22,-1,STONE:6)
Block(-1,22,1,STONE:6)
Block(-1,23,-7,STONE:6)
Block(-1,23,-1,STONE:6)
Block(-1,23,1,STONE:6)
Block(-1,24,-7,STONE:6)
Block(-1,24,-1,STONE:6)
Block(-1,24,1,STONE:6)
Block(-1,25,-7,STONE:6)
Block(-1,25,-1,STONE:6)
Block(-1,25,1,STONE:6)
Block(-1,26,-7,STONE:6)
Block(-1,26,-1,STONE:6)
Block(-1,26,1,STONE:6)
Block(-1,27,-7,STONE:6)
Block(-1,27,-1,STONE:6)
Block(-1,27,1,STONE:6)
Block(-1,28,-7,STONE:6)
Block(-1,28,-1,STONE:6)
Block(-1,28,1,STONE:6)
Block(-1,29,-7,STONE:6)
Block(-1,29,-1,STONE:6)
Block(-1,29,1,STONE:6)
Block(-1,30,-7,STONE:6)
Block(-1,30,-1,STONE:6)
Block(-1,30,1,STONE:6)
Block(-1,31,-7,STONE:6)
Block(-1,31,-1,STONE:6)
Block(-1,31,1,STONE:6)
Block(-1,32,-7,STONE:6)
Block(-1,32,-1,STONE:6)
Block(-1,32,1,STONE:6)
Block(-1,33,-7,STONE:6)
Block(-1,33,-6,SMOOTH_STAIRS:7)
Block(-1,33,-2,SMOOTH_STAIRS:6)
Block(-1,33,-1,STONE:6)
Block(-1,33,1,STONE:6)
Block(-1,33,2,SMOOTH_STAIRS:7)
Block(-1,34,-7,STONE:6)
Block(-1,34,-6,STONE:6)
Block(-1,34,-5,SMOOTH_STAIRS:7)
Block(-1,34,-3,SMOOTH_STAIRS:6)
Block(-1,34,-2,STONE:6)
Block(-1,34,-1,STONE:6)
Block(-1,34,1,STONE:6)
Block(-1,34,2,STONE:6)
Block(-1,35,-7,STONE:6)
Block(-1,35,-6,SMOOTH_STAIRS:3)
Block(-1,35,-5,SMOOTH_STAIRS:2)
Block(-1,35,-4,STONE:6)
Block(-1,35,-3,SMOOTH_STAIRS:3)
Block(-1,35,-2,SMOOTH_STAIRS:2)
Block(-1,35,-1,STONE:6)
Block(-1,35,1,STONE:6)
Block(-1,35,2,SMOOTH_STAIRS:3)
Block(-1,36,-7,STONE:6)
Block(-1,36,-6,SMOOTH_STAIRS:7)
Block(-1,36,-4,COBBLE_WALL:0)
Block(-1,36,-2,SMOOTH_STAIRS:6)
Block(-1,36,-1,STONE:6)
Block(-1,36,1,STONE:6)
Block(-1,36,2,SMOOTH_STAIRS:7)
Block(-1,37,-7,STONE:6)
Block(-1,37,-6,STONE:6)
Block(-1,37,-5,STONE:6)
Block(-1,37,-4,STONE:6)
Block(-1,37,-3,STONE:6)
Block(-1,37,-2,STONE:6)
Block(-1,37,-1,STONE:6)
Block(-1,37,1,STONE:6)
Block(-1,37,2,STONE:6)
Block(-1,37,3,STONE:6)
Block(-1,38,-7,STEP:0)
Block(-1,38,-6,STEP:0)
Block(-1,38,-5,STEP:0)
Block(-1,38,-4,STEP:0)
Block(-1,38,-3,STEP:0)
Block(-1,38,-2,STEP:0)
Block(-1,38,-1,STEP:0)
Block(-1,38,1,STEP:0)

#######################################################################
# +-----------------------------------------------------------------+ #
# |                             Branches                            | #
# +-----------------------------------------------------------------+ #
#######################################################################

Branch(0,0,-16,true,SpawnHexC9R17,NORTH,100.0,0)

#######################################################################
# +-----------------------------------------------------------------+ #
# |                             Entities                            | #
# +-----------------------------------------------------------------+ #
#######################################################################


#######################################################################
# +-----------------------------------------------------------------+ #
# |                            Particles                            | #
# +-----------------------------------------------------------------+ #
#######################################################################


#######################################################################
# +-----------------------------------------------------------------+ #
# |                             Spawners                            | #
# +-----------------------------------------------------------------+ #
#######################################################################


#######################################################################
# +-----------------------------------------------------------------+ #
# |                             ModData                             | #
# +-----------------------------------------------------------------+ #
#######################################################################

