
#######################################################################
# +-----------------------------------------------------------------+ #
# |                            BO4 object                           | #
# +-----------------------------------------------------------------+ #
#######################################################################

Author: NLBlackEagle

Description: No description given

SettingsMode: WriteDisable


#######################################################################
# +-----------------------------------------------------------------+ #
# |                          Main settings                          | #
# +-----------------------------------------------------------------+ #
#######################################################################

Frequency: 0

SpawnHeight: highestBlock

UseCenterForHighestBlock: true

##############################
# Height Limits for the BO4. #
##############################

MinHeight: 0

MaxHeight: 255

InheritBO3: 

InheritBO3Rotation: NORTH

OverrideChildSettings: true

OverrideParentHeight: false

CanOverride: false

BranchFrequency: 0

BranchFrequencyGroup: 

MustBeBelowOther: false

MustBeInside: 

CannotBeInside: 

ReplacesBO3: 

MustBeInsideWorldBorders: false

CanSpawnOnWater: true

SpawnOnWaterOnly: false

SpawnUnderWater: false

SpawnAtWaterLevel: false

HeightOffset: 0

RemoveAir: true

ReplaceAbove: 

ReplaceBelow: 

ReplaceWithBiomeBlocks: true

ReplaceWithSurfaceBlock: GRASS

ReplaceWithGroundBlock: DIRT

ReplaceWithStoneBlock: STONE

SmoothRadius: 0

SmoothHeightOffset: 0

SmoothStartTop: false

SmoothStartWood: false

SmoothingSurfaceBlock: 

SmoothingGroundBlock: 

BO3Group: 

IsSpawnPoint: false

DoReplaceBlocks: true


#######################################################################
# +-----------------------------------------------------------------+ #
# |                              Blocks                             | #
# +-----------------------------------------------------------------+ #
#######################################################################

Block(-8,0,-6,COBBLESTONE:0)
Block(-8,1,-6,COBBLESTONE:0)
Block(-8,2,-6,COBBLESTONE:0)
Block(-8,3,-6,COBBLESTONE:0)
Block(-8,4,-6,COBBLESTONE:0)
Block(-8,5,-6,COBBLESTONE:0)
Block(-8,6,-6,COBBLESTONE:0)
Block(-8,7,-6,COBBLESTONE:0)
Block(-8,8,-6,COBBLESTONE:0)
Block(-8,9,-6,COBBLESTONE:0)
Block(-8,10,-6,COBBLESTONE:0)
Block(-8,11,-6,COBBLESTONE:0)
Block(-8,12,-6,COBBLESTONE:0)
Block(-8,13,-6,COBBLESTONE:0)
Block(-8,14,-6,COBBLESTONE:0)
Block(-8,15,-6,COBBLESTONE:0)
Block(-8,16,-6,COBBLESTONE:0)
Block(-8,17,-6,COBBLESTONE:0)
Block(-8,18,-6,COBBLESTONE:0)
Block(-8,19,-6,COBBLESTONE:0)
Block(-8,20,-6,COBBLESTONE:0)
Block(-8,21,-6,COBBLESTONE:0)
Block(-8,22,-6,COBBLESTONE:0)
Block(-8,23,-6,COBBLESTONE:0)
Block(-8,24,-6,COBBLESTONE:0)
Block(-8,25,-6,COBBLESTONE:0)
Block(-8,26,-6,COBBLESTONE:0)
Block(-8,27,-6,COBBLESTONE:0)
Block(-8,28,-6,COBBLESTONE:0)
Block(-8,29,-6,COBBLESTONE:0)
Block(-8,30,-6,COBBLESTONE:0)
Block(-8,31,-6,COBBLESTONE:0)
Block(-8,32,-6,COBBLESTONE:0)
Block(-8,33,-6,COBBLESTONE:0)
Block(-8,33,-5,SMOOTH_STAIRS:5)
Block(-8,33,-4,SMOOTH_STAIRS:7)
Block(-8,34,-6,COBBLESTONE:0)
Block(-8,34,-5,SMOOTH_STAIRS:2)
Block(-8,34,-4,STONE:6)
Block(-8,35,-6,COBBLESTONE:0)
Block(-8,35,-4,SMOOTH_STAIRS:2)
Block(-8,36,-6,COBBLESTONE:0)
Block(-8,36,-4,STEP:13)
Block(-8,37,-7,COBBLESTONE:0)
Block(-8,37,-6,COBBLESTONE:0)
Block(-8,37,-5,COBBLESTONE:0)
Block(-8,37,-4,STONE:6)
Block(-8,38,-4,STEP:0)
Block(-7,0,-7,STONE:6)
Block(-7,1,-7,STONE:6)
Block(-7,2,-7,STONE:6)
Block(-7,3,-7,STONE:6)
Block(-7,4,-7,STONE:6)
Block(-7,5,-7,STONE:6)
Block(-7,6,-7,STONE:6)
Block(-7,7,-7,STONE:6)
Block(-7,8,-7,STONE:6)
Block(-7,9,-7,STONE:6)
Block(-7,10,-7,STONE:6)
Block(-7,11,-7,STONE:6)
Block(-7,12,-7,STONE:6)
Block(-7,13,-7,STONE:6)
Block(-7,14,-7,STONE:6)
Block(-7,15,-7,STONE:6)
Block(-7,16,-7,STONE:6)
Block(-7,17,-7,STONE:6)
Block(-7,18,-7,STONE:6)
Block(-7,19,-7,STONE:6)
Block(-7,20,-7,STONE:6)
Block(-7,21,-7,STONE:6)
Block(-7,22,-7,STONE:6)
Block(-7,23,-7,STONE:6)
Block(-7,24,-7,STONE:6)
Block(-7,25,-7,STONE:6)
Block(-7,26,-7,STONE:6)
Block(-7,27,-7,STONE:6)
Block(-7,28,-7,STONE:6)
Block(-7,29,-7,STONE:6)
Block(-7,30,-7,STONE:6)
Block(-7,31,-7,STONE:6)
Block(-7,32,-7,STONE:6)
Block(-7,33,-7,STONE:6)
Block(-7,33,-6,SMOOTH_STAIRS:7)
Block(-7,34,-7,STONE:6)
Block(-7,34,-6,SMOOTH_STAIRS:0)
Block(-7,34,-3,STEP:13)
Block(-7,35,-7,STONE:6)
Block(-7,35,-3,STONE:6)
Block(-7,36,-7,STONE:6)
Block(-7,36,-3,COBBLE_WALL:0)
Block(-7,37,-7,STONE:6)
Block(-7,37,-6,COBBLESTONE:0)
Block(-7,37,-5,COBBLESTONE:0)
Block(-7,37,-4,COBBLESTONE:0)
Block(-7,37,-3,STONE:6)
Block(-7,38,-7,STEP:0)
Block(-7,38,-3,STEP:0)
Block(-6,33,-6,SMOOTH_STAIRS:5)
Block(-6,33,-2,SMOOTH_STAIRS:4)
Block(-6,34,-6,STONE:6)
Block(-6,34,-2,STONE:6)
Block(-6,35,-6,SMOOTH_STAIRS:0)
Block(-6,35,-2,SMOOTH_STAIRS:1)
Block(-6,36,-6,STEP:13)
Block(-6,36,-2,STEP:13)
Block(-6,37,-6,STONE:6)
Block(-6,37,-5,COBBLESTONE:0)
Block(-6,37,-4,COBBLESTONE:0)
Block(-6,37,-3,COBBLESTONE:0)
Block(-6,37,-2,STONE:6)
Block(-6,38,-6,STEP:0)
Block(-6,38,-2,STEP:0)
Block(-5,0,-1,STONE:6)
Block(-5,1,-1,STONE:6)
Block(-5,2,-1,STONE:6)
Block(-5,3,-1,STONE:6)
Block(-5,4,-1,STONE:6)
Block(-5,5,-1,STONE:6)
Block(-5,6,-1,STONE:6)
Block(-5,7,-1,STONE:6)
Block(-5,8,-1,STONE:6)
Block(-5,9,-1,STONE:6)
Block(-5,10,-1,STONE:6)
Block(-5,11,-1,STONE:6)
Block(-5,12,-1,STONE:6)
Block(-5,13,-1,STONE:6)
Block(-5,14,-1,STONE:6)
Block(-5,15,-1,STONE:6)
Block(-5,16,-1,STONE:6)
Block(-5,17,-1,STONE:6)
Block(-5,18,-1,STONE:6)
Block(-5,19,-1,STONE:6)
Block(-5,20,-1,STONE:6)
Block(-5,21,-1,STONE:6)
Block(-5,22,-1,STONE:6)
Block(-5,23,-1,STONE:6)
Block(-5,24,-1,STONE:6)
Block(-5,25,-1,STONE:6)
Block(-5,26,-1,STONE:6)
Block(-5,27,-1,STONE:6)
Block(-5,28,-1,STONE:6)
Block(-5,29,-1,STONE:6)
Block(-5,30,-1,STONE:6)
Block(-5,31,-1,STONE:6)
Block(-5,32,-1,STONE:6)
Block(-5,33,-2,SMOOTH_STAIRS:6)
Block(-5,33,-1,STONE:6)
Block(-5,34,-5,STEP:13)
Block(-5,34,-2,SMOOTH_STAIRS:1)
Block(-5,34,-1,STONE:6)
Block(-5,35,-5,STONE:6)
Block(-5,35,-1,STONE:6)
Block(-5,36,-5,COBBLE_WALL:0)
Block(-5,36,-1,STONE:6)
Block(-5,37,-5,STONE:6)
Block(-5,37,-4,COBBLESTONE:0)
Block(-5,37,-3,COBBLESTONE:0)
Block(-5,37,-2,COBBLESTONE:0)
Block(-5,37,-1,STONE:6)
Block(-5,38,-5,STEP:0)
Block(-5,38,-1,STEP:0)
Block(-4,0,-2,COBBLESTONE:0)
Block(-4,1,-2,COBBLESTONE:0)
Block(-4,2,-2,COBBLESTONE:0)
Block(-4,3,-2,COBBLESTONE:0)
Block(-4,4,-2,COBBLESTONE:0)
Block(-4,5,-2,COBBLESTONE:0)
Block(-4,6,-2,COBBLESTONE:0)
Block(-4,7,-2,COBBLESTONE:0)
Block(-4,8,-2,COBBLESTONE:0)
Block(-4,9,-2,COBBLESTONE:0)
Block(-4,10,-2,COBBLESTONE:0)
Block(-4,11,-2,COBBLESTONE:0)
Block(-4,12,-2,COBBLESTONE:0)
Block(-4,13,-2,COBBLESTONE:0)
Block(-4,14,-2,COBBLESTONE:0)
Block(-4,15,-2,COBBLESTONE:0)
Block(-4,16,-2,COBBLESTONE:0)
Block(-4,17,-2,COBBLESTONE:0)
Block(-4,18,-2,COBBLESTONE:0)
Block(-4,19,-2,COBBLESTONE:0)
Block(-4,20,-2,COBBLESTONE:0)
Block(-4,21,-2,COBBLESTONE:0)
Block(-4,22,-2,COBBLESTONE:0)
Block(-4,23,-2,COBBLESTONE:0)
Block(-4,24,-2,COBBLESTONE:0)
Block(-4,25,-2,COBBLESTONE:0)
Block(-4,26,-2,COBBLESTONE:0)
Block(-4,27,-2,COBBLESTONE:0)
Block(-4,28,-2,COBBLESTONE:0)
Block(-4,29,-2,COBBLESTONE:0)
Block(-4,30,-2,COBBLESTONE:0)
Block(-4,31,-2,COBBLESTONE:0)
Block(-4,32,-2,COBBLESTONE:0)
Block(-4,33,-4,SMOOTH_STAIRS:6)
Block(-4,33,-3,SMOOTH_STAIRS:4)
Block(-4,33,-2,COBBLESTONE:0)
Block(-4,34,-4,STONE:6)
Block(-4,34,-3,SMOOTH_STAIRS:3)
Block(-4,34,-2,COBBLESTONE:0)
Block(-4,35,-4,SMOOTH_STAIRS:3)
Block(-4,35,-2,COBBLESTONE:0)
Block(-4,36,-4,STEP:13)
Block(-4,36,-2,COBBLESTONE:0)
Block(-4,37,-4,STONE:6)
Block(-4,37,-3,COBBLESTONE:0)
Block(-4,37,-2,COBBLESTONE:0)
Block(-4,37,-1,SMOOTH_STAIRS:5)
Block(-4,38,-4,STEP:0)
Block(-3,0,-3,STONE:6)
Block(-3,0,-1,COBBLESTONE:0)
Block(-3,0,1,STONE:6)
Block(-3,1,-3,STONE:6)
Block(-3,1,-1,COBBLESTONE:0)
Block(-3,1,1,STONE:6)
Block(-3,2,-3,STONE:6)
Block(-3,2,-1,COBBLESTONE:0)
Block(-3,2,1,STONE:6)
Block(-3,3,-3,STONE:6)
Block(-3,3,-1,COBBLESTONE:0)
Block(-3,3,1,STONE:6)
Block(-3,4,-3,STONE:6)
Block(-3,4,-1,COBBLESTONE:0)
Block(-3,4,1,STONE:6)
Block(-3,5,-3,STONE:6)
Block(-3,5,-1,COBBLESTONE:0)
Block(-3,5,1,STONE:6)
Block(-3,6,-3,STONE:6)
Block(-3,6,-1,COBBLESTONE:0)
Block(-3,6,1,STONE:6)
Block(-3,7,-3,STONE:6)
Block(-3,7,-1,COBBLESTONE:0)
Block(-3,7,1,STONE:6)
Block(-3,8,-3,STONE:6)
Block(-3,8,-1,COBBLESTONE:0)
Block(-3,8,1,STONE:6)
Block(-3,9,-3,STONE:6)
Block(-3,9,-1,COBBLESTONE:0)
Block(-3,9,1,STONE:6)
Block(-3,10,-3,STONE:6)
Block(-3,10,-1,COBBLESTONE:0)
Block(-3,10,1,STONE:6)
Block(-3,11,-3,STONE:6)
Block(-3,11,-1,COBBLESTONE:0)
Block(-3,11,1,STONE:6)
Block(-3,12,-3,STONE:6)
Block(-3,12,-1,COBBLESTONE:0)
Block(-3,12,1,STONE:6)
Block(-3,13,-3,STONE:6)
Block(-3,13,-1,COBBLESTONE:0)
Block(-3,13,1,STONE:6)
Block(-3,14,-3,STONE:6)
Block(-3,14,-1,COBBLESTONE:0)
Block(-3,14,1,STONE:6)
Block(-3,15,-3,STONE:6)
Block(-3,15,-1,COBBLESTONE:0)
Block(-3,15,1,STONE:6)
Block(-3,16,-3,STONE:6)
Block(-3,16,-1,COBBLESTONE:0)
Block(-3,16,1,STONE:6)
Block(-3,17,-3,STONE:6)
Block(-3,17,-1,COBBLESTONE:0)
Block(-3,17,1,STONE:6)
Block(-3,18,-3,STONE:6)
Block(-3,18,-1,COBBLESTONE:0)
Block(-3,18,1,STONE:6)
Block(-3,19,-3,STONE:6)
Block(-3,19,-1,COBBLESTONE:0)
Block(-3,19,1,STONE:6)
Block(-3,20,-3,STONE:6)
Block(-3,20,-1,COBBLESTONE:0)
Block(-3,20,1,STONE:6)
Block(-3,21,-3,STONE:6)
Block(-3,21,-1,COBBLESTONE:0)
Block(-3,21,1,STONE:6)
Block(-3,22,-3,STONE:6)
Block(-3,22,-1,COBBLESTONE:0)
Block(-3,22,1,STONE:6)
Block(-3,23,-3,STONE:6)
Block(-3,23,-1,COBBLESTONE:0)
Block(-3,23,1,STONE:6)
Block(-3,24,-3,STONE:6)
Block(-3,24,-1,COBBLESTONE:0)
Block(-3,24,1,STONE:6)
Block(-3,25,-3,STONE:6)
Block(-3,25,-1,COBBLESTONE:0)
Block(-3,25,1,STONE:6)
Block(-3,26,-3,STONE:6)
Block(-3,26,-1,COBBLESTONE:0)
Block(-3,26,1,STONE:6)
Block(-3,27,-3,STONE:6)
Block(-3,27,-1,COBBLESTONE:0)
Block(-3,27,1,STONE:6)
Block(-3,28,-3,STONE:6)
Block(-3,28,-1,COBBLESTONE:0)
Block(-3,28,1,STONE:6)
Block(-3,29,-3,STONE:6)
Block(-3,29,-1,COBBLESTONE:0)
Block(-3,29,1,STONE:6)
Block(-3,30,-3,STONE:6)
Block(-3,30,-1,COBBLESTONE:0)
Block(-3,30,1,STONE:6)
Block(-3,31,-3,STONE:6)
Block(-3,31,-1,COBBLESTONE:0)
Block(-3,31,1,STONE:6)
Block(-3,32,-3,STONE:6)
Block(-3,32,-1,COBBLESTONE:0)
Block(-3,32,1,STONE:6)
Block(-3,33,-3,STONE:6)
Block(-3,33,-1,COBBLESTONE:0)
Block(-3,33,1,STONE:6)
Block(-3,34,-3,STONE:6)
Block(-3,34,-1,COBBLESTONE:0)
Block(-3,34,1,STONE:6)
Block(-3,35,-3,STONE:6)
Block(-3,35,-1,COBBLESTONE:0)
Block(-3,35,1,STONE:6)
Block(-3,36,-3,STONE:6)
Block(-3,36,-1,COBBLESTONE:0)
Block(-3,36,1,STONE:6)
Block(-3,37,-3,STONE:6)
Block(-3,37,-2,SMOOTH_STAIRS:7)
Block(-3,37,-1,COBBLESTONE:0)
Block(-3,37,0,SMOOTH_STAIRS:6)
Block(-3,37,1,STONE:6)
Block(-3,38,-3,STEP:0)
Block(-3,38,1,STEP:0)
Block(-2,0,0,COBBLESTONE:0)
Block(-2,1,0,COBBLESTONE:0)
Block(-2,2,0,COBBLESTONE:0)
Block(-2,3,0,COBBLESTONE:0)
Block(-2,4,0,COBBLESTONE:0)
Block(-2,5,0,COBBLESTONE:0)
Block(-2,6,0,COBBLESTONE:0)
Block(-2,7,0,COBBLESTONE:0)
Block(-2,8,0,COBBLESTONE:0)
Block(-2,9,0,COBBLESTONE:0)
Block(-2,10,0,COBBLESTONE:0)
Block(-2,11,0,COBBLESTONE:0)
Block(-2,12,0,COBBLESTONE:0)
Block(-2,13,0,COBBLESTONE:0)
Block(-2,14,0,COBBLESTONE:0)
Block(-2,15,0,COBBLESTONE:0)
Block(-2,16,0,COBBLESTONE:0)
Block(-2,17,0,COBBLESTONE:0)
Block(-2,18,0,COBBLESTONE:0)
Block(-2,19,0,COBBLESTONE:0)
Block(-2,20,0,COBBLESTONE:0)
Block(-2,21,0,COBBLESTONE:0)
Block(-2,22,0,COBBLESTONE:0)
Block(-2,23,0,COBBLESTONE:0)
Block(-2,24,0,COBBLESTONE:0)
Block(-2,25,0,COBBLESTONE:0)
Block(-2,26,0,COBBLESTONE:0)
Block(-2,27,0,COBBLESTONE:0)
Block(-2,28,0,COBBLESTONE:0)
Block(-2,29,0,COBBLESTONE:0)
Block(-2,30,0,COBBLESTONE:0)
Block(-2,31,0,COBBLESTONE:0)
Block(-2,32,0,COBBLESTONE:0)
Block(-2,33,0,COBBLESTONE:0)
Block(-2,33,1,SMOOTH_STAIRS:5)
Block(-2,33,2,SMOOTH_STAIRS:7)
Block(-2,34,0,COBBLESTONE:0)
Block(-2,34,1,SMOOTH_STAIRS:2)
Block(-2,34,2,STONE:6)
Block(-2,35,0,COBBLESTONE:0)
Block(-2,35,2,SMOOTH_STAIRS:2)
Block(-2,36,0,COBBLESTONE:0)
Block(-2,36,2,STEP:13)
Block(-2,37,-1,SMOOTH_STAIRS:4)
Block(-2,37,0,COBBLESTONE:0)
Block(-2,37,1,COBBLESTONE:0)
Block(-2,37,2,STONE:6)
Block(-2,38,2,STEP:0)
Block(-1,0,-1,STONE:6)
Block(-1,1,-1,STONE:6)
Block(-1,2,-1,STONE:6)
Block(-1,3,-1,STONE:6)
Block(-1,4,-1,STONE:6)
Block(-1,5,-1,STONE:6)
Block(-1,6,-1,STONE:6)
Block(-1,7,-1,STONE:6)
Block(-1,8,-1,STONE:6)
Block(-1,9,-1,STONE:6)
Block(-1,10,-1,STONE:6)
Block(-1,11,-1,STONE:6)
Block(-1,12,-1,STONE:6)
Block(-1,13,-1,STONE:6)
Block(-1,14,-1,STONE:6)
Block(-1,15,-1,STONE:6)
Block(-1,16,-1,STONE:6)
Block(-1,17,-1,STONE:6)
Block(-1,18,-1,STONE:6)
Block(-1,19,-1,STONE:6)
Block(-1,20,-1,STONE:6)
Block(-1,21,-1,STONE:6)
Block(-1,22,-1,STONE:6)
Block(-1,23,-1,STONE:6)
Block(-1,24,-1,STONE:6)
Block(-1,25,-1,STONE:6)
Block(-1,26,-1,STONE:6)
Block(-1,27,-1,STONE:6)
Block(-1,28,-1,STONE:6)
Block(-1,29,-1,STONE:6)
Block(-1,30,-1,STONE:6)
Block(-1,31,-1,STONE:6)
Block(-1,32,-1,STONE:6)
Block(-1,33,-1,STONE:6)
Block(-1,33,0,SMOOTH_STAIRS:7)
Block(-1,34,-1,STONE:6)
Block(-1,34,0,SMOOTH_STAIRS:0)
Block(-1,34,3,STEP:13)
Block(-1,35,-1,STONE:6)
Block(-1,35,3,STONE:6)
Block(-1,36,-1,STONE:6)
Block(-1,36,3,COBBLE_WALL:0)
Block(-1,37,-1,STONE:6)
Block(-1,37,0,COBBLESTONE:0)
Block(-1,37,1,COBBLESTONE:0)
Block(-1,37,2,COBBLESTONE:0)
Block(-1,37,3,STONE:6)
Block(-1,38,-1,STEP:0)
Block(-1,38,3,STEP:0)
Block(0,33,0,SMOOTH_STAIRS:5)
Block(0,33,4,SMOOTH_STAIRS:4)
Block(0,34,0,STONE:6)
Block(0,34,4,STONE:6)
Block(0,35,0,SMOOTH_STAIRS:0)
Block(0,35,4,SMOOTH_STAIRS:1)
Block(0,36,0,STEP:13)
Block(0,36,4,STEP:13)
Block(0,37,0,STONE:6)
Block(0,37,1,COBBLESTONE:0)
Block(0,37,2,COBBLESTONE:0)
Block(0,37,3,COBBLESTONE:0)
Block(0,37,4,STONE:6)
Block(0,38,0,STEP:0)
Block(0,38,4,STEP:0)
Block(1,0,5,STONE:6)
Block(1,1,5,STONE:6)
Block(1,2,5,STONE:6)
Block(1,3,5,STONE:6)
Block(1,4,5,STONE:6)
Block(1,5,5,STONE:6)
Block(1,6,5,STONE:6)
Block(1,7,5,STONE:6)
Block(1,8,5,STONE:6)
Block(1,9,5,STONE:6)
Block(1,10,5,STONE:6)
Block(1,11,5,STONE:6)
Block(1,12,5,STONE:6)
Block(1,13,5,STONE:6)
Block(1,14,5,STONE:6)
Block(1,15,5,STONE:6)
Block(1,16,5,STONE:6)
Block(1,17,5,STONE:6)
Block(1,18,5,STONE:6)
Block(1,19,5,STONE:6)
Block(1,20,5,STONE:6)
Block(1,21,5,STONE:6)
Block(1,22,5,STONE:6)
Block(1,23,5,STONE:6)
Block(1,24,5,STONE:6)
Block(1,25,5,STONE:6)
Block(1,26,5,STONE:6)
Block(1,27,5,STONE:6)
Block(1,28,5,STONE:6)
Block(1,29,5,STONE:6)
Block(1,30,5,STONE:6)
Block(1,31,5,STONE:6)
Block(1,32,5,STONE:6)
Block(1,33,4,SMOOTH_STAIRS:6)
Block(1,33,5,STONE:6)
Block(1,34,1,STEP:13)
Block(1,34,4,SMOOTH_STAIRS:1)
Block(1,34,5,STONE:6)
Block(1,35,1,STONE:6)
Block(1,35,5,STONE:6)
Block(1,36,1,COBBLE_WALL:0)
Block(1,36,5,STONE:6)
Block(1,37,1,STONE:6)
Block(1,37,2,COBBLESTONE:0)
Block(1,37,3,COBBLESTONE:0)
Block(1,37,4,COBBLESTONE:0)
Block(1,37,5,STONE:6)
Block(1,38,1,STEP:0)
Block(1,38,5,STEP:0)
Block(2,0,4,COBBLESTONE:0)
Block(2,1,4,COBBLESTONE:0)
Block(2,2,4,COBBLESTONE:0)
Block(2,3,4,COBBLESTONE:0)
Block(2,4,4,COBBLESTONE:0)
Block(2,5,4,COBBLESTONE:0)
Block(2,6,4,COBBLESTONE:0)
Block(2,7,4,COBBLESTONE:0)
Block(2,8,4,COBBLESTONE:0)
Block(2,9,4,COBBLESTONE:0)
Block(2,10,4,COBBLESTONE:0)
Block(2,11,4,COBBLESTONE:0)
Block(2,12,4,COBBLESTONE:0)
Block(2,13,4,COBBLESTONE:0)
Block(2,14,4,COBBLESTONE:0)
Block(2,15,4,COBBLESTONE:0)
Block(2,16,4,COBBLESTONE:0)
Block(2,17,4,COBBLESTONE:0)
Block(2,18,4,COBBLESTONE:0)
Block(2,19,4,COBBLESTONE:0)
Block(2,20,4,COBBLESTONE:0)
Block(2,21,4,COBBLESTONE:0)
Block(2,22,4,COBBLESTONE:0)
Block(2,23,4,COBBLESTONE:0)
Block(2,24,4,COBBLESTONE:0)
Block(2,25,4,COBBLESTONE:0)
Block(2,26,4,COBBLESTONE:0)
Block(2,27,4,COBBLESTONE:0)
Block(2,28,4,COBBLESTONE:0)
Block(2,29,4,COBBLESTONE:0)
Block(2,30,4,COBBLESTONE:0)
Block(2,31,4,COBBLESTONE:0)
Block(2,32,4,COBBLESTONE:0)
Block(2,33,2,SMOOTH_STAIRS:6)
Block(2,33,3,SMOOTH_STAIRS:4)
Block(2,33,4,COBBLESTONE:0)
Block(2,34,2,STONE:6)
Block(2,34,3,SMOOTH_STAIRS:3)
Block(2,34,4,COBBLESTONE:0)
Block(2,35,2,SMOOTH_STAIRS:3)
Block(2,35,4,COBBLESTONE:0)
Block(2,36,2,STEP:13)
Block(2,36,4,COBBLESTONE:0)
Block(2,37,2,STONE:6)
Block(2,37,3,COBBLESTONE:0)
Block(2,37,4,COBBLESTONE:0)
Block(2,37,5,SMOOTH_STAIRS:5)
Block(2,38,2,STEP:0)
Block(3,0,3,STONE:6)
Block(3,0,5,COBBLESTONE:0)
Block(3,0,7,STONE:6)
Block(3,1,3,STONE:6)
Block(3,1,5,COBBLESTONE:0)
Block(3,1,7,STONE:6)
Block(3,2,3,STONE:6)
Block(3,2,5,COBBLESTONE:0)
Block(3,2,7,STONE:6)
Block(3,3,3,STONE:6)
Block(3,3,5,COBBLESTONE:0)
Block(3,3,7,STONE:6)
Block(3,4,3,STONE:6)
Block(3,4,5,COBBLESTONE:0)
Block(3,4,7,STONE:6)
Block(3,5,3,STONE:6)
Block(3,5,5,COBBLESTONE:0)
Block(3,5,7,STONE:6)
Block(3,6,3,STONE:6)
Block(3,6,5,COBBLESTONE:0)
Block(3,6,7,STONE:6)
Block(3,7,3,STONE:6)
Block(3,7,5,COBBLESTONE:0)
Block(3,7,7,STONE:6)
Block(3,8,3,STONE:6)
Block(3,8,5,COBBLESTONE:0)
Block(3,8,7,STONE:6)
Block(3,9,3,STONE:6)
Block(3,9,5,COBBLESTONE:0)
Block(3,9,7,STONE:6)
Block(3,10,3,STONE:6)
Block(3,10,5,COBBLESTONE:0)
Block(3,10,7,STONE:6)
Block(3,11,3,STONE:6)
Block(3,11,5,COBBLESTONE:0)
Block(3,11,7,STONE:6)
Block(3,12,3,STONE:6)
Block(3,12,5,COBBLESTONE:0)
Block(3,12,7,STONE:6)
Block(3,13,3,STONE:6)
Block(3,13,5,COBBLESTONE:0)
Block(3,13,7,STONE:6)
Block(3,14,3,STONE:6)
Block(3,14,5,COBBLESTONE:0)
Block(3,14,7,STONE:6)
Block(3,15,3,STONE:6)
Block(3,15,5,COBBLESTONE:0)
Block(3,15,7,STONE:6)
Block(3,16,3,STONE:6)
Block(3,16,5,COBBLESTONE:0)
Block(3,16,7,STONE:6)
Block(3,17,3,STONE:6)
Block(3,17,5,COBBLESTONE:0)
Block(3,17,7,STONE:6)
Block(3,18,3,STONE:6)
Block(3,18,5,COBBLESTONE:0)
Block(3,18,7,STONE:6)
Block(3,19,3,STONE:6)
Block(3,19,5,COBBLESTONE:0)
Block(3,19,7,STONE:6)
Block(3,20,3,STONE:6)
Block(3,20,5,COBBLESTONE:0)
Block(3,20,7,STONE:6)
Block(3,21,3,STONE:6)
Block(3,21,5,COBBLESTONE:0)
Block(3,21,7,STONE:6)
Block(3,22,3,STONE:6)
Block(3,22,5,COBBLESTONE:0)
Block(3,22,7,STONE:6)
Block(3,23,3,STONE:6)
Block(3,23,5,COBBLESTONE:0)
Block(3,23,7,STONE:6)
Block(3,24,3,STONE:6)
Block(3,24,5,COBBLESTONE:0)
Block(3,24,7,STONE:6)
Block(3,25,3,STONE:6)
Block(3,25,5,COBBLESTONE:0)
Block(3,25,7,STONE:6)
Block(3,26,3,STONE:6)
Block(3,26,5,COBBLESTONE:0)
Block(3,26,7,STONE:6)
Block(3,27,3,STONE:6)
Block(3,27,5,COBBLESTONE:0)
Block(3,27,7,STONE:6)
Block(3,28,3,STONE:6)
Block(3,28,5,COBBLESTONE:0)
Block(3,28,7,STONE:6)
Block(3,29,3,STONE:6)
Block(3,29,5,COBBLESTONE:0)
Block(3,29,7,STONE:6)
Block(3,30,3,STONE:6)
Block(3,30,5,COBBLESTONE:0)
Block(3,30,7,STONE:6)
Block(3,31,3,STONE:6)
Block(3,31,5,COBBLESTONE:0)
Block(3,31,7,STONE:6)
Block(3,32,3,STONE:6)
Block(3,32,5,COBBLESTONE:0)
Block(3,32,7,STONE:6)
Block(3,33,3,STONE:6)
Block(3,33,5,COBBLESTONE:0)
Block(3,33,7,STONE:6)
Block(3,34,3,STONE:6)
Block(3,34,5,COBBLESTONE:0)
Block(3,34,7,STONE:6)
Block(3,35,3,STONE:6)
Block(3,35,5,COBBLESTONE:0)
Block(3,35,7,STONE:6)
Block(3,36,3,STONE:6)
Block(3,36,7,STONE:6)
Block(3,37,3,STONE:6)
Block(3,37,7,STONE:6)
Block(3,38,3,STEP:0)
Block(3,38,7,STEP:0)
Block(4,0,6,COBBLESTONE:0)
Block(4,1,6,COBBLESTONE:0)
Block(4,2,6,COBBLESTONE:0)
Block(4,3,6,COBBLESTONE:0)
Block(4,4,6,COBBLESTONE:0)
Block(4,5,6,COBBLESTONE:0)
Block(4,6,6,COBBLESTONE:0)
Block(4,7,6,COBBLESTONE:0)
Block(4,8,6,COBBLESTONE:0)
Block(4,9,6,COBBLESTONE:0)
Block(4,10,6,COBBLESTONE:0)
Block(4,11,6,COBBLESTONE:0)
Block(4,12,6,COBBLESTONE:0)
Block(4,13,6,COBBLESTONE:0)
Block(4,14,6,COBBLESTONE:0)
Block(4,15,6,COBBLESTONE:0)
Block(4,16,6,COBBLESTONE:0)
Block(4,17,6,COBBLESTONE:0)
Block(4,18,6,COBBLESTONE:0)
Block(4,19,6,COBBLESTONE:0)
Block(4,20,6,COBBLESTONE:0)
Block(4,21,6,COBBLESTONE:0)
Block(4,22,6,COBBLESTONE:0)
Block(4,23,6,COBBLESTONE:0)
Block(4,24,6,COBBLESTONE:0)
Block(4,25,6,COBBLESTONE:0)
Block(4,26,6,COBBLESTONE:0)
Block(4,27,6,COBBLESTONE:0)
Block(4,28,6,COBBLESTONE:0)
Block(4,29,6,COBBLESTONE:0)
Block(4,30,6,COBBLESTONE:0)
Block(4,31,6,COBBLESTONE:0)
Block(4,32,6,COBBLESTONE:0)
Block(4,33,6,COBBLESTONE:0)
Block(4,33,7,SMOOTH_STAIRS:5)
Block(4,33,8,SMOOTH_STAIRS:7)
Block(4,34,6,COBBLESTONE:0)
Block(4,34,7,SMOOTH_STAIRS:2)
Block(4,34,8,STONE:6)
Block(4,35,8,SMOOTH_STAIRS:2)
Block(4,36,8,STEP:13)
Block(4,37,8,STONE:6)
Block(4,38,8,STEP:0)
Block(5,0,5,STONE:6)
Block(5,1,5,STONE:6)
Block(5,2,5,STONE:6)
Block(5,3,5,STONE:6)
Block(5,4,5,STONE:6)
Block(5,5,5,STONE:6)
Block(5,6,5,STONE:6)
Block(5,7,5,STONE:6)
Block(5,8,5,STONE:6)
Block(5,9,5,STONE:6)
Block(5,10,5,STONE:6)
Block(5,11,5,STONE:6)
Block(5,12,5,STONE:6)
Block(5,13,5,STONE:6)
Block(5,14,5,STONE:6)
Block(5,15,5,STONE:6)
Block(5,16,5,STONE:6)
Block(5,17,5,STONE:6)
Block(5,18,5,STONE:6)
Block(5,19,5,STONE:6)
Block(5,20,5,STONE:6)
Block(5,21,5,STONE:6)
Block(5,22,5,STONE:6)
Block(5,23,5,STONE:6)
Block(5,24,5,STONE:6)
Block(5,25,5,STONE:6)
Block(5,26,5,STONE:6)
Block(5,27,5,STONE:6)
Block(5,28,5,STONE:6)
Block(5,29,5,STONE:6)
Block(5,30,5,STONE:6)
Block(5,31,5,STONE:6)
Block(5,32,5,STONE:6)
Block(5,33,5,STONE:6)
Block(5,33,6,SMOOTH_STAIRS:7)
Block(5,34,5,STONE:6)
Block(5,34,6,SMOOTH_STAIRS:0)
Block(5,37,8,COBBLESTONE:0)
Block(6,33,6,SMOOTH_STAIRS:5)
Block(6,34,6,STONE:6)
Block(6,37,8,COBBLESTONE:0)
Block(7,34,7,STEP:13)
Block(7,35,7,STONE:6)
Block(7,36,7,COBBLE_WALL:0)
Block(7,37,7,STONE:6)
Block(7,37,8,COBBLESTONE:0)
Block(7,38,7,STEP:0)

#######################################################################
# +-----------------------------------------------------------------+ #
# |                             Branches                            | #
# +-----------------------------------------------------------------+ #
#######################################################################

Branch(0,0,-16,true,SpawnHexC15R14,NORTH,100.0,0)

#######################################################################
# +-----------------------------------------------------------------+ #
# |                             Entities                            | #
# +-----------------------------------------------------------------+ #
#######################################################################


#######################################################################
# +-----------------------------------------------------------------+ #
# |                            Particles                            | #
# +-----------------------------------------------------------------+ #
#######################################################################


#######################################################################
# +-----------------------------------------------------------------+ #
# |                             Spawners                            | #
# +-----------------------------------------------------------------+ #
#######################################################################


#######################################################################
# +-----------------------------------------------------------------+ #
# |                             ModData                             | #
# +-----------------------------------------------------------------+ #
#######################################################################

