
#######################################################################
# +-----------------------------------------------------------------+ #
# |                            BO4 object                           | #
# +-----------------------------------------------------------------+ #
#######################################################################

Author: NLBlackEagle

Description: No description given

SettingsMode: WriteDisable


#######################################################################
# +-----------------------------------------------------------------+ #
# |                          Main settings                          | #
# +-----------------------------------------------------------------+ #
#######################################################################

Frequency: 0

SpawnHeight: highestBlock

UseCenterForHighestBlock: true

##############################
# Height Limits for the BO4. #
##############################

MinHeight: 0

MaxHeight: 255

InheritBO3: 

InheritBO3Rotation: NORTH

OverrideChildSettings: true

OverrideParentHeight: false

CanOverride: false

BranchFrequency: 0

BranchFrequencyGroup: 

MustBeBelowOther: false

MustBeInside: 

CannotBeInside: 

ReplacesBO3: 

MustBeInsideWorldBorders: false

CanSpawnOnWater: true

SpawnOnWaterOnly: false

SpawnUnderWater: false

SpawnAtWaterLevel: false

HeightOffset: 0

RemoveAir: false

ReplaceAbove: 

ReplaceBelow: 

ReplaceWithBiomeBlocks: false

ReplaceWithSurfaceBlock: 

ReplaceWithGroundBlock: 

ReplaceWithStoneBlock: 

SmoothRadius: 0

SmoothHeightOffset: 0

SmoothStartTop: false

SmoothStartWood: false

SmoothingSurfaceBlock: 

SmoothingGroundBlock: 

BO3Group: 

IsSpawnPoint: false

DoReplaceBlocks: false


#######################################################################
# +-----------------------------------------------------------------+ #
# |                              Blocks                             | #
# +-----------------------------------------------------------------+ #
#######################################################################

Block(-8,44,-7,STONE:3)
Block(-8,45,-7,STONE:3)
Block(-8,45,-6,STONE:3)
Block(-8,46,-7,STONE:3)
Block(-8,46,-6,STONE:3)
Block(-8,46,-5,STONE:3)
Block(-8,47,-7,STONE:3)
Block(-8,47,-6,STONE:3)
Block(-8,47,-5,STONE:3)
Block(-8,47,-4,STONE:3)
Block(-8,48,-7,STONE:3)
Block(-8,48,-6,STONE:3)
Block(-8,48,-5,STONE:3)
Block(-8,48,-4,STONE:3)
Block(-8,49,-7,STONE:3)
Block(-8,49,-6,STONE:3)
Block(-8,49,-5,STONE:3)
Block(-8,49,-4,STONE:3)
Block(-8,50,-7,STONE:3)
Block(-8,50,-6,STONE:3)
Block(-8,50,-5,STONE:3)
Block(-8,50,-4,STONE:3)
Block(-8,51,-7,STONE:3)
Block(-8,51,-6,STONE:3)
Block(-8,51,-5,STONE:3)
Block(-8,51,-4,STONE:3)
Block(-8,52,-7,STONE:3)
Block(-8,52,-6,STONE:3)
Block(-8,52,-5,STONE:3)
Block(-8,52,-4,STONE:3)
Block(-8,53,-7,STONE:3)
Block(-8,53,-6,STONE:3)
Block(-8,53,-5,STONE:3)
Block(-8,53,-4,STONE:5)
Block(-8,54,-7,STONE:3)
Block(-8,54,-6,STONE:3)
Block(-8,54,-5,STONE:5)
Block(-8,55,-7,STONE:5)
Block(-8,55,-6,STONE:5)
Block(-7,43,-7,OBSIDIAN:0)
Block(-7,44,-7,STONE:3)
Block(-7,45,-7,STONE:3)
Block(-7,45,-6,STONE:3)
Block(-7,46,-7,STONE:3)
Block(-7,46,-6,STONE:3)
Block(-7,46,-5,STONE:3)
Block(-7,47,-7,STONE:3)
Block(-7,47,-6,STONE:3)
Block(-7,47,-5,STONE:3)
Block(-7,47,-4,STONE:3)
Block(-7,48,-7,STONE:3)
Block(-7,48,-6,STONE:3)
Block(-7,48,-5,STONE:3)
Block(-7,48,-4,STONE:3)
Block(-7,49,-7,STONE:3)
Block(-7,49,-6,STONE:3)
Block(-7,49,-5,STONE:3)
Block(-7,49,-4,STONE:3)
Block(-7,50,-7,STONE:3)
Block(-7,50,-6,STONE:3)
Block(-7,50,-5,STONE:3)
Block(-7,50,-4,STONE:3)
Block(-7,51,-7,STONE:3)
Block(-7,51,-6,STONE:3)
Block(-7,51,-5,STONE:3)
Block(-7,51,-4,STONE:3)
Block(-7,52,-7,STONE:3)
Block(-7,52,-6,STONE:3)
Block(-7,52,-5,STONE:3)
Block(-7,52,-4,STONE:3)
Block(-7,53,-7,STONE:3)
Block(-7,53,-6,STONE:3)
Block(-7,53,-5,STONE:3)
Block(-7,53,-4,STONE:5)
Block(-7,54,-7,STONE:3)
Block(-7,54,-6,STONE:3)
Block(-7,54,-5,STONE:5)
Block(-7,55,-7,STONE:5)
Block(-7,55,-6,STONE:5)
Block(-6,43,-7,OBSIDIAN:0)
Block(-6,44,-7,STONE:3)
Block(-6,44,-6,STONE:3)
Block(-6,45,-7,STONE:3)
Block(-6,45,-6,STONE:3)
Block(-6,46,-7,STONE:3)
Block(-6,46,-6,STONE:3)
Block(-6,46,-5,STONE:3)
Block(-6,47,-7,STONE:3)
Block(-6,47,-6,STONE:3)
Block(-6,47,-5,STONE:3)
Block(-6,47,-4,STONE:3)
Block(-6,48,-7,STONE:3)
Block(-6,48,-6,STONE:3)
Block(-6,48,-5,STONE:3)
Block(-6,48,-4,STONE:3)
Block(-6,49,-7,STONE:3)
Block(-6,49,-6,STONE:3)
Block(-6,49,-5,STONE:3)
Block(-6,49,-4,STONE:3)
Block(-6,50,-7,STONE:3)
Block(-6,50,-6,STONE:3)
Block(-6,50,-5,STONE:3)
Block(-6,50,-4,STONE:3)
Block(-6,51,-7,STONE:3)
Block(-6,51,-6,STONE:3)
Block(-6,51,-5,STONE:3)
Block(-6,51,-4,STONE:3)
Block(-6,52,-7,OBSIDIAN:0)
Block(-6,52,-6,STONE:3)
Block(-6,52,-5,STONE:3)
Block(-6,52,-4,STONE:3)
Block(-6,53,-7,STONE:3)
Block(-6,53,-6,OBSIDIAN:0)
Block(-6,53,-5,STONE:3)
Block(-6,53,-4,STONE:5)
Block(-6,54,-7,STONE:3)
Block(-6,54,-6,STONE:3)
Block(-6,54,-5,STONE:5)
Block(-6,55,-7,STONE:5)
Block(-6,55,-6,STONE:5)
Block(-5,44,-7,STONE:3)
Block(-5,45,-7,STONE:3)
Block(-5,45,-6,STONE:3)
Block(-5,46,-7,STONE:3)
Block(-5,46,-6,STONE:3)
Block(-5,46,-5,STONE:3)
Block(-5,47,-7,STONE:3)
Block(-5,47,-6,STONE:3)
Block(-5,47,-5,STONE:3)
Block(-5,48,-7,STONE:3)
Block(-5,48,-6,STONE:3)
Block(-5,48,-5,STONE:3)
Block(-5,48,-4,STONE:3)
Block(-5,49,-7,STONE:3)
Block(-5,49,-6,STONE:3)
Block(-5,49,-5,STONE:3)
Block(-5,49,-4,STONE:3)
Block(-5,50,-7,STONE:3)
Block(-5,50,-6,STONE:3)
Block(-5,50,-5,STONE:3)
Block(-5,50,-4,STONE:3)
Block(-5,51,-7,STONE:3)
Block(-5,51,-6,STONE:3)
Block(-5,51,-5,STONE:3)
Block(-5,51,-4,STONE:3)
Block(-5,52,-7,OBSIDIAN:0)
Block(-5,52,-6,STONE:3)
Block(-5,52,-5,STONE:3)
Block(-5,52,-4,STONE:5)
Block(-5,53,-7,OBSIDIAN:0)
Block(-5,53,-6,STONE:3)
Block(-5,53,-5,STONE:3)
Block(-5,54,-7,STONE:3)
Block(-5,54,-6,STONE:5)
Block(-5,54,-5,STONE:5)
Block(-5,55,-7,STONE:5)
Block(-4,45,-7,STONE:3)
Block(-4,46,-7,STONE:3)
Block(-4,46,-6,STONE:3)
Block(-4,46,-5,STONE:3)
Block(-4,47,-7,STONE:3)
Block(-4,47,-6,STONE:3)
Block(-4,47,-5,STONE:3)
Block(-4,48,-7,STONE:3)
Block(-4,48,-6,STONE:3)
Block(-4,48,-5,STONE:3)
Block(-4,48,-4,STONE:3)
Block(-4,49,-7,STONE:3)
Block(-4,49,-6,STONE:3)
Block(-4,49,-5,STONE:3)
Block(-4,49,-4,STONE:3)
Block(-4,50,-7,STONE:3)
Block(-4,50,-6,STONE:3)
Block(-4,50,-5,STONE:3)
Block(-4,50,-4,STONE:3)
Block(-4,51,-7,STONE:3)
Block(-4,51,-6,STONE:3)
Block(-4,51,-5,STONE:3)
Block(-4,51,-4,STONE:5)
Block(-4,52,-7,STONE:3)
Block(-4,52,-6,STONE:3)
Block(-4,52,-5,STONE:3)
Block(-4,53,-7,STONE:3)
Block(-4,53,-6,STONE:3)
Block(-4,53,-5,STONE:5)
Block(-4,54,-7,STONE:5)
Block(-4,54,-6,STONE:5)
Block(-3,44,-7,STONE:3)
Block(-3,45,-7,STONE:3)
Block(-3,46,-7,STONE:3)
Block(-3,46,-6,STONE:3)
Block(-3,47,-7,STONE:3)
Block(-3,47,-6,STONE:3)
Block(-3,47,-5,STONE:3)
Block(-3,48,-7,STONE:3)
Block(-3,48,-6,STONE:3)
Block(-3,48,-5,STONE:3)
Block(-3,49,-7,STONE:3)
Block(-3,49,-6,STONE:3)
Block(-3,49,-5,STONE:3)
Block(-3,49,-4,STONE:3)
Block(-3,50,-7,STONE:3)
Block(-3,50,-6,STONE:3)
Block(-3,50,-5,STONE:3)
Block(-3,50,-4,STONE:5)
Block(-3,51,-7,STONE:3)
Block(-3,51,-6,STONE:3)
Block(-3,51,-5,STONE:3)
Block(-3,52,-7,STONE:3)
Block(-3,52,-6,STONE:3)
Block(-3,52,-5,STONE:5)
Block(-3,53,-7,STONE:3)
Block(-3,53,-6,STONE:5)
Block(-3,54,-7,STONE:5)
Block(-2,41,-7,OBSIDIAN:0)
Block(-2,42,-7,STONE:3)
Block(-2,43,-7,STONE:3)
Block(-2,44,-7,STONE:3)
Block(-2,45,-7,STONE:3)
Block(-2,45,-6,STONE:3)
Block(-2,46,-7,STONE:3)
Block(-2,46,-6,STONE:3)
Block(-2,47,-7,STONE:3)
Block(-2,47,-6,STONE:3)
Block(-2,47,-5,STONE:3)
Block(-2,48,-7,STONE:3)
Block(-2,48,-6,STONE:3)
Block(-2,48,-5,STONE:3)
Block(-2,49,-7,STONE:3)
Block(-2,49,-6,STONE:3)
Block(-2,49,-5,STONE:3)
Block(-2,50,-7,STONE:3)
Block(-2,50,-6,STONE:3)
Block(-2,50,-5,STONE:3)
Block(-2,51,-7,STONE:3)
Block(-2,51,-6,STONE:3)
Block(-2,51,-5,STONE:3)
Block(-2,52,-7,STONE:3)
Block(-2,52,-6,STONE:3)
Block(-2,52,-5,STONE:5)
Block(-2,53,-7,STONE:3)
Block(-2,53,-6,STONE:5)
Block(-2,54,-7,STONE:5)
Block(-1,40,-7,OBSIDIAN:0)
Block(-1,41,-7,OBSIDIAN:0)
Block(-1,42,-7,STONE:3)
Block(-1,43,-7,STONE:3)
Block(-1,44,-7,STONE:3)
Block(-1,44,-6,STONE:3)
Block(-1,45,-7,STONE:3)
Block(-1,45,-6,STONE:3)
Block(-1,46,-7,STONE:3)
Block(-1,46,-6,STONE:3)
Block(-1,46,-5,STONE:3)
Block(-1,47,-7,STONE:3)
Block(-1,47,-6,STONE:3)
Block(-1,47,-5,STONE:3)
Block(-1,48,-7,STONE:3)
Block(-1,48,-6,STONE:3)
Block(-1,48,-5,STONE:3)
Block(-1,49,-7,STONE:3)
Block(-1,49,-6,STONE:3)
Block(-1,49,-5,STONE:3)
Block(-1,50,-7,STONE:3)
Block(-1,50,-6,STONE:3)
Block(-1,50,-5,STONE:5)
Block(-1,51,-7,STONE:3)
Block(-1,51,-6,STONE:3)
Block(-1,52,-7,STONE:3)
Block(-1,52,-6,STONE:5)
Block(-1,53,-7,STONE:3)
Block(-1,54,-7,STONE:3)
Block(-1,55,-7,STONE:5)
Block(0,40,-7,OBSIDIAN:0)
Block(0,41,-7,STONE:3)
Block(0,41,-6,STONE:3)
Block(0,42,-7,STONE:3)
Block(0,42,-6,STONE:3)
Block(0,43,-7,STONE:3)
Block(0,43,-6,STONE:3)
Block(0,44,-7,STONE:3)
Block(0,44,-6,STONE:3)
Block(0,45,-7,STONE:3)
Block(0,45,-6,STONE:3)
Block(0,45,-5,STONE:3)
Block(0,46,-7,STONE:3)
Block(0,46,-6,STONE:3)
Block(0,46,-5,STONE:3)
Block(0,47,-7,STONE:3)
Block(0,47,-6,STONE:3)
Block(0,47,-5,STONE:3)
Block(0,47,-4,STONE:3)
Block(0,48,-7,STONE:3)
Block(0,48,-6,STONE:3)
Block(0,48,-5,STONE:3)
Block(0,48,-4,STONE:3)
Block(0,49,-7,STONE:3)
Block(0,49,-6,STONE:3)
Block(0,49,-5,STONE:3)
Block(0,49,-4,STONE:5)
Block(0,50,-7,STONE:3)
Block(0,50,-6,STONE:3)
Block(0,50,-5,STONE:3)
Block(0,51,-7,STONE:3)
Block(0,51,-6,STONE:3)
Block(0,51,-5,STONE:5)
Block(0,52,-7,STONE:3)
Block(0,52,-6,STONE:3)
Block(0,53,-7,STONE:3)
Block(0,54,-7,STONE:3)
Block(0,54,-6,STONE:3)
Block(0,55,-7,STONE:3)
Block(0,55,-6,STONE:5)
Block(0,56,-7,STONE:5)
Block(1,35,-7,OBSIDIAN:0)
Block(1,36,-7,OBSIDIAN:0)
Block(1,37,-7,OBSIDIAN:0)
Block(1,38,-7,OBSIDIAN:0)
Block(1,39,-7,OBSIDIAN:0)
Block(1,39,-6,STONE:3)
Block(1,40,-7,STONE:3)
Block(1,40,-6,STONE:3)
Block(1,40,-5,STONE:3)
Block(1,41,-7,STONE:3)
Block(1,41,-6,STONE:3)
Block(1,41,-5,STONE:3)
Block(1,42,-7,STONE:3)
Block(1,42,-6,STONE:3)
Block(1,42,-5,STONE:3)
Block(1,43,-7,STONE:3)
Block(1,43,-6,STONE:3)
Block(1,43,-5,STONE:3)
Block(1,44,-7,STONE:3)
Block(1,44,-6,STONE:3)
Block(1,44,-5,STONE:3)
Block(1,45,-7,STONE:3)
Block(1,45,-6,STONE:3)
Block(1,45,-5,STONE:3)
Block(1,46,-7,STONE:3)
Block(1,46,-6,STONE:3)
Block(1,46,-5,STONE:3)
Block(1,46,-4,STONE:3)
Block(1,47,-7,STONE:3)
Block(1,47,-6,STONE:3)
Block(1,47,-5,STONE:3)
Block(1,47,-4,STONE:3)
Block(1,48,-7,STONE:3)
Block(1,48,-6,STONE:3)
Block(1,48,-5,STONE:3)
Block(1,48,-4,STONE:3)
Block(1,49,-7,STONE:3)
Block(1,49,-6,STONE:3)
Block(1,49,-5,STONE:3)
Block(1,49,-4,STONE:3)
Block(1,50,-7,STONE:3)
Block(1,50,-6,STONE:3)
Block(1,50,-5,STONE:3)
Block(1,50,-4,STONE:5)
Block(1,51,-7,STONE:3)
Block(1,51,-6,STONE:3)
Block(1,51,-5,STONE:3)
Block(1,52,-7,STONE:3)
Block(1,52,-6,STONE:3)
Block(1,52,-5,STONE:3)
Block(1,53,-7,STONE:3)
Block(1,53,-6,STONE:3)
Block(1,53,-5,STONE:3)
Block(1,54,-7,STONE:3)
Block(1,54,-6,STONE:3)
Block(1,54,-5,STONE:3)
Block(1,55,-7,STONE:3)
Block(1,55,-6,STONE:3)
Block(1,55,-5,STONE:5)
Block(1,56,-7,STONE:3)
Block(1,56,-6,STONE:3)
Block(1,57,-7,STONE:3)
Block(1,57,-6,STONE:5)
Block(1,58,-7,STONE:5)
Block(2,34,-7,OBSIDIAN:0)
Block(2,35,-7,OBSIDIAN:0)
Block(2,36,-7,OBSIDIAN:0)
Block(2,36,-6,OBSIDIAN:0)
Block(2,37,-7,OBSIDIAN:0)
Block(2,37,-6,OBSIDIAN:0)
Block(2,38,-7,OBSIDIAN:0)
Block(2,38,-6,STONE:3)
Block(2,38,-5,STONE:3)
Block(2,39,-7,STONE:3)
Block(2,39,-6,STONE:3)
Block(2,39,-5,STONE:3)
Block(2,40,-7,STONE:3)
Block(2,40,-6,STONE:3)
Block(2,40,-5,STONE:3)
Block(2,40,-4,STONE:3)
Block(2,41,-7,STONE:3)
Block(2,41,-6,STONE:3)
Block(2,41,-5,STONE:3)
Block(2,41,-4,STONE:3)
Block(2,42,-7,STONE:3)
Block(2,42,-6,STONE:3)
Block(2,42,-5,STONE:3)
Block(2,42,-4,STONE:3)
Block(2,43,-7,STONE:3)
Block(2,43,-6,STONE:3)
Block(2,43,-5,STONE:3)
Block(2,43,-4,STONE:3)
Block(2,44,-7,STONE:3)
Block(2,44,-6,STONE:3)
Block(2,44,-5,STONE:3)
Block(2,45,-7,STONE:3)
Block(2,45,-6,STONE:3)
Block(2,45,-5,STONE:3)
Block(2,45,-4,STONE:3)
Block(2,46,-7,STONE:3)
Block(2,46,-6,STONE:3)
Block(2,46,-5,STONE:3)
Block(2,46,-4,STONE:3)
Block(2,47,-7,STONE:3)
Block(2,47,-6,STONE:3)
Block(2,47,-5,STONE:3)
Block(2,47,-4,STONE:3)
Block(2,48,-7,STONE:3)
Block(2,48,-6,STONE:3)
Block(2,48,-5,STONE:3)
Block(2,48,-4,STONE:3)
Block(2,49,-7,STONE:3)
Block(2,49,-6,STONE:3)
Block(2,49,-5,STONE:3)
Block(2,49,-4,STONE:3)
Block(2,50,-7,STONE:3)
Block(2,50,-6,STONE:3)
Block(2,50,-5,STONE:3)
Block(2,50,-4,STONE:3)
Block(2,51,-7,STONE:3)
Block(2,51,-6,STONE:3)
Block(2,51,-5,STONE:3)
Block(2,51,-4,STONE:3)
Block(2,52,-7,STONE:3)
Block(2,52,-6,STONE:3)
Block(2,52,-5,STONE:3)
Block(2,53,-7,STONE:3)
Block(2,53,-6,STONE:3)
Block(2,53,-5,STONE:3)
Block(2,54,-7,STONE:3)
Block(2,54,-6,STONE:3)
Block(2,54,-5,STONE:3)
Block(2,54,-4,STONE:5)
Block(2,55,-7,STONE:3)
Block(2,55,-6,STONE:3)
Block(2,55,-5,STONE:3)
Block(2,56,-7,STONE:3)
Block(2,56,-6,STONE:3)
Block(2,56,-5,STONE:3)
Block(2,57,-7,STONE:3)
Block(2,57,-6,STONE:3)
Block(2,57,-5,STONE:5)
Block(2,58,-7,STONE:3)
Block(2,58,-6,STONE:5)
Block(2,59,-7,STONE:5)
Block(3,33,-7,OBSIDIAN:0)
Block(3,34,-7,OBSIDIAN:0)
Block(3,34,-6,OBSIDIAN:0)
Block(3,35,-7,OBSIDIAN:0)
Block(3,35,-6,OBSIDIAN:0)
Block(3,35,-5,OBSIDIAN:0)
Block(3,36,-7,OBSIDIAN:0)
Block(3,36,-6,OBSIDIAN:0)
Block(3,36,-5,OBSIDIAN:0)
Block(3,37,-7,OBSIDIAN:0)
Block(3,37,-6,OBSIDIAN:0)
Block(3,37,-5,STONE:3)
Block(3,38,-7,OBSIDIAN:0)
Block(3,38,-6,STONE:3)
Block(3,38,-5,STONE:3)
Block(3,39,-7,STONE:3)
Block(3,39,-6,STONE:3)
Block(3,39,-5,STONE:3)
Block(3,39,-4,STONE:3)
Block(3,40,-7,STONE:3)
Block(3,40,-6,STONE:3)
Block(3,40,-5,STONE:3)
Block(3,40,-4,STONE:3)
Block(3,41,-7,STONE:3)
Block(3,41,-6,STONE:3)
Block(3,41,-5,STONE:3)
Block(3,41,-4,STONE:3)
Block(3,42,-7,STONE:3)
Block(3,42,-6,STONE:3)
Block(3,42,-5,STONE:3)
Block(3,42,-4,STONE:3)
Block(3,43,-7,STONE:3)
Block(3,43,-6,STONE:3)
Block(3,43,-5,STONE:3)
Block(3,43,-4,STONE:3)
Block(3,44,-7,STONE:3)
Block(3,44,-6,STONE:3)
Block(3,44,-5,STONE:3)
Block(3,44,-4,STONE:3)
Block(3,45,-7,STONE:3)
Block(3,45,-6,STONE:3)
Block(3,45,-5,STONE:3)
Block(3,45,-4,STONE:3)
Block(3,46,-7,STONE:3)
Block(3,46,-6,STONE:3)
Block(3,46,-5,STONE:3)
Block(3,46,-4,STONE:3)
Block(3,47,-7,STONE:3)
Block(3,47,-6,STONE:3)
Block(3,47,-5,STONE:3)
Block(3,47,-4,STONE:3)
Block(3,48,-7,STONE:3)
Block(3,48,-6,STONE:3)
Block(3,48,-5,STONE:3)
Block(3,48,-4,STONE:3)
Block(3,49,-7,STONE:3)
Block(3,49,-6,STONE:3)
Block(3,49,-5,STONE:3)
Block(3,49,-4,STONE:3)
Block(3,50,-7,STONE:3)
Block(3,50,-6,STONE:3)
Block(3,50,-5,STONE:3)
Block(3,50,-4,STONE:3)
Block(3,51,-7,STONE:3)
Block(3,51,-6,STONE:3)
Block(3,51,-5,STONE:3)
Block(3,51,-4,STONE:3)
Block(3,52,-7,STONE:3)
Block(3,52,-6,STONE:3)
Block(3,52,-5,STONE:3)
Block(3,53,-7,STONE:3)
Block(3,53,-6,STONE:3)
Block(3,53,-5,STONE:3)
Block(3,53,-4,STONE:3)
Block(3,54,-7,STONE:3)
Block(3,54,-6,STONE:3)
Block(3,54,-5,STONE:3)
Block(3,54,-4,STONE:3)
Block(3,55,-7,STONE:3)
Block(3,55,-6,STONE:3)
Block(3,55,-5,STONE:3)
Block(3,55,-4,STONE:3)
Block(3,56,-7,STONE:3)
Block(3,56,-6,STONE:3)
Block(3,56,-5,STONE:3)
Block(3,56,-4,STONE:5)
Block(3,57,-7,STONE:3)
Block(3,57,-6,STONE:3)
Block(3,57,-5,STONE:3)
Block(3,58,-7,STONE:3)
Block(3,58,-6,STONE:3)
Block(3,58,-5,STONE:5)
Block(3,59,-7,STONE:5)
Block(3,59,-6,STONE:5)
Block(4,33,-7,OBSIDIAN:0)
Block(4,33,-6,OBSIDIAN:0)
Block(4,34,-7,OBSIDIAN:0)
Block(4,34,-6,OBSIDIAN:0)
Block(4,34,-5,OBSIDIAN:0)
Block(4,35,-7,OBSIDIAN:0)
Block(4,35,-6,OBSIDIAN:0)
Block(4,35,-5,OBSIDIAN:0)
Block(4,36,-7,OBSIDIAN:0)
Block(4,36,-6,OBSIDIAN:0)
Block(4,36,-5,OBSIDIAN:0)
Block(4,37,-7,OBSIDIAN:0)
Block(4,37,-6,OBSIDIAN:0)
Block(4,37,-5,STONE:3)
Block(4,38,-7,STONE:3)
Block(4,38,-6,STONE:3)
Block(4,38,-5,STONE:3)
Block(4,38,-4,STONE:3)
Block(4,39,-7,STONE:3)
Block(4,39,-6,STONE:3)
Block(4,39,-5,STONE:3)
Block(4,39,-4,STONE:3)
Block(4,40,-7,STONE:3)
Block(4,40,-6,STONE:3)
Block(4,40,-5,STONE:3)
Block(4,40,-4,STONE:3)
Block(4,41,-7,STONE:3)
Block(4,41,-6,STONE:3)
Block(4,41,-5,STONE:3)
Block(4,41,-4,STONE:3)
Block(4,42,-7,STONE:3)
Block(4,42,-6,STONE:3)
Block(4,42,-5,STONE:3)
Block(4,42,-4,STONE:3)
Block(4,43,-7,STONE:3)
Block(4,43,-6,STONE:3)
Block(4,43,-5,STONE:3)
Block(4,43,-4,STONE:3)
Block(4,44,-7,STONE:3)
Block(4,44,-6,STONE:3)
Block(4,44,-5,STONE:3)
Block(4,44,-4,STONE:3)
Block(4,45,-7,STONE:3)
Block(4,45,-6,STONE:3)
Block(4,45,-5,STONE:3)
Block(4,45,-4,STONE:3)
Block(4,46,-7,STONE:3)
Block(4,46,-6,STONE:3)
Block(4,46,-5,STONE:3)
Block(4,46,-4,STONE:3)
Block(4,47,-7,STONE:3)
Block(4,47,-6,STONE:3)
Block(4,47,-5,STONE:3)
Block(4,47,-4,STONE:3)
Block(4,48,-7,STONE:3)
Block(4,48,-6,STONE:3)
Block(4,48,-5,STONE:3)
Block(4,48,-4,STONE:3)
Block(4,49,-7,STONE:3)
Block(4,49,-6,STONE:3)
Block(4,49,-5,STONE:3)
Block(4,49,-4,STONE:3)
Block(4,50,-7,STONE:3)
Block(4,50,-6,STONE:3)
Block(4,50,-5,STONE:3)
Block(4,50,-4,STONE:3)
Block(4,50,-3,STONE:5)
Block(4,51,-7,STONE:3)
Block(4,51,-6,STONE:3)
Block(4,51,-5,STONE:3)
Block(4,51,-4,STONE:3)
Block(4,52,-7,STONE:3)
Block(4,52,-6,STONE:3)
Block(4,52,-5,STONE:3)
Block(4,52,-4,STONE:3)
Block(4,53,-7,STONE:3)
Block(4,53,-6,STONE:3)
Block(4,53,-5,STONE:3)
Block(4,53,-4,STONE:3)
Block(4,54,-7,STONE:3)
Block(4,54,-6,STONE:3)
Block(4,54,-5,STONE:3)
Block(4,54,-4,STONE:3)
Block(4,55,-7,STONE:3)
Block(4,55,-6,STONE:3)
Block(4,55,-5,STONE:3)
Block(4,55,-4,STONE:3)
Block(4,56,-7,STONE:3)
Block(4,56,-6,STONE:3)
Block(4,56,-5,STONE:3)
Block(4,56,-4,STONE:3)
Block(4,57,-7,STONE:3)
Block(4,57,-6,STONE:3)
Block(4,57,-5,STONE:3)
Block(4,57,-4,STONE:5)
Block(4,58,-7,STONE:3)
Block(4,58,-6,STONE:3)
Block(4,58,-5,STONE:5)
Block(4,59,-7,STONE:3)
Block(4,59,-6,STONE:5)
Block(4,60,-7,STONE:5)
Block(5,32,-7,OBSIDIAN:0)
Block(5,33,-7,OBSIDIAN:0)
Block(5,33,-6,OBSIDIAN:0)
Block(5,33,-5,OBSIDIAN:0)
Block(5,34,-7,OBSIDIAN:0)
Block(5,34,-6,OBSIDIAN:0)
Block(5,34,-5,OBSIDIAN:0)
Block(5,35,-7,OBSIDIAN:0)
Block(5,35,-6,OBSIDIAN:0)
Block(5,35,-5,OBSIDIAN:0)
Block(5,36,-7,OBSIDIAN:0)
Block(5,36,-6,OBSIDIAN:0)
Block(5,36,-5,STONE:3)
Block(5,37,-7,OBSIDIAN:0)
Block(5,37,-6,STONE:3)
Block(5,37,-5,STONE:3)
Block(5,38,-7,STONE:3)
Block(5,38,-6,STONE:3)
Block(5,38,-5,STONE:3)
Block(5,38,-4,STONE:3)
Block(5,39,-7,STONE:3)
Block(5,39,-6,STONE:3)
Block(5,39,-5,STONE:3)
Block(5,39,-4,STONE:3)
Block(5,40,-7,STONE:3)
Block(5,40,-6,STONE:3)
Block(5,40,-5,STONE:3)
Block(5,40,-4,STONE:3)
Block(5,41,-7,STONE:3)
Block(5,41,-6,STONE:3)
Block(5,41,-5,STONE:3)
Block(5,41,-4,STONE:3)
Block(5,42,-7,STONE:3)
Block(5,42,-6,STONE:3)
Block(5,42,-5,STONE:3)
Block(5,42,-4,STONE:3)
Block(5,43,-7,OBSIDIAN:0)
Block(5,43,-6,STONE:3)
Block(5,43,-5,STONE:3)
Block(5,43,-4,STONE:3)
Block(5,44,-7,STONE:3)
Block(5,44,-6,STONE:3)
Block(5,44,-5,STONE:3)
Block(5,44,-4,STONE:3)
Block(5,45,-7,STONE:3)
Block(5,45,-6,STONE:3)
Block(5,45,-5,STONE:3)
Block(5,45,-4,STONE:3)
Block(5,45,-3,STONE:3)
Block(5,46,-7,STONE:3)
Block(5,46,-6,STONE:3)
Block(5,46,-5,STONE:3)
Block(5,46,-4,STONE:3)
Block(5,46,-3,STONE:3)
Block(5,47,-7,STONE:3)
Block(5,47,-6,STONE:3)
Block(5,47,-5,STONE:3)
Block(5,47,-4,STONE:3)
Block(5,47,-3,STONE:3)
Block(5,48,-7,STONE:3)
Block(5,48,-6,STONE:3)
Block(5,48,-5,STONE:3)
Block(5,48,-4,STONE:3)
Block(5,48,-3,STONE:3)
Block(5,48,-2,STONE:3)
Block(5,49,-7,OBSIDIAN:0)
Block(5,49,-6,STONE:3)
Block(5,49,-5,STONE:3)
Block(5,49,-4,STONE:3)
Block(5,49,-3,STONE:3)
Block(5,49,-2,STONE:5)
Block(5,50,-7,OBSIDIAN:0)
Block(5,50,-6,STONE:3)
Block(5,50,-5,STONE:3)
Block(5,50,-4,STONE:3)
Block(5,50,-3,STONE:3)
Block(5,51,-7,STONE:3)
Block(5,51,-6,STONE:3)
Block(5,51,-5,STONE:3)
Block(5,51,-4,STONE:3)
Block(5,51,-3,STONE:3)
Block(5,52,-7,STONE:3)
Block(5,52,-6,STONE:3)
Block(5,52,-5,STONE:3)
Block(5,52,-4,STONE:3)
Block(5,53,-7,STONE:3)
Block(5,53,-6,STONE:3)
Block(5,53,-5,STONE:3)
Block(5,53,-4,STONE:3)
Block(5,53,-3,STONE:3)
Block(5,54,-7,STONE:3)
Block(5,54,-6,STONE:3)
Block(5,54,-5,STONE:3)
Block(5,54,-4,STONE:3)
Block(5,54,-3,STONE:5)
Block(5,55,-7,STONE:3)
Block(5,55,-6,STONE:3)
Block(5,55,-5,STONE:3)
Block(5,55,-4,STONE:3)
Block(5,56,-7,STONE:3)
Block(5,56,-6,STONE:3)
Block(5,56,-5,STONE:3)
Block(5,56,-4,STONE:3)
Block(5,57,-7,STONE:3)
Block(5,57,-6,STONE:3)
Block(5,57,-5,STONE:3)
Block(5,57,-4,STONE:5)
Block(5,58,-7,STONE:3)
Block(5,58,-6,STONE:3)
Block(5,58,-5,STONE:5)
Block(5,59,-7,STONE:3)
Block(5,59,-6,STONE:5)
Block(5,60,-7,STONE:5)
Block(6,33,-7,OBSIDIAN:0)
Block(6,33,-6,OBSIDIAN:0)
Block(6,34,-7,OBSIDIAN:0)
Block(6,34,-6,OBSIDIAN:0)
Block(6,34,-5,STONE:3)
Block(6,35,-7,OBSIDIAN:0)
Block(6,35,-6,OBSIDIAN:0)
Block(6,35,-5,STONE:3)
Block(6,36,-7,OBSIDIAN:0)
Block(6,36,-6,STONE:3)
Block(6,36,-5,STONE:3)
Block(6,37,-7,STONE:3)
Block(6,37,-6,STONE:3)
Block(6,37,-5,STONE:3)
Block(6,38,-7,STONE:3)
Block(6,38,-6,STONE:3)
Block(6,38,-5,STONE:3)
Block(6,38,-4,STONE:3)
Block(6,39,-7,STONE:3)
Block(6,39,-6,STONE:3)
Block(6,39,-5,STONE:3)
Block(6,39,-4,STONE:3)
Block(6,40,-7,STONE:3)
Block(6,40,-6,STONE:3)
Block(6,40,-5,STONE:3)
Block(6,40,-4,STONE:3)
Block(6,40,-3,STONE:3)
Block(6,41,-7,STONE:3)
Block(6,41,-6,STONE:3)
Block(6,41,-5,STONE:3)
Block(6,41,-4,STONE:3)
Block(6,41,-3,STONE:3)
Block(6,42,-7,STONE:3)
Block(6,42,-6,STONE:3)
Block(6,42,-5,STONE:3)
Block(6,42,-4,STONE:3)
Block(6,42,-3,STONE:3)
Block(6,43,-7,OBSIDIAN:0)
Block(6,43,-6,STONE:3)
Block(6,43,-5,STONE:3)
Block(6,43,-4,STONE:3)
Block(6,43,-3,STONE:3)
Block(6,44,-7,STONE:3)
Block(6,44,-6,STONE:3)
Block(6,44,-5,STONE:3)
Block(6,44,-4,STONE:3)
Block(6,44,-3,STONE:3)
Block(6,45,-7,STONE:3)
Block(6,45,-6,STONE:3)
Block(6,45,-5,STONE:3)
Block(6,45,-4,STONE:3)
Block(6,45,-3,STONE:3)
Block(6,45,-2,STONE:3)
Block(6,46,-7,STONE:3)
Block(6,46,-6,STONE:3)
Block(6,46,-5,STONE:3)
Block(6,46,-4,STONE:3)
Block(6,46,-3,STONE:3)
Block(6,46,-2,STONE:3)
Block(6,47,-7,STONE:3)
Block(6,47,-6,STONE:3)
Block(6,47,-5,STONE:3)
Block(6,47,-4,STONE:3)
Block(6,47,-3,STONE:3)
Block(6,47,-2,STONE:3)
Block(6,48,-7,STONE:3)
Block(6,48,-6,STONE:3)
Block(6,48,-5,STONE:3)
Block(6,48,-4,STONE:3)
Block(6,48,-3,STONE:3)
Block(6,48,-2,STONE:3)
Block(6,49,-7,OBSIDIAN:0)
Block(6,49,-6,STONE:3)
Block(6,49,-5,STONE:3)
Block(6,49,-4,STONE:3)
Block(6,49,-3,STONE:3)
Block(6,49,-2,STONE:3)
Block(6,50,-7,OBSIDIAN:0)
Block(6,50,-6,OBSIDIAN:0)
Block(6,50,-5,STONE:3)
Block(6,50,-4,STONE:3)
Block(6,50,-3,STONE:3)
Block(6,50,-2,STONE:5)
Block(6,51,-7,OBSIDIAN:0)
Block(6,51,-6,STONE:3)
Block(6,51,-5,STONE:3)
Block(6,51,-4,STONE:3)
Block(6,51,-3,STONE:3)
Block(6,52,-7,STONE:3)
Block(6,52,-6,STONE:3)
Block(6,52,-5,STONE:3)
Block(6,52,-4,STONE:3)
Block(6,52,-3,STONE:3)
Block(6,53,-7,STONE:3)
Block(6,53,-6,STONE:3)
Block(6,53,-5,STONE:3)
Block(6,53,-4,STONE:3)
Block(6,53,-3,STONE:3)
Block(6,54,-7,STONE:3)
Block(6,54,-6,STONE:3)
Block(6,54,-5,STONE:3)
Block(6,54,-4,STONE:3)
Block(6,54,-3,STONE:3)
Block(6,55,-7,STONE:3)
Block(6,55,-6,STONE:3)
Block(6,55,-5,STONE:3)
Block(6,55,-4,STONE:3)
Block(6,55,-3,STONE:5)
Block(6,56,-7,STONE:3)
Block(6,56,-6,STONE:3)
Block(6,56,-5,STONE:3)
Block(6,56,-4,STONE:3)
Block(6,57,-7,STONE:3)
Block(6,57,-6,STONE:3)
Block(6,57,-5,STONE:3)
Block(6,57,-4,STONE:5)
Block(6,58,-7,STONE:3)
Block(6,58,-6,STONE:3)
Block(6,58,-5,STONE:5)
Block(6,59,-7,STONE:3)
Block(6,59,-6,STONE:5)
Block(6,60,-7,STONE:5)
Block(7,31,-7,STONE:3)
Block(7,32,-7,OBSIDIAN:0)
Block(7,33,-7,OBSIDIAN:0)
Block(7,33,-6,STONE:3)
Block(7,34,-7,OBSIDIAN:0)
Block(7,34,-6,STONE:3)
Block(7,34,-5,STONE:3)
Block(7,35,-7,STONE:3)
Block(7,35,-6,STONE:3)
Block(7,35,-5,STONE:3)
Block(7,36,-7,STONE:3)
Block(7,36,-6,STONE:3)
Block(7,36,-5,STONE:3)
Block(7,37,-7,STONE:3)
Block(7,37,-6,STONE:3)
Block(7,37,-5,STONE:3)
Block(7,38,-7,STONE:3)
Block(7,38,-6,STONE:3)
Block(7,38,-5,STONE:3)
Block(7,38,-4,STONE:3)
Block(7,39,-7,STONE:3)
Block(7,39,-6,STONE:3)
Block(7,39,-5,STONE:3)
Block(7,39,-4,STONE:3)
Block(7,39,-3,STONE:3)
Block(7,40,-7,STONE:3)
Block(7,40,-6,STONE:3)
Block(7,40,-5,STONE:3)
Block(7,40,-4,STONE:3)
Block(7,40,-3,STONE:3)
Block(7,41,-7,STONE:3)
Block(7,41,-6,STONE:3)
Block(7,41,-5,STONE:3)
Block(7,41,-4,STONE:3)
Block(7,41,-3,STONE:3)
Block(7,41,-2,STONE:3)
Block(7,42,-7,STONE:3)
Block(7,42,-6,STONE:3)
Block(7,42,-5,STONE:3)
Block(7,42,-4,STONE:3)
Block(7,42,-3,STONE:3)
Block(7,42,-2,STONE:3)
Block(7,43,-7,OBSIDIAN:0)
Block(7,43,-6,STONE:3)
Block(7,43,-5,STONE:3)
Block(7,43,-4,STONE:3)
Block(7,43,-3,STONE:3)
Block(7,43,-2,STONE:3)
Block(7,44,-7,STONE:3)
Block(7,44,-6,STONE:3)
Block(7,44,-5,STONE:3)
Block(7,44,-4,STONE:3)
Block(7,44,-3,STONE:3)
Block(7,44,-2,STONE:3)
Block(7,45,-7,STONE:3)
Block(7,45,-6,STONE:3)
Block(7,45,-5,STONE:3)
Block(7,45,-4,STONE:3)
Block(7,45,-3,STONE:3)
Block(7,45,-2,STONE:3)
Block(7,46,-7,STONE:3)
Block(7,46,-6,STONE:3)
Block(7,46,-5,STONE:3)
Block(7,46,-4,STONE:3)
Block(7,46,-3,STONE:3)
Block(7,46,-2,STONE:3)
Block(7,47,-7,STONE:3)
Block(7,47,-6,STONE:3)
Block(7,47,-5,STONE:3)
Block(7,47,-4,STONE:3)
Block(7,47,-3,STONE:3)
Block(7,47,-2,STONE:3)
Block(7,48,-7,STONE:3)
Block(7,48,-6,STONE:3)
Block(7,48,-5,STONE:3)
Block(7,48,-4,STONE:3)
Block(7,48,-3,STONE:3)
Block(7,48,-2,STONE:3)
Block(7,49,-7,OBSIDIAN:0)
Block(7,49,-6,STONE:3)
Block(7,49,-5,STONE:3)
Block(7,49,-4,STONE:3)
Block(7,49,-3,STONE:3)
Block(7,49,-2,STONE:3)
Block(7,50,-7,OBSIDIAN:0)
Block(7,50,-6,OBSIDIAN:0)
Block(7,50,-5,STONE:3)
Block(7,50,-4,STONE:3)
Block(7,50,-3,STONE:3)
Block(7,50,-2,STONE:3)
Block(7,51,-7,OBSIDIAN:0)
Block(7,51,-6,STONE:3)
Block(7,51,-5,STONE:3)
Block(7,51,-4,STONE:3)
Block(7,51,-3,STONE:3)
Block(7,51,-2,STONE:5)
Block(7,52,-7,STONE:3)
Block(7,52,-6,STONE:3)
Block(7,52,-5,STONE:3)
Block(7,52,-4,STONE:3)
Block(7,52,-3,STONE:3)
Block(7,53,-7,STONE:3)
Block(7,53,-6,STONE:3)
Block(7,53,-5,STONE:3)
Block(7,53,-4,STONE:3)
Block(7,53,-3,STONE:3)
Block(7,54,-7,STONE:3)
Block(7,54,-6,STONE:3)
Block(7,54,-5,STONE:3)
Block(7,54,-4,STONE:3)
Block(7,54,-3,STONE:3)
Block(7,55,-7,STONE:3)
Block(7,55,-6,STONE:3)
Block(7,55,-5,STONE:3)
Block(7,55,-4,STONE:3)
Block(7,55,-3,STONE:3)
Block(7,56,-7,STONE:3)
Block(7,56,-6,STONE:3)
Block(7,56,-5,STONE:3)
Block(7,56,-4,STONE:3)
Block(7,56,-3,STONE:5)
Block(7,57,-7,STONE:3)
Block(7,57,-6,STONE:3)
Block(7,57,-5,STONE:3)
Block(7,57,-4,STONE:5)
Block(7,58,-7,STONE:3)
Block(7,58,-6,STONE:3)
Block(7,58,-5,STONE:3)
Block(7,59,-7,STONE:3)
Block(7,59,-6,STONE:3)
Block(7,59,-5,STONE:5)
Block(7,60,-7,STONE:3)
Block(7,60,-6,STONE:5)
Block(7,61,-7,STONE:5)

#######################################################################
# +-----------------------------------------------------------------+ #
# |                             Branches                            | #
# +-----------------------------------------------------------------+ #
#######################################################################

Branch(0,0,-16,true,Amethyst_Desert_BigC8R8,NORTH,100.0,0)

#######################################################################
# +-----------------------------------------------------------------+ #
# |                             Entities                            | #
# +-----------------------------------------------------------------+ #
#######################################################################


#######################################################################
# +-----------------------------------------------------------------+ #
# |                            Particles                            | #
# +-----------------------------------------------------------------+ #
#######################################################################


#######################################################################
# +-----------------------------------------------------------------+ #
# |                             Spawners                            | #
# +-----------------------------------------------------------------+ #
#######################################################################


#######################################################################
# +-----------------------------------------------------------------+ #
# |                             ModData                             | #
# +-----------------------------------------------------------------+ #
#######################################################################

