
#######################################################################
# +-----------------------------------------------------------------+ #
# |                            BO4 object                           | #
# +-----------------------------------------------------------------+ #
#######################################################################

Author: NLBlackEagle

Description: No description given

SettingsMode: WriteDisable


#######################################################################
# +-----------------------------------------------------------------+ #
# |                          Main settings                          | #
# +-----------------------------------------------------------------+ #
#######################################################################

Frequency: 0

SpawnHeight: highestBlock

UseCenterForHighestBlock: true

##############################
# Height Limits for the BO4. #
##############################

MinHeight: 0

MaxHeight: 255

InheritBO3: 

InheritBO3Rotation: NORTH

OverrideChildSettings: true

OverrideParentHeight: false

CanOverride: false

BranchFrequency: 0

BranchFrequencyGroup: 

MustBeBelowOther: false

MustBeInside: 

CannotBeInside: 

ReplacesBO3: 

MustBeInsideWorldBorders: false

CanSpawnOnWater: true

SpawnOnWaterOnly: false

SpawnUnderWater: false

SpawnAtWaterLevel: false

HeightOffset: 0

RemoveAir: false

ReplaceAbove: 

ReplaceBelow: 

ReplaceWithBiomeBlocks: false

ReplaceWithSurfaceBlock: 

ReplaceWithGroundBlock: 

ReplaceWithStoneBlock: 

SmoothRadius: 0

SmoothHeightOffset: 0

SmoothStartTop: false

SmoothStartWood: false

SmoothingSurfaceBlock: 

SmoothingGroundBlock: 

BO3Group: 

IsSpawnPoint: false

DoReplaceBlocks: false


#######################################################################
# +-----------------------------------------------------------------+ #
# |                              Blocks                             | #
# +-----------------------------------------------------------------+ #
#######################################################################

Block(-4,37,-7,STONE:3)
Block(-4,38,-7,STONE:3)
Block(-4,39,-7,STONE:3)
Block(-3,26,-7,STONE:3)
Block(-3,27,-7,STONE:3)
Block(-3,27,-4,STONE:3)
Block(-3,27,-3,STONE:3)
Block(-3,27,-2,STONE:3)
Block(-3,27,-1,STONE:3)
Block(-3,28,-7,STONE:3)
Block(-3,28,-6,STONE:3)
Block(-3,28,-5,STONE:3)
Block(-3,28,-4,STONE:3)
Block(-3,28,-3,STONE:3)
Block(-3,28,-2,STONE:3)
Block(-3,28,-1,STONE:3)
Block(-3,28,0,STONE:3)
Block(-3,28,1,STONE:3)
Block(-3,28,2,STONE:3)
Block(-3,28,3,STONE:3)
Block(-3,29,-7,STONE:3)
Block(-3,29,-6,STONE:3)
Block(-3,29,-5,STONE:3)
Block(-3,29,-4,STONE:3)
Block(-3,29,-3,STONE:3)
Block(-3,29,-2,STONE:3)
Block(-3,29,-1,STONE:3)
Block(-3,29,0,STONE:3)
Block(-3,29,1,STONE:3)
Block(-3,29,2,STONE:3)
Block(-3,29,3,STONE:3)
Block(-3,29,4,STONE:3)
Block(-3,30,-7,STONE:3)
Block(-3,30,-6,STONE:3)
Block(-3,30,-5,STONE:3)
Block(-3,30,-4,STONE:3)
Block(-3,30,-3,STONE:3)
Block(-3,30,-2,STONE:3)
Block(-3,30,-1,STONE:3)
Block(-3,30,0,STONE:3)
Block(-3,30,1,STONE:3)
Block(-3,30,2,STONE:3)
Block(-3,30,3,STONE:3)
Block(-3,30,4,STONE:3)
Block(-3,30,5,STONE:3)
Block(-3,31,-7,STONE:3)
Block(-3,31,-6,STONE:3)
Block(-3,31,-5,STONE:3)
Block(-3,31,-4,STONE:3)
Block(-3,31,-3,STONE:3)
Block(-3,31,-2,STONE:3)
Block(-3,31,-1,STONE:3)
Block(-3,31,0,STONE:3)
Block(-3,31,1,STONE:3)
Block(-3,31,2,STONE:3)
Block(-3,31,3,STONE:3)
Block(-3,31,4,STONE:3)
Block(-3,31,5,STONE:3)
Block(-3,31,6,STONE:3)
Block(-3,32,-7,STONE:3)
Block(-3,32,-6,STONE:3)
Block(-3,32,-5,STONE:3)
Block(-3,32,-4,STONE:3)
Block(-3,32,-3,STONE:3)
Block(-3,32,-2,STONE:3)
Block(-3,32,-1,STONE:3)
Block(-3,32,0,STONE:3)
Block(-3,32,1,STONE:3)
Block(-3,32,2,STONE:3)
Block(-3,32,3,STONE:3)
Block(-3,32,4,STONE:3)
Block(-3,32,5,STONE:3)
Block(-3,32,6,STONE:3)
Block(-3,32,7,STONE:3)
Block(-3,33,-7,STONE:3)
Block(-3,33,-6,STONE:3)
Block(-3,33,-5,STONE:3)
Block(-3,33,-4,STONE:3)
Block(-3,33,-3,STONE:3)
Block(-3,33,-2,STONE:3)
Block(-3,33,-1,STONE:3)
Block(-3,33,0,STONE:3)
Block(-3,33,1,STONE:3)
Block(-3,33,2,STONE:3)
Block(-3,33,3,STONE:3)
Block(-3,33,4,STONE:3)
Block(-3,33,5,STONE:3)
Block(-3,33,6,STONE:3)
Block(-3,34,-7,STONE:3)
Block(-3,34,-6,STONE:3)
Block(-3,34,-5,STONE:3)
Block(-3,34,-4,STONE:3)
Block(-3,34,-3,STONE:3)
Block(-3,34,-2,STONE:3)
Block(-3,34,-1,STONE:3)
Block(-3,34,0,STONE:3)
Block(-3,34,1,STONE:3)
Block(-3,34,2,STONE:3)
Block(-3,34,3,STONE:3)
Block(-3,34,4,STONE:3)
Block(-3,34,5,STONE:3)
Block(-3,35,-7,STONE:3)
Block(-3,35,-6,STONE:3)
Block(-3,35,-5,STONE:3)
Block(-3,35,-4,STONE:3)
Block(-3,35,-3,STONE:3)
Block(-3,35,-2,STONE:3)
Block(-3,35,-1,STONE:3)
Block(-3,35,0,STONE:3)
Block(-3,35,1,STONE:3)
Block(-3,35,2,STONE:3)
Block(-3,35,3,STONE:3)
Block(-3,35,4,STONE:5)
Block(-3,36,-7,STONE:3)
Block(-3,36,-6,STONE:3)
Block(-3,36,-5,STONE:3)
Block(-3,36,-4,STONE:3)
Block(-3,36,-3,STONE:3)
Block(-3,36,-2,STONE:3)
Block(-3,36,-1,STONE:3)
Block(-3,36,0,STONE:3)
Block(-3,36,1,STONE:3)
Block(-3,36,2,STONE:3)
Block(-3,36,3,STONE:5)
Block(-3,37,-7,STONE:3)
Block(-3,37,-6,STONE:3)
Block(-3,37,-5,STONE:3)
Block(-3,37,-4,STONE:3)
Block(-3,37,-3,STONE:3)
Block(-3,37,-2,STONE:3)
Block(-3,37,-1,STONE:3)
Block(-3,37,0,STONE:3)
Block(-3,37,1,STONE:3)
Block(-3,37,2,STONE:5)
Block(-3,38,-7,STONE:3)
Block(-3,38,-6,STONE:3)
Block(-3,38,-5,STONE:3)
Block(-3,38,-4,STONE:3)
Block(-3,38,-3,STONE:3)
Block(-3,38,-2,STONE:3)
Block(-3,38,-1,STONE:3)
Block(-3,38,0,STONE:5)
Block(-3,38,1,STONE:5)
Block(-3,39,-7,STONE:3)
Block(-3,39,-6,STONE:3)
Block(-3,39,-5,STONE:3)
Block(-3,39,-4,STONE:3)
Block(-3,39,-3,STONE:3)
Block(-3,39,-2,STONE:3)
Block(-3,39,-1,STONE:5)
Block(-3,40,-7,STONE:3)
Block(-3,40,-6,STONE:3)
Block(-3,40,-5,STONE:3)
Block(-3,40,-4,STONE:5)
Block(-3,40,-3,STONE:5)
Block(-3,40,-2,STONE:5)
Block(-3,41,-7,STONE:3)
Block(-3,41,-6,STONE:3)
Block(-3,41,-5,STONE:5)
Block(-3,42,-7,STONE:3)
Block(-3,42,-6,STONE:5)
Block(-2,24,-7,STONE:3)
Block(-2,25,-7,STONE:3)
Block(-2,25,-6,STONE:3)
Block(-2,25,-5,STONE:3)
Block(-2,25,-4,STONE:3)
Block(-2,26,-7,STONE:3)
Block(-2,26,-6,STONE:3)
Block(-2,26,-5,STONE:3)
Block(-2,26,-4,STONE:3)
Block(-2,26,-3,STONE:3)
Block(-2,26,-2,STONE:3)
Block(-2,27,-7,STONE:3)
Block(-2,27,-6,STONE:3)
Block(-2,27,-5,STONE:3)
Block(-2,27,-4,STONE:3)
Block(-2,27,-3,STONE:3)
Block(-2,27,-2,STONE:3)
Block(-2,27,-1,STONE:3)
Block(-2,27,0,STONE:3)
Block(-2,27,1,STONE:3)
Block(-2,27,2,STONE:3)
Block(-2,28,-7,STONE:3)
Block(-2,28,-6,STONE:3)
Block(-2,28,-5,STONE:3)
Block(-2,28,-4,STONE:3)
Block(-2,28,-3,STONE:3)
Block(-2,28,-2,STONE:3)
Block(-2,28,-1,STONE:3)
Block(-2,28,0,STONE:3)
Block(-2,28,1,STONE:3)
Block(-2,28,2,STONE:3)
Block(-2,28,3,STONE:3)
Block(-2,28,4,STONE:3)
Block(-2,29,-7,STONE:3)
Block(-2,29,-6,STONE:3)
Block(-2,29,-5,STONE:3)
Block(-2,29,-4,STONE:3)
Block(-2,29,-3,STONE:3)
Block(-2,29,-2,STONE:3)
Block(-2,29,-1,STONE:3)
Block(-2,29,0,STONE:3)
Block(-2,29,1,STONE:3)
Block(-2,29,2,STONE:3)
Block(-2,29,3,STONE:3)
Block(-2,29,4,STONE:3)
Block(-2,29,5,STONE:3)
Block(-2,30,-7,STONE:3)
Block(-2,30,-6,STONE:3)
Block(-2,30,-5,STONE:3)
Block(-2,30,-4,STONE:3)
Block(-2,30,-3,STONE:3)
Block(-2,30,-2,STONE:3)
Block(-2,30,-1,STONE:3)
Block(-2,30,0,STONE:3)
Block(-2,30,1,STONE:3)
Block(-2,30,2,STONE:3)
Block(-2,30,3,STONE:3)
Block(-2,30,4,STONE:3)
Block(-2,30,5,STONE:3)
Block(-2,30,6,STONE:3)
Block(-2,31,-7,STONE:3)
Block(-2,31,-6,STONE:3)
Block(-2,31,-5,STONE:3)
Block(-2,31,-4,STONE:3)
Block(-2,31,-3,STONE:3)
Block(-2,31,-2,STONE:3)
Block(-2,31,-1,STONE:3)
Block(-2,31,0,STONE:3)
Block(-2,31,1,STONE:3)
Block(-2,31,2,STONE:3)
Block(-2,31,3,STONE:3)
Block(-2,31,4,STONE:3)
Block(-2,31,5,STONE:3)
Block(-2,31,6,STONE:3)
Block(-2,31,7,STONE:3)
Block(-2,32,-7,STONE:3)
Block(-2,32,-6,STONE:3)
Block(-2,32,-5,STONE:3)
Block(-2,32,-4,STONE:3)
Block(-2,32,-3,STONE:3)
Block(-2,32,-2,STONE:3)
Block(-2,32,-1,STONE:3)
Block(-2,32,0,STONE:3)
Block(-2,32,1,STONE:3)
Block(-2,32,2,STONE:3)
Block(-2,32,3,STONE:3)
Block(-2,32,4,STONE:3)
Block(-2,32,5,STONE:3)
Block(-2,32,6,STONE:3)
Block(-2,32,7,STONE:3)
Block(-2,33,-7,STONE:3)
Block(-2,33,-6,STONE:3)
Block(-2,33,-5,STONE:3)
Block(-2,33,-4,STONE:3)
Block(-2,33,-3,STONE:3)
Block(-2,33,-2,STONE:3)
Block(-2,33,-1,STONE:3)
Block(-2,33,0,STONE:3)
Block(-2,33,1,STONE:3)
Block(-2,33,2,STONE:3)
Block(-2,33,3,STONE:3)
Block(-2,33,4,STONE:3)
Block(-2,33,5,STONE:3)
Block(-2,33,6,STONE:3)
Block(-2,33,7,STONE:3)
Block(-2,34,-7,STONE:3)
Block(-2,34,-6,STONE:3)
Block(-2,34,-5,STONE:3)
Block(-2,34,-4,STONE:3)
Block(-2,34,-3,STONE:3)
Block(-2,34,-2,STONE:3)
Block(-2,34,-1,STONE:3)
Block(-2,34,0,STONE:3)
Block(-2,34,1,STONE:3)
Block(-2,34,2,STONE:3)
Block(-2,34,3,STONE:3)
Block(-2,34,4,STONE:3)
Block(-2,34,5,STONE:3)
Block(-2,34,6,STONE:3)
Block(-2,34,7,STONE:3)
Block(-2,35,-7,STONE:3)
Block(-2,35,-6,STONE:3)
Block(-2,35,-5,STONE:3)
Block(-2,35,-4,STONE:3)
Block(-2,35,-3,STONE:3)
Block(-2,35,-2,STONE:3)
Block(-2,35,-1,STONE:3)
Block(-2,35,0,STONE:3)
Block(-2,35,1,STONE:3)
Block(-2,35,2,STONE:3)
Block(-2,35,3,STONE:3)
Block(-2,35,4,STONE:3)
Block(-2,35,5,STONE:3)
Block(-2,35,6,STONE:3)
Block(-2,36,-7,STONE:3)
Block(-2,36,-6,STONE:3)
Block(-2,36,-5,STONE:3)
Block(-2,36,-4,STONE:3)
Block(-2,36,-3,STONE:3)
Block(-2,36,-2,STONE:3)
Block(-2,36,-1,STONE:3)
Block(-2,36,0,STONE:3)
Block(-2,36,1,STONE:3)
Block(-2,36,2,STONE:3)
Block(-2,36,3,STONE:3)
Block(-2,36,4,STONE:3)
Block(-2,36,5,STONE:5)
Block(-2,37,-7,STONE:3)
Block(-2,37,-6,STONE:3)
Block(-2,37,-5,STONE:3)
Block(-2,37,-4,STONE:3)
Block(-2,37,-3,STONE:3)
Block(-2,37,-2,STONE:3)
Block(-2,37,-1,STONE:3)
Block(-2,37,0,STONE:3)
Block(-2,37,1,STONE:3)
Block(-2,37,2,STONE:3)
Block(-2,37,3,STONE:3)
Block(-2,37,4,STONE:3)
Block(-2,38,-7,STONE:3)
Block(-2,38,-6,STONE:3)
Block(-2,38,-5,STONE:3)
Block(-2,38,-4,STONE:3)
Block(-2,38,-3,STONE:3)
Block(-2,38,-2,STONE:3)
Block(-2,38,-1,STONE:3)
Block(-2,38,0,STONE:3)
Block(-2,38,1,STONE:3)
Block(-2,38,2,STONE:3)
Block(-2,38,3,STONE:3)
Block(-2,38,4,STONE:5)
Block(-2,39,-7,STONE:3)
Block(-2,39,-6,STONE:3)
Block(-2,39,-5,STONE:3)
Block(-2,39,-4,STONE:3)
Block(-2,39,-3,STONE:3)
Block(-2,39,-2,STONE:3)
Block(-2,39,-1,STONE:3)
Block(-2,39,0,STONE:3)
Block(-2,39,1,STONE:3)
Block(-2,39,2,STONE:5)
Block(-2,39,3,STONE:5)
Block(-2,40,-7,STONE:3)
Block(-2,40,-6,STONE:3)
Block(-2,40,-5,STONE:3)
Block(-2,40,-4,STONE:3)
Block(-2,40,-3,STONE:3)
Block(-2,40,-2,STONE:3)
Block(-2,40,-1,STONE:3)
Block(-2,40,0,STONE:3)
Block(-2,40,1,STONE:5)
Block(-2,41,-7,STONE:3)
Block(-2,41,-6,STONE:3)
Block(-2,41,-5,STONE:3)
Block(-2,41,-4,STONE:3)
Block(-2,41,-3,STONE:3)
Block(-2,41,-2,STONE:3)
Block(-2,41,-1,STONE:3)
Block(-2,41,0,STONE:3)
Block(-2,42,-7,STONE:3)
Block(-2,42,-6,STONE:3)
Block(-2,42,-5,STONE:3)
Block(-2,42,-4,STONE:3)
Block(-2,42,-3,STONE:3)
Block(-2,42,-2,STONE:3)
Block(-2,42,-1,STONE:3)
Block(-2,42,0,STONE:3)
Block(-2,43,-7,STONE:3)
Block(-2,43,-6,STONE:3)
Block(-2,43,-5,STONE:3)
Block(-2,43,-4,STONE:3)
Block(-2,43,-3,STONE:3)
Block(-2,43,-2,STONE:3)
Block(-2,43,-1,STONE:3)
Block(-2,43,0,STONE:3)
Block(-2,44,-7,STONE:3)
Block(-2,44,-6,STONE:3)
Block(-2,44,-5,STONE:3)
Block(-2,44,-4,STONE:3)
Block(-2,44,-3,STONE:3)
Block(-2,44,-2,STONE:3)
Block(-2,44,-1,STONE:3)
Block(-2,44,0,STONE:5)
Block(-2,45,-7,STONE:3)
Block(-2,45,-6,STONE:3)
Block(-2,45,-5,STONE:3)
Block(-2,45,-4,STONE:3)
Block(-2,45,-3,STONE:3)
Block(-2,45,-2,STONE:3)
Block(-2,45,-1,STONE:3)
Block(-2,46,-7,STONE:3)
Block(-2,46,-6,STONE:3)
Block(-2,46,-5,STONE:3)
Block(-2,46,-4,STONE:3)
Block(-2,46,-3,STONE:3)
Block(-2,46,-2,STONE:5)
Block(-2,46,-1,STONE:5)
Block(-2,47,-7,STONE:5)
Block(-2,47,-6,STONE:5)
Block(-2,47,-5,STONE:5)
Block(-2,47,-4,STONE:5)
Block(-2,47,-3,STONE:5)
Block(-1,23,-7,STONE:3)
Block(-1,24,-7,STONE:3)
Block(-1,24,-6,STONE:3)
Block(-1,24,-5,STONE:3)
Block(-1,24,-4,STONE:3)
Block(-1,24,-3,STONE:3)
Block(-1,24,-2,STONE:3)
Block(-1,25,-7,STONE:3)
Block(-1,25,-6,STONE:3)
Block(-1,25,-5,STONE:3)
Block(-1,25,-4,STONE:3)
Block(-1,25,-3,STONE:3)
Block(-1,25,-2,STONE:3)
Block(-1,26,-7,STONE:3)
Block(-1,26,-6,STONE:3)
Block(-1,26,-5,STONE:3)
Block(-1,26,-4,STONE:3)
Block(-1,26,-3,STONE:3)
Block(-1,26,-2,STONE:3)
Block(-1,26,-1,STONE:3)
Block(-1,26,0,STONE:3)
Block(-1,26,1,STONE:3)
Block(-1,27,-7,STONE:3)
Block(-1,27,-6,STONE:3)
Block(-1,27,-5,STONE:3)
Block(-1,27,-4,STONE:3)
Block(-1,27,-3,STONE:3)
Block(-1,27,-2,STONE:3)
Block(-1,27,-1,STONE:3)
Block(-1,27,0,STONE:3)
Block(-1,27,1,STONE:3)
Block(-1,27,2,STONE:3)
Block(-1,27,3,STONE:3)
Block(-1,27,4,STONE:3)
Block(-1,28,-7,STONE:3)
Block(-1,28,-6,STONE:3)
Block(-1,28,-5,STONE:3)
Block(-1,28,-4,STONE:3)
Block(-1,28,-3,STONE:3)
Block(-1,28,-2,STONE:3)
Block(-1,28,-1,STONE:3)
Block(-1,28,0,STONE:3)
Block(-1,28,1,STONE:3)
Block(-1,28,2,STONE:3)
Block(-1,28,3,STONE:3)
Block(-1,28,4,STONE:3)
Block(-1,28,5,STONE:3)
Block(-1,29,-7,STONE:3)
Block(-1,29,-6,STONE:3)
Block(-1,29,-5,STONE:3)
Block(-1,29,-4,STONE:3)
Block(-1,29,-3,STONE:3)
Block(-1,29,-2,STONE:3)
Block(-1,29,-1,STONE:3)
Block(-1,29,0,STONE:3)
Block(-1,29,1,STONE:3)
Block(-1,29,2,STONE:3)
Block(-1,29,3,STONE:3)
Block(-1,29,4,STONE:3)
Block(-1,29,5,STONE:3)
Block(-1,29,6,STONE:3)
Block(-1,30,-7,STONE:3)
Block(-1,30,-6,STONE:3)
Block(-1,30,-5,STONE:3)
Block(-1,30,-4,STONE:3)
Block(-1,30,-3,STONE:3)
Block(-1,30,-2,STONE:3)
Block(-1,30,-1,STONE:3)
Block(-1,30,0,STONE:3)
Block(-1,30,1,STONE:3)
Block(-1,30,2,STONE:3)
Block(-1,30,3,STONE:3)
Block(-1,30,4,STONE:3)
Block(-1,30,5,STONE:3)
Block(-1,30,6,STONE:3)
Block(-1,30,7,STONE:3)
Block(-1,31,-7,STONE:3)
Block(-1,31,-6,STONE:3)
Block(-1,31,-5,STONE:3)
Block(-1,31,-4,STONE:3)
Block(-1,31,-3,STONE:3)
Block(-1,31,-2,STONE:3)
Block(-1,31,-1,STONE:3)
Block(-1,31,0,STONE:3)
Block(-1,31,1,STONE:3)
Block(-1,31,2,STONE:3)
Block(-1,31,3,STONE:3)
Block(-1,31,4,STONE:3)
Block(-1,31,5,STONE:3)
Block(-1,31,6,STONE:3)
Block(-1,31,7,STONE:3)
Block(-1,32,-7,STONE:3)
Block(-1,32,-6,STONE:3)
Block(-1,32,-5,STONE:3)
Block(-1,32,-4,STONE:3)
Block(-1,32,-3,STONE:3)
Block(-1,32,-2,STONE:3)
Block(-1,32,-1,STONE:3)
Block(-1,32,0,STONE:3)
Block(-1,32,1,STONE:3)
Block(-1,32,2,STONE:3)
Block(-1,32,3,STONE:3)
Block(-1,32,4,STONE:3)
Block(-1,32,5,STONE:3)
Block(-1,32,6,STONE:3)
Block(-1,32,7,STONE:3)
Block(-1,33,-7,STONE:3)
Block(-1,33,-6,STONE:3)
Block(-1,33,-5,STONE:3)
Block(-1,33,-4,STONE:3)
Block(-1,33,-3,STONE:3)
Block(-1,33,-2,STONE:3)
Block(-1,33,-1,STONE:3)
Block(-1,33,0,STONE:3)
Block(-1,33,1,STONE:3)
Block(-1,33,2,STONE:3)
Block(-1,33,3,STONE:3)
Block(-1,33,4,STONE:3)
Block(-1,33,5,STONE:3)
Block(-1,33,6,STONE:3)
Block(-1,33,7,STONE:3)
Block(-1,34,-7,STONE:3)
Block(-1,34,-6,STONE:3)
Block(-1,34,-5,STONE:3)
Block(-1,34,-4,STONE:3)
Block(-1,34,-3,STONE:3)
Block(-1,34,-2,STONE:3)
Block(-1,34,-1,STONE:3)
Block(-1,34,0,STONE:3)
Block(-1,34,1,STONE:3)
Block(-1,34,2,STONE:3)
Block(-1,34,3,STONE:3)
Block(-1,34,4,STONE:3)
Block(-1,34,5,STONE:3)
Block(-1,34,6,STONE:3)
Block(-1,34,7,STONE:3)
Block(-1,34,8,STONE:3)
Block(-1,35,-7,STONE:3)
Block(-1,35,-6,STONE:3)
Block(-1,35,-5,STONE:3)
Block(-1,35,-4,STONE:3)
Block(-1,35,-3,STONE:3)
Block(-1,35,-2,STONE:3)
Block(-1,35,-1,STONE:3)
Block(-1,35,0,STONE:3)
Block(-1,35,1,STONE:3)
Block(-1,35,2,STONE:3)
Block(-1,35,3,STONE:3)
Block(-1,35,4,STONE:3)
Block(-1,35,5,STONE:3)
Block(-1,35,6,STONE:3)
Block(-1,35,7,STONE:3)
Block(-1,35,8,STONE:3)
Block(-1,36,-7,STONE:3)
Block(-1,36,-6,STONE:3)
Block(-1,36,-5,STONE:3)
Block(-1,36,-4,STONE:3)
Block(-1,36,-3,STONE:3)
Block(-1,36,-2,STONE:3)
Block(-1,36,-1,STONE:3)
Block(-1,36,0,STONE:3)
Block(-1,36,1,STONE:3)
Block(-1,36,2,STONE:3)
Block(-1,36,3,STONE:3)
Block(-1,36,4,STONE:3)
Block(-1,36,5,STONE:3)
Block(-1,36,6,STONE:3)
Block(-1,36,7,STONE:3)
Block(-1,37,-7,STONE:3)
Block(-1,37,-6,STONE:3)
Block(-1,37,-5,STONE:3)
Block(-1,37,-4,STONE:3)
Block(-1,37,-3,STONE:3)
Block(-1,37,-2,STONE:3)
Block(-1,37,-1,STONE:3)
Block(-1,37,0,STONE:3)
Block(-1,37,1,STONE:3)
Block(-1,37,2,STONE:3)
Block(-1,37,3,STONE:3)
Block(-1,37,4,STONE:3)
Block(-1,37,5,STONE:3)
Block(-1,37,6,STONE:3)
Block(-1,38,-7,STONE:3)
Block(-1,38,-6,STONE:3)
Block(-1,38,-5,STONE:3)
Block(-1,38,-4,STONE:3)
Block(-1,38,-3,STONE:3)
Block(-1,38,-2,STONE:3)
Block(-1,38,-1,STONE:3)
Block(-1,38,0,STONE:3)
Block(-1,38,1,STONE:3)
Block(-1,38,2,STONE:3)
Block(-1,38,3,STONE:3)
Block(-1,38,4,STONE:3)
Block(-1,38,5,STONE:3)
Block(-1,38,6,STONE:5)
Block(-1,39,-7,STONE:3)
Block(-1,39,-6,STONE:3)
Block(-1,39,-5,STONE:3)
Block(-1,39,-4,STONE:3)
Block(-1,39,-3,STONE:3)
Block(-1,39,-2,STONE:3)
Block(-1,39,-1,STONE:3)
Block(-1,39,0,STONE:3)
Block(-1,39,1,STONE:3)
Block(-1,39,2,STONE:3)
Block(-1,39,3,STONE:5)
Block(-1,39,4,STONE:5)
Block(-1,39,5,STONE:5)
Block(-1,40,-7,STONE:3)
Block(-1,40,-6,STONE:3)
Block(-1,40,-5,STONE:3)
Block(-1,40,-4,STONE:3)
Block(-1,40,-3,STONE:3)
Block(-1,40,-2,STONE:3)
Block(-1,40,-1,STONE:3)
Block(-1,40,0,STONE:3)
Block(-1,40,1,STONE:3)
Block(-1,40,2,STONE:5)
Block(-1,41,-7,STONE:3)
Block(-1,41,-6,STONE:3)
Block(-1,41,-5,STONE:3)
Block(-1,41,-4,STONE:3)
Block(-1,41,-3,STONE:3)
Block(-1,41,-2,STONE:3)
Block(-1,41,-1,STONE:3)
Block(-1,41,0,STONE:3)
Block(-1,41,1,STONE:3)
Block(-1,42,-7,STONE:3)
Block(-1,42,-6,STONE:3)
Block(-1,42,-5,STONE:3)
Block(-1,42,-4,STONE:3)
Block(-1,42,-3,STONE:3)
Block(-1,42,-2,STONE:3)
Block(-1,42,-1,STONE:3)
Block(-1,42,0,STONE:3)
Block(-1,43,-7,STONE:3)
Block(-1,43,-6,STONE:3)
Block(-1,43,-5,STONE:3)
Block(-1,43,-4,STONE:3)
Block(-1,43,-3,STONE:3)
Block(-1,43,-2,STONE:3)
Block(-1,43,-1,STONE:3)
Block(-1,43,0,STONE:3)
Block(-1,43,1,STONE:3)
Block(-1,44,-7,STONE:3)
Block(-1,44,-6,STONE:3)
Block(-1,44,-5,STONE:3)
Block(-1,44,-4,STONE:3)
Block(-1,44,-3,STONE:3)
Block(-1,44,-2,STONE:3)
Block(-1,44,-1,STONE:3)
Block(-1,44,0,STONE:3)
Block(-1,44,1,STONE:5)
Block(-1,45,-7,STONE:3)
Block(-1,45,-6,STONE:3)
Block(-1,45,-5,STONE:3)
Block(-1,45,-4,STONE:3)
Block(-1,45,-3,STONE:3)
Block(-1,45,-2,STONE:3)
Block(-1,45,-1,STONE:3)
Block(-1,45,0,STONE:3)
Block(-1,46,-7,STONE:3)
Block(-1,46,-6,STONE:3)
Block(-1,46,-5,STONE:3)
Block(-1,46,-4,STONE:3)
Block(-1,46,-3,STONE:3)
Block(-1,46,-2,STONE:3)
Block(-1,46,-1,STONE:3)
Block(-1,46,0,STONE:5)
Block(-1,47,-7,STONE:5)
Block(-1,47,-6,STONE:3)
Block(-1,47,-5,STONE:3)
Block(-1,47,-4,STONE:5)
Block(-1,47,-3,STONE:5)
Block(-1,47,-2,STONE:5)
Block(-1,47,-1,STONE:5)
Block(-1,48,-6,STONE:5)
Block(-1,48,-5,STONE:5)
Block(0,19,-7,STONE:3)
Block(0,20,-7,STONE:3)
Block(0,20,-6,STONE:3)
Block(0,21,-7,STONE:3)
Block(0,21,-6,STONE:3)
Block(0,21,-5,STONE:3)
Block(0,22,-7,STONE:3)
Block(0,22,-6,STONE:3)
Block(0,22,-5,STONE:3)
Block(0,23,-7,STONE:3)
Block(0,23,-6,STONE:3)
Block(0,23,-5,STONE:3)
Block(0,23,-4,STONE:3)
Block(0,23,-3,STONE:3)
Block(0,23,-2,STONE:3)
Block(0,24,-7,STONE:3)
Block(0,24,-6,STONE:3)
Block(0,24,-5,STONE:3)
Block(0,24,-4,STONE:3)
Block(0,24,-3,STONE:3)
Block(0,24,-2,STONE:3)
Block(0,24,-1,STONE:3)
Block(0,25,-7,STONE:3)
Block(0,25,-6,STONE:3)
Block(0,25,-5,STONE:3)
Block(0,25,-4,STONE:3)
Block(0,25,-3,STONE:3)
Block(0,25,-2,STONE:3)
Block(0,25,-1,STONE:3)
Block(0,25,0,STONE:3)
Block(0,25,1,STONE:3)
Block(0,26,-7,STONE:3)
Block(0,26,-6,STONE:3)
Block(0,26,-5,STONE:3)
Block(0,26,-4,STONE:3)
Block(0,26,-3,STONE:3)
Block(0,26,-2,STONE:3)
Block(0,26,-1,STONE:3)
Block(0,26,0,STONE:3)
Block(0,26,1,STONE:3)
Block(0,26,2,STONE:3)
Block(0,26,4,STONE:3)
Block(0,27,-7,STONE:3)
Block(0,27,-6,STONE:3)
Block(0,27,-5,STONE:3)
Block(0,27,-4,STONE:3)
Block(0,27,-3,STONE:3)
Block(0,27,-2,STONE:3)
Block(0,27,-1,STONE:3)
Block(0,27,0,STONE:3)
Block(0,27,1,STONE:3)
Block(0,27,2,STONE:3)
Block(0,27,3,STONE:3)
Block(0,27,4,STONE:3)
Block(0,27,5,STONE:3)
Block(0,28,-7,STONE:3)
Block(0,28,-6,STONE:3)
Block(0,28,-5,STONE:3)
Block(0,28,-4,STONE:3)
Block(0,28,-3,STONE:3)
Block(0,28,-2,STONE:3)
Block(0,28,-1,STONE:3)
Block(0,28,0,STONE:3)
Block(0,28,1,STONE:3)
Block(0,28,2,STONE:3)
Block(0,28,3,STONE:3)
Block(0,28,4,STONE:3)
Block(0,28,5,STONE:3)
Block(0,28,6,STONE:3)
Block(0,29,-7,STONE:3)
Block(0,29,-6,STONE:3)
Block(0,29,-5,STONE:3)
Block(0,29,-4,STONE:3)
Block(0,29,-3,STONE:3)
Block(0,29,-2,STONE:3)
Block(0,29,-1,STONE:3)
Block(0,29,0,STONE:3)
Block(0,29,1,STONE:3)
Block(0,29,2,STONE:3)
Block(0,29,3,STONE:3)
Block(0,29,4,STONE:3)
Block(0,29,5,STONE:3)
Block(0,29,6,STONE:3)
Block(0,29,7,STONE:3)
Block(0,30,-7,STONE:3)
Block(0,30,-6,STONE:3)
Block(0,30,-5,STONE:3)
Block(0,30,-4,STONE:3)
Block(0,30,-3,STONE:3)
Block(0,30,-2,STONE:3)
Block(0,30,-1,STONE:3)
Block(0,30,0,STONE:3)
Block(0,30,1,STONE:3)
Block(0,30,2,STONE:3)
Block(0,30,3,STONE:3)
Block(0,30,4,STONE:3)
Block(0,30,5,STONE:3)
Block(0,30,6,STONE:3)
Block(0,30,7,STONE:3)
Block(0,30,8,STONE:3)
Block(0,31,-7,STONE:3)
Block(0,31,-6,STONE:3)
Block(0,31,-5,STONE:3)
Block(0,31,-4,STONE:3)
Block(0,31,-3,STONE:3)
Block(0,31,-2,STONE:3)
Block(0,31,-1,STONE:3)
Block(0,31,0,STONE:3)
Block(0,31,1,STONE:3)
Block(0,31,2,STONE:3)
Block(0,31,3,STONE:3)
Block(0,31,4,STONE:3)
Block(0,31,5,STONE:3)
Block(0,31,6,STONE:3)
Block(0,31,7,STONE:3)
Block(0,31,8,STONE:3)
Block(0,32,-7,STONE:3)
Block(0,32,-6,STONE:3)
Block(0,32,-5,STONE:3)
Block(0,32,-4,STONE:3)
Block(0,32,-3,STONE:3)
Block(0,32,-2,STONE:3)
Block(0,32,-1,STONE:3)
Block(0,32,0,STONE:3)
Block(0,32,1,STONE:3)
Block(0,32,2,STONE:3)
Block(0,32,3,STONE:3)
Block(0,32,4,STONE:3)
Block(0,32,5,STONE:3)
Block(0,32,6,STONE:3)
Block(0,32,7,STONE:3)
Block(0,33,-7,STONE:3)
Block(0,33,-6,STONE:3)
Block(0,33,-5,STONE:3)
Block(0,33,-4,STONE:3)
Block(0,33,-3,STONE:3)
Block(0,33,-2,STONE:3)
Block(0,33,-1,STONE:3)
Block(0,33,0,STONE:3)
Block(0,33,1,STONE:3)
Block(0,33,2,STONE:3)
Block(0,33,3,STONE:3)
Block(0,33,4,STONE:3)
Block(0,33,5,STONE:3)
Block(0,33,6,STONE:3)
Block(0,33,7,STONE:3)
Block(0,33,8,STONE:3)
Block(0,34,-7,STONE:3)
Block(0,34,-6,STONE:3)
Block(0,34,-5,STONE:3)
Block(0,34,-4,STONE:3)
Block(0,34,-3,STONE:3)
Block(0,34,-2,STONE:3)
Block(0,34,-1,STONE:3)
Block(0,34,0,STONE:3)
Block(0,34,1,STONE:3)
Block(0,34,2,STONE:3)
Block(0,34,3,STONE:3)
Block(0,34,4,STONE:3)
Block(0,34,5,STONE:3)
Block(0,34,6,STONE:3)
Block(0,34,7,STONE:3)
Block(0,34,8,STONE:3)
Block(0,35,-7,STONE:3)
Block(0,35,-6,STONE:3)
Block(0,35,-5,STONE:3)
Block(0,35,-4,STONE:3)
Block(0,35,-3,STONE:3)
Block(0,35,-2,STONE:3)
Block(0,35,-1,STONE:3)
Block(0,35,0,STONE:3)
Block(0,35,1,STONE:3)
Block(0,35,2,STONE:3)
Block(0,35,3,STONE:3)
Block(0,35,4,STONE:3)
Block(0,35,5,STONE:3)
Block(0,35,6,STONE:3)
Block(0,35,7,STONE:3)
Block(0,35,8,STONE:3)
Block(0,36,-7,STONE:3)
Block(0,36,-6,STONE:3)
Block(0,36,-5,STONE:3)
Block(0,36,-4,STONE:3)
Block(0,36,-3,STONE:3)
Block(0,36,-2,STONE:3)
Block(0,36,-1,STONE:3)
Block(0,36,0,STONE:3)
Block(0,36,1,STONE:3)
Block(0,36,2,STONE:3)
Block(0,36,3,STONE:3)
Block(0,36,4,STONE:3)
Block(0,36,5,STONE:3)
Block(0,36,6,STONE:3)
Block(0,36,7,STONE:3)
Block(0,37,-7,STONE:3)
Block(0,37,-6,STONE:3)
Block(0,37,-5,STONE:3)
Block(0,37,-4,STONE:3)
Block(0,37,-3,STONE:3)
Block(0,37,-2,STONE:3)
Block(0,37,-1,STONE:3)
Block(0,37,0,STONE:3)
Block(0,37,1,STONE:3)
Block(0,37,2,STONE:3)
Block(0,37,3,STONE:3)
Block(0,37,4,STONE:3)
Block(0,37,5,STONE:3)
Block(0,37,6,STONE:3)
Block(0,37,7,STONE:3)
Block(0,38,-7,STONE:3)
Block(0,38,-6,STONE:3)
Block(0,38,-5,STONE:3)
Block(0,38,-4,STONE:3)
Block(0,38,-3,STONE:3)
Block(0,38,-2,STONE:3)
Block(0,38,-1,STONE:3)
Block(0,38,0,STONE:3)
Block(0,38,1,STONE:3)
Block(0,38,2,STONE:3)
Block(0,38,3,STONE:3)
Block(0,38,4,STONE:3)
Block(0,38,5,STONE:3)
Block(0,38,6,STONE:3)
Block(0,38,7,STONE:5)
Block(0,39,-7,STONE:3)
Block(0,39,-6,STONE:3)
Block(0,39,-5,STONE:3)
Block(0,39,-4,STONE:3)
Block(0,39,-3,STONE:3)
Block(0,39,-2,STONE:3)
Block(0,39,-1,STONE:3)
Block(0,39,0,STONE:3)
Block(0,39,1,STONE:3)
Block(0,39,2,STONE:3)
Block(0,39,3,STONE:3)
Block(0,39,4,STONE:3)
Block(0,39,5,STONE:5)
Block(0,39,6,STONE:5)
Block(0,40,-7,STONE:3)
Block(0,40,-6,STONE:3)
Block(0,40,-5,STONE:3)
Block(0,40,-4,STONE:3)
Block(0,40,-3,STONE:3)
Block(0,40,-2,STONE:3)
Block(0,40,-1,STONE:3)
Block(0,40,0,STONE:3)
Block(0,40,1,STONE:3)
Block(0,40,2,STONE:3)
Block(0,40,3,STONE:5)
Block(0,40,4,STONE:5)
Block(0,41,-7,STONE:3)
Block(0,41,-6,STONE:3)
Block(0,41,-5,STONE:3)
Block(0,41,-4,STONE:3)
Block(0,41,-3,STONE:3)
Block(0,41,-2,STONE:3)
Block(0,41,-1,STONE:3)
Block(0,41,0,STONE:3)
Block(0,41,1,STONE:3)
Block(0,41,2,STONE:3)
Block(0,42,-7,STONE:3)
Block(0,42,-6,STONE:3)
Block(0,42,-5,STONE:3)
Block(0,42,-4,STONE:3)
Block(0,42,-3,STONE:3)
Block(0,42,-2,STONE:3)
Block(0,42,-1,STONE:3)
Block(0,42,0,STONE:3)
Block(0,42,1,STONE:3)
Block(0,43,-7,STONE:3)
Block(0,43,-6,STONE:3)
Block(0,43,-5,STONE:3)
Block(0,43,-4,STONE:3)
Block(0,43,-3,STONE:3)
Block(0,43,-2,STONE:3)
Block(0,43,-1,STONE:3)
Block(0,43,0,STONE:3)
Block(0,43,1,STONE:3)
Block(0,43,2,STONE:3)
Block(0,44,-7,STONE:3)
Block(0,44,-6,STONE:3)
Block(0,44,-5,STONE:3)
Block(0,44,-4,STONE:3)
Block(0,44,-3,STONE:3)
Block(0,44,-2,STONE:3)
Block(0,44,-1,STONE:3)
Block(0,44,0,STONE:3)
Block(0,44,1,STONE:3)
Block(0,44,2,STONE:5)
Block(0,45,-7,STONE:3)
Block(0,45,-6,STONE:3)
Block(0,45,-5,STONE:3)
Block(0,45,-4,STONE:3)
Block(0,45,-3,STONE:3)
Block(0,45,-2,STONE:3)
Block(0,45,-1,STONE:3)
Block(0,45,0,STONE:3)
Block(0,45,1,STONE:3)
Block(0,46,-7,STONE:3)
Block(0,46,-6,STONE:3)
Block(0,46,-5,STONE:3)
Block(0,46,-4,STONE:3)
Block(0,46,-3,STONE:3)
Block(0,46,-2,STONE:3)
Block(0,46,-1,STONE:3)
Block(0,46,0,STONE:3)
Block(0,46,1,STONE:5)
Block(0,47,-7,STONE:3)
Block(0,47,-6,STONE:3)
Block(0,47,-5,STONE:3)
Block(0,47,-4,STONE:3)
Block(0,47,-3,STONE:5)
Block(0,47,-2,STONE:3)
Block(0,47,-1,STONE:3)
Block(0,47,0,STONE:5)
Block(0,48,-7,STONE:5)
Block(0,48,-6,STONE:5)
Block(0,48,-5,STONE:3)
Block(0,48,-4,STONE:5)
Block(0,48,-2,STONE:5)
Block(0,48,-1,STONE:5)
Block(0,49,-5,STONE:5)
Block(1,17,-7,STONE:3)
Block(1,18,-7,STONE:3)
Block(1,18,-6,STONE:3)
Block(1,19,-7,STONE:3)
Block(1,19,-6,STONE:3)
Block(1,19,-5,STONE:3)
Block(1,20,-7,STONE:3)
Block(1,20,-6,STONE:3)
Block(1,20,-5,STONE:3)
Block(1,20,-3,STONE:3)
Block(1,20,-2,STONE:3)
Block(1,20,-1,STONE:3)
Block(1,21,-7,STONE:3)
Block(1,21,-6,STONE:3)
Block(1,21,-5,STONE:3)
Block(1,21,-4,STONE:3)
Block(1,21,-3,STONE:3)
Block(1,21,-2,STONE:3)
Block(1,21,-1,STONE:3)
Block(1,22,-7,STONE:3)
Block(1,22,-6,STONE:3)
Block(1,22,-5,STONE:3)
Block(1,22,-4,STONE:3)
Block(1,22,-3,STONE:3)
Block(1,22,-2,STONE:3)
Block(1,22,-1,STONE:3)
Block(1,22,0,STONE:3)
Block(1,22,1,STONE:3)
Block(1,22,2,STONE:3)
Block(1,23,-7,STONE:3)
Block(1,23,-6,STONE:3)
Block(1,23,-5,STONE:3)
Block(1,23,-4,STONE:3)
Block(1,23,-3,STONE:3)
Block(1,23,-2,STONE:3)
Block(1,23,-1,STONE:3)
Block(1,23,0,STONE:3)
Block(1,23,1,STONE:3)
Block(1,23,2,STONE:3)
Block(1,24,-7,STONE:3)
Block(1,24,-6,STONE:3)
Block(1,24,-5,STONE:3)
Block(1,24,-4,STONE:3)
Block(1,24,-3,STONE:3)
Block(1,24,-2,STONE:3)
Block(1,24,-1,STONE:3)
Block(1,24,0,STONE:3)
Block(1,24,1,STONE:3)
Block(1,24,2,STONE:3)
Block(1,25,-7,STONE:3)
Block(1,25,-6,STONE:3)
Block(1,25,-5,STONE:3)
Block(1,25,-4,STONE:3)
Block(1,25,-3,STONE:3)
Block(1,25,-2,STONE:3)
Block(1,25,-1,STONE:3)
Block(1,25,0,STONE:3)
Block(1,25,1,STONE:3)
Block(1,25,2,STONE:3)
Block(1,25,4,STONE:3)
Block(1,25,5,STONE:3)
Block(1,26,-7,STONE:3)
Block(1,26,-6,STONE:3)
Block(1,26,-5,STONE:3)
Block(1,26,-4,STONE:3)
Block(1,26,-3,STONE:3)
Block(1,26,-2,STONE:3)
Block(1,26,-1,STONE:3)
Block(1,26,0,STONE:3)
Block(1,26,1,STONE:3)
Block(1,26,2,STONE:3)
Block(1,26,3,STONE:3)
Block(1,26,4,STONE:3)
Block(1,26,5,STONE:3)
Block(1,26,6,STONE:3)
Block(1,27,-7,STONE:3)
Block(1,27,-6,STONE:3)
Block(1,27,-5,STONE:3)
Block(1,27,-4,STONE:3)
Block(1,27,-3,STONE:3)
Block(1,27,-2,STONE:3)
Block(1,27,-1,STONE:3)
Block(1,27,0,STONE:3)
Block(1,27,1,STONE:3)
Block(1,27,2,STONE:3)
Block(1,27,3,STONE:3)
Block(1,27,4,STONE:3)
Block(1,27,5,STONE:3)
Block(1,27,6,STONE:3)
Block(1,27,7,STONE:3)
Block(1,28,-7,STONE:3)
Block(1,28,-6,STONE:3)
Block(1,28,-5,STONE:3)
Block(1,28,-4,STONE:3)
Block(1,28,-3,STONE:3)
Block(1,28,-2,STONE:3)
Block(1,28,-1,STONE:3)
Block(1,28,0,STONE:3)
Block(1,28,1,STONE:3)
Block(1,28,2,STONE:3)
Block(1,28,3,STONE:3)
Block(1,28,4,STONE:3)
Block(1,28,5,STONE:3)
Block(1,28,6,STONE:3)
Block(1,28,7,STONE:3)
Block(1,28,8,STONE:3)
Block(1,29,-7,STONE:3)
Block(1,29,-6,STONE:3)
Block(1,29,-5,STONE:3)
Block(1,29,-4,STONE:3)
Block(1,29,-3,STONE:3)
Block(1,29,-2,STONE:3)
Block(1,29,-1,STONE:3)
Block(1,29,0,STONE:3)
Block(1,29,1,STONE:3)
Block(1,29,2,STONE:3)
Block(1,29,3,STONE:3)
Block(1,29,4,STONE:3)
Block(1,29,5,STONE:3)
Block(1,29,6,STONE:3)
Block(1,29,7,STONE:3)
Block(1,29,8,STONE:3)
Block(1,30,-7,STONE:3)
Block(1,30,-6,STONE:3)
Block(1,30,-5,STONE:3)
Block(1,30,-4,STONE:3)
Block(1,30,-3,STONE:3)
Block(1,30,-2,STONE:3)
Block(1,30,-1,STONE:3)
Block(1,30,0,STONE:3)
Block(1,30,1,STONE:3)
Block(1,30,2,STONE:3)
Block(1,30,3,STONE:3)
Block(1,30,4,STONE:3)
Block(1,30,5,STONE:3)
Block(1,30,6,STONE:3)
Block(1,30,7,STONE:3)
Block(1,30,8,STONE:3)
Block(1,31,-7,STONE:3)
Block(1,31,-6,STONE:3)
Block(1,31,-5,STONE:3)
Block(1,31,-4,STONE:3)
Block(1,31,-3,STONE:3)
Block(1,31,-2,STONE:3)
Block(1,31,-1,STONE:3)
Block(1,31,0,STONE:3)
Block(1,31,1,STONE:3)
Block(1,31,2,STONE:3)
Block(1,31,3,STONE:3)
Block(1,31,4,STONE:3)
Block(1,31,5,STONE:3)
Block(1,31,6,STONE:3)
Block(1,31,7,STONE:3)
Block(1,31,8,STONE:3)
Block(1,32,-7,STONE:3)
Block(1,32,-6,STONE:3)
Block(1,32,-5,STONE:3)
Block(1,32,-4,STONE:3)
Block(1,32,-3,STONE:3)
Block(1,32,-2,STONE:3)
Block(1,32,-1,STONE:3)
Block(1,32,0,STONE:3)
Block(1,32,1,STONE:3)
Block(1,32,2,STONE:3)
Block(1,32,3,STONE:3)
Block(1,32,4,STONE:3)
Block(1,32,5,STONE:3)
Block(1,32,6,STONE:3)
Block(1,32,7,STONE:3)
Block(1,32,8,STONE:3)
Block(1,33,-7,STONE:3)
Block(1,33,-6,STONE:3)
Block(1,33,-5,STONE:3)
Block(1,33,-4,STONE:3)
Block(1,33,-3,STONE:3)
Block(1,33,-2,STONE:3)
Block(1,33,-1,STONE:3)
Block(1,33,0,STONE:3)
Block(1,33,1,STONE:3)
Block(1,33,2,STONE:3)
Block(1,33,3,STONE:3)
Block(1,33,4,STONE:3)
Block(1,33,5,STONE:3)
Block(1,33,6,STONE:3)
Block(1,33,7,STONE:3)
Block(1,33,8,STONE:3)
Block(1,34,-7,STONE:3)
Block(1,34,-6,STONE:3)
Block(1,34,-5,STONE:3)
Block(1,34,-4,STONE:3)
Block(1,34,-3,STONE:3)
Block(1,34,-2,STONE:3)
Block(1,34,-1,STONE:3)
Block(1,34,0,STONE:3)
Block(1,34,1,STONE:3)
Block(1,34,2,STONE:3)
Block(1,34,3,STONE:3)
Block(1,34,4,STONE:3)
Block(1,34,5,STONE:3)
Block(1,34,6,STONE:3)
Block(1,34,7,STONE:3)
Block(1,34,8,STONE:3)
Block(1,35,-7,STONE:3)
Block(1,35,-6,STONE:3)
Block(1,35,-5,STONE:3)
Block(1,35,-4,STONE:3)
Block(1,35,-3,STONE:3)
Block(1,35,-2,STONE:3)
Block(1,35,-1,STONE:3)
Block(1,35,0,STONE:3)
Block(1,35,1,STONE:3)
Block(1,35,2,STONE:3)
Block(1,35,3,STONE:3)
Block(1,35,4,STONE:3)
Block(1,35,5,STONE:3)
Block(1,35,6,STONE:3)
Block(1,35,7,STONE:3)
Block(1,35,8,STONE:3)
Block(1,36,-7,STONE:3)
Block(1,36,-6,OBSIDIAN:0)
Block(1,36,-5,STONE:3)
Block(1,36,-4,STONE:3)
Block(1,36,-3,STONE:3)
Block(1,36,-2,STONE:3)
Block(1,36,-1,STONE:3)
Block(1,36,0,STONE:3)
Block(1,36,1,STONE:3)
Block(1,36,2,STONE:3)
Block(1,36,3,STONE:3)
Block(1,36,4,STONE:3)
Block(1,36,5,STONE:3)
Block(1,36,6,STONE:3)
Block(1,36,7,STONE:3)
Block(1,36,8,STONE:3)
Block(1,37,-7,STONE:3)
Block(1,37,-6,STONE:3)
Block(1,37,-5,STONE:3)
Block(1,37,-4,STONE:3)
Block(1,37,-3,STONE:3)
Block(1,37,-2,STONE:3)
Block(1,37,-1,STONE:3)
Block(1,37,0,STONE:3)
Block(1,37,1,STONE:3)
Block(1,37,2,STONE:3)
Block(1,37,3,STONE:3)
Block(1,37,4,STONE:3)
Block(1,37,5,STONE:3)
Block(1,37,6,STONE:3)
Block(1,37,7,STONE:3)
Block(1,37,8,STONE:3)
Block(1,38,-7,STONE:3)
Block(1,38,-6,STONE:3)
Block(1,38,-5,OBSIDIAN:0)
Block(1,38,-4,STONE:3)
Block(1,38,-3,STONE:3)
Block(1,38,-2,STONE:3)
Block(1,38,-1,STONE:3)
Block(1,38,0,STONE:3)
Block(1,38,1,STONE:3)
Block(1,38,2,STONE:3)
Block(1,38,3,STONE:3)
Block(1,38,4,STONE:3)
Block(1,38,5,STONE:3)
Block(1,38,6,STONE:3)
Block(1,38,7,STONE:3)
Block(1,38,8,STONE:5)
Block(1,39,-7,STONE:3)
Block(1,39,-6,STONE:3)
Block(1,39,-5,OBSIDIAN:0)
Block(1,39,-4,STONE:3)
Block(1,39,-3,STONE:3)
Block(1,39,-2,STONE:3)
Block(1,39,-1,STONE:3)
Block(1,39,0,STONE:3)
Block(1,39,1,STONE:3)
Block(1,39,2,STONE:3)
Block(1,39,3,STONE:3)
Block(1,39,4,STONE:3)
Block(1,39,5,STONE:3)
Block(1,39,6,STONE:3)
Block(1,39,7,STONE:5)
Block(1,40,-7,STONE:3)
Block(1,40,-6,STONE:3)
Block(1,40,-5,STONE:3)
Block(1,40,-4,STONE:3)
Block(1,40,-3,STONE:3)
Block(1,40,-2,STONE:3)
Block(1,40,-1,STONE:3)
Block(1,40,0,STONE:3)
Block(1,40,1,STONE:3)
Block(1,40,2,STONE:3)
Block(1,40,3,STONE:3)
Block(1,40,4,STONE:3)
Block(1,40,5,STONE:5)
Block(1,40,6,STONE:5)
Block(1,41,-7,STONE:3)
Block(1,41,-6,STONE:3)
Block(1,41,-5,STONE:3)
Block(1,41,-4,STONE:3)
Block(1,41,-3,STONE:3)
Block(1,41,-2,STONE:3)
Block(1,41,-1,STONE:3)
Block(1,41,0,STONE:3)
Block(1,41,1,STONE:3)
Block(1,41,2,STONE:3)
Block(1,41,3,STONE:3)
Block(1,41,4,STONE:5)
Block(1,42,-7,STONE:3)
Block(1,42,-6,STONE:3)
Block(1,42,-5,STONE:3)
Block(1,42,-4,STONE:3)
Block(1,42,-3,STONE:3)
Block(1,42,-2,STONE:3)
Block(1,42,-1,STONE:3)
Block(1,42,0,STONE:3)
Block(1,42,1,STONE:3)
Block(1,42,2,STONE:3)
Block(1,43,-7,STONE:3)
Block(1,43,-6,STONE:3)
Block(1,43,-5,STONE:3)
Block(1,43,-4,STONE:3)
Block(1,43,-3,STONE:3)
Block(1,43,-2,STONE:3)
Block(1,43,-1,STONE:3)
Block(1,43,0,STONE:3)
Block(1,43,1,STONE:3)
Block(1,43,2,STONE:3)
Block(1,43,3,STONE:3)
Block(1,44,-7,STONE:3)
Block(1,44,-6,STONE:3)
Block(1,44,-5,STONE:3)
Block(1,44,-4,STONE:3)
Block(1,44,-3,STONE:3)
Block(1,44,-2,STONE:3)
Block(1,44,-1,STONE:3)
Block(1,44,0,STONE:3)
Block(1,44,1,STONE:3)
Block(1,44,2,STONE:3)
Block(1,44,3,STONE:5)
Block(1,45,-7,STONE:3)
Block(1,45,-6,STONE:3)
Block(1,45,-5,STONE:3)
Block(1,45,-4,STONE:3)
Block(1,45,-3,STONE:3)
Block(1,45,-2,STONE:3)
Block(1,45,-1,STONE:3)
Block(1,45,0,STONE:3)
Block(1,45,1,STONE:3)
Block(1,45,2,STONE:3)
Block(1,46,-7,STONE:3)
Block(1,46,-6,STONE:3)
Block(1,46,-5,STONE:3)
Block(1,46,-4,STONE:3)
Block(1,46,-3,STONE:3)
Block(1,46,-2,STONE:3)
Block(1,46,-1,STONE:3)
Block(1,46,0,STONE:3)
Block(1,46,1,STONE:3)
Block(1,46,2,STONE:5)
Block(1,47,-7,STONE:3)
Block(1,47,-6,STONE:3)
Block(1,47,-5,STONE:3)
Block(1,47,-4,STONE:3)
Block(1,47,-3,STONE:3)
Block(1,47,-2,STONE:3)
Block(1,47,-1,STONE:3)
Block(1,47,0,STONE:3)
Block(1,47,1,STONE:5)
Block(1,48,-7,STONE:5)
Block(1,48,-6,STONE:5)
Block(1,48,-5,STONE:3)
Block(1,48,-4,STONE:3)
Block(1,48,-3,STONE:5)
Block(1,48,-2,STONE:3)
Block(1,48,-1,STONE:5)
Block(1,48,0,STONE:5)
Block(1,49,-5,STONE:5)
Block(1,49,-4,STONE:5)
Block(1,49,-2,STONE:5)
Block(2,17,-7,STONE:3)
Block(2,17,-6,STONE:3)
Block(2,18,-7,STONE:3)
Block(2,18,-6,STONE:3)
Block(2,18,-5,STONE:3)
Block(2,19,-7,STONE:3)
Block(2,19,-6,STONE:3)
Block(2,19,-5,STONE:3)
Block(2,20,-7,STONE:3)
Block(2,20,-6,STONE:3)
Block(2,20,-5,STONE:3)
Block(2,20,-4,STONE:3)
Block(2,20,-3,STONE:3)
Block(2,20,-2,STONE:3)
Block(2,20,-1,STONE:3)
Block(2,20,0,STONE:3)
Block(2,21,-7,STONE:3)
Block(2,21,-6,STONE:3)
Block(2,21,-5,STONE:3)
Block(2,21,-4,STONE:3)
Block(2,21,-3,STONE:3)
Block(2,21,-2,STONE:3)
Block(2,21,-1,STONE:3)
Block(2,21,0,STONE:3)
Block(2,21,1,STONE:3)
Block(2,21,2,STONE:3)
Block(2,22,-7,STONE:3)
Block(2,22,-6,STONE:3)
Block(2,22,-5,STONE:3)
Block(2,22,-4,STONE:3)
Block(2,22,-3,STONE:3)
Block(2,22,-2,STONE:3)
Block(2,22,-1,STONE:3)
Block(2,22,0,STONE:3)
Block(2,22,1,STONE:3)
Block(2,22,2,STONE:3)
Block(2,22,3,STONE:3)
Block(2,23,-7,STONE:3)
Block(2,23,-6,STONE:3)
Block(2,23,-5,STONE:3)
Block(2,23,-4,STONE:3)
Block(2,23,-3,STONE:3)
Block(2,23,-2,STONE:3)
Block(2,23,-1,STONE:3)
Block(2,23,0,STONE:3)
Block(2,23,1,STONE:3)
Block(2,23,2,STONE:3)
Block(2,23,3,STONE:3)
Block(2,24,-7,STONE:3)
Block(2,24,-6,STONE:3)
Block(2,24,-5,STONE:3)
Block(2,24,-4,STONE:3)
Block(2,24,-3,STONE:3)
Block(2,24,-2,STONE:3)
Block(2,24,-1,STONE:3)
Block(2,24,0,STONE:3)
Block(2,24,1,STONE:3)
Block(2,24,2,STONE:3)
Block(2,24,3,STONE:3)
Block(2,24,5,STONE:3)
Block(2,25,-7,STONE:3)
Block(2,25,-6,STONE:3)
Block(2,25,-5,STONE:3)
Block(2,25,-4,STONE:3)
Block(2,25,-3,STONE:3)
Block(2,25,-2,STONE:3)
Block(2,25,-1,STONE:3)
Block(2,25,0,STONE:3)
Block(2,25,1,STONE:3)
Block(2,25,2,STONE:3)
Block(2,25,3,STONE:3)
Block(2,25,4,STONE:3)
Block(2,25,5,STONE:3)
Block(2,25,6,STONE:3)
Block(2,26,-7,STONE:3)
Block(2,26,-6,STONE:3)
Block(2,26,-5,STONE:3)
Block(2,26,-4,STONE:3)
Block(2,26,-3,STONE:3)
Block(2,26,-2,STONE:3)
Block(2,26,-1,STONE:3)
Block(2,26,0,STONE:3)
Block(2,26,1,STONE:3)
Block(2,26,2,STONE:3)
Block(2,26,3,STONE:3)
Block(2,26,4,STONE:3)
Block(2,26,5,STONE:3)
Block(2,26,6,STONE:3)
Block(2,26,7,STONE:3)
Block(2,27,-7,STONE:3)
Block(2,27,-6,STONE:3)
Block(2,27,-5,STONE:3)
Block(2,27,-4,STONE:3)
Block(2,27,-3,STONE:3)
Block(2,27,-2,STONE:3)
Block(2,27,-1,STONE:3)
Block(2,27,0,STONE:3)
Block(2,27,1,STONE:3)
Block(2,27,2,STONE:3)
Block(2,27,3,STONE:3)
Block(2,27,4,STONE:3)
Block(2,27,5,STONE:3)
Block(2,27,6,STONE:3)
Block(2,27,7,STONE:3)
Block(2,27,8,STONE:3)
Block(2,28,-7,STONE:3)
Block(2,28,-6,STONE:3)
Block(2,28,-5,STONE:3)
Block(2,28,-4,STONE:3)
Block(2,28,-3,STONE:3)
Block(2,28,-2,STONE:3)
Block(2,28,-1,STONE:3)
Block(2,28,0,STONE:3)
Block(2,28,1,STONE:3)
Block(2,28,2,STONE:3)
Block(2,28,3,STONE:3)
Block(2,28,4,STONE:3)
Block(2,28,5,STONE:3)
Block(2,28,6,STONE:3)
Block(2,28,7,STONE:3)
Block(2,28,8,STONE:3)
Block(2,29,-7,STONE:3)
Block(2,29,-6,STONE:3)
Block(2,29,-5,STONE:3)
Block(2,29,-4,STONE:3)
Block(2,29,-3,STONE:3)
Block(2,29,-2,STONE:3)
Block(2,29,-1,STONE:3)
Block(2,29,0,STONE:3)
Block(2,29,1,STONE:3)
Block(2,29,2,STONE:3)
Block(2,29,3,STONE:3)
Block(2,29,4,STONE:3)
Block(2,29,5,STONE:3)
Block(2,29,6,STONE:3)
Block(2,29,7,STONE:3)
Block(2,29,8,STONE:3)
Block(2,30,-7,STONE:3)
Block(2,30,-6,STONE:3)
Block(2,30,-5,STONE:3)
Block(2,30,-4,STONE:3)
Block(2,30,-3,STONE:3)
Block(2,30,-2,STONE:3)
Block(2,30,-1,OBSIDIAN:0)
Block(2,30,0,STONE:3)
Block(2,30,1,STONE:3)
Block(2,30,2,STONE:3)
Block(2,30,3,STONE:3)
Block(2,30,4,STONE:3)
Block(2,30,5,STONE:3)
Block(2,30,6,STONE:3)
Block(2,30,7,STONE:3)
Block(2,30,8,STONE:3)
Block(2,31,-7,STONE:3)
Block(2,31,-6,STONE:3)
Block(2,31,-5,STONE:3)
Block(2,31,-4,STONE:3)
Block(2,31,-3,STONE:3)
Block(2,31,-2,STONE:3)
Block(2,31,-1,OBSIDIAN:0)
Block(2,31,0,OBSIDIAN:0)
Block(2,31,1,OBSIDIAN:0)
Block(2,31,2,OBSIDIAN:0)
Block(2,31,3,OBSIDIAN:0)
Block(2,31,4,STONE:3)
Block(2,31,5,STONE:3)
Block(2,31,6,STONE:3)
Block(2,31,7,STONE:3)
Block(2,31,8,STONE:3)
Block(2,32,-7,STONE:3)
Block(2,32,-6,STONE:3)
Block(2,32,-5,STONE:3)
Block(2,32,-4,STONE:3)
Block(2,32,-3,STONE:3)
Block(2,32,-2,STONE:3)
Block(2,32,-1,OBSIDIAN:0)
Block(2,32,0,STONE:3)
Block(2,32,1,STONE:3)
Block(2,32,2,STONE:3)
Block(2,32,3,STONE:3)
Block(2,32,4,STONE:3)
Block(2,32,5,STONE:3)
Block(2,32,6,STONE:3)
Block(2,32,7,STONE:3)
Block(2,32,8,STONE:3)
Block(2,33,-7,STONE:3)
Block(2,33,-6,STONE:3)
Block(2,33,-5,STONE:3)
Block(2,33,-4,STONE:3)
Block(2,33,-3,STONE:3)
Block(2,33,-2,STONE:3)
Block(2,33,-1,STONE:3)
Block(2,33,0,STONE:3)
Block(2,33,1,STONE:3)
Block(2,33,2,STONE:3)
Block(2,33,3,STONE:3)
Block(2,33,4,STONE:3)
Block(2,33,5,STONE:3)
Block(2,33,6,STONE:3)
Block(2,33,7,STONE:3)
Block(2,33,8,STONE:3)
Block(2,34,-7,STONE:3)
Block(2,34,-6,STONE:3)
Block(2,34,-5,OBSIDIAN:0)
Block(2,34,-4,STONE:3)
Block(2,34,-3,STONE:3)
Block(2,34,-2,STONE:3)
Block(2,34,-1,STONE:3)
Block(2,34,0,STONE:3)
Block(2,34,1,STONE:3)
Block(2,34,2,STONE:3)
Block(2,34,3,STONE:3)
Block(2,34,4,STONE:3)
Block(2,34,5,STONE:3)
Block(2,34,6,STONE:3)
Block(2,34,7,STONE:3)
Block(2,34,8,STONE:3)
Block(2,35,-7,OBSIDIAN:0)
Block(2,35,-6,OBSIDIAN:0)
Block(2,35,-5,OBSIDIAN:0)
Block(2,35,-4,STONE:3)
Block(2,35,-3,STONE:3)
Block(2,35,-2,STONE:3)
Block(2,35,-1,STONE:3)
Block(2,35,0,STONE:3)
Block(2,35,1,STONE:3)
Block(2,35,2,STONE:3)
Block(2,35,3,STONE:3)
Block(2,35,4,STONE:3)
Block(2,35,5,STONE:3)
Block(2,35,6,STONE:3)
Block(2,35,7,STONE:3)
Block(2,35,8,STONE:3)
Block(2,36,-7,OBSIDIAN:0)
Block(2,36,-6,OBSIDIAN:0)
Block(2,36,-5,OBSIDIAN:0)
Block(2,36,-4,STONE:3)
Block(2,36,-3,STONE:3)
Block(2,36,-2,STONE:3)
Block(2,36,-1,STONE:3)
Block(2,36,0,STONE:3)
Block(2,36,1,STONE:3)
Block(2,36,2,STONE:3)
Block(2,36,3,OBSIDIAN:0)
Block(2,36,4,STONE:3)
Block(2,36,5,STONE:3)
Block(2,36,6,STONE:3)
Block(2,36,7,STONE:3)
Block(2,36,8,STONE:3)
Block(2,37,-7,OBSIDIAN:0)
Block(2,37,-6,OBSIDIAN:0)
Block(2,37,-5,OBSIDIAN:0)
Block(2,37,-4,OBSIDIAN:0)
Block(2,37,-3,STONE:3)
Block(2,37,-2,STONE:3)
Block(2,37,-1,STONE:3)
Block(2,37,0,STONE:3)
Block(2,37,1,STONE:3)
Block(2,37,2,STONE:3)
Block(2,37,3,OBSIDIAN:0)
Block(2,37,4,STONE:3)
Block(2,37,5,STONE:3)
Block(2,37,6,STONE:3)
Block(2,37,7,STONE:3)
Block(2,37,8,STONE:3)
Block(2,38,-7,OBSIDIAN:0)
Block(2,38,-6,OBSIDIAN:0)
Block(2,38,-5,OBSIDIAN:0)
Block(2,38,-4,OBSIDIAN:0)
Block(2,38,-3,STONE:3)
Block(2,38,-2,STONE:3)
Block(2,38,-1,STONE:3)
Block(2,38,0,STONE:3)
Block(2,38,1,STONE:3)
Block(2,38,2,STONE:3)
Block(2,38,3,STONE:3)
Block(2,38,4,OBSIDIAN:0)
Block(2,38,5,STONE:3)
Block(2,38,6,STONE:3)
Block(2,38,7,STONE:3)
Block(2,38,8,STONE:3)
Block(2,39,-7,OBSIDIAN:0)
Block(2,39,-6,OBSIDIAN:0)
Block(2,39,-5,OBSIDIAN:0)
Block(2,39,-4,STONE:3)
Block(2,39,-3,STONE:3)
Block(2,39,-2,STONE:3)
Block(2,39,-1,STONE:3)
Block(2,39,0,STONE:3)
Block(2,39,1,STONE:3)
Block(2,39,2,STONE:3)
Block(2,39,3,STONE:3)
Block(2,39,4,STONE:3)
Block(2,39,5,STONE:3)
Block(2,39,6,STONE:3)
Block(2,39,7,STONE:5)
Block(2,39,8,STONE:5)
Block(2,40,-7,OBSIDIAN:0)
Block(2,40,-6,OBSIDIAN:0)
Block(2,40,-5,OBSIDIAN:0)
Block(2,40,-4,STONE:3)
Block(2,40,-3,STONE:3)
Block(2,40,-2,STONE:3)
Block(2,40,-1,STONE:3)
Block(2,40,0,STONE:3)
Block(2,40,1,STONE:3)
Block(2,40,2,STONE:3)
Block(2,40,3,STONE:3)
Block(2,40,4,STONE:3)
Block(2,40,5,STONE:3)
Block(2,40,6,STONE:5)
Block(2,41,-7,STONE:3)
Block(2,41,-6,STONE:3)
Block(2,41,-5,STONE:3)
Block(2,41,-4,STONE:3)
Block(2,41,-3,STONE:3)
Block(2,41,-2,STONE:3)
Block(2,41,-1,STONE:3)
Block(2,41,0,STONE:3)
Block(2,41,1,STONE:3)
Block(2,41,2,STONE:3)
Block(2,41,3,STONE:3)
Block(2,41,4,STONE:3)
Block(2,41,5,STONE:3)
Block(2,42,-7,STONE:3)
Block(2,42,-6,STONE:3)
Block(2,42,-5,STONE:3)
Block(2,42,-4,STONE:3)
Block(2,42,-3,STONE:3)
Block(2,42,-2,STONE:3)
Block(2,42,-1,STONE:3)
Block(2,42,0,STONE:3)
Block(2,42,1,STONE:3)
Block(2,42,2,STONE:3)
Block(2,42,3,STONE:3)
Block(2,42,4,STONE:3)
Block(2,42,5,STONE:5)
Block(2,43,-7,STONE:3)
Block(2,43,-6,STONE:3)
Block(2,43,-5,STONE:3)
Block(2,43,-4,STONE:3)
Block(2,43,-3,STONE:3)
Block(2,43,-2,STONE:3)
Block(2,43,-1,STONE:3)
Block(2,43,0,STONE:3)
Block(2,43,1,STONE:3)
Block(2,43,2,STONE:3)
Block(2,43,3,STONE:3)
Block(2,44,-7,STONE:3)
Block(2,44,-6,STONE:3)
Block(2,44,-5,STONE:3)
Block(2,44,-4,STONE:3)
Block(2,44,-3,STONE:3)
Block(2,44,-2,STONE:3)
Block(2,44,-1,STONE:3)
Block(2,44,0,STONE:3)
Block(2,44,1,STONE:3)
Block(2,44,2,STONE:3)
Block(2,44,3,STONE:3)
Block(2,44,4,STONE:3)
Block(2,45,-7,STONE:3)
Block(2,45,-6,STONE:3)
Block(2,45,-5,STONE:3)
Block(2,45,-4,STONE:3)
Block(2,45,-3,STONE:3)
Block(2,45,-2,STONE:3)
Block(2,45,-1,STONE:3)
Block(2,45,0,STONE:3)
Block(2,45,1,STONE:3)
Block(2,45,2,STONE:3)
Block(2,45,3,STONE:3)
Block(2,45,4,STONE:3)
Block(2,46,-7,STONE:3)
Block(2,46,-6,STONE:3)
Block(2,46,-5,STONE:3)
Block(2,46,-4,STONE:3)
Block(2,46,-3,STONE:3)
Block(2,46,-2,STONE:3)
Block(2,46,-1,STONE:3)
Block(2,46,0,STONE:3)
Block(2,46,1,STONE:3)
Block(2,46,2,STONE:3)
Block(2,46,3,STONE:3)
Block(2,46,4,STONE:3)
Block(2,47,-7,STONE:3)
Block(2,47,-6,STONE:3)
Block(2,47,-5,STONE:3)
Block(2,47,-4,STONE:3)
Block(2,47,-3,STONE:3)
Block(2,47,-2,STONE:3)
Block(2,47,-1,STONE:3)
Block(2,47,0,STONE:3)
Block(2,47,1,STONE:3)
Block(2,47,2,STONE:3)
Block(2,47,3,STONE:3)
Block(2,47,4,STONE:3)
Block(2,48,-7,STONE:3)
Block(2,48,-6,STONE:3)
Block(2,48,-5,STONE:3)
Block(2,48,-4,STONE:3)
Block(2,48,-3,STONE:3)
Block(2,48,-2,STONE:3)
Block(2,48,-1,STONE:3)
Block(2,48,0,STONE:3)
Block(2,48,1,STONE:3)
Block(2,48,2,STONE:3)
Block(2,48,3,STONE:3)
Block(2,48,4,STONE:5)
Block(2,49,-7,STONE:3)
Block(2,49,-6,STONE:3)
Block(2,49,-5,STONE:3)
Block(2,49,-4,STONE:3)
Block(2,49,-3,STONE:5)
Block(2,49,-2,STONE:3)
Block(2,49,-1,STONE:3)
Block(2,49,0,STONE:3)
Block(2,49,1,STONE:3)
Block(2,49,2,STONE:3)
Block(2,49,3,STONE:5)
Block(2,50,-7,STONE:3)
Block(2,50,-6,STONE:3)
Block(2,50,-5,STONE:3)
Block(2,50,-4,STONE:3)
Block(2,50,-2,STONE:5)
Block(2,50,-1,STONE:5)
Block(2,50,0,STONE:5)
Block(2,50,1,STONE:5)
Block(2,50,2,STONE:5)
Block(2,51,-7,STONE:3)
Block(2,51,-6,STONE:3)
Block(2,51,-5,STONE:3)
Block(2,51,-4,STONE:5)
Block(2,52,-7,STONE:3)
Block(2,52,-6,STONE:3)
Block(2,52,-5,STONE:3)
Block(2,53,-7,STONE:3)
Block(2,53,-6,STONE:3)
Block(2,53,-5,STONE:5)
Block(2,54,-7,STONE:5)
Block(2,54,-6,STONE:5)
Block(3,16,-7,STONE:3)
Block(3,17,-7,STONE:3)
Block(3,17,-6,STONE:3)
Block(3,17,-5,STONE:3)
Block(3,18,-7,STONE:3)
Block(3,18,-6,STONE:3)
Block(3,18,-5,STONE:3)
Block(3,19,-7,STONE:3)
Block(3,19,-6,STONE:3)
Block(3,19,-5,STONE:3)
Block(3,19,-4,STONE:3)
Block(3,19,-3,STONE:3)
Block(3,19,-2,STONE:3)
Block(3,19,-1,STONE:3)
Block(3,20,-7,STONE:3)
Block(3,20,-6,STONE:3)
Block(3,20,-5,STONE:3)
Block(3,20,-4,STONE:3)
Block(3,20,-3,STONE:3)
Block(3,20,-2,STONE:3)
Block(3,20,-1,STONE:3)
Block(3,20,0,STONE:3)
Block(3,20,1,STONE:3)
Block(3,20,2,STONE:3)
Block(3,21,-7,STONE:3)
Block(3,21,-6,STONE:3)
Block(3,21,-5,STONE:3)
Block(3,21,-4,STONE:3)
Block(3,21,-3,STONE:3)
Block(3,21,-2,STONE:3)
Block(3,21,-1,STONE:3)
Block(3,21,0,STONE:3)
Block(3,21,1,STONE:3)
Block(3,21,2,STONE:3)
Block(3,21,3,STONE:3)
Block(3,22,-7,STONE:3)
Block(3,22,-6,STONE:3)
Block(3,22,-5,STONE:3)
Block(3,22,-4,STONE:3)
Block(3,22,-3,STONE:3)
Block(3,22,-2,STONE:3)
Block(3,22,-1,STONE:3)
Block(3,22,0,STONE:3)
Block(3,22,1,STONE:3)
Block(3,22,2,STONE:3)
Block(3,22,3,STONE:3)
Block(3,22,4,STONE:3)
Block(3,23,-7,STONE:3)
Block(3,23,-6,STONE:3)
Block(3,23,-5,STONE:3)
Block(3,23,-4,STONE:3)
Block(3,23,-3,STONE:3)
Block(3,23,-2,STONE:3)
Block(3,23,-1,STONE:3)
Block(3,23,0,STONE:3)
Block(3,23,1,STONE:3)
Block(3,23,2,STONE:3)
Block(3,23,3,STONE:3)
Block(3,23,4,STONE:3)
Block(3,23,5,STONE:3)
Block(3,23,6,STONE:3)
Block(3,23,7,STONE:3)
Block(3,24,-7,OBSIDIAN:0)
Block(3,24,-6,STONE:3)
Block(3,24,-5,STONE:3)
Block(3,24,-4,STONE:3)
Block(3,24,-3,STONE:3)
Block(3,24,-2,STONE:3)
Block(3,24,-1,STONE:3)
Block(3,24,0,STONE:3)
Block(3,24,1,STONE:3)
Block(3,24,2,STONE:3)
Block(3,24,3,STONE:3)
Block(3,24,4,STONE:3)
Block(3,24,5,STONE:3)
Block(3,24,6,STONE:3)
Block(3,24,7,STONE:3)
Block(3,24,8,STONE:3)
Block(3,25,-7,OBSIDIAN:0)
Block(3,25,-6,STONE:3)
Block(3,25,-5,STONE:3)
Block(3,25,-4,STONE:3)
Block(3,25,-3,STONE:3)
Block(3,25,-2,STONE:3)
Block(3,25,-1,STONE:3)
Block(3,25,0,STONE:3)
Block(3,25,1,STONE:3)
Block(3,25,2,STONE:3)
Block(3,25,3,STONE:3)
Block(3,25,4,STONE:3)
Block(3,25,5,STONE:3)
Block(3,25,6,STONE:3)
Block(3,25,7,STONE:3)
Block(3,25,8,STONE:3)
Block(3,26,-7,OBSIDIAN:0)
Block(3,26,-6,STONE:3)
Block(3,26,-5,STONE:3)
Block(3,26,-4,STONE:3)
Block(3,26,-3,STONE:3)
Block(3,26,-2,STONE:3)
Block(3,26,-1,STONE:3)
Block(3,26,0,STONE:3)
Block(3,26,1,STONE:3)
Block(3,26,2,STONE:3)
Block(3,26,3,STONE:3)
Block(3,26,4,STONE:3)
Block(3,26,5,STONE:3)
Block(3,26,6,STONE:3)
Block(3,26,7,STONE:3)
Block(3,26,8,STONE:3)
Block(3,27,-7,OBSIDIAN:0)
Block(3,27,-6,STONE:3)
Block(3,27,-5,STONE:3)
Block(3,27,-4,STONE:3)
Block(3,27,-3,STONE:3)
Block(3,27,-2,STONE:3)
Block(3,27,-1,STONE:3)
Block(3,27,0,STONE:3)
Block(3,27,1,STONE:3)
Block(3,27,2,STONE:3)
Block(3,27,3,STONE:3)
Block(3,27,4,STONE:3)
Block(3,27,5,STONE:3)
Block(3,27,6,STONE:3)
Block(3,27,7,STONE:3)
Block(3,27,8,STONE:3)
Block(3,28,-7,OBSIDIAN:0)
Block(3,28,-6,OBSIDIAN:0)
Block(3,28,-5,STONE:3)
Block(3,28,-4,STONE:3)
Block(3,28,-3,STONE:3)
Block(3,28,-2,STONE:3)
Block(3,28,-1,STONE:3)
Block(3,28,0,STONE:3)
Block(3,28,1,STONE:3)
Block(3,28,2,STONE:3)
Block(3,28,3,STONE:3)
Block(3,28,4,STONE:3)
Block(3,28,5,STONE:3)
Block(3,28,6,STONE:3)
Block(3,28,7,STONE:3)
Block(3,28,8,STONE:3)
Block(3,29,-7,OBSIDIAN:0)
Block(3,29,-6,OBSIDIAN:0)
Block(3,29,-5,OBSIDIAN:0)
Block(3,29,-4,OBSIDIAN:0)
Block(3,29,-3,OBSIDIAN:0)
Block(3,29,-2,OBSIDIAN:0)
Block(3,29,-1,STONE:3)
Block(3,29,0,STONE:3)
Block(3,29,1,STONE:3)
Block(3,29,2,STONE:3)
Block(3,29,3,STONE:3)
Block(3,29,4,STONE:3)
Block(3,29,5,STONE:3)
Block(3,29,6,STONE:3)
Block(3,29,7,STONE:3)
Block(3,29,8,STONE:3)
Block(3,30,-7,OBSIDIAN:0)
Block(3,30,-6,OBSIDIAN:0)
Block(3,30,-5,OBSIDIAN:0)
Block(3,30,-4,OBSIDIAN:0)
Block(3,30,-3,OBSIDIAN:0)
Block(3,30,-2,OBSIDIAN:0)
Block(3,30,-1,OBSIDIAN:0)
Block(3,30,0,OBSIDIAN:0)
Block(3,30,1,STONE:3)
Block(3,30,2,STONE:3)
Block(3,30,3,STONE:3)
Block(3,30,4,STONE:3)
Block(3,30,5,STONE:3)
Block(3,30,6,STONE:3)
Block(3,30,7,STONE:3)
Block(3,30,8,STONE:3)
Block(3,31,-7,OBSIDIAN:0)
Block(3,31,-6,OBSIDIAN:0)
Block(3,31,-5,OBSIDIAN:0)
Block(3,31,-4,OBSIDIAN:0)
Block(3,31,-3,OBSIDIAN:0)
Block(3,31,-2,OBSIDIAN:0)
Block(3,31,-1,OBSIDIAN:0)
Block(3,31,0,OBSIDIAN:0)
Block(3,31,1,OBSIDIAN:0)
Block(3,31,2,OBSIDIAN:0)
Block(3,31,3,OBSIDIAN:0)
Block(3,31,4,STONE:3)
Block(3,31,5,STONE:3)
Block(3,31,6,STONE:3)
Block(3,31,7,STONE:3)
Block(3,31,8,STONE:3)
Block(3,32,-7,OBSIDIAN:0)
Block(3,32,-6,OBSIDIAN:0)
Block(3,32,-5,OBSIDIAN:0)
Block(3,32,-4,OBSIDIAN:0)
Block(3,32,-3,OBSIDIAN:0)
Block(3,32,-2,OBSIDIAN:0)
Block(3,32,-1,OBSIDIAN:0)
Block(3,32,0,OBSIDIAN:0)
Block(3,32,1,OBSIDIAN:0)
Block(3,32,2,OBSIDIAN:0)
Block(3,32,3,OBSIDIAN:0)
Block(3,32,4,STONE:3)
Block(3,32,5,STONE:3)
Block(3,32,6,STONE:3)
Block(3,32,7,STONE:3)
Block(3,32,8,STONE:3)
Block(3,33,-7,OBSIDIAN:0)
Block(3,33,-6,OBSIDIAN:0)
Block(3,33,-5,OBSIDIAN:0)
Block(3,33,-4,OBSIDIAN:0)
Block(3,33,-3,OBSIDIAN:0)
Block(3,33,-2,OBSIDIAN:0)
Block(3,33,-1,OBSIDIAN:0)
Block(3,33,0,OBSIDIAN:0)
Block(3,33,1,OBSIDIAN:0)
Block(3,33,2,OBSIDIAN:0)
Block(3,33,3,OBSIDIAN:0)
Block(3,33,4,STONE:3)
Block(3,33,5,STONE:3)
Block(3,33,6,STONE:3)
Block(3,33,7,STONE:3)
Block(3,33,8,STONE:3)
Block(3,34,-7,OBSIDIAN:0)
Block(3,34,-6,OBSIDIAN:0)
Block(3,34,-5,OBSIDIAN:0)
Block(3,34,-4,OBSIDIAN:0)
Block(3,34,-3,OBSIDIAN:0)
Block(3,34,-2,OBSIDIAN:0)
Block(3,34,-1,OBSIDIAN:0)
Block(3,34,0,OBSIDIAN:0)
Block(3,34,1,OBSIDIAN:0)
Block(3,34,2,OBSIDIAN:0)
Block(3,34,3,OBSIDIAN:0)
Block(3,34,4,STONE:3)
Block(3,34,5,STONE:3)
Block(3,34,6,STONE:3)
Block(3,34,7,STONE:3)
Block(3,34,8,STONE:3)
Block(3,35,-7,OBSIDIAN:0)
Block(3,35,-6,OBSIDIAN:0)
Block(3,35,-5,OBSIDIAN:0)
Block(3,35,-4,OBSIDIAN:0)
Block(3,35,-3,OBSIDIAN:0)
Block(3,35,-2,OBSIDIAN:0)
Block(3,35,-1,OBSIDIAN:0)
Block(3,35,0,OBSIDIAN:0)
Block(3,35,1,OBSIDIAN:0)
Block(3,35,2,OBSIDIAN:0)
Block(3,35,3,OBSIDIAN:0)
Block(3,35,4,STONE:3)
Block(3,35,5,STONE:3)
Block(3,35,6,STONE:3)
Block(3,35,7,STONE:3)
Block(3,35,8,STONE:3)
Block(3,36,-7,OBSIDIAN:0)
Block(3,36,-6,OBSIDIAN:0)
Block(3,36,-5,OBSIDIAN:0)
Block(3,36,-4,OBSIDIAN:0)
Block(3,36,-3,OBSIDIAN:0)
Block(3,36,-2,OBSIDIAN:0)
Block(3,36,-1,OBSIDIAN:0)
Block(3,36,0,OBSIDIAN:0)
Block(3,36,1,OBSIDIAN:0)
Block(3,36,2,OBSIDIAN:0)
Block(3,36,3,OBSIDIAN:0)
Block(3,36,4,STONE:3)
Block(3,36,5,STONE:3)
Block(3,36,6,STONE:3)
Block(3,36,7,STONE:3)
Block(3,36,8,STONE:3)
Block(3,37,-7,OBSIDIAN:0)
Block(3,37,-6,OBSIDIAN:0)
Block(3,37,-5,OBSIDIAN:0)
Block(3,37,-4,OBSIDIAN:0)
Block(3,37,-3,OBSIDIAN:0)
Block(3,37,-2,OBSIDIAN:0)
Block(3,37,-1,OBSIDIAN:0)
Block(3,37,0,OBSIDIAN:0)
Block(3,37,1,OBSIDIAN:0)
Block(3,37,2,OBSIDIAN:0)
Block(3,37,3,OBSIDIAN:0)
Block(3,37,4,OBSIDIAN:0)
Block(3,37,5,STONE:3)
Block(3,37,6,STONE:3)
Block(3,37,7,STONE:3)
Block(3,37,8,STONE:3)
Block(3,38,-7,OBSIDIAN:0)
Block(3,38,-6,OBSIDIAN:0)
Block(3,38,-5,OBSIDIAN:0)
Block(3,38,-4,OBSIDIAN:0)
Block(3,38,-3,OBSIDIAN:0)
Block(3,38,-2,STONE:3)
Block(3,38,-1,STONE:3)
Block(3,38,0,STONE:3)
Block(3,38,1,STONE:3)
Block(3,38,2,STONE:3)
Block(3,38,3,OBSIDIAN:0)
Block(3,38,4,OBSIDIAN:0)
Block(3,38,5,STONE:3)
Block(3,38,6,STONE:3)
Block(3,38,7,STONE:3)
Block(3,38,8,STONE:3)
Block(3,39,-7,OBSIDIAN:0)
Block(3,39,-6,OBSIDIAN:0)
Block(3,39,-5,OBSIDIAN:0)
Block(3,39,-4,OBSIDIAN:0)
Block(3,39,-3,STONE:3)
Block(3,39,-2,STONE:3)
Block(3,39,-1,STONE:3)
Block(3,39,0,STONE:3)
Block(3,39,1,STONE:3)
Block(3,39,2,STONE:3)
Block(3,39,3,STONE:3)
Block(3,39,4,STONE:3)
Block(3,39,5,STONE:3)
Block(3,39,6,STONE:3)
Block(3,39,7,STONE:3)
Block(3,39,8,STONE:5)
Block(3,40,-7,OBSIDIAN:0)
Block(3,40,-6,OBSIDIAN:0)
Block(3,40,-5,OBSIDIAN:0)
Block(3,40,-4,OBSIDIAN:0)
Block(3,40,-3,STONE:3)
Block(3,40,-2,STONE:3)
Block(3,40,-1,STONE:3)
Block(3,40,0,STONE:3)
Block(3,40,1,STONE:3)
Block(3,40,2,STONE:3)
Block(3,40,3,STONE:3)
Block(3,40,4,STONE:3)
Block(3,40,5,STONE:3)
Block(3,40,6,STONE:3)
Block(3,40,7,STONE:5)
Block(3,41,-7,OBSIDIAN:0)
Block(3,41,-6,OBSIDIAN:0)
Block(3,41,-5,OBSIDIAN:0)
Block(3,41,-4,OBSIDIAN:0)
Block(3,41,-3,STONE:3)
Block(3,41,-2,STONE:3)
Block(3,41,-1,STONE:3)
Block(3,41,0,STONE:3)
Block(3,41,1,STONE:3)
Block(3,41,2,STONE:3)
Block(3,41,3,STONE:3)
Block(3,41,4,STONE:3)
Block(3,41,5,STONE:3)
Block(3,41,6,STONE:5)
Block(3,42,-7,OBSIDIAN:0)
Block(3,42,-6,STONE:3)
Block(3,42,-5,STONE:3)
Block(3,42,-4,STONE:3)
Block(3,42,-3,STONE:3)
Block(3,42,-2,STONE:3)
Block(3,42,-1,STONE:3)
Block(3,42,0,STONE:3)
Block(3,42,1,STONE:3)
Block(3,42,2,STONE:3)
Block(3,42,3,STONE:3)
Block(3,42,4,STONE:3)
Block(3,42,5,STONE:3)
Block(3,43,-7,STONE:3)
Block(3,43,-6,STONE:3)
Block(3,43,-5,STONE:3)
Block(3,43,-4,STONE:3)
Block(3,43,-3,STONE:3)
Block(3,43,-2,STONE:3)
Block(3,43,-1,STONE:3)
Block(3,43,0,STONE:3)
Block(3,43,1,STONE:3)
Block(3,43,2,STONE:3)
Block(3,43,3,STONE:3)
Block(3,43,4,STONE:3)
Block(3,43,5,STONE:3)
Block(3,44,-7,STONE:3)
Block(3,44,-6,STONE:3)
Block(3,44,-5,STONE:3)
Block(3,44,-4,STONE:3)
Block(3,44,-3,STONE:3)
Block(3,44,-2,STONE:3)
Block(3,44,-1,STONE:3)
Block(3,44,0,STONE:3)
Block(3,44,1,STONE:3)
Block(3,44,2,STONE:3)
Block(3,44,3,STONE:3)
Block(3,44,4,STONE:3)
Block(3,44,5,STONE:3)
Block(3,45,-7,STONE:3)
Block(3,45,-6,STONE:3)
Block(3,45,-5,STONE:3)
Block(3,45,-4,STONE:3)
Block(3,45,-3,STONE:3)
Block(3,45,-2,STONE:3)
Block(3,45,-1,STONE:3)
Block(3,45,0,STONE:3)
Block(3,45,1,STONE:3)
Block(3,45,2,STONE:3)
Block(3,45,3,STONE:3)
Block(3,45,4,STONE:3)
Block(3,45,5,STONE:3)
Block(3,46,-7,STONE:3)
Block(3,46,-6,STONE:3)
Block(3,46,-5,STONE:3)
Block(3,46,-4,STONE:3)
Block(3,46,-3,STONE:3)
Block(3,46,-2,STONE:3)
Block(3,46,-1,STONE:3)
Block(3,46,0,STONE:3)
Block(3,46,1,STONE:3)
Block(3,46,2,STONE:3)
Block(3,46,3,STONE:3)
Block(3,46,4,STONE:3)
Block(3,46,5,STONE:3)
Block(3,47,-7,STONE:3)
Block(3,47,-6,STONE:3)
Block(3,47,-5,OBSIDIAN:0)
Block(3,47,-4,STONE:3)
Block(3,47,-3,STONE:3)
Block(3,47,-2,STONE:3)
Block(3,47,-1,STONE:3)
Block(3,47,0,STONE:3)
Block(3,47,1,STONE:3)
Block(3,47,2,STONE:3)
Block(3,47,3,STONE:3)
Block(3,47,4,STONE:3)
Block(3,47,5,STONE:5)
Block(3,48,-7,STONE:3)
Block(3,48,-6,OBSIDIAN:0)
Block(3,48,-5,OBSIDIAN:0)
Block(3,48,-4,STONE:3)
Block(3,48,-3,STONE:3)
Block(3,48,-2,STONE:3)
Block(3,48,-1,STONE:3)
Block(3,48,0,STONE:3)
Block(3,48,1,STONE:3)
Block(3,48,2,STONE:3)
Block(3,48,3,STONE:3)
Block(3,48,4,STONE:3)
Block(3,49,-7,STONE:3)
Block(3,49,-6,STONE:3)
Block(3,49,-5,STONE:3)
Block(3,49,-4,STONE:3)
Block(3,49,-3,STONE:3)
Block(3,49,-2,STONE:3)
Block(3,49,-1,STONE:3)
Block(3,49,0,STONE:3)
Block(3,49,1,STONE:3)
Block(3,49,2,STONE:3)
Block(3,49,3,STONE:3)
Block(3,49,4,STONE:3)
Block(3,50,-7,STONE:3)
Block(3,50,-6,STONE:3)
Block(3,50,-5,STONE:3)
Block(3,50,-4,STONE:3)
Block(3,50,-3,STONE:3)
Block(3,50,-2,STONE:3)
Block(3,50,-1,STONE:5)
Block(3,50,0,STONE:5)
Block(3,50,1,STONE:5)
Block(3,50,2,STONE:5)
Block(3,50,3,STONE:5)
Block(3,50,4,STONE:5)
Block(3,51,-7,STONE:3)
Block(3,51,-6,STONE:3)
Block(3,51,-5,STONE:3)
Block(3,51,-4,STONE:3)
Block(3,51,-3,STONE:5)
Block(3,51,-2,STONE:5)
Block(3,52,-7,STONE:3)
Block(3,52,-6,STONE:3)
Block(3,52,-5,STONE:3)
Block(3,52,-4,STONE:3)
Block(3,53,-7,STONE:3)
Block(3,53,-6,STONE:3)
Block(3,53,-5,STONE:3)
Block(3,53,-4,STONE:3)
Block(3,54,-7,STONE:3)
Block(3,54,-6,STONE:3)
Block(3,54,-5,STONE:3)
Block(3,54,-4,STONE:5)
Block(3,55,-7,STONE:5)
Block(3,55,-6,STONE:5)
Block(3,55,-5,STONE:5)
Block(4,14,-7,OBSIDIAN:0)
Block(4,15,-7,STONE:3)
Block(4,16,-7,STONE:3)
Block(4,16,-6,STONE:3)
Block(4,16,-5,STONE:3)
Block(4,17,-7,STONE:3)
Block(4,17,-6,STONE:3)
Block(4,17,-5,STONE:3)
Block(4,17,-4,STONE:3)
Block(4,18,-7,STONE:3)
Block(4,18,-6,STONE:3)
Block(4,18,-5,STONE:3)
Block(4,18,-4,STONE:3)
Block(4,18,-3,STONE:3)
Block(4,19,-7,STONE:3)
Block(4,19,-6,STONE:3)
Block(4,19,-5,STONE:3)
Block(4,19,-4,STONE:3)
Block(4,19,-3,STONE:3)
Block(4,19,-2,STONE:3)
Block(4,19,-1,STONE:3)
Block(4,19,0,STONE:3)
Block(4,20,-7,STONE:3)
Block(4,20,-6,STONE:3)
Block(4,20,-5,STONE:3)
Block(4,20,-4,STONE:3)
Block(4,20,-3,STONE:3)
Block(4,20,-2,STONE:3)
Block(4,20,-1,STONE:3)
Block(4,20,0,STONE:3)
Block(4,20,1,STONE:3)
Block(4,20,2,STONE:3)
Block(4,20,3,STONE:3)
Block(4,21,-7,STONE:3)
Block(4,21,-6,STONE:3)
Block(4,21,-5,STONE:3)
Block(4,21,-4,STONE:3)
Block(4,21,-3,STONE:3)
Block(4,21,-2,STONE:3)
Block(4,21,-1,STONE:3)
Block(4,21,0,STONE:3)
Block(4,21,1,STONE:3)
Block(4,21,2,STONE:3)
Block(4,21,3,STONE:3)
Block(4,21,4,STONE:3)
Block(4,22,-7,STONE:3)
Block(4,22,-6,STONE:3)
Block(4,22,-5,STONE:3)
Block(4,22,-4,STONE:3)
Block(4,22,-3,STONE:3)
Block(4,22,-2,STONE:3)
Block(4,22,-1,STONE:3)
Block(4,22,0,STONE:3)
Block(4,22,1,STONE:3)
Block(4,22,2,STONE:3)
Block(4,22,3,STONE:3)
Block(4,22,4,STONE:3)
Block(4,22,5,STONE:3)
Block(4,22,6,STONE:3)
Block(4,23,-7,OBSIDIAN:0)
Block(4,23,-6,OBSIDIAN:0)
Block(4,23,-5,STONE:3)
Block(4,23,-4,STONE:3)
Block(4,23,-3,STONE:3)
Block(4,23,-2,STONE:3)
Block(4,23,-1,STONE:3)
Block(4,23,0,STONE:3)
Block(4,23,1,STONE:3)
Block(4,23,2,STONE:3)
Block(4,23,3,STONE:3)
Block(4,23,4,STONE:3)
Block(4,23,5,STONE:3)
Block(4,23,6,STONE:3)
Block(4,23,7,STONE:3)
Block(4,23,8,STONE:3)
Block(4,24,-7,OBSIDIAN:0)
Block(4,24,-6,OBSIDIAN:0)
Block(4,24,-5,STONE:3)
Block(4,24,-4,STONE:3)
Block(4,24,-3,STONE:3)
Block(4,24,-2,STONE:3)
Block(4,24,-1,STONE:3)
Block(4,24,0,STONE:3)
Block(4,24,1,STONE:3)
Block(4,24,2,STONE:3)
Block(4,24,3,STONE:3)
Block(4,24,4,STONE:3)
Block(4,24,5,STONE:3)
Block(4,24,6,STONE:3)
Block(4,24,7,STONE:3)
Block(4,24,8,STONE:3)
Block(4,25,-7,OBSIDIAN:0)
Block(4,25,-6,OBSIDIAN:0)
Block(4,25,-5,STONE:3)
Block(4,25,-4,STONE:3)
Block(4,25,-3,STONE:3)
Block(4,25,-2,STONE:3)
Block(4,25,-1,STONE:3)
Block(4,25,0,STONE:3)
Block(4,25,1,STONE:3)
Block(4,25,2,STONE:3)
Block(4,25,3,STONE:3)
Block(4,25,4,STONE:3)
Block(4,25,5,STONE:3)
Block(4,25,6,STONE:3)
Block(4,25,7,STONE:3)
Block(4,25,8,STONE:3)
Block(4,26,-7,OBSIDIAN:0)
Block(4,26,-6,OBSIDIAN:0)
Block(4,26,-5,STONE:3)
Block(4,26,-4,STONE:3)
Block(4,26,-3,STONE:3)
Block(4,26,-2,STONE:3)
Block(4,26,-1,STONE:3)
Block(4,26,0,STONE:3)
Block(4,26,1,STONE:3)
Block(4,26,2,STONE:3)
Block(4,26,3,STONE:3)
Block(4,26,4,STONE:3)
Block(4,26,5,STONE:3)
Block(4,26,6,STONE:3)
Block(4,26,7,STONE:3)
Block(4,26,8,STONE:3)
Block(4,27,-7,OBSIDIAN:0)
Block(4,27,-6,OBSIDIAN:0)
Block(4,27,-5,OBSIDIAN:0)
Block(4,27,-4,STONE:3)
Block(4,27,-3,STONE:3)
Block(4,27,-2,STONE:3)
Block(4,27,-1,STONE:3)
Block(4,27,0,STONE:3)
Block(4,27,1,STONE:3)
Block(4,27,2,STONE:3)
Block(4,27,3,STONE:3)
Block(4,27,4,STONE:3)
Block(4,27,5,STONE:3)
Block(4,27,6,STONE:3)
Block(4,27,7,STONE:3)
Block(4,27,8,STONE:3)
Block(4,28,-7,OBSIDIAN:0)
Block(4,28,-6,OBSIDIAN:0)
Block(4,28,-5,OBSIDIAN:0)
Block(4,28,-4,OBSIDIAN:0)
Block(4,28,-3,OBSIDIAN:0)
Block(4,28,-2,OBSIDIAN:0)
Block(4,28,-1,STONE:3)
Block(4,28,0,STONE:3)
Block(4,28,1,STONE:3)
Block(4,28,2,STONE:3)
Block(4,28,3,STONE:3)
Block(4,28,4,STONE:3)
Block(4,28,5,STONE:3)
Block(4,28,6,STONE:3)
Block(4,28,7,STONE:3)
Block(4,28,8,STONE:3)
Block(4,29,-7,OBSIDIAN:0)
Block(4,29,-6,OBSIDIAN:0)
Block(4,29,-5,OBSIDIAN:0)
Block(4,29,-4,OBSIDIAN:0)
Block(4,29,-3,OBSIDIAN:0)
Block(4,29,-2,OBSIDIAN:0)
Block(4,29,-1,OBSIDIAN:0)
Block(4,29,0,STONE:3)
Block(4,29,1,STONE:3)
Block(4,29,2,STONE:3)
Block(4,29,3,STONE:3)
Block(4,29,4,STONE:3)
Block(4,29,5,STONE:3)
Block(4,29,6,STONE:3)
Block(4,29,7,STONE:3)
Block(4,29,8,STONE:3)
Block(4,30,-7,OBSIDIAN:0)
Block(4,30,-6,OBSIDIAN:0)
Block(4,30,-5,OBSIDIAN:0)
Block(4,30,-4,OBSIDIAN:0)
Block(4,30,-3,OBSIDIAN:0)
Block(4,30,-2,OBSIDIAN:0)
Block(4,30,-1,OBSIDIAN:0)
Block(4,30,0,OBSIDIAN:0)
Block(4,30,1,OBSIDIAN:0)
Block(4,30,2,STONE:3)
Block(4,30,3,STONE:3)
Block(4,30,4,STONE:3)
Block(4,30,5,STONE:3)
Block(4,30,6,STONE:3)
Block(4,30,7,STONE:3)
Block(4,30,8,STONE:3)
Block(4,31,-7,OBSIDIAN:0)
Block(4,31,-6,OBSIDIAN:0)
Block(4,31,-5,OBSIDIAN:0)
Block(4,31,-4,OBSIDIAN:0)
Block(4,31,-3,OBSIDIAN:0)
Block(4,31,-2,OBSIDIAN:0)
Block(4,31,-1,OBSIDIAN:0)
Block(4,31,0,OBSIDIAN:0)
Block(4,31,1,OBSIDIAN:0)
Block(4,31,2,OBSIDIAN:0)
Block(4,31,3,OBSIDIAN:0)
Block(4,31,4,OBSIDIAN:0)
Block(4,31,5,STONE:3)
Block(4,31,6,STONE:3)
Block(4,31,7,STONE:3)
Block(4,31,8,STONE:3)
Block(4,32,-7,OBSIDIAN:0)
Block(4,32,-6,OBSIDIAN:0)
Block(4,32,-5,OBSIDIAN:0)
Block(4,32,-4,OBSIDIAN:0)
Block(4,32,-3,OBSIDIAN:0)
Block(4,32,-2,OBSIDIAN:0)
Block(4,32,-1,OBSIDIAN:0)
Block(4,32,0,OBSIDIAN:0)
Block(4,32,1,OBSIDIAN:0)
Block(4,32,2,OBSIDIAN:0)
Block(4,32,3,OBSIDIAN:0)
Block(4,32,4,OBSIDIAN:0)
Block(4,32,5,STONE:3)
Block(4,32,6,STONE:3)
Block(4,32,7,STONE:3)
Block(4,32,8,STONE:3)
Block(4,33,-7,OBSIDIAN:0)
Block(4,33,-6,OBSIDIAN:0)
Block(4,33,-5,OBSIDIAN:0)
Block(4,33,-4,OBSIDIAN:0)
Block(4,33,-3,OBSIDIAN:0)
Block(4,33,-2,OBSIDIAN:0)
Block(4,33,-1,OBSIDIAN:0)
Block(4,33,0,OBSIDIAN:0)
Block(4,33,1,OBSIDIAN:0)
Block(4,33,2,OBSIDIAN:0)
Block(4,33,3,OBSIDIAN:0)
Block(4,33,4,OBSIDIAN:0)
Block(4,33,5,STONE:3)
Block(4,33,6,STONE:3)
Block(4,33,7,STONE:3)
Block(4,33,8,STONE:3)
Block(4,34,-7,OBSIDIAN:0)
Block(4,34,-6,OBSIDIAN:0)
Block(4,34,-5,OBSIDIAN:0)
Block(4,34,-4,OBSIDIAN:0)
Block(4,34,-3,OBSIDIAN:0)
Block(4,34,-2,OBSIDIAN:0)
Block(4,34,-1,OBSIDIAN:0)
Block(4,34,0,OBSIDIAN:0)
Block(4,34,1,OBSIDIAN:0)
Block(4,34,2,OBSIDIAN:0)
Block(4,34,3,OBSIDIAN:0)
Block(4,34,4,OBSIDIAN:0)
Block(4,34,5,STONE:3)
Block(4,34,6,STONE:3)
Block(4,34,7,STONE:3)
Block(4,34,8,STONE:3)
Block(4,35,-7,OBSIDIAN:0)
Block(4,35,-6,OBSIDIAN:0)
Block(4,35,-5,OBSIDIAN:0)
Block(4,35,-4,OBSIDIAN:0)
Block(4,35,-3,OBSIDIAN:0)
Block(4,35,-2,OBSIDIAN:0)
Block(4,35,-1,OBSIDIAN:0)
Block(4,35,0,OBSIDIAN:0)
Block(4,35,1,OBSIDIAN:0)
Block(4,35,2,OBSIDIAN:0)
Block(4,35,3,OBSIDIAN:0)
Block(4,35,4,OBSIDIAN:0)
Block(4,35,5,STONE:3)
Block(4,35,6,STONE:3)
Block(4,35,7,STONE:3)
Block(4,35,8,STONE:3)
Block(4,36,-7,OBSIDIAN:0)
Block(4,36,-6,OBSIDIAN:0)
Block(4,36,-5,OBSIDIAN:0)
Block(4,36,-4,OBSIDIAN:0)
Block(4,36,-3,OBSIDIAN:0)
Block(4,36,-2,OBSIDIAN:0)
Block(4,36,-1,OBSIDIAN:0)
Block(4,36,0,OBSIDIAN:0)
Block(4,36,1,OBSIDIAN:0)
Block(4,36,2,OBSIDIAN:0)
Block(4,36,3,OBSIDIAN:0)
Block(4,36,4,OBSIDIAN:0)
Block(4,36,5,STONE:3)
Block(4,36,6,STONE:3)
Block(4,36,7,STONE:3)
Block(4,36,8,STONE:3)
Block(4,37,-7,OBSIDIAN:0)
Block(4,37,-6,OBSIDIAN:0)
Block(4,37,-5,OBSIDIAN:0)
Block(4,37,-4,OBSIDIAN:0)
Block(4,37,-3,OBSIDIAN:0)
Block(4,37,-2,OBSIDIAN:0)
Block(4,37,-1,OBSIDIAN:0)
Block(4,37,0,OBSIDIAN:0)
Block(4,37,1,OBSIDIAN:0)
Block(4,37,2,OBSIDIAN:0)
Block(4,37,3,OBSIDIAN:0)
Block(4,37,4,OBSIDIAN:0)
Block(4,37,5,OBSIDIAN:0)
Block(4,37,6,STONE:3)
Block(4,37,7,STONE:3)
Block(4,37,8,STONE:3)
Block(4,38,-7,OBSIDIAN:0)
Block(4,38,-6,OBSIDIAN:0)
Block(4,38,-5,OBSIDIAN:0)
Block(4,38,-4,OBSIDIAN:0)
Block(4,38,-3,OBSIDIAN:0)
Block(4,38,-2,OBSIDIAN:0)
Block(4,38,-1,OBSIDIAN:0)
Block(4,38,0,OBSIDIAN:0)
Block(4,38,1,OBSIDIAN:0)
Block(4,38,2,OBSIDIAN:0)
Block(4,38,3,OBSIDIAN:0)
Block(4,38,4,OBSIDIAN:0)
Block(4,38,5,STONE:3)
Block(4,38,6,STONE:3)
Block(4,38,7,STONE:3)
Block(4,38,8,STONE:3)
Block(4,39,-7,OBSIDIAN:0)
Block(4,39,-6,OBSIDIAN:0)
Block(4,39,-5,OBSIDIAN:0)
Block(4,39,-4,OBSIDIAN:0)
Block(4,39,-3,OBSIDIAN:0)
Block(4,39,-2,OBSIDIAN:0)
Block(4,39,-1,STONE:3)
Block(4,39,0,STONE:3)
Block(4,39,1,STONE:3)
Block(4,39,2,OBSIDIAN:0)
Block(4,39,3,STONE:3)
Block(4,39,4,STONE:3)
Block(4,39,5,STONE:3)
Block(4,39,6,STONE:3)
Block(4,39,7,STONE:3)
Block(4,39,8,STONE:3)
Block(4,40,-7,OBSIDIAN:0)
Block(4,40,-6,OBSIDIAN:0)
Block(4,40,-5,OBSIDIAN:0)
Block(4,40,-4,OBSIDIAN:0)
Block(4,40,-3,OBSIDIAN:0)
Block(4,40,-2,STONE:3)
Block(4,40,-1,STONE:3)
Block(4,40,0,STONE:3)
Block(4,40,1,STONE:3)
Block(4,40,2,STONE:3)
Block(4,40,3,STONE:3)
Block(4,40,4,STONE:3)
Block(4,40,5,STONE:3)
Block(4,40,6,STONE:3)
Block(4,40,7,STONE:3)
Block(4,40,8,STONE:3)
Block(4,41,-7,OBSIDIAN:0)
Block(4,41,-6,OBSIDIAN:0)
Block(4,41,-5,OBSIDIAN:0)
Block(4,41,-4,OBSIDIAN:0)
Block(4,41,-3,OBSIDIAN:0)
Block(4,41,-2,STONE:3)
Block(4,41,-1,STONE:3)
Block(4,41,0,STONE:3)
Block(4,41,1,STONE:3)
Block(4,41,2,STONE:3)
Block(4,41,3,STONE:3)
Block(4,41,4,STONE:3)
Block(4,41,5,STONE:3)
Block(4,41,6,STONE:3)
Block(4,41,7,STONE:3)
Block(4,41,8,STONE:5)
Block(4,42,-7,OBSIDIAN:0)
Block(4,42,-6,OBSIDIAN:0)
Block(4,42,-5,OBSIDIAN:0)
Block(4,42,-4,OBSIDIAN:0)
Block(4,42,-3,OBSIDIAN:0)
Block(4,42,-2,STONE:3)
Block(4,42,-1,STONE:3)
Block(4,42,0,STONE:3)
Block(4,42,1,STONE:3)
Block(4,42,2,STONE:3)
Block(4,42,3,STONE:3)
Block(4,42,4,STONE:3)
Block(4,42,5,STONE:3)
Block(4,42,6,STONE:3)
Block(4,43,-7,OBSIDIAN:0)
Block(4,43,-6,OBSIDIAN:0)
Block(4,43,-5,OBSIDIAN:0)
Block(4,43,-4,OBSIDIAN:0)
Block(4,43,-3,OBSIDIAN:0)
Block(4,43,-2,OBSIDIAN:0)
Block(4,43,-1,STONE:3)
Block(4,43,0,STONE:3)
Block(4,43,1,STONE:3)
Block(4,43,2,STONE:3)
Block(4,43,3,STONE:3)
Block(4,43,4,STONE:3)
Block(4,43,5,STONE:3)
Block(4,43,6,STONE:3)
Block(4,44,-7,OBSIDIAN:0)
Block(4,44,-6,OBSIDIAN:0)
Block(4,44,-5,OBSIDIAN:0)
Block(4,44,-4,OBSIDIAN:0)
Block(4,44,-3,OBSIDIAN:0)
Block(4,44,-2,STONE:3)
Block(4,44,-1,STONE:3)
Block(4,44,0,STONE:3)
Block(4,44,1,STONE:3)
Block(4,44,2,STONE:3)
Block(4,44,3,STONE:3)
Block(4,44,4,STONE:3)
Block(4,44,5,STONE:3)
Block(4,44,6,STONE:3)
Block(4,44,7,STONE:5)
Block(4,45,-7,OBSIDIAN:0)
Block(4,45,-6,OBSIDIAN:0)
Block(4,45,-5,OBSIDIAN:0)
Block(4,45,-4,OBSIDIAN:0)
Block(4,45,-3,STONE:3)
Block(4,45,-2,STONE:3)
Block(4,45,-1,STONE:3)
Block(4,45,0,STONE:3)
Block(4,45,1,STONE:3)
Block(4,45,2,STONE:3)
Block(4,45,3,STONE:3)
Block(4,45,4,STONE:3)
Block(4,45,5,STONE:3)
Block(4,45,6,STONE:3)
Block(4,46,-7,OBSIDIAN:0)
Block(4,46,-6,OBSIDIAN:0)
Block(4,46,-5,OBSIDIAN:0)
Block(4,46,-4,OBSIDIAN:0)
Block(4,46,-3,STONE:3)
Block(4,46,-2,STONE:3)
Block(4,46,-1,STONE:3)
Block(4,46,0,STONE:3)
Block(4,46,1,STONE:3)
Block(4,46,2,STONE:3)
Block(4,46,3,STONE:3)
Block(4,46,4,STONE:3)
Block(4,46,5,STONE:3)
Block(4,46,6,STONE:5)
Block(4,47,-7,OBSIDIAN:0)
Block(4,47,-6,OBSIDIAN:0)
Block(4,47,-5,OBSIDIAN:0)
Block(4,47,-4,OBSIDIAN:0)
Block(4,47,-3,STONE:3)
Block(4,47,-2,STONE:3)
Block(4,47,-1,STONE:3)
Block(4,47,0,STONE:3)
Block(4,47,1,STONE:3)
Block(4,47,2,STONE:3)
Block(4,47,3,STONE:3)
Block(4,47,4,STONE:3)
Block(4,47,5,STONE:3)
Block(4,48,-7,OBSIDIAN:0)
Block(4,48,-6,OBSIDIAN:0)
Block(4,48,-5,OBSIDIAN:0)
Block(4,48,-4,OBSIDIAN:0)
Block(4,48,-3,STONE:3)
Block(4,48,-2,STONE:3)
Block(4,48,-1,STONE:3)
Block(4,48,0,STONE:3)
Block(4,48,1,STONE:3)
Block(4,48,2,STONE:3)
Block(4,48,3,STONE:3)
Block(4,48,4,STONE:3)
Block(4,48,5,STONE:5)
Block(4,49,-7,STONE:3)
Block(4,49,-6,STONE:3)
Block(4,49,-5,STONE:3)
Block(4,49,-4,STONE:3)
Block(4,49,-3,STONE:3)
Block(4,49,-2,STONE:3)
Block(4,49,-1,STONE:3)
Block(4,49,0,STONE:3)
Block(4,49,1,STONE:3)
Block(4,49,2,STONE:3)
Block(4,49,3,STONE:3)
Block(4,49,4,STONE:3)
Block(4,50,-7,STONE:3)
Block(4,50,-6,STONE:3)
Block(4,50,-5,STONE:3)
Block(4,50,-4,STONE:3)
Block(4,50,-3,STONE:3)
Block(4,50,-2,STONE:3)
Block(4,50,-1,STONE:3)
Block(4,50,0,STONE:3)
Block(4,50,1,STONE:3)
Block(4,50,2,STONE:5)
Block(4,50,3,STONE:5)
Block(4,50,4,STONE:5)
Block(4,51,-7,STONE:3)
Block(4,51,-6,STONE:3)
Block(4,51,-5,STONE:3)
Block(4,51,-4,STONE:3)
Block(4,51,-3,STONE:3)
Block(4,51,-2,STONE:5)
Block(4,51,-1,STONE:5)
Block(4,51,0,STONE:5)
Block(4,51,1,STONE:5)
Block(4,52,-7,STONE:3)
Block(4,52,-6,STONE:3)
Block(4,52,-5,STONE:3)
Block(4,52,-4,STONE:3)
Block(4,52,-3,STONE:3)
Block(4,53,-7,STONE:3)
Block(4,53,-6,STONE:3)
Block(4,53,-5,STONE:3)
Block(4,53,-4,STONE:3)
Block(4,53,-3,STONE:3)
Block(4,54,-7,STONE:3)
Block(4,54,-6,STONE:3)
Block(4,54,-5,STONE:3)
Block(4,54,-4,STONE:3)
Block(4,54,-3,STONE:5)
Block(4,55,-7,STONE:3)
Block(4,55,-6,STONE:3)
Block(4,55,-5,STONE:3)
Block(4,55,-4,STONE:5)
Block(4,56,-7,STONE:5)
Block(4,56,-6,STONE:5)
Block(4,56,-5,STONE:5)
Block(5,12,-7,OBSIDIAN:0)
Block(5,13,-7,OBSIDIAN:0)
Block(5,13,-6,STONE:3)
Block(5,13,-5,STONE:3)
Block(5,13,-4,STONE:3)
Block(5,13,-3,STONE:3)
Block(5,14,-7,OBSIDIAN:0)
Block(5,14,-6,STONE:3)
Block(5,14,-5,STONE:3)
Block(5,14,-4,STONE:3)
Block(5,14,-3,STONE:3)
Block(5,14,-2,STONE:3)
Block(5,15,-7,STONE:3)
Block(5,15,-6,STONE:3)
Block(5,15,-5,STONE:3)
Block(5,15,-4,STONE:3)
Block(5,15,-3,STONE:3)
Block(5,15,-2,STONE:3)
Block(5,15,-1,STONE:3)
Block(5,16,-7,STONE:3)
Block(5,16,-6,STONE:3)
Block(5,16,-5,STONE:3)
Block(5,16,-4,STONE:3)
Block(5,16,-3,STONE:3)
Block(5,16,-2,STONE:3)
Block(5,16,-1,STONE:3)
Block(5,17,-7,STONE:3)
Block(5,17,-6,STONE:3)
Block(5,17,-5,STONE:3)
Block(5,17,-4,STONE:3)
Block(5,17,-3,STONE:3)
Block(5,17,-2,STONE:3)
Block(5,17,-1,STONE:3)
Block(5,18,-7,STONE:3)
Block(5,18,-6,STONE:3)
Block(5,18,-5,STONE:3)
Block(5,18,-4,STONE:3)
Block(5,18,-3,STONE:3)
Block(5,18,-2,STONE:3)
Block(5,18,-1,STONE:3)
Block(5,19,-7,STONE:3)
Block(5,19,-6,STONE:3)
Block(5,19,-5,STONE:3)
Block(5,19,-4,STONE:3)
Block(5,19,-3,STONE:3)
Block(5,19,-2,STONE:3)
Block(5,19,-1,STONE:3)
Block(5,19,0,STONE:3)
Block(5,19,1,STONE:3)
Block(5,20,-7,STONE:3)
Block(5,20,-6,STONE:3)
Block(5,20,-5,STONE:3)
Block(5,20,-4,STONE:3)
Block(5,20,-3,STONE:3)
Block(5,20,-2,STONE:3)
Block(5,20,-1,STONE:3)
Block(5,20,0,STONE:3)
Block(5,20,1,STONE:3)
Block(5,20,2,STONE:3)
Block(5,20,3,STONE:3)
Block(5,20,4,STONE:3)
Block(5,21,-7,STONE:3)
Block(5,21,-6,STONE:3)
Block(5,21,-5,STONE:3)
Block(5,21,-4,STONE:3)
Block(5,21,-3,STONE:3)
Block(5,21,-2,STONE:3)
Block(5,21,-1,STONE:3)
Block(5,21,0,STONE:3)
Block(5,21,1,STONE:3)
Block(5,21,2,STONE:3)
Block(5,21,3,STONE:3)
Block(5,21,4,STONE:3)
Block(5,21,5,STONE:3)
Block(5,21,6,STONE:3)
Block(5,22,-7,OBSIDIAN:0)
Block(5,22,-6,STONE:3)
Block(5,22,-5,STONE:3)
Block(5,22,-4,STONE:3)
Block(5,22,-3,STONE:3)
Block(5,22,-2,STONE:3)
Block(5,22,-1,STONE:3)
Block(5,22,0,STONE:3)
Block(5,22,1,STONE:3)
Block(5,22,2,STONE:3)
Block(5,22,3,STONE:3)
Block(5,22,4,STONE:3)
Block(5,22,5,STONE:3)
Block(5,22,6,STONE:3)
Block(5,22,7,STONE:3)
Block(5,22,8,STONE:3)
Block(5,23,-7,OBSIDIAN:0)
Block(5,23,-6,OBSIDIAN:0)
Block(5,23,-5,STONE:3)
Block(5,23,-4,STONE:3)
Block(5,23,-3,STONE:3)
Block(5,23,-2,STONE:3)
Block(5,23,-1,STONE:3)
Block(5,23,0,STONE:3)
Block(5,23,1,STONE:3)
Block(5,23,2,STONE:3)
Block(5,23,3,STONE:3)
Block(5,23,4,STONE:3)
Block(5,23,5,STONE:3)
Block(5,23,6,STONE:3)
Block(5,23,7,STONE:3)
Block(5,23,8,STONE:3)
Block(5,24,-7,OBSIDIAN:0)
Block(5,24,-6,OBSIDIAN:0)
Block(5,24,-5,OBSIDIAN:0)
Block(5,24,-4,OBSIDIAN:0)
Block(5,24,-3,STONE:3)
Block(5,24,-2,STONE:3)
Block(5,24,-1,STONE:3)
Block(5,24,0,STONE:3)
Block(5,24,1,STONE:3)
Block(5,24,2,STONE:3)
Block(5,24,3,STONE:3)
Block(5,24,4,STONE:3)
Block(5,24,5,STONE:3)
Block(5,24,6,STONE:3)
Block(5,24,7,STONE:3)
Block(5,24,8,STONE:3)
Block(5,25,-7,OBSIDIAN:0)
Block(5,25,-6,OBSIDIAN:0)
Block(5,25,-5,OBSIDIAN:0)
Block(5,25,-4,OBSIDIAN:0)
Block(5,25,-3,OBSIDIAN:0)
Block(5,25,-2,OBSIDIAN:0)
Block(5,25,-1,STONE:3)
Block(5,25,0,STONE:3)
Block(5,25,1,STONE:3)
Block(5,25,2,STONE:3)
Block(5,25,3,STONE:3)
Block(5,25,4,STONE:3)
Block(5,25,5,STONE:3)
Block(5,25,6,STONE:3)
Block(5,25,7,STONE:3)
Block(5,25,8,STONE:3)
Block(5,26,-7,OBSIDIAN:0)
Block(5,26,-6,OBSIDIAN:0)
Block(5,26,-5,OBSIDIAN:0)
Block(5,26,-4,OBSIDIAN:0)
Block(5,26,-3,OBSIDIAN:0)
Block(5,26,-2,OBSIDIAN:0)
Block(5,26,-1,STONE:3)
Block(5,26,0,STONE:3)
Block(5,26,1,STONE:3)
Block(5,26,2,STONE:3)
Block(5,26,3,STONE:3)
Block(5,26,4,STONE:3)
Block(5,26,5,STONE:3)
Block(5,26,6,STONE:3)
Block(5,26,7,STONE:3)
Block(5,26,8,STONE:3)
Block(5,27,-7,OBSIDIAN:0)
Block(5,27,-6,OBSIDIAN:0)
Block(5,27,-5,OBSIDIAN:0)
Block(5,27,-4,OBSIDIAN:0)
Block(5,27,-3,OBSIDIAN:0)
Block(5,27,-2,OBSIDIAN:0)
Block(5,27,-1,STONE:3)
Block(5,27,0,STONE:3)
Block(5,27,1,STONE:3)
Block(5,27,2,STONE:3)
Block(5,27,3,STONE:3)
Block(5,27,4,STONE:3)
Block(5,27,5,STONE:3)
Block(5,27,6,STONE:3)
Block(5,27,7,STONE:3)
Block(5,27,8,STONE:3)
Block(5,28,-7,OBSIDIAN:0)
Block(5,28,-6,OBSIDIAN:0)
Block(5,28,-5,OBSIDIAN:0)
Block(5,28,-4,OBSIDIAN:0)
Block(5,28,-3,OBSIDIAN:0)
Block(5,28,-2,OBSIDIAN:0)
Block(5,28,-1,OBSIDIAN:0)
Block(5,28,0,STONE:3)
Block(5,28,1,STONE:3)
Block(5,28,2,STONE:3)
Block(5,28,3,STONE:3)
Block(5,28,4,STONE:3)
Block(5,28,5,STONE:3)
Block(5,28,6,STONE:3)
Block(5,28,7,STONE:3)
Block(5,28,8,STONE:3)
Block(5,29,-7,OBSIDIAN:0)
Block(5,29,-6,OBSIDIAN:0)
Block(5,29,-5,OBSIDIAN:0)
Block(5,29,-4,OBSIDIAN:0)
Block(5,29,-3,OBSIDIAN:0)
Block(5,29,-2,OBSIDIAN:0)
Block(5,29,-1,OBSIDIAN:0)
Block(5,29,0,OBSIDIAN:0)
Block(5,29,1,STONE:3)
Block(5,29,2,STONE:3)
Block(5,29,3,STONE:3)
Block(5,29,4,STONE:3)
Block(5,29,5,STONE:3)
Block(5,29,6,STONE:3)
Block(5,29,7,STONE:3)
Block(5,29,8,STONE:3)
Block(5,30,-7,OBSIDIAN:0)
Block(5,30,-6,OBSIDIAN:0)
Block(5,30,-5,OBSIDIAN:0)
Block(5,30,-4,OBSIDIAN:0)
Block(5,30,-3,OBSIDIAN:0)
Block(5,30,-2,OBSIDIAN:0)
Block(5,30,-1,OBSIDIAN:0)
Block(5,30,0,OBSIDIAN:0)
Block(5,30,1,OBSIDIAN:0)
Block(5,30,2,OBSIDIAN:0)
Block(5,30,3,OBSIDIAN:0)
Block(5,30,4,OBSIDIAN:0)
Block(5,30,5,OBSIDIAN:0)
Block(5,30,6,STONE:3)
Block(5,30,7,STONE:3)
Block(5,30,8,STONE:3)
Block(5,31,-7,OBSIDIAN:0)
Block(5,31,-6,OBSIDIAN:0)
Block(5,31,-5,OBSIDIAN:0)
Block(5,31,-4,OBSIDIAN:0)
Block(5,31,-3,OBSIDIAN:0)
Block(5,31,-2,OBSIDIAN:0)
Block(5,31,-1,OBSIDIAN:0)
Block(5,31,0,OBSIDIAN:0)
Block(5,31,1,OBSIDIAN:0)
Block(5,31,2,OBSIDIAN:0)
Block(5,31,3,OBSIDIAN:0)
Block(5,31,4,OBSIDIAN:0)
Block(5,31,5,OBSIDIAN:0)
Block(5,31,6,STONE:3)
Block(5,31,7,STONE:3)
Block(5,31,8,STONE:3)
Block(5,32,-7,OBSIDIAN:0)
Block(5,32,-6,OBSIDIAN:0)
Block(5,32,-5,OBSIDIAN:0)
Block(5,32,-4,OBSIDIAN:0)
Block(5,32,-3,OBSIDIAN:0)
Block(5,32,-2,OBSIDIAN:0)
Block(5,32,-1,OBSIDIAN:0)
Block(5,32,0,OBSIDIAN:0)
Block(5,32,1,OBSIDIAN:0)
Block(5,32,2,OBSIDIAN:0)
Block(5,32,3,OBSIDIAN:0)
Block(5,32,4,OBSIDIAN:0)
Block(5,32,5,OBSIDIAN:0)
Block(5,32,6,STONE:3)
Block(5,32,7,STONE:3)
Block(5,32,8,STONE:3)
Block(5,33,-7,OBSIDIAN:0)
Block(5,33,-6,OBSIDIAN:0)
Block(5,33,-5,OBSIDIAN:0)
Block(5,33,-4,OBSIDIAN:0)
Block(5,33,-3,OBSIDIAN:0)
Block(5,33,-2,OBSIDIAN:0)
Block(5,33,-1,OBSIDIAN:0)
Block(5,33,0,OBSIDIAN:0)
Block(5,33,1,OBSIDIAN:0)
Block(5,33,2,OBSIDIAN:0)
Block(5,33,3,OBSIDIAN:0)
Block(5,33,4,OBSIDIAN:0)
Block(5,33,5,OBSIDIAN:0)
Block(5,33,6,STONE:3)
Block(5,33,7,STONE:3)
Block(5,33,8,STONE:3)
Block(5,34,-7,OBSIDIAN:0)
Block(5,34,-6,OBSIDIAN:0)
Block(5,34,-5,OBSIDIAN:0)
Block(5,34,-4,OBSIDIAN:0)
Block(5,34,-3,OBSIDIAN:0)
Block(5,34,-2,OBSIDIAN:0)
Block(5,34,-1,OBSIDIAN:0)
Block(5,34,0,OBSIDIAN:0)
Block(5,34,1,OBSIDIAN:0)
Block(5,34,2,OBSIDIAN:0)
Block(5,34,3,OBSIDIAN:0)
Block(5,34,4,OBSIDIAN:0)
Block(5,34,5,OBSIDIAN:0)
Block(5,34,6,STONE:3)
Block(5,34,7,STONE:3)
Block(5,34,8,STONE:3)
Block(5,35,-7,OBSIDIAN:0)
Block(5,35,-6,OBSIDIAN:0)
Block(5,35,-5,OBSIDIAN:0)
Block(5,35,-4,OBSIDIAN:0)
Block(5,35,-3,OBSIDIAN:0)
Block(5,35,-2,OBSIDIAN:0)
Block(5,35,-1,OBSIDIAN:0)
Block(5,35,0,OBSIDIAN:0)
Block(5,35,1,OBSIDIAN:0)
Block(5,35,2,OBSIDIAN:0)
Block(5,35,3,OBSIDIAN:0)
Block(5,35,4,OBSIDIAN:0)
Block(5,35,5,OBSIDIAN:0)
Block(5,35,6,STONE:3)
Block(5,35,7,STONE:3)
Block(5,35,8,STONE:3)
Block(5,36,-7,OBSIDIAN:0)
Block(5,36,-6,OBSIDIAN:0)
Block(5,36,-5,OBSIDIAN:0)
Block(5,36,-4,OBSIDIAN:0)
Block(5,36,-3,OBSIDIAN:0)
Block(5,36,-2,OBSIDIAN:0)
Block(5,36,-1,OBSIDIAN:0)
Block(5,36,0,OBSIDIAN:0)
Block(5,36,1,OBSIDIAN:0)
Block(5,36,2,OBSIDIAN:0)
Block(5,36,3,OBSIDIAN:0)
Block(5,36,4,OBSIDIAN:0)
Block(5,36,5,OBSIDIAN:0)
Block(5,36,6,STONE:3)
Block(5,36,7,STONE:3)
Block(5,36,8,STONE:3)
Block(5,37,-7,OBSIDIAN:0)
Block(5,37,-6,OBSIDIAN:0)
Block(5,37,-5,OBSIDIAN:0)
Block(5,37,-4,OBSIDIAN:0)
Block(5,37,-3,OBSIDIAN:0)
Block(5,37,-2,OBSIDIAN:0)
Block(5,37,-1,OBSIDIAN:0)
Block(5,37,0,OBSIDIAN:0)
Block(5,37,1,OBSIDIAN:0)
Block(5,37,2,OBSIDIAN:0)
Block(5,37,3,OBSIDIAN:0)
Block(5,37,4,OBSIDIAN:0)
Block(5,37,5,OBSIDIAN:0)
Block(5,37,6,STONE:3)
Block(5,37,7,STONE:3)
Block(5,37,8,STONE:3)
Block(5,38,-7,OBSIDIAN:0)
Block(5,38,-6,OBSIDIAN:0)
Block(5,38,-5,OBSIDIAN:0)
Block(5,38,-4,OBSIDIAN:0)
Block(5,38,-3,OBSIDIAN:0)
Block(5,38,-2,OBSIDIAN:0)
Block(5,38,-1,OBSIDIAN:0)
Block(5,38,0,OBSIDIAN:0)
Block(5,38,1,OBSIDIAN:0)
Block(5,38,2,OBSIDIAN:0)
Block(5,38,3,OBSIDIAN:0)
Block(5,38,4,OBSIDIAN:0)
Block(5,38,5,STONE:3)
Block(5,38,6,STONE:3)
Block(5,38,7,STONE:3)
Block(5,38,8,STONE:3)
Block(5,39,-7,OBSIDIAN:0)
Block(5,39,-6,OBSIDIAN:0)
Block(5,39,-5,OBSIDIAN:0)
Block(5,39,-4,OBSIDIAN:0)
Block(5,39,-3,OBSIDIAN:0)
Block(5,39,-2,OBSIDIAN:0)
Block(5,39,-1,OBSIDIAN:0)
Block(5,39,0,OBSIDIAN:0)
Block(5,39,1,OBSIDIAN:0)
Block(5,39,2,OBSIDIAN:0)
Block(5,39,3,OBSIDIAN:0)
Block(5,39,4,STONE:3)
Block(5,39,5,STONE:3)
Block(5,39,6,STONE:3)
Block(5,39,7,STONE:3)
Block(5,39,8,STONE:3)
Block(5,40,-7,OBSIDIAN:0)
Block(5,40,-6,OBSIDIAN:0)
Block(5,40,-5,OBSIDIAN:0)
Block(5,40,-4,OBSIDIAN:0)
Block(5,40,-3,OBSIDIAN:0)
Block(5,40,-2,OBSIDIAN:0)
Block(5,40,-1,OBSIDIAN:0)
Block(5,40,0,OBSIDIAN:0)
Block(5,40,1,OBSIDIAN:0)
Block(5,40,2,STONE:3)
Block(5,40,3,STONE:3)
Block(5,40,4,STONE:3)
Block(5,40,5,STONE:3)
Block(5,40,6,STONE:3)
Block(5,40,7,STONE:3)
Block(5,40,8,STONE:3)
Block(5,41,-7,OBSIDIAN:0)
Block(5,41,-6,OBSIDIAN:0)
Block(5,41,-5,OBSIDIAN:0)
Block(5,41,-4,OBSIDIAN:0)
Block(5,41,-3,OBSIDIAN:0)
Block(5,41,-2,OBSIDIAN:0)
Block(5,41,-1,OBSIDIAN:0)
Block(5,41,0,OBSIDIAN:0)
Block(5,41,1,STONE:3)
Block(5,41,2,STONE:3)
Block(5,41,3,STONE:3)
Block(5,41,4,STONE:3)
Block(5,41,5,STONE:3)
Block(5,41,6,STONE:3)
Block(5,41,7,STONE:3)
Block(5,41,8,STONE:3)
Block(5,42,-7,OBSIDIAN:0)
Block(5,42,-6,OBSIDIAN:0)
Block(5,42,-5,OBSIDIAN:0)
Block(5,42,-4,OBSIDIAN:0)
Block(5,42,-3,OBSIDIAN:0)
Block(5,42,-2,OBSIDIAN:0)
Block(5,42,-1,OBSIDIAN:0)
Block(5,42,0,STONE:3)
Block(5,42,1,STONE:3)
Block(5,42,2,STONE:3)
Block(5,42,3,STONE:3)
Block(5,42,4,STONE:3)
Block(5,42,5,STONE:3)
Block(5,42,6,STONE:3)
Block(5,42,7,STONE:3)
Block(5,42,8,STONE:3)
Block(5,43,-7,OBSIDIAN:0)
Block(5,43,-6,OBSIDIAN:0)
Block(5,43,-5,OBSIDIAN:0)
Block(5,43,-4,OBSIDIAN:0)
Block(5,43,-3,OBSIDIAN:0)
Block(5,43,-2,OBSIDIAN:0)
Block(5,43,-1,OBSIDIAN:0)
Block(5,43,0,STONE:3)
Block(5,43,1,STONE:3)
Block(5,43,2,STONE:3)
Block(5,43,3,STONE:3)
Block(5,43,4,STONE:3)
Block(5,43,5,STONE:3)
Block(5,43,6,STONE:3)
Block(5,43,7,STONE:3)
Block(5,44,-7,OBSIDIAN:0)
Block(5,44,-6,OBSIDIAN:0)
Block(5,44,-5,OBSIDIAN:0)
Block(5,44,-4,OBSIDIAN:0)
Block(5,44,-3,OBSIDIAN:0)
Block(5,44,-2,OBSIDIAN:0)
Block(5,44,-1,STONE:3)
Block(5,44,0,STONE:3)
Block(5,44,1,STONE:3)
Block(5,44,2,STONE:3)
Block(5,44,3,STONE:3)
Block(5,44,4,STONE:3)
Block(5,44,5,STONE:3)
Block(5,44,6,STONE:3)
Block(5,44,7,STONE:3)
Block(5,44,8,STONE:5)
Block(5,45,-7,OBSIDIAN:0)
Block(5,45,-6,OBSIDIAN:0)
Block(5,45,-5,OBSIDIAN:0)
Block(5,45,-4,OBSIDIAN:0)
Block(5,45,-3,OBSIDIAN:0)
Block(5,45,-2,STONE:3)
Block(5,45,-1,STONE:3)
Block(5,45,0,STONE:3)
Block(5,45,1,STONE:3)
Block(5,45,2,STONE:3)
Block(5,45,3,STONE:3)
Block(5,45,4,STONE:3)
Block(5,45,5,STONE:3)
Block(5,45,6,STONE:3)
Block(5,45,7,STONE:3)
Block(5,46,-7,OBSIDIAN:0)
Block(5,46,-6,OBSIDIAN:0)
Block(5,46,-5,OBSIDIAN:0)
Block(5,46,-4,OBSIDIAN:0)
Block(5,46,-3,OBSIDIAN:0)
Block(5,46,-2,STONE:3)
Block(5,46,-1,STONE:3)
Block(5,46,0,STONE:3)
Block(5,46,1,STONE:3)
Block(5,46,2,STONE:3)
Block(5,46,3,STONE:3)
Block(5,46,4,STONE:3)
Block(5,46,5,STONE:3)
Block(5,46,6,STONE:3)
Block(5,46,7,STONE:5)
Block(5,47,-7,OBSIDIAN:0)
Block(5,47,-6,OBSIDIAN:0)
Block(5,47,-5,OBSIDIAN:0)
Block(5,47,-4,OBSIDIAN:0)
Block(5,47,-3,OBSIDIAN:0)
Block(5,47,-2,STONE:3)
Block(5,47,-1,STONE:3)
Block(5,47,0,STONE:3)
Block(5,47,1,STONE:3)
Block(5,47,2,STONE:3)
Block(5,47,3,STONE:3)
Block(5,47,4,STONE:3)
Block(5,47,5,STONE:3)
Block(5,47,6,STONE:5)
Block(5,48,-7,OBSIDIAN:0)
Block(5,48,-6,OBSIDIAN:0)
Block(5,48,-5,OBSIDIAN:0)
Block(5,48,-4,OBSIDIAN:0)
Block(5,48,-3,OBSIDIAN:0)
Block(5,48,-2,STONE:3)
Block(5,48,-1,STONE:3)
Block(5,48,0,STONE:3)
Block(5,48,1,STONE:3)
Block(5,48,2,STONE:3)
Block(5,48,3,STONE:3)
Block(5,48,4,STONE:3)
Block(5,48,5,STONE:3)
Block(5,49,-7,OBSIDIAN:0)
Block(5,49,-6,OBSIDIAN:0)
Block(5,49,-5,OBSIDIAN:0)
Block(5,49,-4,STONE:3)
Block(5,49,-3,STONE:3)
Block(5,49,-2,STONE:3)
Block(5,49,-1,STONE:3)
Block(5,49,0,STONE:3)
Block(5,49,1,STONE:3)
Block(5,49,2,STONE:3)
Block(5,49,3,STONE:3)
Block(5,49,4,STONE:3)
Block(5,49,5,STONE:5)
Block(5,50,-7,STONE:3)
Block(5,50,-6,STONE:3)
Block(5,50,-5,STONE:3)
Block(5,50,-4,STONE:3)
Block(5,50,-3,STONE:3)
Block(5,50,-2,STONE:3)
Block(5,50,-1,STONE:3)
Block(5,50,0,STONE:3)
Block(5,50,1,STONE:3)
Block(5,50,2,STONE:3)
Block(5,50,3,STONE:5)
Block(5,50,4,STONE:5)
Block(5,51,-7,STONE:3)
Block(5,51,-6,STONE:3)
Block(5,51,-5,STONE:3)
Block(5,51,-4,STONE:3)
Block(5,51,-3,STONE:3)
Block(5,51,-2,STONE:3)
Block(5,51,-1,STONE:3)
Block(5,51,0,STONE:3)
Block(5,51,1,STONE:3)
Block(5,51,2,STONE:5)
Block(5,52,-7,STONE:3)
Block(5,52,-6,STONE:3)
Block(5,52,-5,STONE:3)
Block(5,52,-4,STONE:3)
Block(5,52,-3,STONE:3)
Block(5,52,-2,STONE:3)
Block(5,52,-1,STONE:5)
Block(5,52,0,STONE:5)
Block(5,52,1,STONE:5)
Block(5,53,-7,STONE:3)
Block(5,53,-6,STONE:3)
Block(5,53,-5,STONE:3)
Block(5,53,-4,STONE:3)
Block(5,53,-3,STONE:3)
Block(5,53,-2,STONE:5)
Block(5,54,-7,OBSIDIAN:0)
Block(5,54,-6,STONE:3)
Block(5,54,-5,STONE:3)
Block(5,54,-4,STONE:3)
Block(5,54,-3,STONE:3)
Block(5,55,-7,OBSIDIAN:0)
Block(5,55,-6,OBSIDIAN:0)
Block(5,55,-5,STONE:3)
Block(5,55,-4,STONE:3)
Block(5,55,-3,STONE:5)
Block(5,56,-7,STONE:3)
Block(5,56,-6,STONE:3)
Block(5,56,-5,STONE:5)
Block(5,56,-4,STONE:5)
Block(5,57,-7,STONE:5)
Block(5,57,-6,STONE:5)
Block(6,11,-7,OBSIDIAN:0)
Block(6,12,-7,OBSIDIAN:0)
Block(6,12,-6,STONE:3)
Block(6,12,-5,STONE:3)
Block(6,12,-4,STONE:3)
Block(6,13,-7,OBSIDIAN:0)
Block(6,13,-6,STONE:3)
Block(6,13,-5,STONE:3)
Block(6,13,-4,STONE:3)
Block(6,13,-3,STONE:3)
Block(6,13,-2,STONE:3)
Block(6,14,-7,STONE:3)
Block(6,14,-6,STONE:3)
Block(6,14,-5,STONE:3)
Block(6,14,-4,STONE:3)
Block(6,14,-3,STONE:3)
Block(6,14,-2,STONE:3)
Block(6,14,-1,STONE:3)
Block(6,15,-7,STONE:3)
Block(6,15,-6,STONE:3)
Block(6,15,-5,STONE:3)
Block(6,15,-4,STONE:3)
Block(6,15,-3,STONE:3)
Block(6,15,-2,STONE:3)
Block(6,15,-1,STONE:3)
Block(6,16,-7,STONE:3)
Block(6,16,-6,STONE:3)
Block(6,16,-5,STONE:3)
Block(6,16,-4,STONE:3)
Block(6,16,-3,STONE:3)
Block(6,16,-2,STONE:3)
Block(6,16,-1,STONE:3)
Block(6,16,0,STONE:3)
Block(6,17,-7,STONE:3)
Block(6,17,-6,STONE:3)
Block(6,17,-5,STONE:3)
Block(6,17,-4,STONE:3)
Block(6,17,-3,STONE:3)
Block(6,17,-2,STONE:3)
Block(6,17,-1,STONE:3)
Block(6,17,0,STONE:3)
Block(6,18,-7,STONE:3)
Block(6,18,-6,STONE:3)
Block(6,18,-5,STONE:3)
Block(6,18,-4,STONE:3)
Block(6,18,-3,STONE:3)
Block(6,18,-2,STONE:3)
Block(6,18,-1,STONE:3)
Block(6,18,0,STONE:3)
Block(6,18,5,STONE:3)
Block(6,19,-7,STONE:3)
Block(6,19,-6,STONE:3)
Block(6,19,-5,STONE:3)
Block(6,19,-4,STONE:3)
Block(6,19,-3,STONE:3)
Block(6,19,-2,STONE:3)
Block(6,19,-1,STONE:3)
Block(6,19,0,STONE:3)
Block(6,19,1,STONE:3)
Block(6,19,2,STONE:3)
Block(6,19,3,STONE:3)
Block(6,19,4,STONE:3)
Block(6,19,5,STONE:3)
Block(6,19,6,STONE:3)
Block(6,20,-7,STONE:3)
Block(6,20,-6,STONE:3)
Block(6,20,-5,STONE:3)
Block(6,20,-4,STONE:3)
Block(6,20,-3,STONE:3)
Block(6,20,-2,STONE:3)
Block(6,20,-1,STONE:3)
Block(6,20,0,STONE:3)
Block(6,20,1,STONE:3)
Block(6,20,2,STONE:3)
Block(6,20,3,STONE:3)
Block(6,20,4,STONE:3)
Block(6,20,5,STONE:3)
Block(6,20,6,STONE:3)
Block(6,20,7,STONE:3)
Block(6,21,-7,OBSIDIAN:0)
Block(6,21,-6,STONE:3)
Block(6,21,-5,STONE:3)
Block(6,21,-4,STONE:3)
Block(6,21,-3,STONE:3)
Block(6,21,-2,STONE:3)
Block(6,21,-1,STONE:3)
Block(6,21,0,STONE:3)
Block(6,21,1,STONE:3)
Block(6,21,2,STONE:3)
Block(6,21,3,STONE:3)
Block(6,21,4,STONE:3)
Block(6,21,5,STONE:3)
Block(6,21,6,STONE:3)
Block(6,21,7,STONE:3)
Block(6,21,8,STONE:3)
Block(6,22,-7,OBSIDIAN:0)
Block(6,22,-6,OBSIDIAN:0)
Block(6,22,-5,STONE:3)
Block(6,22,-4,STONE:3)
Block(6,22,-3,STONE:3)
Block(6,22,-2,STONE:3)
Block(6,22,-1,STONE:3)
Block(6,22,0,STONE:3)
Block(6,22,1,STONE:3)
Block(6,22,2,STONE:3)
Block(6,22,3,STONE:3)
Block(6,22,4,STONE:3)
Block(6,22,5,STONE:3)
Block(6,22,6,STONE:3)
Block(6,22,7,STONE:3)
Block(6,22,8,STONE:3)
Block(6,23,-7,OBSIDIAN:0)
Block(6,23,-6,OBSIDIAN:0)
Block(6,23,-5,OBSIDIAN:0)
Block(6,23,-4,STONE:3)
Block(6,23,-3,STONE:3)
Block(6,23,-2,STONE:3)
Block(6,23,-1,STONE:3)
Block(6,23,0,STONE:3)
Block(6,23,1,STONE:3)
Block(6,23,2,STONE:3)
Block(6,23,3,STONE:3)
Block(6,23,4,STONE:3)
Block(6,23,5,STONE:3)
Block(6,23,6,STONE:3)
Block(6,23,7,STONE:3)
Block(6,23,8,STONE:3)
Block(6,24,-7,OBSIDIAN:0)
Block(6,24,-6,OBSIDIAN:0)
Block(6,24,-5,OBSIDIAN:0)
Block(6,24,-4,OBSIDIAN:0)
Block(6,24,-3,OBSIDIAN:0)
Block(6,24,-2,OBSIDIAN:0)
Block(6,24,-1,OBSIDIAN:0)
Block(6,24,0,STONE:3)
Block(6,24,1,STONE:3)
Block(6,24,2,STONE:3)
Block(6,24,3,STONE:3)
Block(6,24,4,STONE:3)
Block(6,24,5,STONE:3)
Block(6,24,6,STONE:3)
Block(6,24,7,STONE:3)
Block(6,24,8,STONE:3)
Block(6,25,-7,OBSIDIAN:0)
Block(6,25,-6,OBSIDIAN:0)
Block(6,25,-5,OBSIDIAN:0)
Block(6,25,-4,OBSIDIAN:0)
Block(6,25,-3,OBSIDIAN:0)
Block(6,25,-2,OBSIDIAN:0)
Block(6,25,-1,OBSIDIAN:0)
Block(6,25,0,STONE:3)
Block(6,25,1,STONE:3)
Block(6,25,2,STONE:3)
Block(6,25,3,STONE:3)
Block(6,25,4,STONE:3)
Block(6,25,5,STONE:3)
Block(6,25,6,STONE:3)
Block(6,25,7,STONE:3)
Block(6,25,8,STONE:3)
Block(6,26,-7,OBSIDIAN:0)
Block(6,26,-6,OBSIDIAN:0)
Block(6,26,-5,OBSIDIAN:0)
Block(6,26,-4,OBSIDIAN:0)
Block(6,26,-3,OBSIDIAN:0)
Block(6,26,-2,OBSIDIAN:0)
Block(6,26,-1,OBSIDIAN:0)
Block(6,26,0,STONE:3)
Block(6,26,1,STONE:3)
Block(6,26,2,STONE:3)
Block(6,26,3,STONE:3)
Block(6,26,4,STONE:3)
Block(6,26,5,STONE:3)
Block(6,26,6,STONE:3)
Block(6,26,7,STONE:3)
Block(6,26,8,STONE:3)
Block(6,27,-7,OBSIDIAN:0)
Block(6,27,-6,OBSIDIAN:0)
Block(6,27,-5,OBSIDIAN:0)
Block(6,27,-4,OBSIDIAN:0)
Block(6,27,-3,OBSIDIAN:0)
Block(6,27,-2,OBSIDIAN:0)
Block(6,27,-1,OBSIDIAN:0)
Block(6,27,0,STONE:3)
Block(6,27,1,STONE:3)
Block(6,27,2,STONE:3)
Block(6,27,3,STONE:3)
Block(6,27,4,STONE:3)
Block(6,27,5,STONE:3)
Block(6,27,6,STONE:3)
Block(6,27,7,STONE:3)
Block(6,27,8,STONE:3)
Block(6,28,-7,OBSIDIAN:0)
Block(6,28,-6,OBSIDIAN:0)
Block(6,28,-5,OBSIDIAN:0)
Block(6,28,-4,OBSIDIAN:0)
Block(6,28,-3,OBSIDIAN:0)
Block(6,28,-2,OBSIDIAN:0)
Block(6,28,-1,OBSIDIAN:0)
Block(6,28,0,OBSIDIAN:0)
Block(6,28,1,STONE:3)
Block(6,28,2,STONE:3)
Block(6,28,3,STONE:3)
Block(6,28,4,STONE:3)
Block(6,28,5,STONE:3)
Block(6,28,6,STONE:3)
Block(6,28,7,STONE:3)
Block(6,28,8,STONE:3)
Block(6,29,-7,OBSIDIAN:0)
Block(6,29,-6,OBSIDIAN:0)
Block(6,29,-5,OBSIDIAN:0)
Block(6,29,-4,OBSIDIAN:0)
Block(6,29,-3,OBSIDIAN:0)
Block(6,29,-2,OBSIDIAN:0)
Block(6,29,-1,OBSIDIAN:0)
Block(6,29,0,OBSIDIAN:0)
Block(6,29,1,OBSIDIAN:0)
Block(6,29,2,OBSIDIAN:0)
Block(6,29,3,OBSIDIAN:0)
Block(6,29,4,OBSIDIAN:0)
Block(6,29,5,OBSIDIAN:0)
Block(6,29,6,OBSIDIAN:0)
Block(6,29,7,STONE:3)
Block(6,29,8,STONE:3)
Block(6,30,-7,OBSIDIAN:0)
Block(6,30,-6,OBSIDIAN:0)
Block(6,30,-5,OBSIDIAN:0)
Block(6,30,-4,OBSIDIAN:0)
Block(6,30,-3,OBSIDIAN:0)
Block(6,30,-2,OBSIDIAN:0)
Block(6,30,-1,OBSIDIAN:0)
Block(6,30,0,OBSIDIAN:0)
Block(6,30,1,OBSIDIAN:0)
Block(6,30,2,OBSIDIAN:0)
Block(6,30,3,OBSIDIAN:0)
Block(6,30,4,OBSIDIAN:0)
Block(6,30,5,OBSIDIAN:0)
Block(6,30,6,OBSIDIAN:0)
Block(6,30,7,STONE:3)
Block(6,30,8,STONE:3)
Block(6,31,-7,OBSIDIAN:0)
Block(6,31,-6,OBSIDIAN:0)
Block(6,31,-5,OBSIDIAN:0)
Block(6,31,-4,OBSIDIAN:0)
Block(6,31,-3,OBSIDIAN:0)
Block(6,31,-2,OBSIDIAN:0)
Block(6,31,-1,OBSIDIAN:0)
Block(6,31,0,OBSIDIAN:0)
Block(6,31,1,OBSIDIAN:0)
Block(6,31,2,OBSIDIAN:0)
Block(6,31,3,OBSIDIAN:0)
Block(6,31,4,OBSIDIAN:0)
Block(6,31,5,OBSIDIAN:0)
Block(6,31,6,OBSIDIAN:0)
Block(6,31,7,STONE:3)
Block(6,31,8,STONE:3)
Block(6,32,-7,OBSIDIAN:0)
Block(6,32,-6,OBSIDIAN:0)
Block(6,32,-5,OBSIDIAN:0)
Block(6,32,-4,OBSIDIAN:0)
Block(6,32,-3,OBSIDIAN:0)
Block(6,32,-2,OBSIDIAN:0)
Block(6,32,-1,OBSIDIAN:0)
Block(6,32,0,OBSIDIAN:0)
Block(6,32,1,OBSIDIAN:0)
Block(6,32,2,OBSIDIAN:0)
Block(6,32,3,OBSIDIAN:0)
Block(6,32,4,OBSIDIAN:0)
Block(6,32,5,OBSIDIAN:0)
Block(6,32,6,OBSIDIAN:0)
Block(6,32,7,STONE:3)
Block(6,32,8,STONE:3)
Block(6,33,-7,OBSIDIAN:0)
Block(6,33,-6,OBSIDIAN:0)
Block(6,33,-5,OBSIDIAN:0)
Block(6,33,-4,OBSIDIAN:0)
Block(6,33,-3,OBSIDIAN:0)
Block(6,33,-2,OBSIDIAN:0)
Block(6,33,-1,OBSIDIAN:0)
Block(6,33,0,OBSIDIAN:0)
Block(6,33,1,OBSIDIAN:0)
Block(6,33,2,OBSIDIAN:0)
Block(6,33,3,OBSIDIAN:0)
Block(6,33,4,OBSIDIAN:0)
Block(6,33,5,OBSIDIAN:0)
Block(6,33,6,STONE:3)
Block(6,33,7,STONE:3)
Block(6,33,8,STONE:3)
Block(6,34,-7,OBSIDIAN:0)
Block(6,34,-6,OBSIDIAN:0)
Block(6,34,-5,OBSIDIAN:0)
Block(6,34,-4,OBSIDIAN:0)
Block(6,34,-3,OBSIDIAN:0)
Block(6,34,-2,OBSIDIAN:0)
Block(6,34,-1,OBSIDIAN:0)
Block(6,34,0,OBSIDIAN:0)
Block(6,34,1,OBSIDIAN:0)
Block(6,34,2,OBSIDIAN:0)
Block(6,34,3,OBSIDIAN:0)
Block(6,34,4,OBSIDIAN:0)
Block(6,34,5,OBSIDIAN:0)
Block(6,34,6,STONE:3)
Block(6,34,7,STONE:3)
Block(6,34,8,STONE:3)
Block(6,35,-7,OBSIDIAN:0)
Block(6,35,-6,OBSIDIAN:0)
Block(6,35,-5,OBSIDIAN:0)
Block(6,35,-4,OBSIDIAN:0)
Block(6,35,-3,OBSIDIAN:0)
Block(6,35,-2,OBSIDIAN:0)
Block(6,35,-1,OBSIDIAN:0)
Block(6,35,0,OBSIDIAN:0)
Block(6,35,1,OBSIDIAN:0)
Block(6,35,2,OBSIDIAN:0)
Block(6,35,3,OBSIDIAN:0)
Block(6,35,4,OBSIDIAN:0)
Block(6,35,5,OBSIDIAN:0)
Block(6,35,6,STONE:3)
Block(6,35,7,STONE:3)
Block(6,35,8,STONE:3)
Block(6,36,-7,OBSIDIAN:0)
Block(6,36,-6,OBSIDIAN:0)
Block(6,36,-5,OBSIDIAN:0)
Block(6,36,-4,OBSIDIAN:0)
Block(6,36,-3,OBSIDIAN:0)
Block(6,36,-2,OBSIDIAN:0)
Block(6,36,-1,OBSIDIAN:0)
Block(6,36,0,OBSIDIAN:0)
Block(6,36,1,OBSIDIAN:0)
Block(6,36,2,OBSIDIAN:0)
Block(6,36,3,OBSIDIAN:0)
Block(6,36,4,OBSIDIAN:0)
Block(6,36,5,OBSIDIAN:0)
Block(6,36,6,STONE:3)
Block(6,36,7,STONE:3)
Block(6,36,8,STONE:3)
Block(6,37,-7,OBSIDIAN:0)
Block(6,37,-6,OBSIDIAN:0)
Block(6,37,-5,OBSIDIAN:0)
Block(6,37,-4,OBSIDIAN:0)
Block(6,37,-3,OBSIDIAN:0)
Block(6,37,-2,OBSIDIAN:0)
Block(6,37,-1,OBSIDIAN:0)
Block(6,37,0,OBSIDIAN:0)
Block(6,37,1,OBSIDIAN:0)
Block(6,37,2,OBSIDIAN:0)
Block(6,37,3,OBSIDIAN:0)
Block(6,37,4,OBSIDIAN:0)
Block(6,37,5,OBSIDIAN:0)
Block(6,37,6,STONE:3)
Block(6,37,7,STONE:3)
Block(6,37,8,STONE:3)
Block(6,38,-7,OBSIDIAN:0)
Block(6,38,-6,OBSIDIAN:0)
Block(6,38,-5,OBSIDIAN:0)
Block(6,38,-4,OBSIDIAN:0)
Block(6,38,-3,OBSIDIAN:0)
Block(6,38,-2,OBSIDIAN:0)
Block(6,38,-1,OBSIDIAN:0)
Block(6,38,0,OBSIDIAN:0)
Block(6,38,1,OBSIDIAN:0)
Block(6,38,2,OBSIDIAN:0)
Block(6,38,3,OBSIDIAN:0)
Block(6,38,4,OBSIDIAN:0)
Block(6,38,5,STONE:3)
Block(6,38,6,STONE:3)
Block(6,38,7,STONE:3)
Block(6,38,8,STONE:3)
Block(6,39,-7,OBSIDIAN:0)
Block(6,39,-6,OBSIDIAN:0)
Block(6,39,-5,OBSIDIAN:0)
Block(6,39,-4,OBSIDIAN:0)
Block(6,39,-3,OBSIDIAN:0)
Block(6,39,-2,OBSIDIAN:0)
Block(6,39,-1,OBSIDIAN:0)
Block(6,39,0,OBSIDIAN:0)
Block(6,39,1,OBSIDIAN:0)
Block(6,39,2,OBSIDIAN:0)
Block(6,39,3,OBSIDIAN:0)
Block(6,39,4,STONE:3)
Block(6,39,5,STONE:3)
Block(6,39,6,STONE:3)
Block(6,39,7,STONE:3)
Block(6,39,8,STONE:3)
Block(6,40,-7,OBSIDIAN:0)
Block(6,40,-6,OBSIDIAN:0)
Block(6,40,-5,OBSIDIAN:0)
Block(6,40,-4,OBSIDIAN:0)
Block(6,40,-3,OBSIDIAN:0)
Block(6,40,-2,OBSIDIAN:0)
Block(6,40,-1,OBSIDIAN:0)
Block(6,40,0,OBSIDIAN:0)
Block(6,40,1,OBSIDIAN:0)
Block(6,40,2,OBSIDIAN:0)
Block(6,40,3,STONE:3)
Block(6,40,4,STONE:3)
Block(6,40,5,STONE:3)
Block(6,40,6,STONE:3)
Block(6,40,7,STONE:3)
Block(6,40,8,STONE:3)
Block(6,41,-7,OBSIDIAN:0)
Block(6,41,-6,OBSIDIAN:0)
Block(6,41,-5,OBSIDIAN:0)
Block(6,41,-4,OBSIDIAN:0)
Block(6,41,-3,OBSIDIAN:0)
Block(6,41,-2,OBSIDIAN:0)
Block(6,41,-1,OBSIDIAN:0)
Block(6,41,0,OBSIDIAN:0)
Block(6,41,1,OBSIDIAN:0)
Block(6,41,2,STONE:3)
Block(6,41,3,STONE:3)
Block(6,41,4,STONE:3)
Block(6,41,5,STONE:3)
Block(6,41,6,STONE:3)
Block(6,41,7,STONE:3)
Block(6,41,8,STONE:3)
Block(6,42,-7,OBSIDIAN:0)
Block(6,42,-6,OBSIDIAN:0)
Block(6,42,-5,OBSIDIAN:0)
Block(6,42,-4,OBSIDIAN:0)
Block(6,42,-3,OBSIDIAN:0)
Block(6,42,-2,OBSIDIAN:0)
Block(6,42,-1,OBSIDIAN:0)
Block(6,42,0,OBSIDIAN:0)
Block(6,42,1,STONE:3)
Block(6,42,2,STONE:3)
Block(6,42,3,STONE:3)
Block(6,42,4,STONE:3)
Block(6,42,5,STONE:3)
Block(6,42,6,STONE:3)
Block(6,42,7,STONE:3)
Block(6,42,8,STONE:3)
Block(6,43,-7,OBSIDIAN:0)
Block(6,43,-6,OBSIDIAN:0)
Block(6,43,-5,OBSIDIAN:0)
Block(6,43,-4,OBSIDIAN:0)
Block(6,43,-3,OBSIDIAN:0)
Block(6,43,-2,OBSIDIAN:0)
Block(6,43,-1,OBSIDIAN:0)
Block(6,43,0,OBSIDIAN:0)
Block(6,43,1,STONE:3)
Block(6,43,2,STONE:3)
Block(6,43,3,STONE:3)
Block(6,43,4,STONE:3)
Block(6,43,5,STONE:3)
Block(6,43,6,STONE:3)
Block(6,43,7,STONE:3)
Block(6,43,8,STONE:3)
Block(6,44,-7,OBSIDIAN:0)
Block(6,44,-6,OBSIDIAN:0)
Block(6,44,-5,OBSIDIAN:0)
Block(6,44,-4,OBSIDIAN:0)
Block(6,44,-3,OBSIDIAN:0)
Block(6,44,-2,OBSIDIAN:0)
Block(6,44,-1,OBSIDIAN:0)
Block(6,44,0,OBSIDIAN:0)
Block(6,44,1,STONE:3)
Block(6,44,2,STONE:3)
Block(6,44,3,STONE:3)
Block(6,44,4,STONE:3)
Block(6,44,5,STONE:3)
Block(6,44,6,STONE:3)
Block(6,44,7,STONE:3)
Block(6,44,8,STONE:3)
Block(6,45,-7,OBSIDIAN:0)
Block(6,45,-6,OBSIDIAN:0)
Block(6,45,-5,OBSIDIAN:0)
Block(6,45,-4,OBSIDIAN:0)
Block(6,45,-3,OBSIDIAN:0)
Block(6,45,-2,OBSIDIAN:0)
Block(6,45,-1,OBSIDIAN:0)
Block(6,45,0,STONE:3)
Block(6,45,1,STONE:3)
Block(6,45,2,STONE:3)
Block(6,45,3,STONE:3)
Block(6,45,4,STONE:3)
Block(6,45,5,STONE:3)
Block(6,45,6,STONE:3)
Block(6,45,7,STONE:3)
Block(6,45,8,STONE:3)
Block(6,46,-7,OBSIDIAN:0)
Block(6,46,-6,OBSIDIAN:0)
Block(6,46,-5,OBSIDIAN:0)
Block(6,46,-4,OBSIDIAN:0)
Block(6,46,-3,OBSIDIAN:0)
Block(6,46,-2,OBSIDIAN:0)
Block(6,46,-1,STONE:3)
Block(6,46,0,STONE:3)
Block(6,46,1,STONE:3)
Block(6,46,2,STONE:3)
Block(6,46,3,STONE:3)
Block(6,46,4,STONE:3)
Block(6,46,5,STONE:3)
Block(6,46,6,STONE:3)
Block(6,46,7,STONE:3)
Block(6,46,8,STONE:5)
Block(6,47,-7,OBSIDIAN:0)
Block(6,47,-6,OBSIDIAN:0)
Block(6,47,-5,OBSIDIAN:0)
Block(6,47,-4,OBSIDIAN:0)
Block(6,47,-3,OBSIDIAN:0)
Block(6,47,-2,OBSIDIAN:0)
Block(6,47,-1,STONE:3)
Block(6,47,0,STONE:3)
Block(6,47,1,STONE:3)
Block(6,47,2,STONE:3)
Block(6,47,3,STONE:3)
Block(6,47,4,STONE:3)
Block(6,47,5,STONE:3)
Block(6,47,6,STONE:3)
Block(6,47,7,STONE:5)
Block(6,48,-7,OBSIDIAN:0)
Block(6,48,-6,OBSIDIAN:0)
Block(6,48,-5,OBSIDIAN:0)
Block(6,48,-4,OBSIDIAN:0)
Block(6,48,-3,OBSIDIAN:0)
Block(6,48,-2,OBSIDIAN:0)
Block(6,48,-1,STONE:3)
Block(6,48,0,STONE:3)
Block(6,48,1,STONE:3)
Block(6,48,2,STONE:3)
Block(6,48,3,STONE:3)
Block(6,48,4,STONE:3)
Block(6,48,5,STONE:3)
Block(6,48,6,STONE:5)
Block(6,49,-7,OBSIDIAN:0)
Block(6,49,-6,OBSIDIAN:0)
Block(6,49,-5,OBSIDIAN:0)
Block(6,49,-4,OBSIDIAN:0)
Block(6,49,-3,OBSIDIAN:0)
Block(6,49,-2,OBSIDIAN:0)
Block(6,49,-1,OBSIDIAN:0)
Block(6,49,0,STONE:3)
Block(6,49,1,STONE:3)
Block(6,49,2,STONE:3)
Block(6,49,3,STONE:3)
Block(6,49,4,STONE:3)
Block(6,49,5,STONE:5)
Block(6,50,-7,OBSIDIAN:0)
Block(6,50,-6,OBSIDIAN:0)
Block(6,50,-5,STONE:3)
Block(6,50,-4,STONE:3)
Block(6,50,-3,STONE:3)
Block(6,50,-2,STONE:3)
Block(6,50,-1,STONE:3)
Block(6,50,0,STONE:3)
Block(6,50,1,STONE:3)
Block(6,50,2,STONE:3)
Block(6,50,3,STONE:3)
Block(6,50,4,STONE:5)
Block(6,51,-7,OBSIDIAN:0)
Block(6,51,-6,OBSIDIAN:0)
Block(6,51,-5,STONE:3)
Block(6,51,-4,STONE:3)
Block(6,51,-3,STONE:3)
Block(6,51,-2,STONE:3)
Block(6,51,-1,STONE:3)
Block(6,51,0,STONE:3)
Block(6,51,1,STONE:3)
Block(6,51,2,STONE:3)
Block(6,51,3,STONE:5)
Block(6,52,-7,OBSIDIAN:0)
Block(6,52,-6,OBSIDIAN:0)
Block(6,52,-5,STONE:3)
Block(6,52,-4,STONE:3)
Block(6,52,-3,STONE:3)
Block(6,52,-2,STONE:3)
Block(6,52,-1,STONE:3)
Block(6,52,0,STONE:3)
Block(6,52,1,STONE:3)
Block(6,52,2,STONE:5)
Block(6,53,-7,OBSIDIAN:0)
Block(6,53,-6,OBSIDIAN:0)
Block(6,53,-5,STONE:3)
Block(6,53,-4,STONE:3)
Block(6,53,-3,STONE:3)
Block(6,53,-2,STONE:3)
Block(6,53,-1,STONE:3)
Block(6,53,0,STONE:3)
Block(6,53,1,STONE:3)
Block(6,54,-7,OBSIDIAN:0)
Block(6,54,-6,OBSIDIAN:0)
Block(6,54,-5,STONE:3)
Block(6,54,-4,STONE:3)
Block(6,54,-3,STONE:3)
Block(6,54,-2,STONE:3)
Block(6,54,-1,STONE:3)
Block(6,54,0,STONE:3)
Block(6,54,1,STONE:5)
Block(6,55,-7,OBSIDIAN:0)
Block(6,55,-6,OBSIDIAN:0)
Block(6,55,-5,OBSIDIAN:0)
Block(6,55,-4,OBSIDIAN:0)
Block(6,55,-3,STONE:3)
Block(6,55,-2,STONE:5)
Block(6,55,-1,STONE:5)
Block(6,55,0,STONE:5)
Block(6,56,-7,OBSIDIAN:0)
Block(6,56,-6,OBSIDIAN:0)
Block(6,56,-5,OBSIDIAN:0)
Block(6,56,-4,STONE:3)
Block(6,56,-3,STONE:5)
Block(6,57,-7,OBSIDIAN:0)
Block(6,57,-6,STONE:3)
Block(6,57,-5,STONE:3)
Block(6,57,-4,STONE:5)
Block(6,58,-7,STONE:3)
Block(6,58,-6,STONE:5)
Block(6,58,-5,STONE:5)
Block(6,59,-7,STONE:5)
Block(7,11,-7,OBSIDIAN:0)
Block(7,11,-6,OBSIDIAN:0)
Block(7,11,-5,STONE:3)
Block(7,12,-7,OBSIDIAN:0)
Block(7,12,-6,STONE:3)
Block(7,12,-5,STONE:3)
Block(7,12,-4,STONE:3)
Block(7,12,-3,STONE:3)
Block(7,12,-2,STONE:3)
Block(7,13,-7,STONE:3)
Block(7,13,-6,STONE:3)
Block(7,13,-5,STONE:3)
Block(7,13,-4,STONE:3)
Block(7,13,-3,STONE:3)
Block(7,13,-2,STONE:3)
Block(7,13,-1,STONE:3)
Block(7,14,-7,STONE:3)
Block(7,14,-6,STONE:3)
Block(7,14,-5,STONE:3)
Block(7,14,-4,STONE:3)
