
#######################################################################
# +-----------------------------------------------------------------+ #
# |                            BO4 object                           | #
# +-----------------------------------------------------------------+ #
#######################################################################

Author: NLBlackEagle

Description: No description given

SettingsMode: WriteDisable


#######################################################################
# +-----------------------------------------------------------------+ #
# |                          Main settings                          | #
# +-----------------------------------------------------------------+ #
#######################################################################

Frequency: 0

SpawnHeight: highestBlock

UseCenterForHighestBlock: true

##############################
# Height Limits for the BO4. #
##############################

MinHeight: 0

MaxHeight: 255

InheritBO3: 

InheritBO3Rotation: NORTH

OverrideChildSettings: true

OverrideParentHeight: false

CanOverride: false

BranchFrequency: 0

BranchFrequencyGroup: 

MustBeBelowOther: false

MustBeInside: 

CannotBeInside: 

ReplacesBO3: 

MustBeInsideWorldBorders: false

CanSpawnOnWater: true

SpawnOnWaterOnly: false

SpawnUnderWater: false

SpawnAtWaterLevel: false

HeightOffset: 0

RemoveAir: false

ReplaceAbove: 

ReplaceBelow: 

ReplaceWithBiomeBlocks: false

ReplaceWithSurfaceBlock: 

ReplaceWithGroundBlock: 

ReplaceWithStoneBlock: 

SmoothRadius: 0

SmoothHeightOffset: 0

SmoothStartTop: false

SmoothStartWood: false

SmoothingSurfaceBlock: 

SmoothingGroundBlock: 

BO3Group: 

IsSpawnPoint: false

DoReplaceBlocks: false


#######################################################################
# +-----------------------------------------------------------------+ #
# |                              Blocks                             | #
# +-----------------------------------------------------------------+ #
#######################################################################

Block(-8,14,1,OBSIDIAN:0)
Block(-8,14,2,OBSIDIAN:0)
Block(-8,14,3,OBSIDIAN:0)
Block(-8,14,4,OBSIDIAN:0)
Block(-8,14,5,MAGMA:0)
Block(-8,14,6,MAGMA:0)
Block(-8,14,7,MAGMA:0)
Block(-8,14,8,MAGMA:0)
Block(-8,15,-3,STONE:3)
Block(-8,15,-2,STONE:3)
Block(-8,15,-1,STONE:3)
Block(-8,15,0,STONE:3)
Block(-8,15,1,OBSIDIAN:0)
Block(-8,15,2,OBSIDIAN:0)
Block(-8,15,3,OBSIDIAN:0)
Block(-8,15,4,OBSIDIAN:0)
Block(-8,15,5,MAGMA:0)
Block(-8,15,6,MAGMA:0)
Block(-8,15,7,MAGMA:0)
Block(-8,15,8,MAGMA:0)
Block(-8,16,-4,STONE:3)
Block(-8,16,-3,STONE:3)
Block(-8,16,-2,STONE:3)
Block(-8,16,-1,STONE:3)
Block(-8,16,0,STONE:3)
Block(-8,16,1,OBSIDIAN:0)
Block(-8,16,2,OBSIDIAN:0)
Block(-8,16,3,OBSIDIAN:0)
Block(-8,16,4,OBSIDIAN:0)
Block(-8,16,5,OBSIDIAN:0)
Block(-8,16,6,MAGMA:0)
Block(-8,16,7,MAGMA:0)
Block(-8,16,8,MAGMA:0)
Block(-8,17,-5,STONE:3)
Block(-8,17,-4,STONE:3)
Block(-8,17,-3,STONE:3)
Block(-8,17,-2,STONE:3)
Block(-8,17,-1,STONE:3)
Block(-8,17,0,STONE:3)
Block(-8,17,1,STONE:3)
Block(-8,17,2,OBSIDIAN:0)
Block(-8,17,3,OBSIDIAN:0)
Block(-8,17,4,OBSIDIAN:0)
Block(-8,17,5,OBSIDIAN:0)
Block(-8,17,6,OBSIDIAN:0)
Block(-8,17,7,OBSIDIAN:0)
Block(-8,17,8,OBSIDIAN:0)
Block(-8,18,-5,STONE:3)
Block(-8,18,-4,STONE:3)
Block(-8,18,-3,STONE:3)
Block(-8,18,-2,STONE:3)
Block(-8,18,-1,STONE:3)
Block(-8,18,0,STONE:3)
Block(-8,18,1,STONE:3)
Block(-8,18,2,STONE:3)
Block(-8,18,3,OBSIDIAN:0)
Block(-8,18,4,OBSIDIAN:0)
Block(-8,18,5,OBSIDIAN:0)
Block(-8,18,6,OBSIDIAN:0)
Block(-8,18,7,OBSIDIAN:0)
Block(-8,18,8,OBSIDIAN:0)
Block(-8,19,-6,STONE:3)
Block(-8,19,-5,STONE:3)
Block(-8,19,-4,STONE:3)
Block(-8,19,-3,STONE:3)
Block(-8,19,-2,STONE:3)
Block(-8,19,-1,STONE:3)
Block(-8,19,0,STONE:3)
Block(-8,19,1,STONE:3)
Block(-8,19,2,STONE:3)
Block(-8,19,3,STONE:3)
Block(-8,19,4,OBSIDIAN:0)
Block(-8,19,5,OBSIDIAN:0)
Block(-8,19,6,OBSIDIAN:0)
Block(-8,19,7,OBSIDIAN:0)
Block(-8,19,8,OBSIDIAN:0)
Block(-8,20,-7,STONE:3)
Block(-8,20,-6,STONE:3)
Block(-8,20,-5,STONE:3)
Block(-8,20,-4,STONE:3)
Block(-8,20,-3,STONE:3)
Block(-8,20,-2,STONE:3)
Block(-8,20,-1,STONE:3)
Block(-8,20,0,STONE:3)
Block(-8,20,1,OBSIDIAN:0)
Block(-8,20,2,OBSIDIAN:0)
Block(-8,20,3,OBSIDIAN:0)
Block(-8,20,4,OBSIDIAN:0)
Block(-8,20,5,OBSIDIAN:0)
Block(-8,20,6,OBSIDIAN:0)
Block(-8,20,7,OBSIDIAN:0)
Block(-8,20,8,OBSIDIAN:0)
Block(-8,21,-7,STONE:3)
Block(-8,21,-6,STONE:3)
Block(-8,21,-5,STONE:3)
Block(-8,21,-4,STONE:3)
Block(-8,21,-3,STONE:3)
Block(-8,21,-2,STONE:3)
Block(-8,21,-1,STONE:3)
Block(-8,21,0,OBSIDIAN:0)
Block(-8,21,1,OBSIDIAN:0)
Block(-8,21,2,OBSIDIAN:0)
Block(-8,21,3,OBSIDIAN:0)
Block(-8,21,4,OBSIDIAN:0)
Block(-8,21,5,OBSIDIAN:0)
Block(-8,21,6,OBSIDIAN:0)
Block(-8,21,7,OBSIDIAN:0)
Block(-8,21,8,OBSIDIAN:0)
Block(-8,22,-7,STONE:3)
Block(-8,22,-6,STONE:3)
Block(-8,22,-5,STONE:3)
Block(-8,22,-4,STONE:3)
Block(-8,22,-3,STONE:3)
Block(-8,22,-2,STONE:3)
Block(-8,22,-1,OBSIDIAN:0)
Block(-8,22,0,OBSIDIAN:0)
Block(-8,22,1,OBSIDIAN:0)
Block(-8,22,2,OBSIDIAN:0)
Block(-8,22,3,OBSIDIAN:0)
Block(-8,22,4,OBSIDIAN:0)
Block(-8,22,5,OBSIDIAN:0)
Block(-8,22,6,OBSIDIAN:0)
Block(-8,22,7,OBSIDIAN:0)
Block(-8,22,8,OBSIDIAN:0)
Block(-8,23,-7,STONE:3)
Block(-8,23,-6,STONE:3)
Block(-8,23,-5,STONE:3)
Block(-8,23,-4,STONE:3)
Block(-8,23,-3,STONE:3)
Block(-8,23,-2,OBSIDIAN:0)
Block(-8,23,-1,OBSIDIAN:0)
Block(-8,23,0,OBSIDIAN:0)
Block(-8,23,1,OBSIDIAN:0)
Block(-8,23,2,OBSIDIAN:0)
Block(-8,23,3,OBSIDIAN:0)
Block(-8,23,4,OBSIDIAN:0)
Block(-8,23,5,OBSIDIAN:0)
Block(-8,23,6,OBSIDIAN:0)
Block(-8,23,7,OBSIDIAN:0)
Block(-8,23,8,OBSIDIAN:0)
Block(-8,24,-7,OBSIDIAN:0)
Block(-8,24,-6,OBSIDIAN:0)
Block(-8,24,-5,OBSIDIAN:0)
Block(-8,24,-4,OBSIDIAN:0)
Block(-8,24,-3,OBSIDIAN:0)
Block(-8,24,-2,OBSIDIAN:0)
Block(-8,24,-1,OBSIDIAN:0)
Block(-8,24,0,OBSIDIAN:0)
Block(-8,24,1,OBSIDIAN:0)
Block(-8,24,2,OBSIDIAN:0)
Block(-8,24,3,OBSIDIAN:0)
Block(-8,24,4,OBSIDIAN:0)
Block(-8,24,5,OBSIDIAN:0)
Block(-8,24,6,OBSIDIAN:0)
Block(-8,24,7,OBSIDIAN:0)
Block(-8,24,8,OBSIDIAN:0)
Block(-8,25,-7,OBSIDIAN:0)
Block(-8,25,-6,OBSIDIAN:0)
Block(-8,25,-5,OBSIDIAN:0)
Block(-8,25,-4,OBSIDIAN:0)
Block(-8,25,-3,OBSIDIAN:0)
Block(-8,25,-2,OBSIDIAN:0)
Block(-8,25,-1,OBSIDIAN:0)
Block(-8,25,0,OBSIDIAN:0)
Block(-8,25,1,OBSIDIAN:0)
Block(-8,25,2,OBSIDIAN:0)
Block(-8,25,3,OBSIDIAN:0)
Block(-8,25,4,OBSIDIAN:0)
Block(-8,25,5,OBSIDIAN:0)
Block(-8,25,6,OBSIDIAN:0)
Block(-8,25,7,OBSIDIAN:0)
Block(-8,25,8,OBSIDIAN:0)
Block(-8,26,-7,OBSIDIAN:0)
Block(-8,26,-6,OBSIDIAN:0)
Block(-8,26,-5,OBSIDIAN:0)
Block(-8,26,-4,OBSIDIAN:0)
Block(-8,26,-3,OBSIDIAN:0)
Block(-8,26,-2,OBSIDIAN:0)
Block(-8,26,-1,OBSIDIAN:0)
Block(-8,26,0,OBSIDIAN:0)
Block(-8,26,1,OBSIDIAN:0)
Block(-8,26,2,OBSIDIAN:0)
Block(-8,26,3,OBSIDIAN:0)
Block(-8,26,4,OBSIDIAN:0)
Block(-8,26,5,OBSIDIAN:0)
Block(-8,26,6,OBSIDIAN:0)
Block(-8,26,7,OBSIDIAN:0)
Block(-8,26,8,OBSIDIAN:0)
Block(-8,27,-7,OBSIDIAN:0)
Block(-8,27,-6,OBSIDIAN:0)
Block(-8,27,-5,OBSIDIAN:0)
Block(-8,27,-4,OBSIDIAN:0)
Block(-8,27,-3,OBSIDIAN:0)
Block(-8,27,-2,OBSIDIAN:0)
Block(-8,27,-1,OBSIDIAN:0)
Block(-8,27,0,OBSIDIAN:0)
Block(-8,27,1,OBSIDIAN:0)
Block(-8,27,2,OBSIDIAN:0)
Block(-8,27,3,OBSIDIAN:0)
Block(-8,27,4,OBSIDIAN:0)
Block(-8,27,5,OBSIDIAN:0)
Block(-8,27,6,OBSIDIAN:0)
Block(-8,27,7,OBSIDIAN:0)
Block(-8,27,8,OBSIDIAN:0)
Block(-8,28,-7,OBSIDIAN:0)
Block(-8,28,-6,OBSIDIAN:0)
Block(-8,28,-5,OBSIDIAN:0)
Block(-8,28,-4,OBSIDIAN:0)
Block(-8,28,-3,OBSIDIAN:0)
Block(-8,28,-2,OBSIDIAN:0)
Block(-8,28,-1,OBSIDIAN:0)
Block(-8,28,0,OBSIDIAN:0)
Block(-8,28,1,OBSIDIAN:0)
Block(-8,28,2,OBSIDIAN:0)
Block(-8,28,3,OBSIDIAN:0)
Block(-8,28,4,OBSIDIAN:0)
Block(-8,28,5,OBSIDIAN:0)
Block(-8,28,6,OBSIDIAN:0)
Block(-8,28,7,OBSIDIAN:0)
Block(-8,28,8,OBSIDIAN:0)
Block(-8,29,-7,OBSIDIAN:0)
Block(-8,29,-6,OBSIDIAN:0)
Block(-8,29,-5,OBSIDIAN:0)
Block(-8,29,-4,OBSIDIAN:0)
Block(-8,29,-3,OBSIDIAN:0)
Block(-8,29,-2,OBSIDIAN:0)
Block(-8,29,-1,OBSIDIAN:0)
Block(-8,29,0,OBSIDIAN:0)
Block(-8,29,1,OBSIDIAN:0)
Block(-8,29,2,OBSIDIAN:0)
Block(-8,29,3,OBSIDIAN:0)
Block(-8,29,4,OBSIDIAN:0)
Block(-8,29,5,OBSIDIAN:0)
Block(-8,29,6,OBSIDIAN:0)
Block(-8,29,7,OBSIDIAN:0)
Block(-8,29,8,OBSIDIAN:0)
Block(-8,30,-7,OBSIDIAN:0)
Block(-8,30,-6,OBSIDIAN:0)
Block(-8,30,-5,OBSIDIAN:0)
Block(-8,30,-4,OBSIDIAN:0)
Block(-8,30,-3,OBSIDIAN:0)
Block(-8,30,-2,OBSIDIAN:0)
Block(-8,30,-1,OBSIDIAN:0)
Block(-8,30,0,OBSIDIAN:0)
Block(-8,30,1,OBSIDIAN:0)
Block(-8,30,2,OBSIDIAN:0)
Block(-8,30,3,OBSIDIAN:0)
Block(-8,30,4,OBSIDIAN:0)
Block(-8,30,5,OBSIDIAN:0)
Block(-8,30,6,OBSIDIAN:0)
Block(-8,30,7,OBSIDIAN:0)
Block(-8,30,8,OBSIDIAN:0)
Block(-8,31,-7,OBSIDIAN:0)
Block(-8,31,-6,OBSIDIAN:0)
Block(-8,31,-5,OBSIDIAN:0)
Block(-8,31,-4,OBSIDIAN:0)
Block(-8,31,-3,OBSIDIAN:0)
Block(-8,31,-2,OBSIDIAN:0)
Block(-8,31,-1,OBSIDIAN:0)
Block(-8,31,0,OBSIDIAN:0)
Block(-8,31,1,OBSIDIAN:0)
Block(-8,31,2,OBSIDIAN:0)
Block(-8,31,3,OBSIDIAN:0)
Block(-8,31,4,OBSIDIAN:0)
Block(-8,31,5,OBSIDIAN:0)
Block(-8,31,6,OBSIDIAN:0)
Block(-8,31,7,OBSIDIAN:0)
Block(-8,31,8,OBSIDIAN:0)
Block(-8,32,-7,OBSIDIAN:0)
Block(-8,32,-6,OBSIDIAN:0)
Block(-8,32,-5,OBSIDIAN:0)
Block(-8,32,-4,OBSIDIAN:0)
Block(-8,32,-3,OBSIDIAN:0)
Block(-8,32,-2,OBSIDIAN:0)
Block(-8,32,-1,OBSIDIAN:0)
Block(-8,32,0,OBSIDIAN:0)
Block(-8,32,1,OBSIDIAN:0)
Block(-8,32,2,OBSIDIAN:0)
Block(-8,32,3,OBSIDIAN:0)
Block(-8,32,4,OBSIDIAN:0)
Block(-8,32,5,OBSIDIAN:0)
Block(-8,32,6,OBSIDIAN:0)
Block(-8,32,7,OBSIDIAN:0)
Block(-8,32,8,OBSIDIAN:0)
Block(-8,33,-7,OBSIDIAN:0)
Block(-8,33,-6,OBSIDIAN:0)
Block(-8,33,-5,OBSIDIAN:0)
Block(-8,33,-4,OBSIDIAN:0)
Block(-8,33,-3,OBSIDIAN:0)
Block(-8,33,-2,OBSIDIAN:0)
Block(-8,33,-1,OBSIDIAN:0)
Block(-8,33,0,OBSIDIAN:0)
Block(-8,33,1,OBSIDIAN:0)
Block(-8,33,2,OBSIDIAN:0)
Block(-8,33,3,OBSIDIAN:0)
Block(-8,33,4,OBSIDIAN:0)
Block(-8,33,5,OBSIDIAN:0)
Block(-8,33,6,OBSIDIAN:0)
Block(-8,33,7,OBSIDIAN:0)
Block(-8,33,8,OBSIDIAN:0)
Block(-8,34,-7,OBSIDIAN:0)
Block(-8,34,-6,OBSIDIAN:0)
Block(-8,34,-5,OBSIDIAN:0)
Block(-8,34,-4,OBSIDIAN:0)
Block(-8,34,-3,OBSIDIAN:0)
Block(-8,34,-2,OBSIDIAN:0)
Block(-8,34,-1,OBSIDIAN:0)
Block(-8,34,0,OBSIDIAN:0)
Block(-8,34,1,OBSIDIAN:0)
Block(-8,34,2,OBSIDIAN:0)
Block(-8,34,3,OBSIDIAN:0)
Block(-8,34,4,OBSIDIAN:0)
Block(-8,34,5,OBSIDIAN:0)
Block(-8,34,6,OBSIDIAN:0)
Block(-8,34,7,OBSIDIAN:0)
Block(-8,34,8,OBSIDIAN:0)
Block(-8,35,-7,OBSIDIAN:0)
Block(-8,35,-6,OBSIDIAN:0)
Block(-8,35,-5,OBSIDIAN:0)
Block(-8,35,-4,OBSIDIAN:0)
Block(-8,35,-3,OBSIDIAN:0)
Block(-8,35,-2,OBSIDIAN:0)
Block(-8,35,-1,OBSIDIAN:0)
Block(-8,35,0,OBSIDIAN:0)
Block(-8,35,1,OBSIDIAN:0)
Block(-8,35,2,OBSIDIAN:0)
Block(-8,35,3,OBSIDIAN:0)
Block(-8,35,4,OBSIDIAN:0)
Block(-8,35,5,OBSIDIAN:0)
Block(-8,35,6,OBSIDIAN:0)
Block(-8,35,7,OBSIDIAN:0)
Block(-8,35,8,OBSIDIAN:0)
Block(-8,36,-7,OBSIDIAN:0)
Block(-8,36,-6,OBSIDIAN:0)
Block(-8,36,-5,OBSIDIAN:0)
Block(-8,36,-4,OBSIDIAN:0)
Block(-8,36,-3,OBSIDIAN:0)
Block(-8,36,-2,OBSIDIAN:0)
Block(-8,36,-1,OBSIDIAN:0)
Block(-8,36,0,OBSIDIAN:0)
Block(-8,36,1,OBSIDIAN:0)
Block(-8,36,2,OBSIDIAN:0)
Block(-8,36,3,OBSIDIAN:0)
Block(-8,36,4,OBSIDIAN:0)
Block(-8,36,5,OBSIDIAN:0)
Block(-8,36,6,OBSIDIAN:0)
Block(-8,36,7,OBSIDIAN:0)
Block(-8,36,8,OBSIDIAN:0)
Block(-8,37,-7,OBSIDIAN:0)
Block(-8,37,-6,OBSIDIAN:0)
Block(-8,37,-5,OBSIDIAN:0)
Block(-8,37,-4,OBSIDIAN:0)
Block(-8,37,-3,OBSIDIAN:0)
Block(-8,37,-2,OBSIDIAN:0)
Block(-8,37,-1,OBSIDIAN:0)
Block(-8,37,0,OBSIDIAN:0)
Block(-8,37,1,OBSIDIAN:0)
Block(-8,37,2,OBSIDIAN:0)
Block(-8,37,3,OBSIDIAN:0)
Block(-8,37,4,OBSIDIAN:0)
Block(-8,37,5,OBSIDIAN:0)
Block(-8,37,6,OBSIDIAN:0)
Block(-8,37,7,OBSIDIAN:0)
Block(-8,37,8,OBSIDIAN:0)
Block(-8,38,-7,OBSIDIAN:0)
Block(-8,38,-6,OBSIDIAN:0)
Block(-8,38,-5,OBSIDIAN:0)
Block(-8,38,-4,OBSIDIAN:0)
Block(-8,38,-3,OBSIDIAN:0)
Block(-8,38,-2,OBSIDIAN:0)
Block(-8,38,-1,OBSIDIAN:0)
Block(-8,38,0,OBSIDIAN:0)
Block(-8,38,1,OBSIDIAN:0)
Block(-8,38,2,OBSIDIAN:0)
Block(-8,38,3,OBSIDIAN:0)
Block(-8,38,4,OBSIDIAN:0)
Block(-8,38,5,OBSIDIAN:0)
Block(-8,38,6,OBSIDIAN:0)
Block(-8,38,7,OBSIDIAN:0)
Block(-8,38,8,OBSIDIAN:0)
Block(-8,39,-7,OBSIDIAN:0)
Block(-8,39,-6,OBSIDIAN:0)
Block(-8,39,-5,OBSIDIAN:0)
Block(-8,39,-4,OBSIDIAN:0)
Block(-8,39,-3,OBSIDIAN:0)
Block(-8,39,-2,OBSIDIAN:0)
Block(-8,39,-1,OBSIDIAN:0)
Block(-8,39,0,OBSIDIAN:0)
Block(-8,39,1,OBSIDIAN:0)
Block(-8,39,2,OBSIDIAN:0)
Block(-8,39,3,OBSIDIAN:0)
Block(-8,39,4,OBSIDIAN:0)
Block(-8,39,5,OBSIDIAN:0)
Block(-8,39,6,OBSIDIAN:0)
Block(-8,39,7,OBSIDIAN:0)
Block(-8,39,8,STONE:5)
Block(-8,40,-7,OBSIDIAN:0)
Block(-8,40,-6,OBSIDIAN:0)
Block(-8,40,-5,OBSIDIAN:0)
Block(-8,40,-4,OBSIDIAN:0)
Block(-8,40,-3,OBSIDIAN:0)
Block(-8,40,-2,OBSIDIAN:0)
Block(-8,40,-1,OBSIDIAN:0)
Block(-8,40,0,OBSIDIAN:0)
Block(-8,40,1,OBSIDIAN:0)
Block(-8,40,2,OBSIDIAN:0)
Block(-8,40,3,OBSIDIAN:0)
Block(-8,40,4,OBSIDIAN:0)
Block(-8,40,5,OBSIDIAN:0)
Block(-8,40,6,STONE:5)
Block(-8,40,7,STONE:5)
Block(-8,40,8,STONE:5)
Block(-8,41,-7,OBSIDIAN:0)
Block(-8,41,-6,OBSIDIAN:0)
Block(-8,41,-5,OBSIDIAN:0)
Block(-8,41,-4,OBSIDIAN:0)
Block(-8,41,-3,OBSIDIAN:0)
Block(-8,41,-2,OBSIDIAN:0)
Block(-8,41,-1,OBSIDIAN:0)
Block(-8,41,0,OBSIDIAN:0)
Block(-8,41,1,OBSIDIAN:0)
Block(-8,41,2,OBSIDIAN:0)
Block(-8,41,3,OBSIDIAN:0)
Block(-8,41,4,OBSIDIAN:0)
Block(-8,41,5,STONE:5)
Block(-8,41,6,STONE:5)
Block(-8,41,7,STONE:5)
Block(-8,41,8,STONE:5)
Block(-8,42,-7,OBSIDIAN:0)
Block(-8,42,-6,OBSIDIAN:0)
Block(-8,42,-5,OBSIDIAN:0)
Block(-8,42,-4,OBSIDIAN:0)
Block(-8,42,-3,OBSIDIAN:0)
Block(-8,42,-2,OBSIDIAN:0)
Block(-8,42,-1,OBSIDIAN:0)
Block(-8,42,0,OBSIDIAN:0)
Block(-8,42,1,OBSIDIAN:0)
Block(-8,42,2,OBSIDIAN:0)
Block(-8,42,3,OBSIDIAN:0)
Block(-8,42,4,STONE:5)
Block(-8,42,5,STONE:5)
Block(-8,42,6,STONE:5)
Block(-8,42,7,GRASS:0)
Block(-8,42,8,GRASS:0)
Block(-8,43,-7,OBSIDIAN:0)
Block(-8,43,-6,OBSIDIAN:0)
Block(-8,43,-5,OBSIDIAN:0)
Block(-8,43,-4,OBSIDIAN:0)
Block(-8,43,-3,OBSIDIAN:0)
Block(-8,43,-2,OBSIDIAN:0)
Block(-8,43,-1,OBSIDIAN:0)
Block(-8,43,0,OBSIDIAN:0)
Block(-8,43,1,OBSIDIAN:0)
Block(-8,43,2,OBSIDIAN:0)
Block(-8,43,3,STONE:5)
Block(-8,43,4,STONE:5)
Block(-8,43,5,STONE:5)
Block(-8,43,6,AIR:0)
Block(-8,43,7,AIR:0)
Block(-8,43,8,AIR:0)
Block(-8,44,-7,OBSIDIAN:0)
Block(-8,44,-6,OBSIDIAN:0)
Block(-8,44,-5,OBSIDIAN:0)
Block(-8,44,-4,OBSIDIAN:0)
Block(-8,44,-3,OBSIDIAN:0)
Block(-8,44,-2,OBSIDIAN:0)
Block(-8,44,-1,OBSIDIAN:0)
Block(-8,44,0,OBSIDIAN:0)
Block(-8,44,1,OBSIDIAN:0)
Block(-8,44,2,OBSIDIAN:0)
Block(-8,44,3,STONE:5)
Block(-8,44,4,STONE:5)
Block(-8,44,5,STONE:5)
Block(-8,44,6,AIR:0)
Block(-8,44,7,AIR:0)
Block(-8,44,8,AIR:0)
Block(-8,45,-7,OBSIDIAN:0)
Block(-8,45,-6,OBSIDIAN:0)
Block(-8,45,-5,OBSIDIAN:0)
Block(-8,45,-4,OBSIDIAN:0)
Block(-8,45,-3,OBSIDIAN:0)
Block(-8,45,-2,OBSIDIAN:0)
Block(-8,45,-1,OBSIDIAN:0)
Block(-8,45,0,OBSIDIAN:0)
Block(-8,45,1,OBSIDIAN:0)
Block(-8,45,2,OBSIDIAN:0)
Block(-8,45,3,STONE:5)
Block(-8,45,4,STONE:5)
Block(-8,45,5,STONE:5)
Block(-8,45,6,AIR:0)
Block(-8,45,7,AIR:0)
Block(-8,45,8,AIR:0)
Block(-8,46,-7,OBSIDIAN:0)
Block(-8,46,-6,OBSIDIAN:0)
Block(-8,46,-5,OBSIDIAN:0)
Block(-8,46,-4,STONE:3)
Block(-8,46,-3,STONE:3)
Block(-8,46,-2,STONE:3)
Block(-8,46,-1,OBSIDIAN:0)
Block(-8,46,0,OBSIDIAN:0)
Block(-8,46,1,STONE:5)
Block(-8,46,2,STONE:5)
Block(-8,46,3,STONE:5)
Block(-8,46,4,STONE:5)
Block(-8,46,5,AIR:0)
Block(-8,46,6,AIR:0)
Block(-8,46,7,AIR:0)
Block(-8,46,8,AIR:0)
Block(-8,47,-7,OBSIDIAN:0)
Block(-8,47,-6,OBSIDIAN:0)
Block(-8,47,-5,STONE:3)
Block(-8,47,-4,STONE:3)
Block(-8,47,-3,STONE:3)
Block(-8,47,-2,STONE:3)
Block(-8,47,-1,STONE:3)
Block(-8,47,0,STONE:3)
Block(-8,47,1,STONE:5)
Block(-8,47,2,STONE:5)
Block(-8,47,3,STONE:5)
Block(-8,47,4,AIR:0)
Block(-8,47,5,AIR:0)
Block(-8,47,6,AIR:0)
Block(-8,47,7,AIR:0)
Block(-8,47,8,AIR:0)
Block(-8,48,-7,OBSIDIAN:0)
Block(-8,48,-6,STONE:3)
Block(-8,48,-5,STONE:3)
Block(-8,48,-4,STONE:3)
Block(-8,48,-3,STONE:3)
Block(-8,48,-2,STONE:3)
Block(-8,48,-1,STONE:3)
Block(-8,48,0,STONE:3)
Block(-8,48,1,STONE:5)
Block(-8,48,2,STONE:5)
Block(-8,48,3,AIR:0)
Block(-8,48,4,AIR:0)
Block(-8,48,5,AIR:0)
Block(-8,48,6,AIR:0)
Block(-8,48,7,AIR:0)
Block(-8,48,8,AIR:0)
Block(-8,49,-7,OBSIDIAN:0)
Block(-8,49,-6,STONE:3)
Block(-8,49,-5,STONE:3)
Block(-8,49,-4,AIR:0)
Block(-8,49,-3,AIR:0)
Block(-8,49,-2,AIR:0)
Block(-8,49,-1,STONE:3)
Block(-8,49,0,STONE:3)
Block(-8,49,1,STONE:5)
Block(-8,49,2,AIR:0)
Block(-8,49,3,AIR:0)
Block(-8,49,4,AIR:0)
Block(-8,49,5,AIR:0)
Block(-8,49,6,AIR:0)
Block(-8,49,7,AIR:0)
Block(-8,49,8,AIR:0)
Block(-8,50,-7,OBSIDIAN:0)
Block(-8,50,-6,STONE:3)
Block(-8,50,-5,STONE:3)
Block(-8,50,-4,AIR:0)
Block(-8,50,-3,AIR:0)
Block(-8,50,-2,AIR:0)
Block(-8,50,-1,AIR:0)
Block(-8,50,0,STONE:5)
Block(-8,50,1,AIR:0)
Block(-8,50,2,AIR:0)
Block(-8,50,3,AIR:0)
Block(-8,50,4,AIR:0)
Block(-8,50,5,AIR:0)
Block(-8,50,6,AIR:0)
Block(-8,50,7,AIR:0)
Block(-8,50,8,AIR:0)
Block(-8,51,-7,OBSIDIAN:0)
Block(-8,51,-6,OBSIDIAN:0)
Block(-8,51,-5,STONE:3)
Block(-8,51,-4,STONE:3)
Block(-8,51,-3,AIR:0)
Block(-8,51,-2,AIR:0)
Block(-8,51,-1,AIR:0)
Block(-8,51,0,AIR:0)
Block(-8,51,1,AIR:0)
Block(-8,51,2,AIR:0)
Block(-8,51,3,AIR:0)
Block(-8,51,4,AIR:0)
Block(-8,51,5,AIR:0)
Block(-8,51,6,AIR:0)
Block(-8,51,7,AIR:0)
Block(-8,51,8,AIR:0)
Block(-8,52,-7,OBSIDIAN:0)
Block(-8,52,-6,OBSIDIAN:0)
Block(-8,52,-5,OBSIDIAN:0)
Block(-8,52,-4,AIR:0)
Block(-8,52,-3,AIR:0)
Block(-8,52,-2,AIR:0)
Block(-8,52,-1,AIR:0)
Block(-8,52,0,AIR:0)
Block(-8,52,1,AIR:0)
Block(-8,52,2,AIR:0)
Block(-8,52,3,AIR:0)
Block(-8,52,4,AIR:0)
Block(-8,52,5,AIR:0)
Block(-8,52,6,AIR:0)
Block(-8,52,7,AIR:0)
Block(-8,52,8,AIR:0)
Block(-8,53,-7,OBSIDIAN:0)
Block(-8,53,-6,OBSIDIAN:0)
Block(-8,53,-5,AIR:0)
Block(-8,53,-4,AIR:0)
Block(-8,53,-3,AIR:0)
Block(-8,53,-2,AIR:0)
Block(-8,53,-1,AIR:0)
Block(-8,53,0,AIR:0)
Block(-8,53,1,AIR:0)
Block(-8,53,2,AIR:0)
Block(-8,53,3,AIR:0)
Block(-8,53,4,AIR:0)
Block(-8,53,5,AIR:0)
Block(-8,53,6,AIR:0)
Block(-8,53,7,AIR:0)
Block(-8,53,8,AIR:0)
Block(-8,54,-7,AIR:0)
Block(-8,54,-6,AIR:0)
Block(-8,54,-5,AIR:0)
Block(-8,54,-4,AIR:0)
Block(-8,54,-3,AIR:0)
Block(-8,54,-2,AIR:0)
Block(-8,54,-1,AIR:0)
Block(-8,54,0,AIR:0)
Block(-8,54,1,AIR:0)
Block(-8,54,2,AIR:0)
Block(-8,54,3,AIR:0)
Block(-8,54,4,AIR:0)
Block(-8,54,5,AIR:0)
Block(-8,54,6,AIR:0)
Block(-8,54,7,AIR:0)
Block(-8,54,8,AIR:0)
Block(-8,55,-7,AIR:0)
Block(-8,55,-6,AIR:0)
Block(-8,55,-5,AIR:0)
Block(-8,55,-4,AIR:0)
Block(-8,55,-3,AIR:0)
Block(-8,55,-2,AIR:0)
Block(-8,55,-1,AIR:0)
Block(-8,55,0,AIR:0)
Block(-8,55,1,AIR:0)
Block(-8,55,2,AIR:0)
Block(-8,55,3,AIR:0)
Block(-8,55,4,AIR:0)
Block(-8,55,5,AIR:0)
Block(-8,55,6,AIR:0)
Block(-8,55,7,AIR:0)
Block(-8,55,8,AIR:0)
Block(-8,56,-7,AIR:0)
Block(-8,56,-6,AIR:0)
Block(-8,56,-5,AIR:0)
Block(-8,56,-4,AIR:0)
Block(-8,56,-3,AIR:0)
Block(-8,56,-2,AIR:0)
Block(-8,56,-1,AIR:0)
Block(-8,56,0,AIR:0)
Block(-8,56,1,AIR:0)
Block(-8,56,2,AIR:0)
Block(-8,56,3,AIR:0)
Block(-8,56,4,AIR:0)
Block(-8,56,5,AIR:0)
Block(-8,56,6,AIR:0)
Block(-8,56,7,AIR:0)
Block(-8,56,8,AIR:0)
Block(-8,57,-7,AIR:0)
Block(-8,57,-6,AIR:0)
Block(-8,57,-5,AIR:0)
Block(-8,57,-4,AIR:0)
Block(-8,57,-3,AIR:0)
Block(-8,57,-2,AIR:0)
Block(-8,57,-1,AIR:0)
Block(-8,57,0,AIR:0)
Block(-8,57,1,AIR:0)
Block(-8,57,2,AIR:0)
Block(-8,57,3,AIR:0)
Block(-8,57,4,AIR:0)
Block(-8,57,5,AIR:0)
Block(-8,57,6,AIR:0)
Block(-8,57,7,AIR:0)
Block(-8,57,8,AIR:0)
Block(-8,58,-7,AIR:0)
Block(-8,58,-6,AIR:0)
Block(-8,58,-5,AIR:0)
Block(-8,58,-4,AIR:0)
Block(-8,58,-3,AIR:0)
Block(-8,58,-2,AIR:0)
Block(-8,58,-1,AIR:0)
Block(-8,58,0,AIR:0)
Block(-8,58,1,AIR:0)
Block(-8,58,2,AIR:0)
Block(-8,58,3,AIR:0)
Block(-8,58,4,AIR:0)
Block(-8,58,5,AIR:0)
Block(-8,58,6,AIR:0)
Block(-8,58,7,AIR:0)
Block(-8,58,8,AIR:0)
Block(-8,59,-7,AIR:0)
Block(-8,59,-6,AIR:0)
Block(-8,59,-5,AIR:0)
Block(-8,59,-4,AIR:0)
Block(-8,59,-3,AIR:0)
Block(-8,59,-2,AIR:0)
Block(-8,59,-1,AIR:0)
Block(-8,59,0,AIR:0)
Block(-8,59,1,AIR:0)
Block(-8,59,2,AIR:0)
Block(-8,59,3,AIR:0)
Block(-8,59,4,AIR:0)
Block(-8,59,5,AIR:0)
Block(-8,59,6,AIR:0)
Block(-8,59,7,AIR:0)
Block(-8,59,8,AIR:0)
Block(-8,60,-7,AIR:0)
Block(-8,60,-6,AIR:0)
Block(-8,60,-5,AIR:0)
Block(-8,60,-4,AIR:0)
Block(-8,60,-3,AIR:0)
Block(-8,60,-2,AIR:0)
Block(-8,60,-1,AIR:0)
Block(-8,60,0,AIR:0)
Block(-8,60,1,AIR:0)
Block(-8,60,2,AIR:0)
Block(-8,60,3,AIR:0)
Block(-8,60,4,AIR:0)
Block(-8,60,5,AIR:0)
Block(-8,60,6,AIR:0)
Block(-8,60,7,AIR:0)
Block(-8,60,8,AIR:0)
Block(-8,61,-7,AIR:0)
Block(-8,61,-6,AIR:0)
Block(-8,61,-5,AIR:0)
Block(-8,61,-4,OBSIDIAN:0)
Block(-8,61,-3,OBSIDIAN:0)
Block(-8,61,-2,OBSIDIAN:0)
Block(-8,61,-1,AIR:0)
Block(-8,61,0,AIR:0)
Block(-8,61,1,AIR:0)
Block(-8,61,2,AIR:0)
Block(-8,61,3,AIR:0)
Block(-8,61,4,AIR:0)
Block(-8,61,5,AIR:0)
Block(-8,61,6,AIR:0)
Block(-8,61,7,AIR:0)
Block(-8,61,8,AIR:0)
Block(-8,62,-7,AIR:0)
Block(-8,62,-6,AIR:0)
Block(-8,62,-5,AIR:0)
Block(-8,62,-4,OBSIDIAN:0)
Block(-8,62,-3,OBSIDIAN:0)
Block(-8,62,-2,OBSIDIAN:0)
Block(-8,62,-1,OBSIDIAN:0)
Block(-8,62,0,AIR:0)
Block(-8,62,1,AIR:0)
Block(-8,62,2,AIR:0)
Block(-8,62,3,AIR:0)
Block(-8,62,4,AIR:0)
Block(-8,62,5,AIR:0)
Block(-8,62,6,AIR:0)
Block(-8,62,7,AIR:0)
Block(-8,62,8,AIR:0)
Block(-8,63,-7,AIR:0)
Block(-8,63,-6,AIR:0)
Block(-8,63,-5,AIR:0)
Block(-8,63,-4,OBSIDIAN:0)
Block(-8,63,-3,OBSIDIAN:0)
Block(-8,63,-2,OBSIDIAN:0)
Block(-8,63,-1,OBSIDIAN:0)
Block(-8,63,0,OBSIDIAN:0)
Block(-8,63,1,AIR:0)
Block(-8,63,2,AIR:0)
Block(-8,63,3,AIR:0)
Block(-8,63,4,AIR:0)
Block(-8,63,5,AIR:0)
Block(-8,63,6,AIR:0)
Block(-8,63,7,AIR:0)
Block(-8,63,8,AIR:0)
Block(-8,64,-7,AIR:0)
Block(-8,64,-6,AIR:0)
Block(-8,64,-5,AIR:0)
Block(-8,64,-4,OBSIDIAN:0)
Block(-8,64,-3,OBSIDIAN:0)
Block(-8,64,-2,OBSIDIAN:0)
Block(-8,64,-1,OBSIDIAN:0)
Block(-8,64,0,OBSIDIAN:0)
Block(-8,64,1,OBSIDIAN:0)
Block(-8,64,2,AIR:0)
Block(-8,64,3,AIR:0)
Block(-8,64,4,AIR:0)
Block(-8,64,5,AIR:0)
Block(-8,64,6,AIR:0)
Block(-8,64,7,AIR:0)
Block(-8,64,8,AIR:0)
Block(-8,65,-7,AIR:0)
Block(-8,65,-6,AIR:0)
Block(-8,65,-5,AIR:0)
Block(-8,65,-4,OBSIDIAN:0)
Block(-8,65,-3,OBSIDIAN:0)
Block(-8,65,-2,OBSIDIAN:0)
Block(-8,65,-1,OBSIDIAN:0)
Block(-8,65,0,OBSIDIAN:0)
Block(-8,65,1,OBSIDIAN:0)
Block(-8,65,2,AIR:0)
Block(-8,65,3,AIR:0)
Block(-8,65,4,AIR:0)
Block(-8,65,5,AIR:0)
Block(-8,65,6,AIR:0)
Block(-8,65,7,AIR:0)
Block(-8,65,8,AIR:0)
Block(-8,66,-7,AIR:0)
Block(-8,66,-6,AIR:0)
Block(-8,66,-5,AIR:0)
Block(-8,66,-4,OBSIDIAN:0)
Block(-8,66,-3,OBSIDIAN:0)
Block(-8,66,-2,OBSIDIAN:0)
Block(-8,66,-1,OBSIDIAN:0)
Block(-8,66,0,OBSIDIAN:0)
Block(-8,66,1,OBSIDIAN:0)
Block(-8,66,2,OBSIDIAN:0)
Block(-8,66,3,OBSIDIAN:0)
Block(-8,66,4,AIR:0)
Block(-8,66,5,AIR:0)
Block(-8,66,6,AIR:0)
Block(-8,66,7,AIR:0)
Block(-8,66,8,AIR:0)
Block(-8,67,-7,AIR:0)
Block(-8,67,-6,OBSIDIAN:0)
Block(-8,67,-5,OBSIDIAN:0)
Block(-8,67,-4,OBSIDIAN:0)
Block(-8,67,-3,OBSIDIAN:0)
Block(-8,67,-2,OBSIDIAN:0)
Block(-8,67,-1,OBSIDIAN:0)
Block(-8,67,0,OBSIDIAN:0)
Block(-8,67,1,OBSIDIAN:0)
Block(-8,67,2,OBSIDIAN:0)
Block(-8,67,3,OBSIDIAN:0)
Block(-8,67,4,OBSIDIAN:0)
Block(-8,67,5,AIR:0)
Block(-8,67,6,AIR:0)
Block(-8,67,7,AIR:0)
Block(-8,67,8,AIR:0)
Block(-8,68,-7,OBSIDIAN:0)
Block(-8,68,-6,OBSIDIAN:0)
Block(-8,68,-5,OBSIDIAN:0)
Block(-8,68,-4,OBSIDIAN:0)
Block(-8,68,-3,OBSIDIAN:0)
Block(-8,68,-2,OBSIDIAN:0)
Block(-8,68,-1,OBSIDIAN:0)
Block(-8,68,0,OBSIDIAN:0)
Block(-8,68,1,OBSIDIAN:0)
Block(-8,68,2,OBSIDIAN:0)
Block(-8,68,3,OBSIDIAN:0)
Block(-8,68,4,OBSIDIAN:0)
Block(-8,68,5,AIR:0)
Block(-8,68,6,AIR:0)
Block(-8,68,7,AIR:0)
Block(-8,68,8,AIR:0)
Block(-8,69,-7,OBSIDIAN:0)
Block(-8,69,-6,OBSIDIAN:0)
Block(-8,69,-5,OBSIDIAN:0)
Block(-8,69,-4,OBSIDIAN:0)
Block(-8,69,-3,OBSIDIAN:0)
Block(-8,69,-2,OBSIDIAN:0)
Block(-8,69,-1,OBSIDIAN:0)
Block(-8,69,0,OBSIDIAN:0)
Block(-8,69,1,OBSIDIAN:0)
Block(-8,69,2,OBSIDIAN:0)
Block(-8,69,3,OBSIDIAN:0)
Block(-8,69,4,OBSIDIAN:0)
Block(-8,69,5,OBSIDIAN:0)
Block(-8,69,6,AIR:0)
Block(-8,69,7,AIR:0)
Block(-8,69,8,AIR:0)
Block(-8,70,-7,OBSIDIAN:0)
Block(-8,70,-6,OBSIDIAN:0)
Block(-8,70,-5,OBSIDIAN:0)
Block(-8,70,-4,OBSIDIAN:0)
Block(-8,70,-3,OBSIDIAN:0)
Block(-8,70,-2,OBSIDIAN:0)
Block(-8,70,-1,OBSIDIAN:0)
Block(-8,70,0,OBSIDIAN:0)
Block(-8,70,1,OBSIDIAN:0)
Block(-8,70,2,OBSIDIAN:0)
Block(-8,70,3,OBSIDIAN:0)
Block(-8,70,4,OBSIDIAN:0)
Block(-8,70,5,OBSIDIAN:0)
Block(-8,70,6,AIR:0)
Block(-8,70,7,AIR:0)
Block(-8,70,8,AIR:0)
Block(-8,71,-7,OBSIDIAN:0)
Block(-8,71,-6,OBSIDIAN:0)
Block(-8,71,-5,OBSIDIAN:0)
Block(-8,71,-4,OBSIDIAN:0)
Block(-8,71,-3,OBSIDIAN:0)
Block(-8,71,-2,OBSIDIAN:0)
Block(-8,71,-1,OBSIDIAN:0)
Block(-8,71,0,OBSIDIAN:0)
Block(-8,71,1,OBSIDIAN:0)
Block(-8,71,2,OBSIDIAN:0)
Block(-8,71,3,OBSIDIAN:0)
Block(-8,71,4,OBSIDIAN:0)
Block(-8,71,5,OBSIDIAN:0)
Block(-8,71,6,OBSIDIAN:0)
Block(-8,71,7,AIR:0)
Block(-8,71,8,AIR:0)
Block(-8,72,-7,OBSIDIAN:0)
Block(-8,72,-6,OBSIDIAN:0)
Block(-8,72,-5,OBSIDIAN:0)
Block(-8,72,-4,OBSIDIAN:0)
Block(-8,72,-3,OBSIDIAN:0)
Block(-8,72,-2,OBSIDIAN:0)
Block(-8,72,-1,OBSIDIAN:0)
Block(-8,72,0,OBSIDIAN:0)
Block(-8,72,1,OBSIDIAN:0)
Block(-8,72,2,OBSIDIAN:0)
Block(-8,72,3,OBSIDIAN:0)
Block(-8,72,4,OBSIDIAN:0)
Block(-8,72,5,OBSIDIAN:0)
Block(-8,72,6,OBSIDIAN:0)
Block(-8,72,7,OBSIDIAN:0)
Block(-8,72,8,AIR:0)
Block(-8,73,-7,OBSIDIAN:0)
Block(-8,73,-6,OBSIDIAN:0)
Block(-8,73,-5,OBSIDIAN:0)
Block(-8,73,-4,OBSIDIAN:0)
Block(-8,73,-3,OBSIDIAN:0)
Block(-8,73,-2,OBSIDIAN:0)
Block(-8,73,-1,OBSIDIAN:0)
Block(-8,73,0,OBSIDIAN:0)
Block(-8,73,1,OBSIDIAN:0)
Block(-8,73,2,OBSIDIAN:0)
Block(-8,73,3,OBSIDIAN:0)
Block(-8,73,4,OBSIDIAN:0)
Block(-8,73,5,OBSIDIAN:0)
Block(-8,73,6,OBSIDIAN:0)
Block(-8,73,7,OBSIDIAN:0)
Block(-8,73,8,OBSIDIAN:0)
Block(-8,74,-7,OBSIDIAN:0)
Block(-8,74,-6,OBSIDIAN:0)
Block(-8,74,-5,OBSIDIAN:0)
Block(-8,74,-4,OBSIDIAN:0)
Block(-8,74,-3,OBSIDIAN:0)
Block(-8,74,-2,OBSIDIAN:0)
Block(-8,74,-1,OBSIDIAN:0)
Block(-8,74,0,OBSIDIAN:0)
Block(-8,74,1,OBSIDIAN:0)
Block(-8,74,2,OBSIDIAN:0)
Block(-8,74,3,OBSIDIAN:0)
Block(-8,74,4,OBSIDIAN:0)
Block(-8,74,5,OBSIDIAN:0)
Block(-8,74,6,OBSIDIAN:0)
Block(-8,74,7,OBSIDIAN:0)
Block(-8,74,8,OBSIDIAN:0)
Block(-8,75,-7,OBSIDIAN:0)
Block(-8,75,-6,OBSIDIAN:0)
Block(-8,75,-5,OBSIDIAN:0)
Block(-8,75,-4,OBSIDIAN:0)
Block(-8,75,-3,OBSIDIAN:0)
Block(-8,75,-2,OBSIDIAN:0)
Block(-8,75,-1,OBSIDIAN:0)
Block(-8,75,0,OBSIDIAN:0)
Block(-8,75,1,OBSIDIAN:0)
Block(-8,75,2,OBSIDIAN:0)
Block(-8,75,3,OBSIDIAN:0)
Block(-8,75,4,OBSIDIAN:0)
Block(-8,75,5,OBSIDIAN:0)
Block(-8,75,6,OBSIDIAN:0)
Block(-8,75,7,OBSIDIAN:0)
Block(-8,75,8,OBSIDIAN:0)
Block(-8,76,-7,OBSIDIAN:0)
Block(-8,76,-6,OBSIDIAN:0)
Block(-8,76,-5,OBSIDIAN:0)
Block(-8,76,-4,OBSIDIAN:0)
Block(-8,76,-3,OBSIDIAN:0)
Block(-8,76,-2,OBSIDIAN:0)
Block(-8,76,-1,OBSIDIAN:0)
Block(-8,76,0,OBSIDIAN:0)
Block(-8,76,1,OBSIDIAN:0)
Block(-8,76,2,OBSIDIAN:0)
Block(-8,76,3,OBSIDIAN:0)
Block(-8,76,4,OBSIDIAN:0)
Block(-8,76,5,OBSIDIAN:0)
Block(-8,76,6,OBSIDIAN:0)
Block(-8,76,7,OBSIDIAN:0)
Block(-8,76,8,OBSIDIAN:0)
Block(-8,77,-7,OBSIDIAN:0)
Block(-8,77,-6,OBSIDIAN:0)
Block(-8,77,-5,OBSIDIAN:0)
Block(-8,77,-4,OBSIDIAN:0)
Block(-8,77,-3,OBSIDIAN:0)
Block(-8,77,-2,OBSIDIAN:0)
Block(-8,77,-1,OBSIDIAN:0)
Block(-8,77,0,OBSIDIAN:0)
Block(-8,77,1,OBSIDIAN:0)
Block(-8,77,2,OBSIDIAN:0)
Block(-8,77,3,OBSIDIAN:0)
Block(-8,77,4,OBSIDIAN:0)
Block(-8,77,5,OBSIDIAN:0)
Block(-8,77,6,OBSIDIAN:0)
Block(-8,77,7,OBSIDIAN:0)
Block(-8,77,8,OBSIDIAN:0)
Block(-8,78,-7,OBSIDIAN:0)
Block(-8,78,-6,OBSIDIAN:0)
Block(-8,78,-5,OBSIDIAN:0)
Block(-8,78,-4,OBSIDIAN:0)
Block(-8,78,-3,OBSIDIAN:0)
Block(-8,78,-2,OBSIDIAN:0)
Block(-8,78,-1,OBSIDIAN:0)
Block(-8,78,0,OBSIDIAN:0)
Block(-8,78,1,OBSIDIAN:0)
Block(-8,78,2,OBSIDIAN:0)
Block(-8,78,3,OBSIDIAN:0)
Block(-8,78,4,OBSIDIAN:0)
Block(-8,78,5,OBSIDIAN:0)
Block(-8,78,6,OBSIDIAN:0)
Block(-8,78,7,OBSIDIAN:0)
Block(-8,78,8,OBSIDIAN:0)
Block(-8,79,-7,OBSIDIAN:0)
Block(-8,79,-6,OBSIDIAN:0)
Block(-8,79,-5,OBSIDIAN:0)
Block(-8,79,-4,OBSIDIAN:0)
Block(-8,79,-3,OBSIDIAN:0)
Block(-8,79,-2,OBSIDIAN:0)
Block(-8,79,-1,OBSIDIAN:0)
Block(-8,79,0,OBSIDIAN:0)
Block(-8,79,1,OBSIDIAN:0)
Block(-8,79,2,OBSIDIAN:0)
Block(-8,79,3,OBSIDIAN:0)
Block(-8,79,4,OBSIDIAN:0)
Block(-8,79,5,OBSIDIAN:0)
Block(-8,79,6,OBSIDIAN:0)
Block(-8,79,7,OBSIDIAN:0)
Block(-8,79,8,OBSIDIAN:0)
Block(-8,80,-7,OBSIDIAN:0)
Block(-8,80,-6,OBSIDIAN:0)
Block(-8,80,-5,OBSIDIAN:0)
Block(-8,80,-4,OBSIDIAN:0)
Block(-8,80,-3,OBSIDIAN:0)
Block(-8,80,-2,OBSIDIAN:0)
Block(-8,80,-1,OBSIDIAN:0)
Block(-8,80,0,OBSIDIAN:0)
Block(-8,80,1,OBSIDIAN:0)
Block(-8,80,2,OBSIDIAN:0)
Block(-8,80,3,OBSIDIAN:0)
Block(-8,80,4,OBSIDIAN:0)
Block(-8,80,5,OBSIDIAN:0)
Block(-8,80,6,OBSIDIAN:0)
Block(-8,80,7,OBSIDIAN:0)
Block(-8,80,8,OBSIDIAN:0)
Block(-8,81,-7,OBSIDIAN:0)
Block(-8,81,-6,OBSIDIAN:0)
Block(-8,81,-5,OBSIDIAN:0)
Block(-8,81,-4,OBSIDIAN:0)
Block(-8,81,-3,OBSIDIAN:0)
Block(-8,81,-2,OBSIDIAN:0)
Block(-8,81,-1,OBSIDIAN:0)
Block(-8,81,0,OBSIDIAN:0)
Block(-8,81,1,OBSIDIAN:0)
Block(-8,81,2,OBSIDIAN:0)
Block(-8,81,3,OBSIDIAN:0)
Block(-8,81,4,OBSIDIAN:0)
Block(-8,81,5,OBSIDIAN:0)
Block(-8,81,6,OBSIDIAN:0)
Block(-8,81,7,OBSIDIAN:0)
Block(-8,81,8,OBSIDIAN:0)
Block(-8,82,-7,OBSIDIAN:0)
Block(-8,82,-6,OBSIDIAN:0)
Block(-8,82,-5,OBSIDIAN:0)
Block(-8,82,-4,OBSIDIAN:0)
Block(-8,82,-3,OBSIDIAN:0)
Block(-8,82,-2,OBSIDIAN:0)
Block(-8,82,-1,OBSIDIAN:0)
Block(-8,82,0,OBSIDIAN:0)
Block(-8,82,1,OBSIDIAN:0)
Block(-8,82,2,OBSIDIAN:0)
Block(-8,82,3,OBSIDIAN:0)
Block(-8,82,4,OBSIDIAN:0)
Block(-8,82,5,OBSIDIAN:0)
Block(-8,82,6,OBSIDIAN:0)
Block(-8,82,7,OBSIDIAN:0)
Block(-8,82,8,OBSIDIAN:0)
Block(-8,83,-7,OBSIDIAN:0)
Block(-8,83,-6,OBSIDIAN:0)
Block(-8,83,-5,OBSIDIAN:0)
Block(-8,83,-4,OBSIDIAN:0)
Block(-8,83,-3,OBSIDIAN:0)
Block(-8,83,-2,OBSIDIAN:0)
Block(-8,83,-1,OBSIDIAN:0)
Block(-8,83,0,OBSIDIAN:0)
Block(-8,83,1,OBSIDIAN:0)
Block(-8,83,2,OBSIDIAN:0)
Block(-8,83,3,OBSIDIAN:0)
Block(-8,83,4,OBSIDIAN:0)
Block(-8,83,5,OBSIDIAN:0)
Block(-8,83,6,OBSIDIAN:0)
Block(-8,83,7,OBSIDIAN:0)
Block(-8,83,8,OBSIDIAN:0)
Block(-8,84,-7,OBSIDIAN:0)
Block(-8,84,-6,OBSIDIAN:0)
Block(-8,84,-5,OBSIDIAN:0)
Block(-8,84,-4,OBSIDIAN:0)
Block(-8,84,-3,OBSIDIAN:0)
Block(-8,84,-2,OBSIDIAN:0)
Block(-8,84,-1,OBSIDIAN:0)
Block(-8,84,0,OBSIDIAN:0)
Block(-8,84,1,OBSIDIAN:0)
Block(-8,84,2,OBSIDIAN:0)
Block(-8,84,3,OBSIDIAN:0)
Block(-8,84,4,OBSIDIAN:0)
Block(-8,84,5,OBSIDIAN:0)
Block(-8,84,6,OBSIDIAN:0)
Block(-8,84,7,OBSIDIAN:0)
Block(-8,84,8,OBSIDIAN:0)
Block(-8,85,-7,OBSIDIAN:0)
Block(-8,85,-6,OBSIDIAN:0)
Block(-8,85,-5,OBSIDIAN:0)
Block(-8,85,-4,OBSIDIAN:0)
Block(-8,85,-3,OBSIDIAN:0)
Block(-8,85,-2,OBSIDIAN:0)
Block(-8,85,-1,OBSIDIAN:0)
Block(-8,85,0,OBSIDIAN:0)
Block(-8,85,1,OBSIDIAN:0)
Block(-8,85,2,OBSIDIAN:0)
Block(-8,85,3,OBSIDIAN:0)
Block(-8,85,4,OBSIDIAN:0)
Block(-8,85,5,OBSIDIAN:0)
Block(-8,85,6,OBSIDIAN:0)
Block(-8,85,7,OBSIDIAN:0)
Block(-8,85,8,OBSIDIAN:0)
Block(-8,86,-7,OBSIDIAN:0)
Block(-8,86,-6,OBSIDIAN:0)
Block(-8,86,-5,OBSIDIAN:0)
Block(-8,86,-4,OBSIDIAN:0)
Block(-8,86,-3,OBSIDIAN:0)
Block(-8,86,-2,OBSIDIAN:0)
Block(-8,86,-1,OBSIDIAN:0)
Block(-8,86,0,OBSIDIAN:0)
Block(-8,86,1,OBSIDIAN:0)
Block(-8,86,2,OBSIDIAN:0)
Block(-8,86,3,OBSIDIAN:0)
Block(-8,86,4,OBSIDIAN:0)
Block(-8,86,5,OBSIDIAN:0)
Block(-8,86,6,OBSIDIAN:0)
Block(-8,86,7,OBSIDIAN:0)
Block(-8,86,8,OBSIDIAN:0)
Block(-8,87,-7,OBSIDIAN:0)
Block(-8,87,-6,OBSIDIAN:0)
Block(-8,87,-5,OBSIDIAN:0)
Block(-8,87,-4,OBSIDIAN:0)
Block(-8,87,-3,OBSIDIAN:0)
Block(-8,87,-2,OBSIDIAN:0)
Block(-8,87,-1,OBSIDIAN:0)
Block(-8,87,0,OBSIDIAN:0)
Block(-8,87,1,OBSIDIAN:0)
Block(-8,87,2,OBSIDIAN:0)
Block(-8,87,3,OBSIDIAN:0)
Block(-8,87,4,OBSIDIAN:0)
Block(-8,87,5,OBSIDIAN:0)
Block(-8,87,6,OBSIDIAN:0)
Block(-8,87,7,OBSIDIAN:0)
Block(-8,87,8,OBSIDIAN:0)
Block(-8,88,-7,OBSIDIAN:0)
Block(-8,88,-6,OBSIDIAN:0)
Block(-8,88,-5,OBSIDIAN:0)
Block(-8,88,-4,OBSIDIAN:0)
Block(-8,88,-3,OBSIDIAN:0)
Block(-8,88,-2,OBSIDIAN:0)
Block(-8,88,-1,OBSIDIAN:0)
Block(-8,88,0,OBSIDIAN:0)
Block(-8,88,1,OBSIDIAN:0)
Block(-8,88,2,OBSIDIAN:0)
Block(-8,88,3,OBSIDIAN:0)
Block(-8,88,4,OBSIDIAN:0)
Block(-8,88,5,OBSIDIAN:0)
Block(-8,88,6,OBSIDIAN:0)
Block(-8,88,7,OBSIDIAN:0)
Block(-8,88,8,OBSIDIAN:0)
Block(-8,89,-7,OBSIDIAN:0)
Block(-8,89,-6,OBSIDIAN:0)
Block(-8,89,-5,OBSIDIAN:0)
Block(-8,89,-4,OBSIDIAN:0)
Block(-8,89,-3,OBSIDIAN:0)
Block(-8,89,-2,OBSIDIAN:0)
Block(-8,89,-1,OBSIDIAN:0)
Block(-8,89,0,OBSIDIAN:0)
Block(-8,89,1,OBSIDIAN:0)
Block(-8,89,2,OBSIDIAN:0)
Block(-8,89,3,OBSIDIAN:0)
Block(-8,89,4,OBSIDIAN:0)
Block(-8,89,5,OBSIDIAN:0)
Block(-8,89,6,OBSIDIAN:0)
Block(-8,89,7,OBSIDIAN:0)
Block(-8,89,8,OBSIDIAN:0)
Block(-8,90,-7,OBSIDIAN:0)
Block(-8,90,-6,OBSIDIAN:0)
Block(-8,90,-5,OBSIDIAN:0)
Block(-8,90,-4,OBSIDIAN:0)
Block(-8,90,-3,OBSIDIAN:0)
Block(-8,90,-2,OBSIDIAN:0)
Block(-8,90,-1,OBSIDIAN:0)
Block(-8,90,0,OBSIDIAN:0)
Block(-8,90,1,OBSIDIAN:0)
Block(-8,90,2,OBSIDIAN:0)
Block(-8,90,3,OBSIDIAN:0)
Block(-8,90,4,OBSIDIAN:0)
Block(-8,90,5,OBSIDIAN:0)
Block(-8,90,6,OBSIDIAN:0)
Block(-8,90,7,OBSIDIAN:0)
Block(-8,90,8,OBSIDIAN:0)
Block(-8,91,-7,OBSIDIAN:0)
Block(-8,91,-6,OBSIDIAN:0)
Block(-8,91,-5,OBSIDIAN:0)
Block(-8,91,-4,OBSIDIAN:0)
Block(-8,91,-3,OBSIDIAN:0)
Block(-8,91,-2,OBSIDIAN:0)
Block(-8,91,-1,OBSIDIAN:0)
Block(-8,91,0,OBSIDIAN:0)
Block(-8,91,1,OBSIDIAN:0)
Block(-8,91,2,OBSIDIAN:0)
Block(-8,91,3,OBSIDIAN:0)
Block(-8,91,4,OBSIDIAN:0)
Block(-8,91,5,OBSIDIAN:0)
Block(-8,91,6,OBSIDIAN:0)
Block(-8,91,7,OBSIDIAN:0)
Block(-8,91,8,OBSIDIAN:0)
Block(-8,92,-7,OBSIDIAN:0)
Block(-8,92,-6,OBSIDIAN:0)
Block(-8,92,-5,OBSIDIAN:0)
Block(-8,92,-4,OBSIDIAN:0)
Block(-8,92,-3,OBSIDIAN:0)
Block(-8,92,-2,OBSIDIAN:0)
Block(-8,92,-1,OBSIDIAN:0)
Block(-8,92,0,OBSIDIAN:0)
Block(-8,92,1,OBSIDIAN:0)
Block(-8,92,2,OBSIDIAN:0)
Block(-8,92,3,OBSIDIAN:0)
Block(-8,92,4,OBSIDIAN:0)
Block(-8,92,5,OBSIDIAN:0)
Block(-8,92,6,OBSIDIAN:0)
Block(-8,92,7,OBSIDIAN:0)
Block(-8,92,8,OBSIDIAN:0)
Block(-8,93,-7,OBSIDIAN:0)
Block(-8,93,-6,OBSIDIAN:0)
Block(-8,93,-5,OBSIDIAN:0)
Block(-8,93,-4,OBSIDIAN:0)
Block(-8,93,-3,OBSIDIAN:0)
Block(-8,93,-2,OBSIDIAN:0)
Block(-8,93,-1,OBSIDIAN:0)
Block(-8,93,0,OBSIDIAN:0)
Block(-8,93,1,OBSIDIAN:0)
Block(-8,93,2,OBSIDIAN:0)
Block(-8,93,3,OBSIDIAN:0)
Block(-8,93,4,OBSIDIAN:0)
Block(-8,93,5,OBSIDIAN:0)
Block(-8,93,6,OBSIDIAN:0)
Block(-8,93,7,OBSIDIAN:0)
Block(-8,93,8,OBSIDIAN:0)
Block(-8,94,-7,OBSIDIAN:0)
Block(-8,94,-6,OBSIDIAN:0)
Block(-8,94,-5,OBSIDIAN:0)
Block(-8,94,-4,OBSIDIAN:0)
Block(-8,94,-3,OBSIDIAN:0)
Block(-8,94,-2,OBSIDIAN:0)
Block(-8,94,-1,OBSIDIAN:0)
Block(-8,94,0,OBSIDIAN:0)
Block(-8,94,1,OBSIDIAN:0)
Block(-8,94,2,OBSIDIAN:0)
Block(-8,94,3,OBSIDIAN:0)
Block(-8,94,4,OBSIDIAN:0)
Block(-8,94,5,OBSIDIAN:0)
Block(-8,94,6,OBSIDIAN:0)
Block(-8,94,7,OBSIDIAN:0)
Block(-8,94,8,OBSIDIAN:0)
Block(-8,95,-7,OBSIDIAN:0)
Block(-8,95,-6,OBSIDIAN:0)
Block(-8,95,-5,OBSIDIAN:0)
Block(-8,95,-4,OBSIDIAN:0)
Block(-8,95,-3,OBSIDIAN:0)
Block(-8,95,-2,OBSIDIAN:0)
Block(-8,95,-1,OBSIDIAN:0)
Block(-8,95,0,OBSIDIAN:0)
Block(-8,95,1,OBSIDIAN:0)
Block(-8,95,2,OBSIDIAN:0)
Block(-8,95,3,OBSIDIAN:0)
Block(-8,95,4,OBSIDIAN:0)
Block(-8,95,5,OBSIDIAN:0)
Block(-8,95,6,OBSIDIAN:0)
Block(-8,95,7,OBSIDIAN:0)
Block(-8,95,8,OBSIDIAN:0)
Block(-8,96,-7,OBSIDIAN:0)
Block(-8,96,-6,OBSIDIAN:0)
Block(-8,96,-5,OBSIDIAN:0)
Block(-8,96,-4,OBSIDIAN:0)
Block(-8,96,-3,OBSIDIAN:0)
Block(-8,96,-2,OBSIDIAN:0)
Block(-8,96,-1,OBSIDIAN:0)
Block(-8,96,0,OBSIDIAN:0)
Block(-8,96,1,OBSIDIAN:0)
Block(-8,96,2,OBSIDIAN:0)
Block(-8,96,3,OBSIDIAN:0)
Block(-8,96,4,OBSIDIAN:0)
Block(-8,96,5,OBSIDIAN:0)
Block(-8,96,6,OBSIDIAN:0)
Block(-8,96,7,OBSIDIAN:0)
Block(-8,96,8,OBSIDIAN:0)
Block(-8,97,-7,OBSIDIAN:0)
Block(-8,97,-6,OBSIDIAN:0)
Block(-8,97,-5,OBSIDIAN:0)
Block(-8,97,-4,OBSIDIAN:0)
Block(-8,97,-3,OBSIDIAN:0)
Block(-8,97,-2,OBSIDIAN:0)
Block(-8,97,-1,OBSIDIAN:0)
Block(-8,97,0,OBSIDIAN:0)
Block(-8,97,1,OBSIDIAN:0)
Block(-8,97,2,OBSIDIAN:0)
Block(-8,97,3,OBSIDIAN:0)
Block(-8,97,4,OBSIDIAN:0)
Block(-8,97,5,OBSIDIAN:0)
Block(-8,97,6,OBSIDIAN:0)
Block(-8,97,7,OBSIDIAN:0)
Block(-8,97,8,OBSIDIAN:0)
Block(-8,98,-7,OBSIDIAN:0)
Block(-8,98,-6,OBSIDIAN:0)
Block(-8,98,-5,OBSIDIAN:0)
Block(-8,98,-4,OBSIDIAN:0)
Block(-8,98,-3,OBSIDIAN:0)
Block(-8,98,-2,OBSIDIAN:0)
Block(-8,98,-1,OBSIDIAN:0)
Block(-8,98,0,OBSIDIAN:0)
Block(-8,98,1,OBSIDIAN:0)
Block(-8,98,2,OBSIDIAN:0)
Block(-8,98,3,OBSIDIAN:0)
Block(-8,98,4,OBSIDIAN:0)
Block(-8,98,5,OBSIDIAN:0)
Block(-8,98,6,OBSIDIAN:0)
Block(-8,98,7,OBSIDIAN:0)
Block(-8,98,8,OBSIDIAN:0)
Block(-8,99,-7,OBSIDIAN:0)
Block(-8,99,-6,OBSIDIAN:0)
Block(-8,99,-5,OBSIDIAN:0)
Block(-8,99,-4,OBSIDIAN:0)
Block(-8,99,-3,OBSIDIAN:0)
Block(-8,99,-2,OBSIDIAN:0)
Block(-8,99,-1,OBSIDIAN:0)
Block(-8,99,0,OBSIDIAN:0)
Block(-8,99,1,OBSIDIAN:0)
Block(-8,99,2,OBSIDIAN:0)
Block(-8,99,3,OBSIDIAN:0)
Block(-8,99,4,OBSIDIAN:0)
Block(-8,99,5,OBSIDIAN:0)
Block(-8,99,6,OBSIDIAN:0)
Block(-8,99,7,OBSIDIAN:0)
Block(-8,99,8,OBSIDIAN:0)
Block(-8,100,-7,OBSIDIAN:0)
Block(-8,100,-6,OBSIDIAN:0)
Block(-8,100,-5,OBSIDIAN:0)
Block(-8,100,-4,OBSIDIAN:0)
Block(-8,100,-3,OBSIDIAN:0)
Block(-8,100,-2,OBSIDIAN:0)
Block(-8,100,-1,OBSIDIAN:0)
Block(-8,100,0,OBSIDIAN:0)
Block(-8,100,1,OBSIDIAN:0)
Block(-8,100,2,OBSIDIAN:0)
Block(-8,100,3,OBSIDIAN:0)
Block(-8,100,4,OBSIDIAN:0)
Block(-8,100,5,OBSIDIAN:0)
Block(-8,100,6,OBSIDIAN:0)
Block(-8,100,7,OBSIDIAN:0)
Block(-8,100,8,OBSIDIAN:0)
Block(-8,101,-7,OBSIDIAN:0)
Block(-8,101,-6,OBSIDIAN:0)
Block(-8,101,-5,OBSIDIAN:0)
Block(-8,101,-4,OBSIDIAN:0)
Block(-8,101,-3,OBSIDIAN:0)
Block(-8,101,-2,OBSIDIAN:0)
Block(-8,101,-1,OBSIDIAN:0)
Block(-8,101,0,OBSIDIAN:0)
Block(-8,101,1,OBSIDIAN:0)
Block(-8,101,2,OBSIDIAN:0)
Block(-8,101,3,OBSIDIAN:0)
Block(-8,101,4,OBSIDIAN:0)
Block(-8,101,5,OBSIDIAN:0)
Block(-8,101,6,OBSIDIAN:0)
Block(-8,101,7,OBSIDIAN:0)
Block(-8,101,8,OBSIDIAN:0)
Block(-8,102,-7,OBSIDIAN:0)
Block(-8,102,-6,OBSIDIAN:0)
Block(-8,102,-5,OBSIDIAN:0)
Block(-8,102,-4,OBSIDIAN:0)
Block(-8,102,-3,OBSIDIAN:0)
Block(-8,102,-2,OBSIDIAN:0)
Block(-8,102,-1,OBSIDIAN:0)
Block(-8,102,0,OBSIDIAN:0)
Block(-8,102,1,OBSIDIAN:0)
Block(-8,102,2,OBSIDIAN:0)
Block(-8,102,3,OBSIDIAN:0)
Block(-8,102,4,OBSIDIAN:0)
Block(-8,102,5,OBSIDIAN:0)
Block(-8,102,6,OBSIDIAN:0)
Block(-8,102,7,OBSIDIAN:0)
Block(-8,102,8,OBSIDIAN:0)
Block(-8,103,-7,OBSIDIAN:0)
Block(-8,103,-6,OBSIDIAN:0)
Block(-8,103,-5,OBSIDIAN:0)
Block(-8,103,-4,OBSIDIAN:0)
Block(-8,103,-3,OBSIDIAN:0)
Block(-8,103,-2,OBSIDIAN:0)
Block(-8,103,-1,OBSIDIAN:0)
Block(-8,103,0,OBSIDIAN:0)
Block(-8,103,1,OBSIDIAN:0)
Block(-8,103,2,OBSIDIAN:0)
Block(-8,103,3,OBSIDIAN:0)
Block(-8,103,4,OBSIDIAN:0)
Block(-8,103,5,OBSIDIAN:0)
Block(-8,103,6,OBSIDIAN:0)
Block(-8,103,7,OBSIDIAN:0)
Block(-8,103,8,STONE:3)
Block(-8,104,-7,STONE:3)
Block(-8,104,-6,OBSIDIAN:0)
Block(-8,104,-5,OBSIDIAN:0)
Block(-8,104,-4,OBSIDIAN:0)
Block(-8,104,-3,OBSIDIAN:0)
Block(-8,104,-2,OBSIDIAN:0)
Block(-8,104,-1,STONE:3)
Block(-8,104,0,STONE:3)
Block(-8,104,1,STONE:3)
Block(-8,104,2,STONE:3)
Block(-8,104,3,STONE:3)
Block(-8,104,4,OBSIDIAN:0)
Block(-8,104,5,OBSIDIAN:0)
Block(-8,104,6,OBSIDIAN:0)
Block(-8,104,7,STONE:3)
Block(-8,104,8,STONE:3)
Block(-8,105,-7,STONE:3)
Block(-8,105,-6,OBSIDIAN:0)
Block(-8,105,-5,OBSIDIAN:0)
Block(-8,105,-4,OBSIDIAN:0)
Block(-8,105,-3,OBSIDIAN:0)
Block(-8,105,-2,STONE:3)
Block(-8,105,-1,STONE:3)
Block(-8,105,0,STONE:3)
Block(-8,105,1,STONE:3)
Block(-8,105,2,STONE:3)
Block(-8,105,3,STONE:3)
Block(-8,105,4,STONE:3)
Block(-8,105,5,OBSIDIAN:0)
Block(-8,105,6,STONE:3)
Block(-8,105,7,STONE:3)
Block(-8,105,8,STONE:3)
Block(-8,106,-6,STONE:3)
Block(-8,106,-5,OBSIDIAN:0)
Block(-8,106,-4,OBSIDIAN:0)
Block(-8,106,-3,STONE:3)
Block(-8,106,-2,STONE:3)
Block(-8,106,-1,STONE:3)
Block(-8,106,0,STONE:3)
Block(-8,106,1,STONE:3)
Block(-8,106,2,STONE:3)
Block(-8,106,3,STONE:3)
Block(-8,106,4,STONE:3)
Block(-8,106,5,STONE:3)
Block(-8,106,6,STONE:3)
Block(-8,106,7,STONE:3)
Block(-8,106,8,STONE:3)
Block(-8,107,-6,STONE:3)
Block(-8,107,-5,STONE:3)
Block(-8,107,-4,STONE:3)
Block(-8,107,-3,STONE:3)
Block(-8,107,-2,STONE:3)
Block(-8,107,-1,STONE:3)
Block(-8,107,0,STONE:3)
Block(-8,107,1,STONE:3)
Block(-8,107,2,STONE:3)
Block(-8,107,3,STONE:3)
Block(-8,107,4,STONE:3)
Block(-8,107,5,STONE:3)
Block(-8,107,6,STONE:3)
Block(-8,107,7,STONE:3)
Block(-8,107,8,STONE:3)
Block(-8,108,-5,STONE:3)
Block(-8,108,-4,STONE:3)
Block(-8,108,-3,STONE:3)
Block(-8,108,1,STONE:3)
Block(-8,108,2,STONE:3)
Block(-8,108,3,STONE:3)
Block(-8,108,4,STONE:3)
Block(-8,108,5,STONE:3)
Block(-8,108,6,STONE:3)
Block(-8,108,8,STONE:3)
Block(-7,14,0,STONE:3)
Block(-7,14,1,OBSIDIAN:0)
Block(-7,14,2,OBSIDIAN:0)
Block(-7,14,3,OBSIDIAN:0)
Block(-7,14,4,OBSIDIAN:0)
Block(-7,14,5,MAGMA:0)
Block(-7,14,6,MAGMA:0)
Block(-7,14,7,MAGMA:0)
Block(-7,14,8,MAGMA:0)
Block(-7,15,-3,STONE:3)
Block(-7,15,-2,STONE:3)
Block(-7,15,-1,STONE:3)
Block(-7,15,0,STONE:3)
Block(-7,15,1,OBSIDIAN:0)
Block(-7,15,2,OBSIDIAN:0)
Block(-7,15,3,OBSIDIAN:0)
Block(-7,15,4,OBSIDIAN:0)
Block(-7,15,5,MAGMA:0)
Block(-7,15,6,MAGMA:0)
Block(-7,15,7,MAGMA:0)
Block(-7,15,8,MAGMA:0)
Block(-7,16,-4,STONE:3)
Block(-7,16,-3,STONE:3)
Block(-7,16,-2,STONE:3)
Block(-7,16,-1,STONE:3)
Block(-7,16,0,STONE:3)
Block(-7,16,1,OBSIDIAN:0)
Block(-7,16,2,OBSIDIAN:0)
Block(-7,16,3,OBSIDIAN:0)
Block(-7,16,4,OBSIDIAN:0)
Block(-7,16,5,OBSIDIAN:0)
Block(-7,16,6,MAGMA:0)
Block(-7,16,7,MAGMA:0)
Block(-7,16,8,MAGMA:0)
Block(-7,17,-5,STONE:3)
Block(-7,17,-4,STONE:3)
Block(-7,17,-3,STONE:3)
Block(-7,17,-2,STONE:3)
Block(-7,17,-1,STONE:3)
Block(-7,17,0,STONE:3)
Block(-7,17,1,STONE:3)
Block(-7,17,2,OBSIDIAN:0)
Block(-7,17,3,OBSIDIAN:0)
Block(-7,17,4,OBSIDIAN:0)
Block(-7,17,5,OBSIDIAN:0)
Block(-7,17,6,OBSIDIAN:0)
Block(-7,17,7,OBSIDIAN:0)
Block(-7,17,8,OBSIDIAN:0)
Block(-7,18,-5,STONE:3)
Block(-7,18,-4,STONE:3)
Block(-7,18,-3,STONE:3)
Block(-7,18,-2,STONE:3)
Block(-7,18,-1,STONE:3)
Block(-7,18,0,STONE:3)
Block(-7,18,1,STONE:3)
Block(-7,18,2,STONE:3)
Block(-7,18,3,OBSIDIAN:0)
Block(-7,18,4,OBSIDIAN:0)
Block(-7,18,5,OBSIDIAN:0)
Block(-7,18,6,OBSIDIAN:0)
Block(-7,18,7,OBSIDIAN:0)
Block(-7,18,8,OBSIDIAN:0)
Block(-7,19,-6,STONE:3)
Block(-7,19,-5,STONE:3)
Block(-7,19,-4,STONE:3)
Block(-7,19,-3,STONE:3)
Block(-7,19,-2,STONE:3)
Block(-7,19,-1,STONE:3)
Block(-7,19,0,STONE:3)
Block(-7,19,1,STONE:3)
Block(-7,19,2,STONE:3)
Block(-7,19,3,STONE:3)
Block(-7,19,4,OBSIDIAN:0)
Block(-7,19,5,OBSIDIAN:0)
Block(-7,19,6,OBSIDIAN:0)
Block(-7,19,7,OBSIDIAN:0)
Block(-7,19,8,OBSIDIAN:0)
Block(-7,20,-7,STONE:3)
Block(-7,20,-6,STONE:3)
Block(-7,20,-5,STONE:3)
Block(-7,20,-4,STONE:3)
Block(-7,20,-3,STONE:3)
Block(-7,20,-2,STONE:3)
Block(-7,20,-1,STONE:3)
Block(-7,20,0,OBSIDIAN:0)
Block(-7,20,1,OBSIDIAN:0)
Block(-7,20,2,OBSIDIAN:0)
Block(-7,20,3,OBSIDIAN:0)
Block(-7,20,4,OBSIDIAN:0)
Block(-7,20,5,OBSIDIAN:0)
Block(-7,20,6,OBSIDIAN:0)
Block(-7,20,7,OBSIDIAN:0)
Block(-7,20,8,OBSIDIAN:0)
Block(-7,21,-7,STONE:3)
Block(-7,21,-6,STONE:3)
Block(-7,21,-5,STONE:3)
Block(-7,21,-4,STONE:3)
Block(-7,21,-3,STONE:3)
Block(-7,21,-2,STONE:3)
Block(-7,21,-1,STONE:3)
Block(-7,21,0,OBSIDIAN:0)
Block(-7,21,1,OBSIDIAN:0)
Block(-7,21,2,OBSIDIAN:0)
Block(-7,21,3,OBSIDIAN:0)
Block(-7,21,4,OBSIDIAN:0)
Block(-7,21,5,OBSIDIAN:0)
Block(-7,21,6,OBSIDIAN:0)
Block(-7,21,7,OBSIDIAN:0)
Block(-7,21,8,OBSIDIAN:0)
Block(-7,22,-7,STONE:3)
Block(-7,22,-6,STONE:3)
Block(-7,22,-5,STONE:3)
Block(-7,22,-4,STONE:3)
Block(-7,22,-3,STONE:3)
Block(-7,22,-2,STONE:3)
Block(-7,22,-1,OBSIDIAN:0)
Block(-7,22,0,OBSIDIAN:0)
Block(-7,22,1,OBSIDIAN:0)
Block(-7,22,2,OBSIDIAN:0)
Block(-7,22,3,OBSIDIAN:0)
Block(-7,22,4,OBSIDIAN:0)
Block(-7,22,5,OBSIDIAN:0)
Block(-7,22,6,OBSIDIAN:0)
Block(-7,22,7,OBSIDIAN:0)
Block(-7,22,8,OBSIDIAN:0)
Block(-7,23,-7,OBSIDIAN:0)
Block(-7,23,-6,STONE:3)
Block(-7,23,-5,STONE:3)
Block(-7,23,-4,STONE:3)
Block(-7,23,-3,OBSIDIAN:0)
Block(-7,23,-2,OBSIDIAN:0)
Block(-7,23,-1,OBSIDIAN:0)
Block(-7,23,0,OBSIDIAN:0)
Block(-7,23,1,OBSIDIAN:0)
Block(-7,23,2,OBSIDIAN:0)
Block(-7,23,3,OBSIDIAN:0)
Block(-7,23,4,OBSIDIAN:0)
Block(-7,23,5,OBSIDIAN:0)
Block(-7,23,6,OBSIDIAN:0)
Block(-7,23,7,OBSIDIAN:0)
Block(-7,23,8,OBSIDIAN:0)
Block(-7,24,-7,OBSIDIAN:0)
Block(-7,24,-6,OBSIDIAN:0)
Block(-7,24,-5,OBSIDIAN:0)
Block(-7,24,-4,OBSIDIAN:0)
Block(-7,24,-3,OBSIDIAN:0)
Block(-7,24,-2,OBSIDIAN:0)
Block(-7,24,-1,OBSIDIAN:0)
Block(-7,24,0,OBSIDIAN:0)
Block(-7,24,1,OBSIDIAN:0)
Block(-7,24,2,OBSIDIAN:0)
Block(-7,24,3,OBSIDIAN:0)
Block(-7,24,4,OBSIDIAN:0)
Block(-7,24,5,OBSIDIAN:0)
Block(-7,24,6,OBSIDIAN:0)
Block(-7,24,7,OBSIDIAN:0)
Block(-7,24,8,OBSIDIAN:0)
Block(-7,25,-7,OBSIDIAN:0)
Block(-7,25,-6,OBSIDIAN:0)
Block(-7,25,-5,OBSIDIAN:0)
Block(-7,25,-4,OBSIDIAN:0)
Block(-7,25,-3,OBSIDIAN:0)
Block(-7,25,-2,OBSIDIAN:0)
Block(-7,25,-1,OBSIDIAN:0)
Block(-7,25,0,OBSIDIAN:0)
Block(-7,25,1,OBSIDIAN:0)
Block(-7,25,2,OBSIDIAN:0)
Block(-7,25,3,OBSIDIAN:0)
Block(-7,25,4,OBSIDIAN:0)
Block(-7,25,5,OBSIDIAN:0)
Block(-7,25,6,OBSIDIAN:0)
Block(-7,25,7,OBSIDIAN:0)
Block(-7,25,8,OBSIDIAN:0)
Block(-7,26,-7,OBSIDIAN:0)
Block(-7,26,-6,OBSIDIAN:0)
Block(-7,26,-5,OBSIDIAN:0)
Block(-7,26,-4,OBSIDIAN:0)
Block(-7,26,-3,OBSIDIAN:0)
Block(-7,26,-2,OBSIDIAN:0)
Block(-7,26,-1,OBSIDIAN:0)
Block(-7,26,0,OBSIDIAN:0)
Block(-7,26,1,OBSIDIAN:0)
Block(-7,26,2,OBSIDIAN:0)
Block(-7,26,3,OBSIDIAN:0)
Block(-7,26,4,OBSIDIAN:0)
Block(-7,26,5,OBSIDIAN:0)
Block(-7,26,6,OBSIDIAN:0)
Block(-7,26,7,OBSIDIAN:0)
Block(-7,26,8,OBSIDIAN:0)
Block(-7,27,-7,OBSIDIAN:0)
Block(-7,27,-6,OBSIDIAN:0)
Block(-7,27,-5,OBSIDIAN:0)
Block(-7,27,-4,OBSIDIAN:0)
Block(-7,27,-3,OBSIDIAN:0)
Block(-7,27,-2,OBSIDIAN:0)
Block(-7,27,-1,OBSIDIAN:0)
Block(-7,27,0,OBSIDIAN:0)
Block(-7,27,1,OBSIDIAN:0)
Block(-7,27,2,OBSIDIAN:0)
Block(-7,27,3,OBSIDIAN:0)
Block(-7,27,4,OBSIDIAN:0)
Block(-7,27,5,OBSIDIAN:0)
Block(-7,27,6,OBSIDIAN:0)
Block(-7,27,7,OBSIDIAN:0)
Block(-7,27,8,OBSIDIAN:0)
Block(-7,28,-7,OBSIDIAN:0)
Block(-7,28,-6,OBSIDIAN:0)
Block(-7,28,-5,OBSIDIAN:0)
Block(-7,28,-4,OBSIDIAN:0)
Block(-7,28,-3,OBSIDIAN:0)
Block(-7,28,-2,OBSIDIAN:0)
Block(-7,28,-1,OBSIDIAN:0)
Block(-7,28,0,OBSIDIAN:0)
Block(-7,28,1,OBSIDIAN:0)
Block(-7,28,2,OBSIDIAN:0)
Block(-7,28,3,OBSIDIAN:0)
Block(-7,28,4,OBSIDIAN:0)
Block(-7,28,5,OBSIDIAN:0)
Block(-7,28,6,OBSIDIAN:0)
Block(-7,28,7,OBSIDIAN:0)
Block(-7,28,8,OBSIDIAN:0)
Block(-7,29,-7,OBSIDIAN:0)
Block(-7,29,-6,OBSIDIAN:0)
Block(-7,29,-5,OBSIDIAN:0)
Block(-7,29,-4,OBSIDIAN:0)
Block(-7,29,-3,OBSIDIAN:0)
Block(-7,29,-2,OBSIDIAN:0)
Block(-7,29,-1,OBSIDIAN:0)
Block(-7,29,0,OBSIDIAN:0)
Block(-7,29,1,OBSIDIAN:0)
Block(-7,29,2,OBSIDIAN:0)
Block(-7,29,3,OBSIDIAN:0)
Block(-7,29,4,OBSIDIAN:0)
Block(-7,29,5,OBSIDIAN:0)
Block(-7,29,6,OBSIDIAN:0)
Block(-7,29,7,OBSIDIAN:0)
Block(-7,29,8,OBSIDIAN:0)
Block(-7,30,-7,OBSIDIAN:0)
Block(-7,30,-6,OBSIDIAN:0)
Block(-7,30,-5,OBSIDIAN:0)
Block(-7,30,-4,OBSIDIAN:0)
Block(-7,30,-3,OBSIDIAN:0)
Block(-7,30,-2,OBSIDIAN:0)
Block(-7,30,-1,OBSIDIAN:0)
Block(-7,30,0,OBSIDIAN:0)
Block(-7,30,1,OBSIDIAN:0)
Block(-7,30,2,OBSIDIAN:0)
Block(-7,30,3,OBSIDIAN:0)
Block(-7,30,4,OBSIDIAN:0)
Block(-7,30,5,OBSIDIAN:0)
Block(-7,30,6,OBSIDIAN:0)
Block(-7,30,7,OBSIDIAN:0)
Block(-7,30,8,OBSIDIAN:0)
Block(-7,31,-7,OBSIDIAN:0)
Block(-7,31,-6,OBSIDIAN:0)
Block(-7,31,-5,OBSIDIAN:0)
Block(-7,31,-4,OBSIDIAN:0)
Block(-7,31,-3,OBSIDIAN:0)
Block(-7,31,-2,OBSIDIAN:0)
Block(-7,31,-1,OBSIDIAN:0)
Block(-7,31,0,OBSIDIAN:0)
Block(-7,31,1,OBSIDIAN:0)
Block(-7,31,2,OBSIDIAN:0)
Block(-7,31,3,OBSIDIAN:0)
Block(-7,31,4,OBSIDIAN:0)
Block(-7,31,5,OBSIDIAN:0)
Block(-7,31,6,OBSIDIAN:0)
Block(-7,31,7,OBSIDIAN:0)
Block(-7,31,8,OBSIDIAN:0)
Block(-7,32,-7,OBSIDIAN:0)
Block(-7,32,-6,OBSIDIAN:0)
Block(-7,32,-5,OBSIDIAN:0)
Block(-7,32,-4,OBSIDIAN:0)
Block(-7,32,-3,OBSIDIAN:0)
Block(-7,32,-2,OBSIDIAN:0)
Block(-7,32,-1,OBSIDIAN:0)
Block(-7,32,0,OBSIDIAN:0)
Block(-7,32,1,OBSIDIAN:0)
Block(-7,32,2,OBSIDIAN:0)
Block(-7,32,3,OBSIDIAN:0)
Block(-7,32,4,OBSIDIAN:0)
Block(-7,32,5,OBSIDIAN:0)
Block(-7,32,6,OBSIDIAN:0)
Block(-7,32,7,OBSIDIAN:0)
Block(-7,32,8,OBSIDIAN:0)
Block(-7,33,-7,OBSIDIAN:0)
Block(-7,33,-6,OBSIDIAN:0)
Block(-7,33,-5,OBSIDIAN:0)
Block(-7,33,-4,OBSIDIAN:0)
Block(-7,33,-3,OBSIDIAN:0)
Block(-7,33,-2,OBSIDIAN:0)
Block(-7,33,-1,OBSIDIAN:0)
Block(-7,33,0,OBSIDIAN:0)
Block(-7,33,1,OBSIDIAN:0)
Block(-7,33,2,OBSIDIAN:0)
Block(-7,33,3,OBSIDIAN:0)
Block(-7,33,4,OBSIDIAN:0)
Block(-7,33,5,OBSIDIAN:0)
Block(-7,33,6,OBSIDIAN:0)
Block(-7,33,7,OBSIDIAN:0)
Block(-7,33,8,OBSIDIAN:0)
Block(-7,34,-7,OBSIDIAN:0)
Block(-7,34,-6,OBSIDIAN:0)
Block(-7,34,-5,OBSIDIAN:0)
Block(-7,34,-4,OBSIDIAN:0)
Block(-7,34,-3,OBSIDIAN:0)
Block(-7,34,-2,OBSIDIAN:0)
Block(-7,34,-1,OBSIDIAN:0)
Block(-7,34,0,OBSIDIAN:0)
Block(-7,34,1,OBSIDIAN:0)
Block(-7,34,2,OBSIDIAN:0)
Block(-7,34,3,OBSIDIAN:0)
Block(-7,34,4,OBSIDIAN:0)
Block(-7,34,5,OBSIDIAN:0)
Block(-7,34,6,OBSIDIAN:0)
Block(-7,34,7,OBSIDIAN:0)
Block(-7,34,8,OBSIDIAN:0)
Block(-7,35,-7,OBSIDIAN:0)
Block(-7,35,-6,OBSIDIAN:0)
Block(-7,35,-5,OBSIDIAN:0)
Block(-7,35,-4,OBSIDIAN:0)
Block(-7,35,-3,OBSIDIAN:0)
Block(-7,35,-2,OBSIDIAN:0)
Block(-7,35,-1,OBSIDIAN:0)
Block(-7,35,0,OBSIDIAN:0)
Block(-7,35,1,OBSIDIAN:0)
Block(-7,35,2,OBSIDIAN:0)
Block(-7,35,3,OBSIDIAN:0)
Block(-7,35,4,OBSIDIAN:0)
Block(-7,35,5,OBSIDIAN:0)
Block(-7,35,6,OBSIDIAN:0)
Block(-7,35,7,OBSIDIAN:0)
Block(-7,35,8,OBSIDIAN:0)
Block(-7,36,-7,OBSIDIAN:0)
Block(-7,36,-6,OBSIDIAN:0)
Block(-7,36,-5,OBSIDIAN:0)
Block(-7,36,-4,OBSIDIAN:0)
Block(-7,36,-3,OBSIDIAN:0)
Block(-7,36,-2,OBSIDIAN:0)
Block(-7,36,-1,OBSIDIAN:0)
Block(-7,36,0,OBSIDIAN:0)
Block(-7,36,1,OBSIDIAN:0)
Block(-7,36,2,OBSIDIAN:0)
Block(-7,36,3,OBSIDIAN:0)
Block(-7,36,4,OBSIDIAN:0)
Block(-7,36,5,OBSIDIAN:0)
Block(-7,36,6,OBSIDIAN:0)
Block(-7,36,7,OBSIDIAN:0)
Block(-7,36,8,OBSIDIAN:0)
Block(-7,37,-7,OBSIDIAN:0)
Block(-7,37,-6,OBSIDIAN:0)
Block(-7,37,-5,OBSIDIAN:0)
Block(-7,37,-4,OBSIDIAN:0)
Block(-7,37,-3,OBSIDIAN:0)
Block(-7,37,-2,OBSIDIAN:0)
Block(-7,37,-1,OBSIDIAN:0)
Block(-7,37,0,OBSIDIAN:0)
Block(-7,37,1,OBSIDIAN:0)
Block(-7,37,2,OBSIDIAN:0)
Block(-7,37,3,OBSIDIAN:0)
Block(-7,37,4,OBSIDIAN:0)
Block(-7,37,5,OBSIDIAN:0)
Block(-7,37,6,OBSIDIAN:0)
Block(-7,37,7,OBSIDIAN:0)
Block(-7,37,8,OBSIDIAN:0)
Block(-7,38,-7,OBSIDIAN:0)
Block(-7,38,-6,OBSIDIAN:0)
Block(-7,38,-5,OBSIDIAN:0)
Block(-7,38,-4,OBSIDIAN:0)
Block(-7,38,-3,OBSIDIAN:0)
Block(-7,38,-2,OBSIDIAN:0)
Block(-7,38,-1,OBSIDIAN:0)
Block(-7,38,0,OBSIDIAN:0)
Block(-7,38,1,OBSIDIAN:0)
Block(-7,38,2,OBSIDIAN:0)
Block(-7,38,3,OBSIDIAN:0)
Block(-7,38,4,OBSIDIAN:0)
Block(-7,38,5,OBSIDIAN:0)
Block(-7,38,6,OBSIDIAN:0)
Block(-7,38,7,OBSIDIAN:0)
Block(-7,38,8,OBSIDIAN:0)
Block(-7,39,-7,OBSIDIAN:0)
Block(-7,39,-6,OBSIDIAN:0)
Block(-7,39,-5,OBSIDIAN:0)
Block(-7,39,-4,OBSIDIAN:0)
Block(-7,39,-3,OBSIDIAN:0)
Block(-7,39,-2,OBSIDIAN:0)
Block(-7,39,-1,OBSIDIAN:0)
Block(-7,39,0,OBSIDIAN:0)
Block(-7,39,1,OBSIDIAN:0)
Block(-7,39,2,OBSIDIAN:0)
Block(-7,39,3,OBSIDIAN:0)
Block(-7,39,4,OBSIDIAN:0)
Block(-7,39,5,OBSIDIAN:0)
Block(-7,39,6,OBSIDIAN:0)
Block(-7,39,7,OBSIDIAN:0)
Block(-7,39,8,STONE:5)
Block(-7,40,-7,OBSIDIAN:0)
Block(-7,40,-6,OBSIDIAN:0)
Block(-7,40,-5,OBSIDIAN:0)
Block(-7,40,-4,OBSIDIAN:0)
Block(-7,40,-3,OBSIDIAN:0)
Block(-7,40,-2,OBSIDIAN:0)
Block(-7,40,-1,OBSIDIAN:0)
Block(-7,40,0,OBSIDIAN:0)
Block(-7,40,1,OBSIDIAN:0)
Block(-7,40,2,OBSIDIAN:0)
Block(-7,40,3,OBSIDIAN:0)
Block(-7,40,4,OBSIDIAN:0)
Block(-7,40,5,OBSIDIAN:0)
Block(-7,40,6,STONE:5)
Block(-7,40,7,STONE:5)
Block(-7,40,8,STONE:5)
Block(-7,41,-7,OBSIDIAN:0)
Block(-7,41,-6,OBSIDIAN:0)
Block(-7,41,-5,OBSIDIAN:0)
Block(-7,41,-4,OBSIDIAN:0)
Block(-7,41,-3,OBSIDIAN:0)
Block(-7,41,-2,OBSIDIAN:0)
Block(-7,41,-1,OBSIDIAN:0)
Block(-7,41,0,OBSIDIAN:0)
Block(-7,41,1,OBSIDIAN:0)
Block(-7,41,2,OBSIDIAN:0)
Block(-7,41,3,OBSIDIAN:0)
Block(-7,41,4,OBSIDIAN:0)
Block(-7,41,5,STONE:5)
Block(-7,41,6,STONE:5)
Block(-7,41,7,STONE:5)
Block(-7,41,8,STONE:5)
Block(-7,42,-7,OBSIDIAN:0)
Block(-7,42,-6,OBSIDIAN:0)
Block(-7,42,-5,OBSIDIAN:0)
Block(-7,42,-4,OBSIDIAN:0)
Block(-7,42,-3,OBSIDIAN:0)
Block(-7,42,-2,OBSIDIAN:0)
Block(-7,42,-1,OBSIDIAN:0)
Block(-7,42,0,OBSIDIAN:0)
Block(-7,42,1,OBSIDIAN:0)
Block(-7,42,2,OBSIDIAN:0)
Block(-7,42,3,OBSIDIAN:0)
Block(-7,42,4,STONE:5)
Block(-7,42,5,STONE:5)
Block(-7,42,6,STONE:5)
Block(-7,42,7,STONE:5)
Block(-7,42,8,STONE:5)
Block(-7,43,-7,OBSIDIAN:0)
Block(-7,43,-6,OBSIDIAN:0)
Block(-7,43,-5,OBSIDIAN:0)
Block(-7,43,-4,OBSIDIAN:0)
Block(-7,43,-3,OBSIDIAN:0)
Block(-7,43,-2,OBSIDIAN:0)
Block(-7,43,-1,OBSIDIAN:0)
Block(-7,43,0,OBSIDIAN:0)
Block(-7,43,1,OBSIDIAN:0)
Block(-7,43,2,OBSIDIAN:0)
Block(-7,43,3,STONE:5)
Block(-7,43,4,STONE:5)
Block(-7,43,5,STONE:5)
Block(-7,43,6,STONE:5)
Block(-7,43,7,AIR:0)
Block(-7,43,8,AIR:0)
Block(-7,44,-7,OBSIDIAN:0)
Block(-7,44,-6,OBSIDIAN:0)
Block(-7,44,-5,OBSIDIAN:0)
Block(-7,44,-4,OBSIDIAN:0)
Block(-7,44,-3,OBSIDIAN:0)
Block(-7,44,-2,OBSIDIAN:0)
Block(-7,44,-1,OBSIDIAN:0)
Block(-7,44,0,OBSIDIAN:0)
Block(-7,44,1,OBSIDIAN:0)
Block(-7,44,2,OBSIDIAN:0)
Block(-7,44,3,STONE:5)
Block(-7,44,4,STONE:5)
Block(-7,44,5,STONE:5)
Block(-7,44,6,STONE:5)
Block(-7,44,7,AIR:0)
Block(-7,44,8,AIR:0)
Block(-7,45,-7,OBSIDIAN:0)
Block(-7,45,-6,OBSIDIAN:0)
Block(-7,45,-5,OBSIDIAN:0)
Block(-7,45,-4,OBSIDIAN:0)
Block(-7,45,-3,OBSIDIAN:0)
Block(-7,45,-2,OBSIDIAN:0)
Block(-7,45,-1,OBSIDIAN:0)
Block(-7,45,0,OBSIDIAN:0)
Block(-7,45,1,OBSIDIAN:0)
Block(-7,45,2,OBSIDIAN:0)
Block(-7,45,3,STONE:5)
Block(-7,45,4,STONE:5)
Block(-7,45,5,STONE:5)
Block(-7,45,6,AIR:0)
Block(-7,45,7,AIR:0)
Block(-7,45,8,AIR:0)
Block(-7,46,-7,OBSIDIAN:0)
Block(-7,46,-6,OBSIDIAN:0)
Block(-7,46,-5,OBSIDIAN:0)
Block(-7,46,-4,STONE:3)
Block(-7,46,-3,STONE:3)
Block(-7,46,-2,STONE:3)
Block(-7,46,-1,STONE:3)
Block(-7,46,0,STONE:3)
Block(-7,46,1,STONE:5)
Block(-7,46,2,STONE:5)
Block(-7,46,3,STONE:5)
Block(-7,46,4,STONE:5)
Block(-7,46,5,STONE:5)
Block(-7,46,6,AIR:0)
Block(-7,46,7,AIR:0)
Block(-7,46,8,AIR:0)
Block(-7,47,-7,OBSIDIAN:0)
Block(-7,47,-6,OBSIDIAN:0)
Block(-7,47,-5,STONE:3)
Block(-7,47,-4,STONE:3)
Block(-7,47,-3,STONE:3)
Block(-7,47,-2,STONE:3)
Block(-7,47,-1,STONE:3)
Block(-7,47,0,STONE:3)
Block(-7,47,1,STONE:3)
Block(-7,47,2,STONE:5)
Block(-7,47,3,STONE:5)
Block(-7,47,4,STONE:5)
Block(-7,47,5,AIR:0)
Block(-7,47,6,AIR:0)
Block(-7,47,7,AIR:0)
Block(-7,47,8,AIR:0)
Block(-7,48,-7,OBSIDIAN:0)
Block(-7,48,-6,OBSIDIAN:0)
Block(-7,48,-5,STONE:3)
Block(-7,48,-4,STONE:3)
Block(-7,48,-3,STONE:3)
Block(-7,48,-2,STONE:3)
Block(-7,48,-1,AIR:0)
Block(-7,48,0,STONE:3)
Block(-7,48,1,STONE:3)
Block(-7,48,2,AIR:0)
Block(-7,48,3,AIR:0)
Block(-7,48,4,AIR:0)
Block(-7,48,5,AIR:0)
Block(-7,48,6,AIR:0)
Block(-7,48,7,AIR:0)
Block(-7,48,8,AIR:0)
Block(-7,49,-7,OBSIDIAN:0)
Block(-7,49,-6,OBSIDIAN:0)
Block(-7,49,-5,AIR:0)
Block(-7,49,-4,AIR:0)
Block(-7,49,-3,AIR:0)
Block(-7,49,-2,AIR:0)
Block(-7,49,-1,AIR:0)
Block(-7,49,0,STONE:3)
Block(-7,49,1,AIR:0)
Block(-7,49,2,AIR:0)
Block(-7,49,3,AIR:0)
Block(-7,49,4,AIR:0)
Block(-7,49,5,AIR:0)
Block(-7,49,6,AIR:0)
Block(-7,49,7,AIR:0)
Block(-7,49,8,AIR:0)
Block(-7,50,-7,OBSIDIAN:0)
Block(-7,50,-6,OBSIDIAN:0)
Block(-7,50,-5,STONE:3)
Block(-7,50,-4,AIR:0)
Block(-7,50,-3,AIR:0)
Block(-7,50,-2,AIR:0)
Block(-7,50,-1,AIR:0)
Block(-7,50,0,AIR:0)
Block(-7,50,1,AIR:0)
Block(-7,50,2,AIR:0)
Block(-7,50,3,AIR:0)
Block(-7,50,4,AIR:0)
Block(-7,50,5,AIR:0)
Block(-7,50,6,AIR:0)
Block(-7,50,7,AIR:0)
Block(-7,50,8,AIR:0)
Block(-7,51,-7,OBSIDIAN:0)
Block(-7,51,-6,OBSIDIAN:0)
Block(-7,51,-5,OBSIDIAN:0)
Block(-7,51,-4,AIR:0)
Block(-7,51,-3,AIR:0)
Block(-7,51,-2,AIR:0)
Block(-7,51,-1,AIR:0)
Block(-7,51,0,AIR:0)
Block(-7,51,1,AIR:0)
Block(-7,51,2,AIR:0)
Block(-7,51,3,AIR:0)
Block(-7,51,4,AIR:0)
Block(-7,51,5,AIR:0)
Block(-7,51,6,AIR:0)
Block(-7,51,7,AIR:0)
Block(-7,51,8,AIR:0)
Block(-7,52,-7,OBSIDIAN:0)
Block(-7,52,-6,OBSIDIAN:0)
Block(-7,52,-5,OBSIDIAN:0)
Block(-7,52,-4,AIR:0)
Block(-7,52,-3,AIR:0)
Block(-7,52,-2,AIR:0)
Block(-7,52,-1,AIR:0)
Block(-7,52,0,AIR:0)
Block(-7,52,1,AIR:0)
Block(-7,52,2,AIR:0)
Block(-7,52,3,AIR:0)
Block(-7,52,4,AIR:0)
Block(-7,52,5,AIR:0)
Block(-7,52,6,AIR:0)
Block(-7,52,7,AIR:0)
Block(-7,52,8,AIR:0)
Block(-7,53,-7,OBSIDIAN:0)
Block(-7,53,-6,OBSIDIAN:0)
Block(-7,53,-5,AIR:0)
Block(-7,53,-4,AIR:0)
Block(-7,53,-3,AIR:0)
Block(-7,53,-2,AIR:0)
Block(-7,53,-1,AIR:0)
Block(-7,53,0,AIR:0)
Block(-7,53,1,AIR:0)
Block(-7,53,2,AIR:0)
Block(-7,53,3,AIR:0)
Block(-7,53,4,AIR:0)
Block(-7,53,5,AIR:0)
Block(-7,53,6,AIR:0)
Block(-7,53,7,AIR:0)
Block(-7,53,8,AIR:0)
Block(-7,54,-7,AIR:0)
Block(-7,54,-6,AIR:0)
Block(-7,54,-5,AIR:0)
Block(-7,54,-4,AIR:0)
Block(-7,54,-3,AIR:0)
Block(-7,54,-2,AIR:0)
Block(-7,54,-1,AIR:0)
Block(-7,54,0,AIR:0)
Block(-7,54,1,AIR:0)
Block(-7,54,2,AIR:0)
Block(-7,54,3,AIR:0)
Block(-7,54,4,AIR:0)
Block(-7,54,5,AIR:0)
Block(-7,54,6,AIR:0)
Block(-7,54,7,AIR:0)
Block(-7,54,8,AIR:0)
Block(-7,55,-7,AIR:0)
Block(-7,55,-6,AIR:0)
Block(-7,55,-5,AIR:0)
Block(-7,55,-4,AIR:0)
Block(-7,55,-3,AIR:0)
Block(-7,55,-2,AIR:0)
Block(-7,55,-1,AIR:0)
Block(-7,55,0,AIR:0)
Block(-7,55,1,AIR:0)
Block(-7,55,2,AIR:0)
Block(-7,55,3,AIR:0)
Block(-7,55,4,AIR:0)
Block(-7,55,5,AIR:0)
Block(-7,55,6,AIR:0)
Block(-7,55,7,AIR:0)
Block(-7,55,8,AIR:0)
Block(-7,56,-7,AIR:0)
Block(-7,56,-6,AIR:0)
Block(-7,56,-5,AIR:0)
Block(-7,56,-4,AIR:0)
Block(-7,56,-3,AIR:0)
Block(-7,56,-2,AIR:0)
Block(-7,56,-1,AIR:0)
Block(-7,56,0,AIR:0)
Block(-7,56,1,AIR:0)
Block(-7,56,2,AIR:0)
Block(-7,56,3,AIR:0)
Block(-7,56,4,AIR:0)
Block(-7,56,5,AIR:0)
Block(-7,56,6,AIR:0)
Block(-7,56,7,AIR:0)
Block(-7,56,8,AIR:0)
Block(-7,57,-7,AIR:0)
Block(-7,57,-6,AIR:0)
Block(-7,57,-5,AIR:0)
Block(-7,57,-4,AIR:0)
Block(-7,57,-3,AIR:0)
Block(-7,57,-2,AIR:0)
Block(-7,57,-1,AIR:0)
Block(-7,57,0,AIR:0)
Block(-7,57,1,AIR:0)
Block(-7,57,2,AIR:0)
Block(-7,57,3,AIR:0)
Block(-7,57,4,AIR:0)
Block(-7,57,5,AIR:0)
Block(-7,57,6,AIR:0)
Block(-7,57,7,AIR:0)
Block(-7,57,8,AIR:0)
Block(-7,58,-7,AIR:0)
Block(-7,58,-6,AIR:0)
Block(-7,58,-5,AIR:0)
Block(-7,58,-4,AIR:0)
Block(-7,58,-3,AIR:0)
Block(-7,58,-2,AIR:0)
Block(-7,58,-1,AIR:0)
Block(-7,58,0,AIR:0)
Block(-7,58,1,AIR:0)
Block(-7,58,2,AIR:0)
Block(-7,58,3,AIR:0)
Block(-7,58,4,AIR:0)
Block(-7,58,5,AIR:0)
Block(-7,58,6,AIR:0)
Block(-7,58,7,AIR:0)
Block(-7,58,8,AIR:0)
Block(-7,59,-7,AIR:0)
Block(-7,59,-6,AIR:0)
Block(-7,59,-5,AIR:0)
Block(-7,59,-4,AIR:0)
Block(-7,59,-3,AIR:0)
Block(-7,59,-2,AIR:0)
Block(-7,59,-1,AIR:0)
Block(-7,59,0,AIR:0)
Block(-7,59,1,AIR:0)
Block(-7,59,2,AIR:0)
Block(-7,59,3,AIR:0)
Block(-7,59,4,AIR:0)
Block(-7,59,5,AIR:0)
Block(-7,59,6,AIR:0)
Block(-7,59,7,AIR:0)
Block(-7,59,8,AIR:0)
Block(-7,60,-7,AIR:0)
Block(-7,60,-6,AIR:0)
Block(-7,60,-5,AIR:0)
Block(-7,60,-4,AIR:0)
Block(-7,60,-3,AIR:0)
Block(-7,60,-2,AIR:0)
Block(-7,60,-1,AIR:0)
Block(-7,60,0,AIR:0)
Block(-7,60,1,AIR:0)
Block(-7,60,2,AIR:0)
Block(-7,60,3,AIR:0)
Block(-7,60,4,AIR:0)
Block(-7,60,5,AIR:0)
Block(-7,60,6,AIR:0)
Block(-7,60,7,AIR:0)
Block(-7,60,8,AIR:0)
Block(-7,61,-7,AIR:0)
Block(-7,61,-6,AIR:0)
Block(-7,61,-5,AIR:0)
Block(-7,61,-4,OBSIDIAN:0)
Block(-7,61,-3,AIR:0)
Block(-7,61,-2,AIR:0)
Block(-7,61,-1,AIR:0)
Block(-7,61,0,AIR:0)
Block(-7,61,1,AIR:0)
Block(-7,61,2,AIR:0)
Block(-7,61,3,AIR:0)
Block(-7,61,4,AIR:0)
Block(-7,61,5,AIR:0)
Block(-7,61,6,AIR:0)
Block(-7,61,7,AIR:0)
Block(-7,61,8,AIR:0)
Block(-7,62,-7,AIR:0)
Block(-7,62,-6,AIR:0)
Block(-7,62,-5,AIR:0)
Block(-7,62,-4,AIR:0)
Block(-7,62,-3,OBSIDIAN:0)
Block(-7,62,-2,OBSIDIAN:0)
Block(-7,62,-1,AIR:0)
Block(-7,62,0,AIR:0)
Block(-7,62,1,AIR:0)
Block(-7,62,2,AIR:0)
Block(-7,62,3,AIR:0)
Block(-7,62,4,AIR:0)
Block(-7,62,5,AIR:0)
Block(-7,62,6,AIR:0)
Block(-7,62,7,AIR:0)
Block(-7,62,8,AIR:0)
Block(-7,63,-7,AIR:0)
Block(-7,63,-6,AIR:0)
Block(-7,63,-5,AIR:0)
Block(-7,63,-4,AIR:0)
Block(-7,63,-3,OBSIDIAN:0)
Block(-7,63,-2,OBSIDIAN:0)
Block(-7,63,-1,OBSIDIAN:0)
Block(-7,63,0,AIR:0)
Block(-7,63,1,AIR:0)
Block(-7,63,2,AIR:0)
Block(-7,63,3,AIR:0)
Block(-7,63,4,AIR:0)
Block(-7,63,5,AIR:0)
Block(-7,63,6,AIR:0)
Block(-7,63,7,AIR:0)
Block(-7,63,8,AIR:0)
Block(-7,64,-7,AIR:0)
Block(-7,64,-6,AIR:0)
Block(-7,64,-5,AIR:0)
Block(-7,64,-4,AIR:0)
Block(-7,64,-3,OBSIDIAN:0)
Block(-7,64,-2,OBSIDIAN:0)
Block(-7,64,-1,OBSIDIAN:0)
Block(-7,64,0,OBSIDIAN:0)
Block(-7,64,1,AIR:0)
Block(-7,64,2,AIR:0)
Block(-7,64,3,AIR:0)
Block(-7,64,4,AIR:0)
Block(-7,64,5,AIR:0)
Block(-7,64,6,AIR:0)
Block(-7,64,7,AIR:0)
Block(-7,64,8,AIR:0)
Block(-7,65,-7,AIR:0)
Block(-7,65,-6,AIR:0)
Block(-7,65,-5,AIR:0)
Block(-7,65,-4,AIR:0)
Block(-7,65,-3,OBSIDIAN:0)
Block(-7,65,-2,OBSIDIAN:0)
Block(-7,65,-1,OBSIDIAN:0)
Block(-7,65,0,OBSIDIAN:0)
Block(-7,65,1,OBSIDIAN:0)
Block(-7,65,2,AIR:0)
Block(-7,65,3,AIR:0)
Block(-7,65,4,AIR:0)
Block(-7,65,5,AIR:0)
Block(-7,65,6,AIR:0)
Block(-7,65,7,AIR:0)
Block(-7,65,8,AIR:0)
Block(-7,66,-7,AIR:0)
Block(-7,66,-6,AIR:0)
Block(-7,66,-5,AIR:0)
Block(-7,66,-4,AIR:0)
Block(-7,66,-3,OBSIDIAN:0)
Block(-7,66,-2,OBSIDIAN:0)
Block(-7,66,-1,OBSIDIAN:0)
Block(-7,66,0,OBSIDIAN:0)
Block(-7,66,1,OBSIDIAN:0)
Block(-7,66,2,AIR:0)
Block(-7,66,3,AIR:0)
Block(-7,66,4,AIR:0)
Block(-7,66,5,AIR:0)
Block(-7,66,6,AIR:0)
Block(-7,66,7,AIR:0)
Block(-7,66,8,AIR:0)
Block(-7,67,-7,AIR:0)
Block(-7,67,-6,AIR:0)
Block(-7,67,-5,AIR:0)
Block(-7,67,-4,OBSIDIAN:0)
Block(-7,67,-3,OBSIDIAN:0)
Block(-7,67,-2,OBSIDIAN:0)
Block(-7,67,-1,OBSIDIAN:0)
Block(-7,67,0,OBSIDIAN:0)
Block(-7,67,1,OBSIDIAN:0)
Block(-7,67,2,OBSIDIAN:0)
Block(-7,67,3,AIR:0)
Block(-7,67,4,AIR:0)
Block(-7,67,5,AIR:0)
Block(-7,67,6,AIR:0)
Block(-7,67,7,AIR:0)
Block(-7,67,8,AIR:0)
Block(-7,68,-7,AIR:0)
Block(-7,68,-6,OBSIDIAN:0)
Block(-7,68,-5,OBSIDIAN:0)
Block(-7,68,-4,OBSIDIAN:0)
Block(-7,68,-3,OBSIDIAN:0)
Block(-7,68,-2,OBSIDIAN:0)
Block(-7,68,-1,OBSIDIAN:0)
Block(-7,68,0,OBSIDIAN:0)
Block(-7,68,1,OBSIDIAN:0)
Block(-7,68,2,OBSIDIAN:0)
Block(-7,68,3,OBSIDIAN:0)
Block(-7,68,4,AIR:0)
Block(-7,68,5,AIR:0)
Block(-7,68,6,AIR:0)
Block(-7,68,7,AIR:0)
Block(-7,68,8,AIR:0)
Block(-7,69,-7,OBSIDIAN:0)
Block(-7,69,-6,OBSIDIAN:0)
Block(-7,69,-5,OBSIDIAN:0)
Block(-7,69,-4,OBSIDIAN:0)
Block(-7,69,-3,OBSIDIAN:0)
Block(-7,69,-2,OBSIDIAN:0)
Block(-7,69,-1,OBSIDIAN:0)
Block(-7,69,0,OBSIDIAN:0)
Block(-7,69,1,OBSIDIAN:0)
Block(-7,69,2,OBSIDIAN:0)
Block(-7,69,3,OBSIDIAN:0)
Block(-7,69,4,OBSIDIAN:0)
Block(-7,69,5,AIR:0)
Block(-7,69,6,AIR:0)
Block(-7,69,7,AIR:0)
Block(-7,69,8,AIR:0)
Block(-7,70,-7,OBSIDIAN:0)
Block(-7,70,-6,OBSIDIAN:0)
Block(-7,70,-5,OBSIDIAN:0)
Block(-7,70,-4,OBSIDIAN:0)
Block(-7,70,-3,OBSIDIAN:0)
Block(-7,70,-2,OBSIDIAN:0)
Block(-7,70,-1,OBSIDIAN:0)
Block(-7,70,0,OBSIDIAN:0)
Block(-7,70,1,OBSIDIAN:0)
Block(-7,70,2,OBSIDIAN:0)
Block(-7,70,3,OBSIDIAN:0)
Block(-7,70,4,OBSIDIAN:0)
Block(-7,70,5,AIR:0)
Block(-7,70,6,AIR:0)
Block(-7,70,7,AIR:0)
Block(-7,70,8,AIR:0)
Block(-7,71,-7,OBSIDIAN:0)
Block(-7,71,-6,OBSIDIAN:0)
Block(-7,71,-5,OBSIDIAN:0)
Block(-7,71,-4,OBSIDIAN:0)
Block(-7,71,-3,OBSIDIAN:0)
Block(-7,71,-2,OBSIDIAN:0)
Block(-7,71,-1,OBSIDIAN:0)
Block(-7,71,0,OBSIDIAN:0)
Block(-7,71,1,OBSIDIAN:0)
Block(-7,71,2,OBSIDIAN:0)
Block(-7,71,3,OBSIDIAN:0)
Block(-7,71,4,OBSIDIAN:0)
Block(-7,71,5,OBSIDIAN:0)
Block(-7,71,6,AIR:0)
Block(-7,71,7,AIR:0)
Block(-7,71,8,AIR:0)
Block(-7,72,-7,OBSIDIAN:0)
Block(-7,72,-6,OBSIDIAN:0)
Block(-7,72,-5,OBSIDIAN:0)
Block(-7,72,-4,OBSIDIAN:0)
Block(-7,72,-3,OBSIDIAN:0)
Block(-7,72,-2,OBSIDIAN:0)
Block(-7,72,-1,OBSIDIAN:0)
Block(-7,72,0,OBSIDIAN:0)
Block(-7,72,1,OBSIDIAN:0)
Block(-7,72,2,OBSIDIAN:0)
Block(-7,72,3,OBSIDIAN:0)
Block(-7,72,4,OBSIDIAN:0)
Block(-7,72,5,OBSIDIAN:0)
Block(-7,72,6,AIR:0)
Block(-7,72,7,AIR:0)
Block(-7,72,8,AIR:0)
Block(-7,73,-7,OBSIDIAN:0)
Block(-7,73,-6,OBSIDIAN:0)
Block(-7,73,-5,OBSIDIAN:0)
Block(-7,73,-4,OBSIDIAN:0)
Block(-7,73,-3,OBSIDIAN:0)
Block(-7,73,-2,OBSIDIAN:0)
Block(-7,73,-1,OBSIDIAN:0)
Block(-7,73,0,OBSIDIAN:0)
Block(-7,73,1,OBSIDIAN:0)
Block(-7,73,2,OBSIDIAN:0)
Block(-7,73,3,OBSIDIAN:0)
Block(-7,73,4,OBSIDIAN:0)
Block(-7,73,5,OBSIDIAN:0)
Block(-7,73,6,OBSIDIAN:0)
Block(-7,73,7,AIR:0)
Block(-7,73,8,AIR:0)
Block(-7,74,-7,OBSIDIAN:0)
Block(-7,74,-6,OBSIDIAN:0)
Block(-7,74,-5,OBSIDIAN:0)
Block(-7,74,-4,OBSIDIAN:0)
Block(-7,74,-3,OBSIDIAN:0)
Block(-7,74,-2,OBSIDIAN:0)
Block(-7,74,-1,OBSIDIAN:0)
Block(-7,74,0,OBSIDIAN:0)
Block(-7,74,1,OBSIDIAN:0)
Block(-7,74,2,OBSIDIAN:0)
Block(-7,74,3,OBSIDIAN:0)
Block(-7,74,4,OBSIDIAN:0)
Block(-7,74,5,OBSIDIAN:0)
Block(-7,74,6,OBSIDIAN:0)
Block(-7,74,7,OBSIDIAN:0)
Block(-7,74,8,AIR:0)
Block(-7,75,-7,OBSIDIAN:0)
Block(-7,75,-6,OBSIDIAN:0)
Block(-7,75,-5,OBSIDIAN:0)
Block(-7,75,-4,OBSIDIAN:0)
Block(-7,75,-3,OBSIDIAN:0)
Block(-7,75,-2,OBSIDIAN:0)
Block(-7,75,-1,OBSIDIAN:0)
Block(-7,75,0,OBSIDIAN:0)
Block(-7,75,1,OBSIDIAN:0)
Block(-7,75,2,OBSIDIAN:0)
Block(-7,75,3,OBSIDIAN:0)
Block(-7,75,4,OBSIDIAN:0)
Block(-7,75,5,OBSIDIAN:0)
Block(-7,75,6,OBSIDIAN:0)
Block(-7,75,7,OBSIDIAN:0)
Block(-7,75,8,OBSIDIAN:0)
Block(-7,76,-7,OBSIDIAN:0)
Block(-7,76,-6,OBSIDIAN:0)
Block(-7,76,-5,OBSIDIAN:0)
Block(-7,76,-4,OBSIDIAN:0)
Block(-7,76,-3,OBSIDIAN:0)
Block(-7,76,-2,OBSIDIAN:0)
Block(-7,76,-1,OBSIDIAN:0)
Block(-7,76,0,OBSIDIAN:0)
Block(-7,76,1,OBSIDIAN:0)
Block(-7,76,2,OBSIDIAN:0)
Block(-7,76,3,OBSIDIAN:0)
Block(-7,76,4,OBSIDIAN:0)
Block(-7,76,5,OBSIDIAN:0)
Block(-7,76,6,OBSIDIAN:0)
Block(-7,76,7,OBSIDIAN:0)
Block(-7,76,8,OBSIDIAN:0)
Block(-7,77,-7,OBSIDIAN:0)
Block(-7,77,-6,OBSIDIAN:0)
Block(-7,77,-5,OBSIDIAN:0)
Block(-7,77,-4,OBSIDIAN:0)
Block(-7,77,-3,OBSIDIAN:0)
Block(-7,77,-2,OBSIDIAN:0)
Block(-7,77,-1,OBSIDIAN:0)
Block(-7,77,0,OBSIDIAN:0)
Block(-7,77,1,OBSIDIAN:0)
Block(-7,77,2,OBSIDIAN:0)
Block(-7,77,3,OBSIDIAN:0)
Block(-7,77,4,OBSIDIAN:0)
Block(-7,77,5,OBSIDIAN:0)
Block(-7,77,6,OBSIDIAN:0)
Block(-7,77,7,OBSIDIAN:0)
Block(-7,77,8,OBSIDIAN:0)
Block(-7,78,-7,OBSIDIAN:0)
Block(-7,78,-6,OBSIDIAN:0)
Block(-7,78,-5,OBSIDIAN:0)
Block(-7,78,-4,OBSIDIAN:0)
Block(-7,78,-3,OBSIDIAN:0)
Block(-7,78,-2,OBSIDIAN:0)
Block(-7,78,-1,OBSIDIAN:0)
Block(-7,78,0,OBSIDIAN:0)
Block(-7,78,1,OBSIDIAN:0)
Block(-7,78,2,OBSIDIAN:0)
Block(-7,78,3,OBSIDIAN:0)
Block(-7,78,4,OBSIDIAN:0)
Block(-7,78,5,OBSIDIAN:0)
Block(-7,78,6,OBSIDIAN:0)
Block(-7,78,7,OBSIDIAN:0)
Block(-7,78,8,OBSIDIAN:0)
Block(-7,79,-7,OBSIDIAN:0)
Block(-7,79,-6,OBSIDIAN:0)
Block(-7,79,-5,OBSIDIAN:0)
Block(-7,79,-4,OBSIDIAN:0)
Block(-7,79,-3,OBSIDIAN:0)
Block(-7,79,-2,OBSIDIAN:0)
Block(-7,79,-1,OBSIDIAN:0)
Block(-7,79,0,OBSIDIAN:0)
Block(-7,79,1,OBSIDIAN:0)
Block(-7,79,2,OBSIDIAN:0)
Block(-7,79,3,OBSIDIAN:0)
Block(-7,79,4,OBSIDIAN:0)
Block(-7,79,5,OBSIDIAN:0)
Block(-7,79,6,OBSIDIAN:0)
Block(-7,79,7,OBSIDIAN:0)
Block(-7,79,8,OBSIDIAN:0)
Block(-7,80,-7,OBSIDIAN:0)
Block(-7,80,-6,OBSIDIAN:0)
Block(-7,80,-5,OBSIDIAN:0)
Block(-7,80,-4,OBSIDIAN:0)
Block(-7,80,-3,OBSIDIAN:0)
Block(-7,80,-2,OBSIDIAN:0)
Block(-7,80,-1,OBSIDIAN:0)
Block(-7,80,0,OBSIDIAN:0)
Block(-7,80,1,OBSIDIAN:0)
Block(-7,80,2,OBSIDIAN:0)
Block(-7,80,3,OBSIDIAN:0)
Block(-7,80,4,OBSIDIAN:0)
Block(-7,80,5,OBSIDIAN:0)
Block(-7,80,6,OBSIDIAN:0)
Block(-7,80,7,OBSIDIAN:0)
Block(-7,80,8,OBSIDIAN:0)
Block(-7,81,-7,OBSIDIAN:0)
Block(-7,81,-6,OBSIDIAN:0)
Block(-7,81,-5,OBSIDIAN:0)
Block(-7,81,-4,OBSIDIAN:0)
Block(-7,81,-3,OBSIDIAN:0)
Block(-7,81,-2,OBSIDIAN:0)
Block(-7,81,-1,OBSIDIAN:0)
Block(-7,81,0,OBSIDIAN:0)
Block(-7,81,1,OBSIDIAN:0)
Block(-7,81,2,OBSIDIAN:0)
Block(-7,81,3,OBSIDIAN:0)
Block(-7,81,4,OBSIDIAN:0)
Block(-7,81,5,OBSIDIAN:0)
Block(-7,81,6,OBSIDIAN:0)
Block(-7,81,7,OBSIDIAN:0)
Block(-7,81,8,OBSIDIAN:0)
Block(-7,82,-7,OBSIDIAN:0)
Block(-7,82,-6,OBSIDIAN:0)
Block(-7,82,-5,OBSIDIAN:0)
Block(-7,82,-4,OBSIDIAN:0)
Block(-7,82,-3,OBSIDIAN:0)
Block(-7,82,-2,OBSIDIAN:0)
Block(-7,82,-1,OBSIDIAN:0)
Block(-7,82,0,OBSIDIAN:0)
Block(-7,82,1,OBSIDIAN:0)
Block(-7,82,2,OBSIDIAN:0)
Block(-7,82,3,OBSIDIAN:0)
Block(-7,82,4,OBSIDIAN:0)
Block(-7,82,5,OBSIDIAN:0)
Block(-7,82,6,OBSIDIAN:0)
Block(-7,82,7,OBSIDIAN:0)
Block(-7,82,8,OBSIDIAN:0)
Block(-7,83,-7,OBSIDIAN:0)
Block(-7,83,-6,OBSIDIAN:0)
Block(-7,83,-5,OBSIDIAN:0)
Block(-7,83,-4,OBSIDIAN:0)
Block(-7,83,-3,OBSIDIAN:0)
Block(-7,83,-2,OBSIDIAN:0)
Block(-7,83,-1,OBSIDIAN:0)
Block(-7,83,0,OBSIDIAN:0)
Block(-7,83,1,OBSIDIAN:0)
Block(-7,83,2,OBSIDIAN:0)
Block(-7,83,3,OBSIDIAN:0)
Block(-7,83,4,OBSIDIAN:0)
Block(-7,83,5,OBSIDIAN:0)
Block(-7,83,6,OBSIDIAN:0)
Block(-7,83,7,OBSIDIAN:0)
Block(-7,83,8,OBSIDIAN:0)
Block(-7,84,-7,OBSIDIAN:0)
Block(-7,84,-6,OBSIDIAN:0)
Block(-7,84,-5,OBSIDIAN:0)
Block(-7,84,-4,OBSIDIAN:0)
Block(-7,84,-3,OBSIDIAN:0)
Block(-7,84,-2,OBSIDIAN:0)
Block(-7,84,-1,OBSIDIAN:0)
Block(-7,84,0,OBSIDIAN:0)
Block(-7,84,1,OBSIDIAN:0)
Block(-7,84,2,OBSIDIAN:0)
Block(-7,84,3,OBSIDIAN:0)
Block(-7,84,4,OBSIDIAN:0)
Block(-7,84,5,OBSIDIAN:0)
Block(-7,84,6,OBSIDIAN:0)
Block(-7,84,7,OBSIDIAN:0)
Block(-7,84,8,OBSIDIAN:0)
Block(-7,85,-7,OBSIDIAN:0)
Block(-7,85,-6,OBSIDIAN:0)
Block(-7,85,-5,OBSIDIAN:0)
Block(-7,85,-4,OBSIDIAN:0)
Block(-7,85,-3,OBSIDIAN:0)
Block(-7,85,-2,OBSIDIAN:0)
Block(-7,85,-1,OBSIDIAN:0)
Block(-7,85,0,OBSIDIAN:0)
Block(-7,85,1,OBSIDIAN:0)
Block(-7,85,2,OBSIDIAN:0)
Block(-7,85,3,OBSIDIAN:0)
Block(-7,85,4,OBSIDIAN:0)
Block(-7,85,5,OBSIDIAN:0)
Block(-7,85,6,OBSIDIAN:0)
Block(-7,85,7,OBSIDIAN:0)
Block(-7,85,8,OBSIDIAN:0)
Block(-7,86,-7,OBSIDIAN:0)
Block(-7,86,-6,OBSIDIAN:0)
Block(-7,86,-5,OBSIDIAN:0)
Block(-7,86,-4,OBSIDIAN:0)
Block(-7,86,-3,OBSIDIAN:0)
Block(-7,86,-2,OBSIDIAN:0)
Block(-7,86,-1,OBSIDIAN:0)
Block(-7,86,0,OBSIDIAN:0)
Block(-7,86,1,OBSIDIAN:0)
Block(-7,86,2,OBSIDIAN:0)
Block(-7,86,3,OBSIDIAN:0)
Block(-7,86,4,OBSIDIAN:0)
Block(-7,86,5,OBSIDIAN:0)
Block(-7,86,6,OBSIDIAN:0)
Block(-7,86,7,OBSIDIAN:0)
Block(-7,86,8,OBSIDIAN:0)
Block(-7,87,-7,OBSIDIAN:0)
Block(-7,87,-6,OBSIDIAN:0)
Block(-7,87,-5,OBSIDIAN:0)
Block(-7,87,-4,OBSIDIAN:0)
Block(-7,87,-3,OBSIDIAN:0)
Block(-7,87,-2,OBSIDIAN:0)
Block(-7,87,-1,OBSIDIAN:0)
Block(-7,87,0,OBSIDIAN:0)
Block(-7,87,1,OBSIDIAN:0)
Block(-7,87,2,OBSIDIAN:0)
Block(-7,87,3,OBSIDIAN:0)
Block(-7,87,4,OBSIDIAN:0)
Block(-7,87,5,OBSIDIAN:0)
Block(-7,87,6,OBSIDIAN:0)
Block(-7,87,7,OBSIDIAN:0)
Block(-7,87,8,OBSIDIAN:0)
Block(-7,88,-7,OBSIDIAN:0)
Block(-7,88,-6,OBSIDIAN:0)
Block(-7,88,-5,OBSIDIAN:0)
Block(-7,88,-4,OBSIDIAN:0)
Block(-7,88,-3,OBSIDIAN:0)
Block(-7,88,-2,OBSIDIAN:0)
Block(-7,88,-1,OBSIDIAN:0)
Block(-7,88,0,OBSIDIAN:0)
Block(-7,88,1,OBSIDIAN:0)
Block(-7,88,2,OBSIDIAN:0)
Block(-7,88,3,OBSIDIAN:0)
Block(-7,88,4,OBSIDIAN:0)
Block(-7,88,5,OBSIDIAN:0)
Block(-7,88,6,OBSIDIAN:0)
Block(-7,88,7,OBSIDIAN:0)
Block(-7,88,8,OBSIDIAN:0)
Block(-7,89,-7,OBSIDIAN:0)
Block(-7,89,-6,OBSIDIAN:0)
Block(-7,89,-5,OBSIDIAN:0)
Block(-7,89,-4,OBSIDIAN:0)
Block(-7,89,-3,OBSIDIAN:0)
Block(-7,89,-2,OBSIDIAN:0)
Block(-7,89,-1,OBSIDIAN:0)
Block(-7,89,0,OBSIDIAN:0)
Block(-7,89,1,OBSIDIAN:0)
Block(-7,89,2,OBSIDIAN:0)
Block(-7,89,3,OBSIDIAN:0)
Block(-7,89,4,OBSIDIAN:0)
Block(-7,89,5,OBSIDIAN:0)
Block(-7,89,6,OBSIDIAN:0)
Block(-7,89,7,OBSIDIAN:0)
Block(-7,89,8,OBSIDIAN:0)
Block(-7,90,-7,OBSIDIAN:0)
Block(-7,90,-6,OBSIDIAN:0)
Block(-7,90,-5,OBSIDIAN:0)
Block(-7,90,-4,OBSIDIAN:0)
Block(-7,90,-3,OBSIDIAN:0)
Block(-7,90,-2,OBSIDIAN:0)
Block(-7,90,-1,OBSIDIAN:0)
Block(-7,90,0,OBSIDIAN:0)
Block(-7,90,1,OBSIDIAN:0)
Block(-7,90,2,OBSIDIAN:0)
Block(-7,90,3,OBSIDIAN:0)
Block(-7,90,4,OBSIDIAN:0)
Block(-7,90,5,OBSIDIAN:0)
Block(-7,90,6,OBSIDIAN:0)
Block(-7,90,7,OBSIDIAN:0)
Block(-7,90,8,OBSIDIAN:0)
Block(-7,91,-7,OBSIDIAN:0)
Block(-7,91,-6,OBSIDIAN:0)
Block(-7,91,-5,OBSIDIAN:0)
Block(-7,91,-4,OBSIDIAN:0)
Block(-7,91,-3,OBSIDIAN:0)
Block(-7,91,-2,OBSIDIAN:0)
Block(-7,91,-1,OBSIDIAN:0)
Block(-7,91,0,OBSIDIAN:0)
Block(-7,91,1,OBSIDIAN:0)
Block(-7,91,2,OBSIDIAN:0)
Block(-7,91,3,OBSIDIAN:0)
Block(-7,91,4,OBSIDIAN:0)
Block(-7,91,5,OBSIDIAN:0)
Block(-7,91,6,OBSIDIAN:0)
Block(-7,91,7,OBSIDIAN:0)
Block(-7,91,8,OBSIDIAN:0)
Block(-7,92,-7,OBSIDIAN:0)
Block(-7,92,-6,OBSIDIAN:0)
Block(-7,92,-5,OBSIDIAN:0)
Block(-7,92,-4,OBSIDIAN:0)
Block(-7,92,-3,OBSIDIAN:0)
Block(-7,92,-2,OBSIDIAN:0)
Block(-7,92,-1,OBSIDIAN:0)
Block(-7,92,0,OBSIDIAN:0)
Block(-7,92,1,OBSIDIAN:0)
Block(-7,92,2,OBSIDIAN:0)
Block(-7,92,3,OBSIDIAN:0)
Block(-7,92,4,OBSIDIAN:0)
Block(-7,92,5,OBSIDIAN:0)
Block(-7,92,6,OBSIDIAN:0)
Block(-7,92,7,OBSIDIAN:0)
Block(-7,92,8,OBSIDIAN:0)
Block(-7,93,-7,OBSIDIAN:0)
Block(-7,93,-6,OBSIDIAN:0)
Block(-7,93,-5,OBSIDIAN:0)
Block(-7,93,-4,OBSIDIAN:0)
Block(-7,93,-3,OBSIDIAN:0)
Block(-7,93,-2,OBSIDIAN:0)
Block(-7,93,-1,OBSIDIAN:0)
Block(-7,93,0,OBSIDIAN:0)
Block(-7,93,1,OBSIDIAN:0)
Block(-7,93,2,OBSIDIAN:0)
Block(-7,93,3,OBSIDIAN:0)
Block(-7,93,4,OBSIDIAN:0)
Block(-7,93,5,OBSIDIAN:0)
Block(-7,93,6,OBSIDIAN:0)
Block(-7,93,7,OBSIDIAN:0)
Block(-7,93,8,OBSIDIAN:0)
Block(-7,94,-7,OBSIDIAN:0)
Block(-7,94,-6,OBSIDIAN:0)
Block(-7,94,-5,OBSIDIAN:0)
Block(-7,94,-4,OBSIDIAN:0)
Block(-7,94,-3,OBSIDIAN:0)
Block(-7,94,-2,OBSIDIAN:0)
Block(-7,94,-1,OBSIDIAN:0)
Block(-7,94,0,OBSIDIAN:0)
Block(-7,94,1,OBSIDIAN:0)
Block(-7,94,2,OBSIDIAN:0)
Block(-7,94,3,OBSIDIAN:0)
Block(-7,94,4,OBSIDIAN:0)
Block(-7,94,5,OBSIDIAN:0)
Block(-7,94,6,OBSIDIAN:0)
Block(-7,94,7,OBSIDIAN:0)
Block(-7,94,8,OBSIDIAN:0)
Block(-7,95,-7,OBSIDIAN:0)
Block(-7,95,-6,OBSIDIAN:0)
Block(-7,95,-5,OBSIDIAN:0)
Block(-7,95,-4,OBSIDIAN:0)
Block(-7,95,-3,OBSIDIAN:0)
Block(-7,95,-2,OBSIDIAN:0)
Block(-7,95,-1,OBSIDIAN:0)
Block(-7,95,0,OBSIDIAN:0)
Block(-7,95,1,OBSIDIAN:0)
Block(-7,95,2,OBSIDIAN:0)
Block(-7,95,3,OBSIDIAN:0)
Block(-7,95,4,OBSIDIAN:0)
Block(-7,95,5,OBSIDIAN:0)
Block(-7,95,6,OBSIDIAN:0)
Block(-7,95,7,OBSIDIAN:0)
Block(-7,95,8,OBSIDIAN:0)
Block(-7,96,-7,OBSIDIAN:0)
Block(-7,96,-6,OBSIDIAN:0)
Block(-7,96,-5,OBSIDIAN:0)
Block(-7,96,-4,OBSIDIAN:0)
Block(-7,96,-3,OBSIDIAN:0)
Block(-7,96,-2,OBSIDIAN:0)
Block(-7,96,-1,OBSIDIAN:0)
Block(-7,96,0,OBSIDIAN:0)
Block(-7,96,1,OBSIDIAN:0)
Block(-7,96,2,OBSIDIAN:0)
Block(-7,96,3,OBSIDIAN:0)
Block(-7,96,4,OBSIDIAN:0)
Block(-7,96,5,OBSIDIAN:0)
Block(-7,96,6,OBSIDIAN:0)
Block(-7,96,7,OBSIDIAN:0)
Block(-7,96,8,OBSIDIAN:0)
Block(-7,97,-7,OBSIDIAN:0)
Block(-7,97,-6,OBSIDIAN:0)
Block(-7,97,-5,OBSIDIAN:0)
Block(-7,97,-4,OBSIDIAN:0)
Block(-7,97,-3,OBSIDIAN:0)
Block(-7,97,-2,OBSIDIAN:0)
Block(-7,97,-1,OBSIDIAN:0)
Block(-7,97,0,OBSIDIAN:0)
Block(-7,97,1,OBSIDIAN:0)
Block(-7,97,2,OBSIDIAN:0)
Block(-7,97,3,OBSIDIAN:0)
Block(-7,97,4,OBSIDIAN:0)
Block(-7,97,5,OBSIDIAN:0)
Block(-7,97,6,OBSIDIAN:0)
Block(-7,97,7,OBSIDIAN:0)
Block(-7,97,8,OBSIDIAN:0)
Block(-7,98,-7,OBSIDIAN:0)
Block(-7,98,-6,OBSIDIAN:0)
Block(-7,98,-5,OBSIDIAN:0)
Block(-7,98,-4,OBSIDIAN:0)
Block(-7,98,-3,OBSIDIAN:0)
Block(-7,98,-2,OBSIDIAN:0)
Block(-7,98,-1,OBSIDIAN:0)
Block(-7,98,0,OBSIDIAN:0)
Block(-7,98,1,OBSIDIAN:0)
Block(-7,98,2,OBSIDIAN:0)
Block(-7,98,3,OBSIDIAN:0)
Block(-7,98,4,OBSIDIAN:0)
Block(-7,98,5,OBSIDIAN:0)
Block(-7,98,6,OBSIDIAN:0)
Block(-7,98,7,OBSIDIAN:0)
Block(-7,98,8,OBSIDIAN:0)
Block(-7,99,-7,OBSIDIAN:0)
Block(-7,99,-6,OBSIDIAN:0)
Block(-7,99,-5,OBSIDIAN:0)
Block(-7,99,-4,OBSIDIAN:0)
Block(-7,99,-3,OBSIDIAN:0)
Block(-7,99,-2,OBSIDIAN:0)
Block(-7,99,-1,OBSIDIAN:0)
Block(-7,99,0,OBSIDIAN:0)
Block(-7,99,1,OBSIDIAN:0)
Block(-7,99,2,OBSIDIAN:0)
Block(-7,99,3,OBSIDIAN:0)
Block(-7,99,4,OBSIDIAN:0)
Block(-7,99,5,OBSIDIAN:0)
Block(-7,99,6,OBSIDIAN:0)
Block(-7,99,7,OBSIDIAN:0)
Block(-7,99,8,OBSIDIAN:0)
Block(-7,100,-7,OBSIDIAN:0)
Block(-7,100,-6,OBSIDIAN:0)
Block(-7,100,-5,OBSIDIAN:0)
Block(-7,100,-4,OBSIDIAN:0)
Block(-7,100,-3,OBSIDIAN:0)
Block(-7,100,-2,OBSIDIAN:0)
Block(-7,100,-1,OBSIDIAN:0)
Block(-7,100,0,OBSIDIAN:0)
Block(-7,100,1,OBSIDIAN:0)
Block(-7,100,2,OBSIDIAN:0)
Block(-7,100,3,OBSIDIAN:0)
Block(-7,100,4,OBSIDIAN:0)
Block(-7,100,5,OBSIDIAN:0)
Block(-7,100,6,OBSIDIAN:0)
Block(-7,100,7,OBSIDIAN:0)
Block(-7,100,8,OBSIDIAN:0)
Block(-7,101,-7,OBSIDIAN:0)
Block(-7,101,-6,OBSIDIAN:0)
Block(-7,101,-5,OBSIDIAN:0)
Block(-7,101,-4,OBSIDIAN:0)
Block(-7,101,-3,OBSIDIAN:0)
Block(-7,101,-2,OBSIDIAN:0)
Block(-7,101,-1,OBSIDIAN:0)
Block(-7,101,0,OBSIDIAN:0)
Block(-7,101,1,OBSIDIAN:0)
Block(-7,101,2,OBSIDIAN:0)
Block(-7,101,3,OBSIDIAN:0)
Block(-7,101,4,OBSIDIAN:0)
Block(-7,101,5,OBSIDIAN:0)
Block(-7,101,6,OBSIDIAN:0)
Block(-7,101,7,OBSIDIAN:0)
Block(-7,101,8,OBSIDIAN:0)
Block(-7,102,-7,OBSIDIAN:0)
Block(-7,102,-6,OBSIDIAN:0)
Block(-7,102,-5,OBSIDIAN:0)
Block(-7,102,-4,OBSIDIAN:0)
Block(-7,102,-3,OBSIDIAN:0)
Block(-7,102,-2,OBSIDIAN:0)
Block(-7,102,-1,OBSIDIAN:0)
Block(-7,102,0,OBSIDIAN:0)
Block(-7,102,1,OBSIDIAN:0)
Block(-7,102,2,OBSIDIAN:0)
Block(-7,102,3,OBSIDIAN:0)
Block(-7,102,4,OBSIDIAN:0)
Block(-7,102,5,OBSIDIAN:0)
Block(-7,102,6,OBSIDIAN:0)
Block(-7,102,7,OBSIDIAN:0)
Block(-7,102,8,OBSIDIAN:0)
Block(-7,103,-7,OBSIDIAN:0)
Block(-7,103,-6,OBSIDIAN:0)
Block(-7,103,-5,OBSIDIAN:0)
Block(-7,103,-4,OBSIDIAN:0)
Block(-7,103,-3,OBSIDIAN:0)
Block(-7,103,-2,OBSIDIAN:0)
Block(-7,103,-1,OBSIDIAN:0)
Block(-7,103,0,OBSIDIAN:0)
Block(-7,103,1,OBSIDIAN:0)
Block(-7,103,2,OBSIDIAN:0)
Block(-7,103,3,OBSIDIAN:0)
Block(-7,103,4,OBSIDIAN:0)
Block(-7,103,5,OBSIDIAN:0)
Block(-7,103,6,OBSIDIAN:0)
Block(-7,103,7,OBSIDIAN:0)
Block(-7,103,8,STONE:3)
Block(-7,104,-7,OBSIDIAN:0)
Block(-7,104,-6,OBSIDIAN:0)
Block(-7,104,-5,OBSIDIAN:0)
Block(-7,104,-4,OBSIDIAN:0)
Block(-7,104,-3,OBSIDIAN:0)
Block(-7,104,-2,OBSIDIAN:0)
Block(-7,104,-1,STONE:3)
Block(-7,104,0,STONE:3)
Block(-7,104,1,STONE:3)
Block(-7,104,2,STONE:3)
Block(-7,104,3,STONE:3)
Block(-7,104,4,OBSIDIAN:0)
Block(-7,104,5,OBSIDIAN:0)
Block(-7,104,6,OBSIDIAN:0)
Block(-7,104,7,STONE:3)
Block(-7,104,8,STONE:3)
Block(-7,105,-7,OBSIDIAN:0)
Block(-7,105,-6,OBSIDIAN:0)
Block(-7,105,-5,OBSIDIAN:0)
Block(-7,105,-4,OBSIDIAN:0)
Block(-7,105,-3,OBSIDIAN:0)
Block(-7,105,-2,STONE:3)
Block(-7,105,-1,STONE:3)
Block(-7,105,0,STONE:3)
Block(-7,105,1,STONE:3)
Block(-7,105,2,STONE:3)
Block(-7,105,3,STONE:3)
Block(-7,105,4,STONE:3)
Block(-7,105,5,STONE:3)
Block(-7,105,6,STONE:3)
Block(-7,105,7,STONE:3)
Block(-7,105,8,STONE:3)
Block(-7,106,-7,STONE:3)
Block(-7,106,-6,OBSIDIAN:0)
Block(-7,106,-5,OBSIDIAN:0)
Block(-7,106,-4,OBSIDIAN:0)
Block(-7,106,-3,STONE:3)
Block(-7,106,-2,STONE:3)
Block(-7,106,-1,STONE:3)
Block(-7,106,0,STONE:3)
Block(-7,106,1,STONE:3)
Block(-7,106,2,STONE:3)
Block(-7,106,3,STONE:3)
Block(-7,106,4,STONE:3)
Block(-7,106,5,STONE:3)
Block(-7,106,6,STONE:3)
Block(-7,106,7,STONE:3)
Block(-7,106,8,STONE:3)
Block(-7,107,-7,STONE:3)
Block(-7,107,-6,STONE:3)
Block(-7,107,-5,STONE:3)
Block(-7,107,-4,STONE:3)
Block(-7,107,-3,STONE:3)
Block(-7,107,-2,STONE:3)
Block(-7,107,-1,STONE:3)
Block(-7,107,0,STONE:3)
Block(-7,107,1,STONE:3)
Block(-7,107,2,STONE:3)
Block(-7,107,3,STONE:3)
Block(-7,107,4,STONE:3)
Block(-7,107,5,STONE:3)
Block(-7,107,6,STONE:3)
Block(-7,107,7,STONE:3)
Block(-7,107,8,STONE:3)
Block(-7,108,-6,STONE:3)
Block(-7,108,-5,STONE:3)
Block(-7,108,-4,STONE:3)
Block(-7,108,-3,STONE:3)
Block(-7,108,-2,STONE:3)
Block(-7,108,-1,STONE:3)
Block(-7,108,0,STONE:3)
Block(-7,108,1,STONE:3)
Block(-7,108,2,STONE:3)
Block(-7,108,3,STONE:3)
Block(-7,108,4,STONE:3)
Block(-7,108,5,STONE:3)
Block(-7,108,6,STONE:3)
Block(-7,108,7,STONE:3)
Block(-7,108,8,STONE:3)
Block(-7,109,1,STONE:3)
Block(-7,109,2,STONE:3)
Block(-7,109,3,STONE:3)
Block(-7,109,4,STONE:3)
Block(-6,13,5,MAGMA:0)
Block(-6,13,7,MAGMA:0)
Block(-6,14,0,STONE:3)
Block(-6,14,1,OBSIDIAN:0)
Block(-6,14,2,OBSIDIAN:0)
Block(-6,14,3,OBSIDIAN:0)
Block(-6,14,4,OBSIDIAN:0)
Block(-6,14,5,MAGMA:0)
Block(-6,14,6,MAGMA:0)
Block(-6,14,7,MAGMA:0)
Block(-6,14,8,MAGMA:0)
Block(-6,15,-3,STONE:3)
Block(-6,15,-2,STONE:3)
Block(-6,15,-1,STONE:3)
Block(-6,15,0,STONE:3)
Block(-6,15,1,OBSIDIAN:0)
Block(-6,15,2,OBSIDIAN:0)
Block(-6,15,3,OBSIDIAN:0)
Block(-6,15,4,OBSIDIAN:0)
Block(-6,15,5,OBSIDIAN:0)
Block(-6,15,6,MAGMA:0)
Block(-6,15,7,MAGMA:0)
Block(-6,15,8,MAGMA:0)
Block(-6,16,-5,STONE:3)
Block(-6,16,-4,STONE:3)
Block(-6,16,-3,STONE:3)
Block(-6,16,-2,STONE:3)
Block(-6,16,-1,STONE:3)
Block(-6,16,0,STONE:3)
Block(-6,16,1,STONE:3)
Block(-6,16,2,OBSIDIAN:0)
Block(-6,16,3,OBSIDIAN:0)
Block(-6,16,4,OBSIDIAN:0)
Block(-6,16,5,OBSIDIAN:0)
Block(-6,16,6,OBSIDIAN:0)
Block(-6,16,7,OBSIDIAN:0)
Block(-6,16,8,OBSIDIAN:0)
Block(-6,17,-5,STONE:3)
Block(-6,17,-4,STONE:3)
Block(-6,17,-3,STONE:3)
Block(-6,17,-2,STONE:3)
Block(-6,17,-1,STONE:3)
Block(-6,17,0,STONE:3)
Block(-6,17,1,STONE:3)
Block(-6,17,2,OBSIDIAN:0)
Block(-6,17,3,OBSIDIAN:0)
Block(-6,17,4,OBSIDIAN:0)
Block(-6,17,5,OBSIDIAN:0)
Block(-6,17,6,OBSIDIAN:0)
Block(-6,17,7,OBSIDIAN:0)
Block(-6,17,8,OBSIDIAN:0)
Block(-6,18,-6,STONE:3)
Block(-6,18,-5,STONE:3)
Block(-6,18,-4,STONE:3)
Block(-6,18,-3,STONE:3)
Block(-6,18,-2,STONE:3)
Block(-6,18,-1,STONE:3)
Block(-6,18,0,STONE:3)
Block(-6,18,1,STONE:3)
Block(-6,18,2,STONE:3)
Block(-6,18,3,OBSIDIAN:0)
Block(-6,18,4,OBSIDIAN:0)
Block(-6,18,5,OBSIDIAN:0)
Block(-6,18,6,OBSIDIAN:0)
Block(-6,18,7,OBSIDIAN:0)
Block(-6,18,8,OBSIDIAN:0)
Block(-6,19,-7,STONE:3)
Block(-6,19,-6,STONE:3)
Block(-6,19,-5,STONE:3)
Block(-6,19,-4,STONE:3)
Block(-6,19,-3,STONE:3)
Block(-6,19,-2,STONE:3)
Block(-6,19,-1,STONE:3)
Block(-6,19,0,STONE:3)
Block(-6,19,1,STONE:3)
Block(-6,19,2,STONE:3)
Block(-6,19,3,STONE:3)
Block(-6,19,4,STONE:3)
Block(-6,19,5,OBSIDIAN:0)
Block(-6,19,6,OBSIDIAN:0)
Block(-6,19,7,OBSIDIAN:0)
Block(-6,19,8,STONE:3)
Block(-6,20,-7,STONE:3)
Block(-6,20,-6,STONE:3)
Block(-6,20,-5,STONE:3)
Block(-6,20,-4,STONE:3)
Block(-6,20,-3,STONE:3)
Block(-6,20,-2,STONE:3)
Block(-6,20,-1,STONE:3)
Block(-6,20,0,OBSIDIAN:0)
Block(-6,20,1,OBSIDIAN:0)
Block(-6,20,2,OBSIDIAN:0)
Block(-6,20,3,OBSIDIAN:0)
Block(-6,20,4,OBSIDIAN:0)
Block(-6,20,5,OBSIDIAN:0)
Block(-6,20,6,OBSIDIAN:0)
Block(-6,20,7,OBSIDIAN:0)
Block(-6,20,8,OBSIDIAN:0)
Block(-6,21,-7,STONE:3)
Block(-6,21,-6,STONE:3)
Block(-6,21,-5,STONE:3)
Block(-6,21,-4,STONE:3)
Block(-6,21,-3,STONE:3)
Block(-6,21,-2,STONE:3)
Block(-6,21,-1,STONE:3)
Block(-6,21,0,OBSIDIAN:0)
Block(-6,21,1,OBSIDIAN:0)
Block(-6,21,2,OBSIDIAN:0)
Block(-6,21,3,OBSIDIAN:0)
Block(-6,21,4,OBSIDIAN:0)
Block(-6,21,5,OBSIDIAN:0)
Block(-6,21,6,OBSIDIAN:0)
Block(-6,21,7,OBSIDIAN:0)
Block(-6,21,8,OBSIDIAN:0)
Block(-6,22,-7,STONE:3)
Block(-6,22,-6,STONE:3)
Block(-6,22,-5,STONE:3)
Block(-6,22,-4,STONE:3)
Block(-6,22,-3,STONE:3)
Block(-6,22,-2,STONE:3)
Block(-6,22,-1,OBSIDIAN:0)
Block(-6,22,0,OBSIDIAN:0)
Block(-6,22,1,OBSIDIAN:0)
Block(-6,22,2,OBSIDIAN:0)
Block(-6,22,3,OBSIDIAN:0)
Block(-6,22,4,OBSIDIAN:0)
Block(-6,22,5,OBSIDIAN:0)
Block(-6,22,6,OBSIDIAN:0)
Block(-6,22,7,OBSIDIAN:0)
Block(-6,22,8,OBSIDIAN:0)
Block(-6,23,-7,STONE:3)
Block(-6,23,-6,STONE:3)
Block(-6,23,-5,STONE:3)
Block(-6,23,-4,STONE:3)
Block(-6,23,-3,OBSIDIAN:0)
Block(-6,23,-2,OBSIDIAN:0)
Block(-6,23,-1,OBSIDIAN:0)
Block(-6,23,0,OBSIDIAN:0)
Block(-6,23,1,OBSIDIAN:0)
Block(-6,23,2,OBSIDIAN:0)
Block(-6,23,3,OBSIDIAN:0)
Block(-6,23,4,OBSIDIAN:0)
Block(-6,23,5,OBSIDIAN:0)
Block(-6,23,6,OBSIDIAN:0)
Block(-6,23,7,OBSIDIAN:0)
Block(-6,23,8,OBSIDIAN:0)
Block(-6,24,-7,OBSIDIAN:0)
Block(-6,24,-6,OBSIDIAN:0)
Block(-6,24,-5,OBSIDIAN:0)
Block(-6,24,-4,OBSIDIAN:0)
Block(-6,24,-3,OBSIDIAN:0)
Block(-6,24,-2,OBSIDIAN:0)
Block(-6,24,-1,OBSIDIAN:0)
Block(-6,24,0,OBSIDIAN:0)
Block(-6,24,1,OBSIDIAN:0)
Block(-6,24,2,OBSIDIAN:0)
Block(-6,24,3,OBSIDIAN:0)
Block(-6,24,4,OBSIDIAN:0)
Block(-6,24,5,OBSIDIAN:0)
Block(-6,24,6,OBSIDIAN:0)
Block(-6,24,7,OBSIDIAN:0)
Block(-6,24,8,OBSIDIAN:0)
Block(-6,25,-7,OBSIDIAN:0)
Block(-6,25,-6,OBSIDIAN:0)
Block(-6,25,-5,OBSIDIAN:0)
Block(-6,25,-4,OBSIDIAN:0)
Block(-6,25,-3,OBSIDIAN:0)
Block(-6,25,-2,OBSIDIAN:0)
Block(-6,25,-1,OBSIDIAN:0)
Block(-6,25,0,OBSIDIAN:0)
Block(-6,25,1,OBSIDIAN:0)
Block(-6,25,2,OBSIDIAN:0)
Block(-6,25,3,OBSIDIAN:0)
Block(-6,25,4,OBSIDIAN:0)
Block(-6,25,5,OBSIDIAN:0)
Block(-6,25,6,OBSIDIAN:0)
Block(-6,25,7,OBSIDIAN:0)
Block(-6,25,8,OBSIDIAN:0)
Block(-6,26,-7,OBSIDIAN:0)
Block(-6,26,-6,OBSIDIAN:0)
Block(-6,26,-5,OBSIDIAN:0)
Block(-6,26,-4,OBSIDIAN:0)
Block(-6,26,-3,OBSIDIAN:0)
Block(-6,26,-2,OBSIDIAN:0)
Block(-6,26,-1,OBSIDIAN:0)
Block(-6,26,0,OBSIDIAN:0)
Block(-6,26,1,OBSIDIAN:0)
Block(-6,26,2,OBSIDIAN:0)
Block(-6,26,3,OBSIDIAN:0)
Block(-6,26,4,OBSIDIAN:0)
Block(-6,26,5,OBSIDIAN:0)
Block(-6,26,6,OBSIDIAN:0)
Block(-6,26,7,OBSIDIAN:0)
Block(-6,26,8,OBSIDIAN:0)
Block(-6,27,-7,OBSIDIAN:0)
Block(-6,27,-6,OBSIDIAN:0)
Block(-6,27,-5,OBSIDIAN:0)
Block(-6,27,-4,OBSIDIAN:0)
Block(-6,27,-3,OBSIDIAN:0)
Block(-6,27,-2,OBSIDIAN:0)
Block(-6,27,-1,OBSIDIAN:0)
Block(-6,27,0,OBSIDIAN:0)
Block(-6,27,1,OBSIDIAN:0)
Block(-6,27,2,OBSIDIAN:0)
Block(-6,27,3,OBSIDIAN:0)
Block(-6,27,4,OBSIDIAN:0)
Block(-6,27,5,OBSIDIAN:0)
Block(-6,27,6,OBSIDIAN:0)
Block(-6,27,7,OBSIDIAN:0)
Block(-6,27,8,OBSIDIAN:0)
Block(-6,28,-7,OBSIDIAN:0)
Block(-6,28,-6,OBSIDIAN:0)
Block(-6,28,-5,OBSIDIAN:0)
Block(-6,28,-4,OBSIDIAN:0)
Block(-6,28,-3,OBSIDIAN:0)
Block(-6,28,-2,OBSIDIAN:0)
Block(-6,28,-1,OBSIDIAN:0)
Block(-6,28,0,OBSIDIAN:0)
Block(-6,28,1,OBSIDIAN:0)
Block(-6,28,2,OBSIDIAN:0)
Block(-6,28,3,OBSIDIAN:0)
Block(-6,28,4,OBSIDIAN:0)
Block(-6,28,5,OBSIDIAN:0)
Block(-6,28,6,OBSIDIAN:0)
Block(-6,28,7,OBSIDIAN:0)
Block(-6,28,8,OBSIDIAN:0)
Block(-6,29,-7,OBSIDIAN:0)
Block(-6,29,-6,OBSIDIAN:0)
Block(-6,29,-5,OBSIDIAN:0)
Block(-6,29,-4,OBSIDIAN:0)
Block(-6,29,-3,OBSIDIAN:0)
Block(-6,29,-2,OBSIDIAN:0)
Block(-6,29,-1,OBSIDIAN:0)
Block(-6,29,0,OBSIDIAN:0)
Block(-6,29,1,OBSIDIAN:0)
Block(-6,29,2,OBSIDIAN:0)
Block(-6,29,3,OBSIDIAN:0)
Block(-6,29,4,OBSIDIAN:0)
Block(-6,29,5,OBSIDIAN:0)
Block(-6,29,6,OBSIDIAN:0)
Block(-6,29,7,OBSIDIAN:0)
Block(-6,29,8,OBSIDIAN:0)
Block(-6,30,-7,OBSIDIAN:0)
Block(-6,30,-6,OBSIDIAN:0)
Block(-6,30,-5,OBSIDIAN:0)
Block(-6,30,-4,OBSIDIAN:0)
Block(-6,30,-3,OBSIDIAN:0)
Block(-6,30,-2,OBSIDIAN:0)
Block(-6,30,-1,OBSIDIAN:0)
Block(-6,30,0,OBSIDIAN:0)
Block(-6,30,1,OBSIDIAN:0)
Block(-6,30,2,OBSIDIAN:0)
Block(-6,30,3,OBSIDIAN:0)
Block(-6,30,4,OBSIDIAN:0)
Block(-6,30,5,OBSIDIAN:0)
Block(-6,30,6,OBSIDIAN:0)
Block(-6,30,7,OBSIDIAN:0)
Block(-6,30,8,OBSIDIAN:0)
Block(-6,31,-7,OBSIDIAN:0)
Block(-6,31,-6,OBSIDIAN:0)
Block(-6,31,-5,OBSIDIAN:0)
Block(-6,31,-4,OBSIDIAN:0)
Block(-6,31,-3,OBSIDIAN:0)
Block(-6,31,-2,OBSIDIAN:0)
Block(-6,31,-1,OBSIDIAN:0)
Block(-6,31,0,OBSIDIAN:0)
Block(-6,31,1,OBSIDIAN:0)
Block(-6,31,2,OBSIDIAN:0)
Block(-6,31,3,OBSIDIAN:0)
Block(-6,31,4,OBSIDIAN:0)
Block(-6,31,5,OBSIDIAN:0)
Block(-6,31,6,OBSIDIAN:0)
Block(-6,31,7,OBSIDIAN:0)
Block(-6,31,8,OBSIDIAN:0)
Block(-6,32,-7,OBSIDIAN:0)
Block(-6,32,-6,OBSIDIAN:0)
Block(-6,32,-5,OBSIDIAN:0)
Block(-6,32,-4,OBSIDIAN:0)
Block(-6,32,-3,OBSIDIAN:0)
Block(-6,32,-2,OBSIDIAN:0)
Block(-6,32,-1,OBSIDIAN:0)
Block(-6,32,0,OBSIDIAN:0)
Block(-6,32,1,OBSIDIAN:0)
Block(-6,32,2,OBSIDIAN:0)
Block(-6,32,3,OBSIDIAN:0)
Block(-6,32,4,OBSIDIAN:0)
Block(-6,32,5,OBSIDIAN:0)
Block(-6,32,6,OBSIDIAN:0)
Block(-6,32,7,OBSIDIAN:0)
Block(-6,32,8,OBSIDIAN:0)
Block(-6,33,-7,OBSIDIAN:0)
Block(-6,33,-6,OBSIDIAN:0)
Block(-6,33,-5,OBSIDIAN:0)
Block(-6,33,-4,OBSIDIAN:0)
Block(-6,33,-3,OBSIDIAN:0)
Block(-6,33,-2,OBSIDIAN:0)
Block(-6,33,-1,OBSIDIAN:0)
Block(-6,33,0,OBSIDIAN:0)
Block(-6,33,1,OBSIDIAN:0)
Block(-6,33,2,OBSIDIAN:0)
Block(-6,33,3,OBSIDIAN:0)
Block(-6,33,4,OBSIDIAN:0)
Block(-6,33,5,OBSIDIAN:0)
Block(-6,33,6,OBSIDIAN:0)
Block(-6,33,7,OBSIDIAN:0)
Block(-6,33,8,OBSIDIAN:0)
Block(-6,34,-7,OBSIDIAN:0)
Block(-6,34,-6,OBSIDIAN:0)
Block(-6,34,-5,OBSIDIAN:0)
Block(-6,34,-4,OBSIDIAN:0)
Block(-6,34,-3,OBSIDIAN:0)
Block(-6,34,-2,OBSIDIAN:0)
Block(-6,34,-1,OBSIDIAN:0)
Block(-6,34,0,OBSIDIAN:0)
Block(-6,34,1,OBSIDIAN:0)
Block(-6,34,2,OBSIDIAN:0)
Block(-6,34,3,OBSIDIAN:0)
Block(-6,34,4,OBSIDIAN:0)
Block(-6,34,5,OBSIDIAN:0)
Block(-6,34,6,OBSIDIAN:0)
Block(-6,34,7,OBSIDIAN:0)
Block(-6,34,8,OBSIDIAN:0)
Block(-6,35,-7,OBSIDIAN:0)
Block(-6,35,-6,OBSIDIAN:0)
Block(-6,35,-5,OBSIDIAN:0)
Block(-6,35,-4,OBSIDIAN:0)
Block(-6,35,-3,OBSIDIAN:0)
Block(-6,35,-2,OBSIDIAN:0)
Block(-6,35,-1,OBSIDIAN:0)
Block(-6,35,0,OBSIDIAN:0)
Block(-6,35,1,OBSIDIAN:0)
Block(-6,35,2,OBSIDIAN:0)
Block(-6,35,3,OBSIDIAN:0)
Block(-6,35,4,OBSIDIAN:0)
Block(-6,35,5,OBSIDIAN:0)
Block(-6,35,6,OBSIDIAN:0)
Block(-6,35,7,OBSIDIAN:0)
Block(-6,35,8,OBSIDIAN:0)
Block(-6,36,-7,OBSIDIAN:0)
Block(-6,36,-6,OBSIDIAN:0)
Block(-6,36,-5,OBSIDIAN:0)
Block(-6,36,-4,OBSIDIAN:0)
Block(-6,36,-3,OBSIDIAN:0)
Block(-6,36,-2,OBSIDIAN:0)
Block(-6,36,-1,OBSIDIAN:0)
Block(-6,36,0,OBSIDIAN:0)
Block(-6,36,1,OBSIDIAN:0)
Block(-6,36,2,OBSIDIAN:0)
Block(-6,36,3,OBSIDIAN:0)
Block(-6,36,4,OBSIDIAN:0)
Block(-6,36,5,OBSIDIAN:0)
Block(-6,36,6,OBSIDIAN:0)
Block(-6,36,7,OBSIDIAN:0)
Block(-6,36,8,OBSIDIAN:0)
Block(-6,37,-7,OBSIDIAN:0)
Block(-6,37,-6,OBSIDIAN:0)
Block(-6,37,-5,OBSIDIAN:0)
Block(-6,37,-4,OBSIDIAN:0)
Block(-6,37,-3,OBSIDIAN:0)
Block(-6,37,-2,OBSIDIAN:0)
Block(-6,37,-1,OBSIDIAN:0)
Block(-6,37,0,OBSIDIAN:0)
Block(-6,37,1,OBSIDIAN:0)
Block(-6,37,2,OBSIDIAN:0)
Block(-6,37,3,OBSIDIAN:0)
Block(-6,37,4,OBSIDIAN:0)
Block(-6,37,5,OBSIDIAN:0)
Block(-6,37,6,OBSIDIAN:0)
Block(-6,37,7,OBSIDIAN:0)
Block(-6,37,8,OBSIDIAN:0)
Block(-6,38,-7,OBSIDIAN:0)
Block(-6,38,-6,OBSIDIAN:0)
Block(-6,38,-5,OBSIDIAN:0)
Block(-6,38,-4,OBSIDIAN:0)
Block(-6,38,-3,OBSIDIAN:0)
Block(-6,38,-2,OBSIDIAN:0)
Block(-6,38,-1,OBSIDIAN:0)
Block(-6,38,0,OBSIDIAN:0)
Block(-6,38,1,OBSIDIAN:0)
Block(-6,38,2,OBSIDIAN:0)
Block(-6,38,3,OBSIDIAN:0)
Block(-6,38,4,OBSIDIAN:0)
Block(-6,38,5,OBSIDIAN:0)
Block(-6,38,6,OBSIDIAN:0)
Block(-6,38,7,OBSIDIAN:0)
Block(-6,38,8,OBSIDIAN:0)
Block(-6,39,-7,OBSIDIAN:0)
Block(-6,39,-6,OBSIDIAN:0)
Block(-6,39,-5,OBSIDIAN:0)
Block(-6,39,-4,OBSIDIAN:0)
Block(-6,39,-3,OBSIDIAN:0)
Block(-6,39,-2,OBSIDIAN:0)
Block(-6,39,-1,OBSIDIAN:0)
Block(-6,39,0,OBSIDIAN:0)
Block(-6,39,1,OBSIDIAN:0)
Block(-6,39,2,OBSIDIAN:0)
Block(-6,39,3,OBSIDIAN:0)
Block(-6,39,4,OBSIDIAN:0)
Block(-6,39,5,OBSIDIAN:0)
Block(-6,39,6,OBSIDIAN:0)
Block(-6,39,7,OBSIDIAN:0)
Block(-6,39,8,STONE:5)
Block(-6,40,-7,OBSIDIAN:0)
Block(-6,40,-6,OBSIDIAN:0)
Block(-6,40,-5,OBSIDIAN:0)
Block(-6,40,-4,OBSIDIAN:0)
Block(-6,40,-3,OBSIDIAN:0)
Block(-6,40,-2,OBSIDIAN:0)
Block(-6,40,-1,OBSIDIAN:0)
Block(-6,40,0,OBSIDIAN:0)
Block(-6,40,1,OBSIDIAN:0)
Block(-6,40,2,OBSIDIAN:0)
Block(-6,40,3,OBSIDIAN:0)
Block(-6,40,4,OBSIDIAN:0)
Block(-6,40,5,OBSIDIAN:0)
Block(-6,40,6,STONE:5)
Block(-6,40,7,STONE:5)
Block(-6,40,8,STONE:5)
Block(-6,41,-7,OBSIDIAN:0)
Block(-6,41,-6,OBSIDIAN:0)
Block(-6,41,-5,OBSIDIAN:0)
Block(-6,41,-4,OBSIDIAN:0)
Block(-6,41,-3,OBSIDIAN:0)
Block(-6,41,-2,OBSIDIAN:0)
Block(-6,41,-1,OBSIDIAN:0)
Block(-6,41,0,OBSIDIAN:0)
Block(-6,41,1,OBSIDIAN:0)
Block(-6,41,2,OBSIDIAN:0)
Block(-6,41,3,OBSIDIAN:0)
Block(-6,41,4,OBSIDIAN:0)
Block(-6,41,5,STONE:5)
Block(-6,41,6,STONE:5)
Block(-6,41,7,STONE:5)
Block(-6,41,8,STONE:5)
Block(-6,42,-7,OBSIDIAN:0)
Block(-6,42,-6,OBSIDIAN:0)
Block(-6,42,-5,OBSIDIAN:0)
Block(-6,42,-4,OBSIDIAN:0)
Block(-6,42,-3,OBSIDIAN:0)
Block(-6,42,-2,OBSIDIAN:0)
Block(-6,42,-1,OBSIDIAN:0)
Block(-6,42,0,OBSIDIAN:0)
Block(-6,42,1,OBSIDIAN:0)
Block(-6,42,2,OBSIDIAN:0)
Block(-6,42,3,OBSIDIAN:0)
Block(-6,42,4,OBSIDIAN:0)
Block(-6,42,5,STONE:5)
Block(-6,42,6,STONE:5)
Block(-6,42,7,STONE:5)
Block(-6,42,8,STONE:5)
Block(-6,43,-7,OBSIDIAN:0)
Block(-6,43,-6,OBSIDIAN:0)
Block(-6,43,-5,OBSIDIAN:0)
Block(-6,43,-4,OBSIDIAN:0)
Block(-6,43,-3,OBSIDIAN:0)
Block(-6,43,-2,OBSIDIAN:0)
Block(-6,43,-1,OBSIDIAN:0)
Block(-6,43,0,OBSIDIAN:0)
Block(-6,43,1,OBSIDIAN:0)
Block(-6,43,2,OBSIDIAN:0)
Block(-6,43,3,OBSIDIAN:0)
Block(-6,43,4,STONE:5)
Block(-6,43,5,STONE:5)
Block(-6,43,6,STONE:5)
Block(-6,43,7,STONE:5)
Block(-6,43,8,AIR:0)
Block(-6,44,-7,OBSIDIAN:0)
Block(-6,44,-6,OBSIDIAN:0)
Block(-6,44,-5,OBSIDIAN:0)
Block(-6,44,-4,OBSIDIAN:0)
Block(-6,44,-3,OBSIDIAN:0)
Block(-6,44,-2,OBSIDIAN:0)
Block(-6,44,-1,OBSIDIAN:0)
Block(-6,44,0,OBSIDIAN:0)
Block(-6,44,1,OBSIDIAN:0)
Block(-6,44,2,OBSIDIAN:0)
Block(-6,44,3,OBSIDIAN:0)
Block(-6,44,4,STONE:5)
Block(-6,44,5,STONE:5)
Block(-6,44,6,STONE:5)
Block(-6,44,7,STONE:5)
Block(-6,44,8,AIR:0)
Block(-6,45,-7,OBSIDIAN:0)
Block(-6,45,-6,OBSIDIAN:0)
Block(-6,45,-5,OBSIDIAN:0)
Block(-6,45,-4,OBSIDIAN:0)
Block(-6,45,-3,OBSIDIAN:0)
Block(-6,45,-2,OBSIDIAN:0)
Block(-6,45,-1,OBSIDIAN:0)
Block(-6,45,0,OBSIDIAN:0)
Block(-6,45,1,OBSIDIAN:0)
Block(-6,45,2,OBSIDIAN:0)
Block(-6,45,3,STONE:5)
Block(-6,45,4,STONE:5)
Block(-6,45,5,STONE:5)
Block(-6,45,6,AIR:0)
Block(-6,45,7,AIR:0)
Block(-6,45,8,AIR:0)
Block(-6,46,-7,OBSIDIAN:0)
Block(-6,46,-6,OBSIDIAN:0)
Block(-6,46,-5,OBSIDIAN:0)
Block(-6,46,-4,OBSIDIAN:0)
Block(-6,46,-3,OBSIDIAN:0)
Block(-6,46,-2,STONE:3)
Block(-6,46,-1,STONE:3)
Block(-6,46,0,STONE:3)
Block(-6,46,1,OBSIDIAN:0)
Block(-6,46,2,STONE:5)
Block(-6,46,3,STONE:5)
Block(-6,46,4,STONE:5)
Block(-6,46,5,AIR:0)
Block(-6,46,6,AIR:0)
Block(-6,46,7,AIR:0)
Block(-6,46,8,AIR:0)
Block(-6,47,-7,OBSIDIAN:0)
Block(-6,47,-6,OBSIDIAN:0)
Block(-6,47,-5,OBSIDIAN:0)
Block(-6,47,-4,STONE:3)
Block(-6,47,-3,STONE:3)
Block(-6,47,-2,STONE:3)
Block(-6,47,-1,STONE:3)
Block(-6,47,0,STONE:3)
Block(-6,47,1,STONE:3)
Block(-6,47,2,STONE:3)
Block(-6,47,3,STONE:5)
Block(-6,47,4,AIR:0)
Block(-6,47,5,AIR:0)
Block(-6,47,6,AIR:0)
Block(-6,47,7,AIR:0)
Block(-6,47,8,AIR:0)
Block(-6,48,-7,OBSIDIAN:0)
Block(-6,48,-6,OBSIDIAN:0)
Block(-6,48,-5,OBSIDIAN:0)
Block(-6,48,-4,STONE:3)
Block(-6,48,-3,STONE:3)
Block(-6,48,-2,STONE:3)
Block(-6,48,-1,STONE:3)
Block(-6,48,0,STONE:3)
Block(-6,48,1,STONE:3)
Block(-6,48,2,AIR:0)
Block(-6,48,3,AIR:0)
Block(-6,48,4,AIR:0)
Block(-6,48,5,AIR:0)
Block(-6,48,6,AIR:0)
Block(-6,48,7,AIR:0)
Block(-6,48,8,AIR:0)
Block(-6,49,-7,OBSIDIAN:0)
Block(-6,49,-6,OBSIDIAN:0)
Block(-6,49,-5,AIR:0)
Block(-6,49,-4,AIR:0)
Block(-6,49,-3,AIR:0)
Block(-6,49,-2,AIR:0)
Block(-6,49,-1,AIR:0)
Block(-6,49,0,AIR:0)
Block(-6,49,1,AIR:0)
Block(-6,49,2,AIR:0)
Block(-6,49,3,AIR:0)
Block(-6,49,4,AIR:0)
Block(-6,49,5,AIR:0)
Block(-6,49,6,AIR:0)
Block(-6,49,7,AIR:0)
Block(-6,49,8,AIR:0)
Block(-6,50,-7,OBSIDIAN:0)
Block(-6,50,-6,OBSIDIAN:0)
Block(-6,50,-5,OBSIDIAN:0)
Block(-6,50,-4,AIR:0)
Block(-6,50,-3,AIR:0)
Block(-6,50,-2,AIR:0)
Block(-6,50,-1,AIR:0)
Block(-6,50,0,AIR:0)
Block(-6,50,1,AIR:0)
Block(-6,50,2,AIR:0)
Block(-6,50,3,AIR:0)
Block(-6,50,4,AIR:0)
Block(-6,50,5,AIR:0)
Block(-6,50,6,AIR:0)
Block(-6,50,7,AIR:0)
Block(-6,50,8,AIR:0)
Block(-6,51,-7,OBSIDIAN:0)
Block(-6,51,-6,OBSIDIAN:0)
Block(-6,51,-5,OBSIDIAN:0)
Block(-6,51,-4,AIR:0)
Block(-6,51,-3,AIR:0)
Block(-6,51,-2,AIR:0)
Block(-6,51,-1,AIR:0)
Block(-6,51,0,AIR:0)
Block(-6,51,1,AIR:0)
Block(-6,51,2,AIR:0)
Block(-6,51,3,AIR:0)
Block(-6,51,4,AIR:0)
Block(-6,51,5,AIR:0)
Block(-6,51,6,AIR:0)
Block(-6,51,7,AIR:0)
Block(-6,51,8,AIR:0)
Block(-6,52,-7,OBSIDIAN:0)
Block(-6,52,-6,OBSIDIAN:0)
Block(-6,52,-5,AIR:0)
Block(-6,52,-4,AIR:0)
Block(-6,52,-3,AIR:0)
Block(-6,52,-2,AIR:0)
Block(-6,52,-1,AIR:0)
Block(-6,52,0,AIR:0)
Block(-6,52,1,AIR:0)
Block(-6,52,2,AIR:0)
Block(-6,52,3,AIR:0)
Block(-6,52,4,AIR:0)
Block(-6,52,5,AIR:0)
Block(-6,52,6,AIR:0)
Block(-6,52,7,AIR:0)
Block(-6,52,8,AIR:0)
Block(-6,53,-7,OBSIDIAN:0)
Block(-6,53,-6,OBSIDIAN:0)
Block(-6,53,-5,AIR:0)
Block(-6,53,-4,AIR:0)
Block(-6,53,-3,AIR:0)
Block(-6,53,-2,AIR:0)
Block(-6,53,-1,AIR:0)
Block(-6,53,0,AIR:0)
Block(-6,53,1,AIR:0)
Block(-6,53,2,AIR:0)
Block(-6,53,3,AIR:0)
Block(-6,53,4,AIR:0)
Block(-6,53,5,AIR:0)
Block(-6,53,6,AIR:0)
Block(-6,53,7,AIR:0)
Block(-6,53,8,AIR:0)
Block(-6,54,-7,OBSIDIAN:0)
Block(-6,54,-6,AIR:0)
Block(-6,54,-5,AIR:0)
Block(-6,54,-4,AIR:0)
Block(-6,54,-3,AIR:0)
Block(-6,54,-2,AIR:0)
Block(-6,54,-1,AIR:0)
Block(-6,54,0,AIR:0)
Block(-6,54,1,AIR:0)
Block(-6,54,2,AIR:0)
Block(-6,54,3,AIR:0)
Block(-6,54,4,AIR:0)
Block(-6,54,5,AIR:0)
Block(-6,54,6,AIR:0)
Block(-6,54,7,AIR:0)
Block(-6,54,8,AIR:0)
Block(-6,55,-7,AIR:0)
Block(-6,55,-6,AIR:0)
Block(-6,55,-5,AIR:0)
Block(-6,55,-4,AIR:0)
Block(-6,55,-3,AIR:0)
Block(-6,55,-2,AIR:0)
Block(-6,55,-1,AIR:0)
Block(-6,55,0,AIR:0)
Block(-6,55,1,AIR:0)
Block(-6,55,2,AIR:0)
Block(-6,55,3,AIR:0)
Block(-6,55,4,AIR:0)
Block(-6,55,5,AIR:0)
Block(-6,55,6,AIR:0)
Block(-6,55,7,AIR:0)
Block(-6,55,8,AIR:0)
Block(-6,56,-7,AIR:0)
Block(-6,56,-6,AIR:0)
Block(-6,56,-5,AIR:0)
Block(-6,56,-4,AIR:0)
Block(-6,56,-3,AIR:0)
Block(-6,56,-2,AIR:0)
Block(-6,56,-1,AIR:0)
Block(-6,56,0,AIR:0)
Block(-6,56,1,AIR:0)
Block(-6,56,2,AIR:0)
Block(-6,56,3,AIR:0)
Block(-6,56,4,AIR:0)
Block(-6,56,5,AIR:0)
Block(-6,56,6,AIR:0)
Block(-6,56,7,AIR:0)
Block(-6,56,8,AIR:0)
Block(-6,57,-7,AIR:0)
Block(-6,57,-6,AIR:0)
Block(-6,57,-5,AIR:0)
Block(-6,57,-4,AIR:0)
Block(-6,57,-3,AIR:0)
Block(-6,57,-2,AIR:0)
Block(-6,57,-1,AIR:0)
Block(-6,57,0,AIR:0)
Block(-6,57,1,AIR:0)
Block(-6,57,2,AIR:0)
Block(-6,57,3,AIR:0)
Block(-6,57,4,AIR:0)
Block(-6,57,5,AIR:0)
Block(-6,57,6,AIR:0)
Block(-6,57,7,AIR:0)
Block(-6,57,8,AIR:0)
Block(-6,58,-7,AIR:0)
Block(-6,58,-6,AIR:0)
Block(-6,58,-5,AIR:0)
Block(-6,58,-4,AIR:0)
Block(-6,58,-3,AIR:0)
Block(-6,58,-2,AIR:0)
Block(-6,58,-1,AIR:0)
Block(-6,58,0,AIR:0)
Block(-6,58,1,AIR:0)
Block(-6,58,2,AIR:0)
Block(-6,58,3,AIR:0)
Block(-6,58,4,AIR:0)
Block(-6,58,5,AIR:0)
Block(-6,58,6,AIR:0)
Block(-6,58,7,AIR:0)
Block(-6,58,8,AIR:0)
Block(-6,59,-7,AIR:0)
Block(-6,59,-6,AIR:0)
Block(-6,59,-5,AIR:0)
Block(-6,59,-4,AIR:0)
Block(-6,59,-3,AIR:0)
Block(-6,59,-2,AIR:0)
Block(-6,59,-1,AIR:0)
Block(-6,59,0,AIR:0)
Block(-6,59,1,AIR:0)
Block(-6,59,2,AIR:0)
Block(-6,59,3,AIR:0)
Block(-6,59,4,AIR:0)
Block(-6,59,5,AIR:0)
Block(-6,59,6,AIR:0)
Block(-6,59,7,AIR:0)
Block(-6,59,8,AIR:0)
Block(-6,60,-7,AIR:0)
Block(-6,60,-6,AIR:0)
Block(-6,60,-5,AIR:0)
Block(-6,60,-4,AIR:0)
Block(-6,60,-3,AIR:0)
Block(-6,60,-2,AIR:0)
Block(-6,60,-1,AIR:0)
Block(-6,60,0,AIR:0)
Block(-6,60,1,AIR:0)
Block(-6,60,2,AIR:0)
Block(-6,60,3,AIR:0)
Block(-6,60,4,AIR:0)
Block(-6,60,5,AIR:0)
Block(-6,60,6,AIR:0)
Block(-6,60,7,AIR:0)
Block(-6,60,8,AIR:0)
Block(-6,61,-7,AIR:0)
Block(-6,61,-6,AIR:0)
Block(-6,61,-5,AIR:0)
Block(-6,61,-4,AIR:0)
Block(-6,61,-3,AIR:0)
Block(-6,61,-2,AIR:0)
Block(-6,61,-1,AIR:0)
Block(-6,61,0,AIR:0)
Block(-6,61,1,AIR:0)
Block(-6,61,2,AIR:0)
Block(-6,61,3,AIR:0)
Block(-6,61,4,AIR:0)
Block(-6,61,5,AIR:0)
Block(-6,61,6,AIR:0)
Block(-6,61,7,AIR:0)
Block(-6,61,8,AIR:0)
Block(-6,62,-7,AIR:0)
Block(-6,62,-6,AIR:0)
Block(-6,62,-5,AIR:0)
Block(-6,62,-4,AIR:0)
Block(-6,62,-3,AIR:0)
Block(-6,62,-2,AIR:0)
