#######################################################################
# +-----------------------------------------------------------------+ #
# |                            BO3 object                           | #
# +-----------------------------------------------------------------+ #
#######################################################################

Author: Bo3 BulkEdit

Description: Converted Schematic - Modified by Bo3BulkEdit

Version: 3

SettingsMode: WriteDisable

#######################################################################
# +-----------------------------------------------------------------+ #
# |                          Main settings                          | #
# +-----------------------------------------------------------------+ #
#######################################################################



Frequency: 0


SpawnHeight: randomY





##############################
# Height Limits for the BO3. #
##############################

MinHeight: 0
MaxHeight: 256

#######################################################################
# +-----------------------------------------------------------------+ #
# |                      Source block settings                      | #
# +-----------------------------------------------------------------+ #
#######################################################################

CanOverride: true
MaxPercentageOutsideSourceBlock: 100
OutsideSourceBlock: placeAnyway

#######################################################################
# +-----------------------------------------------------------------+ #
# |                               OTG+                              | #
# +-----------------------------------------------------------------+ #
#######################################################################

#######################################################################
# +-----------------------------------------------------------------+ #
# |                              Blocks                             | #
# +-----------------------------------------------------------------+ #
#######################################################################

B(0,750,0,AIR)
B(15,750,15,AIR)
B(15,8,14,betternether:quartz_stained_glass:15)
B(14,8,15,betternether:quartz_stained_glass:15)
B(15,8,15,betternether:quartz_stained_glass:15)
B(14,9,12,betternether:quartz_stained_glass:15)
B(15,9,12,betternether:quartz_stained_glass:15)
B(13,9,13,betternether:quartz_stained_glass:15)
B(14,9,13,betternether:quartz_stained_glass:15)
B(15,9,13,betternether:quartz_stained_glass:15)
B(12,9,14,betternether:quartz_stained_glass:15)
B(13,9,14,betternether:quartz_stained_glass:15)
B(14,9,14,betternether:quartz_stained_glass:15)
B(15,9,14,betternether:quartz_stained_glass:15)
B(12,9,15,betternether:quartz_stained_glass:15)
B(13,9,15,betternether:quartz_stained_glass:15)
B(14,9,15,betternether:quartz_stained_glass:15)
B(15,9,15,betternether:quartz_stained_glass:15)
B(13,10,10,betternether:quartz_stained_glass:15)
B(14,10,10,betternether:quartz_stained_glass:15)
B(12,10,11,betternether:quartz_stained_glass:15)
B(13,10,11,betternether:quartz_stained_glass:15)
B(14,10,11,betternether:quartz_stained_glass:15)
B(15,10,11,betternether:quartz_stained_glass:15)
B(11,10,12,betternether:quartz_stained_glass:15)
B(12,10,12,betternether:quartz_stained_glass:15)
B(13,10,12,betternether:quartz_stained_glass:15)
B(14,10,12,betternether:quartz_stained_glass:15)
B(15,10,12,betternether:quartz_stained_glass:15)
B(10,10,13,betternether:quartz_stained_glass:15)
B(11,10,13,betternether:quartz_stained_glass:15)
B(12,10,13,betternether:quartz_stained_glass:15)
B(13,10,13,betternether:quartz_stained_glass:15)
B(14,10,13,betternether:quartz_stained_glass:15)
B(15,10,13,betternether:quartz_stained_glass:15)
B(10,10,14,betternether:quartz_stained_glass:15)
B(11,10,14,betternether:quartz_stained_glass:15)
B(12,10,14,betternether:quartz_stained_glass:15)
B(13,10,14,betternether:quartz_stained_glass:15)
B(14,10,14,betternether:quartz_stained_glass:15)
B(15,10,14,betternether:quartz_stained_glass:15)
B(11,10,15,betternether:quartz_stained_glass:15)
B(12,10,15,betternether:quartz_stained_glass:15)
B(13,10,15,betternether:quartz_stained_glass:15)
B(14,10,15,betternether:quartz_stained_glass:15)
B(15,10,15,betternether:quartz_stained_glass:15)
B(11,11,9,betternether:quartz_stained_glass:15)
B(12,11,9,betternether:quartz_stained_glass:15)
B(13,11,9,betternether:quartz_stained_glass:15)
B(10,11,10,betternether:quartz_stained_glass:15)
B(11,11,10,betternether:quartz_stained_glass:15)
B(12,11,10,betternether:quartz_stained_glass:15)
B(13,11,10,betternether:quartz_stained_glass:15)
B(14,11,10,betternether:quartz_stained_glass:15)
B(9,11,11,betternether:quartz_stained_glass:15)
B(10,11,11,betternether:quartz_stained_glass:15)
B(11,11,11,betternether:quartz_stained_glass:15)
B(12,11,11,betternether:quartz_stained_glass:15)
B(13,11,11,betternether:quartz_stained_glass:15)
B(14,11,11,betternether:quartz_stained_glass:15)
B(15,11,11,betternether:quartz_stained_glass:15)
B(9,11,12,betternether:quartz_stained_glass:15)
B(10,11,12,betternether:quartz_stained_glass:15)
B(11,11,12,betternether:quartz_stained_glass:15)
B(12,11,12,betternether:quartz_stained_glass:15)
B(13,11,12,betternether:quartz_stained_glass:15)
B(14,11,12,betternether:quartz_stained_glass:15)
B(15,11,12,betternether:quartz_stained_glass:15)
B(9,11,13,betternether:quartz_stained_glass:15)
B(10,11,13,betternether:quartz_stained_glass:15)
B(11,11,13,betternether:quartz_stained_glass:15)
B(12,11,13,betternether:quartz_stained_glass:15)
B(13,11,13,betternether:quartz_stained_glass:15)
B(14,11,13,betternether:quartz_stained_glass:15)
B(15,11,13,betternether:quartz_stained_glass:15)
B(10,11,14,betternether:quartz_stained_glass:15)
B(11,11,14,betternether:quartz_stained_glass:15)
B(12,11,14,betternether:quartz_stained_glass:15)
B(13,11,14,betternether:quartz_stained_glass:15)
B(14,11,14,betternether:quartz_stained_glass:15)
B(15,11,14,betternether:quartz_stained_glass:15)
B(11,11,15,betternether:quartz_stained_glass:15)
B(12,11,15,betternether:quartz_stained_glass:15)
B(13,11,15,betternether:quartz_stained_glass:15)
B(14,11,15,betternether:quartz_stained_glass:15)
RB(15,11,15,srparasites:parasitestain:1,80,quark:crystal:1,30,srparasites:parasiterubbledense:1,100)
B(10,12,7,betternether:quartz_stained_glass:15)
B(11,12,7,betternether:quartz_stained_glass:15)
B(9,12,8,betternether:quartz_stained_glass:15)
B(10,12,8,betternether:quartz_stained_glass:15)
B(11,12,8,betternether:quartz_stained_glass:15)
B(12,12,8,betternether:quartz_stained_glass:15)
B(8,12,9,betternether:quartz_stained_glass:15)
B(9,12,9,betternether:quartz_stained_glass:15)
B(10,12,9,betternether:quartz_stained_glass:15)
B(11,12,9,betternether:quartz_stained_glass:15)
B(12,12,9,betternether:quartz_stained_glass:15)
B(13,12,9,betternether:quartz_stained_glass:15)
B(7,12,10,betternether:quartz_stained_glass:15)
B(8,12,10,betternether:quartz_stained_glass:15)
B(9,12,10,betternether:quartz_stained_glass:15)
B(10,12,10,betternether:quartz_stained_glass:15)
B(11,12,10,betternether:quartz_stained_glass:15)
B(12,12,10,betternether:quartz_stained_glass:15)
B(13,12,10,betternether:quartz_stained_glass:15)
B(14,12,10,betternether:quartz_stained_glass:15)
B(7,12,11,betternether:quartz_stained_glass:15)
B(8,12,11,betternether:quartz_stained_glass:15)
B(9,12,11,betternether:quartz_stained_glass:15)
B(10,12,11,betternether:quartz_stained_glass:15)
B(11,12,11,betternether:quartz_stained_glass:15)
B(12,12,11,betternether:quartz_stained_glass:15)
B(13,12,11,betternether:quartz_stained_glass:15)
B(14,12,11,betternether:quartz_stained_glass:15)
B(15,12,11,betternether:quartz_stained_glass:15)
B(8,12,12,betternether:quartz_stained_glass:15)
B(9,12,12,betternether:quartz_stained_glass:15)
B(10,12,12,betternether:quartz_stained_glass:15)
B(11,12,12,betternether:quartz_stained_glass:15)
B(12,12,12,betternether:quartz_stained_glass:15)
B(13,12,12,betternether:quartz_stained_glass:15)
B(14,12,12,betternether:quartz_stained_glass:15)
B(15,12,12,betternether:quartz_stained_glass:15)
B(9,12,13,betternether:quartz_stained_glass:15)
B(10,12,13,betternether:quartz_stained_glass:15)
B(11,12,13,betternether:quartz_stained_glass:15)
B(12,12,13,betternether:quartz_stained_glass:15)
RB(13,12,13,srparasites:parasitestain:1,80,quark:crystal:1,30,srparasites:parasiterubbledense:1,100)
RB(14,12,13,srparasites:parasitestain:1,80,quark:crystal:1,30,srparasites:parasiterubbledense:1,100)
B(15,12,13,betternether:quartz_stained_glass:15)
B(10,12,14,betternether:quartz_stained_glass:15)
B(11,12,14,betternether:quartz_stained_glass:15)
B(12,12,14,betternether:quartz_stained_glass:15)
RB(13,12,14,srparasites:parasitestain:1,80,quark:crystal:1,30,srparasites:parasiterubbledense:1,100)
RB(14,12,14,srparasites:parasitestain:1,80,quark:crystal:1,30,srparasites:parasiterubbledense:1,100)
RB(15,12,14,srparasites:parasitestain:1,80,quark:crystal:1,30,srparasites:parasiterubbledense:1,100)
B(11,12,15,betternether:quartz_stained_glass:15)
B(12,12,15,betternether:quartz_stained_glass:15)
B(13,12,15,betternether:quartz_stained_glass:15)
B(14,12,15,betternether:quartz_stained_glass:15)
RB(15,12,15,srparasites:parasitestain:1,80,quark:crystal:1,30,srparasites:parasiterubbledense:1,100)
B(8,13,6,betternether:quartz_stained_glass:15)
B(9,13,6,betternether:quartz_stained_glass:15)
B(10,13,6,betternether:quartz_stained_glass:15)
B(7,13,7,betternether:quartz_stained_glass:15)
B(8,13,7,betternether:quartz_stained_glass:15)
B(9,13,7,betternether:quartz_stained_glass:15)
B(10,13,7,betternether:quartz_stained_glass:15)
B(11,13,7,betternether:quartz_stained_glass:15)
B(6,13,8,betternether:quartz_stained_glass:15)
B(7,13,8,betternether:quartz_stained_glass:15)
B(8,13,8,betternether:quartz_stained_glass:15)
B(9,13,8,betternether:quartz_stained_glass:15)
B(10,13,8,betternether:quartz_stained_glass:15)
B(11,13,8,betternether:quartz_stained_glass:15)
B(12,13,8,betternether:quartz_stained_glass:15)
B(6,13,9,betternether:quartz_stained_glass:15)
B(7,13,9,betternether:quartz_stained_glass:15)
B(8,13,9,betternether:quartz_stained_glass:15)
B(9,13,9,betternether:quartz_stained_glass:15)
B(10,13,9,betternether:quartz_stained_glass:15)
B(11,13,9,betternether:quartz_stained_glass:15)
B(12,13,9,betternether:quartz_stained_glass:15)
B(13,13,9,betternether:quartz_stained_glass:15)
B(6,13,10,betternether:quartz_stained_glass:15)
B(7,13,10,betternether:quartz_stained_glass:15)
B(8,13,10,betternether:quartz_stained_glass:15)
B(9,13,10,betternether:quartz_stained_glass:15)
B(10,13,10,betternether:quartz_stained_glass:15)
B(11,13,10,betternether:quartz_stained_glass:15)
B(12,13,10,betternether:quartz_stained_glass:15)
B(13,13,10,betternether:quartz_stained_glass:15)
B(14,13,10,betternether:quartz_stained_glass:15)
B(7,13,11,betternether:quartz_stained_glass:15)
B(8,13,11,betternether:quartz_stained_glass:15)
B(9,13,11,betternether:quartz_stained_glass:15)
B(10,13,11,betternether:quartz_stained_glass:15)
RB(11,13,11,srparasites:parasitestain:1,80,quark:crystal:1,30,srparasites:parasiterubbledense:1,100)
B(12,13,11,betternether:quartz_stained_glass:15)
B(13,13,11,betternether:quartz_stained_glass:15)
B(14,13,11,betternether:quartz_stained_glass:15)
B(15,13,11,betternether:quartz_stained_glass:15)
B(8,13,12,betternether:quartz_stained_glass:15)
B(9,13,12,betternether:quartz_stained_glass:15)
B(10,13,12,betternether:quartz_stained_glass:15)
B(11,13,12,betternether:quartz_stained_glass:15)
RB(12,13,12,srparasites:parasitestain:1,80,quark:crystal:1,30,srparasites:parasiterubbledense:1,100)
RB(13,13,12,srparasites:parasitestain:1,80,quark:crystal:1,30,srparasites:parasiterubbledense:1,100)
B(14,13,12,betternether:quartz_stained_glass:15)
B(15,13,12,betternether:quartz_stained_glass:15)
B(9,13,13,betternether:quartz_stained_glass:15)
B(10,13,13,betternether:quartz_stained_glass:15)
B(11,13,13,betternether:quartz_stained_glass:15)
RB(12,13,13,srparasites:parasitestain:1,80,quark:crystal:1,30,srparasites:parasiterubbledense:1,100)
RB(13,13,13,srparasites:parasitestain:1,80,quark:crystal:1,30,srparasites:parasiterubbledense:1,100)
B(14,13,13,betternether:quartz_stained_glass:15)
B(15,13,13,betternether:quartz_stained_glass:15)
B(10,13,14,betternether:quartz_stained_glass:15)
B(11,13,14,betternether:quartz_stained_glass:15)
B(12,13,14,betternether:quartz_stained_glass:15)
B(13,13,14,betternether:quartz_stained_glass:15)
B(14,13,14,betternether:quartz_stained_glass:15)
B(15,13,14,betternether:quartz_stained_glass:15)
B(11,13,15,betternether:quartz_stained_glass:15)
B(12,13,15,betternether:quartz_stained_glass:15)
B(13,13,15,betternether:quartz_stained_glass:15)
B(14,13,15,betternether:quartz_stained_glass:15)
B(15,13,15,betternether:quartz_stained_glass:15)
B(7,14,4,betternether:quartz_stained_glass:15)
B(8,14,4,betternether:quartz_stained_glass:15)
B(6,14,5,betternether:quartz_stained_glass:15)
B(7,14,5,betternether:quartz_stained_glass:15)
B(8,14,5,betternether:quartz_stained_glass:15)
B(9,14,5,betternether:quartz_stained_glass:15)
B(5,14,6,betternether:quartz_stained_glass:15)
B(6,14,6,betternether:quartz_stained_glass:15)
B(7,14,6,betternether:quartz_stained_glass:15)
B(8,14,6,betternether:quartz_stained_glass:15)
B(9,14,6,betternether:quartz_stained_glass:15)
B(10,14,6,betternether:quartz_stained_glass:15)
B(4,14,7,betternether:quartz_stained_glass:15)
B(5,14,7,betternether:quartz_stained_glass:15)
B(6,14,7,betternether:quartz_stained_glass:15)
B(7,14,7,betternether:quartz_stained_glass:15)
B(8,14,7,betternether:quartz_stained_glass:15)
B(9,14,7,betternether:quartz_stained_glass:15)
B(10,14,7,betternether:quartz_stained_glass:15)
B(11,14,7,betternether:quartz_stained_glass:15)
B(4,14,8,betternether:quartz_stained_glass:15)
B(5,14,8,betternether:quartz_stained_glass:15)
B(6,14,8,betternether:quartz_stained_glass:15)
B(7,14,8,betternether:quartz_stained_glass:15)
B(8,14,8,betternether:quartz_stained_glass:15)
B(9,14,8,betternether:quartz_stained_glass:15)
B(10,14,8,betternether:quartz_stained_glass:15)
B(11,14,8,betternether:quartz_stained_glass:15)
B(12,14,8,betternether:quartz_stained_glass:15)
B(5,14,9,betternether:quartz_stained_glass:15)
B(6,14,9,betternether:quartz_stained_glass:15)
B(7,14,9,betternether:quartz_stained_glass:15)
B(8,14,9,betternether:quartz_stained_glass:15)
B(9,14,9,betternether:quartz_stained_glass:15)
B(10,14,9,betternether:quartz_stained_glass:15)
B(11,14,9,betternether:quartz_stained_glass:15)
B(12,14,9,betternether:quartz_stained_glass:15)
B(13,14,9,betternether:quartz_stained_glass:15)
B(6,14,10,betternether:quartz_stained_glass:15)
B(7,14,10,betternether:quartz_stained_glass:15)
B(8,14,10,betternether:quartz_stained_glass:15)
B(9,14,10,betternether:quartz_stained_glass:15)
RB(10,14,10,srparasites:parasitestain:1,80,quark:crystal:1,30,srparasites:parasiterubbledense:1,100)
RB(11,14,10,srparasites:parasitestain:1,80,quark:crystal:1,30,srparasites:parasiterubbledense:1,100)
B(12,14,10,betternether:quartz_stained_glass:15)
B(13,14,10,betternether:quartz_stained_glass:15)
B(14,14,10,betternether:quartz_stained_glass:15)
B(7,14,11,betternether:quartz_stained_glass:15)
B(8,14,11,betternether:quartz_stained_glass:15)
B(9,14,11,betternether:quartz_stained_glass:15)
RB(10,14,11,srparasites:parasitestain:1,80,quark:crystal:1,30,srparasites:parasiterubbledense:1,100)
RB(11,14,11,srparasites:parasitestain:1,80,quark:crystal:1,30,srparasites:parasiterubbledense:1,100)
RB(12,14,11,srparasites:parasitestain:1,80,quark:crystal:1,30,srparasites:parasiterubbledense:1,100)
B(13,14,11,betternether:quartz_stained_glass:15)
B(14,14,11,betternether:quartz_stained_glass:15)
B(15,14,11,betternether:quartz_stained_glass:15)
B(8,14,12,betternether:quartz_stained_glass:15)
B(9,14,12,betternether:quartz_stained_glass:15)
B(10,14,12,betternether:quartz_stained_glass:15)
RB(11,14,12,srparasites:parasitestain:1,80,quark:crystal:1,30,srparasites:parasiterubbledense:1,100)
B(12,14,12,betternether:quartz_stained_glass:15)
B(13,14,12,betternether:quartz_stained_glass:15)
B(14,14,12,betternether:quartz_stained_glass:15)
B(15,14,12,betternether:quartz_stained_glass:15)
B(9,14,13,betternether:quartz_stained_glass:15)
B(10,14,13,betternether:quartz_stained_glass:15)
B(11,14,13,betternether:quartz_stained_glass:15)
B(12,14,13,betternether:quartz_stained_glass:15)
B(13,14,13,betternether:quartz_stained_glass:15)
B(14,14,13,betternether:quartz_stained_glass:15)
B(15,14,13,betternether:quartz_stained_glass:15)
B(10,14,14,betternether:quartz_stained_glass:15)
B(11,14,14,betternether:quartz_stained_glass:15)
B(12,14,14,betternether:quartz_stained_glass:15)
B(13,14,14,betternether:quartz_stained_glass:15)
B(14,14,14,betternether:quartz_stained_glass:15)
B(15,14,14,betternether:quartz_stained_glass:15)
B(11,14,15,betternether:quartz_stained_glass:15)
B(12,14,15,betternether:quartz_stained_glass:15)
B(13,14,15,betternether:quartz_stained_glass:15)
B(14,14,15,betternether:quartz_stained_glass:15)
B(15,14,15,betternether:quartz_stained_glass:15)
B(5,15,3,betternether:quartz_stained_glass:15)
B(6,15,3,betternether:quartz_stained_glass:15)
B(7,15,3,betternether:quartz_stained_glass:15)
B(4,15,4,betternether:quartz_stained_glass:15)
B(5,15,4,betternether:quartz_stained_glass:15)
B(6,15,4,betternether:quartz_stained_glass:15)
B(7,15,4,betternether:quartz_stained_glass:15)
B(8,15,4,betternether:quartz_stained_glass:15)
B(3,15,5,betternether:quartz_stained_glass:15)
B(4,15,5,betternether:quartz_stained_glass:15)
B(5,15,5,betternether:quartz_stained_glass:15)
B(6,15,5,betternether:quartz_stained_glass:15)
B(7,15,5,betternether:quartz_stained_glass:15)
B(8,15,5,betternether:quartz_stained_glass:15)
B(9,15,5,betternether:quartz_stained_glass:15)
B(3,15,6,betternether:quartz_stained_glass:15)
B(4,15,6,betternether:quartz_stained_glass:15)
B(5,15,6,betternether:quartz_stained_glass:15)
B(6,15,6,betternether:quartz_stained_glass:15)
B(7,15,6,betternether:quartz_stained_glass:15)
B(8,15,6,betternether:quartz_stained_glass:15)
B(9,15,6,betternether:quartz_stained_glass:15)
B(10,15,6,betternether:quartz_stained_glass:15)
B(3,15,7,betternether:quartz_stained_glass:15)
B(4,15,7,betternether:quartz_stained_glass:15)
B(5,15,7,betternether:quartz_stained_glass:15)
B(6,15,7,betternether:quartz_stained_glass:15)
B(7,15,7,betternether:quartz_stained_glass:15)
B(8,15,7,betternether:quartz_stained_glass:15)
B(9,15,7,betternether:quartz_stained_glass:15)
B(10,15,7,betternether:quartz_stained_glass:15)
B(11,15,7,betternether:quartz_stained_glass:15)
B(4,15,8,betternether:quartz_stained_glass:15)
B(5,15,8,betternether:quartz_stained_glass:15)
B(6,15,8,betternether:quartz_stained_glass:15)
B(7,15,8,betternether:quartz_stained_glass:15)
B(8,15,8,betternether:quartz_stained_glass:15)
B(9,15,8,betternether:quartz_stained_glass:15)
B(10,15,8,betternether:quartz_stained_glass:15)
B(11,15,8,betternether:quartz_stained_glass:15)
B(12,15,8,betternether:quartz_stained_glass:15)
B(5,15,9,betternether:quartz_stained_glass:15)
B(6,15,9,betternether:quartz_stained_glass:15)
B(7,15,9,betternether:quartz_stained_glass:15)
B(8,15,9,betternether:quartz_stained_glass:15)
RB(9,15,9,srparasites:parasitestain:1,80,quark:crystal:1,30,srparasites:parasiterubbledense:1,100)
RB(10,15,9,srparasites:parasitestain:1,80,quark:crystal:1,30,srparasites:parasiterubbledense:1,100)
B(11,15,9,betternether:quartz_stained_glass:15)
B(12,15,9,betternether:quartz_stained_glass:15)
B(13,15,9,betternether:quartz_stained_glass:15)
B(6,15,10,betternether:quartz_stained_glass:15)
B(7,15,10,betternether:quartz_stained_glass:15)
B(8,15,10,betternether:quartz_stained_glass:15)
RB(9,15,10,srparasites:parasitestain:1,80,quark:crystal:1,30,srparasites:parasiterubbledense:1,100)
RB(10,15,10,srparasites:parasitestain:1,80,quark:crystal:1,30,srparasites:parasiterubbledense:1,100)
B(11,15,10,betternether:quartz_stained_glass:15)
B(12,15,10,betternether:quartz_stained_glass:15)
B(13,15,10,betternether:quartz_stained_glass:15)
B(14,15,10,betternether:quartz_stained_glass:15)
B(7,15,11,betternether:quartz_stained_glass:15)
B(8,15,11,betternether:quartz_stained_glass:15)
B(9,15,11,betternether:quartz_stained_glass:15)
B(10,15,11,betternether:quartz_stained_glass:15)
B(11,15,11,betternether:quartz_stained_glass:15)
B(12,15,11,betternether:quartz_stained_glass:15)
B(13,15,11,betternether:quartz_stained_glass:15)
B(14,15,11,betternether:quartz_stained_glass:15)
B(15,15,11,betternether:quartz_stained_glass:15)
B(8,15,12,betternether:quartz_stained_glass:15)
B(9,15,12,betternether:quartz_stained_glass:15)
B(10,15,12,betternether:quartz_stained_glass:15)
B(11,15,12,betternether:quartz_stained_glass:15)
B(12,15,12,betternether:quartz_stained_glass:15)
B(13,15,12,betternether:quartz_stained_glass:15)
B(14,15,12,betternether:quartz_stained_glass:15)
B(15,15,12,betternether:quartz_stained_glass:15)
B(9,15,13,betternether:quartz_stained_glass:15)
B(10,15,13,betternether:quartz_stained_glass:15)
B(11,15,13,betternether:quartz_stained_glass:15)
B(12,15,13,betternether:quartz_stained_glass:15)
B(13,15,13,betternether:quartz_stained_glass:15)
B(14,15,13,betternether:quartz_stained_glass:15)
B(15,15,13,betternether:quartz_stained_glass:15)
B(10,15,14,betternether:quartz_stained_glass:15)
B(11,15,14,betternether:quartz_stained_glass:15)
B(12,15,14,betternether:quartz_stained_glass:15)
B(13,15,14,betternether:quartz_stained_glass:15)
B(14,15,14,betternether:quartz_stained_glass:15)
B(15,15,14,betternether:quartz_stained_glass:15)
B(11,15,15,betternether:quartz_stained_glass:15)
B(12,15,15,betternether:quartz_stained_glass:15)
B(13,15,15,betternether:quartz_stained_glass:15)
B(14,15,15,betternether:quartz_stained_glass:15)
B(15,15,15,betternether:quartz_stained_glass:15)
B(5,16,3,betternether:quartz_stained_glass:15)
B(6,16,3,betternether:quartz_stained_glass:15)
B(7,16,3,betternether:quartz_stained_glass:15)
B(4,16,4,betternether:quartz_stained_glass:15)
B(5,16,4,betternether:quartz_stained_glass:15)
B(6,16,4,betternether:quartz_stained_glass:15)
B(7,16,4,betternether:quartz_stained_glass:15)
B(8,16,4,betternether:quartz_stained_glass:15)
B(3,16,5,betternether:quartz_stained_glass:15)
B(4,16,5,betternether:quartz_stained_glass:15)
B(5,16,5,betternether:quartz_stained_glass:15)
B(6,16,5,betternether:quartz_stained_glass:15)
B(7,16,5,betternether:quartz_stained_glass:15)
B(8,16,5,betternether:quartz_stained_glass:15)
B(9,16,5,betternether:quartz_stained_glass:15)
B(3,16,6,betternether:quartz_stained_glass:15)
B(4,16,6,betternether:quartz_stained_glass:15)
B(5,16,6,betternether:quartz_stained_glass:15)
B(6,16,6,betternether:quartz_stained_glass:15)
B(7,16,6,betternether:quartz_stained_glass:15)
B(8,16,6,betternether:quartz_stained_glass:15)
B(9,16,6,betternether:quartz_stained_glass:15)
B(10,16,6,betternether:quartz_stained_glass:15)
B(3,16,7,betternether:quartz_stained_glass:15)
B(4,16,7,betternether:quartz_stained_glass:15)
B(5,16,7,betternether:quartz_stained_glass:15)
B(6,16,7,betternether:quartz_stained_glass:15)
RB(7,16,7,srparasites:parasitestain:1,80,quark:crystal:1,30,srparasites:parasiterubbledense:1,100)
RB(8,16,7,srparasites:parasitestain:1,80,quark:crystal:1,30,srparasites:parasiterubbledense:1,100)
B(9,16,7,betternether:quartz_stained_glass:15)
B(10,16,7,betternether:quartz_stained_glass:15)
B(11,16,7,betternether:quartz_stained_glass:15)
B(4,16,8,betternether:quartz_stained_glass:15)
B(5,16,8,betternether:quartz_stained_glass:15)
B(6,16,8,betternether:quartz_stained_glass:15)
RB(7,16,8,srparasites:parasitestain:1,80,quark:crystal:1,30,srparasites:parasiterubbledense:1,100)
RB(8,16,8,srparasites:parasitestain:1,80,quark:crystal:1,30,srparasites:parasiterubbledense:1,100)
RB(9,16,8,srparasites:parasitestain:1,80,quark:crystal:1,30,srparasites:parasiterubbledense:1,100)
B(10,16,8,betternether:quartz_stained_glass:15)
B(11,16,8,betternether:quartz_stained_glass:15)
B(12,16,8,betternether:quartz_stained_glass:15)
B(5,16,9,betternether:quartz_stained_glass:15)
B(6,16,9,betternether:quartz_stained_glass:15)
B(7,16,9,betternether:quartz_stained_glass:15)
RB(8,16,9,srparasites:parasitestain:1,80,quark:crystal:1,30,srparasites:parasiterubbledense:1,100)
RB(9,16,9,srparasites:parasitestain:1,80,quark:crystal:1,30,srparasites:parasiterubbledense:1,100)
B(10,16,9,betternether:quartz_stained_glass:15)
B(11,16,9,betternether:quartz_stained_glass:15)
B(12,16,9,betternether:quartz_stained_glass:15)
B(13,16,9,betternether:quartz_stained_glass:15)
B(6,16,10,betternether:quartz_stained_glass:15)
B(7,16,10,betternether:quartz_stained_glass:15)
B(8,16,10,betternether:quartz_stained_glass:15)
B(9,16,10,betternether:quartz_stained_glass:15)
B(10,16,10,betternether:quartz_stained_glass:15)
B(11,16,10,betternether:quartz_stained_glass:15)
B(12,16,10,betternether:quartz_stained_glass:15)
B(13,16,10,betternether:quartz_stained_glass:15)
B(14,16,10,betternether:quartz_stained_glass:15)
B(7,16,11,betternether:quartz_stained_glass:15)
B(8,16,11,betternether:quartz_stained_glass:15)
B(9,16,11,betternether:quartz_stained_glass:15)
B(10,16,11,betternether:quartz_stained_glass:15)
B(11,16,11,betternether:quartz_stained_glass:15)
B(12,16,11,betternether:quartz_stained_glass:15)
B(13,16,11,betternether:quartz_stained_glass:15)
B(14,16,11,betternether:quartz_stained_glass:15)
B(15,16,11,betternether:quartz_stained_glass:15)
B(8,16,12,betternether:quartz_stained_glass:15)
B(9,16,12,betternether:quartz_stained_glass:15)
B(10,16,12,betternether:quartz_stained_glass:15)
B(11,16,12,betternether:quartz_stained_glass:15)
B(12,16,12,betternether:quartz_stained_glass:15)
B(13,16,12,betternether:quartz_stained_glass:15)
B(14,16,12,betternether:quartz_stained_glass:15)
B(15,16,12,betternether:quartz_stained_glass:15)
B(9,16,13,betternether:quartz_stained_glass:15)
B(10,16,13,betternether:quartz_stained_glass:15)
B(11,16,13,betternether:quartz_stained_glass:15)
B(12,16,13,betternether:quartz_stained_glass:15)
B(13,16,13,betternether:quartz_stained_glass:15)
B(14,16,13,betternether:quartz_stained_glass:15)
B(10,16,14,betternether:quartz_stained_glass:15)
B(11,16,14,betternether:quartz_stained_glass:15)
B(12,16,14,betternether:quartz_stained_glass:15)
B(13,16,14,betternether:quartz_stained_glass:15)
B(11,16,15,betternether:quartz_stained_glass:15)
B(12,16,15,betternether:quartz_stained_glass:15)
B(4,17,2,betternether:quartz_stained_glass:15)
B(5,17,2,betternether:quartz_stained_glass:15)
B(3,17,3,betternether:quartz_stained_glass:15)
B(4,17,3,betternether:quartz_stained_glass:15)
B(5,17,3,betternether:quartz_stained_glass:15)
B(6,17,3,betternether:quartz_stained_glass:15)
B(7,17,3,betternether:quartz_stained_glass:15)
B(2,17,4,betternether:quartz_stained_glass:15)
B(3,17,4,betternether:quartz_stained_glass:15)
B(4,17,4,betternether:quartz_stained_glass:15)
B(5,17,4,betternether:quartz_stained_glass:15)
B(6,17,4,betternether:quartz_stained_glass:15)
B(7,17,4,betternether:quartz_stained_glass:15)
B(8,17,4,betternether:quartz_stained_glass:15)
B(2,17,5,betternether:quartz_stained_glass:15)
B(3,17,5,betternether:quartz_stained_glass:15)
B(4,17,5,betternether:quartz_stained_glass:15)
B(5,17,5,betternether:quartz_stained_glass:15)
B(6,17,5,betternether:quartz_stained_glass:15)
B(7,17,5,betternether:quartz_stained_glass:15)
B(8,17,5,betternether:quartz_stained_glass:15)
B(9,17,5,betternether:quartz_stained_glass:15)
B(3,17,6,betternether:quartz_stained_glass:15)
B(4,17,6,betternether:quartz_stained_glass:15)
B(5,17,6,betternether:quartz_stained_glass:15)
RB(6,17,6,srparasites:parasitestain:1,80,quark:crystal:1,30,srparasites:parasiterubbledense:1,100)
RB(7,17,6,srparasites:parasitestain:1,80,quark:crystal:1,30,srparasites:parasiterubbledense:1,100)
B(8,17,6,betternether:quartz_stained_glass:15)
B(9,17,6,betternether:quartz_stained_glass:15)
B(10,17,6,betternether:quartz_stained_glass:15)
B(3,17,7,betternether:quartz_stained_glass:15)
B(4,17,7,betternether:quartz_stained_glass:15)
B(5,17,7,betternether:quartz_stained_glass:15)
RB(6,17,7,srparasites:parasitestain:1,80,quark:crystal:1,30,srparasites:parasiterubbledense:1,100)
RB(7,17,7,srparasites:parasitestain:1,80,quark:crystal:1,30,srparasites:parasiterubbledense:1,100)
B(8,17,7,betternether:quartz_stained_glass:15)
B(9,17,7,betternether:quartz_stained_glass:15)
B(10,17,7,betternether:quartz_stained_glass:15)
B(11,17,7,betternether:quartz_stained_glass:15)
B(4,17,8,betternether:quartz_stained_glass:15)
B(5,17,8,betternether:quartz_stained_glass:15)
B(6,17,8,betternether:quartz_stained_glass:15)
B(7,17,8,betternether:quartz_stained_glass:15)
RB(8,17,8,srparasites:parasitestain:1,80,quark:crystal:1,30,srparasites:parasiterubbledense:1,100)
B(9,17,8,betternether:quartz_stained_glass:15)
B(10,17,8,betternether:quartz_stained_glass:15)
B(11,17,8,betternether:quartz_stained_glass:15)
B(12,17,8,betternether:quartz_stained_glass:15)
B(5,17,9,betternether:quartz_stained_glass:15)
B(6,17,9,betternether:quartz_stained_glass:15)
B(7,17,9,betternether:quartz_stained_glass:15)
B(8,17,9,betternether:quartz_stained_glass:15)
B(9,17,9,betternether:quartz_stained_glass:15)
B(10,17,9,betternether:quartz_stained_glass:15)
B(11,17,9,betternether:quartz_stained_glass:15)
B(12,17,9,betternether:quartz_stained_glass:15)
B(13,17,9,betternether:quartz_stained_glass:15)
B(6,17,10,betternether:quartz_stained_glass:15)
B(7,17,10,betternether:quartz_stained_glass:15)
B(8,17,10,betternether:quartz_stained_glass:15)
B(9,17,10,betternether:quartz_stained_glass:15)
B(10,17,10,betternether:quartz_stained_glass:15)
B(11,17,10,betternether:quartz_stained_glass:15)
B(12,17,10,betternether:quartz_stained_glass:15)
B(13,17,10,betternether:quartz_stained_glass:15)
B(7,17,11,betternether:quartz_stained_glass:15)
B(8,17,11,betternether:quartz_stained_glass:15)
B(9,17,11,betternether:quartz_stained_glass:15)
B(10,17,11,betternether:quartz_stained_glass:15)
B(11,17,11,betternether:quartz_stained_glass:15)
B(12,17,11,betternether:quartz_stained_glass:15)
B(13,17,11,betternether:quartz_stained_glass:15)
B(8,17,12,betternether:quartz_stained_glass:15)
B(9,17,12,betternether:quartz_stained_glass:15)
B(10,17,12,betternether:quartz_stained_glass:15)
B(11,17,12,betternether:quartz_stained_glass:15)
B(12,17,12,betternether:quartz_stained_glass:15)
B(9,17,13,betternether:quartz_stained_glass:15)
B(10,17,13,betternether:quartz_stained_glass:15)
B(11,17,13,betternether:quartz_stained_glass:15)
B(3,18,2,betternether:quartz_stained_glass:15)
B(4,18,2,betternether:quartz_stained_glass:15)
B(5,18,2,betternether:quartz_stained_glass:15)
B(2,18,3,betternether:quartz_stained_glass:15)
B(3,18,3,betternether:quartz_stained_glass:15)
B(4,18,3,betternether:quartz_stained_glass:15)
B(5,18,3,betternether:quartz_stained_glass:15)
B(6,18,3,betternether:quartz_stained_glass:15)
B(7,18,3,betternether:quartz_stained_glass:15)
B(2,18,4,betternether:quartz_stained_glass:15)
B(3,18,4,betternether:quartz_stained_glass:15)
B(4,18,4,betternether:quartz_stained_glass:15)
B(5,18,4,betternether:quartz_stained_glass:15)
B(6,18,4,betternether:quartz_stained_glass:15)
B(7,18,4,betternether:quartz_stained_glass:15)
B(8,18,4,betternether:quartz_stained_glass:15)
B(2,18,5,betternether:quartz_stained_glass:15)
B(3,18,5,betternether:quartz_stained_glass:15)
B(4,18,5,betternether:quartz_stained_glass:15)
RB(5,18,5,srparasites:parasitestain:1,80,quark:crystal:1,30,srparasites:parasiterubbledense:1,100)
RB(6,18,5,srparasites:parasitestain:1,80,quark:crystal:1,30,srparasites:parasiterubbledense:1,100)
B(7,18,5,betternether:quartz_stained_glass:15)
B(8,18,5,betternether:quartz_stained_glass:15)
B(9,18,5,betternether:quartz_stained_glass:15)
B(3,18,6,betternether:quartz_stained_glass:15)
B(4,18,6,betternether:quartz_stained_glass:15)
B(5,18,6,betternether:quartz_stained_glass:15)
B(6,18,6,betternether:quartz_stained_glass:15)
B(7,18,6,betternether:quartz_stained_glass:15)
B(8,18,6,betternether:quartz_stained_glass:15)
B(9,18,6,betternether:quartz_stained_glass:15)
B(10,18,6,betternether:quartz_stained_glass:15)
B(3,18,7,betternether:quartz_stained_glass:15)
B(4,18,7,betternether:quartz_stained_glass:15)
B(5,18,7,betternether:quartz_stained_glass:15)
B(6,18,7,betternether:quartz_stained_glass:15)
B(7,18,7,betternether:quartz_stained_glass:15)
B(8,18,7,betternether:quartz_stained_glass:15)
B(9,18,7,betternether:quartz_stained_glass:15)
B(10,18,7,betternether:quartz_stained_glass:15)
B(11,18,7,betternether:quartz_stained_glass:15)
B(4,18,8,betternether:quartz_stained_glass:15)
B(5,18,8,betternether:quartz_stained_glass:15)
B(6,18,8,betternether:quartz_stained_glass:15)
B(7,18,8,betternether:quartz_stained_glass:15)
B(8,18,8,betternether:quartz_stained_glass:15)
B(9,18,8,betternether:quartz_stained_glass:15)
B(10,18,8,betternether:quartz_stained_glass:15)
B(11,18,8,betternether:quartz_stained_glass:15)
B(12,18,8,betternether:quartz_stained_glass:15)
B(5,18,9,betternether:quartz_stained_glass:15)
B(6,18,9,betternether:quartz_stained_glass:15)
B(7,18,9,betternether:quartz_stained_glass:15)
B(8,18,9,betternether:quartz_stained_glass:15)
B(9,18,9,betternether:quartz_stained_glass:15)
B(10,18,9,betternether:quartz_stained_glass:15)
B(11,18,9,betternether:quartz_stained_glass:15)
B(12,18,9,betternether:quartz_stained_glass:15)
B(6,18,10,betternether:quartz_stained_glass:15)
B(7,18,10,betternether:quartz_stained_glass:15)
B(8,18,10,betternether:quartz_stained_glass:15)
B(9,18,10,betternether:quartz_stained_glass:15)
B(10,18,10,betternether:quartz_stained_glass:15)
B(11,18,10,betternether:quartz_stained_glass:15)
B(7,18,11,betternether:quartz_stained_glass:15)
B(8,18,11,betternether:quartz_stained_glass:15)
B(9,18,11,betternether:quartz_stained_glass:15)
B(10,18,11,betternether:quartz_stained_glass:15)
B(8,18,12,betternether:quartz_stained_glass:15)
B(9,18,12,betternether:quartz_stained_glass:15)
B(2,19,1,betternether:quartz_stained_glass:15)
B(3,19,1,betternether:quartz_stained_glass:15)
B(1,19,2,betternether:quartz_stained_glass:15)
B(2,19,2,betternether:quartz_stained_glass:15)
B(3,19,2,betternether:quartz_stained_glass:15)
B(4,19,2,betternether:quartz_stained_glass:15)
B(5,19,2,betternether:quartz_stained_glass:15)
B(1,19,3,betternether:quartz_stained_glass:15)
B(2,19,3,betternether:quartz_stained_glass:15)
B(3,19,3,betternether:quartz_stained_glass:15)
B(4,19,3,betternether:quartz_stained_glass:15)
B(5,19,3,betternether:quartz_stained_glass:15)
B(6,19,3,betternether:quartz_stained_glass:15)
B(7,19,3,betternether:quartz_stained_glass:15)
B(2,19,4,betternether:quartz_stained_glass:15)
B(3,19,4,betternether:quartz_stained_glass:15)
B(4,19,4,betternether:quartz_stained_glass:15)
B(5,19,4,betternether:quartz_stained_glass:15)
B(6,19,4,betternether:quartz_stained_glass:15)
B(7,19,4,betternether:quartz_stained_glass:15)
B(8,19,4,betternether:quartz_stained_glass:15)
B(2,19,5,betternether:quartz_stained_glass:15)
B(3,19,5,betternether:quartz_stained_glass:15)
B(4,19,5,betternether:quartz_stained_glass:15)
B(5,19,5,betternether:quartz_stained_glass:15)
B(6,19,5,betternether:quartz_stained_glass:15)
B(7,19,5,betternether:quartz_stained_glass:15)
B(8,19,5,betternether:quartz_stained_glass:15)
B(9,19,5,betternether:quartz_stained_glass:15)
B(3,19,6,betternether:quartz_stained_glass:15)
B(4,19,6,betternether:quartz_stained_glass:15)
B(5,19,6,betternether:quartz_stained_glass:15)
RB(6,19,6,srparasites:parasitestain:1,80,quark:crystal:1,30,srparasites:parasiterubbledense:1,100)
B(7,19,6,betternether:quartz_stained_glass:15)
B(8,19,6,betternether:quartz_stained_glass:15)
B(9,19,6,betternether:quartz_stained_glass:15)
B(10,19,6,betternether:quartz_stained_glass:15)
B(3,19,7,betternether:quartz_stained_glass:15)
B(4,19,7,betternether:quartz_stained_glass:15)
B(5,19,7,betternether:quartz_stained_glass:15)
B(6,19,7,betternether:quartz_stained_glass:15)
B(7,19,7,betternether:quartz_stained_glass:15)
B(8,19,7,betternether:quartz_stained_glass:15)
B(9,19,7,betternether:quartz_stained_glass:15)
B(10,19,7,betternether:quartz_stained_glass:15)
B(4,19,8,betternether:quartz_stained_glass:15)
B(5,19,8,betternether:quartz_stained_glass:15)
B(6,19,8,betternether:quartz_stained_glass:15)
B(7,19,8,betternether:quartz_stained_glass:15)
B(8,19,8,betternether:quartz_stained_glass:15)
B(9,19,8,betternether:quartz_stained_glass:15)
B(10,19,8,betternether:quartz_stained_glass:15)
B(5,19,9,betternether:quartz_stained_glass:15)
B(6,19,9,betternether:quartz_stained_glass:15)
B(7,19,9,betternether:quartz_stained_glass:15)
B(8,19,9,betternether:quartz_stained_glass:15)
B(9,19,9,betternether:quartz_stained_glass:15)
B(6,19,10,betternether:quartz_stained_glass:15)
B(7,19,10,betternether:quartz_stained_glass:15)
B(8,19,10,betternether:quartz_stained_glass:15)
B(1,20,1,betternether:quartz_stained_glass:15)
B(2,20,1,betternether:quartz_stained_glass:15)
B(3,20,1,betternether:quartz_stained_glass:15)
B(1,20,2,betternether:quartz_stained_glass:15)
B(2,20,2,betternether:quartz_stained_glass:15)
B(3,20,2,betternether:quartz_stained_glass:15)
B(4,20,2,betternether:quartz_stained_glass:15)
B(5,20,2,betternether:quartz_stained_glass:15)
B(1,20,3,betternether:quartz_stained_glass:15)
B(2,20,3,betternether:quartz_stained_glass:15)
B(3,20,3,betternether:quartz_stained_glass:15)
B(4,20,3,betternether:quartz_stained_glass:15)
B(5,20,3,betternether:quartz_stained_glass:15)
B(6,20,3,betternether:quartz_stained_glass:15)
B(7,20,3,betternether:quartz_stained_glass:15)
B(2,20,4,betternether:quartz_stained_glass:15)
B(3,20,4,betternether:quartz_stained_glass:15)
B(4,20,4,betternether:quartz_stained_glass:15)
B(5,20,4,betternether:quartz_stained_glass:15)
B(6,20,4,betternether:quartz_stained_glass:15)
B(7,20,4,betternether:quartz_stained_glass:15)
B(8,20,4,betternether:quartz_stained_glass:15)
B(2,20,5,betternether:quartz_stained_glass:15)
B(3,20,5,betternether:quartz_stained_glass:15)
B(4,20,5,betternether:quartz_stained_glass:15)
B(5,20,5,betternether:quartz_stained_glass:15)
B(6,20,5,betternether:quartz_stained_glass:15)
B(7,20,5,betternether:quartz_stained_glass:15)
B(8,20,5,betternether:quartz_stained_glass:15)
B(9,20,5,betternether:quartz_stained_glass:15)
B(3,20,6,betternether:quartz_stained_glass:15)
B(4,20,6,betternether:quartz_stained_glass:15)
B(5,20,6,betternether:quartz_stained_glass:15)
B(6,20,6,betternether:quartz_stained_glass:15)
B(7,20,6,betternether:quartz_stained_glass:15)
B(8,20,6,betternether:quartz_stained_glass:15)
B(9,20,6,betternether:quartz_stained_glass:15)
B(3,20,7,betternether:quartz_stained_glass:15)
B(4,20,7,betternether:quartz_stained_glass:15)
B(5,20,7,betternether:quartz_stained_glass:15)
B(6,20,7,betternether:quartz_stained_glass:15)
B(7,20,7,betternether:quartz_stained_glass:15)
B(8,20,7,betternether:quartz_stained_glass:15)
B(4,20,8,betternether:quartz_stained_glass:15)
B(5,20,8,betternether:quartz_stained_glass:15)
B(6,20,8,betternether:quartz_stained_glass:15)
B(7,20,8,betternether:quartz_stained_glass:15)
B(5,20,9,betternether:quartz_stained_glass:15)
B(6,20,9,betternether:quartz_stained_glass:15)
B(0,21,0,betternether:quartz_stained_glass:15)
B(1,21,0,betternether:quartz_stained_glass:15)
B(0,21,1,betternether:quartz_stained_glass:15)
B(1,21,1,betternether:quartz_stained_glass:15)
B(2,21,1,betternether:quartz_stained_glass:15)
B(3,21,1,betternether:quartz_stained_glass:15)
B(1,21,2,betternether:quartz_stained_glass:15)
B(2,21,2,betternether:quartz_stained_glass:15)
B(3,21,2,betternether:quartz_stained_glass:15)
B(4,21,2,betternether:quartz_stained_glass:15)
B(5,21,2,betternether:quartz_stained_glass:15)
B(1,21,3,betternether:quartz_stained_glass:15)
B(2,21,3,betternether:quartz_stained_glass:15)
B(3,21,3,betternether:quartz_stained_glass:15)
B(4,21,3,betternether:quartz_stained_glass:15)
B(5,21,3,betternether:quartz_stained_glass:15)
B(6,21,3,betternether:quartz_stained_glass:15)
B(2,21,4,betternether:quartz_stained_glass:15)
B(3,21,4,betternether:quartz_stained_glass:15)
B(4,21,4,betternether:quartz_stained_glass:15)
B(5,21,4,betternether:quartz_stained_glass:15)
B(6,21,4,betternether:quartz_stained_glass:15)
B(7,21,4,betternether:quartz_stained_glass:15)
B(2,21,5,betternether:quartz_stained_glass:15)
B(3,21,5,betternether:quartz_stained_glass:15)
B(4,21,5,betternether:quartz_stained_glass:15)
B(5,21,5,betternether:quartz_stained_glass:15)
B(6,21,5,betternether:quartz_stained_glass:15)
B(7,21,5,betternether:quartz_stained_glass:15)
B(3,21,6,betternether:quartz_stained_glass:15)
B(4,21,6,betternether:quartz_stained_glass:15)
B(5,21,6,betternether:quartz_stained_glass:15)
B(6,21,6,betternether:quartz_stained_glass:15)
B(4,21,7,betternether:quartz_stained_glass:15)
B(5,21,7,betternether:quartz_stained_glass:15)
B(0,22,0,betternether:quartz_stained_glass:15)
B(1,22,0,betternether:quartz_stained_glass:15)
B(0,22,1,betternether:quartz_stained_glass:15)
B(1,22,1,betternether:quartz_stained_glass:15)
B(2,22,1,betternether:quartz_stained_glass:15)
B(1,22,2,betternether:quartz_stained_glass:15)
B(2,22,2,betternether:quartz_stained_glass:15)
B(3,22,2,betternether:quartz_stained_glass:15)
B(2,22,3,betternether:quartz_stained_glass:15)
B(3,22,3,betternether:quartz_stained_glass:15)
B(4,22,3,betternether:quartz_stained_glass:15)
B(5,22,3,betternether:quartz_stained_glass:15)
B(3,22,4,betternether:quartz_stained_glass:15)
B(4,22,4,betternether:quartz_stained_glass:15)
B(5,22,4,betternether:quartz_stained_glass:15)
B(6,22,4,betternether:quartz_stained_glass:15)
B(3,22,5,betternether:quartz_stained_glass:15)
B(4,22,5,betternether:quartz_stained_glass:15)
B(5,22,5,betternether:quartz_stained_glass:15)
B(4,22,6,betternether:quartz_stained_glass:15)
B(0,23,0,betternether:quartz_stained_glass:15)
B(1,23,1,betternether:quartz_stained_glass:15)
B(2,23,2,betternether:quartz_stained_glass:15)
B(3,23,3,betternether:quartz_stained_glass:15)

