
#######################################################################
# +-----------------------------------------------------------------+ #
# |                            BO3 object                           | #
# +-----------------------------------------------------------------+ #
#######################################################################

Author: NLBlackHeavenNL

Description: No description given

Version: 3

SettingsMode: WriteWithoutComments


#######################################################################
# +-----------------------------------------------------------------+ #
# |                          Main settings                          | #
# +-----------------------------------------------------------------+ #
#######################################################################

Tree: true

Frequency: 1

Rarity: 100.0

RotateRandomly: false

SpawnHeight: highestSolidBlock

SpawnHeightOffset: -1

SpawnHeightVariance: 0

##############################
# Height Limits for the BO3. #
##############################

MinHeight: 0

MaxHeight: 255

######################
# Extrusion settings #
######################

ExtrudeMode: None

ExtrudeThroughBlocks: AIR

MaxBranchDepth: 10

ExcludedBiomes: All


#######################################################################
# +-----------------------------------------------------------------+ #
# |                      Source block settings                      | #
# +-----------------------------------------------------------------+ #
#######################################################################

SourceBlocks: AIR,GRASS,DIRT,biomesoplenty:dirt,biomesoplenty:grass,MYCEL

MaxPercentageOutsideSourceBlock: 0

OutsideSourceBlock: placeAnyway

DoReplaceBlocks: true

IsOTGPlus: false


#######################################################################
# +-----------------------------------------------------------------+ #
# |                              Blocks                             | #
# +-----------------------------------------------------------------+ #
#######################################################################

Block(-3,6,2,dynamictreesbop:leaves0:8)
Block(-3,7,-2,dynamictreesbop:leaves0:8)
Block(-3,7,-1,dynamictreesbop:leaves0:8)
Block(-3,7,0,dynamictreesbop:leaves0:8)
Block(-3,8,-1,dynamictreesbop:leaves0:8)
Block(-3,8,0,dynamictreesbop:leaves0:8)
Block(-2,6,-2,dynamictreesbop:leaves0:8)
Block(-2,6,-1,dynamictreesbop:leaves0:8)
Block(-2,6,0,dynamictreesbop:leaves0:8)
Block(-2,6,1,dynamictreesbop:leaves0:8)
Block(-2,7,-3,dynamictreesbop:leaves0:8)
Block(-2,7,-2,dynamictreesbop:leaves0:9)
Block(-2,7,-1,dynamictreesbop:leaves0:10)
Block(-2,7,0,dynamictreesbop:leaves0:11)
Block(-2,7,1,dynamictreesbop:leaves0:8)
Block(-2,8,-2,dynamictreesbop:leaves0:8)
Block(-2,8,-1,dynamictreesbop:leaves0:9)
Block(-2,8,0,dynamictreesbop:leaves0:10)
Block(-2,8,1,dynamictreesbop:leaves0:8)
Block(-2,8,2,dynamictreesbop:leaves0:8)
Block(-2,8,3,dynamictreesbop:leaves0:8)
Block(-2,9,-1,dynamictreesbop:leaves0:8)
Block(-2,9,0,dynamictreesbop:leaves0:8)
Block(-2,9,1,dynamictreesbop:leaves0:8)
Block(-2,9,2,dynamictreesbop:leaves0:8)
Block(-1,4,5,dynamictreesbop:leaves0:8)
Block(-1,4,6,dynamictreesbop:leaves0:8)
Block(-1,5,1,dynamictreesbop:magicbranch)
Block(-1,5,5,dynamictreesbop:leaves0:8)
Block(-1,5,6,dynamictreesbop:leaves0:8)
Block(-1,6,-2,dynamictreesbop:leaves0:8)
Block(-1,6,1,dynamictreesbop:leaves0:11)
Block(-1,6,5,dynamictreesbop:leaves0:8)
Block(-1,6,6,dynamictreesbop:leaves0:8)
Block(-1,7,-3,dynamictreesbop:leaves0:8)
Block(-1,7,-2,dynamictreesbop:leaves0:10)
Block(-1,7,-1,dynamictreesbop:leaves0:11)
Block(-1,7,0,dynamictreesbop:magicbranch)
Block(-1,7,1,dynamictreesbop:magicbranch:1)
Block(-1,7,2,dynamictreesbop:leaves0:8)
Block(-1,7,3,dynamictreesbop:leaves0:8)
Block(-1,8,-3,dynamictreesbop:leaves0:8)
Block(-1,8,-2,dynamictreesbop:leaves0:9)
Block(-1,8,-1,dynamictreesbop:leaves0:10)
Block(-1,8,0,dynamictreesbop:leaves0:11)
Block(-1,8,1,dynamictreesbop:leaves0:11)
Block(-1,8,2,dynamictreesbop:leaves0:10)
Block(-1,8,3,dynamictreesbop:leaves0:9)
Block(-1,8,4,dynamictreesbop:leaves0:8)
Block(-1,9,-2,dynamictreesbop:leaves0:8)
Block(-1,9,-1,dynamictreesbop:leaves0:9)
Block(-1,9,0,dynamictreesbop:leaves0:9)
Block(-1,9,1,dynamictreesbop:leaves0:10)
Block(-1,9,2,dynamictreesbop:leaves0:9)
Block(-1,9,3,dynamictreesbop:leaves0:8)
Block(-1,10,-1,dynamictreesbop:leaves0:8)
Block(-1,10,0,dynamictreesbop:leaves0:8)
Block(-1,10,1,dynamictreesbop:leaves0:8)
Block(-1,10,2,dynamictreesbop:leaves0:8)
Block(0,4,1,dynamictreesbop:magicbranch:3)
Block(0,4,4,dynamictreesbop:leaves0:8)
Block(0,4,5,dynamictreesbop:leaves0:10)
Block(0,4,6,dynamictreesbop:leaves0:9)
Block(0,4,7,dynamictreesbop:leaves0:8)
Block(0,5,0,dynamictreesbop:magicbranch)
Block(0,5,1,dynamictreesbop:magicbranch:2)
Block(0,5,4,dynamictreesbop:leaves0:8)
Block(0,5,5,dynamictreesbop:leaves0:11)
Block(0,5,6,dynamictreesbop:leaves0:10)
Block(0,5,7,dynamictreesbop:leaves0:8)
Block(0,6,0,dynamictreesbop:leaves0:11)
Block(0,6,1,dynamictreesbop:magicbranch:2)
Block(0,6,4,dynamictreesbop:leaves0:8)
Block(0,6,5,dynamictreesbop:leaves0:10)
Block(0,6,6,dynamictreesbop:leaves0:9)
Block(0,6,7,dynamictreesbop:leaves0:8)
Block(0,7,-3,dynamictreesbop:leaves0:8)
Block(0,7,-2,dynamictreesbop:leaves0:11)
Block(0,7,-1,dynamictreesbop:magicbranch)
Block(0,7,0,dynamictreesbop:leaves0:11)
Block(0,7,1,dynamictreesbop:magicbranch:1)
Block(0,7,2,dynamictreesbop:leaves0:8)
Block(0,7,3,dynamictreesbop:leaves0:8)
Block(0,7,4,dynamictreesbop:leaves0:8)
Block(0,7,5,dynamictreesbop:leaves0:8)
Block(0,7,6,dynamictreesbop:leaves0:8)
Block(0,8,-3,dynamictreesbop:leaves0:8)
Block(0,8,-2,dynamictreesbop:leaves0:10)
Block(0,8,-1,dynamictreesbop:leaves0:11)
Block(0,8,0,dynamictreesbop:leaves0:11)
Block(0,8,1,dynamictreesbop:magicbranch)
Block(0,8,2,dynamictreesbop:leaves0:11)
Block(0,8,3,dynamictreesbop:leaves0:10)
Block(0,8,4,dynamictreesbop:leaves0:8)
Block(0,9,-3,dynamictreesbop:leaves0:8)
Block(0,9,-2,dynamictreesbop:leaves0:9)
Block(0,9,-1,dynamictreesbop:leaves0:10)
Block(0,9,0,dynamictreesbop:leaves0:10)
Block(0,9,1,dynamictreesbop:leaves0:11)
Block(0,9,2,dynamictreesbop:leaves0:10)
Block(0,9,3,dynamictreesbop:leaves0:9)
Block(0,9,4,dynamictreesbop:leaves0:8)
Block(0,10,-2,dynamictreesbop:leaves0:8)
Block(0,10,-1,dynamictreesbop:leaves0:8)
Block(0,10,0,dynamictreesbop:leaves0:8)
Block(0,10,1,dynamictreesbop:leaves0:8)
Block(0,10,2,dynamictreesbop:leaves0:8)
Block(0,10,3,dynamictreesbop:leaves0:8)
Block(1,0,1,dynamictrees:rootydirt:0)
Block(1,1,1,dynamictreesbop:magicbranch:7)
Block(1,2,1,dynamictreesbop:magicbranch:7)
Block(1,3,-1,dynamictreesbop:magicbranch:2)
Block(1,3,0,dynamictreesbop:magicbranch:3)
Block(1,3,1,dynamictreesbop:magicbranch:7)
Block(1,4,-1,dynamictreesbop:magicbranch:2)
Block(1,4,1,dynamictreesbop:magicbranch:6)
Block(1,4,2,dynamictreesbop:magicbranch:3)
Block(1,4,3,dynamictreesbop:magicbranch:1)
Block(1,4,4,dynamictreesbop:magicbranch:1)
Block(1,4,5,dynamictreesbop:leaves0:11)
Block(1,4,6,dynamictreesbop:leaves0:10)
Block(1,4,7,dynamictreesbop:leaves0:8)
Block(1,5,-1,dynamictreesbop:magicbranch:2)
Block(1,5,2,dynamictreesbop:magicbranch:2)
Block(1,5,4,dynamictreesbop:magicbranch:1)
Block(1,5,5,dynamictreesbop:magicbranch)
Block(1,5,6,dynamictreesbop:leaves0:11)
Block(1,5,7,dynamictreesbop:leaves0:8)
Block(1,6,-1,dynamictreesbop:magicbranch:1)
Block(1,6,2,dynamictreesbop:magicbranch:1)
Block(1,6,3,dynamictreesbop:magicbranch)
Block(1,6,4,dynamictreesbop:leaves0:11)
Block(1,6,5,dynamictreesbop:leaves0:11)
Block(1,6,6,dynamictreesbop:leaves0:10)
Block(1,6,7,dynamictreesbop:leaves0:8)
Block(1,7,-3,dynamictreesbop:leaves0:8)
Block(1,7,-2,dynamictreesbop:leaves0:10)
Block(1,7,-1,dynamictreesbop:magicbranch:1)
Block(1,7,0,dynamictreesbop:leaves0:10)
Block(1,7,1,dynamictreesbop:leaves0:9)
Block(1,7,2,dynamictreesbop:magicbranch:1)
Block(1,7,3,dynamictreesbop:leaves0:11)
Block(1,7,4,dynamictreesbop:leaves0:10)
Block(1,7,5,dynamictreesbop:leaves0:8)
Block(1,7,6,dynamictreesbop:leaves0:8)
Block(1,8,-3,dynamictreesbop:leaves0:8)
Block(1,8,-2,dynamictreesbop:leaves0:11)
Block(1,8,-1,dynamictreesbop:magicbranch)
Block(1,8,0,dynamictreesbop:leaves0:11)
Block(1,8,1,dynamictreesbop:leaves0:11)
Block(1,8,2,dynamictreesbop:magicbranch)
Block(1,8,3,dynamictreesbop:leaves0:11)
Block(1,8,4,dynamictreesbop:leaves0:8)
Block(1,9,-3,dynamictreesbop:leaves0:8)
Block(1,9,-2,dynamictreesbop:leaves0:10)
Block(1,9,-1,dynamictreesbop:leaves0:11)
Block(1,9,0,dynamictreesbop:leaves0:10)
Block(1,9,1,dynamictreesbop:leaves0:10)
Block(1,9,2,dynamictreesbop:leaves0:11)
Block(1,9,3,dynamictreesbop:leaves0:10)
Block(1,9,4,dynamictreesbop:leaves0:8)
Block(1,10,-2,dynamictreesbop:leaves0:8)
Block(1,10,-1,dynamictreesbop:leaves0:8)
Block(1,10,0,dynamictreesbop:leaves0:8)
Block(1,10,1,dynamictreesbop:leaves0:8)
Block(1,10,2,dynamictreesbop:leaves0:8)
Block(1,10,3,dynamictreesbop:leaves0:8)
Block(2,4,1,dynamictreesbop:magicbranch:3)
Block(2,4,5,dynamictreesbop:leaves0:10)
Block(2,4,6,dynamictreesbop:leaves0:9)
Block(2,4,7,dynamictreesbop:leaves0:8)
Block(2,5,0,dynamictreesbop:magicbranch:1)
Block(2,5,1,dynamictreesbop:magicbranch:2)
Block(2,5,5,dynamictreesbop:leaves0:11)
Block(2,5,6,dynamictreesbop:leaves0:10)
Block(2,5,7,dynamictreesbop:leaves0:8)
Block(2,6,0,dynamictreesbop:magicbranch)
Block(2,6,2,dynamictreesbop:magicbranch)
Block(2,6,4,dynamictreesbop:leaves0:8)
Block(2,6,5,dynamictreesbop:leaves0:10)
Block(2,6,6,dynamictreesbop:leaves0:9)
Block(2,6,7,dynamictreesbop:leaves0:8)
Block(2,7,-3,dynamictreesbop:leaves0:8)
Block(2,7,-2,dynamictreesbop:leaves0:11)
Block(2,7,-1,dynamictreesbop:magicbranch)
Block(2,7,0,dynamictreesbop:leaves0:11)
Block(2,7,1,dynamictreesbop:leaves0:10)
Block(2,7,2,dynamictreesbop:leaves0:11)
Block(2,7,3,dynamictreesbop:leaves0:10)
Block(2,7,4,dynamictreesbop:leaves0:9)
Block(2,7,5,dynamictreesbop:leaves0:8)
Block(2,7,6,dynamictreesbop:leaves0:8)
Block(2,8,-3,dynamictreesbop:leaves0:8)
Block(2,8,-2,dynamictreesbop:leaves0:10)
Block(2,8,-1,dynamictreesbop:leaves0:11)
Block(2,8,0,dynamictreesbop:leaves0:10)
Block(2,8,1,dynamictreesbop:leaves0:10)
Block(2,8,2,dynamictreesbop:leaves0:11)
Block(2,8,3,dynamictreesbop:leaves0:10)
Block(2,8,4,dynamictreesbop:leaves0:8)
Block(2,9,-3,dynamictreesbop:leaves0:8)
Block(2,9,-2,dynamictreesbop:leaves0:9)
Block(2,9,-1,dynamictreesbop:leaves0:10)
Block(2,9,0,dynamictreesbop:leaves0:9)
Block(2,9,1,dynamictreesbop:leaves0:9)
Block(2,9,2,dynamictreesbop:leaves0:10)
Block(2,9,3,dynamictreesbop:leaves0:9)
Block(2,9,4,dynamictreesbop:leaves0:8)
Block(2,10,-2,dynamictreesbop:leaves0:8)
Block(2,10,-1,dynamictreesbop:leaves0:8)
Block(2,10,0,dynamictreesbop:leaves0:8)
Block(2,10,1,dynamictreesbop:leaves0:8)
Block(2,10,2,dynamictreesbop:leaves0:8)
Block(2,10,3,dynamictreesbop:leaves0:8)
Block(3,4,1,dynamictreesbop:magicbranch:2)
Block(3,4,4,dynamictreesbop:leaves0:8)
Block(3,4,5,dynamictreesbop:leaves0:8)
Block(3,4,6,dynamictreesbop:leaves0:8)
Block(3,5,-1,dynamictreesbop:magicbranch)
Block(3,5,0,dynamictreesbop:magicbranch:1)
Block(3,5,4,dynamictreesbop:leaves0:8)
Block(3,5,5,dynamictreesbop:leaves0:8)
Block(3,5,6,dynamictreesbop:leaves0:8)
Block(3,6,-2,dynamictreesbop:leaves0:8)
Block(3,6,-1,dynamictreesbop:leaves0:11)
Block(3,6,0,dynamictreesbop:leaves0:11)
Block(3,6,1,dynamictreesbop:leaves0:10)
Block(3,6,2,dynamictreesbop:leaves0:11)
Block(3,6,3,dynamictreesbop:leaves0:10)
Block(3,6,4,dynamictreesbop:leaves0:9)
Block(3,6,5,dynamictreesbop:leaves0:8)
Block(3,6,6,dynamictreesbop:leaves0:8)
Block(3,7,-3,dynamictreesbop:leaves0:8)
Block(3,7,-2,dynamictreesbop:leaves0:10)
Block(3,7,-1,dynamictreesbop:leaves0:11)
Block(3,7,0,dynamictreesbop:leaves0:10)
Block(3,7,1,dynamictreesbop:leaves0:9)
Block(3,7,2,dynamictreesbop:leaves0:10)
Block(3,7,3,dynamictreesbop:leaves0:9)
Block(3,7,4,dynamictreesbop:leaves0:8)
Block(3,8,-3,dynamictreesbop:leaves0:8)
Block(3,8,-2,dynamictreesbop:leaves0:9)
Block(3,8,-1,dynamictreesbop:leaves0:10)
Block(3,8,0,dynamictreesbop:leaves0:9)
Block(3,8,1,dynamictreesbop:leaves0:8)
Block(3,8,2,dynamictreesbop:leaves0:8)
Block(3,8,3,dynamictreesbop:leaves0:8)
Block(3,9,-2,dynamictreesbop:leaves0:8)
Block(3,9,-1,dynamictreesbop:leaves0:9)
Block(3,9,0,dynamictreesbop:leaves0:8)
Block(3,9,1,dynamictreesbop:leaves0:8)
Block(3,9,2,dynamictreesbop:leaves0:8)
Block(3,9,3,dynamictreesbop:leaves0:8)
Block(3,10,-1,dynamictreesbop:leaves0:8)
Block(4,4,1,dynamictreesbop:magicbranch:1)
Block(4,4,2,dynamictreesbop:magicbranch:1)
Block(4,4,3,dynamictreesbop:magicbranch:1)
Block(4,4,4,dynamictreesbop:leaves0:10)
Block(4,4,5,dynamictreesbop:leaves0:8)
Block(4,5,-2,dynamictreesbop:leaves0:8)
Block(4,5,-1,dynamictreesbop:leaves0:11)
Block(4,5,0,dynamictreesbop:leaves0:11)
Block(4,5,1,dynamictreesbop:magicbranch)
Block(4,5,2,dynamictreesbop:leaves0:11)
Block(4,5,3,dynamictreesbop:magicbranch)
Block(4,5,4,dynamictreesbop:leaves0:11)
Block(4,5,5,dynamictreesbop:leaves0:8)
Block(4,6,-2,dynamictreesbop:leaves0:8)
Block(4,6,-1,dynamictreesbop:leaves0:10)
Block(4,6,0,dynamictreesbop:leaves0:10)
Block(4,6,1,dynamictreesbop:leaves0:11)
Block(4,6,2,dynamictreesbop:leaves0:10)
Block(4,6,3,dynamictreesbop:leaves0:11)
Block(4,6,4,dynamictreesbop:leaves0:10)
Block(4,6,5,dynamictreesbop:leaves0:8)
Block(4,7,-2,dynamictreesbop:leaves0:8)
Block(4,7,-1,dynamictreesbop:leaves0:8)
Block(4,7,0,dynamictreesbop:leaves0:9)
Block(4,7,1,dynamictreesbop:leaves0:8)
Block(4,7,2,dynamictreesbop:leaves0:9)
Block(4,7,3,dynamictreesbop:leaves0:8)
Block(4,7,4,dynamictreesbop:leaves0:8)
Block(4,8,-2,dynamictreesbop:leaves0:8)
Block(4,8,-1,dynamictreesbop:leaves0:8)
Block(4,8,0,dynamictreesbop:leaves0:8)
Block(4,8,2,dynamictreesbop:leaves0:8)
Block(4,9,-1,dynamictreesbop:leaves0:8)
Block(5,4,-1,dynamictreesbop:leaves0:8)
Block(5,4,0,dynamictreesbop:leaves0:11)
Block(5,4,1,dynamictreesbop:magicbranch)
Block(5,4,2,dynamictreesbop:leaves0:11)
Block(5,4,3,dynamictreesbop:magicbranch)
Block(5,4,4,dynamictreesbop:leaves0:11)
Block(5,4,5,dynamictreesbop:leaves0:8)
Block(5,5,-1,dynamictreesbop:leaves0:8)
Block(5,5,0,dynamictreesbop:leaves0:10)
Block(5,5,1,dynamictreesbop:leaves0:11)
Block(5,5,2,dynamictreesbop:leaves0:10)
Block(5,5,3,dynamictreesbop:leaves0:11)
Block(5,5,4,dynamictreesbop:leaves0:10)
Block(5,5,5,dynamictreesbop:leaves0:8)
Block(5,6,-1,dynamictreesbop:leaves0:8)
Block(5,6,0,dynamictreesbop:leaves0:9)
Block(5,6,1,dynamictreesbop:leaves0:10)
Block(5,6,2,dynamictreesbop:leaves0:9)
Block(5,6,3,dynamictreesbop:leaves0:10)
Block(5,6,4,dynamictreesbop:leaves0:9)
Block(5,6,5,dynamictreesbop:leaves0:8)
Block(5,7,0,dynamictreesbop:leaves0:8)
Block(5,7,1,dynamictreesbop:leaves0:8)
Block(5,7,2,dynamictreesbop:leaves0:8)
Block(5,7,3,dynamictreesbop:leaves0:8)
Block(5,7,4,dynamictreesbop:leaves0:8)
Block(6,3,0,dynamictreesbop:leaves0:8)
Block(6,3,1,dynamictreesbop:leaves0:8)
Block(6,3,2,dynamictreesbop:leaves0:8)
Block(6,3,3,dynamictreesbop:leaves0:8)
Block(6,3,4,dynamictreesbop:leaves0:8)
Block(6,4,-1,dynamictreesbop:leaves0:8)
Block(6,4,0,dynamictreesbop:leaves0:10)
Block(6,4,1,dynamictreesbop:leaves0:11)
Block(6,4,2,dynamictreesbop:leaves0:10)
Block(6,4,3,dynamictreesbop:leaves0:11)
Block(6,4,4,dynamictreesbop:leaves0:10)
Block(6,4,5,dynamictreesbop:leaves0:8)
Block(6,5,-1,dynamictreesbop:leaves0:8)
Block(6,5,0,dynamictreesbop:leaves0:9)
Block(6,5,1,dynamictreesbop:leaves0:10)
Block(6,5,2,dynamictreesbop:leaves0:9)
Block(6,5,3,dynamictreesbop:leaves0:10)
Block(6,5,4,dynamictreesbop:leaves0:9)
Block(6,5,5,dynamictreesbop:leaves0:8)
Block(6,6,0,dynamictreesbop:leaves0:8)
Block(6,6,1,dynamictreesbop:leaves0:9)
Block(6,6,2,dynamictreesbop:leaves0:8)
Block(6,6,3,dynamictreesbop:leaves0:9)
Block(6,6,4,dynamictreesbop:leaves0:8)
Block(6,7,1,dynamictreesbop:leaves0:8)
Block(6,7,3,dynamictreesbop:leaves0:8)
Block(7,4,0,dynamictreesbop:leaves0:8)
Block(7,4,1,dynamictreesbop:leaves0:8)
Block(7,4,2,dynamictreesbop:leaves0:8)
Block(7,4,3,dynamictreesbop:leaves0:8)
Block(7,4,4,dynamictreesbop:leaves0:8)
Block(7,5,0,dynamictreesbop:leaves0:8)
Block(7,5,1,dynamictreesbop:leaves0:8)
Block(7,5,2,dynamictreesbop:leaves0:8)
Block(7,5,3,dynamictreesbop:leaves0:8)
Block(7,5,4,dynamictreesbop:leaves0:8)
Block(7,6,1,dynamictreesbop:leaves0:8)
Block(7,6,3,dynamictreesbop:leaves0:8)

#######################################################################
# +-----------------------------------------------------------------+ #
# |                            BO3 checks                           | #
# +-----------------------------------------------------------------+ #
#######################################################################

BlockCheck(1,-1,1,GRASS,DIRT,MYCEL,biomesoplenty:grass,biomesoplenty:dirt)

#######################################################################
# +-----------------------------------------------------------------+ #
# |                             Branches                            | #
# +-----------------------------------------------------------------+ #
#######################################################################


#######################################################################
# +-----------------------------------------------------------------+ #
# |                             Entities                            | #
# +-----------------------------------------------------------------+ #
#######################################################################


#######################################################################
# +-----------------------------------------------------------------+ #
# |                            Particles                            | #
# +-----------------------------------------------------------------+ #
#######################################################################


#######################################################################
# +-----------------------------------------------------------------+ #
# |                             Spawners                            | #
# +-----------------------------------------------------------------+ #
#######################################################################


#######################################################################
# +-----------------------------------------------------------------+ #
# |                             ModData                             | #
# +-----------------------------------------------------------------+ #
#######################################################################

