
#######################################################################
# +-----------------------------------------------------------------+ #
# |                            BO4 object                           | #
# +-----------------------------------------------------------------+ #
#######################################################################

Author: NLBlackEagle

Description: No description given

SettingsMode: WriteDisable


#######################################################################
# +-----------------------------------------------------------------+ #
# |                          Main settings                          | #
# +-----------------------------------------------------------------+ #
#######################################################################

FixedRotation: 

Frequency: 0

SpawnHeight: highestBlock

UseCenterForHighestBlock: true

##############################
# Height Limits for the BO4. #
##############################

MinHeight: 0

MaxHeight: 255

InheritBO3: 

InheritBO3Rotation: NORTH

OverrideChildSettings: true

OverrideParentHeight: false

CanOverride: false

BranchFrequency: 0

BranchFrequencyGroup: 

MustBeBelowOther: false

MustBeInside: 

CannotBeInside: 

ReplacesBO3: 

MustBeInsideWorldBorders: false

CanSpawnOnWater: true

SpawnOnWaterOnly: false

SpawnUnderWater: false

SpawnAtWaterLevel: false

HeightOffset: 0

RemoveAir: true

ReplaceAbove: 

ReplaceBelow: 

ReplaceWithBiomeBlocks: true

ReplaceWithSurfaceBlock: GRASS

ReplaceWithGroundBlock: DIRT

ReplaceWithStoneBlock: STONE

SmoothRadius: 0

SmoothHeightOffset: 0

SmoothStartTop: false

SmoothStartWood: false

SmoothingSurfaceBlock: 

SmoothingGroundBlock: 

BO3Group: 

IsSpawnPoint: false

DoReplaceBlocks: true


#######################################################################
# +-----------------------------------------------------------------+ #
# |                              Blocks                             | #
# +-----------------------------------------------------------------+ #
#######################################################################

Block(-8,6,-5,LOG:12)
Block(-8,7,-6,LOG:12)
Block(-8,7,-5,LOG:12)
Block(-8,7,-4,LOG:12)
Block(-8,8,-7,LOG:12)
Block(-8,8,-6,LOG:12)
Block(-8,8,-5,LOG:12)
Block(-8,8,-4,LOG:12)
Block(-8,8,1,LOG:12)
Block(-8,9,-7,LOG:12)
Block(-8,9,-6,LOG:12)
Block(-8,9,-5,LOG:12)
Block(-8,9,-4,LOG:12)
Block(-8,9,0,LOG:12)
Block(-8,9,1,LOG:12)
Block(-8,9,2,LOG:12)
Block(-8,10,-7,LOG:12)
Block(-8,10,-6,LOG:12)
Block(-8,10,-5,LOG:12)
Block(-8,10,-4,quark:leaf_carpet)
Block(-8,10,-1,LOG:12)
Block(-8,10,0,LOG:12)
Block(-8,10,1,LOG:12)
Block(-8,11,-7,LOG:12)
Block(-8,11,-6,LOG:12)
Block(-8,11,-5,quark:leaf_carpet)
Block(-8,11,-1,LOG:12)
Block(-8,11,0,LOG:12)
Block(-8,11,1,LOG:12)
Block(-8,12,-7,LOG:12)
Block(-8,12,-6,quark:leaf_carpet)
Block(-8,12,-1,LOG:12)
Block(-8,12,0,LOG:12)
Block(-8,12,1,LOG:12)
Block(-8,13,-7,LOG:12)
Block(-8,13,-1,LOG:12)
Block(-8,13,0,LOG:12)
Block(-8,13,1,LOG:12)
Block(-8,14,-1,LOG:12)
Block(-8,14,0,LOG:12)
Block(-8,14,1,LOG:12)
Block(-8,15,-7,LOG:12)
Block(-8,15,-2,LOG:12)
Block(-8,15,-1,LOG:12)
Block(-8,15,0,LOG:12)
Block(-8,15,1,quark:leaf_carpet)
Block(-8,16,-7,LOG:12)
Block(-8,16,-6,LOG:12)
Block(-8,16,-3,LOG:12)
Block(-8,16,-2,LOG:12)
Block(-8,16,-1,LOG:12)
Block(-8,16,0,LOG:12)
Block(-8,17,-7,LOG:12)
Block(-8,17,-6,LOG:12)
Block(-8,17,-5,LOG:12)
Block(-8,17,-4,LOG:12)
Block(-8,17,-3,LOG:12)
Block(-8,17,-2,LOG:12)
Block(-8,17,-1,LOG:12)
Block(-8,17,0,LOG:12)
Block(-8,18,-7,LOG:12)
Block(-8,18,-6,LOG:12)
Block(-8,18,-5,LOG:12)
Block(-8,18,-4,LOG:12)
Block(-8,18,-3,LOG:12)
Block(-8,18,-2,LOG:12)
Block(-8,18,-1,LOG:12)
Block(-8,18,0,quark:leaf_carpet)
Block(-8,19,-6,LOG:12)
Block(-8,19,-5,LOG:12)
Block(-8,19,-4,LOG:12)
Block(-8,19,-3,LOG:12)
Block(-8,19,-2,LOG:12)
Block(-8,19,-1,quark:leaf_carpet)
Block(-8,20,-5,LOG:12)
Block(-8,20,-4,LOG:12)
Block(-8,20,-3,LOG:12)
Block(-8,21,-4,LOG:12)
Block(-8,21,-3,quark:leaf_carpet)
Block(-8,32,-7,LOG:12)
RandomBlock(-8,32,-1,quark:quilted_wool:7,10,quark:quilted_wool:7,100)
RandomBlock(-8,32,0,quark:quilted_wool:7,10,quark:quilted_wool:7,100)
RandomBlock(-8,32,1,quark:quilted_wool:7,10,quark:quilted_wool:7,100)
Block(-8,33,-7,LOG:12)
Block(-8,33,-6,LOG:12)
RandomBlock(-8,33,-2,quark:quilted_wool:7,10,quark:quilted_wool:7,100)
RandomBlock(-8,33,-1,quark:quilted_wool:7,10,quark:quilted_wool:7,100)
RandomBlock(-8,33,0,quark:quilted_wool:7,10,quark:quilted_wool:7,100)
RandomBlock(-8,33,1,quark:quilted_wool:7,10,quark:quilted_wool:7,100)
RandomBlock(-8,33,2,quark:quilted_wool:7,10,quark:quilted_wool:7,100)
Block(-8,34,-7,LOG:12)
Block(-8,34,-6,LOG:12)
RandomBlock(-8,34,-3,quark:quilted_wool:7,10,quark:quilted_wool:7,100)
RandomBlock(-8,34,-2,quark:quilted_wool:7,10,quark:quilted_wool:7,100)
RandomBlock(-8,34,-1,quark:quilted_wool:7,10,quark:quilted_wool:7,100)
RandomBlock(-8,34,0,quark:quilted_wool:7,10,quark:quilted_wool:7,100)
RandomBlock(-8,34,1,quark:quilted_wool:7,10,quark:quilted_wool:7,100)
RandomBlock(-8,34,2,quark:quilted_wool:7,10,quark:quilted_wool:7,100)
RandomBlock(-8,34,3,quark:quilted_wool:7,10,quark:quilted_wool:7,100)
Block(-8,35,-7,LOG:12)
Block(-8,35,-6,LOG:12)
RandomBlock(-8,35,-4,quark:quilted_wool:7,10,quark:quilted_wool:7,100)
RandomBlock(-8,35,-3,quark:quilted_wool:7,10,quark:quilted_wool:7,100)
RandomBlock(-8,35,-2,quark:quilted_wool:7,10,quark:quilted_wool:7,100)
RandomBlock(-8,35,-1,quark:quilted_wool:7,10,quark:quilted_wool:7,100)
RandomBlock(-8,35,0,quark:quilted_wool:7,10,quark:quilted_wool:7,100)
RandomBlock(-8,35,1,quark:quilted_wool:7,10,quark:quilted_wool:7,100)
RandomBlock(-8,35,2,quark:quilted_wool:7,10,quark:quilted_wool:7,100)
RandomBlock(-8,35,3,quark:quilted_wool:7,10,quark:quilted_wool:7,100)
RandomBlock(-8,35,4,quark:quilted_wool:7,10,quark:quilted_wool:7,100)
Block(-8,36,-7,LOG:12)
RandomBlock(-8,36,-4,quark:quilted_wool:7,10,quark:quilted_wool:7,100)
RandomBlock(-8,36,-3,quark:quilted_wool:7,10,quark:quilted_wool:7,100)
RandomBlock(-8,36,-2,quark:quilted_wool:7,10,quark:quilted_wool:7,100)
RandomBlock(-8,36,-1,quark:quilted_wool:7,10,quark:quilted_wool:7,100)
RandomBlock(-8,36,0,quark:quilted_wool:7,10,quark:quilted_wool:7,100)
RandomBlock(-8,36,1,quark:quilted_wool:7,10,quark:quilted_wool:7,100)
RandomBlock(-8,36,2,quark:quilted_wool:7,10,quark:quilted_wool:7,100)
RandomBlock(-8,36,3,quark:quilted_wool:7,10,quark:quilted_wool:7,100)
RandomBlock(-8,36,4,quark:quilted_wool:7,10,quark:quilted_wool:7,100)
RandomBlock(-8,37,-4,quark:quilted_wool:7,10,quark:quilted_wool:7,100)
RandomBlock(-8,37,-3,quark:quilted_wool:7,10,quark:quilted_wool:7,100)
RandomBlock(-8,37,-2,quark:quilted_wool:7,10,quark:quilted_wool:7,100)
RandomBlock(-8,37,-1,quark:quilted_wool:7,10,quark:quilted_wool:7,100)
RandomBlock(-8,37,0,quark:quilted_wool:7,10,quark:quilted_wool:7,100)
RandomBlock(-8,37,1,quark:quilted_wool:7,10,quark:quilted_wool:7,100)
RandomBlock(-8,37,2,quark:quilted_wool:7,10,quark:quilted_wool:7,100)
RandomBlock(-8,37,3,quark:quilted_wool:7,10,quark:quilted_wool:7,100)
RandomBlock(-8,37,4,quark:quilted_wool:7,10,quark:quilted_wool:7,100)
RandomBlock(-8,38,-4,quark:quilted_wool:7,10,quark:quilted_wool:7,100)
RandomBlock(-8,38,-3,quark:quilted_wool:7,10,quark:quilted_wool:7,100)
RandomBlock(-8,38,-2,quark:quilted_wool:7,10,quark:quilted_wool:7,100)
RandomBlock(-8,38,-1,quark:quilted_wool:7,10,quark:quilted_wool:7,100)
RandomBlock(-8,38,0,quark:quilted_wool:7,10,quark:quilted_wool:7,100)
RandomBlock(-8,38,1,quark:quilted_wool:7,10,quark:quilted_wool:7,100)
RandomBlock(-8,38,2,quark:quilted_wool:7,10,quark:quilted_wool:7,100)
RandomBlock(-8,38,3,quark:quilted_wool:7,10,quark:quilted_wool:7,100)
RandomBlock(-8,38,4,quark:quilted_wool:7,10,quark:quilted_wool:7,100)
RandomBlock(-8,39,-4,quark:quilted_wool:7,10,quark:quilted_wool:7,100)
RandomBlock(-8,39,-3,quark:quilted_wool:7,10,quark:quilted_wool:7,100)
RandomBlock(-8,39,-2,quark:quilted_wool:7,10,quark:quilted_wool:7,100)
RandomBlock(-8,39,-1,quark:quilted_wool:7,10,quark:quilted_wool:7,100)
RandomBlock(-8,39,0,quark:quilted_wool:7,10,quark:quilted_wool:7,100)
RandomBlock(-8,39,1,quark:quilted_wool:7,10,quark:quilted_wool:7,100)
RandomBlock(-8,39,2,quark:quilted_wool:7,10,quark:quilted_wool:7,100)
RandomBlock(-8,39,3,quark:quilted_wool:7,10,quark:quilted_wool:7,100)
RandomBlock(-8,39,4,quark:quilted_wool:7,10,quark:quilted_wool:7,100)
RandomBlock(-8,40,-3,quark:quilted_wool:7,10,quark:quilted_wool:7,100)
RandomBlock(-8,40,-2,quark:quilted_wool:7,10,quark:quilted_wool:7,100)
RandomBlock(-8,40,-1,quark:quilted_wool:7,10,quark:quilted_wool:7,100)
RandomBlock(-8,40,0,quark:quilted_wool:7,10,quark:quilted_wool:7,100)
RandomBlock(-8,40,1,quark:quilted_wool:7,10,quark:quilted_wool:7,100)
RandomBlock(-8,40,2,quark:quilted_wool:7,10,quark:quilted_wool:7,100)
RandomBlock(-8,40,3,quark:quilted_wool:7,10,quark:quilted_wool:7,100)
RandomBlock(-8,41,-2,quark:quilted_wool:7,10,quark:quilted_wool:7,100)
RandomBlock(-8,41,-1,quark:quilted_wool:7,10,quark:quilted_wool:7,100)
RandomBlock(-8,41,0,quark:quilted_wool:7,10,quark:quilted_wool:7,100)
RandomBlock(-8,41,1,quark:quilted_wool:7,10,quark:quilted_wool:7,100)
RandomBlock(-8,41,2,quark:quilted_wool:7,10,quark:quilted_wool:7,100)
RandomBlock(-8,42,-1,quark:quilted_wool:7,10,quark:quilted_wool:7,100)
RandomBlock(-8,42,0,quark:quilted_wool:7,10,quark:quilted_wool:7,100)
RandomBlock(-8,42,1,quark:quilted_wool:7,10,quark:quilted_wool:7,100)
Block(-8,44,3,VINE:1)
Block(-8,45,3,VINE:1)
Block(-8,46,3,VINE:1)
Block(-8,47,-4,VINE:4)
Block(-8,47,3,VINE:1)
Block(-8,48,-7,LEAVES:0)
Block(-8,48,-4,VINE:4)
Block(-8,48,3,VINE:1)
Block(-8,49,-7,LOG:12)
Block(-8,49,-6,LOG:12)
Block(-8,49,-5,LOG:12)
Block(-8,49,-4,VINE:4)
Block(-8,49,3,VINE:1)
Block(-8,50,-7,LOG:12)
Block(-8,50,-6,LOG:12)
Block(-8,50,-5,LOG:12)
Block(-8,50,-4,LOG:12)
Block(-8,50,-3,LOG:12)
Block(-8,50,3,VINE:1)
Block(-8,50,5,VINE:4)
Block(-8,51,-6,LOG:12)
Block(-8,51,-5,LOG:12)
Block(-8,51,-4,VINE:4)
Block(-8,51,3,VINE:1)
Block(-8,51,5,VINE:4)
Block(-8,52,-7,LEAVES:0)
Block(-8,52,-6,LOG:12)
Block(-8,52,-5,LOG:12)
Block(-8,52,-4,LEAVES:0)
Block(-8,52,3,VINE:1)
Block(-8,52,5,VINE:4)
Block(-8,53,-7,LEAVES:0)
Block(-8,53,-6,LOG:12)
Block(-8,53,-5,LOG:12)
Block(-8,53,-4,LEAVES:0)
Block(-8,53,-3,LEAVES:0)
Block(-8,53,3,VINE:1)
Block(-8,53,5,VINE:4)
Block(-8,54,-7,LEAVES:0)
Block(-8,54,-6,LOG:12)
Block(-8,54,-5,LOG:12)
Block(-8,54,-4,LEAVES:0)
Block(-8,54,-3,LEAVES:0)
Block(-8,54,-2,LEAVES:0)
Block(-8,54,-1,LEAVES:0)
Block(-8,54,3,VINE:1)
Block(-8,54,5,VINE:4)
Block(-8,55,-7,LEAVES:0)
Block(-8,55,-6,LEAVES:0)
Block(-8,55,-5,LOG:12)
Block(-8,55,-4,LEAVES:0)
Block(-8,55,-3,LEAVES:0)
Block(-8,55,-2,LEAVES:0)
Block(-8,55,-1,LEAVES:0)
Block(-8,55,0,LEAVES:0)
Block(-8,55,3,VINE:1)
Block(-8,55,5,VINE:4)
Block(-8,56,-6,LEAVES:0)
Block(-8,56,-5,LEAVES:0)
Block(-8,56,-4,LEAVES:0)
Block(-8,56,3,VINE:1)
Block(-8,56,5,VINE:4)
Block(-8,57,-6,LEAVES:0)
Block(-8,57,-5,LEAVES:0)
Block(-8,57,-4,LEAVES:0)
Block(-8,57,-3,LEAVES:0)
Block(-8,57,-2,LEAVES:0)
Block(-8,57,3,VINE:1)
Block(-8,57,5,VINE:4)
Block(-8,58,-6,LEAVES:0)
Block(-8,58,-5,LEAVES:0)
Block(-8,58,-4,LEAVES:0)
Block(-8,58,-3,LEAVES:0)
Block(-8,58,-2,LEAVES:0)
Block(-8,58,-1,LEAVES:0)
Block(-8,58,0,LEAVES:0)
Block(-8,58,1,LEAVES:0)
Block(-8,58,3,VINE:1)
Block(-8,58,5,VINE:4)
Block(-8,59,-7,WOOD_STEP:8)
Block(-8,59,-6,WOOD_STEP:8)
Block(-8,59,-5,WOOD_STEP:8)
Block(-8,59,-4,WOOD_STEP:8)
Block(-8,59,-3,WOOD_STEP:8)
Block(-8,59,-2,WOOD_STEP:8)
Block(-8,59,-1,LEAVES:0)
Block(-8,59,0,LEAVES:0)
Block(-8,59,3,VINE:1)
Block(-8,59,5,VINE:4)
Block(-8,60,-7,FENCE:0)
Block(-8,60,-6,FENCE:0)
Block(-8,60,-2,FENCE:0)
Block(-8,60,-1,VINE:4)
Block(-8,60,3,VINE:1)
Block(-8,60,5,VINE:4)
Block(-8,61,-7,FENCE:0)
Block(-8,61,-6,FENCE:0)
Block(-8,61,-2,FENCE:0)
Block(-8,61,-1,VINE:4)
Block(-8,61,3,VINE:1)
Block(-8,61,5,VINE:4)
Block(-8,62,-1,VINE:4)
Block(-8,62,3,VINE:1)
Block(-8,62,5,VINE:4)
Block(-8,63,-7,LEAVES:0)
Block(-8,63,-6,LEAVES:0)
Block(-8,63,-5,LEAVES:0)
Block(-8,63,-4,LEAVES:0)
Block(-8,63,-1,VINE:4)
Block(-8,63,3,VINE:1)
Block(-8,63,5,VINE:4)
Block(-8,64,-6,LEAVES:0)
Block(-8,64,-5,LEAVES:0)
Block(-8,64,-4,LEAVES:0)
Block(-8,64,-3,LEAVES:0)
Block(-8,64,-1,VINE:4)
Block(-8,64,3,VINE:1)
Block(-8,64,5,VINE:4)
Block(-8,65,-6,LEAVES:0)
Block(-8,65,-5,LEAVES:0)
Block(-8,65,-4,LEAVES:0)
Block(-8,65,-3,LEAVES:0)
Block(-8,65,-2,LEAVES:0)
Block(-8,65,-1,VINE:4)
Block(-8,65,3,VINE:1)
Block(-8,65,5,VINE:4)
Block(-8,66,-6,LEAVES:0)
Block(-8,66,-5,LOG:12)
Block(-8,66,-4,LOG:12)
Block(-8,66,-3,LOG:12)
Block(-8,66,-2,LOG:12)
Block(-8,66,-1,VINE:4)
Block(-8,66,3,VINE:1)
Block(-8,66,5,VINE:4)
Block(-8,67,-5,LOG:12)
Block(-8,67,-4,LOG:12)
Block(-8,67,-3,LOG:12)
Block(-8,67,-2,LOG:12)
Block(-8,67,-1,VINE:4)
Block(-8,67,3,VINE:1)
Block(-8,67,4,LOG:12)
Block(-8,67,5,VINE:4)
Block(-8,68,-4,LEAVES:0)
Block(-8,68,-2,LOG:12)
Block(-8,68,-1,VINE:4)
Block(-8,68,3,VINE:1)
Block(-8,68,4,LOG:12)
Block(-8,68,5,VINE:4)
Block(-8,69,-4,LEAVES:0)
Block(-8,69,-3,LEAVES:0)
Block(-8,69,-2,LOG:12)
Block(-8,69,-1,VINE:4)
Block(-8,69,3,VINE:1)
Block(-8,69,4,LOG:12)
Block(-8,69,5,VINE:4)
Block(-8,70,-4,LEAVES:0)
Block(-8,70,-3,LEAVES:0)
Block(-8,70,-2,LOG:12)
Block(-8,70,-1,VINE:4)
Block(-8,70,2,LEAVES:0)
Block(-8,70,3,LEAVES:0)
Block(-8,70,4,LOG:12)
Block(-8,70,5,LEAVES:0)
Block(-8,70,6,LEAVES:0)
Block(-8,71,-3,VINE:1)
Block(-8,71,-2,LOG:12)
Block(-8,71,-1,VINE:4)
Block(-8,71,2,LEAVES:0)
Block(-8,71,3,LEAVES:0)
Block(-8,71,4,LOG:12)
Block(-8,71,5,LEAVES:0)
Block(-8,71,6,LEAVES:0)
Block(-8,72,-7,LOG:12)
Block(-8,72,-4,LEAVES:0)
Block(-8,72,-3,LEAVES:0)
Block(-8,72,-2,LOG:12)
Block(-8,72,-1,LEAVES:0)
Block(-8,72,0,LEAVES:0)
Block(-8,72,3,LEAVES:0)
Block(-8,72,4,LOG:12)
Block(-8,72,5,LEAVES:0)
Block(-8,73,-7,LOG:12)
Block(-8,73,-6,LEAVES:0)
Block(-8,73,-5,LEAVES:0)
Block(-8,73,-4,LEAVES:0)
Block(-8,73,-3,LEAVES:0)
Block(-8,73,-2,LOG:12)
Block(-8,73,-1,LEAVES:0)
Block(-8,73,0,LEAVES:0)
Block(-8,73,3,LEAVES:0)
Block(-8,73,4,LEAVES:0)
Block(-8,73,5,LEAVES:0)
Block(-8,74,-7,LOG:12)
Block(-8,74,-6,LEAVES:0)
Block(-8,74,-5,LEAVES:0)
Block(-8,74,-4,LEAVES:0)
Block(-8,74,-3,LEAVES:0)
Block(-8,74,-2,LOG:12)
Block(-8,74,-1,LEAVES:0)
Block(-8,74,5,LEAVES:0)
Block(-8,75,-7,LOG:12)
Block(-8,75,-6,LEAVES:0)
Block(-8,75,-5,LEAVES:0)
Block(-8,75,-4,LEAVES:0)
Block(-8,75,-3,LEAVES:0)
Block(-8,75,-2,LEAVES:0)
Block(-8,75,-1,LEAVES:0)
Block(-8,75,4,LEAVES:0)
Block(-8,75,5,LEAVES:0)
Block(-8,75,6,LEAVES:0)
Block(-8,75,7,LEAVES:0)
Block(-8,76,-7,LOG:12)
Block(-8,76,-6,LEAVES:0)
Block(-8,76,-5,LEAVES:0)
Block(-8,76,-4,LEAVES:0)
Block(-8,76,-3,LEAVES:0)
Block(-8,76,-2,LEAVES:12)
Block(-8,76,3,LEAVES:0)
Block(-8,76,4,LEAVES:0)
Block(-8,76,5,LEAVES:0)
Block(-8,76,6,LEAVES:0)
Block(-8,76,7,LEAVES:0)
Block(-8,77,-7,LEAVES:0)
Block(-8,77,-6,LEAVES:0)
Block(-8,77,-5,LEAVES:0)
Block(-8,77,-4,LEAVES:0)
Block(-8,77,-3,LEAVES:0)
Block(-8,77,-2,LEAVES:0)
Block(-8,77,4,LEAVES:0)
Block(-8,77,5,LEAVES:0)
Block(-8,77,6,LEAVES:0)
Block(-8,77,7,LEAVES:0)
Block(-8,77,8,LEAVES:0)
Block(-8,78,-7,LEAVES:0)
Block(-8,78,-6,LEAVES:0)
Block(-8,78,-5,LEAVES:0)
Block(-8,78,-4,LEAVES:0)
Block(-8,78,-2,VINE:8)
Block(-8,78,5,LEAVES:0)
Block(-8,78,6,LEAVES:0)
Block(-8,78,7,LEAVES:0)
Block(-8,78,8,LEAVES:0)
Block(-8,79,-7,LEAVES:0)
Block(-8,79,-6,LEAVES:0)
Block(-8,79,-2,VINE:8)
Block(-8,79,6,LEAVES:0)
Block(-8,80,-7,LEAVES:0)
Block(-8,80,-6,LEAVES:0)
Block(-8,80,-5,LEAVES:0)
Block(-8,80,-4,LEAVES:0)
Block(-8,80,-3,LEAVES:0)
Block(-8,80,-2,LEAVES:0)
Block(-8,80,-1,LEAVES:0)
Block(-8,80,0,LEAVES:0)
Block(-8,81,-7,LEAVES:0)
Block(-8,81,-6,LEAVES:0)
Block(-8,81,-5,LEAVES:0)
Block(-8,81,-4,LEAVES:0)
Block(-8,81,-3,LEAVES:0)
Block(-8,81,-2,LEAVES:0)
Block(-8,81,-1,LEAVES:0)
Block(-8,81,0,LEAVES:0)
Block(-8,81,3,LEAVES:0)
Block(-8,81,4,LEAVES:0)
Block(-8,81,5,LEAVES:0)
Block(-8,82,-7,LEAVES:0)
Block(-8,82,-6,LEAVES:0)
Block(-8,82,-4,LEAVES:0)
Block(-8,82,-3,LEAVES:0)
Block(-8,82,-2,LEAVES:0)
Block(-8,82,-1,LEAVES:0)
Block(-8,82,4,LEAVES:0)
Block(-8,83,-7,LEAVES:0)
Block(-8,83,-4,LEAVES:0)
Block(-8,83,-3,LEAVES:0)
Block(-8,83,-2,LEAVES:0)
RandomBlock(-8,87,7,quark:quilted_wool:7,10,quark:quilted_wool:7,100)
RandomBlock(-8,88,-4,quark:quilted_wool:0,10,quark:quilted_wool:0,100)
RandomBlock(-8,88,-3,quark:quilted_wool:0,10,quark:quilted_wool:0,100)
RandomBlock(-8,88,-2,quark:quilted_wool:0,10,quark:quilted_wool:0,100)
RandomBlock(-8,88,5,quark:quilted_wool:7,10,quark:quilted_wool:7,100)
RandomBlock(-8,88,6,quark:quilted_wool:7,10,quark:quilted_wool:7,100)
RandomBlock(-8,88,7,quark:quilted_wool:7,10,quark:quilted_wool:7,100)
RandomBlock(-8,88,8,quark:quilted_wool:7,10,quark:quilted_wool:7,100)
RandomBlock(-8,89,-5,quark:quilted_wool:0,10,quark:quilted_wool:0,100)
RandomBlock(-8,89,-4,quark:quilted_wool:0,10,quark:quilted_wool:0,100)
RandomBlock(-8,89,-3,quark:quilted_wool:0,10,quark:quilted_wool:0,100)
RandomBlock(-8,89,-2,quark:quilted_wool:0,10,quark:quilted_wool:0,100)
RandomBlock(-8,89,-1,quark:quilted_wool:0,10,quark:quilted_wool:0,100)
RandomBlock(-8,89,4,quark:quilted_wool:7,10,quark:quilted_wool:7,100)
RandomBlock(-8,89,5,quark:quilted_wool:7,10,quark:quilted_wool:7,100)
RandomBlock(-8,89,6,quark:quilted_wool:7,10,quark:quilted_wool:7,100)
RandomBlock(-8,89,7,quark:quilted_wool:7,10,quark:quilted_wool:7,100)
RandomBlock(-8,89,8,quark:quilted_wool:7,10,quark:quilted_wool:7,100)
RandomBlock(-8,90,-6,quark:quilted_wool:0,10,quark:quilted_wool:0,100)
RandomBlock(-8,90,-5,quark:quilted_wool:0,10,quark:quilted_wool:0,100)
RandomBlock(-8,90,-4,quark:quilted_wool:0,10,quark:quilted_wool:0,100)
RandomBlock(-8,90,-3,quark:quilted_wool:0,10,quark:quilted_wool:0,100)
RandomBlock(-8,90,-2,quark:quilted_wool:0,10,quark:quilted_wool:0,100)
RandomBlock(-8,90,-1,quark:quilted_wool:0,10,quark:quilted_wool:0,100)
RandomBlock(-8,90,0,quark:quilted_wool:0,10,quark:quilted_wool:0,100)
RandomBlock(-8,90,4,quark:quilted_wool:7,10,quark:quilted_wool:7,100)
RandomBlock(-8,90,5,quark:quilted_wool:7,10,quark:quilted_wool:7,100)
RandomBlock(-8,90,6,quark:quilted_wool:7,10,quark:quilted_wool:7,100)
RandomBlock(-8,90,7,quark:quilted_wool:7,10,quark:quilted_wool:7,100)
RandomBlock(-8,90,8,quark:quilted_wool:7,10,quark:quilted_wool:7,100)
RandomBlock(-8,91,-6,quark:quilted_wool:0,10,quark:quilted_wool:0,100)
RandomBlock(-8,91,-5,quark:quilted_wool:0,10,quark:quilted_wool:0,100)
RandomBlock(-8,91,-4,quark:quilted_wool:0,10,quark:quilted_wool:0,100)
RandomBlock(-8,91,-3,quark:quilted_wool:0,10,quark:quilted_wool:0,100)
RandomBlock(-8,91,-2,quark:quilted_wool:0,10,quark:quilted_wool:0,100)
RandomBlock(-8,91,-1,quark:quilted_wool:0,10,quark:quilted_wool:0,100)
RandomBlock(-8,91,0,quark:quilted_wool:0,10,quark:quilted_wool:0,100)
RandomBlock(-8,91,4,quark:quilted_wool:7,10,quark:quilted_wool:7,100)
RandomBlock(-8,91,5,quark:quilted_wool:7,10,quark:quilted_wool:7,100)
RandomBlock(-8,91,6,quark:quilted_wool:7,10,quark:quilted_wool:7,100)
RandomBlock(-8,91,7,quark:quilted_wool:7,10,quark:quilted_wool:7,100)
RandomBlock(-8,91,8,quark:quilted_wool:7,10,quark:quilted_wool:7,100)
RandomBlock(-8,92,-7,quark:quilted_wool:0,10,quark:quilted_wool:0,100)
RandomBlock(-8,92,-6,quark:quilted_wool:0,10,quark:quilted_wool:0,100)
RandomBlock(-8,92,-5,quark:quilted_wool:0,10,quark:quilted_wool:0,100)
RandomBlock(-8,92,-4,quark:quilted_wool:0,10,quark:quilted_wool:0,100)
RandomBlock(-8,92,-3,quark:quilted_wool:0,10,quark:quilted_wool:0,100)
RandomBlock(-8,92,-2,quark:quilted_wool:0,10,quark:quilted_wool:0,100)
RandomBlock(-8,92,-1,quark:quilted_wool:0,10,quark:quilted_wool:0,100)
RandomBlock(-8,92,0,quark:quilted_wool:0,10,quark:quilted_wool:0,100)
RandomBlock(-8,92,1,quark:quilted_wool:0,10,quark:quilted_wool:0,100)
RandomBlock(-8,92,4,quark:quilted_wool:7,10,quark:quilted_wool:7,100)
RandomBlock(-8,92,5,quark:quilted_wool:7,10,quark:quilted_wool:7,100)
RandomBlock(-8,92,6,quark:quilted_wool:7,10,quark:quilted_wool:7,100)
RandomBlock(-8,92,7,quark:quilted_wool:7,10,quark:quilted_wool:7,100)
RandomBlock(-8,92,8,quark:quilted_wool:7,10,quark:quilted_wool:7,100)
RandomBlock(-8,93,-7,quark:quilted_wool:0,10,quark:quilted_wool:0,100)
RandomBlock(-8,93,-6,quark:quilted_wool:0,10,quark:quilted_wool:0,100)
RandomBlock(-8,93,-5,quark:quilted_wool:0,10,quark:quilted_wool:0,100)
RandomBlock(-8,93,-4,quark:quilted_wool:0,10,quark:quilted_wool:0,100)
RandomBlock(-8,93,-3,quark:quilted_wool:0,10,quark:quilted_wool:0,100)
RandomBlock(-8,93,-2,quark:quilted_wool:0,10,quark:quilted_wool:0,100)
RandomBlock(-8,93,-1,quark:quilted_wool:0,10,quark:quilted_wool:0,100)
RandomBlock(-8,93,0,quark:quilted_wool:0,10,quark:quilted_wool:0,100)
RandomBlock(-8,93,1,quark:quilted_wool:0,10,quark:quilted_wool:0,100)
RandomBlock(-8,93,4,quark:quilted_wool:7,10,quark:quilted_wool:7,100)
RandomBlock(-8,93,5,quark:quilted_wool:7,10,quark:quilted_wool:7,100)
RandomBlock(-8,93,6,quark:quilted_wool:7,10,quark:quilted_wool:7,100)
RandomBlock(-8,93,7,quark:quilted_wool:7,10,quark:quilted_wool:7,100)
RandomBlock(-8,93,8,quark:quilted_wool:7,10,quark:quilted_wool:7,100)
RandomBlock(-8,94,-7,quark:quilted_wool:0,10,quark:quilted_wool:0,100)
RandomBlock(-8,94,-6,quark:quilted_wool:0,10,quark:quilted_wool:0,100)
RandomBlock(-8,94,-5,quark:quilted_wool:0,10,quark:quilted_wool:0,100)
RandomBlock(-8,94,-4,quark:quilted_wool:0,10,quark:quilted_wool:0,100)
RandomBlock(-8,94,-3,quark:quilted_wool:0,10,quark:quilted_wool:0,100)
RandomBlock(-8,94,-2,quark:quilted_wool:0,10,quark:quilted_wool:0,100)
RandomBlock(-8,94,-1,quark:quilted_wool:0,10,quark:quilted_wool:0,100)
RandomBlock(-8,94,0,quark:quilted_wool:0,10,quark:quilted_wool:0,100)
RandomBlock(-8,94,1,quark:quilted_wool:0,10,quark:quilted_wool:0,100)
RandomBlock(-8,94,4,quark:quilted_wool:7,10,quark:quilted_wool:7,100)
RandomBlock(-8,94,5,quark:quilted_wool:7,10,quark:quilted_wool:7,100)
RandomBlock(-8,94,6,quark:quilted_wool:7,10,quark:quilted_wool:7,100)
RandomBlock(-8,94,7,quark:quilted_wool:7,10,quark:quilted_wool:7,100)
RandomBlock(-8,94,8,quark:quilted_wool:7,10,quark:quilted_wool:7,100)
RandomBlock(-8,95,-7,quark:quilted_wool:0,10,quark:quilted_wool:0,100)
RandomBlock(-8,95,-6,quark:quilted_wool:0,10,quark:quilted_wool:0,100)
RandomBlock(-8,95,-5,quark:quilted_wool:0,10,quark:quilted_wool:0,100)
RandomBlock(-8,95,-4,quark:quilted_wool:0,10,quark:quilted_wool:0,100)
RandomBlock(-8,95,-3,quark:quilted_wool:0,10,quark:quilted_wool:0,100)
RandomBlock(-8,95,-2,quark:quilted_wool:0,10,quark:quilted_wool:0,100)
RandomBlock(-8,95,-1,quark:quilted_wool:0,10,quark:quilted_wool:0,100)
RandomBlock(-8,95,0,quark:quilted_wool:0,10,quark:quilted_wool:0,100)
RandomBlock(-8,95,1,quark:quilted_wool:0,10,quark:quilted_wool:0,100)
RandomBlock(-8,95,2,quark:quilted_wool:0,10,quark:quilted_wool:0,100)
RandomBlock(-8,95,4,quark:quilted_wool:7,10,quark:quilted_wool:7,100)
RandomBlock(-8,95,5,quark:quilted_wool:7,10,quark:quilted_wool:7,100)
RandomBlock(-8,95,6,quark:quilted_wool:7,10,quark:quilted_wool:7,100)
RandomBlock(-8,95,7,quark:quilted_wool:7,10,quark:quilted_wool:7,100)
RandomBlock(-8,95,8,quark:quilted_wool:7,10,quark:quilted_wool:7,100)
RandomBlock(-8,96,-7,quark:quilted_wool:0,10,quark:quilted_wool:0,100)
RandomBlock(-8,96,-6,quark:quilted_wool:0,10,quark:quilted_wool:0,100)
RandomBlock(-8,96,-5,quark:quilted_wool:0,10,quark:quilted_wool:0,100)
RandomBlock(-8,96,-4,quark:quilted_wool:0,10,quark:quilted_wool:0,100)
RandomBlock(-8,96,-3,quark:quilted_wool:0,10,quark:quilted_wool:0,100)
RandomBlock(-8,96,-2,quark:quilted_wool:0,10,quark:quilted_wool:0,100)
RandomBlock(-8,96,-1,quark:quilted_wool:0,10,quark:quilted_wool:0,100)
RandomBlock(-8,96,0,quark:quilted_wool:0,10,quark:quilted_wool:0,100)
RandomBlock(-8,96,1,quark:quilted_wool:0,10,quark:quilted_wool:0,100)
RandomBlock(-8,96,2,quark:quilted_wool:0,10,quark:quilted_wool:0,100)
RandomBlock(-8,96,5,quark:quilted_wool:7,10,quark:quilted_wool:7,100)
RandomBlock(-8,96,6,quark:quilted_wool:7,10,quark:quilted_wool:7,100)
RandomBlock(-8,96,7,quark:quilted_wool:7,10,quark:quilted_wool:7,100)
RandomBlock(-8,96,8,quark:quilted_wool:7,10,quark:quilted_wool:7,100)
RandomBlock(-8,97,-7,quark:quilted_wool:0,10,quark:quilted_wool:0,100)
RandomBlock(-8,97,-6,quark:quilted_wool:0,10,quark:quilted_wool:0,100)
RandomBlock(-8,97,-5,quark:quilted_wool:0,10,quark:quilted_wool:0,100)
RandomBlock(-8,97,-4,quark:quilted_wool:0,10,quark:quilted_wool:0,100)
RandomBlock(-8,97,-3,quark:quilted_wool:0,10,quark:quilted_wool:0,100)
RandomBlock(-8,97,-2,quark:quilted_wool:0,10,quark:quilted_wool:0,100)
RandomBlock(-8,97,-1,quark:quilted_wool:0,10,quark:quilted_wool:0,100)
RandomBlock(-8,97,0,quark:quilted_wool:0,10,quark:quilted_wool:0,100)
RandomBlock(-8,97,1,quark:quilted_wool:0,10,quark:quilted_wool:0,100)
RandomBlock(-8,97,2,quark:quilted_wool:0,10,quark:quilted_wool:0,100)
RandomBlock(-8,97,7,quark:quilted_wool:7,10,quark:quilted_wool:7,100)
RandomBlock(-8,98,-7,quark:quilted_wool:0,10,quark:quilted_wool:0,100)
RandomBlock(-8,98,-6,quark:quilted_wool:0,10,quark:quilted_wool:0,100)
RandomBlock(-8,98,-5,quark:quilted_wool:0,10,quark:quilted_wool:0,100)
RandomBlock(-8,98,-4,quark:quilted_wool:0,10,quark:quilted_wool:0,100)
RandomBlock(-8,98,-3,quark:quilted_wool:0,10,quark:quilted_wool:0,100)
RandomBlock(-8,98,-2,quark:quilted_wool:0,10,quark:quilted_wool:0,100)
RandomBlock(-8,98,-1,quark:quilted_wool:0,10,quark:quilted_wool:0,100)
RandomBlock(-8,98,0,quark:quilted_wool:0,10,quark:quilted_wool:0,100)
RandomBlock(-8,98,1,quark:quilted_wool:0,10,quark:quilted_wool:0,100)
RandomBlock(-8,98,2,quark:quilted_wool:0,10,quark:quilted_wool:0,100)
RandomBlock(-8,99,-7,quark:quilted_wool:0,10,quark:quilted_wool:0,100)
RandomBlock(-8,99,-6,quark:quilted_wool:0,10,quark:quilted_wool:0,100)
RandomBlock(-8,99,-5,quark:quilted_wool:0,10,quark:quilted_wool:0,100)
RandomBlock(-8,99,-4,quark:quilted_wool:0,10,quark:quilted_wool:0,100)
RandomBlock(-8,99,-3,quark:quilted_wool:0,10,quark:quilted_wool:0,100)
RandomBlock(-8,99,-2,quark:quilted_wool:0,10,quark:quilted_wool:0,100)
RandomBlock(-8,99,-1,quark:quilted_wool:0,10,quark:quilted_wool:0,100)
RandomBlock(-8,99,0,quark:quilted_wool:0,10,quark:quilted_wool:0,100)
RandomBlock(-8,99,1,quark:quilted_wool:0,10,quark:quilted_wool:0,100)
RandomBlock(-8,99,2,quark:quilted_wool:0,10,quark:quilted_wool:0,100)
RandomBlock(-8,100,-7,quark:quilted_wool:0,10,quark:quilted_wool:0,100)
RandomBlock(-8,100,-6,quark:quilted_wool:0,10,quark:quilted_wool:0,100)
RandomBlock(-8,100,-5,quark:quilted_wool:0,10,quark:quilted_wool:0,100)
RandomBlock(-8,100,-4,quark:quilted_wool:0,10,quark:quilted_wool:0,100)
RandomBlock(-8,100,-3,quark:quilted_wool:0,10,quark:quilted_wool:0,100)
RandomBlock(-8,100,-2,quark:quilted_wool:0,10,quark:quilted_wool:0,100)
RandomBlock(-8,100,-1,quark:quilted_wool:0,10,quark:quilted_wool:0,100)
RandomBlock(-8,100,0,quark:quilted_wool:0,10,quark:quilted_wool:0,100)
RandomBlock(-8,100,1,quark:quilted_wool:0,10,quark:quilted_wool:0,100)
RandomBlock(-8,100,2,quark:quilted_wool:0,10,quark:quilted_wool:0,100)
RandomBlock(-8,101,-7,quark:quilted_wool:0,10,quark:quilted_wool:0,100)
RandomBlock(-8,101,-6,quark:quilted_wool:0,10,quark:quilted_wool:0,100)
RandomBlock(-8,101,-5,quark:quilted_wool:0,10,quark:quilted_wool:0,100)
RandomBlock(-8,101,-4,quark:quilted_wool:0,10,quark:quilted_wool:0,100)
RandomBlock(-8,101,-3,quark:quilted_wool:0,10,quark:quilted_wool:0,100)
RandomBlock(-8,101,-2,quark:quilted_wool:0,10,quark:quilted_wool:0,100)
RandomBlock(-8,101,-1,quark:quilted_wool:0,10,quark:quilted_wool:0,100)
RandomBlock(-8,101,0,quark:quilted_wool:0,10,quark:quilted_wool:0,100)
RandomBlock(-8,101,1,quark:quilted_wool:0,10,quark:quilted_wool:0,100)
RandomBlock(-8,101,2,quark:quilted_wool:0,10,quark:quilted_wool:0,100)
RandomBlock(-8,102,-7,quark:quilted_wool:0,10,quark:quilted_wool:0,100)
RandomBlock(-8,102,-6,quark:quilted_wool:0,10,quark:quilted_wool:0,100)
RandomBlock(-8,102,-5,quark:quilted_wool:0,10,quark:quilted_wool:0,100)
RandomBlock(-8,102,-4,quark:quilted_wool:0,10,quark:quilted_wool:0,100)
RandomBlock(-8,102,-3,quark:quilted_wool:0,10,quark:quilted_wool:0,100)
RandomBlock(-8,102,-2,quark:quilted_wool:0,10,quark:quilted_wool:0,100)
RandomBlock(-8,102,-1,quark:quilted_wool:0,10,quark:quilted_wool:0,100)
RandomBlock(-8,102,0,quark:quilted_wool:0,10,quark:quilted_wool:0,100)
RandomBlock(-8,102,1,quark:quilted_wool:0,10,quark:quilted_wool:0,100)
RandomBlock(-8,103,-7,quark:quilted_wool:0,10,quark:quilted_wool:0,100)
RandomBlock(-8,103,-6,quark:quilted_wool:0,10,quark:quilted_wool:0,100)
RandomBlock(-8,103,-5,quark:quilted_wool:0,10,quark:quilted_wool:0,100)
RandomBlock(-8,103,-4,quark:quilted_wool:0,10,quark:quilted_wool:0,100)
RandomBlock(-8,103,-3,quark:quilted_wool:0,10,quark:quilted_wool:0,100)
RandomBlock(-8,103,-2,quark:quilted_wool:0,10,quark:quilted_wool:0,100)
RandomBlock(-8,103,-1,quark:quilted_wool:0,10,quark:quilted_wool:0,100)
RandomBlock(-8,103,0,quark:quilted_wool:0,10,quark:quilted_wool:0,100)
RandomBlock(-8,103,1,quark:quilted_wool:0,10,quark:quilted_wool:0,100)
RandomBlock(-8,104,-7,quark:quilted_wool:0,10,quark:quilted_wool:0,100)
RandomBlock(-8,104,-6,quark:quilted_wool:0,10,quark:quilted_wool:0,100)
RandomBlock(-8,104,-5,quark:quilted_wool:0,10,quark:quilted_wool:0,100)
RandomBlock(-8,104,-4,quark:quilted_wool:0,10,quark:quilted_wool:0,100)
RandomBlock(-8,104,-3,quark:quilted_wool:0,10,quark:quilted_wool:0,100)
RandomBlock(-8,104,-2,quark:quilted_wool:0,10,quark:quilted_wool:0,100)
RandomBlock(-8,104,-1,quark:quilted_wool:0,10,quark:quilted_wool:0,100)
RandomBlock(-8,104,0,quark:quilted_wool:0,10,quark:quilted_wool:0,100)
RandomBlock(-8,104,1,quark:quilted_wool:0,10,quark:quilted_wool:0,100)
RandomBlock(-8,105,-6,quark:quilted_wool:0,10,quark:quilted_wool:0,100)
RandomBlock(-8,105,-5,quark:quilted_wool:0,10,quark:quilted_wool:0,100)
RandomBlock(-8,105,-4,quark:quilted_wool:0,10,quark:quilted_wool:0,100)
RandomBlock(-8,105,-3,quark:quilted_wool:0,10,quark:quilted_wool:0,100)
RandomBlock(-8,105,-2,quark:quilted_wool:0,10,quark:quilted_wool:0,100)
RandomBlock(-8,105,-1,quark:quilted_wool:0,10,quark:quilted_wool:0,100)
RandomBlock(-8,105,0,quark:quilted_wool:0,10,quark:quilted_wool:0,100)
RandomBlock(-8,106,-6,quark:quilted_wool:0,10,quark:quilted_wool:0,100)
RandomBlock(-8,106,-5,quark:quilted_wool:0,10,quark:quilted_wool:0,100)
RandomBlock(-8,106,-4,quark:quilted_wool:0,10,quark:quilted_wool:0,100)
RandomBlock(-8,106,-3,quark:quilted_wool:0,10,quark:quilted_wool:0,100)
RandomBlock(-8,106,-2,quark:quilted_wool:0,10,quark:quilted_wool:0,100)
RandomBlock(-8,106,-1,quark:quilted_wool:0,10,quark:quilted_wool:0,100)
RandomBlock(-8,106,0,quark:quilted_wool:0,10,quark:quilted_wool:0,100)
RandomBlock(-8,107,-5,quark:quilted_wool:0,10,quark:quilted_wool:0,100)
RandomBlock(-8,107,-4,quark:quilted_wool:0,10,quark:quilted_wool:0,100)
RandomBlock(-8,107,-3,quark:quilted_wool:0,10,quark:quilted_wool:0,100)
RandomBlock(-8,107,-2,quark:quilted_wool:0,10,quark:quilted_wool:0,100)
RandomBlock(-8,107,-1,quark:quilted_wool:0,10,quark:quilted_wool:0,100)
RandomBlock(-8,108,-4,quark:quilted_wool:0,10,quark:quilted_wool:0,100)
RandomBlock(-8,108,-3,quark:quilted_wool:0,10,quark:quilted_wool:0,100)
RandomBlock(-8,108,-2,quark:quilted_wool:0,10,quark:quilted_wool:0,100)
Block(-7,6,2,LOG:12)
Block(-7,7,-5,LOG:12)
Block(-7,7,1,LOG:12)
Block(-7,7,2,LOG:12)
Block(-7,7,3,LOG:12)
Block(-7,8,-6,LOG:12)
Block(-7,8,-5,LOG:12)
Block(-7,8,-4,LOG:12)
Block(-7,8,0,LOG:12)
Block(-7,8,1,LOG:12)
Block(-7,8,2,LOG:12)
Block(-7,9,-7,LOG:12)
Block(-7,9,-6,LOG:12)
Block(-7,9,-5,LOG:12)
Block(-7,9,-1,LOG:12)
Block(-7,9,0,LOG:12)
Block(-7,9,1,LOG:12)
Block(-7,9,2,LOG:12)
Block(-7,10,-7,LOG:12)
Block(-7,10,-6,LOG:12)
Block(-7,10,-5,LOG:12)
Block(-7,10,-1,LOG:12)
Block(-7,10,0,LOG:12)
Block(-7,10,1,LOG:12)
Block(-7,10,2,LOG:12)
Block(-7,11,-7,LOG:12)
Block(-7,11,-6,LOG:12)
Block(-7,11,-5,LOG:12)
Block(-7,11,-1,LOG:12)
Block(-7,11,0,LOG:12)
Block(-7,11,1,LOG:12)
Block(-7,11,2,quark:leaf_carpet)
Block(-7,12,-7,LOG:12)
Block(-7,12,-6,LOG:12)
Block(-7,12,0,LOG:12)
Block(-7,12,1,quark:leaf_carpet)
Block(-7,13,-7,LOG:12)
Block(-7,13,-6,quark:leaf_carpet)
Block(-7,13,0,quark:leaf_carpet)
Block(-7,14,-7,LOG:12)
Block(-7,15,-7,quark:leaf_carpet)
Block(-7,15,-1,LOG:12)
Block(-7,16,-2,LOG:12)
Block(-7,16,-1,LOG:12)
Block(-7,16,0,LOG:12)
Block(-7,17,-7,LEAVES:0)
Block(-7,17,-3,LOG:12)
Block(-7,17,-2,LOG:12)
Block(-7,17,-1,LOG:12)
Block(-7,17,0,inspirations:rope:1)
Block(-7,18,-7,LEAVES:0)
Block(-7,18,-4,LOG:12)
Block(-7,18,-3,LOG:12)
Block(-7,18,-2,LOG:12)
Block(-7,18,-1,LOG:12)
Block(-7,18,0,inspirations:rope:1)
Block(-7,19,-5,LOG:12)
Block(-7,19,-4,LOG:12)
Block(-7,19,-3,LOG:12)
Block(-7,19,-2,LOG:12)
Block(-7,19,-1,LOG:12)
Block(-7,19,0,inspirations:rope:1)
Block(-7,20,-5,LOG:12)
Block(-7,20,-4,LOG:12)
Block(-7,20,-3,LOG:12)
Block(-7,20,-2,LOG:12)
Block(-7,20,0,inspirations:rope:1)
Block(-7,21,-7,LOG:12)
Block(-7,21,-5,LOG:12)
Block(-7,21,-4,LOG:12)
Block(-7,21,-3,LOG:12)
Block(-7,21,-2,quark:leaf_carpet)
Block(-7,21,0,inspirations:rope:1)
Block(-7,22,-7,LOG:12)
Block(-7,22,-5,LOG:12)
Block(-7,22,-4,LOG:12)
Block(-7,22,0,inspirations:rope:1)
Block(-7,23,-7,LOG:12)
Block(-7,23,-5,quark:leaf_carpet)
Block(-7,23,-4,quark:leaf_carpet)
Block(-7,23,0,inspirations:rope:1)
Block(-7,24,-7,LOG:12)
Block(-7,24,0,inspirations:rope:1)
Block(-7,25,-7,LOG:12)
Block(-7,25,0,inspirations:rope:1)
Block(-7,26,-7,LOG:12)
Block(-7,26,0,inspirations:rope:1)
Block(-7,27,-5,LOG:12)
Block(-7,27,0,inspirations:rope:1)
Block(-7,28,-6,LOG:12)
Block(-7,28,-5,LOG:12)
Block(-7,28,-4,LOG:12)
Block(-7,28,0,inspirations:rope:1)
Block(-7,29,-7,LOG:12)
Block(-7,29,-6,LOG:12)
Block(-7,29,-5,LOG:12)
Block(-7,29,0,inspirations:rope:1)
Block(-7,30,-7,LOG:12)
Block(-7,30,-6,LOG:12)
Block(-7,30,-5,LOG:12)
Block(-7,30,-4,LOG:12)
Block(-7,30,0,inspirations:rope:1)
Block(-7,31,-7,LOG:12)
Block(-7,31,-5,LOG:12)
Block(-7,31,0,inspirations:rope:1)
Block(-7,32,-7,LOG:12)
Block(-7,32,-5,quark:leaf_carpet)
RandomBlock(-7,32,-1,quark:quilted_wool:7,10,quark:quilted_wool:7,100)
RandomBlock(-7,32,0,quark:quilted_wool:7,10,quark:quilted_wool:7,100)
RandomBlock(-7,32,1,quark:quilted_wool:7,10,quark:quilted_wool:7,100)
Block(-7,33,-7,LOG:12)
RandomBlock(-7,33,-3,quark:quilted_wool:7,10,quark:quilted_wool:7,100)
RandomBlock(-7,33,-2,quark:quilted_wool:7,10,quark:quilted_wool:7,100)
RandomBlock(-7,33,-1,quark:quilted_wool:7,10,quark:quilted_wool:7,100)
RandomBlock(-7,33,0,quark:quilted_wool:7,10,quark:quilted_wool:7,100)
RandomBlock(-7,33,1,quark:quilted_wool:7,10,quark:quilted_wool:7,100)
RandomBlock(-7,33,2,quark:quilted_wool:7,10,quark:quilted_wool:7,100)
RandomBlock(-7,33,3,quark:quilted_wool:7,10,quark:quilted_wool:7,100)
Block(-7,34,-7,LOG:12)
Block(-7,34,-6,LOG:12)
RandomBlock(-7,34,-3,quark:quilted_wool:7,10,quark:quilted_wool:7,100)
RandomBlock(-7,34,-2,quark:quilted_wool:7,10,quark:quilted_wool:7,100)
RandomBlock(-7,34,-1,quark:quilted_wool:7,10,quark:quilted_wool:7,100)
RandomBlock(-7,34,0,quark:quilted_wool:7,10,quark:quilted_wool:7,100)
RandomBlock(-7,34,1,quark:quilted_wool:7,10,quark:quilted_wool:7,100)
RandomBlock(-7,34,2,quark:quilted_wool:7,10,quark:quilted_wool:7,100)
RandomBlock(-7,34,3,quark:quilted_wool:7,10,quark:quilted_wool:7,100)
Block(-7,35,-7,LOG:12)
RandomBlock(-7,35,-4,quark:quilted_wool:7,10,quark:quilted_wool:7,100)
RandomBlock(-7,35,-3,quark:quilted_wool:7,10,quark:quilted_wool:7,100)
RandomBlock(-7,35,-2,quark:quilted_wool:7,10,quark:quilted_wool:7,100)
RandomBlock(-7,35,-1,quark:quilted_wool:7,10,quark:quilted_wool:7,100)
RandomBlock(-7,35,0,quark:quilted_wool:7,10,quark:quilted_wool:7,100)
RandomBlock(-7,35,1,quark:quilted_wool:7,10,quark:quilted_wool:7,100)
RandomBlock(-7,35,2,quark:quilted_wool:7,10,quark:quilted_wool:7,100)
RandomBlock(-7,35,3,quark:quilted_wool:7,10,quark:quilted_wool:7,100)
RandomBlock(-7,35,4,quark:quilted_wool:7,10,quark:quilted_wool:7,100)
RandomBlock(-7,36,-4,quark:quilted_wool:7,10,quark:quilted_wool:7,100)
RandomBlock(-7,36,-3,quark:quilted_wool:7,10,quark:quilted_wool:7,100)
RandomBlock(-7,36,-2,quark:quilted_wool:7,10,quark:quilted_wool:7,100)
RandomBlock(-7,36,-1,quark:quilted_wool:7,10,quark:quilted_wool:7,100)
RandomBlock(-7,36,0,quark:quilted_wool:7,10,quark:quilted_wool:7,100)
RandomBlock(-7,36,1,quark:quilted_wool:7,10,quark:quilted_wool:7,100)
RandomBlock(-7,36,2,quark:quilted_wool:7,10,quark:quilted_wool:7,100)
RandomBlock(-7,36,3,quark:quilted_wool:7,10,quark:quilted_wool:7,100)
RandomBlock(-7,36,4,quark:quilted_wool:7,10,quark:quilted_wool:7,100)
RandomBlock(-7,37,-4,quark:quilted_wool:7,10,quark:quilted_wool:7,100)
RandomBlock(-7,37,-3,quark:quilted_wool:7,10,quark:quilted_wool:7,100)
RandomBlock(-7,37,-2,quark:quilted_wool:7,10,quark:quilted_wool:7,100)
RandomBlock(-7,37,-1,quark:quilted_wool:7,10,quark:quilted_wool:7,100)
RandomBlock(-7,37,0,quark:quilted_wool:7,10,quark:quilted_wool:7,100)
RandomBlock(-7,37,1,quark:quilted_wool:7,10,quark:quilted_wool:7,100)
RandomBlock(-7,37,2,quark:quilted_wool:7,10,quark:quilted_wool:7,100)
RandomBlock(-7,37,3,quark:quilted_wool:7,10,quark:quilted_wool:7,100)
RandomBlock(-7,37,4,quark:quilted_wool:7,10,quark:quilted_wool:7,100)
RandomBlock(-7,38,-4,quark:quilted_wool:7,10,quark:quilted_wool:7,100)
RandomBlock(-7,38,-3,quark:quilted_wool:7,10,quark:quilted_wool:7,100)
RandomBlock(-7,38,-2,quark:quilted_wool:7,10,quark:quilted_wool:7,100)
RandomBlock(-7,38,-1,quark:quilted_wool:7,10,quark:quilted_wool:7,100)
RandomBlock(-7,38,0,quark:quilted_wool:7,10,quark:quilted_wool:7,100)
RandomBlock(-7,38,1,quark:quilted_wool:7,10,quark:quilted_wool:7,100)
RandomBlock(-7,38,2,quark:quilted_wool:7,10,quark:quilted_wool:7,100)
RandomBlock(-7,38,3,quark:quilted_wool:7,10,quark:quilted_wool:7,100)
RandomBlock(-7,38,4,quark:quilted_wool:7,10,quark:quilted_wool:7,100)
RandomBlock(-7,39,-4,quark:quilted_wool:7,10,quark:quilted_wool:7,100)
RandomBlock(-7,39,-3,quark:quilted_wool:7,10,quark:quilted_wool:7,100)
RandomBlock(-7,39,-2,quark:quilted_wool:7,10,quark:quilted_wool:7,100)
RandomBlock(-7,39,-1,quark:quilted_wool:7,10,quark:quilted_wool:7,100)
RandomBlock(-7,39,0,quark:quilted_wool:7,10,quark:quilted_wool:7,100)
RandomBlock(-7,39,1,quark:quilted_wool:7,10,quark:quilted_wool:7,100)
RandomBlock(-7,39,2,quark:quilted_wool:7,10,quark:quilted_wool:7,100)
RandomBlock(-7,39,3,quark:quilted_wool:7,10,quark:quilted_wool:7,100)
RandomBlock(-7,39,4,quark:quilted_wool:7,10,quark:quilted_wool:7,100)
RandomBlock(-7,40,-3,quark:quilted_wool:7,10,quark:quilted_wool:7,100)
RandomBlock(-7,40,-2,quark:quilted_wool:7,10,quark:quilted_wool:7,100)
RandomBlock(-7,40,-1,quark:quilted_wool:7,10,quark:quilted_wool:7,100)
RandomBlock(-7,40,0,quark:quilted_wool:7,10,quark:quilted_wool:7,100)
RandomBlock(-7,40,1,quark:quilted_wool:7,10,quark:quilted_wool:7,100)
RandomBlock(-7,40,2,quark:quilted_wool:7,10,quark:quilted_wool:7,100)
RandomBlock(-7,40,3,quark:quilted_wool:7,10,quark:quilted_wool:7,100)
RandomBlock(-7,41,-3,quark:quilted_wool:7,10,quark:quilted_wool:7,100)
RandomBlock(-7,41,-2,quark:quilted_wool:7,10,quark:quilted_wool:7,100)
RandomBlock(-7,41,-1,quark:quilted_wool:7,10,quark:quilted_wool:7,100)
RandomBlock(-7,41,0,quark:quilted_wool:7,10,quark:quilted_wool:7,100)
RandomBlock(-7,41,1,quark:quilted_wool:7,10,quark:quilted_wool:7,100)
RandomBlock(-7,41,2,quark:quilted_wool:7,10,quark:quilted_wool:7,100)
RandomBlock(-7,41,3,quark:quilted_wool:7,10,quark:quilted_wool:7,100)
RandomBlock(-7,42,-1,quark:quilted_wool:7,10,quark:quilted_wool:7,100)
RandomBlock(-7,42,0,quark:quilted_wool:7,10,quark:quilted_wool:7,100)
RandomBlock(-7,42,1,quark:quilted_wool:7,10,quark:quilted_wool:7,100)
Block(-7,43,-7,LEAVES:0)
Block(-7,44,-7,LEAVES:0)
Block(-7,45,-5,rustic:iron_lantern:0)
Block(-7,46,-7,LEAVES:0)
Block(-7,46,-5,FENCE:0)
Block(-7,47,-5,FENCE:0)
Block(-7,47,-4,VINE:4)
Block(-7,48,-7,LEAVES:0)
Block(-7,48,-5,FENCE:0)
Block(-7,48,-4,VINE:4)
Block(-7,49,-7,LOG:12)
Block(-7,49,-6,LOG:12)
Block(-7,49,-5,LOG:12)
Block(-7,49,-4,VINE:4)
Block(-7,50,-7,LOG:12)
Block(-7,50,-6,LOG:12)
Block(-7,50,-5,LOG:12)
Block(-7,50,-4,VINE:4)
Block(-7,51,-6,LOG:12)
Block(-7,51,-5,LOG:12)
Block(-7,51,-4,VINE:4)
Block(-7,52,-7,LEAVES:0)
Block(-7,52,-6,LOG:12)
Block(-7,52,-5,LOG:12)
Block(-7,52,-4,LEAVES:0)
Block(-7,53,-7,LEAVES:0)
Block(-7,53,-6,LOG:12)
Block(-7,53,-5,LOG:12)
Block(-7,53,-4,LEAVES:0)
Block(-7,53,-3,LEAVES:0)
Block(-7,54,-7,LEAVES:0)
Block(-7,54,-6,LOG:12)
Block(-7,54,-5,LOG:12)
Block(-7,54,-4,LEAVES:0)
Block(-7,54,-3,LEAVES:0)
Block(-7,55,-7,LEAVES:0)
Block(-7,55,-6,LOG:12)
Block(-7,55,-5,LOG:12)
Block(-7,55,-4,LEAVES:0)
Block(-7,55,-3,LEAVES:0)
Block(-7,56,-7,LEAVES:0)
Block(-7,56,-6,LEAVES:0)
Block(-7,56,-5,LOG:12)
Block(-7,56,-4,LEAVES:0)
Block(-7,57,-6,LEAVES:0)
Block(-7,57,-5,LEAVES:0)
Block(-7,57,-4,LEAVES:0)
Block(-7,57,-3,LEAVES:0)
Block(-7,57,-2,LEAVES:0)
Block(-7,58,-6,LEAVES:0)
Block(-7,58,-5,LEAVES:0)
Block(-7,58,-4,LEAVES:0)
Block(-7,58,-3,LEAVES:0)
Block(-7,58,-2,LEAVES:0)
Block(-7,58,-1,LEAVES:0)
Block(-7,58,0,LEAVES:0)
Block(-7,58,1,LEAVES:0)
Block(-7,59,-7,LOG:12)
Block(-7,59,-6,LOG:12)
Block(-7,59,-5,LOG:12)
Block(-7,59,-4,LOG:12)
Block(-7,59,-3,LEAVES:0)
Block(-7,59,-2,LEAVES:0)
Block(-7,59,-1,LEAVES:0)
Block(-7,59,0,LEAVES:0)
Block(-7,59,1,LEAVES:0)
Block(-7,60,-4,LOG:12)
Block(-7,60,-3,WOOD_STEP:0)
Block(-7,60,-2,WOOD_DOUBLE_STEP:0)
Block(-7,60,-1,LEAVES:0)
Block(-7,60,0,LEAVES:0)
Block(-7,61,-4,LOG:12)
Block(-7,61,-1,LEAVES:0)
Block(-7,62,-4,LOG:12)
Block(-7,63,-7,LEAVES:0)
Block(-7,63,-6,LEAVES:0)
Block(-7,63,-5,LEAVES:0)
Block(-7,63,-4,LOG:12)
Block(-7,63,-3,LEAVES:0)
Block(-7,64,-7,LEAVES:0)
Block(-7,64,-6,LEAVES:0)
Block(-7,64,-5,LEAVES:0)
Block(-7,64,-4,LOG:12)
Block(-7,64,-3,LEAVES:0)
Block(-7,64,-2,LEAVES:0)
Block(-7,65,-6,LEAVES:0)
Block(-7,65,-5,LEAVES:0)
Block(-7,65,-4,LOG:12)
Block(-7,65,-3,LEAVES:0)
Block(-7,65,-2,LEAVES:0)
Block(-7,66,-6,LOG:12)
Block(-7,66,-5,LOG:12)
Block(-7,66,-4,LOG:12)
Block(-7,66,-3,LOG:12)
Block(-7,66,-2,LOG:12)
Block(-7,66,4,LOG:12)
Block(-7,67,-6,LOG:12)
Block(-7,67,-5,LOG:12)
Block(-7,67,-4,LOG:12)
Block(-7,67,-3,LOG:12)
Block(-7,67,-2,LOG:12)
Block(-7,67,4,LOG:12)
Block(-7,68,-5,LEAVES:0)
Block(-7,68,-4,LEAVES:0)
Block(-7,68,-3,LEAVES:0)
Block(-7,68,-2,LOG:12)
Block(-7,68,4,VINE:2)
Block(-7,69,-5,LEAVES:0)
Block(-7,69,-4,LEAVES:0)
Block(-7,69,-3,LEAVES:0)
Block(-7,69,-2,LOG:12)
Block(-7,69,-1,LEAVES:0)
Block(-7,69,4,VINE:2)
Block(-7,69,5,VINE:0)
Block(-7,70,-7,rustic:iron_lantern:0)
Block(-7,70,-5,LEAVES:0)
Block(-7,70,-4,LEAVES:0)
Block(-7,70,-3,LEAVES:0)
Block(-7,70,-2,LOG:12)
Block(-7,70,-1,LEAVES:0)
Block(-7,70,2,LEAVES:0)
Block(-7,70,3,LEAVES:0)
Block(-7,70,4,LEAVES:0)
Block(-7,70,5,LEAVES:0)
Block(-7,70,6,LEAVES:0)
Block(-7,71,-7,FENCE:0)
Block(-7,71,-3,LEAVES:0)
Block(-7,71,-2,LOG:12)
Block(-7,71,2,LEAVES:0)
Block(-7,71,3,LEAVES:0)
Block(-7,71,4,LEAVES:0)
Block(-7,71,5,LEAVES:0)
Block(-7,71,6,LEAVES:0)
Block(-7,72,-7,FENCE:0)
Block(-7,72,-6,LOG:12)
Block(-7,72,-4,LEAVES:0)
Block(-7,72,-3,LEAVES:0)
Block(-7,72,-2,LOG:12)
Block(-7,72,-1,LEAVES:0)
Block(-7,72,0,LEAVES:0)
Block(-7,72,4,LEAVES:0)
Block(-7,72,5,LEAVES:0)
Block(-7,73,-7,LEAVES:0)
Block(-7,73,-6,LOG:12)
Block(-7,73,-5,LEAVES:0)
Block(-7,73,-4,LEAVES:0)
Block(-7,73,-3,LEAVES:0)
Block(-7,73,-2,LOG:12)
Block(-7,73,-1,LEAVES:0)
Block(-7,73,0,LEAVES:0)
Block(-7,73,4,LEAVES:0)
Block(-7,74,-7,LEAVES:0)
Block(-7,74,-6,LOG:12)
Block(-7,74,-5,LEAVES:0)
Block(-7,74,-4,LEAVES:0)
Block(-7,74,-3,LEAVES:0)
Block(-7,74,-2,LOG:12)
Block(-7,74,-1,LEAVES:0)
Block(-7,74,4,LEAVES:0)
Block(-7,74,5,LEAVES:0)
Block(-7,74,6,LEAVES:0)
Block(-7,75,-7,LEAVES:0)
Block(-7,75,-6,LOG:12)
Block(-7,75,-5,LEAVES:0)
Block(-7,75,-4,LEAVES:0)
Block(-7,75,-3,LEAVES:0)
Block(-7,75,-2,LEAVES:0)
Block(-7,75,-1,LEAVES:0)
Block(-7,75,3,LEAVES:0)
Block(-7,75,4,LEAVES:0)
Block(-7,75,5,LEAVES:0)
Block(-7,75,6,LEAVES:0)
Block(-7,75,7,LEAVES:0)
Block(-7,76,-7,LEAVES:0)
Block(-7,76,-6,LOG:12)
Block(-7,76,-5,LEAVES:0)
Block(-7,76,-4,LEAVES:0)
Block(-7,76,-3,LEAVES:12)
Block(-7,76,-2,LEAVES:12)
Block(-7,76,-1,LEAVES:12)
Block(-7,76,3,LEAVES:0)
Block(-7,76,4,LEAVES:0)
Block(-7,76,5,LEAVES:0)
Block(-7,76,6,LOG:12)
Block(-7,76,7,LEAVES:0)
Block(-7,77,-7,LEAVES:0)
Block(-7,77,-6,LEAVES:0)
Block(-7,77,-5,LEAVES:0)
Block(-7,77,-4,LEAVES:0)
Block(-7,77,-3,LOG:12)
Block(-7,77,-2,LOG:12)
Block(-7,77,-1,LEAVES:12)
Block(-7,77,4,LEAVES:0)
Block(-7,77,5,LEAVES:0)
Block(-7,77,6,LEAVES:0)
Block(-7,77,7,LEAVES:0)
Block(-7,77,8,LEAVES:0)
Block(-7,78,-7,LEAVES:0)
Block(-7,78,-6,LEAVES:0)
Block(-7,78,-5,LEAVES:0)
Block(-7,78,-4,LEAVES:0)
Block(-7,78,-3,LOG:12)
Block(-7,78,-2,LOG:12)
Block(-7,78,-1,VINE:4)
Block(-7,78,4,LEAVES:0)
Block(-7,78,5,LEAVES:0)
Block(-7,78,6,LEAVES:0)
Block(-7,78,7,LEAVES:0)
Block(-7,78,8,LEAVES:0)
Block(-7,79,-7,LEAVES:0)
Block(-7,79,-6,LEAVES:0)
Block(-7,79,-5,LEAVES:0)
Block(-7,79,-4,LEAVES:0)
Block(-7,79,-3,LOG:12)
Block(-7,79,-2,LOG:12)
Block(-7,79,-1,VINE:4)
Block(-7,79,5,LEAVES:0)
Block(-7,79,6,LEAVES:0)
Block(-7,79,7,LEAVES:0)
Block(-7,80,-7,LEAVES:0)
Block(-7,80,-6,LEAVES:0)
Block(-7,80,-5,LEAVES:0)
Block(-7,80,-4,LEAVES:0)
Block(-7,80,-3,LOG:12)
Block(-7,80,-2,LOG:12)
Block(-7,80,-1,LEAVES:0)
Block(-7,80,0,LEAVES:0)
Block(-7,80,4,LEAVES:0)
Block(-7,81,-7,LEAVES:0)
Block(-7,81,-5,LEAVES:0)
Block(-7,81,-4,LEAVES:0)
Block(-7,81,-3,LOG:12)
Block(-7,81,-2,LOG:12)
Block(-7,81,-1,LEAVES:0)
Block(-7,81,0,LEAVES:0)
Block(-7,81,2,LEAVES:0)
Block(-7,81,3,LEAVES:0)
Block(-7,81,4,LEAVES:0)
Block(-7,81,5,LEAVES:0)
Block(-7,81,6,LEAVES:0)
Block(-7,81,7,LEAVES:0)
Block(-7,82,-7,LEAVES:0)
Block(-7,82,-6,LEAVES:0)
Block(-7,82,-5,LEAVES:0)
Block(-7,82,-4,LEAVES:0)
Block(-7,82,-3,LOG:12)
Block(-7,82,-2,LOG:12)
Block(-7,82,-1,LEAVES:0)
Block(-7,82,3,LEAVES:0)
Block(-7,82,4,LEAVES:0)
Block(-7,82,5,LEAVES:0)
Block(-7,82,6,LEAVES:0)
Block(-7,83,-7,LEAVES:0)
Block(-7,83,-6,LEAVES:0)
Block(-7,83,-5,LEAVES:0)
Block(-7,83,-4,LEAVES:0)
Block(-7,83,-3,LEAVES:0)
Block(-7,83,-2,LEAVES:0)
Block(-7,83,-1,LEAVES:0)
Block(-7,83,4,LEAVES:0)
Block(-7,84,-7,LEAVES:0)
Block(-7,84,-3,LEAVES:0)
Block(-7,85,-3,LEAVES:0)
RandomBlock(-7,86,6,quark:quilted_wool:7,10,quark:quilted_wool:7,100)
RandomBlock(-7,86,7,quark:quilted_wool:7,10,quark:quilted_wool:7,100)
RandomBlock(-7,86,8,quark:quilted_wool:7,10,quark:quilted_wool:7,100)
RandomBlock(-7,87,5,quark:quilted_wool:7,10,quark:quilted_wool:7,100)
RandomBlock(-7,87,6,quark:quilted_wool:7,10,quark:quilted_wool:7,100)
RandomBlock(-7,87,7,quark:quilted_wool:7,10,quark:quilted_wool:7,100)
RandomBlock(-7,87,8,quark:quilted_wool:7,10,quark:quilted_wool:7,100)
RandomBlock(-7,88,4,quark:quilted_wool:7,10,quark:quilted_wool:7,100)
RandomBlock(-7,88,5,quark:quilted_wool:7,10,quark:quilted_wool:7,100)
RandomBlock(-7,88,6,quark:quilted_wool:7,10,quark:quilted_wool:7,100)
RandomBlock(-7,88,7,quark:quilted_wool:7,10,quark:quilted_wool:7,100)
RandomBlock(-7,88,8,quark:quilted_wool:7,10,quark:quilted_wool:7,100)
RandomBlock(-7,89,-5,quark:quilted_wool:0,10,quark:quilted_wool:0,100)
RandomBlock(-7,89,-4,quark:quilted_wool:0,10,quark:quilted_wool:0,100)
RandomBlock(-7,89,-3,quark:quilted_wool:0,10,quark:quilted_wool:0,100)
RandomBlock(-7,89,-2,quark:quilted_wool:0,10,quark:quilted_wool:0,100)
RandomBlock(-7,89,-1,quark:quilted_wool:0,10,quark:quilted_wool:0,100)
RandomBlock(-7,89,3,quark:quilted_wool:7,10,quark:quilted_wool:7,100)
RandomBlock(-7,89,4,quark:quilted_wool:7,10,quark:quilted_wool:7,100)
RandomBlock(-7,89,5,quark:quilted_wool:7,10,quark:quilted_wool:7,100)
RandomBlock(-7,89,6,quark:quilted_wool:7,10,quark:quilted_wool:7,100)
RandomBlock(-7,89,7,quark:quilted_wool:7,10,quark:quilted_wool:7,100)
RandomBlock(-7,89,8,quark:quilted_wool:7,10,quark:quilted_wool:7,100)
RandomBlock(-7,90,-5,quark:quilted_wool:0,10,quark:quilted_wool:0,100)
RandomBlock(-7,90,-4,quark:quilted_wool:0,10,quark:quilted_wool:0,100)
RandomBlock(-7,90,-3,quark:quilted_wool:0,10,quark:quilted_wool:0,100)
RandomBlock(-7,90,-2,quark:quilted_wool:0,10,quark:quilted_wool:0,100)
RandomBlock(-7,90,-1,quark:quilted_wool:0,10,quark:quilted_wool:0,100)
RandomBlock(-7,90,3,quark:quilted_wool:7,10,quark:quilted_wool:7,100)
RandomBlock(-7,90,4,quark:quilted_wool:7,10,quark:quilted_wool:7,100)
RandomBlock(-7,90,5,quark:quilted_wool:7,10,quark:quilted_wool:7,100)
RandomBlock(-7,90,6,quark:quilted_wool:7,10,quark:quilted_wool:7,100)
RandomBlock(-7,90,7,quark:quilted_wool:7,10,quark:quilted_wool:7,100)
RandomBlock(-7,90,8,quark:quilted_wool:7,10,quark:quilted_wool:7,100)
RandomBlock(-7,91,-6,quark:quilted_wool:0,10,quark:quilted_wool:0,100)
RandomBlock(-7,91,-5,quark:quilted_wool:0,10,quark:quilted_wool:0,100)
RandomBlock(-7,91,-4,quark:quilted_wool:0,10,quark:quilted_wool:0,100)
RandomBlock(-7,91,-3,quark:quilted_wool:0,10,quark:quilted_wool:0,100)
RandomBlock(-7,91,-2,quark:quilted_wool:0,10,quark:quilted_wool:0,100)
RandomBlock(-7,91,-1,quark:quilted_wool:0,10,quark:quilted_wool:0,100)
RandomBlock(-7,91,0,quark:quilted_wool:0,10,quark:quilted_wool:0,100)
RandomBlock(-7,91,3,quark:quilted_wool:7,10,quark:quilted_wool:7,100)
RandomBlock(-7,91,4,quark:quilted_wool:7,10,quark:quilted_wool:7,100)
RandomBlock(-7,91,5,quark:quilted_wool:7,10,quark:quilted_wool:7,100)
RandomBlock(-7,91,6,quark:quilted_wool:7,10,quark:quilted_wool:7,100)
RandomBlock(-7,91,7,quark:quilted_wool:7,10,quark:quilted_wool:7,100)
RandomBlock(-7,91,8,quark:quilted_wool:7,10,quark:quilted_wool:7,100)
RandomBlock(-7,92,-7,quark:quilted_wool:0,10,quark:quilted_wool:0,100)
RandomBlock(-7,92,-6,quark:quilted_wool:0,10,quark:quilted_wool:0,100)
RandomBlock(-7,92,-5,quark:quilted_wool:0,10,quark:quilted_wool:0,100)
RandomBlock(-7,92,-4,quark:quilted_wool:0,10,quark:quilted_wool:0,100)
RandomBlock(-7,92,-3,quark:quilted_wool:0,10,quark:quilted_wool:0,100)
RandomBlock(-7,92,-2,quark:quilted_wool:0,10,quark:quilted_wool:0,100)
RandomBlock(-7,92,-1,quark:quilted_wool:0,10,quark:quilted_wool:0,100)
RandomBlock(-7,92,0,quark:quilted_wool:0,10,quark:quilted_wool:0,100)
RandomBlock(-7,92,1,quark:quilted_wool:0,10,quark:quilted_wool:0,100)
RandomBlock(-7,92,3,quark:quilted_wool:7,10,quark:quilted_wool:7,100)
RandomBlock(-7,92,4,quark:quilted_wool:7,10,quark:quilted_wool:7,100)
RandomBlock(-7,92,5,quark:quilted_wool:7,10,quark:quilted_wool:7,100)
RandomBlock(-7,92,6,quark:quilted_wool:7,10,quark:quilted_wool:7,100)
RandomBlock(-7,92,7,quark:quilted_wool:7,10,quark:quilted_wool:7,100)
RandomBlock(-7,92,8,quark:quilted_wool:7,10,quark:quilted_wool:7,100)
RandomBlock(-7,93,-7,quark:quilted_wool:0,10,quark:quilted_wool:0,100)
RandomBlock(-7,93,-6,quark:quilted_wool:0,10,quark:quilted_wool:0,100)
RandomBlock(-7,93,-5,quark:quilted_wool:0,10,quark:quilted_wool:0,100)
RandomBlock(-7,93,-4,quark:quilted_wool:0,10,quark:quilted_wool:0,100)
RandomBlock(-7,93,-3,quark:quilted_wool:0,10,quark:quilted_wool:0,100)
RandomBlock(-7,93,-2,quark:quilted_wool:0,10,quark:quilted_wool:0,100)
RandomBlock(-7,93,-1,quark:quilted_wool:0,10,quark:quilted_wool:0,100)
RandomBlock(-7,93,0,quark:quilted_wool:0,10,quark:quilted_wool:0,100)
RandomBlock(-7,93,1,quark:quilted_wool:0,10,quark:quilted_wool:0,100)
RandomBlock(-7,93,3,quark:quilted_wool:7,10,quark:quilted_wool:7,100)
RandomBlock(-7,93,4,quark:quilted_wool:7,10,quark:quilted_wool:7,100)
RandomBlock(-7,93,5,quark:quilted_wool:7,10,quark:quilted_wool:7,100)
RandomBlock(-7,93,6,quark:quilted_wool:7,10,quark:quilted_wool:7,100)
RandomBlock(-7,93,7,quark:quilted_wool:7,10,quark:quilted_wool:7,100)
RandomBlock(-7,93,8,quark:quilted_wool:7,10,quark:quilted_wool:7,100)
RandomBlock(-7,94,-7,quark:quilted_wool:0,10,quark:quilted_wool:0,100)
RandomBlock(-7,94,-6,quark:quilted_wool:0,10,quark:quilted_wool:0,100)
RandomBlock(-7,94,-5,quark:quilted_wool:0,10,quark:quilted_wool:0,100)
RandomBlock(-7,94,-4,quark:quilted_wool:0,10,quark:quilted_wool:0,100)
RandomBlock(-7,94,-3,quark:quilted_wool:0,10,quark:quilted_wool:0,100)
RandomBlock(-7,94,-2,quark:quilted_wool:0,10,quark:quilted_wool:0,100)
RandomBlock(-7,94,-1,quark:quilted_wool:0,10,quark:quilted_wool:0,100)
RandomBlock(-7,94,0,quark:quilted_wool:0,10,quark:quilted_wool:0,100)
RandomBlock(-7,94,1,quark:quilted_wool:0,10,quark:quilted_wool:0,100)
RandomBlock(-7,94,3,quark:quilted_wool:7,10,quark:quilted_wool:7,100)
RandomBlock(-7,94,4,quark:quilted_wool:7,10,quark:quilted_wool:7,100)
RandomBlock(-7,94,5,quark:quilted_wool:7,10,quark:quilted_wool:7,100)
RandomBlock(-7,94,6,quark:quilted_wool:7,10,quark:quilted_wool:7,100)
RandomBlock(-7,94,7,quark:quilted_wool:7,10,quark:quilted_wool:7,100)
RandomBlock(-7,94,8,quark:quilted_wool:7,10,quark:quilted_wool:7,100)
RandomBlock(-7,95,-7,quark:quilted_wool:0,10,quark:quilted_wool:0,100)
RandomBlock(-7,95,-6,quark:quilted_wool:0,10,quark:quilted_wool:0,100)
RandomBlock(-7,95,-5,quark:quilted_wool:0,10,quark:quilted_wool:0,100)
RandomBlock(-7,95,-4,quark:quilted_wool:0,10,quark:quilted_wool:0,100)
RandomBlock(-7,95,-3,quark:quilted_wool:0,10,quark:quilted_wool:0,100)
RandomBlock(-7,95,-2,quark:quilted_wool:0,10,quark:quilted_wool:0,100)
RandomBlock(-7,95,-1,quark:quilted_wool:0,10,quark:quilted_wool:0,100)
RandomBlock(-7,95,0,quark:quilted_wool:0,10,quark:quilted_wool:0,100)
RandomBlock(-7,95,1,quark:quilted_wool:0,10,quark:quilted_wool:0,100)
RandomBlock(-7,95,3,quark:quilted_wool:7,10,quark:quilted_wool:7,100)
RandomBlock(-7,95,4,quark:quilted_wool:7,10,quark:quilted_wool:7,100)
RandomBlock(-7,95,5,quark:quilted_wool:7,10,quark:quilted_wool:7,100)
RandomBlock(-7,95,6,quark:quilted_wool:7,10,quark:quilted_wool:7,100)
RandomBlock(-7,95,7,quark:quilted_wool:7,10,quark:quilted_wool:7,100)
RandomBlock(-7,95,8,quark:quilted_wool:7,10,quark:quilted_wool:7,100)
RandomBlock(-7,96,-7,quark:quilted_wool:0,10,quark:quilted_wool:0,100)
RandomBlock(-7,96,-6,quark:quilted_wool:0,10,quark:quilted_wool:0,100)
RandomBlock(-7,96,-5,quark:quilted_wool:0,10,quark:quilted_wool:0,100)
RandomBlock(-7,96,-4,quark:quilted_wool:0,10,quark:quilted_wool:0,100)
RandomBlock(-7,96,-3,quark:quilted_wool:0,10,quark:quilted_wool:0,100)
RandomBlock(-7,96,-2,quark:quilted_wool:0,10,quark:quilted_wool:0,100)
RandomBlock(-7,96,-1,quark:quilted_wool:0,10,quark:quilted_wool:0,100)
RandomBlock(-7,96,0,quark:quilted_wool:0,10,quark:quilted_wool:0,100)
RandomBlock(-7,96,1,quark:quilted_wool:0,10,quark:quilted_wool:0,100)
RandomBlock(-7,96,2,quark:quilted_wool:0,10,quark:quilted_wool:0,100)
RandomBlock(-7,96,4,quark:quilted_wool:7,10,quark:quilted_wool:7,100)
RandomBlock(-7,96,5,quark:quilted_wool:7,10,quark:quilted_wool:7,100)
RandomBlock(-7,96,6,quark:quilted_wool:7,10,quark:quilted_wool:7,100)
RandomBlock(-7,96,7,quark:quilted_wool:7,10,quark:quilted_wool:7,100)
RandomBlock(-7,96,8,quark:quilted_wool:7,10,quark:quilted_wool:7,100)
RandomBlock(-7,97,-7,quark:quilted_wool:0,10,quark:quilted_wool:0,100)
RandomBlock(-7,97,-6,quark:quilted_wool:0,10,quark:quilted_wool:0,100)
RandomBlock(-7,97,-5,quark:quilted_wool:0,10,quark:quilted_wool:0,100)
RandomBlock(-7,97,-4,quark:quilted_wool:0,10,quark:quilted_wool:0,100)
RandomBlock(-7,97,-3,quark:quilted_wool:0,10,quark:quilted_wool:0,100)
RandomBlock(-7,97,-2,quark:quilted_wool:0,10,quark:quilted_wool:0,100)
RandomBlock(-7,97,-1,quark:quilted_wool:0,10,quark:quilted_wool:0,100)
RandomBlock(-7,97,0,quark:quilted_wool:0,10,quark:quilted_wool:0,100)
RandomBlock(-7,97,1,quark:quilted_wool:0,10,quark:quilted_wool:0,100)
RandomBlock(-7,97,2,quark:quilted_wool:0,10,quark:quilted_wool:0,100)
RandomBlock(-7,97,5,quark:quilted_wool:7,10,quark:quilted_wool:7,100)
RandomBlock(-7,97,6,quark:quilted_wool:7,10,quark:quilted_wool:7,100)
RandomBlock(-7,97,7,quark:quilted_wool:7,10,quark:quilted_wool:7,100)
RandomBlock(-7,97,8,quark:quilted_wool:7,10,quark:quilted_wool:7,100)
RandomBlock(-7,98,-7,quark:quilted_wool:0,10,quark:quilted_wool:0,100)
RandomBlock(-7,98,-6,quark:quilted_wool:0,10,quark:quilted_wool:0,100)
RandomBlock(-7,98,-5,quark:quilted_wool:0,10,quark:quilted_wool:0,100)
RandomBlock(-7,98,-4,quark:quilted_wool:0,10,quark:quilted_wool:0,100)
RandomBlock(-7,98,-3,quark:quilted_wool:0,10,quark:quilted_wool:0,100)
RandomBlock(-7,98,-2,quark:quilted_wool:0,10,quark:quilted_wool:0,100)
RandomBlock(-7,98,-1,quark:quilted_wool:0,10,quark:quilted_wool:0,100)
RandomBlock(-7,98,0,quark:quilted_wool:0,10,quark:quilted_wool:0,100)
RandomBlock(-7,98,1,quark:quilted_wool:0,10,quark:quilted_wool:0,100)
RandomBlock(-7,98,2,quark:quilted_wool:0,10,quark:quilted_wool:0,100)
RandomBlock(-7,98,6,quark:quilted_wool:7,10,quark:quilted_wool:7,100)
RandomBlock(-7,98,7,quark:quilted_wool:7,10,quark:quilted_wool:7,100)
RandomBlock(-7,98,8,quark:quilted_wool:7,10,quark:quilted_wool:7,100)
RandomBlock(-7,99,-7,quark:quilted_wool:0,10,quark:quilted_wool:0,100)
RandomBlock(-7,99,-6,quark:quilted_wool:0,10,quark:quilted_wool:0,100)
RandomBlock(-7,99,-5,quark:quilted_wool:0,10,quark:quilted_wool:0,100)
RandomBlock(-7,99,-4,quark:quilted_wool:0,10,quark:quilted_wool:0,100)
RandomBlock(-7,99,-3,quark:quilted_wool:0,10,quark:quilted_wool:0,100)
RandomBlock(-7,99,-2,quark:quilted_wool:0,10,quark:quilted_wool:0,100)
RandomBlock(-7,99,-1,quark:quilted_wool:0,10,quark:quilted_wool:0,100)
RandomBlock(-7,99,0,quark:quilted_wool:0,10,quark:quilted_wool:0,100)
RandomBlock(-7,99,1,quark:quilted_wool:0,10,quark:quilted_wool:0,100)
RandomBlock(-7,99,2,quark:quilted_wool:0,10,quark:quilted_wool:0,100)
RandomBlock(-7,100,-7,quark:quilted_wool:0,10,quark:quilted_wool:0,100)
RandomBlock(-7,100,-6,quark:quilted_wool:0,10,quark:quilted_wool:0,100)
RandomBlock(-7,100,-5,quark:quilted_wool:0,10,quark:quilted_wool:0,100)
RandomBlock(-7,100,-4,quark:quilted_wool:0,10,quark:quilted_wool:0,100)
RandomBlock(-7,100,-3,quark:quilted_wool:0,10,quark:quilted_wool:0,100)
RandomBlock(-7,100,-2,quark:quilted_wool:0,10,quark:quilted_wool:0,100)
RandomBlock(-7,100,-1,quark:quilted_wool:0,10,quark:quilted_wool:0,100)
RandomBlock(-7,100,0,quark:quilted_wool:0,10,quark:quilted_wool:0,100)
RandomBlock(-7,100,1,quark:quilted_wool:0,10,quark:quilted_wool:0,100)
RandomBlock(-7,100,2,quark:quilted_wool:0,10,quark:quilted_wool:0,100)
RandomBlock(-7,101,-7,quark:quilted_wool:0,10,quark:quilted_wool:0,100)
RandomBlock(-7,101,-6,quark:quilted_wool:0,10,quark:quilted_wool:0,100)
RandomBlock(-7,101,-5,quark:quilted_wool:0,10,quark:quilted_wool:0,100)
RandomBlock(-7,101,-4,quark:quilted_wool:0,10,quark:quilted_wool:0,100)
RandomBlock(-7,101,-3,quark:quilted_wool:0,10,quark:quilted_wool:0,100)
RandomBlock(-7,101,-2,quark:quilted_wool:0,10,quark:quilted_wool:0,100)
RandomBlock(-7,101,-1,quark:quilted_wool:0,10,quark:quilted_wool:0,100)
RandomBlock(-7,101,0,quark:quilted_wool:0,10,quark:quilted_wool:0,100)
RandomBlock(-7,101,1,quark:quilted_wool:0,10,quark:quilted_wool:0,100)
RandomBlock(-7,102,-7,quark:quilted_wool:0,10,quark:quilted_wool:0,100)
RandomBlock(-7,102,-6,quark:quilted_wool:0,10,quark:quilted_wool:0,100)
RandomBlock(-7,102,-5,quark:quilted_wool:0,10,quark:quilted_wool:0,100)
RandomBlock(-7,102,-4,quark:quilted_wool:0,10,quark:quilted_wool:0,100)
RandomBlock(-7,102,-3,quark:quilted_wool:0,10,quark:quilted_wool:0,100)
RandomBlock(-7,102,-2,quark:quilted_wool:0,10,quark:quilted_wool:0,100)
RandomBlock(-7,102,-1,quark:quilted_wool:0,10,quark:quilted_wool:0,100)
RandomBlock(-7,102,0,quark:quilted_wool:0,10,quark:quilted_wool:0,100)
RandomBlock(-7,102,1,quark:quilted_wool:0,10,quark:quilted_wool:0,100)
RandomBlock(-7,103,-7,quark:quilted_wool:0,10,quark:quilted_wool:0,100)
RandomBlock(-7,103,-6,quark:quilted_wool:0,10,quark:quilted_wool:0,100)
RandomBlock(-7,103,-5,quark:quilted_wool:0,10,quark:quilted_wool:0,100)
RandomBlock(-7,103,-4,quark:quilted_wool:0,10,quark:quilted_wool:0,100)
RandomBlock(-7,103,-3,quark:quilted_wool:0,10,quark:quilted_wool:0,100)
RandomBlock(-7,103,-2,quark:quilted_wool:0,10,quark:quilted_wool:0,100)
RandomBlock(-7,103,-1,quark:quilted_wool:0,10,quark:quilted_wool:0,100)
RandomBlock(-7,103,0,quark:quilted_wool:0,10,quark:quilted_wool:0,100)
RandomBlock(-7,103,1,quark:quilted_wool:0,10,quark:quilted_wool:0,100)
RandomBlock(-7,104,-7,quark:quilted_wool:0,10,quark:quilted_wool:0,100)
RandomBlock(-7,104,-6,quark:quilted_wool:0,10,quark:quilted_wool:0,100)
RandomBlock(-7,104,-5,quark:quilted_wool:0,10,quark:quilted_wool:0,100)
RandomBlock(-7,104,-4,quark:quilted_wool:0,10,quark:quilted_wool:0,100)
RandomBlock(-7,104,-3,quark:quilted_wool:0,10,quark:quilted_wool:0,100)
RandomBlock(-7,104,-2,quark:quilted_wool:0,10,quark:quilted_wool:0,100)
RandomBlock(-7,104,-1,quark:quilted_wool:0,10,quark:quilted_wool:0,100)
RandomBlock(-7,104,0,quark:quilted_wool:0,10,quark:quilted_wool:0,100)
RandomBlock(-7,104,1,quark:quilted_wool:0,10,quark:quilted_wool:0,100)
RandomBlock(-7,105,-6,quark:quilted_wool:0,10,quark:quilted_wool:0,100)
RandomBlock(-7,105,-5,quark:quilted_wool:0,10,quark:quilted_wool:0,100)
RandomBlock(-7,105,-4,quark:quilted_wool:0,10,quark:quilted_wool:0,100)
RandomBlock(-7,105,-3,quark:quilted_wool:0,10,quark:quilted_wool:0,100)
RandomBlock(-7,105,-2,quark:quilted_wool:0,10,quark:quilted_wool:0,100)
RandomBlock(-7,105,-1,quark:quilted_wool:0,10,quark:quilted_wool:0,100)
RandomBlock(-7,105,0,quark:quilted_wool:0,10,quark:quilted_wool:0,100)
RandomBlock(-7,106,-5,quark:quilted_wool:0,10,quark:quilted_wool:0,100)
RandomBlock(-7,106,-4,quark:quilted_wool:0,10,quark:quilted_wool:0,100)
RandomBlock(-7,106,-3,quark:quilted_wool:0,10,quark:quilted_wool:0,100)
RandomBlock(-7,106,-2,quark:quilted_wool:0,10,quark:quilted_wool:0,100)
RandomBlock(-7,106,-1,quark:quilted_wool:0,10,quark:quilted_wool:0,100)
RandomBlock(-7,107,-5,quark:quilted_wool:0,10,quark:quilted_wool:0,100)
RandomBlock(-7,107,-4,quark:quilted_wool:0,10,quark:quilted_wool:0,100)
RandomBlock(-7,107,-3,quark:quilted_wool:0,10,quark:quilted_wool:0,100)
RandomBlock(-7,107,-2,quark:quilted_wool:0,10,quark:quilted_wool:0,100)
RandomBlock(-7,107,-1,quark:quilted_wool:0,10,quark:quilted_wool:0,100)
Block(-6,5,2,LOG:12)
Block(-6,6,1,LOG:12)
Block(-6,6,2,LOG:12)
Block(-6,6,3,LOG:12)
Block(-6,7,0,LOG:12)
Block(-6,7,1,LOG:12)
Block(-6,7,2,LOG:12)
Block(-6,7,3,LOG:12)
Block(-6,8,0,LOG:12)
Block(-6,8,1,LOG:12)
Block(-6,8,2,LOG:12)
Block(-6,8,3,LOG:12)
Block(-6,9,-6,LOG:12)
Block(-6,9,0,LOG:12)
Block(-6,9,1,LOG:12)
Block(-6,9,2,LOG:12)
Block(-6,9,3,quark:leaf_carpet)
Block(-6,10,-7,LOG:12)
Block(-6,10,-6,LOG:12)
Block(-6,10,-5,LOG:12)
Block(-6,10,-1,LOG:12)
Block(-6,10,0,LOG:12)
Block(-6,10,1,LOG:12)
Block(-6,10,2,quark:leaf_carpet)
Block(-6,11,-7,LOG:12)
Block(-6,11,-6,LOG:12)
Block(-6,11,0,LOG:12)
Block(-6,11,1,quark:leaf_carpet)
Block(-6,12,-7,LOG:12)
Block(-6,13,-7,LOG:12)
Block(-6,14,-7,LOG:12)
Block(-6,15,-7,LOG:12)
Block(-6,16,-7,LEAVES:0)
Block(-6,17,-7,LEAVES:0)
Block(-6,17,-6,LEAVES:0)
Block(-6,17,-5,LEAVES:0)
Block(-6,17,-2,LOG:12)
Block(-6,18,-7,LEAVES:0)
Block(-6,18,-6,LEAVES:0)
Block(-6,18,-3,LOG:12)
Block(-6,18,-2,LOG:12)
Block(-6,18,-1,LOG:12)
Block(-6,19,-7,LEAVES:0)
Block(-6,19,-4,LOG:12)
Block(-6,19,-3,LOG:12)
Block(-6,19,-2,LOG:12)
Block(-6,20,-5,LOG:12)
Block(-6,20,-4,LOG:12)
Block(-6,20,-3,LOG:12)
Block(-6,20,-2,quark:leaf_carpet)
Block(-6,21,-7,LOG:12)
Block(-6,21,-6,LOG:12)
Block(-6,21,-5,LOG:12)
Block(-6,21,-4,LOG:12)
Block(-6,21,-3,LOG:12)
Block(-6,22,-7,LOG:12)
Block(-6,22,-6,LOG:12)
Block(-6,22,-5,LOG:12)
Block(-6,22,-4,LOG:12)
Block(-6,22,-3,LOG:12)
Block(-6,23,-7,LOG:12)
Block(-6,23,-6,LOG:12)
Block(-6,23,-5,LOG:12)
Block(-6,23,-4,LOG:12)
Block(-6,23,-3,quark:leaf_carpet)
Block(-6,24,-7,LOG:12)
Block(-6,24,-6,LOG:12)
Block(-6,24,-5,LOG:12)
Block(-6,24,-4,LOG:12)
Block(-6,25,-7,LOG:12)
Block(-6,25,-6,LOG:12)
Block(-6,25,-5,LOG:12)
Block(-6,25,-4,quark:leaf_carpet)
Block(-6,26,-7,LOG:12)
Block(-6,26,-6,LOG:12)
Block(-6,26,-5,quark:leaf_carpet)
Block(-6,27,-7,LOG:12)
Block(-6,27,-6,LOG:12)
Block(-6,27,-5,LOG:12)
Block(-6,27,-4,LOG:12)
Block(-6,28,-7,LOG:12)
Block(-6,28,-6,LOG:12)
Block(-6,28,-5,LOG:12)
Block(-6,28,-4,LOG:12)
Block(-6,28,-3,LOG:12)
Block(-6,29,-7,LOG:12)
Block(-6,29,-6,LOG:12)
Block(-6,29,-5,LOG:12)
Block(-6,29,-4,LOG:12)
Block(-6,30,-7,LOG:12)
Block(-6,30,-6,LOG:12)
Block(-6,30,-5,LOG:12)
Block(-6,30,-4,LOG:12)
Block(-6,31,-7,LOG:12)
Block(-6,31,-6,LOG:12)
Block(-6,31,-5,LOG:12)
Block(-6,31,-4,LOG:12)
Block(-6,32,-7,LOG:12)
Block(-6,32,-6,quark:leaf_carpet)
Block(-6,32,-5,quark:leaf_carpet)
RandomBlock(-6,32,-1,quark:quilted_wool:7,10,quark:quilted_wool:7,100)
RandomBlock(-6,32,0,quark:quilted_wool:7,10,quark:quilted_wool:7,100)
RandomBlock(-6,32,1,quark:quilted_wool:7,10,quark:quilted_wool:7,100)
Block(-6,33,-7,LOG:12)
RandomBlock(-6,33,-2,quark:quilted_wool:7,10,quark:quilted_wool:7,100)
RandomBlock(-6,33,-1,quark:quilted_wool:7,10,quark:quilted_wool:7,100)
RandomBlock(-6,33,0,quark:quilted_wool:7,10,quark:quilted_wool:7,100)
RandomBlock(-6,33,1,quark:quilted_wool:7,10,quark:quilted_wool:7,100)
RandomBlock(-6,33,2,quark:quilted_wool:7,10,quark:quilted_wool:7,100)
Block(-6,34,-7,LOG:12)
RandomBlock(-6,34,-3,quark:quilted_wool:7,10,quark:quilted_wool:7,100)
RandomBlock(-6,34,-2,quark:quilted_wool:7,10,quark:quilted_wool:7,100)
RandomBlock(-6,34,-1,quark:quilted_wool:7,10,quark:quilted_wool:7,100)
RandomBlock(-6,34,0,quark:quilted_wool:7,10,quark:quilted_wool:7,100)
RandomBlock(-6,34,1,quark:quilted_wool:7,10,quark:quilted_wool:7,100)
RandomBlock(-6,34,2,quark:quilted_wool:7,10,quark:quilted_wool:7,100)
RandomBlock(-6,34,3,quark:quilted_wool:7,10,quark:quilted_wool:7,100)
Block(-6,35,-7,LOG:12)
RandomBlock(-6,35,-4,quark:quilted_wool:7,10,quark:quilted_wool:7,100)
RandomBlock(-6,35,-3,quark:quilted_wool:7,10,quark:quilted_wool:7,100)
RandomBlock(-6,35,-2,quark:quilted_wool:7,10,quark:quilted_wool:7,100)
RandomBlock(-6,35,-1,quark:quilted_wool:7,10,quark:quilted_wool:7,100)
RandomBlock(-6,35,0,quark:quilted_wool:7,10,quark:quilted_wool:7,100)
RandomBlock(-6,35,1,quark:quilted_wool:7,10,quark:quilted_wool:7,100)
RandomBlock(-6,35,2,quark:quilted_wool:7,10,quark:quilted_wool:7,100)
RandomBlock(-6,35,3,quark:quilted_wool:7,10,quark:quilted_wool:7,100)
RandomBlock(-6,35,4,quark:quilted_wool:7,10,quark:quilted_wool:7,100)
RandomBlock(-6,36,-4,quark:quilted_wool:7,10,quark:quilted_wool:7,100)
RandomBlock(-6,36,-3,quark:quilted_wool:7,10,quark:quilted_wool:7,100)
RandomBlock(-6,36,-2,quark:quilted_wool:7,10,quark:quilted_wool:7,100)
RandomBlock(-6,36,-1,quark:quilted_wool:7,10,quark:quilted_wool:7,100)
RandomBlock(-6,36,0,quark:quilted_wool:7,10,quark:quilted_wool:7,100)
RandomBlock(-6,36,1,quark:quilted_wool:7,10,quark:quilted_wool:7,100)
RandomBlock(-6,36,2,quark:quilted_wool:7,10,quark:quilted_wool:7,100)
RandomBlock(-6,36,3,quark:quilted_wool:7,10,quark:quilted_wool:7,100)
RandomBlock(-6,36,4,quark:quilted_wool:7,10,quark:quilted_wool:7,100)
RandomBlock(-6,37,-4,quark:quilted_wool:7,10,quark:quilted_wool:7,100)
RandomBlock(-6,37,-3,quark:quilted_wool:7,10,quark:quilted_wool:7,100)
RandomBlock(-6,37,-2,quark:quilted_wool:7,10,quark:quilted_wool:7,100)
RandomBlock(-6,37,-1,quark:quilted_wool:7,10,quark:quilted_wool:7,100)
RandomBlock(-6,37,0,quark:quilted_wool:7,10,quark:quilted_wool:7,100)
RandomBlock(-6,37,1,quark:quilted_wool:7,10,quark:quilted_wool:7,100)
RandomBlock(-6,37,2,quark:quilted_wool:7,10,quark:quilted_wool:7,100)
RandomBlock(-6,37,3,quark:quilted_wool:7,10,quark:quilted_wool:7,100)
RandomBlock(-6,37,4,quark:quilted_wool:7,10,quark:quilted_wool:7,100)
RandomBlock(-6,38,-4,quark:quilted_wool:7,10,quark:quilted_wool:7,100)
RandomBlock(-6,38,-3,quark:quilted_wool:7,10,quark:quilted_wool:7,100)
RandomBlock(-6,38,-2,quark:quilted_wool:7,10,quark:quilted_wool:7,100)
RandomBlock(-6,38,-1,quark:quilted_wool:7,10,quark:quilted_wool:7,100)
RandomBlock(-6,38,0,quark:quilted_wool:7,10,quark:quilted_wool:7,100)
RandomBlock(-6,38,1,quark:quilted_wool:7,10,quark:quilted_wool:7,100)
RandomBlock(-6,38,2,quark:quilted_wool:7,10,quark:quilted_wool:7,100)
RandomBlock(-6,38,3,quark:quilted_wool:7,10,quark:quilted_wool:7,100)
RandomBlock(-6,38,4,quark:quilted_wool:7,10,quark:quilted_wool:7,100)
RandomBlock(-6,39,-4,quark:quilted_wool:7,10,quark:quilted_wool:7,100)
RandomBlock(-6,39,-3,quark:quilted_wool:7,10,quark:quilted_wool:7,100)
RandomBlock(-6,39,-2,quark:quilted_wool:7,10,quark:quilted_wool:7,100)
RandomBlock(-6,39,-1,quark:quilted_wool:7,10,quark:quilted_wool:7,100)
RandomBlock(-6,39,0,quark:quilted_wool:7,10,quark:quilted_wool:7,100)
RandomBlock(-6,39,1,quark:quilted_wool:7,10,quark:quilted_wool:7,100)
RandomBlock(-6,39,2,quark:quilted_wool:7,10,quark:quilted_wool:7,100)
RandomBlock(-6,39,3,quark:quilted_wool:7,10,quark:quilted_wool:7,100)
RandomBlock(-6,39,4,quark:quilted_wool:7,10,quark:quilted_wool:7,100)
RandomBlock(-6,40,-3,quark:quilted_wool:7,10,quark:quilted_wool:7,100)
RandomBlock(-6,40,-2,quark:quilted_wool:7,10,quark:quilted_wool:7,100)
RandomBlock(-6,40,-1,quark:quilted_wool:7,10,quark:quilted_wool:7,100)
RandomBlock(-6,40,0,quark:quilted_wool:7,10,quark:quilted_wool:7,100)
RandomBlock(-6,40,1,quark:quilted_wool:7,10,quark:quilted_wool:7,100)
RandomBlock(-6,40,2,quark:quilted_wool:7,10,quark:quilted_wool:7,100)
RandomBlock(-6,40,3,quark:quilted_wool:7,10,quark:quilted_wool:7,100)
Block(-6,41,-7,LEAVES:0)
Block(-6,41,-6,LEAVES:0)
RandomBlock(-6,41,-2,quark:quilted_wool:7,10,quark:quilted_wool:7,100)
RandomBlock(-6,41,-1,quark:quilted_wool:7,10,quark:quilted_wool:7,100)
RandomBlock(-6,41,0,quark:quilted_wool:7,10,quark:quilted_wool:7,100)
RandomBlock(-6,41,1,quark:quilted_wool:7,10,quark:quilted_wool:7,100)
RandomBlock(-6,41,2,quark:quilted_wool:7,10,quark:quilted_wool:7,100)
Block(-6,42,-7,LEAVES:0)
RandomBlock(-6,42,-1,quark:quilted_wool:7,10,quark:quilted_wool:7,100)
RandomBlock(-6,42,0,quark:quilted_wool:7,10,quark:quilted_wool:7,100)
RandomBlock(-6,42,1,quark:quilted_wool:7,10,quark:quilted_wool:7,100)
Block(-6,43,-7,LEAVES:0)
Block(-6,43,-6,LEAVES:0)
Block(-6,44,-7,LEAVES:0)
Block(-6,44,-6,LEAVES:0)
Block(-6,45,-7,LEAVES:0)
Block(-6,46,-7,LEAVES:0)
Block(-6,47,-7,LEAVES:0)
Block(-6,48,-7,LEAVES:0)
Block(-6,49,-7,LOG:12)
Block(-6,50,-7,LOG:12)
Block(-6,51,-7,LEAVES:0)
Block(-6,51,0,VINE:4)
Block(-6,52,-7,LEAVES:0)
Block(-6,52,-6,LEAVES:0)
Block(-6,52,-5,LEAVES:0)
Block(-6,52,0,VINE:4)
Block(-6,53,-7,LEAVES:0)
Block(-6,53,-6,LEAVES:0)
Block(-6,53,-5,LEAVES:0)
Block(-6,53,-4,LEAVES:0)
Block(-6,53,0,VINE:4)
Block(-6,54,-7,LEAVES:0)
Block(-6,54,-6,LEAVES:0)
Block(-6,54,-5,LEAVES:0)
Block(-6,54,-4,LEAVES:0)
Block(-6,54,-3,LEAVES:0)
Block(-6,54,-1,LOG:12)
Block(-6,54,0,VINE:4)
Block(-6,55,-7,LEAVES:0)
Block(-6,55,-6,LEAVES:0)
Block(-6,55,-5,LEAVES:0)
Block(-6,55,-4,LEAVES:0)
Block(-6,55,-3,LEAVES:0)
Block(-6,55,-1,LOG:12)
Block(-6,55,0,VINE:4)
Block(-6,56,-6,LEAVES:0)
Block(-6,56,-5,LEAVES:0)
Block(-6,56,-1,LOG:12)
Block(-6,56,0,VINE:4)
Block(-6,57,-5,LEAVES:0)
Block(-6,57,-1,LOG:12)
Block(-6,57,0,VINE:4)
Block(-6,58,-7,LOG:12)
Block(-6,58,-6,LOG:12)
Block(-6,58,-5,LOG:12)
Block(-6,58,-4,LOG:12)
Block(-6,58,-3,LOG:12)
Block(-6,58,-2,LEAVES:0)
Block(-6,58,-1,LOG:12)
Block(-6,58,0,LEAVES:0)
Block(-6,58,1,LEAVES:0)
Block(-6,59,-7,LOG:12)
Block(-6,59,-6,LOG:12)
Block(-6,59,-5,LOG:12)
Block(-6,59,-4,LOG:12)
Block(-6,59,-3,LOG:12)
Block(-6,59,-2,LEAVES:0)
Block(-6,59,-1,LOG:12)
Block(-6,59,0,LEAVES:0)
Block(-6,59,1,LEAVES:0)
Block(-6,60,-7,LOG:12)
Block(-6,60,-6,LOG:12)
Block(-6,60,-5,LOG:12)
Block(-6,60,-4,LOG:12)
Block(-6,60,-3,LOG:12)
Block(-6,60,-2,LEAVES:0)
Block(-6,60,-1,LOG:12)
Block(-6,60,0,WOOD_DOUBLE_STEP:0)
Block(-6,60,1,WOOD_DOUBLE_STEP:0)
Block(-6,61,-5,LOG:12)
Block(-6,61,-4,LOG:12)
Block(-6,61,-3,LOG:12)
Block(-6,61,-2,WOOD_STEP:0)
Block(-6,61,-1,FENCE:0)
Block(-6,61,0,FENCE:0)
Block(-6,61,1,FENCE:0)
Block(-6,62,-7,rustic:lantern_wood)
Block(-6,62,-5,LOG:12)
Block(-6,62,-4,LOG:12)
Block(-6,62,-3,LOG:12)
Block(-6,62,1,FENCE:0)
Block(-6,63,-7,LEAVES:0)
Block(-6,63,-6,LEAVES:0)
Block(-6,63,-5,LOG:12)
Block(-6,63,-4,LOG:12)
Block(-6,63,-3,LOG:12)
Block(-6,64,-7,LEAVES:0)
Block(-6,64,-6,LEAVES:0)
Block(-6,64,-5,LOG:12)
Block(-6,64,-4,LOG:12)
Block(-6,64,-3,LOG:12)
Block(-6,64,-2,LEAVES:0)
Block(-6,64,4,rustic:iron_lantern:0)
Block(-6,65,-6,LEAVES:0)
Block(-6,65,-5,LOG:12)
Block(-6,65,-4,LOG:12)
Block(-6,65,-3,LOG:12)
Block(-6,65,-2,LEAVES:0)
Block(-6,65,4,inspirations:rope:1)
Block(-6,66,-7,LOG:12)
Block(-6,66,-6,LOG:12)
Block(-6,66,-5,LOG:12)
Block(-6,66,-4,LOG:12)
Block(-6,66,-3,LOG:12)
Block(-6,66,-2,LEAVES:0)
Block(-6,66,4,LOG:12)
Block(-6,67,-7,LOG:12)
Block(-6,67,-6,LOG:12)
Block(-6,67,-5,LOG:12)
Block(-6,67,-4,LOG:12)
Block(-6,67,-3,LOG:12)
Block(-6,68,-4,LEAVES:0)
Block(-6,68,-3,LOG:12)
Block(-6,68,-2,LEAVES:0)
Block(-6,69,-5,LEAVES:0)
Block(-6,69,-4,LEAVES:0)
Block(-6,69,-3,LEAVES:0)
Block(-6,69,-2,LEAVES:0)
Block(-6,69,-1,LEAVES:0)
Block(-6,70,-5,LEAVES:0)
Block(-6,70,-4,LEAVES:0)
Block(-6,70,-3,LEAVES:0)
Block(-6,70,-2,LEAVES:0)
Block(-6,70,-1,LEAVES:0)
Block(-6,70,2,LEAVES:0)
Block(-6,70,3,LEAVES:0)
Block(-6,70,4,LEAVES:0)
Block(-6,70,5,LEAVES:0)
Block(-6,71,-4,LEAVES:0)
Block(-6,71,-3,LEAVES:0)
Block(-6,71,-2,LEAVES:0)
Block(-6,71,2,LEAVES:0)
Block(-6,71,3,LEAVES:0)
Block(-6,71,4,LEAVES:0)
Block(-6,71,5,LEAVES:0)
Block(-6,71,6,LEAVES:0)
Block(-6,72,-7,LOG:12)
Block(-6,72,-5,LOG:12)
Block(-6,72,-4,LEAVES:0)
Block(-6,72,-3,LEAVES:0)
Block(-6,72,-2,LEAVES:0)
Block(-6,72,-1,LEAVES:0)
Block(-6,72,0,LEAVES:0)
Block(-6,73,-7,LOG:12)
Block(-6,73,-6,LEAVES:0)
Block(-6,73,-5,LOG:12)
Block(-6,73,-4,LEAVES:0)
Block(-6,73,-3,LEAVES:0)
Block(-6,73,-2,LEAVES:0)
Block(-6,73,-1,LEAVES:0)
Block(-6,73,0,LEAVES:0)
Block(-6,74,-7,LOG:12)
Block(-6,74,-6,LEAVES:0)
Block(-6,74,-5,LOG:12)
Block(-6,74,-4,LEAVES:0)
Block(-6,74,-3,LEAVES:0)
Block(-6,74,-2,LEAVES:0)
Block(-6,74,-1,LEAVES:0)
Block(-6,74,5,LEAVES:0)
Block(-6,75,-7,LOG:12)
Block(-6,75,-6,LEAVES:0)
Block(-6,75,-5,LOG:12)
Block(-6,75,-4,LEAVES:0)
Block(-6,75,-3,LEAVES:0)
Block(-6,75,-2,LEAVES:0)
Block(-6,75,3,LEAVES:0)
Block(-6,75,4,LEAVES:0)
Block(-6,75,5,LEAVES:0)
Block(-6,75,6,LEAVES:0)
Block(-6,75,7,LEAVES:0)
Block(-6,76,-7,LEAVES:0)
Block(-6,76,-6,LEAVES:0)
Block(-6,76,-5,LEAVES:0)
Block(-6,76,-4,LEAVES:0)
Block(-6,76,-3,LEAVES:0)
Block(-6,76,-2,LEAVES:12)
Block(-6,76,-1,LEAVES:12)
Block(-6,76,0,LEAVES:0)
Block(-6,76,1,LEAVES:0)
Block(-6,76,2,LEAVES:0)
Block(-6,76,3,LEAVES:0)
Block(-6,76,4,LEAVES:0)
Block(-6,76,5,LOG:12)
Block(-6,76,6,LEAVES:0)
Block(-6,76,7,LEAVES:0)
Block(-6,77,-7,LOG:12)
Block(-6,77,-6,LEAVES:0)
Block(-6,77,-5,LEAVES:0)
Block(-6,77,-4,LEAVES:0)
Block(-6,77,-3,LEAVES:0)
Block(-6,77,-2,LOG:12)
Block(-6,77,-1,VINE:15)
Block(-6,77,0,LEAVES:0)
Block(-6,77,1,LEAVES:0)
Block(-6,77,2,LEAVES:0)
Block(-6,77,4,LEAVES:0)
Block(-6,77,5,LEAVES:0)
Block(-6,77,6,LEAVES:0)
Block(-6,77,7,LEAVES:0)
Block(-6,77,8,LEAVES:0)
Block(-6,78,-7,LEAVES:0)
Block(-6,78,-6,LEAVES:0)
Block(-6,78,-5,LEAVES:0)
Block(-6,78,-4,LEAVES:0)
Block(-6,78,-3,LEAVES:12)
Block(-6,78,-2,LOG:12)
Block(-6,78,-1,VINE:4)
Block(-6,78,4,LEAVES:0)
Block(-6,78,5,LEAVES:0)
Block(-6,78,6,LEAVES:0)
Block(-6,78,7,LEAVES:0)
Block(-6,79,-7,LEAVES:0)
Block(-6,79,-6,LEAVES:0)
Block(-6,79,-5,LEAVES:0)
Block(-6,79,-4,LEAVES:0)
Block(-6,79,-3,LOG:12)
Block(-6,79,-2,LOG:12)
Block(-6,79,-1,VINE:4)
Block(-6,79,6,LEAVES:0)
Block(-6,80,-7,LEAVES:0)
Block(-6,80,-6,LEAVES:0)
Block(-6,80,-5,LEAVES:0)
Block(-6,80,-4,LEAVES:0)
Block(-6,80,-3,LOG:12)
Block(-6,80,-2,LOG:12)
Block(-6,80,-1,LEAVES:0)
Block(-6,80,0,LEAVES:0)
Block(-6,80,3,LEAVES:0)
Block(-6,80,4,LOG:12)
Block(-6,80,5,LEAVES:0)
Block(-6,80,6,LEAVES:0)
Block(-6,81,-6,LEAVES:0)
Block(-6,81,-5,LEAVES:0)
Block(-6,81,-4,LEAVES:0)
Block(-6,81,-3,LOG:12)
Block(-6,81,-2,LOG:12)
Block(-6,81,-1,LEAVES:0)
Block(-6,81,0,LEAVES:0)
Block(-6,81,2,LEAVES:0)
Block(-6,81,3,LEAVES:0)
Block(-6,81,4,LEAVES:0)
Block(-6,81,5,LEAVES:0)
Block(-6,81,6,LEAVES:0)
Block(-6,81,7,LEAVES:0)
Block(-6,81,8,LEAVES:0)
Block(-6,82,-7,LEAVES:0)
Block(-6,82,-6,LEAVES:0)
Block(-6,82,-5,LEAVES:0)
Block(-6,82,-4,LEAVES:0)
Block(-6,82,-3,LOG:12)
Block(-6,82,-2,LOG:12)
Block(-6,82,-1,LEAVES:0)
Block(-6,82,2,LEAVES:0)
Block(-6,82,3,LEAVES:0)
Block(-6,82,4,LEAVES:0)
Block(-6,82,5,LEAVES:0)
Block(-6,82,6,LEAVES:0)
Block(-6,82,7,LEAVES:0)
Block(-6,83,-7,LEAVES:0)
Block(-6,83,-5,LEAVES:0)
Block(-6,83,-4,LEAVES:0)
Block(-6,83,-3,LOG:12)
Block(-6,83,-2,LEAVES:0)
Block(-6,83,-1,LEAVES:0)
Block(-6,83,3,LEAVES:0)
Block(-6,83,4,LEAVES:0)
Block(-6,83,5,LEAVES:0)
Block(-6,83,6,LEAVES:0)
Block(-6,84,-4,LEAVES:0)
Block(-6,84,-3,LOG:12)
Block(-6,84,-2,LEAVES:0)
Block(-6,85,-4,LEAVES:0)
Block(-6,85,-3,LEAVES:0)
Block(-6,85,-2,LEAVES:0)
RandomBlock(-6,86,5,quark:quilted_wool:7,10,quark:quilted_wool:7,100)
RandomBlock(-6,86,6,quark:quilted_wool:7,10,quark:quilted_wool:7,100)
RandomBlock(-6,86,7,quark:quilted_wool:7,10,quark:quilted_wool:7,100)
RandomBlock(-6,86,8,quark:quilted_wool:7,10,quark:quilted_wool:7,100)
RandomBlock(-6,87,4,quark:quilted_wool:7,10,quark:quilted_wool:7,100)
RandomBlock(-6,87,5,quark:quilted_wool:7,10,quark:quilted_wool:7,100)
RandomBlock(-6,87,6,quark:quilted_wool:7,10,quark:quilted_wool:7,100)
RandomBlock(-6,87,7,quark:quilted_wool:7,10,quark:quilted_wool:7,100)
RandomBlock(-6,87,8,quark:quilted_wool:7,10,quark:quilted_wool:7,100)
RandomBlock(-6,88,3,quark:quilted_wool:7,10,quark:quilted_wool:7,100)
RandomBlock(-6,88,4,quark:quilted_wool:7,10,quark:quilted_wool:7,100)
RandomBlock(-6,88,5,quark:quilted_wool:7,10,quark:quilted_wool:7,100)
RandomBlock(-6,88,6,quark:quilted_wool:7,10,quark:quilted_wool:7,100)
RandomBlock(-6,88,7,quark:quilted_wool:7,10,quark:quilted_wool:7,100)
RandomBlock(-6,88,8,quark:quilted_wool:7,10,quark:quilted_wool:7,100)
RandomBlock(-6,89,3,quark:quilted_wool:7,10,quark:quilted_wool:7,100)
RandomBlock(-6,89,4,quark:quilted_wool:7,10,quark:quilted_wool:7,100)
RandomBlock(-6,89,5,quark:quilted_wool:7,10,quark:quilted_wool:7,100)
RandomBlock(-6,89,6,quark:quilted_wool:7,10,quark:quilted_wool:7,100)
RandomBlock(-6,89,7,quark:quilted_wool:7,10,quark:quilted_wool:7,100)
RandomBlock(-6,89,8,quark:quilted_wool:7,10,quark:quilted_wool:7,100)
RandomBlock(-6,90,-4,quark:quilted_wool:0,10,quark:quilted_wool:0,100)
RandomBlock(-6,90,-3,quark:quilted_wool:0,10,quark:quilted_wool:0,100)
RandomBlock(-6,90,-2,quark:quilted_wool:0,10,quark:quilted_wool:0,100)
RandomBlock(-6,90,3,quark:quilted_wool:7,10,quark:quilted_wool:7,100)
RandomBlock(-6,90,4,quark:quilted_wool:7,10,quark:quilted_wool:7,100)
RandomBlock(-6,90,5,quark:quilted_wool:7,10,quark:quilted_wool:7,100)
RandomBlock(-6,90,6,quark:quilted_wool:7,10,quark:quilted_wool:7,100)
RandomBlock(-6,90,7,quark:quilted_wool:7,10,quark:quilted_wool:7,100)
RandomBlock(-6,90,8,quark:quilted_wool:7,10,quark:quilted_wool:7,100)
RandomBlock(-6,91,-5,quark:quilted_wool:0,10,quark:quilted_wool:0,100)
RandomBlock(-6,91,-4,quark:quilted_wool:0,10,quark:quilted_wool:0,100)
RandomBlock(-6,91,-3,quark:quilted_wool:0,10,quark:quilted_wool:0,100)
RandomBlock(-6,91,-2,quark:quilted_wool:0,10,quark:quilted_wool:0,100)
RandomBlock(-6,91,-1,quark:quilted_wool:0,10,quark:quilted_wool:0,100)
RandomBlock(-6,91,2,quark:quilted_wool:7,10,quark:quilted_wool:7,100)
RandomBlock(-6,91,3,quark:quilted_wool:7,10,quark:quilted_wool:7,100)
RandomBlock(-6,91,4,quark:quilted_wool:7,10,quark:quilted_wool:7,100)
RandomBlock(-6,91,5,quark:quilted_wool:7,10,quark:quilted_wool:7,100)
RandomBlock(-6,91,6,quark:quilted_wool:7,10,quark:quilted_wool:7,100)
RandomBlock(-6,91,7,quark:quilted_wool:7,10,quark:quilted_wool:7,100)
RandomBlock(-6,91,8,quark:quilted_wool:7,10,quark:quilted_wool:7,100)
RandomBlock(-6,92,-6,quark:quilted_wool:0,10,quark:quilted_wool:0,100)
RandomBlock(-6,92,-5,quark:quilted_wool:0,10,quark:quilted_wool:0,100)
RandomBlock(-6,92,-4,quark:quilted_wool:0,10,quark:quilted_wool:0,100)
RandomBlock(-6,92,-3,quark:quilted_wool:0,10,quark:quilted_wool:0,100)
RandomBlock(-6,92,-2,quark:quilted_wool:0,10,quark:quilted_wool:0,100)
RandomBlock(-6,92,-1,quark:quilted_wool:0,10,quark:quilted_wool:0,100)
RandomBlock(-6,92,0,quark:quilted_wool:0,10,quark:quilted_wool:0,100)
RandomBlock(-6,92,2,quark:quilted_wool:7,10,quark:quilted_wool:7,100)
RandomBlock(-6,92,3,quark:quilted_wool:7,10,quark:quilted_wool:7,100)
RandomBlock(-6,92,4,quark:quilted_wool:7,10,quark:quilted_wool:7,100)
RandomBlock(-6,92,5,quark:quilted_wool:7,10,quark:quilted_wool:7,100)
RandomBlock(-6,92,6,quark:quilted_wool:7,10,quark:quilted_wool:7,100)
RandomBlock(-6,92,7,quark:quilted_wool:7,10,quark:quilted_wool:7,100)
RandomBlock(-6,92,8,quark:quilted_wool:7,10,quark:quilted_wool:7,100)
RandomBlock(-6,93,-6,quark:quilted_wool:0,10,quark:quilted_wool:0,100)
RandomBlock(-6,93,-5,quark:quilted_wool:0,10,quark:quilted_wool:0,100)
RandomBlock(-6,93,-4,quark:quilted_wool:0,10,quark:quilted_wool:0,100)
RandomBlock(-6,93,-3,quark:quilted_wool:0,10,quark:quilted_wool:0,100)
RandomBlock(-6,93,-2,quark:quilted_wool:0,10,quark:quilted_wool:0,100)
RandomBlock(-6,93,-1,quark:quilted_wool:0,10,quark:quilted_wool:0,100)
RandomBlock(-6,93,0,quark:quilted_wool:0,10,quark:quilted_wool:0,100)
RandomBlock(-6,93,2,quark:quilted_wool:7,10,quark:quilted_wool:7,100)
RandomBlock(-6,93,3,quark:quilted_wool:7,10,quark:quilted_wool:7,100)
RandomBlock(-6,93,4,quark:quilted_wool:7,10,quark:quilted_wool:7,100)
RandomBlock(-6,93,5,quark:quilted_wool:7,10,quark:quilted_wool:7,100)
RandomBlock(-6,93,6,quark:quilted_wool:7,10,quark:quilted_wool:7,100)
RandomBlock(-6,93,7,quark:quilted_wool:7,10,quark:quilted_wool:7,100)
RandomBlock(-6,93,8,quark:quilted_wool:7,10,quark:quilted_wool:7,100)
RandomBlock(-6,94,-7,quark:quilted_wool:0,10,quark:quilted_wool:0,100)
RandomBlock(-6,94,-6,quark:quilted_wool:0,10,quark:quilted_wool:0,100)
RandomBlock(-6,94,-5,quark:quilted_wool:0,10,quark:quilted_wool:0,100)
RandomBlock(-6,94,-4,quark:quilted_wool:0,10,quark:quilted_wool:0,100)
RandomBlock(-6,94,-3,quark:quilted_wool:0,10,quark:quilted_wool:0,100)
RandomBlock(-6,94,-2,quark:quilted_wool:0,10,quark:quilted_wool:0,100)
RandomBlock(-6,94,-1,quark:quilted_wool:0,10,quark:quilted_wool:0,100)
RandomBlock(-6,94,0,quark:quilted_wool:0,10,quark:quilted_wool:0,100)
RandomBlock(-6,94,1,quark:quilted_wool:0,10,quark:quilted_wool:0,100)
RandomBlock(-6,94,3,quark:quilted_wool:7,10,quark:quilted_wool:7,100)
RandomBlock(-6,94,4,quark:quilted_wool:7,10,quark:quilted_wool:7,100)
RandomBlock(-6,94,5,quark:quilted_wool:7,10,quark:quilted_wool:7,100)
RandomBlock(-6,94,6,quark:quilted_wool:7,10,quark:quilted_wool:7,100)
RandomBlock(-6,94,7,quark:quilted_wool:7,10,quark:quilted_wool:7,100)
RandomBlock(-6,94,8,quark:quilted_wool:7,10,quark:quilted_wool:7,100)
RandomBlock(-6,95,-7,quark:quilted_wool:0,10,quark:quilted_wool:0,100)
RandomBlock(-6,95,-6,quark:quilted_wool:0,10,quark:quilted_wool:0,100)
RandomBlock(-6,95,-5,quark:quilted_wool:0,10,quark:quilted_wool:0,100)
RandomBlock(-6,95,-4,quark:quilted_wool:0,10,quark:quilted_wool:0,100)
RandomBlock(-6,95,-3,quark:quilted_wool:0,10,quark:quilted_wool:0,100)
RandomBlock(-6,95,-2,quark:quilted_wool:0,10,quark:quilted_wool:0,100)
RandomBlock(-6,95,-1,quark:quilted_wool:0,10,quark:quilted_wool:0,100)
RandomBlock(-6,95,0,quark:quilted_wool:0,10,quark:quilted_wool:0,100)
RandomBlock(-6,95,1,quark:quilted_wool:0,10,quark:quilted_wool:0,100)
RandomBlock(-6,95,3,quark:quilted_wool:7,10,quark:quilted_wool:7,100)
RandomBlock(-6,95,4,quark:quilted_wool:7,10,quark:quilted_wool:7,100)
RandomBlock(-6,95,5,quark:quilted_wool:7,10,quark:quilted_wool:7,100)
RandomBlock(-6,95,6,quark:quilted_wool:7,10,quark:quilted_wool:7,100)
RandomBlock(-6,95,7,quark:quilted_wool:7,10,quark:quilted_wool:7,100)
RandomBlock(-6,95,8,quark:quilted_wool:7,10,quark:quilted_wool:7,100)
RandomBlock(-6,96,-7,quark:quilted_wool:0,10,quark:quilted_wool:0,100)
RandomBlock(-6,96,-6,quark:quilted_wool:0,10,quark:quilted_wool:0,100)
RandomBlock(-6,96,-5,quark:quilted_wool:0,10,quark:quilted_wool:0,100)
RandomBlock(-6,96,-4,quark:quilted_wool:0,10,quark:quilted_wool:0,100)
RandomBlock(-6,96,-3,quark:quilted_wool:0,10,quark:quilted_wool:0,100)
RandomBlock(-6,96,-2,quark:quilted_wool:0,10,quark:quilted_wool:0,100)
RandomBlock(-6,96,-1,quark:quilted_wool:0,10,quark:quilted_wool:0,100)
RandomBlock(-6,96,0,quark:quilted_wool:0,10,quark:quilted_wool:0,100)
RandomBlock(-6,96,1,quark:quilted_wool:0,10,quark:quilted_wool:0,100)
RandomBlock(-6,96,3,quark:quilted_wool:7,10,quark:quilted_wool:7,100)
RandomBlock(-6,96,4,quark:quilted_wool:7,10,quark:quilted_wool:7,100)
RandomBlock(-6,96,5,quark:quilted_wool:7,10,quark:quilted_wool:7,100)
RandomBlock(-6,96,6,quark:quilted_wool:7,10,quark:quilted_wool:7,100)
RandomBlock(-6,96,7,quark:quilted_wool:7,10,quark:quilted_wool:7,100)
RandomBlock(-6,96,8,quark:quilted_wool:7,10,quark:quilted_wool:7,100)
RandomBlock(-6,97,-7,quark:quilted_wool:0,10,quark:quilted_wool:0,100)
RandomBlock(-6,97,-6,quark:quilted_wool:0,10,quark:quilted_wool:0,100)
RandomBlock(-6,97,-5,quark:quilted_wool:0,10,quark:quilted_wool:0,100)
RandomBlock(-6,97,-4,quark:quilted_wool:0,10,quark:quilted_wool:0,100)
RandomBlock(-6,97,-3,quark:quilted_wool:0,10,quark:quilted_wool:0,100)
RandomBlock(-6,97,-2,quark:quilted_wool:0,10,quark:quilted_wool:0,100)
RandomBlock(-6,97,-1,quark:quilted_wool:0,10,quark:quilted_wool:0,100)
RandomBlock(-6,97,0,quark:quilted_wool:0,10,quark:quilted_wool:0,100)
RandomBlock(-6,97,1,quark:quilted_wool:0,10,quark:quilted_wool:0,100)
RandomBlock(-6,97,4,quark:quilted_wool:7,10,quark:quilted_wool:7,100)
RandomBlock(-6,97,5,quark:quilted_wool:7,10,quark:quilted_wool:7,100)
RandomBlock(-6,97,6,quark:quilted_wool:7,10,quark:quilted_wool:7,100)
RandomBlock(-6,97,7,quark:quilted_wool:7,10,quark:quilted_wool:7,100)
RandomBlock(-6,97,8,quark:quilted_wool:7,10,quark:quilted_wool:7,100)
RandomBlock(-6,98,-7,quark:quilted_wool:0,10,quark:quilted_wool:0,100)
RandomBlock(-6,98,-6,quark:quilted_wool:0,10,quark:quilted_wool:0,100)
RandomBlock(-6,98,-5,quark:quilted_wool:0,10,quark:quilted_wool:0,100)
RandomBlock(-6,98,-4,quark:quilted_wool:0,10,quark:quilted_wool:0,100)
RandomBlock(-6,98,-3,quark:quilted_wool:0,10,quark:quilted_wool:0,100)
RandomBlock(-6,98,-2,quark:quilted_wool:0,10,quark:quilted_wool:0,100)
RandomBlock(-6,98,-1,quark:quilted_wool:0,10,quark:quilted_wool:0,100)
RandomBlock(-6,98,0,quark:quilted_wool:0,10,quark:quilted_wool:0,100)
RandomBlock(-6,98,1,quark:quilted_wool:0,10,quark:quilted_wool:0,100)
RandomBlock(-6,98,5,quark:quilted_wool:7,10,quark:quilted_wool:7,100)
RandomBlock(-6,98,6,quark:quilted_wool:7,10,quark:quilted_wool:7,100)
RandomBlock(-6,98,7,quark:quilted_wool:7,10,quark:quilted_wool:7,100)
RandomBlock(-6,98,8,quark:quilted_wool:7,10,quark:quilted_wool:7,100)
RandomBlock(-6,99,-7,quark:quilted_wool:0,10,quark:quilted_wool:0,100)
RandomBlock(-6,99,-6,quark:quilted_wool:0,10,quark:quilted_wool:0,100)
RandomBlock(-6,99,-5,quark:quilted_wool:0,10,quark:quilted_wool:0,100)
RandomBlock(-6,99,-4,quark:quilted_wool:0,10,quark:quilted_wool:0,100)
RandomBlock(-6,99,-3,quark:quilted_wool:0,10,quark:quilted_wool:0,100)
RandomBlock(-6,99,-2,quark:quilted_wool:0,10,quark:quilted_wool:0,100)
RandomBlock(-6,99,-1,quark:quilted_wool:0,10,quark:quilted_wool:0,100)
RandomBlock(-6,99,0,quark:quilted_wool:0,10,quark:quilted_wool:0,100)
RandomBlock(-6,99,1,quark:quilted_wool:0,10,quark:quilted_wool:0,100)
RandomBlock(-6,100,-7,quark:quilted_wool:0,10,quark:quilted_wool:0,100)
RandomBlock(-6,100,-6,quark:quilted_wool:0,10,quark:quilted_wool:0,100)
RandomBlock(-6,100,-5,quark:quilted_wool:0,10,quark:quilted_wool:0,100)
RandomBlock(-6,100,-4,quark:quilted_wool:0,10,quark:quilted_wool:0,100)
RandomBlock(-6,100,-3,quark:quilted_wool:0,10,quark:quilted_wool:0,100)
RandomBlock(-6,100,-2,quark:quilted_wool:0,10,quark:quilted_wool:0,100)
RandomBlock(-6,100,-1,quark:quilted_wool:0,10,quark:quilted_wool:0,100)
RandomBlock(-6,100,0,quark:quilted_wool:0,10,quark:quilted_wool:0,100)
RandomBlock(-6,100,1,quark:quilted_wool:0,10,quark:quilted_wool:0,100)
RandomBlock(-6,101,-7,quark:quilted_wool:0,10,quark:quilted_wool:0,100)
RandomBlock(-6,101,-6,quark:quilted_wool:0,10,quark:quilted_wool:0,100)
RandomBlock(-6,101,-5,quark:quilted_wool:0,10,quark:quilted_wool:0,100)
RandomBlock(-6,101,-4,quark:quilted_wool:0,10,quark:quilted_wool:0,100)
RandomBlock(-6,101,-3,quark:quilted_wool:0,10,quark:quilted_wool:0,100)
RandomBlock(-6,101,-2,quark:quilted_wool:0,10,quark:quilted_wool:0,100)
RandomBlock(-6,101,-1,quark:quilted_wool:0,10,quark:quilted_wool:0,100)
RandomBlock(-6,101,0,quark:quilted_wool:0,10,quark:quilted_wool:0,100)
RandomBlock(-6,101,1,quark:quilted_wool:0,10,quark:quilted_wool:0,100)
RandomBlock(-6,102,-7,quark:quilted_wool:0,10,quark:quilted_wool:0,100)
RandomBlock(-6,102,-6,quark:quilted_wool:0,10,quark:quilted_wool:0,100)
RandomBlock(-6,102,-5,quark:quilted_wool:0,10,quark:quilted_wool:0,100)
RandomBlock(-6,102,-4,quark:quilted_wool:0,10,quark:quilted_wool:0,100)
RandomBlock(-6,102,-3,quark:quilted_wool:0,10,quark:quilted_wool:0,100)
RandomBlock(-6,102,-2,quark:quilted_wool:0,10,quark:quilted_wool:0,100)
RandomBlock(-6,102,-1,quark:quilted_wool:0,10,quark:quilted_wool:0,100)
RandomBlock(-6,102,0,quark:quilted_wool:0,10,quark:quilted_wool:0,100)
RandomBlock(-6,102,1,quark:quilted_wool:0,10,quark:quilted_wool:0,100)
RandomBlock(-6,103,-6,quark:quilted_wool:0,10,quark:quilted_wool:0,100)
RandomBlock(-6,103,-5,quark:quilted_wool:0,10,quark:quilted_wool:0,100)
RandomBlock(-6,103,-4,quark:quilted_wool:0,10,quark:quilted_wool:0,100)
RandomBlock(-6,103,-3,quark:quilted_wool:0,10,quark:quilted_wool:0,100)
RandomBlock(-6,103,-2,quark:quilted_wool:0,10,quark:quilted_wool:0,100)
RandomBlock(-6,103,-1,quark:quilted_wool:0,10,quark:quilted_wool:0,100)
RandomBlock(-6,103,0,quark:quilted_wool:0,10,quark:quilted_wool:0,100)
RandomBlock(-6,104,-6,quark:quilted_wool:0,10,quark:quilted_wool:0,100)
RandomBlock(-6,104,-5,quark:quilted_wool:0,10,quark:quilted_wool:0,100)
RandomBlock(-6,104,-4,quark:quilted_wool:0,10,quark:quilted_wool:0,100)
RandomBlock(-6,104,-3,quark:quilted_wool:0,10,quark:quilted_wool:0,100)
RandomBlock(-6,104,-2,quark:quilted_wool:0,10,quark:quilted_wool:0,100)
RandomBlock(-6,104,-1,quark:quilted_wool:0,10,quark:quilted_wool:0,100)
RandomBlock(-6,104,0,quark:quilted_wool:0,10,quark:quilted_wool:0,100)
RandomBlock(-6,105,-5,quark:quilted_wool:0,10,quark:quilted_wool:0,100)
RandomBlock(-6,105,-4,quark:quilted_wool:0,10,quark:quilted_wool:0,100)
RandomBlock(-6,105,-3,quark:quilted_wool:0,10,quark:quilted_wool:0,100)
RandomBlock(-6,105,-2,quark:quilted_wool:0,10,quark:quilted_wool:0,100)
RandomBlock(-6,105,-1,quark:quilted_wool:0,10,quark:quilted_wool:0,100)
RandomBlock(-6,106,-4,quark:quilted_wool:0,10,quark:quilted_wool:0,100)
RandomBlock(-6,106,-3,quark:quilted_wool:0,10,quark:quilted_wool:0,100)
RandomBlock(-6,106,-2,quark:quilted_wool:0,10,quark:quilted_wool:0,100)
Block(-5,5,1,LOG:12)
Block(-5,5,2,LOG:12)
Block(-5,5,3,LOG:12)
Block(-5,5,4,LOG:12)
Block(-5,6,1,LOG:12)
Block(-5,6,2,LOG:12)
Block(-5,6,3,LOG:12)
Block(-5,6,4,LOG:12)
Block(-5,6,5,LOG:12)
Block(-5,7,1,LOG:12)
Block(-5,7,2,LOG:12)
Block(-5,7,3,LOG:12)
Block(-5,7,4,LOG:12)
Block(-5,8,0,LOG:12)
Block(-5,8,1,LOG:12)
Block(-5,8,2,LOG:12)
Block(-5,8,3,quark:leaf_carpet)
Block(-5,9,1,LOG:12)
Block(-5,9,2,quark:leaf_carpet)
Block(-5,10,1,quark:leaf_carpet)
Block(-5,14,-7,LOG:12)
Block(-5,15,-7,LOG:12)
Block(-5,16,-7,LOG:12)
Block(-5,16,-6,LOG:12)
Block(-5,16,-5,LEAVES:0)
Block(-5,17,-7,LOG:12)
Block(-5,17,-6,LOG:12)
Block(-5,17,-5,LEAVES:0)
Block(-5,17,-4,LEAVES:0)
Block(-5,18,-7,LOG:12)
Block(-5,18,-6,LOG:12)
Block(-5,18,-5,LOG:12)
Block(-5,19,-7,LEAVES:0)
Block(-5,19,-6,LOG:12)
Block(-5,19,-5,LOG:12)
Block(-5,19,-4,LOG:12)
Block(-5,20,-7,LOG:12)
Block(-5,20,-6,LOG:12)
Block(-5,20,-5,LOG:12)
Block(-5,20,-4,LOG:12)
Block(-5,21,-7,LOG:12)
Block(-5,21,-6,LOG:12)
Block(-5,21,-5,LOG:12)
Block(-5,21,-4,LOG:12)
Block(-5,21,-3,LOG:12)
Block(-5,22,-7,LOG:12)
Block(-5,22,-6,LOG:12)
Block(-5,22,-5,LOG:12)
Block(-5,22,-4,LOG:12)
Block(-5,22,-3,LOG:12)
Block(-5,23,-7,LOG:12)
Block(-5,23,-6,LOG:12)
Block(-5,23,-5,LOG:12)
Block(-5,23,-4,LOG:12)
Block(-5,23,-3,LOG:12)
Block(-5,24,-7,LOG:12)
Block(-5,24,-6,LOG:12)
Block(-5,24,-5,LOG:12)
Block(-5,24,-4,LOG:12)
Block(-5,24,-3,quark:leaf_carpet)
Block(-5,25,-7,LOG:12)
Block(-5,25,-6,LOG:12)
Block(-5,25,-5,LOG:12)
Block(-5,25,-4,LOG:12)
Block(-5,26,-7,LOG:12)
Block(-5,26,-6,LOG:12)
Block(-5,26,-5,LOG:12)
Block(-5,27,-7,LOG:12)
Block(-5,27,-6,LOG:12)
Block(-5,27,-5,LOG:12)
Block(-5,27,-4,LOG:12)
Block(-5,27,-3,LOG:12)
Block(-5,28,-7,LOG:12)
Block(-5,28,-6,LOG:12)
Block(-5,28,-5,LOG:12)
Block(-5,28,-4,LOG:12)
Block(-5,28,-3,LOG:12)
Block(-5,29,-7,LOG:12)
Block(-5,29,-6,LOG:12)
Block(-5,29,-5,LOG:12)
Block(-5,29,-4,LOG:12)
Block(-5,29,-3,LOG:12)
Block(-5,30,-7,LOG:12)
Block(-5,30,-6,LOG:12)
Block(-5,30,-5,LOG:12)
Block(-5,30,-4,LOG:12)
Block(-5,31,-7,LOG:12)
Block(-5,31,-6,LOG:12)
Block(-5,31,-5,LOG:12)
Block(-5,31,-4,quark:leaf_carpet)
Block(-5,32,-7,LOG:12)
Block(-5,32,-6,LOG:12)
Block(-5,33,-7,LOG:12)
Block(-5,33,-6,LOG:12)
RandomBlock(-5,33,-2,quark:quilted_wool:7,10,quark:quilted_wool:7,100)
RandomBlock(-5,33,-1,quark:quilted_wool:7,10,quark:quilted_wool:7,100)
RandomBlock(-5,33,0,quark:quilted_wool:7,10,quark:quilted_wool:7,100)
RandomBlock(-5,33,1,quark:quilted_wool:7,10,quark:quilted_wool:7,100)
RandomBlock(-5,33,2,quark:quilted_wool:7,10,quark:quilted_wool:7,100)
Block(-5,34,-7,LOG:12)
Block(-5,34,-6,LOG:12)
RandomBlock(-5,34,-3,quark:quilted_wool:7,10,quark:quilted_wool:7,100)
RandomBlock(-5,34,-2,quark:quilted_wool:7,10,quark:quilted_wool:7,100)
RandomBlock(-5,34,-1,quark:quilted_wool:7,10,quark:quilted_wool:7,100)
RandomBlock(-5,34,0,quark:quilted_wool:7,10,quark:quilted_wool:7,100)
RandomBlock(-5,34,1,quark:quilted_wool:7,10,quark:quilted_wool:7,100)
RandomBlock(-5,34,2,quark:quilted_wool:7,10,quark:quilted_wool:7,100)
RandomBlock(-5,34,3,quark:quilted_wool:7,10,quark:quilted_wool:7,100)
Block(-5,35,-7,LOG:12)
Block(-5,35,-6,LOG:12)
RandomBlock(-5,35,-3,quark:quilted_wool:7,10,quark:quilted_wool:7,100)
RandomBlock(-5,35,-2,quark:quilted_wool:7,10,quark:quilted_wool:7,100)
RandomBlock(-5,35,-1,quark:quilted_wool:7,10,quark:quilted_wool:7,100)
RandomBlock(-5,35,0,quark:quilted_wool:7,10,quark:quilted_wool:7,100)
RandomBlock(-5,35,1,quark:quilted_wool:7,10,quark:quilted_wool:7,100)
RandomBlock(-5,35,2,quark:quilted_wool:7,10,quark:quilted_wool:7,100)
RandomBlock(-5,35,3,quark:quilted_wool:7,10,quark:quilted_wool:7,100)
Block(-5,36,-7,LOG:12)
Block(-5,36,-6,LOG:12)
RandomBlock(-5,36,-3,quark:quilted_wool:7,10,quark:quilted_wool:7,100)
RandomBlock(-5,36,-2,quark:quilted_wool:7,10,quark:quilted_wool:7,100)
RandomBlock(-5,36,-1,quark:quilted_wool:7,10,quark:quilted_wool:7,100)
RandomBlock(-5,36,0,quark:quilted_wool:7,10,quark:quilted_wool:7,100)
RandomBlock(-5,36,1,quark:quilted_wool:7,10,quark:quilted_wool:7,100)
RandomBlock(-5,36,2,quark:quilted_wool:7,10,quark:quilted_wool:7,100)
RandomBlock(-5,36,3,quark:quilted_wool:7,10,quark:quilted_wool:7,100)
Block(-5,37,-7,LOG:12)
Block(-5,37,-6,LOG:12)
RandomBlock(-5,37,-4,quark:quilted_wool:7,10,quark:quilted_wool:7,100)
RandomBlock(-5,37,-3,quark:quilted_wool:7,10,quark:quilted_wool:7,100)
RandomBlock(-5,37,-2,quark:quilted_wool:7,10,quark:quilted_wool:7,100)
RandomBlock(-5,37,-1,quark:quilted_wool:7,10,quark:quilted_wool:7,100)
RandomBlock(-5,37,0,quark:quilted_wool:7,10,quark:quilted_wool:7,100)
RandomBlock(-5,37,1,quark:quilted_wool:7,10,quark:quilted_wool:7,100)
RandomBlock(-5,37,2,quark:quilted_wool:7,10,quark:quilted_wool:7,100)
RandomBlock(-5,37,3,quark:quilted_wool:7,10,quark:quilted_wool:7,100)
RandomBlock(-5,37,4,quark:quilted_wool:7,10,quark:quilted_wool:7,100)
Block(-5,38,-7,LOG:12)
Block(-5,38,-6,LOG:12)
RandomBlock(-5,38,-3,quark:quilted_wool:7,10,quark:quilted_wool:7,100)
RandomBlock(-5,38,-2,quark:quilted_wool:7,10,quark:quilted_wool:7,100)
RandomBlock(-5,38,-1,quark:quilted_wool:7,10,quark:quilted_wool:7,100)
RandomBlock(-5,38,0,quark:quilted_wool:7,10,quark:quilted_wool:7,100)
RandomBlock(-5,38,1,quark:quilted_wool:7,10,quark:quilted_wool:7,100)
RandomBlock(-5,38,2,quark:quilted_wool:7,10,quark:quilted_wool:7,100)
RandomBlock(-5,38,3,quark:quilted_wool:7,10,quark:quilted_wool:7,100)
Block(-5,39,-7,LOG:12)
Block(-5,39,-6,LEAVES:0)
RandomBlock(-5,39,-3,quark:quilted_wool:7,10,quark:quilted_wool:7,100)
RandomBlock(-5,39,-2,quark:quilted_wool:7,10,quark:quilted_wool:7,100)
RandomBlock(-5,39,-1,quark:quilted_wool:7,10,quark:quilted_wool:7,100)
RandomBlock(-5,39,0,quark:quilted_wool:7,10,quark:quilted_wool:7,100)
RandomBlock(-5,39,1,quark:quilted_wool:7,10,quark:quilted_wool:7,100)
RandomBlock(-5,39,2,quark:quilted_wool:7,10,quark:quilted_wool:7,100)
RandomBlock(-5,39,3,quark:quilted_wool:7,10,quark:quilted_wool:7,100)
Block(-5,40,-7,LOG:12)
Block(-5,40,-6,LEAVES:0)
RandomBlock(-5,40,-3,quark:quilted_wool:7,10,quark:quilted_wool:7,100)
RandomBlock(-5,40,-2,quark:quilted_wool:7,10,quark:quilted_wool:7,100)
RandomBlock(-5,40,-1,quark:quilted_wool:7,10,quark:quilted_wool:7,100)
RandomBlock(-5,40,0,quark:quilted_wool:7,10,quark:quilted_wool:7,100)
RandomBlock(-5,40,1,quark:quilted_wool:7,10,quark:quilted_wool:7,100)
RandomBlock(-5,40,2,quark:quilted_wool:7,10,quark:quilted_wool:7,100)
RandomBlock(-5,40,3,quark:quilted_wool:7,10,quark:quilted_wool:7,100)
Block(-5,41,-7,LOG:12)
Block(-5,41,-6,LEAVES:0)
Block(-5,41,-5,LEAVES:0)
RandomBlock(-5,41,-2,quark:quilted_wool:7,10,quark:quilted_wool:7,100)
RandomBlock(-5,41,-1,quark:quilted_wool:7,10,quark:quilted_wool:7,100)
RandomBlock(-5,41,0,quark:quilted_wool:7,10,quark:quilted_wool:7,100)
RandomBlock(-5,41,1,quark:quilted_wool:7,10,quark:quilted_wool:7,100)
RandomBlock(-5,41,2,quark:quilted_wool:7,10,quark:quilted_wool:7,100)
Block(-5,42,-7,LOG:12)
Block(-5,42,-6,LEAVES:0)
Block(-5,43,-7,LOG:12)
Block(-5,43,-6,LEAVES:0)
Block(-5,44,-7,LOG:12)
Block(-5,45,-7,LOG:12)
Block(-5,46,-7,LOG:12)
Block(-5,47,-7,LOG:12)
Block(-5,48,-7,LOG:12)
Block(-5,49,-7,LOG:12)
Block(-5,50,-7,LOG:12)
Block(-5,51,-7,LOG:12)
Block(-5,51,0,VINE:4)
Block(-5,52,-7,LOG:12)
Block(-5,52,0,VINE:4)
Block(-5,53,-7,LOG:12)
Block(-5,53,-6,LEAVES:0)
Block(-5,53,-5,LEAVES:0)
Block(-5,53,0,VINE:4)
Block(-5,54,-7,LOG:12)
Block(-5,54,-6,LEAVES:0)
Block(-5,54,-5,LEAVES:0)
Block(-5,54,-4,LEAVES:0)
Block(-5,54,-1,LOG:12)
