
#######################################################################
# +-----------------------------------------------------------------+ #
# |                            BO4 object                           | #
# +-----------------------------------------------------------------+ #
#######################################################################

Author: NLBlackEagle

Description: No description given

SettingsMode: WriteDisable


#######################################################################
# +-----------------------------------------------------------------+ #
# |                          Main settings                          | #
# +-----------------------------------------------------------------+ #
#######################################################################

FixedRotation: 

Frequency: 0

SpawnHeight: highestBlock

UseCenterForHighestBlock: true

##############################
# Height Limits for the BO4. #
##############################

MinHeight: 0

MaxHeight: 255

InheritBO3: 

InheritBO3Rotation: NORTH

OverrideChildSettings: true

OverrideParentHeight: false

CanOverride: false

BranchFrequency: 0

BranchFrequencyGroup: 

MustBeBelowOther: false

MustBeInside: 

CannotBeInside: 

ReplacesBO3: 

MustBeInsideWorldBorders: false

CanSpawnOnWater: true

SpawnOnWaterOnly: false

SpawnUnderWater: false

SpawnAtWaterLevel: false

HeightOffset: 0

RemoveAir: true

ReplaceAbove: 

ReplaceBelow: 

ReplaceWithBiomeBlocks: true

ReplaceWithSurfaceBlock: GRASS

ReplaceWithGroundBlock: DIRT

ReplaceWithStoneBlock: STONE

SmoothRadius: 0

SmoothHeightOffset: 0

SmoothStartTop: false

SmoothStartWood: false

SmoothingSurfaceBlock: 

SmoothingGroundBlock: 

BO3Group: 

IsSpawnPoint: false

DoReplaceBlocks: true


#######################################################################
# +-----------------------------------------------------------------+ #
# |                              Blocks                             | #
# +-----------------------------------------------------------------+ #
#######################################################################

RandomBlock(-8,88,-7,quark:quilted_wool:7,10,quark:quilted_wool:7,100)
RandomBlock(-8,89,-7,quark:quilted_wool:7,10,quark:quilted_wool:7,100)
RandomBlock(-8,89,-6,quark:quilted_wool:7,10,quark:quilted_wool:7,100)
RandomBlock(-8,90,-7,quark:quilted_wool:7,10,quark:quilted_wool:7,100)
RandomBlock(-8,90,-6,quark:quilted_wool:7,10,quark:quilted_wool:7,100)
RandomBlock(-8,91,-7,quark:quilted_wool:7,10,quark:quilted_wool:7,100)
RandomBlock(-8,91,-6,quark:quilted_wool:7,10,quark:quilted_wool:7,100)
RandomBlock(-8,92,-7,quark:quilted_wool:7,10,quark:quilted_wool:7,100)
RandomBlock(-8,92,-6,quark:quilted_wool:7,10,quark:quilted_wool:7,100)
RandomBlock(-8,93,-7,quark:quilted_wool:7,10,quark:quilted_wool:7,100)
RandomBlock(-8,93,-6,quark:quilted_wool:7,10,quark:quilted_wool:7,100)
RandomBlock(-8,94,-7,quark:quilted_wool:7,10,quark:quilted_wool:7,100)
RandomBlock(-8,94,-6,quark:quilted_wool:7,10,quark:quilted_wool:7,100)
RandomBlock(-8,95,-7,quark:quilted_wool:7,10,quark:quilted_wool:7,100)
RandomBlock(-8,95,-6,quark:quilted_wool:7,10,quark:quilted_wool:7,100)
RandomBlock(-8,96,-7,quark:quilted_wool:7,10,quark:quilted_wool:7,100)
RandomBlock(-7,87,-7,quark:quilted_wool:7,10,quark:quilted_wool:7,100)
RandomBlock(-7,88,-7,quark:quilted_wool:7,10,quark:quilted_wool:7,100)
RandomBlock(-7,88,-6,quark:quilted_wool:7,10,quark:quilted_wool:7,100)
RandomBlock(-7,89,-7,quark:quilted_wool:7,10,quark:quilted_wool:7,100)
RandomBlock(-7,89,-6,quark:quilted_wool:7,10,quark:quilted_wool:7,100)
RandomBlock(-7,89,-5,quark:quilted_wool:7,10,quark:quilted_wool:7,100)
RandomBlock(-7,90,-7,quark:quilted_wool:7,10,quark:quilted_wool:7,100)
RandomBlock(-7,90,-6,quark:quilted_wool:7,10,quark:quilted_wool:7,100)
RandomBlock(-7,90,-5,quark:quilted_wool:7,10,quark:quilted_wool:7,100)
RandomBlock(-7,91,-7,quark:quilted_wool:7,10,quark:quilted_wool:7,100)
RandomBlock(-7,91,-6,quark:quilted_wool:7,10,quark:quilted_wool:7,100)
RandomBlock(-7,91,-5,quark:quilted_wool:7,10,quark:quilted_wool:7,100)
RandomBlock(-7,92,-7,quark:quilted_wool:7,10,quark:quilted_wool:7,100)
RandomBlock(-7,92,-6,quark:quilted_wool:7,10,quark:quilted_wool:7,100)
RandomBlock(-7,92,-5,quark:quilted_wool:7,10,quark:quilted_wool:7,100)
RandomBlock(-7,93,-7,quark:quilted_wool:7,10,quark:quilted_wool:7,100)
RandomBlock(-7,93,-6,quark:quilted_wool:7,10,quark:quilted_wool:7,100)
RandomBlock(-7,93,-5,quark:quilted_wool:7,10,quark:quilted_wool:7,100)
RandomBlock(-7,94,-7,quark:quilted_wool:7,10,quark:quilted_wool:7,100)
RandomBlock(-7,94,-6,quark:quilted_wool:7,10,quark:quilted_wool:7,100)
RandomBlock(-7,94,-5,quark:quilted_wool:7,10,quark:quilted_wool:7,100)
RandomBlock(-7,95,-7,quark:quilted_wool:7,10,quark:quilted_wool:7,100)
RandomBlock(-7,95,-6,quark:quilted_wool:7,10,quark:quilted_wool:7,100)
RandomBlock(-7,95,-5,quark:quilted_wool:7,10,quark:quilted_wool:7,100)
RandomBlock(-7,96,-7,quark:quilted_wool:7,10,quark:quilted_wool:7,100)
RandomBlock(-7,96,-6,quark:quilted_wool:7,10,quark:quilted_wool:7,100)
RandomBlock(-7,97,-7,quark:quilted_wool:7,10,quark:quilted_wool:7,100)
RandomBlock(-6,86,-7,quark:quilted_wool:7,10,quark:quilted_wool:7,100)
RandomBlock(-6,87,-7,quark:quilted_wool:7,10,quark:quilted_wool:7,100)
RandomBlock(-6,87,-6,quark:quilted_wool:7,10,quark:quilted_wool:7,100)
RandomBlock(-6,88,-7,quark:quilted_wool:7,10,quark:quilted_wool:7,100)
RandomBlock(-6,88,-6,quark:quilted_wool:7,10,quark:quilted_wool:7,100)
RandomBlock(-6,88,-5,quark:quilted_wool:7,10,quark:quilted_wool:7,100)
RandomBlock(-6,89,-7,quark:quilted_wool:7,10,quark:quilted_wool:7,100)
RandomBlock(-6,89,-6,quark:quilted_wool:7,10,quark:quilted_wool:7,100)
RandomBlock(-6,89,-5,quark:quilted_wool:7,10,quark:quilted_wool:7,100)
RandomBlock(-6,90,-7,quark:quilted_wool:7,10,quark:quilted_wool:7,100)
RandomBlock(-6,90,-6,quark:quilted_wool:7,10,quark:quilted_wool:7,100)
RandomBlock(-6,90,-5,quark:quilted_wool:7,10,quark:quilted_wool:7,100)
RandomBlock(-6,91,-7,quark:quilted_wool:7,10,quark:quilted_wool:7,100)
RandomBlock(-6,91,-6,quark:quilted_wool:7,10,quark:quilted_wool:7,100)
RandomBlock(-6,91,-5,quark:quilted_wool:7,10,quark:quilted_wool:7,100)
RandomBlock(-6,91,-4,quark:quilted_wool:7,10,quark:quilted_wool:7,100)
RandomBlock(-6,92,-7,quark:quilted_wool:7,10,quark:quilted_wool:7,100)
RandomBlock(-6,92,-6,quark:quilted_wool:7,10,quark:quilted_wool:7,100)
RandomBlock(-6,92,-5,quark:quilted_wool:7,10,quark:quilted_wool:7,100)
RandomBlock(-6,92,-4,quark:quilted_wool:7,10,quark:quilted_wool:7,100)
RandomBlock(-6,93,-7,quark:quilted_wool:7,10,quark:quilted_wool:7,100)
RandomBlock(-6,93,-6,quark:quilted_wool:7,10,quark:quilted_wool:7,100)
RandomBlock(-6,93,-5,quark:quilted_wool:7,10,quark:quilted_wool:7,100)
RandomBlock(-6,93,-4,quark:quilted_wool:7,10,quark:quilted_wool:7,100)
RandomBlock(-6,94,-7,quark:quilted_wool:7,10,quark:quilted_wool:7,100)
RandomBlock(-6,94,-6,quark:quilted_wool:7,10,quark:quilted_wool:7,100)
RandomBlock(-6,94,-5,quark:quilted_wool:7,10,quark:quilted_wool:7,100)
RandomBlock(-6,95,-7,quark:quilted_wool:7,10,quark:quilted_wool:7,100)
RandomBlock(-6,95,-6,quark:quilted_wool:7,10,quark:quilted_wool:7,100)
RandomBlock(-6,95,-5,quark:quilted_wool:7,10,quark:quilted_wool:7,100)
RandomBlock(-6,96,-7,quark:quilted_wool:7,10,quark:quilted_wool:7,100)
RandomBlock(-6,96,-6,quark:quilted_wool:7,10,quark:quilted_wool:7,100)
RandomBlock(-6,96,-5,quark:quilted_wool:7,10,quark:quilted_wool:7,100)
RandomBlock(-6,97,-7,quark:quilted_wool:7,10,quark:quilted_wool:7,100)
RandomBlock(-6,97,-6,quark:quilted_wool:7,10,quark:quilted_wool:7,100)
RandomBlock(-6,98,-7,quark:quilted_wool:7,10,quark:quilted_wool:7,100)
RandomBlock(-5,86,-7,quark:quilted_wool:7,10,quark:quilted_wool:7,100)
RandomBlock(-5,86,-6,quark:quilted_wool:7,10,quark:quilted_wool:7,100)
RandomBlock(-5,87,-7,quark:quilted_wool:7,10,quark:quilted_wool:7,100)
RandomBlock(-5,87,-6,quark:quilted_wool:7,10,quark:quilted_wool:7,100)
RandomBlock(-5,88,-7,quark:quilted_wool:7,10,quark:quilted_wool:7,100)
RandomBlock(-5,88,-6,quark:quilted_wool:7,10,quark:quilted_wool:7,100)
RandomBlock(-5,88,-5,quark:quilted_wool:7,10,quark:quilted_wool:7,100)
RandomBlock(-5,89,-7,quark:quilted_wool:7,10,quark:quilted_wool:7,100)
RandomBlock(-5,89,-6,quark:quilted_wool:7,10,quark:quilted_wool:7,100)
RandomBlock(-5,89,-5,quark:quilted_wool:7,10,quark:quilted_wool:7,100)
RandomBlock(-5,90,-7,quark:quilted_wool:7,10,quark:quilted_wool:7,100)
RandomBlock(-5,90,-6,quark:quilted_wool:7,10,quark:quilted_wool:7,100)
RandomBlock(-5,90,-5,quark:quilted_wool:7,10,quark:quilted_wool:7,100)
RandomBlock(-5,90,-4,quark:quilted_wool:7,10,quark:quilted_wool:7,100)
RandomBlock(-5,91,-7,quark:quilted_wool:7,10,quark:quilted_wool:7,100)
RandomBlock(-5,91,-6,quark:quilted_wool:7,10,quark:quilted_wool:7,100)
RandomBlock(-5,91,-5,quark:quilted_wool:7,10,quark:quilted_wool:7,100)
RandomBlock(-5,91,-4,quark:quilted_wool:7,10,quark:quilted_wool:7,100)
RandomBlock(-5,92,-7,quark:quilted_wool:7,10,quark:quilted_wool:7,100)
RandomBlock(-5,92,-6,quark:quilted_wool:7,10,quark:quilted_wool:7,100)
RandomBlock(-5,92,-5,quark:quilted_wool:7,10,quark:quilted_wool:7,100)
RandomBlock(-5,92,-4,quark:quilted_wool:7,10,quark:quilted_wool:7,100)
RandomBlock(-5,93,-7,quark:quilted_wool:7,10,quark:quilted_wool:7,100)
RandomBlock(-5,93,-6,quark:quilted_wool:7,10,quark:quilted_wool:7,100)
RandomBlock(-5,93,-5,quark:quilted_wool:7,10,quark:quilted_wool:7,100)
RandomBlock(-5,93,-4,quark:quilted_wool:7,10,quark:quilted_wool:7,100)
RandomBlock(-5,94,-7,quark:quilted_wool:7,10,quark:quilted_wool:7,100)
RandomBlock(-5,94,-6,quark:quilted_wool:7,10,quark:quilted_wool:7,100)
RandomBlock(-5,94,-5,quark:quilted_wool:7,10,quark:quilted_wool:7,100)
RandomBlock(-5,94,-4,quark:quilted_wool:7,10,quark:quilted_wool:7,100)
RandomBlock(-5,95,-7,quark:quilted_wool:7,10,quark:quilted_wool:7,100)
RandomBlock(-5,95,-6,quark:quilted_wool:7,10,quark:quilted_wool:7,100)
RandomBlock(-5,95,-5,quark:quilted_wool:7,10,quark:quilted_wool:7,100)
RandomBlock(-5,96,-7,quark:quilted_wool:7,10,quark:quilted_wool:7,100)
RandomBlock(-5,96,-6,quark:quilted_wool:7,10,quark:quilted_wool:7,100)
RandomBlock(-5,96,-5,quark:quilted_wool:7,10,quark:quilted_wool:7,100)
RandomBlock(-5,97,-7,quark:quilted_wool:7,10,quark:quilted_wool:7,100)
RandomBlock(-5,97,-6,quark:quilted_wool:7,10,quark:quilted_wool:7,100)
RandomBlock(-5,98,-7,quark:quilted_wool:7,10,quark:quilted_wool:7,100)
RandomBlock(-5,98,-6,quark:quilted_wool:7,10,quark:quilted_wool:7,100)
Block(-4,78,-7,LEAVES:0)
Block(-4,78,-6,LEAVES:0)
Block(-4,79,-7,LEAVES:0)
Block(-4,80,-7,LEAVES:0)
RandomBlock(-4,86,-7,quark:quilted_wool:7,10,quark:quilted_wool:7,100)
RandomBlock(-4,86,-6,quark:quilted_wool:7,10,quark:quilted_wool:7,100)
RandomBlock(-4,87,-7,quark:quilted_wool:7,10,quark:quilted_wool:7,100)
RandomBlock(-4,87,-6,quark:quilted_wool:7,10,quark:quilted_wool:7,100)
RandomBlock(-4,87,-5,quark:quilted_wool:7,10,quark:quilted_wool:7,100)
RandomBlock(-4,88,-7,quark:quilted_wool:7,10,quark:quilted_wool:7,100)
RandomBlock(-4,88,-6,quark:quilted_wool:7,10,quark:quilted_wool:7,100)
RandomBlock(-4,88,-5,quark:quilted_wool:7,10,quark:quilted_wool:7,100)
RandomBlock(-4,89,-7,quark:quilted_wool:7,10,quark:quilted_wool:7,100)
RandomBlock(-4,89,-6,quark:quilted_wool:7,10,quark:quilted_wool:7,100)
RandomBlock(-4,89,-5,quark:quilted_wool:7,10,quark:quilted_wool:7,100)
RandomBlock(-4,89,-4,quark:quilted_wool:7,10,quark:quilted_wool:7,100)
RandomBlock(-4,90,-7,quark:quilted_wool:7,10,quark:quilted_wool:7,100)
RandomBlock(-4,90,-6,quark:quilted_wool:7,10,quark:quilted_wool:7,100)
RandomBlock(-4,90,-5,quark:quilted_wool:7,10,quark:quilted_wool:7,100)
RandomBlock(-4,90,-4,quark:quilted_wool:7,10,quark:quilted_wool:7,100)
RandomBlock(-4,91,-7,quark:quilted_wool:7,10,quark:quilted_wool:7,100)
RandomBlock(-4,91,-6,quark:quilted_wool:7,10,quark:quilted_wool:7,100)
RandomBlock(-4,91,-5,quark:quilted_wool:7,10,quark:quilted_wool:7,100)
RandomBlock(-4,91,-4,quark:quilted_wool:7,10,quark:quilted_wool:7,100)
RandomBlock(-4,92,-7,quark:quilted_wool:7,10,quark:quilted_wool:7,100)
RandomBlock(-4,92,-6,quark:quilted_wool:7,10,quark:quilted_wool:7,100)
RandomBlock(-4,92,-5,quark:quilted_wool:7,10,quark:quilted_wool:7,100)
RandomBlock(-4,92,-4,quark:quilted_wool:7,10,quark:quilted_wool:7,100)
RandomBlock(-4,93,-7,quark:quilted_wool:7,10,quark:quilted_wool:7,100)
RandomBlock(-4,93,-6,quark:quilted_wool:7,10,quark:quilted_wool:7,100)
RandomBlock(-4,93,-5,quark:quilted_wool:7,10,quark:quilted_wool:7,100)
RandomBlock(-4,93,-4,quark:quilted_wool:7,10,quark:quilted_wool:7,100)
RandomBlock(-4,94,-7,quark:quilted_wool:7,10,quark:quilted_wool:7,100)
RandomBlock(-4,94,-6,quark:quilted_wool:7,10,quark:quilted_wool:7,100)
RandomBlock(-4,94,-5,quark:quilted_wool:7,10,quark:quilted_wool:7,100)
RandomBlock(-4,94,-4,quark:quilted_wool:7,10,quark:quilted_wool:7,100)
RandomBlock(-4,95,-7,quark:quilted_wool:7,10,quark:quilted_wool:7,100)
RandomBlock(-4,95,-6,quark:quilted_wool:7,10,quark:quilted_wool:7,100)
RandomBlock(-4,95,-5,quark:quilted_wool:7,10,quark:quilted_wool:7,100)
RandomBlock(-4,95,-4,quark:quilted_wool:7,10,quark:quilted_wool:7,100)
RandomBlock(-4,96,-7,quark:quilted_wool:7,10,quark:quilted_wool:7,100)
RandomBlock(-4,96,-6,quark:quilted_wool:7,10,quark:quilted_wool:7,100)
RandomBlock(-4,96,-5,quark:quilted_wool:7,10,quark:quilted_wool:7,100)
RandomBlock(-4,97,-7,quark:quilted_wool:7,10,quark:quilted_wool:7,100)
RandomBlock(-4,97,-6,quark:quilted_wool:7,10,quark:quilted_wool:7,100)
RandomBlock(-4,97,-5,quark:quilted_wool:7,10,quark:quilted_wool:7,100)
RandomBlock(-4,98,-7,quark:quilted_wool:7,10,quark:quilted_wool:7,100)
RandomBlock(-4,98,-6,quark:quilted_wool:7,10,quark:quilted_wool:7,100)
Block(-3,77,-7,LEAVES:0)
Block(-3,78,-7,LEAVES:0)
Block(-3,78,-6,LEAVES:0)
Block(-3,78,-5,LEAVES:0)
Block(-3,79,-7,LEAVES:0)
Block(-3,79,-6,LEAVES:0)
Block(-3,80,-7,LEAVES:0)
RandomBlock(-3,86,-7,quark:quilted_wool:7,10,quark:quilted_wool:7,100)
RandomBlock(-3,86,-6,quark:quilted_wool:7,10,quark:quilted_wool:7,100)
RandomBlock(-3,87,-7,quark:quilted_wool:7,10,quark:quilted_wool:7,100)
RandomBlock(-3,87,-6,quark:quilted_wool:7,10,quark:quilted_wool:7,100)
RandomBlock(-3,88,-7,quark:quilted_wool:7,10,quark:quilted_wool:7,100)
RandomBlock(-3,88,-6,quark:quilted_wool:7,10,quark:quilted_wool:7,100)
RandomBlock(-3,88,-5,quark:quilted_wool:7,10,quark:quilted_wool:7,100)
RandomBlock(-3,89,-7,quark:quilted_wool:7,10,quark:quilted_wool:7,100)
RandomBlock(-3,89,-6,quark:quilted_wool:7,10,quark:quilted_wool:7,100)
RandomBlock(-3,89,-5,quark:quilted_wool:7,10,quark:quilted_wool:7,100)
RandomBlock(-3,90,-7,quark:quilted_wool:7,10,quark:quilted_wool:7,100)
RandomBlock(-3,90,-6,quark:quilted_wool:7,10,quark:quilted_wool:7,100)
RandomBlock(-3,90,-5,quark:quilted_wool:7,10,quark:quilted_wool:7,100)
RandomBlock(-3,90,-4,quark:quilted_wool:7,10,quark:quilted_wool:7,100)
RandomBlock(-3,91,-7,quark:quilted_wool:7,10,quark:quilted_wool:7,100)
RandomBlock(-3,91,-6,quark:quilted_wool:7,10,quark:quilted_wool:7,100)
RandomBlock(-3,91,-5,quark:quilted_wool:7,10,quark:quilted_wool:7,100)
RandomBlock(-3,91,-4,quark:quilted_wool:7,10,quark:quilted_wool:7,100)
RandomBlock(-3,92,-7,quark:quilted_wool:7,10,quark:quilted_wool:7,100)
RandomBlock(-3,92,-6,quark:quilted_wool:7,10,quark:quilted_wool:7,100)
RandomBlock(-3,92,-5,quark:quilted_wool:7,10,quark:quilted_wool:7,100)
RandomBlock(-3,92,-4,quark:quilted_wool:7,10,quark:quilted_wool:7,100)
RandomBlock(-3,93,-7,quark:quilted_wool:7,10,quark:quilted_wool:7,100)
RandomBlock(-3,93,-6,quark:quilted_wool:7,10,quark:quilted_wool:7,100)
RandomBlock(-3,93,-5,quark:quilted_wool:7,10,quark:quilted_wool:7,100)
RandomBlock(-3,93,-4,quark:quilted_wool:7,10,quark:quilted_wool:7,100)
RandomBlock(-3,94,-7,quark:quilted_wool:7,10,quark:quilted_wool:7,100)
RandomBlock(-3,94,-6,quark:quilted_wool:7,10,quark:quilted_wool:7,100)
RandomBlock(-3,94,-5,quark:quilted_wool:7,10,quark:quilted_wool:7,100)
RandomBlock(-3,94,-4,quark:quilted_wool:7,10,quark:quilted_wool:7,100)
RandomBlock(-3,95,-7,quark:quilted_wool:7,10,quark:quilted_wool:7,100)
RandomBlock(-3,95,-6,quark:quilted_wool:7,10,quark:quilted_wool:7,100)
RandomBlock(-3,95,-5,quark:quilted_wool:7,10,quark:quilted_wool:7,100)
RandomBlock(-3,96,-7,quark:quilted_wool:7,10,quark:quilted_wool:7,100)
RandomBlock(-3,96,-6,quark:quilted_wool:7,10,quark:quilted_wool:7,100)
RandomBlock(-3,96,-5,quark:quilted_wool:7,10,quark:quilted_wool:7,100)
RandomBlock(-3,97,-7,quark:quilted_wool:7,10,quark:quilted_wool:7,100)
RandomBlock(-3,97,-6,quark:quilted_wool:7,10,quark:quilted_wool:7,100)
RandomBlock(-3,98,-7,quark:quilted_wool:7,10,quark:quilted_wool:7,100)
RandomBlock(-3,98,-6,quark:quilted_wool:7,10,quark:quilted_wool:7,100)
Block(-2,77,-7,LOG:12)
Block(-2,77,-6,LEAVES:0)
Block(-2,78,-7,LEAVES:0)
Block(-2,78,-6,LEAVES:0)
Block(-2,78,-5,LEAVES:0)
Block(-2,79,-7,LEAVES:0)
Block(-2,79,-6,LEAVES:0)
Block(-2,79,-5,LEAVES:0)
Block(-2,80,-7,LEAVES:0)
Block(-2,80,-6,LEAVES:0)
Block(-2,81,-7,LEAVES:0)
RandomBlock(-2,86,-7,quark:quilted_wool:7,10,quark:quilted_wool:7,100)
RandomBlock(-2,87,-7,quark:quilted_wool:7,10,quark:quilted_wool:7,100)
RandomBlock(-2,87,-6,quark:quilted_wool:7,10,quark:quilted_wool:7,100)
RandomBlock(-2,88,-7,quark:quilted_wool:7,10,quark:quilted_wool:7,100)
RandomBlock(-2,88,-6,quark:quilted_wool:7,10,quark:quilted_wool:7,100)
RandomBlock(-2,88,-5,quark:quilted_wool:7,10,quark:quilted_wool:7,100)
RandomBlock(-2,89,-7,quark:quilted_wool:7,10,quark:quilted_wool:7,100)
RandomBlock(-2,89,-6,quark:quilted_wool:7,10,quark:quilted_wool:7,100)
RandomBlock(-2,89,-5,quark:quilted_wool:7,10,quark:quilted_wool:7,100)
RandomBlock(-2,90,-7,quark:quilted_wool:7,10,quark:quilted_wool:7,100)
RandomBlock(-2,90,-6,quark:quilted_wool:7,10,quark:quilted_wool:7,100)
RandomBlock(-2,90,-5,quark:quilted_wool:7,10,quark:quilted_wool:7,100)
RandomBlock(-2,91,-7,quark:quilted_wool:7,10,quark:quilted_wool:7,100)
RandomBlock(-2,91,-6,quark:quilted_wool:7,10,quark:quilted_wool:7,100)
RandomBlock(-2,91,-5,quark:quilted_wool:7,10,quark:quilted_wool:7,100)
RandomBlock(-2,91,-4,quark:quilted_wool:7,10,quark:quilted_wool:7,100)
RandomBlock(-2,92,-7,quark:quilted_wool:7,10,quark:quilted_wool:7,100)
RandomBlock(-2,92,-6,quark:quilted_wool:7,10,quark:quilted_wool:7,100)
RandomBlock(-2,92,-5,quark:quilted_wool:7,10,quark:quilted_wool:7,100)
RandomBlock(-2,92,-4,quark:quilted_wool:7,10,quark:quilted_wool:7,100)
RandomBlock(-2,93,-7,quark:quilted_wool:7,10,quark:quilted_wool:7,100)
RandomBlock(-2,93,-6,quark:quilted_wool:7,10,quark:quilted_wool:7,100)
RandomBlock(-2,93,-5,quark:quilted_wool:7,10,quark:quilted_wool:7,100)
RandomBlock(-2,93,-4,quark:quilted_wool:7,10,quark:quilted_wool:7,100)
RandomBlock(-2,94,-7,quark:quilted_wool:7,10,quark:quilted_wool:7,100)
RandomBlock(-2,94,-6,quark:quilted_wool:7,10,quark:quilted_wool:7,100)
RandomBlock(-2,94,-5,quark:quilted_wool:7,10,quark:quilted_wool:7,100)
RandomBlock(-2,95,-7,quark:quilted_wool:7,10,quark:quilted_wool:7,100)
RandomBlock(-2,95,-6,quark:quilted_wool:7,10,quark:quilted_wool:7,100)
RandomBlock(-2,95,-5,quark:quilted_wool:7,10,quark:quilted_wool:7,100)
RandomBlock(-2,96,-7,quark:quilted_wool:7,10,quark:quilted_wool:7,100)
RandomBlock(-2,96,-6,quark:quilted_wool:7,10,quark:quilted_wool:7,100)
RandomBlock(-2,96,-5,quark:quilted_wool:7,10,quark:quilted_wool:7,100)
RandomBlock(-2,97,-7,quark:quilted_wool:7,10,quark:quilted_wool:7,100)
RandomBlock(-2,97,-6,quark:quilted_wool:7,10,quark:quilted_wool:7,100)
RandomBlock(-2,98,-7,quark:quilted_wool:7,10,quark:quilted_wool:7,100)
Block(-1,77,-7,LEAVES:0)
Block(-1,78,-7,LEAVES:0)
Block(-1,78,-6,LEAVES:0)
Block(-1,78,-5,LEAVES:0)
Block(-1,79,-7,LEAVES:0)
Block(-1,79,-6,LEAVES:0)
Block(-1,79,-5,LEAVES:0)
Block(-1,80,-7,LEAVES:0)
Block(-1,80,-6,LEAVES:0)
Block(-1,81,-7,LEAVES:0)
RandomBlock(-1,87,-7,quark:quilted_wool:7,10,quark:quilted_wool:7,100)
RandomBlock(-1,88,-7,quark:quilted_wool:7,10,quark:quilted_wool:7,100)
RandomBlock(-1,88,-6,quark:quilted_wool:7,10,quark:quilted_wool:7,100)
RandomBlock(-1,89,-7,quark:quilted_wool:7,10,quark:quilted_wool:7,100)
RandomBlock(-1,89,-6,quark:quilted_wool:7,10,quark:quilted_wool:7,100)
RandomBlock(-1,89,-5,quark:quilted_wool:7,10,quark:quilted_wool:7,100)
RandomBlock(-1,90,-7,quark:quilted_wool:7,10,quark:quilted_wool:7,100)
RandomBlock(-1,90,-6,quark:quilted_wool:7,10,quark:quilted_wool:7,100)
RandomBlock(-1,90,-5,quark:quilted_wool:7,10,quark:quilted_wool:7,100)
RandomBlock(-1,91,-7,quark:quilted_wool:7,10,quark:quilted_wool:7,100)
RandomBlock(-1,91,-6,quark:quilted_wool:7,10,quark:quilted_wool:7,100)
RandomBlock(-1,91,-5,quark:quilted_wool:7,10,quark:quilted_wool:7,100)
RandomBlock(-1,92,-7,quark:quilted_wool:7,10,quark:quilted_wool:7,100)
RandomBlock(-1,92,-6,quark:quilted_wool:7,10,quark:quilted_wool:7,100)
RandomBlock(-1,92,-5,quark:quilted_wool:7,10,quark:quilted_wool:7,100)
RandomBlock(-1,93,-7,quark:quilted_wool:7,10,quark:quilted_wool:7,100)
RandomBlock(-1,93,-6,quark:quilted_wool:7,10,quark:quilted_wool:7,100)
RandomBlock(-1,93,-5,quark:quilted_wool:7,10,quark:quilted_wool:7,100)
RandomBlock(-1,94,-7,quark:quilted_wool:7,10,quark:quilted_wool:7,100)
RandomBlock(-1,94,-6,quark:quilted_wool:7,10,quark:quilted_wool:7,100)
RandomBlock(-1,94,-5,quark:quilted_wool:7,10,quark:quilted_wool:7,100)
RandomBlock(-1,95,-7,quark:quilted_wool:7,10,quark:quilted_wool:7,100)
RandomBlock(-1,95,-6,quark:quilted_wool:7,10,quark:quilted_wool:7,100)
RandomBlock(-1,95,-5,quark:quilted_wool:7,10,quark:quilted_wool:7,100)
RandomBlock(-1,96,-7,quark:quilted_wool:7,10,quark:quilted_wool:7,100)
RandomBlock(-1,96,-6,quark:quilted_wool:7,10,quark:quilted_wool:7,100)
RandomBlock(-1,97,-7,quark:quilted_wool:7,10,quark:quilted_wool:7,100)
Block(0,78,-7,LEAVES:0)
Block(0,78,-6,LEAVES:0)
Block(0,79,-7,LEAVES:0)
Block(0,79,-6,LEAVES:0)
Block(0,80,-7,LEAVES:0)
RandomBlock(0,88,-7,quark:quilted_wool:7,10,quark:quilted_wool:7,100)
RandomBlock(0,89,-7,quark:quilted_wool:7,10,quark:quilted_wool:7,100)
RandomBlock(0,89,-6,quark:quilted_wool:7,10,quark:quilted_wool:7,100)
RandomBlock(0,90,-7,quark:quilted_wool:7,10,quark:quilted_wool:7,100)
RandomBlock(0,90,-6,quark:quilted_wool:7,10,quark:quilted_wool:7,100)
RandomBlock(0,91,-7,quark:quilted_wool:7,10,quark:quilted_wool:7,100)
RandomBlock(0,91,-6,quark:quilted_wool:7,10,quark:quilted_wool:7,100)
RandomBlock(0,92,-7,quark:quilted_wool:7,10,quark:quilted_wool:7,100)
RandomBlock(0,92,-6,quark:quilted_wool:7,10,quark:quilted_wool:7,100)
RandomBlock(0,93,-7,quark:quilted_wool:7,10,quark:quilted_wool:7,100)
RandomBlock(0,93,-6,quark:quilted_wool:7,10,quark:quilted_wool:7,100)
RandomBlock(0,94,-7,quark:quilted_wool:7,10,quark:quilted_wool:7,100)
RandomBlock(0,94,-6,quark:quilted_wool:7,10,quark:quilted_wool:7,100)
RandomBlock(0,95,-7,quark:quilted_wool:7,10,quark:quilted_wool:7,100)
RandomBlock(0,95,-6,quark:quilted_wool:7,10,quark:quilted_wool:7,100)
RandomBlock(0,96,-7,quark:quilted_wool:7,10,quark:quilted_wool:7,100)
RandomBlock(1,91,-7,quark:quilted_wool:7,10,quark:quilted_wool:7,100)
RandomBlock(1,92,-7,quark:quilted_wool:7,10,quark:quilted_wool:7,100)
RandomBlock(1,93,-7,quark:quilted_wool:7,10,quark:quilted_wool:7,100)

#######################################################################
# +-----------------------------------------------------------------+ #
# |                             Branches                            | #
# +-----------------------------------------------------------------+ #
#######################################################################

Branch(-16,0,0,true,TreeTestC0R3,NORTH,100.0,0)

#######################################################################
# +-----------------------------------------------------------------+ #
# |                             Entities                            | #
# +-----------------------------------------------------------------+ #
#######################################################################


#######################################################################
# +-----------------------------------------------------------------+ #
# |                            Particles                            | #
# +-----------------------------------------------------------------+ #
#######################################################################


#######################################################################
# +-----------------------------------------------------------------+ #
# |                             Spawners                            | #
# +-----------------------------------------------------------------+ #
#######################################################################


#######################################################################
# +-----------------------------------------------------------------+ #
# |                             ModData                             | #
# +-----------------------------------------------------------------+ #
#######################################################################

