
#######################################################################
# +-----------------------------------------------------------------+ #
# |                            BO4 object                           | #
# +-----------------------------------------------------------------+ #
#######################################################################

Author: NLBlackEagle

Description: No description given

SettingsMode: WriteDisable


#######################################################################
# +-----------------------------------------------------------------+ #
# |                          Main settings                          | #
# +-----------------------------------------------------------------+ #
#######################################################################

FixedRotation: 

Frequency: 0

SpawnHeight: highestBlock

UseCenterForHighestBlock: true

##############################
# Height Limits for the BO4. #
##############################

MinHeight: 0

MaxHeight: 255

InheritBO3: 

InheritBO3Rotation: NORTH

OverrideChildSettings: true

OverrideParentHeight: false

CanOverride: false

BranchFrequency: 0

BranchFrequencyGroup: 

MustBeBelowOther: false

MustBeInside: 

CannotBeInside: 

ReplacesBO3: 

MustBeInsideWorldBorders: false

CanSpawnOnWater: true

SpawnOnWaterOnly: false

SpawnUnderWater: false

SpawnAtWaterLevel: false

HeightOffset: 0

RemoveAir: true

ReplaceAbove: 

ReplaceBelow: 

ReplaceWithBiomeBlocks: true

ReplaceWithSurfaceBlock: GRASS

ReplaceWithGroundBlock: DIRT

ReplaceWithStoneBlock: STONE

SmoothRadius: 0

SmoothHeightOffset: 0

SmoothStartTop: false

SmoothStartWood: false

SmoothingSurfaceBlock: 

SmoothingGroundBlock: 

BO3Group: 

IsSpawnPoint: false

DoReplaceBlocks: true


#######################################################################
# +-----------------------------------------------------------------+ #
# |                              Blocks                             | #
# +-----------------------------------------------------------------+ #
#######################################################################

Block(-8,11,8,LOG:12)
Block(-8,12,7,LOG:12)
Block(-8,12,8,LOG:12)
Block(-8,13,-3,LOG:12)
Block(-8,13,3,LOG:12)
Block(-8,13,7,LOG:12)
Block(-8,13,8,LOG:12)
Block(-8,14,-4,LOG:12)
Block(-8,14,-3,LOG:12)
Block(-8,14,-2,LOG:12)
Block(-8,14,2,LOG:12)
Block(-8,14,3,LOG:12)
Block(-8,14,4,LOG:12)
Block(-8,14,8,LOG:12)
Block(-8,15,-5,LOG:12)
Block(-8,15,-4,LOG:12)
Block(-8,15,-3,LOG:12)
Block(-8,15,2,LOG:12)
Block(-8,15,3,LOG:12)
Block(-8,15,4,LOG:12)
Block(-8,16,-4,LOG:12)
Block(-8,16,-3,LOG:12)
Block(-8,16,-2,LOG:12)
Block(-8,16,2,LOG:12)
Block(-8,16,3,LOG:12)
Block(-8,16,4,LOG:12)
Block(-8,16,8,LOG:12)
Block(-8,17,-5,LEAVES:0)
Block(-8,17,-4,LOG:12)
Block(-8,17,-3,LOG:12)
Block(-8,17,-2,LOG:12)
Block(-8,17,2,LOG:12)
Block(-8,17,3,LOG:12)
Block(-8,17,4,LOG:12)
Block(-8,17,5,LEAVES:0)
Block(-8,18,-4,LOG:12)
Block(-8,18,-3,LOG:12)
Block(-8,18,-2,LOG:12)
Block(-8,18,1,LEAVES:0)
Block(-8,18,2,LOG:12)
Block(-8,18,3,LOG:12)
Block(-8,18,4,LOG:12)
Block(-8,18,5,LEAVES:0)
Block(-8,18,6,LEAVES:0)
Block(-8,19,-5,LEAVES:0)
Block(-8,19,-4,quark:leaf_carpet)
Block(-8,19,-3,LOG:12)
Block(-8,19,0,LEAVES:0)
Block(-8,19,1,LEAVES:0)
Block(-8,19,2,LOG:12)
Block(-8,19,3,LOG:12)
Block(-8,19,4,LOG:12)
Block(-8,19,5,LOG:12)
Block(-8,19,6,LEAVES:0)
Block(-8,19,7,LEAVES:0)
Block(-8,20,-4,LEAVES:0)
Block(-8,20,-3,quark:leaf_carpet)
Block(-8,20,0,LEAVES:0)
Block(-8,20,1,LOG:12)
Block(-8,20,2,LOG:12)
Block(-8,20,3,LOG:12)
Block(-8,20,4,LOG:12)
Block(-8,20,5,LOG:12)
Block(-8,20,6,LOG:12)
Block(-8,21,-4,LEAVES:0)
Block(-8,21,0,LOG:12)
Block(-8,21,1,LOG:12)
Block(-8,21,2,LOG:12)
Block(-8,21,3,LOG:12)
Block(-8,21,4,LOG:12)
Block(-8,21,5,LOG:12)
Block(-8,21,6,LOG:12)
Block(-8,21,7,LOG:12)
Block(-8,22,-3,LEAVES:0)
Block(-8,22,-1,LOG:12)
Block(-8,22,0,LOG:12)
Block(-8,22,1,LOG:12)
Block(-8,22,2,LOG:12)
Block(-8,22,3,LOG:12)
Block(-8,22,4,LOG:12)
Block(-8,22,5,LOG:12)
Block(-8,22,6,LOG:12)
Block(-8,22,7,LOG:12)
Block(-8,23,-1,LOG:12)
Block(-8,23,0,LOG:12)
Block(-8,23,1,LOG:12)
Block(-8,23,2,LOG:12)
Block(-8,23,3,LOG:12)
Block(-8,23,4,LOG:12)
Block(-8,23,5,LOG:12)
Block(-8,23,6,LOG:12)
Block(-8,23,7,LOG:12)
Block(-8,24,-1,LOG:12)
Block(-8,24,0,LOG:12)
Block(-8,24,1,LOG:12)
Block(-8,24,2,LOG:12)
Block(-8,24,3,LOG:12)
Block(-8,24,4,LOG:12)
Block(-8,24,5,LOG:12)
Block(-8,24,6,LOG:12)
Block(-8,24,7,LOG:12)
Block(-8,25,1,LOG:12)
Block(-8,25,2,LOG:12)
Block(-8,25,3,LOG:12)
Block(-8,25,4,LOG:12)
Block(-8,25,5,LOG:12)
Block(-8,25,6,LOG:12)
Block(-8,25,7,LOG:12)
Block(-8,26,0,LOG:12)
Block(-8,26,1,LOG:12)
Block(-8,26,2,LOG:12)
Block(-8,26,3,LOG:12)
Block(-8,26,4,LOG:12)
Block(-8,26,5,LOG:12)
Block(-8,26,6,LOG:12)
Block(-8,26,7,LOG:12)
Block(-8,27,0,LOG:12)
Block(-8,27,1,LOG:12)
Block(-8,27,2,LOG:12)
Block(-8,27,3,LOG:12)
Block(-8,27,4,LOG:12)
Block(-8,27,5,LOG:12)
Block(-8,27,6,LOG:12)
Block(-8,27,7,LOG:12)
Block(-8,28,-1,LOG:12)
Block(-8,28,0,LOG:12)
Block(-8,28,1,LOG:12)
Block(-8,28,2,LOG:12)
Block(-8,28,3,LOG:12)
Block(-8,28,4,LOG:12)
Block(-8,28,5,LOG:12)
Block(-8,28,6,LOG:12)
Block(-8,28,7,LOG:12)
Block(-8,29,0,LOG:12)
Block(-8,29,1,LOG:12)
Block(-8,29,2,LOG:12)
Block(-8,29,3,LOG:12)
Block(-8,29,4,LOG:12)
Block(-8,29,5,LOG:12)
Block(-8,29,6,LOG:12)
Block(-8,29,7,LOG:12)
Block(-8,30,-1,LOG:12)
Block(-8,30,0,LOG:12)
Block(-8,30,1,LOG:12)
Block(-8,30,2,LOG:12)
Block(-8,30,3,LOG:12)
Block(-8,30,4,LOG:12)
Block(-8,30,5,LOG:12)
Block(-8,30,6,LOG:12)
Block(-8,30,7,LOG:12)
Block(-8,31,-1,LOG:12)
Block(-8,31,0,LOG:12)
Block(-8,31,1,LOG:12)
Block(-8,31,2,LOG:12)
Block(-8,31,3,LOG:12)
Block(-8,31,4,LOG:12)
Block(-8,31,5,LOG:12)
Block(-8,31,6,LOG:12)
Block(-8,31,7,LOG:12)
Block(-8,31,8,LOG:12)
Block(-8,32,0,LOG:12)
Block(-8,32,1,LOG:12)
Block(-8,32,2,LOG:12)
Block(-8,32,3,LOG:12)
Block(-8,32,4,LOG:12)
Block(-8,32,5,LOG:12)
Block(-8,32,6,LOG:12)
Block(-8,32,7,LOG:12)
Block(-8,32,8,LOG:12)
Block(-8,33,-1,LEAVES:0)
Block(-8,33,0,LOG:12)
Block(-8,33,1,LOG:12)
Block(-8,33,2,LOG:12)
Block(-8,33,3,LOG:12)
Block(-8,33,4,LOG:12)
Block(-8,33,5,LOG:12)
Block(-8,33,6,LOG:12)
Block(-8,33,7,LOG:12)
Block(-8,33,8,LOG:12)
Block(-8,34,-1,LEAVES:0)
Block(-8,34,0,LEAVES:0)
Block(-8,34,1,LOG:12)
Block(-8,34,2,LOG:12)
Block(-8,34,3,LOG:12)
Block(-8,34,4,LOG:12)
Block(-8,34,5,LOG:12)
Block(-8,34,6,LOG:12)
Block(-8,34,7,LOG:12)
Block(-8,34,8,LOG:12)
Block(-8,35,-1,LEAVES:0)
Block(-8,35,0,LEAVES:0)
Block(-8,35,3,LOG:12)
Block(-8,35,4,LOG:12)
Block(-8,35,5,LOG:12)
Block(-8,35,6,LOG:12)
Block(-8,35,7,LOG:12)
Block(-8,35,8,LOG:12)
Block(-8,36,-3,LEAVES:0)
Block(-8,36,-2,LEAVES:0)
Block(-8,36,-1,LEAVES:0)
Block(-8,36,3,LOG:12)
Block(-8,36,4,LOG:12)
Block(-8,36,5,LOG:12)
Block(-8,36,6,LOG:12)
Block(-8,36,7,LOG:12)
Block(-8,36,8,LOG:12)
Block(-8,37,-3,LEAVES:0)
Block(-8,37,3,LOG:12)
Block(-8,37,4,LOG:12)
Block(-8,37,5,LOG:12)
Block(-8,37,6,LOG:12)
Block(-8,37,7,LOG:12)
Block(-8,37,8,LOG:12)
Block(-8,38,3,LOG:12)
Block(-8,38,4,LOG:12)
Block(-8,38,5,LOG:12)
Block(-8,38,6,LOG:12)
Block(-8,38,7,LOG:12)
Block(-8,39,3,LOG:12)
Block(-8,39,4,LOG:12)
Block(-8,39,5,LOG:12)
Block(-8,39,6,LOG:12)
Block(-8,39,7,VINE:12)
Block(-8,40,3,LOG:12)
Block(-8,40,4,LOG:12)
Block(-8,40,5,LOG:12)
Block(-8,40,6,LOG:12)
Block(-8,40,7,VINE:8)
Block(-8,41,3,LOG:12)
Block(-8,41,4,LOG:12)
Block(-8,41,5,LOG:12)
Block(-8,41,6,VINE:12)
Block(-8,41,7,VINE:8)
Block(-8,42,2,LOG:12)
Block(-8,42,3,LOG:12)
Block(-8,42,4,LOG:12)
Block(-8,42,6,VINE:12)
Block(-8,42,7,VINE:8)
Block(-8,43,3,LOG:12)
Block(-8,43,4,LOG:12)
Block(-8,43,5,LOG:12)
Block(-8,43,6,VINE:12)
Block(-8,43,7,VINE:8)
Block(-8,44,3,LOG:12)
Block(-8,44,4,LOG:12)
Block(-8,44,5,LOG:12)
Block(-8,44,6,VINE:12)
Block(-8,44,7,VINE:8)
Block(-8,45,-2,rustic:iron_lantern:0)
Block(-8,45,3,LOG:12)
Block(-8,45,4,LOG:12)
Block(-8,45,5,LOG:12)
Block(-8,45,6,VINE:12)
Block(-8,45,7,VINE:8)
Block(-8,46,-2,FENCE:0)
Block(-8,46,3,LOG:12)
Block(-8,46,4,LOG:12)
Block(-8,46,5,LOG:12)
Block(-8,46,6,VINE:12)
Block(-8,46,7,VINE:8)
Block(-8,46,8,LEAVES:0)
Block(-8,47,-2,LOG:12)
Block(-8,47,-1,LOG:12)
Block(-8,47,4,LOG:12)
Block(-8,47,5,LOG:12)
Block(-8,47,6,VINE:12)
Block(-8,47,7,VINE:8)
Block(-8,47,8,LEAVES:0)
Block(-8,48,-4,LOG:12)
Block(-8,48,-3,LOG:12)
Block(-8,48,-2,LOG:12)
Block(-8,48,-1,LOG:12)
Block(-8,48,0,WOOD_DOUBLE_STEP:0)
Block(-8,48,1,WOOD_DOUBLE_STEP:0)
Block(-8,48,2,WOOD_STAIRS:7)
Block(-8,48,4,LOG:12)
Block(-8,48,5,LOG:12)
Block(-8,48,6,VINE:12)
Block(-8,48,7,VINE:8)
Block(-8,48,8,LEAVES:0)
Block(-8,49,-3,VINE:1)
Block(-8,49,-2,LOG:12)
Block(-8,49,-1,LOG:12)
Block(-8,49,0,WOOD_DOUBLE_STEP:0)
Block(-8,49,1,WOOD_DOUBLE_STEP:0)
Block(-8,49,2,WOOD_DOUBLE_STEP:0)
Block(-8,49,3,LOG:12)
Block(-8,49,4,LOG:12)
Block(-8,49,5,LOG:12)
Block(-8,49,6,VINE:12)
Block(-8,49,7,VINE:8)
Block(-8,49,8,LOG:12)
Block(-8,50,-3,VINE:1)
Block(-8,50,-2,LOG:12)
Block(-8,50,-1,LOG:12)
Block(-8,50,1,LADDER:4)
Block(-8,50,2,FENCE:0)
Block(-8,50,3,LOG:12)
Block(-8,50,4,LOG:12)
Block(-8,50,5,LOG:12)
Block(-8,50,6,VINE:12)
Block(-8,50,7,VINE:8)
Block(-8,50,8,LOG:12)
Block(-8,51,-3,VINE:1)
Block(-8,51,-2,LOG:12)
Block(-8,51,-1,LOG:12)
Block(-8,51,1,LADDER:4)
Block(-8,51,3,LOG:12)
Block(-8,51,4,LOG:12)
Block(-8,51,5,LOG:12)
Block(-8,51,6,VINE:12)
Block(-8,51,7,VINE:8)
Block(-8,51,8,LEAVES:0)
Block(-8,52,-7,LEAVES:0)
Block(-8,52,-6,LEAVES:0)
Block(-8,52,-5,LEAVES:0)
Block(-8,52,-4,LEAVES:0)
Block(-8,52,-3,LEAVES:0)
Block(-8,52,-2,LOG:12)
Block(-8,52,-1,LOG:12)
Block(-8,52,0,LEAVES:0)
Block(-8,52,1,LADDER:4)
Block(-8,52,2,LOG:12)
Block(-8,52,4,LOG:12)
Block(-8,52,5,LOG:12)
Block(-8,52,6,VINE:12)
Block(-8,52,7,VINE:8)
Block(-8,52,8,LEAVES:0)
Block(-8,53,-7,LEAVES:0)
Block(-8,53,-6,LEAVES:0)
Block(-8,53,-5,LEAVES:0)
Block(-8,53,-4,LEAVES:0)
Block(-8,53,-3,LEAVES:0)
Block(-8,53,-2,LOG:12)
Block(-8,53,-1,LOG:12)
Block(-8,53,0,LEAVES:0)
Block(-8,53,1,LADDER:4)
Block(-8,53,2,LOG:12)
Block(-8,53,3,LEAVES:4)
Block(-8,53,4,LEAVES:4)
Block(-8,53,5,LOG:12)
Block(-8,53,6,VINE:12)
Block(-8,53,7,VINE:8)
Block(-8,53,8,LEAVES:0)
Block(-8,54,-7,LEAVES:0)
Block(-8,54,-6,LEAVES:0)
Block(-8,54,-5,LEAVES:0)
Block(-8,54,-4,LEAVES:0)
Block(-8,54,-3,LEAVES:0)
Block(-8,54,-2,LOG:12)
Block(-8,54,-1,LOG:12)
Block(-8,54,0,LEAVES:0)
Block(-8,54,1,LADDER:4)
Block(-8,54,3,LOG:12)
Block(-8,54,4,LOG:12)
Block(-8,54,5,VINE:8)
Block(-8,54,6,VINE:8)
Block(-8,54,7,VINE:8)
Block(-8,54,8,LEAVES:0)
Block(-8,55,-7,LEAVES:0)
Block(-8,55,-6,LEAVES:0)
Block(-8,55,-5,LEAVES:0)
Block(-8,55,-4,LEAVES:0)
Block(-8,55,-3,LEAVES:0)
Block(-8,55,-2,LOG:12)
Block(-8,55,-1,LEAVES:0)
Block(-8,55,0,LEAVES:0)
Block(-8,55,3,LEAVES:4)
Block(-8,55,4,LEAVES:4)
Block(-8,55,5,VINE:8)
Block(-8,55,6,VINE:8)
Block(-8,55,7,VINE:8)
Block(-8,56,-6,LEAVES:0)
Block(-8,56,-5,LEAVES:0)
Block(-8,56,-3,LEAVES:0)
Block(-8,56,-2,LOG:12)
Block(-8,56,-1,LEAVES:0)
Block(-8,56,3,LEAVES:4)
Block(-8,56,4,VINE:8)
Block(-8,56,5,VINE:8)
Block(-8,56,6,VINE:8)
Block(-8,56,7,VINE:8)
Block(-8,57,-5,LEAVES:0)
Block(-8,57,-3,LEAVES:0)
Block(-8,57,-2,LEAVES:0)
Block(-8,57,-1,LEAVES:0)
Block(-8,57,4,VINE:8)
Block(-8,57,5,VINE:8)
Block(-8,57,6,VINE:8)
Block(-8,57,7,VINE:8)
Block(-8,58,4,VINE:8)
Block(-8,58,5,VINE:8)
Block(-8,58,6,VINE:8)
Block(-8,58,7,VINE:8)
Block(-8,59,5,VINE:8)
Block(-8,59,6,VINE:8)
Block(-8,59,7,WOOD_STEP:8)
Block(-8,59,8,WOOD_STEP:8)
Block(-8,60,-5,LOG:12)
Block(-8,60,-4,LOG:12)
Block(-8,60,-3,LOG:12)
Block(-8,60,-2,LOG:12)
Block(-8,60,5,VINE:8)
Block(-8,60,6,VINE:8)
Block(-8,60,7,FENCE:0)
Block(-8,60,8,FENCE:0)
Block(-8,61,-5,LOG:12)
Block(-8,61,-4,LOG:12)
Block(-8,61,-3,LOG:12)
Block(-8,61,-2,LOG:12)
Block(-8,61,5,VINE:8)
Block(-8,61,6,VINE:8)
Block(-8,61,7,FENCE:0)
Block(-8,61,8,FENCE:0)
Block(-8,62,-5,LOG:12)
Block(-8,62,-4,LOG:12)
Block(-8,62,3,LOG:12)
Block(-8,62,4,LOG:12)
Block(-8,62,5,VINE:8)
Block(-8,62,6,VINE:8)
Block(-8,62,7,VINE:8)
Block(-8,63,-5,LOG:12)
Block(-8,63,-4,LOG:12)
Block(-8,63,2,LOG:12)
Block(-8,63,5,LOG:12)
Block(-8,63,6,VINE:8)
Block(-8,63,7,VINE:8)
Block(-8,64,-6,LEAVES:0)
Block(-8,64,-5,LOG:12)
Block(-8,64,-4,LOG:12)
Block(-8,64,-3,LEAVES:0)
Block(-8,64,-2,LEAVES:0)
Block(-8,64,3,LOG:12)
Block(-8,64,4,LOG:12)
Block(-8,64,5,VINE:8)
Block(-8,64,6,VINE:8)
Block(-8,64,7,VINE:8)
Block(-8,65,-7,LEAVES:0)
Block(-8,65,-6,LEAVES:0)
Block(-8,65,-5,LOG:12)
Block(-8,65,-4,LOG:12)
Block(-8,65,-3,LEAVES:0)
Block(-8,65,-2,LEAVES:0)
Block(-8,65,3,VINE:8)
Block(-8,65,4,VINE:8)
Block(-8,65,5,VINE:8)
Block(-8,65,6,VINE:8)
Block(-8,65,7,VINE:8)
Block(-8,66,-7,LEAVES:0)
Block(-8,66,-6,LOG:12)
Block(-8,66,-5,LOG:12)
Block(-8,66,-4,LOG:12)
Block(-8,66,-3,LOG:12)
Block(-8,66,-2,LOG:12)
Block(-8,66,-1,LOG:12)
Block(-8,66,0,LOG:12)
Block(-8,66,3,VINE:8)
Block(-8,66,4,VINE:8)
Block(-8,66,5,VINE:8)
Block(-8,66,6,VINE:8)
Block(-8,66,7,VINE:8)
Block(-8,67,-7,LEAVES:0)
Block(-8,67,-6,LEAVES:0)
Block(-8,67,-5,LOG:12)
Block(-8,67,-4,LEAVES:0)
Block(-8,67,-3,LOG:12)
Block(-8,67,-2,LOG:12)
Block(-8,67,-1,LOG:12)
Block(-8,67,0,LOG:12)
Block(-8,67,1,LEAVES:0)
Block(-8,67,2,LEAVES:0)
Block(-8,67,3,VINE:8)
Block(-8,67,4,VINE:8)
Block(-8,67,5,VINE:8)
Block(-8,67,6,VINE:8)
Block(-8,67,7,VINE:8)
Block(-8,68,-7,LEAVES:0)
Block(-8,68,-6,LEAVES:0)
Block(-8,68,-5,LEAVES:0)
Block(-8,68,-4,LEAVES:0)
Block(-8,68,-3,LEAVES:0)
Block(-8,68,-2,LEAVES:0)
Block(-8,68,-1,LEAVES:0)
Block(-8,68,0,LEAVES:0)
Block(-8,68,1,LEAVES:0)
Block(-8,68,2,VINE:8)
Block(-8,68,3,VINE:8)
Block(-8,68,4,VINE:8)
Block(-8,68,5,VINE:8)
Block(-8,68,6,VINE:8)
Block(-8,68,7,VINE:8)
Block(-8,69,-7,LEAVES:0)
Block(-8,69,-5,LEAVES:0)
Block(-8,69,-4,LEAVES:0)
Block(-8,69,-3,LEAVES:0)
Block(-8,69,1,VINE:8)
Block(-8,69,2,VINE:8)
Block(-8,69,3,VINE:8)
Block(-8,69,4,VINE:8)
Block(-8,69,5,VINE:8)
Block(-8,69,6,VINE:8)
Block(-8,69,7,VINE:8)
Block(-8,70,-7,VINE:1)
Block(-8,70,-6,LOG:12)
Block(-8,70,-5,LEAVES:0)
Block(-8,70,-4,LEAVES:0)
Block(-8,70,-3,LEAVES:0)
Block(-8,70,-2,LEAVES:0)
Block(-8,70,1,VINE:8)
Block(-8,70,2,VINE:8)
Block(-8,70,3,VINE:8)
Block(-8,70,4,VINE:8)
Block(-8,70,5,VINE:8)
Block(-8,70,6,VINE:8)
Block(-8,70,7,VINE:8)
Block(-8,71,-7,VINE:1)
Block(-8,71,-6,LOG:12)
Block(-8,71,-4,LEAVES:0)
Block(-8,71,-3,LEAVES:0)
Block(-8,71,-2,LEAVES:0)
Block(-8,71,1,VINE:8)
Block(-8,71,2,VINE:8)
Block(-8,71,3,VINE:8)
Block(-8,71,4,VINE:8)
Block(-8,71,5,VINE:8)
Block(-8,71,6,VINE:8)
Block(-8,71,7,VINE:8)
Block(-8,72,-7,VINE:1)
Block(-8,72,-6,LOG:12)
Block(-8,72,-5,LEAVES:0)
Block(-8,72,-4,LEAVES:0)
Block(-8,72,-3,LEAVES:0)
Block(-8,72,-2,LEAVES:0)
Block(-8,72,-1,LOG:12)
Block(-8,72,0,LOG:12)
Block(-8,72,1,LOG:12)
Block(-8,72,2,LOG:12)
Block(-8,72,3,LOG:12)
Block(-8,72,4,LOG:12)
Block(-8,72,5,LOG:12)
Block(-8,72,6,LOG:12)
Block(-8,72,7,LOG:12)
Block(-8,73,-7,LEAVES:0)
Block(-8,73,-6,LOG:12)
Block(-8,73,-5,LEAVES:0)
Block(-8,73,-4,LEAVES:0)
Block(-8,73,-3,LEAVES:0)
Block(-8,73,-2,LEAVES:0)
Block(-8,73,-1,LOG:12)
Block(-8,73,0,LOG:12)
Block(-8,73,1,LOG:12)
Block(-8,73,2,LOG:12)
Block(-8,73,3,LOG:12)
Block(-8,73,4,LOG:12)
Block(-8,73,5,LOG:12)
Block(-8,73,6,LOG:12)
Block(-8,73,7,LOG:12)
Block(-8,73,8,LEAVES:0)
Block(-8,74,-7,LEAVES:0)
Block(-8,74,-6,LOG:12)
Block(-8,74,-5,LEAVES:0)
Block(-8,74,-4,LEAVES:0)
Block(-8,74,-3,LOG:12)
Block(-8,74,-2,LEAVES:0)
Block(-8,74,-1,LOG:12)
Block(-8,74,0,LOG:12)
Block(-8,74,1,LOG:12)
Block(-8,74,2,LOG:12)
Block(-8,74,3,LOG:12)
Block(-8,74,4,LOG:12)
Block(-8,74,5,LOG:12)
Block(-8,74,6,LOG:12)
Block(-8,74,7,LOG:12)
Block(-8,74,8,LEAVES:0)
Block(-8,75,-7,LEAVES:0)
Block(-8,75,-6,LOG:12)
Block(-8,75,-5,LEAVES:0)
Block(-8,75,-4,LEAVES:0)
Block(-8,75,-3,LEAVES:0)
Block(-8,75,-2,LEAVES:0)
Block(-8,75,-1,LOG:12)
Block(-8,75,0,LOG:12)
Block(-8,75,1,LOG:12)
Block(-8,75,2,LOG:12)
Block(-8,75,3,LOG:12)
Block(-8,75,4,LOG:12)
Block(-8,75,5,LOG:12)
Block(-8,75,6,LOG:12)
Block(-8,75,7,LOG:12)
Block(-8,75,8,LEAVES:0)
Block(-8,76,-7,LEAVES:0)
Block(-8,76,-6,LEAVES:0)
Block(-8,76,-5,LEAVES:0)
Block(-8,76,-4,LEAVES:0)
Block(-8,76,-3,LEAVES:0)
Block(-8,76,-2,LEAVES:0)
Block(-8,76,-1,LOG:12)
Block(-8,76,0,LEAVES:0)
Block(-8,76,1,LOG:12)
Block(-8,76,2,LOG:12)
Block(-8,76,3,LOG:12)
Block(-8,76,4,LEAVES:0)
Block(-8,76,5,LOG:12)
Block(-8,76,6,LOG:12)
Block(-8,76,7,LOG:12)
Block(-8,76,8,LEAVES:0)
Block(-8,77,-7,LEAVES:0)
Block(-8,77,-6,LEAVES:0)
Block(-8,77,-5,LEAVES:0)
Block(-8,77,-4,LEAVES:0)
Block(-8,77,-3,LEAVES:0)
Block(-8,77,-2,LEAVES:0)
Block(-8,77,-1,LOG:12)
Block(-8,77,0,LEAVES:0)
Block(-8,77,1,LOG:12)
Block(-8,77,2,LOG:12)
Block(-8,77,3,LOG:12)
Block(-8,77,4,LEAVES:0)
Block(-8,77,5,LOG:12)
Block(-8,77,6,LOG:12)
Block(-8,77,7,LEAVES:0)
Block(-8,77,8,LOG:12)
Block(-8,78,-7,LEAVES:0)
Block(-8,78,-6,LEAVES:0)
Block(-8,78,-5,LEAVES:0)
Block(-8,78,-4,LEAVES:0)
Block(-8,78,-3,LEAVES:0)
Block(-8,78,-2,LEAVES:0)
Block(-8,78,-1,LEAVES:0)
Block(-8,78,0,LEAVES:0)
Block(-8,78,1,LEAVES:0)
Block(-8,78,2,LEAVES:0)
Block(-8,78,3,LEAVES:0)
Block(-8,78,4,LEAVES:0)
Block(-8,78,5,LEAVES:0)
Block(-8,78,6,LEAVES:0)
Block(-8,78,7,LOG:12)
Block(-8,78,8,LOG:12)
Block(-8,79,-4,LEAVES:0)
Block(-8,79,-3,LEAVES:0)
Block(-8,79,-2,LEAVES:0)
Block(-8,79,-1,LEAVES:0)
Block(-8,79,0,LEAVES:0)
Block(-8,79,2,LEAVES:0)
Block(-8,79,3,LEAVES:0)
Block(-8,79,4,LEAVES:0)
Block(-8,79,5,LEAVES:0)
Block(-8,79,6,LOG:12)
Block(-8,79,7,LEAVES:0)
Block(-8,79,8,LEAVES:0)
Block(-8,80,-4,LEAVES:0)
Block(-8,80,-3,LEAVES:0)
Block(-8,80,-2,LEAVES:0)
Block(-8,80,-1,LEAVES:0)
Block(-8,80,0,LEAVES:0)
Block(-8,80,2,LEAVES:0)
Block(-8,80,3,LEAVES:0)
Block(-8,80,4,LEAVES:0)
Block(-8,80,5,LEAVES:0)
Block(-8,80,6,LOG:12)
Block(-8,80,7,LOG:12)
Block(-8,80,8,LOG:12)
Block(-8,81,-2,LEAVES:0)
Block(-8,81,2,LEAVES:0)
Block(-8,81,3,LEAVES:0)
Block(-8,81,4,LEAVES:0)
Block(-8,81,5,LEAVES:0)
Block(-8,81,6,LEAVES:0)
Block(-8,81,7,LEAVES:0)
Block(-8,81,8,LEAVES:0)
Block(-8,82,-6,LEAVES:0)
Block(-8,82,-5,LEAVES:0)
Block(-8,82,-4,LEAVES:0)
Block(-8,82,2,LEAVES:0)
Block(-8,82,3,LEAVES:0)
Block(-8,82,4,LEAVES:0)
Block(-8,82,5,LEAVES:0)
Block(-8,82,6,LEAVES:0)
Block(-8,82,7,LEAVES:0)
Block(-8,82,8,LEAVES:0)
Block(-8,83,-6,LEAVES:0)
Block(-8,83,-5,LEAVES:0)
Block(-8,83,-4,LEAVES:0)
Block(-8,83,-1,LEAVES:0)
Block(-8,83,0,LOG:12)
Block(-8,83,1,LEAVES:0)
Block(-8,83,4,LEAVES:0)
Block(-8,83,5,LEAVES:0)
Block(-8,83,6,LEAVES:0)
Block(-8,83,7,LEAVES:0)
Block(-8,83,8,LEAVES:0)
Block(-8,84,-2,LEAVES:0)
Block(-8,84,-1,LEAVES:0)
Block(-8,84,0,LEAVES:0)
Block(-8,84,1,LEAVES:0)
Block(-8,84,2,LEAVES:0)
Block(-8,84,4,LEAVES:0)
Block(-8,84,5,LEAVES:0)
Block(-8,84,6,LEAVES:0)
Block(-8,84,7,LEAVES:0)
Block(-8,84,8,LEAVES:0)
Block(-8,85,-2,LEAVES:0)
Block(-8,85,-1,LEAVES:0)
Block(-8,85,0,LEAVES:0)
Block(-8,85,1,LEAVES:0)
Block(-8,85,2,LEAVES:0)
Block(-8,85,6,LEAVES:0)
Block(-8,86,-1,LEAVES:0)
Block(-8,86,0,LEAVES:0)
Block(-8,86,1,LEAVES:0)
RandomBlock(-8,95,-1,quark:quilted_wool:0,10,quark:quilted_wool:0,100)
RandomBlock(-8,95,0,quark:quilted_wool:0,10,quark:quilted_wool:0,100)
RandomBlock(-8,95,1,quark:quilted_wool:0,10,quark:quilted_wool:0,100)
RandomBlock(-8,95,8,quark:quilted_wool:0,10,quark:quilted_wool:0,100)
RandomBlock(-8,96,-3,quark:quilted_wool:0,10,quark:quilted_wool:0,100)
RandomBlock(-8,96,-2,quark:quilted_wool:0,10,quark:quilted_wool:0,100)
RandomBlock(-8,96,-1,quark:quilted_wool:0,10,quark:quilted_wool:0,100)
RandomBlock(-8,96,0,quark:quilted_wool:0,10,quark:quilted_wool:0,100)
RandomBlock(-8,96,1,quark:quilted_wool:0,10,quark:quilted_wool:0,100)
RandomBlock(-8,96,2,quark:quilted_wool:0,10,quark:quilted_wool:0,100)
RandomBlock(-8,96,3,quark:quilted_wool:0,10,quark:quilted_wool:0,100)
RandomBlock(-8,96,8,quark:quilted_wool:0,10,quark:quilted_wool:0,100)
RandomBlock(-8,97,-4,quark:quilted_wool:0,10,quark:quilted_wool:0,100)
RandomBlock(-8,97,-3,quark:quilted_wool:0,10,quark:quilted_wool:0,100)
RandomBlock(-8,97,-2,quark:quilted_wool:0,10,quark:quilted_wool:0,100)
RandomBlock(-8,97,-1,quark:quilted_wool:0,10,quark:quilted_wool:0,100)
RandomBlock(-8,97,0,quark:quilted_wool:0,10,quark:quilted_wool:0,100)
RandomBlock(-8,97,1,quark:quilted_wool:0,10,quark:quilted_wool:0,100)
RandomBlock(-8,97,2,quark:quilted_wool:0,10,quark:quilted_wool:0,100)
RandomBlock(-8,97,3,quark:quilted_wool:0,10,quark:quilted_wool:0,100)
RandomBlock(-8,97,4,quark:quilted_wool:0,10,quark:quilted_wool:0,100)
RandomBlock(-8,97,8,quark:quilted_wool:0,10,quark:quilted_wool:0,100)
RandomBlock(-8,98,-5,quark:quilted_wool:0,10,quark:quilted_wool:0,100)
RandomBlock(-8,98,-4,quark:quilted_wool:0,10,quark:quilted_wool:0,100)
RandomBlock(-8,98,-3,quark:quilted_wool:0,10,quark:quilted_wool:0,100)
RandomBlock(-8,98,-2,quark:quilted_wool:0,10,quark:quilted_wool:0,100)
RandomBlock(-8,98,-1,quark:quilted_wool:0,10,quark:quilted_wool:0,100)
RandomBlock(-8,98,0,quark:quilted_wool:0,10,quark:quilted_wool:0,100)
RandomBlock(-8,98,1,quark:quilted_wool:0,10,quark:quilted_wool:0,100)
RandomBlock(-8,98,2,quark:quilted_wool:0,10,quark:quilted_wool:0,100)
RandomBlock(-8,98,3,quark:quilted_wool:0,10,quark:quilted_wool:0,100)
RandomBlock(-8,98,4,quark:quilted_wool:0,10,quark:quilted_wool:0,100)
RandomBlock(-8,98,5,quark:quilted_wool:0,10,quark:quilted_wool:0,100)
RandomBlock(-8,98,8,quark:quilted_wool:0,10,quark:quilted_wool:0,100)
RandomBlock(-8,99,-5,quark:quilted_wool:0,10,quark:quilted_wool:0,100)
RandomBlock(-8,99,-4,quark:quilted_wool:0,10,quark:quilted_wool:0,100)
RandomBlock(-8,99,-3,quark:quilted_wool:0,10,quark:quilted_wool:0,100)
RandomBlock(-8,99,-2,quark:quilted_wool:0,10,quark:quilted_wool:0,100)
RandomBlock(-8,99,-1,quark:quilted_wool:0,10,quark:quilted_wool:0,100)
RandomBlock(-8,99,0,quark:quilted_wool:0,10,quark:quilted_wool:0,100)
RandomBlock(-8,99,1,quark:quilted_wool:0,10,quark:quilted_wool:0,100)
RandomBlock(-8,99,2,quark:quilted_wool:0,10,quark:quilted_wool:0,100)
RandomBlock(-8,99,3,quark:quilted_wool:0,10,quark:quilted_wool:0,100)
RandomBlock(-8,99,4,quark:quilted_wool:0,10,quark:quilted_wool:0,100)
RandomBlock(-8,99,5,quark:quilted_wool:0,10,quark:quilted_wool:0,100)
RandomBlock(-8,99,8,quark:quilted_wool:0,10,quark:quilted_wool:0,100)
RandomBlock(-8,100,-5,quark:quilted_wool:0,10,quark:quilted_wool:0,100)
RandomBlock(-8,100,-4,quark:quilted_wool:0,10,quark:quilted_wool:0,100)
RandomBlock(-8,100,-3,quark:quilted_wool:0,10,quark:quilted_wool:0,100)
RandomBlock(-8,100,-2,quark:quilted_wool:0,10,quark:quilted_wool:0,100)
RandomBlock(-8,100,-1,quark:quilted_wool:0,10,quark:quilted_wool:0,100)
RandomBlock(-8,100,0,quark:quilted_wool:0,10,quark:quilted_wool:0,100)
RandomBlock(-8,100,1,quark:quilted_wool:0,10,quark:quilted_wool:0,100)
RandomBlock(-8,100,2,quark:quilted_wool:0,10,quark:quilted_wool:0,100)
RandomBlock(-8,100,3,quark:quilted_wool:0,10,quark:quilted_wool:0,100)
RandomBlock(-8,100,4,quark:quilted_wool:0,10,quark:quilted_wool:0,100)
RandomBlock(-8,100,5,quark:quilted_wool:0,10,quark:quilted_wool:0,100)
RandomBlock(-8,100,8,quark:quilted_wool:0,10,quark:quilted_wool:0,100)
RandomBlock(-8,101,-6,quark:quilted_wool:0,10,quark:quilted_wool:0,100)
RandomBlock(-8,101,-5,quark:quilted_wool:0,10,quark:quilted_wool:0,100)
RandomBlock(-8,101,-4,quark:quilted_wool:0,10,quark:quilted_wool:0,100)
RandomBlock(-8,101,-3,quark:quilted_wool:0,10,quark:quilted_wool:0,100)
RandomBlock(-8,101,-2,quark:quilted_wool:0,10,quark:quilted_wool:0,100)
RandomBlock(-8,101,-1,quark:quilted_wool:0,10,quark:quilted_wool:0,100)
RandomBlock(-8,101,0,quark:quilted_wool:0,10,quark:quilted_wool:0,100)
RandomBlock(-8,101,1,quark:quilted_wool:0,10,quark:quilted_wool:0,100)
RandomBlock(-8,101,2,quark:quilted_wool:0,10,quark:quilted_wool:0,100)
RandomBlock(-8,101,3,quark:quilted_wool:0,10,quark:quilted_wool:0,100)
RandomBlock(-8,101,4,quark:quilted_wool:0,10,quark:quilted_wool:0,100)
RandomBlock(-8,101,5,quark:quilted_wool:0,10,quark:quilted_wool:0,100)
RandomBlock(-8,101,6,quark:quilted_wool:0,10,quark:quilted_wool:0,100)
RandomBlock(-8,101,8,quark:quilted_wool:0,10,quark:quilted_wool:0,100)
RandomBlock(-8,102,-6,quark:quilted_wool:0,10,quark:quilted_wool:0,100)
RandomBlock(-8,102,-5,quark:quilted_wool:0,10,quark:quilted_wool:0,100)
RandomBlock(-8,102,-4,quark:quilted_wool:0,10,quark:quilted_wool:0,100)
RandomBlock(-8,102,-3,quark:quilted_wool:0,10,quark:quilted_wool:0,100)
RandomBlock(-8,102,-2,quark:quilted_wool:0,10,quark:quilted_wool:0,100)
RandomBlock(-8,102,-1,quark:quilted_wool:0,10,quark:quilted_wool:0,100)
RandomBlock(-8,102,0,quark:quilted_wool:0,10,quark:quilted_wool:0,100)
RandomBlock(-8,102,1,quark:quilted_wool:0,10,quark:quilted_wool:0,100)
RandomBlock(-8,102,2,quark:quilted_wool:0,10,quark:quilted_wool:0,100)
RandomBlock(-8,102,3,quark:quilted_wool:0,10,quark:quilted_wool:0,100)
RandomBlock(-8,102,4,quark:quilted_wool:0,10,quark:quilted_wool:0,100)
RandomBlock(-8,102,5,quark:quilted_wool:0,10,quark:quilted_wool:0,100)
RandomBlock(-8,102,6,quark:quilted_wool:0,10,quark:quilted_wool:0,100)
RandomBlock(-8,103,-6,quark:quilted_wool:0,10,quark:quilted_wool:0,100)
RandomBlock(-8,103,-5,quark:quilted_wool:0,10,quark:quilted_wool:0,100)
RandomBlock(-8,103,-4,quark:quilted_wool:0,10,quark:quilted_wool:0,100)
RandomBlock(-8,103,-3,quark:quilted_wool:0,10,quark:quilted_wool:0,100)
RandomBlock(-8,103,-2,quark:quilted_wool:0,10,quark:quilted_wool:0,100)
RandomBlock(-8,103,-1,quark:quilted_wool:0,10,quark:quilted_wool:0,100)
RandomBlock(-8,103,0,quark:quilted_wool:0,10,quark:quilted_wool:0,100)
RandomBlock(-8,103,1,quark:quilted_wool:0,10,quark:quilted_wool:0,100)
RandomBlock(-8,103,2,quark:quilted_wool:0,10,quark:quilted_wool:0,100)
RandomBlock(-8,103,3,quark:quilted_wool:0,10,quark:quilted_wool:0,100)
RandomBlock(-8,103,4,quark:quilted_wool:0,10,quark:quilted_wool:0,100)
RandomBlock(-8,103,5,quark:quilted_wool:0,10,quark:quilted_wool:0,100)
RandomBlock(-8,103,6,quark:quilted_wool:0,10,quark:quilted_wool:0,100)
RandomBlock(-8,104,-5,quark:quilted_wool:0,10,quark:quilted_wool:0,100)
RandomBlock(-8,104,-4,quark:quilted_wool:0,10,quark:quilted_wool:0,100)
RandomBlock(-8,104,-3,quark:quilted_wool:0,10,quark:quilted_wool:0,100)
RandomBlock(-8,104,-2,quark:quilted_wool:0,10,quark:quilted_wool:0,100)
RandomBlock(-8,104,-1,quark:quilted_wool:0,10,quark:quilted_wool:0,100)
RandomBlock(-8,104,0,quark:quilted_wool:0,10,quark:quilted_wool:0,100)
RandomBlock(-8,104,1,quark:quilted_wool:0,10,quark:quilted_wool:0,100)
RandomBlock(-8,104,2,quark:quilted_wool:0,10,quark:quilted_wool:0,100)
RandomBlock(-8,104,3,quark:quilted_wool:0,10,quark:quilted_wool:0,100)
RandomBlock(-8,104,4,quark:quilted_wool:0,10,quark:quilted_wool:0,100)
RandomBlock(-8,104,5,quark:quilted_wool:0,10,quark:quilted_wool:0,100)
RandomBlock(-8,105,-5,quark:quilted_wool:0,10,quark:quilted_wool:0,100)
RandomBlock(-8,105,-4,quark:quilted_wool:0,10,quark:quilted_wool:0,100)
RandomBlock(-8,105,-3,quark:quilted_wool:0,10,quark:quilted_wool:0,100)
RandomBlock(-8,105,-2,quark:quilted_wool:0,10,quark:quilted_wool:0,100)
RandomBlock(-8,105,-1,quark:quilted_wool:0,10,quark:quilted_wool:0,100)
RandomBlock(-8,105,0,quark:quilted_wool:0,10,quark:quilted_wool:0,100)
RandomBlock(-8,105,1,quark:quilted_wool:0,10,quark:quilted_wool:0,100)
RandomBlock(-8,105,2,quark:quilted_wool:0,10,quark:quilted_wool:0,100)
RandomBlock(-8,105,3,quark:quilted_wool:0,10,quark:quilted_wool:0,100)
RandomBlock(-8,105,4,quark:quilted_wool:0,10,quark:quilted_wool:0,100)
RandomBlock(-8,105,5,quark:quilted_wool:0,10,quark:quilted_wool:0,100)
RandomBlock(-8,106,-5,quark:quilted_wool:0,10,quark:quilted_wool:0,100)
RandomBlock(-8,106,-4,quark:quilted_wool:0,10,quark:quilted_wool:0,100)
RandomBlock(-8,106,-3,quark:quilted_wool:0,10,quark:quilted_wool:0,100)
RandomBlock(-8,106,-2,quark:quilted_wool:0,10,quark:quilted_wool:0,100)
RandomBlock(-8,106,-1,quark:quilted_wool:0,10,quark:quilted_wool:0,100)
RandomBlock(-8,106,0,quark:quilted_wool:0,10,quark:quilted_wool:0,100)
RandomBlock(-8,106,1,quark:quilted_wool:0,10,quark:quilted_wool:0,100)
RandomBlock(-8,106,2,quark:quilted_wool:0,10,quark:quilted_wool:0,100)
RandomBlock(-8,106,3,quark:quilted_wool:0,10,quark:quilted_wool:0,100)
RandomBlock(-8,106,4,quark:quilted_wool:0,10,quark:quilted_wool:0,100)
RandomBlock(-8,106,5,quark:quilted_wool:0,10,quark:quilted_wool:0,100)
RandomBlock(-8,107,-4,quark:quilted_wool:0,10,quark:quilted_wool:0,100)
RandomBlock(-8,107,-3,quark:quilted_wool:0,10,quark:quilted_wool:0,100)
RandomBlock(-8,107,-2,quark:quilted_wool:0,10,quark:quilted_wool:0,100)
RandomBlock(-8,107,-1,quark:quilted_wool:0,10,quark:quilted_wool:0,100)
RandomBlock(-8,107,0,quark:quilted_wool:0,10,quark:quilted_wool:0,100)
RandomBlock(-8,107,1,quark:quilted_wool:0,10,quark:quilted_wool:0,100)
RandomBlock(-8,107,2,quark:quilted_wool:0,10,quark:quilted_wool:0,100)
RandomBlock(-8,107,3,quark:quilted_wool:0,10,quark:quilted_wool:0,100)
RandomBlock(-8,107,4,quark:quilted_wool:0,10,quark:quilted_wool:0,100)
RandomBlock(-8,108,-3,quark:quilted_wool:0,10,quark:quilted_wool:0,100)
RandomBlock(-8,108,-2,quark:quilted_wool:0,10,quark:quilted_wool:0,100)
RandomBlock(-8,108,-1,quark:quilted_wool:0,10,quark:quilted_wool:0,100)
RandomBlock(-8,108,0,quark:quilted_wool:0,10,quark:quilted_wool:0,100)
RandomBlock(-8,108,1,quark:quilted_wool:0,10,quark:quilted_wool:0,100)
RandomBlock(-8,108,2,quark:quilted_wool:0,10,quark:quilted_wool:0,100)
RandomBlock(-8,108,3,quark:quilted_wool:0,10,quark:quilted_wool:0,100)
RandomBlock(-8,109,-1,quark:quilted_wool:0,10,quark:quilted_wool:0,100)
RandomBlock(-8,109,0,quark:quilted_wool:0,10,quark:quilted_wool:0,100)
RandomBlock(-8,109,1,quark:quilted_wool:0,10,quark:quilted_wool:0,100)
Block(-7,10,8,LOG:12)
Block(-7,11,7,LOG:12)
Block(-7,11,8,LOG:12)
Block(-7,12,7,LOG:12)
Block(-7,12,8,LOG:12)
Block(-7,13,7,LOG:12)
Block(-7,13,8,LOG:12)
Block(-7,14,7,LOG:12)
Block(-7,14,8,LOG:12)
Block(-7,15,6,LOG:12)
Block(-7,15,7,LOG:12)
Block(-7,15,8,LOG:12)
Block(-7,16,-3,LOG:12)
Block(-7,16,5,LOG:12)
Block(-7,16,6,LOG:12)
Block(-7,16,7,LOG:12)
Block(-7,16,8,quark:leaf_carpet)
Block(-7,17,-4,LOG:12)
Block(-7,17,-3,LOG:12)
Block(-7,17,-2,LOG:12)
Block(-7,17,3,LOG:12)
Block(-7,17,6,LOG:12)
Block(-7,17,7,quark:leaf_carpet)
Block(-7,18,-4,LOG:12)
Block(-7,18,-3,LOG:12)
Block(-7,18,-2,LOG:12)
Block(-7,18,-1,LOG:12)
Block(-7,18,0,LEAVES:0)
Block(-7,18,2,LOG:12)
Block(-7,18,3,LOG:12)
Block(-7,18,4,LOG:12)
Block(-7,18,5,LEAVES:0)
Block(-7,18,6,LEAVES:0)
Block(-7,18,7,LEAVES:0)
Block(-7,18,8,LEAVES:0)
Block(-7,19,-4,LOG:12)
Block(-7,19,-3,LOG:12)
Block(-7,19,-2,LOG:12)
Block(-7,19,-1,LOG:12)
Block(-7,19,0,LOG:12)
Block(-7,19,1,LEAVES:0)
Block(-7,19,2,LOG:12)
Block(-7,19,3,LOG:12)
Block(-7,19,4,LOG:12)
Block(-7,19,5,LOG:12)
Block(-7,19,6,LOG:12)
Block(-7,19,7,LOG:12)
Block(-7,19,8,LEAVES:0)
Block(-7,20,-4,LEAVES:0)
Block(-7,20,-3,LOG:12)
Block(-7,20,-1,LOG:12)
Block(-7,20,0,LOG:12)
Block(-7,20,1,LOG:12)
Block(-7,20,2,LOG:12)
Block(-7,20,3,LOG:12)
Block(-7,20,4,LOG:12)
Block(-7,20,5,LOG:12)
Block(-7,20,6,LOG:12)
Block(-7,20,7,LOG:12)
Block(-7,20,8,LOG:12)
Block(-7,21,-5,LEAVES:0)
Block(-7,21,-4,LOG:12)
Block(-7,21,-3,LOG:12)
Block(-7,21,-2,LOG:12)
Block(-7,21,0,LOG:12)
Block(-7,21,1,LOG:12)
Block(-7,21,2,LOG:12)
Block(-7,21,3,LOG:12)
Block(-7,21,4,LOG:12)
Block(-7,21,5,LOG:12)
Block(-7,21,6,LOG:12)
Block(-7,21,7,LOG:12)
Block(-7,21,8,LOG:12)
Block(-7,22,-4,LEAVES:0)
Block(-7,22,-3,LOG:12)
Block(-7,22,-2,LEAVES:0)
Block(-7,22,0,LOG:12)
Block(-7,22,1,LOG:12)
Block(-7,22,2,LOG:12)
Block(-7,22,3,LOG:12)
Block(-7,22,4,LOG:12)
Block(-7,22,5,LOG:12)
Block(-7,22,6,LOG:12)
Block(-7,22,7,LOG:12)
Block(-7,22,8,LOG:12)
Block(-7,23,-3,LEAVES:0)
Block(-7,23,-2,LEAVES:0)
Block(-7,23,-1,LOG:12)
Block(-7,23,0,LOG:12)
Block(-7,23,1,LOG:12)
Block(-7,23,2,LOG:12)
Block(-7,23,3,LOG:12)
Block(-7,23,4,LOG:12)
Block(-7,23,5,LOG:12)
Block(-7,23,6,LOG:12)
Block(-7,23,7,LOG:12)
Block(-7,23,8,LOG:12)
Block(-7,24,-2,LEAVES:0)
Block(-7,24,0,LOG:12)
Block(-7,24,1,LOG:12)
Block(-7,24,2,LOG:12)
Block(-7,24,3,LOG:12)
Block(-7,24,4,LOG:12)
Block(-7,24,5,LOG:12)
Block(-7,24,6,LOG:12)
Block(-7,24,7,LOG:12)
Block(-7,24,8,LOG:12)
Block(-7,25,0,LOG:12)
Block(-7,25,1,LOG:12)
Block(-7,25,2,LOG:12)
Block(-7,25,3,LOG:12)
Block(-7,25,4,LOG:12)
Block(-7,25,5,LOG:12)
Block(-7,25,6,LOG:12)
Block(-7,25,7,LOG:12)
Block(-7,25,8,LOG:12)
Block(-7,26,0,LOG:12)
Block(-7,26,1,LOG:12)
Block(-7,26,2,LOG:12)
Block(-7,26,3,LOG:12)
Block(-7,26,4,LOG:12)
Block(-7,26,5,LOG:12)
Block(-7,26,6,LOG:12)
Block(-7,26,7,LOG:12)
Block(-7,26,8,LOG:12)
Block(-7,27,0,LOG:12)
Block(-7,27,1,LOG:12)
Block(-7,27,2,LOG:12)
Block(-7,27,3,LOG:12)
Block(-7,27,4,LOG:12)
Block(-7,27,5,LOG:12)
Block(-7,27,6,LOG:12)
Block(-7,27,7,LOG:12)
Block(-7,27,8,LOG:12)
Block(-7,28,0,LOG:12)
Block(-7,28,1,LOG:12)
Block(-7,28,2,LOG:12)
Block(-7,28,3,LOG:12)
Block(-7,28,4,LOG:12)
Block(-7,28,5,LOG:12)
Block(-7,28,6,LOG:12)
Block(-7,28,7,LOG:12)
Block(-7,28,8,LOG:12)
Block(-7,29,-1,LOG:12)
Block(-7,29,0,LOG:12)
Block(-7,29,1,LOG:12)
Block(-7,29,2,LOG:12)
Block(-7,29,3,LOG:12)
Block(-7,29,4,LOG:12)
Block(-7,29,5,LOG:12)
Block(-7,29,6,LOG:12)
Block(-7,29,7,LOG:12)
Block(-7,29,8,LOG:12)
Block(-7,30,-1,LOG:12)
Block(-7,30,0,LOG:12)
Block(-7,30,1,LOG:12)
Block(-7,30,2,LOG:12)
Block(-7,30,3,LOG:12)
Block(-7,30,4,LOG:12)
Block(-7,30,5,LOG:12)
Block(-7,30,6,LOG:12)
Block(-7,30,7,LOG:12)
Block(-7,30,8,LOG:12)
Block(-7,31,-1,LOG:12)
Block(-7,31,0,LOG:12)
Block(-7,31,1,LOG:12)
Block(-7,31,2,LOG:12)
Block(-7,31,3,LOG:12)
Block(-7,31,4,LOG:12)
Block(-7,31,5,LOG:12)
Block(-7,31,6,LOG:12)
Block(-7,31,7,LOG:12)
Block(-7,31,8,LOG:12)
Block(-7,32,-1,LOG:12)
Block(-7,32,0,LOG:12)
Block(-7,32,1,LOG:12)
Block(-7,32,2,LOG:12)
Block(-7,32,3,LOG:12)
Block(-7,32,4,LOG:12)
Block(-7,32,5,LOG:12)
Block(-7,32,6,LOG:12)
Block(-7,32,7,LOG:12)
Block(-7,32,8,LOG:12)
Block(-7,33,-1,LOG:12)
Block(-7,33,0,LOG:12)
Block(-7,33,1,LOG:12)
Block(-7,33,2,LOG:12)
Block(-7,33,3,LOG:12)
Block(-7,33,4,LOG:12)
Block(-7,33,5,LOG:12)
Block(-7,33,6,LOG:12)
Block(-7,33,7,LOG:12)
Block(-7,33,8,LOG:12)
Block(-7,34,-7,WOOL:14)
Block(-7,34,-2,LOG:12)
Block(-7,34,-1,LOG:12)
Block(-7,34,0,LOG:12)
Block(-7,34,1,LOG:12)
Block(-7,34,2,LOG:12)
Block(-7,34,3,LOG:12)
Block(-7,34,4,LOG:12)
Block(-7,34,5,LOG:12)
Block(-7,34,6,LOG:12)
Block(-7,34,7,LOG:12)
Block(-7,34,8,LOG:12)
Block(-7,35,-3,LEAVES:0)
Block(-7,35,-2,LEAVES:0)
Block(-7,35,-1,LOG:12)
Block(-7,35,0,LOG:12)
Block(-7,35,1,LOG:12)
Block(-7,35,2,LOG:12)
Block(-7,35,3,LOG:12)
Block(-7,35,4,LOG:12)
Block(-7,35,5,LOG:12)
Block(-7,35,6,LOG:12)
Block(-7,35,7,LOG:12)
Block(-7,35,8,LOG:12)
Block(-7,36,-4,LEAVES:0)
Block(-7,36,-3,LEAVES:0)
Block(-7,36,-2,LEAVES:0)
Block(-7,36,-1,LEAVES:0)
Block(-7,36,0,LOG:12)
Block(-7,36,1,LOG:12)
Block(-7,36,2,LOG:12)
Block(-7,36,3,LOG:12)
Block(-7,36,4,LOG:12)
Block(-7,36,5,LOG:12)
Block(-7,36,6,LOG:12)
Block(-7,36,7,LOG:12)
Block(-7,36,8,VINE:4)
Block(-7,37,-4,LEAVES:0)
Block(-7,37,-3,LEAVES:0)
Block(-7,37,-2,LEAVES:0)
Block(-7,37,-1,LEAVES:0)
Block(-7,37,0,LOG:12)
Block(-7,37,1,LOG:12)
Block(-7,37,2,LOG:12)
Block(-7,37,3,LOG:12)
Block(-7,37,4,LOG:12)
Block(-7,37,5,LOG:12)
Block(-7,37,6,LOG:12)
Block(-7,37,7,LOG:12)
Block(-7,37,8,VINE:12)
Block(-7,38,-3,LEAVES:0)
Block(-7,38,-1,LOG:12)
Block(-7,38,0,LOG:12)
Block(-7,38,1,LOG:12)
Block(-7,38,2,LOG:12)
Block(-7,38,3,LOG:12)
Block(-7,38,4,LOG:12)
Block(-7,38,5,LOG:12)
Block(-7,38,6,LOG:12)
Block(-7,38,7,LOG:12)
Block(-7,38,8,VINE:12)
Block(-7,39,-1,LOG:12)
Block(-7,39,0,LOG:12)
Block(-7,39,1,LOG:12)
Block(-7,39,2,LOG:12)
Block(-7,39,3,LOG:12)
Block(-7,39,4,LOG:12)
Block(-7,39,5,LOG:12)
Block(-7,39,6,LOG:12)
Block(-7,39,7,LOG:12)
Block(-7,39,8,VINE:12)
Block(-7,40,-2,LOG:12)
Block(-7,40,-1,LOG:12)
Block(-7,40,0,LOG:12)
Block(-7,40,1,LOG:12)
Block(-7,40,2,LOG:12)
Block(-7,40,3,LOG:12)
Block(-7,40,4,LOG:12)
Block(-7,40,5,LOG:12)
Block(-7,40,6,LOG:12)
Block(-7,40,7,LOG:12)
Block(-7,40,8,VINE:12)
Block(-7,41,-1,LOG:12)
Block(-7,41,0,LOG:12)
Block(-7,41,1,LOG:12)
Block(-7,41,2,LOG:12)
Block(-7,41,3,LOG:12)
Block(-7,41,4,LOG:12)
Block(-7,41,5,LOG:12)
Block(-7,41,6,LOG:12)
Block(-7,41,7,LOG:12)
Block(-7,41,8,VINE:12)
Block(-7,42,-1,LOG:12)
Block(-7,42,0,LOG:12)
Block(-7,42,1,LOG:12)
Block(-7,42,2,LOG:12)
Block(-7,42,3,LOG:12)
Block(-7,42,4,LOG:12)
Block(-7,42,5,LOG:12)
Block(-7,42,6,LOG:12)
Block(-7,42,7,LOG:12)
Block(-7,42,8,VINE:4)
Block(-7,43,-1,LOG:12)
Block(-7,43,0,LOG:12)
Block(-7,43,1,LOG:12)
Block(-7,43,2,LOG:12)
Block(-7,43,3,LOG:12)
Block(-7,43,4,LOG:12)
Block(-7,43,5,LOG:12)
Block(-7,43,6,LOG:12)
Block(-7,43,7,LOG:12)
Block(-7,43,8,VINE:4)
Block(-7,44,-2,LOG:12)
Block(-7,44,-1,LOG:12)
Block(-7,44,0,LOG:12)
Block(-7,44,1,LOG:12)
Block(-7,44,2,LOG:12)
Block(-7,44,3,LOG:12)
Block(-7,44,4,LOG:12)
Block(-7,44,5,LOG:12)
Block(-7,44,6,LOG:12)
Block(-7,44,7,LOG:12)
Block(-7,45,-2,LOG:12)
Block(-7,45,-1,LOG:12)
Block(-7,45,0,LOG:12)
Block(-7,45,1,LOG:12)
Block(-7,45,2,LOG:12)
Block(-7,45,3,LOG:12)
Block(-7,45,4,LOG:12)
Block(-7,45,5,LOG:12)
Block(-7,45,6,LOG:12)
Block(-7,45,7,LOG:12)
Block(-7,45,8,LEAVES:0)
Block(-7,46,-1,LOG:12)
Block(-7,46,1,LOG:12)
Block(-7,46,2,LOG:12)
Block(-7,46,3,LOG:12)
Block(-7,46,4,LOG:12)
Block(-7,46,5,LOG:12)
Block(-7,46,6,LOG:12)
Block(-7,46,7,LOG:12)
Block(-7,46,8,LEAVES:0)
Block(-7,47,-2,LOG:12)
Block(-7,47,-1,LOG:12)
Block(-7,47,1,LOG:12)
Block(-7,47,2,LOG:12)
Block(-7,47,3,LOG:12)
Block(-7,47,4,LOG:12)
Block(-7,47,5,LOG:12)
Block(-7,47,6,LOG:12)
Block(-7,47,7,LOG:12)
Block(-7,47,8,LEAVES:0)
Block(-7,48,-2,LOG:12)
Block(-7,48,-1,LOG:12)
Block(-7,48,0,WOOD_DOUBLE_STEP:0)
Block(-7,48,1,LOG:12)
Block(-7,48,2,LOG:12)
Block(-7,48,3,LOG:12)
Block(-7,48,4,LOG:12)
Block(-7,48,5,LOG:12)
Block(-7,48,6,LOG:12)
Block(-7,48,7,LOG:12)
Block(-7,48,8,LEAVES:0)
Block(-7,49,-2,VINE:2)
Block(-7,49,0,WOOD_STEP:0)
Block(-7,49,1,LOG:12)
Block(-7,49,2,LOG:12)
Block(-7,49,3,LOG:12)
Block(-7,49,4,LOG:12)
Block(-7,49,5,LOG:12)
Block(-7,49,6,LOG:12)
Block(-7,49,7,LOG:12)
Block(-7,49,8,LOG:12)
Block(-7,50,-2,VINE:2)
Block(-7,50,1,LOG:12)
Block(-7,50,2,LOG:12)
Block(-7,50,3,LOG:12)
Block(-7,50,4,LOG:12)
Block(-7,50,5,LOG:12)
Block(-7,50,6,LOG:12)
Block(-7,50,7,LOG:12)
Block(-7,50,8,LOG:12)
Block(-7,51,-5,LOG:12)
Block(-7,51,-2,VINE:2)
Block(-7,51,1,LOG:12)
Block(-7,51,2,LOG:12)
Block(-7,51,3,LOG:12)
Block(-7,51,4,LOG:12)
Block(-7,51,5,LOG:12)
Block(-7,51,6,LOG:12)
Block(-7,51,7,LOG:12)
Block(-7,52,-6,LEAVES:0)
Block(-7,52,-5,LOG:12)
Block(-7,52,-4,LEAVES:0)
Block(-7,52,-3,LEAVES:0)
Block(-7,52,-2,LEAVES:0)
Block(-7,52,-1,LEAVES:0)
Block(-7,52,0,LEAVES:0)
Block(-7,52,1,LOG:12)
Block(-7,52,2,LOG:12)
Block(-7,52,3,LOG:12)
Block(-7,52,4,LOG:12)
Block(-7,52,5,LOG:12)
Block(-7,52,6,LOG:12)
Block(-7,52,7,LOG:12)
Block(-7,52,8,LEAVES:0)
Block(-7,53,-7,LEAVES:0)
Block(-7,53,-6,LEAVES:0)
Block(-7,53,-5,LOG:12)
Block(-7,53,-4,LEAVES:0)
Block(-7,53,-3,LEAVES:0)
Block(-7,53,-2,LEAVES:0)
Block(-7,53,-1,LEAVES:0)
Block(-7,53,0,LEAVES:0)
Block(-7,53,1,LOG:12)
Block(-7,53,2,LOG:12)
Block(-7,53,3,LOG:12)
Block(-7,53,4,LOG:12)
Block(-7,53,5,LOG:12)
Block(-7,53,6,LOG:12)
Block(-7,53,7,LOG:12)
Block(-7,53,8,LEAVES:0)
Block(-7,54,-7,LEAVES:0)
Block(-7,54,-6,LEAVES:0)
Block(-7,54,-5,LOG:12)
Block(-7,54,-4,LEAVES:0)
Block(-7,54,-3,LEAVES:0)
Block(-7,54,-2,LEAVES:0)
Block(-7,54,-1,LEAVES:0)
Block(-7,54,0,LEAVES:0)
Block(-7,54,1,LOG:12)
Block(-7,54,2,LOG:12)
Block(-7,54,3,LOG:12)
Block(-7,54,4,LOG:12)
Block(-7,54,5,LOG:12)
Block(-7,54,6,LOG:12)
Block(-7,54,7,LOG:12)
Block(-7,54,8,LEAVES:0)
Block(-7,55,-7,LEAVES:0)
Block(-7,55,-6,LEAVES:0)
Block(-7,55,-5,LOG:12)
Block(-7,55,-4,LEAVES:0)
Block(-7,55,-3,LEAVES:0)
Block(-7,55,-2,LEAVES:0)
Block(-7,55,-1,LEAVES:0)
Block(-7,55,0,LEAVES:0)
Block(-7,55,1,LOG:12)
Block(-7,55,2,LOG:12)
Block(-7,55,3,LOG:12)
Block(-7,55,4,LOG:12)
Block(-7,55,5,LOG:12)
Block(-7,55,6,LOG:12)
Block(-7,55,7,LOG:12)
Block(-7,56,-6,LEAVES:0)
Block(-7,56,-5,LOG:12)
Block(-7,56,-4,LEAVES:0)
Block(-7,56,-3,LEAVES:0)
Block(-7,56,-2,LEAVES:0)
Block(-7,56,-1,LEAVES:0)
Block(-7,56,1,LOG:12)
Block(-7,56,2,LOG:12)
Block(-7,56,3,LOG:12)
Block(-7,56,4,LOG:12)
Block(-7,56,5,LOG:12)
Block(-7,56,6,LOG:12)
Block(-7,56,7,LOG:12)
Block(-7,57,-6,LEAVES:0)
Block(-7,57,-5,LEAVES:0)
Block(-7,57,-4,LEAVES:0)
Block(-7,57,-2,LEAVES:0)
Block(-7,57,1,LOG:12)
Block(-7,57,2,LOG:12)
Block(-7,57,3,LOG:12)
Block(-7,57,4,LOG:12)
Block(-7,57,5,LOG:12)
Block(-7,57,6,LOG:12)
Block(-7,57,7,LOG:12)
Block(-7,58,1,LOG:12)
Block(-7,58,2,LOG:12)
Block(-7,58,3,LOG:12)
Block(-7,58,4,LOG:12)
Block(-7,58,5,LOG:12)
Block(-7,58,6,LOG:12)
Block(-7,58,7,LOG:12)
Block(-7,59,1,LOG:12)
Block(-7,59,2,LOG:12)
Block(-7,59,3,LOG:12)
Block(-7,59,4,LOG:12)
Block(-7,59,5,LOG:12)
Block(-7,59,6,LOG:12)
Block(-7,59,7,LOG:12)
Block(-7,59,8,LOG:12)
Block(-7,60,-5,LOG:12)
Block(-7,60,-4,LOG:12)
Block(-7,60,-3,LOG:12)
Block(-7,60,-2,LOG:12)
Block(-7,60,1,LOG:12)
Block(-7,60,2,LOG:12)
Block(-7,60,3,LOG:12)
Block(-7,60,4,LOG:12)
Block(-7,60,5,LOG:12)
Block(-7,60,6,LOG:12)
Block(-7,60,7,LOG:12)
Block(-7,60,8,VINE:4)
Block(-7,61,-7,LOG:12)
Block(-7,61,-6,LOG:12)
Block(-7,61,-5,LOG:12)
Block(-7,61,-4,LOG:12)
Block(-7,61,-3,LOG:12)
Block(-7,61,-2,LOG:12)
Block(-7,61,1,LOG:12)
Block(-7,61,2,LOG:12)
Block(-7,61,3,LOG:12)
Block(-7,61,4,LOG:12)
Block(-7,61,5,LOG:12)
Block(-7,61,6,LOG:12)
Block(-7,61,7,LOG:12)
Block(-7,61,8,VINE:4)
Block(-7,62,-5,LOG:12)
Block(-7,62,-4,LOG:12)
Block(-7,62,1,LOG:12)
Block(-7,62,2,LOG:12)
Block(-7,62,3,LOG:12)
Block(-7,62,4,LOG:12)
Block(-7,62,5,LOG:12)
Block(-7,62,6,LOG:12)
Block(-7,62,7,LOG:12)
Block(-7,62,8,VINE:4)
Block(-7,63,-5,LOG:12)
Block(-7,63,-4,LOG:12)
Block(-7,63,1,LOG:12)
Block(-7,63,2,LOG:12)
Block(-7,63,3,LOG:12)
Block(-7,63,4,LOG:12)
Block(-7,63,5,LOG:12)
Block(-7,63,6,LOG:12)
Block(-7,63,7,LOG:12)
Block(-7,63,8,VINE:4)
Block(-7,64,-6,LEAVES:0)
Block(-7,64,-5,LOG:12)
Block(-7,64,-4,LOG:12)
Block(-7,64,-3,LEAVES:0)
Block(-7,64,-2,LEAVES:0)
Block(-7,64,1,LOG:12)
Block(-7,64,2,LOG:12)
Block(-7,64,3,LOG:12)
Block(-7,64,4,LOG:12)
Block(-7,64,5,LOG:12)
Block(-7,64,6,LOG:12)
Block(-7,64,7,LOG:12)
Block(-7,65,-7,LEAVES:0)
Block(-7,65,-6,LEAVES:0)
Block(-7,65,-5,LOG:12)
Block(-7,65,-4,LOG:12)
Block(-7,65,-3,LEAVES:0)
Block(-7,65,-2,LEAVES:0)
Block(-7,65,1,LOG:12)
Block(-7,65,2,LOG:12)
Block(-7,65,3,LOG:12)
Block(-7,65,4,LOG:12)
Block(-7,65,5,LOG:12)
Block(-7,65,6,LOG:12)
Block(-7,65,7,LOG:12)
Block(-7,66,-7,LEAVES:0)
Block(-7,66,-6,LEAVES:0)
Block(-7,66,-5,LOG:12)
Block(-7,66,-4,LOG:12)
Block(-7,66,-3,LEAVES:0)
Block(-7,66,-2,LOG:12)
Block(-7,66,-1,LOG:12)
Block(-7,66,0,LOG:12)
Block(-7,66,1,LOG:12)
Block(-7,66,2,LOG:12)
Block(-7,66,3,LOG:12)
Block(-7,66,4,LOG:12)
Block(-7,66,5,LOG:12)
Block(-7,66,6,LOG:12)
Block(-7,66,7,LOG:12)
Block(-7,67,-7,LEAVES:0)
Block(-7,67,-6,LEAVES:0)
Block(-7,67,-5,LOG:12)
Block(-7,67,-4,LEAVES:0)
Block(-7,67,-3,LEAVES:0)
Block(-7,67,-2,LOG:12)
Block(-7,67,-1,LOG:12)
Block(-7,67,0,LOG:12)
Block(-7,67,1,LOG:12)
Block(-7,67,2,LOG:12)
Block(-7,67,3,LOG:12)
Block(-7,67,4,LOG:12)
Block(-7,67,5,LOG:12)
Block(-7,67,6,LOG:12)
Block(-7,67,7,LOG:12)
Block(-7,68,-7,LEAVES:0)
Block(-7,68,-6,LEAVES:0)
Block(-7,68,-5,LOG:12)
Block(-7,68,-4,LEAVES:0)
Block(-7,68,-3,LEAVES:0)
Block(-7,68,1,LOG:12)
Block(-7,68,2,LOG:12)
Block(-7,68,3,LOG:12)
Block(-7,68,4,LOG:12)
Block(-7,68,5,LOG:12)
Block(-7,68,6,LOG:12)
Block(-7,68,7,LOG:12)
Block(-7,69,-7,LEAVES:0)
Block(-7,69,-6,LEAVES:0)
Block(-7,69,-5,LEAVES:0)
Block(-7,69,-4,LEAVES:0)
Block(-7,69,-3,LEAVES:0)
Block(-7,69,1,LOG:12)
Block(-7,69,2,LOG:12)
Block(-7,69,3,LOG:12)
Block(-7,69,4,LOG:12)
Block(-7,69,5,LOG:12)
Block(-7,69,6,LOG:12)
Block(-7,69,7,LOG:12)
Block(-7,70,-6,VINE:2)
Block(-7,70,-5,LEAVES:0)
Block(-7,70,1,LOG:12)
Block(-7,70,2,LOG:12)
Block(-7,70,3,LOG:12)
Block(-7,70,4,LOG:12)
Block(-7,70,5,LOG:12)
Block(-7,70,6,LOG:12)
Block(-7,70,7,LOG:12)
Block(-7,71,-6,VINE:2)
Block(-7,71,1,LOG:12)
Block(-7,71,2,LOG:12)
Block(-7,71,3,LOG:12)
Block(-7,71,4,LOG:12)
Block(-7,71,5,LOG:12)
Block(-7,71,6,LOG:12)
Block(-7,71,7,LOG:12)
Block(-7,72,-7,LEAVES:0)
Block(-7,72,-6,LEAVES:0)
Block(-7,72,-5,LEAVES:0)
Block(-7,72,-4,LEAVES:0)
Block(-7,72,-3,LEAVES:0)
Block(-7,72,-2,LOG:12)
Block(-7,72,0,LOG:12)
Block(-7,72,1,LOG:12)
Block(-7,72,2,LOG:12)
Block(-7,72,3,LOG:12)
Block(-7,72,4,LOG:12)
Block(-7,72,5,LOG:12)
Block(-7,72,6,LOG:12)
Block(-7,72,7,LOG:12)
Block(-7,72,8,LOG:12)
Block(-7,73,-7,LEAVES:0)
Block(-7,73,-6,LEAVES:0)
Block(-7,73,-5,LEAVES:0)
Block(-7,73,-4,LEAVES:0)
Block(-7,73,-3,LEAVES:0)
Block(-7,73,-2,LOG:12)
Block(-7,73,-1,LEAVES:0)
Block(-7,73,0,LOG:12)
Block(-7,73,1,LOG:12)
Block(-7,73,2,LOG:12)
Block(-7,73,3,LOG:12)
Block(-7,73,4,LOG:12)
Block(-7,73,5,LOG:12)
Block(-7,73,6,LOG:12)
Block(-7,73,7,LOG:12)
Block(-7,73,8,LOG:12)
Block(-7,74,-7,LEAVES:0)
Block(-7,74,-6,LOG:12)
Block(-7,74,-5,LEAVES:0)
Block(-7,74,-4,LEAVES:0)
Block(-7,74,-3,LEAVES:0)
Block(-7,74,-2,LOG:12)
Block(-7,74,-1,LEAVES:0)
Block(-7,74,0,LOG:12)
Block(-7,74,1,LOG:12)
Block(-7,74,2,LOG:12)
Block(-7,74,3,LOG:12)
Block(-7,74,4,LOG:12)
Block(-7,74,5,LOG:12)
Block(-7,74,6,LOG:12)
Block(-7,74,7,LOG:12)
Block(-7,74,8,LOG:12)
Block(-7,75,-7,LEAVES:0)
Block(-7,75,-6,LEAVES:0)
Block(-7,75,-5,LEAVES:0)
Block(-7,75,-4,LEAVES:0)
Block(-7,75,-3,LEAVES:0)
Block(-7,75,-2,LOG:12)
Block(-7,75,-1,LEAVES:0)
Block(-7,75,0,LOG:12)
Block(-7,75,1,LOG:12)
Block(-7,75,2,LOG:12)
Block(-7,75,3,LOG:12)
Block(-7,75,4,LOG:12)
Block(-7,75,5,LOG:12)
Block(-7,75,6,LOG:12)
Block(-7,75,7,LOG:12)
Block(-7,75,8,LOG:12)
Block(-7,76,-7,LEAVES:0)
Block(-7,76,-6,LEAVES:0)
Block(-7,76,-5,LEAVES:0)
Block(-7,76,-4,LEAVES:0)
Block(-7,76,-3,LEAVES:0)
Block(-7,76,-2,LOG:12)
Block(-7,76,-1,LEAVES:0)
Block(-7,76,0,LOG:12)
Block(-7,76,1,LOG:12)
Block(-7,76,2,LOG:12)
Block(-7,76,3,LOG:12)
Block(-7,76,4,LOG:12)
Block(-7,76,5,LOG:12)
Block(-7,76,6,LOG:12)
Block(-7,76,7,LOG:12)
Block(-7,76,8,LOG:12)
Block(-7,77,-7,LEAVES:0)
Block(-7,77,-6,LEAVES:0)
Block(-7,77,-5,LEAVES:0)
Block(-7,77,-4,LEAVES:0)
Block(-7,77,-3,LEAVES:0)
Block(-7,77,-2,LOG:12)
Block(-7,77,-1,LEAVES:0)
Block(-7,77,0,LEAVES:0)
Block(-7,77,1,LOG:12)
Block(-7,77,2,LOG:12)
Block(-7,77,3,LOG:12)
Block(-7,77,4,LOG:12)
Block(-7,77,5,LOG:12)
Block(-7,77,6,LOG:12)
Block(-7,77,7,LOG:12)
Block(-7,77,8,LOG:12)
Block(-7,78,-6,LEAVES:0)
Block(-7,78,-4,LEAVES:0)
Block(-7,78,-3,LEAVES:0)
Block(-7,78,-2,LOG:12)
Block(-7,78,-1,LEAVES:0)
Block(-7,78,0,LEAVES:0)
Block(-7,78,1,LEAVES:0)
Block(-7,78,2,LEAVES:0)
Block(-7,78,3,LEAVES:0)
Block(-7,78,4,LEAVES:0)
Block(-7,78,5,LEAVES:0)
Block(-7,78,6,LOG:12)
Block(-7,78,7,LEAVES:0)
Block(-7,78,8,LOG:12)
Block(-7,79,-4,LEAVES:0)
Block(-7,79,-3,LEAVES:0)
Block(-7,79,-2,LEAVES:0)
Block(-7,79,-1,LEAVES:0)
Block(-7,79,0,LEAVES:0)
Block(-7,79,1,LEAVES:0)
Block(-7,79,2,LEAVES:0)
Block(-7,79,3,LEAVES:0)
Block(-7,79,4,LEAVES:0)
Block(-7,79,5,LEAVES:0)
Block(-7,79,6,LOG:12)
Block(-7,79,7,LEAVES:0)
Block(-7,79,8,LOG:12)
Block(-7,80,-4,LEAVES:0)
Block(-7,80,-3,LEAVES:0)
Block(-7,80,-2,LEAVES:0)
Block(-7,80,-1,LEAVES:0)
Block(-7,80,0,LEAVES:0)
Block(-7,80,1,LEAVES:0)
Block(-7,80,2,LEAVES:0)
Block(-7,80,3,LEAVES:0)
Block(-7,80,4,LOG:12)
Block(-7,80,5,LEAVES:0)
Block(-7,80,6,LOG:12)
Block(-7,80,7,LEAVES:0)
Block(-7,80,8,LOG:12)
Block(-7,81,-5,LEAVES:0)
Block(-7,81,-3,LEAVES:0)
Block(-7,81,-2,LEAVES:0)
Block(-7,81,-1,LEAVES:0)
Block(-7,81,1,LEAVES:0)
Block(-7,81,2,LEAVES:0)
Block(-7,81,3,LEAVES:0)
Block(-7,81,4,LEAVES:0)
Block(-7,81,5,LEAVES:0)
Block(-7,81,6,LOG:12)
Block(-7,81,7,LEAVES:0)
Block(-7,81,8,LOG:12)
Block(-7,82,-7,LEAVES:0)
Block(-7,82,-6,LEAVES:0)
Block(-7,82,-5,LEAVES:0)
Block(-7,82,-4,LEAVES:0)
Block(-7,82,-3,LEAVES:0)
Block(-7,82,2,LEAVES:0)
Block(-7,82,3,LEAVES:0)
Block(-7,82,4,LEAVES:0)
Block(-7,82,5,LEAVES:0)
Block(-7,82,6,LOG:12)
Block(-7,82,7,LEAVES:0)
Block(-7,82,8,LEAVES:0)
Block(-7,83,-7,LEAVES:0)
Block(-7,83,-6,LEAVES:0)
Block(-7,83,-5,LEAVES:0)
Block(-7,83,-4,LEAVES:0)
Block(-7,83,-3,LEAVES:0)
Block(-7,83,0,LEAVES:0)
Block(-7,83,1,LOG:12)
Block(-7,83,3,LEAVES:0)
Block(-7,83,4,LEAVES:0)
Block(-7,83,5,LEAVES:0)
Block(-7,83,6,LEAVES:0)
Block(-7,83,7,LEAVES:0)
Block(-7,83,8,LEAVES:0)
Block(-7,84,-5,LEAVES:0)
Block(-7,84,-2,LEAVES:0)
Block(-7,84,-1,LEAVES:0)
Block(-7,84,0,LEAVES:0)
Block(-7,84,1,LEAVES:0)
Block(-7,84,2,LEAVES:0)
Block(-7,84,4,LEAVES:0)
Block(-7,84,5,LEAVES:0)
Block(-7,84,6,LEAVES:0)
Block(-7,84,7,LEAVES:0)
Block(-7,84,8,LEAVES:0)
Block(-7,85,-1,LEAVES:0)
Block(-7,85,0,LEAVES:0)
Block(-7,85,1,LEAVES:0)
Block(-7,85,2,LEAVES:0)
Block(-7,85,5,LEAVES:0)
Block(-7,85,6,LEAVES:0)
Block(-7,85,7,LEAVES:0)
Block(-7,86,0,LEAVES:0)
Block(-7,86,4,LEAVES:0)
Block(-7,86,5,LEAVES:0)
Block(-7,86,6,LEAVES:0)
Block(-7,86,7,LEAVES:0)
Block(-7,87,5,LEAVES:0)
Block(-7,87,6,LEAVES:0)
RandomBlock(-7,95,-2,quark:quilted_wool:0,10,quark:quilted_wool:0,100)
RandomBlock(-7,95,-1,quark:quilted_wool:0,10,quark:quilted_wool:0,100)
RandomBlock(-7,95,0,quark:quilted_wool:0,10,quark:quilted_wool:0,100)
RandomBlock(-7,95,1,quark:quilted_wool:0,10,quark:quilted_wool:0,100)
RandomBlock(-7,95,2,quark:quilted_wool:0,10,quark:quilted_wool:0,100)
RandomBlock(-7,96,-3,quark:quilted_wool:0,10,quark:quilted_wool:0,100)
RandomBlock(-7,96,-2,quark:quilted_wool:0,10,quark:quilted_wool:0,100)
RandomBlock(-7,96,-1,quark:quilted_wool:0,10,quark:quilted_wool:0,100)
RandomBlock(-7,96,0,quark:quilted_wool:0,10,quark:quilted_wool:0,100)
RandomBlock(-7,96,1,quark:quilted_wool:0,10,quark:quilted_wool:0,100)
RandomBlock(-7,96,2,quark:quilted_wool:0,10,quark:quilted_wool:0,100)
RandomBlock(-7,96,3,quark:quilted_wool:0,10,quark:quilted_wool:0,100)
RandomBlock(-7,96,8,quark:quilted_wool:0,10,quark:quilted_wool:0,100)
RandomBlock(-7,97,-4,quark:quilted_wool:0,10,quark:quilted_wool:0,100)
RandomBlock(-7,97,-3,quark:quilted_wool:0,10,quark:quilted_wool:0,100)
RandomBlock(-7,97,-2,quark:quilted_wool:0,10,quark:quilted_wool:0,100)
RandomBlock(-7,97,-1,quark:quilted_wool:0,10,quark:quilted_wool:0,100)
RandomBlock(-7,97,0,quark:quilted_wool:0,10,quark:quilted_wool:0,100)
RandomBlock(-7,97,1,quark:quilted_wool:0,10,quark:quilted_wool:0,100)
RandomBlock(-7,97,2,quark:quilted_wool:0,10,quark:quilted_wool:0,100)
RandomBlock(-7,97,3,quark:quilted_wool:0,10,quark:quilted_wool:0,100)
RandomBlock(-7,97,4,quark:quilted_wool:0,10,quark:quilted_wool:0,100)
RandomBlock(-7,97,8,quark:quilted_wool:0,10,quark:quilted_wool:0,100)
RandomBlock(-7,98,-5,quark:quilted_wool:0,10,quark:quilted_wool:0,100)
RandomBlock(-7,98,-4,quark:quilted_wool:0,10,quark:quilted_wool:0,100)
RandomBlock(-7,98,-3,quark:quilted_wool:0,10,quark:quilted_wool:0,100)
RandomBlock(-7,98,-2,quark:quilted_wool:0,10,quark:quilted_wool:0,100)
RandomBlock(-7,98,-1,quark:quilted_wool:0,10,quark:quilted_wool:0,100)
RandomBlock(-7,98,0,quark:quilted_wool:0,10,quark:quilted_wool:0,100)
RandomBlock(-7,98,1,quark:quilted_wool:0,10,quark:quilted_wool:0,100)
RandomBlock(-7,98,2,quark:quilted_wool:0,10,quark:quilted_wool:0,100)
RandomBlock(-7,98,3,quark:quilted_wool:0,10,quark:quilted_wool:0,100)
RandomBlock(-7,98,4,quark:quilted_wool:0,10,quark:quilted_wool:0,100)
RandomBlock(-7,98,5,quark:quilted_wool:0,10,quark:quilted_wool:0,100)
RandomBlock(-7,98,8,quark:quilted_wool:0,10,quark:quilted_wool:0,100)
RandomBlock(-7,99,-5,quark:quilted_wool:0,10,quark:quilted_wool:0,100)
RandomBlock(-7,99,-4,quark:quilted_wool:0,10,quark:quilted_wool:0,100)
RandomBlock(-7,99,-3,quark:quilted_wool:0,10,quark:quilted_wool:0,100)
RandomBlock(-7,99,-2,quark:quilted_wool:0,10,quark:quilted_wool:0,100)
RandomBlock(-7,99,-1,quark:quilted_wool:0,10,quark:quilted_wool:0,100)
RandomBlock(-7,99,0,quark:quilted_wool:0,10,quark:quilted_wool:0,100)
RandomBlock(-7,99,1,quark:quilted_wool:0,10,quark:quilted_wool:0,100)
RandomBlock(-7,99,2,quark:quilted_wool:0,10,quark:quilted_wool:0,100)
RandomBlock(-7,99,3,quark:quilted_wool:0,10,quark:quilted_wool:0,100)
RandomBlock(-7,99,4,quark:quilted_wool:0,10,quark:quilted_wool:0,100)
RandomBlock(-7,99,5,quark:quilted_wool:0,10,quark:quilted_wool:0,100)
RandomBlock(-7,99,8,quark:quilted_wool:0,10,quark:quilted_wool:0,100)
RandomBlock(-7,100,-6,quark:quilted_wool:0,10,quark:quilted_wool:0,100)
RandomBlock(-7,100,-5,quark:quilted_wool:0,10,quark:quilted_wool:0,100)
RandomBlock(-7,100,-4,quark:quilted_wool:0,10,quark:quilted_wool:0,100)
RandomBlock(-7,100,-3,quark:quilted_wool:0,10,quark:quilted_wool:0,100)
RandomBlock(-7,100,-2,quark:quilted_wool:0,10,quark:quilted_wool:0,100)
RandomBlock(-7,100,-1,quark:quilted_wool:0,10,quark:quilted_wool:0,100)
RandomBlock(-7,100,0,quark:quilted_wool:0,10,quark:quilted_wool:0,100)
RandomBlock(-7,100,1,quark:quilted_wool:0,10,quark:quilted_wool:0,100)
RandomBlock(-7,100,2,quark:quilted_wool:0,10,quark:quilted_wool:0,100)
RandomBlock(-7,100,3,quark:quilted_wool:0,10,quark:quilted_wool:0,100)
RandomBlock(-7,100,4,quark:quilted_wool:0,10,quark:quilted_wool:0,100)
RandomBlock(-7,100,5,quark:quilted_wool:0,10,quark:quilted_wool:0,100)
RandomBlock(-7,100,6,quark:quilted_wool:0,10,quark:quilted_wool:0,100)
RandomBlock(-7,100,8,quark:quilted_wool:0,10,quark:quilted_wool:0,100)
RandomBlock(-7,101,-6,quark:quilted_wool:0,10,quark:quilted_wool:0,100)
RandomBlock(-7,101,-5,quark:quilted_wool:0,10,quark:quilted_wool:0,100)
RandomBlock(-7,101,-4,quark:quilted_wool:0,10,quark:quilted_wool:0,100)
RandomBlock(-7,101,-3,quark:quilted_wool:0,10,quark:quilted_wool:0,100)
RandomBlock(-7,101,-2,quark:quilted_wool:0,10,quark:quilted_wool:0,100)
RandomBlock(-7,101,-1,quark:quilted_wool:0,10,quark:quilted_wool:0,100)
RandomBlock(-7,101,0,quark:quilted_wool:0,10,quark:quilted_wool:0,100)
RandomBlock(-7,101,1,quark:quilted_wool:0,10,quark:quilted_wool:0,100)
RandomBlock(-7,101,2,quark:quilted_wool:0,10,quark:quilted_wool:0,100)
RandomBlock(-7,101,3,quark:quilted_wool:0,10,quark:quilted_wool:0,100)
RandomBlock(-7,101,4,quark:quilted_wool:0,10,quark:quilted_wool:0,100)
RandomBlock(-7,101,5,quark:quilted_wool:0,10,quark:quilted_wool:0,100)
RandomBlock(-7,101,6,quark:quilted_wool:0,10,quark:quilted_wool:0,100)
RandomBlock(-7,102,-6,quark:quilted_wool:0,10,quark:quilted_wool:0,100)
RandomBlock(-7,102,-5,quark:quilted_wool:0,10,quark:quilted_wool:0,100)
RandomBlock(-7,102,-4,quark:quilted_wool:0,10,quark:quilted_wool:0,100)
RandomBlock(-7,102,-3,quark:quilted_wool:0,10,quark:quilted_wool:0,100)
RandomBlock(-7,102,-2,quark:quilted_wool:0,10,quark:quilted_wool:0,100)
RandomBlock(-7,102,-1,quark:quilted_wool:0,10,quark:quilted_wool:0,100)
RandomBlock(-7,102,0,quark:quilted_wool:0,10,quark:quilted_wool:0,100)
RandomBlock(-7,102,1,quark:quilted_wool:0,10,quark:quilted_wool:0,100)
RandomBlock(-7,102,2,quark:quilted_wool:0,10,quark:quilted_wool:0,100)
RandomBlock(-7,102,3,quark:quilted_wool:0,10,quark:quilted_wool:0,100)
RandomBlock(-7,102,4,quark:quilted_wool:0,10,quark:quilted_wool:0,100)
RandomBlock(-7,102,5,quark:quilted_wool:0,10,quark:quilted_wool:0,100)
RandomBlock(-7,102,6,quark:quilted_wool:0,10,quark:quilted_wool:0,100)
RandomBlock(-7,103,-6,quark:quilted_wool:0,10,quark:quilted_wool:0,100)
RandomBlock(-7,103,-5,quark:quilted_wool:0,10,quark:quilted_wool:0,100)
RandomBlock(-7,103,-4,quark:quilted_wool:0,10,quark:quilted_wool:0,100)
RandomBlock(-7,103,-3,quark:quilted_wool:0,10,quark:quilted_wool:0,100)
RandomBlock(-7,103,-2,quark:quilted_wool:0,10,quark:quilted_wool:0,100)
RandomBlock(-7,103,-1,quark:quilted_wool:0,10,quark:quilted_wool:0,100)
RandomBlock(-7,103,0,quark:quilted_wool:0,10,quark:quilted_wool:0,100)
RandomBlock(-7,103,1,quark:quilted_wool:0,10,quark:quilted_wool:0,100)
RandomBlock(-7,103,2,quark:quilted_wool:0,10,quark:quilted_wool:0,100)
RandomBlock(-7,103,3,quark:quilted_wool:0,10,quark:quilted_wool:0,100)
RandomBlock(-7,103,4,quark:quilted_wool:0,10,quark:quilted_wool:0,100)
RandomBlock(-7,103,5,quark:quilted_wool:0,10,quark:quilted_wool:0,100)
RandomBlock(-7,103,6,quark:quilted_wool:0,10,quark:quilted_wool:0,100)
RandomBlock(-7,104,-6,quark:quilted_wool:0,10,quark:quilted_wool:0,100)
RandomBlock(-7,104,-5,quark:quilted_wool:0,10,quark:quilted_wool:0,100)
RandomBlock(-7,104,-4,quark:quilted_wool:0,10,quark:quilted_wool:0,100)
RandomBlock(-7,104,-3,quark:quilted_wool:0,10,quark:quilted_wool:0,100)
RandomBlock(-7,104,-2,quark:quilted_wool:0,10,quark:quilted_wool:0,100)
RandomBlock(-7,104,-1,quark:quilted_wool:0,10,quark:quilted_wool:0,100)
RandomBlock(-7,104,0,quark:quilted_wool:0,10,quark:quilted_wool:0,100)
RandomBlock(-7,104,1,quark:quilted_wool:0,10,quark:quilted_wool:0,100)
RandomBlock(-7,104,2,quark:quilted_wool:0,10,quark:quilted_wool:0,100)
RandomBlock(-7,104,3,quark:quilted_wool:0,10,quark:quilted_wool:0,100)
RandomBlock(-7,104,4,quark:quilted_wool:0,10,quark:quilted_wool:0,100)
RandomBlock(-7,104,5,quark:quilted_wool:0,10,quark:quilted_wool:0,100)
RandomBlock(-7,104,6,quark:quilted_wool:0,10,quark:quilted_wool:0,100)
RandomBlock(-7,105,-5,quark:quilted_wool:0,10,quark:quilted_wool:0,100)
RandomBlock(-7,105,-4,quark:quilted_wool:0,10,quark:quilted_wool:0,100)
RandomBlock(-7,105,-3,quark:quilted_wool:0,10,quark:quilted_wool:0,100)
RandomBlock(-7,105,-2,quark:quilted_wool:0,10,quark:quilted_wool:0,100)
RandomBlock(-7,105,-1,quark:quilted_wool:0,10,quark:quilted_wool:0,100)
RandomBlock(-7,105,0,quark:quilted_wool:0,10,quark:quilted_wool:0,100)
RandomBlock(-7,105,1,quark:quilted_wool:0,10,quark:quilted_wool:0,100)
RandomBlock(-7,105,2,quark:quilted_wool:0,10,quark:quilted_wool:0,100)
RandomBlock(-7,105,3,quark:quilted_wool:0,10,quark:quilted_wool:0,100)
RandomBlock(-7,105,4,quark:quilted_wool:0,10,quark:quilted_wool:0,100)
RandomBlock(-7,105,5,quark:quilted_wool:0,10,quark:quilted_wool:0,100)
RandomBlock(-7,106,-5,quark:quilted_wool:0,10,quark:quilted_wool:0,100)
RandomBlock(-7,106,-4,quark:quilted_wool:0,10,quark:quilted_wool:0,100)
RandomBlock(-7,106,-3,quark:quilted_wool:0,10,quark:quilted_wool:0,100)
RandomBlock(-7,106,-2,quark:quilted_wool:0,10,quark:quilted_wool:0,100)
RandomBlock(-7,106,-1,quark:quilted_wool:0,10,quark:quilted_wool:0,100)
RandomBlock(-7,106,0,quark:quilted_wool:0,10,quark:quilted_wool:0,100)
RandomBlock(-7,106,1,quark:quilted_wool:0,10,quark:quilted_wool:0,100)
RandomBlock(-7,106,2,quark:quilted_wool:0,10,quark:quilted_wool:0,100)
RandomBlock(-7,106,3,quark:quilted_wool:0,10,quark:quilted_wool:0,100)
RandomBlock(-7,106,4,quark:quilted_wool:0,10,quark:quilted_wool:0,100)
RandomBlock(-7,106,5,quark:quilted_wool:0,10,quark:quilted_wool:0,100)
RandomBlock(-7,107,-4,quark:quilted_wool:0,10,quark:quilted_wool:0,100)
RandomBlock(-7,107,-3,quark:quilted_wool:0,10,quark:quilted_wool:0,100)
RandomBlock(-7,107,-2,quark:quilted_wool:0,10,quark:quilted_wool:0,100)
RandomBlock(-7,107,-1,quark:quilted_wool:0,10,quark:quilted_wool:0,100)
RandomBlock(-7,107,0,quark:quilted_wool:0,10,quark:quilted_wool:0,100)
RandomBlock(-7,107,1,quark:quilted_wool:0,10,quark:quilted_wool:0,100)
RandomBlock(-7,107,2,quark:quilted_wool:0,10,quark:quilted_wool:0,100)
RandomBlock(-7,107,3,quark:quilted_wool:0,10,quark:quilted_wool:0,100)
RandomBlock(-7,107,4,quark:quilted_wool:0,10,quark:quilted_wool:0,100)
RandomBlock(-7,108,-3,quark:quilted_wool:0,10,quark:quilted_wool:0,100)
RandomBlock(-7,108,-2,quark:quilted_wool:0,10,quark:quilted_wool:0,100)
RandomBlock(-7,108,-1,quark:quilted_wool:0,10,quark:quilted_wool:0,100)
RandomBlock(-7,108,0,quark:quilted_wool:0,10,quark:quilted_wool:0,100)
RandomBlock(-7,108,1,quark:quilted_wool:0,10,quark:quilted_wool:0,100)
RandomBlock(-7,108,2,quark:quilted_wool:0,10,quark:quilted_wool:0,100)
RandomBlock(-7,108,3,quark:quilted_wool:0,10,quark:quilted_wool:0,100)
RandomBlock(-7,109,-2,quark:quilted_wool:0,10,quark:quilted_wool:0,100)
RandomBlock(-7,109,-1,quark:quilted_wool:0,10,quark:quilted_wool:0,100)
RandomBlock(-7,109,0,quark:quilted_wool:0,10,quark:quilted_wool:0,100)
RandomBlock(-7,109,1,quark:quilted_wool:0,10,quark:quilted_wool:0,100)
RandomBlock(-7,109,2,quark:quilted_wool:0,10,quark:quilted_wool:0,100)
Block(-6,11,8,LOG:12)
Block(-6,12,7,LOG:12)
Block(-6,12,8,LOG:12)
Block(-6,13,7,LOG:12)
Block(-6,13,8,LOG:12)
Block(-6,14,6,LOG:12)
Block(-6,14,7,LOG:12)
Block(-6,14,8,LOG:12)
Block(-6,15,5,LOG:12)
Block(-6,15,6,LOG:12)
Block(-6,15,7,LOG:12)
Block(-6,15,8,LOG:12)
Block(-6,16,5,LOG:12)
Block(-6,16,6,LOG:12)
Block(-6,16,7,LOG:12)
Block(-6,16,8,LOG:12)
Block(-6,17,-3,LOG:12)
Block(-6,17,-2,LOG:12)
Block(-6,17,-1,LOG:12)
Block(-6,17,0,LEAVES:0)
Block(-6,17,5,LOG:12)
Block(-6,17,6,LOG:12)
Block(-6,17,7,LOG:12)
Block(-6,17,8,quark:leaf_carpet)
Block(-6,18,-4,LOG:12)
Block(-6,18,-3,LOG:12)
Block(-6,18,-2,LOG:12)
Block(-6,18,-1,LOG:12)
Block(-6,18,0,LOG:12)
Block(-6,18,1,LEAVES:0)
Block(-6,18,2,LEAVES:0)
Block(-6,18,3,LEAVES:0)
Block(-6,18,4,LEAVES:0)
Block(-6,18,5,LOG:12)
Block(-6,18,6,LOG:12)
Block(-6,18,7,LOG:12)
Block(-6,18,8,LEAVES:0)
Block(-6,19,-3,LOG:12)
Block(-6,19,-2,LOG:12)
Block(-6,19,-1,LOG:12)
Block(-6,19,0,LOG:12)
Block(-6,19,1,LOG:12)
Block(-6,19,2,LOG:12)
Block(-6,19,3,LOG:12)
Block(-6,19,4,LOG:12)
Block(-6,19,5,LOG:12)
Block(-6,19,6,LOG:12)
Block(-6,19,7,LOG:12)
Block(-6,19,8,LOG:12)
Block(-6,20,-4,LOG:12)
Block(-6,20,-3,LOG:12)
Block(-6,20,-2,LOG:12)
Block(-6,20,-1,LOG:12)
Block(-6,20,0,LOG:12)
Block(-6,20,1,LOG:12)
Block(-6,20,2,LOG:12)
Block(-6,20,3,LOG:12)
Block(-6,20,4,LOG:12)
Block(-6,20,5,LOG:12)
Block(-6,20,6,LOG:12)
Block(-6,20,7,LOG:12)
Block(-6,20,8,LOG:12)
Block(-6,21,-4,LOG:12)
Block(-6,21,-3,LOG:12)
Block(-6,21,-2,LOG:12)
Block(-6,21,-1,LOG:12)
Block(-6,21,0,LOG:12)
Block(-6,21,1,LOG:12)
Block(-6,21,2,LOG:12)
Block(-6,21,3,LOG:12)
Block(-6,21,5,LOG:12)
Block(-6,21,6,LEAVES:4)
Block(-6,21,7,LOG:12)
Block(-6,21,8,LOG:12)
Block(-6,22,-4,LOG:12)
Block(-6,22,-3,LOG:12)
Block(-6,22,-2,LOG:12)
Block(-6,22,-1,LOG:12)
Block(-6,22,0,LOG:12)
Block(-6,22,1,LOG:12)
Block(-6,22,5,LEAVES:12)
Block(-6,22,6,VINE:2)
Block(-6,22,7,VINE:3)
Block(-6,22,8,LOG:12)
Block(-6,23,-3,quark:leaf_carpet)
Block(-6,23,-2,LEAVES:0)
Block(-6,23,-1,LOG:12)
Block(-6,23,0,LOG:12)
Block(-6,23,5,LEAVES:4)
Block(-6,23,6,VINE:2)
Block(-6,23,7,VINE:3)
Block(-6,23,8,LOG:12)
Block(-6,24,-3,LEAVES:0)
Block(-6,24,-2,LEAVES:0)
Block(-6,24,-1,LOG:12)
Block(-6,24,0,LOG:12)
Block(-6,24,1,LOG:12)
Block(-6,24,2,LOG:12)
Block(-6,24,3,LOG:12)
Block(-6,24,4,LOG:12)
Block(-6,24,5,LOG:12)
Block(-6,24,6,LOG:12)
Block(-6,24,7,LOG:12)
Block(-6,24,8,LOG:12)
Block(-6,25,-5,LEAVES:0)
Block(-6,25,-2,LEAVES:0)
Block(-6,25,-1,LOG:12)
Block(-6,25,0,LOG:12)
Block(-6,25,1,LOG:12)
Block(-6,25,7,LEAVES:4)
Block(-6,25,8,LOG:12)
Block(-6,26,-1,LOG:12)
Block(-6,26,0,LOG:12)
Block(-6,26,1,LOG:12)
Block(-6,26,6,LOG:12)
Block(-6,26,7,VINE:3)
Block(-6,26,8,LOG:12)
Block(-6,27,-1,LOG:12)
Block(-6,27,0,LOG:12)
Block(-6,27,1,LOG:12)
Block(-6,27,2,WOOD_STAIRS:7)
Block(-6,27,4,LOG:12)
Block(-6,27,7,VINE:3)
Block(-6,27,8,LOG:12)
Block(-6,28,0,LOG:12)
Block(-6,28,1,LOG:12)
Block(-6,28,2,LOG:12)
Block(-6,28,6,VINE:2)
Block(-6,28,7,VINE:3)
Block(-6,28,8,LOG:12)
Block(-6,29,-1,LOG:12)
Block(-6,29,0,LOG:12)
Block(-6,29,1,LOG:12)
Block(-6,29,6,VINE:2)
Block(-6,29,7,VINE:3)
Block(-6,29,8,LOG:12)
Block(-6,30,-1,LOG:12)
Block(-6,30,0,LOG:12)
Block(-6,30,1,REDSTONE_TORCH_ON:3)
Block(-6,30,3,inspirations:rope:2)
Block(-6,30,5,VINE:2)
Block(-6,30,6,VINE:2)
Block(-6,30,7,VINE:3)
Block(-6,30,8,LOG:12)
Block(-6,31,-1,LOG:12)
Block(-6,31,0,LOG:12)
Block(-6,31,1,LOG:12)
Block(-6,31,2,LOG:12)
Block(-6,31,3,LOG:12)
Block(-6,31,4,LOG:12)
Block(-6,31,5,LOG:12)
Block(-6,31,6,LOG:12)
Block(-6,31,7,LOG:12)
Block(-6,31,8,LOG:12)
Block(-6,32,-7,WOOL:14)
Block(-6,32,-1,LOG:12)
Block(-6,32,0,LOG:12)
Block(-6,32,1,LOG:12)
Block(-6,32,2,LEAVES:12)
Block(-6,32,3,LEAVES:12)
Block(-6,32,6,LEAVES:12)
Block(-6,32,7,LOG:12)
Block(-6,32,8,LOG:12)
Block(-6,33,-7,WOOL:14)
Block(-6,33,-3,LOG:12)
Block(-6,33,-2,LOG:12)
Block(-6,33,-1,LOG:12)
Block(-6,33,0,LOG:12)
Block(-6,33,1,LOG:12)
Block(-6,33,7,LEAVES:12)
Block(-6,33,8,LOG:12)
Block(-6,34,-7,WOOL:14)
Block(-6,34,-4,LOG:12)
Block(-6,34,-3,LOG:12)
Block(-6,34,-2,LOG:12)
Block(-6,34,-1,LOG:12)
Block(-6,34,0,LOG:12)
Block(-6,34,1,LOG:12)
Block(-6,34,6,variedcommodities:beam:1)
Block(-6,34,7,LEAVES:12)
Block(-6,34,8,LOG:12)
Block(-6,35,-7,WOOL:14)
Block(-6,35,-3,LOG:12)
Block(-6,35,-2,LOG:12)
Block(-6,35,-1,LOG:12)
Block(-6,35,0,LOG:12)
Block(-6,35,1,LOG:12)
Block(-6,35,7,LEAVES:12)
Block(-6,35,8,LOG:12)
Block(-6,36,-7,WOOL:14)
Block(-6,36,-3,LEAVES:0)
Block(-6,36,-2,LOG:12)
Block(-6,36,-1,LOG:12)
Block(-6,36,0,LOG:12)
Block(-6,36,8,LOG:12)
Block(-6,37,-3,LEAVES:0)
Block(-6,37,-2,LOG:12)
Block(-6,37,-1,LOG:12)
Block(-6,37,0,LOG:12)
Block(-6,37,8,LOG:12)
Block(-6,38,-4,LEAVES:0)
Block(-6,38,-3,LEAVES:0)
Block(-6,38,-2,LOG:12)
Block(-6,38,-1,LOG:12)
Block(-6,38,0,LOG:12)
Block(-6,38,2,variedcommodities:beam:1)
Block(-6,38,7,WOOD_STAIRS:6)
Block(-6,38,8,LOG:12)
Block(-6,39,-2,LOG:12)
Block(-6,39,-1,LOG:12)
Block(-6,39,0,LOG:12)
Block(-6,39,5,WOOD_STAIRS:6)
Block(-6,39,6,WOOD_DOUBLE_STEP:0)
Block(-6,39,7,WOOD_STEP:0)
Block(-6,39,8,LOG:12)
Block(-6,40,-2,LOG:12)
Block(-6,40,-1,LOG:12)
Block(-6,40,0,LOG:12)
Block(-6,40,3,WOOD_STAIRS:6)
Block(-6,40,4,WOOD_DOUBLE_STEP:0)
Block(-6,40,5,WOOD_STEP:0)
Block(-6,40,6,LADDER:5)
Block(-6,40,8,LOG:12)
Block(-6,41,-2,LOG:12)
Block(-6,41,-1,LOG:12)
Block(-6,41,0,LOG:12)
Block(-6,41,1,WOOD_STAIRS:5)
Block(-6,41,2,WOOD_DOUBLE_STEP:0)
Block(-6,41,3,WOOD_STEP:0)
Block(-6,41,6,LADDER:5)
Block(-6,41,8,LOG:12)
Block(-6,42,-1,LOG:12)
Block(-6,42,0,LOG:12)
Block(-6,42,1,WOOD_STEP:0)
Block(-6,42,2,LOG:12)
Block(-6,42,5,WOOD_STEP:8)
Block(-6,42,6,LADDER:5)
Block(-6,42,8,LOG:12)
Block(-6,43,-2,LOG:12)
Block(-6,43,-1,LOG:12)
Block(-6,43,0,LOG:12)
Block(-6,43,1,LOG:12)
Block(-6,43,6,LADDER:5)
Block(-6,43,8,LOG:12)
Block(-6,44,-2,LOG:12)
Block(-6,44,-1,LOG:12)
Block(-6,44,0,LOG:12)
Block(-6,44,1,LOG:12)
Block(-6,44,6,REDSTONE_TORCH_ON:1)
Block(-6,44,8,LOG:12)
Block(-6,45,-2,LOG:12)
Block(-6,45,-1,LOG:12)
Block(-6,45,0,LOG:12)
Block(-6,45,2,LOG:12)
Block(-6,45,3,LEAVES:4)
Block(-6,45,4,LEAVES:4)
Block(-6,45,5,LEAVES:4)
Block(-6,45,6,LOG:12)
Block(-6,45,7,LOG:12)
Block(-6,45,8,LOG:12)
Block(-6,46,-2,LOG:12)
Block(-6,46,-1,LOG:12)
Block(-6,46,0,LOG:12)
Block(-6,46,1,LOG:12)
Block(-6,46,2,LOG:12)
Block(-6,46,3,LOG:12)
Block(-6,46,4,LOG:12)
Block(-6,46,5,LOG:12)
Block(-6,46,6,LOG:12)
Block(-6,46,7,LOG:12)
Block(-6,46,8,LOG:12)
Block(-6,47,-2,LOG:12)
Block(-6,47,-1,LOG:12)
Block(-6,47,0,LOG:12)
Block(-6,47,1,LEAVES:12)
Block(-6,47,2,RED_MUSHROOM:0)
Block(-6,47,3,quark:leaf_carpet)
Block(-6,47,5,LOG:12)
Block(-6,47,6,LOG:12)
Block(-6,47,8,LOG:12)
Block(-6,48,-2,LOG:12)
Block(-6,48,-1,LOG:12)
Block(-6,48,0,LOG:12)
Block(-6,48,1,VINE:2)
Block(-6,48,4,LOG:12)
Block(-6,48,5,LOG:12)
Block(-6,48,6,LOG:12)
Block(-6,48,7,LEAVES:0)
Block(-6,48,8,LOG:12)
Block(-6,49,-1,WOOD_STEP:8)
Block(-6,49,0,LOG:12)
Block(-6,49,1,VINE:2)
Block(-6,49,2,LOG:12)
Block(-6,49,3,LOG:12)
Block(-6,49,4,VINE:2)
Block(-6,49,5,LOG:12)
Block(-6,49,6,VINE:2)
Block(-6,49,8,LOG:12)
Block(-6,50,-7,WOOD_STEP:8)
Block(-6,50,-6,WOOD_STEP:8)
Block(-6,50,-2,WOOD_STEP:0)
Block(-6,50,0,LOG:12)
Block(-6,50,1,VINE:2)
Block(-6,50,4,VINE:2)
Block(-6,50,6,VINE:2)
Block(-6,50,8,LOG:12)
Block(-6,51,-7,FENCE:0)
Block(-6,51,-6,WOOD_DOUBLE_STEP:0)
Block(-6,51,-5,LOG:12)
Block(-6,51,0,LOG:12)
Block(-6,51,1,VINE:2)
Block(-6,51,4,VINE:2)
Block(-6,51,6,VINE:2)
Block(-6,51,8,LOG:12)
Block(-6,52,0,LOG:12)
Block(-6,52,1,VINE:2)
Block(-6,52,8,LOG:12)
Block(-6,53,-1,LEAVES:0)
Block(-6,53,0,LOG:12)
Block(-6,53,1,VINE:2)
Block(-6,53,8,LOG:12)
Block(-6,54,-7,LEAVES:0)
Block(-6,54,-6,LEAVES:0)
Block(-6,54,-5,LEAVES:0)
Block(-6,54,-4,LEAVES:0)
Block(-6,54,-3,LEAVES:0)
Block(-6,54,-2,LEAVES:0)
Block(-6,54,-1,LEAVES:0)
Block(-6,54,0,LOG:12)
Block(-6,54,4,VINE:2)
Block(-6,54,8,LOG:12)
Block(-6,55,-7,LEAVES:0)
Block(-6,55,-6,LEAVES:0)
Block(-6,55,-5,LEAVES:0)
Block(-6,55,-4,LEAVES:0)
Block(-6,55,-3,LEAVES:0)
Block(-6,55,-2,LEAVES:0)
Block(-6,55,-1,LEAVES:0)
Block(-6,55,0,LOG:12)
Block(-6,55,2,variedcommodities:beam:1)
Block(-6,55,4,VINE:2)
Block(-6,55,8,LOG:12)
Block(-6,56,-5,LEAVES:0)
Block(-6,56,0,LOG:12)
Block(-6,56,4,VINE:2)
Block(-6,56,8,LOG:12)
Block(-6,57,-5,LEAVES:0)
Block(-6,57,0,LOG:12)
Block(-6,57,4,VINE:2)
Block(-6,57,8,LOG:12)
Block(-6,58,0,LOG:12)
Block(-6,58,3,LEAVES:12)
Block(-6,58,4,VINE:2)
Block(-6,58,5,variedcommodities:beam:1)
Block(-6,58,7,LEAVES:4)
Block(-6,58,8,LOG:12)
Block(-6,59,0,LOG:12)
Block(-6,59,3,LEAVES:12)
Block(-6,59,4,VINE:6)
Block(-6,59,7,LEAVES:4)
Block(-6,59,8,LOG:12)
Block(-6,60,-3,LOG:12)
Block(-6,60,-2,LOG:12)
Block(-6,60,-1,LOG:12)
Block(-6,60,0,LOG:0)
Block(-6,60,2,LEAVES:12)
Block(-6,60,3,LEAVES:12)
Block(-6,60,4,VINE:6)
Block(-6,60,6,LEAVES:4)
Block(-6,60,7,LEAVES:4)
Block(-6,60,8,LOG:12)
Block(-6,61,-7,LOG:12)
Block(-6,61,-3,LOG:12)
Block(-6,61,-2,LOG:12)
Block(-6,61,-1,LOG:12)
Block(-6,61,0,LOG:12)
Block(-6,61,1,LEAVES:12)
Block(-6,61,2,LEAVES:12)
Block(-6,61,3,LEAVES:12)
Block(-6,61,4,VINE:4)
Block(-6,61,6,LEAVES:4)
Block(-6,61,7,LEAVES:4)
Block(-6,61,8,LOG:12)
Block(-6,62,0,LOG:12)
Block(-6,62,1,LOG:12)
Block(-6,62,2,LOG:12)
Block(-6,62,3,LOG:12)
Block(-6,62,4,LOG:12)
Block(-6,62,5,LOG:12)
Block(-6,62,6,LOG:12)
Block(-6,62,7,LOG:12)
Block(-6,62,8,LOG:12)
Block(-6,63,0,LOG:12)
Block(-6,63,1,LOG:0)
Block(-6,63,2,LEAVES:12)
Block(-6,63,3,LEAVES:12)
Block(-6,63,5,LOG:0)
Block(-6,63,6,LOG:8)
Block(-6,63,7,LOG:0)
Block(-6,63,8,LOG:12)
Block(-6,64,-6,LEAVES:0)
Block(-6,64,-5,LEAVES:0)
Block(-6,64,-4,LEAVES:0)
Block(-6,64,-3,LEAVES:0)
Block(-6,64,-2,LEAVES:0)
Block(-6,64,0,LOG:12)
Block(-6,64,1,LEAVES:12)
Block(-6,64,2,VINE:2)
Block(-6,64,5,LEAVES:12)
Block(-6,64,6,LOG:0)
Block(-6,64,7,LOG:8)
Block(-6,64,8,LOG:12)
Block(-6,65,-7,LEAVES:0)
Block(-6,65,-6,LEAVES:0)
Block(-6,65,-5,LEAVES:0)
Block(-6,65,-4,LEAVES:0)
Block(-6,65,-3,LEAVES:0)
Block(-6,65,-2,LEAVES:0)
Block(-6,65,0,LOG:12)
Block(-6,65,1,LEAVES:4)
Block(-6,65,2,VINE:2)
Block(-6,65,3,variedcommodities:beam:1)
Block(-6,65,6,LEAVES:12)
Block(-6,65,7,LOG:4)
Block(-6,65,8,LOG:12)
Block(-6,66,-7,LEAVES:0)
Block(-6,66,-6,LEAVES:0)
Block(-6,66,-5,LEAVES:0)
Block(-6,66,-4,LEAVES:0)
Block(-6,66,-3,LEAVES:0)
Block(-6,66,-1,LOG:12)
Block(-6,66,0,LOG:12)
Block(-6,66,2,VINE:2)
Block(-6,66,7,LOG:4)
Block(-6,66,8,LOG:12)
Block(-6,67,-7,LEAVES:0)
Block(-6,67,-6,LEAVES:0)
Block(-6,67,-5,LEAVES:0)
Block(-6,67,-4,LEAVES:0)
Block(-6,67,-3,LEAVES:0)
Block(-6,67,-1,LOG:12)
Block(-6,67,0,LOG:12)
Block(-6,67,2,VINE:2)
Block(-6,67,7,VINE:2)
Block(-6,67,8,LOG:12)
Block(-6,68,-7,LEAVES:0)
Block(-6,68,-6,LEAVES:0)
Block(-6,68,-5,LEAVES:0)
Block(-6,68,-4,LEAVES:0)
Block(-6,68,0,LOG:12)
Block(-6,68,2,VINE:2)
Block(-6,68,4,variedcommodities:beam:1)
Block(-6,68,7,VINE:2)
Block(-6,68,8,LOG:12)
Block(-6,69,-6,LEAVES:0)
Block(-6,69,-5,LEAVES:0)
Block(-6,69,-4,LEAVES:0)
Block(-6,69,0,LOG:12)
Block(-6,69,2,VINE:2)
Block(-6,69,7,VINE:2)
Block(-6,69,8,LOG:12)
Block(-6,70,-7,LEAVES:0)
Block(-6,70,0,LOG:12)
Block(-6,70,2,VINE:2)
Block(-6,70,5,LEAVES:12)
Block(-6,70,7,VINE:2)
Block(-6,70,8,LOG:12)
Block(-6,71,-7,LEAVES:0)
Block(-6,71,-6,LEAVES:0)
Block(-6,71,0,LOG:12)
Block(-6,71,2,VINE:2)
Block(-6,71,3,LEAVES:12)
Block(-6,71,7,VINE:2)
Block(-6,71,8,LOG:12)
Block(-6,72,-7,LEAVES:0)
Block(-6,72,-6,LEAVES:0)
Block(-6,72,-3,LOG:12)
Block(-6,72,-1,LOG:12)
Block(-6,72,0,LOG:12)
Block(-6,72,2,VINE:2)
Block(-6,72,3,LEAVES:12)
Block(-6,72,5,LEAVES:12)
Block(-6,72,6,LEAVES:12)
Block(-6,72,7,VINE:2)
Block(-6,72,8,LOG:12)
Block(-6,73,-7,LEAVES:0)
Block(-6,73,-6,LEAVES:0)
Block(-6,73,-5,LEAVES:0)
Block(-6,73,-4,LEAVES:0)
Block(-6,73,-3,LOG:12)
Block(-6,73,-2,LEAVES:0)
Block(-6,73,-1,LOG:12)
Block(-6,73,0,LOG:12)
Block(-6,73,1,LEAVES:0)
Block(-6,73,2,LEAVES:0)
Block(-6,73,3,LEAVES:0)
Block(-6,73,4,LEAVES:0)
Block(-6,73,5,LEAVES:0)
Block(-6,73,6,LEAVES:0)
Block(-6,73,7,LEAVES:0)
Block(-6,73,8,LOG:12)
Block(-6,74,-7,LEAVES:0)
Block(-6,74,-6,LEAVES:0)
Block(-6,74,-5,LEAVES:0)
Block(-6,74,-4,LEAVES:0)
Block(-6,74,-3,LOG:12)
Block(-6,74,-2,LEAVES:0)
Block(-6,74,-1,LOG:12)
Block(-6,74,0,LOG:12)
Block(-6,74,1,LEAVES:0)
Block(-6,74,2,LEAVES:0)
Block(-6,74,3,LEAVES:0)
Block(-6,74,4,LEAVES:0)
Block(-6,74,5,LEAVES:0)
Block(-6,74,6,LEAVES:0)
Block(-6,74,7,LEAVES:0)
Block(-6,74,8,LOG:12)
Block(-6,75,-7,LEAVES:0)
Block(-6,75,-6,LEAVES:0)
Block(-6,75,-5,LEAVES:0)
Block(-6,75,-4,LEAVES:0)
Block(-6,75,-3,LOG:12)
Block(-6,75,-2,LEAVES:0)
Block(-6,75,-1,LOG:12)
Block(-6,75,0,LOG:12)
Block(-6,75,1,LEAVES:0)
Block(-6,75,2,LEAVES:0)
Block(-6,75,3,LEAVES:0)
Block(-6,75,4,LEAVES:0)
Block(-6,75,5,LEAVES:0)
Block(-6,75,6,LEAVES:0)
Block(-6,75,7,LEAVES:0)
Block(-6,75,8,LOG:12)
Block(-6,76,-7,LEAVES:0)
Block(-6,76,-6,LEAVES:0)
Block(-6,76,-5,LEAVES:0)
Block(-6,76,-4,LEAVES:0)
Block(-6,76,-3,LEAVES:0)
Block(-6,76,-2,LEAVES:0)
Block(-6,76,-1,LEAVES:0)
Block(-6,76,0,LOG:12)
Block(-6,76,1,LEAVES:0)
Block(-6,76,2,LEAVES:0)
Block(-6,76,3,LEAVES:0)
Block(-6,76,4,LEAVES:0)
Block(-6,76,5,LEAVES:0)
Block(-6,76,6,LEAVES:0)
Block(-6,76,7,LEAVES:0)
Block(-6,76,8,LOG:12)
Block(-6,77,-7,LEAVES:0)
Block(-6,77,-6,LEAVES:0)
Block(-6,77,-5,LEAVES:0)
Block(-6,77,-4,LEAVES:0)
Block(-6,77,-3,LEAVES:0)
Block(-6,77,-2,LOG:12)
Block(-6,77,-1,LEAVES:0)
Block(-6,77,0,LOG:12)
Block(-6,77,1,LEAVES:0)
Block(-6,77,2,LEAVES:0)
Block(-6,77,3,LEAVES:0)
Block(-6,77,4,LEAVES:0)
Block(-6,77,5,LOG:12)
Block(-6,77,6,LEAVES:0)
Block(-6,77,7,LEAVES:0)
Block(-6,77,8,LOG:12)
Block(-6,78,-7,LEAVES:0)
Block(-6,78,-6,LEAVES:0)
Block(-6,78,-5,LEAVES:0)
Block(-6,78,-4,LEAVES:0)
Block(-6,78,-3,LEAVES:0)
Block(-6,78,-2,LEAVES:0)
Block(-6,78,-1,LEAVES:0)
Block(-6,78,0,LOG:12)
Block(-6,78,1,LEAVES:0)
Block(-6,78,2,LEAVES:0)
Block(-6,78,3,LEAVES:0)
Block(-6,78,4,LOG:12)
Block(-6,78,5,LOG:12)
Block(-6,78,6,LOG:12)
Block(-6,78,7,LEAVES:0)
Block(-6,78,8,LOG:12)
Block(-6,79,-6,LEAVES:0)
Block(-6,79,-5,LEAVES:0)
Block(-6,79,-4,LEAVES:0)
Block(-6,79,-3,LEAVES:0)
Block(-6,79,-2,LEAVES:0)
Block(-6,79,-1,LEAVES:0)
Block(-6,79,0,LEAVES:0)
Block(-6,79,1,LEAVES:0)
Block(-6,79,2,LEAVES:0)
Block(-6,79,3,LOG:12)
Block(-6,79,4,LOG:12)
Block(-6,79,5,LOG:12)
Block(-6,79,6,LEAVES:0)
Block(-6,79,7,LEAVES:0)
Block(-6,79,8,LEAVES:0)
Block(-6,80,-7,LEAVES:0)
Block(-6,80,-6,LEAVES:0)
Block(-6,80,-5,LEAVES:0)
Block(-6,80,-4,LEAVES:0)
Block(-6,80,-3,LEAVES:0)
Block(-6,80,-2,LEAVES:0)
Block(-6,80,-1,LEAVES:0)
Block(-6,80,0,LEAVES:0)
Block(-6,80,1,LEAVES:0)
Block(-6,80,2,LEAVES:0)
Block(-6,80,3,LEAVES:0)
Block(-6,80,4,LEAVES:0)
Block(-6,80,5,LEAVES:0)
Block(-6,80,6,LOG:12)
Block(-6,80,7,LEAVES:0)
Block(-6,80,8,LEAVES:0)
Block(-6,81,-7,LEAVES:0)
Block(-6,81,-6,LEAVES:0)
Block(-6,81,-5,LOG:12)
Block(-6,81,-4,LEAVES:0)
Block(-6,81,-2,LEAVES:0)
Block(-6,81,-1,LEAVES:0)
Block(-6,81,0,LEAVES:0)
Block(-6,81,1,LEAVES:0)
Block(-6,81,2,LEAVES:0)
Block(-6,81,3,LEAVES:0)
Block(-6,81,4,LEAVES:0)
Block(-6,81,5,LEAVES:0)
Block(-6,81,6,LEAVES:0)
Block(-6,81,7,LOG:12)
Block(-6,81,8,LEAVES:0)
Block(-6,82,-7,LEAVES:0)
Block(-6,82,-6,LEAVES:0)
Block(-6,82,-5,LEAVES:0)
Block(-6,82,-4,LEAVES:0)
Block(-6,82,-3,LEAVES:0)
Block(-6,82,1,LOG:12)
Block(-6,82,2,LEAVES:0)
Block(-6,82,3,LEAVES:0)
Block(-6,82,4,LEAVES:0)
Block(-6,82,5,LEAVES:0)
Block(-6,82,6,LEAVES:0)
Block(-6,82,7,LEAVES:0)
Block(-6,82,8,LEAVES:0)
Block(-6,83,-7,LEAVES:0)
Block(-6,83,-6,LEAVES:0)
Block(-6,83,-5,LEAVES:0)
Block(-6,83,-4,LEAVES:0)
Block(-6,83,-3,LEAVES:0)
Block(-6,83,-2,LEAVES:0)
Block(-6,83,-1,LEAVES:0)
Block(-6,83,0,LEAVES:0)
Block(-6,83,4,LEAVES:0)
Block(-6,83,5,LEAVES:0)
Block(-6,83,6,LEAVES:0)
Block(-6,83,7,LEAVES:0)
Block(-6,83,8,LEAVES:0)
Block(-6,84,-6,LEAVES:0)
Block(-6,84,-5,LEAVES:0)
Block(-6,84,-4,LEAVES:0)
Block(-6,84,-3,LEAVES:0)
Block(-6,84,-2,LEAVES:0)
Block(-6,84,-1,LEAVES:0)
Block(-6,84,0,LEAVES:0)
Block(-6,84,1,LEAVES:0)
Block(-6,84,2,LEAVES:0)
Block(-6,84,4,LEAVES:0)
Block(-6,84,5,LEAVES:0)
Block(-6,84,6,LEAVES:0)
Block(-6,84,7,LEAVES:0)
Block(-6,84,8,LEAVES:0)
Block(-6,85,-2,LEAVES:0)
Block(-6,85,-1,LEAVES:0)
Block(-6,85,0,LEAVES:0)
Block(-6,85,1,LEAVES:0)
Block(-6,85,2,LEAVES:0)
Block(-6,85,5,LEAVES:0)
Block(-6,85,6,LEAVES:0)
Block(-6,86,0,LEAVES:0)
Block(-6,86,3,LEAVES:0)
Block(-6,86,4,LEAVES:0)
Block(-6,86,5,LEAVES:0)
Block(-6,86,6,LEAVES:0)
Block(-6,86,7,LEAVES:0)
Block(-6,86,8,LEAVES:0)
Block(-6,87,0,inspirations:rope:1)
Block(-6,87,2,LEAVES:0)
Block(-6,87,3,LEAVES:0)
Block(-6,87,4,LEAVES:0)
Block(-6,87,5,LEAVES:0)
Block(-6,87,6,LEAVES:0)
Block(-6,87,7,LEAVES:0)
Block(-6,88,0,inspirations:rope:1)
Block(-6,88,3,LEAVES:0)
Block(-6,88,5,LEAVES:0)
Block(-6,88,6,LEAVES:0)
Block(-6,89,0,inspirations:rope:1)
Block(-6,90,0,inspirations:rope:1)
Block(-6,91,0,inspirations:rope:1)
Block(-6,92,0,inspirations:rope:1)
Block(-6,93,0,inspirations:rope:1)
Block(-6,94,0,inspirations:rope:1)
RandomBlock(-6,95,-2,quark:quilted_wool:0,10,quark:quilted_wool:0,100)
RandomBlock(-6,95,-1,quark:quilted_wool:0,10,quark:quilted_wool:0,100)
RandomBlock(-6,95,0,quark:quilted_wool:0,10,quark:quilted_wool:0,100)
RandomBlock(-6,95,1,quark:quilted_wool:0,10,quark:quilted_wool:0,100)
RandomBlock(-6,95,2,quark:quilted_wool:0,10,quark:quilted_wool:0,100)
RandomBlock(-6,96,-3,quark:quilted_wool:0,10,quark:quilted_wool:0,100)
RandomBlock(-6,96,-2,quark:quilted_wool:0,10,quark:quilted_wool:0,100)
RandomBlock(-6,96,-1,quark:quilted_wool:0,10,quark:quilted_wool:0,100)
RandomBlock(-6,96,0,quark:quilted_wool:0,10,quark:quilted_wool:0,100)
RandomBlock(-6,96,1,quark:quilted_wool:0,10,quark:quilted_wool:0,100)
RandomBlock(-6,96,2,quark:quilted_wool:0,10,quark:quilted_wool:0,100)
RandomBlock(-6,96,3,quark:quilted_wool:0,10,quark:quilted_wool:0,100)
RandomBlock(-6,97,-4,quark:quilted_wool:0,10,quark:quilted_wool:0,100)
RandomBlock(-6,97,-3,quark:quilted_wool:0,10,quark:quilted_wool:0,100)
RandomBlock(-6,97,-2,quark:quilted_wool:0,10,quark:quilted_wool:0,100)
RandomBlock(-6,97,-1,quark:quilted_wool:0,10,quark:quilted_wool:0,100)
RandomBlock(-6,97,0,quark:quilted_wool:0,10,quark:quilted_wool:0,100)
RandomBlock(-6,97,1,quark:quilted_wool:0,10,quark:quilted_wool:0,100)
RandomBlock(-6,97,2,quark:quilted_wool:0,10,quark:quilted_wool:0,100)
RandomBlock(-6,97,3,quark:quilted_wool:0,10,quark:quilted_wool:0,100)
RandomBlock(-6,97,4,quark:quilted_wool:0,10,quark:quilted_wool:0,100)
RandomBlock(-6,98,-5,quark:quilted_wool:0,10,quark:quilted_wool:0,100)
RandomBlock(-6,98,-4,quark:quilted_wool:0,10,quark:quilted_wool:0,100)
RandomBlock(-6,98,-3,quark:quilted_wool:0,10,quark:quilted_wool:0,100)
RandomBlock(-6,98,-2,quark:quilted_wool:0,10,quark:quilted_wool:0,100)
RandomBlock(-6,98,-1,quark:quilted_wool:0,10,quark:quilted_wool:0,100)
RandomBlock(-6,98,0,quark:quilted_wool:0,10,quark:quilted_wool:0,100)
RandomBlock(-6,98,1,quark:quilted_wool:0,10,quark:quilted_wool:0,100)
RandomBlock(-6,98,2,quark:quilted_wool:0,10,quark:quilted_wool:0,100)
RandomBlock(-6,98,3,quark:quilted_wool:0,10,quark:quilted_wool:0,100)
RandomBlock(-6,98,4,quark:quilted_wool:0,10,quark:quilted_wool:0,100)
RandomBlock(-6,98,5,quark:quilted_wool:0,10,quark:quilted_wool:0,100)
RandomBlock(-6,99,-5,quark:quilted_wool:0,10,quark:quilted_wool:0,100)
RandomBlock(-6,99,-4,quark:quilted_wool:0,10,quark:quilted_wool:0,100)
RandomBlock(-6,99,-3,quark:quilted_wool:0,10,quark:quilted_wool:0,100)
RandomBlock(-6,99,-2,quark:quilted_wool:0,10,quark:quilted_wool:0,100)
RandomBlock(-6,99,-1,quark:quilted_wool:0,10,quark:quilted_wool:0,100)
RandomBlock(-6,99,0,quark:quilted_wool:0,10,quark:quilted_wool:0,100)
RandomBlock(-6,99,1,quark:quilted_wool:0,10,quark:quilted_wool:0,100)
RandomBlock(-6,99,2,quark:quilted_wool:0,10,quark:quilted_wool:0,100)
RandomBlock(-6,99,3,quark:quilted_wool:0,10,quark:quilted_wool:0,100)
RandomBlock(-6,99,4,quark:quilted_wool:0,10,quark:quilted_wool:0,100)
RandomBlock(-6,99,5,quark:quilted_wool:0,10,quark:quilted_wool:0,100)
RandomBlock(-6,100,-6,quark:quilted_wool:0,10,quark:quilted_wool:0,100)
RandomBlock(-6,100,-5,quark:quilted_wool:0,10,quark:quilted_wool:0,100)
RandomBlock(-6,100,-4,quark:quilted_wool:0,10,quark:quilted_wool:0,100)
RandomBlock(-6,100,-3,quark:quilted_wool:0,10,quark:quilted_wool:0,100)
RandomBlock(-6,100,-2,quark:quilted_wool:0,10,quark:quilted_wool:0,100)
RandomBlock(-6,100,-1,quark:quilted_wool:0,10,quark:quilted_wool:0,100)
RandomBlock(-6,100,0,quark:quilted_wool:0,10,quark:quilted_wool:0,100)
RandomBlock(-6,100,1,quark:quilted_wool:0,10,quark:quilted_wool:0,100)
RandomBlock(-6,100,2,quark:quilted_wool:0,10,quark:quilted_wool:0,100)
RandomBlock(-6,100,3,quark:quilted_wool:0,10,quark:quilted_wool:0,100)
RandomBlock(-6,100,4,quark:quilted_wool:0,10,quark:quilted_wool:0,100)
RandomBlock(-6,100,5,quark:quilted_wool:0,10,quark:quilted_wool:0,100)
RandomBlock(-6,100,6,quark:quilted_wool:0,10,quark:quilted_wool:0,100)
RandomBlock(-6,101,-6,quark:quilted_wool:0,10,quark:quilted_wool:0,100)
RandomBlock(-6,101,-5,quark:quilted_wool:0,10,quark:quilted_wool:0,100)
RandomBlock(-6,101,-4,quark:quilted_wool:0,10,quark:quilted_wool:0,100)
RandomBlock(-6,101,-3,quark:quilted_wool:0,10,quark:quilted_wool:0,100)
RandomBlock(-6,101,-2,quark:quilted_wool:0,10,quark:quilted_wool:0,100)
RandomBlock(-6,101,-1,quark:quilted_wool:0,10,quark:quilted_wool:0,100)
RandomBlock(-6,101,0,quark:quilted_wool:0,10,quark:quilted_wool:0,100)
RandomBlock(-6,101,1,quark:quilted_wool:0,10,quark:quilted_wool:0,100)
RandomBlock(-6,101,2,quark:quilted_wool:0,10,quark:quilted_wool:0,100)
RandomBlock(-6,101,3,quark:quilted_wool:0,10,quark:quilted_wool:0,100)
RandomBlock(-6,101,4,quark:quilted_wool:0,10,quark:quilted_wool:0,100)
RandomBlock(-6,101,5,quark:quilted_wool:0,10,quark:quilted_wool:0,100)
RandomBlock(-6,101,6,quark:quilted_wool:0,10,quark:quilted_wool:0,100)
RandomBlock(-6,102,-6,quark:quilted_wool:0,10,quark:quilted_wool:0,100)
RandomBlock(-6,102,-5,quark:quilted_wool:0,10,quark:quilted_wool:0,100)
RandomBlock(-6,102,-4,quark:quilted_wool:0,10,quark:quilted_wool:0,100)
RandomBlock(-6,102,-3,quark:quilted_wool:0,10,quark:quilted_wool:0,100)
RandomBlock(-6,102,-2,quark:quilted_wool:0,10,quark:quilted_wool:0,100)
RandomBlock(-6,102,-1,quark:quilted_wool:0,10,quark:quilted_wool:0,100)
RandomBlock(-6,102,0,quark:quilted_wool:0,10,quark:quilted_wool:0,100)
RandomBlock(-6,102,1,quark:quilted_wool:0,10,quark:quilted_wool:0,100)
RandomBlock(-6,102,2,quark:quilted_wool:0,10,quark:quilted_wool:0,100)
RandomBlock(-6,102,3,quark:quilted_wool:0,10,quark:quilted_wool:0,100)
RandomBlock(-6,102,4,quark:quilted_wool:0,10,quark:quilted_wool:0,100)
RandomBlock(-6,102,5,quark:quilted_wool:0,10,quark:quilted_wool:0,100)
RandomBlock(-6,102,6,quark:quilted_wool:0,10,quark:quilted_wool:0,100)
RandomBlock(-6,103,-6,quark:quilted_wool:0,10,quark:quilted_wool:0,100)
RandomBlock(-6,103,-5,quark:quilted_wool:0,10,quark:quilted_wool:0,100)
RandomBlock(-6,103,-4,quark:quilted_wool:0,10,quark:quilted_wool:0,100)
RandomBlock(-6,103,-3,quark:quilted_wool:0,10,quark:quilted_wool:0,100)
RandomBlock(-6,103,-2,quark:quilted_wool:0,10,quark:quilted_wool:0,100)
RandomBlock(-6,103,-1,quark:quilted_wool:0,10,quark:quilted_wool:0,100)
RandomBlock(-6,103,0,quark:quilted_wool:0,10,quark:quilted_wool:0,100)
RandomBlock(-6,103,1,quark:quilted_wool:0,10,quark:quilted_wool:0,100)
RandomBlock(-6,103,2,quark:quilted_wool:0,10,quark:quilted_wool:0,100)
RandomBlock(-6,103,3,quark:quilted_wool:0,10,quark:quilted_wool:0,100)
RandomBlock(-6,103,4,quark:quilted_wool:0,10,quark:quilted_wool:0,100)
RandomBlock(-6,103,5,quark:quilted_wool:0,10,quark:quilted_wool:0,100)
RandomBlock(-6,103,6,quark:quilted_wool:0,10,quark:quilted_wool:0,100)
RandomBlock(-6,104,-6,quark:quilted_wool:0,10,quark:quilted_wool:0,100)
RandomBlock(-6,104,-5,quark:quilted_wool:0,10,quark:quilted_wool:0,100)
RandomBlock(-6,104,-4,quark:quilted_wool:0,10,quark:quilted_wool:0,100)
RandomBlock(-6,104,-3,quark:quilted_wool:0,10,quark:quilted_wool:0,100)
RandomBlock(-6,104,-2,quark:quilted_wool:0,10,quark:quilted_wool:0,100)
RandomBlock(-6,104,-1,quark:quilted_wool:0,10,quark:quilted_wool:0,100)
RandomBlock(-6,104,0,quark:quilted_wool:0,10,quark:quilted_wool:0,100)
RandomBlock(-6,104,1,quark:quilted_wool:0,10,quark:quilted_wool:0,100)
RandomBlock(-6,104,2,quark:quilted_wool:0,10,quark:quilted_wool:0,100)
RandomBlock(-6,104,3,quark:quilted_wool:0,10,quark:quilted_wool:0,100)
RandomBlock(-6,104,4,quark:quilted_wool:0,10,quark:quilted_wool:0,100)
RandomBlock(-6,104,5,quark:quilted_wool:0,10,quark:quilted_wool:0,100)
RandomBlock(-6,104,6,quark:quilted_wool:0,10,quark:quilted_wool:0,100)
RandomBlock(-6,105,-5,quark:quilted_wool:0,10,quark:quilted_wool:0,100)
RandomBlock(-6,105,-4,quark:quilted_wool:0,10,quark:quilted_wool:0,100)
RandomBlock(-6,105,-3,quark:quilted_wool:0,10,quark:quilted_wool:0,100)
RandomBlock(-6,105,-2,quark:quilted_wool:0,10,quark:quilted_wool:0,100)
RandomBlock(-6,105,-1,quark:quilted_wool:0,10,quark:quilted_wool:0,100)
RandomBlock(-6,105,0,quark:quilted_wool:0,10,quark:quilted_wool:0,100)
RandomBlock(-6,105,1,quark:quilted_wool:0,10,quark:quilted_wool:0,100)
RandomBlock(-6,105,2,quark:quilted_wool:0,10,quark:quilted_wool:0,100)
RandomBlock(-6,105,3,quark:quilted_wool:0,10,quark:quilted_wool:0,100)
RandomBlock(-6,105,4,quark:quilted_wool:0,10,quark:quilted_wool:0,100)
RandomBlock(-6,105,5,quark:quilted_wool:0,10,quark:quilted_wool:0,100)
RandomBlock(-6,106,-5,quark:quilted_wool:0,10,quark:quilted_wool:0,100)
RandomBlock(-6,106,-4,quark:quilted_wool:0,10,quark:quilted_wool:0,100)
RandomBlock(-6,106,-3,quark:quilted_wool:0,10,quark:quilted_wool:0,100)
RandomBlock(-6,106,-2,quark:quilted_wool:0,10,quark:quilted_wool:0,100)
RandomBlock(-6,106,-1,quark:quilted_wool:0,10,quark:quilted_wool:0,100)
RandomBlock(-6,106,0,quark:quilted_wool:0,10,quark:quilted_wool:0,100)
RandomBlock(-6,106,1,quark:quilted_wool:0,10,quark:quilted_wool:0,100)
RandomBlock(-6,106,2,quark:quilted_wool:0,10,quark:quilted_wool:0,100)
RandomBlock(-6,106,3,quark:quilted_wool:0,10,quark:quilted_wool:0,100)
RandomBlock(-6,106,4,quark:quilted_wool:0,10,quark:quilted_wool:0,100)
RandomBlock(-6,106,5,quark:quilted_wool:0,10,quark:quilted_wool:0,100)
RandomBlock(-6,107,-4,quark:quilted_wool:0,10,quark:quilted_wool:0,100)
RandomBlock(-6,107,-3,quark:quilted_wool:0,10,quark:quilted_wool:0,100)
RandomBlock(-6,107,-2,quark:quilted_wool:0,10,quark:quilted_wool:0,100)
RandomBlock(-6,107,-1,quark:quilted_wool:0,10,quark:quilted_wool:0,100)
RandomBlock(-6,107,0,quark:quilted_wool:0,10,quark:quilted_wool:0,100)
RandomBlock(-6,107,1,quark:quilted_wool:0,10,quark:quilted_wool:0,100)
RandomBlock(-6,107,2,quark:quilted_wool:0,10,quark:quilted_wool:0,100)
RandomBlock(-6,107,3,quark:quilted_wool:0,10,quark:quilted_wool:0,100)
RandomBlock(-6,107,4,quark:quilted_wool:0,10,quark:quilted_wool:0,100)
RandomBlock(-6,108,-3,quark:quilted_wool:0,10,quark:quilted_wool:0,100)
RandomBlock(-6,108,-2,quark:quilted_wool:0,10,quark:quilted_wool:0,100)
RandomBlock(-6,108,-1,quark:quilted_wool:0,10,quark:quilted_wool:0,100)
RandomBlock(-6,108,0,quark:quilted_wool:0,10,quark:quilted_wool:0,100)
RandomBlock(-6,108,1,quark:quilted_wool:0,10,quark:quilted_wool:0,100)
RandomBlock(-6,108,2,quark:quilted_wool:0,10,quark:quilted_wool:0,100)
RandomBlock(-6,108,3,quark:quilted_wool:0,10,quark:quilted_wool:0,100)
RandomBlock(-6,109,-2,quark:quilted_wool:0,10,quark:quilted_wool:0,100)
RandomBlock(-6,109,-1,quark:quilted_wool:0,10,quark:quilted_wool:0,100)
RandomBlock(-6,109,0,quark:quilted_wool:0,10,quark:quilted_wool:0,100)
RandomBlock(-6,109,1,quark:quilted_wool:0,10,quark:quilted_wool:0,100)
RandomBlock(-6,109,2,quark:quilted_wool:0,10,quark:quilted_wool:0,100)
Block(-5,6,-2,LOG:12)
Block(-5,7,-2,LOG:12)
Block(-5,8,-2,LOG:12)
Block(-5,9,-3,LOG:12)
Block(-5,9,-2,LOG:12)
Block(-5,9,-1,LOG:12)
Block(-5,10,-3,LOG:12)
Block(-5,10,-2,LOG:12)
Block(-5,10,-1,LOG:12)
Block(-5,11,-2,LOG:12)
Block(-5,12,-2,quark:leaf_carpet)
Block(-5,13,8,LOG:12)
Block(-5,14,7,LOG:12)
Block(-5,14,8,LOG:12)
Block(-5,15,5,LOG:12)
Block(-5,15,6,LOG:12)
Block(-5,15,7,LOG:12)
Block(-5,15,8,LOG:12)
Block(-5,16,5,LOG:12)
Block(-5,16,6,LOG:12)
Block(-5,16,7,LOG:12)
Block(-5,16,8,LOG:12)
Block(-5,17,-2,LOG:12)
Block(-5,17,2,LEAVES:0)
Block(-5,17,3,LEAVES:0)
Block(-5,17,4,LEAVES:0)
Block(-5,17,5,LOG:12)
Block(-5,17,6,LOG:12)
Block(-5,17,7,LOG:12)
Block(-5,17,8,LOG:12)
Block(-5,18,-3,LOG:12)
Block(-5,18,-2,LOG:12)
Block(-5,18,-1,LOG:12)
Block(-5,18,0,LEAVES:0)
Block(-5,18,1,LEAVES:0)
Block(-5,18,2,LEAVES:0)
Block(-5,18,3,LEAVES:0)
Block(-5,18,4,LOG:12)
Block(-5,18,5,LOG:12)
Block(-5,18,6,LOG:12)
Block(-5,18,7,LOG:12)
Block(-5,18,8,LEAVES:0)
Block(-5,19,-2,LOG:12)
Block(-5,19,-1,LOG:12)
Block(-5,19,0,LOG:12)
Block(-5,19,1,LOG:12)
Block(-5,19,2,LOG:12)
Block(-5,19,3,LOG:12)
Block(-5,19,4,LOG:12)
Block(-5,19,5,LOG:12)
Block(-5,19,6,LOG:12)
Block(-5,19,7,LOG:12)
Block(-5,20,-3,LOG:12)
Block(-5,20,-1,LOG:12)
Block(-5,20,0,LOG:12)
Block(-5,20,1,LOG:12)
Block(-5,20,2,LOG:12)
Block(-5,20,3,LOG:12)
Block(-5,20,4,LOG:12)
Block(-5,20,5,LOG:12)
Block(-5,20,6,LOG:12)
Block(-5,20,7,LOG:12)
Block(-5,20,8,LOG:12)
Block(-5,21,-4,LOG:12)
Block(-5,21,-3,LOG:12)
Block(-5,21,-2,LOG:12)
Block(-5,21,-1,LOG:12)
Block(-5,21,0,LOG:12)
Block(-5,21,5,LEAVES:4)
Block(-5,21,6,LEAVES:4)
Block(-5,21,7,LOG:12)
Block(-5,21,8,LEAVES:4)
Block(-5,22,-3,LOG:12)
Block(-5,22,-1,LOG:12)
Block(-5,22,5,LEAVES:4)
Block(-5,22,8,VINE:2)
Block(-5,23,-2,LEAVES:0)
Block(-5,23,-1,LOG:12)
Block(-5,23,4,LOG:12)
Block(-5,23,5,LEAVES:4)
Block(-5,23,8,VINE:2)
Block(-5,24,-5,LEAVES:0)
Block(-5,24,-3,LEAVES:0)
Block(-5,24,-2,LEAVES:0)
Block(-5,24,-1,LOG:12)
Block(-5,24,0,LOG:12)
Block(-5,24,1,LOG:12)
Block(-5,24,2,LOG:12)
Block(-5,24,3,LOG:12)
Block(-5,24,4,LOG:12)
Block(-5,24,5,LOG:12)
Block(-5,24,6,LOG:12)
Block(-5,24,7,LOG:12)
Block(-5,24,8,LOG:12)
Block(-5,25,-6,LEAVES:0)
Block(-5,25,-5,LEAVES:0)
Block(-5,25,-4,LEAVES:0)
Block(-5,25,-3,LEAVES:0)
Block(-5,25,-2,LEAVES:0)
Block(-5,25,-1,LOG:12)
Block(-5,25,0,LEAVES:4)
Block(-5,25,1,LEAVES:4)
Block(-5,25,2,LEAVES:4)
Block(-5,25,7,LEAVES:4)
Block(-5,25,8,LOG:12)
Block(-5,26,-5,LEAVES:0)
Block(-5,26,-2,LEAVES:0)
Block(-5,26,-1,LOG:12)
Block(-5,26,0,LEAVES:4)
Block(-5,26,8,VINE:2)
Block(-5,27,-1,LOG:12)
Block(-5,27,0,WOOD_STAIRS:5)
Block(-5,27,1,WOOD_STAIRS:5)
Block(-5,27,2,WOOD_STAIRS:7)
Block(-5,27,4,LOG:12)
Block(-5,27,7,VINE:1)
Block(-5,27,8,VINE:2)
Block(-5,28,-1,LOG:12)
Block(-5,28,7,VINE:1)
Block(-5,28,8,VINE:2)
Block(-5,29,-2,LOG:12)
Block(-5,29,-1,LOG:12)
Block(-5,29,7,VINE:1)
Block(-5,29,8,VINE:2)
Block(-5,30,-2,LOG:12)
Block(-5,30,-1,LOG:12)
Block(-5,30,0,LOG:12)
Block(-5,30,7,VINE:1)
Block(-5,30,8,LOG:12)
Block(-5,31,-2,LOG:12)
Block(-5,31,-1,LOG:12)
Block(-5,31,0,LOG:12)
Block(-5,31,1,LOG:12)
Block(-5,31,2,LOG:12)
Block(-5,31,3,LOG:12)
Block(-5,31,4,LOG:12)
Block(-5,31,5,LOG:12)
Block(-5,31,6,LOG:12)
Block(-5,31,7,LOG:12)
Block(-5,31,8,LOG:12)
Block(-5,32,-7,WOOL:14)
Block(-5,32,-3,LOG:12)
Block(-5,32,-2,LOG:12)
Block(-5,32,-1,LOG:12)
Block(-5,32,0,LOG:12)
Block(-5,32,1,LOG:12)
Block(-5,32,2,LEAVES:12)
Block(-5,32,4,RED_MUSHROOM:0)
Block(-5,32,7,LEAVES:12)
Block(-5,33,-7,WOOL:14)
Block(-5,33,-4,LOG:12)
Block(-5,33,-3,LOG:12)
Block(-5,33,-2,LOG:12)
Block(-5,33,-1,LOG:12)
Block(-5,33,0,LOG:12)
Block(-5,33,2,LEAVES:12)
Block(-5,34,-7,WOOL:14)
Block(-5,34,-4,LOG:12)
Block(-5,34,-3,LOG:12)
Block(-5,34,-2,LOG:12)
Block(-5,34,-1,LOG:12)
Block(-5,34,0,LOG:12)
Block(-5,34,1,LOG:12)
Block(-5,35,-7,WOOL:14)
Block(-5,35,-4,LOG:12)
Block(-5,35,-3,LOG:12)
Block(-5,35,-2,LOG:12)
Block(-5,35,-1,LOG:12)
Block(-5,35,0,LOG:12)
Block(-5,36,-7,WOOL:14)
Block(-5,36,-3,LOG:12)
Block(-5,36,-2,LOG:12)
Block(-5,36,-1,LOG:12)
Block(-5,36,0,LOG:12)
Block(-5,37,-4,LEAVES:0)
Block(-5,37,-3,LOG:12)
Block(-5,37,-2,LOG:12)
Block(-5,37,-1,LOG:12)
Block(-5,37,0,LOG:12)
Block(-5,38,-5,LEAVES:0)
Block(-5,38,-4,LEAVES:0)
Block(-5,38,-3,LEAVES:0)
Block(-5,38,-2,LOG:12)
Block(-5,38,-1,LOG:12)
Block(-5,38,0,LOG:12)
Block(-5,38,7,WOOD_STEP:8)
Block(-5,38,8,WOOD_STAIRS:6)
Block(-5,39,-4,LEAVES:0)
Block(-5,39,-3,LEAVES:0)
Block(-5,39,-2,LOG:12)
Block(-5,39,-1,LOG:12)
Block(-5,39,0,LOG:12)
Block(-5,39,7,WOOD_STEP:0)
Block(-5,39,8,WOOD_STEP:0)
Block(-5,40,-2,LOG:12)
Block(-5,40,-1,LOG:12)
Block(-5,40,0,LOG:12)
Block(-5,40,4,WOOD_STEP:8)
Block(-5,40,5,WOOD_STEP:0)
Block(-5,41,-1,LOG:12)
Block(-5,41,1,WOOD_STEP:8)
Block(-5,41,2,WOOD_STEP:8)
Block(-5,41,3,WOOD_STEP:0)
Block(-5,41,8,LEAVES:0)
Block(-5,42,-1,LOG:12)
Block(-5,42,0,WOOD_DOUBLE_STEP:0)
Block(-5,42,1,WOOD_STEP:0)
Block(-5,43,-1,LOG:12)
Block(-5,43,8,LOG:12)
Block(-5,44,-2,LOG:12)
Block(-5,44,-1,LOG:12)
Block(-5,44,8,LOG:12)
Block(-5,45,-2,LOG:12)
Block(-5,45,-1,LOG:12)
Block(-5,45,0,LOG:12)
Block(-5,45,1,LOG:12)
Block(-5,45,4,LEAVES:12)
Block(-5,45,6,LEAVES:4)
Block(-5,45,7,LOG:12)
Block(-5,45,8,LOG:12)
Block(-5,46,-1,LOG:12)
Block(-5,46,0,LOG:12)
Block(-5,46,1,LOG:12)
Block(-5,46,2,LOG:12)
Block(-5,46,3,LOG:12)
Block(-5,46,4,LOG:12)
Block(-5,46,5,LOG:12)
Block(-5,46,6,LOG:12)
Block(-5,46,7,LOG:12)
Block(-5,46,8,LOG:12)
Block(-5,47,-2,LOG:12)
Block(-5,47,-1,LOG:12)
Block(-5,47,1,LEAVES:4)
Block(-5,47,3,quark:leaf_carpet)
Block(-5,47,4,RED_MUSHROOM:0)
Block(-5,47,8,BROWN_MUSHROOM:0)
Block(-5,48,-2,LOG:12)
Block(-5,48,-1,LOG:12)
Block(-5,48,0,LEAVES:12)
Block(-5,48,1,LEAVES:4)
Block(-5,48,8,VINE:3)
Block(-5,49,-1,LOG:12)
Block(-5,49,0,LEAVES:12)
Block(-5,49,8,VINE:3)
Block(-5,50,-7,WOOD_STEP:8)
Block(-5,50,-6,WOOD_STEP:8)
Block(-5,50,-2,WOOD_STEP:8)
Block(-5,50,-1,LOG:12)
Block(-5,50,0,LOG:12)
Block(-5,50,8,VINE:3)
Block(-5,51,-6,WOOD_STEP:0)
Block(-5,51,-5,LOG:12)
Block(-5,51,-4,LOG:12)
Block(-5,51,-3,WOOD_STEP:0)
Block(-5,51,-1,LOG:12)
Block(-5,51,0,VINE:4)
Block(-5,51,8,VINE:3)
Block(-5,52,-1,LOG:12)
Block(-5,52,0,VINE:4)
Block(-5,52,8,VINE:1)
Block(-5,53,-1,LOG:12)
Block(-5,53,0,VINE:4)
Block(-5,53,8,VINE:1)
Block(-5,54,-7,LEAVES:0)
Block(-5,54,-6,LEAVES:0)
Block(-5,54,-5,LEAVES:0)
Block(-5,54,-4,LEAVES:0)
Block(-5,54,-1,LOG:12)
Block(-5,54,0,VINE:4)
Block(-5,54,8,VINE:3)
Block(-5,55,-7,LEAVES:0)
Block(-5,55,-6,LEAVES:0)
Block(-5,55,-5,LEAVES:0)
Block(-5,55,-4,LEAVES:0)
Block(-5,55,-3,LEAVES:0)
Block(-5,55,-1,LOG:12)
Block(-5,55,0,VINE:4)
Block(-5,55,8,VINE:3)
Block(-5,56,-7,LEAVES:0)
Block(-5,56,-6,LEAVES:0)
Block(-5,56,-5,LEAVES:0)
Block(-5,56,-4,LEAVES:0)
Block(-5,56,-3,LEAVES:0)
Block(-5,56,-1,LOG:12)
Block(-5,56,0,VINE:4)
Block(-5,56,8,VINE:3)
Block(-5,57,-1,LOG:12)
Block(-5,57,0,VINE:4)
Block(-5,57,1,LEAVES:4)
Block(-5,57,8,VINE:3)
Block(-5,58,-1,LOG:12)
Block(-5,58,1,LEAVES:4)
Block(-5,58,8,VINE:3)
Block(-5,59,-1,LOG:12)
Block(-5,59,0,LEAVES:4)
Block(-5,59,1,LEAVES:4)
Block(-5,59,8,VINE:3)
Block(-5,60,-3,LOG:12)
Block(-5,60,-2,LOG:12)
Block(-5,60,-1,LOG:12)
Block(-5,60,0,LEAVES:12)
Block(-5,60,1,LEAVES:12)
Block(-5,61,-3,LOG:12)
Block(-5,61,-2,LOG:12)
Block(-5,61,-1,LOG:12)
Block(-5,61,0,LEAVES:12)
Block(-5,61,1,LEAVES:12)
Block(-5,61,3,LEAVES:12)
Block(-5,61,5,LEAVES:4)
Block(-5,61,6,LEAVES:4)
Block(-5,61,7,LEAVES:4)
Block(-5,61,8,LEAVES:4)
Block(-5,62,-1,LOG:12)
Block(-5,62,0,LOG:12)
Block(-5,62,1,LOG:12)
Block(-5,62,2,LOG:12)
Block(-5,62,3,LOG:12)
Block(-5,62,4,LOG:12)
Block(-5,62,5,LOG:12)
Block(-5,62,6,LOG:12)
Block(-5,62,7,LOG:12)
Block(-5,62,8,LOG:12)
Block(-5,63,-1,LOG:12)
Block(-5,63,0,LOG:0)
Block(-5,63,1,LEAVES:12)
Block(-5,63,2,LEAVES:12)
Block(-5,63,5,LEAVES:12)
Block(-5,63,6,LOG:8)
Block(-5,63,7,LOG:0)
Block(-5,63,8,LOG:12)
Block(-5,64,-5,LEAVES:0)
Block(-5,64,-4,LEAVES:0)
Block(-5,64,-3,LEAVES:0)
Block(-5,64,-1,LOG:12)
Block(-5,64,0,LOG:8)
Block(-5,64,1,LEAVES:12)
Block(-5,64,5,LEAVES:4)
Block(-5,64,7,LOG:0)
Block(-5,64,8,LOG:12)
Block(-5,65,-7,LEAVES:0)
Block(-5,65,-6,LEAVES:0)
Block(-5,65,-5,LEAVES:0)
Block(-5,65,-4,LEAVES:0)
Block(-5,65,-3,LEAVES:0)
Block(-5,65,-2,LEAVES:0)
Block(-5,65,-1,LOG:12)
Block(-5,65,1,LEAVES:4)
Block(-5,65,6,LEAVES:12)
Block(-5,65,7,LEAVES:4)
Block(-5,65,8,LOG:12)
Block(-5,66,-7,LEAVES:0)
Block(-5,66,-6,LEAVES:0)
Block(-5,66,-5,LEAVES:0)
Block(-5,66,-4,LEAVES:0)
Block(-5,66,-3,LEAVES:0)
Block(-5,66,-1,LOG:12)
Block(-5,66,0,LEAVES:4)
Block(-5,66,8,LOG:12)
Block(-5,67,-7,LEAVES:0)
Block(-5,67,-6,LEAVES:0)
Block(-5,67,-5,LEAVES:0)
Block(-5,67,-4,LEAVES:0)
Block(-5,67,-1,LOG:12)
Block(-5,67,0,VINE:4)
Block(-5,67,5,inspirations:rope:2)
Block(-5,67,8,LOG:12)
Block(-5,68,-1,LOG:12)
Block(-5,68,0,VINE:4)
Block(-5,68,5,inspirations:rope:2)
Block(-5,68,8,LOG:12)
Block(-5,69,-1,LOG:12)
Block(-5,69,0,VINE:4)
Block(-5,69,5,inspirations:rope:2)
Block(-5,69,8,LOG:12)
Block(-5,70,-7,LEAVES:0)
Block(-5,70,-6,LEAVES:0)
Block(-5,70,-1,LOG:12)
Block(-5,70,0,VINE:4)
Block(-5,70,5,inspirations:rope:2)
Block(-5,70,8,LOG:12)
Block(-5,71,-7,LEAVES:0)
Block(-5,71,-6,LEAVES:0)
Block(-5,71,-1,LOG:12)
Block(-5,71,0,VINE:4)
Block(-5,71,5,inspirations:rope:2)
Block(-5,71,8,LOG:12)
Block(-5,72,-7,LEAVES:0)
Block(-5,72,-4,LOG:12)
Block(-5,72,-2,LOG:12)
Block(-5,72,-1,LOG:12)
Block(-5,72,0,VINE:4)
Block(-5,72,1,LEAVES:12)
Block(-5,72,3,LEAVES:12)
Block(-5,72,5,LEAVES:12)
Block(-5,72,7,LEAVES:12)
Block(-5,72,8,LOG:12)
Block(-5,73,-7,LEAVES:0)
Block(-5,73,-6,LEAVES:0)
Block(-5,73,-5,LEAVES:0)
Block(-5,73,-4,LOG:12)
Block(-5,73,-3,LEAVES:0)
Block(-5,73,-2,LOG:12)
Block(-5,73,-1,LOG:12)
Block(-5,73,0,LEAVES:0)
Block(-5,73,1,LEAVES:0)
Block(-5,73,3,LEAVES:12)
Block(-5,73,7,LEAVES:0)
Block(-5,73,8,LEAVES:0)
Block(-5,74,-7,LEAVES:0)
Block(-5,74,-6,LEAVES:0)
Block(-5,74,-5,LEAVES:0)
Block(-5,74,-4,LOG:12)
Block(-5,74,-3,LEAVES:0)
Block(-5,74,-2,LOG:12)
Block(-5,74,-1,LOG:12)
Block(-5,74,0,LEAVES:0)
Block(-5,74,1,LEAVES:0)
Block(-5,74,7,LEAVES:0)
Block(-5,74,8,LEAVES:0)
Block(-5,75,-7,LEAVES:0)
Block(-5,75,-6,LEAVES:0)
Block(-5,75,-5,LEAVES:0)
Block(-5,75,-4,LOG:12)
Block(-5,75,-3,LEAVES:0)
Block(-5,75,-2,LOG:12)
Block(-5,75,-1,LOG:12)
Block(-5,75,0,LEAVES:0)
Block(-5,75,1,LEAVES:0)
Block(-5,75,2,LEAVES:0)
Block(-5,75,3,LEAVES:0)
Block(-5,75,4,LEAVES:0)
Block(-5,75,5,LEAVES:0)
Block(-5,75,6,LEAVES:0)
Block(-5,75,7,LEAVES:0)
