
#######################################################################
# +-----------------------------------------------------------------+ #
# |                            BO3 object                           | #
# +-----------------------------------------------------------------+ #
#######################################################################

Author: NLBlackHeavenNL

Description: No description given

Version: 3

SettingsMode: WriteWithoutComments


#######################################################################
# +-----------------------------------------------------------------+ #
# |                          Main settings                          | #
# +-----------------------------------------------------------------+ #
#######################################################################

Tree: true

Frequency: 1

Rarity: 100.0

RotateRandomly: false

SpawnHeight: highestSolidBlock

SpawnHeightOffset: -1

SpawnHeightVariance: 0

##############################
# Height Limits for the BO3. #
##############################

MinHeight: 0

MaxHeight: 255

######################
# Extrusion settings #
######################

ExtrudeMode: None

ExtrudeThroughBlocks: AIR

MaxBranchDepth: 10

ExcludedBiomes: All


#######################################################################
# +-----------------------------------------------------------------+ #
# |                      Source block settings                      | #
# +-----------------------------------------------------------------+ #
#######################################################################

SourceBlocks: AIR,GRASS,DIRT,biomesoplenty:dirt

MaxPercentageOutsideSourceBlock: 0

OutsideSourceBlock: placeAnyway

DoReplaceBlocks: true

IsOTGPlus: false


#######################################################################
# +-----------------------------------------------------------------+ #
# |                              Blocks                             | #
# +-----------------------------------------------------------------+ #
#######################################################################

Block(-3,3,2,rustic:leaves0:0)
Block(-3,4,2,rustic:leaves0:0)
Block(-2,2,2,rustic:leaves0:0)
Block(-2,3,1,rustic:leaves0)
Block(-2,3,2,rustic:leaves0:2)
Block(-2,3,3,rustic:leaves0:0)
Block(-2,4,-1,rustic:leaves0:0)
Block(-2,4,0,rustic:leaves0:0)
Block(-2,4,1,rustic:leaves0:0)
Block(-2,4,2,rustic:leaves0:1)
Block(-2,4,3,rustic:leaves0:0)
Block(-2,5,-1,rustic:leaves0:0)
Block(-2,5,0,rustic:leaves0:0)
Block(-2,5,1,rustic:leaves0:0)
Block(-2,5,2,rustic:leaves0:0)
Block(-2,6,-1,rustic:leaves0:0)
Block(-2,6,0,rustic:leaves0:0)
Block(-2,6,1,rustic:leaves0:0)
Block(-1,2,3,rustic:leaves0:0)
Block(-1,3,1,rustic:olivebranch)
Block(-1,3,2,rustic:leaves0)
Block(-1,3,3,rustic:leaves0:2)
Block(-1,3,4,rustic:leaves0:0)
Block(-1,4,-2,rustic:leaves0:0)
Block(-1,4,-1,rustic:leaves0:1)
Block(-1,4,0,rustic:leaves0:2)
Block(-1,4,1,rustic:leaves0)
Block(-1,4,2,rustic:leaves0:2)
Block(-1,4,3,rustic:leaves0:1)
Block(-1,4,4,rustic:leaves0:0)
Block(-1,5,-2,rustic:leaves0:0)
Block(-1,5,-1,rustic:leaves0:2)
Block(-1,5,0,rustic:leaves0)
Block(-1,5,1,rustic:leaves0:2)
Block(-1,5,2,rustic:leaves0:1)
Block(-1,5,3,rustic:leaves0:0)
Block(-1,6,-2,rustic:leaves0:0)
Block(-1,6,-1,rustic:leaves0:1)
Block(-1,6,0,rustic:leaves0:2)
Block(-1,6,1,rustic:leaves0:1)
Block(-1,6,2,rustic:leaves0:0)
Block(-1,7,-1,rustic:leaves0:0)
Block(-1,7,0,rustic:leaves0:0)
Block(-1,7,1,rustic:leaves0:0)
Block(0,0,1,dynamictrees:rootydirt:0)
Block(0,1,1,rustic:olivebranch:3)
Block(0,2,1,rustic:olivebranch:2)
Block(0,2,2,rustic:leaves0)
Block(0,2,3,rustic:leaves0:0)
Block(0,3,1,rustic:olivebranch:2)
Block(0,3,2,rustic:olivebranch)
Block(0,3,3,rustic:leaves0)
Block(0,3,4,rustic:leaves0:0)
Block(0,4,-2,rustic:leaves0:0)
Block(0,4,-1,rustic:leaves0:2)
Block(0,4,0,rustic:leaves0)
Block(0,4,1,rustic:olivebranch:1)
Block(0,4,2,rustic:leaves0)
Block(0,4,3,rustic:leaves0:2)
Block(0,4,4,rustic:leaves0:0)
Block(0,5,-2,rustic:leaves0:0)
Block(0,5,-1,rustic:leaves0)
Block(0,5,0,rustic:olivebranch)
Block(0,5,1,rustic:olivebranch:1)
Block(0,5,2,rustic:leaves0:0)
Block(0,5,3,rustic:leaves0:0)
Block(0,6,-2,rustic:leaves0:0)
Block(0,6,-1,rustic:leaves0:2)
Block(0,6,0,rustic:leaves0)
Block(0,6,1,rustic:leaves0:0)
Block(0,7,-1,rustic:leaves0:0)
Block(0,7,0,rustic:leaves0:0)
Block(1,2,3,rustic:leaves0:0)
Block(1,3,2,rustic:leaves0)
Block(1,3,3,rustic:leaves0:2)
Block(1,3,4,rustic:leaves0:0)
Block(1,4,-2,rustic:leaves0:0)
Block(1,4,-1,rustic:leaves0:1)
Block(1,4,0,rustic:leaves0)
Block(1,4,1,rustic:olivebranch)
Block(1,4,2,rustic:leaves0)
Block(1,4,3,rustic:leaves0:1)
Block(1,4,4,rustic:leaves0:0)
Block(1,5,-2,rustic:leaves0:0)
Block(1,5,-1,rustic:leaves0:2)
Block(1,5,0,rustic:leaves0)
Block(1,5,1,rustic:leaves0)
Block(1,5,2,rustic:leaves0:2)
Block(1,5,3,rustic:leaves0:0)
Block(1,6,-2,rustic:leaves0:0)
Block(1,6,-1,rustic:leaves0:1)
Block(1,6,0,rustic:leaves0:2)
Block(1,6,1,rustic:leaves0:0)
Block(1,6,2,rustic:leaves0:0)
Block(1,7,-1,rustic:leaves0:0)
Block(1,7,0,rustic:leaves0:0)
Block(2,3,0,rustic:leaves0:0)
Block(2,3,1,rustic:leaves0:0)
Block(2,3,2,rustic:leaves0:0)
Block(2,3,3,rustic:leaves0:0)
Block(2,4,-1,rustic:leaves0:0)
Block(2,4,0,rustic:leaves0:2)
Block(2,4,1,rustic:leaves0)
Block(2,4,2,rustic:leaves0:2)
Block(2,4,3,rustic:leaves0:0)
Block(2,5,-1,rustic:leaves0:0)
Block(2,5,0,rustic:leaves0:1)
Block(2,5,1,rustic:leaves0:2)
Block(2,5,2,rustic:leaves0:1)
Block(2,5,3,rustic:leaves0:0)
Block(2,6,-1,rustic:leaves0:0)
Block(2,6,0,rustic:leaves0:0)
Block(2,6,1,rustic:leaves0:0)
Block(2,6,2,rustic:leaves0:0)
Block(3,4,0,rustic:leaves0:0)
Block(3,4,1,rustic:leaves0:0)
Block(3,4,2,rustic:leaves0:0)
Block(3,5,0,rustic:leaves0:0)
Block(3,5,1,rustic:leaves0:0)
Block(3,5,2,rustic:leaves0:0)

#######################################################################
# +-----------------------------------------------------------------+ #
# |                            BO3 checks                           | #
# +-----------------------------------------------------------------+ #
#######################################################################

BlockCheck(0,-1,1,GRASS,DIRT,biomesoplenty:grass,biomesoplenty:dirt)

#######################################################################
# +-----------------------------------------------------------------+ #
# |                             Branches                            | #
# +-----------------------------------------------------------------+ #
#######################################################################


#######################################################################
# +-----------------------------------------------------------------+ #
# |                             Entities                            | #
# +-----------------------------------------------------------------+ #
#######################################################################


#######################################################################
# +-----------------------------------------------------------------+ #
# |                            Particles                            | #
# +-----------------------------------------------------------------+ #
#######################################################################


#######################################################################
# +-----------------------------------------------------------------+ #
# |                             Spawners                            | #
# +-----------------------------------------------------------------+ #
#######################################################################


#######################################################################
# +-----------------------------------------------------------------+ #
# |                             ModData                             | #
# +-----------------------------------------------------------------+ #
#######################################################################

