
#######################################################################
# +-----------------------------------------------------------------+ #
# |                            BO4 object                           | #
# +-----------------------------------------------------------------+ #
#######################################################################

Author: NLBlackEagle

Description: No description given

SettingsMode: WriteWithoutComments


#######################################################################
# +-----------------------------------------------------------------+ #
# |                          Main settings                          | #
# +-----------------------------------------------------------------+ #
#######################################################################

FixedRotation: 

Frequency: 0

SpawnHeight: highestBlock

UseCenterForHighestBlock: true

##############################
# Height Limits for the BO4. #
##############################

MinHeight: 0

MaxHeight: 255

InheritBO3: 

InheritBO3Rotation: NORTH

OverrideChildSettings: true

OverrideParentHeight: false

CanOverride: true

BranchFrequency: 0

BranchFrequencyGroup: 

MustBeBelowOther: false

MustBeInside: 

CannotBeInside: 

ReplacesBO3: 

MustBeInsideWorldBorders: false

CanSpawnOnWater: true

SpawnOnWaterOnly: false

SpawnUnderWater: false

SpawnAtWaterLevel: false

HeightOffset: 0

RemoveAir: false

ReplaceAbove: 

ReplaceBelow: 

ReplaceWithBiomeBlocks: false

ReplaceWithSurfaceBlock: GRASS

ReplaceWithGroundBlock: DIRT

ReplaceWithStoneBlock: STONE

SmoothRadius: 0

SmoothHeightOffset: 0

SmoothStartTop: false

SmoothStartWood: false

SmoothingSurfaceBlock: 

SmoothingGroundBlock: 

BO3Group: 

IsSpawnPoint: false

DoReplaceBlocks: true


#######################################################################
# +-----------------------------------------------------------------+ #
# |                              Blocks                             | #
# +-----------------------------------------------------------------+ #
#######################################################################

Block(-8,0,-7,COBBLESTONE:0)
Block(-8,0,-6,COBBLESTONE:0)
Block(-8,0,-5,MOSSY_COBBLESTONE:0)
Block(-8,0,-4,COBBLESTONE:0)
Block(-8,0,-3,COBBLESTONE:0)
Block(-8,0,-2,COBBLESTONE:0)
Block(-8,0,-1,COBBLESTONE:0)
Block(-8,0,0,COBBLESTONE:0)
Block(-8,0,1,MOSSY_COBBLESTONE:0)
Block(-8,1,-7,GRAVEL:0)
Block(-8,1,-6,GRAVEL:0)
Block(-8,1,-5,GRAVEL:0)
Block(-8,1,-4,GRAVEL:0)
Block(-8,1,-3,GRAVEL:0)
Block(-8,1,-2,GRAVEL:0)
Block(-8,1,-1,GRAVEL:0)
Block(-8,1,0,MOSSY_COBBLESTONE:0)
Block(-8,1,1,MOSSY_COBBLESTONE:0)
RandomBlock(-8,2,-7,MOB_SPAWNER:0,../../ruins_spawners/crypt_multi.nbt,1,AIR:0,90,CHEST:2,../../../../Chests/Loot/bone_loot.nbt,2,CHEST:2,../../../../Chests/Loot/common_loot.nbt,2,CHEST:2,../../../../Chests/Loot/simple_dungeon.nbt,2,AIR:0,100)
RandomBlock(-8,2,-6,MOB_SPAWNER:0,../../ruins_spawners/crypt_multi.nbt,1,AIR:0,90,CHEST:2,../../../../Chests/Loot/bone_loot.nbt,2,CHEST:2,../../../../Chests/Loot/common_loot.nbt,2,CHEST:2,../../../../Chests/Loot/simple_dungeon.nbt,2,AIR:0,100)
RandomBlock(-8,2,-5,MOB_SPAWNER:0,../../ruins_spawners/crypt_multi.nbt,1,AIR:0,90,CHEST:2,../../../../Chests/Loot/bone_loot.nbt,2,CHEST:2,../../../../Chests/Loot/common_loot.nbt,2,CHEST:2,../../../../Chests/Loot/simple_dungeon.nbt,2,AIR:0,100)
RandomBlock(-8,2,-4,MOB_SPAWNER:0,../../ruins_spawners/crypt_multi.nbt,1,AIR:0,90,CHEST:2,../../../../Chests/Loot/bone_loot.nbt,2,CHEST:2,../../../../Chests/Loot/common_loot.nbt,2,CHEST:2,../../../../Chests/Loot/simple_dungeon.nbt,2,AIR:0,100)
RandomBlock(-8,2,-3,MOB_SPAWNER:0,../../ruins_spawners/crypt_multi.nbt,1,AIR:0,90,CHEST:2,../../../../Chests/Loot/bone_loot.nbt,2,CHEST:2,../../../../Chests/Loot/common_loot.nbt,2,CHEST:2,../../../../Chests/Loot/simple_dungeon.nbt,2,AIR:0,100)
RandomBlock(-8,2,-2,MOB_SPAWNER:0,../../ruins_spawners/crypt_multi.nbt,1,AIR:0,90,CHEST:2,../../../../Chests/Loot/bone_loot.nbt,2,CHEST:2,../../../../Chests/Loot/common_loot.nbt,2,CHEST:2,../../../../Chests/Loot/simple_dungeon.nbt,2,AIR:0,100)
RandomBlock(-8,2,-1,MOB_SPAWNER:0,../../ruins_spawners/crypt_multi.nbt,1,AIR:0,90,CHEST:2,../../../../Chests/Loot/bone_loot.nbt,2,CHEST:2,../../../../Chests/Loot/common_loot.nbt,2,CHEST:2,../../../../Chests/Loot/simple_dungeon.nbt,2,AIR:0,100)
Block(-8,2,0,COBBLESTONE:0)
Block(-8,2,1,COBBLESTONE:0)
Block(-8,3,-7,AIR:0)
Block(-8,3,-6,AIR:0)
Block(-8,3,-5,AIR:0)
Block(-8,3,-4,AIR:0)
Block(-8,3,-3,AIR:0)
Block(-8,3,-2,AIR:0)
Block(-8,3,-1,AIR:0)
Block(-8,3,0,COBBLESTONE:0)
Block(-8,3,1,MOSSY_COBBLESTONE:0)
Block(-8,4,-7,AIR:0)
Block(-8,4,-6,AIR:0)
Block(-8,4,-5,AIR:0)
Block(-8,4,-4,AIR:0)
Block(-8,4,-3,AIR:0)
Block(-8,4,-2,AIR:0)
Block(-8,4,-1,AIR:0)
Block(-8,4,0,MOSSY_COBBLESTONE:0)
Block(-8,4,1,COBBLESTONE:0)
Block(-8,5,-7,AIR:0)
Block(-8,5,-6,AIR:0)
Block(-8,5,-5,AIR:0)
Block(-8,5,-4,AIR:0)
Block(-8,5,-3,AIR:0)
Block(-8,5,-2,AIR:0)
Block(-8,5,-1,AIR:0)
Block(-8,5,0,COBBLESTONE:0)
Block(-8,5,1,COBBLESTONE:0)
Block(-8,6,-7,AIR:0)
Block(-8,6,-6,AIR:0)
Block(-8,6,-5,AIR:0)
Block(-8,6,-4,AIR:0)
Block(-8,6,-3,AIR:0)
Block(-8,6,-2,AIR:0)
Block(-8,6,-1,COBBLESTONE_STAIRS:2)
Block(-8,6,0,COBBLESTONE:0)
Block(-8,6,1,COBBLESTONE:0)
Block(-8,7,-7,AIR:0)
Block(-8,7,-6,AIR:0)
Block(-8,7,-5,AIR:0)
Block(-8,7,-4,AIR:0)
Block(-8,7,-3,AIR:0)
Block(-8,7,-2,AIR:0)
Block(-8,7,-1,AIR:0)
Block(-8,7,0,AIR:0)
Block(-8,7,1,COBBLESTONE_STAIRS:2)
Block(-8,7,2,COBBLESTONE:0)
Block(-8,7,3,COBBLESTONE:0)
Block(-8,8,-7,AIR:0)
Block(-8,8,-6,AIR:0)
Block(-8,8,-5,AIR:0)
Block(-8,8,-4,AIR:0)
Block(-8,8,-3,AIR:0)
Block(-8,8,-2,AIR:0)
Block(-8,8,-1,AIR:0)
Block(-8,8,0,AIR:0)
Block(-8,8,1,AIR:0)
Block(-8,8,2,AIR:0)
Block(-8,8,3,COBBLESTONE_STAIRS:2)
Block(-7,0,-7,COBBLESTONE:0)
Block(-7,0,-6,COBBLESTONE:0)
Block(-7,0,-5,MOSSY_COBBLESTONE:0)
Block(-7,0,-4,COBBLESTONE:0)
Block(-7,0,-3,COBBLESTONE:0)
Block(-7,0,-2,MOSSY_COBBLESTONE:0)
Block(-7,0,-1,COBBLESTONE:0)
Block(-7,1,-7,GRAVEL:0)
Block(-7,1,-6,GRAVEL:0)
Block(-7,1,-5,GRAVEL:0)
Block(-7,1,-4,GRAVEL:0)
Block(-7,1,-3,GRAVEL:0)
Block(-7,1,-2,GRAVEL:0)
Block(-7,1,-1,COBBLESTONE:0)
RandomBlock(-7,2,-7,MOB_SPAWNER:0,../../ruins_spawners/crypt_multi.nbt,1,AIR:0,90,CHEST:2,../../../../Chests/Loot/bone_loot.nbt,2,CHEST:2,../../../../Chests/Loot/common_loot.nbt,2,CHEST:2,../../../../Chests/Loot/simple_dungeon.nbt,2,AIR:0,100)
RandomBlock(-7,2,-6,MOB_SPAWNER:0,../../ruins_spawners/crypt_multi.nbt,1,AIR:0,90,CHEST:2,../../../../Chests/Loot/bone_loot.nbt,2,CHEST:2,../../../../Chests/Loot/common_loot.nbt,2,CHEST:2,../../../../Chests/Loot/simple_dungeon.nbt,2,AIR:0,100)
RandomBlock(-7,2,-5,MOB_SPAWNER:0,../../ruins_spawners/crypt_multi.nbt,1,AIR:0,90,CHEST:2,../../../../Chests/Loot/bone_loot.nbt,2,CHEST:2,../../../../Chests/Loot/common_loot.nbt,2,CHEST:2,../../../../Chests/Loot/simple_dungeon.nbt,2,AIR:0,100)
RandomBlock(-7,2,-4,MOB_SPAWNER:0,../../ruins_spawners/crypt_multi.nbt,1,AIR:0,90,CHEST:2,../../../../Chests/Loot/bone_loot.nbt,2,CHEST:2,../../../../Chests/Loot/common_loot.nbt,2,CHEST:2,../../../../Chests/Loot/simple_dungeon.nbt,2,AIR:0,100)
RandomBlock(-7,2,-3,MOB_SPAWNER:0,../../ruins_spawners/crypt_multi.nbt,1,AIR:0,90,CHEST:2,../../../../Chests/Loot/bone_loot.nbt,2,CHEST:2,../../../../Chests/Loot/common_loot.nbt,2,CHEST:2,../../../../Chests/Loot/simple_dungeon.nbt,2,AIR:0,100)
RandomBlock(-7,2,-2,MOB_SPAWNER:0,../../ruins_spawners/crypt_multi.nbt,1,AIR:0,90,CHEST:2,../../../../Chests/Loot/bone_loot.nbt,2,CHEST:2,../../../../Chests/Loot/common_loot.nbt,2,CHEST:2,../../../../Chests/Loot/simple_dungeon.nbt,2,AIR:0,100)
Block(-7,2,-1,COBBLESTONE:0)
Block(-7,3,-7,AIR:0)
Block(-7,3,-6,AIR:0)
Block(-7,3,-5,AIR:0)
Block(-7,3,-4,AIR:0)
Block(-7,3,-3,AIR:0)
Block(-7,3,-2,AIR:0)
Block(-7,3,-1,COBBLESTONE:0)
Block(-7,4,-7,AIR:0)
Block(-7,4,-6,AIR:0)
Block(-7,4,-5,AIR:0)
Block(-7,4,-4,AIR:0)
Block(-7,4,-3,AIR:0)
Block(-7,4,-2,AIR:0)
Block(-7,4,-1,MOSSY_COBBLESTONE:0)
Block(-7,5,-7,AIR:0)
Block(-7,5,-6,AIR:0)
Block(-7,5,-5,AIR:0)
Block(-7,5,-4,AIR:0)
Block(-7,5,-3,AIR:0)
Block(-7,5,-2,AIR:0)
Block(-7,5,-1,COBBLESTONE:0)
Block(-7,6,-7,AIR:0)
Block(-7,6,-6,AIR:0)
Block(-7,6,-5,AIR:0)
Block(-7,6,-4,AIR:0)
Block(-7,6,-3,AIR:0)
Block(-7,6,-2,COBBLESTONE_STAIRS:2)
Block(-7,6,-1,COBBLESTONE:0)
Block(-7,6,0,MOSSY_COBBLESTONE:0)
Block(-7,7,-7,AIR:0)
Block(-7,7,-6,AIR:0)
Block(-7,7,-5,AIR:0)
Block(-7,7,-4,AIR:0)
Block(-7,7,-3,AIR:0)
Block(-7,7,-2,AIR:0)
Block(-7,7,-1,AIR:0)
Block(-7,7,0,AIR:0)
Block(-7,7,1,COBBLESTONE_STAIRS:2)
Block(-7,7,2,MOSSY_COBBLESTONE:0)
Block(-7,7,3,COBBLESTONE:0)
Block(-7,8,-7,AIR:0)
Block(-7,8,-6,AIR:0)
Block(-7,8,-5,AIR:0)
Block(-7,8,-4,AIR:0)
Block(-7,8,-3,AIR:0)
Block(-7,8,-2,AIR:0)
Block(-7,8,-1,AIR:0)
Block(-7,8,0,AIR:0)
Block(-7,8,1,AIR:0)
Block(-7,8,2,AIR:0)
Block(-7,8,3,COBBLESTONE_STAIRS:2)
Block(-6,0,-7,MOSSY_COBBLESTONE:0)
Block(-6,0,-6,COBBLESTONE:0)
Block(-6,0,-5,COBBLESTONE:0)
Block(-6,0,-4,COBBLESTONE:0)
Block(-6,0,-3,COBBLESTONE:0)
Block(-6,0,-2,MOSSY_COBBLESTONE:0)
Block(-6,0,-1,COBBLESTONE:0)
Block(-6,1,-7,GRAVEL:0)
Block(-6,1,-6,GRAVEL:0)
Block(-6,1,-5,GRAVEL:0)
Block(-6,1,-4,GRAVEL:0)
Block(-6,1,-3,GRAVEL:0)
Block(-6,1,-2,GRAVEL:0)
Block(-6,1,-1,COBBLESTONE:0)
RandomBlock(-6,2,-7,MOB_SPAWNER:0,../../ruins_spawners/crypt_multi.nbt,1,AIR:0,90,CHEST:2,../../../../Chests/Loot/bone_loot.nbt,2,CHEST:2,../../../../Chests/Loot/common_loot.nbt,2,CHEST:2,../../../../Chests/Loot/simple_dungeon.nbt,2,AIR:0,100)
RandomBlock(-6,2,-6,MOB_SPAWNER:0,../../ruins_spawners/crypt_multi.nbt,1,AIR:0,90,CHEST:2,../../../../Chests/Loot/bone_loot.nbt,2,CHEST:2,../../../../Chests/Loot/common_loot.nbt,2,CHEST:2,../../../../Chests/Loot/simple_dungeon.nbt,2,AIR:0,100)
RandomBlock(-6,2,-5,MOB_SPAWNER:0,../../ruins_spawners/crypt_multi.nbt,1,AIR:0,90,CHEST:2,../../../../Chests/Loot/bone_loot.nbt,2,CHEST:2,../../../../Chests/Loot/common_loot.nbt,2,CHEST:2,../../../../Chests/Loot/simple_dungeon.nbt,2,AIR:0,100)
RandomBlock(-6,2,-4,MOB_SPAWNER:0,../../ruins_spawners/crypt_multi.nbt,1,AIR:0,90,CHEST:2,../../../../Chests/Loot/bone_loot.nbt,2,CHEST:2,../../../../Chests/Loot/common_loot.nbt,2,CHEST:2,../../../../Chests/Loot/simple_dungeon.nbt,2,AIR:0,100)
RandomBlock(-6,2,-3,MOB_SPAWNER:0,../../ruins_spawners/crypt_multi.nbt,1,AIR:0,90,CHEST:2,../../../../Chests/Loot/bone_loot.nbt,2,CHEST:2,../../../../Chests/Loot/common_loot.nbt,2,CHEST:2,../../../../Chests/Loot/simple_dungeon.nbt,2,AIR:0,100)
RandomBlock(-6,2,-2,MOB_SPAWNER:0,../../ruins_spawners/crypt_multi.nbt,1,AIR:0,90,CHEST:2,../../../../Chests/Loot/bone_loot.nbt,2,CHEST:2,../../../../Chests/Loot/common_loot.nbt,2,CHEST:2,../../../../Chests/Loot/simple_dungeon.nbt,2,AIR:0,100)
Block(-6,2,-1,COBBLESTONE:0)
Block(-6,3,-7,AIR:0)
Block(-6,3,-6,AIR:0)
Block(-6,3,-5,AIR:0)
Block(-6,3,-4,AIR:0)
Block(-6,3,-3,AIR:0)
Block(-6,3,-2,AIR:0)
Block(-6,3,-1,COBBLESTONE:0)
Block(-6,4,-7,AIR:0)
Block(-6,4,-6,AIR:0)
Block(-6,4,-5,AIR:0)
Block(-6,4,-4,AIR:0)
Block(-6,4,-3,AIR:0)
Block(-6,4,-2,AIR:0)
Block(-6,4,-1,MOSSY_COBBLESTONE:0)
Block(-6,5,-7,AIR:0)
Block(-6,5,-6,AIR:0)
Block(-6,5,-5,AIR:0)
Block(-6,5,-4,AIR:0)
Block(-6,5,-3,AIR:0)
Block(-6,5,-2,AIR:0)
Block(-6,5,-1,COBBLESTONE:0)
Block(-6,6,-7,AIR:0)
Block(-6,6,-6,AIR:0)
Block(-6,6,-5,AIR:0)
Block(-6,6,-4,AIR:0)
Block(-6,6,-3,AIR:0)
Block(-6,6,-2,COBBLESTONE_STAIRS:2)
Block(-6,6,-1,COBBLESTONE:0)
Block(-6,6,0,COBBLESTONE:0)
Block(-6,7,-7,AIR:0)
Block(-6,7,-6,AIR:0)
Block(-6,7,-5,AIR:0)
Block(-6,7,-4,AIR:0)
Block(-6,7,-3,AIR:0)
Block(-6,7,-2,AIR:0)
Block(-6,7,-1,AIR:0)
Block(-6,7,0,COBBLESTONE_STAIRS:2)
Block(-6,7,1,COBBLESTONE:0)
Block(-6,7,2,COBBLESTONE:0)
Block(-6,7,3,COBBLESTONE:0)
Block(-6,8,-7,AIR:0)
Block(-6,8,-6,AIR:0)
Block(-6,8,-5,AIR:0)
Block(-6,8,-4,AIR:0)
Block(-6,8,-3,AIR:0)
Block(-6,8,-2,AIR:0)
Block(-6,8,-1,AIR:0)
Block(-6,8,0,AIR:0)
Block(-6,8,1,AIR:0)
Block(-6,8,2,AIR:0)
Block(-6,8,3,COBBLESTONE_STAIRS:2)
Block(-5,0,-7,COBBLESTONE:0)
Block(-5,0,-6,COBBLESTONE:0)
Block(-5,0,-5,COBBLESTONE:0)
Block(-5,0,-4,COBBLESTONE:0)
Block(-5,0,-3,COBBLESTONE:0)
Block(-5,0,-2,COBBLESTONE:0)
Block(-5,1,-7,GRAVEL:0)
Block(-5,1,-6,GRAVEL:0)
Block(-5,1,-5,GRAVEL:0)
Block(-5,1,-4,GRAVEL:0)
Block(-5,1,-3,GRAVEL:0)
Block(-5,1,-2,COBBLESTONE:0)
RandomBlock(-5,2,-7,MOB_SPAWNER:0,../../ruins_spawners/crypt_multi.nbt,1,AIR:0,90,CHEST:2,../../../../Chests/Loot/bone_loot.nbt,2,CHEST:2,../../../../Chests/Loot/common_loot.nbt,2,CHEST:2,../../../../Chests/Loot/simple_dungeon.nbt,2,AIR:0,100)
RandomBlock(-5,2,-6,MOB_SPAWNER:0,../../ruins_spawners/crypt_multi.nbt,1,AIR:0,90,CHEST:2,../../../../Chests/Loot/bone_loot.nbt,2,CHEST:2,../../../../Chests/Loot/common_loot.nbt,2,CHEST:2,../../../../Chests/Loot/simple_dungeon.nbt,2,AIR:0,100)
RandomBlock(-5,2,-5,MOB_SPAWNER:0,../../ruins_spawners/crypt_multi.nbt,1,AIR:0,90,CHEST:2,../../../../Chests/Loot/bone_loot.nbt,2,CHEST:2,../../../../Chests/Loot/common_loot.nbt,2,CHEST:2,../../../../Chests/Loot/simple_dungeon.nbt,2,AIR:0,100)
RandomBlock(-5,2,-4,MOB_SPAWNER:0,../../ruins_spawners/crypt_multi.nbt,1,AIR:0,90,CHEST:2,../../../../Chests/Loot/bone_loot.nbt,2,CHEST:2,../../../../Chests/Loot/common_loot.nbt,2,CHEST:2,../../../../Chests/Loot/simple_dungeon.nbt,2,AIR:0,100)
RandomBlock(-5,2,-3,MOB_SPAWNER:0,../../ruins_spawners/crypt_multi.nbt,1,AIR:0,90,CHEST:2,../../../../Chests/Loot/bone_loot.nbt,2,CHEST:2,../../../../Chests/Loot/common_loot.nbt,2,CHEST:2,../../../../Chests/Loot/simple_dungeon.nbt,2,AIR:0,100)
Block(-5,2,-2,COBBLESTONE:0)
Block(-5,3,-7,AIR:0)
Block(-5,3,-6,AIR:0)
Block(-5,3,-5,AIR:0)
Block(-5,3,-4,AIR:0)
Block(-5,3,-3,AIR:0)
Block(-5,3,-2,COBBLESTONE:0)
Block(-5,4,-7,AIR:0)
Block(-5,4,-6,AIR:0)
Block(-5,4,-5,AIR:0)
Block(-5,4,-4,AIR:0)
Block(-5,4,-3,AIR:0)
Block(-5,4,-2,MOSSY_COBBLESTONE:0)
Block(-5,5,-7,AIR:0)
Block(-5,5,-6,AIR:0)
Block(-5,5,-5,AIR:0)
Block(-5,5,-4,AIR:0)
Block(-5,5,-3,AIR:0)
Block(-5,5,-2,COBBLESTONE:0)
Block(-5,6,-7,AIR:0)
Block(-5,6,-6,AIR:0)
Block(-5,6,-5,AIR:0)
Block(-5,6,-4,AIR:0)
Block(-5,6,-3,STEP:3)
Block(-5,6,-2,COBBLESTONE:0)
Block(-5,6,-1,COBBLESTONE:0)
Block(-5,6,0,COBBLESTONE:0)
Block(-5,7,-7,AIR:0)
Block(-5,7,-6,AIR:0)
Block(-5,7,-5,AIR:0)
Block(-5,7,-4,AIR:0)
Block(-5,7,-3,AIR:0)
Block(-5,7,-2,AIR:0)
Block(-5,7,-1,AIR:0)
Block(-5,7,0,COBBLESTONE_STAIRS:2)
Block(-5,7,1,COBBLESTONE:0)
Block(-5,7,2,COBBLESTONE:0)
Block(-5,7,3,COBBLESTONE:0)
Block(-5,8,-7,AIR:0)
Block(-5,8,-6,AIR:0)
Block(-5,8,-5,AIR:0)
Block(-5,8,-4,AIR:0)
Block(-5,8,-3,AIR:0)
Block(-5,8,-2,AIR:0)
Block(-5,8,-1,AIR:0)
Block(-5,8,0,AIR:0)
Block(-5,8,1,AIR:0)
Block(-5,8,2,COBBLESTONE_STAIRS:2)
Block(-5,8,3,COBBLESTONE:0)
Block(-4,0,-7,COBBLESTONE:0)
Block(-4,0,-6,COBBLESTONE:0)
Block(-4,0,-5,COBBLESTONE:0)
Block(-4,0,-4,COBBLESTONE:0)
Block(-4,0,-3,COBBLESTONE:0)
Block(-4,1,-7,GRAVEL:0)
Block(-4,1,-6,GRAVEL:0)
Block(-4,1,-5,GRAVEL:0)
Block(-4,1,-4,GRAVEL:0)
Block(-4,1,-3,COBBLESTONE:0)
RandomBlock(-4,2,-7,MOB_SPAWNER:0,../../ruins_spawners/crypt_multi.nbt,1,AIR:0,90,CHEST:2,../../../../Chests/Loot/bone_loot.nbt,2,CHEST:2,../../../../Chests/Loot/common_loot.nbt,2,CHEST:2,../../../../Chests/Loot/simple_dungeon.nbt,2,AIR:0,100)
RandomBlock(-4,2,-6,MOB_SPAWNER:0,../../ruins_spawners/crypt_multi.nbt,1,AIR:0,90,CHEST:2,../../../../Chests/Loot/bone_loot.nbt,2,CHEST:2,../../../../Chests/Loot/common_loot.nbt,2,CHEST:2,../../../../Chests/Loot/simple_dungeon.nbt,2,AIR:0,100)
RandomBlock(-4,2,-5,MOB_SPAWNER:0,../../ruins_spawners/crypt_multi.nbt,1,AIR:0,90,CHEST:2,../../../../Chests/Loot/bone_loot.nbt,2,CHEST:2,../../../../Chests/Loot/common_loot.nbt,2,CHEST:2,../../../../Chests/Loot/simple_dungeon.nbt,2,AIR:0,100)
RandomBlock(-4,2,-4,MOB_SPAWNER:0,../../ruins_spawners/crypt_multi.nbt,1,AIR:0,90,CHEST:2,../../../../Chests/Loot/bone_loot.nbt,2,CHEST:2,../../../../Chests/Loot/common_loot.nbt,2,CHEST:2,../../../../Chests/Loot/simple_dungeon.nbt,2,AIR:0,100)
Block(-4,2,-3,MOSSY_COBBLESTONE:0)
Block(-4,3,-7,AIR:0)
Block(-4,3,-6,AIR:0)
Block(-4,3,-5,AIR:0)
Block(-4,3,-4,AIR:0)
Block(-4,3,-3,COBBLESTONE:0)
Block(-4,4,-7,AIR:0)
Block(-4,4,-6,AIR:0)
Block(-4,4,-5,AIR:0)
Block(-4,4,-4,AIR:0)
Block(-4,4,-3,COBBLESTONE:0)
Block(-4,5,-7,AIR:0)
Block(-4,5,-6,AIR:0)
Block(-4,5,-5,AIR:0)
Block(-4,5,-4,AIR:0)
Block(-4,5,-3,MOSSY_COBBLESTONE:0)
Block(-4,6,-7,AIR:0)
Block(-4,6,-6,AIR:0)
Block(-4,6,-5,AIR:0)
Block(-4,6,-4,STEP:3)
Block(-4,6,-3,COBBLESTONE:0)
Block(-4,6,-2,COBBLESTONE:0)
Block(-4,6,-1,MOSSY_COBBLESTONE:0)
Block(-4,7,-7,AIR:0)
Block(-4,7,-6,AIR:0)
Block(-4,7,-5,AIR:0)
Block(-4,7,-4,AIR:0)
Block(-4,7,-3,AIR:0)
Block(-4,7,-2,AIR:0)
Block(-4,7,-1,STEP:3)
Block(-4,7,0,COBBLESTONE:0)
Block(-4,7,1,COBBLESTONE:0)
Block(-4,7,2,COBBLESTONE:0)
Block(-4,7,3,COBBLESTONE:0)
Block(-4,8,-7,AIR:0)
Block(-4,8,-6,AIR:0)
Block(-4,8,-5,AIR:0)
Block(-4,8,-4,AIR:0)
Block(-4,8,-3,AIR:0)
Block(-4,8,-2,AIR:0)
Block(-4,8,-1,AIR:0)
Block(-4,8,0,AIR:0)
Block(-4,8,1,AIR:0)
Block(-4,8,2,COBBLESTONE_STAIRS:2)
Block(-4,8,3,MOSSY_COBBLESTONE:0)
Block(-3,0,-7,COBBLESTONE:0)
Block(-3,0,-6,COBBLESTONE:0)
Block(-3,0,-5,COBBLESTONE:0)
Block(-3,0,-4,COBBLESTONE:0)
Block(-3,1,-7,GRAVEL:0)
Block(-3,1,-6,GRAVEL:0)
Block(-3,1,-5,GRAVEL:0)
Block(-3,1,-4,COBBLESTONE:0)
RandomBlock(-3,2,-7,MOB_SPAWNER:0,../../ruins_spawners/crypt_multi.nbt,1,AIR:0,90,CHEST:2,../../../../Chests/Loot/bone_loot.nbt,2,CHEST:2,../../../../Chests/Loot/common_loot.nbt,2,CHEST:2,../../../../Chests/Loot/simple_dungeon.nbt,2,AIR:0,100)
RandomBlock(-3,2,-6,MOB_SPAWNER:0,../../ruins_spawners/crypt_multi.nbt,1,AIR:0,90,CHEST:2,../../../../Chests/Loot/bone_loot.nbt,2,CHEST:2,../../../../Chests/Loot/common_loot.nbt,2,CHEST:2,../../../../Chests/Loot/simple_dungeon.nbt,2,AIR:0,100)
RandomBlock(-3,2,-5,MOB_SPAWNER:0,../../ruins_spawners/crypt_multi.nbt,1,AIR:0,90,CHEST:2,../../../../Chests/Loot/bone_loot.nbt,2,CHEST:2,../../../../Chests/Loot/common_loot.nbt,2,CHEST:2,../../../../Chests/Loot/simple_dungeon.nbt,2,AIR:0,100)
Block(-3,2,-4,COBBLESTONE:0)
Block(-3,3,-7,AIR:0)
Block(-3,3,-6,AIR:0)
Block(-3,3,-5,AIR:0)
Block(-3,3,-4,COBBLESTONE:0)
Block(-3,4,-7,AIR:0)
Block(-3,4,-6,AIR:0)
Block(-3,4,-5,AIR:0)
Block(-3,4,-4,MOSSY_COBBLESTONE:0)
Block(-3,5,-7,AIR:0)
Block(-3,5,-6,AIR:0)
Block(-3,5,-5,AIR:0)
Block(-3,5,-4,COBBLESTONE:0)
Block(-3,6,-7,AIR:0)
Block(-3,6,-6,COBBLESTONE_STAIRS:0)
Block(-3,6,-5,COBBLESTONE_STAIRS:0)
Block(-3,6,-4,COBBLESTONE:0)
Block(-3,6,-3,MOSSY_COBBLESTONE:0)
Block(-3,6,-2,COBBLESTONE:0)
Block(-3,7,-7,AIR:0)
Block(-3,7,-6,AIR:0)
Block(-3,7,-5,AIR:0)
Block(-3,7,-4,AIR:0)
Block(-3,7,-3,AIR:0)
Block(-3,7,-2,STEP:3)
Block(-3,7,-1,COBBLESTONE:0)
Block(-3,7,0,COBBLESTONE:0)
Block(-3,7,1,COBBLESTONE:0)
Block(-3,7,2,COBBLESTONE:0)
Block(-3,8,-7,AIR:0)
Block(-3,8,-6,AIR:0)
Block(-3,8,-5,AIR:0)
Block(-3,8,-4,AIR:0)
Block(-3,8,-3,AIR:0)
Block(-3,8,-2,AIR:0)
Block(-3,8,-1,AIR:0)
Block(-3,8,0,AIR:0)
Block(-3,8,1,STEP:3)
Block(-3,8,2,COBBLESTONE:0)
Block(-2,0,-7,COBBLESTONE:0)
Block(-2,0,-6,COBBLESTONE:0)
Block(-2,0,-5,COBBLESTONE:0)
Block(-2,1,-7,GRAVEL:0)
Block(-2,1,-6,COBBLESTONE:0)
Block(-2,1,-5,COBBLESTONE:0)
RandomBlock(-2,2,-7,MOB_SPAWNER:0,../../ruins_spawners/crypt_multi.nbt,1,AIR:0,90,CHEST:2,../../../../Chests/Loot/bone_loot.nbt,2,CHEST:2,../../../../Chests/Loot/common_loot.nbt,2,CHEST:2,../../../../Chests/Loot/simple_dungeon.nbt,2,AIR:0,100)
Block(-2,2,-6,COBBLESTONE:0)
Block(-2,2,-5,COBBLESTONE:0)
Block(-2,3,-7,AIR:0)
Block(-2,3,-6,COBBLESTONE:0)
Block(-2,3,-5,COBBLESTONE:0)
Block(-2,4,-7,AIR:0)
Block(-2,4,-6,MOSSY_COBBLESTONE:0)
Block(-2,4,-5,COBBLESTONE:0)
Block(-2,5,-7,AIR:0)
Block(-2,5,-6,COBBLESTONE:0)
Block(-2,5,-5,COBBLESTONE:0)
Block(-2,6,-7,COBBLESTONE_STAIRS:0)
Block(-2,6,-6,COBBLESTONE:0)
Block(-2,6,-5,COBBLESTONE:0)
Block(-2,6,-4,COBBLESTONE:0)
Block(-2,6,-3,COBBLESTONE:0)
Block(-2,7,-7,AIR:0)
Block(-2,7,-6,AIR:0)
Block(-2,7,-5,AIR:0)
Block(-2,7,-4,AIR:0)
Block(-2,7,-3,STEP:3)
Block(-2,7,-2,COBBLESTONE:0)
Block(-2,7,-1,COBBLESTONE:0)
Block(-2,7,0,COBBLESTONE:0)
Block(-2,7,1,MOSSY_COBBLESTONE:0)
Block(-2,8,-7,AIR:0)
Block(-2,8,-6,AIR:0)
Block(-2,8,-5,AIR:0)
Block(-2,8,-4,AIR:0)
Block(-2,8,-3,AIR:0)
Block(-2,8,-2,AIR:0)
Block(-2,8,-1,AIR:0)
Block(-2,8,0,STEP:3)
Block(-2,8,1,COBBLESTONE:0)
Block(-1,0,-7,COBBLESTONE:0)
Block(-1,1,-7,COBBLESTONE:0)
Block(-1,2,-7,COBBLESTONE:0)
Block(-1,3,-7,COBBLESTONE:0)
Block(-1,4,-7,COBBLESTONE:0)
Block(-1,5,-7,COBBLESTONE:0)
Block(-1,6,-7,COBBLESTONE:0)
Block(-1,6,-6,COBBLESTONE:0)
Block(-1,6,-5,COBBLESTONE:0)
Block(-1,6,-4,COBBLESTONE:0)
Block(-1,7,-7,AIR:0)
Block(-1,7,-6,AIR:0)
Block(-1,7,-5,COBBLESTONE_STAIRS:0)
Block(-1,7,-4,COBBLESTONE_STAIRS:0)
Block(-1,7,-3,COBBLESTONE:0)
Block(-1,7,-2,COBBLESTONE:0)
Block(-1,7,-1,MOSSY_COBBLESTONE:0)
Block(-1,7,0,COBBLESTONE:0)
Block(-1,8,-7,AIR:0)
Block(-1,8,-6,AIR:0)
Block(-1,8,-5,AIR:0)
Block(-1,8,-4,AIR:0)
Block(-1,8,-3,AIR:0)
Block(-1,8,-2,AIR:0)
Block(-1,8,-1,STEP:3)
Block(-1,8,0,COBBLESTONE:0)
Block(0,0,-7,COBBLESTONE:0)
Block(0,1,-7,COBBLESTONE:0)
Block(0,2,-7,MOSSY_COBBLESTONE:0)
Block(0,3,-7,COBBLESTONE:0)
Block(0,4,-7,MOSSY_COBBLESTONE:0)
Block(0,5,-7,COBBLESTONE:0)
Block(0,6,-7,COBBLESTONE:0)
Block(0,7,-7,COBBLESTONE_STAIRS:0)
Block(0,7,-6,COBBLESTONE_STAIRS:0)
Block(0,7,-5,COBBLESTONE:0)
Block(0,7,-4,COBBLESTONE:0)
Block(0,7,-3,MOSSY_COBBLESTONE:0)
Block(0,7,-2,COBBLESTONE:0)
Block(0,7,-1,COBBLESTONE:0)
Block(0,8,-7,AIR:0)
Block(0,8,-6,AIR:0)
Block(0,8,-5,AIR:0)
Block(0,8,-4,AIR:0)
Block(0,8,-3,AIR:0)
Block(0,8,-2,STEP:3)
Block(0,8,-1,COBBLESTONE:0)
Block(0,8,1,COBBLESTONE:0)
Block(1,7,-7,COBBLESTONE:0)
Block(1,7,-6,COBBLESTONE:0)
Block(1,7,-5,COBBLESTONE:0)
Block(1,7,-4,MOSSY_COBBLESTONE:0)
Block(1,7,-3,COBBLESTONE:0)
Block(1,7,-2,COBBLESTONE:0)
Block(1,8,-7,AIR:0)
Block(1,8,-6,AIR:0)
Block(1,8,-5,AIR:0)
Block(1,8,-4,COBBLESTONE_STAIRS:0)
Block(1,8,-3,COBBLESTONE_STAIRS:0)
Block(1,8,-2,COBBLESTONE:0)
Block(2,7,-7,COBBLESTONE:0)
Block(2,7,-6,COBBLESTONE:0)
Block(2,7,-5,COBBLESTONE:0)
Block(2,7,-4,COBBLESTONE:0)
Block(2,7,-3,COBBLESTONE:0)
Block(2,8,-7,COBBLESTONE_STAIRS:0)
Block(2,8,-6,COBBLESTONE_STAIRS:0)
Block(2,8,-5,COBBLESTONE_STAIRS:0)
Block(2,8,-4,COBBLESTONE:0)
Block(2,8,-3,COBBLESTONE:0)
Block(2,8,-1,MOSSY_COBBLESTONE:0)

#######################################################################
# +-----------------------------------------------------------------+ #
# |                             Branches                            | #
# +-----------------------------------------------------------------+ #
#######################################################################

Branch(-16,0,0,true,Pit-bigC0R1,NORTH,100.0,0)

#######################################################################
# +-----------------------------------------------------------------+ #
# |                             Entities                            | #
# +-----------------------------------------------------------------+ #
#######################################################################


#######################################################################
# +-----------------------------------------------------------------+ #
# |                            Particles                            | #
# +-----------------------------------------------------------------+ #
#######################################################################


#######################################################################
# +-----------------------------------------------------------------+ #
# |                             Spawners                            | #
# +-----------------------------------------------------------------+ #
#######################################################################


#######################################################################
# +-----------------------------------------------------------------+ #
# |                             ModData                             | #
# +-----------------------------------------------------------------+ #
#######################################################################

