#######################################################################
# +-----------------------------------------------------------------+ #
# |                            BO3 object                           | #
# +-----------------------------------------------------------------+ #
#######################################################################

Author: Bo3 BulkEdit

Description: Converted Schematic - Modified by Bo3BulkEdit

Version: 3

SettingsMode: WriteDisable

#######################################################################
# +-----------------------------------------------------------------+ #
# |                          Main settings                          | #
# +-----------------------------------------------------------------+ #
#######################################################################

IsOTGPlus: true
Tree: false
Frequency: 1
Rarity: 100.0
RotateRandomly: false
SpawnHeight: randomY
MaxBranchDepth: 10
ExcludedBiomes: All

##############################
# Height Limits for the BO3. #
##############################

MinHeight: 0
MaxHeight: 255

#######################################################################
# +-----------------------------------------------------------------+ #
# |                      Source block settings                      | #
# +-----------------------------------------------------------------+ #
#######################################################################

CanOverride: true
MaxPercentageOutsideSourceBlock: 100
OutsideSourceBlock: placeAnyway

#######################################################################
# +-----------------------------------------------------------------+ #
# |                               OTG+                              | #
# +-----------------------------------------------------------------+ #
#######################################################################

BO3Group: CeilingCrystals:0

#######################################################################
# +-----------------------------------------------------------------+ #
# |                              Blocks                             | #
# +-----------------------------------------------------------------+ #
#######################################################################

B(0,750,0,AIR)
B(15,750,15,AIR)
B(12,-32,12,betternether:quartz_stained_glass:15)
B(13,-32,12,betternether:quartz_stained_glass:15)
B(12,-32,13,betternether:quartz_stained_glass:15)
B(13,-32,13,betternether:quartz_stained_glass:15)
B(11,-31,10,betternether:quartz_stained_glass:15)
B(10,-31,11,betternether:quartz_stained_glass:15)
B(11,-31,11,betternether:quartz_stained_glass:15)
B(12,-31,11,betternether:quartz_stained_glass:15)
B(13,-31,11,betternether:quartz_stained_glass:15)
B(10,-31,12,betternether:quartz_stained_glass:15)
B(11,-31,12,betternether:quartz_stained_glass:15)
B(12,-31,12,betternether:quartz_stained_glass:15)
B(13,-31,12,betternether:quartz_stained_glass:15)
B(11,-31,13,betternether:quartz_stained_glass:15)
B(12,-31,13,betternether:quartz_stained_glass:15)
B(13,-31,13,betternether:quartz_stained_glass:15)
B(10,-30,8,betternether:quartz_stained_glass:15)
B(9,-30,9,betternether:quartz_stained_glass:15)
B(10,-30,9,betternether:quartz_stained_glass:15)
B(11,-30,9,betternether:quartz_stained_glass:15)
B(9,-30,10,betternether:quartz_stained_glass:15)
B(10,-30,10,betternether:quartz_stained_glass:15)
B(11,-30,10,betternether:quartz_stained_glass:15)
B(12,-30,10,betternether:quartz_stained_glass:15)
B(9,-30,11,betternether:quartz_stained_glass:15)
B(10,-30,11,betternether:quartz_stained_glass:15)
B(11,-30,11,betternether:quartz_stained_glass:15)
B(12,-30,11,betternether:quartz_stained_glass:15)
B(13,-30,11,betternether:quartz_stained_glass:15)
B(10,-30,12,betternether:quartz_stained_glass:15)
B(11,-30,12,betternether:quartz_stained_glass:15)
B(13,-30,12,betternether:quartz_stained_glass:15)
B(10,-30,13,betternether:quartz_stained_glass:15)
B(11,-30,13,betternether:quartz_stained_glass:15)
B(12,-30,13,betternether:quartz_stained_glass:15)
B(13,-30,13,betternether:quartz_stained_glass:15)
B(9,-29,6,betternether:quartz_stained_glass:15)
B(8,-29,7,betternether:quartz_stained_glass:15)
B(9,-29,7,betternether:quartz_stained_glass:15)
B(10,-29,7,betternether:quartz_stained_glass:15)
B(7,-29,8,betternether:quartz_stained_glass:15)
B(8,-29,8,betternether:quartz_stained_glass:15)
B(9,-29,8,betternether:quartz_stained_glass:15)
B(10,-29,8,betternether:quartz_stained_glass:15)
B(11,-29,8,betternether:quartz_stained_glass:15)
B(7,-29,9,betternether:quartz_stained_glass:15)
B(8,-29,9,betternether:quartz_stained_glass:15)
B(9,-29,9,betternether:quartz_stained_glass:15)
B(10,-29,9,betternether:quartz_stained_glass:15)
B(11,-29,9,betternether:quartz_stained_glass:15)
B(12,-29,9,betternether:quartz_stained_glass:15)
B(7,-29,10,betternether:quartz_stained_glass:15)
B(8,-29,10,betternether:quartz_stained_glass:15)
B(9,-29,10,betternether:quartz_stained_glass:15)
RB(10,-29,10,srparasites:parasitestain:1,80,quark:crystal:1,30,srparasites:parasiterubbledense:1,100)
RB(11,-29,10,srparasites:parasitestain:1,80,quark:crystal:1,30,srparasites:parasiterubbledense:1,100)
B(12,-29,10,betternether:quartz_stained_glass:15)
B(13,-29,10,betternether:quartz_stained_glass:15)
B(8,-29,11,betternether:quartz_stained_glass:15)
B(9,-29,11,betternether:quartz_stained_glass:15)
RB(10,-29,11,srparasites:parasitestain:1,80,quark:crystal:1,30,srparasites:parasiterubbledense:1,100)
RB(11,-29,11,srparasites:parasitestain:1,80,quark:crystal:1,30,srparasites:parasiterubbledense:1,100)
B(13,-29,11,betternether:quartz_stained_glass:15)
B(9,-29,12,betternether:quartz_stained_glass:15)
B(10,-29,12,betternether:quartz_stained_glass:15)
B(12,-29,12,betternether:quartz_stained_glass:15)
B(13,-29,12,betternether:quartz_stained_glass:15)
B(10,-29,13,betternether:quartz_stained_glass:15)
B(11,-29,13,betternether:quartz_stained_glass:15)
B(12,-29,13,betternether:quartz_stained_glass:15)
B(13,-29,13,betternether:quartz_stained_glass:15)
B(7,-28,5,betternether:quartz_stained_glass:15)
B(8,-28,5,betternether:quartz_stained_glass:15)
B(7,-28,6,betternether:quartz_stained_glass:15)
B(8,-28,6,betternether:quartz_stained_glass:15)
B(9,-28,6,betternether:quartz_stained_glass:15)
B(5,-28,7,betternether:quartz_stained_glass:15)
B(6,-28,7,betternether:quartz_stained_glass:15)
B(7,-28,7,betternether:quartz_stained_glass:15)
B(8,-28,7,betternether:quartz_stained_glass:15)
B(9,-28,7,betternether:quartz_stained_glass:15)
B(10,-28,7,betternether:quartz_stained_glass:15)
B(11,-28,7,betternether:quartz_stained_glass:15)
B(5,-28,8,betternether:quartz_stained_glass:15)
B(6,-28,8,betternether:quartz_stained_glass:15)
B(7,-28,8,betternether:quartz_stained_glass:15)
RB(8,-28,8,srparasites:parasitestain:1,80,quark:crystal:1,30,srparasites:parasiterubbledense:1,100)
RB(10,-28,8,srparasites:parasitestain:1,80,quark:crystal:1,30,srparasites:parasiterubbledense:1,100)
B(11,-28,8,betternether:quartz_stained_glass:15)
B(12,-28,8,betternether:quartz_stained_glass:15)
B(5,-28,9,betternether:quartz_stained_glass:15)
B(6,-28,9,betternether:quartz_stained_glass:15)
B(7,-28,9,betternether:quartz_stained_glass:15)
RB(9,-28,9,srparasites:parasitestain:1,80,quark:crystal:1,30,srparasites:parasiterubbledense:1,100)
RB(10,-28,9,srparasites:parasitestain:1,80,quark:crystal:1,30,srparasites:parasiterubbledense:1,100)
B(12,-28,9,betternether:quartz_stained_glass:15)
B(13,-28,9,betternether:quartz_stained_glass:15)
B(6,-28,10,betternether:quartz_stained_glass:15)
B(7,-28,10,betternether:quartz_stained_glass:15)
RB(8,-28,10,srparasites:parasitestain:1,80,quark:crystal:1,30,srparasites:parasiterubbledense:1,100)
RB(9,-28,10,srparasites:parasitestain:1,80,quark:crystal:1,30,srparasites:parasiterubbledense:1,100)
RB(10,-28,10,srparasites:parasitestain:1,80,quark:crystal:1,30,srparasites:parasiterubbledense:1,100)
B(12,-28,10,betternether:quartz_stained_glass:15)
B(13,-28,10,betternether:quartz_stained_glass:15)
B(7,-28,11,betternether:quartz_stained_glass:15)
B(8,-28,11,betternether:quartz_stained_glass:15)
B(13,-28,11,betternether:quartz_stained_glass:15)
B(8,-28,12,betternether:quartz_stained_glass:15)
B(9,-28,12,betternether:quartz_stained_glass:15)
B(12,-28,12,betternether:quartz_stained_glass:15)
B(13,-28,12,betternether:quartz_stained_glass:15)
B(9,-28,13,betternether:quartz_stained_glass:15)
B(10,-28,13,betternether:quartz_stained_glass:15)
B(11,-28,13,betternether:quartz_stained_glass:15)
B(12,-28,13,betternether:quartz_stained_glass:15)
B(6,-27,4,betternether:quartz_stained_glass:15)
B(7,-27,4,betternether:quartz_stained_glass:15)
B(8,-27,4,betternether:quartz_stained_glass:15)
B(5,-27,5,betternether:quartz_stained_glass:15)
B(6,-27,5,betternether:quartz_stained_glass:15)
B(7,-27,5,betternether:quartz_stained_glass:15)
B(8,-27,5,betternether:quartz_stained_glass:15)
B(9,-27,5,betternether:quartz_stained_glass:15)
B(4,-27,6,betternether:quartz_stained_glass:15)
B(5,-27,6,betternether:quartz_stained_glass:15)
B(6,-27,6,betternether:quartz_stained_glass:15)
B(7,-27,6,betternether:quartz_stained_glass:15)
B(8,-27,6,betternether:quartz_stained_glass:15)
B(9,-27,6,betternether:quartz_stained_glass:15)
B(10,-27,6,betternether:quartz_stained_glass:15)
B(4,-27,7,betternether:quartz_stained_glass:15)
B(5,-27,7,betternether:quartz_stained_glass:15)
B(6,-27,7,betternether:quartz_stained_glass:15)
RB(7,-27,7,srparasites:parasitestain:1,80,quark:crystal:1,30,srparasites:parasiterubbledense:1,100)
B(8,-27,7,betternether:quartz_stained_glass:15)
RB(9,-27,7,srparasites:parasitestain:1,80,quark:crystal:1,30,srparasites:parasiterubbledense:1,100)
B(10,-27,7,betternether:quartz_stained_glass:15)
B(11,-27,7,betternether:quartz_stained_glass:15)
B(4,-27,8,betternether:quartz_stained_glass:15)
B(5,-27,8,betternether:quartz_stained_glass:15)
B(6,-27,8,betternether:quartz_stained_glass:15)
B(7,-27,8,betternether:quartz_stained_glass:15)
RB(8,-27,8,srparasites:parasitestain:1,80,quark:crystal:1,30,srparasites:parasiterubbledense:1,100)
RB(9,-27,8,srparasites:parasitestain:1,80,quark:crystal:1,30,srparasites:parasiterubbledense:1,100)
B(10,-27,8,betternether:quartz_stained_glass:15)
B(11,-27,8,betternether:quartz_stained_glass:15)
B(12,-27,8,betternether:quartz_stained_glass:15)
B(5,-27,9,betternether:quartz_stained_glass:15)
B(6,-27,9,betternether:quartz_stained_glass:15)
RB(7,-27,9,srparasites:parasitestain:1,80,quark:crystal:1,30,srparasites:parasiterubbledense:1,100)
RB(8,-27,9,srparasites:parasitestain:1,80,quark:crystal:1,30,srparasites:parasiterubbledense:1,100)
RB(9,-27,9,srparasites:parasitestain:1,80,quark:crystal:1,30,srparasites:parasiterubbledense:1,100)
B(10,-27,9,betternether:quartz_stained_glass:15)
B(11,-27,9,betternether:quartz_stained_glass:15)
B(12,-27,9,betternether:quartz_stained_glass:15)
B(13,-27,9,betternether:quartz_stained_glass:15)
B(6,-27,10,betternether:quartz_stained_glass:15)
B(7,-27,10,betternether:quartz_stained_glass:15)
B(8,-27,10,betternether:quartz_stained_glass:15)
B(9,-27,10,betternether:quartz_stained_glass:15)
RB(10,-27,10,srparasites:parasitestain:1,80,quark:crystal:1,30,srparasites:parasiterubbledense:1,100)
B(11,-27,10,betternether:quartz_stained_glass:15)
B(12,-27,10,betternether:quartz_stained_glass:15)
B(13,-27,10,betternether:quartz_stained_glass:15)
B(7,-27,11,betternether:quartz_stained_glass:15)
B(8,-27,11,betternether:quartz_stained_glass:15)
B(9,-27,11,betternether:quartz_stained_glass:15)
B(10,-27,11,betternether:quartz_stained_glass:15)
B(11,-27,11,betternether:quartz_stained_glass:15)
B(12,-27,11,betternether:quartz_stained_glass:15)
B(13,-27,11,betternether:quartz_stained_glass:15)
B(8,-27,12,betternether:quartz_stained_glass:15)
B(9,-27,12,betternether:quartz_stained_glass:15)
B(10,-27,12,betternether:quartz_stained_glass:15)
B(11,-27,12,betternether:quartz_stained_glass:15)
B(12,-27,12,betternether:quartz_stained_glass:15)
B(9,-27,13,betternether:quartz_stained_glass:15)
B(10,-27,13,betternether:quartz_stained_glass:15)
B(11,-27,13,betternether:quartz_stained_glass:15)
B(5,-26,3,betternether:quartz_stained_glass:15)
B(6,-26,3,betternether:quartz_stained_glass:15)
B(7,-26,3,betternether:quartz_stained_glass:15)
B(4,-26,4,betternether:quartz_stained_glass:15)
B(5,-26,4,betternether:quartz_stained_glass:15)
B(6,-26,4,betternether:quartz_stained_glass:15)
B(7,-26,4,betternether:quartz_stained_glass:15)
B(8,-26,4,betternether:quartz_stained_glass:15)
B(3,-26,5,betternether:quartz_stained_glass:15)
B(4,-26,5,betternether:quartz_stained_glass:15)
B(5,-26,5,betternether:quartz_stained_glass:15)
B(6,-26,5,betternether:quartz_stained_glass:15)
B(7,-26,5,betternether:quartz_stained_glass:15)
B(8,-26,5,betternether:quartz_stained_glass:15)
B(9,-26,5,betternether:quartz_stained_glass:15)
B(3,-26,6,betternether:quartz_stained_glass:15)
B(4,-26,6,betternether:quartz_stained_glass:15)
B(5,-26,6,betternether:quartz_stained_glass:15)
RB(6,-26,6,srparasites:parasitestain:1,80,quark:crystal:1,30,srparasites:parasiterubbledense:1,100)
B(7,-26,6,betternether:quartz_stained_glass:15)
B(8,-26,6,betternether:quartz_stained_glass:15)
B(9,-26,6,betternether:quartz_stained_glass:15)
B(10,-26,6,betternether:quartz_stained_glass:15)
B(3,-26,7,betternether:quartz_stained_glass:15)
B(4,-26,7,betternether:quartz_stained_glass:15)
B(5,-26,7,betternether:quartz_stained_glass:15)
B(6,-26,7,betternether:quartz_stained_glass:15)
RB(7,-26,7,srparasites:parasitestain:1,80,quark:crystal:1,30,srparasites:parasiterubbledense:1,100)
RB(8,-26,7,srparasites:parasitestain:1,80,quark:crystal:1,30,srparasites:parasiterubbledense:1,100)
RB(9,-26,7,srparasites:parasitestain:1,80,quark:crystal:1,30,srparasites:parasiterubbledense:1,100)
B(10,-26,7,betternether:quartz_stained_glass:15)
B(11,-26,7,betternether:quartz_stained_glass:15)
B(4,-26,8,betternether:quartz_stained_glass:15)
B(5,-26,8,betternether:quartz_stained_glass:15)
B(6,-26,8,betternether:quartz_stained_glass:15)
RB(7,-26,8,srparasites:parasitestain:1,80,quark:crystal:1,30,srparasites:parasiterubbledense:1,100)
RB(8,-26,8,srparasites:parasitestain:1,80,quark:crystal:1,30,srparasites:parasiterubbledense:1,100)
B(9,-26,8,betternether:quartz_stained_glass:15)
B(10,-26,8,betternether:quartz_stained_glass:15)
B(11,-26,8,betternether:quartz_stained_glass:15)
B(12,-26,8,betternether:quartz_stained_glass:15)
B(5,-26,9,betternether:quartz_stained_glass:15)
B(6,-26,9,betternether:quartz_stained_glass:15)
RB(7,-26,9,srparasites:parasitestain:1,80,quark:crystal:1,30,srparasites:parasiterubbledense:1,100)
B(8,-26,9,betternether:quartz_stained_glass:15)
RB(9,-26,9,srparasites:parasitestain:1,80,quark:crystal:1,30,srparasites:parasiterubbledense:1,100)
B(10,-26,9,betternether:quartz_stained_glass:15)
B(11,-26,9,betternether:quartz_stained_glass:15)
B(12,-26,9,betternether:quartz_stained_glass:15)
B(6,-26,10,betternether:quartz_stained_glass:15)
B(7,-26,10,betternether:quartz_stained_glass:15)
B(8,-26,10,betternether:quartz_stained_glass:15)
B(9,-26,10,betternether:quartz_stained_glass:15)
B(10,-26,10,betternether:quartz_stained_glass:15)
B(11,-26,10,betternether:quartz_stained_glass:15)
B(12,-26,10,betternether:quartz_stained_glass:15)
B(7,-26,11,betternether:quartz_stained_glass:15)
B(8,-26,11,betternether:quartz_stained_glass:15)
B(9,-26,11,betternether:quartz_stained_glass:15)
B(10,-26,11,betternether:quartz_stained_glass:15)
B(11,-26,11,betternether:quartz_stained_glass:15)
B(8,-26,12,betternether:quartz_stained_glass:15)
B(9,-26,12,betternether:quartz_stained_glass:15)
B(10,-26,12,betternether:quartz_stained_glass:15)
B(4,-25,2,betternether:quartz_stained_glass:15)
B(5,-25,2,betternether:quartz_stained_glass:15)
B(6,-25,2,betternether:quartz_stained_glass:15)
B(3,-25,3,betternether:quartz_stained_glass:15)
B(4,-25,3,betternether:quartz_stained_glass:15)
B(5,-25,3,betternether:quartz_stained_glass:15)
B(6,-25,3,betternether:quartz_stained_glass:15)
B(7,-25,3,betternether:quartz_stained_glass:15)
B(2,-25,4,betternether:quartz_stained_glass:15)
B(3,-25,4,betternether:quartz_stained_glass:15)
B(4,-25,4,betternether:quartz_stained_glass:15)
B(5,-25,4,betternether:quartz_stained_glass:15)
B(6,-25,4,betternether:quartz_stained_glass:15)
B(7,-25,4,betternether:quartz_stained_glass:15)
B(8,-25,4,betternether:quartz_stained_glass:15)
B(2,-25,5,betternether:quartz_stained_glass:15)
B(3,-25,5,betternether:quartz_stained_glass:15)
B(4,-25,5,betternether:quartz_stained_glass:15)
B(5,-25,5,betternether:quartz_stained_glass:15)
B(6,-25,5,betternether:quartz_stained_glass:15)
B(7,-25,5,betternether:quartz_stained_glass:15)
B(8,-25,5,betternether:quartz_stained_glass:15)
B(9,-25,5,betternether:quartz_stained_glass:15)
B(2,-25,6,betternether:quartz_stained_glass:15)
B(3,-25,6,betternether:quartz_stained_glass:15)
B(4,-25,6,betternether:quartz_stained_glass:15)
B(5,-25,6,betternether:quartz_stained_glass:15)
RB(6,-25,6,srparasites:parasitestain:1,80,quark:crystal:1,30,srparasites:parasiterubbledense:1,100)
RB(7,-25,6,srparasites:parasitestain:1,80,quark:crystal:1,30,srparasites:parasiterubbledense:1,100)
RB(8,-25,6,srparasites:parasitestain:1,80,quark:crystal:1,30,srparasites:parasiterubbledense:1,100)
B(9,-25,6,betternether:quartz_stained_glass:15)
B(10,-25,6,betternether:quartz_stained_glass:15)
B(3,-25,7,betternether:quartz_stained_glass:15)
B(4,-25,7,betternether:quartz_stained_glass:15)
B(5,-25,7,betternether:quartz_stained_glass:15)
RB(6,-25,7,srparasites:parasitestain:1,80,quark:crystal:1,30,srparasites:parasiterubbledense:1,100)
RB(7,-25,7,srparasites:parasitestain:1,80,quark:crystal:1,30,srparasites:parasiterubbledense:1,100)
B(8,-25,7,betternether:quartz_stained_glass:15)
B(9,-25,7,betternether:quartz_stained_glass:15)
B(10,-25,7,betternether:quartz_stained_glass:15)
B(11,-25,7,betternether:quartz_stained_glass:15)
B(4,-25,8,betternether:quartz_stained_glass:15)
B(5,-25,8,betternether:quartz_stained_glass:15)
RB(6,-25,8,srparasites:parasitestain:1,80,quark:crystal:1,30,srparasites:parasiterubbledense:1,100)
B(7,-25,8,betternether:quartz_stained_glass:15)
RB(8,-25,8,srparasites:parasitestain:1,80,quark:crystal:1,30,srparasites:parasiterubbledense:1,100)
B(9,-25,8,betternether:quartz_stained_glass:15)
B(10,-25,8,betternether:quartz_stained_glass:15)
B(11,-25,8,betternether:quartz_stained_glass:15)
B(12,-25,8,betternether:quartz_stained_glass:15)
B(5,-25,9,betternether:quartz_stained_glass:15)
B(6,-25,9,betternether:quartz_stained_glass:15)
B(7,-25,9,betternether:quartz_stained_glass:15)
B(8,-25,9,betternether:quartz_stained_glass:15)
B(9,-25,9,betternether:quartz_stained_glass:15)
B(10,-25,9,betternether:quartz_stained_glass:15)
B(11,-25,9,betternether:quartz_stained_glass:15)
B(12,-25,9,betternether:quartz_stained_glass:15)
B(6,-25,10,betternether:quartz_stained_glass:15)
B(7,-25,10,betternether:quartz_stained_glass:15)
B(8,-25,10,betternether:quartz_stained_glass:15)
B(9,-25,10,betternether:quartz_stained_glass:15)
B(10,-25,10,betternether:quartz_stained_glass:15)
B(11,-25,10,betternether:quartz_stained_glass:15)
B(7,-25,11,betternether:quartz_stained_glass:15)
B(8,-25,11,betternether:quartz_stained_glass:15)
B(9,-25,11,betternether:quartz_stained_glass:15)
B(10,-25,11,betternether:quartz_stained_glass:15)
B(8,-25,12,betternether:quartz_stained_glass:15)
B(9,-25,12,betternether:quartz_stained_glass:15)
B(4,-24,1,betternether:quartz_stained_glass:15)
B(5,-24,1,betternether:quartz_stained_glass:15)
B(3,-24,2,betternether:quartz_stained_glass:15)
B(4,-24,2,betternether:quartz_stained_glass:15)
B(5,-24,2,betternether:quartz_stained_glass:15)
B(6,-24,2,betternether:quartz_stained_glass:15)
B(2,-24,3,betternether:quartz_stained_glass:15)
B(3,-24,3,betternether:quartz_stained_glass:15)
B(4,-24,3,betternether:quartz_stained_glass:15)
B(5,-24,3,betternether:quartz_stained_glass:15)
B(6,-24,3,betternether:quartz_stained_glass:15)
B(7,-24,3,betternether:quartz_stained_glass:15)
B(1,-24,4,betternether:quartz_stained_glass:15)
B(2,-24,4,betternether:quartz_stained_glass:15)
B(3,-24,4,betternether:quartz_stained_glass:15)
B(4,-24,4,betternether:quartz_stained_glass:15)
B(5,-24,4,betternether:quartz_stained_glass:15)
B(6,-24,4,betternether:quartz_stained_glass:15)
B(7,-24,4,betternether:quartz_stained_glass:15)
B(8,-24,4,betternether:quartz_stained_glass:15)
B(1,-24,5,betternether:quartz_stained_glass:15)
B(2,-24,5,betternether:quartz_stained_glass:15)
B(3,-24,5,betternether:quartz_stained_glass:15)
B(4,-24,5,betternether:quartz_stained_glass:15)
RB(5,-24,5,srparasites:parasitestain:1,80,quark:crystal:1,30,srparasites:parasiterubbledense:1,100)
RB(6,-24,5,srparasites:parasitestain:1,80,quark:crystal:1,30,srparasites:parasiterubbledense:1,100)
RB(7,-24,5,srparasites:parasitestain:1,80,quark:crystal:1,30,srparasites:parasiterubbledense:1,100)
B(8,-24,5,betternether:quartz_stained_glass:15)
B(9,-24,5,betternether:quartz_stained_glass:15)
B(2,-24,6,betternether:quartz_stained_glass:15)
B(3,-24,6,betternether:quartz_stained_glass:15)
B(4,-24,6,betternether:quartz_stained_glass:15)
RB(5,-24,6,srparasites:parasitestain:1,80,quark:crystal:1,30,srparasites:parasiterubbledense:1,100)
RB(6,-24,6,srparasites:parasitestain:1,80,quark:crystal:1,30,srparasites:parasiterubbledense:1,100)
B(7,-24,6,betternether:quartz_stained_glass:15)
B(8,-24,6,betternether:quartz_stained_glass:15)
B(9,-24,6,betternether:quartz_stained_glass:15)
B(10,-24,6,betternether:quartz_stained_glass:15)
B(3,-24,7,betternether:quartz_stained_glass:15)
B(4,-24,7,betternether:quartz_stained_glass:15)
RB(5,-24,7,srparasites:parasitestain:1,80,quark:crystal:1,30,srparasites:parasiterubbledense:1,100)
B(6,-24,7,betternether:quartz_stained_glass:15)
RB(7,-24,7,srparasites:parasitestain:1,80,quark:crystal:1,30,srparasites:parasiterubbledense:1,100)
B(8,-24,7,betternether:quartz_stained_glass:15)
B(9,-24,7,betternether:quartz_stained_glass:15)
B(10,-24,7,betternether:quartz_stained_glass:15)
B(11,-24,7,betternether:quartz_stained_glass:15)
B(4,-24,8,betternether:quartz_stained_glass:15)
B(5,-24,8,betternether:quartz_stained_glass:15)
B(6,-24,8,betternether:quartz_stained_glass:15)
B(7,-24,8,betternether:quartz_stained_glass:15)
B(8,-24,8,betternether:quartz_stained_glass:15)
B(9,-24,8,betternether:quartz_stained_glass:15)
B(10,-24,8,betternether:quartz_stained_glass:15)
B(11,-24,8,betternether:quartz_stained_glass:15)
B(5,-24,9,betternether:quartz_stained_glass:15)
B(6,-24,9,betternether:quartz_stained_glass:15)
B(7,-24,9,betternether:quartz_stained_glass:15)
B(8,-24,9,betternether:quartz_stained_glass:15)
B(9,-24,9,betternether:quartz_stained_glass:15)
B(10,-24,9,betternether:quartz_stained_glass:15)
B(6,-24,10,betternether:quartz_stained_glass:15)
B(7,-24,10,betternether:quartz_stained_glass:15)
B(8,-24,10,betternether:quartz_stained_glass:15)
B(9,-24,10,betternether:quartz_stained_glass:15)
B(7,-24,11,betternether:quartz_stained_glass:15)
B(8,-24,11,betternether:quartz_stained_glass:15)
B(3,-23,0,betternether:quartz_stained_glass:15)
B(4,-23,0,betternether:quartz_stained_glass:15)
B(2,-23,1,betternether:quartz_stained_glass:15)
B(3,-23,1,betternether:quartz_stained_glass:15)
B(4,-23,1,betternether:quartz_stained_glass:15)
B(5,-23,1,betternether:quartz_stained_glass:15)
B(1,-23,2,betternether:quartz_stained_glass:15)
B(2,-23,2,betternether:quartz_stained_glass:15)
B(3,-23,2,betternether:quartz_stained_glass:15)
B(4,-23,2,betternether:quartz_stained_glass:15)
B(5,-23,2,betternether:quartz_stained_glass:15)
B(6,-23,2,betternether:quartz_stained_glass:15)
B(0,-23,3,betternether:quartz_stained_glass:15)
B(1,-23,3,betternether:quartz_stained_glass:15)
B(2,-23,3,betternether:quartz_stained_glass:15)
B(3,-23,3,betternether:quartz_stained_glass:15)
B(4,-23,3,betternether:quartz_stained_glass:15)
B(5,-23,3,betternether:quartz_stained_glass:15)
B(6,-23,3,betternether:quartz_stained_glass:15)
B(7,-23,3,betternether:quartz_stained_glass:15)
B(0,-23,4,betternether:quartz_stained_glass:15)
B(1,-23,4,betternether:quartz_stained_glass:15)
B(2,-23,4,betternether:quartz_stained_glass:15)
B(3,-23,4,betternether:quartz_stained_glass:15)
RB(4,-23,4,srparasites:parasitestain:1,80,quark:crystal:1,30,srparasites:parasiterubbledense:1,100)
B(5,-23,4,betternether:quartz_stained_glass:15)
RB(6,-23,4,srparasites:parasitestain:1,80,quark:crystal:1,30,srparasites:parasiterubbledense:1,100)
B(7,-23,4,betternether:quartz_stained_glass:15)
B(8,-23,4,betternether:quartz_stained_glass:15)
B(1,-23,5,betternether:quartz_stained_glass:15)
B(2,-23,5,betternether:quartz_stained_glass:15)
B(3,-23,5,betternether:quartz_stained_glass:15)
B(4,-23,5,betternether:quartz_stained_glass:15)
RB(5,-23,5,srparasites:parasitestain:1,80,quark:crystal:1,30,srparasites:parasiterubbledense:1,100)
RB(6,-23,5,srparasites:parasitestain:1,80,quark:crystal:1,30,srparasites:parasiterubbledense:1,100)
B(7,-23,5,betternether:quartz_stained_glass:15)
B(8,-23,5,betternether:quartz_stained_glass:15)
B(9,-23,5,betternether:quartz_stained_glass:15)
B(2,-23,6,betternether:quartz_stained_glass:15)
B(3,-23,6,betternether:quartz_stained_glass:15)
RB(4,-23,6,srparasites:parasitestain:1,80,quark:crystal:1,30,srparasites:parasiterubbledense:1,100)
RB(5,-23,6,srparasites:parasitestain:1,80,quark:crystal:1,30,srparasites:parasiterubbledense:1,100)
RB(6,-23,6,srparasites:parasitestain:1,80,quark:crystal:1,30,srparasites:parasiterubbledense:1,100)
B(7,-23,6,betternether:quartz_stained_glass:15)
B(8,-23,6,betternether:quartz_stained_glass:15)
B(9,-23,6,betternether:quartz_stained_glass:15)
B(10,-23,6,betternether:quartz_stained_glass:15)
B(3,-23,7,betternether:quartz_stained_glass:15)
B(4,-23,7,betternether:quartz_stained_glass:15)
B(5,-23,7,betternether:quartz_stained_glass:15)
B(6,-23,7,betternether:quartz_stained_glass:15)
B(7,-23,7,betternether:quartz_stained_glass:15)
B(8,-23,7,betternether:quartz_stained_glass:15)
B(9,-23,7,betternether:quartz_stained_glass:15)
B(10,-23,7,betternether:quartz_stained_glass:15)
B(4,-23,8,betternether:quartz_stained_glass:15)
B(5,-23,8,betternether:quartz_stained_glass:15)
B(6,-23,8,betternether:quartz_stained_glass:15)
B(7,-23,8,betternether:quartz_stained_glass:15)
B(8,-23,8,betternether:quartz_stained_glass:15)
B(9,-23,8,betternether:quartz_stained_glass:15)
B(5,-23,9,betternether:quartz_stained_glass:15)
B(6,-23,9,betternether:quartz_stained_glass:15)
B(7,-23,9,betternether:quartz_stained_glass:15)
B(8,-23,9,betternether:quartz_stained_glass:15)
B(6,-23,10,betternether:quartz_stained_glass:15)
B(7,-23,10,betternether:quartz_stained_glass:15)
B(1,-22,0,betternether:quartz_stained_glass:15)
B(2,-22,0,betternether:quartz_stained_glass:15)
B(3,-22,0,betternether:quartz_stained_glass:15)
B(4,-22,0,betternether:quartz_stained_glass:15)
B(0,-22,1,betternether:quartz_stained_glass:15)
B(1,-22,1,betternether:quartz_stained_glass:15)
B(2,-22,1,betternether:quartz_stained_glass:15)
B(3,-22,1,betternether:quartz_stained_glass:15)
B(4,-22,1,betternether:quartz_stained_glass:15)
B(5,-22,1,betternether:quartz_stained_glass:15)
B(0,-22,2,betternether:quartz_stained_glass:15)
B(1,-22,2,betternether:quartz_stained_glass:15)
B(2,-22,2,betternether:quartz_stained_glass:15)
B(3,-22,2,betternether:quartz_stained_glass:15)
B(4,-22,2,betternether:quartz_stained_glass:15)
B(5,-22,2,betternether:quartz_stained_glass:15)
B(6,-22,2,betternether:quartz_stained_glass:15)
B(0,-22,3,betternether:quartz_stained_glass:15)
B(1,-22,3,betternether:quartz_stained_glass:15)
B(2,-22,3,betternether:quartz_stained_glass:15)
RB(3,-22,3,srparasites:parasitestain:1,80,quark:crystal:1,30,srparasites:parasiterubbledense:1,100)
B(4,-22,3,betternether:quartz_stained_glass:15)
RB(5,-22,3,srparasites:parasitestain:1,80,quark:crystal:1,30,srparasites:parasiterubbledense:1,100)
B(6,-22,3,betternether:quartz_stained_glass:15)
B(7,-22,3,betternether:quartz_stained_glass:15)
B(0,-22,4,betternether:quartz_stained_glass:15)
B(1,-22,4,betternether:quartz_stained_glass:15)
B(2,-22,4,betternether:quartz_stained_glass:15)
B(3,-22,4,betternether:quartz_stained_glass:15)
RB(4,-22,4,srparasites:parasitestain:1,80,quark:crystal:1,30,srparasites:parasiterubbledense:1,100)
RB(5,-22,4,srparasites:parasitestain:1,80,quark:crystal:1,30,srparasites:parasiterubbledense:1,100)
B(6,-22,4,betternether:quartz_stained_glass:15)
B(7,-22,4,betternether:quartz_stained_glass:15)
B(8,-22,4,betternether:quartz_stained_glass:15)
B(1,-22,5,betternether:quartz_stained_glass:15)
B(2,-22,5,betternether:quartz_stained_glass:15)
RB(3,-22,5,srparasites:parasitestain:1,80,quark:crystal:1,30,srparasites:parasiterubbledense:1,100)
RB(4,-22,5,srparasites:parasitestain:1,80,quark:crystal:1,30,srparasites:parasiterubbledense:1,100)
RB(5,-22,5,srparasites:parasitestain:1,80,quark:crystal:1,30,srparasites:parasiterubbledense:1,100)
B(6,-22,5,betternether:quartz_stained_glass:15)
B(7,-22,5,betternether:quartz_stained_glass:15)
B(8,-22,5,betternether:quartz_stained_glass:15)
B(9,-22,5,betternether:quartz_stained_glass:15)
B(2,-22,6,betternether:quartz_stained_glass:15)
B(3,-22,6,betternether:quartz_stained_glass:15)
B(4,-22,6,betternether:quartz_stained_glass:15)
B(5,-22,6,betternether:quartz_stained_glass:15)
B(6,-22,6,betternether:quartz_stained_glass:15)
B(7,-22,6,betternether:quartz_stained_glass:15)
B(8,-22,6,betternether:quartz_stained_glass:15)
B(9,-22,6,betternether:quartz_stained_glass:15)
B(3,-22,7,betternether:quartz_stained_glass:15)
B(4,-22,7,betternether:quartz_stained_glass:15)
B(5,-22,7,betternether:quartz_stained_glass:15)
B(6,-22,7,betternether:quartz_stained_glass:15)
B(7,-22,7,betternether:quartz_stained_glass:15)
B(8,-22,7,betternether:quartz_stained_glass:15)
B(9,-22,7,betternether:quartz_stained_glass:15)
B(4,-22,8,betternether:quartz_stained_glass:15)
B(5,-22,8,betternether:quartz_stained_glass:15)
B(6,-22,8,betternether:quartz_stained_glass:15)
B(7,-22,8,betternether:quartz_stained_glass:15)
B(8,-22,8,betternether:quartz_stained_glass:15)
B(5,-22,9,betternether:quartz_stained_glass:15)
B(6,-22,9,betternether:quartz_stained_glass:15)
B(7,-22,9,betternether:quartz_stained_glass:15)
B(0,-21,0,betternether:quartz_stained_glass:15)
B(1,-21,0,betternether:quartz_stained_glass:15)
B(2,-21,0,betternether:quartz_stained_glass:15)
B(3,-21,0,betternether:quartz_stained_glass:15)
B(4,-21,0,betternether:quartz_stained_glass:15)
B(0,-21,1,betternether:quartz_stained_glass:15)
B(1,-21,1,betternether:quartz_stained_glass:15)
B(2,-21,1,betternether:quartz_stained_glass:15)
B(3,-21,1,betternether:quartz_stained_glass:15)
B(4,-21,1,betternether:quartz_stained_glass:15)
B(5,-21,1,betternether:quartz_stained_glass:15)
B(0,-21,2,betternether:quartz_stained_glass:15)
B(1,-21,2,betternether:quartz_stained_glass:15)
RB(2,-21,2,srparasites:parasitestain:1,80,quark:crystal:1,30,srparasites:parasiterubbledense:1,100)
B(3,-21,2,betternether:quartz_stained_glass:15)
RB(4,-21,2,srparasites:parasitestain:1,80,quark:crystal:1,30,srparasites:parasiterubbledense:1,100)
B(5,-21,2,betternether:quartz_stained_glass:15)
B(6,-21,2,betternether:quartz_stained_glass:15)
B(0,-21,3,betternether:quartz_stained_glass:15)
B(1,-21,3,betternether:quartz_stained_glass:15)
B(2,-21,3,betternether:quartz_stained_glass:15)
RB(3,-21,3,srparasites:parasitestain:1,80,quark:crystal:1,30,srparasites:parasiterubbledense:1,100)
RB(4,-21,3,srparasites:parasitestain:1,80,quark:crystal:1,30,srparasites:parasiterubbledense:1,100)
B(5,-21,3,betternether:quartz_stained_glass:15)
B(6,-21,3,betternether:quartz_stained_glass:15)
B(7,-21,3,betternether:quartz_stained_glass:15)
B(0,-21,4,betternether:quartz_stained_glass:15)
B(1,-21,4,betternether:quartz_stained_glass:15)
RB(2,-21,4,srparasites:parasitestain:1,80,quark:crystal:1,30,srparasites:parasiterubbledense:1,100)
RB(3,-21,4,srparasites:parasitestain:1,80,quark:crystal:1,30,srparasites:parasiterubbledense:1,100)
RB(4,-21,4,srparasites:parasitestain:1,80,quark:crystal:1,30,srparasites:parasiterubbledense:1,100)
B(5,-21,4,betternether:quartz_stained_glass:15)
B(6,-21,4,betternether:quartz_stained_glass:15)
B(7,-21,4,betternether:quartz_stained_glass:15)
B(8,-21,4,betternether:quartz_stained_glass:15)
B(1,-21,5,betternether:quartz_stained_glass:15)
B(2,-21,5,betternether:quartz_stained_glass:15)
B(3,-21,5,betternether:quartz_stained_glass:15)
B(4,-21,5,betternether:quartz_stained_glass:15)
RB(5,-21,5,srparasites:parasitestain:1,80,quark:crystal:1,30,srparasites:parasiterubbledense:1,100)
B(6,-21,5,betternether:quartz_stained_glass:15)
B(7,-21,5,betternether:quartz_stained_glass:15)
B(8,-21,5,betternether:quartz_stained_glass:15)
B(2,-21,6,betternether:quartz_stained_glass:15)
B(3,-21,6,betternether:quartz_stained_glass:15)
B(4,-21,6,betternether:quartz_stained_glass:15)
B(5,-21,6,betternether:quartz_stained_glass:15)
B(6,-21,6,betternether:quartz_stained_glass:15)
B(7,-21,6,betternether:quartz_stained_glass:15)
B(8,-21,6,betternether:quartz_stained_glass:15)
B(3,-21,7,betternether:quartz_stained_glass:15)
B(4,-21,7,betternether:quartz_stained_glass:15)
B(5,-21,7,betternether:quartz_stained_glass:15)
B(6,-21,7,betternether:quartz_stained_glass:15)
B(7,-21,7,betternether:quartz_stained_glass:15)
B(4,-21,8,betternether:quartz_stained_glass:15)
B(5,-21,8,betternether:quartz_stained_glass:15)
B(6,-21,8,betternether:quartz_stained_glass:15)
B(0,-20,0,betternether:quartz_stained_glass:15)
B(1,-20,0,betternether:quartz_stained_glass:15)
B(2,-20,0,betternether:quartz_stained_glass:15)
B(3,-20,0,betternether:quartz_stained_glass:15)
B(4,-20,0,betternether:quartz_stained_glass:15)
B(0,-20,1,betternether:quartz_stained_glass:15)
RB(1,-20,1,srparasites:parasitestain:1,80,quark:crystal:1,30,srparasites:parasiterubbledense:1,100)
B(2,-20,1,betternether:quartz_stained_glass:15)
RB(3,-20,1,srparasites:parasitestain:1,80,quark:crystal:1,30,srparasites:parasiterubbledense:1,100)
B(4,-20,1,betternether:quartz_stained_glass:15)
B(5,-20,1,betternether:quartz_stained_glass:15)
B(0,-20,2,betternether:quartz_stained_glass:15)
B(1,-20,2,betternether:quartz_stained_glass:15)
RB(2,-20,2,srparasites:parasitestain:1,80,quark:crystal:1,30,srparasites:parasiterubbledense:1,100)
RB(3,-20,2,srparasites:parasitestain:1,80,quark:crystal:1,30,srparasites:parasiterubbledense:1,100)
RB(4,-20,2,srparasites:parasitestain:1,80,quark:crystal:1,30,srparasites:parasiterubbledense:1,100)
B(5,-20,2,betternether:quartz_stained_glass:15)
B(6,-20,2,betternether:quartz_stained_glass:15)
B(0,-20,3,betternether:quartz_stained_glass:15)
RB(1,-20,3,srparasites:parasitestain:1,80,quark:crystal:1,30,srparasites:parasiterubbledense:1,100)
RB(2,-20,3,srparasites:parasitestain:1,80,quark:crystal:1,30,srparasites:parasiterubbledense:1,100)
RB(3,-20,3,srparasites:parasitestain:1,80,quark:crystal:1,30,srparasites:parasiterubbledense:1,100)
B(4,-20,3,betternether:quartz_stained_glass:15)
B(5,-20,3,betternether:quartz_stained_glass:15)
B(6,-20,3,betternether:quartz_stained_glass:15)
B(7,-20,3,betternether:quartz_stained_glass:15)
B(0,-20,4,betternether:quartz_stained_glass:15)
B(1,-20,4,betternether:quartz_stained_glass:15)
RB(2,-20,4,srparasites:parasitestain:1,80,quark:crystal:1,30,srparasites:parasiterubbledense:1,100)
B(3,-20,4,betternether:quartz_stained_glass:15)
RB(4,-20,4,srparasites:parasitestain:1,80,quark:crystal:1,30,srparasites:parasiterubbledense:1,100)
B(5,-20,4,betternether:quartz_stained_glass:15)
B(6,-20,4,betternether:quartz_stained_glass:15)
B(7,-20,4,betternether:quartz_stained_glass:15)
B(1,-20,5,betternether:quartz_stained_glass:15)
B(2,-20,5,betternether:quartz_stained_glass:15)
B(3,-20,5,betternether:quartz_stained_glass:15)
B(4,-20,5,betternether:quartz_stained_glass:15)
B(5,-20,5,betternether:quartz_stained_glass:15)
B(6,-20,5,betternether:quartz_stained_glass:15)
B(7,-20,5,betternether:quartz_stained_glass:15)
B(2,-20,6,betternether:quartz_stained_glass:15)
B(3,-20,6,betternether:quartz_stained_glass:15)
B(4,-20,6,betternether:quartz_stained_glass:15)
B(5,-20,6,betternether:quartz_stained_glass:15)
B(6,-20,6,betternether:quartz_stained_glass:15)
B(3,-20,7,betternether:quartz_stained_glass:15)
B(4,-20,7,betternether:quartz_stained_glass:15)
B(5,-20,7,betternether:quartz_stained_glass:15)
B(0,-19,0,betternether:quartz_stained_glass:15)
B(1,-19,0,betternether:quartz_stained_glass:15)
B(2,-19,0,betternether:quartz_stained_glass:15)
B(3,-19,0,betternether:quartz_stained_glass:15)
B(4,-19,0,betternether:quartz_stained_glass:15)
B(0,-19,1,betternether:quartz_stained_glass:15)
RB(1,-19,1,srparasites:parasitestain:1,80,quark:crystal:1,30,srparasites:parasiterubbledense:1,100)
RB(2,-19,1,srparasites:parasitestain:1,80,quark:crystal:1,30,srparasites:parasiterubbledense:1,100)
RB(3,-19,1,srparasites:parasitestain:1,80,quark:crystal:1,30,srparasites:parasiterubbledense:1,100)
B(4,-19,1,betternether:quartz_stained_glass:15)
B(5,-19,1,betternether:quartz_stained_glass:15)
B(0,-19,2,betternether:quartz_stained_glass:15)
RB(1,-19,2,srparasites:parasitestain:1,80,quark:crystal:1,30,srparasites:parasiterubbledense:1,100)
RB(2,-19,2,srparasites:parasitestain:1,80,quark:crystal:1,30,srparasites:parasiterubbledense:1,100)
B(3,-19,2,betternether:quartz_stained_glass:15)
B(4,-19,2,betternether:quartz_stained_glass:15)
B(5,-19,2,betternether:quartz_stained_glass:15)
B(6,-19,2,betternether:quartz_stained_glass:15)
B(0,-19,3,betternether:quartz_stained_glass:15)
RB(1,-19,3,srparasites:parasitestain:1,80,quark:crystal:1,30,srparasites:parasiterubbledense:1,100)
B(2,-19,3,betternether:quartz_stained_glass:15)
RB(3,-19,3,srparasites:parasitestain:1,80,quark:crystal:1,30,srparasites:parasiterubbledense:1,100)
B(4,-19,3,betternether:quartz_stained_glass:15)
B(5,-19,3,betternether:quartz_stained_glass:15)
B(6,-19,3,betternether:quartz_stained_glass:15)
B(7,-19,3,betternether:quartz_stained_glass:15)
B(0,-19,4,betternether:quartz_stained_glass:15)
B(1,-19,4,betternether:quartz_stained_glass:15)
B(2,-19,4,betternether:quartz_stained_glass:15)
B(3,-19,4,betternether:quartz_stained_glass:15)
B(4,-19,4,betternether:quartz_stained_glass:15)
B(5,-19,4,betternether:quartz_stained_glass:15)
B(6,-19,4,betternether:quartz_stained_glass:15)
B(7,-19,4,betternether:quartz_stained_glass:15)
B(1,-19,5,betternether:quartz_stained_glass:15)
B(2,-19,5,betternether:quartz_stained_glass:15)
B(3,-19,5,betternether:quartz_stained_glass:15)
B(4,-19,5,betternether:quartz_stained_glass:15)
B(5,-19,5,betternether:quartz_stained_glass:15)
B(6,-19,5,betternether:quartz_stained_glass:15)
B(2,-19,6,betternether:quartz_stained_glass:15)
B(3,-19,6,betternether:quartz_stained_glass:15)
B(4,-19,6,betternether:quartz_stained_glass:15)
B(5,-19,6,betternether:quartz_stained_glass:15)
B(3,-19,7,betternether:quartz_stained_glass:15)
B(4,-19,7,betternether:quartz_stained_glass:15)
RB(0,-18,0,srparasites:parasitestain:1,80,quark:crystal:1,30,srparasites:parasiterubbledense:1,100)
RB(1,-18,0,srparasites:parasitestain:1,80,quark:crystal:1,30,srparasites:parasiterubbledense:1,100)
RB(2,-18,0,srparasites:parasitestain:1,80,quark:crystal:1,30,srparasites:parasiterubbledense:1,100)
B(3,-18,0,betternether:quartz_stained_glass:15)
B(4,-18,0,betternether:quartz_stained_glass:15)
RB(0,-18,1,srparasites:parasitestain:1,80,quark:crystal:1,30,srparasites:parasiterubbledense:1,100)
RB(1,-18,1,srparasites:parasitestain:1,80,quark:crystal:1,30,srparasites:parasiterubbledense:1,100)
B(2,-18,1,betternether:quartz_stained_glass:15)
B(3,-18,1,betternether:quartz_stained_glass:15)
B(4,-18,1,betternether:quartz_stained_glass:15)
B(5,-18,1,betternether:quartz_stained_glass:15)
RB(0,-18,2,srparasites:parasitestain:1,80,quark:crystal:1,30,srparasites:parasiterubbledense:1,100)
B(1,-18,2,betternether:quartz_stained_glass:15)
RB(2,-18,2,srparasites:parasitestain:1,80,quark:crystal:1,30,srparasites:parasiterubbledense:1,100)
B(3,-18,2,betternether:quartz_stained_glass:15)
B(4,-18,2,betternether:quartz_stained_glass:15)
B(5,-18,2,betternether:quartz_stained_glass:15)
B(6,-18,2,betternether:quartz_stained_glass:15)
B(0,-18,3,betternether:quartz_stained_glass:15)
B(1,-18,3,betternether:quartz_stained_glass:15)
B(2,-18,3,betternether:quartz_stained_glass:15)
B(3,-18,3,betternether:quartz_stained_glass:15)
B(4,-18,3,betternether:quartz_stained_glass:15)
B(5,-18,3,betternether:quartz_stained_glass:15)
B(6,-18,3,betternether:quartz_stained_glass:15)
B(0,-18,4,betternether:quartz_stained_glass:15)
B(1,-18,4,betternether:quartz_stained_glass:15)
B(2,-18,4,betternether:quartz_stained_glass:15)
B(3,-18,4,betternether:quartz_stained_glass:15)
B(4,-18,4,betternether:quartz_stained_glass:15)
B(5,-18,4,betternether:quartz_stained_glass:15)
B(1,-18,5,betternether:quartz_stained_glass:15)
B(2,-18,5,betternether:quartz_stained_glass:15)
B(3,-18,5,betternether:quartz_stained_glass:15)
B(4,-18,5,betternether:quartz_stained_glass:15)
B(2,-18,6,betternether:quartz_stained_glass:15)
B(3,-18,6,betternether:quartz_stained_glass:15)
RB(0,-17,0,srparasites:parasitestain:1,80,quark:crystal:1,30,srparasites:parasiterubbledense:1,100)
RB(1,-17,0,srparasites:parasitestain:1,80,quark:crystal:1,30,srparasites:parasiterubbledense:1,100)
B(2,-17,0,betternether:quartz_stained_glass:15)
B(3,-17,0,betternether:quartz_stained_glass:15)
B(4,-17,0,betternether:quartz_stained_glass:15)
RB(0,-17,1,srparasites:parasitestain:1,80,quark:crystal:1,30,srparasites:parasiterubbledense:1,100)
RB(1,-17,1,srparasites:parasitestain:1,80,quark:crystal:1,30,srparasites:parasiterubbledense:1,100)
B(2,-17,1,betternether:quartz_stained_glass:15)
B(3,-17,1,betternether:quartz_stained_glass:15)
B(4,-17,1,betternether:quartz_stained_glass:15)
B(5,-17,1,betternether:quartz_stained_glass:15)
B(0,-17,2,betternether:quartz_stained_glass:15)
B(1,-17,2,betternether:quartz_stained_glass:15)
B(2,-17,2,betternether:quartz_stained_glass:15)
B(3,-17,2,betternether:quartz_stained_glass:15)
B(4,-17,2,betternether:quartz_stained_glass:15)
B(5,-17,2,betternether:quartz_stained_glass:15)
B(0,-17,3,betternether:quartz_stained_glass:15)
B(1,-17,3,betternether:quartz_stained_glass:15)
B(2,-17,3,betternether:quartz_stained_glass:15)
B(3,-17,3,betternether:quartz_stained_glass:15)
B(4,-17,3,betternether:quartz_stained_glass:15)
B(0,-17,4,betternether:quartz_stained_glass:15)
B(1,-17,4,betternether:quartz_stained_glass:15)
B(2,-17,4,betternether:quartz_stained_glass:15)
B(3,-17,4,betternether:quartz_stained_glass:15)
B(1,-17,5,betternether:quartz_stained_glass:15)
B(2,-17,5,betternether:quartz_stained_glass:15)
RB(0,-16,0,srparasites:parasitestain:1,80,quark:crystal:1,30,srparasites:parasiterubbledense:1,100)
B(1,-16,0,betternether:quartz_stained_glass:15)
B(2,-16,0,betternether:quartz_stained_glass:15)
B(3,-16,0,betternether:quartz_stained_glass:15)
B(4,-16,0,betternether:quartz_stained_glass:15)
B(0,-16,1,betternether:quartz_stained_glass:15)
B(1,-16,1,betternether:quartz_stained_glass:15)
B(2,-16,1,betternether:quartz_stained_glass:15)
B(3,-16,1,betternether:quartz_stained_glass:15)
B(4,-16,1,betternether:quartz_stained_glass:15)
B(0,-16,2,betternether:quartz_stained_glass:15)
B(1,-16,2,betternether:quartz_stained_glass:15)
B(2,-16,2,betternether:quartz_stained_glass:15)
B(3,-16,2,betternether:quartz_stained_glass:15)
B(4,-16,2,betternether:quartz_stained_glass:15)
B(0,-16,3,betternether:quartz_stained_glass:15)
B(1,-16,3,betternether:quartz_stained_glass:15)
B(2,-16,3,betternether:quartz_stained_glass:15)
B(3,-16,3,betternether:quartz_stained_glass:15)
B(0,-16,4,betternether:quartz_stained_glass:15)
B(1,-16,4,betternether:quartz_stained_glass:15)
B(2,-16,4,betternether:quartz_stained_glass:15)
B(0,-15,0,betternether:quartz_stained_glass:15)
B(1,-15,0,betternether:quartz_stained_glass:15)
B(2,-15,0,betternether:quartz_stained_glass:15)
B(3,-15,0,betternether:quartz_stained_glass:15)
B(0,-15,1,betternether:quartz_stained_glass:15)
B(1,-15,1,betternether:quartz_stained_glass:15)
B(2,-15,1,betternether:quartz_stained_glass:15)
B(3,-15,1,betternether:quartz_stained_glass:15)
B(0,-15,2,betternether:quartz_stained_glass:15)
B(1,-15,2,betternether:quartz_stained_glass:15)
B(2,-15,2,betternether:quartz_stained_glass:15)
B(0,-15,3,betternether:quartz_stained_glass:15)
B(1,-15,3,betternether:quartz_stained_glass:15)
B(0,-14,0,betternether:quartz_stained_glass:15)
B(1,-14,0,betternether:quartz_stained_glass:15)
B(2,-14,0,betternether:quartz_stained_glass:15)
B(0,-14,1,betternether:quartz_stained_glass:15)
B(1,-14,1,betternether:quartz_stained_glass:15)
B(0,-14,2,betternether:quartz_stained_glass:15)
B(0,-13,0,betternether:quartz_stained_glass:15)

