#######################################################################
# +-----------------------------------------------------------------+ #
# |                            BO3 object                           | #
# +-----------------------------------------------------------------+ #
#######################################################################

Author: Bo3 BulkEdit

Description: Converted Schematic - Modified by Bo3BulkEdit

Version: 3

SettingsMode: WriteDisable

#######################################################################
# +-----------------------------------------------------------------+ #
# |                          Main settings                          | #
# +-----------------------------------------------------------------+ #
#######################################################################



Frequency: 0


SpawnHeight: randomY





##############################
# Height Limits for the BO3. #
##############################

MinHeight: 0
MaxHeight: 256

#######################################################################
# +-----------------------------------------------------------------+ #
# |                      Source block settings                      | #
# +-----------------------------------------------------------------+ #
#######################################################################

CanOverride: true
MaxPercentageOutsideSourceBlock: 100
OutsideSourceBlock: placeAnyway

#######################################################################
# +-----------------------------------------------------------------+ #
# |                               OTG+                              | #
# +-----------------------------------------------------------------+ #
#######################################################################

#######################################################################
# +-----------------------------------------------------------------+ #
# |                              Blocks                             | #
# +-----------------------------------------------------------------+ #
#######################################################################

B(0,750,0,AIR)
B(15,750,15,AIR)
B(2,0,14,betternether:quartz_stained_glass:15)
B(3,0,14,betternether:quartz_stained_glass:15)
B(1,0,15,betternether:quartz_stained_glass:15)
B(2,0,15,betternether:quartz_stained_glass:15)
B(3,0,15,betternether:quartz_stained_glass:15)
B(4,0,15,betternether:quartz_stained_glass:15)
B(5,0,15,betternether:quartz_stained_glass:15)
B(1,1,13,betternether:quartz_stained_glass:15)
B(2,1,13,betternether:quartz_stained_glass:15)
B(0,1,14,betternether:quartz_stained_glass:15)
B(1,1,14,betternether:quartz_stained_glass:15)
B(2,1,14,betternether:quartz_stained_glass:15)
B(3,1,14,betternether:quartz_stained_glass:15)
B(4,1,14,betternether:quartz_stained_glass:15)
B(0,1,15,betternether:quartz_stained_glass:15)
B(1,1,15,betternether:quartz_stained_glass:15)
B(2,1,15,betternether:quartz_stained_glass:15)
B(3,1,15,betternether:quartz_stained_glass:15)
B(4,1,15,betternether:quartz_stained_glass:15)
B(5,1,15,betternether:quartz_stained_glass:15)
B(1,2,12,betternether:quartz_stained_glass:15)
B(0,2,13,betternether:quartz_stained_glass:15)
B(1,2,13,betternether:quartz_stained_glass:15)
B(2,2,13,betternether:quartz_stained_glass:15)
B(0,2,14,betternether:quartz_stained_glass:15)
B(1,2,14,betternether:quartz_stained_glass:15)
B(2,2,14,betternether:quartz_stained_glass:15)
B(3,2,14,betternether:quartz_stained_glass:15)
B(4,2,14,betternether:quartz_stained_glass:15)
B(0,2,15,betternether:quartz_stained_glass:15)
B(1,2,15,betternether:quartz_stained_glass:15)
B(2,2,15,betternether:quartz_stained_glass:15)
B(3,2,15,betternether:quartz_stained_glass:15)
B(4,2,15,betternether:quartz_stained_glass:15)
B(5,2,15,betternether:quartz_stained_glass:15)
B(0,3,12,betternether:quartz_stained_glass:15)
B(1,3,12,betternether:quartz_stained_glass:15)
B(0,3,13,betternether:quartz_stained_glass:15)
B(1,3,13,betternether:quartz_stained_glass:15)
B(2,3,13,betternether:quartz_stained_glass:15)
B(3,3,13,betternether:quartz_stained_glass:15)
B(0,3,14,betternether:quartz_stained_glass:15)
B(1,3,14,betternether:quartz_stained_glass:15)
B(2,3,14,betternether:quartz_stained_glass:15)
B(3,3,14,betternether:quartz_stained_glass:15)
B(4,3,14,betternether:quartz_stained_glass:15)
B(0,3,15,betternether:quartz_stained_glass:15)
B(1,3,15,betternether:quartz_stained_glass:15)
B(2,3,15,betternether:quartz_stained_glass:15)
B(3,3,15,betternether:quartz_stained_glass:15)
B(4,3,15,betternether:quartz_stained_glass:15)
B(5,3,15,betternether:quartz_stained_glass:15)
B(0,4,11,betternether:quartz_stained_glass:15)
B(0,4,12,betternether:quartz_stained_glass:15)
B(1,4,12,betternether:quartz_stained_glass:15)
B(0,4,13,betternether:quartz_stained_glass:15)
B(1,4,13,betternether:quartz_stained_glass:15)
B(2,4,13,betternether:quartz_stained_glass:15)
B(3,4,13,betternether:quartz_stained_glass:15)
B(0,4,14,betternether:quartz_stained_glass:15)
B(1,4,14,betternether:quartz_stained_glass:15)
B(2,4,14,betternether:quartz_stained_glass:15)
B(3,4,14,betternether:quartz_stained_glass:15)
B(4,4,14,betternether:quartz_stained_glass:15)
B(0,4,15,betternether:quartz_stained_glass:15)
B(1,4,15,betternether:quartz_stained_glass:15)
B(2,4,15,betternether:quartz_stained_glass:15)
B(3,4,15,betternether:quartz_stained_glass:15)
B(4,4,15,betternether:quartz_stained_glass:15)
B(5,4,15,betternether:quartz_stained_glass:15)
B(0,5,11,betternether:quartz_stained_glass:15)
B(0,5,12,betternether:quartz_stained_glass:15)
B(1,5,12,betternether:quartz_stained_glass:15)
B(2,5,12,betternether:quartz_stained_glass:15)
B(0,5,13,betternether:quartz_stained_glass:15)
B(1,5,13,betternether:quartz_stained_glass:15)
B(2,5,13,betternether:quartz_stained_glass:15)
B(3,5,13,betternether:quartz_stained_glass:15)
B(0,5,14,betternether:quartz_stained_glass:15)
B(1,5,14,betternether:quartz_stained_glass:15)
B(2,5,14,betternether:quartz_stained_glass:15)
B(3,5,14,betternether:quartz_stained_glass:15)
B(4,5,14,betternether:quartz_stained_glass:15)
B(0,5,15,betternether:quartz_stained_glass:15)
B(1,5,15,betternether:quartz_stained_glass:15)
B(2,5,15,betternether:quartz_stained_glass:15)
B(3,5,15,betternether:quartz_stained_glass:15)
B(4,5,15,betternether:quartz_stained_glass:15)
B(5,5,15,betternether:quartz_stained_glass:15)
B(0,6,11,betternether:quartz_stained_glass:15)
B(0,6,12,betternether:quartz_stained_glass:15)
B(1,6,12,betternether:quartz_stained_glass:15)
B(2,6,12,betternether:quartz_stained_glass:15)
B(0,6,13,betternether:quartz_stained_glass:15)
B(1,6,13,betternether:quartz_stained_glass:15)
B(2,6,13,betternether:quartz_stained_glass:15)
B(3,6,13,betternether:quartz_stained_glass:15)
B(0,6,14,betternether:quartz_stained_glass:15)
B(1,6,14,betternether:quartz_stained_glass:15)
B(2,6,14,betternether:quartz_stained_glass:15)
B(3,6,14,betternether:quartz_stained_glass:15)
B(4,6,14,betternether:quartz_stained_glass:15)
RB(0,6,15,srparasites:parasitestain:1,80,quark:crystal:1,30,srparasites:parasiterubbledense:1,100)
B(1,6,15,betternether:quartz_stained_glass:15)
B(2,6,15,betternether:quartz_stained_glass:15)
B(3,6,15,betternether:quartz_stained_glass:15)
B(4,6,15,betternether:quartz_stained_glass:15)
B(0,7,11,betternether:quartz_stained_glass:15)
B(1,7,11,betternether:quartz_stained_glass:15)
B(0,7,12,betternether:quartz_stained_glass:15)
B(1,7,12,betternether:quartz_stained_glass:15)
B(2,7,12,betternether:quartz_stained_glass:15)
B(0,7,13,betternether:quartz_stained_glass:15)
B(1,7,13,betternether:quartz_stained_glass:15)
B(2,7,13,betternether:quartz_stained_glass:15)
B(3,7,13,betternether:quartz_stained_glass:15)
B(0,7,14,betternether:quartz_stained_glass:15)
B(1,7,14,betternether:quartz_stained_glass:15)
B(2,7,14,betternether:quartz_stained_glass:15)
B(3,7,14,betternether:quartz_stained_glass:15)
B(4,7,14,betternether:quartz_stained_glass:15)
RB(0,7,15,srparasites:parasitestain:1,80,quark:crystal:1,30,srparasites:parasiterubbledense:1,100)
B(1,7,15,betternether:quartz_stained_glass:15)
B(2,7,15,betternether:quartz_stained_glass:15)
B(3,7,15,betternether:quartz_stained_glass:15)
B(4,7,15,betternether:quartz_stained_glass:15)
B(0,8,11,betternether:quartz_stained_glass:15)
B(1,8,11,betternether:quartz_stained_glass:15)
B(0,8,12,betternether:quartz_stained_glass:15)
B(1,8,12,betternether:quartz_stained_glass:15)
B(2,8,12,betternether:quartz_stained_glass:15)
B(0,8,13,betternether:quartz_stained_glass:15)
B(1,8,13,betternether:quartz_stained_glass:15)
B(2,8,13,betternether:quartz_stained_glass:15)
B(3,8,13,betternether:quartz_stained_glass:15)
B(0,8,14,betternether:quartz_stained_glass:15)
B(1,8,14,betternether:quartz_stained_glass:15)
B(2,8,14,betternether:quartz_stained_glass:15)
B(3,8,14,betternether:quartz_stained_glass:15)
RB(0,8,15,srparasites:parasitestain:1,80,quark:crystal:1,30,srparasites:parasiterubbledense:1,100)
B(1,8,15,betternether:quartz_stained_glass:15)
B(2,8,15,betternether:quartz_stained_glass:15)
B(3,8,15,betternether:quartz_stained_glass:15)
B(4,8,15,betternether:quartz_stained_glass:15)
B(0,9,10,betternether:quartz_stained_glass:15)
B(0,9,11,betternether:quartz_stained_glass:15)
B(1,9,11,betternether:quartz_stained_glass:15)
B(0,9,12,betternether:quartz_stained_glass:15)
B(1,9,12,betternether:quartz_stained_glass:15)
B(2,9,12,betternether:quartz_stained_glass:15)
B(0,9,13,betternether:quartz_stained_glass:15)
B(1,9,13,betternether:quartz_stained_glass:15)
B(2,9,13,betternether:quartz_stained_glass:15)
B(3,9,13,betternether:quartz_stained_glass:15)
B(0,9,14,betternether:quartz_stained_glass:15)
B(1,9,14,betternether:quartz_stained_glass:15)
B(2,9,14,betternether:quartz_stained_glass:15)
B(3,9,14,betternether:quartz_stained_glass:15)
B(0,9,15,betternether:quartz_stained_glass:15)
B(1,9,15,betternether:quartz_stained_glass:15)
B(2,9,15,betternether:quartz_stained_glass:15)
B(3,9,15,betternether:quartz_stained_glass:15)
B(0,10,10,betternether:quartz_stained_glass:15)
B(0,10,11,betternether:quartz_stained_glass:15)
B(1,10,11,betternether:quartz_stained_glass:15)
B(0,10,12,betternether:quartz_stained_glass:15)
B(1,10,12,betternether:quartz_stained_glass:15)
B(2,10,12,betternether:quartz_stained_glass:15)
B(0,10,13,betternether:quartz_stained_glass:15)
B(1,10,13,betternether:quartz_stained_glass:15)
B(2,10,13,betternether:quartz_stained_glass:15)
B(0,10,14,betternether:quartz_stained_glass:15)
B(1,10,14,betternether:quartz_stained_glass:15)
B(2,10,14,betternether:quartz_stained_glass:15)
B(3,10,14,betternether:quartz_stained_glass:15)
B(0,10,15,betternether:quartz_stained_glass:15)
B(1,10,15,betternether:quartz_stained_glass:15)
B(2,10,15,betternether:quartz_stained_glass:15)
B(0,11,10,betternether:quartz_stained_glass:15)
B(0,11,11,betternether:quartz_stained_glass:15)
B(1,11,11,betternether:quartz_stained_glass:15)
B(0,11,12,betternether:quartz_stained_glass:15)
B(1,11,12,betternether:quartz_stained_glass:15)
B(2,11,12,betternether:quartz_stained_glass:15)
B(0,11,13,betternether:quartz_stained_glass:15)
B(1,11,13,betternether:quartz_stained_glass:15)
B(2,11,13,betternether:quartz_stained_glass:15)
B(0,11,14,betternether:quartz_stained_glass:15)
B(1,11,14,betternether:quartz_stained_glass:15)
B(2,11,14,betternether:quartz_stained_glass:15)
B(0,11,15,betternether:quartz_stained_glass:15)
B(1,11,15,betternether:quartz_stained_glass:15)
B(0,12,10,betternether:quartz_stained_glass:15)
B(0,12,11,betternether:quartz_stained_glass:15)
B(1,12,11,betternether:quartz_stained_glass:15)
B(0,12,12,betternether:quartz_stained_glass:15)
B(1,12,12,betternether:quartz_stained_glass:15)
B(0,12,13,betternether:quartz_stained_glass:15)
B(1,12,13,betternether:quartz_stained_glass:15)
B(2,12,13,betternether:quartz_stained_glass:15)
B(0,12,14,betternether:quartz_stained_glass:15)
B(1,12,14,betternether:quartz_stained_glass:15)
B(0,12,15,betternether:quartz_stained_glass:15)
B(1,12,15,betternether:quartz_stained_glass:15)
B(0,13,10,betternether:quartz_stained_glass:15)
B(0,13,11,betternether:quartz_stained_glass:15)
B(1,13,11,betternether:quartz_stained_glass:15)
B(0,13,12,betternether:quartz_stained_glass:15)
B(1,13,12,betternether:quartz_stained_glass:15)
B(0,13,13,betternether:quartz_stained_glass:15)
B(1,13,13,betternether:quartz_stained_glass:15)
B(0,13,14,betternether:quartz_stained_glass:15)
B(0,13,15,betternether:quartz_stained_glass:15)
B(0,14,10,betternether:quartz_stained_glass:15)
B(0,14,11,betternether:quartz_stained_glass:15)
B(0,14,12,betternether:quartz_stained_glass:15)
B(1,14,12,betternether:quartz_stained_glass:15)
B(0,14,13,betternether:quartz_stained_glass:15)
B(0,14,14,betternether:quartz_stained_glass:15)
B(0,15,10,betternether:quartz_stained_glass:15)
B(0,15,11,betternether:quartz_stained_glass:15)
B(0,15,12,betternether:quartz_stained_glass:15)
B(0,16,11,betternether:quartz_stained_glass:15)

#######################################################################
# +-----------------------------------------------------------------+ #
# |                             Branches                            | #
# +-----------------------------------------------------------------+ #
#######################################################################

BR(-16,0,0,true,CRYST-FAT-BIG-02_0x0,NORTH,100,0)
