
#######################################################################
# +-----------------------------------------------------------------+ #
# |                            BO3 object                           | #
# +-----------------------------------------------------------------+ #
#######################################################################

Author: NLBlackEagle

Description: No description given

Version: 3

SettingsMode: WriteDisable


#######################################################################
# +-----------------------------------------------------------------+ #
# |                          Main settings                          | #
# +-----------------------------------------------------------------+ #
#######################################################################

Tree: false

Frequency: 1

Rarity: 100.0

RotateRandomly: true

SpawnHeight: highestSolidBlock

SpawnHeightOffset: 0

SpawnHeightVariance: 0

##############################
# Height Limits for the BO3. #
##############################

MinHeight: 0

MaxHeight: 255

######################
# Extrusion settings #
######################

ExtrudeMode: None

ExtrudeThroughBlocks: AIR

MaxBranchDepth: 10

ExcludedBiomes: All


#######################################################################
# +-----------------------------------------------------------------+ #
# |                      Source block settings                      | #
# +-----------------------------------------------------------------+ #
#######################################################################

SourceBlocks: AIR,GRASS,WATER,STATIONARY_WATER,BIOMESOPLENTY:BLOOD,BIOMESOPLENTY:FLESH

MaxPercentageOutsideSourceBlock: 15

OutsideSourceBlock: placeAnyway

DoReplaceBlocks: true

IsOTGPlus: false


#######################################################################
# +-----------------------------------------------------------------+ #
# |                              Blocks                             | #
# +-----------------------------------------------------------------+ #
#######################################################################

Block(0,0,0,BONE_BLOCK:0)
Block(-5,-5,-4,BONE_BLOCK:0)
Block(-5,-4,-4,BONE_BLOCK:0)
Block(-5,-3,-4,BONE_BLOCK:0)
Block(-5,-2,-4,BONE_BLOCK:0)
Block(-5,-1,-4,BONE_BLOCK:0)
Block(-5,0,-4,BONE_BLOCK:0)
Block(-5,1,-4,BONE_BLOCK:0)
Block(-5,2,-4,BONE_BLOCK:0)
Block(-4,-5,-5,BONE_BLOCK:0)
Block(-4,-5,-4,BONE_BLOCK:8)
Block(-4,-5,-3,BONE_BLOCK:0)
Block(-4,-4,-5,BONE_BLOCK:0)
Block(-4,-4,-4,BONE_BLOCK:8)
Block(-4,-4,-3,BONE_BLOCK:0)
Block(-4,-3,-5,BONE_BLOCK:0)
Block(-4,-3,-4,BONE_BLOCK:8)
Block(-4,-3,-3,BONE_BLOCK:0)
Block(-4,-2,-5,BONE_BLOCK:0)
Block(-4,-2,-4,BONE_BLOCK:8)
Block(-4,-2,-3,minecraft:black_glazed_terracotta:0)
Block(-4,-1,-5,BONE_BLOCK:0)
Block(-4,-1,-4,BONE_BLOCK:8)
Block(-4,-1,-3,minecraft:red_glazed_terracotta:1)
Block(-4,0,-5,BONE_BLOCK:0)
Block(-4,0,-4,BONE_BLOCK:8)
Block(-4,0,-3,minecraft:red_glazed_terracotta:1)
Block(-4,1,-5,BONE_BLOCK:0)
Block(-4,1,-4,BONE_BLOCK:8)
Block(-4,1,-3,BONE_BLOCK:0)
Block(-4,2,-5,BONE_BLOCK:0)
Block(-4,2,-4,BONE_BLOCK:0)
Block(-4,2,-3,BONE_BLOCK:0)
Block(-4,3,-4,BONE_BLOCK:0)
Block(-4,3,-3,BONE_BLOCK:0)
Block(-4,4,-4,BONE_BLOCK:0)
Block(-4,4,-3,BONE_BLOCK:0)
Block(-4,5,-3,BONE_BLOCK:0)
Block(-4,6,-3,BONE_BLOCK:0)
Block(-3,-5,-4,BONE_BLOCK:0)
Block(-3,-5,-3,BONE_BLOCK:0)
Block(-3,-5,-2,BONE_BLOCK:0)
Block(-3,-4,-4,BONE_BLOCK:0)
Block(-3,-4,-3,BONE_BLOCK:0)
Block(-3,-4,-2,BONE_BLOCK:0)
Block(-3,-3,-4,minecraft:black_glazed_terracotta:3)
Block(-3,-3,-3,BONE_BLOCK:0)
Block(-3,-3,-2,minecraft:black_glazed_terracotta:0)
Block(-3,-2,-4,minecraft:red_glazed_terracotta:3)
Block(-3,-2,-3,BONE_BLOCK:0)
Block(-3,-2,-2,minecraft:red_glazed_terracotta:0)
Block(-3,-1,-4,minecraft:red_glazed_terracotta:3)
Block(-3,-1,-3,BONE_BLOCK:0)
Block(-3,-1,-2,minecraft:red_glazed_terracotta:0)
Block(-3,0,-4,minecraft:black_glazed_terracotta:3)
Block(-3,0,-3,BONE_BLOCK:0)
Block(-3,0,-2,minecraft:red_glazed_terracotta:0)
Block(-3,1,-4,BONE_BLOCK:0)
Block(-3,1,-3,BONE_BLOCK:0)
Block(-3,1,-2,minecraft:red_glazed_terracotta:1)
Block(-3,2,-4,BONE_BLOCK:0)
Block(-3,2,-3,BONE_BLOCK:0)
Block(-3,2,-2,minecraft:red_glazed_terracotta:0)
Block(-3,3,-4,BONE_BLOCK:0)
Block(-3,3,-3,BONE_BLOCK:0)
Block(-3,3,-2,minecraft:red_glazed_terracotta:0)
Block(-3,4,-4,BONE_BLOCK:0)
Block(-3,4,-3,minecraft:red_glazed_terracotta:1)
Block(-3,4,-2,minecraft:red_glazed_terracotta:1)
Block(-3,5,-4,BONE_BLOCK:0)
Block(-3,5,-3,minecraft:red_glazed_terracotta:1)
Block(-3,5,-2,minecraft:red_glazed_terracotta:1)
Block(-3,6,-4,BONE_BLOCK:0)
Block(-3,6,-3,minecraft:red_glazed_terracotta:1)
Block(-3,6,-2,BONE_BLOCK:0)
Block(-3,7,-3,BONE_BLOCK:0)
Block(-3,7,-2,BONE_BLOCK:0)
Block(-3,8,-3,BONE_BLOCK:0)
Block(-3,8,-2,BONE_BLOCK:0)
Block(-3,9,-2,BONE_BLOCK:0)
Block(-3,10,-2,BONE_BLOCK:0)
Block(-3,11,-2,BONE_BLOCK:0)
Block(-2,-5,-3,BONE_BLOCK:0)
Block(-2,-5,-2,BONE_BLOCK:0)
Block(-2,-5,-1,BONE_BLOCK:0)
Block(-2,-4,-3,minecraft:black_glazed_terracotta:3)
Block(-2,-4,-2,BONE_BLOCK:0)
Block(-2,-4,-1,BONE_BLOCK:0)
Block(-2,-3,-3,minecraft:red_glazed_terracotta)
Block(-2,-3,-2,BONE_BLOCK:0)
Block(-2,-3,-1,minecraft:black_glazed_terracotta:1)
Block(-2,-2,-3,minecraft:red_glazed_terracotta:3)
Block(-2,-2,-2,BONE_BLOCK:0)
Block(-2,-2,-1,minecraft:red_glazed_terracotta:1)
Block(-2,-1,-3,minecraft:pink_glazed_terracotta:3)
Block(-2,-1,-2,BONE_BLOCK:0)
Block(-2,-1,-1,minecraft:pink_glazed_terracotta:1)
Block(-2,0,-3,minecraft:red_glazed_terracotta:3)
Block(-2,0,-2,minecraft:red_glazed_terracotta:1)
Block(-2,0,-1,minecraft:pink_glazed_terracotta:1)
Block(-2,1,-3,minecraft:red_glazed_terracotta:3)
Block(-2,1,-2,minecraft:pink_glazed_terracotta:1)
Block(-2,1,-1,minecraft:pink_glazed_terracotta:1)
Block(-2,2,-3,minecraft:black_glazed_terracotta:3)
Block(-2,2,-2,BONE_BLOCK:0)
Block(-2,2,-1,minecraft:pink_glazed_terracotta:0)
Block(-2,3,-3,minecraft:pink_glazed_terracotta:3)
Block(-2,3,-2,BONE_BLOCK:0)
Block(-2,3,-1,LEAVES:4)
Block(-2,4,-3,minecraft:pink_glazed_terracotta:3)
Block(-2,4,-2,BONE_BLOCK:0)
Block(-2,5,-3,BONE_BLOCK:0)
Block(-2,5,-2,LEAVES:4)
Block(-2,6,-3,BONE_BLOCK:0)
Block(-2,7,-3,BONE_BLOCK:0)
Block(-2,7,-2,minecraft:red_glazed_terracotta:0)
Block(-2,8,-3,BONE_BLOCK:0)
Block(-2,8,-2,minecraft:red_glazed_terracotta:0)
Block(-2,9,-3,BONE_BLOCK:0)
Block(-2,9,-2,BONE_BLOCK:0)
Block(-2,9,-1,minecraft:red_glazed_terracotta:1)
Block(-2,10,-3,BONE_BLOCK:0)
Block(-2,10,-2,BONE_BLOCK:0)
Block(-2,10,-1,minecraft:red_glazed_terracotta:1)
Block(-2,11,-3,BONE_BLOCK:0)
Block(-2,11,-2,BONE_BLOCK:0)
Block(-2,11,-1,BONE_BLOCK:0)
Block(-2,12,-2,BONE_BLOCK:0)
Block(-2,12,-1,BONE_BLOCK:0)
Block(-2,13,-1,BONE_BLOCK:0)
Block(-2,14,-1,BONE_BLOCK:0)
Block(-1,-5,-2,BONE_BLOCK:0)
Block(-1,-5,-1,BONE_BLOCK:0)
Block(-1,-5,0,BONE_BLOCK:0)
Block(-1,-4,-2,BONE_BLOCK:0)
Block(-1,-4,-1,BONE_BLOCK:0)
Block(-1,-4,0,BONE_BLOCK:0)
Block(-1,-3,-2,minecraft:black_glazed_terracotta:3)
Block(-1,-3,-1,BONE_BLOCK:0)
Block(-1,-3,0,BONE_BLOCK:0)
Block(-1,-2,-2,minecraft:red_glazed_terracotta:3)
Block(-1,-2,-1,BONE_BLOCK:0)
Block(-1,-2,0,minecraft:black_glazed_terracotta:0)
Block(-1,-1,-2,minecraft:pink_glazed_terracotta:3)
Block(-1,-1,-1,BONE_BLOCK:0)
Block(-1,-1,0,minecraft:red_glazed_terracotta:1)
Block(-1,0,-2,minecraft:pink_glazed_terracotta:3)
Block(-1,0,-1,BONE_BLOCK:0)
Block(-1,0,0,minecraft:pink_glazed_terracotta:1)
Block(-1,1,-2,minecraft:red_glazed_terracotta:3)
Block(-1,1,-1,BONE_BLOCK:0)
Block(-1,1,0,minecraft:pink_glazed_terracotta:1)
Block(-1,2,-2,minecraft:red_glazed_terracotta)
Block(-1,2,-1,BONE_BLOCK:0)
Block(-1,2,0,minecraft:pink_glazed_terracotta:1)
Block(-1,3,-2,minecraft:red_glazed_terracotta:3)
Block(-1,3,-1,LEAVES:4)
Block(-1,3,0,LEAVES:4)
Block(-1,4,-2,minecraft:red_glazed_terracotta:3)
Block(-1,4,-1,LEAVES:4)
Block(-1,5,-2,minecraft:black_glazed_terracotta)
Block(-1,6,-2,minecraft:red_glazed_terracotta)
Block(-1,9,-2,minecraft:black_glazed_terracotta:3)
Block(-1,10,-2,LEAVES:4)
Block(-1,10,-1,minecraft:red_glazed_terracotta:0)
Block(-1,11,-2,BONE_BLOCK:0)
Block(-1,11,-1,minecraft:red_glazed_terracotta:0)
Block(-1,12,-2,BONE_BLOCK:0)
Block(-1,12,-1,minecraft:red_glazed_terracotta:0)
Block(-1,13,-2,BONE_BLOCK:0)
Block(-1,13,-1,BONE_BLOCK:0)
Block(-1,13,0,minecraft:red_glazed_terracotta:1)
Block(-1,14,-2,BONE_BLOCK:0)
Block(-1,14,-1,BONE_BLOCK:0)
Block(-1,14,0,BONE_BLOCK:0)
Block(-1,15,-1,BONE_BLOCK:0)
Block(-1,15,0,BONE_BLOCK:0)
Block(-1,16,0,BONE_BLOCK:0)
Block(-1,17,0,BONE_BLOCK:0)
Block(0,-5,-1,BONE_BLOCK:0)
Block(0,-5,0,BONE_BLOCK:0)
Block(0,-5,1,BONE_BLOCK:0)
Block(0,-4,-1,BONE_BLOCK:0)
Block(0,-4,0,BONE_BLOCK:0)
Block(0,-4,1,BONE_BLOCK:0)
Block(0,-3,-1,minecraft:black_glazed_terracotta:3)
Block(0,-3,0,BONE_BLOCK:0)
Block(0,-3,1,BONE_BLOCK:0)
Block(0,-2,-1,minecraft:red_glazed_terracotta:3)
Block(0,-2,0,BONE_BLOCK:0)
Block(0,-2,1,minecraft:black_glazed_terracotta:1)
Block(0,-1,-1,minecraft:pink_glazed_terracotta)
Block(0,-1,0,BONE_BLOCK:0)
Block(0,-1,1,minecraft:red_glazed_terracotta:1)
Block(0,0,-1,minecraft:red_glazed_terracotta)
Block(0,0,1,minecraft:red_glazed_terracotta:1)
Block(0,1,-1,minecraft:red_glazed_terracotta)
Block(0,1,0,BONE_BLOCK:0)
Block(0,1,1,minecraft:pink_glazed_terracotta:1)
Block(0,2,-1,minecraft:black_glazed_terracotta:3)
Block(0,2,0,minecraft:pink_glazed_terracotta:1)
Block(0,2,1,minecraft:pink_glazed_terracotta:1)
Block(0,3,-1,minecraft:pink_glazed_terracotta)
Block(0,3,0,BONE_BLOCK:0)
Block(0,3,1,minecraft:pink_glazed_terracotta:1)
Block(0,4,-1,minecraft:red_glazed_terracotta)
Block(0,4,0,LEAVES:4)
Block(0,4,1,minecraft:black_glazed_terracotta:1)
Block(0,5,-1,minecraft:red_glazed_terracotta)
Block(0,5,0,BONE_BLOCK:0)
Block(0,6,1,minecraft:red_glazed_terracotta:0)
Block(0,7,1,minecraft:red_glazed_terracotta:1)
Block(0,8,1,BONE_BLOCK:0)
Block(0,10,0,minecraft:red_glazed_terracotta:1)
Block(0,11,0,LEAVES:4)
Block(0,11,1,minecraft:red_glazed_terracotta:1)
Block(0,12,0,LEAVES:4)
Block(0,12,1,minecraft:red_glazed_terracotta:1)
Block(0,13,-1,minecraft:black_glazed_terracotta)
Block(0,13,0,BONE_BLOCK:0)
Block(0,13,1,minecraft:red_glazed_terracotta:1)
Block(0,14,-1,BONE_BLOCK:0)
Block(0,14,0,BONE_BLOCK:0)
Block(0,14,1,minecraft:pink_glazed_terracotta:1)
Block(0,15,-1,BONE_BLOCK:0)
Block(0,15,0,BONE_BLOCK:0)
Block(0,15,1,minecraft:pink_glazed_terracotta:0)
Block(0,16,-1,BONE_BLOCK:0)
Block(0,16,0,minecraft:pink_glazed_terracotta:3)
Block(0,16,1,minecraft:red_glazed_terracotta:1)
Block(0,17,-1,BONE_BLOCK:0)
Block(0,17,0,BONE_BLOCK:0)
Block(0,17,1,minecraft:black_glazed_terracotta:0)
Block(0,18,0,BONE_BLOCK:0)
Block(0,18,1,BONE_BLOCK:0)
Block(0,19,1,BONE_BLOCK:0)
Block(1,-5,0,BONE_BLOCK:0)
Block(1,-5,1,BONE_BLOCK:0)
Block(1,-5,2,BONE_BLOCK:0)
Block(1,-4,0,BONE_BLOCK:0)
Block(1,-4,1,BONE_BLOCK:0)
Block(1,-4,2,BONE_BLOCK:0)
Block(1,-3,0,BONE_BLOCK:0)
Block(1,-3,1,BONE_BLOCK:0)
Block(1,-3,2,minecraft:black_glazed_terracotta:0)
Block(1,-2,0,BONE_BLOCK:0)
Block(1,-2,1,BONE_BLOCK:0)
Block(1,-2,2,minecraft:red_glazed_terracotta:1)
Block(1,-1,0,minecraft:red_glazed_terracotta:3)
Block(1,-1,1,minecraft:red_glazed_terracotta:3)
Block(1,-1,2,minecraft:red_glazed_terracotta:1)
Block(1,0,0,minecraft:pink_glazed_terracotta:3)
Block(1,0,1,BONE_BLOCK:0)
Block(1,0,2,minecraft:red_glazed_terracotta:1)
Block(1,1,0,minecraft:pink_glazed_terracotta:3)
Block(1,1,1,BONE_BLOCK:0)
Block(1,1,2,minecraft:pink_glazed_terracotta:1)
Block(1,2,0,minecraft:pink_glazed_terracotta)
Block(1,2,1,BONE_BLOCK:0)
Block(1,2,2,minecraft:pink_glazed_terracotta:1)
Block(1,3,0,LEAVES:4)
Block(1,3,1,BONE_BLOCK:0)
Block(1,3,2,minecraft:black_glazed_terracotta:1)
Block(1,4,0,minecraft:red_glazed_terracotta:3)
Block(1,4,1,BONE_BLOCK:0)
Block(1,4,2,BONE_BLOCK:0)
Block(1,5,0,minecraft:red_glazed_terracotta:3)
Block(1,5,1,BONE_BLOCK:0)
Block(1,5,2,BONE_BLOCK:0)
Block(1,6,0,minecraft:red_glazed_terracotta:3)
Block(1,6,1,BONE_BLOCK:0)
Block(1,6,2,BONE_BLOCK:0)
Block(1,7,0,minecraft:red_glazed_terracotta)
Block(1,7,1,BONE_BLOCK:0)
Block(1,7,2,BONE_BLOCK:0)
Block(1,8,0,minecraft:red_glazed_terracotta)
Block(1,8,1,BONE_BLOCK:0)
Block(1,8,2,LEAVES:4)
Block(1,9,0,minecraft:red_glazed_terracotta)
Block(1,9,1,BONE_BLOCK:0)
Block(1,9,2,BONE_BLOCK:0)
Block(1,10,0,minecraft:red_glazed_terracotta)
Block(1,10,1,BONE_BLOCK:0)
Block(1,10,2,BONE_BLOCK:0)
Block(1,11,1,BONE_BLOCK:0)
Block(1,11,2,minecraft:black_glazed_terracotta:1)
Block(1,12,1,BONE_BLOCK:0)
Block(1,12,2,minecraft:red_glazed_terracotta:0)
Block(1,13,0,LEAVES:4)
Block(1,13,1,BONE_BLOCK:0)
Block(1,13,2,minecraft:pink_glazed_terracotta:1)
Block(1,14,0,minecraft:black_glazed_terracotta:3)
Block(1,14,1,BONE_BLOCK:0)
Block(1,14,2,minecraft:pink_glazed_terracotta:1)
Block(1,15,0,minecraft:pink_glazed_terracotta)
Block(1,15,1,BONE_BLOCK:0)
Block(1,15,2,minecraft:pink_glazed_terracotta:1)
Block(1,16,0,minecraft:pink_glazed_terracotta:3)
Block(1,16,1,BONE_BLOCK:0)
Block(1,16,2,minecraft:red_glazed_terracotta:0)
Block(1,17,0,BONE_BLOCK:0)
Block(1,17,1,BONE_BLOCK:0)
Block(1,17,2,minecraft:red_glazed_terracotta:0)
Block(1,18,0,BONE_BLOCK:0)
Block(1,18,1,BONE_BLOCK:0)
Block(1,18,2,minecraft:black_glazed_terracotta:0)
Block(1,19,0,BONE_BLOCK:0)
Block(1,19,1,BONE_BLOCK:0)
Block(1,19,2,BONE_BLOCK:0)
Block(1,20,1,BONE_BLOCK:0)
Block(1,20,2,BONE_BLOCK:0)
Block(2,-5,1,BONE_BLOCK:0)
Block(2,-5,2,BONE_BLOCK:0)
Block(2,-5,3,BONE_BLOCK:0)
Block(2,-4,1,BONE_BLOCK:0)
Block(2,-4,2,BONE_BLOCK:0)
Block(2,-4,3,BONE_BLOCK:0)
Block(2,-3,1,minecraft:black_glazed_terracotta:3)
Block(2,-3,2,minecraft:black_glazed_terracotta:3)
Block(2,-3,3,BONE_BLOCK:0)
Block(2,-2,1,minecraft:red_glazed_terracotta)
Block(2,-2,2,BONE_BLOCK:0)
Block(2,-2,3,BONE_BLOCK:0)
Block(2,-1,1,minecraft:pink_glazed_terracotta:3)
Block(2,-1,2,BONE_BLOCK:0)
Block(2,-1,3,minecraft:black_glazed_terracotta:1)
Block(2,0,1,minecraft:pink_glazed_terracotta:3)
Block(2,0,2,BONE_BLOCK:0)
Block(2,0,3,minecraft:red_glazed_terracotta:1)
Block(2,1,1,minecraft:pink_glazed_terracotta)
Block(2,1,2,BONE_BLOCK:0)
Block(2,1,3,minecraft:red_glazed_terracotta:1)
Block(2,2,1,minecraft:pink_glazed_terracotta)
Block(2,2,2,BONE_BLOCK:0)
Block(2,2,3,minecraft:red_glazed_terracotta:1)
Block(2,3,1,minecraft:red_glazed_terracotta:3)
Block(2,3,2,BONE_BLOCK:0)
Block(2,3,3,BONE_BLOCK:0)
Block(2,4,1,minecraft:black_glazed_terracotta:3)
Block(2,4,2,BONE_BLOCK:0)
Block(2,5,1,BONE_BLOCK:0)
Block(2,5,2,BONE_BLOCK:0)
Block(2,6,1,BONE_BLOCK:0)
Block(2,6,2,BONE_BLOCK:0)
Block(2,6,3,BONE_BLOCK:0)
Block(2,7,1,BONE_BLOCK:0)
Block(2,7,2,BONE_BLOCK:0)
Block(2,7,3,BONE_BLOCK:0)
Block(2,8,1,LEAVES:4)
Block(2,8,2,BONE_BLOCK:0)
Block(2,8,3,BONE_BLOCK:0)
Block(2,9,1,BONE_BLOCK:0)
Block(2,9,2,BONE_BLOCK:0)
Block(2,10,1,minecraft:black_glazed_terracotta:3)
Block(2,10,2,BONE_BLOCK:0)
Block(2,10,3,BONE_BLOCK:0)
Block(2,11,1,minecraft:red_glazed_terracotta:3)
Block(2,11,2,BONE_BLOCK:0)
Block(2,11,3,BONE_BLOCK:0)
Block(2,12,1,LEAVES:4)
Block(2,12,2,BONE_BLOCK:0)
Block(2,12,3,BONE_BLOCK:0)
Block(2,13,1,minecraft:red_glazed_terracotta)
Block(2,13,2,BONE_BLOCK:0)
Block(2,13,3,minecraft:red_glazed_terracotta:0)
Block(2,14,1,minecraft:pink_glazed_terracotta:3)
Block(2,14,2,BONE_BLOCK:0)
Block(2,14,3,minecraft:pink_glazed_terracotta:1)
Block(2,15,1,minecraft:pink_glazed_terracotta:3)
Block(2,15,2,BONE_BLOCK:0)
Block(2,15,3,minecraft:pink_glazed_terracotta:1)
Block(2,16,1,minecraft:red_glazed_terracotta)
Block(2,16,2,BONE_BLOCK:0)
Block(2,16,3,minecraft:red_glazed_terracotta:1)
Block(2,17,1,minecraft:red_glazed_terracotta:3)
Block(2,17,2,LEAVES:4)
Block(2,18,1,minecraft:red_glazed_terracotta)
Block(2,18,2,BONE_BLOCK:0)
Block(2,19,1,BONE_BLOCK:0)
Block(2,19,2,BONE_BLOCK:0)
Block(2,19,3,minecraft:red_glazed_terracotta:1)
Block(2,20,1,BONE_BLOCK:0)
Block(2,20,2,BONE_BLOCK:0)
Block(2,20,3,BONE_BLOCK:0)
Block(2,21,2,BONE_BLOCK:0)
Block(2,21,3,BONE_BLOCK:0)
Block(2,22,3,BONE_BLOCK:0)
Block(3,-5,2,BONE_BLOCK:0)
Block(3,-5,3,BONE_BLOCK:0)
Block(3,-5,4,BONE_BLOCK:0)
Block(3,-4,2,BONE_BLOCK:0)
Block(3,-4,3,BONE_BLOCK:0)
Block(3,-4,4,BONE_BLOCK:0)
Block(3,-3,2,BONE_BLOCK:0)
Block(3,-3,3,BONE_BLOCK:0)
Block(3,-3,4,BONE_BLOCK:0)
Block(3,-2,2,BONE_BLOCK:0)
Block(3,-2,3,BONE_BLOCK:0)
Block(3,-2,4,BONE_BLOCK:0)
Block(3,-1,2,minecraft:red_glazed_terracotta:3)
Block(3,-1,3,BONE_BLOCK:0)
Block(3,-1,4,BONE_BLOCK:0)
Block(3,0,2,minecraft:red_glazed_terracotta:3)
Block(3,0,3,BONE_BLOCK:0)
Block(3,0,4,BONE_BLOCK:0)
Block(3,1,2,minecraft:red_glazed_terracotta)
Block(3,1,3,BONE_BLOCK:0)
Block(3,1,4,BONE_BLOCK:0)
Block(3,2,2,minecraft:red_glazed_terracotta)
Block(3,2,3,BONE_BLOCK:0)
Block(3,2,4,BONE_BLOCK:0)
Block(3,3,2,BONE_BLOCK:0)
Block(3,3,3,BONE_BLOCK:0)
Block(3,4,3,BONE_BLOCK:0)
Block(3,5,3,BONE_BLOCK:0)
Block(3,6,2,BONE_BLOCK:0)
Block(3,6,3,BONE_BLOCK:0)
Block(3,7,2,BONE_BLOCK:0)
Block(3,7,3,BONE_BLOCK:0)
Block(3,7,4,BONE_BLOCK:0)
Block(3,8,2,BONE_BLOCK:0)
Block(3,8,4,BONE_BLOCK:0)
Block(3,10,2,BONE_BLOCK:0)
Block(3,10,3,BONE_BLOCK:0)
Block(3,10,4,BONE_BLOCK:0)
Block(3,11,2,BONE_BLOCK:0)
Block(3,11,3,BONE_BLOCK:0)
Block(3,11,4,BONE_BLOCK:0)
Block(3,12,2,minecraft:red_glazed_terracotta)
Block(3,12,3,BONE_BLOCK:0)
Block(3,12,4,LEAVES:4)
Block(3,13,2,minecraft:pink_glazed_terracotta)
Block(3,13,3,BONE_BLOCK:0)
Block(3,13,4,BONE_BLOCK:0)
Block(3,14,2,minecraft:pink_glazed_terracotta)
Block(3,14,3,BONE_BLOCK:0)
Block(3,14,4,BONE_BLOCK:0)
Block(3,15,2,minecraft:red_glazed_terracotta:3)
Block(3,15,3,BONE_BLOCK:0)
Block(3,15,4,BONE_BLOCK:0)
Block(3,19,2,minecraft:black_glazed_terracotta:3)
Block(3,19,3,LEAVES:4)
Block(3,20,2,BONE_BLOCK:0)
Block(3,20,3,BONE_BLOCK:0)
Block(3,20,4,LEAVES:4)
Block(3,21,2,BONE_BLOCK:0)
Block(3,21,3,BONE_BLOCK:0)
Block(3,21,4,minecraft:black_glazed_terracotta:1)
Block(3,22,2,BONE_BLOCK:0)
Block(3,22,3,BONE_BLOCK:0)
Block(3,22,4,BONE_BLOCK:0)
Block(3,23,4,BONE_BLOCK:0)
Block(4,-5,3,BONE_BLOCK:0)
Block(4,-5,4,BONE_BLOCK:0)
Block(4,-4,3,BONE_BLOCK:0)
Block(4,-4,4,BONE_BLOCK:0)
Block(4,-3,3,BONE_BLOCK:0)
Block(4,-3,4,BONE_BLOCK:0)
Block(4,-2,3,minecraft:black_glazed_terracotta)
Block(4,-2,4,BONE_BLOCK:0)
Block(4,-1,3,minecraft:red_glazed_terracotta)
Block(4,-1,4,BONE_BLOCK:0)
Block(4,0,3,minecraft:red_glazed_terracotta)
Block(4,0,4,BONE_BLOCK:0)
Block(4,1,3,BONE_BLOCK:0)
Block(4,1,4,BONE_BLOCK:0)
Block(4,2,3,BONE_BLOCK:0)
Block(4,2,4,BONE_BLOCK:0)
Block(4,3,4,BONE_BLOCK:0)
Block(4,6,4,BONE_BLOCK:0)
Block(4,7,3,BONE_BLOCK:0)
Block(4,7,4,BONE_BLOCK:0)
Block(4,8,3,BONE_BLOCK:0)
Block(4,8,4,BONE_BLOCK:0)
Block(4,10,3,BONE_BLOCK:0)
Block(4,10,4,BONE_BLOCK:0)
Block(4,11,3,BONE_BLOCK:0)
Block(4,11,4,BONE_BLOCK:0)
Block(4,12,4,BONE_BLOCK:0)
Block(4,13,3,BONE_BLOCK:0)
Block(4,13,4,BONE_BLOCK:0)
Block(4,14,3,BONE_BLOCK:0)
Block(4,14,4,BONE_BLOCK:0)
Block(4,15,3,minecraft:red_glazed_terracotta)
Block(4,15,4,BONE_BLOCK:0)
Block(4,15,5,BONE_BLOCK:0)
Block(4,16,3,minecraft:black_glazed_terracotta)
Block(4,16,4,BONE_BLOCK:0)
Block(4,16,5,BONE_BLOCK:0)
Block(4,17,4,LEAVES:4)
Block(4,17,5,BONE_BLOCK:0)
Block(4,18,5,BONE_BLOCK:0)
Block(4,19,3,minecraft:red_glazed_terracotta)
Block(4,19,4,LEAVES:4)
Block(4,19,5,minecraft:red_glazed_terracotta:0)
Block(4,20,3,minecraft:red_glazed_terracotta)
Block(4,20,4,BONE_BLOCK:0)
Block(4,20,5,minecraft:red_glazed_terracotta:0)
Block(4,21,3,BONE_BLOCK:0)
Block(4,21,4,BONE_BLOCK:0)
Block(4,21,5,minecraft:red_glazed_terracotta:0)
Block(4,22,3,BONE_BLOCK:0)
Block(4,22,4,BONE_BLOCK:0)
Block(4,22,5,minecraft:red_glazed_terracotta:0)
Block(4,23,3,BONE_BLOCK:0)
Block(4,23,4,BONE_BLOCK:0)
Block(4,23,5,minecraft:red_glazed_terracotta:0)
Block(4,24,4,BONE_BLOCK:0)
Block(4,24,5,BONE_BLOCK:0)
Block(5,-5,5,BONE_BLOCK:0)
Block(5,-4,5,BONE_BLOCK:0)
Block(5,-3,5,BONE_BLOCK:0)
Block(5,-2,5,BONE_BLOCK:0)
Block(5,-1,5,BONE_BLOCK:0)
Block(5,0,5,BONE_BLOCK:0)
Block(5,1,5,BONE_BLOCK:0)
Block(5,2,5,BONE_BLOCK:0)
Block(5,7,5,BONE_BLOCK:0)
Block(5,8,5,BONE_BLOCK:0)
Block(5,10,5,BONE_BLOCK:0)
Block(5,11,5,BONE_BLOCK:0)
Block(5,13,5,BONE_BLOCK:0)
Block(5,14,5,BONE_BLOCK:0)
Block(5,15,4,BONE_BLOCK:0)
Block(5,15,5,BONE_BLOCK:0)
Block(5,15,6,BONE_BLOCK:0)
Block(5,16,4,BONE_BLOCK:0)
Block(5,16,5,BONE_BLOCK:0)
Block(5,16,6,BONE_BLOCK:0)
Block(5,17,4,BONE_BLOCK:0)
Block(5,17,5,BONE_BLOCK:0)
Block(5,18,4,LEAVES:4)
Block(5,18,5,BONE_BLOCK:0)
Block(5,19,4,BONE_BLOCK:0)
Block(5,19,5,BONE_BLOCK:0)
Block(5,19,6,BONE_BLOCK:0)
Block(5,20,4,minecraft:red_glazed_terracotta)
Block(5,20,5,BONE_BLOCK:0)
Block(5,20,6,BONE_BLOCK:0)
Block(5,21,4,minecraft:black_glazed_terracotta)
Block(5,21,5,BONE_BLOCK:0)
Block(5,21,6,BONE_BLOCK:0)
Block(5,22,4,minecraft:pink_glazed_terracotta)
Block(5,22,5,BONE_BLOCK:0)
Block(5,22,6,minecraft:black_glazed_terracotta:1)
Block(5,23,4,BONE_BLOCK:0)
Block(5,23,5,BONE_BLOCK:0)
Block(5,23,6,minecraft:pink_glazed_terracotta:0)
Block(5,24,4,BONE_BLOCK:0)
Block(5,24,5,BONE_BLOCK:0)
Block(5,24,6,minecraft:pink_glazed_terracotta:0)
Block(5,25,5,BONE_BLOCK:0)
Block(5,25,6,BONE_BLOCK:0)
Block(6,15,5,BONE_BLOCK:0)
Block(6,15,6,BONE_BLOCK:0)
Block(6,16,5,BONE_BLOCK:0)
Block(6,16,6,BONE_BLOCK:0)
Block(6,17,5,LEAVES:4)
Block(6,17,6,BONE_BLOCK:0)
Block(6,18,5,LEAVES:4)
Block(6,18,6,BONE_BLOCK:0)
Block(6,18,7,BONE_BLOCK:0)
Block(6,19,5,BONE_BLOCK:0)
Block(6,19,6,BONE_BLOCK:0)
Block(6,19,7,BONE_BLOCK:0)
Block(6,20,5,BONE_BLOCK:0)
Block(6,20,6,BONE_BLOCK:0)
Block(6,21,5,LEAVES:4)
Block(6,21,6,BONE_BLOCK:0)
Block(6,21,7,BONE_BLOCK:0)
Block(6,22,5,minecraft:pink_glazed_terracotta)
Block(6,22,6,BONE_BLOCK:0)
Block(6,22,7,BONE_BLOCK:0)
Block(6,23,5,minecraft:pink_glazed_terracotta)
Block(6,23,6,BONE_BLOCK:0)
Block(6,23,7,BONE_BLOCK:0)
Block(6,24,5,BONE_BLOCK:0)
Block(6,24,6,BONE_BLOCK:0)
Block(6,24,7,minecraft:pink_glazed_terracotta:1)
Block(6,25,5,BONE_BLOCK:0)
Block(6,25,6,minecraft:pink_glazed_terracotta:0)
Block(6,25,7,minecraft:pink_glazed_terracotta:0)
Block(6,26,6,BONE_BLOCK:0)
Block(6,26,7,BONE_BLOCK:0)
Block(7,15,7,BONE_BLOCK:0)
Block(7,16,7,BONE_BLOCK:0)
Block(7,18,6,BONE_BLOCK:0)
Block(7,19,6,BONE_BLOCK:0)
Block(7,19,7,BONE_BLOCK:0)
Block(7,20,7,BONE_BLOCK:0)
Block(7,21,6,BONE_BLOCK:0)
Block(7,21,7,BONE_BLOCK:0)
Block(7,21,8,BONE_BLOCK:0)
Block(7,22,6,LEAVES:4)
Block(7,22,7,BONE_BLOCK:0)
Block(7,22,8,BONE_BLOCK:0)
Block(7,23,6,minecraft:red_glazed_terracotta)
Block(7,23,7,BONE_BLOCK:0)
Block(7,24,6,minecraft:black_glazed_terracotta)
Block(7,24,7,BONE_BLOCK:0)
Block(7,24,8,BONE_BLOCK:0)
Block(7,25,6,BONE_BLOCK:0)
Block(7,25,7,BONE_BLOCK:0)
Block(7,25,8,minecraft:pink_glazed_terracotta:1)
Block(7,26,6,BONE_BLOCK:0)
Block(7,26,7,BONE_BLOCK:8)
Block(7,26,8,minecraft:black_glazed_terracotta:1)
Block(7,27,7,BONE_BLOCK:0)
Block(7,27,8,BONE_BLOCK:0)
Block(8,18,8,BONE_BLOCK:0)
Block(8,19,8,BONE_BLOCK:0)
Block(8,21,7,BONE_BLOCK:0)
Block(8,21,8,BONE_BLOCK:0)
Block(8,22,7,BONE_BLOCK:0)
Block(8,22,8,BONE_BLOCK:0)
Block(8,23,7,LEAVES:4)
Block(8,23,8,BONE_BLOCK:0)
Block(8,24,7,BONE_BLOCK:0)
Block(8,24,8,BONE_BLOCK:0)
Block(8,24,9,BONE_BLOCK:0)
Block(8,25,7,minecraft:red_glazed_terracotta:3)
Block(8,25,8,BONE_BLOCK:0)
Block(8,25,9,BONE_BLOCK:0)
Block(8,26,7,BONE_BLOCK:0)
Block(8,26,8,BONE_BLOCK:0)
Block(8,26,9,minecraft:red_glazed_terracotta:1)
Block(8,27,7,BONE_BLOCK:0)
Block(8,27,8,BONE_BLOCK:8)
Block(8,27,9,minecraft:red_glazed_terracotta:1)
Block(8,28,8,BONE_BLOCK:8)
Block(8,28,9,BONE_BLOCK:0)
Block(9,21,9,BONE_BLOCK:0)
Block(9,22,9,BONE_BLOCK:0)
Block(9,24,8,BONE_BLOCK:0)
Block(9,24,9,BONE_BLOCK:0)
Block(9,25,8,LEAVES:4)
Block(9,25,9,BONE_BLOCK:0)
Block(9,25,10,LEAVES:4)
Block(9,26,8,minecraft:black_glazed_terracotta)
Block(9,26,9,BONE_BLOCK:0)
Block(9,26,10,LEAVES:12)
Block(9,27,8,BONE_BLOCK:0)
Block(9,27,9,BONE_BLOCK:0)
Block(9,27,10,minecraft:black_glazed_terracotta:1)
Block(9,28,8,BONE_BLOCK:0)
Block(9,28,9,BONE_BLOCK:0)
Block(9,28,10,BONE_BLOCK:0)
Block(9,29,9,BONE_BLOCK:0)
Block(9,29,10,BONE_BLOCK:0)
Block(10,24,10,BONE_BLOCK:0)
Block(10,25,10,BONE_BLOCK:0)
Block(10,26,10,BONE_BLOCK:0)
Block(10,26,11,BONE_BLOCK:0)
Block(10,27,9,BONE_BLOCK:0)
Block(10,27,10,BONE_BLOCK:0)
Block(10,27,11,BONE_BLOCK:0)
Block(10,28,9,BONE_BLOCK:0)
Block(10,28,10,BONE_BLOCK:0)
Block(10,28,11,minecraft:red_glazed_terracotta:0)
Block(10,29,9,BONE_BLOCK:0)
Block(10,29,10,BONE_BLOCK:0)
Block(10,29,11,BONE_BLOCK:0)
Block(10,30,10,BONE_BLOCK:0)
Block(11,26,10,BONE_BLOCK:0)
Block(11,27,10,BONE_BLOCK:0)
Block(11,27,11,BONE_BLOCK:0)
Block(11,27,12,BONE_BLOCK:0)
Block(11,28,10,BONE_BLOCK:0)
Block(11,28,11,BONE_BLOCK:0)
Block(11,28,12,BONE_BLOCK:0)
Block(11,29,10,BONE_BLOCK:0)
Block(11,29,11,BONE_BLOCK:0)
Block(11,29,12,BONE_BLOCK:0)
Block(11,30,11,BONE_BLOCK:8)
Block(11,30,12,BONE_BLOCK:0)
Block(12,26,12,BONE_BLOCK:0)
Block(12,27,11,BONE_BLOCK:0)
Block(12,27,12,BONE_BLOCK:0)
Block(12,28,11,BONE_BLOCK:0)
Block(12,28,12,BONE_BLOCK:0)
Block(12,29,11,BONE_BLOCK:0)
Block(12,29,12,BONE_BLOCK:0)
Block(12,29,13,BONE_BLOCK:0)
Block(12,30,11,BONE_BLOCK:0)
Block(12,30,12,BONE_BLOCK:0)
Block(12,30,13,BONE_BLOCK:0)
Block(12,31,12,BONE_BLOCK:0)
Block(13,27,13,BONE_BLOCK:0)
Block(13,28,13,BONE_BLOCK:0)
Block(13,29,12,BONE_BLOCK:0)
Block(13,29,13,BONE_BLOCK:0)
Block(13,30,12,BONE_BLOCK:0)
Block(13,30,13,BONE_BLOCK:0)
Block(13,31,13,BONE_BLOCK:4)
Block(13,31,14,BONE_BLOCK:8)
Block(14,29,14,BONE_BLOCK:0)
Block(14,30,14,BONE_BLOCK:0)
Block(14,31,13,BONE_BLOCK:8)
Block(14,31,14,BONE_BLOCK:0)
Block(14,32,14,BONE_BLOCK:0)
Block(15,31,15,BONE_BLOCK:8)
Block(15,32,15,BONE_BLOCK:0)

#######################################################################
# +-----------------------------------------------------------------+ #
# |                            BO3 checks                           | #
# +-----------------------------------------------------------------+ #
#######################################################################

BlockCheck(-5,-6,-4,Solid)
BlockCheck(-4,-6,-5,Solid)
BlockCheck(-4,-6,-3,Solid)
BlockCheck(-3,-6,-4,Solid)
BlockCheck(-3,-6,-2,Solid)
BlockCheck(-2,-6,-3,Solid)
BlockCheck(-2,-6,-1,Solid)
BlockCheck(-1,-6,-2,Solid)
BlockCheck(-1,-6,0,Solid)
BlockCheck(0,-6,-1,Solid)
BlockCheck(0,-6,1,Solid)
BlockCheck(1,-6,0,Solid)
BlockCheck(1,-6,2,Solid)
BlockCheck(2,-6,1,Solid)
BlockCheck(2,-6,3,Solid)
BlockCheck(3,-6,2,Solid)
BlockCheck(3,-6,4,Solid)
BlockCheck(4,-6,3,Solid)
BlockCheck(4,-6,4,Solid)
BlockCheck(5,-6,5,Solid)

#######################################################################
# +-----------------------------------------------------------------+ #
# |                             Branches                            | #
# +-----------------------------------------------------------------+ #
#######################################################################


#######################################################################
# +-----------------------------------------------------------------+ #
# |                             Entities                            | #
# +-----------------------------------------------------------------+ #
#######################################################################


#######################################################################
# +-----------------------------------------------------------------+ #
# |                            Particles                            | #
# +-----------------------------------------------------------------+ #
#######################################################################


#######################################################################
# +-----------------------------------------------------------------+ #
# |                             Spawners                            | #
# +-----------------------------------------------------------------+ #
#######################################################################


#######################################################################
# +-----------------------------------------------------------------+ #
# |                             ModData                             | #
# +-----------------------------------------------------------------+ #
#######################################################################

