#######################################################################
# +-----------------------------------------------------------------+ #
# |                            BO3 object                           | #
# +-----------------------------------------------------------------+ #
#######################################################################

Author: Bo3 BulkEdit

Description: Converted Schematic - Modified by Bo3BulkEdit

Version: 3

SettingsMode: WriteDisable

#######################################################################
# +-----------------------------------------------------------------+ #
# |                          Main settings                          | #
# +-----------------------------------------------------------------+ #
#######################################################################



Frequency: 0


SpawnHeight: randomY





##############################
# Height Limits for the BO3. #
##############################

MinHeight: 0
MaxHeight: 256

#######################################################################
# +-----------------------------------------------------------------+ #
# |                      Source block settings                      | #
# +-----------------------------------------------------------------+ #
#######################################################################

CanOverride: true
MaxPercentageOutsideSourceBlock: 100
OutsideSourceBlock: placeAnyway

#######################################################################
# +-----------------------------------------------------------------+ #
# |                               OTG+                              | #
# +-----------------------------------------------------------------+ #
#######################################################################

#######################################################################
# +-----------------------------------------------------------------+ #
# |                              Blocks                             | #
# +-----------------------------------------------------------------+ #
#######################################################################

B(0,750,0,AIR)
B(15,750,15,AIR)
B(15,1,3,betternether:quartz_stained_glass:15)
B(15,2,2,betternether:quartz_stained_glass:15)
B(15,2,3,betternether:quartz_stained_glass:15)
B(15,3,1,betternether:quartz_stained_glass:15)
B(14,3,2,betternether:quartz_stained_glass:15)
B(15,3,2,betternether:quartz_stained_glass:15)
B(15,3,3,betternether:quartz_stained_glass:15)
B(15,4,0,betternether:quartz_stained_glass:15)
B(14,4,1,betternether:quartz_stained_glass:15)
B(15,4,1,betternether:quartz_stained_glass:15)
B(14,4,2,betternether:quartz_stained_glass:15)
B(15,4,2,betternether:quartz_stained_glass:15)
B(15,4,3,betternether:quartz_stained_glass:15)
B(15,4,4,betternether:quartz_stained_glass:15)
B(14,5,0,betternether:quartz_stained_glass:15)
B(15,5,0,betternether:quartz_stained_glass:15)
B(13,5,1,betternether:quartz_stained_glass:15)
B(14,5,1,betternether:quartz_stained_glass:15)
B(15,5,1,betternether:quartz_stained_glass:15)
B(14,5,2,betternether:quartz_stained_glass:15)
B(15,5,2,betternether:quartz_stained_glass:15)
B(15,5,3,betternether:quartz_stained_glass:15)
B(15,5,4,betternether:quartz_stained_glass:15)
B(13,6,0,betternether:quartz_stained_glass:15)
B(14,6,0,betternether:quartz_stained_glass:15)
B(15,6,0,betternether:quartz_stained_glass:15)
B(13,6,1,betternether:quartz_stained_glass:15)
B(14,6,1,betternether:quartz_stained_glass:15)
B(15,6,1,betternether:quartz_stained_glass:15)
B(14,6,2,betternether:quartz_stained_glass:15)
B(15,6,2,betternether:quartz_stained_glass:15)
B(14,6,3,betternether:quartz_stained_glass:15)
B(15,6,3,betternether:quartz_stained_glass:15)
B(15,6,4,betternether:quartz_stained_glass:15)
B(12,7,0,betternether:quartz_stained_glass:15)
B(13,7,0,betternether:quartz_stained_glass:15)
B(14,7,0,betternether:quartz_stained_glass:15)
RB(15,7,0,srparasites:parasitestain:1,80,quark:crystal:1,30,srparasites:parasiterubbledense:1,100)
B(13,7,1,betternether:quartz_stained_glass:15)
B(14,7,1,betternether:quartz_stained_glass:15)
B(15,7,1,betternether:quartz_stained_glass:15)
B(14,7,2,betternether:quartz_stained_glass:15)
B(15,7,2,betternether:quartz_stained_glass:15)
B(14,7,3,betternether:quartz_stained_glass:15)
B(15,7,3,betternether:quartz_stained_glass:15)
B(12,8,0,betternether:quartz_stained_glass:15)
B(13,8,0,betternether:quartz_stained_glass:15)
B(14,8,0,betternether:quartz_stained_glass:15)
RB(15,8,0,srparasites:parasitestain:1,80,quark:crystal:1,30,srparasites:parasiterubbledense:1,100)
B(13,8,1,betternether:quartz_stained_glass:15)
B(14,8,1,betternether:quartz_stained_glass:15)
B(15,8,1,betternether:quartz_stained_glass:15)
B(13,8,2,betternether:quartz_stained_glass:15)
B(14,8,2,betternether:quartz_stained_glass:15)
B(15,8,2,srparasites:parasiterubbledense:1)
B(14,8,3,betternether:quartz_stained_glass:15)
B(15,8,3,betternether:quartz_stained_glass:15)
B(12,9,0,betternether:quartz_stained_glass:15)
B(13,9,0,betternether:quartz_stained_glass:15)
B(14,9,0,betternether:quartz_stained_glass:15)
RB(15,9,0,srparasites:parasitestain:1,80,quark:crystal:1,30,srparasites:parasiterubbledense:1,100)
B(13,9,1,betternether:quartz_stained_glass:15)
B(14,9,1,betternether:quartz_stained_glass:15)
B(15,9,1,srparasites:parasiterubbledense:1)
B(13,9,2,betternether:quartz_stained_glass:15)
B(14,9,2,betternether:quartz_stained_glass:15)
B(15,9,2,srparasites:parasiterubbledense:1)
B(15,9,3,betternether:quartz_stained_glass:15)
B(12,10,0,betternether:quartz_stained_glass:15)
B(13,10,0,betternether:quartz_stained_glass:15)
B(14,10,0,betternether:quartz_stained_glass:15)
B(15,10,0,betternether:quartz_stained_glass:15)
B(12,10,1,betternether:quartz_stained_glass:15)
B(13,10,1,betternether:quartz_stained_glass:15)
B(14,10,1,srparasites:parasiterubbledense:1)
B(15,10,1,srparasites:parasiterubbledense:1)
B(13,10,2,betternether:quartz_stained_glass:15)
B(14,10,2,betternether:quartz_stained_glass:15)
B(15,10,2,betternether:quartz_stained_glass:15)
B(12,11,0,betternether:quartz_stained_glass:15)
B(13,11,0,betternether:quartz_stained_glass:15)
B(14,11,0,srparasites:parasiterubbledense:1)
B(15,11,0,betternether:quartz_stained_glass:15)
B(12,11,1,betternether:quartz_stained_glass:15)
B(13,11,1,betternether:quartz_stained_glass:15)
B(14,11,1,srparasites:parasiterubbledense:1)
B(15,11,1,betternether:quartz_stained_glass:15)
B(14,11,2,betternether:quartz_stained_glass:15)
B(11,12,0,betternether:quartz_stained_glass:15)
B(12,12,0,betternether:quartz_stained_glass:15)
B(13,12,0,betternether:quartz_stained_glass:15)
B(14,12,0,betternether:quartz_stained_glass:15)
B(15,12,0,betternether:quartz_stained_glass:15)
B(12,12,1,betternether:quartz_stained_glass:15)
B(13,12,1,betternether:quartz_stained_glass:15)
B(14,12,1,betternether:quartz_stained_glass:15)
B(11,13,0,betternether:quartz_stained_glass:15)
B(12,13,0,betternether:quartz_stained_glass:15)
B(13,13,0,betternether:quartz_stained_glass:15)
B(14,13,0,betternether:quartz_stained_glass:15)
B(15,13,0,betternether:quartz_stained_glass:15)
B(13,13,1,betternether:quartz_stained_glass:15)
B(11,14,0,betternether:quartz_stained_glass:15)
B(12,14,0,betternether:quartz_stained_glass:15)
B(13,14,0,betternether:quartz_stained_glass:15)
B(12,15,0,betternether:quartz_stained_glass:15)

