#######################################################################
# +-----------------------------------------------------------------+ #
# |                            BO3 object                           | #
# +-----------------------------------------------------------------+ #
#######################################################################

Author: Bo3 BulkEdit

Description: Converted Schematic - Modified by Bo3BulkEdit

Version: 3

SettingsMode: WriteDisable

#######################################################################
# +-----------------------------------------------------------------+ #
# |                          Main settings                          | #
# +-----------------------------------------------------------------+ #
#######################################################################

IsOTGPlus: true
Tree: false
Frequency: 1
Rarity: 100.0
RotateRandomly: false
SpawnHeight: randomY
MaxBranchDepth: 10
ExcludedBiomes: All

##############################
# Height Limits for the BO3. #
##############################

MinHeight: 0
MaxHeight: 255

#######################################################################
# +-----------------------------------------------------------------+ #
# |                      Source block settings                      | #
# +-----------------------------------------------------------------+ #
#######################################################################

CanOverride: true
MaxPercentageOutsideSourceBlock: 100
OutsideSourceBlock: placeAnyway

#######################################################################
# +-----------------------------------------------------------------+ #
# |                               OTG+                              | #
# +-----------------------------------------------------------------+ #
#######################################################################

BO3Group: CeilingCrystals:0

#######################################################################
# +-----------------------------------------------------------------+ #
# |                              Blocks                             | #
# +-----------------------------------------------------------------+ #
#######################################################################

B(0,750,0,AIR)
B(15,750,15,AIR)
B(6,-10,15,betternether:quartz_stained_glass:15)
B(7,-10,15,betternether:quartz_stained_glass:15)
B(8,-10,15,betternether:quartz_stained_glass:15)
B(4,-9,14,betternether:quartz_stained_glass:15)
B(5,-9,14,betternether:quartz_stained_glass:15)
B(6,-9,14,betternether:quartz_stained_glass:15)
B(7,-9,14,betternether:quartz_stained_glass:15)
B(8,-9,14,betternether:quartz_stained_glass:15)
B(4,-9,15,betternether:quartz_stained_glass:15)
B(5,-9,15,betternether:quartz_stained_glass:15)
B(6,-9,15,betternether:quartz_stained_glass:15)
B(7,-9,15,betternether:quartz_stained_glass:15)
B(8,-9,15,betternether:quartz_stained_glass:15)
B(5,-8,12,betternether:quartz_stained_glass:15)
B(7,-8,12,betternether:quartz_stained_glass:15)
B(4,-8,13,betternether:quartz_stained_glass:15)
B(5,-8,13,betternether:quartz_stained_glass:15)
B(6,-8,13,betternether:quartz_stained_glass:15)
B(7,-8,13,betternether:quartz_stained_glass:15)
B(3,-8,14,betternether:quartz_stained_glass:15)
B(4,-8,14,betternether:quartz_stained_glass:15)
B(5,-8,14,betternether:quartz_stained_glass:15)
B(6,-8,14,betternether:quartz_stained_glass:15)
B(7,-8,14,betternether:quartz_stained_glass:15)
B(8,-8,14,betternether:quartz_stained_glass:15)
B(4,-8,15,betternether:quartz_stained_glass:15)
B(5,-8,15,betternether:quartz_stained_glass:15)
RB(6,-8,15,srparasites:parasitestain:1,80,quark:crystal:1,30,srparasites:parasiterubbledense:1,100)
B(7,-8,15,betternether:quartz_stained_glass:15)
B(8,-8,15,betternether:quartz_stained_glass:15)
B(5,-7,11,betternether:quartz_stained_glass:15)
B(6,-7,11,betternether:quartz_stained_glass:15)
B(7,-7,11,betternether:quartz_stained_glass:15)
B(3,-7,12,betternether:quartz_stained_glass:15)
B(4,-7,12,betternether:quartz_stained_glass:15)
B(5,-7,12,betternether:quartz_stained_glass:15)
B(6,-7,12,betternether:quartz_stained_glass:15)
B(7,-7,12,betternether:quartz_stained_glass:15)
B(3,-7,13,betternether:quartz_stained_glass:15)
B(4,-7,13,betternether:quartz_stained_glass:15)
B(5,-7,13,betternether:quartz_stained_glass:15)
B(6,-7,13,betternether:quartz_stained_glass:15)
B(7,-7,13,betternether:quartz_stained_glass:15)
B(3,-7,14,betternether:quartz_stained_glass:15)
B(4,-7,14,betternether:quartz_stained_glass:15)
RB(5,-7,14,srparasites:parasitestain:1,80,quark:crystal:1,30,srparasites:parasiterubbledense:1,100)
RB(6,-7,14,srparasites:parasitestain:1,80,quark:crystal:1,30,srparasites:parasiterubbledense:1,100)
B(7,-7,14,betternether:quartz_stained_glass:15)
B(8,-7,14,betternether:quartz_stained_glass:15)
B(4,-7,15,betternether:quartz_stained_glass:15)
RB(5,-7,15,srparasites:parasitestain:1,80,quark:crystal:1,30,srparasites:parasiterubbledense:1,100)
RB(6,-7,15,srparasites:parasitestain:1,80,quark:crystal:1,30,srparasites:parasiterubbledense:1,100)
B(7,-7,15,betternether:quartz_stained_glass:15)
B(8,-7,15,betternether:quartz_stained_glass:15)
B(3,-6,10,betternether:quartz_stained_glass:15)
B(4,-6,10,betternether:quartz_stained_glass:15)
B(5,-6,10,betternether:quartz_stained_glass:15)
B(6,-6,10,betternether:quartz_stained_glass:15)
B(7,-6,10,betternether:quartz_stained_glass:15)
B(3,-6,11,betternether:quartz_stained_glass:15)
B(4,-6,11,betternether:quartz_stained_glass:15)
B(5,-6,11,betternether:quartz_stained_glass:15)
B(6,-6,11,betternether:quartz_stained_glass:15)
B(7,-6,11,betternether:quartz_stained_glass:15)
B(3,-6,12,betternether:quartz_stained_glass:15)
B(4,-6,12,betternether:quartz_stained_glass:15)
RB(5,-6,12,srparasites:parasitestain:1,80,quark:crystal:1,30,srparasites:parasiterubbledense:1,100)
B(6,-6,12,betternether:quartz_stained_glass:15)
B(7,-6,12,betternether:quartz_stained_glass:15)
B(3,-6,13,betternether:quartz_stained_glass:15)
B(4,-6,13,betternether:quartz_stained_glass:15)
RB(5,-6,13,srparasites:parasitestain:1,80,quark:crystal:1,30,srparasites:parasiterubbledense:1,100)
RB(6,-6,13,srparasites:parasitestain:1,80,quark:crystal:1,30,srparasites:parasiterubbledense:1,100)
B(7,-6,13,betternether:quartz_stained_glass:15)
B(3,-6,14,betternether:quartz_stained_glass:15)
B(4,-6,14,betternether:quartz_stained_glass:15)
RB(5,-6,14,srparasites:parasitestain:1,80,quark:crystal:1,30,srparasites:parasiterubbledense:1,100)
RB(6,-6,14,srparasites:parasitestain:1,80,quark:crystal:1,30,srparasites:parasiterubbledense:1,100)
B(7,-6,14,betternether:quartz_stained_glass:15)
B(8,-6,14,betternether:quartz_stained_glass:15)
B(4,-6,15,betternether:quartz_stained_glass:15)
B(5,-6,15,betternether:quartz_stained_glass:15)
B(6,-6,15,betternether:quartz_stained_glass:15)
B(7,-6,15,betternether:quartz_stained_glass:15)
B(8,-6,15,betternether:quartz_stained_glass:15)
B(4,-5,8,betternether:quartz_stained_glass:15)
B(5,-5,8,betternether:quartz_stained_glass:15)
B(6,-5,8,betternether:quartz_stained_glass:15)
B(3,-5,9,betternether:quartz_stained_glass:15)
B(4,-5,9,betternether:quartz_stained_glass:15)
B(5,-5,9,betternether:quartz_stained_glass:15)
B(6,-5,9,betternether:quartz_stained_glass:15)
B(2,-5,10,betternether:quartz_stained_glass:15)
B(3,-5,10,betternether:quartz_stained_glass:15)
B(4,-5,10,betternether:quartz_stained_glass:15)
B(5,-5,10,betternether:quartz_stained_glass:15)
B(6,-5,10,betternether:quartz_stained_glass:15)
B(7,-5,10,betternether:quartz_stained_glass:15)
B(3,-5,11,betternether:quartz_stained_glass:15)
B(4,-5,11,betternether:quartz_stained_glass:15)
B(5,-5,11,betternether:quartz_stained_glass:15)
B(6,-5,11,betternether:quartz_stained_glass:15)
B(7,-5,11,betternether:quartz_stained_glass:15)
B(3,-5,12,betternether:quartz_stained_glass:15)
RB(4,-5,12,srparasites:parasitestain:1,80,quark:crystal:1,30,srparasites:parasiterubbledense:1,100)
RB(5,-5,12,srparasites:parasitestain:1,80,quark:crystal:1,30,srparasites:parasiterubbledense:1,100)
RB(6,-5,12,srparasites:parasitestain:1,80,quark:crystal:1,30,srparasites:parasiterubbledense:1,100)
B(7,-5,12,betternether:quartz_stained_glass:15)
B(3,-5,13,betternether:quartz_stained_glass:15)
B(4,-5,13,betternether:quartz_stained_glass:15)
RB(5,-5,13,srparasites:parasitestain:1,80,quark:crystal:1,30,srparasites:parasiterubbledense:1,100)
B(6,-5,13,betternether:quartz_stained_glass:15)
B(7,-5,13,betternether:quartz_stained_glass:15)
B(3,-5,14,betternether:quartz_stained_glass:15)
B(4,-5,14,betternether:quartz_stained_glass:15)
B(5,-5,14,betternether:quartz_stained_glass:15)
B(6,-5,14,betternether:quartz_stained_glass:15)
B(7,-5,14,betternether:quartz_stained_glass:15)
B(8,-5,14,betternether:quartz_stained_glass:15)
B(4,-5,15,betternether:quartz_stained_glass:15)
B(5,-5,15,betternether:quartz_stained_glass:15)
B(6,-5,15,betternether:quartz_stained_glass:15)
B(7,-5,15,betternether:quartz_stained_glass:15)
B(4,-4,7,betternether:quartz_stained_glass:15)
B(5,-4,7,betternether:quartz_stained_glass:15)
B(6,-4,7,betternether:quartz_stained_glass:15)
B(2,-4,8,betternether:quartz_stained_glass:15)
B(3,-4,8,betternether:quartz_stained_glass:15)
B(4,-4,8,betternether:quartz_stained_glass:15)
B(5,-4,8,betternether:quartz_stained_glass:15)
B(6,-4,8,betternether:quartz_stained_glass:15)
B(2,-4,9,betternether:quartz_stained_glass:15)
B(3,-4,9,betternether:quartz_stained_glass:15)
B(4,-4,9,betternether:quartz_stained_glass:15)
B(5,-4,9,betternether:quartz_stained_glass:15)
B(6,-4,9,betternether:quartz_stained_glass:15)
B(2,-4,10,betternether:quartz_stained_glass:15)
B(3,-4,10,betternether:quartz_stained_glass:15)
B(4,-4,10,betternether:quartz_stained_glass:15)
B(5,-4,10,betternether:quartz_stained_glass:15)
B(6,-4,10,betternether:quartz_stained_glass:15)
B(7,-4,10,betternether:quartz_stained_glass:15)
B(3,-4,11,betternether:quartz_stained_glass:15)
B(4,-4,11,betternether:quartz_stained_glass:15)
RB(5,-4,11,srparasites:parasitestain:1,80,quark:crystal:1,30,srparasites:parasiterubbledense:1,100)
B(6,-4,11,betternether:quartz_stained_glass:15)
B(7,-4,11,betternether:quartz_stained_glass:15)
B(3,-4,12,betternether:quartz_stained_glass:15)
B(4,-4,12,betternether:quartz_stained_glass:15)
B(5,-4,12,betternether:quartz_stained_glass:15)
B(6,-4,12,betternether:quartz_stained_glass:15)
B(7,-4,12,betternether:quartz_stained_glass:15)
B(3,-4,13,betternether:quartz_stained_glass:15)
B(4,-4,13,betternether:quartz_stained_glass:15)
B(5,-4,13,betternether:quartz_stained_glass:15)
B(6,-4,13,betternether:quartz_stained_glass:15)
B(7,-4,13,betternether:quartz_stained_glass:15)
B(3,-4,14,betternether:quartz_stained_glass:15)
B(4,-4,14,betternether:quartz_stained_glass:15)
B(5,-4,14,betternether:quartz_stained_glass:15)
B(6,-4,14,betternether:quartz_stained_glass:15)
B(7,-4,14,betternether:quartz_stained_glass:15)
B(5,-4,15,betternether:quartz_stained_glass:15)
B(2,-3,6,betternether:quartz_stained_glass:15)
B(3,-3,6,betternether:quartz_stained_glass:15)
B(4,-3,6,betternether:quartz_stained_glass:15)
B(5,-3,6,betternether:quartz_stained_glass:15)
B(6,-3,6,betternether:quartz_stained_glass:15)
B(1,-3,7,betternether:quartz_stained_glass:15)
B(2,-3,7,betternether:quartz_stained_glass:15)
B(3,-3,7,betternether:quartz_stained_glass:15)
B(4,-3,7,betternether:quartz_stained_glass:15)
B(5,-3,7,betternether:quartz_stained_glass:15)
B(6,-3,7,betternether:quartz_stained_glass:15)
B(2,-3,8,betternether:quartz_stained_glass:15)
B(3,-3,8,betternether:quartz_stained_glass:15)
RB(4,-3,8,srparasites:parasitestain:1,80,quark:crystal:1,30,srparasites:parasiterubbledense:1,100)
B(5,-3,8,betternether:quartz_stained_glass:15)
B(6,-3,8,betternether:quartz_stained_glass:15)
B(2,-3,9,betternether:quartz_stained_glass:15)
B(3,-3,9,betternether:quartz_stained_glass:15)
RB(4,-3,9,srparasites:parasitestain:1,80,quark:crystal:1,30,srparasites:parasiterubbledense:1,100)
RB(5,-3,9,srparasites:parasitestain:1,80,quark:crystal:1,30,srparasites:parasiterubbledense:1,100)
B(6,-3,9,betternether:quartz_stained_glass:15)
B(2,-3,10,betternether:quartz_stained_glass:15)
B(3,-3,10,betternether:quartz_stained_glass:15)
RB(4,-3,10,srparasites:parasitestain:1,80,quark:crystal:1,30,srparasites:parasiterubbledense:1,100)
B(5,-3,10,betternether:quartz_stained_glass:15)
B(6,-3,10,betternether:quartz_stained_glass:15)
B(7,-3,10,betternether:quartz_stained_glass:15)
B(3,-3,11,betternether:quartz_stained_glass:15)
B(4,-3,11,betternether:quartz_stained_glass:15)
B(5,-3,11,betternether:quartz_stained_glass:15)
B(6,-3,11,betternether:quartz_stained_glass:15)
B(7,-3,11,betternether:quartz_stained_glass:15)
B(3,-3,12,betternether:quartz_stained_glass:15)
B(4,-3,12,betternether:quartz_stained_glass:15)
B(5,-3,12,betternether:quartz_stained_glass:15)
B(6,-3,12,betternether:quartz_stained_glass:15)
B(7,-3,12,betternether:quartz_stained_glass:15)
B(3,-3,13,betternether:quartz_stained_glass:15)
B(4,-3,13,betternether:quartz_stained_glass:15)
B(5,-3,13,betternether:quartz_stained_glass:15)
B(6,-3,13,betternether:quartz_stained_glass:15)
B(3,-2,4,betternether:quartz_stained_glass:15)
B(4,-2,4,betternether:quartz_stained_glass:15)
B(5,-2,4,betternether:quartz_stained_glass:15)
B(1,-2,5,betternether:quartz_stained_glass:15)
B(2,-2,5,betternether:quartz_stained_glass:15)
B(3,-2,5,betternether:quartz_stained_glass:15)
B(4,-2,5,betternether:quartz_stained_glass:15)
B(5,-2,5,betternether:quartz_stained_glass:15)
B(1,-2,6,betternether:quartz_stained_glass:15)
B(2,-2,6,betternether:quartz_stained_glass:15)
B(3,-2,6,betternether:quartz_stained_glass:15)
B(4,-2,6,betternether:quartz_stained_glass:15)
B(5,-2,6,betternether:quartz_stained_glass:15)
B(6,-2,6,betternether:quartz_stained_glass:15)
B(1,-2,7,betternether:quartz_stained_glass:15)
B(2,-2,7,betternether:quartz_stained_glass:15)
B(3,-2,7,betternether:quartz_stained_glass:15)
RB(4,-2,7,srparasites:parasitestain:1,80,quark:crystal:1,30,srparasites:parasiterubbledense:1,100)
B(5,-2,7,betternether:quartz_stained_glass:15)
B(6,-2,7,betternether:quartz_stained_glass:15)
B(2,-2,8,betternether:quartz_stained_glass:15)
B(3,-2,8,betternether:quartz_stained_glass:15)
RB(4,-2,8,srparasites:parasitestain:1,80,quark:crystal:1,30,srparasites:parasiterubbledense:1,100)
B(5,-2,8,betternether:quartz_stained_glass:15)
B(6,-2,8,betternether:quartz_stained_glass:15)
B(2,-2,9,betternether:quartz_stained_glass:15)
B(3,-2,9,betternether:quartz_stained_glass:15)
RB(4,-2,9,srparasites:parasitestain:1,80,quark:crystal:1,30,srparasites:parasiterubbledense:1,100)
B(5,-2,9,betternether:quartz_stained_glass:15)
B(6,-2,9,betternether:quartz_stained_glass:15)
B(2,-2,10,betternether:quartz_stained_glass:15)
B(3,-2,10,betternether:quartz_stained_glass:15)
B(4,-2,10,betternether:quartz_stained_glass:15)
B(5,-2,10,betternether:quartz_stained_glass:15)
B(6,-2,10,betternether:quartz_stained_glass:15)
B(7,-2,10,betternether:quartz_stained_glass:15)
B(3,-2,11,betternether:quartz_stained_glass:15)
B(4,-2,11,betternether:quartz_stained_glass:15)
B(5,-2,11,betternether:quartz_stained_glass:15)
B(6,-2,11,betternether:quartz_stained_glass:15)
B(4,-2,12,betternether:quartz_stained_glass:15)
B(6,-2,12,betternether:quartz_stained_glass:15)
B(1,-1,3,betternether:quartz_stained_glass:15)
B(3,-1,3,betternether:quartz_stained_glass:15)
B(4,-1,3,betternether:quartz_stained_glass:15)
B(5,-1,3,betternether:quartz_stained_glass:15)
B(1,-1,4,betternether:quartz_stained_glass:15)
B(2,-1,4,betternether:quartz_stained_glass:15)
B(3,-1,4,betternether:quartz_stained_glass:15)
B(4,-1,4,betternether:quartz_stained_glass:15)
B(5,-1,4,betternether:quartz_stained_glass:15)
B(1,-1,5,betternether:quartz_stained_glass:15)
B(2,-1,5,betternether:quartz_stained_glass:15)
B(3,-1,5,betternether:quartz_stained_glass:15)
B(4,-1,5,betternether:quartz_stained_glass:15)
B(5,-1,5,betternether:quartz_stained_glass:15)
B(1,-1,6,betternether:quartz_stained_glass:15)
B(2,-1,6,betternether:quartz_stained_glass:15)
RB(3,-1,6,srparasites:parasitestain:1,80,quark:crystal:1,30,srparasites:parasiterubbledense:1,100)
RB(4,-1,6,srparasites:parasitestain:1,80,quark:crystal:1,30,srparasites:parasiterubbledense:1,100)
B(5,-1,6,betternether:quartz_stained_glass:15)
B(6,-1,6,betternether:quartz_stained_glass:15)
B(1,-1,7,betternether:quartz_stained_glass:15)
B(2,-1,7,betternether:quartz_stained_glass:15)
RB(3,-1,7,srparasites:parasitestain:1,80,quark:crystal:1,30,srparasites:parasiterubbledense:1,100)
RB(4,-1,7,srparasites:parasitestain:1,80,quark:crystal:1,30,srparasites:parasiterubbledense:1,100)
B(5,-1,7,betternether:quartz_stained_glass:15)
B(6,-1,7,betternether:quartz_stained_glass:15)
B(2,-1,8,betternether:quartz_stained_glass:15)
B(3,-1,8,betternether:quartz_stained_glass:15)
B(4,-1,8,betternether:quartz_stained_glass:15)
B(5,-1,8,betternether:quartz_stained_glass:15)
B(6,-1,8,betternether:quartz_stained_glass:15)
B(2,-1,9,betternether:quartz_stained_glass:15)
B(3,-1,9,betternether:quartz_stained_glass:15)
B(4,-1,9,betternether:quartz_stained_glass:15)
B(5,-1,9,betternether:quartz_stained_glass:15)
B(6,-1,9,betternether:quartz_stained_glass:15)
B(2,-1,10,betternether:quartz_stained_glass:15)
B(3,-1,10,betternether:quartz_stained_glass:15)
B(4,-1,10,betternether:quartz_stained_glass:15)
B(5,-1,10,betternether:quartz_stained_glass:15)
B(6,-1,10,betternether:quartz_stained_glass:15)
B(4,-1,11,betternether:quartz_stained_glass:15)
B(3,0,2,betternether:quartz_stained_glass:15)
B(4,0,2,betternether:quartz_stained_glass:15)
B(0,0,3,betternether:quartz_stained_glass:15)
B(1,0,3,betternether:quartz_stained_glass:15)
B(2,0,3,betternether:quartz_stained_glass:15)
B(3,0,3,betternether:quartz_stained_glass:15)
B(4,0,3,betternether:quartz_stained_glass:15)
B(5,0,3,betternether:quartz_stained_glass:15)
B(1,0,4,betternether:quartz_stained_glass:15)
B(2,0,4,betternether:quartz_stained_glass:15)
B(3,0,4,betternether:quartz_stained_glass:15)
B(4,0,4,betternether:quartz_stained_glass:15)
B(5,0,4,betternether:quartz_stained_glass:15)
B(1,0,5,betternether:quartz_stained_glass:15)
B(2,0,5,betternether:quartz_stained_glass:15)
B(3,0,5,betternether:quartz_stained_glass:15)
B(4,0,5,betternether:quartz_stained_glass:15)
B(5,0,5,betternether:quartz_stained_glass:15)
B(1,0,6,betternether:quartz_stained_glass:15)
B(2,0,6,betternether:quartz_stained_glass:15)
B(4,0,6,betternether:quartz_stained_glass:15)
B(5,0,6,betternether:quartz_stained_glass:15)
B(6,0,6,betternether:quartz_stained_glass:15)
B(1,0,7,betternether:quartz_stained_glass:15)
B(2,0,7,betternether:quartz_stained_glass:15)
B(3,0,7,betternether:quartz_stained_glass:15)
B(4,0,7,betternether:quartz_stained_glass:15)
B(5,0,7,betternether:quartz_stained_glass:15)
B(6,0,7,betternether:quartz_stained_glass:15)
B(2,0,8,betternether:quartz_stained_glass:15)
B(3,0,8,betternether:quartz_stained_glass:15)
B(4,0,8,betternether:quartz_stained_glass:15)
B(5,0,8,betternether:quartz_stained_glass:15)
B(6,0,8,betternether:quartz_stained_glass:15)
B(2,0,9,betternether:quartz_stained_glass:15)
B(3,0,9,betternether:quartz_stained_glass:15)
B(4,0,9,betternether:quartz_stained_glass:15)
B(5,0,9,betternether:quartz_stained_glass:15)
B(1,1,2,betternether:quartz_stained_glass:15)
B(2,1,2,betternether:quartz_stained_glass:15)
B(3,1,2,betternether:quartz_stained_glass:15)
B(4,1,2,betternether:quartz_stained_glass:15)
B(0,1,3,betternether:quartz_stained_glass:15)
B(1,1,3,betternether:quartz_stained_glass:15)
B(2,1,3,betternether:quartz_stained_glass:15)
B(3,1,3,betternether:quartz_stained_glass:15)
B(4,1,3,betternether:quartz_stained_glass:15)
B(5,1,3,betternether:quartz_stained_glass:15)
B(1,1,4,betternether:quartz_stained_glass:15)
B(2,1,4,betternether:quartz_stained_glass:15)
B(3,1,4,betternether:quartz_stained_glass:15)
B(4,1,4,betternether:quartz_stained_glass:15)
B(5,1,4,betternether:quartz_stained_glass:15)
B(1,1,5,betternether:quartz_stained_glass:15)
B(2,1,5,betternether:quartz_stained_glass:15)
B(3,1,5,betternether:quartz_stained_glass:15)
B(4,1,5,betternether:quartz_stained_glass:15)
B(5,1,5,betternether:quartz_stained_glass:15)
B(1,1,6,betternether:quartz_stained_glass:15)
B(2,1,6,betternether:quartz_stained_glass:15)
B(3,1,6,betternether:quartz_stained_glass:15)
B(4,1,6,betternether:quartz_stained_glass:15)
B(5,1,6,betternether:quartz_stained_glass:15)
B(6,1,6,betternether:quartz_stained_glass:15)
B(1,1,7,betternether:quartz_stained_glass:15)
B(2,1,7,betternether:quartz_stained_glass:15)
B(3,1,7,betternether:quartz_stained_glass:15)
B(4,1,7,betternether:quartz_stained_glass:15)
B(5,1,7,betternether:quartz_stained_glass:15)
B(3,1,8,betternether:quartz_stained_glass:15)
B(2,2,0,betternether:quartz_stained_glass:15)
B(1,2,1,betternether:quartz_stained_glass:15)
B(2,2,1,betternether:quartz_stained_glass:15)
B(3,2,1,betternether:quartz_stained_glass:15)
B(1,2,2,betternether:quartz_stained_glass:15)
B(2,2,2,betternether:quartz_stained_glass:15)
B(3,2,2,betternether:quartz_stained_glass:15)
B(1,2,3,betternether:quartz_stained_glass:15)
B(2,2,3,betternether:quartz_stained_glass:15)
B(3,2,3,betternether:quartz_stained_glass:15)
B(4,2,3,betternether:quartz_stained_glass:15)
B(5,2,3,betternether:quartz_stained_glass:15)
B(1,2,4,betternether:quartz_stained_glass:15)
B(2,2,4,betternether:quartz_stained_glass:15)
B(3,2,4,betternether:quartz_stained_glass:15)
B(4,2,4,betternether:quartz_stained_glass:15)
B(5,2,4,betternether:quartz_stained_glass:15)
B(1,2,5,betternether:quartz_stained_glass:15)
B(2,2,5,betternether:quartz_stained_glass:15)
B(3,2,5,betternether:quartz_stained_glass:15)
B(4,2,5,betternether:quartz_stained_glass:15)
B(5,2,5,betternether:quartz_stained_glass:15)
B(1,2,6,betternether:quartz_stained_glass:15)
B(2,2,6,betternether:quartz_stained_glass:15)
B(3,2,6,betternether:quartz_stained_glass:15)
B(4,2,6,betternether:quartz_stained_glass:15)
B(3,2,7,betternether:quartz_stained_glass:15)
B(2,3,0,betternether:quartz_stained_glass:15)
B(1,3,1,betternether:quartz_stained_glass:15)
B(2,3,1,betternether:quartz_stained_glass:15)
B(3,3,1,betternether:quartz_stained_glass:15)
B(2,3,2,betternether:quartz_stained_glass:15)
B(3,3,2,betternether:quartz_stained_glass:15)
B(2,3,3,betternether:quartz_stained_glass:15)
B(3,3,3,betternether:quartz_stained_glass:15)
B(2,3,4,betternether:quartz_stained_glass:15)
B(3,3,4,betternether:quartz_stained_glass:15)
B(3,3,5,betternether:quartz_stained_glass:15)
B(4,3,5,betternether:quartz_stained_glass:15)
B(2,4,0,betternether:quartz_stained_glass:15)
B(2,4,1,betternether:quartz_stained_glass:15)
B(2,4,2,betternether:quartz_stained_glass:15)
B(3,4,3,betternether:quartz_stained_glass:15)

#######################################################################
# +-----------------------------------------------------------------+ #
# |                             Branches                            | #
# +-----------------------------------------------------------------+ #
#######################################################################

BR(0,0,16,true,CEILING_CRYST-SET-DIAG-THIN-07_0x1,NORTH,100,0)
