#######################################################################
# +-----------------------------------------------------------------+ #
# |                            BO3 object                           | #
# +-----------------------------------------------------------------+ #
#######################################################################

Author: Bo3 BulkEdit

Description: Converted Schematic - Modified by Bo3BulkEdit

Version: 3

SettingsMode: WriteDisable

#######################################################################
# +-----------------------------------------------------------------+ #
# |                          Main settings                          | #
# +-----------------------------------------------------------------+ #
#######################################################################

IsOTGPlus: true
Tree: false
Frequency: 1
Rarity: 100.0
RotateRandomly: false
SpawnHeight: randomY
MaxBranchDepth: 10
ExcludedBiomes: All

##############################
# Height Limits for the BO3. #
##############################

MinHeight: 0
MaxHeight: 255

#######################################################################
# +-----------------------------------------------------------------+ #
# |                      Source block settings                      | #
# +-----------------------------------------------------------------+ #
#######################################################################

CanOverride: true
MaxPercentageOutsideSourceBlock: 100
OutsideSourceBlock: placeAnyway

#######################################################################
# +-----------------------------------------------------------------+ #
# |                               OTG+                              | #
# +-----------------------------------------------------------------+ #
#######################################################################

BO3Group: CeilingCrystals:0

#######################################################################
# +-----------------------------------------------------------------+ #
# |                              Blocks                             | #
# +-----------------------------------------------------------------+ #
#######################################################################

B(9,-18,9,betternether:quartz_stained_glass:15)
B(10,-18,9,betternether:quartz_stained_glass:15)
B(9,-18,10,betternether:quartz_stained_glass:15)
B(10,-18,10,betternether:quartz_stained_glass:15)
B(8,-17,8,betternether:quartz_stained_glass:15)
B(9,-17,8,betternether:quartz_stained_glass:15)
B(8,-17,9,betternether:quartz_stained_glass:15)
B(9,-17,9,betternether:quartz_stained_glass:15)
B(10,-17,9,betternether:quartz_stained_glass:15)
B(8,-17,10,betternether:quartz_stained_glass:15)
B(9,-17,10,betternether:quartz_stained_glass:15)
B(10,-17,10,betternether:quartz_stained_glass:15)
B(7,-16,7,betternether:quartz_stained_glass:15)
B(8,-16,7,betternether:quartz_stained_glass:15)
B(9,-16,7,betternether:quartz_stained_glass:15)
B(7,-16,8,betternether:quartz_stained_glass:15)
B(8,-16,8,betternether:quartz_stained_glass:15)
B(9,-16,8,betternether:quartz_stained_glass:15)
B(10,-16,8,betternether:quartz_stained_glass:15)
B(7,-16,9,betternether:quartz_stained_glass:15)
B(8,-16,9,betternether:quartz_stained_glass:15)
B(9,-16,9,betternether:quartz_stained_glass:15)
B(10,-16,9,betternether:quartz_stained_glass:15)
B(8,-16,10,betternether:quartz_stained_glass:15)
B(9,-16,10,betternether:quartz_stained_glass:15)
B(6,-15,6,betternether:quartz_stained_glass:15)
B(7,-15,6,betternether:quartz_stained_glass:15)
B(8,-15,6,betternether:quartz_stained_glass:15)
B(9,-15,6,betternether:quartz_stained_glass:15)
B(6,-15,7,betternether:quartz_stained_glass:15)
B(7,-15,7,betternether:quartz_stained_glass:15)
B(8,-15,7,betternether:quartz_stained_glass:15)
B(9,-15,7,betternether:quartz_stained_glass:15)
B(6,-15,8,betternether:quartz_stained_glass:15)
B(7,-15,8,betternether:quartz_stained_glass:15)
RB(8,-15,8,srparasites:parasitestain:1,80,quark:crystal:1,30,srparasites:parasiterubbledense:1,100)
B(9,-15,8,betternether:quartz_stained_glass:15)
B(10,-15,8,betternether:quartz_stained_glass:15)
B(6,-15,9,betternether:quartz_stained_glass:15)
B(7,-15,9,betternether:quartz_stained_glass:15)
B(8,-15,9,betternether:quartz_stained_glass:15)
B(8,-15,10,betternether:quartz_stained_glass:15)
B(5,-14,5,betternether:quartz_stained_glass:15)
B(6,-14,5,betternether:quartz_stained_glass:15)
B(7,-14,5,betternether:quartz_stained_glass:15)
B(8,-14,5,betternether:quartz_stained_glass:15)
B(5,-14,6,betternether:quartz_stained_glass:15)
B(6,-14,6,betternether:quartz_stained_glass:15)
B(7,-14,6,betternether:quartz_stained_glass:15)
B(8,-14,6,betternether:quartz_stained_glass:15)
B(9,-14,6,betternether:quartz_stained_glass:15)
B(5,-14,7,betternether:quartz_stained_glass:15)
B(6,-14,7,betternether:quartz_stained_glass:15)
RB(7,-14,7,srparasites:parasitestain:1,80,quark:crystal:1,30,srparasites:parasiterubbledense:1,100)
RB(8,-14,7,srparasites:parasitestain:1,80,quark:crystal:1,30,srparasites:parasiterubbledense:1,100)
B(9,-14,7,betternether:quartz_stained_glass:15)
B(5,-14,8,betternether:quartz_stained_glass:15)
B(6,-14,8,betternether:quartz_stained_glass:15)
RB(7,-14,8,srparasites:parasitestain:1,80,quark:crystal:1,30,srparasites:parasiterubbledense:1,100)
B(9,-14,8,betternether:quartz_stained_glass:15)
B(6,-14,9,betternether:quartz_stained_glass:15)
B(7,-14,9,betternether:quartz_stained_glass:15)
B(8,-14,9,betternether:quartz_stained_glass:15)
B(6,-13,4,betternether:quartz_stained_glass:15)
B(7,-13,4,betternether:quartz_stained_glass:15)
B(5,-13,5,betternether:quartz_stained_glass:15)
B(6,-13,5,betternether:quartz_stained_glass:15)
B(7,-13,5,betternether:quartz_stained_glass:15)
B(8,-13,5,betternether:quartz_stained_glass:15)
B(4,-13,6,betternether:quartz_stained_glass:15)
B(5,-13,6,betternether:quartz_stained_glass:15)
RB(6,-13,6,srparasites:parasitestain:1,80,quark:crystal:1,30,srparasites:parasiterubbledense:1,100)
RB(7,-13,6,srparasites:parasitestain:1,80,quark:crystal:1,30,srparasites:parasiterubbledense:1,100)
B(8,-13,6,betternether:quartz_stained_glass:15)
B(9,-13,6,betternether:quartz_stained_glass:15)
B(4,-13,7,betternether:quartz_stained_glass:15)
B(5,-13,7,betternether:quartz_stained_glass:15)
RB(6,-13,7,srparasites:parasitestain:1,80,quark:crystal:1,30,srparasites:parasiterubbledense:1,100)
RB(7,-13,7,srparasites:parasitestain:1,80,quark:crystal:1,30,srparasites:parasiterubbledense:1,100)
B(8,-13,7,betternether:quartz_stained_glass:15)
B(9,-13,7,betternether:quartz_stained_glass:15)
B(5,-13,8,betternether:quartz_stained_glass:15)
B(6,-13,8,betternether:quartz_stained_glass:15)
B(7,-13,8,betternether:quartz_stained_glass:15)
B(8,-13,8,betternether:quartz_stained_glass:15)
B(6,-13,9,betternether:quartz_stained_glass:15)
B(7,-13,9,betternether:quartz_stained_glass:15)
B(6,-12,3,betternether:quartz_stained_glass:15)
B(5,-12,4,betternether:quartz_stained_glass:15)
B(6,-12,4,betternether:quartz_stained_glass:15)
B(7,-12,4,betternether:quartz_stained_glass:15)
B(4,-12,5,betternether:quartz_stained_glass:15)
B(5,-12,5,betternether:quartz_stained_glass:15)
RB(6,-12,5,srparasites:parasitestain:1,80,quark:crystal:1,30,srparasites:parasiterubbledense:1,100)
B(7,-12,5,betternether:quartz_stained_glass:15)
B(8,-12,5,betternether:quartz_stained_glass:15)
B(3,-12,6,betternether:quartz_stained_glass:15)
B(4,-12,6,betternether:quartz_stained_glass:15)
RB(5,-12,6,srparasites:parasitestain:1,80,quark:crystal:1,30,srparasites:parasiterubbledense:1,100)
RB(6,-12,6,srparasites:parasitestain:1,80,quark:crystal:1,30,srparasites:parasiterubbledense:1,100)
RB(7,-12,6,srparasites:parasitestain:1,80,quark:crystal:1,30,srparasites:parasiterubbledense:1,100)
B(8,-12,6,betternether:quartz_stained_glass:15)
B(9,-12,6,betternether:quartz_stained_glass:15)
B(4,-12,7,betternether:quartz_stained_glass:15)
B(5,-12,7,betternether:quartz_stained_glass:15)
RB(6,-12,7,srparasites:parasitestain:1,80,quark:crystal:1,30,srparasites:parasiterubbledense:1,100)
B(7,-12,7,betternether:quartz_stained_glass:15)
B(8,-12,7,betternether:quartz_stained_glass:15)
B(5,-12,8,betternether:quartz_stained_glass:15)
B(6,-12,8,betternether:quartz_stained_glass:15)
B(7,-12,8,betternether:quartz_stained_glass:15)
B(6,-12,9,betternether:quartz_stained_glass:15)
B(5,-11,3,betternether:quartz_stained_glass:15)
B(6,-11,3,betternether:quartz_stained_glass:15)
B(4,-11,4,betternether:quartz_stained_glass:15)
B(5,-11,4,betternether:quartz_stained_glass:15)
B(6,-11,4,betternether:quartz_stained_glass:15)
B(7,-11,4,betternether:quartz_stained_glass:15)
B(3,-11,5,betternether:quartz_stained_glass:15)
B(4,-11,5,betternether:quartz_stained_glass:15)
RB(5,-11,5,srparasites:parasitestain:1,80,quark:crystal:1,30,srparasites:parasiterubbledense:1,100)
RB(6,-11,5,srparasites:parasitestain:1,80,quark:crystal:1,30,srparasites:parasiterubbledense:1,100)
B(7,-11,5,betternether:quartz_stained_glass:15)
B(8,-11,5,betternether:quartz_stained_glass:15)
B(3,-11,6,betternether:quartz_stained_glass:15)
B(4,-11,6,betternether:quartz_stained_glass:15)
RB(5,-11,6,srparasites:parasitestain:1,80,quark:crystal:1,30,srparasites:parasiterubbledense:1,100)
RB(6,-11,6,srparasites:parasitestain:1,80,quark:crystal:1,30,srparasites:parasiterubbledense:1,100)
B(7,-11,6,betternether:quartz_stained_glass:15)
B(8,-11,6,betternether:quartz_stained_glass:15)
B(4,-11,7,betternether:quartz_stained_glass:15)
B(5,-11,7,betternether:quartz_stained_glass:15)
B(6,-11,7,betternether:quartz_stained_glass:15)
B(7,-11,7,betternether:quartz_stained_glass:15)
B(5,-11,8,betternether:quartz_stained_glass:15)
B(6,-11,8,betternether:quartz_stained_glass:15)
B(5,-10,2,betternether:quartz_stained_glass:15)
B(4,-10,3,betternether:quartz_stained_glass:15)
B(5,-10,3,betternether:quartz_stained_glass:15)
B(6,-10,3,betternether:quartz_stained_glass:15)
B(3,-10,4,betternether:quartz_stained_glass:15)
B(4,-10,4,betternether:quartz_stained_glass:15)
RB(5,-10,4,srparasites:parasitestain:1,80,quark:crystal:1,30,srparasites:parasiterubbledense:1,100)
B(6,-10,4,betternether:quartz_stained_glass:15)
B(7,-10,4,betternether:quartz_stained_glass:15)
B(2,-10,5,betternether:quartz_stained_glass:15)
B(3,-10,5,betternether:quartz_stained_glass:15)
RB(4,-10,5,srparasites:parasitestain:1,80,quark:crystal:1,30,srparasites:parasiterubbledense:1,100)
RB(5,-10,5,srparasites:parasitestain:1,80,quark:crystal:1,30,srparasites:parasiterubbledense:1,100)
RB(6,-10,5,srparasites:parasitestain:1,80,quark:crystal:1,30,srparasites:parasiterubbledense:1,100)
B(7,-10,5,betternether:quartz_stained_glass:15)
B(8,-10,5,betternether:quartz_stained_glass:15)
B(3,-10,6,betternether:quartz_stained_glass:15)
B(4,-10,6,betternether:quartz_stained_glass:15)
RB(5,-10,6,srparasites:parasitestain:1,80,quark:crystal:1,30,srparasites:parasiterubbledense:1,100)
B(6,-10,6,betternether:quartz_stained_glass:15)
B(7,-10,6,betternether:quartz_stained_glass:15)
B(4,-10,7,betternether:quartz_stained_glass:15)
B(5,-10,7,betternether:quartz_stained_glass:15)
B(6,-10,7,betternether:quartz_stained_glass:15)
B(5,-10,8,betternether:quartz_stained_glass:15)
B(4,-9,2,betternether:quartz_stained_glass:15)
B(5,-9,2,betternether:quartz_stained_glass:15)
B(3,-9,3,betternether:quartz_stained_glass:15)
B(4,-9,3,betternether:quartz_stained_glass:15)
B(5,-9,3,betternether:quartz_stained_glass:15)
B(6,-9,3,betternether:quartz_stained_glass:15)
B(2,-9,4,betternether:quartz_stained_glass:15)
B(3,-9,4,betternether:quartz_stained_glass:15)
RB(4,-9,4,srparasites:parasitestain:1,80,quark:crystal:1,30,srparasites:parasiterubbledense:1,100)
RB(5,-9,4,srparasites:parasitestain:1,80,quark:crystal:1,30,srparasites:parasiterubbledense:1,100)
B(6,-9,4,betternether:quartz_stained_glass:15)
B(7,-9,4,betternether:quartz_stained_glass:15)
B(2,-9,5,betternether:quartz_stained_glass:15)
B(3,-9,5,betternether:quartz_stained_glass:15)
RB(4,-9,5,srparasites:parasitestain:1,80,quark:crystal:1,30,srparasites:parasiterubbledense:1,100)
RB(5,-9,5,srparasites:parasitestain:1,80,quark:crystal:1,30,srparasites:parasiterubbledense:1,100)
B(6,-9,5,betternether:quartz_stained_glass:15)
B(7,-9,5,betternether:quartz_stained_glass:15)
B(3,-9,6,betternether:quartz_stained_glass:15)
B(4,-9,6,betternether:quartz_stained_glass:15)
B(5,-9,6,betternether:quartz_stained_glass:15)
B(6,-9,6,betternether:quartz_stained_glass:15)
B(4,-9,7,betternether:quartz_stained_glass:15)
B(5,-9,7,betternether:quartz_stained_glass:15)
B(4,-8,1,betternether:quartz_stained_glass:15)
B(3,-8,2,betternether:quartz_stained_glass:15)
B(4,-8,2,betternether:quartz_stained_glass:15)
B(5,-8,2,betternether:quartz_stained_glass:15)
B(2,-8,3,betternether:quartz_stained_glass:15)
B(3,-8,3,betternether:quartz_stained_glass:15)
RB(4,-8,3,srparasites:parasitestain:1,80,quark:crystal:1,30,srparasites:parasiterubbledense:1,100)
B(5,-8,3,betternether:quartz_stained_glass:15)
B(6,-8,3,betternether:quartz_stained_glass:15)
B(1,-8,4,betternether:quartz_stained_glass:15)
B(2,-8,4,betternether:quartz_stained_glass:15)
RB(3,-8,4,srparasites:parasitestain:1,80,quark:crystal:1,30,srparasites:parasiterubbledense:1,100)
RB(4,-8,4,srparasites:parasitestain:1,80,quark:crystal:1,30,srparasites:parasiterubbledense:1,100)
RB(5,-8,4,srparasites:parasitestain:1,80,quark:crystal:1,30,srparasites:parasiterubbledense:1,100)
B(6,-8,4,betternether:quartz_stained_glass:15)
B(7,-8,4,betternether:quartz_stained_glass:15)
B(2,-8,5,betternether:quartz_stained_glass:15)
B(3,-8,5,betternether:quartz_stained_glass:15)
RB(4,-8,5,srparasites:parasitestain:1,80,quark:crystal:1,30,srparasites:parasiterubbledense:1,100)
B(5,-8,5,betternether:quartz_stained_glass:15)
B(6,-8,5,betternether:quartz_stained_glass:15)
B(3,-8,6,betternether:quartz_stained_glass:15)
B(4,-8,6,betternether:quartz_stained_glass:15)
B(5,-8,6,betternether:quartz_stained_glass:15)
B(4,-8,7,betternether:quartz_stained_glass:15)
B(3,-7,1,betternether:quartz_stained_glass:15)
B(4,-7,1,betternether:quartz_stained_glass:15)
B(2,-7,2,betternether:quartz_stained_glass:15)
B(3,-7,2,betternether:quartz_stained_glass:15)
B(4,-7,2,betternether:quartz_stained_glass:15)
B(5,-7,2,betternether:quartz_stained_glass:15)
B(1,-7,3,betternether:quartz_stained_glass:15)
B(2,-7,3,betternether:quartz_stained_glass:15)
RB(3,-7,3,srparasites:parasitestain:1,80,quark:crystal:1,30,srparasites:parasiterubbledense:1,100)
RB(4,-7,3,srparasites:parasitestain:1,80,quark:crystal:1,30,srparasites:parasiterubbledense:1,100)
B(5,-7,3,betternether:quartz_stained_glass:15)
B(6,-7,3,betternether:quartz_stained_glass:15)
B(1,-7,4,betternether:quartz_stained_glass:15)
B(2,-7,4,betternether:quartz_stained_glass:15)
RB(3,-7,4,srparasites:parasitestain:1,80,quark:crystal:1,30,srparasites:parasiterubbledense:1,100)
RB(4,-7,4,srparasites:parasitestain:1,80,quark:crystal:1,30,srparasites:parasiterubbledense:1,100)
B(5,-7,4,betternether:quartz_stained_glass:15)
B(6,-7,4,betternether:quartz_stained_glass:15)
B(2,-7,5,betternether:quartz_stained_glass:15)
B(3,-7,5,betternether:quartz_stained_glass:15)
B(4,-7,5,betternether:quartz_stained_glass:15)
B(5,-7,5,betternether:quartz_stained_glass:15)
B(3,-7,6,betternether:quartz_stained_glass:15)
B(4,-7,6,betternether:quartz_stained_glass:15)
B(3,-6,0,betternether:quartz_stained_glass:15)
B(2,-6,1,betternether:quartz_stained_glass:15)
B(3,-6,1,betternether:quartz_stained_glass:15)
B(4,-6,1,betternether:quartz_stained_glass:15)
B(1,-6,2,betternether:quartz_stained_glass:15)
B(2,-6,2,betternether:quartz_stained_glass:15)
RB(3,-6,2,srparasites:parasitestain:1,80,quark:crystal:1,30,srparasites:parasiterubbledense:1,100)
B(4,-6,2,betternether:quartz_stained_glass:15)
B(5,-6,2,betternether:quartz_stained_glass:15)
B(0,-6,3,betternether:quartz_stained_glass:15)
B(1,-6,3,betternether:quartz_stained_glass:15)
RB(2,-6,3,srparasites:parasitestain:1,80,quark:crystal:1,30,srparasites:parasiterubbledense:1,100)
RB(3,-6,3,srparasites:parasitestain:1,80,quark:crystal:1,30,srparasites:parasiterubbledense:1,100)
RB(4,-6,3,srparasites:parasitestain:1,80,quark:crystal:1,30,srparasites:parasiterubbledense:1,100)
B(5,-6,3,betternether:quartz_stained_glass:15)
B(6,-6,3,betternether:quartz_stained_glass:15)
B(1,-6,4,betternether:quartz_stained_glass:15)
B(2,-6,4,betternether:quartz_stained_glass:15)
RB(3,-6,4,srparasites:parasitestain:1,80,quark:crystal:1,30,srparasites:parasiterubbledense:1,100)
B(4,-6,4,betternether:quartz_stained_glass:15)
B(5,-6,4,betternether:quartz_stained_glass:15)
B(2,-6,5,betternether:quartz_stained_glass:15)
B(3,-6,5,betternether:quartz_stained_glass:15)
B(4,-6,5,betternether:quartz_stained_glass:15)
B(3,-6,6,betternether:quartz_stained_glass:15)
B(2,-5,0,betternether:quartz_stained_glass:15)
B(3,-5,0,betternether:quartz_stained_glass:15)
B(1,-5,1,betternether:quartz_stained_glass:15)
B(2,-5,1,betternether:quartz_stained_glass:15)
B(3,-5,1,betternether:quartz_stained_glass:15)
B(4,-5,1,betternether:quartz_stained_glass:15)
B(0,-5,2,betternether:quartz_stained_glass:15)
B(1,-5,2,betternether:quartz_stained_glass:15)
RB(2,-5,2,srparasites:parasitestain:1,80,quark:crystal:1,30,srparasites:parasiterubbledense:1,100)
RB(3,-5,2,srparasites:parasitestain:1,80,quark:crystal:1,30,srparasites:parasiterubbledense:1,100)
B(4,-5,2,betternether:quartz_stained_glass:15)
B(5,-5,2,betternether:quartz_stained_glass:15)
B(0,-5,3,betternether:quartz_stained_glass:15)
B(1,-5,3,betternether:quartz_stained_glass:15)
RB(2,-5,3,srparasites:parasitestain:1,80,quark:crystal:1,30,srparasites:parasiterubbledense:1,100)
RB(3,-5,3,srparasites:parasitestain:1,80,quark:crystal:1,30,srparasites:parasiterubbledense:1,100)
B(4,-5,3,betternether:quartz_stained_glass:15)
B(5,-5,3,betternether:quartz_stained_glass:15)
B(1,-5,4,betternether:quartz_stained_glass:15)
B(2,-5,4,betternether:quartz_stained_glass:15)
B(3,-5,4,betternether:quartz_stained_glass:15)
B(4,-5,4,betternether:quartz_stained_glass:15)
B(2,-5,5,betternether:quartz_stained_glass:15)
B(3,-5,5,betternether:quartz_stained_glass:15)
B(2,-4,-1,betternether:quartz_stained_glass:15)
B(1,-4,0,betternether:quartz_stained_glass:15)
B(2,-4,0,betternether:quartz_stained_glass:15)
B(3,-4,0,betternether:quartz_stained_glass:15)
B(0,-4,1,betternether:quartz_stained_glass:15)
B(1,-4,1,betternether:quartz_stained_glass:15)
RB(2,-4,1,srparasites:parasitestain:1,80,quark:crystal:1,30,srparasites:parasiterubbledense:1,100)
B(3,-4,1,betternether:quartz_stained_glass:15)
B(4,-4,1,betternether:quartz_stained_glass:15)
B(-1,-4,2,betternether:quartz_stained_glass:15)
B(0,-4,2,betternether:quartz_stained_glass:15)
RB(1,-4,2,srparasites:parasitestain:1,80,quark:crystal:1,30,srparasites:parasiterubbledense:1,100)
RB(2,-4,2,srparasites:parasitestain:1,80,quark:crystal:1,30,srparasites:parasiterubbledense:1,100)
RB(3,-4,2,srparasites:parasitestain:1,80,quark:crystal:1,30,srparasites:parasiterubbledense:1,100)
B(4,-4,2,betternether:quartz_stained_glass:15)
B(5,-4,2,betternether:quartz_stained_glass:15)
B(0,-4,3,betternether:quartz_stained_glass:15)
B(1,-4,3,betternether:quartz_stained_glass:15)
RB(2,-4,3,srparasites:parasitestain:1,80,quark:crystal:1,30,srparasites:parasiterubbledense:1,100)
B(3,-4,3,betternether:quartz_stained_glass:15)
B(4,-4,3,betternether:quartz_stained_glass:15)
B(1,-4,4,betternether:quartz_stained_glass:15)
B(2,-4,4,betternether:quartz_stained_glass:15)
B(3,-4,4,betternether:quartz_stained_glass:15)
B(2,-4,5,betternether:quartz_stained_glass:15)
B(1,-3,-1,betternether:quartz_stained_glass:15)
B(2,-3,-1,betternether:quartz_stained_glass:15)
B(0,-3,0,betternether:quartz_stained_glass:15)
B(1,-3,0,betternether:quartz_stained_glass:15)
B(2,-3,0,betternether:quartz_stained_glass:15)
B(3,-3,0,betternether:quartz_stained_glass:15)
B(-1,-3,1,betternether:quartz_stained_glass:15)
B(0,-3,1,betternether:quartz_stained_glass:15)
RB(1,-3,1,srparasites:parasitestain:1,80,quark:crystal:1,30,srparasites:parasiterubbledense:1,100)
RB(2,-3,1,srparasites:parasitestain:1,80,quark:crystal:1,30,srparasites:parasiterubbledense:1,100)
B(3,-3,1,betternether:quartz_stained_glass:15)
B(4,-3,1,betternether:quartz_stained_glass:15)
B(-1,-3,2,betternether:quartz_stained_glass:15)
B(0,-3,2,betternether:quartz_stained_glass:15)
RB(1,-3,2,srparasites:parasitestain:1,80,quark:crystal:1,30,srparasites:parasiterubbledense:1,100)
RB(2,-3,2,srparasites:parasitestain:1,80,quark:crystal:1,30,srparasites:parasiterubbledense:1,100)
B(3,-3,2,betternether:quartz_stained_glass:15)
B(4,-3,2,betternether:quartz_stained_glass:15)
B(0,-3,3,betternether:quartz_stained_glass:15)
B(1,-3,3,betternether:quartz_stained_glass:15)
B(2,-3,3,betternether:quartz_stained_glass:15)
B(3,-3,3,betternether:quartz_stained_glass:15)
B(1,-3,4,betternether:quartz_stained_glass:15)
B(2,-3,4,betternether:quartz_stained_glass:15)
B(1,-2,-1,betternether:quartz_stained_glass:15)
B(2,-2,-1,betternether:quartz_stained_glass:15)
B(0,-2,0,betternether:quartz_stained_glass:15)
RB(1,-2,0,srparasites:parasitestain:1,80,quark:crystal:1,30,srparasites:parasiterubbledense:1,100)
B(2,-2,0,betternether:quartz_stained_glass:15)
B(3,-2,0,betternether:quartz_stained_glass:15)
B(-1,-2,1,betternether:quartz_stained_glass:15)
RB(0,-2,1,srparasites:parasitestain:1,80,quark:crystal:1,30,srparasites:parasiterubbledense:1,100)
RB(1,-2,1,srparasites:parasitestain:1,80,quark:crystal:1,30,srparasites:parasiterubbledense:1,100)
RB(2,-2,1,srparasites:parasitestain:1,80,quark:crystal:1,30,srparasites:parasiterubbledense:1,100)
B(3,-2,1,betternether:quartz_stained_glass:15)
B(4,-2,1,betternether:quartz_stained_glass:15)
B(-1,-2,2,betternether:quartz_stained_glass:15)
B(0,-2,2,betternether:quartz_stained_glass:15)
RB(1,-2,2,srparasites:parasitestain:1,80,quark:crystal:1,30,srparasites:parasiterubbledense:1,100)
B(2,-2,2,betternether:quartz_stained_glass:15)
B(3,-2,2,betternether:quartz_stained_glass:15)
B(0,-2,3,betternether:quartz_stained_glass:15)
B(1,-2,3,betternether:quartz_stained_glass:15)
B(2,-2,3,betternether:quartz_stained_glass:15)
B(1,-2,4,betternether:quartz_stained_glass:15)
B(0,-1,-1,betternether:quartz_stained_glass:15)
B(1,-1,-1,betternether:quartz_stained_glass:15)
B(2,-1,-1,betternether:quartz_stained_glass:15)
B(-1,-1,0,betternether:quartz_stained_glass:15)
RB(0,-1,0,srparasites:parasitestain:1,80,quark:crystal:1,30,srparasites:parasiterubbledense:1,100)
RB(1,-1,0,srparasites:parasitestain:1,80,quark:crystal:1,30,srparasites:parasiterubbledense:1,100)
B(2,-1,0,betternether:quartz_stained_glass:15)
B(3,-1,0,betternether:quartz_stained_glass:15)
B(-1,-1,1,betternether:quartz_stained_glass:15)
RB(0,-1,1,srparasites:parasitestain:1,80,quark:crystal:1,30,srparasites:parasiterubbledense:1,100)
RB(1,-1,1,srparasites:parasitestain:1,80,quark:crystal:1,30,srparasites:parasiterubbledense:1,100)
B(2,-1,1,betternether:quartz_stained_glass:15)
B(3,-1,1,betternether:quartz_stained_glass:15)
B(-1,-1,2,betternether:quartz_stained_glass:15)
B(0,-1,2,betternether:quartz_stained_glass:15)
B(1,-1,2,betternether:quartz_stained_glass:15)
B(2,-1,2,betternether:quartz_stained_glass:15)
B(0,-1,3,betternether:quartz_stained_glass:15)
B(1,-1,3,betternether:quartz_stained_glass:15)
B(0,0,-1,betternether:quartz_stained_glass:15)
B(1,0,-1,betternether:quartz_stained_glass:15)
B(-1,0,0,betternether:quartz_stained_glass:15)
B(1,0,0,betternether:quartz_stained_glass:15)
B(2,0,0,betternether:quartz_stained_glass:15)
B(-1,0,1,betternether:quartz_stained_glass:15)
B(0,0,1,betternether:quartz_stained_glass:15)
B(1,0,1,betternether:quartz_stained_glass:15)
B(2,0,1,betternether:quartz_stained_glass:15)
B(0,0,2,betternether:quartz_stained_glass:15)
B(1,0,2,betternether:quartz_stained_glass:15)
B(0,1,-1,betternether:quartz_stained_glass:15)
B(-1,1,0,betternether:quartz_stained_glass:15)
B(0,1,0,betternether:quartz_stained_glass:15)
B(1,1,0,betternether:quartz_stained_glass:15)
B(0,1,1,betternether:quartz_stained_glass:15)
B(1,1,1,betternether:quartz_stained_glass:15)
B(0,2,0,betternether:quartz_stained_glass:15)

