
#######################################################################
# +-----------------------------------------------------------------+ #
# |                            BO4 object                           | #
# +-----------------------------------------------------------------+ #
#######################################################################

Author: NLBlackEagle

Description: No description given

SettingsMode: WriteDisable


#######################################################################
# +-----------------------------------------------------------------+ #
# |                          Main settings                          | #
# +-----------------------------------------------------------------+ #
#######################################################################

Frequency: 0

SpawnHeight: highestBlock

UseCenterForHighestBlock: true

##############################
# Height Limits for the BO4. #
##############################

MinHeight: 0

MaxHeight: 255

InheritBO3: 

InheritBO3Rotation: NORTH

OverrideChildSettings: true

OverrideParentHeight: false

CanOverride: false

BranchFrequency: 0

BranchFrequencyGroup: 

MustBeBelowOther: false

MustBeInside: 

CannotBeInside: 

ReplacesBO3: 

MustBeInsideWorldBorders: false

CanSpawnOnWater: true

SpawnOnWaterOnly: false

SpawnUnderWater: false

SpawnAtWaterLevel: false

HeightOffset: 0

RemoveAir: true

ReplaceAbove: 

ReplaceBelow: 

ReplaceWithBiomeBlocks: true

ReplaceWithSurfaceBlock: GRASS

ReplaceWithGroundBlock: DIRT

ReplaceWithStoneBlock: STONE

SmoothRadius: 0

SmoothHeightOffset: 0

SmoothStartTop: false

SmoothStartWood: false

SmoothingSurfaceBlock: 

SmoothingGroundBlock: 

BO3Group: 

IsSpawnPoint: false

DoReplaceBlocks: true


#######################################################################
# +-----------------------------------------------------------------+ #
# |                              Blocks                             | #
# +-----------------------------------------------------------------+ #
#######################################################################

Block(-8,10,3,PACKED_ICE:0)
Block(-8,11,2,PACKED_ICE:0)
Block(-8,11,3,PACKED_ICE:0)
Block(-8,11,4,PACKED_ICE:0)
Block(-8,12,1,PACKED_ICE:0)
Block(-8,12,2,PACKED_ICE:0)
Block(-8,12,3,PACKED_ICE:0)
Block(-8,12,4,PACKED_ICE:0)
Block(-8,12,5,PACKED_ICE:0)
Block(-8,13,0,PACKED_ICE:0)
Block(-8,13,1,PACKED_ICE:0)
Block(-8,13,2,PACKED_ICE:0)
Block(-8,13,3,PACKED_ICE:0)
Block(-8,13,4,PACKED_ICE:0)
Block(-8,13,5,PACKED_ICE:0)
Block(-8,13,6,PACKED_ICE:0)
Block(-8,13,7,PACKED_ICE:0)
Block(-8,14,-1,ICE:0)
Block(-8,14,0,ICE:0)
Block(-8,14,1,PACKED_ICE:0)
Block(-8,14,2,PACKED_ICE:0)
Block(-8,14,3,PACKED_ICE:0)
Block(-8,14,4,PACKED_ICE:0)
Block(-8,14,5,PACKED_ICE:0)
Block(-8,14,6,PACKED_ICE:0)
Block(-8,14,7,ICE:0)
Block(-8,15,-3,ICE:0)
Block(-8,15,-2,ICE:0)
Block(-8,15,-1,ICE:0)
Block(-8,15,0,PACKED_ICE:0)
Block(-8,15,1,PACKED_ICE:0)
Block(-8,15,2,PACKED_ICE:0)
Block(-8,15,3,PACKED_ICE:0)
Block(-8,15,4,PACKED_ICE:0)
Block(-8,15,5,PACKED_ICE:0)
Block(-8,15,6,PACKED_ICE:0)
Block(-8,15,7,ICE:0)
Block(-8,16,-4,ICE:0)
Block(-8,16,-3,ICE:0)
Block(-8,16,-2,ICE:0)
Block(-8,16,-1,ICE:0)
Block(-8,16,0,PACKED_ICE:0)
Block(-8,16,1,PACKED_ICE:0)
Block(-8,16,2,PACKED_ICE:0)
Block(-8,16,3,PACKED_ICE:0)
Block(-8,16,4,PACKED_ICE:0)
Block(-8,16,5,PACKED_ICE:0)
Block(-8,16,6,PACKED_ICE:0)
Block(-8,16,7,ICE:0)
Block(-8,16,8,ICE:0)
Block(-8,17,-5,PACKED_ICE:0)
Block(-8,17,-4,ICE:0)
Block(-8,17,-3,ICE:0)
Block(-8,17,-2,PACKED_ICE:0)
Block(-8,17,-1,PACKED_ICE:0)
Block(-8,17,0,PACKED_ICE:0)
Block(-8,17,1,PACKED_ICE:0)
Block(-8,17,2,PACKED_ICE:0)
Block(-8,17,3,PACKED_ICE:0)
Block(-8,17,4,PACKED_ICE:0)
Block(-8,17,5,PACKED_ICE:0)
Block(-8,17,6,PACKED_ICE:0)
Block(-8,17,7,PACKED_ICE:0)
Block(-8,18,-6,ICE:0)
Block(-8,18,-5,PACKED_ICE:0)
Block(-8,18,-4,ICE:0)
Block(-8,18,-3,ICE:0)
Block(-8,18,-2,PACKED_ICE:0)
Block(-8,18,-1,PACKED_ICE:0)
Block(-8,18,0,PACKED_ICE:0)
Block(-8,18,1,PACKED_ICE:0)
Block(-8,18,2,PACKED_ICE:0)
Block(-8,18,3,PACKED_ICE:0)
Block(-8,18,4,PACKED_ICE:0)
Block(-8,18,5,PACKED_ICE:0)
Block(-8,18,6,PACKED_ICE:0)
Block(-8,18,7,PACKED_ICE:0)
Block(-8,19,-7,ICE:0)
Block(-8,19,-6,ICE:0)
Block(-8,19,-5,ICE:0)
Block(-8,19,-4,ICE:0)
Block(-8,19,-3,ICE:0)
Block(-8,19,-2,PACKED_ICE:0)
Block(-8,19,-1,PACKED_ICE:0)
Block(-8,19,0,PACKED_ICE:0)
Block(-8,19,1,PACKED_ICE:0)
Block(-8,19,2,PACKED_ICE:0)
Block(-8,19,3,PACKED_ICE:0)
Block(-8,19,4,PACKED_ICE:0)
Block(-8,19,5,PACKED_ICE:0)
Block(-8,19,6,PACKED_ICE:0)
Block(-8,19,7,PACKED_ICE:0)
Block(-8,20,-7,ICE:0)
Block(-8,20,-6,ICE:0)
Block(-8,20,-5,ICE:0)
Block(-8,20,-4,ICE:0)
Block(-8,20,-3,ICE:0)
Block(-8,20,-2,PACKED_ICE:0)
Block(-8,20,-1,PACKED_ICE:0)
Block(-8,20,0,PACKED_ICE:0)
Block(-8,20,1,PACKED_ICE:0)
Block(-8,20,2,PACKED_ICE:0)
Block(-8,20,3,PACKED_ICE:0)
Block(-8,20,4,PACKED_ICE:0)
Block(-8,20,5,PACKED_ICE:0)
Block(-8,20,6,PACKED_ICE:0)
Block(-8,20,7,PACKED_ICE:0)
Block(-8,21,-7,ICE:0)
Block(-8,21,-3,ICE:0)
Block(-8,21,-2,ICE:0)
Block(-8,21,-1,PACKED_ICE:0)
Block(-8,21,0,PACKED_ICE:0)
Block(-8,21,1,PACKED_ICE:0)
Block(-8,21,2,PACKED_ICE:0)
Block(-8,21,3,PACKED_ICE:0)
Block(-8,21,4,PACKED_ICE:0)
Block(-8,21,5,PACKED_ICE:0)
Block(-8,21,6,ICE:0)
Block(-8,22,-2,ICE:0)
Block(-8,22,-1,ICE:0)
Block(-8,22,0,PACKED_ICE:0)
Block(-8,22,1,PACKED_ICE:0)
Block(-8,22,2,PACKED_ICE:0)
Block(-8,22,3,PACKED_ICE:0)
Block(-8,22,4,PACKED_ICE:0)
Block(-8,22,5,ICE:0)
Block(-8,22,6,ICE:0)
Block(-8,23,-5,ICE:0)
Block(-8,23,-3,ICE:0)
Block(-8,23,-2,ICE:0)
Block(-8,23,-1,PACKED_ICE:0)
Block(-8,23,0,PACKED_ICE:0)
Block(-8,23,1,PACKED_ICE:0)
Block(-8,23,2,PACKED_ICE:0)
Block(-8,23,3,PACKED_ICE:0)
Block(-8,23,4,PACKED_ICE:0)
Block(-8,23,5,ICE:0)
Block(-8,24,-5,ICE:0)
Block(-8,24,-4,ICE:0)
Block(-8,24,1,PACKED_ICE:0)
Block(-8,24,2,PACKED_ICE:0)
Block(-8,24,3,PACKED_ICE:0)
Block(-8,24,4,ICE:0)
Block(-8,24,5,ICE:0)
Block(-8,25,-5,ICE:0)
Block(-8,25,1,PACKED_ICE:0)
Block(-8,25,2,PACKED_ICE:0)
Block(-8,25,3,PACKED_ICE:0)
Block(-8,25,4,PACKED_ICE:0)
Block(-8,25,5,ICE:0)
Block(-8,26,-5,PACKED_ICE:0)
Block(-8,26,-4,ICE:0)
Block(-8,26,1,PACKED_ICE:0)
Block(-8,26,2,PACKED_ICE:0)
Block(-8,26,3,PACKED_ICE:0)
Block(-8,26,4,PACKED_ICE:0)
Block(-8,26,5,PACKED_ICE:0)
Block(-8,27,-5,PACKED_ICE:0)
Block(-8,27,-4,ICE:0)
Block(-8,27,-3,ICE:0)
Block(-8,27,-2,PACKED_ICE:0)
Block(-8,27,-1,PACKED_ICE:0)
Block(-8,27,0,PACKED_ICE:0)
Block(-8,27,1,PACKED_ICE:0)
Block(-8,27,2,PACKED_ICE:0)
Block(-8,27,3,PACKED_ICE:0)
Block(-8,27,4,PACKED_ICE:0)
Block(-8,28,-5,ICE:0)
Block(-8,28,-4,ICE:0)
Block(-8,28,-3,ICE:0)
Block(-8,28,-2,PACKED_ICE:0)
Block(-8,28,-1,PACKED_ICE:0)
Block(-8,28,0,PACKED_ICE:0)
Block(-8,28,1,PACKED_ICE:0)
Block(-8,28,2,PACKED_ICE:0)
Block(-8,28,3,PACKED_ICE:0)
Block(-8,28,4,PACKED_ICE:0)
Block(-8,29,-5,ICE:0)
Block(-8,29,-4,ICE:0)
Block(-8,29,-3,ICE:0)
Block(-8,29,-2,PACKED_ICE:0)
Block(-8,29,-1,PACKED_ICE:0)
Block(-8,29,0,PACKED_ICE:0)
Block(-8,29,1,PACKED_ICE:0)
Block(-8,29,2,PACKED_ICE:0)
Block(-8,29,3,PACKED_ICE:0)
Block(-8,29,4,PACKED_ICE:0)
Block(-8,30,-4,ICE:0)
Block(-8,30,-3,ICE:0)
Block(-8,30,-2,PACKED_ICE:0)
Block(-8,30,-1,PACKED_ICE:0)
Block(-8,30,0,PACKED_ICE:0)
Block(-8,30,1,PACKED_ICE:0)
Block(-8,30,2,PACKED_ICE:0)
Block(-8,30,3,PACKED_ICE:0)
Block(-8,30,4,PACKED_ICE:0)
Block(-8,31,-4,SNOW:0)
Block(-8,31,-3,PACKED_ICE:0)
Block(-8,31,-2,PACKED_ICE:0)
Block(-8,31,-1,PACKED_ICE:0)
Block(-8,31,0,PACKED_ICE:0)
Block(-8,31,1,PACKED_ICE:0)
Block(-8,31,2,ICE:0)
Block(-8,31,3,ICE:0)
Block(-8,31,4,ICE:0)
Block(-8,32,-3,SNOW:0)
Block(-8,32,-2,PACKED_ICE:0)
Block(-8,32,-1,PACKED_ICE:0)
Block(-8,32,0,PACKED_ICE:0)
Block(-8,32,1,PACKED_ICE:0)
Block(-8,32,2,PACKED_ICE:0)
Block(-8,32,3,ICE:0)
Block(-8,32,4,ICE:0)
Block(-8,32,5,ICE:0)
Block(-8,32,7,ICE:0)
Block(-8,33,-1,PACKED_ICE:0)
Block(-8,33,0,PACKED_ICE:0)
Block(-8,33,1,PACKED_ICE:0)
Block(-8,33,2,PACKED_ICE:0)
Block(-8,33,3,PACKED_ICE:0)
Block(-8,33,4,ICE:0)
Block(-8,33,5,ICE:0)
Block(-8,33,7,ICE:0)
Block(-8,34,-2,PACKED_ICE:0)
Block(-8,34,-1,PACKED_ICE:0)
Block(-8,34,0,LOG_2:1)
Block(-8,34,1,PACKED_ICE:0)
Block(-8,34,2,PACKED_ICE:0)
Block(-8,34,3,PACKED_ICE:0)
Block(-8,34,4,ICE:0)
Block(-8,34,5,ICE:0)
Block(-8,34,6,ICE:0)
Block(-8,34,7,ICE:0)
Block(-8,35,-3,PACKED_ICE:0)
Block(-8,35,-2,PACKED_ICE:0)
Block(-8,35,0,SNOW:5)
Block(-8,35,2,ICE:0)
Block(-8,35,3,LOG_2:1)
Block(-8,35,4,PACKED_ICE:0)
Block(-8,35,5,PACKED_ICE:0)
Block(-8,35,6,PACKED_ICE:0)
Block(-8,35,7,ICE:0)
Block(-8,36,-5,LOG_2:1)
Block(-8,36,-4,PACKED_ICE:0)
Block(-8,36,3,SNOW:5)
Block(-8,36,4,LOG_2:1)
Block(-8,36,5,LOG_2:1)
Block(-8,36,6,PACKED_ICE:0)
Block(-8,36,7,PACKED_ICE:0)
Block(-8,36,8,ICE:0)
Block(-8,37,-6,LOG_2:1)
Block(-8,37,-5,SNOW:5)
Block(-8,37,4,SNOW:5)
Block(-8,37,5,SNOW_BLOCK:0)
Block(-8,37,6,LOG_2:1)
Block(-8,37,7,PACKED_ICE:0)
Block(-8,37,8,ICE:0)
Block(-8,38,-6,PACKED_ICE:0)
Block(-8,38,5,SNOW:3)
Block(-8,38,6,LOG_2:1)
Block(-8,38,7,PACKED_ICE:0)
Block(-8,38,8,ICE:0)
Block(-8,39,-7,ICE:0)
Block(-8,39,-6,PACKED_ICE:0)
Block(-8,39,6,SNOW:5)
Block(-8,39,7,WOOD:5)
Block(-8,39,8,PACKED_ICE:0)
Block(-8,40,-7,ICE:0)
Block(-8,40,-6,ICE:0)
Block(-8,40,-5,PACKED_ICE:0)
Block(-8,40,-4,ICE:0)
Block(-8,40,-3,ICE:0)
Block(-8,40,7,PACKED_ICE:0)
Block(-8,40,8,PACKED_ICE:0)
Block(-8,41,-6,ICE:0)
Block(-8,41,-5,ICE:0)
Block(-8,41,-3,SNOW:0)
Block(-8,41,7,ICE:0)
Block(-8,41,8,SNOW:0)
Block(-8,42,-5,SNOW:0)
Block(-7,9,6,PACKED_ICE:0)
Block(-7,10,2,ICE:0)
Block(-7,10,3,ICE:0)
Block(-7,10,6,PACKED_ICE:0)
Block(-7,11,1,ICE:0)
Block(-7,11,2,ICE:0)
Block(-7,11,3,PACKED_ICE:0)
Block(-7,11,4,PACKED_ICE:0)
Block(-7,11,6,PACKED_ICE:0)
Block(-7,12,0,PACKED_ICE:0)
Block(-7,12,1,PACKED_ICE:0)
Block(-7,12,2,PACKED_ICE:0)
Block(-7,12,3,PACKED_ICE:0)
Block(-7,12,4,PACKED_ICE:0)
Block(-7,12,5,PACKED_ICE:0)
Block(-7,12,6,PACKED_ICE:0)
Block(-7,12,7,PACKED_ICE:0)
Block(-7,13,-1,PACKED_ICE:0)
Block(-7,13,0,PACKED_ICE:0)
Block(-7,13,1,PACKED_ICE:0)
Block(-7,13,2,PACKED_ICE:0)
Block(-7,13,3,PACKED_ICE:0)
Block(-7,13,4,PACKED_ICE:0)
Block(-7,13,5,PACKED_ICE:0)
Block(-7,13,6,PACKED_ICE:0)
Block(-7,13,7,PACKED_ICE:0)
Block(-7,14,-2,ICE:0)
Block(-7,14,-1,PACKED_ICE:0)
Block(-7,14,0,PACKED_ICE:0)
Block(-7,14,1,PACKED_ICE:0)
Block(-7,14,2,PACKED_ICE:0)
Block(-7,14,3,PACKED_ICE:0)
Block(-7,14,4,PACKED_ICE:0)
Block(-7,14,5,PACKED_ICE:0)
Block(-7,14,6,PACKED_ICE:0)
Block(-7,14,7,ICE:0)
Block(-7,15,-3,ICE:0)
Block(-7,15,-2,ICE:0)
Block(-7,15,-1,ICE:0)
Block(-7,15,0,PACKED_ICE:0)
Block(-7,15,1,PACKED_ICE:0)
Block(-7,15,2,PACKED_ICE:0)
Block(-7,15,3,PACKED_ICE:0)
Block(-7,15,4,PACKED_ICE:0)
Block(-7,15,5,PACKED_ICE:0)
Block(-7,15,6,PACKED_ICE:0)
Block(-7,15,7,ICE:0)
Block(-7,16,-5,ICE:0)
Block(-7,16,-4,ICE:0)
Block(-7,16,-3,ICE:0)
Block(-7,16,-2,ICE:0)
Block(-7,16,-1,PACKED_ICE:0)
Block(-7,16,0,PACKED_ICE:0)
Block(-7,16,1,PACKED_ICE:0)
Block(-7,16,2,PACKED_ICE:0)
Block(-7,16,3,PACKED_ICE:0)
Block(-7,16,4,PACKED_ICE:0)
Block(-7,16,5,PACKED_ICE:0)
Block(-7,16,6,PACKED_ICE:0)
Block(-7,16,7,ICE:0)
Block(-7,16,8,ICE:0)
Block(-7,17,-5,ICE:0)
Block(-7,17,-4,ICE:0)
Block(-7,17,-3,ICE:0)
Block(-7,17,-2,PACKED_ICE:0)
Block(-7,17,-1,PACKED_ICE:0)
Block(-7,17,0,PACKED_ICE:0)
Block(-7,17,1,PACKED_ICE:0)
Block(-7,17,2,PACKED_ICE:0)
Block(-7,17,3,PACKED_ICE:0)
Block(-7,17,4,PACKED_ICE:0)
Block(-7,17,5,PACKED_ICE:0)
Block(-7,17,6,PACKED_ICE:0)
Block(-7,17,7,PACKED_ICE:0)
Block(-7,17,8,ICE:0)
Block(-7,18,-6,ICE:0)
Block(-7,18,-5,ICE:0)
Block(-7,18,-4,PACKED_ICE:0)
Block(-7,18,-3,ICE:0)
Block(-7,18,-2,PACKED_ICE:0)
Block(-7,18,-1,PACKED_ICE:0)
Block(-7,18,0,PACKED_ICE:0)
Block(-7,18,1,PACKED_ICE:0)
Block(-7,18,2,PACKED_ICE:0)
Block(-7,18,3,PACKED_ICE:0)
Block(-7,18,4,PACKED_ICE:0)
Block(-7,18,5,PACKED_ICE:0)
Block(-7,18,6,PACKED_ICE:0)
Block(-7,18,7,ICE:0)
Block(-7,19,-7,ICE:0)
Block(-7,19,-6,ICE:0)
Block(-7,19,-5,ICE:0)
Block(-7,19,-4,ICE:0)
Block(-7,19,-3,ICE:0)
Block(-7,19,-2,PACKED_ICE:0)
Block(-7,19,-1,PACKED_ICE:0)
Block(-7,19,0,PACKED_ICE:0)
Block(-7,19,1,PACKED_ICE:0)
Block(-7,19,2,PACKED_ICE:0)
Block(-7,19,3,PACKED_ICE:0)
Block(-7,19,4,PACKED_ICE:0)
Block(-7,19,5,PACKED_ICE:0)
Block(-7,19,6,PACKED_ICE:0)
Block(-7,19,7,PACKED_ICE:0)
Block(-7,20,-7,PACKED_ICE:0)
Block(-7,20,-6,ICE:0)
Block(-7,20,-5,ICE:0)
Block(-7,20,-4,ICE:0)
Block(-7,20,-3,ICE:0)
Block(-7,20,-2,ICE:0)
Block(-7,20,-1,PACKED_ICE:0)
Block(-7,20,0,PACKED_ICE:0)
Block(-7,20,1,PACKED_ICE:0)
Block(-7,20,2,PACKED_ICE:0)
Block(-7,20,3,PACKED_ICE:0)
Block(-7,20,4,PACKED_ICE:0)
Block(-7,20,5,PACKED_ICE:0)
Block(-7,20,6,PACKED_ICE:0)
Block(-7,21,-2,ICE:0)
Block(-7,21,-1,ICE:0)
Block(-7,21,0,PACKED_ICE:0)
Block(-7,21,1,PACKED_ICE:0)
Block(-7,21,2,PACKED_ICE:0)
Block(-7,21,3,PACKED_ICE:0)
Block(-7,21,4,PACKED_ICE:0)
Block(-7,21,5,ICE:0)
Block(-7,21,6,ICE:0)
Block(-7,22,-2,PACKED_ICE:0)
Block(-7,22,-1,ICE:0)
Block(-7,22,0,ICE:0)
Block(-7,22,1,PACKED_ICE:0)
Block(-7,22,2,PACKED_ICE:0)
Block(-7,22,3,PACKED_ICE:0)
Block(-7,22,4,PACKED_ICE:0)
Block(-7,22,5,ICE:0)
Block(-7,22,6,ICE:0)
Block(-7,23,-2,PACKED_ICE:0)
Block(-7,23,-1,ICE:0)
Block(-7,23,0,PACKED_ICE:0)
Block(-7,23,1,PACKED_ICE:0)
Block(-7,23,2,PACKED_ICE:0)
Block(-7,23,3,PACKED_ICE:0)
Block(-7,23,4,PACKED_ICE:0)
Block(-7,23,5,ICE:0)
Block(-7,23,6,ICE:0)
Block(-7,24,-6,ICE:0)
Block(-7,24,-5,ICE:0)
Block(-7,24,-2,PACKED_ICE:0)
Block(-7,24,1,PACKED_ICE:0)
Block(-7,24,2,PACKED_ICE:0)
Block(-7,24,3,PACKED_ICE:0)
Block(-7,24,4,PACKED_ICE:0)
Block(-7,24,5,PACKED_ICE:0)
Block(-7,24,6,PACKED_ICE:0)
Block(-7,25,-6,PACKED_ICE:0)
Block(-7,25,-5,ICE:0)
Block(-7,25,-4,PACKED_ICE:0)
Block(-7,25,-3,ICE:0)
Block(-7,25,2,PACKED_ICE:0)
Block(-7,25,3,PACKED_ICE:0)
Block(-7,25,4,PACKED_ICE:0)
Block(-7,25,5,PACKED_ICE:0)
Block(-7,25,6,PACKED_ICE:0)
Block(-7,26,-6,PACKED_ICE:0)
Block(-7,26,-5,ICE:0)
Block(-7,26,-4,PACKED_ICE:0)
Block(-7,26,-3,ICE:0)
Block(-7,26,-2,PACKED_ICE:0)
Block(-7,26,1,PACKED_ICE:0)
Block(-7,26,2,PACKED_ICE:0)
Block(-7,26,3,PACKED_ICE:0)
Block(-7,26,4,PACKED_ICE:0)
Block(-7,26,5,PACKED_ICE:0)
Block(-7,27,-6,PACKED_ICE:0)
Block(-7,27,-5,ICE:0)
Block(-7,27,-4,PACKED_ICE:0)
Block(-7,27,-3,ICE:0)
Block(-7,27,-2,PACKED_ICE:0)
Block(-7,27,-1,PACKED_ICE:0)
Block(-7,27,0,PACKED_ICE:0)
Block(-7,27,1,PACKED_ICE:0)
Block(-7,27,2,PACKED_ICE:0)
Block(-7,27,3,PACKED_ICE:0)
Block(-7,27,4,PACKED_ICE:0)
Block(-7,27,5,PACKED_ICE:0)
Block(-7,28,-6,ICE:0)
Block(-7,28,-5,ICE:0)
Block(-7,28,-4,ICE:0)
Block(-7,28,-3,ICE:0)
Block(-7,28,-2,PACKED_ICE:0)
Block(-7,28,-1,PACKED_ICE:0)
Block(-7,28,0,PACKED_ICE:0)
Block(-7,28,1,PACKED_ICE:0)
Block(-7,28,2,PACKED_ICE:0)
Block(-7,28,3,PACKED_ICE:0)
Block(-7,28,4,PACKED_ICE:0)
Block(-7,28,5,PACKED_ICE:0)
Block(-7,29,-5,ICE:0)
Block(-7,29,-4,ICE:0)
Block(-7,29,-3,ICE:0)
Block(-7,29,-2,PACKED_ICE:0)
Block(-7,29,-1,PACKED_ICE:0)
Block(-7,29,0,PACKED_ICE:0)
Block(-7,29,1,PACKED_ICE:0)
Block(-7,29,2,PACKED_ICE:0)
Block(-7,29,3,PACKED_ICE:0)
Block(-7,29,4,PACKED_ICE:0)
Block(-7,29,5,PACKED_ICE:0)
Block(-7,30,-5,ICE:0)
Block(-7,30,-4,ICE:0)
Block(-7,30,-3,ICE:0)
Block(-7,30,-2,PACKED_ICE:0)
Block(-7,30,-1,PACKED_ICE:0)
Block(-7,30,0,PACKED_ICE:0)
Block(-7,30,1,PACKED_ICE:0)
Block(-7,30,2,PACKED_ICE:0)
Block(-7,30,3,PACKED_ICE:0)
Block(-7,30,4,PACKED_ICE:0)
Block(-7,30,5,SNOW:0)
Block(-7,31,-5,SNOW:0)
Block(-7,31,-4,ICE:0)
Block(-7,31,-3,ICE:0)
Block(-7,31,-2,PACKED_ICE:0)
Block(-7,31,-1,PACKED_ICE:0)
Block(-7,31,0,PACKED_ICE:0)
Block(-7,31,1,ICE:0)
Block(-7,31,2,PACKED_ICE:0)
Block(-7,31,3,ICE:0)
Block(-7,31,4,ICE:0)
Block(-7,32,-3,ICE:0)
Block(-7,32,-2,ICE:0)
Block(-7,32,-1,PACKED_ICE:0)
Block(-7,32,0,PACKED_ICE:0)
Block(-7,32,1,PACKED_ICE:0)
Block(-7,32,2,PACKED_ICE:0)
Block(-7,32,3,PACKED_ICE:0)
Block(-7,32,4,ICE:0)
Block(-7,32,5,ICE:0)
Block(-7,33,-2,ICE:0)
Block(-7,33,-1,PACKED_ICE:0)
Block(-7,33,0,PACKED_ICE:0)
Block(-7,33,1,PACKED_ICE:0)
Block(-7,33,2,PACKED_ICE:0)
Block(-7,33,3,ICE:0)
Block(-7,33,4,ICE:0)
Block(-7,33,5,ICE:0)
Block(-7,33,6,ICE:0)
Block(-7,34,-3,ICE:0)
Block(-7,34,-2,PACKED_ICE:0)
Block(-7,34,-1,PACKED_ICE:0)
Block(-7,34,0,LOG_2:1)
Block(-7,34,1,PACKED_ICE:0)
Block(-7,34,2,PACKED_ICE:0)
Block(-7,34,3,PACKED_ICE:0)
Block(-7,34,4,PACKED_ICE:0)
Block(-7,34,5,PACKED_ICE:0)
Block(-7,34,6,PACKED_ICE:0)
Block(-7,34,7,ICE:0)
Block(-7,35,-4,ICE:0)
Block(-7,35,-3,PACKED_ICE:0)
Block(-7,35,-2,PACKED_ICE:0)
Block(-7,35,0,SNOW:4)
Block(-7,35,1,ICE:0)
Block(-7,35,2,PACKED_ICE:0)
Block(-7,35,3,PACKED_ICE:0)
Block(-7,35,4,PACKED_ICE:0)
Block(-7,35,5,PACKED_ICE:0)
Block(-7,35,6,PACKED_ICE:0)
Block(-7,35,7,ICE:0)
Block(-7,35,8,ICE:0)
Block(-7,36,-5,LOG_2:1)
Block(-7,36,-4,PACKED_ICE:0)
Block(-7,36,-3,PACKED_ICE:0)
Block(-7,36,-2,PACKED_ICE:0)
Block(-7,36,3,ICE:0)
Block(-7,36,4,LOG_2:1)
Block(-7,36,5,LOG_2:1)
Block(-7,36,6,PACKED_ICE:0)
Block(-7,36,7,PACKED_ICE:0)
Block(-7,36,8,ICE:0)
Block(-7,37,-6,ICE:0)
Block(-7,37,-5,ICE:0)
Block(-7,37,3,SNOW_BLOCK:0)
Block(-7,37,4,SNOW_BLOCK:0)
Block(-7,37,5,SNOW_BLOCK:0)
Block(-7,37,6,LOG_2:1)
Block(-7,37,7,PACKED_ICE:0)
Block(-7,37,8,ICE:0)
Block(-7,38,-7,ICE:0)
Block(-7,38,-6,ICE:0)
Block(-7,38,-5,PACKED_ICE:0)
Block(-7,38,3,SNOW:0)
Block(-7,38,4,SNOW:2)
Block(-7,38,5,SNOW:5)
Block(-7,38,6,LOG_2:1)
Block(-7,38,7,PACKED_ICE:0)
Block(-7,38,8,ICE:0)
Block(-7,39,-7,ICE:0)
Block(-7,39,-6,PACKED_ICE:0)
Block(-7,39,6,SNOW:1)
Block(-7,39,7,PACKED_ICE:0)
Block(-7,39,8,PACKED_ICE:0)
Block(-7,40,-7,ICE:0)
Block(-7,40,-6,ICE:0)
Block(-7,40,-5,ICE:0)
Block(-7,40,-4,ICE:0)
Block(-7,40,7,ICE:0)
Block(-7,40,8,SNOW:0)
Block(-7,41,-6,ICE:0)
Block(-7,41,7,ICE:0)
Block(-6,10,1,ICE:0)
Block(-6,10,2,ICE:0)
Block(-6,11,0,ICE:0)
Block(-6,11,1,ICE:0)
Block(-6,11,2,ICE:0)
Block(-6,11,3,ICE:0)
Block(-6,12,-1,PACKED_ICE:0)
Block(-6,12,0,PACKED_ICE:0)
Block(-6,12,1,PACKED_ICE:0)
Block(-6,12,2,ICE:0)
Block(-6,12,3,ICE:0)
Block(-6,12,4,ICE:0)
Block(-6,13,-1,PACKED_ICE:0)
Block(-6,13,0,PACKED_ICE:0)
Block(-6,13,1,PACKED_ICE:0)
Block(-6,13,2,PACKED_ICE:0)
Block(-6,13,3,ICE:0)
Block(-6,13,4,PACKED_ICE:0)
Block(-6,13,5,PACKED_ICE:0)
Block(-6,13,6,PACKED_ICE:0)
Block(-6,14,-2,PACKED_ICE:0)
Block(-6,14,-1,PACKED_ICE:0)
Block(-6,14,0,PACKED_ICE:0)
Block(-6,14,1,PACKED_ICE:0)
Block(-6,14,2,PACKED_ICE:0)
Block(-6,14,3,PACKED_ICE:0)
Block(-6,14,4,PACKED_ICE:0)
Block(-6,14,5,PACKED_ICE:0)
Block(-6,14,6,PACKED_ICE:0)
Block(-6,15,-4,ICE:0)
Block(-6,15,-3,PACKED_ICE:0)
Block(-6,15,-2,PACKED_ICE:0)
Block(-6,15,-1,PACKED_ICE:0)
Block(-6,15,0,PACKED_ICE:0)
Block(-6,15,1,PACKED_ICE:0)
Block(-6,15,2,PACKED_ICE:0)
Block(-6,15,3,PACKED_ICE:0)
Block(-6,15,4,PACKED_ICE:0)
Block(-6,15,5,PACKED_ICE:0)
Block(-6,15,6,PACKED_ICE:0)
Block(-6,15,7,ICE:0)
Block(-6,16,-5,ICE:0)
Block(-6,16,-4,ICE:0)
Block(-6,16,-3,ICE:0)
Block(-6,16,-2,PACKED_ICE:0)
Block(-6,16,-1,PACKED_ICE:0)
Block(-6,16,0,PACKED_ICE:0)
Block(-6,16,1,PACKED_ICE:0)
Block(-6,16,2,PACKED_ICE:0)
Block(-6,16,3,PACKED_ICE:0)
Block(-6,16,4,PACKED_ICE:0)
Block(-6,16,5,PACKED_ICE:0)
Block(-6,16,6,PACKED_ICE:0)
Block(-6,16,7,ICE:0)
Block(-6,16,8,ICE:0)
Block(-6,17,-6,ICE:0)
Block(-6,17,-5,PACKED_ICE:0)
Block(-6,17,-4,ICE:0)
Block(-6,17,-3,PACKED_ICE:0)
Block(-6,17,-2,PACKED_ICE:0)
Block(-6,17,-1,PACKED_ICE:0)
Block(-6,17,0,PACKED_ICE:0)
Block(-6,17,1,PACKED_ICE:0)
Block(-6,17,2,PACKED_ICE:0)
Block(-6,17,3,PACKED_ICE:0)
Block(-6,17,4,PACKED_ICE:0)
Block(-6,17,5,PACKED_ICE:0)
Block(-6,17,6,PACKED_ICE:0)
Block(-6,17,7,ICE:0)
Block(-6,17,8,ICE:0)
Block(-6,18,-6,ICE:0)
Block(-6,18,-5,PACKED_ICE:0)
Block(-6,18,-4,PACKED_ICE:0)
Block(-6,18,-3,PACKED_ICE:0)
Block(-6,18,-2,PACKED_ICE:0)
Block(-6,18,-1,PACKED_ICE:0)
Block(-6,18,0,PACKED_ICE:0)
Block(-6,18,1,PACKED_ICE:0)
Block(-6,18,2,PACKED_ICE:0)
Block(-6,18,3,PACKED_ICE:0)
Block(-6,18,4,PACKED_ICE:0)
Block(-6,18,5,PACKED_ICE:0)
Block(-6,18,6,PACKED_ICE:0)
Block(-6,18,7,ICE:0)
Block(-6,18,8,ICE:0)
Block(-6,19,-7,ICE:0)
Block(-6,19,-6,ICE:0)
Block(-6,19,-5,ICE:0)
Block(-6,19,-4,PACKED_ICE:0)
Block(-6,19,-3,PACKED_ICE:0)
Block(-6,19,-2,PACKED_ICE:0)
Block(-6,19,-1,PACKED_ICE:0)
Block(-6,19,0,PACKED_ICE:0)
Block(-6,19,1,PACKED_ICE:0)
Block(-6,19,2,PACKED_ICE:0)
Block(-6,19,3,PACKED_ICE:0)
Block(-6,19,4,PACKED_ICE:0)
Block(-6,19,5,PACKED_ICE:0)
Block(-6,19,6,PACKED_ICE:0)
Block(-6,19,7,ICE:0)
Block(-6,20,-7,PACKED_ICE:0)
Block(-6,20,-6,ICE:0)
Block(-6,20,-5,ICE:0)
Block(-6,20,-4,ICE:0)
Block(-6,20,-3,ICE:0)
Block(-6,20,-2,ICE:0)
Block(-6,20,-1,ICE:0)
Block(-6,20,0,PACKED_ICE:0)
Block(-6,20,1,PACKED_ICE:0)
Block(-6,20,2,PACKED_ICE:0)
Block(-6,20,3,PACKED_ICE:0)
Block(-6,20,4,PACKED_ICE:0)
Block(-6,20,5,PACKED_ICE:0)
Block(-6,20,6,ICE:0)
Block(-6,20,7,ICE:0)
Block(-6,21,-7,PACKED_ICE:0)
Block(-6,21,-3,ICE:0)
Block(-6,21,-2,ICE:0)
Block(-6,21,-1,ICE:0)
Block(-6,21,0,ICE:0)
Block(-6,21,1,PACKED_ICE:0)
Block(-6,21,2,PACKED_ICE:0)
Block(-6,21,3,PACKED_ICE:0)
Block(-6,21,4,PACKED_ICE:0)
Block(-6,21,5,PACKED_ICE:0)
Block(-6,21,6,ICE:0)
Block(-6,21,7,ICE:0)
Block(-6,22,-1,ICE:0)
Block(-6,22,0,ICE:0)
Block(-6,22,1,PACKED_ICE:0)
Block(-6,22,2,PACKED_ICE:0)
Block(-6,22,3,PACKED_ICE:0)
Block(-6,22,4,PACKED_ICE:0)
Block(-6,22,5,ICE:0)
Block(-6,22,6,ICE:0)
Block(-6,22,7,ICE:0)
Block(-6,23,-7,ICE:0)
Block(-6,23,0,ICE:0)
Block(-6,23,1,PACKED_ICE:0)
Block(-6,23,2,PACKED_ICE:0)
Block(-6,23,3,PACKED_ICE:0)
Block(-6,23,4,PACKED_ICE:0)
Block(-6,23,5,PACKED_ICE:0)
Block(-6,23,6,ICE:0)
Block(-6,24,-7,ICE:0)
Block(-6,24,-6,ICE:0)
Block(-6,24,-5,PACKED_ICE:0)
Block(-6,24,2,PACKED_ICE:0)
Block(-6,24,3,PACKED_ICE:0)
Block(-6,24,4,PACKED_ICE:0)
Block(-6,24,5,PACKED_ICE:0)
Block(-6,24,6,PACKED_ICE:0)
Block(-6,25,-6,ICE:0)
Block(-6,25,-5,PACKED_ICE:0)
Block(-6,25,-4,PACKED_ICE:0)
Block(-6,25,-3,PACKED_ICE:0)
Block(-6,25,2,PACKED_ICE:0)
Block(-6,25,3,PACKED_ICE:0)
Block(-6,25,4,PACKED_ICE:0)
Block(-6,25,5,PACKED_ICE:0)
Block(-6,25,6,PACKED_ICE:0)
Block(-6,26,-5,PACKED_ICE:0)
Block(-6,26,-4,PACKED_ICE:0)
Block(-6,26,-3,ICE:0)
Block(-6,26,-2,ICE:0)
Block(-6,26,2,PACKED_ICE:0)
Block(-6,26,3,PACKED_ICE:0)
Block(-6,26,4,PACKED_ICE:0)
Block(-6,26,5,PACKED_ICE:0)
Block(-6,26,6,PACKED_ICE:0)
Block(-6,27,-5,PACKED_ICE:0)
Block(-6,27,-4,PACKED_ICE:0)
Block(-6,27,-3,PACKED_ICE:0)
Block(-6,27,-2,ICE:0)
Block(-6,27,-1,ICE:0)
Block(-6,27,0,PACKED_ICE:0)
Block(-6,27,1,PACKED_ICE:0)
Block(-6,27,2,PACKED_ICE:0)
Block(-6,27,3,PACKED_ICE:0)
Block(-6,27,4,PACKED_ICE:0)
Block(-6,27,5,PACKED_ICE:0)
Block(-6,27,6,PACKED_ICE:0)
Block(-6,28,-5,ICE:0)
Block(-6,28,-4,PACKED_ICE:0)
Block(-6,28,-3,PACKED_ICE:0)
Block(-6,28,-2,PACKED_ICE:0)
Block(-6,28,-1,PACKED_ICE:0)
Block(-6,28,0,PACKED_ICE:0)
Block(-6,28,1,PACKED_ICE:0)
Block(-6,28,2,PACKED_ICE:0)
Block(-6,28,3,PACKED_ICE:0)
Block(-6,28,4,PACKED_ICE:0)
Block(-6,28,5,PACKED_ICE:0)
Block(-6,29,-5,ICE:0)
Block(-6,29,-4,ICE:0)
Block(-6,29,-3,PACKED_ICE:0)
Block(-6,29,-2,PACKED_ICE:0)
Block(-6,29,-1,PACKED_ICE:0)
Block(-6,29,0,PACKED_ICE:0)
Block(-6,29,1,PACKED_ICE:0)
Block(-6,29,2,PACKED_ICE:0)
Block(-6,29,3,PACKED_ICE:0)
Block(-6,29,4,PACKED_ICE:0)
Block(-6,29,5,PACKED_ICE:0)
Block(-6,30,-5,ICE:0)
Block(-6,30,-4,PACKED_ICE:0)
Block(-6,30,-3,PACKED_ICE:0)
Block(-6,30,-2,PACKED_ICE:0)
Block(-6,30,-1,PACKED_ICE:0)
Block(-6,30,0,PACKED_ICE:0)
Block(-6,30,1,PACKED_ICE:0)
Block(-6,30,2,PACKED_ICE:0)
Block(-6,30,3,PACKED_ICE:0)
Block(-6,30,4,PACKED_ICE:0)
Block(-6,30,5,PACKED_ICE:0)
Block(-6,31,-5,ICE:0)
Block(-6,31,-4,PACKED_ICE:0)
Block(-6,31,-3,PACKED_ICE:0)
Block(-6,31,-2,PACKED_ICE:0)
Block(-6,31,-1,PACKED_ICE:0)
Block(-6,31,1,ICE:0)
Block(-6,31,2,ICE:0)
Block(-6,31,3,PACKED_ICE:0)
Block(-6,31,4,PACKED_ICE:0)
Block(-6,31,5,ICE:0)
Block(-6,32,-3,PACKED_ICE:0)
Block(-6,32,-2,PACKED_ICE:0)
Block(-6,32,-1,PACKED_ICE:0)
Block(-6,32,0,PACKED_ICE:0)
Block(-6,32,1,PACKED_ICE:0)
Block(-6,32,2,PACKED_ICE:0)
Block(-6,32,3,PACKED_ICE:0)
Block(-6,32,4,PACKED_ICE:0)
Block(-6,32,5,PACKED_ICE:0)
Block(-6,33,-2,PACKED_ICE:0)
Block(-6,33,-1,PACKED_ICE:0)
Block(-6,33,0,PACKED_ICE:0)
Block(-6,33,1,PACKED_ICE:0)
Block(-6,33,2,PACKED_ICE:0)
Block(-6,33,3,PACKED_ICE:0)
Block(-6,33,4,PACKED_ICE:0)
Block(-6,33,5,PACKED_ICE:0)
Block(-6,33,6,ICE:0)
Block(-6,33,7,ICE:0)
Block(-6,34,-3,PACKED_ICE:0)
Block(-6,34,-2,PACKED_ICE:0)
Block(-6,34,-1,PACKED_ICE:0)
Block(-6,34,0,PACKED_ICE:0)
Block(-6,34,1,PACKED_ICE:0)
Block(-6,34,2,PACKED_ICE:0)
Block(-6,34,3,PACKED_ICE:0)
Block(-6,34,4,PACKED_ICE:0)
Block(-6,34,5,PACKED_ICE:0)
Block(-6,34,6,PACKED_ICE:0)
Block(-6,34,7,ICE:0)
Block(-6,35,-7,PACKED_ICE:0)
Block(-6,35,-4,PACKED_ICE:0)
Block(-6,35,-3,PACKED_ICE:0)
Block(-6,35,-2,PACKED_ICE:0)
Block(-6,35,-1,PACKED_ICE:0)
Block(-6,35,1,ICE:0)
Block(-6,35,2,LOG_2:1)
Block(-6,35,3,PACKED_ICE:0)
Block(-6,35,4,PACKED_ICE:0)
Block(-6,35,5,PACKED_ICE:0)
Block(-6,35,6,PACKED_ICE:0)
Block(-6,35,7,PACKED_ICE:0)
Block(-6,35,8,ICE:0)
Block(-6,36,-7,PACKED_ICE:0)
Block(-6,36,-5,ICE:0)
Block(-6,36,-4,PACKED_ICE:0)
Block(-6,36,-3,PACKED_ICE:0)
Block(-6,36,-2,PACKED_ICE:0)
Block(-6,36,2,SNOW:4)
Block(-6,36,3,ICE:0)
Block(-6,36,4,LOG_2:1)
Block(-6,36,5,LOG_2:1)
Block(-6,36,6,PACKED_ICE:0)
Block(-6,36,7,PACKED_ICE:0)
Block(-6,36,8,ICE:0)
Block(-6,37,-7,PACKED_ICE:0)
Block(-6,37,-5,ICE:0)
Block(-6,37,-4,PACKED_ICE:0)
Block(-6,37,-3,PACKED_ICE:0)
Block(-6,37,3,SNOW:0)
Block(-6,37,4,SNOW_BLOCK:0)
Block(-6,37,5,SNOW_BLOCK:0)
Block(-6,37,6,LOG_2:1)
Block(-6,37,7,PACKED_ICE:0)
Block(-6,37,8,ICE:0)
Block(-6,38,-7,PACKED_ICE:0)
Block(-6,38,-6,LOG_2:1)
Block(-6,38,-5,ICE:0)
Block(-6,38,-3,PACKED_ICE:0)
Block(-6,38,4,SNOW:2)
Block(-6,38,5,SNOW_BLOCK:0)
Block(-6,38,6,LOG_2:1)
Block(-6,38,7,PACKED_ICE:0)
Block(-6,38,8,ICE:0)
Block(-6,39,-7,PACKED_ICE:0)
Block(-6,39,-6,ICE:0)
Block(-6,39,-5,ICE:0)
Block(-6,39,5,SNOW:2)
Block(-6,39,6,SNOW:7)
Block(-6,39,7,PACKED_ICE:0)
Block(-6,39,8,SNOW:0)
Block(-6,40,-7,ICE:0)
Block(-6,40,-6,ICE:0)
Block(-6,40,-5,ICE:0)
Block(-6,40,7,PACKED_ICE:0)
Block(-6,41,-7,SNOW:0)
Block(-6,41,7,ICE:0)
Block(-5,10,0,ICE:0)
Block(-5,10,1,ICE:0)
Block(-5,11,0,ICE:0)
Block(-5,11,1,ICE:0)
Block(-5,11,2,ICE:0)
Block(-5,12,-1,PACKED_ICE:0)
Block(-5,12,0,PACKED_ICE:0)
Block(-5,12,1,ICE:0)
Block(-5,12,2,ICE:0)
Block(-5,12,3,ICE:0)
Block(-5,13,-4,ICE:0)
Block(-5,13,-1,PACKED_ICE:0)
Block(-5,13,0,PACKED_ICE:0)
Block(-5,13,1,PACKED_ICE:0)
Block(-5,13,2,ICE:0)
Block(-5,13,3,ICE:0)
Block(-5,13,4,ICE:0)
Block(-5,14,-4,ICE:0)
Block(-5,14,-3,PACKED_ICE:0)
Block(-5,14,-2,PACKED_ICE:0)
Block(-5,14,-1,PACKED_ICE:0)
Block(-5,14,0,PACKED_ICE:0)
Block(-5,14,1,PACKED_ICE:0)
Block(-5,14,2,PACKED_ICE:0)
Block(-5,14,3,ICE:0)
Block(-5,14,4,PACKED_ICE:0)
Block(-5,14,5,PACKED_ICE:0)
Block(-5,15,-5,ICE:0)
Block(-5,15,-4,ICE:0)
Block(-5,15,-3,PACKED_ICE:0)
Block(-5,15,-2,PACKED_ICE:0)
Block(-5,15,-1,PACKED_ICE:0)
Block(-5,15,0,PACKED_ICE:0)
Block(-5,15,1,PACKED_ICE:0)
Block(-5,15,2,PACKED_ICE:0)
Block(-5,15,3,PACKED_ICE:0)
Block(-5,15,4,PACKED_ICE:0)
Block(-5,15,5,PACKED_ICE:0)
Block(-5,15,6,PACKED_ICE:0)
Block(-5,15,7,PACKED_ICE:0)
Block(-5,16,-6,ICE:0)
Block(-5,16,-5,ICE:0)
Block(-5,16,-4,ICE:0)
Block(-5,16,-3,PACKED_ICE:0)
Block(-5,16,-2,PACKED_ICE:0)
Block(-5,16,-1,PACKED_ICE:0)
Block(-5,16,0,PACKED_ICE:0)
Block(-5,16,1,PACKED_ICE:0)
Block(-5,16,2,PACKED_ICE:0)
Block(-5,16,3,PACKED_ICE:0)
Block(-5,16,4,PACKED_ICE:0)
Block(-5,16,5,PACKED_ICE:0)
Block(-5,16,6,PACKED_ICE:0)
Block(-5,16,7,ICE:0)
Block(-5,16,8,ICE:0)
Block(-5,17,-6,ICE:0)
Block(-5,17,-5,ICE:0)
Block(-5,17,-4,PACKED_ICE:0)
Block(-5,17,-3,PACKED_ICE:0)
Block(-5,17,-2,PACKED_ICE:0)
Block(-5,17,-1,PACKED_ICE:0)
Block(-5,17,0,PACKED_ICE:0)
Block(-5,17,1,PACKED_ICE:0)
Block(-5,17,2,PACKED_ICE:0)
Block(-5,17,3,PACKED_ICE:0)
Block(-5,17,4,PACKED_ICE:0)
Block(-5,17,5,PACKED_ICE:0)
Block(-5,17,6,PACKED_ICE:0)
Block(-5,17,7,ICE:0)
Block(-5,17,8,ICE:0)
Block(-5,18,-7,ICE:0)
Block(-5,18,-6,ICE:0)
Block(-5,18,-5,PACKED_ICE:0)
Block(-5,18,-4,PACKED_ICE:0)
Block(-5,18,-3,PACKED_ICE:0)
Block(-5,18,-2,PACKED_ICE:0)
Block(-5,18,-1,PACKED_ICE:0)
Block(-5,18,0,PACKED_ICE:0)
Block(-5,18,1,PACKED_ICE:0)
Block(-5,18,2,PACKED_ICE:0)
Block(-5,18,3,PACKED_ICE:0)
Block(-5,18,4,PACKED_ICE:0)
Block(-5,18,5,PACKED_ICE:0)
Block(-5,18,6,PACKED_ICE:0)
Block(-5,18,7,ICE:0)
Block(-5,18,8,ICE:0)
Block(-5,19,-7,ICE:0)
Block(-5,19,-6,PACKED_ICE:0)
Block(-5,19,-5,PACKED_ICE:0)
Block(-5,19,-4,PACKED_ICE:0)
Block(-5,19,-3,PACKED_ICE:0)
Block(-5,19,-2,PACKED_ICE:0)
Block(-5,19,-1,PACKED_ICE:0)
Block(-5,19,0,PACKED_ICE:0)
Block(-5,19,1,PACKED_ICE:0)
Block(-5,19,2,PACKED_ICE:0)
Block(-5,19,3,PACKED_ICE:0)
Block(-5,19,4,PACKED_ICE:0)
Block(-5,19,5,PACKED_ICE:0)
Block(-5,19,6,ICE:0)
Block(-5,19,7,ICE:0)
Block(-5,19,8,PACKED_ICE:0)
Block(-5,20,-7,PACKED_ICE:0)
Block(-5,20,-6,PACKED_ICE:0)
Block(-5,20,-5,PACKED_ICE:0)
Block(-5,20,-4,PACKED_ICE:0)
Block(-5,20,-3,ICE:0)
Block(-5,20,-2,ICE:0)
Block(-5,20,-1,PACKED_ICE:0)
Block(-5,20,0,PACKED_ICE:0)
Block(-5,20,1,PACKED_ICE:0)
Block(-5,20,2,PACKED_ICE:0)
Block(-5,20,3,PACKED_ICE:0)
Block(-5,20,4,PACKED_ICE:0)
Block(-5,20,5,PACKED_ICE:0)
Block(-5,20,6,ICE:0)
Block(-5,20,7,ICE:0)
Block(-5,21,-7,PACKED_ICE:0)
Block(-5,21,-6,PACKED_ICE:0)
Block(-5,21,-3,ICE:0)
Block(-5,21,-2,ICE:0)
Block(-5,21,-1,ICE:0)
Block(-5,21,0,PACKED_ICE:0)
Block(-5,21,1,PACKED_ICE:0)
Block(-5,21,2,PACKED_ICE:0)
Block(-5,21,3,PACKED_ICE:0)
Block(-5,21,4,PACKED_ICE:0)
Block(-5,21,5,PACKED_ICE:0)
Block(-5,21,6,ICE:0)
Block(-5,21,7,ICE:0)
Block(-5,22,-7,PACKED_ICE:0)
Block(-5,22,-6,PACKED_ICE:0)
Block(-5,22,0,ICE:0)
Block(-5,22,1,PACKED_ICE:0)
Block(-5,22,2,PACKED_ICE:0)
Block(-5,22,3,PACKED_ICE:0)
Block(-5,22,4,PACKED_ICE:0)
Block(-5,22,5,PACKED_ICE:0)
Block(-5,22,6,PACKED_ICE:0)
Block(-5,22,7,ICE:0)
Block(-5,23,-7,ICE:0)
Block(-5,23,-6,PACKED_ICE:0)
Block(-5,23,-5,PACKED_ICE:0)
Block(-5,23,1,PACKED_ICE:0)
Block(-5,23,2,PACKED_ICE:0)
Block(-5,23,3,PACKED_ICE:0)
Block(-5,23,4,PACKED_ICE:0)
Block(-5,23,5,PACKED_ICE:0)
Block(-5,23,6,PACKED_ICE:0)
Block(-5,23,7,PACKED_ICE:0)
Block(-5,24,-7,ICE:0)
Block(-5,24,-6,ICE:0)
Block(-5,24,-5,ICE:0)
Block(-5,24,2,PACKED_ICE:0)
Block(-5,24,3,PACKED_ICE:0)
Block(-5,24,4,ICE:0)
Block(-5,24,5,PACKED_ICE:0)
Block(-5,24,6,PACKED_ICE:0)
Block(-5,24,7,PACKED_ICE:0)
Block(-5,25,-7,ICE:0)
Block(-5,25,-6,ICE:0)
Block(-5,25,-5,PACKED_ICE:0)
Block(-5,25,-4,ICE:0)
Block(-5,25,3,ICE:0)
Block(-5,25,4,ICE:0)
Block(-5,25,5,ICE:0)
Block(-5,25,6,PACKED_ICE:0)
Block(-5,26,-7,ICE:0)
Block(-5,26,-6,ICE:0)
Block(-5,26,-5,ICE:0)
Block(-5,26,-4,PACKED_ICE:0)
Block(-5,26,-3,ICE:0)
Block(-5,26,-2,ICE:0)
Block(-5,26,-1,ICE:0)
Block(-5,26,2,PACKED_ICE:0)
Block(-5,26,3,PACKED_ICE:0)
Block(-5,26,4,ICE:0)
Block(-5,26,5,PACKED_ICE:0)
Block(-5,26,6,PACKED_ICE:0)
Block(-5,27,-6,ICE:0)
Block(-5,27,-5,ICE:0)
Block(-5,27,-4,PACKED_ICE:0)
Block(-5,27,-3,ICE:0)
Block(-5,27,-2,ICE:0)
Block(-5,27,-1,ICE:0)
Block(-5,27,0,ICE:0)
Block(-5,27,1,ICE:0)
Block(-5,27,2,PACKED_ICE:0)
Block(-5,27,3,PACKED_ICE:0)
Block(-5,27,4,PACKED_ICE:0)
Block(-5,27,5,PACKED_ICE:0)
Block(-5,27,6,PACKED_ICE:0)
Block(-5,28,-6,ICE:0)
Block(-5,28,-5,ICE:0)
Block(-5,28,-4,PACKED_ICE:0)
Block(-5,28,-3,PACKED_ICE:0)
Block(-5,28,-2,PACKED_ICE:0)
Block(-5,28,-1,PACKED_ICE:0)
Block(-5,28,0,ICE:0)
Block(-5,28,1,PACKED_ICE:0)
Block(-5,28,2,PACKED_ICE:0)
Block(-5,28,3,PACKED_ICE:0)
Block(-5,28,4,PACKED_ICE:0)
Block(-5,28,5,PACKED_ICE:0)
Block(-5,28,6,PACKED_ICE:0)
Block(-5,29,-6,ICE:0)
Block(-5,29,-5,ICE:0)
Block(-5,29,-4,PACKED_ICE:0)
Block(-5,29,-3,PACKED_ICE:0)
Block(-5,29,-2,PACKED_ICE:0)
Block(-5,29,-1,PACKED_ICE:0)
Block(-5,29,0,PACKED_ICE:0)
Block(-5,29,1,PACKED_ICE:0)
Block(-5,29,2,PACKED_ICE:0)
Block(-5,29,3,PACKED_ICE:0)
Block(-5,29,4,PACKED_ICE:0)
Block(-5,29,5,PACKED_ICE:0)
Block(-5,29,6,SNOW:0)
Block(-5,30,-6,PACKED_ICE:0)
Block(-5,30,-5,PACKED_ICE:0)
Block(-5,30,-4,PACKED_ICE:0)
Block(-5,30,-3,PACKED_ICE:0)
Block(-5,30,-2,PACKED_ICE:0)
Block(-5,30,-1,PACKED_ICE:0)
Block(-5,30,0,PACKED_ICE:0)
Block(-5,30,1,PACKED_ICE:0)
Block(-5,30,2,PACKED_ICE:0)
Block(-5,30,3,PACKED_ICE:0)
Block(-5,30,4,PACKED_ICE:0)
Block(-5,30,5,PACKED_ICE:0)
Block(-5,31,-6,SNOW:0)
Block(-5,31,-5,PACKED_ICE:0)
Block(-5,31,-4,PACKED_ICE:0)
Block(-5,31,-3,PACKED_ICE:0)
Block(-5,31,-2,PACKED_ICE:0)
Block(-5,31,-1,PACKED_ICE:0)
Block(-5,31,0,PACKED_ICE:0)
Block(-5,31,1,ICE:0)
Block(-5,31,2,PACKED_ICE:0)
Block(-5,31,3,PACKED_ICE:0)
Block(-5,31,4,ICE:0)
Block(-5,31,5,SNOW:0)
Block(-5,32,-4,PACKED_ICE:0)
Block(-5,32,-3,PACKED_ICE:0)
Block(-5,32,-2,PACKED_ICE:0)
Block(-5,32,-1,PACKED_ICE:0)
Block(-5,32,0,PACKED_ICE:0)
Block(-5,32,1,PACKED_ICE:0)
Block(-5,32,2,PACKED_ICE:0)
Block(-5,32,3,PACKED_ICE:0)
Block(-5,32,4,PACKED_ICE:0)
Block(-5,32,5,PACKED_ICE:0)
Block(-5,32,6,PACKED_ICE:0)
Block(-5,33,-4,SNOW:0)
Block(-5,33,-3,PACKED_ICE:0)
Block(-5,33,-2,PACKED_ICE:0)
Block(-5,33,-1,PACKED_ICE:0)
Block(-5,33,0,PACKED_ICE:0)
Block(-5,33,1,PACKED_ICE:0)
Block(-5,33,2,PACKED_ICE:0)
Block(-5,33,3,PACKED_ICE:0)
Block(-5,33,4,PACKED_ICE:0)
Block(-5,33,5,PACKED_ICE:0)
Block(-5,33,6,ICE:0)
Block(-5,34,-4,PACKED_ICE:0)
Block(-5,34,-3,PACKED_ICE:0)
Block(-5,34,-2,PACKED_ICE:0)
Block(-5,34,-1,PACKED_ICE:0)
Block(-5,34,0,ICE:0)
Block(-5,34,1,PACKED_ICE:0)
Block(-5,34,2,PACKED_ICE:0)
Block(-5,34,3,PACKED_ICE:0)
Block(-5,34,5,PACKED_ICE:0)
Block(-5,34,6,PACKED_ICE:0)
Block(-5,34,7,ICE:0)
Block(-5,35,-5,ICE:0)
Block(-5,35,-4,PACKED_ICE:0)
Block(-5,35,-3,PACKED_ICE:0)
Block(-5,35,-2,PACKED_ICE:0)
Block(-5,35,-1,PACKED_ICE:0)
Block(-5,35,1,ICE:0)
Block(-5,35,2,PACKED_ICE:0)
Block(-5,35,3,LOG_2:1)
Block(-5,35,4,PACKED_ICE:0)
Block(-5,35,5,PACKED_ICE:0)
Block(-5,35,6,PACKED_ICE:0)
Block(-5,35,7,ICE:0)
Block(-5,35,8,ICE:0)
Block(-5,36,-5,PACKED_ICE:0)
Block(-5,36,-4,PACKED_ICE:0)
Block(-5,36,-3,PACKED_ICE:0)
Block(-5,36,-2,PACKED_ICE:0)
Block(-5,36,1,ICE:0)
Block(-5,36,2,PACKED_ICE:0)
Block(-5,36,3,PACKED_ICE:0)
Block(-5,36,4,PACKED_ICE:0)
Block(-5,36,5,LOG_2:1)
Block(-5,36,6,PACKED_ICE:0)
Block(-5,36,7,PACKED_ICE:0)
Block(-5,36,8,PACKED_ICE:0)
Block(-5,37,-6,LOG_2:1)
Block(-5,37,-5,PACKED_ICE:0)
Block(-5,37,-4,PACKED_ICE:0)
Block(-5,37,-3,PACKED_ICE:0)
Block(-5,37,-2,PACKED_ICE:0)
Block(-5,37,1,SNOW:0)
Block(-5,37,2,ICE:0)
Block(-5,37,3,PACKED_ICE:0)
Block(-5,37,4,ICE:0)
Block(-5,37,5,SNOW_BLOCK:0)
Block(-5,37,6,LOG_2:1)
Block(-5,37,7,PACKED_ICE:0)
Block(-5,37,8,PACKED_ICE:0)
Block(-5,38,-7,PACKED_ICE:0)
Block(-5,38,-6,LOG_2:1)
Block(-5,38,-5,PACKED_ICE:0)
Block(-5,38,-4,PACKED_ICE:0)
Block(-5,38,-3,PACKED_ICE:0)
Block(-5,38,5,SNOW_BLOCK:0)
Block(-5,38,6,LOG_2:1)
Block(-5,38,8,SNOW:0)
Block(-5,39,-7,WOOD:5)
Block(-5,39,-6,ICE:0)
Block(-5,39,-5,PACKED_ICE:0)
Block(-5,39,-4,PACKED_ICE:0)
Block(-5,39,-3,PACKED_ICE:0)
Block(-5,39,5,SNOW_BLOCK:0)
Block(-5,39,6,SNOW_BLOCK:0)
Block(-5,39,7,WOOD:5)
Block(-5,40,-7,ICE:0)
Block(-5,40,-6,ICE:0)
Block(-5,40,-5,PACKED_ICE:0)
Block(-5,40,-4,PACKED_ICE:0)
Block(-5,40,5,SNOW:2)
Block(-5,40,6,SNOW:2)
Block(-5,40,7,DISPENSER:3)
Block(-5,41,-5,PACKED_ICE:0)
Block(-5,41,-4,PACKED_ICE:0)
Block(-5,41,7,WOOD:5)
Block(-5,42,-5,PACKED_ICE:0)
Block(-5,42,-4,SNOW:0)
Block(-5,42,7,SNOW:1)
Block(-5,43,-5,PACKED_ICE:0)
Block(-5,44,-5,SNOW:0)
Block(-4,8,-4,ICE:0)
Block(-4,9,-4,ICE:0)
Block(-4,9,1,PACKED_ICE:0)
Block(-4,10,-4,ICE:0)
Block(-4,10,0,ICE:0)
Block(-4,10,1,ICE:0)
Block(-4,10,2,ICE:0)
Block(-4,11,-4,ICE:0)
Block(-4,11,-1,ICE:0)
Block(-4,11,0,ICE:0)
Block(-4,11,1,ICE:0)
Block(-4,11,2,ICE:0)
Block(-4,12,-5,ICE:0)
Block(-4,12,-4,ICE:0)
Block(-4,12,-1,PACKED_ICE:0)
Block(-4,12,0,ICE:0)
Block(-4,12,1,PACKED_ICE:0)
Block(-4,12,2,ICE:0)
Block(-4,13,-5,ICE:0)
Block(-4,13,-4,ICE:0)
Block(-4,13,-2,PACKED_ICE:0)
Block(-4,13,-1,PACKED_ICE:0)
Block(-4,13,0,PACKED_ICE:0)
Block(-4,13,1,PACKED_ICE:0)
Block(-4,13,2,ICE:0)
Block(-4,13,3,ICE:0)
Block(-4,14,-5,ICE:0)
Block(-4,14,-4,ICE:0)
Block(-4,14,-3,ICE:0)
Block(-4,14,-2,PACKED_ICE:0)
Block(-4,14,-1,PACKED_ICE:0)
Block(-4,14,0,PACKED_ICE:0)
Block(-4,14,1,PACKED_ICE:0)
Block(-4,14,2,ICE:0)
Block(-4,14,3,ICE:0)
Block(-4,14,4,ICE:0)
Block(-4,14,5,PACKED_ICE:0)
Block(-4,15,-5,ICE:0)
Block(-4,15,-4,ICE:0)
Block(-4,15,-3,PACKED_ICE:0)
Block(-4,15,-2,ICE:0)
Block(-4,15,-1,ICE:0)
Block(-4,15,0,PACKED_ICE:0)
Block(-4,15,1,PACKED_ICE:0)
Block(-4,15,2,PACKED_ICE:0)
Block(-4,15,3,PACKED_ICE:0)
Block(-4,15,4,PACKED_ICE:0)
Block(-4,15,5,PACKED_ICE:0)
Block(-4,15,6,PACKED_ICE:0)
Block(-4,16,-5,ICE:0)
Block(-4,16,-4,ICE:0)
Block(-4,16,-3,PACKED_ICE:0)
Block(-4,16,-2,ICE:0)
Block(-4,16,-1,ICE:0)
Block(-4,16,0,PACKED_ICE:0)
Block(-4,16,1,PACKED_ICE:0)
Block(-4,16,2,PACKED_ICE:0)
Block(-4,16,3,PACKED_ICE:0)
Block(-4,16,4,PACKED_ICE:0)
Block(-4,16,5,PACKED_ICE:0)
Block(-4,16,6,PACKED_ICE:0)
Block(-4,16,7,PACKED_ICE:0)
Block(-4,17,-6,ICE:0)
Block(-4,17,-5,ICE:0)
Block(-4,17,-4,ICE:0)
Block(-4,17,-3,PACKED_ICE:0)
Block(-4,17,-2,ICE:0)
Block(-4,17,-1,ICE:0)
Block(-4,17,0,PACKED_ICE:0)
Block(-4,17,1,PACKED_ICE:0)
Block(-4,17,2,PACKED_ICE:0)
Block(-4,17,3,PACKED_ICE:0)
Block(-4,17,4,PACKED_ICE:0)
Block(-4,17,5,PACKED_ICE:0)
Block(-4,17,6,PACKED_ICE:0)
Block(-4,17,7,ICE:0)
Block(-4,17,8,ICE:0)
Block(-4,18,-7,ICE:0)
Block(-4,18,-6,ICE:0)
Block(-4,18,-5,PACKED_ICE:0)
Block(-4,18,-4,PACKED_ICE:0)
Block(-4,18,-3,PACKED_ICE:0)
Block(-4,18,-2,ICE:0)
Block(-4,18,-1,ICE:0)
Block(-4,18,0,PACKED_ICE:0)
Block(-4,18,1,PACKED_ICE:0)
Block(-4,18,2,PACKED_ICE:0)
Block(-4,18,3,PACKED_ICE:0)
Block(-4,18,4,PACKED_ICE:0)
Block(-4,18,5,PACKED_ICE:0)
Block(-4,18,6,PACKED_ICE:0)
Block(-4,18,7,ICE:0)
Block(-4,18,8,ICE:0)
Block(-4,19,-7,PACKED_ICE:0)
Block(-4,19,-6,PACKED_ICE:0)
Block(-4,19,-5,PACKED_ICE:0)
Block(-4,19,-4,PACKED_ICE:0)
Block(-4,19,-3,PACKED_ICE:0)
Block(-4,19,-2,ICE:0)
Block(-4,19,-1,ICE:0)
Block(-4,19,0,PACKED_ICE:0)
Block(-4,19,1,PACKED_ICE:0)
Block(-4,19,2,PACKED_ICE:0)
Block(-4,19,3,PACKED_ICE:0)
Block(-4,19,4,PACKED_ICE:0)
Block(-4,19,5,PACKED_ICE:0)
Block(-4,19,6,PACKED_ICE:0)
Block(-4,19,7,ICE:0)
Block(-4,19,8,ICE:0)
Block(-4,20,-7,PACKED_ICE:0)
Block(-4,20,-6,PACKED_ICE:0)
Block(-4,20,-5,PACKED_ICE:0)
Block(-4,20,-4,PACKED_ICE:0)
Block(-4,20,-3,PACKED_ICE:0)
Block(-4,20,-2,ICE:0)
Block(-4,20,-1,ICE:0)
Block(-4,20,0,PACKED_ICE:0)
Block(-4,20,1,PACKED_ICE:0)
Block(-4,20,2,PACKED_ICE:0)
Block(-4,20,3,PACKED_ICE:0)
Block(-4,20,4,PACKED_ICE:0)
Block(-4,20,5,PACKED_ICE:0)
Block(-4,20,6,ICE:0)
Block(-4,20,7,ICE:0)
Block(-4,20,8,ICE:0)
Block(-4,21,-7,PACKED_ICE:0)
Block(-4,21,-6,PACKED_ICE:0)
Block(-4,21,-5,PACKED_ICE:0)
Block(-4,21,-4,ICE:0)
Block(-4,21,-3,ICE:0)
Block(-4,21,-2,ICE:0)
Block(-4,21,-1,ICE:0)
Block(-4,21,0,PACKED_ICE:0)
Block(-4,21,1,PACKED_ICE:0)
Block(-4,21,2,PACKED_ICE:0)
Block(-4,21,3,PACKED_ICE:0)
Block(-4,21,4,PACKED_ICE:0)
Block(-4,21,5,PACKED_ICE:0)
Block(-4,21,6,PACKED_ICE:0)
Block(-4,21,7,ICE:0)
Block(-4,21,8,PACKED_ICE:0)
Block(-4,22,-7,PACKED_ICE:0)
Block(-4,22,-6,PACKED_ICE:0)
Block(-4,22,-5,PACKED_ICE:0)
Block(-4,22,-4,ICE:0)
Block(-4,22,-3,ICE:0)
Block(-4,22,1,PACKED_ICE:0)
Block(-4,22,2,PACKED_ICE:0)
Block(-4,22,3,PACKED_ICE:0)
Block(-4,22,4,PACKED_ICE:0)
Block(-4,22,5,PACKED_ICE:0)
Block(-4,22,6,PACKED_ICE:0)
Block(-4,22,7,PACKED_ICE:0)
Block(-4,23,-7,PACKED_ICE:0)
Block(-4,23,-6,PACKED_ICE:0)
Block(-4,23,-5,ICE:0)
Block(-4,23,-4,ICE:0)
Block(-4,23,1,PACKED_ICE:0)
Block(-4,23,2,PACKED_ICE:0)
Block(-4,23,3,ICE:0)
Block(-4,23,4,PACKED_ICE:0)
Block(-4,23,5,PACKED_ICE:0)
Block(-4,23,6,PACKED_ICE:0)
Block(-4,23,7,PACKED_ICE:0)
Block(-4,24,-6,PACKED_ICE:0)
Block(-4,24,-5,ICE:0)
Block(-4,24,-4,ICE:0)
Block(-4,24,3,ICE:0)
Block(-4,24,4,ICE:0)
Block(-4,24,5,ICE:0)
Block(-4,24,6,PACKED_ICE:0)
Block(-4,24,7,PACKED_ICE:0)
Block(-4,25,-6,ICE:0)
Block(-4,25,-5,ICE:0)
Block(-4,25,-4,ICE:0)
Block(-4,25,-3,ICE:0)
Block(-4,25,3,ICE:0)
Block(-4,25,4,ICE:0)
Block(-4,25,5,ICE:0)
Block(-4,25,6,PACKED_ICE:0)
Block(-4,25,7,PACKED_ICE:0)
Block(-4,26,-6,ICE:0)
Block(-4,26,-5,ICE:0)
Block(-4,26,-4,ICE:0)
Block(-4,26,-3,ICE:0)
Block(-4,26,-2,ICE:0)
Block(-4,26,-1,ICE:0)
Block(-4,26,3,ICE:0)
Block(-4,26,4,ICE:0)
Block(-4,26,5,ICE:0)
Block(-4,26,6,ICE:0)
Block(-4,26,7,PACKED_ICE:0)
Block(-4,27,-6,ICE:0)
Block(-4,27,-5,ICE:0)
Block(-4,27,-4,PACKED_ICE:0)
Block(-4,27,-3,PACKED_ICE:0)
Block(-4,27,-2,ICE:0)
Block(-4,27,-1,ICE:0)
Block(-4,27,0,ICE:0)
Block(-4,27,1,ICE:0)
Block(-4,27,2,PACKED_ICE:0)
Block(-4,27,3,PACKED_ICE:0)
Block(-4,27,4,PACKED_ICE:0)
Block(-4,27,5,ICE:0)
Block(-4,27,6,ICE:0)
Block(-4,27,7,ICE:0)
Block(-4,28,-6,ICE:0)
Block(-4,28,-5,ICE:0)
Block(-4,28,-4,ICE:0)
Block(-4,28,-3,PACKED_ICE:0)
Block(-4,28,-2,ICE:0)
Block(-4,28,-1,ICE:0)
Block(-4,28,0,ICE:0)
Block(-4,28,1,ICE:0)
Block(-4,28,2,PACKED_ICE:0)
Block(-4,28,3,PACKED_ICE:0)
Block(-4,28,4,PACKED_ICE:0)
Block(-4,28,5,PACKED_ICE:0)
Block(-4,28,6,ICE:0)
Block(-4,28,7,PACKED_ICE:0)
Block(-4,29,-6,ICE:0)
Block(-4,29,-5,ICE:0)
Block(-4,29,-4,PACKED_ICE:0)
Block(-4,29,-3,PACKED_ICE:0)
Block(-4,29,-2,ICE:0)
Block(-4,29,-1,ICE:0)
Block(-4,29,0,PACKED_ICE:0)
Block(-4,29,1,PACKED_ICE:0)
Block(-4,29,2,PACKED_ICE:0)
Block(-4,29,3,PACKED_ICE:0)
Block(-4,29,4,PACKED_ICE:0)
Block(-4,29,5,PACKED_ICE:0)
Block(-4,29,6,PACKED_ICE:0)
Block(-4,29,7,SNOW:0)
Block(-4,30,-5,PACKED_ICE:0)
Block(-4,30,-4,PACKED_ICE:0)
Block(-4,30,-3,PACKED_ICE:0)
Block(-4,30,-2,ICE:0)
Block(-4,30,-1,ICE:0)
Block(-4,30,0,PACKED_ICE:0)
Block(-4,30,1,PACKED_ICE:0)
Block(-4,30,2,PACKED_ICE:0)
Block(-4,30,3,PACKED_ICE:0)
Block(-4,30,4,PACKED_ICE:0)
Block(-4,30,5,PACKED_ICE:0)
Block(-4,30,6,PACKED_ICE:0)
Block(-4,31,-5,ICE:0)
Block(-4,31,-4,PACKED_ICE:0)
Block(-4,31,-3,PACKED_ICE:0)
Block(-4,31,-2,ICE:0)
Block(-4,31,-1,ICE:0)
Block(-4,31,0,ICE:0)
Block(-4,31,1,ICE:0)
Block(-4,31,2,ICE:0)
Block(-4,31,3,ICE:0)
Block(-4,31,4,PACKED_ICE:0)
Block(-4,31,5,ICE:0)
Block(-4,32,-7,PACKED_ICE:0)
Block(-4,32,-5,ICE:0)
Block(-4,32,-4,PACKED_ICE:0)
Block(-4,32,-3,PACKED_ICE:0)
Block(-4,32,-2,PACKED_ICE:0)
Block(-4,32,-1,ICE:0)
Block(-4,32,0,PACKED_ICE:0)
Block(-4,32,1,PACKED_ICE:0)
Block(-4,32,2,PACKED_ICE:0)
Block(-4,32,3,PACKED_ICE:0)
Block(-4,32,4,PACKED_ICE:0)
Block(-4,32,5,PACKED_ICE:0)
Block(-4,32,6,PACKED_ICE:0)
Block(-4,33,-7,PACKED_ICE:0)
Block(-4,33,-5,SNOW:0)
Block(-4,33,-4,PACKED_ICE:0)
Block(-4,33,-3,PACKED_ICE:0)
Block(-4,33,-2,PACKED_ICE:0)
Block(-4,33,-1,PACKED_ICE:0)
Block(-4,33,0,ICE:0)
Block(-4,33,1,PACKED_ICE:0)
Block(-4,33,2,PACKED_ICE:0)
Block(-4,33,3,PACKED_ICE:0)
Block(-4,33,4,PACKED_ICE:0)
Block(-4,33,5,PACKED_ICE:0)
Block(-4,33,6,ICE:0)
Block(-4,34,-7,PACKED_ICE:0)
Block(-4,34,-5,ICE:0)
Block(-4,34,-4,PACKED_ICE:0)
Block(-4,34,-2,PACKED_ICE:0)
Block(-4,34,-1,PACKED_ICE:0)
Block(-4,34,0,ICE:0)
Block(-4,34,2,PACKED_ICE:0)
Block(-4,34,3,PACKED_ICE:0)
Block(-4,34,4,PACKED_ICE:0)
Block(-4,34,5,PACKED_ICE:0)
Block(-4,34,6,PACKED_ICE:0)
Block(-4,35,-7,PACKED_ICE:0)
Block(-4,35,-5,ICE:0)
Block(-4,35,-4,PACKED_ICE:0)
Block(-4,35,-3,PACKED_ICE:0)
Block(-4,35,-2,LOG_2:1)
Block(-4,35,-1,PACKED_ICE:0)
Block(-4,35,0,ICE:0)
Block(-4,35,1,PACKED_ICE:0)
Block(-4,35,2,PACKED_ICE:0)
Block(-4,35,3,PACKED_ICE:0)
Block(-4,35,4,PACKED_ICE:0)
Block(-4,35,5,PACKED_ICE:0)
Block(-4,35,6,PACKED_ICE:0)
Block(-4,35,7,ICE:0)
Block(-4,36,-7,PACKED_ICE:0)
Block(-4,36,-5,LOG_2:1)
Block(-4,36,-4,LOG_2:1)
Block(-4,36,-3,SNOW:0)
Block(-4,36,-2,ICE:0)
Block(-4,36,-1,PACKED_ICE:0)
Block(-4,36,0,PACKED_ICE:0)
Block(-4,36,1,ICE:0)
Block(-4,36,2,PACKED_ICE:0)
Block(-4,36,3,PACKED_ICE:0)
Block(-4,36,4,PACKED_ICE:0)
Block(-4,36,5,PACKED_ICE:0)
Block(-4,36,6,PACKED_ICE:0)
Block(-4,36,7,ICE:0)
Block(-4,36,8,ICE:0)
Block(-4,37,-7,PACKED_ICE:0)
Block(-4,37,-6,LOG_2:1)
Block(-4,37,-5,PACKED_ICE:0)
Block(-4,37,-4,SNOW:0)
Block(-4,37,-2,PACKED_ICE:0)
Block(-4,37,-1,PACKED_ICE:0)
Block(-4,37,0,SNOW:0)
Block(-4,37,1,PACKED_ICE:0)
Block(-4,37,2,PACKED_ICE:0)
Block(-4,37,3,PACKED_ICE:0)
Block(-4,37,4,PACKED_ICE:0)
Block(-4,37,5,PACKED_ICE:0)
Block(-4,37,6,LOG_2:1)
Block(-4,37,7,PACKED_ICE:0)
Block(-4,38,-7,PACKED_ICE:0)
Block(-4,38,-6,LOG_2:1)
Block(-4,38,-5,PACKED_ICE:0)
Block(-4,38,-1,SNOW:0)
Block(-4,38,3,PACKED_ICE:0)
Block(-4,38,4,PACKED_ICE:0)
Block(-4,38,5,SNOW_BLOCK:0)
Block(-4,38,6,LOG_2:1)
Block(-4,38,7,PACKED_ICE:0)
Block(-4,39,-7,PACKED_ICE:0)
Block(-4,39,-6,WOOD:5)
Block(-4,39,-5,ICE:0)
Block(-4,39,3,PACKED_ICE:0)
Block(-4,39,4,SNOW_BLOCK:0)
Block(-4,39,5,SNOW_BLOCK:0)
Block(-4,39,6,WOOD:5)
Block(-4,39,7,PACKED_ICE:0)
Block(-4,40,-7,WOOD:5)
Block(-4,40,4,SNOW:2)
Block(-4,40,5,SNOW_BLOCK:0)
Block(-4,40,6,SNOW_BLOCK:0)
Block(-4,40,7,WOOD:5)
Block(-4,41,-7,WOOD:5)
Block(-4,41,-6,WOOD_STEP:5)
Block(-4,41,6,WOOD_STEP:5)
Block(-4,41,7,WOOD:5)
Block(-4,42,-7,SNOW:2)
Block(-4,42,7,SNOW:4)
Block(-3,10,0,ICE:0)
Block(-3,10,1,ICE:0)
Block(-3,11,-4,ICE:0)
Block(-3,11,-1,ICE:0)
Block(-3,11,0,ICE:0)
Block(-3,11,1,ICE:0)
Block(-3,11,7,PACKED_ICE:0)
Block(-3,12,-4,ICE:0)
Block(-3,12,-2,ICE:0)
Block(-3,12,-1,ICE:0)
Block(-3,12,0,ICE:0)
Block(-3,12,1,ICE:0)
Block(-3,12,2,ICE:0)
Block(-3,12,7,PACKED_ICE:0)
Block(-3,13,-4,ICE:0)
Block(-3,13,-3,ICE:0)
Block(-3,13,-2,PACKED_ICE:0)
Block(-3,13,-1,PACKED_ICE:0)
Block(-3,13,0,PACKED_ICE:0)
Block(-3,13,1,PACKED_ICE:0)
Block(-3,13,2,ICE:0)
Block(-3,13,3,ICE:0)
Block(-3,13,4,ICE:0)
Block(-3,13,7,PACKED_ICE:0)
Block(-3,14,-5,ICE:0)
Block(-3,14,-4,ICE:0)
Block(-3,14,-3,ICE:0)
Block(-3,14,-2,PACKED_ICE:0)
Block(-3,14,-1,PACKED_ICE:0)
Block(-3,14,0,PACKED_ICE:0)
Block(-3,14,1,PACKED_ICE:0)
Block(-3,14,2,ICE:0)
Block(-3,14,3,ICE:0)
Block(-3,14,4,ICE:0)
Block(-3,14,5,PACKED_ICE:0)
Block(-3,14,6,PACKED_ICE:0)
Block(-3,14,7,PACKED_ICE:0)
Block(-3,15,-5,ICE:0)
Block(-3,15,-4,ICE:0)
Block(-3,15,-3,ICE:0)
Block(-3,15,-2,ICE:0)
Block(-3,15,-1,PACKED_ICE:0)
Block(-3,15,0,PACKED_ICE:0)
Block(-3,15,1,PACKED_ICE:0)
Block(-3,15,2,PACKED_ICE:0)
Block(-3,15,3,PACKED_ICE:0)
Block(-3,15,4,PACKED_ICE:0)
Block(-3,15,5,PACKED_ICE:0)
Block(-3,15,6,PACKED_ICE:0)
Block(-3,15,7,PACKED_ICE:0)
Block(-3,16,-5,ICE:0)
Block(-3,16,-4,ICE:0)
Block(-3,16,-3,ICE:0)
Block(-3,16,-2,ICE:0)
Block(-3,16,-1,PACKED_ICE:0)
Block(-3,16,0,PACKED_ICE:0)
Block(-3,16,1,PACKED_ICE:0)
Block(-3,16,2,PACKED_ICE:0)
Block(-3,16,3,PACKED_ICE:0)
Block(-3,16,4,PACKED_ICE:0)
Block(-3,16,5,PACKED_ICE:0)
Block(-3,16,6,PACKED_ICE:0)
Block(-3,16,7,ICE:0)
Block(-3,16,8,ICE:0)
Block(-3,17,-6,ICE:0)
Block(-3,17,-5,ICE:0)
Block(-3,17,-4,PACKED_ICE:0)
Block(-3,17,-3,ICE:0)
Block(-3,17,-2,ICE:0)
Block(-3,17,-1,PACKED_ICE:0)
Block(-3,17,0,PACKED_ICE:0)
Block(-3,17,1,PACKED_ICE:0)
Block(-3,17,2,PACKED_ICE:0)
Block(-3,17,3,PACKED_ICE:0)
Block(-3,17,4,PACKED_ICE:0)
Block(-3,17,5,PACKED_ICE:0)
Block(-3,17,6,PACKED_ICE:0)
Block(-3,17,7,ICE:0)
Block(-3,17,8,ICE:0)
Block(-3,18,-6,ICE:0)
Block(-3,18,-5,PACKED_ICE:0)
Block(-3,18,-4,PACKED_ICE:0)
Block(-3,18,-3,ICE:0)
Block(-3,18,-2,ICE:0)
Block(-3,18,-1,PACKED_ICE:0)
Block(-3,18,0,PACKED_ICE:0)
Block(-3,18,1,PACKED_ICE:0)
Block(-3,18,2,PACKED_ICE:0)
Block(-3,18,3,PACKED_ICE:0)
Block(-3,18,4,PACKED_ICE:0)
Block(-3,18,5,PACKED_ICE:0)
Block(-3,18,6,PACKED_ICE:0)
Block(-3,18,7,ICE:0)
Block(-3,18,8,ICE:0)
Block(-3,19,-7,PACKED_ICE:0)
Block(-3,19,-6,PACKED_ICE:0)
Block(-3,19,-5,PACKED_ICE:0)
Block(-3,19,-4,PACKED_ICE:0)
Block(-3,19,-3,ICE:0)
Block(-3,19,-2,ICE:0)
Block(-3,19,-1,PACKED_ICE:0)
Block(-3,19,0,PACKED_ICE:0)
Block(-3,19,1,PACKED_ICE:0)
Block(-3,19,2,PACKED_ICE:0)
Block(-3,19,3,PACKED_ICE:0)
Block(-3,19,4,PACKED_ICE:0)
Block(-3,19,5,PACKED_ICE:0)
Block(-3,19,6,PACKED_ICE:0)
Block(-3,19,7,ICE:0)
Block(-3,19,8,ICE:0)
Block(-3,20,-7,PACKED_ICE:0)
Block(-3,20,-6,PACKED_ICE:0)
Block(-3,20,-5,PACKED_ICE:0)
Block(-3,20,-4,PACKED_ICE:0)
Block(-3,20,-3,ICE:0)
Block(-3,20,-2,ICE:0)
Block(-3,20,-1,PACKED_ICE:0)
Block(-3,20,0,PACKED_ICE:0)
Block(-3,20,1,PACKED_ICE:0)
Block(-3,20,2,PACKED_ICE:0)
Block(-3,20,3,PACKED_ICE:0)
Block(-3,20,4,PACKED_ICE:0)
Block(-3,20,5,PACKED_ICE:0)
Block(-3,20,6,PACKED_ICE:0)
Block(-3,20,7,PACKED_ICE:0)
Block(-3,20,8,ICE:0)
Block(-3,21,-6,PACKED_ICE:0)
Block(-3,21,-5,PACKED_ICE:0)
Block(-3,21,-4,PACKED_ICE:0)
Block(-3,21,-3,ICE:0)
Block(-3,21,-2,ICE:0)
Block(-3,21,-1,PACKED_ICE:0)
Block(-3,21,0,PACKED_ICE:0)
Block(-3,21,1,PACKED_ICE:0)
Block(-3,21,2,PACKED_ICE:0)
Block(-3,21,3,PACKED_ICE:0)
Block(-3,21,4,PACKED_ICE:0)
Block(-3,21,5,PACKED_ICE:0)
Block(-3,21,6,PACKED_ICE:0)
Block(-3,21,7,PACKED_ICE:0)
Block(-3,22,-6,PACKED_ICE:0)
Block(-3,22,-5,PACKED_ICE:0)
Block(-3,22,-4,ICE:0)
Block(-3,22,-3,ICE:0)
Block(-3,22,-2,ICE:0)
Block(-3,22,0,PACKED_ICE:0)
Block(-3,22,1,PACKED_ICE:0)
Block(-3,22,2,PACKED_ICE:0)
Block(-3,22,3,ICE:0)
Block(-3,22,4,ICE:0)
Block(-3,22,5,ICE:0)
Block(-3,22,6,PACKED_ICE:0)
Block(-3,22,7,PACKED_ICE:0)
Block(-3,23,-6,PACKED_ICE:0)
Block(-3,23,-5,PACKED_ICE:0)
Block(-3,23,-4,ICE:0)
Block(-3,23,-3,ICE:0)
Block(-3,23,2,ICE:0)
Block(-3,23,3,ICE:0)
Block(-3,23,4,ICE:0)
Block(-3,23,5,ICE:0)
Block(-3,23,6,ICE:0)
Block(-3,23,7,PACKED_ICE:0)
Block(-3,24,-6,PACKED_ICE:0)
Block(-3,24,-5,ICE:0)
Block(-3,24,-4,ICE:0)
Block(-3,24,-3,ICE:0)
Block(-3,24,-2,ICE:0)
Block(-3,24,3,ICE:0)
Block(-3,24,5,ICE:0)
Block(-3,24,6,PACKED_ICE:0)
Block(-3,24,7,PACKED_ICE:0)
Block(-3,25,-6,ICE:0)
Block(-3,25,-5,PACKED_ICE:0)
Block(-3,25,-4,ICE:0)
Block(-3,25,-3,ICE:0)
Block(-3,25,-2,ICE:0)
Block(-3,25,6,ICE:0)
Block(-3,25,7,PACKED_ICE:0)
Block(-3,26,-6,ICE:0)
Block(-3,26,-5,ICE:0)
Block(-3,26,-4,PACKED_ICE:0)
Block(-3,26,-3,ICE:0)
Block(-3,26,-2,ICE:0)
Block(-3,26,-1,ICE:0)
Block(-3,26,0,ICE:0)
Block(-3,26,3,PACKED_ICE:0)
Block(-3,26,5,ICE:0)
Block(-3,26,6,ICE:0)
Block(-3,27,-6,ICE:0)
Block(-3,27,-5,ICE:0)
Block(-3,27,-4,ICE:0)
Block(-3,27,-3,ICE:0)
Block(-3,27,-2,ICE:0)
Block(-3,27,-1,ICE:0)
Block(-3,27,0,ICE:0)
Block(-3,27,1,ICE:0)
Block(-3,27,2,ICE:0)
Block(-3,27,3,ICE:0)
Block(-3,27,4,ICE:0)
Block(-3,27,5,ICE:0)
Block(-3,27,6,ICE:0)
Block(-3,28,-5,ICE:0)
Block(-3,28,-4,ICE:0)
Block(-3,28,-3,ICE:0)
Block(-3,28,-2,ICE:0)
Block(-3,28,-1,PACKED_ICE:0)
Block(-3,28,0,ICE:0)
Block(-3,28,1,PACKED_ICE:0)
Block(-3,28,2,ICE:0)
Block(-3,28,3,PACKED_ICE:0)
Block(-3,28,4,PACKED_ICE:0)
Block(-3,28,5,ICE:0)
Block(-3,28,6,ICE:0)
Block(-3,29,-5,ICE:0)
Block(-3,29,-4,ICE:0)
Block(-3,29,-3,ICE:0)
Block(-3,29,-2,ICE:0)
Block(-3,29,-1,PACKED_ICE:0)
Block(-3,29,0,PACKED_ICE:0)
Block(-3,29,1,PACKED_ICE:0)
Block(-3,29,2,PACKED_ICE:0)
Block(-3,29,3,PACKED_ICE:0)
Block(-3,29,4,PACKED_ICE:0)
Block(-3,29,5,PACKED_ICE:0)
Block(-3,29,6,PACKED_ICE:0)
Block(-3,30,-5,PACKED_ICE:0)
Block(-3,30,-4,PACKED_ICE:0)
Block(-3,30,-3,ICE:0)
Block(-3,30,-2,ICE:0)
Block(-3,30,-1,PACKED_ICE:0)
Block(-3,30,0,PACKED_ICE:0)
Block(-3,30,1,PACKED_ICE:0)
Block(-3,30,2,PACKED_ICE:0)
Block(-3,30,3,PACKED_ICE:0)
Block(-3,30,4,PACKED_ICE:0)
Block(-3,30,5,PACKED_ICE:0)
Block(-3,30,6,PACKED_ICE:0)
Block(-3,31,-5,SNOW:0)
Block(-3,31,-4,PACKED_ICE:0)
Block(-3,31,-3,PACKED_ICE:0)
Block(-3,31,-2,ICE:0)
Block(-3,31,-1,ICE:0)
Block(-3,31,0,ICE:0)
Block(-3,31,1,ICE:0)
Block(-3,31,2,ICE:0)
Block(-3,31,3,ICE:0)
Block(-3,31,4,ICE:0)
Block(-3,31,5,ICE:0)
Block(-3,32,-4,PACKED_ICE:0)
Block(-3,32,-3,PACKED_ICE:0)
Block(-3,32,-1,ICE:0)
Block(-3,32,0,ICE:0)
Block(-3,32,1,PACKED_ICE:0)
Block(-3,32,2,PACKED_ICE:0)
Block(-3,32,3,PACKED_ICE:0)
Block(-3,32,4,PACKED_ICE:0)
Block(-3,32,5,PACKED_ICE:0)
Block(-3,33,-4,SNOW:0)
Block(-3,33,-3,PACKED_ICE:0)
Block(-3,33,-2,ICE:0)
Block(-3,33,-1,PACKED_ICE:0)
Block(-3,33,0,ICE:0)
Block(-3,33,2,PACKED_ICE:0)
Block(-3,33,3,PACKED_ICE:0)
Block(-3,33,4,PACKED_ICE:0)
Block(-3,33,5,PACKED_ICE:0)
Block(-3,33,6,PACKED_ICE:0)
Block(-3,33,7,PACKED_ICE:0)
Block(-3,34,-4,ICE:0)
Block(-3,34,-3,ICE:0)
Block(-3,34,-2,PACKED_ICE:0)
Block(-3,34,-1,ICE:0)
Block(-3,34,0,ICE:0)
Block(-3,34,1,PACKED_ICE:0)
Block(-3,34,2,PACKED_ICE:0)
Block(-3,34,3,PACKED_ICE:0)
Block(-3,34,4,PACKED_ICE:0)
Block(-3,34,5,PACKED_ICE:0)
Block(-3,34,6,PACKED_ICE:0)
Block(-3,34,7,PACKED_ICE:0)
Block(-3,35,-4,PACKED_ICE:0)
Block(-3,35,-3,PACKED_ICE:0)
Block(-3,35,-2,LOG_2:1)
Block(-3,35,-1,WOOD:5)
Block(-3,35,0,WOOD:5)
Block(-3,35,1,PACKED_ICE:0)
Block(-3,35,2,PACKED_ICE:0)
Block(-3,35,3,PACKED_ICE:0)
Block(-3,35,4,PACKED_ICE:0)
Block(-3,35,5,PACKED_ICE:0)
Block(-3,35,6,PACKED_ICE:0)
Block(-3,35,7,ICE:0)
Block(-3,36,-7,ICE:0)
Block(-3,36,-5,PACKED_ICE:0)
Block(-3,36,-4,LOG_2:1)
Block(-3,36,-3,LOG_2:1)
Block(-3,36,-2,ICE:0)
Block(-3,36,-1,ICE:0)
Block(-3,36,0,ICE:0)
Block(-3,36,1,PACKED_ICE:0)
Block(-3,36,2,PACKED_ICE:0)
Block(-3,36,3,PACKED_ICE:0)
Block(-3,36,4,PACKED_ICE:0)
Block(-3,36,5,PACKED_ICE:0)
Block(-3,36,6,PACKED_ICE:0)
Block(-3,36,7,ICE:0)
Block(-3,37,-7,ICE:0)
Block(-3,37,-6,LOG_2:1)
Block(-3,37,-5,LOG_2:1)
Block(-3,37,-4,WOOD:5)
Block(-3,37,-3,WOOD:5)
Block(-3,37,-2,PACKED_ICE:0)
Block(-3,37,-1,PACKED_ICE:0)
Block(-3,37,0,PACKED_ICE:0)
Block(-3,37,1,PACKED_ICE:0)
Block(-3,37,2,PACKED_ICE:0)
Block(-3,37,3,PACKED_ICE:0)
Block(-3,37,4,PACKED_ICE:0)
Block(-3,37,5,PACKED_ICE:0)
Block(-3,37,6,LOG_2:1)
Block(-3,37,7,ICE:0)
Block(-3,38,-7,ICE:0)
Block(-3,38,-6,LOG_2:1)
Block(-3,38,-5,WOOD:5)
Block(-3,38,-4,WOOD:5)
Block(-3,38,-3,WOOD:5)
Block(-3,38,-1,PACKED_ICE:0)
Block(-3,38,0,PACKED_ICE:0)
Block(-3,38,1,PACKED_ICE:0)
Block(-3,38,2,PACKED_ICE:0)
Block(-3,38,3,PACKED_ICE:0)
Block(-3,38,4,PACKED_ICE:0)
Block(-3,38,5,WOOD:5)
Block(-3,38,6,LOG_2:1)
Block(-3,38,7,PACKED_ICE:0)
Block(-3,39,-7,ICE:0)
Block(-3,39,-6,WOOD:5)
Block(-3,39,-5,WOOD:5)
Block(-3,39,-4,ICE:0)
Block(-3,39,-3,SNOW:0)
Block(-3,39,1,SNOW:0)
Block(-3,39,2,PACKED_ICE:0)
Block(-3,39,3,PACKED_ICE:0)
Block(-3,39,4,PACKED_ICE:0)
Block(-3,39,5,WOOD:5)
Block(-3,39,6,WOOD:5)
Block(-3,39,7,ICE:0)
Block(-3,40,-7,ICE:0)
Block(-3,40,-5,TRIPWIRE:0)
Block(-3,40,2,PACKED_ICE:0)
Block(-3,40,3,PACKED_ICE:0)
Block(-3,40,4,PACKED_ICE:0)
Block(-3,40,5,SNOW_BLOCK:0)
Block(-3,40,6,SNOW_BLOCK:0)
Block(-3,40,7,ICE:0)
Block(-3,41,-7,ICE:0)
Block(-3,41,-6,WOOD_STEP:5)
Block(-3,41,2,PACKED_ICE:0)
Block(-3,41,3,PACKED_ICE:0)
Block(-3,41,4,SNOW:0)
Block(-3,41,6,SNOW_BLOCK:0)
Block(-3,41,7,PACKED_ICE:0)
Block(-3,42,2,SNOW:0)
Block(-3,42,3,PACKED_ICE:0)
Block(-3,42,6,SNOW:3)
Block(-3,43,3,PACKED_ICE:0)
Block(-3,44,3,PACKED_ICE:0)
Block(-3,45,3,PACKED_ICE:0)
Block(-3,46,3,PACKED_ICE:0)
Block(-3,47,3,SNOW:0)
Block(-2,9,0,PACKED_ICE:0)
Block(-2,10,-1,ICE:0)
Block(-2,10,0,ICE:0)
Block(-2,10,1,PACKED_ICE:0)
Block(-2,11,-2,ICE:0)
Block(-2,11,-1,ICE:0)
Block(-2,11,0,ICE:0)
Block(-2,11,1,ICE:0)
Block(-2,11,2,PACKED_ICE:0)
Block(-2,12,-2,ICE:0)
Block(-2,12,-1,ICE:0)
Block(-2,12,0,ICE:0)
Block(-2,12,1,PACKED_ICE:0)
Block(-2,12,2,PACKED_ICE:0)
Block(-2,12,3,ICE:0)
Block(-2,13,-3,ICE:0)
Block(-2,13,-2,PACKED_ICE:0)
Block(-2,13,-1,PACKED_ICE:0)
Block(-2,13,0,PACKED_ICE:0)
Block(-2,13,1,PACKED_ICE:0)
Block(-2,13,2,ICE:0)
Block(-2,13,3,ICE:0)
Block(-2,13,4,ICE:0)
Block(-2,13,7,PACKED_ICE:0)
Block(-2,14,-4,ICE:0)
Block(-2,14,-3,ICE:0)
Block(-2,14,-2,ICE:0)
Block(-2,14,-1,PACKED_ICE:0)
Block(-2,14,0,PACKED_ICE:0)
Block(-2,14,1,PACKED_ICE:0)
Block(-2,14,2,PACKED_ICE:0)
Block(-2,14,3,ICE:0)
Block(-2,14,4,ICE:0)
Block(-2,14,5,ICE:0)
Block(-2,14,7,PACKED_ICE:0)
Block(-2,15,-4,ICE:0)
Block(-2,15,-3,ICE:0)
Block(-2,15,-2,ICE:0)
Block(-2,15,-1,PACKED_ICE:0)
Block(-2,15,0,PACKED_ICE:0)
Block(-2,15,1,PACKED_ICE:0)
Block(-2,15,2,PACKED_ICE:0)
Block(-2,15,3,PACKED_ICE:0)
Block(-2,15,4,ICE:0)
Block(-2,15,5,ICE:0)
Block(-2,15,6,ICE:0)
Block(-2,15,7,PACKED_ICE:0)
Block(-2,16,-5,PACKED_ICE:0)
Block(-2,16,-4,PACKED_ICE:0)
Block(-2,16,-3,ICE:0)
Block(-2,16,-2,ICE:0)
Block(-2,16,-1,PACKED_ICE:0)
Block(-2,16,0,PACKED_ICE:0)
Block(-2,16,1,PACKED_ICE:0)
Block(-2,16,2,PACKED_ICE:0)
Block(-2,16,3,PACKED_ICE:0)
Block(-2,16,4,PACKED_ICE:0)
Block(-2,16,5,ICE:0)
Block(-2,16,6,PACKED_ICE:0)
Block(-2,16,7,PACKED_ICE:0)
Block(-2,17,-6,ICE:0)
Block(-2,17,-5,PACKED_ICE:0)
Block(-2,17,-4,PACKED_ICE:0)
Block(-2,17,-3,ICE:0)
Block(-2,17,-2,ICE:0)
Block(-2,17,-1,PACKED_ICE:0)
Block(-2,17,0,PACKED_ICE:0)
Block(-2,17,1,PACKED_ICE:0)
Block(-2,17,2,PACKED_ICE:0)
Block(-2,17,3,PACKED_ICE:0)
Block(-2,17,4,PACKED_ICE:0)
Block(-2,17,5,PACKED_ICE:0)
Block(-2,17,6,PACKED_ICE:0)
Block(-2,17,7,ICE:0)
Block(-2,18,-6,ICE:0)
Block(-2,18,-5,PACKED_ICE:0)
Block(-2,18,-4,PACKED_ICE:0)
Block(-2,18,-3,ICE:0)
Block(-2,18,-2,ICE:0)
Block(-2,18,-1,PACKED_ICE:0)
Block(-2,18,0,PACKED_ICE:0)
Block(-2,18,1,PACKED_ICE:0)
Block(-2,18,2,PACKED_ICE:0)
Block(-2,18,3,PACKED_ICE:0)
Block(-2,18,4,PACKED_ICE:0)
Block(-2,18,5,PACKED_ICE:0)
Block(-2,18,6,PACKED_ICE:0)
Block(-2,18,7,ICE:0)
Block(-2,19,-7,PACKED_ICE:0)
Block(-2,19,-6,PACKED_ICE:0)
Block(-2,19,-5,PACKED_ICE:0)
Block(-2,19,-4,PACKED_ICE:0)
Block(-2,19,-3,ICE:0)
Block(-2,19,-2,ICE:0)
Block(-2,19,-1,PACKED_ICE:0)
Block(-2,19,0,PACKED_ICE:0)
Block(-2,19,1,PACKED_ICE:0)
Block(-2,19,2,PACKED_ICE:0)
Block(-2,19,3,PACKED_ICE:0)
Block(-2,19,4,PACKED_ICE:0)
Block(-2,19,5,PACKED_ICE:0)
Block(-2,19,6,ICE:0)
Block(-2,19,7,ICE:0)
Block(-2,19,8,ICE:0)
Block(-2,20,-7,PACKED_ICE:0)
Block(-2,20,-6,PACKED_ICE:0)
Block(-2,20,-5,PACKED_ICE:0)
Block(-2,20,-4,PACKED_ICE:0)
Block(-2,20,-3,ICE:0)
Block(-2,20,-2,ICE:0)
Block(-2,20,-1,PACKED_ICE:0)
Block(-2,20,0,PACKED_ICE:0)
Block(-2,20,1,PACKED_ICE:0)
Block(-2,20,2,PACKED_ICE:0)
Block(-2,20,3,PACKED_ICE:0)
Block(-2,20,4,PACKED_ICE:0)
Block(-2,20,5,PACKED_ICE:0)
Block(-2,20,6,PACKED_ICE:0)
Block(-2,20,7,ICE:0)
Block(-2,21,-7,PACKED_ICE:0)
Block(-2,21,-6,PACKED_ICE:0)
Block(-2,21,-5,PACKED_ICE:0)
Block(-2,21,-4,PACKED_ICE:0)
Block(-2,21,-3,ICE:0)
Block(-2,21,-2,ICE:0)
Block(-2,21,-1,PACKED_ICE:0)
Block(-2,21,0,PACKED_ICE:0)
Block(-2,21,1,PACKED_ICE:0)
Block(-2,21,2,PACKED_ICE:0)
Block(-2,21,3,PACKED_ICE:0)
Block(-2,21,4,PACKED_ICE:0)
Block(-2,21,5,PACKED_ICE:0)
Block(-2,21,6,PACKED_ICE:0)
Block(-2,21,7,PACKED_ICE:0)
Block(-2,22,-7,PACKED_ICE:0)
Block(-2,22,-6,PACKED_ICE:0)
Block(-2,22,-5,PACKED_ICE:0)
Block(-2,22,-4,PACKED_ICE:0)
Block(-2,22,-3,ICE:0)
Block(-2,22,-2,ICE:0)
Block(-2,22,-1,PACKED_ICE:0)
Block(-2,22,0,PACKED_ICE:0)
Block(-2,22,1,PACKED_ICE:0)
Block(-2,22,2,ICE:0)
Block(-2,22,3,ICE:0)
Block(-2,22,4,ICE:0)
Block(-2,22,5,ICE:0)
Block(-2,22,6,ICE:0)
Block(-2,22,7,PACKED_ICE:0)
Block(-2,23,-6,PACKED_ICE:0)
Block(-2,23,-5,PACKED_ICE:0)
Block(-2,23,-4,PACKED_ICE:0)
Block(-2,23,-3,ICE:0)
Block(-2,23,-2,ICE:0)
Block(-2,23,2,ICE:0)
Block(-2,23,3,ICE:0)
Block(-2,23,4,ICE:0)
Block(-2,23,5,ICE:0)
Block(-2,23,6,ICE:0)
Block(-2,23,7,PACKED_ICE:0)
Block(-2,24,-5,PACKED_ICE:0)
Block(-2,24,-4,PACKED_ICE:0)
Block(-2,24,-3,ICE:0)
Block(-2,24,6,ICE:0)
Block(-2,24,7,PACKED_ICE:0)
Block(-2,25,-5,PACKED_ICE:0)
Block(-2,25,-4,PACKED_ICE:0)
Block(-2,25,-3,ICE:0)
Block(-2,25,-2,ICE:0)
Block(-2,25,6,ICE:0)
Block(-2,26,-5,ICE:0)
Block(-2,26,-4,ICE:0)
Block(-2,26,-3,ICE:0)
Block(-2,26,-2,ICE:0)
Block(-2,26,-1,ICE:0)
Block(-2,26,0,ICE:0)
Block(-2,26,6,ICE:0)
Block(-2,27,-5,ICE:0)
Block(-2,27,-4,ICE:0)
Block(-2,27,-3,ICE:0)
Block(-2,27,-2,ICE:0)
Block(-2,27,-1,ICE:0)
Block(-2,27,0,ICE:0)
Block(-2,27,1,ICE:0)
Block(-2,27,2,ICE:0)
Block(-2,27,3,ICE:0)
Block(-2,27,4,PACKED_ICE:0)
Block(-2,27,5,ICE:0)
Block(-2,27,6,ICE:0)
Block(-2,27,7,ICE:0)
Block(-2,28,-5,ICE:0)
Block(-2,28,-4,ICE:0)
Block(-2,28,-3,ICE:0)
Block(-2,28,-2,ICE:0)
Block(-2,28,-1,PACKED_ICE:0)
Block(-2,28,0,PACKED_ICE:0)
Block(-2,28,1,ICE:0)
Block(-2,28,2,ICE:0)
Block(-2,28,3,ICE:0)
Block(-2,28,4,PACKED_ICE:0)
Block(-2,28,5,PACKED_ICE:0)
Block(-2,28,6,ICE:0)
Block(-2,28,7,ICE:0)
Block(-2,29,-4,PACKED_ICE:0)
Block(-2,29,-3,ICE:0)
Block(-2,29,-2,ICE:0)
Block(-2,29,-1,PACKED_ICE:0)
Block(-2,29,0,PACKED_ICE:0)
Block(-2,29,1,PACKED_ICE:0)
Block(-2,29,2,PACKED_ICE:0)
Block(-2,29,3,PACKED_ICE:0)
Block(-2,29,4,PACKED_ICE:0)
Block(-2,29,5,PACKED_ICE:0)
Block(-2,29,6,ICE:0)
Block(-2,29,7,ICE:0)
Block(-2,30,-4,PACKED_ICE:0)
Block(-2,30,-3,ICE:0)
Block(-2,30,-2,ICE:0)
Block(-2,30,-1,PACKED_ICE:0)
Block(-2,30,0,PACKED_ICE:0)
Block(-2,30,1,PACKED_ICE:0)
Block(-2,30,2,PACKED_ICE:0)
Block(-2,30,3,PACKED_ICE:0)
Block(-2,30,4,PACKED_ICE:0)
Block(-2,30,5,PACKED_ICE:0)
Block(-2,30,6,PACKED_ICE:0)
Block(-2,30,7,PACKED_ICE:0)
Block(-2,31,-4,PACKED_ICE:0)
Block(-2,31,-3,ICE:0)
Block(-2,31,-2,ICE:0)
Block(-2,31,-1,ICE:0)
Block(-2,31,0,ICE:0)
Block(-2,31,1,ICE:0)
Block(-2,31,2,ICE:0)
Block(-2,31,3,ICE:0)
Block(-2,31,4,ICE:0)
Block(-2,31,5,ICE:0)
Block(-2,31,6,ICE:0)
Block(-2,31,7,PACKED_ICE:0)
Block(-2,32,-4,SNOW:0)
Block(-2,32,-3,ICE:0)
Block(-2,32,-2,ICE:0)
Block(-2,32,-1,ICE:0)
Block(-2,32,0,ICE:0)
Block(-2,32,1,PACKED_ICE:0)
Block(-2,32,2,PACKED_ICE:0)
Block(-2,32,3,PACKED_ICE:0)
Block(-2,32,4,PACKED_ICE:0)
Block(-2,32,5,ICE:0)
Block(-2,32,7,PACKED_ICE:0)
Block(-2,33,-6,ICE:0)
Block(-2,33,-3,SNOW:0)
Block(-2,33,-2,ICE:0)
Block(-2,33,-1,ICE:0)
Block(-2,33,0,ICE:0)
Block(-2,33,1,PACKED_ICE:0)
Block(-2,33,2,PACKED_ICE:0)
Block(-2,33,3,PACKED_ICE:0)
Block(-2,33,4,PACKED_ICE:0)
Block(-2,33,5,PACKED_ICE:0)
Block(-2,33,6,PACKED_ICE:0)
Block(-2,33,7,PACKED_ICE:0)
Block(-2,34,-6,ICE:0)
Block(-2,34,-3,ICE:0)
Block(-2,34,-2,PACKED_ICE:0)
Block(-2,34,-1,ICE:0)
Block(-2,34,0,ICE:0)
Block(-2,34,1,PACKED_ICE:0)
Block(-2,34,2,PACKED_ICE:0)
Block(-2,34,3,PACKED_ICE:0)
Block(-2,34,4,PACKED_ICE:0)
Block(-2,34,5,PACKED_ICE:0)
Block(-2,34,6,PACKED_ICE:0)
Block(-2,34,7,PACKED_ICE:0)
Block(-2,35,-6,ICE:0)
Block(-2,35,-4,ICE:0)
Block(-2,35,-3,PACKED_ICE:0)
Block(-2,35,-2,LOG_2:1)
Block(-2,35,-1,ICE:0)
Block(-2,35,0,ICE:0)
Block(-2,35,1,PACKED_ICE:0)
Block(-2,35,2,PACKED_ICE:0)
Block(-2,35,3,PACKED_ICE:0)
Block(-2,35,4,PACKED_ICE:0)
Block(-2,35,5,PACKED_ICE:0)
Block(-2,35,6,PACKED_ICE:0)
Block(-2,35,7,PACKED_ICE:0)
Block(-2,36,-6,ICE:0)
Block(-2,36,-5,PACKED_ICE:0)
Block(-2,36,-4,LOG_2:1)
Block(-2,36,-3,LOG_2:1)
Block(-2,36,-2,ICE:0)
Block(-2,36,-1,PACKED_ICE:0)
Block(-2,36,0,PACKED_ICE:0)
Block(-2,36,1,ICE:0)
Block(-2,36,2,PACKED_ICE:0)
Block(-2,36,3,PACKED_ICE:0)
Block(-2,36,4,PACKED_ICE:0)
Block(-2,36,5,PACKED_ICE:0)
Block(-2,36,6,PACKED_ICE:0)
Block(-2,36,7,PACKED_ICE:0)
Block(-2,37,-6,ICE:0)
Block(-2,37,-5,LOG_2:1)
Block(-2,37,-4,PACKED_ICE:0)
Block(-2,37,-3,PACKED_ICE:0)
Block(-2,37,-2,PACKED_ICE:0)
Block(-2,37,-1,PACKED_ICE:0)
Block(-2,37,0,ICE:0)
Block(-2,37,1,PACKED_ICE:0)
Block(-2,37,2,PACKED_ICE:0)
Block(-2,37,3,PACKED_ICE:0)
Block(-2,37,4,PACKED_ICE:0)
Block(-2,37,5,LOG_2:1)
Block(-2,37,6,LOG_2:1)
Block(-2,37,7,ICE:0)
Block(-2,38,-7,ICE:0)
Block(-2,38,-6,ICE:0)
Block(-2,38,-5,PACKED_ICE:0)
Block(-2,38,-4,PACKED_ICE:0)
Block(-2,38,-3,PACKED_ICE:0)
Block(-2,38,-2,PACKED_ICE:0)
Block(-2,38,-1,PACKED_ICE:0)
Block(-2,38,0,ICE:0)
Block(-2,38,1,PACKED_ICE:0)
Block(-2,38,2,ICE:0)
Block(-2,38,3,PACKED_ICE:0)
Block(-2,38,4,PACKED_ICE:0)
Block(-2,38,5,PACKED_ICE:0)
Block(-2,38,6,LOG_2:1)
Block(-2,38,7,ICE:0)
Block(-2,39,-7,ICE:0)
Block(-2,39,-6,ICE:0)
Block(-2,39,-5,WOOD:5)
Block(-2,39,-4,PACKED_ICE:0)
Block(-2,39,-3,ICE:0)
Block(-2,39,-2,PACKED_ICE:0)
Block(-2,39,-1,PACKED_ICE:0)
Block(-2,39,0,ICE:0)
Block(-2,39,1,PACKED_ICE:0)
Block(-2,39,2,PACKED_ICE:0)
Block(-2,39,3,ICE:0)
Block(-2,39,4,PACKED_ICE:0)
Block(-2,39,5,WOOD:5)
Block(-2,39,6,WOOD:5)
Block(-2,39,7,ICE:0)
Block(-2,40,-7,ICE:0)
Block(-2,40,-6,ICE:0)
Block(-2,40,-5,DARK_OAK_STAIRS:3)
Block(-2,40,-1,SNOW:0)
Block(-2,40,0,ICE:0)
Block(-2,40,3,SNOW_BLOCK:0)
Block(-2,40,4,SNOW_BLOCK:0)
Block(-2,40,5,SNOW_BLOCK:0)
Block(-2,40,6,COAL_BLOCK:0)
Block(-2,40,7,DISPENSER:3)
Block(-2,41,0,SNOW:0)
Block(-2,41,5,SNOW_BLOCK:0)
Block(-2,41,6,SNOW_BLOCK:0)
Block(-2,41,7,WOOD:5)
Block(-2,42,6,SNOW_BLOCK:0)
Block(-2,42,7,SNOW:6)
Block(-2,43,6,SNOW:1)
Block(-1,9,1,PACKED_ICE:0)
Block(-1,10,0,PACKED_ICE:0)
Block(-1,10,1,PACKED_ICE:0)
Block(-1,11,-1,ICE:0)
Block(-1,11,0,PACKED_ICE:0)
Block(-1,11,1,PACKED_ICE:0)
Block(-1,11,2,PACKED_ICE:0)
Block(-1,12,-2,ICE:0)
Block(-1,12,-1,PACKED_ICE:0)
Block(-1,12,0,PACKED_ICE:0)
Block(-1,12,1,PACKED_ICE:0)
Block(-1,12,2,PACKED_ICE:0)
Block(-1,12,3,ICE:0)
Block(-1,13,-2,ICE:0)
Block(-1,13,-1,PACKED_ICE:0)
Block(-1,13,0,PACKED_ICE:0)
Block(-1,13,1,PACKED_ICE:0)
Block(-1,13,2,ICE:0)
Block(-1,13,3,ICE:0)
Block(-1,13,4,ICE:0)
Block(-1,14,-3,ICE:0)
Block(-1,14,-2,ICE:0)
Block(-1,14,-1,ICE:0)
Block(-1,14,0,PACKED_ICE:0)
Block(-1,14,1,PACKED_ICE:0)
Block(-1,14,2,PACKED_ICE:0)
Block(-1,14,3,ICE:0)
Block(-1,14,4,ICE:0)
Block(-1,15,-5,ICE:0)
Block(-1,15,-4,ICE:0)
Block(-1,15,-3,ICE:0)
Block(-1,15,-2,ICE:0)
Block(-1,15,-1,PACKED_ICE:0)
Block(-1,15,0,PACKED_ICE:0)
Block(-1,15,1,PACKED_ICE:0)
Block(-1,15,2,PACKED_ICE:0)
Block(-1,15,3,ICE:0)
Block(-1,15,4,ICE:0)
Block(-1,15,5,ICE:0)
Block(-1,16,-5,PACKED_ICE:0)
Block(-1,16,-4,PACKED_ICE:0)
Block(-1,16,-3,PACKED_ICE:0)
Block(-1,16,-2,PACKED_ICE:0)
Block(-1,16,-1,PACKED_ICE:0)
Block(-1,16,0,PACKED_ICE:0)
Block(-1,16,1,PACKED_ICE:0)
Block(-1,16,2,PACKED_ICE:0)
Block(-1,16,3,ICE:0)
Block(-1,16,4,ICE:0)
Block(-1,16,5,ICE:0)
Block(-1,16,6,ICE:0)
Block(-1,17,-7,ICE:0)
Block(-1,17,-6,ICE:0)
Block(-1,17,-5,PACKED_ICE:0)
Block(-1,17,-4,PACKED_ICE:0)
Block(-1,17,-3,PACKED_ICE:0)
Block(-1,17,-2,PACKED_ICE:0)
Block(-1,17,-1,PACKED_ICE:0)
Block(-1,17,0,PACKED_ICE:0)
Block(-1,17,1,PACKED_ICE:0)
Block(-1,17,2,PACKED_ICE:0)
Block(-1,17,3,ICE:0)
Block(-1,17,4,ICE:0)
Block(-1,17,5,PACKED_ICE:0)
Block(-1,17,6,ICE:0)
Block(-1,18,-6,ICE:0)
Block(-1,18,-5,ICE:0)
Block(-1,18,-4,PACKED_ICE:0)
Block(-1,18,-3,PACKED_ICE:0)
Block(-1,18,-2,PACKED_ICE:0)
Block(-1,18,-1,PACKED_ICE:0)
Block(-1,18,0,PACKED_ICE:0)
Block(-1,18,1,PACKED_ICE:0)
Block(-1,18,2,PACKED_ICE:0)
Block(-1,18,3,ICE:0)
Block(-1,18,4,ICE:0)
Block(-1,18,5,ICE:0)
Block(-1,18,6,ICE:0)
Block(-1,18,7,ICE:0)
Block(-1,19,-6,ICE:0)
Block(-1,19,-5,PACKED_ICE:0)
Block(-1,19,-4,PACKED_ICE:0)
Block(-1,19,-3,PACKED_ICE:0)
Block(-1,19,-2,PACKED_ICE:0)
Block(-1,19,-1,PACKED_ICE:0)
Block(-1,19,0,PACKED_ICE:0)
Block(-1,19,1,PACKED_ICE:0)
Block(-1,19,2,PACKED_ICE:0)
Block(-1,19,3,ICE:0)
Block(-1,19,4,ICE:0)
Block(-1,19,5,ICE:0)
Block(-1,19,6,ICE:0)
Block(-1,19,7,ICE:0)
Block(-1,20,-6,PACKED_ICE:0)
Block(-1,20,-5,PACKED_ICE:0)
Block(-1,20,-4,PACKED_ICE:0)
Block(-1,20,-3,PACKED_ICE:0)
Block(-1,20,-2,PACKED_ICE:0)
Block(-1,20,-1,PACKED_ICE:0)
Block(-1,20,0,PACKED_ICE:0)
Block(-1,20,1,PACKED_ICE:0)
Block(-1,20,2,PACKED_ICE:0)
Block(-1,20,3,ICE:0)
Block(-1,20,4,ICE:0)
Block(-1,20,5,ICE:0)
Block(-1,20,6,ICE:0)
Block(-1,20,7,ICE:0)
Block(-1,21,-6,PACKED_ICE:0)
Block(-1,21,-5,PACKED_ICE:0)
Block(-1,21,-4,PACKED_ICE:0)
Block(-1,21,-3,PACKED_ICE:0)
Block(-1,21,-2,PACKED_ICE:0)
Block(-1,21,-1,PACKED_ICE:0)
Block(-1,21,0,PACKED_ICE:0)
Block(-1,21,1,PACKED_ICE:0)
Block(-1,21,2,PACKED_ICE:0)
Block(-1,21,3,ICE:0)
Block(-1,21,4,ICE:0)
Block(-1,21,5,ICE:0)
Block(-1,21,6,ICE:0)
Block(-1,21,7,PACKED_ICE:0)
Block(-1,22,-5,PACKED_ICE:0)
Block(-1,22,-4,PACKED_ICE:0)
Block(-1,22,-3,PACKED_ICE:0)
Block(-1,22,-2,PACKED_ICE:0)
Block(-1,22,-1,PACKED_ICE:0)
Block(-1,22,0,PACKED_ICE:0)
Block(-1,22,1,PACKED_ICE:0)
Block(-1,22,2,PACKED_ICE:0)
Block(-1,22,3,ICE:0)
Block(-1,22,4,ICE:0)
Block(-1,22,5,ICE:0)
Block(-1,22,6,ICE:0)
Block(-1,22,7,PACKED_ICE:0)
Block(-1,23,-5,PACKED_ICE:0)
Block(-1,23,-4,PACKED_ICE:0)
Block(-1,23,-3,PACKED_ICE:0)
Block(-1,23,3,ICE:0)
Block(-1,23,4,ICE:0)
Block(-1,23,5,ICE:0)
Block(-1,23,6,ICE:0)
Block(-1,24,-5,PACKED_ICE:0)
Block(-1,24,-4,PACKED_ICE:0)
Block(-1,24,-3,PACKED_ICE:0)
Block(-1,25,-5,PACKED_ICE:0)
Block(-1,25,-4,PACKED_ICE:0)
Block(-1,25,-3,ICE:0)
Block(-1,26,-4,ICE:0)
Block(-1,26,-3,ICE:0)
Block(-1,26,-2,ICE:0)
Block(-1,26,-1,ICE:0)
Block(-1,27,-4,ICE:0)
Block(-1,27,-3,ICE:0)
Block(-1,27,-2,PACKED_ICE:0)
Block(-1,27,-1,PACKED_ICE:0)
Block(-1,27,0,ICE:0)
Block(-1,27,1,ICE:0)
Block(-1,27,2,ICE:0)
Block(-1,27,3,ICE:0)
Block(-1,27,4,ICE:0)
Block(-1,27,5,ICE:0)
Block(-1,27,6,ICE:0)
Block(-1,28,-3,PACKED_ICE:0)
Block(-1,28,-2,PACKED_ICE:0)
Block(-1,28,-1,PACKED_ICE:0)
Block(-1,28,0,PACKED_ICE:0)
Block(-1,28,1,ICE:0)
Block(-1,28,2,ICE:0)
Block(-1,28,3,ICE:0)
Block(-1,28,4,ICE:0)
Block(-1,28,5,ICE:0)
Block(-1,29,-3,PACKED_ICE:0)
Block(-1,29,-2,PACKED_ICE:0)
Block(-1,29,-1,PACKED_ICE:0)
Block(-1,29,0,PACKED_ICE:0)
Block(-1,29,1,PACKED_ICE:0)
Block(-1,29,2,PACKED_ICE:0)
Block(-1,29,3,ICE:0)
Block(-1,29,4,ICE:0)
Block(-1,29,5,ICE:0)
Block(-1,30,-3,PACKED_ICE:0)
Block(-1,30,-2,PACKED_ICE:0)
Block(-1,30,-1,PACKED_ICE:0)
Block(-1,30,0,PACKED_ICE:0)
Block(-1,30,1,PACKED_ICE:0)
Block(-1,30,2,PACKED_ICE:0)
Block(-1,30,3,ICE:0)
Block(-1,30,4,ICE:0)
Block(-1,30,5,ICE:0)
Block(-1,31,-3,ICE:0)
Block(-1,31,-2,ICE:0)
Block(-1,31,-1,ICE:0)
Block(-1,31,0,ICE:0)
Block(-1,31,1,ICE:0)
Block(-1,31,2,ICE:0)
Block(-1,31,3,ICE:0)
Block(-1,31,4,ICE:0)
Block(-1,31,5,ICE:0)
Block(-1,32,-3,ICE:0)
Block(-1,32,-2,ICE:0)
Block(-1,32,-1,ICE:0)
Block(-1,32,0,ICE:0)
Block(-1,32,1,PACKED_ICE:0)
Block(-1,32,2,PACKED_ICE:0)
Block(-1,32,3,PACKED_ICE:0)
Block(-1,32,4,PACKED_ICE:0)
Block(-1,32,5,ICE:0)
Block(-1,33,-3,ICE:0)
Block(-1,33,-2,ICE:0)
Block(-1,33,-1,ICE:0)
Block(-1,33,0,ICE:0)
Block(-1,33,1,PACKED_ICE:0)
Block(-1,33,2,PACKED_ICE:0)
Block(-1,33,3,PACKED_ICE:0)
Block(-1,33,4,PACKED_ICE:0)
Block(-1,33,5,PACKED_ICE:0)
Block(-1,34,-4,ICE:0)
Block(-1,34,-3,ICE:0)
Block(-1,34,-2,PACKED_ICE:0)
Block(-1,34,-1,ICE:0)
Block(-1,34,0,PACKED_ICE:0)
Block(-1,34,1,LOG_2:1)
Block(-1,34,2,PACKED_ICE:0)
Block(-1,34,3,PACKED_ICE:0)
Block(-1,34,4,PACKED_ICE:0)
Block(-1,34,5,PACKED_ICE:0)
Block(-1,34,6,PACKED_ICE:0)
Block(-1,35,-4,ICE:0)
Block(-1,35,-3,PACKED_ICE:0)
Block(-1,35,-2,LOG_2:1)
Block(-1,35,-1,ICE:0)
Block(-1,35,0,LOG_2:1)
Block(-1,35,1,LOG_2:1)
Block(-1,35,2,PACKED_ICE:0)
Block(-1,35,3,PACKED_ICE:0)
Block(-1,35,5,PACKED_ICE:0)
Block(-1,35,6,PACKED_ICE:0)
Block(-1,36,-5,PACKED_ICE:0)
Block(-1,36,-4,LOG_2:1)
Block(-1,36,-3,LOG_2:1)
Block(-1,36,-2,PACKED_ICE:0)
Block(-1,36,-1,PACKED_ICE:0)
Block(-1,36,0,LOG:1)
Block(-1,36,1,PACKED_ICE:0)
Block(-1,36,2,PACKED_ICE:0)
Block(-1,36,3,PACKED_ICE:0)
Block(-1,36,4,PACKED_ICE:0)
Block(-1,36,5,PACKED_ICE:0)
Block(-1,36,6,PACKED_ICE:0)
Block(-1,36,7,PACKED_ICE:0)
Block(-1,37,-6,PACKED_ICE:0)
Block(-1,37,-5,PACKED_ICE:0)
Block(-1,37,-4,ICE:0)
Block(-1,37,-3,ICE:0)
Block(-1,37,-2,PACKED_ICE:0)
Block(-1,37,-1,PACKED_ICE:0)
Block(-1,37,0,LOG:1)
Block(-1,37,1,PACKED_ICE:0)
Block(-1,37,2,ICE:0)
Block(-1,37,3,ICE:0)
Block(-1,37,4,PACKED_ICE:0)
Block(-1,37,5,LOG_2:1)
Block(-1,37,6,PACKED_ICE:0)
Block(-1,37,7,PACKED_ICE:0)
Block(-1,38,-7,ICE:0)
Block(-1,38,-6,LOG_2:1)
Block(-1,38,-5,PACKED_ICE:0)
Block(-1,38,-4,PACKED_ICE:0)
Block(-1,38,-3,PACKED_ICE:0)
Block(-1,38,-2,PACKED_ICE:0)
Block(-1,38,-1,ICE:0)
Block(-1,38,0,ICE:0)
Block(-1,38,1,ICE:0)
Block(-1,38,2,ICE:0)
Block(-1,38,3,PACKED_ICE:0)
Block(-1,38,4,PACKED_ICE:0)
Block(-1,38,5,PACKED_ICE:0)
Block(-1,38,6,LOG_2:1)
Block(-1,38,7,ICE:0)
Block(-1,39,-7,WOOD:5)
Block(-1,39,-6,WOOD:5)
Block(-1,39,-5,WOOD:5)
Block(-1,39,-4,PACKED_ICE:0)
Block(-1,39,-3,ICE:0)
Block(-1,39,-2,ICE:0)
Block(-1,39,-1,ICE:0)
Block(-1,39,0,ICE:0)
Block(-1,39,1,PACKED_ICE:0)
Block(-1,39,2,PACKED_ICE:0)
Block(-1,39,3,ICE:0)
Block(-1,39,4,ICE:0)
Block(-1,39,5,WOOD:5)
Block(-1,39,6,WOOD:5)
Block(-1,39,7,ICE:0)
Block(-1,40,-7,SNOW:1)
Block(-1,40,-6,PACKED_ICE:0)
Block(-1,40,-5,FLOWER_POT:0)
Block(-1,40,-4,ICE:0)
Block(-1,40,-3,PACKED_ICE:0)
Block(-1,40,-2,PACKED_ICE:0)
Block(-1,40,-1,ICE:0)
Block(-1,40,0,ICE:0)
Block(-1,40,1,PACKED_ICE:0)
Block(-1,40,2,ICE:0)
Block(-1,40,3,SNOW_BLOCK:0)
Block(-1,40,4,SNOW_BLOCK:0)
Block(-1,40,5,SNOW_BLOCK:0)
Block(-1,40,6,SNOW_BLOCK:0)
Block(-1,40,7,PACKED_ICE:0)
Block(-1,41,-2,SNOW:0)
Block(-1,41,-1,ICE:0)
Block(-1,41,0,ICE:0)
Block(-1,41,1,ICE:0)
Block(-1,41,2,ICE:0)
Block(-1,41,3,SNOW_BLOCK:0)
Block(-1,41,4,SNOW_BLOCK:0)
Block(-1,41,5,SNOW_BLOCK:0)
Block(-1,41,6,SNOW_BLOCK:0)
Block(-1,41,7,SNOW_BLOCK:0)
Block(-1,42,-1,SNOW:0)
Block(-1,42,0,ICE:0)
Block(-1,42,2,SNOW:0)
Block(-1,42,5,SNOW_BLOCK:0)
Block(-1,42,6,SNOW_BLOCK:0)
Block(-1,42,7,SNOW:4)
Block(-1,43,0,SNOW:0)
Block(-1,43,5,SNOW:1)
Block(0,6,1,PACKED_ICE:0)
Block(0,7,1,PACKED_ICE:0)
Block(0,8,1,PACKED_ICE:0)
Block(0,8,2,PACKED_ICE:0)
Block(0,9,1,PACKED_ICE:0)
Block(0,9,2,PACKED_ICE:0)
Block(0,10,0,PACKED_ICE:0)
Block(0,10,1,PACKED_ICE:0)
Block(0,10,2,ICE:0)
Block(0,11,-4,PACKED_ICE:0)
Block(0,11,-1,PACKED_ICE:0)
Block(0,11,0,PACKED_ICE:0)
Block(0,11,1,ICE:0)
Block(0,11,2,ICE:0)
Block(0,11,3,ICE:0)
Block(0,12,-4,PACKED_ICE:0)
Block(0,12,-1,PACKED_ICE:0)
Block(0,12,0,PACKED_ICE:0)
Block(0,12,1,PACKED_ICE:0)
Block(0,12,2,ICE:0)
Block(0,12,3,ICE:0)
Block(0,13,-4,PACKED_ICE:0)
Block(0,13,-3,PACKED_ICE:0)
Block(0,13,-2,ICE:0)
Block(0,13,-1,ICE:0)
Block(0,13,0,PACKED_ICE:0)
Block(0,13,1,PACKED_ICE:0)
Block(0,13,2,ICE:0)
Block(0,13,3,ICE:0)
Block(0,14,-4,ICE:0)
Block(0,14,-3,ICE:0)
Block(0,14,-2,ICE:0)
Block(0,14,-1,ICE:0)
Block(0,14,0,PACKED_ICE:0)
Block(0,14,1,PACKED_ICE:0)
Block(0,14,2,ICE:0)
Block(0,14,3,ICE:0)
Block(0,15,-6,ICE:0)
Block(0,15,-5,ICE:0)
Block(0,15,-4,ICE:0)
Block(0,15,-3,ICE:0)
Block(0,15,-2,ICE:0)
Block(0,15,-1,ICE:0)
Block(0,15,0,PACKED_ICE:0)
Block(0,15,1,PACKED_ICE:0)
Block(0,15,2,ICE:0)
Block(0,15,3,ICE:0)
Block(0,15,4,ICE:0)
Block(0,15,5,ICE:0)
Block(0,16,-6,ICE:0)
Block(0,16,-5,ICE:0)
Block(0,16,-4,PACKED_ICE:0)
Block(0,16,-3,PACKED_ICE:0)
Block(0,16,-2,PACKED_ICE:0)
Block(0,16,-1,PACKED_ICE:0)
Block(0,16,0,PACKED_ICE:0)
Block(0,16,1,PACKED_ICE:0)
Block(0,16,2,ICE:0)
Block(0,16,3,ICE:0)
Block(0,16,4,ICE:0)
Block(0,16,5,ICE:0)
Block(0,16,6,ICE:0)
Block(0,17,-6,ICE:0)
Block(0,17,-5,ICE:0)
Block(0,17,-4,PACKED_ICE:0)
Block(0,17,-3,PACKED_ICE:0)
Block(0,17,-2,PACKED_ICE:0)
Block(0,17,-1,PACKED_ICE:0)
Block(0,17,0,PACKED_ICE:0)
Block(0,17,1,PACKED_ICE:0)
Block(0,17,2,ICE:0)
Block(0,17,3,ICE:0)
Block(0,17,4,ICE:0)
Block(0,17,5,ICE:0)
Block(0,17,6,ICE:0)
Block(0,18,-6,ICE:0)
Block(0,18,-5,ICE:0)
Block(0,18,-4,PACKED_ICE:0)
Block(0,18,-3,PACKED_ICE:0)
Block(0,18,-2,PACKED_ICE:0)
Block(0,18,-1,PACKED_ICE:0)
Block(0,18,0,PACKED_ICE:0)
Block(0,18,1,PACKED_ICE:0)
Block(0,18,2,ICE:0)
Block(0,18,3,ICE:0)
Block(0,18,4,ICE:0)
Block(0,18,5,ICE:0)
Block(0,18,6,ICE:0)
Block(0,19,-6,ICE:0)
Block(0,19,-5,ICE:0)
Block(0,19,-4,PACKED_ICE:0)
Block(0,19,-3,PACKED_ICE:0)
Block(0,19,-2,PACKED_ICE:0)
Block(0,19,-1,PACKED_ICE:0)
Block(0,19,0,PACKED_ICE:0)
Block(0,19,1,PACKED_ICE:0)
Block(0,19,2,ICE:0)
Block(0,19,3,ICE:0)
Block(0,19,4,ICE:0)
Block(0,19,5,ICE:0)
Block(0,19,6,ICE:0)
Block(0,19,7,ICE:0)
Block(0,20,-5,PACKED_ICE:0)
Block(0,20,-4,PACKED_ICE:0)
Block(0,20,-3,PACKED_ICE:0)
Block(0,20,-2,PACKED_ICE:0)
Block(0,20,-1,PACKED_ICE:0)
Block(0,20,0,PACKED_ICE:0)
Block(0,20,1,PACKED_ICE:0)
Block(0,20,2,ICE:0)
Block(0,20,3,ICE:0)
Block(0,20,4,ICE:0)
Block(0,20,5,ICE:0)
Block(0,20,6,ICE:0)
Block(0,20,7,ICE:0)
Block(0,21,-5,PACKED_ICE:0)
Block(0,21,-4,PACKED_ICE:0)
Block(0,21,-3,PACKED_ICE:0)
Block(0,21,-2,PACKED_ICE:0)
Block(0,21,-1,PACKED_ICE:0)
Block(0,21,0,PACKED_ICE:0)
Block(0,21,1,PACKED_ICE:0)
Block(0,21,2,ICE:0)
Block(0,21,3,ICE:0)
Block(0,21,4,ICE:0)
Block(0,21,5,ICE:0)
Block(0,21,6,ICE:0)
Block(0,22,-5,ICE:0)
Block(0,22,-4,PACKED_ICE:0)
Block(0,22,-3,PACKED_ICE:0)
Block(0,22,-2,PACKED_ICE:0)
Block(0,22,-1,PACKED_ICE:0)
Block(0,22,0,PACKED_ICE:0)
Block(0,22,2,ICE:0)
Block(0,22,3,ICE:0)
Block(0,22,4,ICE:0)
Block(0,22,5,ICE:0)
Block(0,22,6,ICE:0)
Block(0,23,-4,PACKED_ICE:0)
Block(0,23,-3,PACKED_ICE:0)
Block(0,23,-2,PACKED_ICE:0)
Block(0,23,3,ICE:0)
Block(0,23,4,ICE:0)
Block(0,23,5,ICE:0)
Block(0,24,-4,PACKED_ICE:0)
Block(0,24,-3,PACKED_ICE:0)
Block(0,25,-4,ICE:0)
Block(0,25,-3,ICE:0)
Block(0,25,-2,ICE:0)
Block(0,26,-3,ICE:0)
Block(0,26,-2,ICE:0)
Block(0,27,-3,ICE:0)
Block(0,27,-2,ICE:0)
Block(0,27,-1,PACKED_ICE:0)
Block(0,27,0,ICE:0)
Block(0,27,1,ICE:0)
Block(0,27,2,ICE:0)
Block(0,27,3,ICE:0)
Block(0,27,4,ICE:0)
Block(0,27,5,ICE:0)
Block(0,28,-3,PACKED_ICE:0)
Block(0,28,-2,PACKED_ICE:0)
Block(0,28,-1,PACKED_ICE:0)
Block(0,28,0,ICE:0)
Block(0,28,1,ICE:0)
Block(0,28,2,ICE:0)
Block(0,28,3,ICE:0)
Block(0,28,4,ICE:0)
Block(0,28,5,ICE:0)
Block(0,29,-3,PACKED_ICE:0)
Block(0,29,-2,PACKED_ICE:0)
Block(0,29,-1,PACKED_ICE:0)
Block(0,29,0,PACKED_ICE:0)
Block(0,29,1,PACKED_ICE:0)
Block(0,29,2,ICE:0)
Block(0,29,3,ICE:0)
Block(0,29,4,ICE:0)
Block(0,29,5,ICE:0)
Block(0,30,-3,PACKED_ICE:0)
Block(0,30,-2,PACKED_ICE:0)
Block(0,30,-1,PACKED_ICE:0)
Block(0,30,0,PACKED_ICE:0)
Block(0,30,1,PACKED_ICE:0)
Block(0,30,2,ICE:0)
Block(0,30,3,ICE:0)
Block(0,30,4,ICE:0)
Block(0,30,5,ICE:0)
Block(0,31,-5,ICE:0)
Block(0,31,-3,PACKED_ICE:0)
Block(0,31,-2,ICE:0)
Block(0,31,-1,ICE:0)
Block(0,31,0,ICE:0)
Block(0,31,1,ICE:0)
Block(0,31,2,ICE:0)
Block(0,31,3,ICE:0)
Block(0,31,4,ICE:0)
Block(0,32,-5,ICE:0)
Block(0,32,-3,PACKED_ICE:0)
Block(0,32,-2,ICE:0)
Block(0,32,-1,ICE:0)
Block(0,32,0,ICE:0)
Block(0,32,1,PACKED_ICE:0)
Block(0,32,2,PACKED_ICE:0)
Block(0,32,3,PACKED_ICE:0)
Block(0,32,4,PACKED_ICE:0)
Block(0,32,5,ICE:0)
Block(0,33,-5,ICE:0)
Block(0,33,-3,ICE:0)
Block(0,33,-2,ICE:0)
Block(0,33,-1,ICE:0)
Block(0,33,0,PACKED_ICE:0)
Block(0,33,1,PACKED_ICE:0)
Block(0,33,2,PACKED_ICE:0)
Block(0,33,3,PACKED_ICE:0)
Block(0,33,4,PACKED_ICE:0)
Block(0,33,5,PACKED_ICE:0)
Block(0,34,-5,ICE:0)
Block(0,34,-4,ICE:0)
Block(0,34,-3,ICE:0)
Block(0,34,-2,ICE:0)
Block(0,34,-1,ICE:0)
Block(0,34,0,PACKED_ICE:0)
Block(0,34,1,LOG_2:1)
Block(0,34,2,PACKED_ICE:0)
Block(0,34,3,PACKED_ICE:0)
Block(0,34,4,PACKED_ICE:0)
Block(0,34,5,PACKED_ICE:0)
Block(0,35,-5,ICE:0)
Block(0,35,-4,PACKED_ICE:0)
Block(0,35,-3,PACKED_ICE:0)
Block(0,35,-2,PACKED_ICE:0)
Block(0,35,-1,PACKED_ICE:0)
Block(0,35,0,LOG_2:1)
Block(0,35,1,LOG_2:1)
Block(0,35,2,LOG_2:1)
Block(0,35,3,PACKED_ICE:0)
Block(0,35,4,PACKED_ICE:0)
Block(0,35,5,PACKED_ICE:0)
Block(0,35,6,PACKED_ICE:0)
Block(0,36,-6,ICE:0)
Block(0,36,-5,PACKED_ICE:0)
Block(0,36,-4,LOG_2:1)
Block(0,36,-3,LOG_2:1)
Block(0,36,-2,PACKED_ICE:0)
Block(0,36,-1,PACKED_ICE:0)
Block(0,36,0,PACKED_ICE:0)
Block(0,36,1,PACKED_ICE:0)
Block(0,36,2,PACKED_ICE:0)
Block(0,36,3,ICE:0)
Block(0,36,4,LOG_2:1)
Block(0,36,5,PACKED_ICE:0)
Block(0,36,6,PACKED_ICE:0)
Block(0,37,-6,ICE:0)
Block(0,37,-5,LOG_2:1)
Block(0,37,-4,PACKED_ICE:0)
Block(0,37,-3,PACKED_ICE:0)
Block(0,37,-2,PACKED_ICE:0)
Block(0,37,-1,PACKED_ICE:0)
Block(0,37,0,PACKED_ICE:0)
Block(0,37,1,PACKED_ICE:0)
Block(0,37,2,ICE:0)
Block(0,37,3,ICE:0)
Block(0,37,4,ICE:0)
Block(0,37,5,LOG_2:1)
Block(0,37,6,PACKED_ICE:0)
Block(0,37,7,ICE:0)
Block(0,38,-7,PACKED_ICE:0)
Block(0,38,-6,LOG_2:1)
Block(0,38,-5,PACKED_ICE:0)
Block(0,38,-4,PACKED_ICE:0)
Block(0,38,-3,PACKED_ICE:0)
Block(0,38,-2,PACKED_ICE:0)
Block(0,38,-1,PACKED_ICE:0)
Block(0,38,0,ICE:0)
Block(0,38,1,PACKED_ICE:0)
Block(0,38,2,ICE:0)
Block(0,38,3,PACKED_ICE:0)
Block(0,38,4,PACKED_ICE:0)
Block(0,38,5,PACKED_ICE:0)
Block(0,38,6,PACKED_ICE:0)
Block(0,38,7,ICE:0)
Block(0,39,-7,PACKED_ICE:0)
Block(0,39,-6,WOOD:5)
Block(0,39,-5,PACKED_ICE:0)
Block(0,39,-4,PACKED_ICE:0)
Block(0,39,-3,PACKED_ICE:0)
Block(0,39,-2,PACKED_ICE:0)
Block(0,39,-1,PACKED_ICE:0)
Block(0,39,0,ICE:0)
Block(0,39,1,PACKED_ICE:0)
Block(0,39,2,ICE:0)
Block(0,39,3,PACKED_ICE:0)
Block(0,39,4,PACKED_ICE:0)
Block(0,39,5,WOOD:5)
Block(0,39,6,ICE:0)
Block(0,39,7,ICE:0)
Block(0,40,-6,PACKED_ICE:0)
Block(0,40,-5,PACKED_ICE:0)
Block(0,40,-4,PACKED_ICE:0)
Block(0,40,-3,PACKED_ICE:0)
Block(0,40,-2,PACKED_ICE:0)
Block(0,40,-1,PACKED_ICE:0)
Block(0,40,0,ICE:0)
Block(0,40,1,PACKED_ICE:0)
Block(0,40,2,ICE:0)
Block(0,40,3,ICE:0)
Block(0,40,4,SNOW_BLOCK:0)
Block(0,40,5,STAINED_CLAY:9)
Block(0,40,7,PACKED_ICE:0)
Block(0,41,-5,SNOW:0)
Block(0,41,-4,ICE:0)
Block(0,41,-3,PACKED_ICE:0)
Block(0,41,-2,PACKED_ICE:0)
Block(0,41,-1,ICE:0)
Block(0,41,0,ICE:0)
Block(0,41,1,PACKED_ICE:0)
Block(0,41,2,ICE:0)
Block(0,41,3,SNOW_BLOCK:0)
Block(0,41,4,SNOW_BLOCK:0)
Block(0,41,5,STAINED_CLAY:9)
Block(0,41,6,STAINED_CLAY:9)
Block(0,41,7,WOOD:5)
Block(0,42,-4,SNOW:0)
Block(0,42,-3,ICE:0)
Block(0,42,-2,PACKED_ICE:0)
Block(0,42,-1,PACKED_ICE:0)
Block(0,42,0,ICE:0)
Block(0,42,2,ICE:0)
Block(0,42,3,SNOW_BLOCK:0)
Block(0,42,4,SNOW_BLOCK:0)
Block(0,42,5,SNOW_BLOCK:0)
Block(0,42,6,SNOW_BLOCK:0)
Block(0,42,7,SNOW:7)
Block(0,43,-3,SNOW:0)
Block(0,43,-2,ICE:0)
Block(0,43,-1,PACKED_ICE:0)
Block(0,43,0,ICE:0)
Block(0,43,2,SNOW:0)
Block(0,43,3,SNOW_BLOCK:0)
Block(0,43,4,SNOW:6)
Block(0,43,5,SNOW:4)
Block(0,43,6,SNOW:1)
Block(0,44,-2,SNOW:0)
Block(0,44,-1,ICE:0)
Block(0,44,0,ICE:0)
Block(0,44,3,SNOW:2)
Block(0,45,-1,ICE:0)
Block(0,45,0,PACKED_ICE:0)
Block(0,46,-1,SNOW:0)
Block(0,46,0,PACKED_ICE:0)
Block(0,47,0,PACKED_ICE:0)
Block(0,48,0,SNOW:0)
Block(1,8,-4,PACKED_ICE:0)
Block(1,9,-4,PACKED_ICE:0)
Block(1,9,1,PACKED_ICE:0)
Block(1,10,-4,PACKED_ICE:0)
Block(1,10,-1,PACKED_ICE:0)
Block(1,10,0,PACKED_ICE:0)
Block(1,10,1,ICE:0)
Block(1,10,2,ICE:0)
Block(1,11,-4,PACKED_ICE:0)
Block(1,11,-1,ICE:0)
Block(1,11,0,PACKED_ICE:0)
Block(1,11,1,ICE:0)
Block(1,11,2,ICE:0)
Block(1,12,-5,PACKED_ICE:0)
Block(1,12,-4,ICE:0)
Block(1,12,-2,ICE:0)
Block(1,12,-1,ICE:0)
Block(1,12,0,ICE:0)
Block(1,12,1,ICE:0)
Block(1,12,2,ICE:0)
Block(1,12,3,ICE:0)
Block(1,13,-5,ICE:0)
Block(1,13,-4,ICE:0)
Block(1,13,-3,ICE:0)
Block(1,13,-2,ICE:0)
Block(1,13,-1,ICE:0)
Block(1,13,0,PACKED_ICE:0)
Block(1,13,1,PACKED_ICE:0)
Block(1,13,2,ICE:0)
Block(1,13,3,ICE:0)
Block(1,14,-5,ICE:0)
Block(1,14,-4,ICE:0)
Block(1,14,-3,ICE:0)
Block(1,14,-2,ICE:0)
Block(1,14,-1,ICE:0)
Block(1,14,0,PACKED_ICE:0)
Block(1,14,1,PACKED_ICE:0)
Block(1,14,2,PACKED_ICE:0)
Block(1,14,3,ICE:0)
Block(1,15,-5,ICE:0)
Block(1,15,-4,PACKED_ICE:0)
Block(1,15,-3,ICE:0)
Block(1,15,-2,ICE:0)
Block(1,15,-1,PACKED_ICE:0)
Block(1,15,0,PACKED_ICE:0)
Block(1,15,1,PACKED_ICE:0)
Block(1,15,2,PACKED_ICE:0)
Block(1,15,3,PACKED_ICE:0)
Block(1,15,4,ICE:0)
Block(1,15,5,ICE:0)
Block(1,16,-6,ICE:0)
Block(1,16,-5,PACKED_ICE:0)
Block(1,16,-4,PACKED_ICE:0)
Block(1,16,-3,PACKED_ICE:0)
Block(1,16,-2,PACKED_ICE:0)
Block(1,16,-1,PACKED_ICE:0)
Block(1,16,0,PACKED_ICE:0)
Block(1,16,1,PACKED_ICE:0)
Block(1,16,2,PACKED_ICE:0)
Block(1,16,3,PACKED_ICE:0)
Block(1,16,4,PACKED_ICE:0)
Block(1,16,5,ICE:0)
Block(1,16,6,ICE:0)
Block(1,17,-7,ICE:0)
Block(1,17,-6,ICE:0)
Block(1,17,-5,PACKED_ICE:0)
Block(1,17,-4,PACKED_ICE:0)
Block(1,17,-3,PACKED_ICE:0)
Block(1,17,-2,PACKED_ICE:0)
Block(1,17,-1,PACKED_ICE:0)
Block(1,17,0,PACKED_ICE:0)
Block(1,17,1,PACKED_ICE:0)
Block(1,17,2,PACKED_ICE:0)
Block(1,17,3,PACKED_ICE:0)
Block(1,17,4,PACKED_ICE:0)
Block(1,17,5,PACKED_ICE:0)
Block(1,17,6,ICE:0)
Block(1,18,-7,ICE:0)
Block(1,18,-6,ICE:0)
Block(1,18,-5,ICE:0)
Block(1,18,-4,PACKED_ICE:0)
Block(1,18,-3,PACKED_ICE:0)
Block(1,18,-2,PACKED_ICE:0)
Block(1,18,-1,PACKED_ICE:0)
Block(1,18,0,PACKED_ICE:0)
Block(1,18,1,PACKED_ICE:0)
Block(1,18,2,PACKED_ICE:0)
Block(1,18,3,PACKED_ICE:0)
Block(1,18,4,PACKED_ICE:0)
Block(1,18,5,ICE:0)
Block(1,18,6,ICE:0)
Block(1,19,-6,ICE:0)
Block(1,19,-5,PACKED_ICE:0)
Block(1,19,-4,PACKED_ICE:0)
Block(1,19,-3,PACKED_ICE:0)
Block(1,19,-2,PACKED_ICE:0)
Block(1,19,-1,PACKED_ICE:0)
Block(1,19,0,PACKED_ICE:0)
Block(1,19,1,PACKED_ICE:0)
Block(1,19,2,PACKED_ICE:0)
Block(1,19,3,PACKED_ICE:0)
Block(1,19,4,PACKED_ICE:0)
Block(1,19,5,PACKED_ICE:0)
Block(1,19,6,ICE:0)
Block(1,19,7,ICE:0)
Block(1,20,-6,PACKED_ICE:0)
Block(1,20,-5,PACKED_ICE:0)
Block(1,20,-4,PACKED_ICE:0)
Block(1,20,-3,PACKED_ICE:0)
Block(1,20,-2,PACKED_ICE:0)
Block(1,20,-1,PACKED_ICE:0)
Block(1,20,0,PACKED_ICE:0)
Block(1,20,1,PACKED_ICE:0)
Block(1,20,2,PACKED_ICE:0)
Block(1,20,3,PACKED_ICE:0)
Block(1,20,4,PACKED_ICE:0)
Block(1,20,5,ICE:0)
Block(1,20,6,ICE:0)
Block(1,21,-6,ICE:0)
Block(1,21,-5,ICE:0)
Block(1,21,-4,PACKED_ICE:0)
Block(1,21,-3,PACKED_ICE:0)
Block(1,21,-2,PACKED_ICE:0)
Block(1,21,-1,PACKED_ICE:0)
Block(1,21,1,PACKED_ICE:0)
Block(1,21,2,PACKED_ICE:0)
Block(1,21,3,PACKED_ICE:0)
Block(1,21,4,ICE:0)
Block(1,21,5,ICE:0)
Block(1,21,6,ICE:0)
Block(1,22,-6,ICE:0)
Block(1,22,-5,ICE:0)
Block(1,22,-4,PACKED_ICE:0)
Block(1,22,-3,PACKED_ICE:0)
Block(1,22,-2,PACKED_ICE:0)
Block(1,22,3,PACKED_ICE:0)
Block(1,22,4,ICE:0)
Block(1,22,5,ICE:0)
Block(1,23,-5,ICE:0)
Block(1,23,-4,PACKED_ICE:0)
Block(1,23,-3,PACKED_ICE:0)
Block(1,23,-2,PACKED_ICE:0)
Block(1,23,-1,PACKED_ICE:0)
Block(1,23,3,PACKED_ICE:0)
Block(1,23,4,ICE:0)
Block(1,23,5,ICE:0)
Block(1,24,-5,ICE:0)
Block(1,24,-4,ICE:0)
Block(1,24,-3,PACKED_ICE:0)
Block(1,24,-2,PACKED_ICE:0)
Block(1,24,-1,PACKED_ICE:0)
Block(1,24,4,ICE:0)
Block(1,25,-4,ICE:0)
Block(1,25,-3,ICE:0)
Block(1,25,-2,ICE:0)
Block(1,26,-4,ICE:0)
Block(1,26,-3,ICE:0)
Block(1,26,-2,ICE:0)
Block(1,26,3,PACKED_ICE:0)
Block(1,26,4,PACKED_ICE:0)
Block(1,27,-4,PACKED_ICE:0)
Block(1,27,-3,ICE:0)
Block(1,27,-2,ICE:0)
Block(1,27,-1,PACKED_ICE:0)
Block(1,27,0,ICE:0)
Block(1,27,1,ICE:0)
Block(1,27,2,ICE:0)
Block(1,27,3,PACKED_ICE:0)
Block(1,27,4,PACKED_ICE:0)
Block(1,27,5,PACKED_ICE:0)
Block(1,27,6,PACKED_ICE:0)
Block(1,28,-4,PACKED_ICE:0)
Block(1,28,-3,PACKED_ICE:0)
Block(1,28,-2,PACKED_ICE:0)
Block(1,28,-1,PACKED_ICE:0)
Block(1,28,0,PACKED_ICE:0)
Block(1,28,1,ICE:0)
Block(1,28,2,PACKED_ICE:0)
Block(1,28,3,PACKED_ICE:0)
Block(1,28,4,PACKED_ICE:0)
Block(1,28,5,PACKED_ICE:0)
Block(1,28,6,PACKED_ICE:0)
Block(1,29,-4,PACKED_ICE:0)
Block(1,29,-3,PACKED_ICE:0)
Block(1,29,-2,PACKED_ICE:0)
Block(1,29,-1,PACKED_ICE:0)
Block(1,29,0,PACKED_ICE:0)
Block(1,29,1,PACKED_ICE:0)
Block(1,29,2,PACKED_ICE:0)
Block(1,29,3,PACKED_ICE:0)
Block(1,29,4,PACKED_ICE:0)
Block(1,29,5,PACKED_ICE:0)
Block(1,30,-4,PACKED_ICE:0)
Block(1,30,-3,PACKED_ICE:0)
Block(1,30,-2,PACKED_ICE:0)
Block(1,30,-1,PACKED_ICE:0)
Block(1,30,0,PACKED_ICE:0)
Block(1,30,1,PACKED_ICE:0)
Block(1,30,2,PACKED_ICE:0)
Block(1,30,3,PACKED_ICE:0)
Block(1,30,4,PACKED_ICE:0)
Block(1,30,5,PACKED_ICE:0)
Block(1,31,-4,SNOW:0)
Block(1,31,-3,PACKED_ICE:0)
Block(1,31,-2,ICE:0)
Block(1,31,-1,ICE:0)
Block(1,31,0,ICE:0)
Block(1,31,1,ICE:0)
Block(1,31,2,ICE:0)
Block(1,31,3,ICE:0)
Block(1,31,4,PACKED_ICE:0)
Block(1,32,-3,PACKED_ICE:0)
Block(1,32,-2,ICE:0)
Block(1,32,-1,ICE:0)
Block(1,32,0,ICE:0)
Block(1,32,1,PACKED_ICE:0)
Block(1,32,2,PACKED_ICE:0)
Block(1,32,3,PACKED_ICE:0)
Block(1,32,4,PACKED_ICE:0)
Block(1,32,7,ICE:0)
Block(1,33,-4,PACKED_ICE:0)
Block(1,33,-3,PACKED_ICE:0)
Block(1,33,-2,ICE:0)
Block(1,33,-1,ICE:0)
Block(1,33,0,PACKED_ICE:0)
Block(1,33,1,PACKED_ICE:0)
Block(1,33,2,PACKED_ICE:0)
Block(1,33,3,PACKED_ICE:0)
Block(1,33,4,PACKED_ICE:0)
Block(1,33,7,ICE:0)
Block(1,34,-4,PACKED_ICE:0)
Block(1,34,-3,PACKED_ICE:0)
Block(1,34,-2,ICE:0)
Block(1,34,-1,PACKED_ICE:0)
Block(1,34,0,PACKED_ICE:0)
Block(1,34,1,LOG_2:1)
Block(1,34,2,PACKED_ICE:0)
Block(1,34,3,PACKED_ICE:0)
Block(1,34,4,PACKED_ICE:0)
Block(1,34,7,ICE:0)
Block(1,35,-5,PACKED_ICE:0)
Block(1,35,-4,PACKED_ICE:0)
Block(1,35,-3,PACKED_ICE:0)
Block(1,35,-2,PACKED_ICE:0)
Block(1,35,-1,PACKED_ICE:0)
Block(1,35,0,LOG_2:1)
Block(1,35,1,LOG_2:1)
Block(1,35,2,LOG_2:1)
Block(1,35,3,ICE:0)
Block(1,35,4,PACKED_ICE:0)
Block(1,35,5,PACKED_ICE:0)
Block(1,35,7,PACKED_ICE:0)
Block(1,36,-5,PACKED_ICE:0)
Block(1,36,-4,PACKED_ICE:0)
Block(1,36,-3,PACKED_ICE:0)
Block(1,36,-2,PACKED_ICE:0)
Block(1,36,-1,PACKED_ICE:0)
Block(1,36,0,PACKED_ICE:0)
Block(1,36,1,PACKED_ICE:0)
Block(1,36,2,PACKED_ICE:0)
Block(1,36,3,ICE:0)
Block(1,36,4,LOG_2:1)
Block(1,36,5,PACKED_ICE:0)
Block(1,36,7,PACKED_ICE:0)
Block(1,37,-6,PACKED_ICE:0)
Block(1,37,-5,PACKED_ICE:0)
Block(1,37,-4,PACKED_ICE:0)
Block(1,37,-3,PACKED_ICE:0)
Block(1,37,-2,PACKED_ICE:0)
Block(1,37,-1,PACKED_ICE:0)
Block(1,37,0,PACKED_ICE:0)
Block(1,37,1,PACKED_ICE:0)
Block(1,37,2,ICE:0)
Block(1,37,3,ICE:0)
Block(1,37,4,ICE:0)
Block(1,37,5,LOG_2:1)
Block(1,37,6,PACKED_ICE:0)
Block(1,37,7,PACKED_ICE:0)
Block(1,38,-6,PACKED_ICE:0)
Block(1,38,-5,WOOD:5)
Block(1,38,-4,PACKED_ICE:0)
Block(1,38,-3,PACKED_ICE:0)
Block(1,38,-2,PACKED_ICE:0)
Block(1,38,-1,PACKED_ICE:0)
Block(1,38,0,PACKED_ICE:0)
Block(1,38,1,ICE:0)
Block(1,38,2,PACKED_ICE:0)
Block(1,38,3,PACKED_ICE:0)
Block(1,38,4,PACKED_ICE:0)
Block(1,38,5,WOOD:5)
Block(1,38,6,PACKED_ICE:0)
Block(1,38,7,ICE:0)
Block(1,39,-6,PACKED_ICE:0)
Block(1,39,-5,PACKED_ICE:0)
Block(1,39,-4,PACKED_ICE:0)
Block(1,39,-3,PACKED_ICE:0)
Block(1,39,-2,PACKED_ICE:0)
Block(1,39,-1,PACKED_ICE:0)
Block(1,39,0,PACKED_ICE:0)
Block(1,39,1,ICE:0)
Block(1,39,2,PACKED_ICE:0)
Block(1,39,3,PACKED_ICE:0)
Block(1,39,4,PACKED_ICE:0)
Block(1,39,5,PACKED_ICE:0)
Block(1,39,6,ICE:0)
Block(1,39,7,PACKED_ICE:0)
Block(1,40,-6,SNOW:0)
Block(1,40,-5,ICE:0)
Block(1,40,-4,PACKED_ICE:0)
Block(1,40,-3,ICE:0)
Block(1,40,-2,PACKED_ICE:0)
Block(1,40,-1,PACKED_ICE:0)
Block(1,40,0,PACKED_ICE:0)
Block(1,40,1,ICE:0)
Block(1,40,2,PACKED_ICE:0)
Block(1,40,3,PACKED_ICE:0)
Block(1,40,4,PACKED_ICE:0)
Block(1,40,5,PACKED_ICE:0)
Block(1,40,6,PACKED_ICE:0)
Block(1,40,7,PACKED_ICE:0)
Block(1,41,-5,ICE:0)
Block(1,41,-4,PACKED_ICE:0)
Block(1,41,-3,ICE:0)
Block(1,41,-2,PACKED_ICE:0)
Block(1,41,-1,PACKED_ICE:0)
Block(1,41,0,PACKED_ICE:0)
Block(1,41,1,ICE:0)
Block(1,41,2,PACKED_ICE:0)
Block(1,41,3,ICE:0)
Block(1,41,4,ICE:0)
Block(1,41,5,WOOD_STEP:5)
Block(1,41,6,PACKED_ICE:0)
Block(1,41,7,SNOW_BLOCK:0)
Block(1,42,-5,SNOW:0)
Block(1,42,-4,PACKED_ICE:0)
Block(1,42,-3,PACKED_ICE:0)
Block(1,42,-2,ICE:0)
Block(1,42,-1,PACKED_ICE:0)
Block(1,42,0,PACKED_ICE:0)
Block(1,42,1,ICE:0)
Block(1,42,2,PACKED_ICE:0)
Block(1,42,3,ICE:0)
Block(1,42,4,SNOW_BLOCK:0)
Block(1,42,5,SNOW_BLOCK:0)
Block(1,42,6,SNOW_BLOCK:0)
Block(1,42,7,SNOW:2)
Block(1,43,-4,SNOW:0)
Block(1,43,-3,PACKED_ICE:0)
Block(1,43,-2,PACKED_ICE:0)
Block(1,43,-1,ICE:0)
Block(1,43,0,PACKED_ICE:0)
Block(1,43,1,ICE:0)
Block(1,43,2,PACKED_ICE:0)
Block(1,43,3,SNOW_BLOCK:0)
Block(1,43,4,SNOW_BLOCK:0)
Block(1,43,5,SNOW:5)
Block(1,43,6,SNOW:2)
Block(1,44,-3,SNOW:0)
Block(1,44,-2,ICE:0)
Block(1,44,-1,ICE:0)
Block(1,44,0,PACKED_ICE:0)
Block(1,44,1,ICE:0)
Block(1,44,2,ICE:0)
Block(1,44,3,SNOW_BLOCK:0)
Block(1,44,4,SNOW:1)
Block(1,45,-2,SNOW:0)
Block(1,45,-1,ICE:0)
Block(1,45,0,PACKED_ICE:0)
Block(1,45,1,PACKED_ICE:0)
Block(1,45,3,SNOW:0)
Block(1,46,-1,ICE:0)
Block(1,46,0,ICE:0)
Block(1,46,1,PACKED_ICE:0)
Block(1,47,-1,SNOW:0)
Block(1,47,0,ICE:0)
Block(1,47,1,SNOW:0)
Block(1,48,0,ICE:0)
Block(1,49,0,ICE:0)
Block(2,9,1,ICE:0)
Block(2,10,0,ICE:0)
Block(2,10,1,ICE:0)
Block(2,11,-1,ICE:0)
Block(2,11,0,ICE:0)
Block(2,11,1,ICE:0)
Block(2,11,2,ICE:0)
Block(2,11,5,PACKED_ICE:0)
Block(2,12,-1,ICE:0)
Block(2,12,0,ICE:0)
Block(2,12,1,ICE:0)
Block(2,12,2,ICE:0)
Block(2,12,5,PACKED_ICE:0)
Block(2,13,-4,ICE:0)
Block(2,13,-2,ICE:0)
Block(2,13,-1,ICE:0)
Block(2,13,0,ICE:0)
Block(2,13,1,PACKED_ICE:0)
Block(2,13,2,PACKED_ICE:0)
Block(2,13,5,PACKED_ICE:0)
Block(2,14,-5,ICE:0)
Block(2,14,-4,ICE:0)
Block(2,14,-3,ICE:0)
Block(2,14,-2,ICE:0)
Block(2,14,-1,ICE:0)
Block(2,14,0,PACKED_ICE:0)
Block(2,14,1,PACKED_ICE:0)
Block(2,14,2,PACKED_ICE:0)
Block(2,14,3,PACKED_ICE:0)
Block(2,14,5,PACKED_ICE:0)
Block(2,14,6,PACKED_ICE:0)
Block(2,15,-5,ICE:0)
Block(2,15,-4,ICE:0)
Block(2,15,-3,ICE:0)
Block(2,15,-2,ICE:0)
Block(2,15,-1,PACKED_ICE:0)
Block(2,15,0,PACKED_ICE:0)
Block(2,15,1,PACKED_ICE:0)
Block(2,15,2,PACKED_ICE:0)
Block(2,15,3,PACKED_ICE:0)
Block(2,15,4,PACKED_ICE:0)
Block(2,15,5,PACKED_ICE:0)
Block(2,15,6,PACKED_ICE:0)
Block(2,16,-6,PACKED_ICE:0)
Block(2,16,-5,PACKED_ICE:0)
Block(2,16,-4,PACKED_ICE:0)
Block(2,16,-3,PACKED_ICE:0)
Block(2,16,-2,PACKED_ICE:0)
Block(2,16,-1,PACKED_ICE:0)
Block(2,16,0,PACKED_ICE:0)
Block(2,16,1,PACKED_ICE:0)
Block(2,16,2,PACKED_ICE:0)
Block(2,16,3,PACKED_ICE:0)
Block(2,16,4,PACKED_ICE:0)
Block(2,16,5,PACKED_ICE:0)
Block(2,16,6,PACKED_ICE:0)
Block(2,17,-7,ICE:0)
Block(2,17,-6,ICE:0)
Block(2,17,-5,PACKED_ICE:0)
Block(2,17,-4,PACKED_ICE:0)
Block(2,17,-3,PACKED_ICE:0)
Block(2,17,-2,PACKED_ICE:0)
Block(2,17,-1,PACKED_ICE:0)
Block(2,17,0,PACKED_ICE:0)
Block(2,17,1,PACKED_ICE:0)
Block(2,17,2,PACKED_ICE:0)
Block(2,17,3,PACKED_ICE:0)
Block(2,17,4,PACKED_ICE:0)
Block(2,17,5,ICE:0)
Block(2,17,6,ICE:0)
Block(2,18,-6,ICE:0)
Block(2,18,-5,ICE:0)
Block(2,18,-4,PACKED_ICE:0)
Block(2,18,-3,PACKED_ICE:0)
Block(2,18,-2,PACKED_ICE:0)
Block(2,18,-1,PACKED_ICE:0)
Block(2,18,0,PACKED_ICE:0)
Block(2,18,1,PACKED_ICE:0)
Block(2,18,2,PACKED_ICE:0)
Block(2,18,3,PACKED_ICE:0)
Block(2,18,4,PACKED_ICE:0)
Block(2,18,5,ICE:0)
Block(2,18,6,ICE:0)
Block(2,19,-6,ICE:0)
Block(2,19,-5,ICE:0)
Block(2,19,-4,ICE:0)
Block(2,19,-3,PACKED_ICE:0)
Block(2,19,-2,PACKED_ICE:0)
Block(2,19,-1,PACKED_ICE:0)
Block(2,19,0,PACKED_ICE:0)
Block(2,19,1,PACKED_ICE:0)
Block(2,19,2,PACKED_ICE:0)
Block(2,19,3,PACKED_ICE:0)
Block(2,19,4,PACKED_ICE:0)
Block(2,19,5,ICE:0)
Block(2,19,6,ICE:0)
Block(2,20,-6,PACKED_ICE:0)
Block(2,20,-5,ICE:0)
Block(2,20,-4,ICE:0)
Block(2,20,-3,PACKED_ICE:0)
Block(2,20,-2,PACKED_ICE:0)
Block(2,20,0,PACKED_ICE:0)
Block(2,20,1,PACKED_ICE:0)
Block(2,20,2,PACKED_ICE:0)
Block(2,20,3,PACKED_ICE:0)
Block(2,20,4,ICE:0)
Block(2,20,5,ICE:0)
Block(2,20,6,ICE:0)
Block(2,21,-5,ICE:0)
Block(2,21,-4,ICE:0)
Block(2,21,-3,ICE:0)
Block(2,21,2,PACKED_ICE:0)
Block(2,21,3,PACKED_ICE:0)
Block(2,21,4,ICE:0)
Block(2,21,5,ICE:0)
Block(2,21,6,ICE:0)
Block(2,22,-5,ICE:0)
Block(2,22,-4,ICE:0)
Block(2,22,-3,PACKED_ICE:0)
Block(2,22,-2,PACKED_ICE:0)
Block(2,22,2,ICE:0)
Block(2,22,3,PACKED_ICE:0)
Block(2,22,4,ICE:0)
Block(2,22,5,ICE:0)
Block(2,23,-4,PACKED_ICE:0)
Block(2,23,-3,PACKED_ICE:0)
Block(2,23,-2,PACKED_ICE:0)
Block(2,23,3,ICE:0)
Block(2,23,4,ICE:0)
Block(2,23,5,ICE:0)
Block(2,24,-4,PACKED_ICE:0)
Block(2,24,-2,PACKED_ICE:0)
Block(2,24,3,ICE:0)
Block(2,24,4,PACKED_ICE:0)
Block(2,25,-1,ICE:0)
Block(2,25,2,ICE:0)
Block(2,25,3,ICE:0)
Block(2,25,4,PACKED_ICE:0)
Block(2,26,-2,ICE:0)
Block(2,26,-1,ICE:0)
Block(2,26,0,ICE:0)
Block(2,26,1,ICE:0)
Block(2,26,2,ICE:0)
Block(2,26,3,PACKED_ICE:0)
Block(2,26,4,PACKED_ICE:0)
Block(2,27,-3,ICE:0)
Block(2,27,-2,ICE:0)
Block(2,27,-1,ICE:0)
Block(2,27,0,ICE:0)
Block(2,27,1,ICE:0)
Block(2,27,2,ICE:0)
Block(2,27,3,PACKED_ICE:0)
Block(2,27,4,PACKED_ICE:0)
Block(2,27,5,PACKED_ICE:0)
Block(2,28,-3,PACKED_ICE:0)
Block(2,28,-2,PACKED_ICE:0)
Block(2,28,-1,ICE:0)
Block(2,28,0,PACKED_ICE:0)
Block(2,28,1,PACKED_ICE:0)
Block(2,28,2,PACKED_ICE:0)
Block(2,28,3,PACKED_ICE:0)
Block(2,28,4,PACKED_ICE:0)
Block(2,28,5,ICE:0)
Block(2,29,-3,PACKED_ICE:0)
Block(2,29,-2,PACKED_ICE:0)
Block(2,29,-1,PACKED_ICE:0)
Block(2,29,0,PACKED_ICE:0)
Block(2,29,1,PACKED_ICE:0)
Block(2,29,2,PACKED_ICE:0)
Block(2,29,3,PACKED_ICE:0)
Block(2,29,4,PACKED_ICE:0)
Block(2,29,5,ICE:0)
Block(2,30,-4,PACKED_ICE:0)
Block(2,30,-3,PACKED_ICE:0)
Block(2,30,-2,PACKED_ICE:0)
Block(2,30,-1,PACKED_ICE:0)
Block(2,30,0,PACKED_ICE:0)
Block(2,30,1,PACKED_ICE:0)
Block(2,30,2,PACKED_ICE:0)
Block(2,30,3,PACKED_ICE:0)
Block(2,30,4,PACKED_ICE:0)
Block(2,30,5,ICE:0)
Block(2,31,-4,PACKED_ICE:0)
Block(2,31,-3,PACKED_ICE:0)
Block(2,31,-2,ICE:0)
Block(2,31,-1,ICE:0)
Block(2,31,0,ICE:0)
Block(2,31,1,ICE:0)
Block(2,31,2,ICE:0)
Block(2,31,3,ICE:0)
Block(2,31,5,ICE:0)
Block(2,32,-4,PACKED_ICE:0)
Block(2,32,-3,PACKED_ICE:0)
Block(2,32,-2,PACKED_ICE:0)
Block(2,32,-1,PACKED_ICE:0)
Block(2,32,0,PACKED_ICE:0)
Block(2,32,1,PACKED_ICE:0)
Block(2,32,2,PACKED_ICE:0)
Block(2,32,3,SNOW:0)
Block(2,32,5,ICE:0)
Block(2,33,-5,PACKED_ICE:0)
Block(2,33,-4,PACKED_ICE:0)
Block(2,33,-3,PACKED_ICE:0)
Block(2,33,-2,PACKED_ICE:0)
Block(2,33,-1,PACKED_ICE:0)
Block(2,33,0,PACKED_ICE:0)
Block(2,33,1,PACKED_ICE:0)
Block(2,33,2,PACKED_ICE:0)
Block(2,33,3,PACKED_ICE:0)
Block(2,33,5,ICE:0)
Block(2,34,-5,PACKED_ICE:0)
Block(2,34,-4,ICE:0)
Block(2,34,-3,PACKED_ICE:0)
Block(2,34,-2,PACKED_ICE:0)
Block(2,34,-1,ICE:0)
Block(2,34,0,PACKED_ICE:0)
Block(2,34,1,PACKED_ICE:0)
Block(2,34,2,PACKED_ICE:0)
Block(2,34,3,PACKED_ICE:0)
Block(2,34,4,PACKED_ICE:0)
Block(2,34,5,ICE:0)
Block(2,35,-5,PACKED_ICE:0)
Block(2,35,-4,ICE:0)
Block(2,35,-3,PACKED_ICE:0)
Block(2,35,-2,PACKED_ICE:0)
Block(2,35,-1,PACKED_ICE:0)
Block(2,35,0,LOG_2:1)
Block(2,35,1,LOG_2:1)
Block(2,35,2,LOG_2:1)
Block(2,35,3,PACKED_ICE:0)
Block(2,35,4,PACKED_ICE:0)
Block(2,35,5,ICE:0)
Block(2,36,-6,PACKED_ICE:0)
Block(2,36,-5,PACKED_ICE:0)
Block(2,36,-4,ICE:0)
Block(2,36,-3,PACKED_ICE:0)
Block(2,36,-2,PACKED_ICE:0)
Block(2,36,-1,PACKED_ICE:0)
Block(2,36,0,PACKED_ICE:0)
Block(2,36,1,PACKED_ICE:0)
Block(2,36,2,PACKED_ICE:0)
Block(2,36,3,ICE:0)
Block(2,36,4,LOG_2:1)
Block(2,36,5,PACKED_ICE:0)
Block(2,37,-6,PACKED_ICE:0)
Block(2,37,-5,PACKED_ICE:0)
Block(2,37,-4,ICE:0)
Block(2,37,-3,ICE:0)
Block(2,37,-2,PACKED_ICE:0)
Block(2,37,-1,PACKED_ICE:0)
Block(2,37,0,PACKED_ICE:0)
Block(2,37,1,ICE:0)
Block(2,37,2,ICE:0)
Block(2,37,3,ICE:0)
Block(2,37,4,ICE:0)
Block(2,37,5,LOG_2:1)
Block(2,37,6,ICE:0)
Block(2,38,-7,PACKED_ICE:0)
Block(2,38,-6,PACKED_ICE:0)
Block(2,38,-5,PACKED_ICE:0)
Block(2,38,-4,PACKED_ICE:0)
Block(2,38,-3,PACKED_ICE:0)
Block(2,38,-2,PACKED_ICE:0)
Block(2,38,-1,PACKED_ICE:0)
Block(2,38,0,PACKED_ICE:0)
Block(2,38,1,PACKED_ICE:0)
Block(2,38,2,PACKED_ICE:0)
Block(2,38,3,PACKED_ICE:0)
Block(2,38,4,PACKED_ICE:0)
Block(2,38,5,PACKED_ICE:0)
Block(2,38,6,PACKED_ICE:0)
Block(2,39,-7,PACKED_ICE:0)
Block(2,39,-6,PACKED_ICE:0)
Block(2,39,-5,PACKED_ICE:0)
Block(2,39,-4,PACKED_ICE:0)
Block(2,39,-3,PACKED_ICE:0)
Block(2,39,-2,ICE:0)
Block(2,39,-1,PACKED_ICE:0)
Block(2,39,0,PACKED_ICE:0)
Block(2,39,1,PACKED_ICE:0)
Block(2,39,2,PACKED_ICE:0)
Block(2,39,3,PACKED_ICE:0)
Block(2,39,4,PACKED_ICE:0)
Block(2,39,5,PACKED_ICE:0)
Block(2,39,6,ICE:0)
Block(2,40,-7,SNOW:0)
Block(2,40,-6,ICE:0)
Block(2,40,-5,ICE:0)
Block(2,40,-4,ICE:0)
Block(2,40,-3,PACKED_ICE:0)
Block(2,40,-2,PACKED_ICE:0)
Block(2,40,-1,PACKED_ICE:0)
Block(2,40,0,PACKED_ICE:0)
Block(2,40,1,PACKED_ICE:0)
Block(2,40,2,PACKED_ICE:0)
Block(2,40,3,PACKED_ICE:0)
Block(2,40,4,PACKED_ICE:0)
Block(2,40,5,PACKED_ICE:0)
Block(2,40,6,PACKED_ICE:0)
Block(2,40,7,PACKED_ICE:0)
Block(2,41,-6,SNOW:0)
Block(2,41,-5,ICE:0)
Block(2,41,-4,ICE:0)
Block(2,41,-3,PACKED_ICE:0)
Block(2,41,-2,PACKED_ICE:0)
Block(2,41,-1,PACKED_ICE:0)
