Author: NLBlackEagle
Description: No description given
SettingsMode: WriteDisable
Frequency: 0
SpawnHeight: highestBlock
UseCenterForHighestBlock: true
MinHeight: 0
MaxHeight: 255
InheritBO3: 
InheritBO3Rotation: NORTH
OverrideChildSettings: true
OverrideParentHeight: true
CanOverride: true
BranchFrequency: 0
BranchFrequencyGroup: 
MustBeBelowOther: false
MustBeInside: 
CannotBeInside: 
ReplacesBO3: 
MustBeInsideWorldBorders: false
CanSpawnOnWater: false
SpawnOnWaterOnly: false
SpawnUnderWater: false
SpawnAtWaterLevel: false
HeightOffset: -9
RemoveAir: true
ReplaceAbove: 
ReplaceBelow: dirt
ReplaceWithBiomeBlocks: true
ReplaceWithSurfaceBlock: GRASS
ReplaceWithGroundBlock: DIRT
ReplaceWithStoneBlock: STONE
SmoothRadius: 0
SmoothHeightOffset: 0
SmoothStartTop: false
SmoothStartWood: false
SmoothingSurfaceBlock: 
SmoothingGroundBlock: 
BO3Group: 
IsSpawnPoint: false
DoReplaceBlocks: true
Block(1,10,-7,SPRUCE_FENCE:0)
Block(2,0,-7,WOOD:3)
Block(2,0,-6,WOOD:3)
Block(2,0,-5,WOOD:3)
Block(2,0,-4,WOOD:3)
Block(2,0,-3,WOOD:3)
Block(2,1,-7,WOOD:3)
Block(2,1,-6,WOOD:3)
Block(2,1,-5,WOOD:3)
Block(2,1,-4,WOOD:3)
Block(2,1,-3,WOOD:3)
Block(2,2,-7,WOOD:3)
Block(2,2,-6,WOOD:3)
Block(2,2,-5,WOOD:3)
Block(2,2,-4,WOOD:3)
Block(2,2,-3,WOOD:3)
Block(2,3,-7,WOOD:3)
Block(2,3,-6,WOOD:3)
Block(2,3,-5,WOOD:3)
Block(2,3,-4,WOOD:3)
Block(2,3,-3,WOOD:3)
Block(2,4,-7,WOOD:3)
Block(2,4,-6,WOOD:3)
Block(2,4,-5,WOOD:3)
Block(2,4,-4,WOOD:3)
Block(2,4,-3,WOOD:3)
Block(2,5,-7,WOOD:3)
Block(2,5,-6,WOOD:3)
Block(2,5,-5,WOOD:3)
Block(2,5,-4,WOOD:3)
Block(2,5,-3,WOOD:3)
Block(2,6,-7,WOOD:3)
Block(2,6,-6,WOOD:3)
Block(2,6,-5,WOOD:3)
Block(2,6,-4,WOOD:3)
Block(2,6,-3,WOOD:3)
Block(2,7,-7,WOOD:3)
Block(2,7,-6,WOOD:3)
Block(2,7,-5,WOOD:3)
Block(2,7,-4,WOOD:3)
Block(2,7,-3,WOOD:3)
Block(2,8,-7,WOOD:3)
Block(2,8,-6,WOOD:3)
Block(2,8,-5,WOOD:3)
Block(2,8,-4,WOOD:3)
Block(2,8,-3,WOOD:3)
Block(2,9,-7,WOOD:3)
Block(2,9,-6,WOOD:3)
Block(2,9,-5,WOOD:3)
Block(2,9,-4,WOOD:3)
Block(2,9,-3,WOOD:3)
Block(2,10,-7,WOOD:3)
Block(2,10,-6,WOOD:3)
Block(2,10,-5,WOOD:3)
Block(2,10,-4,WOOD:3)
Block(2,10,-3,WOOD:3)
Block(2,10,-2,SPRUCE_FENCE:0)
Block(2,11,-7,WOOD:3)
Block(2,11,-6,WOOD:3)
Block(2,11,-5,WOOD:3)
Block(2,11,-4,WOOD:3)
Block(2,11,-3,WOOD:3)
Block(2,12,-7,WOOD:3)
Block(2,12,-6,WOOD:3)
Block(2,12,-5,WOOD:3)
Block(2,12,-4,WOOD:3)
Block(2,12,-3,WOOD:3)
Block(2,13,-7,WOOD:3)
Block(2,13,-6,WOOD:3)
Block(2,13,-5,WOOD:3)
Block(2,13,-4,WOOD:3)
Block(2,14,-7,WOOD:3)
Block(2,14,-6,WOOD:3)
Block(2,14,-5,WOOD:3)
Block(3,0,-2,WOOD:3)
Block(3,1,-2,WOOD:3)
Block(3,2,-2,WOOD:3)
Block(3,3,-2,WOOD:3)
Block(3,4,-2,WOOD:3)
Block(3,5,-2,WOOD:3)
Block(3,6,-2,WOOD:3)
Block(3,7,-2,WOOD:3)
Block(3,8,-2,WOOD:3)
Block(3,9,-2,WOOD:3)
Block(3,10,-2,WOOD:3)
Block(3,10,-1,SPRUCE_FENCE:0)
Block(3,10,0,SPRUCE_FENCE:0)
Block(3,11,-2,WOOD:3)
Block(3,11,-1,SPRUCE_FENCE:0)
Block(3,12,-2,WOOD:3)
Block(4,0,-1,WOOD:3)
Block(4,0,0,WOOD:3)
Block(4,0,1,LOG:3)
Block(4,1,-1,WOOD:3)
Block(4,1,0,WOOD:3)
Block(4,1,1,LOG:3)
Block(4,2,-1,WOOD:3)
Block(4,2,0,WOOD:3)
Block(4,2,1,LOG:3)
Block(4,3,-1,WOOD:3)
Block(4,3,0,WOOD:3)
Block(4,3,1,LOG:3)
Block(4,4,-1,WOOD:3)
Block(4,4,0,WOOD:3)
Block(4,4,1,LOG:3)
Block(4,5,-1,WOOD:3)
Block(4,5,0,WOOD:3)
Block(4,5,1,LOG:3)
Block(4,6,-1,WOOD:3)
Block(4,6,0,WOOD:3)
Block(4,6,1,LOG:3)
Block(4,7,-1,WOOD:3)
Block(4,7,0,WOOD:3)
Block(4,7,1,LOG:3)
Block(4,8,-1,WOOD:3)
Block(4,8,0,WOOD:3)
Block(4,8,1,LOG:3)
Block(4,9,-1,WOOD:3)
Block(4,9,0,WOOD:3)
Block(4,9,1,LOG:3)
Block(4,10,-1,WOOD:3)
Block(4,10,0,WOOD:3)
Block(4,10,1,LOG:3)
Block(4,10,2,SPRUCE_FENCE:0)
Block(4,11,-1,WOOD:3)
Block(4,11,0,WOOD:3)
Block(4,11,1,LOG:3)
Block(4,12,-1,WOOD:3)
Block(4,12,0,WOOD:3)
Block(4,12,1,LOG:3)
Block(4,13,-1,WOOD:3)
Block(4,13,0,WOOD:3)
Block(4,13,1,LOG:3)
RandomBlock(4,14,1,STANDING_BANNER:2,../../NBT/banners/JungleBanner01.nbt,8,STANDING_BANNER:2,../../NBT/banners/JungleBanner02.nbt,8,STANDING_BANNER:2,../../NBT/banners/JungleBanner03.nbt,8,STANDING_BANNER:2,../../NBT/banners/JungleBanner04.nbt,8,STANDING_BANNER:2,../../NBT/banners/JungleBanner05.nbt,8,STANDING_BANNER:2,../../NBT/banners/JungleBanner06.nbt,8,STANDING_BANNER:2,../../NBT/banners/JungleBanner07.nbt,8,STANDING_BANNER:2,../../NBT/banners/JungleBanner08.nbt,8,STANDING_BANNER:2,../../NBT/banners/JungleBanner09.nbt,8,STANDING_BANNER:2,../../NBT/banners/JungleBanner10.nbt,8,STANDING_BANNER:2,../../NBT/banners/JungleBanner11.nbt,8,STANDING_BANNER:2,../../NBT/banners/JungleBanner12.nbt,8,STANDING_BANNER:2,../../NBT/banners/JungleBanner13.nbt,8,STANDING_BANNER:2,../../NBT/banners/JungleBanner14.nbt,8,STANDING_BANNER:2,../../NBT/banners/JungleBanner15.nbt,8,STANDING_BANNER:2,../../NBT/banners/JungleBanner16.nbt,8,STANDING_BANNER:2,../../NBT/banners/JungleBanner17.nbt,8,STANDING_BANNER:2,../../NBT/banners/JungleBanner18.nbt,8,STANDING_BANNER:2,../../NBT/banners/JungleBanner19.nbt,8,STANDING_BANNER:2,../../NBT/banners/JungleBanner20.nbt,100)
Block(5,0,2,WOOD:3)
Block(5,1,2,WOOD:3)
Block(5,2,2,WOOD:3)
Block(5,3,2,WOOD:3)
Block(5,4,2,WOOD:3)
Block(5,5,2,WOOD:3)
Block(5,6,2,WOOD:3)
Block(5,7,2,WOOD:3)
Block(5,8,2,WOOD:3)
Block(5,9,2,WOOD:3)
Block(5,10,2,WOOD:3)
Block(5,10,3,SPRUCE_FENCE:0)
Block(5,11,2,WOOD:3)
Block(5,11,3,SPRUCE_FENCE:0)
Block(5,12,2,WOOD:3)
Block(5,13,2,WOOD:3)
Block(6,0,3,WOOD:3)
Block(6,1,3,WOOD:3)
Block(6,2,3,WOOD:3)
Block(6,3,3,WOOD:3)
Block(6,4,3,WOOD:3)
Block(6,5,3,WOOD:3)
Block(6,6,3,WOOD:3)
Block(6,7,3,WOOD:3)
Block(6,8,3,WOOD:3)
Block(6,9,-6,GRASS_PATH:0)
Block(6,9,3,WOOD:3)
Block(6,10,3,WOOD:3)
Block(6,10,6,SPRUCE_FENCE:0)
Block(6,10,7,SPRUCE_FENCE:0)
Block(6,11,3,WOOD:3)
Block(6,12,3,WOOD:3)
Block(6,13,3,WOOD:3)
Block(7,0,4,WOOD:3)
Block(7,0,5,WOOD:3)
Block(7,0,6,WOOD:3)
Block(7,0,7,WOOD:3)
Block(7,1,4,WOOD:3)
Block(7,1,5,WOOD:3)
Block(7,1,6,WOOD:3)
Block(7,1,7,WOOD:3)
Block(7,2,4,WOOD:3)
Block(7,2,5,WOOD:3)
Block(7,2,6,WOOD:3)
Block(7,2,7,WOOD:3)
Block(7,3,4,WOOD:3)
Block(7,3,5,WOOD:3)
Block(7,3,6,WOOD:3)
Block(7,3,7,WOOD:3)
Block(7,4,4,WOOD:3)
Block(7,4,5,WOOD:3)
Block(7,4,6,WOOD:3)
Block(7,4,7,WOOD:3)
Block(7,5,4,WOOD:3)
Block(7,5,5,WOOD:3)
Block(7,5,6,WOOD:3)
Block(7,5,7,WOOD:3)
Block(7,6,4,WOOD:3)
Block(7,6,5,WOOD:3)
Block(7,6,6,WOOD:3)
Block(7,6,7,WOOD:3)
Block(7,7,4,WOOD:3)
Block(7,7,5,WOOD:3)
Block(7,7,6,WOOD:3)
Block(7,7,7,WOOD:3)
Block(7,8,4,WOOD:3)
Block(7,8,5,WOOD:3)
Block(7,8,6,WOOD:3)
Block(7,8,7,WOOD:3)
Block(7,9,-7,GRASS_PATH:0)
Block(7,9,-6,GRASS_PATH:0)
Block(7,9,4,WOOD:3)
Block(7,9,5,WOOD:3)
Block(7,9,6,WOOD:3)
Block(7,9,7,WOOD:3)
Block(7,10,4,WOOD:3)
Block(7,10,5,WOOD:3)
Block(7,10,6,WOOD:3)
Block(7,10,7,WOOD:3)
Block(7,10,8,SPRUCE_FENCE:0)
Block(7,11,4,WOOD:3)
Block(7,11,5,WOOD:3)
Block(7,11,6,WOOD:3)
Block(7,11,7,WOOD:3)
Block(7,11,8,SPRUCE_FENCE:0)
Block(7,12,4,WOOD:3)
Block(7,12,5,WOOD:3)
Block(7,12,6,WOOD:3)
Block(7,12,7,WOOD:3)
Block(7,13,4,WOOD:3)
Branch(0,0,-16,true,JungleVillagePath05C1R3,NORTH,100.0,0)
Branch(-16,0,0,true,JungleVillagePath05C0R4,NORTH,100.0,0)