Author: NLBlackEagle
Description: No description given
SettingsMode: WriteDisable
Frequency: 0
SpawnHeight: highestBlock
UseCenterForHighestBlock: true
MinHeight: 0
MaxHeight: 255
InheritBO3: 
InheritBO3Rotation: NORTH
OverrideChildSettings: true
OverrideParentHeight: true
CanOverride: true
BranchFrequency: 0
BranchFrequencyGroup: 
MustBeBelowOther: false
MustBeInside: 
CannotBeInside: 
ReplacesBO3: 
MustBeInsideWorldBorders: false
CanSpawnOnWater: false
SpawnOnWaterOnly: false
SpawnUnderWater: false
SpawnAtWaterLevel: false
HeightOffset: -9
RemoveAir: true
ReplaceAbove: 
ReplaceBelow: dirt
ReplaceWithBiomeBlocks: true
ReplaceWithSurfaceBlock: GRASS
ReplaceWithGroundBlock: DIRT
ReplaceWithStoneBlock: STONE
SmoothRadius: 0
SmoothHeightOffset: 0
SmoothStartTop: false
SmoothStartWood: false
SmoothingSurfaceBlock: 
SmoothingGroundBlock: 
BO3Group: 
IsSpawnPoint: false
DoReplaceBlocks: true
Block(-8,9,8,GRASS_PATH:0)
Block(-7,9,8,GRASS_PATH:0)
Block(-6,9,8,GRASS_PATH:0)
Block(-5,9,8,WOOD:3)
Block(-1,0,-4,LOG:3)
Block(-1,0,3,LOG:3)
Block(-1,1,-4,LOG:3)
Block(-1,1,3,LOG:3)
Block(-1,2,-4,LOG:3)
Block(-1,2,3,LOG:3)
Block(-1,3,-4,LOG:3)
Block(-1,3,3,LOG:3)
Block(-1,4,-4,LOG:3)
Block(-1,4,3,LOG:3)
Block(-1,5,-4,LOG:3)
Block(-1,5,3,LOG:3)
Block(-1,6,-4,LOG:3)
Block(-1,6,3,LOG:3)
Block(-1,7,-4,LOG:3)
Block(-1,7,3,LOG:3)
Block(-1,8,-4,LOG:3)
Block(-1,8,3,LOG:3)
Block(-1,9,-4,LOG:3)
Block(-1,9,3,LOG:3)
Block(-1,10,-4,LOG:3)
Block(-1,10,3,LOG:3)
Block(-1,11,-4,LOG:7)
Block(-1,11,3,LOG:7)
Block(-1,12,-3,WOOD_STEP:3)
Block(-1,12,-2,WOOD_STEP:3)
Block(-1,12,3,WOOD_STEP:3)
Block(-1,12,5,WOOD_STEP:3)
Block(-1,12,6,WOOD_STEP:3)
Block(-1,12,7,WOOD_STEP:3)
Block(-1,12,8,WOOD_STEP:3)
Block(0,0,-7,LOG:3)
Block(0,0,1,LOG:3)
Block(0,0,6,WOOD:3)
Block(0,1,-7,LOG:3)
Block(0,1,1,LOG:3)
Block(0,1,6,WOOD:3)
Block(0,2,-7,LOG:3)
Block(0,2,1,LOG:3)
Block(0,2,6,WOOD:3)
Block(0,3,-7,LOG:3)
Block(0,3,1,LOG:3)
Block(0,3,6,WOOD:3)
Block(0,4,-7,LOG:3)
Block(0,4,1,LOG:3)
Block(0,4,6,WOOD:3)
Block(0,5,-7,LOG:3)
Block(0,5,1,LOG:3)
Block(0,5,6,WOOD:3)
Block(0,6,-7,LOG:3)
Block(0,6,1,LOG:3)
Block(0,6,6,WOOD:3)
Block(0,7,-7,LOG:3)
Block(0,7,1,LOG:3)
Block(0,7,6,WOOD:3)
Block(0,8,-7,LOG:3)
Block(0,8,1,LOG:3)
Block(0,8,6,WOOD:3)
Block(0,9,-7,LOG:3)
Block(0,9,1,LOG:3)
Block(0,9,6,WOOD:3)
Block(0,10,-7,LOG:3)
Block(0,10,1,LOG:3)
Block(0,10,6,WOOD:3)
Block(0,11,-7,LOG:7)
Block(0,11,-4,LOG:7)
Block(0,11,1,LOG:7)
Block(0,11,3,LOG:7)
Block(0,11,6,WOOD:3)
Block(0,12,-5,WOOD_STEP:3)
Block(0,12,-4,WOOD_STEP:3)
Block(0,12,-3,WOOD_STEP:3)
Block(0,12,-2,WOOD_STEP:3)
Block(0,12,-1,WOOD_STEP:3)
Block(0,12,0,WOOD_STEP:3)
Block(0,12,2,WOOD_STEP:3)
Block(0,12,3,WOOD_STEP:3)
Block(0,12,4,WOOD_STEP:3)
Block(0,12,5,WOOD_STEP:3)
Block(0,12,6,WOOD:3)
Block(0,12,7,WOOD_STEP:3)
Block(0,12,8,WOOD_STEP:3)
Block(0,13,6,SPRUCE_FENCE:0)
Block(1,0,-2,WOOD:3)
Block(1,0,-1,WOOD:3)
Block(1,0,5,WOOD:3)
Block(1,0,7,WOOD:3)
Block(1,0,8,WOOD:3)
Block(1,1,-2,WOOD:3)
Block(1,1,-1,WOOD:3)
Block(1,1,5,WOOD:3)
Block(1,1,7,WOOD:3)
Block(1,1,8,WOOD:3)
Block(1,2,-2,WOOD:3)
Block(1,2,-1,WOOD:3)
Block(1,2,5,WOOD:3)
Block(1,2,7,WOOD:3)
Block(1,2,8,WOOD:3)
Block(1,3,-2,WOOD:3)
Block(1,3,-1,WOOD:3)
Block(1,3,5,WOOD:3)
Block(1,3,7,WOOD:3)
Block(1,3,8,WOOD:3)
Block(1,4,-2,WOOD:3)
Block(1,4,-1,WOOD:3)
Block(1,4,5,WOOD:3)
Block(1,4,7,WOOD:3)
Block(1,4,8,WOOD:3)
Block(1,5,-2,WOOD:3)
Block(1,5,-1,WOOD:3)
Block(1,5,5,WOOD:3)
Block(1,5,7,WOOD:3)
Block(1,5,8,WOOD:3)
Block(1,6,-2,WOOD:3)
Block(1,6,-1,WOOD:3)
Block(1,6,5,WOOD:3)
Block(1,6,7,WOOD:3)
Block(1,6,8,WOOD:3)
Block(1,7,-2,WOOD:3)
Block(1,7,-1,WOOD:3)
Block(1,7,5,WOOD:3)
Block(1,7,7,WOOD:3)
Block(1,7,8,WOOD:3)
Block(1,8,-2,WOOD:3)
Block(1,8,-1,WOOD:3)
Block(1,8,5,WOOD:3)
Block(1,8,7,WOOD:3)
Block(1,8,8,WOOD:3)
Block(1,9,-2,WOOD:3)
Block(1,9,-1,WOOD:3)
Block(1,9,5,WOOD:3)
Block(1,9,7,WOOD:3)
Block(1,9,8,WOOD:3)
Block(1,10,-2,WOOD:3)
Block(1,10,-1,WOOD:3)
Block(1,10,5,WOOD:3)
Block(1,10,6,SPRUCE_FENCE:0)
Block(1,10,7,WOOD:3)
Block(1,10,8,WOOD:3)
Block(1,11,-7,LOG:7)
Block(1,11,-4,LOG:7)
Block(1,11,-2,WOOD:3)
Block(1,11,-1,WOOD:3)
Block(1,11,1,LOG:7)
Block(1,11,3,LOG:7)
Block(1,11,5,WOOD:3)
Block(1,11,7,WOOD:3)
Block(1,11,8,WOOD:3)
Block(1,12,-7,WOOD_STEP:3)
Block(1,12,-6,WOOD_STEP:3)
Block(1,12,-5,WOOD_STEP:3)
Block(1,12,-4,WOOD_STEP:3)
Block(1,12,-3,WOOD_STEP:3)
Block(1,12,-2,WOOD:3)
Block(1,12,-1,WOOD:3)
Block(1,12,0,WOOD_STEP:3)
Block(1,12,1,WOOD_STEP:3)
Block(1,12,2,WOOD_STEP:3)
Block(1,12,3,WOOD_STEP:3)
Block(1,12,4,WOOD_STEP:3)
Block(1,12,5,WOOD:3)
Block(1,12,7,WOOD:3)
Block(1,12,8,WOOD:3)
Block(1,13,-6,AIR:0)
Block(1,13,-2,SPRUCE_FENCE:0)
Block(1,13,-1,SPRUCE_FENCE:0)
Block(1,13,2,AIR:0)
Block(1,13,5,SPRUCE_FENCE:0)
Block(1,13,7,SPRUCE_FENCE:0)
Block(1,13,8,WOOD:3)
Block(2,0,-3,WOOD:3)
Block(2,0,0,WOOD:3)
Block(2,0,3,LOG:3)
Block(2,0,4,WOOD:3)
Block(2,1,-3,WOOD:3)
Block(2,1,0,WOOD:3)
Block(2,1,3,LOG:3)
Block(2,1,4,WOOD:3)
Block(2,2,-3,WOOD:3)
Block(2,2,0,WOOD:3)
Block(2,2,3,LOG:3)
Block(2,2,4,WOOD:3)
Block(2,3,-3,WOOD:3)
Block(2,3,0,WOOD:3)
Block(2,3,3,LOG:3)
Block(2,3,4,WOOD:3)
Block(2,4,-3,WOOD:3)
Block(2,4,0,WOOD:3)
Block(2,4,3,LOG:3)
Block(2,4,4,WOOD:3)
Block(2,5,-3,WOOD:3)
Block(2,5,0,WOOD:3)
Block(2,5,3,LOG:3)
Block(2,5,4,WOOD:3)
Block(2,6,-3,WOOD:3)
Block(2,6,0,WOOD:3)
Block(2,6,3,LOG:3)
Block(2,6,4,WOOD:3)
Block(2,7,-3,WOOD:3)
Block(2,7,0,WOOD:3)
Block(2,7,3,LOG:3)
Block(2,7,4,WOOD:3)
Block(2,8,-3,WOOD:3)
Block(2,8,0,WOOD:3)
Block(2,8,3,LOG:3)
Block(2,8,4,WOOD:3)
Block(2,9,-3,WOOD:3)
Block(2,9,0,WOOD:3)
Block(2,9,3,LOG:3)
Block(2,9,4,WOOD:3)
Block(2,10,-3,WOOD:3)
Block(2,10,-2,SPRUCE_FENCE:0)
Block(2,10,-1,SPRUCE_FENCE:0)
Block(2,10,0,WOOD:3)
Block(2,10,3,LOG:3)
Block(2,10,4,WOOD:3)
Block(2,10,5,SPRUCE_FENCE:0)
Block(2,10,8,SPRUCE_FENCE:0)
Block(2,11,-7,LOG:7)
Block(2,11,-4,LOG:7)
Block(2,11,-3,WOOD:3)
Block(2,11,-2,SPRUCE_FENCE:0)
Block(2,11,0,WOOD:3)
Block(2,11,1,LOG:7)
Block(2,11,3,LOG:3)
Block(2,11,4,WOOD:3)
Block(2,12,-7,WOOD_STEP:3)
Block(2,12,-6,WOOD_STEP:3)
Block(2,12,-5,WOOD_STEP:3)
Block(2,12,-4,WOOD_STEP:3)
Block(2,12,-3,WOOD:3)
Block(2,12,0,WOOD:3)
Block(2,12,1,WOOD_STEP:3)
Block(2,12,2,WOOD_STEP:3)
Block(2,12,3,LOG:3)
Block(2,12,4,WOOD:3)
Block(2,13,-3,WOOD:3)
Block(2,13,0,WOOD:3)
Block(2,13,3,LOG:3)
Block(2,13,4,WOOD:3)
Block(2,14,3,LOG:3)
Block(3,0,-7,LOG:3)
Block(3,0,-6,WOOD:3)
Block(3,0,-5,WOOD:3)
Block(3,0,-4,LOG:3)
Block(3,0,1,LOG:3)
Block(3,0,2,WOOD:3)
Block(3,1,-7,LOG:3)
Block(3,1,-6,WOOD:3)
Block(3,1,-5,WOOD:3)
Block(3,1,-4,LOG:3)
Block(3,1,1,LOG:3)
Block(3,1,2,WOOD:3)
Block(3,2,-7,LOG:3)
Block(3,2,-6,WOOD:3)
Block(3,2,-5,WOOD:3)
Block(3,2,-4,LOG:3)
Block(3,2,1,LOG:3)
Block(3,2,2,WOOD:3)
Block(3,3,-7,LOG:3)
Block(3,3,-6,WOOD:3)
Block(3,3,-5,WOOD:3)
Block(3,3,-4,LOG:3)
Block(3,3,1,LOG:3)
Block(3,3,2,WOOD:3)
Block(3,4,-7,LOG:3)
Block(3,4,-6,WOOD:3)
Block(3,4,-5,WOOD:3)
Block(3,4,-4,LOG:3)
Block(3,4,1,LOG:3)
Block(3,4,2,WOOD:3)
Block(3,5,-7,LOG:3)
Block(3,5,-6,WOOD:3)
Block(3,5,-5,WOOD:3)
Block(3,5,-4,LOG:3)
Block(3,5,1,LOG:3)
Block(3,5,2,WOOD:3)
Block(3,6,-7,LOG:3)
Block(3,6,-6,WOOD:3)
Block(3,6,-5,WOOD:3)
Block(3,6,-4,LOG:3)
Block(3,6,1,LOG:3)
Block(3,6,2,WOOD:3)
Block(3,7,-7,LOG:3)
Block(3,7,-6,WOOD:3)
Block(3,7,-5,WOOD:3)
Block(3,7,-4,LOG:3)
Block(3,7,1,LOG:3)
Block(3,7,2,WOOD:3)
Block(3,8,-7,LOG:3)
Block(3,8,-6,WOOD:3)
Block(3,8,-5,WOOD:3)
Block(3,8,-4,LOG:3)
Block(3,8,1,LOG:3)
Block(3,8,2,WOOD:3)
Block(3,9,-7,LOG:3)
Block(3,9,-6,WOOD:3)
Block(3,9,-5,WOOD:3)
Block(3,9,-4,LOG:3)
Block(3,9,1,LOG:3)
Block(3,9,2,WOOD:3)
Block(3,10,-7,LOG:3)
Block(3,10,-6,WOOD:3)
Block(3,10,-5,WOOD:3)
Block(3,10,-4,LOG:3)
Block(3,10,-3,SPRUCE_FENCE:0)
Block(3,10,0,SPRUCE_FENCE:0)
Block(3,10,1,LOG:3)
Block(3,10,2,WOOD:3)
Block(3,10,3,SPRUCE_FENCE:0)
Block(3,11,-7,LOG:3)
Block(3,11,-6,WOOD:3)
Block(3,11,-5,WOOD:3)
Block(3,11,-4,LOG:3)
Block(3,11,1,LOG:3)
Block(3,11,2,WOOD:3)
Block(3,12,-7,LOG:3)
Block(3,12,-6,WOOD:3)
Block(3,12,-5,WOOD:3)
Block(3,12,-4,LOG:3)
Block(3,12,1,LOG:3)
Block(3,12,2,WOOD:3)
Block(3,13,-7,LOG:3)
Block(3,13,-6,WOOD:3)
Block(3,13,-5,WOOD:3)
Block(3,13,-4,LOG:3)
Block(3,13,1,LOG:3)
Block(3,13,2,WOOD:3)
Block(3,14,-7,LOG:3)
Block(3,14,-4,LOG:3)
RandomBlock(3,14,-3,WALL_BANNER:3,../../NBT/banners/JungleBanner01.nbt,8,WALL_BANNER:3,../../NBT/banners/JungleBanner02.nbt,8,WALL_BANNER:3,../../NBT/banners/JungleBanner03.nbt,8,WALL_BANNER:3,../../NBT/banners/JungleBanner04.nbt,8,WALL_BANNER:3,../../NBT/banners/JungleBanner05.nbt,8,WALL_BANNER:3,../../NBT/banners/JungleBanner06.nbt,8,WALL_BANNER:3,../../NBT/banners/JungleBanner07.nbt,8,WALL_BANNER:3,../../NBT/banners/JungleBanner08.nbt,8,WALL_BANNER:3,../../NBT/banners/JungleBanner09.nbt,8,WALL_BANNER:3,../../NBT/banners/JungleBanner10.nbt,8,WALL_BANNER:3,../../NBT/banners/JungleBanner11.nbt,8,WALL_BANNER:3,../../NBT/banners/JungleBanner12.nbt,8,WALL_BANNER:3,../../NBT/banners/JungleBanner13.nbt,8,WALL_BANNER:3,../../NBT/banners/JungleBanner14.nbt,8,WALL_BANNER:3,../../NBT/banners/JungleBanner15.nbt,8,WALL_BANNER:3,../../NBT/banners/JungleBanner16.nbt,8,WALL_BANNER:3,../../NBT/banners/JungleBanner17.nbt,8,WALL_BANNER:3,../../NBT/banners/JungleBanner18.nbt,8,WALL_BANNER:3,../../NBT/banners/JungleBanner19.nbt,8,WALL_BANNER:3,../../NBT/banners/JungleBanner20.nbt,100)
RandomBlock(3,14,0,WALL_BANNER:2,../../NBT/banners/JungleBanner01.nbt,8,WALL_BANNER:2,../../NBT/banners/JungleBanner02.nbt,8,WALL_BANNER:2,../../NBT/banners/JungleBanner03.nbt,8,WALL_BANNER:2,../../NBT/banners/JungleBanner04.nbt,8,WALL_BANNER:2,../../NBT/banners/JungleBanner05.nbt,8,WALL_BANNER:2,../../NBT/banners/JungleBanner06.nbt,8,WALL_BANNER:2,../../NBT/banners/JungleBanner07.nbt,8,WALL_BANNER:2,../../NBT/banners/JungleBanner08.nbt,8,WALL_BANNER:2,../../NBT/banners/JungleBanner09.nbt,8,WALL_BANNER:2,../../NBT/banners/JungleBanner10.nbt,8,WALL_BANNER:2,../../NBT/banners/JungleBanner11.nbt,8,WALL_BANNER:2,../../NBT/banners/JungleBanner12.nbt,8,WALL_BANNER:2,../../NBT/banners/JungleBanner13.nbt,8,WALL_BANNER:2,../../NBT/banners/JungleBanner14.nbt,8,WALL_BANNER:2,../../NBT/banners/JungleBanner15.nbt,8,WALL_BANNER:2,../../NBT/banners/JungleBanner16.nbt,8,WALL_BANNER:2,../../NBT/banners/JungleBanner17.nbt,8,WALL_BANNER:2,../../NBT/banners/JungleBanner18.nbt,8,WALL_BANNER:2,../../NBT/banners/JungleBanner19.nbt,8,WALL_BANNER:2,../../NBT/banners/JungleBanner20.nbt,100)
Block(3,14,1,LOG:3)
RandomBlock(3,14,3,WALL_BANNER:5,../../NBT/banners/JungleBanner01.nbt,8,WALL_BANNER:5,../../NBT/banners/JungleBanner02.nbt,8,WALL_BANNER:5,../../NBT/banners/JungleBanner03.nbt,8,WALL_BANNER:5,../../NBT/banners/JungleBanner04.nbt,8,WALL_BANNER:5,../../NBT/banners/JungleBanner05.nbt,8,WALL_BANNER:5,../../NBT/banners/JungleBanner06.nbt,8,WALL_BANNER:5,../../NBT/banners/JungleBanner07.nbt,8,WALL_BANNER:5,../../NBT/banners/JungleBanner08.nbt,8,WALL_BANNER:5,../../NBT/banners/JungleBanner09.nbt,8,WALL_BANNER:5,../../NBT/banners/JungleBanner10.nbt,8,WALL_BANNER:5,../../NBT/banners/JungleBanner11.nbt,8,WALL_BANNER:5,../../NBT/banners/JungleBanner12.nbt,8,WALL_BANNER:5,../../NBT/banners/JungleBanner13.nbt,8,WALL_BANNER:5,../../NBT/banners/JungleBanner14.nbt,8,WALL_BANNER:5,../../NBT/banners/JungleBanner15.nbt,8,WALL_BANNER:5,../../NBT/banners/JungleBanner16.nbt,8,WALL_BANNER:5,../../NBT/banners/JungleBanner17.nbt,8,WALL_BANNER:5,../../NBT/banners/JungleBanner18.nbt,8,WALL_BANNER:5,../../NBT/banners/JungleBanner19.nbt,8,WALL_BANNER:5,../../NBT/banners/JungleBanner20.nbt,100)
Block(4,10,-5,SPRUCE_FENCE:0)
Block(4,10,-4,SPRUCE_FENCE:0)
Block(4,10,1,SPRUCE_FENCE:0)
RandomBlock(4,14,-7,WALL_BANNER:5,../../NBT/banners/JungleBanner01.nbt,8,WALL_BANNER:5,../../NBT/banners/JungleBanner02.nbt,8,WALL_BANNER:5,../../NBT/banners/JungleBanner03.nbt,8,WALL_BANNER:5,../../NBT/banners/JungleBanner04.nbt,8,WALL_BANNER:5,../../NBT/banners/JungleBanner05.nbt,8,WALL_BANNER:5,../../NBT/banners/JungleBanner06.nbt,8,WALL_BANNER:5,../../NBT/banners/JungleBanner07.nbt,8,WALL_BANNER:5,../../NBT/banners/JungleBanner08.nbt,8,WALL_BANNER:5,../../NBT/banners/JungleBanner09.nbt,8,WALL_BANNER:5,../../NBT/banners/JungleBanner10.nbt,8,WALL_BANNER:5,../../NBT/banners/JungleBanner11.nbt,8,WALL_BANNER:5,../../NBT/banners/JungleBanner12.nbt,8,WALL_BANNER:5,../../NBT/banners/JungleBanner13.nbt,8,WALL_BANNER:5,../../NBT/banners/JungleBanner14.nbt,8,WALL_BANNER:5,../../NBT/banners/JungleBanner15.nbt,8,WALL_BANNER:5,../../NBT/banners/JungleBanner16.nbt,8,WALL_BANNER:5,../../NBT/banners/JungleBanner17.nbt,8,WALL_BANNER:5,../../NBT/banners/JungleBanner18.nbt,8,WALL_BANNER:5,../../NBT/banners/JungleBanner19.nbt,8,WALL_BANNER:5,../../NBT/banners/JungleBanner20.nbt,100)
RandomBlock(4,14,-4,WALL_BANNER:5,../../NBT/banners/JungleBanner01.nbt,8,WALL_BANNER:5,../../NBT/banners/JungleBanner02.nbt,8,WALL_BANNER:5,../../NBT/banners/JungleBanner03.nbt,8,WALL_BANNER:5,../../NBT/banners/JungleBanner04.nbt,8,WALL_BANNER:5,../../NBT/banners/JungleBanner05.nbt,8,WALL_BANNER:5,../../NBT/banners/JungleBanner06.nbt,8,WALL_BANNER:5,../../NBT/banners/JungleBanner07.nbt,8,WALL_BANNER:5,../../NBT/banners/JungleBanner08.nbt,8,WALL_BANNER:5,../../NBT/banners/JungleBanner09.nbt,8,WALL_BANNER:5,../../NBT/banners/JungleBanner10.nbt,8,WALL_BANNER:5,../../NBT/banners/JungleBanner11.nbt,8,WALL_BANNER:5,../../NBT/banners/JungleBanner12.nbt,8,WALL_BANNER:5,../../NBT/banners/JungleBanner13.nbt,8,WALL_BANNER:5,../../NBT/banners/JungleBanner14.nbt,8,WALL_BANNER:5,../../NBT/banners/JungleBanner15.nbt,8,WALL_BANNER:5,../../NBT/banners/JungleBanner16.nbt,8,WALL_BANNER:5,../../NBT/banners/JungleBanner17.nbt,8,WALL_BANNER:5,../../NBT/banners/JungleBanner18.nbt,8,WALL_BANNER:5,../../NBT/banners/JungleBanner19.nbt,8,WALL_BANNER:5,../../NBT/banners/JungleBanner20.nbt,100)
RandomBlock(4,14,1,WALL_BANNER:5,../../NBT/banners/JungleBanner01.nbt,8,WALL_BANNER:5,../../NBT/banners/JungleBanner02.nbt,8,WALL_BANNER:5,../../NBT/banners/JungleBanner03.nbt,8,WALL_BANNER:5,../../NBT/banners/JungleBanner04.nbt,8,WALL_BANNER:5,../../NBT/banners/JungleBanner05.nbt,8,WALL_BANNER:5,../../NBT/banners/JungleBanner06.nbt,8,WALL_BANNER:5,../../NBT/banners/JungleBanner07.nbt,8,WALL_BANNER:5,../../NBT/banners/JungleBanner08.nbt,8,WALL_BANNER:5,../../NBT/banners/JungleBanner09.nbt,8,WALL_BANNER:5,../../NBT/banners/JungleBanner10.nbt,8,WALL_BANNER:5,../../NBT/banners/JungleBanner11.nbt,8,WALL_BANNER:5,../../NBT/banners/JungleBanner12.nbt,8,WALL_BANNER:5,../../NBT/banners/JungleBanner13.nbt,8,WALL_BANNER:5,../../NBT/banners/JungleBanner14.nbt,8,WALL_BANNER:5,../../NBT/banners/JungleBanner15.nbt,8,WALL_BANNER:5,../../NBT/banners/JungleBanner16.nbt,8,WALL_BANNER:5,../../NBT/banners/JungleBanner17.nbt,8,WALL_BANNER:5,../../NBT/banners/JungleBanner18.nbt,8,WALL_BANNER:5,../../NBT/banners/JungleBanner19.nbt,8,WALL_BANNER:5,../../NBT/banners/JungleBanner20.nbt,100)
Branch(0,0,16,true,JungleVillagePath09C6R4,NORTH,100.0,0)
#Entity(1,13,-6,minecraft:villager,1,../../NBT/entities/tribalbowman.txt)
#Entity(1,13,2,minecraft:villager,1,../../NBT/entities/tribalbowman.txt)