
#######################################################################
# +-----------------------------------------------------------------+ #
# |                            BO3 object                           | #
# +-----------------------------------------------------------------+ #
#######################################################################

Author: NLBlackHeavenNL

Description: No description given

Version: 3

SettingsMode: WriteWithoutComments


#######################################################################
# +-----------------------------------------------------------------+ #
# |                          Main settings                          | #
# +-----------------------------------------------------------------+ #
#######################################################################

Tree: true

Frequency: 1

Rarity: 100.0

RotateRandomly: false

SpawnHeight: highestSolidBlock

SpawnHeightOffset: -1

SpawnHeightVariance: 0

##############################
# Height Limits for the BO3. #
##############################

MinHeight: 0

MaxHeight: 255

######################
# Extrusion settings #
######################

ExtrudeMode: None

ExtrudeThroughBlocks: AIR

MaxBranchDepth: 10

ExcludedBiomes: All


#######################################################################
# +-----------------------------------------------------------------+ #
# |                      Source block settings                      | #
# +-----------------------------------------------------------------+ #
#######################################################################

SourceBlocks: AIR,GRASS,DIRT,biomesoplenty:dirt,biomesoplenty:grass,MYCEL

MaxPercentageOutsideSourceBlock: 0

OutsideSourceBlock: placeAnyway

DoReplaceBlocks: true

IsOTGPlus: false


#######################################################################
# +-----------------------------------------------------------------+ #
# |                              Blocks                             | #
# +-----------------------------------------------------------------+ #
#######################################################################

Block(-3,7,-1,dynamictreesbop:leaves3:2)
Block(-3,7,0,dynamictreesbop:leaves3:1)
Block(-3,7,1,dynamictreesbop:leaves3:0)
Block(-3,8,-1,dynamictreesbop:leaves3:0)
Block(-3,8,0,dynamictreesbop:leaves3:0)
Block(-3,8,1,dynamictreesbop:leaves3:0)
Block(-2,6,1,dynamictreesbop:leaves3:0)
Block(-2,7,-2,dynamictreesbop:leaves3:2)
Block(-2,7,-1,dynamictreesbop:leaves3)
Block(-2,7,0,dynamictreesbop:leaves3)
Block(-2,7,1,dynamictreesbop:leaves3:2)
Block(-2,7,2,dynamictreesbop:leaves3:0)
Block(-2,8,-2,dynamictreesbop:leaves3:0)
Block(-2,8,-1,dynamictreesbop:leaves3:0)
Block(-2,8,0,dynamictreesbop:leaves3:2)
Block(-2,8,1,dynamictreesbop:leaves3:1)
Block(-2,8,2,dynamictreesbop:leaves3:0)
Block(-2,9,-2,dynamictreesbop:leaves3:0)
Block(-2,9,-1,dynamictreesbop:leaves3:0)
Block(-2,9,0,dynamictreesbop:leaves3:1)
Block(-2,9,1,dynamictreesbop:leaves3:0)
Block(-2,10,-2,dynamictreesbop:leaves3:0)
Block(-2,10,-1,dynamictreesbop:leaves3:0)
Block(-2,10,0,dynamictreesbop:leaves3:0)
Block(-2,11,-1,dynamictreesbop:leaves3:0)
Block(-1,6,1,dynamictreesbop:leaves3:0)
Block(-1,6,3,dynamictreesbop:leaves3:0)
Block(-1,6,4,dynamictreesbop:leaves3:0)
Block(-1,7,-2,dynamictreesbop:leaves3)
Block(-1,7,0,dynamictreesbop:jacarandabranch)
Block(-1,7,1,dynamictreesbop:leaves3)
Block(-1,7,3,dynamictreesbop:leaves3:0)
Block(-1,7,4,dynamictreesbop:leaves3:0)
Block(-1,8,-2,dynamictreesbop:leaves3:0)
Block(-1,8,0,dynamictreesbop:leaves3)
Block(-1,8,1,dynamictreesbop:leaves3)
Block(-1,8,2,dynamictreesbop:leaves3:0)
Block(-1,9,-3,dynamictreesbop:leaves3:1)
Block(-1,9,-2,dynamictreesbop:leaves3:2)
Block(-1,9,-1,dynamictreesbop:leaves3)
Block(-1,9,0,dynamictreesbop:leaves3:2)
Block(-1,9,1,dynamictreesbop:leaves3:2)
Block(-1,9,2,dynamictreesbop:leaves3:0)
Block(-1,10,-3,dynamictreesbop:leaves3:0)
Block(-1,10,-2,dynamictreesbop:leaves3:1)
Block(-1,10,-1,dynamictreesbop:leaves3:2)
Block(-1,10,0,dynamictreesbop:leaves3:1)
Block(-1,10,1,dynamictreesbop:leaves3:0)
Block(-1,10,2,dynamictreesbop:leaves3:0)
Block(-1,11,-2,dynamictreesbop:leaves3:0)
Block(-1,11,-1,dynamictreesbop:leaves3:1)
Block(-1,11,0,dynamictreesbop:leaves3:0)
Block(-1,11,1,dynamictreesbop:leaves3:0)
Block(-1,11,2,dynamictreesbop:leaves3:0)
Block(-1,12,-1,dynamictreesbop:leaves3:0)
Block(-1,12,0,dynamictreesbop:leaves3:0)
Block(-1,12,1,dynamictreesbop:leaves3:0)
Block(0,5,3,dynamictreesbop:leaves3:0)
Block(0,5,4,dynamictreesbop:leaves3:0)
Block(0,6,3,dynamictreesbop:leaves3)
Block(0,6,4,dynamictreesbop:leaves3:2)
Block(0,6,5,dynamictreesbop:leaves3:0)
Block(0,7,0,dynamictreesbop:jacarandabranch:1)
Block(0,7,3,dynamictreesbop:leaves3:2)
Block(0,7,4,dynamictreesbop:leaves3:1)
Block(0,7,5,dynamictreesbop:leaves3:0)
Block(0,8,-3,dynamictreesbop:leaves3:0)
Block(0,8,1,dynamictreesbop:jacarandabranch)
Block(0,8,3,dynamictreesbop:leaves3:0)
Block(0,8,4,dynamictreesbop:leaves3:0)
Block(0,9,-4,dynamictreesbop:leaves3:0)
Block(0,9,-3,dynamictreesbop:leaves3:2)
Block(0,9,-2,dynamictreesbop:leaves3)
Block(0,9,-1,dynamictreesbop:jacarandabranch)
Block(0,9,1,dynamictreesbop:leaves3)
Block(0,9,2,dynamictreesbop:leaves3:0)
Block(0,10,-4,dynamictreesbop:leaves3:0)
Block(0,10,-3,dynamictreesbop:leaves3:1)
Block(0,10,-2,dynamictreesbop:leaves3:2)
Block(0,10,-1,dynamictreesbop:leaves3)
Block(0,10,0,dynamictreesbop:leaves3:2)
Block(0,10,1,dynamictreesbop:leaves3)
Block(0,10,2,dynamictreesbop:leaves3:2)
Block(0,10,3,dynamictreesbop:leaves3:0)
Block(0,11,-3,dynamictreesbop:leaves3:0)
Block(0,11,-2,dynamictreesbop:leaves3:1)
Block(0,11,-1,dynamictreesbop:leaves3:2)
Block(0,11,0,dynamictreesbop:leaves3)
Block(0,11,1,dynamictreesbop:leaves3:2)
Block(0,11,2,dynamictreesbop:leaves3:1)
Block(0,11,3,dynamictreesbop:leaves3:0)
Block(0,12,-2,dynamictreesbop:leaves3:0)
Block(0,12,-1,dynamictreesbop:leaves3:1)
Block(0,12,0,dynamictreesbop:leaves3:2)
Block(0,12,1,dynamictreesbop:leaves3:1)
Block(0,12,2,dynamictreesbop:leaves3:0)
Block(0,13,-1,dynamictreesbop:leaves3:0)
Block(0,13,0,dynamictreesbop:leaves3:0)
Block(0,13,1,dynamictreesbop:leaves3:0)
Block(1,0,0,dynamictrees:rootydirt:6)
Block(1,1,0,dynamictreesbop:jacarandabranch:7)
Block(1,2,0,dynamictreesbop:jacarandabranch:7)
Block(1,3,0,dynamictreesbop:jacarandabranch:7)
Block(1,4,0,dynamictreesbop:jacarandabranch:7)
Block(1,5,-2,dynamictreesbop:jacarandabranch:2)
Block(1,5,-1,dynamictreesbop:jacarandabranch:2)
Block(1,5,0,dynamictreesbop:jacarandabranch:6)
Block(1,5,1,dynamictreesbop:jacarandabranch:2)
Block(1,5,2,dynamictreesbop:jacarandabranch:2)
Block(1,5,3,dynamictreesbop:jacarandabranch:1)
Block(1,5,4,dynamictreesbop:leaves3:0)
Block(1,6,-2,dynamictreesbop:jacarandabranch:1)
Block(1,6,0,dynamictreesbop:jacarandabranch:5)
Block(1,6,3,dynamictreesbop:jacarandabranch)
Block(1,6,4,dynamictreesbop:leaves3)
Block(1,6,5,dynamictreesbop:leaves3:0)
Block(1,7,-1,dynamictreesbop:jacarandabranch)
Block(1,7,0,dynamictreesbop:jacarandabranch:4)
Block(1,7,3,dynamictreesbop:leaves3)
Block(1,7,4,dynamictreesbop:leaves3:2)
Block(1,7,5,dynamictreesbop:leaves3:0)
Block(1,8,-1,dynamictreesbop:leaves3)
Block(1,8,0,dynamictreesbop:jacarandabranch:3)
Block(1,8,1,dynamictreesbop:jacarandabranch:1)
Block(1,8,3,dynamictreesbop:leaves3:0)
Block(1,8,4,dynamictreesbop:leaves3:0)
Block(1,9,-4,dynamictreesbop:leaves3:0)
Block(1,9,-3,dynamictreesbop:leaves3)
Block(1,9,-2,dynamictreesbop:jacarandabranch)
Block(1,9,-1,dynamictreesbop:jacarandabranch:1)
Block(1,9,0,dynamictreesbop:jacarandabranch:2)
Block(1,10,-4,dynamictreesbop:leaves3:0)
Block(1,10,-3,dynamictreesbop:leaves3:2)
Block(1,10,-2,dynamictreesbop:leaves3)
Block(1,10,-1,dynamictreesbop:leaves3:2)
Block(1,10,0,dynamictreesbop:jacarandabranch:1)
Block(1,10,1,dynamictreesbop:jacarandabranch)
Block(1,10,2,dynamictreesbop:leaves3)
Block(1,10,3,dynamictreesbop:leaves3:0)
Block(1,11,-4,dynamictreesbop:leaves3:0)
Block(1,11,-3,dynamictreesbop:leaves3:1)
Block(1,11,-2,dynamictreesbop:leaves3:2)
Block(1,11,-1,dynamictreesbop:leaves3)
Block(1,11,0,dynamictreesbop:jacarandabranch)
Block(1,11,1,dynamictreesbop:leaves3)
Block(1,11,2,dynamictreesbop:leaves3:2)
Block(1,11,3,dynamictreesbop:leaves3:0)
Block(1,12,-3,dynamictreesbop:leaves3:0)
Block(1,12,-2,dynamictreesbop:leaves3:1)
Block(1,12,-1,dynamictreesbop:leaves3:2)
Block(1,12,0,dynamictreesbop:leaves3)
Block(1,12,1,dynamictreesbop:leaves3:2)
Block(1,12,2,dynamictreesbop:leaves3:1)
Block(1,12,3,dynamictreesbop:leaves3:0)
Block(1,13,-2,dynamictreesbop:leaves3:0)
Block(1,13,-1,dynamictreesbop:leaves3:0)
Block(1,13,0,dynamictreesbop:leaves3:0)
Block(1,13,1,dynamictreesbop:leaves3:0)
Block(1,13,2,dynamictreesbop:leaves3:0)
Block(2,5,2,dynamictreesbop:jacarandabranch:1)
Block(2,5,3,dynamictreesbop:leaves3:0)
Block(2,5,4,dynamictreesbop:leaves3:0)
Block(2,6,-2,dynamictreesbop:jacarandabranch:1)
Block(2,6,0,dynamictreesbop:jacarandabranch:1)
Block(2,6,1,dynamictreesbop:jacarandabranch:1)
Block(2,6,3,dynamictreesbop:leaves3)
Block(2,6,4,dynamictreesbop:leaves3:2)
Block(2,6,5,dynamictreesbop:leaves3:0)
Block(2,7,-2,dynamictreesbop:jacarandabranch:1)
Block(2,7,1,dynamictreesbop:jacarandabranch)
Block(2,7,3,dynamictreesbop:leaves3:2)
Block(2,7,4,dynamictreesbop:leaves3:1)
Block(2,7,5,dynamictreesbop:leaves3:0)
Block(2,8,-4,dynamictreesbop:leaves3:0)
Block(2,8,-3,dynamictreesbop:leaves3)
Block(2,8,-2,dynamictreesbop:jacarandabranch)
Block(2,8,1,dynamictreesbop:leaves3)
Block(2,8,3,dynamictreesbop:leaves3:0)
Block(2,8,4,dynamictreesbop:leaves3:0)
Block(2,9,-4,dynamictreesbop:leaves3:0)
Block(2,9,-3,dynamictreesbop:leaves3:2)
Block(2,9,-2,dynamictreesbop:leaves3)
Block(2,9,-1,dynamictreesbop:leaves3)
Block(2,9,0,dynamictreesbop:jacarandabranch)
Block(2,9,1,dynamictreesbop:leaves3)
Block(2,9,2,dynamictreesbop:leaves3:0)
Block(2,10,-4,dynamictreesbop:leaves3:0)
Block(2,10,-3,dynamictreesbop:leaves3:1)
Block(2,10,-2,dynamictreesbop:leaves3:2)
Block(2,10,-1,dynamictreesbop:leaves3:2)
Block(2,10,0,dynamictreesbop:leaves3)
Block(2,10,1,dynamictreesbop:leaves3)
Block(2,10,2,dynamictreesbop:leaves3:2)
Block(2,10,3,dynamictreesbop:leaves3:0)
Block(2,11,-3,dynamictreesbop:leaves3:0)
Block(2,11,-2,dynamictreesbop:leaves3:1)
Block(2,11,-1,dynamictreesbop:leaves3:2)
Block(2,11,0,dynamictreesbop:leaves3)
Block(2,11,1,dynamictreesbop:leaves3:2)
Block(2,11,2,dynamictreesbop:leaves3:1)
Block(2,11,3,dynamictreesbop:leaves3:0)
Block(2,12,-2,dynamictreesbop:leaves3:0)
Block(2,12,-1,dynamictreesbop:leaves3:1)
Block(2,12,0,dynamictreesbop:leaves3:2)
Block(2,12,1,dynamictreesbop:leaves3:1)
Block(2,12,2,dynamictreesbop:leaves3:0)
Block(2,13,-1,dynamictreesbop:leaves3:0)
Block(2,13,0,dynamictreesbop:leaves3:0)
Block(2,13,1,dynamictreesbop:leaves3:0)
Block(3,5,2,dynamictreesbop:jacarandabranch:1)
Block(3,5,3,dynamictreesbop:leaves3:2)
Block(3,5,4,dynamictreesbop:leaves3:0)
Block(3,6,2,dynamictreesbop:jacarandabranch)
Block(3,6,3,dynamictreesbop:leaves3)
Block(3,6,4,dynamictreesbop:leaves3:0)
Block(3,7,-3,dynamictreesbop:leaves3:0)
Block(3,7,2,dynamictreesbop:leaves3)
Block(3,7,3,dynamictreesbop:leaves3:2)
Block(3,7,4,dynamictreesbop:leaves3:0)
Block(3,8,-4,dynamictreesbop:leaves3:0)
Block(3,8,-3,dynamictreesbop:leaves3:2)
Block(3,8,-2,dynamictreesbop:leaves3)
Block(3,8,2,dynamictreesbop:leaves3:0)
Block(3,8,3,dynamictreesbop:leaves3:0)
Block(3,9,-4,dynamictreesbop:leaves3:0)
Block(3,9,-3,dynamictreesbop:leaves3:1)
Block(3,9,-2,dynamictreesbop:leaves3:2)
Block(3,9,-1,dynamictreesbop:leaves3:2)
Block(3,9,0,dynamictreesbop:leaves3)
Block(3,9,1,dynamictreesbop:leaves3:2)
Block(3,9,2,dynamictreesbop:leaves3:0)
Block(3,10,-3,dynamictreesbop:leaves3:0)
Block(3,10,-2,dynamictreesbop:leaves3:1)
Block(3,10,-1,dynamictreesbop:leaves3:1)
Block(3,10,0,dynamictreesbop:leaves3:2)
Block(3,10,1,dynamictreesbop:leaves3:1)
Block(3,10,2,dynamictreesbop:leaves3:0)
Block(3,11,-2,dynamictreesbop:leaves3:0)
Block(3,11,-1,dynamictreesbop:leaves3:0)
Block(3,11,0,dynamictreesbop:leaves3:0)
Block(3,11,1,dynamictreesbop:leaves3:0)
Block(3,11,2,dynamictreesbop:leaves3:0)
Block(3,12,-1,dynamictreesbop:leaves3:0)
Block(3,12,0,dynamictreesbop:leaves3:0)
Block(3,12,1,dynamictreesbop:leaves3:0)
Block(4,5,2,dynamictreesbop:jacarandabranch)
Block(4,5,3,dynamictreesbop:leaves3)
Block(4,5,4,dynamictreesbop:leaves3:0)
Block(4,6,1,dynamictreesbop:leaves3:0)
Block(4,6,2,dynamictreesbop:leaves3)
Block(4,6,3,dynamictreesbop:leaves3:2)
Block(4,6,4,dynamictreesbop:leaves3:0)
Block(4,7,1,dynamictreesbop:leaves3:0)
Block(4,7,2,dynamictreesbop:leaves3:2)
Block(4,7,3,dynamictreesbop:leaves3:1)
Block(4,7,4,dynamictreesbop:leaves3:0)
Block(4,8,-3,dynamictreesbop:leaves3:0)
Block(4,8,-2,dynamictreesbop:leaves3:0)
Block(4,8,2,dynamictreesbop:leaves3:0)
Block(4,8,3,dynamictreesbop:leaves3:0)
Block(4,9,-3,dynamictreesbop:leaves3:0)
Block(4,9,-2,dynamictreesbop:leaves3:0)
Block(4,9,-1,dynamictreesbop:leaves3:0)
Block(4,9,0,dynamictreesbop:leaves3:0)
Block(4,9,1,dynamictreesbop:leaves3:0)
Block(4,10,-2,dynamictreesbop:leaves3:0)
Block(4,10,-1,dynamictreesbop:leaves3:0)
Block(4,10,0,dynamictreesbop:leaves3:0)
Block(4,10,1,dynamictreesbop:leaves3:0)
Block(5,4,1,dynamictreesbop:leaves3:2)
Block(5,4,3,dynamictreesbop:leaves3:0)
Block(5,5,1,dynamictreesbop:leaves3)
Block(5,5,2,dynamictreesbop:leaves3)
Block(5,5,3,dynamictreesbop:leaves3:2)
Block(5,5,4,dynamictreesbop:leaves3:0)
Block(5,6,0,dynamictreesbop:leaves3)
Block(5,6,1,dynamictreesbop:leaves3:2)
Block(5,6,2,dynamictreesbop:leaves3:2)
Block(5,6,3,dynamictreesbop:leaves3:1)
Block(5,6,4,dynamictreesbop:leaves3:0)
Block(5,7,1,dynamictreesbop:leaves3:0)
Block(5,7,2,dynamictreesbop:leaves3:1)
Block(5,7,3,dynamictreesbop:leaves3:0)
Block(6,5,1,dynamictreesbop:leaves3:2)
Block(6,5,2,dynamictreesbop:leaves3:0)
Block(6,5,3,dynamictreesbop:leaves3:0)
Block(6,6,1,dynamictreesbop:leaves3:1)
Block(6,6,2,dynamictreesbop:leaves3:0)
Block(6,6,3,dynamictreesbop:leaves3:0)

#######################################################################
# +-----------------------------------------------------------------+ #
# |                            BO3 checks                           | #
# +-----------------------------------------------------------------+ #
#######################################################################

BlockCheck(1,-1,-1,GRASS,DIRT,MYCEL,biomesoplenty:grass,biomesoplenty:dirt)

#######################################################################
# +-----------------------------------------------------------------+ #
# |                             Branches                            | #
# +-----------------------------------------------------------------+ #
#######################################################################


#######################################################################
# +-----------------------------------------------------------------+ #
# |                             Entities                            | #
# +-----------------------------------------------------------------+ #
#######################################################################


#######################################################################
# +-----------------------------------------------------------------+ #
# |                            Particles                            | #
# +-----------------------------------------------------------------+ #
#######################################################################


#######################################################################
# +-----------------------------------------------------------------+ #
# |                             Spawners                            | #
# +-----------------------------------------------------------------+ #
#######################################################################


#######################################################################
# +-----------------------------------------------------------------+ #
# |                             ModData                             | #
# +-----------------------------------------------------------------+ #
#######################################################################

