
#######################################################################
# +-----------------------------------------------------------------+ #
# |                            BO3 object                           | #
# +-----------------------------------------------------------------+ #
#######################################################################

Author: NLBlackHeavenNL

Description: No description given

Version: 3

SettingsMode: WriteWithoutComments


#######################################################################
# +-----------------------------------------------------------------+ #
# |                          Main settings                          | #
# +-----------------------------------------------------------------+ #
#######################################################################

Tree: true

Frequency: 1

Rarity: 100.0

RotateRandomly: false

SpawnHeight: highestSolidBlock

SpawnHeightOffset: -2

SpawnHeightVariance: 0

##############################
# Height Limits for the BO3. #
##############################

MinHeight: 0

MaxHeight: 255

######################
# Extrusion settings #
######################

ExtrudeMode: None

ExtrudeThroughBlocks: AIR

MaxBranchDepth: 10

ExcludedBiomes: All


#######################################################################
# +-----------------------------------------------------------------+ #
# |                      Source block settings                      | #
# +-----------------------------------------------------------------+ #
#######################################################################

SourceBlocks: AIR,GRASS,DIRT,biomesoplenty:dirt,biomesoplenty:grass,STATIONARY_WATER,biomesoplenty:mud

MaxPercentageOutsideSourceBlock: 0

OutsideSourceBlock: placeAnyway

DoReplaceBlocks: true

IsOTGPlus: false


#######################################################################
# +-----------------------------------------------------------------+ #
# |                              Blocks                             | #
# +-----------------------------------------------------------------+ #
#######################################################################

Block(-3,5,0,dynamictreesbop:leaves3:4)
Block(-3,5,1,dynamictreesbop:leaves3:4)
Block(-3,6,0,dynamictreesbop:leaves3:4)
Block(-3,6,1,dynamictreesbop:leaves3:4)
Block(-2,4,0,dynamictreesbop:leaves3:4)
Block(-2,4,1,dynamictreesbop:leaves3:4)
Block(-2,5,-2,dynamictreesbop:leaves3:4)
Block(-2,5,-1,dynamictreesbop:leaves3:4)
Block(-2,5,0,dynamictreesbop:leaves3:7)
Block(-2,5,1,dynamictreesbop:leaves3:6)
Block(-2,5,2,dynamictreesbop:leaves3:4)
Block(-2,6,-3,dynamictreesbop:leaves3:4)
Block(-2,6,-2,dynamictreesbop:leaves3:4)
Block(-2,6,-1,dynamictreesbop:leaves3:4)
Block(-2,6,0,dynamictreesbop:leaves3:6)
Block(-2,6,1,dynamictreesbop:leaves3:5)
Block(-2,6,2,dynamictreesbop:leaves3:4)
Block(-2,7,-2,dynamictreesbop:leaves3:4)
Block(-2,7,-1,dynamictreesbop:leaves3:4)
Block(-2,7,0,dynamictreesbop:leaves3:4)
Block(-2,7,1,dynamictreesbop:leaves3:4)
Block(-1,4,-5,dynamictreesbop:leaves3:4)
Block(-1,4,-4,dynamictreesbop:leaves3:4)
Block(-1,4,1,dynamictreesbop:leaves3:4)
Block(-1,5,-5,dynamictreesbop:leaves3:4)
Block(-1,5,-4,dynamictreesbop:leaves3:4)
Block(-1,5,-3,dynamictreesbop:leaves3:4)
Block(-1,5,-2,dynamictreesbop:leaves3:5)
Block(-1,5,-1,dynamictreesbop:mangrovebranch:1)
Block(-1,5,0,dynamictreesbop:mangrovebranch)
Block(-1,5,1,dynamictreesbop:leaves3:7)
Block(-1,5,2,dynamictreesbop:leaves3:4)
Block(-1,6,-4,dynamictreesbop:leaves3:4)
Block(-1,6,-3,dynamictreesbop:leaves3:5)
Block(-1,6,-2,dynamictreesbop:leaves3:6)
Block(-1,6,-1,dynamictreesbop:leaves3:7)
Block(-1,6,0,dynamictreesbop:leaves3:7)
Block(-1,6,1,dynamictreesbop:leaves3:6)
Block(-1,6,2,dynamictreesbop:leaves3:4)
Block(-1,7,-3,dynamictreesbop:leaves3:4)
Block(-1,7,-2,dynamictreesbop:leaves3:5)
Block(-1,7,-1,dynamictreesbop:leaves3:6)
Block(-1,7,0,dynamictreesbop:leaves3:5)
Block(-1,7,1,dynamictreesbop:leaves3:4)
Block(-1,8,-2,dynamictreesbop:leaves3:4)
Block(-1,8,-1,dynamictreesbop:leaves3:4)
Block(-1,8,0,dynamictreesbop:leaves3:4)
Block(0,3,-5,dynamictreesbop:leaves3:4)
Block(0,4,-6,dynamictreesbop:leaves3:4)
Block(0,4,-5,dynamictreesbop:leaves3:6)
Block(0,4,-4,dynamictreesbop:leaves3:7)
Block(0,4,1,dynamictreesbop:leaves3:4)
Block(0,5,-6,dynamictreesbop:leaves3:4)
Block(0,5,-5,dynamictreesbop:leaves3:5)
Block(0,5,-4,dynamictreesbop:leaves3:6)
Block(0,5,-3,dynamictreesbop:leaves3:7)
Block(0,5,-2,dynamictreesbop:leaves3:6)
Block(0,5,-1,dynamictreesbop:mangrovebranch:1)
Block(0,5,0,dynamictreesbop:leaves3:7)
Block(0,5,1,dynamictreesbop:leaves3:6)
Block(0,5,2,dynamictreesbop:leaves3:4)
Block(0,6,-5,dynamictreesbop:leaves3:4)
Block(0,6,-4,dynamictreesbop:leaves3:5)
Block(0,6,-3,dynamictreesbop:leaves3:6)
Block(0,6,-2,dynamictreesbop:leaves3:7)
Block(0,6,-1,dynamictreesbop:mangrovebranch)
Block(0,6,0,dynamictreesbop:leaves3:7)
Block(0,6,1,dynamictreesbop:leaves3:5)
Block(0,6,2,dynamictreesbop:leaves3:4)
Block(0,7,-4,dynamictreesbop:leaves3:4)
Block(0,7,-3,dynamictreesbop:leaves3:5)
Block(0,7,-2,dynamictreesbop:leaves3:6)
Block(0,7,-1,dynamictreesbop:leaves3:7)
Block(0,7,0,dynamictreesbop:leaves3:6)
Block(0,7,1,dynamictreesbop:leaves3:4)
Block(0,8,-3,dynamictreesbop:leaves3:4)
Block(0,8,-2,dynamictreesbop:leaves3:4)
Block(0,8,-1,dynamictreesbop:leaves3:4)
Block(0,8,0,dynamictreesbop:leaves3:4)
Block(1,1,0,dynamictreesbop:rootywater:5)
Block(1,2,0,dynamictreesbop:mangrovebranch:3)
Block(1,3,-1,dynamictreesbop:mangrovebranch:2)
Block(1,3,0,dynamictreesbop:mangrovebranch:3)
Block(1,4,-6,dynamictreesbop:leaves3:4)
Block(1,4,-5,dynamictreesbop:leaves3:7)
Block(1,4,-4,dynamictreesbop:mangrovebranch)
Block(1,4,-3,dynamictreesbop:mangrovebranch:1)
Block(1,4,-2,dynamictreesbop:mangrovebranch:1)
Block(1,4,-1,dynamictreesbop:mangrovebranch:2)
Block(1,4,1,dynamictreesbop:leaves3:4)
Block(1,5,-6,dynamictreesbop:leaves3:4)
Block(1,5,-5,dynamictreesbop:leaves3:6)
Block(1,5,-4,dynamictreesbop:leaves3:7)
Block(1,5,-3,dynamictreesbop:mangrovebranch)
Block(1,5,-2,dynamictreesbop:leaves3:7)
Block(1,5,-1,dynamictreesbop:mangrovebranch:1)
Block(1,5,0,dynamictreesbop:mangrovebranch)
Block(1,5,1,dynamictreesbop:leaves3:7)
Block(1,5,2,dynamictreesbop:leaves3:4)
Block(1,6,-6,dynamictreesbop:leaves3:4)
Block(1,6,-5,dynamictreesbop:leaves3:5)
Block(1,6,-4,dynamictreesbop:leaves3:6)
Block(1,6,-3,dynamictreesbop:leaves3:7)
Block(1,6,-2,dynamictreesbop:leaves3:6)
Block(1,6,-1,dynamictreesbop:leaves3:7)
Block(1,6,0,dynamictreesbop:leaves3:7)
Block(1,6,1,dynamictreesbop:leaves3:6)
Block(1,6,2,dynamictreesbop:leaves3:4)
Block(1,7,-5,dynamictreesbop:leaves3:4)
Block(1,7,-4,dynamictreesbop:leaves3:4)
Block(1,7,-3,dynamictreesbop:leaves3:4)
Block(1,7,-2,dynamictreesbop:leaves3:5)
Block(1,7,-1,dynamictreesbop:leaves3:6)
Block(1,7,0,dynamictreesbop:leaves3:5)
Block(1,7,1,dynamictreesbop:leaves3:4)
Block(1,8,-2,dynamictreesbop:leaves3:4)
Block(1,8,-1,dynamictreesbop:leaves3:4)
Block(1,8,0,dynamictreesbop:leaves3:4)
Block(2,3,-5,dynamictreesbop:leaves3:4)
Block(2,4,-6,dynamictreesbop:leaves3:4)
Block(2,4,-5,dynamictreesbop:leaves3:6)
Block(2,4,-4,dynamictreesbop:leaves3:7)
Block(2,4,-3,dynamictreesbop:leaves3:7)
Block(2,4,-2,dynamictreesbop:mangrovebranch)
Block(2,4,1,dynamictreesbop:leaves3:6)
Block(2,5,-6,dynamictreesbop:leaves3:4)
Block(2,5,-5,dynamictreesbop:leaves3:5)
Block(2,5,-4,dynamictreesbop:leaves3:6)
Block(2,5,-3,dynamictreesbop:leaves3:7)
Block(2,5,-2,dynamictreesbop:leaves3:7)
Block(2,5,-1,dynamictreesbop:leaves3:6)
Block(2,5,0,dynamictreesbop:leaves3:7)
Block(2,5,1,dynamictreesbop:leaves3:7)
Block(2,5,2,dynamictreesbop:leaves3:4)
Block(2,6,-5,dynamictreesbop:leaves3:4)
Block(2,6,-4,dynamictreesbop:leaves3:5)
Block(2,6,-3,dynamictreesbop:leaves3:6)
Block(2,6,-2,dynamictreesbop:leaves3:5)
Block(2,6,-1,dynamictreesbop:leaves3:5)
Block(2,6,0,dynamictreesbop:leaves3:6)
Block(2,6,1,dynamictreesbop:leaves3:6)
Block(2,6,2,dynamictreesbop:leaves3:5)
Block(2,7,-4,dynamictreesbop:leaves3:4)
Block(2,7,-3,dynamictreesbop:leaves3:4)
Block(2,7,-2,dynamictreesbop:leaves3:4)
Block(2,7,-1,dynamictreesbop:leaves3:4)
Block(2,7,0,dynamictreesbop:leaves3:4)
Block(2,7,1,dynamictreesbop:leaves3:4)
Block(3,3,-3,dynamictreesbop:leaves3:4)
Block(3,4,-5,dynamictreesbop:leaves3:4)
Block(3,4,-4,dynamictreesbop:leaves3:4)
Block(3,4,-3,dynamictreesbop:leaves3:6)
Block(3,4,-2,dynamictreesbop:leaves3:7)
Block(3,5,-5,dynamictreesbop:leaves3:4)
Block(3,5,-4,dynamictreesbop:leaves3:4)
Block(3,5,-3,dynamictreesbop:leaves3:5)
Block(3,5,-2,dynamictreesbop:leaves3:6)
Block(3,5,-1,dynamictreesbop:leaves3:7)
Block(3,6,-4,dynamictreesbop:leaves3:4)
Block(3,6,-3,dynamictreesbop:leaves3:4)
Block(3,6,-2,dynamictreesbop:leaves3:4)
Block(3,6,-1,dynamictreesbop:leaves3:4)
Block(3,6,0,dynamictreesbop:leaves3:4)
Block(3,6,1,dynamictreesbop:leaves3:7)
Block(4,4,-3,dynamictreesbop:leaves3:6)
Block(4,4,-2,dynamictreesbop:leaves3:7)
Block(4,4,-1,dynamictreesbop:leaves3:7)
Block(4,5,-3,dynamictreesbop:leaves3:4)
Block(4,5,-2,dynamictreesbop:leaves3:5)
Block(4,5,-1,dynamictreesbop:leaves3:6)

#######################################################################
# +-----------------------------------------------------------------+ #
# |                            BO3 checks                           | #
# +-----------------------------------------------------------------+ #
#######################################################################

BlockCheck(1,-1,0,STATIONARY_WATER)
BlockCheck(1,1,-1,AIR)
BlockCheck(1,-1,-1,Solid,biomesoplenty:mud)

#######################################################################
# +-----------------------------------------------------------------+ #
# |                             Branches                            | #
# +-----------------------------------------------------------------+ #
#######################################################################


#######################################################################
# +-----------------------------------------------------------------+ #
# |                             Entities                            | #
# +-----------------------------------------------------------------+ #
#######################################################################


#######################################################################
# +-----------------------------------------------------------------+ #
# |                            Particles                            | #
# +-----------------------------------------------------------------+ #
#######################################################################


#######################################################################
# +-----------------------------------------------------------------+ #
# |                             Spawners                            | #
# +-----------------------------------------------------------------+ #
#######################################################################


#######################################################################
# +-----------------------------------------------------------------+ #
# |                             ModData                             | #
# +-----------------------------------------------------------------+ #
#######################################################################

