
#######################################################################
# +-----------------------------------------------------------------+ #
# |                            BO4 object                           | #
# +-----------------------------------------------------------------+ #
#######################################################################

Author: NLBlackEagle

Description: No description given

SettingsMode: WriteWithoutComments


#######################################################################
# +-----------------------------------------------------------------+ #
# |                          Main settings                          | #
# +-----------------------------------------------------------------+ #
#######################################################################

FixedRotation: 

Frequency: 0

SpawnHeight: highestBlock

UseCenterForHighestBlock: true

##############################
# Height Limits for the BO4. #
##############################

MinHeight: 0

MaxHeight: 255

InheritBO3: 

InheritBO3Rotation: NORTH

OverrideChildSettings: true

OverrideParentHeight: false

CanOverride: true

BranchFrequency: 0

BranchFrequencyGroup: 

MustBeBelowOther: false

MustBeInside: 

CannotBeInside: 

ReplacesBO3: 

MustBeInsideWorldBorders: false

CanSpawnOnWater: true

SpawnOnWaterOnly: false

SpawnUnderWater: false

SpawnAtWaterLevel: false

HeightOffset: 0

RemoveAir: false

ReplaceAbove: 

ReplaceBelow: 

ReplaceWithBiomeBlocks: true

ReplaceWithSurfaceBlock: GRASS

ReplaceWithGroundBlock: DIRT

ReplaceWithStoneBlock: STONE

SmoothRadius: 0

SmoothHeightOffset: 0

SmoothStartTop: false

SmoothStartWood: false

SmoothingSurfaceBlock: 

SmoothingGroundBlock: 

BO3Group: 

IsSpawnPoint: false

DoReplaceBlocks: true


#######################################################################
# +-----------------------------------------------------------------+ #
# |                              Blocks                             | #
# +-----------------------------------------------------------------+ #
#######################################################################

Block(-4,24,-7,STONE:0)
Block(-4,25,-7,STONE:0)
Block(-4,25,-6,STONE:0)
Block(-4,26,-7,STONE:0)
Block(-4,26,-6,STONE:0)
Block(-4,27,-7,STONE:0)
Block(-3,23,-7,STONE:0)
Block(-3,23,-6,STONE:0)
Block(-3,24,-7,STONE:0)
Block(-3,24,-6,STONE:0)
Block(-3,24,-5,STONE:0)
Block(-3,24,-4,STONE:0)
Block(-3,25,-7,STONE:0)
Block(-3,25,-6,STONE:0)
Block(-3,25,-5,STONE:0)
Block(-3,25,-4,STONE:0)
Block(-3,26,-7,STONE:0)
Block(-3,26,-6,STONE:0)
Block(-3,26,-5,STONE:0)
Block(-3,26,-4,STONE:0)
Block(-3,27,-7,STONE:0)
Block(-3,27,-6,STONE:0)
Block(-3,27,-5,STONE:0)
Block(-2,21,-7,STONE:5)
Block(-2,22,-7,STONE:5)
Block(-2,22,-6,STONE:5)
Block(-2,22,-5,STONE:5)
Block(-2,22,-4,STONE:5)
Block(-2,22,-3,STONE:5)
Block(-2,23,-7,STONE:0)
Block(-2,23,-6,STONE:0)
Block(-2,23,-5,STONE:0)
Block(-2,23,-4,STONE:0)
Block(-2,23,-3,STONE:0)
Block(-2,23,-2,STONE:0)
Block(-2,24,-7,STONE:0)
Block(-2,24,-6,STONE:0)
Block(-2,24,-5,STONE:0)
Block(-2,24,-4,STONE:0)
Block(-2,25,-7,STONE:0)
Block(-2,25,-6,STONE:0)
Block(-2,25,-5,STONE:0)
Block(-2,25,-4,STONE:0)
Block(-2,26,-7,STONE:0)
Block(-2,26,-6,STONE:0)
Block(-2,26,-5,STONE:0)
Block(-2,26,-4,STONE:0)
Block(-2,26,-3,STONE:0)
Block(-2,27,-7,STONE:0)
Block(-2,27,-6,STONE:0)
Block(-2,27,-5,STONE:0)
Block(-2,27,-4,STONE:0)
Block(-1,20,-7,STONE:5)
Block(-1,20,-6,STONE:5)
Block(-1,20,-5,STONE:5)
Block(-1,20,-4,STONE:5)
Block(-1,21,-7,STONE:5)
Block(-1,21,-6,STONE:5)
Block(-1,21,-5,STONE:5)
Block(-1,21,-4,STONE:5)
Block(-1,21,-3,STONE:5)
Block(-1,22,-7,STONE:5)
Block(-1,22,-6,STONE:5)
Block(-1,22,-5,STONE:5)
Block(-1,22,-4,STONE:5)
Block(-1,22,-3,STONE:5)
Block(-1,22,-2,STONE:5)
Block(-1,23,-7,STONE:0)
Block(-1,23,-6,STONE:0)
Block(-1,23,-5,STONE:0)
Block(-1,23,-4,STONE:0)
Block(-1,23,-3,STONE:0)
Block(-1,23,-2,STONE:0)
Block(-1,23,-1,STONE:0)
Block(-1,24,-7,STONE:0)
Block(-1,24,-6,STONE:0)
Block(-1,24,-5,STONE:0)
Block(-1,24,-4,STONE:0)
Block(-1,24,-3,STONE:0)
Block(-1,24,-2,STONE:0)
Block(-1,24,-1,STONE:0)
Block(-1,25,-7,STONE:0)
Block(-1,25,-6,STONE:0)
Block(-1,25,-5,STONE:0)
Block(-1,25,-4,STONE:0)
Block(-1,25,-3,STONE:0)
Block(-1,26,-7,STONE:0)
Block(-1,26,-6,STONE:0)
Block(-1,26,-5,STONE:0)
Block(-1,26,-4,STONE:0)
Block(-1,26,-3,STONE:0)
Block(-1,26,-2,STONE:0)
Block(-1,27,-7,STONE:0)
Block(-1,27,-6,STONE:0)
Block(-1,27,-5,STONE:0)
Block(-1,27,-4,STONE:0)
Block(-1,27,-3,STONE:0)
Block(0,19,-7,STONE:5)
Block(0,19,-6,STONE:5)
Block(0,19,-3,STONE:5)
Block(0,19,-2,STONE:5)
Block(0,20,-7,STONE:5)
Block(0,20,-6,STONE:5)
Block(0,20,-5,STONE:5)
Block(0,20,-4,STONE:5)
Block(0,20,-3,STONE:5)
Block(0,20,-2,STONE:5)
Block(0,20,-1,STONE:5)
Block(0,21,-7,STONE:5)
Block(0,21,-6,STONE:5)
Block(0,21,-5,STONE:5)
Block(0,21,-4,STONE:5)
Block(0,21,-3,STONE:5)
Block(0,21,-2,STONE:5)
Block(0,21,-1,STONE:5)
Block(0,21,0,STONE:5)
Block(0,22,-7,STONE:5)
Block(0,22,-6,STONE:5)
Block(0,22,-5,STONE:5)
Block(0,22,-4,STONE:5)
Block(0,22,-3,STONE:5)
Block(0,22,-2,STONE:5)
Block(0,22,-1,STONE:5)
Block(0,22,0,STONE:5)
Block(0,22,1,STONE:5)
Block(0,23,-7,STONE:0)
Block(0,23,-6,STONE:0)
Block(0,23,-5,STONE:0)
Block(0,23,-4,STONE:0)
Block(0,23,-3,STONE:0)
Block(0,23,-2,STONE:0)
Block(0,23,-1,STONE:0)
Block(0,23,0,STONE:0)
Block(0,24,-7,STONE:0)
Block(0,24,-6,STONE:0)
Block(0,24,-5,STONE:0)
Block(0,24,-4,STONE:0)
Block(0,24,-3,STONE:0)
Block(0,24,-2,STONE:0)
Block(0,24,-1,STONE:0)
Block(0,24,0,STONE:0)
Block(0,25,-7,STONE:0)
Block(0,25,-6,STONE:0)
Block(0,25,-5,STONE:0)
Block(0,25,-4,STONE:0)
Block(0,25,-3,STONE:0)
Block(0,25,-2,STONE:0)
Block(0,26,-7,STONE:0)
Block(0,26,-6,STONE:0)
Block(0,26,-5,STONE:0)
Block(0,26,-4,STONE:0)
Block(0,26,-3,STONE:0)
Block(0,26,-2,STONE:0)
Block(0,26,-1,STONE:0)
Block(0,27,-6,STONE:0)
Block(0,27,-5,STONE:0)
Block(0,27,-4,STONE:0)
Block(0,27,-3,STONE:0)
Block(0,27,-2,STONE:0)
Block(1,18,-7,STONE:5)
Block(1,18,-6,STONE:5)
Block(1,18,-5,STONE:5)
Block(1,18,-3,STONE:5)
Block(1,18,-2,STONE:5)
Block(1,18,-1,STONE:5)
Block(1,19,-7,STONE:5)
Block(1,19,-6,STONE:5)
Block(1,19,-5,STONE:5)
Block(1,19,-4,STONE:5)
Block(1,19,-3,STONE:5)
Block(1,19,-2,STONE:5)
Block(1,19,-1,STONE:5)
Block(1,19,0,STONE:5)
Block(1,19,1,STONE:5)
Block(1,20,-7,STONE:5)
Block(1,20,-6,STONE:5)
Block(1,20,-5,STONE:5)
Block(1,20,-4,STONE:5)
Block(1,20,-3,STONE:5)
Block(1,20,-2,STONE:5)
Block(1,20,-1,STONE:5)
Block(1,20,0,STONE:5)
Block(1,20,1,STONE:5)
Block(1,20,2,STONE:5)
Block(1,21,-7,STONE:5)
Block(1,21,-6,STONE:5)
Block(1,21,-5,STONE:5)
Block(1,21,-4,STONE:5)
Block(1,21,-3,STONE:5)
Block(1,21,-2,STONE:5)
Block(1,21,-1,STONE:5)
Block(1,21,0,STONE:5)
Block(1,21,1,STONE:5)
Block(1,21,2,STONE:5)
Block(1,21,3,STONE:5)
Block(1,22,-7,STONE:5)
Block(1,22,-6,STONE:5)
Block(1,22,-5,STONE:5)
Block(1,22,-4,STONE:5)
Block(1,22,-3,STONE:5)
Block(1,22,-2,STONE:5)
Block(1,22,-1,STONE:5)
Block(1,22,0,STONE:5)
Block(1,22,1,STONE:5)
Block(1,22,2,STONE:5)
Block(1,23,-7,STONE:0)
Block(1,23,-6,STONE:0)
Block(1,23,-5,STONE:0)
Block(1,23,-4,STONE:0)
Block(1,23,-3,STONE:0)
Block(1,23,-2,STONE:0)
Block(1,23,-1,STONE:0)
Block(1,23,0,STONE:0)
Block(1,23,1,STONE:0)
Block(1,23,2,STONE:0)
Block(1,24,-7,STONE:0)
Block(1,24,-6,STONE:0)
Block(1,24,-5,STONE:0)
Block(1,24,-4,STONE:0)
Block(1,24,-3,STONE:0)
Block(1,24,-2,STONE:0)
Block(1,24,-1,STONE:0)
Block(1,24,0,STONE:0)
Block(1,24,1,STONE:0)
Block(1,25,-7,STONE:0)
Block(1,25,-6,STONE:0)
Block(1,25,-5,STONE:0)
Block(1,25,-4,STONE:0)
Block(1,25,-3,STONE:0)
Block(1,25,-2,STONE:0)
Block(1,25,-1,STONE:0)
Block(1,26,-7,STONE:0)
Block(1,26,-6,STONE:0)
Block(1,26,-5,STONE:0)
Block(1,26,-4,STONE:0)
Block(1,26,-3,STONE:0)
Block(1,26,-2,STONE:0)
Block(1,26,-1,STONE:0)
Block(1,26,0,STONE:0)
Block(1,27,-3,STONE:0)
Block(1,27,-2,STONE:0)
Block(1,27,-1,STONE:0)
Block(2,18,-7,STONE:5)
Block(2,18,-6,STONE:5)
Block(2,18,-5,STONE:5)
Block(2,18,-4,STONE:5)
Block(2,18,-3,STONE:5)
Block(2,18,-2,STONE:5)
Block(2,18,-1,STONE:5)
Block(2,18,0,STONE:5)
Block(2,19,-7,STONE:5)
Block(2,19,-6,STONE:5)
Block(2,19,-5,STONE:5)
Block(2,19,-4,STONE:5)
Block(2,19,-3,STONE:5)
Block(2,19,-2,STONE:5)
Block(2,19,-1,STONE:5)
Block(2,19,0,STONE:5)
Block(2,19,1,STONE:5)
Block(2,19,2,STONE:5)
Block(2,20,-7,STONE:5)
Block(2,20,-6,STONE:5)
Block(2,20,-5,STONE:5)
Block(2,20,-4,STONE:5)
Block(2,20,-3,STONE:5)
Block(2,20,-2,STONE:5)
Block(2,20,-1,STONE:5)
Block(2,20,0,STONE:5)
Block(2,20,1,STONE:5)
Block(2,20,2,STONE:5)
Block(2,20,3,STONE:5)
Block(2,20,4,STONE:5)
Block(2,21,-7,STONE:5)
Block(2,21,-6,STONE:5)
Block(2,21,-5,STONE:5)
Block(2,21,-4,STONE:5)
Block(2,21,-3,STONE:5)
Block(2,21,-2,STONE:5)
Block(2,21,-1,STONE:5)
Block(2,21,0,STONE:5)
Block(2,21,1,STONE:5)
Block(2,21,2,STONE:5)
Block(2,21,3,STONE:5)
Block(2,21,4,STONE:5)
Block(2,22,-7,STONE:5)
Block(2,22,-6,STONE:5)
Block(2,22,-5,STONE:5)
Block(2,22,-4,STONE:5)
Block(2,22,-3,STONE:5)
Block(2,22,-2,STONE:5)
Block(2,22,-1,STONE:5)
Block(2,22,0,STONE:5)
Block(2,22,1,STONE:5)
Block(2,22,2,STONE:5)
Block(2,22,3,STONE:5)
Block(2,22,4,STONE:5)
Block(2,22,5,STONE:5)
Block(2,23,-7,STONE:0)
Block(2,23,-6,STONE:0)
Block(2,23,-5,STONE:0)
Block(2,23,-4,STONE:0)
Block(2,23,-3,STONE:0)
Block(2,23,-2,STONE:0)
Block(2,23,-1,STONE:0)
Block(2,23,0,STONE:0)
Block(2,23,1,STONE:0)
Block(2,23,2,STONE:0)
Block(2,23,3,STONE:0)
Block(2,23,4,STONE:0)
Block(2,24,-7,STONE:0)
Block(2,24,-6,STONE:0)
Block(2,24,-5,STONE:0)
Block(2,24,-4,STONE:0)
Block(2,24,-3,STONE:0)
Block(2,24,-2,STONE:0)
Block(2,24,-1,STONE:0)
Block(2,24,0,STONE:0)
Block(2,24,1,STONE:0)
Block(2,25,-7,STONE:0)
Block(2,25,-6,STONE:0)
Block(2,25,-5,STONE:0)
Block(2,25,-4,STONE:0)
Block(2,25,-3,STONE:0)
Block(2,25,-2,STONE:0)
Block(2,25,-1,STONE:0)
Block(2,25,0,STONE:0)
Block(2,25,1,STONE:0)
Block(2,25,2,STONE:0)
Block(2,26,-6,STONE:0)
Block(2,26,-5,STONE:0)
Block(2,26,-4,STONE:0)
Block(2,26,-3,STONE:0)
Block(2,26,-2,STONE:0)
Block(2,26,-1,STONE:0)
Block(2,26,0,STONE:0)
Block(2,26,1,STONE:0)
Block(2,27,-3,STONE:0)
Block(2,27,-2,STONE:0)
Block(2,27,-1,STONE:0)
Block(2,27,0,STONE:0)
Block(2,27,1,STONE:0)
Block(3,18,-7,STONE:5)
Block(3,18,-6,STONE:5)
Block(3,18,-5,STONE:5)
Block(3,18,-4,STONE:5)
Block(3,18,-3,STONE:5)
Block(3,18,-2,STONE:5)
Block(3,18,-1,STONE:5)
Block(3,18,0,STONE:5)
Block(3,18,1,STONE:5)
Block(3,18,2,STONE:5)
Block(3,18,3,STONE:5)
Block(3,19,-7,STONE:5)
Block(3,19,-6,STONE:5)
Block(3,19,-5,STONE:5)
Block(3,19,-4,STONE:5)
Block(3,19,-3,STONE:5)
Block(3,19,-2,STONE:5)
Block(3,19,-1,STONE:5)
Block(3,19,0,STONE:5)
Block(3,19,1,STONE:5)
Block(3,19,2,STONE:5)
Block(3,19,3,STONE:5)
Block(3,19,4,STONE:5)
Block(3,20,-7,STONE:5)
Block(3,20,-6,STONE:5)
Block(3,20,-5,STONE:5)
Block(3,20,-4,STONE:5)
Block(3,20,-3,STONE:5)
Block(3,20,-2,STONE:5)
Block(3,20,-1,STONE:5)
Block(3,20,0,STONE:5)
Block(3,20,1,STONE:5)
Block(3,20,2,STONE:5)
Block(3,20,3,STONE:5)
Block(3,20,4,STONE:5)
Block(3,20,5,STONE:5)
Block(3,21,-7,STONE:5)
Block(3,21,-6,STONE:5)
Block(3,21,-5,STONE:5)
Block(3,21,-4,STONE:5)
Block(3,21,-3,STONE:5)
Block(3,21,-2,STONE:5)
Block(3,21,-1,STONE:5)
Block(3,21,0,STONE:5)
Block(3,21,1,STONE:5)
Block(3,21,2,STONE:5)
Block(3,21,3,STONE:5)
Block(3,21,4,STONE:5)
Block(3,21,5,STONE:5)
Block(3,22,-7,STONE:5)
Block(3,22,-6,STONE:5)
Block(3,22,-5,STONE:5)
Block(3,22,-4,STONE:5)
Block(3,22,-3,STONE:5)
Block(3,22,-2,STONE:5)
Block(3,22,-1,STONE:5)
Block(3,22,0,STONE:5)
Block(3,22,1,STONE:5)
Block(3,22,2,STONE:5)
Block(3,22,3,STONE:5)
Block(3,22,4,STONE:5)
Block(3,22,5,STONE:5)
Block(3,23,-7,STONE:0)
Block(3,23,-6,STONE:0)
Block(3,23,-5,STONE:0)
Block(3,23,-4,STONE:0)
Block(3,23,-3,STONE:0)
Block(3,23,-2,STONE:0)
Block(3,23,-1,STONE:0)
Block(3,23,0,STONE:0)
Block(3,23,1,STONE:0)
Block(3,23,2,STONE:0)
Block(3,23,3,STONE:0)
Block(3,23,4,STONE:0)
Block(3,24,-7,STONE:0)
Block(3,24,-6,STONE:0)
Block(3,24,-5,STONE:0)
Block(3,24,-4,STONE:0)
Block(3,24,-3,STONE:0)
Block(3,24,-2,STONE:0)
Block(3,24,-1,STONE:0)
Block(3,24,0,STONE:0)
Block(3,24,1,STONE:0)
Block(3,24,2,STONE:0)
Block(3,24,3,STONE:0)
Block(3,25,-7,STONE:0)
Block(3,25,-6,STONE:0)
Block(3,25,-5,STONE:0)
Block(3,25,-4,STONE:0)
Block(3,25,-3,STONE:0)
Block(3,25,-2,STONE:0)
Block(3,25,-1,STONE:0)
Block(3,25,0,STONE:0)
Block(3,25,1,STONE:0)
Block(3,25,2,STONE:0)
Block(3,26,-5,STONE:0)
Block(3,26,-3,STONE:0)
Block(3,26,-2,STONE:0)
Block(3,26,-1,STONE:0)
Block(3,26,0,STONE:0)
Block(3,26,1,STONE:0)
Block(3,26,2,STONE:0)
Block(3,27,-2,STONE:0)
Block(3,27,-1,STONE:0)
Block(3,27,0,STONE:0)
Block(3,27,1,STONE:0)
RandomBlock(4,17,-2,STONE:5,50,STONE:0,100)
RandomBlock(4,17,-1,STONE:5,50,STONE:0,100)
RandomBlock(4,17,0,STONE:5,50,STONE:0,100)
RandomBlock(4,17,1,STONE:5,50,STONE:0,100)
Block(4,18,-7,STONE:5)
Block(4,18,-6,STONE:5)
Block(4,18,-5,STONE:5)
Block(4,18,-4,STONE:5)
Block(4,18,-3,STONE:5)
Block(4,18,-2,STONE:5)
Block(4,18,-1,STONE:5)
Block(4,18,0,STONE:5)
Block(4,18,1,STONE:5)
Block(4,18,2,STONE:5)
Block(4,18,3,STONE:5)
Block(4,18,4,STONE:5)
Block(4,19,-7,STONE:5)
Block(4,19,-6,STONE:5)
Block(4,19,-5,STONE:5)
Block(4,19,-4,STONE:5)
Block(4,19,-3,STONE:5)
Block(4,19,-2,STONE:5)
Block(4,19,-1,STONE:5)
Block(4,19,0,STONE:5)
Block(4,19,1,STONE:5)
Block(4,19,2,STONE:5)
Block(4,19,3,STONE:5)
Block(4,19,4,STONE:5)
Block(4,19,5,STONE:5)
Block(4,20,-7,STONE:5)
Block(4,20,-6,STONE:5)
Block(4,20,-5,STONE:5)
Block(4,20,-4,STONE:5)
Block(4,20,-3,STONE:5)
Block(4,20,-2,STONE:5)
Block(4,20,-1,STONE:5)
Block(4,20,0,STONE:5)
Block(4,20,1,STONE:5)
Block(4,20,2,STONE:5)
Block(4,20,3,STONE:5)
Block(4,20,4,STONE:5)
Block(4,20,5,STONE:5)
Block(4,20,6,STONE:5)
Block(4,21,-7,STONE:5)
Block(4,21,-6,STONE:5)
Block(4,21,-5,STONE:5)
Block(4,21,-4,STONE:5)
Block(4,21,-3,STONE:5)
Block(4,21,-2,STONE:5)
Block(4,21,-1,STONE:5)
Block(4,21,0,STONE:5)
Block(4,21,1,STONE:5)
Block(4,21,2,STONE:5)
Block(4,21,3,STONE:5)
Block(4,21,4,STONE:5)
Block(4,21,5,STONE:5)
Block(4,22,-7,STONE:5)
Block(4,22,-6,STONE:5)
Block(4,22,-5,STONE:5)
Block(4,22,-4,STONE:5)
Block(4,22,-3,STONE:5)
Block(4,22,-2,STONE:5)
Block(4,22,-1,STONE:5)
Block(4,22,0,STONE:5)
Block(4,22,1,STONE:5)
Block(4,22,2,STONE:5)
Block(4,22,3,STONE:5)
Block(4,22,4,STONE:5)
Block(4,22,5,STONE:5)
Block(4,23,-7,STONE:0)
Block(4,23,-6,STONE:0)
Block(4,23,-5,STONE:0)
Block(4,23,-4,STONE:0)
Block(4,23,-3,STONE:0)
Block(4,23,-2,STONE:0)
Block(4,23,-1,STONE:0)
Block(4,23,0,STONE:0)
Block(4,23,1,STONE:0)
Block(4,23,2,STONE:0)
Block(4,23,3,STONE:0)
Block(4,23,4,STONE:0)
Block(4,24,-7,STONE:0)
Block(4,24,-6,STONE:0)
Block(4,24,-5,STONE:0)
Block(4,24,-4,STONE:0)
Block(4,24,-3,STONE:0)
Block(4,24,-2,STONE:0)
Block(4,24,-1,STONE:0)
Block(4,24,0,STONE:0)
Block(4,24,1,STONE:0)
Block(4,24,2,STONE:0)
Block(4,24,3,STONE:0)
Block(4,24,4,STONE:0)
Block(4,25,-7,STONE:0)
Block(4,25,-5,STONE:0)
Block(4,25,-4,STONE:0)
Block(4,25,-3,STONE:0)
Block(4,25,-2,STONE:0)
Block(4,25,-1,STONE:0)
Block(4,25,0,STONE:0)
Block(4,25,1,STONE:0)
Block(4,25,2,STONE:0)
Block(4,25,3,STONE:0)
Block(4,26,-3,STONE:0)
Block(4,26,-2,STONE:0)
Block(4,26,-1,STONE:0)
Block(4,26,0,STONE:0)
Block(4,26,1,STONE:0)
Block(4,26,2,STONE:0)
Block(4,27,-2,STONE:0)
Block(4,27,-1,STONE:0)
Block(4,27,0,STONE:0)
Block(4,27,1,STONE:0)
Block(4,27,2,STONE:0)
Block(4,28,-1,STONE:0)
Block(4,28,0,STONE:0)
Block(4,28,1,STONE:0)
RandomBlock(5,17,-6,STONE:5,50,STONE:0,100)
RandomBlock(5,17,-5,STONE:5,50,STONE:0,100)
RandomBlock(5,17,-2,STONE:5,50,STONE:0,100)
RandomBlock(5,17,-1,STONE:5,50,STONE:0,100)
RandomBlock(5,17,0,STONE:5,50,STONE:0,100)
RandomBlock(5,17,1,STONE:5,50,STONE:0,100)
RandomBlock(5,17,2,STONE:5,50,STONE:0,100)
Block(5,18,-7,STONE:5)
Block(5,18,-6,STONE:5)
Block(5,18,-5,STONE:5)
Block(5,18,-4,STONE:5)
Block(5,18,-3,STONE:5)
Block(5,18,-2,STONE:5)
Block(5,18,-1,STONE:5)
Block(5,18,0,STONE:5)
Block(5,18,1,STONE:5)
Block(5,18,2,STONE:5)
Block(5,18,3,STONE:5)
Block(5,18,4,STONE:5)
Block(5,19,-7,STONE:5)
Block(5,19,-6,STONE:5)
Block(5,19,-5,STONE:5)
Block(5,19,-4,STONE:5)
Block(5,19,-3,STONE:5)
Block(5,19,-2,STONE:5)
Block(5,19,-1,STONE:5)
Block(5,19,0,STONE:5)
Block(5,19,1,STONE:5)
Block(5,19,2,STONE:5)
Block(5,19,3,STONE:5)
Block(5,19,4,STONE:5)
Block(5,19,5,STONE:5)
Block(5,20,-7,STONE:5)
Block(5,20,-6,STONE:5)
Block(5,20,-5,STONE:5)
Block(5,20,-4,STONE:5)
Block(5,20,-3,STONE:5)
Block(5,20,-2,STONE:5)
Block(5,20,-1,STONE:5)
Block(5,20,0,STONE:5)
Block(5,20,1,STONE:5)
Block(5,20,2,STONE:5)
Block(5,20,3,STONE:5)
Block(5,20,4,STONE:5)
Block(5,20,5,STONE:5)
Block(5,20,6,STONE:5)
Block(5,20,7,STONE:5)
Block(5,21,-7,STONE:5)
Block(5,21,-6,STONE:5)
Block(5,21,-5,STONE:5)
Block(5,21,-4,STONE:5)
Block(5,21,-3,STONE:5)
Block(5,21,-2,STONE:5)
Block(5,21,-1,STONE:5)
Block(5,21,0,STONE:5)
Block(5,21,1,STONE:5)
Block(5,21,2,STONE:5)
Block(5,21,3,STONE:5)
Block(5,21,4,STONE:5)
Block(5,21,5,STONE:5)
Block(5,21,6,STONE:5)
Block(5,22,-7,STONE:5)
Block(5,22,-6,STONE:5)
Block(5,22,-5,STONE:5)
Block(5,22,-4,STONE:5)
Block(5,22,-3,STONE:5)
Block(5,22,-2,STONE:5)
Block(5,22,-1,STONE:5)
Block(5,22,0,STONE:5)
Block(5,22,1,STONE:5)
Block(5,22,2,STONE:5)
Block(5,22,3,STONE:5)
Block(5,22,4,STONE:5)
Block(5,22,5,STONE:5)
Block(5,22,6,STONE:5)
Block(5,23,-7,STONE:0)
Block(5,23,-6,STONE:0)
Block(5,23,-5,STONE:0)
Block(5,23,-4,STONE:0)
Block(5,23,-3,STONE:0)
Block(5,23,-2,STONE:0)
Block(5,23,-1,STONE:0)
Block(5,23,0,STONE:0)
Block(5,23,1,STONE:0)
Block(5,23,2,STONE:0)
Block(5,23,3,STONE:0)
Block(5,23,4,STONE:0)
Block(5,23,5,STONE:0)
Block(5,24,-7,STONE:0)
Block(5,24,-6,STONE:0)
Block(5,24,-5,STONE:0)
Block(5,24,-4,STONE:0)
Block(5,24,-3,STONE:0)
Block(5,24,-2,STONE:0)
Block(5,24,-1,STONE:0)
Block(5,24,0,STONE:0)
Block(5,24,1,STONE:0)
Block(5,24,2,STONE:0)
Block(5,24,3,STONE:0)
Block(5,24,4,STONE:0)
Block(5,25,-7,STONE:0)
Block(5,25,-3,STONE:0)
Block(5,25,-2,STONE:0)
Block(5,25,-1,STONE:0)
Block(5,25,0,STONE:0)
Block(5,25,1,STONE:0)
Block(5,25,2,STONE:0)
Block(5,25,3,STONE:0)
Block(5,26,-2,STONE:0)
Block(5,26,-1,STONE:0)
Block(5,26,0,STONE:0)
Block(5,26,1,STONE:0)
Block(5,26,2,STONE:0)
Block(5,27,-1,STONE:0)
Block(5,27,0,STONE:0)
Block(5,27,1,STONE:0)
Block(5,28,-1,STONE:0)
Block(5,28,0,STONE:0)
Block(5,28,1,STONE:0)
RandomBlock(6,17,-7,STONE:5,50,STONE:0,100)
RandomBlock(6,17,-6,STONE:5,50,STONE:0,100)
RandomBlock(6,17,-5,STONE:5,50,STONE:0,100)
RandomBlock(6,17,-4,STONE:5,50,STONE:0,100)
RandomBlock(6,17,-3,STONE:5,50,STONE:0,100)
RandomBlock(6,17,-2,STONE:5,50,STONE:0,100)
RandomBlock(6,17,-1,STONE:5,50,STONE:0,100)
RandomBlock(6,17,0,STONE:5,50,STONE:0,100)
RandomBlock(6,17,1,STONE:5,50,STONE:0,100)
RandomBlock(6,17,2,STONE:5,50,STONE:0,100)
Block(6,18,-7,STONE:5)
Block(6,18,-6,STONE:5)
Block(6,18,-5,STONE:5)
Block(6,18,-4,STONE:5)
Block(6,18,-3,STONE:5)
Block(6,18,-2,STONE:5)
Block(6,18,-1,STONE:5)
Block(6,18,0,STONE:5)
Block(6,18,1,STONE:5)
Block(6,18,2,STONE:5)
Block(6,18,3,STONE:5)
Block(6,18,4,STONE:5)
Block(6,19,-7,STONE:5)
Block(6,19,-6,STONE:5)
Block(6,19,-5,STONE:5)
Block(6,19,-4,STONE:5)
Block(6,19,-3,STONE:5)
Block(6,19,-2,STONE:5)
Block(6,19,-1,STONE:5)
Block(6,19,0,STONE:5)
Block(6,19,1,STONE:5)
Block(6,19,2,STONE:5)
Block(6,19,3,STONE:5)
Block(6,19,4,STONE:5)
Block(6,19,5,STONE:5)
Block(6,19,6,STONE:5)
Block(6,20,-7,STONE:5)
Block(6,20,-6,STONE:5)
Block(6,20,-5,STONE:5)
Block(6,20,-4,STONE:5)
Block(6,20,-3,STONE:5)
Block(6,20,-2,STONE:5)
Block(6,20,-1,STONE:5)
Block(6,20,0,STONE:5)
Block(6,20,1,STONE:5)
Block(6,20,2,STONE:5)
Block(6,20,3,STONE:5)
Block(6,20,4,STONE:5)
Block(6,20,5,STONE:5)
Block(6,20,6,STONE:5)
Block(6,20,7,STONE:5)
Block(6,21,-7,STONE:5)
Block(6,21,-6,STONE:5)
Block(6,21,-5,STONE:5)
Block(6,21,-4,STONE:5)
Block(6,21,-3,STONE:5)
Block(6,21,-2,STONE:5)
Block(6,21,-1,STONE:5)
Block(6,21,0,STONE:5)
Block(6,21,1,STONE:5)
Block(6,21,2,STONE:5)
Block(6,21,3,STONE:5)
Block(6,21,4,STONE:5)
Block(6,21,5,STONE:5)
Block(6,21,6,STONE:5)
Block(6,21,7,STONE:5)
Block(6,22,-7,STONE:5)
Block(6,22,-6,STONE:5)
Block(6,22,-5,STONE:5)
Block(6,22,-4,STONE:5)
Block(6,22,-3,STONE:5)
Block(6,22,-2,STONE:5)
Block(6,22,-1,STONE:5)
Block(6,22,0,STONE:5)
Block(6,22,1,STONE:5)
Block(6,22,2,STONE:5)
Block(6,22,3,STONE:5)
Block(6,22,4,STONE:5)
Block(6,22,5,STONE:5)
Block(6,22,6,STONE:5)
Block(6,22,7,STONE:5)
Block(6,22,8,STONE:5)
Block(6,23,-7,STONE:0)
Block(6,23,-6,STONE:0)
Block(6,23,-5,STONE:0)
Block(6,23,-4,STONE:0)
Block(6,23,-3,STONE:0)
Block(6,23,-2,STONE:0)
Block(6,23,-1,STONE:0)
Block(6,23,0,STONE:0)
Block(6,23,1,STONE:0)
Block(6,23,2,STONE:0)
Block(6,23,3,STONE:0)
Block(6,23,4,STONE:0)
Block(6,23,5,STONE:0)
Block(6,23,6,STONE:0)
Block(6,24,-7,STONE:0)
Block(6,24,-6,STONE:0)
Block(6,24,-4,STONE:0)
Block(6,24,-3,STONE:0)
Block(6,24,-2,STONE:0)
Block(6,24,-1,STONE:0)
Block(6,24,0,STONE:0)
Block(6,24,1,STONE:0)
Block(6,24,2,STONE:0)
Block(6,24,3,STONE:0)
Block(6,24,4,STONE:0)
Block(6,25,-2,STONE:0)
Block(6,25,-1,STONE:0)
Block(6,25,0,STONE:0)
Block(6,25,1,STONE:0)
Block(6,25,2,STONE:0)
Block(6,25,3,STONE:0)
Block(6,25,4,STONE:0)
Block(6,26,-2,STONE:0)
Block(6,26,-1,STONE:0)
Block(6,26,0,STONE:0)
Block(6,26,1,STONE:0)
Block(6,26,2,STONE:0)
Block(6,26,3,STONE:0)
Block(6,26,4,STONE:0)
Block(6,27,-1,STONE:0)
Block(6,27,0,STONE:0)
Block(6,27,1,STONE:0)
Block(6,27,2,STONE:0)
Block(6,27,3,STONE:0)
Block(6,28,-1,STONE:0)
Block(6,28,0,STONE:0)
Block(6,28,1,STONE:0)
Block(7,16,-5,STONE:0)
RandomBlock(7,17,-7,STONE:5,50,STONE:0,100)
RandomBlock(7,17,-6,STONE:5,50,STONE:0,100)
RandomBlock(7,17,-5,STONE:5,50,STONE:0,100)
RandomBlock(7,17,-4,STONE:5,50,STONE:0,100)
RandomBlock(7,17,-3,STONE:5,50,STONE:0,100)
RandomBlock(7,17,-2,STONE:5,50,STONE:0,100)
RandomBlock(7,17,-1,STONE:5,50,STONE:0,100)
RandomBlock(7,17,0,STONE:5,50,STONE:0,100)
RandomBlock(7,17,1,STONE:5,50,STONE:0,100)
RandomBlock(7,17,2,STONE:5,50,STONE:0,100)
RandomBlock(7,17,3,STONE:5,50,STONE:0,100)
RandomBlock(7,17,4,STONE:5,50,STONE:0,100)
RandomBlock(7,17,5,STONE:5,50,STONE:0,100)
RandomBlock(7,17,6,STONE:5,50,STONE:0,100)
Block(7,18,-7,STONE:5)
Block(7,18,-6,STONE:5)
Block(7,18,-5,STONE:5)
Block(7,18,-4,STONE:5)
Block(7,18,-3,STONE:5)
Block(7,18,-2,STONE:5)
Block(7,18,-1,STONE:5)
Block(7,18,0,STONE:5)
Block(7,18,1,STONE:5)
Block(7,18,2,STONE:5)
Block(7,18,3,STONE:5)
Block(7,18,4,STONE:5)
Block(7,18,5,STONE:5)
Block(7,18,6,STONE:5)
Block(7,19,-7,STONE:5)
Block(7,19,-6,STONE:5)
Block(7,19,-5,STONE:5)
Block(7,19,-4,STONE:5)
Block(7,19,-3,STONE:5)
Block(7,19,-2,STONE:5)
Block(7,19,-1,STONE:5)
Block(7,19,0,STONE:5)
Block(7,19,1,STONE:5)
Block(7,19,2,STONE:5)
Block(7,19,3,STONE:5)
Block(7,19,4,STONE:5)
Block(7,19,5,STONE:5)
Block(7,19,6,STONE:5)
Block(7,19,7,STONE:5)
Block(7,20,-7,STONE:5)
Block(7,20,-6,STONE:5)
Block(7,20,-5,STONE:5)
Block(7,20,-4,STONE:5)
Block(7,20,-3,STONE:5)
Block(7,20,-2,STONE:5)
Block(7,20,-1,STONE:5)
Block(7,20,0,STONE:5)
Block(7,20,1,STONE:5)
Block(7,20,2,STONE:5)
Block(7,20,3,STONE:5)
Block(7,20,4,STONE:5)
Block(7,20,5,STONE:5)
Block(7,20,6,STONE:5)
Block(7,20,7,STONE:5)
Block(7,21,-7,STONE:5)
Block(7,21,-6,STONE:5)
Block(7,21,-5,STONE:5)
Block(7,21,-4,STONE:5)
Block(7,21,-3,STONE:5)
Block(7,21,-2,STONE:5)
Block(7,21,-1,STONE:5)
Block(7,21,0,STONE:5)
Block(7,21,1,STONE:5)
Block(7,21,2,STONE:5)
Block(7,21,3,STONE:5)
Block(7,21,4,STONE:5)
Block(7,21,5,STONE:5)
Block(7,21,6,STONE:5)
Block(7,21,7,STONE:5)
Block(7,21,8,STONE:5)
Block(7,22,-7,STONE:5)
Block(7,22,-6,STONE:5)
Block(7,22,-5,STONE:5)
Block(7,22,-4,STONE:5)
Block(7,22,-3,STONE:5)
Block(7,22,-2,STONE:5)
Block(7,22,-1,STONE:5)
Block(7,22,0,STONE:5)
Block(7,22,1,STONE:5)
Block(7,22,2,STONE:5)
Block(7,22,3,STONE:5)
Block(7,22,4,STONE:5)
Block(7,22,5,STONE:5)
Block(7,22,6,STONE:5)
Block(7,22,7,STONE:5)
Block(7,23,-6,STONE:0)
Block(7,23,-5,STONE:0)
Block(7,23,-4,STONE:0)
Block(7,23,-3,STONE:0)
Block(7,23,-2,STONE:0)
Block(7,23,-1,STONE:0)
Block(7,23,0,STONE:0)
Block(7,23,1,STONE:0)
Block(7,23,2,STONE:0)
Block(7,23,3,STONE:0)
Block(7,23,4,STONE:0)
Block(7,23,5,STONE:0)
Block(7,23,6,STONE:0)
Block(7,23,7,STONE:0)
Block(7,24,-3,STONE:0)
Block(7,24,-2,STONE:0)
Block(7,24,-1,STONE:0)
Block(7,24,0,STONE:0)
Block(7,24,1,STONE:0)
Block(7,24,2,STONE:0)
Block(7,24,3,STONE:0)
Block(7,24,4,STONE:0)
Block(7,25,-2,STONE:0)
Block(7,25,-1,STONE:0)
Block(7,25,0,STONE:0)
Block(7,25,1,STONE:0)
Block(7,25,2,STONE:0)
Block(7,25,3,STONE:0)
Block(7,25,4,STONE:0)
Block(7,26,-1,STONE:0)
Block(7,26,0,STONE:0)
Block(7,26,1,STONE:0)
Block(7,26,2,STONE:0)
Block(7,26,3,STONE:0)
Block(7,26,4,STONE:0)
Block(7,26,5,STONE:0)
Block(7,27,-1,STONE:0)
Block(7,27,0,STONE:0)
Block(7,27,1,STONE:0)
Block(7,27,2,STONE:0)
Block(7,27,3,STONE:0)
Block(7,27,4,STONE:0)
Block(7,28,1,STONE:0)
Block(7,28,2,STONE:0)

#######################################################################
# +-----------------------------------------------------------------+ #
# |                             Branches                            | #
# +-----------------------------------------------------------------+ #
#######################################################################

Branch(0,0,16,true,cyclops_branch_1C0R2,NORTH,100.0,0)

#######################################################################
# +-----------------------------------------------------------------+ #
# |                             Entities                            | #
# +-----------------------------------------------------------------+ #
#######################################################################


#######################################################################
# +-----------------------------------------------------------------+ #
# |                            Particles                            | #
# +-----------------------------------------------------------------+ #
#######################################################################


#######################################################################
# +-----------------------------------------------------------------+ #
# |                             Spawners                            | #
# +-----------------------------------------------------------------+ #
#######################################################################


#######################################################################
# +-----------------------------------------------------------------+ #
# |                             ModData                             | #
# +-----------------------------------------------------------------+ #
#######################################################################

