
#######################################################################
# +-----------------------------------------------------------------+ #
# |                            BO4 object                           | #
# +-----------------------------------------------------------------+ #
#######################################################################

Author: NLBlackEagle

Description: No description given

SettingsMode: WriteWithoutComments


#######################################################################
# +-----------------------------------------------------------------+ #
# |                          Main settings                          | #
# +-----------------------------------------------------------------+ #
#######################################################################

FixedRotation: 

Frequency: 0

SpawnHeight: highestBlock

UseCenterForHighestBlock: true

##############################
# Height Limits for the BO4. #
##############################

MinHeight: 0

MaxHeight: 255

InheritBO3: 

InheritBO3Rotation: NORTH

OverrideChildSettings: true

OverrideParentHeight: false

CanOverride: true

BranchFrequency: 0

BranchFrequencyGroup: 

MustBeBelowOther: false

MustBeInside: 

CannotBeInside: 

ReplacesBO3: 

MustBeInsideWorldBorders: false

CanSpawnOnWater: true

SpawnOnWaterOnly: false

SpawnUnderWater: false

SpawnAtWaterLevel: false

HeightOffset: 0

RemoveAir: false

ReplaceAbove: 

ReplaceBelow: 

ReplaceWithBiomeBlocks: true

ReplaceWithSurfaceBlock: GRASS

ReplaceWithGroundBlock: DIRT

ReplaceWithStoneBlock: STONE

SmoothRadius: 0

SmoothHeightOffset: 0

SmoothStartTop: false

SmoothStartWood: false

SmoothingSurfaceBlock: 

SmoothingGroundBlock: 

BO3Group: 

IsSpawnPoint: false

DoReplaceBlocks: true


#######################################################################
# +-----------------------------------------------------------------+ #
# |                              Blocks                             | #
# +-----------------------------------------------------------------+ #
#######################################################################

Block(-8,10,5,STONE:0)
Block(-8,10,6,STONE:0)
Block(-8,10,7,STONE:0)
Block(-8,10,8,STONE:0)
Block(-8,11,4,STONE:0)
Block(-8,11,5,STONE:0)
Block(-8,11,6,STONE:0)
Block(-8,11,7,STONE:0)
Block(-8,11,8,STONE:0)
Block(-8,12,3,STONE:0)
Block(-8,12,4,STONE:0)
Block(-8,12,5,STONE:0)
Block(-8,12,6,STONE:0)
Block(-8,12,7,STONE:0)
Block(-8,12,8,STONE:0)
Block(-8,13,3,STONE:0)
Block(-8,13,4,STONE:0)
Block(-8,13,5,STONE:0)
Block(-8,13,6,STONE:0)
Block(-8,13,7,STONE:0)
Block(-8,13,8,STONE:0)
Block(-8,14,3,STONE:0)
Block(-8,14,4,STONE:0)
Block(-8,14,5,STONE:0)
Block(-8,14,6,STONE:0)
Block(-8,14,7,STONE:0)
Block(-8,15,2,STONE:0)
Block(-8,15,3,STONE:0)
Block(-8,15,4,STONE:0)
Block(-8,15,5,STONE:0)
Block(-8,15,6,STONE:0)
Block(-8,15,7,STONE:0)
Block(-8,16,-1,STONE:0)
Block(-8,16,0,STONE:0)
Block(-8,16,1,STONE:0)
Block(-8,16,2,STONE:0)
Block(-8,16,3,STONE:0)
Block(-8,16,4,STONE:0)
Block(-8,16,5,STONE:0)
RandomBlock(-8,17,-1,STONE:5,50,STONE:0,100)
RandomBlock(-8,17,0,STONE:5,50,STONE:0,100)
RandomBlock(-8,17,1,STONE:5,50,STONE:0,100)
RandomBlock(-8,17,2,STONE:5,50,STONE:0,100)
RandomBlock(-8,17,3,STONE:5,50,STONE:0,100)
RandomBlock(-8,17,4,STONE:5,50,STONE:0,100)
RandomBlock(-8,17,5,STONE:5,50,STONE:0,100)
Block(-8,18,-2,STONE:5)
Block(-8,18,-1,STONE:5)
Block(-8,18,0,STONE:5)
Block(-8,18,1,STONE:5)
Block(-8,18,2,STONE:5)
Block(-8,18,3,STONE:5)
Block(-8,18,4,STONE:5)
Block(-8,18,5,STONE:5)
Block(-8,19,-2,STONE:5)
Block(-8,19,-1,STONE:5)
Block(-8,19,0,STONE:5)
Block(-8,19,1,STONE:5)
Block(-8,19,2,STONE:5)
Block(-8,19,3,STONE:5)
Block(-8,19,4,STONE:5)
Block(-8,19,5,STONE:5)
Block(-8,20,-3,STONE:5)
Block(-8,20,-2,STONE:5)
Block(-8,20,-1,STONE:5)
Block(-8,20,0,STONE:5)
Block(-8,20,1,STONE:5)
Block(-8,20,2,STONE:5)
Block(-8,20,3,STONE:5)
Block(-8,20,4,STONE:5)
Block(-8,20,5,STONE:5)
Block(-8,21,-2,STONE:5)
Block(-8,21,-1,STONE:5)
Block(-8,21,0,STONE:5)
Block(-8,21,1,STONE:5)
Block(-8,21,2,STONE:5)
Block(-8,21,3,STONE:5)
Block(-8,21,4,STONE:5)
Block(-8,21,5,STONE:5)
Block(-8,22,-2,STONE:5)
Block(-8,22,-1,STONE:5)
Block(-8,22,0,STONE:5)
Block(-8,22,1,STONE:5)
Block(-8,22,2,STONE:5)
Block(-8,22,3,STONE:5)
Block(-8,22,4,STONE:5)
Block(-8,22,5,STONE:5)
Block(-8,22,6,STONE:5)
Block(-8,23,-3,STONE:0)
Block(-8,23,-2,STONE:0)
Block(-8,23,-1,STONE:0)
Block(-8,23,0,STONE:0)
Block(-8,23,1,STONE:0)
Block(-8,23,2,STONE:0)
Block(-8,23,3,STONE:0)
Block(-8,23,4,STONE:0)
Block(-8,23,5,STONE:0)
Block(-8,23,6,STONE:0)
Block(-8,23,7,STONE:0)
Block(-8,24,-2,STONE:0)
Block(-8,24,-1,STONE:0)
Block(-8,24,0,STONE:0)
Block(-8,24,1,STONE:0)
Block(-8,24,2,STONE:0)
Block(-8,24,3,STONE:0)
Block(-8,24,4,STONE:0)
Block(-8,24,5,STONE:0)
Block(-8,24,6,STONE:0)
Block(-8,24,7,STONE:0)
Block(-8,25,-2,STONE:0)
Block(-8,25,-1,STONE:0)
Block(-8,25,0,STONE:0)
Block(-8,25,1,STONE:0)
Block(-8,25,2,STONE:0)
Block(-8,25,3,STONE:0)
Block(-8,25,4,STONE:0)
Block(-8,25,5,STONE:0)
Block(-8,25,6,STONE:0)
Block(-8,25,7,STONE:0)
Block(-8,26,-1,STONE:0)
Block(-8,26,0,STONE:0)
Block(-8,26,1,STONE:0)
Block(-8,26,2,STONE:0)
Block(-8,26,3,STONE:0)
Block(-8,26,4,STONE:0)
Block(-8,26,5,STONE:0)
Block(-8,27,0,STONE:0)
Block(-8,27,1,STONE:0)
Block(-8,27,2,STONE:0)
Block(-8,27,3,STONE:0)
Block(-8,27,4,STONE:0)
Block(-8,27,5,STONE:0)
Block(-8,28,1,STONE:0)
Block(-8,28,2,STONE:0)
Block(-8,28,3,STONE:0)
Block(-8,28,4,STONE:0)
Block(-7,10,6,STONE:0)
Block(-7,10,7,STONE:0)
Block(-7,10,8,STONE:0)
Block(-7,11,4,STONE:0)
Block(-7,11,5,STONE:0)
Block(-7,11,6,STONE:0)
Block(-7,11,7,STONE:0)
Block(-7,11,8,STONE:0)
Block(-7,12,4,STONE:0)
Block(-7,12,5,STONE:0)
Block(-7,12,6,STONE:0)
Block(-7,12,7,STONE:0)
Block(-7,12,8,STONE:0)
Block(-7,13,3,STONE:0)
Block(-7,13,4,STONE:0)
Block(-7,13,5,STONE:0)
Block(-7,13,6,STONE:0)
Block(-7,13,7,STONE:0)
Block(-7,13,8,STONE:0)
Block(-7,14,3,STONE:0)
Block(-7,14,4,STONE:0)
Block(-7,14,5,STONE:0)
Block(-7,14,6,STONE:0)
Block(-7,14,7,STONE:0)
Block(-7,15,3,STONE:0)
Block(-7,15,4,STONE:0)
Block(-7,15,5,STONE:0)
Block(-7,15,6,STONE:0)
Block(-7,16,0,STONE:0)
Block(-7,16,1,STONE:0)
Block(-7,16,2,STONE:0)
Block(-7,16,3,STONE:0)
Block(-7,16,4,STONE:0)
Block(-7,16,5,STONE:0)
RandomBlock(-7,17,-1,STONE:5,50,STONE:0,100)
RandomBlock(-7,17,0,STONE:5,50,STONE:0,100)
RandomBlock(-7,17,1,STONE:5,50,STONE:0,100)
RandomBlock(-7,17,2,STONE:5,50,STONE:0,100)
RandomBlock(-7,17,3,STONE:5,50,STONE:0,100)
RandomBlock(-7,17,4,STONE:5,50,STONE:0,100)
RandomBlock(-7,17,5,STONE:5,50,STONE:0,100)
Block(-7,18,-1,STONE:5)
Block(-7,18,0,STONE:5)
Block(-7,18,1,STONE:5)
Block(-7,18,2,STONE:5)
Block(-7,18,3,STONE:5)
Block(-7,18,4,STONE:5)
Block(-7,18,5,STONE:5)
Block(-7,19,-2,STONE:5)
Block(-7,19,-1,STONE:5)
Block(-7,19,0,STONE:5)
Block(-7,19,1,STONE:5)
Block(-7,19,2,STONE:5)
Block(-7,19,3,STONE:5)
Block(-7,19,4,STONE:5)
Block(-7,19,5,STONE:5)
Block(-7,20,-2,STONE:5)
Block(-7,20,-1,STONE:5)
Block(-7,20,0,STONE:5)
Block(-7,20,1,STONE:5)
Block(-7,20,2,STONE:5)
Block(-7,20,3,STONE:5)
Block(-7,20,4,STONE:5)
Block(-7,20,5,STONE:5)
Block(-7,21,-2,STONE:5)
Block(-7,21,-1,STONE:5)
Block(-7,21,0,STONE:5)
Block(-7,21,1,STONE:5)
Block(-7,21,2,STONE:5)
Block(-7,21,3,STONE:5)
Block(-7,21,4,STONE:5)
Block(-7,21,5,STONE:5)
Block(-7,21,6,STONE:5)
Block(-7,22,-3,STONE:5)
Block(-7,22,-2,STONE:5)
Block(-7,22,-1,STONE:5)
Block(-7,22,0,STONE:5)
Block(-7,22,1,STONE:5)
Block(-7,22,2,STONE:5)
Block(-7,22,3,STONE:5)
Block(-7,22,4,STONE:5)
Block(-7,22,5,STONE:5)
Block(-7,22,6,STONE:5)
Block(-7,22,7,STONE:5)
Block(-7,23,-3,STONE:0)
Block(-7,23,-2,STONE:0)
Block(-7,23,-1,STONE:0)
Block(-7,23,0,STONE:0)
Block(-7,23,1,STONE:0)
Block(-7,23,2,STONE:0)
Block(-7,23,3,STONE:0)
Block(-7,23,4,STONE:0)
Block(-7,23,5,STONE:0)
Block(-7,23,6,STONE:0)
Block(-7,23,7,STONE:0)
Block(-7,24,-2,STONE:0)
Block(-7,24,-1,STONE:0)
Block(-7,24,0,STONE:0)
Block(-7,24,1,STONE:0)
Block(-7,24,2,STONE:0)
Block(-7,24,3,STONE:0)
Block(-7,24,4,STONE:0)
Block(-7,24,5,STONE:0)
Block(-7,24,6,STONE:0)
Block(-7,24,7,STONE:0)
Block(-7,25,-2,STONE:0)
Block(-7,25,-1,STONE:0)
Block(-7,25,0,STONE:0)
Block(-7,25,1,STONE:0)
Block(-7,25,2,STONE:0)
Block(-7,25,3,STONE:0)
Block(-7,25,4,STONE:0)
Block(-7,25,5,STONE:0)
Block(-7,25,6,STONE:0)
Block(-7,25,7,STONE:0)
Block(-7,25,8,STONE:0)
Block(-7,26,-1,STONE:0)
Block(-7,26,0,STONE:0)
Block(-7,26,1,STONE:0)
Block(-7,26,2,STONE:0)
Block(-7,26,3,STONE:0)
Block(-7,26,4,STONE:0)
Block(-7,26,5,STONE:0)
Block(-7,26,6,STONE:0)
Block(-7,27,2,STONE:0)
Block(-7,27,3,STONE:0)
Block(-7,27,4,STONE:0)
Block(-6,9,7,STONE:0)
Block(-6,9,8,STONE:0)
Block(-6,10,6,STONE:0)
Block(-6,10,7,STONE:0)
Block(-6,10,8,STONE:0)
Block(-6,11,5,STONE:0)
Block(-6,11,6,STONE:0)
Block(-6,11,7,STONE:0)
Block(-6,11,8,STONE:0)
Block(-6,12,4,STONE:0)
Block(-6,12,5,STONE:0)
Block(-6,12,6,STONE:0)
Block(-6,12,7,STONE:0)
Block(-6,12,8,STONE:0)
Block(-6,13,4,STONE:0)
Block(-6,13,5,STONE:0)
Block(-6,13,6,STONE:0)
Block(-6,13,7,STONE:0)
Block(-6,14,3,STONE:0)
Block(-6,14,4,STONE:0)
Block(-6,14,5,STONE:0)
Block(-6,14,6,STONE:0)
Block(-6,15,4,STONE:0)
Block(-6,15,5,STONE:0)
Block(-6,16,0,STONE:0)
Block(-6,16,1,STONE:0)
Block(-6,16,2,STONE:0)
Block(-6,16,3,STONE:0)
Block(-6,16,4,STONE:0)
Block(-6,16,5,STONE:0)
RandomBlock(-6,17,-1,STONE:5,50,STONE:0,100)
RandomBlock(-6,17,0,STONE:5,50,STONE:0,100)
RandomBlock(-6,17,1,STONE:5,50,STONE:0,100)
RandomBlock(-6,17,2,STONE:5,50,STONE:0,100)
RandomBlock(-6,17,3,STONE:5,50,STONE:0,100)
RandomBlock(-6,17,4,STONE:5,50,STONE:0,100)
RandomBlock(-6,17,5,STONE:5,50,STONE:0,100)
Block(-6,18,-1,STONE:5)
Block(-6,18,0,STONE:5)
Block(-6,18,1,STONE:5)
Block(-6,18,2,STONE:5)
Block(-6,18,3,STONE:5)
Block(-6,18,4,STONE:5)
Block(-6,18,5,STONE:5)
Block(-6,19,-1,STONE:5)
Block(-6,19,0,STONE:5)
Block(-6,19,1,STONE:5)
Block(-6,19,2,STONE:5)
Block(-6,19,3,STONE:5)
Block(-6,19,4,STONE:5)
Block(-6,19,5,STONE:5)
Block(-6,20,-1,STONE:5)
Block(-6,20,0,STONE:5)
Block(-6,20,1,STONE:5)
Block(-6,20,2,STONE:5)
Block(-6,20,3,STONE:5)
Block(-6,20,4,STONE:5)
Block(-6,20,5,STONE:5)
Block(-6,21,-2,STONE:5)
Block(-6,21,-1,STONE:5)
Block(-6,21,0,STONE:5)
Block(-6,21,1,STONE:5)
Block(-6,21,2,STONE:5)
Block(-6,21,3,STONE:5)
Block(-6,21,4,STONE:5)
Block(-6,21,5,STONE:5)
Block(-6,21,6,STONE:5)
Block(-6,22,-2,STONE:5)
Block(-6,22,-1,STONE:5)
Block(-6,22,0,STONE:5)
Block(-6,22,1,STONE:5)
Block(-6,22,2,STONE:5)
Block(-6,22,3,STONE:5)
Block(-6,22,4,STONE:5)
Block(-6,22,5,STONE:5)
Block(-6,22,6,STONE:5)
Block(-6,22,7,STONE:5)
Block(-6,23,-3,STONE:0)
Block(-6,23,-2,STONE:0)
Block(-6,23,-1,STONE:0)
Block(-6,23,0,STONE:0)
Block(-6,23,1,STONE:0)
Block(-6,23,2,STONE:0)
Block(-6,23,3,STONE:0)
Block(-6,23,4,STONE:0)
Block(-6,23,5,STONE:0)
Block(-6,23,6,STONE:0)
Block(-6,23,7,STONE:0)
Block(-6,24,-2,STONE:0)
Block(-6,24,-1,STONE:0)
Block(-6,24,0,STONE:0)
Block(-6,24,1,STONE:0)
Block(-6,24,2,STONE:0)
Block(-6,24,3,STONE:0)
Block(-6,24,4,STONE:0)
Block(-6,24,5,STONE:0)
Block(-6,24,6,STONE:0)
Block(-6,24,7,STONE:0)
Block(-6,25,-2,STONE:0)
Block(-6,25,-1,STONE:0)
Block(-6,25,0,STONE:0)
Block(-6,25,1,STONE:0)
Block(-6,25,2,STONE:0)
Block(-6,25,3,STONE:0)
Block(-6,25,4,STONE:0)
Block(-6,25,5,STONE:0)
Block(-6,25,6,STONE:0)
Block(-6,25,7,STONE:0)
Block(-6,25,8,STONE:0)
Block(-6,26,0,STONE:0)
Block(-6,26,1,STONE:0)
Block(-6,26,2,STONE:0)
Block(-6,26,3,STONE:0)
Block(-6,26,4,STONE:0)
Block(-6,26,5,STONE:0)
Block(-6,26,6,STONE:0)
Block(-6,26,7,STONE:0)
Block(-6,26,8,STONE:0)
Block(-6,27,4,STONE:0)
Block(-6,27,6,STONE:0)
Block(-5,8,8,STONE:0)
Block(-5,9,6,STONE:0)
Block(-5,9,7,STONE:0)
Block(-5,9,8,STONE:0)
Block(-5,10,5,STONE:0)
Block(-5,10,6,STONE:0)
Block(-5,10,7,STONE:0)
Block(-5,10,8,STONE:0)
Block(-5,11,5,STONE:0)
Block(-5,11,6,STONE:0)
Block(-5,11,7,STONE:0)
Block(-5,11,8,STONE:0)
Block(-5,12,4,STONE:0)
Block(-5,12,5,STONE:0)
Block(-5,12,6,STONE:0)
Block(-5,12,7,STONE:0)
Block(-5,12,8,STONE:0)
Block(-5,13,4,STONE:0)
Block(-5,13,5,STONE:0)
Block(-5,13,6,STONE:0)
Block(-5,13,7,STONE:0)
Block(-5,14,3,STONE:0)
Block(-5,14,4,STONE:0)
Block(-5,14,5,STONE:0)
Block(-5,14,6,STONE:0)
Block(-5,14,7,STONE:0)
Block(-5,15,4,STONE:0)
Block(-5,15,5,STONE:0)
Block(-5,16,0,STONE:0)
Block(-5,16,1,STONE:0)
Block(-5,16,2,STONE:0)
Block(-5,16,3,STONE:0)
Block(-5,16,4,STONE:0)
Block(-5,16,5,STONE:0)
RandomBlock(-5,17,0,STONE:5,50,STONE:0,100)
RandomBlock(-5,17,1,STONE:5,50,STONE:0,100)
RandomBlock(-5,17,2,STONE:5,50,STONE:0,100)
RandomBlock(-5,17,3,STONE:5,50,STONE:0,100)
RandomBlock(-5,17,4,STONE:5,50,STONE:0,100)
RandomBlock(-5,17,5,STONE:5,50,STONE:0,100)
Block(-5,18,-1,STONE:5)
Block(-5,18,0,STONE:5)
Block(-5,18,1,STONE:5)
Block(-5,18,2,STONE:5)
Block(-5,18,3,STONE:5)
Block(-5,18,4,STONE:5)
Block(-5,18,5,STONE:5)
Block(-5,19,-2,STONE:5)
Block(-5,19,-1,STONE:5)
Block(-5,19,0,STONE:5)
Block(-5,19,1,STONE:5)
Block(-5,19,2,STONE:5)
Block(-5,19,3,STONE:5)
Block(-5,19,4,STONE:5)
Block(-5,19,5,STONE:5)
Block(-5,20,-2,STONE:5)
Block(-5,20,-1,STONE:5)
Block(-5,20,0,STONE:5)
Block(-5,20,1,STONE:5)
Block(-5,20,2,STONE:5)
Block(-5,20,3,STONE:5)
Block(-5,20,4,STONE:5)
Block(-5,20,5,STONE:5)
Block(-5,20,6,STONE:5)
Block(-5,21,-2,STONE:5)
Block(-5,21,-1,STONE:5)
Block(-5,21,0,STONE:5)
Block(-5,21,1,STONE:5)
Block(-5,21,2,STONE:5)
Block(-5,21,3,STONE:5)
Block(-5,21,4,STONE:5)
Block(-5,21,5,STONE:5)
Block(-5,21,6,STONE:5)
Block(-5,21,7,STONE:5)
Block(-5,22,-2,STONE:5)
Block(-5,22,-1,STONE:5)
Block(-5,22,0,STONE:5)
Block(-5,22,1,STONE:5)
Block(-5,22,2,STONE:5)
Block(-5,22,3,STONE:5)
Block(-5,22,4,STONE:5)
Block(-5,22,5,STONE:5)
Block(-5,22,6,STONE:5)
Block(-5,22,7,STONE:5)
Block(-5,23,-2,STONE:0)
Block(-5,23,-1,STONE:0)
Block(-5,23,0,STONE:0)
Block(-5,23,1,STONE:0)
Block(-5,23,2,STONE:0)
Block(-5,23,3,STONE:0)
Block(-5,23,4,STONE:0)
Block(-5,23,5,STONE:0)
Block(-5,23,6,STONE:0)
Block(-5,23,7,STONE:0)
Block(-5,24,-1,STONE:0)
Block(-5,24,0,STONE:0)
Block(-5,24,1,STONE:0)
Block(-5,24,2,STONE:0)
Block(-5,24,3,STONE:0)
Block(-5,24,4,STONE:0)
Block(-5,24,5,STONE:0)
Block(-5,24,6,STONE:0)
Block(-5,24,7,STONE:0)
Block(-5,24,8,STONE:0)
Block(-5,25,-1,STONE:0)
Block(-5,25,0,STONE:0)
Block(-5,25,1,STONE:0)
Block(-5,25,2,STONE:0)
Block(-5,25,3,STONE:0)
Block(-5,25,4,STONE:0)
Block(-5,25,5,STONE:0)
Block(-5,25,6,STONE:0)
Block(-5,25,7,STONE:0)
Block(-5,25,8,STONE:0)
Block(-5,26,3,STONE:0)
Block(-5,26,4,STONE:0)
Block(-5,26,5,STONE:0)
Block(-5,26,6,STONE:0)
Block(-5,26,7,STONE:0)
Block(-5,26,8,STONE:0)
Block(-5,27,5,STONE:0)
Block(-5,27,6,STONE:0)
Block(-5,27,7,STONE:0)
Block(-5,27,8,STONE:0)
Block(-5,28,6,STONE:0)
Block(-5,28,8,STONE:0)
Block(-4,8,7,STONE:0)
Block(-4,8,8,STONE:0)
Block(-4,9,5,STONE:0)
Block(-4,9,6,STONE:0)
Block(-4,9,7,STONE:0)
Block(-4,9,8,STONE:0)
Block(-4,10,5,STONE:0)
Block(-4,10,6,STONE:0)
Block(-4,10,7,STONE:0)
Block(-4,10,8,STONE:0)
Block(-4,11,4,STONE:0)
Block(-4,11,5,STONE:0)
Block(-4,11,6,STONE:0)
Block(-4,11,7,STONE:0)
Block(-4,11,8,STONE:0)
Block(-4,12,4,STONE:0)
Block(-4,12,5,STONE:0)
Block(-4,12,6,STONE:0)
Block(-4,12,7,STONE:0)
Block(-4,12,8,STONE:0)
Block(-4,13,3,STONE:0)
Block(-4,13,4,STONE:0)
Block(-4,13,5,STONE:0)
Block(-4,13,6,STONE:0)
Block(-4,13,7,STONE:0)
Block(-4,14,3,STONE:0)
Block(-4,14,4,STONE:0)
Block(-4,14,5,STONE:0)
Block(-4,14,6,STONE:0)
Block(-4,14,7,STONE:0)
Block(-4,15,3,STONE:0)
Block(-4,15,4,STONE:0)
Block(-4,15,5,STONE:0)
Block(-4,15,6,STONE:0)
Block(-4,16,1,STONE:0)
Block(-4,16,2,STONE:0)
Block(-4,16,3,STONE:0)
Block(-4,16,4,STONE:0)
Block(-4,16,5,STONE:0)
RandomBlock(-4,17,0,STONE:5,50,STONE:0,100)
RandomBlock(-4,17,1,STONE:5,50,STONE:0,100)
RandomBlock(-4,17,2,STONE:5,50,STONE:0,100)
RandomBlock(-4,17,3,STONE:5,50,STONE:0,100)
RandomBlock(-4,17,4,STONE:5,50,STONE:0,100)
RandomBlock(-4,17,5,STONE:5,50,STONE:0,100)
Block(-4,18,-1,STONE:5)
Block(-4,18,0,STONE:5)
Block(-4,18,1,STONE:5)
Block(-4,18,2,STONE:5)
Block(-4,18,3,STONE:5)
Block(-4,18,4,STONE:5)
Block(-4,18,5,STONE:5)
Block(-4,19,-2,STONE:5)
Block(-4,19,-1,STONE:5)
Block(-4,19,0,STONE:5)
Block(-4,19,1,STONE:5)
Block(-4,19,2,STONE:5)
Block(-4,19,3,STONE:5)
Block(-4,19,4,STONE:5)
Block(-4,19,5,STONE:5)
Block(-4,20,-2,STONE:5)
Block(-4,20,-1,STONE:5)
Block(-4,20,0,STONE:5)
Block(-4,20,1,STONE:5)
Block(-4,20,2,STONE:5)
Block(-4,20,3,STONE:5)
Block(-4,20,4,STONE:5)
Block(-4,20,5,STONE:5)
Block(-4,20,6,STONE:5)
Block(-4,21,-2,STONE:5)
Block(-4,21,-1,STONE:5)
Block(-4,21,0,STONE:5)
Block(-4,21,1,STONE:5)
Block(-4,21,2,STONE:5)
Block(-4,21,3,STONE:5)
Block(-4,21,4,STONE:5)
Block(-4,21,5,STONE:5)
Block(-4,21,6,STONE:5)
Block(-4,21,7,STONE:5)
Block(-4,22,-2,STONE:5)
Block(-4,22,-1,STONE:5)
Block(-4,22,0,STONE:5)
Block(-4,22,1,STONE:5)
Block(-4,22,2,STONE:5)
Block(-4,22,3,STONE:5)
Block(-4,22,4,STONE:5)
Block(-4,22,5,STONE:5)
Block(-4,22,6,STONE:5)
Block(-4,22,7,STONE:5)
Block(-4,23,-1,STONE:0)
Block(-4,23,0,STONE:0)
Block(-4,23,1,STONE:0)
Block(-4,23,2,STONE:0)
Block(-4,23,3,STONE:0)
Block(-4,23,4,STONE:0)
Block(-4,23,5,STONE:0)
Block(-4,23,6,STONE:0)
Block(-4,23,7,STONE:0)
Block(-4,23,8,STONE:0)
Block(-4,24,-1,STONE:0)
Block(-4,24,0,STONE:0)
Block(-4,24,1,STONE:0)
Block(-4,24,2,STONE:0)
Block(-4,24,3,STONE:0)
Block(-4,24,4,STONE:0)
Block(-4,24,5,STONE:0)
Block(-4,24,6,STONE:0)
Block(-4,24,7,STONE:0)
Block(-4,24,8,STONE:0)
Block(-4,25,0,STONE:0)
Block(-4,25,1,STONE:0)
Block(-4,25,2,STONE:0)
Block(-4,25,3,STONE:0)
Block(-4,25,4,STONE:0)
Block(-4,25,5,STONE:0)
Block(-4,25,6,STONE:0)
Block(-4,25,7,STONE:0)
Block(-4,25,8,STONE:0)
Block(-4,26,4,STONE:0)
Block(-4,26,5,STONE:0)
Block(-4,26,6,STONE:0)
Block(-4,26,7,STONE:0)
Block(-4,26,8,STONE:0)
Block(-4,27,6,STONE:0)
Block(-4,27,7,STONE:0)
Block(-4,27,8,STONE:0)
Block(-4,28,7,STONE:0)
Block(-4,28,8,STONE:0)
Block(-3,8,6,STONE:0)
Block(-3,8,7,STONE:0)
Block(-3,8,8,STONE:0)
Block(-3,9,5,STONE:0)
Block(-3,9,6,STONE:0)
Block(-3,9,7,STONE:0)
Block(-3,9,8,STONE:0)
Block(-3,10,4,STONE:0)
Block(-3,10,5,STONE:0)
Block(-3,10,6,STONE:0)
Block(-3,10,7,STONE:0)
Block(-3,10,8,STONE:0)
Block(-3,11,4,STONE:0)
Block(-3,11,5,STONE:0)
Block(-3,11,6,STONE:0)
Block(-3,11,7,STONE:0)
Block(-3,11,8,STONE:0)
Block(-3,12,3,STONE:0)
Block(-3,12,4,STONE:0)
Block(-3,12,5,STONE:0)
Block(-3,12,6,STONE:0)
Block(-3,12,7,STONE:0)
Block(-3,12,8,STONE:0)
Block(-3,13,3,STONE:0)
Block(-3,13,4,STONE:0)
Block(-3,13,5,STONE:0)
Block(-3,13,6,STONE:0)
Block(-3,13,7,STONE:0)
Block(-3,14,3,STONE:0)
Block(-3,14,4,STONE:0)
Block(-3,14,5,STONE:0)
Block(-3,14,6,STONE:0)
Block(-3,14,7,STONE:0)
Block(-3,15,3,STONE:0)
Block(-3,15,4,STONE:0)
Block(-3,15,5,STONE:0)
Block(-3,15,6,STONE:0)
Block(-3,15,7,STONE:0)
Block(-3,16,3,STONE:0)
Block(-3,16,4,STONE:0)
Block(-3,16,5,STONE:0)
Block(-3,16,6,STONE:0)
RandomBlock(-3,17,1,STONE:5,50,STONE:0,100)
RandomBlock(-3,17,2,STONE:5,50,STONE:0,100)
RandomBlock(-3,17,3,STONE:5,50,STONE:0,100)
RandomBlock(-3,17,4,STONE:5,50,STONE:0,100)
RandomBlock(-3,17,5,STONE:5,50,STONE:0,100)
Block(-3,18,0,STONE:5)
Block(-3,18,1,STONE:5)
Block(-3,18,2,STONE:5)
Block(-3,18,3,STONE:5)
Block(-3,18,4,STONE:5)
Block(-3,18,5,STONE:5)
Block(-3,18,6,STONE:5)
Block(-3,19,-1,STONE:5)
Block(-3,19,0,STONE:5)
Block(-3,19,1,STONE:5)
Block(-3,19,2,STONE:5)
Block(-3,19,3,STONE:5)
Block(-3,19,4,STONE:5)
Block(-3,19,5,STONE:5)
Block(-3,19,6,STONE:5)
Block(-3,20,-2,STONE:5)
Block(-3,20,-1,STONE:5)
Block(-3,20,0,STONE:5)
Block(-3,20,1,STONE:5)
Block(-3,20,2,STONE:5)
Block(-3,20,3,STONE:5)
Block(-3,20,4,STONE:5)
Block(-3,20,5,STONE:5)
Block(-3,20,6,STONE:5)
Block(-3,20,7,STONE:5)
Block(-3,21,-1,STONE:5)
Block(-3,21,0,STONE:5)
Block(-3,21,1,STONE:5)
Block(-3,21,2,STONE:5)
Block(-3,21,3,STONE:5)
Block(-3,21,4,STONE:5)
Block(-3,21,5,STONE:5)
Block(-3,21,6,STONE:5)
Block(-3,21,7,STONE:5)
Block(-3,22,-2,STONE:5)
Block(-3,22,-1,STONE:5)
Block(-3,22,0,STONE:5)
Block(-3,22,1,STONE:5)
Block(-3,22,2,STONE:5)
Block(-3,22,3,STONE:5)
Block(-3,22,4,STONE:5)
Block(-3,22,5,STONE:5)
Block(-3,22,6,STONE:5)
Block(-3,22,7,STONE:5)
Block(-3,22,8,STONE:5)
Block(-3,23,-1,STONE:0)
Block(-3,23,0,STONE:0)
Block(-3,23,1,STONE:0)
Block(-3,23,2,STONE:0)
Block(-3,23,3,STONE:0)
Block(-3,23,4,STONE:0)
Block(-3,23,5,STONE:0)
Block(-3,23,6,STONE:0)
Block(-3,23,7,STONE:0)
Block(-3,23,8,STONE:0)
Block(-3,24,-1,STONE:0)
Block(-3,24,0,STONE:0)
Block(-3,24,1,STONE:0)
Block(-3,24,2,STONE:0)
Block(-3,24,3,STONE:0)
Block(-3,24,4,STONE:0)
Block(-3,24,5,STONE:0)
Block(-3,24,6,STONE:0)
Block(-3,24,7,STONE:0)
Block(-3,24,8,STONE:0)
Block(-3,25,0,STONE:0)
Block(-3,25,1,STONE:0)
Block(-3,25,2,STONE:0)
Block(-3,25,3,STONE:0)
Block(-3,25,4,STONE:0)
Block(-3,25,5,STONE:0)
Block(-3,25,6,STONE:0)
Block(-3,25,7,STONE:0)
Block(-3,25,8,STONE:0)
Block(-3,26,5,STONE:0)
Block(-3,26,6,STONE:0)
Block(-3,26,7,STONE:0)
Block(-3,26,8,STONE:0)
Block(-3,27,6,STONE:0)
Block(-3,27,7,STONE:0)
Block(-3,27,8,STONE:0)
Block(-3,28,6,STONE:0)
Block(-3,28,7,STONE:0)
Block(-3,28,8,STONE:0)
Block(-2,8,7,STONE:0)
Block(-2,8,8,STONE:0)
Block(-2,9,5,STONE:0)
Block(-2,9,6,STONE:0)
Block(-2,9,7,STONE:0)
Block(-2,9,8,STONE:0)
Block(-2,10,5,STONE:0)
Block(-2,10,6,STONE:0)
Block(-2,10,7,STONE:0)
Block(-2,10,8,STONE:0)
Block(-2,11,4,STONE:0)
Block(-2,11,5,STONE:0)
Block(-2,11,6,STONE:0)
Block(-2,11,7,STONE:0)
Block(-2,11,8,STONE:0)
Block(-2,12,4,STONE:0)
Block(-2,12,5,STONE:0)
Block(-2,12,6,STONE:0)
Block(-2,12,7,STONE:0)
Block(-2,13,3,STONE:0)
Block(-2,13,4,STONE:0)
Block(-2,13,5,STONE:0)
Block(-2,13,6,STONE:0)
Block(-2,13,7,STONE:0)
Block(-2,14,3,STONE:0)
Block(-2,14,4,STONE:0)
Block(-2,14,5,STONE:0)
Block(-2,14,6,STONE:0)
Block(-2,14,7,STONE:0)
Block(-2,15,3,STONE:0)
Block(-2,15,4,STONE:0)
Block(-2,15,5,STONE:0)
Block(-2,15,6,STONE:0)
Block(-2,15,7,STONE:0)
Block(-2,16,2,STONE:0)
Block(-2,16,3,STONE:0)
Block(-2,16,4,STONE:0)
Block(-2,16,5,STONE:0)
Block(-2,16,6,STONE:0)
RandomBlock(-2,17,1,STONE:5,50,STONE:0,100)
RandomBlock(-2,17,2,STONE:5,50,STONE:0,100)
RandomBlock(-2,17,3,STONE:5,50,STONE:0,100)
RandomBlock(-2,17,4,STONE:5,50,STONE:0,100)
RandomBlock(-2,17,5,STONE:5,50,STONE:0,100)
RandomBlock(-2,17,6,STONE:5,50,STONE:0,100)
Block(-2,18,1,STONE:5)
Block(-2,18,2,STONE:5)
Block(-2,18,3,STONE:5)
Block(-2,18,4,STONE:5)
Block(-2,18,5,STONE:5)
Block(-2,18,6,STONE:5)
Block(-2,18,7,STONE:5)
Block(-2,19,0,STONE:5)
Block(-2,19,1,STONE:5)
Block(-2,19,2,STONE:5)
Block(-2,19,3,STONE:5)
Block(-2,19,4,STONE:5)
Block(-2,19,5,STONE:5)
Block(-2,19,6,STONE:5)
Block(-2,19,7,STONE:5)
Block(-2,20,-1,STONE:5)
Block(-2,20,0,STONE:5)
Block(-2,20,1,STONE:5)
Block(-2,20,2,STONE:5)
Block(-2,20,3,STONE:5)
Block(-2,20,4,STONE:5)
Block(-2,20,5,STONE:5)
Block(-2,20,6,STONE:5)
Block(-2,20,7,STONE:5)
Block(-2,21,-1,STONE:5)
Block(-2,21,0,STONE:5)
Block(-2,21,1,STONE:5)
Block(-2,21,2,STONE:5)
Block(-2,21,3,STONE:5)
Block(-2,21,4,STONE:5)
Block(-2,21,5,STONE:5)
Block(-2,21,6,STONE:5)
Block(-2,21,7,STONE:5)
Block(-2,21,8,STONE:5)
Block(-2,22,-1,STONE:5)
Block(-2,22,0,STONE:5)
Block(-2,22,1,STONE:5)
Block(-2,22,2,STONE:5)
Block(-2,22,3,STONE:5)
Block(-2,22,4,STONE:5)
Block(-2,22,5,STONE:5)
Block(-2,22,6,STONE:5)
Block(-2,22,7,STONE:5)
Block(-2,22,8,STONE:5)
Block(-2,23,0,STONE:0)
Block(-2,23,1,STONE:0)
Block(-2,23,2,STONE:0)
Block(-2,23,3,STONE:0)
Block(-2,23,4,STONE:0)
Block(-2,23,5,STONE:0)
Block(-2,23,6,STONE:0)
Block(-2,23,7,STONE:0)
Block(-2,23,8,STONE:0)
Block(-2,24,1,STONE:0)
Block(-2,24,2,STONE:0)
Block(-2,24,3,STONE:0)
Block(-2,24,4,STONE:0)
Block(-2,24,5,STONE:0)
Block(-2,24,6,STONE:0)
Block(-2,24,7,STONE:0)
Block(-2,24,8,STONE:0)
Block(-2,25,2,STONE:0)
Block(-2,25,3,STONE:0)
Block(-2,25,4,STONE:0)
Block(-2,25,5,STONE:0)
Block(-2,25,6,STONE:0)
Block(-2,25,7,STONE:0)
Block(-2,25,8,STONE:0)
Block(-2,26,4,STONE:0)
Block(-2,26,5,STONE:0)
Block(-2,26,6,STONE:0)
Block(-2,26,7,STONE:0)
Block(-2,26,8,STONE:0)
Block(-2,27,5,STONE:0)
Block(-2,27,6,STONE:0)
Block(-2,27,7,STONE:0)
Block(-2,27,8,STONE:0)
Block(-2,28,7,STONE:0)
Block(-1,7,8,STONE:0)
Block(-1,8,8,STONE:0)
Block(-1,9,6,STONE:0)
Block(-1,9,7,STONE:0)
Block(-1,9,8,STONE:0)
Block(-1,10,5,STONE:0)
Block(-1,10,6,STONE:0)
Block(-1,10,7,STONE:0)
Block(-1,10,8,STONE:0)
Block(-1,11,5,STONE:0)
Block(-1,11,6,STONE:0)
Block(-1,11,7,STONE:0)
Block(-1,11,8,STONE:0)
Block(-1,12,4,STONE:0)
Block(-1,12,5,STONE:0)
Block(-1,12,6,STONE:0)
Block(-1,12,7,STONE:0)
Block(-1,13,4,STONE:0)
Block(-1,13,5,STONE:0)
Block(-1,13,6,STONE:0)
Block(-1,13,7,STONE:0)
Block(-1,14,3,STONE:0)
Block(-1,14,4,STONE:0)
Block(-1,14,5,STONE:0)
Block(-1,14,6,STONE:0)
Block(-1,14,7,STONE:0)
Block(-1,15,2,STONE:0)
Block(-1,15,3,STONE:0)
Block(-1,15,4,STONE:0)
Block(-1,15,5,STONE:0)
Block(-1,15,6,STONE:0)
Block(-1,15,7,STONE:0)
Block(-1,16,1,STONE:0)
Block(-1,16,2,STONE:0)
Block(-1,16,3,STONE:0)
Block(-1,16,4,STONE:0)
Block(-1,16,5,STONE:0)
Block(-1,16,6,STONE:0)
Block(-1,16,7,STONE:0)
RandomBlock(-1,17,1,STONE:5,50,STONE:0,100)
RandomBlock(-1,17,2,STONE:5,50,STONE:0,100)
RandomBlock(-1,17,3,STONE:5,50,STONE:0,100)
RandomBlock(-1,17,4,STONE:5,50,STONE:0,100)
RandomBlock(-1,17,5,STONE:5,50,STONE:0,100)
RandomBlock(-1,17,6,STONE:5,50,STONE:0,100)
RandomBlock(-1,17,7,STONE:5,50,STONE:0,100)
Block(-1,18,1,STONE:5)
Block(-1,18,2,STONE:5)
Block(-1,18,3,STONE:5)
Block(-1,18,4,STONE:5)
Block(-1,18,5,STONE:5)
Block(-1,18,6,STONE:5)
Block(-1,18,7,STONE:5)
Block(-1,19,0,STONE:5)
Block(-1,19,1,STONE:5)
Block(-1,19,2,STONE:5)
Block(-1,19,3,STONE:5)
Block(-1,19,4,STONE:5)
Block(-1,19,5,STONE:5)
Block(-1,19,6,STONE:5)
Block(-1,19,7,STONE:5)
Block(-1,19,8,STONE:5)
Block(-1,20,0,STONE:5)
Block(-1,20,1,STONE:5)
Block(-1,20,2,STONE:5)
Block(-1,20,3,STONE:5)
Block(-1,20,4,STONE:5)
Block(-1,20,5,STONE:5)
Block(-1,20,6,STONE:5)
Block(-1,20,7,STONE:5)
Block(-1,20,8,STONE:5)
Block(-1,21,-1,STONE:5)
Block(-1,21,0,STONE:5)
Block(-1,21,1,STONE:5)
Block(-1,21,2,STONE:5)
Block(-1,21,3,STONE:5)
Block(-1,21,4,STONE:5)
Block(-1,21,5,STONE:5)
Block(-1,21,6,STONE:5)
Block(-1,21,7,STONE:5)
Block(-1,21,8,STONE:5)
Block(-1,22,-1,STONE:5)
Block(-1,22,0,STONE:5)
Block(-1,22,1,STONE:5)
Block(-1,22,2,STONE:5)
Block(-1,22,3,STONE:5)
Block(-1,22,4,STONE:5)
Block(-1,22,5,STONE:5)
Block(-1,22,6,STONE:5)
Block(-1,22,7,STONE:5)
Block(-1,22,8,STONE:5)
Block(-1,23,0,STONE:0)
Block(-1,23,1,STONE:0)
Block(-1,23,2,STONE:0)
Block(-1,23,3,STONE:0)
Block(-1,23,4,STONE:0)
Block(-1,23,5,STONE:0)
Block(-1,23,6,STONE:0)
Block(-1,23,7,STONE:0)
Block(-1,23,8,STONE:0)
Block(-1,24,2,STONE:0)
Block(-1,24,3,STONE:0)
Block(-1,24,4,STONE:0)
Block(-1,24,5,STONE:0)
Block(-1,24,6,STONE:0)
Block(-1,24,7,STONE:0)
Block(-1,24,8,STONE:0)
Block(-1,25,3,STONE:0)
Block(-1,25,4,STONE:0)
Block(-1,25,5,STONE:0)
Block(-1,25,6,STONE:0)
Block(-1,25,7,STONE:0)
Block(-1,25,8,STONE:0)
Block(-1,26,4,STONE:0)
Block(-1,26,5,STONE:0)
Block(-1,26,6,STONE:0)
Block(-1,26,7,STONE:0)
Block(-1,26,8,STONE:0)
Block(-1,27,5,STONE:0)
Block(-1,27,6,STONE:0)
Block(-1,27,7,STONE:0)
Block(-1,27,8,STONE:0)
Block(0,8,7,STONE:0)
Block(0,8,8,STONE:0)
Block(0,9,7,STONE:0)
Block(0,9,8,STONE:0)
Block(0,10,6,STONE:0)
Block(0,10,7,STONE:0)
Block(0,10,8,STONE:0)
Block(0,11,5,STONE:0)
Block(0,11,6,STONE:0)
Block(0,11,7,STONE:0)
Block(0,11,8,STONE:0)
Block(0,12,5,STONE:0)
Block(0,12,6,STONE:0)
Block(0,12,7,STONE:0)
Block(0,13,4,STONE:0)
Block(0,13,5,STONE:0)
Block(0,13,6,STONE:0)
Block(0,13,7,STONE:0)
Block(0,14,3,STONE:0)
Block(0,14,4,STONE:0)
Block(0,14,5,STONE:0)
Block(0,14,6,STONE:0)
Block(0,14,7,STONE:0)
Block(0,15,3,STONE:0)
Block(0,15,4,STONE:0)
Block(0,15,5,STONE:0)
Block(0,15,6,STONE:0)
Block(0,15,7,STONE:0)
Block(0,16,2,STONE:0)
Block(0,16,3,STONE:0)
Block(0,16,4,STONE:0)
Block(0,16,5,STONE:0)
Block(0,16,6,STONE:0)
Block(0,16,7,STONE:0)
RandomBlock(0,17,1,STONE:5,50,STONE:0,100)
RandomBlock(0,17,2,STONE:5,50,STONE:0,100)
RandomBlock(0,17,3,STONE:5,50,STONE:0,100)
RandomBlock(0,17,4,STONE:5,50,STONE:0,100)
RandomBlock(0,17,5,STONE:5,50,STONE:0,100)
RandomBlock(0,17,6,STONE:5,50,STONE:0,100)
RandomBlock(0,17,7,STONE:5,50,STONE:0,100)
Block(0,18,0,STONE:5)
Block(0,18,1,STONE:5)
Block(0,18,2,STONE:5)
Block(0,18,3,STONE:5)
Block(0,18,4,STONE:5)
Block(0,18,5,STONE:5)
Block(0,18,6,STONE:5)
Block(0,18,7,STONE:5)
Block(0,18,8,STONE:5)
Block(0,19,0,STONE:5)
Block(0,19,1,STONE:5)
Block(0,19,2,STONE:5)
Block(0,19,3,STONE:5)
Block(0,19,4,STONE:5)
Block(0,19,5,STONE:5)
Block(0,19,6,STONE:5)
Block(0,19,7,STONE:5)
Block(0,19,8,STONE:5)
Block(0,20,0,STONE:5)
Block(0,20,1,STONE:5)
Block(0,20,2,STONE:5)
Block(0,20,3,STONE:5)
Block(0,20,4,STONE:5)
Block(0,20,5,STONE:5)
Block(0,20,6,STONE:5)
Block(0,20,7,STONE:5)
Block(0,20,8,STONE:5)
Block(0,21,0,STONE:5)
Block(0,21,1,STONE:5)
Block(0,21,2,STONE:5)
Block(0,21,3,STONE:5)
Block(0,21,4,STONE:5)
Block(0,21,5,STONE:5)
Block(0,21,6,STONE:5)
Block(0,21,7,STONE:5)
Block(0,21,8,STONE:5)
Block(0,22,0,STONE:5)
Block(0,22,1,STONE:5)
Block(0,22,2,STONE:5)
Block(0,22,3,STONE:5)
Block(0,22,4,STONE:5)
Block(0,22,5,STONE:5)
Block(0,22,6,STONE:5)
Block(0,22,7,STONE:5)
Block(0,22,8,STONE:5)
Block(0,23,1,STONE:0)
Block(0,23,2,STONE:0)
Block(0,23,3,STONE:0)
Block(0,23,4,STONE:0)
Block(0,23,5,STONE:0)
Block(0,23,6,STONE:0)
Block(0,23,7,STONE:0)
Block(0,23,8,STONE:0)
Block(0,24,2,STONE:0)
Block(0,24,3,STONE:0)
Block(0,24,4,STONE:0)
Block(0,24,5,STONE:0)
Block(0,24,6,STONE:0)
Block(0,24,7,STONE:0)
Block(0,24,8,STONE:0)
Block(0,25,4,STONE:0)
Block(0,25,5,STONE:0)
Block(0,25,6,STONE:0)
Block(0,25,7,STONE:0)
Block(0,25,8,STONE:0)
Block(0,26,7,STONE:0)
Block(0,26,8,STONE:0)
Block(0,27,7,STONE:0)
Block(0,27,8,STONE:0)
Block(1,7,8,STONE:0)
Block(1,8,7,STONE:0)
Block(1,8,8,STONE:0)
Block(1,9,6,STONE:0)
Block(1,9,7,STONE:0)
Block(1,9,8,STONE:0)
Block(1,10,6,STONE:0)
Block(1,10,7,STONE:0)
Block(1,10,8,STONE:0)
Block(1,11,6,STONE:0)
Block(1,11,7,STONE:0)
Block(1,11,8,STONE:0)
Block(1,12,6,STONE:0)
Block(1,12,7,STONE:0)
Block(1,12,8,STONE:0)
Block(1,13,5,STONE:0)
Block(1,13,6,STONE:0)
Block(1,13,7,STONE:0)
Block(1,14,4,STONE:0)
Block(1,14,5,STONE:0)
Block(1,14,6,STONE:0)
Block(1,14,7,STONE:0)
Block(1,15,3,STONE:0)
Block(1,15,4,STONE:0)
Block(1,15,5,STONE:0)
Block(1,15,6,STONE:0)
Block(1,15,7,STONE:0)
Block(1,16,3,STONE:0)
Block(1,16,4,STONE:0)
Block(1,16,5,STONE:0)
Block(1,16,6,STONE:0)
Block(1,16,7,STONE:0)
RandomBlock(1,17,2,STONE:5,50,STONE:0,100)
RandomBlock(1,17,3,STONE:5,50,STONE:0,100)
RandomBlock(1,17,4,STONE:5,50,STONE:0,100)
RandomBlock(1,17,5,STONE:5,50,STONE:0,100)
RandomBlock(1,17,6,STONE:5,50,STONE:0,100)
RandomBlock(1,17,7,STONE:5,50,STONE:0,100)
Block(1,18,1,STONE:5)
Block(1,18,2,STONE:5)
Block(1,18,3,STONE:5)
Block(1,18,4,STONE:5)
Block(1,18,5,STONE:5)
Block(1,18,6,STONE:5)
Block(1,18,7,STONE:5)
Block(1,18,8,STONE:5)
Block(1,19,0,STONE:5)
Block(1,19,1,STONE:5)
Block(1,19,2,STONE:5)
Block(1,19,3,STONE:5)
Block(1,19,4,STONE:5)
Block(1,19,5,STONE:5)
Block(1,19,6,STONE:5)
Block(1,19,7,STONE:5)
Block(1,19,8,STONE:5)
Block(1,20,0,STONE:5)
Block(1,20,1,STONE:5)
Block(1,20,2,STONE:5)
Block(1,20,3,STONE:5)
Block(1,20,4,STONE:5)
Block(1,20,5,STONE:5)
Block(1,20,6,STONE:5)
Block(1,20,7,STONE:5)
Block(1,20,8,STONE:5)
Block(1,21,1,STONE:5)
Block(1,21,2,STONE:5)
Block(1,21,3,STONE:5)
Block(1,21,4,STONE:5)
Block(1,21,5,STONE:5)
Block(1,21,6,STONE:5)
Block(1,21,7,STONE:5)
Block(1,21,8,STONE:5)
Block(1,22,1,STONE:5)
Block(1,22,2,STONE:5)
Block(1,22,3,STONE:5)
Block(1,22,4,STONE:5)
Block(1,22,5,STONE:5)
Block(1,22,6,STONE:5)
Block(1,22,7,STONE:5)
Block(1,22,8,STONE:5)
Block(1,23,3,STONE:0)
Block(1,23,4,STONE:0)
Block(1,23,5,STONE:0)
Block(1,23,6,STONE:0)
Block(1,23,7,STONE:0)
Block(1,23,8,STONE:0)
Block(1,24,2,STONE:0)
Block(1,24,4,STONE:0)
Block(1,24,5,STONE:0)
Block(1,24,6,STONE:0)
Block(1,24,7,STONE:0)
Block(1,24,8,STONE:0)
Block(1,25,6,STONE:0)
Block(1,25,7,STONE:0)
Block(1,25,8,STONE:0)
Block(1,26,8,STONE:0)
Block(2,8,7,STONE:0)
Block(2,8,8,STONE:0)
Block(2,9,7,STONE:0)
Block(2,9,8,STONE:0)
Block(2,10,6,STONE:0)
Block(2,10,7,STONE:0)
Block(2,10,8,STONE:0)
Block(2,11,6,STONE:0)
Block(2,11,7,STONE:0)
Block(2,11,8,STONE:0)
Block(2,12,5,STONE:0)
Block(2,12,6,STONE:0)
Block(2,12,7,STONE:0)
Block(2,12,8,STONE:0)
Block(2,13,5,STONE:0)
Block(2,13,6,STONE:0)
Block(2,13,7,STONE:0)
Block(2,13,8,STONE:0)
Block(2,14,4,STONE:0)
Block(2,14,5,STONE:0)
Block(2,14,6,STONE:0)
Block(2,14,7,STONE:0)
Block(2,15,4,STONE:0)
Block(2,15,5,STONE:0)
Block(2,15,6,STONE:0)
Block(2,15,7,STONE:0)
Block(2,16,3,STONE:0)
Block(2,16,4,STONE:0)
Block(2,16,5,STONE:0)
Block(2,16,6,STONE:0)
Block(2,16,7,STONE:0)
RandomBlock(2,17,3,STONE:5,50,STONE:0,100)
RandomBlock(2,17,4,STONE:5,50,STONE:0,100)
RandomBlock(2,17,5,STONE:5,50,STONE:0,100)
RandomBlock(2,17,6,STONE:5,50,STONE:0,100)
RandomBlock(2,17,7,STONE:5,50,STONE:0,100)
RandomBlock(2,17,8,STONE:5,50,STONE:0,100)
Block(2,18,2,STONE:5)
Block(2,18,3,STONE:5)
Block(2,18,4,STONE:5)
Block(2,18,5,STONE:5)
Block(2,18,6,STONE:5)
Block(2,18,7,STONE:5)
Block(2,18,8,STONE:5)
Block(2,19,1,STONE:5)
Block(2,19,2,STONE:5)
Block(2,19,3,STONE:5)
Block(2,19,4,STONE:5)
Block(2,19,5,STONE:5)
Block(2,19,6,STONE:5)
Block(2,19,7,STONE:5)
Block(2,19,8,STONE:5)
Block(2,20,1,STONE:5)
Block(2,20,2,STONE:5)
Block(2,20,3,STONE:5)
Block(2,20,4,STONE:5)
Block(2,20,5,STONE:5)
Block(2,20,6,STONE:5)
Block(2,20,7,STONE:5)
Block(2,20,8,STONE:5)
Block(2,21,1,STONE:5)
Block(2,21,2,STONE:5)
Block(2,21,3,STONE:5)
Block(2,21,4,STONE:5)
Block(2,21,5,STONE:5)
Block(2,21,6,STONE:5)
Block(2,21,7,STONE:5)
Block(2,21,8,STONE:5)
Block(2,22,2,STONE:5)
Block(2,22,3,STONE:5)
Block(2,22,4,STONE:5)
Block(2,22,5,STONE:5)
Block(2,22,6,STONE:5)
Block(2,22,7,STONE:5)
Block(2,22,8,STONE:5)
Block(2,23,4,STONE:0)
Block(2,23,5,STONE:0)
Block(2,23,6,STONE:0)
Block(2,23,7,STONE:0)
Block(2,23,8,STONE:0)
Block(2,24,6,STONE:0)
Block(2,24,7,STONE:0)
Block(2,24,8,STONE:0)
Block(2,25,7,STONE:0)
Block(2,25,8,STONE:0)
Block(3,8,8,STONE:0)
Block(3,9,7,STONE:0)
Block(3,9,8,STONE:0)
Block(3,10,7,STONE:0)
Block(3,10,8,STONE:0)
Block(3,11,6,STONE:0)
Block(3,11,7,STONE:0)
Block(3,11,8,STONE:0)
Block(3,12,5,STONE:0)
Block(3,12,6,STONE:0)
Block(3,12,7,STONE:0)
Block(3,12,8,STONE:0)
Block(3,13,4,STONE:0)
Block(3,13,5,STONE:0)
Block(3,13,6,STONE:0)
Block(3,13,7,STONE:0)
Block(3,13,8,STONE:0)
Block(3,14,4,STONE:0)
Block(3,14,5,STONE:0)
Block(3,14,6,STONE:0)
Block(3,14,7,STONE:0)
Block(3,14,8,STONE:0)
Block(3,15,4,STONE:0)
Block(3,15,5,STONE:0)
Block(3,15,6,STONE:0)
Block(3,15,7,STONE:0)
Block(3,15,8,STONE:0)
Block(3,16,3,STONE:0)
Block(3,16,4,STONE:0)
Block(3,16,5,STONE:0)
Block(3,16,6,STONE:0)
Block(3,16,7,STONE:0)
Block(3,16,8,STONE:0)
RandomBlock(3,17,3,STONE:5,50,STONE:0,100)
RandomBlock(3,17,4,STONE:5,50,STONE:0,100)
RandomBlock(3,17,5,STONE:5,50,STONE:0,100)
RandomBlock(3,17,6,STONE:5,50,STONE:0,100)
RandomBlock(3,17,7,STONE:5,50,STONE:0,100)
RandomBlock(3,17,8,STONE:5,50,STONE:0,100)
Block(3,18,2,STONE:5)
Block(3,18,3,STONE:5)
Block(3,18,4,STONE:5)
Block(3,18,5,STONE:5)
Block(3,18,6,STONE:5)
Block(3,18,7,STONE:5)
Block(3,18,8,STONE:5)
Block(3,19,2,STONE:5)
Block(3,19,3,STONE:5)
Block(3,19,4,STONE:5)
Block(3,19,5,STONE:5)
Block(3,19,6,STONE:5)
Block(3,19,7,STONE:5)
Block(3,19,8,STONE:5)
Block(3,20,2,STONE:5)
Block(3,20,3,STONE:5)
Block(3,20,4,STONE:5)
Block(3,20,5,STONE:5)
Block(3,20,6,STONE:5)
Block(3,20,7,STONE:5)
Block(3,20,8,STONE:5)
Block(3,21,3,STONE:5)
Block(3,21,4,STONE:5)
Block(3,21,5,STONE:5)
Block(3,21,6,STONE:5)
Block(3,21,7,STONE:5)
Block(3,21,8,STONE:5)
Block(3,22,4,STONE:5)
Block(3,22,5,STONE:5)
Block(3,22,6,STONE:5)
Block(3,22,7,STONE:5)
Block(3,22,8,STONE:5)
Block(3,23,3,STONE:0)
Block(3,23,4,STONE:0)
Block(3,23,5,STONE:0)
Block(3,23,6,STONE:0)
Block(3,23,7,STONE:0)
Block(3,23,8,STONE:0)
Block(3,24,7,STONE:0)
Block(3,24,8,STONE:0)
Block(4,9,8,STONE:0)
Block(4,10,7,STONE:0)
Block(4,10,8,STONE:0)
Block(4,11,7,STONE:0)
Block(4,11,8,STONE:0)
Block(4,12,5,STONE:0)
Block(4,12,6,STONE:0)
Block(4,12,7,STONE:0)
Block(4,12,8,STONE:0)
Block(4,13,5,STONE:0)
Block(4,13,6,STONE:0)
Block(4,13,7,STONE:0)
Block(4,13,8,STONE:0)
Block(4,14,4,STONE:0)
Block(4,14,5,STONE:0)
Block(4,14,6,STONE:0)
Block(4,14,7,STONE:0)
Block(4,14,8,STONE:0)
Block(4,15,4,STONE:0)
Block(4,15,5,STONE:0)
Block(4,15,6,STONE:0)
Block(4,15,7,STONE:0)
Block(4,15,8,STONE:0)
Block(4,16,4,STONE:0)
Block(4,16,5,STONE:0)
Block(4,16,6,STONE:0)
Block(4,16,7,STONE:0)
Block(4,16,8,STONE:0)
RandomBlock(4,17,3,STONE:5,50,STONE:0,100)
RandomBlock(4,17,4,STONE:5,50,STONE:0,100)
RandomBlock(4,17,5,STONE:5,50,STONE:0,100)
RandomBlock(4,17,6,STONE:5,50,STONE:0,100)
RandomBlock(4,17,7,STONE:5,50,STONE:0,100)
RandomBlock(4,17,8,STONE:5,50,STONE:0,100)
Block(4,18,3,STONE:5)
Block(4,18,4,STONE:5)
Block(4,18,5,STONE:5)
Block(4,18,6,STONE:5)
Block(4,18,7,STONE:5)
Block(4,18,8,STONE:5)
Block(4,19,2,STONE:5)
Block(4,19,3,STONE:5)
Block(4,19,4,STONE:5)
Block(4,19,5,STONE:5)
Block(4,19,6,STONE:5)
Block(4,19,7,STONE:5)
Block(4,19,8,STONE:5)
Block(4,20,3,STONE:5)
Block(4,20,4,STONE:5)
Block(4,20,5,STONE:5)
Block(4,20,6,STONE:5)
Block(4,20,7,STONE:5)
Block(4,20,8,STONE:5)
Block(4,21,4,STONE:5)
Block(4,21,5,STONE:5)
Block(4,21,6,STONE:5)
Block(4,21,7,STONE:5)
Block(4,21,8,STONE:5)
Block(4,22,5,STONE:5)
Block(4,22,6,STONE:5)
Block(4,22,7,STONE:5)
Block(4,22,8,STONE:5)
Block(4,23,7,STONE:0)
Block(4,23,8,STONE:0)
Block(4,24,8,STONE:0)
Block(5,9,8,STONE:0)
Block(5,10,8,STONE:0)
Block(5,11,7,STONE:0)
Block(5,11,8,STONE:0)
Block(5,12,6,STONE:0)
Block(5,12,7,STONE:0)
Block(5,12,8,STONE:0)
Block(5,13,5,STONE:0)
Block(5,13,6,STONE:0)
Block(5,13,7,STONE:0)
Block(5,13,8,STONE:0)
Block(5,14,5,STONE:0)
Block(5,14,6,STONE:0)
Block(5,14,7,STONE:0)
Block(5,14,8,STONE:0)
Block(5,15,4,STONE:0)
Block(5,15,5,STONE:0)
Block(5,15,6,STONE:0)
Block(5,15,7,STONE:0)
Block(5,15,8,STONE:0)
Block(5,16,4,STONE:0)
Block(5,16,5,STONE:0)
Block(5,16,6,STONE:0)
Block(5,16,7,STONE:0)
Block(5,16,8,STONE:0)
RandomBlock(5,17,4,STONE:5,50,STONE:0,100)
RandomBlock(5,17,5,STONE:5,50,STONE:0,100)
RandomBlock(5,17,6,STONE:5,50,STONE:0,100)
RandomBlock(5,17,7,STONE:5,50,STONE:0,100)
RandomBlock(5,17,8,STONE:5,50,STONE:0,100)
Block(5,18,3,STONE:5)
Block(5,18,4,STONE:5)
Block(5,18,5,STONE:5)
Block(5,18,6,STONE:5)
Block(5,18,7,STONE:5)
Block(5,18,8,STONE:5)
Block(5,19,3,STONE:5)
Block(5,19,4,STONE:5)
Block(5,19,5,STONE:5)
Block(5,19,6,STONE:5)
Block(5,19,7,STONE:5)
Block(5,19,8,STONE:5)
Block(5,20,4,STONE:5)
Block(5,20,5,STONE:5)
Block(5,20,6,STONE:5)
Block(5,20,7,STONE:5)
Block(5,20,8,STONE:5)
Block(5,21,6,STONE:5)
Block(5,21,7,STONE:5)
Block(5,21,8,STONE:5)
Block(5,22,7,STONE:5)
Block(5,22,8,STONE:5)
Block(5,23,7,STONE:0)
Block(5,23,8,STONE:0)
Block(5,24,8,STONE:0)
Block(6,8,8,STONE:0)
Block(6,9,8,STONE:0)
Block(6,10,7,STONE:0)
Block(6,10,8,STONE:0)
Block(6,11,7,STONE:0)
Block(6,11,8,STONE:0)
Block(6,12,7,STONE:0)
Block(6,12,8,STONE:0)
Block(6,13,6,STONE:0)
Block(6,13,7,STONE:0)
Block(6,13,8,STONE:0)
Block(6,14,5,STONE:0)
Block(6,14,6,STONE:0)
Block(6,14,7,STONE:0)
Block(6,14,8,STONE:0)
Block(6,15,4,STONE:0)
Block(6,15,5,STONE:0)
Block(6,15,6,STONE:0)
Block(6,15,7,STONE:0)
Block(6,15,8,STONE:0)
Block(6,16,4,STONE:0)
Block(6,16,5,STONE:0)
Block(6,16,6,STONE:0)
Block(6,16,7,STONE:0)
Block(6,16,8,STONE:0)
RandomBlock(6,17,4,STONE:5,50,STONE:0,100)
RandomBlock(6,17,5,STONE:5,50,STONE:0,100)
RandomBlock(6,17,6,STONE:5,50,STONE:0,100)
RandomBlock(6,17,7,STONE:5,50,STONE:0,100)
RandomBlock(6,17,8,STONE:5,50,STONE:0,100)
Block(6,18,5,STONE:5)
Block(6,18,6,STONE:5)
Block(6,18,7,STONE:5)
Block(6,18,8,STONE:5)
Block(6,19,5,STONE:5)
Block(6,19,6,STONE:5)
Block(6,19,7,STONE:5)
Block(6,19,8,STONE:5)
Block(6,20,6,STONE:5)
Block(6,20,7,STONE:5)
Block(6,20,8,STONE:5)
Block(6,21,6,STONE:5)
Block(6,21,7,STONE:5)
Block(6,21,8,STONE:5)
Block(6,22,8,STONE:5)
Block(6,23,8,STONE:0)
Block(7,8,8,STONE:0)
Block(7,9,7,STONE:0)
Block(7,9,8,STONE:0)
Block(7,10,7,STONE:0)
Block(7,10,8,STONE:0)
Block(7,11,7,STONE:0)
Block(7,11,8,STONE:0)
Block(7,12,7,STONE:0)
Block(7,12,8,STONE:0)
Block(7,13,7,STONE:0)
Block(7,13,8,STONE:0)
Block(7,14,6,STONE:0)
Block(7,14,7,STONE:0)
Block(7,14,8,STONE:0)
Block(7,15,5,STONE:0)
Block(7,15,6,STONE:0)
Block(7,15,7,STONE:0)
Block(7,15,8,STONE:0)
Block(7,16,5,STONE:0)
Block(7,16,6,STONE:0)
Block(7,16,7,STONE:0)
Block(7,16,8,STONE:0)
RandomBlock(7,17,5,STONE:5,50,STONE:0,100)
RandomBlock(7,17,6,STONE:5,50,STONE:0,100)
RandomBlock(7,17,7,STONE:5,50,STONE:0,100)
RandomBlock(7,17,8,STONE:5,50,STONE:0,100)
Block(7,18,6,STONE:5)
Block(7,18,7,STONE:5)
Block(7,18,8,STONE:5)
Block(7,19,6,STONE:5)
Block(7,19,7,STONE:5)
Block(7,19,8,STONE:5)
Block(7,20,6,STONE:5)
Block(7,20,7,STONE:5)
Block(7,20,8,STONE:5)
Block(7,21,7,STONE:5)
Block(7,21,8,STONE:5)

#######################################################################
# +-----------------------------------------------------------------+ #
# |                             Branches                            | #
# +-----------------------------------------------------------------+ #
#######################################################################

Branch(16,0,0,true,cyclops_branch_3C3R0,NORTH,100.0,0)

#######################################################################
# +-----------------------------------------------------------------+ #
# |                             Entities                            | #
# +-----------------------------------------------------------------+ #
#######################################################################


#######################################################################
# +-----------------------------------------------------------------+ #
# |                            Particles                            | #
# +-----------------------------------------------------------------+ #
#######################################################################


#######################################################################
# +-----------------------------------------------------------------+ #
# |                             Spawners                            | #
# +-----------------------------------------------------------------+ #
#######################################################################


#######################################################################
# +-----------------------------------------------------------------+ #
# |                             ModData                             | #
# +-----------------------------------------------------------------+ #
#######################################################################

