
#######################################################################
# +-----------------------------------------------------------------+ #
# |                            BO4 object                           | #
# +-----------------------------------------------------------------+ #
#######################################################################

Author: NLBlackEagle

Description: No description given

SettingsMode: WriteWithoutComments


#######################################################################
# +-----------------------------------------------------------------+ #
# |                          Main settings                          | #
# +-----------------------------------------------------------------+ #
#######################################################################

FixedRotation: 

Frequency: 0

SpawnHeight: highestBlock

UseCenterForHighestBlock: true

##############################
# Height Limits for the BO4. #
##############################

MinHeight: 0

MaxHeight: 255

InheritBO3: 

InheritBO3Rotation: NORTH

OverrideChildSettings: true

OverrideParentHeight: false

CanOverride: true

BranchFrequency: 0

BranchFrequencyGroup: 

MustBeBelowOther: false

MustBeInside: 

CannotBeInside: 

ReplacesBO3: 

MustBeInsideWorldBorders: false

CanSpawnOnWater: true

SpawnOnWaterOnly: false

SpawnUnderWater: false

SpawnAtWaterLevel: false

HeightOffset: 0

RemoveAir: false

ReplaceAbove: 

ReplaceBelow: 

ReplaceWithBiomeBlocks: true

ReplaceWithSurfaceBlock: GRASS

ReplaceWithGroundBlock: DIRT

ReplaceWithStoneBlock: STONE

SmoothRadius: 0

SmoothHeightOffset: 0

SmoothStartTop: false

SmoothStartWood: false

SmoothingSurfaceBlock: 

SmoothingGroundBlock: 

BO3Group: 

IsSpawnPoint: false

DoReplaceBlocks: true


#######################################################################
# +-----------------------------------------------------------------+ #
# |                              Blocks                             | #
# +-----------------------------------------------------------------+ #
#######################################################################

Block(-8,7,2,STONE:0)
Block(-8,7,3,STONE:0)
Block(-8,7,4,STONE:0)
Block(-8,7,5,STONE:0)
Block(-8,7,6,STONE:0)
Block(-8,7,7,STONE:0)
Block(-8,7,8,STONE:0)
Block(-8,8,1,STONE:0)
Block(-8,8,2,STONE:0)
Block(-8,8,3,STONE:0)
Block(-8,8,4,STONE:0)
Block(-8,8,5,STONE:0)
Block(-8,8,6,STONE:0)
Block(-8,8,7,STONE:0)
Block(-8,8,8,STONE:0)
Block(-8,9,0,STONE:0)
Block(-8,9,1,STONE:0)
Block(-8,9,2,STONE:0)
Block(-8,9,3,STONE:0)
Block(-8,9,4,STONE:0)
Block(-8,9,5,STONE:0)
Block(-8,9,6,STONE:0)
Block(-8,9,7,STONE:0)
Block(-8,9,8,STONE:0)
Block(-8,10,0,STONE:0)
Block(-8,10,1,STONE:0)
Block(-8,10,2,STONE:0)
Block(-8,10,3,STONE:0)
Block(-8,10,4,STONE:0)
Block(-8,10,5,STONE:0)
Block(-8,10,6,STONE:0)
Block(-8,10,7,STONE:0)
Block(-8,10,8,STONE:0)
Block(-8,11,0,STONE:0)
Block(-8,11,1,STONE:0)
Block(-8,11,2,STONE:0)
Block(-8,11,3,STONE:0)
Block(-8,11,4,STONE:0)
Block(-8,11,5,STONE:0)
Block(-8,11,6,STONE:0)
Block(-8,11,7,STONE:0)
Block(-8,11,8,STONE:0)
Block(-8,12,0,STONE:0)
Block(-8,12,1,STONE:0)
Block(-8,12,2,STONE:0)
Block(-8,12,3,STONE:0)
Block(-8,12,4,STONE:0)
Block(-8,12,5,STONE:0)
Block(-8,12,6,STONE:0)
Block(-8,12,7,STONE:0)
Block(-8,12,8,STONE:0)
Block(-8,13,1,STONE:0)
Block(-8,13,2,STONE:0)
Block(-8,13,3,STONE:0)
Block(-8,13,4,STONE:0)
Block(-8,13,5,STONE:0)
Block(-8,13,6,STONE:0)
Block(-8,13,7,STONE:0)
Block(-8,13,8,STONE:0)
Block(-8,14,1,STONE:0)
Block(-8,14,2,STONE:0)
Block(-8,14,3,STONE:0)
Block(-8,14,4,STONE:0)
Block(-8,14,5,STONE:0)
Block(-8,14,6,STONE:0)
Block(-8,14,7,STONE:0)
Block(-8,14,8,STONE:0)
Block(-8,15,1,STONE:0)
Block(-8,15,2,STONE:0)
Block(-8,15,3,STONE:0)
Block(-8,15,4,STONE:0)
Block(-8,15,5,STONE:0)
Block(-8,15,6,STONE:0)
Block(-8,15,7,STONE:0)
Block(-8,15,8,STONE:0)
Block(-8,16,1,STONE:0)
Block(-8,16,2,STONE:0)
Block(-8,16,3,STONE:0)
Block(-8,16,4,STONE:0)
Block(-8,16,5,STONE:0)
Block(-8,16,6,STONE:0)
Block(-8,16,7,STONE:0)
Block(-8,16,8,STONE:0)
RandomBlock(-8,17,2,STONE:5,50,STONE:0,100)
RandomBlock(-8,17,3,STONE:5,50,STONE:0,100)
RandomBlock(-8,17,4,STONE:5,50,STONE:0,100)
RandomBlock(-8,17,5,STONE:5,50,STONE:0,100)
RandomBlock(-8,17,6,STONE:5,50,STONE:0,100)
RandomBlock(-8,17,7,STONE:5,50,STONE:0,100)
RandomBlock(-8,17,8,STONE:5,50,STONE:0,100)
Block(-8,18,2,STONE:5)
Block(-8,18,3,STONE:5)
Block(-8,18,4,STONE:5)
Block(-8,18,5,STONE:5)
Block(-8,18,6,STONE:5)
Block(-8,19,3,STONE:5)
Block(-8,19,4,STONE:5)
Block(-8,19,5,STONE:5)
Block(-8,19,6,STONE:5)
Block(-7,7,2,STONE:0)
Block(-7,7,3,STONE:0)
Block(-7,7,4,STONE:0)
Block(-7,7,5,STONE:0)
Block(-7,7,6,STONE:0)
Block(-7,7,7,STONE:0)
Block(-7,7,8,STONE:0)
Block(-7,8,1,STONE:0)
Block(-7,8,2,STONE:0)
Block(-7,8,3,STONE:0)
Block(-7,8,4,STONE:0)
Block(-7,8,5,STONE:0)
Block(-7,8,6,STONE:0)
Block(-7,8,7,STONE:0)
Block(-7,8,8,STONE:0)
Block(-7,9,0,STONE:0)
Block(-7,9,1,STONE:0)
Block(-7,9,2,STONE:0)
Block(-7,9,3,STONE:0)
Block(-7,9,4,STONE:0)
Block(-7,9,5,STONE:0)
Block(-7,9,6,STONE:0)
Block(-7,9,7,STONE:0)
Block(-7,9,8,STONE:0)
Block(-7,10,0,STONE:0)
Block(-7,10,1,STONE:0)
Block(-7,10,2,STONE:0)
Block(-7,10,3,STONE:0)
Block(-7,10,4,STONE:0)
Block(-7,10,5,STONE:0)
Block(-7,10,6,STONE:0)
Block(-7,10,7,STONE:0)
Block(-7,10,8,STONE:0)
Block(-7,11,0,STONE:0)
Block(-7,11,1,STONE:0)
Block(-7,11,2,STONE:0)
Block(-7,11,3,STONE:0)
Block(-7,11,4,STONE:0)
Block(-7,11,5,STONE:0)
Block(-7,11,6,STONE:0)
Block(-7,11,7,STONE:0)
Block(-7,11,8,STONE:0)
Block(-7,12,0,STONE:0)
Block(-7,12,1,STONE:0)
Block(-7,12,2,STONE:0)
Block(-7,12,3,STONE:0)
Block(-7,12,4,STONE:0)
Block(-7,12,5,STONE:0)
Block(-7,12,6,STONE:0)
Block(-7,12,7,STONE:0)
Block(-7,12,8,STONE:0)
Block(-7,13,1,STONE:0)
Block(-7,13,2,STONE:0)
Block(-7,13,3,STONE:0)
Block(-7,13,4,STONE:0)
Block(-7,13,5,STONE:0)
Block(-7,13,6,STONE:0)
Block(-7,13,7,STONE:0)
Block(-7,13,8,STONE:0)
Block(-7,14,1,STONE:0)
Block(-7,14,2,STONE:0)
Block(-7,14,3,STONE:0)
Block(-7,14,4,STONE:0)
Block(-7,14,5,STONE:0)
Block(-7,14,6,STONE:0)
Block(-7,14,7,STONE:0)
Block(-7,14,8,STONE:0)
Block(-7,15,1,STONE:0)
Block(-7,15,2,STONE:0)
Block(-7,15,3,STONE:0)
Block(-7,15,4,STONE:0)
Block(-7,15,5,STONE:0)
Block(-7,15,6,STONE:0)
Block(-7,15,7,STONE:0)
Block(-7,15,8,STONE:0)
Block(-7,16,1,STONE:0)
Block(-7,16,2,STONE:0)
Block(-7,16,3,STONE:0)
Block(-7,16,4,STONE:0)
Block(-7,16,5,STONE:0)
Block(-7,16,6,STONE:0)
Block(-7,16,7,STONE:0)
Block(-7,16,8,STONE:0)
RandomBlock(-7,17,2,STONE:5,50,STONE:0,100)
RandomBlock(-7,17,3,STONE:5,50,STONE:0,100)
RandomBlock(-7,17,4,STONE:5,50,STONE:0,100)
RandomBlock(-7,17,5,STONE:5,50,STONE:0,100)
RandomBlock(-7,17,6,STONE:5,50,STONE:0,100)
RandomBlock(-7,17,7,STONE:5,50,STONE:0,100)
Block(-7,18,2,STONE:5)
Block(-7,18,3,STONE:5)
Block(-7,18,4,STONE:5)
Block(-7,18,5,STONE:5)
Block(-7,18,6,STONE:5)
Block(-7,19,4,STONE:5)
Block(-7,19,5,STONE:5)
Block(-6,7,3,STONE:0)
Block(-6,7,4,STONE:0)
Block(-6,7,5,STONE:0)
Block(-6,7,6,STONE:0)
Block(-6,7,7,STONE:0)
Block(-6,8,2,STONE:0)
Block(-6,8,3,STONE:0)
Block(-6,8,4,STONE:0)
Block(-6,8,5,STONE:0)
Block(-6,8,6,STONE:0)
Block(-6,8,7,STONE:0)
Block(-6,8,8,STONE:0)
Block(-6,9,0,STONE:0)
Block(-6,9,1,STONE:0)
Block(-6,9,2,STONE:0)
Block(-6,9,3,STONE:0)
Block(-6,9,4,STONE:0)
Block(-6,9,5,STONE:0)
Block(-6,9,6,STONE:0)
Block(-6,9,7,STONE:0)
Block(-6,9,8,STONE:0)
Block(-6,10,0,STONE:0)
Block(-6,10,1,STONE:0)
Block(-6,10,2,STONE:0)
Block(-6,10,3,STONE:0)
Block(-6,10,4,STONE:0)
Block(-6,10,5,STONE:0)
Block(-6,10,6,STONE:0)
Block(-6,10,7,STONE:0)
Block(-6,10,8,STONE:0)
Block(-6,11,0,STONE:0)
Block(-6,11,1,STONE:0)
Block(-6,11,2,STONE:0)
Block(-6,11,3,STONE:0)
Block(-6,11,4,STONE:0)
Block(-6,11,5,STONE:0)
Block(-6,11,6,STONE:0)
Block(-6,11,7,STONE:0)
Block(-6,11,8,STONE:0)
Block(-6,12,0,STONE:0)
Block(-6,12,1,STONE:0)
Block(-6,12,2,STONE:0)
Block(-6,12,3,STONE:0)
Block(-6,12,4,STONE:0)
Block(-6,12,5,STONE:0)
Block(-6,12,6,STONE:0)
Block(-6,12,7,STONE:0)
Block(-6,12,8,STONE:0)
Block(-6,13,1,STONE:0)
Block(-6,13,2,STONE:0)
Block(-6,13,3,STONE:0)
Block(-6,13,4,STONE:0)
Block(-6,13,5,STONE:0)
Block(-6,13,6,STONE:0)
Block(-6,13,7,STONE:0)
Block(-6,13,8,STONE:0)
Block(-6,14,1,STONE:0)
Block(-6,14,2,STONE:0)
Block(-6,14,3,STONE:0)
Block(-6,14,4,STONE:0)
Block(-6,14,5,STONE:0)
Block(-6,14,6,STONE:0)
Block(-6,14,7,STONE:0)
Block(-6,14,8,STONE:0)
Block(-6,15,1,STONE:0)
Block(-6,15,2,STONE:0)
Block(-6,15,3,STONE:0)
Block(-6,15,4,STONE:0)
Block(-6,15,5,STONE:0)
Block(-6,15,6,STONE:0)
Block(-6,15,7,STONE:0)
Block(-6,15,8,STONE:0)
Block(-6,16,2,STONE:0)
Block(-6,16,3,STONE:0)
Block(-6,16,4,STONE:0)
Block(-6,16,5,STONE:0)
Block(-6,16,6,STONE:0)
Block(-6,16,7,STONE:0)
RandomBlock(-6,17,3,STONE:5,50,STONE:0,100)
RandomBlock(-6,17,4,STONE:5,50,STONE:0,100)
RandomBlock(-6,17,5,STONE:5,50,STONE:0,100)
RandomBlock(-6,17,6,STONE:5,50,STONE:0,100)
Block(-5,7,4,STONE:0)
Block(-5,7,5,STONE:0)
Block(-5,8,3,STONE:0)
Block(-5,8,4,STONE:0)
Block(-5,8,5,STONE:0)
Block(-5,8,6,STONE:0)
Block(-5,8,7,STONE:0)
Block(-5,8,8,STONE:0)
Block(-5,9,0,STONE:0)
Block(-5,9,1,STONE:0)
Block(-5,9,2,STONE:0)
Block(-5,9,3,STONE:0)
Block(-5,9,4,STONE:0)
Block(-5,9,5,STONE:0)
Block(-5,9,6,STONE:0)
Block(-5,9,7,STONE:0)
Block(-5,9,8,STONE:0)
Block(-5,10,0,STONE:0)
Block(-5,10,1,STONE:0)
Block(-5,10,2,STONE:0)
Block(-5,10,3,STONE:0)
Block(-5,10,4,STONE:0)
Block(-5,10,5,STONE:0)
Block(-5,10,6,STONE:0)
Block(-5,10,7,STONE:0)
Block(-5,10,8,STONE:0)
Block(-5,11,0,STONE:0)
Block(-5,11,1,STONE:0)
Block(-5,11,2,STONE:0)
Block(-5,11,3,STONE:0)
Block(-5,11,4,STONE:0)
Block(-5,11,5,STONE:0)
Block(-5,11,6,STONE:0)
Block(-5,11,7,STONE:0)
Block(-5,11,8,STONE:0)
Block(-5,12,0,STONE:0)
Block(-5,12,1,STONE:0)
Block(-5,12,2,STONE:0)
Block(-5,12,3,STONE:0)
Block(-5,12,4,STONE:0)
Block(-5,12,5,STONE:0)
Block(-5,12,6,STONE:0)
Block(-5,12,7,STONE:0)
Block(-5,12,8,STONE:0)
Block(-5,13,1,STONE:0)
Block(-5,13,2,STONE:0)
Block(-5,13,3,STONE:0)
Block(-5,13,4,STONE:0)
Block(-5,13,5,STONE:0)
Block(-5,13,6,STONE:0)
Block(-5,13,7,STONE:0)
Block(-5,13,8,STONE:0)
Block(-5,14,2,STONE:0)
Block(-5,14,3,STONE:0)
Block(-5,14,4,STONE:0)
Block(-5,14,5,STONE:0)
Block(-5,14,6,STONE:0)
Block(-5,14,7,STONE:0)
Block(-5,14,8,STONE:0)
Block(-5,15,2,STONE:0)
Block(-5,15,3,STONE:0)
Block(-5,15,4,STONE:0)
Block(-5,15,5,STONE:0)
Block(-5,15,6,STONE:0)
Block(-5,15,7,STONE:0)
Block(-5,16,3,STONE:0)
Block(-5,16,4,STONE:0)
Block(-5,16,5,STONE:0)
Block(-5,16,6,STONE:0)
Block(-4,8,4,STONE:0)
Block(-4,8,5,STONE:0)
Block(-4,9,1,STONE:0)
Block(-4,9,2,STONE:0)
Block(-4,9,3,STONE:0)
Block(-4,9,4,STONE:0)
Block(-4,9,5,STONE:0)
Block(-4,9,6,STONE:0)
Block(-4,9,7,STONE:0)
Block(-4,9,8,STONE:0)
Block(-4,10,1,STONE:0)
Block(-4,10,2,STONE:0)
Block(-4,10,3,STONE:0)
Block(-4,10,4,STONE:0)
Block(-4,10,5,STONE:0)
Block(-4,10,6,STONE:0)
Block(-4,10,7,STONE:0)
Block(-4,10,8,STONE:0)
Block(-4,11,0,STONE:0)
Block(-4,11,1,STONE:0)
Block(-4,11,2,STONE:0)
Block(-4,11,3,STONE:0)
Block(-4,11,4,STONE:0)
Block(-4,11,5,STONE:0)
Block(-4,11,6,STONE:0)
Block(-4,11,7,STONE:0)
Block(-4,11,8,STONE:0)
Block(-4,12,1,STONE:0)
Block(-4,12,2,STONE:0)
Block(-4,12,3,STONE:0)
Block(-4,12,4,STONE:0)
Block(-4,12,5,STONE:0)
Block(-4,12,6,STONE:0)
Block(-4,12,7,STONE:0)
Block(-4,12,8,STONE:0)
Block(-4,13,2,STONE:0)
Block(-4,13,3,STONE:0)
Block(-4,13,4,STONE:0)
Block(-4,13,5,STONE:0)
Block(-4,13,6,STONE:0)
Block(-4,13,7,STONE:0)
Block(-4,13,8,STONE:0)
Block(-4,14,4,STONE:0)
Block(-4,14,5,STONE:0)
Block(-4,14,6,STONE:0)
Block(-4,14,7,STONE:0)
Block(-4,14,8,STONE:0)
Block(-3,9,3,STONE:0)
Block(-3,9,4,STONE:0)
Block(-3,10,3,STONE:0)
Block(-3,10,4,STONE:0)
Block(-3,10,5,STONE:0)
Block(-3,10,6,STONE:0)
Block(-3,11,2,STONE:0)
Block(-3,11,3,STONE:0)
Block(-3,11,4,STONE:0)
Block(-3,11,5,STONE:0)
Block(-3,11,6,STONE:0)
Block(-3,11,7,STONE:0)
Block(-3,11,8,STONE:0)
Block(-3,12,2,STONE:0)
Block(-3,12,3,STONE:0)
Block(-3,12,4,STONE:0)
Block(-3,12,5,STONE:0)
Block(-3,12,6,STONE:0)
Block(-3,12,7,STONE:0)
Block(-3,12,8,STONE:0)
Block(-3,13,3,STONE:0)
Block(-3,13,4,STONE:0)
Block(-3,13,5,STONE:0)
Block(-3,13,6,STONE:0)
Block(-3,13,7,STONE:0)
Block(-3,13,8,STONE:0)
Block(-3,14,4,STONE:0)
Block(-3,14,5,STONE:0)
Block(-3,14,6,STONE:0)
Block(-2,11,4,STONE:0)
Block(-2,11,5,STONE:0)
Block(-2,11,6,STONE:0)
Block(-2,12,4,STONE:0)
Block(-2,12,5,STONE:0)
Block(-2,12,6,STONE:0)
Block(-2,13,4,STONE:0)
Block(-2,13,5,STONE:0)
Block(-2,13,6,STONE:0)
Block(-8,2,2,STONE:0)
Block(-8,2,3,STONE:0)
Block(-8,2,4,STONE:0)
Block(-8,2,6,STONE:0)
Block(-8,2,7,STONE:0)
Block(-8,3,0,STONE:0)
Block(-8,3,1,STONE:0)
Block(-8,3,2,STONE:0)
Block(-8,3,3,STONE:0)
Block(-8,3,4,STONE:0)
Block(-8,3,5,STONE:0)
Block(-8,3,6,STONE:0)
Block(-8,3,7,STONE:0)
Block(-8,3,8,STONE:0)
Block(-8,4,0,STONE:0)
Block(-8,4,1,STONE:0)
Block(-8,4,2,STONE:0)
Block(-8,4,3,STONE:0)
Block(-8,4,4,MOSSY_COBBLESTONE:0)
Block(-8,4,5,MOSSY_COBBLESTONE:0)
Block(-8,4,6,MOSSY_COBBLESTONE:0)
Block(-8,4,7,MOSSY_COBBLESTONE:0)
Block(-8,4,8,MOSSY_COBBLESTONE:0)
Block(-8,5,-1,STONE:0)
Block(-8,5,0,MOSSY_COBBLESTONE:0)
Block(-8,5,1,MOSSY_COBBLESTONE:0)
Block(-8,5,2,MOSSY_COBBLESTONE:0)
Block(-8,5,3,MOSSY_COBBLESTONE:0)
Block(-8,5,4,MOSSY_COBBLESTONE:0)
Block(-8,5,5,MOSSY_COBBLESTONE:0)
Block(-8,5,6,MOSSY_COBBLESTONE:0)
Block(-8,5,7,MOSSY_COBBLESTONE:0)
Block(-8,5,8,MOSSY_COBBLESTONE:0)
Block(-8,6,-1,MOSSY_COBBLESTONE:0)
Block(-8,6,0,MOSSY_COBBLESTONE:0)
Block(-8,6,1,MOSSY_COBBLESTONE:0)
Block(-8,6,2,MOSSY_COBBLESTONE:0)
Block(-8,6,3,MOSSY_COBBLESTONE:0)
Block(-8,6,4,MOSSY_COBBLESTONE:0)
Block(-8,6,5,MOSSY_COBBLESTONE:0)
Block(-8,6,6,MOSSY_COBBLESTONE:0)
Block(-8,6,7,MOSSY_COBBLESTONE:0)
Block(-8,6,8,MOSSY_COBBLESTONE:0)
Block(-8,7,-1,MOSSY_COBBLESTONE:0)
Block(-8,7,0,MOSSY_COBBLESTONE:0)
Block(-8,7,1,MOSSY_COBBLESTONE:0)
Block(-8,8,-1,MOSSY_COBBLESTONE:0)
Block(-8,8,0,MOSSY_COBBLESTONE:0)
Block(-8,9,-2,STONE:0)
Block(-8,9,-1,STONE:0)
Block(-8,10,-3,STONE:0)
Block(-8,10,-2,STONE:0)
Block(-8,10,-1,STONE:0)
Block(-8,11,-4,STONE:0)
Block(-8,11,-3,STONE:0)
Block(-8,11,-2,STONE:0)
Block(-8,11,-1,STONE:0)
Block(-8,12,-4,STONE:0)
Block(-8,12,-3,STONE:0)
Block(-8,12,-2,STONE:0)
Block(-8,12,-1,MOSSY_COBBLESTONE:0)
Block(-8,13,-4,STONE:0)
Block(-8,13,-3,STONE:0)
Block(-8,13,-2,MOSSY_COBBLESTONE:0)
Block(-8,13,-1,MOSSY_COBBLESTONE:0)
Block(-8,13,0,MOSSY_COBBLESTONE:0)
Block(-8,14,-5,STONE:0)
Block(-8,14,-4,STONE:0)
Block(-8,14,-3,STONE:0)
Block(-8,14,-2,MOSSY_COBBLESTONE:0)
Block(-8,14,-1,MOSSY_COBBLESTONE:0)
Block(-8,14,0,MOSSY_COBBLESTONE:0)
Block(-8,15,-5,STONE:0)
Block(-8,15,-4,STONE:0)
Block(-8,15,-3,STONE:0)
Block(-8,15,-2,MOSSY_COBBLESTONE:0)
Block(-8,15,-1,MOSSY_COBBLESTONE:0)
Block(-8,15,0,MOSSY_COBBLESTONE:0)
Block(-8,16,-6,STONE:0)
Block(-8,16,-5,STONE:0)
Block(-8,16,-4,STONE:0)
Block(-8,16,-3,STONE:0)
Block(-8,16,-2,STONE:0)
Block(-8,16,-1,MOSSY_COBBLESTONE:0)
Block(-8,16,0,MOSSY_COBBLESTONE:0)
RandomBlock(-8,17,-6,STONE:5,50,STONE:0,100)
RandomBlock(-8,17,-5,STONE:5,50,STONE:0,100)
RandomBlock(-8,17,-4,STONE:5,50,STONE:0,100)
RandomBlock(-8,17,-3,STONE:5,50,STONE:0,100)
RandomBlock(-8,17,-2,STONE:5,50,STONE:0,100)
RandomBlock(-8,17,-1,STONE:5,50,STONE:0,100)
Block(-8,17,0,MOSSY_COBBLESTONE:0)
Block(-8,17,1,MOSSY_COBBLESTONE:0)
Block(-8,18,-5,STONE:5)
Block(-8,18,-4,STONE:5)
Block(-8,18,-3,STONE:5)
Block(-8,18,-2,STONE:5)
Block(-8,18,-1,STONE:5)
Block(-8,18,0,MOSSY_COBBLESTONE:0)
Block(-8,18,1,MOSSY_COBBLESTONE:0)
Block(-8,18,7,STONE:5)
Block(-8,18,8,STONE:5)
Block(-8,19,-4,STONE:5)
Block(-8,19,-3,STONE:5)
Block(-8,19,-2,STONE:5)
Block(-8,19,-1,STONE:5)
Block(-8,19,0,STONE:5)
Block(-8,19,1,STONE:5)
Block(-8,19,2,STONE:5)
Block(-8,19,7,STONE:5)
Block(-8,19,8,STONE:5)
Block(-8,20,-1,STONE:5)
Block(-8,20,0,STONE:5)
Block(-8,20,1,STONE:5)
Block(-8,20,2,STONE:5)
Block(-8,20,3,STONE:5)
Block(-8,20,4,STONE:5)
Block(-8,20,5,STONE:5)
Block(-8,20,6,STONE:5)
Block(-8,20,7,STONE:5)
Block(-8,20,8,STONE:5)
Block(-8,21,0,STONE:5)
Block(-8,21,1,STONE:5)
Block(-8,21,2,STONE:5)
Block(-8,21,3,STONE:5)
Block(-8,21,4,STONE:5)
Block(-8,21,5,STONE:5)
Block(-8,21,6,STONE:5)
Block(-8,21,7,STONE:5)
Block(-8,21,8,STONE:5)
Block(-8,22,1,STONE:5)
Block(-8,22,2,STONE:5)
Block(-8,22,3,STONE:5)
Block(-8,22,4,STONE:5)
Block(-8,22,5,STONE:5)
Block(-8,22,6,STONE:5)
Block(-8,22,7,STONE:5)
Block(-8,22,8,STONE:5)
Block(-8,23,1,STONE:0)
Block(-8,23,2,STONE:0)
Block(-8,23,3,STONE:0)
Block(-8,23,4,STONE:0)
Block(-8,23,5,STONE:0)
Block(-8,23,6,STONE:0)
Block(-8,23,7,STONE:0)
Block(-8,23,8,STONE:0)
Block(-8,24,3,STONE:0)
Block(-8,24,4,STONE:0)
Block(-8,24,5,STONE:0)
Block(-8,24,6,STONE:0)
Block(-8,24,7,STONE:0)
Block(-7,2,3,STONE:0)
Block(-7,2,6,STONE:0)
Block(-7,2,7,STONE:0)
Block(-7,2,8,STONE:0)
Block(-7,3,1,STONE:0)
Block(-7,3,2,STONE:0)
Block(-7,3,3,STONE:0)
Block(-7,3,4,STONE:0)
Block(-7,3,5,STONE:0)
Block(-7,3,6,STONE:0)
Block(-7,3,7,STONE:0)
Block(-7,3,8,STONE:0)
Block(-7,4,0,STONE:0)
Block(-7,4,1,STONE:0)
Block(-7,4,2,STONE:0)
Block(-7,4,3,STONE:0)
Block(-7,4,4,MOSSY_COBBLESTONE:0)
Block(-7,4,5,MOSSY_COBBLESTONE:0)
Block(-7,4,6,MOSSY_COBBLESTONE:0)
Block(-7,4,7,MOSSY_COBBLESTONE:0)
Block(-7,4,8,MOSSY_COBBLESTONE:0)
Block(-7,5,0,MOSSY_COBBLESTONE:0)
Block(-7,5,1,MOSSY_COBBLESTONE:0)
Block(-7,5,2,MOSSY_COBBLESTONE:0)
Block(-7,5,3,MOSSY_COBBLESTONE:0)
Block(-7,5,4,MOSSY_COBBLESTONE:0)
Block(-7,5,5,MOSSY_COBBLESTONE:0)
Block(-7,5,6,MOSSY_COBBLESTONE:0)
Block(-7,5,7,MOSSY_COBBLESTONE:0)
Block(-7,5,8,MOSSY_COBBLESTONE:0)
Block(-7,6,-1,MOSSY_COBBLESTONE:0)
Block(-7,6,0,MOSSY_COBBLESTONE:0)
Block(-7,6,1,MOSSY_COBBLESTONE:0)
Block(-7,6,2,MOSSY_COBBLESTONE:0)
Block(-7,6,3,MOSSY_COBBLESTONE:0)
Block(-7,6,4,MOSSY_COBBLESTONE:0)
Block(-7,6,5,MOSSY_COBBLESTONE:0)
Block(-7,6,6,MOSSY_COBBLESTONE:0)
Block(-7,6,7,MOSSY_COBBLESTONE:0)
Block(-7,6,8,MOSSY_COBBLESTONE:0)
Block(-7,7,-2,STONE:0)
Block(-7,7,-1,MOSSY_COBBLESTONE:0)
Block(-7,7,0,MOSSY_COBBLESTONE:0)
Block(-7,7,1,MOSSY_COBBLESTONE:0)
Block(-7,8,-3,STONE:0)
Block(-7,8,-2,STONE:0)
Block(-7,8,-1,MOSSY_COBBLESTONE:0)
Block(-7,8,0,MOSSY_COBBLESTONE:0)
Block(-7,9,-3,STONE:0)
Block(-7,9,-2,STONE:0)
Block(-7,9,-1,STONE:0)
Block(-7,10,-4,STONE:0)
Block(-7,10,-3,STONE:0)
Block(-7,10,-2,STONE:0)
Block(-7,10,-1,STONE:0)
Block(-7,11,-4,STONE:0)
Block(-7,11,-3,STONE:0)
Block(-7,11,-2,STONE:0)
Block(-7,11,-1,STONE:0)
Block(-7,12,-4,STONE:0)
Block(-7,12,-3,STONE:0)
Block(-7,12,-2,STONE:0)
Block(-7,12,-1,MOSSY_COBBLESTONE:0)
Block(-7,13,-4,STONE:0)
Block(-7,13,-3,STONE:0)
Block(-7,13,-2,MOSSY_COBBLESTONE:0)
Block(-7,13,-1,MOSSY_COBBLESTONE:0)
Block(-7,13,0,MOSSY_COBBLESTONE:0)
Block(-7,14,-4,STONE:0)
Block(-7,14,-3,STONE:0)
Block(-7,14,-2,MOSSY_COBBLESTONE:0)
Block(-7,14,-1,MOSSY_COBBLESTONE:0)
Block(-7,14,0,MOSSY_COBBLESTONE:0)
Block(-7,15,-4,STONE:0)
Block(-7,15,-3,STONE:0)
Block(-7,15,-2,MOSSY_COBBLESTONE:0)
Block(-7,15,-1,MOSSY_COBBLESTONE:0)
Block(-7,15,0,MOSSY_COBBLESTONE:0)
Block(-7,16,-6,STONE:0)
Block(-7,16,-5,STONE:0)
Block(-7,16,-4,STONE:0)
Block(-7,16,-3,STONE:0)
Block(-7,16,-2,STONE:0)
Block(-7,16,-1,MOSSY_COBBLESTONE:0)
Block(-7,16,0,MOSSY_COBBLESTONE:0)
RandomBlock(-7,17,-6,STONE:5,50,STONE:0,100)
RandomBlock(-7,17,-5,STONE:5,50,STONE:0,100)
RandomBlock(-7,17,-4,STONE:5,50,STONE:0,100)
RandomBlock(-7,17,-3,STONE:5,50,STONE:0,100)
RandomBlock(-7,17,-2,STONE:5,50,STONE:0,100)
RandomBlock(-7,17,-1,STONE:5,50,STONE:0,100)
RandomBlock(-7,17,0,STONE:5,50,STONE:0,100)
RandomBlock(-7,17,1,STONE:5,50,STONE:0,100)
RandomBlock(-7,17,8,STONE:5,50,STONE:0,100)
Block(-7,18,-4,STONE:5)
Block(-7,18,-3,STONE:5)
Block(-7,18,-2,STONE:5)
Block(-7,18,-1,STONE:5)
Block(-7,18,0,STONE:5)
Block(-7,18,1,STONE:5)
Block(-7,18,7,STONE:5)
Block(-7,18,8,STONE:5)
Block(-7,19,-3,STONE:5)
Block(-7,19,-2,STONE:5)
Block(-7,19,-1,STONE:5)
Block(-7,19,0,STONE:5)
Block(-7,19,1,STONE:5)
Block(-7,19,2,STONE:5)
Block(-7,19,3,STONE:5)
Block(-7,19,6,STONE:5)
Block(-7,19,7,STONE:5)
Block(-7,19,8,STONE:5)
Block(-7,20,0,STONE:5)
Block(-7,20,1,STONE:5)
Block(-7,20,2,STONE:5)
Block(-7,20,3,STONE:5)
Block(-7,20,4,STONE:5)
Block(-7,20,5,STONE:5)
Block(-7,20,6,STONE:5)
Block(-7,20,7,STONE:5)
Block(-7,20,8,STONE:5)
Block(-7,21,1,STONE:5)
Block(-7,21,2,STONE:5)
Block(-7,21,3,STONE:5)
Block(-7,21,4,STONE:5)
Block(-7,21,5,STONE:5)
Block(-7,21,6,STONE:5)
Block(-7,21,7,STONE:5)
Block(-7,21,8,STONE:5)
Block(-7,22,1,STONE:5)
Block(-7,22,2,STONE:5)
Block(-7,22,3,STONE:5)
Block(-7,22,4,STONE:5)
Block(-7,22,5,STONE:5)
Block(-7,22,6,STONE:5)
Block(-7,22,7,STONE:5)
Block(-7,22,8,STONE:5)
Block(-7,23,2,STONE:0)
Block(-7,23,3,STONE:0)
Block(-7,23,4,STONE:0)
Block(-7,23,5,STONE:0)
Block(-7,23,6,STONE:0)
Block(-7,23,7,STONE:0)
Block(-7,23,8,STONE:0)
Block(-7,24,4,STONE:0)
Block(-7,24,6,STONE:0)
Block(-6,2,5,STONE:0)
Block(-6,2,6,STONE:0)
Block(-6,2,7,STONE:0)
Block(-6,2,8,STONE:0)
Block(-6,3,2,STONE:0)
Block(-6,3,3,STONE:0)
Block(-6,3,4,STONE:0)
Block(-6,3,5,STONE:0)
Block(-6,3,6,STONE:0)
Block(-6,3,7,STONE:0)
Block(-6,3,8,STONE:0)
Block(-6,4,1,STONE:0)
Block(-6,4,2,STONE:0)
Block(-6,4,3,STONE:0)
Block(-6,4,4,STONE:0)
Block(-6,4,5,STONE:0)
Block(-6,4,6,STONE:0)
Block(-6,4,7,STONE:0)
Block(-6,4,8,STONE:0)
Block(-6,5,-1,STONE:0)
Block(-6,5,0,STONE:0)
Block(-6,5,1,STONE:0)
Block(-6,5,2,MOSSY_COBBLESTONE:0)
Block(-6,5,3,MOSSY_COBBLESTONE:0)
Block(-6,5,4,MOSSY_COBBLESTONE:0)
Block(-6,5,5,MOSSY_COBBLESTONE:0)
Block(-6,5,6,MOSSY_COBBLESTONE:0)
Block(-6,5,7,MOSSY_COBBLESTONE:0)
Block(-6,5,8,MOSSY_COBBLESTONE:0)
Block(-6,6,-2,STONE:0)
Block(-6,6,-1,STONE:0)
Block(-6,6,0,MOSSY_COBBLESTONE:0)
Block(-6,6,1,MOSSY_COBBLESTONE:0)
Block(-6,6,2,MOSSY_COBBLESTONE:0)
Block(-6,6,3,MOSSY_COBBLESTONE:0)
Block(-6,6,4,MOSSY_COBBLESTONE:0)
Block(-6,6,5,MOSSY_COBBLESTONE:0)
Block(-6,6,6,MOSSY_COBBLESTONE:0)
Block(-6,6,7,MOSSY_COBBLESTONE:0)
Block(-6,6,8,MOSSY_COBBLESTONE:0)
Block(-6,7,-3,STONE:0)
Block(-6,7,-2,STONE:0)
Block(-6,7,-1,MOSSY_COBBLESTONE:0)
Block(-6,7,0,MOSSY_COBBLESTONE:0)
Block(-6,7,1,MOSSY_COBBLESTONE:0)
Block(-6,7,2,MOSSY_COBBLESTONE:0)
Block(-6,7,8,MOSSY_COBBLESTONE:0)
Block(-6,8,-3,STONE:0)
Block(-6,8,-2,STONE:0)
Block(-6,8,-1,MOSSY_COBBLESTONE:0)
Block(-6,8,0,MOSSY_COBBLESTONE:0)
Block(-6,8,1,MOSSY_COBBLESTONE:0)
Block(-6,9,-3,STONE:0)
Block(-6,9,-2,STONE:0)
Block(-6,9,-1,MOSSY_COBBLESTONE:0)
Block(-6,10,-4,STONE:0)
Block(-6,10,-3,STONE:0)
Block(-6,10,-2,STONE:0)
Block(-6,10,-1,STONE:0)
Block(-6,11,-4,STONE:0)
Block(-6,11,-3,STONE:0)
Block(-6,11,-2,STONE:0)
Block(-6,11,-1,STONE:0)
Block(-6,12,-4,STONE:0)
Block(-6,12,-3,STONE:0)
Block(-6,12,-2,STONE:0)
Block(-6,12,-1,STONE:0)
Block(-6,13,-4,STONE:0)
Block(-6,13,-3,STONE:0)
Block(-6,13,-2,STONE:0)
Block(-6,13,-1,MOSSY_COBBLESTONE:0)
Block(-6,13,0,MOSSY_COBBLESTONE:0)
Block(-6,14,-4,STONE:0)
Block(-6,14,-3,STONE:0)
Block(-6,14,-2,STONE:0)
Block(-6,14,-1,MOSSY_COBBLESTONE:0)
Block(-6,14,0,MOSSY_COBBLESTONE:0)
Block(-6,15,-4,STONE:0)
Block(-6,15,-3,STONE:0)
Block(-6,15,-2,STONE:0)
Block(-6,15,-1,MOSSY_COBBLESTONE:0)
Block(-6,15,0,MOSSY_COBBLESTONE:0)
Block(-6,16,-6,STONE:0)
Block(-6,16,-5,STONE:0)
Block(-6,16,-4,STONE:0)
Block(-6,16,-3,STONE:0)
Block(-6,16,-2,STONE:0)
Block(-6,16,-1,STONE:0)
Block(-6,16,0,STONE:0)
Block(-6,16,1,STONE:0)
Block(-6,16,8,STONE:0)
RandomBlock(-6,17,-6,STONE:5,50,STONE:0,100)
RandomBlock(-6,17,-5,STONE:5,50,STONE:0,100)
RandomBlock(-6,17,-4,STONE:5,50,STONE:0,100)
RandomBlock(-6,17,-3,STONE:5,50,STONE:0,100)
RandomBlock(-6,17,-2,STONE:5,50,STONE:0,100)
RandomBlock(-6,17,-1,STONE:5,50,STONE:0,100)
RandomBlock(-6,17,0,STONE:5,50,STONE:0,100)
RandomBlock(-6,17,1,STONE:5,50,STONE:0,100)
RandomBlock(-6,17,2,STONE:5,50,STONE:0,100)
RandomBlock(-6,17,7,STONE:5,50,STONE:0,100)
RandomBlock(-6,17,8,STONE:5,50,STONE:0,100)
Block(-6,18,-5,STONE:5)
Block(-6,18,-4,STONE:5)
Block(-6,18,-3,STONE:5)
Block(-6,18,-2,STONE:5)
Block(-6,18,-1,STONE:5)
Block(-6,18,0,STONE:5)
Block(-6,18,1,STONE:5)
Block(-6,18,2,STONE:5)
Block(-6,18,3,STONE:5)
Block(-6,18,4,STONE:5)
Block(-6,18,5,STONE:5)
Block(-6,18,6,STONE:5)
Block(-6,18,7,STONE:5)
Block(-6,18,8,STONE:5)
Block(-6,19,-3,STONE:5)
Block(-6,19,-2,STONE:5)
Block(-6,19,-1,STONE:5)
Block(-6,19,0,STONE:5)
Block(-6,19,1,STONE:5)
Block(-6,19,2,STONE:5)
Block(-6,19,3,STONE:5)
Block(-6,19,4,STONE:5)
Block(-6,19,5,STONE:5)
Block(-6,19,6,STONE:5)
Block(-6,19,7,STONE:5)
Block(-6,19,8,STONE:5)
Block(-6,20,-2,STONE:5)
Block(-6,20,-1,STONE:5)
Block(-6,20,0,STONE:5)
Block(-6,20,1,STONE:5)
Block(-6,20,2,STONE:5)
Block(-6,20,3,STONE:5)
Block(-6,20,4,STONE:5)
Block(-6,20,5,STONE:5)
Block(-6,20,6,STONE:5)
Block(-6,20,7,STONE:5)
Block(-6,20,8,STONE:5)
Block(-6,21,1,STONE:5)
Block(-6,21,2,STONE:5)
Block(-6,21,3,STONE:5)
Block(-6,21,4,STONE:5)
Block(-6,21,5,STONE:5)
Block(-6,21,6,STONE:5)
Block(-6,21,7,STONE:5)
Block(-6,21,8,STONE:5)
Block(-6,22,2,STONE:5)
Block(-6,22,3,STONE:5)
Block(-6,22,4,STONE:5)
Block(-6,22,5,STONE:5)
Block(-6,22,6,STONE:5)
Block(-6,22,7,STONE:5)
Block(-6,22,8,STONE:5)
Block(-6,23,3,STONE:0)
Block(-6,23,4,STONE:0)
Block(-6,23,5,STONE:0)
Block(-6,23,6,STONE:0)
Block(-6,23,7,STONE:0)
Block(-5,2,6,STONE:0)
Block(-5,2,7,STONE:0)
Block(-5,2,8,STONE:0)
Block(-5,3,4,STONE:0)
Block(-5,3,5,STONE:0)
Block(-5,3,6,STONE:0)
Block(-5,3,7,STONE:0)
Block(-5,3,8,STONE:0)
Block(-5,4,0,STONE:0)
Block(-5,4,1,STONE:0)
Block(-5,4,2,STONE:0)
Block(-5,4,3,STONE:0)
Block(-5,4,4,STONE:0)
Block(-5,4,5,STONE:0)
Block(-5,4,6,STONE:0)
Block(-5,4,7,STONE:0)
Block(-5,4,8,STONE:0)
Block(-5,5,-1,STONE:0)
Block(-5,5,0,STONE:0)
Block(-5,5,1,STONE:0)
Block(-5,5,2,MOSSY_COBBLESTONE:0)
Block(-5,5,3,MOSSY_COBBLESTONE:0)
Block(-5,5,4,MOSSY_COBBLESTONE:0)
Block(-5,5,5,MOSSY_COBBLESTONE:0)
Block(-5,5,6,MOSSY_COBBLESTONE:0)
Block(-5,5,7,MOSSY_COBBLESTONE:0)
Block(-5,5,8,MOSSY_COBBLESTONE:0)
Block(-5,6,-3,STONE:0)
Block(-5,6,-2,STONE:0)
Block(-5,6,-1,STONE:0)
Block(-5,6,0,MOSSY_COBBLESTONE:0)
Block(-5,6,1,MOSSY_COBBLESTONE:0)
Block(-5,6,2,MOSSY_COBBLESTONE:0)
Block(-5,6,3,MOSSY_COBBLESTONE:0)
Block(-5,6,4,MOSSY_COBBLESTONE:0)
Block(-5,6,5,MOSSY_COBBLESTONE:0)
Block(-5,6,6,MOSSY_COBBLESTONE:0)
Block(-5,6,7,MOSSY_COBBLESTONE:0)
Block(-5,6,8,MOSSY_COBBLESTONE:0)
Block(-5,7,-3,STONE:0)
Block(-5,7,-2,STONE:0)
Block(-5,7,-1,MOSSY_COBBLESTONE:0)
Block(-5,7,0,MOSSY_COBBLESTONE:0)
Block(-5,7,1,MOSSY_COBBLESTONE:0)
Block(-5,7,2,MOSSY_COBBLESTONE:0)
Block(-5,7,3,MOSSY_COBBLESTONE:0)
Block(-5,7,6,MOSSY_COBBLESTONE:0)
Block(-5,7,7,MOSSY_COBBLESTONE:0)
Block(-5,7,8,MOSSY_COBBLESTONE:0)
Block(-5,8,-4,STONE:0)
Block(-5,8,-3,STONE:0)
Block(-5,8,-2,STONE:0)
Block(-5,8,-1,MOSSY_COBBLESTONE:0)
Block(-5,8,0,MOSSY_COBBLESTONE:0)
Block(-5,8,1,MOSSY_COBBLESTONE:0)
Block(-5,8,2,MOSSY_COBBLESTONE:0)
Block(-5,9,-4,STONE:0)
Block(-5,9,-3,STONE:0)
Block(-5,9,-2,STONE:0)
Block(-5,9,-1,MOSSY_COBBLESTONE:0)
Block(-5,10,-3,STONE:0)
Block(-5,10,-2,STONE:0)
Block(-5,10,-1,STONE:0)
Block(-5,11,-3,STONE:0)
Block(-5,11,-2,STONE:0)
Block(-5,11,-1,STONE:0)
Block(-5,12,-3,STONE:0)
Block(-5,12,-2,STONE:0)
Block(-5,12,-1,STONE:0)
Block(-5,13,-3,STONE:0)
Block(-5,13,-2,STONE:0)
Block(-5,13,-1,STONE:0)
Block(-5,13,0,STONE:0)
Block(-5,14,-3,STONE:0)
Block(-5,14,-2,STONE:0)
Block(-5,14,-1,STONE:0)
Block(-5,14,0,STONE:0)
Block(-5,14,1,STONE:0)
Block(-5,15,-3,STONE:0)
Block(-5,15,-2,STONE:0)
Block(-5,15,-1,STONE:0)
Block(-5,15,0,STONE:0)
Block(-5,15,1,STONE:0)
Block(-5,15,8,STONE:0)
Block(-5,16,-5,STONE:0)
Block(-5,16,-4,STONE:0)
Block(-5,16,-3,STONE:0)
Block(-5,16,-2,STONE:0)
Block(-5,16,-1,STONE:0)
Block(-5,16,0,STONE:0)
Block(-5,16,1,STONE:0)
Block(-5,16,2,MOSSY_COBBLESTONE:0)
Block(-5,16,7,STONE:0)
Block(-5,16,8,STONE:0)
RandomBlock(-5,17,-5,STONE:5,50,STONE:0,100)
RandomBlock(-5,17,-4,STONE:5,50,STONE:0,100)
RandomBlock(-5,17,-3,STONE:5,50,STONE:0,100)
RandomBlock(-5,17,-2,STONE:5,50,STONE:0,100)
RandomBlock(-5,17,-1,STONE:5,50,STONE:0,100)
RandomBlock(-5,17,0,STONE:5,50,STONE:0,100)
RandomBlock(-5,17,1,STONE:5,50,STONE:0,100)
RandomBlock(-5,17,2,STONE:5,50,STONE:0,100)
Block(-5,17,3,MOSSY_COBBLESTONE:0)
Block(-5,17,4,MOSSY_COBBLESTONE:0)
Block(-5,17,5,MOSSY_COBBLESTONE:0)
RandomBlock(-5,17,6,STONE:5,50,STONE:0,100)
RandomBlock(-5,17,7,STONE:5,50,STONE:0,100)
RandomBlock(-5,17,8,STONE:5,50,STONE:0,100)
Block(-5,18,-5,STONE:5)
Block(-5,18,-4,STONE:5)
Block(-5,18,-3,STONE:5)
Block(-5,18,-2,STONE:5)
Block(-5,18,-1,STONE:5)
Block(-5,18,0,STONE:5)
Block(-5,18,1,STONE:5)
Block(-5,18,2,STONE:5)
Block(-5,18,3,STONE:5)
Block(-5,18,4,STONE:5)
Block(-5,18,5,STONE:5)
Block(-5,18,6,STONE:5)
Block(-5,18,7,STONE:5)
Block(-5,18,8,STONE:5)
Block(-5,19,-3,STONE:5)
Block(-5,19,-2,STONE:5)
Block(-5,19,-1,STONE:5)
Block(-5,19,0,STONE:5)
Block(-5,19,1,STONE:5)
Block(-5,19,2,STONE:5)
Block(-5,19,3,STONE:5)
Block(-5,19,4,STONE:5)
Block(-5,19,5,STONE:5)
Block(-5,19,6,STONE:5)
Block(-5,19,7,STONE:5)
Block(-5,19,8,STONE:5)
Block(-5,20,-1,STONE:5)
Block(-5,20,0,STONE:5)
Block(-5,20,1,STONE:5)
Block(-5,20,2,STONE:5)
Block(-5,20,3,STONE:5)
Block(-5,20,4,STONE:5)
Block(-5,20,5,STONE:5)
Block(-5,20,6,STONE:5)
Block(-5,20,7,STONE:5)
Block(-5,20,8,STONE:5)
Block(-5,21,1,STONE:5)
Block(-5,21,2,STONE:5)
Block(-5,21,3,STONE:5)
Block(-5,21,4,STONE:5)
Block(-5,21,5,STONE:5)
Block(-5,21,6,STONE:5)
Block(-5,21,7,STONE:5)
Block(-5,21,8,STONE:5)
Block(-5,22,3,STONE:5)
Block(-5,22,4,STONE:5)
Block(-5,22,5,STONE:5)
Block(-5,22,6,STONE:5)
Block(-5,22,8,STONE:5)
Block(-4,2,7,STONE:0)
Block(-4,3,5,STONE:0)
Block(-4,3,6,STONE:0)
Block(-4,3,7,STONE:0)
Block(-4,3,8,STONE:0)
Block(-4,4,1,STONE:0)
Block(-4,4,2,STONE:0)
Block(-4,4,3,STONE:0)
Block(-4,4,4,STONE:0)
Block(-4,4,5,STONE:0)
Block(-4,4,6,STONE:0)
Block(-4,4,7,STONE:0)
Block(-4,4,8,STONE:0)
Block(-4,5,-2,STONE:0)
Block(-4,5,-1,STONE:0)
Block(-4,5,0,STONE:0)
Block(-4,5,1,STONE:0)
Block(-4,5,2,MOSSY_COBBLESTONE:0)
Block(-4,5,3,MOSSY_COBBLESTONE:0)
Block(-4,5,4,MOSSY_COBBLESTONE:0)
Block(-4,5,5,MOSSY_COBBLESTONE:0)
Block(-4,5,6,MOSSY_COBBLESTONE:0)
Block(-4,5,7,STONE:0)
Block(-4,5,8,STONE:0)
Block(-4,6,-3,STONE:0)
Block(-4,6,-2,STONE:0)
Block(-4,6,-1,STONE:0)
Block(-4,6,0,MOSSY_COBBLESTONE:0)
Block(-4,6,1,MOSSY_COBBLESTONE:0)
Block(-4,6,2,MOSSY_COBBLESTONE:0)
Block(-4,6,3,MOSSY_COBBLESTONE:0)
Block(-4,6,4,MOSSY_COBBLESTONE:0)
Block(-4,6,5,MOSSY_COBBLESTONE:0)
Block(-4,6,6,MOSSY_COBBLESTONE:0)
Block(-4,6,7,MOSSY_COBBLESTONE:0)
Block(-4,6,8,MOSSY_COBBLESTONE:0)
Block(-4,7,-4,STONE:0)
Block(-4,7,-3,STONE:0)
Block(-4,7,-2,STONE:0)
Block(-4,7,-1,MOSSY_COBBLESTONE:0)
Block(-4,7,0,MOSSY_COBBLESTONE:0)
Block(-4,7,1,MOSSY_COBBLESTONE:0)
Block(-4,7,2,MOSSY_COBBLESTONE:0)
Block(-4,7,3,MOSSY_COBBLESTONE:0)
Block(-4,7,4,MOSSY_COBBLESTONE:0)
Block(-4,7,5,MOSSY_COBBLESTONE:0)
Block(-4,7,6,MOSSY_COBBLESTONE:0)
Block(-4,7,7,MOSSY_COBBLESTONE:0)
Block(-4,7,8,MOSSY_COBBLESTONE:0)
Block(-4,8,-4,STONE:0)
Block(-4,8,-3,STONE:0)
Block(-4,8,-2,STONE:0)
Block(-4,8,-1,MOSSY_COBBLESTONE:0)
Block(-4,8,0,MOSSY_COBBLESTONE:0)
Block(-4,8,1,MOSSY_COBBLESTONE:0)
Block(-4,8,2,MOSSY_COBBLESTONE:0)
Block(-4,8,3,MOSSY_COBBLESTONE:0)
Block(-4,8,6,MOSSY_COBBLESTONE:0)
Block(-4,8,7,MOSSY_COBBLESTONE:0)
Block(-4,8,8,MOSSY_COBBLESTONE:0)
Block(-4,9,-4,STONE:0)
Block(-4,9,-3,STONE:0)
Block(-4,9,-2,STONE:0)
Block(-4,9,-1,MOSSY_COBBLESTONE:0)
Block(-4,9,0,MOSSY_COBBLESTONE:0)
Block(-4,10,-3,STONE:0)
Block(-4,10,-2,STONE:0)
Block(-4,10,-1,STONE:0)
Block(-4,10,0,MOSSY_COBBLESTONE:0)
Block(-4,11,-2,STONE:0)
Block(-4,11,-1,STONE:0)
Block(-4,12,-2,STONE:0)
Block(-4,12,-1,STONE:0)
Block(-4,12,0,STONE:0)
Block(-4,13,-2,STONE:0)
Block(-4,13,-1,STONE:0)
Block(-4,13,0,STONE:0)
Block(-4,13,1,STONE:0)
Block(-4,14,-2,STONE:0)
Block(-4,14,-1,STONE:0)
Block(-4,14,0,STONE:0)
Block(-4,14,1,STONE:0)
Block(-4,14,2,MOSSY_COBBLESTONE:0)
Block(-4,14,3,MOSSY_COBBLESTONE:0)
Block(-4,15,-3,STONE:0)
Block(-4,15,-2,STONE:0)
Block(-4,15,-1,STONE:0)
Block(-4,15,0,STONE:0)
Block(-4,15,1,STONE:0)
Block(-4,15,2,MOSSY_COBBLESTONE:0)
Block(-4,15,3,MOSSY_COBBLESTONE:0)
Block(-4,15,4,MOSSY_COBBLESTONE:0)
Block(-4,15,5,MOSSY_COBBLESTONE:0)
Block(-4,15,6,MOSSY_COBBLESTONE:0)
Block(-4,15,7,STONE:0)
Block(-4,15,8,STONE:0)
Block(-4,16,-4,STONE:0)
Block(-4,16,-3,STONE:0)
Block(-4,16,-2,STONE:0)
Block(-4,16,-1,STONE:0)
Block(-4,16,0,STONE:0)
Block(-4,16,1,STONE:0)
Block(-4,16,2,MOSSY_COBBLESTONE:0)
Block(-4,16,3,MOSSY_COBBLESTONE:0)
Block(-4,16,4,MOSSY_COBBLESTONE:0)
Block(-4,16,5,MOSSY_COBBLESTONE:0)
Block(-4,16,6,MOSSY_COBBLESTONE:0)
Block(-4,16,7,STONE:0)
Block(-4,16,8,STONE:0)
RandomBlock(-4,17,-4,STONE:5,50,STONE:0,100)
RandomBlock(-4,17,-3,STONE:5,50,STONE:0,100)
RandomBlock(-4,17,-2,STONE:5,50,STONE:0,100)
RandomBlock(-4,17,-1,STONE:5,50,STONE:0,100)
RandomBlock(-4,17,0,STONE:5,50,STONE:0,100)
RandomBlock(-4,17,1,STONE:5,50,STONE:0,100)
RandomBlock(-4,17,2,STONE:5,50,STONE:0,100)
Block(-4,17,3,MOSSY_COBBLESTONE:0)
Block(-4,17,4,MOSSY_COBBLESTONE:0)
Block(-4,17,5,MOSSY_COBBLESTONE:0)
RandomBlock(-4,17,6,STONE:5,50,STONE:0,100)
RandomBlock(-4,17,7,STONE:5,50,STONE:0,100)
RandomBlock(-4,17,8,STONE:5,50,STONE:0,100)
Block(-4,18,-3,STONE:5)
Block(-4,18,-2,STONE:5)
Block(-4,18,-1,STONE:5)
Block(-4,18,0,STONE:5)
Block(-4,18,1,STONE:5)
Block(-4,18,2,STONE:5)
Block(-4,18,3,STONE:5)
Block(-4,18,4,STONE:5)
Block(-4,18,5,STONE:5)
Block(-4,18,6,STONE:5)
Block(-4,18,7,STONE:5)
Block(-4,18,8,STONE:5)
Block(-4,19,-2,STONE:5)
Block(-4,19,-1,STONE:5)
Block(-4,19,0,STONE:5)
Block(-4,19,1,STONE:5)
Block(-4,19,2,STONE:5)
Block(-4,19,3,STONE:5)
Block(-4,19,4,STONE:5)
Block(-4,19,5,STONE:5)
Block(-4,19,6,STONE:5)
Block(-4,19,7,STONE:5)
Block(-4,19,8,STONE:5)
Block(-4,20,1,STONE:5)
Block(-4,20,2,STONE:5)
Block(-4,20,3,STONE:5)
Block(-4,20,4,STONE:5)
Block(-4,20,5,STONE:5)
Block(-4,20,6,STONE:5)
Block(-4,20,7,STONE:5)
Block(-4,20,8,STONE:5)
Block(-4,21,2,STONE:5)
Block(-4,21,3,STONE:5)
Block(-4,21,4,STONE:5)
Block(-4,21,5,STONE:5)
Block(-4,21,6,STONE:5)
Block(-4,21,7,STONE:5)
Block(-4,21,8,STONE:5)
Block(-4,22,4,STONE:5)
Block(-3,3,6,STONE:0)
Block(-3,3,7,STONE:0)
Block(-3,3,8,STONE:0)
Block(-3,4,2,STONE:0)
Block(-3,4,5,STONE:0)
Block(-3,4,6,STONE:0)
Block(-3,4,7,STONE:0)
Block(-3,4,8,STONE:0)
Block(-3,5,-1,STONE:0)
Block(-3,5,0,STONE:0)
Block(-3,5,1,STONE:0)
Block(-3,5,2,STONE:0)
Block(-3,5,3,STONE:0)
Block(-3,5,4,MOSSY_COBBLESTONE:0)
Block(-3,5,5,MOSSY_COBBLESTONE:0)
Block(-3,5,6,MOSSY_COBBLESTONE:0)
Block(-3,5,7,STONE:0)
Block(-3,5,8,STONE:0)
Block(-3,6,-3,STONE:0)
Block(-3,6,-2,STONE:0)
Block(-3,6,-1,STONE:0)
Block(-3,6,0,STONE:0)
Block(-3,6,1,STONE:0)
Block(-3,6,2,MOSSY_COBBLESTONE:0)
Block(-3,6,3,MOSSY_COBBLESTONE:0)
Block(-3,6,4,MOSSY_COBBLESTONE:0)
Block(-3,6,5,MOSSY_COBBLESTONE:0)
Block(-3,6,6,MOSSY_COBBLESTONE:0)
Block(-3,6,7,MOSSY_COBBLESTONE:0)
Block(-3,6,8,STONE:0)
Block(-3,7,-3,STONE:0)
Block(-3,7,-2,STONE:0)
Block(-3,7,-1,STONE:0)
Block(-3,7,0,MOSSY_COBBLESTONE:0)
Block(-3,7,1,MOSSY_COBBLESTONE:0)
Block(-3,7,2,MOSSY_COBBLESTONE:0)
Block(-3,7,3,MOSSY_COBBLESTONE:0)
Block(-3,7,4,MOSSY_COBBLESTONE:0)
Block(-3,7,5,MOSSY_COBBLESTONE:0)
Block(-3,7,6,MOSSY_COBBLESTONE:0)
Block(-3,7,7,MOSSY_COBBLESTONE:0)
Block(-3,7,8,STONE:0)
Block(-3,8,-4,STONE:0)
Block(-3,8,-3,STONE:0)
Block(-3,8,-2,STONE:0)
Block(-3,8,-1,STONE:0)
Block(-3,8,0,MOSSY_COBBLESTONE:0)
Block(-3,8,1,MOSSY_COBBLESTONE:0)
Block(-3,8,2,MOSSY_COBBLESTONE:0)
Block(-3,8,3,MOSSY_COBBLESTONE:0)
Block(-3,8,4,MOSSY_COBBLESTONE:0)
Block(-3,8,5,MOSSY_COBBLESTONE:0)
Block(-3,8,6,MOSSY_COBBLESTONE:0)
Block(-3,8,7,MOSSY_COBBLESTONE:0)
Block(-3,8,8,STONE:0)
Block(-3,9,-4,STONE:0)
Block(-3,9,-3,STONE:0)
Block(-3,9,-2,STONE:0)
Block(-3,9,-1,STONE:0)
Block(-3,9,0,MOSSY_COBBLESTONE:0)
Block(-3,9,1,MOSSY_COBBLESTONE:0)
Block(-3,9,2,MOSSY_COBBLESTONE:0)
Block(-3,9,5,MOSSY_COBBLESTONE:0)
Block(-3,9,6,MOSSY_COBBLESTONE:0)
Block(-3,9,7,STONE:0)
Block(-3,9,8,STONE:0)
Block(-3,10,-3,STONE:0)
Block(-3,10,-2,STONE:0)
Block(-3,10,-1,STONE:0)
Block(-3,10,0,STONE:0)
Block(-3,10,1,STONE:0)
Block(-3,10,2,STONE:0)
Block(-3,10,7,STONE:0)
Block(-3,10,8,STONE:0)
Block(-3,11,-2,STONE:0)
Block(-3,11,-1,STONE:0)
Block(-3,11,0,STONE:0)
Block(-3,11,1,STONE:0)
Block(-3,12,-2,STONE:0)
Block(-3,12,-1,STONE:0)
Block(-3,12,0,STONE:0)
Block(-3,12,1,STONE:0)
Block(-3,13,-2,STONE:0)
Block(-3,13,-1,STONE:0)
Block(-3,13,0,STONE:0)
Block(-3,13,1,STONE:0)
Block(-3,13,2,STONE:0)
Block(-3,14,-2,STONE:0)
Block(-3,14,-1,STONE:0)
Block(-3,14,0,STONE:0)
Block(-3,14,1,STONE:0)
Block(-3,14,2,MOSSY_COBBLESTONE:0)
Block(-3,14,3,MOSSY_COBBLESTONE:0)
Block(-3,14,7,STONE:0)
Block(-3,14,8,STONE:0)
Block(-3,15,-2,STONE:0)
Block(-3,15,-1,STONE:0)
Block(-3,15,0,STONE:0)
Block(-3,15,1,STONE:0)
Block(-3,15,2,MOSSY_COBBLESTONE:0)
Block(-3,15,3,MOSSY_COBBLESTONE:0)
Block(-3,15,4,MOSSY_COBBLESTONE:0)
Block(-3,15,5,MOSSY_COBBLESTONE:0)
Block(-3,15,6,MOSSY_COBBLESTONE:0)
Block(-3,15,7,STONE:0)
Block(-3,15,8,STONE:0)
Block(-3,16,-3,STONE:0)
Block(-3,16,-2,STONE:0)
Block(-3,16,-1,STONE:0)
Block(-3,16,0,STONE:0)
Block(-3,16,1,STONE:0)
Block(-3,16,2,MOSSY_COBBLESTONE:0)
Block(-3,16,3,MOSSY_COBBLESTONE:0)
Block(-3,16,4,MOSSY_COBBLESTONE:0)
Block(-3,16,5,MOSSY_COBBLESTONE:0)
Block(-3,16,6,MOSSY_COBBLESTONE:0)
Block(-3,16,7,STONE:0)
Block(-3,16,8,STONE:0)
RandomBlock(-3,17,-2,STONE:5,50,STONE:0,100)
RandomBlock(-3,17,-1,STONE:5,50,STONE:0,100)
RandomBlock(-3,17,0,STONE:5,50,STONE:0,100)
RandomBlock(-3,17,1,STONE:5,50,STONE:0,100)
RandomBlock(-3,17,2,STONE:5,50,STONE:0,100)
Block(-3,17,3,MOSSY_COBBLESTONE:0)
Block(-3,17,4,MOSSY_COBBLESTONE:0)
Block(-3,17,5,MOSSY_COBBLESTONE:0)
RandomBlock(-3,17,6,STONE:5,50,STONE:0,100)
RandomBlock(-3,17,7,STONE:5,50,STONE:0,100)
RandomBlock(-3,17,8,STONE:5,50,STONE:0,100)
Block(-3,18,-3,STONE:5)
Block(-3,18,-2,STONE:5)
Block(-3,18,-1,STONE:5)
Block(-3,18,0,STONE:5)
Block(-3,18,1,STONE:5)
Block(-3,18,2,STONE:5)
Block(-3,18,3,STONE:5)
Block(-3,18,4,STONE:5)
Block(-3,18,5,STONE:5)
Block(-3,18,6,STONE:5)
Block(-3,18,7,STONE:5)
Block(-3,18,8,STONE:5)
Block(-3,19,-1,STONE:5)
Block(-3,19,0,STONE:5)
Block(-3,19,1,STONE:5)
Block(-3,19,2,STONE:5)
Block(-3,19,3,STONE:5)
Block(-3,19,4,STONE:5)
Block(-3,19,5,STONE:5)
Block(-3,19,6,STONE:5)
Block(-3,19,7,STONE:5)
Block(-3,19,8,STONE:5)
Block(-3,20,2,STONE:5)
Block(-3,20,3,STONE:5)
Block(-3,20,4,STONE:5)
Block(-3,20,5,STONE:5)
Block(-3,20,6,STONE:5)
Block(-3,20,7,STONE:5)
Block(-3,20,8,STONE:5)
Block(-3,21,3,STONE:5)
Block(-3,21,4,STONE:5)
Block(-3,21,5,STONE:5)
Block(-3,21,6,STONE:5)
Block(-3,21,7,STONE:5)
Block(-3,21,8,STONE:5)
Block(-2,4,7,STONE:0)
Block(-2,5,0,STONE:0)
Block(-2,5,1,STONE:0)
Block(-2,5,2,STONE:0)
Block(-2,5,3,STONE:0)
Block(-2,5,6,STONE:0)
Block(-2,5,7,STONE:0)
Block(-2,5,8,STONE:0)
Block(-2,6,-2,STONE:0)
Block(-2,6,-1,STONE:0)
Block(-2,6,0,STONE:0)
Block(-2,6,1,STONE:0)
Block(-2,6,2,STONE:0)
Block(-2,6,3,STONE:0)
Block(-2,6,4,MOSSY_COBBLESTONE:0)
Block(-2,6,5,MOSSY_COBBLESTONE:0)
Block(-2,6,6,MOSSY_COBBLESTONE:0)
Block(-2,6,7,STONE:0)
Block(-2,6,8,STONE:0)
Block(-2,7,-3,STONE:0)
Block(-2,7,-2,STONE:0)
Block(-2,7,-1,STONE:0)
Block(-2,7,0,STONE:0)
Block(-2,7,1,STONE:0)
Block(-2,7,2,STONE:0)
Block(-2,7,3,STONE:0)
Block(-2,7,4,MOSSY_COBBLESTONE:0)
Block(-2,7,5,MOSSY_COBBLESTONE:0)
Block(-2,7,6,MOSSY_COBBLESTONE:0)
Block(-2,7,7,STONE:0)
Block(-2,7,8,STONE:0)
Block(-2,8,-3,STONE:0)
Block(-2,8,-2,STONE:0)
Block(-2,8,-1,STONE:0)
Block(-2,8,0,STONE:0)
Block(-2,8,1,STONE:0)
Block(-2,8,2,STONE:0)
Block(-2,8,3,STONE:0)
Block(-2,8,4,MOSSY_COBBLESTONE:0)
Block(-2,8,5,MOSSY_COBBLESTONE:0)
Block(-2,8,6,MOSSY_COBBLESTONE:0)
Block(-2,8,7,STONE:0)
Block(-2,8,8,STONE:0)
Block(-2,9,-4,STONE:0)
Block(-2,9,-3,STONE:0)
Block(-2,9,-2,STONE:0)
Block(-2,9,-1,STONE:0)
Block(-2,9,0,STONE:0)
Block(-2,9,1,STONE:0)
Block(-2,9,2,STONE:0)
Block(-2,9,3,STONE:0)
Block(-2,9,4,STONE:0)
Block(-2,9,5,STONE:0)
Block(-2,9,6,STONE:0)
Block(-2,9,7,STONE:0)
Block(-2,9,8,STONE:0)
Block(-2,10,-3,STONE:0)
Block(-2,10,-2,STONE:0)
Block(-2,10,-1,STONE:0)
Block(-2,10,0,STONE:0)
Block(-2,10,1,STONE:0)
Block(-2,10,2,STONE:0)
Block(-2,10,3,STONE:0)
Block(-2,10,4,STONE:0)
Block(-2,10,5,STONE:0)
Block(-2,10,6,STONE:0)
Block(-2,10,7,STONE:0)
Block(-2,10,8,STONE:0)
Block(-2,11,-2,STONE:0)
Block(-2,11,-1,STONE:0)
Block(-2,11,0,STONE:0)
Block(-2,11,1,STONE:0)
Block(-2,11,2,STONE:0)
Block(-2,11,3,STONE:0)
Block(-2,11,7,STONE:0)
Block(-2,11,8,STONE:0)
Block(-2,12,-1,STONE:0)
Block(-2,12,0,STONE:0)
Block(-2,12,1,STONE:0)
Block(-2,12,2,STONE:0)
Block(-2,12,3,STONE:0)
Block(-2,12,7,STONE:0)
Block(-2,12,8,STONE:0)
Block(-2,13,0,STONE:0)
Block(-2,13,1,STONE:0)
Block(-2,13,2,STONE:0)
Block(-2,13,3,STONE:0)
Block(-2,13,7,STONE:0)
Block(-2,13,8,STONE:0)
Block(-2,14,0,STONE:0)
Block(-2,14,1,STONE:0)
Block(-2,14,2,STONE:0)
Block(-2,14,3,MOSSY_COBBLESTONE:0)
Block(-2,14,4,MOSSY_COBBLESTONE:0)
Block(-2,14,5,MOSSY_COBBLESTONE:0)
Block(-2,14,6,STONE:0)
Block(-2,14,7,STONE:0)
Block(-2,14,8,STONE:0)
Block(-2,15,0,STONE:0)
Block(-2,15,1,STONE:0)
Block(-2,15,2,STONE:0)
Block(-2,15,3,MOSSY_COBBLESTONE:0)
Block(-2,15,4,MOSSY_COBBLESTONE:0)
Block(-2,15,5,MOSSY_COBBLESTONE:0)
Block(-2,15,6,STONE:0)
Block(-2,15,7,STONE:0)
Block(-2,15,8,STONE:0)
Block(-2,16,-1,STONE:0)
Block(-2,16,0,STONE:0)
Block(-2,16,1,STONE:0)
Block(-2,16,2,STONE:0)
Block(-2,16,3,MOSSY_COBBLESTONE:0)
Block(-2,16,4,MOSSY_COBBLESTONE:0)
Block(-2,16,5,MOSSY_COBBLESTONE:0)
Block(-2,16,6,STONE:0)
Block(-2,16,7,STONE:0)
Block(-2,16,8,STONE:0)
RandomBlock(-2,17,-2,STONE:5,50,STONE:0,100)
RandomBlock(-2,17,-1,STONE:5,50,STONE:0,100)
RandomBlock(-2,17,0,STONE:5,50,STONE:0,100)
RandomBlock(-2,17,1,STONE:5,50,STONE:0,100)
RandomBlock(-2,17,2,STONE:5,50,STONE:0,100)
RandomBlock(-2,17,3,STONE:5,50,STONE:0,100)
RandomBlock(-2,17,4,STONE:5,50,STONE:0,100)
RandomBlock(-2,17,5,STONE:5,50,STONE:0,100)
RandomBlock(-2,17,6,STONE:5,50,STONE:0,100)
RandomBlock(-2,17,7,STONE:5,50,STONE:0,100)
RandomBlock(-2,17,8,STONE:5,50,STONE:0,100)
Block(-2,18,1,STONE:5)
Block(-2,18,2,STONE:5)
Block(-2,18,3,STONE:5)
Block(-2,18,4,STONE:5)
Block(-2,18,5,STONE:5)
Block(-2,18,6,STONE:5)
Block(-2,18,7,STONE:5)
Block(-2,18,8,STONE:5)
Block(-2,19,3,STONE:5)
Block(-2,19,4,STONE:5)
Block(-2,19,5,STONE:5)
Block(-2,19,6,STONE:5)
Block(-2,19,7,STONE:5)
Block(-2,19,8,STONE:5)
Block(-2,20,4,STONE:5)
Block(-2,20,5,STONE:5)
Block(-2,20,6,STONE:5)
Block(-2,20,7,STONE:5)
Block(-2,20,8,STONE:5)
Block(-2,21,6,STONE:5)
Block(-1,6,-1,STONE:0)
Block(-1,6,0,STONE:0)
Block(-1,6,1,STONE:0)
Block(-1,6,2,STONE:0)
Block(-1,6,7,STONE:0)
Block(-1,7,-2,STONE:0)
Block(-1,7,-1,STONE:0)
Block(-1,7,0,STONE:0)
Block(-1,7,1,STONE:0)
Block(-1,7,2,STONE:0)
Block(-1,7,3,STONE:0)
Block(-1,7,4,STONE:0)
Block(-1,7,5,STONE:0)
Block(-1,7,6,STONE:0)
Block(-1,7,7,STONE:0)
Block(-1,7,8,STONE:0)
Block(-1,8,-3,STONE:0)
Block(-1,8,-2,STONE:0)
Block(-1,8,-1,STONE:0)
Block(-1,8,0,STONE:0)
Block(-1,8,1,STONE:0)
Block(-1,8,2,STONE:0)
Block(-1,8,3,STONE:0)
Block(-1,8,4,STONE:0)
Block(-1,8,5,STONE:0)
Block(-1,8,6,STONE:0)
Block(-1,8,7,STONE:0)
Block(-1,8,8,STONE:0)
Block(-1,9,-3,STONE:0)
Block(-1,9,-2,STONE:0)
Block(-1,9,-1,STONE:0)
Block(-1,9,0,STONE:0)
Block(-1,9,1,STONE:0)
Block(-1,9,2,STONE:0)
Block(-1,9,3,STONE:0)
Block(-1,9,4,STONE:0)
Block(-1,9,5,STONE:0)
Block(-1,9,6,STONE:0)
Block(-1,9,7,STONE:0)
Block(-1,9,8,STONE:0)
Block(-1,10,-2,STONE:0)
Block(-1,10,-1,STONE:0)
Block(-1,10,0,STONE:0)
Block(-1,10,1,STONE:0)
Block(-1,10,2,STONE:0)
Block(-1,10,3,STONE:0)
Block(-1,10,4,STONE:0)
Block(-1,10,5,STONE:0)
Block(-1,10,6,STONE:0)
Block(-1,10,7,STONE:0)
Block(-1,10,8,STONE:0)
Block(-1,11,-1,STONE:0)
Block(-1,11,0,STONE:0)
Block(-1,11,1,STONE:0)
Block(-1,11,2,STONE:0)
Block(-1,11,3,STONE:0)
Block(-1,11,4,STONE:0)
Block(-1,11,5,STONE:0)
Block(-1,11,6,STONE:0)
Block(-1,11,7,STONE:0)
Block(-1,11,8,STONE:0)
Block(-1,12,-1,STONE:0)
Block(-1,12,0,STONE:0)
Block(-1,12,1,STONE:0)
Block(-1,12,2,STONE:0)
Block(-1,12,3,STONE:0)
Block(-1,12,4,STONE:0)
Block(-1,12,5,STONE:0)
Block(-1,12,6,STONE:0)
Block(-1,12,7,STONE:0)
Block(-1,12,8,STONE:0)
Block(-1,13,0,STONE:0)
Block(-1,13,1,STONE:0)
Block(-1,13,2,STONE:0)
Block(-1,13,3,STONE:0)
Block(-1,13,4,STONE:0)
Block(-1,13,5,STONE:0)
Block(-1,13,6,STONE:0)
Block(-1,13,7,STONE:0)
Block(-1,13,8,STONE:0)
Block(-1,14,0,STONE:0)
Block(-1,14,1,STONE:0)
Block(-1,14,2,STONE:0)
Block(-1,14,3,STONE:0)
Block(-1,14,4,STONE:0)
Block(-1,14,5,STONE:0)
Block(-1,14,6,STONE:0)
Block(-1,14,7,STONE:0)
Block(-1,14,8,STONE:0)
Block(-1,15,0,STONE:0)
Block(-1,15,1,STONE:0)
Block(-1,15,2,STONE:0)
Block(-1,15,3,STONE:0)
Block(-1,15,4,STONE:0)
Block(-1,15,5,STONE:0)
Block(-1,15,6,STONE:0)
Block(-1,15,7,STONE:0)
Block(-1,15,8,STONE:0)
Block(-1,16,1,STONE:0)
Block(-1,16,2,STONE:0)
Block(-1,16,3,STONE:0)
Block(-1,16,4,STONE:0)
Block(-1,16,5,STONE:0)
Block(-1,16,6,STONE:0)
Block(-1,16,7,STONE:0)
Block(-1,16,8,STONE:0)
RandomBlock(-1,17,1,STONE:5,50,STONE:0,100)
RandomBlock(-1,17,2,STONE:5,50,STONE:0,100)
RandomBlock(-1,17,3,STONE:5,50,STONE:0,100)
RandomBlock(-1,17,4,STONE:5,50,STONE:0,100)
RandomBlock(-1,17,5,STONE:5,50,STONE:0,100)
RandomBlock(-1,17,6,STONE:5,50,STONE:0,100)
RandomBlock(-1,17,7,STONE:5,50,STONE:0,100)
RandomBlock(-1,17,8,STONE:5,50,STONE:0,100)
Block(-1,18,3,STONE:5)
Block(-1,18,4,STONE:5)
Block(-1,18,5,STONE:5)
Block(-1,18,6,STONE:5)
Block(-1,18,7,STONE:5)
Block(-1,18,8,STONE:5)
Block(-1,19,6,STONE:5)
Block(-1,19,7,STONE:5)
Block(-1,20,6,STONE:5)
Block(0,7,0,STONE:0)
Block(0,7,2,STONE:0)
Block(0,7,3,STONE:0)
Block(0,7,4,STONE:0)
Block(0,7,6,STONE:0)
Block(0,7,7,STONE:0)
Block(0,7,8,STONE:0)
Block(0,8,-1,STONE:0)
Block(0,8,0,STONE:0)
Block(0,8,1,STONE:0)
Block(0,8,2,STONE:0)
Block(0,8,3,STONE:0)
Block(0,8,4,STONE:0)
Block(0,8,5,STONE:0)
Block(0,8,6,STONE:0)
Block(0,8,7,STONE:0)
Block(0,8,8,STONE:0)
Block(0,9,-2,STONE:0)
Block(0,9,-1,STONE:0)
Block(0,9,0,STONE:0)
Block(0,9,1,STONE:0)
Block(0,9,2,STONE:0)
Block(0,9,3,STONE:0)
Block(0,9,4,STONE:0)
Block(0,9,5,STONE:0)
Block(0,9,6,STONE:0)
Block(0,9,7,STONE:0)
Block(0,9,8,STONE:0)
Block(0,10,-1,STONE:0)
Block(0,10,0,STONE:0)
Block(0,10,1,STONE:0)
Block(0,10,2,STONE:0)
Block(0,10,3,STONE:0)
Block(0,10,4,STONE:0)
Block(0,10,5,STONE:0)
Block(0,10,6,STONE:0)
Block(0,10,7,STONE:0)
Block(0,10,8,STONE:0)
Block(0,11,-1,STONE:0)
Block(0,11,0,STONE:0)
Block(0,11,1,STONE:0)
Block(0,11,2,STONE:0)
Block(0,11,3,STONE:0)
Block(0,11,4,STONE:0)
Block(0,11,5,STONE:0)
Block(0,11,6,STONE:0)
Block(0,11,7,STONE:0)
Block(0,11,8,STONE:0)
Block(0,12,-1,STONE:0)
Block(0,12,0,STONE:0)
Block(0,12,1,STONE:0)
Block(0,12,2,STONE:0)
Block(0,12,3,STONE:0)
Block(0,12,4,STONE:0)
Block(0,12,5,STONE:0)
Block(0,12,6,STONE:0)
Block(0,12,7,STONE:0)
Block(0,12,8,STONE:0)
Block(0,13,0,STONE:0)
Block(0,13,1,STONE:0)
Block(0,13,2,STONE:0)
Block(0,13,3,STONE:0)
Block(0,13,4,STONE:0)
Block(0,13,5,STONE:0)
Block(0,13,6,STONE:0)
Block(0,13,7,STONE:0)
Block(0,13,8,STONE:0)
Block(0,14,0,STONE:0)
Block(0,14,1,STONE:0)
Block(0,14,2,STONE:0)
Block(0,14,3,STONE:0)
Block(0,14,4,STONE:0)
Block(0,14,5,STONE:0)
Block(0,14,6,STONE:0)
Block(0,14,7,STONE:0)
Block(0,14,8,STONE:0)
Block(0,15,1,STONE:0)
Block(0,15,2,STONE:0)
Block(0,15,3,STONE:0)
Block(0,15,4,STONE:0)
Block(0,15,5,STONE:0)
Block(0,15,6,STONE:0)
Block(0,15,7,STONE:0)
Block(0,15,8,STONE:0)
Block(0,16,1,STONE:0)
Block(0,16,2,STONE:0)
Block(0,16,3,STONE:0)
Block(0,16,4,STONE:0)
Block(0,16,5,STONE:0)
Block(0,16,6,STONE:0)
Block(0,16,7,STONE:0)
RandomBlock(0,17,2,STONE:5,50,STONE:0,100)
RandomBlock(0,17,3,STONE:5,50,STONE:0,100)
RandomBlock(0,17,4,STONE:5,50,STONE:0,100)
RandomBlock(0,17,5,STONE:5,50,STONE:0,100)
RandomBlock(0,17,6,STONE:5,50,STONE:0,100)
Block(0,18,4,STONE:5)
Block(1,7,3,STONE:0)
Block(1,8,1,STONE:0)
Block(1,8,2,STONE:0)
Block(1,8,3,STONE:0)
Block(1,8,4,STONE:0)
Block(1,8,5,STONE:0)
Block(1,8,7,STONE:0)
Block(1,9,0,STONE:0)
Block(1,9,1,STONE:0)
Block(1,9,2,STONE:0)
Block(1,9,3,STONE:0)
Block(1,9,4,STONE:0)
Block(1,9,5,STONE:0)
Block(1,9,6,STONE:0)
Block(1,9,7,STONE:0)
Block(1,9,8,STONE:0)
Block(1,10,0,STONE:0)
Block(1,10,1,STONE:0)
Block(1,10,2,STONE:0)
Block(1,10,3,STONE:0)
Block(1,10,4,STONE:0)
Block(1,10,5,STONE:0)
Block(1,10,6,STONE:0)
Block(1,10,7,STONE:0)
Block(1,10,8,STONE:0)
Block(1,11,-1,STONE:0)
Block(1,11,0,STONE:0)
Block(1,11,1,STONE:0)
Block(1,11,2,STONE:0)
Block(1,11,3,STONE:0)
Block(1,11,4,STONE:0)
Block(1,11,5,STONE:0)
Block(1,11,6,STONE:0)
Block(1,11,7,STONE:0)
Block(1,11,8,STONE:0)
Block(1,12,0,STONE:0)
Block(1,12,1,STONE:0)
Block(1,12,2,STONE:0)
Block(1,12,3,STONE:0)
Block(1,12,4,STONE:0)
Block(1,12,5,STONE:0)
Block(1,12,6,STONE:0)
Block(1,12,7,STONE:0)
Block(1,12,8,STONE:0)
Block(1,13,0,STONE:0)
Block(1,13,1,STONE:0)
Block(1,13,2,STONE:0)
Block(1,13,3,STONE:0)
Block(1,13,4,STONE:0)
Block(1,13,5,STONE:0)
Block(1,13,6,STONE:0)
Block(1,13,7,STONE:0)
Block(1,13,8,STONE:0)
Block(1,14,1,STONE:0)
Block(1,14,2,STONE:0)
Block(1,14,3,STONE:0)
Block(1,14,4,STONE:0)
Block(1,14,5,STONE:0)
Block(1,14,6,STONE:0)
Block(1,14,7,STONE:0)
Block(1,15,1,STONE:0)
Block(1,15,2,STONE:0)
Block(1,15,3,STONE:0)
Block(1,15,4,STONE:0)
Block(1,15,5,STONE:0)
Block(1,15,6,STONE:0)
Block(1,15,7,STONE:0)
Block(1,16,2,STONE:0)
Block(1,16,3,STONE:0)
Block(1,16,4,STONE:0)
Block(1,16,5,STONE:0)
Block(1,16,6,STONE:0)
RandomBlock(1,17,3,STONE:5,50,STONE:0,100)
RandomBlock(1,17,4,STONE:5,50,STONE:0,100)
RandomBlock(1,17,5,STONE:5,50,STONE:0,100)
Block(2,8,2,STONE:0)
Block(2,8,3,STONE:0)
Block(2,8,4,STONE:0)
Block(2,9,1,STONE:0)
Block(2,9,2,STONE:0)
Block(2,9,3,STONE:0)
Block(2,9,4,STONE:0)
Block(2,9,5,STONE:0)
Block(2,10,0,STONE:0)
Block(2,10,1,STONE:0)
Block(2,10,2,STONE:0)
Block(2,10,3,STONE:0)
Block(2,10,4,STONE:0)
Block(2,10,5,STONE:0)
Block(2,10,6,STONE:0)
Block(2,11,0,STONE:0)
Block(2,11,1,STONE:0)
Block(2,11,2,STONE:0)
Block(2,11,3,STONE:0)
Block(2,11,4,STONE:0)
Block(2,11,5,STONE:0)
Block(2,11,6,STONE:0)
Block(2,11,8,STONE:0)
Block(2,12,0,STONE:0)
Block(2,12,1,STONE:0)
Block(2,12,2,STONE:0)
Block(2,12,3,STONE:0)
Block(2,12,4,STONE:0)
Block(2,12,5,STONE:0)
Block(2,12,6,STONE:0)
Block(2,13,1,STONE:0)
Block(2,13,2,STONE:0)
Block(2,13,3,STONE:0)
Block(2,13,4,STONE:0)
Block(2,13,5,STONE:0)
Block(2,14,2,STONE:0)
Block(2,14,3,STONE:0)
Block(2,14,4,STONE:0)
Block(2,14,5,STONE:0)
Block(2,14,6,STONE:0)
Block(2,15,3,STONE:0)
Block(2,15,4,STONE:0)
Block(2,15,5,STONE:0)
Block(2,16,4,STONE:0)
Block(3,9,3,STONE:0)
Block(3,10,2,STONE:0)
Block(3,10,3,STONE:0)
Block(3,10,4,STONE:0)
Block(3,11,1,STONE:0)
Block(3,11,2,STONE:0)
Block(3,11,3,STONE:0)
Block(3,11,4,STONE:0)
Block(3,11,5,STONE:0)
Block(3,12,2,STONE:0)
Block(3,12,3,STONE:0)
Block(3,12,4,STONE:0)
Block(3,13,3,STONE:0)

#######################################################################
# +-----------------------------------------------------------------+ #
# |                             Branches                            | #
# +-----------------------------------------------------------------+ #
#######################################################################

Branch(0,0,16,true,cyclops_mainC4R2,NORTH,100.0,0)

#######################################################################
# +-----------------------------------------------------------------+ #
# |                             Entities                            | #
# +-----------------------------------------------------------------+ #
#######################################################################


#######################################################################
# +-----------------------------------------------------------------+ #
# |                            Particles                            | #
# +-----------------------------------------------------------------+ #
#######################################################################


#######################################################################
# +-----------------------------------------------------------------+ #
# |                             Spawners                            | #
# +-----------------------------------------------------------------+ #
#######################################################################


#######################################################################
# +-----------------------------------------------------------------+ #
# |                             ModData                             | #
# +-----------------------------------------------------------------+ #
#######################################################################

