
#######################################################################
# +-----------------------------------------------------------------+ #
# |                            BO4 object                           | #
# +-----------------------------------------------------------------+ #
#######################################################################

Author: NLBlackEagle

Description: No description given

SettingsMode: WriteWithoutComments


#######################################################################
# +-----------------------------------------------------------------+ #
# |                          Main settings                          | #
# +-----------------------------------------------------------------+ #
#######################################################################

FixedRotation: 

Frequency: 0

SpawnHeight: highestSolidBlock

UseCenterForHighestBlock: true

##############################
# Height Limits for the BO4. #
##############################

MinHeight: 0

MaxHeight: 255

InheritBO3: 

InheritBO3Rotation: NORTH

OverrideChildSettings: true

OverrideParentHeight: false

CanOverride: true

BranchFrequency: 0

BranchFrequencyGroup: 

MustBeBelowOther: false

MustBeInside: 

CannotBeInside: 

ReplacesBO3: 

MustBeInsideWorldBorders: false

CanSpawnOnWater: true

SpawnOnWaterOnly: false

SpawnUnderWater: false

SpawnAtWaterLevel: false

HeightOffset: 0

RemoveAir: true

ReplaceAbove: 

ReplaceBelow: 

ReplaceWithBiomeBlocks: false

ReplaceWithSurfaceBlock: GRASS

ReplaceWithGroundBlock: DIRT

ReplaceWithStoneBlock: STONE

SmoothRadius: 0

SmoothHeightOffset: 0

SmoothStartTop: false

SmoothStartWood: false

SmoothingSurfaceBlock: 

SmoothingGroundBlock: 

BO3Group: 

IsSpawnPoint: false

DoReplaceBlocks: true


#######################################################################
# +-----------------------------------------------------------------+ #
# |                              Blocks                             | #
# +-----------------------------------------------------------------+ #
#######################################################################

Block(-2,0,-2,ICE:0)
Block(-2,0,-1,ICE:0)
Block(-2,0,0,ICE:0)
Block(-2,0,1,ICE:0)
Block(-2,0,2,ICE:0)
Block(-2,0,3,ICE:0)
Block(-2,1,-2,SNOW_BLOCK:0)
Block(-2,1,0,SNOW_BLOCK:0)
Block(-2,1,1,AIR:0)
Block(-2,1,2,SNOW_BLOCK:0)
Block(-2,1,3,SNOW_BLOCK:0)
Block(-2,2,0,AIR:0)
Block(-2,2,1,AIR:0)
Block(-2,2,2,SNOW_BLOCK:0)
Block(-2,2,3,SNOW_BLOCK:0)
Block(-2,3,-2,AIR:0)
Block(-2,3,0,SNOW_BLOCK:0)
Block(-2,3,1,SNOW_BLOCK:0)
Block(-2,3,2,SNOW_BLOCK:0)
Block(-2,3,3,AIR:0)
Block(-2,4,-2,AIR:0)
Block(-2,4,-1,AIR:0)
Block(-2,4,0,SNOW_BLOCK:0)
Block(-2,4,2,AIR:0)
Block(-2,4,3,AIR:0)
Block(-1,0,-2,ICE:0)
Block(-1,0,-1,ICE:0)
Block(-1,0,0,ICE:0)
Block(-1,0,1,ICE:0)
Block(-1,0,2,ICE:0)
Block(-1,0,3,ICE:0)
Block(-1,1,-2,SNOW_BLOCK:0)
Block(-1,1,-1,AIR:0)
Block(-1,1,0,AIR:0)
Block(-1,1,1,AIR:0)
Block(-1,1,2,AIR:0)
Block(-1,1,3,SNOW_BLOCK:0)
Block(-1,2,-2,AIR:0)
Block(-1,2,-1,AIR:0)
Block(-1,2,0,AIR:0)
Block(-1,2,1,AIR:0)
Block(-1,2,2,AIR:0)
Block(-1,2,3,SNOW_BLOCK:0)
Block(-1,3,0,AIR:0)
Block(-1,3,1,AIR:0)
Block(-1,3,3,SNOW_BLOCK:0)
Block(-1,4,-2,AIR:0)
Block(-1,4,2,SNOW_BLOCK:0)
Block(-1,4,3,AIR:0)
Block(0,0,-2,ICE:0)
Block(0,0,-1,ICE:0)
Block(0,0,0,ICE:0)
Block(0,0,1,ICE:0)
Block(0,0,2,ICE:0)
Block(0,0,3,ICE:0)
Block(0,1,-2,SNOW_BLOCK:0)
Block(0,1,-1,AIR:0)
Block(0,1,0,SNOW_BLOCK:0)
Block(0,1,1,SNOW_BLOCK:0)
Block(0,1,2,AIR:0)
Block(0,1,3,SNOW_BLOCK:0)
Block(0,2,-1,AIR:0)
Block(0,2,0,AIR:0)
Block(0,2,1,AIR:0)
Block(0,2,2,AIR:0)
Block(0,3,-1,AIR:0)
Block(0,3,0,AIR:0)
Block(0,3,1,AIR:0)
Block(0,3,2,AIR:0)
Block(0,4,2,SNOW_BLOCK:0)
Block(1,0,-2,ICE:0)
Block(1,0,-1,ICE:0)
Block(1,0,0,ICE:0)
Block(1,0,1,ICE:0)
Block(1,0,2,ICE:0)
Block(1,0,3,ICE:0)
Block(1,1,-2,SNOW_BLOCK:0)
Block(1,1,-1,AIR:0)
Block(1,1,0,SNOW_BLOCK:0)
Block(1,1,1,SNOW_BLOCK:0)
Block(1,1,2,AIR:0)
Block(1,1,3,AIR:0)
Block(1,2,-2,SNOW_BLOCK:0)
Block(1,2,-1,AIR:0)
Block(1,2,0,AIR:0)
Block(1,2,1,AIR:0)
Block(1,2,2,AIR:0)
Block(1,2,3,AIR:0)
Block(1,3,-2,SNOW_BLOCK:0)
Block(1,3,-1,AIR:0)
Block(1,3,0,AIR:0)
Block(1,3,1,AIR:0)
Block(1,3,2,AIR:0)
Block(1,3,3,SNOW_BLOCK:0)
Block(1,4,3,SNOW_BLOCK:0)
Block(2,0,-2,ICE:0)
Block(2,0,-1,ICE:0)
Block(2,0,0,ICE:0)
Block(2,0,1,ICE:0)
Block(2,0,2,ICE:0)
Block(2,0,3,ICE:0)
Block(2,1,-2,SNOW_BLOCK:0)
Block(2,1,-1,AIR:0)
Block(2,1,0,AIR:0)
Block(2,1,1,AIR:0)
Block(2,1,2,AIR:0)
Block(2,1,3,SNOW_BLOCK:0)
Block(2,2,-2,AIR:0)
Block(2,2,-1,AIR:0)
Block(2,2,0,AIR:0)
Block(2,2,1,AIR:0)
Block(2,2,2,AIR:0)
Block(2,2,3,SNOW_BLOCK:0)
Block(2,3,-2,SNOW_BLOCK:0)
Block(2,3,-1,SNOW_BLOCK:0)
Block(2,3,0,AIR:0)
Block(2,3,1,AIR:0)
Block(2,3,3,SNOW_BLOCK:0)
Block(2,4,-2,AIR:0)
Block(2,4,3,AIR:0)
Block(3,0,-2,ICE:0)
Block(3,0,-1,ICE:0)
Block(3,0,0,ICE:0)
Block(3,0,1,ICE:0)
Block(3,0,2,ICE:0)
Block(3,0,3,ICE:0)
Block(3,1,-2,SNOW_BLOCK:0)
Block(3,1,-1,SNOW_BLOCK:0)
Block(3,1,0,SNOW_BLOCK:0)
Block(3,1,1,SNOW_BLOCK:0)
Block(3,1,2,SNOW_BLOCK:0)
Block(3,1,3,SNOW_BLOCK:0)
Block(3,2,-2,SNOW_BLOCK:0)
Block(3,2,-1,SNOW_BLOCK:0)
Block(3,2,0,SNOW_BLOCK:0)
Block(3,2,1,SNOW_BLOCK:0)
Block(3,3,-2,AIR:0)
Block(3,3,-1,SNOW_BLOCK:0)
Block(3,3,0,SNOW_BLOCK:0)
Block(3,3,3,AIR:0)
Block(3,4,-2,AIR:0)
Block(3,4,-1,AIR:0)
Block(3,4,0,SNOW_BLOCK:0)
Block(3,4,1,SNOW_BLOCK:0)
Block(3,4,2,AIR:0)
Block(3,4,3,AIR:0)

#######################################################################
# +-----------------------------------------------------------------+ #
# |                             Branches                            | #
# +-----------------------------------------------------------------+ #
#######################################################################


#######################################################################
# +-----------------------------------------------------------------+ #
# |                             Entities                            | #
# +-----------------------------------------------------------------+ #
#######################################################################


#######################################################################
# +-----------------------------------------------------------------+ #
# |                            Particles                            | #
# +-----------------------------------------------------------------+ #
#######################################################################


#######################################################################
# +-----------------------------------------------------------------+ #
# |                             Spawners                            | #
# +-----------------------------------------------------------------+ #
#######################################################################


#######################################################################
# +-----------------------------------------------------------------+ #
# |                             ModData                             | #
# +-----------------------------------------------------------------+ #
#######################################################################

