
#######################################################################
# +-----------------------------------------------------------------+ #
# |                            BO3 object                           | #
# +-----------------------------------------------------------------+ #
#######################################################################

Author: NLBlackHeavenNL

Description: No description given

Version: 3

SettingsMode: WriteWithoutComments


#######################################################################
# +-----------------------------------------------------------------+ #
# |                          Main settings                          | #
# +-----------------------------------------------------------------+ #
#######################################################################

Tree: true

Frequency: 1

Rarity: 100.0

RotateRandomly: false

SpawnHeight: highestSolidBlock

SpawnHeightOffset: -1

SpawnHeightVariance: 0

##############################
# Height Limits for the BO3. #
##############################

MinHeight: 0

MaxHeight: 255

######################
# Extrusion settings #
######################

ExtrudeMode: None

ExtrudeThroughBlocks: AIR

MaxBranchDepth: 10

ExcludedBiomes: All


#######################################################################
# +-----------------------------------------------------------------+ #
# |                      Source block settings                      | #
# +-----------------------------------------------------------------+ #
#######################################################################

SourceBlocks: AIR,GRASS,DIRT,biomesoplenty:dirt

MaxPercentageOutsideSourceBlock: 0

OutsideSourceBlock: placeAnyway

DoReplaceBlocks: true

IsOTGPlus: false


#######################################################################
# +-----------------------------------------------------------------+ #
# |                              Blocks                             | #
# +-----------------------------------------------------------------+ #
#######################################################################

Block(-3,8,1,dynamictrees:leaves0:12)
Block(-3,9,1,dynamictrees:leaves0:12)
Block(-2,2,4,dynamictrees:leaves0:12)
Block(-2,2,5,dynamictrees:leaves0:12)
Block(-2,3,4,dynamictrees:leaves0:12)
Block(-2,3,5,dynamictrees:leaves0:12)
Block(-2,4,4,dynamictrees:leaves0:12)
Block(-2,4,5,dynamictrees:leaves0:12)
Block(-2,8,0,dynamictrees:leaves0:12)
Block(-2,8,1,dynamictrees:leaves0:15)
Block(-2,8,2,dynamictrees:leaves0:12)
Block(-2,9,0,dynamictrees:leaves0:12)
Block(-2,9,1,dynamictrees:leaves0:14)
Block(-2,9,2,dynamictrees:leaves0:12)
Block(-2,10,0,dynamictrees:leaves0:12)
Block(-2,10,1,dynamictrees:leaves0:12)
Block(-2,10,2,dynamictrees:leaves0:12)
Block(-2,11,0,dynamictrees:leaves0:12)
Block(-2,11,1,dynamictrees:leaves0:12)
Block(-2,11,2,dynamictrees:leaves0:12)
Block(-1,2,3,dynamictrees:leaves0:12)
Block(-1,2,4,dynamictrees:leaves0:14)
Block(-1,2,5,dynamictrees:leaves0:13)
Block(-1,2,6,dynamictrees:leaves0:12)
Block(-1,3,3,dynamictrees:leaves0:12)
Block(-1,3,4,dynamictrees:leaves0:15)
Block(-1,3,5,dynamictrees:leaves0:14)
Block(-1,3,6,dynamictrees:leaves0:12)
Block(-1,4,3,dynamictrees:leaves0:12)
Block(-1,4,4,dynamictrees:leaves0:14)
Block(-1,4,5,dynamictrees:leaves0:13)
Block(-1,4,6,dynamictrees:leaves0:12)
Block(-1,5,4,dynamictrees:leaves0:12)
Block(-1,5,5,dynamictrees:leaves0:12)
Block(-1,8,-1,dynamictrees:leaves0:12)
Block(-1,8,1,dynamictrees:junglebranch)
Block(-1,9,0,dynamictrees:leaves0:12)
Block(-1,9,1,dynamictrees:leaves0:15)
Block(-1,9,2,dynamictrees:leaves0:12)
Block(-1,10,-1,dynamictrees:leaves0:12)
Block(-1,10,0,dynamictrees:leaves0:14)
Block(-1,10,1,dynamictrees:leaves0:15)
Block(-1,10,2,dynamictrees:leaves0:14)
Block(-1,10,3,dynamictrees:leaves0:12)
Block(-1,11,-1,dynamictrees:leaves0:12)
Block(-1,11,0,dynamictrees:leaves0:13)
Block(-1,11,1,dynamictrees:leaves0:14)
Block(-1,11,2,dynamictrees:leaves0:13)
Block(-1,11,3,dynamictrees:leaves0:12)
Block(-1,12,0,dynamictrees:leaves0:12)
Block(-1,12,1,dynamictrees:leaves0:12)
Block(-1,12,2,dynamictrees:leaves0:12)
Block(0,0,1,dynamictrees:rootydirt:13)
Block(0,1,1,dynamictrees:junglebranch:3)
Block(0,2,1,dynamictrees:junglebranch:3)
Block(0,2,3,dynamictrees:leaves0:12)
Block(0,2,4,dynamictrees:leaves0:15)
Block(0,2,5,dynamictrees:leaves0:14)
Block(0,2,6,dynamictrees:leaves0:12)
Block(0,3,1,dynamictrees:junglebranch:3)
Block(0,3,2,dynamictrees:junglebranch:1)
Block(0,3,3,dynamictrees:junglebranch:1)
Block(0,3,4,dynamictrees:junglebranch)
Block(0,3,5,dynamictrees:leaves0:15)
Block(0,3,6,dynamictrees:leaves0:12)
Block(0,4,1,dynamictrees:junglebranch:2)
Block(0,4,3,dynamictrees:leaves0:12)
Block(0,4,4,dynamictrees:leaves0:15)
Block(0,4,5,dynamictrees:leaves0:14)
Block(0,4,6,dynamictrees:leaves0:12)
Block(0,5,1,dynamictrees:junglebranch:2)
Block(0,5,4,dynamictrees:leaves0:12)
Block(0,5,5,dynamictrees:leaves0:12)
Block(0,6,1,dynamictrees:junglebranch:2)
Block(0,7,1,dynamictrees:junglebranch:2)
Block(0,8,1,dynamictrees:junglebranch:2)
Block(0,9,0,dynamictrees:leaves0:12)
Block(0,9,1,dynamictrees:junglebranch:1)
Block(0,9,2,dynamictrees:leaves0:12)
Block(0,10,-1,dynamictrees:leaves0:12)
Block(0,10,0,dynamictrees:leaves0:15)
Block(0,10,1,dynamictrees:junglebranch)
Block(0,10,2,dynamictrees:leaves0:15)
Block(0,10,3,dynamictrees:leaves0:12)
Block(0,11,-1,dynamictrees:leaves0:12)
Block(0,11,0,dynamictrees:leaves0:14)
Block(0,11,1,dynamictrees:leaves0:15)
Block(0,11,2,dynamictrees:leaves0:14)
Block(0,11,3,dynamictrees:leaves0:12)
Block(0,12,0,dynamictrees:leaves0:12)
Block(0,12,1,dynamictrees:leaves0:12)
Block(0,12,2,dynamictrees:leaves0:12)
Block(1,2,3,dynamictrees:leaves0:12)
Block(1,2,4,dynamictrees:leaves0:14)
Block(1,2,5,dynamictrees:leaves0:13)
Block(1,2,6,dynamictrees:leaves0:12)
Block(1,3,3,dynamictrees:leaves0:12)
Block(1,3,4,dynamictrees:leaves0:15)
Block(1,3,5,dynamictrees:leaves0:14)
Block(1,3,6,dynamictrees:leaves0:12)
Block(1,4,3,dynamictrees:leaves0:12)
Block(1,4,4,dynamictrees:leaves0:14)
Block(1,4,5,dynamictrees:leaves0:13)
Block(1,4,6,dynamictrees:leaves0:12)
Block(1,5,4,dynamictrees:leaves0:12)
Block(1,5,5,dynamictrees:leaves0:12)
Block(1,9,0,dynamictrees:leaves0:12)
Block(1,9,1,dynamictrees:leaves0:12)
Block(1,9,2,dynamictrees:leaves0:12)
Block(1,10,-1,dynamictrees:leaves0:12)
Block(1,10,0,dynamictrees:leaves0:14)
Block(1,10,1,dynamictrees:leaves0:15)
Block(1,10,2,dynamictrees:leaves0:14)
Block(1,10,3,dynamictrees:leaves0:12)
Block(1,11,-1,dynamictrees:leaves0:12)
Block(1,11,0,dynamictrees:leaves0:13)
Block(1,11,1,dynamictrees:leaves0:14)
Block(1,11,2,dynamictrees:leaves0:13)
Block(1,11,3,dynamictrees:leaves0:12)
Block(1,12,0,dynamictrees:leaves0:12)
Block(1,12,1,dynamictrees:leaves0:12)
Block(1,12,2,dynamictrees:leaves0:12)
Block(2,2,4,dynamictrees:leaves0:12)
Block(2,2,5,dynamictrees:leaves0:12)
Block(2,3,4,dynamictrees:leaves0:12)
Block(2,3,5,dynamictrees:leaves0:12)
Block(2,4,4,dynamictrees:leaves0:12)
Block(2,4,5,dynamictrees:leaves0:12)
Block(2,10,0,dynamictrees:leaves0:12)
Block(2,10,1,dynamictrees:leaves0:12)
Block(2,10,2,dynamictrees:leaves0:12)
Block(2,11,0,dynamictrees:leaves0:12)
Block(2,11,1,dynamictrees:leaves0:12)
Block(2,11,2,dynamictrees:leaves0:12)

#######################################################################
# +-----------------------------------------------------------------+ #
# |                            BO3 checks                           | #
# +-----------------------------------------------------------------+ #
#######################################################################

BlockCheck(0,-1,1,GRASS,DIRT,biomesoplenty:grass,biomesoplenty:dirt)

#######################################################################
# +-----------------------------------------------------------------+ #
# |                             Branches                            | #
# +-----------------------------------------------------------------+ #
#######################################################################


#######################################################################
# +-----------------------------------------------------------------+ #
# |                             Entities                            | #
# +-----------------------------------------------------------------+ #
#######################################################################


#######################################################################
# +-----------------------------------------------------------------+ #
# |                            Particles                            | #
# +-----------------------------------------------------------------+ #
#######################################################################


#######################################################################
# +-----------------------------------------------------------------+ #
# |                             Spawners                            | #
# +-----------------------------------------------------------------+ #
#######################################################################


#######################################################################
# +-----------------------------------------------------------------+ #
# |                             ModData                             | #
# +-----------------------------------------------------------------+ #
#######################################################################

