
#######################################################################
# +-----------------------------------------------------------------+ #
# |                            BO3 object                           | #
# +-----------------------------------------------------------------+ #
#######################################################################

Author: NLBlackHeavenNL

Description: No description given

Version: 3

SettingsMode: WriteWithoutComments


#######################################################################
# +-----------------------------------------------------------------+ #
# |                          Main settings                          | #
# +-----------------------------------------------------------------+ #
#######################################################################

Tree: true

Frequency: 1

Rarity: 100.0

RotateRandomly: false

SpawnHeight: highestSolidBlock

SpawnHeightOffset: -1

SpawnHeightVariance: 0

##############################
# Height Limits for the BO3. #
##############################

MinHeight: 0

MaxHeight: 255

######################
# Extrusion settings #
######################

ExtrudeMode: None

ExtrudeThroughBlocks: AIR

MaxBranchDepth: 10

ExcludedBiomes: All


#######################################################################
# +-----------------------------------------------------------------+ #
# |                      Source block settings                      | #
# +-----------------------------------------------------------------+ #
#######################################################################

SourceBlocks: AIR,GRASS,DIRT,biomesoplenty:dirt

MaxPercentageOutsideSourceBlock: 0

OutsideSourceBlock: placeAnyway

DoReplaceBlocks: true

IsOTGPlus: false


#######################################################################
# +-----------------------------------------------------------------+ #
# |                              Blocks                             | #
# +-----------------------------------------------------------------+ #
#######################################################################

Block(-2,14,0,dynamictrees:leaves0:12)
Block(-2,14,1,dynamictrees:leaves0:12)
Block(-2,15,0,dynamictrees:leaves0:12)
Block(-2,15,1,dynamictrees:leaves0:12)
Block(-2,15,2,dynamictrees:leaves0:12)
Block(-2,16,0,dynamictrees:leaves0:12)
Block(-2,16,1,dynamictrees:leaves0:12)
Block(-2,16,2,dynamictrees:leaves0:12)
Block(-1,13,2,dynamictrees:leaves0:12)
Block(-1,14,-1,dynamictrees:leaves0:12)
Block(-1,14,0,dynamictrees:leaves0:14)
Block(-1,14,1,dynamictrees:leaves0:12)
Block(-1,14,2,dynamictrees:leaves0:12)
Block(-1,15,-1,dynamictrees:leaves0:12)
Block(-1,15,0,dynamictrees:leaves0:14)
Block(-1,15,1,dynamictrees:leaves0:15)
Block(-1,15,2,dynamictrees:leaves0:14)
Block(-1,15,3,dynamictrees:leaves0:12)
Block(-1,16,-1,dynamictrees:leaves0:12)
Block(-1,16,0,dynamictrees:leaves0:13)
Block(-1,16,1,dynamictrees:leaves0:14)
Block(-1,16,2,dynamictrees:leaves0:13)
Block(-1,16,3,dynamictrees:leaves0:12)
Block(-1,17,0,dynamictrees:leaves0:12)
Block(-1,17,1,dynamictrees:leaves0:12)
Block(-1,17,2,dynamictrees:leaves0:12)
Block(0,0,1,dynamictrees:rootydirt:0)
Block(0,1,1,dynamictrees:junglebranch:4)
Block(0,2,1,dynamictrees:junglebranch:4)
Block(0,3,1,dynamictrees:junglebranch:4)
Block(0,4,1,dynamictrees:junglebranch:4)
Block(0,5,1,dynamictrees:junglebranch:3)
Block(0,6,1,dynamictrees:junglebranch:2)
Block(0,7,1,dynamictrees:junglebranch:2)
Block(0,8,1,dynamictrees:junglebranch:2)
Block(0,9,1,dynamictrees:junglebranch:2)
Block(0,10,1,dynamictrees:junglebranch:2)
Block(0,11,1,dynamictrees:junglebranch:1)
Block(0,12,1,dynamictrees:junglebranch:1)
Block(0,13,1,dynamictrees:junglebranch:1)
Block(0,14,-1,dynamictrees:leaves0:12)
Block(0,14,0,dynamictrees:leaves0:12)
Block(0,14,1,dynamictrees:junglebranch:1)
Block(0,14,2,dynamictrees:leaves0:12)
Block(0,15,-1,dynamictrees:leaves0:12)
Block(0,15,0,dynamictrees:leaves0:15)
Block(0,15,1,dynamictrees:junglebranch)
Block(0,15,2,dynamictrees:leaves0:15)
Block(0,15,3,dynamictrees:leaves0:12)
Block(0,16,-1,dynamictrees:leaves0:12)
Block(0,16,0,dynamictrees:leaves0:14)
Block(0,16,1,dynamictrees:leaves0:15)
Block(0,16,2,dynamictrees:leaves0:14)
Block(0,16,3,dynamictrees:leaves0:12)
Block(0,17,0,dynamictrees:leaves0:12)
Block(0,17,1,dynamictrees:leaves0:12)
Block(0,17,2,dynamictrees:leaves0:12)
Block(1,14,0,dynamictrees:leaves0:12)
Block(1,14,1,dynamictrees:leaves0:12)
Block(1,14,2,dynamictrees:leaves0:12)
Block(1,15,-1,dynamictrees:leaves0:12)
Block(1,15,0,dynamictrees:leaves0:14)
Block(1,15,1,dynamictrees:leaves0:15)
Block(1,15,2,dynamictrees:leaves0:14)
Block(1,15,3,dynamictrees:leaves0:12)
Block(1,16,-1,dynamictrees:leaves0:12)
Block(1,16,0,dynamictrees:leaves0:13)
Block(1,16,1,dynamictrees:leaves0:14)
Block(1,16,2,dynamictrees:leaves0:13)
Block(1,16,3,dynamictrees:leaves0:12)
Block(1,17,0,dynamictrees:leaves0:12)
Block(1,17,1,dynamictrees:leaves0:12)
Block(1,17,2,dynamictrees:leaves0:12)
Block(2,14,1,dynamictrees:leaves0:12)
Block(2,15,0,dynamictrees:leaves0:12)
Block(2,15,1,dynamictrees:leaves0:12)
Block(2,15,2,dynamictrees:leaves0:12)
Block(2,16,0,dynamictrees:leaves0:12)
Block(2,16,1,dynamictrees:leaves0:12)
Block(2,16,2,dynamictrees:leaves0:12)

#######################################################################
# +-----------------------------------------------------------------+ #
# |                            BO3 checks                           | #
# +-----------------------------------------------------------------+ #
#######################################################################

BlockCheck(0,-1,1,GRASS,DIRT,biomesoplenty:grass,biomesoplenty:dirt)

#######################################################################
# +-----------------------------------------------------------------+ #
# |                             Branches                            | #
# +-----------------------------------------------------------------+ #
#######################################################################


#######################################################################
# +-----------------------------------------------------------------+ #
# |                             Entities                            | #
# +-----------------------------------------------------------------+ #
#######################################################################


#######################################################################
# +-----------------------------------------------------------------+ #
# |                            Particles                            | #
# +-----------------------------------------------------------------+ #
#######################################################################


#######################################################################
# +-----------------------------------------------------------------+ #
# |                             Spawners                            | #
# +-----------------------------------------------------------------+ #
#######################################################################


#######################################################################
# +-----------------------------------------------------------------+ #
# |                             ModData                             | #
# +-----------------------------------------------------------------+ #
#######################################################################

