
#######################################################################
# +-----------------------------------------------------------------+ #
# |                            BO4 object                           | #
# +-----------------------------------------------------------------+ #
#######################################################################

Author: NLBlackEagle

Description: No description given

SettingsMode: WriteDisable


#######################################################################
# +-----------------------------------------------------------------+ #
# |                          Main settings                          | #
# +-----------------------------------------------------------------+ #
#######################################################################

Frequency: 0

SpawnHeight: highestBlock

UseCenterForHighestBlock: true

##############################
# Height Limits for the BO4. #
##############################

MinHeight: 0

MaxHeight: 255

InheritBO3: 

InheritBO3Rotation: NORTH

OverrideChildSettings: true

OverrideParentHeight: false

CanOverride: false

BranchFrequency: 0

BranchFrequencyGroup: 

MustBeBelowOther: false

MustBeInside: 

CannotBeInside: 

ReplacesBO3: 

MustBeInsideWorldBorders: false

CanSpawnOnWater: true

SpawnOnWaterOnly: false

SpawnUnderWater: false

SpawnAtWaterLevel: false

HeightOffset: 0

RemoveAir: true

ReplaceAbove: 

ReplaceBelow: 

ReplaceWithBiomeBlocks: true

ReplaceWithSurfaceBlock: GRASS

ReplaceWithGroundBlock: DIRT

ReplaceWithStoneBlock: STONE

SmoothRadius: 0

SmoothHeightOffset: 0

SmoothStartTop: false

SmoothStartWood: false

SmoothingSurfaceBlock: 

SmoothingGroundBlock: 

BO3Group: 

IsSpawnPoint: false

DoReplaceBlocks: true


#######################################################################
# +-----------------------------------------------------------------+ #
# |                              Blocks                             | #
# +-----------------------------------------------------------------+ #
#######################################################################

Block(-8,-3,3,LOG:13)
Block(-8,-2,3,LOG:13)
Block(-8,-1,-3,LOG:13)
Block(-8,-1,-2,LOG:13)
Block(-8,-1,3,LOG:13)
Block(-8,0,-7,LOG:13)
Block(-8,0,-6,LOG:13)
Block(-8,0,2,LOG:13)
Block(-8,0,3,LOG:13)
Block(-8,1,-7,LOG:13)
Block(-8,1,-6,LOG:13)
Block(-8,1,-5,LOG:13)
Block(-8,1,1,LOG:13)
Block(-8,1,2,LOG:13)
Block(-8,1,3,LOG:13)
Block(-8,2,-7,LOG:13)
Block(-8,2,-6,LOG:13)
Block(-8,2,-5,LOG:13)
Block(-8,2,2,minecraft:black_glazed_terracotta:3)
Block(-8,3,-7,minecraft:black_glazed_terracotta:3)
Block(-8,3,-6,LOG:13)
Block(-8,11,-7,LEAVES:12)
Block(-8,12,-7,LOG:13)
Block(-8,12,-6,LOG:13)
Block(-8,13,-7,LOG:13)
Block(-8,13,-6,LOG:13)
Block(-8,13,-5,LEAVES:12)
Block(-8,14,-7,LOG:13)
Block(-8,14,-6,LEAVES:12)
Block(-8,14,-5,LEAVES:12)
Block(-8,14,-4,LEAVES:12)
Block(-8,15,-7,LEAVES:12)
Block(-8,15,-6,LEAVES:12)
Block(-8,15,-5,LEAVES:12)
Block(-8,15,-4,LEAVES:12)
Block(-8,15,-3,LEAVES:12)
Block(-8,16,-7,LEAVES:12)
Block(-8,16,-6,LEAVES:12)
Block(-8,16,-4,LEAVES:12)
Block(-8,20,0,LEAVES:12)
Block(-8,20,1,LEAVES:12)
Block(-8,20,2,LEAVES:12)
Block(-8,20,3,LEAVES:12)
Block(-8,20,5,LEAVES:12)
Block(-8,20,8,LEAVES:12)
Block(-8,21,0,LEAVES:12)
Block(-8,21,1,LEAVES:12)
Block(-8,21,2,LEAVES:12)
Block(-8,21,3,LEAVES:12)
Block(-8,21,4,LEAVES:12)
Block(-8,21,6,LEAVES:12)
Block(-8,21,7,LEAVES:12)
Block(-8,21,8,LEAVES:12)
Block(-8,22,0,LEAVES:12)
Block(-8,22,1,LEAVES:12)
Block(-8,22,2,LEAVES:12)
Block(-8,22,3,LEAVES:12)
Block(-8,22,4,LEAVES:12)
Block(-8,22,5,LOG:13)
Block(-8,22,6,LOG:13)
Block(-8,22,7,LEAVES:12)
Block(-8,22,8,LEAVES:12)
Block(-8,23,2,LEAVES:12)
Block(-8,23,3,LEAVES:12)
Block(-8,23,4,LEAVES:12)
Block(-8,23,5,LEAVES:12)
Block(-8,23,6,LEAVES:12)
Block(-8,23,7,LEAVES:12)
Block(-8,23,8,LEAVES:12)
Block(-8,24,5,LEAVES:12)
Block(-8,24,6,LEAVES:12)
Block(-8,24,7,LEAVES:12)
Block(-8,24,8,LEAVES:12)
Block(-7,-5,-5,LOG:13)
Block(-7,-4,-5,LOG:13)
Block(-7,-4,-3,LOG:13)
Block(-7,-3,-5,LOG:13)
Block(-7,-3,-3,LOG:13)
Block(-7,-2,-5,LOG:13)
Block(-7,-2,-3,LOG:13)
Block(-7,-1,-5,LOG:13)
Block(-7,-1,-3,LOG:13)
Block(-7,0,-6,LOG:13)
Block(-7,0,-5,LOG:13)
Block(-7,0,-3,LOG:13)
Block(-7,0,1,LOG:13)
Block(-7,0,2,LOG_2:13)
Block(-7,1,-7,LOG:13)
Block(-7,1,-6,LOG:13)
Block(-7,1,-5,LOG:13)
Block(-7,1,-4,LOG:13)
Block(-7,1,-3,LOG:13)
Block(-7,1,0,LOG:13)
Block(-7,1,1,LOG:13)
Block(-7,1,2,LOG:13)
Block(-7,2,-7,LOG:13)
Block(-7,2,-6,LOG:13)
Block(-7,2,-5,LOG:13)
Block(-7,2,-4,LOG:13)
Block(-7,2,1,minecraft:black_glazed_terracotta:3)
Block(-7,3,-6,LOG:13)
Block(-7,3,-5,LOG:13)
Block(-7,4,-6,minecraft:black_glazed_terracotta:3)
Block(-7,10,-7,LOG_2:13)
Block(-7,10,-6,LEAVES:12)
Block(-7,11,-7,LOG:13)
Block(-7,11,-6,LOG:13)
Block(-7,11,-5,LOG_2:13)
Block(-7,12,-7,LOG:13)
Block(-7,12,-6,LOG_2:13)
Block(-7,12,-5,LEAVES:12)
Block(-7,13,-7,LOG:13)
Block(-7,13,-6,LOG:13)
Block(-7,14,-7,LOG_2:13)
Block(-7,14,-6,LEAVES:12)
Block(-7,14,-5,LEAVES:12)
Block(-7,15,-6,LEAVES:12)
Block(-7,15,-4,LEAVES:12)
Block(-7,16,4,LEAVES:12)
Block(-7,17,4,LEAVES:12)
Block(-7,18,4,LEAVES:12)
Block(-7,19,3,LEAVES:12)
Block(-7,19,4,LEAVES:12)
Block(-7,20,1,LEAVES:12)
Block(-7,20,2,LEAVES:12)
Block(-7,20,5,LEAVES:12)
Block(-7,21,0,LEAVES:12)
Block(-7,21,1,LEAVES:12)
Block(-7,21,2,LEAVES:12)
Block(-7,21,3,LEAVES:12)
Block(-7,21,4,LEAVES:12)
Block(-7,21,5,LEAVES:12)
Block(-7,21,6,LEAVES:12)
Block(-7,21,7,LEAVES:12)
Block(-7,21,8,LEAVES:12)
Block(-7,22,1,LEAVES:12)
Block(-7,22,2,LEAVES:12)
Block(-7,22,3,LEAVES:12)
Block(-7,22,4,LOG:13)
Block(-7,22,5,LOG:13)
Block(-7,22,6,LEAVES:12)
Block(-7,22,7,LEAVES:12)
Block(-7,22,8,LEAVES:12)
Block(-7,23,3,LEAVES:12)
Block(-7,23,4,LEAVES:12)
Block(-7,23,5,LEAVES:12)
Block(-7,23,6,LEAVES:12)
Block(-7,23,7,LEAVES:12)
Block(-7,23,8,LEAVES:12)
Block(-7,24,5,LEAVES:12)
Block(-7,24,6,LEAVES:12)
Block(-7,24,7,LEAVES:12)
Block(-6,-4,2,LOG:13)
Block(-6,-3,2,LOG:13)
Block(-6,-2,2,LOG:13)
Block(-6,-1,2,LOG:13)
Block(-6,0,-6,LOG:13)
Block(-6,0,-5,LOG:13)
Block(-6,0,0,LOG:13)
Block(-6,0,1,LOG:13)
Block(-6,0,2,LOG:13)
Block(-6,1,-7,LOG:13)
Block(-6,1,-6,LOG:13)
Block(-6,1,-5,LOG_2:13)
Block(-6,1,-4,LOG_2:13)
Block(-6,1,-3,LOG:13)
Block(-6,1,-2,LOG_2:13)
Block(-6,1,-1,LOG:13)
Block(-6,1,0,LOG:13)
Block(-6,1,1,LOG:13)
Block(-6,1,2,LOG_2:13)
Block(-6,2,-6,LOG:13)
Block(-6,2,-5,LOG:13)
Block(-6,2,-4,LOG:13)
Block(-6,2,-3,LOG:13)
Block(-6,2,-2,LOG_2:13)
Block(-6,2,0,minecraft:black_glazed_terracotta:3)
Block(-6,2,1,LOG_2:13)
Block(-6,3,-6,LOG:13)
Block(-6,3,-5,LOG:13)
Block(-6,3,-4,LOG:13)
Block(-6,3,-3,LOG:13)
Block(-6,4,-6,LOG:13)
Block(-6,4,-5,LOG:13)
Block(-6,8,-7,LOG:13)
Block(-6,8,-6,LEAVES:12)
Block(-6,9,-7,LOG:13)
Block(-6,9,-6,LOG:13)
Block(-6,10,-7,LOG_2:13)
Block(-6,10,-6,LOG:13)
Block(-6,10,-5,LOG_2:13)
Block(-6,10,-4,LEAVES:12)
Block(-6,11,-7,LOG:13)
Block(-6,11,-6,LOG_2:13)
Block(-6,11,-5,LOG:13)
Block(-6,11,-4,LOG:13)
Block(-6,12,-7,LOG:13)
Block(-6,12,-6,LOG:13)
Block(-6,12,-5,LOG_2:13)
Block(-6,12,-4,LOG_2:13)
Block(-6,13,-7,LOG_2:13)
Block(-6,13,-6,LOG:13)
Block(-6,13,-5,LOG:13)
Block(-6,14,-7,LEAVES:12)
Block(-6,14,-6,LOG_2:13)
Block(-6,17,6,LEAVES:12)
Block(-6,18,6,LEAVES:12)
Block(-6,19,5,LEAVES:12)
Block(-6,19,6,LEAVES:12)
Block(-6,20,1,LEAVES:12)
Block(-6,20,2,LEAVES:12)
Block(-6,20,3,LEAVES:12)
Block(-6,20,4,LEAVES:12)
Block(-6,20,6,LEAVES:12)
Block(-6,20,8,LEAVES:12)
Block(-6,21,-1,LEAVES:12)
Block(-6,21,0,LEAVES:12)
Block(-6,21,1,LEAVES:12)
Block(-6,21,2,LEAVES:12)
Block(-6,21,3,LOG:13)
Block(-6,21,4,LOG:13)
Block(-6,21,5,LEAVES:12)
Block(-6,21,6,LEAVES:12)
Block(-6,21,7,LEAVES:12)
Block(-6,21,8,LEAVES:12)
Block(-6,22,1,LEAVES:12)
Block(-6,22,2,LEAVES:12)
Block(-6,22,3,LEAVES:12)
Block(-6,22,4,LOG:13)
Block(-6,22,5,LEAVES:12)
Block(-6,22,6,LEAVES:12)
Block(-6,22,7,LEAVES:12)
Block(-6,22,8,LEAVES:12)
Block(-6,23,3,LEAVES:12)
Block(-6,23,4,LEAVES:12)
Block(-6,23,5,LEAVES:12)
Block(-6,23,6,LEAVES:12)
Block(-6,23,7,LEAVES:12)
Block(-6,23,8,LEAVES:12)
Block(-6,24,6,LEAVES:12)
Block(-5,-4,-2,LOG:13)
Block(-5,-3,-2,LOG:13)
Block(-5,-2,-2,LOG:13)
Block(-5,-1,-2,LOG:13)
Block(-5,0,-4,LOG:13)
Block(-5,0,-2,LOG:13)
Block(-5,0,-1,LOG:13)
Block(-5,0,0,LOG:13)
Block(-5,1,-6,LOG:13)
Block(-5,1,-5,LOG:13)
Block(-5,1,-4,LOG:13)
Block(-5,1,-3,LOG:13)
Block(-5,1,-2,LOG_2:13)
Block(-5,1,-1,LOG:13)
Block(-5,1,0,LOG:13)
Block(-5,1,1,LOG:13)
Block(-5,2,-6,LOG:13)
Block(-5,2,-5,LOG:13)
Block(-5,2,-4,LOG:13)
Block(-5,2,-3,LOG:13)
Block(-5,2,-2,LOG:13)
Block(-5,2,-1,LOG:13)
Block(-5,2,0,LOG_2:13)
Block(-5,2,1,LOG:13)
Block(-5,3,-6,LOG:13)
Block(-5,3,-5,LOG:13)
Block(-5,3,-4,LOG:13)
Block(-5,3,-3,LOG:13)
Block(-5,3,-2,LOG:13)
Block(-5,3,-1,LOG:13)
Block(-5,3,0,minecraft:black_glazed_terracotta:3)
Block(-5,4,-5,LOG:13)
Block(-5,4,-4,LOG:13)
Block(-5,4,-3,LOG:13)
Block(-5,4,-1,minecraft:black_glazed_terracotta:3)
Block(-5,5,-5,minecraft:black_glazed_terracotta:3)
Block(-5,5,-4,LOG:13)
Block(-5,6,-6,LOG:13)
Block(-5,6,-5,minecraft:black_glazed_terracotta:3)
Block(-5,6,-4,minecraft:black_glazed_terracotta:3)
Block(-5,7,-6,LOG:13)
Block(-5,7,-5,minecraft:black_glazed_terracotta:3)
Block(-5,7,-4,LOG:13)
Block(-5,8,-6,LOG:13)
Block(-5,8,-5,LOG_2:13)
Block(-5,8,-4,minecraft:black_glazed_terracotta:3)
Block(-5,8,-3,LOG:13)
Block(-5,9,-7,LOG_2:13)
Block(-5,9,-6,LOG:13)
Block(-5,9,-5,LOG_2:13)
Block(-5,9,-4,minecraft:black_glazed_terracotta:3)
Block(-5,9,-3,LOG:13)
Block(-5,10,-7,LOG_2:13)
Block(-5,10,-6,LOG:13)
Block(-5,10,-5,LOG_2:13)
Block(-5,10,-4,LOG_2:13)
Block(-5,10,-3,minecraft:black_glazed_terracotta:3)
Block(-5,11,-7,LOG:13)
Block(-5,11,-6,LOG_2:13)
Block(-5,11,-5,LOG:13)
Block(-5,11,-4,LOG:13)
Block(-5,11,-3,minecraft:black_glazed_terracotta:3)
Block(-5,11,-2,LEAVES:12)
Block(-5,12,-6,LOG_2:13)
Block(-5,12,-5,LOG_2:13)
Block(-5,12,-4,LOG:13)
Block(-5,12,-3,minecraft:black_glazed_terracotta:3)
Block(-5,12,-2,LOG:13)
Block(-5,13,-7,LEAVES:12)
Block(-5,13,-5,LOG:13)
Block(-5,13,-4,LOG:13)
Block(-5,13,-3,minecraft:black_glazed_terracotta:3)
Block(-5,13,-2,LOG_2:13)
Block(-5,14,-3,LOG:13)
Block(-5,14,-2,minecraft:black_glazed_terracotta:3)
Block(-5,14,-1,LEAVES:12)
Block(-5,15,-2,LOG_2:13)
Block(-5,15,-1,minecraft:black_glazed_terracotta:3)
Block(-5,16,-1,minecraft:black_glazed_terracotta:3)
Block(-5,16,0,LEAVES:12)
Block(-5,17,0,minecraft:black_glazed_terracotta:3)
Block(-5,18,1,LEAVES:12)
Block(-5,19,1,LEAVES:12)
Block(-5,19,2,LEAVES:12)
Block(-5,19,4,LEAVES:12)
Block(-5,19,6,LEAVES:12)
Block(-5,20,0,LEAVES:12)
Block(-5,20,1,LEAVES:12)
Block(-5,20,2,LEAVES:12)
Block(-5,20,3,LEAVES:12)
Block(-5,20,4,LEAVES:12)
Block(-5,20,6,LEAVES:12)
Block(-5,20,7,LEAVES:12)
Block(-5,20,8,LEAVES:12)
Block(-5,21,0,LEAVES:12)
Block(-5,21,1,LEAVES:12)
Block(-5,21,2,LOG:13)
Block(-5,21,3,LOG_2:13)
Block(-5,21,4,LEAVES:12)
Block(-5,21,5,LEAVES:12)
Block(-5,21,6,LEAVES:12)
Block(-5,21,7,LEAVES:12)
Block(-5,21,8,LEAVES:12)
Block(-5,22,0,LEAVES:12)
Block(-5,22,1,LEAVES:12)
Block(-5,22,2,LEAVES:12)
Block(-5,22,3,LEAVES:12)
Block(-5,22,4,LEAVES:12)
Block(-5,22,5,LEAVES:12)
Block(-5,22,6,LEAVES:12)
Block(-5,22,7,LEAVES:12)
Block(-5,22,8,LEAVES:12)
Block(-5,23,4,LEAVES:12)
Block(-5,23,5,LEAVES:12)
Block(-5,23,6,LEAVES:12)
Block(-5,23,7,LEAVES:12)
Block(-5,23,8,LEAVES:12)
Block(-4,-1,-7,LOG:13)
Block(-4,0,-5,LOG:13)
Block(-4,0,-4,LOG:13)
Block(-4,0,-1,LOG_2:13)
Block(-4,1,-6,LOG:13)
Block(-4,1,-5,LOG:13)
Block(-4,1,-4,LOG:13)
Block(-4,1,-3,LOG:13)
Block(-4,1,-2,LOG:13)
Block(-4,1,-1,LOG:13)
Block(-4,1,0,LOG_2:13)
Block(-4,1,1,LOG:13)
Block(-4,2,-6,LOG:13)
Block(-4,2,-5,LOG:13)
Block(-4,2,-4,LOG:13)
Block(-4,2,-2,LOG:13)
Block(-4,2,-1,LOG:13)
Block(-4,2,0,LOG:13)
Block(-4,3,-5,LOG_2:13)
Block(-4,3,-4,LOG:13)
Block(-4,3,-3,LOG:13)
Block(-4,3,-2,LOG:13)
Block(-4,3,-1,LOG:13)
Block(-4,4,-5,LOG:13)
Block(-4,4,-4,LOG:13)
Block(-4,4,-3,LOG_2:13)
Block(-4,4,-2,LOG_2:13)
Block(-4,5,-5,LOG:13)
Block(-4,5,-4,LOG:13)
Block(-4,5,-3,LOG:13)
Block(-4,5,-2,minecraft:black_glazed_terracotta:3)
Block(-4,6,-5,LOG:13)
Block(-4,6,-4,LOG:13)
Block(-4,6,-3,minecraft:black_glazed_terracotta:3)
Block(-4,7,-6,LOG:13)
Block(-4,7,-5,LOG:13)
Block(-4,7,-4,LOG:13)
Block(-4,7,-3,LOG:13)
Block(-4,8,-6,LOG_2:13)
Block(-4,8,-5,LOG:13)
Block(-4,8,-4,LOG:13)
Block(-4,8,-3,LOG:13)
Block(-4,9,-6,LOG_2:13)
Block(-4,9,-5,LOG_2:13)
Block(-4,9,-4,LOG:13)
Block(-4,9,-3,LOG:13)
Block(-4,9,-2,LOG_2:13)
Block(-4,10,-6,LOG:13)
Block(-4,10,-5,LOG:13)
Block(-4,10,-4,LOG_2:13)
Block(-4,10,-3,LOG:13)
Block(-4,10,-2,LOG:13)
Block(-4,11,-5,LOG:13)
Block(-4,11,-4,LOG:13)
Block(-4,11,-3,LOG:13)
Block(-4,11,-2,LOG:13)
Block(-4,11,-1,LOG:13)
Block(-4,12,-5,LOG_2:13)
Block(-4,12,-4,LOG_2:13)
Block(-4,12,-3,LOG:13)
Block(-4,12,-2,LOG:13)
Block(-4,12,-1,LOG:13)
Block(-4,13,-4,LOG:13)
Block(-4,13,-3,LOG:13)
Block(-4,13,-2,LOG_2:13)
Block(-4,13,-1,LOG:13)
Block(-4,14,-4,LOG:13)
Block(-4,14,-3,LOG:13)
Block(-4,14,-2,LOG:13)
Block(-4,14,-1,LOG:13)
Block(-4,15,-3,LOG:13)
Block(-4,15,-2,LOG:13)
Block(-4,15,-1,LOG_2:13)
Block(-4,15,0,LEAVES:12)
Block(-4,15,3,LEAVES:12)
Block(-4,16,-2,LOG:13)
Block(-4,16,-1,LOG_2:13)
Block(-4,16,0,LOG:13)
Block(-4,16,3,LEAVES:12)
Block(-4,17,-2,LEAVES:12)
Block(-4,17,-1,LOG:13)
Block(-4,17,0,LOG:13)
Block(-4,17,1,LEAVES:12)
Block(-4,17,3,LEAVES:12)
Block(-4,18,-1,LEAVES:12)
Block(-4,18,0,LOG_2:13)
Block(-4,18,1,LOG:13)
Block(-4,18,3,LEAVES:12)
Block(-4,19,0,LEAVES:12)
Block(-4,19,1,LOG:13)
Block(-4,19,2,LEAVES:12)
Block(-4,19,3,LEAVES:12)
Block(-4,19,7,LEAVES:12)
Block(-4,19,8,LEAVES:12)
Block(-4,20,0,LEAVES:12)
Block(-4,20,1,LOG_2:13)
Block(-4,20,2,LOG_2:13)
Block(-4,20,3,LEAVES:12)
Block(-4,20,5,LEAVES:12)
Block(-4,20,6,LEAVES:12)
Block(-4,20,7,LEAVES:12)
Block(-4,20,8,LEAVES:12)
Block(-4,21,0,LEAVES:12)
Block(-4,21,1,LEAVES:12)
Block(-4,21,2,LOG:13)
Block(-4,21,3,LEAVES:12)
Block(-4,21,4,LEAVES:12)
Block(-4,21,5,LEAVES:12)
Block(-4,21,6,LEAVES:12)
Block(-4,21,7,LEAVES:12)
Block(-4,21,8,LEAVES:12)
Block(-4,22,1,LEAVES:12)
Block(-4,22,2,LEAVES:12)
Block(-4,22,3,LEAVES:12)
Block(-4,22,4,LEAVES:12)
Block(-4,22,5,LEAVES:12)
Block(-4,22,6,LEAVES:12)
Block(-4,22,7,LOG:13)
Block(-4,22,8,LOG:13)
Block(-4,23,4,LEAVES:12)
Block(-4,23,5,LEAVES:12)
Block(-4,23,6,LEAVES:12)
Block(-4,23,7,LEAVES:12)
Block(-4,23,8,LEAVES:12)
Block(-4,24,7,LEAVES:12)
Block(-3,-6,-7,LOG:13)
Block(-3,-5,-7,LOG:13)
Block(-3,-4,-7,LOG:13)
Block(-3,-3,-7,LOG:13)
Block(-3,-2,-7,LOG:13)
Block(-3,-1,-7,LOG_2:13)
Block(-3,-1,-6,LOG_2:13)
Block(-3,-1,-1,LOG:13)
Block(-3,0,-6,LOG_2:13)
Block(-3,0,-5,LOG:13)
Block(-3,0,-4,LOG:13)
Block(-3,1,-6,LOG:13)
Block(-3,1,-5,LOG:13)
Block(-3,1,-4,LOG:13)
Block(-3,1,-3,LOG_2:13)
Block(-3,1,-2,LOG:13)
Block(-3,1,-1,LOG_2:13)
Block(-3,1,0,LOG_2:13)
Block(-3,2,-5,LOG:13)
Block(-3,2,-4,LOG:13)
Block(-3,2,-3,LOG:13)
Block(-3,2,-2,LOG:13)
Block(-3,2,-1,LOG:13)
Block(-3,2,0,LOG_2:13)
Block(-3,3,-5,LOG:13)
Block(-3,3,-4,LOG:13)
Block(-3,3,-3,LOG:13)
Block(-3,3,-2,LOG:13)
Block(-3,3,-1,LOG:13)
Block(-3,4,-5,LOG:13)
Block(-3,4,-4,LOG:13)
Block(-3,4,-3,LOG:13)
Block(-3,4,-2,LOG:13)
Block(-3,5,-5,LOG:13)
Block(-3,5,-4,LOG:13)
Block(-3,5,-3,LOG:13)
Block(-3,5,-2,LOG:13)
Block(-3,6,-5,LOG:13)
Block(-3,6,-4,LOG_2:13)
Block(-3,6,-3,LOG:13)
Block(-3,6,-2,LOG:13)
Block(-3,7,-6,LEAVES:12)
Block(-3,7,-5,LOG_2:13)
Block(-3,7,-4,LOG:13)
Block(-3,7,-3,LOG:13)
Block(-3,7,-2,LOG_2:13)
Block(-3,8,-7,LEAVES:12)
Block(-3,8,-6,LOG:13)
Block(-3,8,-5,LOG:13)
Block(-3,8,-4,LOG:13)
Block(-3,8,-3,LOG:13)
Block(-3,8,-2,LOG:13)
Block(-3,9,-6,LOG:13)
Block(-3,9,-5,LOG:13)
Block(-3,9,-4,LOG:13)
Block(-3,9,-3,LOG:13)
Block(-3,9,-2,LOG:13)
Block(-3,10,-7,LEAVES:12)
Block(-3,10,-5,LOG:13)
Block(-3,10,-4,LOG_2:13)
Block(-3,10,-3,LOG:13)
Block(-3,10,-2,LOG:13)
Block(-3,11,-7,LEAVES:12)
Block(-3,11,-6,LEAVES:12)
Block(-3,11,-5,LOG:13)
Block(-3,11,-4,LOG_2:13)
Block(-3,11,-3,LOG:13)
Block(-3,11,-2,LOG_2:13)
Block(-3,12,-7,LEAVES:12)
Block(-3,12,-4,LOG_2:13)
Block(-3,12,-3,LOG:13)
Block(-3,12,-2,LOG_2:13)
Block(-3,13,-4,LOG:13)
Block(-3,13,-3,LOG:13)
Block(-3,13,-2,LOG:13)
Block(-3,13,-1,LOG:13)
Block(-3,14,-3,LOG:13)
Block(-3,14,-2,LOG:13)
Block(-3,14,-1,LOG:13)
Block(-3,14,0,LEAVES:12)
Block(-3,15,-3,LOG_2:13)
Block(-3,15,-2,LOG:13)
Block(-3,15,-1,LOG_2:13)
Block(-3,15,0,LOG:13)
Block(-3,15,1,LEAVES:12)
Block(-3,16,-3,LOG:13)
Block(-3,16,-2,LOG:13)
Block(-3,16,-1,LOG:13)
Block(-3,16,0,LOG_2:13)
Block(-3,16,1,LOG:13)
Block(-3,17,-2,LOG:13)
Block(-3,17,-1,LOG:13)
Block(-3,17,0,LOG:13)
Block(-3,17,1,LOG:13)
Block(-3,17,2,LEAVES:12)
Block(-3,17,6,LEAVES:12)
Block(-3,18,-2,LEAVES:12)
Block(-3,18,-1,LOG_2:13)
Block(-3,18,0,LOG:13)
Block(-3,18,1,LOG_2:13)
Block(-3,18,2,LEAVES:12)
Block(-3,18,6,LEAVES:12)
Block(-3,19,-1,LEAVES:12)
Block(-3,19,0,LOG:13)
Block(-3,19,1,LOG:13)
Block(-3,19,2,LOG:13)
Block(-3,19,6,LEAVES:12)
Block(-3,19,7,LEAVES:12)
Block(-3,19,8,LEAVES:12)
Block(-3,20,0,LEAVES:12)
Block(-3,20,1,LOG:13)
Block(-3,20,2,LOG:13)
Block(-3,20,4,LEAVES:12)
Block(-3,20,5,LEAVES:12)
Block(-3,20,6,LEAVES:12)
Block(-3,20,7,LEAVES:12)
Block(-3,20,8,LEAVES:12)
Block(-3,21,0,LEAVES:12)
Block(-3,21,1,LEAVES:12)
Block(-3,21,2,LEAVES:12)
Block(-3,21,3,LEAVES:12)
Block(-3,21,4,LEAVES:12)
Block(-3,21,5,LOG:13)
Block(-3,21,6,LOG:13)
Block(-3,21,7,LEAVES:12)
Block(-3,21,8,LEAVES:12)
Block(-3,22,0,LEAVES:12)
Block(-3,22,1,LEAVES:12)
Block(-3,22,2,LEAVES:12)
Block(-3,22,3,LEAVES:12)
Block(-3,22,4,LEAVES:12)
Block(-3,22,5,LEAVES:12)
Block(-3,22,6,LEAVES:12)
Block(-3,22,7,LOG:13)
Block(-3,22,8,LEAVES:12)
Block(-3,23,3,LEAVES:12)
Block(-3,23,4,LEAVES:12)
Block(-3,23,5,LEAVES:12)
Block(-3,23,6,LEAVES:12)
Block(-3,23,7,LEAVES:12)
Block(-3,23,8,LEAVES:12)
Block(-3,24,6,LEAVES:12)
Block(-3,24,7,LEAVES:12)
Block(-3,24,8,LEAVES:12)
Block(-3,25,8,LEAVES:12)
Block(-2,0,-3,LOG:13)
Block(-2,0,-1,LOG:13)
Block(-2,0,0,LOG:13)
Block(-2,1,-5,LOG:13)
Block(-2,1,-4,LOG:13)
Block(-2,1,-3,LOG:13)
Block(-2,1,-2,LOG:13)
Block(-2,1,-1,LOG:13)
Block(-2,1,0,LOG:13)
Block(-2,2,-5,LOG:13)
Block(-2,2,-4,LOG:13)
Block(-2,2,-3,LOG:13)
Block(-2,2,-2,LOG_2:13)
Block(-2,2,-1,LOG:13)
Block(-2,3,-5,minecraft:black_glazed_terracotta:3)
Block(-2,3,-4,LOG:13)
Block(-2,3,-3,LOG:13)
Block(-2,3,-2,LOG_2:13)
Block(-2,3,-1,LOG:13)
Block(-2,4,-6,minecraft:black_glazed_terracotta:3)
Block(-2,4,-5,LOG:13)
Block(-2,4,-4,LOG:13)
Block(-2,4,-3,LOG:13)
Block(-2,4,-2,LOG_2:13)
Block(-2,4,-1,LOG_2:13)
Block(-2,5,-6,minecraft:black_glazed_terracotta:3)
Block(-2,5,-5,LOG:13)
Block(-2,5,-4,LOG:13)
Block(-2,5,-3,LOG:13)
Block(-2,5,-2,LOG:13)
Block(-2,6,-5,LOG:13)
Block(-2,6,-4,LOG:13)
Block(-2,6,-3,LOG_2:13)
Block(-2,6,-2,LOG:13)
Block(-2,7,-5,LOG:13)
Block(-2,7,-4,LOG:13)
Block(-2,7,-3,LOG:13)
Block(-2,7,-2,LOG:13)
Block(-2,7,-1,LOG:13)
Block(-2,8,-5,LOG:13)
Block(-2,8,-4,LOG:13)
Block(-2,8,-3,LOG:13)
Block(-2,8,-2,LOG:13)
Block(-2,8,-1,LOG_2:13)
Block(-2,9,-5,LOG:13)
Block(-2,9,-4,LOG:13)
Block(-2,9,-3,LOG:13)
Block(-2,9,-2,LOG:13)
Block(-2,10,-7,LEAVES:12)
Block(-2,10,-6,LEAVES:12)
Block(-2,10,-4,LOG_2:13)
Block(-2,10,-3,LOG:13)
Block(-2,10,-2,LOG:13)
Block(-2,11,-7,LEAVES:12)
Block(-2,11,-6,LEAVES:12)
Block(-2,11,-5,LEAVES:12)
Block(-2,11,-4,LOG:13)
Block(-2,11,-3,LOG:13)
Block(-2,12,-7,LEAVES:12)
Block(-2,12,-6,LEAVES:12)
Block(-2,12,-3,LOG:13)
Block(-2,13,-3,LOG:13)
Block(-2,13,-2,LEAVES:12)
Block(-2,14,-3,LOG:13)
Block(-2,14,-2,LOG:13)
Block(-2,15,-2,LOG:13)
Block(-2,15,-1,LOG:13)
Block(-2,15,0,LEAVES:12)
Block(-2,16,-1,LOG:13)
Block(-2,16,0,LOG:13)
Block(-2,17,-1,LOG:13)
Block(-2,17,0,LOG_2:13)
Block(-2,17,1,LOG:13)
Block(-2,18,0,LOG:13)
Block(-2,18,1,LOG:13)
Block(-2,18,2,LOG:13)
Block(-2,18,3,LEAVES:12)
Block(-2,18,8,LEAVES:12)
Block(-2,19,0,LOG:13)
Block(-2,19,1,LOG:13)
Block(-2,19,2,LOG:13)
Block(-2,19,3,LOG:13)
Block(-2,19,7,LEAVES:12)
Block(-2,19,8,LEAVES:12)
Block(-2,20,1,LOG:13)
Block(-2,20,2,LOG:13)
Block(-2,20,3,LOG_2:13)
Block(-2,20,5,LEAVES:12)
Block(-2,20,6,LEAVES:12)
Block(-2,20,7,LEAVES:12)
Block(-2,20,8,LEAVES:12)
Block(-2,21,0,LEAVES:12)
Block(-2,21,1,LEAVES:12)
Block(-2,21,2,LOG:13)
Block(-2,21,3,LOG:13)
Block(-2,21,4,LOG:13)
Block(-2,21,5,LOG:13)
Block(-2,21,6,LOG_2:13)
Block(-2,21,7,LEAVES:12)
Block(-2,21,8,LEAVES:12)
Block(-2,22,1,LEAVES:12)
Block(-2,22,2,LEAVES:12)
Block(-2,22,3,LEAVES:12)
Block(-2,22,4,LOG:13)
Block(-2,22,5,LOG:13)
Block(-2,22,6,LEAVES:12)
Block(-2,22,7,LEAVES:12)
Block(-2,22,8,LEAVES:12)
Block(-2,23,3,LEAVES:12)
Block(-2,23,4,LEAVES:12)
Block(-2,23,5,LEAVES:12)
Block(-2,23,6,LEAVES:12)
Block(-2,23,7,LEAVES:12)
Block(-2,23,8,LEAVES:12)
Block(-2,24,6,LEAVES:12)
Block(-2,24,7,LEAVES:12)
Block(-2,24,8,LEAVES:12)
Block(-1,-4,-2,LOG:13)
Block(-1,-3,-2,LOG:13)
Block(-1,-2,-2,LOG:13)
Block(-1,-1,-2,LOG_2:13)
Block(-1,0,-4,LOG:13)
Block(-1,0,-3,LOG:13)
Block(-1,0,-2,LOG:13)
Block(-1,0,0,LOG:13)
Block(-1,1,-6,LOG:13)
Block(-1,1,-5,LOG:13)
Block(-1,1,-4,LOG_2:13)
Block(-1,1,-3,LOG:13)
Block(-1,1,-2,LOG:13)
Block(-1,1,-1,LOG:13)
Block(-1,1,0,LOG:13)
Block(-1,2,-5,LOG:13)
Block(-1,2,-4,LOG:13)
Block(-1,2,-3,LOG:13)
Block(-1,2,-2,LOG:13)
Block(-1,2,-1,LOG_2:13)
Block(-1,3,-5,minecraft:black_glazed_terracotta:3)
Block(-1,3,-4,LOG_2:13)
Block(-1,3,-3,LOG:13)
Block(-1,3,-2,LOG:13)
Block(-1,3,-1,LOG:13)
Block(-1,4,-5,LOG_2:13)
Block(-1,4,-4,LOG_2:13)
Block(-1,4,-3,LOG_2:13)
Block(-1,4,-2,LOG:13)
Block(-1,4,-1,LOG:13)
Block(-1,5,-6,LOG:13)
Block(-1,5,-5,LOG_2:13)
Block(-1,5,-4,LOG_2:13)
Block(-1,5,-3,LOG:13)
Block(-1,5,-2,LOG:13)
Block(-1,5,-1,LOG:13)
Block(-1,6,-6,minecraft:black_glazed_terracotta:3)
Block(-1,6,-5,minecraft:black_glazed_terracotta:3)
Block(-1,6,-4,LOG:13)
Block(-1,6,-3,LOG_2:13)
Block(-1,6,-2,LOG:13)
Block(-1,6,-1,LOG_2:13)
Block(-1,7,-6,minecraft:black_glazed_terracotta:3)
Block(-1,7,-5,LOG:13)
Block(-1,7,-4,LOG:13)
Block(-1,7,-3,LOG:13)
Block(-1,7,-2,LOG:13)
Block(-1,7,-1,LOG_2:13)
Block(-1,8,-5,LOG:13)
Block(-1,8,-4,LOG:13)
Block(-1,8,-3,LOG:13)
Block(-1,8,-2,LOG:13)
Block(-1,9,-6,LEAVES:12)
Block(-1,9,-4,LOG:13)
Block(-1,9,-3,LOG:13)
Block(-1,9,-2,LEAVES:12)
Block(-1,10,-7,LEAVES:12)
Block(-1,10,-6,LEAVES:12)
Block(-1,10,-5,LEAVES:12)
Block(-1,10,-4,LOG:13)
Block(-1,10,-3,LOG:13)
Block(-1,10,-1,LEAVES:12)
Block(-1,11,-7,LEAVES:12)
Block(-1,11,-6,LEAVES:12)
Block(-1,11,-5,LEAVES:12)
Block(-1,11,-4,LEAVES:12)
Block(-1,11,-3,LOG:13)
Block(-1,12,-7,LEAVES:12)
Block(-1,12,-6,LEAVES:12)
Block(-1,12,-5,LEAVES:12)
Block(-1,12,-3,LOG:13)
Block(-1,17,0,LOG_2:13)
Block(-1,17,1,LEAVES:12)
Block(-1,18,-1,LEAVES:12)
Block(-1,18,0,LOG:13)
Block(-1,18,1,LOG_2:13)
Block(-1,18,2,LOG:13)
Block(-1,19,0,LEAVES:12)
Block(-1,19,1,LOG_2:13)
Block(-1,19,2,LOG:13)
Block(-1,19,3,LOG:13)
Block(-1,19,4,LEAVES:12)
Block(-1,20,0,LEAVES:12)
Block(-1,20,1,LOG:13)
Block(-1,20,2,LOG:13)
Block(-1,20,3,LOG:13)
Block(-1,20,4,LOG:13)
Block(-1,20,6,LEAVES:12)
Block(-1,21,-1,LEAVES:12)
Block(-1,21,0,LEAVES:12)
Block(-1,21,1,LOG_2:13)
Block(-1,21,2,LOG:13)
Block(-1,21,3,LOG:13)
Block(-1,21,4,LOG:13)
Block(-1,21,5,LEAVES:12)
Block(-1,21,6,LEAVES:12)
Block(-1,21,7,LEAVES:12)
Block(-1,21,8,LEAVES:12)
Block(-1,22,0,LEAVES:12)
Block(-1,22,1,LEAVES:12)
Block(-1,22,2,LEAVES:12)
Block(-1,22,3,LEAVES:12)
Block(-1,22,4,LEAVES:12)
Block(-1,22,5,LEAVES:12)
Block(-1,22,6,LEAVES:12)
Block(-1,22,7,LEAVES:12)
Block(-1,22,8,LEAVES:12)
Block(-1,23,3,LEAVES:12)
Block(-1,23,4,LEAVES:12)
Block(-1,23,5,LEAVES:12)
Block(-1,23,6,LEAVES:12)
Block(-1,23,7,LEAVES:12)
Block(-1,23,8,LEAVES:12)
Block(-1,24,4,LEAVES:12)
Block(-1,24,5,LEAVES:12)
Block(-1,24,6,LEAVES:12)
Block(-1,24,7,LEAVES:12)
Block(-1,24,8,LEAVES:12)
Block(-1,25,8,LEAVES:12)
Block(0,-4,-6,LOG:13)
Block(0,-3,-6,LOG:13)
Block(0,-2,-6,LOG:13)
Block(0,-2,-2,LOG:13)
Block(0,-2,-1,LOG:13)
Block(0,-1,-6,LOG:13)
Block(0,0,-6,LOG_2:13)
Block(0,0,-4,LOG:13)
Block(0,0,0,LOG:13)
Block(0,1,-7,LOG:13)
Block(0,1,-6,LOG:13)
Block(0,1,-5,LOG:13)
Block(0,1,-4,LOG:13)
Block(0,1,-3,LOG_2:13)
Block(0,1,-2,LOG:13)
Block(0,1,-1,LOG_2:13)
Block(0,1,0,LOG:13)
Block(0,1,1,LOG:13)
Block(0,2,-6,minecraft:black_glazed_terracotta:3)
Block(0,2,-5,LOG:13)
Block(0,2,-4,LOG_2:13)
Block(0,2,-3,LOG:13)
Block(0,2,-2,LOG_2:13)
Block(0,2,-1,LOG_2:13)
Block(0,2,0,LOG:13)
Block(0,3,-6,minecraft:black_glazed_terracotta:3)
Block(0,3,-5,LOG:13)
Block(0,3,-4,LOG:13)
Block(0,3,-3,LOG:13)
Block(0,3,-2,LOG:13)
Block(0,3,-1,LOG:13)
Block(0,3,0,LOG:13)
Block(0,4,-5,LOG_2:13)
Block(0,4,-4,LOG:13)
Block(0,4,-3,LOG:13)
Block(0,4,-2,LOG:13)
Block(0,4,-1,LOG_2:13)
Block(0,5,-6,LEAVES:12)
Block(0,5,-5,LOG:13)
Block(0,5,-4,LOG:13)
Block(0,5,-3,LOG:13)
Block(0,5,-2,LOG_2:13)
Block(0,5,-1,LOG:13)
Block(0,6,-6,LOG:13)
Block(0,6,-5,LOG:13)
Block(0,6,-4,LOG_2:13)
Block(0,6,-3,LOG:13)
Block(0,6,-2,LOG:13)
Block(0,6,-1,LOG:13)
Block(0,6,0,LOG_2:13)
Block(0,7,-6,minecraft:black_glazed_terracotta:3)
Block(0,7,-5,LOG_2:13)
Block(0,7,-4,LOG:13)
Block(0,7,-3,LOG:13)
Block(0,7,-2,LOG:13)
Block(0,7,-1,LOG:13)
Block(0,8,-6,minecraft:black_glazed_terracotta:3)
Block(0,8,-5,LOG:13)
Block(0,8,-4,LOG:13)
Block(0,8,-3,LOG:13)
Block(0,8,-2,LOG:13)
Block(0,9,-7,LEAVES:12)
Block(0,9,-6,LOG_2:13)
Block(0,9,-5,LOG:13)
Block(0,9,-4,LOG_2:13)
Block(0,9,-3,LOG:13)
Block(0,9,-2,LEAVES:12)
Block(0,10,-7,LOG:13)
Block(0,10,-6,LEAVES:12)
Block(0,10,-5,LEAVES:12)
Block(0,10,-4,LEAVES:12)
Block(0,10,0,LEAVES:12)
Block(0,11,-7,LEAVES:12)
Block(0,11,-6,LEAVES:12)
Block(0,11,-5,LEAVES:12)
Block(0,11,-4,LEAVES:12)
Block(0,11,-3,LEAVES:12)
Block(0,11,-2,LEAVES:12)
Block(0,12,-7,LEAVES:12)
Block(0,12,-6,LEAVES:12)
Block(0,12,-5,LEAVES:12)
Block(0,12,-4,LEAVES:12)
Block(0,13,-7,LEAVES:12)
Block(0,16,5,LEAVES:12)
Block(0,17,3,LEAVES:12)
Block(0,17,5,LEAVES:12)
Block(0,18,2,LEAVES:12)
Block(0,18,3,LEAVES:12)
Block(0,18,5,LEAVES:12)
Block(0,19,1,LEAVES:12)
Block(0,19,2,LOG_2:13)
Block(0,19,3,LOG_2:13)
Block(0,19,4,LOG:13)
Block(0,19,5,LEAVES:12)
Block(0,20,-1,LEAVES:12)
Block(0,20,0,LEAVES:12)
Block(0,20,1,LOG:13)
Block(0,20,2,LOG:13)
Block(0,20,3,LOG:13)
Block(0,20,4,LOG:13)
Block(0,20,5,LEAVES:12)
Block(0,21,-1,LEAVES:12)
Block(0,21,0,LOG:13)
Block(0,21,1,LOG:13)
Block(0,21,2,LEAVES:12)
Block(0,21,3,LOG:13)
Block(0,21,4,LOG:13)
Block(0,21,5,LOG:13)
Block(0,21,6,LEAVES:12)
Block(0,21,7,LEAVES:12)
Block(0,22,-3,LEAVES:12)
Block(0,22,-2,LEAVES:12)
Block(0,22,-1,LEAVES:12)
Block(0,22,0,LEAVES:12)
Block(0,22,1,LEAVES:12)
Block(0,22,2,LEAVES:12)
Block(0,22,3,LEAVES:12)
Block(0,22,4,LOG:13)
Block(0,22,5,LOG:13)
Block(0,22,6,LEAVES:12)
Block(0,22,7,LEAVES:12)
Block(0,23,-1,LEAVES:12)
Block(0,23,2,LEAVES:12)
Block(0,23,3,LEAVES:12)
Block(0,23,4,LEAVES:12)
Block(0,23,5,LEAVES:12)
Block(0,23,6,LEAVES:12)
Block(0,23,7,LEAVES:12)
Block(0,23,8,LEAVES:12)
Block(0,24,3,LEAVES:12)
Block(0,24,4,LEAVES:12)
Block(0,24,5,LEAVES:12)
Block(0,24,6,LEAVES:12)
Block(0,24,7,LEAVES:12)
Block(0,24,8,LEAVES:12)
Block(0,25,6,LEAVES:12)
Block(0,25,7,LEAVES:12)
Block(0,25,8,LEAVES:12)
Block(1,-7,-1,LOG:13)
Block(1,-6,-1,LOG:13)
Block(1,-5,-4,LOG:13)
Block(1,-5,-1,LOG:13)
Block(1,-4,-4,LOG:13)
Block(1,-4,-1,LOG:13)
Block(1,-4,1,LOG:13)
Block(1,-3,-4,LOG:13)
Block(1,-3,-1,LOG:13)
Block(1,-3,1,LOG:13)
Block(1,-2,-4,LOG:13)
Block(1,-2,-1,LOG:13)
Block(1,-2,1,LOG:13)
Block(1,-1,-4,LOG:13)
Block(1,-1,1,LOG:13)
Block(1,0,-5,LOG:13)
Block(1,0,-4,LOG:13)
Block(1,0,-1,LOG:13)
Block(1,0,0,LOG:13)
Block(1,0,1,LOG:13)
Block(1,1,-7,LOG:13)
Block(1,1,-6,LOG:13)
Block(1,1,-5,LOG:13)
Block(1,1,-4,LOG_2:13)
Block(1,1,-3,LOG:13)
Block(1,1,-2,LOG_2:13)
Block(1,1,-1,LOG:13)
Block(1,1,0,LOG:13)
Block(1,1,1,LOG:13)
Block(1,2,-7,LOG:13)
Block(1,2,-6,LOG:13)
Block(1,2,-5,LOG:13)
Block(1,2,-4,LOG:13)
Block(1,2,-3,LOG_2:13)
Block(1,2,-2,LOG:13)
Block(1,2,-1,LOG:13)
Block(1,2,0,LOG:13)
Block(1,2,1,LOG:13)
Block(1,3,-6,LOG:13)
Block(1,3,-4,LOG:13)
Block(1,3,-3,LOG:13)
Block(1,3,-2,LOG:13)
Block(1,3,-1,LOG:13)
Block(1,3,0,LOG:13)
Block(1,4,-3,LOG:13)
Block(1,4,-2,LOG:13)
Block(1,4,-1,LOG:13)
Block(1,4,0,LOG:13)
Block(1,5,-4,LOG_2:13)
Block(1,5,-3,LOG:13)
Block(1,5,-2,LOG:13)
Block(1,5,-1,LOG_2:13)
Block(1,5,0,LOG:13)
Block(1,6,-6,LEAVES:12)
Block(1,6,-5,LOG:13)
Block(1,6,-4,LOG:13)
Block(1,6,-3,LOG:13)
Block(1,6,-2,LOG:13)
Block(1,6,-1,LOG:13)
Block(1,7,-7,LEAVES:12)
Block(1,7,-6,LOG:13)
Block(1,7,-5,LOG:13)
Block(1,7,-4,LOG:13)
Block(1,7,-3,LOG:13)
Block(1,7,-1,LEAVES:12)
Block(1,8,-7,minecraft:black_glazed_terracotta:3)
Block(1,8,-6,LOG:13)
Block(1,8,-5,LOG:13)
Block(1,8,-4,LOG:13)
Block(1,8,-2,LEAVES:12)
Block(1,8,-1,LEAVES:12)
Block(1,9,-7,minecraft:black_glazed_terracotta:3)
Block(1,9,-6,LOG_2:13)
Block(1,9,-5,LOG:13)
Block(1,9,-4,LOG:13)
Block(1,9,-3,LEAVES:12)
Block(1,10,-7,LOG:13)
Block(1,10,-6,LOG_2:13)
Block(1,10,-5,LOG:13)
Block(1,10,-4,LEAVES:12)
Block(1,10,-3,LEAVES:12)
Block(1,10,-1,LEAVES:12)
Block(1,11,-7,LEAVES:12)
Block(1,11,-6,LEAVES:12)
Block(1,11,-5,LEAVES:12)
Block(1,11,-4,LEAVES:12)
Block(1,11,-3,LEAVES:12)
Block(1,12,-7,LEAVES:12)
Block(1,12,-6,LEAVES:12)
Block(1,12,-5,LEAVES:12)
Block(1,12,-4,LEAVES:12)
Block(1,12,-3,LEAVES:12)
Block(1,13,-7,LEAVES:12)
Block(1,13,-6,LEAVES:12)
Block(1,13,-5,LEAVES:12)
Block(1,19,-1,LEAVES:12)
Block(1,19,4,LEAVES:12)
Block(1,20,-3,LEAVES:12)
Block(1,20,-1,LEAVES:12)
Block(1,20,0,LEAVES:12)
Block(1,20,1,LEAVES:12)
Block(1,20,2,LEAVES:12)
Block(1,20,3,LOG:13)
Block(1,20,4,LOG:13)
Block(1,21,-4,LEAVES:12)
Block(1,21,-3,LEAVES:12)
Block(1,21,-2,LEAVES:12)
Block(1,21,-1,LOG_2:13)
Block(1,21,0,LOG_2:13)
Block(1,21,1,LEAVES:12)
Block(1,21,2,LEAVES:12)
Block(1,21,3,LEAVES:12)
Block(1,21,4,LOG:13)
Block(1,21,5,LOG_2:13)
Block(1,21,6,LEAVES:12)
Block(1,21,7,LEAVES:12)
Block(1,22,-5,LEAVES:12)
Block(1,22,-3,LEAVES:12)
Block(1,22,-2,LEAVES:12)
Block(1,22,-1,LOG:13)
Block(1,22,0,LOG:13)
Block(1,22,1,LEAVES:12)
Block(1,22,2,LEAVES:12)
Block(1,22,3,LEAVES:12)
Block(1,22,4,LOG_2:13)
Block(1,22,5,LOG:13)
Block(1,22,6,LOG:13)
Block(1,22,7,LEAVES:12)
Block(1,23,-2,LEAVES:12)
Block(1,23,-1,LEAVES:12)
Block(1,23,0,LEAVES:12)
Block(1,23,1,LEAVES:12)
Block(1,23,2,LEAVES:12)
Block(1,23,3,LEAVES:12)
Block(1,23,4,LEAVES:12)
Block(1,23,5,LOG:13)
Block(1,23,6,LOG:13)
Block(1,23,7,LEAVES:12)
Block(1,23,8,LEAVES:12)
Block(1,24,4,LEAVES:12)
Block(1,24,5,LEAVES:12)
Block(1,24,6,LEAVES:12)
Block(1,24,7,LEAVES:12)
Block(1,24,8,LEAVES:12)
Block(1,25,7,LEAVES:12)
Block(1,25,8,LOG:13)
Block(1,26,8,LEAVES:12)
Block(2,0,-1,LOG:13)
Block(2,0,0,LOG:13)
Block(2,0,1,LOG:13)
Block(2,1,-7,minecraft:black_glazed_terracotta:3)
Block(2,1,-4,LOG:13)
Block(2,1,-3,LOG:13)
Block(2,1,-2,LOG_2:13)
Block(2,1,-1,LOG:13)
Block(2,1,0,LOG:13)
Block(2,1,1,LOG_2:13)
Block(2,1,2,LOG_2:13)
Block(2,2,-3,LOG:13)
Block(2,2,-2,LOG:13)
Block(2,2,-1,LOG:13)
Block(2,2,0,LOG_2:13)
Block(2,2,1,LOG:13)
Block(2,3,-3,LOG:13)
Block(2,3,-2,LOG:13)
Block(2,3,-1,LOG_2:13)
Block(2,3,0,LOG:13)
Block(2,4,-3,LOG:13)
Block(2,4,-2,LOG:13)
Block(2,4,-1,LOG:13)
Block(2,4,0,LOG:13)
Block(2,5,-3,LOG:13)
Block(2,5,-2,minecraft:black_glazed_terracotta:3)
Block(2,5,-1,minecraft:black_glazed_terracotta:3)
Block(2,5,0,LOG_2:13)
Block(2,6,-4,LOG:13)
Block(2,6,-3,minecraft:black_glazed_terracotta:3)
Block(2,7,-6,LEAVES:12)
Block(2,7,-5,LOG:13)
Block(2,7,-4,minecraft:black_glazed_terracotta:3)
Block(2,8,-7,LOG:13)
Block(2,8,-6,LOG:13)
Block(2,8,-5,LOG:13)
Block(2,8,-4,LOG:13)
Block(2,8,-3,LEAVES:12)
Block(2,9,-7,LOG:13)
Block(2,9,-6,LOG:13)
Block(2,9,-5,LOG:13)
Block(2,9,-4,LEAVES:12)
Block(2,9,-1,LEAVES:12)
Block(2,10,-7,LOG_2:13)
Block(2,10,-6,LOG:13)
Block(2,10,-5,LEAVES:12)
Block(2,10,-4,LEAVES:12)
Block(2,10,-2,LEAVES:12)
Block(2,11,-7,LOG:13)
Block(2,11,-6,LEAVES:12)
Block(2,11,-5,LEAVES:12)
Block(2,11,-4,LEAVES:12)
Block(2,11,-3,LEAVES:12)
Block(2,12,-7,LEAVES:12)
Block(2,12,-6,LEAVES:12)
Block(2,12,-5,LEAVES:12)
Block(2,12,-4,LEAVES:12)
Block(2,13,-7,LEAVES:12)
Block(2,13,-6,LEAVES:12)
Block(2,19,2,LEAVES:12)
Block(2,19,5,LEAVES:12)
Block(2,20,-4,LEAVES:12)
Block(2,20,-3,LEAVES:12)
Block(2,20,-2,LEAVES:12)
Block(2,20,1,LEAVES:12)
Block(2,20,2,LEAVES:12)
Block(2,20,3,LEAVES:12)
Block(2,20,4,LEAVES:12)
Block(2,20,5,LEAVES:12)
Block(2,21,-5,LEAVES:12)
Block(2,21,-4,LEAVES:12)
Block(2,21,-3,LEAVES:12)
Block(2,21,-2,LOG:13)
Block(2,21,-1,LOG:13)
Block(2,21,0,LEAVES:12)
Block(2,21,1,LEAVES:12)
Block(2,21,2,LEAVES:12)
Block(2,21,3,LEAVES:12)
Block(2,21,4,LEAVES:12)
Block(2,21,5,LOG:13)
Block(2,21,6,LEAVES:12)
Block(2,21,7,LEAVES:12)
Block(2,22,-4,LEAVES:12)
Block(2,22,-3,LEAVES:12)
Block(2,22,-2,LEAVES:12)
Block(2,22,-1,LOG:13)
Block(2,22,0,LEAVES:12)
Block(2,22,1,LEAVES:12)
Block(2,22,2,LEAVES:12)
Block(2,22,3,LEAVES:12)
Block(2,22,4,LEAVES:12)
Block(2,22,5,LOG:13)
Block(2,22,6,LOG_2:13)
Block(2,22,7,LOG:13)
Block(2,23,-2,LEAVES:12)
Block(2,23,-1,LEAVES:12)
Block(2,23,0,LEAVES:12)
Block(2,23,1,LEAVES:12)
Block(2,23,2,LEAVES:12)
Block(2,23,3,LEAVES:12)
Block(2,23,4,LEAVES:12)
Block(2,23,5,LEAVES:12)
Block(2,23,6,LOG:13)
Block(2,23,7,LOG:13)
Block(2,23,8,LOG_2:13)
Block(2,24,4,LEAVES:12)
Block(2,24,5,LEAVES:12)
Block(2,24,6,LOG:13)
Block(2,24,7,LOG:13)
Block(2,24,8,LOG:13)
Block(2,25,6,LEAVES:12)
Block(2,25,7,LEAVES:12)
Block(2,25,8,LOG:13)
Block(2,26,7,LEAVES:12)
Block(2,26,8,LEAVES:12)
Block(3,0,-1,LOG:13)
Block(3,0,0,LOG:13)
Block(3,0,1,LOG:13)
Block(3,1,-3,LOG:13)
Block(3,1,-2,LOG:13)
Block(3,1,-1,LOG:13)
Block(3,1,0,LOG:13)
Block(3,1,1,LOG:13)
Block(3,1,2,LOG:13)
Block(3,2,-3,LOG:13)
Block(3,2,-2,LOG:13)
Block(3,2,-1,LOG:13)
Block(3,2,0,LOG:13)
Block(3,2,1,LOG_2:13)
Block(3,2,2,LOG:13)
Block(3,3,-2,LOG:13)
Block(3,3,-1,LOG:13)
Block(3,3,0,LOG:13)
Block(3,3,1,LOG_2:13)
Block(3,4,-4,LEAVES:12)
Block(3,4,-1,minecraft:black_glazed_terracotta:3)
Block(3,4,0,LOG_2:13)
Block(3,5,-4,LEAVES:12)
Block(3,6,-4,LEAVES:12)
Block(3,7,-4,LEAVES:12)
Block(3,8,-6,minecraft:black_glazed_terracotta:3)
Block(3,8,-5,minecraft:black_glazed_terracotta:3)
Block(3,8,-4,LEAVES:12)
Block(3,9,-7,LOG:13)
Block(3,9,-6,LOG:13)
Block(3,9,-4,LEAVES:12)
Block(3,9,-2,LEAVES:12)
Block(3,9,0,LEAVES:12)
Block(3,10,-7,LOG:13)
Block(3,10,-6,LEAVES:12)
Block(3,10,-5,LEAVES:12)
Block(3,10,-3,LEAVES:12)
Block(3,11,-7,LEAVES:12)
Block(3,11,-6,LEAVES:12)
Block(3,11,-5,LEAVES:12)
Block(3,11,-4,LEAVES:12)
Block(3,12,-7,LEAVES:12)
Block(3,12,-5,LEAVES:12)
Block(3,13,-7,LEAVES:12)
Block(3,13,-6,LEAVES:12)
Block(3,13,-5,LEAVES:12)
Block(3,13,-4,LEAVES:12)
Block(3,14,-7,LEAVES:12)
Block(3,14,-5,LEAVES:12)
Block(3,17,-1,LEAVES:12)
Block(3,17,5,LEAVES:12)
Block(3,18,-3,LEAVES:12)
Block(3,18,-1,LEAVES:12)
Block(3,18,5,LEAVES:12)
Block(3,19,-3,LEAVES:12)
Block(3,19,-1,LEAVES:12)
Block(3,20,-5,LEAVES:12)
Block(3,20,-4,LEAVES:12)
Block(3,20,-3,LEAVES:12)
Block(3,20,-2,LEAVES:12)
Block(3,20,-1,LEAVES:12)
Block(3,20,2,LEAVES:12)
Block(3,20,3,LEAVES:12)
Block(3,20,4,LEAVES:12)
Block(3,21,-7,LEAVES:12)
Block(3,21,-5,LEAVES:12)
Block(3,21,-4,LEAVES:12)
Block(3,21,-3,LOG:13)
Block(3,21,-2,LOG:13)
Block(3,21,-1,LEAVES:12)
Block(3,21,0,LEAVES:12)
Block(3,21,1,LEAVES:12)
Block(3,21,2,LEAVES:12)
Block(3,21,3,LEAVES:12)
Block(3,21,4,LEAVES:12)
Block(3,21,5,LEAVES:12)
Block(3,22,-5,LEAVES:12)
Block(3,22,-4,LEAVES:12)
Block(3,22,-3,LEAVES:12)
Block(3,22,-2,LEAVES:12)
Block(3,22,-1,LOG_2:13)
Block(3,22,0,LEAVES:12)
Block(3,22,1,LEAVES:12)
Block(3,22,2,LEAVES:12)
Block(3,22,3,LEAVES:12)
Block(3,22,4,LEAVES:12)
Block(3,22,5,LEAVES:12)
Block(3,22,6,LOG:13)
Block(3,23,-4,LEAVES:12)
Block(3,23,-3,LEAVES:12)
Block(3,23,-2,LEAVES:12)
Block(3,23,-1,LEAVES:12)
Block(3,23,0,LEAVES:12)
Block(3,23,1,LEAVES:12)
Block(3,23,2,LEAVES:12)
Block(3,23,3,LEAVES:12)
Block(3,23,4,LEAVES:12)
Block(3,23,5,LEAVES:12)
Block(3,23,6,LOG_2:13)
Block(3,23,7,LOG:13)
Block(3,23,8,LOG:13)
Block(3,24,3,LEAVES:12)
Block(3,24,4,LEAVES:12)
Block(3,24,5,LEAVES:12)
Block(3,24,6,LEAVES:12)
Block(3,24,7,LOG_2:13)
Block(3,24,8,LOG:13)
Block(3,25,5,LEAVES:12)
Block(3,25,6,LEAVES:12)
Block(3,25,7,LOG:13)
Block(3,25,8,LOG_2:13)
Block(3,26,6,LEAVES:12)
Block(3,26,7,LEAVES:12)
Block(3,26,8,LEAVES:12)
Block(4,-5,2,LOG:13)
Block(4,-4,-2,LOG:13)
Block(4,-4,2,LOG:13)
Block(4,-3,-2,LOG:13)
Block(4,-3,2,LOG:13)
Block(4,-2,-2,LOG:13)
Block(4,-2,2,LOG:13)
Block(4,-1,-2,LOG:13)
Block(4,-1,2,LOG:13)
Block(4,0,-2,LOG:13)
Block(4,0,-1,LOG:13)
Block(4,0,2,LOG_2:13)
Block(4,1,-2,LOG_2:13)
Block(4,1,-1,LOG:13)
Block(4,1,0,LOG:13)
Block(4,1,1,LOG_2:13)
Block(4,1,2,LOG:13)
Block(4,2,-1,LOG:13)
Block(4,2,0,LOG:13)
Block(4,2,1,LOG:13)
Block(4,2,2,LOG:13)
Block(4,3,0,minecraft:black_glazed_terracotta:3)
Block(4,3,1,minecraft:black_glazed_terracotta:3)
Block(4,6,-7,LEAVES:12)
Block(4,7,-7,LEAVES:12)
Block(4,8,-7,LEAVES:12)
Block(4,9,-7,LEAVES:12)
Block(4,9,-5,LEAVES:12)
Block(4,9,-3,LEAVES:12)
Block(4,10,-7,LEAVES:12)
Block(4,11,-7,LEAVES:12)
Block(4,11,-5,LEAVES:12)
Block(4,11,-3,LEAVES:12)
Block(4,12,-7,LEAVES:12)
Block(4,12,-6,LEAVES:12)
Block(4,12,-5,LEAVES:12)
Block(4,12,-4,LEAVES:12)
Block(4,13,-7,LEAVES:12)
Block(4,13,-6,LEAVES:12)
Block(4,13,-5,LEAVES:12)
Block(4,13,-4,LEAVES:12)
Block(4,13,-3,LEAVES:12)
Block(4,14,-7,LEAVES:12)
Block(4,14,-6,LEAVES:12)
Block(4,14,-5,LEAVES:12)
Block(4,14,-4,LEAVES:12)
Block(4,17,2,LEAVES:12)
Block(4,18,1,LEAVES:12)
Block(4,18,2,LEAVES:12)
Block(4,19,1,LEAVES:12)
Block(4,19,2,LEAVES:12)
Block(4,20,-5,LEAVES:12)
Block(4,20,-4,LEAVES:12)
Block(4,20,-3,LEAVES:12)
Block(4,20,-2,LEAVES:12)
Block(4,20,0,LEAVES:12)
Block(4,20,1,LEAVES:12)
Block(4,20,2,LEAVES:12)
Block(4,20,3,LEAVES:12)
Block(4,21,-6,LEAVES:12)
Block(4,21,-5,LEAVES:12)
Block(4,21,-4,LOG:13)
Block(4,21,-3,LOG:13)
Block(4,21,-2,LEAVES:12)
Block(4,21,-1,LEAVES:12)
Block(4,21,0,LEAVES:12)
Block(4,21,1,LEAVES:12)
Block(4,21,2,LEAVES:12)
Block(4,21,3,LEAVES:12)
Block(4,21,4,LEAVES:12)
Block(4,21,5,LEAVES:12)
Block(4,21,6,LEAVES:12)
Block(4,21,7,LEAVES:12)
Block(4,22,-6,LEAVES:12)
Block(4,22,-5,LEAVES:12)
Block(4,22,-4,LOG:13)
Block(4,22,-3,LEAVES:12)
Block(4,22,-2,LEAVES:12)
Block(4,22,-1,LEAVES:12)
Block(4,22,0,LOG:13)
Block(4,22,1,LEAVES:12)
Block(4,22,2,LEAVES:12)
Block(4,22,3,LEAVES:12)
Block(4,22,4,LEAVES:12)
Block(4,22,5,LEAVES:12)
Block(4,22,6,LEAVES:12)
Block(4,22,7,LEAVES:12)
Block(4,23,-4,LEAVES:12)
Block(4,23,-3,LEAVES:12)
Block(4,23,-2,LEAVES:12)
Block(4,23,-1,LEAVES:12)
Block(4,23,0,LEAVES:12)
Block(4,23,1,LEAVES:12)
Block(4,23,2,LEAVES:12)
Block(4,23,3,LEAVES:12)
Block(4,23,4,LEAVES:12)
Block(4,23,5,LEAVES:12)
Block(4,23,6,LEAVES:12)
Block(4,23,7,LEAVES:12)
Block(4,23,8,LEAVES:12)
Block(4,24,3,LEAVES:12)
Block(4,24,4,LEAVES:12)
Block(4,24,5,LEAVES:12)
Block(4,24,6,LOG:13)
Block(4,24,7,LOG:13)
Block(4,24,8,LEAVES:12)
Block(4,25,6,LEAVES:12)
Block(4,25,7,LOG:13)
Block(4,25,8,LEAVES:12)
Block(4,26,7,LEAVES:12)
Block(4,26,8,LEAVES:12)
Block(4,27,8,LEAVES:12)
Block(5,0,-1,LOG:13)
Block(5,0,2,LOG_2:13)
Block(5,1,-1,LOG:13)
Block(5,1,0,LOG:13)
Block(5,1,1,LOG:13)
Block(5,1,2,LOG:13)
Block(5,1,3,LOG:13)
Block(5,2,0,LOG:13)
Block(5,2,1,minecraft:black_glazed_terracotta:3)
Block(5,2,2,LOG_2:13)
Block(5,3,2,LOG:13)
Block(5,9,-2,LEAVES:12)
Block(5,10,-6,LEAVES:12)
Block(5,11,-6,LEAVES:12)
Block(5,12,-7,LEAVES:12)
Block(5,12,-6,LEAVES:12)
Block(5,12,-5,LEAVES:12)
Block(5,12,-4,LEAVES:12)
Block(5,12,-3,LEAVES:12)
Block(5,13,-7,LEAVES:12)
Block(5,13,-6,LEAVES:12)
Block(5,13,-5,LEAVES:12)
Block(5,13,-4,LEAVES:12)
Block(5,13,-3,LEAVES:12)
Block(5,14,-7,LEAVES:12)
Block(5,14,-6,LEAVES:12)
Block(5,14,-5,LEAVES:12)
Block(5,14,-4,LEAVES:12)
Block(5,14,-3,LEAVES:12)
Block(5,15,-6,LEAVES:12)
Block(5,16,-3,LEAVES:12)
Block(5,17,-3,LEAVES:12)
Block(5,18,-3,LEAVES:12)
Block(5,18,4,LEAVES:12)
Block(5,19,-6,LEAVES:12)
Block(5,19,-4,LEAVES:12)
Block(5,19,-3,LEAVES:12)
Block(5,19,4,LEAVES:12)
Block(5,20,-7,LEAVES:12)
Block(5,20,-6,LEAVES:12)
Block(5,20,-5,LEAVES:12)
Block(5,20,-4,LEAVES:12)
Block(5,20,-3,LEAVES:12)
Block(5,20,-2,LEAVES:12)
Block(5,20,-1,LEAVES:12)
Block(5,20,3,LEAVES:12)
Block(5,20,4,LEAVES:12)
Block(5,21,-7,LEAVES:12)
Block(5,21,-6,LEAVES:12)
Block(5,21,-5,LEAVES:12)
Block(5,21,-4,LEAVES:12)
Block(5,21,-3,LEAVES:12)
Block(5,21,-2,LEAVES:12)
Block(5,21,-1,LEAVES:12)
Block(5,21,0,LEAVES:12)
Block(5,21,1,LEAVES:12)
Block(5,21,2,LEAVES:12)
Block(5,21,3,LEAVES:12)
Block(5,21,5,LEAVES:12)
Block(5,22,-6,LEAVES:12)
Block(5,22,-5,LOG:13)
Block(5,22,-4,LOG:13)
Block(5,22,-3,LEAVES:12)
Block(5,22,-2,LEAVES:12)
Block(5,22,-1,LEAVES:12)
Block(5,22,0,LOG:13)
Block(5,22,1,LEAVES:12)
Block(5,22,2,LEAVES:12)
Block(5,22,3,LEAVES:12)
Block(5,22,4,LEAVES:12)
Block(5,22,5,LEAVES:12)
Block(5,22,6,LEAVES:12)
Block(5,23,-5,LEAVES:12)
Block(5,23,-4,LEAVES:12)
Block(5,23,-3,LEAVES:12)
Block(5,23,-2,LEAVES:12)
Block(5,23,-1,LEAVES:12)
Block(5,23,0,LEAVES:12)
Block(5,23,1,LEAVES:12)
Block(5,23,2,LEAVES:12)
Block(5,23,3,LEAVES:12)
Block(5,23,4,LEAVES:12)
Block(5,23,5,LEAVES:12)
Block(5,23,6,LEAVES:12)
Block(5,23,7,LEAVES:12)
Block(5,23,8,LEAVES:12)
Block(5,24,2,LEAVES:12)
Block(5,24,3,LEAVES:12)
Block(5,24,4,LEAVES:12)
Block(5,24,5,LEAVES:12)
Block(5,24,6,LOG:13)
Block(5,24,7,LEAVES:12)
Block(5,24,8,LEAVES:12)
Block(5,25,5,LEAVES:12)
Block(5,25,6,LEAVES:12)
Block(5,25,7,LEAVES:12)
Block(5,25,8,LEAVES:12)
Block(5,26,6,LEAVES:12)
Block(5,26,7,LEAVES:12)
Block(5,26,8,LEAVES:12)
Block(6,0,2,LOG:13)
Block(6,0,3,LOG:13)
Block(6,1,1,LOG:13)
Block(6,1,2,LOG:13)
Block(6,1,3,LOG_2:13)
Block(6,2,2,minecraft:black_glazed_terracotta:3)
Block(6,2,3,LOG:13)
Block(6,9,-5,LEAVES:12)
Block(6,10,-5,LEAVES:12)
Block(6,11,-5,LEAVES:12)
Block(6,12,-7,LOG:13)
Block(6,12,-6,LEAVES:12)
Block(6,12,-5,LEAVES:12)
Block(6,12,-4,LEAVES:12)
Block(6,13,-7,LOG:13)
Block(6,13,-6,LEAVES:12)
Block(6,13,-5,LEAVES:12)
Block(6,13,-4,LEAVES:12)
Block(6,13,-3,LEAVES:12)
Block(6,14,-7,LEAVES:12)
Block(6,14,-6,LEAVES:12)
Block(6,14,-5,LEAVES:12)
Block(6,14,-4,LEAVES:12)
Block(6,14,-2,LEAVES:12)
Block(6,15,-7,LEAVES:12)
Block(6,15,-6,LEAVES:12)
Block(6,15,-5,LEAVES:12)
Block(6,15,-4,LEAVES:12)
Block(6,16,-2,LEAVES:12)
Block(6,17,-2,LEAVES:12)
Block(6,17,-1,LEAVES:12)
Block(6,18,-2,LEAVES:12)
Block(6,18,-1,LEAVES:12)
Block(6,19,-7,LEAVES:12)
Block(6,19,-6,LEAVES:12)
Block(6,19,-5,LEAVES:12)
Block(6,19,-2,LEAVES:12)
Block(6,19,-1,LEAVES:12)
Block(6,19,7,LEAVES:12)
Block(6,20,-7,LEAVES:12)
Block(6,20,-6,LEAVES:12)
Block(6,20,-5,LEAVES:12)
Block(6,20,-4,LEAVES:12)
Block(6,20,-3,LEAVES:12)
Block(6,20,-2,LEAVES:12)
Block(6,20,-1,LEAVES:12)
Block(6,20,0,LEAVES:12)
Block(6,20,1,LEAVES:12)
Block(6,20,2,LEAVES:12)
Block(6,20,7,LEAVES:12)
Block(6,21,-7,LEAVES:12)
Block(6,21,-6,LEAVES:12)
Block(6,21,-5,LEAVES:12)
Block(6,21,-4,LEAVES:12)
Block(6,21,-3,LEAVES:12)
Block(6,21,-2,LEAVES:12)
Block(6,21,-1,LEAVES:12)
Block(6,21,0,LEAVES:12)
Block(6,21,1,LEAVES:12)
Block(6,21,2,LEAVES:12)
Block(6,21,3,LEAVES:12)
Block(6,21,4,LEAVES:12)
Block(6,21,7,LEAVES:12)
Block(6,21,8,LEAVES:12)
Block(6,22,-6,LEAVES:12)
Block(6,22,-5,LOG:13)
Block(6,22,-4,LEAVES:12)
Block(6,22,-3,LEAVES:12)
Block(6,22,-2,LEAVES:12)
Block(6,22,-1,LEAVES:12)
Block(6,22,0,LEAVES:12)
Block(6,22,1,LOG_2:13)
Block(6,22,2,LEAVES:12)
Block(6,22,3,LEAVES:12)
Block(6,22,4,LEAVES:12)
Block(6,22,5,LEAVES:12)
Block(6,22,6,LEAVES:12)
Block(6,22,7,LEAVES:12)
Block(6,23,-6,LEAVES:12)
Block(6,23,-5,LEAVES:12)
Block(6,23,-4,LEAVES:12)
Block(6,23,-3,LEAVES:12)
Block(6,23,-2,LEAVES:12)
Block(6,23,-1,LEAVES:12)
Block(6,23,0,LEAVES:12)
Block(6,23,1,LEAVES:12)
Block(6,23,2,LEAVES:12)
Block(6,23,3,LEAVES:12)
Block(6,23,4,LEAVES:12)
Block(6,23,5,LEAVES:12)
Block(6,23,6,LEAVES:12)
Block(6,23,7,LEAVES:12)
Block(6,23,8,LEAVES:12)
Block(6,24,3,LEAVES:12)
Block(6,24,4,LEAVES:12)
Block(6,24,5,LOG:13)
Block(6,24,6,LEAVES:12)
Block(6,24,7,LEAVES:12)
Block(6,24,8,LEAVES:12)
Block(6,25,4,LEAVES:12)
Block(6,25,5,LEAVES:12)
Block(6,25,6,LEAVES:12)
Block(6,25,7,LEAVES:12)
Block(6,25,8,LEAVES:12)
Block(6,26,6,LEAVES:12)
Block(6,26,7,LEAVES:12)
Block(6,26,8,LEAVES:12)
Block(7,-6,3,LOG:13)
Block(7,-5,3,LOG:13)
Block(7,-4,3,LOG:13)
Block(7,-3,3,LOG:13)
Block(7,-2,3,LOG:13)
Block(7,-1,3,LOG:13)
Block(7,0,3,LOG_2:13)
Block(7,0,4,LOG_2:13)
Block(7,1,2,LOG:13)
Block(7,1,3,minecraft:black_glazed_terracotta:3)
Block(7,1,4,LOG_2:13)
Block(7,2,3,minecraft:black_glazed_terracotta:3)
Block(7,10,-3,LEAVES:12)
Block(7,11,-3,LEAVES:12)
Block(7,12,-7,LOG:13)
Block(7,12,-4,LEAVES:12)
Block(7,12,-3,LEAVES:12)
Block(7,13,-7,LOG_2:13)
Block(7,13,-6,LEAVES:12)
Block(7,13,-5,LEAVES:12)
Block(7,14,-7,LEAVES:12)
Block(7,14,-6,LEAVES:12)
Block(7,14,-5,LEAVES:12)
Block(7,14,-3,LEAVES:12)
Block(7,15,-7,LEAVES:12)
Block(7,15,-6,LEAVES:12)
Block(7,16,1,LEAVES:12)
Block(7,17,1,LEAVES:12)
Block(7,18,1,LEAVES:12)
Block(7,19,-6,LEAVES:12)
Block(7,19,-5,LEAVES:12)
Block(7,19,-3,LEAVES:12)
Block(7,19,-2,LEAVES:12)
Block(7,19,1,LEAVES:12)
Block(7,20,-7,LEAVES:12)
Block(7,20,-6,LEAVES:12)
Block(7,20,-5,LEAVES:12)
Block(7,20,-4,LEAVES:12)
Block(7,20,-3,LEAVES:12)
Block(7,20,-2,LEAVES:12)
Block(7,20,-1,LEAVES:12)
Block(7,20,0,LEAVES:12)
Block(7,20,1,LEAVES:12)
Block(7,20,2,LEAVES:12)
Block(7,20,8,LEAVES:12)
Block(7,21,-6,LEAVES:12)
Block(7,21,-5,LEAVES:12)
Block(7,21,-4,LEAVES:12)
Block(7,21,-3,LEAVES:12)
Block(7,21,-2,LEAVES:12)
Block(7,21,-1,LEAVES:12)
Block(7,21,0,LEAVES:12)
Block(7,21,1,LEAVES:12)
Block(7,21,2,LEAVES:12)
Block(7,21,3,LEAVES:12)
Block(7,21,5,LEAVES:12)
Block(7,21,8,LEAVES:12)
Block(7,22,-6,LEAVES:12)
Block(7,22,-5,LEAVES:12)
Block(7,22,-4,LEAVES:12)
Block(7,22,-3,LEAVES:12)
Block(7,22,-2,LEAVES:12)
Block(7,22,-1,LEAVES:12)
Block(7,22,0,LEAVES:12)
Block(7,22,1,LEAVES:12)
Block(7,22,2,LEAVES:12)
Block(7,22,3,LEAVES:12)
Block(7,22,4,LEAVES:12)
Block(7,22,5,LEAVES:12)
Block(7,22,8,LEAVES:12)
Block(7,23,-5,LEAVES:12)
Block(7,23,-3,LEAVES:12)
Block(7,23,-2,LEAVES:12)
Block(7,23,-1,LEAVES:12)
Block(7,23,0,LEAVES:12)
Block(7,23,1,LEAVES:12)
Block(7,23,2,LEAVES:12)
Block(7,23,3,LEAVES:12)
Block(7,23,4,LEAVES:12)
Block(7,23,5,LEAVES:12)
Block(7,23,7,LEAVES:12)
Block(7,24,2,LEAVES:12)
Block(7,24,3,LEAVES:12)
Block(7,24,4,LOG:13)
Block(7,24,5,LEAVES:12)
Block(7,24,6,LEAVES:12)
Block(7,24,7,LEAVES:12)
Block(7,24,8,LEAVES:12)
Block(7,25,3,LEAVES:12)
Block(7,25,4,LEAVES:12)
Block(7,25,5,LEAVES:12)
Block(7,25,6,LEAVES:12)
Block(7,25,7,LEAVES:12)
Block(7,25,8,LEAVES:12)
Block(7,26,5,LEAVES:12)
Block(7,26,6,LEAVES:12)
Block(7,26,7,LEAVES:12)
Block(7,26,8,LEAVES:12)

#######################################################################
# +-----------------------------------------------------------------+ #
# |                             Branches                            | #
# +-----------------------------------------------------------------+ #
#######################################################################

Branch(-16,0,0,true,CherryTreeCorrupted06C0R1,NORTH,100.0,0)

#######################################################################
# +-----------------------------------------------------------------+ #
# |                             Entities                            | #
# +-----------------------------------------------------------------+ #
#######################################################################


#######################################################################
# +-----------------------------------------------------------------+ #
# |                            Particles                            | #
# +-----------------------------------------------------------------+ #
#######################################################################


#######################################################################
# +-----------------------------------------------------------------+ #
# |                             Spawners                            | #
# +-----------------------------------------------------------------+ #
#######################################################################


#######################################################################
# +-----------------------------------------------------------------+ #
# |                             ModData                             | #
# +-----------------------------------------------------------------+ #
#######################################################################

