
#######################################################################
# +-----------------------------------------------------------------+ #
# |                            BO4 object                           | #
# +-----------------------------------------------------------------+ #
#######################################################################

Author: NLBlackEagle

Description: No description given

SettingsMode: WriteDisable


#######################################################################
# +-----------------------------------------------------------------+ #
# |                          Main settings                          | #
# +-----------------------------------------------------------------+ #
#######################################################################

Frequency: 0

SpawnHeight: highestBlock

UseCenterForHighestBlock: true

##############################
# Height Limits for the BO4. #
##############################

MinHeight: 0

MaxHeight: 255

InheritBO3: 

InheritBO3Rotation: NORTH

OverrideChildSettings: true

OverrideParentHeight: false

CanOverride: false

BranchFrequency: 0

BranchFrequencyGroup: 

MustBeBelowOther: false

MustBeInside: 

CannotBeInside: 

ReplacesBO3: 

MustBeInsideWorldBorders: false

CanSpawnOnWater: true

SpawnOnWaterOnly: false

SpawnUnderWater: false

SpawnAtWaterLevel: false

HeightOffset: 0

RemoveAir: true

ReplaceAbove: 

ReplaceBelow: 

ReplaceWithBiomeBlocks: true

ReplaceWithSurfaceBlock: GRASS

ReplaceWithGroundBlock: DIRT

ReplaceWithStoneBlock: STONE

SmoothRadius: 0

SmoothHeightOffset: 0

SmoothStartTop: false

SmoothStartWood: false

SmoothingSurfaceBlock: 

SmoothingGroundBlock: 

BO3Group: 

IsSpawnPoint: false

DoReplaceBlocks: true


#######################################################################
# +-----------------------------------------------------------------+ #
# |                              Blocks                             | #
# +-----------------------------------------------------------------+ #
#######################################################################

Block(-8,20,-7,LEAVES:12)
Block(-8,21,-7,LEAVES:12)
Block(-8,21,-6,LEAVES:12)
Block(-8,22,-7,LEAVES:12)
Block(-8,23,-7,LEAVES:12)
Block(-8,23,-6,LEAVES:12)
Block(-8,24,-6,LEAVES:12)
Block(-8,24,-5,LEAVES:12)
Block(-8,24,-3,LEAVES:12)
Block(-8,24,0,LEAVES:12)
Block(-8,24,1,LEAVES:12)
Block(-8,25,-7,LEAVES:12)
Block(-8,25,-6,LEAVES:12)
Block(-8,25,-5,LEAVES:12)
Block(-8,25,-4,LEAVES:12)
Block(-8,25,-3,LEAVES:12)
Block(-8,25,-2,LOG:13)
Block(-8,25,-1,LEAVES:12)
Block(-8,25,0,LEAVES:12)
Block(-8,25,1,LEAVES:12)
Block(-8,25,2,LEAVES:12)
Block(-8,26,-7,LOG:13)
Block(-8,26,-6,LEAVES:12)
Block(-8,26,-5,LEAVES:12)
Block(-8,26,-4,LEAVES:12)
Block(-8,26,-3,LEAVES:12)
Block(-8,26,-2,LEAVES:12)
Block(-8,26,-1,LEAVES:12)
Block(-8,26,0,LEAVES:12)
Block(-8,26,1,LEAVES:12)
Block(-8,26,2,LEAVES:12)
Block(-8,27,-7,LEAVES:12)
Block(-8,27,-6,LEAVES:12)
Block(-8,27,-5,LEAVES:12)
Block(-8,27,-4,LEAVES:12)
Block(-8,27,-3,LEAVES:12)
Block(-8,27,-2,LEAVES:12)
Block(-8,27,-1,LEAVES:12)
Block(-8,27,0,LEAVES:12)
Block(-8,27,1,LEAVES:12)
Block(-8,27,2,LEAVES:12)
Block(-7,23,-6,LEAVES:12)
Block(-7,23,-4,LEAVES:12)
Block(-7,23,3,LEAVES:12)
Block(-7,24,-5,LEAVES:12)
Block(-7,24,-4,LEAVES:12)
Block(-7,24,0,LEAVES:12)
Block(-7,24,1,LEAVES:12)
Block(-7,24,2,LEAVES:12)
Block(-7,24,3,LEAVES:12)
Block(-7,25,-7,LEAVES:12)
Block(-7,25,-6,LEAVES:12)
Block(-7,25,-5,LEAVES:12)
Block(-7,25,-4,LEAVES:12)
Block(-7,25,-3,LEAVES:12)
Block(-7,25,-2,LEAVES:12)
Block(-7,25,-1,LOG:13)
Block(-7,25,0,LEAVES:12)
Block(-7,25,1,LEAVES:12)
Block(-7,25,2,LEAVES:12)
Block(-7,26,-7,LOG:13)
Block(-7,26,-6,LEAVES:12)
Block(-7,26,-5,LEAVES:12)
Block(-7,26,-4,LEAVES:12)
Block(-7,26,-3,LEAVES:12)
Block(-7,26,-2,LEAVES:12)
Block(-7,26,-1,LEAVES:12)
Block(-7,26,0,LEAVES:12)
Block(-7,26,1,LEAVES:12)
Block(-7,26,2,LEAVES:12)
Block(-7,26,3,LEAVES:12)
Block(-7,27,-7,LEAVES:12)
Block(-7,27,-6,LEAVES:12)
Block(-7,27,-5,LEAVES:12)
Block(-7,27,-4,LEAVES:12)
Block(-7,27,-3,LEAVES:12)
Block(-7,27,-2,LEAVES:12)
Block(-7,27,-1,LEAVES:12)
Block(-7,27,0,LEAVES:12)
Block(-6,23,-6,LEAVES:12)
Block(-6,24,-7,LEAVES:12)
Block(-6,24,-6,LEAVES:12)
Block(-6,24,-5,LEAVES:12)
Block(-6,24,-4,LEAVES:12)
Block(-6,24,-2,LEAVES:12)
Block(-6,24,-1,LEAVES:12)
Block(-6,24,0,LEAVES:12)
Block(-6,24,1,LEAVES:12)
Block(-6,25,-7,LEAVES:12)
Block(-6,25,-6,LEAVES:12)
Block(-6,25,-5,LEAVES:12)
Block(-6,25,-4,LEAVES:12)
Block(-6,25,-3,LEAVES:12)
Block(-6,25,-2,LEAVES:12)
Block(-6,25,-1,LEAVES:12)
Block(-6,25,0,LEAVES:12)
Block(-6,25,1,LEAVES:12)
Block(-6,25,2,LEAVES:12)
Block(-6,25,3,LEAVES:12)
Block(-6,26,-7,LEAVES:12)
Block(-6,26,-6,LEAVES:12)
Block(-6,26,-5,LEAVES:12)
Block(-6,26,-4,LEAVES:12)
Block(-6,26,-3,LEAVES:12)
Block(-6,26,-2,LEAVES:12)
Block(-6,26,-1,LEAVES:12)
Block(-6,26,0,LEAVES:12)
Block(-6,26,1,LEAVES:12)
Block(-6,26,2,LEAVES:12)
Block(-6,27,-7,LEAVES:12)
Block(-6,27,-6,LEAVES:12)
Block(-6,27,-5,LEAVES:12)
Block(-6,27,-4,LEAVES:12)
Block(-6,27,-3,LEAVES:12)
Block(-6,27,-2,LEAVES:12)
Block(-6,27,-1,LEAVES:12)
Block(-6,27,1,LEAVES:12)
Block(-5,22,-4,LEAVES:12)
Block(-5,23,-4,LEAVES:12)
Block(-5,24,-5,LEAVES:12)
Block(-5,24,-4,LEAVES:12)
Block(-5,24,-3,LEAVES:12)
Block(-5,24,-2,LEAVES:12)
Block(-5,24,-1,LEAVES:12)
Block(-5,24,0,LEAVES:12)
Block(-5,24,1,LEAVES:12)
Block(-5,25,-6,LEAVES:12)
Block(-5,25,-5,LEAVES:12)
Block(-5,25,-4,LEAVES:12)
Block(-5,25,-3,LEAVES:12)
Block(-5,25,-2,LEAVES:12)
Block(-5,25,-1,LEAVES:12)
Block(-5,25,0,LEAVES:12)
Block(-5,25,1,LEAVES:12)
Block(-5,25,2,LEAVES:12)
Block(-5,26,-7,LEAVES:12)
Block(-5,26,-6,LEAVES:12)
Block(-5,26,-5,LEAVES:12)
Block(-5,26,-4,LEAVES:12)
Block(-5,26,-3,LEAVES:12)
Block(-5,26,-2,LEAVES:12)
Block(-5,26,-1,LEAVES:12)
Block(-5,26,0,LEAVES:12)
Block(-5,26,1,LEAVES:12)
Block(-5,27,-7,LEAVES:12)
Block(-5,27,-6,LEAVES:12)
Block(-5,27,-5,LEAVES:12)
Block(-5,27,-4,LEAVES:12)
Block(-5,27,-3,LEAVES:12)
Block(-5,27,-2,LEAVES:12)
Block(-4,24,-7,LEAVES:12)
Block(-4,24,-6,LEAVES:12)
Block(-4,24,-5,LEAVES:12)
Block(-4,24,-2,LEAVES:12)
Block(-4,24,0,LEAVES:12)
Block(-4,25,-7,LEAVES:12)
Block(-4,25,-6,LEAVES:12)
Block(-4,25,-5,LEAVES:12)
Block(-4,25,-4,LEAVES:12)
Block(-4,25,-3,LEAVES:12)
Block(-4,25,-2,LEAVES:12)
Block(-4,25,-1,LEAVES:12)
Block(-4,25,0,LEAVES:12)
Block(-4,25,1,LEAVES:12)
Block(-4,26,-7,LEAVES:12)
Block(-4,26,-5,LEAVES:12)
Block(-4,26,-4,LEAVES:12)
Block(-4,26,-3,LEAVES:12)
Block(-4,26,-2,LEAVES:12)
Block(-4,26,0,LEAVES:12)
Block(-4,27,-6,LEAVES:12)
Block(-4,27,-5,LEAVES:12)
Block(-4,27,-4,LEAVES:12)
Block(-3,20,-7,LEAVES:12)
Block(-3,21,-7,LEAVES:12)
Block(-3,22,-7,LEAVES:12)
Block(-3,23,-7,LEAVES:12)
Block(-3,24,-7,LEAVES:12)
Block(-3,24,-6,LEAVES:12)
Block(-3,24,-5,LEAVES:12)
Block(-3,24,-4,LEAVES:12)
Block(-3,25,-7,LEAVES:12)
Block(-3,25,-6,LEAVES:12)
Block(-3,25,-5,LEAVES:12)
Block(-3,25,-4,LEAVES:12)
Block(-3,25,-3,LEAVES:12)
Block(-3,25,2,LEAVES:12)
Block(-3,26,-7,LEAVES:12)
Block(-3,26,-6,LEAVES:12)
Block(-3,26,-5,LEAVES:12)
Block(-3,26,-4,LEAVES:12)
Block(-3,26,-2,LEAVES:12)
Block(-2,24,-7,LEAVES:12)
Block(-2,24,-5,LEAVES:12)
Block(-2,25,-7,LEAVES:12)
Block(-2,25,-6,LEAVES:12)
Block(-2,25,-5,LEAVES:12)
Block(-2,25,-4,LEAVES:12)
Block(-2,26,-7,LEAVES:12)
Block(-2,26,-5,LEAVES:12)
Block(-1,25,-5,LEAVES:12)

#######################################################################
# +-----------------------------------------------------------------+ #
# |                             Branches                            | #
# +-----------------------------------------------------------------+ #
#######################################################################

Branch(-16,0,0,true,CherryTreeCorrupted06C1R2,NORTH,100.0,0)

#######################################################################
# +-----------------------------------------------------------------+ #
# |                             Entities                            | #
# +-----------------------------------------------------------------+ #
#######################################################################


#######################################################################
# +-----------------------------------------------------------------+ #
# |                            Particles                            | #
# +-----------------------------------------------------------------+ #
#######################################################################


#######################################################################
# +-----------------------------------------------------------------+ #
# |                             Spawners                            | #
# +-----------------------------------------------------------------+ #
#######################################################################


#######################################################################
# +-----------------------------------------------------------------+ #
# |                             ModData                             | #
# +-----------------------------------------------------------------+ #
#######################################################################

