
#######################################################################
# +-----------------------------------------------------------------+ #
# |                            BO4 object                           | #
# +-----------------------------------------------------------------+ #
#######################################################################

Author: NLBlackEagle

Description: No description given

SettingsMode: WriteDisable


#######################################################################
# +-----------------------------------------------------------------+ #
# |                          Main settings                          | #
# +-----------------------------------------------------------------+ #
#######################################################################

Frequency: 0

SpawnHeight: highestBlock

UseCenterForHighestBlock: true

##############################
# Height Limits for the BO4. #
##############################

MinHeight: 0

MaxHeight: 255

InheritBO3: 

InheritBO3Rotation: NORTH

OverrideChildSettings: true

OverrideParentHeight: false

CanOverride: false

BranchFrequency: 0

BranchFrequencyGroup: 

MustBeBelowOther: false

MustBeInside: 

CannotBeInside: 

ReplacesBO3: 

MustBeInsideWorldBorders: false

CanSpawnOnWater: true

SpawnOnWaterOnly: false

SpawnUnderWater: false

SpawnAtWaterLevel: false

HeightOffset: 0

RemoveAir: true

ReplaceAbove: 

ReplaceBelow: 

ReplaceWithBiomeBlocks: true

ReplaceWithSurfaceBlock: GRASS

ReplaceWithGroundBlock: DIRT

ReplaceWithStoneBlock: STONE

SmoothRadius: 0

SmoothHeightOffset: 0

SmoothStartTop: false

SmoothStartWood: false

SmoothingSurfaceBlock: 

SmoothingGroundBlock: 

BO3Group: 

IsSpawnPoint: false

DoReplaceBlocks: true


#######################################################################
# +-----------------------------------------------------------------+ #
# |                              Blocks                             | #
# +-----------------------------------------------------------------+ #
#######################################################################

Block(-8,8,3,LEAVES:12)
Block(-8,9,-1,LEAVES:12)
Block(-8,9,3,LEAVES:12)
Block(-8,10,-1,LEAVES:12)
Block(-8,10,3,LEAVES:12)
Block(-8,11,-1,LEAVES:12)
Block(-8,11,2,LEAVES:12)
Block(-8,11,3,LOG:13)
Block(-8,11,4,LEAVES:12)
Block(-8,12,-1,LEAVES:12)
Block(-8,12,1,LEAVES:12)
Block(-8,12,2,LOG:13)
Block(-8,12,3,LOG:13)
Block(-8,12,4,LEAVES:12)
Block(-8,12,5,LEAVES:12)
Block(-8,12,6,LEAVES:12)
Block(-8,12,7,LEAVES:12)
Block(-8,12,8,LEAVES:12)
Block(-8,13,-1,LEAVES:12)
Block(-8,13,0,LEAVES:12)
Block(-8,13,1,LEAVES:12)
Block(-8,13,2,LOG_2:13)
Block(-8,13,3,LEAVES:12)
Block(-8,13,4,LEAVES:12)
Block(-8,13,5,LEAVES:12)
Block(-8,13,6,LEAVES:12)
Block(-8,13,7,LEAVES:12)
Block(-8,13,8,LEAVES:12)
Block(-8,14,-6,LEAVES:12)
Block(-8,14,-5,LEAVES:12)
Block(-8,14,-4,LEAVES:12)
Block(-8,14,-3,LEAVES:12)
Block(-8,14,-2,LEAVES:12)
Block(-8,14,-1,LEAVES:12)
Block(-8,14,0,LEAVES:12)
Block(-8,14,1,LEAVES:12)
Block(-8,14,2,LEAVES:12)
Block(-8,14,3,LEAVES:12)
Block(-8,14,4,LEAVES:12)
Block(-8,14,5,LEAVES:12)
Block(-8,14,6,LEAVES:12)
Block(-8,14,7,LEAVES:12)
Block(-8,14,8,LEAVES:12)
Block(-8,15,-6,LEAVES:12)
Block(-8,15,-5,LEAVES:12)
Block(-8,15,-4,LEAVES:12)
Block(-8,15,-3,LEAVES:12)
Block(-8,15,-2,LEAVES:12)
Block(-8,15,-1,LEAVES:12)
Block(-8,15,0,LEAVES:12)
Block(-8,15,1,LEAVES:12)
Block(-8,15,2,LEAVES:12)
Block(-8,15,7,LEAVES:12)
Block(-8,15,8,LEAVES:12)
Block(-8,16,-6,LEAVES:12)
Block(-8,16,-5,LEAVES:12)
Block(-8,16,-4,LEAVES:12)
Block(-8,16,-3,LEAVES:12)
Block(-8,16,-2,LEAVES:12)
Block(-8,16,-1,LEAVES:12)
Block(-8,16,0,LEAVES:12)
Block(-8,16,1,LEAVES:12)
Block(-7,11,2,LEAVES:12)
Block(-7,12,1,LOG:13)
Block(-7,12,2,LOG:13)
Block(-7,12,3,LEAVES:12)
Block(-7,12,4,LEAVES:12)
Block(-7,12,7,LEAVES:12)
Block(-7,13,-1,LEAVES:12)
Block(-7,13,0,LEAVES:12)
Block(-7,13,1,LOG:13)
Block(-7,13,2,LEAVES:12)
Block(-7,13,3,LEAVES:12)
Block(-7,13,4,LEAVES:12)
Block(-7,13,5,LEAVES:12)
Block(-7,13,6,LEAVES:12)
Block(-7,13,7,LEAVES:12)
Block(-7,13,8,LEAVES:12)
Block(-7,14,-5,LEAVES:12)
Block(-7,14,-4,LEAVES:12)
Block(-7,14,-3,LEAVES:12)
Block(-7,14,-2,LEAVES:12)
Block(-7,14,-1,LEAVES:12)
Block(-7,14,0,LEAVES:12)
Block(-7,14,1,LEAVES:12)
Block(-7,14,2,LEAVES:12)
Block(-7,14,3,LEAVES:12)
Block(-7,14,4,LEAVES:12)
Block(-7,14,5,LEAVES:12)
Block(-7,14,6,LEAVES:12)
Block(-7,14,7,LEAVES:12)
Block(-7,14,8,LEAVES:12)
Block(-7,15,-6,LEAVES:12)
Block(-7,15,-5,LEAVES:12)
Block(-7,15,-4,LEAVES:12)
Block(-7,15,-3,LEAVES:12)
Block(-7,15,-2,LEAVES:12)
Block(-7,15,-1,LEAVES:12)
Block(-7,15,0,LEAVES:12)
Block(-7,15,1,LEAVES:12)
Block(-7,15,2,LEAVES:12)
Block(-7,15,3,LEAVES:12)
Block(-7,15,5,LEAVES:12)
Block(-7,15,6,LEAVES:12)
Block(-7,15,7,LEAVES:12)
Block(-7,15,8,LEAVES:12)
Block(-7,16,-6,LEAVES:12)
Block(-7,16,-5,LEAVES:12)
Block(-7,16,-4,LEAVES:12)
Block(-7,16,-3,LEAVES:12)
Block(-7,16,-2,LEAVES:12)
Block(-7,16,-1,LEAVES:12)
Block(-7,16,0,LEAVES:12)
Block(-7,16,8,LEAVES:12)
Block(-6,9,2,LEAVES:12)
Block(-6,10,2,LEAVES:12)
Block(-6,11,2,LEAVES:12)
Block(-6,12,1,LEAVES:12)
Block(-6,12,2,LEAVES:12)
Block(-6,12,3,LEAVES:12)
Block(-6,13,-3,LEAVES:12)
Block(-6,13,-1,LEAVES:12)
Block(-6,13,0,LEAVES:12)
Block(-6,13,1,LOG:13)
Block(-6,13,2,LEAVES:12)
Block(-6,13,3,LEAVES:12)
Block(-6,13,4,LEAVES:12)
Block(-6,13,5,LEAVES:12)
Block(-6,13,6,LEAVES:12)
Block(-6,13,7,LEAVES:12)
Block(-6,14,-4,LEAVES:12)
Block(-6,14,-3,LEAVES:12)
Block(-6,14,-2,LEAVES:12)
Block(-6,14,-1,LEAVES:12)
Block(-6,14,0,LEAVES:12)
Block(-6,14,1,LOG:13)
Block(-6,14,2,LEAVES:12)
Block(-6,14,3,LEAVES:12)
Block(-6,14,4,LEAVES:12)
Block(-6,14,5,LEAVES:12)
Block(-6,14,6,LEAVES:12)
Block(-6,14,7,LEAVES:12)
Block(-6,14,8,LOG:13)
Block(-6,15,-5,LEAVES:12)
Block(-6,15,-4,LEAVES:12)
Block(-6,15,-3,LEAVES:12)
Block(-6,15,-2,LEAVES:12)
Block(-6,15,-1,LEAVES:12)
Block(-6,15,0,LEAVES:12)
Block(-6,15,1,LEAVES:12)
Block(-6,15,2,LEAVES:12)
Block(-6,15,3,LEAVES:12)
Block(-6,15,4,LEAVES:12)
Block(-6,15,5,LEAVES:12)
Block(-6,15,6,LEAVES:12)
Block(-6,15,7,LEAVES:12)
Block(-6,15,8,LEAVES:12)
Block(-6,16,-5,LEAVES:12)
Block(-6,16,-4,LEAVES:12)
Block(-6,16,-3,LEAVES:12)
Block(-6,16,-2,LEAVES:12)
Block(-6,16,-1,LEAVES:12)
Block(-6,16,0,LEAVES:12)
Block(-6,16,7,LEAVES:12)
Block(-6,16,8,LEAVES:12)
Block(-6,17,-3,LEAVES:12)
Block(-5,10,4,LEAVES:12)
Block(-5,11,4,LEAVES:12)
Block(-5,12,3,LEAVES:12)
Block(-5,12,4,LEAVES:12)
Block(-5,13,-4,LEAVES:12)
Block(-5,13,-3,LEAVES:12)
Block(-5,13,-2,LEAVES:12)
Block(-5,13,-1,LEAVES:12)
Block(-5,13,0,LOG_2:13)
Block(-5,13,1,LEAVES:12)
Block(-5,13,2,LEAVES:12)
Block(-5,13,3,LEAVES:12)
Block(-5,13,4,LEAVES:12)
Block(-5,13,5,LEAVES:12)
Block(-5,13,8,LEAVES:12)
Block(-5,14,-4,LEAVES:12)
Block(-5,14,-3,LEAVES:12)
Block(-5,14,-2,LEAVES:12)
Block(-5,14,-1,LOG_2:13)
Block(-5,14,0,LOG_2:13)
Block(-5,14,1,LEAVES:12)
Block(-5,14,2,LEAVES:12)
Block(-5,14,3,LEAVES:12)
Block(-5,14,4,LEAVES:12)
Block(-5,14,5,LEAVES:12)
Block(-5,14,6,LEAVES:12)
Block(-5,14,7,LOG:13)
Block(-5,14,8,LEAVES:12)
Block(-5,15,-4,LEAVES:12)
Block(-5,15,-3,LEAVES:12)
Block(-5,15,-2,LEAVES:12)
Block(-5,15,-1,LEAVES:12)
Block(-5,15,0,LEAVES:12)
Block(-5,15,1,LEAVES:12)
Block(-5,15,2,LEAVES:12)
Block(-5,15,3,LEAVES:12)
Block(-5,15,4,LEAVES:12)
Block(-5,15,5,LEAVES:12)
Block(-5,15,6,LEAVES:12)
Block(-5,15,7,LEAVES:12)
Block(-5,15,8,LEAVES:12)
Block(-5,16,-4,LEAVES:12)
Block(-5,16,-3,LEAVES:12)
Block(-5,16,-2,LEAVES:12)
Block(-5,16,-1,LEAVES:12)
Block(-5,16,0,LEAVES:12)
Block(-5,16,1,LEAVES:12)
Block(-5,16,6,LEAVES:12)
Block(-5,16,7,LEAVES:12)
Block(-5,16,8,LEAVES:12)
Block(-5,17,-4,LEAVES:12)
Block(-5,17,-3,LEAVES:12)
Block(-5,17,-2,LEAVES:12)
Block(-4,11,-1,LEAVES:12)
Block(-4,12,-1,LEAVES:12)
Block(-4,12,0,LEAVES:12)
Block(-4,12,2,LEAVES:12)
Block(-4,13,-3,LEAVES:12)
Block(-4,13,-2,LEAVES:12)
Block(-4,13,-1,LOG:13)
Block(-4,13,0,LEAVES:12)
Block(-4,13,1,LEAVES:12)
Block(-4,13,2,LEAVES:12)
Block(-4,13,3,LEAVES:12)
Block(-4,13,4,LEAVES:12)
Block(-4,13,5,LEAVES:12)
Block(-4,13,6,LEAVES:12)
Block(-4,14,-4,LEAVES:12)
Block(-4,14,-3,LOG_2:13)
Block(-4,14,-2,LOG:13)
Block(-4,14,-1,LOG:13)
Block(-4,14,0,LEAVES:12)
Block(-4,14,1,LEAVES:12)
Block(-4,14,2,LEAVES:12)
Block(-4,14,3,LEAVES:12)
Block(-4,14,4,LEAVES:12)
Block(-4,14,5,LEAVES:12)
Block(-4,14,6,LEAVES:12)
Block(-4,14,7,LEAVES:12)
Block(-4,14,8,LEAVES:12)
Block(-4,15,-5,LEAVES:12)
Block(-4,15,-4,LEAVES:12)
Block(-4,15,-3,LEAVES:12)
Block(-4,15,-2,LEAVES:12)
Block(-4,15,-1,LEAVES:12)
Block(-4,15,0,LEAVES:12)
Block(-4,15,1,LEAVES:12)
Block(-4,15,2,LEAVES:12)
Block(-4,15,3,LEAVES:12)
Block(-4,15,4,LEAVES:12)
Block(-4,15,5,LEAVES:12)
Block(-4,15,6,LOG:13)
Block(-4,15,7,LEAVES:12)
Block(-4,15,8,LEAVES:12)
Block(-4,16,-5,LEAVES:12)
Block(-4,16,-4,LEAVES:12)
Block(-4,16,-3,LEAVES:12)
Block(-4,16,-2,LEAVES:12)
Block(-4,16,-1,LEAVES:12)
Block(-4,16,0,LEAVES:12)
Block(-4,16,1,LEAVES:12)
Block(-4,16,2,LEAVES:12)
Block(-4,16,5,LEAVES:12)
Block(-4,16,6,LEAVES:12)
Block(-4,16,7,LEAVES:12)
Block(-4,16,8,LEAVES:12)
Block(-4,17,-4,LEAVES:12)
Block(-4,17,-3,LEAVES:12)
Block(-4,17,-2,LEAVES:12)
Block(-4,17,-1,LEAVES:12)
Block(-4,17,0,LEAVES:12)
Block(-3,12,1,LEAVES:12)
Block(-3,13,-1,LEAVES:12)
Block(-3,13,1,LEAVES:12)
Block(-3,13,2,LEAVES:12)
Block(-3,13,3,LEAVES:12)
Block(-3,13,4,LEAVES:12)
Block(-3,13,5,LEAVES:12)
Block(-3,13,6,LEAVES:12)
Block(-3,13,7,LEAVES:12)
Block(-3,14,-5,LEAVES:12)
Block(-3,14,-4,LOG:13)
Block(-3,14,-3,LEAVES:12)
Block(-3,14,-1,LOG:13)
Block(-3,14,0,LEAVES:12)
Block(-3,14,1,LEAVES:12)
Block(-3,14,2,LEAVES:12)
Block(-3,14,3,LEAVES:12)
Block(-3,14,4,LEAVES:12)
Block(-3,14,5,LEAVES:12)
Block(-3,14,6,LEAVES:12)
Block(-3,14,7,LEAVES:12)
Block(-3,14,8,LEAVES:12)
Block(-3,15,-5,LEAVES:12)
Block(-3,15,-4,LEAVES:12)
Block(-3,15,-3,LEAVES:12)
Block(-3,15,-2,LEAVES:12)
Block(-3,15,-1,LEAVES:12)
Block(-3,15,0,LEAVES:12)
Block(-3,15,1,LEAVES:12)
Block(-3,15,2,LEAVES:12)
Block(-3,15,3,LEAVES:12)
Block(-3,15,4,LEAVES:12)
Block(-3,15,5,LEAVES:12)
Block(-3,15,6,LEAVES:12)
Block(-3,15,7,LEAVES:12)
Block(-3,15,8,LEAVES:12)
Block(-3,16,-6,LEAVES:12)
Block(-3,16,-5,LEAVES:12)
Block(-3,16,-4,LEAVES:12)
Block(-3,16,-3,LEAVES:12)
Block(-3,16,-2,LEAVES:12)
Block(-3,16,-1,LEAVES:12)
Block(-3,16,0,LEAVES:12)
Block(-3,16,1,LEAVES:12)
Block(-3,16,6,LEAVES:12)
Block(-3,16,7,LEAVES:12)
Block(-3,16,8,LEAVES:12)
Block(-3,17,-4,LEAVES:12)
Block(-3,17,-3,LEAVES:12)
Block(-3,17,-2,LEAVES:12)
Block(-3,17,-1,LEAVES:12)
Block(-3,17,0,LEAVES:12)
Block(-2,9,8,LEAVES:12)
Block(-2,10,8,LEAVES:12)
Block(-2,11,8,LEAVES:12)
Block(-2,12,8,LEAVES:12)
Block(-2,13,0,LEAVES:12)
Block(-2,13,2,LEAVES:12)
Block(-2,13,3,LEAVES:12)
Block(-2,13,4,LEAVES:12)
Block(-2,13,5,LEAVES:12)
Block(-2,13,6,LEAVES:12)
Block(-2,13,7,LEAVES:12)
Block(-2,13,8,LEAVES:12)
Block(-2,14,-4,LEAVES:12)
Block(-2,14,-3,LEAVES:12)
Block(-2,14,-2,LEAVES:12)
Block(-2,14,-1,LEAVES:12)
Block(-2,14,1,LEAVES:12)
Block(-2,14,2,LEAVES:12)
Block(-2,14,3,LEAVES:12)
Block(-2,14,4,LEAVES:12)
Block(-2,14,5,LEAVES:12)
Block(-2,14,6,LEAVES:12)
Block(-2,14,7,LEAVES:12)
Block(-2,14,8,LEAVES:12)
Block(-2,15,-5,LEAVES:12)
Block(-2,15,-4,LEAVES:12)
Block(-2,15,-3,LEAVES:12)
Block(-2,15,-2,LEAVES:12)
Block(-2,15,-1,LEAVES:12)
Block(-2,15,1,LEAVES:12)
Block(-2,15,2,LEAVES:12)
Block(-2,15,3,LEAVES:12)
Block(-2,15,4,LEAVES:12)
Block(-2,15,5,LEAVES:12)
Block(-2,15,6,LEAVES:12)
Block(-2,15,7,LEAVES:12)
Block(-2,15,8,LEAVES:12)
Block(-2,16,-4,LEAVES:12)
Block(-2,16,-3,LEAVES:12)
Block(-2,16,-2,LEAVES:12)
Block(-2,16,-1,LEAVES:12)
Block(-2,16,0,LEAVES:12)
Block(-2,16,5,LEAVES:12)
Block(-2,16,6,LEAVES:12)
Block(-2,16,7,LEAVES:12)
Block(-2,16,8,LEAVES:12)
Block(-2,17,-3,LEAVES:12)
Block(-2,17,-2,LEAVES:12)
Block(-2,17,-1,LEAVES:12)
Block(-1,13,3,LEAVES:12)
Block(-1,13,6,LEAVES:12)
Block(-1,14,-3,LEAVES:12)
Block(-1,14,-2,LEAVES:12)
Block(-1,14,-1,LEAVES:12)
Block(-1,14,2,LEAVES:12)
Block(-1,14,3,LEAVES:12)
Block(-1,14,4,LEAVES:12)
Block(-1,14,5,LEAVES:12)
Block(-1,14,6,LEAVES:12)
Block(-1,14,7,LEAVES:12)
Block(-1,14,8,LEAVES:12)
Block(-1,15,-4,LEAVES:12)
Block(-1,15,-3,LEAVES:12)
Block(-1,15,-2,LEAVES:12)
Block(-1,15,-1,LEAVES:12)
Block(-1,15,0,LEAVES:12)
Block(-1,15,2,LEAVES:12)
Block(-1,15,3,LEAVES:12)
Block(-1,15,5,LEAVES:12)
Block(-1,15,6,LEAVES:12)
Block(-1,15,7,LEAVES:12)
Block(-1,15,8,LEAVES:12)
Block(-1,16,-4,LEAVES:12)
Block(-1,16,-3,LEAVES:12)
Block(-1,16,-2,LEAVES:12)
Block(-1,16,-1,LEAVES:12)
Block(-1,16,6,LEAVES:12)
Block(-1,16,8,LEAVES:12)
Block(-1,17,-4,LEAVES:12)
Block(-1,17,-3,LEAVES:12)
Block(-1,17,-2,LEAVES:12)
Block(0,14,-2,LEAVES:12)
Block(0,15,-3,LEAVES:12)
Block(0,15,-2,LEAVES:12)
Block(0,15,-1,LEAVES:12)
Block(0,15,6,LEAVES:12)
Block(0,16,-4,LEAVES:12)
Block(0,16,-3,LEAVES:12)
Block(0,16,-2,LEAVES:12)
Block(0,17,-3,LEAVES:12)
Block(1,15,0,LEAVES:12)
Block(1,16,-4,LEAVES:12)

#######################################################################
# +-----------------------------------------------------------------+ #
# |                             Branches                            | #
# +-----------------------------------------------------------------+ #
#######################################################################

Branch(0,0,16,true,CherryTree06C2R1,NORTH,100.0,0)

#######################################################################
# +-----------------------------------------------------------------+ #
# |                             Entities                            | #
# +-----------------------------------------------------------------+ #
#######################################################################


#######################################################################
# +-----------------------------------------------------------------+ #
# |                            Particles                            | #
# +-----------------------------------------------------------------+ #
#######################################################################


#######################################################################
# +-----------------------------------------------------------------+ #
# |                             Spawners                            | #
# +-----------------------------------------------------------------+ #
#######################################################################


#######################################################################
# +-----------------------------------------------------------------+ #
# |                             ModData                             | #
# +-----------------------------------------------------------------+ #
#######################################################################

