
#######################################################################
# +-----------------------------------------------------------------+ #
# |                            BO4 object                           | #
# +-----------------------------------------------------------------+ #
#######################################################################

Author: NLBlackEagle

Description: No description given

SettingsMode: WriteWithoutComments


#######################################################################
# +-----------------------------------------------------------------+ #
# |                          Main settings                          | #
# +-----------------------------------------------------------------+ #
#######################################################################

FixedRotation: 

Frequency: 0

SpawnHeight: highestBlock

UseCenterForHighestBlock: true

##############################
# Height Limits for the BO4. #
##############################

MinHeight: 0

MaxHeight: 255

InheritBO3: 

InheritBO3Rotation: NORTH

OverrideChildSettings: true

OverrideParentHeight: false

CanOverride: true

BranchFrequency: 0

BranchFrequencyGroup: 

MustBeBelowOther: false

MustBeInside: 

CannotBeInside: 

ReplacesBO3: 

MustBeInsideWorldBorders: false

CanSpawnOnWater: true

SpawnOnWaterOnly: false

SpawnUnderWater: false

SpawnAtWaterLevel: false

HeightOffset: 0

RemoveAir: true

ReplaceAbove: 

ReplaceBelow: 

ReplaceWithBiomeBlocks: false

ReplaceWithSurfaceBlock: GRASS

ReplaceWithGroundBlock: DIRT

ReplaceWithStoneBlock: STONE

SmoothRadius: 0

SmoothHeightOffset: 0

SmoothStartTop: false

SmoothStartWood: false

SmoothingSurfaceBlock: 

SmoothingGroundBlock: 

BO3Group: 

IsSpawnPoint: false

DoReplaceBlocks: true


#######################################################################
# +-----------------------------------------------------------------+ #
# |                              Blocks                             | #
# +-----------------------------------------------------------------+ #
#######################################################################

Block(-8,0,1,quark:iron_plate:1)
Block(-8,1,1,quark:iron_plate:1)
Block(-8,2,1,quark:iron_plate:1)
Block(-8,3,1,quark:iron_plate:1)
Block(-8,4,1,quark:iron_plate:1)
Block(-8,9,1,VINE:8)
Block(-8,10,1,VINE:8)
Block(-8,11,1,VINE:8)
Block(-8,12,1,VINE:8)
Block(-8,15,2,VINE:8)
Block(-8,16,2,VINE:8)
Block(-7,0,0,quark:iron_plate:1)
Block(-7,0,1,quark:iron_plate:1)
Block(-7,0,2,quark:iron_plate:1)
Block(-7,1,0,quark:iron_plate:1)
Block(-7,1,1,quark:iron_plate:1)
Block(-7,1,2,quark:iron_plate:1)
Block(-7,2,0,quark:iron_plate:1)
Block(-7,2,1,quark:iron_plate:1)
Block(-7,2,2,quark:iron_plate:1)
Block(-7,3,0,quark:iron_plate:1)
Block(-7,3,1,quark:iron_plate:1)
Block(-7,3,2,quark:iron_plate:1)
Block(-7,4,0,quark:iron_plate:1)
Block(-7,4,1,quark:iron_plate:1)
Block(-7,4,2,quark:iron_plate:1)
Block(-7,5,1,CONCRETE:15)
Block(-7,6,1,CONCRETE:4)
Block(-7,7,0,VINE:1)
Block(-7,7,1,quark:iron_plate:1)
Block(-7,8,0,VINE:1)
Block(-7,8,1,quark:iron_plate:1)
Block(-7,9,0,VINE:1)
Block(-7,9,1,quark:iron_plate:1)
Block(-7,9,3,VINE:4)
Block(-7,10,1,quark:iron_plate:1)
Block(-7,10,3,VINE:12)
Block(-7,10,6,rustic:iron_lattice:0)
Block(-7,10,8,VINE:8)
Block(-7,11,1,quark:iron_plate:1)
Block(-7,11,2,quark:iron_plate:1)
Block(-7,11,3,VINE:12)
Block(-7,11,6,rustic:iron_lattice:0)
Block(-7,11,8,VINE:8)
Block(-7,12,-5,VINE:8)
Block(-7,12,1,quark:iron_plate:1)
Block(-7,12,2,quark:iron_plate:1)
Block(-7,12,3,VINE:12)
Block(-7,13,-5,VINE:8)
Block(-7,13,1,VINE:9)
Block(-7,13,2,quark:iron_plate:1)
Block(-7,13,3,VINE:12)
Block(-7,13,6,VINE:8)
Block(-7,14,-5,VINE:8)
Block(-7,14,1,VINE:9)
Block(-7,14,2,quark:iron_plate:1)
Block(-7,14,3,VINE:12)
Block(-7,14,6,VINE:8)
Block(-7,15,-5,VINE:8)
Block(-7,15,1,VINE:9)
Block(-7,15,2,quark:iron_plate:1)
Block(-7,15,3,VINE:8)
Block(-7,15,6,VINE:8)
Block(-7,15,8,VINE:8)
Block(-7,16,-5,VINE:8)
Block(-7,16,1,VINE:8)
Block(-7,16,2,CONCRETE:7)
Block(-7,16,3,VINE:8)
Block(-7,16,6,VINE:8)
Block(-7,16,8,VINE:8)
Block(-7,17,2,IRON_FENCE:0)
Block(-7,18,2,IRON_FENCE:0)
Block(-7,19,2,quark:iron_plate_slab)
Block(-6,0,1,quark:iron_plate:1)
Block(-6,1,1,quark:iron_plate:1)
Block(-6,2,1,quark:iron_plate:1)
Block(-6,3,1,quark:iron_plate:1)
Block(-6,4,1,quark:iron_plate:1)
Block(-6,5,1,IRON_FENCE:0)
Block(-6,6,1,IRON_FENCE:0)
Block(-6,7,1,IRON_FENCE:0)
Block(-6,8,1,IRON_FENCE:0)
Block(-6,8,7,VINE:4)
Block(-6,9,1,IRON_FENCE:0)
Block(-6,9,5,VINE:1)
Block(-6,9,7,VINE:4)
Block(-6,10,1,IRON_FENCE:0)
Block(-6,10,5,VINE:1)
Block(-6,10,6,quark:iron_plate:1)
Block(-6,10,7,VINE:4)
Block(-6,11,1,IRON_FENCE:0)
Block(-6,11,2,quark:iron_plate_stairs:7)
Block(-6,11,3,quark:iron_plate:1)
Block(-6,11,4,quark:iron_plate:1)
Block(-6,11,5,quark:iron_plate:1)
Block(-6,11,6,quark:iron_plate:1)
Block(-6,11,7,quark:iron_plate:1)
Block(-6,11,8,quark:iron_plate:1)
Block(-6,12,1,quark:iron_plate_slab)
Block(-6,12,2,quark:iron_plate_stairs:2)
Block(-6,12,3,quark:iron_plate)
Block(-6,12,4,IRON_FENCE:0)
Block(-6,13,3,quark:iron_plate_stairs:2)
Block(-6,13,4,quark:iron_plate)
Block(-6,13,5,IRON_FENCE:0)
Block(-6,14,-6,VINE:9)
Block(-6,14,4,quark:iron_plate_stairs:2)
Block(-6,14,5,quark:iron_plate)
Block(-6,14,6,IRON_FENCE:0)
Block(-6,15,-6,VINE:9)
Block(-6,15,2,quark:iron_plate:1)
Block(-6,15,5,quark:iron_plate_stairs:2)
Block(-6,15,6,quark:iron_plate)
Block(-6,15,7,IRON_FENCE:0)
Block(-6,15,8,quark:iron_plate:1)
Block(-6,16,-6,VINE:9)
Block(-6,16,-5,quark:iron_plate:1)
Block(-6,16,-4,quark:iron_plate:1)
Block(-6,16,-3,quark:iron_plate:1)
Block(-6,16,-2,quark:iron_plate:1)
Block(-6,16,-1,quark:iron_plate:1)
Block(-6,16,0,quark:iron_plate:1)
Block(-6,16,1,quark:iron_plate:1)
Block(-6,16,2,quark:iron_plate:1)
Block(-6,16,3,quark:iron_plate:1)
Block(-6,16,4,quark:iron_plate:1)
Block(-6,16,5,quark:iron_plate:1)
Block(-6,16,6,quark:iron_plate:1)
Block(-6,16,7,quark:iron_plate:1)
Block(-6,16,8,quark:iron_plate:1)
Block(-6,17,-5,rustic:iron_lattice:0)
Block(-6,17,-4,rustic:iron_lattice:0)
Block(-6,17,-3,rustic:iron_lattice:0)
Block(-6,17,-2,rustic:iron_lattice:0)
Block(-6,17,-1,rustic:iron_lattice:0)
Block(-6,17,0,rustic:iron_lattice:0)
Block(-6,17,1,rustic:iron_lattice:0)
Block(-6,17,2,quark:iron_plate:1)
Block(-6,17,3,rustic:iron_lattice:0)
Block(-6,17,4,rustic:iron_lattice:0)
Block(-6,17,5,rustic:iron_lattice:0)
Block(-6,17,6,rustic:iron_lattice:0)
Block(-6,17,7,rustic:iron_lattice:0)
Block(-6,17,8,rustic:iron_lattice:0)
Block(-6,18,2,quark:iron_plate:1)
Block(-6,19,2,quark:iron_plate_stairs:0)
Block(-5,10,6,IRON_FENCE:0)
Block(-5,10,7,VINE:2)
Block(-5,11,2,quark:iron_plate:1)
Block(-5,11,6,quark:iron_plate)
Block(-5,11,7,VINE:2)
Block(-5,12,8,VINE:8)
Block(-5,13,8,VINE:8)
Block(-5,14,1,VINE:1)
Block(-5,15,1,VINE:1)
Block(-5,15,2,quark:iron_plate:1)
Block(-5,15,8,IRON_FENCE:0)
Block(-5,16,-7,quark:iron_plate:1)
Block(-5,16,-6,quark:iron_plate:1)
Block(-5,16,-5,quark:iron_plate:1)
Block(-5,16,-4,quark:iron_plate:1)
Block(-5,16,-3,quark:iron_plate:1)
Block(-5,16,-2,quark:iron_plate:1)
Block(-5,16,-1,quark:iron_plate:1)
Block(-5,16,0,quark:iron_plate:1)
Block(-5,16,1,quark:iron_plate:1)
Block(-5,16,2,quark:iron_plate:1)
Block(-5,16,3,quark:iron_plate:1)
Block(-5,16,4,quark:iron_plate:1)
Block(-5,16,5,quark:iron_plate:1)
Block(-5,16,6,quark:iron_plate:1)
Block(-5,16,7,quark:iron_plate:1)
Block(-5,16,8,quark:iron_plate:1)
Block(-5,17,-7,rustic:iron_lattice:0)
Block(-5,17,-6,rustic:iron_lattice:0)
Block(-5,17,-5,rustic:iron_lattice:0)
Block(-5,19,2,quark:iron_plate_slab:8)
Block(-4,7,3,VINE:4)
Block(-4,8,3,VINE:4)
Block(-4,9,3,VINE:4)
Block(-4,10,3,VINE:4)
Block(-4,11,2,quark:iron_plate:1)
Block(-4,11,3,VINE:4)
Block(-4,11,6,quark:iron_plate)
Block(-4,11,7,VINE:4)
Block(-4,13,8,CONCRETE:7)
Block(-4,14,8,CONCRETE:7)
Block(-4,15,8,CONCRETE:7)
Block(-4,16,-7,quark:iron_plate:1)
Block(-4,16,-6,quark:grate)
Block(-4,16,-5,quark:grate)
Block(-4,16,-4,quark:grate)
Block(-4,16,-3,quark:grate)
Block(-4,16,-2,quark:grate)
Block(-4,16,-1,quark:grate)
Block(-4,16,0,quark:grate)
Block(-4,16,1,quark:grate)
Block(-4,16,2,quark:iron_plate:1)
Block(-4,16,3,quark:grate)
Block(-4,16,4,quark:grate)
Block(-4,16,5,quark:grate)
Block(-4,16,6,quark:grate)
Block(-4,16,7,quark:grate)
Block(-4,16,8,quark:grate)
Block(-4,17,-7,rustic:iron_lattice:0)
Block(-4,17,1,VINE:1)
Block(-4,17,2,quark:iron_plate:1)
Block(-4,18,1,VINE:1)
Block(-4,18,2,quark:iron_plate:1)
Block(-4,19,2,quark:iron_plate_stairs:1)
Block(-3,5,1,VINE:1)
Block(-3,6,1,VINE:1)
Block(-3,7,1,VINE:1)
Block(-3,8,1,VINE:1)
Block(-3,9,1,VINE:1)
Block(-3,10,1,VINE:1)
Block(-3,11,1,VINE:1)
Block(-3,11,2,quark:iron_plate:1)
Block(-3,11,6,IRON_FENCE:0)
Block(-3,12,6,quark:iron_plate)
Block(-3,12,8,WOOD_STEP:13)
Block(-3,13,6,quark:iron_plate:1)
Block(-3,13,7,CONCRETE:7)
Block(-3,14,7,CONCRETE:7)
Block(-3,15,3,VINE:4)
Block(-3,15,7,CONCRETE:7)
Block(-3,16,-7,quark:iron_plate:1)
Block(-3,16,-6,quark:grate)
Block(-3,16,1,VINE:1)
Block(-3,16,3,VINE:4)
Block(-3,16,7,quark:grate)
Block(-3,16,8,CONCRETE:7)
Block(-3,17,-7,rustic:iron_lattice:0)
Block(-3,17,1,VINE:1)
Block(-3,17,2,quark:iron_plate:1)
Block(-3,17,3,VINE:4)
Block(-3,17,7,IRON_FENCE:0)
Block(-3,18,2,IRON_FENCE:0)
Block(-3,19,2,quark:iron_plate_slab)
Block(-2,11,2,quark:iron_plate:1)
Block(-2,12,6,rustic:iron_lattice:0)
Block(-2,12,7,WOOD_STEP:13)
Block(-2,12,8,WOOD_STEP:13)
Block(-2,13,6,IRON_FENCE:0)
Block(-2,13,7,CONCRETE:7)
Block(-2,14,7,CONCRETE:7)
Block(-2,15,7,CONCRETE:7)
Block(-2,16,-7,quark:iron_plate:1)
Block(-2,16,-6,quark:grate)
Block(-2,16,7,quark:grate)
Block(-2,16,8,CONCRETE:7)
Block(-2,17,-7,rustic:iron_lattice:0)
Block(-2,17,2,IRON_FENCE:0)
Block(-2,17,7,IRON_FENCE:0)
Block(-2,18,2,IRON_FENCE:0)
Block(-2,19,2,quark:iron_plate_slab)
Block(-1,10,3,VINE:4)
Block(-1,11,2,quark:iron_plate:1)
Block(-1,11,3,VINE:4)
Block(-1,11,6,IRON_FENCE:0)
Block(-1,12,6,quark:iron_plate)
Block(-1,12,7,VINE:4)
Block(-1,12,8,WOOD_STEP:13)
Block(-1,13,6,quark:iron_plate:1)
Block(-1,13,7,CONCRETE:7)
Block(-1,14,3,VINE:4)
Block(-1,14,7,CONCRETE:7)
Block(-1,15,3,VINE:4)
Block(-1,15,7,CONCRETE:7)
Block(-1,16,-7,quark:iron_plate:1)
Block(-1,16,-6,quark:grate)
Block(-1,16,3,VINE:4)
Block(-1,16,7,quark:grate)
Block(-1,16,8,CONCRETE:7)
Block(-1,17,-7,rustic:iron_lattice:0)
Block(-1,17,2,quark:iron_plate:1)
Block(-1,17,3,VINE:4)
Block(-1,17,7,IRON_FENCE:0)
Block(-1,18,2,IRON_FENCE:0)
Block(-1,19,2,quark:iron_plate_slab)
Block(0,8,1,VINE:1)
Block(0,9,1,VINE:1)
Block(0,9,7,VINE:4)
Block(0,10,1,VINE:1)
Block(0,10,7,VINE:4)
Block(0,11,1,VINE:1)
Block(0,11,2,quark:iron_plate:1)
Block(0,11,6,quark:iron_plate)
Block(0,11,7,VINE:4)
Block(0,13,8,CONCRETE:7)
Block(0,14,8,CONCRETE:7)
Block(0,15,8,CONCRETE:7)
Block(0,16,-7,quark:iron_plate:1)
Block(0,16,-6,quark:grate)
Block(0,16,-5,quark:grate)
Block(0,16,-4,quark:grate)
Block(0,16,-3,quark:grate)
Block(0,16,-2,quark:grate)
Block(0,16,-1,quark:grate)
Block(0,16,0,quark:grate)
Block(0,16,1,quark:grate)
Block(0,16,2,quark:iron_plate:1)
Block(0,16,3,quark:grate)
Block(0,16,4,quark:grate)
Block(0,16,5,quark:grate)
Block(0,16,6,quark:grate)
Block(0,16,7,quark:grate)
Block(0,16,8,quark:grate)
Block(0,17,-7,rustic:iron_lattice:0)
Block(0,17,2,quark:iron_plate:1)
Block(0,18,2,quark:iron_plate:1)
Block(0,19,2,quark:iron_plate_stairs:0)
Block(1,7,3,VINE:4)
Block(1,8,3,VINE:4)
Block(1,9,3,VINE:4)
Block(1,10,3,VINE:4)
Block(1,10,6,IRON_FENCE:0)
Block(1,10,8,VINE:8)
Block(1,11,2,quark:iron_plate:1)
Block(1,11,3,VINE:4)
Block(1,11,6,quark:iron_plate)
Block(1,11,8,VINE:8)
Block(1,13,1,VINE:1)
Block(1,14,1,VINE:1)
Block(1,15,1,VINE:1)
Block(1,15,2,quark:iron_plate:1)
Block(1,15,8,IRON_FENCE:0)
Block(1,16,-7,quark:iron_plate:1)
Block(1,16,-6,quark:iron_plate:1)
Block(1,16,-5,quark:iron_plate:1)
Block(1,16,-4,quark:iron_plate:1)
Block(1,16,-3,quark:iron_plate:1)
Block(1,16,-2,quark:iron_plate:1)
Block(1,16,-1,quark:iron_plate:1)
Block(1,16,0,quark:iron_plate:1)
Block(1,16,1,quark:iron_plate:1)
Block(1,16,2,quark:iron_plate:1)
Block(1,16,3,quark:iron_plate:1)
Block(1,16,4,quark:iron_plate:1)
Block(1,16,5,quark:iron_plate:1)
Block(1,16,6,quark:iron_plate:1)
Block(1,16,7,quark:iron_plate:1)
Block(1,16,8,quark:iron_plate:1)
Block(1,17,-7,rustic:iron_lattice:0)
Block(1,17,-6,rustic:iron_lattice:0)
Block(1,17,-5,rustic:iron_lattice:0)
Block(1,17,2,VINE:8)
Block(1,18,2,VINE:8)
Block(1,19,2,quark:iron_plate_slab:8)
Block(2,0,1,quark:iron_plate:1)
Block(2,1,1,quark:iron_plate:1)
Block(2,2,1,quark:iron_plate:1)
Block(2,3,1,quark:iron_plate:1)
Block(2,4,1,quark:iron_plate:1)
Block(2,6,1,quark:iron_plate_stairs:6)
Block(2,6,2,quark:iron_plate_stairs:4)
Block(2,6,7,VINE:4)
Block(2,7,0,quark:iron_plate_stairs:6)
Block(2,7,1,quark:iron_plate_stairs)
Block(2,7,7,VINE:4)
Block(2,8,7,VINE:4)
Block(2,9,7,VINE:4)
Block(2,10,5,VINE:1)
Block(2,10,6,quark:iron_plate:1)
Block(2,10,7,VINE:4)
Block(2,11,2,quark:iron_plate)
Block(2,11,3,quark:iron_plate:1)
Block(2,11,4,quark:iron_plate:1)
Block(2,11,5,quark:iron_plate:1)
Block(2,11,6,quark:iron_plate:1)
Block(2,11,7,quark:iron_plate:1)
Block(2,11,8,quark:iron_plate:1)
Block(2,12,1,quark:iron_plate_slab)
Block(2,12,2,quark:iron_plate_stairs:2)
Block(2,12,3,quark:iron_plate)
Block(2,12,4,IRON_FENCE:0)
Block(2,13,2,VINE:8)
Block(2,13,3,quark:iron_plate_stairs:2)
Block(2,13,4,quark:iron_plate)
Block(2,13,5,IRON_FENCE:0)
Block(2,14,2,VINE:8)
Block(2,14,4,quark:iron_plate_stairs:2)
Block(2,14,5,quark:iron_plate)
Block(2,14,6,IRON_FENCE:0)
Block(2,15,2,quark:iron_plate:1)
Block(2,15,5,quark:iron_plate_stairs:2)
Block(2,15,6,quark:iron_plate)
Block(2,15,7,IRON_FENCE:0)
Block(2,15,8,quark:iron_plate:1)
Block(2,16,-6,VINE:3)
Block(2,16,-5,quark:iron_plate:1)
Block(2,16,-4,quark:iron_plate:1)
Block(2,16,-3,quark:iron_plate:1)
Block(2,16,-2,quark:iron_plate:1)
Block(2,16,-1,quark:iron_plate:1)
Block(2,16,0,quark:iron_plate:1)
Block(2,16,1,quark:iron_plate:1)
Block(2,16,2,quark:iron_plate:1)
Block(2,16,3,quark:iron_plate:1)
Block(2,16,4,quark:iron_plate:1)
Block(2,16,5,quark:iron_plate:1)
Block(2,16,6,quark:iron_plate:1)
Block(2,16,7,quark:iron_plate:1)
Block(2,16,8,quark:iron_plate:1)
Block(2,17,-5,rustic:iron_lattice:0)
Block(2,17,-4,rustic:iron_lattice:0)
Block(2,17,-3,rustic:iron_lattice:0)
Block(2,17,-2,rustic:iron_lattice:0)
Block(2,17,-1,rustic:iron_lattice:0)
Block(2,17,0,rustic:iron_lattice:0)
Block(2,17,1,rustic:iron_lattice:0)
Block(2,17,2,quark:iron_plate:1)
Block(2,17,3,rustic:iron_lattice:0)
Block(2,17,4,rustic:iron_lattice:0)
Block(2,17,5,rustic:iron_lattice:0)
Block(2,17,6,rustic:iron_lattice:0)
Block(2,17,7,rustic:iron_lattice:0)
Block(2,17,8,rustic:iron_lattice:0)
Block(2,18,2,quark:iron_plate:1)
Block(2,19,2,quark:iron_plate_stairs:1)
Block(3,0,0,quark:iron_plate:1)
Block(3,0,1,quark:iron_plate:1)
Block(3,0,2,quark:iron_plate:1)
Block(3,1,0,quark:iron_plate:1)
Block(3,1,1,quark:iron_plate:1)
Block(3,1,2,quark:iron_plate:1)
Block(3,2,0,quark:iron_plate:1)
Block(3,2,1,quark:iron_plate:1)
Block(3,2,2,quark:iron_plate:1)
Block(3,3,0,quark:iron_plate:1)
Block(3,3,1,quark:iron_plate:1)
Block(3,3,2,quark:iron_plate:1)
Block(3,4,0,quark:iron_plate:1)
Block(3,4,1,quark:iron_plate:1)
Block(3,4,2,quark:iron_plate:1)
Block(3,5,1,CONCRETE:15)
Block(3,5,2,quark:iron_plate_stairs:4)
Block(3,6,1,CONCRETE:4)
Block(3,6,2,quark:iron_plate_stairs:1)
Block(3,7,0,quark:iron_plate_stairs:5)
Block(3,7,1,quark:iron_plate:1)
Block(3,8,0,quark:iron_plate_stairs:0)
Block(3,8,1,quark:iron_plate:1)
Block(3,9,0,VINE:1)
Block(3,9,1,quark:iron_plate:1)
Block(3,10,0,VINE:1)
Block(3,10,1,quark:iron_plate:1)
Block(3,10,6,rustic:iron_lattice:0)
Block(3,11,0,VINE:3)
Block(3,11,1,quark:iron_plate:1)
Block(3,11,2,quark:iron_plate:1)
Block(3,11,6,rustic:iron_lattice:0)
Block(3,12,0,VINE:3)
Block(3,12,1,quark:iron_plate:1)
Block(3,12,2,quark:iron_plate:1)
Block(3,13,0,VINE:2)
Block(3,13,2,quark:iron_plate:1)
Block(3,13,4,VINE:2)
Block(3,14,0,VINE:2)
Block(3,14,2,quark:iron_plate:1)
Block(3,14,4,VINE:2)
Block(3,14,6,VINE:2)
Block(3,15,-3,VINE:2)
Block(3,15,0,VINE:2)
Block(3,15,2,quark:iron_plate:1)
Block(3,15,4,VINE:2)
Block(3,15,6,VINE:2)
Block(3,16,-3,VINE:2)
Block(3,16,0,VINE:2)
Block(3,16,2,quark:iron_plate)
Block(3,16,4,VINE:2)
Block(3,16,8,VINE:2)
Block(3,17,2,IRON_FENCE:0)
Block(3,18,2,IRON_FENCE:0)
Block(3,19,2,quark:iron_plate_slab)
Block(4,0,1,quark:iron_plate:1)
Block(4,1,1,quark:iron_plate:1)
Block(4,2,1,quark:iron_plate:1)
Block(4,3,1,quark:iron_plate:1)
Block(4,4,1,quark:iron_plate:1)
Block(4,5,2,quark:iron_plate_stairs:1)
Block(4,8,0,quark:iron_plate_stairs:5)
Block(4,9,0,quark:iron_plate_slab)
Block(4,9,1,quark:iron_plate_slab)
Block(4,9,2,quark:iron_plate_slab)
Block(4,9,3,quark:iron_plate_slab)
Block(4,9,4,quark:iron_plate_slab)
Block(4,9,5,quark:iron_plate_slab_double)
Block(4,9,6,quark:iron_plate_slab:8)
Block(4,10,6,quark:iron_plate_slab)
Block(4,10,7,quark:iron_plate_slab_double)
Block(4,10,8,quark:iron_plate_slab:8)
Block(4,11,2,VINE:2)
Block(4,12,2,VINE:2)
Block(4,13,2,VINE:2)
Block(4,14,2,VINE:2)
Block(4,15,2,VINE:2)
Block(4,16,2,VINE:2)

#######################################################################
# +-----------------------------------------------------------------+ #
# |                             Branches                            | #
# +-----------------------------------------------------------------+ #
#######################################################################

Branch(16,0,0,true,GantryCraneC2R0,NORTH,100.0,0)

#######################################################################
# +-----------------------------------------------------------------+ #
# |                             Entities                            | #
# +-----------------------------------------------------------------+ #
#######################################################################


#######################################################################
# +-----------------------------------------------------------------+ #
# |                            Particles                            | #
# +-----------------------------------------------------------------+ #
#######################################################################


#######################################################################
# +-----------------------------------------------------------------+ #
# |                             Spawners                            | #
# +-----------------------------------------------------------------+ #
#######################################################################


#######################################################################
# +-----------------------------------------------------------------+ #
# |                             ModData                             | #
# +-----------------------------------------------------------------+ #
#######################################################################

