
#######################################################################
# +-----------------------------------------------------------------+ #
# |                            BO4 object                           | #
# +-----------------------------------------------------------------+ #
#######################################################################

Author: NLBlackEagle

Description: No description given

SettingsMode: WriteWithoutComments


#######################################################################
# +-----------------------------------------------------------------+ #
# |                          Main settings                          | #
# +-----------------------------------------------------------------+ #
#######################################################################

FixedRotation: 

Frequency: 0

SpawnHeight: highestBlock

UseCenterForHighestBlock: true

##############################
# Height Limits for the BO4. #
##############################

MinHeight: 0

MaxHeight: 255

InheritBO3: 

InheritBO3Rotation: NORTH

OverrideChildSettings: true

OverrideParentHeight: false

CanOverride: false

BranchFrequency: 0

BranchFrequencyGroup: 

MustBeBelowOther: false

MustBeInside: 

CannotBeInside: 

ReplacesBO3: 

MustBeInsideWorldBorders: false

CanSpawnOnWater: true

SpawnOnWaterOnly: false

SpawnUnderWater: false

SpawnAtWaterLevel: false

HeightOffset: 0

RemoveAir: false

ReplaceAbove: 

ReplaceBelow: 

ReplaceWithBiomeBlocks: true

ReplaceWithSurfaceBlock: GRASS

ReplaceWithGroundBlock: DIRT

ReplaceWithStoneBlock: STONE

SmoothRadius: 0

SmoothHeightOffset: 0

SmoothStartTop: false

SmoothStartWood: false

SmoothingSurfaceBlock: 

SmoothingGroundBlock: 

BO3Group: 

IsSpawnPoint: false

DoReplaceBlocks: false


#######################################################################
# +-----------------------------------------------------------------+ #
# |                              Blocks                             | #
# +-----------------------------------------------------------------+ #
#######################################################################

Block(-8,0,-2,STONE:0)
Block(-8,0,-1,STONE:0)
Block(-8,0,0,STONE:0)
Block(-8,0,1,STONE:0)
Block(-8,0,2,STONE:0)
Block(-8,0,3,STONE:0)
Block(-8,0,4,STONE:0)
Block(-8,0,5,STONE:0)
Block(-8,0,6,STONE:0)
Block(-8,0,7,STONE:0)
Block(-8,0,8,STONE:0)
Block(-8,1,-2,STONE:0)
Block(-8,1,-1,STONE:0)
Block(-8,1,0,STONE:0)
Block(-8,1,1,STONE:0)
Block(-8,1,2,STONE:0)
Block(-8,1,3,STONE:0)
Block(-8,1,4,STONE:0)
Block(-8,1,5,STONE:0)
Block(-8,1,6,STONE:0)
Block(-8,1,7,STONE:0)
Block(-8,1,8,STONE:0)
Block(-8,2,-2,STONE:0)
RandomBlock(-8,2,-1,SAND:0,50,biomesoplenty:dried_sand,100)
RandomBlock(-8,2,0,SAND:0,50,biomesoplenty:dried_sand,100)
Block(-8,2,1,STONE:0)
Block(-8,2,2,STONE:0)
Block(-8,2,3,STONE:0)
Block(-8,2,4,STONE:0)
Block(-8,2,5,STONE:0)
Block(-8,2,6,STONE:0)
Block(-8,2,7,STONE:0)
Block(-8,2,8,STONE:0)
RandomBlock(-8,3,0,SAND:0,50,biomesoplenty:dried_sand,100)
Block(-8,3,1,STONE:0)
Block(-8,3,2,STONE:0)
Block(-8,3,3,STONE:0)
Block(-8,3,4,STONE:0)
Block(-8,3,5,STONE:0)
Block(-8,3,6,STONE:0)
Block(-8,3,7,STONE:0)
Block(-8,3,8,STONE:0)
Block(-8,4,1,STONE:0)
Block(-8,4,2,STONE:0)
Block(-8,4,3,STONE:0)
Block(-8,4,4,STONE:0)
Block(-8,4,5,STONE:0)
Block(-8,4,6,STONE:0)
Block(-8,4,7,STONE:0)
Block(-8,4,8,STONE:0)
Block(-8,5,2,STONE:0)
Block(-8,5,3,STONE:0)
Block(-8,5,4,STONE:0)
Block(-8,5,5,STONE:0)
Block(-8,5,6,STONE:0)
Block(-8,5,7,STONE:0)
Block(-8,5,8,STONE:0)
RandomBlock(-8,6,3,SAND:0,50,biomesoplenty:dried_sand,100)
RandomBlock(-8,6,4,SAND:0,50,biomesoplenty:dried_sand,100)
Block(-8,6,5,STONE:0)
Block(-8,6,6,STONE:0)
Block(-8,6,7,STONE:0)
Block(-8,6,8,STONE:0)
RandomBlock(-8,7,4,SAND:0,50,biomesoplenty:dried_sand,100)
Block(-8,7,5,STONE:0)
Block(-8,7,6,STONE:0)
Block(-8,7,7,STONE:0)
Block(-8,7,8,STONE:0)
Block(-8,8,4,STONE:0)
Block(-8,8,5,STONE:0)
Block(-8,8,6,STONE:0)
Block(-8,8,7,STONE:0)
Block(-8,8,8,STONE:0)
RandomBlock(-8,9,4,SAND:0,50,biomesoplenty:dried_sand,100)
RandomBlock(-8,9,5,SAND:0,50,biomesoplenty:dried_sand,100)
Block(-8,9,6,STONE:0)
Block(-8,9,7,STONE:0)
Block(-8,9,8,STONE:0)
RandomBlock(-8,10,4,SAND:0,50,biomesoplenty:dried_sand,100)
RandomBlock(-8,10,5,SAND:0,50,biomesoplenty:dried_sand,100)
RandomBlock(-8,10,6,SAND:0,50,biomesoplenty:dried_sand,100)
RandomBlock(-8,10,7,SAND:0,50,biomesoplenty:dried_sand,100)
Block(-8,10,8,STONE:0)
RandomBlock(-8,11,6,SAND:0,50,biomesoplenty:dried_sand,100)
RandomBlock(-8,11,7,SAND:0,50,biomesoplenty:dried_sand,100)
RandomBlock(-8,11,8,SAND:0,50,biomesoplenty:dried_sand,100)
RandomBlock(-8,12,8,SAND:0,50,biomesoplenty:dried_sand,100)
Block(-7,0,-2,STONE:0)
Block(-7,0,-1,STONE:0)
Block(-7,0,0,STONE:0)
Block(-7,0,1,STONE:0)
Block(-7,0,2,STONE:0)
Block(-7,0,3,STONE:0)
Block(-7,0,4,STONE:0)
Block(-7,0,5,STONE:0)
Block(-7,0,6,STONE:0)
Block(-7,0,7,STONE:0)
Block(-7,0,8,STONE:0)
Block(-7,1,-2,STONE:0)
Block(-7,1,-1,STONE:0)
Block(-7,1,0,STONE:0)
Block(-7,1,1,STONE:0)
Block(-7,1,2,STONE:0)
Block(-7,1,3,STONE:0)
Block(-7,1,4,STONE:0)
Block(-7,1,5,STONE:0)
Block(-7,1,6,STONE:0)
Block(-7,1,7,STONE:0)
Block(-7,1,8,STONE:0)
Block(-7,2,-1,STONE:0)
Block(-7,2,0,STONE:0)
Block(-7,2,1,STONE:0)
Block(-7,2,2,STONE:0)
Block(-7,2,3,STONE:0)
Block(-7,2,4,STONE:0)
Block(-7,2,5,STONE:0)
Block(-7,2,6,STONE:0)
Block(-7,2,7,STONE:0)
Block(-7,2,8,STONE:0)
Block(-7,3,0,STONE:0)
Block(-7,3,1,STONE:0)
Block(-7,3,2,STONE:0)
Block(-7,3,3,STONE:0)
Block(-7,3,4,STONE:0)
Block(-7,3,5,STONE:0)
Block(-7,3,6,STONE:0)
Block(-7,3,7,STONE:0)
Block(-7,3,8,STONE:0)
Block(-7,4,1,STONE:0)
Block(-7,4,2,STONE:0)
Block(-7,4,3,STONE:0)
Block(-7,4,4,STONE:0)
Block(-7,4,5,STONE:0)
Block(-7,4,6,STONE:0)
Block(-7,4,7,STONE:0)
Block(-7,4,8,STONE:0)
Block(-7,5,1,STONE:0)
Block(-7,5,2,STONE:0)
Block(-7,5,3,STONE:0)
RandomBlock(-7,5,4,SAND:0,50,biomesoplenty:dried_sand,100)
Block(-7,5,5,STONE:0)
Block(-7,5,6,STONE:0)
Block(-7,5,7,STONE:0)
Block(-7,5,8,STONE:0)
RandomBlock(-7,6,2,SAND:0,50,biomesoplenty:dried_sand,100)
RandomBlock(-7,6,3,SAND:0,50,biomesoplenty:dried_sand,100)
RandomBlock(-7,6,4,SAND:0,50,biomesoplenty:dried_sand,100)
Block(-7,6,5,STONE:0)
Block(-7,6,6,STONE:0)
Block(-7,6,7,STONE:0)
Block(-7,6,8,STONE:0)
RandomBlock(-7,7,3,SAND:0,50,biomesoplenty:dried_sand,100)
RandomBlock(-7,7,4,SAND:0,50,biomesoplenty:dried_sand,100)
Block(-7,7,5,STONE:0)
Block(-7,7,6,STONE:0)
Block(-7,7,7,STONE:0)
Block(-7,7,8,STONE:0)
RandomBlock(-7,8,5,SAND:0,50,biomesoplenty:dried_sand,100)
RandomBlock(-7,8,6,SAND:0,50,biomesoplenty:dried_sand,100)
Block(-7,8,7,STONE:0)
Block(-7,8,8,STONE:0)
RandomBlock(-7,9,5,SAND:0,50,biomesoplenty:dried_sand,100)
RandomBlock(-7,9,6,SAND:0,50,biomesoplenty:dried_sand,100)
RandomBlock(-7,9,7,SAND:0,50,biomesoplenty:dried_sand,100)
Block(-7,9,8,STONE:0)
RandomBlock(-7,10,7,SAND:0,50,biomesoplenty:dried_sand,100)
RandomBlock(-7,10,8,SAND:0,50,biomesoplenty:dried_sand,100)
RandomBlock(-7,11,8,SAND:0,50,biomesoplenty:dried_sand,100)
Block(-6,0,-2,STONE:0)
Block(-6,0,-1,STONE:0)
Block(-6,0,0,STONE:0)
Block(-6,0,1,STONE:0)
Block(-6,0,2,STONE:0)
Block(-6,0,3,STONE:0)
Block(-6,0,4,STONE:0)
Block(-6,0,5,STONE:0)
Block(-6,0,6,STONE:0)
Block(-6,0,7,STONE:0)
Block(-6,0,8,STONE:0)
Block(-6,1,-2,STONE:0)
Block(-6,1,-1,STONE:0)
Block(-6,1,0,STONE:0)
Block(-6,1,1,STONE:0)
RandomBlock(-6,1,2,SAND:0,50,biomesoplenty:dried_sand,100)
RandomBlock(-6,1,3,SAND:0,50,biomesoplenty:dried_sand,100)
RandomBlock(-6,1,4,SAND:0,50,biomesoplenty:dried_sand,100)
Block(-6,1,5,STONE:0)
Block(-6,1,6,STONE:0)
Block(-6,1,7,STONE:0)
Block(-6,1,8,STONE:0)
Block(-6,2,-1,STONE:0)
Block(-6,2,0,STONE:0)
Block(-6,2,1,STONE:0)
Block(-6,2,2,STONE:0)
RandomBlock(-6,2,3,SAND:0,50,biomesoplenty:dried_sand,100)
Block(-6,2,4,STONE:0)
Block(-6,2,5,STONE:0)
Block(-6,2,6,STONE:0)
Block(-6,2,7,STONE:0)
Block(-6,2,8,STONE:0)
Block(-6,3,1,STONE:0)
Block(-6,3,2,STONE:0)
RandomBlock(-6,3,3,SAND:0,50,biomesoplenty:dried_sand,100)
Block(-6,3,4,STONE:0)
Block(-6,3,5,STONE:0)
Block(-6,3,6,STONE:0)
Block(-6,3,7,STONE:0)
Block(-6,3,8,STONE:0)
Block(-6,4,1,STONE:0)
Block(-6,4,2,STONE:0)
RandomBlock(-6,4,3,SAND:0,50,biomesoplenty:dried_sand,100)
RandomBlock(-6,4,4,SAND:0,50,biomesoplenty:dried_sand,100)
Block(-6,4,5,STONE:0)
Block(-6,4,6,STONE:0)
Block(-6,4,7,STONE:0)
Block(-6,4,8,STONE:0)
Block(-6,5,2,STONE:0)
RandomBlock(-6,5,3,SAND:0,50,biomesoplenty:dried_sand,100)
RandomBlock(-6,5,4,SAND:0,50,biomesoplenty:dried_sand,100)
Block(-6,5,5,STONE:0)
Block(-6,5,6,STONE:0)
Block(-6,5,7,STONE:0)
Block(-6,5,8,STONE:0)
RandomBlock(-6,6,4,SAND:0,50,biomesoplenty:dried_sand,100)
RandomBlock(-6,6,5,SAND:0,50,biomesoplenty:dried_sand,100)
Block(-6,6,6,STONE:0)
Block(-6,6,7,STONE:0)
Block(-6,6,8,STONE:0)
RandomBlock(-6,7,4,SAND:0,50,biomesoplenty:dried_sand,100)
RandomBlock(-6,7,5,SAND:0,50,biomesoplenty:dried_sand,100)
RandomBlock(-6,7,6,SAND:0,50,biomesoplenty:dried_sand,100)
Block(-6,7,7,STONE:0)
Block(-6,7,8,STONE:0)
RandomBlock(-6,8,5,SAND:0,50,biomesoplenty:dried_sand,100)
RandomBlock(-6,8,6,SAND:0,50,biomesoplenty:dried_sand,100)
RandomBlock(-6,8,7,SAND:0,50,biomesoplenty:dried_sand,100)
RandomBlock(-6,8,8,SAND:0,50,biomesoplenty:dried_sand,100)
RandomBlock(-6,9,7,SAND:0,50,biomesoplenty:dried_sand,100)
RandomBlock(-6,9,8,SAND:0,50,biomesoplenty:dried_sand,100)
Block(-5,0,-1,STONE:0)
Block(-5,0,0,STONE:0)
Block(-5,0,1,STONE:0)
Block(-5,0,2,STONE:0)
Block(-5,0,3,STONE:0)
Block(-5,0,4,STONE:0)
Block(-5,0,5,STONE:0)
Block(-5,0,6,STONE:0)
Block(-5,0,7,STONE:0)
Block(-5,0,8,STONE:0)
Block(-5,1,-1,STONE:0)
Block(-5,1,0,STONE:0)
Block(-5,1,1,STONE:0)
RandomBlock(-5,1,2,SAND:0,50,biomesoplenty:dried_sand,100)
RandomBlock(-5,1,3,SAND:0,50,biomesoplenty:dried_sand,100)
RandomBlock(-5,1,4,SAND:0,50,biomesoplenty:dried_sand,100)
Block(-5,1,5,STONE:0)
Block(-5,1,6,STONE:0)
Block(-5,1,7,STONE:0)
Block(-5,1,8,STONE:0)
Block(-5,2,0,STONE:0)
Block(-5,2,1,STONE:0)
RandomBlock(-5,2,2,SAND:0,50,biomesoplenty:dried_sand,100)
RandomBlock(-5,2,3,SAND:0,50,biomesoplenty:dried_sand,100)
RandomBlock(-5,2,4,SAND:0,50,biomesoplenty:dried_sand,100)
Block(-5,2,5,STONE:0)
Block(-5,2,6,STONE:0)
Block(-5,2,7,STONE:0)
Block(-5,2,8,STONE:0)
Block(-5,3,1,STONE:0)
Block(-5,3,2,STONE:0)
RandomBlock(-5,3,3,SAND:0,50,biomesoplenty:dried_sand,100)
RandomBlock(-5,3,4,SAND:0,50,biomesoplenty:dried_sand,100)
Block(-5,3,5,STONE:0)
Block(-5,3,6,STONE:0)
Block(-5,3,7,STONE:0)
Block(-5,3,8,STONE:0)
Block(-5,4,2,STONE:0)
RandomBlock(-5,4,3,SAND:0,50,biomesoplenty:dried_sand,100)
RandomBlock(-5,4,4,SAND:0,50,biomesoplenty:dried_sand,100)
RandomBlock(-5,4,5,SAND:0,50,biomesoplenty:dried_sand,100)
Block(-5,4,6,STONE:0)
Block(-5,4,7,STONE:0)
Block(-5,4,8,STONE:0)
RandomBlock(-5,5,2,SAND:0,50,biomesoplenty:dried_sand,100)
RandomBlock(-5,5,3,SAND:0,50,biomesoplenty:dried_sand,100)
RandomBlock(-5,5,4,SAND:0,50,biomesoplenty:dried_sand,100)
Block(-5,5,5,STONE:0)
Block(-5,5,6,STONE:0)
Block(-5,5,7,STONE:0)
Block(-5,5,8,STONE:0)
Block(-5,6,5,STONE:0)
RandomBlock(-5,6,6,SAND:0,50,biomesoplenty:dried_sand,100)
Block(-5,6,7,STONE:0)
Block(-5,6,8,STONE:0)
RandomBlock(-5,7,5,SAND:0,50,biomesoplenty:dried_sand,100)
RandomBlock(-5,7,6,SAND:0,50,biomesoplenty:dried_sand,100)
RandomBlock(-5,7,7,SAND:0,50,biomesoplenty:dried_sand,100)
Block(-5,7,8,STONE:0)
RandomBlock(-5,8,7,SAND:0,50,biomesoplenty:dried_sand,100)
RandomBlock(-5,8,8,SAND:0,50,biomesoplenty:dried_sand,100)
RandomBlock(-5,9,8,SAND:0,50,biomesoplenty:dried_sand,100)
Block(-4,0,-1,STONE:0)
Block(-4,0,0,STONE:0)
Block(-4,0,1,STONE:0)
Block(-4,0,2,STONE:0)
Block(-4,0,3,STONE:0)
Block(-4,0,4,STONE:0)
Block(-4,0,6,STONE:0)
Block(-4,0,7,STONE:0)
Block(-4,0,8,STONE:0)
Block(-4,1,-1,STONE:0)
Block(-4,1,0,STONE:0)
Block(-4,1,1,STONE:0)
Block(-4,1,2,STONE:0)
RandomBlock(-4,1,3,SAND:0,50,biomesoplenty:dried_sand,100)
RandomBlock(-4,1,4,SAND:0,50,biomesoplenty:dried_sand,100)
Block(-4,1,5,STONE:0)
Block(-4,1,6,STONE:0)
Block(-4,1,7,STONE:0)
Block(-4,1,8,STONE:0)
Block(-4,2,1,STONE:0)
Block(-4,2,2,STONE:0)
RandomBlock(-4,2,3,SAND:0,50,biomesoplenty:dried_sand,100)
RandomBlock(-4,2,4,SAND:0,50,biomesoplenty:dried_sand,100)
Block(-4,2,5,STONE:0)
RandomBlock(-4,2,6,SAND:0,50,biomesoplenty:dried_sand,100)
Block(-4,2,7,STONE:0)
Block(-4,2,8,STONE:0)
Block(-4,3,1,STONE:0)
Block(-4,3,2,STONE:0)
RandomBlock(-4,3,3,SAND:0,50,biomesoplenty:dried_sand,100)
RandomBlock(-4,3,4,SAND:0,50,biomesoplenty:dried_sand,100)
Block(-4,3,5,STONE:0)
Block(-4,3,6,STONE:0)
Block(-4,3,7,STONE:0)
Block(-4,3,8,STONE:0)
RandomBlock(-4,4,2,SAND:0,50,biomesoplenty:dried_sand,100)
RandomBlock(-4,4,3,SAND:0,50,biomesoplenty:dried_sand,100)
RandomBlock(-4,4,4,SAND:0,50,biomesoplenty:dried_sand,100)
RandomBlock(-4,4,5,SAND:0,50,biomesoplenty:dried_sand,100)
Block(-4,4,6,STONE:0)
Block(-4,4,7,STONE:0)
Block(-4,4,8,STONE:0)
RandomBlock(-4,5,2,SAND:0,50,biomesoplenty:dried_sand,100)
RandomBlock(-4,5,3,SAND:0,50,biomesoplenty:dried_sand,100)
RandomBlock(-4,5,4,SAND:0,50,biomesoplenty:dried_sand,100)
RandomBlock(-4,5,5,SAND:0,50,biomesoplenty:dried_sand,100)
Block(-4,5,6,STONE:0)
Block(-4,5,7,STONE:0)
Block(-4,5,8,STONE:0)
RandomBlock(-4,6,5,SAND:0,50,biomesoplenty:dried_sand,100)
Block(-4,6,6,STONE:0)
RandomBlock(-4,6,7,SAND:0,50,biomesoplenty:dried_sand,100)
Block(-4,6,8,STONE:0)
RandomBlock(-4,7,5,SAND:0,50,biomesoplenty:dried_sand,100)
RandomBlock(-4,7,7,SAND:0,50,biomesoplenty:dried_sand,100)
RandomBlock(-4,7,8,SAND:0,50,biomesoplenty:dried_sand,100)
RandomBlock(-4,8,8,SAND:0,50,biomesoplenty:dried_sand,100)
Block(-3,0,-2,STONE:0)
Block(-3,0,-1,STONE:0)
Block(-3,0,0,STONE:0)
Block(-3,0,1,STONE:0)
Block(-3,0,2,STONE:0)
Block(-3,0,3,STONE:0)
Block(-3,0,4,STONE:0)
Block(-3,0,5,STONE:0)
Block(-3,0,6,STONE:0)
Block(-3,0,7,STONE:0)
Block(-3,0,8,STONE:0)
Block(-3,1,-2,STONE:0)
Block(-3,1,-1,STONE:0)
Block(-3,1,0,STONE:0)
Block(-3,1,1,STONE:0)
Block(-3,1,2,STONE:0)
RandomBlock(-3,1,3,SAND:0,50,biomesoplenty:dried_sand,100)
Block(-3,1,4,STONE:0)
RandomBlock(-3,1,5,SAND:0,50,biomesoplenty:dried_sand,100)
RandomBlock(-3,1,6,SAND:0,50,biomesoplenty:dried_sand,100)
Block(-3,1,7,STONE:0)
Block(-3,1,8,STONE:0)
Block(-3,2,-1,STONE:0)
Block(-3,2,0,STONE:0)
Block(-3,2,1,STONE:0)
Block(-3,2,2,STONE:0)
RandomBlock(-3,2,3,SAND:0,50,biomesoplenty:dried_sand,100)
Block(-3,2,4,STONE:0)
RandomBlock(-3,2,5,SAND:0,50,biomesoplenty:dried_sand,100)
RandomBlock(-3,2,6,SAND:0,50,biomesoplenty:dried_sand,100)
Block(-3,2,7,STONE:0)
Block(-3,2,8,STONE:0)
RandomBlock(-3,3,1,SAND:0,50,biomesoplenty:dried_sand,100)
Block(-3,3,2,STONE:0)
RandomBlock(-3,3,3,SAND:0,50,biomesoplenty:dried_sand,100)
RandomBlock(-3,3,4,SAND:0,50,biomesoplenty:dried_sand,100)
RandomBlock(-3,3,5,SAND:0,50,biomesoplenty:dried_sand,100)
Block(-3,3,6,STONE:0)
Block(-3,3,7,STONE:0)
Block(-3,3,8,STONE:0)
RandomBlock(-3,4,1,SAND:0,50,biomesoplenty:dried_sand,100)
RandomBlock(-3,4,2,SAND:0,50,biomesoplenty:dried_sand,100)
RandomBlock(-3,4,3,SAND:0,50,biomesoplenty:dried_sand,100)
RandomBlock(-3,4,4,SAND:0,50,biomesoplenty:dried_sand,100)
Block(-3,4,5,STONE:0)
Block(-3,4,6,STONE:0)
Block(-3,4,7,STONE:0)
Block(-3,4,8,STONE:0)
RandomBlock(-3,5,2,SAND:0,50,biomesoplenty:dried_sand,100)
RandomBlock(-3,5,3,SAND:0,50,biomesoplenty:dried_sand,100)
RandomBlock(-3,5,4,SAND:0,50,biomesoplenty:dried_sand,100)
Block(-3,5,5,STONE:0)
Block(-3,5,6,STONE:0)
Block(-3,5,7,STONE:0)
Block(-3,5,8,STONE:0)
RandomBlock(-3,6,4,SAND:0,50,biomesoplenty:dried_sand,100)
Block(-3,6,5,STONE:0)
Block(-3,6,6,STONE:0)
RandomBlock(-3,6,7,SAND:0,50,biomesoplenty:dried_sand,100)
Block(-3,6,8,STONE:0)
RandomBlock(-3,7,7,SAND:0,50,biomesoplenty:dried_sand,100)
RandomBlock(-3,7,8,SAND:0,50,biomesoplenty:dried_sand,100)
RandomBlock(-3,8,8,SAND:0,50,biomesoplenty:dried_sand,100)
Block(-2,0,-2,STONE:0)
Block(-2,0,-1,STONE:0)
Block(-2,0,0,STONE:0)
Block(-2,0,1,STONE:0)
Block(-2,0,2,STONE:0)
Block(-2,0,3,STONE:0)
Block(-2,0,4,STONE:0)
Block(-2,0,5,STONE:0)
Block(-2,0,6,STONE:0)
Block(-2,0,7,STONE:0)
Block(-2,0,8,STONE:0)
Block(-2,1,-2,STONE:0)
Block(-2,1,-1,STONE:0)
Block(-2,1,0,STONE:0)
Block(-2,1,1,STONE:0)
RandomBlock(-2,1,2,SAND:0,50,biomesoplenty:dried_sand,100)
RandomBlock(-2,1,3,SAND:0,50,biomesoplenty:dried_sand,100)
Block(-2,1,4,STONE:0)
RandomBlock(-2,1,5,SAND:0,50,biomesoplenty:dried_sand,100)
Block(-2,1,6,STONE:0)
Block(-2,1,7,STONE:0)
Block(-2,1,8,STONE:0)
Block(-2,2,-1,STONE:0)
Block(-2,2,0,STONE:0)
RandomBlock(-2,2,1,SAND:0,50,biomesoplenty:dried_sand,100)
RandomBlock(-2,2,2,SAND:0,50,biomesoplenty:dried_sand,100)
RandomBlock(-2,2,3,SAND:0,50,biomesoplenty:dried_sand,100)
RandomBlock(-2,2,4,SAND:0,50,biomesoplenty:dried_sand,100)
RandomBlock(-2,2,5,SAND:0,50,biomesoplenty:dried_sand,100)
RandomBlock(-2,2,6,SAND:0,50,biomesoplenty:dried_sand,100)
Block(-2,2,7,STONE:0)
Block(-2,2,8,STONE:0)
RandomBlock(-2,3,1,SAND:0,50,biomesoplenty:dried_sand,100)
RandomBlock(-2,3,2,SAND:0,50,biomesoplenty:dried_sand,100)
RandomBlock(-2,3,3,SAND:0,50,biomesoplenty:dried_sand,100)
RandomBlock(-2,3,4,SAND:0,50,biomesoplenty:dried_sand,100)
Block(-2,3,5,STONE:0)
RandomBlock(-2,3,6,SAND:0,50,biomesoplenty:dried_sand,100)
Block(-2,3,7,STONE:0)
Block(-2,3,8,STONE:0)
RandomBlock(-2,4,1,SAND:0,50,biomesoplenty:dried_sand,100)
RandomBlock(-2,4,2,SAND:0,50,biomesoplenty:dried_sand,100)
RandomBlock(-2,4,3,SAND:0,50,biomesoplenty:dried_sand,100)
RandomBlock(-2,4,4,SAND:0,50,biomesoplenty:dried_sand,100)
Block(-2,4,5,STONE:0)
Block(-2,4,6,STONE:0)
Block(-2,4,7,STONE:0)
Block(-2,4,8,STONE:0)
RandomBlock(-2,5,3,SAND:0,50,biomesoplenty:dried_sand,100)
RandomBlock(-2,5,4,SAND:0,50,biomesoplenty:dried_sand,100)
Block(-2,5,5,STONE:0)
Block(-2,5,6,STONE:0)
Block(-2,5,7,STONE:0)
Block(-2,5,8,STONE:0)
RandomBlock(-2,6,4,SAND:0,50,biomesoplenty:dried_sand,100)
Block(-2,6,5,STONE:0)
Block(-2,6,6,STONE:0)
RandomBlock(-2,6,7,SAND:0,50,biomesoplenty:dried_sand,100)
RandomBlock(-2,6,8,SAND:0,50,biomesoplenty:dried_sand,100)
RandomBlock(-2,7,7,SAND:0,50,biomesoplenty:dried_sand,100)
RandomBlock(-2,7,8,SAND:0,50,biomesoplenty:dried_sand,100)
Block(-1,0,-3,STONE:0)
Block(-1,0,-2,STONE:0)
Block(-1,0,-1,STONE:0)
Block(-1,0,0,STONE:0)
Block(-1,0,1,STONE:0)
Block(-1,0,2,STONE:0)
Block(-1,0,3,STONE:0)
Block(-1,0,4,STONE:0)
Block(-1,0,5,STONE:0)
Block(-1,0,6,STONE:0)
Block(-1,0,7,STONE:0)
Block(-1,0,8,STONE:0)
Block(-1,1,-3,STONE:0)
Block(-1,1,-2,STONE:0)
Block(-1,1,-1,STONE:0)
Block(-1,1,0,STONE:0)
RandomBlock(-1,1,1,SAND:0,50,biomesoplenty:dried_sand,100)
RandomBlock(-1,1,2,SAND:0,50,biomesoplenty:dried_sand,100)
Block(-1,1,3,STONE:0)
Block(-1,1,4,STONE:0)
Block(-1,1,5,STONE:0)
Block(-1,1,6,STONE:0)
Block(-1,1,7,STONE:0)
Block(-1,1,8,STONE:0)
Block(-1,2,-2,STONE:0)
Block(-1,2,-1,STONE:0)
Block(-1,2,0,STONE:0)
RandomBlock(-1,2,1,SAND:0,50,biomesoplenty:dried_sand,100)
RandomBlock(-1,2,2,SAND:0,50,biomesoplenty:dried_sand,100)
RandomBlock(-1,2,3,SAND:0,50,biomesoplenty:dried_sand,100)
RandomBlock(-1,2,4,SAND:0,50,biomesoplenty:dried_sand,100)
RandomBlock(-1,2,5,SAND:0,50,biomesoplenty:dried_sand,100)
Block(-1,2,6,STONE:0)
Block(-1,2,7,STONE:0)
Block(-1,2,8,STONE:0)
Block(-1,3,-1,STONE:0)
Block(-1,3,0,STONE:0)
RandomBlock(-1,3,1,SAND:0,50,biomesoplenty:dried_sand,100)
RandomBlock(-1,3,2,SAND:0,50,biomesoplenty:dried_sand,100)
RandomBlock(-1,3,3,SAND:0,50,biomesoplenty:dried_sand,100)
RandomBlock(-1,3,4,SAND:0,50,biomesoplenty:dried_sand,100)
RandomBlock(-1,3,5,SAND:0,50,biomesoplenty:dried_sand,100)
Block(-1,3,6,STONE:0)
Block(-1,3,7,STONE:0)
Block(-1,3,8,STONE:0)
RandomBlock(-1,4,1,SAND:0,50,biomesoplenty:dried_sand,100)
RandomBlock(-1,4,2,SAND:0,50,biomesoplenty:dried_sand,100)
RandomBlock(-1,4,3,SAND:0,50,biomesoplenty:dried_sand,100)
RandomBlock(-1,4,4,SAND:0,50,biomesoplenty:dried_sand,100)
RandomBlock(-1,4,5,SAND:0,50,biomesoplenty:dried_sand,100)
Block(-1,4,6,STONE:0)
Block(-1,4,7,STONE:0)
Block(-1,4,8,STONE:0)
RandomBlock(-1,5,2,SAND:0,50,biomesoplenty:dried_sand,100)
RandomBlock(-1,5,3,SAND:0,50,biomesoplenty:dried_sand,100)
RandomBlock(-1,5,4,SAND:0,50,biomesoplenty:dried_sand,100)
RandomBlock(-1,5,5,SAND:0,50,biomesoplenty:dried_sand,100)
RandomBlock(-1,5,6,SAND:0,50,biomesoplenty:dried_sand,100)
Block(-1,5,7,STONE:0)
Block(-1,5,8,STONE:0)
RandomBlock(-1,6,3,SAND:0,50,biomesoplenty:dried_sand,100)
Block(-1,6,4,STONE:0)
Block(-1,6,5,STONE:0)
RandomBlock(-1,6,6,SAND:0,50,biomesoplenty:dried_sand,100)
RandomBlock(-1,6,7,SAND:0,50,biomesoplenty:dried_sand,100)
Block(-1,6,8,STONE:0)
RandomBlock(-1,7,7,SAND:0,50,biomesoplenty:dried_sand,100)
RandomBlock(-1,7,8,SAND:0,50,biomesoplenty:dried_sand,100)
RandomBlock(-1,8,8,SAND:0,50,biomesoplenty:dried_sand,100)
Block(0,0,-4,STONE:0)
Block(0,0,-3,STONE:0)
Block(0,0,-2,STONE:0)
Block(0,0,-1,STONE:0)
Block(0,0,0,STONE:0)
Block(0,0,1,STONE:0)
Block(0,0,2,STONE:0)
Block(0,0,3,STONE:0)
Block(0,0,4,STONE:0)
Block(0,0,5,STONE:0)
Block(0,0,6,STONE:0)
Block(0,0,7,STONE:0)
Block(0,0,8,STONE:0)
Block(0,1,-4,STONE:0)
Block(0,1,-3,STONE:0)
Block(0,1,-2,STONE:0)
Block(0,1,-1,STONE:0)
Block(0,1,0,STONE:0)
RandomBlock(0,1,1,SAND:0,50,biomesoplenty:dried_sand,100)
RandomBlock(0,1,2,SAND:0,50,biomesoplenty:dried_sand,100)
Block(0,1,3,STONE:0)
Block(0,1,4,STONE:0)
Block(0,1,5,STONE:0)
Block(0,1,6,STONE:0)
Block(0,1,7,STONE:0)
Block(0,1,8,STONE:0)
Block(0,2,-3,STONE:0)
Block(0,2,-2,STONE:0)
Block(0,2,-1,STONE:0)
Block(0,2,0,STONE:0)
RandomBlock(0,2,1,SAND:0,50,biomesoplenty:dried_sand,100)
RandomBlock(0,2,2,SAND:0,50,biomesoplenty:dried_sand,100)
Block(0,2,3,STONE:0)
Block(0,2,4,STONE:0)
Block(0,2,5,STONE:0)
Block(0,2,6,STONE:0)
Block(0,2,7,STONE:0)
Block(0,2,8,STONE:0)
Block(0,3,-2,STONE:0)
Block(0,3,-1,STONE:0)
Block(0,3,0,STONE:0)
RandomBlock(0,3,1,SAND:0,50,biomesoplenty:dried_sand,100)
RandomBlock(0,3,2,SAND:0,50,biomesoplenty:dried_sand,100)
RandomBlock(0,3,3,SAND:0,50,biomesoplenty:dried_sand,100)
Block(0,3,4,STONE:0)
Block(0,3,5,STONE:0)
Block(0,3,6,STONE:0)
Block(0,3,7,STONE:0)
Block(0,3,8,STONE:0)
RandomBlock(0,4,0,SAND:0,50,biomesoplenty:dried_sand,100)
RandomBlock(0,4,1,SAND:0,50,biomesoplenty:dried_sand,100)
RandomBlock(0,4,2,SAND:0,50,biomesoplenty:dried_sand,100)
Block(0,4,3,STONE:0)
Block(0,4,4,STONE:0)
Block(0,4,5,STONE:0)
Block(0,4,6,STONE:0)
Block(0,4,7,STONE:0)
Block(0,4,8,STONE:0)
RandomBlock(0,5,2,SAND:0,50,biomesoplenty:dried_sand,100)
Block(0,5,3,STONE:0)
RandomBlock(0,5,4,SAND:0,50,biomesoplenty:dried_sand,100)
RandomBlock(0,5,5,SAND:0,50,biomesoplenty:dried_sand,100)
Block(0,5,6,STONE:0)
Block(0,5,7,STONE:0)
Block(0,5,8,STONE:0)
RandomBlock(0,6,3,SAND:0,50,biomesoplenty:dried_sand,100)
RandomBlock(0,6,4,SAND:0,50,biomesoplenty:dried_sand,100)
RandomBlock(0,6,5,SAND:0,50,biomesoplenty:dried_sand,100)
RandomBlock(0,6,6,SAND:0,50,biomesoplenty:dried_sand,100)
RandomBlock(0,6,7,SAND:0,50,biomesoplenty:dried_sand,100)
Block(0,6,8,STONE:0)
RandomBlock(0,7,3,SAND:0,50,biomesoplenty:dried_sand,100)
RandomBlock(0,7,4,SAND:0,50,biomesoplenty:dried_sand,100)
RandomBlock(0,7,6,SAND:0,50,biomesoplenty:dried_sand,100)
RandomBlock(0,7,7,SAND:0,50,biomesoplenty:dried_sand,100)
RandomBlock(0,7,8,SAND:0,50,biomesoplenty:dried_sand,100)
RandomBlock(0,8,8,SAND:0,50,biomesoplenty:dried_sand,100)
Block(1,0,-4,STONE:0)
Block(1,0,-3,STONE:0)
Block(1,0,-2,STONE:0)
Block(1,0,-1,STONE:0)
Block(1,0,0,STONE:0)
Block(1,0,1,STONE:0)
Block(1,0,2,STONE:0)
Block(1,0,3,STONE:0)
Block(1,0,4,STONE:0)
Block(1,0,5,STONE:0)
Block(1,0,6,STONE:0)
Block(1,0,7,STONE:0)
Block(1,0,8,STONE:0)
Block(1,1,-4,STONE:0)
Block(1,1,-3,STONE:0)
Block(1,1,-2,STONE:0)
Block(1,1,-1,STONE:0)
RandomBlock(1,1,0,SAND:0,50,biomesoplenty:dried_sand,100)
RandomBlock(1,1,1,SAND:0,50,biomesoplenty:dried_sand,100)
RandomBlock(1,1,2,SAND:0,50,biomesoplenty:dried_sand,100)
Block(1,1,3,STONE:0)
Block(1,1,4,STONE:0)
Block(1,1,5,STONE:0)
Block(1,1,6,STONE:0)
Block(1,1,7,STONE:0)
Block(1,1,8,STONE:0)
Block(1,2,-3,STONE:0)
Block(1,2,-2,STONE:0)
Block(1,2,-1,STONE:0)
RandomBlock(1,2,0,SAND:0,50,biomesoplenty:dried_sand,100)
RandomBlock(1,2,1,SAND:0,50,biomesoplenty:dried_sand,100)
RandomBlock(1,2,2,SAND:0,50,biomesoplenty:dried_sand,100)
Block(1,2,3,STONE:0)
Block(1,2,4,STONE:0)
Block(1,2,5,STONE:0)
Block(1,2,6,STONE:0)
Block(1,2,7,STONE:0)
Block(1,2,8,STONE:0)
Block(1,3,-3,STONE:0)
Block(1,3,-2,STONE:0)
Block(1,3,-1,STONE:0)
RandomBlock(1,3,0,SAND:0,50,biomesoplenty:dried_sand,100)
RandomBlock(1,3,1,SAND:0,50,biomesoplenty:dried_sand,100)
RandomBlock(1,3,2,SAND:0,50,biomesoplenty:dried_sand,100)
Block(1,3,3,STONE:0)
Block(1,3,4,STONE:0)
Block(1,3,5,STONE:0)
Block(1,3,6,STONE:0)
Block(1,3,7,STONE:0)
Block(1,3,8,STONE:0)
RandomBlock(1,4,-1,SAND:0,50,biomesoplenty:dried_sand,100)
Block(1,4,0,STONE:0)
RandomBlock(1,4,1,SAND:0,50,biomesoplenty:dried_sand,100)
RandomBlock(1,4,2,SAND:0,50,biomesoplenty:dried_sand,100)
Block(1,4,3,STONE:0)
Block(1,4,4,STONE:0)
RandomBlock(1,4,5,SAND:0,50,biomesoplenty:dried_sand,100)
Block(1,4,6,STONE:0)
Block(1,4,7,STONE:0)
Block(1,4,8,STONE:0)
RandomBlock(1,5,2,SAND:0,50,biomesoplenty:dried_sand,100)
Block(1,5,3,STONE:0)
RandomBlock(1,5,4,SAND:0,50,biomesoplenty:dried_sand,100)
RandomBlock(1,5,5,SAND:0,50,biomesoplenty:dried_sand,100)
Block(1,5,6,STONE:0)
Block(1,5,7,STONE:0)
Block(1,5,8,STONE:0)
RandomBlock(1,6,3,SAND:0,50,biomesoplenty:dried_sand,100)
RandomBlock(1,6,4,SAND:0,50,biomesoplenty:dried_sand,100)
Block(1,6,5,STONE:0)
RandomBlock(1,6,6,SAND:0,50,biomesoplenty:dried_sand,100)
Block(1,6,7,STONE:0)
Block(1,6,8,STONE:0)
RandomBlock(1,7,3,SAND:0,50,biomesoplenty:dried_sand,100)
RandomBlock(1,7,4,SAND:0,50,biomesoplenty:dried_sand,100)
RandomBlock(1,7,6,SAND:0,50,biomesoplenty:dried_sand,100)
RandomBlock(1,7,7,SAND:0,50,biomesoplenty:dried_sand,100)
Block(1,7,8,STONE:0)
RandomBlock(1,8,7,SAND:0,50,biomesoplenty:dried_sand,100)
RandomBlock(1,8,8,SAND:0,50,biomesoplenty:dried_sand,100)
RandomBlock(1,9,8,SAND:0,50,biomesoplenty:dried_sand,100)
Block(2,0,-5,STONE:0)
Block(2,0,-4,STONE:0)
Block(2,0,-3,STONE:0)
Block(2,0,-2,STONE:0)
Block(2,0,-1,STONE:0)
Block(2,0,0,STONE:0)
Block(2,0,1,STONE:0)
Block(2,0,2,STONE:0)
Block(2,0,3,STONE:0)
Block(2,0,4,STONE:0)
Block(2,0,5,STONE:0)
Block(2,0,6,STONE:0)
Block(2,0,7,STONE:0)
Block(2,0,8,STONE:0)
RandomBlock(2,1,-4,SAND:0,50,biomesoplenty:dried_sand,100)
RandomBlock(2,1,-3,SAND:0,50,biomesoplenty:dried_sand,100)
Block(2,1,-2,STONE:0)
RandomBlock(2,1,-1,SAND:0,50,biomesoplenty:dried_sand,100)
RandomBlock(2,1,0,SAND:0,50,biomesoplenty:dried_sand,100)
RandomBlock(2,1,1,SAND:0,50,biomesoplenty:dried_sand,100)
Block(2,1,2,STONE:0)
Block(2,1,3,STONE:0)
Block(2,1,4,STONE:0)
Block(2,1,5,STONE:0)
Block(2,1,6,STONE:0)
Block(2,1,7,STONE:0)
Block(2,1,8,STONE:0)
RandomBlock(2,2,-3,SAND:0,50,biomesoplenty:dried_sand,100)
Block(2,2,-2,STONE:0)
RandomBlock(2,2,-1,SAND:0,50,biomesoplenty:dried_sand,100)
RandomBlock(2,2,0,SAND:0,50,biomesoplenty:dried_sand,100)
RandomBlock(2,2,1,SAND:0,50,biomesoplenty:dried_sand,100)
Block(2,2,2,STONE:0)
Block(2,2,3,STONE:0)
Block(2,2,4,STONE:0)
Block(2,2,5,STONE:0)
Block(2,2,6,STONE:0)
Block(2,2,7,STONE:0)
Block(2,2,8,STONE:0)
Block(2,3,-2,STONE:0)
RandomBlock(2,3,-1,SAND:0,50,biomesoplenty:dried_sand,100)
RandomBlock(2,3,0,SAND:0,50,biomesoplenty:dried_sand,100)
RandomBlock(2,3,1,SAND:0,50,biomesoplenty:dried_sand,100)
Block(2,3,2,STONE:0)
Block(2,3,3,STONE:0)
Block(2,3,4,STONE:0)
Block(2,3,5,STONE:0)
Block(2,3,6,STONE:0)
Block(2,3,7,STONE:0)
Block(2,3,8,STONE:0)
Block(2,4,-2,STONE:0)
Block(2,4,-1,STONE:0)
RandomBlock(2,4,0,SAND:0,50,biomesoplenty:dried_sand,100)
RandomBlock(2,4,1,SAND:0,50,biomesoplenty:dried_sand,100)
Block(2,4,2,STONE:0)
Block(2,4,3,STONE:0)
Block(2,4,4,STONE:0)
Block(2,4,5,STONE:0)
Block(2,4,6,STONE:0)
Block(2,4,7,STONE:0)
Block(2,4,8,STONE:0)
RandomBlock(2,5,2,SAND:0,50,biomesoplenty:dried_sand,100)
Block(2,5,3,STONE:0)
Block(2,5,4,STONE:0)
Block(2,5,5,STONE:0)
Block(2,5,6,STONE:0)
Block(2,5,7,STONE:0)
Block(2,5,8,STONE:0)
Block(2,6,1,STONE:0)
Block(2,6,2,STONE:0)
RandomBlock(2,6,3,SAND:0,50,biomesoplenty:dried_sand,100)
RandomBlock(2,6,4,SAND:0,50,biomesoplenty:dried_sand,100)
Block(2,6,5,STONE:0)
Block(2,6,6,STONE:0)
Block(2,6,7,STONE:0)
Block(2,6,8,STONE:0)
RandomBlock(2,7,2,SAND:0,50,biomesoplenty:dried_sand,100)
RandomBlock(2,7,3,SAND:0,50,biomesoplenty:dried_sand,100)
RandomBlock(2,7,4,SAND:0,50,biomesoplenty:dried_sand,100)
RandomBlock(2,7,5,SAND:0,50,biomesoplenty:dried_sand,100)
RandomBlock(2,7,6,SAND:0,50,biomesoplenty:dried_sand,100)
Block(2,7,7,STONE:0)
Block(2,7,8,STONE:0)
RandomBlock(2,8,5,SAND:0,50,biomesoplenty:dried_sand,100)
RandomBlock(2,8,6,SAND:0,50,biomesoplenty:dried_sand,100)
RandomBlock(2,8,7,SAND:0,50,biomesoplenty:dried_sand,100)
Block(2,8,8,STONE:0)
RandomBlock(2,9,7,SAND:0,50,biomesoplenty:dried_sand,100)
RandomBlock(2,9,8,SAND:0,50,biomesoplenty:dried_sand,100)
RandomBlock(2,10,8,SAND:0,50,biomesoplenty:dried_sand,100)
Block(3,0,-6,STONE:0)
Block(3,0,-5,STONE:0)
Block(3,0,-4,STONE:0)
Block(3,0,-3,STONE:0)
Block(3,0,-2,STONE:0)
Block(3,0,-1,STONE:0)
Block(3,0,0,STONE:0)
Block(3,0,1,STONE:0)
Block(3,0,2,STONE:0)
Block(3,0,3,STONE:0)
Block(3,0,4,STONE:0)
Block(3,0,5,STONE:0)
Block(3,0,6,STONE:0)
Block(3,0,7,STONE:0)
Block(3,0,8,STONE:0)
Block(3,1,-6,STONE:0)
Block(3,1,-5,STONE:0)
Block(3,1,-4,STONE:0)
RandomBlock(3,1,-3,SAND:0,50,biomesoplenty:dried_sand,100)
RandomBlock(3,1,-2,SAND:0,50,biomesoplenty:dried_sand,100)
RandomBlock(3,1,-1,SAND:0,50,biomesoplenty:dried_sand,100)
Block(3,1,0,STONE:0)
RandomBlock(3,1,1,SAND:0,50,biomesoplenty:dried_sand,100)
Block(3,1,2,STONE:0)
Block(3,1,3,STONE:0)
Block(3,1,4,STONE:0)
Block(3,1,5,STONE:0)
Block(3,1,6,STONE:0)
Block(3,1,7,STONE:0)
Block(3,1,8,STONE:0)
RandomBlock(3,2,-5,SAND:0,50,biomesoplenty:dried_sand,100)
RandomBlock(3,2,-4,SAND:0,50,biomesoplenty:dried_sand,100)
RandomBlock(3,2,-3,SAND:0,50,biomesoplenty:dried_sand,100)
RandomBlock(3,2,-2,SAND:0,50,biomesoplenty:dried_sand,100)
RandomBlock(3,2,-1,SAND:0,50,biomesoplenty:dried_sand,100)
RandomBlock(3,2,0,SAND:0,50,biomesoplenty:dried_sand,100)
RandomBlock(3,2,1,SAND:0,50,biomesoplenty:dried_sand,100)
Block(3,2,2,STONE:0)
Block(3,2,3,STONE:0)
Block(3,2,4,STONE:0)
Block(3,2,5,STONE:0)
Block(3,2,6,STONE:0)
Block(3,2,7,STONE:0)
Block(3,2,8,STONE:0)
RandomBlock(3,3,-4,SAND:0,50,biomesoplenty:dried_sand,100)
RandomBlock(3,3,-3,SAND:0,50,biomesoplenty:dried_sand,100)
RandomBlock(3,3,-2,SAND:0,50,biomesoplenty:dried_sand,100)
RandomBlock(3,3,-1,SAND:0,50,biomesoplenty:dried_sand,100)
RandomBlock(3,3,0,SAND:0,50,biomesoplenty:dried_sand,100)
RandomBlock(3,3,1,SAND:0,50,biomesoplenty:dried_sand,100)
RandomBlock(3,3,2,SAND:0,50,biomesoplenty:dried_sand,100)
Block(3,3,3,STONE:0)
Block(3,3,4,STONE:0)
Block(3,3,5,STONE:0)
Block(3,3,6,STONE:0)
Block(3,3,7,STONE:0)
Block(3,3,8,STONE:0)
RandomBlock(3,4,-4,SAND:0,50,biomesoplenty:dried_sand,100)
RandomBlock(3,4,-1,SAND:0,50,biomesoplenty:dried_sand,100)
RandomBlock(3,4,0,SAND:0,50,biomesoplenty:dried_sand,100)
RandomBlock(3,4,1,SAND:0,50,biomesoplenty:dried_sand,100)
RandomBlock(3,4,2,SAND:0,50,biomesoplenty:dried_sand,100)
Block(3,4,3,STONE:0)
Block(3,4,4,STONE:0)
Block(3,4,5,STONE:0)
Block(3,4,6,STONE:0)
Block(3,4,7,STONE:0)
Block(3,4,8,STONE:0)
RandomBlock(3,5,0,SAND:0,50,biomesoplenty:dried_sand,100)
RandomBlock(3,5,1,SAND:0,50,biomesoplenty:dried_sand,100)
Block(3,5,2,STONE:0)
Block(3,5,3,STONE:0)
Block(3,5,4,STONE:0)
Block(3,5,5,STONE:0)
Block(3,5,6,STONE:0)
Block(3,5,7,STONE:0)
Block(3,5,8,STONE:0)
RandomBlock(3,6,0,SAND:0,50,biomesoplenty:dried_sand,100)
RandomBlock(3,6,1,SAND:0,50,biomesoplenty:dried_sand,100)
Block(3,6,2,STONE:0)
Block(3,6,3,STONE:0)
Block(3,6,4,STONE:0)
Block(3,6,5,STONE:0)
Block(3,6,6,STONE:0)
Block(3,6,7,STONE:0)
Block(3,6,8,STONE:0)
RandomBlock(3,7,2,SAND:0,50,biomesoplenty:dried_sand,100)
Block(3,7,3,STONE:0)
RandomBlock(3,7,4,SAND:0,50,biomesoplenty:dried_sand,100)
RandomBlock(3,7,5,SAND:0,50,biomesoplenty:dried_sand,100)
Block(3,7,6,STONE:0)
Block(3,7,7,STONE:0)
Block(3,7,8,STONE:0)
RandomBlock(3,8,3,SAND:0,50,biomesoplenty:dried_sand,100)
RandomBlock(3,8,5,SAND:0,50,biomesoplenty:dried_sand,100)
RandomBlock(3,8,6,SAND:0,50,biomesoplenty:dried_sand,100)
Block(3,8,7,STONE:0)
Block(3,8,8,STONE:0)
RandomBlock(3,9,6,SAND:0,50,biomesoplenty:dried_sand,100)
RandomBlock(3,9,7,SAND:0,50,biomesoplenty:dried_sand,100)
Block(3,9,8,STONE:0)
RandomBlock(3,10,7,SAND:0,50,biomesoplenty:dried_sand,100)
RandomBlock(3,10,8,SAND:0,50,biomesoplenty:dried_sand,100)
RandomBlock(3,11,8,SAND:0,50,biomesoplenty:dried_sand,100)
Block(4,0,-6,STONE:0)
Block(4,0,-5,STONE:0)
Block(4,0,-4,STONE:0)
Block(4,0,-3,STONE:0)
Block(4,0,-2,STONE:0)
Block(4,0,-1,STONE:0)
Block(4,0,0,STONE:0)
Block(4,0,1,STONE:0)
Block(4,0,2,STONE:0)
Block(4,0,4,STONE:0)
Block(4,0,5,STONE:0)
Block(4,0,6,STONE:0)
Block(4,0,7,STONE:0)
Block(4,0,8,STONE:0)
Block(4,1,-6,STONE:0)
Block(4,1,-5,STONE:0)
RandomBlock(4,1,-4,SAND:0,50,biomesoplenty:dried_sand,100)
RandomBlock(4,1,-3,SAND:0,50,biomesoplenty:dried_sand,100)
RandomBlock(4,1,-2,SAND:0,50,biomesoplenty:dried_sand,100)
Block(4,1,-1,STONE:0)
Block(4,1,0,STONE:0)
RandomBlock(4,1,1,SAND:0,50,biomesoplenty:dried_sand,100)
RandomBlock(4,1,2,SAND:0,50,biomesoplenty:dried_sand,100)
Block(4,1,3,STONE:0)
Block(4,1,4,STONE:0)
Block(4,1,5,STONE:0)
Block(4,1,6,STONE:0)
Block(4,1,7,STONE:0)
Block(4,1,8,STONE:0)
RandomBlock(4,2,-6,SAND:0,50,biomesoplenty:dried_sand,100)
RandomBlock(4,2,-5,SAND:0,50,biomesoplenty:dried_sand,100)
RandomBlock(4,2,-4,SAND:0,50,biomesoplenty:dried_sand,100)
RandomBlock(4,2,-3,SAND:0,50,biomesoplenty:dried_sand,100)
RandomBlock(4,2,-2,SAND:0,50,biomesoplenty:dried_sand,100)
RandomBlock(4,2,-1,SAND:0,50,biomesoplenty:dried_sand,100)
Block(4,2,0,STONE:0)
RandomBlock(4,2,1,SAND:0,50,biomesoplenty:dried_sand,100)
RandomBlock(4,2,2,SAND:0,50,biomesoplenty:dried_sand,100)
Block(4,2,3,STONE:0)
Block(4,2,4,STONE:0)
Block(4,2,5,STONE:0)
Block(4,2,6,STONE:0)
Block(4,2,7,STONE:0)
Block(4,2,8,STONE:0)
RandomBlock(4,3,-4,SAND:0,50,biomesoplenty:dried_sand,100)
RandomBlock(4,3,-3,SAND:0,50,biomesoplenty:dried_sand,100)
RandomBlock(4,3,-2,SAND:0,50,biomesoplenty:dried_sand,100)
RandomBlock(4,3,-1,SAND:0,50,biomesoplenty:dried_sand,100)
Block(4,3,0,STONE:0)
RandomBlock(4,3,1,SAND:0,50,biomesoplenty:dried_sand,100)
Block(4,3,2,STONE:0)
Block(4,3,3,STONE:0)
Block(4,3,4,STONE:0)
Block(4,3,5,STONE:0)
Block(4,3,6,STONE:0)
Block(4,3,7,STONE:0)
Block(4,3,8,STONE:0)
RandomBlock(4,4,-1,SAND:0,50,biomesoplenty:dried_sand,100)
Block(4,4,0,STONE:0)
Block(4,4,1,STONE:0)
Block(4,4,2,STONE:0)
Block(4,4,3,STONE:0)
Block(4,4,4,STONE:0)
Block(4,4,5,STONE:0)
Block(4,4,6,STONE:0)
Block(4,4,7,STONE:0)
Block(4,4,8,STONE:0)
RandomBlock(4,5,-1,SAND:0,50,biomesoplenty:dried_sand,100)
RandomBlock(4,5,0,SAND:0,50,biomesoplenty:dried_sand,100)
Block(4,5,1,STONE:0)
Block(4,5,2,STONE:0)
Block(4,5,3,STONE:0)
Block(4,5,4,STONE:0)
Block(4,5,5,STONE:0)
Block(4,5,6,STONE:0)
Block(4,5,7,STONE:0)
Block(4,5,8,STONE:0)
RandomBlock(4,6,-1,SAND:0,50,biomesoplenty:dried_sand,100)
Block(4,6,0,STONE:0)
Block(4,6,1,STONE:0)
Block(4,6,2,STONE:0)
Block(4,6,3,STONE:0)
Block(4,6,4,STONE:0)
Block(4,6,5,STONE:0)
Block(4,6,6,STONE:0)
Block(4,6,7,STONE:0)
Block(4,6,8,STONE:0)
RandomBlock(4,7,1,SAND:0,50,biomesoplenty:dried_sand,100)
RandomBlock(4,7,2,SAND:0,50,biomesoplenty:dried_sand,100)
Block(4,7,3,STONE:0)
Block(4,7,4,STONE:0)
Block(4,7,5,STONE:0)
Block(4,7,6,STONE:0)
Block(4,7,7,STONE:0)
Block(4,7,8,STONE:0)
RandomBlock(4,8,3,SAND:0,50,biomesoplenty:dried_sand,100)
RandomBlock(4,8,4,SAND:0,50,biomesoplenty:dried_sand,100)
RandomBlock(4,8,5,SAND:0,50,biomesoplenty:dried_sand,100)
RandomBlock(4,8,6,SAND:0,50,biomesoplenty:dried_sand,100)
Block(4,8,7,STONE:0)
Block(4,8,8,STONE:0)
RandomBlock(4,9,6,SAND:0,50,biomesoplenty:dried_sand,100)
RandomBlock(4,9,7,SAND:0,50,biomesoplenty:dried_sand,100)
Block(4,9,8,STONE:0)
RandomBlock(4,10,7,SAND:0,50,biomesoplenty:dried_sand,100)
RandomBlock(4,10,8,SAND:0,50,biomesoplenty:dried_sand,100)
RandomBlock(4,11,8,SAND:0,50,biomesoplenty:dried_sand,100)
Block(5,0,-7,STONE:0)
Block(5,0,-6,STONE:0)
Block(5,0,-5,STONE:0)
Block(5,0,-4,STONE:0)
Block(5,0,-3,STONE:0)
Block(5,0,-2,STONE:0)
Block(5,0,-1,STONE:0)
Block(5,0,0,STONE:0)
Block(5,0,1,STONE:0)
Block(5,0,4,STONE:0)
Block(5,0,5,STONE:0)
Block(5,0,6,STONE:0)
Block(5,0,7,STONE:0)
Block(5,0,8,STONE:0)
Block(5,1,-7,STONE:0)
RandomBlock(5,1,-6,SAND:0,50,biomesoplenty:dried_sand,100)
RandomBlock(5,1,-5,SAND:0,50,biomesoplenty:dried_sand,100)
RandomBlock(5,1,-4,SAND:0,50,biomesoplenty:dried_sand,100)
Block(5,1,-3,STONE:0)
Block(5,1,-2,STONE:0)
Block(5,1,-1,STONE:0)
Block(5,1,0,STONE:0)
Block(5,1,1,STONE:0)
Block(5,1,2,STONE:0)
Block(5,1,3,STONE:0)
Block(5,1,4,STONE:0)
Block(5,1,5,STONE:0)
Block(5,1,6,STONE:0)
Block(5,1,7,STONE:0)
Block(5,1,8,STONE:0)
Block(5,2,-6,STONE:0)
RandomBlock(5,2,-5,SAND:0,50,biomesoplenty:dried_sand,100)
RandomBlock(5,2,-4,SAND:0,50,biomesoplenty:dried_sand,100)
Block(5,2,-3,STONE:0)
Block(5,2,-2,STONE:0)
Block(5,2,-1,STONE:0)
Block(5,2,0,STONE:0)
Block(5,2,1,STONE:0)
Block(5,2,2,STONE:0)
Block(5,2,3,STONE:0)
Block(5,2,4,STONE:0)
Block(5,2,5,STONE:0)
Block(5,2,6,STONE:0)
Block(5,2,7,STONE:0)
Block(5,2,8,STONE:0)
RandomBlock(5,3,-5,SAND:0,50,biomesoplenty:dried_sand,100)
RandomBlock(5,3,-4,SAND:0,50,biomesoplenty:dried_sand,100)
Block(5,3,-3,STONE:0)
Block(5,3,-2,STONE:0)
Block(5,3,-1,STONE:0)
Block(5,3,0,STONE:0)
Block(5,3,1,STONE:0)
Block(5,3,2,STONE:0)
Block(5,3,3,STONE:0)
Block(5,3,4,STONE:0)
Block(5,3,5,STONE:0)
Block(5,3,6,STONE:0)
Block(5,3,7,STONE:0)
Block(5,3,8,STONE:0)
Block(5,4,-3,STONE:0)
Block(5,4,-2,STONE:0)
Block(5,4,-1,STONE:0)
Block(5,4,0,STONE:0)
Block(5,4,1,STONE:0)
Block(5,4,2,STONE:0)
Block(5,4,3,STONE:0)
Block(5,4,4,STONE:0)
Block(5,4,5,STONE:0)
Block(5,4,6,STONE:0)
Block(5,4,7,STONE:0)
Block(5,4,8,STONE:0)
RandomBlock(5,5,-3,SAND:0,50,biomesoplenty:dried_sand,100)
RandomBlock(5,5,-2,SAND:0,50,biomesoplenty:dried_sand,100)
RandomBlock(5,5,-1,SAND:0,50,biomesoplenty:dried_sand,100)
RandomBlock(5,5,0,SAND:0,50,biomesoplenty:dried_sand,100)
Block(5,5,1,STONE:0)
Block(5,5,2,STONE:0)
Block(5,5,3,STONE:0)
Block(5,5,4,STONE:0)
Block(5,5,5,STONE:0)
Block(5,5,6,STONE:0)
Block(5,5,7,STONE:0)
Block(5,5,8,STONE:0)
Block(5,6,-1,STONE:0)
Block(5,6,0,STONE:0)
Block(5,6,1,STONE:0)
Block(5,6,2,STONE:0)
Block(5,6,3,STONE:0)
Block(5,6,4,STONE:0)
Block(5,6,5,STONE:0)
Block(5,6,6,STONE:0)
Block(5,6,7,STONE:0)
Block(5,6,8,STONE:0)
RandomBlock(5,7,1,SAND:0,50,biomesoplenty:dried_sand,100)
Block(5,7,2,STONE:0)
RandomBlock(5,7,3,SAND:0,50,biomesoplenty:dried_sand,100)
Block(5,7,4,STONE:0)
Block(5,7,5,STONE:0)
Block(5,7,6,STONE:0)
Block(5,7,7,STONE:0)
Block(5,7,8,STONE:0)
RandomBlock(5,8,2,SAND:0,50,biomesoplenty:dried_sand,100)
RandomBlock(5,8,3,SAND:0,50,biomesoplenty:dried_sand,100)
RandomBlock(5,8,4,SAND:0,50,biomesoplenty:dried_sand,100)
Block(5,8,5,STONE:0)
Block(5,8,6,STONE:0)
Block(5,8,7,STONE:0)
Block(5,8,8,STONE:0)
Block(5,9,5,STONE:0)
Block(5,9,6,STONE:0)
Block(5,9,7,STONE:0)
Block(5,9,8,STONE:0)
RandomBlock(5,10,5,SAND:0,50,biomesoplenty:dried_sand,100)
Block(5,10,6,STONE:0)
Block(5,10,7,STONE:0)
Block(5,10,8,STONE:0)
RandomBlock(5,11,6,SAND:0,50,biomesoplenty:dried_sand,100)
RandomBlock(5,11,7,SAND:0,50,biomesoplenty:dried_sand,100)
RandomBlock(5,11,8,SAND:0,50,biomesoplenty:dried_sand,100)
RandomBlock(5,12,7,SAND:0,50,biomesoplenty:dried_sand,100)
RandomBlock(5,12,8,SAND:0,50,biomesoplenty:dried_sand,100)
Block(6,0,-7,STONE:0)
Block(6,0,-6,STONE:0)
Block(6,0,-5,STONE:0)
Block(6,0,-4,STONE:0)
Block(6,0,-3,STONE:0)
Block(6,0,-2,STONE:0)
Block(6,0,-1,STONE:0)
Block(6,0,1,STONE:0)
Block(6,0,3,STONE:0)
Block(6,0,4,STONE:0)
Block(6,0,5,STONE:0)
Block(6,0,6,STONE:0)
Block(6,0,7,STONE:0)
Block(6,0,8,STONE:0)
Block(6,1,-7,STONE:0)
RandomBlock(6,1,-6,SAND:0,50,biomesoplenty:dried_sand,100)
RandomBlock(6,1,-5,SAND:0,50,biomesoplenty:dried_sand,100)
Block(6,1,-4,STONE:0)
Block(6,1,-3,STONE:0)
Block(6,1,-2,STONE:0)
Block(6,1,-1,STONE:0)
Block(6,1,0,STONE:0)
Block(6,1,1,STONE:0)
Block(6,1,2,STONE:0)
Block(6,1,3,STONE:0)
Block(6,1,4,STONE:0)
Block(6,1,5,STONE:0)
Block(6,1,6,STONE:0)
Block(6,1,7,STONE:0)
Block(6,1,8,STONE:0)
RandomBlock(6,2,-7,SAND:0,50,biomesoplenty:dried_sand,100)
RandomBlock(6,2,-6,SAND:0,50,biomesoplenty:dried_sand,100)
RandomBlock(6,2,-5,SAND:0,50,biomesoplenty:dried_sand,100)
Block(6,2,-4,STONE:0)
Block(6,2,-3,STONE:0)
Block(6,2,-2,STONE:0)
Block(6,2,-1,STONE:0)
Block(6,2,0,STONE:0)
Block(6,2,1,STONE:0)
Block(6,2,2,STONE:0)
Block(6,2,3,STONE:0)
Block(6,2,4,STONE:0)
Block(6,2,5,STONE:0)
Block(6,2,6,STONE:0)
Block(6,2,7,STONE:0)
Block(6,2,8,STONE:0)
RandomBlock(6,3,-5,SAND:0,50,biomesoplenty:dried_sand,100)
Block(6,3,-4,STONE:0)
Block(6,3,-3,STONE:0)
Block(6,3,-2,STONE:0)
Block(6,3,-1,STONE:0)
Block(6,3,0,STONE:0)
Block(6,3,1,STONE:0)
Block(6,3,2,STONE:0)
Block(6,3,3,STONE:0)
Block(6,3,4,STONE:0)
Block(6,3,5,STONE:0)
Block(6,3,6,STONE:0)
Block(6,3,7,STONE:0)
Block(6,3,8,STONE:0)
Block(6,4,-4,STONE:0)
Block(6,4,-3,STONE:0)
Block(6,4,-2,STONE:0)
Block(6,4,-1,STONE:0)
Block(6,4,0,STONE:0)
Block(6,4,1,STONE:0)
Block(6,4,2,STONE:0)
Block(6,4,3,STONE:0)
Block(6,4,4,STONE:0)
Block(6,4,5,STONE:0)
Block(6,4,6,STONE:0)
Block(6,4,7,STONE:0)
Block(6,4,8,STONE:0)
RandomBlock(6,5,-4,SAND:0,50,biomesoplenty:dried_sand,100)
Block(6,5,-3,STONE:0)
Block(6,5,-2,STONE:0)
Block(6,5,-1,STONE:0)
Block(6,5,0,STONE:0)
Block(6,5,1,STONE:0)
Block(6,5,2,STONE:0)
Block(6,5,3,STONE:0)
Block(6,5,4,STONE:0)
Block(6,5,5,STONE:0)
Block(6,5,6,STONE:0)
Block(6,5,7,STONE:0)
Block(6,5,8,STONE:0)
RandomBlock(6,6,-3,SAND:0,50,biomesoplenty:dried_sand,100)
RandomBlock(6,6,-2,SAND:0,50,biomesoplenty:dried_sand,100)
Block(6,6,-1,STONE:0)
Block(6,6,0,STONE:0)
Block(6,6,1,STONE:0)
Block(6,6,2,STONE:0)
Block(6,6,3,STONE:0)
Block(6,6,4,STONE:0)
Block(6,6,5,STONE:0)
Block(6,6,6,STONE:0)
Block(6,6,7,STONE:0)
Block(6,6,8,STONE:0)
RandomBlock(6,7,-1,SAND:0,50,biomesoplenty:dried_sand,100)
Block(6,7,1,STONE:0)
Block(6,7,2,STONE:0)
RandomBlock(6,7,3,SAND:0,50,biomesoplenty:dried_sand,100)
Block(6,7,4,STONE:0)
Block(6,7,5,STONE:0)
Block(6,7,6,STONE:0)
Block(6,7,7,STONE:0)
Block(6,7,8,STONE:0)
RandomBlock(6,8,1,SAND:0,50,biomesoplenty:dried_sand,100)
RandomBlock(6,8,2,SAND:0,50,biomesoplenty:dried_sand,100)
Block(6,8,3,STONE:0)
Block(6,8,4,STONE:0)
Block(6,8,5,STONE:0)
Block(6,8,6,STONE:0)
Block(6,8,7,STONE:0)
Block(6,8,8,STONE:0)
RandomBlock(6,9,4,SAND:0,50,biomesoplenty:dried_sand,100)
Block(6,9,5,STONE:0)
Block(6,9,6,STONE:0)
Block(6,9,7,STONE:0)
Block(6,9,8,STONE:0)
RandomBlock(6,10,5,SAND:0,50,biomesoplenty:dried_sand,100)
Block(6,10,6,STONE:0)
Block(6,10,7,STONE:0)
Block(6,10,8,STONE:0)
RandomBlock(6,11,6,SAND:0,50,biomesoplenty:dried_sand,100)
Block(6,11,7,STONE:0)
Block(6,11,8,STONE:0)
RandomBlock(6,12,7,SAND:0,50,biomesoplenty:dried_sand,100)
RandomBlock(6,12,8,SAND:0,50,biomesoplenty:dried_sand,100)
RandomBlock(6,13,8,SAND:0,50,biomesoplenty:dried_sand,100)
Block(7,0,-7,STONE:0)
Block(7,0,-6,STONE:0)
Block(7,0,-5,STONE:0)
Block(7,0,-4,STONE:0)
Block(7,0,-3,STONE:0)
Block(7,0,-2,STONE:0)
Block(7,0,-1,STONE:0)
Block(7,0,0,STONE:0)
Block(7,0,1,STONE:0)
Block(7,0,3,STONE:0)
Block(7,0,4,STONE:0)
Block(7,0,5,STONE:0)
Block(7,0,6,STONE:0)
Block(7,0,7,STONE:0)
Block(7,0,8,STONE:0)
RandomBlock(7,1,-7,SAND:0,50,biomesoplenty:dried_sand,100)
RandomBlock(7,1,-6,SAND:0,50,biomesoplenty:dried_sand,100)
RandomBlock(7,1,-5,SAND:0,50,biomesoplenty:dried_sand,100)
Block(7,1,-4,STONE:0)
Block(7,1,-3,STONE:0)
Block(7,1,-2,STONE:0)
Block(7,1,-1,STONE:0)
Block(7,1,0,STONE:0)
Block(7,1,1,STONE:0)
Block(7,1,2,STONE:0)
Block(7,1,3,STONE:0)
Block(7,1,4,STONE:0)
Block(7,1,5,STONE:0)
Block(7,1,6,STONE:0)
Block(7,1,7,STONE:0)
Block(7,1,8,STONE:0)
RandomBlock(7,2,-6,SAND:0,50,biomesoplenty:dried_sand,100)
RandomBlock(7,2,-5,SAND:0,50,biomesoplenty:dried_sand,100)
Block(7,2,-4,STONE:0)
Block(7,2,-3,STONE:0)
Block(7,2,-2,STONE:0)
Block(7,2,-1,STONE:0)
Block(7,2,0,STONE:0)
Block(7,2,1,STONE:0)
Block(7,2,2,STONE:0)
Block(7,2,3,STONE:0)
Block(7,2,4,STONE:0)
Block(7,2,5,STONE:0)
Block(7,2,6,STONE:0)
Block(7,2,7,STONE:0)
Block(7,2,8,STONE:0)
RandomBlock(7,3,-5,SAND:0,50,biomesoplenty:dried_sand,100)
Block(7,3,-4,STONE:0)
Block(7,3,-3,STONE:0)
Block(7,3,-2,STONE:0)
Block(7,3,-1,STONE:0)
Block(7,3,0,STONE:0)
Block(7,3,1,STONE:0)
Block(7,3,2,STONE:0)
Block(7,3,3,STONE:0)
Block(7,3,4,STONE:0)
Block(7,3,5,STONE:0)
Block(7,3,6,STONE:0)
Block(7,3,7,STONE:0)
Block(7,3,8,STONE:0)
Block(7,4,-4,STONE:0)
Block(7,4,-3,STONE:0)
Block(7,4,-2,STONE:0)
Block(7,4,-1,STONE:0)
Block(7,4,0,STONE:0)
Block(7,4,1,STONE:0)
Block(7,4,2,STONE:0)
Block(7,4,3,STONE:0)
Block(7,4,4,STONE:0)
Block(7,4,5,STONE:0)
Block(7,4,6,STONE:0)
Block(7,4,7,STONE:0)
Block(7,4,8,STONE:0)
RandomBlock(7,5,-4,SAND:0,50,biomesoplenty:dried_sand,100)
Block(7,5,-3,STONE:0)
Block(7,5,-2,STONE:0)
Block(7,5,-1,STONE:0)
Block(7,5,0,STONE:0)
Block(7,5,1,STONE:0)
Block(7,5,2,STONE:0)
Block(7,5,3,STONE:0)
Block(7,5,4,STONE:0)
Block(7,5,5,STONE:0)
Block(7,5,6,STONE:0)
Block(7,5,7,STONE:0)
Block(7,5,8,STONE:0)
RandomBlock(7,6,-3,SAND:0,50,biomesoplenty:dried_sand,100)
Block(7,6,-2,STONE:0)
Block(7,6,-1,STONE:0)
Block(7,6,0,STONE:0)
Block(7,6,1,STONE:0)
Block(7,6,2,STONE:0)
Block(7,6,3,STONE:0)
Block(7,6,4,STONE:0)
Block(7,6,5,STONE:0)
Block(7,6,6,STONE:0)
Block(7,6,7,STONE:0)
Block(7,6,8,STONE:0)
RandomBlock(7,7,-2,SAND:0,50,biomesoplenty:dried_sand,100)
RandomBlock(7,7,-1,SAND:0,50,biomesoplenty:dried_sand,100)
Block(7,7,0,STONE:0)
Block(7,7,1,STONE:0)
Block(7,7,2,STONE:0)
RandomBlock(7,7,3,SAND:0,50,biomesoplenty:dried_sand,100)
Block(7,7,4,STONE:0)
Block(7,7,5,STONE:0)
Block(7,7,6,STONE:0)
Block(7,7,7,STONE:0)
Block(7,7,8,STONE:0)
RandomBlock(7,8,0,SAND:0,50,biomesoplenty:dried_sand,100)
RandomBlock(7,8,1,SAND:0,50,biomesoplenty:dried_sand,100)
Block(7,8,2,STONE:0)
Block(7,8,3,STONE:0)
Block(7,8,4,STONE:0)
Block(7,8,5,STONE:0)
Block(7,8,6,STONE:0)
Block(7,8,7,STONE:0)
Block(7,8,8,STONE:0)
RandomBlock(7,9,2,SAND:0,50,biomesoplenty:dried_sand,100)
RandomBlock(7,9,4,SAND:0,50,biomesoplenty:dried_sand,100)
Block(7,9,5,STONE:0)
Block(7,9,6,STONE:0)
Block(7,9,7,STONE:0)
Block(7,9,8,STONE:0)
RandomBlock(7,10,5,SAND:0,50,biomesoplenty:dried_sand,100)
Block(7,10,6,STONE:0)
Block(7,10,7,STONE:0)
Block(7,10,8,STONE:0)
Block(7,11,6,STONE:0)
Block(7,11,7,STONE:0)
Block(7,11,8,STONE:0)
RandomBlock(7,12,6,SAND:0,50,biomesoplenty:dried_sand,100)
Block(7,12,7,STONE:0)
Block(7,12,8,STONE:0)
RandomBlock(7,13,7,SAND:0,50,biomesoplenty:dried_sand,100)
RandomBlock(7,13,8,SAND:0,50,biomesoplenty:dried_sand,100)

#######################################################################
# +-----------------------------------------------------------------+ #
# |                             Branches                            | #
# +-----------------------------------------------------------------+ #
#######################################################################

Branch(16,0,0,true,GorgonTemple_02C8R0,NORTH,100.0,0)

#######################################################################
# +-----------------------------------------------------------------+ #
# |                             Entities                            | #
# +-----------------------------------------------------------------+ #
#######################################################################


#######################################################################
# +-----------------------------------------------------------------+ #
# |                            Particles                            | #
# +-----------------------------------------------------------------+ #
#######################################################################


#######################################################################
# +-----------------------------------------------------------------+ #
# |                             Spawners                            | #
# +-----------------------------------------------------------------+ #
#######################################################################


#######################################################################
# +-----------------------------------------------------------------+ #
# |                             ModData                             | #
# +-----------------------------------------------------------------+ #
#######################################################################

