
#######################################################################
# +-----------------------------------------------------------------+ #
# |                            BO4 object                           | #
# +-----------------------------------------------------------------+ #
#######################################################################

Author: NLBlackEagle

Description: No description given

SettingsMode: WriteWithoutComments


#######################################################################
# +-----------------------------------------------------------------+ #
# |                          Main settings                          | #
# +-----------------------------------------------------------------+ #
#######################################################################

FixedRotation: 

Frequency: 0

SpawnHeight: highestBlock

UseCenterForHighestBlock: true

##############################
# Height Limits for the BO4. #
##############################

MinHeight: 0

MaxHeight: 255

InheritBO3: 

InheritBO3Rotation: NORTH

OverrideChildSettings: true

OverrideParentHeight: false

CanOverride: false

BranchFrequency: 0

BranchFrequencyGroup: 

MustBeBelowOther: false

MustBeInside: 

CannotBeInside: 

ReplacesBO3: 

MustBeInsideWorldBorders: false

CanSpawnOnWater: true

SpawnOnWaterOnly: false

SpawnUnderWater: false

SpawnAtWaterLevel: false

HeightOffset: 0

RemoveAir: false

ReplaceAbove: 

ReplaceBelow: 

ReplaceWithBiomeBlocks: true

ReplaceWithSurfaceBlock: GRASS

ReplaceWithGroundBlock: DIRT

ReplaceWithStoneBlock: STONE

SmoothRadius: 0

SmoothHeightOffset: 0

SmoothStartTop: false

SmoothStartWood: false

SmoothingSurfaceBlock: 

SmoothingGroundBlock: 

BO3Group: 

IsSpawnPoint: false

DoReplaceBlocks: false


#######################################################################
# +-----------------------------------------------------------------+ #
# |                              Blocks                             | #
# +-----------------------------------------------------------------+ #
#######################################################################

Block(-8,0,-7,STONE:0)
Block(-8,0,-6,STONE:0)
Block(-8,0,-5,STONE:0)
Block(-8,0,-4,STONE:0)
Block(-8,0,-3,STONE:0)
Block(-8,0,-2,STONE:0)
Block(-8,0,-1,STONE:0)
Block(-8,0,0,STONE:0)
Block(-8,0,1,STONE:0)
Block(-8,0,2,STONE:0)
Block(-8,1,-7,STONE:0)
Block(-8,1,-6,STONE:0)
RandomBlock(-8,1,-5,SAND:0,50,biomesoplenty:dried_sand,100)
RandomBlock(-8,1,-4,SAND:0,50,biomesoplenty:dried_sand,100)
RandomBlock(-8,1,-3,SAND:0,50,biomesoplenty:dried_sand,100)
Block(-8,1,-2,STONE:0)
Block(-8,1,-1,STONE:0)
Block(-8,1,0,STONE:0)
Block(-8,1,1,STONE:0)
Block(-8,1,2,STONE:0)
Block(-8,2,-7,STONE:0)
Block(-8,2,-6,STONE:0)
RandomBlock(-8,2,-5,SAND:0,50,biomesoplenty:dried_sand,100)
RandomBlock(-8,2,-4,SAND:0,50,biomesoplenty:dried_sand,100)
RandomBlock(-8,2,-3,SAND:0,50,biomesoplenty:dried_sand,100)
RandomBlock(-8,2,-2,SAND:0,50,biomesoplenty:dried_sand,100)
RandomBlock(-8,2,-1,SAND:0,50,biomesoplenty:dried_sand,100)
Block(-8,2,0,STONE:0)
Block(-8,2,1,STONE:0)
Block(-8,3,-7,STONE:0)
Block(-8,3,-6,STONE:0)
RandomBlock(-8,3,-5,SAND:0,50,biomesoplenty:dried_sand,100)
RandomBlock(-8,3,-4,SAND:0,50,biomesoplenty:dried_sand,100)
RandomBlock(-8,3,-3,SAND:0,50,biomesoplenty:dried_sand,100)
RandomBlock(-8,3,-2,SAND:0,50,biomesoplenty:dried_sand,100)
Block(-8,3,-1,STONE:0)
Block(-8,3,0,STONE:0)
Block(-8,4,-7,STONE:0)
Block(-8,4,-6,STONE:0)
RandomBlock(-8,4,-5,SAND:0,50,biomesoplenty:dried_sand,100)
RandomBlock(-8,4,-4,SAND:0,50,biomesoplenty:dried_sand,100)
RandomBlock(-8,4,-3,SAND:0,50,biomesoplenty:dried_sand,100)
RandomBlock(-8,4,-2,SAND:0,50,biomesoplenty:dried_sand,100)
RandomBlock(-8,4,-1,SAND:0,50,biomesoplenty:dried_sand,100)
Block(-8,5,-7,STONE:0)
Block(-8,5,-6,STONE:0)
RandomBlock(-8,5,-5,SAND:0,50,biomesoplenty:dried_sand,100)
RandomBlock(-8,5,-4,SAND:0,50,biomesoplenty:dried_sand,100)
Block(-8,6,-7,STONE:0)
RandomBlock(-8,6,-6,SAND:0,50,biomesoplenty:dried_sand,100)
RandomBlock(-8,7,-7,SAND:0,50,biomesoplenty:dried_sand,100)
Block(-7,0,-7,STONE:0)
Block(-7,0,-6,STONE:0)
Block(-7,0,-5,STONE:0)
Block(-7,0,-4,STONE:0)
Block(-7,0,-3,STONE:0)
Block(-7,0,-2,STONE:0)
Block(-7,0,-1,STONE:0)
Block(-7,0,0,STONE:0)
Block(-7,0,1,STONE:0)
Block(-7,1,-7,STONE:0)
RandomBlock(-7,1,-6,SAND:0,50,biomesoplenty:dried_sand,100)
RandomBlock(-7,1,-5,SAND:0,50,biomesoplenty:dried_sand,100)
RandomBlock(-7,1,-4,SAND:0,50,biomesoplenty:dried_sand,100)
Block(-7,1,-3,STONE:0)
Block(-7,1,-2,STONE:0)
Block(-7,1,-1,STONE:0)
Block(-7,1,0,STONE:0)
Block(-7,1,1,STONE:0)
Block(-7,2,-7,STONE:0)
RandomBlock(-7,2,-6,SAND:0,50,biomesoplenty:dried_sand,100)
RandomBlock(-7,2,-5,SAND:0,50,biomesoplenty:dried_sand,100)
RandomBlock(-7,2,-4,SAND:0,50,biomesoplenty:dried_sand,100)
RandomBlock(-7,2,-3,SAND:0,50,biomesoplenty:dried_sand,100)
Block(-7,2,-2,STONE:0)
RandomBlock(-7,2,-1,SAND:0,50,biomesoplenty:dried_sand,100)
Block(-7,2,0,STONE:0)
Block(-7,3,-7,STONE:0)
RandomBlock(-7,3,-6,SAND:0,50,biomesoplenty:dried_sand,100)
RandomBlock(-7,3,-5,SAND:0,50,biomesoplenty:dried_sand,100)
RandomBlock(-7,3,-4,SAND:0,50,biomesoplenty:dried_sand,100)
RandomBlock(-7,3,-3,SAND:0,50,biomesoplenty:dried_sand,100)
Block(-7,3,-2,STONE:0)
RandomBlock(-7,3,-1,SAND:0,50,biomesoplenty:dried_sand,100)
Block(-7,3,0,STONE:0)
Block(-7,4,-7,STONE:0)
RandomBlock(-7,4,-6,SAND:0,50,biomesoplenty:dried_sand,100)
RandomBlock(-7,4,-5,SAND:0,50,biomesoplenty:dried_sand,100)
RandomBlock(-7,4,-4,SAND:0,50,biomesoplenty:dried_sand,100)
RandomBlock(-7,4,-3,SAND:0,50,biomesoplenty:dried_sand,100)
RandomBlock(-7,4,-2,SAND:0,50,biomesoplenty:dried_sand,100)
RandomBlock(-7,4,-1,SAND:0,50,biomesoplenty:dried_sand,100)
Block(-7,5,-7,STONE:0)
RandomBlock(-7,6,-7,SAND:0,50,biomesoplenty:dried_sand,100)
Block(-6,0,-7,STONE:0)
Block(-6,0,-6,STONE:0)
Block(-6,0,-5,STONE:0)
Block(-6,0,-4,STONE:0)
Block(-6,0,-3,STONE:0)
Block(-6,0,-2,STONE:0)
Block(-6,0,-1,STONE:0)
Block(-6,0,0,STONE:0)
Block(-6,0,1,STONE:0)
Block(-6,0,2,STONE:0)
Block(-6,1,-7,STONE:0)
RandomBlock(-6,1,-6,SAND:0,50,biomesoplenty:dried_sand,100)
RandomBlock(-6,1,-5,SAND:0,50,biomesoplenty:dried_sand,100)
Block(-6,1,-4,STONE:0)
Block(-6,1,-3,STONE:0)
Block(-6,1,-2,STONE:0)
Block(-6,1,-1,STONE:0)
Block(-6,1,0,STONE:0)
Block(-6,1,1,STONE:0)
Block(-6,1,2,STONE:0)
Block(-6,2,-7,STONE:0)
RandomBlock(-6,2,-6,SAND:0,50,biomesoplenty:dried_sand,100)
RandomBlock(-6,2,-5,SAND:0,50,biomesoplenty:dried_sand,100)
Block(-6,2,-4,STONE:0)
Block(-6,2,-3,STONE:0)
Block(-6,2,-2,STONE:0)
Block(-6,2,-1,STONE:0)
Block(-6,2,0,STONE:0)
Block(-6,2,1,STONE:0)
Block(-6,3,-7,STONE:0)
RandomBlock(-6,3,-6,SAND:0,50,biomesoplenty:dried_sand,100)
RandomBlock(-6,3,-5,SAND:0,50,biomesoplenty:dried_sand,100)
RandomBlock(-6,3,-4,SAND:0,50,biomesoplenty:dried_sand,100)
Block(-6,3,-3,STONE:0)
Block(-6,3,-2,STONE:0)
Block(-6,3,-1,STONE:0)
Block(-6,4,-7,STONE:0)
RandomBlock(-6,4,-6,SAND:0,50,biomesoplenty:dried_sand,100)
RandomBlock(-6,4,-5,SAND:0,50,biomesoplenty:dried_sand,100)
RandomBlock(-6,4,-4,SAND:0,50,biomesoplenty:dried_sand,100)
RandomBlock(-6,4,-2,SAND:0,50,biomesoplenty:dried_sand,100)
Block(-6,5,-7,STONE:0)
RandomBlock(-6,6,-7,SAND:0,50,biomesoplenty:dried_sand,100)
Block(-5,0,-7,STONE:0)
Block(-5,0,-6,STONE:0)
Block(-5,0,-5,STONE:0)
Block(-5,0,-4,STONE:0)
Block(-5,0,-3,STONE:0)
Block(-5,0,-2,STONE:0)
Block(-5,0,-1,STONE:0)
Block(-5,0,0,STONE:0)
Block(-5,0,1,STONE:0)
Block(-5,1,-7,STONE:0)
RandomBlock(-5,1,-6,SAND:0,50,biomesoplenty:dried_sand,100)
Block(-5,1,-5,STONE:0)
Block(-5,1,-4,STONE:0)
Block(-5,1,-3,STONE:0)
Block(-5,1,-2,STONE:0)
Block(-5,1,-1,STONE:0)
Block(-5,1,0,STONE:0)
Block(-5,1,1,STONE:0)
Block(-5,2,-7,STONE:0)
RandomBlock(-5,2,-6,SAND:0,50,biomesoplenty:dried_sand,100)
RandomBlock(-5,2,-5,SAND:0,50,biomesoplenty:dried_sand,100)
Block(-5,2,-4,STONE:0)
Block(-5,2,-3,STONE:0)
Block(-5,2,-2,STONE:0)
Block(-5,2,-1,STONE:0)
Block(-5,2,0,STONE:0)
Block(-5,3,-7,STONE:0)
RandomBlock(-5,3,-6,SAND:0,50,biomesoplenty:dried_sand,100)
RandomBlock(-5,3,-5,SAND:0,50,biomesoplenty:dried_sand,100)
Block(-5,3,-4,STONE:0)
Block(-5,3,-3,STONE:0)
Block(-5,4,-7,STONE:0)
RandomBlock(-5,4,-6,SAND:0,50,biomesoplenty:dried_sand,100)
RandomBlock(-5,4,-5,SAND:0,50,biomesoplenty:dried_sand,100)
RandomBlock(-5,4,-4,SAND:0,50,biomesoplenty:dried_sand,100)
Block(-5,5,-7,STONE:0)
Block(-5,6,-7,STONE:0)
RandomBlock(-5,7,-7,SAND:0,50,biomesoplenty:dried_sand,100)
Block(-4,0,-7,STONE:0)
Block(-4,0,-6,STONE:0)
Block(-4,0,-5,STONE:0)
Block(-4,0,-4,STONE:0)
Block(-4,0,-3,STONE:0)
Block(-4,0,-2,STONE:0)
Block(-4,0,-1,STONE:0)
Block(-4,0,0,STONE:0)
Block(-4,0,1,STONE:0)
Block(-4,1,-7,STONE:0)
RandomBlock(-4,1,-6,SAND:0,50,biomesoplenty:dried_sand,100)
Block(-4,1,-5,STONE:0)
Block(-4,1,-4,STONE:0)
Block(-4,1,-3,STONE:0)
Block(-4,1,-2,STONE:0)
Block(-4,1,-1,STONE:0)
Block(-4,1,0,STONE:0)
Block(-4,1,1,STONE:0)
Block(-4,2,-7,STONE:0)
RandomBlock(-4,2,-6,SAND:0,50,biomesoplenty:dried_sand,100)
RandomBlock(-4,2,-5,SAND:0,50,biomesoplenty:dried_sand,100)
Block(-4,2,-4,STONE:0)
Block(-4,2,-3,STONE:0)
Block(-4,2,-2,STONE:0)
Block(-4,2,-1,STONE:0)
Block(-4,2,0,STONE:0)
Block(-4,3,-7,STONE:0)
RandomBlock(-4,3,-6,SAND:0,50,biomesoplenty:dried_sand,100)
RandomBlock(-4,3,-5,SAND:0,50,biomesoplenty:dried_sand,100)
RandomBlock(-4,3,-4,SAND:0,50,biomesoplenty:dried_sand,100)
Block(-4,3,-3,STONE:0)
Block(-4,3,-2,STONE:0)
Block(-4,4,-7,STONE:0)
RandomBlock(-4,4,-6,SAND:0,50,biomesoplenty:dried_sand,100)
RandomBlock(-4,4,-5,SAND:0,50,biomesoplenty:dried_sand,100)
Block(-4,5,-7,STONE:0)
RandomBlock(-4,6,-7,SAND:0,50,biomesoplenty:dried_sand,100)
Block(-3,0,-7,STONE:0)
Block(-3,0,-6,STONE:0)
Block(-3,0,-5,STONE:0)
Block(-3,0,-4,STONE:0)
Block(-3,0,-3,STONE:0)
Block(-3,0,-2,STONE:0)
Block(-3,0,-1,STONE:0)
Block(-3,0,0,STONE:0)
Block(-3,0,1,STONE:0)
Block(-3,1,-7,STONE:0)
RandomBlock(-3,1,-6,SAND:0,50,biomesoplenty:dried_sand,100)
Block(-3,1,-5,STONE:0)
Block(-3,1,-4,STONE:0)
Block(-3,1,-3,STONE:0)
Block(-3,1,-2,STONE:0)
Block(-3,1,-1,STONE:0)
Block(-3,1,0,STONE:0)
Block(-3,1,1,STONE:0)
Block(-3,2,-7,STONE:0)
RandomBlock(-3,2,-6,SAND:0,50,biomesoplenty:dried_sand,100)
RandomBlock(-3,2,-5,SAND:0,50,biomesoplenty:dried_sand,100)
Block(-3,2,-4,STONE:0)
Block(-3,2,-3,STONE:0)
Block(-3,2,-2,STONE:0)
Block(-3,2,-1,STONE:0)
Block(-3,2,0,STONE:0)
Block(-3,3,-7,STONE:0)
RandomBlock(-3,3,-6,SAND:0,50,biomesoplenty:dried_sand,100)
RandomBlock(-3,3,-5,SAND:0,50,biomesoplenty:dried_sand,100)
RandomBlock(-3,3,-4,SAND:0,50,biomesoplenty:dried_sand,100)
Block(-3,4,-7,STONE:0)
RandomBlock(-3,4,-6,SAND:0,50,biomesoplenty:dried_sand,100)
RandomBlock(-3,4,-5,SAND:0,50,biomesoplenty:dried_sand,100)
Block(-3,5,-7,STONE:0)
RandomBlock(-3,6,-7,SAND:0,50,biomesoplenty:dried_sand,100)
Block(-2,0,-7,STONE:0)
Block(-2,0,-6,STONE:0)
Block(-2,0,-5,STONE:0)
Block(-2,0,-4,STONE:0)
Block(-2,0,-3,STONE:0)
Block(-2,0,-2,STONE:0)
Block(-2,0,-1,STONE:0)
Block(-2,0,0,STONE:0)
Block(-2,0,1,STONE:0)
Block(-2,0,2,STONE:0)
Block(-2,1,-7,STONE:0)
RandomBlock(-2,1,-6,SAND:0,50,biomesoplenty:dried_sand,100)
Block(-2,1,-5,STONE:0)
Block(-2,1,-4,STONE:0)
Block(-2,1,-3,STONE:0)
Block(-2,1,-2,STONE:0)
Block(-2,1,-1,STONE:0)
Block(-2,1,0,STONE:0)
Block(-2,1,1,STONE:0)
Block(-2,1,2,STONE:0)
Block(-2,2,-7,STONE:0)
RandomBlock(-2,2,-6,SAND:0,50,biomesoplenty:dried_sand,100)
Block(-2,2,-5,STONE:0)
Block(-2,2,-4,STONE:0)
Block(-2,2,-3,STONE:0)
Block(-2,2,-2,STONE:0)
Block(-2,2,-1,STONE:0)
Block(-2,2,0,STONE:0)
Block(-2,2,1,STONE:0)
Block(-2,3,-7,STONE:0)
RandomBlock(-2,3,-6,SAND:0,50,biomesoplenty:dried_sand,100)
RandomBlock(-2,3,-5,SAND:0,50,biomesoplenty:dried_sand,100)
RandomBlock(-2,3,-4,SAND:0,50,biomesoplenty:dried_sand,100)
Block(-2,4,-7,STONE:0)
RandomBlock(-2,4,-6,SAND:0,50,biomesoplenty:dried_sand,100)
RandomBlock(-2,4,-5,SAND:0,50,biomesoplenty:dried_sand,100)
Block(-2,5,-7,STONE:0)
RandomBlock(-2,5,-6,SAND:0,50,biomesoplenty:dried_sand,100)
RandomBlock(-2,6,-7,SAND:0,50,biomesoplenty:dried_sand,100)
RandomBlock(-2,7,-7,SAND:0,50,biomesoplenty:dried_sand,100)
Block(-1,0,-7,STONE:0)
Block(-1,0,-6,STONE:0)
Block(-1,0,-5,STONE:0)
Block(-1,0,-4,STONE:0)
Block(-1,0,-3,STONE:0)
Block(-1,0,-2,STONE:0)
Block(-1,0,-1,STONE:0)
Block(-1,0,0,STONE:0)
Block(-1,0,1,STONE:0)
Block(-1,1,-7,STONE:0)
Block(-1,1,-6,STONE:0)
Block(-1,1,-5,STONE:0)
Block(-1,1,-4,STONE:0)
Block(-1,1,-3,STONE:0)
Block(-1,1,-2,STONE:0)
Block(-1,1,-1,STONE:0)
Block(-1,1,0,STONE:0)
Block(-1,1,1,STONE:0)
Block(-1,2,-7,STONE:0)
Block(-1,2,-6,STONE:0)
Block(-1,2,-5,STONE:0)
Block(-1,2,-4,STONE:0)
Block(-1,2,-3,STONE:0)
Block(-1,2,-2,STONE:0)
Block(-1,2,-1,STONE:0)
Block(-1,3,-7,STONE:0)
Block(-1,3,-6,STONE:0)
Block(-1,3,-5,STONE:0)
Block(-1,3,-4,STONE:0)
Block(-1,4,-7,STONE:0)
Block(-1,4,-6,STONE:0)
Block(-1,4,-5,STONE:0)
Block(-1,5,-7,STONE:0)
RandomBlock(-1,5,-6,SAND:0,50,biomesoplenty:dried_sand,100)
RandomBlock(-1,6,-7,SAND:0,50,biomesoplenty:dried_sand,100)
RandomBlock(-1,6,-6,SAND:0,50,biomesoplenty:dried_sand,100)
RandomBlock(-1,7,-7,SAND:0,50,biomesoplenty:dried_sand,100)
Block(0,0,-7,STONE:0)
Block(0,0,-6,STONE:0)
Block(0,0,-5,STONE:0)
Block(0,0,-4,STONE:0)
Block(0,0,-3,STONE:0)
Block(0,0,-2,STONE:0)
Block(0,0,-1,STONE:0)
Block(0,0,0,STONE:0)
Block(0,1,-7,STONE:0)
Block(0,1,-6,STONE:0)
Block(0,1,-5,STONE:0)
Block(0,1,-4,STONE:0)
Block(0,1,-3,STONE:0)
Block(0,1,-2,STONE:0)
Block(0,1,-1,STONE:0)
Block(0,1,0,STONE:0)
Block(0,2,-7,STONE:0)
Block(0,2,-6,STONE:0)
Block(0,2,-5,STONE:0)
Block(0,2,-4,STONE:0)
Block(0,2,-3,STONE:0)
Block(0,2,-2,STONE:0)
Block(0,2,-1,STONE:0)
Block(0,3,-7,STONE:0)
Block(0,3,-6,STONE:0)
Block(0,3,-5,STONE:0)
Block(0,3,-4,STONE:0)
Block(0,4,-7,STONE:0)
Block(0,4,-6,STONE:0)
Block(0,4,-5,STONE:0)
RandomBlock(0,5,-7,SAND:0,50,biomesoplenty:dried_sand,100)
RandomBlock(0,5,-6,SAND:0,50,biomesoplenty:dried_sand,100)
RandomBlock(0,6,-7,SAND:0,50,biomesoplenty:dried_sand,100)
RandomBlock(0,6,-6,SAND:0,50,biomesoplenty:dried_sand,100)
Block(1,0,-7,STONE:0)
Block(1,0,-6,STONE:0)
Block(1,0,-5,STONE:0)
Block(1,0,-4,STONE:0)
Block(1,0,-3,STONE:0)
Block(1,0,-2,STONE:0)
Block(1,0,-1,STONE:0)
Block(1,1,-7,STONE:0)
Block(1,1,-6,STONE:0)
Block(1,1,-5,STONE:0)
Block(1,1,-4,STONE:0)
Block(1,1,-3,STONE:0)
Block(1,1,-2,STONE:0)
Block(1,1,-1,STONE:0)
Block(1,2,-7,STONE:0)
Block(1,2,-6,STONE:0)
Block(1,2,-5,STONE:0)
Block(1,2,-4,STONE:0)
Block(1,3,-7,STONE:0)
Block(1,3,-6,STONE:0)
Block(1,3,-5,STONE:0)
Block(1,4,-7,STONE:0)
Block(1,4,-6,STONE:0)
RandomBlock(1,5,-7,SAND:0,50,biomesoplenty:dried_sand,100)
RandomBlock(1,5,-6,SAND:0,50,biomesoplenty:dried_sand,100)
RandomBlock(1,6,-7,SAND:0,50,biomesoplenty:dried_sand,100)
RandomBlock(1,6,-6,SAND:0,50,biomesoplenty:dried_sand,100)
Block(2,0,-7,STONE:0)
Block(2,0,-6,STONE:0)
Block(2,0,-5,STONE:0)
Block(2,0,-4,STONE:0)
Block(2,0,-3,STONE:0)
Block(2,0,-2,STONE:0)
RandomBlock(2,1,-7,SAND:0,50,biomesoplenty:dried_sand,100)
Block(2,1,-6,STONE:0)
Block(2,1,-5,STONE:0)
Block(2,1,-4,STONE:0)
Block(2,1,-3,STONE:0)
Block(2,1,-2,STONE:0)
RandomBlock(2,2,-7,SAND:0,50,biomesoplenty:dried_sand,100)
Block(2,2,-6,STONE:0)
Block(2,2,-5,STONE:0)
Block(2,2,-4,STONE:0)
Block(2,2,-3,STONE:0)
RandomBlock(2,3,-7,SAND:0,50,biomesoplenty:dried_sand,100)
Block(2,3,-6,STONE:0)
Block(2,3,-5,STONE:0)
Block(2,3,-4,STONE:0)
RandomBlock(2,4,-7,SAND:0,50,biomesoplenty:dried_sand,100)
Block(2,4,-6,STONE:0)
RandomBlock(2,5,-7,SAND:0,50,biomesoplenty:dried_sand,100)
Block(3,0,-7,STONE:0)
Block(3,0,-6,STONE:0)
Block(3,0,-5,STONE:0)
Block(3,0,-4,STONE:0)
Block(3,0,-3,STONE:0)
Block(3,0,-2,STONE:0)
RandomBlock(3,1,-7,SAND:0,50,biomesoplenty:dried_sand,100)
Block(3,1,-6,STONE:0)
Block(3,1,-5,STONE:0)
Block(3,1,-4,STONE:0)
Block(3,1,-3,STONE:0)
Block(3,1,-2,STONE:0)
RandomBlock(3,2,-7,SAND:0,50,biomesoplenty:dried_sand,100)
Block(3,2,-6,STONE:0)
Block(3,2,-5,STONE:0)
Block(3,2,-4,STONE:0)
Block(3,2,-3,STONE:0)
Block(3,3,-7,STONE:0)
RandomBlock(3,3,-6,SAND:0,50,biomesoplenty:dried_sand,100)
Block(3,3,-5,STONE:0)
Block(4,0,-7,STONE:0)
Block(4,0,-6,STONE:0)
Block(4,0,-5,STONE:0)
Block(4,0,-4,STONE:0)
Block(4,0,-3,STONE:0)
RandomBlock(4,1,-7,SAND:0,50,biomesoplenty:dried_sand,100)
Block(4,1,-6,STONE:0)
Block(4,1,-5,STONE:0)
Block(4,1,-4,STONE:0)
Block(4,1,-3,STONE:0)
RandomBlock(4,2,-7,SAND:0,50,biomesoplenty:dried_sand,100)
Block(4,2,-6,STONE:0)
Block(4,2,-5,STONE:0)
Block(4,2,-4,STONE:0)
Block(4,2,-3,STONE:0)
Block(4,3,-7,STONE:0)
Block(4,3,-6,STONE:0)
Block(4,3,-5,STONE:0)
Block(5,0,-7,STONE:0)
Block(5,0,-6,STONE:0)
Block(5,0,-5,STONE:0)
Block(5,0,-4,STONE:0)
Block(5,0,-3,STONE:0)
Block(5,1,-7,STONE:0)
Block(5,1,-6,STONE:0)
Block(5,1,-5,STONE:0)
Block(5,1,-4,STONE:0)
Block(5,1,-3,STONE:0)
RandomBlock(5,2,-7,SAND:0,50,biomesoplenty:dried_sand,100)
Block(5,2,-6,STONE:0)
Block(5,2,-5,STONE:0)
Block(5,2,-4,STONE:0)
Block(5,3,-7,STONE:0)
Block(6,0,-7,STONE:0)
Block(6,0,-6,STONE:0)
Block(6,0,-5,STONE:0)
Block(6,0,-4,STONE:0)
Block(6,0,-3,STONE:0)
Block(6,1,-7,STONE:0)
Block(6,1,-6,STONE:0)
Block(6,1,-5,STONE:0)
Block(6,1,-4,STONE:0)
Block(6,1,-3,STONE:0)
RandomBlock(6,2,-7,SAND:0,50,biomesoplenty:dried_sand,100)
Block(6,2,-6,STONE:0)
Block(6,2,-5,STONE:0)
Block(6,3,-7,STONE:0)
Block(6,3,-6,STONE:0)
Block(7,0,-7,STONE:0)
Block(7,0,-6,STONE:0)
Block(7,0,-5,STONE:0)
Block(7,1,-7,STONE:0)
Block(7,1,-6,STONE:0)
Block(7,1,-5,STONE:0)
RandomBlock(7,2,-7,SAND:0,50,biomesoplenty:dried_sand,100)
Block(7,2,-6,STONE:0)
Block(7,3,-7,STONE:0)

#######################################################################
# +-----------------------------------------------------------------+ #
# |                             Branches                            | #
# +-----------------------------------------------------------------+ #
#######################################################################

Branch(0,0,16,true,GorgonTemple_02C10R12,NORTH,100.0,0)

#######################################################################
# +-----------------------------------------------------------------+ #
# |                             Entities                            | #
# +-----------------------------------------------------------------+ #
#######################################################################


#######################################################################
# +-----------------------------------------------------------------+ #
# |                            Particles                            | #
# +-----------------------------------------------------------------+ #
#######################################################################


#######################################################################
# +-----------------------------------------------------------------+ #
# |                             Spawners                            | #
# +-----------------------------------------------------------------+ #
#######################################################################


#######################################################################
# +-----------------------------------------------------------------+ #
# |                             ModData                             | #
# +-----------------------------------------------------------------+ #
#######################################################################

