
#######################################################################
# +-----------------------------------------------------------------+ #
# |                            BO4 object                           | #
# +-----------------------------------------------------------------+ #
#######################################################################

Author: NLBlackEagle

Description: No description given

SettingsMode: WriteDisable


#######################################################################
# +-----------------------------------------------------------------+ #
# |                          Main settings                          | #
# +-----------------------------------------------------------------+ #
#######################################################################

Frequency: 0

SpawnHeight: highestBlock

UseCenterForHighestBlock: true

##############################
# Height Limits for the BO4. #
##############################

MinHeight: 0

MaxHeight: 255

InheritBO3: 

InheritBO3Rotation: NORTH

OverrideChildSettings: true

OverrideParentHeight: false

CanOverride: false

BranchFrequency: 0

BranchFrequencyGroup: 

MustBeBelowOther: false

MustBeInside: 

CannotBeInside: 

ReplacesBO3: 

MustBeInsideWorldBorders: false

CanSpawnOnWater: true

SpawnOnWaterOnly: false

SpawnUnderWater: false

SpawnAtWaterLevel: false

HeightOffset: 0

RemoveAir: false

ReplaceAbove: 

ReplaceBelow: 

ReplaceWithBiomeBlocks: true

ReplaceWithSurfaceBlock: GRASS

ReplaceWithGroundBlock: DIRT

ReplaceWithStoneBlock: STONE

SmoothRadius: 0

SmoothHeightOffset: 0

SmoothStartTop: false

SmoothStartWood: false

SmoothingSurfaceBlock: 

SmoothingGroundBlock: 

BO3Group: 

IsSpawnPoint: false

DoReplaceBlocks: true


#######################################################################
# +-----------------------------------------------------------------+ #
# |                              Blocks                             | #
# +-----------------------------------------------------------------+ #
#######################################################################

Block(-8,0,1,GRASS:0)
Block(-8,0,2,GRASS:0)
Block(-8,0,3,DIRT:0)
Block(-8,0,4,DIRT:0)
Block(-8,0,5,STONE:0)
Block(-8,0,6,STONE:0)
Block(-8,0,7,STONE:0)
Block(-8,0,8,STONE:0)
Block(-8,1,3,DIRT:0)
Block(-8,1,4,DIRT:0)
RandomBlock(-8,1,5,COAL_ORE,33,STONE,100)
RandomBlock(-8,1,6,COAL_ORE,33,STONE,100)
RandomBlock(-8,1,7,COAL_ORE,33,STONE,100)
Block(-8,1,8,STONE:0)
Block(-8,2,3,GRASS:0)
Block(-8,2,4,DIRT:0)
RandomBlock(-8,2,5,COAL_ORE,33,STONE,100)
Block(-8,2,6,STONE:0)
Block(-8,2,7,STONE:0)
RandomBlock(-8,2,8,COAL_ORE,33,STONE,100)
Block(-8,3,4,GRASS:0)
Block(-8,3,5,STONE:0)
Block(-8,3,6,STONE:0)
Block(-8,3,7,STONE:0)
Block(-8,3,8,STONE:0)
Block(-8,4,5,STONE:0)
Block(-8,4,6,STONE:0)
Block(-8,4,7,STONE:0)
Block(-8,4,8,STONE:0)
Block(-8,5,6,GRASS:0)
Block(-8,5,7,DIRT:0)
Block(-8,5,8,DIRT:0)
Block(-8,6,7,GRASS:0)
Block(-8,6,8,GRASS:0)
Block(-7,0,1,GRASS:0)
Block(-7,0,2,GRASS:0)
Block(-7,0,3,DIRT:0)
Block(-7,0,4,DIRT:0)
Block(-7,0,5,STONE:0)
Block(-7,0,6,STONE:0)
Block(-7,0,7,STONE:0)
Block(-7,0,8,STONE:0)
Block(-7,1,3,DIRT:0)
Block(-7,1,4,DIRT:0)
Block(-7,1,5,STONE:0)
RandomBlock(-7,1,6,COAL_ORE,33,STONE,100)
Block(-7,1,7,STONE:0)
RandomBlock(-7,1,8,COAL_ORE,33,STONE,100)
Block(-7,2,3,GRASS:0)
Block(-7,2,4,DIRT:0)
Block(-7,2,5,DIRT:0)
Block(-7,2,6,STONE:0)
Block(-7,2,7,STONE:0)
Block(-7,2,8,STONE:0)
Block(-7,3,4,GRASS:0)
Block(-7,3,5,STONE:0)
RandomBlock(-7,3,6,COAL_ORE,33,STONE,100)
Block(-7,3,7,STONE:0)
Block(-7,3,8,STONE:0)
Block(-7,4,5,STONE:0)
Block(-7,4,6,STONE:0)
Block(-7,4,7,STONE:0)
Block(-7,4,8,STONE:0)
Block(-7,5,6,GRASS:0)
Block(-7,5,7,GRASS:0)
Block(-7,5,8,DIRT:0)
Block(-7,6,8,GRASS:0)
Block(-6,0,2,GRASS:0)
Block(-6,0,3,DIRT:0)
Block(-6,0,4,DIRT:0)
Block(-6,0,5,DIRT:0)
RandomBlock(-6,0,6,COAL_ORE,33,STONE,100)
Block(-6,0,7,STONE:0)
Block(-6,0,8,STONE:0)
Block(-6,1,3,DIRT:0)
Block(-6,1,4,DIRT:0)
Block(-6,1,5,DIRT:0)
Block(-6,1,6,STONE:0)
Block(-6,1,7,STONE:0)
RandomBlock(-6,1,8,COAL_ORE,33,STONE,100)
Block(-6,2,3,GRASS:0)
Block(-6,2,4,DIRT:0)
Block(-6,2,5,DIRT:0)
Block(-6,2,6,DIRT:0)
RandomBlock(-6,2,7,COAL_ORE,33,STONE,100)
Block(-6,2,8,STONE:0)
Block(-6,3,4,GRASS:0)
Block(-6,3,5,GRASS:0)
Block(-6,3,6,STONE:0)
RandomBlock(-6,3,7,COAL_ORE,33,STONE,100)
Block(-6,3,8,STONE:0)
RandomBlock(-6,4,6,COAL_ORE,33,STONE,100)
Block(-6,4,7,STONE:0)
Block(-6,4,8,STONE:0)
Block(-6,5,6,GRASS:0)
Block(-6,5,7,GRASS:0)
Block(-6,5,8,STONE:0)
Block(-6,6,8,GRASS:0)
Block(-5,0,2,GRASS:0)
Block(-5,0,3,DIRT:0)
Block(-5,0,4,DIRT:0)
Block(-5,0,5,DIRT:0)
Block(-5,0,6,STONE:0)
RandomBlock(-5,0,7,COAL_ORE,33,STONE,100)
RandomBlock(-5,0,8,COAL_ORE,33,STONE,100)
Block(-5,1,3,DIRT:0)
Block(-5,1,4,DIRT:0)
Block(-5,1,5,DIRT:0)
Block(-5,1,6,DIRT:0)
Block(-5,1,7,DIRT:0)
Block(-5,1,8,STONE:0)
Block(-5,2,3,GRASS:0)
Block(-5,2,4,GRASS:0)
Block(-5,2,5,DIRT:0)
Block(-5,2,6,DIRT:0)
Block(-5,2,7,DIRT:0)
RandomBlock(-5,2,8,COAL_ORE,33,STONE,100)
Block(-5,3,5,GRASS:0)
Block(-5,3,6,DIRT:0)
Block(-5,3,7,DIRT:0)
Block(-5,3,8,STONE:0)
Block(-5,4,6,STONE:0)
Block(-5,4,7,STONE:0)
Block(-5,4,8,STONE:0)
Block(-5,5,7,STONE:0)
Block(-5,5,8,STONE:0)
Block(-5,6,8,GRASS:0)
Block(-4,0,2,GRASS:0)
Block(-4,0,3,DIRT:0)
Block(-4,0,4,DIRT:0)
Block(-4,0,5,DIRT:0)
Block(-4,0,6,DIRT:0)
Block(-4,0,7,DIRT:0)
Block(-4,0,8,DIRT:0)
Block(-4,1,3,DIRT:0)
Block(-4,1,4,DIRT:0)
Block(-4,1,5,DIRT:0)
Block(-4,1,6,DIRT:0)
Block(-4,1,7,DIRT:0)
Block(-4,1,8,DIRT:0)
Block(-4,2,3,GRASS:0)
Block(-4,2,4,GRASS:0)
Block(-4,2,5,DIRT:0)
Block(-4,2,6,DIRT:0)
Block(-4,2,7,DIRT:0)
Block(-4,2,8,DIRT:0)
Block(-4,3,5,GRASS:0)
Block(-4,3,6,GRASS:0)
Block(-4,3,7,DIRT:0)
Block(-4,3,8,DIRT:0)
Block(-4,4,7,GRASS:0)
Block(-4,4,8,DIRT:0)
Block(-4,5,8,STONE:0)
Block(-3,0,2,GRASS:0)
Block(-3,0,3,DIRT:0)
Block(-3,0,4,DIRT:0)
Block(-3,0,5,DIRT:0)
Block(-3,0,6,DIRT:0)
Block(-3,0,7,DIRT:0)
Block(-3,0,8,DIRT:0)
Block(-3,1,3,GRASS:0)
Block(-3,1,4,DIRT:0)
Block(-3,1,5,DIRT:0)
Block(-3,1,6,DIRT:0)
Block(-3,1,7,DIRT:0)
Block(-3,1,8,DIRT:0)
Block(-3,2,4,GRASS:0)
Block(-3,2,5,GRASS:0)
Block(-3,2,6,DIRT:0)
Block(-3,2,7,DIRT:0)
Block(-3,2,8,DIRT:0)
Block(-3,3,6,GRASS:0)
Block(-3,3,7,DIRT:0)
Block(-3,3,8,DIRT:0)
Block(-3,4,7,GRASS:0)
Block(-3,4,8,DIRT:0)
Block(-3,5,8,STONE:0)
Block(-2,0,2,GRASS:0)
Block(-2,0,3,GRASS:0)
Block(-2,0,4,DIRT:0)
Block(-2,0,5,DIRT:0)
Block(-2,0,6,DIRT:0)
Block(-2,0,7,DIRT:0)
Block(-2,0,8,DIRT:0)
Block(-2,1,4,GRASS:0)
Block(-2,1,5,DIRT:0)
Block(-2,1,6,DIRT:0)
Block(-2,1,7,DIRT:0)
Block(-2,1,8,DIRT:0)
Block(-2,2,5,GRASS:0)
Block(-2,2,6,GRASS:0)
Block(-2,2,7,DIRT:0)
Block(-2,2,8,DIRT:0)
Block(-2,3,7,GRASS:0)
Block(-2,3,8,DIRT:0)
Block(-2,4,8,DIRT:0)
Block(-2,5,8,GRASS:0)
Block(-1,0,3,GRASS:0)
Block(-1,0,4,GRASS:0)
Block(-1,0,5,DIRT:0)
Block(-1,0,6,DIRT:0)
Block(-1,0,7,DIRT:0)
Block(-1,0,8,DIRT:0)
Block(-1,1,5,GRASS:0)
Block(-1,1,6,DIRT:0)
Block(-1,1,7,DIRT:0)
Block(-1,1,8,DIRT:0)
Block(-1,2,6,GRASS:0)
Block(-1,2,7,GRASS:0)
Block(-1,2,8,DIRT:0)
Block(-1,3,8,GRASS:0)
Block(0,0,4,GRASS:0)
Block(0,0,5,GRASS:0)
Block(0,0,6,DIRT:0)
Block(0,0,7,DIRT:0)
Block(0,0,8,DIRT:0)
Block(0,1,6,GRASS:0)
Block(0,1,7,DIRT:0)
Block(0,1,8,DIRT:0)
Block(0,2,7,GRASS:0)
Block(0,2,8,DIRT:0)
Block(0,3,8,GRASS:0)
Block(1,0,5,GRASS:0)
Block(1,0,6,GRASS:0)
Block(1,0,7,DIRT:0)
Block(1,0,8,DIRT:0)
Block(1,1,7,GRASS:0)
Block(1,1,8,DIRT:0)
Block(1,2,8,GRASS:0)
Block(2,0,6,STONE:0)
Block(2,0,7,STONE:0)
Block(2,0,8,DIRT:0)
Block(2,1,7,GRASS:0)
Block(2,1,8,GRASS:0)
Block(3,0,7,STONE:0)
Block(3,0,8,STONE:0)
Block(4,0,8,STONE:0)

#######################################################################
# +-----------------------------------------------------------------+ #
# |                             Branches                            | #
# +-----------------------------------------------------------------+ #
#######################################################################

Branch(0,0,16,true,quarryC7R3,NORTH,100.0,0)

#######################################################################
# +-----------------------------------------------------------------+ #
# |                             Entities                            | #
# +-----------------------------------------------------------------+ #
#######################################################################


#######################################################################
# +-----------------------------------------------------------------+ #
# |                            Particles                            | #
# +-----------------------------------------------------------------+ #
#######################################################################


#######################################################################
# +-----------------------------------------------------------------+ #
# |                             Spawners                            | #
# +-----------------------------------------------------------------+ #
#######################################################################


#######################################################################
# +-----------------------------------------------------------------+ #
# |                             ModData                             | #
# +-----------------------------------------------------------------+ #
#######################################################################

